File: Data/15% 30min RT - 1 - 1_07262023_144613.csv
Time (sec),S:Load (lbs),S:HL1 (DIM),S:LVDT (in),S:Position (in),Ch:Position (mm),Ch:Load (N),Ch:Stress (MPa),Ch:Strain (mm/mm),Ch:HL1 (DIM),Set Point (),Cycles ()
0.110000,-0.012661,-203.589310,0.000043,-0.000000,-0.000000,-0.056317,-0.002869,-0.000000,-203.589310,0.000017,0.000000
0.630000,-0.013405,-203.544830,0.000026,0.000132,0.003348,-0.059630,-0.003038,0.033475,-203.544830,0.004093,0.000000
1.150000,-0.002607,-203.500351,0.000211,0.000450,0.011430,-0.011595,-0.000591,0.114301,-203.500351,0.012766,0.000000
1.670000,0.024949,-203.366913,0.000573,0.000794,0.020163,0.110978,0.005654,0.201630,-203.366913,0.021420,0.000000
2.190000,0.018619,-203.366913,0.000927,0.001135,0.028835,0.082820,0.004219,0.288353,-203.366913,0.030093,0.000000
2.710000,0.007820,-203.366913,0.001263,0.001484,0.037690,0.034784,0.001772,0.376897,-203.366913,0.038748,0.000000
3.230000,0.009309,-203.233459,0.001587,0.001814,0.046067,0.041410,0.002110,0.460670,-203.233459,0.047420,0.000000
3.750000,0.031652,-203.188980,0.001962,0.002157,0.054791,0.140794,0.007172,0.547913,-203.188980,0.056075,0.000000
4.270000,0.033141,-203.055542,0.002341,0.002506,0.063654,0.147419,0.007510,0.636544,-203.055542,0.064747,0.000000
4.790000,0.047291,-203.011063,0.002677,0.002844,0.072231,0.210362,0.010716,0.722312,-203.011063,0.073402,0.000000
5.310000,0.020108,-203.011063,0.003001,0.003180,0.080765,0.089445,0.004557,0.807647,-203.011063,0.082074,0.000000
5.830000,0.002607,-202.966583,0.003380,0.003521,0.089446,0.011595,0.000591,0.894457,-202.966583,0.090729,0.000000
6.350000,0.059580,-202.833130,0.003717,0.003858,0.098005,0.265023,0.013501,0.980052,-202.833130,0.099401,0.000000
6.870000,0.062186,-202.744171,0.004113,0.004205,0.106808,0.276618,0.014092,1.068075,-202.744171,0.108056,0.000000
7.390000,0.033886,-202.744171,0.004449,0.004547,0.115497,0.150732,0.007679,1.154971,-202.744171,0.116711,0.000000
7.910000,0.016384,-202.699692,0.004838,0.004890,0.124195,0.072882,0.003713,1.241954,-202.699692,0.125383,0.000000
8.430000,0.075592,-202.655212,0.005178,0.005226,0.132746,0.336248,0.017129,1.327462,-202.655212,0.134038,0.000000
8.950001,0.075592,-202.521774,0.005553,0.005573,0.141566,0.336248,0.017129,1.415660,-202.521774,0.142711,0.000000
9.470000,0.052132,-202.521774,0.005898,0.005915,0.150238,0.231895,0.011813,1.502382,-202.521774,0.151366,0.000000
9.990001,0.058463,-202.343842,0.006217,0.006248,0.158702,0.260054,0.013248,1.587023,-202.343842,0.160038,0.000000
10.510000,0.064793,-202.343842,0.006610,0.006596,0.167548,0.288213,0.014682,1.675480,-202.343842,0.168693,0.000000
11.030001,0.067399,-202.343842,0.006967,0.006942,0.176324,0.299808,0.015273,1.763243,-202.343842,0.177365,0.000000
11.550000,0.063303,-202.254883,0.007317,0.007275,0.184780,0.281587,0.014345,1.847798,-202.254883,0.186020,0.000000
12.070001,0.016012,-202.165924,0.007662,0.007612,0.193357,0.071225,0.003628,1.933567,-202.165924,0.194692,0.000000
12.590000,0.078571,-202.032486,0.008024,0.007963,0.202263,0.349499,0.017804,2.022631,-202.032486,0.203347,0.000000
13.110001,0.087508,-202.076965,0.008343,0.008294,0.210658,0.389253,0.019829,2.106578,-202.076965,0.212019,0.000000
13.630001,0.067399,-201.987991,0.008722,0.008638,0.219408,0.299808,0.015273,2.194081,-201.987991,0.220674,0.000000
14.150001,0.042078,-201.899033,0.009084,0.008982,0.228141,0.187173,0.009535,2.281411,-201.899033,0.229347,0.000000
14.670001,0.084529,-201.765594,0.009434,0.009321,0.236744,0.376002,0.019154,2.367440,-201.765594,0.238001,0.000000
15.190001,0.078571,-201.721115,0.009796,0.009666,0.245529,0.349499,0.017804,2.455289,-201.721115,0.246674,0.000000
15.710001,0.072240,-201.676636,0.010111,0.010008,0.254210,0.321341,0.016370,2.542099,-201.676636,0.255329,0.000000
16.230001,0.068144,-201.632156,0.010490,0.010343,0.262709,0.303121,0.015442,2.627087,-201.632156,0.263983,0.000000
16.750000,0.085646,-201.498703,0.010848,0.010681,0.271303,0.380971,0.019408,2.713029,-201.498703,0.272656,0.000000
17.270000,0.090859,-201.454224,0.011240,0.011032,0.280218,0.404160,0.020589,2.802180,-201.454224,0.281311,0.000000
17.790001,0.084901,-201.365265,0.011598,0.011373,0.288864,0.377658,0.019239,2.888642,-201.365265,0.289983,0.000000
18.310001,0.083039,-201.276306,0.011913,0.011706,0.297337,0.369376,0.018817,2.973370,-201.276306,0.298638,0.000000
18.830002,0.098679,-201.187347,0.012314,0.012058,0.306269,0.438945,0.022361,3.062694,-201.187347,0.307310,0.000000
19.350000,0.118787,-201.187347,0.012641,0.012393,0.314794,0.528390,0.026917,3.147943,-201.187347,0.315965,0.000000
19.870001,0.097934,-201.187347,0.013008,0.012734,0.323432,0.435632,0.022192,3.234318,-201.187347,0.324637,0.000000
20.390001,0.058090,-201.053894,0.013344,0.013071,0.332009,0.258398,0.013163,3.320087,-201.053894,0.333292,0.000000
20.910002,0.114318,-200.964935,0.013698,0.013419,0.340854,0.508514,0.025905,3.408544,-200.964935,0.341964,0.000000
21.430000,0.122511,-200.875977,0.014056,0.013755,0.349371,0.544954,0.027761,3.493706,-200.875977,0.350619,0.000000
21.950001,0.099796,-200.831497,0.014413,0.014103,0.358216,0.443914,0.022614,3.582162,-200.831497,0.359292,0.000000
22.470001,0.101285,-200.787018,0.014763,0.014438,0.366715,0.450540,0.022952,3.667151,-200.787018,0.367947,0.000000
22.990002,0.139640,-200.653564,0.015120,0.014780,0.375413,0.621148,0.031643,3.754134,-200.653564,0.376619,0.000000
23.510000,0.131820,-200.564606,0.015483,0.015122,0.384094,0.586364,0.029871,3.840943,-200.564606,0.385274,0.000000
24.030001,0.111712,-200.520126,0.015853,0.015468,0.392888,0.496919,0.025314,3.928879,-200.520126,0.393946,0.000000
24.550001,0.098679,-200.386688,0.016168,0.015800,0.401317,0.438945,0.022361,4.013174,-200.386688,0.402601,0.000000
25.070002,0.138895,-200.342209,0.016543,0.016144,0.410059,0.617835,0.031474,4.100590,-200.342209,0.411256,0.000000
25.590002,0.117297,-200.253235,0.016914,0.016492,0.418887,0.521765,0.026580,4.188873,-200.253235,0.419928,0.000000
26.110001,0.136288,-200.208755,0.017250,0.016830,0.427490,0.606241,0.030883,4.274902,-200.208755,0.428583,0.000000
26.630001,0.112084,-200.075317,0.017621,0.017165,0.435980,0.498575,0.025399,4.359804,-200.075317,0.437255,0.000000
27.150002,0.082667,-199.986359,0.017988,0.017505,0.444627,0.367720,0.018733,4.446266,-199.986359,0.445910,0.000000
27.670002,0.147087,-199.941879,0.018346,0.017842,0.453177,0.654276,0.033330,4.531775,-199.941879,0.454582,0.000000
28.190001,0.143363,-199.852921,0.018677,0.018190,0.462023,0.637712,0.032487,4.620232,-199.852921,0.463237,0.000000
28.710001,0.109850,-199.763947,0.019083,0.018531,0.470687,0.488637,0.024892,4.706867,-199.763947,0.471910,0.000000
29.230001,0.098679,-199.630508,0.019462,0.018872,0.479359,0.438945,0.022361,4.793590,-199.630508,0.480564,0.000000
29.750002,0.137033,-199.586029,0.019751,0.019212,0.487979,0.609554,0.031052,4.879793,-199.586029,0.489237,0.000000
30.270002,0.161982,-199.497070,0.020152,0.019557,0.496747,0.720532,0.036706,4.967469,-199.497070,0.497892,0.000000
30.790001,0.121766,-199.452591,0.020480,0.019898,0.505410,0.541641,0.027593,5.054105,-199.452591,0.506564,0.000000
31.310001,0.118414,-199.319138,0.020881,0.020233,0.513918,0.526734,0.026833,5.139180,-199.319138,0.515219,0.000000
31.830002,0.096444,-199.185699,0.021290,0.020582,0.522772,0.429007,0.021855,5.227723,-199.185699,0.523891,0.000000
32.350002,0.164216,-199.096741,0.021562,0.020925,0.531488,0.730470,0.037212,5.314879,-199.096741,0.532546,0.000000
32.870003,0.143363,-199.096741,0.021928,0.021258,0.539943,0.637712,0.032487,5.399434,-199.096741,0.541218,0.000000
33.390003,0.105754,-199.007782,0.022243,0.021598,0.548598,0.470416,0.023964,5.485983,-199.007782,0.549873,0.000000
33.910000,0.158258,-198.963287,0.022588,0.021946,0.557435,0.703968,0.035862,5.574353,-198.963287,0.558545,0.000000
34.430000,0.178739,-198.696411,0.022967,0.022278,0.565865,0.795070,0.040503,5.658648,-198.696411,0.567200,0.000000
34.950001,0.159003,-198.607452,0.023312,0.022624,0.574641,0.707281,0.036031,5.746411,-198.607452,0.575855,0.000000
35.470001,0.117297,-198.651932,0.023692,0.022965,0.583305,0.521765,0.026580,5.833047,-198.651932,0.584527,0.000000
35.990002,0.160493,-198.473999,0.024007,0.023305,0.591951,0.713906,0.036368,5.919509,-198.473999,0.593182,0.000000
36.510002,0.140384,-198.473999,0.024399,0.023650,0.600719,0.624461,0.031812,6.007186,-198.473999,0.601855,0.000000
37.030003,0.153417,-198.385040,0.024770,0.023993,0.609417,0.682435,0.034765,6.094169,-198.385040,0.610510,0.000000
37.550003,0.143363,-198.251602,0.025123,0.024328,0.617924,0.637712,0.032487,6.179244,-198.251602,0.619182,0.000000
38.070004,0.161610,-198.118149,0.025447,0.024665,0.626493,0.718876,0.036621,6.264925,-198.118149,0.627837,0.000000
38.590000,0.172036,-198.029190,0.025822,0.025017,0.635442,0.765255,0.038984,6.354423,-198.029190,0.636509,0.000000
39.110001,0.156024,-197.984711,0.026171,0.025357,0.644080,0.694030,0.035356,6.440799,-197.984711,0.645164,0.000000
39.630001,0.153417,-197.895752,0.026494,0.025691,0.652561,0.682435,0.034765,6.525614,-197.895752,0.653836,0.000000
40.150002,0.179484,-197.806793,0.026861,0.026040,0.661424,0.798383,0.040672,6.614244,-197.806793,0.662491,0.000000
40.670002,0.196240,-197.628860,0.027214,0.026378,0.670010,0.872920,0.044469,6.700099,-197.628860,0.671163,0.000000
41.190002,0.170919,-197.539902,0.027551,0.026718,0.678648,0.760286,0.038731,6.786475,-197.539902,0.679818,0.000000
41.710003,0.129958,-197.495422,0.027900,0.027056,0.687216,0.578082,0.029449,6.872157,-197.495422,0.688491,0.000000
42.230003,0.190282,-197.450943,0.028258,0.027405,0.696096,0.846418,0.043119,6.960961,-197.450943,0.697145,0.000000
42.750004,0.189910,-197.361984,0.028616,0.027738,0.704543,0.844762,0.043034,7.045428,-197.361984,0.705818,0.000000
43.270000,0.170919,-197.228531,0.028969,0.028087,0.713397,0.760286,0.038731,7.133972,-197.228531,0.714473,0.000000
43.790001,0.164216,-197.095093,0.029310,0.028423,0.721939,0.730470,0.037212,7.219394,-197.095093,0.723127,0.000000
44.310001,0.208901,-197.006134,0.029612,0.028763,0.730586,0.929238,0.047338,7.305856,-197.006134,0.731800,0.000000
44.830002,0.203315,-196.917175,0.029952,0.029107,0.739327,0.904392,0.046072,7.393272,-196.917175,0.740455,0.000000
45.350002,0.181718,-196.783722,0.030353,0.029452,0.748086,0.808321,0.041178,7.480863,-196.783722,0.749127,0.000000
45.870003,0.177249,-196.650284,0.030707,0.029785,0.756542,0.788444,0.040165,7.565417,-196.650284,0.757782,0.000000
46.390003,0.212625,-196.605804,0.031060,0.030128,0.765257,0.945802,0.048181,7.652573,-196.605804,0.766454,0.000000
46.910004,0.188420,-196.472366,0.031388,0.030477,0.774120,0.838136,0.042697,7.741204,-196.472366,0.775109,0.000000
47.430004,0.219700,-196.427887,0.031720,0.030814,0.782671,0.977273,0.049785,7.826712,-196.427887,0.783781,0.000000
47.950001,0.194006,-196.294434,0.032022,0.031148,0.791170,0.862982,0.043962,7.911700,-196.294434,0.792436,0.000000
48.470001,0.197357,-196.205475,0.032354,0.031491,0.799877,0.877890,0.044722,7.998770,-196.205475,0.801108,0.000000
48.990002,0.246511,-196.072037,0.032720,0.031826,0.808376,1.096534,0.055860,8.083757,-196.072037,0.809763,0.000000
49.510002,0.228637,-195.983063,0.033074,0.032174,0.817230,1.017027,0.051810,8.172301,-195.983063,0.818436,0.000000
50.030003,0.194751,-195.894104,0.033436,0.032516,0.825911,0.866295,0.044131,8.259110,-195.894104,0.827091,0.000000
50.550003,0.177249,-195.805145,0.033789,0.032855,0.834523,0.788444,0.040165,8.345226,-195.805145,0.835763,0.000000
51.070004,0.225285,-195.671707,0.034199,0.033196,0.843186,1.002119,0.051050,8.431862,-195.671707,0.844418,0.000000
51.590004,0.229381,-195.538254,0.034553,0.033541,0.851937,1.020340,0.051979,8.519365,-195.538254,0.853090,0.000000
52.110001,0.204060,-195.449295,0.034897,0.033883,0.860626,0.907705,0.046241,8.606260,-195.449295,0.861745,0.000000
52.630001,0.209646,-195.271378,0.035268,0.034217,0.869108,0.932551,0.047506,8.691076,-195.271378,0.870400,0.000000
53.150002,0.209646,-195.315857,0.035600,0.034567,0.877997,0.932551,0.047506,8.779966,-195.315857,0.879072,0.000000
53.670002,0.221562,-195.182419,0.035954,0.034910,0.886721,0.985555,0.050207,8.867210,-195.182419,0.887727,0.000000
54.190002,0.210390,-195.004486,0.036307,0.035244,0.895185,0.935863,0.047675,8.951850,-195.004486,0.896399,0.000000
54.710003,0.172036,-194.915527,0.036665,0.035582,0.903779,0.765255,0.038984,9.037793,-194.915527,0.905054,0.000000
55.230003,0.210390,-194.782089,0.037014,0.035932,0.912668,0.935863,0.047675,9.126684,-194.782089,0.913726,0.000000
55.750004,0.228264,-194.737610,0.037342,0.036264,0.921098,1.015370,0.051725,9.210978,-194.737610,0.922381,0.000000
56.270004,0.221189,-194.648636,0.037704,0.036609,0.929865,0.983899,0.050122,9.298655,-194.648636,0.931053,0.000000
56.790001,0.184697,-194.515198,0.038079,0.036951,0.938555,0.821572,0.041853,9.385550,-194.515198,0.939708,0.000000
57.310001,0.228637,-194.381760,0.038459,0.037289,0.947149,1.017027,0.051810,9.471492,-194.381760,0.948381,0.000000
57.830002,0.205177,-194.248306,0.038817,0.037636,0.955960,0.912674,0.046494,9.559602,-194.248306,0.957036,0.000000
58.350002,0.200709,-194.159348,0.039153,0.037978,0.964650,0.892797,0.045481,9.646500,-194.159348,0.965708,0.000000
58.870003,0.192144,-194.114868,0.039502,0.038312,0.973131,0.854700,0.043541,9.731313,-194.114868,0.974363,0.000000
59.390003,0.223423,-193.981430,0.039877,0.038649,0.981682,0.993837,0.050628,9.816821,-193.981430,0.983035,0.000000
59.910004,0.224168,-193.803497,0.040218,0.039000,0.990606,0.997150,0.050797,9.906060,-193.803497,0.991690,0.000000
60.430004,0.217093,-193.714539,0.040563,0.039343,0.999321,0.965679,0.049194,9.993215,-193.714539,1.000362,0.000000
60.950005,0.200709,-193.625580,0.040908,0.039674,1.007708,0.892797,0.045481,10.077077,-193.625580,1.009017,0.000000
61.470001,0.224168,-193.536621,0.041248,0.040024,1.016614,0.997150,0.050797,10.166141,-193.536621,1.017689,0.000000
61.990002,0.234967,-193.447662,0.041602,0.040363,1.025217,1.045186,0.053244,10.252170,-193.447662,1.026344,0.000000
62.510002,0.211135,-193.269730,0.041964,0.040702,1.033828,0.939176,0.047844,10.338285,-193.269730,1.034999,0.000000
63.030003,0.186186,-193.180771,0.042287,0.041040,1.042423,0.828198,0.042190,10.424227,-193.180771,1.043671,0.000000
63.550003,0.240553,-192.958359,0.042641,0.041387,1.051225,1.070031,0.054510,10.512251,-192.958359,1.052326,0.000000
64.070000,0.234967,-192.913879,0.042994,0.041720,1.059689,1.045186,0.053244,10.596892,-192.913879,1.060999,0.000000
64.590004,0.210018,-192.824921,0.043348,0.042070,1.068570,0.934207,0.047591,10.685696,-192.824921,1.069654,0.000000
65.110001,0.222679,-192.735962,0.043684,0.042406,1.077112,0.990524,0.050460,10.771116,-192.735962,1.078326,0.000000
65.630005,0.259916,-192.602524,0.044064,0.042746,1.085758,1.156164,0.058898,10.857580,-192.602524,1.086981,0.000000
66.150002,0.230871,-192.469070,0.044430,0.043091,1.094517,1.026965,0.052316,10.945168,-192.469070,1.095653,0.000000
66.670006,0.214487,-192.335632,0.044797,0.043436,1.103285,0.954084,0.048603,11.032845,-192.335632,1.104308,0.000000
67.190002,0.213742,-192.202194,0.045155,0.043769,1.111731,0.950771,0.048435,11.117313,-192.202194,1.112980,0.000000
67.710007,0.230499,-192.157715,0.045517,0.044112,1.120456,1.025309,0.052232,11.204557,-192.157715,1.121635,0.000000
68.230003,0.220817,-191.979782,0.045870,0.044461,1.129319,0.982243,0.050038,11.293188,-191.979782,1.130307,0.000000
68.750000,0.244276,-191.846344,0.046215,0.044800,1.137913,1.086595,0.055354,11.379129,-191.846344,1.138962,0.000000
69.270004,0.206294,-191.757385,0.046569,0.045134,1.146394,0.917643,0.046747,11.463943,-191.757385,1.147634,0.000000
69.790001,0.199592,-191.623932,0.046922,0.045477,1.155110,0.887828,0.045228,11.551100,-191.623932,1.156289,0.000000
70.310005,0.252096,-191.446014,0.047233,0.045811,1.163600,1.121380,0.057126,11.636001,-191.446014,1.164962,0.000000
70.830002,0.247255,-191.357056,0.047591,0.046159,1.172437,1.099847,0.056029,11.724373,-191.357056,1.173617,0.000000
71.350006,0.222679,-191.312576,0.047953,0.046502,1.181144,0.990524,0.050460,11.811440,-191.312576,1.182271,0.000000
71.870003,0.208901,-191.090164,0.048319,0.046842,1.189799,0.929238,0.047338,11.897989,-191.090164,1.190944,0.000000
72.390007,0.233850,-191.001205,0.048677,0.047182,1.198411,1.040216,0.052991,11.984105,-191.001205,1.199599,0.000000
72.910004,0.244276,-190.912247,0.049044,0.047526,1.207152,1.086595,0.055354,12.071521,-190.912247,1.208271,0.000000
73.430000,0.222679,-190.734314,0.049401,0.047869,1.215876,0.990524,0.050460,12.158765,-190.734314,1.216926,0.000000
73.950005,0.218955,-190.600876,0.049746,0.048201,1.224297,0.973961,0.049616,12.242973,-190.600876,1.225598,0.000000
74.470001,0.225658,-190.467438,0.050108,0.048549,1.233152,1.003776,0.051135,12.331517,-190.467438,1.234253,0.000000
74.990005,0.234222,-190.333984,0.050449,0.048893,1.241885,1.041873,0.053076,12.418846,-190.333984,1.242925,0.000000
75.510002,0.236084,-190.245026,0.050794,0.049227,1.250357,1.050155,0.053497,12.503574,-190.245026,1.251580,0.000000
76.030006,0.172408,-190.200546,0.051165,0.049563,1.258908,0.766911,0.039068,12.589083,-190.200546,1.260252,0.000000
76.550003,0.226775,-190.022629,0.051527,0.049915,1.267841,1.008745,0.051388,12.678407,-190.022629,1.268907,0.000000
77.070007,0.248372,-189.889175,0.051846,0.050248,1.276305,1.104816,0.056282,12.763048,-189.889175,1.277580,0.000000
77.590004,0.223423,-189.711258,0.052187,0.050593,1.285064,0.993837,0.050628,12.850638,-189.711258,1.286234,0.000000
78.110001,0.200709,-189.577820,0.052553,0.050934,1.293736,0.892797,0.045481,12.937360,-189.577820,1.294907,0.000000
78.630005,0.253213,-189.488846,0.052885,0.051273,1.302339,1.126349,0.057379,13.023388,-189.488846,1.303562,0.000000
79.150002,0.236829,-189.399887,0.053260,0.051619,1.311124,1.053468,0.053666,13.111239,-189.399887,1.312234,0.000000
79.670006,0.223051,-189.177490,0.053609,0.051962,1.319822,0.992181,0.050544,13.198222,-189.177490,1.320889,0.000000
80.190002,0.221562,-189.044037,0.053963,0.052296,1.328312,0.985555,0.050207,13.283123,-189.044037,1.329544,0.000000
80.710007,0.241297,-188.910599,0.054299,0.052633,1.336881,1.073344,0.054679,13.368805,-188.910599,1.338216,0.000000
81.230003,0.242787,-188.866119,0.054657,0.052986,1.345839,1.079970,0.055016,13.458390,-188.866119,1.346871,0.000000
81.750008,0.232360,-188.732681,0.054993,0.053327,1.354503,1.033591,0.052654,13.545026,-188.732681,1.355543,0.000000
82.270004,0.220817,-188.599228,0.055334,0.053659,1.362932,0.982243,0.050038,13.629320,-188.599228,1.364198,0.000000
82.790001,0.250234,-188.376831,0.055692,0.054008,1.371804,1.113098,0.056704,13.718038,-188.376831,1.372870,0.000000
83.310005,0.272577,-188.243378,0.056011,0.054347,1.380415,1.212481,0.061767,13.804152,-188.243378,1.381525,0.000000
83.830002,0.244276,-188.109940,0.056360,0.054687,1.389053,1.086595,0.055354,13.890529,-188.109940,1.390198,0.000000
84.350006,0.206667,-188.065460,0.056701,0.055024,1.397612,0.919299,0.046831,13.976124,-188.065460,1.398852,0.000000
84.870003,0.247255,-187.887543,0.057059,0.055372,1.406441,1.099847,0.056029,14.064406,-187.887543,1.407525,0.000000
85.390007,0.272204,-187.754089,0.057369,0.055706,1.414931,1.210825,0.061682,14.149307,-187.754089,1.416180,0.000000
85.910004,0.242787,-187.576172,0.057688,0.056055,1.423802,1.079970,0.055016,14.238026,-187.576172,1.424852,0.000000
86.430000,0.248000,-187.487213,0.057986,0.056390,1.432301,1.103159,0.056198,14.323013,-187.487213,1.433507,0.000000
86.950005,0.291940,-187.353760,0.058313,0.056730,1.440930,1.298614,0.066155,14.409304,-187.353760,1.442179,0.000000
87.470001,0.276673,-187.220322,0.058654,0.057075,1.449715,1.230702,0.062695,14.497152,-187.220322,1.450834,0.000000
87.990005,0.281141,-187.086884,0.058994,0.057421,1.458483,1.250579,0.063708,14.584829,-187.086884,1.459506,0.000000
88.510002,0.258799,-186.864471,0.059318,0.057752,1.466912,1.151195,0.058645,14.669123,-186.864471,1.468161,0.000000
89.030006,0.292685,-186.775513,0.059663,0.058095,1.475619,1.301927,0.066323,14.756192,-186.775513,1.476833,0.000000
89.550003,0.296409,-186.686554,0.059995,0.058443,1.484448,1.318491,0.067167,14.844478,-186.686554,1.485488,0.000000
90.070007,0.302739,-186.553116,0.060348,0.058779,1.492990,1.346650,0.068602,14.929898,-186.553116,1.494143,0.000000
90.590004,0.265874,-186.375183,0.060693,0.059116,1.501558,1.182666,0.060248,15.015579,-186.375183,1.502815,0.000000
91.110001,0.261778,-186.241745,0.061034,0.059459,1.510256,1.164446,0.059320,15.102564,-186.241745,1.511470,0.000000
91.630005,0.308697,-186.063812,0.061379,0.059794,1.518755,1.373152,0.069952,15.187551,-186.063812,1.520143,0.000000
92.150002,0.310186,-185.974854,0.061732,0.060142,1.527601,1.379777,0.070289,15.276009,-185.974854,1.528798,0.000000
92.670006,0.281141,-185.841415,0.062094,0.060484,1.536299,1.250579,0.063708,15.362990,-185.841415,1.537470,0.000000
93.190002,0.279652,-185.707977,0.062431,0.060824,1.544937,1.243953,0.063370,15.449366,-185.707977,1.546125,0.000000
93.710007,0.294919,-185.574524,0.062819,0.061166,1.553609,1.311865,0.066830,15.536089,-185.574524,1.554797,0.000000
94.230003,0.306835,-185.396606,0.063177,0.061509,1.562333,1.364870,0.069530,15.623331,-185.396606,1.563452,0.000000
94.750008,0.289706,-185.218674,0.063500,0.061852,1.571049,1.288676,0.065648,15.710487,-185.218674,1.572124,0.000000
95.270004,0.291195,-185.085236,0.063867,0.062186,1.579513,1.295301,0.065986,15.795130,-185.085236,1.580779,0.000000
95.790001,0.294547,-184.996277,0.064220,0.062533,1.588350,1.310209,0.066745,15.883499,-184.996277,1.589451,0.000000
96.310005,0.300132,-184.773865,0.064565,0.062877,1.597074,1.335055,0.068011,15.970743,-184.773865,1.598106,0.000000
96.830002,0.297898,-184.684906,0.064940,0.063212,1.605573,1.325117,0.067505,16.055731,-184.684906,1.606779,0.000000
97.350006,0.240553,-184.506989,0.065289,0.063546,1.614081,1.070031,0.054510,16.140806,-184.506989,1.615433,0.000000
97.870003,0.291568,-184.329056,0.065647,0.063900,1.623048,1.296958,0.066070,16.230478,-184.329056,1.624106,0.000000
98.390007,0.313538,-184.195618,0.065996,0.064232,1.631494,1.394685,0.071049,16.314945,-184.195618,1.632761,0.000000
98.910004,0.287844,-184.106659,0.066324,0.064577,1.640253,1.280394,0.065226,16.402534,-184.106659,1.641415,0.000000
99.430008,0.267736,-183.928726,0.066682,0.064919,1.648952,1.190948,0.060670,16.489517,-183.928726,1.650088,0.000000
99.950005,0.305718,-183.795288,0.067048,0.065258,1.657546,1.359901,0.069277,16.575459,-183.795288,1.658743,0.000000
100.470001,0.284120,-183.617371,0.067411,0.065604,1.666348,1.263830,0.064383,16.663483,-183.617371,1.667415,0.000000
100.990005,0.274811,-183.528397,0.067747,0.065946,1.675029,1.222420,0.062273,16.750292,-183.528397,1.676070,0.000000
101.510002,0.281886,-183.483917,0.068079,0.066281,1.683528,1.253891,0.063876,16.835279,-183.483917,1.684742,0.000000
102.030006,0.299760,-183.217041,0.068445,0.066618,1.692105,1.333398,0.067927,16.921049,-183.217041,1.693397,0.000000
102.550003,0.308697,-183.039108,0.068790,0.066968,1.700985,1.373152,0.069952,17.009851,-183.039108,1.702069,0.000000
103.070007,0.287099,-182.861191,0.069135,0.067311,1.709692,1.277081,0.065058,17.096922,-182.861191,1.710724,0.000000
103.590004,0.293057,-182.727753,0.069476,0.067645,1.718182,1.303583,0.066408,17.181824,-182.727753,1.719396,0.000000
104.110008,0.306835,-182.638779,0.069821,0.067993,1.727011,1.364870,0.069530,17.270107,-182.638779,1.728051,0.000000
104.630005,0.318751,-182.460861,0.070170,0.068329,1.735544,1.417874,0.072230,17.355440,-182.460861,1.736724,0.000000
105.150002,0.301249,-182.327423,0.070523,0.068672,1.744260,1.340024,0.068264,17.442598,-182.327423,1.745378,0.000000
105.670006,0.255448,-182.193970,0.070873,0.069007,1.752785,1.136287,0.057885,17.527847,-182.193970,1.754051,0.000000
106.190002,0.330667,-181.971573,0.071200,0.069354,1.761604,1.470879,0.074930,17.616043,-181.971573,1.762706,0.000000
106.710007,0.340721,-181.838135,0.071558,0.069691,1.770146,1.515602,0.077208,17.701466,-181.838135,1.771378,0.000000
107.230003,0.303856,-181.704681,0.071890,0.070040,1.779018,1.351619,0.068855,17.790182,-181.704681,1.780033,0.000000
107.750008,0.283748,-181.526764,0.072248,0.070374,1.787491,1.262174,0.064298,17.874910,-181.526764,1.788688,0.000000
108.270004,0.345562,-181.393326,0.072602,0.070715,1.796163,1.537135,0.078305,17.961632,-181.393326,1.797360,0.000000
108.790009,0.321357,-181.215393,0.072955,0.071060,1.804931,1.429469,0.072821,18.049309,-181.215393,1.806015,0.000000
109.310005,0.312421,-181.081955,0.073291,0.071405,1.813681,1.389716,0.070796,18.136812,-181.081955,1.814687,0.000000
109.830002,0.316144,-180.992996,0.073628,0.071737,1.822128,1.406280,0.071639,18.221279,-180.992996,1.823342,0.000000
110.350006,0.329550,-180.815063,0.073968,0.072081,1.830852,1.465910,0.074677,18.308523,-180.815063,1.832014,0.000000
110.870003,0.323964,-180.637146,0.074292,0.072428,1.839672,1.441064,0.073411,18.396721,-180.637146,1.840669,0.000000
111.390007,0.345562,-180.370255,0.074628,0.072764,1.848205,1.537135,0.078305,18.482054,-180.370255,1.849342,0.000000
111.910004,0.321357,-180.236816,0.074960,0.073101,1.856756,1.429469,0.072821,18.567562,-180.236816,1.857996,0.000000
112.430008,0.301994,-180.192337,0.075322,0.073443,1.865455,1.343337,0.068433,18.654545,-180.192337,1.866669,0.000000
112.950005,0.361201,-179.969925,0.075667,0.073778,1.873953,1.606704,0.081849,18.739534,-179.969925,1.875324,0.000000
113.470009,0.376469,-179.836487,0.076029,0.074127,1.882825,1.674616,0.085309,18.828251,-179.836487,1.883996,0.000000
113.990005,0.583135,-179.658554,0.076297,-0.000000,-0.000000,2.593915,0.132140,-0.000000,-179.658554,0.000304,0.000000
114.510002,0.624841,-179.436157,0.076288,-0.000000,-0.000000,2.779432,0.141591,-0.000000,-179.436157,0.000503,0.000000
115.030006,0.703784,-179.258240,0.076288,0.000015,0.000390,3.130588,0.159480,0.003902,-179.258240,0.001370,0.000000
115.550003,0.815868,-179.213745,0.076305,0.000046,0.001171,3.629163,0.184878,0.011707,-179.213745,0.002229,0.000000
116.070007,0.987904,-178.991348,0.076340,0.000084,0.002125,4.394417,0.223862,0.021247,-178.991348,0.003096,0.000000
116.590004,1.115256,-178.813431,0.076366,0.000111,0.002810,4.960905,0.252721,0.028097,-178.813431,0.003963,0.000000
117.110008,1.385970,-178.679977,0.076379,0.000146,0.003720,6.165104,0.314065,0.037204,-178.679977,0.004830,0.000000
117.630005,1.637322,-178.502060,0.076409,0.000184,0.004674,7.283171,0.371022,0.046743,-178.502060,0.005698,0.000000
118.150009,1.870427,-178.368607,0.076439,0.000218,0.005541,8.320074,0.423845,0.055415,-178.368607,0.006565,0.000000
118.670006,2.148589,-178.235168,0.076465,0.000251,0.006374,9.557402,0.486877,0.063741,-178.235168,0.007432,0.000000
119.190002,2.472553,-178.057251,0.076499,0.000285,0.007250,10.998466,0.560289,0.072500,-178.057251,0.008299,0.000000
119.710007,2.802848,-177.923798,0.076538,0.000322,0.008178,12.467689,0.635134,0.081778,-177.923798,0.009167,0.000000
120.230003,3.013238,-177.701401,0.076555,0.000350,0.008880,13.403552,0.682809,0.088803,-177.701401,0.010034,0.000000
120.750008,3.428061,-177.523483,0.076573,0.000387,0.009826,15.248777,0.776810,0.098256,-177.523483,0.010901,0.000000
121.270004,3.782560,-177.434509,0.076620,0.000420,0.010667,16.825666,0.857140,0.106668,-177.434509,0.011768,0.000000
121.790009,4.122163,-177.345551,0.076659,0.000455,0.011551,18.336298,0.934096,0.115515,-177.345551,0.012635,0.000000
122.310005,4.531773,-177.034180,0.076685,0.000490,0.012453,20.158331,1.026914,0.124533,-177.034180,0.013503,0.000000
122.830009,4.965214,-176.900742,0.076715,0.000524,0.013312,22.086376,1.125134,0.133119,-176.900742,0.014370,0.000000
123.350006,5.466428,-176.811783,0.076754,0.000563,0.014292,24.315886,1.238710,0.142918,-176.811783,0.015237,0.000000
123.870003,5.818320,-176.678345,0.076780,0.000598,0.015185,25.881180,1.318450,0.151852,-176.678345,0.016104,0.000000
124.390007,6.124783,-176.500412,0.076818,0.000629,0.015983,27.244394,1.387896,0.159829,-176.500412,0.016963,0.000000
124.910004,6.590992,-176.322495,0.076844,0.000661,0.016781,29.318199,1.493540,0.167807,-176.322495,0.017830,0.000000
125.430008,7.066140,-176.144562,0.076870,0.000698,0.017735,31.431759,1.601210,0.177347,-176.144562,0.018697,0.000000
125.950005,7.435534,-175.966644,0.076905,0.000735,0.018663,33.074905,1.684916,0.186627,-175.966644,0.019565,0.000000
126.470009,7.769551,-175.922165,0.076935,0.000769,0.019521,34.560692,1.760605,0.195212,-175.922165,0.020432,0.000000
126.990005,7.999305,-175.788712,0.076969,0.000793,0.020146,35.582687,1.812668,0.201457,-175.788712,0.021299,0.000000
127.510010,8.690429,-175.521835,0.076999,0.000837,0.021264,38.656960,1.969279,0.212643,-175.521835,0.022166,0.000000
128.029999,8.835653,-175.388397,0.077043,0.000869,0.022062,39.302948,2.002188,0.220622,-175.388397,0.023034,0.000000
128.550003,9.119774,-175.254944,0.077055,0.000900,0.022869,40.566780,2.066570,0.228687,-175.254944,0.023901,0.000000
129.070007,9.451930,-175.121506,0.077090,0.000930,0.023623,42.044285,2.141838,0.236232,-175.121506,0.024768,0.000000
129.590012,10.188855,-175.032547,0.077124,0.000974,0.024742,45.322292,2.308828,0.247419,-175.032547,0.025635,0.000000
130.110001,10.319185,-174.765656,0.077150,0.001004,0.025514,45.902027,2.338361,0.255138,-174.765656,0.026502,0.000000
130.630005,10.502765,-174.632217,0.077193,0.001035,0.026286,46.718632,2.379961,0.262855,-174.632217,0.027370,0.000000
131.150009,11.233732,-174.454285,0.077202,0.001075,0.027318,49.970135,2.545600,0.273177,-174.454285,0.028237,0.000000
131.670013,11.484339,-174.231888,0.077245,0.001109,0.028167,51.084888,2.602388,0.281674,-174.231888,0.029104,0.000000
132.190002,11.723029,-174.098450,0.077280,0.001141,0.028974,52.146637,2.656476,0.289739,-174.098450,0.029971,0.000000
132.710007,12.070826,-174.009476,0.077301,0.001174,0.029824,53.693714,2.735288,0.298238,-174.009476,0.030839,0.000000
133.230011,12.633108,-173.831558,0.077344,0.001217,0.030899,56.194870,2.862703,0.308993,-173.831558,0.031706,0.000000
133.750000,12.644651,-173.609146,0.077374,0.001245,0.031628,56.246220,2.865319,0.316277,-173.609146,0.032564,0.000000
134.270004,12.934730,-173.520187,0.077387,0.001279,0.032486,57.536552,2.931052,0.324863,-173.520187,0.033432,0.000000
134.790009,13.385300,-173.386749,0.077426,0.001313,0.033362,59.540787,3.033152,0.333621,-173.386749,0.034299,0.000000
135.310013,13.666441,-173.253311,0.077465,0.001350,0.034281,60.791367,3.096860,0.342815,-173.253311,0.035166,0.000000
135.830002,13.696231,-173.030899,0.077495,0.001376,0.034940,60.923878,3.103610,0.349404,-173.030899,0.036033,0.000000
136.350006,14.193721,-172.897461,0.077521,0.001413,0.035894,63.136822,3.216343,0.358944,-172.897461,0.036900,0.000000
136.870010,14.382886,-172.719528,0.077551,0.001442,0.036614,63.978271,3.259209,0.366143,-172.719528,0.037768,0.000000
137.389999,14.672964,-172.630569,0.077586,0.001480,0.037603,65.268600,3.324941,0.376029,-172.630569,0.038635,0.000000
137.910004,14.621576,-172.452652,0.077612,0.001507,0.038288,65.040016,3.313297,0.382880,-172.452652,0.039502,0.000000
138.430008,15.231523,-172.319199,0.077650,0.001546,0.039277,67.753197,3.451512,0.392766,-172.319199,0.040369,0.000000
138.950012,15.715607,-172.185760,0.077681,0.001582,0.040187,69.906509,3.561208,0.401873,-172.185760,0.041237,0.000000
139.470001,15.915943,-171.918869,0.077706,0.001617,0.041063,70.797653,3.606604,0.410631,-171.918869,0.042104,0.000000
139.990005,16.113300,-171.740952,0.077741,0.001649,0.041878,71.675537,3.651326,0.418783,-171.740952,0.042971,0.000000
140.510010,16.445457,-171.651993,0.077775,0.001685,0.042798,73.153046,3.726594,0.427975,-171.651993,0.043838,0.000000
141.030014,16.717661,-171.518555,0.077801,0.001720,0.043699,74.363869,3.788276,0.436995,-171.518555,0.044705,0.000000
141.550003,16.590311,-171.385101,0.077853,0.001748,0.044402,73.797386,3.759418,0.444019,-171.385101,0.045573,0.000000
142.070007,17.094875,-171.118225,0.077870,0.001786,0.045356,76.041801,3.873754,0.453559,-171.118225,0.046440,0.000000
142.590012,17.148870,-171.073730,0.077883,0.001818,0.046180,76.281982,3.885990,0.461797,-171.073730,0.047299,0.000000
143.110001,17.512678,-170.851334,0.077935,0.001855,0.047108,77.900284,3.968430,0.471078,-170.851334,0.048166,0.000000
143.630005,17.783764,-170.762375,0.077961,0.001889,0.047984,79.106133,4.029859,0.479836,-170.762375,0.049033,0.000000
144.150009,18.033627,-170.628922,0.077982,0.001922,0.048825,80.217575,4.086478,0.488248,-170.628922,0.049900,0.000000
144.670013,18.618996,-170.362045,0.078038,0.001962,0.049839,82.821426,4.219124,0.498395,-170.362045,0.050767,0.000000
145.190002,18.662563,-170.228607,0.078073,0.001997,0.050715,83.015228,4.228997,0.507153,-170.228607,0.051635,0.000000
145.710007,18.575800,-170.095154,0.078095,0.002027,0.051487,82.629288,4.209336,0.514872,-170.095154,0.052502,0.000000
146.230011,18.930672,-169.961716,0.078125,0.002061,0.052346,84.207832,4.289752,0.523457,-169.961716,0.053369,0.000000
146.750000,19.376774,-169.783783,0.078155,0.002097,0.053265,86.192192,4.390840,0.532650,-169.783783,0.054236,0.000000
147.270004,19.572641,-169.650345,0.078189,0.002133,0.054175,87.063454,4.435224,0.541755,-169.650345,0.055104,0.000000
147.790009,19.729784,-169.516907,0.078232,0.002168,0.055060,87.762459,4.470833,0.550602,-169.516907,0.055971,0.000000
148.310013,19.488485,-169.294495,0.078258,0.002193,0.055693,86.689110,4.416154,0.556932,-169.294495,0.056838,0.000000
148.830002,20.291321,-169.250015,0.078297,0.002235,0.056777,90.260300,4.598079,0.567772,-169.250015,0.057705,0.000000
149.350006,20.226528,-169.072098,0.078332,0.002267,0.057584,89.972092,4.583397,0.575838,-169.072098,0.058572,0.000000
149.870010,20.173651,-168.849686,0.078366,0.002298,0.058364,89.736877,4.571414,0.583642,-168.849686,0.059440,0.000000
150.390015,20.319620,-168.716248,0.078401,0.002329,0.059153,90.386185,4.604492,0.591534,-168.716248,0.060307,0.000000
150.910004,21.158949,-168.582809,0.078439,0.002371,0.060229,94.119705,4.794686,0.602288,-168.582809,0.061174,0.000000
151.430008,20.993988,-168.449356,0.078483,0.002402,0.061018,93.385925,4.757306,0.610180,-168.449356,0.062033,0.000000
151.950012,20.919886,-168.315918,0.078508,0.002433,0.061798,93.056297,4.740514,0.617984,-168.315918,0.062900,0.000000
152.470001,21.726072,-168.093521,0.078560,0.002474,0.062830,96.642395,4.923199,0.628304,-168.093521,0.063767,0.000000
152.990005,21.730541,-168.004547,0.078599,0.002507,0.063689,96.662277,4.924211,0.636890,-168.004547,0.064634,0.000000
153.510010,21.787514,-167.782150,0.078633,0.002539,0.064496,96.915703,4.937121,0.644956,-167.782150,0.065502,0.000000
154.030014,21.959549,-167.648712,0.078681,0.002573,0.065345,97.680954,4.976105,0.653455,-167.648712,0.066369,0.000000
154.550003,22.565399,-167.515259,0.078733,0.002614,0.066395,100.375908,5.113393,0.663948,-167.515259,0.067236,0.000000
155.070007,22.271225,-167.337341,0.078789,0.002644,0.067149,99.067360,5.046731,0.671493,-167.337341,0.068103,0.000000
155.590012,22.376980,-167.203888,0.078827,0.002677,0.068008,99.537781,5.070696,0.680077,-167.203888,0.068970,0.000000
156.110001,22.687538,-167.070450,0.078853,0.002712,0.068875,100.919212,5.141069,0.688751,-167.070450,0.069838,0.000000
156.630005,22.855850,-166.892532,0.078892,0.002746,0.069760,101.667900,5.179210,0.697596,-166.892532,0.070705,0.000000
157.150009,22.617531,-166.759079,0.078931,0.002773,0.070445,100.607803,5.125206,0.704447,-166.759079,0.071572,0.000000
157.670013,23.136246,-166.714600,0.078974,0.002811,0.071407,102.915161,5.242748,0.714073,-166.714600,0.072439,0.000000
158.190002,23.145555,-166.536682,0.079021,0.002840,0.072136,102.956573,5.244858,0.721357,-166.536682,0.073307,0.000000
158.710007,23.527611,-166.269791,0.079056,0.002879,0.073116,104.656036,5.331433,0.731158,-166.269791,0.074174,0.000000
159.230011,23.185772,-166.180832,0.079090,0.002906,0.073818,103.135468,5.253971,0.738183,-166.180832,0.075041,0.000000
159.750000,23.886578,-166.002914,0.079129,0.002943,0.074763,106.252808,5.412776,0.747634,-166.002914,0.075908,0.000000
160.270004,24.374384,-165.869461,0.079172,0.002981,0.075709,108.422676,5.523314,0.757087,-165.869461,0.076775,0.000000
160.790009,24.420187,-165.691544,0.079224,0.003015,0.076576,108.626419,5.533694,0.765760,-165.691544,0.077634,0.000000
161.310013,24.691647,-165.558105,0.079254,0.003047,0.077383,109.833931,5.595207,0.773826,-165.558105,0.078501,0.000000
161.830002,24.977255,-165.335693,0.079306,0.003083,0.078319,111.104378,5.659927,0.783191,-165.335693,0.079368,0.000000
162.350006,25.301964,-165.246735,0.079341,0.003119,0.079221,112.548759,5.733507,0.792211,-165.246735,0.080236,0.000000
162.870010,24.842457,-165.202255,0.079384,0.003146,0.079897,110.504768,5.629381,0.798974,-165.202255,0.081103,0.000000
163.390015,25.359682,-164.935364,0.079427,0.003184,0.080878,112.805496,5.746586,0.808775,-164.935364,0.081970,0.000000
163.910004,25.556295,-164.757446,0.079453,0.003217,0.081719,113.680077,5.791139,0.817187,-164.757446,0.082837,0.000000
164.430008,25.739874,-164.579514,0.079500,0.003251,0.082577,114.496681,5.832739,0.825771,-164.579514,0.083705,0.000000
164.950012,26.112991,-164.446075,0.079548,0.003287,0.083488,116.156387,5.917288,0.834878,-164.446075,0.084572,0.000000
165.470001,26.352427,-164.357117,0.079591,0.003320,0.084320,117.221451,5.971545,0.843203,-164.357117,0.085439,0.000000
165.990005,27.091587,-164.179184,0.079634,0.003359,0.085326,120.509399,6.139041,0.853263,-164.179184,0.086306,0.000000
166.510010,27.271442,-163.956787,0.079660,0.003394,0.086211,121.309433,6.179797,0.862108,-163.956787,0.087174,0.000000
167.030014,27.153400,-163.956787,0.079720,0.003425,0.087000,120.784355,6.153049,0.870000,-163.956787,0.088041,0.000000
167.550003,27.446457,-163.689896,0.079746,0.003458,0.087833,122.087936,6.219456,0.878327,-163.689896,0.088908,0.000000
168.070007,28.022890,-163.556458,0.079785,0.003492,0.088700,124.652039,6.350078,0.886998,-163.556458,0.089775,0.000000
168.590012,28.492079,-163.423019,0.079836,0.003531,0.089688,126.739098,6.456397,0.896884,-163.423019,0.090642,0.000000
169.110001,28.697256,-163.200607,0.079879,0.003565,0.090547,127.651772,6.502892,0.905470,-163.200607,0.091510,0.000000
169.630005,28.391911,-163.067169,0.079918,0.003590,0.091180,126.293526,6.433699,0.911800,-163.067169,0.092368,0.000000
170.150009,29.467323,-162.933731,0.079970,0.003630,0.092212,131.077194,6.677391,0.922122,-162.933731,0.093235,0.000000
170.670013,29.660583,-162.844757,0.080026,0.003664,0.093071,131.936859,6.721184,0.930706,-162.844757,0.094103,0.000000
171.190002,29.842302,-162.666840,0.080048,0.003696,0.093886,132.745193,6.762362,0.938858,-162.666840,0.094970,0.000000
171.710007,29.791286,-162.488907,0.080091,0.003725,0.094623,132.518265,6.750802,0.946229,-162.488907,0.095837,0.000000
172.230011,30.873774,-162.310989,0.080138,0.003768,0.095698,137.333405,6.996097,0.956984,-162.310989,0.096704,0.000000
172.750015,31.218218,-162.177551,0.080173,0.003800,0.096531,138.865570,7.074149,0.965309,-162.177551,0.097572,0.000000
173.270004,31.249498,-161.999619,0.080216,0.003828,0.097242,139.004715,7.081237,0.972419,-161.999619,0.098439,0.000000
173.790009,32.630997,-161.866180,0.080255,0.003871,0.098326,145.149918,7.394289,0.983261,-161.866180,0.099306,0.000000
174.310013,32.909904,-161.777222,0.080302,0.003905,0.099176,146.390564,7.457491,0.991760,-161.777222,0.100173,0.000000
174.830002,33.440536,-161.554810,0.080341,0.003937,0.100008,148.750931,7.577734,1.000085,-161.554810,0.101040,0.000000
175.350006,33.725029,-161.421371,0.080362,0.003970,0.100832,150.016418,7.642201,1.008322,-161.421371,0.101908,0.000000
175.870010,35.228668,-161.198959,0.080410,0.004011,0.101890,156.704941,7.982931,1.018903,-161.198959,0.102775,0.000000
176.390015,35.433846,-161.110001,0.080449,0.004042,0.102662,157.617615,8.029424,1.026623,-161.110001,0.103642,0.000000
176.910004,35.978256,-160.976562,0.080487,0.004075,0.103503,160.039276,8.152789,1.035034,-160.976562,0.104509,0.000000
177.430008,36.864128,-160.843124,0.080518,0.004110,0.104388,163.979828,8.353531,1.043880,-160.843124,0.105377,0.000000
177.950012,37.550041,-160.709671,0.080543,0.004144,0.105247,167.030930,8.508961,1.052466,-160.709671,0.106244,0.000000
178.470001,38.124611,-160.531754,0.080569,0.004172,0.105975,169.586746,8.639161,1.059750,-160.531754,0.107102,0.000000
178.990005,39.030220,-160.442795,0.080608,0.004205,0.106799,173.615097,8.844375,1.067988,-160.442795,0.107970,0.000000
179.510010,40.024826,-160.264862,0.080625,0.004238,0.107657,178.039322,9.069756,1.076574,-160.264862,0.108837,0.000000
180.030014,41.373932,-160.131424,0.080656,0.004275,0.108594,184.040436,9.375467,1.085939,-160.131424,0.109704,0.000000
180.550003,41.753380,-159.953506,0.080686,0.004302,0.109279,185.728302,9.461451,1.092790,-159.953506,0.110571,0.000000
181.070007,43.442089,-159.775574,0.080720,0.004341,0.110268,193.240067,9.844118,1.102678,-159.775574,0.111438,0.000000
181.590012,45.136013,-159.642136,0.080746,0.004378,0.111213,200.775009,10.227966,1.112131,-159.642136,0.112306,0.000000
182.110016,46.305634,-159.508698,0.080763,0.004413,0.112098,205.977753,10.493006,1.120976,-159.508698,0.113173,0.000000
182.630005,47.580635,-159.330765,0.080798,0.004445,0.112895,211.649231,10.781926,1.128955,-159.330765,0.114040,0.000000
183.150009,49.120396,-159.197327,0.080819,0.004481,0.113815,218.498428,11.130841,1.138146,-159.197327,0.114907,0.000000
183.670013,50.758091,-159.019394,0.080854,0.004517,0.114734,225.783264,11.501948,1.147340,-159.019394,0.115775,0.000000
184.190002,51.651783,-158.885956,0.080871,0.004544,0.115419,229.758606,11.704461,1.154190,-158.885956,0.116642,0.000000
184.710007,53.349060,-158.708038,0.080901,0.004581,0.116356,237.308472,12.089070,1.163556,-158.708038,0.117509,0.000000
185.230011,54.952122,-158.619064,0.080914,0.004615,0.117223,244.439240,12.452329,1.172229,-158.619064,0.118376,0.000000
185.750015,56.824039,-158.530106,0.080944,0.004650,0.118107,252.765945,12.876512,1.181075,-158.530106,0.119243,0.000000
186.270004,58.697445,-158.352188,0.080966,0.004686,0.119027,261.099274,13.301031,1.190266,-158.352188,0.120111,0.000000
186.790009,60.451691,-158.174255,0.080975,0.004720,0.119877,268.902557,13.698549,1.198765,-158.174255,0.120978,0.000000
187.310013,62.748112,-157.951859,0.081018,0.004758,0.120848,279.117554,14.218925,1.208479,-157.951859,0.121845,0.000000
187.830002,64.821854,-157.862900,0.081013,0.004793,0.121741,288.342010,14.688843,1.217412,-157.862900,0.122704,0.000000
188.350006,66.590622,-157.773926,0.081044,0.004824,0.122522,296.209869,15.089650,1.225216,-157.773926,0.123571,0.000000
188.870010,67.159233,-157.596008,0.081057,0.004835,0.122799,298.739197,15.218499,1.227992,-157.596008,0.123059,0.000000
189.390015,65.699158,-157.418091,0.081095,0.004831,0.122704,292.244446,14.887642,1.227036,-157.418091,0.122799,0.000000
189.910004,64.592842,-157.240158,0.081100,0.004828,0.122643,287.323303,14.636948,1.226431,-157.240158,0.122799,0.000000
190.430008,63.688351,-157.151199,0.081095,0.004828,0.122626,283.299927,14.431987,1.226257,-157.151199,0.122799,0.000000
190.950012,62.975258,-156.973282,0.081108,0.004827,0.122608,280.127930,14.270397,1.226083,-156.973282,0.122799,0.000000
191.470016,62.363079,-156.884308,0.081117,0.004827,0.122600,277.404816,14.131676,1.225997,-156.884308,0.122799,0.000000
191.990005,61.845108,-156.661911,0.081117,0.004827,0.122600,275.100769,14.014301,1.225997,-156.661911,0.122799,0.000000
192.510010,61.363258,-156.483978,0.081121,0.004826,0.122591,272.957397,13.905113,1.225910,-156.483978,0.122799,0.000000
193.030014,60.978226,-156.306061,0.081126,0.004826,0.122591,271.244690,13.817863,1.225910,-156.306061,0.122799,0.000000
193.550003,60.640858,-156.217102,0.081126,0.004826,0.122591,269.744019,13.741415,1.225910,-156.217102,0.122799,0.000000
194.070007,60.328808,-156.128143,0.081113,0.004826,0.122591,268.355927,13.670703,1.225910,-156.128143,0.122799,0.000000
194.590012,60.045803,-155.905731,0.081130,0.004826,0.122591,267.097076,13.606573,1.225910,-155.905731,0.122799,0.000000
195.110016,59.714020,-155.772293,0.081138,0.004826,0.122582,265.621216,13.531390,1.225823,-155.772293,0.122799,0.000000
195.630005,59.482777,-155.638855,0.081117,0.004826,0.122582,264.592590,13.478990,1.225823,-155.638855,0.122799,0.000000
196.150009,59.276482,-155.460922,0.081113,0.004826,0.122582,263.674957,13.432243,1.225823,-155.460922,0.122799,0.000000
196.670013,59.057529,-155.327484,0.081113,0.004826,0.122582,262.701019,13.382627,1.225823,-155.327484,0.122799,0.000000
197.190002,58.879536,-155.194031,0.081143,0.004826,0.122582,261.909241,13.342293,1.225823,-155.194031,0.122799,0.000000
197.710007,58.709358,-155.060593,0.081138,0.004826,0.122582,261.152283,13.303731,1.225823,-155.060593,0.122799,0.000000
198.230011,58.544025,-154.882675,0.081143,0.004826,0.122582,260.416840,13.266266,1.225823,-154.882675,0.122799,0.000000
198.750015,58.390980,-154.704742,0.081130,0.004826,0.122582,259.736053,13.231586,1.225823,-154.704742,0.122799,0.000000
199.270004,58.233467,-154.615784,0.081121,0.004826,0.122582,259.035400,13.195892,1.225823,-154.615784,0.122799,0.000000
199.790009,58.113194,-154.437866,0.081130,0.004826,0.122582,258.500397,13.168637,1.225823,-154.437866,0.122799,0.000000
200.310013,57.996265,-154.304413,0.081134,0.004826,0.122582,257.980286,13.142141,1.225823,-154.304413,0.122799,0.000000
200.830017,57.864819,-154.126495,0.081138,0.004826,0.122582,257.395569,13.112355,1.225823,-154.126495,0.122799,0.000000
201.350006,57.743427,-153.993057,0.081130,0.004826,0.122582,256.855591,13.084847,1.225823,-153.993057,0.122799,0.000000
201.870010,57.636555,-153.859604,0.081134,0.004826,0.122582,256.380188,13.060630,1.225823,-153.859604,0.122799,0.000000
202.390015,57.522236,-153.726166,0.081134,0.004826,0.122582,255.871689,13.034724,1.225823,-153.726166,0.122799,0.000000
202.910004,57.433613,-153.548248,0.081126,0.004826,0.122582,255.477463,13.014643,1.225823,-153.548248,0.122799,0.000000
203.430008,57.343498,-153.414795,0.081126,0.004826,0.122582,255.076614,12.994223,1.225823,-153.414795,0.122799,0.000000
203.950012,57.226944,-153.281357,0.081134,0.004826,0.122582,254.558167,12.967811,1.225823,-153.281357,0.122799,0.000000
204.470016,57.172581,-153.103439,0.081134,0.004826,0.122582,254.316345,12.955492,1.225823,-153.103439,0.122799,0.000000
204.990005,57.060493,-152.969986,0.081138,0.004826,0.122582,253.817749,12.930093,1.225823,-152.969986,0.122799,0.000000
205.510010,56.976337,-152.836548,0.081130,0.004826,0.122582,253.443405,12.911022,1.225823,-152.836548,0.122799,0.000000
206.030014,56.899258,-152.703110,0.081138,0.004826,0.122582,253.100540,12.893557,1.225823,-152.703110,0.122799,0.000000
206.550003,56.829998,-152.480698,0.081151,0.004826,0.122582,252.792450,12.877862,1.225823,-152.480698,0.122799,0.000000
207.070007,56.762596,-152.347260,0.081147,0.004826,0.122582,252.492645,12.862588,1.225823,-152.347260,0.122799,0.000000
207.590012,56.664291,-152.258301,0.081126,0.004826,0.122582,252.055359,12.840312,1.225823,-152.258301,0.122799,0.000000
208.110016,56.597637,-152.169327,0.081143,0.004826,0.122582,251.758865,12.825208,1.225823,-152.169327,0.122799,0.000000
208.630005,56.530983,-152.035889,0.081143,0.004826,0.122582,251.462372,12.810103,1.225823,-152.035889,0.122799,0.000000
209.150009,56.454643,-151.813492,0.081156,0.004826,0.122582,251.122803,12.792805,1.225823,-151.813492,0.122799,0.000000
209.670013,56.412193,-151.724518,0.081147,0.004826,0.122582,250.933975,12.783186,1.225823,-151.724518,0.122799,0.000000
210.190002,56.342560,-151.502121,0.081143,0.004826,0.122582,250.624222,12.767406,1.225823,-151.502121,0.122799,0.000000
210.710007,56.280746,-151.457642,0.081147,0.004826,0.122582,250.349258,12.753399,1.225823,-151.457642,0.122799,0.000000
211.230011,56.227127,-151.279709,0.081138,0.004826,0.122582,250.110748,12.741250,1.225823,-151.279709,0.122799,0.000000
211.750015,56.156746,-151.101791,0.081147,0.004826,0.122582,249.797684,12.725301,1.225823,-151.101791,0.122799,0.000000
212.270004,56.111691,-150.968353,0.081143,0.004826,0.122582,249.597260,12.715091,1.225823,-150.968353,0.122799,0.000000
212.790009,56.057697,-150.790421,0.081147,0.004826,0.122582,249.357086,12.702856,1.225823,-150.790421,0.122799,0.000000
213.310013,55.988434,-150.701462,0.081134,0.004826,0.122582,249.048996,12.687160,1.225823,-150.701462,0.122799,0.000000
213.830017,55.928112,-150.568024,0.081151,0.004826,0.122582,248.780670,12.673491,1.225823,-150.568024,0.122799,0.000000
214.350006,55.904278,-150.390091,0.081156,0.004826,0.122582,248.674652,12.668090,1.225823,-150.390091,0.122799,0.000000
214.870010,55.877468,-150.167694,0.081156,0.004826,0.122582,248.555389,12.662015,1.225823,-150.167694,0.122799,0.000000
215.390015,55.793312,-150.034241,0.081147,0.004826,0.122582,248.181046,12.642945,1.225823,-150.034241,0.122799,0.000000
215.910004,55.750862,-149.945282,0.081151,0.004826,0.122582,247.992218,12.633327,1.225823,-149.945282,0.122799,0.000000
216.430008,55.723679,-149.811844,0.081147,0.004826,0.122582,247.871307,12.627166,1.225823,-149.811844,0.122799,0.000000
216.950012,55.638405,-149.678406,0.081147,0.004826,0.122582,247.491989,12.607842,1.225823,-149.678406,0.122799,0.000000
217.470016,55.620903,-149.500473,0.081143,0.004826,0.122582,247.414139,12.603877,1.225823,-149.500473,0.122799,0.000000
217.990005,55.587017,-149.322556,0.081151,0.004826,0.122582,247.263397,12.596198,1.225823,-149.322556,0.122799,0.000000
218.510010,55.518871,-149.189117,0.081143,0.004826,0.122582,246.960266,12.580756,1.225823,-149.189117,0.122799,0.000000
219.030014,55.499508,-149.055664,0.081147,0.004826,0.122582,246.874146,12.576368,1.225823,-149.055664,0.122799,0.000000
219.200012,55.479774,-149.011185,0.081151,0.004826,0.122582,246.786362,12.571897,1.225823,-149.011185,0.122799,0.000000