File: Data/15% 30min RT - 1 - 3_07262023_145717.csv
Time (sec),S:Load (lbs),S:HL1 (DIM),S:LVDT (in),S:Position (in),Ch:Position (mm),Ch:Load (N),Ch:Stress (MPa),Ch:Strain (mm/mm),Ch:HL1 (DIM),Set Point (),Cycles ()
0.010000,0.003351,-116.940422,0.000017,-0.000000,-0.000000,0.014907,0.000759,-0.000000,-116.940422,0.000078,0.000000
0.350000,-0.000000,-116.940422,0.000000,-0.000000,-0.000000,-0.000000,-0.000000,-0.000000,-116.940422,0.000078,0.000000
0.690000,-0.020853,-116.851456,0.000013,0.000180,0.004562,-0.092758,-0.004725,0.045616,-116.851456,0.005316,0.000000
1.030000,0.031279,-116.762497,0.000073,0.000381,0.009678,0.139137,0.007088,0.096782,-116.762497,0.010970,0.000000
1.370000,0.042823,-116.762497,0.000293,0.000612,0.015549,0.190485,0.009704,0.155493,-116.762497,0.016642,0.000000
1.710000,0.017501,-116.673538,0.000504,0.000836,0.021238,0.077850,0.003966,0.212384,-116.673538,0.022314,0.000000
2.050000,0.052504,-116.629051,0.000703,0.001055,0.026806,0.233552,0.011898,0.268060,-116.629051,0.027968,0.000000
2.390000,0.062931,-116.540092,0.000961,0.001278,0.032469,0.279931,0.014260,0.324689,-116.540092,0.033640,0.000000
2.730000,0.045057,-116.451126,0.001173,0.001504,0.038210,0.200424,0.010210,0.382100,-116.451126,0.039294,0.000000
3.070000,-0.008192,-116.406647,0.001388,0.001725,0.043804,-0.036441,-0.001856,0.438035,-116.406647,0.044966,0.000000
3.410000,0.022342,-116.273209,0.001621,0.001949,0.049501,0.099384,0.005063,0.495013,-116.273209,0.050620,0.000000
3.750000,0.061814,-116.273209,0.001858,0.002167,0.055034,0.274962,0.014007,0.550341,-116.273209,0.056292,0.000000
4.090000,0.053622,-116.273209,0.002091,0.002394,0.060810,0.238521,0.012151,0.608098,-116.273209,0.061963,0.000000
4.430000,0.056228,-116.139763,0.002324,0.002620,0.066542,0.250116,0.012741,0.665422,-116.139763,0.067618,0.000000
4.770000,0.046547,-116.139763,0.002531,0.002845,0.072257,0.207049,0.010548,0.722572,-116.139763,0.073289,0.000000
5.110000,0.037610,-116.006317,0.002759,0.003064,0.077825,0.167296,0.008522,0.778248,-116.006317,0.078944,0.000000
5.450000,0.037982,-115.961838,0.002966,0.003285,0.083444,0.168952,0.008607,0.834444,-115.961838,0.084615,0.000000
5.790000,0.053249,-115.872879,0.003199,0.003513,0.089229,0.236864,0.012066,0.892289,-115.872879,0.090270,0.000000
6.130000,0.081922,-115.828400,0.003410,0.003738,0.094935,0.364407,0.018564,0.949352,-115.828400,0.095941,0.000000
6.470000,0.082667,-115.828400,0.003609,0.003947,0.100251,0.367720,0.018733,1.002513,-115.828400,0.101613,0.000000
6.810000,0.055856,-115.650475,0.003859,0.004181,0.106209,0.248459,0.012657,1.062091,-115.650475,0.107267,0.000000
7.150001,0.030162,-115.605995,0.004061,0.004401,0.111777,0.134168,0.006835,1.117766,-115.605995,0.112939,0.000000
7.490000,0.059207,-115.561508,0.004281,0.004626,0.117509,0.263367,0.013417,1.175091,-115.561508,0.118593,0.000000
7.830000,0.073357,-115.472549,0.004488,0.004845,0.123051,0.326310,0.016623,1.230507,-115.472549,0.124265,0.000000
8.170000,0.071123,-115.517029,0.004700,0.005069,0.128757,0.316371,0.016117,1.287570,-115.517029,0.129919,0.000000
8.510000,0.079688,-115.339104,0.004928,0.005294,0.134463,0.354468,0.018057,1.344633,-115.339104,0.135591,0.000000
8.850000,0.081550,-115.250145,0.005148,0.005522,0.140265,0.362750,0.018479,1.402652,-115.250145,0.141262,0.000000
9.190001,0.085273,-115.205666,0.005368,0.005742,0.145859,0.379314,0.019323,1.458587,-115.205666,0.146917,0.000000
9.530001,0.087880,-115.116699,0.005575,0.005959,0.151357,0.390909,0.019914,1.513570,-115.116699,0.152588,0.000000
9.870001,0.037982,-115.072220,0.005790,0.006188,0.157176,0.168952,0.008607,1.571759,-115.072220,0.158243,0.000000
10.210000,0.087507,-114.983261,0.006015,0.006412,0.162865,0.389253,0.019829,1.628650,-114.983261,0.163914,0.000000
10.550000,0.113946,-114.894295,0.006204,0.006626,0.168311,0.506857,0.025821,1.683113,-114.894295,0.169586,0.000000
10.890000,0.110222,-114.894295,0.006407,0.006856,0.174130,0.490293,0.024977,1.741303,-114.894295,0.175240,0.000000
11.230000,0.099423,-114.805336,0.006618,0.007074,0.179672,0.442257,0.022530,1.796718,-114.805336,0.180912,0.000000
11.570001,0.089742,-114.805336,0.006825,0.007297,0.185343,0.399191,0.020336,1.853435,-114.805336,0.186566,0.000000
11.910001,0.094955,-114.671890,0.007036,0.007519,0.190989,0.422381,0.021517,1.909892,-114.671890,0.192238,0.000000
12.250001,0.119159,-114.538452,0.007252,0.007739,0.196583,0.530046,0.027002,1.965827,-114.538452,0.197892,0.000000
12.590000,0.106498,-114.582932,0.007480,0.007970,0.202436,0.473729,0.024133,2.024364,-114.582932,0.203564,0.000000
12.930000,0.116925,-114.449486,0.007700,0.008197,0.208195,0.520108,0.026496,2.081950,-114.449486,0.209236,0.000000
13.270000,0.128841,-114.449486,0.007929,0.008424,0.213962,0.573113,0.029196,2.139620,-114.449486,0.214890,0.000000
13.610001,0.125490,-114.405006,0.008149,0.008638,0.219408,0.558205,0.028436,2.194081,-114.405006,0.220562,0.000000
13.950001,0.063303,-114.227081,0.008369,0.008857,0.224967,0.281587,0.014345,2.249670,-114.227081,0.226216,0.000000
14.290001,0.122511,-114.227081,0.008593,0.009086,0.230795,0.544954,0.027761,2.307948,-114.227081,0.231887,0.000000
14.630001,0.145970,-114.093643,0.008808,0.009297,0.236137,0.649307,0.033077,2.361369,-114.093643,0.237542,0.000000
14.970000,0.132565,-114.049156,0.009046,0.009526,0.241956,0.589677,0.030040,2.419560,-114.049156,0.243213,0.000000
15.310000,0.114691,-114.004677,0.009270,0.009759,0.247879,0.510170,0.025989,2.478792,-114.004677,0.248885,0.000000
15.650001,0.077826,-113.871231,0.009503,0.009979,0.253455,0.346187,0.017636,2.534553,-113.871231,0.254539,0.000000
15.990001,0.093465,-113.871231,0.009718,0.010197,0.259006,0.415755,0.021180,2.590057,-113.871231,0.260211,0.000000
16.330000,0.165706,-113.737793,0.009968,0.010420,0.264660,0.737096,0.037549,2.646599,-113.737793,0.265865,0.000000
16.670000,0.118414,-113.648827,0.010188,0.010648,0.270453,0.526734,0.026833,2.704531,-113.648827,0.271537,0.000000
17.010000,0.118414,-113.648827,0.010417,0.010871,0.276125,0.526734,0.026833,2.761247,-113.648827,0.277209,0.000000
17.350000,0.153790,-113.470909,0.010637,0.011097,0.281857,0.684091,0.034849,2.818570,-113.470909,0.282863,0.000000
17.690001,0.151183,-113.515388,0.010865,0.011315,0.287399,0.672496,0.034259,2.873986,-113.515388,0.288535,0.000000
18.030001,0.118787,-113.381943,0.011106,0.011534,0.292966,0.528390,0.026917,2.929662,-113.381943,0.294189,0.000000
18.370001,0.070751,-113.337463,0.011352,0.011761,0.298742,0.314715,0.016032,2.987419,-113.337463,0.299861,0.000000
18.710001,0.133309,-113.292984,0.011594,0.011983,0.304362,0.592989,0.030208,3.043616,-113.292984,0.305515,0.000000
19.050001,0.134426,-113.159538,0.011818,0.012200,0.309868,0.597959,0.030461,3.098684,-113.159538,0.311187,0.000000
19.390001,0.123628,-113.115059,0.012081,0.012434,0.315835,0.549923,0.028014,3.158349,-113.115059,0.316858,0.000000
19.730001,0.099796,-112.981613,0.012314,0.012656,0.321455,0.443914,0.022614,3.214545,-112.981613,0.322513,0.000000
20.070002,0.106871,-112.981613,0.012551,0.012875,0.327013,0.475385,0.024217,3.270134,-112.981613,0.328184,0.000000
20.410002,0.122138,-112.937134,0.012788,0.013095,0.332616,0.543298,0.027677,3.326158,-112.937134,0.333839,0.000000
20.750002,0.124372,-112.803696,0.013021,0.013319,0.338313,0.553236,0.028183,3.383134,-112.803696,0.339510,0.000000
21.090000,0.086390,-112.714729,0.013249,0.013549,0.344141,0.384284,0.019576,3.441412,-112.714729,0.345164,0.000000
21.430000,0.122138,-112.625771,0.013495,0.013774,0.349856,0.543298,0.027677,3.498562,-112.625771,0.350836,0.000000
21.770000,0.124000,-112.581284,0.013728,0.013993,0.355432,0.551580,0.028099,3.554325,-112.581284,0.356508,0.000000
22.110001,0.107616,-112.536804,0.013948,0.014214,0.361026,0.478698,0.024386,3.610260,-112.536804,0.362162,0.000000
22.450001,0.056601,-112.403366,0.014194,0.014436,0.366663,0.251772,0.012826,3.666630,-112.403366,0.367834,0.000000
22.790001,0.126979,-112.358879,0.014422,0.014662,0.372413,0.564831,0.028774,3.724127,-112.358879,0.373488,0.000000
23.130001,0.129586,-112.314400,0.014663,0.014877,0.377868,0.576425,0.029365,3.778676,-112.314400,0.379160,0.000000
23.470001,0.121021,-112.180962,0.014879,0.015107,0.383730,0.538328,0.027424,3.837301,-112.180962,0.384814,0.000000
23.810001,0.094210,-112.180962,0.015095,0.015332,0.389436,0.419068,0.021348,3.894364,-112.180962,0.390486,0.000000
24.150002,0.127351,-112.003036,0.015323,0.015559,0.395195,0.566487,0.028858,3.951947,-112.003036,0.396157,0.000000
24.490002,0.118787,-112.003036,0.015539,0.015771,0.400580,0.528390,0.026917,4.005802,-112.003036,0.401812,0.000000
24.830002,0.126979,-111.914070,0.015793,0.016000,0.406391,0.564831,0.028774,4.063906,-111.914070,0.407483,0.000000
25.170002,0.104637,-111.825111,0.016035,0.016223,0.412062,0.465447,0.023711,4.120623,-111.825111,0.413138,0.000000
25.510002,0.138150,-111.736153,0.016241,0.016447,0.417743,0.614523,0.031305,4.177426,-111.736153,0.418809,0.000000
25.850000,0.139640,-111.602707,0.016479,0.016668,0.423380,0.621148,0.031643,4.233797,-111.602707,0.424481,0.000000
26.190001,0.125490,-111.602707,0.016703,0.016891,0.429025,0.558205,0.028436,4.290252,-111.602707,0.430135,0.000000
26.530001,0.079315,-111.558228,0.016936,0.017111,0.434627,0.352812,0.017973,4.346274,-111.558228,0.435807,0.000000
26.870001,0.103147,-111.424782,0.017160,0.017339,0.440412,0.458821,0.023373,4.404119,-111.424782,0.441461,0.000000
27.210001,0.132937,-111.380302,0.017371,0.017555,0.445893,0.591333,0.030124,4.458928,-111.380302,0.447133,0.000000
27.550001,0.133309,-111.246857,0.017613,0.017780,0.451608,0.592989,0.030208,4.516078,-111.246857,0.452787,0.000000
27.890001,0.125490,-111.202377,0.017850,0.018008,0.457392,0.558205,0.028436,4.573923,-111.202377,0.458459,0.000000
28.230001,0.119159,-111.202377,0.018078,0.018233,0.463116,0.530046,0.027002,4.631160,-111.202377,0.464130,0.000000
28.570002,0.112829,-111.024452,0.018294,0.018448,0.468571,0.501888,0.025567,4.685708,-111.024452,0.469785,0.000000
28.910002,0.113574,-110.979973,0.018509,0.018672,0.474268,0.505200,0.025736,4.742683,-110.979973,0.475456,0.000000
29.250002,0.112829,-110.891014,0.018751,0.018899,0.480035,0.501888,0.025567,4.800354,-110.891014,0.481111,0.000000
29.590002,0.140384,-110.802048,0.018975,0.019123,0.485724,0.624461,0.031812,4.857244,-110.802048,0.486783,0.000000
29.930002,0.145970,-110.713089,0.019195,0.019338,0.491197,0.649307,0.033077,4.911967,-110.713089,0.492437,0.000000
30.270002,0.136288,-110.624123,0.019436,0.019569,0.497059,0.606241,0.030883,4.970591,-110.624123,0.498108,0.000000
30.610001,0.097934,-110.579643,0.019656,0.019787,0.502592,0.435632,0.022192,5.025920,-110.579643,0.503780,0.000000
30.950001,0.088252,-110.490685,0.019876,0.020015,0.508385,0.392566,0.019998,5.083850,-110.490685,0.509434,0.000000
31.290001,0.137033,-110.401718,0.020100,0.020232,0.513892,0.609553,0.031052,5.138920,-110.401718,0.515106,0.000000
31.630001,0.139267,-110.312759,0.020329,0.020456,0.519590,0.619492,0.031558,5.195896,-110.312759,0.520760,0.000000
31.970001,0.135171,-110.268280,0.020557,0.020682,0.525313,0.601271,0.030630,5.253133,-110.268280,0.526432,0.000000
32.310001,0.121766,-110.179314,0.020782,0.020908,0.531063,0.541641,0.027593,5.310630,-110.179314,0.532086,0.000000
32.650002,0.137778,-110.134834,0.021001,0.021131,0.536717,0.612866,0.031221,5.367174,-110.134834,0.537758,0.000000
32.990002,0.126979,-110.001389,0.021213,0.021347,0.542207,0.564831,0.028774,5.422068,-110.001389,0.543430,0.000000
33.330002,0.124372,-109.956909,0.021450,0.021575,0.548000,0.553236,0.028183,5.480000,-109.956909,0.549084,0.000000
33.670002,0.124372,-109.823471,0.021674,0.021799,0.553698,0.553236,0.028183,5.536976,-109.823471,0.554756,0.000000
34.010002,0.166078,-109.778984,0.021881,0.022015,0.559178,0.738752,0.037634,5.591785,-109.778984,0.560410,0.000000
34.350002,0.167568,-109.645546,0.022118,0.022241,0.564911,0.745378,0.037971,5.649109,-109.645546,0.566082,0.000000
34.690002,0.146342,-109.512100,0.022329,0.022463,0.570556,0.650963,0.033162,5.705564,-109.512100,0.571753,0.000000
35.030003,0.103147,-109.601067,0.022541,0.022687,0.576245,0.458821,0.023373,5.762455,-109.601067,0.577407,0.000000
35.370003,0.145225,-109.423141,0.022791,0.022912,0.581960,0.645994,0.032909,5.819605,-109.423141,0.583079,0.000000
35.710003,0.159375,-109.378662,0.022993,0.023128,0.587459,0.708937,0.036115,5.874587,-109.378662,0.588734,0.000000
36.050003,0.151183,-109.289696,0.023226,0.023357,0.593269,0.672496,0.034259,5.932690,-109.289696,0.594405,0.000000
36.390003,0.166078,-109.156258,0.023455,0.023584,0.599028,0.738752,0.037634,5.990276,-109.156258,0.600060,0.000000
36.730003,0.150811,-109.200737,0.023679,0.023810,0.604777,0.670840,0.034174,6.047772,-109.200737,0.605731,0.000000
37.070004,0.167940,-108.978333,0.023890,0.024025,0.610232,0.747034,0.038056,6.102320,-108.978333,0.611403,0.000000
37.410004,0.120649,-108.889366,0.024106,0.024245,0.615817,0.536672,0.027339,6.158170,-108.889366,0.617057,0.000000
37.750000,0.152300,-108.889366,0.024364,0.024474,0.621645,0.677466,0.034512,6.216448,-108.889366,0.622729,0.000000
38.090000,0.204805,-108.755928,0.024550,0.024689,0.627100,0.911017,0.046409,6.270996,-108.755928,0.628383,0.000000
38.430000,0.206294,-108.711441,0.024796,0.024914,0.632806,0.917643,0.046747,6.328059,-108.711441,0.634055,0.000000
38.770000,0.215976,-108.578003,0.025011,0.025146,0.638720,0.960709,0.048941,6.387203,-108.578003,0.639709,0.000000
39.110001,0.587604,-108.489037,0.025244,0.000006,0.000147,2.613792,0.133153,0.001474,-108.489037,0.001240,0.000000
39.450001,0.637874,-108.400078,0.025274,0.000010,0.000252,2.837405,0.144544,0.002515,-108.400078,0.000494,0.000000
39.790001,0.638991,-108.355598,0.025270,0.000010,0.000252,2.842375,0.144797,0.002515,-108.355598,0.000702,0.000000
40.130001,0.617021,-108.311119,0.025287,0.000014,0.000364,2.744647,0.139819,0.003643,-108.311119,0.001266,0.000000
40.470001,0.777141,-108.177673,0.025283,0.000034,0.000876,3.456897,0.176103,0.008760,-108.177673,0.001830,0.000000
40.810001,0.941358,-108.133194,0.025270,0.000057,0.001448,4.187367,0.213315,0.014483,-108.133194,0.002402,0.000000
41.150002,1.024024,-108.044228,0.025287,0.000073,0.001856,4.555088,0.232047,0.018559,-108.044228,0.002966,0.000000
41.490002,1.235904,-107.910789,0.025317,0.000102,0.002602,5.497577,0.280060,0.026017,-107.910789,0.003530,0.000000
41.830002,1.375171,-107.955269,0.025326,0.000125,0.003165,6.117068,0.311618,0.031655,-107.955269,0.004102,0.000000
42.170002,1.479808,-107.777344,0.025352,0.000140,0.003556,6.582515,0.335329,0.035557,-107.777344,0.004666,0.000000
42.510002,1.751268,-107.688385,0.025356,0.000165,0.004189,7.790028,0.396843,0.041887,-107.688385,0.005238,0.000000
42.850002,1.966127,-107.599419,0.025382,0.000186,0.004718,8.745768,0.445531,0.047179,-107.599419,0.005802,0.000000
43.190002,2.176889,-107.554939,0.025395,0.000211,0.005360,9.683288,0.493290,0.053596,-107.554939,0.006365,0.000000
43.530003,2.411856,-107.510460,0.025408,0.000236,0.005993,10.728473,0.546534,0.059926,-107.510460,0.006938,0.000000
43.870003,2.505322,-107.332535,0.025438,0.000255,0.006478,11.144229,0.567714,0.064782,-107.332535,0.007502,0.000000
44.210003,2.690763,-107.332535,0.025455,0.000273,0.006947,11.969113,0.609736,0.069466,-107.332535,0.008065,0.000000
44.550003,3.040049,-107.243576,0.025464,0.000298,0.007562,13.522812,0.688885,0.075622,-107.243576,0.008638,0.000000
44.890003,3.275761,-107.110130,0.025503,0.000318,0.008065,14.571311,0.742298,0.080652,-107.110130,0.009201,0.000000
45.230003,3.620950,-107.154610,0.025511,0.000347,0.008811,16.106789,0.820519,0.088110,-107.154610,0.009765,0.000000
45.570004,3.783304,-106.932205,0.025537,0.000367,0.009331,16.828978,0.857309,0.093315,-106.932205,0.010337,0.000000
45.910004,4.036518,-106.887726,0.025554,0.000390,0.009912,17.955328,0.914688,0.099125,-106.887726,0.010901,0.000000
46.250004,4.327340,-106.843246,0.025567,0.000411,0.010433,19.248970,0.980589,0.104329,-106.843246,0.011465,0.000000
46.590004,4.539593,-106.709801,0.025597,0.000431,0.010944,20.193117,1.028686,0.109444,-106.709801,0.012037,0.000000
46.930004,4.782380,-106.665321,0.025602,0.000453,0.011499,21.273087,1.083703,0.114995,-106.665321,0.012601,0.000000
47.270000,5.136134,-106.576355,0.025636,0.000479,0.012159,22.846664,1.163864,0.121586,-106.576355,0.013165,0.000000
47.610001,5.365887,-106.531876,0.025641,0.000503,0.012774,23.868658,1.215927,0.127744,-106.531876,0.013737,0.000000
47.950001,5.606440,-106.398437,0.025671,0.000524,0.013303,24.938690,1.270437,0.133033,-106.398437,0.014301,0.000000
48.290001,5.795605,-106.309471,0.025679,0.000543,0.013780,25.780140,1.313303,0.137802,-106.309471,0.014864,0.000000
48.630001,6.087173,-106.264992,0.025701,0.000562,0.014275,27.077095,1.379373,0.142745,-106.264992,0.015437,0.000000
48.970001,6.266656,-106.176033,0.025714,0.000583,0.014804,27.875481,1.420045,0.148037,-106.176033,0.016000,0.000000
49.310001,6.707545,-105.998108,0.025727,0.000613,0.015558,29.836651,1.519951,0.155582,-105.998108,0.016564,0.000000
49.650002,6.915329,-105.998108,0.025761,0.000637,0.016191,30.760920,1.567036,0.161912,-105.998108,0.017136,0.000000
49.990002,7.086248,-105.909142,0.025783,0.000657,0.016694,31.521206,1.605767,0.166942,-105.909142,0.017700,0.000000
50.330002,7.342440,-105.864662,0.025791,0.000678,0.017223,32.660805,1.663821,0.172232,-105.864662,0.018273,0.000000
50.670002,7.332014,-105.731224,0.025817,0.000692,0.017579,32.614426,1.661458,0.175788,-105.731224,0.018836,0.000000
51.010002,7.719654,-105.642258,0.025817,0.000717,0.018203,34.338734,1.749299,0.182031,-105.642258,0.019400,0.000000
51.350002,8.223101,-105.642258,0.025860,0.000748,0.018992,36.578178,1.863381,0.189924,-105.642258,0.019972,0.000000
51.690002,8.329972,-105.508820,0.025891,0.000769,0.019539,37.053566,1.887599,0.195388,-105.508820,0.020536,0.000000
52.030003,8.483017,-105.464333,0.025895,0.000787,0.019998,37.734344,1.922279,0.199982,-105.464333,0.021100,0.000000
52.370003,8.751870,-105.419853,0.025934,0.000809,0.020545,38.930264,1.983202,0.205446,-105.419853,0.021672,0.000000
52.710003,8.962260,-105.286407,0.025942,0.000828,0.021039,39.866123,2.030877,0.210389,-105.286407,0.022236,0.000000
53.050003,9.380062,-105.241928,0.025955,0.000856,0.021733,41.724602,2.125553,0.217327,-105.241928,0.022799,0.000000
53.390003,9.703654,-105.064003,0.025990,0.000883,0.022435,43.164009,2.198879,0.224352,-105.064003,0.023372,0.000000
53.730003,9.676099,-105.019524,0.026003,0.000901,0.022886,43.041439,2.192636,0.228861,-105.019524,0.023935,0.000000
54.070004,10.026874,-104.930565,0.026033,0.000926,0.023519,44.601761,2.272122,0.235193,-104.930565,0.024499,0.000000
54.410004,10.030597,-104.797119,0.026055,0.000942,0.023918,44.618324,2.272966,0.239181,-104.797119,0.025072,0.000000
54.750004,10.408928,-104.797119,0.026076,0.000969,0.024621,46.301224,2.358697,0.246206,-104.797119,0.025635,0.000000
55.090004,10.709060,-104.619194,0.026089,0.000993,0.025210,47.636276,2.426708,0.252102,-104.619194,0.026199,0.000000
55.430004,10.865457,-104.574715,0.026106,0.001015,0.025774,48.331966,2.462148,0.257740,-104.574715,0.026771,0.000000
55.770004,11.093349,-104.530235,0.026145,0.001040,0.026416,49.345680,2.513789,0.264157,-104.530235,0.027335,0.000000
56.110004,11.214742,-104.441277,0.026154,0.001059,0.026893,49.885662,2.541297,0.268928,-104.441277,0.027899,0.000000
56.450005,11.428483,-104.396790,0.026188,0.001080,0.027422,50.836430,2.589731,0.274218,-104.396790,0.028471,0.000000
56.790001,11.883150,-104.263351,0.026201,0.001109,0.028159,52.858891,2.692760,0.281589,-104.263351,0.029035,0.000000
57.130001,11.839211,-104.218872,0.026253,0.001127,0.028619,52.663437,2.682803,0.286185,-104.218872,0.029598,0.000000
57.470001,12.009757,-104.174385,0.026261,0.001149,0.029191,53.422066,2.721450,0.291908,-104.174385,0.030171,0.000000
57.810001,12.237649,-103.996460,0.026283,0.001172,0.029781,54.435780,2.773091,0.297807,-103.996460,0.030734,0.000000
58.150002,12.294621,-104.040947,0.026305,0.001192,0.030266,54.689209,2.786001,0.302663,-104.040947,0.031298,0.000000
58.490002,12.744075,-103.818542,0.026326,0.001219,0.030960,56.688477,2.887849,0.309601,-103.818542,0.031871,0.000000
58.830002,12.834561,-103.863022,0.026365,0.001242,0.031541,57.090981,2.908353,0.315410,-103.863022,0.032434,0.000000
59.170002,12.912760,-103.818542,0.026386,0.001262,0.032061,57.438824,2.926073,0.320615,-103.818542,0.033007,0.000000
59.510002,12.951115,-103.640617,0.026399,0.001280,0.032512,57.609436,2.934765,0.325124,-103.640617,0.033570,0.000000
59.850002,13.167835,-103.596138,0.026421,0.001303,0.033093,58.573456,2.983874,0.330934,-103.596138,0.034134,0.000000
60.190002,13.395354,-103.462692,0.026451,0.001324,0.033631,59.585510,3.035431,0.336311,-103.462692,0.034707,0.000000
60.530003,13.644099,-103.418213,0.026490,0.001348,0.034238,60.691986,3.091797,0.342382,-103.418213,0.035270,0.000000
60.870003,13.952796,-103.329247,0.026524,0.001375,0.034915,62.065136,3.161749,0.349145,-103.329247,0.035834,0.000000
61.210003,13.765492,-103.284767,0.026529,0.001392,0.035348,61.231968,3.119305,0.353483,-103.284767,0.036406,0.000000
61.550003,13.792676,-103.195808,0.026542,0.001409,0.035791,61.352886,3.125465,0.357905,-103.195808,0.036970,0.000000
61.890003,13.915932,-103.062363,0.026568,0.001427,0.036250,61.901157,3.153395,0.362502,-103.062363,0.037534,0.000000
62.230003,14.499066,-103.062363,0.026602,0.001458,0.037031,64.495071,3.285535,0.370307,-103.062363,0.038106,0.000000
62.570004,14.311764,-102.973404,0.026632,0.001477,0.037508,63.661903,3.243092,0.375076,-102.973404,0.038670,0.000000
62.910004,14.718766,-102.884438,0.026658,0.001502,0.038158,65.472343,3.335320,0.381580,-102.884438,0.039233,0.000000
63.250004,14.807763,-102.795479,0.026684,0.001525,0.038730,65.868217,3.355487,0.387305,-102.795479,0.039806,0.000000
63.590004,14.646153,-102.706512,0.026714,0.001543,0.039199,65.149345,3.318866,0.391986,-102.706512,0.040369,0.000000
63.930004,14.965650,-102.662033,0.026723,0.001566,0.039771,66.570534,3.391265,0.397711,-102.662033,0.040933,0.000000
64.270004,15.021505,-102.528595,0.026762,0.001585,0.040265,66.818993,3.403922,0.402654,-102.528595,0.041506,0.000000
64.610001,15.440424,-102.439629,0.026779,0.001616,0.041037,68.682434,3.498850,0.410372,-102.439629,0.042069,0.000000
64.950005,15.550274,-102.306190,0.026826,0.001638,0.041610,69.171074,3.523742,0.416096,-102.306190,0.042633,0.000000
65.290001,15.338394,-102.217224,0.026856,0.001658,0.042104,68.228584,3.475730,0.421039,-102.217224,0.043205,0.000000
65.630005,15.661985,-102.217224,0.026856,0.001681,0.042694,69.667992,3.549057,0.426936,-102.217224,0.043769,0.000000
65.970001,15.535007,-102.172745,0.026904,0.001699,0.043145,69.103157,3.520283,0.431446,-102.172745,0.044333,0.000000
66.310005,15.675391,-102.039299,0.026917,0.001719,0.043674,69.727623,3.552094,0.436735,-102.039299,0.044905,0.000000
66.650002,16.156868,-102.039299,0.026956,0.001749,0.044437,71.869339,3.661199,0.444367,-102.039299,0.045469,0.000000
66.990005,15.946851,-101.905861,0.027003,0.001770,0.044948,70.935135,3.613608,0.449485,-101.905861,0.046041,0.000000
67.330002,16.155752,-101.905861,0.027025,0.001794,0.045573,71.864372,3.660946,0.455728,-101.905861,0.046605,0.000000
67.670006,16.296881,-101.727936,0.027063,0.001815,0.046110,72.492149,3.692926,0.461104,-101.727936,0.047168,0.000000
68.010002,16.142345,-101.683456,0.027068,0.001832,0.046535,71.804741,3.657908,0.465355,-101.683456,0.047741,0.000000
68.350006,16.379919,-101.638969,0.027098,0.001858,0.047194,72.861519,3.711743,0.471944,-101.638969,0.048305,0.000000
68.690002,16.703884,-101.461052,0.027141,0.001885,0.047888,74.302589,3.785154,0.478882,-101.461052,0.048868,0.000000
69.030006,16.668880,-101.461052,0.027154,0.001907,0.048443,74.146881,3.777222,0.484432,-101.461052,0.049441,0.000000
69.370003,16.775379,-101.416565,0.027210,0.001930,0.049033,74.620613,3.801355,0.490329,-101.416565,0.050004,0.000000
69.710007,16.316616,-101.283127,0.027232,0.001942,0.049319,72.579933,3.697398,0.493193,-101.283127,0.050568,0.000000
70.050003,16.897146,-101.194160,0.027249,0.001969,0.050013,75.162262,3.828948,0.500130,-101.194160,0.051140,0.000000
70.390007,17.360004,-101.060722,0.027309,0.001997,0.050733,77.221153,3.933833,0.507327,-101.060722,0.051704,0.000000
70.730003,17.243452,-101.105202,0.027313,0.002019,0.051270,76.702705,3.907422,0.512704,-101.105202,0.052268,0.000000
71.070000,17.178286,-100.971756,0.027361,0.002040,0.051825,76.412834,3.892655,0.518254,-100.971756,0.052840,0.000000
71.410004,17.432245,-100.838318,0.027378,0.002066,0.052467,77.542503,3.950203,0.524672,-100.838318,0.053404,0.000000
71.750000,17.140305,-100.793839,0.027426,0.002083,0.052910,76.243881,3.884048,0.529096,-100.793839,0.053967,0.000000
72.090004,17.015560,-100.704872,0.027434,0.002099,0.053317,75.688995,3.855781,0.533171,-100.704872,0.054540,0.000000
72.430000,17.925638,-100.660393,0.027469,0.002133,0.054167,79.737221,4.062008,0.541670,-100.660393,0.055104,0.000000
72.770004,17.702215,-100.526947,0.027507,0.002154,0.054705,78.743385,4.011379,0.547046,-100.526947,0.055667,0.000000
73.110001,17.568905,-100.482468,0.027520,0.002173,0.055199,78.150391,3.981171,0.551989,-100.482468,0.056240,0.000000
73.450005,17.474323,-100.393509,0.027568,0.002196,0.055771,77.729675,3.959738,0.557714,-100.393509,0.056803,0.000000
73.790001,17.479908,-100.304543,0.027594,0.002211,0.056153,77.754517,3.961004,0.561529,-100.304543,0.057367,0.000000
74.130005,17.481398,-100.260063,0.027607,0.002232,0.056699,77.761139,3.961341,0.566992,-100.260063,0.057939,0.000000
74.470001,18.225771,-100.082138,0.027645,0.002262,0.057462,81.072281,4.130019,0.574625,-100.082138,0.058503,0.000000
74.810005,18.324450,-100.082138,0.027658,0.002287,0.058095,81.511223,4.152380,0.580955,-100.082138,0.059067,0.000000
75.150002,18.169914,-99.993179,0.027702,0.002306,0.058573,80.823814,4.117362,0.585726,-99.993179,0.059639,0.000000
75.490005,18.419403,-99.948700,0.027723,0.002332,0.059223,81.933594,4.173896,0.592230,-99.948700,0.060203,0.000000
75.830002,18.208269,-99.859734,0.027736,0.002349,0.059665,80.994423,4.126053,0.596653,-99.859734,0.060775,0.000000
76.170006,18.994347,-99.770775,0.027796,0.002380,0.060446,84.491074,4.304181,0.604457,-99.770775,0.061339,0.000000
76.510002,18.755657,-99.681808,0.027796,0.002400,0.060949,83.429329,4.250093,0.609487,-99.681808,0.061903,0.000000
76.850006,18.773531,-99.637329,0.027844,0.002421,0.061495,83.508835,4.254143,0.614951,-99.637329,0.062475,0.000000
77.190002,18.945566,-99.459404,0.027874,0.002446,0.062128,84.274086,4.293127,0.621281,-99.459404,0.063039,0.000000
77.530006,18.758263,-99.459404,0.027870,0.002462,0.062544,83.440918,4.250683,0.625444,-99.459404,0.063602,0.000000
77.870003,19.237879,-99.370445,0.027921,0.002489,0.063230,85.574356,4.359365,0.632295,-99.370445,0.064175,0.000000
78.210007,19.511200,-99.325966,0.027926,0.002514,0.063863,86.790154,4.421301,0.638625,-99.325966,0.064739,0.000000
78.550003,19.363369,-99.192520,0.027952,0.002534,0.064366,86.132568,4.387803,0.643655,-99.192520,0.065302,0.000000
78.890007,19.361506,-99.059074,0.027986,0.002556,0.064921,86.124275,4.387380,0.649206,-99.059074,0.065875,0.000000
79.230003,19.698875,-99.103561,0.028021,0.002580,0.065536,87.624977,4.463829,0.655364,-99.103561,0.066438,0.000000
79.570007,19.621794,-98.970116,0.028025,0.002598,0.065996,87.282097,4.446362,0.659959,-98.970116,0.067002,0.000000
79.910004,20.054119,-98.925636,0.028038,0.002626,0.066690,89.205177,4.544328,0.666897,-98.925636,0.067574,0.000000
80.250000,20.033638,-98.836670,0.028072,0.002646,0.067210,89.114075,4.539688,0.672101,-98.836670,0.068138,0.000000
80.590004,20.071993,-98.792191,0.028098,0.002668,0.067774,89.284683,4.548378,0.677738,-98.792191,0.068702,0.000000
80.930000,19.721218,-98.703232,0.028111,0.002683,0.068138,87.724358,4.468892,0.681379,-98.703232,0.069274,0.000000
81.270004,20.349783,-98.569786,0.028128,0.002709,0.068815,90.520355,4.611327,0.688145,-98.569786,0.069838,0.000000
81.610001,20.435057,-98.525307,0.028137,0.002731,0.069361,90.899673,4.630650,0.693609,-98.525307,0.070402,0.000000
81.950005,20.902756,-98.436348,0.028171,0.002758,0.070046,92.980103,4.736632,0.700459,-98.436348,0.070974,0.000000
82.290001,20.862911,-98.302902,0.028184,0.002778,0.070566,92.802864,4.727603,0.705661,-98.302902,0.071538,0.000000
82.630005,20.707260,-98.258423,0.028210,0.002798,0.071069,92.110497,4.692332,0.710692,-98.258423,0.072101,0.000000
82.970001,20.760509,-98.213943,0.028236,0.002820,0.071616,92.347359,4.704399,0.716155,-98.213943,0.072674,0.000000
83.310005,21.221506,-98.080498,0.028288,0.002841,0.072171,94.397972,4.808862,0.721706,-98.080498,0.073237,0.000000
83.650002,21.286673,-97.991531,0.028309,0.002863,0.072717,94.687851,4.823629,0.727169,-97.991531,0.073810,0.000000
83.990005,21.355560,-97.947052,0.028322,0.002886,0.073307,94.994278,4.839239,0.733066,-97.947052,0.074373,0.000000
84.330002,21.295609,-97.902573,0.028335,0.002905,0.073792,94.727600,4.825654,0.737924,-97.902573,0.074937,0.000000
84.670006,21.417002,-97.769127,0.028335,0.002927,0.074356,95.267578,4.853162,0.743560,-97.769127,0.075509,0.000000
85.010002,21.638191,-97.724648,0.028361,0.002951,0.074954,96.251480,4.903284,0.749544,-97.724648,0.076073,0.000000
85.350006,21.666864,-97.680168,0.028378,0.002971,0.075457,96.379028,4.909781,0.754574,-97.680168,0.076637,0.000000
85.690002,21.857147,-97.546722,0.028387,0.002996,0.076090,97.225449,4.952900,0.760904,-97.546722,0.077209,0.000000
86.030006,22.028811,-97.502243,0.028430,0.003019,0.076680,97.989044,4.991799,0.766803,-97.502243,0.077773,0.000000
86.370003,22.278299,-97.368805,0.028434,0.003046,0.077357,99.098824,5.048335,0.773566,-97.368805,0.078337,0.000000
86.710007,21.899969,-97.368805,0.028443,0.003062,0.077764,97.415924,4.962604,0.777643,-97.368805,0.078909,0.000000
87.050003,22.216114,-97.279839,0.028473,0.003085,0.078363,98.822212,5.034244,0.783627,-97.279839,0.079473,0.000000
87.390007,22.273830,-97.190880,0.028529,0.003107,0.078909,99.078949,5.047322,0.789090,-97.190880,0.080036,0.000000
87.730003,22.300270,-97.190880,0.028529,0.003128,0.079447,99.196556,5.053314,0.794466,-97.190880,0.080609,0.000000
88.070007,22.963093,-97.012955,0.028529,0.003155,0.080132,102.144936,5.203511,0.801317,-97.012955,0.081172,0.000000
88.410004,22.896811,-96.968475,0.028547,0.003178,0.080713,101.850098,5.188491,0.807127,-96.968475,0.081736,0.000000
88.750008,22.768715,-96.923996,0.028577,0.003197,0.081207,101.280304,5.159465,0.812070,-96.923996,0.082308,0.000000
89.090004,22.893087,-96.746071,0.028581,0.003219,0.081771,101.833542,5.187648,0.817708,-96.746071,0.082872,0.000000
89.430008,23.196198,-96.746071,0.028594,0.003243,0.082360,103.181839,5.256334,0.823605,-96.746071,0.083436,0.000000
89.770004,23.698900,-96.612625,0.028667,0.003267,0.082985,105.417976,5.370248,0.829850,-96.612625,0.084008,0.000000
90.110001,23.795345,-96.568146,0.028659,0.003291,0.083592,105.846985,5.392102,0.835921,-96.568146,0.084572,0.000000
90.450005,23.873543,-96.523666,0.028654,0.003313,0.084147,106.194824,5.409822,0.841469,-96.523666,0.085136,0.000000
90.790001,23.791994,-96.390221,0.028676,0.003334,0.084685,105.832077,5.391343,0.846848,-96.390221,0.085708,0.000000
91.130005,23.468029,-96.390221,0.028685,0.003348,0.085032,104.391006,5.317932,0.850316,-96.390221,0.086272,0.000000
91.470001,24.042973,-96.167816,0.028697,0.003374,0.085691,106.948486,5.448215,0.856906,-96.167816,0.086835,0.000000
91.810005,24.655525,-96.167816,0.028710,0.003400,0.086367,109.673256,5.587022,0.863671,-96.167816,0.087408,0.000000
92.150002,24.836126,-96.123337,0.028736,0.003425,0.086991,110.476608,5.627947,0.869915,-96.123337,0.087971,0.000000
92.490005,24.859585,-95.989891,0.028745,0.003445,0.087494,110.580956,5.633263,0.874945,-95.989891,0.088544,0.000000
92.830002,25.173496,-95.989891,0.028762,0.003470,0.088136,111.977303,5.704396,0.881362,-95.989891,0.089108,0.000000
93.170006,24.785856,-95.767487,0.028779,0.003484,0.088500,110.252998,5.616556,0.885005,-95.767487,0.089671,0.000000
93.510002,24.940390,-95.811966,0.028797,0.003505,0.089021,110.940392,5.651573,0.890207,-95.811966,0.090244,0.000000
93.850006,26.024738,-95.678528,0.028822,0.003535,0.089793,115.763817,5.897290,0.897927,-95.678528,0.090807,0.000000
94.190002,26.248535,-95.634048,0.028822,0.003560,0.090417,116.759315,5.948003,0.904170,-95.634048,0.091371,0.000000
94.530006,25.870205,-95.545082,0.028861,0.003579,0.090894,115.076416,5.862272,0.908941,-95.545082,0.091943,0.000000
94.870003,26.166613,-95.456123,0.028874,0.003600,0.091440,116.394905,5.929440,0.914404,-95.456123,0.092507,0.000000
95.210007,26.384823,-95.456123,0.028866,0.003620,0.091952,117.365555,5.978886,0.919519,-95.456123,0.093071,0.000000
95.550003,26.824223,-95.322678,0.028900,0.003643,0.092542,119.320099,6.078455,0.925418,-95.322678,0.093643,0.000000
95.890007,27.298252,-95.189232,0.028935,0.003669,0.093184,121.428688,6.185872,0.931835,-95.189232,0.094207,0.000000
96.230003,27.631899,-95.189232,0.028930,0.003692,0.093765,122.912827,6.261478,0.937645,-95.189232,0.094771,0.000000
96.570007,27.884367,-95.055794,0.028960,0.003715,0.094354,124.035858,6.318687,0.943542,-95.055794,0.095343,0.000000
96.910004,27.944691,-95.055794,0.028956,0.003734,0.094831,124.304192,6.332357,0.948313,-95.055794,0.095907,0.000000
97.250008,27.873568,-94.877869,0.028991,0.003750,0.095256,123.987823,6.316241,0.952562,-94.877869,0.096470,0.000000
97.590004,29.190649,-94.922348,0.028986,0.003785,0.096141,129.846497,6.614696,0.961407,-94.922348,0.097043,0.000000
97.930008,29.140007,-94.877869,0.029012,0.003805,0.096652,129.621231,6.603220,0.966524,-94.877869,0.097606,0.000000
98.270004,29.426361,-94.699944,0.029029,0.003825,0.097155,130.894989,6.668109,0.971554,-94.699944,0.098170,0.000000
98.610008,29.676224,-94.655464,0.029042,0.003848,0.097745,132.006439,6.724728,0.977451,-94.655464,0.098742,0.000000
98.950005,29.853474,-94.522018,0.029073,0.003867,0.098213,132.794876,6.764894,0.982135,-94.522018,0.099306,0.000000
99.290001,30.824993,-94.477539,0.029077,0.003894,0.098899,137.116425,6.985043,0.988985,-94.477539,0.099870,0.000000
99.630005,31.446482,-94.433060,0.029094,0.003919,0.099540,139.880936,7.125875,0.995403,-94.433060,0.100442,0.000000
99.970001,31.672512,-94.344101,0.029111,0.003940,0.100087,140.886368,7.177094,1.000866,-94.344101,0.101006,0.000000
100.310005,32.135368,-94.210655,0.029133,0.003963,0.100668,142.945251,7.281979,1.006676,-94.210655,0.101578,0.000000
100.650002,32.493221,-94.166176,0.029167,0.003984,0.101188,144.537064,7.363069,1.011880,-94.166176,0.102142,0.000000
100.990005,32.735634,-94.121689,0.029159,0.004005,0.101726,145.615372,7.418001,1.017257,-94.121689,0.102706,0.000000
101.330002,33.771202,-94.032730,0.029172,0.004031,0.102393,150.221817,7.652664,1.023933,-94.032730,0.103278,0.000000
101.670006,34.052341,-93.899284,0.029189,0.004051,0.102896,151.472382,7.716371,1.028963,-93.899284,0.103842,0.000000
102.010002,34.542759,-93.899284,0.029215,0.004072,0.103434,153.653870,7.827501,1.034342,-93.899284,0.104405,0.000000
102.350006,34.564728,-93.765846,0.029223,0.004090,0.103876,153.751587,7.832479,1.038764,-93.765846,0.104978,0.000000
102.690002,35.713497,-93.721367,0.029232,0.004114,0.104501,158.861572,8.092794,1.045008,-93.721367,0.105541,0.000000
103.030006,36.325676,-93.676880,0.029232,0.004134,0.105004,161.584671,8.231516,1.050038,-93.676880,0.106105,0.000000
103.370003,37.782768,-93.587921,0.029267,0.004165,0.105784,168.066147,8.561697,1.057842,-93.587921,0.106677,0.000000
103.710007,37.919060,-93.498962,0.029288,0.004182,0.106226,168.672409,8.592582,1.062265,-93.498962,0.107241,0.000000
104.050003,38.463467,-93.409996,0.029301,0.004203,0.106747,171.094040,8.715946,1.067469,-93.409996,0.107805,0.000000
104.390007,39.004898,-93.321037,0.029305,0.004223,0.107259,173.502457,8.838636,1.072586,-93.321037,0.108377,0.000000
104.730003,40.098553,-93.232071,0.029305,0.004246,0.107857,178.367264,9.086462,1.078570,-93.232071,0.108941,0.000000
105.070007,40.635887,-93.187592,0.029349,0.004265,0.108334,180.757446,9.208224,1.083339,-93.187592,0.109505,0.000000
105.410004,41.950733,-93.143112,0.029331,0.004293,0.109036,186.606186,9.506172,1.090364,-93.143112,0.110077,0.000000
105.750008,42.758038,-93.009666,0.029374,0.004316,0.109626,190.197250,9.689110,1.096261,-93.009666,0.110641,0.000000
106.090004,43.479698,-92.920708,0.029387,0.004334,0.110094,193.407364,9.852640,1.100945,-92.920708,0.111204,0.000000
106.430008,44.494038,-92.965187,0.029379,0.004359,0.110710,197.919357,10.082493,1.107101,-92.965187,0.111777,0.000000
106.770004,45.268200,-92.787262,0.029400,0.004381,0.111283,201.363007,10.257920,1.112825,-92.787262,0.112340,0.000000
107.110008,46.561825,-92.698303,0.029409,0.004405,0.111881,207.117340,10.551060,1.118809,-92.698303,0.112904,0.000000
107.450005,47.816719,-92.653824,0.029435,0.004428,0.112471,212.699387,10.835423,1.124706,-92.653824,0.113477,0.000000
107.790009,48.412888,-92.520378,0.029448,0.004448,0.112974,215.351273,10.970517,1.129736,-92.520378,0.114040,0.000000
108.130005,48.896973,-92.520378,0.029452,0.004465,0.113398,217.504593,11.080213,1.133985,-92.520378,0.114604,0.000000
108.470009,50.233788,-92.386932,0.029474,0.004488,0.113997,223.451050,11.383139,1.139969,-92.386932,0.115176,0.000000
108.810005,51.573956,-92.342453,0.029482,0.004513,0.114630,229.412415,11.686826,1.146299,-92.342453,0.115740,0.000000
109.150002,52.952850,-92.253494,0.029482,0.004540,0.115315,235.546036,11.999288,1.153152,-92.253494,0.116312,0.000000
109.490005,53.752335,-92.209015,0.029512,0.004560,0.115827,239.102325,12.180453,1.158267,-92.209015,0.116876,0.000000
109.830002,55.080589,-92.164528,0.029517,0.004584,0.116425,245.010696,12.481440,1.164251,-92.164528,0.117440,0.000000
110.170006,55.982475,-92.031090,0.029534,0.004604,0.116937,249.022491,12.685810,1.169368,-92.031090,0.118012,0.000000
110.510002,57.270138,-91.986610,0.029534,0.004625,0.117483,254.750290,12.977599,1.174831,-91.986610,0.118576,0.000000
110.850006,58.180588,-91.897644,0.029568,0.004646,0.118004,258.800171,13.183909,1.180036,-91.897644,0.119140,0.000000
111.190002,60.026066,-91.853165,0.029547,0.004672,0.118671,267.009277,13.602101,1.186712,-91.853165,0.119712,0.000000
111.530006,61.361023,-91.764198,0.029568,0.004695,0.119252,272.947449,13.904607,1.192522,-91.764198,0.120276,0.000000
111.870003,62.678104,-91.630760,0.029577,0.004717,0.119807,278.806122,14.203061,1.198073,-91.630760,0.120839,0.000000
112.210007,63.794106,-91.586281,0.029581,0.004736,0.120302,283.770355,14.455951,1.203016,-91.586281,0.121412,0.000000
112.550003,64.569756,-91.497314,0.029633,0.004755,0.120779,287.220612,14.631716,1.207786,-91.497314,0.121975,0.000000
112.890007,66.075264,-91.452835,0.029624,0.004777,0.121325,293.917450,14.972869,1.213250,-91.452835,0.122539,0.000000
113.230003,66.965607,-91.408356,0.029646,0.004786,0.121568,297.877899,15.174623,1.215678,-91.408356,0.121793,0.000000
113.570007,66.068558,-91.274910,0.029629,0.004783,0.121498,293.887634,14.971349,1.214983,-91.274910,0.121568,0.000000
113.910004,65.288811,-91.230431,0.029646,0.004782,0.121464,290.419128,14.794656,1.214637,-91.230431,0.121568,0.000000
114.250008,64.628220,-91.141472,0.029646,0.004781,0.121446,287.480682,14.644963,1.214463,-91.141472,0.121568,0.000000
114.590004,64.062210,-91.008026,0.029629,0.004781,0.121438,284.962952,14.516704,1.214378,-91.008026,0.121568,0.000000
114.930008,63.564724,-91.008026,0.029650,0.004781,0.121429,282.750000,14.403973,1.214291,-91.008026,0.121568,0.000000
115.270004,63.139099,-90.919067,0.029659,0.004780,0.121420,280.856750,14.307525,1.214204,-90.919067,0.121568,0.000000
115.610008,62.752949,-90.874580,0.029663,0.004780,0.121420,279.139069,14.220021,1.214204,-90.874580,0.121568,0.000000
115.950005,62.419304,-90.741142,0.029668,0.004780,0.121420,277.654938,14.144416,1.214204,-90.741142,0.121568,0.000000
116.290009,62.093105,-90.652176,0.029663,0.004780,0.121412,276.203918,14.070499,1.214117,-90.652176,0.121568,0.000000
116.630005,61.816433,-90.652176,0.029659,0.004780,0.121412,274.973236,14.007805,1.214117,-90.652176,0.121568,0.000000
116.970009,61.558380,-90.518738,0.029685,0.004780,0.121412,273.825348,13.949328,1.214117,-90.518738,0.121568,0.000000
117.310005,61.316711,-90.474251,0.029668,0.004780,0.121412,272.750366,13.894566,1.214117,-90.474251,0.121568,0.000000
117.650009,61.104084,-90.429771,0.029676,0.004780,0.121412,271.804535,13.846383,1.214117,-90.429771,0.121568,0.000000
117.990005,60.918644,-90.296333,0.029676,0.004780,0.121403,270.979675,13.804361,1.214030,-90.296333,0.121568,0.000000
118.330002,60.726498,-90.251846,0.029668,0.004780,0.121403,270.124939,13.760820,1.214030,-90.251846,0.121568,0.000000
118.670006,60.553345,-90.207367,0.029672,0.004780,0.121403,269.354736,13.721583,1.214030,-90.207367,0.121568,0.000000
119.010002,60.396576,-90.207367,0.029672,0.004780,0.121403,268.657379,13.686060,1.214030,-90.207367,0.121568,0.000000
119.350006,60.225658,-89.984962,0.029676,0.004780,0.121403,267.897095,13.647329,1.214030,-89.984962,0.121568,0.000000
119.690002,60.089741,-89.940483,0.029672,0.004780,0.121403,267.292511,13.616530,1.214030,-89.940483,0.121568,0.000000
120.030006,59.953453,-89.896004,0.029672,0.004780,0.121403,266.686279,13.585647,1.214030,-89.896004,0.121568,0.000000
120.370003,59.810089,-89.807037,0.029680,0.004780,0.121403,266.048553,13.553161,1.214030,-89.807037,0.121568,0.000000
120.710007,59.690186,-89.718079,0.029668,0.004779,0.121394,265.515198,13.525990,1.213943,-89.718079,0.121568,0.000000
121.050003,59.583317,-89.629120,0.029680,0.004779,0.121394,265.039825,13.501773,1.213943,-89.629120,0.121568,0.000000
121.390007,59.465275,-89.540154,0.029693,0.004779,0.121394,264.514740,13.475024,1.213943,-89.540154,0.121568,0.000000
121.730003,59.355797,-89.495674,0.029668,0.004779,0.121394,264.027771,13.450215,1.213943,-89.495674,0.121568,0.000000
122.070007,59.250786,-89.406715,0.029689,0.004779,0.121394,263.560669,13.426420,1.213943,-89.406715,0.121568,0.000000
122.410004,59.149128,-89.362228,0.029685,0.004779,0.121394,263.108459,13.403383,1.213943,-89.362228,0.121568,0.000000
122.750008,59.050449,-89.273270,0.029672,0.004779,0.121394,262.669525,13.381022,1.213943,-89.273270,0.121568,0.000000
123.090004,58.957729,-89.184303,0.029680,0.004779,0.121394,262.257080,13.360012,1.213943,-89.184303,0.121568,0.000000
123.430008,58.880276,-89.139824,0.029680,0.004779,0.121394,261.912537,13.342462,1.213943,-89.139824,0.121568,0.000000
123.770004,58.799099,-89.006386,0.029685,0.004779,0.121394,261.551453,13.324066,1.213943,-89.006386,0.121568,0.000000
124.110008,58.710846,-89.006386,0.029676,0.004779,0.121394,261.158875,13.304068,1.213943,-89.006386,0.121568,0.000000
124.450005,58.626690,-88.917419,0.029676,0.004779,0.121394,260.784546,13.284998,1.213943,-88.917419,0.121568,0.000000
124.790009,58.545513,-88.828461,0.029693,0.004779,0.121394,260.423462,13.266603,1.213943,-88.828461,0.121568,0.000000
125.130005,58.484818,-88.783981,0.029689,0.004779,0.121394,260.153473,13.252849,1.213943,-88.783981,0.121568,0.000000
125.470009,58.416302,-88.650536,0.029685,0.004779,0.121394,259.848694,13.237323,1.213943,-88.650536,0.121568,0.000000
125.810005,58.342571,-88.561577,0.029685,0.004779,0.121394,259.520721,13.220615,1.213943,-88.561577,0.121568,0.000000
126.150009,58.278896,-88.517090,0.029685,0.004779,0.121394,259.237488,13.206187,1.213943,-88.517090,0.121568,0.000000
126.490005,58.205536,-88.428131,0.029689,0.004779,0.121386,258.911163,13.189563,1.213857,-88.428131,0.121568,0.000000
126.830009,58.137394,-88.428131,0.029680,0.004779,0.121386,258.608032,13.174122,1.213857,-88.428131,0.121568,0.000000
127.170006,58.078930,-88.294685,0.029685,0.004779,0.121386,258.347992,13.160873,1.213857,-88.294685,0.121568,0.000000
127.510010,58.026428,-88.250206,0.029685,0.004779,0.121386,258.114441,13.148976,1.213857,-88.250206,0.121568,0.000000
127.850006,57.963867,-88.116760,0.029693,0.004779,0.121386,257.836151,13.134800,1.213857,-88.116760,0.121568,0.000000
128.190002,57.899075,-88.072281,0.029680,0.004779,0.121386,257.547943,13.120118,1.213857,-88.072281,0.121568,0.000000
128.529999,57.852528,-88.027802,0.029702,0.004779,0.121386,257.340881,13.109570,1.213857,-88.027802,0.121568,0.000000
128.870010,57.791458,-87.894356,0.029693,0.004779,0.121386,257.069244,13.095732,1.213857,-87.894356,0.121568,0.000000
129.210007,57.740818,-87.849876,0.029685,0.004779,0.121386,256.843994,13.084256,1.213857,-87.849876,0.121568,0.000000
129.550003,57.700974,-87.760918,0.029689,0.004779,0.121386,256.666748,13.075227,1.213857,-87.760918,0.121568,0.000000
129.889999,57.647724,-87.671951,0.029693,0.004779,0.121386,256.429871,13.063161,1.213857,-87.671951,0.121568,0.000000
130.230011,57.584049,-87.671951,0.029680,0.004779,0.121386,256.146637,13.048732,1.213857,-87.671951,0.121568,0.000000
130.570007,57.537872,-87.538513,0.029706,0.004779,0.121386,255.941238,13.038268,1.213857,-87.538513,0.121568,0.000000
130.910004,57.490955,-87.494034,0.029689,0.004779,0.121386,255.732544,13.027637,1.213857,-87.494034,0.121568,0.000000
131.250000,57.457813,-87.360588,0.029698,0.004779,0.121386,255.585114,13.020126,1.213857,-87.360588,0.121568,0.000000
131.590012,57.410149,-87.316109,0.029693,0.004779,0.121386,255.373093,13.009325,1.213857,-87.316109,0.121568,0.000000
131.930008,57.367699,-87.271629,0.029711,0.004779,0.121386,255.184265,12.999706,1.213857,-87.271629,0.121568,0.000000
132.270004,57.326740,-87.182663,0.029706,0.004779,0.121386,255.002075,12.990425,1.213857,-87.182663,0.121568,0.000000
132.610001,57.279076,-87.138184,0.029689,0.004779,0.121386,254.790054,12.979624,1.213857,-87.138184,0.121568,0.000000
132.950012,57.225082,-87.049225,0.029698,0.004779,0.121386,254.549881,12.967389,1.213857,-87.049225,0.121568,0.000000
133.290009,57.200504,-86.960258,0.029702,0.004779,0.121386,254.440552,12.961820,1.213857,-86.960258,0.121568,0.000000
133.630005,57.159542,-87.004738,0.029689,0.004779,0.121386,254.258347,12.952537,1.213857,-87.004738,0.121568,0.000000
133.970001,57.119328,-86.871300,0.029702,0.004779,0.121386,254.079453,12.943425,1.213857,-86.871300,0.121568,0.000000
134.310013,57.074642,-86.737854,0.029680,0.004779,0.121386,253.880692,12.933299,1.213857,-86.737854,0.121568,0.000000
134.650009,57.026608,-86.693375,0.029702,0.004779,0.121386,253.667023,12.922414,1.213857,-86.693375,0.121568,0.000000
134.990005,56.992722,-86.559929,0.029689,0.004779,0.121386,253.516281,12.914736,1.213857,-86.559929,0.121568,0.000000
135.330002,56.970379,-86.559929,0.029706,0.004779,0.121386,253.416901,12.909673,1.213857,-86.559929,0.121568,0.000000
135.670013,56.929790,-86.470970,0.029693,0.004779,0.121386,253.236359,12.900475,1.213857,-86.470970,0.121568,0.000000
136.010010,56.888828,-86.382004,0.029685,0.004779,0.121386,253.054153,12.891192,1.213857,-86.382004,0.121568,0.000000
136.350006,56.855316,-86.293045,0.029698,0.004779,0.121386,252.905075,12.883599,1.213857,-86.293045,0.121568,0.000000
136.690002,56.820686,-86.248566,0.029689,0.004779,0.121386,252.751038,12.875751,1.213857,-86.248566,0.121568,0.000000
137.030014,56.797596,-86.204086,0.029702,0.004779,0.121386,252.648331,12.870519,1.213857,-86.204086,0.121568,0.000000
137.370010,56.765572,-86.070641,0.029693,0.004779,0.121386,252.505875,12.863262,1.213857,-86.070641,0.121568,0.000000
137.710007,56.728336,-86.026161,0.029685,0.004779,0.121386,252.340240,12.854825,1.213857,-86.026161,0.121568,0.000000
138.050003,56.697430,-85.937195,0.029711,0.004779,0.121386,252.202759,12.847821,1.213857,-85.937195,0.121568,0.000000
138.389999,56.665405,-85.848236,0.029698,0.004779,0.121386,252.060318,12.840565,1.213857,-85.848236,0.121568,0.000000
138.730011,56.623699,-85.848236,0.029685,0.004779,0.121386,251.874786,12.831113,1.213857,-85.848236,0.121568,0.000000
139.070007,56.606941,-85.714790,0.029693,0.004779,0.121386,251.800247,12.827316,1.213857,-85.714790,0.121568,0.000000
139.410004,56.584229,-85.714790,0.029702,0.004779,0.121386,251.699219,12.822169,1.213857,-85.714790,0.121568,0.000000
139.750000,56.550343,-85.625832,0.029706,0.004779,0.121386,251.548492,12.814490,1.213857,-85.625832,0.121568,0.000000
140.090012,56.520180,-85.536865,0.029693,0.004779,0.121386,251.414322,12.807655,1.213857,-85.536865,0.121568,0.000000
140.430008,56.487038,-85.492386,0.029702,0.004779,0.121386,251.266891,12.800146,1.213857,-85.492386,0.121568,0.000000
140.770004,56.464695,-85.269981,0.029702,0.004779,0.121386,251.167511,12.795083,1.213857,-85.269981,0.121568,0.000000
141.110001,56.427830,-85.358948,0.029715,0.004779,0.121386,251.003525,12.786729,1.213857,-85.358948,0.121568,0.000000
141.450012,56.403629,-85.181023,0.029711,0.004779,0.121386,250.895874,12.781245,1.213857,-85.181023,0.121568,0.000000
141.790009,56.377190,-85.136543,0.029702,0.004779,0.121386,250.778259,12.775253,1.213857,-85.136543,0.121568,0.000000
142.130005,56.347027,-85.136543,0.029711,0.004779,0.121386,250.644089,12.768418,1.213857,-85.136543,0.121568,0.000000
142.470001,56.321705,-84.958618,0.029693,0.004779,0.121386,250.531448,12.762681,1.213857,-84.958618,0.121568,0.000000
142.810013,56.296013,-84.914139,0.029702,0.004779,0.121386,250.417175,12.756859,1.213857,-84.914139,0.121568,0.000000
143.150009,56.273296,-84.825172,0.029702,0.004779,0.121386,250.316116,12.751712,1.213857,-84.825172,0.121568,0.000000
143.490005,56.242764,-84.780693,0.029693,0.004779,0.121386,250.180313,12.744792,1.213857,-84.780693,0.121568,0.000000
143.500000,56.240154,-84.780693,0.029706,0.004779,0.121386,250.168701,12.744201,1.213857,-84.780693,0.121568,0.000000