File: Data/AD Membrane New Dongle 500N_07172023_140036.csv
Time (sec),S:Load (lbs),S:HL1 (DIM),S:LVDT (in),S:Position (in),Ch:Position (mm),Ch:Load (N),Ch:Stress (MPa),Ch:Strain (mm/mm),Ch:HL1 (DIM),Set Point (),Cycles ()
0.110000,0.032396,-38.075695,0.016755,-0.044286,-1.124861,0.144106,0.007341,-11.248610,-38.075695,-1.125009,0.000000
0.480000,0.029045,-38.075695,0.016737,-0.044258,-1.124150,0.129199,0.006582,-11.241502,-38.075695,-1.123586,0.000000
0.850000,0.047291,-38.164658,0.016849,-0.044040,-1.118617,0.210362,0.010716,-11.186173,-38.164658,-1.117411,0.000000
1.220000,0.062559,-38.164658,0.017099,-0.043795,-1.112381,0.278274,0.014176,-11.123814,-38.164658,-1.111254,0.000000
1.590000,0.052132,-38.120174,0.017341,-0.043555,-1.106285,0.231895,0.011813,-11.062847,-38.120174,-1.105097,0.000000
1.960000,0.062559,-38.164658,0.017595,-0.043312,-1.100119,0.278274,0.014176,-11.001191,-38.164658,-1.098922,0.000000
2.330000,0.072613,-38.075695,0.017863,-0.043065,-1.093841,0.322997,0.016454,-10.938407,-38.075695,-1.092765,0.000000
2.700000,0.046547,-38.164658,0.018108,-0.042827,-1.087795,0.207049,0.010548,-10.877954,-38.164658,-1.086590,0.000000
3.070000,0.013405,-38.253616,0.018346,-0.042592,-1.081838,0.059630,0.003038,-10.818380,-38.253616,-1.080433,0.000000
3.440000,0.000745,-38.253616,0.018617,-0.042338,-1.075386,0.003313,0.000169,-10.753856,-38.253616,-1.074276,0.000000
3.810000,0.067399,-38.209137,0.018863,-0.042096,-1.069237,0.299807,0.015273,-10.692373,-38.209137,-1.068101,0.000000
4.180000,0.081177,-38.209137,0.019126,-0.041851,-1.063010,0.361094,0.018395,-10.630105,-38.209137,-1.061944,0.000000
4.550000,0.079688,-38.253616,0.019354,-0.041615,-1.057018,0.354468,0.018057,-10.570182,-38.253616,-1.055769,0.000000
4.920000,0.081177,-38.253616,0.019613,-0.041375,-1.050921,0.361094,0.018395,-10.509215,-38.253616,-1.049612,0.000000
5.290000,0.064048,-38.253616,0.019863,-0.041130,-1.044695,0.284900,0.014513,-10.446946,-38.253616,-1.043455,0.000000
5.660000,0.067772,-38.253616,0.020135,-0.040878,-1.038294,0.301464,0.015357,-10.382943,-38.253616,-1.037280,0.000000
6.030000,0.078198,-38.253616,0.020385,-0.040637,-1.032189,0.347843,0.017720,-10.321893,-38.253616,-1.031123,0.000000
6.400000,0.067772,-38.298100,0.020631,-0.040395,-1.026032,0.301464,0.015357,-10.260321,-38.298100,-1.024965,0.000000
6.770000,0.058462,-38.298100,0.020898,-0.040152,-1.019866,0.260054,0.013248,-10.198657,-38.298100,-1.018791,0.000000
7.140000,0.036120,-38.298100,0.021144,-0.039914,-1.013821,0.160670,0.008185,-10.138212,-38.298100,-1.012633,0.000000
7.510000,0.011916,-38.298100,0.021394,-0.039670,-1.007621,0.053004,0.002700,-10.076208,-38.298100,-1.006459,0.000000
7.880001,0.069261,-38.298100,0.021631,-0.039423,-1.001351,0.308089,0.015695,-10.013507,-38.298100,-1.000302,0.000000
8.250000,0.089369,-38.298100,0.021898,-0.039180,-0.995168,0.397535,0.020251,-9.951677,-38.298100,-0.994144,0.000000
8.620001,0.093093,-38.342579,0.022144,-0.038938,-0.989027,0.414099,0.021095,-9.890271,-38.342579,-0.987970,0.000000
8.990001,0.086018,-38.253616,0.022390,-0.038703,-0.983052,0.382627,0.019492,-9.830523,-38.253616,-0.981812,0.000000
9.360001,0.076709,-38.253616,0.022644,-0.038456,-0.976774,0.341217,0.017382,-9.767739,-38.253616,-0.975638,0.000000
9.730000,0.068516,-38.342579,0.022898,-0.038209,-0.970504,0.304777,0.015526,-9.705038,-38.342579,-0.969480,0.000000
10.100000,0.088625,-38.342579,0.023153,-0.037969,-0.964415,0.394222,0.020083,-9.644155,-38.342579,-0.963323,0.000000
10.470000,0.073357,-38.387062,0.023407,-0.037728,-0.958293,0.326310,0.016623,-9.582931,-38.387062,-0.957148,0.000000
10.840000,0.097562,-38.387062,0.023653,-0.037484,-0.952093,0.433975,0.022108,-9.520926,-38.387062,-0.950991,0.000000
11.210001,0.067772,-38.431541,0.023903,-0.037243,-0.945961,0.301464,0.015357,-9.459611,-38.431541,-0.944816,0.000000
11.580001,0.058462,-38.431541,0.024140,-0.037003,-0.939873,0.260054,0.013248,-9.398734,-38.431541,-0.938659,0.000000
11.950001,0.072613,-38.476021,0.024399,-0.036750,-0.933447,0.322997,0.016454,-9.334467,-38.476021,-0.932502,0.000000
12.320001,0.097934,-38.387062,0.024640,-0.036521,-0.927637,0.435632,0.022192,-9.276369,-38.387062,-0.926327,0.000000
12.690001,0.103147,-38.342579,0.024895,-0.036277,-0.921427,0.458821,0.023373,-9.214273,-38.342579,-0.920170,0.000000
13.060000,0.106871,-38.387062,0.025149,-0.036035,-0.915296,0.475385,0.024217,-9.152959,-38.387062,-0.913995,0.000000
13.430000,0.107243,-38.476021,0.025408,-0.035790,-0.909078,0.477042,0.024302,-9.090780,-38.476021,-0.907838,0.000000
13.800000,0.080432,-38.387062,0.025654,-0.035548,-0.902912,0.357781,0.018226,-9.029117,-38.387062,-0.901681,0.000000
14.170001,0.105381,-38.387062,0.025904,-0.035300,-0.896624,0.468760,0.023880,-8.966242,-38.387062,-0.895506,0.000000
14.540001,0.089742,-38.431541,0.026167,-0.035061,-0.890546,0.399191,0.020336,-8.905457,-38.431541,-0.889349,0.000000
14.910001,0.071868,-38.520504,0.026421,-0.034813,-0.884258,0.319684,0.016285,-8.842582,-38.520504,-0.883174,0.000000
15.280001,0.078943,-38.431541,0.026658,-0.034571,-0.878109,0.351156,0.017889,-8.781093,-38.431541,-0.877017,0.000000
15.650001,0.053994,-38.476021,0.026921,-0.034330,-0.871987,0.240177,0.012235,-8.719868,-38.476021,-0.870860,0.000000
16.020000,0.086018,-38.387062,0.027171,-0.034080,-0.865630,0.382627,0.019492,-8.656297,-38.387062,-0.864685,0.000000
16.390001,0.105381,-38.431541,0.027426,-0.033840,-0.859525,0.468760,0.023880,-8.595246,-38.431541,-0.858527,0.000000
16.760000,0.124745,-38.476021,0.027654,-0.033611,-0.853732,0.554892,0.028268,-8.537315,-38.476021,-0.852353,0.000000
17.130001,0.106498,-38.520504,0.027921,-0.033362,-0.847392,0.473729,0.024133,-8.473918,-38.520504,-0.846195,0.000000
17.500000,0.099796,-38.476021,0.028184,-0.033121,-0.841261,0.443914,0.022614,-8.412610,-38.476021,-0.840038,0.000000
17.870001,0.096072,-38.476021,0.028434,-0.032877,-0.835069,0.427350,0.021770,-8.350690,-38.476021,-0.833863,0.000000
18.240002,0.086763,-38.520504,0.028680,-0.032632,-0.828842,0.385940,0.019661,-8.288421,-38.520504,-0.827706,0.000000
18.610001,0.100541,-38.520504,0.028939,-0.032390,-0.822694,0.447227,0.022783,-8.226938,-38.520504,-0.821549,0.000000
18.980001,0.084901,-38.564983,0.029193,-0.032145,-0.816484,0.377658,0.019239,-8.164844,-38.564983,-0.815374,0.000000
19.350000,0.102030,-38.520504,0.029448,-0.031900,-0.810266,0.453852,0.023120,-8.102665,-38.520504,-0.809217,0.000000
19.720001,0.097934,-38.520504,0.029685,-0.031661,-0.804178,0.435632,0.022192,-8.041781,-38.520504,-0.803042,0.000000
20.090000,0.096072,-38.520504,0.029943,-0.031413,-0.797891,0.427350,0.021770,-7.978907,-38.520504,-0.796885,0.000000
20.460001,0.089369,-38.609467,0.030189,-0.031167,-0.791647,0.397535,0.020251,-7.916471,-38.609467,-0.790727,0.000000
20.830002,0.129958,-38.564983,0.030418,-0.030940,-0.785880,0.578082,0.029449,-7.858797,-38.564983,-0.784553,0.000000
21.200001,0.126607,-38.564983,0.030685,-0.030697,-0.779697,0.563174,0.028689,-7.796967,-38.564983,-0.778395,0.000000
21.570002,0.131820,-38.609467,0.030948,-0.030453,-0.773495,0.586364,0.029871,-7.734955,-38.609467,-0.772221,0.000000
21.940001,0.118787,-38.564983,0.031198,-0.030204,-0.767191,0.528390,0.026917,-7.671914,-38.564983,-0.766064,0.000000
22.310001,0.106126,-38.609467,0.031440,-0.029962,-0.761034,0.472073,0.024049,-7.610341,-38.609467,-0.759906,0.000000
22.680000,0.060697,-38.609467,0.031685,-0.029720,-0.754893,0.269992,0.013754,-7.548935,-38.609467,-0.753732,0.000000
23.050001,0.105009,-38.564983,0.031935,-0.029477,-0.748728,0.467103,0.023795,-7.487279,-38.564983,-0.747574,0.000000
23.420002,0.097934,-38.609467,0.032190,-0.029230,-0.742440,0.435632,0.022192,-7.424405,-38.609467,-0.741400,0.000000
23.790001,0.105754,-38.609467,0.032440,-0.028987,-0.736275,0.470416,0.023964,-7.362749,-38.609467,-0.735242,0.000000
24.160002,0.109850,-38.609467,0.032694,-0.028742,-0.730056,0.488637,0.024892,-7.300563,-38.609467,-0.729085,0.000000
24.530001,0.093838,-38.653946,0.032957,-0.028499,-0.723882,0.417412,0.021264,-7.238816,-38.653946,-0.722910,0.000000
24.900002,0.125862,-38.564983,0.033199,-0.028258,-0.717742,0.559862,0.028521,-7.177417,-38.564983,-0.716753,0.000000
25.270000,0.140757,-38.564983,0.033432,-0.028030,-0.711966,0.626117,0.031896,-7.119660,-38.564983,-0.710578,0.000000
25.640001,0.120276,-38.564983,0.033686,-0.027779,-0.705592,0.535016,0.027255,-7.055923,-38.564983,-0.704421,0.000000
26.010002,0.127724,-38.609467,0.033945,-0.027534,-0.699374,0.568144,0.028943,-6.993744,-38.609467,-0.698264,0.000000
26.380001,0.097562,-38.609467,0.034190,-0.027296,-0.693313,0.433975,0.022108,-6.933125,-38.609467,-0.692089,0.000000
26.750002,0.058090,-38.609467,0.034445,-0.027052,-0.687120,0.258398,0.013163,-6.871204,-38.609467,-0.685932,0.000000
27.120001,0.117670,-38.564983,0.034699,-0.026807,-0.680893,0.523421,0.026664,-6.808935,-38.564983,-0.679757,0.000000
27.490002,0.088997,-38.653946,0.034949,-0.026562,-0.674676,0.395878,0.020167,-6.746757,-38.653946,-0.673600,0.000000
27.860001,0.126979,-38.653946,0.035216,-0.026318,-0.668484,0.564831,0.028774,-6.684836,-38.653946,-0.667443,0.000000
28.230001,0.120276,-38.653946,0.035467,-0.026073,-0.662266,0.535016,0.027255,-6.622658,-38.653946,-0.661268,0.000000
28.600002,0.114691,-38.609467,0.035704,-0.025834,-0.656186,0.510170,0.025989,-6.561865,-38.609467,-0.655111,0.000000
28.970001,0.110967,-38.609467,0.035962,-0.025589,-0.649951,0.493606,0.025145,-6.499513,-38.609467,-0.648954,0.000000
29.340002,0.154162,-38.653946,0.036204,-0.025359,-0.644114,0.685748,0.034934,-6.441142,-38.653946,-0.642779,0.000000
29.710001,0.131075,-38.742908,0.036463,-0.025112,-0.637836,0.583051,0.029702,-6.378358,-38.742908,-0.636622,0.000000
30.080002,0.161237,-38.653946,0.036730,-0.024865,-0.631574,0.717219,0.036537,-6.315741,-38.653946,-0.630447,0.000000
30.450001,0.129586,-38.653946,0.036989,-0.024625,-0.625478,0.576425,0.029365,-6.254781,-38.653946,-0.624290,0.000000
30.820002,0.084901,-38.653946,0.037217,-0.024381,-0.619286,0.377658,0.019239,-6.192860,-38.653946,-0.618132,0.000000
31.190001,0.075964,-38.653946,0.037463,-0.024138,-0.613111,0.337905,0.017214,-6.131114,-38.653946,-0.611958,0.000000
31.560001,0.109850,-38.653946,0.037726,-0.023897,-0.606972,0.488637,0.024892,-6.069715,-38.653946,-0.605800,0.000000
31.930002,0.126607,-38.653946,0.037980,-0.023649,-0.600684,0.563174,0.028689,-6.006840,-38.653946,-0.599626,0.000000
32.300003,0.140757,-38.653946,0.038235,-0.023404,-0.594457,0.626117,0.031896,-5.944571,-38.653946,-0.593468,0.000000
32.670002,0.125862,-38.698429,0.038459,-0.023168,-0.588473,0.559862,0.028521,-5.884732,-38.698429,-0.587311,0.000000
33.040001,0.114691,-38.653946,0.038700,-0.022927,-0.582351,0.510170,0.025989,-5.823507,-38.653946,-0.581137,0.000000
33.410000,0.172408,-38.698429,0.038967,-0.022680,-0.576072,0.766911,0.039068,-5.760716,-38.698429,-0.574979,0.000000
33.780003,0.141501,-38.698429,0.039209,-0.022444,-0.570079,0.629430,0.032065,-5.700794,-38.698429,-0.568805,0.000000
34.150002,0.128468,-38.653946,0.039463,-0.022196,-0.563784,0.571456,0.029111,-5.637836,-38.653946,-0.562647,0.000000
34.520000,0.124372,-38.698429,0.039718,-0.021951,-0.557565,0.553236,0.028183,-5.575650,-38.698429,-0.556490,0.000000
34.890003,0.100541,-38.698429,0.039951,-0.021715,-0.551564,0.447227,0.022783,-5.515644,-38.698429,-0.550315,0.000000
35.260002,0.068889,-38.742908,0.040205,-0.021473,-0.545424,0.306433,0.015610,-5.454238,-38.742908,-0.544158,0.000000
35.630001,0.125489,-38.698429,0.040459,-0.021225,-0.539120,0.558205,0.028436,-5.391197,-38.698429,-0.537983,0.000000
36.000000,0.118414,-38.698429,0.040705,-0.020978,-0.532841,0.526734,0.026833,-5.328405,-38.698429,-0.531826,0.000000
36.370003,0.146715,-38.742908,0.040964,-0.020733,-0.526614,0.652620,0.033246,-5.266144,-38.742908,-0.525669,0.000000
36.740002,0.136288,-38.787388,0.041231,-0.020491,-0.520474,0.606241,0.030883,-5.204738,-38.787388,-0.519494,0.000000
37.110001,0.138895,-38.698429,0.041468,-0.020256,-0.514499,0.617835,0.031474,-5.144989,-38.698429,-0.513337,0.000000
37.480003,0.139267,-38.698429,0.041731,-0.020008,-0.508203,0.619492,0.031558,-5.082031,-38.698429,-0.507162,0.000000
37.850002,0.163099,-38.698429,0.041977,-0.019773,-0.502228,0.725501,0.036959,-5.022275,-38.698429,-0.501005,0.000000
38.220001,0.137405,-38.742908,0.042218,-0.019526,-0.495949,0.611210,0.031137,-4.959492,-38.742908,-0.494848,0.000000
38.590000,0.145970,-38.698429,0.042464,-0.019281,-0.489731,0.649307,0.033077,-4.897306,-38.698429,-0.488673,0.000000
38.960003,0.125489,-38.787388,0.042719,-0.019044,-0.483713,0.558205,0.028436,-4.837126,-38.787388,-0.482516,0.000000
39.330002,0.085646,-38.653946,0.042956,-0.018805,-0.477659,0.380971,0.019408,-4.776590,-38.653946,-0.476341,0.000000
39.700001,0.081922,-38.653946,0.043227,-0.018556,-0.471311,0.364407,0.018564,-4.713110,-38.653946,-0.470184,0.000000
40.070004,0.149321,-38.742908,0.043464,-0.018312,-0.465119,0.664214,0.033837,-4.651189,-38.742908,-0.464027,0.000000
40.440002,0.155652,-38.742908,0.043723,-0.018066,-0.458875,0.692373,0.035271,-4.588754,-38.742908,-0.457852,0.000000
40.810001,0.157141,-38.653946,0.043982,-0.017824,-0.452735,0.698999,0.035609,-4.527348,-38.653946,-0.451695,0.000000
41.180000,0.141874,-38.742908,0.044206,-0.017589,-0.446760,0.631087,0.032149,-4.467599,-38.742908,-0.445537,0.000000
41.550003,0.161237,-38.742908,0.044452,-0.017346,-0.440585,0.717219,0.036537,-4.405852,-38.742908,-0.439363,0.000000
41.920002,0.172036,-38.742908,0.044715,-0.017096,-0.434246,0.765255,0.038984,-4.342455,-38.742908,-0.433205,0.000000
42.290001,0.160865,-38.787388,0.044965,-0.016856,-0.428140,0.715563,0.036453,-4.281405,-38.787388,-0.427031,0.000000
42.660004,0.159748,-38.698429,0.045215,-0.016612,-0.421948,0.710594,0.036199,-4.219484,-38.698429,-0.420873,0.000000
43.030003,0.144480,-38.698429,0.045478,-0.016367,-0.415722,0.642681,0.032740,-4.157223,-38.698429,-0.414716,0.000000
43.400002,0.115435,-38.742908,0.045702,-0.016131,-0.409729,0.513482,0.026158,-4.097292,-38.742908,-0.408542,0.000000
43.770000,0.079688,-38.831871,0.045956,-0.015890,-0.403598,0.354468,0.018057,-4.035977,-38.831871,-0.402384,0.000000
44.140003,0.160865,-38.742908,0.046224,-0.015641,-0.397294,0.715563,0.036453,-3.972936,-38.742908,-0.396210,0.000000
44.510002,0.175387,-38.653946,0.046465,-0.015394,-0.391006,0.780162,0.039743,-3.910061,-38.653946,-0.390052,0.000000
44.880001,0.171291,-38.653946,0.046711,-0.015156,-0.384953,0.761942,0.038815,-3.849526,-38.653946,-0.383895,0.000000
45.250004,0.164216,-38.787388,0.046948,-0.014915,-0.378848,0.730470,0.037212,-3.788476,-38.787388,-0.377720,0.000000
45.620003,0.160120,-38.787388,0.047215,-0.014676,-0.372768,0.712250,0.036284,-3.727683,-38.787388,-0.371563,0.000000
45.990002,0.157141,-38.698429,0.047465,-0.014427,-0.366455,0.698999,0.035609,-3.664551,-38.698429,-0.365388,0.000000
46.360001,0.163099,-38.787388,0.047716,-0.014186,-0.360324,0.725501,0.036959,-3.603235,-38.787388,-0.359231,0.000000
46.730003,0.155279,-38.698429,0.047944,-0.013944,-0.354184,0.690717,0.035187,-3.541837,-38.698429,-0.353073,0.000000
47.100002,0.175015,-38.787388,0.048198,-0.013700,-0.347974,0.778506,0.039659,-3.479742,-38.787388,-0.346898,0.000000
47.470001,0.152300,-38.742908,0.048440,-0.013459,-0.341852,0.677466,0.034512,-3.418517,-38.742908,-0.340741,0.000000
47.840004,0.114318,-38.742908,0.048694,-0.013225,-0.335903,0.508513,0.025905,-3.359026,-38.742908,-0.334567,0.000000
48.210003,0.128468,-38.742908,0.048957,-0.012968,-0.329398,0.571456,0.029111,-3.293979,-38.742908,-0.328409,0.000000
48.580002,0.164961,-38.742908,0.049194,-0.012729,-0.323319,0.733783,0.037381,-3.233194,-38.742908,-0.322252,0.000000
48.950001,0.180973,-38.787388,0.049440,-0.012490,-0.317257,0.805008,0.041009,-3.172575,-38.787388,-0.316077,0.000000
49.320004,0.173898,-38.787388,0.049712,-0.012248,-0.311099,0.773537,0.039406,-3.110994,-38.787388,-0.309920,0.000000
49.690002,0.185814,-38.742908,0.049936,-0.012009,-0.305021,0.826541,0.042106,-3.050209,-38.742908,-0.303745,0.000000
50.060001,0.163844,-38.698429,0.050203,-0.011764,-0.298794,0.728814,0.037128,-2.987940,-38.698429,-0.297588,0.000000
50.430004,0.180601,-38.698429,0.050453,-0.011512,-0.292394,0.803352,0.040925,-2.923937,-38.698429,-0.291431,0.000000
50.800003,0.168312,-38.787388,0.050691,-0.011274,-0.286349,0.748691,0.038140,-2.863492,-38.787388,-0.285256,0.000000
51.170002,0.167568,-38.698429,0.050958,-0.011032,-0.280200,0.745378,0.037971,-2.802003,-38.698429,-0.279099,0.000000
51.540001,0.154162,-38.653946,0.051217,-0.010786,-0.273965,0.685748,0.034934,-2.739651,-38.653946,-0.272942,0.000000
51.910004,0.138523,-38.698429,0.051445,-0.010548,-0.267929,0.616179,0.031390,-2.679289,-38.698429,-0.266767,0.000000
52.280003,0.128468,-38.698429,0.051699,-0.010301,-0.261642,0.571456,0.029111,-2.616422,-38.698429,-0.260610,0.000000
52.650002,0.191027,-38.742908,0.051945,-0.010055,-0.255398,0.849731,0.043287,-2.553979,-38.742908,-0.254435,0.000000
53.020004,0.198474,-38.742908,0.052187,-0.009821,-0.249449,0.882859,0.044975,-2.494488,-38.742908,-0.248278,0.000000
53.390003,0.176877,-38.698429,0.052432,-0.009579,-0.243309,0.786788,0.040081,-2.433089,-38.698429,-0.242120,0.000000
53.760002,0.190655,-38.742908,0.052695,-0.009336,-0.237143,0.848074,0.043203,-2.371426,-38.742908,-0.235946,0.000000
54.130001,0.173898,-38.787388,0.052941,-0.009091,-0.230907,0.773537,0.039406,-2.309074,-38.787388,-0.229789,0.000000
54.500004,0.166078,-38.742908,0.053200,-0.008842,-0.224594,0.738752,0.037634,-2.245942,-38.742908,-0.223614,0.000000
54.870003,0.157886,-38.698429,0.053437,-0.008602,-0.218489,0.702312,0.035777,-2.184891,-38.698429,-0.217457,0.000000
55.240002,0.166823,-38.742908,0.053687,-0.008363,-0.212418,0.742065,0.037803,-2.124182,-38.742908,-0.211299,0.000000
55.610004,0.181345,-38.742908,0.053933,-0.008118,-0.206209,0.806664,0.041093,-2.062087,-38.742908,-0.205125,0.000000
55.980003,0.151556,-38.742908,0.054179,-0.007876,-0.200043,0.674153,0.034343,-2.000431,-38.742908,-0.198967,0.000000
56.350002,0.161610,-38.742908,0.054416,-0.007635,-0.193937,0.718875,0.036621,-1.939373,-38.742908,-0.192793,0.000000
56.720001,0.172036,-38.787388,0.054692,-0.007383,-0.187538,0.765255,0.038984,-1.875378,-38.787388,-0.186635,0.000000
57.090004,0.191399,-38.698429,0.054916,-0.007155,-0.181727,0.851387,0.043372,-1.817272,-38.698429,-0.180478,0.000000
57.460003,0.196240,-38.698429,0.055162,-0.006913,-0.175596,0.872920,0.044469,-1.755957,-38.698429,-0.174303,0.000000
57.830002,0.196613,-38.787388,0.055407,-0.006670,-0.169413,0.874577,0.044553,-1.694127,-38.787388,-0.168146,0.000000
58.200005,0.182462,-38.742908,0.055675,-0.006422,-0.163125,0.811634,0.041347,-1.631252,-38.742908,-0.161972,0.000000
58.570004,0.186931,-38.653946,0.055907,-0.006178,-0.156933,0.831510,0.042359,-1.569331,-38.653946,-0.155814,0.000000
58.940002,0.186931,-38.653946,0.056162,-0.005935,-0.150741,0.831510,0.042359,-1.507410,-38.653946,-0.149657,0.000000
59.310001,0.180601,-38.653946,0.056399,-0.005697,-0.144714,0.803352,0.040925,-1.447140,-38.653946,-0.143482,0.000000
59.680004,0.169802,-38.698429,0.056649,-0.005448,-0.138392,0.755316,0.038478,-1.383917,-38.698429,-0.137325,0.000000
60.050003,0.165333,-38.698429,0.056912,-0.005204,-0.132191,0.735439,0.037465,-1.321912,-38.698429,-0.131150,0.000000
60.420002,0.173898,-38.698429,0.057149,-0.004963,-0.126069,0.773537,0.039406,-1.260688,-38.698429,-0.124993,0.000000
60.790005,0.174270,-38.653946,0.057391,-0.004716,-0.119790,0.775193,0.039490,-1.197897,-38.653946,-0.118836,0.000000
61.160004,0.193634,-38.653946,0.057649,-0.004473,-0.113624,0.861326,0.043878,-1.136241,-38.653946,-0.112661,0.000000
61.530003,0.222679,-38.698429,0.057873,-0.004248,-0.107891,0.990524,0.050460,-1.078915,-38.698429,-0.106504,0.000000
61.900002,0.201081,-38.698429,0.058141,-0.003999,-0.101569,0.894453,0.045566,-1.015692,-38.698429,-0.100347,0.000000
62.270004,0.197730,-38.653946,0.058387,-0.003752,-0.095299,0.879546,0.044806,-0.952991,-38.653946,-0.094172,0.000000
62.640003,0.192144,-38.653946,0.058624,-0.003509,-0.089116,0.854700,0.043540,-0.891161,-38.653946,-0.088015,0.000000
63.010002,0.185441,-38.698429,0.058878,-0.003263,-0.082889,0.824885,0.042022,-0.828892,-38.698429,-0.081840,0.000000
63.380005,0.192144,-38.698429,0.059137,-0.003022,-0.076749,0.854700,0.043540,-0.767493,-38.698429,-0.075683,0.000000
63.750004,0.182090,-38.653946,0.059374,-0.002781,-0.070627,0.809977,0.041262,-0.706269,-38.653946,-0.069525,0.000000
64.120003,0.200336,-38.609467,0.059633,-0.002536,-0.064409,0.891141,0.045397,-0.644091,-38.609467,-0.063351,0.000000
64.490005,0.183580,-38.609467,0.059883,-0.002293,-0.058234,0.816603,0.041600,-0.582344,-38.609467,-0.057194,0.000000
64.860001,0.182090,-38.653946,0.060120,-0.002049,-0.052042,0.809977,0.041262,-0.520423,-38.653946,-0.051019,0.000000
65.230003,0.188793,-38.653946,0.060374,-0.001804,-0.045824,0.839792,0.042781,-0.458245,-38.653946,-0.044862,0.000000
65.600006,0.229754,-38.653946,0.060607,-0.001574,-0.039979,1.021996,0.052063,-0.399791,-38.653946,-0.038704,0.000000
65.970001,0.226402,-38.564983,0.060844,-0.001331,-0.033795,1.007088,0.051304,-0.337953,-38.564983,-0.032530,0.000000
66.340004,0.227520,-38.609467,0.061103,-0.001086,-0.027578,1.012058,0.051557,-0.275775,-38.609467,-0.026372,0.000000
66.710007,0.225285,-38.698429,0.061340,-0.000840,-0.021334,1.002119,0.051050,-0.213339,-38.698429,-0.020198,0.000000
67.080002,0.220444,-38.609467,0.061603,-0.000596,-0.015150,0.980586,0.049953,-0.151502,-38.609467,-0.014040,0.000000
67.450005,0.262523,-38.609467,0.061849,-0.000354,-0.009002,1.167759,0.059488,-0.090020,-38.609467,-0.007883,0.000000
67.820000,0.599147,-38.609467,0.062025,-0.000007,-0.000173,2.665140,0.135769,-0.001733,-38.609467,0.000052,0.000000
68.190002,0.605105,-38.609467,0.062025,-0.000007,-0.000173,2.691643,0.137119,-0.001733,-38.609467,0.000052,0.000000
68.560005,0.650907,-38.609467,0.062021,-0.000006,-0.000165,2.895379,0.147498,-0.001650,-38.609467,0.000529,0.000000
68.930000,0.706391,-38.609467,0.062038,0.000006,0.000156,3.142182,0.160070,0.001559,-38.609467,0.001145,0.000000
69.300003,0.811400,-38.609467,0.062056,0.000033,0.000841,3.609286,0.183866,0.008410,-38.609467,0.001769,0.000000
69.670006,0.921994,-38.564983,0.062082,0.000058,0.001474,4.101235,0.208927,0.014738,-38.564983,0.002384,0.000000
70.040001,1.015460,-38.520504,0.062103,0.000079,0.002003,4.516990,0.230106,0.020030,-38.520504,0.003001,0.000000
70.410004,1.218775,-38.609467,0.062125,0.000108,0.002740,5.421382,0.276178,0.027403,-38.609467,0.003616,0.000000
70.780006,1.338679,-38.564983,0.062146,0.000123,0.003131,5.954741,0.303349,0.031309,-38.564983,0.004232,0.000000
71.150002,1.652961,-38.564983,0.062181,0.000161,0.004093,7.352739,0.374566,0.040930,-38.564983,0.004848,0.000000
71.520004,1.830583,-38.564983,0.062189,0.000181,0.004596,8.142840,0.414816,0.045964,-38.564983,0.005463,0.000000
71.890007,2.016397,-38.520504,0.062202,0.000204,0.005177,8.969380,0.456922,0.051770,-38.520504,0.006079,0.000000
72.260002,2.294559,-38.609467,0.062241,0.000230,0.005836,10.206708,0.519955,0.058363,-38.609467,0.006704,0.000000
72.630005,2.533622,-38.520504,0.062267,0.000249,0.006322,11.270115,0.574127,0.063223,-38.520504,0.007319,0.000000
73.000000,2.774175,-38.564983,0.062271,0.000268,0.006817,12.340146,0.628637,0.068166,-38.564983,0.007935,0.000000
73.370003,3.254535,-38.520504,0.062301,0.000300,0.007631,14.476896,0.737488,0.076311,-38.520504,0.008551,0.000000
73.740005,3.606055,-38.564983,0.062319,0.000325,0.008256,16.040533,0.817144,0.082556,-38.564983,0.009166,0.000000
74.110001,4.012686,-38.564983,0.062345,0.000352,0.008941,17.849318,0.909288,0.089407,-38.564983,0.009782,0.000000
74.480003,4.357130,-38.520504,0.062375,0.000373,0.009470,19.381483,0.987340,0.094698,-38.520504,0.010398,0.000000
74.850006,4.687425,-38.476021,0.062379,0.000390,0.009904,20.850706,1.062186,0.099036,-38.476021,0.011013,0.000000
75.220001,5.452650,-38.564983,0.062418,0.000427,0.010857,24.254597,1.235588,0.108573,-38.564983,0.011629,0.000000
75.590004,5.774380,-38.564983,0.062414,0.000446,0.011334,25.685724,1.308493,0.113342,-38.564983,0.012254,0.000000
75.960007,6.348578,-38.609467,0.062452,0.000473,0.012002,28.239885,1.438608,0.120019,-38.609467,0.012869,0.000000
76.330002,6.815906,-38.520504,0.062461,0.000493,0.012531,30.318663,1.544506,0.125310,-38.520504,0.013485,0.000000
76.700005,7.397923,-38.476021,0.062483,0.000517,0.013138,32.907608,1.676393,0.131381,-38.476021,0.014101,0.000000
77.070007,8.289383,-38.476021,0.062508,0.000550,0.013971,36.873016,1.878401,0.139708,-38.476021,0.014716,0.000000
77.440002,8.550417,-38.520504,0.062539,0.000569,0.014448,38.034153,1.937552,0.144477,-38.520504,0.015333,0.000000
77.810005,9.330165,-38.476021,0.062539,0.000594,0.015098,41.502647,2.114246,0.150979,-38.476021,0.015948,0.000000
78.180000,9.892075,-38.431541,0.062560,0.000617,0.015662,44.002144,2.241576,0.156619,-38.431541,0.016564,0.000000
78.550003,10.525108,-38.431541,0.062582,0.000638,0.016217,46.818020,2.385024,0.162168,-38.431541,0.017180,0.000000
78.920006,11.508916,-38.431541,0.062595,0.000667,0.016954,51.194214,2.607958,0.169541,-38.431541,0.017804,0.000000
79.290001,12.051462,-38.476021,0.062625,0.000688,0.017483,53.607582,2.730901,0.174832,-38.476021,0.018420,0.000000
79.660004,12.786526,-38.476021,0.062642,0.000712,0.018081,56.877308,2.897468,0.180812,-38.476021,0.019036,0.000000
80.030006,13.567763,-38.431541,0.062651,0.000734,0.018645,60.352425,3.074499,0.186451,-38.431541,0.019651,0.000000
80.400002,14.286815,-38.431541,0.062672,0.000757,0.019235,63.550926,3.237439,0.192348,-38.431541,0.020267,0.000000
80.770004,14.925433,-38.431541,0.062689,0.000774,0.019669,66.391640,3.382151,0.196686,-38.431541,0.020883,0.000000
81.140007,16.431307,-38.476021,0.062711,0.000811,0.020605,73.090103,3.723387,0.206050,-38.476021,0.021498,0.000000
81.510002,16.929543,-38.431541,0.062728,0.000831,0.021099,75.306366,3.836289,0.210993,-38.431541,0.022114,0.000000
81.880005,17.708918,-38.431541,0.062746,0.000850,0.021603,78.773201,4.012898,0.216027,-38.431541,0.022730,0.000000
82.250008,19.063608,-38.387062,0.062754,0.000881,0.022366,84.799164,4.319875,0.223657,-38.387062,0.023354,0.000000
82.620003,19.760317,-38.387062,0.062763,0.000900,0.022868,87.898277,4.477752,0.228683,-38.387062,0.023970,0.000000
82.990005,21.138840,-38.431541,0.062789,0.000932,0.023666,94.030258,4.790130,0.236662,-38.431541,0.024586,0.000000
83.360001,21.654949,-38.476021,0.062810,0.000947,0.024057,96.326027,4.907082,0.240568,-38.476021,0.025201,0.000000
83.730003,22.918407,-38.431541,0.062819,0.000976,0.024785,101.946167,5.193385,0.247850,-38.431541,0.025818,0.000000
84.100006,24.139790,-38.342579,0.062832,0.001001,0.025427,107.379150,5.470154,0.254269,-38.342579,0.026433,0.000000
84.470001,25.087105,-38.431541,0.062840,0.001024,0.025999,111.593018,5.684819,0.259992,-38.431541,0.027048,0.000000
84.840004,26.633940,-38.431541,0.062871,0.001054,0.026780,118.473679,6.035337,0.267796,-38.431541,0.027665,0.000000
85.210007,27.479227,-38.387062,0.062892,0.001074,0.027291,122.233704,6.226882,0.272914,-38.387062,0.028280,0.000000
85.580002,28.382975,-38.387062,0.062905,0.001097,0.027864,126.253777,6.431674,0.278636,-38.387062,0.028904,0.000000
85.950005,30.179670,-38.298100,0.062918,0.001128,0.028644,134.245880,6.838811,0.286441,-38.298100,0.029520,0.000000
86.320007,30.970219,-38.342579,0.062940,0.001148,0.029156,137.762405,7.017952,0.291558,-38.342579,0.030136,0.000000
86.690002,32.569183,-38.387062,0.062948,0.001177,0.029893,144.874969,7.380282,0.298931,-38.387062,0.030752,0.000000
87.060005,33.754448,-38.342579,0.062970,0.001201,0.030500,150.147278,7.648867,0.305002,-38.342579,0.031368,0.000000
87.430008,34.538662,-38.298100,0.062987,0.001219,0.030969,153.635635,7.826572,0.309688,-38.298100,0.031983,0.000000
87.800003,36.291050,-38.298100,0.063000,0.001249,0.031723,161.430649,8.223670,0.317227,-38.298100,0.032599,0.000000
88.170006,37.290497,-38.298100,0.063009,0.001268,0.032209,165.876419,8.450148,0.322087,-38.298100,0.033215,0.000000
88.540001,38.944202,-38.387062,0.063030,0.001297,0.032954,173.232468,8.824883,0.329543,-38.387062,0.033830,0.000000
88.910004,40.176754,-38.298100,0.063056,0.001320,0.033536,178.715134,9.104182,0.335357,-38.298100,0.034455,0.000000
89.280006,41.203014,-38.298100,0.063052,0.001342,0.034099,183.280167,9.336737,0.340989,-38.298100,0.035070,0.000000
89.650002,42.620636,-38.298100,0.063060,0.001365,0.034671,189.586060,9.657973,0.346712,-38.298100,0.035686,0.000000
90.020004,43.972347,-38.298100,0.063073,0.001389,0.035270,195.598770,9.964276,0.352699,-38.298100,0.036302,0.000000
90.390007,44.788960,-38.387062,0.063095,0.001405,0.035677,199.231247,10.149323,0.356772,-38.387062,0.036918,0.000000
90.760002,46.990799,-38.342579,0.063108,0.001440,0.036588,209.025513,10.648267,0.365878,-38.342579,0.037533,0.000000
91.130005,48.107544,-38.253616,0.063134,0.001460,0.037091,213.993042,10.901325,0.370912,-38.253616,0.038149,0.000000
91.500008,49.222797,-38.253616,0.063138,0.001484,0.037681,218.953934,11.154045,0.376809,-38.253616,0.038765,0.000000
91.870003,51.163231,-38.342579,0.063151,0.001511,0.038383,227.585419,11.593754,0.383834,-38.342579,0.039380,0.000000
92.240005,51.912819,-38.298100,0.063168,0.001529,0.038825,230.919754,11.763613,0.388255,-38.298100,0.040005,0.000000
92.610001,54.648266,-38.298100,0.063190,0.001566,0.039771,243.087631,12.383474,0.397709,-38.298100,0.040621,0.000000
92.980003,55.543823,-38.253616,0.063194,0.001585,0.040248,247.071259,12.586410,0.402478,-38.253616,0.041236,0.000000
93.350006,56.807655,-38.209137,0.063203,0.001608,0.040846,252.693069,12.872799,0.408458,-38.209137,0.041852,0.000000
93.720001,58.646427,-38.253616,0.063224,0.001634,0.041505,260.872345,13.289471,0.415052,-38.253616,0.042468,0.000000
94.090004,59.396759,-38.298100,0.063233,0.001648,0.041852,264.209991,13.459498,0.418519,-38.298100,0.043083,0.000000
94.460007,61.687222,-38.253616,0.063250,0.001683,0.042745,274.398468,13.978523,0.427451,-38.253616,0.043700,0.000000
94.830002,63.025158,-38.253616,0.063259,0.001702,0.043231,280.349915,14.281705,0.432311,-38.253616,0.044315,0.000000
95.200005,64.633804,-38.253616,0.063272,0.001728,0.043890,287.505524,14.646229,0.438904,-38.253616,0.044940,0.000000
95.570007,66.452103,-38.298100,0.063284,0.001754,0.044558,295.593719,15.058262,0.445581,-38.298100,0.045555,0.000000
95.940002,67.764717,-38.298100,0.063302,0.001775,0.045078,301.432526,15.355704,0.450781,-38.298100,0.046171,0.000000
96.310005,68.611488,-38.209137,0.063310,0.001794,0.045564,305.199158,15.547585,0.455641,-38.209137,0.046787,0.000000
96.680008,71.587120,-38.164658,0.063323,0.001829,0.046466,318.435425,16.221874,0.464656,-38.164658,0.047402,0.000000
97.050003,72.711311,-38.209137,0.063340,0.001850,0.046995,323.436066,16.476618,0.469948,-38.209137,0.048018,0.000000
97.420006,74.458481,-38.253616,0.063349,0.001877,0.047672,331.207855,16.872534,0.476715,-38.253616,0.048634,0.000000
97.790001,75.843704,-38.253616,0.063362,0.001896,0.048166,337.369659,17.186428,0.481658,-38.253616,0.049250,0.000000
98.160004,77.235634,-38.253616,0.063375,0.001917,0.048686,343.561249,17.501846,0.486859,-38.253616,0.049865,0.000000
98.530006,80.028053,-38.164658,0.063388,0.001954,0.049622,355.982574,18.134615,0.496222,-38.164658,0.050490,0.000000
98.900002,81.128418,-38.209137,0.063401,0.001973,0.050126,360.877228,18.383963,0.501256,-38.209137,0.051105,0.000000
99.270004,82.863297,-38.209137,0.063401,0.001998,0.050750,368.594360,18.777092,0.507501,-38.209137,0.051721,0.000000
99.640007,84.275337,-38.253616,0.063422,0.002020,0.051296,374.875427,19.097065,0.512959,-38.253616,0.052337,0.000000
100.010002,85.761848,-38.209137,0.063431,0.002041,0.051834,381.487762,19.433912,0.518341,-38.209137,0.052953,0.000000
100.380005,88.232910,-38.164658,0.063435,0.002074,0.052683,392.479584,19.993864,0.526835,-38.164658,0.053568,0.000000
100.750008,89.396576,-38.209137,0.063448,0.002092,0.053126,397.655823,20.257555,0.531263,-38.209137,0.054184,0.000000
101.120003,90.961281,-38.209137,0.063466,0.002114,0.053689,404.615997,20.612122,0.536895,-38.209137,0.054800,0.000000
101.490005,92.745323,-38.164658,0.063470,0.002139,0.054331,412.551788,21.016390,0.543314,-38.164658,0.055415,0.000000
101.860008,94.067612,-38.164658,0.063478,0.002157,0.054800,418.433624,21.316027,0.548000,-38.164658,0.056040,0.000000
102.230003,96.043053,-38.209137,0.063491,0.002184,0.055485,427.220825,21.763668,0.554850,-38.209137,0.056655,0.000000
102.600006,98.342819,-38.164658,0.063504,0.002212,0.056188,437.450714,22.284801,0.561875,-38.164658,0.057272,0.000000
102.970001,99.688950,-38.164658,0.063504,0.002233,0.056725,443.438599,22.589838,0.567250,-38.164658,0.057887,0.000000
103.340004,101.185516,-38.120174,0.063526,0.002255,0.057272,450.095642,22.928965,0.572715,-38.120174,0.058503,0.000000
103.710007,103.410065,-38.164658,0.063547,0.002281,0.057939,459.990936,23.433054,0.579392,-38.164658,0.059119,0.000000
104.080002,104.754333,-38.120174,0.063556,0.002305,0.058538,465.970551,23.737673,0.585379,-38.120174,0.059734,0.000000
104.450005,107.435783,-38.120174,0.063552,0.002334,0.059292,477.898224,24.345297,0.592919,-38.120174,0.060350,0.000000
104.820007,108.257988,-38.120174,0.063569,0.002348,0.059648,481.555573,24.531610,0.596477,-38.120174,0.060966,0.000000
105.190002,110.563339,-38.164658,0.063586,0.002378,0.060402,491.810303,25.054010,0.604024,-38.164658,0.061590,0.000000
105.560005,112.457230,-38.120174,0.063599,0.002393,0.060792,500.234741,25.483173,0.607922,-38.120174,0.060966,0.000000
105.930008,111.753441,-38.164658,0.063604,0.002390,0.060714,497.104126,25.323692,0.607143,-38.164658,0.060922,0.000000
106.300003,111.272713,-38.120174,0.063599,0.002382,0.060498,494.965759,25.214758,0.604978,-38.120174,0.060307,0.000000
106.670006,110.748787,-38.164658,0.063621,0.002358,0.059899,492.635223,25.096033,0.598990,-38.164658,0.059691,0.000000
107.040009,110.377159,-38.031212,0.063616,0.002337,0.059362,490.982117,25.011822,0.593615,-38.031212,0.059075,0.000000
107.410004,110.060638,-38.075695,0.063608,0.002317,0.058841,489.574158,24.940096,0.588407,-38.075695,0.058451,0.000000
107.780006,109.674492,-38.120174,0.063621,0.002290,0.058173,487.856506,24.852594,0.581731,-38.120174,0.057835,0.000000
108.150002,109.417549,-38.164658,0.063608,0.002269,0.057627,486.713562,24.794371,0.576273,-38.164658,0.057219,0.000000
108.520004,109.115555,-38.031212,0.063621,0.002245,0.057029,485.370239,24.725939,0.570285,-38.031212,0.056604,0.000000
108.890007,108.868675,-38.075695,0.063612,0.002220,0.056387,484.272064,24.669994,0.563866,-38.075695,0.055988,0.000000
109.260002,108.570404,-38.075695,0.063629,0.002199,0.055867,482.945282,24.602406,0.558666,-38.075695,0.055372,0.000000
109.630005,108.421829,-38.031212,0.063616,0.002178,0.055312,482.284393,24.568737,0.553117,-38.031212,0.054757,0.000000
110.000008,108.096001,-38.075695,0.063621,0.002152,0.054661,480.835022,24.494904,0.546615,-38.075695,0.054141,0.000000
110.370003,107.662933,-38.075695,0.063629,0.002132,0.054158,478.908661,24.396769,0.541581,-38.075695,0.053516,0.000000
110.740005,106.297073,-38.075695,0.063634,0.002101,0.053378,472.833008,24.087261,0.533776,-38.075695,0.052901,0.000000
111.110008,105.726227,-38.075695,0.063629,0.002087,0.053014,470.293732,23.957905,0.530135,-38.075695,0.052285,0.000000
111.480003,104.145874,-38.075695,0.063621,0.002060,0.052319,463.263977,23.599792,0.523194,-38.075695,0.051669,0.000000
111.850006,102.135063,-38.075695,0.063625,0.002031,0.051591,454.319458,23.144136,0.515911,-38.075695,0.051054,0.000000
112.220009,100.413956,-38.031212,0.063625,0.002008,0.051010,446.663574,22.754128,0.510098,-38.031212,0.050438,0.000000
112.590004,98.609070,-38.075695,0.063634,0.001986,0.050447,438.635040,22.345135,0.504466,-38.075695,0.049822,0.000000
112.960007,96.522667,-37.986732,0.063621,0.001962,0.049839,429.354279,21.872349,0.498395,-37.986732,0.049206,0.000000
113.330002,94.564362,-38.031212,0.063634,0.001943,0.049363,420.643280,21.428591,0.493626,-38.031212,0.048590,0.000000
113.700005,92.582596,-37.986732,0.063629,0.001921,0.048799,411.827942,20.979517,0.487987,-37.986732,0.047966,0.000000
114.070007,89.723518,-37.986732,0.063621,0.001892,0.048061,399.110138,20.331640,0.480614,-37.986732,0.047351,0.000000
114.440002,87.344055,-37.986732,0.063621,0.001868,0.047446,388.525757,19.792446,0.474459,-37.986732,0.046734,0.000000
114.810005,84.716972,-37.942253,0.063625,0.001843,0.046804,376.839905,19.197140,0.468040,-37.942253,0.046119,0.000000
115.180008,83.059166,-38.075695,0.063616,0.001825,0.046362,369.465637,18.821476,0.463619,-38.075695,0.045504,0.000000
115.550003,80.797379,-37.986732,0.063616,0.001804,0.045824,359.404694,18.308949,0.458237,-37.986732,0.044887,0.000000
115.920006,77.716370,-37.986732,0.063621,0.001772,0.045018,345.699677,17.610781,0.450175,-37.986732,0.044272,0.000000
116.290009,75.570755,-37.942253,0.063625,0.001752,0.044497,336.155518,17.124578,0.444975,-37.942253,0.043656,0.000000
116.660004,72.979790,-37.986732,0.063621,0.001727,0.043864,324.630310,16.537457,0.438639,-37.986732,0.043040,0.000000
117.030006,70.906044,-37.986732,0.063625,0.001707,0.043370,315.405823,16.067539,0.433696,-37.986732,0.042416,0.000000
117.400009,68.610741,-37.986732,0.063625,0.001685,0.042797,305.195831,15.547416,0.427973,-37.986732,0.041800,0.000000
117.770004,65.906204,-37.942253,0.063625,0.001656,0.042069,293.165436,14.934560,0.420691,-37.942253,0.041184,0.000000
118.140007,63.368111,-37.942253,0.063608,0.001634,0.041514,281.875427,14.359420,0.415142,-37.942253,0.040569,0.000000
118.510002,60.926838,-37.942253,0.063616,0.001610,0.040898,271.016113,13.806219,0.408981,-37.942253,0.039953,0.000000
118.880005,57.765766,-37.986732,0.063604,0.001582,0.040178,256.954956,13.089910,0.401782,-37.986732,0.039337,0.000000
119.250008,55.804111,-37.897770,0.063595,0.001563,0.039701,248.229080,12.645392,0.397013,-37.897770,0.038722,0.000000
119.620003,53.857346,-37.942253,0.063599,0.001545,0.039233,239.569443,12.204248,0.392335,-37.942253,0.038106,0.000000
119.990005,50.550678,-37.853291,0.063578,0.001511,0.038383,224.860641,11.454947,0.383834,-37.853291,0.037490,0.000000
120.360008,48.225212,-37.897770,0.063569,0.001488,0.037802,214.516464,10.927989,0.378020,-37.897770,0.036866,0.000000
120.730003,45.208622,-37.897770,0.063578,0.001459,0.037065,201.097992,10.244420,0.370647,-37.897770,0.036250,0.000000
121.100006,42.915928,-37.986732,0.063565,0.001436,0.036467,190.899582,9.724888,0.364667,-37.986732,0.035634,0.000000
121.470009,40.895061,-37.897770,0.063560,0.001416,0.035955,181.910324,9.266953,0.359550,-37.897770,0.035019,0.000000
121.840004,37.963001,-37.853291,0.063565,0.001385,0.035175,168.867859,8.602539,0.351745,-37.853291,0.034402,0.000000
122.210007,36.557667,-37.897770,0.063543,0.001369,0.034776,162.616623,8.284086,0.347756,-37.897770,0.033787,0.000000
122.580009,33.354145,-37.897770,0.063539,0.001337,0.033952,148.366653,7.558157,0.339520,-37.897770,0.033172,0.000000
122.950005,31.136669,-37.897770,0.063530,0.001314,0.033371,138.502823,7.055670,0.333707,-37.897770,0.032555,0.000000
123.320007,29.046541,-37.853291,0.063526,0.001291,0.032781,129.205475,6.582040,0.327810,-37.853291,0.031940,0.000000
123.690002,26.534889,-37.808807,0.063504,0.001262,0.032044,118.033081,6.012892,0.320437,-37.808807,0.031315,0.000000
124.060005,25.104979,-37.853291,0.063496,0.001246,0.031636,111.672523,5.688869,0.316364,-37.853291,0.030699,0.000000
124.430008,22.293940,-37.897770,0.063496,0.001213,0.030821,99.168396,5.051879,0.308212,-37.897770,0.030084,0.000000
124.800003,20.473412,-37.853291,0.063487,0.001192,0.030266,91.070282,4.639341,0.302663,-37.853291,0.029468,0.000000
125.170006,18.719536,-37.853291,0.063491,0.001170,0.029728,83.268654,4.241907,0.297281,-37.853291,0.028852,0.000000
125.540009,16.448063,-37.853291,0.063474,0.001140,0.028957,73.164635,3.727184,0.289567,-37.853291,0.028237,0.000000
125.910004,15.062467,-37.764328,0.063448,0.001124,0.028558,67.001198,3.413204,0.285578,-37.764328,0.027621,0.000000
126.280006,12.937337,-37.853291,0.063461,0.001095,0.027803,57.548149,2.931643,0.278031,-37.853291,0.027005,0.000000
126.650009,11.199102,-37.853291,0.063444,0.001070,0.027170,49.816097,2.537753,0.271702,-37.853291,0.026390,0.000000
127.020004,9.747594,-37.853291,0.063435,0.001048,0.026624,43.359463,2.208836,0.266237,-37.853291,0.025765,0.000000
127.390007,8.101336,-37.808807,0.063422,0.001022,0.025956,36.036541,1.835789,0.259561,-37.808807,0.025149,0.000000
127.760010,7.001347,-37.808807,0.063409,0.001002,0.025462,31.143545,1.586528,0.254617,-37.808807,0.024534,0.000000
128.130005,5.806776,-37.853291,0.063384,0.000979,0.024872,25.829830,1.315834,0.248721,-37.853291,0.023918,0.000000
128.500000,4.529166,-37.808807,0.063371,0.000952,0.024187,20.146738,1.026324,0.241870,-37.808807,0.023302,0.000000
128.870010,3.620950,-37.853291,0.063358,0.000930,0.023615,16.106789,0.820519,0.236147,-37.853291,0.022687,0.000000
129.240005,3.002439,-37.764328,0.063345,0.000910,0.023120,13.355516,0.680362,0.231204,-37.764328,0.022070,0.000000
129.610001,1.974691,-37.853291,0.063323,0.000875,0.022218,8.783865,0.447471,0.222181,-37.853291,0.021455,0.000000
129.980011,1.624289,-37.853291,0.063306,0.000855,0.021715,7.225197,0.368069,0.217155,-37.853291,0.020840,0.000000
130.350006,1.101105,-37.808807,0.063284,0.000827,0.020996,4.897961,0.249514,0.209956,-37.808807,0.020215,0.000000
130.720001,0.959976,-37.719845,0.063263,0.000808,0.020527,4.270187,0.217534,0.205270,-37.719845,0.019599,0.000000
131.090012,0.698198,-37.764328,0.063233,0.000785,0.019937,3.105741,0.158214,0.199373,-37.764328,0.018984,0.000000
131.460007,0.554463,-37.808807,0.063211,0.000759,0.019278,2.466373,0.125643,0.192780,-37.808807,0.018367,0.000000
131.830002,0.473658,-37.764328,0.063194,0.000742,0.018845,2.106935,0.107332,0.188450,-37.764328,0.017752,0.000000
132.200012,0.372745,-37.764328,0.063164,0.000709,0.018021,1.658052,0.084465,0.180206,-37.764328,0.017136,0.000000
132.570007,0.321730,-37.675365,0.063142,0.000692,0.017569,1.431126,0.072905,0.175695,-37.675365,0.016520,0.000000
132.940002,0.274811,-37.808807,0.063099,0.000663,0.016841,1.222420,0.062273,0.168413,-37.808807,0.015905,0.000000
133.310013,0.257309,-37.764328,0.063082,0.000632,0.016061,1.144569,0.058307,0.160608,-37.764328,0.015280,0.000000
133.680008,0.266991,-37.719845,0.063047,0.000609,0.015463,1.187635,0.060501,0.154628,-37.719845,0.014665,0.000000
134.050003,0.238318,-37.764328,0.063017,0.000582,0.014794,1.060093,0.054004,0.147944,-37.764328,0.014049,0.000000
134.420013,0.237946,-37.719845,0.062996,0.000559,0.014187,1.058437,0.053919,0.141873,-37.719845,0.013433,0.000000
134.790009,0.193261,-37.719845,0.062974,0.000541,0.013737,0.859669,0.043794,0.137369,-37.719845,0.012817,0.000000
135.160004,0.187303,-37.764328,0.062948,0.000514,0.013060,0.833167,0.042444,0.130602,-37.764328,0.012202,0.000000
135.530014,0.180601,-37.719845,0.062918,0.000487,0.012375,0.803352,0.040925,0.123751,-37.719845,0.011586,0.000000
135.900009,0.180601,-37.719845,0.062901,0.000460,0.011690,0.803352,0.040925,0.116900,-37.719845,0.010970,0.000000
136.270004,0.186931,-37.719845,0.062875,0.000438,0.011126,0.831510,0.042359,0.111261,-37.719845,0.010355,0.000000
136.639999,0.167568,-37.719845,0.062849,0.000422,0.010719,0.745378,0.037971,0.107188,-37.719845,0.009730,0.000000
137.010010,0.149694,-37.764328,0.062827,0.000397,0.010086,0.665871,0.033921,0.100860,-37.764328,0.009114,0.000000
137.380005,0.164589,-37.719845,0.062802,0.000366,0.009288,0.732127,0.037296,0.092881,-37.719845,0.008499,0.000000
137.750000,0.202571,-37.675365,0.062776,0.000344,0.008750,0.901079,0.045903,0.087499,-37.675365,0.007883,0.000000
138.120010,0.177994,-37.719845,0.062750,0.000318,0.008065,0.791757,0.040334,0.080649,-37.719845,0.007267,0.000000
138.490005,0.167940,-37.630886,0.062737,0.000297,0.007553,0.747034,0.038056,0.075531,-37.630886,0.006652,0.000000
138.860001,0.149321,-37.675365,0.062707,0.000276,0.007016,0.664214,0.033837,0.070157,-37.675365,0.006035,0.000000
139.230011,0.168312,-37.675365,0.062672,0.000245,0.006226,0.748691,0.038140,0.062262,-37.675365,0.005420,0.000000
139.600006,0.182462,-37.675365,0.062651,0.000231,0.005871,0.811634,0.041347,0.058711,-37.675365,0.004805,0.000000
139.970001,0.173153,-37.630886,0.062625,0.000195,0.004960,0.770224,0.039237,0.049605,-37.630886,0.004180,0.000000
140.340012,0.179111,-37.675365,0.062608,0.000178,0.004518,0.796726,0.040587,0.045184,-37.675365,0.003564,0.000000
140.710007,0.149694,-37.630886,0.062582,0.000156,0.003972,0.665871,0.033921,0.039719,-37.630886,0.002948,0.000000
141.080002,0.177249,-37.675365,0.062556,0.000127,0.003226,0.788444,0.040165,0.032262,-37.675365,0.002333,0.000000
141.450012,0.171291,-37.541924,0.062539,0.000108,0.002732,0.761942,0.038815,0.027319,-37.541924,0.001717,0.000000
141.820007,0.166823,-37.630886,0.062504,0.000081,0.002047,0.742065,0.037803,0.020469,-37.630886,0.001101,0.000000
142.190002,0.186186,-37.719845,0.062465,0.000058,0.001474,0.828198,0.042190,0.014738,-37.719845,0.000485,0.000000
142.560013,0.182462,-37.630886,0.062448,0.000030,0.000754,0.811634,0.041347,0.007540,-37.630886,-0.000130,0.000000
142.930008,0.160492,-37.630886,0.062431,0.000008,0.000191,0.713906,0.036368,0.001908,-37.630886,-0.000746,0.000000
143.300003,0.182462,-37.586403,0.062405,-0.000019,-0.000486,0.811634,0.041347,-0.004860,-37.586403,-0.001370,0.000000
143.670013,0.164589,-37.586403,0.062383,-0.000038,-0.000971,0.732127,0.037296,-0.009712,-37.586403,-0.001986,0.000000
144.040009,0.161610,-37.675365,0.062349,-0.000071,-0.001813,0.718875,0.036621,-0.018130,-37.675365,-0.002602,0.000000
144.410004,0.162727,-37.586403,0.062310,-0.000095,-0.002411,0.723845,0.036874,-0.024110,-37.586403,-0.003218,0.000000
144.780014,0.192517,-37.586403,0.062293,-0.000115,-0.002923,0.856356,0.043625,-0.029227,-37.586403,-0.003833,0.000000
145.150009,0.193634,-37.541924,0.062276,-0.000145,-0.003677,0.861326,0.043878,-0.036774,-37.541924,-0.004449,0.000000
145.520004,0.201453,-37.586403,0.062237,-0.000163,-0.004145,0.896110,0.045650,-0.041452,-37.586403,-0.005065,0.000000
145.889999,0.200336,-37.541924,0.062215,-0.000195,-0.004960,0.891141,0.045397,-0.049605,-37.541924,-0.005680,0.000000
146.260010,0.172781,-37.675365,0.062198,-0.000217,-0.005524,0.768567,0.039153,-0.055244,-37.675365,-0.006297,0.000000
146.630005,0.203688,-37.630886,0.062172,-0.000236,-0.005993,0.906048,0.046156,-0.059930,-37.630886,-0.006920,0.000000
147.000000,0.199219,-37.586403,0.062146,-0.000267,-0.006791,0.886171,0.045144,-0.067909,-37.586403,-0.007536,0.000000
147.370010,0.214859,-37.541924,0.062116,-0.000285,-0.007241,0.955740,0.048688,-0.072413,-37.541924,-0.008152,0.000000
147.740005,0.186559,-37.630886,0.062086,-0.000315,-0.007996,0.829854,0.042275,-0.079960,-37.630886,-0.008768,0.000000
148.110001,0.169057,-37.586403,0.062060,-0.000336,-0.008533,0.752003,0.038309,-0.085334,-37.586403,-0.009384,0.000000
148.480011,0.185814,-37.541924,0.062056,-0.000358,-0.009089,0.826541,0.042106,-0.090890,-37.541924,-0.009999,0.000000
148.850006,0.204805,-37.586403,0.062025,-0.000385,-0.009791,0.911017,0.046409,-0.097908,-37.586403,-0.010615,0.000000
149.220001,0.209646,-37.586403,0.062000,-0.000407,-0.010329,0.932551,0.047506,-0.103290,-37.586403,-0.011231,0.000000
149.590012,0.192517,-37.586403,0.061961,-0.000435,-0.011057,0.856356,0.043625,-0.110572,-37.586403,-0.011847,0.000000
149.960007,0.183207,-37.586403,0.061944,-0.000458,-0.011639,0.814946,0.041515,-0.116386,-37.586403,-0.012471,0.000000
150.330002,0.154907,-37.541924,0.061939,-0.000476,-0.012081,0.689060,0.035102,-0.120806,-37.541924,-0.013087,0.000000
150.700012,0.195868,-37.497440,0.061896,-0.000508,-0.012896,0.871264,0.044384,-0.128959,-37.497440,-0.013702,0.000000
151.070007,0.206294,-37.497440,0.061866,-0.000529,-0.013433,0.917643,0.046747,-0.134333,-37.497440,-0.014318,0.000000
151.440002,0.208156,-37.586403,0.061844,-0.000552,-0.014015,0.925925,0.047169,-0.140147,-37.586403,-0.014934,0.000000
151.810013,0.191027,-37.541924,0.061823,-0.000580,-0.014735,0.849731,0.043287,-0.147346,-37.541924,-0.015550,0.000000
152.180008,0.177994,-37.541924,0.061801,-0.000599,-0.015202,0.791757,0.040334,-0.152024,-37.541924,-0.016165,0.000000
152.550003,0.174270,-37.452961,0.061780,-0.000621,-0.015784,0.775193,0.039490,-0.157838,-37.452961,-0.016781,0.000000
152.920013,0.196985,-37.586403,0.061745,-0.000649,-0.016486,0.876233,0.044637,-0.164862,-37.586403,-0.017397,0.000000
153.290009,0.192144,-37.541924,0.061728,-0.000666,-0.016911,0.854700,0.043540,-0.169109,-37.541924,-0.018021,0.000000
153.660004,0.187303,-37.452961,0.061711,-0.000696,-0.017674,0.833167,0.042444,-0.176739,-37.452961,-0.018637,0.000000
154.030014,0.177622,-37.497440,0.061681,-0.000717,-0.018203,0.790101,0.040250,-0.182031,-37.497440,-0.019252,0.000000
154.400009,0.167195,-37.497440,0.061646,-0.000743,-0.018862,0.743721,0.037887,-0.188624,-37.497440,-0.019868,0.000000
154.770004,0.177994,-37.452961,0.061603,-0.000777,-0.019730,0.791757,0.040334,-0.197299,-37.452961,-0.019816,0.000000
154.900009,0.172408,-37.452961,0.061616,-0.000776,-0.019712,0.766911,0.039068,-0.197125,-37.452961,-0.019816,0.000000