File: Data/AD Membrane New Dongle_07172023_135247.csv
Time (sec),S:Load (lbs),S:HL1 (DIM),S:LVDT (in),S:Position (in),Ch:Position (mm),Ch:Load (N),Ch:Stress (MPa),Ch:Strain (mm/mm),Ch:HL1 (DIM),Set Point (),Cycles ()
0.110000,0.006703,-37.319519,0.000022,-0.000000,-0.000000,0.029815,0.001519,-0.000000,-37.319519,-0.000069,0.000000
0.480000,0.032396,-37.275036,0.000017,0.000021,0.000538,0.144106,0.007341,0.005382,-37.275036,0.001145,0.000000
0.850000,0.010054,-37.275036,0.000138,0.000244,0.006192,0.044723,0.002278,0.061921,-37.275036,0.007303,0.000000
1.220000,0.003351,-37.319519,0.000375,0.000483,0.012280,0.014907,0.000759,0.122805,-37.319519,0.013460,0.000000
1.590000,-0.024577,-37.275036,0.000629,0.000723,0.018376,-0.109322,-0.005569,0.183764,-37.275036,0.019635,0.000000
1.960000,-0.055484,-37.363998,0.000888,0.000961,0.024413,-0.246803,-0.012573,0.244126,-37.363998,0.025792,0.000000
2.330000,0.021970,-37.319519,0.001155,0.001211,0.030770,0.097727,0.004978,0.307697,-37.319519,0.031966,0.000000
2.700000,0.007820,-37.319519,0.001410,0.001459,0.037048,0.034784,0.001772,0.370481,-37.319519,0.038124,0.000000
3.070000,0.036120,-37.363998,0.001681,0.001705,0.043318,0.160670,0.008185,0.433181,-37.363998,0.044281,0.000000
3.440000,0.016757,-37.363998,0.001927,0.001938,0.049232,0.074538,0.003797,0.492324,-37.363998,0.050456,0.000000
3.810000,0.030162,-37.363998,0.002190,0.002183,0.055442,0.134168,0.006835,0.554419,-37.363998,0.056613,0.000000
4.180000,0.040589,-37.408482,0.002440,0.002426,0.061608,0.180547,0.009197,0.616082,-37.408482,0.062788,0.000000
4.550000,0.051015,-37.363998,0.002708,0.002669,0.067791,0.226926,0.011560,0.677913,-37.363998,0.068945,0.000000
4.920000,0.045057,-37.408482,0.002940,0.002914,0.074018,0.200424,0.010210,0.740182,-37.408482,0.075102,0.000000
5.290000,0.037610,-37.452961,0.003216,0.003160,0.080253,0.167296,0.008522,0.802534,-37.452961,0.081277,0.000000
5.660000,0.010426,-37.497440,0.003458,0.003390,0.086107,0.046379,0.002363,0.861071,-37.497440,0.087434,0.000000
6.030000,-0.013033,-37.452961,0.003712,0.003631,0.092239,-0.057974,-0.002953,0.922386,-37.452961,0.093609,0.000000
6.400000,-0.017874,-37.452961,0.003988,0.003881,0.098587,-0.079507,-0.004050,0.985867,-37.452961,0.099766,0.000000
6.770000,0.083784,-37.452961,0.004264,0.004124,0.104744,0.372689,0.018986,1.047439,-37.452961,0.105923,0.000000
7.140000,0.051760,-37.541924,0.004510,0.004371,0.111031,0.230239,0.011729,1.110314,-37.541924,0.112098,0.000000
7.510000,0.049525,-37.497440,0.004756,0.004611,0.117128,0.220300,0.011223,1.171281,-37.497440,0.118255,0.000000
7.880001,0.044312,-37.452961,0.005001,0.004851,0.123216,0.197111,0.010041,1.232157,-37.452961,0.124430,0.000000
8.250000,0.052132,-37.497440,0.005269,0.005094,0.129381,0.231895,0.011813,1.293813,-37.497440,0.130587,0.000000
8.620001,0.062186,-37.497440,0.005527,0.005342,0.135678,0.276618,0.014092,1.356779,-37.497440,0.136744,0.000000
8.990001,0.049153,-37.541924,0.005782,0.005581,0.141766,0.218644,0.011138,1.417655,-37.541924,0.142919,0.000000
9.360001,0.041333,-37.541924,0.006040,0.005827,0.148001,0.183860,0.009366,1.480008,-37.541924,0.149076,0.000000
9.730000,0.048036,-37.586403,0.006295,0.006066,0.154072,0.213675,0.010885,1.540717,-37.586403,0.155234,0.000000
10.100000,0.011544,-37.541924,0.006545,0.006301,0.160047,0.051348,0.002616,1.600466,-37.541924,0.161408,0.000000
10.470000,-0.008192,-37.586403,0.006808,0.006549,0.166351,-0.036441,-0.001856,1.663514,-37.586403,0.167566,0.000000
10.840000,0.052132,-37.675365,0.007049,0.006797,0.172647,0.231895,0.011813,1.726472,-37.675365,0.173740,0.000000
11.210001,0.077453,-37.630886,0.007312,0.007042,0.178857,0.344530,0.017551,1.788567,-37.630886,0.179898,0.000000
11.580001,0.057345,-37.630886,0.007562,0.007277,0.184832,0.255085,0.012995,1.848323,-37.630886,0.186055,0.000000
11.950001,0.059207,-37.630886,0.007825,0.007517,0.190929,0.263367,0.013417,1.909290,-37.630886,0.192230,0.000000
12.320001,0.046174,-37.630886,0.008084,0.007764,0.197199,0.205393,0.010463,1.971991,-37.630886,0.198387,0.000000
12.690001,0.050270,-37.630886,0.008351,0.008012,0.203495,0.223613,0.011391,2.034949,-37.630886,0.204561,0.000000
13.060000,0.053622,-37.675365,0.008601,0.008257,0.209722,0.238521,0.012151,2.097218,-37.675365,0.210719,0.000000
13.430000,0.061441,-37.630886,0.008860,0.008494,0.215740,0.273305,0.013923,2.157398,-37.630886,0.216876,0.000000
13.800000,0.077081,-37.675365,0.009106,0.008737,0.221932,0.342874,0.017467,2.219319,-37.675365,0.223051,0.000000
14.170001,0.040961,-37.675365,0.009369,0.008976,0.228003,0.182203,0.009282,2.280028,-37.675365,0.229208,0.000000
14.540001,0.014895,-37.808807,0.009615,0.009215,0.234056,0.066256,0.003375,2.340556,-37.808807,0.235383,0.000000
14.910001,0.024949,-37.764328,0.009882,0.009469,0.240508,0.110978,0.005654,2.405081,-37.764328,0.241540,0.000000
15.280001,0.081177,-37.719845,0.010136,0.009707,0.246570,0.361094,0.018395,2.465700,-37.719845,0.247697,0.000000
15.650001,0.086390,-37.719845,0.010386,0.009943,0.252562,0.384284,0.019576,2.525623,-37.719845,0.253872,0.000000
16.020000,0.084901,-37.719845,0.010641,0.010188,0.258772,0.377658,0.019239,2.587718,-37.719845,0.260029,0.000000
16.390001,0.082667,-37.764328,0.010895,0.010432,0.264972,0.367720,0.018733,2.649722,-37.764328,0.266204,0.000000
16.760000,0.058835,-37.764328,0.011163,0.010677,0.271191,0.261710,0.013332,2.711908,-37.764328,0.272361,0.000000
17.130001,0.072613,-37.808807,0.011421,0.010926,0.277530,0.322997,0.016454,2.775297,-37.808807,0.278518,0.000000
17.500000,0.058462,-37.764328,0.011663,0.011161,0.283488,0.260054,0.013248,2.834879,-37.764328,0.284693,0.000000
17.870001,0.063303,-37.764328,0.011939,0.011404,0.289653,0.281587,0.014345,2.896535,-37.764328,0.290850,0.000000
18.240002,0.052132,-37.808807,0.012184,0.011648,0.295863,0.231895,0.011813,2.958630,-37.808807,0.297025,0.000000
18.610001,0.031279,-37.853291,0.012430,0.011889,0.301968,0.139137,0.007088,3.019680,-37.853291,0.303182,0.000000
18.980001,0.026438,-37.808807,0.012706,0.012139,0.308333,0.117604,0.005991,3.083334,-37.808807,0.309339,0.000000
19.350000,0.074847,-37.853291,0.012969,0.012382,0.314500,0.332935,0.016961,3.144998,-37.853291,0.315514,0.000000
19.720001,0.096444,-37.808807,0.013193,0.012616,0.320440,0.429006,0.021855,3.204398,-37.808807,0.321671,0.000000
20.090000,0.074102,-37.897770,0.013448,0.012855,0.326511,0.329623,0.016792,3.265108,-37.897770,0.327846,0.000000
20.460001,0.089742,-37.853291,0.013724,0.013100,0.332738,0.399191,0.020336,3.327377,-37.853291,0.334003,0.000000
20.830002,0.069634,-37.853291,0.013982,0.013348,0.339051,0.309746,0.015779,3.390509,-37.853291,0.340161,0.000000
21.200001,0.059207,-37.853291,0.014245,0.013594,0.345286,0.263367,0.013417,3.452861,-37.853291,0.346335,0.000000
21.570002,0.076709,-37.853291,0.014500,0.013837,0.351452,0.341217,0.017382,3.514525,-37.853291,0.352493,0.000000
21.940001,0.065538,-37.942253,0.014745,0.014075,0.357497,0.291525,0.014851,3.574970,-37.942253,0.358650,0.000000
22.310001,0.084901,-37.942253,0.015004,0.014317,0.363645,0.377658,0.019239,3.636451,-37.942253,0.364825,0.000000
22.680000,0.049898,-37.897770,0.015263,0.014561,0.369837,0.221957,0.011307,3.698372,-37.897770,0.370982,0.000000
23.050001,0.073357,-37.897770,0.015521,0.014802,0.375977,0.326310,0.016623,3.759771,-37.897770,0.377156,0.000000
23.420002,0.064793,-37.897770,0.015784,0.015055,0.382403,0.288213,0.014682,3.824031,-37.897770,0.383314,0.000000
23.790001,0.080805,-37.897770,0.016022,0.015284,0.388223,0.359438,0.018311,3.882227,-37.897770,0.389471,0.000000
24.160002,0.092721,-37.986732,0.016267,0.015523,0.394285,0.412442,0.021011,3.942846,-37.986732,0.395646,0.000000
24.530001,0.091231,-37.986732,0.016535,0.015765,0.400433,0.405817,0.020673,4.004328,-37.986732,0.401803,0.000000
24.900002,0.084156,-37.942253,0.016789,0.016017,0.406825,0.374345,0.019070,4.068247,-37.942253,0.407978,0.000000
25.270000,0.081550,-37.942253,0.017030,0.016260,0.412999,0.362750,0.018479,4.129994,-37.942253,0.414135,0.000000
25.640001,0.083411,-38.031212,0.017281,0.016504,0.419208,0.371032,0.018901,4.192081,-38.031212,0.420293,0.000000
26.010002,0.070378,-38.031212,0.017535,0.016741,0.425227,0.313059,0.015948,4.252269,-38.031212,0.426467,0.000000
26.380001,0.067772,-37.942253,0.017794,0.016988,0.431506,0.301464,0.015357,4.315060,-37.942253,0.432625,0.000000
26.750002,0.077826,-37.942253,0.018048,0.017233,0.437706,0.346187,0.017636,4.377065,-37.942253,0.438799,0.000000
27.120001,0.076336,-37.986732,0.018302,0.017475,0.443855,0.339561,0.017298,4.438554,-37.986732,0.444957,0.000000
27.490002,0.071495,-38.031212,0.018557,0.017721,0.450108,0.318028,0.016201,4.501081,-38.031212,0.451114,0.000000
27.860001,0.103519,-37.986732,0.018820,0.017962,0.456230,0.460478,0.023458,4.562305,-37.986732,0.457289,0.000000
28.230001,0.110222,-38.031212,0.019057,0.018192,0.462084,0.490293,0.024977,4.620842,-38.031212,0.463446,0.000000
28.600002,0.092721,-38.031212,0.019307,0.018437,0.468302,0.412442,0.021011,4.683020,-38.031212,0.469621,0.000000
28.970001,0.096072,-38.075695,0.019561,0.018684,0.474564,0.427350,0.021770,4.745637,-38.075695,0.475778,0.000000
29.340002,0.073730,-38.120174,0.019824,0.018930,0.480834,0.327966,0.016707,4.808338,-38.120174,0.481935,0.000000
29.710001,0.056228,-38.120174,0.020079,0.019171,0.486947,0.250116,0.012741,4.869472,-38.120174,0.488110,0.000000
30.080002,0.091604,-38.120174,0.020333,0.019416,0.493174,0.407473,0.020758,4.931741,-38.120174,0.494267,0.000000
30.450001,0.058462,-38.075695,0.020592,0.019659,0.499331,0.260054,0.013248,4.993313,-38.075695,0.500442,0.000000
30.820002,0.095700,-38.120174,0.020838,0.019902,0.505506,0.425693,0.021686,5.055060,-38.120174,0.506599,0.000000
31.190001,0.086763,-38.164658,0.021088,0.020147,0.511724,0.385940,0.019661,5.117239,-38.164658,0.512756,0.000000
31.560001,0.076336,-38.120174,0.021342,0.020384,0.517743,0.339561,0.017298,5.177426,-38.120174,0.518931,0.000000
31.930002,0.075592,-38.120174,0.021605,0.020636,0.524151,0.336248,0.017129,5.241512,-38.120174,0.525088,0.000000
32.300003,0.112084,-38.120174,0.021842,0.020868,0.530049,0.498575,0.025399,5.300488,-38.120174,0.531246,0.000000
32.670002,0.116925,-38.120174,0.022088,0.021109,0.536171,0.520108,0.026496,5.361712,-38.120174,0.537420,0.000000
33.040001,0.115063,-38.164658,0.022342,0.021352,0.542346,0.511826,0.026074,5.423459,-38.164658,0.543577,0.000000
33.410000,0.094210,-38.164658,0.022597,0.021597,0.548573,0.419068,0.021348,5.485728,-38.164658,0.549752,0.000000
33.780003,0.060697,-38.164658,0.022838,0.021837,0.554652,0.269992,0.013754,5.546521,-38.164658,0.555909,0.000000
34.150002,0.051387,-38.120174,0.023101,0.022084,0.560922,0.228582,0.011645,5.609222,-38.120174,0.562067,0.000000
34.520000,0.087135,-38.120174,0.023355,0.022326,0.567079,0.387596,0.019745,5.670794,-38.120174,0.568241,0.000000
34.890003,0.082667,-38.209137,0.023597,0.022574,0.573375,0.367720,0.018733,5.733753,-38.209137,0.574399,0.000000
35.260002,0.103147,-38.209137,0.023864,0.022817,0.579541,0.458821,0.023373,5.795408,-38.209137,0.580573,0.000000
35.630001,0.098679,-38.209137,0.024110,0.023058,0.585681,0.438945,0.022361,5.856814,-38.209137,0.586731,0.000000
36.000000,0.094583,-38.209137,0.024360,0.023298,0.591761,0.420724,0.021433,5.917608,-38.209137,0.592888,0.000000
36.370003,0.112456,-38.164658,0.024610,0.023542,0.597969,0.500231,0.025483,5.979695,-38.164658,0.599063,0.000000
36.740002,0.135171,-38.253616,0.024860,0.023775,0.603885,0.601271,0.030630,6.038846,-38.253616,0.605220,0.000000
37.110001,0.105754,-38.298100,0.025115,0.024025,0.610233,0.470416,0.023964,6.102325,-38.298100,0.611395,0.000000
37.480003,0.096444,-38.253616,0.025378,0.024271,0.616494,0.429006,0.021855,6.164935,-38.253616,0.617552,0.000000
37.850002,0.076336,-38.209137,0.025619,0.024505,0.622417,0.339561,0.017298,6.224169,-38.209137,0.623709,0.000000
38.220001,0.033886,-38.253616,0.025873,0.024747,0.628574,0.150732,0.007679,6.285742,-38.253616,0.629884,0.000000
38.590000,0.099423,-38.342579,0.026119,0.024996,0.634905,0.442257,0.022530,6.349048,-38.342579,0.636041,0.000000
38.960003,0.072985,-38.298100,0.026395,0.025242,0.641157,0.324653,0.016539,6.411574,-38.298100,0.642216,0.000000
39.330002,0.113574,-38.253616,0.026649,0.025487,0.647359,0.505200,0.025736,6.473586,-38.253616,0.648373,0.000000
39.700001,0.115063,-38.253616,0.026891,0.025730,0.653550,0.511826,0.026074,6.535499,-38.253616,0.654530,0.000000
40.070004,0.094583,-38.298100,0.027115,0.025962,0.659430,0.420724,0.021433,6.594301,-38.298100,0.660705,0.000000
40.440002,0.088997,-38.298100,0.027387,0.026215,0.665856,0.395878,0.020167,6.658561,-38.298100,0.666862,0.000000
40.810001,0.154535,-38.253616,0.027633,0.026448,0.671788,0.687404,0.035018,6.717878,-38.253616,0.673037,0.000000
41.180000,0.117670,-38.298100,0.027904,0.026694,0.678023,0.523421,0.026664,6.780231,-38.298100,0.679194,0.000000
41.550003,0.121766,-38.298100,0.028141,0.026939,0.684259,0.541641,0.027593,6.842590,-38.298100,0.685351,0.000000
41.920002,0.101658,-38.342579,0.028391,0.027176,0.690269,0.452196,0.023036,6.902687,-38.342579,0.691526,0.000000
42.290001,0.061814,-38.387062,0.028650,0.027418,0.696426,0.274961,0.014007,6.964260,-38.387062,0.697683,0.000000
42.660004,0.059952,-38.298100,0.028917,0.027666,0.702722,0.266680,0.013585,7.027218,-38.298100,0.703858,0.000000
43.030003,0.094210,-38.342579,0.029167,0.027911,0.708931,0.419068,0.021348,7.089313,-38.342579,0.710015,0.000000
43.400002,0.126607,-38.342579,0.029417,0.028156,0.715167,0.563174,0.028689,7.151665,-38.342579,0.716173,0.000000
43.770000,0.132565,-38.342579,0.029668,0.028401,0.721384,0.589677,0.030040,7.213843,-38.342579,0.722347,0.000000
44.140003,0.110222,-38.342579,0.029913,0.028632,0.727255,0.490293,0.024977,7.272554,-38.342579,0.728504,0.000000
44.510002,0.119159,-38.387062,0.030159,0.028875,0.733430,0.530046,0.027002,7.334301,-38.387062,0.734662,0.000000
44.880001,0.155652,-38.387062,0.030444,0.029125,0.739778,0.692373,0.035271,7.397781,-38.387062,0.740836,0.000000
45.250004,0.114691,-38.342579,0.030664,0.029363,0.745814,0.510170,0.025989,7.458143,-38.342579,0.746994,0.000000
45.620003,0.112456,-38.431541,0.030914,0.029611,0.752128,0.500231,0.025483,7.521275,-38.431541,0.753168,0.000000
45.990002,0.107243,-38.431541,0.031164,0.029854,0.758302,0.477042,0.024302,7.583022,-38.431541,0.759326,0.000000
46.360001,0.086390,-38.387062,0.031414,0.030089,0.764260,0.384284,0.019576,7.642604,-38.387062,0.765483,0.000000
46.730003,0.067399,-38.342579,0.031659,0.030332,0.770426,0.299807,0.015273,7.704260,-38.342579,0.771658,0.000000
47.100002,0.109105,-38.387062,0.031918,0.030580,0.776731,0.485324,0.024724,7.767308,-38.387062,0.777815,0.000000
47.470001,0.129213,-38.431541,0.032181,0.030828,0.783036,0.574769,0.029280,7.830357,-38.431541,0.783989,0.000000
47.840004,0.128468,-38.520504,0.032436,0.031072,0.789228,0.571456,0.029111,7.892278,-38.520504,0.790147,0.000000
48.210003,0.123255,-38.431541,0.032677,0.031307,0.795203,0.548267,0.027930,7.952026,-38.431541,0.796304,0.000000
48.580002,0.123628,-38.476021,0.032914,0.031543,0.801187,0.549923,0.028014,8.011866,-38.476021,0.802479,0.000000
48.950001,0.124000,-38.431541,0.033160,0.031793,0.807544,0.551580,0.028099,8.075437,-38.431541,0.808636,0.000000
49.320004,0.137778,-38.520504,0.033414,0.032036,0.813718,0.612866,0.031221,8.137183,-38.520504,0.814811,0.000000
49.690002,0.134426,-38.476021,0.033669,0.032278,0.819858,0.597959,0.030461,8.198582,-38.476021,0.820968,0.000000
50.060001,0.144480,-38.431541,0.033932,0.032523,0.826085,0.642681,0.032740,8.260851,-38.431541,0.827125,0.000000
50.430004,0.122510,-38.431541,0.034182,0.032760,0.832112,0.544954,0.027761,8.321122,-38.431541,0.833300,0.000000
50.800003,0.067027,-38.431541,0.034419,0.033001,0.838217,0.298151,0.015189,8.382173,-38.431541,0.839457,0.000000
51.170002,0.062186,-38.520504,0.034673,0.033249,0.844522,0.276618,0.014092,8.445221,-38.520504,0.845632,0.000000
51.540001,0.136661,-38.520504,0.034949,0.033494,0.850740,0.607897,0.030968,8.507400,-38.520504,0.851789,0.000000
51.910004,0.162354,-38.476021,0.035195,0.033738,0.856949,0.722188,0.036790,8.569494,-38.476021,0.857946,0.000000
52.280003,0.158258,-38.431541,0.035436,0.033974,0.862933,0.703968,0.035862,8.629333,-38.431541,0.864121,0.000000
52.650002,0.149694,-38.476021,0.035686,0.034211,0.868952,0.665871,0.033921,8.689521,-38.476021,0.870278,0.000000
53.020004,0.156769,-38.520504,0.035949,0.034459,0.875265,0.697342,0.035524,8.752653,-38.520504,0.876453,0.000000
53.390003,0.142991,-38.520504,0.036204,0.034708,0.881578,0.636056,0.032402,8.815784,-38.520504,0.882610,0.000000
53.760002,0.141129,-38.431541,0.036454,0.034949,0.887701,0.627774,0.031980,8.877009,-38.431541,0.888767,0.000000
54.130001,0.138895,-38.476021,0.036708,0.035191,0.893841,0.617835,0.031474,8.938408,-38.476021,0.894942,0.000000
54.500004,0.137033,-38.520504,0.036954,0.035434,0.900025,0.609553,0.031052,9.000245,-38.520504,0.901099,0.000000
54.870003,0.105009,-38.520504,0.037195,0.035670,0.906026,0.467103,0.023795,9.060259,-38.520504,0.907257,0.000000
55.240002,0.068516,-38.564983,0.037463,0.035916,0.912269,0.304777,0.015526,9.122694,-38.564983,0.913431,0.000000
55.610004,0.154535,-38.520504,0.037717,0.036162,0.918522,0.687404,0.035018,9.185221,-38.520504,0.919589,0.000000
55.980003,0.168685,-38.476021,0.037967,0.036407,0.924749,0.750347,0.038225,9.247490,-38.476021,0.925763,0.000000
56.350002,0.148949,-38.609467,0.038213,0.036645,0.930785,0.662558,0.033752,9.307852,-38.609467,0.931921,0.000000
56.720001,0.138150,-38.609467,0.038467,0.036884,0.936864,0.614523,0.031305,9.368645,-38.609467,0.938079,0.000000
57.090004,0.138523,-38.609467,0.038730,0.037131,0.943134,0.616179,0.031390,9.431345,-38.609467,0.944253,0.000000
57.460003,0.124745,-38.564983,0.038980,0.037376,0.949352,0.554892,0.028268,9.493524,-38.564983,0.950411,0.000000
57.830002,0.157513,-38.609467,0.039226,0.037617,0.955466,0.700655,0.035693,9.554665,-38.609467,0.956585,0.000000
58.200005,0.149694,-38.564983,0.039455,0.037857,0.961580,0.665871,0.033921,9.615798,-38.564983,0.962743,0.000000
58.570004,0.154535,-38.609467,0.039718,0.038101,0.967772,0.687404,0.035018,9.677719,-38.609467,0.968900,0.000000
58.940002,0.131447,-38.564983,0.039972,0.038345,0.973956,0.584707,0.029786,9.739556,-38.564983,0.975074,0.000000
59.310001,0.119904,-38.609467,0.040231,0.038584,0.980026,0.533359,0.027171,9.800259,-38.609467,0.981232,0.000000
59.680004,0.129213,-38.564983,0.040472,0.038836,0.986444,0.574769,0.029280,9.864435,-38.564983,0.987406,0.000000
60.050003,0.151928,-38.564983,0.040705,0.039072,0.992418,0.675809,0.034427,9.924184,-38.564983,0.993564,0.000000
60.420002,0.165706,-38.609467,0.040955,0.039315,0.998593,0.737096,0.037549,9.985930,-38.609467,0.999721,0.000000
60.790005,0.179483,-38.564983,0.041205,0.039554,1.004681,0.798382,0.040672,10.046814,-38.564983,1.005896,0.000000
61.160004,0.180973,-38.609467,0.041455,0.039797,1.010839,0.805008,0.041009,10.108387,-38.609467,1.012053,0.000000
61.530003,0.154535,-38.609467,0.041714,0.040042,1.017074,0.687404,0.035018,10.170739,-38.609467,1.018228,0.000000
61.900002,0.169802,-38.653946,0.041947,0.040291,1.023387,0.755316,0.038478,10.233871,-38.653946,1.024385,0.000000
62.270004,0.144108,-38.653946,0.042193,0.040527,1.029380,0.641025,0.032655,10.293801,-38.653946,1.030542,0.000000
62.640003,0.144853,-38.609467,0.042460,0.040772,1.035606,0.644338,0.032824,10.356063,-38.609467,1.036717,0.000000
63.010002,0.134799,-38.653946,0.042706,0.041015,1.041790,0.599615,0.030546,10.417901,-38.653946,1.042874,0.000000
63.380005,0.116553,-38.653946,0.042938,0.041256,1.047903,0.518452,0.026411,10.479034,-38.653946,1.049049,0.000000
63.750004,0.134054,-38.653946,0.043193,0.041504,1.054200,0.596302,0.030377,10.542000,-38.653946,1.055206,0.000000
64.120003,0.163471,-38.609467,0.043451,0.041746,1.060348,0.727157,0.037043,10.603481,-38.609467,1.061363,0.000000
64.490005,0.186559,-38.653946,0.043689,0.041981,1.066324,0.829854,0.042275,10.663238,-38.653946,1.067538,0.000000
64.860001,0.166823,-38.609467,0.043943,0.042225,1.072524,0.742065,0.037803,10.725242,-38.609467,1.073695,0.000000
65.230003,0.169429,-38.653946,0.044184,0.042467,1.078673,0.753660,0.038393,10.786731,-38.653946,1.079852,0.000000
65.600006,0.152673,-38.653946,0.044439,0.042714,1.084926,0.679122,0.034596,10.849257,-38.653946,1.086027,0.000000
65.970001,0.154535,-38.698429,0.044685,0.042958,1.091144,0.687404,0.035018,10.911436,-38.698429,1.092184,0.000000
66.340004,0.157886,-38.653946,0.044952,0.043198,1.097240,0.702312,0.035777,10.972403,-38.653946,1.098359,0.000000
66.710007,0.157886,-38.653946,0.045193,0.043439,1.103345,0.702312,0.035777,11.033453,-38.653946,1.104516,0.000000
67.080002,0.164961,-38.653946,0.045439,0.043684,1.109581,0.733783,0.037381,11.095805,-38.653946,1.110674,0.000000
67.450005,0.139267,-38.698429,0.045689,0.043926,1.115729,0.619492,0.031558,11.157295,-38.698429,1.116848,0.000000
67.820000,0.136288,-38.698429,0.045931,0.044168,1.121878,0.606241,0.030883,11.218784,-38.698429,1.123006,0.000000
68.190002,0.143736,-38.742908,0.046189,0.044420,1.128260,0.639369,0.032571,11.282605,-38.742908,1.129180,0.000000
68.560005,0.171664,-38.653946,0.046426,0.044649,1.134080,0.763598,0.038900,11.340802,-38.653946,1.135337,0.000000
68.930000,0.182462,-38.653946,0.046659,0.044889,1.140185,0.811634,0.041347,11.401853,-38.653946,1.141495,0.000000
69.300003,0.191772,-38.653946,0.046918,0.045135,1.146420,0.853044,0.043456,11.464205,-38.653946,1.147669,0.000000
69.670006,0.175387,-38.653946,0.047172,0.045383,1.152717,0.780162,0.039743,11.527170,-38.653946,1.153827,0.000000
70.040001,0.172781,-38.653946,0.047431,0.045624,1.158848,0.768567,0.039153,11.588478,-38.653946,1.160001,0.000000
70.410004,0.164216,-38.698429,0.047677,0.045867,1.165032,0.730470,0.037212,11.650315,-38.698429,1.166159,0.000000
70.780006,0.159748,-38.698429,0.047923,0.046109,1.171180,0.710594,0.036199,11.711798,-38.698429,1.172316,0.000000
71.150002,0.160120,-38.698429,0.048181,0.046355,1.177407,0.712250,0.036284,11.774066,-38.698429,1.178491,0.000000
71.520004,0.154535,-38.742908,0.048423,0.046599,1.183624,0.687404,0.035018,11.836245,-38.742908,1.184648,0.000000
71.890007,0.156024,-38.698429,0.048673,0.046842,1.189791,0.694030,0.035356,11.897908,-38.698429,1.190823,0.000000
72.260002,0.167940,-38.653946,0.048923,0.047082,1.195887,0.747034,0.038056,11.958876,-38.653946,1.196980,0.000000
72.630005,0.181718,-38.698429,0.049177,0.047326,1.202070,0.808321,0.041178,12.020705,-38.698429,1.203137,0.000000
73.000000,0.207039,-38.698429,0.049410,0.047557,1.207950,0.920956,0.046916,12.079500,-38.698429,1.209312,0.000000
73.370003,0.189538,-38.742908,0.049673,0.047807,1.214307,0.843105,0.042950,12.143071,-38.742908,1.215469,0.000000
73.740005,0.168685,-38.698429,0.049927,0.048051,1.220508,0.750347,0.038225,12.205075,-38.698429,1.221644,0.000000
74.110001,0.163844,-38.698429,0.050169,0.048291,1.226596,0.728814,0.037128,12.265959,-38.698429,1.227801,0.000000
74.480003,0.134426,-38.653946,0.050410,0.048535,1.232788,0.597959,0.030461,12.327880,-38.653946,1.233958,0.000000
74.850006,0.172036,-38.698429,0.050669,0.048780,1.239014,0.765255,0.038984,12.390141,-38.698429,1.240133,0.000000
75.220001,0.160120,-38.698429,0.050915,0.049024,1.245215,0.712250,0.036284,12.452153,-38.698429,1.246290,0.000000
75.590004,0.185814,-38.698429,0.051165,0.049267,1.251373,0.826541,0.042106,12.513725,-38.698429,1.252465,0.000000
75.960007,0.173153,-38.742908,0.051419,0.049511,1.257590,0.770224,0.039237,12.575904,-38.742908,1.258622,0.000000
76.330002,0.164961,-38.742908,0.051656,0.049747,1.263583,0.733783,0.037381,12.635826,-38.742908,1.264779,0.000000
76.700005,0.159748,-38.742908,0.051915,0.050001,1.270018,0.710594,0.036199,12.700177,-38.742908,1.270954,0.000000
77.070007,0.204805,-38.742908,0.052156,0.050229,1.275811,0.911017,0.046409,12.758109,-38.742908,1.277111,0.000000
77.440002,0.215976,-38.698429,0.052415,0.050475,1.282063,0.960709,0.048941,12.820635,-38.698429,1.283269,0.000000
77.810005,0.198847,-38.742908,0.052665,0.050720,1.288299,0.884515,0.045059,12.882988,-38.742908,1.289443,0.000000
78.180000,0.195868,-38.698429,0.052915,0.050964,1.294491,0.871264,0.044384,12.944908,-38.698429,1.295601,0.000000
78.550003,0.153790,-38.831871,0.053148,0.051204,1.300588,0.684091,0.034849,13.005876,-38.831871,1.301775,0.000000
78.920006,0.145225,-38.742908,0.053407,0.051449,1.306805,0.645994,0.032909,13.068054,-38.742908,1.307932,0.000000
79.290001,0.172036,-38.787388,0.053661,0.051693,1.313006,0.765255,0.038984,13.130058,-38.787388,1.314090,0.000000
79.660004,0.172781,-38.698429,0.053911,0.051936,1.319180,0.768567,0.039153,13.191805,-38.698429,1.320264,0.000000
80.030006,0.196985,-38.742908,0.054148,0.052184,1.325468,0.876233,0.044637,13.254680,-38.742908,1.326422,0.000000
80.400002,0.183952,-38.742908,0.054398,0.052421,1.331504,0.818259,0.041684,13.315041,-38.742908,1.332596,0.000000
80.770004,0.173526,-38.787388,0.054644,0.052660,1.337574,0.771880,0.039321,13.375743,-38.787388,1.338754,0.000000
81.140007,0.216348,-38.742908,0.054907,0.052905,1.343776,0.962366,0.049025,13.437755,-38.742908,1.344911,0.000000
81.510002,0.226030,-38.698429,0.055140,0.053140,1.349759,1.005432,0.051219,13.497594,-38.698429,1.351086,0.000000
81.880005,0.187676,-38.698429,0.055386,0.053393,1.356176,0.834823,0.042528,13.561763,-38.698429,1.357243,0.000000
82.250008,0.185069,-38.831871,0.055644,0.053637,1.362386,0.823228,0.041937,13.623858,-38.831871,1.363418,0.000000
82.620003,0.148577,-38.742908,0.055873,0.053869,1.368283,0.660902,0.033668,13.682827,-38.742908,1.369575,0.000000
82.990005,0.131075,-38.653946,0.056127,0.054116,1.374535,0.583051,0.029702,13.745353,-38.653946,1.375732,0.000000
83.360001,0.194378,-38.742908,0.056382,0.054361,1.380780,0.864638,0.044047,13.807796,-38.742908,1.381907,0.000000
83.730003,0.173153,-38.742908,0.056636,0.054609,1.387059,0.770224,0.039237,13.870587,-38.742908,1.388064,0.000000
84.100006,0.209273,-38.787388,0.056878,0.054852,1.393242,0.930894,0.047422,13.932418,-38.787388,1.394239,0.000000
84.470001,0.188420,-38.831871,0.057136,0.055097,1.399469,0.838136,0.042697,13.994687,-38.831871,1.400396,0.000000
84.840004,0.183580,-38.787388,0.057369,0.055327,1.405305,0.816603,0.041600,14.053050,-38.787388,1.406553,0.000000
85.210007,0.183952,-38.742908,0.057623,0.055580,1.411739,0.818259,0.041684,14.117393,-38.742908,1.412728,0.000000
85.580002,0.233478,-38.742908,0.057852,0.055813,1.417654,1.038560,0.052907,14.176543,-38.742908,1.418886,0.000000
85.950005,0.197357,-38.787388,0.058111,0.056061,1.423950,0.877889,0.044722,14.239502,-38.787388,1.425060,0.000000
86.320007,0.217465,-38.787388,0.058369,0.056306,1.430168,0.967335,0.049278,14.301680,-38.787388,1.431218,0.000000
86.690002,0.209646,-38.698429,0.058611,0.056546,1.436256,0.932551,0.047506,14.362563,-38.698429,1.437375,0.000000
87.060005,0.155652,-38.698429,0.058844,0.056782,1.442274,0.692373,0.035271,14.422744,-38.698429,1.443550,0.000000
87.430008,0.153417,-38.742908,0.059107,0.057033,1.448631,0.682435,0.034765,14.486315,-38.742908,1.449707,0.000000
87.800003,0.188793,-38.742908,0.059357,0.057277,1.454823,0.839792,0.042781,14.548235,-38.742908,1.455864,0.000000
88.170006,0.227520,-38.787388,0.059615,0.057521,1.461033,1.012058,0.051557,14.610331,-38.787388,1.462039,0.000000
88.540001,0.228637,-38.742908,0.059861,0.057763,1.467173,1.017027,0.051810,14.671729,-38.742908,1.468196,0.000000
88.910004,0.214486,-38.742908,0.060090,0.057999,1.473165,0.954084,0.048603,14.731651,-38.742908,1.474371,0.000000
89.280006,0.228637,-38.787388,0.060340,0.058240,1.479288,1.017027,0.051810,14.792876,-38.787388,1.480528,0.000000
89.650002,0.251724,-38.787388,0.060594,0.058489,1.485619,1.119723,0.057041,14.856190,-38.787388,1.486686,0.000000
90.020004,0.224168,-38.698429,0.060853,0.058730,1.491741,0.997150,0.050797,14.917414,-38.698429,1.492860,0.000000
90.390007,0.218583,-38.787388,0.061090,0.058977,1.498020,0.972304,0.049532,14.980198,-38.787388,1.499017,0.000000
90.760002,0.228637,-38.742908,0.061336,0.059220,1.504177,1.017027,0.051810,15.041771,-38.742908,1.505192,0.000000
91.130005,0.210390,-38.787388,0.061586,0.059453,1.510109,0.935863,0.047675,15.101088,-38.787388,1.511349,0.000000
91.500008,0.207784,-38.787388,0.061831,0.059698,1.516318,0.924269,0.047084,15.163182,-38.787388,1.517507,0.000000
91.870003,0.336997,-38.831871,0.062090,0.059944,1.522588,1.499038,0.076365,15.225883,-38.831871,1.523681,0.000000
92.240005,1.070571,-38.742908,0.062332,0.060194,1.528936,4.762137,0.242595,15.289363,-38.742908,1.529839,0.000000
92.610001,1.084349,-38.742908,0.062353,-0.000001,-0.000035,4.823423,0.245717,-0.000348,-38.742908,0.000191,0.000000
92.980003,1.078018,-38.742908,0.062340,-0.000001,-0.000035,4.795264,0.244282,-0.000348,-38.742908,0.000434,0.000000
93.350006,1.080997,-38.831871,0.062353,-0.000001,-0.000026,4.808516,0.244957,-0.000257,-38.831871,0.001049,0.000000
93.720001,1.122331,-38.698429,0.062362,0.000022,0.000564,4.992375,0.254324,0.005639,-38.698429,0.001665,0.000000
94.090004,1.623544,-38.698429,0.062392,0.000056,0.001414,7.221884,0.367900,0.014140,-38.698429,0.002281,0.000000
94.460007,1.789250,-38.787388,0.062409,0.000071,0.001804,7.958980,0.405450,0.018039,-38.787388,0.002897,0.000000
94.830002,2.226415,-38.787388,0.062448,0.000107,0.002706,9.903588,0.504513,0.027062,-38.787388,0.003512,0.000000
95.200005,2.512025,-38.787388,0.062470,0.000130,0.003304,11.174044,0.569233,0.033042,-38.787388,0.004137,0.000000
95.570007,2.847160,-38.653946,0.062478,0.000152,0.003868,12.664800,0.645176,0.038682,-38.653946,0.004752,0.000000
95.940002,3.216926,-38.831871,0.062504,0.000176,0.004475,14.309600,0.728966,0.044753,-38.831871,0.005368,0.000000
96.310005,3.523388,-38.698429,0.062517,0.000191,0.004839,15.672814,0.798411,0.048394,-38.698429,0.005984,0.000000
96.680008,4.318031,-38.742908,0.062543,0.000231,0.005863,19.207560,0.978480,0.058628,-38.742908,0.006599,0.000000
97.050003,4.608109,-38.787388,0.062560,0.000247,0.006262,20.497892,1.044212,0.062617,-38.787388,0.007216,0.000000
97.420006,5.301094,-38.787388,0.062582,0.000274,0.006964,23.580444,1.201245,0.069642,-38.787388,0.007831,0.000000
97.790001,5.777731,-38.698429,0.062603,0.000297,0.007545,25.700630,1.309253,0.075448,-38.698429,0.008447,0.000000
98.160004,6.237238,-38.698429,0.062616,0.000313,0.007953,27.744621,1.413378,0.079528,-38.698429,0.009063,0.000000
98.530006,7.280254,-38.831871,0.062646,0.000351,0.008907,32.384186,1.649729,0.089066,-38.831871,0.009687,0.000000
98.900002,7.756518,-38.742908,0.062668,0.000370,0.009392,34.502716,1.757652,0.093918,-38.742908,0.010302,0.000000
99.270004,8.508711,-38.742908,0.062685,0.000396,0.010060,37.848637,1.928102,0.100603,-38.742908,0.010919,0.000000
99.640007,9.254201,-38.698429,0.062702,0.000418,0.010623,41.164742,2.097032,0.106234,-38.698429,0.011534,0.000000
100.010002,9.843294,-38.787388,0.062715,0.000436,0.011075,43.785160,2.230522,0.110746,-38.787388,0.012150,0.000000
100.380005,11.098189,-38.698429,0.062746,0.000469,0.011916,49.367210,2.514886,0.119156,-38.698429,0.012766,0.000000
100.750008,11.707763,-38.698429,0.062758,0.000489,0.012427,52.078728,2.653017,0.124273,-38.698429,0.013381,0.000000
101.120003,12.575018,-38.742908,0.062771,0.000514,0.013060,55.936474,2.849540,0.130602,-38.742908,0.013997,0.000000
101.490005,13.403919,-38.698429,0.062784,0.000536,0.013616,59.623611,3.037371,0.136158,-38.698429,0.014613,0.000000
101.860008,14.279367,-38.698429,0.062802,0.000559,0.014196,63.517799,3.235751,0.141964,-38.698429,0.015237,0.000000
102.230003,15.128376,-38.787388,0.062814,0.000580,0.014735,67.294380,3.428139,0.147346,-38.787388,0.015853,0.000000
102.600006,16.656593,-38.742908,0.062853,0.000615,0.015610,74.092224,3.774438,0.156104,-38.742908,0.016469,0.000000
102.970001,17.110888,-38.742908,0.062866,0.000633,0.016070,76.113029,3.877383,0.160699,-38.742908,0.017084,0.000000
103.340004,17.886168,-38.698429,0.062875,0.000651,0.016538,79.561646,4.053063,0.165377,-38.698429,0.017700,0.000000
103.710007,19.454971,-38.742908,0.062892,0.000684,0.017370,86.540031,4.408560,0.173704,-38.742908,0.018316,0.000000
104.080002,20.230997,-38.831871,0.062905,0.000704,0.017891,89.991966,4.584409,0.178912,-38.831871,0.018931,0.000000
104.450005,21.407320,-38.742908,0.062935,0.000731,0.018559,95.224518,4.850968,0.185589,-38.742908,0.019547,0.000000
104.820007,22.223188,-38.698429,0.062948,0.000750,0.019061,98.853676,5.035847,0.190615,-38.698429,0.020163,0.000000
105.190002,23.364883,-38.653946,0.062957,0.000776,0.019712,103.932190,5.294558,0.197125,-38.653946,0.020787,0.000000
105.560005,24.625364,-38.698429,0.062965,0.000802,0.020380,109.539093,5.580187,0.203801,-38.698429,0.021404,0.000000
105.930008,25.638216,-38.742908,0.062991,0.000825,0.020961,114.044479,5.809703,0.209607,-38.742908,0.022019,0.000000
106.300003,27.064404,-38.653946,0.063013,0.000854,0.021690,120.388481,6.132882,0.216897,-38.653946,0.022634,0.000000
106.670006,28.290998,-38.742908,0.063034,0.000880,0.022357,125.844643,6.410832,0.223574,-38.742908,0.023251,0.000000
107.040009,28.845833,-38.653946,0.063039,0.000897,0.022791,128.312668,6.536559,0.227911,-38.653946,0.023866,0.000000
107.410004,30.643274,-38.742908,0.063060,0.000930,0.023615,136.308090,6.943865,0.236147,-38.742908,0.024482,0.000000
107.780006,31.490423,-38.742908,0.063078,0.000948,0.024083,140.076401,7.135832,0.240833,-38.742908,0.025098,0.000000
108.150002,33.148598,-38.698429,0.063099,0.000980,0.024881,147.452332,7.511580,0.248811,-38.698429,0.025713,0.000000
108.520004,34.270184,-38.653946,0.063112,0.001003,0.025487,152.441391,7.765734,0.254875,-38.653946,0.026338,0.000000
108.890007,35.062218,-38.698429,0.063112,0.001023,0.025991,155.964539,7.945212,0.259909,-38.698429,0.026954,0.000000
109.260002,36.399410,-38.742908,0.063138,0.001047,0.026606,161.912659,8.248224,0.266063,-38.742908,0.027569,0.000000
109.630005,37.846447,-38.742908,0.063151,0.001072,0.027240,168.349411,8.576128,0.272399,-38.742908,0.028185,0.000000
110.000008,38.714077,-38.787388,0.063159,0.001092,0.027734,172.208817,8.772735,0.277342,-38.787388,0.028801,0.000000
110.370003,40.503326,-38.698429,0.063194,0.001122,0.028506,180.167801,9.178185,0.285056,-38.698429,0.029416,0.000000
110.740005,41.394039,-38.742908,0.063207,0.001144,0.029052,184.129883,9.380024,0.290521,-38.742908,0.030032,0.000000
111.110008,42.850018,-38.787388,0.063215,0.001169,0.029685,190.606400,9.709953,0.296849,-38.787388,0.030648,0.000000
111.480003,44.254604,-38.787388,0.063237,0.001193,0.030301,196.854309,10.028237,0.303011,-38.787388,0.031263,0.000000
111.850006,44.974030,-38.698429,0.063250,0.001209,0.030717,200.054474,10.191260,0.307175,-38.698429,0.031888,0.000000
112.220009,44.343231,-38.742908,0.063241,0.001200,0.030492,197.248550,10.048320,0.304919,-38.742908,0.030717,0.000000
112.590004,43.912769,-38.742908,0.063259,0.001195,0.030362,195.333755,9.950776,0.303617,-38.742908,0.030171,0.000000
112.960007,43.487144,-38.742908,0.063250,0.001172,0.029763,193.440475,9.854328,0.297629,-38.742908,0.029546,0.000000
113.330002,43.175098,-38.742908,0.063267,0.001148,0.029157,192.052429,9.783617,0.291566,-38.742908,0.028931,0.000000
113.700005,43.002689,-38.742908,0.063263,0.001126,0.028610,191.285522,9.744548,0.286100,-38.742908,0.028315,0.000000
114.070007,42.818363,-38.742908,0.063272,0.001104,0.028038,190.465591,9.702780,0.280377,-38.742908,0.027699,0.000000
114.440002,42.651169,-38.742908,0.063254,0.001077,0.027344,189.721878,9.664893,0.273436,-38.742908,0.027083,0.000000
114.810005,42.559193,-38.742908,0.063263,0.001056,0.026814,189.312744,9.644052,0.268145,-38.742908,0.026468,0.000000
115.180008,42.445621,-38.787388,0.063259,0.001031,0.026190,188.807556,9.618316,0.261900,-38.787388,0.025852,0.000000
115.550003,42.345451,-38.698429,0.063259,0.001007,0.025584,188.361969,9.595616,0.255836,-38.698429,0.025236,0.000000
115.920006,42.191288,-38.698429,0.063267,0.000987,0.025063,187.676224,9.560682,0.250628,-38.698429,0.024621,0.000000
116.290009,42.068405,-38.698429,0.063272,0.000964,0.024473,187.129608,9.532837,0.244731,-38.698429,0.023996,0.000000
116.660004,41.576504,-38.742908,0.063263,0.000938,0.023823,184.941528,9.421371,0.238229,-38.742908,0.023381,0.000000
117.030006,40.866016,-38.742908,0.063280,0.000918,0.023319,181.781113,9.260372,0.233195,-38.742908,0.022765,0.000000
117.400009,39.558243,-38.698429,0.063276,0.000891,0.022644,175.963852,8.964026,0.226435,-38.698429,0.022149,0.000000
117.770004,38.465332,-38.698429,0.063276,0.000870,0.022089,171.102341,8.716369,0.220886,-38.698429,0.021533,0.000000
118.140007,37.154579,-38.742908,0.063272,0.000849,0.021577,165.271820,8.419348,0.215769,-38.742908,0.020918,0.000000
118.510002,35.509811,-38.787388,0.063272,0.000824,0.020935,157.955536,8.046638,0.209350,-38.787388,0.020302,0.000000
118.880005,34.330135,-38.698429,0.063272,0.000808,0.020527,152.708069,7.779320,0.205270,-38.698429,0.019686,0.000000
119.250008,32.730049,-38.698429,0.063263,0.000786,0.019955,145.590530,7.416735,0.199547,-38.698429,0.019071,0.000000
119.620003,30.467888,-38.742908,0.063263,0.000758,0.019244,135.527939,6.904122,0.192439,-38.742908,0.018446,0.000000
119.990005,28.687202,-38.787388,0.063263,0.000737,0.018723,127.607048,6.500613,0.187231,-38.787388,0.017830,0.000000
120.360008,27.063286,-38.787388,0.063272,0.000719,0.018255,120.383507,6.132628,0.182553,-38.787388,0.017214,0.000000
120.730003,24.419813,-38.742908,0.063276,0.000685,0.017405,108.624756,5.533609,0.174052,-38.742908,0.016599,0.000000
121.100006,22.857712,-38.653946,0.063272,0.000665,0.016894,101.676178,5.179632,0.168935,-38.653946,0.015983,0.000000
121.470009,20.661831,-38.742908,0.063267,0.000638,0.016200,91.908417,4.682038,0.162001,-38.742908,0.015367,0.000000
121.840004,19.087069,-38.698429,0.063259,0.000621,0.015766,84.903519,4.325191,0.157664,-38.698429,0.014751,0.000000
122.210007,17.303776,-38.787388,0.063267,0.000598,0.015177,76.971039,3.921092,0.151767,-38.787388,0.014136,0.000000
122.580009,15.434094,-38.742908,0.063263,0.000573,0.014552,68.654282,3.497416,0.145522,-38.742908,0.013511,0.000000
122.950005,13.434454,-38.698429,0.063267,0.000549,0.013953,59.759438,3.044291,0.139534,-38.698429,0.012896,0.000000
123.320007,11.746490,-38.698429,0.063241,0.000525,0.013330,52.250996,2.661793,0.133296,-38.698429,0.012280,0.000000
123.690002,9.763234,-38.742908,0.063241,0.000501,0.012723,43.429035,2.212380,0.127225,-38.742908,0.011664,0.000000
124.060005,7.936002,-38.698429,0.063220,0.000473,0.012011,35.301098,1.798324,0.120110,-38.698429,0.011049,0.000000
124.430008,6.230164,-38.742908,0.063220,0.000445,0.011300,27.713152,1.411775,0.113002,-38.742908,0.010433,0.000000
124.800003,4.824085,-38.653946,0.063198,0.000420,0.010667,21.458603,1.093153,0.106666,-38.653946,0.009817,0.000000
125.170006,3.588926,-38.742908,0.063172,0.000393,0.009973,15.964339,0.813262,0.099732,-38.742908,0.009201,0.000000
125.540009,2.773430,-38.698429,0.063164,0.000370,0.009392,12.336833,0.628468,0.093918,-38.698429,0.008586,0.000000
125.910004,2.233118,-38.698429,0.063159,0.000353,0.008967,9.933403,0.506032,0.089672,-38.698429,0.007961,0.000000
126.280006,1.533430,-38.698429,0.063129,0.000321,0.008152,6.821036,0.347480,0.081519,-38.698429,0.007346,0.000000
126.650009,1.145045,-38.698429,0.063103,0.000296,0.007510,5.093416,0.259471,0.075100,-38.698429,0.006730,0.000000
127.020004,0.884012,-38.742908,0.063078,0.000271,0.006885,3.932283,0.200320,0.068855,-38.742908,0.006114,0.000000
127.390007,0.700060,-38.742908,0.063052,0.000247,0.006262,3.114023,0.158636,0.062617,-38.742908,0.005498,0.000000
127.760010,0.582763,-38.742908,0.063021,0.000229,0.005819,2.592258,0.132056,0.058189,-38.742908,0.004883,0.000000
128.130005,0.460625,-38.742908,0.063013,0.000206,0.005229,2.048961,0.104379,0.052292,-38.742908,0.004267,0.000000
128.500000,0.398066,-38.742908,0.062961,0.000174,0.004414,1.770687,0.090203,0.044139,-38.742908,0.003651,0.000000
128.870010,0.378330,-38.698429,0.062948,0.000154,0.003911,1.682898,0.085731,0.039113,-38.698429,0.003035,0.000000
129.240005,0.309069,-38.698429,0.062922,0.000127,0.003226,1.374808,0.070036,0.032262,-38.698429,0.002411,0.000000
129.610001,0.300132,-38.742908,0.062909,0.000115,0.002914,1.335055,0.068011,0.029136,-38.742908,0.001796,0.000000
129.980011,0.241297,-38.653946,0.062862,0.000085,0.002151,1.073344,0.054679,0.021506,-38.653946,0.001179,0.000000
130.350006,0.232733,-38.698429,0.062836,0.000054,0.001370,1.035247,0.052738,0.013701,-38.698429,0.000564,0.000000
130.720001,0.239063,-38.698429,0.062797,0.000038,0.000954,1.063406,0.054172,0.009538,-38.698429,-0.000052,0.000000
131.090012,0.218583,-38.742908,0.062763,0.000005,0.000122,0.972304,0.049532,0.001219,-38.742908,-0.000668,0.000000
131.460007,0.228637,-38.698429,0.062737,-0.000015,-0.000382,1.017027,0.051810,-0.003815,-38.698429,-0.001283,0.000000
131.830002,0.185441,-38.698429,0.062724,-0.000035,-0.000884,0.824885,0.042022,-0.008842,-38.698429,-0.001899,0.000000
132.200012,0.219327,-38.742908,0.062711,-0.000051,-0.001300,0.975617,0.049700,-0.013005,-38.742908,-0.002515,0.000000
132.570007,0.214114,-38.742908,0.062655,-0.000085,-0.002168,0.952427,0.048519,-0.021680,-38.742908,-0.003139,0.000000
132.940002,0.225658,-38.787388,0.062620,-0.000114,-0.002905,1.003776,0.051135,-0.029053,-38.787388,-0.003755,0.000000
133.310013,0.221934,-38.698429,0.062586,-0.000137,-0.003468,0.987212,0.050291,-0.034685,-38.698429,-0.004371,0.000000
133.680008,0.215604,-38.653946,0.062556,-0.000162,-0.004119,0.959053,0.048856,-0.041195,-38.653946,-0.004986,0.000000
134.050003,0.200709,-38.698429,0.062530,-0.000180,-0.004570,0.892797,0.045481,-0.045699,-38.698429,-0.005602,0.000000
134.420013,0.202571,-38.787388,0.062495,-0.000212,-0.005394,0.901079,0.045903,-0.053942,-38.787388,-0.006218,0.000000
134.790009,0.188793,-38.742908,0.062478,-0.000228,-0.005784,0.839792,0.042781,-0.057841,-38.742908,-0.006834,0.000000
135.160004,0.196240,-38.698429,0.062431,-0.000264,-0.006712,0.872920,0.044469,-0.067121,-38.698429,-0.007449,0.000000
135.530014,0.188048,-38.653946,0.062409,-0.000287,-0.007284,0.836480,0.042612,-0.072844,-38.653946,-0.008065,0.000000
135.900009,0.226402,-38.698429,0.062388,-0.000305,-0.007753,1.007088,0.051304,-0.077530,-38.698429,-0.008689,0.000000
136.270004,0.221562,-38.698429,0.062353,-0.000338,-0.008594,0.985555,0.050207,-0.085940,-38.698429,-0.009306,0.000000
136.639999,0.212252,-38.742908,0.062336,-0.000351,-0.008907,0.944145,0.048097,-0.089066,-38.742908,-0.009921,0.000000
137.010010,0.212625,-38.698429,0.062306,-0.000388,-0.009843,0.945802,0.048181,-0.098430,-38.698429,-0.010536,0.000000
137.380005,0.206294,-38.698429,0.062280,-0.000408,-0.010372,0.917643,0.046747,-0.103721,-38.698429,-0.011153,0.000000
137.750000,0.218210,-38.698429,0.062250,-0.000426,-0.010832,0.970648,0.049447,-0.108316,-38.698429,-0.011768,0.000000
138.120010,0.223796,-38.742908,0.062207,-0.000460,-0.011690,0.995494,0.050713,-0.116900,-38.742908,-0.012384,0.000000
138.490005,0.244649,-38.742908,0.062189,-0.000476,-0.012089,1.088252,0.055438,-0.120890,-38.742908,-0.013000,0.000000
138.860001,0.219700,-38.653946,0.062181,-0.000507,-0.012887,0.977273,0.049785,-0.128868,-38.653946,-0.013615,0.000000
139.230011,0.186186,-38.698429,0.062138,-0.000529,-0.013442,0.828198,0.042190,-0.134417,-38.698429,-0.014240,0.000000
139.600006,0.201081,-38.742908,0.062120,-0.000551,-0.014006,0.894453,0.045566,-0.140056,-38.742908,-0.014856,0.000000
139.970001,0.215976,-38.698429,0.062086,-0.000578,-0.014691,0.960709,0.048941,-0.146907,-38.698429,-0.015471,0.000000
140.340012,0.229754,-38.698429,0.062073,-0.000599,-0.015202,1.021996,0.052063,-0.152024,-38.698429,-0.016087,0.000000
140.710007,0.201081,-38.698429,0.062047,-0.000628,-0.015940,0.894453,0.045566,-0.159397,-38.698429,-0.016703,0.000000
141.080002,0.214859,-38.698429,0.062030,-0.000649,-0.016486,0.955740,0.048688,-0.164862,-38.698429,-0.017318,0.000000
141.450012,0.185441,-38.698429,0.061991,-0.000669,-0.016997,0.824885,0.042022,-0.169972,-38.698429,-0.017934,0.000000
141.820007,0.214859,-38.742908,0.061969,-0.000699,-0.017752,0.955740,0.048688,-0.177519,-38.742908,-0.018550,0.000000
142.190002,0.233850,-38.698429,0.061939,-0.000719,-0.018273,1.040216,0.052991,-0.182727,-38.698429,-0.019166,0.000000
142.560013,0.221562,-38.698429,0.061931,-0.000741,-0.018818,0.985555,0.050207,-0.188185,-38.698429,-0.019790,0.000000
142.930008,0.209646,-38.653946,0.061892,-0.000771,-0.019582,0.932551,0.047506,-0.195815,-38.653946,-0.020406,0.000000
143.300003,0.190282,-38.698429,0.061862,-0.000789,-0.020050,0.846418,0.043119,-0.200501,-38.698429,-0.021021,0.000000
143.670013,0.183580,-38.698429,0.061844,-0.000812,-0.020631,0.816603,0.041600,-0.206315,-38.698429,-0.021637,0.000000
144.040009,0.211880,-38.742908,0.061810,-0.000842,-0.021377,0.942489,0.048013,-0.213771,-38.742908,-0.022253,0.000000
144.410004,0.195495,-38.653946,0.061806,-0.000858,-0.021802,0.869607,0.044300,-0.218018,-38.653946,-0.022868,0.000000
144.780014,0.216721,-38.742908,0.061771,-0.000889,-0.022582,0.964022,0.049110,-0.225822,-38.742908,-0.023485,0.000000
145.150009,0.194378,-38.698429,0.061758,-0.000900,-0.022852,0.864638,0.044047,-0.228517,-38.698429,-0.024100,0.000000
145.520004,0.188420,-38.787388,0.061724,-0.000935,-0.023762,0.838136,0.042697,-0.237616,-38.787388,-0.024716,0.000000
145.889999,0.208156,-38.698429,0.061681,-0.000970,-0.024629,0.925925,0.047169,-0.246291,-38.698429,-0.025340,0.000000
146.260010,0.195123,-38.698429,0.061672,-0.000990,-0.025158,0.867951,0.044216,-0.251582,-38.698429,-0.025956,0.000000
146.630005,0.193261,-38.698429,0.061637,-0.001015,-0.025791,0.859669,0.043794,-0.257910,-38.698429,-0.026571,0.000000
147.000000,0.186559,-38.698429,0.061612,-0.001037,-0.026329,0.829854,0.042275,-0.263292,-38.698429,-0.027188,0.000000
147.370010,0.154907,-38.787388,0.061599,-0.001057,-0.026858,0.689060,0.035102,-0.268576,-38.787388,-0.027803,0.000000
147.740005,0.154162,-38.698429,0.061560,-0.001089,-0.027673,0.685748,0.034934,-0.276729,-38.698429,-0.028419,0.000000
148.110001,0.180601,-38.698429,0.061521,-0.001111,-0.028228,0.803352,0.040925,-0.282277,-38.698429,-0.029035,0.000000
148.480011,0.168685,-38.653946,0.061512,-0.001138,-0.028914,0.750347,0.038225,-0.289136,-38.653946,-0.029650,0.000000
148.850006,0.179856,-38.653946,0.061478,-0.001155,-0.029329,0.800039,0.040756,-0.293292,-38.653946,-0.030275,0.000000
149.220001,0.144480,-38.787388,0.061452,-0.001178,-0.029919,0.642681,0.032740,-0.299188,-38.787388,-0.030891,0.000000
149.590012,0.172036,-38.742908,0.061443,-0.001209,-0.030717,0.765255,0.038984,-0.307167,-38.742908,-0.031506,0.000000
149.960007,0.176504,-38.698429,0.061413,-0.001229,-0.031220,0.785131,0.039996,-0.312201,-38.698429,-0.032122,0.000000
150.330002,0.180228,-38.698429,0.061387,-0.001252,-0.031810,0.801695,0.040840,-0.318098,-38.698429,-0.032738,0.000000
150.700012,0.185069,-38.698429,0.061353,-0.001279,-0.032495,0.823228,0.041937,-0.324948,-38.698429,-0.033353,0.000000
151.070007,0.150811,-38.698429,0.061344,-0.001301,-0.033041,0.670840,0.034174,-0.330414,-38.698429,-0.033969,0.000000
151.440002,0.180228,-38.653946,0.061310,-0.001327,-0.033717,0.801695,0.040840,-0.337174,-38.653946,-0.034585,0.000000
151.810013,0.178739,-38.698429,0.061288,-0.001350,-0.034281,0.795070,0.040503,-0.342813,-38.698429,-0.035200,0.000000
152.180008,0.173526,-38.698429,0.061271,-0.001370,-0.034793,0.771880,0.039321,-0.347930,-38.698429,-0.035825,0.000000
152.550003,0.170919,-38.698429,0.061228,-0.001404,-0.035669,0.760285,0.038731,-0.356688,-38.698429,-0.036441,0.000000
152.920013,0.166823,-38.698429,0.061228,-0.001420,-0.036068,0.742065,0.037803,-0.360678,-38.698429,-0.037056,0.000000
153.290009,0.155652,-38.698429,0.061202,-0.001441,-0.036605,0.692373,0.035271,-0.366052,-38.698429,-0.037673,0.000000
153.660004,0.176877,-38.653946,0.061167,-0.001474,-0.037438,0.786788,0.040081,-0.374379,-38.653946,-0.038288,0.000000
154.030014,0.172036,-38.698429,0.061146,-0.001491,-0.037880,0.765255,0.038984,-0.378800,-38.698429,-0.038903,0.000000
154.400009,0.182090,-38.742908,0.061111,-0.001527,-0.038791,0.809977,0.041262,-0.387906,-38.742908,-0.039520,0.000000
154.770004,0.178739,-38.698429,0.061086,-0.001547,-0.039285,0.795070,0.040503,-0.392849,-38.698429,-0.040135,0.000000
155.140015,0.177622,-38.653946,0.061068,-0.001567,-0.039814,0.790101,0.040250,-0.398141,-38.653946,-0.040751,0.000000
155.510010,0.168685,-38.653946,0.061038,-0.001598,-0.040586,0.750347,0.038225,-0.405862,-38.653946,-0.041375,0.000000
155.880005,0.164216,-38.698429,0.061021,-0.001616,-0.041037,0.730470,0.037212,-0.410373,-38.698429,-0.041991,0.000000
156.250000,0.184324,-38.653946,0.060986,-0.001642,-0.041696,0.819916,0.041768,-0.416959,-38.653946,-0.042607,0.000000
156.620010,0.186559,-38.698429,0.060969,-0.001668,-0.042364,0.829854,0.042275,-0.423636,-38.698429,-0.043223,0.000000
156.990005,0.186559,-38.698429,0.060939,-0.001693,-0.042997,0.829854,0.042275,-0.429972,-38.698429,-0.043838,0.000000
157.360001,0.204060,-38.653946,0.060909,-0.001723,-0.043769,0.907705,0.046241,-0.437685,-38.653946,-0.044454,0.000000
157.730011,0.178366,-38.653946,0.060879,-0.001743,-0.044263,0.793413,0.040418,-0.442628,-38.653946,-0.045070,0.000000
158.100006,0.185814,-38.787388,0.060866,-0.001769,-0.044922,0.826541,0.042106,-0.449222,-38.787388,-0.045685,0.000000
158.470001,0.193261,-38.698429,0.060831,-0.001792,-0.045512,0.859669,0.043794,-0.455118,-38.698429,-0.046301,0.000000
158.840012,0.197730,-38.698429,0.060823,-0.001814,-0.046076,0.879546,0.044806,-0.460758,-38.698429,-0.046925,0.000000
159.210007,0.194378,-38.653946,0.060788,-0.001844,-0.046847,0.864638,0.044047,-0.468472,-38.653946,-0.047541,0.000000
159.580002,0.189165,-38.653946,0.060758,-0.001866,-0.047385,0.841449,0.042865,-0.473854,-38.653946,-0.048157,0.000000
159.950012,0.194378,-38.742908,0.060732,-0.001890,-0.048018,0.864638,0.044047,-0.480182,-38.742908,-0.048773,0.000000
160.320007,0.188793,-38.742908,0.060715,-0.001915,-0.048634,0.839792,0.042781,-0.486336,-38.742908,-0.049388,0.000000
160.690002,0.177622,-38.698429,0.060698,-0.001932,-0.049085,0.790101,0.040250,-0.490848,-38.698429,-0.050005,0.000000
161.000015,0.173898,-38.698429,0.060672,-0.001943,-0.049345,0.773537,0.039406,-0.493452,-38.698429,-0.049501,0.000000