File: Data/AD_LVDT_01mm_06192023_134725.csv
Time (sec),S:Load (lbs),S:HL1 (DIM),S:LVDT (in),S:Position (in),Ch:Position (mm),Ch:Load (N),Ch:Stress (MPa),Ch:Strain (mm/mm),Ch:HL1 (DIM),Set Point (),Cycles ()
0.010000,-0.011544,-1294.618042,-0.000043,-0.000000,-0.000000,-0.051348,-0.002616,-0.000000,-1294.618042,0.000208,0.000000
0.240000,-0.016757,-1294.662598,-0.000043,-0.000000,-0.000000,-0.074538,-0.003797,-0.000000,-1294.662598,0.000208,0.000000
0.470000,0.009309,-1294.662598,-0.000060,0.000074,0.001874,0.041410,0.002110,0.018735,-1294.662598,0.002568,0.000000
0.700000,0.042078,-1294.573608,-0.000190,0.000201,0.005108,0.187173,0.009535,0.051081,-1294.573608,0.006400,0.000000
0.930000,0.026066,-1294.662598,0.000129,0.000367,0.009323,0.115948,0.005907,0.093230,-1294.662598,0.010216,0.000000
1.160000,-0.088252,-1294.618042,0.000194,0.000505,0.012835,-0.392566,-0.019998,0.128353,-1294.618042,0.014050,0.000000
1.390000,-0.044312,-1294.662598,0.000504,0.000656,0.016669,-0.197111,-0.010041,0.166687,-1294.662598,0.017883,0.000000
1.620000,0.020481,-1294.618042,0.000496,0.000810,0.020580,0.091102,0.004641,0.205800,-1294.618042,0.021715,0.000000
1.850000,0.023832,-1294.662598,0.000793,0.000957,0.024300,0.106009,0.005400,0.242998,-1294.662598,0.025549,0.000000
2.080000,-0.015640,-1294.573608,0.000845,0.001113,0.028272,-0.069568,-0.003544,0.282717,-1294.573608,0.029382,0.000000
2.310000,-0.093465,-1294.751465,0.000927,0.001265,0.032131,-0.415755,-0.021180,0.321307,-1294.751465,0.033215,0.000000
2.540000,-0.128841,-1294.662598,0.001220,0.001414,0.035904,-0.573113,-0.029196,0.359035,-1294.662598,0.037048,0.000000
2.770000,0.003351,-1294.618042,0.001341,0.001568,0.039823,0.014908,0.000759,0.398232,-1294.618042,0.040881,0.000000
3.000000,0.036865,-1294.618042,0.001483,0.001715,0.043553,0.163983,0.008354,0.435528,-1294.618042,0.044715,0.000000
3.230000,0.021970,-1294.662598,0.001647,0.001868,0.047455,0.097727,0.004978,0.474550,-1294.662598,0.048547,0.000000
3.460000,0.021598,-1294.662598,0.001746,0.002023,0.051392,0.096071,0.004894,0.513921,-1294.662598,0.052381,0.000000
3.690000,-0.051387,-1294.618042,0.001940,0.002166,0.055017,-0.228582,-0.011645,0.550172,-1294.618042,0.056214,0.000000
3.920000,-0.004468,-1294.662598,0.002164,0.002321,0.058946,-0.019877,-0.001013,0.589460,-1294.662598,0.060030,0.000000
4.150000,0.004841,-1294.618042,0.002333,0.002472,0.062796,0.021533,0.001097,0.627959,-1294.618042,0.063863,0.000000
4.380000,0.014523,-1294.662598,0.002393,0.002619,0.066516,0.064600,0.003291,0.665165,-1294.662598,0.067696,0.000000
4.610000,-0.005213,-1294.618042,0.002634,0.002780,0.070601,-0.023189,-0.001181,0.706012,-1294.618042,0.071529,0.000000
4.840000,-0.078571,-1294.618042,0.002746,0.002923,0.074252,-0.349499,-0.017804,0.742521,-1294.618042,0.075363,0.000000
5.070000,-0.083784,-1294.707031,0.002841,0.003068,0.077938,-0.372689,-0.018986,0.779378,-1294.707031,0.079195,0.000000
5.300000,-0.006703,-1294.618042,0.003014,0.003229,0.082022,-0.029815,-0.001519,0.820225,-1294.618042,0.083028,0.000000
5.530000,0.034258,-1294.662598,0.003182,0.003374,0.085700,0.152389,0.007763,0.856999,-1294.662598,0.086862,0.000000
5.760000,0.042823,-1294.662598,0.003436,0.003518,0.089351,0.190485,0.009704,0.893508,-1294.662598,0.090695,0.000000
5.990000,0.028673,-1294.662598,0.003548,0.003676,0.093375,0.127543,0.006497,0.933749,-1294.662598,0.094528,0.000000
6.220000,-0.084901,-1294.707031,0.003656,0.003823,0.097112,-0.377658,-0.019239,0.971121,-1294.707031,0.098361,0.000000
6.450000,0.000745,-1294.618042,0.004161,0.003977,0.101023,0.003313,0.000169,1.010234,-1294.618042,0.102194,0.000000
6.680000,0.012288,-1294.618042,0.003988,0.004130,0.104892,0.054661,0.002785,1.048916,-1294.618042,0.106010,0.000000
6.910000,0.039099,-1294.707031,0.004277,0.004282,0.108759,0.173922,0.008860,1.087590,-1294.707031,0.109843,0.000000
7.140000,0.042078,-1294.707031,0.004393,0.004438,0.112722,0.187173,0.009535,1.127225,-1294.707031,0.113676,0.000000
7.370000,-0.090486,-1294.662598,0.004381,0.004582,0.116382,-0.402504,-0.020505,1.163817,-1294.662598,0.117510,0.000000
7.600000,-0.044312,-1294.618042,0.004553,0.004729,0.120120,-0.197111,-0.010041,1.201197,-1294.618042,0.121342,0.000000
7.830000,0.042823,-1294.618042,0.004794,0.004886,0.124101,0.190485,0.009704,1.241006,-1294.618042,0.125176,0.000000
8.060000,0.045802,-1294.662598,0.004993,0.005028,0.127717,0.203737,0.010379,1.277167,-1294.662598,0.129009,0.000000
8.290000,0.008565,-1294.707031,0.005092,0.005192,0.131888,0.038097,0.001941,1.318877,-1294.707031,0.132842,0.000000
8.520000,-0.083784,-1294.662598,0.005226,0.005334,0.135478,-0.372689,-0.018986,1.354780,-1294.662598,0.136675,0.000000
8.750000,-0.128468,-1294.707031,0.005338,0.005484,0.139294,-0.571456,-0.029111,1.392940,-1294.707031,0.140508,0.000000
8.980000,0.027556,-1294.751465,0.005652,0.005642,0.143310,0.122573,0.006244,1.433097,-1294.751465,0.144342,0.000000
9.210000,0.064420,-1294.707031,0.005661,0.005782,0.146856,0.286557,0.014598,1.468562,-1294.707031,0.148175,0.000000
9.440001,0.057718,-1294.796021,0.005941,0.005944,0.150967,0.256741,0.013079,1.509673,-1294.796021,0.152007,0.000000
9.670000,-0.036865,-1294.662598,0.005980,0.006094,0.154800,-0.163983,-0.008354,1.547999,-1294.662598,0.155823,0.000000
9.900001,-0.029790,-1294.618042,0.006140,0.006242,0.158538,-0.132511,-0.006750,1.585379,-1294.618042,0.159657,0.000000
10.130000,-0.000372,-1294.618042,0.006463,0.006394,0.162397,-0.001656,-0.000084,1.623970,-1294.618042,0.163490,0.000000
10.360001,0.036865,-1294.707031,0.006459,0.006540,0.166126,0.163983,0.008354,1.661259,-1294.707031,0.167323,0.000000
10.590000,0.001117,-1294.751465,0.006696,0.006694,0.170020,0.004969,0.000253,1.700198,-1294.751465,0.171156,0.000000
10.820001,0.003724,-1294.662598,0.006829,0.006852,0.174044,0.016564,0.000844,1.740439,-1294.662598,0.174989,0.000000
11.050000,-0.116925,-1294.662598,0.006890,0.006997,0.177712,-0.520108,-0.026496,1.777122,-1294.662598,0.178823,0.000000
11.280001,-0.051015,-1294.707031,0.007205,0.007147,0.181546,-0.226926,-0.011560,1.815455,-1294.707031,0.182655,0.000000
11.510000,0.027556,-1294.751465,0.007265,0.007303,0.185500,0.122573,0.006244,1.855000,-1294.751465,0.186489,0.000000
11.740001,0.017129,-1294.751465,0.007549,0.007448,0.189168,0.076194,0.003882,1.891683,-1294.751465,0.190322,0.000000
11.970000,0.043568,-1294.662598,0.007627,0.007608,0.193253,0.193798,0.009873,1.932530,-1294.662598,0.194155,0.000000
12.200001,-0.026066,-1294.662598,0.007731,0.007753,0.196921,-0.115948,-0.005907,1.969213,-1294.662598,0.197988,0.000000
12.430000,-0.050643,-1294.751465,0.007847,0.007900,0.200650,-0.225270,-0.011476,2.006501,-1294.751465,0.201804,0.000000
12.660001,0.023459,-1294.796021,0.008075,0.008056,0.204614,0.104353,0.005316,2.046137,-1294.796021,0.205637,0.000000
12.890000,0.037982,-1294.707031,0.008123,0.008200,0.208290,0.168952,0.008607,2.082903,-1294.707031,0.209470,0.000000
13.120001,0.016757,-1294.751465,0.008382,0.008360,0.212332,0.074538,0.003797,2.123318,-1294.751465,0.213303,0.000000
13.350000,0.026066,-1294.662598,0.008502,0.008509,0.216139,0.115948,0.005907,2.161387,-1294.662598,0.217136,0.000000
13.580001,-0.058090,-1294.707031,0.008627,0.008653,0.219790,-0.258398,-0.013163,2.197904,-1294.707031,0.220970,0.000000
13.810000,-0.040589,-1294.796021,0.008778,0.008810,0.223762,-0.180547,-0.009197,2.237622,-1294.796021,0.224802,0.000000
14.040001,0.056228,-1294.751465,0.009002,0.008959,0.227561,0.250116,0.012742,2.275608,-1294.751465,0.228636,0.000000
14.270000,0.063303,-1294.840454,0.009136,0.009099,0.231125,0.281587,0.014345,2.311246,-1294.840454,0.232469,0.000000
14.500001,0.050643,-1294.751465,0.009278,0.009261,0.235235,0.225270,0.011476,2.352350,-1294.751465,0.236302,0.000000
14.730000,-0.070006,-1294.707031,0.009447,0.009410,0.239025,-0.311402,-0.015864,2.390252,-1294.707031,0.240135,0.000000
14.960001,-0.078943,-1294.796021,0.009645,0.009556,0.242728,-0.351156,-0.017889,2.427284,-1294.796021,0.243968,0.000000
15.190001,0.026811,-1294.751465,0.009722,0.009713,0.246709,0.119261,0.006075,2.467085,-1294.751465,0.247802,0.000000
15.420001,0.057718,-1294.796021,0.009882,0.009862,0.250499,0.256741,0.013079,2.504987,-1294.796021,0.251618,0.000000
15.650001,0.054739,-1294.751465,0.010016,0.010013,0.254340,0.243490,0.012404,2.543404,-1294.751465,0.255450,0.000000
15.880001,-0.067399,-1294.796021,0.010175,0.010167,0.258243,-0.299807,-0.015273,2.582426,-1294.796021,0.259283,0.000000
16.110001,-0.050643,-1294.796021,0.010309,0.010311,0.261911,-0.225270,-0.011476,2.619109,-1294.796021,0.263117,0.000000
16.340000,0.064420,-1294.796021,0.010499,0.010466,0.265840,0.286557,0.014598,2.658397,-1294.796021,0.266950,0.000000
16.570002,0.059580,-1294.751465,0.010632,0.010614,0.269595,0.265023,0.013501,2.695951,-1294.751465,0.270783,0.000000
16.800001,0.033886,-1294.751465,0.010904,0.010768,0.273497,0.150732,0.007679,2.734973,-1294.751465,0.274616,0.000000
17.030001,0.014895,-1294.796021,0.010956,0.010920,0.277356,0.066256,0.003375,2.773563,-1294.796021,0.278449,0.000000
17.260000,-0.105381,-1294.796021,0.011188,0.011064,0.281025,-0.468760,-0.023880,2.810247,-1294.796021,0.282282,0.000000
17.490002,-0.065538,-1294.840454,0.011275,0.011218,0.284945,-0.291525,-0.014851,2.849451,-1294.840454,0.286115,0.000000
17.720001,0.044685,-1294.796021,0.011645,0.011370,0.288795,0.198768,0.010126,2.887951,-1294.796021,0.289949,0.000000
17.950001,0.053994,-1294.751465,0.011632,0.011517,0.292533,0.240178,0.012235,2.925330,-1294.751465,0.293782,0.000000
18.180000,0.037610,-1294.796021,0.011745,0.011680,0.296678,0.167296,0.008522,2.966782,-1294.796021,0.297597,0.000000
18.410002,-0.018246,-1294.796021,0.011891,0.011824,0.300338,-0.081163,-0.004135,3.003382,-1294.796021,0.301431,0.000000
18.640001,-0.011171,-1294.796021,0.012107,0.011974,0.304145,-0.049692,-0.002531,3.041451,-1294.796021,0.305264,0.000000
18.870001,0.051015,-1294.840454,0.012180,0.012127,0.308013,0.226926,0.011560,3.080132,-1294.840454,0.309097,0.000000
19.100000,0.040589,-1294.751465,0.012387,0.012272,0.311707,0.180547,0.009198,3.117073,-1294.751465,0.312930,0.000000
19.330002,0.028673,-1294.796021,0.012503,0.012430,0.315714,0.127543,0.006497,3.157140,-1294.796021,0.316763,0.000000
19.560001,-0.053249,-1294.885010,0.012758,0.012582,0.319581,-0.236864,-0.012066,3.195814,-1294.885010,0.320596,0.000000
19.790001,-0.068889,-1294.840454,0.012810,0.012725,0.323207,-0.306433,-0.015610,3.232066,-1294.840454,0.324430,0.000000
20.020000,-0.021225,-1294.885010,0.013051,0.012882,0.327196,-0.094414,-0.004810,3.271958,-1294.885010,0.328262,0.000000
20.250002,0.037610,-1294.796021,0.013206,0.013030,0.330969,0.167296,0.008522,3.309686,-1294.796021,0.332096,0.000000
20.480001,0.068889,-1294.796021,0.013241,0.013183,0.334853,0.306433,0.015610,3.348534,-1294.796021,0.335929,0.000000
20.710001,0.065910,-1294.840454,0.013547,0.013334,0.338687,0.293182,0.014935,3.386868,-1294.840454,0.339762,0.000000
20.940001,-0.040961,-1294.840454,0.013741,0.013478,0.342338,-0.182203,-0.009282,3.423377,-1294.840454,0.343595,0.000000
21.170000,-0.034631,-1294.840454,0.013715,0.013630,0.346214,-0.154045,-0.007847,3.462142,-1294.840454,0.347411,0.000000
21.400002,0.043940,-1294.840454,0.013874,0.013784,0.350125,0.195455,0.009957,3.501255,-1294.840454,0.351244,0.000000
21.630001,0.033886,-1294.751465,0.014125,0.013935,0.353941,0.150732,0.007679,3.539414,-1294.751465,0.355077,0.000000
21.860001,0.069634,-1294.885010,0.014206,0.014091,0.357913,0.309746,0.015779,3.579133,-1294.885010,0.358910,0.000000
22.090000,-0.054366,-1294.840454,0.014426,0.014238,0.361642,-0.241834,-0.012320,3.616422,-1294.840454,0.362744,0.000000
22.320002,-0.055856,-1294.885010,0.014500,0.014387,0.365441,-0.248459,-0.012657,3.654407,-1294.885010,0.366577,0.000000
22.550001,0.062559,-1294.840454,0.014651,0.014538,0.369274,0.278275,0.014176,3.692740,-1294.840454,0.370409,0.000000
22.780001,0.072985,-1294.840454,0.014784,0.014683,0.372960,0.324654,0.016539,3.729598,-1294.840454,0.374243,0.000000
23.010000,0.051760,-1294.885010,0.015000,0.014838,0.376879,0.230239,0.011729,3.768794,-1294.885010,0.378076,0.000000
23.240002,0.035748,-1294.885010,0.015211,0.014995,0.380869,0.159014,0.008101,3.808687,-1294.885010,0.381910,0.000000
23.470001,-0.070751,-1294.885010,0.015250,0.015136,0.384459,-0.314715,-0.016032,3.844590,-1294.885010,0.385742,0.000000
23.700001,0.023832,-1294.885010,0.015521,0.015291,0.388388,0.106009,0.005400,3.883878,-1294.885010,0.389575,0.000000
23.930000,0.060324,-1294.840454,0.015629,0.015442,0.392238,0.268336,0.013670,3.922378,-1294.840454,0.393391,0.000000
24.160002,0.094955,-1294.885010,0.015784,0.015588,0.395923,0.422381,0.021517,3.959235,-1294.885010,0.397225,0.000000
24.390001,0.065165,-1294.973877,0.015884,0.015753,0.400121,0.289869,0.014767,4.001209,-1294.973877,0.401057,0.000000
24.620001,-0.038354,-1294.929443,0.016022,0.015895,0.403729,-0.170609,-0.008691,4.037287,-1294.929443,0.404891,0.000000
24.850000,0.002607,-1294.885010,0.016224,0.016045,0.407536,0.011595,0.000591,4.075356,-1294.885010,0.408724,0.000000
25.080002,0.069634,-1294.885010,0.016341,0.016200,0.411490,0.309746,0.015779,4.114900,-1294.885010,0.412557,0.000000
25.310001,0.071868,-1294.796021,0.016444,0.016344,0.415142,0.319684,0.016285,4.151417,-1294.796021,0.416390,0.000000
25.540001,0.041333,-1294.929443,0.016638,0.016501,0.419130,0.183860,0.009366,4.191302,-1294.929443,0.420223,0.000000
25.770000,-0.065165,-1294.973877,0.016841,0.016649,0.422886,-0.289869,-0.014767,4.228856,-1294.973877,0.424057,0.000000
26.000002,-0.102402,-1294.885010,0.016931,0.016802,0.426762,-0.455509,-0.023205,4.267621,-1294.885010,0.427889,0.000000
26.230001,0.067399,-1294.885010,0.017156,0.016954,0.430639,0.299808,0.015273,4.306386,-1294.885010,0.431723,0.000000
26.460001,0.086390,-1294.885010,0.017276,0.017100,0.434333,0.384284,0.019576,4.343334,-1294.885010,0.435556,0.000000
26.690001,0.063676,-1294.929443,0.017410,0.017260,0.438392,0.283244,0.014429,4.383915,-1294.929443,0.439389,0.000000
26.920002,0.046174,-1294.929443,0.017595,0.017408,0.442155,0.205393,0.010463,4.421552,-1294.929443,0.443204,0.000000
27.150002,-0.007447,-1294.973877,0.018001,0.017555,0.445901,-0.033128,-0.001688,4.459015,-1294.973877,0.447038,0.000000
27.380001,0.024577,-1294.885010,0.018005,0.017703,0.449665,0.109322,0.005569,4.496652,-1294.885010,0.450871,0.000000
27.610001,0.054739,-1294.973877,0.017979,0.017856,0.453533,0.243490,0.012404,4.535334,-1294.973877,0.454704,0.000000
27.840002,0.049898,-1295.018433,0.018272,0.018003,0.457271,0.221957,0.011307,4.572713,-1295.018433,0.458537,0.000000
28.070002,0.040589,-1294.929443,0.018367,0.018166,0.461407,0.180547,0.009198,4.614075,-1294.929443,0.462370,0.000000
28.300001,-0.043568,-1294.929443,0.018483,0.018309,0.465042,-0.193798,-0.009873,4.650417,-1294.929443,0.466204,0.000000
28.530001,-0.045429,-1294.929443,0.018583,0.018458,0.468823,-0.202080,-0.010294,4.688228,-1294.929443,0.470037,0.000000
28.760002,0.042823,-1295.018433,0.018755,0.018616,0.472846,0.190485,0.009704,4.728462,-1295.018433,0.473870,0.000000
28.990002,0.069261,-1295.018433,0.019018,0.018760,0.476515,0.308090,0.015695,4.765152,-1295.018433,0.477703,0.000000
29.220001,0.070378,-1295.062866,0.019113,0.018913,0.480392,0.313059,0.015948,4.803917,-1295.062866,0.481536,0.000000
29.450001,0.039472,-1294.973877,0.019423,0.019061,0.484146,0.175578,0.008944,4.841464,-1294.973877,0.485369,0.000000
29.680002,-0.046174,-1295.018433,0.019367,0.019211,0.487971,-0.205393,-0.010463,4.879706,-1295.018433,0.489185,0.000000
29.910002,0.065538,-1295.018433,0.019544,0.019367,0.491926,0.291526,0.014851,4.919258,-1295.018433,0.493018,0.000000
30.140001,0.063303,-1294.973877,0.019777,0.019516,0.495698,0.281587,0.014345,4.956978,-1294.973877,0.496851,0.000000
30.370001,0.081177,-1295.018433,0.019980,0.019671,0.499635,0.361094,0.018395,4.996349,-1295.018433,0.500685,0.000000
30.600002,0.085646,-1294.973877,0.019958,0.019822,0.503486,0.380971,0.019408,5.034856,-1294.973877,0.504517,0.000000
30.830002,-0.039844,-1294.929443,0.020234,0.019968,0.507197,-0.177234,-0.009029,5.071971,-1294.929443,0.508351,0.000000
31.060001,0.013778,-1294.973877,0.020320,0.020116,0.510935,0.061287,0.003122,5.109351,-1294.973877,0.512184,0.000000
31.290001,0.088625,-1295.018433,0.020566,0.020271,0.514872,0.394222,0.020083,5.148721,-1295.018433,0.516017,0.000000
31.520002,0.078571,-1295.018433,0.020708,0.020415,0.518540,0.349499,0.017804,5.185404,-1295.018433,0.519850,0.000000
31.750002,0.044312,-1295.018433,0.020898,0.020577,0.522668,0.197111,0.010041,5.226683,-1295.018433,0.523683,0.000000
31.980001,-0.050643,-1294.973877,0.021045,0.020720,0.526285,-0.225270,-0.011476,5.262851,-1294.973877,0.527517,0.000000
32.210003,-0.082667,-1294.929443,0.021135,0.020869,0.530084,-0.367720,-0.018733,5.300836,-1294.929443,0.531349,0.000000
32.440002,0.072985,-1295.062866,0.021299,0.021028,0.534107,0.324654,0.016539,5.341070,-1295.062866,0.535183,0.000000
32.670002,0.108360,-1294.973877,0.021484,0.021168,0.537663,0.482011,0.024555,5.376633,-1294.973877,0.538999,0.000000
32.900002,0.089369,-1294.973877,0.021855,0.021333,0.541852,0.397535,0.020251,5.418516,-1294.973877,0.542832,0.000000
33.130001,-0.018991,-1294.973877,0.021674,0.021477,0.545520,-0.084476,-0.004303,5.455199,-1294.973877,0.546664,0.000000
33.360001,0.022715,-1294.929443,0.021950,0.021627,0.549327,0.101040,0.005147,5.493268,-1294.929443,0.550498,0.000000
33.590000,0.036120,-1295.018433,0.021997,0.021779,0.553178,0.160671,0.008185,5.531775,-1295.018433,0.554331,0.000000
33.820004,0.080060,-1295.018433,0.022101,0.021928,0.556959,0.356125,0.018142,5.569586,-1295.018433,0.558164,0.000000
34.050003,0.039472,-1295.018433,0.022321,0.022077,0.560757,0.175578,0.008944,5.607572,-1295.018433,0.561997,0.000000
34.280003,0.050643,-1295.018433,0.022476,0.022236,0.564807,0.225270,0.011476,5.648070,-1295.018433,0.565830,0.000000
34.510002,-0.061069,-1295.062866,0.022562,0.022385,0.568571,-0.271649,-0.013838,5.685707,-1295.062866,0.569664,0.000000
34.740002,-0.014150,-1295.062866,0.022829,0.022532,0.572309,-0.062943,-0.003206,5.723087,-1295.062866,0.573496,0.000000
34.970001,0.067027,-1295.062866,0.023067,0.022688,0.576263,0.298151,0.015189,5.762631,-1295.062866,0.577330,0.000000
35.200001,0.079688,-1295.107422,0.023062,0.022834,0.579992,0.354469,0.018057,5.799920,-1295.107422,0.581163,0.000000
35.430000,0.087880,-1295.018433,0.023317,0.022993,0.584033,0.390909,0.019914,5.840335,-1295.018433,0.584979,0.000000
35.660000,-0.001862,-1295.018433,0.023377,0.023139,0.587719,-0.008282,-0.000422,5.877192,-1295.018433,0.588812,0.000000
35.890003,0.004096,-1295.107422,0.023532,0.023286,0.591475,0.018220,0.000928,5.914746,-1295.107422,0.592645,0.000000
36.120003,0.077453,-1295.018433,0.023782,0.023440,0.595385,0.344530,0.017551,5.953852,-1295.018433,0.596478,0.000000
36.350002,0.076336,-1295.018433,0.023817,0.023584,0.599037,0.339561,0.017298,5.990368,-1295.018433,0.600312,0.000000
36.580002,0.045802,-1295.107422,0.024114,0.023748,0.603190,0.203737,0.010379,6.031904,-1295.107422,0.604144,0.000000
36.810001,0.038727,-1295.018433,0.024157,0.023894,0.606911,0.172265,0.008776,6.069109,-1295.018433,0.607978,0.000000
37.040001,-0.014150,-1295.018433,0.024321,0.024040,0.610622,-0.062943,-0.003206,6.106224,-1295.018433,0.611811,0.000000
37.270000,0.013778,-1295.107422,0.024515,0.024198,0.614638,0.061287,0.003122,6.146382,-1295.107422,0.615644,0.000000
37.500000,0.092721,-1295.107422,0.024709,0.024344,0.618332,0.412442,0.021011,6.183322,-1295.107422,0.619477,0.000000
37.730003,0.095327,-1295.018433,0.024886,0.024488,0.621992,0.424037,0.021601,6.219922,-1295.018433,0.623310,0.000000
37.960003,0.078943,-1295.062866,0.025076,0.024648,0.626050,0.351156,0.017889,6.260504,-1295.062866,0.627143,0.000000
38.190002,-0.024204,-1295.062866,0.025322,0.024797,0.629831,-0.107666,-0.005485,6.298315,-1295.062866,0.630977,0.000000
38.420002,-0.012661,-1295.062866,0.025334,0.024946,0.633630,-0.056317,-0.002869,6.336300,-1295.062866,0.634792,0.000000
38.650002,0.060697,-1295.062866,0.025421,0.025100,0.637550,0.269993,0.013754,6.375496,-1295.062866,0.638625,0.000000
38.880001,0.102402,-1295.062866,0.025511,0.025249,0.641322,0.455509,0.023205,6.413224,-1295.062866,0.642459,0.000000
39.110001,0.111339,-1295.018433,0.025779,0.025403,0.645234,0.495262,0.025230,6.452338,-1295.018433,0.646292,0.000000
39.340000,-0.024949,-1295.107422,0.025917,0.025554,0.649084,-0.110978,-0.005654,6.490838,-1295.107422,0.650125,0.000000
39.570004,0.005213,-1295.196289,0.025998,0.025700,0.652779,0.023190,0.001181,6.527786,-1295.196289,0.653958,0.000000
39.800003,0.123255,-1295.107422,0.026223,0.025854,0.656681,0.548267,0.027930,6.566808,-1295.107422,0.657791,0.000000
40.030003,0.112084,-1295.107422,0.026300,0.026000,0.660401,0.498575,0.025399,6.604013,-1295.107422,0.661624,0.000000
40.260002,0.070378,-1295.062866,0.026546,0.026158,0.664408,0.313059,0.015948,6.644080,-1295.062866,0.665457,0.000000
40.490002,0.062931,-1295.107422,0.026624,0.026306,0.668163,0.279931,0.014260,6.681634,-1295.107422,0.669291,0.000000
40.720001,-0.045429,-1295.151855,0.026766,0.026454,0.671935,-0.202080,-0.010294,6.719354,-1295.151855,0.673124,0.000000
40.950001,0.074102,-1295.107422,0.026895,0.026611,0.675907,0.329623,0.016792,6.759073,-1295.107422,0.676956,0.000000
41.180000,0.096444,-1295.151855,0.027072,0.026756,0.679593,0.429007,0.021855,6.795930,-1295.151855,0.680772,0.000000
41.410004,0.112457,-1295.107422,0.027357,0.026908,0.683452,0.500232,0.025483,6.834521,-1295.107422,0.684606,0.000000
41.640003,0.089369,-1295.062866,0.027434,0.027068,0.687528,0.397535,0.020251,6.875284,-1295.062866,0.688439,0.000000
41.870003,0.040961,-1295.151855,0.027546,0.027212,0.691179,0.182203,0.009282,6.911794,-1295.151855,0.692272,0.000000
42.100002,0.036120,-1295.196289,0.027684,0.027359,0.694908,0.160671,0.008185,6.949082,-1295.196289,0.696105,0.000000
42.330002,0.090859,-1295.151855,0.027973,0.027511,0.698776,0.404160,0.020589,6.987764,-1295.151855,0.699938,0.000000
42.560001,0.076336,-1295.151855,0.028029,0.027659,0.702531,0.339561,0.017298,7.025310,-1295.151855,0.703772,0.000000
42.790001,0.074475,-1295.062866,0.028236,0.027820,0.706616,0.331279,0.016876,7.066157,-1295.062866,0.707604,0.000000
43.020000,-0.049525,-1295.107422,0.028439,0.027967,0.710371,-0.220300,-0.011223,7.103710,-1295.107422,0.711438,0.000000
43.250004,-0.012288,-1295.196289,0.028503,0.028112,0.714057,-0.054661,-0.002785,7.140568,-1295.196289,0.715271,0.000000
43.480003,0.071868,-1295.151855,0.028693,0.028271,0.718089,0.319684,0.016285,7.180892,-1295.151855,0.719104,0.000000
43.710003,0.090114,-1295.107422,0.028840,0.028417,0.721784,0.400848,0.020420,7.217840,-1295.107422,0.722937,0.000000
43.940002,0.119159,-1295.196289,0.029008,0.028572,0.725729,0.530047,0.027002,7.257294,-1295.196289,0.726770,0.000000
44.170002,0.097934,-1295.196289,0.029142,0.028723,0.729563,0.435632,0.022192,7.295627,-1295.196289,0.730586,0.000000
44.400002,0.004841,-1295.151855,0.029241,0.028867,0.733231,0.021533,0.001097,7.332311,-1295.151855,0.734419,0.000000
44.630001,0.057345,-1295.107422,0.029512,0.029019,0.737073,0.255085,0.012995,7.370727,-1295.107422,0.738252,0.000000
44.860001,0.082667,-1295.107422,0.029624,0.029168,0.740863,0.367720,0.018733,7.408629,-1295.107422,0.742085,0.000000
45.090004,0.077081,-1295.196289,0.029668,0.029324,0.744835,0.342874,0.017467,7.448348,-1295.196289,0.745919,0.000000
45.320004,0.090487,-1295.240845,0.029892,0.029478,0.748737,0.402504,0.020505,7.487370,-1295.240845,0.749751,0.000000
45.550003,-0.000745,-1295.196289,0.029943,0.029625,0.752466,-0.003313,-0.000169,7.524659,-1295.196289,0.753585,0.000000
45.780003,-0.001862,-1295.196289,0.030172,0.029775,0.756273,-0.008282,-0.000422,7.562735,-1295.196289,0.757418,0.000000
46.010002,0.123628,-1295.196289,0.030396,0.029927,0.760158,0.549923,0.028014,7.601583,-1295.196289,0.761251,0.000000
46.240002,0.125117,-1295.151855,0.030413,0.030071,0.763792,0.556549,0.028352,7.637918,-1295.151855,0.765084,0.000000
46.470001,0.087880,-1295.196289,0.030711,0.030227,0.767764,0.390909,0.019914,7.677637,-1295.196289,0.768917,0.000000
46.700001,-0.010054,-1295.240845,0.030832,0.030382,0.771710,-0.044723,-0.002278,7.717098,-1295.240845,0.772751,0.000000
46.930004,-0.016012,-1295.240845,0.030883,0.030525,0.775326,-0.071225,-0.003628,7.753259,-1295.240845,0.776584,0.000000
47.160004,0.077453,-1295.196289,0.031190,0.030680,0.779264,0.344530,0.017551,7.792637,-1295.196289,0.780399,0.000000
47.390003,0.118414,-1295.240845,0.031185,0.030830,0.783088,0.526734,0.026833,7.830880,-1295.240845,0.784232,0.000000
47.620003,0.133309,-1295.196289,0.031461,0.030974,0.786747,0.592990,0.030208,7.867472,-1295.196289,0.788066,0.000000
47.850002,0.080060,-1295.240845,0.031569,0.031140,0.790954,0.356125,0.018142,7.909537,-1295.240845,0.791899,0.000000
48.080002,0.019736,-1295.240845,0.031785,0.031283,0.794587,0.087789,0.004472,7.945872,-1295.240845,0.795732,0.000000
48.310001,0.071496,-1295.151855,0.031793,0.031433,0.798403,0.318028,0.016201,7.984032,-1295.151855,0.799565,0.000000
48.540001,0.106126,-1295.240845,0.031987,0.031586,0.802297,0.472073,0.024049,8.022970,-1295.240845,0.803398,0.000000
48.770000,0.106126,-1295.285278,0.032220,0.031732,0.805983,0.472073,0.024049,8.059828,-1295.285278,0.807231,0.000000
49.000004,0.078571,-1295.285278,0.032384,0.031888,0.809963,0.349499,0.017804,8.099629,-1295.285278,0.811064,0.000000
49.230003,-0.035748,-1295.285278,0.032453,0.032038,0.813753,-0.159014,-0.008101,8.137531,-1295.285278,0.814898,0.000000
49.460003,-0.024949,-1295.151855,0.032686,0.032190,0.817638,-0.110978,-0.005654,8.176380,-1295.151855,0.818731,0.000000
49.690002,0.115808,-1295.285278,0.032716,0.032341,0.821471,0.515139,0.026242,8.214713,-1295.285278,0.822564,0.000000
49.920002,0.119904,-1295.240845,0.032858,0.032485,0.825131,0.533360,0.027171,8.251306,-1295.240845,0.826380,0.000000
50.150002,0.099796,-1295.329834,0.033108,0.032648,0.829267,0.443914,0.022614,8.292675,-1295.329834,0.830213,0.000000
50.380001,0.053994,-1295.285278,0.033246,0.032795,0.832988,0.240178,0.012235,8.329880,-1295.285278,0.834046,0.000000
50.610001,0.039844,-1295.285278,0.033388,0.032942,0.836726,0.177234,0.009029,8.367260,-1295.285278,0.837879,0.000000
50.840004,0.110222,-1295.196289,0.033457,0.033094,0.840585,0.490293,0.024977,8.405850,-1295.196289,0.841712,0.000000
51.070004,0.103520,-1295.240845,0.033716,0.033240,0.844297,0.460478,0.023458,8.442966,-1295.240845,0.845546,0.000000
51.300003,0.085273,-1295.285278,0.033863,0.033396,0.848260,0.379315,0.019323,8.482600,-1295.285278,0.849379,0.000000
51.530003,0.070751,-1295.329834,0.033927,0.033553,0.852258,0.314715,0.016032,8.522576,-1295.329834,0.853211,0.000000
51.760002,0.030907,-1295.285278,0.034095,0.033695,0.855865,0.137481,0.007004,8.558654,-1295.285278,0.857045,0.000000
51.990002,0.018246,-1295.196289,0.034320,0.033847,0.859716,0.081164,0.004135,8.597162,-1295.196289,0.860878,0.000000
52.220001,0.090487,-1295.285278,0.034389,0.034003,0.863671,0.402504,0.020505,8.636706,-1295.285278,0.864711,0.000000
52.450001,0.119532,-1295.285278,0.034600,0.034150,0.867408,0.531703,0.027086,8.674078,-1295.285278,0.868544,0.000000
52.680004,0.128469,-1295.285278,0.034721,0.034302,0.871268,0.571456,0.029111,8.712677,-1295.285278,0.872377,0.000000
52.910004,0.045057,-1295.196289,0.034949,0.034448,0.874987,0.200424,0.010210,8.749875,-1295.196289,0.876193,0.000000
53.140003,0.004469,-1295.285278,0.035260,0.034600,0.878830,0.019877,0.001013,8.788299,-1295.285278,0.880027,0.000000
53.370003,0.100168,-1295.285278,0.035281,0.034755,0.882775,0.445571,0.022698,8.827753,-1295.285278,0.883859,0.000000
53.600002,0.102402,-1295.374268,0.035324,0.034902,0.886513,0.455509,0.023205,8.865132,-1295.374268,0.887693,0.000000
53.830002,0.121766,-1295.285278,0.035561,0.035059,0.890503,0.541641,0.027593,8.905025,-1295.285278,0.891526,0.000000
54.060001,0.085273,-1295.240845,0.035755,0.035209,0.894318,0.379315,0.019323,8.943185,-1295.240845,0.895359,0.000000
54.290001,0.012288,-1295.285278,0.035872,0.035356,0.898047,0.054661,0.002785,8.980474,-1295.285278,0.899192,0.000000
54.520004,0.117297,-1295.329834,0.035880,0.035506,0.901863,0.521765,0.026580,9.018633,-1295.329834,0.903025,0.000000
54.750004,0.134799,-1295.329834,0.036049,0.035657,0.905679,0.599615,0.030546,9.056792,-1295.329834,0.906859,0.000000
54.980003,0.127724,-1295.329834,0.036355,0.035803,0.909408,0.568144,0.028943,9.094081,-1295.329834,0.910691,0.000000
55.210003,0.099051,-1295.329834,0.036372,0.035965,0.913518,0.440601,0.022445,9.135184,-1295.329834,0.914524,0.000000
55.440002,0.004096,-1295.329834,0.036575,0.036108,0.917135,0.018220,0.000928,9.171346,-1295.329834,0.918358,0.000000
55.670002,0.005958,-1295.285278,0.036631,0.036259,0.920985,0.026502,0.001350,9.209853,-1295.285278,0.922174,0.000000
55.900002,0.138150,-1295.329834,0.036799,0.036416,0.924975,0.614523,0.031305,9.249745,-1295.329834,0.926006,0.000000
56.130001,0.166451,-1295.285278,0.037027,0.036554,0.928478,0.740409,0.037718,9.284779,-1295.285278,0.929840,0.000000
56.360004,0.167568,-1295.329834,0.037092,0.036722,0.932737,0.745378,0.037971,9.327367,-1295.329834,0.933673,0.000000
56.590004,0.159003,-1295.329834,0.037320,0.036865,0.936361,0.707281,0.036031,9.363610,-1295.329834,0.937506,0.000000
56.820004,0.542919,-1295.285278,0.037502,0.037015,0.940169,2.415025,0.123027,9.401687,-1295.285278,0.941339,0.000000
57.050003,1.109670,-1295.374268,0.037583,-0.000000,-0.000000,4.936059,0.251455,-0.000000,-1295.374268,0.000277,0.000000
57.280003,1.087700,-1295.374268,0.037532,-0.000000,-0.000000,4.838331,0.246476,-0.000000,-1295.374268,0.000277,0.000000
57.510002,1.087328,-1295.329834,0.037532,-0.000000,-0.000000,4.836675,0.246392,-0.000000,-1295.329834,0.000312,0.000000
57.740002,1.102222,-1295.240845,0.037631,-0.000000,-0.000000,4.902930,0.249767,-0.000000,-1295.240845,0.000693,0.000000
57.970001,1.137970,-1295.329834,0.037769,0.000005,0.000121,5.061944,0.257868,0.001211,-1295.329834,0.001075,0.000000
58.200005,1.221754,-1295.374268,0.037601,0.000021,0.000528,5.434634,0.276853,0.005284,-1295.374268,0.001456,0.000000
58.430004,1.374799,-1295.374268,0.037545,0.000037,0.000936,6.115412,0.311534,0.009364,-1295.374268,0.001838,0.000000
58.660004,1.503268,-1295.374268,0.037614,0.000047,0.001205,6.686869,0.340645,0.012051,-1295.374268,0.002229,0.000000
58.890003,1.787760,-1295.329834,0.037545,0.000067,0.001709,7.952355,0.405112,0.017085,-1295.329834,0.002610,0.000000
59.120003,1.911388,-1295.329834,0.037627,0.000080,0.002029,8.502278,0.433127,0.020287,-1295.329834,0.002992,0.000000
59.350002,2.052145,-1295.329834,0.037678,0.000090,0.002298,9.128395,0.465023,0.022982,-1295.329834,0.003373,0.000000
59.580002,2.338127,-1295.374268,0.037665,0.000112,0.002853,10.400507,0.529827,0.028531,-1295.374268,0.003755,0.000000
59.810001,2.565646,-1295.285278,0.037553,0.000127,0.003235,11.412564,0.581384,0.032346,-1295.285278,0.004145,0.000000
60.040005,2.665070,-1295.463257,0.037618,0.000138,0.003503,11.854821,0.603913,0.035033,-1295.463257,0.004527,0.000000
60.270004,2.853490,-1295.329834,0.037579,0.000154,0.003902,12.692959,0.646610,0.039022,-1295.329834,0.004908,0.000000
60.500004,3.199797,-1295.374268,0.037713,0.000172,0.004362,14.233406,0.725084,0.043617,-1295.374268,0.005290,0.000000
60.730003,3.542752,-1295.329834,0.037683,0.000187,0.004761,15.758947,0.802799,0.047606,-1295.329834,0.005680,0.000000
60.960003,3.750163,-1295.418701,0.037747,0.000199,0.005047,16.681559,0.849799,0.050468,-1295.418701,0.006062,0.000000
61.190002,4.017154,-1295.374268,0.037648,0.000211,0.005368,17.869194,0.910300,0.053677,-1295.374268,0.006443,0.000000
61.420002,4.465118,-1295.374268,0.037717,0.000234,0.005949,19.861839,1.011810,0.059491,-1295.374268,0.006825,0.000000
61.650002,4.900049,-1295.374268,0.037786,0.000251,0.006383,21.796507,1.110367,0.063828,-1295.374268,0.007206,0.000000
61.880001,5.095917,-1295.374268,0.037730,0.000262,0.006652,22.667772,1.154751,0.066516,-1295.374268,0.007596,0.000000
62.110004,5.302211,-1295.418701,0.037812,0.000273,0.006946,23.585413,1.201498,0.069460,-1295.418701,0.007978,0.000000
62.340004,5.629527,-1295.463257,0.037808,0.000289,0.007337,25.041386,1.275669,0.073366,-1295.463257,0.008360,0.000000
62.570004,6.055521,-1295.329834,0.037696,0.000302,0.007675,26.936302,1.372201,0.076750,-1295.329834,0.008742,0.000000
62.800003,6.640146,-1295.374268,0.037881,0.000320,0.008125,29.536844,1.504679,0.081254,-1295.374268,0.009123,0.000000
63.030003,6.889635,-1295.463257,0.037885,0.000329,0.008368,30.646627,1.561214,0.083684,-1295.463257,0.009513,0.000000
63.260002,7.244878,-1295.418701,0.037790,0.000342,0.008698,32.226830,1.641713,0.086977,-1295.418701,0.009894,0.000000
63.490002,7.979569,-1295.418701,0.037846,0.000366,0.009305,35.494896,1.808196,0.093048,-1295.418701,0.010276,0.000000
63.720001,8.475570,-1295.463257,0.037903,0.000380,0.009661,37.701218,1.920592,0.096606,-1295.463257,0.010658,0.000000
63.950005,8.784639,-1295.329834,0.037933,0.000392,0.009956,39.076027,1.990628,0.099558,-1295.329834,0.011040,0.000000
64.180000,9.111954,-1295.463257,0.037864,0.000407,0.010337,40.531994,2.064798,0.103373,-1295.463257,0.011430,0.000000
64.410004,9.521564,-1295.463257,0.037864,0.000418,0.010614,42.354031,2.157617,0.106144,-1295.463257,0.011811,0.000000
64.639999,10.671823,-1295.418701,0.037976,0.000443,0.011265,47.470638,2.418270,0.112646,-1295.418701,0.012193,0.000000
64.870003,10.859126,-1295.418701,0.037903,0.000453,0.011499,48.303806,2.460713,0.114993,-1295.418701,0.012574,0.000000
65.100006,11.162982,-1295.463257,0.037829,0.000464,0.011785,49.655422,2.529568,0.117854,-1295.463257,0.012956,0.000000
65.330002,12.100987,-1295.463257,0.037963,0.000488,0.012401,53.827881,2.742123,0.124008,-1295.463257,0.013346,0.000000
65.560005,12.773120,-1295.463257,0.037890,0.000505,0.012817,56.817677,2.894430,0.128172,-1295.463257,0.013728,0.000000
65.790001,13.191667,-1295.418701,0.037954,0.000518,0.013146,58.679462,2.989274,0.131465,-1295.418701,0.014109,0.000000
66.020004,13.370405,-1295.374268,0.037937,0.000526,0.013372,59.474533,3.029777,0.133720,-1295.374268,0.014491,0.000000
66.250000,14.019451,-1295.374268,0.037993,0.000543,0.013797,62.361633,3.176853,0.137975,-1295.374268,0.014872,0.000000
66.480003,14.759727,-1295.507690,0.038045,0.000559,0.014196,65.654549,3.344602,0.141964,-1295.507690,0.015263,0.000000
66.710007,15.541337,-1295.463257,0.038010,0.000576,0.014638,69.131317,3.521717,0.146385,-1295.463257,0.015644,0.000000
66.940002,15.983715,-1295.418701,0.038006,0.000589,0.014959,71.099113,3.621962,0.149594,-1295.418701,0.016026,0.000000
67.170006,16.726971,-1295.374268,0.038010,0.000607,0.015411,74.405281,3.790386,0.154106,-1295.374268,0.016408,0.000000
67.400002,17.609121,-1295.507690,0.037976,0.000625,0.015887,78.329285,3.990284,0.158875,-1295.507690,0.016789,0.000000
67.630005,18.190395,-1295.463257,0.038097,0.000641,0.016269,80.914917,4.122002,0.162690,-1295.463257,0.017180,0.000000
67.860001,18.502071,-1295.596680,0.038028,0.000652,0.016573,82.301323,4.192629,0.165725,-1295.596680,0.017561,0.000000
68.090004,18.966047,-1295.418701,0.038049,0.000664,0.016876,84.365189,4.297768,0.168761,-1295.418701,0.017943,0.000000
68.320000,19.649351,-1295.418701,0.038053,0.000678,0.017231,87.404678,4.452607,0.172311,-1295.418701,0.018324,0.000000
68.550003,20.795885,-1295.463257,0.038075,0.000699,0.017752,92.504715,4.712415,0.177519,-1295.463257,0.018715,0.000000
68.780006,21.364498,-1295.463257,0.038166,0.000713,0.018099,95.034035,4.841265,0.180986,-1295.463257,0.019096,0.000000
69.010002,21.764053,-1295.418701,0.038131,0.000726,0.018445,96.811348,4.931805,0.184453,-1295.418701,0.019478,0.000000
69.240005,22.916174,-1295.463257,0.038235,0.000745,0.018931,101.936234,5.192879,0.189313,-1295.463257,0.019859,0.000000
69.470001,23.618469,-1295.507690,0.038166,0.000760,0.019313,105.060196,5.352021,0.193128,-1295.507690,0.020241,0.000000
69.700005,24.008343,-1295.507690,0.038092,0.000772,0.019608,106.794441,5.440368,0.196080,-1295.507690,0.020631,0.000000
69.930000,24.536739,-1295.507690,0.038101,0.000786,0.019955,109.144867,5.560104,0.199547,-1295.507690,0.021012,0.000000
70.160004,25.133652,-1295.552124,0.038437,0.000799,0.020293,111.800064,5.695367,0.202931,-1295.552124,0.021394,0.000000
70.390007,26.342373,-1295.552124,0.038161,0.000820,0.020839,117.176727,5.969267,0.208389,-1295.552124,0.021776,0.000000
70.620003,26.878962,-1295.463257,0.038187,0.000832,0.021125,119.563591,6.090860,0.211250,-1295.463257,0.022158,0.000000
70.850006,27.325809,-1295.463257,0.038187,0.000842,0.021385,121.551270,6.192117,0.213854,-1295.463257,0.022547,0.000000
71.080002,27.555191,-1295.507690,0.038373,0.000850,0.021602,122.571609,6.244096,0.216019,-1295.507690,0.022929,0.000000
71.310005,29.314651,-1295.552124,0.038377,0.000878,0.022296,130.398087,6.642795,0.222961,-1295.552124,0.023310,0.000000
71.540001,30.023275,-1295.507690,0.038230,0.000894,0.022712,133.550201,6.803371,0.227124,-1295.507690,0.023692,0.000000
71.770004,30.299204,-1295.507690,0.038157,0.000903,0.022938,134.777588,6.865898,0.229380,-1295.507690,0.024074,0.000000
72.000000,30.795576,-1295.507690,0.038308,0.000917,0.023285,136.985565,6.978377,0.232847,-1295.507690,0.024464,0.000000
72.230003,31.923492,-1295.507690,0.038239,0.000938,0.023831,142.002792,7.233967,0.238312,-1295.507690,0.024846,0.000000
72.460007,33.057739,-1295.552124,0.038325,0.000956,0.024291,147.048172,7.490991,0.242907,-1295.552124,0.025227,0.000000
72.690002,33.462509,-1295.552124,0.038329,0.000968,0.024585,148.848679,7.582713,0.245852,-1295.552124,0.025609,0.000000
72.920006,33.453197,-1295.507690,0.038316,0.000975,0.024768,148.807251,7.580603,0.247676,-1295.507690,0.025990,0.000000
73.150002,35.252502,-1295.507690,0.038286,0.001001,0.025435,156.810959,7.988331,0.254353,-1295.507690,0.026381,0.000000
73.380005,36.081032,-1295.507690,0.038247,0.001016,0.025817,160.496445,8.176079,0.258168,-1295.507690,0.026762,0.000000
73.610001,36.607937,-1295.596680,0.038269,0.001031,0.026181,162.840240,8.295478,0.261809,-1295.596680,0.027144,0.000000
73.840004,37.058136,-1295.552124,0.038385,0.001044,0.026519,164.842819,8.397493,0.265192,-1295.552124,0.027525,0.000000
74.070007,37.539612,-1295.507690,0.038385,0.001054,0.026762,166.984528,8.506598,0.267622,-1295.507690,0.027907,0.000000
74.300003,38.916645,-1295.552124,0.038450,0.001076,0.027326,173.109879,8.818638,0.273262,-1295.552124,0.028297,0.000000
74.530006,39.772732,-1295.552124,0.038377,0.001090,0.027690,176.917953,9.012630,0.276903,-1295.552124,0.028679,0.000000
74.760002,39.908276,-1295.596680,0.038368,0.001097,0.027864,177.520874,9.043344,0.278636,-1295.596680,0.029060,0.000000
74.990005,40.743134,-1295.552124,0.038433,0.001115,0.028323,181.234512,9.232526,0.283231,-1295.552124,0.029442,0.000000
75.220001,42.381199,-1295.552124,0.038407,0.001138,0.028895,188.520981,9.603717,0.288954,-1295.552124,0.029823,0.000000
75.450005,43.023170,-1295.552124,0.038364,0.001152,0.029251,191.376617,9.749190,0.292512,-1295.552124,0.030214,0.000000
75.680000,43.083866,-1295.552124,0.038467,0.001157,0.029381,191.646606,9.762944,0.293814,-1295.552124,0.030596,0.000000
75.910004,43.856167,-1295.641113,0.038493,0.001173,0.029789,195.081970,9.937949,0.297886,-1295.641113,0.030977,0.000000
76.140007,44.483616,-1295.596680,0.038364,0.001185,0.030101,197.873001,10.080132,0.301013,-1295.596680,0.031359,0.000000
76.370003,44.984455,-1295.507690,0.038360,0.001182,0.030032,200.100845,10.193623,0.300316,-1295.507690,0.030387,0.000000
76.600006,44.577824,-1295.463257,0.038454,0.001182,0.030032,198.292068,10.101479,0.300316,-1295.463257,0.030387,0.000000
76.830002,44.295940,-1295.507690,0.038584,0.001175,0.029850,197.038177,10.037604,0.298500,-1295.507690,0.030049,0.000000
77.060005,44.010704,-1295.552124,0.038390,0.001173,0.029789,195.769394,9.972968,0.297886,-1295.552124,0.029668,0.000000
77.290001,43.698654,-1295.596680,0.038446,0.001162,0.029512,194.381317,9.902257,0.295116,-1295.596680,0.029286,0.000000
77.520004,43.504646,-1295.596680,0.038498,0.001149,0.029182,193.518326,9.858294,0.291815,-1295.596680,0.028904,0.000000
77.750000,43.345646,-1295.552124,0.038429,0.001135,0.028835,192.811066,9.822264,0.288348,-1295.552124,0.028514,0.000000
77.980003,43.192226,-1295.552124,0.038420,0.001123,0.028523,192.128616,9.787498,0.285230,-1295.552124,0.028132,0.000000
78.210007,43.086102,-1295.641113,0.038407,0.001105,0.028063,191.656555,9.763451,0.280635,-1295.641113,0.027751,0.000000
78.440002,42.949814,-1295.596680,0.038394,0.001093,0.027768,191.050308,9.732567,0.277683,-1295.596680,0.027369,0.000000
78.670006,42.841454,-1295.641113,0.038407,0.001082,0.027482,190.568298,9.708013,0.274821,-1295.641113,0.026988,0.000000
78.900002,42.760277,-1295.507690,0.038541,0.001064,0.027014,190.207214,9.689617,0.270136,-1295.507690,0.026597,0.000000
79.130005,42.648937,-1295.552124,0.038472,0.001049,0.026649,189.711945,9.664388,0.266494,-1295.552124,0.026216,0.000000
79.360001,42.561802,-1295.596680,0.038446,0.001034,0.026260,189.324356,9.644642,0.262596,-1295.596680,0.025834,0.000000
79.590004,42.483231,-1295.596680,0.038441,0.001022,0.025956,188.974854,9.626838,0.259561,-1295.596680,0.025453,0.000000
79.820007,42.313057,-1295.641113,0.038446,0.001005,0.025522,188.217880,9.588276,0.255223,-1295.641113,0.025071,0.000000
80.050003,42.270977,-1295.552124,0.038433,0.000991,0.025184,188.030701,9.578740,0.251839,-1295.552124,0.024681,0.000000
80.280006,42.307842,-1295.507690,0.038558,0.000970,0.024629,188.194687,9.587094,0.246291,-1295.507690,0.024299,0.000000
80.510002,42.239700,-1295.552124,0.038472,0.000958,0.024334,187.891571,9.571652,0.243338,-1295.552124,0.023918,0.000000
80.740005,42.182724,-1295.596680,0.038472,0.000946,0.024039,187.638123,9.558743,0.240394,-1295.596680,0.023536,0.000000
80.970001,42.113838,-1295.596680,0.038463,0.000931,0.023640,187.331711,9.543132,0.236405,-1295.596680,0.023146,0.000000
81.200005,42.053886,-1295.507690,0.038506,0.000915,0.023242,187.065033,9.529547,0.232415,-1295.507690,0.022765,0.000000
81.430000,41.978294,-1295.552124,0.038441,0.000901,0.022894,186.728775,9.512418,0.228941,-1295.552124,0.022383,0.000000
81.660004,41.835674,-1295.507690,0.038476,0.000890,0.022617,186.094376,9.480100,0.226170,-1295.507690,0.022001,0.000000
81.890007,41.734760,-1295.596680,0.038722,0.000876,0.022261,185.645493,9.457232,0.222612,-1295.596680,0.021619,0.000000
82.120003,41.604057,-1295.596680,0.038502,0.000865,0.021975,185.064087,9.427614,0.219751,-1295.596680,0.021229,0.000000
82.350006,41.168011,-1295.596680,0.038429,0.000842,0.021394,183.124451,9.328804,0.213945,-1295.596680,0.020848,0.000000
82.580002,40.812767,-1295.552124,0.038502,0.000834,0.021177,181.544250,9.248305,0.211772,-1295.552124,0.020466,0.000000
82.810005,40.300385,-1295.552124,0.038489,0.000822,0.020874,179.265060,9.132197,0.208737,-1295.552124,0.020085,0.000000
83.040001,39.848694,-1295.596680,0.038640,0.000813,0.020648,177.255844,9.029843,0.206481,-1295.596680,0.019703,0.000000
83.270004,38.658592,-1295.641113,0.038381,0.000792,0.020128,171.962006,8.760162,0.201281,-1295.641113,0.019313,0.000000
83.500008,37.541847,-1295.507690,0.038541,0.000775,0.019686,166.994476,8.507104,0.196860,-1295.507690,0.018931,0.000000
83.730003,37.116600,-1295.463257,0.038510,0.000767,0.019486,165.102890,8.410742,0.194862,-1295.463257,0.018550,0.000000
83.960007,35.747383,-1295.596680,0.038454,0.000749,0.019035,159.012299,8.100473,0.190350,-1295.596680,0.018168,0.000000
84.190002,34.864491,-1295.596680,0.038454,0.000734,0.018645,155.085007,7.900406,0.186451,-1295.596680,0.017787,0.000000
84.420006,33.395107,-1295.552124,0.038433,0.000714,0.018142,148.548859,7.567440,0.181418,-1295.552124,0.017396,0.000000
84.650002,32.538277,-1295.507690,0.038730,0.000702,0.017838,144.737488,7.373279,0.178382,-1295.507690,0.017015,0.000000
84.880005,31.870987,-1295.552124,0.038454,0.000694,0.017630,141.769226,7.222069,0.176300,-1295.552124,0.016633,0.000000
85.110001,31.013786,-1295.507690,0.038377,0.000682,0.017318,137.956207,7.027824,0.173182,-1295.507690,0.016252,0.000000
85.340004,29.318747,-1295.596680,0.038403,0.000660,0.016763,130.416306,6.643723,0.167633,-1295.596680,0.015870,0.000000
85.570007,28.220247,-1295.552124,0.038493,0.000647,0.016442,125.529930,6.394799,0.164423,-1295.552124,0.015479,0.000000
85.800003,27.233461,-1295.552124,0.038480,0.000637,0.016174,121.140488,6.171191,0.161736,-1295.552124,0.015098,0.000000
86.030006,26.182627,-1295.507690,0.038407,0.000624,0.015844,116.466141,5.933068,0.158436,-1295.507690,0.014716,0.000000
86.260002,25.095671,-1295.552124,0.038403,0.000611,0.015514,111.631119,5.686760,0.155143,-1295.552124,0.014335,0.000000
86.490005,23.081509,-1295.641113,0.038506,0.000586,0.014872,102.671677,5.230344,0.148724,-1295.641113,0.013953,0.000000
86.720001,21.969231,-1295.596680,0.038467,0.000573,0.014543,97.724022,4.978299,0.145431,-1295.596680,0.013563,0.000000
86.950005,21.197304,-1295.552124,0.038467,0.000562,0.014274,94.290314,4.803378,0.142744,-1295.552124,0.013181,0.000000
87.180008,20.180353,-1295.463257,0.038420,0.000551,0.014006,89.766693,4.572934,0.140056,-1295.463257,0.012800,0.000000
87.410004,18.517712,-1295.507690,0.038476,0.000531,0.013494,82.370895,4.196173,0.134939,-1295.507690,0.012418,0.000000
87.640007,17.139561,-1295.596680,0.038390,0.000515,0.013086,76.240570,3.883880,0.130859,-1295.596680,0.012037,0.000000
87.870003,16.324064,-1295.596680,0.038437,0.000507,0.012878,72.613068,3.699086,0.128777,-1295.596680,0.011647,0.000000
88.100006,14.856916,-1295.552124,0.038480,0.000489,0.012418,66.086868,3.366625,0.124182,-1295.552124,0.011265,0.000000
88.330002,13.228904,-1295.507690,0.038450,0.000468,0.011881,58.845104,2.997712,0.118808,-1295.507690,0.010883,0.000000
88.560005,12.387342,-1295.507690,0.038390,0.000457,0.011612,55.101650,2.807012,0.116121,-1295.507690,0.010502,0.000000
88.790001,11.619138,-1295.596680,0.038325,0.000448,0.011369,51.684505,2.632934,0.113691,-1295.596680,0.010120,0.000000
89.020004,10.670705,-1295.552124,0.038407,0.000433,0.011005,47.465664,2.418016,0.110050,-1295.552124,0.009730,0.000000
89.250008,9.090357,-1295.552124,0.038416,0.000411,0.010441,40.435928,2.059904,0.104410,-1295.552124,0.009349,0.000000
89.480003,7.947546,-1295.552124,0.038394,0.000398,0.010112,35.352448,1.800940,0.101117,-1295.552124,0.008967,0.000000
89.710007,7.211365,-1295.596680,0.038325,0.000386,0.009808,32.077755,1.634119,0.098082,-1295.596680,0.008585,0.000000
89.940002,6.116590,-1295.552124,0.038308,0.000369,0.009383,27.207951,1.386039,0.093828,-1295.552124,0.008195,0.000000
90.170006,5.409082,-1295.596680,0.038273,0.000357,0.009063,24.060801,1.225716,0.090626,-1295.596680,0.007814,0.000000
90.400002,4.226055,-1295.507690,0.038213,0.000333,0.008446,18.798431,0.957638,0.084464,-1295.507690,0.007432,0.000000
90.630005,3.967256,-1295.507690,0.038265,0.000325,0.008247,17.647236,0.898993,0.082473,-1295.507690,0.007051,0.000000
90.860001,3.147665,-1295.552124,0.038217,0.000304,0.007726,14.001512,0.713271,0.077265,-1295.552124,0.006669,0.000000
91.090004,2.424517,-1295.507690,0.038260,0.000284,0.007206,10.784791,0.549403,0.072064,-1295.507690,0.006278,0.000000
91.320007,2.089382,-1295.552124,0.038161,0.000271,0.006877,9.294035,0.473461,0.068772,-1295.552124,0.005897,0.000000
91.550003,1.904313,-1295.596680,0.038347,0.000262,0.006652,8.470807,0.431523,0.066516,-1295.596680,0.005515,0.000000
91.780006,1.464169,-1295.552124,0.038347,0.000248,0.006296,6.512947,0.331785,0.062958,-1295.552124,0.005134,0.000000
92.010002,1.203508,-1295.552124,0.038269,0.000233,0.005914,5.353470,0.272719,0.059143,-1295.552124,0.004752,0.000000
92.240005,1.129406,-1295.641113,0.038196,0.000220,0.005593,5.023848,0.255927,0.055933,-1295.641113,0.004362,0.000000
92.470001,0.935400,-1295.641113,0.038226,0.000205,0.005194,4.160865,0.211965,0.051944,-1295.641113,0.003980,0.000000
92.700005,0.818847,-1295.596680,0.038140,0.000192,0.004865,3.642414,0.185553,0.048651,-1295.596680,0.003599,0.000000
92.930008,0.680697,-1295.507690,0.038226,0.000174,0.004431,3.027891,0.154248,0.044314,-1295.507690,0.003217,0.000000
93.160004,0.486691,-1295.552124,0.038209,0.000150,0.003798,2.164909,0.110286,0.037978,-1295.552124,0.002836,0.000000
93.390007,0.456901,-1295.596680,0.038135,0.000139,0.003529,2.032397,0.103535,0.035290,-1295.596680,0.002445,0.000000
93.620003,0.252096,-1295.685669,0.038213,0.000125,0.003182,1.121380,0.057126,0.031823,-1295.685669,0.002064,0.000000
93.850006,0.203315,-1295.596680,0.038183,0.000111,0.002809,0.904392,0.046072,0.028091,-1295.596680,0.001682,0.000000
94.080002,0.280769,-1295.552124,0.038036,0.000091,0.002307,1.248922,0.063623,0.023065,-1295.552124,0.001300,0.000000
94.310005,0.277790,-1295.552124,0.038066,0.000075,0.001908,1.235671,0.062948,0.019076,-1295.552124,0.000919,0.000000
94.540001,0.270715,-1295.596680,0.037997,0.000059,0.001500,1.204200,0.061345,0.015003,-1295.596680,0.000528,0.000000
94.770004,0.244649,-1295.685669,0.038019,0.000049,0.001240,1.088252,0.055438,0.012399,-1295.685669,0.000147,0.000000
95.000008,0.208529,-1295.596680,0.037937,0.000029,0.000746,0.927581,0.047253,0.007456,-1295.596680,-0.000235,0.000000
95.230003,0.196240,-1295.596680,0.037959,0.000014,0.000364,0.872920,0.044469,0.003641,-1295.596680,-0.000616,0.000000
95.460007,0.047664,-1295.552124,0.037997,0.000003,0.000086,0.212019,0.010801,0.000863,-1295.552124,-0.000998,0.000000
95.690002,0.176505,-1295.552124,0.037997,0.000001,0.000017,0.785131,0.039997,0.000174,-1295.552124,-0.000174,0.000000
95.920006,0.175387,-1295.685669,0.038023,0.000001,0.000026,0.780162,0.039743,0.000257,-1295.685669,-0.000174,0.000000
96.150002,0.190282,-1295.596680,0.038015,0.000001,0.000034,0.846418,0.043119,0.000341,-1295.596680,-0.000000,0.000000
96.200005,0.199964,-1295.685669,0.038010,0.000002,0.000043,0.889485,0.045313,0.000431,-1295.685669,-0.000000,0.000000