File: Data/I-16 Position Control Dwell_07192023_175927.csv
Time (sec),S:Load (lbs),S:HL1 (DIM),S:LVDT (in),S:Position (in),Ch:Position (mm),Ch:Load (N),Ch:Stress (MPa),Ch:Strain (mm/mm),Ch:HL1 (DIM),Set Point (),Cycles ()
0.110000,-0.007075,-20.416756,-0.000017,-0.000000,-0.000000,-0.031472,-0.001603,-0.000000,-20.416756,0.000017,0.000000
0.410000,-0.032024,-20.416756,0.000013,0.000000,0.000009,-0.142450,-0.007257,0.000086,-20.416756,0.000399,0.000000
0.710000,-0.029045,-20.416756,0.000004,0.000178,0.004510,-0.129199,-0.006582,0.045095,-20.416756,0.005394,0.000000
1.010000,0.049525,-20.416756,0.000004,0.000360,0.009132,0.220300,0.011223,0.091318,-20.416756,0.010389,0.000000
1.310000,0.025321,-20.416756,0.000250,0.000563,0.014300,0.112635,0.005738,0.143005,-20.416756,0.015402,0.000000
1.610000,0.041706,-20.461237,0.000418,0.000763,0.019374,0.185516,0.009451,0.193737,-20.461237,0.020397,0.000000
1.910000,0.035003,-20.372276,0.000595,0.000957,0.024300,0.155701,0.007932,0.242996,-20.372276,0.025392,0.000000
2.210000,0.033886,-20.416756,0.000789,0.001155,0.029347,0.150732,0.007679,0.293468,-20.416756,0.030388,0.000000
2.510000,0.053994,-20.416756,0.000970,0.001347,0.034221,0.240177,0.012235,0.342207,-20.416756,0.035383,0.000000
2.810000,0.008192,-20.372276,0.001134,0.001543,0.039199,0.036441,0.001856,0.391985,-20.372276,0.040378,0.000000
3.110000,0.090114,-20.416756,0.001337,0.001741,0.044220,0.400848,0.020420,0.442198,-20.416756,0.045373,0.000000
3.410000,0.023087,-20.372276,0.001513,0.001942,0.049328,0.102696,0.005232,0.493278,-20.372276,0.050386,0.000000
3.710000,0.068144,-20.416756,0.001733,0.002133,0.054167,0.303120,0.015442,0.541669,-20.416756,0.055381,0.000000
4.010000,0.058835,-20.372276,0.001932,0.002335,0.059309,0.261710,0.013332,0.593095,-20.372276,0.060376,0.000000
4.310000,0.057718,-20.416756,0.002143,0.002531,0.064279,0.256741,0.013079,0.642787,-20.416756,0.065371,0.000000
4.610000,0.049525,-20.416756,0.002345,0.002728,0.069283,0.220300,0.011223,0.692826,-20.416756,0.070367,0.000000
4.910000,0.045057,-20.416756,0.002570,0.002924,0.074269,0.200424,0.010210,0.742692,-20.416756,0.075362,0.000000
5.210000,0.052504,-20.461237,0.002764,0.003116,0.079134,0.233552,0.011898,0.791343,-20.461237,0.080374,0.000000
5.510000,0.064420,-20.461237,0.002940,0.003320,0.084320,0.286556,0.014598,0.843203,-20.461237,0.085370,0.000000
5.810000,0.059952,-20.505718,0.003147,0.003506,0.089064,0.266679,0.013585,0.890641,-20.505718,0.090365,0.000000
6.110000,0.046174,-20.461237,0.003367,0.003715,0.094354,0.205393,0.010463,0.943541,-20.461237,0.095360,0.000000
6.410000,0.055483,-20.461237,0.003553,0.003902,0.099107,0.246803,0.012573,0.991065,-20.461237,0.100355,0.000000
6.710001,0.012288,-20.416756,0.003738,0.004104,0.104232,0.054661,0.002785,1.042318,-20.416756,0.105351,0.000000
7.010000,0.056228,-20.416756,0.003932,0.004298,0.109158,0.250116,0.012741,1.091577,-20.416756,0.110363,0.000000
7.310000,0.064793,-20.461237,0.004139,0.004496,0.114205,0.288213,0.014682,1.142049,-20.461237,0.115358,0.000000
7.610000,0.071495,-20.505718,0.004333,0.004691,0.119139,0.318028,0.016201,1.191394,-20.505718,0.120354,0.000000
7.910000,0.059580,-20.416756,0.004553,0.004893,0.124282,0.265023,0.013501,1.242820,-20.416756,0.125349,0.000000
8.210000,0.072985,-20.461237,0.004777,0.005091,0.129321,0.324653,0.016539,1.293207,-20.461237,0.130344,0.000000
8.510000,0.055483,-20.461237,0.004971,0.005281,0.134134,0.246803,0.012573,1.341337,-20.461237,0.135339,0.000000
8.810000,0.008565,-20.505718,0.005174,0.005482,0.139242,0.038097,0.001941,1.392417,-20.505718,0.140334,0.000000
9.110001,0.067772,-20.461237,0.005394,0.005676,0.144159,0.301464,0.015357,1.441589,-20.461237,0.145347,0.000000
9.410001,0.056973,-20.461237,0.005601,0.005877,0.149284,0.253428,0.012910,1.492842,-20.461237,0.150342,0.000000
9.710000,0.082667,-20.550200,0.005786,0.006065,0.154063,0.367720,0.018733,1.540626,-20.550200,0.155337,0.000000
10.010000,0.035375,-20.416756,0.006010,0.006269,0.159240,0.157357,0.008016,1.592399,-20.416756,0.160333,0.000000
10.310000,0.068144,-20.505718,0.006234,0.006464,0.164192,0.303120,0.015442,1.641918,-20.505718,0.165328,0.000000
10.610001,0.051387,-20.505718,0.006450,0.006657,0.169092,0.228582,0.011645,1.690916,-20.505718,0.170323,0.000000
10.910001,0.038354,-20.550200,0.006644,0.006860,0.174252,0.170609,0.008691,1.742516,-20.550200,0.175336,0.000000
11.210001,0.039099,-20.461237,0.006847,0.007052,0.179125,0.173921,0.008860,1.791255,-20.461237,0.180331,0.000000
11.510000,0.075964,-20.505718,0.007054,0.007253,0.184225,0.337905,0.017214,1.842247,-20.505718,0.185326,0.000000
11.810000,0.058462,-20.505718,0.007274,0.007445,0.189107,0.260054,0.013248,1.891072,-20.505718,0.190321,0.000000
12.110001,0.047291,-20.550200,0.007472,0.007649,0.194285,0.210362,0.010716,1.942845,-20.550200,0.195317,0.000000
12.410001,0.077826,-20.505718,0.007679,0.007843,0.199219,0.346187,0.017636,1.992191,-20.505718,0.200312,0.000000
12.710001,0.026811,-20.505718,0.007877,0.008041,0.204249,0.119260,0.006075,2.042489,-20.505718,0.205324,0.000000
13.010000,0.029790,-20.550200,0.008088,0.008234,0.209149,0.132511,0.006750,2.091488,-20.550200,0.210320,0.000000
13.310000,-0.004096,-20.550200,0.008278,0.008431,0.214153,-0.018221,-0.000928,2.141527,-20.550200,0.215315,0.000000
13.610001,0.065538,-20.505718,0.008498,0.008629,0.219183,0.291525,0.014851,2.191826,-20.505718,0.220310,0.000000
13.910001,0.033513,-20.550200,0.008714,0.008826,0.224169,0.149075,0.007594,2.241691,-20.550200,0.225305,0.000000
14.210001,0.057718,-20.505718,0.008921,0.009026,0.229268,0.256741,0.013079,2.292684,-20.505718,0.230300,0.000000
14.510000,0.048781,-20.550200,0.009140,0.009221,0.234220,0.216988,0.011054,2.342203,-20.550200,0.235296,0.000000
14.810000,0.026811,-20.550200,0.009317,0.009421,0.239302,0.119260,0.006075,2.393023,-20.550200,0.240308,0.000000
15.110001,0.045429,-20.594681,0.009503,0.009616,0.244237,0.202080,0.010294,2.442367,-20.594681,0.245303,0.000000
15.410001,-0.008192,-20.594681,0.009705,0.009810,0.249180,-0.036441,-0.001856,2.491799,-20.594681,0.250299,0.000000
15.710001,0.089369,-20.505718,0.009925,0.010007,0.254166,0.397535,0.020251,2.541665,-20.505718,0.255294,0.000000
16.010000,0.036120,-20.594681,0.010145,0.010208,0.259283,0.160670,0.008185,2.592831,-20.594681,0.260289,0.000000
16.310001,0.060324,-20.505718,0.010335,0.010398,0.264114,0.268336,0.013670,2.641136,-20.505718,0.265284,0.000000
16.610001,0.055483,-20.550200,0.010555,0.010601,0.269265,0.246803,0.012573,2.692649,-20.550200,0.270297,0.000000
16.910002,0.050270,-20.594681,0.010757,0.010795,0.274191,0.223613,0.011391,2.741908,-20.594681,0.275292,0.000000
17.210001,0.048036,-20.505718,0.010956,0.010993,0.279221,0.213675,0.010885,2.792206,-20.505718,0.280287,0.000000
17.510000,0.042450,-20.505718,0.011137,0.011186,0.284120,0.188829,0.009619,2.841204,-20.505718,0.285282,0.000000
17.810001,0.064793,-20.594681,0.011352,0.011385,0.289176,0.288213,0.014682,2.891764,-20.594681,0.290278,0.000000
18.110001,0.036492,-20.550200,0.011546,0.011586,0.294276,0.162327,0.008269,2.942757,-20.550200,0.295273,0.000000
18.410002,0.053249,-20.550200,0.011758,0.011777,0.299123,0.236864,0.012066,2.991235,-20.550200,0.300268,0.000000
18.710001,0.052504,-20.550200,0.011990,0.011978,0.304231,0.233552,0.011898,3.042314,-20.550200,0.305281,0.000000
19.010000,0.061069,-20.550200,0.012189,0.012172,0.309175,0.271649,0.013838,3.091746,-20.550200,0.310276,0.000000
19.310001,-0.001862,-20.505718,0.012391,0.012369,0.314170,-0.008282,-0.000422,3.141698,-20.505718,0.315271,0.000000
19.610001,0.042450,-20.550200,0.012594,0.012560,0.319026,0.188829,0.009619,3.190262,-20.550200,0.320266,0.000000
19.910002,0.002607,-20.594681,0.012810,0.012762,0.324152,0.011595,0.000591,3.241516,-20.594681,0.325262,0.000000
20.210001,0.070378,-20.594681,0.012991,0.012957,0.329103,0.313059,0.015948,3.291034,-20.594681,0.330257,0.000000
20.510000,0.051015,-20.550200,0.013219,0.013157,0.334177,0.226926,0.011560,3.341767,-20.550200,0.335269,0.000000
20.810001,0.043940,-20.550200,0.013426,0.013355,0.339207,0.195455,0.009957,3.392066,-20.550200,0.340265,0.000000
21.110001,0.051387,-20.594681,0.013611,0.013548,0.344124,0.228582,0.011645,3.441238,-20.594681,0.345260,0.000000
21.410002,0.005958,-20.594681,0.013814,0.013750,0.349249,0.026502,0.001350,3.492491,-20.594681,0.350255,0.000000
21.710001,0.055856,-20.594681,0.013999,0.013939,0.354053,0.248459,0.012657,3.540535,-20.594681,0.355250,0.000000
22.010000,0.000745,-20.550200,0.014189,0.014137,0.359075,0.003313,0.000169,3.590748,-20.550200,0.360245,0.000000
22.310001,0.080805,-20.594681,0.014405,0.014332,0.364044,0.359438,0.018311,3.640440,-20.594681,0.365258,0.000000
22.610001,0.020853,-20.594681,0.014616,0.014533,0.369143,0.092758,0.004725,3.691433,-20.594681,0.370253,0.000000
22.910002,0.067772,-20.594681,0.014827,0.014730,0.374130,0.301464,0.015357,3.741298,-20.594681,0.375249,0.000000
23.210001,0.051760,-20.594681,0.015030,0.014927,0.379142,0.230239,0.011729,3.791423,-20.594681,0.380244,0.000000
23.510000,0.064793,-20.594681,0.015211,0.015128,0.384242,0.288213,0.014682,3.842416,-20.594681,0.385239,0.000000
23.810001,0.059207,-20.639162,0.015422,0.015319,0.389098,0.263367,0.013417,3.890981,-20.639162,0.390234,0.000000
24.110001,0.040589,-20.594681,0.015608,0.015517,0.394137,0.180547,0.009197,3.941367,-20.594681,0.395229,0.000000
24.410002,0.062559,-20.594681,0.015819,0.015711,0.399071,0.278274,0.014176,3.990712,-20.594681,0.400242,0.000000
24.710001,0.039471,-20.594681,0.016039,0.015914,0.404223,0.175578,0.008944,4.042225,-20.594681,0.405237,0.000000
25.010002,0.060697,-20.639162,0.016246,0.016102,0.408984,0.269992,0.013754,4.089836,-20.639162,0.410232,0.000000
25.310001,0.044312,-20.550200,0.016444,0.016306,0.414178,0.197111,0.010041,4.141783,-20.550200,0.415228,0.000000
25.610001,0.054739,-20.594681,0.016642,0.016496,0.418991,0.243490,0.012404,4.189914,-20.594681,0.420223,0.000000
25.910002,0.009309,-20.550200,0.016832,0.016698,0.424117,0.041410,0.002110,4.241167,-20.550200,0.425218,0.000000
26.210001,0.039471,-20.550200,0.017056,0.016895,0.429129,0.175578,0.008944,4.291293,-20.550200,0.430231,0.000000
26.510002,0.059580,-20.594681,0.017250,0.017089,0.434072,0.265023,0.013501,4.340724,-20.594681,0.435226,0.000000
26.810001,0.086763,-20.639162,0.017457,0.017287,0.439102,0.385940,0.019661,4.391024,-20.639162,0.440221,0.000000
27.110001,0.057345,-20.639162,0.017677,0.017483,0.444063,0.255085,0.012995,4.440629,-20.639162,0.445216,0.000000
27.410002,0.046919,-20.683641,0.017871,0.017686,0.449223,0.208706,0.010632,4.492229,-20.683641,0.450211,0.000000
27.710001,0.052132,-20.594681,0.018074,0.017873,0.453975,0.231895,0.011813,4.539752,-20.594681,0.455207,0.000000
28.010002,-0.004841,-20.639162,0.018259,0.018076,0.459118,-0.021533,-0.001097,4.591179,-20.639162,0.460219,0.000000
28.310001,0.060697,-20.639162,0.018466,0.018268,0.464018,0.269992,0.013754,4.640178,-20.639162,0.465214,0.000000
28.610001,0.042450,-20.639162,0.018660,0.018470,0.469143,0.188829,0.009619,4.691430,-20.639162,0.470210,0.000000
28.910002,0.090114,-20.639162,0.018850,0.018660,0.473956,0.400848,0.020420,4.739562,-20.639162,0.475205,0.000000
29.210001,0.058462,-20.594681,0.019066,0.018861,0.479073,0.260054,0.013248,4.790728,-20.594681,0.480200,0.000000
29.510002,0.068144,-20.639162,0.019290,0.019061,0.484155,0.303120,0.015442,4.841547,-20.639162,0.485195,0.000000
29.810001,0.061814,-20.639162,0.019484,0.019254,0.489046,0.274962,0.014007,4.890459,-20.639162,0.490191,0.000000
30.110001,0.043940,-20.639162,0.019673,0.019455,0.494145,0.195455,0.009957,4.941452,-20.639162,0.495203,0.000000
30.410002,0.062186,-20.683641,0.019859,0.019646,0.499010,0.276618,0.014092,4.990103,-20.683641,0.500198,0.000000
30.710001,0.057345,-20.639162,0.020061,0.019849,0.504153,0.255085,0.012995,5.041529,-20.639162,0.505194,0.000000
31.010002,0.071123,-20.639162,0.020256,0.020037,0.508949,0.316371,0.016117,5.089487,-20.639162,0.510189,0.000000
31.310001,0.052132,-20.683641,0.020437,0.020241,0.514117,0.231895,0.011813,5.141174,-20.683641,0.515184,0.000000
31.610001,0.090486,-20.639162,0.020656,0.020434,0.519035,0.402504,0.020505,5.190345,-20.639162,0.520179,0.000000
31.910002,0.044685,-20.639162,0.020863,0.020631,0.524021,0.198767,0.010126,5.240211,-20.639162,0.525192,0.000000
32.210003,0.052877,-20.594681,0.021057,0.020826,0.528982,0.235208,0.011982,5.289816,-20.594681,0.530187,0.000000
32.510002,0.008565,-20.594681,0.021251,0.021022,0.533968,0.038097,0.001941,5.339682,-20.594681,0.535182,0.000000
32.810001,0.088252,-20.683641,0.021454,0.021223,0.539067,0.392566,0.019998,5.390675,-20.683641,0.540178,0.000000
33.110001,0.063676,-20.683641,0.021644,0.021418,0.544019,0.283244,0.014429,5.440193,-20.683641,0.545173,0.000000
33.410000,0.089742,-20.683641,0.021842,0.021617,0.549067,0.399191,0.020336,5.490666,-20.683641,0.550168,0.000000
33.710003,0.091231,-20.594681,0.022028,0.021812,0.554036,0.405817,0.020673,5.540358,-20.594681,0.555163,0.000000
34.010002,0.052132,-20.728123,0.022222,0.022012,0.559100,0.231895,0.011813,5.591004,-20.728123,0.560176,0.000000
34.310001,0.069634,-20.639162,0.022407,0.022204,0.563974,0.309746,0.015779,5.639742,-20.639162,0.565171,0.000000
34.610001,0.018991,-20.639162,0.022584,0.022402,0.569013,0.084476,0.004303,5.690128,-20.639162,0.570166,0.000000
34.910000,0.111339,-20.639162,0.022773,0.022598,0.573991,0.495262,0.025230,5.739906,-20.639162,0.575161,0.000000
35.210003,0.081922,-20.639162,0.022942,0.022797,0.579047,0.364407,0.018564,5.790465,-20.639162,0.580157,0.000000
35.510002,0.115063,-20.683641,0.023144,0.022992,0.584007,0.511826,0.026074,5.840071,-20.683641,0.585152,0.000000
35.810001,0.093838,-20.639162,0.023343,0.023192,0.589089,0.417412,0.021264,5.890891,-20.639162,0.590164,0.000000
36.110001,0.102402,-20.594681,0.023506,0.023389,0.594084,0.455509,0.023205,5.940843,-20.594681,0.595160,0.000000
36.410000,0.106871,-20.639162,0.023692,0.023584,0.599036,0.475385,0.024217,5.990361,-20.639162,0.600155,0.000000
36.710003,0.076709,-20.639162,0.023894,0.023779,0.603988,0.341217,0.017382,6.039879,-20.639162,0.605150,0.000000
37.010002,0.118414,-20.639162,0.024088,0.023976,0.608983,0.526734,0.026833,6.089832,-20.639162,0.610145,0.000000
37.310001,0.080805,-20.594681,0.024282,0.024177,0.614108,0.359438,0.018311,6.141085,-20.594681,0.615140,0.000000
37.610001,0.116925,-20.639162,0.024489,0.024368,0.618948,0.520108,0.026496,6.189476,-20.639162,0.620153,0.000000
37.910004,0.118787,-20.728123,0.024666,0.024569,0.624056,0.528390,0.026917,6.240556,-20.728123,0.625148,0.000000
38.210003,0.110967,-20.639162,0.024865,0.024765,0.629025,0.493606,0.025145,6.290248,-20.639162,0.630144,0.000000
38.510002,0.075219,-20.683641,0.025054,0.024958,0.633942,0.334592,0.017045,6.339419,-20.683641,0.635139,0.000000
38.810001,0.090859,-20.639162,0.025235,0.025152,0.638859,0.404160,0.020589,6.388591,-20.639162,0.640134,0.000000
39.110001,0.105381,-20.683641,0.025438,0.025355,0.644019,0.468760,0.023880,6.440191,-20.683641,0.645129,0.000000
39.410004,0.132937,-20.683641,0.025636,0.025551,0.648997,0.591333,0.030124,6.489970,-20.683641,0.650124,0.000000
39.710003,0.121393,-20.683641,0.025817,0.025751,0.654070,0.539985,0.027508,6.540702,-20.683641,0.655137,0.000000
40.010002,0.133309,-20.728123,0.026003,0.025947,0.659048,0.592989,0.030208,6.590481,-20.728123,0.660132,0.000000
40.310001,0.130330,-20.639162,0.026205,0.026143,0.664026,0.579738,0.029533,6.640260,-20.639162,0.665127,0.000000
40.610001,0.086763,-20.639162,0.026421,0.026341,0.669065,0.385940,0.019661,6.690646,-20.639162,0.670123,0.000000
40.910004,0.138523,-20.639162,0.026606,0.026532,0.673921,0.616179,0.031390,6.739210,-20.639162,0.675118,0.000000
41.210003,0.068144,-20.728123,0.026809,0.026734,0.679038,0.303120,0.015442,6.790377,-20.728123,0.680113,0.000000
41.510002,0.147087,-20.639162,0.026994,0.026926,0.683920,0.654276,0.033330,6.839201,-20.639162,0.685126,0.000000
41.810001,0.121393,-20.683641,0.027175,0.027126,0.689011,0.539985,0.027508,6.890108,-20.683641,0.690121,0.000000
42.110001,0.147832,-20.639162,0.027361,0.027323,0.694006,0.657589,0.033499,6.940060,-20.639162,0.695116,0.000000
42.410004,0.132565,-20.639162,0.027559,0.027520,0.699019,0.589677,0.030040,6.990186,-20.639162,0.700111,0.000000
42.710003,0.141129,-20.639162,0.027749,0.027720,0.704092,0.627774,0.031980,7.040918,-20.639162,0.705106,0.000000
43.010002,0.145225,-20.728123,0.027930,0.027912,0.708957,0.645994,0.032909,7.089570,-20.728123,0.710102,0.000000
43.310001,0.101285,-20.683641,0.028137,0.028110,0.713996,0.450539,0.022952,7.139956,-20.683641,0.715097,0.000000
43.610001,0.170919,-20.639162,0.028322,0.028304,0.718921,0.760285,0.038731,7.189214,-20.639162,0.720109,0.000000
43.910004,0.125117,-20.683641,0.028534,0.028508,0.724107,0.556549,0.028352,7.241074,-20.683641,0.725105,0.000000
44.210003,0.145970,-20.639162,0.028732,0.028696,0.728877,0.649307,0.033077,7.288772,-20.639162,0.730100,0.000000
44.510002,0.121393,-20.683641,0.028943,0.028897,0.733985,0.539985,0.027508,7.339851,-20.683641,0.735095,0.000000
44.810001,0.147459,-20.683641,0.029146,0.029092,0.738946,0.655932,0.033415,7.389457,-20.683641,0.740090,0.000000
45.110001,0.123255,-20.639162,0.029336,0.029290,0.743976,0.548267,0.027930,7.439755,-20.639162,0.745086,0.000000
45.410004,0.115063,-20.639162,0.029543,0.029491,0.749084,0.511826,0.026074,7.490835,-20.639162,0.750098,0.000000
45.710003,0.160865,-20.639162,0.029745,0.029684,0.753983,0.715563,0.036453,7.539834,-20.639162,0.755093,0.000000
46.010002,0.166450,-20.639162,0.029943,0.029885,0.759083,0.740409,0.037718,7.590827,-20.639162,0.760089,0.000000
46.310001,0.150066,-20.683641,0.030142,0.030075,0.763896,0.667527,0.034005,7.638957,-20.683641,0.765084,0.000000
46.610001,0.131075,-20.639162,0.030357,0.030279,0.769090,0.583051,0.029702,7.690904,-20.639162,0.770079,0.000000
46.910004,0.162354,-20.639162,0.030543,0.030465,0.773817,0.722188,0.036790,7.738168,-20.639162,0.775074,0.000000
47.210003,0.097189,-20.683641,0.030745,0.030667,0.778951,0.432319,0.022023,7.789508,-20.683641,0.780087,0.000000
47.510002,0.144108,-20.594681,0.030957,0.030862,0.783903,0.641025,0.032655,7.839026,-20.594681,0.785082,0.000000
47.810001,0.142619,-20.639162,0.031159,0.031062,0.788985,0.634399,0.032318,7.889845,-20.639162,0.790077,0.000000
48.110001,0.185441,-20.683641,0.031332,0.031258,0.793954,0.824885,0.042022,7.939538,-20.683641,0.795072,0.000000
48.410004,0.152300,-20.639162,0.031534,0.031455,0.798966,0.677466,0.034512,7.989664,-20.639162,0.800068,0.000000
48.710003,0.154907,-20.683641,0.031746,0.031657,0.804092,0.689060,0.035102,8.040916,-20.683641,0.805063,0.000000
49.010002,0.163471,-20.594681,0.031931,0.031845,0.808861,0.727158,0.037043,8.088614,-20.594681,0.810058,0.000000
49.310001,0.146715,-20.639162,0.032121,0.032045,0.813952,0.652620,0.033246,8.139520,-20.639162,0.815071,0.000000
49.610001,0.141502,-20.639162,0.032341,0.032241,0.818921,0.629430,0.032065,8.189212,-20.639162,0.820066,0.000000
49.910004,0.139640,-20.639162,0.032561,0.032442,0.824020,0.621148,0.031643,8.240205,-20.639162,0.825061,0.000000
50.210003,0.182462,-20.639162,0.032763,0.032632,0.828851,0.811634,0.041347,8.288509,-20.639162,0.830056,0.000000
50.510002,0.141129,-20.639162,0.032966,0.032833,0.833959,0.627774,0.031980,8.339588,-20.639162,0.835052,0.000000
50.810001,0.172036,-20.683641,0.033147,0.033028,0.838919,0.765255,0.038984,8.389194,-20.683641,0.840047,0.000000
51.110001,0.147832,-20.639162,0.033337,0.033224,0.843897,0.657589,0.033499,8.438973,-20.639162,0.845059,0.000000
51.410004,0.137778,-20.594681,0.033531,0.033420,0.848875,0.612866,0.031221,8.488752,-20.594681,0.850055,0.000000
51.710003,0.138523,-20.594681,0.033742,0.033617,0.853879,0.616179,0.031390,8.538791,-20.594681,0.855050,0.000000
52.010002,0.175760,-20.683641,0.033945,0.033817,0.858944,0.781818,0.039828,8.589437,-20.683641,0.860045,0.000000
52.310001,0.175387,-20.639162,0.034130,0.034011,0.863887,0.780162,0.039743,8.638868,-20.639162,0.865040,0.000000
52.610001,0.162354,-20.594681,0.034328,0.034212,0.868977,0.722188,0.036790,8.689775,-20.594681,0.870035,0.000000
52.910004,0.183207,-20.550200,0.034527,0.034404,0.873851,0.814946,0.041515,8.738512,-20.550200,0.875048,0.000000
53.210003,0.146342,-20.683641,0.034721,0.034606,0.878994,0.650963,0.033162,8.789939,-20.683641,0.880043,0.000000
53.510002,0.164589,-20.594681,0.034910,0.034797,0.883842,0.732127,0.037296,8.838417,-20.594681,0.885038,0.000000
53.810001,0.097934,-20.639162,0.035104,0.034997,0.888924,0.435632,0.022192,8.889236,-20.639162,0.890034,0.000000
54.110004,0.183580,-20.594681,0.035307,0.035194,0.893919,0.816603,0.041600,8.939189,-20.594681,0.895029,0.000000
54.410004,0.141874,-20.594681,0.035536,0.035390,0.898905,0.631086,0.032149,8.989054,-20.594681,0.900024,0.000000
54.710003,0.191772,-20.683641,0.035742,0.035588,0.903944,0.853043,0.043456,9.039440,-20.683641,0.905019,0.000000
55.010002,0.174643,-20.639162,0.035928,0.035785,0.908939,0.776849,0.039575,9.089392,-20.639162,0.910032,0.000000
55.310001,0.165706,-20.550200,0.036109,0.035982,0.913943,0.737096,0.037549,9.139431,-20.550200,0.915027,0.000000
55.610004,0.153790,-20.594681,0.036320,0.036178,0.918912,0.684091,0.034849,9.189123,-20.594681,0.920022,0.000000
55.910004,0.136661,-20.550200,0.036506,0.036373,0.923873,0.607897,0.030968,9.238728,-20.550200,0.925018,0.000000
56.210003,0.205922,-20.550200,0.036704,0.036570,0.928877,0.915987,0.046663,9.288767,-20.550200,0.930013,0.000000
56.510002,0.150438,-20.594681,0.036902,0.036770,0.933950,0.669184,0.034090,9.339499,-20.594681,0.935008,0.000000
56.810001,0.194751,-20.594681,0.037101,0.036961,0.938798,0.866295,0.044131,9.387978,-20.594681,0.940021,0.000000
57.110004,0.177994,-20.639162,0.037303,0.037162,0.943914,0.791757,0.040334,9.439144,-20.639162,0.945016,0.000000
57.410004,0.177622,-20.594681,0.037484,0.037359,0.948910,0.790100,0.040250,9.489097,-20.594681,0.950011,0.000000
57.710003,0.167568,-20.594681,0.037687,0.037551,0.953783,0.745378,0.037971,9.537835,-20.594681,0.955006,0.000000
58.010002,0.163099,-20.594681,0.037872,0.037747,0.958761,0.725501,0.036959,9.587613,-20.594681,0.960001,0.000000
58.310001,0.208901,-20.594681,0.038053,0.037948,0.963869,0.929238,0.047338,9.638693,-20.594681,0.964997,0.000000
58.610004,0.225658,-20.550200,0.038213,0.038145,0.968882,1.003775,0.051135,9.688818,-20.550200,0.969992,0.000000
58.910004,0.210763,-20.594681,0.038429,0.038341,0.973868,0.937520,0.047760,9.738685,-20.594681,0.975004,0.000000
59.210003,0.219700,-20.594681,0.038592,0.038539,0.978898,0.977273,0.049785,9.788983,-20.594681,0.980000,0.000000
59.510002,0.257682,-20.505718,0.038778,0.038734,0.983841,1.146226,0.058392,9.838415,-20.505718,0.984995,0.000000
59.810001,0.221189,-20.594681,0.038959,0.038933,0.988897,0.983899,0.050122,9.888974,-20.594681,0.989990,0.000000
60.110004,0.306835,-20.550200,0.039166,0.039125,0.993780,1.364870,0.069530,9.937799,-20.550200,0.994985,0.000000
60.410004,0.409237,-20.594681,0.039381,0.039326,0.998879,1.820379,0.092735,9.988792,-20.594681,0.999981,0.000000
60.710003,0.677718,-20.550200,0.039502,-0.000001,-0.000017,3.014640,0.153573,-0.000173,-20.550200,0.000252,0.000000
61.010002,0.665057,-20.550200,0.039524,-0.000001,-0.000017,2.958322,0.150704,-0.000173,-20.550200,0.000252,0.000000
61.310001,0.643087,-20.550200,0.039532,-0.000001,-0.000017,2.860595,0.145726,-0.000173,-20.550200,0.000590,0.000000
61.610004,0.651652,-20.505718,0.039528,0.000010,0.000252,2.898692,0.147666,0.002515,-20.505718,0.001093,0.000000
61.910004,0.714210,-20.550200,0.039524,0.000025,0.000624,3.176966,0.161842,0.006244,-20.550200,0.001587,0.000000
62.210003,0.788312,-20.550200,0.039515,0.000041,0.001049,3.506589,0.178634,0.010494,-20.550200,0.002090,0.000000
62.510002,0.870979,-20.594681,0.039541,0.000061,0.001544,3.874309,0.197367,0.015437,-20.594681,0.002593,0.000000
62.810001,0.966679,-20.550200,0.039537,0.000079,0.002003,4.300002,0.219053,0.020033,-20.550200,0.003087,0.000000
63.110004,1.070571,-20.550200,0.039541,0.000101,0.002576,4.762137,0.242595,0.025757,-20.550200,0.003590,0.000000
63.410004,1.159195,-20.550200,0.039554,0.000126,0.003200,5.156359,0.262677,0.032001,-20.550200,0.004093,0.000000
63.710003,1.265694,-20.594681,0.039550,0.000146,0.003703,5.630088,0.286810,0.037031,-20.594681,0.004588,0.000000
64.010002,1.362883,-20.550200,0.039593,0.000163,0.004137,6.062407,0.308834,0.041367,-20.550200,0.005091,0.000000
64.310005,1.476829,-20.505718,0.039606,0.000179,0.004544,6.569264,0.334654,0.045443,-20.505718,0.005594,0.000000
64.610001,1.643280,-20.594681,0.039636,0.000199,0.005056,7.309672,0.372372,0.050559,-20.594681,0.006088,0.000000
64.910004,1.777334,-20.461237,0.039640,0.000219,0.005568,7.905975,0.402750,0.055676,-20.461237,0.006591,0.000000
65.210007,1.988841,-20.550200,0.039640,0.000244,0.006209,8.846807,0.450678,0.062093,-20.550200,0.007094,0.000000
65.510002,2.084913,-20.505718,0.039653,0.000263,0.006678,9.274158,0.472448,0.066776,-20.505718,0.007588,0.000000
65.810005,2.197370,-20.550200,0.039670,0.000278,0.007068,9.774389,0.497931,0.070679,-20.550200,0.008091,0.000000
66.110001,2.482607,-20.550200,0.039692,0.000302,0.007666,11.043188,0.562567,0.076663,-20.550200,0.008594,0.000000
66.410004,2.584637,-20.550200,0.039718,0.000315,0.008013,11.497042,0.585687,0.080132,-20.550200,0.009089,0.000000
66.710007,2.800613,-20.505718,0.039731,0.000338,0.008586,12.457750,0.634628,0.085855,-20.505718,0.009592,0.000000
67.010002,3.093670,-20.550200,0.039735,0.000360,0.009149,13.761333,0.701036,0.091492,-20.550200,0.010095,0.000000
67.310005,3.269803,-20.550200,0.039757,0.000380,0.009652,14.544808,0.740948,0.096522,-20.550200,0.010589,0.000000
67.610001,3.468277,-20.639162,0.039774,0.000399,0.010129,15.427668,0.785923,0.101292,-20.639162,0.011092,0.000000
67.910004,3.689839,-20.594681,0.039782,0.000417,0.010598,16.413221,0.836129,0.105975,-20.594681,0.011595,0.000000
68.210007,3.862992,-20.505718,0.039791,0.000431,0.010936,17.183447,0.875367,0.109357,-20.505718,0.012089,0.000000
68.510002,4.173923,-20.550200,0.039813,0.000453,0.011508,18.566536,0.945824,0.115081,-20.550200,0.012592,0.000000
68.810005,4.458788,-20.550200,0.039821,0.000477,0.012115,19.833679,1.010376,0.121152,-20.550200,0.013095,0.000000
69.110001,4.720565,-20.505718,0.039834,0.000496,0.012609,20.998123,1.069695,0.126095,-20.505718,0.013589,0.000000
69.410004,5.014740,-20.594681,0.039851,0.000517,0.013121,22.306675,1.136356,0.131211,-20.594681,0.014092,0.000000
69.710007,5.253058,-20.550200,0.039877,0.000533,0.013546,23.366768,1.190360,0.135461,-20.550200,0.014587,0.000000
70.010002,5.562500,-20.550200,0.039903,0.000553,0.014058,24.743233,1.260480,0.140577,-20.550200,0.015090,0.000000
70.310005,5.795232,-20.550200,0.039912,0.000570,0.014483,25.778481,1.313218,0.144827,-20.550200,0.015593,0.000000
70.610001,6.193671,-20.550200,0.039925,0.000594,0.015090,27.550823,1.403506,0.150897,-20.550200,0.016087,0.000000
70.910004,6.593971,-20.505718,0.039946,0.000619,0.015714,29.331450,1.494215,0.157141,-20.505718,0.016590,0.000000
71.210007,6.823353,-20.550200,0.039963,0.000637,0.016174,30.351789,1.546194,0.161738,-20.550200,0.017093,0.000000
71.510002,7.078800,-20.550200,0.039981,0.000653,0.016590,31.488075,1.604079,0.165900,-20.550200,0.017587,0.000000
71.810005,7.407605,-20.550200,0.039981,0.000673,0.017102,32.950672,1.678587,0.171017,-20.550200,0.018090,0.000000
72.110001,7.653371,-20.550200,0.040002,0.000689,0.017509,34.043896,1.734279,0.175093,-20.550200,0.018593,0.000000
72.410004,8.097239,-20.550200,0.040011,0.000711,0.018056,36.018322,1.834861,0.180556,-20.550200,0.019088,0.000000
72.710007,8.376518,-20.505718,0.040024,0.000731,0.018559,37.260612,1.898146,0.185586,-20.505718,0.019591,0.000000
73.010002,8.838633,-20.594681,0.040063,0.000754,0.019157,39.316200,2.002863,0.191570,-20.594681,0.020094,0.000000
73.310005,9.130945,-20.594681,0.040071,0.000773,0.019643,40.616474,2.069102,0.196427,-20.594681,0.020588,0.000000
73.610001,9.279149,-20.550200,0.040093,0.000787,0.019998,41.275715,2.102685,0.199982,-20.550200,0.021091,0.000000
73.910004,9.681684,-20.550200,0.040114,0.000805,0.020449,43.066280,2.193901,0.204492,-20.550200,0.021594,0.000000
74.210007,10.084218,-20.550200,0.040123,0.000825,0.020961,44.856842,2.285116,0.209608,-20.550200,0.022088,0.000000
74.510002,10.464783,-20.550200,0.040123,0.000846,0.021490,46.549679,2.371354,0.214899,-20.550200,0.022591,0.000000
74.810005,11.053876,-20.505718,0.040140,0.000873,0.022166,49.170097,2.504844,0.221663,-20.505718,0.023094,0.000000
75.110001,11.186440,-20.550200,0.040170,0.000890,0.022609,49.759773,2.534884,0.226086,-20.550200,0.023589,0.000000
75.410004,11.481732,-20.550200,0.040188,0.000907,0.023042,51.073296,2.601798,0.230422,-20.550200,0.024092,0.000000
75.710007,11.784843,-20.550200,0.040205,0.000926,0.023519,52.421600,2.670484,0.235192,-20.550200,0.024595,0.000000
76.010002,12.286057,-20.550200,0.040226,0.000945,0.024013,54.651108,2.784060,0.240135,-20.550200,0.025089,0.000000
76.310005,12.594381,-20.505718,0.040239,0.000962,0.024438,56.022606,2.853928,0.244384,-20.505718,0.025592,0.000000
76.610001,13.085541,-20.505718,0.040257,0.000984,0.025002,58.207394,2.965226,0.250021,-20.505718,0.026095,0.000000
76.910004,13.377852,-20.550200,0.040265,0.001005,0.025531,59.507660,3.031465,0.255311,-20.550200,0.026589,0.000000
77.210007,13.865289,-20.550200,0.040278,0.001027,0.026095,61.675884,3.141919,0.260948,-20.550200,0.027092,0.000000
77.510002,14.102862,-20.550200,0.040304,0.001044,0.026520,62.732666,3.195754,0.265198,-20.550200,0.027595,0.000000
77.810005,14.498694,-20.505718,0.040308,0.001063,0.027005,64.493416,3.285451,0.270054,-20.505718,0.028089,0.000000
78.110001,14.881866,-20.505718,0.040339,0.001083,0.027517,66.197845,3.372279,0.275171,-20.505718,0.028592,0.000000
78.410004,15.239343,-20.505718,0.040334,0.001100,0.027942,67.787979,3.453285,0.279420,-20.505718,0.029095,0.000000
78.710007,15.798646,-20.594681,0.040356,0.001122,0.028506,70.275887,3.580024,0.285057,-20.594681,0.029590,0.000000
79.010002,16.036964,-20.550200,0.040373,0.001142,0.029000,71.335983,3.634028,0.290000,-20.550200,0.030093,0.000000
79.310005,16.533709,-20.550200,0.040395,0.001164,0.029555,73.545609,3.746592,0.295551,-20.550200,0.030596,0.000000
79.610001,17.050190,-20.550200,0.040399,0.001183,0.030049,75.843033,3.863628,0.300494,-20.550200,0.031090,0.000000
79.910004,17.306009,-20.505718,0.040420,0.001200,0.030474,76.980972,3.921598,0.304743,-20.505718,0.031593,0.000000
80.210007,17.771475,-20.505718,0.040455,0.001220,0.030995,79.051468,4.027074,0.309947,-20.505718,0.032096,0.000000
80.510002,18.441002,-20.550200,0.040455,0.001247,0.031662,82.029671,4.178791,0.316624,-20.550200,0.032590,0.000000
80.810005,18.534840,-20.505718,0.040477,0.001260,0.031992,82.447083,4.200055,0.319920,-20.505718,0.033093,0.000000
81.110001,19.114250,-20.505718,0.040494,0.001283,0.032582,85.024429,4.331351,0.325817,-20.505718,0.033596,0.000000
81.410004,19.441195,-20.550200,0.040507,0.001299,0.032998,86.478752,4.405437,0.329979,-20.550200,0.034091,0.000000
81.710007,20.100292,-20.505718,0.040524,0.001321,0.033553,89.410568,4.554791,0.335530,-20.505718,0.034594,0.000000
82.010002,20.613050,-20.550200,0.040533,0.001339,0.034004,91.691429,4.670984,0.340039,-20.550200,0.035088,0.000000
82.310005,21.209591,-20.550200,0.040537,0.001362,0.034585,94.344971,4.806162,0.345850,-20.550200,0.035591,0.000000
82.610001,21.792727,-20.505718,0.040563,0.001382,0.035105,96.938889,4.938303,0.351053,-20.505718,0.036094,0.000000
82.910004,22.324474,-20.505718,0.040584,0.001403,0.035634,99.304222,5.058798,0.356343,-20.505718,0.036588,0.000000
83.210007,22.714348,-20.550200,0.040602,0.001421,0.036094,101.038467,5.147145,0.360939,-20.550200,0.037091,0.000000
83.510002,23.153376,-20.505718,0.040602,0.001436,0.036467,102.991356,5.246630,0.364668,-20.505718,0.037594,0.000000
83.810005,23.627777,-20.505718,0.040636,0.001453,0.036909,105.101601,5.354131,0.369091,-20.505718,0.038089,0.000000
84.110001,24.257460,-20.505718,0.040610,0.001471,0.037360,107.902573,5.496819,0.373601,-20.505718,0.038592,0.000000
84.410004,25.372343,-20.505718,0.040636,0.001499,0.038071,112.861816,5.749455,0.380712,-20.505718,0.039095,0.000000
84.710007,25.958456,-20.550200,0.040666,0.001520,0.038600,115.468979,5.882270,0.386002,-20.550200,0.039589,0.000000
85.010002,26.504726,-20.505718,0.040675,0.001540,0.039121,117.898911,6.006057,0.391206,-20.505718,0.040092,0.000000
85.310005,26.832415,-20.550200,0.040696,0.001556,0.039519,119.356544,6.080312,0.395195,-20.550200,0.040595,0.000000
85.610001,27.600246,-20.505718,0.040696,0.001576,0.040031,122.772026,6.254305,0.400311,-20.505718,0.041089,0.000000
85.910004,28.132740,-20.461237,0.040709,0.001596,0.040534,125.140678,6.374970,0.405341,-20.461237,0.041592,0.000000
86.210007,29.141125,-20.505718,0.040727,0.001616,0.041037,129.626190,6.603473,0.410371,-20.505718,0.042095,0.000000
86.510002,30.064236,-20.461237,0.040727,0.001640,0.041653,133.732407,6.812653,0.416529,-20.461237,0.042589,0.000000
86.810005,30.755358,-20.505718,0.040752,0.001660,0.042156,136.806671,6.969264,0.421558,-20.505718,0.043092,0.000000
87.110001,31.180981,-20.461237,0.040774,0.001676,0.042572,138.699936,7.065711,0.425721,-20.461237,0.043595,0.000000
87.410004,32.336452,-20.461237,0.040774,0.001699,0.043162,143.839722,7.327545,0.431618,-20.461237,0.044090,0.000000
87.710007,32.752392,-20.461237,0.040796,0.001713,0.043517,145.689911,7.421798,0.435174,-20.461237,0.044593,0.000000
88.010002,33.406651,-20.461237,0.040800,0.001731,0.043960,148.600204,7.570055,0.439597,-20.461237,0.045096,0.000000
88.310005,34.816826,-20.505718,0.040817,0.001758,0.044645,154.872971,7.889606,0.446448,-20.505718,0.045590,0.000000
88.610001,35.391022,-20.461237,0.040821,0.001774,0.045052,157.427124,8.019720,0.450524,-20.461237,0.046093,0.000000
88.910004,36.350254,-20.461237,0.040847,0.001795,0.045581,161.694000,8.237085,0.455814,-20.461237,0.046596,0.000000
89.210007,37.020527,-20.505718,0.040856,0.001812,0.046032,164.675522,8.388971,0.460323,-20.505718,0.047090,0.000000
89.510002,37.899696,-20.461237,0.040873,0.001829,0.046457,168.586273,8.588194,0.464573,-20.461237,0.047593,0.000000
89.810005,38.725620,-20.505718,0.040877,0.001849,0.046969,172.260162,8.775351,0.469689,-20.505718,0.048096,0.000000
90.110001,39.747780,-20.461237,0.040890,0.001870,0.047489,176.806961,9.006975,0.474893,-20.461237,0.048591,0.000000
90.410004,41.081619,-20.461237,0.040903,0.001892,0.048062,182.740173,9.309228,0.480617,-20.461237,0.049094,0.000000
90.710007,41.926533,-20.461237,0.040916,0.001913,0.048582,186.498535,9.500689,0.485820,-20.461237,0.049597,0.000000
91.010002,42.803471,-20.416756,0.040925,0.001930,0.049016,190.399353,9.699405,0.490156,-20.416756,0.050091,0.000000
91.310005,43.952240,-20.461237,0.040942,0.001951,0.049553,195.509323,9.959721,0.495533,-20.461237,0.050594,0.000000
91.610001,44.729008,-20.416756,0.040946,0.001968,0.049978,198.964569,10.135738,0.499782,-20.416756,0.051097,0.000000
91.910004,45.847240,-20.461237,0.040955,0.001989,0.050516,203.938705,10.389132,0.505159,-20.461237,0.051591,0.000000
92.210007,47.275291,-20.461237,0.040972,0.002013,0.051140,210.291000,10.712734,0.511403,-20.461237,0.052094,0.000000
92.510002,48.242340,-20.505718,0.040981,0.002031,0.051600,214.592651,10.931870,0.515999,-20.505718,0.052597,0.000000
92.810005,49.187050,-20.505718,0.040994,0.002051,0.052086,218.794922,11.145945,0.520856,-20.505718,0.053092,0.000000
93.110001,50.113884,-20.416756,0.041011,0.002069,0.052563,222.917694,11.355968,0.525626,-20.416756,0.053595,0.000000
93.410004,51.166210,-20.461237,0.040998,0.002087,0.053014,227.598663,11.594429,0.530135,-20.461237,0.054098,0.000000
93.710007,52.529095,-20.461237,0.041033,0.002108,0.053534,233.661087,11.903263,0.535339,-20.461237,0.054592,0.000000
94.010002,53.688660,-20.461237,0.041024,0.002128,0.054054,238.819092,12.166024,0.540542,-20.461237,0.055095,0.000000
94.310005,55.155064,-20.416756,0.041046,0.002151,0.054635,245.341980,12.498316,0.546352,-20.416756,0.055598,0.000000
94.610008,56.127701,-20.416756,0.041046,0.002169,0.055095,249.668488,12.718719,0.550949,-20.416756,0.056092,0.000000
94.910004,56.871700,-20.416756,0.041072,0.002183,0.055450,252.977951,12.887311,0.554504,-20.416756,0.056595,0.000000
95.210007,58.162346,-20.461237,0.041063,0.002203,0.055945,258.719025,13.179776,0.559447,-20.461237,0.057089,0.000000
95.510002,59.075027,-20.461237,0.041084,0.002220,0.056378,262.778839,13.386592,0.563783,-20.461237,0.057592,0.000000
95.810005,60.682560,-20.461237,0.041084,0.002242,0.056951,269.929504,13.750864,0.569507,-20.461237,0.058095,0.000000
96.110008,62.432339,-20.461237,0.041080,0.002268,0.057618,277.712921,14.147370,0.576185,-20.461237,0.058590,0.000000
96.410004,63.383007,-20.505718,0.041106,0.002284,0.058026,281.941711,14.362795,0.580261,-20.505718,0.059093,0.000000
96.710007,64.669182,-20.461237,0.041102,0.002303,0.058503,287.662903,14.654246,0.585030,-20.461237,0.059596,0.000000
97.010002,65.437386,-20.461237,0.041119,0.002317,0.058859,291.080017,14.828324,0.588586,-20.461237,0.060090,0.000000
97.310005,67.232224,-20.505718,0.041115,0.002342,0.059492,299.063873,15.235040,0.594917,-20.505718,0.060593,0.000000
97.610008,67.249725,-20.461237,0.041136,0.002337,0.059362,299.141724,15.239006,0.593616,-20.461237,0.059630,0.000000
97.910004,66.782021,-20.461237,0.041136,0.002332,0.059223,297.061249,15.133022,0.592228,-20.461237,0.059362,0.000000
98.210007,66.415237,-20.505718,0.041145,0.002330,0.059171,295.429718,15.049908,0.591708,-20.505718,0.059362,0.000000
98.510002,66.109146,-20.461237,0.041158,0.002329,0.059153,294.068176,14.980546,0.591535,-20.461237,0.059362,0.000000
98.810005,65.877533,-20.461237,0.041145,0.002329,0.059153,293.037903,14.928062,0.591535,-20.461237,0.059362,0.000000
99.110008,65.571068,-20.505718,0.041158,0.002329,0.059145,291.674683,14.858616,0.591448,-20.505718,0.059362,0.000000
99.410004,65.389351,-20.461237,0.041149,0.002329,0.059145,290.866364,14.817439,0.591448,-20.461237,0.059362,0.000000
99.710007,65.242638,-20.505718,0.041166,0.002329,0.059145,290.213745,14.784193,0.591448,-20.505718,0.059362,0.000000
100.010002,65.094055,-20.416756,0.041166,0.002329,0.059145,289.552826,14.750524,0.591448,-20.416756,0.059362,0.000000
100.310005,64.961494,-20.461237,0.041166,0.002329,0.059145,288.963165,14.720485,0.591448,-20.461237,0.059362,0.000000
100.610008,64.836372,-20.416756,0.041162,0.002329,0.059145,288.406586,14.692132,0.591448,-20.416756,0.059362,0.000000
100.910004,64.728760,-20.505718,0.041162,0.002329,0.059145,287.927917,14.667747,0.591448,-20.505718,0.059362,0.000000
101.210007,64.628220,-20.461237,0.041162,0.002329,0.059145,287.480682,14.644963,0.591448,-20.461237,0.059362,0.000000
101.510002,64.540337,-20.416756,0.041171,0.002329,0.059145,287.089752,14.625050,0.591448,-20.416756,0.059362,0.000000
101.810005,64.452087,-20.461237,0.041171,0.002329,0.059145,286.697205,14.605051,0.591448,-20.461237,0.059362,0.000000
102.110008,64.370911,-20.505718,0.041162,0.002329,0.059145,286.336121,14.586657,0.591448,-20.505718,0.059362,0.000000
102.410004,64.282288,-20.461237,0.041188,0.002329,0.059145,285.941895,14.566574,0.591448,-20.461237,0.059362,0.000000
102.710007,64.215263,-20.505718,0.041171,0.002329,0.059145,285.643768,14.551387,0.591448,-20.505718,0.059362,0.000000
103.010002,64.149353,-20.505718,0.041153,0.002329,0.059145,285.350586,14.536451,0.591448,-20.505718,0.059362,0.000000
103.310005,64.092751,-20.461237,0.041166,0.002329,0.059145,285.098785,14.523625,0.591448,-20.461237,0.059362,0.000000
103.610008,64.019020,-20.461237,0.041166,0.002329,0.059145,284.770813,14.506917,0.591448,-20.461237,0.059362,0.000000
103.910004,63.963535,-20.461237,0.041158,0.002329,0.059145,284.524017,14.494345,0.591448,-20.461237,0.059362,0.000000
104.210007,63.906933,-20.461237,0.041175,0.002329,0.059145,284.272247,14.481518,0.591448,-20.461237,0.059362,0.000000
104.510002,63.863739,-20.461237,0.041175,0.002329,0.059145,284.080109,14.471730,0.591448,-20.461237,0.059362,0.000000
104.810005,63.814587,-20.505718,0.041171,0.002329,0.059145,283.861450,14.460592,0.591448,-20.505718,0.059362,0.000000
105.110008,63.748302,-20.416756,0.041166,0.002329,0.059145,283.566620,14.445572,0.591448,-20.416756,0.059362,0.000000
105.410004,63.695053,-20.505718,0.041162,0.002329,0.059145,283.329742,14.433506,0.591448,-20.505718,0.059362,0.000000
105.710007,63.679413,-20.505718,0.041158,0.002329,0.059145,283.260162,14.429961,0.591448,-20.505718,0.059362,0.000000
106.010002,63.619091,-20.461237,0.041175,0.002329,0.059145,282.991852,14.416292,0.591448,-20.461237,0.059362,0.000000
106.310005,63.559139,-20.461237,0.041171,0.002329,0.059145,282.725159,14.402707,0.591448,-20.461237,0.059362,0.000000
106.610008,63.533073,-20.461237,0.041162,0.002329,0.059145,282.609222,14.396800,0.591448,-20.461237,0.059362,0.000000
106.910004,63.501793,-20.461237,0.041175,0.002329,0.059145,282.470093,14.389712,0.591448,-20.461237,0.059362,0.000000
107.210007,63.463066,-20.461237,0.041192,0.002329,0.059145,282.297821,14.380937,0.591448,-20.461237,0.059362,0.000000
107.510002,63.409073,-20.461237,0.041153,0.002329,0.059145,282.057648,14.368701,0.591448,-20.461237,0.059362,0.000000
107.810005,63.384869,-20.461237,0.041179,0.002329,0.059145,281.949982,14.363217,0.591448,-20.461237,0.059362,0.000000
108.110008,63.334225,-20.416756,0.041175,0.002329,0.059145,281.724701,14.351740,0.591448,-20.416756,0.059362,0.000000
108.410004,63.304810,-20.461237,0.041166,0.002329,0.059145,281.593842,14.345075,0.591448,-20.461237,0.059362,0.000000
108.710007,63.267197,-20.461237,0.041171,0.002329,0.059145,281.426544,14.336552,0.591448,-20.461237,0.059362,0.000000
109.010002,63.246346,-20.505718,0.041188,0.002329,0.059145,281.333801,14.331826,0.591448,-20.505718,0.059362,0.000000
109.310005,63.208736,-20.505718,0.041171,0.002329,0.059145,281.166504,14.323304,0.591448,-20.505718,0.059362,0.000000
109.610008,63.181927,-20.416756,0.041171,0.002329,0.059145,281.047241,14.317229,0.591448,-20.416756,0.059362,0.000000
109.910004,63.167774,-20.505718,0.041171,0.002329,0.059145,280.984283,14.314022,0.591448,-20.505718,0.059362,0.000000
110.210007,63.113037,-20.461237,0.041175,0.002329,0.059145,280.740814,14.301619,0.591448,-20.461237,0.059362,0.000000
110.510002,63.087715,-20.461237,0.041166,0.002329,0.059145,280.628174,14.295880,0.591448,-20.461237,0.059362,0.000000
110.810005,63.066116,-20.461237,0.041166,0.002329,0.059145,280.532104,14.290986,0.591448,-20.461237,0.059362,0.000000
111.110008,63.059044,-20.505718,0.041184,0.002329,0.059145,280.500641,14.289384,0.591448,-20.505718,0.059362,0.000000
111.410004,63.013985,-20.461237,0.041175,0.002329,0.059145,280.300201,14.279173,0.591448,-20.461237,0.059362,0.000000
111.710007,62.999836,-20.416756,0.041166,0.002329,0.059145,280.237274,14.275967,0.591448,-20.416756,0.059362,0.000000
112.010002,62.978611,-20.372276,0.041184,0.002329,0.059145,280.142853,14.271157,0.591448,-20.372276,0.059362,0.000000
112.310005,62.934669,-20.416756,0.041192,0.002329,0.059145,279.947388,14.261200,0.591448,-20.416756,0.059362,0.000000
112.610008,62.903389,-20.416756,0.041179,0.002329,0.059145,279.808258,14.254111,0.591448,-20.416756,0.059362,0.000000
112.910004,62.890358,-20.416756,0.041179,0.002329,0.059145,279.750275,14.251159,0.591448,-20.416756,0.059362,0.000000
113.210007,62.869877,-20.416756,0.041188,0.002329,0.059145,279.659180,14.246517,0.591448,-20.416756,0.059362,0.000000
113.510002,62.846790,-20.461237,0.041171,0.002329,0.059145,279.556488,14.241286,0.591448,-20.461237,0.059362,0.000000
113.810005,62.813648,-20.416756,0.041179,0.002329,0.059145,279.409058,14.233776,0.591448,-20.416756,0.059362,0.000000
114.110008,62.805828,-20.327795,0.041188,0.002329,0.059145,279.374268,14.232004,0.591448,-20.327795,0.059362,0.000000
114.410004,62.770081,-20.416756,0.041188,0.002329,0.059145,279.215271,14.223904,0.591448,-20.416756,0.059362,0.000000
114.710007,62.765614,-20.372276,0.041188,0.002329,0.059145,279.195404,14.222891,0.591448,-20.372276,0.059362,0.000000
115.010002,62.740665,-20.461237,0.041171,0.002329,0.059145,279.084412,14.217237,0.591448,-20.461237,0.059362,0.000000
115.310005,62.714596,-20.416756,0.041175,0.002329,0.059145,278.968445,14.211330,0.591448,-20.416756,0.059362,0.000000
115.610008,62.707893,-20.416756,0.041179,0.002329,0.059145,278.938629,14.209812,0.591448,-20.416756,0.059362,0.000000
115.910004,62.690022,-20.416756,0.041166,0.002329,0.059145,278.859131,14.205762,0.591448,-20.416756,0.059362,0.000000
116.210007,62.659859,-20.416756,0.041175,0.002329,0.059145,278.724976,14.198927,0.591448,-20.416756,0.059362,0.000000
116.510002,62.648689,-20.416756,0.041184,0.002329,0.059145,278.675293,14.196396,0.591448,-20.416756,0.059362,0.000000
116.810005,62.621506,-20.416756,0.041179,0.002329,0.059145,278.554382,14.190236,0.591448,-20.416756,0.059362,0.000000
117.110008,62.594692,-20.372276,0.041171,0.002329,0.059145,278.435089,14.184160,0.591448,-20.372276,0.059362,0.000000
117.410004,62.597301,-20.372276,0.041171,0.002329,0.059145,278.446716,14.184752,0.591448,-20.372276,0.059362,0.000000
117.710007,62.569000,-20.416756,0.041166,0.002329,0.059145,278.320801,14.178338,0.591448,-20.416756,0.059362,0.000000
118.010002,62.558945,-20.372276,0.041175,0.002329,0.059145,278.276093,14.176059,0.591448,-20.372276,0.059362,0.000000
118.310005,62.535858,-20.416756,0.041175,0.002329,0.059145,278.173401,14.170828,0.591448,-20.416756,0.059362,0.000000
118.610008,62.516495,-20.372276,0.041179,0.002329,0.059145,278.087250,14.166441,0.591448,-20.372276,0.059362,0.000000
118.910004,62.496014,-20.327795,0.041184,0.002329,0.059145,277.996155,14.161798,0.591448,-20.327795,0.059362,0.000000
119.210007,62.476650,-20.372276,0.041179,0.002329,0.059145,277.910034,14.157412,0.591448,-20.372276,0.059362,0.000000
119.510002,62.458778,-20.461237,0.041175,0.002329,0.059145,277.830536,14.153361,0.591448,-20.461237,0.059362,0.000000
119.810005,62.452076,-20.372276,0.041175,0.002329,0.059145,277.800720,14.151842,0.591448,-20.372276,0.059362,0.000000
120.110008,62.443512,-20.372276,0.041184,0.002329,0.059145,277.762604,14.149902,0.591448,-20.372276,0.059362,0.000000
120.410004,62.439785,-20.416756,0.041166,0.002329,0.059145,277.746033,14.149057,0.591448,-20.416756,0.059362,0.000000
120.710007,62.402550,-20.416756,0.041179,0.002329,0.059145,277.580414,14.140619,0.591448,-20.416756,0.059362,0.000000
121.010002,62.380581,-20.372276,0.041171,0.002329,0.059145,277.482697,14.135642,0.591448,-20.372276,0.059362,0.000000
121.310005,62.393242,-20.372276,0.041179,0.002329,0.059145,277.539001,14.138511,0.591448,-20.372276,0.059362,0.000000
121.610008,62.356747,-20.372276,0.041175,0.002329,0.059145,277.376648,14.130240,0.591448,-20.372276,0.059362,0.000000
121.910004,62.351906,-20.372276,0.041171,0.002329,0.059145,277.355133,14.129144,0.591448,-20.372276,0.059362,0.000000
122.210007,62.334404,-20.372276,0.041188,0.002329,0.059145,277.277283,14.125178,0.591448,-20.372276,0.059362,0.000000
122.510002,62.316532,-20.416756,0.041166,0.002329,0.059145,277.197784,14.121128,0.591448,-20.416756,0.059362,0.000000
122.810005,62.308338,-20.372276,0.041171,0.002329,0.059145,277.161316,14.119271,0.591448,-20.372276,0.059362,0.000000
123.110008,62.288605,-20.327795,0.041175,0.002329,0.059145,277.073547,14.114799,0.591448,-20.327795,0.059362,0.000000
123.410004,62.279293,-20.327795,0.041179,0.002329,0.059145,277.032135,14.112689,0.591448,-20.327795,0.059362,0.000000
123.710007,62.268124,-20.372276,0.041171,0.002329,0.059145,276.982452,14.110159,0.591448,-20.372276,0.059362,0.000000
124.010002,62.250248,-20.372276,0.041192,0.002329,0.059145,276.902924,14.106108,0.591448,-20.372276,0.059362,0.000000
124.310005,62.235355,-20.372276,0.041179,0.002329,0.059145,276.836700,14.102733,0.591448,-20.372276,0.059362,0.000000
124.610008,62.246899,-20.327795,0.041162,0.002329,0.059145,276.888031,14.105350,0.591448,-20.327795,0.059362,0.000000
124.910004,62.230885,-20.327795,0.041162,0.002329,0.059145,276.816803,14.101720,0.591448,-20.327795,0.059362,0.000000
125.210007,62.218597,-20.327795,0.041179,0.002329,0.059145,276.762146,14.098935,0.591448,-20.327795,0.059362,0.000000
125.510010,62.199608,-20.372276,0.041171,0.002329,0.059145,276.677673,14.094633,0.591448,-20.372276,0.059362,0.000000
125.810005,62.191414,-20.416756,0.041175,0.002329,0.059145,276.641235,14.092775,0.591448,-20.416756,0.059362,0.000000
126.110008,62.165722,-20.327795,0.041188,0.002329,0.059145,276.526947,14.086953,0.591448,-20.327795,0.059362,0.000000
126.410004,62.156410,-20.372276,0.041179,0.002329,0.059145,276.485535,14.084844,0.591448,-20.372276,0.059362,0.000000
126.710007,62.149708,-20.416756,0.041192,0.002329,0.059145,276.455719,14.083325,0.591448,-20.416756,0.059362,0.000000
127.010010,62.137421,-20.372276,0.041171,0.002329,0.059145,276.401062,14.080541,0.591448,-20.372276,0.059362,0.000000
127.310005,62.132206,-20.372276,0.041179,0.002329,0.059145,276.377869,14.079359,0.591448,-20.372276,0.059362,0.000000
127.610008,62.129227,-20.327795,0.041175,0.002329,0.059145,276.364594,14.078684,0.591448,-20.327795,0.059362,0.000000
127.900009,62.113960,-20.416756,0.041188,0.002329,0.059145,276.296692,14.075224,0.591448,-20.416756,0.059362,0.000000