File: Data/I-18 Polished After 5_08182023_171901.csv
Time (sec),S:Load (lbs),S:HL1 (DIM),S:LVDT (in),S:Position (in),Ch:Position (mm),Ch:Load (N),Ch:Stress (MPa),Ch:Strain (mm/mm),Ch:HL1 (DIM),Set Point (),Cycles ()
0.110000,-0.019363,-34.161369,-0.000983,-0.019513,-0.495620,-0.086133,-0.004388,-4.956195,-34.161369,-0.495455,0.000000
0.350000,-0.021225,-34.072407,-0.001005,-0.019512,-0.495602,-0.094413,-0.004810,-4.956025,-34.072407,-0.495282,0.000000
0.590000,-0.018623,-34.116890,-0.001005,-0.019383,-0.492324,-0.082841,-0.004220,-4.923244,-34.116890,-0.491275,0.000000
0.830000,0.004097,-34.161369,-0.000961,-0.019229,-0.488413,0.018224,0.000928,-4.884130,-34.161369,-0.487286,0.000000
1.070000,0.006699,-34.072407,-0.000949,-0.019074,-0.484467,0.029797,0.001518,-4.844673,-34.072407,-0.483279,0.000000
1.310000,0.074097,-34.116890,-0.000940,-0.018914,-0.480417,0.329598,0.016791,-4.804171,-34.116890,-0.479290,0.000000
1.550000,0.075592,-34.027927,-0.000742,-0.018762,-0.476549,0.336250,0.017129,-4.765493,-34.027927,-0.475283,0.000000
1.790000,0.060318,-34.116890,-0.000535,-0.018596,-0.472343,0.268308,0.013668,-4.723432,-34.116890,-0.471294,0.000000
2.030000,0.064789,-34.161369,-0.000392,-0.018443,-0.468450,0.288195,0.014681,-4.684496,-34.161369,-0.467287,0.000000
2.270000,0.037979,-34.161369,-0.000254,-0.018282,-0.464356,0.168940,0.008606,-4.643563,-34.161369,-0.463298,0.000000
2.510000,0.056229,-34.161369,-0.000103,-0.018133,-0.460584,0.250117,0.012742,-4.605839,-34.161369,-0.459292,0.000000
2.750000,0.047287,-34.072407,0.000034,-0.017969,-0.456404,0.210343,0.010715,-4.564038,-34.072407,-0.455302,0.000000
2.990000,-0.002983,-34.161369,0.000181,-0.017816,-0.452519,-0.013269,-0.000676,-4.525187,-34.161369,-0.451296,0.000000
3.230000,0.014893,-34.161369,0.000358,-0.017658,-0.448521,0.066245,0.003375,-4.485207,-34.161369,-0.447306,0.000000
3.470000,0.090485,-34.116890,0.000543,-0.017502,-0.444557,0.402496,0.020504,-4.445575,-34.116890,-0.443300,0.000000
3.710000,0.084152,-34.072407,0.000655,-0.017344,-0.440542,0.374328,0.019069,-4.405421,-34.072407,-0.439311,0.000000
3.950000,0.038353,-34.072407,0.000849,-0.017181,-0.436388,0.170603,0.008691,-4.363882,-34.072407,-0.435304,0.000000
4.190000,0.067772,-34.116890,0.001035,-0.017024,-0.432408,0.301465,0.015357,-4.324076,-34.116890,-0.431315,0.000000
4.430000,0.042076,-34.161369,0.001181,-0.016873,-0.428575,0.187164,0.009535,-4.285746,-34.161369,-0.427308,0.000000
4.670000,0.049896,-34.116890,0.001306,-0.016715,-0.424559,0.221950,0.011307,-4.245593,-34.116890,-0.423302,0.000000
4.910000,0.032021,-34.161369,0.001513,-0.016552,-0.420431,0.142435,0.007256,-4.204310,-34.161369,-0.419313,0.000000
5.150000,-0.001862,-34.161369,0.001656,-0.016400,-0.416563,-0.008281,-0.000422,-4.165633,-34.161369,-0.415306,0.000000
5.390000,0.074097,-34.116890,0.001841,-0.016238,-0.412453,0.329598,0.016791,-4.124529,-34.116890,-0.411317,0.000000
5.630000,0.070000,-34.161369,0.001983,-0.016087,-0.408620,0.311374,0.015862,-4.086195,-34.161369,-0.407310,0.000000
5.870000,0.081551,-34.161369,0.002164,-0.015923,-0.404439,0.362755,0.018480,-4.044395,-34.161369,-0.403321,0.000000
6.110000,0.051758,-34.250332,0.002324,-0.015766,-0.400459,0.230230,0.011728,-4.004589,-34.250332,-0.399314,0.000000
6.350000,0.061813,-34.161369,0.002514,-0.015609,-0.396461,0.274960,0.014007,-3.964609,-34.161369,-0.395325,0.000000
6.590000,0.053246,-34.116890,0.002686,-0.015462,-0.392723,0.236848,0.012066,-3.927233,-34.116890,-0.391318,0.000000
6.830000,0.053993,-34.161369,0.002871,-0.015293,-0.388431,0.240174,0.012235,-3.884305,-34.161369,-0.387329,0.000000
7.070000,0.007820,-34.161369,0.002992,-0.015139,-0.384528,0.034786,0.001772,-3.845279,-34.161369,-0.383323,0.000000
7.310000,0.050636,-34.161369,0.003152,-0.014978,-0.380443,0.225241,0.011474,-3.804433,-34.161369,-0.379334,0.000000
7.550000,0.082291,-34.205853,0.003346,-0.014828,-0.376628,0.366047,0.018647,-3.766277,-34.205853,-0.375327,0.000000
7.790000,0.070000,-34.161369,0.003505,-0.014670,-0.372612,0.311374,0.015862,-3.726123,-34.161369,-0.371338,0.000000
8.030001,0.054367,-34.161369,0.003712,-0.014508,-0.368502,0.241837,0.012320,-3.685019,-34.161369,-0.367331,0.000000
8.270000,0.045799,-34.161369,0.003842,-0.014351,-0.364504,0.203725,0.010378,-3.645039,-34.161369,-0.363342,0.000000
8.510000,0.072983,-34.161369,0.003988,-0.014197,-0.360601,0.324644,0.016538,-3.606013,-34.161369,-0.359335,0.000000
8.750000,0.057343,-34.294815,0.004182,-0.014037,-0.356543,0.255072,0.012994,-3.565428,-34.294815,-0.355346,0.000000
8.990001,0.029045,-34.161369,0.004346,-0.013880,-0.352545,0.129199,0.006582,-3.525448,-34.161369,-0.351339,0.000000
9.230000,0.007072,-34.250332,0.004493,-0.013724,-0.348590,0.031460,0.001603,-3.485904,-34.250332,-0.347333,0.000000
9.470000,0.056229,-34.205853,0.004687,-0.013563,-0.344488,0.250117,0.012742,-3.444883,-34.205853,-0.343343,0.000000
9.710000,0.074844,-34.250332,0.004820,-0.013414,-0.340707,0.332924,0.016960,-3.407072,-34.250332,-0.339337,0.000000
9.950001,0.063675,-34.116890,0.005023,-0.013252,-0.336605,0.283240,0.014429,-3.366051,-34.116890,-0.335348,0.000000
10.190001,0.044685,-34.161369,0.005157,-0.013095,-0.332607,0.198770,0.010126,-3.326071,-34.161369,-0.331341,0.000000
10.430000,0.067398,-34.205853,0.005342,-0.012933,-0.328505,0.299802,0.015273,-3.285054,-34.205853,-0.327352,0.000000
10.670000,0.077454,-34.116890,0.005493,-0.012779,-0.324585,0.344531,0.017551,-3.245854,-34.116890,-0.323345,0.000000
10.910001,0.055107,-34.161369,0.005639,-0.012616,-0.320458,0.245129,0.012487,-3.204576,-34.161369,-0.319356,0.000000
11.150001,0.027550,-34.205853,0.005825,-0.012466,-0.316624,0.122547,0.006243,-3.166243,-34.205853,-0.315349,0.000000
11.390000,0.054367,-34.116890,0.006023,-0.012304,-0.312522,0.241837,0.012320,-3.125222,-34.116890,-0.311360,0.000000
11.630000,0.061066,-34.205853,0.006127,-0.012148,-0.308568,0.271634,0.013838,-3.085677,-34.205853,-0.307354,0.000000
11.870001,0.069633,-34.116890,0.006338,-0.011990,-0.304535,0.309745,0.015779,-3.045353,-34.116890,-0.303364,0.000000
12.110001,0.051384,-34.161369,0.006489,-0.011836,-0.300633,0.228567,0.011644,-3.006327,-34.161369,-0.299358,0.000000
12.350000,0.062927,-34.161369,0.006622,-0.011673,-0.296487,0.279914,0.014260,-2.964875,-34.161369,-0.295369,0.000000
12.590000,0.075592,-34.205853,0.006795,-0.011524,-0.292715,0.336250,0.017129,-2.927147,-34.205853,-0.291362,0.000000
12.830001,0.078194,-34.205853,0.006950,-0.011356,-0.288431,0.347823,0.017719,-2.884310,-34.205853,-0.287373,0.000000
13.070001,0.050636,-34.161369,0.007110,-0.011200,-0.284485,0.225241,0.011474,-2.844848,-34.161369,-0.283366,0.000000
13.310000,0.054733,-34.161369,0.007274,-0.011048,-0.280608,0.243466,0.012403,-2.806083,-34.161369,-0.279377,0.000000
13.550000,0.089737,-34.250332,0.007407,-0.010886,-0.276506,0.399170,0.020335,-2.765063,-34.250332,-0.275370,0.000000
13.790001,0.071121,-34.161369,0.007584,-0.010727,-0.272456,0.316363,0.016116,-2.724564,-34.161369,-0.271364,0.000000
14.030001,0.077820,-34.205853,0.007739,-0.010573,-0.268563,0.346160,0.017634,-2.685625,-34.205853,-0.267374,0.000000
14.270000,0.062553,-34.205853,0.007894,-0.010420,-0.264660,0.278251,0.014175,-2.646603,-34.205853,-0.263368,0.000000
14.510000,0.080429,-34.161369,0.008075,-0.010258,-0.260558,0.357766,0.018225,-2.605582,-34.161369,-0.259379,0.000000
14.750001,0.086388,-34.250332,0.008222,-0.010098,-0.256482,0.384271,0.019576,-2.564823,-34.250332,-0.255372,0.000000
14.990001,0.077080,-34.161369,0.008386,-0.009939,-0.252441,0.342868,0.017467,-2.524408,-34.161369,-0.251383,0.000000
15.230000,0.072983,-34.294815,0.008541,-0.009786,-0.248573,0.324644,0.016538,-2.485730,-34.294815,-0.247376,0.000000
15.470000,0.082664,-34.250332,0.008731,-0.009629,-0.244575,0.367710,0.018732,-2.445750,-34.250332,-0.243387,0.000000
15.710001,0.074471,-34.205853,0.008860,-0.009469,-0.240525,0.331261,0.016875,-2.405252,-34.205853,-0.239381,0.000000
15.950001,0.067024,-34.250332,0.009058,-0.009311,-0.236501,0.298139,0.015188,-2.365014,-34.250332,-0.235391,0.000000
16.190001,0.067772,-34.205853,0.009227,-0.009158,-0.232608,0.301465,0.015357,-2.326075,-34.205853,-0.231385,0.000000
16.430000,0.084900,-34.205853,0.009378,-0.008998,-0.228558,0.377654,0.019239,-2.285577,-34.205853,-0.227395,0.000000
16.670000,0.106499,-34.205853,0.009533,-0.008845,-0.224664,0.473730,0.024133,-2.246638,-34.205853,-0.223389,0.000000
16.910002,0.097557,-34.250332,0.009727,-0.008674,-0.220327,0.433956,0.022107,-2.203274,-34.250332,-0.219400,0.000000
17.150002,0.082664,-34.250332,0.009895,-0.008521,-0.216442,0.367710,0.018732,-2.164423,-34.250332,-0.215393,0.000000
17.390001,0.082291,-34.205853,0.010033,-0.008366,-0.212496,0.366047,0.018647,-2.124965,-34.205853,-0.211404,0.000000
17.630001,0.089737,-34.250332,0.010167,-0.008213,-0.208603,0.399170,0.020335,-2.086026,-34.250332,-0.207397,0.000000
17.870001,0.071121,-34.250332,0.010361,-0.008051,-0.204492,0.316363,0.016116,-2.044918,-34.250332,-0.203408,0.000000
18.110001,0.035004,-34.205853,0.010473,-0.007897,-0.200572,0.155704,0.007932,-2.005722,-34.205853,-0.199402,0.000000
18.350000,0.091972,-34.250332,0.010671,-0.007735,-0.196479,0.409113,0.020841,-1.964788,-34.250332,-0.195412,0.000000
18.590000,0.117668,-34.205853,0.010874,-0.007584,-0.192637,0.523414,0.026664,-1.926371,-34.205853,-0.191406,0.000000
18.830002,0.097183,-34.250332,0.011033,-0.007422,-0.188526,0.432293,0.022022,-1.885264,-34.250332,-0.187399,0.000000
19.070002,0.093460,-34.250332,0.011197,-0.007263,-0.184477,0.415731,0.021178,-1.844765,-34.250332,-0.183410,0.000000
19.310001,0.067772,-34.205853,0.011352,-0.007102,-0.180383,0.301465,0.015357,-1.803832,-34.205853,-0.179403,0.000000
19.550001,0.086761,-34.250332,0.011516,-0.006952,-0.176576,0.385934,0.019660,-1.765759,-34.250332,-0.175414,0.000000
19.790001,0.068512,-34.250332,0.011714,-0.006790,-0.172474,0.304756,0.015525,-1.724739,-34.250332,-0.171407,0.000000
20.030001,0.056969,-34.294815,0.011878,-0.006636,-0.168554,0.253409,0.012909,-1.685542,-34.294815,-0.167418,0.000000
20.270000,0.034256,-34.339294,0.012046,-0.006481,-0.164617,0.152378,0.007763,-1.646168,-34.339294,-0.163412,0.000000
20.510000,0.091599,-34.161369,0.012232,-0.006321,-0.160550,0.407451,0.020757,-1.605496,-34.161369,-0.159422,0.000000
20.750002,0.093094,-34.294815,0.012374,-0.006170,-0.156708,0.414102,0.021095,-1.567079,-34.294815,-0.155416,0.000000
20.990002,0.086014,-34.205853,0.012572,-0.006001,-0.152424,0.382608,0.019491,-1.524238,-34.205853,-0.151426,0.000000
21.230001,0.096069,-34.250332,0.012706,-0.005848,-0.148530,0.427338,0.021770,-1.485299,-34.250332,-0.147420,0.000000
21.470001,0.074844,-34.294815,0.012878,-0.005691,-0.144549,0.332924,0.016960,-1.445493,-34.294815,-0.143430,0.000000
21.710001,0.096817,-34.250332,0.013055,-0.005538,-0.140673,0.430664,0.021939,-1.406728,-34.250332,-0.139424,0.000000
21.950001,0.055481,-34.250332,0.013206,-0.005373,-0.136475,0.246792,0.012572,-1.364754,-34.250332,-0.135435,0.000000
22.190001,0.021591,-34.250332,0.013366,-0.005221,-0.132625,0.096042,0.004893,-1.326250,-34.250332,-0.131428,0.000000
22.430000,0.097183,-34.250332,0.013538,-0.005062,-0.128584,0.432293,0.022022,-1.285839,-34.250332,-0.127439,0.000000
22.670002,0.104263,-34.250332,0.013719,-0.004909,-0.124690,0.463786,0.023626,-1.246900,-34.250332,-0.123432,0.000000
22.910002,0.110222,-34.250332,0.013862,-0.004745,-0.120527,0.490291,0.024977,-1.205273,-34.250332,-0.119443,0.000000
23.150002,0.077080,-34.294815,0.014051,-0.004588,-0.116529,0.342868,0.017467,-1.165293,-34.294815,-0.115437,0.000000
23.390001,0.097931,-34.294815,0.014219,-0.004428,-0.112462,0.435618,0.022191,-1.124621,-34.294815,-0.111430,0.000000
23.630001,0.096069,-34.339294,0.014396,-0.004279,-0.108681,0.427338,0.021770,-1.086810,-34.339294,-0.107441,0.000000
23.870001,0.078194,-34.339294,0.014547,-0.004112,-0.104449,0.347823,0.017719,-1.044487,-34.339294,-0.103434,0.000000
24.110001,0.036118,-34.250332,0.014741,-0.003959,-0.100564,0.160659,0.008184,-1.005635,-34.250332,-0.099445,0.000000
24.350000,0.038727,-34.250332,0.014883,-0.003803,-0.096592,0.172265,0.008776,-0.965917,-34.250332,-0.095438,0.000000
24.590002,0.094582,-34.294815,0.015056,-0.003646,-0.092620,0.420720,0.021432,-0.926198,-34.294815,-0.091449,0.000000
24.830002,0.088623,-34.205853,0.015237,-0.003491,-0.088665,0.394215,0.020082,-0.886653,-34.205853,-0.087442,0.000000
25.070002,0.073730,-34.250332,0.015401,-0.003328,-0.084520,0.327969,0.016708,-0.845201,-34.250332,-0.083453,0.000000
25.310001,0.090485,-34.294815,0.015552,-0.003175,-0.080652,0.402496,0.020504,-0.806523,-34.294815,-0.079447,0.000000
25.550001,0.102028,-34.339294,0.015711,-0.003017,-0.076637,0.453843,0.023120,-0.766369,-34.339294,-0.075458,0.000000
25.790001,0.102402,-34.294815,0.015875,-0.002864,-0.072743,0.455506,0.023205,-0.727430,-34.294815,-0.071451,0.000000
26.030001,0.086388,-34.294815,0.016082,-0.002698,-0.068537,0.384271,0.019576,-0.685369,-34.294815,-0.067462,0.000000
26.270000,0.054367,-34.294815,0.016233,-0.002547,-0.064695,0.241837,0.012320,-0.646952,-34.294815,-0.063455,0.000000
26.510002,0.087875,-34.250332,0.016379,-0.002384,-0.060550,0.390889,0.019913,-0.605500,-34.250332,-0.059466,0.000000
26.750002,0.116180,-34.294815,0.016543,-0.002236,-0.056786,0.516796,0.026327,-0.567863,-34.294815,-0.055459,0.000000
26.990002,0.113197,-34.294815,0.016707,-0.002074,-0.052684,0.503527,0.025651,-0.526842,-34.294815,-0.051470,0.000000
27.230001,0.083038,-34.294815,0.016884,-0.001914,-0.048626,0.369373,0.018817,-0.486257,-34.294815,-0.047463,0.000000
27.470001,0.112457,-34.383774,0.017035,-0.001755,-0.044584,0.500235,0.025483,-0.445842,-34.383774,-0.043474,0.000000
27.710001,0.115807,-34.294815,0.017225,-0.001604,-0.040751,0.515133,0.026242,-0.407512,-34.294815,-0.039468,0.000000
27.950001,0.112083,-34.294815,0.017371,-0.001440,-0.036571,0.498572,0.025398,-0.365712,-34.294815,-0.035461,0.000000
28.190001,0.073357,-34.294815,0.017544,-0.001290,-0.032773,0.326307,0.016623,-0.327726,-34.294815,-0.031472,0.000000
28.430002,0.084526,-34.294815,0.017694,-0.001132,-0.028740,0.375991,0.019154,-0.287402,-34.294815,-0.027465,0.000000
28.670002,0.121017,-34.339294,0.017876,-0.000973,-0.024716,0.538313,0.027423,-0.247161,-34.339294,-0.023476,0.000000
28.910002,0.140755,-34.294815,0.018026,-0.000816,-0.020727,0.626108,0.031895,-0.207268,-34.294815,-0.019469,0.000000
29.150002,0.143730,-34.294815,0.018182,-0.000658,-0.016720,0.639344,0.032570,-0.167202,-34.294815,-0.015480,0.000000
29.390001,0.186928,-34.339294,0.018358,-0.000501,-0.012714,0.831496,0.042358,-0.127138,-34.339294,-0.011474,0.000000
29.630001,0.238319,-34.205853,0.018496,-0.000344,-0.008742,1.060098,0.054004,-0.087420,-34.205853,-0.007484,0.000000
29.870001,0.325081,-34.339294,0.018669,-0.000182,-0.004631,1.446032,0.073664,-0.046312,-34.339294,-0.003478,0.000000
30.110001,0.459877,-34.250332,0.018833,-0.000024,-0.000616,2.045635,0.104210,-0.006158,-34.250332,0.000511,0.000000
30.350002,0.624466,-34.339294,0.019001,0.000128,0.003243,2.777763,0.141506,0.032433,-34.339294,0.004518,0.000000
30.590002,0.570473,-34.383774,0.019022,-0.000002,-0.000061,2.537589,0.129271,-0.000609,-34.383774,0.000173,0.000000
30.830002,0.556694,-34.250332,0.019018,-0.000002,-0.000061,2.476299,0.126149,-0.000609,-34.250332,0.000173,0.000000
31.070002,0.577171,-34.339294,0.019040,-0.000002,-0.000061,2.567386,0.130789,-0.000609,-34.339294,0.000425,0.000000
31.310001,0.583878,-34.250332,0.019040,-0.000002,-0.000061,2.597217,0.132309,-0.000609,-34.250332,0.000824,0.000000
31.550001,0.614410,-34.383774,0.019018,0.000008,0.000191,2.733034,0.139227,0.001908,-34.383774,0.001223,0.000000
31.790001,0.660583,-34.339294,0.019031,0.000022,0.000564,2.938422,0.149690,0.005636,-34.339294,0.001630,0.000000
32.030003,0.690002,-34.250332,0.019027,0.000034,0.000867,3.069284,0.156357,0.008671,-34.250332,0.002029,0.000000
32.270000,0.757034,-34.339294,0.019061,0.000055,0.001405,3.367457,0.171546,0.014046,-34.339294,0.002428,0.000000
32.510002,0.808044,-34.339294,0.019078,0.000072,0.001830,3.594361,0.183105,0.018296,-34.339294,0.002827,0.000000
32.750000,0.829269,-34.339294,0.019074,0.000088,0.002246,3.688775,0.187915,0.022460,-34.339294,0.003226,0.000000
32.990002,0.833740,-34.383774,0.019100,0.000101,0.002567,3.708662,0.188928,0.025669,-34.383774,0.003625,0.000000
33.230003,0.882149,-34.250332,0.019096,0.000116,0.002940,3.923994,0.199898,0.029397,-34.250332,0.004024,0.000000
33.470001,0.982689,-34.383774,0.019130,0.000132,0.003347,4.371219,0.222680,0.033474,-34.383774,0.004431,0.000000
33.710003,1.025513,-34.339294,0.019135,0.000148,0.003755,4.561708,0.232385,0.037550,-34.339294,0.004830,0.000000
33.950001,1.087326,-34.294815,0.019156,0.000161,0.004084,4.836668,0.246392,0.040843,-34.294815,0.005229,0.000000
34.190002,1.152489,-34.339294,0.019156,0.000182,0.004613,5.126526,0.261158,0.046134,-34.339294,0.005628,0.000000
34.430000,1.240372,-34.339294,0.019199,0.000197,0.005004,5.517449,0.281072,0.050036,-34.339294,0.006027,0.000000
34.670002,1.295113,-34.339294,0.019186,0.000207,0.005255,5.760949,0.293477,0.052553,-34.339294,0.006426,0.000000
34.910000,1.350220,-34.294815,0.019191,0.000223,0.005663,6.006077,0.305964,0.056630,-34.294815,0.006825,0.000000
35.150002,1.436607,-34.383774,0.019203,0.000241,0.006122,6.390349,0.325540,0.061224,-34.383774,0.007224,0.000000
35.390003,1.613113,-34.383774,0.019238,0.000259,0.006582,7.175487,0.365537,0.065819,-34.383774,0.007631,0.000000
35.630001,1.681259,-34.339294,0.019264,0.000272,0.006920,7.478614,0.380979,0.069203,-34.339294,0.008030,0.000000
35.870003,1.792969,-34.339294,0.019272,0.000285,0.007233,7.975523,0.406293,0.072326,-34.339294,0.008429,0.000000
36.110001,1.958305,-34.383774,0.019290,0.000304,0.007727,8.710978,0.443758,0.077269,-34.383774,0.008828,0.000000
36.350002,2.116188,-34.383774,0.019281,0.000323,0.008204,9.413275,0.479535,0.082038,-34.383774,0.009227,0.000000
36.590000,2.203697,-34.428257,0.019298,0.000335,0.008516,9.802535,0.499365,0.085160,-34.428257,0.009626,0.000000
36.830002,2.272217,-34.294815,0.019320,0.000349,0.008871,10.107326,0.514892,0.088714,-34.294815,0.010025,0.000000
37.070004,2.444992,-34.383774,0.019324,0.000365,0.009270,10.875868,0.554043,0.092703,-34.383774,0.010424,0.000000
37.310001,2.674751,-34.339294,0.019372,0.000381,0.009687,11.897888,0.606107,0.096867,-34.339294,0.010832,0.000000
37.550003,2.890350,-34.294815,0.019380,0.000398,0.010120,12.856920,0.654963,0.101204,-34.294815,0.011231,0.000000
37.790001,2.965202,-34.383774,0.019398,0.000408,0.010354,13.189878,0.671924,0.103543,-34.383774,0.011629,0.000000
38.030003,3.143562,-34.339294,0.019402,0.000420,0.010675,13.983264,0.712341,0.106753,-34.339294,0.012028,0.000000
38.270000,3.488380,-34.383774,0.019398,0.000446,0.011335,15.517091,0.790478,0.113346,-34.383774,0.012427,0.000000
38.510002,3.642914,-34.339294,0.019454,0.000459,0.011655,16.204491,0.825496,0.116552,-34.339294,0.012826,0.000000
38.750000,3.830963,-34.428257,0.019441,0.000475,0.012054,17.040976,0.868109,0.120541,-34.428257,0.013225,0.000000
38.990002,3.992577,-34.383774,0.019458,0.000491,0.012470,17.759869,0.904731,0.124705,-34.383774,0.013624,0.000000
39.230003,4.378723,-34.339294,0.019492,0.000511,0.012973,19.477533,0.992233,0.129735,-34.339294,0.014031,0.000000
39.470001,4.494904,-34.383774,0.019514,0.000521,0.013234,19.994329,1.018560,0.132335,-34.383774,0.014430,0.000000
39.710003,4.691521,-34.294815,0.019514,0.000534,0.013554,20.868927,1.063114,0.135545,-34.294815,0.014829,0.000000
39.950001,4.942871,-34.339294,0.019501,0.000551,0.014006,21.986988,1.120071,0.140056,-34.339294,0.015228,0.000000
40.190002,5.244118,-34.428257,0.019510,0.000567,0.014413,23.327002,1.188334,0.144133,-34.428257,0.015627,0.000000
40.430000,5.541641,-34.339294,0.019570,0.000583,0.014812,24.650452,1.255754,0.148122,-34.339294,0.016026,0.000000
40.670002,5.810127,-34.383774,0.019583,0.000600,0.015246,25.844736,1.316594,0.152456,-34.383774,0.016425,0.000000
40.910004,5.936729,-34.339294,0.019587,0.000614,0.015593,26.407892,1.345282,0.155926,-34.339294,0.016824,0.000000
41.150002,6.293091,-34.339294,0.019596,0.000631,0.016035,27.993067,1.426035,0.160347,-34.339294,0.017231,0.000000
41.390003,6.656158,-34.339294,0.019604,0.000650,0.016512,29.608072,1.508307,0.165120,-34.339294,0.017630,0.000000
41.630001,6.723183,-34.383774,0.019613,0.000658,0.016720,29.906210,1.523495,0.167198,-34.383774,0.018029,0.000000
41.870003,7.095924,-34.472736,0.019635,0.000674,0.017127,31.564247,1.607959,0.171274,-34.472736,0.018428,0.000000
42.110001,7.624321,-34.339294,0.019656,0.000697,0.017700,33.914673,1.727696,0.177001,-34.339294,0.018827,0.000000
42.350002,7.859291,-34.339294,0.019673,0.000715,0.018151,34.959873,1.780941,0.181508,-34.339294,0.019226,0.000000
42.590000,8.046967,-34.383774,0.019708,0.000728,0.018498,35.794697,1.823469,0.184979,-34.383774,0.019625,0.000000
42.830002,8.288261,-34.383774,0.019730,0.000742,0.018836,36.868027,1.878147,0.188359,-34.383774,0.020024,0.000000
43.070004,8.581696,-34.383774,0.019721,0.000761,0.019330,38.173290,1.944640,0.193302,-34.383774,0.020432,0.000000
43.310001,8.898209,-34.339294,0.019747,0.000776,0.019712,39.581207,2.016363,0.197117,-34.339294,0.020831,0.000000
43.550003,9.012154,-34.383774,0.019760,0.000786,0.019972,40.088062,2.042183,0.199721,-34.383774,0.021229,0.000000
43.790001,9.203186,-34.428257,0.019764,0.000799,0.020293,40.937817,2.085472,0.202931,-34.428257,0.021628,0.000000
44.030003,9.917023,-34.383774,0.019777,0.000827,0.020995,44.113121,2.247229,0.209952,-34.383774,0.022027,0.000000
44.270000,10.051445,-34.428257,0.019811,0.000840,0.021325,44.711060,2.277690,0.213249,-34.428257,0.022426,0.000000
44.510002,10.287529,-34.383774,0.019811,0.000857,0.021759,45.761215,2.331187,0.217586,-34.383774,0.022825,0.000000
44.750004,10.462547,-34.383774,0.019837,0.000870,0.022097,46.539734,2.370847,0.220966,-34.383774,0.023224,0.000000
44.990002,10.612244,-34.428257,0.019846,0.000879,0.022331,47.205616,2.404769,0.223309,-34.428257,0.023632,0.000000
45.230003,11.054993,-34.339294,0.019885,0.000902,0.022903,49.175064,2.505097,0.229032,-34.339294,0.024031,0.000000
45.470001,11.196861,-34.383774,0.019872,0.000912,0.023164,49.806126,2.537245,0.231636,-34.383774,0.024430,0.000000
45.710003,11.522690,-34.383774,0.019893,0.000930,0.023614,51.255486,2.611079,0.236143,-34.383774,0.024829,0.000000
45.950001,12.208229,-34.383774,0.019936,0.000956,0.024282,54.304916,2.766424,0.242820,-34.383774,0.025227,0.000000
46.190002,12.232063,-34.428257,0.019936,0.000969,0.024612,54.410934,2.771825,0.246117,-34.428257,0.025626,0.000000
46.430000,12.351593,-34.383774,0.019945,0.000983,0.024967,54.942631,2.798911,0.249674,-34.383774,0.026025,0.000000
46.670002,12.580605,-34.472736,0.019971,0.000997,0.025323,55.961323,2.850806,0.253228,-34.472736,0.026433,0.000000
46.910004,13.082558,-34.383774,0.019971,0.001016,0.025808,58.194122,2.964550,0.258084,-34.383774,0.026832,0.000000
47.150002,13.186821,-34.383774,0.019971,0.001027,0.026086,58.657909,2.988176,0.260859,-34.383774,0.027231,0.000000
47.390003,13.196503,-34.428257,0.020010,0.001039,0.026389,58.700977,2.990370,0.263894,-34.428257,0.027630,0.000000
47.630001,13.407639,-34.428257,0.020018,0.001051,0.026702,59.640156,3.038214,0.267017,-34.428257,0.028029,0.000000
47.870003,14.341927,-34.428257,0.020018,0.001079,0.027395,63.796074,3.249927,0.273954,-34.428257,0.028428,0.000000
48.110001,14.537048,-34.383774,0.020023,0.001093,0.027768,64.664024,3.294142,0.277683,-34.383774,0.028827,0.000000
48.350002,14.553429,-34.472736,0.020066,0.001104,0.028046,64.736885,3.297854,0.280461,-34.472736,0.029225,0.000000
48.590004,14.949265,-34.472736,0.020079,0.001122,0.028506,66.497650,3.387552,0.285056,-34.472736,0.029633,0.000000
48.830002,15.443398,-34.383774,0.020092,0.001143,0.029035,68.695663,3.499524,0.290347,-34.383774,0.030032,0.000000
49.070004,15.636292,-34.383774,0.020122,0.001156,0.029373,69.553696,3.543234,0.293727,-34.383774,0.030431,0.000000
49.310001,15.613205,-34.428257,0.020130,0.001163,0.029546,69.451004,3.538003,0.295460,-34.428257,0.030830,0.000000
49.550003,15.705925,-34.428257,0.020130,0.001173,0.029806,69.863441,3.559013,0.298064,-34.428257,0.031229,0.000000
49.790001,16.150909,-34.472736,0.020174,0.001188,0.030171,71.842834,3.659848,0.301705,-34.472736,0.031628,0.000000
50.030003,17.059868,-34.383774,0.020182,0.001219,0.030951,75.886086,3.865821,0.309510,-34.383774,0.032027,0.000000
50.270004,17.204353,-34.472736,0.020204,0.001232,0.031298,76.528786,3.898562,0.312981,-34.472736,0.032426,0.000000
50.510002,17.487350,-34.428257,0.020199,0.001247,0.031680,77.787621,3.962690,0.316796,-34.428257,0.032833,0.000000
50.750004,17.628853,-34.472736,0.020217,0.001263,0.032087,78.417053,3.994755,0.320872,-34.472736,0.033232,0.000000
50.990002,18.311043,-34.517220,0.020217,0.001280,0.032504,81.451584,4.149342,0.325035,-34.517220,0.033631,0.000000
51.230003,18.438019,-34.472736,0.020234,0.001294,0.032876,82.016403,4.178115,0.328764,-34.472736,0.034030,0.000000
51.470001,18.674103,-34.428257,0.020251,0.001307,0.033189,83.066559,4.231612,0.331886,-34.428257,0.034429,0.000000
51.710003,19.530930,-34.428257,0.020277,0.001334,0.033891,86.877914,4.425772,0.338911,-34.428257,0.034827,0.000000
51.950001,19.700363,-34.428257,0.020290,0.001345,0.034151,87.631592,4.464166,0.341511,-34.428257,0.035226,0.000000
52.190002,19.820267,-34.472736,0.020281,0.001358,0.034489,88.164948,4.491337,0.344895,-34.472736,0.035625,0.000000
52.430004,20.063423,-34.428257,0.020324,0.001370,0.034793,89.246567,4.546437,0.347930,-34.428257,0.036033,0.000000
52.670002,20.473778,-34.428257,0.020329,0.001384,0.035148,91.071915,4.639424,0.351484,-34.428257,0.036432,0.000000
52.910004,20.968666,-34.517220,0.020350,0.001401,0.035573,93.273285,4.751567,0.355735,-34.517220,0.036831,0.000000
53.150002,21.463921,-34.472736,0.020329,0.001418,0.036016,95.476288,4.863794,0.360155,-34.472736,0.037230,0.000000
53.390003,21.587921,-34.517220,0.020368,0.001431,0.036354,96.027870,4.891893,0.363539,-34.517220,0.037629,0.000000
53.630001,22.296173,-34.428257,0.020372,0.001451,0.036848,99.178329,5.052385,0.368482,-34.428257,0.038028,0.000000
53.870003,22.926971,-34.472736,0.020393,0.001471,0.037360,101.984261,5.195326,0.373599,-34.472736,0.038427,0.000000
54.110004,23.225243,-34.472736,0.020437,0.001487,0.037768,103.311035,5.262915,0.377676,-34.472736,0.038825,0.000000
54.350002,23.245346,-34.428257,0.020441,0.001499,0.038071,103.400467,5.267471,0.380711,-34.428257,0.039233,0.000000
54.590004,23.681770,-34.517220,0.020437,0.001514,0.038444,105.341774,5.366366,0.384439,-34.517220,0.039632,0.000000
54.830002,24.386299,-34.383774,0.020441,0.001528,0.038817,108.475677,5.526014,0.388167,-34.383774,0.040031,0.000000
55.070004,24.788460,-34.517220,0.020462,0.001545,0.039233,110.264580,5.617145,0.392331,-34.517220,0.040430,0.000000
55.310001,24.903893,-34.472736,0.020484,0.001555,0.039502,110.778046,5.643303,0.395018,-34.472736,0.040829,0.000000
55.550003,25.746948,-34.428257,0.020514,0.001574,0.039987,114.528145,5.834342,0.399874,-34.428257,0.041228,0.000000
55.790001,26.268639,-34.517220,0.020510,0.001595,0.040508,116.848740,5.952559,0.405078,-34.517220,0.041627,0.000000
56.030003,26.671547,-34.428257,0.020506,0.001605,0.040777,118.640968,6.043859,0.407769,-34.428257,0.042026,0.000000
56.270004,27.096794,-34.472736,0.020536,0.001622,0.041193,120.532562,6.140221,0.411929,-34.472736,0.042433,0.000000
56.510002,27.703392,-34.517220,0.020562,0.001641,0.041679,123.230843,6.277678,0.416785,-34.517220,0.042832,0.000000
56.750004,28.425423,-34.428257,0.020566,0.001658,0.042121,126.442596,6.441293,0.421210,-34.428257,0.043231,0.000000
56.990002,28.716614,-34.561699,0.020562,0.001671,0.042442,127.737877,6.507277,0.424419,-34.561699,0.043630,0.000000
57.230003,29.107239,-34.428257,0.020592,0.001683,0.042754,129.475464,6.595794,0.427542,-34.428257,0.044029,0.000000
57.470001,29.926086,-34.517220,0.020596,0.001703,0.043248,133.117874,6.781348,0.432485,-34.517220,0.044428,0.000000
57.710003,30.699875,-34.517220,0.020639,0.001722,0.043734,136.559860,6.956691,0.437341,-34.517220,0.044827,0.000000
57.950005,31.008568,-34.472736,0.020661,0.001735,0.044064,137.932999,7.026642,0.440637,-34.472736,0.045226,0.000000
58.190002,31.354874,-34.561699,0.020661,0.001748,0.044410,139.473450,7.105116,0.444104,-34.561699,0.045633,0.000000
58.430004,31.915672,-34.472736,0.020678,0.001765,0.044827,141.968002,7.232195,0.448268,-34.472736,0.046032,0.000000
58.670002,32.781433,-34.472736,0.020695,0.001784,0.045304,145.819092,7.428379,0.453037,-34.472736,0.046431,0.000000
58.910004,33.360847,-34.517220,0.020691,0.001798,0.045659,148.396454,7.559676,0.456591,-34.517220,0.046830,0.000000
59.150002,33.538467,-34.472736,0.020700,0.001808,0.045911,149.186554,7.599926,0.459108,-34.472736,0.047229,0.000000
59.390003,34.001701,-34.517220,0.020708,0.001818,0.046188,151.247116,7.704896,0.461882,-34.517220,0.047628,0.000000
59.630001,35.370171,-34.517220,0.020734,0.001845,0.046873,157.334381,8.014996,0.468733,-34.517220,0.048027,0.000000
59.870003,35.771210,-34.561699,0.020743,0.001857,0.047177,159.118286,8.105872,0.471768,-34.561699,0.048435,0.000000
60.110004,36.324928,-34.517220,0.020769,0.001873,0.047576,161.581345,8.231347,0.475758,-34.517220,0.048833,0.000000
60.350002,36.903229,-34.472736,0.020769,0.001892,0.048053,164.153763,8.362391,0.480526,-34.472736,0.049232,0.000000
60.590004,37.954803,-34.561699,0.020769,0.001910,0.048504,168.831390,8.600681,0.485038,-34.561699,0.049631,0.000000
60.830002,38.273186,-34.517220,0.020790,0.001919,0.048755,170.247635,8.672828,0.487551,-34.517220,0.050030,0.000000
61.070004,38.699921,-34.517220,0.020807,0.001932,0.049067,172.145844,8.769527,0.490674,-34.517220,0.050429,0.000000
61.310001,39.541115,-34.517220,0.020803,0.001953,0.049597,175.887665,8.960144,0.495965,-34.517220,0.050828,0.000000
61.550003,40.459381,-34.517220,0.020803,0.001969,0.050022,179.972321,9.168227,0.500216,-34.517220,0.051227,0.000000
61.790005,41.096138,-34.517220,0.020829,0.001982,0.050342,182.804749,9.312517,0.503421,-34.517220,0.051634,0.000000
62.030003,41.863228,-34.472736,0.020833,0.001999,0.050767,186.216934,9.486342,0.507672,-34.472736,0.052033,0.000000
62.270004,42.209534,-34.517220,0.020820,0.002014,0.051166,187.757385,9.564816,0.511661,-34.517220,0.052432,0.000000
62.510002,43.263344,-34.517220,0.020859,0.002032,0.051609,192.444962,9.803614,0.516086,-34.517220,0.052831,0.000000
62.750004,44.299286,-34.428257,0.020859,0.002050,0.052068,197.053070,10.038363,0.520680,-34.428257,0.053230,0.000000
62.990002,44.468719,-34.561699,0.020855,0.002058,0.052285,197.806747,10.076756,0.522849,-34.561699,0.053629,0.000000
63.230003,45.286819,-34.472736,0.020889,0.002073,0.052658,201.445831,10.262140,0.526577,-34.472736,0.054028,0.000000
63.470001,46.715988,-34.472736,0.020885,0.002097,0.053274,207.803101,10.585995,0.532735,-34.472736,0.054427,0.000000
63.710003,47.590317,-34.517220,0.020889,0.002113,0.053681,211.692307,10.784120,0.536812,-34.517220,0.054834,0.000000
63.950005,48.136955,-34.428257,0.020907,0.002128,0.054054,214.123871,10.907990,0.540540,-34.428257,0.055233,0.000000
64.190002,48.737221,-34.517220,0.020907,0.002141,0.054392,216.793991,11.044012,0.543923,-34.517220,0.055632,0.000000
64.430000,49.782845,-34.517220,0.020915,0.002162,0.054921,221.445160,11.280953,0.549211,-34.517220,0.056031,0.000000
64.670006,50.470985,-34.472736,0.020915,0.002177,0.055286,224.506149,11.436889,0.552856,-34.472736,0.056430,0.000000
64.910004,50.905174,-34.517220,0.020941,0.002188,0.055563,226.437531,11.535277,0.555630,-34.517220,0.056829,0.000000
65.150002,51.694977,-34.517220,0.020980,0.002203,0.055945,229.950745,11.714249,0.559445,-34.517220,0.057228,0.000000
65.389999,53.439911,-34.561699,0.020937,0.002227,0.056578,237.712601,12.109657,0.565777,-34.561699,0.057627,0.000000
65.630005,54.133270,-34.472736,0.020967,0.002244,0.056994,240.796814,12.266774,0.569941,-34.472736,0.058035,0.000000
65.870003,54.822906,-34.428257,0.020963,0.002255,0.057289,243.864471,12.423049,0.572889,-34.428257,0.058433,0.000000
66.110001,55.424660,-34.517220,0.020963,0.002269,0.057627,246.541199,12.559407,0.576269,-34.517220,0.058832,0.000000
66.350006,55.980988,-34.472736,0.020967,0.002286,0.058052,249.015869,12.685472,0.580520,-34.472736,0.059231,0.000000
66.590004,57.137199,-34.561699,0.020988,0.002301,0.058451,254.158951,12.947474,0.584509,-34.561699,0.059630,0.000000
66.830002,57.712891,-34.517220,0.020988,0.002311,0.058694,256.719757,13.077928,0.586935,-34.517220,0.060029,0.000000
67.070000,58.608444,-34.472736,0.020988,0.002329,0.059153,260.703369,13.280863,0.591534,-34.472736,0.060428,0.000000
67.310005,60.525787,-34.561699,0.020997,0.002355,0.059821,269.232147,13.715340,0.598210,-34.561699,0.060827,0.000000
67.550003,61.192337,-34.517220,0.021010,0.002367,0.060133,272.197113,13.866382,0.601333,-34.517220,0.061235,0.000000
67.790001,61.741585,-34.472736,0.021001,0.002382,0.060497,274.640289,13.990843,0.604974,-34.472736,0.061634,0.000000
68.030006,62.593201,-34.561699,0.021049,0.002396,0.060853,278.428467,14.183822,0.608532,-34.561699,0.062033,0.000000
68.270004,63.907677,-34.561699,0.021032,0.002415,0.061339,284.275543,14.481687,0.613388,-34.561699,0.062431,0.000000
68.510002,64.564537,-34.606178,0.021062,0.002428,0.061668,287.197418,14.630533,0.616684,-34.606178,0.062830,0.000000
68.750000,65.237785,-34.517220,0.021057,0.002442,0.062015,290.192169,14.783093,0.620151,-34.517220,0.063229,0.000000
68.990005,65.685387,-34.561699,0.021045,0.002456,0.062379,292.183197,14.884521,0.623792,-34.561699,0.063628,0.000000
69.230003,67.409096,-34.561699,0.021075,0.002463,0.062562,299.850647,15.275120,0.625617,-34.561699,0.062848,0.000000
69.470001,66.952934,-34.561699,0.021053,0.002463,0.062562,297.821533,15.171751,0.625617,-34.561699,0.062848,0.000000
69.710007,66.658760,-34.606178,0.021045,0.002458,0.062423,296.512970,15.105091,0.624228,-34.606178,0.062562,0.000000
69.950005,66.367195,-34.517220,0.021070,0.002457,0.062405,295.216034,15.039021,0.624053,-34.517220,0.062562,0.000000
70.190002,66.119942,-34.561699,0.021088,0.002456,0.062388,294.116180,14.982993,0.623879,-34.561699,0.062562,0.000000
70.430000,65.911781,-34.561699,0.021088,0.002456,0.062379,293.190247,14.935823,0.623792,-34.561699,0.062562,0.000000
70.670006,65.721123,-34.517220,0.021057,0.002456,0.062371,292.342163,14.892619,0.623705,-34.517220,0.062562,0.000000
70.910004,65.542015,-34.561699,0.021062,0.002455,0.062362,291.545441,14.852034,0.623622,-34.561699,0.062562,0.000000
71.150002,65.403496,-34.517220,0.021057,0.002455,0.062353,290.929291,14.820643,0.623535,-34.517220,0.062562,0.000000
71.390007,65.263481,-34.517220,0.021075,0.002455,0.062353,290.306458,14.788917,0.623535,-34.517220,0.062562,0.000000
71.630005,65.143959,-34.606178,0.021083,0.002455,0.062353,289.774811,14.761832,0.623535,-34.606178,0.062562,0.000000
71.870003,65.023674,-34.517220,0.021101,0.002455,0.062353,289.239746,14.734575,0.623535,-34.517220,0.062562,0.000000
72.110001,64.919792,-34.606178,0.021066,0.002455,0.062353,288.777649,14.711036,0.623535,-34.606178,0.062562,0.000000
72.350006,64.819984,-34.561699,0.021075,0.002455,0.062345,288.333679,14.688418,0.623448,-34.561699,0.062562,0.000000
72.590004,64.737328,-34.561699,0.021075,0.002455,0.062345,287.966003,14.669687,0.623448,-34.561699,0.062562,0.000000
72.830002,64.649071,-34.517220,0.021070,0.002455,0.062345,287.573425,14.649689,0.623448,-34.517220,0.062562,0.000000
73.070000,64.569389,-34.561699,0.021088,0.002455,0.062345,287.218994,14.631633,0.623448,-34.561699,0.062562,0.000000
73.310005,64.491936,-34.517220,0.021062,0.002455,0.062345,286.874451,14.614081,0.623448,-34.517220,0.062562,0.000000
73.550003,64.421547,-34.606178,0.021092,0.002455,0.062345,286.561340,14.598131,0.623448,-34.606178,0.062562,0.000000
73.790001,64.348564,-34.472736,0.021096,0.002455,0.062345,286.236694,14.581593,0.623448,-34.472736,0.062562,0.000000
74.030006,64.282280,-34.606178,0.021096,0.002455,0.062345,285.941864,14.566572,0.623448,-34.606178,0.062562,0.000000
74.270004,64.224937,-34.517220,0.021092,0.002455,0.062345,285.686798,14.553578,0.623448,-34.517220,0.062562,0.000000
74.510002,64.156044,-34.650661,0.021079,0.002455,0.062345,285.380341,14.537968,0.623448,-34.650661,0.062562,0.000000
74.750000,64.089394,-34.606178,0.021075,0.002455,0.062345,285.083862,14.522864,0.623448,-34.606178,0.062562,0.000000
74.990005,64.041359,-34.517220,0.021092,0.002455,0.062345,284.870178,14.511979,0.623448,-34.517220,0.062562,0.000000
75.230003,63.991081,-34.606178,0.021066,0.002455,0.062345,284.646545,14.500587,0.623448,-34.606178,0.062562,0.000000
75.470001,63.949379,-34.561699,0.021105,0.002455,0.062345,284.461060,14.491137,0.623448,-34.561699,0.062562,0.000000
75.710007,63.899117,-34.517220,0.021109,0.002455,0.062345,284.237457,14.479747,0.623448,-34.517220,0.062562,0.000000
75.950005,63.852196,-34.606178,0.021083,0.002455,0.062345,284.028748,14.469115,0.623448,-34.606178,0.062562,0.000000
76.190002,63.798195,-34.561699,0.021101,0.002455,0.062345,283.788544,14.456877,0.623448,-34.561699,0.062562,0.000000
76.430000,63.745323,-34.606178,0.021083,0.002455,0.062345,283.553345,14.444897,0.623448,-34.606178,0.062562,0.000000
76.670006,63.714409,-34.606178,0.021088,0.002455,0.062345,283.415833,14.437892,0.623448,-34.606178,0.062562,0.000000
76.910004,63.675682,-34.561699,0.021101,0.002455,0.062345,283.243591,14.429115,0.623448,-34.561699,0.062562,0.000000
77.150002,63.624672,-34.606178,0.021088,0.002455,0.062345,283.016663,14.417557,0.623448,-34.606178,0.062562,0.000000
77.390007,63.586327,-34.561699,0.021088,0.002455,0.062345,282.846100,14.408868,0.623448,-34.561699,0.062562,0.000000
77.630005,63.550194,-34.650661,0.021070,0.002455,0.062345,282.685394,14.400680,0.623448,-34.650661,0.062562,0.000000
77.870003,63.515572,-34.606178,0.021109,0.002455,0.062345,282.531372,14.392835,0.623448,-34.606178,0.062562,0.000000
78.110001,63.478325,-34.561699,0.021096,0.002455,0.062345,282.365692,14.384395,0.623448,-34.561699,0.062562,0.000000
78.350006,63.459709,-34.606178,0.021092,0.002455,0.062345,282.282898,14.380176,0.623448,-34.606178,0.062562,0.000000
78.590004,63.404228,-34.561699,0.021070,0.002455,0.062345,282.036102,14.367603,0.623448,-34.561699,0.062562,0.000000
78.830002,63.380028,-34.606178,0.021049,0.002455,0.062345,281.928436,14.362120,0.623448,-34.606178,0.062562,0.000000
79.070007,63.348747,-34.561699,0.021079,0.002455,0.062345,281.789307,14.355031,0.623448,-34.561699,0.062562,0.000000
79.310005,63.324547,-34.606178,0.021092,0.002455,0.062345,281.681641,14.349547,0.623448,-34.606178,0.062562,0.000000
79.550003,63.284325,-34.606178,0.021088,0.002455,0.062345,281.502747,14.340433,0.623448,-34.606178,0.062562,0.000000
79.790001,63.254158,-34.606178,0.021122,0.002455,0.062345,281.368561,14.333597,0.623448,-34.606178,0.062562,0.000000
80.030006,63.232933,-34.650661,0.021088,0.002455,0.062345,281.274139,14.328787,0.623448,-34.650661,0.062562,0.000000
80.270004,63.193092,-34.650661,0.021109,0.002455,0.062345,281.096924,14.319759,0.623448,-34.650661,0.062562,0.000000
80.510002,63.182289,-34.606178,0.021092,0.002455,0.062345,281.048859,14.317311,0.623448,-34.606178,0.062562,0.000000
80.750008,63.149147,-34.606178,0.021122,0.002455,0.062345,280.901428,14.309801,0.623448,-34.606178,0.062562,0.000000
80.990005,63.135002,-34.561699,0.021101,0.002455,0.062345,280.838501,14.306596,0.623448,-34.561699,0.062562,0.000000
81.230003,63.097397,-34.650661,0.021092,0.002455,0.062345,280.671234,14.298075,0.623448,-34.650661,0.062562,0.000000
81.470001,63.057549,-34.606178,0.021088,0.002455,0.062345,280.493988,14.289044,0.623448,-34.606178,0.062562,0.000000
81.710007,63.044144,-34.561699,0.021101,0.002455,0.062345,280.434357,14.286007,0.623448,-34.561699,0.062562,0.000000
81.950005,63.028503,-34.650661,0.021105,0.002455,0.062345,280.364777,14.282463,0.623448,-34.650661,0.062562,0.000000
82.190002,62.976746,-34.606178,0.021101,0.002455,0.062345,280.134552,14.270734,0.623448,-34.606178,0.062562,0.000000
82.430000,62.987915,-34.695141,0.021109,0.002455,0.062345,280.184235,14.273265,0.623448,-34.695141,0.062562,0.000000
82.670006,62.937645,-34.606178,0.021109,0.002455,0.062345,279.960632,14.261874,0.623448,-34.606178,0.062562,0.000000
82.910004,62.924988,-34.606178,0.021092,0.002455,0.062345,279.904327,14.259006,0.623448,-34.606178,0.062562,0.000000
83.150002,62.904877,-34.606178,0.021070,0.002455,0.062345,279.814880,14.254449,0.623448,-34.606178,0.062562,0.000000
83.390007,62.875084,-34.561699,0.021105,0.002455,0.062345,279.682343,14.247698,0.623448,-34.561699,0.062562,0.000000
83.630005,62.854233,-34.561699,0.021088,0.002455,0.062345,279.589600,14.242972,0.623448,-34.561699,0.062562,0.000000
83.870003,62.841202,-34.561699,0.021088,0.002455,0.062345,279.531616,14.240020,0.623448,-34.561699,0.062562,0.000000
84.110001,62.802849,-34.650661,0.021109,0.002455,0.062345,279.361023,14.231328,0.623448,-34.650661,0.062562,0.000000
84.350006,62.789444,-34.695141,0.021101,0.002455,0.062345,279.301392,14.228292,0.623448,-34.695141,0.062562,0.000000
84.590004,62.771942,-34.606178,0.021101,0.002455,0.062345,279.223541,14.224325,0.623448,-34.606178,0.062562,0.000000
84.830002,62.749596,-34.606178,0.021088,0.002455,0.062345,279.124146,14.219261,0.623448,-34.606178,0.062562,0.000000
85.070007,62.735077,-34.650661,0.021088,0.002455,0.062345,279.059570,14.215971,0.623448,-34.650661,0.062562,0.000000
85.310005,62.722786,-34.561699,0.021096,0.002455,0.062345,279.004883,14.213186,0.623448,-34.561699,0.062562,0.000000
85.550003,62.705658,-34.606178,0.021113,0.002455,0.062345,278.928711,14.209305,0.623448,-34.606178,0.062562,0.000000
85.790001,62.679588,-34.561699,0.021101,0.002455,0.062345,278.812744,14.203398,0.623448,-34.561699,0.062562,0.000000
86.030006,62.655388,-34.606178,0.021092,0.002455,0.062345,278.705078,14.197913,0.623448,-34.606178,0.062562,0.000000
86.270004,62.633049,-34.650661,0.021101,0.002455,0.062345,278.605713,14.192851,0.623448,-34.650661,0.062562,0.000000
86.510002,62.621132,-34.606178,0.021113,0.002455,0.062345,278.552704,14.190151,0.623448,-34.606178,0.062562,0.000000
86.750008,62.616287,-34.606178,0.021079,0.002455,0.062345,278.531158,14.189054,0.623448,-34.606178,0.062562,0.000000
86.990005,62.600273,-34.606178,0.021092,0.002455,0.062345,278.459930,14.185425,0.623448,-34.606178,0.062562,0.000000
87.230003,62.570114,-34.695141,0.021101,0.002455,0.062345,278.325775,14.178590,0.623448,-34.695141,0.062562,0.000000
87.470001,62.563782,-34.695141,0.021096,0.002455,0.062345,278.297607,14.177155,0.623448,-34.695141,0.062562,0.000000
87.710007,62.539581,-34.606178,0.021092,0.002455,0.062345,278.189941,14.171672,0.623448,-34.606178,0.062562,0.000000
87.950005,62.522820,-34.650661,0.021092,0.002455,0.062345,278.115387,14.167873,0.623448,-34.650661,0.062562,0.000000
88.190002,62.504951,-34.606178,0.021096,0.002455,0.062345,278.035919,14.163824,0.623448,-34.606178,0.062562,0.000000
88.430008,62.491913,-34.606178,0.021096,0.002455,0.062345,277.977905,14.160871,0.623448,-34.606178,0.062562,0.000000
88.670006,62.466599,-34.695141,0.021079,0.002455,0.062345,277.865295,14.155133,0.623448,-34.695141,0.062562,0.000000
88.910004,62.461006,-34.606178,0.021105,0.002455,0.062345,277.840424,14.153866,0.623448,-34.606178,0.062562,0.000000
89.150002,62.433823,-34.695141,0.021101,0.002455,0.062345,277.719513,14.147706,0.623448,-34.695141,0.062562,0.000000
89.390007,62.426376,-34.650661,0.021079,0.002455,0.062345,277.686401,14.146019,0.623448,-34.650661,0.062562,0.000000
89.630005,62.401428,-34.650661,0.021088,0.002455,0.062345,277.575409,14.140366,0.623448,-34.650661,0.062562,0.000000
89.870003,62.400314,-34.695141,0.021118,0.002455,0.062345,277.570465,14.140113,0.623448,-34.695141,0.062562,0.000000
90.110001,62.391373,-34.606178,0.021101,0.002455,0.062345,277.530701,14.138087,0.623448,-34.606178,0.062562,0.000000
90.350006,62.369781,-34.650661,0.021101,0.002455,0.062345,277.434631,14.133195,0.623448,-34.650661,0.062562,0.000000
90.590004,62.354141,-34.695141,0.021105,0.002455,0.062345,277.365082,14.129650,0.623448,-34.695141,0.062562,0.000000
90.830002,62.347809,-34.650661,0.021092,0.002455,0.062345,277.336914,14.128215,0.623448,-34.650661,0.062562,0.000000
91.070007,62.328445,-34.739624,0.021088,0.002455,0.062345,277.250763,14.123827,0.623448,-34.739624,0.062562,0.000000
91.310005,62.328072,-34.650661,0.021101,0.002455,0.062345,277.249115,14.123743,0.623448,-34.650661,0.062562,0.000000
91.550003,62.308334,-34.650661,0.021088,0.002455,0.062345,277.161316,14.119270,0.623448,-34.650661,0.062562,0.000000
91.790001,62.298653,-34.695141,0.021109,0.002455,0.062345,277.118256,14.117077,0.623448,-34.695141,0.062562,0.000000
92.030006,62.278175,-34.650661,0.021109,0.002455,0.062345,277.027161,14.112435,0.623448,-34.650661,0.062562,0.000000
92.270004,62.272964,-34.695141,0.021096,0.002455,0.062345,277.003967,14.111256,0.623448,-34.695141,0.062562,0.000000
92.510002,62.261421,-34.650661,0.021092,0.002455,0.062345,276.952637,14.108640,0.623448,-34.650661,0.062562,0.000000
92.750008,62.251366,-34.695141,0.021109,0.002455,0.062345,276.907898,14.106361,0.623448,-34.695141,0.062562,0.000000
92.990005,62.232742,-34.739624,0.021096,0.002455,0.062345,276.825073,14.102141,0.623448,-34.739624,0.062562,0.000000
93.230003,62.216362,-34.695141,0.021105,0.002455,0.062345,276.752197,14.098429,0.623448,-34.695141,0.062562,0.000000
93.470001,62.202209,-34.695141,0.021113,0.002455,0.062345,276.689240,14.095222,0.623448,-34.695141,0.062562,0.000000
93.710007,62.194763,-34.650661,0.021101,0.002455,0.062345,276.656128,14.093534,0.623448,-34.650661,0.062562,0.000000
93.950005,62.175400,-34.695141,0.021096,0.002455,0.062345,276.569977,14.089147,0.623448,-34.695141,0.062562,0.000000
94.190002,62.171303,-34.739624,0.021105,0.002455,0.062345,276.551758,14.088219,0.623448,-34.739624,0.062562,0.000000
94.430008,62.156784,-34.739624,0.021096,0.002455,0.062345,276.487183,14.084929,0.623448,-34.739624,0.062562,0.000000
94.670006,62.147469,-34.695141,0.021083,0.002455,0.062345,276.445740,14.082817,0.623448,-34.695141,0.062562,0.000000
94.910004,62.132576,-34.695141,0.021092,0.002455,0.062345,276.379517,14.079443,0.623448,-34.695141,0.062562,0.000000
95.150002,62.119545,-34.695141,0.021088,0.002455,0.062345,276.321533,14.076489,0.623448,-34.695141,0.062562,0.000000
95.390007,62.106140,-34.695141,0.021105,0.002455,0.062345,276.261902,14.073452,0.623448,-34.695141,0.062562,0.000000
95.630005,62.109116,-34.606178,0.021105,0.002455,0.062345,276.275146,14.074127,0.623448,-34.606178,0.062562,0.000000
95.870003,62.099808,-34.695141,0.021096,0.002455,0.062345,276.233734,14.072018,0.623448,-34.695141,0.062562,0.000000
96.110008,62.073372,-34.695141,0.021101,0.002455,0.062345,276.116150,14.066027,0.623448,-34.695141,0.062562,0.000000
96.350006,62.078583,-34.650661,0.021113,0.002455,0.062345,276.139313,14.067208,0.623448,-34.650661,0.062562,0.000000
96.590004,62.054008,-34.695141,0.021092,0.002455,0.062345,276.030029,14.061640,0.623448,-34.695141,0.062562,0.000000
96.830002,62.054382,-34.695141,0.021092,0.002455,0.062345,276.031677,14.061724,0.623448,-34.695141,0.062562,0.000000
97.070007,62.030548,-34.650661,0.021101,0.002455,0.062345,275.925659,14.056323,0.623448,-34.650661,0.062562,0.000000
97.310005,62.030922,-34.695141,0.021118,0.002455,0.062345,275.927307,14.056407,0.623448,-34.695141,0.062562,0.000000
97.550003,62.011925,-34.695141,0.021083,0.002455,0.062345,275.842804,14.052102,0.623448,-34.695141,0.062562,0.000000
97.790001,62.019005,-34.739624,0.021113,0.002455,0.062345,275.874298,14.053707,0.623448,-34.739624,0.062562,0.000000
98.030006,62.003738,-34.695141,0.021105,0.002455,0.062345,275.806396,14.050248,0.623448,-34.695141,0.062562,0.000000
98.270004,61.979156,-34.695141,0.021088,0.002455,0.062345,275.697052,14.044678,0.623448,-34.695141,0.062562,0.000000
98.510002,61.978043,-34.739624,0.021092,0.002455,0.062345,275.692108,14.044425,0.623448,-34.739624,0.062562,0.000000
98.750008,61.962776,-34.695141,0.021101,0.002455,0.062345,275.624207,14.040966,0.623448,-34.695141,0.062562,0.000000
98.990005,61.951233,-34.739624,0.021092,0.002455,0.062345,275.572845,14.038349,0.623448,-34.739624,0.062562,0.000000
99.230003,61.937454,-34.695141,0.021131,0.002455,0.062345,275.511566,14.035228,0.623448,-34.695141,0.062562,0.000000
99.470001,61.935593,-34.695141,0.021118,0.002455,0.062345,275.503265,14.034806,0.623448,-34.695141,0.062562,0.000000
99.700005,61.934105,-34.695141,0.021096,0.002455,0.062345,275.496643,14.034469,0.623448,-34.695141,0.062562,0.000000