File: Data/I-18 Lathed test 3_10242023_165444.csv
Time (sec),S:Load (lbs),S:HL1 (DIM),S:LVDT (in),S:Position (in),Ch:Position (mm),Ch:Load (N),Ch:Stress (MPa),Ch:Strain (mm/mm),Ch:HL1 (DIM),Set Point (),Cycles ()
0.110000,-0.035378,-20.461237,0.003290,-0.012891,-0.327438,-0.157367,-0.008017,-3.274384,-20.461237,-0.327230,0.000000
0.310000,-0.034264,-20.461237,0.003277,-0.012891,-0.327438,-0.152412,-0.007764,-3.274384,-20.461237,-0.327230,0.000000
0.510000,-0.014526,-20.416756,0.003277,-0.012820,-0.325635,-0.064617,-0.003292,-3.256348,-20.416756,-0.324976,0.000000
0.710000,-0.036125,-20.416756,0.003311,-0.012702,-0.322625,-0.160693,-0.008186,-3.226254,-20.416756,-0.321645,0.000000
0.910000,-0.049530,-20.461237,0.003445,-0.012574,-0.319391,-0.220321,-0.011224,-3.193906,-20.461237,-0.318315,0.000000
1.110000,-0.034630,-20.416756,0.003570,-0.012445,-0.316104,-0.154041,-0.007847,-3.161038,-20.416756,-0.314985,0.000000
1.310000,-0.024582,-20.461237,0.003725,-0.012316,-0.312826,-0.109346,-0.005570,-3.128257,-20.461237,-0.311638,0.000000
1.510000,-0.037987,-20.550200,0.003833,-0.012186,-0.309513,-0.168974,-0.008608,-3.095130,-20.550200,-0.308307,0.000000
1.710000,-0.050270,-20.461237,0.003958,-0.012048,-0.306018,-0.223612,-0.011391,-3.060180,-20.461237,-0.304977,0.000000
1.910000,-0.050270,-20.461237,0.004122,-0.011920,-0.302766,-0.223612,-0.011391,-3.027660,-20.461237,-0.301647,0.000000
2.110000,-0.049904,-20.461237,0.004264,-0.011793,-0.299549,-0.221983,-0.011308,-2.995485,-20.461237,-0.298317,0.000000
2.310000,-0.045433,-20.505718,0.004389,-0.011662,-0.296210,-0.202096,-0.010295,-2.962097,-20.505718,-0.294987,0.000000
2.510000,-0.037613,-20.461237,0.004497,-0.011535,-0.293001,-0.167311,-0.008523,-2.930010,-20.461237,-0.291657,0.000000
2.710000,-0.035004,-20.461237,0.004682,-0.011400,-0.289549,-0.155704,-0.007932,-2.895494,-20.461237,-0.288327,0.000000
2.910000,-0.029793,-20.505718,0.004825,-0.011259,-0.285968,-0.132525,-0.006751,-2.859677,-20.505718,-0.284997,0.000000
3.110000,-0.033142,-20.505718,0.004984,-0.011126,-0.282603,-0.147423,-0.007510,-2.826030,-20.505718,-0.281666,0.000000
3.310000,-0.048042,-20.505718,0.005101,-0.010998,-0.279351,-0.213703,-0.010887,-2.793510,-20.505718,-0.278319,0.000000
3.510000,-0.051392,-20.461237,0.005230,-0.010865,-0.275969,-0.228601,-0.011646,-2.759688,-20.461237,-0.274989,0.000000
3.710000,-0.051392,-20.505718,0.005385,-0.010734,-0.272656,-0.228601,-0.011646,-2.726559,-20.505718,-0.271659,0.000000
3.910000,-0.074852,-20.505718,0.005497,-0.010602,-0.269300,-0.332958,-0.016962,-2.692998,-20.505718,-0.268329,0.000000
4.110000,-0.096077,-20.505718,0.005665,-0.010474,-0.266039,-0.427372,-0.021771,-2.660391,-20.505718,-0.264998,0.000000
4.310000,-0.082298,-20.550200,0.005812,-0.010343,-0.262700,-0.366081,-0.018649,-2.627001,-20.550200,-0.261668,0.000000
4.510000,-0.055862,-20.505718,0.005933,-0.010217,-0.259500,-0.248488,-0.012659,-2.595000,-20.505718,-0.258338,0.000000
4.710000,-0.053253,-20.594681,0.006053,-0.010085,-0.256170,-0.236882,-0.012067,-2.561700,-20.594681,-0.255008,0.000000
4.910000,-0.064423,-20.505718,0.006226,-0.009948,-0.252675,-0.286566,-0.014598,-2.526751,-20.505718,-0.251678,0.000000
5.110000,-0.046181,-20.505718,0.006347,-0.009815,-0.249302,-0.205422,-0.010465,-2.493016,-20.505718,-0.248330,0.000000
5.310000,-0.047295,-20.550200,0.006463,-0.009684,-0.245980,-0.210377,-0.010717,-2.459800,-20.550200,-0.245000,0.000000
5.510000,-0.069267,-20.594681,0.006605,-0.009555,-0.242684,-0.308116,-0.015696,-2.426844,-20.594681,-0.241670,0.000000
5.710000,-0.038727,-20.550200,0.006765,-0.009424,-0.239372,-0.172265,-0.008776,-2.393719,-20.550200,-0.238340,0.000000
5.910000,-0.052132,-20.550200,0.006907,-0.009299,-0.236198,-0.231893,-0.011813,-2.361979,-20.550200,-0.235010,0.000000
6.110000,-0.043198,-20.550200,0.007036,-0.009164,-0.232772,-0.192153,-0.009789,-2.327722,-20.550200,-0.231679,0.000000
6.310000,-0.045807,-20.594681,0.007179,-0.009035,-0.229485,-0.203759,-0.010380,-2.294854,-20.594681,-0.228350,0.000000
6.510000,-0.037239,-20.594681,0.007295,-0.008902,-0.226112,-0.165648,-0.008438,-2.261119,-20.594681,-0.225019,0.000000
6.710001,-0.026443,-20.639162,0.007459,-0.008773,-0.222842,-0.117626,-0.005992,-2.228425,-20.639162,-0.221689,0.000000
6.910000,-0.025696,-20.550200,0.007584,-0.008645,-0.219591,-0.114301,-0.005823,-2.195905,-20.550200,-0.218359,0.000000
7.110000,-0.039848,-20.594681,0.007722,-0.008508,-0.216113,-0.177254,-0.009030,-2.161130,-20.594681,-0.215012,0.000000
7.310000,-0.036865,-20.639162,0.007847,-0.008378,-0.212791,-0.163985,-0.008354,-2.127913,-20.639162,-0.211681,0.000000
7.510000,-0.020859,-20.550200,0.008011,-0.008250,-0.209556,-0.092784,-0.004727,-2.095564,-20.550200,-0.208351,0.000000
7.710001,-0.024582,-20.639162,0.008123,-0.008118,-0.206200,-0.109346,-0.005570,-2.062003,-20.639162,-0.205021,0.000000
7.910000,-0.022720,-20.594681,0.008269,-0.007988,-0.202888,-0.101065,-0.005149,-2.028878,-20.594681,-0.201691,0.000000
8.110001,-0.030540,-20.639162,0.008416,-0.007853,-0.199471,-0.135851,-0.006921,-1.994708,-20.639162,-0.198361,0.000000
8.310000,-0.039101,-20.639162,0.008532,-0.007721,-0.196106,-0.173928,-0.008860,-1.961060,-20.639162,-0.195031,0.000000
8.510000,-0.045807,-20.683641,0.008696,-0.007591,-0.192810,-0.203759,-0.010380,-1.928105,-20.683641,-0.191700,0.000000
8.710000,-0.014900,-20.639162,0.008821,-0.007461,-0.189506,-0.066279,-0.003376,-1.895063,-20.639162,-0.188370,0.000000
8.910001,-0.029045,-20.639162,0.008946,-0.007334,-0.186289,-0.129199,-0.006582,-1.862888,-20.639162,-0.185023,0.000000
9.110001,-0.030167,-20.683641,0.009097,-0.007199,-0.182863,-0.134188,-0.006836,-1.828634,-20.683641,-0.181693,0.000000
9.310000,-0.008568,-20.683641,0.009222,-0.007063,-0.179412,-0.038112,-0.001941,-1.794120,-20.683641,-0.178362,0.000000
9.510000,-0.013039,-20.594681,0.009408,-0.006926,-0.175926,-0.057999,-0.002955,-1.759257,-20.594681,-0.175032,0.000000
9.710000,-0.024948,-20.683641,0.009528,-0.006800,-0.172726,-0.110975,-0.005653,-1.727256,-20.683641,-0.171702,0.000000
9.910001,-0.043571,-20.683641,0.009653,-0.006667,-0.169352,-0.193816,-0.009873,-1.693521,-20.683641,-0.168372,0.000000
10.110001,-0.051392,-20.639162,0.009800,-0.006537,-0.166048,-0.228601,-0.011646,-1.660479,-20.639162,-0.165042,0.000000
10.310000,-0.061813,-20.683641,0.009955,-0.006404,-0.162666,-0.274960,-0.014007,-1.626657,-20.683641,-0.161712,0.000000
10.510000,-0.072617,-20.772604,0.010102,-0.006276,-0.159414,-0.323015,-0.016455,-1.594137,-20.772604,-0.158382,0.000000
10.710000,-0.072990,-20.683641,0.010214,-0.006145,-0.156075,-0.324678,-0.016540,-1.560747,-20.683641,-0.155051,0.000000
10.910001,-0.037239,-20.683641,0.010365,-0.006019,-0.152883,-0.165648,-0.008438,-1.528833,-20.683641,-0.151704,0.000000
11.110001,-0.046921,-20.683641,0.010473,-0.005889,-0.149571,-0.208714,-0.010632,-1.495707,-20.683641,-0.148374,0.000000
11.310000,-0.061447,-20.728123,0.010624,-0.005751,-0.146084,-0.273331,-0.013924,-1.460845,-20.728123,-0.145044,0.000000
11.510000,-0.044685,-20.728123,0.010774,-0.005620,-0.142737,-0.198770,-0.010126,-1.427367,-20.728123,-0.141714,0.000000
11.710001,-0.037613,-20.728123,0.010912,-0.005487,-0.139372,-0.167311,-0.008523,-1.393719,-20.728123,-0.138383,0.000000
11.910001,-0.046547,-20.683641,0.011050,-0.005357,-0.136076,-0.207051,-0.010548,-1.360764,-20.683641,-0.135053,0.000000
12.110001,-0.038361,-20.728123,0.011201,-0.005227,-0.132764,-0.170636,-0.008693,-1.327639,-20.728123,-0.131723,0.000000
12.310000,-0.046921,-20.728123,0.011335,-0.005102,-0.129581,-0.208714,-0.010632,-1.295812,-20.728123,-0.128393,0.000000
12.510000,-0.034630,-20.728123,0.011477,-0.004967,-0.126164,-0.154041,-0.007847,-1.261642,-20.728123,-0.125063,0.000000
12.710001,-0.032402,-20.683641,0.011602,-0.004836,-0.122843,-0.144131,-0.007342,-1.228426,-20.683641,-0.121715,0.000000
12.910001,-0.021973,-20.728123,0.011740,-0.004706,-0.119521,-0.097739,-0.004979,-1.195213,-20.728123,-0.118385,0.000000
13.110001,-0.010803,-20.728123,0.011883,-0.004575,-0.116217,-0.048055,-0.002448,-1.162171,-20.728123,-0.115055,0.000000
13.310000,-0.022346,-20.728123,0.012016,-0.004448,-0.112982,-0.099402,-0.005064,-1.129821,-20.728123,-0.111725,0.000000
13.510000,-0.025322,-20.728123,0.012158,-0.004312,-0.109531,-0.112638,-0.005738,-1.095307,-20.728123,-0.108395,0.000000
13.710001,-0.025322,-20.772604,0.012279,-0.004182,-0.106235,-0.112638,-0.005738,-1.062352,-20.772604,-0.105065,0.000000
13.910001,0.003349,-20.683641,0.012443,-0.004053,-0.102957,0.014898,0.000759,-1.029571,-20.683641,-0.101735,0.000000
14.110001,-0.016388,-20.728123,0.012564,-0.003923,-0.099636,-0.072897,-0.003714,-0.996358,-20.728123,-0.098404,0.000000
14.310000,-0.014153,-20.772604,0.012697,-0.003790,-0.096271,-0.062954,-0.003207,-0.962707,-20.772604,-0.095074,0.000000
14.510000,-0.021973,-20.772604,0.012840,-0.003659,-0.092932,-0.097739,-0.004979,-0.929320,-20.772604,-0.091744,0.000000
14.710001,-0.032028,-20.772604,0.012986,-0.003525,-0.089532,-0.142469,-0.007258,-0.895324,-20.772604,-0.088397,0.000000
14.910001,-0.026070,-20.728123,0.013146,-0.003393,-0.086185,-0.115964,-0.005907,-0.861851,-20.728123,-0.085066,0.000000
15.110001,-0.006332,-20.772604,0.013267,-0.003266,-0.082950,-0.028168,-0.001435,-0.829501,-20.772604,-0.081736,0.000000
15.310000,-0.017136,-20.772604,0.013405,-0.003138,-0.079716,-0.076223,-0.003883,-0.797156,-20.772604,-0.078406,0.000000
15.510001,-0.000748,-20.861567,0.013542,-0.003003,-0.076273,-0.003326,-0.000169,-0.762728,-20.861567,-0.075076,0.000000
15.710001,-0.001122,-20.817085,0.013698,-0.002865,-0.072760,-0.004989,-0.000254,-0.727604,-20.817085,-0.071746,0.000000
15.910001,-0.007820,-20.772604,0.013831,-0.002728,-0.069300,-0.034786,-0.001772,-0.693003,-20.772604,-0.068416,0.000000
16.110001,-0.022720,-20.772604,0.013961,-0.002602,-0.066091,-0.101065,-0.005149,-0.660915,-20.772604,-0.065085,0.000000
16.310001,-0.029419,-20.728123,0.014090,-0.002472,-0.062779,-0.130862,-0.006666,-0.627785,-20.728123,-0.061755,0.000000
16.510000,-0.049530,-20.728123,0.014250,-0.002341,-0.059457,-0.220321,-0.011224,-0.594573,-20.728123,-0.058425,0.000000
16.710001,-0.062561,-20.817085,0.014379,-0.002207,-0.056066,-0.278285,-0.014177,-0.560664,-20.817085,-0.055078,0.000000
16.910002,-0.057724,-20.772604,0.014530,-0.002080,-0.052831,-0.256769,-0.013080,-0.528315,-20.772604,-0.051747,0.000000
17.110001,-0.064049,-20.817085,0.014668,-0.001948,-0.049475,-0.284903,-0.014514,-0.494754,-20.817085,-0.048418,0.000000
17.310001,-0.030907,-20.817085,0.014793,-0.001822,-0.046284,-0.137480,-0.007004,-0.462840,-20.817085,-0.045087,0.000000
17.510000,-0.039848,-20.772604,0.014931,-0.001690,-0.042937,-0.177254,-0.009030,-0.429366,-20.772604,-0.041757,0.000000
17.710001,-0.033516,-20.817085,0.015064,-0.001555,-0.039493,-0.149086,-0.007595,-0.394935,-20.817085,-0.038427,0.000000
17.910002,-0.036125,-20.817085,0.015207,-0.001422,-0.036120,-0.160693,-0.008186,-0.361200,-20.817085,-0.035097,0.000000
18.110001,-0.017502,-20.817085,0.015353,-0.001290,-0.032755,-0.077852,-0.003966,-0.327552,-20.817085,-0.031767,0.000000
18.310001,-0.023460,-20.861567,0.015474,-0.001160,-0.029460,-0.104357,-0.005316,-0.294597,-20.861567,-0.028436,0.000000
18.510000,-0.008194,-20.861567,0.015599,-0.001031,-0.026182,-0.036449,-0.001857,-0.261816,-20.861567,-0.025089,0.000000
18.710001,-0.016014,-20.861567,0.015759,-0.000903,-0.022938,-0.071234,-0.003629,-0.229384,-20.861567,-0.021759,0.000000
18.910002,-0.012291,-20.861567,0.015888,-0.000769,-0.019530,-0.054673,-0.002785,-0.195301,-20.861567,-0.018429,0.000000
19.110001,0.001488,-20.861567,0.016039,-0.000640,-0.016252,0.006618,0.000337,-0.162520,-20.861567,-0.015099,0.000000
19.310001,0.024948,-20.861567,0.016173,-0.000509,-0.012939,0.110975,0.005653,-0.129390,-20.861567,-0.011768,0.000000
19.510000,0.038353,-20.906048,0.016306,-0.000380,-0.009661,0.170603,0.008691,-0.096609,-20.906048,-0.008438,0.000000
19.710001,0.055855,-20.861567,0.016461,-0.000253,-0.006418,0.248455,0.012657,-0.064177,-20.861567,-0.005108,0.000000
19.910002,0.181717,-20.906048,0.016595,-0.000116,-0.002949,0.808317,0.041178,-0.029488,-20.906048,-0.001778,0.000000
20.110001,0.551109,-20.817085,0.016750,0.000015,0.000373,2.451457,0.124883,0.003728,-20.817085,0.001552,0.000000
20.310001,0.747345,-20.906048,0.016798,-0.000001,-0.000017,3.324357,0.169351,-0.000174,-20.906048,0.000130,0.000000
20.510000,0.733574,-20.906048,0.016780,-0.000001,-0.000026,3.263100,0.166230,-0.000257,-20.906048,0.000130,0.000000
20.710001,0.737297,-20.906048,0.016785,-0.000001,-0.000026,3.279661,0.167074,-0.000257,-20.906048,0.000199,0.000000
20.910002,0.722031,-20.861567,0.016780,-0.000001,-0.000026,3.211753,0.163614,-0.000257,-20.861567,0.000529,0.000000
21.110001,0.736923,-20.950527,0.016780,-0.000001,-0.000026,3.277998,0.166989,-0.000257,-20.950527,0.000867,0.000000
21.310001,0.763359,-20.906048,0.016815,0.000018,0.000469,3.395591,0.172980,0.004686,-20.906048,0.001197,0.000000
21.510000,0.890709,-20.950527,0.016780,0.000028,0.000720,3.962071,0.201838,0.007199,-20.950527,0.001526,0.000000
21.710001,0.986412,-20.906048,0.016806,0.000041,0.001050,4.387780,0.223524,0.010496,-20.906048,0.001865,0.000000
21.910002,1.091797,-20.906048,0.016824,0.000053,0.001353,4.856555,0.247405,0.013531,-20.906048,0.002194,0.000000
22.110001,1.245956,-20.950527,0.016828,0.000069,0.001761,5.542291,0.282338,0.017607,-20.950527,0.002532,0.000000
22.310001,1.354317,-20.906048,0.016824,0.000081,0.002047,6.024302,0.306893,0.020469,-20.906048,0.002862,0.000000
22.510000,1.469376,-20.950527,0.016854,0.000089,0.002264,6.536109,0.332965,0.022637,-20.950527,0.003200,0.000000
22.710001,1.562469,-20.950527,0.016871,0.000098,0.002498,6.950212,0.354061,0.024977,-20.950527,0.003530,0.000000
22.910002,1.721848,-20.950527,0.016901,0.000117,0.002983,7.659160,0.390176,0.029833,-20.950527,0.003859,0.000000
23.110001,1.904312,-20.906048,0.016888,0.000129,0.003287,8.470803,0.431523,0.032868,-20.906048,0.004197,0.000000
23.310001,2.048042,-20.950527,0.016914,0.000142,0.003616,9.110147,0.464093,0.036165,-20.950527,0.004527,0.000000
23.510000,2.226036,-20.906048,0.016905,0.000154,0.003920,9.901903,0.504427,0.039200,-20.906048,0.004865,0.000000
23.710001,2.404778,-20.950527,0.016927,0.000169,0.004284,10.696984,0.544930,0.042841,-20.950527,0.005195,0.000000
23.910002,2.637512,-20.950527,0.016962,0.000182,0.004622,11.732241,0.597669,0.046225,-20.950527,0.005533,0.000000
24.110001,2.885139,-20.906048,0.016962,0.000198,0.005039,12.833741,0.653782,0.050388,-20.906048,0.005862,0.000000
24.310001,2.938019,-20.906048,0.016931,0.000202,0.005126,13.068960,0.665765,0.051255,-20.906048,0.006201,0.000000
24.510000,3.046005,-20.995008,0.016962,0.000211,0.005351,13.549308,0.690235,0.053507,-20.995008,0.006530,0.000000
24.710001,3.369965,-20.950527,0.016987,0.000224,0.005689,14.990352,0.763645,0.056891,-20.950527,0.006860,0.000000
24.910002,3.876770,-20.950527,0.016983,0.000252,0.006392,17.244734,0.878489,0.063916,-20.950527,0.007198,0.000000
25.110001,4.122162,-20.950527,0.017022,0.000264,0.006713,18.336292,0.934095,0.067125,-20.950527,0.007528,0.000000
25.310001,4.340744,-20.950527,0.017035,0.000276,0.007016,19.308594,0.983627,0.070161,-20.950527,0.007866,0.000000
25.510002,4.538475,-20.995008,0.017039,0.000287,0.007302,20.188145,1.028433,0.073022,-20.995008,0.008195,0.000000
25.710001,4.864296,-21.039490,0.017026,0.000300,0.007632,21.637468,1.102265,0.076319,-21.039490,0.008533,0.000000
25.910002,5.212097,-20.950527,0.017061,0.000314,0.007987,23.184566,1.181078,0.079873,-20.950527,0.008863,0.000000
26.110001,5.289551,-20.995008,0.017061,0.000322,0.008169,23.529097,1.198629,0.081693,-20.995008,0.009201,0.000000
26.310001,5.576645,-21.039490,0.017078,0.000332,0.008438,24.806156,1.263686,0.084380,-21.039490,0.009531,0.000000
26.510002,5.738258,-20.995008,0.017078,0.000344,0.008733,25.525047,1.300308,0.087329,-20.995008,0.009860,0.000000
26.710001,6.174675,-21.039490,0.017099,0.000362,0.009184,27.466326,1.399201,0.091840,-21.039490,0.010199,0.000000
26.910002,6.817390,-21.083971,0.017130,0.000383,0.009730,30.325268,1.544843,0.097302,-21.083971,0.010528,0.000000
27.110001,7.046402,-21.039490,0.017117,0.000394,0.010008,31.343962,1.596738,0.100080,-21.039490,0.010866,0.000000
27.310001,7.343552,-21.039490,0.017134,0.000407,0.010329,32.665749,1.664073,0.103286,-21.039490,0.011196,0.000000
27.510002,7.565117,-21.083971,0.017138,0.000416,0.010554,33.651321,1.714280,0.105542,-21.083971,0.011534,0.000000
27.710001,7.854446,-20.995008,0.017143,0.000426,0.010832,34.938324,1.779843,0.108316,-20.995008,0.011864,0.000000
27.910002,8.261078,-20.995008,0.017164,0.000441,0.011214,36.747108,1.871987,0.112135,-20.995008,0.012193,0.000000
28.110001,8.678879,-21.083971,0.017173,0.000455,0.011551,38.605579,1.966662,0.115515,-21.083971,0.012531,0.000000
28.310001,8.956673,-21.039490,0.017177,0.000468,0.011881,39.841270,2.029611,0.118812,-21.039490,0.012861,0.000000
28.510002,9.284729,-21.083971,0.017199,0.000479,0.012159,41.300537,2.103950,0.121586,-21.083971,0.013199,0.000000
28.710001,9.512627,-21.039490,0.017212,0.000493,0.012523,42.314278,2.155592,0.125227,-21.039490,0.013529,0.000000
28.910002,10.198532,-21.083971,0.017220,0.000511,0.012974,45.365337,2.311021,0.129739,-21.083971,0.013867,0.000000
29.110001,10.609634,-21.039490,0.017229,0.000525,0.013347,47.194012,2.404177,0.133467,-21.039490,0.014197,0.000000
29.310001,10.822632,-21.083971,0.017250,0.000536,0.013615,48.141472,2.452444,0.136154,-21.083971,0.014535,0.000000
29.510002,11.100418,-21.083971,0.017255,0.000550,0.013962,49.377125,2.515391,0.139625,-21.083971,0.014864,0.000000
29.710001,11.367409,-21.083971,0.017268,0.000558,0.014162,50.564758,2.575891,0.141619,-21.083971,0.015194,0.000000
29.910002,12.061516,-21.083971,0.017289,0.000577,0.014665,53.652302,2.733179,0.146650,-21.083971,0.015532,0.000000
30.110001,12.149765,-21.128452,0.017289,0.000584,0.014838,54.044853,2.753176,0.148383,-21.128452,0.015862,0.000000
30.310001,12.531448,-21.083971,0.017298,0.000598,0.015194,55.742668,2.839667,0.151941,-21.083971,0.016200,0.000000
30.510002,13.072502,-21.083971,0.017319,0.000617,0.015662,58.149395,2.962271,0.156623,-21.083971,0.016529,0.000000
30.710001,13.375618,-21.128452,0.017311,0.000628,0.015948,59.497719,3.030958,0.159484,-21.128452,0.016868,0.000000
30.910002,13.814270,-21.083971,0.017328,0.000642,0.016304,61.448940,3.130358,0.163038,-21.083971,0.017197,0.000000
31.110001,14.054077,-21.128452,0.017345,0.000653,0.016590,62.515656,3.184700,0.165900,-21.128452,0.017527,0.000000
31.310001,14.373199,-21.128452,0.017350,0.000666,0.016928,63.935184,3.257014,0.169283,-21.128452,0.017865,0.000000
31.510002,14.741852,-21.083971,0.017371,0.000679,0.017258,65.575035,3.340551,0.172580,-21.083971,0.018194,0.000000
31.710001,15.027832,-21.128452,0.017367,0.000691,0.017553,66.847137,3.405355,0.175528,-21.128452,0.018533,0.000000
31.910002,15.398712,-21.128452,0.017406,0.000703,0.017848,68.496895,3.489398,0.178477,-21.128452,0.018862,0.000000
32.110001,15.659004,-21.128452,0.017406,0.000715,0.018151,69.654732,3.548381,0.181512,-21.128452,0.019200,0.000000
32.310001,15.804604,-21.172934,0.017406,0.000723,0.018359,70.302391,3.581374,0.183594,-21.172934,0.019530,0.000000
32.510002,16.407845,-21.172934,0.017436,0.000740,0.018784,72.985741,3.718071,0.187841,-21.172934,0.019868,0.000000
32.710003,16.952255,-21.172934,0.017449,0.000759,0.019278,75.407394,3.841436,0.192784,-21.172934,0.020198,0.000000
32.910000,17.423302,-21.217413,0.017444,0.000776,0.019721,77.502716,3.948176,0.197208,-21.217413,0.020527,0.000000
33.110001,17.621407,-21.261894,0.017457,0.000788,0.020016,78.383934,3.993068,0.200157,-21.261894,0.020866,0.000000
33.310001,17.775940,-21.128452,0.017475,0.000799,0.020293,79.071327,4.028086,0.202931,-21.128452,0.021195,0.000000
33.510002,17.889145,-21.217413,0.017483,0.000809,0.020545,79.574890,4.053738,0.205448,-21.217413,0.021533,0.000000
33.710003,18.356842,-21.172934,0.017492,0.000824,0.020918,81.655312,4.159720,0.209176,-21.172934,0.021863,0.000000
33.910000,18.587341,-21.172934,0.017496,0.000834,0.021195,82.680626,4.211952,0.211950,-21.172934,0.022201,0.000000
34.110001,18.912048,-21.217413,0.017513,0.000844,0.021447,84.124992,4.285532,0.214467,-21.217413,0.022531,0.000000
34.310001,19.051689,-21.172934,0.017518,0.000854,0.021681,84.746147,4.317174,0.216806,-21.172934,0.022869,0.000000
34.510002,19.438210,-21.261894,0.017522,0.000871,0.022114,86.465477,4.404761,0.221144,-21.261894,0.023198,0.000000
34.710003,20.023956,-21.217413,0.017526,0.000886,0.022496,89.071007,4.537493,0.224959,-21.217413,0.023528,0.000000
34.910000,19.977783,-21.172934,0.017569,0.000893,0.022687,88.865616,4.527030,0.226867,-21.172934,0.023866,0.000000
35.110001,20.473038,-21.261894,0.017565,0.000909,0.023086,91.068619,4.639256,0.230856,-21.261894,0.024196,0.000000
35.310001,20.819717,-21.217413,0.017582,0.000925,0.023493,92.610725,4.717815,0.234932,-21.217413,0.024534,0.000000
35.510002,21.049469,-21.217413,0.017587,0.000936,0.023779,93.632713,4.769878,0.237794,-21.217413,0.024863,0.000000
35.710003,21.422958,-21.217413,0.017591,0.000952,0.024178,95.294075,4.854512,0.241783,-21.217413,0.025202,0.000000
35.910000,21.704842,-21.261894,0.017625,0.000965,0.024499,96.547958,4.918387,0.244992,-21.261894,0.025531,0.000000
36.110001,21.782295,-21.261894,0.017638,0.000973,0.024716,96.892487,4.935939,0.247161,-21.261894,0.025861,0.000000
36.310001,22.275688,-21.217413,0.017634,0.000988,0.025098,99.087212,5.047743,0.250976,-21.217413,0.026199,0.000000
36.510002,22.426872,-21.261894,0.017630,0.000999,0.025366,99.759712,5.082002,0.253664,-21.261894,0.026529,0.000000
36.710003,22.766479,-21.217413,0.017647,0.001012,0.025696,101.270355,5.158958,0.256960,-21.217413,0.026867,0.000000
36.910000,23.550323,-21.217413,0.017669,0.001033,0.026251,104.757072,5.336579,0.262509,-21.217413,0.027196,0.000000
37.110001,23.501915,-21.350857,0.017686,0.001042,0.026476,104.541740,5.325610,0.264765,-21.350857,0.027534,0.000000
37.310001,23.668739,-21.306376,0.017699,0.001055,0.026789,105.283813,5.363413,0.267887,-21.306376,0.027864,0.000000
37.510002,23.996422,-21.261894,0.017716,0.001067,0.027101,106.741417,5.437667,0.271010,-21.261894,0.028202,0.000000
37.710003,24.382576,-21.261894,0.017716,0.001083,0.027517,108.459114,5.525171,0.275173,-21.261894,0.028532,0.000000
37.910004,24.420555,-21.306376,0.017729,0.001088,0.027630,108.628052,5.533777,0.276297,-21.306376,0.028861,0.000000
38.110001,24.916931,-21.306376,0.017742,0.001105,0.028072,110.836044,5.646257,0.280722,-21.306376,0.029200,0.000000
38.310001,25.137375,-21.306376,0.017746,0.001115,0.028324,111.816628,5.696210,0.283239,-21.306376,0.029529,0.000000
38.510002,26.073517,-21.306376,0.017772,0.001139,0.028939,115.980797,5.908343,0.289393,-21.306376,0.029867,0.000000
38.710003,26.528931,-21.306376,0.017781,0.001155,0.029330,118.006577,6.011542,0.293295,-21.306376,0.030197,0.000000
38.910004,26.616440,-21.261894,0.017789,0.001169,0.029685,118.395836,6.031371,0.296853,-21.261894,0.030535,0.000000
39.110001,26.792198,-21.261894,0.017798,0.001179,0.029954,119.177650,6.071199,0.299540,-21.261894,0.030865,0.000000
39.310001,27.048019,-21.306376,0.017815,0.001192,0.030284,120.315598,6.129169,0.302837,-21.306376,0.031203,0.000000
39.510002,27.370491,-21.306376,0.017815,0.001204,0.030579,121.750023,6.202242,0.305785,-21.306376,0.031532,0.000000
39.710003,27.783455,-21.306376,0.017824,0.001219,0.030969,123.586983,6.295821,0.309688,-21.306376,0.031862,0.000000
39.910004,28.019905,-21.306376,0.017841,0.001231,0.031272,124.638763,6.349401,0.312723,-21.306376,0.032200,0.000000
40.110001,27.987511,-21.350857,0.017845,0.001235,0.031376,124.494667,6.342061,0.313764,-21.350857,0.032530,0.000000
40.310001,28.775452,-21.395338,0.017876,0.001255,0.031888,127.999603,6.520611,0.318881,-21.395338,0.032868,0.000000
40.510002,29.559296,-21.306376,0.017867,0.001274,0.032356,131.486313,6.698232,0.323563,-21.306376,0.033198,0.000000
40.710003,29.972626,-21.350857,0.017871,0.001290,0.032764,133.324905,6.791894,0.327639,-21.350857,0.033536,0.000000
40.910004,30.197540,-21.395338,0.017897,0.001300,0.033033,134.325363,6.842860,0.330327,-21.395338,0.033865,0.000000
41.110001,30.578110,-21.395338,0.017914,0.001315,0.033388,136.018219,6.929099,0.333885,-21.395338,0.034195,0.000000
41.310001,30.728920,-21.350857,0.017914,0.001325,0.033648,136.689056,6.963273,0.336485,-21.350857,0.034533,0.000000
41.510002,31.290459,-21.350857,0.017919,0.001340,0.034030,139.186905,7.090519,0.340300,-21.350857,0.034863,0.000000
41.710003,31.643463,-21.395338,0.017945,0.001352,0.034342,140.757156,7.170511,0.343422,-21.395338,0.035201,0.000000
41.910004,31.734322,-21.350857,0.017949,0.001359,0.034507,141.161316,7.191100,0.345069,-21.350857,0.035530,0.000000
42.110001,31.962959,-21.395338,0.017975,0.001368,0.034741,142.178345,7.242910,0.347412,-21.395338,0.035869,0.000000
42.310001,33.314674,-21.350857,0.017979,0.001395,0.035426,148.191071,7.549213,0.354262,-21.350857,0.036198,0.000000
42.510002,33.600281,-21.439819,0.017975,0.001406,0.035704,149.461517,7.613933,0.357037,-21.439819,0.036536,0.000000
42.710003,33.971535,-21.395338,0.017979,0.001419,0.036042,151.112930,7.698060,0.360420,-21.395338,0.036866,0.000000
42.910004,34.286568,-21.395338,0.018014,0.001431,0.036337,152.514267,7.769447,0.363369,-21.395338,0.037195,0.000000
43.110001,34.806023,-21.395338,0.018005,0.001444,0.036684,154.824921,7.887157,0.366836,-21.395338,0.037534,0.000000
43.310001,35.243187,-21.484299,0.018018,0.001457,0.037013,156.769531,7.986220,0.370132,-21.484299,0.037863,0.000000
43.510002,35.849411,-21.439819,0.018048,0.001471,0.037369,159.466141,8.123592,0.373690,-21.439819,0.038201,0.000000
43.710003,36.104485,-21.439819,0.018039,0.001481,0.037629,160.600769,8.181393,0.376290,-21.439819,0.038531,0.000000
43.910004,36.205025,-21.439819,0.018039,0.001488,0.037802,161.047989,8.204176,0.378024,-21.439819,0.038869,0.000000
44.110001,36.580376,-21.439819,0.018057,0.001499,0.038080,162.717636,8.289231,0.380798,-21.439819,0.039199,0.000000
44.310001,37.607010,-21.395338,0.018057,0.001519,0.038583,167.284332,8.521871,0.385828,-21.395338,0.039528,0.000000
44.510002,38.127960,-21.350857,0.018070,0.001532,0.038904,169.601639,8.639918,0.389038,-21.350857,0.039866,0.000000
44.710003,38.604225,-21.484299,0.018074,0.001544,0.039225,171.720169,8.747842,0.392248,-21.484299,0.040196,0.000000
44.910004,39.113998,-21.528780,0.018091,0.001558,0.039563,173.987747,8.863358,0.395631,-21.528780,0.040534,0.000000
45.110001,39.602180,-21.484299,0.018113,0.001570,0.039866,176.159302,8.973983,0.398663,-21.484299,0.040864,0.000000
45.310001,40.130577,-21.439819,0.018108,0.001582,0.040179,178.509720,9.093719,0.401786,-21.439819,0.041202,0.000000
45.510002,40.982567,-21.528780,0.018117,0.001598,0.040577,182.299561,9.286782,0.405775,-21.528780,0.041532,0.000000
45.710003,40.850372,-21.439819,0.018130,0.001602,0.040682,181.711533,9.256827,0.406816,-21.439819,0.041870,0.000000
45.910004,41.494202,-21.528780,0.018134,0.001619,0.041133,184.575424,9.402720,0.411327,-21.528780,0.042199,0.000000
46.110001,42.392365,-21.484299,0.018147,0.001633,0.041471,188.570648,9.606247,0.414707,-21.484299,0.042529,0.000000
46.310001,43.524384,-21.528780,0.018151,0.001652,0.041956,193.606125,9.862766,0.419563,-21.528780,0.042867,0.000000
46.510002,44.036392,-21.528780,0.018177,0.001664,0.042260,195.883652,9.978789,0.422599,-21.528780,0.043197,0.000000
46.710003,44.441536,-21.484299,0.018169,0.001676,0.042572,197.685822,10.070596,0.425721,-21.484299,0.043535,0.000000
46.910004,44.910721,-21.484299,0.018182,0.001688,0.042884,199.772858,10.176915,0.428844,-21.484299,0.043864,0.000000
47.110001,45.489388,-21.528780,0.018195,0.001701,0.043214,202.346909,10.308043,0.432140,-21.528780,0.044203,0.000000
47.310001,46.232643,-21.573261,0.018203,0.001715,0.043561,205.653061,10.476466,0.435607,-21.573261,0.044532,0.000000
47.510002,46.572624,-21.528780,0.018212,0.001726,0.043830,207.165375,10.553508,0.438298,-21.528780,0.044870,0.000000
47.710003,46.947975,-21.528780,0.018208,0.001734,0.044038,208.835022,10.638563,0.440380,-21.528780,0.045200,0.000000
47.910004,47.757141,-21.528780,0.018233,0.001749,0.044428,212.434372,10.821922,0.444282,-21.528780,0.045530,0.000000
48.110001,48.969208,-21.528780,0.018251,0.001771,0.044992,217.825912,11.096581,0.449918,-21.528780,0.045868,0.000000
48.310001,49.888969,-21.573261,0.018233,0.001785,0.045330,221.917221,11.305002,0.453302,-21.573261,0.046197,0.000000
48.510002,50.198784,-21.617743,0.018246,0.001795,0.045590,223.295349,11.375207,0.455902,-21.617743,0.046535,0.000000
48.710003,50.729042,-21.573261,0.018242,0.001806,0.045868,225.654053,11.495365,0.458676,-21.573261,0.046865,0.000000
48.910004,51.164345,-21.573261,0.018268,0.001818,0.046171,227.590378,11.594007,0.461712,-21.573261,0.047203,0.000000
49.110001,51.640236,-21.573261,0.018259,0.001827,0.046405,229.707245,11.701845,0.464055,-21.573261,0.047533,0.000000
49.310001,52.735756,-21.573261,0.018259,0.001845,0.046856,234.580353,11.950093,0.468562,-21.573261,0.047862,0.000000
49.510002,53.273834,-21.573261,0.018272,0.001853,0.047073,236.973846,12.072023,0.470731,-21.573261,0.048201,0.000000
49.710003,54.153008,-21.573261,0.018277,0.001870,0.047489,240.884613,12.271247,0.474895,-21.573261,0.048530,0.000000
49.910004,54.540276,-21.617743,0.018302,0.001878,0.047706,242.607269,12.359003,0.477063,-21.617743,0.048868,0.000000
50.110001,55.578445,-21.617743,0.018320,0.001896,0.048157,247.225266,12.594255,0.481571,-21.617743,0.049198,0.000000
50.310001,56.656837,-21.528780,0.018311,0.001913,0.048591,252.022202,12.838623,0.485909,-21.528780,0.049536,0.000000
50.510002,57.549789,-21.573261,0.018328,0.001929,0.048998,255.994247,13.040969,0.489985,-21.573261,0.049866,0.000000
50.710003,57.991051,-21.617743,0.018315,0.001939,0.049250,257.957062,13.140961,0.492498,-21.617743,0.050204,0.000000
50.910004,58.585358,-21.706703,0.018341,0.001949,0.049493,260.600677,13.275632,0.494928,-21.706703,0.050533,0.000000
51.110001,59.064972,-21.662224,0.018350,0.001958,0.049744,262.734131,13.384314,0.497441,-21.662224,0.050863,0.000000
51.310001,60.350403,-21.573261,0.018354,0.001977,0.050212,268.451996,13.675597,0.502123,-21.573261,0.051201,0.000000
51.510002,60.712349,-21.662224,0.018337,0.001985,0.050420,270.062012,13.757615,0.504205,-21.662224,0.051531,0.000000
51.710003,61.454483,-21.662224,0.018376,0.001998,0.050741,273.363190,13.925785,0.507414,-21.662224,0.051869,0.000000
51.910004,62.703796,-21.662224,0.018371,0.002016,0.051201,278.920410,14.208883,0.512013,-21.662224,0.052198,0.000000
52.110001,63.441833,-21.617743,0.018380,0.002028,0.051522,282.203369,14.376124,0.515219,-21.617743,0.052537,0.000000
52.310001,64.494904,-21.662224,0.018380,0.002044,0.051930,286.887665,14.614755,0.519295,-21.662224,0.052866,0.000000
52.510002,65.237045,-21.617743,0.018393,0.002058,0.052268,290.188873,14.782926,0.522679,-21.617743,0.053204,0.000000
52.710003,65.993332,-21.617743,0.018393,0.002070,0.052580,293.553009,14.954303,0.525801,-21.617743,0.053534,0.000000
52.910004,66.558975,-21.706703,0.018436,0.002079,0.052814,296.069122,15.082479,0.528140,-21.706703,0.053864,0.000000
53.110004,67.289185,-21.662224,0.018423,0.002092,0.053135,299.317230,15.247948,0.531350,-21.662224,0.054202,0.000000
53.310001,67.151047,-21.706703,0.018423,0.002085,0.052970,298.702789,15.216645,0.529704,-21.706703,0.053213,0.000000
53.510002,66.783875,-21.662224,0.018432,0.002085,0.052970,297.069519,15.133442,0.529704,-21.662224,0.053213,0.000000
53.710003,66.557480,-21.706703,0.018427,0.002081,0.052866,296.062469,15.082140,0.528663,-21.706703,0.052970,0.000000
53.910004,66.302399,-21.706703,0.018436,0.002080,0.052840,294.927795,15.024338,0.528402,-21.706703,0.052970,0.000000
54.110004,66.059616,-21.706703,0.018432,0.002080,0.052823,293.847839,14.969322,0.528228,-21.706703,0.052970,0.000000
54.310001,65.859650,-21.662224,0.018423,0.002079,0.052814,292.958344,14.924009,0.528140,-21.662224,0.052970,0.000000
54.510002,65.673462,-21.706703,0.018436,0.002079,0.052805,292.130157,14.881820,0.528053,-21.706703,0.052970,0.000000
54.710003,65.518936,-21.706703,0.018436,0.002079,0.052805,291.442780,14.846803,0.528053,-21.706703,0.052970,0.000000
54.910004,65.378922,-21.706703,0.018427,0.002079,0.052805,290.819977,14.815075,0.528053,-21.706703,0.052970,0.000000
55.110004,65.237045,-21.706703,0.018440,0.002079,0.052797,290.188873,14.782926,0.527966,-21.706703,0.052970,0.000000
55.310001,65.111923,-21.795666,0.018449,0.002079,0.052797,289.632294,14.754573,0.527966,-21.795666,0.052970,0.000000
55.510002,64.999466,-21.706703,0.018458,0.002079,0.052797,289.132050,14.729090,0.527966,-21.706703,0.052970,0.000000
55.710003,64.890747,-21.706703,0.018432,0.002079,0.052797,288.648468,14.704453,0.527966,-21.706703,0.052970,0.000000
55.910004,64.794296,-21.751184,0.018427,0.002079,0.052797,288.219421,14.682597,0.527966,-21.751184,0.052970,0.000000
56.110004,64.714615,-21.795666,0.018458,0.002079,0.052797,287.864990,14.664541,0.527966,-21.795666,0.052970,0.000000
56.310001,64.608475,-21.706703,0.018449,0.002079,0.052797,287.392853,14.640490,0.527966,-21.706703,0.052970,0.000000
56.510002,64.512405,-21.751184,0.018449,0.002079,0.052797,286.965515,14.618720,0.527966,-21.751184,0.052970,0.000000
56.710003,64.458786,-21.751184,0.018445,0.002078,0.052788,286.726990,14.606569,0.527883,-21.751184,0.052970,0.000000
56.910004,64.389160,-21.751184,0.018445,0.002078,0.052788,286.417297,14.590792,0.527883,-21.751184,0.052970,0.000000
57.110004,64.308716,-21.795666,0.018449,0.002078,0.052788,286.059448,14.572563,0.527883,-21.795666,0.052970,0.000000
57.310001,64.239838,-21.795666,0.018427,0.002078,0.052788,285.753082,14.556955,0.527883,-21.795666,0.052970,0.000000
57.510002,64.173920,-21.795666,0.018449,0.002078,0.052788,285.459839,14.542018,0.527883,-21.795666,0.052970,0.000000
57.710003,64.108017,-21.795666,0.018449,0.002078,0.052788,285.166687,14.527084,0.527883,-21.795666,0.052970,0.000000
57.910004,64.060349,-21.795666,0.018449,0.002078,0.052788,284.954651,14.516283,0.527883,-21.795666,0.052970,0.000000
58.110004,63.991837,-21.795666,0.018445,0.002078,0.052788,284.649902,14.500757,0.527883,-21.795666,0.052970,0.000000
58.310001,63.941193,-21.795666,0.018445,0.002078,0.052788,284.424622,14.489282,0.527883,-21.795666,0.052970,0.000000
58.510002,63.899109,-21.751184,0.018466,0.002078,0.052788,284.237427,14.479745,0.527883,-21.751184,0.052970,0.000000
58.710003,63.848846,-21.795666,0.018453,0.002078,0.052788,284.013855,14.468356,0.527883,-21.795666,0.052970,0.000000
58.910004,63.792618,-21.840147,0.018440,0.002078,0.052788,283.763733,14.455614,0.527883,-21.840147,0.052970,0.000000
59.110004,63.736008,-21.795666,0.018445,0.002078,0.052788,283.511932,14.442785,0.527883,-21.795666,0.052970,0.000000
59.310001,63.696167,-21.795666,0.018471,0.002078,0.052788,283.334717,14.433758,0.527883,-21.795666,0.052970,0.000000
59.510002,63.652603,-21.840147,0.018458,0.002078,0.052788,283.140930,14.423886,0.527883,-21.840147,0.052970,0.000000
59.710003,63.606430,-21.795666,0.018445,0.002078,0.052788,282.935547,14.413424,0.527883,-21.795666,0.052970,0.000000
59.910004,63.571426,-21.840147,0.018449,0.002078,0.052788,282.779816,14.405492,0.527883,-21.840147,0.052970,0.000000
60.110004,63.527863,-21.795666,0.018458,0.002078,0.052780,282.586060,14.395619,0.527796,-21.795666,0.052970,0.000000
60.310001,63.485413,-21.884628,0.018462,0.002078,0.052780,282.397217,14.386000,0.527796,-21.884628,0.052970,0.000000
60.510002,63.441101,-21.795666,0.018453,0.002078,0.052780,282.200104,14.375959,0.527796,-21.795666,0.052970,0.000000
60.710003,63.405350,-21.840147,0.018449,0.002078,0.052780,282.041077,14.367858,0.527796,-21.840147,0.052970,0.000000
60.910004,63.378540,-21.884628,0.018449,0.002078,0.052780,281.921814,14.361782,0.527796,-21.884628,0.052970,0.000000
61.110004,63.331238,-21.884628,0.018471,0.002078,0.052780,281.711426,14.351064,0.527796,-21.884628,0.052970,0.000000
61.310001,63.307419,-21.884628,0.018458,0.002078,0.052780,281.605469,14.345667,0.527796,-21.884628,0.052970,0.000000
61.510002,63.270172,-21.884628,0.018453,0.002078,0.052780,281.439789,14.337226,0.527796,-21.884628,0.052970,0.000000
61.710003,63.245972,-21.884628,0.018445,0.002078,0.052780,281.332123,14.331742,0.527796,-21.884628,0.052970,0.000000
61.910004,63.214691,-21.929110,0.018449,0.002078,0.052780,281.192993,14.324654,0.527796,-21.929110,0.052970,0.000000
62.110004,63.175598,-21.929110,0.018453,0.002078,0.052780,281.019104,14.315795,0.527796,-21.929110,0.052970,0.000000
62.310001,63.150650,-21.929110,0.018458,0.002078,0.052780,280.908112,14.310142,0.527796,-21.929110,0.052970,0.000000
62.510002,63.114899,-21.884628,0.018449,0.002078,0.052780,280.749084,14.302040,0.527796,-21.884628,0.052970,0.000000
62.710003,63.076920,-21.795666,0.018440,0.002078,0.052780,280.580139,14.293434,0.527796,-21.795666,0.052970,0.000000
62.910004,63.062393,-21.884628,0.018471,0.002078,0.052780,280.515533,14.290143,0.527796,-21.884628,0.052970,0.000000
63.110004,63.023285,-21.884628,0.018449,0.002078,0.052780,280.341583,14.281281,0.527796,-21.884628,0.052970,0.000000
63.310001,62.994247,-21.929110,0.018449,0.002078,0.052780,280.212402,14.274700,0.527796,-21.929110,0.052970,0.000000
63.510002,62.972275,-21.884628,0.018458,0.002078,0.052780,280.114655,14.269721,0.527796,-21.884628,0.052970,0.000000
63.710003,62.956268,-21.929110,0.018475,0.002078,0.052780,280.043457,14.266094,0.527796,-21.929110,0.052970,0.000000
63.910004,62.929077,-21.884628,0.018445,0.002078,0.052780,279.922516,14.259933,0.527796,-21.884628,0.052970,0.000000
64.110001,62.901901,-21.929110,0.018462,0.002078,0.052780,279.801636,14.253775,0.527796,-21.929110,0.052970,0.000000
64.310005,62.865784,-21.973589,0.018458,0.002078,0.052780,279.640961,14.245590,0.527796,-21.973589,0.052970,0.000000
64.510002,62.845291,-21.884628,0.018462,0.002078,0.052780,279.549805,14.240947,0.527796,-21.884628,0.052970,0.000000
64.710007,62.835617,-21.929110,0.018449,0.002078,0.052780,279.506775,14.238754,0.527796,-21.929110,0.052970,0.000000
64.910004,62.800247,-21.929110,0.018449,0.002078,0.052780,279.349457,14.230740,0.527796,-21.929110,0.052970,0.000000
65.110001,62.778641,-21.884628,0.018471,0.002078,0.052780,279.253326,14.225843,0.527796,-21.884628,0.052970,0.000000
65.310005,62.756668,-21.973589,0.018449,0.002078,0.052780,279.155609,14.220864,0.527796,-21.973589,0.052970,0.000000
65.510002,62.730972,-21.973589,0.018471,0.002078,0.052780,279.041290,14.215041,0.527796,-21.973589,0.052970,0.000000
65.710007,62.713104,-21.929110,0.018445,0.002078,0.052780,278.961823,14.210993,0.527796,-21.929110,0.052970,0.000000
65.910004,62.692253,-21.929110,0.018462,0.002078,0.052780,278.869080,14.206267,0.527796,-21.929110,0.052970,0.000000
66.110001,62.661346,-21.973589,0.018458,0.002078,0.052780,278.731598,14.199265,0.527796,-21.973589,0.052970,0.000000
66.310005,62.643845,-21.973589,0.018466,0.002078,0.052780,278.653748,14.195298,0.527796,-21.973589,0.052970,0.000000
66.510002,62.629318,-21.973589,0.018462,0.002078,0.052780,278.589111,14.192006,0.527796,-21.973589,0.052970,0.000000
66.710007,62.603630,-22.018070,0.018458,0.002078,0.052780,278.474854,14.186185,0.527796,-22.018070,0.052970,0.000000
66.910004,62.587616,-21.973589,0.018458,0.002078,0.052780,278.403625,14.182556,0.527796,-21.973589,0.052970,0.000000
67.110001,62.555595,-22.018070,0.018462,0.002078,0.052780,278.261200,14.175300,0.527796,-22.018070,0.052970,0.000000
67.310005,62.542557,-21.929110,0.018449,0.002078,0.052780,278.203186,14.172346,0.527796,-21.929110,0.052970,0.000000
67.510002,62.532135,-22.018070,0.018458,0.002078,0.052780,278.156830,14.169985,0.527796,-22.018070,0.052970,0.000000
67.710007,62.504951,-21.973589,0.018458,0.002078,0.052780,278.035919,14.163824,0.527796,-21.973589,0.052970,0.000000
67.910004,62.495270,-21.973589,0.018458,0.002078,0.052780,277.992859,14.161631,0.527796,-21.973589,0.052970,0.000000
68.110001,62.476280,-21.973589,0.018462,0.002078,0.052780,277.908386,14.157328,0.527796,-21.973589,0.052970,0.000000
68.310005,62.458405,-22.018070,0.018458,0.002078,0.052780,277.828857,14.153276,0.527796,-22.018070,0.052970,0.000000
68.510002,62.438667,-22.018070,0.018462,0.002078,0.052780,277.741058,14.148804,0.527796,-22.018070,0.052970,0.000000
68.710007,62.415581,-22.018070,0.018453,0.002078,0.052780,277.638367,14.143573,0.527796,-22.018070,0.052970,0.000000
68.910004,62.403290,-22.018070,0.018449,0.002078,0.052780,277.583710,14.140788,0.527796,-22.018070,0.052970,0.000000
69.110001,62.394356,-22.062551,0.018466,0.002078,0.052780,277.543945,14.138763,0.527796,-22.062551,0.052970,0.000000
69.310005,62.366425,-22.018070,0.018445,0.002078,0.052780,277.419708,14.132434,0.527796,-22.018070,0.052970,0.000000
69.510002,62.351532,-22.018070,0.018453,0.002078,0.052780,277.353455,14.129059,0.527796,-22.018070,0.052970,0.000000
69.710007,62.344826,-22.018070,0.018475,0.002078,0.052780,277.323639,14.127540,0.527796,-22.018070,0.052970,0.000000
69.910004,62.333282,-22.062551,0.018462,0.002078,0.052780,277.272278,14.124924,0.527796,-22.062551,0.052970,0.000000
70.110001,62.303123,-22.062551,0.018462,0.002078,0.052780,277.138123,14.118090,0.527796,-22.062551,0.052970,0.000000
70.310005,62.292694,-22.018070,0.018471,0.002078,0.052780,277.091736,14.115726,0.527796,-22.018070,0.052970,0.000000
70.510002,62.267006,-22.107033,0.018475,0.002078,0.052780,276.977478,14.109905,0.527796,-22.107033,0.052970,0.000000
70.710007,62.263649,-22.062551,0.018453,0.002078,0.052780,276.962555,14.109145,0.527796,-22.062551,0.052970,0.000000
70.910004,62.229393,-22.018070,0.018458,0.002078,0.052780,276.810150,14.101382,0.527796,-22.018070,0.052970,0.000000
71.110001,62.225296,-22.062551,0.018458,0.002078,0.052780,276.791931,14.100453,0.527796,-22.062551,0.052970,0.000000
71.310005,62.203697,-22.062551,0.018466,0.002078,0.052780,276.695862,14.095559,0.527796,-22.062551,0.052970,0.000000
71.510002,62.192902,-22.107033,0.018475,0.002078,0.052780,276.647858,14.093113,0.527796,-22.107033,0.052970,0.000000
71.710007,62.181732,-22.062551,0.018471,0.002078,0.052780,276.598145,14.090582,0.527796,-22.062551,0.052970,0.000000
71.910004,62.160133,-22.107033,0.018483,0.002078,0.052780,276.502075,14.085687,0.527796,-22.107033,0.052970,0.000000
72.110001,62.159012,-22.107033,0.018445,0.002078,0.052780,276.497101,14.085433,0.527796,-22.107033,0.052970,0.000000
72.310005,62.141884,-22.107033,0.018445,0.002078,0.052780,276.420898,14.081552,0.527796,-22.107033,0.052970,0.000000
72.510002,62.125130,-22.062551,0.018466,0.002078,0.052780,276.346375,14.077755,0.527796,-22.062551,0.052970,0.000000
72.710007,62.102043,-22.107033,0.018458,0.002078,0.052780,276.243683,14.072524,0.527796,-22.107033,0.052970,0.000000
72.910004,62.094597,-22.151514,0.018466,0.002078,0.052771,276.210571,14.070837,0.527709,-22.151514,0.052970,0.000000
73.110001,62.076721,-22.107033,0.018458,0.002078,0.052771,276.131042,14.066786,0.527709,-22.107033,0.052970,0.000000
73.310005,62.072624,-22.107033,0.018475,0.002078,0.052771,276.112823,14.065858,0.527709,-22.107033,0.052970,0.000000
73.510002,62.054008,-22.151514,0.018483,0.002078,0.052771,276.030029,14.061640,0.527709,-22.151514,0.052970,0.000000
73.710007,62.028687,-22.151514,0.018453,0.002078,0.052771,275.917389,14.055901,0.527709,-22.151514,0.052970,0.000000
73.910004,62.017143,-22.107033,0.018462,0.002078,0.052771,275.866028,14.053286,0.527709,-22.107033,0.052970,0.000000
74.110001,62.011185,-22.107033,0.018466,0.002078,0.052771,275.839539,14.051935,0.527709,-22.107033,0.052970,0.000000
74.310005,62.003738,-22.107033,0.018466,0.002078,0.052771,275.806396,14.050248,0.527709,-22.107033,0.052970,0.000000
74.510002,61.988838,-22.151514,0.018475,0.002078,0.052771,275.740112,14.046871,0.527709,-22.151514,0.052970,0.000000
74.710007,61.977669,-22.195995,0.018458,0.002078,0.052771,275.690430,14.044340,0.527709,-22.195995,0.052970,0.000000
74.910004,61.959053,-22.151514,0.018471,0.002078,0.052771,275.607635,14.040122,0.527709,-22.151514,0.052970,0.000000
75.110001,61.946388,-22.151514,0.018453,0.002078,0.052771,275.551300,14.037252,0.527709,-22.151514,0.052970,0.000000
75.310005,61.939316,-22.107033,0.018462,0.002078,0.052771,275.519836,14.035649,0.527709,-22.107033,0.052970,0.000000
75.510002,61.931870,-22.151514,0.018471,0.002078,0.052771,275.486725,14.033962,0.527709,-22.151514,0.052970,0.000000
75.710007,61.922562,-22.151514,0.018475,0.002078,0.052771,275.445312,14.031853,0.527709,-22.151514,0.052970,0.000000
75.910004,61.894630,-22.195995,0.018466,0.002078,0.052771,275.321075,14.025523,0.527709,-22.195995,0.052970,0.000000
76.110001,61.886063,-22.240475,0.018453,0.002078,0.052771,275.282959,14.023582,0.527709,-22.240475,0.052970,0.000000
76.310005,61.872658,-22.151514,0.018466,0.002078,0.052771,275.223328,14.020545,0.527709,-22.151514,0.052970,0.000000
76.510002,61.869682,-22.151514,0.018479,0.002078,0.052771,275.210083,14.019871,0.527709,-22.151514,0.052970,0.000000
76.710007,61.861115,-22.195995,0.018453,0.002078,0.052771,275.171967,14.017929,0.527709,-22.195995,0.052970,0.000000
76.910004,61.841385,-22.195995,0.018458,0.002078,0.052771,275.084229,14.013458,0.527709,-22.195995,0.052970,0.000000
77.110001,61.839149,-22.151514,0.018462,0.002078,0.052771,275.074280,14.012952,0.527709,-22.151514,0.052970,0.000000
77.310005,61.827972,-22.195995,0.018466,0.002078,0.052771,275.024567,14.010419,0.527709,-22.195995,0.052970,0.000000
77.510002,61.819786,-22.240475,0.018462,0.002078,0.052771,274.988129,14.008563,0.527709,-22.240475,0.052970,0.000000
77.710007,61.803772,-22.284956,0.018479,0.002078,0.052771,274.916901,14.004934,0.527709,-22.284956,0.052970,0.000000
77.910004,61.798561,-22.195995,0.018462,0.002078,0.052771,274.893738,14.003755,0.527709,-22.195995,0.052970,0.000000
78.110001,61.778824,-22.195995,0.018466,0.002078,0.052771,274.805939,13.999282,0.527709,-22.195995,0.052970,0.000000
78.310005,61.771378,-22.240475,0.018471,0.002078,0.052771,274.772797,13.997594,0.527709,-22.240475,0.052970,0.000000
78.510002,61.765045,-22.284956,0.018471,0.002078,0.052771,274.744629,13.996160,0.527709,-22.284956,0.052970,0.000000
78.710007,61.745682,-22.240475,0.018453,0.002078,0.052771,274.658508,13.991772,0.527709,-22.240475,0.052970,0.000000
78.910004,61.737862,-22.240475,0.018466,0.002078,0.052771,274.623718,13.990000,0.527709,-22.240475,0.052970,0.000000
79.110001,61.734886,-22.240475,0.018479,0.002078,0.052771,274.610474,13.989326,0.527709,-22.240475,0.052970,0.000000
79.310005,61.730415,-22.195995,0.018466,0.002078,0.052771,274.590607,13.988312,0.527709,-22.195995,0.052970,0.000000
79.510002,61.705093,-22.240475,0.018445,0.002078,0.052771,274.477966,13.982574,0.527709,-22.240475,0.052970,0.000000
79.710007,61.705467,-22.240475,0.018453,0.002078,0.052771,274.479614,13.982659,0.527709,-22.240475,0.052970,0.000000
79.910004,61.682007,-22.240475,0.018458,0.002078,0.052771,274.375275,13.977343,0.527709,-22.240475,0.052970,0.000000
80.110001,61.698761,-22.284956,0.018462,0.002078,0.052771,274.449799,13.981139,0.527709,-22.284956,0.052970,0.000000
80.310005,61.687592,-22.240475,0.018471,0.002078,0.052771,274.400116,13.978608,0.527709,-22.240475,0.052970,0.000000
80.510002,61.670090,-22.240475,0.018462,0.002078,0.052771,274.322266,13.974642,0.527709,-22.240475,0.052970,0.000000
80.710007,61.654076,-22.284956,0.018471,0.002078,0.052771,274.251038,13.971013,0.527709,-22.284956,0.052970,0.000000
80.910004,61.638809,-22.240475,0.018488,0.002078,0.052771,274.183105,13.967553,0.527709,-22.240475,0.052970,0.000000
81.110001,61.634712,-22.284956,0.018466,0.002078,0.052771,274.164886,13.966625,0.527709,-22.284956,0.052970,0.000000
81.310005,61.623169,-22.240475,0.018475,0.002078,0.052771,274.113556,13.964009,0.527709,-22.240475,0.052970,0.000000
81.510002,61.614609,-22.329437,0.018458,0.002078,0.052771,274.075470,13.962070,0.527709,-22.329437,0.052970,0.000000
81.710007,61.602692,-22.284956,0.018471,0.002078,0.052771,274.022461,13.959370,0.527709,-22.284956,0.052970,0.000000
81.910004,61.613861,-22.284956,0.018483,0.002078,0.052771,274.072144,13.961901,0.527709,-22.284956,0.052970,0.000000
82.110001,61.600082,-22.329437,0.018466,0.002078,0.052771,274.010864,13.958778,0.527709,-22.329437,0.052970,0.000000
82.310005,61.579231,-22.284956,0.018479,0.002078,0.052771,273.918091,13.954053,0.527709,-22.284956,0.052970,0.000000
82.510002,61.563591,-22.329437,0.018492,0.002078,0.052771,273.848541,13.950509,0.527709,-22.329437,0.052970,0.000000
82.710007,61.560616,-22.284956,0.018488,0.002078,0.052771,273.835297,13.949835,0.527709,-22.284956,0.052970,0.000000
82.910004,61.559120,-22.284956,0.018479,0.002078,0.052771,273.828644,13.949495,0.527709,-22.284956,0.052970,0.000000
83.110001,61.540504,-22.329437,0.018471,0.002078,0.052771,273.745850,13.945278,0.527709,-22.329437,0.052970,0.000000
83.310005,61.534172,-22.284956,0.018496,0.002078,0.052771,273.717682,13.943843,0.527709,-22.284956,0.052970,0.000000
83.510002,61.522255,-22.329437,0.018466,0.002078,0.052771,273.664673,13.941143,0.527709,-22.329437,0.052970,0.000000
83.600006,61.520027,-22.418400,0.018458,0.002078,0.052771,273.654755,13.940638,0.527709,-22.418400,0.052970,0.000000