File: Data/I-18 Lathed test 5_10242023_165935.csv
Time (sec),S:Load (lbs),S:HL1 (DIM),S:LVDT (in),S:Position (in),Ch:Position (mm),Ch:Load (N),Ch:Stress (MPa),Ch:Strain (mm/mm),Ch:HL1 (DIM),Set Point (),Cycles ()
0.110000,-0.080063,-27.222342,0.005902,-0.010397,-0.264088,-0.356137,-0.018143,-2.640876,-27.222342,-0.263879,0.000000
0.300000,-0.086395,-27.133381,0.005898,-0.010397,-0.264088,-0.384305,-0.019577,-2.640876,-27.133381,-0.263879,0.000000
0.490000,-0.086769,-27.088900,0.005898,-0.010336,-0.262535,-0.385968,-0.019662,-2.625355,-27.088900,-0.261954,0.000000
0.680000,-0.071869,-27.222342,0.005902,-0.010234,-0.259934,-0.319689,-0.016286,-2.599337,-27.222342,-0.258780,0.000000
0.870000,-0.066284,-27.222342,0.006032,-0.010111,-0.256820,-0.294847,-0.015020,-2.568203,-27.222342,-0.255623,0.000000
1.060000,-0.063309,-27.222342,0.006144,-0.009986,-0.253646,-0.281611,-0.014346,-2.536463,-27.222342,-0.252449,0.000000
1.250000,-0.070381,-27.222342,0.006295,-0.009862,-0.250490,-0.313071,-0.015949,-2.504896,-27.222342,-0.249293,0.000000
1.440000,-0.081177,-27.222342,0.006407,-0.009734,-0.247237,-0.361092,-0.018395,-2.472373,-27.222342,-0.246119,0.000000
1.630000,-0.097939,-27.222342,0.006562,-0.009608,-0.244038,-0.435652,-0.022193,-2.440375,-27.222342,-0.242962,0.000000
1.820000,-0.101288,-27.133381,0.006700,-0.009484,-0.240889,-0.450551,-0.022952,-2.408893,-27.133381,-0.239788,0.000000
2.010000,-0.094955,-27.222342,0.006817,-0.009360,-0.237733,-0.422383,-0.021517,-2.377326,-27.222342,-0.236631,0.000000
2.200000,-0.098312,-27.222342,0.006959,-0.009234,-0.234541,-0.437315,-0.022278,-2.345412,-27.222342,-0.233457,0.000000
2.390000,-0.091232,-27.222342,0.007092,-0.009109,-0.231359,-0.405822,-0.020674,-2.313585,-27.222342,-0.230301,0.000000
2.580000,-0.098679,-27.266823,0.007226,-0.008987,-0.228262,-0.438944,-0.022361,-2.282625,-27.266823,-0.227127,0.000000
2.770000,-0.085648,-27.177860,0.007343,-0.008863,-0.225123,-0.380979,-0.019408,-2.251233,-27.177860,-0.223970,0.000000
2.960000,-0.084900,-27.222342,0.007480,-0.008737,-0.221914,-0.377654,-0.019239,-2.219145,-27.222342,-0.220796,0.000000
3.150000,-0.103149,-27.266823,0.007610,-0.008612,-0.218740,-0.458832,-0.023374,-2.187404,-27.266823,-0.217639,0.000000
3.340000,-0.081177,-27.177860,0.007731,-0.008483,-0.215462,-0.361092,-0.018395,-2.154623,-27.177860,-0.214465,0.000000
3.530000,-0.090492,-27.311304,0.007864,-0.008358,-0.212297,-0.402530,-0.020506,-2.122970,-27.311304,-0.211308,0.000000
3.720000,-0.091606,-27.177860,0.008019,-0.008232,-0.209097,-0.407484,-0.020758,-2.090969,-27.177860,-0.208134,0.000000
3.910000,-0.106873,-27.222342,0.008114,-0.008108,-0.205949,-0.475393,-0.024218,-2.059486,-27.222342,-0.204977,0.000000
4.100000,-0.100540,-27.311304,0.008248,-0.007986,-0.202844,-0.447225,-0.022783,-2.028443,-27.311304,-0.201803,0.000000
4.290000,-0.116180,-27.177860,0.008377,-0.007864,-0.199748,-0.516796,-0.026327,-1.997482,-27.177860,-0.198647,0.000000
4.480000,-0.136292,-27.311304,0.008515,-0.007740,-0.196609,-0.606255,-0.030884,-1.966086,-27.311304,-0.195473,0.000000
4.670000,-0.137405,-27.222342,0.008636,-0.007613,-0.193374,-0.611210,-0.031137,-1.933741,-27.222342,-0.192316,0.000000
4.860000,-0.119904,-27.266823,0.008783,-0.007494,-0.190347,-0.533358,-0.027171,-1.903473,-27.266823,-0.189142,0.000000
5.050000,-0.104263,-27.311304,0.008903,-0.007367,-0.187121,-0.463786,-0.023626,-1.871214,-27.311304,-0.185985,0.000000
5.240000,-0.108734,-27.266823,0.009033,-0.007240,-0.183895,-0.483674,-0.024640,-1.838952,-27.266823,-0.182811,0.000000
5.430000,-0.106133,-27.355785,0.009184,-0.007115,-0.180712,-0.472101,-0.024050,-1.807125,-27.355785,-0.179655,0.000000
5.620000,-0.107246,-27.266823,0.009304,-0.006989,-0.177530,-0.477056,-0.024302,-1.775297,-27.266823,-0.176481,0.000000
5.810000,-0.086769,-27.311304,0.009434,-0.006867,-0.174417,-0.385968,-0.019662,-1.744167,-27.311304,-0.173324,0.000000
6.000000,-0.105385,-27.311304,0.009563,-0.006742,-0.171251,-0.468775,-0.023881,-1.712510,-27.311304,-0.170150,0.000000
6.190000,-0.101662,-27.266823,0.009688,-0.006615,-0.168025,-0.452214,-0.023037,-1.680251,-27.266823,-0.166993,0.000000
6.380000,-0.118416,-27.311304,0.009839,-0.006490,-0.164851,-0.526740,-0.026833,-1.648511,-27.311304,-0.163819,0.000000
6.570000,-0.105385,-27.266823,0.009973,-0.006363,-0.161625,-0.468775,-0.023881,-1.616249,-27.266823,-0.160662,0.000000
6.760000,-0.113205,-27.266823,0.010111,-0.006239,-0.158460,-0.503561,-0.025653,-1.584595,-27.266823,-0.157488,0.000000
6.950000,-0.087883,-27.311304,0.010248,-0.006112,-0.155251,-0.390923,-0.019915,-1.552507,-27.311304,-0.154331,0.000000
7.140000,-0.065536,-27.311304,0.010365,-0.005995,-0.152267,-0.291521,-0.014851,-1.522675,-27.311304,-0.151157,0.000000
7.330000,-0.074104,-27.355785,0.010503,-0.005866,-0.148998,-0.329632,-0.016792,-1.489981,-27.355785,-0.148001,0.000000
7.520000,-0.054741,-27.355785,0.010645,-0.005737,-0.145720,-0.243500,-0.012404,-1.457200,-27.355785,-0.144827,0.000000
7.710001,-0.063675,-27.311304,0.010774,-0.005612,-0.142555,-0.283240,-0.014429,-1.425547,-27.311304,-0.141670,0.000000
7.900001,-0.071495,-27.400267,0.010895,-0.005489,-0.139415,-0.318026,-0.016201,-1.394151,-27.400267,-0.138496,0.000000
8.090000,-0.084534,-27.311304,0.011046,-0.005366,-0.136302,-0.376025,-0.019156,-1.363020,-27.311304,-0.135339,0.000000
8.280001,-0.086769,-27.400267,0.011167,-0.005241,-0.133128,-0.385968,-0.019662,-1.331280,-27.400267,-0.132165,0.000000
8.470000,-0.088631,-27.311304,0.011326,-0.005117,-0.129962,-0.394249,-0.020084,-1.299623,-27.311304,-0.129009,0.000000
8.660001,-0.080811,-27.355785,0.011421,-0.004995,-0.126884,-0.359463,-0.018312,-1.268837,-27.355785,-0.125835,0.000000
8.850000,-0.083786,-27.311304,0.011525,-0.004874,-0.123788,-0.372699,-0.018986,-1.237880,-27.311304,-0.122678,0.000000
9.040000,-0.090492,-27.311304,0.011689,-0.004750,-0.120648,-0.402530,-0.020506,-1.206484,-27.311304,-0.119504,0.000000
9.230000,-0.065170,-27.355785,0.011818,-0.004624,-0.117457,-0.289892,-0.014768,-1.174570,-27.355785,-0.116347,0.000000
9.420000,-0.064049,-27.311304,0.011930,-0.004506,-0.114456,-0.284903,-0.014514,-1.144564,-27.311304,-0.113173,0.000000
9.610001,-0.042824,-27.400267,0.012064,-0.004382,-0.111291,-0.190490,-0.009704,-1.112911,-27.400267,-0.110016,0.000000
9.800000,-0.055862,-27.355785,0.012197,-0.004258,-0.108143,-0.248488,-0.012659,-1.081432,-27.355785,-0.106842,0.000000
9.990001,-0.058838,-27.355785,0.012335,-0.004130,-0.104908,-0.261724,-0.013333,-1.049082,-27.355785,-0.103686,0.000000
10.180000,-0.048782,-27.444746,0.012473,-0.004005,-0.101717,-0.216995,-0.011054,-1.017168,-27.444746,-0.100512,0.000000
10.370001,-0.054741,-27.444746,0.012594,-0.003878,-0.098491,-0.243500,-0.012404,-0.984909,-27.444746,-0.097355,0.000000
10.560000,-0.048409,-27.400267,0.012745,-0.003752,-0.095299,-0.215332,-0.010970,-0.952995,-27.400267,-0.094181,0.000000
10.750001,-0.067772,-27.400267,0.012866,-0.003627,-0.092134,-0.301465,-0.015357,-0.921342,-27.400267,-0.091024,0.000000
10.940001,-0.071129,-27.311304,0.012999,-0.003505,-0.089029,-0.316397,-0.016118,-0.890294,-27.311304,-0.087850,0.000000
11.130000,-0.066658,-27.444746,0.013129,-0.003382,-0.085890,-0.296510,-0.015105,-0.858902,-27.444746,-0.084693,0.000000
11.320001,-0.069267,-27.355785,0.013275,-0.003255,-0.082673,-0.308116,-0.015696,-0.826727,-27.355785,-0.081519,0.000000
11.510000,-0.072617,-27.400267,0.013405,-0.003130,-0.079507,-0.323015,-0.016455,-0.795074,-27.400267,-0.078362,0.000000
11.700001,-0.068146,-27.400267,0.013534,-0.003006,-0.076359,-0.303127,-0.015442,-0.763591,-27.400267,-0.075188,0.000000
11.890000,-0.069633,-27.400267,0.013663,-0.002876,-0.073055,-0.309745,-0.015779,-0.730553,-27.400267,-0.072032,0.000000
12.080001,-0.073730,-27.444746,0.013823,-0.002751,-0.069881,-0.327969,-0.016708,-0.698813,-27.444746,-0.068858,0.000000
12.270000,-0.052132,-27.400267,0.013931,-0.002626,-0.066690,-0.231893,-0.011813,-0.666898,-27.400267,-0.065701,0.000000
12.460001,-0.083038,-27.400267,0.014068,-0.002502,-0.063559,-0.369373,-0.018817,-0.635590,-27.400267,-0.062527,0.000000
12.650001,-0.073730,-27.444746,0.014176,-0.002379,-0.060420,-0.327969,-0.016708,-0.604198,-27.444746,-0.059370,0.000000
12.840000,-0.080437,-27.400267,0.014323,-0.002255,-0.057280,-0.357800,-0.018227,-0.572802,-27.400267,-0.056196,0.000000
13.030001,-0.083412,-27.444746,0.014435,-0.002133,-0.054184,-0.371036,-0.018901,-0.541842,-27.444746,-0.053040,0.000000
13.220000,-0.098679,-27.444746,0.014590,-0.002007,-0.050984,-0.438944,-0.022361,-0.509844,-27.444746,-0.049866,0.000000
13.410001,-0.096077,-27.444746,0.014711,-0.001881,-0.047784,-0.427372,-0.021771,-0.477843,-27.444746,-0.046709,0.000000
13.600000,-0.080063,-27.489227,0.014849,-0.001758,-0.044662,-0.356137,-0.018143,-0.446621,-27.489227,-0.043535,0.000000
13.790001,-0.088631,-27.489227,0.014987,-0.001634,-0.041506,-0.394249,-0.020084,-0.415055,-27.489227,-0.040378,0.000000
13.980000,-0.081551,-27.489227,0.015095,-0.001507,-0.038279,-0.362755,-0.018480,-0.382793,-27.489227,-0.037204,0.000000
14.170001,-0.083038,-27.489227,0.015250,-0.001383,-0.035123,-0.369373,-0.018817,-0.351227,-27.489227,-0.034047,0.000000
14.360001,-0.059952,-27.444746,0.015371,-0.001259,-0.031966,-0.266679,-0.013585,-0.319661,-27.444746,-0.030873,0.000000
14.550001,-0.084900,-27.533709,0.015504,-0.001135,-0.028835,-0.377654,-0.019239,-0.288352,-27.533709,-0.027716,0.000000
14.740001,-0.092720,-27.444746,0.015634,-0.001010,-0.025644,-0.412439,-0.021011,-0.256438,-27.444746,-0.024542,0.000000
14.930000,-0.096817,-27.533709,0.015767,-0.000885,-0.022487,-0.430664,-0.021939,-0.224872,-27.533709,-0.021386,0.000000
15.120001,-0.106499,-27.489227,0.015897,-0.000759,-0.019278,-0.473730,-0.024133,-0.192784,-27.489227,-0.018212,0.000000
15.310000,-0.108360,-27.444746,0.016030,-0.000634,-0.016113,-0.482011,-0.024555,-0.161131,-27.444746,-0.015055,0.000000
15.500001,-0.090858,-27.489227,0.016168,-0.000509,-0.012930,-0.404159,-0.020589,-0.129303,-27.489227,-0.011881,0.000000
15.690001,-0.042450,-27.489227,0.016302,-0.000389,-0.009869,-0.188827,-0.009619,-0.098691,-27.489227,-0.008724,0.000000
15.880001,-0.042824,-27.489227,0.016440,-0.000261,-0.006626,-0.190490,-0.009704,-0.066258,-27.489227,-0.005550,0.000000
16.070002,0.030159,-27.578190,0.016573,-0.000132,-0.003365,0.134154,0.006834,-0.033648,-27.578190,-0.002394,0.000000
16.260000,0.241295,-27.578190,0.016677,-0.000009,-0.000234,1.073333,0.054678,-0.002343,-27.578190,0.000780,0.000000
16.450001,0.786446,-27.533709,0.016806,0.000094,0.002394,3.498285,0.178211,0.023936,-27.533709,0.003486,0.000000
16.640001,0.744743,-27.533709,0.016811,-0.000000,-0.000008,3.312784,0.168761,-0.000083,-27.533709,0.000174,0.000000
16.830000,0.730217,-27.489227,0.016819,-0.000001,-0.000017,3.248167,0.165470,-0.000170,-27.489227,0.000174,0.000000
17.020000,0.725380,-27.489227,0.016824,-0.000001,-0.000017,3.226651,0.164373,-0.000170,-27.489227,0.000252,0.000000
17.210001,0.716072,-27.578190,0.016836,-0.000001,-0.000017,3.185248,0.162264,-0.000170,-27.578190,0.000573,0.000000
17.400002,0.741394,-27.533709,0.016819,-0.000000,-0.000008,3.297885,0.168002,-0.000083,-27.533709,0.000893,0.000000
17.590000,0.806183,-27.489227,0.016828,0.000015,0.000382,3.586081,0.182684,0.003819,-27.489227,0.001205,0.000000
17.780001,0.897415,-27.533709,0.016836,0.000029,0.000729,3.991902,0.203357,0.007286,-27.533709,0.001526,0.000000
17.970001,0.997581,-27.533709,0.016841,0.000038,0.000972,4.437464,0.226055,0.009716,-27.533709,0.001839,0.000000
18.160002,1.142807,-27.533709,0.016880,0.000055,0.001388,5.083459,0.258964,0.013875,-27.533709,0.002160,0.000000
18.350000,1.293991,-27.578190,0.016867,0.000067,0.001709,5.755960,0.293223,0.017085,-27.578190,0.002472,0.000000
18.540001,1.393784,-27.622671,0.016884,0.000077,0.001960,6.199859,0.315836,0.019602,-27.622671,0.002792,0.000000
18.730001,1.480919,-27.622671,0.016910,0.000086,0.002194,6.587456,0.335581,0.021941,-27.622671,0.003105,0.000000
18.920000,1.612740,-27.533709,0.016905,0.000095,0.002402,7.173824,0.365452,0.024023,-27.533709,0.003426,0.000000
19.110001,1.794830,-27.622671,0.016914,0.000110,0.002801,7.983804,0.406714,0.028012,-27.622671,0.003738,0.000000
19.300001,1.993309,-27.622671,0.016923,0.000125,0.003183,8.866681,0.451690,0.031827,-27.622671,0.004059,0.000000
19.490002,2.122894,-27.578190,0.016953,0.000135,0.003417,9.443106,0.481055,0.034170,-27.578190,0.004371,0.000000
19.680000,2.266632,-27.622671,0.016953,0.000144,0.003669,10.082483,0.513626,0.036687,-27.622671,0.004692,0.000000
19.870001,2.476646,-27.622671,0.016957,0.000159,0.004050,11.016673,0.561216,0.040502,-27.622671,0.005004,0.000000
20.060001,2.668419,-27.622671,0.016970,0.000172,0.004362,11.869720,0.604672,0.043625,-27.622671,0.005325,0.000000
20.250002,2.966316,-27.622671,0.016996,0.000189,0.004805,13.194834,0.672177,0.048045,-27.622671,0.005637,0.000000
20.440001,3.106331,-27.578190,0.016992,0.000196,0.004987,13.817650,0.703905,0.049866,-27.578190,0.005958,0.000000
20.630001,3.286560,-27.667152,0.016992,0.000208,0.005290,14.619349,0.744745,0.052901,-27.667152,0.006270,0.000000
20.820002,3.537910,-27.578190,0.017005,0.000220,0.005585,15.737411,0.801702,0.055850,-27.578190,0.006591,0.000000
21.010000,3.912888,-27.578190,0.017030,0.000240,0.006097,17.405394,0.886673,0.060967,-27.578190,0.006903,0.000000
21.200001,4.129982,-27.667152,0.017052,0.000251,0.006374,18.371077,0.935867,0.063741,-27.667152,0.007224,0.000000
21.390001,4.371651,-27.533709,0.017048,0.000263,0.006686,19.446074,0.990630,0.066864,-27.533709,0.007536,0.000000
21.580002,4.598801,-27.667152,0.017061,0.000275,0.006990,20.456488,1.042103,0.069899,-27.667152,0.007857,0.000000
21.770000,4.845680,-27.578190,0.017065,0.000287,0.007293,21.554663,1.098047,0.072935,-27.578190,0.008169,0.000000
21.960001,5.092194,-27.622671,0.017082,0.000296,0.007528,22.651209,1.153908,0.075278,-27.622671,0.008490,0.000000
22.150002,5.478714,-27.711632,0.017091,0.000312,0.007935,24.370537,1.241494,0.079354,-27.711632,0.008803,0.000000
22.340000,5.657082,-27.622671,0.017112,0.000323,0.008195,25.163956,1.281913,0.081954,-27.622671,0.009123,0.000000
22.530001,5.905449,-27.667152,0.017117,0.000333,0.008455,26.268749,1.338194,0.084555,-27.667152,0.009436,0.000000
22.720001,6.249153,-27.622671,0.017138,0.000347,0.008811,27.797621,1.416078,0.088112,-27.622671,0.009756,0.000000
22.910002,6.535133,-27.667152,0.017130,0.000359,0.009115,29.069725,1.480882,0.091148,-27.667152,0.010077,0.000000
23.100000,7.054596,-27.711632,0.017156,0.000378,0.009609,31.380409,1.598594,0.096091,-27.711632,0.010390,0.000000
23.290001,7.313019,-27.622671,0.017168,0.000390,0.009904,32.529934,1.657154,0.099039,-27.622671,0.010710,0.000000
23.480001,7.516335,-27.711632,0.017168,0.000399,0.010147,33.434326,1.703226,0.101465,-27.711632,0.011023,0.000000
23.670002,7.774017,-27.667152,0.017190,0.000411,0.010433,34.580555,1.761618,0.104331,-27.667152,0.011343,0.000000
23.860001,8.135216,-27.711632,0.017181,0.000422,0.010728,36.187248,1.843466,0.107279,-27.711632,0.011656,0.000000
24.050001,8.280815,-27.756113,0.017194,0.000433,0.010997,36.834904,1.876460,0.109966,-27.756113,0.011977,0.000000
24.240002,8.752243,-27.711632,0.017181,0.000446,0.011335,38.931923,1.983287,0.113346,-27.711632,0.012289,0.000000
24.430000,9.144348,-27.711632,0.017207,0.000460,0.011682,40.676090,2.072139,0.116817,-27.711632,0.012610,0.000000
24.620001,9.365906,-27.711632,0.017229,0.000469,0.011925,41.661629,2.122344,0.119247,-27.711632,0.012922,0.000000
24.810001,9.690994,-27.711632,0.017237,0.000481,0.012220,43.107697,2.196011,0.122195,-27.711632,0.013243,0.000000
25.000002,10.097992,-27.800594,0.017250,0.000496,0.012610,44.918110,2.288238,0.126098,-27.800594,0.013555,0.000000
25.190001,10.688950,-27.667152,0.017259,0.000516,0.013113,47.546822,2.422151,0.131128,-27.667152,0.013876,0.000000
25.380001,10.923912,-27.756113,0.017268,0.000526,0.013373,48.591988,2.475394,0.133728,-27.756113,0.014188,0.000000
25.570002,11.053131,-27.667152,0.017298,0.000536,0.013624,49.166782,2.504675,0.136241,-27.667152,0.014509,0.000000
25.760002,11.416191,-27.711632,0.017293,0.000546,0.013876,50.781754,2.586946,0.138758,-27.711632,0.014821,0.000000
25.950001,11.692490,-27.756113,0.017298,0.000556,0.014127,52.010792,2.649556,0.141271,-27.756113,0.015142,0.000000
26.140001,12.236900,-27.711632,0.017302,0.000573,0.014561,54.432449,2.772921,0.145609,-27.711632,0.015454,0.000000
26.330002,12.474846,-27.756113,0.017319,0.000584,0.014838,55.490887,2.826840,0.148383,-27.756113,0.015775,0.000000
26.520000,12.664383,-27.756113,0.017328,0.000592,0.015046,56.333988,2.869790,0.150465,-27.756113,0.016087,0.000000
26.710001,13.161873,-27.756113,0.017341,0.000609,0.015472,58.546936,2.982523,0.154715,-27.756113,0.016408,0.000000
26.900002,13.403915,-27.800594,0.017358,0.000619,0.015723,59.623592,3.037371,0.157228,-27.800594,0.016720,0.000000
27.090002,14.030991,-27.756113,0.017371,0.000639,0.016243,62.412964,3.179468,0.162433,-27.756113,0.017041,0.000000
27.280001,14.324425,-27.800594,0.017388,0.000652,0.016556,63.718224,3.245961,0.165555,-27.800594,0.017353,0.000000
27.470001,14.327774,-27.756113,0.017414,0.000659,0.016729,63.733124,3.246720,0.167289,-27.756113,0.017674,0.000000
27.660002,14.724350,-27.756113,0.017410,0.000671,0.017041,65.497177,3.336585,0.170411,-27.756113,0.017987,0.000000
27.850000,15.098953,-27.800594,0.017419,0.000684,0.017362,67.163498,3.421472,0.173621,-27.800594,0.018307,0.000000
28.040001,15.556229,-27.800594,0.017419,0.000699,0.017761,69.197563,3.525092,0.177610,-27.800594,0.018619,0.000000
28.230001,15.675758,-27.800594,0.017423,0.000706,0.017943,69.729256,3.552178,0.179431,-27.800594,0.018940,0.000000
28.420002,15.886520,-27.756113,0.017453,0.000716,0.018177,70.666771,3.599937,0.181773,-27.756113,0.019261,0.000000
28.610001,16.183304,-27.800594,0.017444,0.000726,0.018446,71.986931,3.667189,0.184461,-27.800594,0.019574,0.000000
28.800001,16.648026,-27.800594,0.017470,0.000743,0.018871,74.054115,3.772496,0.188711,-27.800594,0.019894,0.000000
28.990002,17.200996,-27.756113,0.017449,0.000764,0.019409,76.513855,3.897801,0.194086,-27.756113,0.020206,0.000000
29.180002,17.629227,-27.845076,0.017488,0.000778,0.019773,78.418716,3.994840,0.197730,-27.845076,0.020527,0.000000
29.370001,17.528687,-27.845076,0.017483,0.000784,0.019920,77.971489,3.972057,0.199203,-27.845076,0.020840,0.000000
29.560001,17.781158,-27.800594,0.017518,0.000796,0.020224,79.094543,4.029268,0.202238,-27.800594,0.021161,0.000000
29.750002,17.973671,-27.845076,0.017518,0.000809,0.020536,79.950882,4.072892,0.205361,-27.845076,0.021473,0.000000
29.940001,18.473022,-27.800594,0.017535,0.000820,0.020831,82.172112,4.186047,0.208309,-27.800594,0.021793,0.000000
30.130001,18.795494,-27.889557,0.017548,0.000833,0.021161,83.606537,4.259120,0.211606,-27.889557,0.022106,0.000000
30.320002,19.006630,-27.800594,0.017548,0.000844,0.021447,84.545715,4.306964,0.214467,-27.800594,0.022427,0.000000
30.510002,19.036049,-27.845076,0.017539,0.000852,0.021629,84.676575,4.313631,0.216288,-27.845076,0.022739,0.000000
30.700001,19.521996,-27.845076,0.017557,0.000869,0.022063,86.838173,4.423748,0.220625,-27.845076,0.023060,0.000000
30.890001,19.870163,-27.800594,0.017595,0.000880,0.022349,88.386902,4.502644,0.223487,-27.800594,0.023372,0.000000
31.080002,19.930115,-27.889557,0.017595,0.000888,0.022566,88.653580,4.516228,0.225655,-27.889557,0.023693,0.000000
31.270002,20.426491,-27.889557,0.017595,0.000907,0.023034,90.861572,4.628709,0.230337,-27.889557,0.024005,0.000000
31.460001,20.708000,-27.889557,0.017613,0.000919,0.023346,92.113785,4.692500,0.233460,-27.889557,0.024326,0.000000
31.650002,21.007393,-27.845076,0.017634,0.000931,0.023658,93.445549,4.760343,0.236582,-27.845076,0.024638,0.000000
31.840002,21.443062,-27.889557,0.017634,0.000948,0.024083,95.383499,4.859067,0.240829,-27.889557,0.024959,0.000000
32.030003,21.510094,-27.889557,0.017638,0.000958,0.024335,95.681679,4.874257,0.243346,-27.889557,0.025271,0.000000
32.220001,21.612869,-27.845076,0.017660,0.000967,0.024560,96.138847,4.897546,0.245598,-27.845076,0.025592,0.000000
32.410000,21.917465,-27.845076,0.017664,0.000980,0.024889,97.493752,4.966568,0.248895,-27.845076,0.025904,0.000000
32.600002,22.039604,-27.889557,0.017673,0.000988,0.025089,98.037056,4.994246,0.250889,-27.889557,0.026225,0.000000
32.790001,22.579918,-27.889557,0.017690,0.001007,0.025566,100.440491,5.116683,0.255658,-27.889557,0.026537,0.000000
32.980003,23.166779,-27.934038,0.017703,0.001024,0.026008,103.050980,5.249667,0.260083,-27.934038,0.026858,0.000000
33.170002,23.234177,-27.845076,0.017712,0.001034,0.026260,103.350777,5.264940,0.262596,-27.845076,0.027170,0.000000
33.360001,23.403236,-27.934038,0.017725,0.001045,0.026546,104.102798,5.303249,0.265461,-27.934038,0.027491,0.000000
33.550003,23.695915,-27.934038,0.017742,0.001058,0.026884,105.404694,5.369571,0.268841,-27.934038,0.027803,0.000000
33.740002,23.712677,-27.934038,0.017755,0.001067,0.027101,105.479256,5.373369,0.271010,-27.934038,0.028124,0.000000
33.930000,24.177773,-28.022999,0.017755,0.001082,0.027483,107.548103,5.478762,0.274825,-28.022999,0.028445,0.000000
34.120003,24.366562,-27.889557,0.017755,0.001092,0.027725,108.387878,5.521542,0.277255,-27.889557,0.028757,0.000000
34.310001,24.600410,-27.934038,0.017789,0.001102,0.028003,109.428093,5.574533,0.280029,-27.934038,0.029078,0.000000
34.500000,24.779526,-27.934038,0.017776,0.001112,0.028237,110.224838,5.615121,0.282372,-27.934038,0.029390,0.000000
34.690002,25.760727,-27.934038,0.017802,0.001137,0.028887,114.589439,5.837464,0.288875,-27.934038,0.029711,0.000000
34.880001,26.153206,-27.934038,0.017820,0.001152,0.029252,116.335266,5.926401,0.292516,-27.934038,0.030024,0.000000
35.070004,26.159164,-27.934038,0.017841,0.001162,0.029521,116.361778,5.927751,0.295207,-27.934038,0.030344,0.000000
35.260002,26.246674,-27.978518,0.017824,0.001174,0.029824,116.751038,5.947581,0.298242,-27.978518,0.030657,0.000000
35.450001,26.514404,-27.934038,0.017841,0.001186,0.030128,117.941963,6.008250,0.301278,-27.934038,0.030977,0.000000
35.640003,26.716606,-27.978518,0.017867,0.001198,0.030431,118.841400,6.054070,0.304309,-27.978518,0.031290,0.000000
35.830002,27.322830,-27.978518,0.017893,0.001212,0.030787,121.538017,6.191442,0.307867,-27.978518,0.031611,0.000000
36.020000,27.365280,-27.934038,0.017880,0.001221,0.031012,121.726845,6.201061,0.310123,-27.934038,0.031923,0.000000
36.210003,27.513855,-27.934038,0.017880,0.001230,0.031246,122.387741,6.234729,0.312462,-27.934038,0.032244,0.000000
36.400002,27.711586,-27.978518,0.017897,0.001239,0.031480,123.267288,6.279535,0.314805,-27.978518,0.032556,0.000000
36.590000,28.784760,-27.934038,0.017919,0.001264,0.032105,128.041000,6.522719,0.321050,-27.934038,0.032877,0.000000
36.780003,29.126602,-28.022999,0.017914,0.001276,0.032409,129.561600,6.600183,0.324085,-28.022999,0.033189,0.000000
36.970001,29.170914,-27.934038,0.017953,0.001285,0.032634,129.758698,6.610224,0.326337,-27.934038,0.033510,0.000000
37.160004,29.605843,-28.022999,0.017945,0.001298,0.032981,131.693359,6.708780,0.329808,-28.022999,0.033822,0.000000
37.350002,29.818840,-27.978518,0.017970,0.001309,0.033241,132.640823,6.757046,0.332408,-27.978518,0.034143,0.000000
37.540001,30.097000,-28.022999,0.017970,0.001321,0.033553,133.878143,6.820077,0.335531,-28.022999,0.034455,0.000000
37.730003,30.711044,-28.022999,0.017992,0.001337,0.033961,136.609543,6.959222,0.339607,-28.022999,0.034776,0.000000
37.920002,30.829460,-27.978518,0.017996,0.001345,0.034160,137.136292,6.986055,0.341602,-27.978518,0.035088,0.000000
38.110001,30.993301,-27.978518,0.017992,0.001355,0.034412,137.865097,7.023182,0.344115,-27.978518,0.035409,0.000000
38.300003,31.331047,-28.022999,0.018018,0.001365,0.034672,139.367462,7.099717,0.346719,-28.022999,0.035721,0.000000
38.490002,32.364380,-27.978518,0.018005,0.001388,0.035253,143.963959,7.333873,0.352529,-27.978518,0.036042,0.000000
38.680000,32.783669,-28.067480,0.018022,0.001400,0.035556,145.829041,7.428885,0.355564,-28.067480,0.036354,0.000000
38.870003,32.904320,-28.111961,0.018048,0.001408,0.035773,146.365723,7.456225,0.357733,-28.111961,0.036675,0.000000
39.060001,33.177269,-28.067480,0.018057,0.001421,0.036086,147.579865,7.518077,0.360856,-28.067480,0.036988,0.000000
39.250000,33.617409,-28.067480,0.018065,0.001433,0.036397,149.537704,7.617814,0.363974,-28.067480,0.037308,0.000000
39.440002,34.131660,-28.022999,0.018057,0.001447,0.036753,151.825211,7.734345,0.367532,-28.022999,0.037629,0.000000
39.630001,34.751656,-28.067480,0.018087,0.001462,0.037126,154.583084,7.874838,0.371260,-28.067480,0.037941,0.000000
39.820004,34.829857,-28.022999,0.018074,0.001470,0.037325,154.930939,7.892559,0.373255,-28.022999,0.038262,0.000000
40.010002,35.246910,-28.111961,0.018083,0.001480,0.037594,156.786087,7.987064,0.375942,-28.111961,0.038575,0.000000
40.200001,35.442039,-28.111961,0.018091,0.001490,0.037855,157.654068,8.031281,0.378546,-28.111961,0.038895,0.000000
40.390003,36.244499,-28.067480,0.018121,0.001507,0.038288,161.223587,8.213121,0.382880,-28.067480,0.039207,0.000000
40.580002,36.943817,-28.022999,0.018134,0.001522,0.038652,164.334305,8.371589,0.386525,-28.022999,0.039528,0.000000
40.770000,37.320656,-28.111961,0.018134,0.001532,0.038921,166.010574,8.456982,0.389212,-28.111961,0.039841,0.000000
40.960003,37.608124,-28.156443,0.018147,0.001543,0.039181,167.289291,8.522123,0.391812,-28.156443,0.040162,0.000000
41.150002,38.051620,-28.067480,0.018151,0.001555,0.039502,169.262054,8.622621,0.395022,-28.067480,0.040473,0.000000
41.340000,38.421387,-28.067480,0.018121,0.001569,0.039841,170.906860,8.706411,0.398406,-28.067480,0.040794,0.000000
41.530003,39.102455,-28.156443,0.018177,0.001582,0.040187,173.936401,8.860744,0.401873,-28.156443,0.041107,0.000000
41.720001,39.598831,-28.067480,0.018190,0.001592,0.040448,176.144394,8.973224,0.404477,-28.067480,0.041428,0.000000
41.910004,39.935829,-28.111961,0.018186,0.001605,0.040760,177.643448,9.049588,0.407599,-28.111961,0.041740,0.000000
42.100002,40.565506,-28.111961,0.018190,0.001617,0.041080,180.444382,9.192275,0.410805,-28.111961,0.042061,0.000000
42.290001,41.221260,-28.111961,0.018190,0.001633,0.041479,183.361328,9.340871,0.414794,-28.111961,0.042373,0.000000
42.480003,42.006966,-28.156443,0.018225,0.001648,0.041853,186.856308,9.518914,0.418526,-28.156443,0.042694,0.000000
42.670002,42.218842,-28.200924,0.018229,0.001657,0.042095,187.798782,9.566926,0.420952,-28.200924,0.043006,0.000000
42.860001,42.907730,-28.156443,0.018246,0.001671,0.042434,190.863113,9.723031,0.424336,-28.156443,0.043327,0.000000
43.050003,43.348991,-28.111961,0.018229,0.001682,0.042720,192.825943,9.823022,0.427197,-28.111961,0.043639,0.000000
43.240002,43.872917,-28.111961,0.018238,0.001695,0.043041,195.156479,9.941745,0.430407,-28.111961,0.043960,0.000000
43.430000,44.551384,-28.200924,0.018268,0.001707,0.043361,198.174454,10.095488,0.433613,-28.200924,0.044272,0.000000
43.620003,44.806458,-28.156443,0.018272,0.001716,0.043578,199.309082,10.153289,0.435781,-28.156443,0.044593,0.000000
43.810001,45.358688,-28.200924,0.018281,0.001729,0.043908,201.765518,10.278426,0.439078,-28.200924,0.044905,0.000000
44.000004,46.037148,-28.111961,0.018285,0.001741,0.044229,204.783463,10.432166,0.442288,-28.111961,0.045226,0.000000
44.190002,46.291855,-28.245403,0.018302,0.001749,0.044420,205.916458,10.489884,0.444195,-28.245403,0.045538,0.000000
44.380001,47.692345,-28.245403,0.018289,0.001773,0.045027,212.146149,10.807240,0.450266,-28.245403,0.045859,0.000000
44.570004,48.333946,-28.156443,0.018320,0.001786,0.045365,215.000137,10.952629,0.453646,-28.156443,0.046171,0.000000
44.760002,48.609871,-28.200924,0.018315,0.001794,0.045564,216.227509,11.015154,0.455641,-28.200924,0.046492,0.000000
44.950001,48.969955,-28.156443,0.018337,0.001805,0.045842,217.829239,11.096750,0.458419,-28.156443,0.046813,0.000000
45.140003,49.676720,-28.200924,0.018341,0.001818,0.046180,220.973083,11.256906,0.461799,-28.200924,0.047125,0.000000
45.330002,49.880775,-28.245403,0.018354,0.001824,0.046327,221.880768,11.303145,0.463275,-28.245403,0.047446,0.000000
45.520000,50.680260,-28.245403,0.018363,0.001841,0.046761,225.437057,11.484311,0.467609,-28.245403,0.047758,0.000000
45.710003,51.681198,-28.245403,0.018363,0.001855,0.047108,229.889450,11.711126,0.471079,-28.245403,0.048079,0.000000
45.900002,52.057297,-28.200924,0.018380,0.001865,0.047377,231.562424,11.796352,0.473767,-28.200924,0.048391,0.000000
46.090004,52.527229,-28.200924,0.018354,0.001875,0.047628,233.652786,11.902840,0.476284,-28.200924,0.048712,0.000000
46.280003,53.597801,-28.200924,0.018380,0.001892,0.048044,238.414932,12.145435,0.480443,-28.200924,0.049025,0.000000
46.470001,54.360794,-28.245403,0.018380,0.001908,0.048452,241.808884,12.318332,0.484520,-28.245403,0.049345,0.000000
46.660004,55.435455,-28.245403,0.018384,0.001922,0.048825,246.589218,12.561854,0.488251,-28.245403,0.049657,0.000000
46.850002,55.502487,-28.245403,0.018402,0.001927,0.048946,246.887390,12.577043,0.489463,-28.245403,0.049978,0.000000
47.040001,56.169029,-28.200924,0.018389,0.001940,0.049267,249.852325,12.728085,0.492672,-28.200924,0.050291,0.000000
47.230003,56.348885,-28.200924,0.018427,0.001950,0.049519,250.652359,12.768840,0.495189,-28.200924,0.050612,0.000000
47.420002,57.119324,-28.245403,0.018419,0.001964,0.049874,254.079437,12.943424,0.498743,-28.245403,0.050923,0.000000
47.610001,58.278893,-28.334366,0.018436,0.001978,0.050230,259.237457,13.206186,0.502297,-28.334366,0.051244,0.000000
47.800003,58.681427,-28.200924,0.018440,0.001985,0.050429,261.028015,13.297401,0.504292,-28.200924,0.051557,0.000000
47.990002,59.296959,-28.289885,0.018440,0.001999,0.050785,263.766052,13.436883,0.507850,-28.289885,0.051878,0.000000
48.180004,60.471794,-28.289885,0.018458,0.002015,0.051184,268.991974,13.703105,0.511839,-28.289885,0.052190,0.000000
48.370003,61.454857,-28.245403,0.018458,0.002031,0.051592,273.364868,13.925870,0.515915,-28.245403,0.052510,0.000000
48.560001,62.508675,-28.334366,0.018471,0.002046,0.051973,278.052460,14.164668,0.519730,-28.334366,0.052823,0.000000
48.750004,62.913437,-28.245403,0.018492,0.002054,0.052164,279.852936,14.256389,0.521638,-28.245403,0.053144,0.000000
48.940002,63.428436,-28.289885,0.018479,0.002066,0.052467,282.143768,14.373089,0.524674,-28.289885,0.053456,0.000000
49.130001,64.086792,-28.289885,0.018496,0.002077,0.052762,285.072296,14.522274,0.527622,-28.289885,0.053777,0.000000
49.320004,64.677002,-28.245403,0.018501,0.002090,0.053074,287.697662,14.656018,0.530744,-28.245403,0.054089,0.000000
49.510002,65.781830,-28.334366,0.018518,0.002103,0.053412,292.612183,14.906376,0.534124,-28.334366,0.054410,0.000000
49.700001,66.360489,-28.289885,0.018514,0.002113,0.053673,295.186188,15.037501,0.536728,-28.289885,0.054722,0.000000
49.890003,66.606262,-28.378847,0.018514,0.002122,0.053907,296.279449,15.093195,0.539067,-28.378847,0.055043,0.000000
50.080002,67.558411,-28.334366,0.018535,0.002125,0.053968,300.514832,15.308954,0.539677,-28.334366,0.054228,0.000000
50.270004,67.200195,-28.289885,0.018540,0.002125,0.053968,298.921387,15.227782,0.539677,-28.289885,0.054228,0.000000
50.460003,66.878830,-28.378847,0.018540,0.002123,0.053924,297.491882,15.154959,0.539242,-28.378847,0.053968,0.000000
50.650002,66.608871,-28.289885,0.018540,0.002120,0.053855,296.291046,15.093786,0.538549,-28.289885,0.053968,0.000000
50.840004,66.354156,-28.334366,0.018535,0.002120,0.053837,295.158020,15.036066,0.538375,-28.334366,0.053968,0.000000
51.030003,66.148987,-28.334366,0.018548,0.002119,0.053820,294.245392,14.989574,0.538201,-28.334366,0.053968,0.000000
51.220001,65.961685,-28.334366,0.018540,0.002119,0.053811,293.412231,14.947131,0.538114,-28.334366,0.053968,0.000000
51.410004,65.773270,-28.378847,0.018540,0.002118,0.053803,292.574127,14.904435,0.538027,-28.378847,0.053968,0.000000
51.600002,65.637344,-28.334366,0.018535,0.002118,0.053803,291.969482,14.873634,0.538027,-28.334366,0.053968,0.000000
51.790001,65.467545,-28.423328,0.018552,0.002118,0.053794,291.214172,14.835157,0.537943,-28.423328,0.053968,0.000000
51.980003,65.340942,-28.378847,0.018544,0.002118,0.053794,290.651031,14.806470,0.537943,-28.378847,0.053968,0.000000
52.170002,65.237411,-28.289885,0.018548,0.002118,0.053794,290.190491,14.783009,0.537943,-28.289885,0.053968,0.000000
52.360001,65.109329,-28.378847,0.018548,0.002118,0.053786,289.620758,14.753985,0.537856,-28.378847,0.053968,0.000000
52.550003,65.002075,-28.378847,0.018561,0.002118,0.053786,289.143677,14.729681,0.537856,-28.378847,0.053968,0.000000
52.740002,64.914200,-28.423328,0.018552,0.002118,0.053786,288.752777,14.709768,0.537856,-28.423328,0.053968,0.000000
52.930004,64.826691,-28.378847,0.018565,0.002118,0.053786,288.363525,14.689939,0.537856,-28.378847,0.053968,0.000000
53.120003,64.743286,-28.378847,0.018557,0.002118,0.053786,287.992523,14.671039,0.537856,-28.378847,0.053968,0.000000
53.310001,64.669556,-28.423328,0.018557,0.002118,0.053786,287.664551,14.654330,0.537856,-28.423328,0.053968,0.000000
53.500004,64.595444,-28.378847,0.018548,0.002117,0.053777,287.334869,14.637537,0.537769,-28.378847,0.053968,0.000000
53.690002,64.507568,-28.467808,0.018544,0.002117,0.053777,286.944000,14.617624,0.537769,-28.467808,0.053968,0.000000
53.880001,64.425278,-28.378847,0.018565,0.002117,0.053777,286.577942,14.598977,0.537769,-28.378847,0.053968,0.000000
54.070004,64.368668,-28.378847,0.018565,0.002117,0.053777,286.326141,14.586148,0.537769,-28.378847,0.053968,0.000000
54.260002,64.284897,-28.423328,0.018561,0.002117,0.053777,285.953491,14.567166,0.537769,-28.423328,0.053968,0.000000
54.450001,64.232391,-28.378847,0.018561,0.002117,0.053777,285.719940,14.555268,0.537769,-28.378847,0.053968,0.000000
54.640003,64.190674,-28.423328,0.018565,0.002117,0.053777,285.534363,14.545815,0.537769,-28.423328,0.053968,0.000000
54.830002,64.123276,-28.423328,0.018574,0.002117,0.053777,285.234589,14.530542,0.537769,-28.423328,0.053968,0.000000
55.020004,64.064438,-28.423328,0.018552,0.002117,0.053777,284.972839,14.517209,0.537769,-28.423328,0.053968,0.000000
55.210003,64.025345,-28.467808,0.018548,0.002117,0.053777,284.798950,14.508351,0.537769,-28.467808,0.053968,0.000000
55.400002,63.968002,-28.334366,0.018574,0.002117,0.053777,284.543884,14.495357,0.537769,-28.334366,0.053968,0.000000
55.590004,63.916992,-28.467808,0.018557,0.002117,0.053777,284.316986,14.483797,0.537769,-28.467808,0.053968,0.000000
55.780003,63.870804,-28.423328,0.018557,0.002117,0.053777,284.111511,14.473331,0.537769,-28.423328,0.053968,0.000000
55.970001,63.829483,-28.467808,0.018544,0.002117,0.053777,283.927734,14.463967,0.537769,-28.467808,0.053968,0.000000
56.160004,63.776978,-28.467808,0.018570,0.002117,0.053777,283.694153,14.452070,0.537769,-28.467808,0.053968,0.000000
56.350002,63.736755,-28.423328,0.018574,0.002117,0.053777,283.515259,14.442955,0.537769,-28.423328,0.053968,0.000000
56.540001,63.679413,-28.512289,0.018552,0.002117,0.053777,283.260162,14.429961,0.537769,-28.512289,0.053968,0.000000
56.730003,63.652969,-28.423328,0.018587,0.002117,0.053777,283.142548,14.423969,0.537769,-28.423328,0.053968,0.000000
56.920002,63.612762,-28.423328,0.018570,0.002117,0.053777,282.963715,14.414858,0.537769,-28.423328,0.053968,0.000000
57.110004,63.581848,-28.423328,0.018552,0.002117,0.053777,282.826172,14.407853,0.537769,-28.423328,0.053968,0.000000
57.300003,63.539032,-28.467808,0.018548,0.002117,0.053777,282.635742,14.398150,0.537769,-28.467808,0.053968,0.000000
57.490002,63.499191,-28.512289,0.018557,0.002117,0.053768,282.458496,14.389122,0.537682,-28.512289,0.053968,0.000000
57.680004,63.488754,-28.423328,0.018574,0.002117,0.053768,282.412079,14.386757,0.537682,-28.423328,0.053968,0.000000
57.870003,63.446686,-28.467808,0.018565,0.002117,0.053768,282.224945,14.377225,0.537682,-28.467808,0.053968,0.000000
58.060001,63.401245,-28.467808,0.018552,0.002117,0.053768,282.022827,14.366927,0.537682,-28.467808,0.053968,0.000000
58.250004,63.370712,-28.467808,0.018565,0.002117,0.053768,281.886993,14.360009,0.537682,-28.467808,0.053968,0.000000
58.440002,63.336456,-28.512289,0.018561,0.002117,0.053768,281.734619,14.352245,0.537682,-28.512289,0.053968,0.000000
58.630001,63.291031,-28.467808,0.018570,0.002117,0.053768,281.532562,14.341952,0.537682,-28.467808,0.053968,0.000000
58.820004,63.263092,-28.556770,0.018552,0.002117,0.053768,281.408295,14.335622,0.537682,-28.556770,0.053968,0.000000
59.010002,63.243362,-28.467808,0.018565,0.002117,0.053768,281.320526,14.331151,0.537682,-28.467808,0.053968,0.000000
59.200005,63.203888,-28.512289,0.018561,0.002117,0.053768,281.144928,14.322206,0.537682,-28.512289,0.053968,0.000000
59.390003,63.191238,-28.556770,0.018570,0.002117,0.053768,281.088654,14.319339,0.537682,-28.556770,0.053968,0.000000
59.580002,63.167023,-28.467808,0.018570,0.002117,0.053768,280.980957,14.313852,0.537682,-28.467808,0.053968,0.000000
59.770004,63.132019,-28.556770,0.018583,0.002117,0.053768,280.825256,14.305920,0.537682,-28.556770,0.053968,0.000000
59.960003,63.100006,-28.556770,0.018561,0.002117,0.053768,280.682831,14.298666,0.537682,-28.556770,0.053968,0.000000
60.150002,63.085098,-28.512289,0.018565,0.002117,0.053768,280.616547,14.295288,0.537682,-28.512289,0.053968,0.000000
60.340004,63.051971,-28.512289,0.018570,0.002117,0.053768,280.469177,14.287781,0.537682,-28.512289,0.053968,0.000000
60.530003,63.013245,-28.512289,0.018578,0.002117,0.053768,280.296906,14.279005,0.537682,-28.512289,0.053968,0.000000
60.720001,62.986801,-28.601252,0.018565,0.002117,0.053768,280.179291,14.273013,0.537682,-28.601252,0.053968,0.000000
60.910004,62.970047,-28.512289,0.018583,0.002117,0.053768,280.104767,14.269217,0.537682,-28.512289,0.053968,0.000000
61.100002,62.940247,-28.512289,0.018552,0.002117,0.053768,279.972198,14.262464,0.537682,-28.512289,0.053968,0.000000
61.290005,62.930573,-28.645733,0.018565,0.002117,0.053768,279.929169,14.260271,0.537682,-28.645733,0.053968,0.000000
61.480003,62.904510,-28.556770,0.018570,0.002117,0.053768,279.813232,14.254366,0.537682,-28.556770,0.053968,0.000000
61.670002,62.878067,-28.512289,0.018565,0.002117,0.053768,279.695618,14.248373,0.537682,-28.512289,0.053968,0.000000
61.860004,62.869125,-28.601252,0.018561,0.002117,0.053768,279.655823,14.246347,0.537682,-28.601252,0.053968,0.000000
62.050003,62.837479,-28.601252,0.018574,0.002117,0.053768,279.515076,14.239176,0.537682,-28.601252,0.053968,0.000000
62.240002,62.805832,-28.601252,0.018565,0.002117,0.053768,279.374298,14.232005,0.537682,-28.601252,0.053968,0.000000
62.430004,62.780502,-28.601252,0.018557,0.002117,0.053768,279.261627,14.226266,0.537682,-28.601252,0.053968,0.000000
62.620003,62.774551,-28.645733,0.018583,0.002117,0.053768,279.235138,14.224916,0.537682,-28.645733,0.053968,0.000000
62.810001,62.743271,-28.601252,0.018583,0.002117,0.053768,279.096008,14.217828,0.537682,-28.601252,0.053968,0.000000
63.000004,62.710869,-28.645733,0.018565,0.002117,0.053768,278.951874,14.210486,0.537682,-28.645733,0.053968,0.000000
63.190002,62.713852,-28.645733,0.018570,0.002117,0.053768,278.965149,14.211162,0.537682,-28.645733,0.053968,0.000000
63.380005,62.684433,-28.601252,0.018578,0.002117,0.053768,278.834290,14.204495,0.537682,-28.601252,0.053968,0.000000
63.570004,62.664696,-28.645733,0.018561,0.002117,0.053768,278.746490,14.200024,0.537682,-28.645733,0.053968,0.000000
63.760002,62.651291,-28.556770,0.018565,0.002117,0.053768,278.686859,14.196986,0.537682,-28.556770,0.053968,0.000000
63.950005,62.643097,-28.601252,0.018557,0.002117,0.053768,278.650421,14.195128,0.537682,-28.601252,0.053968,0.000000
64.139999,62.617035,-28.645733,0.018570,0.002117,0.053768,278.534485,14.189223,0.537682,-28.645733,0.053968,0.000000
64.330002,62.595062,-28.645733,0.018557,0.002117,0.053768,278.436737,14.184244,0.537682,-28.645733,0.053968,0.000000
64.520004,62.583893,-28.601252,0.018561,0.002117,0.053768,278.387054,14.181713,0.537682,-28.601252,0.053968,0.000000
64.710007,62.556709,-28.645733,0.018552,0.002117,0.053768,278.266144,14.175552,0.537682,-28.645733,0.053968,0.000000
64.900002,62.533997,-28.645733,0.018557,0.002117,0.053768,278.165100,14.170406,0.537682,-28.645733,0.053968,0.000000
65.090004,62.522079,-28.645733,0.018570,0.002117,0.053768,278.112091,14.167706,0.537682,-28.645733,0.053968,0.000000
65.280006,62.496010,-28.645733,0.018561,0.002117,0.053768,277.996124,14.161798,0.537682,-28.645733,0.053968,0.000000
65.470001,62.482231,-28.690214,0.018552,0.002117,0.053768,277.934845,14.158676,0.537682,-28.690214,0.053968,0.000000
65.660004,62.476280,-28.690214,0.018574,0.002117,0.053768,277.908386,14.157328,0.537682,-28.690214,0.053968,0.000000
65.850006,62.460640,-28.734694,0.018583,0.002117,0.053768,277.838806,14.153784,0.537682,-28.734694,0.053968,0.000000
66.040001,62.444626,-28.690214,0.018591,0.002117,0.053768,277.767578,14.150155,0.537682,-28.690214,0.053968,0.000000
66.230003,62.430473,-28.690214,0.018574,0.002117,0.053768,277.704620,14.146948,0.537682,-28.690214,0.053968,0.000000
66.420006,62.416321,-28.690214,0.018587,0.002117,0.053768,277.641663,14.143740,0.537682,-28.690214,0.053968,0.000000
66.610001,62.380577,-28.690214,0.018561,0.002117,0.053768,277.482666,14.135641,0.537682,-28.690214,0.053968,0.000000
66.800003,62.379463,-28.734694,0.018570,0.002117,0.053768,277.477722,14.135388,0.537682,-28.734694,0.053968,0.000000
66.990005,62.366051,-28.690214,0.018583,0.002117,0.053768,277.418060,14.132349,0.537682,-28.690214,0.053968,0.000000
67.180000,62.344826,-28.734694,0.018578,0.002117,0.053768,277.323639,14.127540,0.537682,-28.734694,0.053968,0.000000
67.370003,62.319138,-28.734694,0.018587,0.002117,0.053768,277.209381,14.121718,0.537682,-28.734694,0.053968,0.000000
67.560005,62.316154,-28.645733,0.018578,0.002117,0.053768,277.196106,14.121042,0.537682,-28.645733,0.053968,0.000000
67.750000,62.299026,-28.734694,0.018574,0.002117,0.053768,277.119904,14.117161,0.537682,-28.734694,0.053968,0.000000
67.940002,62.289719,-28.690214,0.018574,0.002117,0.053768,277.078522,14.115052,0.537682,-28.690214,0.053968,0.000000
68.130005,62.278915,-28.690214,0.018561,0.002117,0.053768,277.030457,14.112604,0.537682,-28.690214,0.053968,0.000000
68.320000,62.269981,-28.779175,0.018574,0.002117,0.053768,276.990723,14.110579,0.537682,-28.779175,0.053968,0.000000
68.510002,62.258812,-28.734694,0.018578,0.002117,0.053768,276.941040,14.108048,0.537682,-28.734694,0.053968,0.000000
68.700005,62.245781,-28.734694,0.018561,0.002117,0.053768,276.883057,14.105096,0.537682,-28.734694,0.053968,0.000000
68.890007,62.223808,-28.690214,0.018574,0.002117,0.053768,276.785309,14.100117,0.537682,-28.690214,0.053968,0.000000
69.080002,62.213753,-28.779175,0.018561,0.002117,0.053768,276.740601,14.097837,0.537682,-28.779175,0.053968,0.000000
69.270004,62.191040,-28.779175,0.018578,0.002117,0.053768,276.639557,14.092691,0.537682,-28.779175,0.053968,0.000000
69.460007,62.185829,-28.779175,0.018561,0.002117,0.053768,276.616394,14.091510,0.537682,-28.779175,0.053968,0.000000
69.650002,62.167206,-28.823656,0.018591,0.002117,0.053768,276.533539,14.087291,0.537682,-28.823656,0.053968,0.000000
69.840004,62.157524,-28.734694,0.018565,0.002117,0.053768,276.490479,14.085096,0.537682,-28.734694,0.053968,0.000000
70.030006,62.156410,-28.734694,0.018583,0.002117,0.053768,276.485535,14.084844,0.537682,-28.734694,0.053968,0.000000
70.220001,62.137421,-28.779175,0.018570,0.002117,0.053768,276.401062,14.080541,0.537682,-28.779175,0.053968,0.000000
70.410004,62.120659,-28.779175,0.018587,0.002117,0.053768,276.326477,14.076742,0.537682,-28.779175,0.053968,0.000000
70.600006,62.112099,-28.734694,0.018578,0.002117,0.053768,276.288422,14.074803,0.537682,-28.734694,0.053968,0.000000
70.790001,62.106514,-28.779175,0.018583,0.002117,0.053768,276.263580,14.073538,0.537682,-28.779175,0.053968,0.000000
70.980003,62.080818,-28.779175,0.018574,0.002117,0.053768,276.149261,14.067715,0.537682,-28.779175,0.053968,0.000000
71.170006,62.078583,-28.823656,0.018574,0.002117,0.053768,276.139313,14.067208,0.537682,-28.823656,0.053968,0.000000
71.360001,62.058472,-28.823656,0.018565,0.002117,0.053768,276.049866,14.062651,0.537682,-28.823656,0.053968,0.000000
71.550003,62.039856,-28.868137,0.018587,0.002117,0.053768,275.967072,14.058432,0.537682,-28.868137,0.053968,0.000000
71.740005,62.037621,-28.823656,0.018574,0.002117,0.053768,275.957123,14.057925,0.537682,-28.823656,0.053968,0.000000
71.930000,62.019745,-28.823656,0.018570,0.002117,0.053768,275.877594,14.053875,0.537682,-28.823656,0.053968,0.000000
72.120003,62.016396,-28.868137,0.018574,0.002117,0.053768,275.862701,14.053116,0.537682,-28.868137,0.053968,0.000000
72.310005,61.991074,-28.779175,0.018570,0.002117,0.053768,275.750061,14.047379,0.537682,-28.779175,0.053968,0.000000
72.500000,61.987724,-28.868137,0.018565,0.002117,0.053768,275.735168,14.046619,0.537682,-28.868137,0.053968,0.000000
72.690002,61.986977,-28.823656,0.018583,0.002117,0.053768,275.731842,14.046450,0.537682,-28.823656,0.053968,0.000000
72.880005,61.963150,-28.868137,0.018565,0.002117,0.053768,275.625854,14.041050,0.537682,-28.868137,0.053968,0.000000
73.070000,61.971336,-28.868137,0.018570,0.002117,0.053768,275.662262,14.042905,0.537682,-28.868137,0.053968,0.000000
73.260002,61.961288,-28.823656,0.018570,0.002117,0.053768,275.617584,14.040628,0.537682,-28.823656,0.053968,0.000000
73.450005,61.932243,-28.823656,0.018561,0.002117,0.053768,275.488373,14.034047,0.537682,-28.823656,0.053968,0.000000
73.640007,61.926285,-28.868137,0.018574,0.002117,0.053768,275.461884,14.032697,0.537682,-28.868137,0.053968,0.000000
73.830002,61.918465,-28.868137,0.018583,0.002117,0.053768,275.427094,14.030925,0.537682,-28.868137,0.053968,0.000000
74.020004,61.909157,-28.912619,0.018583,0.002117,0.053768,275.385681,14.028815,0.537682,-28.912619,0.053968,0.000000
74.210007,61.882339,-28.823656,0.018578,0.002117,0.053768,275.266388,14.022738,0.537682,-28.823656,0.053968,0.000000
74.400002,61.871918,-28.912619,0.018578,0.002117,0.053768,275.220032,14.020377,0.537682,-28.912619,0.053968,0.000000
74.590004,61.869682,-28.912619,0.018561,0.002117,0.053768,275.210083,14.019871,0.537682,-28.912619,0.053968,0.000000
74.780006,61.847710,-28.868137,0.018565,0.002117,0.053768,275.112366,14.014891,0.537682,-28.868137,0.053968,0.000000
74.970001,61.848831,-28.912619,0.018561,0.002117,0.053768,275.117340,14.015145,0.537682,-28.912619,0.053968,0.000000
75.160004,61.846970,-28.912619,0.018578,0.002117,0.053768,275.109070,14.014724,0.537682,-28.912619,0.053968,0.000000
75.350006,61.839890,-28.957100,0.018548,0.002117,0.053768,275.077576,14.013119,0.537682,-28.957100,0.053968,0.000000
75.540001,61.820526,-28.868137,0.018591,0.002117,0.053768,274.991425,14.008731,0.537682,-28.868137,0.053968,0.000000
75.730003,61.819412,-28.912619,0.018565,0.002117,0.053768,274.986481,14.008479,0.537682,-28.912619,0.053968,0.000000
75.920006,61.795578,-28.957100,0.018565,0.002117,0.053768,274.880463,14.003078,0.537682,-28.957100,0.053968,0.000000
76.110001,61.796326,-28.912619,0.018583,0.002117,0.053768,274.883789,14.003248,0.537682,-28.912619,0.053968,0.000000
76.300003,61.777702,-28.912619,0.018561,0.002117,0.053768,274.800934,13.999027,0.537682,-28.912619,0.053968,0.000000
76.490005,61.774353,-28.912619,0.018578,0.002117,0.053768,274.786041,13.998268,0.537682,-28.912619,0.053968,0.000000
76.680000,61.757973,-28.912619,0.018578,0.002117,0.053768,274.713196,13.994556,0.537682,-28.912619,0.053968,0.000000
76.870003,61.747543,-28.957100,0.018570,0.002117,0.053768,274.666779,13.992193,0.537682,-28.957100,0.053968,0.000000
77.060005,61.732651,-28.957100,0.018583,0.002117,0.053768,274.600555,13.988819,0.537682,-28.957100,0.053968,0.000000
77.250000,61.740471,-28.957100,0.018583,0.002117,0.053768,274.635345,13.990591,0.537682,-28.957100,0.053968,0.000000
77.440002,61.735252,-28.912619,0.018596,0.002117,0.053768,274.612122,13.989408,0.537682,-28.912619,0.053968,0.000000
77.630005,61.719246,-28.957100,0.018583,0.002117,0.053768,274.540924,13.985781,0.537682,-28.957100,0.053968,0.000000
77.820007,61.718872,-29.001579,0.018561,0.002117,0.053768,274.539246,13.985697,0.537682,-29.001579,0.053968,0.000000
78.010002,61.709564,-28.912619,0.018583,0.002117,0.053768,274.497864,13.983586,0.537682,-28.912619,0.053968,0.000000
78.200005,61.684982,-29.001579,0.018574,0.002117,0.053768,274.388519,13.978016,0.537682,-29.001579,0.053968,0.000000
78.390007,61.684982,-28.957100,0.018565,0.002117,0.053768,274.388519,13.978016,0.537682,-28.957100,0.053968,0.000000
78.580002,61.676422,-28.912619,0.018583,0.002117,0.053768,274.350433,13.976077,0.537682,-28.912619,0.053968,0.000000
78.770004,61.657433,-29.001579,0.018596,0.002117,0.053768,274.265961,13.971774,0.537682,-29.001579,0.053968,0.000000
78.960007,61.654076,-29.001579,0.018583,0.002117,0.053768,274.251038,13.971013,0.537682,-29.001579,0.053968,0.000000
79.150002,61.641792,-29.001579,0.018574,0.002117,0.053768,274.196381,13.968229,0.537682,-29.001579,0.053968,0.000000
79.340004,61.627640,-28.957100,0.018565,0.002117,0.053768,274.133423,13.965022,0.537682,-28.957100,0.053968,0.000000
79.530006,61.619446,-29.001579,0.018578,0.002117,0.053768,274.096985,13.963166,0.537682,-29.001579,0.053968,0.000000
79.720001,61.615349,-29.046061,0.018583,0.002117,0.053768,274.078766,13.962238,0.537682,-29.046061,0.053968,0.000000
79.910004,61.613113,-28.912619,0.018583,0.002117,0.053768,274.068817,13.961732,0.537682,-28.912619,0.053968,0.000000
80.100006,61.601570,-29.046061,0.018583,0.002117,0.053768,274.017456,13.959115,0.537682,-29.046061,0.053968,0.000000
80.290001,61.607529,-29.046061,0.018587,0.002117,0.053768,274.043976,13.960466,0.537682,-29.046061,0.053968,0.000000
80.480003,61.600082,-29.001579,0.018578,0.002117,0.053768,274.010864,13.958778,0.537682,-29.001579,0.053968,0.000000
80.500008,61.586304,-29.046061,0.018583,0.002117,0.053768,273.949554,13.955656,0.537682,-29.046061,0.053968,0.000000