File: Data/I-18 Lathed test 2_10242023_165238.csv
Time (sec),S:Load (lbs),S:HL1 (DIM),S:LVDT (in),S:Position (in),Ch:Position (mm),Ch:Load (N),Ch:Stress (MPa),Ch:Strain (mm/mm),Ch:HL1 (DIM),Set Point (),Cycles ()
0.110000,-0.011917,-17.481014,0.011952,-0.004661,-0.118394,-0.053010,-0.002700,-1.183938,-17.481014,-0.118177,0.000000
0.280000,-0.006332,-17.481014,0.011956,-0.004661,-0.118394,-0.028168,-0.001435,-1.183938,-17.481014,-0.118177,0.000000
0.450000,0.016006,-17.481014,0.011947,-0.004632,-0.117648,0.071200,0.003627,-1.176482,-17.481014,-0.117084,0.000000
0.620000,-0.001122,-17.525496,0.011939,-0.004544,-0.115411,-0.004989,-0.000254,-1.154105,-17.525496,-0.114240,0.000000
0.790000,0.023087,-17.569975,0.012033,-0.004430,-0.112523,0.102694,0.005231,-1.125227,-17.569975,-0.111413,0.000000
0.960000,0.013779,-17.525496,0.012154,-0.004317,-0.109652,0.061291,0.003122,-1.096522,-17.525496,-0.108586,0.000000
1.130000,0.006699,-17.481014,0.012271,-0.004205,-0.106808,0.029797,0.001518,-1.068078,-17.481014,-0.105741,0.000000
1.300000,-0.006706,-17.481014,0.012400,-0.004090,-0.103894,-0.029831,-0.001520,-1.038939,-17.481014,-0.102914,0.000000
1.470000,-0.019737,-17.525496,0.012529,-0.003981,-0.101119,-0.087796,-0.004473,-1.011188,-17.525496,-0.100087,0.000000
1.640000,-0.026070,-17.569975,0.012637,-0.003873,-0.098369,-0.115964,-0.005907,-0.983694,-17.569975,-0.097260,0.000000
1.810000,-0.048409,-17.569975,0.012753,-0.003759,-0.095490,-0.215332,-0.010970,-0.954903,-17.569975,-0.094415,0.000000
1.980000,-0.007454,-17.481014,0.012866,-0.003642,-0.092516,-0.033157,-0.001689,-0.925157,-17.481014,-0.091588,0.000000
2.150000,-0.026070,-17.525496,0.012991,-0.003538,-0.089853,-0.115964,-0.005907,-0.898534,-17.525496,-0.088761,0.000000
2.320000,-0.014900,-17.569975,0.013116,-0.003425,-0.087000,-0.066279,-0.003376,-0.870004,-17.569975,-0.085916,0.000000
2.490000,0.007820,-17.569975,0.013245,-0.003319,-0.084303,0.034786,0.001772,-0.843032,-17.569975,-0.083089,0.000000
2.660000,0.002228,-17.525496,0.013323,-0.003206,-0.081433,0.009910,0.000505,-0.814328,-17.525496,-0.080262,0.000000
2.830000,-0.022720,-17.525496,0.013443,-0.003095,-0.078605,-0.101065,-0.005149,-0.786055,-17.525496,-0.077435,0.000000
3.000000,-0.013039,-17.481014,0.013586,-0.002982,-0.075744,-0.057999,-0.002955,-0.757437,-17.481014,-0.074590,0.000000
3.170000,-0.016388,-17.525496,0.013689,-0.002865,-0.072778,-0.072897,-0.003714,-0.727779,-17.525496,-0.071763,0.000000
3.340000,0.013031,-17.614456,0.013827,-0.002752,-0.069890,0.057965,0.002953,-0.698900,-17.614456,-0.068936,0.000000
3.510000,0.002602,-17.569975,0.013931,-0.002643,-0.067124,0.011573,0.000590,-0.671236,-17.569975,-0.066091,0.000000
3.680000,0.005959,-17.569975,0.014056,-0.002535,-0.064400,0.026505,0.001350,-0.644004,-17.569975,-0.063264,0.000000
3.850000,0.012283,-17.481014,0.014142,-0.002424,-0.061582,0.054639,0.002783,-0.615818,-17.481014,-0.060437,0.000000
4.020000,0.004463,-17.569975,0.014284,-0.002311,-0.058711,0.019853,0.001011,-0.587113,-17.569975,-0.057610,0.000000
4.190000,-0.009682,-17.569975,0.014400,-0.002199,-0.055850,-0.043066,-0.002194,-0.558495,-17.569975,-0.054766,0.000000
4.360000,-0.036125,-17.525496,0.014504,-0.002089,-0.053048,-0.160693,-0.008186,-0.530483,-17.525496,-0.051938,0.000000
4.530000,-0.048782,-17.525496,0.014633,-0.001975,-0.050169,-0.216995,-0.011054,-0.501692,-17.525496,-0.049111,0.000000
4.700000,0.005585,-17.569975,0.014728,-0.001870,-0.047489,0.024842,0.001266,-0.474895,-17.569975,-0.046267,0.000000
4.870000,0.002975,-17.569975,0.014866,-0.001761,-0.044732,0.013236,0.000674,-0.447318,-17.569975,-0.043440,0.000000
5.040000,0.027924,-17.658937,0.014995,-0.001647,-0.041844,0.124210,0.006328,-0.418439,-17.658937,-0.040612,0.000000
5.210000,0.020851,-17.614456,0.015103,-0.001532,-0.038904,0.092750,0.004725,-0.389038,-17.614456,-0.037785,0.000000
5.380000,0.013405,-17.614456,0.015233,-0.001414,-0.035921,0.059628,0.003038,-0.359205,-17.614456,-0.034941,0.000000
5.550000,0.001114,-17.569975,0.015353,-0.001303,-0.033085,0.004955,0.000252,-0.330849,-17.569975,-0.032114,0.000000
5.720000,-0.011917,-17.614456,0.015461,-0.001197,-0.030405,-0.053010,-0.002700,-0.304052,-17.614456,-0.029286,0.000000
5.890000,-0.029793,-17.658937,0.015560,-0.001084,-0.027535,-0.132525,-0.006751,-0.275347,-17.658937,-0.026442,0.000000
6.060000,0.010796,-17.569975,0.015707,-0.000970,-0.024629,0.048021,0.002446,-0.246294,-17.569975,-0.023615,0.000000
6.230000,-0.009682,-17.658937,0.015832,-0.000858,-0.021793,-0.043066,-0.002194,-0.217934,-17.658937,-0.020787,0.000000
6.400000,0.004837,-17.614456,0.015931,-0.000748,-0.019001,0.021516,0.001096,-0.190009,-17.614456,-0.017960,0.000000
6.570000,0.018990,-17.658937,0.016056,-0.000638,-0.016200,0.084470,0.004303,-0.162001,-17.658937,-0.015116,0.000000
6.740000,0.018616,-17.658937,0.016181,-0.000528,-0.013416,0.082807,0.004218,-0.134163,-17.658937,-0.012289,0.000000
6.910000,0.016006,-17.658937,0.016280,-0.000419,-0.010650,0.071200,0.003627,-0.106496,-17.658937,-0.009461,0.000000
7.080000,0.039467,-17.614456,0.016388,-0.000307,-0.007788,0.175557,0.008943,-0.077878,-17.614456,-0.006617,0.000000
7.250000,0.114319,-17.703419,0.016509,-0.000192,-0.004874,0.508516,0.025905,-0.048738,-17.703419,-0.003790,0.000000
7.420001,0.418541,-17.658937,0.016621,-0.000078,-0.001978,1.861763,0.094843,-0.019776,-17.658937,-0.000963,0.000000
7.590000,0.730591,-17.703419,0.016690,-0.000006,-0.000165,3.249830,0.165554,-0.001650,-17.703419,0.000061,0.000000
7.760000,0.723892,-17.747900,0.016724,-0.000006,-0.000165,3.220033,0.164036,-0.001650,-17.747900,0.000061,0.000000
7.930000,0.706390,-17.658937,0.016690,-0.000006,-0.000165,3.142181,0.160070,-0.001650,-17.658937,0.000061,0.000000
8.100000,0.715324,-17.658937,0.016681,-0.000006,-0.000165,3.181922,0.162095,-0.001650,-17.658937,0.000182,0.000000
8.270000,0.713837,-17.703419,0.016686,-0.000006,-0.000165,3.175304,0.161758,-0.001650,-17.703419,0.000459,0.000000
8.440001,0.716072,-17.703419,0.016707,-0.000006,-0.000165,3.185248,0.162264,-0.001650,-17.703419,0.000746,0.000000
8.610001,0.703781,-17.658937,0.016694,-0.000006,-0.000165,3.130575,0.159479,-0.001650,-17.658937,0.001032,0.000000
8.780001,0.843048,-17.658937,0.016703,0.000023,0.000581,3.750065,0.191037,0.005810,-17.658937,0.001309,0.000000
8.950001,0.970024,-17.658937,0.016742,0.000034,0.000858,4.314883,0.219811,0.008584,-17.658937,0.001596,0.000000
9.120001,1.057907,-17.658937,0.016742,0.000044,0.001127,4.705806,0.239725,0.011271,-17.658937,0.001882,0.000000
9.290001,1.132011,-17.658937,0.016755,0.000054,0.001379,5.035438,0.256517,0.013788,-17.658937,0.002159,0.000000
9.460000,1.238136,-17.703419,0.016755,0.000065,0.001656,5.507505,0.280566,0.016563,-17.703419,0.002445,0.000000
9.630000,1.314842,-17.614456,0.016780,0.000075,0.001916,5.848711,0.297947,0.019163,-17.614456,0.002732,0.000000
9.800000,1.428421,-17.703419,0.016767,0.000083,0.002116,6.353934,0.323685,0.021158,-17.703419,0.003009,0.000000
9.970000,1.555397,-17.658937,0.016793,0.000098,0.002480,6.918752,0.352458,0.024802,-17.658937,0.003295,0.000000
10.140000,1.709930,-17.747900,0.016798,0.000108,0.002749,7.606150,0.387476,0.027490,-17.747900,0.003582,0.000000
10.310000,1.822014,-17.747900,0.016806,0.000118,0.003009,8.104722,0.412874,0.030090,-17.747900,0.003859,0.000000
10.480000,1.964264,-17.703419,0.016815,0.000128,0.003261,8.737482,0.445109,0.032607,-17.703419,0.004145,0.000000
10.650001,2.049904,-17.658937,0.016806,0.000135,0.003425,9.118428,0.464515,0.034253,-17.658937,0.004431,0.000000
10.820001,2.183960,-17.703419,0.016815,0.000147,0.003738,9.714739,0.494892,0.037376,-17.703419,0.004717,0.000000
10.990001,2.398079,-17.792381,0.016854,0.000161,0.004093,10.667188,0.543412,0.040930,-17.792381,0.004995,0.000000
11.160001,2.565269,-17.747900,0.016858,0.000172,0.004362,11.410889,0.581298,0.043621,-17.747900,0.005281,0.000000
11.330001,2.724274,-17.747900,0.016875,0.000183,0.004648,12.118175,0.617329,0.046482,-17.747900,0.005568,0.000000
11.500001,2.875832,-17.747900,0.016858,0.000193,0.004900,12.792337,0.651673,0.048995,-17.747900,0.005845,0.000000
11.670001,3.000946,-17.703419,0.016893,0.000202,0.005125,13.348875,0.680024,0.051251,-17.703419,0.006131,0.000000
11.840000,3.226608,-17.792381,0.016871,0.000214,0.005437,14.352671,0.731160,0.054374,-17.792381,0.006417,0.000000
12.010000,3.523010,-17.792381,0.016905,0.000230,0.005836,15.671132,0.798326,0.058363,-17.792381,0.006695,0.000000
12.180000,3.736382,-17.747900,0.016918,0.000240,0.006105,16.620255,0.846676,0.061050,-17.747900,0.006981,0.000000
12.350000,3.842506,-17.747900,0.016927,0.000248,0.006287,17.092321,0.870724,0.062871,-17.747900,0.007267,0.000000
12.520000,3.956451,-17.747900,0.016931,0.000254,0.006452,17.599174,0.896545,0.064521,-17.747900,0.007545,0.000000
12.690001,4.306114,-17.792381,0.016940,0.000270,0.006860,19.154552,0.975779,0.068597,-17.792381,0.007831,0.000000
12.860001,4.652794,-17.792381,0.016962,0.000287,0.007293,20.696661,1.054338,0.072931,-17.792381,0.008117,0.000000
13.030001,4.892975,-17.792381,0.016970,0.000297,0.007554,21.765039,1.108764,0.075535,-17.792381,0.008395,0.000000
13.200001,5.095543,-17.792381,0.016992,0.000308,0.007814,22.666107,1.154667,0.078135,-17.792381,0.008681,0.000000
13.370001,5.288055,-17.792381,0.016974,0.000320,0.008117,23.522446,1.198290,0.081171,-17.792381,0.008967,0.000000
13.540001,5.549461,-17.792381,0.016996,0.000330,0.008377,24.685238,1.257526,0.083771,-17.792381,0.009245,0.000000
13.710001,5.741608,-17.836861,0.016992,0.000338,0.008577,25.539946,1.301067,0.085766,-17.836861,0.009531,0.000000
13.880001,6.093872,-17.792381,0.017022,0.000352,0.008950,27.106897,1.380891,0.089498,-17.792381,0.009817,0.000000
14.050000,6.354530,-17.792381,0.017022,0.000365,0.009262,28.266363,1.439957,0.092620,-17.792381,0.010094,0.000000
14.220000,6.425285,-17.792381,0.017030,0.000369,0.009374,28.581097,1.455990,0.093744,-17.792381,0.010380,0.000000
14.390000,6.801384,-17.792381,0.017026,0.000382,0.009704,30.254066,1.541216,0.097041,-17.792381,0.010667,0.000000
14.560000,7.121994,-17.881342,0.017043,0.000394,0.010016,31.680212,1.613867,0.100163,-17.881342,0.010944,0.000000
14.730000,7.296265,-17.836861,0.017065,0.000403,0.010242,32.455406,1.653357,0.102419,-17.836861,0.011231,0.000000
14.900001,7.850723,-17.836861,0.017074,0.000423,0.010736,34.921761,1.778999,0.107362,-17.836861,0.011517,0.000000
15.070001,8.077873,-17.792381,0.017095,0.000434,0.011014,35.932175,1.830472,0.110137,-17.792381,0.011794,0.000000
15.240001,8.197029,-17.836861,0.017087,0.000442,0.011231,36.462208,1.857473,0.112305,-17.836861,0.012080,0.000000
15.410001,8.475937,-17.836861,0.017095,0.000451,0.011464,37.702850,1.920675,0.114644,-17.836861,0.012366,0.000000
15.580001,8.693779,-17.836861,0.017112,0.000460,0.011681,38.671860,1.970038,0.116813,-17.836861,0.012644,0.000000
15.750001,8.992050,-17.881342,0.017117,0.000471,0.011959,39.998638,2.037628,0.119588,-17.881342,0.012930,0.000000
15.920001,9.304466,-17.792381,0.017130,0.000482,0.012237,41.388332,2.108422,0.122366,-17.792381,0.013216,0.000000
16.090000,9.639977,-17.792381,0.017130,0.000495,0.012566,42.880756,2.184450,0.125659,-17.792381,0.013494,0.000000
16.260000,9.926331,-17.925823,0.017147,0.000505,0.012818,44.154522,2.249339,0.128175,-17.925823,0.013780,0.000000
16.430000,10.313599,-17.836861,0.017138,0.000518,0.013147,45.877178,2.337095,0.131468,-17.836861,0.014066,0.000000
16.600000,10.481537,-17.881342,0.017156,0.000526,0.013364,46.624203,2.375150,0.133637,-17.881342,0.014344,0.000000
16.770000,10.874390,-17.836861,0.017173,0.000539,0.013693,48.371700,2.464172,0.136934,-17.836861,0.014630,0.000000
16.940001,11.116806,-17.881342,0.017177,0.000549,0.013953,49.450024,2.519104,0.139534,-17.881342,0.014916,0.000000
17.110001,11.561043,-17.881342,0.017186,0.000566,0.014370,51.426086,2.619770,0.143697,-17.881342,0.015194,0.000000
17.280001,11.807182,-17.925823,0.017207,0.000575,0.014613,52.520969,2.675546,0.146127,-17.925823,0.015480,0.000000
17.450001,12.022789,-17.881342,0.017216,0.000586,0.014881,53.480038,2.724403,0.148814,-17.881342,0.015766,0.000000
17.620001,12.256264,-17.836861,0.017233,0.000594,0.015098,54.518585,2.777309,0.150983,-17.836861,0.016043,0.000000
17.790001,12.677414,-17.925823,0.017229,0.000609,0.015480,56.391953,2.872743,0.154798,-17.925823,0.016330,0.000000
17.960001,12.971222,-17.836861,0.017246,0.000619,0.015714,57.698875,2.939321,0.157141,-17.836861,0.016616,0.000000
18.130001,13.257576,-17.881342,0.017250,0.000630,0.016009,58.972645,3.004210,0.160090,-17.881342,0.016894,0.000000
18.300001,13.452324,-17.925823,0.017263,0.000640,0.016252,59.838924,3.048340,0.162516,-17.925823,0.017180,0.000000
18.470001,13.815018,-17.792381,0.017268,0.000652,0.016564,61.452267,3.130528,0.165638,-17.792381,0.017466,0.000000
18.640001,14.143822,-17.925823,0.017250,0.000664,0.016876,62.914860,3.205036,0.168761,-17.925823,0.017743,0.000000
18.810001,14.359795,-17.970304,0.017276,0.000673,0.017102,63.875557,3.253976,0.171017,-17.970304,0.018029,0.000000
18.980001,14.606682,-17.970304,0.017298,0.000685,0.017405,64.973763,3.309921,0.174052,-17.970304,0.018315,0.000000
19.150002,15.056503,-17.925823,0.017293,0.000698,0.017717,66.974670,3.411852,0.177171,-17.925823,0.018602,0.000000
19.320002,15.098213,-17.925823,0.017315,0.000706,0.017925,67.160210,3.421304,0.179253,-17.925823,0.018879,0.000000
19.490002,15.508568,-17.925823,0.017315,0.000718,0.018238,68.985558,3.514292,0.182375,-17.925823,0.019166,0.000000
19.660002,15.820984,-17.970304,0.017332,0.000731,0.018558,70.375252,3.585086,0.185585,-17.970304,0.019452,0.000000
19.830002,16.035103,-18.014786,0.017354,0.000740,0.018793,71.327698,3.633606,0.187928,-18.014786,0.019729,0.000000
20.000000,16.382149,-17.925823,0.017367,0.000751,0.019088,72.871437,3.712248,0.190876,-17.925823,0.020015,0.000000
20.170000,16.674461,-17.881342,0.017350,0.000762,0.019365,74.171707,3.778487,0.193650,-17.881342,0.020302,0.000000
20.340000,16.895653,-17.925823,0.017388,0.000773,0.019625,75.155617,3.828610,0.196251,-17.925823,0.020579,0.000000
20.510000,17.295952,-17.925823,0.017393,0.000786,0.019955,76.936234,3.919319,0.199547,-17.925823,0.020865,0.000000
20.680000,17.368568,-17.970304,0.017393,0.000793,0.020137,77.259254,3.935774,0.201368,-17.970304,0.021152,0.000000
20.850000,17.997131,-17.970304,0.017423,0.000812,0.020614,80.055237,4.078208,0.206137,-17.970304,0.021429,0.000000
21.020000,18.203423,-17.925823,0.017423,0.000822,0.020883,80.972870,4.124954,0.208828,-17.925823,0.021715,0.000000
21.190001,18.415680,-18.014786,0.017427,0.000832,0.021143,81.917038,4.173052,0.211428,-18.014786,0.022001,0.000000
21.360001,18.503929,-17.970304,0.017431,0.000840,0.021342,82.309586,4.193050,0.213423,-17.970304,0.022279,0.000000
21.530001,18.625320,-17.970304,0.017431,0.000849,0.021577,82.849564,4.220558,0.215766,-17.970304,0.022565,0.000000
21.700001,19.123932,-18.059267,0.017470,0.000863,0.021932,85.067497,4.333545,0.219320,-18.059267,0.022851,0.000000
21.870001,19.448639,-17.970304,0.017466,0.000874,0.022201,86.511864,4.407125,0.222007,-17.970304,0.023129,0.000000
22.040001,19.579712,-17.970304,0.017475,0.000885,0.022478,87.094910,4.436826,0.224785,-17.970304,0.023415,0.000000
22.210001,19.756966,-18.014786,0.017462,0.000892,0.022652,87.883369,4.476992,0.226518,-18.014786,0.023701,0.000000
22.380001,19.840744,-17.970304,0.017483,0.000901,0.022886,88.256035,4.495977,0.228861,-17.970304,0.023979,0.000000
22.550001,20.104012,-18.014786,0.017500,0.000908,0.023068,89.427109,4.555634,0.230682,-18.014786,0.024265,0.000000
22.720001,20.565758,-17.970304,0.017522,0.000926,0.023528,91.481056,4.660267,0.235277,-17.970304,0.024551,0.000000
22.890001,20.884132,-18.014786,0.017518,0.000936,0.023779,92.897263,4.732412,0.237794,-18.014786,0.024829,0.000000
23.060001,21.345131,-17.970304,0.017526,0.000950,0.024135,94.947884,4.836875,0.241348,-17.970304,0.025115,0.000000
23.230001,21.518654,-18.059267,0.017526,0.000961,0.024412,95.719749,4.876196,0.244122,-18.059267,0.025401,0.000000
23.400002,21.552917,-18.059267,0.017548,0.000970,0.024646,95.872162,4.883961,0.246465,-18.059267,0.025678,0.000000
23.570002,21.756599,-17.970304,0.017552,0.000980,0.024898,96.778191,4.930116,0.248978,-17.970304,0.025965,0.000000
23.740002,22.089500,-18.059267,0.017578,0.000995,0.025262,98.259003,5.005552,0.252623,-18.059267,0.026251,0.000000
23.910002,22.479004,-18.014786,0.017561,0.001006,0.025540,99.991600,5.093815,0.255397,-18.014786,0.026528,0.000000
24.080002,22.484222,-18.014786,0.017578,0.001012,0.025704,100.014816,5.094997,0.257044,-18.014786,0.026814,0.000000
24.250002,22.598534,-18.103746,0.017617,0.001021,0.025921,100.523300,5.120901,0.259212,-18.103746,0.027101,0.000000
24.420002,23.053947,-17.970304,0.017582,0.001035,0.026285,102.549080,5.224099,0.262853,-17.970304,0.027378,0.000000
24.590002,23.200661,-18.059267,0.017613,0.001042,0.026476,103.201691,5.257345,0.264761,-18.059267,0.027664,0.000000
24.760000,23.570061,-18.059267,0.017608,0.001056,0.026832,104.844864,5.341052,0.268319,-18.059267,0.027951,0.000000
24.930000,23.983017,-18.103746,0.017621,0.001071,0.027205,106.681786,5.434629,0.272047,-18.103746,0.028228,0.000000
25.100000,24.475296,-18.103746,0.017638,0.001085,0.027569,108.871552,5.546182,0.275688,-18.103746,0.028514,0.000000
25.270000,24.547165,-18.014786,0.017664,0.001094,0.027794,109.191246,5.562467,0.277944,-18.014786,0.028800,0.000000
25.440001,24.822716,-18.014786,0.017664,0.001106,0.028089,110.416954,5.624908,0.280892,-18.014786,0.029078,0.000000
25.610001,25.049866,-18.059267,0.017664,0.001117,0.028375,111.427368,5.676381,0.283754,-18.059267,0.029364,0.000000
25.780001,25.331009,-18.103746,0.017669,0.001127,0.028627,112.677956,5.740088,0.286271,-18.103746,0.029650,0.000000
25.950001,25.350739,-18.059267,0.017686,0.001135,0.028835,112.765717,5.744559,0.288352,-18.059267,0.029928,0.000000
26.120001,25.574539,-18.014786,0.017690,0.001145,0.029095,113.761230,5.795274,0.290952,-18.014786,0.030214,0.000000
26.290001,25.978561,-18.059267,0.017703,0.001158,0.029416,115.558411,5.886827,0.294162,-18.059267,0.030500,0.000000
26.460001,26.211670,-18.103746,0.017725,0.001166,0.029616,116.595329,5.939650,0.296157,-18.103746,0.030778,0.000000
26.630001,27.110199,-18.059267,0.017729,0.001188,0.030179,120.592186,6.143259,0.301792,-18.059267,0.031064,0.000000
26.800001,27.371239,-18.103746,0.017720,0.001200,0.030483,121.753349,6.202411,0.304828,-18.103746,0.031350,0.000000
26.970001,27.361183,-18.059267,0.017751,0.001209,0.030708,121.708618,6.200133,0.307084,-18.059267,0.031628,0.000000
27.140001,27.636734,-18.059267,0.017763,0.001221,0.031003,122.934334,6.262574,0.310032,-18.059267,0.031914,0.000000
27.310001,27.858673,-18.103746,0.017751,0.001232,0.031289,123.921570,6.312866,0.312893,-18.103746,0.032200,0.000000
27.480001,28.024750,-18.148228,0.017755,0.001242,0.031541,124.660316,6.350499,0.315410,-18.148228,0.032486,0.000000
27.650002,28.641396,-18.148228,0.017789,0.001256,0.031914,127.403290,6.490233,0.319139,-18.148228,0.032764,0.000000
27.820002,28.870407,-18.103746,0.017802,0.001266,0.032148,128.421982,6.542128,0.321478,-18.103746,0.033050,0.000000
27.990002,28.953445,-18.103746,0.017781,0.001275,0.032391,128.791351,6.560945,0.323908,-18.103746,0.033336,0.000000
28.160002,29.066650,-18.148228,0.017807,0.001283,0.032590,129.294922,6.586597,0.325902,-18.148228,0.033614,0.000000
28.330002,29.666542,-18.192709,0.017815,0.001298,0.032972,131.963364,6.722535,0.329717,-18.192709,0.033900,0.000000
28.500002,30.327873,-18.192709,0.017837,0.001313,0.033353,134.905121,6.872394,0.333533,-18.192709,0.034186,0.000000
28.670002,30.831322,-18.103746,0.017854,0.001326,0.033683,137.144562,6.986477,0.336829,-18.103746,0.034463,0.000000
28.840002,31.064056,-18.148228,0.017837,0.001337,0.033960,138.179825,7.039216,0.339603,-18.148228,0.034749,0.000000
29.010002,31.231247,-18.103746,0.017841,0.001347,0.034203,138.923523,7.077102,0.342033,-18.103746,0.035036,0.000000
29.180002,31.465469,-18.192709,0.017845,0.001356,0.034455,139.965393,7.130177,0.344547,-18.192709,0.035313,0.000000
29.350002,31.699318,-18.192709,0.017876,0.001365,0.034672,141.005615,7.183168,0.346715,-18.192709,0.035600,0.000000
29.520000,32.276871,-18.103746,0.017893,0.001380,0.035062,143.574692,7.314044,0.350618,-18.103746,0.035886,0.000000
29.690001,32.699883,-18.192709,0.017888,0.001392,0.035348,145.456345,7.409899,0.353479,-18.192709,0.036163,0.000000
29.860001,32.919586,-18.103746,0.017897,0.001400,0.035565,146.433640,7.459685,0.355648,-18.103746,0.036449,0.000000
30.030001,32.976555,-18.192709,0.017893,0.001407,0.035747,146.687042,7.472594,0.357468,-18.192709,0.036735,0.000000
30.200001,33.541451,-18.192709,0.017919,0.001421,0.036085,149.199829,7.600601,0.360852,-18.192709,0.037013,0.000000
30.370001,34.326035,-18.192709,0.017936,0.001437,0.036502,152.689835,7.778391,0.365015,-18.192709,0.037299,0.000000
30.540001,34.594513,-18.192709,0.017932,0.001446,0.036727,153.884079,7.839229,0.367267,-18.192709,0.037586,0.000000
30.710001,34.961678,-18.148228,0.017936,0.001458,0.037022,155.517303,7.922429,0.370216,-18.148228,0.037863,0.000000
30.880001,35.151215,-18.281672,0.017936,0.001466,0.037238,156.360413,7.965379,0.372384,-18.281672,0.038149,0.000000
31.050001,35.562683,-18.192709,0.017953,0.001477,0.037525,158.190720,8.058619,0.375246,-18.192709,0.038435,0.000000
31.220001,35.894470,-18.192709,0.017983,0.001487,0.037776,159.666580,8.133803,0.377763,-18.192709,0.038713,0.000000
31.390001,36.504044,-18.148228,0.017983,0.001502,0.038140,162.378098,8.271935,0.381404,-18.148228,0.038999,0.000000
31.560001,36.949776,-18.192709,0.017983,0.001512,0.038409,164.360809,8.372939,0.384091,-18.192709,0.039285,0.000000
31.730001,37.204849,-18.192709,0.017996,0.001523,0.038678,165.495438,8.430739,0.386782,-18.192709,0.039563,0.000000
31.900002,37.407043,-18.237190,0.018018,0.001529,0.038825,166.394836,8.476558,0.388255,-18.237190,0.039849,0.000000
32.070000,37.657280,-18.192709,0.018018,0.001538,0.039077,167.507950,8.533262,0.390771,-18.192709,0.040135,0.000000
32.240002,38.401649,-18.237190,0.017992,0.001552,0.039424,170.819061,8.701938,0.394238,-18.237190,0.040412,0.000000
32.410000,39.061127,-18.237190,0.018035,0.001567,0.039797,173.752563,8.851377,0.397970,-18.237190,0.040699,0.000000
32.580002,39.410782,-18.237190,0.018039,0.001575,0.040005,175.307907,8.930611,0.400048,-18.237190,0.040985,0.000000
32.750000,39.799538,-18.237190,0.018048,0.001586,0.040283,177.037186,9.018703,0.402826,-18.237190,0.041263,0.000000
32.920002,40.066528,-18.192709,0.018039,0.001596,0.040534,178.224823,9.079206,0.405340,-18.192709,0.041549,0.000000
33.090000,40.586365,-18.192709,0.018044,0.001606,0.040786,180.537170,9.197002,0.407856,-18.192709,0.041835,0.000000
33.260002,41.406326,-18.237190,0.018061,0.001622,0.041193,184.184540,9.382808,0.411929,-18.237190,0.042112,0.000000
33.430000,41.862106,-18.281672,0.018070,0.001633,0.041479,186.211945,9.486089,0.414794,-18.281672,0.042398,0.000000
33.600002,42.188309,-18.326151,0.018065,0.001640,0.041661,187.662964,9.560008,0.416615,-18.326151,0.042685,0.000000
33.770000,42.384544,-18.281672,0.018104,0.001648,0.041852,188.535873,9.604475,0.418522,-18.281672,0.042962,0.000000
33.940002,43.132271,-18.281672,0.018095,0.001663,0.042251,191.861923,9.773912,0.422512,-18.281672,0.043248,0.000000
34.110001,43.928406,-18.237190,0.018104,0.001678,0.042633,195.403305,9.954319,0.426327,-18.237190,0.043535,0.000000
34.280003,44.699585,-18.237190,0.018113,0.001692,0.042980,198.833679,10.129071,0.429798,-18.237190,0.043812,0.000000
34.450001,44.883537,-18.281672,0.018130,0.001699,0.043144,199.651947,10.170755,0.431444,-18.281672,0.044098,0.000000
34.620003,45.619720,-18.237190,0.018117,0.001713,0.043509,202.926651,10.337577,0.435085,-18.237190,0.044384,0.000000
34.790001,45.893044,-18.281672,0.018130,0.001721,0.043725,204.142456,10.399512,0.437254,-18.281672,0.044662,0.000000
34.960003,46.354408,-18.237190,0.018130,0.001731,0.043977,206.194702,10.504059,0.439767,-18.237190,0.044948,0.000000
35.130001,47.009041,-18.326151,0.018143,0.001746,0.044350,209.106659,10.652400,0.443499,-18.326151,0.045234,0.000000
35.300003,47.625320,-18.326151,0.018130,0.001755,0.044584,211.848007,10.792052,0.445838,-18.326151,0.045512,0.000000
35.470001,48.027481,-18.326151,0.018147,0.001764,0.044809,213.636902,10.883183,0.448094,-18.326151,0.045798,0.000000
35.640003,48.573753,-18.281672,0.018173,0.001777,0.045139,216.066849,11.006969,0.451390,-18.281672,0.046084,0.000000
35.810001,48.849678,-18.281672,0.018169,0.001784,0.045304,217.294220,11.069495,0.453037,-18.281672,0.046370,0.000000
35.980003,49.593681,-18.370632,0.018173,0.001797,0.045651,220.603714,11.238089,0.456508,-18.370632,0.046648,0.000000
36.150002,50.402100,-18.326151,0.018173,0.001814,0.046067,224.199738,11.421279,0.460667,-18.326151,0.046934,0.000000
36.320004,51.314041,-18.326151,0.018208,0.001827,0.046396,228.256256,11.627928,0.463964,-18.326151,0.047220,0.000000
36.490002,51.646942,-18.326151,0.018173,0.001834,0.046587,229.737076,11.703364,0.465871,-18.326151,0.047498,0.000000
36.660000,52.036072,-18.281672,0.018208,0.001844,0.046830,231.468002,11.791542,0.468301,-18.281672,0.047784,0.000000
36.830002,52.375671,-18.370632,0.018203,0.001852,0.047047,232.978622,11.868497,0.470470,-18.370632,0.048070,0.000000
37.000000,52.972961,-18.415113,0.018216,0.001865,0.047368,235.635498,12.003844,0.473676,-18.415113,0.048348,0.000000
37.170002,53.539711,-18.370632,0.018203,0.001875,0.047628,238.156525,12.132272,0.476280,-18.370632,0.048634,0.000000
37.340000,53.991028,-18.326151,0.018225,0.001884,0.047862,240.164093,12.234542,0.478619,-18.326151,0.048920,0.000000
37.510002,54.772636,-18.326151,0.018212,0.001895,0.048122,243.640854,12.411657,0.481223,-18.326151,0.049198,0.000000
37.680000,55.205704,-18.415113,0.018225,0.001904,0.048374,245.567230,12.509791,0.483736,-18.415113,0.049484,0.000000
37.850002,56.165306,-18.326151,0.018225,0.001920,0.048764,249.835754,12.727240,0.487638,-18.326151,0.049770,0.000000
38.020000,56.582367,-18.415113,0.018251,0.001928,0.048972,251.690933,12.821748,0.489720,-18.415113,0.050047,0.000000
38.190002,57.554626,-18.370632,0.018268,0.001942,0.049336,256.015778,13.042065,0.493365,-18.370632,0.050334,0.000000
38.360001,58.343315,-18.370632,0.018285,0.001956,0.049674,259.524017,13.220784,0.496745,-18.370632,0.050620,0.000000
38.530003,59.110771,-18.370632,0.018272,0.001968,0.049987,262.937836,13.394692,0.499867,-18.370632,0.050897,0.000000
38.700001,59.639168,-18.415113,0.018255,0.001979,0.050273,265.288269,13.514429,0.502729,-18.415113,0.051184,0.000000
38.870003,60.174644,-18.370632,0.018285,0.001987,0.050481,267.670197,13.635769,0.504810,-18.370632,0.051470,0.000000
39.040001,60.388008,-18.370632,0.018277,0.001993,0.050629,268.619263,13.684118,0.506287,-18.370632,0.051747,0.000000
39.210003,61.431770,-18.370632,0.018289,0.002009,0.051028,273.262177,13.920638,0.510276,-18.370632,0.052033,0.000000
39.380001,62.052147,-18.415113,0.018289,0.002021,0.051331,276.021729,14.061217,0.513311,-18.415113,0.052320,0.000000
39.550003,62.717201,-18.415113,0.018311,0.002031,0.051582,278.980042,14.211921,0.515824,-18.415113,0.052597,0.000000
39.720001,63.350601,-18.415113,0.018320,0.002042,0.051877,281.797546,14.355452,0.518773,-18.415113,0.052883,0.000000
39.890003,64.208923,-18.415113,0.018298,0.002055,0.052190,285.615570,14.549950,0.521895,-18.415113,0.053169,0.000000
40.060001,64.805099,-18.370632,0.018333,0.002064,0.052424,288.267487,14.685045,0.524238,-18.370632,0.053447,0.000000
40.230003,65.455261,-18.415113,0.018307,0.002077,0.052753,291.159546,14.832374,0.527531,-18.415113,0.053733,0.000000
40.400002,66.482254,-18.459595,0.018333,0.002090,0.053091,295.727844,15.065095,0.530915,-18.459595,0.054020,0.000000
40.570004,67.234085,-18.415113,0.018341,0.002101,0.053360,299.072144,15.235461,0.533602,-18.415113,0.054297,0.000000
40.740002,67.566238,-18.415113,0.018354,0.002100,0.053334,300.549652,15.310728,0.533341,-18.415113,0.053551,0.000000
40.910004,67.200562,-18.415113,0.018363,0.002100,0.053334,298.923035,15.227865,0.533341,-18.415113,0.053551,0.000000
41.080002,66.900055,-18.459595,0.018333,0.002100,0.053334,297.586304,15.159769,0.533341,-18.459595,0.053551,0.000000
41.250004,66.624130,-18.459595,0.018341,0.002098,0.053300,296.358948,15.097244,0.532996,-18.459595,0.053334,0.000000
41.420002,66.391022,-18.504076,0.018363,0.002098,0.053291,295.322021,15.044420,0.532909,-18.504076,0.053334,0.000000
41.590000,66.184357,-18.415113,0.018358,0.002098,0.053282,294.402710,14.997589,0.532822,-18.415113,0.053334,0.000000
41.760002,66.019775,-18.415113,0.018346,0.002097,0.053274,293.670624,14.960295,0.532735,-18.415113,0.053334,0.000000
41.930000,65.836945,-18.415113,0.018367,0.002097,0.053265,292.857361,14.918864,0.532648,-18.415113,0.053334,0.000000
42.100002,65.699158,-18.504076,0.018341,0.002097,0.053265,292.244446,14.887642,0.532648,-18.504076,0.053334,0.000000
42.270000,65.543503,-18.504076,0.018380,0.002097,0.053265,291.552063,14.852370,0.532648,-18.504076,0.053334,0.000000
42.440002,65.436630,-18.504076,0.018371,0.002097,0.053256,291.076660,14.828153,0.532561,-18.504076,0.053334,0.000000
42.610001,65.324921,-18.459595,0.018363,0.002097,0.053256,290.579773,14.802838,0.532561,-18.459595,0.053334,0.000000
42.780003,65.216934,-18.504076,0.018367,0.002097,0.053256,290.099426,14.778368,0.532561,-18.504076,0.053334,0.000000
42.950001,65.108948,-18.504076,0.018376,0.002097,0.053256,289.619049,14.753899,0.532561,-18.504076,0.053334,0.000000
43.120003,65.020325,-18.504076,0.018389,0.002097,0.053256,289.224854,14.733816,0.532561,-18.504076,0.053334,0.000000
43.290001,64.916809,-18.459595,0.018350,0.002096,0.053247,288.764374,14.710359,0.532474,-18.459595,0.053334,0.000000
43.460003,64.831528,-18.504076,0.018380,0.002096,0.053247,288.385040,14.691034,0.532474,-18.504076,0.053334,0.000000
43.630001,64.750351,-18.504076,0.018384,0.002096,0.053247,288.023956,14.672639,0.532474,-18.504076,0.053334,0.000000
43.800003,64.679611,-18.548557,0.018380,0.002096,0.053247,287.709290,14.656610,0.532474,-18.548557,0.053334,0.000000
43.970001,64.600662,-18.504076,0.018384,0.002096,0.053247,287.358093,14.638720,0.532474,-18.504076,0.053334,0.000000
44.140003,64.526566,-18.504076,0.018354,0.002096,0.053247,287.028503,14.621929,0.532474,-18.504076,0.053334,0.000000
44.310001,64.459167,-18.504076,0.018354,0.002096,0.053247,286.728699,14.606656,0.532474,-18.504076,0.053334,0.000000
44.480003,64.413361,-18.504076,0.018354,0.002096,0.053247,286.524933,14.596276,0.532474,-18.504076,0.053334,0.000000
44.650002,64.338882,-18.548557,0.018376,0.002096,0.053239,286.193634,14.579399,0.532387,-18.548557,0.053334,0.000000
44.820004,64.282288,-18.504076,0.018358,0.002096,0.053239,285.941895,14.566574,0.532387,-18.504076,0.053334,0.000000
44.990002,64.234619,-18.548557,0.018371,0.002096,0.053239,285.729858,14.555773,0.532387,-18.548557,0.053334,0.000000
45.160004,64.167221,-18.504076,0.018358,0.002096,0.053239,285.430054,14.540501,0.532387,-18.504076,0.053334,0.000000
45.330002,64.124023,-18.504076,0.018376,0.002096,0.053239,285.237915,14.530711,0.532387,-18.504076,0.053334,0.000000
45.500004,64.082687,-18.548557,0.018363,0.002096,0.053239,285.054016,14.521345,0.532387,-18.548557,0.053334,0.000000
45.670002,64.019760,-18.548557,0.018380,0.002096,0.053239,284.774109,14.507085,0.532387,-18.548557,0.053334,0.000000
45.840004,63.980286,-18.548557,0.018371,0.002096,0.053239,284.598511,14.498140,0.532387,-18.548557,0.053334,0.000000
46.010002,63.937088,-18.593037,0.018358,0.002096,0.053239,284.406372,14.488351,0.532387,-18.593037,0.053334,0.000000
46.180000,63.877884,-18.548557,0.018393,0.002096,0.053239,284.143005,14.474935,0.532387,-18.548557,0.053334,0.000000
46.350002,63.850708,-18.548557,0.018363,0.002096,0.053239,284.022125,14.468777,0.532387,-18.548557,0.053334,0.000000
46.520000,63.796341,-18.593037,0.018397,0.002096,0.053239,283.780304,14.456458,0.532387,-18.593037,0.053334,0.000000
46.690002,63.765060,-18.548557,0.018380,0.002096,0.053239,283.641144,14.449369,0.532387,-18.548557,0.053334,0.000000
46.860001,63.712921,-18.504076,0.018376,0.002096,0.053239,283.409241,14.437554,0.532387,-18.504076,0.053334,0.000000
47.030003,63.680908,-18.504076,0.018367,0.002096,0.053239,283.266815,14.430300,0.532387,-18.504076,0.053334,0.000000
47.200001,63.644409,-18.637518,0.018371,0.002096,0.053239,283.104462,14.422029,0.532387,-18.637518,0.053334,0.000000
47.370003,63.621689,-18.637518,0.018380,0.002096,0.053239,283.003418,14.416881,0.532387,-18.637518,0.053334,0.000000
47.540001,63.576263,-18.593037,0.018367,0.002096,0.053239,282.801331,14.406588,0.532387,-18.593037,0.053334,0.000000
47.710003,63.537537,-18.548557,0.018380,0.002096,0.053239,282.629089,14.397811,0.532387,-18.548557,0.053334,0.000000
47.880001,63.516678,-18.593037,0.018380,0.002096,0.053239,282.536285,14.393085,0.532387,-18.593037,0.053334,0.000000
48.050003,63.475723,-18.548557,0.018371,0.002096,0.053239,282.354126,14.383804,0.532387,-18.548557,0.053334,0.000000
48.220001,63.435883,-18.593037,0.018380,0.002096,0.053239,282.176910,14.374777,0.532387,-18.593037,0.053334,0.000000
48.390003,63.423965,-18.637518,0.018371,0.002096,0.053239,282.123901,14.372076,0.532387,-18.637518,0.053334,0.000000
48.560001,63.378540,-18.548557,0.018371,0.002096,0.053239,281.921814,14.361782,0.532387,-18.548557,0.053334,0.000000
48.730003,63.363647,-18.593037,0.018358,0.002096,0.053239,281.855591,14.358408,0.532387,-18.593037,0.053334,0.000000
48.900002,63.315598,-18.681999,0.018371,0.002096,0.053239,281.641846,14.347520,0.532387,-18.681999,0.053334,0.000000
49.070004,63.286194,-18.637518,0.018367,0.002096,0.053230,281.511047,14.340857,0.532300,-18.637518,0.053334,0.000000
49.240002,63.274277,-18.637518,0.018371,0.002096,0.053230,281.458038,14.338156,0.532300,-18.637518,0.053334,0.000000
49.410004,63.227356,-18.637518,0.018384,0.002096,0.053230,281.249329,14.327523,0.532300,-18.637518,0.053334,0.000000
49.580002,63.224747,-18.593037,0.018393,0.002096,0.053230,281.237732,14.326932,0.532300,-18.593037,0.053334,0.000000
49.750004,63.178192,-18.637518,0.018376,0.002096,0.053230,281.030640,14.316383,0.532300,-18.637518,0.053334,0.000000
49.920002,63.155106,-18.681999,0.018389,0.002096,0.053230,280.927948,14.311152,0.532300,-18.681999,0.053334,0.000000
50.090004,63.120483,-18.681999,0.018376,0.002096,0.053230,280.773926,14.303306,0.532300,-18.681999,0.053334,0.000000
50.260002,63.104095,-18.637518,0.018389,0.002096,0.053230,280.701050,14.299593,0.532300,-18.637518,0.053334,0.000000
50.430004,63.095154,-18.637518,0.018363,0.002096,0.053230,280.661255,14.297566,0.532300,-18.637518,0.053334,0.000000
50.600002,63.062759,-18.593037,0.018397,0.002096,0.053230,280.517151,14.290226,0.532300,-18.593037,0.053334,0.000000
50.770004,63.033722,-18.681999,0.018376,0.002096,0.053230,280.388000,14.283646,0.532300,-18.681999,0.053334,0.000000
50.940002,63.022919,-18.637518,0.018371,0.002096,0.053230,280.339935,14.281198,0.532300,-18.637518,0.053334,0.000000
51.110001,62.975632,-18.637518,0.018389,0.002096,0.053230,280.129608,14.270482,0.532300,-18.637518,0.053334,0.000000
51.280003,62.971527,-18.637518,0.018376,0.002096,0.053230,280.111328,14.269552,0.532300,-18.637518,0.053334,0.000000
51.450001,62.942490,-18.637518,0.018371,0.002096,0.053230,279.982178,14.262972,0.532300,-18.637518,0.053334,0.000000
51.620003,62.920883,-18.726480,0.018367,0.002096,0.053230,279.886078,14.258077,0.532300,-18.726480,0.053334,0.000000
51.790001,62.905991,-18.726480,0.018371,0.002096,0.053230,279.819824,14.254701,0.532300,-18.726480,0.053334,0.000000
51.960003,62.874344,-18.681999,0.018380,0.002096,0.053230,279.679047,14.247530,0.532300,-18.681999,0.053334,0.000000
52.130001,62.867264,-18.681999,0.018380,0.002096,0.053230,279.647552,14.245926,0.532300,-18.681999,0.053334,0.000000
52.300003,62.840836,-18.681999,0.018358,0.002096,0.053230,279.529999,14.239937,0.532300,-18.681999,0.053334,0.000000
52.470001,62.821091,-18.726480,0.018376,0.002096,0.053230,279.442169,14.235463,0.532300,-18.726480,0.053334,0.000000
52.640003,62.789810,-18.770962,0.018376,0.002096,0.053230,279.303040,14.228374,0.532300,-18.770962,0.053334,0.000000
52.810001,62.783859,-18.681999,0.018384,0.002096,0.053230,279.276550,14.227026,0.532300,-18.681999,0.053334,0.000000
52.980003,62.758911,-18.726480,0.018389,0.002096,0.053230,279.165588,14.221373,0.532300,-18.726480,0.053334,0.000000
53.150002,62.750336,-18.681999,0.018371,0.002096,0.053230,279.127441,14.219430,0.532300,-18.681999,0.053334,0.000000
53.320004,62.716087,-18.770962,0.018397,0.002096,0.053230,278.975098,14.211668,0.532300,-18.770962,0.053334,0.000000
53.490002,62.713478,-18.815443,0.018350,0.002096,0.053230,278.963470,14.211078,0.532300,-18.815443,0.053334,0.000000
53.660004,62.698586,-18.770962,0.018389,0.002096,0.053230,278.897247,14.207703,0.532300,-18.770962,0.053334,0.000000
53.830002,62.666183,-18.726480,0.018376,0.002096,0.053230,278.753113,14.200360,0.532300,-18.726480,0.053334,0.000000
54.000004,62.659485,-18.770962,0.018389,0.002096,0.053230,278.723297,14.198842,0.532300,-18.770962,0.053334,0.000000
54.170002,62.639000,-18.815443,0.018393,0.002096,0.053230,278.632202,14.194201,0.532300,-18.815443,0.053334,0.000000
54.340004,62.620010,-18.815443,0.018393,0.002096,0.053230,278.547729,14.189898,0.532300,-18.815443,0.053334,0.000000
54.510002,62.598412,-18.770962,0.018380,0.002096,0.053230,278.451630,14.185003,0.532300,-18.770962,0.053334,0.000000
54.680004,62.583519,-18.770962,0.018389,0.002096,0.053230,278.385406,14.181628,0.532300,-18.770962,0.053334,0.000000
54.850002,62.562668,-18.770962,0.018389,0.002096,0.053230,278.292633,14.176904,0.532300,-18.770962,0.053334,0.000000
55.020004,62.567505,-18.815443,0.018376,0.002096,0.053230,278.314148,14.177999,0.532300,-18.815443,0.053334,0.000000
55.190002,62.535858,-18.726480,0.018380,0.002096,0.053230,278.173401,14.170828,0.532300,-18.726480,0.053334,0.000000
55.360004,62.529900,-18.815443,0.018389,0.002096,0.053230,278.146881,14.169478,0.532300,-18.815443,0.053334,0.000000
55.530003,62.508301,-18.770962,0.018393,0.002096,0.053230,278.050812,14.164583,0.532300,-18.770962,0.053334,0.000000
55.700001,62.482979,-18.726480,0.018397,0.002096,0.053230,277.938171,14.158846,0.532300,-18.726480,0.053334,0.000000
55.870003,62.471809,-18.815443,0.018389,0.002096,0.053230,277.888489,14.156315,0.532300,-18.815443,0.053334,0.000000
56.040001,62.461380,-18.859922,0.018393,0.002096,0.053230,277.842102,14.153952,0.532300,-18.859922,0.053334,0.000000
56.210003,62.458405,-18.770962,0.018380,0.002096,0.053230,277.828857,14.153276,0.532300,-18.770962,0.053334,0.000000
56.380001,62.418930,-18.815443,0.018384,0.002096,0.053230,277.653259,14.144332,0.532300,-18.815443,0.053334,0.000000
56.550003,62.412231,-18.815443,0.018393,0.002096,0.053230,277.623474,14.142814,0.532300,-18.815443,0.053334,0.000000
56.720001,62.407387,-18.859922,0.018380,0.002096,0.053230,277.601929,14.141715,0.532300,-18.859922,0.053334,0.000000
56.890003,62.382812,-18.859922,0.018384,0.002096,0.053230,277.492615,14.136147,0.532300,-18.859922,0.053334,0.000000
57.060001,62.377602,-18.859922,0.018384,0.002096,0.053230,277.469421,14.134967,0.532300,-18.859922,0.053334,0.000000
57.230003,62.351906,-18.859922,0.018380,0.002096,0.053230,277.355133,14.129144,0.532300,-18.859922,0.053334,0.000000
57.400002,62.347061,-18.815443,0.018376,0.002096,0.053230,277.333588,14.128046,0.532300,-18.815443,0.053334,0.000000
57.570004,62.338127,-18.815443,0.018363,0.002096,0.053230,277.293854,14.126021,0.532300,-18.815443,0.053334,0.000000
57.740002,62.308708,-18.859922,0.018380,0.002096,0.053230,277.162964,14.119355,0.532300,-18.859922,0.053334,0.000000
57.910004,62.304611,-18.859922,0.018384,0.002096,0.053230,277.144745,14.118426,0.532300,-18.859922,0.053334,0.000000
58.080002,62.290466,-18.815443,0.018410,0.002096,0.053230,277.081818,14.115221,0.532300,-18.815443,0.053334,0.000000
58.250004,62.269234,-18.815443,0.018384,0.002096,0.053230,276.987396,14.110411,0.532300,-18.815443,0.053334,0.000000
58.420002,62.263283,-18.859922,0.018397,0.002096,0.053230,276.960907,14.109061,0.532300,-18.859922,0.053334,0.000000
58.590004,62.244659,-18.904404,0.018354,0.002096,0.053230,276.878082,14.104842,0.532300,-18.904404,0.053334,0.000000
58.760002,62.226784,-18.859922,0.018376,0.002096,0.053230,276.798553,14.100791,0.532300,-18.859922,0.053334,0.000000
58.930004,62.232002,-18.815443,0.018393,0.002096,0.053230,276.821777,14.101973,0.532300,-18.815443,0.053334,0.000000
59.100002,62.212639,-18.859922,0.018389,0.002096,0.053230,276.735626,14.097586,0.532300,-18.859922,0.053334,0.000000
59.270004,62.201836,-18.859922,0.018397,0.002096,0.053230,276.687592,14.095138,0.532300,-18.859922,0.053334,0.000000
59.440002,62.187691,-18.904404,0.018389,0.002096,0.053230,276.624664,14.091932,0.532300,-18.904404,0.053334,0.000000
59.610004,62.174286,-18.904404,0.018393,0.002096,0.053230,276.565033,14.088895,0.532300,-18.904404,0.053334,0.000000
59.780003,62.165344,-18.859922,0.018389,0.002096,0.053230,276.525269,14.086868,0.532300,-18.859922,0.053334,0.000000
59.950005,62.147102,-18.859922,0.018393,0.002096,0.053230,276.444122,14.082735,0.532300,-18.859922,0.053334,0.000000
60.120003,62.148216,-18.948885,0.018380,0.002096,0.053230,276.449066,14.082987,0.532300,-18.948885,0.053334,0.000000
60.290005,62.129601,-18.993366,0.018376,0.002096,0.053230,276.366272,14.078769,0.532300,-18.993366,0.053334,0.000000
60.460003,62.122520,-18.904404,0.018376,0.002096,0.053230,276.334778,14.077165,0.532300,-18.904404,0.053334,0.000000
60.630001,62.091614,-18.948885,0.018376,0.002096,0.053230,276.197296,14.070161,0.532300,-18.948885,0.053334,0.000000
60.800003,62.101669,-18.904404,0.018389,0.002096,0.053230,276.242035,14.072439,0.532300,-18.904404,0.053334,0.000000
60.970001,62.084541,-18.859922,0.018376,0.002096,0.053230,276.165833,14.068558,0.532300,-18.859922,0.053334,0.000000
61.140003,62.082306,-18.993366,0.018380,0.002096,0.053230,276.155884,14.068051,0.532300,-18.993366,0.053334,0.000000
61.310001,62.060707,-18.993366,0.018384,0.002096,0.053230,276.059814,14.063157,0.532300,-18.993366,0.053334,0.000000
61.480003,62.053261,-18.904404,0.018402,0.002096,0.053230,276.026703,14.061470,0.532300,-18.904404,0.053334,0.000000
61.650002,62.044701,-18.948885,0.018380,0.002096,0.053230,275.988617,14.059530,0.532300,-18.948885,0.053334,0.000000
61.820004,62.028687,-18.904404,0.018406,0.002096,0.053230,275.917389,14.055901,0.532300,-18.904404,0.053334,0.000000
61.990002,62.017883,-18.904404,0.018380,0.002096,0.053230,275.869324,14.053453,0.532300,-18.904404,0.053334,0.000000
62.160004,62.003365,-18.948885,0.018363,0.002096,0.053230,275.804749,14.050163,0.532300,-18.948885,0.053334,0.000000
62.330002,61.999268,-18.904404,0.018389,0.002096,0.053230,275.786530,14.049234,0.532300,-18.904404,0.053334,0.000000
62.500004,61.984375,-18.904404,0.018397,0.002095,0.053222,275.720276,14.045860,0.532217,-18.904404,0.053334,0.000000
62.670002,61.983253,-18.948885,0.018384,0.002095,0.053222,275.715271,14.045606,0.532217,-18.948885,0.053334,0.000000
62.840004,61.974319,-18.948885,0.018393,0.002095,0.053222,275.675537,14.043582,0.532217,-18.948885,0.053334,0.000000
63.010002,61.961655,-18.993366,0.018380,0.002095,0.053222,275.619202,14.040712,0.532217,-18.993366,0.053334,0.000000
63.180004,61.945648,-18.993366,0.018393,0.002095,0.053222,275.548004,14.037085,0.532217,-18.993366,0.053334,0.000000
63.350002,61.946388,-18.948885,0.018376,0.002095,0.053222,275.551300,14.037252,0.532217,-18.948885,0.053334,0.000000
63.520004,61.927399,-18.948885,0.018397,0.002095,0.053222,275.466827,14.032948,0.532217,-18.948885,0.053334,0.000000
63.690002,61.911385,-18.993366,0.018406,0.002095,0.053222,275.395599,14.029321,0.532217,-18.993366,0.053334,0.000000
63.860004,61.900589,-18.993366,0.018384,0.002095,0.053222,275.347565,14.026874,0.532217,-18.993366,0.053334,0.000000
64.030006,61.887932,-18.993366,0.018393,0.002095,0.053222,275.291260,14.024006,0.532217,-18.993366,0.053334,0.000000
64.200005,61.886063,-18.948885,0.018384,0.002095,0.053222,275.282959,14.023582,0.532217,-18.948885,0.053334,0.000000
64.370003,61.880478,-18.948885,0.018384,0.002095,0.053222,275.258118,14.022316,0.532217,-18.948885,0.053334,0.000000
64.540001,61.860374,-19.037848,0.018384,0.002095,0.053222,275.168701,14.017761,0.532217,-19.037848,0.053334,0.000000
64.710007,61.851433,-19.037848,0.018402,0.002095,0.053222,275.128906,14.015736,0.532217,-19.037848,0.053334,0.000000
64.880005,61.848457,-18.993366,0.018380,0.002095,0.053222,275.115692,14.015060,0.532217,-18.993366,0.053334,0.000000
65.050003,61.832443,-18.948885,0.018397,0.002095,0.053222,275.044434,14.011432,0.532217,-18.948885,0.053334,0.000000
65.220001,61.831329,-18.948885,0.018384,0.002095,0.053222,275.039490,14.011180,0.532217,-18.948885,0.053334,0.000000
65.389999,61.824997,-18.993366,0.018393,0.002095,0.053222,275.011322,14.009745,0.532217,-18.993366,0.053334,0.000000
65.560005,61.819786,-18.993366,0.018384,0.002095,0.053222,274.988129,14.008563,0.532217,-18.993366,0.053334,0.000000
65.730003,61.790741,-19.037848,0.018384,0.002095,0.053222,274.858948,14.001983,0.532217,-19.037848,0.053334,0.000000
65.900002,61.790367,-18.948885,0.018397,0.002095,0.053222,274.857269,14.001897,0.532217,-18.948885,0.053334,0.000000
66.070000,61.773979,-18.993366,0.018384,0.002095,0.053222,274.784393,13.998184,0.532217,-18.993366,0.053334,0.000000
66.240005,61.767654,-19.082329,0.018380,0.002095,0.053222,274.756256,13.996751,0.532217,-19.082329,0.053334,0.000000
66.410004,61.757225,-19.037848,0.018371,0.002095,0.053222,274.709869,13.994388,0.532217,-19.037848,0.053334,0.000000
66.580002,61.768768,-18.993366,0.018397,0.002095,0.053222,274.761200,13.997003,0.532217,-18.993366,0.053334,0.000000
66.750000,61.737488,-19.037848,0.018393,0.002095,0.053222,274.622070,13.989915,0.532217,-19.037848,0.053334,0.000000
66.920006,61.751266,-19.037848,0.018402,0.002095,0.053222,274.683350,13.993036,0.532217,-19.037848,0.053334,0.000000
67.090004,61.732651,-19.037848,0.018384,0.002095,0.053222,274.600555,13.988819,0.532217,-19.037848,0.053334,0.000000
67.260002,61.715149,-19.037848,0.018389,0.002095,0.053222,274.522705,13.984852,0.532217,-19.037848,0.053334,0.000000
67.430000,61.713287,-19.082329,0.018393,0.002095,0.053222,274.514404,13.984431,0.532217,-19.082329,0.053334,0.000000
67.600006,61.700623,-19.082329,0.018393,0.002095,0.053222,274.458069,13.981561,0.532217,-19.082329,0.053334,0.000000
67.770004,61.687592,-19.037848,0.018414,0.002095,0.053222,274.400116,13.978608,0.532217,-19.037848,0.053334,0.000000
67.940002,61.685730,-19.082329,0.018384,0.002095,0.053222,274.391846,13.978186,0.532217,-19.082329,0.053334,0.000000
68.110001,61.673439,-19.082329,0.018397,0.002095,0.053222,274.337158,13.975401,0.532217,-19.082329,0.053334,0.000000
68.280006,61.661896,-19.171289,0.018384,0.002095,0.053222,274.285797,13.972785,0.532217,-19.171289,0.053334,0.000000
68.450005,61.664879,-19.082329,0.018389,0.002095,0.053222,274.299072,13.973462,0.532217,-19.082329,0.053334,0.000000
68.620003,61.653709,-19.082329,0.018397,0.002095,0.053222,274.249390,13.970930,0.532217,-19.082329,0.053334,0.000000
68.790001,61.649612,-19.082329,0.018389,0.002095,0.053222,274.231171,13.970002,0.532217,-19.082329,0.053334,0.000000
68.960007,61.626892,-19.082329,0.018397,0.002095,0.053222,274.130096,13.964853,0.532217,-19.082329,0.053334,0.000000
69.130005,61.633972,-19.082329,0.018410,0.002095,0.053222,274.161591,13.966457,0.532217,-19.082329,0.053334,0.000000
69.300003,61.622055,-19.126808,0.018423,0.002095,0.053222,274.108582,13.963757,0.532217,-19.126808,0.053334,0.000000
69.470001,61.626892,-19.037848,0.018397,0.002095,0.053222,274.130096,13.964853,0.532217,-19.037848,0.053334,0.000000
69.640007,61.607162,-19.126808,0.018389,0.002095,0.053222,274.042358,13.960382,0.532217,-19.126808,0.053334,0.000000
69.810005,61.594872,-19.215771,0.018376,0.002095,0.053222,273.987671,13.957597,0.532217,-19.215771,0.053334,0.000000
69.980003,61.579231,-19.171289,0.018397,0.002095,0.053222,273.918091,13.954053,0.532217,-19.171289,0.053334,0.000000
70.150002,61.592636,-19.126808,0.018419,0.002095,0.053222,273.977722,13.957090,0.532217,-19.126808,0.053334,0.000000
70.320000,61.568802,-19.126808,0.018380,0.002095,0.053222,273.871704,13.951690,0.532217,-19.126808,0.053334,0.000000
70.490005,61.580719,-19.126808,0.018389,0.002095,0.053222,273.924713,13.954391,0.532217,-19.126808,0.053334,0.000000
70.660004,61.550560,-19.126808,0.018384,0.002095,0.053222,273.790558,13.947556,0.532217,-19.126808,0.053334,0.000000
70.830002,61.561356,-19.126808,0.018389,0.002095,0.053222,273.838593,13.950002,0.532217,-19.126808,0.053334,0.000000
71.000000,61.546837,-19.171289,0.018402,0.002095,0.053222,273.774017,13.946713,0.532217,-19.171289,0.053334,0.000000
71.100006,61.530823,-19.171289,0.018397,0.002095,0.053222,273.702759,13.943084,0.532217,-19.171289,0.053334,0.000000