File: Data/I-18_1_5_07282023_142425.csv
Time (sec),S:Load (lbs),S:HL1 (DIM),S:LVDT (in),S:Position (in),Ch:Position (mm),Ch:Load (N),Ch:Stress (MPa),Ch:Strain (mm/mm),Ch:HL1 (DIM),Set Point (),Cycles ()
0.110000,0.017129,-3.425033,0.000004,-0.000000,-0.000000,0.076194,0.003882,-0.000000,-3.425033,0.000078,0.000000
0.350000,0.001862,-3.425033,0.000009,-0.000000,-0.000000,0.008282,0.000422,-0.000000,-3.425033,0.000078,0.000000
0.590000,0.001862,-3.425033,0.000017,0.000110,0.002784,0.008282,0.000422,0.027842,-3.425033,0.003495,0.000000
0.830000,0.004841,-3.425033,0.000013,0.000255,0.006478,0.021533,0.001097,0.064782,-3.425033,0.007484,0.000000
1.070000,0.013405,-3.425033,0.000125,0.000410,0.010407,0.059630,0.003038,0.104069,-3.425033,0.011491,0.000000
1.310000,0.008192,-3.425033,0.000293,0.000567,0.014414,0.036441,0.001856,0.144136,-3.425033,0.015480,0.000000
1.550000,0.013033,-3.336071,0.000453,0.000725,0.018420,0.057974,0.002953,0.184203,-3.336071,0.019487,0.000000
1.790000,0.026811,-3.469514,0.000612,0.000883,0.022418,0.119261,0.006075,0.224179,-3.469514,0.023476,0.000000
2.030000,0.044312,-3.425033,0.000763,0.001031,0.026191,0.197111,0.010041,0.261907,-3.425033,0.027483,0.000000
2.270000,0.040589,-3.425033,0.000892,0.001194,0.030327,0.180547,0.009198,0.303268,-3.425033,0.031472,0.000000
2.510000,0.017502,-3.380552,0.001074,0.001354,0.034403,0.077851,0.003966,0.344032,-3.380552,0.035478,0.000000
2.750000,0.013405,-3.336071,0.001216,0.001506,0.038262,0.059630,0.003038,0.382623,-3.336071,0.039467,0.000000
2.990000,0.037982,-3.380552,0.001388,0.001667,0.042330,0.168952,0.008607,0.423295,-3.380552,0.043474,0.000000
3.230000,0.025321,-3.380552,0.001556,0.001828,0.046422,0.112635,0.005738,0.464225,-3.380552,0.047481,0.000000
3.470000,0.026811,-3.380552,0.001699,0.001981,0.050308,0.119261,0.006075,0.503081,-3.380552,0.051470,0.000000
3.710000,0.042823,-3.291590,0.001858,0.002140,0.054349,0.190485,0.009704,0.543488,-3.291590,0.055477,0.000000
3.950000,0.037982,-3.336071,0.002022,0.002297,0.058347,0.168952,0.008607,0.583472,-3.336071,0.059466,0.000000
4.190000,0.060324,-3.291590,0.002164,0.002444,0.062085,0.268336,0.013670,0.620851,-3.291590,0.063473,0.000000
4.430000,0.052877,-3.291590,0.002341,0.002616,0.066447,0.235208,0.011982,0.664469,-3.291590,0.067462,0.000000
4.670000,0.040589,-3.336071,0.002492,0.002768,0.070315,0.180547,0.009198,0.703150,-3.336071,0.071468,0.000000
4.910000,0.038727,-3.336071,0.002643,0.002922,0.074217,0.172265,0.008776,0.742172,-3.336071,0.075457,0.000000
5.150000,0.043940,-3.247109,0.002802,0.003080,0.078224,0.195455,0.009957,0.782239,-3.247109,0.079464,0.000000
5.390000,0.027183,-3.291590,0.002975,0.003243,0.082378,0.120917,0.006160,0.823782,-3.291590,0.083453,0.000000
5.630000,-0.010799,-3.247109,0.003126,0.003393,0.086193,-0.048036,-0.002447,0.861934,-3.247109,0.087460,0.000000
5.870000,0.051015,-3.291590,0.003277,0.003555,0.090295,0.226926,0.011560,0.902955,-3.291590,0.091449,0.000000
6.110000,0.076336,-3.291590,0.003454,0.003706,0.094120,0.339561,0.017298,0.941205,-3.291590,0.095456,0.000000
6.350000,0.070751,-3.247109,0.003587,0.003868,0.098257,0.314715,0.016032,0.982566,-3.247109,0.099445,0.000000
6.590000,0.055484,-3.202628,0.003777,0.004027,0.102298,0.246803,0.012573,1.022981,-3.202628,0.103452,0.000000
6.830000,0.048408,-3.202628,0.003923,0.004188,0.106365,0.215332,0.010970,1.063654,-3.202628,0.107441,0.000000
7.070000,0.065165,-3.202628,0.004057,0.004338,0.110190,0.289869,0.014767,1.101897,-3.202628,0.111447,0.000000
7.310000,0.038727,-3.202628,0.004221,0.004497,0.114231,0.172265,0.008776,1.142312,-3.202628,0.115436,0.000000
7.550000,-0.002234,-3.158148,0.004389,0.004657,0.118290,-0.009938,-0.000506,1.182901,-3.158148,0.119443,0.000000
7.790000,0.001117,-3.158148,0.004531,0.004812,0.122235,0.004969,0.000253,1.222355,-3.158148,0.123450,0.000000
8.030001,0.068144,-3.113667,0.004708,0.004965,0.126104,0.303120,0.015442,1.261036,-3.113667,0.127439,0.000000
8.270000,0.090114,-3.202628,0.004850,0.005118,0.129998,0.400848,0.020420,1.299975,-3.202628,0.131446,0.000000
8.510000,0.068889,-3.158148,0.005032,0.005289,0.134333,0.306433,0.015610,1.343335,-3.158148,0.135435,0.000000
8.750000,0.072985,-3.158148,0.005178,0.005445,0.138305,0.324653,0.016539,1.383054,-3.158148,0.139442,0.000000
8.990001,0.051387,-3.158148,0.005351,0.005602,0.142286,0.228583,0.011645,1.422856,-3.158148,0.143431,0.000000
9.230000,0.072613,-3.113667,0.005493,0.005753,0.146128,0.322997,0.016454,1.461280,-3.113667,0.147438,0.000000
9.470000,0.048408,-3.113667,0.005670,0.005918,0.150325,0.215332,0.010970,1.503254,-3.113667,0.151426,0.000000
9.710000,-0.002979,-3.069186,0.005838,0.006073,0.154262,-0.013251,-0.000675,1.542625,-3.069186,0.155433,0.000000
9.950001,0.065165,-3.024705,0.006010,0.006235,0.158365,0.289869,0.014767,1.583645,-3.024705,0.159422,0.000000
10.190001,0.083039,-3.024705,0.006153,0.006384,0.162154,0.369376,0.018817,1.621540,-3.024705,0.163429,0.000000
10.430000,0.090859,-3.024705,0.006295,0.006549,0.166351,0.404160,0.020589,1.663514,-3.024705,0.167418,0.000000
10.670000,0.064793,-3.024705,0.006480,0.006705,0.170306,0.288213,0.014682,1.703059,-3.024705,0.171425,0.000000
10.910001,0.081177,-2.980224,0.006614,0.006864,0.174356,0.361094,0.018395,1.743557,-2.980224,0.175414,0.000000
11.150001,0.084529,-2.980224,0.006769,0.007016,0.178206,0.376002,0.019154,1.782065,-2.980224,0.179421,0.000000
11.390000,0.074847,-2.980224,0.006929,0.007180,0.182360,0.332935,0.016961,1.823600,-2.980224,0.183410,0.000000
11.630000,0.041333,-2.935743,0.007067,0.007333,0.186254,0.183860,0.009366,1.862539,-2.935743,0.187417,0.000000
11.870001,0.064420,-2.980224,0.007235,0.007492,0.190295,0.286557,0.014598,1.902954,-2.980224,0.191406,0.000000
12.110001,0.115435,-2.980224,0.007394,0.007646,0.194215,0.513483,0.026158,1.942151,-2.980224,0.195412,0.000000
12.350000,0.087135,-2.935743,0.007541,0.007801,0.198144,0.387597,0.019745,1.981438,-2.935743,0.199401,0.000000
12.590000,0.051760,-2.935743,0.007722,0.007967,0.202367,0.230239,0.011729,2.023670,-2.935743,0.203408,0.000000
12.830001,0.083784,-2.891262,0.007881,0.008120,0.206243,0.372689,0.018986,2.062435,-2.891262,0.207415,0.000000
13.070001,0.089369,-2.980224,0.008045,0.008279,0.210294,0.397535,0.020251,2.102941,-2.980224,0.211404,0.000000
13.310000,0.066655,-2.891262,0.008218,0.008439,0.214352,0.296495,0.015104,2.143522,-2.891262,0.215410,0.000000
13.550000,0.057345,-2.846781,0.008373,0.008595,0.218307,0.255085,0.012995,2.183067,-2.846781,0.219400,0.000000
13.790001,0.025694,-2.891262,0.008558,0.008746,0.222157,0.114291,0.005822,2.221574,-2.891262,0.223406,0.000000
14.030001,0.075219,-2.802300,0.008714,0.008905,0.226190,0.334592,0.017045,2.261899,-2.802300,0.227396,0.000000
14.270000,0.088625,-2.891262,0.008873,0.009059,0.230093,0.394222,0.020083,2.300929,-2.891262,0.231402,0.000000
14.510000,0.098306,-2.802300,0.009054,0.009225,0.234316,0.437288,0.022277,2.343160,-2.802300,0.235391,0.000000
14.750001,0.063303,-2.802300,0.009209,0.009382,0.238296,0.281587,0.014345,2.382962,-2.802300,0.239398,0.000000
14.990001,0.090114,-2.757819,0.009356,0.009541,0.242338,0.400848,0.020420,2.423378,-2.757819,0.243387,0.000000
15.230000,0.102030,-2.802300,0.009520,0.009694,0.246240,0.453852,0.023120,2.462400,-2.802300,0.247394,0.000000
15.470000,0.068144,-2.757819,0.009671,0.009857,0.250369,0.303120,0.015442,2.503685,-2.757819,0.251383,0.000000
15.710001,0.048408,-2.713338,0.009826,0.010010,0.254245,0.215332,0.010970,2.542450,-2.713338,0.255390,0.000000
15.950001,0.078943,-2.757819,0.009968,0.010166,0.258225,0.351156,0.017889,2.582252,-2.757819,0.259379,0.000000
16.190001,0.092348,-2.757819,0.010141,0.010322,0.262171,0.410786,0.020926,2.621713,-2.757819,0.263386,0.000000
16.430000,0.098679,-2.668857,0.010287,0.010480,0.266204,0.438945,0.022361,2.662038,-2.668857,0.267375,0.000000
16.670000,0.064793,-2.713338,0.010473,0.010643,0.270323,0.288213,0.014682,2.703233,-2.713338,0.271381,0.000000
16.910002,0.081177,-2.668857,0.010624,0.010800,0.274313,0.361094,0.018395,2.743125,-2.668857,0.275370,0.000000
17.150002,0.102775,-2.713338,0.010796,0.010952,0.278172,0.457165,0.023289,2.781716,-2.713338,0.279377,0.000000
17.390001,0.096444,-2.624376,0.010964,0.011120,0.282447,0.429007,0.021855,2.824470,-2.624376,0.283383,0.000000
17.630001,0.066655,-2.624376,0.011111,0.011272,0.286297,0.296495,0.015104,2.862970,-2.624376,0.287373,0.000000
17.870001,0.059952,-2.713338,0.011283,0.011424,0.290165,0.266680,0.013585,2.901652,-2.713338,0.291379,0.000000
18.110001,0.090859,-2.579895,0.011447,0.011584,0.294224,0.404160,0.020589,2.942241,-2.579895,0.295369,0.000000
18.350000,0.084529,-2.668857,0.011602,0.011741,0.298222,0.376002,0.019154,2.982217,-2.668857,0.299375,0.000000
18.590000,0.083039,-2.624376,0.011783,0.011903,0.302332,0.369376,0.018817,3.023321,-2.624376,0.303365,0.000000
18.830002,0.071868,-2.624376,0.011943,0.012057,0.306253,0.319684,0.016285,3.062525,-2.624376,0.307371,0.000000
19.070002,0.081922,-2.668857,0.012098,0.012215,0.310259,0.364407,0.018564,3.102592,-2.668857,0.311360,0.000000
19.310001,0.092721,-2.535414,0.012262,0.012367,0.314118,0.412442,0.021011,3.141183,-2.535414,0.315367,0.000000
19.550001,0.105009,-2.579895,0.012452,0.012534,0.318376,0.467104,0.023795,3.183763,-2.579895,0.319356,0.000000
19.790001,0.061814,-2.490933,0.012607,0.012686,0.322218,0.274962,0.014007,3.222179,-2.490933,0.323362,0.000000
20.030001,0.088625,-2.490933,0.012753,0.012843,0.326207,0.394222,0.020083,3.262072,-2.490933,0.327352,0.000000
20.270000,0.090487,-2.579895,0.012913,0.013002,0.330240,0.402504,0.020505,3.302397,-2.579895,0.331358,0.000000
20.510000,0.083039,-2.401971,0.013073,0.013161,0.334281,0.369376,0.018817,3.342812,-2.401971,0.335348,0.000000
20.750002,0.082667,-2.490933,0.013223,0.013319,0.338296,0.367720,0.018733,3.382962,-2.490933,0.339354,0.000000
20.990002,0.098306,-2.446452,0.013374,0.013477,0.342320,0.437288,0.022277,3.423203,-2.446452,0.343344,0.000000
21.230001,0.115808,-2.401971,0.013530,0.013625,0.346075,0.515139,0.026242,3.460749,-2.401971,0.347350,0.000000
21.470001,0.114318,-2.446452,0.013698,0.013794,0.350377,0.508514,0.025905,3.503768,-2.446452,0.351340,0.000000
21.710001,0.091604,-2.357490,0.013849,0.013949,0.354296,0.407473,0.020758,3.542964,-2.357490,0.355346,0.000000
21.950001,0.096817,-2.401971,0.013991,0.014100,0.358138,0.430663,0.021939,3.581381,-2.401971,0.359352,0.000000
22.190001,0.112457,-2.357490,0.014159,0.014259,0.362188,0.500232,0.025483,3.621880,-2.357490,0.363342,0.000000
22.430000,0.106499,-2.357490,0.014310,0.014424,0.366368,0.473729,0.024133,3.663680,-2.357490,0.367348,0.000000
22.670002,0.075592,-2.357490,0.014465,0.014574,0.370184,0.336248,0.017129,3.701839,-2.357490,0.371338,0.000000
22.910002,0.110595,-2.357490,0.014629,0.014737,0.374312,0.491949,0.025061,3.743125,-2.357490,0.375344,0.000000
23.150002,0.119532,-2.313010,0.014776,0.014888,0.378145,0.531703,0.027086,3.781451,-2.313010,0.379334,0.000000
23.390001,0.142619,-2.313010,0.014926,0.015042,0.382074,0.634399,0.032318,3.820738,-2.313010,0.383340,0.000000
23.630001,0.121766,-2.268528,0.015112,0.015209,0.386314,0.541641,0.027593,3.863144,-2.268528,0.387329,0.000000
23.870001,0.101658,-2.268528,0.015271,0.015368,0.390338,0.452196,0.023036,3.903385,-2.268528,0.391335,0.000000
24.110001,0.124000,-2.135086,0.015435,0.015519,0.394172,0.551580,0.028099,3.941718,-2.135086,0.395325,0.000000
24.350000,0.107243,-2.224048,0.015608,0.015676,0.398169,0.477042,0.024302,3.981694,-2.224048,0.399331,0.000000
24.590002,0.094955,-2.179567,0.015793,0.015839,0.402306,0.422381,0.021517,4.023063,-2.179567,0.403321,0.000000
24.830002,0.061069,-2.179567,0.015953,0.015991,0.406165,0.271649,0.013838,4.061654,-2.179567,0.407327,0.000000
25.070002,0.113574,-2.135086,0.016147,0.016149,0.410172,0.505201,0.025736,4.101721,-2.135086,0.411317,0.000000
25.310001,0.131820,-2.090605,0.016302,0.016300,0.414022,0.586364,0.029871,4.140221,-2.090605,0.415323,0.000000
25.550001,0.129586,-2.224048,0.016470,0.016468,0.418289,0.576426,0.029365,4.182892,-2.224048,0.419313,0.000000
25.790001,0.118787,-2.135086,0.016651,0.016622,0.422200,0.528390,0.026917,4.222005,-2.135086,0.423319,0.000000
26.030001,0.103147,-2.090605,0.016806,0.016783,0.426293,0.458822,0.023373,4.262935,-2.090605,0.427309,0.000000
26.270000,0.117670,-2.135086,0.016974,0.016931,0.430049,0.523421,0.026664,4.300488,-2.135086,0.431314,0.000000
26.510002,0.094583,-2.046124,0.017130,0.017095,0.434220,0.420724,0.021433,4.342198,-2.046124,0.435304,0.000000
26.750002,0.046174,-2.090605,0.017293,0.017253,0.438236,0.205393,0.010463,4.382356,-2.090605,0.439310,0.000000
26.990002,0.114318,-2.001643,0.017466,0.017412,0.442259,0.508514,0.025905,4.422589,-2.001643,0.443317,0.000000
27.230001,0.119904,-1.957162,0.017608,0.017561,0.446049,0.533359,0.027171,4.460491,-1.957162,0.447306,0.000000
27.470001,0.137033,-1.957162,0.017763,0.017719,0.450056,0.609554,0.031052,4.500558,-1.957162,0.451313,0.000000
27.710001,0.101658,-1.912681,0.017940,0.017883,0.454236,0.452196,0.023036,4.542358,-1.912681,0.455302,0.000000
27.950001,0.128469,-1.957162,0.018074,0.018041,0.458233,0.571456,0.029111,4.582335,-1.957162,0.459309,0.000000
28.190001,0.128469,-2.001643,0.018255,0.018196,0.462180,0.571456,0.029111,4.621796,-2.001643,0.463298,0.000000
28.430002,0.114318,-1.957162,0.018397,0.018351,0.466108,0.508514,0.025905,4.661083,-1.957162,0.467305,0.000000
28.670002,0.090487,-1.957162,0.018578,0.018510,0.470166,0.402504,0.020505,4.701664,-1.957162,0.471294,0.000000
28.910002,0.074475,-1.912681,0.018725,0.018669,0.474181,0.331279,0.016876,4.741815,-1.912681,0.475300,0.000000
29.150002,0.144108,-1.868200,0.018884,0.018827,0.478197,0.641025,0.032655,4.781972,-1.868200,0.479290,0.000000
29.390001,0.157514,-1.823719,0.019040,0.018977,0.482004,0.700655,0.035693,4.820041,-1.823719,0.483296,0.000000
29.630001,0.161982,-1.868200,0.019208,0.019142,0.486219,0.720532,0.036706,4.862190,-1.868200,0.487286,0.000000
29.870001,0.127724,-1.779238,0.019389,0.019297,0.490148,0.568144,0.028943,4.901477,-1.779238,0.491292,0.000000
30.110001,0.152300,-1.823719,0.019561,0.019458,0.494241,0.677466,0.034512,4.942407,-1.823719,0.495282,0.000000
30.350002,0.166823,-1.823719,0.019708,0.019611,0.498109,0.742065,0.037803,4.981088,-1.823719,0.499288,0.000000
30.590002,0.166451,-1.779238,0.019867,0.019774,0.502254,0.740409,0.037718,5.022541,-1.779238,0.503277,0.000000
30.830002,0.117297,-1.779238,0.020031,0.019924,0.506061,0.521765,0.026580,5.060609,-1.779238,0.507284,0.000000
31.070002,0.173153,-1.779238,0.020187,0.020083,0.510102,0.770224,0.039237,5.101024,-1.779238,0.511273,0.000000
31.310001,0.224913,-1.690276,0.020337,0.020238,0.514039,1.000463,0.050966,5.140395,-1.690276,0.515279,0.000000
31.550001,0.230126,-1.734757,0.020506,0.020394,0.518003,1.023652,0.052147,5.180030,-1.734757,0.519286,0.000000
31.790001,0.239435,-1.690276,0.020687,0.020558,0.522166,1.065062,0.054257,5.221656,-1.690276,0.523275,0.000000
32.030003,0.317261,-1.645795,0.020850,0.020713,0.526103,1.411249,0.071892,5.261027,-1.645795,0.527282,0.000000
32.270000,0.457273,-1.645795,0.021014,0.020868,0.530040,2.034054,0.103620,5.300397,-1.645795,0.531271,0.000000
32.510002,0.650535,-1.601314,0.021161,0.000007,0.000182,2.893723,0.147413,0.001817,-1.601314,0.001310,0.000000
32.750000,0.596913,-1.645795,0.021208,0.000018,0.000451,2.655202,0.135262,0.004512,-1.645795,0.000677,0.000000
32.990002,0.581646,-1.601314,0.021226,0.000018,0.000451,2.587290,0.131803,0.004512,-1.601314,0.000677,0.000000
33.230003,0.576433,-1.556833,0.021217,0.000018,0.000451,2.564100,0.130621,0.004512,-1.556833,0.000980,0.000000
33.470001,0.597658,-1.556833,0.021217,0.000018,0.000451,2.658515,0.135431,0.004512,-1.556833,0.001378,0.000000
33.710003,0.572709,-1.512352,0.021226,0.000018,0.000459,2.547536,0.129778,0.004595,-1.512352,0.001777,0.000000
33.950001,0.634150,-1.556833,0.021221,0.000044,0.001127,2.820842,0.143701,0.011271,-1.556833,0.002176,0.000000
34.190002,0.688517,-1.512352,0.021226,0.000056,0.001431,3.062675,0.156020,0.014307,-1.512352,0.002584,0.000000
34.430000,0.740276,-1.467871,0.021239,0.000072,0.001839,3.292914,0.167749,0.018387,-1.467871,0.002983,0.000000
34.670002,0.765970,-1.467871,0.021260,0.000087,0.002211,3.407206,0.173571,0.022111,-1.467871,0.003382,0.000000
34.910000,0.820709,-1.423390,0.021260,0.000104,0.002645,3.650696,0.185975,0.026449,-1.423390,0.003781,0.000000
35.150002,0.857574,-1.423390,0.021277,0.000127,0.003226,3.814678,0.194329,0.032262,-1.423390,0.004180,0.000000
35.390003,0.886246,-1.423390,0.021316,0.000143,0.003625,3.942221,0.200826,0.036252,-1.423390,0.004579,0.000000
35.630001,0.859063,-1.334429,0.021316,0.000156,0.003972,3.821304,0.194667,0.039719,-1.334429,0.004978,0.000000
35.870003,0.891087,-1.334429,0.021329,0.000169,0.004293,3.963754,0.201923,0.042928,-1.334429,0.005377,0.000000
36.110001,0.910823,-1.334429,0.021342,0.000179,0.004544,4.051543,0.206395,0.045441,-1.334429,0.005784,0.000000
36.350002,1.015087,-1.334429,0.021346,0.000200,0.005091,4.515334,0.230022,0.050907,-1.334429,0.006183,0.000000
36.590000,1.049718,-1.200986,0.021364,0.000216,0.005481,4.669379,0.237870,0.054805,-1.200986,0.006582,0.000000
36.830002,1.092168,-1.245467,0.021381,0.000231,0.005862,4.858208,0.247489,0.058620,-1.245467,0.006981,0.000000
37.070004,1.128289,-1.245467,0.021389,0.000249,0.006331,5.018878,0.255674,0.063306,-1.245467,0.007380,0.000000
37.310001,1.176697,-1.200986,0.021415,0.000268,0.006808,5.234210,0.266643,0.068075,-1.200986,0.007779,0.000000
37.550003,1.196060,-1.245467,0.021424,0.000280,0.007120,5.320343,0.271031,0.071201,-1.245467,0.008178,0.000000
37.790001,1.208721,-1.156505,0.021437,0.000294,0.007475,5.376660,0.273900,0.074752,-1.156505,0.008577,0.000000
38.030003,1.275003,-1.245467,0.021454,0.000308,0.007831,5.671498,0.288920,0.078309,-1.245467,0.008985,0.000000
38.270000,1.373310,-1.156505,0.021467,0.000326,0.008273,6.108786,0.311196,0.082730,-1.156505,0.009384,0.000000
38.510002,1.412036,-1.112024,0.021484,0.000341,0.008664,6.281052,0.319972,0.086636,-1.112024,0.009782,0.000000
38.750000,1.485021,-1.112024,0.021502,0.000356,0.009036,6.605705,0.336511,0.090361,-1.112024,0.010181,0.000000
38.990002,1.556144,-1.067543,0.021523,0.000378,0.009592,6.922076,0.352627,0.095917,-1.067543,0.010580,0.000000
39.230003,1.618703,-1.112024,0.021536,0.000394,0.010016,7.200351,0.366803,0.100163,-1.112024,0.010979,0.000000
39.470001,1.637694,-1.112024,0.021549,0.000408,0.010363,7.284827,0.371107,0.103630,-1.112024,0.011378,0.000000
39.710003,1.674931,-1.023062,0.021558,0.000423,0.010745,7.450467,0.379545,0.107446,-1.023062,0.011785,0.000000
39.950001,1.768769,-1.067543,0.021583,0.000437,0.011100,7.867878,0.400809,0.111003,-1.067543,0.012184,0.000000
40.190002,1.919208,-1.023062,0.021588,0.000454,0.011534,8.537062,0.434899,0.115341,-1.023062,0.012583,0.000000
40.430000,1.979160,-1.023062,0.021583,0.000466,0.011838,8.803741,0.448484,0.118376,-1.023062,0.012982,0.000000
40.670002,2.107628,-0.978581,0.021618,0.000482,0.012254,9.375198,0.477595,0.122540,-0.978581,0.013381,0.000000
40.910004,2.211520,-0.934100,0.021622,0.000500,0.012705,9.837332,0.501138,0.127051,-0.934100,0.013780,0.000000
41.150002,2.335148,-1.023062,0.021644,0.000519,0.013173,10.387256,0.529152,0.131729,-1.023062,0.014179,0.000000
41.390003,2.384673,-0.934100,0.021670,0.000529,0.013433,10.607557,0.540375,0.134333,-0.934100,0.014578,0.000000
41.630001,2.494895,-0.889619,0.021674,0.000544,0.013815,11.097849,0.565351,0.138149,-0.889619,0.014986,0.000000
41.870003,2.661346,-0.934100,0.021700,0.000563,0.014301,11.838258,0.603070,0.143008,-0.934100,0.015385,0.000000
42.110001,2.885142,-0.889619,0.021704,0.000581,0.014769,12.833752,0.653782,0.147687,-0.889619,0.015784,0.000000
42.350002,2.991640,-0.934100,0.021717,0.000595,0.015107,13.307481,0.677915,0.151070,-0.934100,0.016183,0.000000
42.590000,3.174848,-0.845138,0.021739,0.000610,0.015498,14.122427,0.719431,0.154976,-0.845138,0.016582,0.000000
42.830002,3.260121,-0.845138,0.021734,0.000620,0.015757,14.501742,0.738754,0.157573,-0.845138,0.016981,0.000000
43.070004,3.495088,-0.800657,0.021760,0.000642,0.016295,15.546928,0.791998,0.162947,-0.800657,0.017379,0.000000
43.310001,3.658187,-0.756176,0.021777,0.000657,0.016685,16.272429,0.828957,0.166853,-0.756176,0.017778,0.000000
43.550003,3.820542,-0.800657,0.021790,0.000673,0.017102,16.994617,0.865747,0.171017,-0.800657,0.018186,0.000000
43.790001,4.012313,-0.667214,0.021812,0.000690,0.017535,17.847662,0.909203,0.175354,-0.667214,0.018585,0.000000
44.030003,4.196638,-0.711695,0.021816,0.000705,0.017917,18.667576,0.950972,0.179169,-0.711695,0.018984,0.000000
44.270000,4.389154,-0.711695,0.021834,0.000717,0.018211,19.523932,0.994596,0.182114,-0.711695,0.019382,0.000000
44.510002,4.695989,-0.622733,0.021846,0.000735,0.018672,20.888803,1.064126,0.186716,-0.622733,0.019781,0.000000
44.750004,4.773442,-0.622733,0.021868,0.000746,0.018949,21.233332,1.081678,0.189487,-0.622733,0.020180,0.000000
44.990002,5.176722,-0.578252,0.021872,0.000768,0.019504,23.027208,1.173062,0.195036,-0.578252,0.020579,0.000000
45.230003,5.326788,-0.622733,0.021881,0.000784,0.019912,23.694736,1.207067,0.199116,-0.622733,0.020978,0.000000
45.470001,5.588566,-0.533771,0.021907,0.000802,0.020363,24.859182,1.266387,0.203627,-0.533771,0.021385,0.000000
45.710003,5.773263,-0.578252,0.021915,0.000814,0.020683,25.680754,1.308240,0.206829,-0.578252,0.021784,0.000000
45.950001,6.177659,-0.533771,0.021928,0.000834,0.021186,27.479599,1.399878,0.211863,-0.533771,0.022183,0.000000
46.190002,6.299797,-0.489290,0.021950,0.000845,0.021455,28.022898,1.427554,0.214551,-0.489290,0.022582,0.000000
46.430000,6.445395,-0.533771,0.021954,0.000855,0.021706,28.670549,1.460547,0.217064,-0.533771,0.022981,0.000000
46.670002,6.722812,-0.578252,0.021967,0.000868,0.022054,29.904562,1.523411,0.220538,-0.578252,0.023380,0.000000
46.910004,7.390104,-0.489290,0.021993,0.000898,0.022808,32.872822,1.674621,0.228078,-0.489290,0.023779,0.000000
47.150002,7.583365,-0.444809,0.022006,0.000914,0.023207,33.732491,1.718415,0.232067,-0.444809,0.024178,0.000000
47.390003,7.765083,-0.444809,0.022010,0.000928,0.023571,34.540813,1.759593,0.235708,-0.444809,0.024586,0.000000
47.630001,8.033564,-0.444809,0.022023,0.000942,0.023936,35.735077,1.820431,0.239357,-0.444809,0.024985,0.000000
47.870003,8.385083,-0.444809,0.022045,0.000960,0.024378,37.298714,1.900087,0.243778,-0.444809,0.025384,0.000000
48.110001,8.659521,-0.311367,0.022045,0.000972,0.024690,38.519474,1.962276,0.246896,-0.311367,0.025783,0.000000
48.350002,8.754477,-0.400329,0.022071,0.000981,0.024915,38.941856,1.983793,0.249152,-0.400329,0.026182,0.000000
48.590004,9.151053,-0.311367,0.022075,0.000996,0.025306,40.705917,2.073658,0.253058,-0.311367,0.026581,0.000000
48.830002,9.803450,-0.355848,0.022079,0.001021,0.025939,43.607922,2.221493,0.259386,-0.355848,0.026979,0.000000
49.070004,10.000807,-0.311367,0.022105,0.001038,0.026363,44.485809,2.266215,0.263633,-0.311367,0.027378,0.000000
49.310001,10.363871,-0.311367,0.022114,0.001056,0.026814,46.100800,2.348487,0.268145,-0.311367,0.027786,0.000000
49.550003,10.523991,-0.400329,0.022131,0.001067,0.027110,46.813049,2.384770,0.271097,-0.400329,0.028185,0.000000
49.790001,11.030416,-0.266886,0.022148,0.001086,0.027595,49.065742,2.499528,0.275949,-0.266886,0.028584,0.000000
50.030003,11.369648,-0.266886,0.022157,0.001101,0.027976,50.574718,2.576399,0.279764,-0.266886,0.028982,0.000000
50.270004,11.356243,-0.177924,0.022170,0.001108,0.028132,50.515091,2.573362,0.281324,-0.177924,0.029381,0.000000
50.510002,11.681696,-0.222405,0.022183,0.001122,0.028506,51.962780,2.647110,0.285056,-0.222405,0.029780,0.000000
50.750004,12.657312,-0.177924,0.022204,0.001152,0.029251,56.302536,2.868188,0.292512,-0.177924,0.030179,0.000000
50.990002,12.732532,-0.133443,0.022209,0.001164,0.029555,56.637131,2.885233,0.295547,-0.133443,0.030578,0.000000
51.230003,13.061337,-0.088962,0.022213,0.001178,0.029928,58.099728,2.959741,0.299279,-0.088962,0.030986,0.000000
51.470001,13.462754,-0.133443,0.022230,0.001196,0.030370,59.885323,3.050704,0.303700,-0.133443,0.031385,0.000000
51.710003,13.857841,-0.088962,0.022247,0.001212,0.030795,61.642754,3.140232,0.307954,-0.088962,0.031784,0.000000
51.950001,14.226117,-0.133443,0.022256,0.001229,0.031212,63.280930,3.223684,0.312118,-0.133443,0.032183,0.000000
52.190002,14.279366,-0.044481,0.022282,0.001237,0.031419,63.517796,3.235751,0.314192,-0.044481,0.032582,0.000000
52.430004,14.930274,-0.044481,0.022278,0.001259,0.031975,66.413177,3.383248,0.319748,-0.044481,0.032981,0.000000
52.670002,15.562562,-0.044481,0.022303,0.001280,0.032504,69.225731,3.526527,0.325039,-0.044481,0.033380,0.000000
52.910004,15.656400,0.000000,0.022312,0.001292,0.032807,69.643143,3.547791,0.328067,0.000000,0.033787,0.000000
53.150002,16.005314,0.000000,0.022325,0.001308,0.033215,71.195190,3.626856,0.332147,0.000000,0.034186,0.000000
53.390003,16.383644,0.044481,0.022351,0.001322,0.033588,72.878090,3.712587,0.335879,0.044481,0.034585,0.000000
53.630001,16.835705,0.000000,0.022329,0.001338,0.033995,74.888954,3.815025,0.339952,0.000000,0.034984,0.000000
53.870003,17.118336,0.000000,0.022355,0.001351,0.034324,76.146164,3.879070,0.343245,0.000000,0.035383,0.000000
54.110004,17.537626,0.088962,0.022377,0.001367,0.034723,78.011261,3.974083,0.347234,0.088962,0.035782,0.000000
54.350002,18.112942,0.088962,0.022385,0.001386,0.035209,80.570389,4.104451,0.352094,0.088962,0.036181,0.000000
54.590004,18.518084,0.133443,0.022390,0.001403,0.035643,82.372551,4.196258,0.356431,0.133443,0.036579,0.000000
54.830002,18.797363,0.133443,0.022407,0.001416,0.035972,83.614845,4.259543,0.359724,0.133443,0.036987,0.000000
55.070004,19.118347,0.177924,0.022424,0.001431,0.036354,85.042656,4.332279,0.363539,0.177924,0.037386,0.000000
55.310001,19.456463,0.222405,0.022433,0.001445,0.036692,86.546669,4.408897,0.366923,0.222405,0.037785,0.000000
55.550003,19.661638,0.177924,0.022454,0.001457,0.037004,87.459335,4.455391,0.370042,0.177924,0.038184,0.000000
55.790001,20.208654,0.222405,0.022467,0.001473,0.037412,89.892586,4.579346,0.374122,0.222405,0.038582,0.000000
56.030003,20.659597,0.266886,0.022459,0.001488,0.037802,91.898476,4.681532,0.378020,0.266886,0.038981,0.000000
56.270004,21.136978,0.222405,0.022485,0.001503,0.038167,94.021973,4.789708,0.381669,0.222405,0.039380,0.000000
56.510002,22.025087,0.311367,0.022485,0.001529,0.038835,97.972481,4.990956,0.388345,0.311367,0.039779,0.000000
56.750004,22.342720,0.266886,0.022497,0.001543,0.039199,99.385384,5.062932,0.391986,0.266886,0.040187,0.000000
56.990002,22.488691,0.311367,0.022519,0.001557,0.039545,100.034698,5.096010,0.395453,0.311367,0.040586,0.000000
57.230003,22.843935,0.266886,0.022536,0.001572,0.039919,101.614899,5.176510,0.399185,0.266886,0.040985,0.000000
57.470001,23.072943,0.355848,0.022545,0.001584,0.040239,102.633575,5.228404,0.402395,0.355848,0.041384,0.000000
57.710003,23.788271,0.400329,0.022558,0.001600,0.040647,105.815514,5.390500,0.406467,0.400329,0.041783,0.000000
57.950005,24.229904,0.400329,0.022554,0.001616,0.041046,107.779999,5.490575,0.410457,0.400329,0.042182,0.000000
58.190002,24.686060,0.444809,0.022584,0.001630,0.041410,109.809082,5.593941,0.414098,0.444809,0.042581,0.000000
58.430004,25.346649,0.444809,0.022575,0.001651,0.041931,112.747528,5.743633,0.419306,0.444809,0.042980,0.000000
58.670002,25.899996,0.444809,0.022601,0.001668,0.042355,115.208939,5.869023,0.423552,0.444809,0.043387,0.000000
58.910004,26.090277,0.489290,0.022623,0.001680,0.042685,116.055344,5.912141,0.426845,0.489290,0.043786,0.000000
59.150002,26.520741,0.444809,0.022635,0.001695,0.043058,117.970146,6.009686,0.430577,0.444809,0.044185,0.000000
59.390003,26.881941,0.533771,0.022640,0.001710,0.043439,119.576843,6.091535,0.434392,0.533771,0.044584,0.000000
59.630001,27.693340,0.489290,0.022640,0.001729,0.043916,123.186127,6.275401,0.439161,0.489290,0.044983,0.000000
59.870003,28.013208,0.533771,0.022653,0.001743,0.044272,124.608971,6.347884,0.442719,0.533771,0.045382,0.000000
60.110004,28.524849,0.578252,0.022657,0.001759,0.044671,126.884865,6.463823,0.446708,0.578252,0.045781,0.000000
60.350002,29.396200,0.578252,0.022670,0.001780,0.045217,130.760834,6.661274,0.452174,0.578252,0.046180,0.000000
60.590004,29.830387,0.622733,0.022692,0.001795,0.045599,132.692184,6.759663,0.455989,0.622733,0.046588,0.000000
60.830002,30.072802,0.622733,0.022696,0.001807,0.045902,133.770508,6.814594,0.459024,0.622733,0.046986,0.000000
61.070004,30.623167,0.711695,0.022722,0.001824,0.046327,136.218643,6.939309,0.463271,0.711695,0.047385,0.000000
61.310001,31.082674,0.622733,0.022717,0.001838,0.046691,138.262634,7.043435,0.466912,0.622733,0.047784,0.000000
61.550003,31.739912,0.622733,0.022730,0.001855,0.047108,141.186172,7.192367,0.471076,0.622733,0.048183,0.000000
61.790005,32.106327,0.711695,0.022735,0.001867,0.047411,142.816071,7.275397,0.474111,0.711695,0.048582,0.000000
62.030003,32.827240,0.711695,0.022752,0.001883,0.047827,146.022858,7.438759,0.478274,0.711695,0.048981,0.000000
62.270004,33.455433,0.711695,0.022761,0.001899,0.048235,148.817200,7.581110,0.482347,0.711695,0.049380,0.000000
62.510002,34.257523,0.756176,0.022761,0.001918,0.048721,152.385071,7.762866,0.487207,0.756176,0.049787,0.000000
62.750004,34.483925,0.756176,0.022778,0.001932,0.049076,153.392166,7.814169,0.490765,0.756176,0.050186,0.000000
62.990002,35.121799,0.845138,0.022791,0.001947,0.049466,156.229568,7.958713,0.494663,0.845138,0.050585,0.000000
63.230003,35.977882,0.800657,0.022799,0.001965,0.049900,160.037613,8.152704,0.499001,0.800657,0.050984,0.000000
63.470001,36.645546,0.845138,0.022821,0.001981,0.050325,163.007523,8.303999,0.503247,0.845138,0.051383,0.000000
63.710003,37.112129,0.845138,0.022812,0.001995,0.050672,165.082993,8.409728,0.506722,0.845138,0.051782,0.000000
63.950005,37.766014,0.889619,0.022834,0.002010,0.051045,167.991623,8.557900,0.510446,0.889619,0.052181,0.000000
64.190002,38.107109,0.934100,0.022838,0.002022,0.051366,169.508881,8.635195,0.513656,0.934100,0.052580,0.000000
64.430000,39.355675,0.889619,0.022855,0.002044,0.051930,175.062790,8.918123,0.519295,0.889619,0.052988,0.000000
64.670006,39.844601,0.934100,0.022864,0.002059,0.052302,177.237640,9.028916,0.523019,0.934100,0.053387,0.000000
64.910004,40.547264,0.978581,0.022877,0.002076,0.052727,180.363235,9.188142,0.527274,0.978581,0.053786,0.000000
65.150002,41.315842,0.889619,0.022881,0.002092,0.053144,183.782043,9.362304,0.531437,0.889619,0.054185,0.000000
65.389999,41.849823,0.978581,0.022886,0.002105,0.053456,186.157303,9.483305,0.534556,0.978581,0.054583,0.000000
65.630005,42.262413,1.023062,0.022890,0.002116,0.053742,187.992599,9.576800,0.537417,1.023062,0.054982,0.000000
65.870003,43.277874,1.023062,0.022916,0.002136,0.054245,192.509598,9.806906,0.542451,1.023062,0.055381,0.000000
66.110001,43.596622,1.067543,0.022916,0.002147,0.054522,193.927460,9.879136,0.545222,1.067543,0.055789,0.000000
66.350006,44.965092,1.067543,0.022924,0.002169,0.055086,200.014725,10.189236,0.550861,1.067543,0.056188,0.000000
66.590004,45.806282,1.112024,0.022924,0.002185,0.055511,203.756516,10.379852,0.555108,1.112024,0.056586,0.000000
66.830002,46.478043,1.067543,0.022946,0.002202,0.055919,206.744659,10.532075,0.559188,1.067543,0.056985,0.000000
67.070000,46.927868,1.067543,0.022950,0.002213,0.056222,208.745575,10.634007,0.562223,1.067543,0.057384,0.000000
67.310005,48.133610,1.067543,0.022950,0.002235,0.056760,214.108994,10.907231,0.567598,1.067543,0.057783,0.000000
67.550003,48.540611,1.156505,0.022967,0.002247,0.057081,215.919418,10.999460,0.570808,1.156505,0.058182,0.000000
67.790001,48.738342,1.245467,0.022967,0.002253,0.057237,216.798981,11.044267,0.572367,1.245467,0.058581,0.000000
68.030006,49.719543,1.156505,0.022985,0.002272,0.057714,221.163574,11.266609,0.577136,1.156505,0.058988,0.000000
68.270004,51.408997,1.156505,0.022985,0.002297,0.058356,228.678635,11.649446,0.583555,1.156505,0.059387,0.000000
68.510002,52.179810,1.200986,0.022989,0.002314,0.058780,232.107391,11.824114,0.587802,1.200986,0.059786,0.000000
68.750000,52.889549,1.289948,0.023002,0.002329,0.059153,235.264465,11.984943,0.591534,1.289948,0.060185,0.000000
68.990005,53.537853,1.245467,0.023006,0.002341,0.059465,238.148270,12.131851,0.594652,1.245467,0.060584,0.000000
69.230003,54.485912,1.200986,0.023019,0.002361,0.059960,242.365448,12.346684,0.599595,1.200986,0.060983,0.000000
69.470001,55.144268,1.289948,0.023024,0.002372,0.060246,245.293961,12.495870,0.602464,1.289948,0.061382,0.000000
69.710007,55.486477,1.334429,0.023024,0.002379,0.060437,246.816177,12.573415,0.604372,1.334429,0.061781,0.000000
69.950005,56.413311,1.334429,0.023041,0.002395,0.060836,250.938934,12.783439,0.608361,1.334429,0.062189,0.000000
70.190002,58.179848,1.334429,0.023028,0.002420,0.061469,258.796875,13.183743,0.614690,1.334429,0.062588,0.000000
70.430000,59.003536,1.378909,0.023049,0.002437,0.061903,262.460846,13.370393,0.619027,1.378909,0.062987,0.000000
70.670006,60.105385,1.467871,0.023058,0.002455,0.062345,267.362091,13.620075,0.623448,1.467871,0.063386,0.000000
70.910004,60.692989,1.423390,0.023067,0.002467,0.062666,269.975891,13.753228,0.626657,1.423390,0.063785,0.000000
71.150002,61.954960,1.423390,0.023067,0.002487,0.063160,275.589417,14.039195,0.631601,1.423390,0.064183,0.000000
71.390007,62.920147,1.512352,0.023075,0.002501,0.063524,279.882782,14.257909,0.635242,1.512352,0.064582,0.000000
71.630005,63.127934,1.423390,0.023084,0.002509,0.063724,280.807068,14.304995,0.637240,1.423390,0.064981,0.000000
71.870003,63.942310,1.512352,0.023101,0.002522,0.064062,284.429596,14.489535,0.640616,1.512352,0.065389,0.000000
72.110001,66.101326,1.467871,0.023101,0.002551,0.064799,294.033386,14.978774,0.647989,1.467871,0.065788,0.000000
72.350006,66.675896,1.512352,0.023101,0.002563,0.065112,296.589203,15.108974,0.651115,1.512352,0.066186,0.000000
72.590004,67.350639,1.556833,0.023110,0.002565,0.065155,299.590607,15.261872,0.651547,1.556833,0.065415,0.000000
72.830002,66.871017,1.556833,0.023114,0.002565,0.065155,297.457153,15.153190,0.651547,1.556833,0.065415,0.000000
73.070000,66.461411,1.601314,0.023118,0.002559,0.064999,295.635132,15.060370,0.649988,1.601314,0.065155,0.000000
73.310005,66.132980,1.601314,0.023131,0.002558,0.064964,294.174194,14.985948,0.649639,1.601314,0.065155,0.000000
73.550003,65.873436,1.645795,0.023131,0.002557,0.064955,293.019684,14.927135,0.649549,1.645795,0.065155,0.000000
73.790001,65.641075,1.645795,0.023136,0.002557,0.064947,291.986084,14.874480,0.649465,1.645795,0.065155,0.000000
74.030006,65.448929,1.645795,0.023149,0.002557,0.064947,291.131378,14.830939,0.649465,1.645795,0.065155,0.000000
74.270004,65.269447,1.779238,0.023144,0.002557,0.064947,290.333008,14.790268,0.649465,1.779238,0.065155,0.000000
74.510002,65.115280,1.690276,0.023131,0.002557,0.064947,289.647247,14.755334,0.649465,1.690276,0.065155,0.000000
74.750000,64.964104,1.734757,0.023153,0.002557,0.064947,288.974762,14.721076,0.649465,1.734757,0.065155,0.000000
74.990005,64.830048,1.734757,0.023140,0.002557,0.064947,288.378448,14.690699,0.649465,1.734757,0.065155,0.000000
75.230003,64.698227,1.734757,0.023149,0.002557,0.064947,287.792084,14.660829,0.649465,1.734757,0.065155,0.000000
75.470001,64.589493,1.779238,0.023157,0.002557,0.064947,287.308411,14.636189,0.649465,1.779238,0.065155,0.000000
75.710007,64.484856,1.734757,0.023131,0.002557,0.064947,286.842957,14.612477,0.649465,1.734757,0.065155,0.000000
75.950005,64.389900,1.823719,0.023140,0.002557,0.064947,286.420593,14.590960,0.649465,1.823719,0.065155,0.000000
76.190002,64.278191,1.868200,0.023140,0.002557,0.064937,285.923676,14.565646,0.649374,1.868200,0.065155,0.000000
76.430000,64.184723,1.823719,0.023153,0.002557,0.064937,285.507904,14.544467,0.649374,1.823719,0.065155,0.000000
76.670006,64.109131,1.912681,0.023157,0.002557,0.064937,285.171661,14.527336,0.649374,1.912681,0.065155,0.000000
76.910004,64.020882,1.912681,0.023144,0.002557,0.064937,284.779114,14.507339,0.649374,1.912681,0.065155,0.000000
77.150002,63.957577,1.868200,0.023153,0.002557,0.064937,284.497498,14.492993,0.649374,1.868200,0.065155,0.000000
77.390007,63.881615,1.957162,0.023149,0.002557,0.064937,284.159607,14.475781,0.649374,1.957162,0.065155,0.000000
77.630005,63.821289,1.957162,0.023144,0.002557,0.064937,283.891266,14.462111,0.649374,1.957162,0.065155,0.000000
77.870003,63.759476,2.001643,0.023153,0.002557,0.064937,283.616302,14.448104,0.649374,2.001643,0.065155,0.000000
78.110001,63.698780,1.912681,0.023149,0.002557,0.064937,283.346313,14.434350,0.649374,1.912681,0.065155,0.000000
78.350006,63.639572,1.957162,0.023149,0.002557,0.064937,283.082947,14.420933,0.649374,1.957162,0.065155,0.000000
78.590004,63.579990,1.957162,0.023153,0.002557,0.064937,282.817932,14.407432,0.649374,1.957162,0.065155,0.000000
78.830002,63.529720,2.090605,0.023157,0.002557,0.064937,282.594299,14.396040,0.649374,2.090605,0.065155,0.000000
79.070007,63.475357,2.090605,0.023149,0.002557,0.064937,282.352478,14.383721,0.649374,2.090605,0.065155,0.000000
79.310005,63.429554,2.046124,0.023153,0.002557,0.064937,282.148743,14.373343,0.649374,2.046124,0.065155,0.000000
79.550003,63.390083,2.090605,0.023153,0.002557,0.064937,281.973175,14.364398,0.649374,2.090605,0.065155,0.000000
79.790001,63.345768,2.090605,0.023166,0.002557,0.064937,281.776062,14.354357,0.649374,2.090605,0.065155,0.000000
80.030006,63.286934,2.046124,0.023144,0.002557,0.064937,281.514343,14.341023,0.649374,2.046124,0.065155,0.000000
80.270004,63.245975,2.179567,0.023153,0.002557,0.064937,281.332153,14.331743,0.649374,2.179567,0.065155,0.000000
80.510002,63.194958,2.135086,0.023157,0.002557,0.064937,281.105225,14.320183,0.649374,2.135086,0.065155,0.000000
80.750008,63.170383,2.224048,0.023153,0.002557,0.064937,280.995911,14.314613,0.649374,2.224048,0.065155,0.000000
80.990005,63.139103,2.179567,0.023153,0.002557,0.064937,280.856750,14.307526,0.649374,2.179567,0.065155,0.000000
81.230003,63.093300,2.179567,0.023157,0.002557,0.064937,280.653015,14.297146,0.649374,2.179567,0.065155,0.000000
81.470001,63.056435,2.268528,0.023161,0.002557,0.064937,280.489044,14.288792,0.649374,2.268528,0.065155,0.000000
81.710007,63.019199,2.268528,0.023149,0.002557,0.064937,280.323395,14.280354,0.649374,2.268528,0.065155,0.000000
81.950005,62.985313,2.313010,0.023157,0.002557,0.064937,280.172668,14.272676,0.649374,2.313010,0.065155,0.000000
82.190002,62.951427,2.268528,0.023149,0.002557,0.064937,280.021942,14.264997,0.649374,2.268528,0.065155,0.000000
82.430000,62.913074,2.313010,0.023161,0.002557,0.064937,279.851318,14.256307,0.649374,2.313010,0.065155,0.000000
82.670006,62.897060,2.357490,0.023144,0.002557,0.064937,279.780090,14.252677,0.649374,2.357490,0.065155,0.000000
82.910004,62.847534,2.268528,0.023157,0.002557,0.064937,279.559784,14.241454,0.649374,2.268528,0.065155,0.000000
83.150002,62.812904,2.401971,0.023166,0.002557,0.064937,279.405762,14.233607,0.649374,2.401971,0.065155,0.000000
83.390007,62.787582,2.357490,0.023153,0.002557,0.064937,279.293121,14.227870,0.649374,2.357490,0.065155,0.000000
83.630005,62.764870,2.446452,0.023161,0.002557,0.064937,279.192078,14.222723,0.649374,2.446452,0.065155,0.000000
83.870003,62.740292,2.446452,0.023153,0.002557,0.064937,279.082764,14.217154,0.649374,2.446452,0.065155,0.000000
84.110001,62.704918,2.446452,0.023140,0.002557,0.064937,278.925415,14.209137,0.649374,2.446452,0.065155,0.000000
84.350006,62.677361,2.490933,0.023144,0.002557,0.064937,278.802826,14.202893,0.649374,2.490933,0.065155,0.000000
84.590004,62.642357,2.490933,0.023157,0.002557,0.064937,278.647125,14.194962,0.649374,2.490933,0.065155,0.000000
84.830002,62.627090,2.446452,0.023157,0.002557,0.064937,278.579224,14.191502,0.649374,2.446452,0.065155,0.000000
85.070007,62.603630,2.579895,0.023161,0.002557,0.064937,278.474854,14.186185,0.649374,2.579895,0.065155,0.000000
85.310005,62.576820,2.535414,0.023153,0.002557,0.064937,278.355591,14.180110,0.649374,2.535414,0.065155,0.000000
85.550003,62.544796,2.579895,0.023149,0.002557,0.064937,278.213135,14.172853,0.649374,2.579895,0.065155,0.000000
85.790001,62.520592,2.579895,0.023157,0.002557,0.064937,278.105469,14.167368,0.649374,2.579895,0.065155,0.000000
86.030006,62.515007,2.624376,0.023157,0.002557,0.064937,278.080627,14.166102,0.649374,2.624376,0.065155,0.000000
86.270004,62.484844,2.713338,0.023153,0.002557,0.064937,277.946472,14.159267,0.649374,2.713338,0.065155,0.000000
86.510002,62.456543,2.668857,0.023157,0.002557,0.064937,277.820587,14.152855,0.649374,2.668857,0.065155,0.000000
86.750008,62.439415,2.668857,0.023157,0.002557,0.064937,277.744385,14.148973,0.649374,2.668857,0.065155,0.000000
86.990005,62.416328,2.757819,0.023157,0.002557,0.064937,277.641693,14.143742,0.649374,2.757819,0.065155,0.000000
87.230003,62.390633,2.668857,0.023179,0.002557,0.064937,277.527405,14.137919,0.649374,2.668857,0.065155,0.000000
87.470001,62.379463,2.757819,0.023161,0.002557,0.064937,277.477722,14.135388,0.649374,2.757819,0.065155,0.000000
87.710007,62.344460,2.713338,0.023166,0.002557,0.064937,277.322021,14.127456,0.649374,2.713338,0.065155,0.000000
87.950005,62.328819,2.802300,0.023161,0.002557,0.064937,277.252441,14.123913,0.649374,2.802300,0.065155,0.000000
88.190002,62.312435,2.802300,0.023153,0.002557,0.064937,277.179565,14.120199,0.649374,2.802300,0.065155,0.000000
88.430008,62.275200,2.802300,0.023170,0.002557,0.064937,277.013916,14.111762,0.649374,2.802300,0.065155,0.000000
88.670006,62.267380,2.846781,0.023170,0.002557,0.064937,276.979126,14.109990,0.649374,2.846781,0.065155,0.000000
88.910004,62.259186,2.802300,0.023161,0.002557,0.064937,276.942688,14.108133,0.649374,2.802300,0.065155,0.000000
89.150002,62.234238,2.935743,0.023149,0.002557,0.064937,276.831726,14.102479,0.649374,2.935743,0.065155,0.000000
89.390007,62.222694,2.846781,0.023157,0.002557,0.064937,276.780365,14.099864,0.649374,2.846781,0.065155,0.000000
89.630005,62.194393,2.846781,0.023170,0.002557,0.064937,276.654480,14.093451,0.649374,2.846781,0.065155,0.000000
89.870003,62.180614,2.891262,0.023161,0.002557,0.064937,276.593201,14.090329,0.649374,2.891262,0.065155,0.000000
90.110001,62.154549,2.891262,0.023157,0.002557,0.064937,276.477234,14.084421,0.649374,2.891262,0.065155,0.000000
90.350006,62.153435,2.980224,0.023161,0.002557,0.064937,276.472290,14.084169,0.649374,2.980224,0.065155,0.000000
90.590004,62.131462,2.980224,0.023161,0.002557,0.064937,276.374542,14.079190,0.649374,2.980224,0.065155,0.000000
90.830002,62.112846,3.024705,0.023157,0.002557,0.064937,276.291748,14.074972,0.649374,3.024705,0.065155,0.000000
91.070007,62.092735,2.980224,0.023149,0.002557,0.064937,276.202271,14.070415,0.649374,2.980224,0.065155,0.000000
91.310005,62.067043,3.024705,0.023153,0.002557,0.064937,276.088013,14.064593,0.649374,3.024705,0.065155,0.000000
91.550003,62.059597,3.024705,0.023161,0.002557,0.064937,276.054871,14.062905,0.649374,3.024705,0.065155,0.000000
91.790001,62.036137,3.024705,0.023161,0.002557,0.064937,275.950531,14.057590,0.649374,3.024705,0.065155,0.000000
92.030006,62.039860,3.158148,0.023170,0.002557,0.064937,275.967072,14.058433,0.649374,3.158148,0.065155,0.000000
92.270004,62.011559,3.158148,0.023157,0.002557,0.064937,275.841187,14.052020,0.649374,3.158148,0.065155,0.000000
92.510002,61.994431,3.113667,0.023161,0.002557,0.064937,275.765015,14.048139,0.649374,3.113667,0.065155,0.000000
92.750008,61.979534,3.158148,0.023153,0.002557,0.064937,275.698730,14.044764,0.649374,3.158148,0.065155,0.000000
92.990005,61.953842,3.113667,0.023153,0.002557,0.064937,275.584442,14.038941,0.649374,3.113667,0.065155,0.000000
93.230003,61.939690,3.202628,0.023161,0.002557,0.064937,275.521515,14.035734,0.649374,3.202628,0.065155,0.000000
93.470001,61.940063,3.202628,0.023166,0.002557,0.064937,275.523163,14.035819,0.649374,3.202628,0.065155,0.000000
93.710007,61.920326,3.202628,0.023166,0.002557,0.064937,275.435364,14.031346,0.649374,3.202628,0.065155,0.000000
93.950005,61.920700,3.291590,0.023161,0.002557,0.064937,275.437042,14.031431,0.649374,3.291590,0.065155,0.000000
94.190002,61.915485,3.247109,0.023153,0.002557,0.064937,275.413849,14.030250,0.649374,3.247109,0.065155,0.000000
94.430008,61.878994,3.247109,0.023170,0.002557,0.064937,275.251526,14.021980,0.649374,3.247109,0.065155,0.000000
94.670006,61.878250,3.291590,0.023161,0.002557,0.064937,275.248199,14.021812,0.649374,3.291590,0.065155,0.000000
94.910004,61.846970,3.247109,0.023153,0.002557,0.064937,275.109070,14.014724,0.649374,3.247109,0.065155,0.000000
95.150002,61.821278,3.291590,0.023153,0.002557,0.064937,274.994781,14.008902,0.649374,3.291590,0.065155,0.000000
95.390007,61.832447,3.291590,0.023161,0.002557,0.064937,275.044464,14.011433,0.649374,3.291590,0.065155,0.000000
95.630005,61.814575,3.380552,0.023179,0.002557,0.064937,274.964966,14.007383,0.649374,3.380552,0.065155,0.000000
95.870003,61.806011,3.336071,0.023149,0.002557,0.064937,274.926880,14.005442,0.649374,3.336071,0.065155,0.000000
96.110008,61.795582,3.380552,0.023153,0.002557,0.064937,274.880463,14.003079,0.649374,3.380552,0.065155,0.000000
96.350006,61.767654,3.425033,0.023157,0.002557,0.064937,274.756256,13.996751,0.649374,3.425033,0.065155,0.000000
96.590004,61.752014,3.425033,0.023161,0.002557,0.064937,274.686676,13.993206,0.649374,3.425033,0.065155,0.000000
96.830002,61.745686,3.425033,0.023157,0.002557,0.064937,274.658539,13.991773,0.649374,3.425033,0.065155,0.000000
97.070007,61.738983,3.469514,0.023157,0.002557,0.064937,274.628723,13.990254,0.649374,3.469514,0.065155,0.000000
97.310005,61.719990,3.380552,0.023170,0.002557,0.064937,274.544220,13.985950,0.649374,3.380552,0.065155,0.000000
97.550003,61.714405,3.558476,0.023170,0.002557,0.064937,274.519379,13.984684,0.649374,3.558476,0.065155,0.000000
97.790001,61.711056,3.469514,0.023161,0.002557,0.064937,274.504486,13.983926,0.649374,3.469514,0.065155,0.000000
98.030006,61.689083,3.513995,0.023170,0.002557,0.064937,274.406738,13.978946,0.649374,3.513995,0.065155,0.000000
98.270004,61.674561,3.602957,0.023170,0.002557,0.064937,274.342133,13.975655,0.649374,3.602957,0.065155,0.000000
98.510002,61.663765,3.513995,0.023170,0.002557,0.064937,274.294128,13.973209,0.649374,3.513995,0.065155,0.000000
98.750008,61.654827,3.647438,0.023161,0.002557,0.064937,274.254364,13.971184,0.649374,3.647438,0.065155,0.000000
98.990005,61.646633,3.647438,0.023161,0.002557,0.064937,274.217926,13.969326,0.649374,3.647438,0.065155,0.000000
99.230003,61.637699,3.602957,0.023166,0.002557,0.064937,274.178192,13.967302,0.649374,3.602957,0.065155,0.000000
99.470001,61.630249,3.691919,0.023157,0.002557,0.064937,274.145050,13.965614,0.649374,3.691919,0.065155,0.000000
99.710007,61.607162,3.647438,0.023161,0.002557,0.064937,274.042358,13.960382,0.649374,3.647438,0.065155,0.000000
99.950005,61.616100,3.736400,0.023157,0.002557,0.064937,274.082092,13.962408,0.649374,3.736400,0.065155,0.000000
100.190002,61.584076,3.736400,0.023166,0.002557,0.064937,273.939636,13.955152,0.649374,3.736400,0.065155,0.000000
100.430008,61.577000,3.691919,0.023166,0.002557,0.064937,273.908173,13.953547,0.649374,3.691919,0.065155,0.000000
100.670006,61.569180,3.736400,0.023179,0.002557,0.064937,273.873383,13.951776,0.649374,3.736400,0.065155,0.000000
100.910004,61.564339,3.736400,0.023166,0.002557,0.064937,273.851868,13.950679,0.649374,3.736400,0.065155,0.000000
101.150002,61.552795,3.869843,0.023166,0.002557,0.064937,273.800507,13.948063,0.649374,3.869843,0.065155,0.000000
101.390007,61.550934,3.780881,0.023153,0.002557,0.064937,273.792236,13.947640,0.649374,3.780881,0.065155,0.000000
101.630005,61.524498,3.914324,0.023170,0.002557,0.064937,273.674622,13.941650,0.649374,3.914324,0.065155,0.000000
101.870003,61.514816,3.869843,0.023157,0.002557,0.064937,273.631561,13.939457,0.649374,3.869843,0.065155,0.000000
102.110008,61.499920,3.825362,0.023161,0.002557,0.064937,273.565308,13.936081,0.649374,3.825362,0.065155,0.000000
102.350006,61.490982,3.914324,0.023153,0.002557,0.064937,273.525543,13.934056,0.649374,3.914324,0.065155,0.000000
102.590004,61.494335,3.869843,0.023161,0.002557,0.064937,273.540466,13.934815,0.649374,3.869843,0.065155,0.000000
102.830002,61.495453,3.914324,0.023170,0.002557,0.064937,273.545441,13.935069,0.649374,3.914324,0.065155,0.000000
103.070007,61.464916,4.003285,0.023161,0.002557,0.064937,273.409607,13.928149,0.649374,4.003285,0.065155,0.000000
103.100006,61.453747,3.958805,0.023174,0.002557,0.064937,273.359924,13.925618,0.649374,3.958805,0.065155,0.000000