File: Data/I-18_1_4_07282023_142145.csv
Time (sec),S:Load (lbs),S:HL1 (DIM),S:LVDT (in),S:Position (in),Ch:Position (mm),Ch:Load (N),Ch:Stress (MPa),Ch:Strain (mm/mm),Ch:HL1 (DIM),Set Point (),Cycles ()
0.110000,-0.003724,-11.965376,-0.000017,-0.000000,-0.000000,-0.016564,-0.000844,-0.000000,-11.965376,0.000035,0.000000
0.380000,-0.013033,-11.965376,-0.000009,-0.000000,-0.000000,-0.057974,-0.002953,-0.000000,-11.965376,0.000035,0.000000
0.650000,-0.036865,-12.009857,0.000004,0.000146,0.003703,-0.163983,-0.008354,0.037031,-12.009857,0.004406,0.000000
0.920000,0.001490,-11.920895,0.000017,0.000308,0.007832,0.006626,0.000338,0.078317,-11.920895,0.008898,0.000000
1.190000,0.045429,-11.920895,0.000185,0.000474,0.012037,0.202080,0.010294,0.120375,-11.920895,0.013390,0.000000
1.460000,-0.000745,-11.965376,0.000371,0.000662,0.016807,-0.003313,-0.000169,0.168072,-11.965376,0.017900,0.000000
1.730000,0.021970,-11.920895,0.000560,0.000839,0.021308,0.097727,0.004978,0.213082,-11.920895,0.022392,0.000000
2.000000,0.017129,-11.965376,0.000742,0.001016,0.025800,0.076194,0.003882,0.258001,-11.965376,0.026884,0.000000
2.270000,-0.014522,-11.876414,0.000905,0.001186,0.030128,-0.064599,-0.003291,0.301278,-11.876414,0.031394,0.000000
2.540000,0.020853,-11.876414,0.001074,0.001367,0.034724,0.092758,0.004725,0.347241,-11.876414,0.035886,0.000000
2.810000,-0.018619,-11.920895,0.001255,0.001539,0.039103,-0.082820,-0.004219,0.391033,-11.920895,0.040378,0.000000
3.080000,0.031652,-11.965376,0.001427,0.001717,0.043622,0.140794,0.007172,0.436217,-11.965376,0.044888,0.000000
3.350000,0.062186,-11.876414,0.001600,0.001893,0.048070,0.276618,0.014092,0.480704,-11.876414,0.049380,0.000000
3.620000,0.024949,-11.920895,0.001789,0.002076,0.052719,0.110978,0.005654,0.527190,-11.920895,0.053873,0.000000
3.890000,0.072613,-11.876414,0.001957,0.002253,0.057220,0.322997,0.016454,0.572200,-11.876414,0.058382,0.000000
4.160000,0.019736,-11.876414,0.002126,0.002433,0.061807,0.087789,0.004472,0.618073,-11.876414,0.062874,0.000000
4.430000,0.026811,-11.920895,0.002294,0.002609,0.066256,0.119261,0.006075,0.662561,-11.920895,0.067367,0.000000
4.700000,0.014523,-11.876414,0.002488,0.002787,0.070801,0.064600,0.003291,0.708010,-11.876414,0.071876,0.000000
4.970000,-0.013033,-11.876414,0.002652,0.002960,0.075180,-0.057974,-0.002953,0.751801,-11.876414,0.076369,0.000000
5.240000,0.058835,-11.831933,0.002811,0.003135,0.079629,0.261710,0.013332,0.796289,-11.831933,0.080860,0.000000
5.510000,0.045802,-11.876414,0.002988,0.003320,0.084338,0.203737,0.010379,0.843381,-11.876414,0.085370,0.000000
5.780000,0.047664,-11.831933,0.003165,0.003497,0.088830,0.212019,0.010801,0.888300,-11.831933,0.089862,0.000000
6.050000,0.070751,-11.876414,0.003328,0.003672,0.093279,0.314715,0.016032,0.932795,-11.876414,0.094354,0.000000
6.320000,0.029790,-11.787452,0.003514,0.003849,0.097763,0.132512,0.006750,0.977631,-11.787452,0.098864,0.000000
6.590000,0.060697,-11.831933,0.003673,0.004026,0.102255,0.269993,0.013754,1.022550,-11.831933,0.103356,0.000000
6.860000,0.041706,-11.876414,0.003842,0.004205,0.106817,0.185516,0.009451,1.068166,-11.876414,0.107848,0.000000
7.130000,0.072985,-11.876414,0.004005,0.004379,0.111222,0.324653,0.016539,1.112222,-11.876414,0.112358,0.000000
7.400001,0.081922,-11.787452,0.004169,0.004551,0.115601,0.364407,0.018564,1.156013,-11.787452,0.116850,0.000000
7.670001,0.041333,-11.787452,0.004376,0.004737,0.120310,0.183860,0.009366,1.203105,-11.787452,0.121342,0.000000
7.940001,0.063676,-11.787452,0.004557,0.004907,0.124646,0.283244,0.014429,1.246464,-11.787452,0.125852,0.000000
8.210000,0.092721,-11.831933,0.004738,0.005094,0.129382,0.412442,0.021011,1.293821,-11.831933,0.130344,0.000000
8.480000,0.059952,-11.742971,0.004911,0.005263,0.133674,0.266680,0.013585,1.336742,-11.742971,0.134837,0.000000
8.750000,0.052132,-11.787452,0.005096,0.005440,0.138175,0.231896,0.011813,1.381752,-11.787452,0.139346,0.000000
9.020000,0.006703,-11.698490,0.005273,0.005621,0.142772,0.029815,0.001519,1.427715,-11.698490,0.143838,0.000000
9.290001,0.090859,-11.698490,0.005450,0.005795,0.147195,0.404160,0.020589,1.471946,-11.698490,0.148331,0.000000
9.560000,0.096817,-11.742971,0.005618,0.005973,0.151704,0.430663,0.021939,1.517039,-11.742971,0.152840,0.000000
9.830001,0.068889,-11.742971,0.005808,0.006150,0.156214,0.306433,0.015610,1.562140,-11.742971,0.157333,0.000000
10.100000,0.090859,-11.654009,0.005967,0.006321,0.160558,0.404160,0.020589,1.605583,-11.654009,0.161842,0.000000
10.370001,0.064793,-11.698490,0.006170,0.006506,0.165250,0.288213,0.014682,1.652500,-11.698490,0.166334,0.000000
10.640000,0.092721,-11.742971,0.006342,0.006682,0.169725,0.412442,0.021011,1.697253,-11.742971,0.170827,0.000000
10.910001,0.062931,-11.698490,0.006515,0.006858,0.174200,0.279931,0.014260,1.741998,-11.698490,0.175336,0.000000
11.180000,0.028300,-11.787452,0.006700,0.007036,0.178727,0.125886,0.006413,1.787265,-11.787452,0.179828,0.000000
11.450001,0.114691,-11.698490,0.006881,0.007210,0.183124,0.510170,0.025989,1.831238,-11.698490,0.184321,0.000000
11.720000,0.075219,-11.654009,0.007054,0.007393,0.187781,0.334592,0.017045,1.877807,-11.654009,0.188830,0.000000
11.990001,0.086763,-11.609529,0.007243,0.007568,0.192221,0.385940,0.019661,1.922212,-11.609529,0.193323,0.000000
12.260000,0.090114,-11.654009,0.007416,0.007747,0.196774,0.400848,0.020420,1.967737,-11.654009,0.197815,0.000000
12.530001,0.069634,-11.698490,0.007614,0.007925,0.201284,0.309746,0.015779,2.012837,-11.698490,0.202324,0.000000
12.800000,0.101285,-11.654009,0.007791,0.008098,0.205680,0.450540,0.022952,2.056803,-11.654009,0.206816,0.000000
13.070001,0.068889,-11.654009,0.007976,0.008273,0.210138,0.306433,0.015610,2.101381,-11.654009,0.211308,0.000000
13.340001,0.073357,-11.609529,0.008157,0.008449,0.214604,0.326310,0.016623,2.146043,-11.609529,0.215818,0.000000
13.610001,0.093093,-11.609529,0.008334,0.008625,0.219079,0.414099,0.021095,2.190788,-11.609529,0.220310,0.000000
13.880001,0.061814,-11.654009,0.008515,0.008808,0.223736,0.274962,0.014007,2.237357,-11.654009,0.224802,0.000000
14.150001,0.099423,-11.609529,0.008718,0.008979,0.228063,0.442258,0.022530,2.280634,-11.609529,0.229312,0.000000
14.420001,0.092721,-11.565047,0.008899,0.009164,0.232773,0.412442,0.021011,2.327726,-11.565047,0.233804,0.000000
14.690001,0.075592,-11.609529,0.009084,0.009342,0.237291,0.336248,0.017129,2.372910,-11.609529,0.238297,0.000000
14.960001,0.082294,-11.609529,0.009253,0.009517,0.241740,0.366064,0.018648,2.417397,-11.609529,0.242806,0.000000
15.230000,0.044685,-11.609529,0.009425,0.009689,0.246101,0.198768,0.010126,2.461015,-11.609529,0.247298,0.000000
15.500001,0.082667,-11.520566,0.009610,0.009865,0.250568,0.367720,0.018733,2.505676,-11.520566,0.251791,0.000000
15.770000,0.099796,-11.520566,0.009783,0.010048,0.255225,0.443914,0.022614,2.552246,-11.520566,0.256300,0.000000
16.040001,0.080805,-11.520566,0.009977,0.010223,0.259674,0.359438,0.018311,2.596741,-11.520566,0.260792,0.000000
16.310001,0.112829,-11.565047,0.010132,0.010394,0.264001,0.501888,0.025567,2.640010,-11.565047,0.265285,0.000000
16.580000,0.087135,-11.565047,0.010356,0.010579,0.268719,0.387597,0.019745,2.687192,-11.565047,0.269794,0.000000
16.850000,0.096072,-11.520566,0.010529,0.010755,0.273176,0.427350,0.021770,2.731763,-11.520566,0.274287,0.000000
17.120001,0.079688,-11.476086,0.010710,0.010937,0.277808,0.354469,0.018057,2.778075,-11.476086,0.278779,0.000000
17.390001,0.053249,-11.476086,0.010865,0.011105,0.282066,0.236865,0.012066,2.820655,-11.476086,0.283288,0.000000
17.660002,0.088625,-11.520566,0.011072,0.011285,0.286636,0.394222,0.020083,2.866362,-11.520566,0.287781,0.000000
17.930000,0.087135,-11.476086,0.011253,0.011465,0.291206,0.387597,0.019745,2.912060,-11.476086,0.292273,0.000000
18.200001,0.106499,-11.476086,0.011426,0.011640,0.295664,0.473729,0.024133,2.956639,-11.476086,0.296783,0.000000
18.470001,0.117297,-11.387123,0.011615,0.011821,0.300243,0.521765,0.026580,3.002429,-11.387123,0.301275,0.000000
18.740002,0.111339,-11.387123,0.011775,0.011996,0.304700,0.495262,0.025230,3.046999,-11.387123,0.305767,0.000000
19.010000,0.105754,-11.431604,0.011973,0.012172,0.309166,0.470416,0.023964,3.091661,-11.431604,0.310277,0.000000
19.280001,0.049898,-11.431604,0.012141,0.012351,0.313710,0.221957,0.011307,3.137103,-11.431604,0.314769,0.000000
19.550001,0.107988,-11.387123,0.012331,0.012525,0.318125,0.480355,0.024470,3.181250,-11.387123,0.319261,0.000000
19.820002,0.072613,-11.387123,0.012516,0.012706,0.322721,0.322997,0.016454,3.227213,-11.387123,0.323770,0.000000
20.090000,0.094210,-11.431604,0.012689,0.012881,0.327170,0.419068,0.021348,3.271701,-11.431604,0.328262,0.000000
20.360001,0.129958,-11.342643,0.012857,0.013050,0.331463,0.578082,0.029449,3.314629,-11.342643,0.332755,0.000000
20.630001,0.096072,-11.431604,0.013034,0.013238,0.336233,0.427350,0.021770,3.362327,-11.431604,0.337264,0.000000
20.900002,0.112457,-11.298162,0.013210,0.013413,0.340699,0.500232,0.025483,3.406988,-11.298162,0.341756,0.000000
21.170000,0.098679,-11.253680,0.013383,0.013589,0.345165,0.438945,0.022361,3.451650,-11.253680,0.346249,0.000000
21.440001,0.063676,-11.298162,0.013573,0.013765,0.349622,0.283244,0.014429,3.496221,-11.298162,0.350758,0.000000
21.710001,0.110967,-11.342643,0.013724,0.013940,0.354080,0.493606,0.025145,3.540800,-11.342643,0.355251,0.000000
21.980001,0.091604,-11.298162,0.013918,0.014120,0.358651,0.407473,0.020758,3.586506,-11.298162,0.359760,0.000000
22.250002,0.109105,-11.298162,0.014112,0.014295,0.363099,0.485324,0.024724,3.630994,-11.298162,0.364252,0.000000
22.520000,0.125490,-11.209200,0.014284,0.014465,0.367400,0.558205,0.028436,3.674005,-11.209200,0.368745,0.000000
22.790001,0.105754,-11.253680,0.014474,0.014651,0.372144,0.470416,0.023964,3.721445,-11.253680,0.373254,0.000000
23.060001,0.110222,-11.253680,0.014651,0.014827,0.376593,0.490293,0.024977,3.765933,-11.253680,0.377747,0.000000
23.330002,0.103892,-11.298162,0.014832,0.015007,0.381172,0.462134,0.023542,3.811722,-11.298162,0.382239,0.000000
23.600000,0.084901,-11.209200,0.015017,0.015177,0.385508,0.377658,0.019239,3.855082,-11.209200,0.386748,0.000000
23.870001,0.094210,-11.209200,0.015181,0.015356,0.390052,0.419068,0.021348,3.900523,-11.209200,0.391241,0.000000
24.140001,0.050270,-11.164719,0.015353,0.015531,0.394493,0.223614,0.011391,3.944928,-11.164719,0.395733,0.000000
24.410002,0.115435,-11.209200,0.015530,0.015705,0.398898,0.513483,0.026158,3.988984,-11.209200,0.400242,0.000000
24.680000,0.137405,-11.253680,0.015711,0.015886,0.403503,0.611210,0.031137,4.035031,-11.253680,0.404735,0.000000
24.950001,0.108360,-11.164719,0.015910,0.016064,0.408022,0.482011,0.024555,4.080215,-11.164719,0.409227,0.000000
25.220001,0.139267,-11.120237,0.016086,0.016239,0.412470,0.619492,0.031558,4.124703,-11.120237,0.413737,0.000000
25.490002,0.094583,-11.209200,0.016259,0.016421,0.417101,0.420724,0.021433,4.171015,-11.209200,0.418229,0.000000
25.760002,0.105754,-11.164719,0.016448,0.016596,0.421541,0.470416,0.023964,4.215412,-11.164719,0.422721,0.000000
26.030001,0.104264,-11.075757,0.016625,0.016776,0.426103,0.463791,0.023627,4.261027,-11.075757,0.427231,0.000000
26.300001,0.065165,-11.120237,0.016819,0.016949,0.430500,0.289869,0.014767,4.305000,-11.120237,0.431723,0.000000
26.570002,0.150066,-11.120237,0.016974,0.017123,0.434914,0.667527,0.034005,4.349140,-11.120237,0.436215,0.000000
26.840002,0.119159,-11.075757,0.017164,0.017307,0.439588,0.530047,0.027002,4.395883,-11.075757,0.440725,0.000000
27.110001,0.117297,-11.075757,0.017328,0.017485,0.444107,0.521765,0.026580,4.441067,-11.075757,0.445216,0.000000
27.380001,0.129958,-11.075757,0.017505,0.017660,0.448565,0.578082,0.029449,4.485646,-11.075757,0.449709,0.000000
27.650002,0.118414,-11.031276,0.017673,0.017835,0.453004,0.526734,0.026833,4.530042,-11.031276,0.454218,0.000000
27.920002,0.132937,-10.986794,0.017863,0.018011,0.457470,0.591333,0.030124,4.574704,-10.986794,0.458710,0.000000
28.190001,0.106499,-11.031276,0.018039,0.018192,0.462084,0.473729,0.024133,4.620842,-11.031276,0.463203,0.000000
28.460001,0.139640,-11.031276,0.018212,0.018364,0.466455,0.621148,0.031643,4.664550,-11.031276,0.467712,0.000000
28.730001,0.146715,-10.986794,0.018384,0.018539,0.470886,0.652620,0.033246,4.708864,-10.986794,0.472205,0.000000
29.000002,0.116925,-10.897833,0.018583,0.018724,0.475587,0.520108,0.026496,4.755872,-10.897833,0.476697,0.000000
29.270000,0.153790,-10.942314,0.018742,0.018894,0.479906,0.684091,0.034849,4.799057,-10.942314,0.481206,0.000000
29.540001,0.148204,-10.897833,0.018923,0.019081,0.484650,0.659245,0.033584,4.846498,-10.897833,0.485699,0.000000
29.810001,0.142619,-10.942314,0.019091,0.019251,0.488977,0.634399,0.032318,4.889766,-10.942314,0.490191,0.000000
30.080002,0.115435,-10.942314,0.019285,0.019427,0.493434,0.513483,0.026158,4.934345,-10.942314,0.494701,0.000000
30.350002,0.087880,-10.853352,0.019484,0.019609,0.498057,0.390909,0.019914,4.980566,-10.853352,0.499193,0.000000
30.620001,0.143363,-10.808871,0.019678,0.019783,0.502480,0.637712,0.032487,5.024796,-10.808871,0.503685,0.000000
30.890001,0.150811,-10.897833,0.019863,0.019965,0.507111,0.670840,0.034174,5.071108,-10.897833,0.508195,0.000000
31.160002,0.118414,-10.853352,0.020049,0.020141,0.511585,0.526734,0.026833,5.115853,-10.853352,0.512687,0.000000
31.430002,0.155279,-10.897833,0.020247,0.020311,0.515887,0.690717,0.035187,5.158873,-10.897833,0.517179,0.000000
31.700001,0.119159,-10.853352,0.020402,0.020496,0.520605,0.530047,0.027002,5.206048,-10.853352,0.521689,0.000000
31.970001,0.142619,-10.808871,0.020596,0.020670,0.525019,0.634399,0.032318,5.250187,-10.808871,0.526181,0.000000
32.240002,0.126234,-10.719910,0.020773,0.020848,0.529545,0.561518,0.028605,5.295454,-10.719910,0.530673,0.000000
32.510002,0.107988,-10.764390,0.020963,0.021026,0.534073,0.480355,0.024470,5.340729,-10.764390,0.535183,0.000000
32.780003,0.169057,-10.808871,0.021122,0.021197,0.538400,0.752004,0.038309,5.383998,-10.808871,0.539675,0.000000
33.050003,0.110595,-10.719910,0.021333,0.021383,0.543126,0.491949,0.025061,5.431264,-10.719910,0.544167,0.000000
33.320000,0.154162,-10.719910,0.021502,0.021558,0.547575,0.685748,0.034934,5.475751,-10.719910,0.548677,0.000000
33.590000,0.151183,-10.719910,0.021678,0.021739,0.552172,0.672497,0.034259,5.521715,-10.719910,0.553169,0.000000
33.860001,0.129958,-10.675428,0.021864,0.021917,0.556690,0.578082,0.029449,5.566899,-10.675428,0.557679,0.000000
34.130001,0.165333,-10.719910,0.022049,0.022086,0.560991,0.735440,0.037465,5.609911,-10.719910,0.562170,0.000000
34.400002,0.122138,-10.630947,0.022222,0.022263,0.565492,0.543298,0.027677,5.654921,-10.630947,0.566663,0.000000
34.670002,0.142991,-10.630947,0.022407,0.022441,0.570002,0.636056,0.032402,5.700022,-10.630947,0.571172,0.000000
34.940002,0.176877,-10.586467,0.022579,0.022620,0.574555,0.786788,0.040081,5.745546,-10.586467,0.575665,0.000000
35.210003,0.122138,-10.675428,0.022786,0.022797,0.579056,0.543298,0.027677,5.790556,-10.675428,0.580157,0.000000
35.480003,0.159003,-10.630947,0.022976,0.022969,0.583418,0.707281,0.036031,5.834181,-10.630947,0.584666,0.000000
35.750000,0.151928,-10.541986,0.023157,0.023154,0.588118,0.675809,0.034427,5.881182,-10.541986,0.589159,0.000000
36.020000,0.134054,-10.453024,0.023351,0.023331,0.592619,0.596303,0.030377,5.926192,-10.453024,0.593651,0.000000
36.290001,0.144853,-10.541986,0.023506,0.023508,0.597103,0.644338,0.032824,5.971027,-10.541986,0.598160,0.000000
36.560001,0.097562,-10.541986,0.023713,0.023680,0.601482,0.433976,0.022108,6.014819,-10.541986,0.602653,0.000000
36.830002,0.157141,-10.586467,0.023886,0.023856,0.605948,0.698999,0.035609,6.059481,-10.586467,0.607145,0.000000
37.100002,0.172781,-10.453024,0.024063,0.024039,0.610597,0.768568,0.039153,6.105967,-10.453024,0.611655,0.000000
37.370003,0.162354,-10.453024,0.024239,0.024217,0.615106,0.722188,0.036790,6.151060,-10.453024,0.616147,0.000000
37.640003,0.160120,-10.453024,0.024403,0.024386,0.619399,0.712250,0.036284,6.193988,-10.453024,0.620639,0.000000
37.910004,0.173898,-10.453024,0.024593,0.024570,0.624091,0.773537,0.039406,6.240906,-10.453024,0.625149,0.000000
38.180000,0.162727,-10.497504,0.024783,0.024745,0.628514,0.723845,0.036874,6.285136,-10.497504,0.629641,0.000000
38.450001,0.155652,-10.453024,0.024955,0.024927,0.633136,0.692373,0.035271,6.331357,-10.453024,0.634133,0.000000
38.720001,0.122138,-10.364061,0.025140,0.025096,0.637438,0.543298,0.027677,6.374376,-10.364061,0.638643,0.000000
38.990002,0.153045,-10.364061,0.025296,0.025276,0.642017,0.680779,0.034681,6.420166,-10.364061,0.643135,0.000000
39.260002,0.152300,-10.319581,0.025481,0.025455,0.646561,0.677466,0.034512,6.465607,-10.319581,0.647627,0.000000
39.530003,0.159375,-10.408543,0.025666,0.025629,0.650983,0.708937,0.036115,6.509830,-10.408543,0.652137,0.000000
39.800003,0.192517,-10.319581,0.025804,0.025811,0.655606,0.856357,0.043625,6.556059,-10.319581,0.656629,0.000000
40.070004,0.174643,-10.230618,0.026029,0.025989,0.660115,0.776850,0.039575,6.601152,-10.230618,0.661121,0.000000
40.340000,0.171664,-10.319581,0.026201,0.026163,0.664547,0.763598,0.038900,6.645465,-10.319581,0.665631,0.000000
40.610001,0.118787,-10.275100,0.026425,0.026340,0.669030,0.528390,0.026917,6.690301,-10.275100,0.670123,0.000000
40.880001,0.163844,-10.319581,0.026615,0.026515,0.673471,0.728814,0.037128,6.734706,-10.319581,0.674615,0.000000
41.150002,0.148577,-10.230618,0.026822,0.026696,0.678075,0.660902,0.033668,6.780753,-10.230618,0.679124,0.000000
41.420002,0.152673,-10.230618,0.027012,0.026871,0.682533,0.679122,0.034596,6.825331,-10.230618,0.683617,0.000000
41.690002,0.198102,-10.230618,0.027210,0.027040,0.686826,0.881203,0.044891,6.868259,-10.230618,0.688109,0.000000
41.960003,0.131820,-10.230618,0.027400,0.027227,0.691578,0.586364,0.029871,6.915783,-10.230618,0.692619,0.000000
42.230003,0.157886,-10.230618,0.027589,0.027402,0.696019,0.702312,0.035777,6.960187,-10.230618,0.697111,0.000000
42.500004,0.139640,-10.141657,0.027770,0.027583,0.700614,0.621148,0.031643,7.006144,-10.141657,0.701603,0.000000
42.770000,0.119159,-10.097176,0.027939,0.027753,0.704934,0.530047,0.027002,7.049336,-10.097176,0.706113,0.000000
43.040001,0.159003,-10.052695,0.028115,0.027931,0.709451,0.707281,0.036031,7.094513,-10.052695,0.710605,0.000000
43.310001,0.110967,-10.141657,0.028314,0.028110,0.714005,0.493606,0.025145,7.140045,-10.141657,0.715098,0.000000
43.580002,0.161610,-10.097176,0.028491,0.028286,0.718453,0.718876,0.036621,7.184533,-10.097176,0.719607,0.000000
43.850002,0.179856,-10.008214,0.028663,0.028457,0.722807,0.800039,0.040756,7.228067,-10.008214,0.724099,0.000000
44.120003,0.136288,-10.008214,0.028861,0.028642,0.727508,0.606241,0.030883,7.275075,-10.008214,0.728592,0.000000
44.390003,0.191399,-10.052695,0.029034,0.028816,0.731930,0.851387,0.043372,7.319298,-10.052695,0.733101,0.000000
44.660004,0.158631,-10.008214,0.029206,0.028997,0.736526,0.705625,0.035946,7.365262,-10.008214,0.737594,0.000000
44.930000,0.156769,-9.963733,0.029387,0.029170,0.740923,0.697343,0.035524,7.409235,-9.963733,0.742103,0.000000
45.200001,0.149694,-9.874771,0.029560,0.029349,0.745468,0.665871,0.033921,7.454676,-9.874771,0.746595,0.000000
45.470001,0.112457,-9.919252,0.029754,0.029525,0.749942,0.500232,0.025483,7.499421,-9.919252,0.751087,0.000000
45.740002,0.171291,-9.919252,0.029931,0.029697,0.754313,0.761942,0.038815,7.543129,-9.919252,0.755597,0.000000
46.010002,0.196240,-9.919252,0.030103,0.029882,0.759005,0.872920,0.044469,7.590047,-9.919252,0.760089,0.000000
46.280003,0.181718,-9.919252,0.030306,0.030057,0.763445,0.808321,0.041178,7.634451,-9.919252,0.764581,0.000000
46.550003,0.185441,-9.874771,0.030474,0.030233,0.767920,0.824885,0.042022,7.679204,-9.874771,0.769091,0.000000
46.820004,0.165333,-9.830290,0.030651,0.030413,0.772490,0.735440,0.037465,7.724903,-9.830290,0.773583,0.000000
47.090004,0.182463,-9.830290,0.030823,0.030587,0.776904,0.811634,0.041347,7.769042,-9.830290,0.778075,0.000000
47.360001,0.186931,-9.874771,0.030991,0.030767,0.781483,0.831511,0.042359,7.814832,-9.874771,0.782585,0.000000
47.630001,0.166823,-9.830290,0.031185,0.030939,0.785863,0.742065,0.037803,7.858630,-9.830290,0.787077,0.000000
47.900002,0.246883,-9.696847,0.031358,0.031114,0.790303,1.098190,0.055944,7.903035,-9.696847,0.791569,0.000000
48.170002,0.255075,-9.696847,0.031560,0.031298,0.794969,1.134631,0.057801,7.949687,-9.696847,0.796079,0.000000
48.440002,0.331039,-9.741328,0.031728,0.031475,0.799470,1.472536,0.075015,7.994698,-9.741328,0.800571,0.000000
48.710003,0.475520,-9.696847,0.031931,0.031654,0.804023,2.115217,0.107754,8.040230,-9.696847,0.805063,0.000000
48.980003,0.668036,-9.652367,0.032099,0.031824,0.808324,2.971574,0.151379,8.083241,-9.652367,0.809573,0.000000
49.250004,0.553718,-9.607885,0.032121,-0.000007,-0.000173,2.463060,0.125474,-0.001733,-9.607885,0.000104,0.000000
49.520000,0.578294,-9.563404,0.032134,-0.000007,-0.000173,2.572382,0.131043,-0.001733,-9.563404,0.000139,0.000000
49.790001,0.592445,-9.607885,0.032129,-0.000007,-0.000173,2.635325,0.134250,-0.001733,-9.607885,0.000590,0.000000
50.060001,0.597285,-9.652367,0.032129,-0.000006,-0.000165,2.656858,0.135347,-0.001650,-9.652367,0.001032,0.000000
50.330002,0.683303,-9.563404,0.032138,0.000016,0.000407,3.039486,0.154839,0.004073,-9.563404,0.001483,0.000000
50.600002,0.729478,-9.607885,0.032142,0.000032,0.000806,3.244879,0.165302,0.008062,-9.607885,0.001934,0.000000
50.870003,0.780865,-9.474442,0.032155,0.000049,0.001248,3.473461,0.176947,0.012483,-9.474442,0.002384,0.000000
51.140003,0.819964,-9.518924,0.032164,0.000075,0.001908,3.647383,0.185807,0.019076,-9.518924,0.002836,0.000000
51.410004,0.840072,-9.563404,0.032185,0.000090,0.002289,3.736828,0.190363,0.022891,-9.563404,0.003287,0.000000
51.680004,0.848637,-9.429961,0.032224,0.000107,0.002715,3.774925,0.192304,0.027145,-9.429961,0.003737,0.000000
51.950001,0.885874,-9.474442,0.032220,0.000122,0.003087,3.940565,0.200742,0.030870,-9.474442,0.004188,0.000000
52.220001,0.952529,-9.385481,0.032233,0.000136,0.003460,4.237060,0.215846,0.034602,-9.385481,0.004640,0.000000
52.490002,1.019556,-9.429961,0.032259,0.000159,0.004050,4.535211,0.231035,0.040498,-9.429961,0.005082,0.000000
52.760002,1.060144,-9.341000,0.032276,0.000173,0.004406,4.715758,0.240232,0.044056,-9.341000,0.005533,0.000000
53.030003,1.106691,-9.429961,0.032293,0.000194,0.004917,4.922807,0.250780,0.049173,-9.429961,0.005984,0.000000
53.300003,1.174463,-9.341000,0.032298,0.000213,0.005412,5.224271,0.266137,0.054116,-9.341000,0.006434,0.000000
53.570004,1.175207,-9.341000,0.032319,0.000227,0.005758,5.227584,0.266306,0.057583,-9.341000,0.006885,0.000000
53.840004,1.251544,-9.252038,0.032323,0.000244,0.006209,5.567145,0.283604,0.062095,-9.252038,0.007337,0.000000
54.110004,1.316337,-9.341000,0.032341,0.000257,0.006530,5.855358,0.298286,0.065297,-9.341000,0.007788,0.000000
54.380001,1.477946,-9.252038,0.032367,0.000281,0.007146,6.574234,0.334907,0.071459,-9.252038,0.008238,0.000000
54.650002,1.571039,-9.163075,0.032392,0.000297,0.007545,6.988332,0.356003,0.075448,-9.163075,0.008689,0.000000
54.920002,1.676421,-9.207557,0.032397,0.000319,0.008100,7.457093,0.379882,0.080997,-9.207557,0.009141,0.000000
55.190002,1.780313,-9.207557,0.032418,0.000339,0.008603,7.919227,0.403425,0.086031,-9.207557,0.009583,0.000000
55.460003,1.823508,-9.163075,0.032431,0.000354,0.009002,8.111369,0.413213,0.090020,-9.163075,0.010034,0.000000
55.730003,1.927400,-9.207557,0.032461,0.000370,0.009409,8.573503,0.436755,0.094092,-9.207557,0.010485,0.000000
56.000004,2.090871,-9.118595,0.032457,0.000388,0.009843,9.300660,0.473798,0.098430,-9.118595,0.010935,0.000000
56.270004,2.240937,-9.118595,0.032487,0.000402,0.010207,9.968187,0.507804,0.102071,-9.118595,0.011386,0.000000
56.540001,2.416325,-9.118595,0.032500,0.000421,0.010693,10.748350,0.547547,0.106931,-9.118595,0.011838,0.000000
56.810001,2.575700,-9.074114,0.032513,0.000439,0.011153,11.457287,0.583662,0.111526,-9.074114,0.012288,0.000000
57.080002,2.797634,-8.985152,0.032539,0.000462,0.011733,12.444499,0.633953,0.117332,-8.985152,0.012739,0.000000
57.350002,2.916421,-9.029634,0.032565,0.000475,0.012072,12.972889,0.660870,0.120715,-9.029634,0.013190,0.000000
57.620003,3.095905,-8.985152,0.032569,0.000494,0.012548,13.771273,0.701542,0.125484,-8.985152,0.013632,0.000000
57.890003,3.265707,-9.029634,0.032578,0.000510,0.012956,14.526588,0.740020,0.129565,-9.029634,0.014084,0.000000
58.160004,3.558019,-9.029634,0.032608,0.000526,0.013373,15.826859,0.806259,0.133728,-9.029634,0.014535,0.000000
58.430004,3.799316,-8.940671,0.032617,0.000543,0.013797,16.900204,0.860937,0.137975,-8.940671,0.014985,0.000000
58.700005,3.968373,-8.896191,0.032634,0.000557,0.014144,17.652206,0.899246,0.141442,-8.896191,0.015436,0.000000
58.970001,4.385058,-8.896191,0.032634,0.000584,0.014838,19.505713,0.993668,0.148383,-8.896191,0.015887,0.000000
59.240002,4.603268,-8.896191,0.032660,0.000601,0.015263,20.476360,1.043115,0.152630,-8.896191,0.016339,0.000000
59.510002,4.843449,-8.940671,0.032686,0.000620,0.015749,21.544735,1.097541,0.157489,-8.940671,0.016789,0.000000
59.780003,5.139485,-8.896191,0.032711,0.000637,0.016191,22.861570,1.164624,0.161910,-8.896191,0.017240,0.000000
60.050003,5.369983,-8.807228,0.032707,0.000651,0.016529,23.886879,1.216856,0.165294,-8.807228,0.017682,0.000000
60.320004,5.501059,-8.807228,0.032720,0.000661,0.016798,24.469931,1.246558,0.167981,-8.807228,0.018133,0.000000
60.590004,5.935245,-8.807228,0.032733,0.000682,0.017318,26.401287,1.344946,0.173182,-8.807228,0.018585,0.000000
60.860004,6.138560,-8.762748,0.032755,0.000700,0.017769,27.305679,1.391018,0.177693,-8.762748,0.019036,0.000000
61.130001,6.731377,-8.762748,0.032780,0.000725,0.018420,29.942661,1.525352,0.184196,-8.762748,0.019486,0.000000
61.400002,7.047149,-8.718266,0.032793,0.000744,0.018896,31.347282,1.596907,0.188965,-8.718266,0.019937,0.000000
61.670002,7.310416,-8.718266,0.032798,0.000759,0.019270,32.518356,1.656564,0.192697,-8.718266,0.020388,0.000000
61.940002,7.794873,-8.673785,0.032811,0.000781,0.019842,34.673325,1.766343,0.198419,-8.673785,0.020839,0.000000
62.210003,8.091654,-8.673785,0.032832,0.000796,0.020215,35.993473,1.833595,0.202151,-8.673785,0.021290,0.000000
62.480003,8.019786,-8.629305,0.032849,0.000800,0.020319,35.673790,1.817309,0.203188,-8.629305,0.021741,0.000000
62.750004,8.668086,-8.629305,0.032854,0.000826,0.020969,38.557571,1.964216,0.209691,-8.629305,0.022183,0.000000
63.020004,9.241912,-8.584824,0.032871,0.000851,0.021611,41.110077,2.094247,0.216110,-8.584824,0.022634,0.000000
63.290005,9.678705,-8.584824,0.032897,0.000871,0.022114,43.053032,2.193226,0.221144,-8.584824,0.023086,0.000000
63.560001,9.916279,-8.629305,0.032910,0.000885,0.022487,44.109810,2.247061,0.224868,-8.629305,0.023536,0.000000
63.830002,10.301684,-8.584824,0.032923,0.000901,0.022877,45.824181,2.334395,0.228774,-8.584824,0.023987,0.000000
64.100006,10.711294,-8.495862,0.032936,0.000919,0.023354,47.646217,2.427214,0.233543,-8.495862,0.024438,0.000000
64.370003,10.873276,-8.495862,0.032940,0.000932,0.023675,48.366745,2.463919,0.236753,-8.495862,0.024889,0.000000
64.639999,11.778141,-8.495862,0.032953,0.000960,0.024395,52.391788,2.668965,0.243952,-8.495862,0.025340,0.000000
64.910004,12.111414,-8.451381,0.032974,0.000974,0.024733,53.874260,2.744486,0.247328,-8.451381,0.025791,0.000000
65.180000,12.512832,-8.451381,0.033009,0.000995,0.025271,55.659855,2.835448,0.252710,-8.451381,0.026233,0.000000
65.450005,12.785409,-8.362419,0.033018,0.001009,0.025626,56.872341,2.897215,0.256260,-8.362419,0.026684,0.000000
65.720001,13.251619,-8.362419,0.033022,0.001027,0.026086,58.946148,3.002860,0.260863,-8.362419,0.027135,0.000000
65.990005,13.699955,-8.406899,0.033043,0.001045,0.026554,60.940445,3.104454,0.265541,-8.406899,0.027587,0.000000
66.260002,13.742033,-8.406899,0.033056,0.001055,0.026789,61.127617,3.113989,0.267887,-8.406899,0.028037,0.000000
66.530006,14.576893,-8.317938,0.033056,0.001083,0.027517,64.841255,3.303171,0.275169,-8.317938,0.028488,0.000000
66.800003,15.074755,-8.317938,0.033087,0.001100,0.027951,67.055855,3.415988,0.279507,-8.317938,0.028939,0.000000
67.070000,15.260941,-8.317938,0.033108,0.001114,0.028289,67.884056,3.458179,0.282891,-8.317938,0.029390,0.000000
67.340004,15.829181,-8.317938,0.033112,0.001134,0.028809,70.411713,3.586944,0.288091,-8.317938,0.029841,0.000000
67.610001,16.350502,-8.273457,0.033130,0.001154,0.029312,72.730667,3.705077,0.293117,-8.273457,0.030284,0.000000
67.880005,16.640207,-8.273457,0.033151,0.001169,0.029702,74.019341,3.770725,0.297023,-8.273457,0.030734,0.000000
68.150002,16.919115,-8.184495,0.033164,0.001182,0.030032,75.259979,3.833926,0.300316,-8.184495,0.031185,0.000000
68.420006,17.641890,-8.184495,0.033169,0.001206,0.030630,78.475044,3.997709,0.306304,-8.184495,0.031636,0.000000
68.690002,18.185181,-8.184495,0.033181,0.001228,0.031194,80.891724,4.120821,0.311936,-8.184495,0.032087,0.000000
68.960007,18.316628,-8.184495,0.033207,0.001241,0.031532,81.476425,4.150607,0.315320,-8.184495,0.032538,0.000000
69.230003,18.737036,-8.184495,0.033225,0.001258,0.031948,83.346497,4.245873,0.319483,-8.184495,0.032989,0.000000
69.500000,19.313841,-8.051052,0.033229,0.001278,0.032460,85.912254,4.376579,0.324600,-8.051052,0.033440,0.000000
69.770004,19.619932,-8.095533,0.033255,0.001293,0.032842,87.273819,4.445940,0.328415,-8.095533,0.033891,0.000000
70.040001,19.932724,-8.095533,0.033255,0.001308,0.033223,88.665184,4.516820,0.332231,-8.095533,0.034342,0.000000
70.310005,20.659224,-8.095533,0.033276,0.001330,0.033770,91.896812,4.681447,0.337696,-8.095533,0.034784,0.000000
70.580002,21.174587,-8.095533,0.033289,0.001350,0.034281,94.189270,4.798230,0.342813,-8.095533,0.035235,0.000000
70.850006,21.373434,-8.006571,0.033302,0.001364,0.034637,95.073784,4.843289,0.346371,-8.006571,0.035686,0.000000
71.120003,21.898851,-8.006571,0.033324,0.001382,0.035114,97.410957,4.962350,0.351140,-8.006571,0.036137,0.000000
71.390007,22.034023,-8.006571,0.033328,0.001394,0.035400,98.012230,4.992981,0.354001,-8.006571,0.036588,0.000000
71.660004,22.653278,-7.962090,0.033345,0.001413,0.035903,100.766815,5.133306,0.359028,-7.962090,0.037039,0.000000
71.930000,23.052090,-7.962090,0.033363,0.001429,0.036302,102.540817,5.223678,0.363017,-7.962090,0.037490,0.000000
72.200005,23.562984,-7.917609,0.033371,0.001447,0.036745,104.813393,5.339449,0.367445,-7.917609,0.037941,0.000000
72.470001,24.581051,-7.828648,0.033388,0.001474,0.037438,109.341972,5.570146,0.374379,-7.828648,0.038392,0.000000
72.740005,24.829050,-7.828648,0.033393,0.001489,0.037811,110.445129,5.626343,0.378111,-7.828648,0.038835,0.000000
73.010002,25.118755,-7.873128,0.033410,0.001505,0.038227,111.733803,5.691991,0.382274,-7.873128,0.039285,0.000000
73.280006,25.424847,-7.828648,0.033436,0.001520,0.038609,113.095367,5.761353,0.386090,-7.828648,0.039736,0.000000
73.550003,26.001652,-7.784166,0.033432,0.001535,0.038990,115.661125,5.892058,0.389905,-7.784166,0.040187,0.000000
73.820000,26.751982,-7.739686,0.033440,0.001558,0.039563,118.998756,6.062086,0.395627,-7.739686,0.040638,0.000000
74.090004,27.069614,-7.828648,0.033466,0.001572,0.039936,120.411659,6.134062,0.399359,-7.828648,0.041089,0.000000
74.360001,27.772282,-7.784166,0.033466,0.001593,0.040456,123.537277,6.293289,0.404560,-7.784166,0.041540,0.000000
74.630005,28.329723,-7.784166,0.033479,0.001611,0.040925,126.016907,6.419607,0.409246,-7.784166,0.041991,0.000000
74.900002,28.635815,-7.695205,0.033500,0.001625,0.041280,127.378464,6.488968,0.412796,-7.695205,0.042442,0.000000
75.170006,29.256931,-7.606243,0.033513,0.001644,0.041766,130.141327,6.629715,0.417656,-7.606243,0.042884,0.000000
75.440002,29.522060,-7.695205,0.033522,0.001657,0.042087,131.320679,6.689795,0.420865,-7.695205,0.043335,0.000000
75.710007,30.576246,-7.695205,0.033531,0.001680,0.042685,136.009933,6.928677,0.426845,-7.695205,0.043786,0.000000
75.980003,31.069267,-7.695205,0.033544,0.001697,0.043093,138.203003,7.040397,0.430925,-7.695205,0.044237,0.000000
76.250000,31.870985,-7.606243,0.033561,0.001718,0.043647,141.769226,7.222068,0.436474,-7.606243,0.044688,0.000000
76.520004,32.572163,-7.606243,0.033574,0.001737,0.044124,144.888214,7.380958,0.441243,-7.606243,0.045139,0.000000
76.790001,33.028690,-7.561762,0.033578,0.001754,0.044558,146.918945,7.484408,0.445581,-7.561762,0.045590,0.000000
77.060005,33.534000,-7.561762,0.033587,0.001770,0.044965,149.166687,7.598913,0.449653,-7.561762,0.046041,0.000000
77.330002,34.176716,-7.561762,0.033608,0.001786,0.045364,152.025620,7.744555,0.453642,-7.561762,0.046492,0.000000
77.600006,34.642181,-7.472800,0.033617,0.001801,0.045755,154.096115,7.850031,0.457548,-7.472800,0.046943,0.000000
77.870003,35.495289,-7.517281,0.033643,0.001821,0.046249,157.890930,8.043347,0.462491,-7.517281,0.047385,0.000000
78.140007,36.222530,-7.517281,0.033638,0.001838,0.046674,161.125870,8.208142,0.466738,-7.517281,0.047836,0.000000
78.410004,37.232403,-7.428319,0.033647,0.001860,0.047246,165.617996,8.436983,0.472461,-7.428319,0.048287,0.000000
78.680000,37.685955,-7.383838,0.033664,0.001875,0.047637,167.635498,8.539760,0.476367,-7.383838,0.048738,0.000000
78.950005,38.432560,-7.428319,0.033673,0.001893,0.048088,170.956558,8.708943,0.480878,-7.428319,0.049188,0.000000
79.220001,39.049210,-7.339357,0.033682,0.001909,0.048487,173.699554,8.848678,0.484868,-7.339357,0.049640,0.000000
79.490005,39.855770,-7.428319,0.033690,0.001926,0.048911,177.287323,9.031446,0.489114,-7.428319,0.050091,0.000000
79.760002,40.602375,-7.339357,0.033716,0.001942,0.049319,180.608383,9.200630,0.493187,-7.339357,0.050542,0.000000
80.030006,41.175083,-7.294876,0.033720,0.001956,0.049683,183.155914,9.330407,0.496828,-7.294876,0.050992,0.000000
80.300003,42.719685,-7.294876,0.033720,0.001983,0.050377,190.026642,9.680419,0.503770,-7.294876,0.051435,0.000000
80.570007,43.526245,-7.294876,0.033746,0.002000,0.050811,193.614410,9.863189,0.508107,-7.294876,0.051886,0.000000
80.840004,44.287746,-7.250395,0.033755,0.002019,0.051288,197.001740,10.035747,0.512876,-7.250395,0.052337,0.000000
81.110001,45.074940,-7.205914,0.033768,0.002037,0.051730,200.503342,10.214128,0.517297,-7.205914,0.052788,0.000000
81.380005,45.613766,-7.161433,0.033781,0.002049,0.052051,202.900162,10.336227,0.520506,-7.161433,0.053239,0.000000
81.650002,45.995819,-7.116952,0.033785,0.002062,0.052372,204.599625,10.422802,0.523716,-7.116952,0.053689,0.000000
81.920006,47.178474,-7.250395,0.033794,0.002080,0.052840,209.860336,10.690795,0.528402,-7.250395,0.054141,0.000000
82.190002,48.078869,-7.161433,0.033807,0.002103,0.053421,213.865494,10.894828,0.534208,-7.161433,0.054592,0.000000
82.460007,49.617886,-7.161433,0.033811,0.002124,0.053950,220.711380,11.243574,0.539499,-7.161433,0.055043,0.000000
82.730003,50.530941,-7.116952,0.033828,0.002142,0.054409,224.772858,11.450475,0.544094,-7.116952,0.055485,0.000000
83.000008,51.161739,-7.116952,0.033820,0.002157,0.054783,227.578781,11.593416,0.547826,-7.116952,0.055936,0.000000
83.270004,52.496696,-7.116952,0.033832,0.002180,0.055363,233.516968,11.895922,0.553632,-7.116952,0.056387,0.000000
83.540001,53.221706,-7.072471,0.033845,0.002194,0.055736,236.741974,12.060210,0.557364,-7.072471,0.056838,0.000000
83.810005,53.127869,-6.983510,0.033858,0.002202,0.055936,236.324570,12.038947,0.559362,-6.983510,0.057289,0.000000
84.080002,54.439365,-7.072471,0.033858,0.002223,0.056465,242.158386,12.336136,0.564646,-7.072471,0.057739,0.000000
84.350006,56.256168,-6.983510,0.033858,0.002249,0.057116,250.239929,12.747829,0.571156,-6.983510,0.058190,0.000000
84.620003,57.312218,-6.939028,0.033880,0.002269,0.057636,254.937469,12.987134,0.576356,-6.939028,0.058642,0.000000
84.890007,58.131435,-6.939028,0.033880,0.002283,0.057982,258.581543,13.172772,0.579823,-6.939028,0.059093,0.000000
85.160004,59.077637,-6.894547,0.033897,0.002298,0.058373,262.790466,13.387184,0.583729,-6.894547,0.059543,0.000000
85.430000,60.065910,-6.894547,0.033901,0.002316,0.058832,267.186523,13.611130,0.588324,-6.894547,0.059986,0.000000
85.700005,60.467327,-6.939028,0.033919,0.002327,0.059110,268.972107,13.702092,0.591102,-6.939028,0.060436,0.000000
85.970001,62.113586,-6.805585,0.033932,0.002353,0.059769,276.295044,14.075140,0.597688,-6.805585,0.060888,0.000000
86.240005,63.711811,-6.850067,0.033932,0.002372,0.060246,283.404297,14.437304,0.602457,-6.850067,0.061339,0.000000
86.510002,64.755577,-6.805585,0.033940,0.002390,0.060714,288.047180,14.673823,0.607143,-6.805585,0.061790,0.000000
86.780006,65.736031,-6.805585,0.033940,0.002406,0.061122,292.408478,14.895997,0.611215,-6.805585,0.062240,0.000000
87.050003,66.578712,-6.761105,0.033940,0.002425,0.061599,296.156891,15.086951,0.615992,-6.761105,0.062691,0.000000
87.320007,67.074341,-6.805585,0.033970,0.002423,0.061547,298.361572,15.199264,0.615469,-6.805585,0.061824,0.000000
87.590004,66.568283,-6.761105,0.033975,0.002415,0.061330,296.110504,15.084588,0.613297,-6.761105,0.061547,0.000000
87.860001,66.196655,-6.716624,0.033975,0.002415,0.061330,294.457428,15.000376,0.613297,-6.716624,0.061547,0.000000
88.130005,65.868599,-6.627662,0.033983,0.002415,0.061330,292.998169,14.926038,0.613297,-6.627662,0.061547,0.000000
88.400002,65.608307,-6.627662,0.033992,0.002415,0.061330,291.840332,14.867055,0.613297,-6.627662,0.061547,0.000000
88.670006,65.374458,-6.627662,0.033975,0.002415,0.061330,290.800110,14.814064,0.613297,-6.627662,0.061547,0.000000
88.940002,65.169655,-6.672143,0.033983,0.002415,0.061330,289.889099,14.767654,0.613297,-6.672143,0.061547,0.000000
89.210007,64.990540,-6.583181,0.033988,0.002415,0.061330,289.092346,14.727067,0.613297,-6.583181,0.061547,0.000000
89.480003,64.844200,-6.538700,0.034005,0.002415,0.061330,288.441406,14.693906,0.613297,-6.538700,0.061547,0.000000
89.750008,64.698601,-6.583181,0.033996,0.002415,0.061330,287.793762,14.660913,0.613297,-6.583181,0.061547,0.000000
90.020004,64.573853,-6.538700,0.033988,0.002415,0.061330,287.238831,14.632645,0.613297,-6.538700,0.061547,0.000000
90.290001,64.425652,-6.583181,0.033992,0.002414,0.061321,286.579620,14.599061,0.613214,-6.583181,0.061547,0.000000
90.560005,64.320267,-6.449738,0.033996,0.002414,0.061321,286.110840,14.575181,0.613214,-6.449738,0.061547,0.000000
90.830002,64.219353,-6.494219,0.033988,0.002414,0.061321,285.661957,14.552313,0.613214,-6.494219,0.061547,0.000000
91.100006,64.116585,-6.449738,0.033996,0.002414,0.061321,285.204803,14.529026,0.613214,-6.449738,0.061547,0.000000
91.370003,64.017532,-6.449738,0.033988,0.002414,0.061321,284.764221,14.506580,0.613214,-6.449738,0.061547,0.000000
91.640007,63.937469,-6.405257,0.033992,0.002414,0.061321,284.408081,14.488438,0.613214,-6.405257,0.061547,0.000000
91.910004,63.874165,-6.360776,0.034001,0.002414,0.061321,284.126465,14.474092,0.613214,-6.360776,0.061547,0.000000
92.180008,63.787403,-6.360776,0.034009,0.002414,0.061321,283.740540,14.454432,0.613214,-6.360776,0.061547,0.000000
92.450005,63.726334,-6.360776,0.034001,0.002414,0.061321,283.468903,14.440593,0.613214,-6.360776,0.061547,0.000000
92.720001,63.650742,-6.405257,0.033988,0.002414,0.061321,283.132629,14.423464,0.613214,-6.405257,0.061547,0.000000
92.990005,63.586319,-6.360776,0.033992,0.002414,0.061321,282.846069,14.408866,0.613214,-6.360776,0.061547,0.000000
93.260002,63.514824,-6.271814,0.034001,0.002414,0.061321,282.528046,14.392665,0.613214,-6.271814,0.061547,0.000000
93.530006,63.461948,-6.271814,0.034005,0.002414,0.061321,282.292847,14.380683,0.613214,-6.271814,0.061547,0.000000
93.800003,63.401997,-6.271814,0.033996,0.002414,0.061321,282.026154,14.367098,0.613214,-6.271814,0.061547,0.000000
94.070007,63.346886,-6.271814,0.033992,0.002414,0.061321,281.781006,14.354609,0.613214,-6.271814,0.061547,0.000000
94.340004,63.284698,-6.227333,0.033996,0.002414,0.061321,281.504395,14.340517,0.613214,-6.227333,0.061547,0.000000
94.610008,63.245602,-6.182852,0.034005,0.002414,0.061321,281.330475,14.331658,0.613214,-6.182852,0.061547,0.000000
94.880005,63.200172,-6.227333,0.034009,0.002414,0.061321,281.128418,14.321363,0.613214,-6.227333,0.061547,0.000000
95.150002,63.155857,-6.138371,0.033992,0.002414,0.061321,280.931274,14.311322,0.613214,-6.138371,0.061547,0.000000
95.420006,63.107822,-6.138371,0.033992,0.002414,0.061321,280.717621,14.300437,0.613214,-6.138371,0.061547,0.000000
95.690002,63.062393,-6.182852,0.034009,0.002414,0.061321,280.515533,14.290143,0.613214,-6.182852,0.061547,0.000000
95.960007,63.021805,-6.093890,0.033992,0.002414,0.061321,280.334991,14.280945,0.613214,-6.093890,0.061547,0.000000
96.230003,62.973022,-6.004929,0.033992,0.002414,0.061321,280.117981,14.269891,0.613214,-6.004929,0.061547,0.000000
96.500008,62.957756,-6.049409,0.034001,0.002414,0.061321,280.050079,14.266431,0.613214,-6.049409,0.061547,0.000000
96.770004,62.906742,-6.093890,0.033988,0.002414,0.061321,279.823151,14.254871,0.613214,-6.093890,0.061547,0.000000
97.040001,62.872856,-6.049409,0.034014,0.002414,0.061321,279.672424,14.247193,0.613214,-6.049409,0.061547,0.000000
97.310005,62.824818,-6.004929,0.034014,0.002414,0.061321,279.458740,14.236307,0.613214,-6.004929,0.061547,0.000000
97.580002,62.789444,-5.915967,0.033996,0.002414,0.061321,279.301392,14.228292,0.613214,-5.915967,0.061547,0.000000
97.850006,62.771198,-5.915967,0.033992,0.002414,0.061321,279.220245,14.224156,0.613214,-5.915967,0.061547,0.000000
98.120003,62.714226,-5.960447,0.034001,0.002414,0.061321,278.966797,14.211247,0.613214,-5.960447,0.061547,0.000000
98.390007,62.697094,-5.960447,0.033996,0.002414,0.061321,278.890594,14.207364,0.613214,-5.960447,0.061547,0.000000
98.660004,62.657253,-5.871486,0.034005,0.002414,0.061321,278.713379,14.198337,0.613214,-5.871486,0.061547,0.000000
98.930008,62.642731,-5.871486,0.034009,0.002414,0.061321,278.648773,14.195045,0.613214,-5.871486,0.061547,0.000000
99.200005,62.606236,-5.871486,0.034005,0.002414,0.061321,278.486450,14.186775,0.613214,-5.871486,0.061547,0.000000
99.470001,62.576073,-5.871486,0.034001,0.002414,0.061321,278.352264,14.179941,0.613214,-5.871486,0.061547,0.000000
99.740005,62.554848,-5.871486,0.034001,0.002414,0.061321,278.257874,14.175132,0.613214,-5.871486,0.061547,0.000000
100.010002,62.522453,-5.782524,0.034014,0.002414,0.061321,278.113770,14.167790,0.613214,-5.782524,0.061547,0.000000
100.280006,62.496014,-5.738043,0.034009,0.002414,0.061321,277.996155,14.161798,0.613214,-5.738043,0.061547,0.000000
100.550003,62.469574,-5.782524,0.034001,0.002414,0.061321,277.878540,14.155807,0.613214,-5.782524,0.061547,0.000000
100.820007,62.436062,-5.782524,0.034001,0.002414,0.061321,277.729462,14.148213,0.613214,-5.782524,0.061547,0.000000
101.090004,62.403294,-5.693562,0.034005,0.002414,0.061321,277.583710,14.140789,0.613214,-5.693562,0.061547,0.000000
101.360008,62.381695,-5.693562,0.034005,0.002414,0.061321,277.487640,14.135895,0.613214,-5.693562,0.061547,0.000000
101.630005,62.364567,-5.649081,0.034014,0.002414,0.061321,277.411438,14.132012,0.613214,-5.649081,0.061547,0.000000
101.900002,62.345577,-5.604600,0.034009,0.002414,0.061321,277.326965,14.127710,0.613214,-5.604600,0.061547,0.000000
102.170006,62.320999,-5.649081,0.034009,0.002414,0.061321,277.217651,14.122141,0.613214,-5.649081,0.061547,0.000000
102.440002,62.305733,-5.604600,0.034001,0.002414,0.061321,277.149750,14.118681,0.613214,-5.604600,0.061547,0.000000
102.710007,62.266632,-5.515638,0.034014,0.002414,0.061321,276.975800,14.109820,0.613214,-5.515638,0.061547,0.000000
102.980003,62.261791,-5.471157,0.034009,0.002414,0.061321,276.954285,14.108724,0.613214,-5.471157,0.061547,0.000000
103.250008,62.239449,-5.560119,0.033996,0.002414,0.061321,276.854889,14.103661,0.613214,-5.560119,0.061547,0.000000
103.520004,62.205936,-5.515638,0.034009,0.002414,0.061321,276.705811,14.096066,0.613214,-5.515638,0.061547,0.000000
103.790009,62.177265,-5.515638,0.034009,0.002414,0.061321,276.578278,14.089570,0.613214,-5.515638,0.061547,0.000000
104.060005,62.170559,-5.471157,0.034014,0.002414,0.061321,276.548462,14.088050,0.613214,-5.471157,0.061547,0.000000
104.330002,62.157902,-5.426676,0.034009,0.002414,0.061321,276.492157,14.085181,0.613214,-5.426676,0.061547,0.000000
104.600006,62.122150,-5.471157,0.034001,0.002414,0.061321,276.333130,14.077081,0.613214,-5.471157,0.061547,0.000000
104.870003,62.110981,-5.382195,0.034001,0.002414,0.061321,276.283447,14.074550,0.613214,-5.382195,0.061547,0.000000
105.140007,62.081192,-5.426676,0.034009,0.002414,0.061321,276.150940,14.067799,0.613214,-5.426676,0.061547,0.000000
105.410004,62.059967,-5.337714,0.034009,0.002414,0.061321,276.056519,14.062989,0.613214,-5.337714,0.061547,0.000000
105.680008,62.048794,-5.337714,0.034018,0.002414,0.061321,276.006805,14.060457,0.613214,-5.337714,0.061547,0.000000
105.950005,62.032410,-5.337714,0.034005,0.002414,0.061321,275.933929,14.056746,0.613214,-5.337714,0.061547,0.000000
106.220009,62.021240,-5.382195,0.034018,0.002414,0.061321,275.884247,14.054214,0.613214,-5.382195,0.061547,0.000000
106.490005,62.000015,-5.337714,0.034005,0.002414,0.061321,275.789856,14.049404,0.613214,-5.337714,0.061547,0.000000
106.760002,61.974319,-5.248752,0.034005,0.002414,0.061321,275.675537,14.043582,0.613214,-5.248752,0.061547,0.000000
107.030006,61.952351,-5.248752,0.034005,0.002414,0.061321,275.577820,14.038603,0.613214,-5.248752,0.061547,0.000000
107.300003,61.945274,-5.293233,0.033996,0.002414,0.061321,275.546356,14.037000,0.613214,-5.293233,0.061547,0.000000
107.570007,61.915485,-5.293233,0.034018,0.002414,0.061321,275.413849,14.030250,0.613214,-5.293233,0.061547,0.000000
107.840004,61.917721,-5.204271,0.034018,0.002414,0.061321,275.423767,14.030756,0.613214,-5.204271,0.061547,0.000000
108.110008,61.888676,-5.204271,0.034014,0.002414,0.061321,275.294586,14.024175,0.613214,-5.204271,0.061547,0.000000
108.380005,61.883835,-5.115309,0.034005,0.002414,0.061321,275.273041,14.023078,0.613214,-5.115309,0.061547,0.000000
108.650002,61.865589,-5.115309,0.034001,0.002414,0.061321,275.191895,14.018943,0.613214,-5.115309,0.061547,0.000000
108.920006,61.851067,-5.070828,0.034001,0.002414,0.061321,275.127289,14.015652,0.613214,-5.070828,0.061547,0.000000
109.190002,61.826488,-5.070828,0.034018,0.002414,0.061321,275.017944,14.010082,0.613214,-5.070828,0.061547,0.000000
109.460007,61.811592,-5.026348,0.034009,0.002414,0.061321,274.951691,14.006707,0.613214,-5.026348,0.061547,0.000000
109.730003,61.796326,-5.026348,0.034009,0.002414,0.061321,274.883789,14.003248,0.613214,-5.026348,0.061547,0.000000
110.000008,61.773613,-5.026348,0.033988,0.002414,0.061321,274.782745,13.998100,0.613214,-5.026348,0.061547,0.000000
110.270004,61.774727,-5.026348,0.034009,0.002414,0.061321,274.787720,13.998353,0.613214,-5.026348,0.061547,0.000000
110.540009,61.766537,-4.981866,0.034018,0.002414,0.061321,274.751282,13.996497,0.613214,-4.981866,0.061547,0.000000
110.810005,61.749409,-4.937386,0.034014,0.002414,0.061321,274.675079,13.992616,0.613214,-4.937386,0.061547,0.000000
111.080002,61.712914,-4.981866,0.034005,0.002414,0.061321,274.512756,13.984345,0.613214,-4.981866,0.061547,0.000000
111.350006,61.718128,-4.937386,0.033996,0.002414,0.061321,274.535950,13.985528,0.613214,-4.937386,0.061547,0.000000
111.620003,61.696159,-4.892905,0.034009,0.002414,0.061321,274.438232,13.980549,0.613214,-4.892905,0.061547,0.000000
111.890007,61.688339,-4.848423,0.034022,0.002414,0.061321,274.403442,13.978777,0.613214,-4.848423,0.061547,0.000000
112.160004,61.667114,-4.803943,0.034014,0.002414,0.061321,274.309021,13.973969,0.613214,-4.803943,0.061547,0.000000
112.430008,61.658920,-4.803943,0.034009,0.002414,0.061321,274.272583,13.972111,0.613214,-4.803943,0.061547,0.000000
112.700005,61.654453,-4.848423,0.034001,0.002414,0.061321,274.252716,13.971099,0.613214,-4.848423,0.061547,0.000000
112.970009,61.628387,-4.803943,0.034009,0.002414,0.061321,274.136749,13.965192,0.613214,-4.803943,0.061547,0.000000
113.240005,61.620937,-4.759462,0.034005,0.002414,0.061321,274.103607,13.963504,0.613214,-4.759462,0.061547,0.000000
113.510002,61.604553,-4.714981,0.033996,0.002414,0.061321,274.030731,13.959791,0.613214,-4.714981,0.061547,0.000000
113.780006,61.598225,-4.670500,0.034005,0.002414,0.061321,274.002594,13.958357,0.613214,-4.670500,0.061547,0.000000
114.050003,61.587799,-4.759462,0.034009,0.002414,0.061321,273.956207,13.955995,0.613214,-4.759462,0.061547,0.000000
114.320007,61.586308,-4.670500,0.034014,0.002414,0.061321,273.949585,13.955657,0.613214,-4.670500,0.061547,0.000000
114.590004,61.556145,-4.670500,0.034014,0.002414,0.061321,273.815399,13.948822,0.613214,-4.670500,0.061547,0.000000
114.860008,61.547581,-4.670500,0.034005,0.002414,0.061321,273.777313,13.946881,0.613214,-4.670500,0.061547,0.000000
115.130005,61.527473,-4.626019,0.034005,0.002414,0.061321,273.687866,13.942325,0.613214,-4.626019,0.061547,0.000000
115.400009,61.537155,-4.670500,0.034005,0.002414,0.061321,273.730927,13.944519,0.613214,-4.670500,0.061547,0.000000
115.670006,61.520027,-4.626019,0.034009,0.002414,0.061321,273.654755,13.940638,0.613214,-4.626019,0.061547,0.000000
115.940002,61.509598,-4.537057,0.034018,0.002414,0.061321,273.608368,13.938273,0.613214,-4.537057,0.061547,0.000000
116.210007,61.477577,-4.537057,0.034005,0.002414,0.061321,273.465912,13.931018,0.613214,-4.537057,0.061547,0.000000
116.480003,61.488747,-4.581538,0.034005,0.002414,0.061321,273.515594,13.933549,0.613214,-4.581538,0.061547,0.000000
116.750008,61.462307,-4.581538,0.034009,0.002414,0.061321,273.398010,13.927558,0.613214,-4.581538,0.061547,0.000000
117.020004,61.450394,-4.492576,0.034014,0.002414,0.061321,273.345001,13.924858,0.613214,-4.492576,0.061547,0.000000
117.290009,61.448158,-4.403614,0.034001,0.002414,0.061321,273.335052,13.924352,0.613214,-4.403614,0.061547,0.000000
117.560005,61.434753,-4.403614,0.034022,0.002414,0.061321,273.275421,13.921314,0.613214,-4.403614,0.061547,0.000000
117.600006,61.429913,-4.492576,0.034005,0.002414,0.061321,273.253906,13.920217,0.613214,-4.492576,0.061547,0.000000