File: Data/I-18_1_2_07282023_141649.csv
Time (sec),S:Load (lbs),S:HL1 (DIM),S:LVDT (in),S:Position (in),Ch:Position (mm),Ch:Load (N),Ch:Stress (MPa),Ch:Strain (mm/mm),Ch:HL1 (DIM),Set Point (),Cycles ()
0.110000,-0.011171,-24.019714,-0.000004,-0.000000,-0.000000,-0.049692,-0.002531,-0.000000,-24.019714,0.000043,0.000000
0.340000,0.007447,-23.975233,-0.000004,-0.000000,-0.000000,0.033128,0.001688,-0.000000,-23.975233,0.000043,0.000000
0.570000,0.018991,-24.019714,-0.000009,0.000096,0.002437,0.084476,0.004303,0.024367,-24.019714,0.003044,0.000000
0.800000,0.013778,-24.064194,-0.000017,0.000228,0.005793,0.061287,0.003122,0.057932,-24.064194,0.006877,0.000000
1.030000,0.042450,-24.019714,0.000069,0.000370,0.009392,0.188829,0.009619,0.093918,-24.019714,0.010692,0.000000
1.260000,0.056228,-23.930752,0.000190,0.000525,0.013346,0.250116,0.012741,0.133463,-23.930752,0.014526,0.000000
1.490000,0.049525,-23.930752,0.000362,0.000685,0.017405,0.220300,0.011223,0.174052,-23.930752,0.018359,0.000000
1.720000,0.009682,-23.930752,0.000522,0.000835,0.021212,0.043066,0.002194,0.212121,-23.930752,0.022192,0.000000
1.950000,0.043195,-24.019714,0.000660,0.000981,0.024924,0.192142,0.009788,0.249235,-24.019714,0.026025,0.000000
2.180000,0.030907,-23.975233,0.000811,0.001134,0.028800,0.137481,0.007004,0.288000,-23.975233,0.029858,0.000000
2.410000,0.017874,-23.975233,0.000957,0.001286,0.032677,0.079507,0.004050,0.326765,-23.975233,0.033692,0.000000
2.640000,0.010799,-23.975233,0.001121,0.001436,0.036467,0.048036,0.002447,0.364667,-23.975233,0.037525,0.000000
2.870000,0.024949,-23.930752,0.001285,0.001587,0.040308,0.110978,0.005654,0.403084,-23.930752,0.041358,0.000000
3.100000,0.034258,-23.930752,0.001427,0.001734,0.044046,0.152388,0.007763,0.440463,-23.930752,0.045191,0.000000
3.330000,0.040589,-23.975233,0.001569,0.001885,0.047871,0.180547,0.009197,0.478706,-23.975233,0.049024,0.000000
3.560000,0.053622,-23.886271,0.001716,0.002029,0.051548,0.238521,0.012151,0.515480,-23.886271,0.052857,0.000000
3.790000,0.061441,-23.886271,0.001880,0.002194,0.055736,0.273305,0.013923,0.557364,-23.886271,0.056690,0.000000
4.020000,0.019736,-23.841789,0.002031,0.002342,0.059492,0.087789,0.004472,0.594917,-23.841789,0.060506,0.000000
4.250000,-0.001490,-23.886271,0.002182,0.002487,0.063177,-0.006626,-0.000338,0.631775,-23.886271,0.064339,0.000000
4.480000,0.050270,-23.886271,0.002315,0.002642,0.067097,0.223613,0.011391,0.670971,-23.886271,0.068172,0.000000
4.710000,0.064793,-23.886271,0.002466,0.002790,0.070869,0.288213,0.014682,0.708691,-23.886271,0.072005,0.000000
4.940000,0.056228,-23.841789,0.002626,0.002938,0.074634,0.250116,0.012741,0.746336,-23.841789,0.075839,0.000000
5.170000,0.046547,-23.841789,0.002785,0.003096,0.078631,0.207049,0.010548,0.786312,-23.841789,0.079672,0.000000
5.400000,0.024949,-23.841789,0.002940,0.003245,0.082421,0.110978,0.005654,0.824206,-23.841789,0.083505,0.000000
5.630000,0.049525,-23.841789,0.003096,0.003395,0.086237,0.220300,0.011223,0.862366,-23.841789,0.087338,0.000000
5.860000,0.069261,-23.841789,0.003251,0.003546,0.090061,0.308089,0.015695,0.900608,-23.841789,0.091171,0.000000
6.090000,0.039471,-23.752829,0.003406,0.003702,0.094033,0.175578,0.008944,0.940327,-23.752829,0.095005,0.000000
6.320000,0.038727,-23.752829,0.003561,0.003852,0.097840,0.172265,0.008776,0.978403,-23.752829,0.098837,0.000000
6.550000,-0.003351,-23.797308,0.003699,0.003999,0.101578,-0.014908,-0.000759,1.015783,-23.797308,0.102671,0.000000
6.780000,0.017874,-23.841789,0.003837,0.004146,0.105307,0.079507,0.004050,1.053071,-23.841789,0.106487,0.000000
7.010000,0.064420,-23.752829,0.003997,0.004298,0.109175,0.286556,0.014598,1.091745,-23.752829,0.110320,0.000000
7.240000,0.088625,-23.708347,0.004135,0.004445,0.112912,0.394222,0.020083,1.129125,-23.708347,0.114152,0.000000
7.470000,0.090859,-23.752829,0.004290,0.004596,0.116746,0.404160,0.020589,1.167458,-23.752829,0.117986,0.000000
7.700000,0.044685,-23.752829,0.004467,0.004754,0.120761,0.198768,0.010126,1.207609,-23.752829,0.121819,0.000000
7.930000,0.081550,-23.752829,0.004626,0.004904,0.124559,0.362751,0.018479,1.245594,-23.752829,0.125652,0.000000
8.160001,0.045057,-23.708347,0.004777,0.005056,0.128428,0.200424,0.010210,1.284275,-23.708347,0.129485,0.000000
8.390000,0.080060,-23.752829,0.004907,0.005203,0.132156,0.356125,0.018142,1.321564,-23.752829,0.133318,0.000000
8.620001,0.050643,-23.663866,0.005075,0.005357,0.136076,0.225270,0.011476,1.360761,-23.663866,0.137152,0.000000
8.850000,0.040961,-23.708347,0.005230,0.005509,0.139918,0.182203,0.009282,1.399177,-23.708347,0.140984,0.000000
9.080001,0.020480,-23.708347,0.005381,0.005656,0.143673,0.091102,0.004641,1.436731,-23.708347,0.144818,0.000000
9.310000,0.051387,-23.663866,0.005523,0.005810,0.147575,0.228582,0.011645,1.475753,-23.663866,0.148651,0.000000
9.540001,0.072240,-23.619385,0.005670,0.005954,0.151235,0.321341,0.016370,1.512353,-23.619385,0.152484,0.000000
9.770000,0.080060,-23.619385,0.005829,0.006100,0.154947,0.356125,0.018142,1.549468,-23.619385,0.156300,0.000000
10.000000,0.068144,-23.663866,0.005967,0.006265,0.159136,0.303120,0.015442,1.591359,-23.663866,0.160133,0.000000
10.230000,0.054366,-23.663866,0.006140,0.006413,0.162891,0.241834,0.012320,1.628905,-23.663866,0.163966,0.000000
10.460000,0.055856,-23.530422,0.006282,0.006560,0.166628,0.248459,0.012657,1.666285,-23.530422,0.167800,0.000000
10.690001,0.072240,-23.574903,0.006433,0.006713,0.170505,0.321341,0.016370,1.705050,-23.574903,0.171632,0.000000
10.920000,0.079315,-23.530422,0.006597,0.006863,0.174312,0.352812,0.017973,1.743118,-23.530422,0.175465,0.000000
11.150001,0.050270,-23.619385,0.006743,0.007015,0.178188,0.223613,0.011391,1.781883,-23.619385,0.179299,0.000000
11.380000,0.079688,-23.574903,0.006890,0.007166,0.182004,0.354469,0.018057,1.820042,-23.574903,0.183132,0.000000
11.610001,0.068889,-23.530422,0.007045,0.007316,0.185829,0.306433,0.015610,1.858293,-23.530422,0.186965,0.000000
11.840000,0.083039,-23.530422,0.007209,0.007468,0.189688,0.369376,0.018817,1.896883,-23.530422,0.190798,0.000000
12.070001,0.085646,-23.530422,0.007364,0.007613,0.193365,0.380971,0.019408,1.933650,-23.530422,0.194631,0.000000
12.300000,0.099051,-23.574903,0.007493,0.007771,0.197380,0.440601,0.022445,1.973800,-23.574903,0.198465,0.000000
12.530001,0.075219,-23.530422,0.007662,0.007923,0.201240,0.334592,0.017045,2.012398,-23.530422,0.202280,0.000000
12.760000,0.048036,-23.530422,0.007795,0.008070,0.204977,0.213675,0.010885,2.049770,-23.530422,0.206113,0.000000
12.990001,0.066282,-23.530422,0.007950,0.008219,0.208758,0.294838,0.015020,2.087582,-23.530422,0.209947,0.000000
13.220000,0.074102,-23.530422,0.008123,0.008372,0.212661,0.329623,0.016792,2.126611,-23.530422,0.213780,0.000000
13.450001,0.098306,-23.485943,0.008295,0.008519,0.216373,0.437288,0.022277,2.163726,-23.485943,0.217613,0.000000
13.680000,0.083039,-23.485943,0.008455,0.008675,0.220344,0.369376,0.018817,2.203445,-23.485943,0.221446,0.000000
13.910001,0.054739,-23.485943,0.008623,0.008829,0.224247,0.243490,0.012404,2.242467,-23.485943,0.225279,0.000000
14.140000,0.072985,-23.441462,0.008787,0.008974,0.227942,0.324653,0.016539,2.279415,-23.441462,0.229112,0.000000
14.370001,0.080432,-23.441462,0.008946,0.009129,0.231887,0.357781,0.018226,2.318869,-23.441462,0.232945,0.000000
14.600000,0.084529,-23.485943,0.009084,0.009280,0.235703,0.376002,0.019154,2.357028,-23.485943,0.236778,0.000000
14.830001,0.062559,-23.441462,0.009244,0.009435,0.239641,0.278274,0.014176,2.396406,-23.441462,0.240612,0.000000
15.060000,0.054366,-23.396980,0.009399,0.009581,0.243360,0.241834,0.012320,2.433604,-23.396980,0.244444,0.000000
15.290001,0.022715,-23.396980,0.009537,0.009731,0.247168,0.101040,0.005147,2.471680,-23.396980,0.248278,0.000000
15.520000,0.075592,-23.396980,0.009701,0.009883,0.251035,0.336248,0.017129,2.510354,-23.396980,0.252094,0.000000
15.750001,0.102402,-23.396980,0.009843,0.010028,0.254713,0.455509,0.023205,2.547128,-23.396980,0.255927,0.000000
15.980000,0.105381,-23.396980,0.009981,0.010177,0.258485,0.468760,0.023880,2.584849,-23.396980,0.259760,0.000000
16.210001,0.109105,-23.396980,0.010136,0.010338,0.262587,0.485324,0.024724,2.625869,-23.396980,0.263593,0.000000
16.440001,0.090114,-23.352499,0.010305,0.010485,0.266316,0.400848,0.020420,2.663158,-23.352499,0.267426,0.000000
16.670000,0.080060,-23.352499,0.010464,0.010641,0.270288,0.356125,0.018142,2.702877,-23.352499,0.271260,0.000000
16.900002,0.093838,-23.352499,0.010593,0.010788,0.274008,0.417412,0.021264,2.740082,-23.352499,0.275092,0.000000
17.130001,0.072240,-23.308018,0.010740,0.010936,0.277764,0.321341,0.016370,2.777636,-23.308018,0.278926,0.000000
17.360001,0.082294,-23.308018,0.010891,0.011094,0.281779,0.366063,0.018648,2.817786,-23.308018,0.282759,0.000000
17.590000,0.045429,-23.308018,0.011046,0.011241,0.285517,0.202080,0.010294,2.855166,-23.308018,0.286591,0.000000
17.820002,0.085273,-23.308018,0.011210,0.011393,0.289393,0.379314,0.019323,2.893931,-23.308018,0.290425,0.000000
18.050001,0.094955,-23.352499,0.011365,0.011544,0.293209,0.422381,0.021517,2.932090,-23.352499,0.294258,0.000000
18.280001,0.116553,-23.263536,0.011516,0.011686,0.296825,0.518452,0.026411,2.968251,-23.263536,0.298074,0.000000
18.510000,0.104264,-23.219057,0.011684,0.011845,0.300858,0.463791,0.023627,3.008575,-23.219057,0.301907,0.000000
18.740002,0.090486,-23.174576,0.011839,0.011997,0.304734,0.402504,0.020505,3.047340,-23.174576,0.305740,0.000000
18.970001,0.070006,-23.263536,0.011995,0.012146,0.308507,0.311402,0.015864,3.085068,-23.263536,0.309573,0.000000
19.200001,0.094210,-23.308018,0.012137,0.012295,0.312296,0.419068,0.021348,3.122962,-23.308018,0.313407,0.000000
19.430000,0.113946,-23.219057,0.012279,0.012448,0.316173,0.506857,0.025821,3.161727,-23.219057,0.317239,0.000000
19.660002,0.092721,-23.130095,0.012447,0.012598,0.319980,0.412442,0.021011,3.199803,-23.130095,0.321073,0.000000
19.890001,0.108360,-23.174576,0.012603,0.012747,0.323779,0.482011,0.024555,3.237788,-23.174576,0.324906,0.000000
20.120001,0.093838,-23.219057,0.012762,0.012900,0.327655,0.417412,0.021264,3.276553,-23.219057,0.328739,0.000000
20.350000,0.091976,-23.219057,0.012904,0.013049,0.331445,0.409130,0.020842,3.314448,-23.219057,0.332572,0.000000
20.580002,0.097934,-23.130095,0.013055,0.013202,0.335339,0.435632,0.022192,3.353387,-23.130095,0.336405,0.000000
20.810001,0.145225,-23.085613,0.013185,0.013350,0.339094,0.645994,0.032909,3.390940,-23.085613,0.340239,0.000000
21.040001,0.109105,-23.130095,0.013353,0.013507,0.343083,0.485324,0.024724,3.430826,-23.130095,0.344072,0.000000
21.270000,0.065910,-23.085613,0.013504,0.013655,0.346830,0.293182,0.014935,3.468296,-23.085613,0.347887,0.000000
21.500002,0.068516,-23.130095,0.013650,0.013802,0.350576,0.304777,0.015526,3.505759,-23.130095,0.351720,0.000000
21.730001,0.107616,-23.041132,0.013805,0.013952,0.354392,0.478698,0.024386,3.543918,-23.041132,0.355554,0.000000
21.960001,0.149321,-22.996653,0.013961,0.014104,0.358233,0.664215,0.033837,3.582335,-22.996653,0.359387,0.000000
22.190001,0.143363,-22.996653,0.014116,0.014253,0.362023,0.637712,0.032487,3.620229,-22.996653,0.363220,0.000000
22.420002,0.124000,-23.085613,0.014280,0.014411,0.366047,0.551580,0.028099,3.660470,-23.085613,0.367053,0.000000
22.650002,0.106871,-23.041132,0.014431,0.014559,0.369793,0.475385,0.024217,3.697933,-23.041132,0.370886,0.000000
22.880001,0.126234,-22.996653,0.014594,0.014714,0.373730,0.561518,0.028605,3.737304,-22.996653,0.374719,0.000000
23.110001,0.123628,-22.996653,0.014780,0.014860,0.377451,0.549923,0.028014,3.774509,-22.996653,0.378552,0.000000
23.340002,0.098679,-22.996653,0.014948,0.015013,0.381336,0.438945,0.022361,3.813365,-22.996653,0.382386,0.000000
23.570002,0.081550,-22.996653,0.015138,0.015164,0.385178,0.362751,0.018479,3.851782,-22.996653,0.386219,0.000000
23.800001,0.027928,-22.952171,0.015315,0.015314,0.388977,0.124230,0.006329,3.889767,-22.952171,0.390052,0.000000
24.030001,0.047291,-22.996653,0.015483,0.015464,0.392784,0.210362,0.010716,3.927835,-22.996653,0.393868,0.000000
24.260000,0.093093,-22.952171,0.015668,0.015610,0.396495,0.414099,0.021095,3.964950,-22.952171,0.397701,0.000000
24.490002,0.120276,-22.952171,0.015832,0.015758,0.400242,0.535016,0.027255,4.002420,-22.952171,0.401534,0.000000
24.720001,0.103520,-22.952171,0.016000,0.015916,0.404257,0.460478,0.023458,4.042571,-22.952171,0.405367,0.000000
24.950001,0.077826,-22.907690,0.016168,0.016070,0.408186,0.346187,0.017636,4.081858,-22.907690,0.409200,0.000000
25.180000,0.067399,-22.863209,0.016341,0.016221,0.412002,0.299807,0.015273,4.120017,-22.863209,0.413033,0.000000
25.410002,0.096444,-22.818727,0.016479,0.016368,0.415756,0.429006,0.021855,4.157563,-22.818727,0.416867,0.000000
25.640001,0.080805,-22.818727,0.016634,0.016517,0.419537,0.359438,0.018311,4.195374,-22.818727,0.420699,0.000000
25.870001,0.062559,-22.863209,0.016789,0.016674,0.423509,0.278274,0.014176,4.235093,-22.863209,0.424533,0.000000
26.100000,0.064793,-22.907690,0.016957,0.016823,0.427299,0.288213,0.014682,4.272995,-22.907690,0.428366,0.000000
26.330002,0.077826,-22.818727,0.017112,0.016974,0.431149,0.346187,0.017636,4.311495,-22.818727,0.432199,0.000000
26.560001,0.074474,-22.685286,0.017263,0.017123,0.434913,0.331279,0.016876,4.349132,-22.685286,0.436032,0.000000
26.790001,0.086763,-22.774246,0.017436,0.017270,0.438660,0.385940,0.019661,4.386602,-22.774246,0.439865,0.000000
27.020000,0.104264,-22.774246,0.017561,0.017418,0.442415,0.463791,0.023627,4.424149,-22.774246,0.443681,0.000000
27.250002,0.104264,-22.774246,0.017720,0.017582,0.446587,0.463791,0.023627,4.465866,-22.774246,0.447515,0.000000
27.480001,0.058090,-22.774246,0.017871,0.017730,0.450341,0.258398,0.013163,4.503412,-22.774246,0.451347,0.000000
27.710001,0.064793,-22.640804,0.018039,0.017876,0.454062,0.288213,0.014682,4.540617,-22.640804,0.455181,0.000000
27.940001,0.080805,-22.774246,0.018195,0.018030,0.457956,0.359438,0.018311,4.579556,-22.774246,0.459014,0.000000
28.170002,0.088252,-22.685286,0.018358,0.018179,0.461754,0.392566,0.019998,4.617542,-22.685286,0.462846,0.000000
28.400002,0.097562,-22.729767,0.018501,0.018327,0.465510,0.433976,0.022108,4.655095,-22.729767,0.466680,0.000000
28.630001,0.081177,-22.729767,0.018665,0.018482,0.469455,0.361094,0.018395,4.694549,-22.729767,0.470513,0.000000
28.860001,0.063303,-22.685286,0.018820,0.018631,0.473228,0.281587,0.014345,4.732277,-22.685286,0.474346,0.000000
29.090002,0.084901,-22.596323,0.018979,0.018786,0.477156,0.377658,0.019239,4.771556,-22.596323,0.478179,0.000000
29.320002,0.113946,-22.640804,0.019139,0.018931,0.480841,0.506857,0.025821,4.808414,-22.640804,0.482012,0.000000
29.550001,0.081550,-22.640804,0.019294,0.019089,0.484865,0.362751,0.018479,4.848655,-22.640804,0.485846,0.000000
29.780001,0.093838,-22.551842,0.019458,0.019238,0.488656,0.417412,0.021264,4.886557,-22.551842,0.489679,0.000000
30.010002,0.045802,-22.596323,0.019609,0.019385,0.492367,0.203737,0.010379,4.923671,-22.596323,0.493494,0.000000
30.240002,0.081550,-22.596323,0.019764,0.019533,0.496131,0.362751,0.018479,4.961308,-22.596323,0.497328,0.000000
30.470001,0.127351,-22.551842,0.019924,0.019686,0.500025,0.566487,0.028858,5.000247,-22.551842,0.501161,0.000000
30.700001,0.107616,-22.596323,0.020070,0.019834,0.503780,0.478698,0.024386,5.037801,-22.596323,0.504994,0.000000
30.930002,0.133309,-22.507360,0.020221,0.019989,0.507725,0.592990,0.030208,5.077255,-22.507360,0.508827,0.000000
31.160002,0.116553,-22.507360,0.020393,0.020142,0.511619,0.518452,0.026411,5.116194,-22.507360,0.512660,0.000000
31.390001,0.176132,-22.462881,0.020557,0.020292,0.515418,0.783475,0.039912,5.154179,-22.462881,0.516494,0.000000
31.620001,0.237201,-22.507360,0.020725,0.020443,0.519260,1.055124,0.053751,5.192596,-22.507360,0.520326,0.000000
31.850002,0.436793,-22.507360,0.020859,0.020590,0.522989,1.942952,0.098979,5.229892,-22.507360,0.524159,0.000000
32.080002,0.698198,-22.507360,0.021001,0.000003,0.000078,3.105741,0.158214,0.000780,-22.507360,0.000338,0.000000
32.310001,0.646439,-22.418400,0.021010,0.000003,0.000078,2.875503,0.146485,0.000780,-22.418400,0.000338,0.000000
32.540001,0.637502,-22.507360,0.021010,0.000003,0.000078,2.835749,0.144460,0.000780,-22.507360,0.000338,0.000000
32.770000,0.635640,-22.462881,0.021014,0.000003,0.000078,2.827467,0.144038,0.000780,-22.462881,0.000712,0.000000
33.000000,0.606222,-22.418400,0.021014,0.000003,0.000078,2.696612,0.137372,0.000780,-22.418400,0.001093,0.000000
33.230003,0.680324,-22.462881,0.021014,0.000022,0.000564,3.026234,0.154164,0.005639,-22.462881,0.001483,0.000000
33.460003,0.744000,-22.373919,0.021019,0.000039,0.000989,3.309478,0.168593,0.009886,-22.373919,0.001864,0.000000
33.690002,0.807676,-22.418400,0.021027,0.000054,0.001379,3.592721,0.183022,0.013792,-22.418400,0.002247,0.000000
33.920002,0.875448,-22.284956,0.021040,0.000068,0.001735,3.894186,0.198379,0.017350,-22.284956,0.002628,0.000000
34.150002,0.889970,-22.418400,0.021045,0.000084,0.002125,3.958785,0.201670,0.021248,-22.418400,0.003010,0.000000
34.380001,0.939868,-22.373919,0.021070,0.000095,0.002403,4.180742,0.212977,0.024027,-22.373919,0.003400,0.000000
34.610001,1.008012,-22.284956,0.021075,0.000110,0.002784,4.483862,0.228419,0.027842,-22.284956,0.003781,0.000000
34.840000,1.158078,-22.284956,0.021096,0.000127,0.003226,5.151390,0.262424,0.032262,-22.284956,0.004163,0.000000
35.070004,1.220265,-22.329437,0.021109,0.000139,0.003530,5.428008,0.276516,0.035298,-22.329437,0.004544,0.000000
35.300003,1.299580,-22.284956,0.021105,0.000154,0.003920,5.780820,0.294489,0.039204,-22.284956,0.004926,0.000000
35.530003,1.386715,-22.240475,0.021131,0.000173,0.004388,6.168417,0.314234,0.043882,-22.240475,0.005316,0.000000
35.760002,1.529334,-22.284956,0.021144,0.000188,0.004787,6.802816,0.346552,0.047871,-22.284956,0.005698,0.000000
35.990002,1.576997,-22.195995,0.021170,0.000202,0.005135,7.014834,0.357353,0.051346,-22.195995,0.006079,0.000000
36.220001,1.647748,-22.151514,0.021174,0.000216,0.005481,7.329550,0.373385,0.054813,-22.151514,0.006461,0.000000
36.450001,1.753502,-22.195995,0.021187,0.000228,0.005802,7.799966,0.397349,0.058022,-22.195995,0.006842,0.000000
36.680000,1.886439,-22.151514,0.021200,0.000237,0.006019,8.391299,0.427473,0.060187,-22.151514,0.007233,0.000000
36.910000,2.081934,-22.151514,0.021208,0.000260,0.006600,9.260907,0.471773,0.066001,-22.151514,0.007614,0.000000
37.140003,2.239076,-22.151514,0.021230,0.000275,0.006973,9.959906,0.507382,0.069725,-22.151514,0.007996,0.000000
37.370003,2.389514,-22.107033,0.021247,0.000291,0.007381,10.629089,0.541472,0.073805,-22.107033,0.008377,0.000000
37.600002,2.554475,-22.151514,0.021247,0.000307,0.007788,11.362873,0.578852,0.077878,-22.151514,0.008759,0.000000
37.830002,2.700073,-22.151514,0.021264,0.000320,0.008118,12.010524,0.611845,0.081178,-22.151514,0.009150,0.000000
38.060001,2.884025,-22.107033,0.021277,0.000336,0.008543,12.828782,0.653529,0.085425,-22.107033,0.009531,0.000000
38.290001,3.013983,-22.062551,0.021290,0.000350,0.008881,13.406864,0.682978,0.088809,-22.062551,0.009913,0.000000
38.520000,3.286559,-22.062551,0.021295,0.000367,0.009314,14.619346,0.744745,0.093139,-22.062551,0.010294,0.000000
38.750000,3.471628,-22.107033,0.021316,0.000380,0.009644,15.442575,0.786682,0.096439,-22.107033,0.010676,0.000000
38.980003,3.644782,-22.062551,0.021320,0.000393,0.009973,16.212799,0.825919,0.099732,-22.062551,0.011066,0.000000
39.210003,3.838415,-22.062551,0.021346,0.000405,0.010277,17.074123,0.869797,0.102767,-22.062551,0.011448,0.000000
39.440002,3.982896,-21.973589,0.021351,0.000417,0.010589,17.716806,0.902537,0.105894,-21.973589,0.011829,0.000000
39.670002,4.361971,-22.018070,0.021364,0.000440,0.011170,19.403015,0.988437,0.111700,-22.018070,0.012211,0.000000
39.900002,4.611088,-22.018070,0.021389,0.000458,0.011629,20.511145,1.044888,0.116295,-22.018070,0.012592,0.000000
40.130001,4.849407,-22.018070,0.021402,0.000474,0.012028,21.571238,1.098891,0.120284,-22.018070,0.012983,0.000000
40.360001,5.070968,-21.973589,0.021420,0.000487,0.012367,22.556793,1.149098,0.123668,-21.973589,0.013364,0.000000
40.590000,5.346152,-21.973589,0.021428,0.000501,0.012731,23.780870,1.211455,0.127309,-21.973589,0.013746,0.000000
40.820004,5.429935,-21.929110,0.021445,0.000509,0.012922,24.153559,1.230441,0.129216,-21.929110,0.014127,0.000000
41.050003,5.867101,-21.929110,0.021445,0.000529,0.013425,26.098167,1.329504,0.134250,-21.929110,0.014517,0.000000
41.280003,6.009347,-21.973589,0.021450,0.000541,0.013746,26.730911,1.361737,0.137460,-21.973589,0.014899,0.000000
41.510002,6.429756,-21.795666,0.021480,0.000560,0.014214,28.600983,1.457003,0.142138,-21.795666,0.015281,0.000000
41.740002,6.748878,-21.884628,0.021493,0.000578,0.014682,30.020512,1.529318,0.146824,-21.884628,0.015663,0.000000
41.970001,6.999858,-21.884628,0.021502,0.000592,0.015038,31.136923,1.586190,0.150381,-21.884628,0.016044,0.000000
42.200001,7.227005,-21.840147,0.021514,0.000605,0.015377,32.147324,1.637663,0.153765,-21.840147,0.016434,0.000000
42.430000,7.714813,-21.840147,0.021514,0.000625,0.015887,34.317200,1.748201,0.158875,-21.840147,0.016816,0.000000
42.660004,7.868975,-21.795666,0.021545,0.000638,0.016208,35.002949,1.783135,0.162084,-21.795666,0.017197,0.000000
42.890003,7.984038,-21.751184,0.021566,0.000646,0.016408,35.514778,1.809209,0.164083,-21.751184,0.017579,0.000000
43.120003,8.313960,-21.751184,0.021571,0.000658,0.016720,36.982342,1.883970,0.167202,-21.751184,0.017961,0.000000
43.350002,9.044183,-21.795666,0.021562,0.000686,0.017423,40.230534,2.049441,0.174226,-21.795666,0.018351,0.000000
43.580002,9.174141,-21.840147,0.021605,0.000698,0.017718,40.808617,2.078890,0.177179,-21.840147,0.018732,0.000000
43.810001,9.441132,-21.751184,0.021618,0.000714,0.018143,41.996250,2.139391,0.181425,-21.751184,0.019114,0.000000
44.040001,9.750200,-21.662224,0.021609,0.000729,0.018516,43.371056,2.209427,0.185157,-21.662224,0.019495,0.000000
44.270000,9.947186,-21.662224,0.021627,0.000743,0.018862,44.247292,2.254065,0.188624,-21.662224,0.019877,0.000000
44.500004,10.432387,-21.751184,0.021648,0.000758,0.019253,46.405575,2.364013,0.192530,-21.751184,0.020267,0.000000
44.730003,10.580219,-21.706703,0.021661,0.000768,0.019495,47.063168,2.397512,0.194952,-21.706703,0.020649,0.000000
44.960003,10.925035,-21.662224,0.021661,0.000783,0.019886,48.596985,2.475648,0.198858,-21.662224,0.021030,0.000000
45.190002,11.212880,-21.617743,0.021683,0.000799,0.020302,49.877380,2.540875,0.203022,-21.617743,0.021412,0.000000
45.420002,11.930442,-21.662224,0.021708,0.000821,0.020857,53.069256,2.703477,0.208570,-21.662224,0.021793,0.000000
45.650002,12.090189,-21.617743,0.021726,0.000835,0.021204,53.779846,2.739676,0.212037,-21.617743,0.022184,0.000000
45.880001,12.378034,-21.662224,0.021739,0.000850,0.021585,55.060242,2.804903,0.215853,-21.662224,0.022566,0.000000
46.110001,12.573156,-21.573261,0.021739,0.000861,0.021880,55.928192,2.849118,0.218805,-21.573261,0.022947,0.000000
46.340004,13.126874,-21.617743,0.021756,0.000883,0.022427,58.391251,2.974592,0.224270,-21.617743,0.023329,0.000000
46.570004,13.420303,-21.573261,0.021769,0.000895,0.022731,59.696491,3.041084,0.227306,-21.573261,0.023710,0.000000
46.800003,13.388652,-21.573261,0.021773,0.000902,0.022921,59.555698,3.033912,0.229213,-21.573261,0.024101,0.000000
47.030003,13.648195,-21.573261,0.021782,0.000914,0.023216,60.710205,3.092725,0.232158,-21.573261,0.024482,0.000000
47.260002,14.709085,-21.528780,0.021808,0.000945,0.024014,65.429276,3.333126,0.240136,-21.528780,0.024864,0.000000
47.490002,14.731054,-21.528780,0.021816,0.000955,0.024257,65.527000,3.338104,0.242566,-21.528780,0.025245,0.000000
47.720001,15.028953,-21.484299,0.021846,0.000970,0.024630,66.852119,3.405609,0.246298,-21.484299,0.025627,0.000000
47.950001,15.358874,-21.439819,0.021842,0.000986,0.025054,68.319687,3.480371,0.250545,-21.439819,0.026017,0.000000
48.180004,15.709277,-21.484299,0.021855,0.001001,0.025419,69.878357,3.559773,0.254186,-21.484299,0.026399,0.000000
48.410004,16.017973,-21.439819,0.021864,0.001016,0.025818,71.251503,3.629725,0.258175,-21.439819,0.026780,0.000000
48.640003,16.182562,-21.395338,0.021890,0.001028,0.026113,71.983627,3.667021,0.261127,-21.395338,0.027162,0.000000
48.870003,16.554562,-21.439819,0.021903,0.001044,0.026520,73.638367,3.751318,0.265200,-21.439819,0.027543,0.000000
49.100002,17.046095,-21.484299,0.021911,0.001063,0.027006,75.824814,3.862700,0.270060,-21.484299,0.027933,0.000000
49.330002,17.424797,-21.439819,0.021924,0.001079,0.027396,77.509369,3.948515,0.273958,-21.439819,0.028315,0.000000
49.560001,17.492941,-21.395338,0.021941,0.001091,0.027708,77.812485,3.963957,0.277085,-21.395338,0.028697,0.000000
49.790001,17.800522,-21.306376,0.021954,0.001105,0.028063,79.180679,4.033656,0.280635,-21.306376,0.029079,0.000000
50.020004,18.256306,-21.306376,0.021967,0.001123,0.028515,81.208107,4.136938,0.285146,-21.306376,0.029468,0.000000
50.250004,18.543404,-21.350857,0.021980,0.001136,0.028853,82.485176,4.201995,0.288530,-21.350857,0.029850,0.000000
50.480003,18.765339,-21.306376,0.021989,0.001150,0.029200,83.472397,4.252286,0.291997,-21.306376,0.030231,0.000000
50.710003,19.066587,-21.261894,0.021993,0.001163,0.029546,84.812416,4.320550,0.295464,-21.261894,0.030613,0.000000
50.940002,19.589771,-21.261894,0.022010,0.001183,0.030041,87.139656,4.439106,0.300407,-21.261894,0.030995,0.000000
51.170002,19.963261,-21.261894,0.022032,0.001199,0.030457,88.801018,4.523739,0.304570,-21.261894,0.031385,0.000000
51.400002,20.070503,-21.306376,0.022040,0.001211,0.030761,89.278061,4.548041,0.307606,-21.306376,0.031767,0.000000
51.630001,20.541555,-21.261894,0.022053,0.001229,0.031212,91.373405,4.654783,0.312118,-21.261894,0.032148,0.000000
51.860001,20.645075,-21.172934,0.022071,0.001239,0.031480,91.833878,4.678241,0.314805,-21.172934,0.032530,0.000000
52.090004,21.032715,-21.172934,0.022066,0.001255,0.031879,93.558189,4.766081,0.318794,-21.172934,0.032911,0.000000
52.320004,21.397638,-21.172934,0.022088,0.001269,0.032235,95.181450,4.848774,0.322352,-21.172934,0.033302,0.000000
52.550003,21.649363,-21.172934,0.022101,0.001282,0.032574,96.301178,4.905816,0.325736,-21.172934,0.033683,0.000000
52.780003,22.067537,-21.172934,0.022109,0.001298,0.032981,98.161308,5.000575,0.329808,-21.172934,0.034065,0.000000
53.010002,22.725519,-21.128452,0.022114,0.001319,0.033501,101.088158,5.149676,0.335009,-21.128452,0.034446,0.000000
53.240002,23.089699,-21.172934,0.022131,0.001335,0.033900,102.708107,5.232201,0.338998,-21.172934,0.034828,0.000000
53.470001,22.974264,-21.128452,0.022153,0.001347,0.034203,102.194633,5.206043,0.342033,-21.128452,0.035218,0.000000
53.700001,23.367861,-21.128452,0.022153,0.001360,0.034542,103.945435,5.295233,0.345417,-21.128452,0.035600,0.000000
53.930004,23.533195,-21.083971,0.022157,0.001370,0.034793,104.680885,5.332698,0.347930,-21.083971,0.035981,0.000000
54.160004,24.119682,-21.083971,0.022187,0.001391,0.035322,107.289703,5.465598,0.353222,-21.083971,0.036363,0.000000
54.390003,24.520355,-21.083971,0.022209,0.001403,0.035635,109.071991,5.556392,0.356348,-21.083971,0.036745,0.000000
54.620003,24.920654,-20.995008,0.022209,0.001417,0.035999,110.852608,5.647101,0.359989,-20.995008,0.037135,0.000000
54.850002,25.555550,-20.995008,0.022222,0.001437,0.036511,113.676765,5.790970,0.365106,-20.995008,0.037517,0.000000
55.080002,25.787910,-21.039490,0.022234,0.001451,0.036849,114.710358,5.843624,0.368490,-21.039490,0.037898,0.000000
55.310001,26.248907,-20.950527,0.022247,0.001467,0.037256,116.760971,5.948087,0.372562,-20.950527,0.038280,0.000000
55.540001,26.671551,-20.995008,0.022260,0.001484,0.037681,118.640984,6.043859,0.376809,-20.995008,0.038661,0.000000
55.770004,26.834650,-20.906048,0.022273,0.001495,0.037976,119.366486,6.080819,0.379761,-20.906048,0.039052,0.000000
56.000004,27.267345,-20.995008,0.022278,0.001509,0.038340,121.291214,6.178869,0.383402,-20.995008,0.039433,0.000000
56.230003,27.848619,-20.950527,0.022286,0.001527,0.038774,123.876846,6.310587,0.387740,-20.950527,0.039815,0.000000
56.460003,28.193810,-20.861567,0.022303,0.001541,0.039138,125.412331,6.388808,0.391381,-20.861567,0.040196,0.000000
56.690002,28.656296,-20.906048,0.022316,0.001558,0.039563,127.469566,6.493609,0.395627,-20.906048,0.040578,0.000000
56.920002,29.233845,-20.950527,0.022329,0.001574,0.039971,130.038635,6.624484,0.399708,-20.950527,0.040968,0.000000
57.150002,29.650902,-20.950527,0.022342,0.001588,0.040327,131.893799,6.718990,0.403265,-20.950527,0.041349,0.000000
57.380001,29.990879,-20.906048,0.022347,0.001603,0.040708,133.406097,6.796030,0.407081,-20.906048,0.041731,0.000000
57.610004,30.362507,-20.861567,0.022377,0.001617,0.041063,135.059174,6.880242,0.410631,-20.861567,0.042113,0.000000
57.840004,30.689821,-20.861567,0.022385,0.001629,0.041367,136.515137,6.954413,0.413666,-20.861567,0.042495,0.000000
58.070004,31.038734,-20.861567,0.022398,0.001644,0.041748,138.067184,7.033478,0.417481,-20.861567,0.042884,0.000000
58.300003,31.974506,-20.861567,0.022394,0.001660,0.042164,142.229706,7.245527,0.421645,-20.861567,0.043266,0.000000
58.530003,32.484283,-20.817085,0.022416,0.001675,0.042538,144.497314,7.361044,0.425377,-20.817085,0.043647,0.000000
58.760002,33.015659,-20.728123,0.022424,0.001690,0.042937,146.860992,7.481455,0.429366,-20.728123,0.044029,0.000000
58.990002,33.592091,-20.772604,0.022437,0.001707,0.043370,149.425079,7.612076,0.433704,-20.772604,0.044420,0.000000
59.220001,33.964466,-20.728123,0.022454,0.001718,0.043647,151.081497,7.696458,0.436474,-20.728123,0.044801,0.000000
59.450005,34.612022,-20.817085,0.022463,0.001737,0.044108,153.961960,7.843196,0.441077,-20.817085,0.045183,0.000000
59.680004,35.067059,-20.683641,0.022476,0.001751,0.044480,155.986069,7.946309,0.444801,-20.683641,0.045564,0.000000
59.910004,35.875854,-20.728123,0.022480,0.001768,0.044906,159.583771,8.129584,0.449055,-20.728123,0.045946,0.000000
60.140003,36.279503,-20.683641,0.022497,0.001781,0.045235,161.379288,8.221053,0.452348,-20.683641,0.046336,0.000000
60.370003,36.648899,-20.683641,0.022506,0.001792,0.045529,163.022446,8.304759,0.455293,-20.683641,0.046718,0.000000
60.600002,37.095001,-20.683641,0.022506,0.001805,0.045842,165.006805,8.405848,0.458419,-20.683641,0.047099,0.000000
60.830002,37.791710,-20.639162,0.022519,0.001826,0.046371,168.105927,8.563724,0.463710,-20.639162,0.047481,0.000000
61.060001,39.033569,-20.639162,0.022532,0.001846,0.046883,173.629990,8.845134,0.468827,-20.639162,0.047862,0.000000
61.290005,39.700863,-20.550200,0.022549,0.001861,0.047264,176.598251,8.996345,0.472643,-20.550200,0.048253,0.000000
61.520004,40.179733,-20.594681,0.022558,0.001873,0.047576,178.728378,9.104857,0.475761,-20.594681,0.048634,0.000000
61.750004,40.779999,-20.683641,0.022558,0.001889,0.047984,181.398499,9.240880,0.479841,-20.683641,0.049016,0.000000
61.980003,41.367603,-20.594681,0.022571,0.001902,0.048322,184.012283,9.374033,0.483218,-20.594681,0.049397,0.000000
62.210003,41.531818,-20.505718,0.022592,0.001912,0.048565,184.742752,9.411244,0.485647,-20.505718,0.049779,0.000000
62.440002,42.508923,-20.505718,0.022592,0.001928,0.048964,189.089127,9.632660,0.489637,-20.505718,0.050170,0.000000
62.670002,43.046257,-20.550200,0.022610,0.001941,0.049310,191.479309,9.754421,0.493104,-20.550200,0.050551,0.000000
62.900002,44.112732,-20.550200,0.022610,0.001960,0.049779,196.223236,9.996088,0.497789,-20.550200,0.050933,0.000000
63.130005,45.041428,-20.505718,0.022623,0.001980,0.050282,200.354279,10.206533,0.502823,-20.505718,0.051314,0.000000
63.360004,45.614510,-20.461237,0.022631,0.001995,0.050672,202.903473,10.336395,0.506722,-20.461237,0.051696,0.000000
63.590004,46.182007,-20.461237,0.022635,0.002008,0.051001,205.427826,10.464992,0.510015,-20.461237,0.052085,0.000000
63.820004,47.340084,-20.461237,0.022657,0.002027,0.051487,210.579208,10.727416,0.514874,-20.461237,0.052468,0.000000
64.050003,48.003281,-20.461237,0.022661,0.002041,0.051843,213.529251,10.877698,0.518432,-20.461237,0.052849,0.000000
64.280006,47.902367,-20.505718,0.022670,0.002045,0.051939,213.080368,10.854832,0.519386,-20.505718,0.053231,0.000000
64.510002,48.572266,-20.416756,0.022687,0.002060,0.052328,216.060226,11.006633,0.523284,-20.416756,0.053612,0.000000
64.740005,50.568554,-20.416756,0.022692,0.002089,0.053048,224.940155,11.458999,0.530483,-20.416756,0.054002,0.000000
64.970001,50.928638,-20.327795,0.022700,0.002099,0.053317,226.541901,11.540594,0.533171,-20.327795,0.054384,0.000000
65.200005,51.899784,-20.461237,0.022726,0.002117,0.053768,230.861771,11.760659,0.537682,-20.461237,0.054766,0.000000
65.430000,52.509731,-20.372276,0.022713,0.002130,0.054107,233.574951,11.898875,0.541066,-20.372276,0.055147,0.000000
65.660004,53.368793,-20.372276,0.022722,0.002145,0.054479,237.396255,12.093541,0.544790,-20.372276,0.055529,0.000000
65.889999,54.071461,-20.327795,0.022735,0.002159,0.054835,240.521866,12.252769,0.548348,-20.327795,0.055919,0.000000
66.120003,54.740616,-20.372276,0.022739,0.002170,0.055130,243.498413,12.404401,0.551300,-20.372276,0.056300,0.000000
66.350006,55.403439,-20.327795,0.022743,0.002183,0.055459,246.446808,12.554598,0.554593,-20.327795,0.056682,0.000000
66.580002,56.688866,-20.327795,0.022756,0.002206,0.056023,252.164673,12.845881,0.560233,-20.327795,0.057063,0.000000
66.810005,57.866310,-20.238832,0.022761,0.002220,0.056396,257.402191,13.112694,0.563957,-20.238832,0.057446,0.000000
67.040001,58.658344,-20.238832,0.022778,0.002237,0.056812,260.925354,13.292171,0.568120,-20.238832,0.057835,0.000000
67.270004,59.542728,-20.283314,0.022778,0.002251,0.057185,264.859283,13.492576,0.571852,-20.283314,0.058217,0.000000
67.500000,60.211140,-20.283314,0.022786,0.002263,0.057489,267.832520,13.644039,0.574888,-20.283314,0.058598,0.000000
67.730003,61.571415,-20.194351,0.022795,0.002283,0.058000,273.883331,13.952282,0.580005,-20.194351,0.058980,0.000000
67.960007,62.207054,-20.194351,0.022799,0.002294,0.058278,276.710785,14.096320,0.582775,-20.194351,0.059371,0.000000
68.190002,62.705662,-20.149870,0.022825,0.002306,0.058581,278.928711,14.209306,0.585811,-20.149870,0.059752,0.000000
68.420006,63.155861,-20.194351,0.022821,0.002319,0.058911,280.931305,14.311323,0.589111,-20.194351,0.060134,0.000000
68.650002,65.560265,-20.194351,0.022829,0.002345,0.059561,291.626617,14.856169,0.595614,-20.194351,0.060515,0.000000
68.880005,66.059616,-20.149870,0.022842,0.002357,0.059865,293.847839,14.969322,0.598649,-20.149870,0.060897,0.000000
69.110001,66.987938,-20.105391,0.022838,0.002372,0.060246,297.977234,15.179684,0.602464,-20.105391,0.061287,0.000000
69.340004,67.278763,-20.105391,0.022855,0.002366,0.060091,299.270874,15.245585,0.600905,-20.105391,0.060446,0.000000
69.570000,66.843086,-20.105391,0.022868,0.002366,0.060091,297.332886,15.146860,0.600905,-20.105391,0.060446,0.000000
69.800003,66.434219,-20.105391,0.022877,0.002361,0.059969,295.514160,15.054210,0.599686,-20.105391,0.060091,0.000000
70.030006,66.128136,-20.105391,0.022877,0.002360,0.059951,294.152649,14.984849,0.599512,-20.105391,0.060091,0.000000
70.260002,65.879387,-20.016428,0.022881,0.002360,0.059943,293.046143,14.928483,0.599429,-20.016428,0.060091,0.000000
70.490005,65.654472,-20.016428,0.022886,0.002360,0.059943,292.045685,14.877517,0.599429,-20.016428,0.060091,0.000000
70.720001,65.439613,-20.016428,0.022898,0.002360,0.059935,291.089935,14.828828,0.599346,-20.016428,0.060091,0.000000
70.950005,65.280609,-20.016428,0.022881,0.002360,0.059935,290.382660,14.792797,0.599346,-20.016428,0.060091,0.000000
71.180000,65.123840,-20.060909,0.022881,0.002360,0.059935,289.685303,14.757273,0.599346,-20.060909,0.060091,0.000000
71.410004,64.959259,-19.971947,0.022890,0.002360,0.059935,288.953217,14.719978,0.599346,-19.971947,0.060091,0.000000
71.640007,64.841209,-19.927465,0.022898,0.002359,0.059925,288.428101,14.693229,0.599255,-19.927465,0.060091,0.000000
71.870003,64.734344,-20.016428,0.022894,0.002359,0.059925,287.952759,14.669012,0.599255,-20.016428,0.060091,0.000000
72.100006,64.598801,-19.927465,0.022898,0.002359,0.059925,287.349823,14.638297,0.599255,-19.927465,0.060091,0.000000
72.330002,64.488953,-19.927465,0.022877,0.002359,0.059925,286.861176,14.613405,0.599255,-19.927465,0.060091,0.000000
72.560005,64.404793,-19.882986,0.022903,0.002359,0.059925,286.486816,14.594335,0.599255,-19.882986,0.060091,0.000000
72.790001,64.321381,-19.882986,0.022903,0.002359,0.059925,286.115784,14.575433,0.599255,-19.882986,0.060091,0.000000
73.020004,64.200363,-19.882986,0.022907,0.002359,0.059925,285.577484,14.548010,0.599255,-19.882986,0.060091,0.000000
73.250000,64.138924,-19.927465,0.022890,0.002359,0.059925,285.304169,14.534088,0.599255,-19.927465,0.060091,0.000000
73.480003,64.070778,-19.838505,0.022898,0.002359,0.059917,285.001068,14.518645,0.599172,-19.838505,0.060091,0.000000
73.710007,63.965397,-19.794024,0.022894,0.002359,0.059917,284.532288,14.494766,0.599172,-19.794024,0.060091,0.000000
73.940002,63.909542,-19.794024,0.022898,0.002359,0.059917,284.283844,14.482110,0.599172,-19.794024,0.060091,0.000000
74.170006,63.855549,-19.838505,0.022911,0.002359,0.059917,284.043671,14.469874,0.599172,-19.838505,0.060091,0.000000
74.400002,63.775860,-19.838505,0.022903,0.002359,0.059917,283.689178,14.451817,0.599172,-19.838505,0.060091,0.000000
74.630005,63.715908,-19.749542,0.022898,0.002359,0.059917,283.422516,14.438231,0.599172,-19.749542,0.060091,0.000000
74.860001,63.679787,-19.749542,0.022886,0.002359,0.059917,283.261841,14.430046,0.599172,-19.749542,0.060091,0.000000
75.090004,63.614994,-19.749542,0.022907,0.002359,0.059917,282.973633,14.415363,0.599172,-19.749542,0.060091,0.000000
75.320007,63.555416,-19.794024,0.022907,0.002359,0.059917,282.708618,14.401863,0.599172,-19.794024,0.060091,0.000000
75.550003,63.512218,-19.749542,0.022894,0.002359,0.059917,282.516449,14.392075,0.599172,-19.749542,0.060091,0.000000
75.780006,63.469769,-19.660580,0.022903,0.002359,0.059917,282.327637,14.382455,0.599172,-19.660580,0.060091,0.000000
76.010002,63.406837,-19.616100,0.022907,0.002359,0.059917,282.047699,14.368195,0.599172,-19.616100,0.060091,0.000000
76.240005,63.366993,-19.616100,0.022898,0.002359,0.059917,281.870453,14.359166,0.599172,-19.616100,0.060091,0.000000
76.470001,63.334225,-19.705061,0.022903,0.002359,0.059917,281.724701,14.351740,0.599172,-19.705061,0.060091,0.000000
76.700005,63.270176,-19.705061,0.022890,0.002359,0.059917,281.439789,14.337226,0.599172,-19.705061,0.060091,0.000000
76.930000,63.215065,-19.660580,0.022903,0.002359,0.059917,281.194641,14.324739,0.599172,-19.660580,0.060091,0.000000
77.160004,63.191608,-19.527138,0.022903,0.002359,0.059917,281.090302,14.319424,0.599172,-19.527138,0.060091,0.000000
77.390007,63.162189,-19.571619,0.022894,0.002359,0.059917,280.959442,14.312757,0.599172,-19.571619,0.060091,0.000000
77.620003,63.106335,-19.616100,0.022898,0.002359,0.059917,280.710999,14.300100,0.599172,-19.616100,0.060091,0.000000
77.850006,63.080269,-19.571619,0.022898,0.002359,0.059917,280.595062,14.294193,0.599172,-19.571619,0.060091,0.000000
78.080002,63.059788,-19.571619,0.022903,0.002359,0.059917,280.503937,14.289552,0.599172,-19.571619,0.060091,0.000000
78.310005,63.008774,-19.527138,0.022894,0.002359,0.059917,280.277039,14.277992,0.599172,-19.527138,0.060091,0.000000
78.540001,62.963345,-19.571619,0.022903,0.002359,0.059917,280.074951,14.267697,0.599172,-19.571619,0.060091,0.000000
78.770004,62.940628,-19.527138,0.022903,0.002359,0.059917,279.973907,14.262550,0.599172,-19.527138,0.060091,0.000000
79.000000,62.905998,-19.571619,0.022894,0.002359,0.059917,279.819855,14.254703,0.599172,-19.571619,0.060091,0.000000
79.230003,62.867271,-19.527138,0.022903,0.002359,0.059917,279.647583,14.245928,0.599172,-19.527138,0.060091,0.000000
79.460007,62.856846,-19.438175,0.022907,0.002359,0.059917,279.601227,14.243566,0.599172,-19.438175,0.060091,0.000000
79.690002,62.811043,-19.482656,0.022916,0.002359,0.059908,279.397461,14.233186,0.599081,-19.482656,0.060091,0.000000
79.920006,62.774921,-19.438175,0.022907,0.002359,0.059908,279.236786,14.225000,0.599081,-19.438175,0.060091,0.000000
80.150002,62.749229,-19.482656,0.022903,0.002359,0.059908,279.122528,14.219179,0.599081,-19.482656,0.060091,0.000000
80.380005,62.745132,-19.349215,0.022898,0.002359,0.059908,279.104279,14.218250,0.599081,-19.349215,0.060091,0.000000
80.610001,62.696724,-19.349215,0.022911,0.002359,0.059908,278.888947,14.207281,0.599081,-19.349215,0.060091,0.000000
80.840004,62.663956,-19.393694,0.022890,0.002359,0.059908,278.743195,14.199856,0.599081,-19.393694,0.060091,0.000000
81.070007,62.646828,-19.482656,0.022920,0.002359,0.059908,278.666992,14.195974,0.599081,-19.482656,0.060091,0.000000
81.300003,62.618526,-19.393694,0.022907,0.002359,0.059908,278.541107,14.189561,0.599081,-19.393694,0.060091,0.000000
81.530006,62.598045,-19.349215,0.022907,0.002359,0.059908,278.450012,14.184919,0.599081,-19.349215,0.060091,0.000000
81.760002,62.571606,-19.304733,0.022907,0.002359,0.059908,278.332397,14.178928,0.599081,-19.304733,0.060091,0.000000
81.990005,62.550011,-19.304733,0.022886,0.002359,0.059908,278.236359,14.174034,0.599081,-19.304733,0.060091,0.000000
82.220001,62.512028,-19.260252,0.022920,0.002359,0.059908,278.067383,14.165428,0.599081,-19.260252,0.060091,0.000000
82.450005,62.504581,-19.260252,0.022894,0.002359,0.059908,278.034271,14.163740,0.599081,-19.260252,0.060091,0.000000
82.680000,62.481491,-19.215771,0.022907,0.002359,0.059908,277.931549,14.158507,0.599081,-19.215771,0.060091,0.000000
82.910004,62.437923,-19.260252,0.022911,0.002359,0.059908,277.737762,14.148636,0.599081,-19.260252,0.060091,0.000000
83.140007,62.419678,-19.260252,0.022911,0.002359,0.059908,277.656586,14.144501,0.599081,-19.260252,0.060091,0.000000
83.370003,62.426754,-19.215771,0.022911,0.002359,0.059908,277.688080,14.146105,0.599081,-19.215771,0.060091,0.000000
83.600006,62.383186,-19.215771,0.022920,0.002359,0.059908,277.494263,14.136232,0.599081,-19.215771,0.060091,0.000000
83.830002,62.356377,-19.171289,0.022903,0.002359,0.059908,277.375031,14.130157,0.599081,-19.171289,0.060091,0.000000
84.060005,62.345577,-19.126808,0.022903,0.002359,0.059908,277.326965,14.127710,0.599081,-19.126808,0.060091,0.000000
84.290001,62.316906,-19.126808,0.022916,0.002359,0.059908,277.199432,14.121213,0.599081,-19.126808,0.060091,0.000000
84.520004,62.291584,-19.215771,0.022907,0.002359,0.059908,277.086792,14.115475,0.599081,-19.215771,0.060091,0.000000
84.750008,62.290092,-19.171289,0.022907,0.002359,0.059908,277.080170,14.115136,0.599081,-19.171289,0.060091,0.000000
84.980003,62.263283,-19.082329,0.022920,0.002359,0.059908,276.960907,14.109061,0.599081,-19.082329,0.060091,0.000000
85.210007,62.238705,-19.037848,0.022898,0.002359,0.059908,276.851593,14.103492,0.599081,-19.037848,0.060091,0.000000
85.440002,62.231632,-19.126808,0.022903,0.002359,0.059908,276.820129,14.101890,0.599081,-19.126808,0.060091,0.000000
85.670006,62.210407,-19.037848,0.022916,0.002359,0.059908,276.725708,14.097079,0.599081,-19.037848,0.060091,0.000000
85.900002,62.178383,-19.037848,0.022907,0.002359,0.059908,276.583252,14.089824,0.599081,-19.037848,0.060091,0.000000
86.130005,62.172794,-19.082329,0.022903,0.002359,0.059908,276.558411,14.088557,0.599081,-19.082329,0.060091,0.000000
86.360001,62.148590,-18.993366,0.022903,0.002359,0.059908,276.450745,14.083072,0.599081,-18.993366,0.060091,0.000000
86.590004,62.132580,-18.993366,0.022903,0.002359,0.059908,276.379517,14.079444,0.599081,-18.993366,0.060091,0.000000
86.820007,62.121410,-19.037848,0.022898,0.002359,0.059908,276.329834,14.076913,0.599081,-19.037848,0.060091,0.000000
87.050003,62.097576,-18.948885,0.022903,0.002359,0.059908,276.223816,14.071512,0.599081,-18.948885,0.060091,0.000000
87.280006,62.078587,-18.993366,0.022907,0.002359,0.059908,276.139343,14.067209,0.599081,-18.993366,0.060091,0.000000
87.510002,62.060341,-18.904404,0.022920,0.002359,0.059908,276.058197,14.063075,0.599081,-18.904404,0.060091,0.000000
87.740005,62.044701,-18.948885,0.022916,0.002359,0.059908,275.988617,14.059530,0.599081,-18.948885,0.060091,0.000000
87.970001,62.026081,-18.993366,0.022911,0.002359,0.059908,275.905792,14.055311,0.599081,-18.993366,0.060091,0.000000
88.200005,62.014538,-18.904404,0.022907,0.002359,0.059908,275.854431,14.052695,0.599081,-18.904404,0.060091,0.000000
88.430008,61.987728,-18.904404,0.022907,0.002359,0.059908,275.735199,14.046620,0.599081,-18.904404,0.060091,0.000000
88.660004,61.982887,-18.815443,0.022911,0.002359,0.059908,275.713654,14.045524,0.599081,-18.815443,0.060091,0.000000
88.890007,61.970970,-18.859922,0.022920,0.002359,0.059908,275.660645,14.042823,0.599081,-18.859922,0.060091,0.000000
89.120003,61.950863,-18.859922,0.022911,0.002359,0.059908,275.571198,14.038266,0.599081,-18.859922,0.060091,0.000000
89.350006,61.928146,-18.815443,0.022903,0.002359,0.059908,275.470154,14.033118,0.599081,-18.815443,0.060091,0.000000
89.580002,61.929638,-18.815443,0.022903,0.002359,0.059908,275.476776,14.033456,0.599081,-18.815443,0.060091,0.000000
89.810005,61.908039,-18.770962,0.022920,0.002359,0.059908,275.380707,14.028563,0.599081,-18.770962,0.060091,0.000000
90.040001,61.891281,-18.770962,0.022920,0.002359,0.059908,275.306183,14.024765,0.599081,-18.770962,0.060091,0.000000
90.270004,61.882717,-18.815443,0.022907,0.002359,0.059908,275.268066,14.022823,0.599081,-18.815443,0.060091,0.000000
90.500008,61.860748,-18.770962,0.022907,0.002359,0.059908,275.170349,14.017846,0.599081,-18.770962,0.060091,0.000000
90.730003,61.851067,-18.726480,0.022907,0.002359,0.059908,275.127289,14.015652,0.599081,-18.726480,0.060091,0.000000
90.960007,61.833939,-18.770962,0.022911,0.002359,0.059908,275.051086,14.011770,0.599081,-18.770962,0.060091,0.000000
91.190002,61.819042,-18.726480,0.022911,0.002359,0.059908,274.984833,14.008395,0.599081,-18.726480,0.060091,0.000000
91.420006,61.819042,-18.770962,0.022911,0.002359,0.059908,274.984833,14.008395,0.599081,-18.770962,0.060091,0.000000
91.650002,61.787392,-18.726480,0.022907,0.002359,0.059908,274.844055,14.001224,0.599081,-18.726480,0.060091,0.000000
91.880005,61.779198,-18.637518,0.022907,0.002359,0.059908,274.807587,13.999366,0.599081,-18.637518,0.060091,0.000000
92.110001,61.778080,-18.637518,0.022920,0.002359,0.059908,274.802612,13.999113,0.599081,-18.637518,0.060091,0.000000
92.340004,61.746429,-18.637518,0.022898,0.002359,0.059908,274.661835,13.991940,0.599081,-18.637518,0.060091,0.000000
92.570007,61.745686,-18.637518,0.022907,0.002359,0.059908,274.658539,13.991773,0.599081,-18.637518,0.060091,0.000000
92.800003,61.726322,-18.637518,0.022907,0.002359,0.059908,274.572388,13.987384,0.599081,-18.637518,0.060091,0.000000
93.030006,61.722225,-18.548557,0.022903,0.002359,0.059908,274.554169,13.986457,0.599081,-18.548557,0.060091,0.000000
93.260002,61.707703,-18.593037,0.022903,0.002359,0.059908,274.489563,13.983166,0.599081,-18.593037,0.060091,0.000000
93.490005,61.683872,-18.593037,0.022916,0.002359,0.059908,274.383575,13.977766,0.599081,-18.593037,0.060091,0.000000
93.720001,61.688713,-18.593037,0.022916,0.002359,0.059908,274.405090,13.978863,0.599081,-18.593037,0.060091,0.000000
93.950005,61.671581,-18.548557,0.022911,0.002359,0.059908,274.328888,13.974980,0.599081,-18.548557,0.060091,0.000000
94.180008,61.661156,-18.548557,0.022911,0.002359,0.059908,274.282532,13.972617,0.599081,-18.548557,0.060091,0.000000
94.410004,61.653336,-18.548557,0.022903,0.002359,0.059908,274.247742,13.970845,0.599081,-18.548557,0.060091,0.000000
94.640007,61.653336,-18.504076,0.022911,0.002359,0.059908,274.247742,13.970845,0.599081,-18.504076,0.060091,0.000000
94.870003,61.629505,-18.548557,0.022911,0.002359,0.059908,274.141724,13.965446,0.599081,-18.548557,0.060091,0.000000
95.100006,61.620941,-18.459595,0.022907,0.002359,0.059908,274.103638,13.963506,0.599081,-18.459595,0.060091,0.000000
95.330002,61.602695,-18.459595,0.022903,0.002359,0.059908,274.022461,13.959370,0.599081,-18.459595,0.060091,0.000000
95.560005,61.589661,-18.415113,0.022916,0.002359,0.059908,273.964508,13.956417,0.599081,-18.415113,0.060091,0.000000
95.790001,61.584820,-18.459595,0.022911,0.002359,0.059908,273.942963,13.955319,0.599081,-18.459595,0.060091,0.000000
96.020004,61.579235,-18.370632,0.022911,0.002359,0.059908,273.918121,13.954054,0.599081,-18.370632,0.060091,0.000000
96.250008,61.565456,-18.415113,0.022903,0.002359,0.059908,273.856842,13.950932,0.599081,-18.415113,0.060091,0.000000
96.480003,61.547211,-18.326151,0.022920,0.002359,0.059908,273.775665,13.946797,0.599081,-18.326151,0.060091,0.000000
96.710007,61.543858,-18.415113,0.022920,0.002359,0.059908,273.760742,13.946037,0.599081,-18.415113,0.060091,0.000000
96.940002,61.531944,-18.370632,0.022911,0.002359,0.059908,273.707764,13.943337,0.599081,-18.370632,0.060091,0.000000
97.170006,61.516674,-18.326151,0.022916,0.002359,0.059908,273.639832,13.939878,0.599081,-18.326151,0.060091,0.000000
97.400002,61.524124,-18.326151,0.022907,0.002359,0.059908,273.672974,13.941566,0.599081,-18.326151,0.060091,0.000000
97.630005,61.508484,-18.281672,0.022916,0.002359,0.059908,273.603394,13.938022,0.599081,-18.281672,0.060091,0.000000
97.860008,61.480556,-18.237190,0.022911,0.002359,0.059908,273.479187,13.931694,0.599081,-18.237190,0.060091,0.000000
98.090004,61.486515,-18.370632,0.022920,0.002359,0.059908,273.505676,13.933043,0.599081,-18.370632,0.060091,0.000000
98.320007,61.461563,-18.237190,0.022907,0.002359,0.059908,273.394684,13.927389,0.599081,-18.237190,0.060091,0.000000
98.550003,61.459332,-18.281672,0.022911,0.002359,0.059908,273.384766,13.926884,0.599081,-18.281672,0.060091,0.000000
98.780006,61.451881,-18.237190,0.022911,0.002359,0.059908,273.351624,13.925196,0.599081,-18.237190,0.060091,0.000000
99.010002,61.433636,-18.237190,0.022907,0.002359,0.059908,273.270447,13.921062,0.599081,-18.237190,0.060091,0.000000
99.240005,61.437359,-18.281672,0.022916,0.002359,0.059908,273.287018,13.921905,0.599081,-18.281672,0.060091,0.000000
99.470001,61.420605,-18.237190,0.022911,0.002359,0.059908,273.212494,13.918108,0.599081,-18.237190,0.060091,0.000000
99.700005,61.408688,-18.192709,0.022903,0.002359,0.059908,273.159485,13.915408,0.599081,-18.192709,0.060091,0.000000