File: Data/I-18 Polished After 3_08182023_171310.csv
Time (sec),S:Load (lbs),S:HL1 (DIM),S:LVDT (in),S:Position (in),Ch:Position (mm),Ch:Load (N),Ch:Stress (MPa),Ch:Strain (mm/mm),Ch:HL1 (DIM),Set Point (),Cycles ()
0.110000,0.001114,-31.536995,0.000000,-0.000000,-0.000000,0.004955,0.000252,-0.000000,-31.536995,0.000199,0.000000
0.340000,-0.001862,-31.536995,0.000000,-0.000000,-0.000000,-0.008281,-0.000422,-0.000000,-31.536995,0.000217,0.000000
0.570000,-0.011543,-31.581474,0.000022,0.000119,0.003035,-0.051347,-0.002616,0.030351,-31.581474,0.004050,0.000000
0.800000,0.035370,-31.536995,-0.000026,0.000268,0.006799,0.157333,0.008015,0.067992,-31.536995,0.007883,0.000000
1.030000,0.020477,-31.536995,0.000259,0.000415,0.010537,0.091088,0.004640,0.105368,-31.536995,0.011716,0.000000
1.260000,0.034256,-31.536995,0.000332,0.000556,0.014110,0.152378,0.007763,0.141097,-31.536995,0.015549,0.000000
1.490000,0.040955,-31.536995,0.000440,0.000722,0.018350,0.182175,0.009280,0.183503,-31.536995,0.019382,0.000000
1.720000,-0.000000,-31.536995,0.000543,0.000868,0.022053,-0.000000,-0.000000,0.220534,-31.536995,0.023216,0.000000
1.950000,-0.025322,-31.625956,0.000664,0.001014,0.025748,-0.112638,-0.005738,0.257479,-31.625956,0.027049,0.000000
2.180000,0.062927,-31.536995,0.000811,0.001171,0.029746,0.279914,0.014260,0.297459,-31.536995,0.030882,0.000000
2.410000,0.082664,-31.492514,0.000957,0.001315,0.033405,0.367710,0.018732,0.334055,-31.492514,0.034715,0.000000
2.640000,0.060692,-31.536995,0.001121,0.001477,0.037525,0.269971,0.013753,0.375250,-31.536995,0.038531,0.000000
2.870000,0.036491,-31.581474,0.001298,0.001625,0.041263,0.162322,0.008269,0.412625,-31.581474,0.042364,0.000000
3.100000,0.067024,-31.581474,0.001397,0.001771,0.044974,0.298139,0.015188,0.449744,-31.581474,0.046197,0.000000
3.330000,0.051010,-31.536995,0.001582,0.001924,0.048860,0.226904,0.011559,0.488596,-31.536995,0.050030,0.000000
3.560000,0.062187,-31.581474,0.001720,0.002070,0.052571,0.276622,0.014092,0.525711,-31.581474,0.053863,0.000000
3.790000,0.035004,-31.536995,0.001893,0.002224,0.056482,0.155704,0.007932,0.564824,-31.536995,0.057697,0.000000
4.020000,0.036118,-31.670437,0.002082,0.002380,0.060463,0.160659,0.008184,0.604629,-31.670437,0.061530,0.000000
4.250000,0.006325,-31.581474,0.002229,0.002528,0.064209,0.028134,0.001433,0.642092,-31.581474,0.065363,0.000000
4.480000,0.058456,-31.492514,0.002397,0.002684,0.068173,0.260027,0.013246,0.681728,-31.492514,0.069196,0.000000
4.710000,0.046547,-31.581474,0.002561,0.002829,0.071858,0.207051,0.010548,0.718581,-31.581474,0.073029,0.000000
4.940000,0.067398,-31.581474,0.002721,0.002974,0.075544,0.299802,0.015273,0.755439,-31.581474,0.076862,0.000000
5.170000,0.049149,-31.581474,0.002863,0.003138,0.079698,0.218624,0.011137,0.796982,-31.581474,0.080695,0.000000
5.400000,0.037979,-31.581474,0.003031,0.003283,0.083392,0.168940,0.008606,0.833922,-31.581474,0.084528,0.000000
5.630000,0.023827,-31.581474,0.003182,0.003430,0.087121,0.105986,0.005399,0.871215,-31.581474,0.088344,0.000000
5.860000,0.033882,-31.581474,0.003337,0.003581,0.090946,0.150715,0.007678,0.909461,-31.581474,0.092177,0.000000
6.090000,0.050636,-31.625956,0.003510,0.003733,0.094814,0.225241,0.011474,0.948139,-31.625956,0.096011,0.000000
6.320000,0.027550,-31.536995,0.003695,0.003887,0.098725,0.122547,0.006243,0.987248,-31.536995,0.099844,0.000000
6.550000,0.050636,-31.581474,0.003842,0.004038,0.102558,0.225241,0.011474,1.025582,-31.581474,0.103677,0.000000
6.780000,0.034630,-31.536995,0.004005,0.004184,0.106278,0.154041,0.007847,1.062783,-31.536995,0.107510,0.000000
7.010000,0.052132,-31.581474,0.004148,0.004339,0.110216,0.231893,0.011813,1.102158,-31.581474,0.111343,0.000000
7.240000,0.052132,-31.625956,0.004316,0.004482,0.113849,0.231893,0.011813,1.138493,-31.625956,0.115176,0.000000
7.470000,0.048775,-31.625956,0.004467,0.004641,0.117891,0.216961,0.011053,1.178908,-31.625956,0.119009,0.000000
7.700000,0.042450,-31.581474,0.004665,0.004794,0.121759,0.188827,0.009619,1.217586,-31.581474,0.122843,0.000000
7.930000,0.010422,-31.625956,0.004781,0.004938,0.125436,0.046358,0.002362,1.254356,-31.625956,0.126676,0.000000
8.160001,0.012657,-31.581474,0.004919,0.005086,0.129173,0.056302,0.002868,1.291732,-31.581474,0.130509,0.000000
8.390000,0.057343,-31.670437,0.005092,0.005243,0.133171,0.255072,0.012994,1.331712,-31.670437,0.134324,0.000000
8.620001,0.080055,-31.670437,0.005238,0.005384,0.136762,0.356103,0.018141,1.367615,-31.670437,0.138158,0.000000
8.850000,0.059952,-31.625956,0.005398,0.005546,0.140881,0.266679,0.013585,1.408806,-31.625956,0.141991,0.000000
9.080001,0.043190,-31.581474,0.005579,0.005696,0.144670,0.192119,0.009787,1.446704,-31.581474,0.145824,0.000000
9.310000,0.052132,-31.625956,0.005747,0.005845,0.148469,0.231893,0.011813,1.484689,-31.625956,0.149657,0.000000
9.540001,0.062187,-31.625956,0.005902,0.006000,0.152398,0.276622,0.014092,1.523977,-31.625956,0.153490,0.000000
9.770000,0.074471,-31.625956,0.006040,0.006140,0.155962,0.331261,0.016875,1.559619,-31.625956,0.157323,0.000000
10.000000,0.052132,-31.625956,0.006217,0.006303,0.160090,0.231893,0.011813,1.600897,-31.625956,0.161157,0.000000
10.230000,0.037979,-31.581474,0.006381,0.006452,0.163871,0.168940,0.008606,1.638708,-31.581474,0.164990,0.000000
10.460000,0.005959,-31.625956,0.006532,0.006600,0.167635,0.026505,0.001350,1.676349,-31.625956,0.168823,0.000000
10.690001,0.072609,-31.625956,0.006653,0.006753,0.171537,0.322981,0.016453,1.715371,-31.625956,0.172656,0.000000
10.920000,0.065910,-31.625956,0.006829,0.006897,0.175180,0.293184,0.014935,1.751797,-31.625956,0.176489,0.000000
11.150001,0.093834,-31.581474,0.006963,0.007057,0.179238,0.417394,0.021263,1.792382,-31.581474,0.180322,0.000000
11.380000,0.086761,-31.625956,0.007136,0.007210,0.183123,0.385934,0.019660,1.831234,-31.625956,0.184138,0.000000
11.610001,0.078941,-31.670437,0.007252,0.007354,0.186792,0.351149,0.017888,1.867918,-31.670437,0.187971,0.000000
11.840000,0.063301,-31.670437,0.007420,0.007512,0.190815,0.281577,0.014344,1.908155,-31.670437,0.191804,0.000000
12.070001,0.073357,-31.581474,0.007567,0.007654,0.194423,0.326307,0.016623,1.944232,-31.581474,0.195637,0.000000
12.300000,0.068138,-31.625956,0.007739,0.007806,0.198282,0.303093,0.015440,1.982823,-31.625956,0.199470,0.000000
12.530001,0.054733,-31.625956,0.007899,0.007963,0.202272,0.243466,0.012403,2.022716,-31.625956,0.203304,0.000000
12.760000,0.008560,-31.670437,0.008071,0.008114,0.206088,0.038078,0.001940,2.060875,-31.670437,0.207137,0.000000
12.990001,0.076332,-31.625956,0.008209,0.008259,0.209791,0.339542,0.017297,2.097907,-31.625956,0.210970,0.000000
13.220000,0.085640,-31.625956,0.008334,0.008413,0.213693,0.380946,0.019406,2.136929,-31.625956,0.214803,0.000000
13.450001,0.093094,-31.625956,0.008511,0.008557,0.217353,0.414102,0.021095,2.173529,-31.625956,0.218636,0.000000
13.680000,0.085274,-31.625956,0.008653,0.008716,0.221377,0.379317,0.019323,2.213766,-31.625956,0.222469,0.000000
13.910001,0.061066,-31.714918,0.008834,0.008866,0.225201,0.271634,0.013838,2.252012,-31.714918,0.226303,0.000000
14.140000,0.064415,-31.625956,0.008942,0.009012,0.228904,0.286532,0.014597,2.289040,-31.625956,0.230118,0.000000
14.370001,0.080429,-31.670437,0.009132,0.009165,0.232781,0.357766,0.018225,2.327809,-31.670437,0.233952,0.000000
14.600000,0.083412,-31.625956,0.009283,0.009316,0.236631,0.371036,0.018901,2.366313,-31.625956,0.237785,0.000000
14.830001,0.068512,-31.670437,0.009472,0.009469,0.240508,0.304756,0.015525,2.405077,-31.670437,0.241618,0.000000
15.060000,0.090485,-31.670437,0.009619,0.009624,0.244462,0.402496,0.020504,2.444622,-31.670437,0.245451,0.000000
15.290001,0.073357,-31.625956,0.009735,0.009770,0.248157,0.326307,0.016623,2.481566,-31.625956,0.249284,0.000000
15.520000,0.077820,-31.581474,0.009908,0.009921,0.251990,0.346160,0.017634,2.519896,-31.581474,0.253117,0.000000
15.750001,0.096817,-31.670437,0.010033,0.010069,0.255762,0.430664,0.021939,2.557620,-31.670437,0.256950,0.000000
15.980000,0.103516,-31.714918,0.010184,0.010220,0.259578,0.460460,0.023457,2.595779,-31.714918,0.260783,0.000000
16.210001,0.089737,-31.670437,0.010330,0.010376,0.263559,0.399170,0.020335,2.635585,-31.670437,0.264616,0.000000
16.440001,0.049896,-31.670437,0.010516,0.010524,0.267314,0.221950,0.011307,2.673135,-31.670437,0.268450,0.000000
16.670000,0.043938,-31.670437,0.010637,0.010671,0.271051,0.195445,0.009956,2.710515,-31.670437,0.272283,0.000000
16.900002,0.087875,-31.670437,0.010822,0.010827,0.274997,0.390889,0.019913,2.749972,-31.670437,0.276116,0.000000
17.130001,0.110596,-31.714918,0.010990,0.010969,0.278605,0.491954,0.025061,2.786050,-31.714918,0.279932,0.000000
17.360001,0.098305,-31.759399,0.011158,0.011129,0.282681,0.437281,0.022276,2.826809,-31.759399,0.283765,0.000000
17.590000,0.080429,-31.625956,0.011331,0.011281,0.286531,0.357766,0.018225,2.865313,-31.625956,0.287598,0.000000
17.820002,0.072609,-31.625956,0.011486,0.011431,0.290339,0.322981,0.016453,2.903385,-31.625956,0.291431,0.000000
18.050001,0.095322,-31.670437,0.011632,0.011585,0.294258,0.424012,0.021600,2.942582,-31.670437,0.295264,0.000000
18.280001,0.080429,-31.714918,0.011796,0.011727,0.297857,0.357766,0.018225,2.978572,-31.714918,0.299098,0.000000
18.510000,0.085640,-31.670437,0.011956,0.011880,0.301742,0.380946,0.019406,3.017424,-31.670437,0.302931,0.000000
18.740002,0.068138,-31.670437,0.012154,0.012038,0.305767,0.303093,0.015440,3.057665,-31.670437,0.306764,0.000000
18.970001,0.026810,-31.625956,0.012331,0.012185,0.309504,0.119255,0.006075,3.095041,-31.625956,0.310597,0.000000
19.200001,0.037979,-31.670437,0.012465,0.012335,0.313320,0.168940,0.008606,3.133200,-31.670437,0.314430,0.000000
19.430000,0.075218,-31.759399,0.012646,0.012486,0.317144,0.334587,0.017045,3.171443,-31.759399,0.318263,0.000000
19.660002,0.110596,-31.670437,0.012745,0.012633,0.320882,0.491954,0.025061,3.208822,-31.670437,0.322096,0.000000
19.890001,0.106865,-31.670437,0.012947,0.012790,0.324863,0.475359,0.024216,3.248628,-31.670437,0.325912,0.000000
20.120001,0.084152,-31.670437,0.013111,0.012940,0.328687,0.374328,0.019069,3.286871,-31.670437,0.329745,0.000000
20.350000,0.070747,-31.670437,0.013262,0.013093,0.332555,0.314700,0.016032,3.325549,-31.670437,0.333578,0.000000
20.580002,0.093094,-31.714918,0.013409,0.013239,0.336275,0.414102,0.021095,3.362754,-31.714918,0.337412,0.000000
20.810001,0.084152,-31.759399,0.013568,0.013386,0.340013,0.374328,0.019069,3.400130,-31.759399,0.341245,0.000000
21.040001,0.081177,-31.625956,0.013715,0.013543,0.343994,0.361092,0.018395,3.439936,-31.625956,0.345078,0.000000
21.270000,0.061066,-31.714918,0.013900,0.013695,0.347853,0.271634,0.013838,3.478530,-31.714918,0.348911,0.000000
21.500002,0.090858,-31.714918,0.014012,0.013842,0.351582,0.404159,0.020589,3.515819,-31.714918,0.352744,0.000000
21.730001,0.084526,-31.714918,0.014189,0.013992,0.355407,0.375991,0.019154,3.554065,-31.714918,0.356577,0.000000
21.960001,0.101280,-31.714918,0.014336,0.014144,0.359257,0.450517,0.022950,3.592569,-31.714918,0.360410,0.000000
22.190001,0.098305,-31.670437,0.014504,0.014289,0.362943,0.437281,0.022276,3.629427,-31.670437,0.364244,0.000000
22.420002,0.096443,-31.714918,0.014698,0.014452,0.367088,0.429001,0.021854,3.670879,-31.714918,0.368076,0.000000
22.650002,0.083412,-31.759399,0.014810,0.014597,0.370765,0.371036,0.018901,3.707649,-31.759399,0.371910,0.000000
22.880001,0.071495,-31.670437,0.014974,0.014745,0.374529,0.318026,0.016201,3.745286,-31.670437,0.375725,0.000000
23.110001,0.098679,-31.714918,0.015138,0.014899,0.378422,0.438944,0.022361,3.784225,-31.714918,0.379559,0.000000
23.340002,0.103889,-31.670437,0.015293,0.015046,0.382160,0.462123,0.023542,3.821605,-31.670437,0.383392,0.000000
23.570002,0.118042,-31.714918,0.015452,0.015202,0.386132,0.525077,0.026749,3.861323,-31.714918,0.387225,0.000000
23.800001,0.103142,-31.714918,0.015599,0.015351,0.389913,0.458798,0.023372,3.899134,-31.714918,0.391058,0.000000
24.030001,0.083412,-31.714918,0.015767,0.015503,0.393781,0.371036,0.018901,3.937812,-31.714918,0.394891,0.000000
24.260000,0.107613,-31.714918,0.015914,0.015653,0.397580,0.478685,0.024385,3.975797,-31.714918,0.398724,0.000000
24.490002,0.133682,-31.714918,0.016082,0.015800,0.401326,0.594648,0.030293,4.013260,-31.714918,0.402558,0.000000
24.720001,0.106865,-31.714918,0.016229,0.015952,0.405176,0.475359,0.024216,4.051764,-31.714918,0.406391,0.000000
24.950001,0.102028,-31.759399,0.016423,0.016109,0.409174,0.453843,0.023120,4.091744,-31.759399,0.410224,0.000000
25.180000,0.050636,-31.714918,0.016582,0.016256,0.412895,0.225241,0.011474,4.128950,-31.714918,0.414057,0.000000
25.410002,0.080429,-31.670437,0.016724,0.016407,0.416728,0.357766,0.018225,4.167279,-31.670437,0.417890,0.000000
25.640001,0.123253,-31.759399,0.016884,0.016557,0.420553,0.548256,0.027929,4.205525,-31.759399,0.421706,0.000000
25.870001,0.147453,-31.714918,0.017026,0.016707,0.424359,0.655905,0.033413,4.243594,-31.714918,0.425539,0.000000
26.100000,0.137032,-31.759399,0.017186,0.016866,0.428392,0.609547,0.031052,4.283922,-31.759399,0.429372,0.000000
26.330002,0.115807,-31.759399,0.017345,0.017013,0.432130,0.515133,0.026242,4.321298,-31.759399,0.433205,0.000000
26.560001,0.142242,-31.625956,0.017496,0.017162,0.435920,0.632726,0.032233,4.359196,-31.625956,0.437038,0.000000
26.790001,0.135910,-31.759399,0.017664,0.017310,0.439683,0.604558,0.030798,4.396833,-31.759399,0.440871,0.000000
27.020000,0.153412,-31.759399,0.017828,0.017458,0.443421,0.682410,0.034764,4.434213,-31.759399,0.444705,0.000000
27.250002,0.134048,-31.759399,0.017962,0.017614,0.447393,0.596277,0.030376,4.473931,-31.759399,0.448538,0.000000
27.480001,0.135170,-31.714918,0.018126,0.017765,0.451243,0.601266,0.030630,4.512435,-31.714918,0.452371,0.000000
27.710001,0.125862,-31.670437,0.018281,0.017913,0.454981,0.559863,0.028521,4.549811,-31.670437,0.456204,0.000000
27.940001,0.197723,-31.759399,0.018414,0.018068,0.458936,0.879518,0.044805,4.589359,-31.759399,0.460037,0.000000
28.170002,0.224541,-31.714918,0.018583,0.018214,0.462647,0.998807,0.050882,4.626474,-31.714918,0.463870,0.000000
28.400002,0.256935,-31.759399,0.018734,0.018361,0.466368,1.142905,0.058222,4.663680,-31.759399,0.467704,0.000000
28.630001,0.296036,-31.714918,0.018876,0.018524,0.470513,1.316833,0.067083,4.705132,-31.714918,0.471519,0.000000
28.860001,0.355240,-31.714918,0.019061,0.018668,0.474164,1.580186,0.080499,4.741644,-31.714918,0.475353,0.000000
29.090002,0.495628,-31.759399,0.019186,0.018814,0.477885,2.204665,0.112311,4.778846,-31.759399,0.479185,0.000000
29.320002,0.685165,-31.803881,0.019294,-0.000006,-0.000148,3.047768,0.155261,-0.001476,-31.803881,0.000112,0.000000
29.550001,0.659096,-31.714918,0.019303,-0.000006,-0.000148,2.931804,0.149353,-0.001476,-31.714918,0.000112,0.000000
29.780001,0.630424,-31.714918,0.019329,-0.000006,-0.000148,2.804268,0.142856,-0.001476,-31.714918,0.000216,0.000000
30.010002,0.612549,-31.714918,0.019316,-0.000006,-0.000148,2.724753,0.138806,-0.001476,-31.714918,0.000598,0.000000
30.240002,0.627815,-31.759399,0.019307,0.000001,0.000017,2.792662,0.142265,0.000170,-31.759399,0.000980,0.000000
30.470001,0.620369,-31.759399,0.019303,0.000011,0.000286,2.759539,0.140578,0.002861,-31.759399,0.001361,0.000000
30.700001,0.676224,-31.803881,0.019303,0.000026,0.000668,3.007993,0.153234,0.006677,-31.803881,0.001752,0.000000
30.930002,0.736923,-31.714918,0.019303,0.000040,0.001014,3.277998,0.166989,0.010144,-31.714918,0.002133,0.000000
31.160002,0.829643,-31.714918,0.019324,0.000053,0.001344,3.690438,0.188000,0.013440,-31.714918,0.002515,0.000000
31.390001,0.896667,-31.759399,0.019341,0.000070,0.001786,3.988576,0.203188,0.017865,-31.759399,0.002896,0.000000
31.620001,0.946571,-31.759399,0.019372,0.000082,0.002090,4.210560,0.214496,0.020900,-31.759399,0.003278,0.000000
31.850002,1.032585,-31.803881,0.019389,0.000100,0.002550,4.593168,0.233987,0.025495,-31.803881,0.003668,0.000000
32.080002,1.140945,-31.759399,0.019380,0.000122,0.003096,5.075179,0.258542,0.030957,-31.759399,0.004050,0.000000
32.310001,1.174835,-31.714918,0.019406,0.000131,0.003321,5.225928,0.266221,0.033212,-31.714918,0.004431,0.000000
32.540001,1.247070,-31.759399,0.019441,0.000147,0.003729,5.547246,0.282590,0.037289,-31.759399,0.004813,0.000000
32.770000,1.305908,-31.803881,0.019454,0.000157,0.003981,5.808970,0.295923,0.039806,-31.803881,0.005203,0.000000
33.000000,1.462677,-31.759399,0.019432,0.000176,0.004475,6.506312,0.331447,0.044749,-31.759399,0.005585,0.000000
33.230003,1.608276,-31.803881,0.019471,0.000193,0.004900,7.153971,0.364441,0.048995,-31.803881,0.005967,0.000000
33.460003,1.685356,-31.803881,0.019462,0.000203,0.005169,7.496839,0.381907,0.051687,-31.803881,0.006348,0.000000
33.690002,1.807869,-31.759399,0.019454,0.000217,0.005515,8.041802,0.409669,0.055153,-31.759399,0.006730,0.000000
33.920002,1.990326,-31.759399,0.019510,0.000240,0.006105,8.853412,0.451014,0.061050,-31.759399,0.007120,0.000000
34.150002,2.106506,-31.803881,0.019510,0.000254,0.006461,9.370208,0.477341,0.064608,-31.803881,0.007501,0.000000
34.380001,2.173538,-31.714918,0.019523,0.000270,0.006860,9.668381,0.492531,0.068597,-31.714918,0.007883,0.000000
34.610001,2.290085,-31.759399,0.019535,0.000280,0.007102,10.186806,0.518941,0.071024,-31.759399,0.008264,0.000000
34.840000,2.447975,-31.803881,0.019553,0.000294,0.007475,10.889137,0.554719,0.074752,-31.803881,0.008646,0.000000
35.070004,2.719437,-31.803881,0.019583,0.000314,0.007978,12.096659,0.616233,0.079782,-31.803881,0.009036,0.000000
35.300003,2.818855,-31.759399,0.019574,0.000322,0.008186,12.538895,0.638762,0.081863,-31.759399,0.009418,0.000000
35.530003,2.995735,-31.803881,0.019566,0.000336,0.008542,13.325696,0.678843,0.085421,-31.803881,0.009799,0.000000
35.760002,3.257141,-31.714918,0.019609,0.000356,0.009054,14.488487,0.738079,0.090538,-31.714918,0.010181,0.000000
35.990002,3.499184,-31.803881,0.019609,0.000376,0.009556,15.565146,0.792926,0.095565,-31.803881,0.010563,0.000000
36.220001,3.586685,-31.848360,0.019626,0.000386,0.009808,15.954372,0.812754,0.098082,-31.848360,0.010953,0.000000
36.450001,3.755745,-31.759399,0.019643,0.000401,0.010190,16.706388,0.851064,0.101897,-31.759399,0.011335,0.000000
36.680000,3.949005,-31.803881,0.019652,0.000414,0.010528,17.566051,0.894857,0.105281,-31.803881,0.011716,0.000000
36.910000,4.288612,-31.759399,0.019678,0.000433,0.011005,19.076700,0.971813,0.110050,-31.759399,0.012098,0.000000
37.140003,4.463623,-31.803881,0.019686,0.000448,0.011386,19.855186,1.011472,0.113865,-31.803881,0.012479,0.000000
37.370003,4.552254,-31.803881,0.019717,0.000457,0.011603,20.249435,1.031556,0.116034,-31.803881,0.012869,0.000000
37.600002,4.838974,-31.759399,0.019695,0.000478,0.012132,21.524832,1.096527,0.121325,-31.759399,0.013251,0.000000
37.830002,5.087349,-31.759399,0.019742,0.000493,0.012514,22.629658,1.152810,0.125140,-31.759399,0.013632,0.000000
38.060001,5.369232,-31.803881,0.019781,0.000509,0.012930,23.883537,1.216685,0.129303,-31.803881,0.014014,0.000000
38.290001,5.569572,-31.892841,0.019764,0.000525,0.013338,24.774696,1.262083,0.133376,-31.892841,0.014396,0.000000
38.520000,5.628777,-31.759399,0.019773,0.000535,0.013598,25.038048,1.275499,0.135980,-31.759399,0.014786,0.000000
38.750000,6.138557,-31.759399,0.019794,0.000558,0.014179,27.305668,1.391017,0.141790,-31.759399,0.015168,0.000000
38.980003,6.217873,-31.848360,0.019833,0.000570,0.014483,27.658480,1.408990,0.144825,-31.848360,0.015549,0.000000
39.210003,6.384323,-31.803881,0.019846,0.000580,0.014734,28.398888,1.446708,0.147338,-31.803881,0.015931,0.000000
39.440002,6.453957,-31.848360,0.019829,0.000592,0.015046,28.708633,1.462487,0.150461,-31.848360,0.016313,0.000000
39.670002,6.818878,-31.848360,0.019855,0.000607,0.015411,30.331884,1.545180,0.154106,-31.848360,0.016703,0.000000
39.900002,7.172264,-31.803881,0.019880,0.000627,0.015914,31.903824,1.625258,0.159136,-31.803881,0.017084,0.000000
40.130001,7.361801,-31.803881,0.019902,0.000640,0.016260,32.746925,1.668208,0.162603,-31.803881,0.017466,0.000000
40.360001,7.546867,-31.892841,0.019906,0.000654,0.016616,33.570141,1.710145,0.166157,-31.892841,0.017847,0.000000
40.590000,7.834343,-31.892841,0.019906,0.000671,0.017049,34.848900,1.775287,0.170494,-31.892841,0.018229,0.000000
40.820004,8.186981,-31.848360,0.019932,0.000689,0.017501,36.417511,1.855196,0.175006,-31.848360,0.018619,0.000000
41.050003,8.416733,-31.803881,0.019949,0.000703,0.017847,37.439499,1.907259,0.178473,-31.803881,0.019001,0.000000
41.280003,8.482643,-31.759399,0.019954,0.000713,0.018099,37.732681,1.922194,0.180990,-31.759399,0.019382,0.000000
41.510002,9.006569,-31.759399,0.019971,0.000736,0.018706,40.063221,2.040918,0.187057,-31.759399,0.019764,0.000000
41.740002,9.241913,-31.848360,0.020005,0.000752,0.019113,41.110081,2.094247,0.191133,-31.848360,0.020154,0.000000
41.970001,9.367775,-31.848360,0.019993,0.000764,0.019417,41.669945,2.122768,0.194169,-31.848360,0.020536,0.000000
42.200001,9.578537,-31.803881,0.020023,0.000780,0.019816,42.607460,2.170527,0.198158,-31.803881,0.020917,0.000000
42.430000,9.834351,-31.848360,0.020040,0.000793,0.020145,43.745377,2.228496,0.201455,-31.848360,0.021299,0.000000
42.660004,10.025383,-31.848360,0.020061,0.000811,0.020588,44.595131,2.271784,0.205879,-31.848360,0.021681,0.000000
42.890003,10.360886,-31.892841,0.020079,0.000824,0.020935,46.087521,2.347810,0.209346,-31.892841,0.022071,0.000000
43.120003,10.480423,-31.848360,0.020083,0.000836,0.021247,46.619251,2.374898,0.212469,-31.848360,0.022452,0.000000
43.350002,10.569786,-31.803881,0.020070,0.000846,0.021498,47.016758,2.395148,0.214982,-31.803881,0.022834,0.000000
43.580002,10.969345,-31.803881,0.020092,0.000864,0.021958,48.794083,2.485689,0.219581,-31.803881,0.023215,0.000000
43.810001,11.488060,-31.892841,0.020143,0.000888,0.022548,51.101444,2.603232,0.225478,-31.892841,0.023597,0.000000
44.040001,11.498116,-31.848360,0.020130,0.000900,0.022869,51.146172,2.605510,0.228687,-31.848360,0.023987,0.000000
44.270000,11.697334,-31.892841,0.020156,0.000914,0.023207,52.032341,2.650654,0.232067,-31.892841,0.024369,0.000000
44.500004,11.869370,-31.848360,0.020174,0.000929,0.023588,52.797592,2.689637,0.235882,-31.848360,0.024751,0.000000
44.730003,12.232803,-31.848360,0.020217,0.000945,0.023996,54.414227,2.771993,0.239959,-31.848360,0.025132,0.000000
44.960003,12.289780,-31.848360,0.020221,0.000954,0.024221,54.667671,2.784904,0.242214,-31.848360,0.025514,0.000000
45.190002,12.442451,-31.848360,0.020251,0.000967,0.024560,55.346786,2.819500,0.245598,-31.848360,0.025904,0.000000
45.420002,12.626030,-31.892841,0.020234,0.000977,0.024811,56.163387,2.861099,0.248111,-31.892841,0.026285,0.000000
45.650002,13.598671,-31.892841,0.020256,0.001013,0.025722,60.489910,3.081503,0.257218,-31.892841,0.026667,0.000000
45.880001,13.414719,-31.848360,0.020286,0.001022,0.025964,59.671650,3.039819,0.259644,-31.848360,0.027049,0.000000
46.110001,13.615425,-31.848360,0.020286,0.001038,0.026355,60.564434,3.085299,0.263550,-31.848360,0.027430,0.000000
46.340004,13.798630,-31.892841,0.020303,0.001049,0.026650,61.379372,3.126814,0.266498,-31.892841,0.027820,0.000000
46.570004,14.240639,-31.848360,0.020329,0.001067,0.027109,63.345524,3.226975,0.271093,-31.848360,0.028202,0.000000
46.800003,14.357933,-31.848360,0.020320,0.001080,0.027439,63.867275,3.253554,0.274390,-31.848360,0.028584,0.000000
47.030003,14.626419,-31.848360,0.020355,0.001094,0.027794,65.061562,3.314394,0.277944,-31.848360,0.028965,0.000000
47.260002,14.928406,-31.848360,0.020368,0.001112,0.028237,66.404869,3.382825,0.282368,-31.848360,0.029347,0.000000
47.490002,15.454575,-31.892841,0.020398,0.001130,0.028696,68.745384,3.502057,0.286963,-31.892841,0.029737,0.000000
47.720001,15.618042,-31.892841,0.020398,0.001144,0.029069,69.472519,3.539099,0.290691,-31.892841,0.030119,0.000000
47.950001,15.622139,-31.892841,0.020402,0.001153,0.029295,69.490746,3.540027,0.292947,-31.892841,0.030500,0.000000
48.180004,16.000473,-31.848360,0.020419,0.001171,0.029745,71.173660,3.625759,0.297455,-31.848360,0.030882,0.000000
48.410004,16.531097,-31.892841,0.020445,0.001192,0.030275,73.533997,3.746000,0.302746,-31.892841,0.031263,0.000000
48.640003,16.519554,-31.937323,0.020432,0.001200,0.030483,73.482643,3.743385,0.304828,-31.937323,0.031653,0.000000
48.870003,16.616005,-31.892841,0.020450,0.001213,0.030804,73.911682,3.765240,0.308037,-31.892841,0.032035,0.000000
49.100002,16.828255,-31.892841,0.020484,0.001222,0.031038,74.855812,3.813337,0.310377,-31.892841,0.032417,0.000000
49.330002,17.275475,-31.848360,0.020488,0.001241,0.031515,76.845146,3.914678,0.315149,-31.848360,0.032798,0.000000
49.560001,18.169167,-31.892841,0.020493,0.001267,0.032191,80.820488,4.117192,0.321913,-31.892841,0.033189,0.000000
49.790001,18.167305,-31.848360,0.020531,0.001279,0.032486,80.812210,4.116770,0.324861,-31.848360,0.033570,0.000000
50.020004,18.338966,-31.892841,0.020549,0.001291,0.032798,81.575798,4.155669,0.327984,-31.892841,0.033952,0.000000
50.250004,18.529999,-31.892841,0.020536,0.001303,0.033102,82.425552,4.198958,0.331019,-31.892841,0.034333,0.000000
50.480003,19.082970,-31.848360,0.020579,0.001320,0.033535,84.885292,4.324263,0.335353,-31.848360,0.034715,0.000000
50.710003,19.303040,-31.937323,0.020600,0.001336,0.033934,85.864212,4.374131,0.339342,-31.937323,0.035105,0.000000
50.940002,19.607643,-31.892841,0.020592,0.001349,0.034273,87.219154,4.443155,0.342726,-31.892841,0.035487,0.000000
51.170002,19.938683,-31.892841,0.020605,0.001363,0.034628,88.691689,4.518170,0.346280,-31.892841,0.035868,0.000000
51.400002,20.708748,-31.848360,0.020626,0.001388,0.035261,92.117111,4.692669,0.352612,-31.848360,0.036250,0.000000
51.630001,20.646561,-31.892841,0.020652,0.001397,0.035487,91.840492,4.678577,0.354868,-31.892841,0.036631,0.000000
51.860001,20.802216,-31.892841,0.020656,0.001409,0.035782,92.532875,4.713850,0.357816,-31.892841,0.037022,0.000000
52.090004,21.300446,-31.937323,0.020656,0.001429,0.036285,94.749115,4.826750,0.362847,-31.937323,0.037403,0.000000
52.320004,21.415886,-31.892841,0.020678,0.001439,0.036545,95.262619,4.852909,0.365447,-31.892841,0.037785,0.000000
52.550003,21.860497,-31.892841,0.020704,0.001452,0.036874,97.240349,4.953660,0.368743,-31.892841,0.038167,0.000000
52.780003,22.347557,-31.892841,0.020725,0.001467,0.037256,99.406898,5.064029,0.372559,-31.892841,0.038548,0.000000
53.010002,22.652534,-31.892841,0.020734,0.001482,0.037637,100.763504,5.133138,0.376374,-31.892841,0.038938,0.000000
53.240002,23.278862,-31.937323,0.020734,0.001499,0.038080,103.549553,5.275065,0.380798,-31.937323,0.039320,0.000000
53.470001,23.988228,-31.892841,0.020782,0.001523,0.038687,106.704964,5.435811,0.386869,-31.892841,0.039701,0.000000
53.700001,24.064568,-31.937323,0.020782,0.001535,0.038999,107.044540,5.453109,0.389988,-31.937323,0.040083,0.000000
53.930004,24.265274,-31.937323,0.020786,0.001546,0.039259,107.937332,5.498590,0.392592,-31.937323,0.040465,0.000000
54.160004,24.513649,-31.892841,0.020794,0.001558,0.039571,109.042160,5.554873,0.395715,-31.892841,0.040855,0.000000
54.390003,25.443092,-31.937323,0.020816,0.001578,0.040091,113.176529,5.765487,0.400915,-31.937323,0.041236,0.000000
54.620003,25.745461,-31.892841,0.020816,0.001593,0.040465,114.521530,5.834005,0.404647,-31.892841,0.041618,0.000000
54.850002,25.922333,-31.892841,0.020850,0.001602,0.040682,115.308296,5.874085,0.406816,-31.892841,0.041999,0.000000
55.080002,26.502121,-31.937323,0.020855,0.001623,0.041219,117.887321,6.005466,0.412190,-31.937323,0.042381,0.000000
55.310001,27.341072,-31.937323,0.020876,0.001639,0.041635,121.619164,6.195575,0.416354,-31.937323,0.042772,0.000000
55.540001,27.688866,-31.892841,0.020885,0.001655,0.042043,123.166229,6.274386,0.420430,-31.892841,0.043153,0.000000
55.770004,28.268280,-31.892841,0.020919,0.001672,0.042459,125.743591,6.405684,0.424593,-31.892841,0.043535,0.000000
56.000004,28.397118,-31.937323,0.020902,0.001681,0.042702,126.316689,6.434879,0.427019,-31.937323,0.043916,0.000000
56.230003,29.177238,-31.937323,0.020902,0.001701,0.043205,129.786835,6.611657,0.432050,-31.937323,0.044298,0.000000
56.460003,29.729095,-31.937323,0.020937,0.001716,0.043595,132.241623,6.736709,0.435952,-31.937323,0.044688,0.000000
56.690002,29.742874,-31.937323,0.020932,0.001726,0.043829,132.302917,6.739831,0.438295,-31.937323,0.045069,0.000000
56.920002,30.268295,-31.892841,0.020950,0.001738,0.044133,134.640106,6.858893,0.441330,-31.892841,0.045451,0.000000
57.150002,31.129959,-31.981804,0.020954,0.001759,0.044688,138.472977,7.054150,0.446879,-31.981804,0.045833,0.000000
57.380001,31.990143,-31.981804,0.020984,0.001777,0.045139,142.299255,7.249070,0.451390,-31.981804,0.046214,0.000000
57.610004,32.092918,-31.892841,0.020993,0.001788,0.045416,142.756424,7.272359,0.454165,-31.892841,0.046605,0.000000
57.840004,32.621689,-31.892841,0.021001,0.001805,0.045842,145.108521,7.392180,0.458415,-31.892841,0.046986,0.000000
58.070004,33.192162,-31.981804,0.020997,0.001817,0.046162,147.646103,7.521451,0.461621,-31.981804,0.047368,0.000000
58.300003,34.013985,-31.937323,0.021027,0.001836,0.046622,151.301758,7.707679,0.466220,-31.937323,0.047749,0.000000
58.530003,34.455994,-31.937323,0.021057,0.001848,0.046951,153.267914,7.807840,0.469512,-31.937323,0.048140,0.000000
58.760002,34.635849,-31.937323,0.021045,0.001856,0.047151,154.067947,7.848596,0.471507,-31.937323,0.048521,0.000000
58.990002,35.803612,-31.892841,0.021066,0.001878,0.047706,159.262421,8.113214,0.477060,-31.892841,0.048903,0.000000
59.220001,36.425842,-31.892841,0.021088,0.001895,0.048122,162.030243,8.254213,0.481223,-31.892841,0.049284,0.000000
59.450005,37.009727,-31.981804,0.021088,0.001908,0.048460,164.627487,8.386524,0.484603,-31.981804,0.049666,0.000000
59.680004,37.630844,-31.981804,0.021083,0.001924,0.048868,167.390350,8.527271,0.488679,-31.981804,0.050056,0.000000
59.910004,38.132423,-31.937323,0.021096,0.001938,0.049224,169.621490,8.640930,0.492237,-31.937323,0.050438,0.000000
60.140003,39.280083,-31.937323,0.021113,0.001960,0.049779,174.726532,8.900994,0.497786,-31.937323,0.050819,0.000000
60.370003,39.634949,-31.937323,0.021139,0.001970,0.050039,176.305054,8.981408,0.500386,-31.937323,0.051201,0.000000
60.600002,39.615585,-31.981804,0.021144,0.001975,0.050177,176.218918,8.977020,0.501775,-31.981804,0.051582,0.000000
60.830002,41.106567,-31.937323,0.021144,0.002002,0.050854,182.851151,9.314881,0.508538,-31.937323,0.051973,0.000000
61.060001,41.509842,-32.026283,0.021157,0.002014,0.051157,184.645004,9.406265,0.511574,-32.026283,0.052354,0.000000
61.290005,42.580788,-31.892841,0.021174,0.002033,0.051643,189.408798,9.648945,0.516430,-31.892841,0.052736,0.000000
61.520004,42.715584,-31.981804,0.021165,0.002041,0.051851,190.008408,9.679490,0.518512,-31.981804,0.053117,0.000000
61.750004,43.557518,-31.981804,0.021204,0.002059,0.052294,193.753510,9.870275,0.522936,-31.981804,0.053499,0.000000
61.980003,44.162254,-31.981804,0.021226,0.002071,0.052597,196.443512,10.007310,0.525972,-31.981804,0.053889,0.000000
62.210003,45.139359,-31.981804,0.021187,0.002090,0.053074,200.789902,10.228724,0.530741,-31.981804,0.054271,0.000000
62.440002,45.783936,-31.892841,0.021243,0.002104,0.053438,203.657120,10.374788,0.534382,-31.892841,0.054652,0.000000
62.670002,46.136948,-31.937323,0.021230,0.002115,0.053716,205.227386,10.454782,0.537156,-31.937323,0.055034,0.000000
62.900002,47.852837,-32.026283,0.021226,0.002140,0.054349,212.860046,10.843608,0.543488,-32.026283,0.055415,0.000000
63.130005,48.713020,-32.026283,0.021260,0.002157,0.054800,216.686340,11.038528,0.548000,-32.026283,0.055806,0.000000
63.360004,48.971443,-31.981804,0.021247,0.002165,0.054999,217.835861,11.097088,0.549994,-31.981804,0.056188,0.000000
63.590004,49.680817,-31.892841,0.021264,0.002184,0.055468,220.991302,11.257834,0.554676,-31.892841,0.056569,0.000000
63.820004,50.320923,-31.937323,0.021290,0.002195,0.055762,223.838638,11.402884,0.557625,-31.937323,0.056951,0.000000
64.050003,51.337875,-32.026283,0.021290,0.002213,0.056213,228.362274,11.633329,0.562133,-32.026283,0.057332,0.000000
64.280006,52.062134,-31.981804,0.021273,0.002228,0.056586,231.583939,11.797448,0.565865,-31.981804,0.057722,0.000000
64.510002,52.478821,-32.026283,0.021299,0.002236,0.056803,233.437454,11.891870,0.568029,-32.026283,0.058104,0.000000
64.740005,53.166962,-32.026283,0.021312,0.002252,0.057202,236.498459,12.047806,0.572019,-32.026283,0.058486,0.000000
64.970001,54.956963,-31.981804,0.021329,0.002277,0.057844,244.460785,12.453425,0.578438,-31.981804,0.058867,0.000000
65.200005,55.572121,-32.026283,0.021312,0.002288,0.058121,247.197144,12.592822,0.581212,-32.026283,0.059249,0.000000
65.430000,56.221909,-31.981804,0.021333,0.002303,0.058486,250.087540,12.740067,0.584857,-31.981804,0.059639,0.000000
65.660004,56.843773,-31.892841,0.021320,0.002315,0.058798,252.853729,12.880982,0.587976,-31.892841,0.060020,0.000000
65.889999,57.616447,-31.937323,0.021303,0.002328,0.059136,256.290771,13.056073,0.591360,-31.937323,0.060402,0.000000
66.120003,58.614777,-31.981804,0.021346,0.002346,0.059587,260.731537,13.282298,0.595867,-31.981804,0.060784,0.000000
66.350006,58.845642,-32.026283,0.021338,0.002354,0.059804,261.758484,13.334613,0.598036,-32.026283,0.061165,0.000000
66.580002,59.679016,-32.026283,0.021351,0.002367,0.060116,265.465515,13.523458,0.601159,-32.026283,0.061556,0.000000
66.810005,60.771553,-31.981804,0.021355,0.002387,0.060619,270.325378,13.771030,0.606189,-31.981804,0.061937,0.000000
67.040001,62.835991,-32.026283,0.021368,0.002413,0.061295,279.508453,14.238839,0.612952,-32.026283,0.062319,0.000000
67.270004,63.246346,-31.937323,0.021377,0.002423,0.061547,281.333801,14.331826,0.615469,-31.937323,0.062700,0.000000
67.500000,63.986992,-32.070766,0.021381,0.002436,0.061885,284.628357,14.499660,0.618849,-32.070766,0.063090,0.000000
67.730003,64.688911,-32.026283,0.021377,0.002453,0.062310,287.750641,14.658716,0.623100,-32.026283,0.063472,0.000000
67.960007,65.838051,-32.026283,0.021394,0.002467,0.062657,292.862274,14.919115,0.626570,-32.026283,0.063854,0.000000
68.190002,66.566048,-32.026283,0.021394,0.002479,0.062969,296.100555,15.084082,0.629689,-32.026283,0.064235,0.000000
68.420006,67.382286,-31.981804,0.021411,0.002493,0.063316,299.731384,15.269045,0.633160,-31.981804,0.064617,0.000000
68.650002,67.458992,-32.070766,0.021402,0.002488,0.063186,300.072571,15.286427,0.631858,-32.070766,0.063498,0.000000
68.880005,67.104500,-31.981804,0.021394,0.002488,0.063186,298.495728,15.206097,0.631858,-31.981804,0.063498,0.000000
69.110001,66.808830,-31.937323,0.021398,0.002481,0.063012,297.180511,15.139097,0.630124,-31.937323,0.063186,0.000000
69.340004,66.573860,-32.070766,0.021428,0.002480,0.062986,296.135315,15.085853,0.629863,-32.070766,0.063186,0.000000
69.570000,66.351936,-32.070766,0.021428,0.002479,0.062978,295.148163,15.035564,0.629776,-32.070766,0.063186,0.000000
69.800003,66.159035,-32.026283,0.021407,0.002479,0.062978,294.290070,14.991852,0.629776,-32.026283,0.063186,0.000000
70.030006,65.997063,-31.981804,0.021437,0.002479,0.062978,293.569611,14.955149,0.629776,-31.981804,0.063186,0.000000
70.260002,65.841042,-31.981804,0.021420,0.002479,0.062978,292.875580,14.919793,0.629776,-31.981804,0.063186,0.000000
70.490005,65.718529,-31.981804,0.021424,0.002479,0.062969,292.330627,14.892032,0.629689,-31.981804,0.063186,0.000000
70.720001,65.595634,-32.026283,0.021433,0.002479,0.062969,291.783966,14.864182,0.629689,-32.026283,0.063186,0.000000
70.950005,65.472755,-32.026283,0.021402,0.002479,0.062969,291.237366,14.836338,0.629689,-32.026283,0.063186,0.000000
71.180000,65.360680,-31.981804,0.021441,0.002479,0.062969,290.738831,14.810942,0.629689,-31.981804,0.063186,0.000000
71.410004,65.273918,-31.981804,0.021437,0.002479,0.062969,290.352875,14.791282,0.629689,-31.981804,0.063186,0.000000
71.640007,65.169640,-32.026283,0.021433,0.002479,0.062969,289.889038,14.767652,0.629689,-32.026283,0.063186,0.000000
71.870003,65.076180,-32.026283,0.021441,0.002479,0.062969,289.473297,14.746473,0.629689,-32.026283,0.063186,0.000000
72.100006,65.005806,-32.026283,0.021424,0.002479,0.062969,289.160278,14.730526,0.629689,-32.026283,0.063186,0.000000
72.330002,64.931328,-32.026283,0.021433,0.002479,0.062969,288.828979,14.713649,0.629689,-32.026283,0.063186,0.000000
72.560005,64.849785,-31.981804,0.021411,0.002479,0.062969,288.466248,14.695170,0.629689,-31.981804,0.063186,0.000000
72.790001,64.763390,-32.026283,0.021433,0.002479,0.062969,288.081940,14.675594,0.629689,-32.026283,0.063186,0.000000
73.020004,64.705299,-32.026283,0.021415,0.002479,0.062969,287.823547,14.662431,0.629689,-32.026283,0.063186,0.000000
73.250000,64.657631,-32.026283,0.021428,0.002479,0.062969,287.611511,14.651628,0.629689,-32.026283,0.063186,0.000000
73.480003,64.579430,-31.937323,0.021411,0.002479,0.062969,287.263641,14.633908,0.629689,-31.937323,0.063186,0.000000
73.710007,64.535500,-31.981804,0.021433,0.002479,0.062969,287.068237,14.623954,0.629689,-31.981804,0.063186,0.000000
73.940002,64.470711,-32.070766,0.021437,0.002479,0.062969,286.780029,14.609272,0.629689,-32.070766,0.063186,0.000000
74.170006,64.419685,-32.026283,0.021407,0.002479,0.062969,286.553070,14.597710,0.629689,-32.026283,0.063186,0.000000
74.400002,64.375755,-32.026283,0.021433,0.002479,0.062969,286.357666,14.587755,0.629689,-32.026283,0.063186,0.000000
74.630005,64.319527,-31.981804,0.021454,0.002479,0.062969,286.107544,14.575013,0.629689,-31.981804,0.063186,0.000000
74.860001,64.266640,-32.070766,0.021437,0.002479,0.062969,285.872284,14.563028,0.629689,-32.070766,0.063186,0.000000
75.090004,64.222710,-32.070766,0.021424,0.002479,0.062969,285.676880,14.553074,0.629689,-32.070766,0.063186,0.000000
75.320007,64.156425,-32.026283,0.021454,0.002479,0.062969,285.382019,14.538054,0.629689,-32.026283,0.063186,0.000000
75.550003,64.132210,-32.070766,0.021433,0.002479,0.062969,285.274323,14.532567,0.629689,-32.070766,0.063186,0.000000
75.780006,64.082314,-31.981804,0.021441,0.002479,0.062969,285.052368,14.521259,0.629689,-31.981804,0.063186,0.000000
76.010002,64.040611,-32.115246,0.021450,0.002479,0.062969,284.866852,14.511809,0.629689,-32.115246,0.063186,0.000000
76.240005,64.004860,-32.070766,0.021428,0.002479,0.062969,284.707825,14.503708,0.629689,-32.070766,0.063186,0.000000
76.470001,63.969124,-32.115246,0.021424,0.002479,0.062969,284.548889,14.495611,0.629689,-32.115246,0.063186,0.000000
76.700005,63.916618,-32.026283,0.021424,0.002479,0.062969,284.315308,14.483713,0.629689,-32.026283,0.063186,0.000000
76.930000,63.880119,-32.026283,0.021471,0.002479,0.062969,284.152954,14.475442,0.629689,-32.026283,0.063186,0.000000
77.160004,63.850334,-32.070766,0.021407,0.002479,0.062969,284.020477,14.468693,0.629689,-32.070766,0.063186,0.000000
77.390007,63.813469,-32.159729,0.021433,0.002479,0.062969,283.856476,14.460339,0.629689,-32.159729,0.063186,0.000000
77.620003,63.788887,-32.026283,0.021420,0.002479,0.062969,283.747131,14.454768,0.629689,-32.026283,0.063186,0.000000
77.850006,63.740486,-32.026283,0.021437,0.002479,0.062969,283.531830,14.443801,0.629689,-32.026283,0.063186,0.000000
78.080002,63.721855,-32.070766,0.021428,0.002479,0.062969,283.448975,14.439578,0.629689,-32.070766,0.063186,0.000000
78.310005,63.689095,-32.070766,0.021441,0.002479,0.062969,283.303253,14.432155,0.629689,-32.070766,0.063186,0.000000
78.540001,63.649254,-32.115246,0.021437,0.002479,0.062969,283.126007,14.423127,0.629689,-32.115246,0.063186,0.000000
78.770004,63.617973,-32.070766,0.021437,0.002479,0.062969,282.986877,14.416039,0.629689,-32.070766,0.063186,0.000000
79.000000,63.598610,-32.026283,0.021420,0.002479,0.062969,282.900757,14.411652,0.629689,-32.026283,0.063186,0.000000
79.230003,63.563606,-32.026283,0.021428,0.002479,0.062969,282.745056,14.403719,0.629689,-32.026283,0.063186,0.000000
79.460007,63.543861,-32.070766,0.021450,0.002479,0.062969,282.657227,14.399244,0.629689,-32.070766,0.063186,0.000000
79.690002,63.515938,-32.070766,0.021428,0.002479,0.062969,282.532990,14.392917,0.629689,-32.070766,0.063186,0.000000
79.920006,63.476463,-32.026283,0.021441,0.002479,0.062969,282.357422,14.383972,0.629689,-32.026283,0.063186,0.000000
80.150002,63.460091,-32.070766,0.021441,0.002479,0.062969,282.284576,14.380262,0.629689,-32.070766,0.063186,0.000000
80.380005,63.420982,-32.026283,0.021433,0.002479,0.062969,282.110626,14.371400,0.629689,-32.026283,0.063186,0.000000
80.610001,63.397148,-32.070766,0.021437,0.002479,0.062969,282.004608,14.365998,0.629689,-32.070766,0.063186,0.000000
80.840004,63.379280,-32.070766,0.021441,0.002479,0.062969,281.925110,14.361951,0.629689,-32.070766,0.063186,0.000000
81.070007,63.349113,-32.115246,0.021441,0.002479,0.062969,281.790924,14.355115,0.629689,-32.115246,0.063186,0.000000
81.300003,63.332359,-32.115246,0.021445,0.002479,0.062969,281.716400,14.351318,0.629689,-32.115246,0.063186,0.000000
81.530006,63.320824,-32.115246,0.021437,0.002479,0.062969,281.665100,14.348704,0.629689,-32.115246,0.063186,0.000000
81.760002,63.279854,-32.159729,0.021445,0.002479,0.062969,281.482849,14.339419,0.629689,-32.159729,0.063186,0.000000
81.990005,63.260490,-32.115246,0.021437,0.002479,0.062969,281.396729,14.335032,0.629689,-32.115246,0.063186,0.000000
82.220001,63.239647,-32.070766,0.021441,0.002479,0.062969,281.303986,14.330309,0.629689,-32.070766,0.063186,0.000000
82.450005,63.202400,-32.070766,0.021437,0.002479,0.062969,281.138306,14.321869,0.629689,-32.070766,0.063186,0.000000
82.680000,63.213570,-32.115246,0.021454,0.002479,0.062969,281.187988,14.324400,0.629689,-32.115246,0.063186,0.000000
82.910004,63.179314,-32.115246,0.021420,0.002479,0.062969,281.035614,14.316637,0.629689,-32.115246,0.063186,0.000000
83.140007,63.158089,-32.115246,0.021433,0.002479,0.062969,280.941223,14.311828,0.629689,-32.115246,0.063186,0.000000
83.370003,63.145805,-32.070766,0.021445,0.002479,0.062969,280.886566,14.309044,0.629689,-32.070766,0.063186,0.000000
83.600006,63.124207,-32.115246,0.021437,0.002479,0.062969,280.790497,14.304150,0.629689,-32.115246,0.063186,0.000000
83.830002,63.092178,-32.159729,0.021428,0.002479,0.062969,280.648041,14.296892,0.629689,-32.159729,0.063186,0.000000
84.060005,63.070580,-32.159729,0.021437,0.002479,0.062969,280.551941,14.291998,0.629689,-32.159729,0.063186,0.000000
84.290001,63.040794,-32.115246,0.021437,0.002479,0.062969,280.419464,14.285248,0.629689,-32.115246,0.063186,0.000000
84.520004,63.033722,-32.115246,0.021450,0.002479,0.062969,280.388000,14.283646,0.629689,-32.115246,0.063186,0.000000
84.750008,63.021057,-32.070766,0.021450,0.002479,0.062969,280.331665,14.280776,0.629689,-32.070766,0.063186,0.000000
84.980003,62.990898,-32.115246,0.021450,0.002479,0.062969,280.197510,14.273942,0.629689,-32.115246,0.063186,0.000000
85.210007,62.975998,-32.115246,0.021420,0.002479,0.062969,280.131226,14.270565,0.629689,-32.115246,0.063186,0.000000
85.440002,62.959991,-32.115246,0.021437,0.002479,0.062969,280.060028,14.266937,0.629689,-32.115246,0.063186,0.000000
85.670006,62.950310,-32.115246,0.021445,0.002479,0.062969,280.016968,14.264745,0.629689,-32.115246,0.063186,0.000000
85.900002,62.933174,-32.026283,0.021428,0.002479,0.062969,279.940735,14.260860,0.629689,-32.026283,0.063186,0.000000
86.130005,62.900040,-32.204208,0.021454,0.002479,0.062969,279.793365,14.253353,0.629689,-32.204208,0.063186,0.000000
86.360001,62.893333,-32.159729,0.021424,0.002479,0.062969,279.763519,14.251833,0.629689,-32.159729,0.063186,0.000000
86.590004,62.867638,-32.115246,0.021437,0.002479,0.062969,279.649231,14.246010,0.629689,-32.115246,0.063186,0.000000
86.820007,62.852371,-32.115246,0.021437,0.002479,0.062969,279.581299,14.242551,0.629689,-32.115246,0.063186,0.000000
87.050003,62.839340,-32.115246,0.021458,0.002479,0.062969,279.523346,14.239598,0.629689,-32.115246,0.063186,0.000000
87.280006,62.830406,-32.204208,0.021445,0.002479,0.062969,279.483612,14.237574,0.629689,-32.204208,0.063186,0.000000
87.510002,62.810295,-32.070766,0.021437,0.002479,0.062969,279.394135,14.233016,0.629689,-32.070766,0.063186,0.000000
87.740005,62.810669,-32.070766,0.021433,0.002479,0.062969,279.395813,14.233101,0.629689,-32.070766,0.063186,0.000000
87.970001,62.782738,-32.070766,0.021445,0.002479,0.062969,279.271576,14.226772,0.629689,-32.070766,0.063186,0.000000
88.200005,62.765984,-32.159729,0.021458,0.002479,0.062969,279.197052,14.222976,0.629689,-32.159729,0.063186,0.000000
88.430008,62.765984,-32.204208,0.021441,0.002479,0.062969,279.197052,14.222976,0.629689,-32.204208,0.063186,0.000000
88.660004,62.735077,-32.159729,0.021424,0.002479,0.062969,279.059570,14.215971,0.629689,-32.159729,0.063186,0.000000
88.890007,62.721672,-32.115246,0.021441,0.002479,0.062969,278.999939,14.212934,0.629689,-32.115246,0.063186,0.000000
89.120003,62.708267,-32.115246,0.021476,0.002479,0.062969,278.940308,14.209896,0.629689,-32.115246,0.063186,0.000000
89.350006,62.684807,-32.115246,0.021445,0.002479,0.062969,278.835937,14.204580,0.629689,-32.115246,0.063186,0.000000
89.580002,62.686668,-32.204208,0.021433,0.002479,0.062969,278.844238,14.205002,0.629689,-32.204208,0.063186,0.000000
89.810005,62.667305,-32.159729,0.021437,0.002479,0.062969,278.758087,14.200614,0.629689,-32.159729,0.063186,0.000000
90.040001,62.644592,-32.115246,0.021424,0.002479,0.062969,278.657074,14.195468,0.629689,-32.115246,0.063186,0.000000
90.270004,62.650543,-32.115246,0.021433,0.002479,0.062969,278.683533,14.196816,0.629689,-32.115246,0.063186,0.000000
90.500008,62.629318,-32.204208,0.021454,0.002479,0.062969,278.589111,14.192006,0.629689,-32.204208,0.063186,0.000000
90.730003,62.611824,-32.204208,0.021433,0.002479,0.062969,278.511292,14.188042,0.629689,-32.204208,0.063186,0.000000
90.960007,62.594688,-32.115246,0.021437,0.002479,0.062969,278.435089,14.184159,0.629689,-32.115246,0.063186,0.000000
91.190002,62.595810,-32.115246,0.021458,0.002479,0.062969,278.440063,14.184413,0.629689,-32.115246,0.063186,0.000000
91.420006,62.562294,-32.204208,0.021441,0.002479,0.062969,278.290985,14.176818,0.629689,-32.204208,0.063186,0.000000
91.650002,62.550377,-32.204208,0.021441,0.002479,0.062969,278.237976,14.174118,0.629689,-32.204208,0.063186,0.000000
91.880005,62.536232,-32.204208,0.021420,0.002479,0.062969,278.175049,14.170913,0.629689,-32.204208,0.063186,0.000000
92.110001,62.529900,-32.115246,0.021437,0.002479,0.062969,278.146881,14.169478,0.629689,-32.115246,0.063186,0.000000
92.340004,62.515747,-32.159729,0.021428,0.002479,0.062969,278.083923,14.166271,0.629689,-32.159729,0.063186,0.000000
92.570007,62.494522,-32.159729,0.021441,0.002479,0.062969,277.989532,14.161461,0.629689,-32.159729,0.063186,0.000000
92.800003,62.479256,-32.204208,0.021424,0.002479,0.062969,277.921600,14.158001,0.629689,-32.204208,0.063186,0.000000
93.030006,62.478508,-32.204208,0.021450,0.002479,0.062969,277.918274,14.157832,0.629689,-32.204208,0.063186,0.000000
93.260002,62.465851,-32.159729,0.021445,0.002479,0.062969,277.861969,14.154964,0.629689,-32.159729,0.063186,0.000000
93.490005,62.462502,-32.115246,0.021420,0.002479,0.062969,277.847076,14.154205,0.629689,-32.115246,0.063186,0.000000
93.720001,62.437553,-32.204208,0.021441,0.002479,0.062969,277.736115,14.148552,0.629689,-32.204208,0.063186,0.000000
93.950005,62.423775,-32.159729,0.021454,0.002479,0.062969,277.674805,14.145430,0.629689,-32.159729,0.063186,0.000000
94.180008,62.408508,-32.248688,0.021433,0.002479,0.062969,277.606903,14.141971,0.629689,-32.248688,0.063186,0.000000
94.410004,62.399193,-32.159729,0.021441,0.002479,0.062969,277.565460,14.139859,0.629689,-32.159729,0.063186,0.000000
94.640007,62.395096,-32.204208,0.021454,0.002479,0.062969,277.547241,14.138931,0.629689,-32.204208,0.063186,0.000000
94.870003,62.379089,-32.204208,0.021463,0.002479,0.062969,277.476044,14.135303,0.629689,-32.204208,0.063186,0.000000
95.100006,62.362701,-32.248688,0.021402,0.002479,0.062969,277.403137,14.131591,0.629689,-32.248688,0.063186,0.000000
95.330002,62.351532,-32.204208,0.021437,0.002479,0.062969,277.353455,14.129059,0.629689,-32.204208,0.063186,0.000000
95.560005,62.344826,-32.159729,0.021445,0.002479,0.062969,277.323639,14.127540,0.629689,-32.159729,0.063186,0.000000
95.790001,62.328445,-32.159729,0.021441,0.002479,0.062969,277.250763,14.123827,0.629689,-32.159729,0.063186,0.000000
96.020004,62.330307,-32.293171,0.021433,0.002479,0.062969,277.259064,14.124249,0.629689,-32.293171,0.063186,0.000000
96.250008,62.307968,-32.204208,0.021437,0.002479,0.062969,277.159698,14.119187,0.629689,-32.204208,0.063186,0.000000
96.480003,62.299774,-32.159729,0.021441,0.002479,0.062969,277.123230,14.117331,0.629689,-32.159729,0.063186,0.000000
96.710007,62.304985,-32.204208,0.021454,0.002479,0.062969,277.146423,14.118511,0.629689,-32.204208,0.063186,0.000000
96.940002,62.285622,-32.159729,0.021454,0.002479,0.062969,277.060272,14.114123,0.629689,-32.159729,0.063186,0.000000
97.170006,62.260674,-32.248688,0.021450,0.002479,0.062969,276.949310,14.108470,0.629689,-32.248688,0.063186,0.000000
97.400002,62.266632,-32.248688,0.021428,0.002479,0.062969,276.975800,14.109820,0.629689,-32.248688,0.063186,0.000000
97.630005,62.251366,-32.204208,0.021441,0.002479,0.062969,276.907898,14.106361,0.629689,-32.204208,0.063186,0.000000
97.860008,62.226044,-32.159729,0.021437,0.002479,0.062969,276.795258,14.100623,0.629689,-32.159729,0.063186,0.000000
98.090004,62.220459,-32.159729,0.021454,0.002479,0.062969,276.770416,14.099358,0.629689,-32.159729,0.063186,0.000000
98.320007,62.226784,-32.204208,0.021441,0.002479,0.062969,276.798553,14.100791,0.629689,-32.204208,0.063186,0.000000
98.550003,62.210030,-32.248688,0.021433,0.002479,0.062969,276.724030,14.096994,0.629689,-32.248688,0.063186,0.000000
98.780006,62.190666,-32.248688,0.021433,0.002479,0.062969,276.637909,14.092607,0.629689,-32.248688,0.063186,0.000000
99.000008,62.185081,-32.204208,0.021437,0.002479,0.062969,276.613068,14.091341,0.629689,-32.204208,0.063186,0.000000