File: Data/I-18_1_3_07282023_141913.csv
Time (sec),S:Load (lbs),S:HL1 (DIM),S:LVDT (in),S:Position (in),Ch:Position (mm),Ch:Load (N),Ch:Stress (MPa),Ch:Strain (mm/mm),Ch:HL1 (DIM),Set Point (),Cycles ()
0.110000,0.001489,-18.593037,0.000004,-0.000000,-0.000000,0.006625,0.000338,-0.000000,-18.593037,-0.000000,0.000000
0.360000,-0.001490,-18.593037,0.000000,-0.000000,-0.000000,-0.006626,-0.000338,-0.000000,-18.593037,-0.000000,0.000000
0.610000,0.013405,-18.637518,0.000000,0.000123,0.003130,0.059630,0.003038,0.031301,-18.637518,0.003711,0.000000
0.860000,0.043195,-18.593037,0.000000,0.000271,0.006877,0.192142,0.009788,0.068772,-18.593037,0.007874,0.000000
1.110000,0.058462,-18.548557,0.000082,0.000432,0.010978,0.260054,0.013248,0.109785,-18.548557,0.012037,0.000000
1.360000,0.025321,-18.548557,0.000233,0.000596,0.015150,0.112635,0.005738,0.151502,-18.548557,0.016199,0.000000
1.610000,0.040589,-18.548557,0.000410,0.000761,0.019330,0.180547,0.009197,0.193302,-18.548557,0.020362,0.000000
1.860000,0.043940,-18.548557,0.000582,0.000925,0.023493,0.195455,0.009957,0.234928,-18.548557,0.024525,0.000000
2.110000,0.001117,-18.504076,0.000759,0.001088,0.027630,0.004969,0.000253,0.276297,-18.504076,0.028687,0.000000
2.360000,0.017129,-18.504076,0.000905,0.001247,0.031680,0.076194,0.003882,0.316796,-18.504076,0.032867,0.000000
2.610000,0.048781,-18.504076,0.001052,0.001414,0.035912,0.216988,0.011054,0.359118,-18.504076,0.037030,0.000000
2.860000,0.066282,-18.548557,0.001220,0.001577,0.040057,0.294838,0.015020,0.400571,-18.548557,0.041193,0.000000
3.110000,0.026811,-18.504076,0.001397,0.001744,0.044298,0.119260,0.006075,0.442977,-18.504076,0.045356,0.000000
3.360000,0.047291,-18.504076,0.001552,0.001907,0.048443,0.210362,0.010716,0.484429,-18.504076,0.049519,0.000000
3.610000,0.057345,-18.459595,0.001720,0.002064,0.052415,0.255085,0.012995,0.524147,-18.459595,0.053681,0.000000
3.860000,0.035748,-18.415113,0.001906,0.002236,0.056803,0.159014,0.008101,0.568029,-18.415113,0.057844,0.000000
4.110000,0.046547,-18.504076,0.002070,0.002395,0.060827,0.207049,0.010548,0.608270,-18.504076,0.062006,0.000000
4.360000,0.058090,-18.459595,0.002216,0.002562,0.065085,0.258398,0.013163,0.650851,-18.459595,0.066186,0.000000
4.610000,0.036120,-18.370632,0.002393,0.002730,0.069352,0.160670,0.008185,0.693521,-18.370632,0.070349,0.000000
4.860000,-0.000745,-18.370632,0.002544,0.002886,0.073307,-0.003313,-0.000169,0.733066,-18.370632,0.074512,0.000000
5.110000,0.055856,-18.459595,0.002721,0.003052,0.077521,0.248459,0.012657,0.775207,-18.459595,0.078674,0.000000
5.360000,0.075592,-18.415113,0.002871,0.003210,0.081527,0.336248,0.017129,0.815274,-18.415113,0.082837,0.000000
5.610000,0.052132,-18.370632,0.003044,0.003386,0.086011,0.231895,0.011813,0.860110,-18.370632,0.087000,0.000000
5.860000,0.073730,-18.459595,0.003208,0.003548,0.090122,0.327966,0.016707,0.901221,-18.459595,0.091162,0.000000
6.110000,0.080432,-18.326151,0.003380,0.003709,0.094215,0.357781,0.018226,0.942151,-18.326151,0.095342,0.000000
6.360000,0.066282,-18.370632,0.003544,0.003879,0.098516,0.294838,0.015020,0.985163,-18.370632,0.099505,0.000000
6.610000,0.026066,-18.370632,0.003708,0.004036,0.102523,0.115948,0.005907,1.025230,-18.370632,0.103668,0.000000
6.860000,0.066282,-18.415113,0.003872,0.004200,0.106677,0.294838,0.015020,1.066773,-18.415113,0.107831,0.000000
7.110000,0.075964,-18.370632,0.004036,0.004360,0.110735,0.337905,0.017214,1.107354,-18.370632,0.111994,0.000000
7.360000,0.055856,-18.370632,0.004212,0.004532,0.115106,0.248459,0.012657,1.151062,-18.370632,0.116156,0.000000
7.610000,0.071495,-18.326151,0.004363,0.004695,0.119261,0.318028,0.016201,1.192605,-18.326151,0.120319,0.000000
7.860001,0.081177,-18.326151,0.004518,0.004850,0.123198,0.361094,0.018395,1.231976,-18.326151,0.124481,0.000000
8.110001,0.078198,-18.370632,0.004708,0.005026,0.127664,0.347843,0.017720,1.276638,-18.370632,0.128661,0.000000
8.360001,0.067772,-18.370632,0.004863,0.005185,0.131688,0.301464,0.015357,1.316879,-18.370632,0.132824,0.000000
8.610001,0.074474,-18.281672,0.005040,0.005353,0.135955,0.331279,0.016876,1.359549,-18.281672,0.136987,0.000000
8.860001,0.061069,-18.237190,0.005195,0.005519,0.140186,0.271649,0.013838,1.401865,-18.237190,0.141149,0.000000
9.110001,0.016384,-18.281672,0.005364,0.005674,0.144124,0.072881,0.003713,1.441243,-18.281672,0.145312,0.000000
9.360001,0.090114,-18.281672,0.005532,0.005841,0.148356,0.400848,0.020420,1.483558,-18.281672,0.149475,0.000000
9.610001,0.106871,-18.237190,0.005674,0.005999,0.152380,0.475385,0.024217,1.523799,-18.237190,0.153637,0.000000
9.860001,0.081177,-18.237190,0.005864,0.006173,0.156803,0.361094,0.018395,1.568029,-18.237190,0.157800,0.000000
10.110001,0.100913,-18.237190,0.006023,0.006335,0.160913,0.448883,0.022867,1.609133,-18.237190,0.161980,0.000000
10.360001,0.090114,-18.237190,0.006183,0.006497,0.165024,0.400848,0.020420,1.650244,-18.237190,0.166143,0.000000
10.610001,0.071868,-18.192709,0.006355,0.006668,0.169369,0.319684,0.016285,1.693688,-18.192709,0.170305,0.000000
10.860001,0.029045,-18.148228,0.006510,0.006823,0.173306,0.129199,0.006582,1.733058,-18.148228,0.174469,0.000000
11.110001,0.081177,-18.192709,0.006683,0.006986,0.177452,0.361094,0.018395,1.774518,-18.192709,0.178631,0.000000
11.360001,0.094210,-18.192709,0.006851,0.007147,0.181536,0.419068,0.021348,1.815364,-18.192709,0.182794,0.000000
11.610001,0.105009,-18.148228,0.007011,0.007318,0.185872,0.467103,0.023795,1.858724,-18.148228,0.186956,0.000000
11.860001,0.077453,-18.192709,0.007174,0.007480,0.189992,0.344530,0.017551,1.899919,-18.192709,0.191136,0.000000
12.110001,0.102775,-18.148228,0.007355,0.007639,0.194042,0.457165,0.023289,1.940417,-18.148228,0.195299,0.000000
12.360001,0.096817,-18.148228,0.007511,0.007814,0.198481,0.430663,0.021939,1.984814,-18.148228,0.199462,0.000000
12.610001,0.075592,-18.103746,0.007670,0.007973,0.202523,0.336248,0.017129,2.025229,-18.103746,0.203624,0.000000
12.860001,0.094583,-18.103746,0.007825,0.008138,0.206703,0.420724,0.021433,2.067029,-18.103746,0.207787,0.000000
13.110001,0.070006,-18.059267,0.008006,0.008303,0.210900,0.311402,0.015864,2.109004,-18.059267,0.211950,0.000000
13.360001,0.065538,-18.148228,0.008162,0.008459,0.214863,0.291525,0.014851,2.148632,-18.148228,0.216112,0.000000
13.610001,0.099051,-18.103746,0.008343,0.008629,0.219173,0.440601,0.022445,2.191734,-18.103746,0.220275,0.000000
13.860001,0.114318,-18.059267,0.008511,0.008785,0.223145,0.508513,0.025905,2.231453,-18.059267,0.224455,0.000000
14.110001,0.121393,-18.059267,0.008675,0.008959,0.227551,0.539985,0.027508,2.275509,-18.059267,0.228617,0.000000
14.360001,0.099796,-18.059267,0.008852,0.009120,0.231653,0.443914,0.022614,2.316530,-18.059267,0.232780,0.000000
14.610001,0.088252,-18.014786,0.009020,0.009285,0.235850,0.392566,0.019998,2.358504,-18.014786,0.236943,0.000000
14.860001,0.081550,-18.059267,0.009179,0.009453,0.240100,0.362750,0.018479,2.401001,-18.059267,0.241106,0.000000
15.110001,0.056601,-18.014786,0.009343,0.009609,0.244080,0.251772,0.012826,2.440803,-18.014786,0.245269,0.000000
15.360001,0.086763,-18.014786,0.009503,0.009773,0.248235,0.385940,0.019661,2.482346,-18.014786,0.249431,0.000000
15.610001,0.132192,-18.014786,0.009671,0.009936,0.252371,0.588020,0.029955,2.523707,-18.014786,0.253594,0.000000
15.860001,0.105381,-17.970304,0.009826,0.010104,0.256646,0.468760,0.023880,2.566462,-17.970304,0.257774,0.000000
16.110001,0.072613,-17.925823,0.010020,0.010268,0.260810,0.322997,0.016454,2.608095,-17.925823,0.261937,0.000000
16.360001,0.100168,-17.970304,0.010179,0.010429,0.264903,0.445570,0.022698,2.649025,-17.970304,0.266099,0.000000
16.610001,0.115063,-17.925823,0.010335,0.010598,0.269186,0.511826,0.026074,2.691863,-17.925823,0.270262,0.000000
16.860001,0.079688,-17.970304,0.010494,0.010763,0.273375,0.354468,0.018057,2.733754,-17.970304,0.274425,0.000000
17.110001,0.097934,-17.925823,0.010662,0.010923,0.277443,0.435632,0.022192,2.774426,-17.925823,0.278587,0.000000
17.360001,0.094955,-17.881342,0.010822,0.011087,0.281605,0.422381,0.021517,2.816053,-17.881342,0.282750,0.000000
17.610001,0.084901,-17.881342,0.010999,0.011251,0.285785,0.377658,0.019239,2.857853,-17.881342,0.286930,0.000000
17.860001,0.101658,-17.881342,0.011154,0.011418,0.290018,0.452196,0.023036,2.900176,-17.881342,0.291092,0.000000
18.110001,0.116553,-17.836861,0.011322,0.011575,0.293998,0.518452,0.026411,2.939978,-17.836861,0.295255,0.000000
18.360001,0.131075,-17.881342,0.011477,0.011743,0.298265,0.583051,0.029702,2.982649,-17.881342,0.299418,0.000000
18.610001,0.123255,-17.881342,0.011645,0.011908,0.302471,0.548267,0.027930,3.024706,-17.881342,0.303581,0.000000
18.860001,0.099051,-17.792381,0.011809,0.012074,0.306685,0.440601,0.022445,3.066855,-17.792381,0.307744,0.000000
19.110001,0.128096,-17.747900,0.011943,0.012238,0.310856,0.569800,0.029027,3.108565,-17.747900,0.311906,0.000000
19.360001,0.106871,-17.792381,0.012150,0.012399,0.314924,0.475385,0.024217,3.149237,-17.792381,0.316069,0.000000
19.610001,0.082667,-17.792381,0.012314,0.012563,0.319104,0.367720,0.018733,3.191037,-17.792381,0.320249,0.000000
19.860001,0.156024,-17.747900,0.012490,0.012724,0.323197,0.694030,0.035356,3.231975,-17.747900,0.324412,0.000000
20.110001,0.130330,-17.792381,0.012672,0.012891,0.327430,0.579738,0.029533,3.274297,-17.792381,0.328574,0.000000
20.360001,0.086390,-17.747900,0.012848,0.013059,0.331688,0.384284,0.019576,3.316878,-17.747900,0.332737,0.000000
20.610001,0.116553,-17.792381,0.013025,0.013222,0.335850,0.518452,0.026411,3.358504,-17.792381,0.336900,0.000000
20.860001,0.136288,-17.747900,0.013172,0.013385,0.339978,0.606241,0.030883,3.399782,-17.747900,0.341062,0.000000
21.110001,0.086018,-17.703419,0.013361,0.013552,0.344210,0.382627,0.019492,3.442105,-17.703419,0.345225,0.000000
21.360001,0.095700,-17.703419,0.013525,0.013709,0.348208,0.425693,0.021686,3.482081,-17.703419,0.349405,0.000000
21.610001,0.128096,-17.703419,0.013676,0.013876,0.352458,0.569800,0.029027,3.524577,-17.703419,0.353567,0.000000
21.860001,0.093838,-17.703419,0.013874,0.014042,0.356673,0.417412,0.021264,3.566726,-17.703419,0.357730,0.000000
22.110001,0.106498,-17.658937,0.014021,0.014206,0.360844,0.473729,0.024133,3.608436,-17.658937,0.361893,0.000000
22.360001,0.123628,-17.614456,0.014189,0.014368,0.364937,0.549923,0.028014,3.649373,-17.614456,0.366055,0.000000
22.610001,0.130330,-17.658937,0.014357,0.014528,0.369022,0.579738,0.029533,3.690220,-17.658937,0.370219,0.000000
22.860001,0.114691,-17.658937,0.014538,0.014698,0.373341,0.510170,0.025989,3.733405,-17.658937,0.374381,0.000000
23.110001,0.115808,-17.658937,0.014702,0.014864,0.377546,0.515139,0.026242,3.775463,-17.658937,0.378544,0.000000
23.360001,0.149321,-17.525496,0.014849,0.015025,0.381631,0.664214,0.033837,3.816310,-17.525496,0.382724,0.000000
23.610001,0.113574,-17.614456,0.015013,0.015190,0.385820,0.505200,0.025736,3.858201,-17.614456,0.386887,0.000000
23.860001,0.067027,-17.525496,0.015189,0.015353,0.389956,0.298151,0.015189,3.899562,-17.525496,0.391049,0.000000
24.110001,0.140012,-17.569975,0.015345,0.015516,0.394101,0.622805,0.031727,3.941014,-17.569975,0.395212,0.000000
24.360001,0.140012,-17.525496,0.015530,0.015674,0.398126,0.622805,0.031727,3.981255,-17.525496,0.399375,0.000000
24.610001,0.092348,-17.569975,0.015707,0.015848,0.402540,0.410786,0.020926,4.025403,-17.569975,0.403537,0.000000
24.860001,0.123628,-17.525496,0.015884,0.016012,0.406694,0.549923,0.028014,4.066938,-17.525496,0.407700,0.000000
25.110001,0.137405,-17.525496,0.016056,0.016171,0.410744,0.611210,0.031137,4.107436,-17.525496,0.411862,0.000000
25.360001,0.124745,-17.481014,0.016224,0.016340,0.415036,0.554892,0.028268,4.150364,-17.481014,0.416042,0.000000
25.610001,0.090114,-17.436533,0.016384,0.016497,0.419035,0.400848,0.020420,4.190348,-17.436533,0.420205,0.000000
25.860001,0.138150,-17.436533,0.016561,0.016665,0.423284,0.614523,0.031305,4.232837,-17.436533,0.424368,0.000000
26.110001,0.109850,-17.436533,0.016707,0.016829,0.427446,0.488637,0.024892,4.274464,-17.436533,0.428530,0.000000
26.360001,0.105009,-17.392052,0.016888,0.016995,0.431661,0.467103,0.023795,4.316612,-17.392052,0.432693,0.000000
26.610001,0.134054,-17.436533,0.017052,0.017159,0.435833,0.596302,0.030377,4.358329,-17.436533,0.436856,0.000000
26.860001,0.145598,-17.392052,0.017216,0.017312,0.439727,0.647650,0.032993,4.397268,-17.392052,0.441019,0.000000
27.110001,0.151928,-17.347570,0.017380,0.017488,0.444201,0.675809,0.034427,4.442013,-17.347570,0.445199,0.000000
27.360001,0.131075,-17.392052,0.017552,0.017652,0.448356,0.583051,0.029702,4.483556,-17.392052,0.449362,0.000000
27.610001,0.149321,-17.303089,0.017712,0.017810,0.452371,0.664214,0.033837,4.523706,-17.303089,0.453524,0.000000
27.860001,0.128468,-17.347570,0.017871,0.017977,0.456611,0.571456,0.029111,4.566113,-17.347570,0.457687,0.000000
28.110001,0.069634,-17.347570,0.018026,0.018141,0.460774,0.309746,0.015779,4.607738,-17.347570,0.461850,0.000000
28.360001,0.172408,-17.303089,0.018199,0.018303,0.464893,0.766911,0.039068,4.648933,-17.303089,0.466012,0.000000
28.610001,0.157141,-17.347570,0.018346,0.018463,0.468961,0.698999,0.035609,4.689606,-17.347570,0.470175,0.000000
28.860001,0.136661,-17.258610,0.018509,0.018635,0.473323,0.607897,0.030968,4.733231,-17.258610,0.474337,0.000000
29.110001,0.143363,-17.214128,0.018686,0.018795,0.477390,0.637712,0.032487,4.773903,-17.214128,0.478517,0.000000
29.360001,0.168685,-17.258610,0.018872,0.018956,0.481492,0.750347,0.038224,4.814924,-17.258610,0.482680,0.000000
29.610001,0.134426,-17.258610,0.019053,0.019128,0.485846,0.597959,0.030461,4.858458,-17.258610,0.486843,0.000000
29.860001,0.093093,-17.214128,0.019238,0.019287,0.489896,0.414099,0.021095,4.898956,-17.214128,0.491005,0.000000
30.110001,0.142619,-17.169647,0.019432,0.019451,0.494067,0.634399,0.032318,4.940666,-17.169647,0.495168,0.000000
30.360001,0.124000,-17.169647,0.019626,0.019615,0.498229,0.551580,0.028099,4.982292,-17.169647,0.499331,0.000000
30.610001,0.134426,-17.169647,0.019798,0.019781,0.502427,0.597959,0.030461,5.024266,-17.169647,0.503494,0.000000
30.860001,0.117297,-17.125166,0.019988,0.019945,0.506607,0.521764,0.026580,5.066067,-17.125166,0.507657,0.000000
31.110001,0.146715,-17.214128,0.020174,0.020101,0.510553,0.652620,0.033246,5.105528,-17.214128,0.511837,0.000000
31.360001,0.142246,-17.169647,0.020346,0.020277,0.515045,0.632743,0.032233,5.150447,-17.169647,0.515999,0.000000
31.610001,0.112456,-17.125166,0.020527,0.020436,0.519086,0.500231,0.025483,5.190862,-17.125166,0.520162,0.000000
31.860001,0.121766,-17.080685,0.020687,0.020598,0.523180,0.541641,0.027593,5.231800,-17.080685,0.524325,0.000000
32.110001,0.115435,-17.125166,0.020842,0.020762,0.527360,0.513482,0.026158,5.273600,-17.125166,0.528487,0.000000
32.360001,0.054366,-17.080685,0.021032,0.020930,0.531618,0.241834,0.012320,5.316180,-17.080685,0.532650,0.000000
32.610001,0.142619,-16.991724,0.021182,0.021092,0.535737,0.634399,0.032318,5.357368,-16.991724,0.536812,0.000000
32.860001,0.151183,-17.036203,0.021368,0.021250,0.539761,0.672496,0.034259,5.397608,-17.036203,0.540992,0.000000
33.110001,0.152300,-16.991724,0.021527,0.021421,0.544097,0.677466,0.034512,5.440968,-16.991724,0.545155,0.000000
33.360001,0.114318,-16.991724,0.021700,0.021584,0.548234,0.508513,0.025905,5.482337,-16.991724,0.549318,0.000000
33.610001,0.142246,-16.947243,0.021864,0.021746,0.552353,0.632743,0.032233,5.523532,-16.947243,0.553480,0.000000
33.860001,0.133309,-16.991724,0.022032,0.021915,0.556637,0.592989,0.030208,5.566370,-16.991724,0.557643,0.000000
34.110001,0.097562,-16.947243,0.022209,0.022077,0.560748,0.433975,0.022108,5.607481,-16.947243,0.561806,0.000000
34.360001,0.139640,-16.947243,0.022368,0.022238,0.564833,0.621148,0.031643,5.648327,-16.947243,0.565968,0.000000
34.610001,0.137778,-16.902761,0.022532,0.022402,0.569013,0.612866,0.031221,5.690128,-16.902761,0.570132,0.000000
34.860001,0.160865,-16.902761,0.022704,0.022568,0.573236,0.715563,0.036453,5.732360,-16.902761,0.574312,0.000000
35.110001,0.140757,-16.902761,0.022868,0.022730,0.577346,0.626117,0.031896,5.773464,-16.902761,0.578474,0.000000
35.360001,0.146715,-16.858280,0.023049,0.022890,0.581396,0.652620,0.033246,5.813962,-16.858280,0.582637,0.000000
35.610001,0.169429,-16.902761,0.023205,0.023062,0.585767,0.753660,0.038393,5.857670,-16.902761,0.586800,0.000000
35.860001,0.132937,-16.813799,0.023373,0.023223,0.589869,0.591333,0.030124,5.898691,-16.813799,0.590962,0.000000
36.110001,0.162727,-16.858280,0.023541,0.023386,0.594006,0.723845,0.036874,5.940060,-16.858280,0.595125,0.000000
36.360001,0.154162,-16.769318,0.023705,0.023548,0.598125,0.685748,0.034934,5.981255,-16.769318,0.599287,0.000000
36.610001,0.152300,-16.724838,0.023886,0.023716,0.602392,0.677466,0.034512,6.023918,-16.724838,0.603450,0.000000
36.860001,0.141502,-16.769318,0.024045,0.023877,0.606468,0.629430,0.032065,6.064681,-16.769318,0.607630,0.000000
37.110001,0.218583,-16.724838,0.024218,0.024035,0.610492,0.972304,0.049532,6.104922,-16.724838,0.611793,0.000000
37.360001,0.268853,-16.724838,0.024386,0.024203,0.614759,1.195917,0.060923,6.147585,-16.724838,0.615955,0.000000
37.610001,0.267363,-16.724838,0.024567,0.024371,0.619034,1.189292,0.060585,6.190340,-16.724838,0.620118,0.000000
37.860001,0.321357,-16.724838,0.024744,0.024534,0.623171,1.429469,0.072821,6.231709,-16.724838,0.624281,0.000000
38.110001,0.370883,-16.680357,0.024908,0.024699,0.627359,1.649770,0.084043,6.273592,-16.680357,0.628443,0.000000
38.360001,0.503075,-16.635876,0.025089,0.024864,0.631548,2.237790,0.113998,6.315483,-16.635876,0.632606,0.000000
38.610001,0.638619,-16.635876,0.025175,-0.000000,-0.000000,2.840718,0.144713,-0.000000,-16.635876,0.000269,0.000000
38.860001,0.619255,-16.635876,0.025175,-0.000000,-0.000000,2.754586,0.140325,-0.000000,-16.635876,0.000269,0.000000
39.110001,0.599892,-16.591394,0.025175,-0.000000,-0.000000,2.668453,0.135937,-0.000000,-16.591394,0.000503,0.000000
39.360001,0.602871,-16.591394,0.025179,0.000000,0.000008,2.681704,0.136613,0.000083,-16.591394,0.000919,0.000000
39.610001,0.639363,-16.502434,0.025175,0.000015,0.000382,2.844031,0.144882,0.003815,-16.502434,0.001335,0.000000
39.860001,0.665057,-16.546913,0.025175,0.000029,0.000737,2.958322,0.150704,0.007365,-16.546913,0.001752,0.000000
40.110001,0.765598,-16.546913,0.025179,0.000050,0.001275,3.405549,0.173487,0.012748,-16.546913,0.002168,0.000000
40.360001,0.826667,-16.502434,0.025197,0.000064,0.001630,3.677198,0.187325,0.016298,-16.502434,0.002584,0.000000
40.610001,0.833370,-16.457952,0.025205,0.000079,0.002003,3.707013,0.188844,0.020030,-16.457952,0.003001,0.000000
40.860001,0.870607,-16.502434,0.025231,0.000093,0.002367,3.872652,0.197282,0.023671,-16.502434,0.003416,0.000000
41.110001,1.019556,-16.413471,0.025240,0.000110,0.002783,4.535211,0.231035,0.027834,-16.413471,0.003833,0.000000
41.360001,1.098499,-16.457952,0.025253,0.000130,0.003303,4.886366,0.248923,0.033035,-16.457952,0.004249,0.000000
41.610001,1.197550,-16.413471,0.025265,0.000143,0.003642,5.326968,0.271369,0.036418,-16.413471,0.004665,0.000000
41.860001,1.271280,-16.413471,0.025278,0.000164,0.004154,5.654934,0.288076,0.041535,-16.413471,0.005082,0.000000
42.110001,1.416132,-16.368990,0.025296,0.000182,0.004613,6.299272,0.320900,0.046130,-16.368990,0.005498,0.000000
42.360001,1.502523,-16.457952,0.025317,0.000197,0.004995,6.683556,0.340477,0.049945,-16.457952,0.005914,0.000000
42.610001,1.547580,-16.368990,0.025326,0.000211,0.005368,6.883980,0.350687,0.053677,-16.368990,0.006331,0.000000
42.860001,1.638439,-16.368990,0.025347,0.000224,0.005697,7.288140,0.371276,0.056970,-16.368990,0.006747,0.000000
43.110001,1.827976,-16.324509,0.025365,0.000241,0.006131,8.131245,0.414225,0.061308,-16.324509,0.007163,0.000000
43.360001,1.992937,-16.324509,0.025369,0.000256,0.006512,8.865028,0.451606,0.065123,-16.324509,0.007579,0.000000
43.610001,2.179124,-16.280027,0.025395,0.000273,0.006938,9.693226,0.493796,0.069377,-16.280027,0.007995,0.000000
43.860001,2.299772,-16.280027,0.025403,0.000290,0.007354,10.229897,0.521136,0.073541,-16.280027,0.008412,0.000000
44.110001,2.509790,-16.235548,0.025412,0.000309,0.007848,11.164105,0.568727,0.078484,-16.235548,0.008837,0.000000
44.360001,2.630811,-16.235548,0.025429,0.000322,0.008169,11.702433,0.596150,0.081693,-16.235548,0.009253,0.000000
44.610001,2.807316,-16.191067,0.025434,0.000338,0.008594,12.487564,0.636147,0.085940,-16.191067,0.009669,0.000000
44.860001,3.025898,-16.191067,0.025464,0.000356,0.009036,13.459868,0.685678,0.090361,-16.191067,0.010085,0.000000
45.110001,3.303316,-16.235548,0.025485,0.000372,0.009461,14.693884,0.748542,0.094615,-16.235548,0.010502,0.000000
45.360001,3.492481,-16.146585,0.025494,0.000388,0.009851,15.535333,0.791408,0.098513,-16.146585,0.010918,0.000000
45.610001,3.692818,-16.146585,0.025498,0.000401,0.010181,16.426474,0.836804,0.101806,-16.146585,0.011334,0.000000
45.860001,3.863364,-16.146585,0.025511,0.000414,0.010528,17.185102,0.875451,0.105281,-16.146585,0.011751,0.000000
46.110001,4.219352,-16.057623,0.025524,0.000438,0.011126,18.768616,0.956119,0.111261,-16.057623,0.012167,0.000000
46.360001,4.468097,-16.146585,0.025554,0.000455,0.011560,19.875090,1.012485,0.115598,-16.146585,0.012583,0.000000
46.610001,4.760037,-16.057623,0.025567,0.000473,0.012002,21.173704,1.078640,0.120019,-16.057623,0.013000,0.000000
46.860001,5.027029,-16.057623,0.025589,0.000490,0.012436,22.361340,1.139141,0.124357,-16.057623,0.013416,0.000000
47.110001,5.239653,-16.013142,0.025597,0.000503,0.012774,23.307140,1.187322,0.127740,-16.013142,0.013832,0.000000
47.360001,5.425467,-16.013142,0.025606,0.000516,0.013112,24.133682,1.229428,0.131124,-16.013142,0.014248,0.000000
47.610001,5.703257,-16.013142,0.025606,0.000528,0.013407,25.369352,1.292377,0.134069,-16.013142,0.014664,0.000000
47.860001,5.898380,-16.013142,0.025619,0.000546,0.013858,26.237305,1.336592,0.138580,-16.013142,0.015081,0.000000
48.110001,6.488590,-15.924180,0.025654,0.000571,0.014491,28.862690,1.470336,0.144908,-15.924180,0.015497,0.000000
48.360001,6.747761,-16.013142,0.025658,0.000587,0.014907,30.015541,1.529065,0.149072,-16.013142,0.015913,0.000000
48.610001,7.032254,-15.924180,0.025671,0.000603,0.015324,31.281029,1.593532,0.153235,-15.924180,0.016330,0.000000
48.860001,7.546128,-15.924180,0.025697,0.000623,0.015835,33.566856,1.709977,0.158352,-15.924180,0.016746,0.000000
49.110001,7.694332,-15.924180,0.025705,0.000635,0.016121,34.226097,1.743561,0.161214,-15.924180,0.017171,0.000000
49.360001,7.835089,-15.924180,0.025714,0.000645,0.016382,34.852219,1.775457,0.163818,-15.924180,0.017587,0.000000
49.610001,8.151978,-15.924180,0.025718,0.000659,0.016737,36.261806,1.847265,0.167368,-15.924180,0.018003,0.000000
49.860001,9.014020,-15.835218,0.025735,0.000688,0.017474,40.096363,2.042606,0.174741,-15.835218,0.018420,0.000000
50.110001,9.082910,-15.835218,0.025757,0.000703,0.017847,40.402802,2.058217,0.178473,-15.835218,0.018836,0.000000
50.360001,9.421023,-15.790737,0.025787,0.000720,0.018289,41.906803,2.134834,0.182894,-15.790737,0.019252,0.000000
50.610001,9.693600,-15.835218,0.025791,0.000734,0.018636,43.119286,2.196601,0.186361,-15.835218,0.019669,0.000000
50.860001,10.121456,-15.835218,0.025809,0.000753,0.019130,45.022484,2.293555,0.191304,-15.835218,0.020085,0.000000
51.110001,10.414886,-15.746257,0.025813,0.000765,0.019443,46.327724,2.360047,0.194430,-15.746257,0.020501,0.000000
51.360001,10.440207,-15.790737,0.025826,0.000771,0.019591,46.440357,2.365785,0.195906,-15.790737,0.020917,0.000000
51.610001,11.166705,-15.701776,0.025852,0.000797,0.020249,49.671986,2.530412,0.202492,-15.701776,0.021333,0.000000
51.860001,11.791919,-15.746257,0.025869,0.000819,0.020813,52.453075,2.672087,0.208131,-15.746257,0.021750,0.000000
52.110001,11.984063,-15.657295,0.025878,0.000835,0.021220,53.307774,2.715628,0.212204,-15.657295,0.022166,0.000000
52.360001,12.348616,-15.701776,0.025895,0.000851,0.021611,54.929386,2.798236,0.216110,-15.701776,0.022582,0.000000
52.610001,12.585444,-15.612814,0.025895,0.000865,0.021967,55.982853,2.851902,0.219668,-15.612814,0.022999,0.000000
52.860001,13.204700,-15.657295,0.025921,0.000886,0.022496,58.737438,2.992228,0.224959,-15.657295,0.023415,0.000000
53.110004,13.277685,-15.612814,0.025921,0.000895,0.022730,59.062092,3.008767,0.227298,-15.612814,0.023831,0.000000
53.360004,13.580796,-15.612814,0.025938,0.000908,0.023051,60.410400,3.077452,0.230508,-15.612814,0.024248,0.000000
53.610004,14.536304,-15.612814,0.025951,0.000936,0.023779,64.660706,3.293973,0.237790,-15.612814,0.024664,0.000000
53.860004,14.577638,-15.568333,0.025986,0.000950,0.024117,64.844574,3.303340,0.241174,-15.568333,0.025080,0.000000
54.110004,14.814094,-15.568333,0.025998,0.000966,0.024534,65.896378,3.356922,0.245337,-15.568333,0.025505,0.000000
54.360004,15.262058,-15.523852,0.026007,0.000980,0.024880,67.889023,3.458432,0.248804,-15.523852,0.025921,0.000000
54.610004,15.781517,-15.523852,0.026011,0.000999,0.025375,70.199692,3.576143,0.253747,-15.523852,0.026338,0.000000
54.860004,16.007919,-15.568333,0.026033,0.001013,0.025730,71.206779,3.627446,0.257305,-15.568333,0.026754,0.000000
55.110004,16.314009,-15.479371,0.026050,0.001027,0.026077,72.568336,3.696807,0.260772,-15.479371,0.027170,0.000000
55.360004,16.834959,-15.434890,0.026055,0.001046,0.026571,74.885635,3.814856,0.265715,-15.434890,0.027586,0.000000
55.610004,17.423679,-15.434890,0.026067,0.001068,0.027126,77.504395,3.948262,0.271263,-15.434890,0.028002,0.000000
55.860004,17.587524,-15.479371,0.026089,0.001081,0.027465,78.233215,3.985390,0.274647,-15.479371,0.028419,0.000000
56.110004,17.898083,-15.434890,0.026111,0.001098,0.027881,79.614647,4.055763,0.278811,-15.434890,0.028835,0.000000
56.360004,18.188160,-15.390409,0.026128,0.001111,0.028210,80.904976,4.121496,0.282103,-15.390409,0.029251,0.000000
56.610004,18.732941,-15.345928,0.026132,0.001130,0.028696,83.328285,4.244945,0.286963,-15.345928,0.029668,0.000000
56.860004,18.995836,-15.345928,0.026141,0.001145,0.029078,84.497704,4.304518,0.290778,-15.345928,0.030084,0.000000
57.110004,19.348101,-15.390409,0.026167,0.001159,0.029442,86.064651,4.384342,0.294419,-15.390409,0.030500,0.000000
57.360004,19.956184,-15.345928,0.026171,0.001179,0.029954,88.769539,4.522136,0.299537,-15.345928,0.030917,0.000000
57.610004,20.342709,-15.301447,0.026197,0.001196,0.030387,90.488884,4.609724,0.303874,-15.301447,0.031333,0.000000
57.860004,20.540810,-15.256967,0.026197,0.001211,0.030769,91.370087,4.654614,0.307689,-15.256967,0.031748,0.000000
58.110004,21.064737,-15.256967,0.026214,0.001228,0.031194,93.700630,4.773337,0.311936,-15.256967,0.032165,0.000000
58.360004,21.184641,-15.212485,0.026227,0.001239,0.031462,94.233986,4.800508,0.314623,-15.212485,0.032581,0.000000
58.610004,21.762564,-15.212485,0.026231,0.001256,0.031905,96.804718,4.931467,0.319052,-15.212485,0.032997,0.000000
58.860004,22.130840,-15.301447,0.026249,0.001272,0.032312,98.442894,5.014920,0.323124,-15.301447,0.033414,0.000000
59.110004,22.401182,-15.168004,0.026257,0.001286,0.032668,99.645432,5.076180,0.326682,-15.168004,0.033830,0.000000
59.360004,23.193964,-15.168004,0.026279,0.001308,0.033232,103.171906,5.255827,0.332321,-15.168004,0.034255,0.000000
59.610004,23.886576,-15.123524,0.026292,0.001330,0.033787,106.252792,5.412776,0.337870,-15.123524,0.034671,0.000000
59.860004,23.716774,-15.168004,0.026305,0.001337,0.033969,105.497482,5.374298,0.339687,-15.168004,0.035087,0.000000
60.110004,24.184101,-15.123524,0.026318,0.001356,0.034455,107.576256,5.480196,0.344547,-15.123524,0.035504,0.000000
60.360004,24.447742,-15.123524,0.026335,0.001367,0.034723,108.748993,5.539938,0.347234,-15.123524,0.035920,0.000000
60.610004,25.282228,-15.123524,0.026348,0.001389,0.035287,112.460968,5.729035,0.352873,-15.123524,0.036337,0.000000
60.860004,25.610289,-15.079042,0.026348,0.001404,0.035651,113.920250,5.803374,0.356514,-15.079042,0.036753,0.000000
61.110004,26.093628,-15.079042,0.026361,0.001418,0.036025,116.070251,5.912901,0.360246,-15.079042,0.037169,0.000000
61.360004,26.822361,-15.034561,0.026378,0.001439,0.036545,119.311821,6.078034,0.365447,-15.034561,0.037586,0.000000
61.610004,27.192871,-15.034561,0.026382,0.001454,0.036944,120.959930,6.161993,0.369436,-15.034561,0.038002,0.000000
61.860004,27.453533,-15.034561,0.026417,0.001468,0.037299,122.119415,6.221060,0.372994,-15.034561,0.038417,0.000000
62.110004,28.038902,-14.990081,0.026412,0.001486,0.037741,124.723267,6.353706,0.377415,-14.990081,0.038834,0.000000
62.360004,28.341640,-15.034561,0.026421,0.001501,0.038114,126.069916,6.422308,0.381139,-15.034561,0.039250,0.000000
62.610004,29.298265,-14.945600,0.026443,0.001521,0.038626,130.325195,6.639081,0.386256,-14.945600,0.039666,0.000000
62.860004,29.572704,-14.856638,0.026455,0.001535,0.038990,131.545959,6.701271,0.389905,-14.856638,0.040083,0.000000
63.110004,30.062002,-14.945600,0.026464,0.001550,0.039372,133.722458,6.812147,0.393720,-14.945600,0.040499,0.000000
63.360004,30.951227,-14.901118,0.026486,0.001572,0.039935,137.677933,7.013649,0.399352,-14.901118,0.040915,0.000000
63.610004,31.432705,-14.901118,0.026494,0.001588,0.040326,139.819656,7.122753,0.403258,-14.901118,0.041332,0.000000
63.860004,31.849016,-14.901118,0.026507,0.001604,0.040750,141.671494,7.217090,0.407504,-14.901118,0.041748,0.000000
64.110001,32.316715,-14.812157,0.026512,0.001618,0.041106,143.751923,7.323072,0.411062,-14.812157,0.042164,0.000000
64.360001,32.845482,-14.767675,0.026524,0.001633,0.041470,146.104004,7.442893,0.414703,-14.767675,0.042589,0.000000
64.610001,33.568260,-14.812157,0.026542,0.001649,0.041887,149.319077,7.606677,0.418867,-14.812157,0.043005,0.000000
64.860001,34.214699,-14.812157,0.026546,0.001667,0.042346,152.194580,7.753162,0.423462,-14.812157,0.043422,0.000000
65.110001,34.784798,-14.767675,0.026563,0.001682,0.042728,154.730515,7.882348,0.427277,-14.767675,0.043838,0.000000
65.360001,35.592102,-14.723195,0.026572,0.001701,0.043196,158.321579,8.065286,0.431962,-14.723195,0.044255,0.000000
65.610001,36.179333,-14.812157,0.026593,0.001717,0.043604,160.933716,8.198354,0.436035,-14.812157,0.044671,0.000000
65.860001,36.666771,-14.767675,0.026593,0.001732,0.043994,163.101944,8.308809,0.439941,-14.767675,0.045086,0.000000
66.110001,37.402576,-14.678714,0.026611,0.001749,0.044419,166.374969,8.475545,0.444188,-14.678714,0.045503,0.000000
66.360001,38.303719,-14.723195,0.026624,0.001766,0.044853,170.383453,8.679747,0.448525,-14.723195,0.045919,0.000000
66.610001,38.828018,-14.678714,0.026637,0.001781,0.045234,172.715652,8.798555,0.452340,-14.678714,0.046335,0.000000
66.860001,39.178421,-14.634233,0.026637,0.001792,0.045529,174.274323,8.877957,0.455293,-14.634233,0.046752,0.000000
67.110001,40.013283,-14.678714,0.026649,0.001808,0.045928,177.987976,9.067140,0.459282,-14.678714,0.047168,0.000000
67.360001,41.260357,-14.678714,0.026667,0.001831,0.046509,183.535233,9.349730,0.465088,-14.678714,0.047584,0.000000
67.610001,41.987228,-14.634233,0.026671,0.001848,0.046952,186.768524,9.514442,0.469516,-14.634233,0.048001,0.000000
67.860001,42.789318,-14.589752,0.026684,0.001866,0.047394,190.336395,9.696198,0.473937,-14.589752,0.048417,0.000000
68.110001,43.555660,-14.545271,0.026710,0.001882,0.047801,193.745255,9.869854,0.478010,-14.545271,0.048833,0.000000
68.360001,44.222206,-14.634233,0.026706,0.001897,0.048192,196.710190,10.020895,0.481916,-14.634233,0.049250,0.000000
68.610001,44.432968,-14.589752,0.026727,0.001905,0.048391,197.647720,10.068655,0.483906,-14.589752,0.049665,0.000000
68.860001,45.640575,-14.545271,0.026727,0.001926,0.048911,203.019424,10.342301,0.489114,-14.545271,0.050082,0.000000
69.110001,46.133595,-14.589752,0.026740,0.001939,0.049241,205.212479,10.454021,0.492407,-14.589752,0.050498,0.000000
69.360001,47.699421,-14.545271,0.026749,0.001965,0.049900,212.177628,10.808844,0.499001,-14.545271,0.050923,0.000000
69.610001,48.418098,-14.545271,0.026762,0.001980,0.050290,215.374466,10.971698,0.502899,-14.545271,0.051340,0.000000
69.860001,49.194122,-14.456309,0.026757,0.001996,0.050698,218.826385,11.147547,0.506979,-14.456309,0.051755,0.000000
70.110001,50.091171,-14.500790,0.026775,0.002014,0.051166,222.816666,11.350821,0.511657,-14.500790,0.052172,0.000000
70.360001,51.080193,-14.456309,0.026792,0.002030,0.051556,227.216049,11.574937,0.515563,-14.456309,0.052588,0.000000
70.610001,51.558315,-14.411828,0.026800,0.002043,0.051886,229.342834,11.683282,0.518856,-14.411828,0.053004,0.000000
70.860001,52.238640,-14.411828,0.026809,0.002055,0.052198,232.369080,11.837444,0.521982,-14.411828,0.053421,0.000000
71.110001,52.795338,-14.367347,0.026822,0.002073,0.052649,234.845398,11.963594,0.526486,-14.367347,0.053837,0.000000
71.360001,54.787903,-14.411828,0.026813,0.002095,0.053213,243.708771,12.415115,0.532126,-14.411828,0.054253,0.000000
71.610001,55.588875,-14.322866,0.026831,0.002113,0.053664,247.271667,12.596619,0.536638,-14.322866,0.054670,0.000000
71.860001,56.424480,-14.322866,0.026839,0.002127,0.054020,250.988617,12.785970,0.540195,-14.322866,0.055086,0.000000
72.110001,57.468987,-14.233904,0.026869,0.002144,0.054462,255.634827,13.022658,0.544616,-14.233904,0.055502,0.000000
72.360001,58.159737,-14.278385,0.026861,0.002158,0.054808,258.707428,13.179185,0.548083,-14.278385,0.055918,0.000000
72.610001,58.751808,-14.233904,0.026865,0.002168,0.055077,261.341095,13.313351,0.550770,-14.233904,0.056334,0.000000
72.860001,59.646248,-14.278385,0.026869,0.002185,0.055493,265.319763,13.516033,0.554934,-14.278385,0.056751,0.000000
73.110001,61.533802,-14.233904,0.026882,0.002209,0.056118,273.716034,13.943759,0.561179,-14.233904,0.057167,0.000000
73.360001,62.452446,-14.189424,0.026895,0.002225,0.056517,277.802368,14.151927,0.565168,-14.189424,0.057583,0.000000
73.610001,63.523018,-14.233904,0.026904,0.002243,0.056968,282.564484,14.394522,0.569680,-14.233904,0.058000,0.000000
73.860001,64.306862,-14.189424,0.026904,0.002257,0.057332,286.051208,14.572143,0.573321,-14.189424,0.058416,0.000000
74.110001,65.587456,-14.189424,0.026921,0.002276,0.057817,291.747589,14.862329,0.578173,-14.189424,0.058832,0.000000
74.360001,66.690422,-14.144942,0.026925,0.002292,0.058216,296.653809,15.112266,0.582162,-14.144942,0.059249,0.000000
74.610001,66.979378,-14.055981,0.026930,0.002302,0.058477,297.939148,15.177744,0.584766,-14.055981,0.059673,0.000000
74.860001,67.073219,-14.100462,0.026934,0.002295,0.058295,298.356567,15.199009,0.582950,-14.100462,0.058589,0.000000
75.110001,66.702705,-14.100462,0.026943,0.002289,0.058147,296.708466,15.115049,0.581473,-14.100462,0.058295,0.000000
75.360001,66.369804,-14.055981,0.026956,0.002287,0.058078,295.227631,15.039612,0.580777,-14.055981,0.058295,0.000000
75.610001,66.097977,-14.055981,0.026956,0.002287,0.058078,294.018494,14.978016,0.580777,-14.055981,0.058295,0.000000
75.860001,65.859657,-14.055981,0.026960,0.002287,0.058078,292.958374,14.924011,0.580777,-14.055981,0.058295,0.000000
76.110001,65.652618,-14.011499,0.026969,0.002287,0.058078,292.037445,14.877096,0.580777,-14.011499,0.058295,0.000000
76.360001,65.462708,-13.967019,0.026956,0.002287,0.058078,291.192657,14.834062,0.580777,-13.967019,0.058295,0.000000
76.610001,65.311897,-13.967019,0.026960,0.002287,0.058078,290.521820,14.799888,0.580777,-13.967019,0.058295,0.000000
76.860001,65.155128,-13.967019,0.026964,0.002287,0.058078,289.824493,14.764363,0.580777,-13.967019,0.058295,0.000000
77.110001,65.025543,-13.967019,0.026973,0.002287,0.058078,289.248077,14.734999,0.580777,-13.967019,0.058295,0.000000
77.360001,64.876221,-13.922538,0.026960,0.002287,0.058078,288.583832,14.701161,0.580777,-13.922538,0.058295,0.000000
77.610001,64.771584,-13.922538,0.026981,0.002287,0.058078,288.118408,14.677451,0.580777,-13.922538,0.058295,0.000000
77.860001,64.664345,-13.922538,0.026964,0.002287,0.058078,287.641357,14.653150,0.580777,-13.922538,0.058295,0.000000
78.110001,64.563057,-13.878057,0.026973,0.002287,0.058078,287.190826,14.630198,0.580777,-13.878057,0.058295,0.000000
78.360001,64.463631,-13.878057,0.026973,0.002287,0.058078,286.748566,14.607668,0.580777,-13.878057,0.058295,0.000000
78.610001,64.385429,-13.833576,0.026960,0.002287,0.058078,286.400696,14.589947,0.580777,-13.833576,0.058295,0.000000
78.860001,64.279305,-13.789095,0.026973,0.002287,0.058078,285.928619,14.565899,0.580777,-13.789095,0.058295,0.000000
79.110001,64.226059,-13.833576,0.026986,0.002287,0.058078,285.691772,14.553833,0.580777,-13.833576,0.058295,0.000000
79.360001,64.145996,-13.744614,0.026969,0.002287,0.058078,285.335632,14.535690,0.580777,-13.744614,0.058295,0.000000
79.610001,64.075249,-13.789095,0.026969,0.002287,0.058078,285.020935,14.519659,0.580777,-13.789095,0.058295,0.000000
79.860001,64.015671,-13.789095,0.026973,0.002287,0.058078,284.755920,14.506158,0.580777,-13.789095,0.058295,0.000000
80.110001,63.972843,-13.744614,0.026973,0.002287,0.058078,284.565430,14.496453,0.580777,-13.744614,0.058295,0.000000
80.360001,63.887943,-13.744614,0.026973,0.002287,0.058078,284.187775,14.477215,0.580777,-13.744614,0.058295,0.000000
80.610001,63.837299,-13.700133,0.026981,0.002287,0.058078,283.962494,14.465738,0.580777,-13.700133,0.058295,0.000000
80.860001,63.781815,-13.655652,0.026973,0.002287,0.058078,283.715668,14.453166,0.580777,-13.655652,0.058295,0.000000
81.110001,63.723354,-13.611171,0.026973,0.002287,0.058078,283.455627,14.439919,0.580777,-13.611171,0.058295,0.000000
81.360001,63.667496,-13.700133,0.026977,0.002287,0.058078,283.207153,14.427260,0.580777,-13.700133,0.058295,0.000000
81.610001,63.608292,-13.611171,0.026969,0.002287,0.058078,282.943817,14.413844,0.580777,-13.611171,0.058295,0.000000
81.860001,63.558392,-13.655652,0.026969,0.002287,0.058078,282.721832,14.402537,0.580777,-13.655652,0.058295,0.000000
82.110001,63.524132,-13.611171,0.026973,0.002287,0.058078,282.569458,14.394774,0.580777,-13.611171,0.058295,0.000000
82.360001,63.480568,-13.522209,0.026977,0.002287,0.058078,282.375671,14.384903,0.580777,-13.522209,0.058295,0.000000
82.610001,63.436253,-13.611171,0.026977,0.002287,0.058078,282.178558,14.374860,0.580777,-13.611171,0.058295,0.000000
82.860001,63.395664,-13.566690,0.026973,0.002287,0.058078,281.997986,14.365663,0.580777,-13.566690,0.058295,0.000000
83.110001,63.360291,-13.522209,0.026964,0.002287,0.058078,281.840637,14.357647,0.580777,-13.522209,0.058295,0.000000
83.360001,63.332733,-13.522209,0.026964,0.002287,0.058078,281.718079,14.351402,0.580777,-13.522209,0.058295,0.000000
83.610001,63.295498,-13.522209,0.026977,0.002287,0.058078,281.552429,14.342965,0.580777,-13.522209,0.058295,0.000000
83.860001,63.249321,-13.522209,0.026977,0.002287,0.058078,281.347046,14.332501,0.580777,-13.522209,0.058295,0.000000
84.110001,63.229588,-13.522209,0.026973,0.002287,0.058078,281.259247,14.328029,0.580777,-13.522209,0.058295,0.000000
84.360001,63.168518,-13.477728,0.026977,0.002287,0.058078,280.987610,14.314191,0.580777,-13.477728,0.058295,0.000000
84.610001,63.143196,-13.477728,0.026981,0.002287,0.058078,280.874969,14.308453,0.580777,-13.477728,0.058295,0.000000
84.860001,63.101120,-13.433248,0.026977,0.002287,0.058078,280.687805,14.298918,0.580777,-13.433248,0.058295,0.000000
85.110001,63.058666,-13.477728,0.026969,0.002287,0.058078,280.498962,14.289298,0.580777,-13.477728,0.058295,0.000000
85.360001,63.031857,-13.344285,0.026981,0.002287,0.058078,280.379700,14.283222,0.580777,-13.344285,0.058295,0.000000
85.610001,63.018452,-13.388766,0.026973,0.002287,0.058078,280.320068,14.280185,0.580777,-13.388766,0.058295,0.000000
85.860001,62.968182,-13.344285,0.026977,0.002287,0.058078,280.096466,14.268794,0.580777,-13.344285,0.058295,0.000000
86.110001,62.961105,-13.344285,0.026981,0.002287,0.058078,280.064972,14.267190,0.580777,-13.344285,0.058295,0.000000
86.360001,62.933178,-13.344285,0.026986,0.002287,0.058078,279.940765,14.260862,0.580777,-13.344285,0.058295,0.000000
86.610001,62.908974,-13.344285,0.026973,0.002287,0.058078,279.833099,14.255377,0.580777,-13.344285,0.058295,0.000000
86.860001,62.874718,-13.299805,0.026973,0.002287,0.058078,279.680725,14.247614,0.580777,-13.299805,0.058295,0.000000
87.110001,62.857586,-13.299805,0.026973,0.002287,0.058078,279.604492,14.243732,0.580777,-13.299805,0.058295,0.000000
87.360001,62.830032,-13.255323,0.026973,0.002287,0.058078,279.481934,14.237489,0.580777,-13.255323,0.058295,0.000000
87.610001,62.792793,-13.255323,0.026981,0.002287,0.058078,279.316284,14.229051,0.580777,-13.255323,0.058295,0.000000
87.860001,62.766727,-13.166362,0.026964,0.002287,0.058078,279.200348,14.223144,0.580777,-13.166362,0.058295,0.000000
88.110001,62.735077,-13.210842,0.026973,0.002287,0.058078,279.059570,14.215971,0.580777,-13.210842,0.058295,0.000000
88.360001,62.714222,-13.166362,0.026981,0.002287,0.058078,278.966797,14.211246,0.580777,-13.166362,0.058295,0.000000
88.610001,62.694489,-13.166362,0.026994,0.002287,0.058078,278.879028,14.206774,0.580777,-13.166362,0.058295,0.000000
88.860001,62.668049,-13.166362,0.026977,0.002287,0.058078,278.761414,14.200784,0.580777,-13.166362,0.058295,0.000000
89.110001,62.654644,-13.077399,0.026977,0.002287,0.058078,278.701782,14.197745,0.580777,-13.077399,0.058295,0.000000
89.360001,62.633045,-13.121881,0.026981,0.002287,0.058078,278.605713,14.192850,0.580777,-13.121881,0.058295,0.000000
89.610001,62.610332,-13.121881,0.026981,0.002287,0.058078,278.504669,14.187704,0.580777,-13.121881,0.058295,0.000000
89.860001,62.596554,-13.077399,0.026973,0.002287,0.058078,278.443390,14.184582,0.580777,-13.077399,0.058295,0.000000
90.110001,62.570488,-13.077399,0.026969,0.002287,0.058078,278.327423,14.178676,0.580777,-13.077399,0.058295,0.000000
90.360001,62.539581,-13.032919,0.026981,0.002287,0.058078,278.189941,14.171672,0.580777,-13.032919,0.058295,0.000000
90.610001,62.518726,-13.077399,0.026981,0.002287,0.058078,278.097198,14.166946,0.580777,-13.077399,0.058295,0.000000
90.860001,62.511280,-13.032919,0.026977,0.002287,0.058078,278.064056,14.165258,0.580777,-13.032919,0.058295,0.000000
91.110001,62.485588,-12.988438,0.026973,0.002287,0.058078,277.949768,14.159436,0.580777,-12.988438,0.058295,0.000000
91.360001,62.471436,-12.988438,0.026986,0.002287,0.058078,277.886810,14.156230,0.580777,-12.988438,0.058295,0.000000
91.610001,62.431591,-12.943956,0.026969,0.002287,0.058078,277.709595,14.147201,0.580777,-12.943956,0.058295,0.000000
91.860001,62.433826,-12.943956,0.026977,0.002287,0.058078,277.719543,14.147707,0.580777,-12.943956,0.058295,0.000000
92.110001,62.396591,-12.899476,0.026981,0.002287,0.058078,277.553894,14.139270,0.580777,-12.899476,0.058295,0.000000
92.360001,62.392120,-12.899476,0.026977,0.002287,0.058078,277.534027,14.138257,0.580777,-12.899476,0.058295,0.000000
92.610001,62.378342,-12.854995,0.026990,0.002287,0.058078,277.472717,14.135135,0.580777,-12.854995,0.058295,0.000000
92.860001,62.346321,-12.899476,0.026990,0.002287,0.058078,277.330292,14.127878,0.580777,-12.899476,0.058295,0.000000
93.110001,62.344830,-12.810513,0.026986,0.002287,0.058078,277.323639,14.127541,0.580777,-12.810513,0.058295,0.000000
93.360008,62.313923,-12.854995,0.026981,0.002287,0.058078,277.186188,14.120537,0.580777,-12.854995,0.058295,0.000000
93.610008,62.309082,-12.810513,0.026986,0.002287,0.058078,277.164642,14.119440,0.580777,-12.810513,0.058295,0.000000
93.860008,62.282642,-12.766033,0.026977,0.002287,0.058078,277.047028,14.113448,0.580777,-12.766033,0.058295,0.000000
94.110008,62.278549,-12.810513,0.026977,0.002287,0.058078,277.028809,14.112521,0.580777,-12.810513,0.058295,0.000000
94.360008,62.247643,-12.810513,0.026986,0.002287,0.058078,276.891357,14.105517,0.580777,-12.810513,0.058295,0.000000
94.610008,62.240566,-12.721552,0.026981,0.002287,0.058078,276.859863,14.103914,0.580777,-12.721552,0.058295,0.000000
94.860008,62.214127,-12.721552,0.026973,0.002287,0.058078,276.742249,14.097922,0.580777,-12.721552,0.058295,0.000000
95.110008,62.214870,-12.677071,0.026990,0.002287,0.058078,276.745575,14.098091,0.580777,-12.677071,0.058295,0.000000
95.360008,62.180241,-12.766033,0.026981,0.002287,0.058078,276.591522,14.090243,0.580777,-12.766033,0.058295,0.000000
95.610008,62.181732,-12.677071,0.026986,0.002287,0.058078,276.598145,14.090582,0.580777,-12.677071,0.058295,0.000000
95.860008,62.150452,-12.677071,0.026994,0.002287,0.058078,276.459015,14.083494,0.580777,-12.677071,0.058295,0.000000
96.110008,62.149334,-12.588109,0.026981,0.002287,0.058078,276.454041,14.083241,0.580777,-12.588109,0.058295,0.000000
96.360008,62.102043,-12.677071,0.026986,0.002287,0.058078,276.243683,14.072524,0.580777,-12.677071,0.058295,0.000000
96.610008,62.147472,-12.632590,0.026977,0.002287,0.058078,276.445770,14.082818,0.580777,-12.632590,0.058295,0.000000
96.860008,62.084915,-12.588109,0.026981,0.002287,0.058078,276.167480,14.068643,0.580777,-12.588109,0.058295,0.000000
97.110008,62.105022,-12.588109,0.026986,0.002287,0.058078,276.256927,14.073199,0.580777,-12.588109,0.058295,0.000000
97.360008,62.087894,-12.588109,0.026981,0.002287,0.058078,276.180756,14.069318,0.580777,-12.588109,0.058295,0.000000
97.610008,62.062199,-12.588109,0.026986,0.002287,0.058078,276.066437,14.063495,0.580777,-12.588109,0.058295,0.000000
97.860008,62.051029,-12.543628,0.026981,0.002287,0.058078,276.016754,14.060964,0.580777,-12.543628,0.058295,0.000000
98.110008,62.036133,-12.543628,0.026977,0.002287,0.058078,275.950500,14.057589,0.580777,-12.543628,0.058295,0.000000
98.360008,62.030922,-12.499147,0.026973,0.002287,0.058078,275.927307,14.056407,0.580777,-12.499147,0.058295,0.000000
98.610008,62.024216,-12.499147,0.026969,0.002287,0.058078,275.897491,14.054888,0.580777,-12.499147,0.058295,0.000000
98.860008,62.009693,-12.454666,0.026986,0.002287,0.058078,275.832886,14.051598,0.580777,-12.454666,0.058295,0.000000
99.110008,61.986980,-12.499147,0.026977,0.002287,0.058078,275.731873,14.046451,0.580777,-12.499147,0.058295,0.000000
99.360008,61.984001,-12.454666,0.026994,0.002287,0.058078,275.718597,14.045775,0.580777,-12.454666,0.058295,0.000000
99.610008,61.969852,-12.410186,0.026986,0.002287,0.058078,275.655670,14.042569,0.580777,-12.410186,0.058295,0.000000
99.860008,61.959053,-12.365705,0.026981,0.002287,0.058078,275.607635,14.040122,0.580777,-12.365705,0.058295,0.000000
100.110008,61.937080,-12.365705,0.026986,0.002287,0.058078,275.509888,14.035143,0.580777,-12.365705,0.058295,0.000000
100.360008,61.930378,-12.321223,0.026977,0.002287,0.058078,275.480072,14.033625,0.580777,-12.321223,0.058295,0.000000
100.610008,61.931126,-12.321223,0.026999,0.002287,0.058078,275.483398,14.033794,0.580777,-12.321223,0.058295,0.000000
100.860008,61.900219,-12.276743,0.026986,0.002287,0.058078,275.345917,14.026790,0.580777,-12.276743,0.058295,0.000000
101.110008,61.903568,-12.276743,0.026986,0.002287,0.058078,275.360809,14.027549,0.580777,-12.276743,0.058295,0.000000
101.360008,61.881226,-12.276743,0.026994,0.002287,0.058078,275.261444,14.022486,0.580777,-12.276743,0.058295,0.000000
101.610008,61.868195,-12.276743,0.026999,0.002287,0.058078,275.203461,14.019534,0.580777,-12.276743,0.058295,0.000000
101.860008,61.861862,-12.276743,0.026977,0.002287,0.058078,275.175293,14.018099,0.580777,-12.276743,0.058295,0.000000
102.110008,61.848457,-12.232262,0.026981,0.002287,0.058078,275.115692,14.015060,0.580777,-12.232262,0.058295,0.000000
102.360008,61.859257,-12.143300,0.026986,0.002287,0.058078,275.163727,14.017509,0.580777,-12.143300,0.058295,0.000000
102.610008,61.821274,-12.187780,0.026986,0.002287,0.058078,274.994751,14.008901,0.580777,-12.187780,0.058295,0.000000
102.860008,61.828720,-12.187780,0.026999,0.002287,0.058078,275.027893,14.010588,0.580777,-12.187780,0.058295,0.000000
103.110008,61.803028,-12.143300,0.026999,0.002287,0.058078,274.913605,14.004766,0.580777,-12.143300,0.058295,0.000000
103.360008,61.804890,-12.143300,0.026986,0.002287,0.058078,274.921875,14.005188,0.580777,-12.143300,0.058295,0.000000
103.610008,61.775101,-12.143300,0.026981,0.002287,0.058078,274.789368,13.998438,0.580777,-12.143300,0.058295,0.000000
103.860008,61.773983,-12.054338,0.026986,0.002287,0.058078,274.784393,13.998185,0.580777,-12.054338,0.058295,0.000000
104.110008,61.767281,-12.098819,0.026977,0.002287,0.058078,274.754578,13.996666,0.580777,-12.098819,0.058295,0.000000
104.360008,61.756481,-12.098819,0.026981,0.002287,0.058078,274.706543,13.994219,0.580777,-12.098819,0.058295,0.000000
104.610008,61.743450,-12.098819,0.026990,0.002287,0.058078,274.648590,13.991266,0.580777,-12.098819,0.058295,0.000000
104.860008,61.734138,-12.098819,0.026990,0.002287,0.058078,274.607178,13.989156,0.580777,-12.098819,0.058295,0.000000
105.110008,61.717754,-12.009857,0.026994,0.002287,0.058078,274.534271,13.985443,0.580777,-12.009857,0.058295,0.000000
105.200005,61.712543,-11.965376,0.026986,0.002287,0.058078,274.511108,13.984262,0.580777,-11.965376,0.058295,0.000000