File: Data/I-18 Polished After 4_08182023_171528.csv
Time (sec),S:Load (lbs),S:HL1 (DIM),S:LVDT (in),S:Position (in),Ch:Position (mm),Ch:Load (N),Ch:Stress (MPa),Ch:Strain (mm/mm),Ch:HL1 (DIM),Set Point (),Cycles ()
0.110000,0.014519,-32.560055,0.003617,-0.015296,-0.388508,0.064583,0.003290,-3.885085,-32.560055,-0.388404,0.000000
0.330000,0.015266,-32.560055,0.003648,-0.015296,-0.388508,0.067908,0.003459,-3.885085,-32.560055,-0.388404,0.000000
0.550000,0.014145,-32.604538,0.003660,-0.015179,-0.385543,0.062920,0.003205,-3.855427,-32.604538,-0.384936,0.000000
0.770000,0.018616,-32.560055,0.003669,-0.015047,-0.382204,0.082807,0.004218,-3.822040,-32.560055,-0.381276,0.000000
0.990000,0.073357,-32.560055,0.003643,-0.014909,-0.378683,0.326307,0.016623,-3.786829,-32.560055,-0.377599,0.000000
1.210000,0.063675,-32.560055,0.003764,-0.014765,-0.375023,0.283240,0.014429,-3.750233,-32.560055,-0.373939,0.000000
1.430000,0.058090,-32.560055,0.003919,-0.014619,-0.371329,0.258398,0.013163,-3.713289,-32.560055,-0.370280,0.000000
1.650000,0.048409,-32.604538,0.004053,-0.014477,-0.367712,0.215332,0.010970,-3.677124,-32.604538,-0.366620,0.000000
1.870000,0.065163,-32.560055,0.004178,-0.014337,-0.364148,0.289858,0.014766,-3.641481,-32.560055,-0.362943,0.000000
2.090000,0.038727,-32.604538,0.004329,-0.014187,-0.360341,0.172265,0.008776,-3.603413,-32.604538,-0.359283,0.000000
2.310000,0.055855,-32.515575,0.004484,-0.014050,-0.356872,0.248455,0.012657,-3.568721,-32.515575,-0.355623,0.000000
2.530000,0.053619,-32.560055,0.004618,-0.013903,-0.353126,0.238511,0.012150,-3.531258,-32.560055,-0.351946,0.000000
2.750000,0.045799,-32.604538,0.004738,-0.013758,-0.349457,0.203725,0.010378,-3.494575,-32.604538,-0.348287,0.000000
2.970000,0.041702,-32.604538,0.004907,-0.013610,-0.345702,0.185501,0.009450,-3.457025,-32.604538,-0.344627,0.000000
3.190000,0.072235,-32.604538,0.005049,-0.013468,-0.342086,0.321318,0.016369,-3.420860,-32.604538,-0.340950,0.000000
3.410000,0.053246,-32.604538,0.005165,-0.013326,-0.338487,0.236848,0.012066,-3.384869,-32.604538,-0.337290,0.000000
3.630000,0.049522,-32.604538,0.005368,-0.013182,-0.334827,0.220287,0.011222,-3.348273,-32.604538,-0.333631,0.000000
3.850000,0.059952,-32.604538,0.005471,-0.013036,-0.331115,0.266679,0.013585,-3.311155,-32.604538,-0.329954,0.000000
4.070000,0.067024,-32.649017,0.005627,-0.012893,-0.327491,0.298139,0.015188,-3.274907,-32.649017,-0.326294,0.000000
4.290000,0.067398,-32.649017,0.005769,-0.012756,-0.323996,0.299802,0.015273,-3.239957,-32.649017,-0.322634,0.000000
4.510000,0.051010,-32.604538,0.005950,-0.012602,-0.320102,0.226904,0.011559,-3.201018,-32.604538,-0.318957,0.000000
4.730000,0.033508,-32.604538,0.006092,-0.012453,-0.316312,0.149052,0.007593,-3.163120,-32.604538,-0.315297,0.000000
4.950000,-0.023087,-32.604538,0.006247,-0.012311,-0.312696,-0.102694,-0.005231,-3.126959,-32.604538,-0.311638,0.000000
5.170000,0.006699,-32.649017,0.006407,-0.012171,-0.309149,0.029797,0.001518,-3.091487,-32.649017,-0.307978,0.000000
5.390000,0.049149,-32.604538,0.006566,-0.012025,-0.305437,0.218624,0.011137,-3.054372,-32.604538,-0.304301,0.000000
5.610000,0.060318,-32.604538,0.006679,-0.011879,-0.301725,0.268308,0.013668,-3.017254,-32.604538,-0.300641,0.000000
5.830000,0.080055,-32.560055,0.006799,-0.011740,-0.298204,0.356103,0.018141,-2.982043,-32.560055,-0.296982,0.000000
6.050000,0.079315,-32.604538,0.006933,-0.011599,-0.294614,0.352812,0.017973,-2.946140,-32.604538,-0.293305,0.000000
6.270000,0.081917,-32.604538,0.007088,-0.011444,-0.290668,0.364384,0.018563,-2.906682,-32.604538,-0.289645,0.000000
6.490000,0.065163,-32.649017,0.007230,-0.011300,-0.287009,0.289858,0.014766,-2.870086,-32.649017,-0.285985,0.000000
6.710001,0.047287,-32.604538,0.007368,-0.011161,-0.283496,0.210343,0.010715,-2.834962,-32.604538,-0.282308,0.000000
6.930000,0.037231,-32.604538,0.007498,-0.011019,-0.279888,0.165614,0.008437,-2.798884,-32.604538,-0.278648,0.000000
7.150001,0.067772,-32.649017,0.007618,-0.010868,-0.276055,0.301465,0.015357,-2.760555,-32.649017,-0.274989,0.000000
7.370000,0.097183,-32.604538,0.007787,-0.010724,-0.272396,0.432293,0.022022,-2.723959,-32.604538,-0.271312,0.000000
7.590000,0.110596,-32.649017,0.007946,-0.010583,-0.268814,0.491954,0.025061,-2.688142,-32.649017,-0.267652,0.000000
7.810000,0.097183,-32.604538,0.008080,-0.010436,-0.265085,0.432293,0.022022,-2.650850,-32.604538,-0.263992,0.000000
8.030001,0.091599,-32.560055,0.008226,-0.010289,-0.261347,0.407451,0.020757,-2.613474,-32.560055,-0.260315,0.000000
8.250000,0.081177,-32.649017,0.008386,-0.010149,-0.257774,0.361092,0.018395,-2.577744,-32.649017,-0.256656,0.000000
8.470000,0.077820,-32.693501,0.008520,-0.010002,-0.254054,0.346160,0.017634,-2.540539,-32.693501,-0.252996,0.000000
8.690001,0.070747,-32.604538,0.008688,-0.009864,-0.250533,0.314700,0.016032,-2.505332,-32.604538,-0.249319,0.000000
8.910001,0.074097,-32.604538,0.008821,-0.009718,-0.246839,0.329598,0.016791,-2.468387,-32.604538,-0.245659,0.000000
9.130000,0.087135,-32.560055,0.008994,-0.009572,-0.243118,0.387597,0.019745,-2.431182,-32.560055,-0.241999,0.000000
9.350000,0.068138,-32.604538,0.009132,-0.009426,-0.239424,0.303093,0.015440,-2.394238,-32.604538,-0.238340,0.000000
9.570001,0.097557,-32.693501,0.009317,-0.009279,-0.235695,0.433956,0.022107,-2.356949,-32.693501,-0.234663,0.000000
9.790001,0.087135,-32.693501,0.009464,-0.009137,-0.232070,0.387597,0.019745,-2.320697,-32.693501,-0.231003,0.000000
10.010000,0.070000,-32.604538,0.009606,-0.008994,-0.228436,0.311374,0.015862,-2.284362,-32.604538,-0.227343,0.000000
10.230000,0.077080,-32.604538,0.009740,-0.008849,-0.224768,0.342868,0.017467,-2.247679,-32.604538,-0.223666,0.000000
10.450001,0.090858,-32.649017,0.009891,-0.008704,-0.221073,0.404159,0.020589,-2.210734,-32.649017,-0.220006,0.000000
10.670000,0.078568,-32.649017,0.010067,-0.008567,-0.217605,0.349486,0.017804,-2.176046,-32.649017,-0.216347,0.000000
10.890000,0.094208,-32.693501,0.010188,-0.008419,-0.213832,0.419057,0.021348,-2.138322,-32.693501,-0.212670,0.000000
11.110001,0.067024,-32.649017,0.010361,-0.008268,-0.210016,0.298139,0.015188,-2.100163,-32.649017,-0.209010,0.000000
11.330001,0.071121,-32.604538,0.010490,-0.008125,-0.206374,0.316363,0.016116,-2.063740,-32.604538,-0.205351,0.000000
11.550000,0.028671,-32.693501,0.010632,-0.007983,-0.202766,0.127536,0.006497,-2.027663,-32.693501,-0.201674,0.000000
11.770000,0.089363,-32.693501,0.010809,-0.007841,-0.199150,0.397507,0.020250,-1.991498,-32.693501,-0.198014,0.000000
11.990001,0.088997,-32.693501,0.010964,-0.007695,-0.195464,0.395878,0.020167,-1.954641,-32.693501,-0.194354,0.000000
12.210001,0.084526,-32.649017,0.011141,-0.007552,-0.191822,0.375991,0.019154,-1.918219,-32.649017,-0.190677,0.000000
12.430000,0.087875,-32.649017,0.011253,-0.007414,-0.188309,0.390889,0.019913,-1.883095,-32.649017,-0.187017,0.000000
12.650001,0.105003,-32.649017,0.011430,-0.007261,-0.184433,0.467078,0.023794,-1.844330,-32.649017,-0.183358,0.000000
12.870001,0.078941,-32.737980,0.011559,-0.007115,-0.180713,0.351149,0.017888,-1.807128,-32.737980,-0.179681,0.000000
13.090000,0.033142,-32.737980,0.011732,-0.006973,-0.177114,0.147423,0.007510,-1.771138,-32.737980,-0.176021,0.000000
13.310000,0.037231,-32.604538,0.011883,-0.006831,-0.173515,0.165614,0.008437,-1.735147,-32.604538,-0.172361,0.000000
13.530001,0.042824,-32.693501,0.012025,-0.006686,-0.169829,0.190490,0.009704,-1.698290,-32.693501,-0.168701,0.000000
13.750001,0.092720,-32.649017,0.012189,-0.006538,-0.166065,0.412439,0.021011,-1.660653,-32.649017,-0.165024,0.000000
13.970000,0.114319,-32.693501,0.012357,-0.006400,-0.162553,0.508516,0.025905,-1.625529,-32.693501,-0.161365,0.000000
14.190001,0.101654,-32.737980,0.012529,-0.006252,-0.158798,0.452180,0.023035,-1.587979,-32.737980,-0.157705,0.000000
14.410001,0.094208,-32.649017,0.012676,-0.006105,-0.155060,0.419057,0.021348,-1.550600,-32.649017,-0.154028,0.000000
14.630001,0.092720,-32.649017,0.012797,-0.005959,-0.151366,0.412439,0.021011,-1.513659,-32.649017,-0.150369,0.000000
14.850000,0.062553,-32.649017,0.012960,-0.005816,-0.147723,0.278251,0.014175,-1.477233,-32.649017,-0.146709,0.000000
15.070001,0.058830,-32.693501,0.013111,-0.005680,-0.144272,0.261690,0.013331,-1.442719,-32.693501,-0.143032,0.000000
15.290001,0.075218,-32.693501,0.013267,-0.005536,-0.140604,0.334587,0.017045,-1.406036,-32.693501,-0.139372,0.000000
15.510001,0.078194,-32.649017,0.013422,-0.005385,-0.136770,0.347823,0.017719,-1.367702,-32.649017,-0.135712,0.000000
15.730000,0.094582,-32.649017,0.013568,-0.005244,-0.133197,0.420720,0.021432,-1.331973,-32.649017,-0.132035,0.000000
15.950001,0.101280,-32.649017,0.013711,-0.005101,-0.129555,0.450517,0.022950,-1.295551,-32.649017,-0.128376,0.000000
16.170000,0.096443,-32.737980,0.013887,-0.004952,-0.125774,0.429001,0.021854,-1.257740,-32.737980,-0.124716,0.000000
16.390001,0.066650,-32.782459,0.014021,-0.004809,-0.122140,0.296476,0.015103,-1.221401,-32.782459,-0.121039,0.000000
16.610001,0.084526,-32.693501,0.014176,-0.004665,-0.118480,0.375991,0.019154,-1.184805,-32.693501,-0.117379,0.000000
16.830000,0.094955,-32.693501,0.014306,-0.004518,-0.114769,0.422383,0.021517,-1.147690,-32.693501,-0.113719,0.000000
17.050001,0.087135,-32.693501,0.014478,-0.004378,-0.111204,0.387597,0.019745,-1.112044,-32.693501,-0.110060,0.000000
17.270000,0.111336,-32.649017,0.014603,-0.004235,-0.107580,0.495246,0.025229,-1.075796,-32.649017,-0.106383,0.000000
17.490002,0.077820,-32.737980,0.014776,-0.004088,-0.103833,0.346160,0.017634,-1.038333,-32.737980,-0.102723,0.000000
17.710001,0.072609,-32.693501,0.014926,-0.003940,-0.100078,0.322981,0.016453,-1.000779,-32.693501,-0.099063,0.000000
17.930000,0.059578,-32.649017,0.015108,-0.003797,-0.096453,0.265016,0.013501,-0.964531,-32.649017,-0.095386,0.000000
18.150002,0.093460,-32.693501,0.015241,-0.003659,-0.092941,0.415731,0.021178,-0.929407,-32.693501,-0.091727,0.000000
18.370001,0.090111,-32.737980,0.015414,-0.003514,-0.089246,0.400833,0.020419,-0.892463,-32.737980,-0.088067,0.000000
18.590000,0.097557,-32.693501,0.015573,-0.003367,-0.085534,0.433956,0.022107,-0.855345,-32.693501,-0.084390,0.000000
18.810001,0.090485,-32.737980,0.015715,-0.003228,-0.081988,0.402496,0.020504,-0.819876,-32.737980,-0.080730,0.000000
19.030001,0.114319,-32.649017,0.015871,-0.003081,-0.078267,0.508516,0.025905,-0.782675,-32.649017,-0.077071,0.000000
19.250000,0.096443,-32.693501,0.016009,-0.002935,-0.074538,0.429001,0.021854,-0.745382,-32.693501,-0.073394,0.000000
19.470001,0.086761,-32.737980,0.016168,-0.002786,-0.070766,0.385934,0.019660,-0.707658,-32.737980,-0.069734,0.000000
19.690001,0.051010,-32.737980,0.016323,-0.002644,-0.067167,0.226904,0.011559,-0.671667,-32.737980,-0.066074,0.000000
19.910002,0.040955,-32.737980,0.016457,-0.002503,-0.063585,0.182175,0.009280,-0.635851,-32.737980,-0.062397,0.000000
20.130001,0.101654,-32.693501,0.016621,-0.002356,-0.059848,0.452180,0.023035,-0.598475,-32.693501,-0.058737,0.000000
20.350000,0.102028,-32.737980,0.016772,-0.002211,-0.056170,0.453843,0.023120,-0.561705,-32.737980,-0.055078,0.000000
20.570002,0.139267,-32.693501,0.016927,-0.002070,-0.052589,0.619490,0.031558,-0.525888,-32.693501,-0.051401,0.000000
20.790001,0.123253,-32.737980,0.017048,-0.001924,-0.048860,0.548256,0.027929,-0.488596,-32.737980,-0.047741,0.000000
21.010000,0.112823,-32.782459,0.017237,-0.001772,-0.045009,0.501864,0.025566,-0.450092,-32.782459,-0.044081,0.000000
21.230001,0.111336,-32.737980,0.017388,-0.001632,-0.041454,0.495246,0.025229,-0.414537,-32.737980,-0.040422,0.000000
21.450001,0.107239,-32.737980,0.017531,-0.001494,-0.037950,0.477022,0.024301,-0.379500,-32.737980,-0.036745,0.000000
21.670000,0.098679,-32.649017,0.017677,-0.001352,-0.034342,0.438944,0.022361,-0.343422,-32.649017,-0.033085,0.000000
21.890001,0.132935,-32.782459,0.017828,-0.001204,-0.030570,0.591322,0.030123,-0.305698,-32.782459,-0.029425,0.000000
22.110001,0.154907,-32.693501,0.017966,-0.001059,-0.026910,0.689062,0.035102,-0.269102,-32.693501,-0.025748,0.000000
22.330002,0.185814,-32.693501,0.018126,-0.000920,-0.023363,0.826542,0.042106,-0.233634,-32.693501,-0.022088,0.000000
22.550001,0.223419,-32.693501,0.018289,-0.000769,-0.019530,0.993818,0.050628,-0.195301,-32.693501,-0.018429,0.000000
22.770000,0.261032,-32.693501,0.018397,-0.000624,-0.015844,1.161129,0.059151,-0.158443,-32.693501,-0.014752,0.000000
22.990002,0.303856,-32.782459,0.018570,-0.000479,-0.012167,1.351619,0.068855,-0.121673,-32.782459,-0.011092,0.000000
23.210001,0.420403,-32.782459,0.018703,-0.000337,-0.008568,1.870044,0.095265,-0.085682,-32.782459,-0.007432,0.000000
23.430000,0.542175,-32.737980,0.018872,-0.000190,-0.004822,2.411716,0.122859,-0.048220,-32.737980,-0.003755,0.000000
23.650002,0.699310,-32.693501,0.018984,0.000005,0.000139,3.110687,0.158466,0.001385,-32.693501,0.000312,0.000000
23.870001,0.536217,-32.737980,0.019005,0.000003,0.000087,2.385211,0.121508,0.000867,-32.737980,0.000312,0.000000
24.090002,0.516106,-32.737980,0.019001,0.000003,0.000087,2.295753,0.116951,0.000867,-32.737980,0.000312,0.000000
24.310001,0.584251,-32.737980,0.019005,0.000003,0.000087,2.598880,0.132393,0.000867,-32.737980,0.000598,0.000000
24.530001,0.581268,-32.737980,0.019005,0.000003,0.000087,2.585611,0.131717,0.000867,-32.737980,0.000971,0.000000
24.750002,0.584625,-32.737980,0.018979,0.000004,0.000095,2.600543,0.132478,0.000954,-32.737980,0.001335,0.000000
24.970001,0.659096,-32.693501,0.018966,0.000027,0.000694,2.931804,0.149353,0.006938,-32.693501,0.001699,0.000000
25.190001,0.700432,-32.782459,0.018997,0.000039,0.000989,3.115676,0.158720,0.009886,-32.782459,0.002073,0.000000
25.410002,0.715324,-32.782459,0.019027,0.000056,0.001431,3.181922,0.162095,0.014307,-32.782459,0.002437,0.000000
25.630001,0.784958,-32.782459,0.019035,0.000078,0.001969,3.491667,0.177874,0.019685,-32.782459,0.002801,0.000000
25.850000,0.792778,-32.737980,0.019035,0.000086,0.002194,3.526453,0.179646,0.021937,-32.737980,0.003165,0.000000
26.070002,0.776764,-32.737980,0.019053,0.000099,0.002515,3.455219,0.176017,0.025147,-32.737980,0.003538,0.000000
26.290001,0.834854,-32.782459,0.019070,0.000116,0.002940,3.713617,0.189181,0.029397,-32.782459,0.003902,0.000000
26.510002,0.847893,-32.871422,0.019070,0.000128,0.003243,3.771615,0.192135,0.032433,-32.871422,0.004267,0.000000
26.730001,0.901512,-32.826942,0.019091,0.000138,0.003512,4.010126,0.204286,0.035120,-32.826942,0.004640,0.000000
26.950001,0.973755,-32.737980,0.019091,0.000157,0.003980,4.331478,0.220656,0.039802,-32.737980,0.005004,0.000000
27.170002,0.976357,-32.693501,0.019122,0.000167,0.004232,4.343050,0.221246,0.042319,-32.693501,0.005368,0.000000
27.390001,1.048599,-32.782459,0.019122,0.000185,0.004700,4.664402,0.237616,0.047001,-32.782459,0.005732,0.000000
27.610001,1.128288,-32.782459,0.019135,0.000205,0.005203,5.018877,0.255674,0.052031,-32.782459,0.006105,0.000000
27.830002,1.165520,-32.826942,0.019173,0.000219,0.005550,5.184491,0.264111,0.055502,-32.826942,0.006469,0.000000
28.050001,1.176323,-32.782459,0.019182,0.000231,0.005862,5.232546,0.266559,0.058624,-32.782459,0.006834,0.000000
28.270000,1.223610,-32.693501,0.019191,0.000242,0.006157,5.442889,0.277274,0.061573,-32.693501,0.007198,0.000000
28.490002,1.320427,-32.782459,0.019203,0.000255,0.006469,5.873552,0.299213,0.064691,-32.782459,0.007571,0.000000
28.710001,1.432144,-32.826942,0.019212,0.000273,0.006929,6.370495,0.324529,0.069290,-32.826942,0.007935,0.000000
28.930002,1.544601,-32.782459,0.019216,0.000287,0.007302,6.870730,0.350012,0.073018,-32.782459,0.008299,0.000000
29.150002,1.613861,-32.737980,0.019251,0.000297,0.007554,7.178813,0.365706,0.075535,-32.737980,0.008672,0.000000
29.370001,1.706207,-32.737980,0.019242,0.000313,0.007952,7.589589,0.386632,0.079524,-32.737980,0.009036,0.000000
29.590002,1.881226,-32.737980,0.019272,0.000334,0.008472,8.368110,0.426292,0.084725,-32.737980,0.009401,0.000000
29.810001,1.969101,-32.826942,0.019277,0.000346,0.008776,8.758999,0.446205,0.087760,-32.826942,0.009765,0.000000
30.030001,2.049164,-32.782459,0.019285,0.000359,0.009114,9.115136,0.464347,0.091144,-32.782459,0.010138,0.000000
30.250002,2.146355,-32.782459,0.019303,0.000370,0.009392,9.547462,0.486371,0.093918,-32.782459,0.010502,0.000000
30.470001,2.407761,-32.737980,0.019329,0.000389,0.009877,10.710254,0.545606,0.098774,-32.737980,0.010866,0.000000
30.690001,2.605484,-32.737980,0.019350,0.000405,0.010294,11.589771,0.590411,0.102938,-32.737980,0.011239,0.000000
30.910002,2.682198,-32.871422,0.019354,0.000415,0.010537,11.931010,0.607795,0.105368,-32.871422,0.011603,0.000000
31.130001,2.867638,-32.782459,0.019346,0.000432,0.010970,12.755889,0.649816,0.109701,-32.782459,0.011967,0.000000
31.350002,3.069092,-32.826942,0.019367,0.000446,0.011335,13.652002,0.695466,0.113346,-32.826942,0.012332,0.000000
31.570002,3.305176,-32.826942,0.019389,0.000463,0.011759,14.702156,0.748964,0.117593,-32.826942,0.012705,0.000000
31.790001,3.416512,-32.782459,0.019385,0.000474,0.012037,15.197402,0.774193,0.120367,-32.782459,0.013069,0.000000
32.010002,3.547592,-32.782459,0.019428,0.000486,0.012340,15.780478,0.803896,0.123403,-32.782459,0.013433,0.000000
32.230003,3.758354,-32.826942,0.019423,0.000500,0.012696,16.717995,0.851655,0.126961,-32.826942,0.013806,0.000000
32.450001,4.009331,-32.782459,0.019454,0.000516,0.013104,17.834394,0.908527,0.131037,-32.782459,0.014170,0.000000
32.670002,4.334412,-32.737980,0.019458,0.000534,0.013563,19.280426,0.982192,0.135632,-32.737980,0.014534,0.000000
32.890003,4.440536,-32.737980,0.019505,0.000544,0.013806,19.752493,1.006240,0.138062,-32.737980,0.014899,0.000000
33.110001,4.520973,-32.826942,0.019488,0.000553,0.014057,20.110292,1.024467,0.140575,-32.826942,0.015272,0.000000
33.330002,4.943245,-32.871422,0.019505,0.000574,0.014587,21.988651,1.120155,0.145866,-32.871422,0.015636,0.000000
33.550003,5.276146,-32.782459,0.019510,0.000594,0.015081,23.469469,1.195592,0.150809,-32.782459,0.016000,0.000000
33.770000,5.346519,-32.737980,0.019527,0.000602,0.015298,23.782507,1.211539,0.152978,-32.737980,0.016373,0.000000
33.990002,5.527870,-32.826942,0.019531,0.000614,0.015593,24.589195,1.252633,0.155926,-32.826942,0.016737,0.000000
34.210003,5.823906,-32.826942,0.019557,0.000630,0.016009,25.906027,1.319716,0.160090,-32.826942,0.017102,0.000000
34.430000,6.127762,-32.826942,0.019544,0.000648,0.016460,27.257647,1.388571,0.164598,-32.826942,0.017466,0.000000
34.650002,6.346344,-32.826942,0.019570,0.000662,0.016815,28.229948,1.438102,0.168152,-32.826942,0.017839,0.000000
34.870003,6.445023,-32.782459,0.019583,0.000670,0.017006,28.668892,1.460463,0.170063,-32.782459,0.018203,0.000000
35.090000,6.793190,-32.782459,0.019609,0.000687,0.017440,30.217619,1.539359,0.174397,-32.782459,0.018567,0.000000
35.310001,7.009911,-32.826942,0.019626,0.000702,0.017821,31.181639,1.588468,0.178212,-32.826942,0.018940,0.000000
35.530003,7.359192,-32.782459,0.019626,0.000718,0.018246,32.735321,1.667617,0.182462,-32.782459,0.019304,0.000000
35.750000,7.591553,-32.826942,0.019656,0.000734,0.018636,33.768913,1.720270,0.186364,-32.826942,0.019669,0.000000
35.970001,7.654488,-32.826942,0.019669,0.000743,0.018862,34.048862,1.734532,0.188620,-32.826942,0.020033,0.000000
36.190002,7.950523,-32.782459,0.019686,0.000759,0.019278,35.365696,1.801614,0.192784,-32.782459,0.020406,0.000000
36.410000,8.271133,-32.826942,0.019704,0.000775,0.019677,36.791840,1.874266,0.196773,-32.826942,0.020770,0.000000
36.630001,8.553764,-32.871422,0.019699,0.000789,0.020041,38.049046,1.938311,0.200414,-32.871422,0.021134,0.000000
36.850002,8.551529,-32.826942,0.019717,0.000798,0.020276,38.039101,1.937804,0.202757,-32.826942,0.021507,0.000000
37.070004,8.951088,-32.826942,0.019738,0.000816,0.020726,39.816429,2.028346,0.207265,-32.826942,0.021871,0.000000
37.290001,9.320854,-32.826942,0.019751,0.000833,0.021169,41.461231,2.112136,0.211689,-32.826942,0.022235,0.000000
37.510002,9.546135,-32.826942,0.019773,0.000848,0.021550,42.463329,2.163185,0.215504,-32.826942,0.022600,0.000000
37.730003,9.538689,-32.871422,0.019760,0.000859,0.021810,42.430206,2.161498,0.218105,-32.871422,0.022973,0.000000
37.950001,9.981071,-32.826942,0.019786,0.000876,0.022262,44.398022,2.261743,0.222616,-32.826942,0.023337,0.000000
38.170002,10.013466,-32.826942,0.019811,0.000885,0.022470,44.542122,2.269084,0.224698,-32.826942,0.023701,0.000000
38.390003,10.444298,-32.782459,0.019820,0.000903,0.022929,46.458557,2.366712,0.229293,-32.782459,0.024074,0.000000
38.610001,10.618568,-32.871422,0.019842,0.000917,0.023285,47.233753,2.406202,0.232847,-32.871422,0.024438,0.000000
38.830002,10.728424,-32.871422,0.019842,0.000927,0.023545,47.722412,2.431096,0.235451,-32.871422,0.024802,0.000000
39.050003,11.104889,-32.915905,0.019863,0.000945,0.024005,49.397015,2.516404,0.240046,-32.915905,0.025167,0.000000
39.270000,11.581154,-32.782459,0.019880,0.000967,0.024551,51.515545,2.624327,0.245511,-32.782459,0.025540,0.000000
39.490002,11.625839,-32.826942,0.019889,0.000978,0.024837,51.714317,2.634453,0.248372,-32.826942,0.025904,0.000000
39.710003,11.762123,-32.782459,0.019906,0.000991,0.025184,52.320538,2.665335,0.251839,-32.782459,0.026268,0.000000
39.930000,12.081253,-32.915905,0.019915,0.001006,0.025540,53.740097,2.737651,0.255397,-32.915905,0.026641,0.000000
40.150002,12.130028,-32.826942,0.019919,0.001015,0.025791,53.957058,2.748703,0.257910,-32.826942,0.027005,0.000000
40.370003,12.555283,-32.871422,0.019945,0.001033,0.026233,55.848686,2.845068,0.262335,-32.871422,0.027369,0.000000
40.590000,12.591774,-32.737980,0.019975,0.001043,0.026494,56.011009,2.853337,0.264935,-32.737980,0.027734,0.000000
40.810001,12.809982,-32.826942,0.019975,0.001054,0.026771,56.981647,2.902783,0.267709,-32.826942,0.028107,0.000000
41.030003,13.520096,-32.915905,0.019997,0.001081,0.027456,60.140388,3.063698,0.274560,-32.915905,0.028471,0.000000
41.250004,13.829910,-32.915905,0.020018,0.001099,0.027916,61.518513,3.133903,0.279159,-32.915905,0.028835,0.000000
41.470001,13.709633,-32.871422,0.020023,0.001107,0.028107,60.983494,3.106647,0.281066,-32.871422,0.029199,0.000000
41.690002,14.052963,-32.871422,0.020018,0.001124,0.028540,62.510704,3.184447,0.285404,-32.871422,0.029572,0.000000
41.910004,14.203773,-32.782459,0.020061,0.001135,0.028818,63.181541,3.218621,0.288178,-32.782459,0.029937,0.000000
42.130001,14.680412,-32.871422,0.020031,0.001153,0.029295,65.301735,3.326629,0.292947,-32.871422,0.030301,0.000000
42.350002,14.750786,-32.826942,0.020070,0.001164,0.029563,65.614769,3.342576,0.295634,-32.826942,0.030674,0.000000
42.570004,15.006233,-32.826942,0.020105,0.001178,0.029919,66.751060,3.400461,0.299192,-32.826942,0.031038,0.000000
42.790001,14.935486,-32.826942,0.020100,0.001185,0.030101,66.436356,3.384429,0.301013,-32.826942,0.031402,0.000000
43.010002,15.687675,-32.871422,0.020105,0.001207,0.030665,69.782265,3.554878,0.306648,-32.871422,0.031766,0.000000
43.230003,16.023560,-32.871422,0.020152,0.001227,0.031159,71.276352,3.630991,0.311591,-32.871422,0.032139,0.000000
43.450001,16.181068,-32.871422,0.020174,0.001238,0.031445,71.976990,3.666682,0.314453,-32.871422,0.032504,0.000000
43.670002,16.446945,-32.915905,0.020148,0.001253,0.031818,73.159668,3.726931,0.318185,-32.915905,0.032868,0.000000
43.890003,16.889320,-32.826942,0.020204,0.001270,0.032252,75.127449,3.827175,0.322518,-32.826942,0.033240,0.000000
44.110001,17.067314,-32.871422,0.020182,0.001283,0.032599,75.919205,3.867509,0.325989,-32.871422,0.033605,0.000000
44.330002,17.131737,-32.915905,0.020225,0.001291,0.032790,76.205772,3.882107,0.327897,-32.915905,0.033969,0.000000
44.550003,17.221107,-32.915905,0.020204,0.001300,0.033032,76.603310,3.902359,0.330323,-32.915905,0.034333,0.000000
44.770000,17.332443,-32.915905,0.020238,0.001308,0.033232,77.098557,3.927588,0.332318,-32.915905,0.034706,0.000000
44.990002,18.445465,-32.915905,0.020256,0.001340,0.034030,82.049530,4.179802,0.340296,-32.915905,0.035070,0.000000
45.210003,18.706497,-32.871422,0.020247,0.001354,0.034403,83.210655,4.238953,0.344028,-32.871422,0.035435,0.000000
45.430000,18.834221,-32.826942,0.020307,0.001366,0.034698,83.778801,4.267895,0.346976,-32.826942,0.035807,0.000000
45.650002,19.055786,-32.915905,0.020268,0.001379,0.035018,84.764374,4.318103,0.350182,-32.915905,0.036172,0.000000
45.870003,19.226707,-32.915905,0.020307,0.001389,0.035287,85.524666,4.356834,0.352873,-32.915905,0.036536,0.000000
46.090004,19.776695,-32.871422,0.020312,0.001406,0.035721,87.971130,4.481463,0.357207,-32.871422,0.036900,0.000000
46.310001,20.057838,-32.826942,0.020329,0.001422,0.036128,89.221718,4.545171,0.361283,-32.826942,0.037273,0.000000
46.530003,20.397820,-32.915905,0.020355,0.001434,0.036432,90.734032,4.622212,0.364319,-32.915905,0.037637,0.000000
46.750004,20.773170,-32.915905,0.020355,0.001450,0.036822,92.403679,4.707268,0.368221,-32.915905,0.038001,0.000000
46.970001,21.521263,-32.960384,0.020372,0.001473,0.037403,95.731361,4.876788,0.374031,-32.960384,0.038375,0.000000
47.190002,21.560364,-32.826942,0.020402,0.001484,0.037681,95.905289,4.885648,0.376809,-32.826942,0.038739,0.000000
47.410004,21.742081,-32.915905,0.020376,0.001495,0.037984,96.713608,4.926826,0.379844,-32.915905,0.039103,0.000000
47.630001,21.980026,-32.915905,0.020402,0.001509,0.038322,97.772041,4.980745,0.383224,-32.915905,0.039467,0.000000
47.850002,22.257072,-32.960384,0.020389,0.001518,0.038557,99.004402,5.043525,0.385567,-32.960384,0.039840,0.000000
48.070004,22.635399,-32.871422,0.020437,0.001534,0.038956,100.687286,5.129254,0.389557,-32.871422,0.040204,0.000000
48.290001,23.150024,-32.915905,0.020441,0.001550,0.039372,102.976448,5.245870,0.393720,-32.915905,0.040569,0.000000
48.510002,23.506752,-32.915905,0.020441,0.001560,0.039632,104.563255,5.326706,0.396320,-32.915905,0.040942,0.000000
48.730003,23.914505,-32.871422,0.020467,0.001579,0.040100,106.377029,5.419104,0.401002,-32.871422,0.041306,0.000000
48.950001,24.924377,-32.915905,0.020467,0.001602,0.040681,110.869171,5.647944,0.406812,-32.915905,0.041670,0.000000
49.170002,25.165672,-32.960384,0.020484,0.001614,0.041002,111.942505,5.702623,0.410021,-32.960384,0.042034,0.000000
49.390003,25.246475,-32.871422,0.020519,0.001626,0.041288,112.301933,5.720933,0.412883,-32.871422,0.042407,0.000000
49.610001,25.552940,-32.826942,0.020514,0.001636,0.041566,113.665154,5.790379,0.415661,-32.826942,0.042771,0.000000
49.830002,25.903717,-32.915905,0.020531,0.001652,0.041965,115.225487,5.869866,0.419650,-32.915905,0.043136,0.000000
50.050003,26.586273,-33.004868,0.020553,0.001665,0.042294,118.261650,6.024536,0.422943,-33.004868,0.043509,0.000000
50.270004,27.147438,-32.960384,0.020562,0.001683,0.042737,120.757835,6.151698,0.427368,-32.960384,0.043873,0.000000
50.490002,27.252823,-32.915905,0.020579,0.001691,0.042962,121.226608,6.175578,0.429623,-32.915905,0.044237,0.000000
50.710003,27.958092,-32.915905,0.020583,0.001710,0.043439,124.363800,6.335394,0.434392,-32.915905,0.044601,0.000000
50.930004,28.688316,-32.871422,0.020600,0.001729,0.043925,127.612007,6.500865,0.439248,-32.871422,0.044974,0.000000
51.150002,28.951958,-32.960384,0.020596,0.001741,0.044211,128.784744,6.560607,0.442110,-32.960384,0.045339,0.000000
51.370003,29.145218,-32.915905,0.020631,0.001751,0.044471,129.644409,6.604401,0.444710,-32.915905,0.045703,0.000000
51.590004,29.703033,-32.871422,0.020652,0.001766,0.044844,132.125687,6.730803,0.448442,-32.871422,0.046075,0.000000
51.810001,30.470863,-32.915905,0.020631,0.001786,0.045364,135.541168,6.904797,0.453642,-32.915905,0.046440,0.000000
52.030003,31.228271,-32.915905,0.020665,0.001802,0.045772,138.910294,7.076427,0.457719,-32.915905,0.046804,0.000000
52.250004,31.099052,-32.960384,0.020661,0.001811,0.045997,138.335495,7.047146,0.459974,-32.960384,0.047168,0.000000
52.470001,31.655380,-32.960384,0.020687,0.001822,0.046275,140.810165,7.173212,0.462749,-32.960384,0.047541,0.000000
52.690002,32.453751,-32.960384,0.020704,0.001840,0.046743,144.361496,7.354125,0.467435,-32.960384,0.047905,0.000000
52.910004,33.299034,-32.915905,0.020700,0.001859,0.047212,148.121506,7.545669,0.472116,-32.915905,0.048270,0.000000
53.130001,33.767105,-32.915905,0.020713,0.001872,0.047541,150.203583,7.651735,0.475413,-32.915905,0.048642,0.000000
53.350002,34.108574,-32.960384,0.020730,0.001884,0.047862,151.722519,7.729114,0.478619,-32.960384,0.049007,0.000000
53.570004,34.454880,-32.960384,0.020751,0.001897,0.048192,153.262955,7.807587,0.481916,-32.960384,0.049371,0.000000
53.790001,35.202599,-32.915905,0.020773,0.001913,0.048582,156.588974,7.977023,0.485818,-32.915905,0.049735,0.000000
54.010002,36.041931,-32.915905,0.020777,0.001930,0.049033,160.322510,8.167218,0.490329,-32.915905,0.050108,0.000000
54.230003,36.306686,-32.960384,0.020777,0.001941,0.049293,161.500214,8.227212,0.492930,-32.960384,0.050472,0.000000
54.450001,36.532341,-32.960384,0.020764,0.001951,0.049553,162.503967,8.278347,0.495530,-32.960384,0.050836,0.000000
54.670002,37.490829,-32.960384,0.020786,0.001969,0.050004,166.767532,8.495543,0.500041,-32.960384,0.051201,0.000000
54.890003,38.490646,-32.915905,0.020799,0.001990,0.050542,171.214951,8.722105,0.505416,-32.915905,0.051574,0.000000
55.110004,38.809402,-32.915905,0.020816,0.001999,0.050776,172.632843,8.794336,0.507759,-32.915905,0.051938,0.000000
55.330002,39.236511,-32.915905,0.020807,0.002010,0.051062,174.532715,8.891120,0.510620,-32.915905,0.052302,0.000000
55.550003,39.466263,-33.004868,0.020850,0.002023,0.051392,175.554703,8.943183,0.513917,-33.004868,0.052675,0.000000
55.770004,40.833244,-32.960384,0.020846,0.002044,0.051912,181.635345,9.252945,0.519121,-32.960384,0.053039,0.000000
55.990002,41.395157,-32.960384,0.020850,0.002057,0.052241,184.134857,9.380277,0.522414,-32.960384,0.053404,0.000000
56.210003,41.664749,-32.871422,0.020855,0.002066,0.052484,185.334061,9.441367,0.524844,-32.871422,0.053768,0.000000
56.430004,42.305229,-32.915905,0.020885,0.002083,0.052901,188.183060,9.586502,0.529007,-32.915905,0.054141,0.000000
56.650002,43.184776,-32.915905,0.020872,0.002098,0.053291,192.095474,9.785810,0.532909,-32.915905,0.054505,0.000000
56.870003,44.254601,-33.049347,0.020898,0.002117,0.053768,196.854294,10.028236,0.537678,-33.049347,0.054869,0.000000
57.090004,44.786354,-32.960384,0.020902,0.002131,0.054132,199.219650,10.148733,0.541319,-32.960384,0.055242,0.000000
57.310001,45.007164,-32.960384,0.020902,0.002139,0.054323,200.201859,10.198770,0.543227,-32.960384,0.055606,0.000000
57.530003,45.786919,-32.960384,0.020898,0.002153,0.054696,203.670380,10.375464,0.546959,-32.960384,0.055971,0.000000
57.750004,46.400955,-32.960384,0.020898,0.002169,0.055103,206.401764,10.514606,0.551032,-32.960384,0.056335,0.000000
57.970001,47.537437,-33.004868,0.020928,0.002186,0.055537,211.457077,10.772138,0.555369,-33.004868,0.056708,0.000000
58.190002,47.732185,-32.960384,0.020928,0.002193,0.055702,212.323364,10.816268,0.557015,-32.960384,0.057072,0.000000
58.410004,48.439697,-32.960384,0.020967,0.002209,0.056118,215.470535,10.976592,0.561179,-32.960384,0.057436,0.000000
58.630001,49.822319,-33.004868,0.020954,0.002231,0.056664,221.620743,11.289899,0.566644,-33.004868,0.057809,0.000000
58.850002,50.788994,-33.004868,0.020958,0.002247,0.057081,225.920731,11.508950,0.570808,-33.004868,0.058173,0.000000
59.070004,50.980392,-33.004868,0.020971,0.002259,0.057384,226.772110,11.552321,0.573843,-33.004868,0.058538,0.000000
59.290001,52.065491,-33.004868,0.020993,0.002275,0.057792,231.598877,11.798208,0.577916,-33.004868,0.058902,0.000000
59.510002,52.345139,-32.915905,0.020967,0.002283,0.057991,232.842804,11.861578,0.579910,-32.915905,0.059275,0.000000
59.730003,53.387039,-32.960384,0.020984,0.002300,0.058425,237.477417,12.097676,0.584248,-32.960384,0.059639,0.000000
59.950005,54.049484,-32.960384,0.020988,0.002315,0.058806,240.424118,12.247788,0.588063,-32.960384,0.060003,0.000000
60.170002,54.560753,-33.004868,0.020980,0.002326,0.059075,242.698349,12.363643,0.590754,-33.004868,0.060376,0.000000
60.390003,55.538605,-33.004868,0.021010,0.002344,0.059526,247.048050,12.585228,0.595262,-33.004868,0.060740,0.000000
60.610004,57.074272,-33.004868,0.021006,0.002365,0.060073,253.879044,12.933215,0.600727,-33.004868,0.061104,0.000000
60.830002,57.537872,-32.960384,0.021023,0.002375,0.060324,255.941238,13.038268,0.603240,-32.960384,0.061469,0.000000
61.050003,58.176865,-33.004868,0.021027,0.002391,0.060723,258.783630,13.183066,0.607230,-33.004868,0.061842,0.000000
61.270004,59.090294,-33.004868,0.021045,0.002405,0.061087,262.846741,13.390052,0.610871,-33.004868,0.062206,0.000000
61.490002,59.537888,-33.004868,0.021057,0.002415,0.061330,264.837738,13.491478,0.613301,-33.004868,0.062570,0.000000
61.710003,60.536964,-33.004868,0.021057,0.002430,0.061729,269.281860,13.717873,0.617290,-33.004868,0.062943,0.000000
61.930004,60.838585,-32.960384,0.021053,0.002438,0.061937,270.623535,13.786221,0.619372,-32.960384,0.063307,0.000000
62.150002,61.643654,-33.004868,0.021053,0.002452,0.062293,274.204681,13.968652,0.622926,-33.004868,0.063671,0.000000
62.370003,62.758537,-33.093826,0.021057,0.002474,0.062839,279.163910,14.221288,0.628391,-33.093826,0.064036,0.000000
62.590004,64.580559,-33.049347,0.021070,0.002496,0.063403,287.268677,14.634164,0.634027,-33.049347,0.064409,0.000000
62.810001,65.044899,-32.960384,0.021075,0.002504,0.063602,289.334167,14.739385,0.636021,-32.960384,0.064773,0.000000
63.030003,65.749809,-32.960384,0.021079,0.002520,0.064001,292.469757,14.899120,0.640011,-32.960384,0.065137,0.000000
63.250004,66.355278,-33.049347,0.021088,0.002531,0.064296,295.163025,15.036321,0.642959,-33.049347,0.065510,0.000000
63.470001,67.442986,-33.049347,0.021079,0.002536,0.064409,300.001373,15.282800,0.644087,-33.049347,0.064686,0.000000
63.690002,66.953682,-33.004868,0.021096,0.002536,0.064409,297.824860,15.171921,0.644087,-33.004868,0.064686,0.000000
63.910004,66.685951,-32.960384,0.021122,0.002527,0.064192,296.633911,15.111253,0.641918,-32.960384,0.064409,0.000000
64.130005,66.407784,-32.960384,0.021113,0.002527,0.064192,295.396576,15.048219,0.641918,-32.960384,0.064409,0.000000
64.350006,66.163506,-33.004868,0.021096,0.002527,0.064192,294.309967,14.992865,0.641918,-33.004868,0.064409,0.000000
64.570000,65.970985,-33.004868,0.021126,0.002527,0.064192,293.453613,14.949239,0.641918,-33.004868,0.064409,0.000000
64.790001,65.795982,-33.004868,0.021113,0.002527,0.064192,292.675140,14.909583,0.641918,-33.004868,0.064409,0.000000
65.010002,65.610542,-33.093826,0.021101,0.002527,0.064192,291.850281,14.867561,0.641918,-33.093826,0.064409,0.000000
65.230003,65.467552,-33.049347,0.021113,0.002527,0.064192,291.214203,14.835159,0.641918,-33.049347,0.064409,0.000000
65.450005,65.333488,-33.004868,0.021118,0.002527,0.064192,290.617859,14.804780,0.641918,-33.004868,0.064409,0.000000
65.670006,65.210609,-33.049347,0.021126,0.002527,0.064192,290.071289,14.776936,0.641918,-33.049347,0.064409,0.000000
65.889999,65.105232,-33.004868,0.021109,0.002527,0.064192,289.602539,14.753057,0.641918,-33.004868,0.064409,0.000000
66.110001,64.994637,-32.960384,0.021118,0.002527,0.064192,289.110596,14.727995,0.641918,-32.960384,0.064409,0.000000
66.330002,64.913826,-33.004868,0.021118,0.002527,0.064192,288.751129,14.709682,0.641918,-33.004868,0.064409,0.000000
66.550003,64.806953,-33.049347,0.021139,0.002527,0.064192,288.275726,14.685465,0.641918,-33.049347,0.064409,0.000000
66.770004,64.715355,-33.004868,0.021118,0.002527,0.064192,287.868286,14.664709,0.641918,-33.004868,0.064409,0.000000
66.990005,64.630074,-33.093826,0.021122,0.002527,0.064192,287.488922,14.645384,0.641918,-33.093826,0.064409,0.000000
67.210007,64.567528,-33.004868,0.021118,0.002527,0.064192,287.210693,14.631210,0.641918,-33.004868,0.064409,0.000000
67.430000,64.501244,-33.004868,0.021122,0.002527,0.064192,286.915863,14.616191,0.641918,-33.004868,0.064409,0.000000
67.650002,64.417076,-33.004868,0.021092,0.002527,0.064192,286.541473,14.597117,0.641918,-33.004868,0.064409,0.000000
67.870003,64.353783,-33.049347,0.021122,0.002527,0.064192,286.259918,14.582775,0.641918,-33.049347,0.064409,0.000000
68.090004,64.289360,-33.049347,0.021122,0.002527,0.064192,285.973358,14.568177,0.641918,-33.049347,0.064409,0.000000
68.310005,64.233879,-33.004868,0.021122,0.002527,0.064192,285.726562,14.555605,0.641918,-33.004868,0.064409,0.000000
68.530006,64.173180,-33.004868,0.021126,0.002527,0.064192,285.456573,14.541850,0.641918,-33.004868,0.064409,0.000000
68.750000,64.119560,-33.049347,0.021118,0.002527,0.064192,285.218048,14.529700,0.641918,-33.049347,0.064409,0.000000
68.970001,64.064445,-33.093826,0.021139,0.002527,0.064192,284.972900,14.517210,0.641918,-33.093826,0.064409,0.000000
69.190002,64.009712,-33.049347,0.021131,0.002527,0.064192,284.729431,14.504808,0.641918,-33.049347,0.064409,0.000000
69.410004,63.968742,-33.093826,0.021144,0.002527,0.064192,284.547180,14.495524,0.641918,-33.093826,0.064409,0.000000
69.630005,63.928902,-33.004868,0.021122,0.002527,0.064192,284.369965,14.486496,0.641918,-33.004868,0.064409,0.000000
69.850006,63.874535,-33.049347,0.021118,0.002527,0.064192,284.128113,14.474176,0.641918,-33.049347,0.064409,0.000000
70.070000,63.826134,-33.049347,0.021139,0.002527,0.064192,283.912811,14.463208,0.641918,-33.049347,0.064409,0.000000
70.290001,63.782188,-33.093826,0.021126,0.002527,0.064192,283.717346,14.453250,0.641918,-33.093826,0.064409,0.000000
70.510002,63.747551,-33.049347,0.021118,0.002527,0.064192,283.563263,14.445401,0.641918,-33.049347,0.064409,0.000000
70.730003,63.706230,-33.004868,0.021131,0.002527,0.064192,283.379456,14.436038,0.641918,-33.004868,0.064409,0.000000
70.950005,63.674568,-33.049347,0.021122,0.002527,0.064192,283.238617,14.428863,0.641918,-33.049347,0.064409,0.000000
71.170006,63.625038,-33.093826,0.021122,0.002527,0.064192,283.018311,14.417640,0.641918,-33.093826,0.064409,0.000000
71.390007,63.594887,-33.049347,0.021122,0.002527,0.064192,282.884186,14.410808,0.641918,-33.049347,0.064409,0.000000
71.610001,63.554665,-33.004868,0.021144,0.002527,0.064192,282.705261,14.401693,0.641918,-33.004868,0.064409,0.000000
71.830002,63.523384,-33.093826,0.021131,0.002527,0.064192,282.566132,14.394605,0.641918,-33.093826,0.064409,0.000000
72.050003,63.476845,-33.093826,0.021122,0.002527,0.064192,282.359100,14.384058,0.641918,-33.093826,0.064409,0.000000
72.270004,63.453011,-33.093826,0.021135,0.002527,0.064192,282.253082,14.378657,0.641918,-33.093826,0.064409,0.000000
72.490005,63.428810,-33.093826,0.021122,0.002527,0.064192,282.145447,14.373174,0.641918,-33.093826,0.064409,0.000000
72.710007,63.399010,-33.004868,0.021148,0.002527,0.064192,282.012878,14.366421,0.641918,-33.004868,0.064409,0.000000
72.930000,63.369591,-33.049347,0.021126,0.002527,0.064192,281.882019,14.359755,0.641918,-33.049347,0.064409,0.000000
73.150002,63.339058,-33.093826,0.021131,0.002527,0.064192,281.746216,14.352836,0.641918,-33.093826,0.064409,0.000000
73.370003,63.305916,-33.049347,0.021122,0.002527,0.064192,281.598785,14.345325,0.641918,-33.049347,0.064409,0.000000
73.590004,63.270180,-33.049347,0.021113,0.002527,0.064192,281.439819,14.337227,0.641918,-33.049347,0.064409,0.000000
73.810005,63.254539,-33.049347,0.021135,0.002527,0.064192,281.370239,14.333684,0.641918,-33.049347,0.064409,0.000000
74.030006,63.221764,-33.049347,0.021126,0.002527,0.064192,281.224457,14.326256,0.641918,-33.049347,0.064409,0.000000
74.250000,63.197929,-33.093826,0.021118,0.002527,0.064192,281.118439,14.320855,0.641918,-33.093826,0.064409,0.000000
74.470001,63.161064,-33.049347,0.021101,0.002527,0.064192,280.954437,14.312501,0.641918,-33.049347,0.064409,0.000000
74.690002,63.121597,-33.093826,0.021092,0.002527,0.064183,280.778900,14.303558,0.641831,-33.093826,0.064409,0.000000
74.910004,63.091438,-33.093826,0.021135,0.002527,0.064183,280.644745,14.296724,0.641831,-33.093826,0.064409,0.000000
75.130005,63.064995,-33.093826,0.021118,0.002527,0.064183,280.527100,14.290732,0.641831,-33.093826,0.064409,0.000000
75.350006,63.051964,-33.049347,0.021131,0.002527,0.064183,280.469147,14.287779,0.641831,-33.049347,0.064409,0.000000
75.570007,63.017334,-33.093826,0.021131,0.002527,0.064183,280.315094,14.279932,0.641831,-33.093826,0.064409,0.000000
75.790001,63.001694,-33.182789,0.021131,0.002527,0.064183,280.245544,14.276387,0.641831,-33.182789,0.064409,0.000000
76.010002,62.967438,-33.093826,0.021139,0.002527,0.064183,280.093140,14.268625,0.641831,-33.093826,0.064409,0.000000
76.230003,62.946213,-33.093826,0.021126,0.002527,0.064183,279.998749,14.263816,0.641831,-33.093826,0.064409,0.000000
76.450005,62.925728,-33.093826,0.021144,0.002527,0.064183,279.907623,14.259174,0.641831,-33.093826,0.064409,0.000000
76.670006,62.906364,-33.093826,0.021113,0.002527,0.064183,279.821472,14.254786,0.641831,-33.093826,0.064409,0.000000
76.890007,62.892960,-33.138309,0.021131,0.002527,0.064183,279.761871,14.251749,0.641831,-33.138309,0.064409,0.000000
77.110001,62.868759,-33.093826,0.021148,0.002527,0.064183,279.654205,14.246264,0.641831,-33.093826,0.064409,0.000000
77.330002,62.848648,-33.093826,0.021144,0.002527,0.064183,279.564758,14.241707,0.641831,-33.093826,0.064409,0.000000
77.550003,62.819603,-33.049347,0.021135,0.002527,0.064183,279.435547,14.235126,0.641831,-33.049347,0.064409,0.000000
77.770004,62.808060,-33.093826,0.021126,0.002527,0.064183,279.384216,14.232510,0.641831,-33.093826,0.064409,0.000000
77.990005,62.789818,-33.093826,0.021139,0.002527,0.064183,279.303070,14.228376,0.641831,-33.093826,0.064409,0.000000
78.210007,62.766357,-33.138309,0.021126,0.002527,0.064183,279.198700,14.223060,0.641831,-33.138309,0.064409,0.000000
78.430000,62.736191,-33.049347,0.021139,0.002527,0.064183,279.064514,14.216224,0.641831,-33.049347,0.064409,0.000000
78.650002,62.722786,-33.049347,0.021135,0.002527,0.064183,279.004883,14.213186,0.641831,-33.049347,0.064409,0.000000
78.870003,62.700821,-33.049347,0.021139,0.002527,0.064183,278.907196,14.208209,0.641831,-33.049347,0.064409,0.000000
79.090004,62.676239,-33.138309,0.021144,0.002527,0.064183,278.797821,14.202639,0.641831,-33.138309,0.064409,0.000000
79.310005,62.662460,-33.138309,0.021131,0.002527,0.064183,278.736542,14.199517,0.641831,-33.138309,0.064409,0.000000
79.530006,62.651665,-33.093826,0.021139,0.002527,0.064183,278.688538,14.197070,0.641831,-33.093826,0.064409,0.000000
79.750000,62.640121,-33.093826,0.021135,0.002527,0.064183,278.637177,14.194455,0.641831,-33.093826,0.064409,0.000000
79.970001,62.598412,-33.093826,0.021135,0.002527,0.064183,278.451630,14.185003,0.641831,-33.093826,0.064409,0.000000
80.190002,62.594322,-33.093826,0.021118,0.002527,0.064183,278.433441,14.184076,0.641831,-33.093826,0.064409,0.000000
80.410004,62.580544,-33.138309,0.021122,0.002527,0.064183,278.372162,14.180954,0.641831,-33.138309,0.064409,0.000000
80.630005,62.562294,-33.093826,0.021105,0.002527,0.064183,278.290985,14.176818,0.641831,-33.093826,0.064409,0.000000
80.850006,62.541817,-33.093826,0.021135,0.002527,0.064183,278.199890,14.172178,0.641831,-33.093826,0.064409,0.000000
81.070007,62.524315,-33.093826,0.021126,0.002527,0.064183,278.122040,14.168213,0.641831,-33.093826,0.064409,0.000000
81.290001,62.518730,-33.138309,0.021118,0.002527,0.064183,278.097198,14.166947,0.641831,-33.138309,0.064409,0.000000
81.510002,62.495270,-33.138309,0.021139,0.002527,0.064183,277.992859,14.161631,0.641831,-33.138309,0.064409,0.000000
81.730003,62.478882,-33.138309,0.021135,0.002527,0.064183,277.919952,14.157917,0.641831,-33.138309,0.064409,0.000000
81.950005,62.456169,-33.093826,0.021144,0.002527,0.064183,277.818909,14.152770,0.641831,-33.093826,0.064409,0.000000
82.170006,62.463242,-33.093826,0.021126,0.002527,0.064183,277.850372,14.154372,0.641831,-33.093826,0.064409,0.000000
82.390007,62.426376,-33.093826,0.021131,0.002527,0.064183,277.686401,14.146019,0.641831,-33.093826,0.064409,0.000000
82.610001,62.420792,-33.138309,0.021152,0.002527,0.064183,277.661560,14.144753,0.641831,-33.138309,0.064409,0.000000
82.830002,62.403664,-33.093826,0.021126,0.002527,0.064183,277.585358,14.140872,0.641831,-33.093826,0.064409,0.000000
83.050003,62.397705,-33.138309,0.021135,0.002527,0.064183,277.558868,14.139523,0.641831,-33.138309,0.064409,0.000000
83.270004,62.361214,-33.138309,0.021126,0.002527,0.064183,277.396545,14.131252,0.641831,-33.138309,0.064409,0.000000
83.490005,62.357491,-33.138309,0.021135,0.002527,0.064183,277.379974,14.130409,0.641831,-33.138309,0.064409,0.000000
83.710007,62.341850,-33.138309,0.021157,0.002527,0.064183,277.310394,14.126865,0.641831,-33.138309,0.064409,0.000000
83.930000,62.322861,-33.138309,0.021139,0.002527,0.064183,277.225922,14.122561,0.641831,-33.138309,0.064409,0.000000
84.150002,62.315781,-33.049347,0.021157,0.002527,0.064183,277.194427,14.120957,0.641831,-33.049347,0.064409,0.000000
84.370003,62.300514,-33.138309,0.021131,0.002527,0.064183,277.126526,14.117498,0.641831,-33.138309,0.064409,0.000000
84.590004,62.273705,-33.138309,0.021118,0.002527,0.064183,277.007263,14.111423,0.641831,-33.138309,0.064409,0.000000
84.810005,62.261421,-33.138309,0.021139,0.002527,0.064183,276.952637,14.108640,0.641831,-33.138309,0.064409,0.000000
85.030006,62.241684,-33.182789,0.021161,0.002527,0.064183,276.864838,14.104167,0.641831,-33.182789,0.064409,0.000000
85.250008,62.236465,-33.138309,0.021135,0.002527,0.064183,276.841614,14.102984,0.641831,-33.138309,0.064409,0.000000
85.470001,62.226418,-33.138309,0.021101,0.002527,0.064183,276.796936,14.100707,0.641831,-33.138309,0.064409,0.000000
85.690002,62.218964,-33.138309,0.021131,0.002527,0.064183,276.763763,14.099019,0.641831,-33.138309,0.064409,0.000000
85.910004,62.193275,-33.182789,0.021144,0.002527,0.064183,276.649506,14.093198,0.641831,-33.182789,0.064409,0.000000
86.130005,62.191040,-33.138309,0.021139,0.002527,0.064183,276.639557,14.092691,0.641831,-33.138309,0.064409,0.000000
86.350006,62.182472,-33.138309,0.021122,0.002527,0.064183,276.601440,14.090750,0.641831,-33.138309,0.064409,0.000000
86.570007,62.168694,-33.138309,0.021144,0.002527,0.064183,276.540161,14.087627,0.641831,-33.138309,0.064409,0.000000
86.790001,62.146729,-33.182789,0.021139,0.002527,0.064183,276.442444,14.082649,0.641831,-33.182789,0.064409,0.000000
87.010002,62.146729,-33.182789,0.021131,0.002527,0.064183,276.442444,14.082649,0.641831,-33.182789,0.064409,0.000000
87.230003,62.125130,-33.227272,0.021126,0.002527,0.064183,276.346375,14.077755,0.641831,-33.227272,0.064409,0.000000
87.450005,62.106140,-33.138309,0.021148,0.002527,0.064183,276.261902,14.073452,0.641831,-33.138309,0.064409,0.000000
87.670006,62.102043,-33.182789,0.021144,0.002527,0.064183,276.243683,14.072524,0.641831,-33.182789,0.064409,0.000000
87.890007,62.072250,-33.182789,0.021131,0.002527,0.064183,276.111145,14.065773,0.641831,-33.182789,0.064409,0.000000
88.110001,62.051025,-33.138309,0.021139,0.002527,0.064183,276.016754,14.060963,0.641831,-33.138309,0.064409,0.000000
88.330002,62.057732,-33.182789,0.021148,0.002527,0.064183,276.046570,14.062483,0.641831,-33.182789,0.064409,0.000000
88.550003,62.055870,-33.182789,0.021152,0.002527,0.064183,276.038300,14.062061,0.641831,-33.182789,0.064409,0.000000
88.770004,62.052513,-33.182789,0.021109,0.002527,0.064183,276.023376,14.061301,0.641831,-33.182789,0.064409,0.000000
88.990005,62.026825,-33.182789,0.021126,0.002527,0.064183,275.909088,14.055480,0.641831,-33.182789,0.064409,0.000000
89.210007,62.013786,-33.138309,0.021144,0.002527,0.064183,275.851105,14.052525,0.641831,-33.138309,0.064409,0.000000
89.430008,61.996658,-33.138309,0.021144,0.002527,0.064183,275.774902,14.048644,0.641831,-33.138309,0.064409,0.000000
89.650002,61.989212,-33.182789,0.021148,0.002527,0.064183,275.741791,14.046956,0.641831,-33.182789,0.064409,0.000000
89.870003,61.985115,-33.182789,0.021139,0.002527,0.064183,275.723572,14.046028,0.641831,-33.182789,0.064409,0.000000
90.090004,61.962776,-33.138309,0.021135,0.002527,0.064183,275.624207,14.040966,0.641831,-33.138309,0.064409,0.000000
90.310005,61.952347,-33.182789,0.021144,0.002527,0.064183,275.577789,14.038602,0.641831,-33.182789,0.064409,0.000000
90.530006,61.946022,-33.182789,0.021126,0.002527,0.064183,275.549683,14.037169,0.641831,-33.182789,0.064409,0.000000
90.750008,61.944153,-33.182789,0.021135,0.002527,0.064183,275.541351,14.036745,0.641831,-33.182789,0.064409,0.000000
90.970001,61.929634,-33.138309,0.021139,0.002527,0.064183,275.476776,14.033456,0.641831,-33.138309,0.064409,0.000000
91.190002,61.929634,-33.138309,0.021118,0.002527,0.064183,275.476776,14.033456,0.641831,-33.138309,0.064409,0.000000
91.410004,61.913620,-33.227272,0.021122,0.002527,0.064183,275.405548,14.029827,0.641831,-33.227272,0.064409,0.000000
91.630005,61.888298,-33.227272,0.021122,0.002527,0.064183,275.292908,14.024088,0.641831,-33.227272,0.064409,0.000000
91.850006,61.881973,-33.227272,0.021122,0.002527,0.064183,275.264771,14.022655,0.641831,-33.227272,0.064409,0.000000
92.070007,61.877129,-33.182789,0.021148,0.002527,0.064183,275.243225,14.021558,0.641831,-33.182789,0.064409,0.000000
92.290001,61.869308,-33.138309,0.021131,0.002527,0.064183,275.208435,14.019786,0.641831,-33.138309,0.064409,0.000000
92.510002,61.856277,-33.227272,0.021135,0.002527,0.064183,275.150452,14.016833,0.641831,-33.227272,0.064409,0.000000
92.730003,61.841011,-33.227272,0.021144,0.002527,0.064183,275.082550,14.013373,0.641831,-33.227272,0.064409,0.000000
92.950005,61.835052,-33.227272,0.021126,0.002527,0.064183,275.056061,14.012023,0.641831,-33.227272,0.064409,0.000000
93.170006,61.827980,-33.182789,0.021144,0.002527,0.064183,275.024597,14.010421,0.641831,-33.182789,0.064409,0.000000
93.390007,61.810844,-33.138309,0.021126,0.002527,0.064183,274.948364,14.006538,0.641831,-33.138309,0.064409,0.000000
93.610008,61.796326,-33.182789,0.021144,0.002527,0.064183,274.883789,14.003248,0.641831,-33.182789,0.064409,0.000000
93.830002,61.798187,-33.227272,0.021122,0.002527,0.064183,274.892059,14.003669,0.641831,-33.227272,0.064409,0.000000
93.900002,61.789619,-33.182789,0.021126,0.002527,0.064183,274.853943,14.001728,0.641831,-33.182789,0.064409,0.000000