File: Data/I-18_1_1_07282023_141413.csv
Time (sec),S:Load (lbs),S:HL1 (DIM),S:LVDT (in),S:Position (in),Ch:Position (mm),Ch:Load (N),Ch:Stress (MPa),Ch:Strain (mm/mm),Ch:HL1 (DIM),Set Point (),Cycles ()
0.210000,-0.007820,-30.336008,0.000013,-0.000000,-0.000000,-0.034784,-0.001772,-0.000000,-30.336008,0.000208,0.000000
0.450000,-0.015267,-30.336008,0.000004,0.000014,0.000347,-0.067912,-0.003460,0.003475,-30.336008,0.000885,0.000000
0.690000,0.010054,-30.336008,0.000004,0.000150,0.003799,0.044723,0.002278,0.037985,-30.336008,0.004874,0.000000
0.930000,0.034631,-30.380489,0.000134,0.000299,0.007589,0.154045,0.007847,0.075887,-30.380489,0.008881,0.000000
1.170000,0.049153,-30.291527,0.000280,0.000466,0.011829,0.218644,0.011138,0.118293,-30.291527,0.012870,0.000000
1.410000,0.018246,-30.336008,0.000453,0.000622,0.015801,0.081164,0.004135,0.158012,-30.336008,0.016876,0.000000
1.650000,0.008937,-30.291527,0.000604,0.000773,0.019625,0.039754,0.002025,0.196254,-30.291527,0.020883,0.000000
1.890000,0.023087,-30.291527,0.000742,0.000930,0.023615,0.102696,0.005232,0.236147,-30.291527,0.024872,0.000000
2.130000,0.016757,-30.247047,0.000914,0.001091,0.027699,0.074538,0.003797,0.276994,-30.247047,0.028879,0.000000
2.370000,0.029045,-30.247047,0.001056,0.001254,0.031845,0.129199,0.006582,0.318446,-30.247047,0.032868,0.000000
2.610000,0.025321,-30.247047,0.001246,0.001406,0.035704,0.112635,0.005738,0.357037,-30.247047,0.036875,0.000000
2.850000,0.029790,-30.247047,0.001401,0.001564,0.039719,0.132512,0.006750,0.397194,-30.247047,0.040864,0.000000
3.090000,0.045429,-30.247047,0.001552,0.001713,0.043501,0.202080,0.010294,0.435006,-30.247047,0.044871,0.000000
3.330000,0.051760,-30.247047,0.001720,0.001885,0.047871,0.230239,0.011729,0.478714,-30.247047,0.048860,0.000000
3.570000,0.018991,-30.202566,0.001884,0.002037,0.051748,0.084476,0.004303,0.517478,-30.202566,0.052867,0.000000
3.810000,0.023087,-30.291527,0.002044,0.002191,0.055658,0.102696,0.005232,0.556584,-30.291527,0.056855,0.000000
4.050000,0.039099,-30.158085,0.002195,0.002348,0.059648,0.173921,0.008860,0.596477,-30.158085,0.060862,0.000000
4.290000,0.023459,-30.202566,0.002376,0.002510,0.063741,0.104353,0.005316,0.637414,-30.202566,0.064851,0.000000
4.530000,0.026066,-30.158085,0.002531,0.002668,0.067756,0.115948,0.005907,0.677564,-30.158085,0.068858,0.000000
4.770000,0.040216,-30.158085,0.002695,0.002826,0.071789,0.178891,0.009113,0.717889,-30.158085,0.072847,0.000000
5.010000,0.058463,-30.202566,0.002833,0.002973,0.075527,0.260054,0.013248,0.755268,-30.202566,0.076854,0.000000
5.250000,0.050643,-30.113604,0.002992,0.003141,0.079794,0.225270,0.011476,0.797939,-30.113604,0.080843,0.000000
5.490000,0.028673,-30.113604,0.003147,0.003297,0.083739,0.127543,0.006497,0.837393,-30.113604,0.084850,0.000000
5.730000,0.027183,-30.113604,0.003320,0.003449,0.087598,0.120917,0.006160,0.875984,-30.113604,0.088839,0.000000
5.970000,0.044312,-30.113604,0.003458,0.003607,0.091622,0.197111,0.010041,0.916225,-30.113604,0.092846,0.000000
6.210001,0.021970,-30.202566,0.003622,0.003767,0.095690,0.097727,0.004978,0.956897,-30.202566,0.096834,0.000000
6.450000,0.017129,-30.069122,0.003790,0.003925,0.099705,0.076194,0.003882,0.997055,-30.069122,0.100841,0.000000
6.690001,0.024577,-30.113604,0.003949,0.004087,0.103807,0.109322,0.005569,1.038068,-30.113604,0.104848,0.000000
6.930000,0.040961,-30.069122,0.004109,0.004238,0.107649,0.182203,0.009282,1.076492,-30.069122,0.108837,0.000000
7.170001,0.072240,-30.069122,0.004273,0.004389,0.111491,0.321341,0.016370,1.114909,-30.069122,0.112844,0.000000
7.410000,0.061814,-30.113604,0.004445,0.004560,0.115835,0.274962,0.014007,1.158352,-30.113604,0.116833,0.000000
7.650001,0.038354,-30.024641,0.004596,0.004716,0.119781,0.170609,0.008691,1.197813,-30.024641,0.120840,0.000000
7.890000,0.053622,-30.113604,0.004738,0.004870,0.123701,0.238521,0.012151,1.237010,-30.113604,0.124829,0.000000
8.130000,0.030162,-30.024641,0.004907,0.005025,0.127639,0.134168,0.006835,1.276388,-30.024641,0.128836,0.000000
8.370001,0.023087,-30.024641,0.005079,0.005188,0.131775,0.102696,0.005232,1.317749,-30.024641,0.132825,0.000000
8.610001,-0.015640,-29.980162,0.005213,0.005340,0.135634,-0.069568,-0.003544,1.356340,-29.980162,0.136831,0.000000
8.850000,0.051015,-29.980162,0.005394,0.005500,0.139710,0.226926,0.011560,1.397103,-29.980162,0.140820,0.000000
9.090000,0.085273,-30.024641,0.005553,0.005649,0.143474,0.379315,0.019323,1.434740,-30.024641,0.144827,0.000000
9.330001,0.077081,-29.935680,0.005717,0.005814,0.147671,0.342874,0.017467,1.476715,-29.935680,0.148816,0.000000
9.570001,0.058463,-29.935680,0.005885,0.005973,0.151721,0.260054,0.013248,1.517213,-29.935680,0.152823,0.000000
9.810000,0.043195,-29.980162,0.006032,0.006135,0.155823,0.192142,0.009788,1.558234,-29.980162,0.156812,0.000000
10.050000,0.059952,-29.935680,0.006183,0.006281,0.159527,0.266680,0.013585,1.595265,-29.935680,0.160819,0.000000
10.290001,0.028300,-29.980162,0.006338,0.006448,0.163767,0.125886,0.006413,1.637671,-29.980162,0.164808,0.000000
10.530001,-0.010426,-29.935680,0.006519,0.006603,0.167713,-0.046379,-0.002363,1.677132,-29.935680,0.168815,0.000000
10.770000,0.056228,-29.935680,0.006670,0.006762,0.171754,0.250116,0.012742,1.717540,-29.935680,0.172804,0.000000
11.010000,0.057345,-29.935680,0.006821,0.006909,0.175501,0.255085,0.012995,1.755010,-29.935680,0.176810,0.000000
11.250001,0.087880,-29.846718,0.006998,0.007066,0.179464,0.390909,0.019914,1.794638,-29.846718,0.180817,0.000000
11.490001,0.035003,-29.891199,0.007144,0.007232,0.183704,0.155701,0.007932,1.837044,-29.891199,0.184806,0.000000
11.730000,0.075964,-29.846718,0.007317,0.007392,0.187746,0.337905,0.017214,1.877459,-29.846718,0.188813,0.000000
11.970000,0.054739,-29.846718,0.007463,0.007549,0.191753,0.243490,0.012404,1.917526,-29.846718,0.192802,0.000000
12.210001,0.057345,-29.802237,0.007618,0.007704,0.195681,0.255085,0.012995,1.956813,-29.802237,0.196808,0.000000
12.450001,0.045802,-29.891199,0.007817,0.007862,0.199687,0.203737,0.010379,1.996873,-29.891199,0.200798,0.000000
12.690001,-0.010799,-29.846718,0.007968,0.008020,0.203703,-0.048036,-0.002447,2.037030,-29.846718,0.204804,0.000000
12.930000,0.074102,-29.802237,0.008106,0.008175,0.207658,0.329623,0.016792,2.076575,-29.802237,0.208794,0.000000
13.170001,0.085273,-29.802237,0.008252,0.008327,0.211508,0.379315,0.019323,2.115083,-29.802237,0.212800,0.000000
13.410001,0.084529,-29.846718,0.008438,0.008494,0.215740,0.376002,0.019154,2.157398,-29.846718,0.216789,0.000000
13.650001,0.055856,-29.802237,0.008593,0.008648,0.219668,0.248459,0.012657,2.196685,-29.802237,0.220796,0.000000
13.890000,0.071868,-29.846718,0.008739,0.008809,0.223753,0.319684,0.016286,2.237531,-29.846718,0.224785,0.000000
14.130001,0.080432,-29.713276,0.008886,0.008966,0.227733,0.357782,0.018226,2.277333,-29.713276,0.228792,0.000000
14.370001,0.063676,-29.713276,0.009033,0.009126,0.231801,0.283244,0.014429,2.318006,-29.713276,0.232781,0.000000
14.610001,0.019363,-29.846718,0.009209,0.009277,0.235634,0.086133,0.004388,2.356339,-29.846718,0.236788,0.000000
14.850000,0.051015,-29.713276,0.009382,0.009437,0.239710,0.226926,0.011560,2.397103,-29.713276,0.240777,0.000000
15.090001,0.100168,-29.757757,0.009559,0.009588,0.243526,0.445570,0.022698,2.435262,-29.757757,0.244784,0.000000
15.330001,0.081550,-29.668795,0.009718,0.009751,0.247680,0.362751,0.018479,2.476797,-29.668795,0.248773,0.000000
15.570001,0.033886,-29.668795,0.009891,0.009912,0.251756,0.150732,0.007679,2.517561,-29.668795,0.252780,0.000000
15.810000,0.058463,-29.713276,0.010046,0.010063,0.255598,0.260054,0.013248,2.555977,-29.713276,0.256785,0.000000
16.050001,0.086763,-29.668795,0.010227,0.010220,0.259595,0.385940,0.019661,2.595953,-29.668795,0.260775,0.000000
16.290001,0.048408,-29.668795,0.010365,0.010386,0.263802,0.215332,0.010970,2.638019,-29.668795,0.264781,0.000000
16.530001,0.020853,-29.668795,0.010529,0.010539,0.267696,0.092758,0.004725,2.676958,-29.668795,0.268771,0.000000
16.770000,0.030907,-29.624313,0.010671,0.010690,0.271520,0.137481,0.007004,2.715200,-29.624313,0.272777,0.000000
17.010000,0.065538,-29.668795,0.010861,0.010849,0.275552,0.291526,0.014851,2.755525,-29.668795,0.276767,0.000000
17.250000,0.075964,-29.579832,0.010994,0.011005,0.279524,0.337905,0.017214,2.795243,-29.579832,0.280773,0.000000
17.490002,0.067772,-29.713276,0.011154,0.011171,0.283748,0.301464,0.015357,2.837475,-29.713276,0.284763,0.000000
17.730001,0.052132,-29.579832,0.011322,0.011327,0.287694,0.231896,0.011813,2.876936,-29.579832,0.288769,0.000000
17.970001,0.069634,-29.579832,0.011477,0.011485,0.291726,0.309746,0.015779,2.917261,-29.579832,0.292759,0.000000
18.210001,0.089742,-29.624313,0.011641,0.011638,0.295612,0.399191,0.020336,2.956116,-29.624313,0.296765,0.000000
18.450001,0.062186,-29.579832,0.011805,0.011800,0.299722,0.276618,0.014092,2.997221,-29.579832,0.300754,0.000000
18.690001,0.037982,-29.579832,0.011969,0.011953,0.303608,0.168952,0.008607,3.036076,-29.579832,0.304760,0.000000
18.930000,0.077081,-29.535351,0.012115,0.012109,0.307579,0.342874,0.017467,3.075795,-29.535351,0.308750,0.000000
19.170000,0.080060,-29.535351,0.012271,0.012265,0.311534,0.356125,0.018142,3.115340,-29.535351,0.312756,0.000000
19.410002,0.087508,-29.579832,0.012443,0.012431,0.315748,0.389253,0.019829,3.157480,-29.579832,0.316746,0.000000
19.650002,0.048036,-29.535351,0.012620,0.012586,0.319686,0.213675,0.010885,3.196859,-29.535351,0.320752,0.000000
19.890001,0.078943,-29.535351,0.012766,0.012743,0.323675,0.351156,0.017889,3.236751,-29.535351,0.324742,0.000000
20.130001,0.073730,-29.446390,0.012939,0.012894,0.327517,0.327966,0.016707,3.275168,-29.446390,0.328748,0.000000
20.370001,0.086018,-29.446390,0.013111,0.013062,0.331775,0.382627,0.019492,3.317748,-29.446390,0.332738,0.000000
20.610001,0.058835,-29.535351,0.013254,0.013216,0.335686,0.261710,0.013332,3.356861,-29.535351,0.336744,0.000000
20.850000,0.055856,-29.401909,0.013396,0.013366,0.339502,0.248459,0.012657,3.395020,-29.401909,0.340750,0.000000
21.090000,0.093093,-29.446390,0.013555,0.013525,0.343543,0.414099,0.021095,3.435428,-29.446390,0.344740,0.000000
21.330002,0.076336,-29.446390,0.013711,0.013684,0.347575,0.339561,0.017298,3.475752,-29.446390,0.348746,0.000000
21.570002,0.094583,-29.446390,0.013862,0.013846,0.351677,0.420724,0.021433,3.516773,-29.446390,0.352736,0.000000
21.810001,0.078571,-29.401909,0.014030,0.014002,0.355641,0.349499,0.017804,3.556408,-29.401909,0.356742,0.000000
22.050001,0.102402,-29.357428,0.014176,0.014154,0.359517,0.455509,0.023205,3.595173,-29.357428,0.360732,0.000000
22.290001,0.091604,-29.401909,0.014323,0.014310,0.363472,0.407473,0.020758,3.634718,-29.401909,0.364738,0.000000
22.530001,0.062931,-29.401909,0.014495,0.014476,0.367687,0.279931,0.014260,3.676867,-29.401909,0.368727,0.000000
22.770000,0.080805,-29.357428,0.014655,0.014629,0.371581,0.359438,0.018311,3.715806,-29.357428,0.372734,0.000000
23.010000,0.092348,-29.401909,0.014814,0.014786,0.375552,0.410786,0.020926,3.755524,-29.401909,0.376723,0.000000
23.250002,0.091231,-29.312946,0.014965,0.014941,0.379499,0.405817,0.020673,3.794986,-29.312946,0.380729,0.000000
23.490002,0.091976,-29.312946,0.015125,0.015103,0.383617,0.409130,0.020842,3.836173,-29.312946,0.384719,0.000000
23.730001,0.085646,-29.268465,0.015293,0.015262,0.387667,0.380971,0.019408,3.876671,-29.268465,0.388725,0.000000
23.970001,0.087508,-29.268465,0.015435,0.015421,0.391691,0.389253,0.019829,3.916912,-29.268465,0.392715,0.000000
24.210001,0.111712,-29.312946,0.015612,0.015568,0.395420,0.496919,0.025314,3.954201,-29.312946,0.396721,0.000000
24.450001,0.110595,-29.268465,0.015780,0.015739,0.399765,0.491949,0.025061,3.997652,-29.268465,0.400711,0.000000
24.690001,0.079688,-29.268465,0.015961,0.015892,0.403668,0.354469,0.018057,4.036681,-29.268465,0.404717,0.000000
24.930000,0.089742,-29.268465,0.016164,0.016047,0.407596,0.399191,0.020336,4.075961,-29.268465,0.408707,0.000000
25.170002,0.085273,-29.223986,0.016336,0.016201,0.411499,0.379315,0.019323,4.114991,-29.223986,0.412713,0.000000
25.410002,0.054739,-29.223986,0.016535,0.016363,0.415618,0.243490,0.012404,4.156178,-29.223986,0.416719,0.000000
25.650002,0.023832,-29.179504,0.016716,0.016518,0.419547,0.106009,0.005400,4.195465,-29.179504,0.420708,0.000000
25.890001,0.058463,-29.223986,0.016893,0.016679,0.423658,0.260054,0.013248,4.236577,-29.223986,0.424715,0.000000
26.130001,0.087880,-29.179504,0.017056,0.016828,0.427421,0.390909,0.019914,4.274214,-29.179504,0.428704,0.000000
26.370001,0.095327,-29.179504,0.017203,0.016986,0.431454,0.424037,0.021601,4.314538,-29.179504,0.432711,0.000000
26.610001,0.077081,-29.179504,0.017393,0.017153,0.435686,0.342874,0.017467,4.356861,-29.179504,0.436700,0.000000
26.850000,0.055484,-29.135023,0.017565,0.017311,0.439692,0.246803,0.012573,4.396920,-29.135023,0.440707,0.000000
27.090002,0.072240,-29.179504,0.017725,0.017462,0.443525,0.321341,0.016370,4.435254,-29.179504,0.444696,0.000000
27.330002,0.047664,-29.090542,0.017884,0.017619,0.447532,0.212019,0.010801,4.475320,-29.090542,0.448703,0.000000
27.570002,0.025694,-29.046061,0.018044,0.017782,0.451669,0.114291,0.005822,4.516689,-29.046061,0.452692,0.000000
27.810001,0.014150,-29.090542,0.018220,0.017938,0.455614,0.062943,0.003206,4.556143,-29.090542,0.456698,0.000000
28.050001,0.075592,-29.001579,0.018363,0.018092,0.459526,0.336248,0.017129,4.595256,-29.001579,0.460688,0.000000
28.290001,0.093093,-29.090542,0.018527,0.018241,0.463324,0.414099,0.021095,4.633241,-29.090542,0.464694,0.000000
28.530001,0.099051,-29.046061,0.018695,0.018410,0.467625,0.440601,0.022445,4.676253,-29.046061,0.468684,0.000000
28.770000,0.082667,-29.046061,0.018850,0.018567,0.471598,0.367720,0.018733,4.715979,-29.046061,0.472690,0.000000
29.010002,0.070751,-29.001579,0.019018,0.018729,0.475726,0.314715,0.016032,4.757257,-29.001579,0.476680,0.000000
29.250002,0.084156,-28.912619,0.019182,0.018875,0.479420,0.374345,0.019070,4.794198,-28.912619,0.480686,0.000000
29.490002,0.049898,-29.001579,0.019346,0.019041,0.483635,0.221957,0.011307,4.836346,-29.001579,0.484675,0.000000
29.730001,0.000372,-29.001579,0.019514,0.019197,0.487606,0.001657,0.000084,4.876065,-29.001579,0.488682,0.000000
29.970001,0.079688,-28.957100,0.019665,0.019356,0.491631,0.354469,0.018057,4.916306,-28.957100,0.492688,0.000000
30.210001,0.098306,-29.001579,0.019850,0.019506,0.495464,0.437289,0.022277,4.954639,-29.001579,0.496677,0.000000
30.450001,0.096072,-28.912619,0.019984,0.019666,0.499514,0.427350,0.021770,4.995138,-28.912619,0.500684,0.000000
30.690001,0.056601,-28.912619,0.020169,0.019828,0.503632,0.251772,0.012826,5.036325,-28.912619,0.504673,0.000000
30.930002,0.081550,-28.868137,0.020333,0.019988,0.507683,0.362751,0.018479,5.076831,-28.868137,0.508680,0.000000
31.170002,0.084529,-28.868137,0.020488,0.020142,0.511603,0.376002,0.019154,5.116027,-28.868137,0.512669,0.000000
31.410002,0.090487,-28.868137,0.020639,0.020302,0.515678,0.402504,0.020505,5.156783,-28.868137,0.516676,0.000000
31.650002,0.043568,-28.823656,0.020812,0.020455,0.519555,0.193798,0.009873,5.195548,-28.823656,0.520665,0.000000
31.890001,0.033886,-28.868137,0.020963,0.020614,0.523596,0.150732,0.007679,5.235963,-28.868137,0.524672,0.000000
32.130001,0.087508,-28.868137,0.021144,0.020768,0.527499,0.389253,0.019829,5.274985,-28.868137,0.528661,0.000000
32.370003,0.095700,-28.868137,0.021299,0.020921,0.531402,0.425694,0.021686,5.314015,-28.868137,0.532668,0.000000
32.610001,0.080432,-28.823656,0.021476,0.021090,0.535677,0.357782,0.018226,5.356770,-28.823656,0.536656,0.000000
32.850002,0.093466,-28.823656,0.021644,0.021242,0.539536,0.415755,0.021180,5.395360,-28.823656,0.540663,0.000000
33.090000,0.136661,-28.779175,0.021816,0.021400,0.543568,0.607897,0.030968,5.435685,-28.779175,0.544652,0.000000
33.330002,0.236829,-28.779175,0.021971,0.021559,0.547610,1.053468,0.053666,5.476099,-28.779175,0.548659,0.000000
33.570000,0.502703,-28.734694,0.022118,0.021720,0.551686,2.236134,0.113914,5.516855,-28.734694,0.552648,0.000000
33.810001,0.571964,-28.734694,0.022209,-0.000000,-0.000008,2.544224,0.129609,-0.000083,-28.734694,0.000216,0.000000
34.050003,0.566006,-28.645733,0.022213,-0.000000,-0.000008,2.517721,0.128259,-0.000083,-28.645733,0.000216,0.000000
34.290001,0.618138,-28.779175,0.022222,-0.000000,-0.000008,2.749617,0.140072,-0.000083,-28.779175,0.000364,0.000000
34.530003,0.617766,-28.645733,0.022222,-0.000000,-0.000008,2.747960,0.139988,-0.000083,-28.645733,0.000763,0.000000
34.770000,0.637502,-28.690214,0.022213,-0.000000,-0.000008,2.835749,0.144460,-0.000083,-28.690214,0.001162,0.000000
35.010002,0.770811,-28.690214,0.022217,0.000023,0.000581,3.428739,0.174668,0.005814,-28.690214,0.001561,0.000000
35.250000,0.863532,-28.601252,0.022230,0.000042,0.001076,3.841181,0.195679,0.010757,-28.601252,0.001960,0.000000
35.490002,0.934283,-28.645733,0.022247,0.000060,0.001535,4.155896,0.211711,0.015352,-28.645733,0.002368,0.000000
35.730003,1.012853,-28.556770,0.022260,0.000074,0.001882,4.505396,0.229516,0.018818,-28.556770,0.002767,0.000000
35.970001,1.070199,-28.601252,0.022265,0.000090,0.002290,4.760481,0.242510,0.022899,-28.601252,0.003166,0.000000
36.210003,1.113766,-28.645733,0.022286,0.000101,0.002559,4.954279,0.252383,0.025586,-28.645733,0.003565,0.000000
36.450001,1.273886,-28.512289,0.022303,0.000118,0.002992,5.666529,0.288667,0.029916,-28.512289,0.003964,0.000000
36.690002,1.376661,-28.601252,0.022308,0.000132,0.003356,6.123694,0.311956,0.033564,-28.601252,0.004362,0.000000
36.930000,1.477946,-28.512289,0.022334,0.000145,0.003686,6.574234,0.334907,0.036857,-28.512289,0.004761,0.000000
37.170002,1.594871,-28.467808,0.022342,0.000166,0.004206,7.094342,0.361403,0.042058,-28.467808,0.005160,0.000000
37.410004,1.785154,-28.467808,0.022360,0.000183,0.004649,7.940760,0.404522,0.046486,-28.467808,0.005568,0.000000
37.650002,1.903940,-28.467808,0.022368,0.000200,0.005091,8.469150,0.431439,0.050907,-28.467808,0.005967,0.000000
37.890003,2.005970,-28.467808,0.022377,0.000216,0.005481,8.923002,0.454559,0.054805,-28.467808,0.006365,0.000000
38.130001,2.117310,-28.512289,0.022398,0.000229,0.005811,9.418264,0.479789,0.058106,-28.512289,0.006764,0.000000
38.370003,2.338499,-28.467808,0.022416,0.000245,0.006218,10.402164,0.529911,0.062178,-28.467808,0.007163,0.000000
38.610001,2.511652,-28.467808,0.022441,0.000258,0.006565,11.172387,0.569149,0.065653,-28.467808,0.007562,0.000000
38.850002,2.576818,-28.423328,0.022441,0.000266,0.006764,11.462256,0.583915,0.067644,-28.423328,0.007961,0.000000
39.090000,2.837478,-28.423328,0.022450,0.000289,0.007337,12.621734,0.642982,0.073366,-28.423328,0.008368,0.000000
39.330002,3.097022,-28.378847,0.022472,0.000307,0.007805,13.776240,0.701795,0.078052,-28.378847,0.008767,0.000000
39.570004,3.299592,-28.378847,0.022485,0.000322,0.008187,14.677320,0.747698,0.081867,-28.378847,0.009166,0.000000
39.810001,3.474607,-28.378847,0.022497,0.000339,0.008611,15.455826,0.787357,0.086114,-28.378847,0.009565,0.000000
40.050003,3.672709,-28.334366,0.022515,0.000354,0.008993,16.337029,0.832248,0.089929,-28.334366,0.009964,0.000000
40.290001,3.995929,-28.334366,0.022515,0.000372,0.009444,17.774778,0.905490,0.094441,-28.334366,0.010363,0.000000
40.530003,4.187701,-28.289885,0.022536,0.000384,0.009765,18.627823,0.948947,0.097650,-28.289885,0.010762,0.000000
40.770000,4.399208,-28.334366,0.022545,0.000398,0.010112,19.568655,0.996875,0.101117,-28.334366,0.011161,0.000000
41.010002,4.549647,-28.334366,0.022554,0.000407,0.010329,20.237841,1.030965,0.103290,-28.334366,0.011569,0.000000
41.250004,4.988674,-28.289885,0.022575,0.000432,0.010979,22.190731,1.130450,0.109792,-28.289885,0.011968,0.000000
41.490002,5.327160,-28.289885,0.022588,0.000452,0.011474,23.696392,1.207152,0.114735,-28.289885,0.012367,0.000000
41.730003,5.536806,-28.245403,0.022614,0.000468,0.011881,24.628944,1.254658,0.118808,-28.245403,0.012766,0.000000
41.970001,5.759857,-28.289885,0.022618,0.000481,0.012219,25.621124,1.305202,0.122192,-28.289885,0.013165,0.000000
42.210003,6.093131,-28.289885,0.022648,0.000499,0.012670,27.103598,1.380723,0.126703,-28.289885,0.013564,0.000000
42.450001,6.291977,-28.200924,0.022657,0.000510,0.012947,27.988113,1.425782,0.129474,-28.200924,0.013962,0.000000
42.690002,6.484494,-28.200924,0.022666,0.000520,0.013217,28.844471,1.469407,0.132169,-28.200924,0.014361,0.000000
42.930000,6.799521,-28.156443,0.022674,0.000537,0.013650,30.245783,1.540794,0.136498,-28.156443,0.014769,0.000000
43.170002,7.346164,-28.200924,0.022679,0.000561,0.014257,32.677372,1.664665,0.142569,-28.200924,0.015168,0.000000
43.410004,7.603474,-28.156443,0.022704,0.000576,0.014638,33.821941,1.722972,0.146385,-28.156443,0.015567,0.000000
43.650002,7.878284,-28.156443,0.022713,0.000593,0.015055,35.044361,1.785245,0.150548,-28.156443,0.015965,0.000000
43.890003,8.162777,-28.111961,0.022722,0.000607,0.015420,36.309845,1.849712,0.154197,-28.111961,0.016364,0.000000
44.130001,8.569036,-28.067480,0.022752,0.000626,0.015897,38.116974,1.941771,0.158966,-28.067480,0.016763,0.000000
44.370003,8.814801,-28.111961,0.022761,0.000639,0.016234,39.210194,1.997463,0.162342,-28.111961,0.017162,0.000000
44.610001,8.987209,-28.067480,0.022769,0.000649,0.016495,39.977104,2.036531,0.164946,-28.067480,0.017561,0.000000
44.850002,9.312663,-28.111961,0.022778,0.000663,0.016850,41.424793,2.110280,0.168504,-28.111961,0.017969,0.000000
45.090004,9.556939,-28.067480,0.022799,0.000676,0.017180,42.511387,2.165633,0.171796,-28.067480,0.018368,0.000000
45.330002,10.264074,-28.022999,0.022834,0.000703,0.017847,45.656883,2.325872,0.178473,-28.022999,0.018767,0.000000
45.570004,10.550801,-28.022999,0.022834,0.000720,0.018281,46.932308,2.390846,0.182810,-28.022999,0.019166,0.000000
45.810001,10.791726,-28.022999,0.022851,0.000734,0.018654,48.003994,2.445440,0.186542,-28.022999,0.019565,0.000000
46.050003,11.115318,-27.978518,0.022860,0.000751,0.019079,49.443405,2.518767,0.190789,-27.978518,0.019964,0.000000
46.290001,11.479499,-27.978518,0.022868,0.000764,0.019400,51.063362,2.601291,0.193999,-27.978518,0.020363,0.000000
46.530003,11.638874,-27.978518,0.022890,0.000775,0.019695,51.772297,2.637407,0.196951,-27.978518,0.020762,0.000000
46.770000,12.077156,-27.978518,0.022886,0.000790,0.020077,53.721874,2.736723,0.200766,-27.978518,0.021169,0.000000
47.010002,12.488627,-27.934038,0.022907,0.000809,0.020536,55.552189,2.829963,0.205361,-27.934038,0.021568,0.000000
47.250004,13.025961,-27.934038,0.022920,0.000827,0.021013,57.942368,2.951725,0.210130,-27.934038,0.021967,0.000000
47.490002,13.342478,-27.934038,0.022937,0.000846,0.021482,59.350304,3.023449,0.214815,-27.934038,0.022366,0.000000
47.730003,13.584520,-27.889557,0.022959,0.000860,0.021837,60.426964,3.078296,0.218366,-27.889557,0.022765,0.000000
47.970001,13.783367,-27.934038,0.022959,0.000873,0.022167,61.311478,3.123356,0.221666,-27.934038,0.023164,0.000000
48.210003,14.427198,-27.889557,0.022972,0.000892,0.022669,64.175385,3.269250,0.226692,-27.889557,0.023562,0.000000
48.450001,14.478958,-27.889557,0.022985,0.000903,0.022947,64.405624,3.280979,0.229471,-27.889557,0.023961,0.000000
48.690002,14.766430,-27.934038,0.023006,0.000916,0.023276,65.684364,3.346121,0.232763,-27.934038,0.024369,0.000000
48.930004,15.729012,-27.845076,0.023019,0.000944,0.023979,69.966141,3.564245,0.239788,-27.845076,0.024768,0.000000
49.170002,15.791572,-27.845076,0.023032,0.000955,0.024265,70.244415,3.578421,0.242650,-27.845076,0.025167,0.000000
49.410004,15.947224,-27.845076,0.023062,0.000970,0.024629,70.936790,3.613693,0.246291,-27.845076,0.025565,0.000000
49.650002,16.330767,-27.800594,0.023058,0.000985,0.025020,72.642876,3.700605,0.250197,-27.800594,0.025964,0.000000
49.890003,16.786551,-27.800594,0.023075,0.001003,0.025470,74.670303,3.803887,0.254701,-27.800594,0.026363,0.000000
50.130001,17.147753,-27.711632,0.023084,0.001018,0.025852,76.277016,3.885736,0.258523,-27.711632,0.026762,0.000000
50.370003,17.257975,-27.800594,0.023088,0.001029,0.026147,76.767303,3.910713,0.261468,-27.800594,0.027161,0.000000
50.610001,17.648594,-27.756113,0.023110,0.001046,0.026571,78.504868,3.999229,0.265715,-27.756113,0.027569,0.000000
50.850002,18.156509,-27.711632,0.023136,0.001067,0.027092,80.764191,4.114324,0.270923,-27.711632,0.027968,0.000000
51.090004,18.602240,-27.756113,0.023144,0.001083,0.027500,82.746895,4.215328,0.274995,-27.756113,0.028367,0.000000
51.330002,18.638731,-27.667152,0.023153,0.001095,0.027812,82.909218,4.223597,0.278122,-27.667152,0.028766,0.000000
51.570004,19.024881,-27.667152,0.023166,0.001110,0.028202,84.626900,4.311100,0.282020,-27.667152,0.029165,0.000000
51.810001,19.468750,-27.622671,0.023183,0.001129,0.028679,86.601326,4.411682,0.286789,-27.622671,0.029564,0.000000
52.050003,19.923416,-27.622671,0.023187,0.001145,0.029095,88.623779,4.514710,0.290952,-27.622671,0.029963,0.000000
52.290001,20.127850,-27.622671,0.023218,0.001159,0.029443,89.533150,4.561036,0.294427,-27.622671,0.030370,0.000000
52.530003,20.488306,-27.622671,0.023226,0.001175,0.029842,91.136536,4.642716,0.298416,-27.622671,0.030769,0.000000
52.770004,20.934780,-27.622671,0.023243,0.001192,0.030284,93.122551,4.743889,0.302837,-27.622671,0.031168,0.000000
53.010002,21.242731,-27.667152,0.023248,0.001208,0.030674,94.492386,4.813672,0.306735,-27.667152,0.031567,0.000000
53.250004,21.563345,-27.622671,0.023243,0.001223,0.031055,95.918549,4.886324,0.310551,-27.622671,0.031966,0.000000
53.490002,21.878744,-27.578190,0.023256,0.001237,0.031428,97.321518,4.957794,0.314283,-27.578190,0.032365,0.000000
53.730003,21.934227,-27.533709,0.023282,0.001246,0.031645,97.568314,4.970367,0.316447,-27.533709,0.032764,0.000000
53.970001,22.599285,-27.578190,0.023295,0.001267,0.032183,100.526642,5.121071,0.321830,-27.578190,0.033162,0.000000
54.210003,22.902395,-27.489227,0.023308,0.001281,0.032530,101.874939,5.189757,0.325297,-27.489227,0.033571,0.000000
54.450001,23.058792,-27.444746,0.023304,0.001291,0.032781,102.570633,5.225197,0.327810,-27.444746,0.033969,0.000000
54.690002,23.861628,-27.489227,0.023330,0.001313,0.033362,106.141823,5.407122,0.333623,-27.489227,0.034368,0.000000
54.930004,24.591105,-27.400267,0.023343,0.001335,0.033917,109.386696,5.572424,0.339172,-27.400267,0.034767,0.000000
55.170002,24.496523,-27.533709,0.023368,0.001344,0.034143,108.965973,5.550991,0.341428,-27.533709,0.035166,0.000000
55.410004,24.826817,-27.444746,0.023386,0.001361,0.034559,110.435196,5.625837,0.345591,-27.444746,0.035565,0.000000
55.650002,25.088594,-27.533709,0.023381,0.001374,0.034888,111.599640,5.685156,0.348884,-27.533709,0.035964,0.000000
55.890003,25.568583,-27.444746,0.023394,0.001388,0.035253,113.734734,5.793924,0.352525,-27.444746,0.036363,0.000000
56.130001,26.048571,-27.400267,0.023416,0.001404,0.035661,115.869827,5.902690,0.356605,-27.400267,0.036770,0.000000
56.370003,26.292475,-27.400267,0.023424,0.001419,0.036033,116.954765,5.957960,0.360330,-27.400267,0.037169,0.000000
56.610004,27.208511,-27.444746,0.023437,0.001441,0.036597,121.029503,6.165536,0.365969,-27.444746,0.037568,0.000000
56.850002,27.599503,-27.400267,0.023446,0.001457,0.036996,122.768723,6.254137,0.369958,-27.400267,0.037967,0.000000
57.090004,28.002409,-27.400267,0.023468,0.001472,0.037386,124.560936,6.345437,0.373864,-27.400267,0.038366,0.000000
57.330002,28.480164,-27.355785,0.023476,0.001488,0.037794,126.686096,6.453697,0.377937,-27.355785,0.038765,0.000000
57.570004,28.710661,-27.311304,0.023485,0.001499,0.038080,127.711395,6.505929,0.380798,-27.311304,0.039164,0.000000
57.810001,29.239803,-27.222342,0.023506,0.001515,0.038479,130.065140,6.625834,0.384788,-27.222342,0.039563,0.000000
58.050003,29.684788,-27.266823,0.023493,0.001530,0.038860,132.044525,6.726669,0.388603,-27.266823,0.039971,0.000000
58.290001,29.974867,-27.266823,0.023532,0.001542,0.039164,133.334869,6.792402,0.391638,-27.266823,0.040370,0.000000
58.530003,30.857018,-27.266823,0.023524,0.001565,0.039745,137.258865,6.992300,0.397452,-27.266823,0.040769,0.000000
58.770004,31.436428,-27.311304,0.023545,0.001581,0.040162,139.836212,7.123597,0.401615,-27.311304,0.041168,0.000000
59.010002,32.038181,-27.266823,0.023550,0.001599,0.040621,142.512955,7.259955,0.406210,-27.266823,0.041566,0.000000
59.250004,32.467155,-27.222342,0.023562,0.001614,0.040993,144.421127,7.357163,0.409934,-27.222342,0.041965,0.000000
59.490002,32.765797,-27.222342,0.023584,0.001627,0.041314,145.749542,7.424836,0.413144,-27.222342,0.042364,0.000000
59.730003,33.446121,-27.177860,0.023597,0.001644,0.041757,148.775772,7.578999,0.417572,-27.177860,0.042763,0.000000
59.970001,33.965584,-27.222342,0.023601,0.001657,0.042087,151.086456,7.696711,0.420865,-27.222342,0.043171,0.000000
60.210003,34.031864,-27.177860,0.023614,0.001664,0.042277,151.381287,7.711730,0.422773,-27.177860,0.043569,0.000000
60.450005,35.014927,-27.177860,0.023618,0.001687,0.042859,155.754181,7.934496,0.428586,-27.177860,0.043968,0.000000
60.690002,35.854256,-27.177860,0.023614,0.001704,0.043292,159.487701,8.124690,0.432916,-27.177860,0.044367,0.000000
60.930004,36.495480,-27.088900,0.023644,0.001721,0.043717,162.339996,8.269994,0.437171,-27.088900,0.044766,0.000000
61.170002,37.039143,-27.133381,0.023657,0.001738,0.044133,164.758331,8.393189,0.441334,-27.133381,0.045165,0.000000
61.410004,37.622650,-27.133381,0.023666,0.001752,0.044506,167.353912,8.525414,0.445058,-27.133381,0.045564,0.000000
61.650002,38.504059,-27.044418,0.023662,0.001771,0.044992,171.274612,8.725144,0.449918,-27.044418,0.045963,0.000000
61.890003,38.906219,-27.044418,0.023696,0.001783,0.045278,173.063507,8.816276,0.452779,-27.044418,0.046370,0.000000
62.130001,39.477066,-26.999937,0.023679,0.001796,0.045625,175.602753,8.945631,0.456246,-26.999937,0.046769,0.000000
62.370003,39.756718,-27.088900,0.023709,0.001805,0.045850,176.846710,9.009001,0.458502,-27.088900,0.047168,0.000000
62.610004,41.186256,-27.088900,0.023713,0.001831,0.046518,183.205612,9.332939,0.465179,-27.088900,0.047567,0.000000
62.850002,42.144745,-26.999937,0.023709,0.001851,0.047021,187.469193,9.550136,0.470213,-26.999937,0.047966,0.000000
63.090004,42.778149,-27.044418,0.023731,0.001867,0.047420,190.286713,9.693667,0.474202,-27.044418,0.048365,0.000000
63.330002,43.240261,-26.955456,0.023748,0.001880,0.047758,192.342285,9.798384,0.477578,-26.955456,0.048764,0.000000
63.570004,44.058739,-26.955456,0.023752,0.001898,0.048209,195.983063,9.983852,0.482090,-26.955456,0.049163,0.000000
63.810001,44.556973,-26.910975,0.023774,0.001911,0.048530,198.199310,10.096754,0.485299,-26.910975,0.049571,0.000000
64.050003,44.899555,-26.910975,0.023778,0.001919,0.048746,199.723190,10.174385,0.487464,-26.910975,0.049970,0.000000
64.290001,45.740372,-26.955456,0.023778,0.001937,0.049198,203.463333,10.364916,0.491976,-26.955456,0.050369,0.000000
64.530006,47.216084,-26.910975,0.023787,0.001961,0.049805,210.027634,10.699318,0.498047,-26.910975,0.050768,0.000000
64.770004,48.052803,-26.955456,0.023800,0.001976,0.050195,213.749542,10.888921,0.501953,-26.955456,0.051166,0.000000
65.010002,48.741695,-26.910975,0.023825,0.001992,0.050585,216.813889,11.045026,0.505851,-26.910975,0.051565,0.000000
65.250000,49.364674,-26.822014,0.023813,0.002006,0.050941,219.585037,11.186194,0.509409,-26.822014,0.051964,0.000000
65.490005,50.364494,-26.866495,0.023830,0.002025,0.051444,224.032455,11.412757,0.514435,-26.866495,0.052372,0.000000
65.730003,51.212383,-26.777533,0.023843,0.002040,0.051808,227.804062,11.604892,0.518084,-26.777533,0.052771,0.000000
65.970001,51.552361,-26.866495,0.023847,0.002050,0.052060,229.316345,11.681932,0.520597,-26.866495,0.053169,0.000000
66.210007,52.139591,-26.777533,0.023869,0.002062,0.052381,231.928482,11.815001,0.523807,-26.777533,0.053568,0.000000
66.450005,52.807255,-26.777533,0.023847,0.002079,0.052805,234.898407,11.966294,0.528053,-26.777533,0.053967,0.000000
66.690002,54.665394,-26.777533,0.023886,0.002101,0.053369,243.163818,12.387355,0.533693,-26.777533,0.054366,0.000000
66.930000,55.430618,-26.777533,0.023873,0.002118,0.053794,246.567703,12.560758,0.537940,-26.777533,0.054765,0.000000
67.170006,56.229733,-26.822014,0.023881,0.002133,0.054175,250.122345,12.741839,0.541755,-26.822014,0.055164,0.000000
67.410004,56.941334,-26.688570,0.023903,0.002149,0.054592,253.287704,12.903090,0.545918,-26.688570,0.055572,0.000000
67.650002,57.932964,-26.733051,0.023903,0.002162,0.054913,257.698700,13.127797,0.549128,-26.733051,0.055971,0.000000
67.890007,58.472157,-26.733051,0.023920,0.002174,0.055216,260.097137,13.249980,0.552163,-26.733051,0.056370,0.000000
68.130005,59.366970,-26.644089,0.023925,0.002189,0.055590,264.077484,13.452747,0.555895,-26.644089,0.056769,0.000000
68.370003,60.501961,-26.733051,0.023929,0.002209,0.056100,269.126160,13.709941,0.561005,-26.733051,0.057168,0.000000
68.610001,61.882717,-26.644089,0.023929,0.002225,0.056517,275.268066,14.022823,0.565168,-26.644089,0.057567,0.000000
68.850006,62.852749,-26.644089,0.023942,0.002243,0.056968,279.582977,14.242637,0.569680,-26.644089,0.057966,0.000000
69.090004,63.739738,-26.688570,0.023950,0.002258,0.057341,283.528503,14.443631,0.573412,-26.688570,0.058365,0.000000
69.330002,64.423782,-26.599609,0.023955,0.002271,0.057688,286.571289,14.598638,0.576879,-26.599609,0.058772,0.000000
69.570000,65.958336,-26.688570,0.023968,0.002291,0.058190,293.397339,14.946372,0.581905,-26.688570,0.059171,0.000000
69.810005,66.497902,-26.555128,0.023981,0.002302,0.058477,295.797455,15.068640,0.584774,-26.555128,0.059570,0.000000
70.050003,67.212486,-26.599609,0.023985,0.002315,0.058807,298.976074,15.230568,0.588067,-26.599609,0.059969,0.000000
70.290001,67.321220,-26.555128,0.023989,0.002311,0.058694,299.459747,15.255206,0.586939,-26.555128,0.058980,0.000000
70.530006,66.887405,-26.555128,0.023994,0.002311,0.058694,297.530029,15.156902,0.586939,-26.555128,0.058980,0.000000
70.770004,66.582802,-26.510647,0.024002,0.002302,0.058477,296.175079,15.087878,0.584774,-26.510647,0.058694,0.000000
71.010002,66.292725,-26.510647,0.023998,0.002302,0.058477,294.884766,15.022146,0.584774,-26.510647,0.058694,0.000000
71.250000,66.050682,-26.510647,0.024002,0.002302,0.058477,293.808105,14.967299,0.584774,-26.510647,0.058694,0.000000
71.490005,65.806778,-26.510647,0.024011,0.002302,0.058477,292.723175,14.912028,0.584774,-26.510647,0.058694,0.000000
71.730003,65.633995,-26.466166,0.024007,0.002302,0.058477,291.954590,14.872875,0.584774,-26.466166,0.058694,0.000000
71.970001,65.466805,-26.510647,0.024024,0.002302,0.058477,291.210876,14.834991,0.584774,-26.510647,0.058694,0.000000
72.210007,65.301094,-26.466166,0.024011,0.002302,0.058477,290.473785,14.797440,0.584774,-26.466166,0.058694,0.000000
72.450005,65.169647,-26.466166,0.024011,0.002302,0.058477,289.889069,14.767653,0.584774,-26.466166,0.058694,0.000000
72.690002,65.031128,-26.421684,0.024011,0.002302,0.058477,289.272919,14.736264,0.584774,-26.421684,0.058694,0.000000
72.930000,64.909363,-26.377205,0.024019,0.002302,0.058477,288.731262,14.708673,0.584774,-26.377205,0.058694,0.000000
73.170006,64.803978,-26.466166,0.024019,0.002302,0.058477,288.262482,14.684792,0.584774,-26.466166,0.058694,0.000000
73.410004,64.707535,-26.332724,0.024032,0.002302,0.058477,287.833496,14.662937,0.584774,-26.332724,0.058694,0.000000
73.650002,64.602524,-26.377205,0.024015,0.002302,0.058477,287.366364,14.639141,0.584774,-26.377205,0.058694,0.000000
73.890007,64.515015,-26.332724,0.024019,0.002302,0.058477,286.977112,14.619310,0.584774,-26.332724,0.058694,0.000000
74.130005,64.418571,-26.332724,0.024024,0.002302,0.058477,286.548126,14.597457,0.584774,-26.332724,0.058694,0.000000
74.370003,64.340744,-26.377205,0.024024,0.002302,0.058477,286.201935,14.579821,0.584774,-26.377205,0.058694,0.000000
74.610001,64.288986,-26.332724,0.024019,0.002302,0.058477,285.971680,14.568092,0.584774,-26.332724,0.058694,0.000000
74.850006,64.212280,-26.332724,0.024015,0.002302,0.058477,285.630493,14.550711,0.584774,-26.332724,0.058694,0.000000
75.090004,64.129982,-26.332724,0.024028,0.002302,0.058477,285.264404,14.532062,0.584774,-26.332724,0.058694,0.000000
75.330002,64.064072,-26.243761,0.024024,0.002302,0.058477,284.971222,14.517126,0.584774,-26.243761,0.058694,0.000000
75.570007,63.992580,-26.288242,0.024028,0.002302,0.058477,284.653229,14.500925,0.584774,-26.288242,0.058694,0.000000
75.810005,63.939331,-26.199280,0.024028,0.002302,0.058477,284.416351,14.488859,0.584774,-26.199280,0.058694,0.000000
76.050003,63.887943,-26.199280,0.024015,0.002302,0.058477,284.187775,14.477215,0.584774,-26.199280,0.058694,0.000000
76.290001,63.831345,-26.199280,0.024032,0.002302,0.058477,283.936005,14.464390,0.584774,-26.199280,0.058694,0.000000
76.530006,63.768414,-26.199280,0.024028,0.002302,0.058477,283.656067,14.450130,0.584774,-26.199280,0.058694,0.000000
76.770004,63.735641,-26.199280,0.024024,0.002302,0.058477,283.510284,14.442703,0.584774,-26.199280,0.058694,0.000000
77.010002,63.681278,-26.154799,0.024037,0.002302,0.058477,283.268463,14.430384,0.584774,-26.154799,0.058694,0.000000
77.250000,63.616856,-26.110319,0.024019,0.002302,0.058477,282.981903,14.415786,0.584774,-26.110319,0.058694,0.000000
77.490005,63.585949,-26.199280,0.024041,0.002302,0.058477,282.844421,14.408782,0.584774,-26.199280,0.058694,0.000000
77.730003,63.544617,-26.110319,0.024032,0.002302,0.058477,282.660583,14.399416,0.584774,-26.110319,0.058694,0.000000
77.970001,63.502911,-26.110319,0.024019,0.002302,0.058477,282.475067,14.389966,0.584774,-26.110319,0.058694,0.000000
78.210007,63.462692,-26.065838,0.024032,0.002302,0.058477,282.296143,14.380852,0.584774,-26.065838,0.058694,0.000000
78.450005,63.410561,-26.021357,0.024015,0.002302,0.058477,282.064270,14.369038,0.584774,-26.021357,0.058694,0.000000
78.690002,63.369972,-26.065838,0.024028,0.002302,0.058477,281.883728,14.359840,0.584774,-26.065838,0.058694,0.000000
78.930000,63.340183,-26.021357,0.024032,0.002302,0.058477,281.751221,14.353091,0.584774,-26.021357,0.058694,0.000000
79.170006,63.303692,-26.021357,0.024028,0.002302,0.058477,281.588898,14.344821,0.584774,-26.021357,0.058694,0.000000
79.410004,63.276134,-25.976875,0.024037,0.002302,0.058477,281.466309,14.338577,0.584774,-25.976875,0.058694,0.000000
79.650002,63.238155,-26.065838,0.024032,0.002302,0.058477,281.297363,14.329971,0.584774,-26.065838,0.058694,0.000000
79.890007,63.196449,-25.976875,0.024024,0.002302,0.058477,281.111847,14.320520,0.584774,-25.976875,0.058694,0.000000
80.130005,63.147293,-25.932394,0.024019,0.002302,0.058477,280.893188,14.309381,0.584774,-25.932394,0.058694,0.000000
80.370003,63.139103,-25.976875,0.024019,0.002302,0.058477,280.856750,14.307526,0.584774,-25.976875,0.058694,0.000000
80.610001,63.094044,-25.932394,0.024037,0.002302,0.058477,280.656311,14.297315,0.584774,-25.932394,0.058694,0.000000
80.850006,63.074310,-25.932394,0.024024,0.002302,0.058477,280.568542,14.292843,0.584774,-25.932394,0.058694,0.000000
81.090004,63.030369,-25.887913,0.024028,0.002302,0.058477,280.373077,14.282886,0.584774,-25.887913,0.058694,0.000000
81.330002,63.003933,-25.887913,0.024028,0.002302,0.058477,280.255493,14.276896,0.584774,-25.887913,0.058694,0.000000
81.570007,62.969299,-25.887913,0.024041,0.002302,0.058477,280.101440,14.269048,0.584774,-25.887913,0.058694,0.000000
81.810005,62.944351,-25.843433,0.024032,0.002302,0.058477,279.990448,14.263393,0.584774,-25.843433,0.058694,0.000000
82.050003,62.921638,-25.887913,0.024028,0.002302,0.058477,279.889435,14.258246,0.584774,-25.887913,0.058694,0.000000
82.290001,62.894455,-25.887913,0.024032,0.002302,0.058477,279.768494,14.252088,0.584774,-25.887913,0.058694,0.000000
82.530006,62.870995,-25.843433,0.024032,0.002302,0.058477,279.664154,14.246771,0.584774,-25.843433,0.058694,0.000000
82.770004,62.840832,-25.843433,0.024032,0.002302,0.058477,279.529968,14.239936,0.584774,-25.843433,0.058694,0.000000
83.010002,62.808064,-25.843433,0.024032,0.002302,0.058477,279.384216,14.232511,0.584774,-25.843433,0.058694,0.000000
83.250008,62.793915,-25.843433,0.024032,0.002302,0.058477,279.321289,14.229305,0.584774,-25.843433,0.058694,0.000000
83.490005,62.771942,-25.798952,0.024041,0.002302,0.058477,279.223541,14.224325,0.584774,-25.798952,0.058694,0.000000
83.730003,62.749973,-25.709990,0.024032,0.002302,0.058477,279.125824,14.219347,0.584774,-25.709990,0.058694,0.000000
83.970001,62.722046,-25.754471,0.024032,0.002302,0.058477,279.001587,14.213019,0.584774,-25.754471,0.058694,0.000000
84.210007,62.703053,-25.709990,0.024041,0.002302,0.058477,278.917114,14.208715,0.584774,-25.709990,0.058694,0.000000
84.450005,62.671032,-25.754471,0.024037,0.002302,0.058477,278.774658,14.201459,0.584774,-25.754471,0.058694,0.000000
84.690002,62.659485,-25.665508,0.024037,0.002302,0.058477,278.723297,14.198842,0.584774,-25.665508,0.058694,0.000000
84.930000,62.637890,-25.665508,0.024037,0.002302,0.058477,278.627258,14.193949,0.584774,-25.665508,0.058694,0.000000
85.170006,62.609589,-25.709990,0.024041,0.002302,0.058477,278.501373,14.187535,0.584774,-25.709990,0.058694,0.000000
85.410004,62.583523,-25.621027,0.024032,0.002302,0.058477,278.385406,14.181628,0.584774,-25.621027,0.058694,0.000000
85.650002,62.565277,-25.665508,0.024032,0.002302,0.058477,278.304260,14.177494,0.584774,-25.665508,0.058694,0.000000
85.890007,62.545914,-25.621027,0.024037,0.002302,0.058477,278.218109,14.173107,0.584774,-25.621027,0.058694,0.000000
86.130005,62.523197,-25.665508,0.024028,0.002302,0.058477,278.117065,14.167959,0.584774,-25.665508,0.058694,0.000000
86.370003,62.507557,-25.665508,0.024037,0.002302,0.058477,278.047485,14.164415,0.584774,-25.665508,0.058694,0.000000
86.610001,62.490803,-25.532066,0.024037,0.002302,0.058477,277.972961,14.160619,0.584774,-25.532066,0.058694,0.000000
86.850006,62.469204,-25.621027,0.024041,0.002302,0.058477,277.876892,14.155725,0.584774,-25.621027,0.058694,0.000000
87.090004,62.444256,-25.576548,0.024037,0.002302,0.058477,277.765930,14.150070,0.584774,-25.576548,0.058694,0.000000
87.330002,62.429359,-25.576548,0.024037,0.002302,0.058477,277.699646,14.146695,0.584774,-25.576548,0.058694,0.000000
87.570007,62.410744,-25.532066,0.024028,0.002302,0.058477,277.616852,14.142477,0.584774,-25.532066,0.058694,0.000000
87.810005,62.405155,-25.487585,0.024037,0.002302,0.058477,277.591980,14.141211,0.584774,-25.487585,0.058694,0.000000
88.050003,62.382442,-25.532066,0.024041,0.002302,0.058477,277.490967,14.136064,0.584774,-25.532066,0.058694,0.000000
88.290001,62.371643,-25.487585,0.024028,0.002302,0.058477,277.442932,14.133616,0.584774,-25.487585,0.058694,0.000000
88.530006,62.358982,-25.398623,0.024041,0.002302,0.058477,277.386597,14.130747,0.584774,-25.398623,0.058694,0.000000
88.770004,62.326958,-25.487585,0.024032,0.002302,0.058477,277.244141,14.123490,0.584774,-25.487585,0.058694,0.000000
89.010002,62.314297,-25.398623,0.024032,0.002302,0.058477,277.187836,14.120622,0.584774,-25.398623,0.058694,0.000000
89.250008,62.289349,-25.487585,0.024028,0.002302,0.058477,277.076874,14.114967,0.584774,-25.487585,0.058694,0.000000
89.490005,62.276314,-25.398623,0.024028,0.002302,0.058477,277.018890,14.112015,0.584774,-25.398623,0.058694,0.000000
89.730003,62.270359,-25.354141,0.024028,0.002302,0.058477,276.992401,14.110665,0.584774,-25.354141,0.058694,0.000000
89.970001,62.245781,-25.398623,0.024050,0.002302,0.058477,276.883057,14.105096,0.584774,-25.398623,0.058694,0.000000
90.210007,62.242428,-25.309662,0.024037,0.002302,0.058477,276.868134,14.104336,0.584774,-25.309662,0.058694,0.000000
90.450005,62.217480,-25.354141,0.024032,0.002302,0.058477,276.757172,14.098682,0.584774,-25.354141,0.058694,0.000000
90.690002,62.200352,-25.309662,0.024024,0.002302,0.058477,276.680969,14.094801,0.584774,-25.309662,0.058694,0.000000
90.930008,62.188808,-25.354141,0.024028,0.002302,0.058477,276.629639,14.092185,0.584774,-25.354141,0.058694,0.000000
91.170006,62.172424,-25.309662,0.024037,0.002302,0.058477,276.556763,14.088472,0.584774,-25.309662,0.058694,0.000000
91.410004,62.161625,-25.265181,0.024024,0.002302,0.058477,276.508728,14.086026,0.584774,-25.265181,0.058694,0.000000
91.650002,62.148220,-25.309662,0.024041,0.002302,0.058477,276.449097,14.082988,0.584774,-25.309662,0.058694,0.000000
91.890007,62.137421,-25.265181,0.024028,0.002302,0.058477,276.401062,14.080541,0.584774,-25.265181,0.058694,0.000000
92.130005,62.092735,-25.265181,0.024028,0.002302,0.058477,276.202271,14.070415,0.584774,-25.265181,0.058694,0.000000
92.370003,62.108002,-25.220699,0.024032,0.002302,0.058477,276.270203,14.073874,0.584774,-25.220699,0.058694,0.000000
92.610001,62.088268,-25.176218,0.024037,0.002302,0.058477,276.182404,14.069403,0.584774,-25.176218,0.058694,0.000000
92.850006,62.083797,-25.220699,0.024045,0.002302,0.058477,276.162537,14.068389,0.584774,-25.220699,0.058694,0.000000
93.090004,62.075977,-25.220699,0.024032,0.002302,0.058477,276.127747,14.066618,0.584774,-25.220699,0.058694,0.000000
93.330002,62.046188,-25.265181,0.024032,0.002302,0.058477,275.995239,14.059867,0.584774,-25.265181,0.058694,0.000000
93.570007,62.035019,-25.220699,0.024037,0.002302,0.058477,275.945557,14.057336,0.584774,-25.220699,0.058694,0.000000
93.810005,62.025707,-25.131737,0.024041,0.002302,0.058477,275.904114,14.055226,0.584774,-25.131737,0.058694,0.000000
94.050003,62.008205,-25.176218,0.024028,0.002302,0.058477,275.826263,14.051260,0.584774,-25.176218,0.058694,0.000000
94.290001,61.991451,-25.131737,0.024037,0.002302,0.058477,275.751740,14.047463,0.584774,-25.131737,0.058694,0.000000
94.530006,61.989960,-25.176218,0.024037,0.002302,0.058477,275.745117,14.047126,0.584774,-25.176218,0.058694,0.000000
94.770004,61.983257,-25.042776,0.024037,0.002302,0.058477,275.715302,14.045607,0.584774,-25.042776,0.058694,0.000000
95.010002,61.964268,-25.087255,0.024032,0.002302,0.058477,275.630829,14.041304,0.584774,-25.087255,0.058694,0.000000
95.250008,61.951607,-25.131737,0.024037,0.002302,0.058477,275.574524,14.038435,0.584774,-25.131737,0.058694,0.000000
95.490005,61.937084,-25.042776,0.024041,0.002302,0.058477,275.509918,14.035144,0.584774,-25.042776,0.058694,0.000000
95.730003,61.923306,-25.087255,0.024024,0.002302,0.058477,275.448608,14.032022,0.584774,-25.087255,0.058694,0.000000
95.970001,61.907665,-25.042776,0.024037,0.002302,0.058477,275.379059,14.028478,0.584774,-25.042776,0.058694,0.000000
96.210007,61.902454,-24.998295,0.024041,0.002302,0.058477,275.355865,14.027297,0.584774,-24.998295,0.058694,0.000000
96.450005,61.897614,-25.087255,0.024041,0.002302,0.058477,275.334351,14.026200,0.584774,-25.087255,0.058694,0.000000
96.690002,61.893143,-24.998295,0.024019,0.002302,0.058477,275.314453,14.025187,0.584774,-24.998295,0.058694,0.000000
96.930008,61.865215,-25.042776,0.024037,0.002302,0.058477,275.190216,14.018858,0.584774,-25.042776,0.058694,0.000000
97.170006,61.854416,-24.953814,0.024045,0.002302,0.058477,275.142181,14.016411,0.584774,-24.953814,0.058694,0.000000
97.410004,61.829842,-24.953814,0.024024,0.002302,0.058477,275.032867,14.010842,0.584774,-24.953814,0.058694,0.000000
97.650002,61.827232,-24.953814,0.024032,0.002302,0.058477,275.021271,14.010251,0.584774,-24.953814,0.058694,0.000000
97.890007,61.827232,-24.953814,0.024032,0.002302,0.058477,275.021271,14.010251,0.584774,-24.953814,0.058694,0.000000
98.130005,61.818668,-24.909332,0.024037,0.002302,0.058477,274.983185,14.008311,0.584774,-24.909332,0.058694,0.000000
98.370003,61.813084,-24.953814,0.024037,0.002302,0.058477,274.958344,14.007046,0.584774,-24.953814,0.058694,0.000000
98.610008,61.792233,-24.864851,0.024019,0.002302,0.058477,274.865570,14.002320,0.584774,-24.864851,0.058694,0.000000
98.850006,61.771378,-24.909332,0.024037,0.002302,0.058477,274.772797,13.997594,0.584774,-24.909332,0.058694,0.000000
99.090004,61.769516,-24.820372,0.024045,0.002302,0.058477,274.764526,13.997172,0.584774,-24.820372,0.058694,0.000000
99.330002,61.749409,-24.864851,0.024024,0.002302,0.058477,274.675079,13.992616,0.584774,-24.864851,0.058694,0.000000
99.570007,61.738609,-24.864851,0.024037,0.002302,0.058477,274.627045,13.990169,0.584774,-24.864851,0.058694,0.000000
99.810005,61.735260,-24.820372,0.024050,0.002302,0.058477,274.612152,13.989409,0.584774,-24.820372,0.058694,0.000000
100.050003,61.729301,-24.820372,0.024041,0.002302,0.058477,274.585632,13.988060,0.584774,-24.820372,0.058694,0.000000
100.290009,61.734886,-24.775890,0.024037,0.002302,0.058477,274.610474,13.989326,0.584774,-24.775890,0.058694,0.000000
100.530006,61.699883,-24.820372,0.024024,0.002302,0.058477,274.454773,13.981394,0.584774,-24.820372,0.058694,0.000000
100.700005,61.696159,-24.775890,0.024037,0.002302,0.058477,274.438232,13.980549,0.584774,-24.775890,0.058694,0.000000