File: Data/I-18 Polished After 1_08182023_170759.csv
Time (sec),S:Load (lbs),S:HL1 (DIM),S:LVDT (in),S:Position (in),Ch:Position (mm),Ch:Load (N),Ch:Stress (MPa),Ch:Strain (mm/mm),Ch:HL1 (DIM),Set Point (),Cycles ()
0.110000,0.000740,-28.912619,0.000026,-0.000000,-0.000000,0.003292,0.000168,-0.000000,-28.912619,0.000087,0.000000
0.410000,-0.002609,-28.912619,0.000004,0.000002,0.000052,-0.011607,-0.000591,0.000519,-28.912619,0.000537,0.000000
0.710000,-0.011917,-28.868137,0.000017,0.000189,0.004813,-0.053010,-0.002700,0.048129,-28.868137,0.005550,0.000000
1.010000,-0.031281,-28.868137,0.000022,0.000369,0.009374,-0.139143,-0.007088,0.093744,-28.868137,0.010545,0.000000
1.310000,-0.022713,-28.868137,0.000022,0.000571,0.014491,-0.101031,-0.005147,0.144912,-28.868137,0.015540,0.000000
1.610000,0.004471,-28.823656,0.000030,0.000769,0.019538,0.019887,0.001013,0.195384,-28.823656,0.020536,0.000000
1.910000,0.021599,-28.868137,0.000022,0.000966,0.024542,0.096076,0.004894,0.245424,-28.868137,0.025531,0.000000
2.210000,0.004837,-28.868137,0.000034,0.001157,0.029399,0.021516,0.001096,0.293988,-28.868137,0.030526,0.000000
2.510000,0.002602,-28.912619,0.000022,0.001359,0.034524,0.011573,0.000590,0.345239,-28.912619,0.035539,0.000000
2.810000,0.011917,-28.912619,0.000009,0.001546,0.039259,0.053010,0.002700,0.392592,-28.912619,0.040534,0.000000
3.110000,-0.040215,-28.912619,0.000009,0.001749,0.044419,-0.178883,-0.009113,0.444191,-28.912619,0.045529,0.000000
3.410000,0.008194,-28.912619,0.000026,0.001943,0.049345,0.036449,0.001857,0.493448,-28.912619,0.050525,0.000000
3.710000,0.002975,-28.912619,0.000009,0.002141,0.054392,0.013236,0.000674,0.543923,-28.912619,0.055519,0.000000
4.010000,0.027184,-28.912619,-0.000004,0.002332,0.059240,0.120918,0.006160,0.592400,-28.912619,0.060515,0.000000
4.310000,-0.005211,-28.868137,0.000034,0.002540,0.064513,-0.023179,-0.001181,0.645128,-28.868137,0.065510,0.000000
4.610000,0.023827,-28.957100,0.000034,0.002738,0.069534,0.105986,0.005399,0.695338,-28.957100,0.070523,0.000000
4.910000,-0.002609,-28.912619,0.000004,0.002930,0.074425,-0.011607,-0.000591,0.744250,-28.912619,0.075518,0.000000
5.210000,-0.008942,-28.912619,0.000004,0.003131,0.079516,-0.039774,-0.002026,0.795157,-28.912619,0.080513,0.000000
5.510000,-0.002609,-28.957100,0.000034,0.003320,0.084320,-0.011607,-0.000591,0.843203,-28.957100,0.085508,0.000000
5.810000,-0.002609,-28.957100,0.000009,0.003520,0.089402,-0.011607,-0.000591,0.894022,-28.957100,0.090504,0.000000
6.110000,0.032394,-28.957100,0.000052,0.003708,0.094172,0.144098,0.007341,0.941720,-28.957100,0.095499,0.000000
6.410000,-0.001488,-28.912619,0.000017,0.003914,0.099427,-0.006618,-0.000337,0.994273,-28.912619,0.100511,0.000000
6.710001,0.026810,-28.912619,0.000026,0.004105,0.104275,0.119255,0.006075,1.042750,-28.912619,0.105507,0.000000
7.010000,-0.007080,-28.912619,0.000030,0.004307,0.109409,-0.031494,-0.001604,1.094092,-28.912619,0.110502,0.000000
7.310000,-0.011543,-28.957100,0.000017,0.004501,0.114335,-0.051347,-0.002616,1.143349,-28.957100,0.115497,0.000000
7.610000,-0.005585,-28.912619,0.000043,0.004699,0.119348,-0.024842,-0.001266,1.193476,-28.912619,0.120492,0.000000
7.910000,0.020477,-28.957100,-0.000009,0.004896,0.124351,0.091088,0.004640,1.243512,-28.957100,0.125487,0.000000
8.210000,0.007446,-28.957100,0.000009,0.005095,0.129424,0.033123,0.001687,1.294245,-28.957100,0.130483,0.000000
8.510000,0.003723,-28.957100,0.000004,0.005294,0.134463,0.016561,0.000844,1.344633,-28.957100,0.135495,0.000000
8.810000,0.015640,-29.001579,0.000022,0.005485,0.139320,0.069571,0.003544,1.393197,-29.001579,0.140490,0.000000
9.110001,-0.004845,-28.957100,-0.000017,0.005682,0.144324,-0.021550,-0.001098,1.443237,-28.957100,0.145486,0.000000
9.410001,-0.000374,-29.046061,0.000022,0.005872,0.149137,-0.001663,-0.000085,1.491366,-29.046061,0.150481,0.000000
9.710000,-0.050644,-29.046061,0.000009,0.006075,0.154297,-0.225275,-0.011476,1.542965,-29.046061,0.155476,0.000000
10.010000,0.018990,-29.001579,0.000000,0.006269,0.159231,0.084470,0.004303,1.592313,-29.001579,0.160471,0.000000
10.310000,-0.006706,-29.001579,0.000030,0.006468,0.164296,-0.029831,-0.001520,1.642959,-29.001579,0.165484,0.000000
10.610001,0.026062,-29.046061,0.000034,0.006665,0.169299,0.115930,0.005906,1.692995,-29.046061,0.170479,0.000000
10.910001,0.013779,-29.001579,0.000026,0.006869,0.174468,0.061291,0.003122,1.744681,-29.001579,0.175474,0.000000
11.210001,-0.004845,-29.001579,0.000013,0.007064,0.179429,-0.021550,-0.001098,1.794290,-29.001579,0.180469,0.000000
11.510000,0.003723,-28.957100,0.000009,0.007259,0.184372,0.016561,0.000844,1.843721,-28.957100,0.185465,0.000000
11.810000,-0.030907,-29.001579,0.000026,0.007457,0.189402,-0.137480,-0.007004,1.894018,-29.001579,0.190460,0.000000
12.110001,0.025322,-29.046061,0.000017,0.007649,0.194276,0.112638,0.005738,1.942756,-29.046061,0.195472,0.000000
12.410001,-0.002609,-29.046061,0.000022,0.007846,0.199297,-0.011607,-0.000591,1.992970,-29.046061,0.200468,0.000000
12.710001,0.020477,-29.046061,0.000017,0.008039,0.204197,0.091088,0.004640,2.041970,-29.046061,0.205463,0.000000
13.010000,0.010796,-29.046061,0.000009,0.008244,0.209391,0.048021,0.002446,2.093914,-29.046061,0.210458,0.000000
13.310000,-0.007446,-29.090542,0.000009,0.008436,0.214265,-0.033123,-0.001687,2.142652,-29.090542,0.215453,0.000000
13.610001,-0.017128,-29.046061,0.000043,0.008631,0.219217,-0.076189,-0.003881,2.192173,-29.046061,0.220449,0.000000
13.910001,-0.013031,-29.046061,0.000004,0.008835,0.224403,-0.057965,-0.002953,2.244030,-29.046061,0.225444,0.000000
14.210001,0.008934,-29.046061,0.000009,0.009028,0.229303,0.039741,0.002024,2.293029,-29.046061,0.230457,0.000000
14.510000,0.021599,-29.001579,0.000009,0.009226,0.234341,0.096076,0.004894,2.343414,-29.001579,0.235452,0.000000
14.810000,-0.007446,-29.090542,0.000026,0.009423,0.239354,-0.033123,-0.001687,2.393541,-29.090542,0.240447,0.000000
15.110001,0.008934,-29.090542,0.000004,0.009622,0.244393,0.039741,0.002024,2.443926,-29.090542,0.245442,0.000000
15.410001,0.007820,-29.046061,-0.000009,0.009811,0.249206,0.034786,0.001772,2.492058,-29.046061,0.250437,0.000000
15.710001,-0.038727,-29.090542,0.000022,0.010011,0.254279,-0.172265,-0.008776,2.542791,-29.090542,0.255432,0.000000
16.010000,0.016754,-29.090542,-0.000004,0.010206,0.259222,0.074526,0.003797,2.592221,-29.090542,0.260445,0.000000
16.310001,-0.043198,-29.090542,0.000030,0.010406,0.264322,-0.192153,-0.009789,2.643215,-29.090542,0.265440,0.000000
16.610001,0.016754,-29.001579,0.000026,0.010601,0.269273,0.074526,0.003797,2.692733,-29.001579,0.270436,0.000000
16.910002,0.005211,-29.090542,0.000000,0.010802,0.274364,0.023179,0.001181,2.743640,-29.090542,0.275431,0.000000
17.210001,0.016754,-29.090542,0.000026,0.011002,0.279463,0.074526,0.003797,2.794634,-29.090542,0.280426,0.000000
17.510000,0.002602,-29.090542,0.000004,0.011197,0.284398,0.011573,0.000590,2.843978,-29.090542,0.285421,0.000000
17.810001,0.004837,-29.090542,0.000009,0.011394,0.289402,0.021516,0.001096,2.894018,-29.090542,0.290434,0.000000
18.110001,-0.000374,-29.135023,0.000022,0.011586,0.294293,-0.001663,-0.000085,2.942930,-29.135023,0.295429,0.000000
18.410002,-0.047295,-29.135023,0.000004,0.011784,0.299323,-0.210377,-0.010717,2.993227,-29.135023,0.300424,0.000000
18.710001,0.034256,-29.179504,0.000009,0.011975,0.304153,0.152378,0.007763,3.041534,-29.179504,0.305419,0.000000
19.010000,-0.008194,-29.135023,0.000000,0.012177,0.309296,-0.036449,-0.001857,3.092959,-29.135023,0.310415,0.000000
19.310001,0.007446,-29.135023,0.000022,0.012366,0.314109,0.033123,0.001687,3.141088,-29.135023,0.315410,0.000000
19.610001,-0.019363,-29.090542,0.000026,0.012575,0.319408,-0.086133,-0.004388,3.194077,-29.090542,0.320405,0.000000
19.910002,-0.002235,-29.090542,0.000013,0.012768,0.324316,-0.009944,-0.000507,3.243163,-29.090542,0.325418,0.000000
20.210001,-0.026443,-29.135023,0.000013,0.012958,0.329121,-0.117626,-0.005992,3.291209,-29.135023,0.330413,0.000000
20.510000,-0.023460,-29.135023,0.000026,0.013164,0.334367,-0.104357,-0.005316,3.343675,-29.135023,0.335408,0.000000
20.810001,0.009308,-29.090542,0.000000,0.013359,0.339328,0.041403,0.002109,3.393280,-29.090542,0.340403,0.000000
21.110001,0.005211,-29.179504,-0.000030,0.013557,0.344358,0.023179,0.001181,3.443577,-29.179504,0.345399,0.000000
21.410002,0.012283,-29.090542,0.000043,0.013748,0.349188,0.054639,0.002783,3.491884,-29.090542,0.350394,0.000000
21.710001,-0.003723,-29.135023,0.000013,0.013948,0.354288,-0.016561,-0.000844,3.542877,-29.135023,0.355406,0.000000
22.010000,0.018616,-29.135023,-0.000009,0.014140,0.359162,0.082807,0.004218,3.591615,-29.135023,0.360401,0.000000
22.310001,-0.042076,-29.135023,-0.000013,0.014338,0.364191,-0.187164,-0.009535,3.641913,-29.135023,0.365397,0.000000
22.610001,-0.003723,-29.135023,0.000047,0.014537,0.369247,-0.016561,-0.000844,3.692472,-29.135023,0.370392,0.000000
22.910002,0.002602,-29.223986,0.000026,0.014734,0.374251,0.011573,0.000590,3.742512,-29.223986,0.375387,0.000000
23.210001,0.028671,-29.135023,0.000013,0.014931,0.379238,0.127536,0.006497,3.792378,-29.135023,0.380382,0.000000
23.510000,0.007446,-29.135023,0.000017,0.015131,0.384328,0.033123,0.001687,3.843281,-29.135023,0.385378,0.000000
23.810001,0.020477,-29.223986,0.000009,0.015332,0.389427,0.091088,0.004640,3.894275,-29.223986,0.390390,0.000000
24.110001,0.016014,-29.179504,-0.000017,0.015519,0.394188,0.071234,0.003629,3.941885,-29.179504,0.395385,0.000000
24.410002,0.013779,-29.179504,0.000026,0.015722,0.399340,0.061291,0.003122,3.993401,-29.179504,0.400381,0.000000
24.710001,0.080803,-29.223986,0.000026,0.015912,0.404170,0.359429,0.018310,4.041704,-29.223986,0.405376,0.000000
25.010002,0.115059,-29.223986,0.000052,0.016112,0.409244,0.511808,0.026073,4.092437,-29.223986,0.410371,0.000000
25.310001,0.183952,-29.179504,0.000034,0.016301,0.414057,0.818261,0.041684,4.140569,-29.179504,0.415366,0.000000
25.610001,0.177620,-29.223986,0.000056,0.016507,0.419286,0.790093,0.040249,4.192861,-29.223986,0.420379,0.000000
25.910002,0.242416,-29.223986,0.000052,0.016703,0.424247,1.078322,0.054932,4.242466,-29.223986,0.425374,0.000000
26.210001,0.232735,-29.179504,0.000043,0.016902,0.429302,1.035256,0.052738,4.293025,-29.179504,0.430369,0.000000
26.510002,0.259918,-29.268465,0.000052,0.017100,0.434333,1.156174,0.058898,4.343326,-29.268465,0.435364,0.000000
26.810001,0.280769,-29.179504,0.000056,0.017292,0.439224,1.248924,0.063623,4.392238,-29.179504,0.440360,0.000000
27.110001,0.316887,-29.223986,0.000151,0.017489,0.444227,1.409583,0.071808,4.442275,-29.223986,0.445355,0.000000
27.410002,0.296410,-29.179504,0.000297,0.017687,0.449249,1.318496,0.067167,4.492489,-29.179504,0.450368,0.000000
27.710001,0.284866,-29.223986,0.000517,0.017887,0.454322,1.267149,0.064552,4.543221,-29.223986,0.455363,0.000000
28.010002,0.320236,-29.179504,0.000673,0.018076,0.459135,1.424482,0.072567,4.591350,-29.179504,0.460358,0.000000
28.310001,0.295662,-29.223986,0.000858,0.018276,0.464208,1.315170,0.066998,4.642083,-29.223986,0.465353,0.000000
28.610001,0.303856,-29.223986,0.001069,0.018463,0.468952,1.351619,0.068855,4.689523,-29.223986,0.470349,0.000000
28.910002,0.255074,-29.223986,0.001255,0.018667,0.474147,1.134624,0.057800,4.741467,-29.223986,0.475343,0.000000
29.210001,0.319122,-29.268465,0.001466,0.018863,0.479107,1.419527,0.072314,4.791075,-29.268465,0.480339,0.000000
29.510002,0.309067,-29.179504,0.001643,0.019062,0.484181,1.374798,0.070036,4.841808,-29.179504,0.485351,0.000000
29.810001,0.335876,-29.223986,0.001901,0.019264,0.489297,1.494053,0.076111,4.892972,-29.223986,0.490347,0.000000
30.110001,0.325455,-29.223986,0.002070,0.019459,0.494258,1.447695,0.073749,4.942577,-29.223986,0.495342,0.000000
30.410002,0.310188,-29.223986,0.002289,0.019655,0.499227,1.379786,0.070290,4.992269,-29.223986,0.500337,0.000000
30.710001,0.313164,-29.179504,0.002462,0.019848,0.504144,1.393022,0.070964,5.041442,-29.179504,0.505332,0.000000
31.010002,0.253960,-29.223986,0.002677,0.020048,0.509209,1.129669,0.057548,5.092088,-29.223986,0.510328,0.000000
31.310001,0.345184,-29.223986,0.002884,0.020237,0.514013,1.535457,0.078220,5.140133,-29.223986,0.515340,0.000000
31.610001,0.308327,-29.268465,0.003078,0.020437,0.519104,1.371506,0.069868,5.191036,-29.268465,0.520335,0.000000
31.910002,0.338486,-29.268465,0.003277,0.020633,0.524082,1.505660,0.076702,5.240815,-29.268465,0.525331,0.000000
32.210003,0.334389,-29.179504,0.003484,0.020836,0.529242,1.487435,0.075774,5.292415,-29.179504,0.530326,0.000000
32.510002,0.305344,-29.223986,0.003686,0.021027,0.534090,1.358236,0.069192,5.340896,-29.223986,0.535321,0.000000
32.810001,0.306458,-29.179504,0.003876,0.021224,0.539093,1.363191,0.069444,5.390932,-29.179504,0.540316,0.000000
33.110001,0.309814,-29.268465,0.004096,0.021426,0.544227,1.378124,0.070205,5.442274,-29.268465,0.545329,0.000000
33.410000,0.333641,-29.223986,0.004290,0.021622,0.549205,1.484110,0.075604,5.492053,-29.223986,0.550324,0.000000
33.710003,0.327690,-29.223986,0.004518,0.021818,0.554183,1.457639,0.074256,5.541832,-29.223986,0.555319,0.000000
34.010002,0.317261,-29.312946,0.004695,0.022014,0.559152,1.411246,0.071892,5.591524,-29.312946,0.560314,0.000000
34.310001,0.331779,-29.268465,0.004898,0.022212,0.564182,1.475829,0.075182,5.641821,-29.268465,0.565310,0.000000
34.610001,0.332901,-29.223986,0.005144,0.022404,0.569065,1.480818,0.075436,5.690646,-29.223986,0.570305,0.000000
34.910000,0.278534,-29.268465,0.005312,0.022602,0.574086,1.238981,0.063117,5.740860,-29.268465,0.575300,0.000000
35.210003,0.314651,-29.223986,0.005536,0.022801,0.579151,1.399640,0.071301,5.791506,-29.223986,0.580313,0.000000
35.510002,0.264755,-29.223986,0.005730,0.022997,0.584111,1.177690,0.059994,5.841111,-29.223986,0.585308,0.000000
35.810001,0.332153,-29.223986,0.005924,0.023194,0.589123,1.477492,0.075267,5.891234,-29.223986,0.590303,0.000000
36.110001,0.306831,-29.357428,0.006140,0.023395,0.594232,1.364854,0.069529,5.942316,-29.357428,0.595298,0.000000
36.410000,0.336998,-29.268465,0.006347,0.023596,0.599340,1.499042,0.076365,5.993396,-29.268465,0.600293,0.000000
36.710003,0.318375,-29.223986,0.006554,0.023785,0.604144,1.416201,0.072145,6.041438,-29.223986,0.605289,0.000000
37.010002,0.303108,-29.223986,0.006765,0.023984,0.609200,1.348293,0.068685,6.092000,-29.223986,0.610301,0.000000
37.310001,0.325455,-29.268465,0.006959,0.024177,0.614091,1.447695,0.073749,6.140909,-29.268465,0.615296,0.000000
37.610001,0.286354,-29.268465,0.007161,0.024375,0.619130,1.273767,0.064889,6.191297,-29.268465,0.620292,0.000000
37.910004,0.349281,-29.312946,0.007351,0.024567,0.624012,1.553681,0.079148,6.240122,-29.312946,0.625287,0.000000
38.210003,0.309441,-29.268465,0.007580,0.024769,0.629129,1.376461,0.070120,6.291286,-29.268465,0.630282,0.000000
38.510002,0.328056,-29.268465,0.007795,0.024961,0.634020,1.459267,0.074339,6.340199,-29.268465,0.635277,0.000000
38.810001,0.310928,-29.357428,0.008006,0.025169,0.639301,1.383078,0.070457,6.393013,-29.357428,0.640272,0.000000
39.110001,0.323593,-29.312946,0.008192,0.025365,0.644279,1.439414,0.073327,6.442792,-29.312946,0.645285,0.000000
39.410004,0.325081,-29.312946,0.008395,0.025551,0.649005,1.446032,0.073664,6.490054,-29.312946,0.650281,0.000000
39.710003,0.313911,-29.268465,0.008632,0.025755,0.654174,1.396348,0.071133,6.541740,-29.268465,0.655275,0.000000
40.010002,0.339233,-29.268465,0.008856,0.025950,0.659126,1.508986,0.076871,6.591262,-29.268465,0.660271,0.000000
40.310001,0.294914,-29.268465,0.009037,0.026149,0.664191,1.311844,0.066829,6.641908,-29.268465,0.665266,0.000000
40.610001,0.334015,-29.268465,0.009222,0.026336,0.668934,1.485772,0.075689,6.689344,-29.268465,0.670261,0.000000
40.910004,0.319122,-29.268465,0.009438,0.026542,0.674155,1.419527,0.072314,6.741553,-29.268465,0.675274,0.000000
41.210003,0.348167,-29.268465,0.009632,0.026732,0.678986,1.548726,0.078896,6.789855,-29.268465,0.680269,0.000000
41.510002,0.266243,-29.312946,0.009848,0.026927,0.683955,1.184308,0.060332,6.839548,-29.312946,0.685264,0.000000
41.810001,0.319496,-29.268465,0.010080,0.027132,0.689158,1.421190,0.072399,6.891582,-29.268465,0.690260,0.000000
42.110001,0.337738,-29.223986,0.010261,0.027329,0.694162,1.502334,0.076533,6.941618,-29.223986,0.695255,0.000000
42.410004,0.358223,-29.268465,0.010477,0.027528,0.699209,1.593455,0.081174,6.992094,-29.268465,0.700250,0.000000
42.710003,0.333641,-29.268465,0.010675,0.027722,0.704135,1.484110,0.075604,7.041350,-29.268465,0.705263,0.000000
43.010002,0.342583,-29.268465,0.010874,0.027924,0.709261,1.523884,0.077630,7.092606,-29.268465,0.710258,0.000000
43.310001,0.342209,-29.268465,0.011094,0.028113,0.714065,1.522221,0.077546,7.140647,-29.268465,0.715253,0.000000
43.610001,0.277786,-29.268465,0.011270,0.028313,0.719155,1.235655,0.062947,7.191554,-29.268465,0.720248,0.000000
43.910004,0.335876,-29.312946,0.011507,0.028506,0.724047,1.494053,0.076111,7.240466,-29.312946,0.725243,0.000000
44.210003,0.329178,-29.312946,0.011710,0.028706,0.729120,1.464256,0.074593,7.291199,-29.312946,0.730239,0.000000
44.510002,0.360085,-29.357428,0.011900,0.028895,0.733941,1.601736,0.081596,7.339415,-29.357428,0.735234,0.000000
44.810001,0.331039,-29.268465,0.012146,0.029100,0.739145,1.472537,0.075015,7.391449,-29.268465,0.740246,0.000000
45.110001,0.354500,-29.312946,0.012327,0.029300,0.744218,1.576894,0.080331,7.442182,-29.312946,0.745242,0.000000
45.410004,0.334763,-29.312946,0.012516,0.029495,0.749161,1.489098,0.075858,7.491613,-29.312946,0.750237,0.000000
45.710003,0.327690,-29.268465,0.012741,0.029694,0.754226,1.457639,0.074256,7.542259,-29.268465,0.755232,0.000000
46.010002,0.345932,-29.268465,0.012935,0.029885,0.759074,1.538782,0.078389,7.590739,-29.268465,0.760227,0.000000
46.310001,0.350403,-29.312946,0.013124,0.030084,0.764121,1.558670,0.079402,7.641211,-29.312946,0.765222,0.000000
46.610001,0.354866,-29.312946,0.013331,0.030277,0.769030,1.578523,0.080414,7.690297,-29.312946,0.770235,0.000000
46.910004,0.326195,-29.312946,0.013551,0.030479,0.774155,1.450987,0.073917,7.741549,-29.312946,0.775230,0.000000
47.210003,0.359711,-29.268465,0.013724,0.030669,0.778994,1.600073,0.081512,7.789938,-29.268465,0.780225,0.000000
47.510002,0.333275,-29.268465,0.013961,0.030866,0.784007,1.482481,0.075521,7.840065,-29.268465,0.785221,0.000000
47.810001,0.322845,-29.312946,0.014155,0.031063,0.789002,1.436088,0.073158,7.890018,-29.312946,0.790216,0.000000
48.110001,0.297897,-29.268465,0.014370,0.031261,0.794040,1.325114,0.067505,7.940403,-29.268465,0.795211,0.000000
48.410004,0.361572,-29.312946,0.014551,0.031460,0.799087,1.608354,0.081933,7.990875,-29.312946,0.800224,0.000000
48.710003,0.333641,-29.357428,0.014801,0.031657,0.804091,1.484110,0.075604,8.040915,-29.357428,0.805219,0.000000
49.010002,0.366409,-29.357428,0.015013,0.031858,0.809182,1.629870,0.083030,8.091822,-29.357428,0.810214,0.000000
49.310001,0.358223,-29.312946,0.015198,0.032050,0.814073,1.593455,0.081174,8.140734,-29.312946,0.815209,0.000000
49.610001,0.326942,-29.357428,0.015405,0.032249,0.819121,1.454313,0.074086,8.191205,-29.357428,0.820204,0.000000
49.910004,0.342957,-29.357428,0.015595,0.032438,0.823934,1.525547,0.077715,8.239338,-29.357428,0.825200,0.000000
50.210003,0.291191,-29.401909,0.015819,0.032641,0.829076,1.295283,0.065985,8.290763,-29.401909,0.830195,0.000000
50.510002,0.371254,-29.357428,0.016013,0.032831,0.833898,1.651420,0.084127,8.338979,-29.357428,0.835207,0.000000
50.810001,0.353752,-29.357428,0.016224,0.033033,0.839041,1.573568,0.080161,8.390409,-29.357428,0.840203,0.000000
51.110001,0.367531,-29.357428,0.016436,0.033230,0.844044,1.634859,0.083284,8.440444,-29.357428,0.845198,0.000000
51.410004,0.359711,-29.357428,0.016634,0.033432,0.849179,1.600073,0.081512,8.491787,-29.357428,0.850193,0.000000
51.710003,0.345558,-29.357428,0.016849,0.033628,0.854139,1.537120,0.078305,8.541391,-29.357428,0.855188,0.000000
52.010002,0.349281,-29.357428,0.017056,0.033820,0.859030,1.553681,0.079148,8.590303,-29.357428,0.860184,0.000000
52.310001,0.331779,-29.401909,0.017259,0.034021,0.864121,1.475829,0.075182,8.641211,-29.401909,0.865196,0.000000
52.610001,0.360825,-29.357428,0.017427,0.034215,0.869073,1.605028,0.081764,8.690728,-29.357428,0.870192,0.000000
52.910004,0.359337,-29.401909,0.017647,0.034408,0.873973,1.598410,0.081427,8.739727,-29.401909,0.875187,0.000000
53.210003,0.381683,-29.446390,0.017884,0.034606,0.878985,1.697812,0.086491,8.789851,-29.446390,0.880182,0.000000
53.510002,0.371254,-29.401909,0.018083,0.034804,0.884015,1.651420,0.084127,8.840152,-29.401909,0.885177,0.000000
53.810001,0.367905,-29.312946,0.018255,0.034996,0.888889,1.636522,0.083368,8.888890,-29.312946,0.890172,0.000000
54.110004,0.331413,-29.401909,0.018462,0.035197,0.893997,1.474200,0.075099,8.939967,-29.401909,0.895167,0.000000
54.410004,0.357849,-29.401909,0.018669,0.035395,0.899027,1.591792,0.081090,8.990269,-29.401909,0.900180,0.000000
54.710003,0.342209,-29.357428,0.018872,0.035591,0.904022,1.522221,0.077546,9.040217,-29.357428,0.905175,0.000000
55.010002,0.391365,-29.401909,0.019078,0.035789,0.909034,1.740879,0.088685,9.090345,-29.401909,0.910171,0.000000
55.310001,0.365669,-29.401909,0.019268,0.035988,0.914108,1.626578,0.082862,9.141078,-29.401909,0.915166,0.000000
55.610004,0.374977,-29.357428,0.019454,0.036187,0.919155,1.667982,0.084971,9.191549,-29.357428,0.920161,0.000000
55.910004,0.369019,-29.357428,0.019673,0.036375,0.923933,1.641477,0.083621,9.239333,-29.357428,0.925156,0.000000
56.210003,0.335503,-29.401909,0.019889,0.036573,0.928963,1.492390,0.076026,9.289635,-29.401909,0.930169,0.000000
56.510002,0.374603,-29.401909,0.020074,0.036769,0.933933,1.666319,0.084886,9.339327,-29.401909,0.935164,0.000000
56.810001,0.323593,-29.446390,0.020281,0.036968,0.938989,1.439414,0.073327,9.389885,-29.446390,0.940159,0.000000
57.110004,0.403275,-29.357428,0.020480,0.037163,0.943940,1.793855,0.091383,9.439404,-29.357428,0.945154,0.000000
57.410004,0.361946,-29.401909,0.020691,0.037364,0.949057,1.610017,0.082018,9.490571,-29.401909,0.950150,0.000000
57.710003,0.398811,-29.446390,0.020876,0.037559,0.954009,1.774001,0.090372,9.540089,-29.446390,0.955145,0.000000
58.010002,0.415192,-29.446390,0.021079,0.037759,0.959082,1.846865,0.094084,9.590821,-29.446390,0.960157,0.000000
58.310001,0.618134,-29.446390,0.021264,0.037959,0.964155,2.749595,0.140071,9.641555,-29.446390,0.965153,0.000000
58.610004,0.627815,-29.446390,0.021286,-0.000000,-0.000000,2.792662,0.142265,-0.000000,-29.446390,0.000234,0.000000
58.910004,0.619255,-29.446390,0.021303,-0.000000,-0.000000,2.754584,0.140325,-0.000000,-29.446390,0.000243,0.000000
59.210003,0.667664,-29.446390,0.021316,-0.000000,-0.000000,2.969916,0.151295,-0.000000,-29.446390,0.000737,0.000000
59.510002,0.678085,-29.490871,0.021325,0.000012,0.000312,3.016274,0.153656,0.003123,-29.490871,0.001240,0.000000
59.810001,0.803947,-29.446390,0.021320,0.000032,0.000815,3.576137,0.182177,0.008149,-29.446390,0.001743,0.000000
60.110004,0.862038,-29.446390,0.021329,0.000047,0.001197,3.834535,0.195341,0.011968,-29.446390,0.002237,0.000000
60.410004,0.910080,-29.446390,0.021351,0.000060,0.001535,4.048238,0.206227,0.015348,-29.446390,0.002740,0.000000
60.710003,1.046738,-29.490871,0.021377,0.000093,0.002367,4.656122,0.237194,0.023675,-29.490871,0.003243,0.000000
61.010002,1.115623,-29.490871,0.021402,0.000107,0.002723,4.962541,0.252804,0.027229,-29.490871,0.003738,0.000000
61.310001,1.193825,-29.490871,0.021407,0.000127,0.003235,5.310398,0.270525,0.032346,-29.490871,0.004241,0.000000
61.610004,1.295113,-29.490871,0.021398,0.000140,0.003564,5.760949,0.293477,0.035642,-29.490871,0.004744,0.000000
61.910004,1.498795,-29.535351,0.021441,0.000162,0.004119,6.666971,0.339632,0.041191,-29.535351,0.005238,0.000000
62.210003,1.639557,-29.446390,0.021458,0.000181,0.004596,7.293113,0.371529,0.045960,-29.446390,0.005741,0.000000
62.510002,1.821648,-29.446390,0.021480,0.000204,0.005177,8.103093,0.412791,0.051774,-29.446390,0.006244,0.000000
62.810001,2.027191,-29.446390,0.021497,0.000226,0.005750,9.017397,0.459368,0.057496,-29.446390,0.006738,0.000000
63.110004,2.146729,-29.446390,0.021510,0.000245,0.006235,9.549126,0.486456,0.062352,-29.446390,0.007241,0.000000
63.410004,2.302750,-29.490871,0.021523,0.000261,0.006634,10.243142,0.521811,0.066342,-29.490871,0.007744,0.000000
63.710003,2.585381,-29.490871,0.021545,0.000282,0.007163,11.500347,0.585856,0.071633,-29.490871,0.008239,0.000000
64.010002,2.781624,-29.490871,0.021553,0.000300,0.007623,12.373281,0.630325,0.076228,-29.490871,0.008742,0.000000
64.310005,2.990891,-29.535351,0.021562,0.000320,0.008126,13.304146,0.677745,0.081258,-29.535351,0.009245,0.000000
64.610001,3.300339,-29.490871,0.021609,0.000343,0.008707,14.680640,0.747867,0.087068,-29.490871,0.009739,0.000000
64.910004,3.573654,-29.490871,0.021627,0.000363,0.009218,15.896408,0.809802,0.092185,-29.490871,0.010242,0.000000
65.210007,3.727448,-29.490871,0.021657,0.000379,0.009617,16.580515,0.844652,0.096174,-29.490871,0.010736,0.000000
65.510002,3.991463,-29.490871,0.021657,0.000399,0.010129,17.754913,0.904478,0.101291,-29.490871,0.011239,0.000000
65.810005,4.426018,-29.490871,0.021678,0.000423,0.010736,19.687910,1.002950,0.107362,-29.490871,0.011742,0.000000
66.110001,4.547035,-29.535351,0.021704,0.000435,0.011048,20.226223,1.030373,0.110485,-29.535351,0.012237,0.000000
66.410004,4.926857,-29.535351,0.021704,0.000458,0.011638,21.915754,1.116442,0.116382,-29.535351,0.012740,0.000000
66.710007,5.226616,-29.535351,0.021734,0.000483,0.012271,23.249149,1.184368,0.122710,-29.535351,0.013243,0.000000
67.010002,5.494354,-29.535351,0.021743,0.000500,0.012705,24.440109,1.245039,0.127048,-29.535351,0.013737,0.000000
67.310005,5.830231,-29.446390,0.021765,0.000521,0.013225,25.934162,1.321149,0.132252,-29.446390,0.014240,0.000000
67.610001,6.178772,-29.535351,0.021786,0.000543,0.013789,27.484550,1.400130,0.137888,-29.535351,0.014743,0.000000
67.910004,6.311340,-29.490871,0.021812,0.000556,0.014110,28.074244,1.430170,0.141097,-29.490871,0.015237,0.000000
68.210007,6.747391,-29.535351,0.021846,0.000579,0.014708,30.013893,1.528981,0.147081,-29.535351,0.015740,0.000000
68.510002,7.068375,-29.490871,0.021851,0.000597,0.015176,31.441700,1.601717,0.151763,-29.490871,0.016243,0.000000
68.810005,7.273552,-29.490871,0.021877,0.000613,0.015558,32.354374,1.648210,0.155578,-29.490871,0.016737,0.000000
69.110001,7.599007,-29.490871,0.021881,0.000634,0.016104,33.802071,1.721960,0.161043,-29.490871,0.017240,0.000000
69.410004,7.915894,-29.535351,0.021894,0.000655,0.016633,35.211655,1.793767,0.166331,-29.535351,0.017743,0.000000
69.710007,8.322525,-29.490871,0.021907,0.000677,0.017188,37.020439,1.885911,0.171883,-29.490871,0.018238,0.000000
70.010002,8.380989,-29.490871,0.021928,0.000687,0.017457,37.280502,1.899159,0.174571,-29.490871,0.018741,0.000000
70.310005,8.800278,-29.535351,0.021946,0.000712,0.018082,39.145592,1.994172,0.180816,-29.535351,0.019244,0.000000
70.610001,9.362190,-29.535351,0.021993,0.000738,0.018741,41.645103,2.121503,0.187405,-29.535351,0.019738,0.000000
70.910004,9.506668,-29.490871,0.022023,0.000755,0.019183,42.287773,2.154242,0.191830,-29.490871,0.020241,0.000000
71.210007,9.778870,-29.490871,0.022010,0.000771,0.019573,43.498585,2.215924,0.195732,-29.490871,0.020744,0.000000
71.510002,10.166138,-29.490871,0.022028,0.000794,0.020163,45.221237,2.303680,0.201629,-29.490871,0.021238,0.000000
71.810005,10.460312,-29.535351,0.022049,0.000812,0.020631,46.529793,2.370341,0.206311,-29.535351,0.021741,0.000000
72.110001,10.649109,-29.535351,0.022071,0.000827,0.021004,47.369602,2.413123,0.210043,-29.535351,0.022244,0.000000
72.410004,11.311928,-29.535351,0.022079,0.000854,0.021698,50.317966,2.563319,0.216980,-29.535351,0.022739,0.000000
72.710007,11.370392,-29.579832,0.022127,0.000869,0.022080,50.578030,2.576568,0.220796,-29.579832,0.023242,0.000000
73.010002,11.661591,-29.535351,0.022127,0.000891,0.022634,51.873344,2.642554,0.226344,-29.535351,0.023745,0.000000
73.310005,11.943848,-29.446390,0.022161,0.000907,0.023033,53.128887,2.706515,0.230334,-29.446390,0.024239,0.000000
73.610001,12.352707,-29.401909,0.022166,0.000928,0.023580,54.947586,2.799163,0.235799,-29.401909,0.024742,0.000000
73.910004,12.527351,-29.490871,0.022187,0.000944,0.023979,55.724442,2.838738,0.239788,-29.490871,0.025245,0.000000
74.210007,13.357368,-29.535351,0.022178,0.000977,0.024811,59.416542,3.026823,0.248111,-29.535351,0.025739,0.000000
74.510002,13.491425,-29.490871,0.022222,0.000995,0.025271,60.012856,3.057201,0.252710,-29.490871,0.026242,0.000000
74.810005,13.659363,-29.579832,0.022234,0.001010,0.025661,60.759880,3.095256,0.256612,-29.579832,0.026745,0.000000
75.110001,14.139725,-29.535351,0.022260,0.001032,0.026225,62.896637,3.204108,0.262248,-29.535351,0.027240,0.000000
75.410004,14.455124,-29.579832,0.022291,0.001053,0.026736,64.299599,3.275578,0.267365,-29.579832,0.027743,0.000000
75.710007,14.605194,-29.579832,0.022299,0.001068,0.027118,64.967148,3.309584,0.271180,-29.579832,0.028246,0.000000
76.010002,15.170822,-29.535351,0.022329,0.001089,0.027656,67.483185,3.437757,0.276558,-29.535351,0.028740,0.000000
76.310005,15.530540,-29.579832,0.022329,0.001110,0.028202,69.083298,3.519271,0.282020,-29.579832,0.029243,0.000000
76.610001,15.961746,-29.535351,0.022360,0.001132,0.028757,71.001396,3.616983,0.287573,-29.535351,0.029746,0.000000
76.910004,16.185913,-29.490871,0.022381,0.001147,0.029130,71.998535,3.667780,0.291301,-29.490871,0.030240,0.000000
77.210007,16.789528,-29.535351,0.022403,0.001172,0.029763,74.683548,3.804561,0.297629,-29.535351,0.030743,0.000000
77.510002,16.860275,-29.535351,0.022411,0.001185,0.030110,74.998253,3.820593,0.301100,-29.535351,0.031246,0.000000
77.810005,17.146263,-29.535351,0.022407,0.001199,0.030465,76.270386,3.885399,0.304654,-29.535351,0.031741,0.000000
78.110001,18.047775,-29.579832,0.022463,0.001229,0.031211,80.280518,4.089684,0.312114,-29.579832,0.032244,0.000000
78.410004,18.392967,-29.490871,0.022463,0.001248,0.031688,81.816002,4.167906,0.316883,-29.490871,0.032738,0.000000
78.710007,18.651390,-29.579832,0.022493,0.001263,0.032087,82.965530,4.226465,0.320872,-29.579832,0.033240,0.000000
79.010002,19.037544,-29.579832,0.022510,0.001281,0.032538,84.683228,4.313969,0.325384,-29.579832,0.033743,0.000000
79.310005,19.698128,-29.579832,0.022523,0.001306,0.033171,87.621651,4.463659,0.331712,-29.579832,0.034238,0.000000
79.610001,19.953575,-29.579832,0.022532,0.001322,0.033588,88.757935,4.521544,0.335875,-29.579832,0.034741,0.000000
79.910004,20.299141,-29.535351,0.022566,0.001338,0.033986,90.295090,4.599851,0.339865,-29.535351,0.035244,0.000000
80.210007,21.421844,-29.579832,0.022605,0.001370,0.034810,95.289124,4.854259,0.348104,-29.579832,0.035738,0.000000
80.510002,21.433014,-29.579832,0.022597,0.001385,0.035183,95.338806,4.856791,0.351832,-29.579832,0.036241,0.000000
80.810005,21.852303,-29.535351,0.022584,0.001403,0.035643,97.203896,4.951802,0.356427,-29.535351,0.036744,0.000000
81.110001,22.071632,-29.579832,0.022610,0.001418,0.036016,98.179527,5.001503,0.360159,-29.579832,0.037238,0.000000
81.410004,22.719185,-29.579832,0.022640,0.001433,0.036406,101.059982,5.148241,0.364061,-29.579832,0.037741,0.000000
81.710007,23.255402,-29.535351,0.022640,0.001453,0.036900,103.445190,5.269749,0.369005,-29.535351,0.038244,0.000000
82.010002,24.301773,-29.624313,0.022674,0.001482,0.037637,108.099686,5.506861,0.376374,-29.624313,0.038739,0.000000
82.310005,24.826073,-29.579832,0.022704,0.001503,0.038175,110.431885,5.625669,0.381752,-29.579832,0.039242,0.000000
82.610001,25.195839,-29.624313,0.022713,0.001521,0.038626,112.076691,5.709458,0.386260,-29.624313,0.039745,0.000000
82.910004,25.440483,-29.579832,0.022722,0.001533,0.038938,113.164917,5.764896,0.389382,-29.579832,0.040239,0.000000
83.210007,26.397484,-29.668795,0.022748,0.001556,0.039519,117.421875,5.981756,0.395192,-29.668795,0.040742,0.000000
83.510002,26.995140,-29.535351,0.022773,0.001575,0.040014,120.080383,6.117186,0.400135,-29.535351,0.041245,0.000000
83.810005,27.201065,-29.579832,0.022761,0.001590,0.040378,120.996384,6.163849,0.403780,-29.579832,0.041739,0.000000
84.110001,28.464897,-29.668795,0.022795,0.001619,0.041132,126.618187,6.450238,0.411323,-29.668795,0.042242,0.000000
84.410004,28.935944,-29.624313,0.022812,0.001634,0.041514,128.713501,6.556978,0.415139,-29.624313,0.042745,0.000000
84.710007,29.547379,-29.624313,0.022829,0.001655,0.042043,131.433304,6.695532,0.420430,-29.624313,0.043240,0.000000
85.010002,30.447777,-29.624313,0.022847,0.001678,0.042624,135.438477,6.899565,0.426240,-29.624313,0.043743,0.000000
85.310005,30.918083,-29.668795,0.022873,0.001696,0.043075,137.530502,7.006138,0.430751,-29.668795,0.044246,0.000000
85.610001,31.445366,-29.579832,0.022851,0.001711,0.043457,139.875977,7.125622,0.434566,-29.579832,0.044740,0.000000
85.910004,32.593758,-29.535351,0.022890,0.001738,0.044150,144.984268,7.385851,0.441504,-29.535351,0.045243,0.000000
86.210007,33.493416,-29.624313,0.022911,0.001760,0.044714,148.986160,7.589716,0.447140,-29.624313,0.045746,0.000000
86.510002,34.013992,-29.668795,0.022903,0.001776,0.045122,151.301788,7.707681,0.451216,-29.668795,0.046240,0.000000
86.810005,34.639572,-29.624313,0.022924,0.001795,0.045581,154.084518,7.849439,0.455811,-29.624313,0.046743,0.000000
87.110001,35.700089,-29.624313,0.022950,0.001818,0.046180,158.801926,8.089755,0.461795,-29.624313,0.047246,0.000000
87.410004,36.159225,-29.668795,0.022959,0.001831,0.046518,160.844269,8.193798,0.465179,-29.668795,0.047741,0.000000
87.710007,37.131119,-29.624313,0.022976,0.001855,0.047108,165.167465,8.414032,0.471076,-29.624313,0.048244,0.000000
88.010002,37.968208,-29.624313,0.022998,0.001873,0.047584,168.891022,8.603719,0.475845,-29.624313,0.048747,0.000000
88.310005,38.812752,-29.668795,0.023002,0.001894,0.048096,172.647736,8.795095,0.480962,-29.668795,0.049241,0.000000
88.610001,39.488609,-29.624313,0.023011,0.001911,0.048539,175.654114,8.948247,0.485386,-29.624313,0.049744,0.000000
88.910004,40.740898,-29.668795,0.023028,0.001936,0.049180,181.224564,9.232019,0.491802,-29.668795,0.050247,0.000000
89.210007,41.417496,-29.668795,0.023041,0.001952,0.049588,184.234222,9.385338,0.495878,-29.668795,0.050741,0.000000
89.510002,41.852432,-29.668795,0.023045,0.001969,0.050022,186.168915,9.483897,0.500216,-29.668795,0.051244,0.000000
89.810005,42.946091,-29.624313,0.023075,0.001989,0.050533,191.033752,9.731723,0.505333,-29.624313,0.051747,0.000000
90.110001,44.213646,-29.668795,0.023071,0.002010,0.051053,196.672119,10.018955,0.510533,-29.668795,0.052241,0.000000
90.410004,44.974030,-29.579832,0.023110,0.002029,0.051539,200.054474,10.191260,0.515393,-29.579832,0.052744,0.000000
90.710007,45.823036,-29.624313,0.023101,0.002048,0.052025,203.831039,10.383649,0.520249,-29.624313,0.053239,0.000000
91.010002,46.925629,-29.713276,0.023088,0.002068,0.052536,208.735626,10.633499,0.525362,-29.713276,0.053742,0.000000
91.310005,47.740753,-29.624313,0.023110,0.002084,0.052927,212.361481,10.818210,0.529268,-29.624313,0.054245,0.000000
91.610001,48.392776,-29.713276,0.023131,0.002100,0.053334,215.261826,10.965960,0.533341,-29.713276,0.054739,0.000000
91.910004,50.761436,-29.668795,0.023149,0.002136,0.054262,225.798141,11.502706,0.542621,-29.668795,0.055242,0.000000
92.210007,51.283134,-29.713276,0.023170,0.002152,0.054670,228.118774,11.620925,0.546698,-29.713276,0.055745,0.000000
92.510002,52.242737,-29.757757,0.023161,0.002169,0.055086,232.387299,11.838373,0.550861,-29.757757,0.056239,0.000000
92.810005,53.295433,-29.713276,0.023166,0.002190,0.055615,237.069931,12.076918,0.556152,-29.713276,0.056742,0.000000
93.110001,54.288177,-29.624313,0.023166,0.002209,0.056110,241.485870,12.301877,0.561096,-29.624313,0.057245,0.000000
93.410004,54.977814,-29.713276,0.023196,0.002224,0.056491,244.553528,12.458150,0.564911,-29.713276,0.057740,0.000000
93.710007,56.834465,-29.713276,0.023213,0.002252,0.057202,252.812332,12.878874,0.572023,-29.713276,0.058243,0.000000
94.010002,57.520744,-29.757757,0.023179,0.002266,0.057558,255.865051,13.034387,0.575577,-29.757757,0.058746,0.000000
94.310005,58.545143,-29.757757,0.023205,0.002286,0.058069,260.421814,13.266520,0.580694,-29.757757,0.059240,0.000000
94.610008,59.552040,-29.757757,0.023230,0.002305,0.058538,264.900696,13.494685,0.585376,-29.757757,0.059743,0.000000
94.910004,60.779373,-29.713276,0.023226,0.002325,0.059049,270.360168,13.772802,0.590493,-29.713276,0.060246,0.000000
95.210007,61.434753,-29.802237,0.023243,0.002337,0.059353,273.275421,13.921314,0.593528,-29.802237,0.060740,0.000000
95.510002,62.219337,-29.757757,0.023230,0.002355,0.059821,276.765442,14.099103,0.598210,-29.757757,0.061243,0.000000
95.810005,64.913834,-29.757757,0.023265,0.002389,0.060689,288.751160,14.709685,0.606885,-29.757757,0.061746,0.000000
96.110008,65.591171,-29.713276,0.023278,0.002403,0.061044,291.764099,14.863172,0.610439,-29.713276,0.062241,0.000000
96.410004,66.666580,-29.757757,0.023269,0.002426,0.061616,296.547760,15.106863,0.616162,-29.757757,0.062744,0.000000
96.710007,67.485809,-29.713276,0.023269,0.002429,0.061685,300.191864,15.292503,0.616855,-29.713276,0.061955,0.000000
97.010002,66.978256,-29.757757,0.023274,0.002421,0.061503,297.934174,15.177490,0.615034,-29.757757,0.061685,0.000000
97.310005,66.602158,-29.757757,0.023278,0.002420,0.061469,296.261200,15.092264,0.614690,-29.757757,0.061685,0.000000
97.610008,66.297562,-29.757757,0.023299,0.002420,0.061469,294.906281,15.023242,0.614690,-29.757757,0.061685,0.000000
97.910004,66.045471,-29.757757,0.023291,0.002420,0.061469,293.784943,14.966118,0.614690,-29.757757,0.061685,0.000000
98.210007,65.822418,-29.757757,0.023287,0.002420,0.061469,292.792725,14.915573,0.614690,-29.757757,0.061685,0.000000
98.510002,65.644791,-29.802237,0.023304,0.002420,0.061469,292.002625,14.875322,0.614690,-29.802237,0.061685,0.000000
98.810005,65.466049,-29.757757,0.023308,0.002420,0.061469,291.207520,14.834819,0.614690,-29.757757,0.061685,0.000000
99.110008,65.331253,-29.802237,0.023291,0.002420,0.061469,290.607941,14.804274,0.614690,-29.802237,0.061685,0.000000
99.410004,65.193848,-29.802237,0.023287,0.002420,0.061469,289.996704,14.773137,0.614690,-29.802237,0.061685,0.000000
99.710007,65.064636,-29.802237,0.023321,0.002420,0.061469,289.421967,14.743857,0.614690,-29.802237,0.061685,0.000000
100.010002,64.941010,-29.757757,0.023308,0.002420,0.061469,288.872040,14.715843,0.614690,-29.757757,0.061685,0.000000
100.310005,64.847916,-29.846718,0.023282,0.002420,0.061469,288.457947,14.694748,0.614690,-29.846718,0.061685,0.000000
100.610008,64.735840,-29.713276,0.023299,0.002420,0.061469,287.959412,14.669351,0.614690,-29.713276,0.061685,0.000000
100.910004,64.647949,-29.757757,0.023287,0.002420,0.061469,287.568451,14.649435,0.614690,-29.757757,0.061685,0.000000
101.210007,64.560822,-29.757757,0.023269,0.002420,0.061469,287.180878,14.629691,0.614690,-29.757757,0.061685,0.000000
101.510002,64.487839,-29.757757,0.023312,0.002420,0.061469,286.856232,14.613153,0.614690,-29.757757,0.061685,0.000000
101.810005,64.411499,-29.757757,0.023334,0.002420,0.061469,286.516663,14.595854,0.614690,-29.757757,0.061685,0.000000
102.110008,64.339264,-29.757757,0.023321,0.002420,0.061469,286.195343,14.579486,0.614690,-29.757757,0.061685,0.000000
102.410004,64.267761,-29.757757,0.023317,0.002420,0.061469,285.877289,14.563282,0.614690,-29.757757,0.061685,0.000000
102.710007,64.192917,-29.802237,0.023312,0.002420,0.061469,285.544342,14.546323,0.614690,-29.802237,0.061685,0.000000
103.010002,64.137436,-29.802237,0.023291,0.002420,0.061469,285.297577,14.533751,0.614690,-29.802237,0.061685,0.000000
103.310005,64.068176,-29.846718,0.023291,0.002420,0.061469,284.989471,14.518057,0.614690,-29.846718,0.061685,0.000000
103.610008,64.016037,-29.802237,0.023287,0.002420,0.061469,284.757568,14.506241,0.614690,-29.802237,0.061685,0.000000
103.910004,63.968002,-29.802237,0.023282,0.002420,0.061469,284.543884,14.495357,0.614690,-29.802237,0.061685,0.000000
104.210007,63.920715,-29.757757,0.023304,0.002420,0.061469,284.333557,14.484642,0.614690,-29.757757,0.061685,0.000000
104.510002,63.861130,-29.802237,0.023291,0.002420,0.061469,284.068481,14.471138,0.614690,-29.802237,0.061685,0.000000
104.810005,63.811600,-29.846718,0.023304,0.002420,0.061469,283.848175,14.459915,0.614690,-29.846718,0.061685,0.000000
105.110008,63.762817,-29.846718,0.023282,0.002420,0.061469,283.631165,14.448861,0.614690,-29.846718,0.061685,0.000000
105.410004,63.731918,-29.802237,0.023304,0.002420,0.061469,283.493744,14.441858,0.614690,-29.802237,0.061685,0.000000
105.710007,63.679779,-29.802237,0.023308,0.002420,0.061469,283.261810,14.430044,0.614690,-29.802237,0.061685,0.000000
106.010002,63.637711,-29.802237,0.023299,0.002420,0.061469,283.074677,14.420511,0.614690,-29.802237,0.061685,0.000000
106.310005,63.596008,-29.802237,0.023304,0.002420,0.061469,282.889160,14.411062,0.614690,-29.802237,0.061685,0.000000
106.610008,63.554291,-29.802237,0.023299,0.002420,0.061469,282.703613,14.401608,0.614690,-29.802237,0.061685,0.000000
106.910004,63.520035,-29.846718,0.023295,0.002420,0.061469,282.551239,14.393846,0.614690,-29.846718,0.061685,0.000000
107.210007,63.473862,-29.757757,0.023295,0.002420,0.061469,282.345825,14.383383,0.614690,-29.757757,0.061685,0.000000
107.510002,63.439606,-29.802237,0.023308,0.002420,0.061469,282.193451,14.375620,0.614690,-29.802237,0.061685,0.000000
107.810005,63.407585,-29.802237,0.023299,0.002420,0.061469,282.051025,14.368364,0.614690,-29.802237,0.061685,0.000000
108.110008,63.369972,-29.757757,0.023304,0.002420,0.061469,281.883728,14.359840,0.614690,-29.757757,0.061685,0.000000
108.410004,63.341301,-29.802237,0.023308,0.002420,0.061469,281.756165,14.353344,0.614690,-29.802237,0.061685,0.000000
108.710007,63.283585,-29.802237,0.023295,0.002420,0.061469,281.499451,14.340265,0.614690,-29.802237,0.061685,0.000000
109.010002,63.281349,-29.802237,0.023295,0.002420,0.061469,281.489502,14.339758,0.614690,-29.802237,0.061685,0.000000
109.310005,63.234428,-29.802237,0.023334,0.002420,0.061469,281.280792,14.329126,0.614690,-29.802237,0.061685,0.000000
109.610008,63.205009,-29.802237,0.023312,0.002420,0.061469,281.149933,14.322459,0.614690,-29.802237,0.061685,0.000000
109.910004,63.168144,-29.757757,0.023317,0.002420,0.061469,280.985931,14.314106,0.614690,-29.757757,0.061685,0.000000
110.210007,63.137611,-29.757757,0.023317,0.002420,0.061469,280.850128,14.307187,0.614690,-29.757757,0.061685,0.000000
110.510002,63.116386,-29.802237,0.023299,0.002420,0.061469,280.755707,14.302378,0.614690,-29.802237,0.061685,0.000000
110.810005,63.086967,-29.802237,0.023312,0.002420,0.061469,280.624847,14.295711,0.614690,-29.802237,0.061685,0.000000
111.110008,63.048988,-29.891199,0.023312,0.002420,0.061469,280.455902,14.287106,0.614690,-29.891199,0.061685,0.000000
111.410004,63.017708,-29.802237,0.023304,0.002420,0.061469,280.316772,14.280017,0.614690,-29.802237,0.061685,0.000000
111.710007,62.995735,-29.802237,0.023308,0.002420,0.061469,280.219025,14.275038,0.614690,-29.802237,0.061685,0.000000
112.010002,62.966690,-29.802237,0.023295,0.002420,0.061469,280.089813,14.268456,0.614690,-29.802237,0.061685,0.000000
112.310005,62.932060,-29.846718,0.023317,0.002420,0.061469,279.935791,14.260610,0.614690,-29.846718,0.061685,0.000000
112.610008,62.913818,-29.846718,0.023312,0.002420,0.061469,279.854645,14.256474,0.614690,-29.846718,0.061685,0.000000
112.910004,62.888870,-29.846718,0.023321,0.002420,0.061469,279.743652,14.250822,0.614690,-29.846718,0.061685,0.000000
113.210007,62.865776,-29.846718,0.023299,0.002420,0.061469,279.640930,14.245589,0.614690,-29.846718,0.061685,0.000000
113.510002,62.837479,-29.846718,0.023299,0.002420,0.061469,279.515076,14.239176,0.614690,-29.846718,0.061685,0.000000
113.810005,62.806946,-29.891199,0.023317,0.002420,0.061469,279.379242,14.232257,0.614690,-29.891199,0.061685,0.000000
114.110008,62.786835,-29.846718,0.023321,0.002420,0.061469,279.289795,14.227700,0.614690,-29.846718,0.061685,0.000000
114.410004,62.765610,-29.802237,0.023321,0.002420,0.061469,279.195374,14.222890,0.614690,-29.802237,0.061685,0.000000
114.710007,62.748108,-29.891199,0.023321,0.002420,0.061469,279.117523,14.218925,0.614690,-29.891199,0.061685,0.000000
115.010002,62.710503,-29.846718,0.023304,0.002420,0.061469,278.950256,14.210402,0.614690,-29.846718,0.061685,0.000000
115.310005,62.709755,-29.846718,0.023312,0.002420,0.061469,278.946930,14.210234,0.614690,-29.846718,0.061685,0.000000
115.610008,62.680710,-29.846718,0.023308,0.002420,0.061469,278.817719,14.203652,0.614690,-29.846718,0.061685,0.000000
115.910004,62.641983,-29.891199,0.023317,0.002420,0.061469,278.645447,14.194876,0.614690,-29.891199,0.061685,0.000000
116.210007,62.627831,-29.891199,0.023308,0.002420,0.061469,278.582489,14.191669,0.614690,-29.891199,0.061685,0.000000
116.510002,62.609589,-29.846718,0.023308,0.002420,0.061469,278.501373,14.187535,0.614690,-29.846718,0.061685,0.000000
116.810005,62.585381,-29.846718,0.023304,0.002420,0.061469,278.393677,14.182050,0.614690,-29.846718,0.061685,0.000000
117.110008,62.561180,-29.935680,0.023308,0.002420,0.061469,278.286041,14.176566,0.614690,-29.935680,0.061685,0.000000
117.410004,62.548149,-29.846718,0.023317,0.002420,0.061469,278.228058,14.173614,0.614690,-29.846718,0.061685,0.000000
117.710007,62.509789,-29.846718,0.023299,0.002420,0.061469,278.057434,14.164921,0.614690,-29.846718,0.061685,0.000000
118.010002,62.504204,-29.846718,0.023299,0.002420,0.061469,278.032593,14.163655,0.614690,-29.846718,0.061685,0.000000
118.310005,62.477020,-29.846718,0.023312,0.002420,0.061469,277.911652,14.157495,0.614690,-29.846718,0.061685,0.000000
118.610008,62.462875,-29.891199,0.023317,0.002420,0.061469,277.848755,14.154290,0.614690,-29.891199,0.061685,0.000000
118.910004,62.442764,-29.891199,0.023317,0.002420,0.061469,277.759277,14.149733,0.614690,-29.891199,0.061685,0.000000
119.210007,62.423775,-29.891199,0.023308,0.002420,0.061469,277.674805,14.145430,0.614690,-29.891199,0.061685,0.000000
119.510002,62.404037,-29.891199,0.023330,0.002420,0.061469,277.587036,14.140958,0.614690,-29.891199,0.061685,0.000000
119.810005,62.386536,-29.935680,0.023304,0.002420,0.061469,277.509155,14.136992,0.614690,-29.935680,0.061685,0.000000
120.110008,62.373505,-29.980162,0.023312,0.002420,0.061469,277.451202,14.134038,0.614690,-29.980162,0.061685,0.000000
120.410004,62.351532,-29.935680,0.023334,0.002420,0.061469,277.353455,14.129059,0.614690,-29.935680,0.061685,0.000000
120.710007,62.334778,-29.935680,0.023325,0.002420,0.061469,277.278931,14.125262,0.614690,-29.935680,0.061685,0.000000
121.010002,62.315788,-29.935680,0.023308,0.002420,0.061469,277.194458,14.120959,0.614690,-29.935680,0.061685,0.000000
121.310005,62.299026,-29.891199,0.023338,0.002420,0.061469,277.119904,14.117161,0.614690,-29.891199,0.061685,0.000000
121.610008,62.280411,-30.024641,0.023317,0.002420,0.061469,277.037109,14.112944,0.614690,-30.024641,0.061685,0.000000
121.910004,62.266632,-29.935680,0.023312,0.002420,0.061469,276.975800,14.109820,0.614690,-29.935680,0.061685,0.000000
122.210007,62.249878,-29.980162,0.023287,0.002420,0.061469,276.901276,14.106024,0.614690,-29.980162,0.061685,0.000000
122.510002,62.221573,-29.980162,0.023334,0.002420,0.061469,276.775391,14.099609,0.614690,-29.980162,0.061685,0.000000
122.810005,62.221573,-29.935680,0.023317,0.002420,0.061469,276.775391,14.099609,0.614690,-29.935680,0.061685,0.000000
123.110008,62.201096,-29.935680,0.023299,0.002420,0.061469,276.684296,14.094970,0.614690,-29.935680,0.061685,0.000000
123.410004,62.182106,-29.980162,0.023295,0.002420,0.061469,276.599823,14.090667,0.614690,-29.980162,0.061685,0.000000
123.710007,62.152687,-29.980162,0.023299,0.002420,0.061469,276.468964,14.084001,0.614690,-29.980162,0.061685,0.000000
124.010002,62.145981,-29.980162,0.023308,0.002420,0.061469,276.439117,14.082480,0.614690,-29.980162,0.061685,0.000000
124.310005,62.114334,-29.980162,0.023308,0.002420,0.061469,276.298370,14.075310,0.614690,-29.980162,0.061685,0.000000
124.610008,62.109489,-29.935680,0.023295,0.002420,0.061469,276.276794,14.074211,0.614690,-29.935680,0.061685,0.000000
124.910004,62.100929,-29.980162,0.023330,0.002420,0.061469,276.238739,14.072272,0.614690,-29.980162,0.061685,0.000000
125.210007,62.079330,-29.980162,0.023308,0.002420,0.061469,276.142639,14.067378,0.614690,-29.980162,0.061685,0.000000
125.510010,62.080818,-30.024641,0.023325,0.002420,0.061469,276.149261,14.067715,0.614690,-30.024641,0.061685,0.000000
125.810005,62.047676,-29.980162,0.023312,0.002420,0.061469,276.001862,14.060205,0.614690,-29.980162,0.061685,0.000000
126.110008,62.029800,-30.069122,0.023321,0.002420,0.061469,275.922333,14.056153,0.614690,-30.069122,0.061685,0.000000
126.410004,62.028313,-29.980162,0.023347,0.002420,0.061469,275.915710,14.055817,0.614690,-29.980162,0.061685,0.000000
126.710007,62.008209,-29.980162,0.023321,0.002420,0.061469,275.826294,14.051261,0.614690,-29.980162,0.061685,0.000000
127.010010,61.998894,-30.024641,0.023325,0.002420,0.061469,275.784851,14.049150,0.614690,-30.024641,0.061685,0.000000
127.100006,61.994431,-29.935680,0.023334,0.002420,0.061469,275.765015,14.048139,0.614690,-29.935680,0.061685,0.000000