File: Data/I-18 Lathed test 1_10242023_165010.csv
Time (sec),S:Load (lbs),S:HL1 (DIM),S:LVDT (in),S:Position (in),Ch:Position (mm),Ch:Load (N),Ch:Stress (MPa),Ch:Strain (mm/mm),Ch:HL1 (DIM),Set Point (),Cycles ()
0.110000,-0.000374,-14.011499,-0.000013,-0.000000,-0.000000,-0.001663,-0.000085,-0.000000,-14.011499,0.000078,0.000000
0.320000,0.000366,-13.967019,-0.000004,-0.000000,-0.000000,0.001629,0.000083,-0.000000,-13.967019,0.000078,0.000000
0.530000,-0.052879,-13.922538,-0.000004,0.000077,0.001960,-0.235219,-0.011983,0.019598,-13.922538,0.002506,0.000000
0.740000,-0.013039,-14.055981,-0.000030,0.000201,0.005117,-0.057999,-0.002955,0.051166,-14.055981,0.006010,0.000000
0.950000,-0.032768,-13.967019,0.000082,0.000331,0.008395,-0.145760,-0.007425,0.083947,-13.967019,0.009496,0.000000
1.160000,-0.030540,-14.055981,0.000211,0.000468,0.011898,-0.135851,-0.006921,0.118982,-14.055981,0.013000,0.000000
1.370000,-0.011543,-14.011499,0.000388,0.000610,0.015489,-0.051347,-0.002616,0.154885,-14.011499,0.016503,0.000000
1.580000,-0.000374,-13.922538,0.000517,0.000747,0.018984,-0.001663,-0.000085,0.189835,-13.922538,0.019990,0.000000
1.790000,-0.002609,-14.011499,0.000677,0.000887,0.022531,-0.011607,-0.000591,0.225305,-14.011499,0.023493,0.000000
2.000000,-0.003357,-13.967019,0.000798,0.001021,0.025921,-0.014932,-0.000761,0.259212,-13.967019,0.026997,0.000000
2.210000,0.010796,-14.055981,0.000923,0.001157,0.029399,0.048021,0.002446,0.293990,-14.055981,0.030483,0.000000
2.420000,-0.001862,-13.967019,0.001095,0.001298,0.032963,-0.008281,-0.000422,0.329632,-13.967019,0.033986,0.000000
2.630000,-0.020859,-13.967019,0.001246,0.001435,0.036458,-0.092784,-0.004727,0.364582,-13.967019,0.037490,0.000000
2.840000,0.002602,-14.055981,0.001393,0.001560,0.039623,0.011573,0.000590,0.396235,-14.055981,0.040994,0.000000
3.050000,0.005959,-14.011499,0.001526,0.001715,0.043561,0.026505,0.001350,0.435607,-14.011499,0.044480,0.000000
3.260000,0.002228,-14.011499,0.001699,0.001851,0.047004,0.009910,0.000505,0.470037,-14.011499,0.047984,0.000000
3.470000,-0.010056,-14.011499,0.001828,0.001987,0.050464,-0.044729,-0.002279,0.504638,-14.011499,0.051487,0.000000
3.680000,0.005211,-14.100462,0.001983,0.002122,0.053889,0.023179,0.001181,0.538893,-14.100462,0.054973,0.000000
3.890000,-0.013779,-14.055981,0.002147,0.002263,0.057471,-0.061291,-0.003122,0.574710,-14.055981,0.058477,0.000000
4.100000,0.000366,-13.967019,0.002285,0.002401,0.060975,0.001629,0.000083,0.609747,-13.967019,0.061980,0.000000
4.310000,0.005959,-14.055981,0.002414,0.002532,0.064305,0.026505,0.001350,0.643048,-14.055981,0.065484,0.000000
4.520000,0.006325,-14.011499,0.002565,0.002670,0.067817,0.028134,0.001433,0.678170,-14.011499,0.068970,0.000000
4.730000,0.004463,-14.100462,0.002703,0.002808,0.071312,0.019853,0.001011,0.713120,-14.100462,0.072474,0.000000
4.940000,0.029411,-14.100462,0.002824,0.002939,0.074659,0.130828,0.006665,0.746593,-14.100462,0.075978,0.000000
5.150000,0.015640,-14.011499,0.002979,0.003080,0.078241,0.069571,0.003544,0.782410,-14.011499,0.079464,0.000000
5.360000,0.015640,-14.144942,0.003165,0.003228,0.081996,0.069571,0.003544,0.819962,-14.144942,0.082967,0.000000
5.570000,0.035744,-14.100462,0.003290,0.003369,0.085569,0.158996,0.008100,0.855691,-14.100462,0.086471,0.000000
5.780000,-0.000748,-14.055981,0.003406,0.003499,0.088865,-0.003326,-0.000169,0.888646,-14.055981,0.089975,0.000000
5.990000,-0.018623,-14.100462,0.003548,0.003639,0.092420,-0.082841,-0.004220,0.924201,-14.100462,0.093461,0.000000
6.200000,-0.018623,-14.100462,0.003734,0.003774,0.095872,-0.082841,-0.004220,0.958718,-14.100462,0.096964,0.000000
6.410000,-0.019737,-14.100462,0.003859,0.003911,0.099341,-0.087796,-0.004473,0.993406,-14.100462,0.100468,0.000000
6.620000,0.004837,-14.100462,0.004014,0.004051,0.102888,0.021516,0.001096,1.028876,-14.100462,0.103954,0.000000
6.830000,-0.008942,-14.144942,0.004182,0.004188,0.106383,-0.039774,-0.002026,1.063826,-14.144942,0.107458,0.000000
7.040000,0.013779,-14.144942,0.004290,0.004322,0.109791,0.061291,0.003122,1.097907,-14.144942,0.110961,0.000000
7.250000,0.013779,-14.100462,0.004419,0.004455,0.113164,0.061291,0.003122,1.131642,-14.100462,0.114465,0.000000
7.460001,0.039467,-14.144942,0.004583,0.004596,0.116737,0.175557,0.008943,1.167371,-14.144942,0.117951,0.000000
7.670001,0.029045,-14.144942,0.004751,0.004739,0.120362,0.129199,0.006582,1.203621,-14.144942,0.121455,0.000000
7.880001,0.016754,-14.189424,0.004894,0.004882,0.124013,0.074526,0.003797,1.240132,-14.189424,0.124959,0.000000
8.090000,0.011909,-14.189424,0.005023,0.005020,0.127508,0.052976,0.002699,1.275082,-14.189424,0.128445,0.000000
8.300000,0.003349,-14.100462,0.005208,0.005156,0.130951,0.014898,0.000759,1.309509,-14.100462,0.131948,0.000000
8.510000,-0.022346,-14.144942,0.005312,0.005289,0.134342,-0.099402,-0.005064,1.343418,-14.144942,0.135452,0.000000
8.720000,-0.045807,-14.189424,0.005463,0.005429,0.137906,-0.203759,-0.010380,1.379061,-14.189424,0.138938,0.000000
8.930000,-0.029045,-14.233904,0.005601,0.005567,0.141392,-0.129199,-0.006582,1.413923,-14.233904,0.142442,0.000000
9.140000,0.011909,-14.233904,0.005760,0.005701,0.144801,0.052976,0.002699,1.448006,-14.233904,0.145946,0.000000
9.350000,0.016754,-14.144942,0.005902,0.005837,0.148269,0.074526,0.003797,1.482695,-14.144942,0.149449,0.000000
9.560000,0.020103,-14.233904,0.006040,0.005976,0.151799,0.089425,0.004556,1.517993,-14.233904,0.152935,0.000000
9.770000,0.030533,-14.189424,0.006200,0.006115,0.155311,0.135817,0.006919,1.553113,-14.189424,0.156439,0.000000
9.980000,0.001488,-14.233904,0.006364,0.006256,0.158910,0.006618,0.000337,1.589103,-14.233904,0.159942,0.000000
10.190001,0.020477,-14.233904,0.006489,0.006395,0.162431,0.091088,0.004640,1.624314,-14.233904,0.163429,0.000000
10.400001,0.005959,-14.189424,0.006640,0.006537,0.166039,0.026505,0.001350,1.660388,-14.189424,0.166932,0.000000
10.610001,0.012283,-14.233904,0.006782,0.006672,0.169473,0.054639,0.002783,1.694732,-14.233904,0.170436,0.000000
10.820001,-0.023460,-14.189424,0.006894,0.006808,0.172916,-0.104357,-0.005316,1.729160,-14.189424,0.173939,0.000000
11.030001,-0.033890,-14.233904,0.007054,0.006944,0.176376,-0.150749,-0.007680,1.763765,-14.233904,0.177426,0.000000
11.240001,-0.015640,-14.189424,0.007226,0.007078,0.179776,-0.069571,-0.003544,1.797757,-14.189424,0.180929,0.000000
11.450001,0.000740,-14.233904,0.007347,0.007213,0.183219,0.003292,0.000168,1.832188,-14.233904,0.184433,0.000000
11.660001,0.012657,-14.278385,0.007489,0.007352,0.186740,0.056302,0.002868,1.867395,-14.278385,0.187919,0.000000
11.870001,0.018990,-14.189424,0.007636,0.007497,0.190417,0.084470,0.004303,1.904166,-14.189424,0.191423,0.000000
12.080001,0.016006,-14.233904,0.007808,0.007633,0.193886,0.071200,0.003627,1.938858,-14.233904,0.194926,0.000000
12.290001,0.037605,-14.233904,0.007942,0.007766,0.197268,0.167277,0.008521,1.972676,-14.233904,0.198430,0.000000
12.500001,0.023460,-14.189424,0.008084,0.007909,0.200893,0.104357,0.005316,2.008928,-14.189424,0.201916,0.000000
12.710001,0.004097,-14.322866,0.008252,0.008049,0.204457,0.018224,0.000928,2.044570,-14.322866,0.205420,0.000000
12.920001,-0.006332,-14.233904,0.008377,0.008183,0.207857,-0.028168,-0.001435,2.078566,-14.233904,0.208923,0.000000
13.130001,-0.002235,-14.278385,0.008524,0.008322,0.211386,-0.009944,-0.000507,2.113864,-14.278385,0.212409,0.000000
13.340001,-0.021973,-14.278385,0.008666,0.008461,0.214916,-0.097739,-0.004979,2.149158,-14.278385,0.215913,0.000000
13.550000,0.008560,-14.233904,0.008804,0.008595,0.218324,0.038078,0.001940,2.183241,-14.233904,0.219417,0.000000
13.760000,-0.001122,-14.278385,0.008959,0.008731,0.221767,-0.004989,-0.000254,2.217668,-14.278385,0.222920,0.000000
13.970000,0.007446,-14.233904,0.009102,0.008869,0.225271,0.033123,0.001687,2.252705,-14.233904,0.226407,0.000000
14.180000,0.018616,-14.367347,0.009261,0.009012,0.228913,0.082807,0.004218,2.289127,-14.367347,0.229910,0.000000
14.390000,0.017128,-14.322866,0.009356,0.009149,0.232390,0.076189,0.003881,2.323903,-14.322866,0.233414,0.000000
14.600000,0.021225,-14.278385,0.009546,0.009283,0.235790,0.094413,0.004810,2.357899,-14.278385,0.236900,0.000000
14.810000,0.042824,-14.322866,0.009671,0.009423,0.239337,0.190490,0.009704,2.393371,-14.322866,0.240404,0.000000
15.020000,0.015640,-14.233904,0.009826,0.009561,0.242858,0.069571,0.003544,2.428578,-14.233904,0.243907,0.000000
15.230000,0.024948,-14.322866,0.009977,0.009696,0.246266,0.110975,0.005653,2.462661,-14.322866,0.247394,0.000000
15.440001,0.011169,-14.322866,0.010111,0.009838,0.249883,0.049684,0.002531,2.498826,-14.322866,0.250897,0.000000
15.650001,0.023460,-14.322866,0.010253,0.009966,0.253126,0.104357,0.005316,2.531258,-14.322866,0.254401,0.000000
15.860001,-0.003723,-14.367347,0.010421,0.010112,0.256838,-0.016561,-0.000844,2.568377,-14.367347,0.257904,0.000000
16.070002,-0.005219,-14.367347,0.010546,0.010249,0.260315,-0.023213,-0.001183,2.603152,-14.367347,0.261391,0.000000
16.280001,0.011909,-14.367347,0.010684,0.010387,0.263819,0.052976,0.002699,2.638185,-14.367347,0.264894,0.000000
16.490002,0.017868,-14.367347,0.010843,0.010525,0.267340,0.079481,0.004049,2.673396,-14.367347,0.268397,0.000000
16.700001,0.007446,-14.367347,0.010994,0.010666,0.270904,0.033123,0.001687,2.709038,-14.367347,0.271884,0.000000
16.910002,0.023087,-14.411828,0.011132,0.010801,0.274338,0.102694,0.005231,2.743383,-14.411828,0.275387,0.000000
17.120001,0.026810,-14.367347,0.011279,0.010934,0.277720,0.119255,0.006075,2.777205,-14.367347,0.278891,0.000000
17.330000,0.035370,-14.411828,0.011391,0.011070,0.281189,0.157333,0.008015,2.811893,-14.411828,0.282395,0.000000
17.540001,0.036118,-14.411828,0.011559,0.011210,0.284745,0.160659,0.008184,2.847448,-14.411828,0.285881,0.000000
17.750000,0.018616,-14.322866,0.011701,0.011343,0.288101,0.082807,0.004218,2.881009,-14.322866,0.289384,0.000000
17.960001,0.029785,-14.411828,0.011839,0.011486,0.291743,0.132491,0.006749,2.917435,-14.411828,0.292888,0.000000
18.170000,0.035370,-14.322866,0.012012,0.011630,0.295412,0.157333,0.008015,2.954118,-14.322866,0.296374,0.000000
18.380001,0.009308,-14.456309,0.012176,0.011768,0.298907,0.041403,0.002109,2.989068,-14.456309,0.299878,0.000000
18.590000,0.027550,-14.456309,0.012301,0.011900,0.302263,0.122547,0.006243,3.022629,-14.456309,0.303382,0.000000
18.800001,0.012657,-14.411828,0.012439,0.012039,0.305792,0.056302,0.002868,3.057923,-14.411828,0.306885,0.000000
19.010000,0.009308,-14.456309,0.012598,0.012178,0.309331,0.041403,0.002109,3.093307,-14.456309,0.310371,0.000000
19.220001,0.027550,-14.411828,0.012741,0.012313,0.312756,0.122547,0.006243,3.127561,-14.411828,0.313875,0.000000
19.430000,0.029411,-14.456309,0.012891,0.012450,0.316225,0.130828,0.006665,3.162250,-14.456309,0.317379,0.000000
19.640001,0.021591,-14.456309,0.013016,0.012586,0.319677,0.096042,0.004893,3.196768,-14.456309,0.320865,0.000000
19.850000,0.042076,-14.456309,0.013163,0.012719,0.323068,0.187164,0.009535,3.230677,-14.456309,0.324369,0.000000
20.060001,0.042824,-14.456309,0.013310,0.012858,0.326597,0.190490,0.009704,3.265971,-14.456309,0.327872,0.000000
20.270000,0.047661,-14.411828,0.013456,0.012999,0.330179,0.212006,0.010800,3.301787,-14.411828,0.331376,0.000000
20.480001,0.051010,-14.545271,0.013620,0.013143,0.333821,0.226904,0.011559,3.338213,-14.545271,0.334862,0.000000
20.690001,0.035744,-14.411828,0.013771,0.013281,0.337333,0.158996,0.008100,3.373333,-14.411828,0.338365,0.000000
20.900002,0.005585,-14.500790,0.013909,0.013417,0.340802,0.024842,0.001266,3.408022,-14.500790,0.341869,0.000000
21.110001,0.014893,-14.545271,0.014051,0.013554,0.344271,0.066245,0.003375,3.442714,-14.545271,0.345355,0.000000
21.320002,-0.003357,-14.456309,0.014215,0.013690,0.347714,-0.014932,-0.000761,3.477141,-14.456309,0.348859,0.000000
21.530001,-0.008194,-14.545271,0.014353,0.013830,0.351278,-0.036449,-0.001857,3.512784,-14.545271,0.352362,0.000000
21.740002,0.007072,-14.456309,0.014487,0.013967,0.354765,0.031460,0.001603,3.547646,-14.456309,0.355849,0.000000
21.950001,0.037231,-14.500790,0.014655,0.014104,0.358233,0.165614,0.008437,3.582335,-14.500790,0.359352,0.000000
22.160002,0.042076,-14.456309,0.014767,0.014238,0.361650,0.187164,0.009535,3.616505,-14.456309,0.362856,0.000000
22.370001,0.058456,-14.456309,0.014939,0.014377,0.365171,0.260027,0.013246,3.651712,-14.456309,0.366359,0.000000
22.580002,0.056229,-14.589752,0.015060,0.014513,0.368623,0.250117,0.012742,3.686230,-14.589752,0.369846,0.000000
22.790001,0.040588,-14.500790,0.015233,0.014658,0.372309,0.180546,0.009197,3.723088,-14.500790,0.373349,0.000000
23.000002,0.032768,-14.545271,0.015358,0.014797,0.375856,0.145760,0.007425,3.758556,-14.545271,0.376853,0.000000
23.210001,0.023460,-14.589752,0.015509,0.014935,0.379351,0.104357,0.005316,3.793506,-14.589752,0.380339,0.000000
23.420002,0.030907,-14.456309,0.015668,0.015069,0.382741,0.137480,0.007004,3.827415,-14.456309,0.383843,0.000000
23.630001,-0.009315,-14.545271,0.015780,0.015209,0.386306,-0.041437,-0.002111,3.863057,-14.545271,0.387346,0.000000
23.840002,0.007820,-14.500790,0.015940,0.015346,0.389792,0.034786,0.001772,3.897919,-14.500790,0.390850,0.000000
24.050001,0.022339,-14.545271,0.016086,0.015478,0.393148,0.099368,0.005062,3.931480,-14.545271,0.394336,0.000000
24.260000,0.066650,-14.545271,0.016207,0.015615,0.396617,0.296476,0.015103,3.966169,-14.545271,0.397840,0.000000
24.470001,0.128090,-14.545271,0.016362,0.015755,0.400172,0.569772,0.029026,4.001724,-14.545271,0.401343,0.000000
24.680000,0.252464,-14.589752,0.016509,0.015894,0.403711,1.123017,0.057209,4.037109,-14.589752,0.404830,0.000000
24.890001,0.670265,-14.545271,0.016642,0.016033,0.407240,2.981488,0.151884,4.072403,-14.545271,0.408333,0.000000
25.100000,0.720909,-14.545271,0.016677,-0.000011,-0.000269,3.206764,0.163360,-0.002691,-14.545271,-0.000044,0.000000
25.310001,0.725380,-14.500790,0.016673,-0.000011,-0.000269,3.226651,0.164373,-0.002691,-14.500790,-0.000044,0.000000
25.520000,0.712349,-14.500790,0.016690,-0.000011,-0.000269,3.168686,0.161421,-0.002691,-14.500790,0.000078,0.000000
25.730001,0.707504,-14.589752,0.016681,-0.000010,-0.000260,3.147136,0.160323,-0.002604,-14.589752,0.000433,0.000000
25.940001,0.713463,-14.589752,0.016686,-0.000005,-0.000121,3.173641,0.161673,-0.001215,-14.589752,0.000780,0.000000
26.150002,0.779373,-14.589752,0.016677,0.000010,0.000260,3.466825,0.176608,0.002600,-14.589752,0.001127,0.000000
26.360001,0.911194,-14.589752,0.016694,0.000027,0.000676,4.053193,0.206479,0.006764,-14.589752,0.001483,0.000000
26.570002,0.968536,-14.545271,0.016707,0.000035,0.000885,4.308265,0.219473,0.008845,-14.545271,0.001830,0.000000
26.780001,1.106316,-14.634233,0.016716,0.000051,0.001300,4.921138,0.250695,0.013005,-14.634233,0.002185,0.000000
26.990002,1.193451,-14.634233,0.016724,0.000063,0.001613,5.308735,0.270440,0.016127,-14.634233,0.002532,0.000000
27.200001,1.306282,-14.589752,0.016750,0.000074,0.001873,5.810633,0.296008,0.018731,-14.589752,0.002879,0.000000
27.410002,1.488373,-14.589752,0.016750,0.000092,0.002333,6.620613,0.337270,0.023326,-14.589752,0.003235,0.000000
27.620001,1.599335,-14.634233,0.016785,0.000102,0.002601,7.114196,0.362414,0.026014,-14.634233,0.003582,0.000000
27.830002,1.755363,-14.634233,0.016785,0.000116,0.002948,7.808247,0.397771,0.029484,-14.634233,0.003928,0.000000
28.040001,1.974319,-14.634233,0.016798,0.000133,0.003373,8.782211,0.447387,0.033735,-14.634233,0.004284,0.000000
28.250002,2.190666,-14.678714,0.016815,0.000151,0.003842,9.744570,0.496412,0.038417,-14.678714,0.004631,0.000000
28.460001,2.309448,-14.634233,0.016849,0.000159,0.004050,10.272939,0.523328,0.040498,-14.634233,0.004978,0.000000
28.670002,2.463242,-14.678714,0.016849,0.000175,0.004457,10.957046,0.558178,0.044575,-14.678714,0.005333,0.000000
28.880001,2.691505,-14.678714,0.016875,0.000187,0.004752,11.972414,0.609904,0.047523,-14.678714,0.005680,0.000000
29.090002,2.833382,-14.634233,0.016862,0.000201,0.005108,12.603511,0.642053,0.051077,-14.634233,0.006036,0.000000
29.300001,3.180428,-14.634233,0.016884,0.000217,0.005515,14.147248,0.720695,0.055153,-14.634233,0.006382,0.000000
29.510002,3.319695,-14.678714,0.016884,0.000226,0.005750,14.766739,0.752254,0.057496,-14.678714,0.006730,0.000000
29.720001,3.426567,-14.678714,0.016893,0.000234,0.005949,15.242131,0.776471,0.059491,-14.678714,0.007085,0.000000
29.930002,3.943794,-14.678714,0.016923,0.000259,0.006582,17.542873,0.893677,0.065819,-14.678714,0.007432,0.000000
30.140001,4.157539,-14.723195,0.016936,0.000272,0.006920,18.493658,0.942112,0.069203,-14.723195,0.007779,0.000000
30.350002,4.442398,-14.723195,0.016927,0.000287,0.007293,19.760773,1.006662,0.072931,-14.723195,0.008134,0.000000
30.560001,4.641617,-14.634233,0.016970,0.000297,0.007545,20.646942,1.051805,0.075448,-14.634233,0.008481,0.000000
30.770002,4.884407,-14.634233,0.016966,0.000310,0.007883,21.726927,1.106822,0.078828,-14.634233,0.008828,0.000000
30.980001,5.264969,-14.767675,0.016983,0.000325,0.008256,23.419752,1.193059,0.082560,-14.767675,0.009184,0.000000
31.190001,5.513344,-14.678714,0.016996,0.000340,0.008646,24.524578,1.249342,0.086462,-14.678714,0.009531,0.000000
31.400002,5.743469,-14.723195,0.016983,0.000351,0.008906,25.548227,1.301489,0.089062,-14.723195,0.009886,0.000000
31.610001,6.027962,-14.723195,0.017000,0.000363,0.009210,26.813713,1.365956,0.092098,-14.723195,0.010233,0.000000
31.820002,6.414116,-14.723195,0.017009,0.000376,0.009548,28.531412,1.453459,0.095482,-14.723195,0.010580,0.000000
32.030003,6.942879,-14.723195,0.017018,0.000398,0.010120,30.883467,1.573279,0.101204,-14.723195,0.010936,0.000000
32.240002,7.214340,-14.678714,0.017043,0.000411,0.010433,32.090988,1.634793,0.104327,-14.678714,0.011282,0.000000
32.450001,7.352493,-14.767675,0.017039,0.000419,0.010649,32.705524,1.666099,0.106492,-14.767675,0.011629,0.000000
32.660000,7.736778,-14.634233,0.017069,0.000434,0.011014,34.414909,1.753179,0.110137,-14.634233,0.011985,0.000000
32.870003,8.095375,-14.767675,0.017078,0.000447,0.011360,36.010025,1.834438,0.113604,-14.767675,0.012332,0.000000
33.080002,8.376144,-14.767675,0.017087,0.000458,0.011621,37.258949,1.898061,0.116208,-14.767675,0.012679,0.000000
33.290001,8.682610,-14.723195,0.017104,0.000471,0.011959,38.622177,1.967507,0.119588,-14.723195,0.013034,0.000000
33.500000,9.013275,-14.856638,0.017091,0.000482,0.012254,40.093052,2.042437,0.122536,-14.856638,0.013381,0.000000
33.710003,9.529007,-14.723195,0.017125,0.000500,0.012696,42.387138,2.159304,0.126961,-14.723195,0.013728,0.000000
33.920002,9.968781,-14.856638,0.017143,0.000517,0.013121,44.343349,2.258958,0.131211,-14.856638,0.014084,0.000000
34.130001,10.421959,-14.767675,0.017121,0.000533,0.013537,46.359188,2.361650,0.135371,-14.767675,0.014430,0.000000
34.340000,10.682617,-14.723195,0.017173,0.000544,0.013824,47.518654,2.420716,0.138236,-14.723195,0.014786,0.000000
34.550003,10.971581,-14.812157,0.017168,0.000559,0.014196,48.804028,2.486196,0.141964,-14.812157,0.015133,0.000000
34.760002,11.325333,-14.767675,0.017177,0.000571,0.014491,50.377594,2.566357,0.144912,-14.767675,0.015480,0.000000
34.970001,11.810905,-14.812157,0.017190,0.000587,0.014899,52.537533,2.676389,0.148989,-14.812157,0.015835,0.000000
35.180000,12.083855,-14.812157,0.017186,0.000599,0.015220,53.751671,2.738241,0.152198,-14.812157,0.016182,0.000000
35.390003,12.336327,-14.812157,0.017186,0.000608,0.015454,54.874722,2.795452,0.154537,-14.812157,0.016529,0.000000
35.600002,12.853546,-14.812157,0.017237,0.000625,0.015887,57.175430,2.912655,0.158875,-14.812157,0.016885,0.000000
35.810001,13.199112,-14.767675,0.017229,0.000640,0.016260,58.712582,2.990962,0.162603,-14.767675,0.017231,0.000000
36.020000,13.643723,-14.856638,0.017250,0.000653,0.016599,60.690308,3.091712,0.165987,-14.856638,0.017579,0.000000
36.230003,13.943855,-14.856638,0.017272,0.000666,0.016928,62.025368,3.159723,0.169279,-14.856638,0.017934,0.000000
36.440002,14.269684,-14.812157,0.017285,0.000680,0.017284,63.474724,3.233557,0.172837,-14.812157,0.018281,0.000000
36.650002,14.664024,-14.856638,0.017293,0.000694,0.017639,65.228836,3.322915,0.176391,-14.856638,0.018636,0.000000
36.860001,15.006981,-14.812157,0.017285,0.000707,0.017960,66.754387,3.400630,0.179601,-14.812157,0.018984,0.000000
37.070004,15.483246,-14.901118,0.017293,0.000723,0.018368,68.872917,3.508554,0.183677,-14.901118,0.019330,0.000000
37.280003,15.670547,-14.856638,0.017324,0.000734,0.018636,69.706078,3.550997,0.186364,-14.856638,0.019686,0.000000
37.490002,15.975517,-14.856638,0.017319,0.000746,0.018949,71.062653,3.620104,0.189487,-14.856638,0.020033,0.000000
37.700001,16.387733,-14.901118,0.017332,0.000761,0.019322,72.896278,3.713513,0.193215,-14.901118,0.020380,0.000000
37.910004,16.843521,-14.812157,0.017362,0.000780,0.019807,74.923721,3.816796,0.198071,-14.812157,0.020735,0.000000
38.120003,17.420326,-14.856638,0.017358,0.000797,0.020232,77.489479,3.947502,0.202322,-14.856638,0.021082,0.000000
38.330002,17.599808,-14.856638,0.017388,0.000807,0.020492,78.287857,3.988173,0.204922,-14.856638,0.021429,0.000000
38.540001,17.794189,-14.901118,0.017375,0.000820,0.020822,79.152512,4.032221,0.208218,-14.901118,0.021784,0.000000
38.750000,18.062294,-14.901118,0.017397,0.000832,0.021143,80.345093,4.092974,0.211428,-14.901118,0.022131,0.000000
38.960003,18.512863,-14.901118,0.017431,0.000846,0.021481,82.349327,4.195075,0.214812,-14.901118,0.022487,0.000000
39.170002,18.900879,-14.990081,0.017440,0.000860,0.021837,84.075310,4.283000,0.218366,-14.990081,0.022834,0.000000
39.380001,19.000305,-14.945600,0.017440,0.000868,0.022053,84.517578,4.305531,0.220534,-14.945600,0.023181,0.000000
39.590000,19.241974,-14.856638,0.017453,0.000882,0.022400,85.592575,4.360293,0.224001,-14.856638,0.023536,0.000000
39.800003,19.789360,-14.945600,0.017440,0.000895,0.022721,88.027473,4.484333,0.227211,-14.945600,0.023883,0.000000
40.010002,20.277168,-14.856638,0.017488,0.000910,0.023120,90.197350,4.594872,0.231200,-14.856638,0.024230,0.000000
40.220001,20.684174,-14.990081,0.017496,0.000927,0.023554,92.007797,4.687101,0.235538,-14.990081,0.024586,0.000000
40.430000,20.880783,-14.856638,0.017496,0.000942,0.023918,92.882362,4.731653,0.239179,-14.856638,0.024933,0.000000
40.640003,21.167511,-14.945600,0.017509,0.000954,0.024221,94.157791,4.796627,0.242214,-14.945600,0.025279,0.000000
40.850002,21.283691,-14.901118,0.017518,0.000963,0.024456,94.674591,4.822953,0.244557,-14.901118,0.025635,0.000000
41.060001,21.870552,-14.945600,0.017539,0.000981,0.024907,97.285072,4.955938,0.249065,-14.945600,0.025982,0.000000
41.270000,21.970718,-14.990081,0.017544,0.000993,0.025227,97.730637,4.978636,0.252275,-14.990081,0.026338,0.000000
41.480003,22.191162,-14.945600,0.017557,0.001003,0.025487,98.711220,5.028589,0.254875,-14.945600,0.026684,0.000000
41.690002,22.574707,-14.945600,0.017578,0.001016,0.025800,100.417313,5.115501,0.257997,-14.945600,0.027031,0.000000
41.900002,23.602455,-14.901118,0.017569,0.001042,0.026476,104.988960,5.348393,0.264761,-14.901118,0.027387,0.000000
42.110001,23.815079,-14.990081,0.017600,0.001056,0.026823,105.934761,5.396574,0.268232,-14.990081,0.027734,0.000000
42.320004,23.761826,-14.901118,0.017608,0.001067,0.027101,105.697876,5.384507,0.271006,-14.901118,0.028081,0.000000
42.530003,24.091751,-14.945600,0.017613,0.001081,0.027448,107.165459,5.459269,0.274477,-14.945600,0.028436,0.000000
42.740002,24.297302,-15.034561,0.017643,0.001090,0.027690,108.079796,5.505847,0.276903,-15.034561,0.028783,0.000000
42.950001,24.750481,-15.034561,0.017651,0.001107,0.028107,110.095634,5.608539,0.281066,-15.034561,0.029130,0.000000
43.160004,25.021194,-14.990081,0.017669,0.001118,0.028401,111.299835,5.669883,0.284015,-14.990081,0.029485,0.000000
43.370003,25.410690,-15.034561,0.017677,0.001130,0.028714,113.032394,5.758145,0.287137,-15.034561,0.029833,0.000000
43.580002,25.745827,-14.990081,0.017677,0.001146,0.029104,114.523155,5.834087,0.291039,-14.990081,0.030179,0.000000
43.790001,26.763527,-14.990081,0.017703,0.001170,0.029728,119.050110,6.064702,0.297285,-14.990081,0.030535,0.000000
44.000004,26.858849,-14.990081,0.017699,0.001182,0.030015,119.474129,6.086302,0.300146,-14.990081,0.030882,0.000000
44.210003,27.019714,-15.034561,0.017720,0.001194,0.030327,120.189690,6.122755,0.303268,-15.034561,0.031237,0.000000
44.420002,27.139992,-15.123524,0.017716,0.001206,0.030630,120.724716,6.150010,0.306304,-15.123524,0.031584,0.000000
44.630001,27.286705,-14.990081,0.017742,0.001216,0.030890,121.377327,6.183256,0.308904,-14.990081,0.031931,0.000000
44.840004,28.247429,-15.034561,0.017751,0.001237,0.031411,125.650841,6.400959,0.314108,-15.034561,0.032287,0.000000
45.050003,28.306259,-15.034561,0.017759,0.001246,0.031653,125.912529,6.414290,0.316535,-15.034561,0.032633,0.000000
45.260002,28.676773,-15.079042,0.017776,0.001260,0.032001,127.560654,6.498250,0.320005,-15.079042,0.032980,0.000000
45.470001,28.883812,-15.123524,0.017772,0.001270,0.032261,128.481613,6.545166,0.322606,-15.123524,0.033336,0.000000
45.680000,30.029228,-15.034561,0.017807,0.001294,0.032868,133.576675,6.804720,0.328676,-15.034561,0.033683,0.000000
45.890003,30.338303,-15.034561,0.017807,0.001308,0.033232,134.951508,6.874758,0.332318,-15.034561,0.034030,0.000000
46.100002,30.572891,-14.990081,0.017832,0.001321,0.033553,135.995010,6.927917,0.335527,-14.990081,0.034385,0.000000
46.310001,30.903931,-15.034561,0.017815,0.001333,0.033856,137.467545,7.002931,0.338563,-15.034561,0.034732,0.000000
46.520000,31.024208,-15.079042,0.017837,0.001342,0.034091,138.002563,7.030186,0.340905,-15.079042,0.035088,0.000000
46.730003,31.695595,-15.079042,0.017863,0.001359,0.034507,140.989044,7.182324,0.345069,-15.079042,0.035435,0.000000
46.940002,32.098503,-15.168004,0.017850,0.001371,0.034819,142.781265,7.273624,0.348188,-15.168004,0.035782,0.000000
47.150002,32.228088,-15.123524,0.017884,0.001379,0.035027,143.357697,7.302989,0.350269,-15.123524,0.036137,0.000000
47.360001,32.887558,-15.123524,0.017888,0.001395,0.035426,146.291168,7.452427,0.354259,-15.123524,0.036484,0.000000
47.570004,33.805832,-15.168004,0.017901,0.001418,0.036016,150.375854,7.660511,0.360155,-15.168004,0.036831,0.000000
47.780003,34.204643,-15.123524,0.017936,0.001428,0.036276,152.149857,7.750883,0.362759,-15.123524,0.037187,0.000000
47.990002,34.299599,-15.168004,0.017919,0.001440,0.036571,152.572235,7.772400,0.365708,-15.168004,0.037533,0.000000
48.200001,34.951622,-15.079042,0.017914,0.001454,0.036935,155.472580,7.920151,0.369349,-15.079042,0.037880,0.000000
48.410004,35.202225,-15.123524,0.017949,0.001466,0.037230,156.587311,7.976938,0.372297,-15.123524,0.038236,0.000000
48.620003,35.849037,-15.123524,0.017945,0.001482,0.037646,159.464478,8.123508,0.376461,-15.123524,0.038583,0.000000
48.830002,36.431801,-15.168004,0.017970,0.001495,0.037976,162.056747,8.255565,0.379757,-15.168004,0.038938,0.000000
49.040001,36.771408,-15.168004,0.017988,0.001505,0.038236,163.567398,8.332520,0.382358,-15.168004,0.039285,0.000000
49.250004,37.253998,-15.123524,0.017988,0.001518,0.038565,165.714066,8.441877,0.385654,-15.123524,0.039632,0.000000
49.460003,38.049019,-15.168004,0.018014,0.001534,0.038956,169.250488,8.622030,0.389557,-15.168004,0.039987,0.000000
49.670002,38.868980,-15.168004,0.017996,0.001552,0.039433,172.897858,8.807837,0.394325,-15.168004,0.040334,0.000000
49.880001,39.048836,-15.123524,0.018005,0.001563,0.039701,173.697891,8.848593,0.397013,-15.123524,0.040682,0.000000
50.090004,39.686707,-15.256967,0.018005,0.001578,0.040074,176.535294,8.993136,0.400745,-15.256967,0.041037,0.000000
50.300003,40.095573,-15.212485,0.018031,0.001590,0.040378,178.354019,9.085787,0.403780,-15.212485,0.041384,0.000000
50.510002,40.698448,-15.168004,0.018044,0.001606,0.040803,181.035736,9.222400,0.408027,-15.168004,0.041731,0.000000
50.720001,41.362015,-15.212485,0.018057,0.001616,0.041046,183.987427,9.372766,0.410457,-15.212485,0.042086,0.000000
50.930004,41.774605,-15.123524,0.018057,0.001629,0.041367,185.822723,9.466260,0.413666,-15.123524,0.042433,0.000000
51.140003,42.329063,-15.212485,0.018070,0.001643,0.041739,188.289078,9.591903,0.417394,-15.212485,0.042780,0.000000
51.350002,43.590660,-15.168004,0.018070,0.001663,0.042234,193.900940,9.877785,0.422338,-15.168004,0.043136,0.000000
51.560001,44.368919,-15.256967,0.018091,0.001679,0.042650,197.362808,10.054141,0.426501,-15.256967,0.043482,0.000000
51.770004,44.790077,-15.212485,0.018100,0.001689,0.042893,199.236221,10.149576,0.428927,-15.212485,0.043838,0.000000
51.980003,45.232079,-15.168004,0.018095,0.001702,0.043231,201.202332,10.249736,0.432311,-15.168004,0.044185,0.000000
52.190002,45.737015,-15.212485,0.018095,0.001714,0.043535,203.448410,10.364156,0.435346,-15.212485,0.044532,0.000000
52.400002,46.620659,-15.212485,0.018134,0.001731,0.043968,207.379044,10.564392,0.439680,-15.212485,0.044887,0.000000
52.610001,47.089844,-15.212485,0.018134,0.001740,0.044185,209.466080,10.670711,0.441849,-15.212485,0.045234,0.000000
52.820004,47.731819,-15.345928,0.018147,0.001754,0.044541,212.321732,10.816185,0.445406,-15.345928,0.045581,0.000000
53.030003,48.307129,-15.212485,0.018143,0.001768,0.044905,214.880844,10.946552,0.449048,-15.212485,0.045937,0.000000
53.240002,49.125610,-15.256967,0.018160,0.001782,0.045269,218.521622,11.132022,0.452689,-15.256967,0.046284,0.000000
53.450001,50.393906,-15.212485,0.018156,0.001802,0.045781,224.163284,11.419422,0.457806,-15.212485,0.046631,0.000000
53.660004,50.853043,-15.301447,0.018169,0.001812,0.046032,226.205627,11.523464,0.460323,-15.301447,0.046986,0.000000
53.870003,51.207542,-15.256967,0.018182,0.001823,0.046301,227.782532,11.603795,0.463010,-15.256967,0.047333,0.000000
54.080002,51.829407,-15.212485,0.018186,0.001835,0.046613,230.548721,11.744711,0.466133,-15.212485,0.047689,0.000000
54.290001,52.541008,-15.345928,0.018199,0.001848,0.046943,233.714081,11.905962,0.469429,-15.345928,0.048036,0.000000
54.500004,53.498749,-15.301447,0.018216,0.001865,0.047376,237.974319,12.122990,0.473763,-15.301447,0.048382,0.000000
54.710003,54.054703,-15.345928,0.018203,0.001875,0.047619,240.447327,12.248971,0.476193,-15.345928,0.048738,0.000000
54.920002,54.843384,-15.301447,0.018216,0.001891,0.048027,243.955551,12.427689,0.480269,-15.301447,0.049085,0.000000
55.130001,55.438812,-15.301447,0.018216,0.001899,0.048243,246.604156,12.562614,0.482434,-15.301447,0.049432,0.000000
55.340004,56.449059,-15.345928,0.018251,0.001915,0.048651,251.097946,12.791539,0.486510,-15.345928,0.049787,0.000000
55.550003,57.632080,-15.256967,0.018233,0.001935,0.049145,256.360291,13.059616,0.491453,-15.256967,0.050134,0.000000
55.760002,58.194740,-15.301447,0.018264,0.001948,0.049475,258.863129,13.187117,0.494750,-15.301447,0.050481,0.000000
55.970001,59.187111,-15.301447,0.018255,0.001963,0.049865,263.277405,13.411991,0.498652,-15.301447,0.050836,0.000000
56.180004,59.429153,-15.301447,0.018281,0.001970,0.050030,264.354065,13.466839,0.500303,-15.301447,0.051184,0.000000
56.390003,60.024948,-15.345928,0.018264,0.001980,0.050299,267.004303,13.601848,0.502990,-15.345928,0.051539,0.000000
56.600002,61.295113,-15.301447,0.018268,0.002000,0.050802,272.654266,13.889670,0.508020,-15.301447,0.051886,0.000000
56.810001,61.713661,-15.345928,0.018281,0.002010,0.051045,274.516083,13.984515,0.510446,-15.345928,0.052233,0.000000
57.020004,62.800613,-15.301447,0.018289,0.002025,0.051444,279.351074,14.230823,0.514435,-15.301447,0.052588,0.000000
57.230003,63.773621,-15.345928,0.018311,0.002040,0.051825,283.679230,14.451309,0.518251,-15.345928,0.052935,0.000000
57.440002,64.784241,-15.345928,0.018311,0.002057,0.052250,288.174683,14.680319,0.522501,-15.345928,0.053282,0.000000
57.650002,65.790390,-15.345928,0.018311,0.002071,0.052615,292.650269,14.908316,0.526146,-15.345928,0.053638,0.000000
57.860004,66.791336,-15.390409,0.018324,0.002087,0.053022,297.102692,15.135134,0.530218,-15.390409,0.053985,0.000000
58.070004,67.534592,-15.345928,0.018320,0.002090,0.053091,300.408875,15.303557,0.530915,-15.345928,0.054271,0.000000
58.280003,66.977509,-15.390409,0.018337,0.002090,0.053091,297.930847,15.177320,0.530915,-15.390409,0.053325,0.000000
58.490002,66.706802,-15.434890,0.018337,0.002090,0.053074,296.726685,15.115977,0.530741,-15.434890,0.053091,0.000000
58.700005,66.397736,-15.345928,0.018337,0.002088,0.053031,295.351868,15.045941,0.530305,-15.345928,0.053091,0.000000
58.910004,66.131851,-15.390409,0.018333,0.002087,0.053014,294.169159,14.985692,0.530135,-15.390409,0.053091,0.000000
59.120003,65.909927,-15.390409,0.018337,0.002087,0.053005,293.182007,14.935403,0.530048,-15.390409,0.053091,0.000000
59.330002,65.712936,-15.345928,0.018337,0.002086,0.052996,292.305725,14.890764,0.529961,-15.345928,0.053091,0.000000
59.540005,65.515579,-15.434890,0.018337,0.002086,0.052996,291.427856,14.846043,0.529961,-15.434890,0.053091,0.000000
59.750004,65.359558,-15.345928,0.018341,0.002086,0.052987,290.733826,14.810687,0.529874,-15.345928,0.053091,0.000000
59.960003,65.208008,-15.345928,0.018346,0.002086,0.052987,290.059692,14.776345,0.529874,-15.345928,0.053091,0.000000
60.170002,65.076187,-15.390409,0.018354,0.002086,0.052987,289.473328,14.746475,0.529874,-15.390409,0.053091,0.000000
60.380001,64.951431,-15.390409,0.018358,0.002086,0.052987,288.918396,14.718204,0.529874,-15.390409,0.053091,0.000000
60.590004,64.849030,-15.479371,0.018354,0.002086,0.052979,288.462891,14.695001,0.529787,-15.479371,0.053091,0.000000
60.800003,64.713120,-15.434890,0.018346,0.002086,0.052979,287.858337,14.664203,0.529787,-15.434890,0.053091,0.000000
61.010002,64.637894,-15.434890,0.018358,0.002086,0.052979,287.523712,14.647156,0.529787,-15.434890,0.053091,0.000000
61.220001,64.540710,-15.434890,0.018354,0.002086,0.052979,287.091431,14.625134,0.529787,-15.434890,0.053091,0.000000
61.430004,64.449478,-15.434890,0.018341,0.002086,0.052979,286.685608,14.604461,0.529787,-15.434890,0.053091,0.000000
61.640003,64.368668,-15.479371,0.018350,0.002086,0.052979,286.326141,14.586148,0.529787,-15.479371,0.053091,0.000000
61.850002,64.300903,-15.390409,0.018346,0.002086,0.052979,286.024689,14.570793,0.529787,-15.390409,0.053091,0.000000
62.060001,64.216003,-15.523852,0.018346,0.002086,0.052979,285.647064,14.551554,0.529787,-15.523852,0.053091,0.000000
62.270004,64.146362,-15.479371,0.018341,0.002086,0.052979,285.337280,14.535773,0.529787,-15.479371,0.053091,0.000000
62.480003,64.091995,-15.479371,0.018371,0.002085,0.052970,285.095428,14.523454,0.529700,-15.479371,0.053091,0.000000
62.690002,64.005615,-15.523852,0.018354,0.002085,0.052970,284.711182,14.503880,0.529700,-15.523852,0.053091,0.000000
62.900002,63.963165,-15.479371,0.018363,0.002085,0.052970,284.522369,14.494260,0.529700,-15.479371,0.053091,0.000000
63.110004,63.902084,-15.479371,0.018350,0.002085,0.052970,284.250671,14.480419,0.529700,-15.479371,0.053091,0.000000
63.320004,63.839157,-15.434890,0.018350,0.002085,0.052970,283.970764,14.466160,0.529700,-15.434890,0.053091,0.000000
63.530003,63.789261,-15.523852,0.018350,0.002085,0.052970,283.748810,14.454854,0.529700,-15.523852,0.053091,0.000000
63.740002,63.747177,-15.523852,0.018358,0.002085,0.052970,283.561615,14.445317,0.529700,-15.523852,0.053091,0.000000
63.950005,63.681274,-15.523852,0.018371,0.002085,0.052970,283.268463,14.430383,0.529700,-15.523852,0.053091,0.000000
64.160004,63.642548,-15.568333,0.018358,0.002085,0.052970,283.096191,14.421608,0.529700,-15.568333,0.053091,0.000000
64.370003,63.591904,-15.523852,0.018363,0.002085,0.052970,282.870911,14.410131,0.529700,-15.523852,0.053091,0.000000
64.580002,63.545364,-15.523852,0.018376,0.002085,0.052970,282.663910,14.399585,0.529700,-15.523852,0.053091,0.000000
64.790001,63.507370,-15.479371,0.018354,0.002085,0.052970,282.494904,14.390976,0.529700,-15.479371,0.053091,0.000000
65.000000,63.457855,-15.523852,0.018367,0.002085,0.052970,282.274628,14.379756,0.529700,-15.523852,0.053091,0.000000
65.210007,63.422852,-15.568333,0.018363,0.002085,0.052970,282.118927,14.371823,0.529700,-15.568333,0.053091,0.000000
65.420006,63.385986,-15.568333,0.018346,0.002085,0.052970,281.954956,14.363470,0.529700,-15.568333,0.053091,0.000000
65.630005,63.353592,-15.523852,0.018389,0.002085,0.052970,281.810852,14.356130,0.529700,-15.523852,0.053091,0.000000
65.840004,63.293640,-15.568333,0.018358,0.002085,0.052970,281.544159,14.342544,0.529700,-15.568333,0.053091,0.000000
66.050003,63.285065,-15.568333,0.018358,0.002085,0.052970,281.506012,14.340601,0.529700,-15.568333,0.053091,0.000000
66.260002,63.235550,-15.568333,0.018358,0.002085,0.052970,281.285767,14.329381,0.529700,-15.568333,0.053091,0.000000
66.470001,63.199799,-15.523852,0.018354,0.002085,0.052970,281.126740,14.321280,0.529700,-15.523852,0.053091,0.000000
66.680000,63.175598,-15.568333,0.018363,0.002085,0.052970,281.019104,14.315795,0.529700,-15.568333,0.053091,0.000000
66.889999,63.139099,-15.568333,0.018358,0.002085,0.052970,280.856750,14.307525,0.529700,-15.568333,0.053091,0.000000
67.100006,63.102982,-15.612814,0.018346,0.002085,0.052970,280.696075,14.299340,0.529700,-15.612814,0.053091,0.000000
67.310005,63.079895,-15.612814,0.018376,0.002085,0.052970,280.593384,14.294108,0.529700,-15.612814,0.053091,0.000000
67.520004,63.039673,-15.568333,0.018363,0.002085,0.052970,280.414459,14.284994,0.529700,-15.568333,0.053091,0.000000
67.730003,63.014725,-15.568333,0.018380,0.002085,0.052970,280.303497,14.279341,0.529700,-15.568333,0.053091,0.000000
67.940002,62.995743,-15.612814,0.018350,0.002085,0.052970,280.219055,14.275039,0.529700,-15.612814,0.053091,0.000000
68.150002,62.950302,-15.523852,0.018389,0.002085,0.052970,280.016937,14.264743,0.529700,-15.523852,0.053091,0.000000
68.360001,62.920517,-15.657295,0.018371,0.002085,0.052970,279.884430,14.257993,0.529700,-15.657295,0.053091,0.000000
68.570000,62.900040,-15.568333,0.018358,0.002085,0.052970,279.793365,14.253353,0.529700,-15.568333,0.053091,0.000000
68.780006,62.871735,-15.568333,0.018376,0.002085,0.052970,279.667450,14.246939,0.529700,-15.568333,0.053091,0.000000
68.990005,62.841202,-15.612814,0.018380,0.002085,0.052970,279.531616,14.240020,0.529700,-15.612814,0.053091,0.000000
69.200005,62.818863,-15.612814,0.018384,0.002085,0.052970,279.432251,14.234958,0.529700,-15.612814,0.053091,0.000000
69.410004,62.782364,-15.657295,0.018376,0.002085,0.052970,279.269897,14.226686,0.529700,-15.657295,0.053091,0.000000
69.620003,62.774918,-15.657295,0.018384,0.002085,0.052970,279.236786,14.225000,0.529700,-15.657295,0.053091,0.000000
69.830002,62.751083,-15.657295,0.018380,0.002085,0.052970,279.130768,14.219599,0.529700,-15.657295,0.053091,0.000000
70.040001,62.719437,-15.701776,0.018358,0.002085,0.052970,278.989990,14.212427,0.529700,-15.701776,0.053091,0.000000
70.250000,62.704544,-15.612814,0.018393,0.002085,0.052970,278.923737,14.209053,0.529700,-15.612814,0.053091,0.000000
70.460007,62.669167,-15.701776,0.018358,0.002085,0.052970,278.766388,14.201036,0.529700,-15.701776,0.053091,0.000000
70.670006,62.651291,-15.657295,0.018384,0.002085,0.052970,278.686859,14.196986,0.529700,-15.657295,0.053091,0.000000
70.880005,62.639374,-15.657295,0.018371,0.002085,0.052970,278.633850,14.194285,0.529700,-15.657295,0.053091,0.000000
71.090004,62.603256,-15.657295,0.018358,0.002085,0.052970,278.473206,14.186101,0.529700,-15.657295,0.053091,0.000000
71.300003,62.587990,-15.612814,0.018389,0.002085,0.052970,278.405273,14.182641,0.529700,-15.612814,0.053091,0.000000
71.510002,62.561920,-15.701776,0.018363,0.002085,0.052970,278.289307,14.176734,0.529700,-15.701776,0.053091,0.000000
71.720001,62.530273,-15.612814,0.018376,0.002085,0.052970,278.148560,14.169562,0.529700,-15.612814,0.053091,0.000000
71.930000,62.531387,-15.701776,0.018371,0.002085,0.052970,278.153503,14.169815,0.529700,-15.701776,0.053091,0.000000
72.140007,62.492661,-15.701776,0.018380,0.002085,0.052970,277.981232,14.161039,0.529700,-15.701776,0.053091,0.000000
72.350006,62.478508,-15.701776,0.018358,0.002085,0.052970,277.918274,14.157832,0.529700,-15.701776,0.053091,0.000000
72.560005,62.469948,-15.746257,0.018363,0.002085,0.052970,277.880219,14.155892,0.529700,-15.746257,0.053091,0.000000
72.770004,62.437180,-15.746257,0.018384,0.002085,0.052970,277.734436,14.148467,0.529700,-15.746257,0.053091,0.000000
72.980003,62.422653,-15.746257,0.018371,0.002085,0.052970,277.669830,14.145175,0.529700,-15.746257,0.053091,0.000000
73.190002,62.413345,-15.746257,0.018371,0.002085,0.052970,277.628418,14.143066,0.529700,-15.746257,0.053091,0.000000
73.400002,62.389511,-15.746257,0.018380,0.002085,0.052961,277.522400,14.137666,0.529613,-15.746257,0.053091,0.000000
73.610001,62.370895,-15.746257,0.018389,0.002085,0.052961,277.439606,14.133447,0.529613,-15.746257,0.053091,0.000000
73.820000,62.344826,-15.790737,0.018389,0.002085,0.052961,277.323639,14.127540,0.529613,-15.790737,0.053091,0.000000
74.030006,62.325096,-15.790737,0.018371,0.002085,0.052961,277.235870,14.123069,0.529613,-15.790737,0.053091,0.000000
74.240005,62.315041,-15.746257,0.018376,0.002085,0.052961,277.191132,14.120790,0.529613,-15.746257,0.053091,0.000000
74.450005,62.287483,-15.746257,0.018367,0.002085,0.052961,277.068573,14.114546,0.529613,-15.746257,0.053091,0.000000
74.660004,62.284508,-15.790737,0.018354,0.002085,0.052961,277.055328,14.113871,0.529613,-15.790737,0.053091,0.000000
74.870003,62.266258,-15.701776,0.018350,0.002085,0.052961,276.974152,14.109735,0.529613,-15.701776,0.053091,0.000000
75.080002,62.244286,-15.790737,0.018376,0.002085,0.052961,276.876404,14.104756,0.529613,-15.790737,0.053091,0.000000
75.290001,62.233490,-15.746257,0.018371,0.002085,0.052961,276.828400,14.102311,0.529613,-15.746257,0.053091,0.000000
75.500000,62.208916,-15.746257,0.018376,0.002085,0.052961,276.719086,14.096742,0.529613,-15.746257,0.053091,0.000000
75.710007,62.200722,-15.790737,0.018402,0.002085,0.052961,276.682617,14.094886,0.529613,-15.790737,0.053091,0.000000
75.920006,62.187317,-15.746257,0.018350,0.002085,0.052961,276.623016,14.091847,0.529613,-15.746257,0.053091,0.000000
76.130005,62.154922,-15.835218,0.018371,0.002085,0.052961,276.478912,14.084507,0.529613,-15.835218,0.053091,0.000000
76.340004,62.151192,-15.790737,0.018384,0.002085,0.052961,276.462311,14.083661,0.529613,-15.790737,0.053091,0.000000
76.550003,62.134438,-15.790737,0.018376,0.002085,0.052961,276.387787,14.079865,0.529613,-15.790737,0.053091,0.000000
76.760002,62.118057,-15.790737,0.018380,0.002085,0.052961,276.314911,14.076153,0.529613,-15.790737,0.053091,0.000000
76.970001,62.101295,-15.790737,0.018371,0.002085,0.052961,276.240356,14.072354,0.529613,-15.790737,0.053091,0.000000
77.180000,62.067039,-15.924180,0.018384,0.002085,0.052961,276.087982,14.064592,0.529613,-15.924180,0.053091,0.000000
77.390007,62.078583,-15.790737,0.018367,0.002085,0.052961,276.139313,14.067208,0.529613,-15.790737,0.053091,0.000000
77.600006,62.057358,-15.835218,0.018376,0.002085,0.052961,276.044922,14.062398,0.529613,-15.835218,0.053091,0.000000
77.810005,62.052887,-15.790737,0.018367,0.002085,0.052961,276.025024,14.061385,0.529613,-15.790737,0.053091,0.000000
78.020004,62.035759,-15.879700,0.018397,0.002085,0.052961,275.948853,14.057505,0.529613,-15.879700,0.053091,0.000000
78.230003,62.001877,-15.879700,0.018397,0.002085,0.052961,275.798126,14.049827,0.529613,-15.879700,0.053091,0.000000
78.440002,62.001129,-15.879700,0.018376,0.002085,0.052961,275.794800,14.049657,0.529613,-15.879700,0.053091,0.000000
78.650002,61.983253,-15.879700,0.018389,0.002085,0.052961,275.715271,14.045606,0.529613,-15.879700,0.053091,0.000000
78.860001,61.972084,-15.879700,0.018393,0.002085,0.052961,275.665588,14.043075,0.529613,-15.879700,0.053091,0.000000
79.070007,61.956818,-15.835218,0.018358,0.002085,0.052961,275.597687,14.039615,0.529613,-15.835218,0.053091,0.000000
79.280006,61.938568,-15.879700,0.018376,0.002085,0.052961,275.516510,14.035480,0.529613,-15.879700,0.053091,0.000000
79.490005,61.943039,-15.835218,0.018376,0.002085,0.052961,275.536407,14.036493,0.529613,-15.835218,0.053091,0.000000
79.700005,61.923302,-15.924180,0.018389,0.002085,0.052961,275.448608,14.032022,0.529613,-15.924180,0.053091,0.000000
79.910004,61.915482,-15.879700,0.018358,0.002085,0.052961,275.413818,14.030249,0.529613,-15.879700,0.053091,0.000000
80.120003,61.918839,-15.835218,0.018363,0.002085,0.052961,275.428741,14.031010,0.529613,-15.835218,0.053091,0.000000
80.330002,61.886063,-15.924180,0.018380,0.002085,0.052961,275.282959,14.023582,0.529613,-15.924180,0.053091,0.000000
80.540001,61.884201,-15.879700,0.018389,0.002085,0.052961,275.274689,14.023161,0.529613,-15.879700,0.053091,0.000000
80.750008,61.858513,-15.879700,0.018397,0.002085,0.052961,275.160400,14.017340,0.529613,-15.879700,0.053091,0.000000
80.960007,61.849205,-15.924180,0.018371,0.002085,0.052961,275.119019,14.015230,0.529613,-15.924180,0.053091,0.000000
81.170006,61.830582,-15.924180,0.018371,0.002085,0.052961,275.036163,14.011010,0.529613,-15.924180,0.053091,0.000000
81.380005,61.821274,-15.924180,0.018380,0.002085,0.052961,274.994751,14.008901,0.529613,-15.924180,0.053091,0.000000
81.590004,61.822021,-15.924180,0.018367,0.002085,0.052961,274.998077,14.009069,0.529613,-15.924180,0.053091,0.000000
81.800003,61.793716,-16.013142,0.018371,0.002085,0.052961,274.872192,14.002656,0.529613,-16.013142,0.053091,0.000000
82.010002,61.798561,-15.924180,0.018367,0.002085,0.052961,274.893738,14.003755,0.529613,-15.924180,0.053091,0.000000
82.220001,61.785896,-15.968661,0.018397,0.002085,0.052961,274.837402,14.000884,0.529613,-15.968661,0.053091,0.000000
82.430000,61.773979,-15.968661,0.018371,0.002085,0.052961,274.784393,13.998184,0.529613,-15.968661,0.053091,0.000000
82.640007,61.757225,-15.924180,0.018384,0.002085,0.052961,274.709869,13.994388,0.529613,-15.924180,0.053091,0.000000
82.850006,61.738235,-16.013142,0.018389,0.002085,0.052961,274.625397,13.990085,0.529613,-16.013142,0.053091,0.000000
83.060005,61.740471,-15.924180,0.018380,0.002085,0.052961,274.635345,13.990591,0.529613,-15.924180,0.053091,0.000000
83.270004,61.717384,-15.924180,0.018389,0.002085,0.052961,274.532623,13.985359,0.529613,-15.924180,0.053091,0.000000
83.480003,61.709930,-16.013142,0.018371,0.002085,0.052961,274.499481,13.983670,0.529613,-16.013142,0.053091,0.000000
83.690002,61.701370,-15.968661,0.018358,0.002085,0.052961,274.461395,13.981730,0.529613,-15.968661,0.053091,0.000000
83.900002,61.687965,-16.013142,0.018363,0.002085,0.052961,274.401764,13.978693,0.529613,-16.013142,0.053091,0.000000
84.110001,61.678658,-15.924180,0.018393,0.002085,0.052961,274.360382,13.976583,0.529613,-15.924180,0.053091,0.000000
84.320007,61.664131,-16.013142,0.018397,0.002085,0.052961,274.295746,13.973292,0.529613,-16.013142,0.053091,0.000000
84.530006,61.658173,-16.013142,0.018376,0.002085,0.052961,274.269257,13.971942,0.529613,-16.013142,0.053091,0.000000
84.740005,61.651100,-15.968661,0.018384,0.002085,0.052961,274.237793,13.970339,0.529613,-15.968661,0.053091,0.000000
84.950005,61.633972,-15.968661,0.018384,0.002085,0.052961,274.161591,13.966457,0.529613,-15.968661,0.053091,0.000000
85.160004,61.625778,-16.013142,0.018384,0.002085,0.052961,274.125153,13.964602,0.529613,-16.013142,0.053091,0.000000
85.370003,61.621681,-15.968661,0.018371,0.002085,0.052961,274.106934,13.963673,0.529613,-15.968661,0.053091,0.000000
85.580002,61.603432,-16.057623,0.018371,0.002085,0.052961,274.025757,13.959538,0.529613,-16.057623,0.053091,0.000000
85.790001,61.595619,-16.013142,0.018380,0.002085,0.052961,273.990997,13.957767,0.529613,-16.013142,0.053091,0.000000
86.000008,61.584076,-16.102104,0.018371,0.002085,0.052961,273.939636,13.955152,0.529613,-16.102104,0.053091,0.000000
86.210007,61.582954,-16.013142,0.018376,0.002085,0.052961,273.934662,13.954897,0.529613,-16.013142,0.053091,0.000000
86.420006,61.568436,-16.013142,0.018376,0.002085,0.052961,273.870087,13.951607,0.529613,-16.013142,0.053091,0.000000
86.630005,61.557632,-16.013142,0.018384,0.002085,0.052961,273.822021,13.949159,0.529613,-16.013142,0.053091,0.000000
86.840004,61.538643,-16.013142,0.018393,0.002085,0.052961,273.737549,13.944856,0.529613,-16.013142,0.053091,0.000000
87.050003,61.537895,-16.057623,0.018384,0.002085,0.052961,273.734222,13.944687,0.529613,-16.057623,0.053091,0.000000
87.260002,61.537529,-16.013142,0.018389,0.002085,0.052961,273.732605,13.944603,0.529613,-16.013142,0.053091,0.000000
87.470001,61.529335,-16.057623,0.018367,0.002085,0.052961,273.696136,13.942747,0.529613,-16.057623,0.053091,0.000000
87.680008,61.519279,-16.057623,0.018389,0.002085,0.052961,273.651428,13.940468,0.529613,-16.057623,0.053091,0.000000
87.890007,61.516304,-16.057623,0.018380,0.002085,0.052961,273.638184,13.939794,0.529613,-16.057623,0.053091,0.000000
88.100006,61.493584,-16.102104,0.018384,0.002085,0.052961,273.537109,13.934645,0.529613,-16.102104,0.053091,0.000000
88.310005,61.483902,-16.057623,0.018371,0.002085,0.052961,273.494049,13.932452,0.529613,-16.057623,0.053091,0.000000
88.500008,61.465660,-16.057623,0.018389,0.002085,0.052961,273.412903,13.928317,0.529613,-16.057623,0.053091,0.000000