File: Data/I-18 Polished After 2_08182023_171106.csv
Time (sec),S:Load (lbs),S:HL1 (DIM),S:LVDT (in),S:Position (in),Ch:Position (mm),Ch:Load (N),Ch:Stress (MPa),Ch:Strain (mm/mm),Ch:HL1 (DIM),Set Point (),Cycles ()
0.110000,-0.014900,-30.558413,-0.000004,-0.000000,-0.000000,-0.066279,-0.003376,-0.000000,-30.558413,0.000199,0.000000
0.290000,-0.003723,-30.513933,-0.000013,-0.000000,-0.000000,-0.016561,-0.000844,-0.000000,-30.513933,0.000199,0.000000
0.470000,0.002602,-30.558413,-0.000004,0.000069,0.001752,0.011573,0.000590,0.017520,-30.558413,0.002333,0.000000
0.650000,-0.003723,-30.513933,-0.000017,0.000166,0.004215,-0.016561,-0.000844,0.042149,-30.513933,0.005316,0.000000
0.830000,-0.001488,-30.513933,0.000056,0.000286,0.007267,-0.006618,-0.000337,0.072674,-30.513933,0.008317,0.000000
1.010000,0.021965,-30.602894,0.000121,0.000401,0.010190,0.097705,0.004977,0.101901,-30.602894,0.011318,0.000000
1.190000,-0.010429,-30.513933,0.000224,0.000514,0.013043,-0.046392,-0.002363,0.130431,-30.513933,0.014318,0.000000
1.370000,-0.033890,-30.558413,0.000371,0.000633,0.016079,-0.150749,-0.007680,0.160786,-30.558413,0.017319,0.000000
1.550000,-0.030907,-30.558413,0.000509,0.000754,0.019149,-0.137480,-0.007004,0.191485,-30.558413,0.020319,0.000000
1.730000,-0.037239,-30.602894,0.000608,0.000876,0.022245,-0.165648,-0.008438,0.222446,-30.602894,0.023320,0.000000
1.910000,0.025696,-30.558413,0.000746,0.000994,0.025237,0.114301,0.005823,0.252365,-30.558413,0.026321,0.000000
2.090000,0.024200,-30.469452,0.000849,0.001112,0.028246,0.107649,0.005484,0.282459,-30.469452,0.029321,0.000000
2.270000,0.037239,-30.513933,0.000953,0.001235,0.031359,0.165648,0.008438,0.313590,-30.513933,0.032304,0.000000
2.450000,0.050644,-30.602894,0.001087,0.001351,0.034316,0.225275,0.011476,0.343161,-30.602894,0.035305,0.000000
2.630000,0.033882,-30.647375,0.001199,0.001458,0.037031,0.150715,0.007678,0.370307,-30.647375,0.038305,0.000000
2.810000,0.048782,-30.513933,0.001319,0.001576,0.040023,0.216995,0.011054,0.400226,-30.513933,0.041306,0.000000
2.990000,0.032394,-30.558413,0.001449,0.001696,0.043066,0.144098,0.007341,0.430664,-30.558413,0.044307,0.000000
3.170000,0.033882,-30.513933,0.001574,0.001816,0.046128,0.150715,0.007678,0.461280,-30.513933,0.047307,0.000000
3.350000,0.017128,-30.602894,0.001656,0.001933,0.049103,0.076189,0.003881,0.491026,-30.602894,0.050308,0.000000
3.530000,0.016380,-30.647375,0.001768,0.002052,0.052120,0.072863,0.003712,0.521203,-30.647375,0.053309,0.000000
3.710000,-0.016762,-30.558413,0.001914,0.002173,0.055191,-0.074560,-0.003798,0.551906,-30.558413,0.056309,0.000000
3.890000,-0.024208,-30.558413,0.002048,0.002293,0.058243,-0.107683,-0.005486,0.582431,-30.558413,0.059292,0.000000
4.070000,0.030533,-30.513933,0.002147,0.002406,0.061122,0.135817,0.006919,0.611223,-30.513933,0.062293,0.000000
4.250000,0.016754,-30.558413,0.002255,0.002527,0.064183,0.074526,0.003797,0.641835,-30.558413,0.065294,0.000000
4.430000,0.013405,-30.558413,0.002393,0.002647,0.067236,0.059628,0.003038,0.672360,-30.558413,0.068294,0.000000
4.610000,0.055107,-30.558413,0.002522,0.002768,0.070315,0.245129,0.012487,0.703150,-30.558413,0.071295,0.000000
4.790000,0.039467,-30.513933,0.002669,0.002889,0.073376,0.175557,0.008943,0.733762,-30.513933,0.074296,0.000000
4.970000,0.048782,-30.558413,0.002764,0.003003,0.076264,0.216995,0.011054,0.762641,-30.558413,0.077296,0.000000
5.150000,0.037605,-30.647375,0.002867,0.003112,0.079048,0.167277,0.008521,0.790479,-30.647375,0.080297,0.000000
5.330000,0.052132,-30.558413,0.002997,0.003231,0.082066,0.231893,0.011813,0.820656,-30.558413,0.083297,0.000000
5.510000,0.034256,-30.558413,0.003113,0.003347,0.085014,0.152378,0.007763,0.850144,-30.558413,0.086298,0.000000
5.690000,0.045799,-30.602894,0.003251,0.003472,0.088180,0.203725,0.010378,0.881797,-30.602894,0.089281,0.000000
5.870000,0.037979,-30.558413,0.003372,0.003590,0.091198,0.168940,0.008606,0.911978,-30.558413,0.092282,0.000000
6.050000,0.058830,-30.647375,0.003492,0.003708,0.094189,0.261690,0.013331,0.941894,-30.647375,0.095282,0.000000
6.230000,0.035378,-30.647375,0.003604,0.003828,0.097234,0.157367,0.008017,0.972336,-30.647375,0.098283,0.000000
6.410000,0.026810,-30.602894,0.003725,0.003941,0.100104,0.119255,0.006075,1.001040,-30.602894,0.101283,0.000000
6.590000,0.016754,-30.513933,0.003863,0.004064,0.103235,0.074526,0.003797,1.032349,-30.513933,0.104284,0.000000
6.770000,0.034630,-30.602894,0.003988,0.004182,0.106218,0.154041,0.007847,1.062182,-30.602894,0.107285,0.000000
6.950000,0.053246,-30.602894,0.004100,0.004298,0.109158,0.236848,0.012066,1.091579,-30.602894,0.110285,0.000000
7.130000,0.072609,-30.602894,0.004247,0.004419,0.112254,0.322981,0.016453,1.122539,-30.602894,0.113286,0.000000
7.310000,0.090485,-30.558413,0.004320,0.004536,0.115202,0.402496,0.020504,1.152024,-30.558413,0.116269,0.000000
7.490000,0.201080,-30.513933,0.004454,0.004652,0.118159,0.894450,0.045565,1.181595,-30.513933,0.119270,0.000000
7.670001,0.512009,-30.602894,0.004566,0.004768,0.121100,2.277528,0.116023,1.210996,-30.602894,0.122270,0.000000
7.850000,0.684418,-30.602894,0.004643,0.000002,0.000052,3.044442,0.155091,0.000519,-30.602894,0.000269,0.000000
8.030001,0.664314,-30.647375,0.004639,0.000002,0.000052,2.955018,0.150536,0.000519,-30.647375,0.000269,0.000000
8.210000,0.666542,-30.558413,0.004635,0.000002,0.000052,2.964927,0.151041,0.000519,-30.558413,0.000269,0.000000
8.390000,0.710487,-30.558413,0.004600,0.000002,0.000052,3.160406,0.160999,0.000519,-30.558413,0.000494,0.000000
8.570001,0.691864,-30.602894,0.004639,0.000002,0.000052,3.077565,0.156779,0.000519,-30.602894,0.000798,0.000000
8.750000,0.695221,-30.602894,0.004635,0.000007,0.000173,3.092497,0.157539,0.001733,-30.602894,0.001093,0.000000
8.930000,0.718307,-30.602894,0.004631,0.000017,0.000433,3.195191,0.162771,0.004334,-30.602894,0.001396,0.000000
9.110001,0.760757,-30.602894,0.004613,0.000025,0.000624,3.384018,0.172390,0.006241,-30.602894,0.001691,0.000000
9.290001,0.815491,-30.513933,0.004605,0.000036,0.000919,3.627484,0.184793,0.009190,-30.513933,0.001995,0.000000
9.470000,1.003166,-30.558413,0.004631,0.000052,0.001318,4.462306,0.227321,0.013179,-30.558413,0.002298,0.000000
9.650001,1.067589,-30.647375,0.004648,0.000065,0.001648,4.748872,0.241919,0.016476,-30.647375,0.002593,0.000000
9.830001,1.125679,-30.602894,0.004665,0.000074,0.001873,5.007270,0.255083,0.018731,-30.602894,0.002897,0.000000
10.010000,1.202393,-30.602894,0.004665,0.000082,0.002081,5.348509,0.272466,0.020813,-30.602894,0.003191,0.000000
10.190001,1.337189,-30.602894,0.004687,0.000101,0.002558,5.948112,0.303011,0.025582,-30.602894,0.003495,0.000000
10.370001,1.435120,-30.602894,0.004674,0.000113,0.002870,6.383731,0.325203,0.028705,-30.602894,0.003798,0.000000
10.550000,1.501404,-30.602894,0.004695,0.000124,0.003139,6.678578,0.340223,0.031392,-30.602894,0.004093,0.000000
10.730000,1.625404,-30.602894,0.004738,0.000135,0.003425,7.230160,0.368322,0.034253,-30.602894,0.004397,0.000000
10.910001,1.667854,-30.602894,0.004721,0.000145,0.003694,7.418986,0.377941,0.036944,-30.602894,0.004691,0.000000
11.090000,1.724083,-30.602894,0.004725,0.000155,0.003937,7.669104,0.390683,0.039370,-30.602894,0.004995,0.000000
11.270000,1.861488,-30.602894,0.004743,0.000169,0.004293,8.280313,0.421819,0.042928,-30.602894,0.005290,0.000000
11.450001,2.042091,-30.647375,0.004751,0.000181,0.004605,9.083676,0.462745,0.046047,-30.647375,0.005593,0.000000
11.630000,2.163857,-30.602894,0.004756,0.000193,0.004891,9.625315,0.490337,0.048908,-30.602894,0.005897,0.000000
11.810000,2.230141,-30.647375,0.004790,0.000201,0.005099,9.920161,0.505357,0.050990,-30.647375,0.006192,0.000000
11.990001,2.323601,-30.647375,0.004764,0.000210,0.005325,10.335893,0.526535,0.053246,-30.647375,0.006495,0.000000
12.170001,2.532127,-30.602894,0.004799,0.000229,0.005819,11.263465,0.573788,0.058189,-30.602894,0.006790,0.000000
12.350000,2.735817,-30.602894,0.004786,0.000244,0.006192,12.169521,0.619945,0.061917,-30.602894,0.007094,0.000000
12.530001,2.824074,-30.602894,0.004812,0.000255,0.006470,12.562108,0.639944,0.064695,-30.602894,0.007397,0.000000
12.710001,2.845673,-30.647375,0.004807,0.000262,0.006643,12.658184,0.644839,0.066429,-30.647375,0.007692,0.000000
12.890000,3.012863,-30.647375,0.004863,0.000276,0.007007,13.401885,0.682725,0.070070,-30.647375,0.007996,0.000000
13.070001,3.224747,-30.691856,0.004859,0.000290,0.007363,14.344390,0.730738,0.073628,-30.691856,0.008290,0.000000
13.250001,3.371086,-30.647375,0.004846,0.000301,0.007649,14.995340,0.763899,0.076489,-30.647375,0.008594,0.000000
13.430000,3.542007,-30.647375,0.004876,0.000314,0.007978,15.755636,0.802630,0.079782,-30.647375,0.008898,0.000000
13.610001,3.686485,-30.602894,0.004881,0.000324,0.008221,16.398306,0.835370,0.082212,-30.602894,0.009192,0.000000
13.790001,3.709572,-30.647375,0.004885,0.000328,0.008334,16.500999,0.840601,0.083340,-30.647375,0.009496,0.000000
13.970000,3.868576,-30.647375,0.004902,0.000341,0.008672,17.208286,0.876632,0.086720,-30.647375,0.009791,0.000000
14.150001,4.137054,-30.691856,0.004889,0.000358,0.009097,18.402536,0.937470,0.090970,-30.691856,0.010094,0.000000
14.330001,4.272224,-30.602894,0.004919,0.000369,0.009383,19.003803,0.968100,0.093831,-30.602894,0.010398,0.000000
14.510000,4.418571,-30.602894,0.004941,0.000382,0.009713,19.654787,1.001263,0.097128,-30.602894,0.010693,0.000000
14.690001,4.626350,-30.602894,0.004937,0.000396,0.010068,20.579035,1.048346,0.100682,-30.602894,0.010996,0.000000
14.870001,4.627472,-30.691856,0.004958,0.000402,0.010216,20.584023,1.048600,0.102158,-30.691856,0.011291,0.000000
15.050001,4.854248,-30.602894,0.004971,0.000416,0.010554,21.592773,1.099988,0.105542,-30.602894,0.011595,0.000000
15.230000,5.159592,-30.647375,0.004980,0.000432,0.010979,22.951010,1.169180,0.109788,-30.647375,0.011898,0.000000
15.410001,5.302582,-30.602894,0.005001,0.000444,0.011274,23.587061,1.201582,0.112737,-30.602894,0.012193,0.000000
15.590001,5.335350,-30.647375,0.005006,0.000451,0.011456,23.732822,1.209008,0.114557,-30.647375,0.012497,0.000000
15.770000,5.384880,-30.691856,0.005014,0.000455,0.011551,23.953142,1.220231,0.115515,-30.691856,0.012791,0.000000
15.950001,5.788528,-30.691856,0.005019,0.000475,0.012054,25.748661,1.311699,0.120541,-30.691856,0.013095,0.000000
16.130001,5.838425,-30.602894,0.005044,0.000481,0.012228,25.970610,1.323006,0.122279,-30.602894,0.013399,0.000000
16.310001,6.218620,-30.602894,0.005062,0.000502,0.012740,27.661804,1.409159,0.127396,-30.602894,0.013693,0.000000
16.490002,6.270378,-30.647375,0.005057,0.000509,0.012930,27.892035,1.420888,0.129303,-30.647375,0.013997,0.000000
16.670000,6.461037,-30.691856,0.005079,0.000523,0.013286,28.740126,1.464092,0.132857,-30.691856,0.014292,0.000000
16.850000,6.501991,-30.647375,0.005088,0.000530,0.013468,28.922302,1.473372,0.134678,-30.647375,0.014595,0.000000
17.030001,6.766006,-30.691856,0.005109,0.000543,0.013797,30.096701,1.533199,0.137975,-30.691856,0.014899,0.000000
17.210001,6.956291,-30.691856,0.005113,0.000557,0.014153,30.943129,1.576318,0.141529,-30.691856,0.015194,0.000000
17.390001,7.177109,-30.602894,0.005113,0.000570,0.014483,31.925375,1.626356,0.144825,-30.602894,0.015497,0.000000
17.570002,7.318977,-30.736338,0.005135,0.000579,0.014708,32.556438,1.658504,0.147081,-30.736338,0.015792,0.000000
17.750000,7.319351,-30.691856,0.005135,0.000584,0.014830,32.558102,1.658589,0.148296,-30.691856,0.016096,0.000000
17.930000,7.952385,-30.647375,0.005157,0.000611,0.015515,35.373974,1.802036,0.155147,-30.647375,0.016399,0.000000
18.110001,8.032074,-30.602894,0.005174,0.000621,0.015783,35.728451,1.820094,0.157834,-30.602894,0.016694,0.000000
18.290001,8.172455,-30.691856,0.005195,0.000633,0.016070,36.352894,1.851905,0.160695,-30.691856,0.016998,0.000000
18.470001,8.170593,-30.691856,0.005187,0.000638,0.016217,36.344612,1.851483,0.162171,-30.691856,0.017292,0.000000
18.650002,8.396255,-30.691856,0.005213,0.000652,0.016555,37.348412,1.902619,0.165551,-30.691856,0.017596,0.000000
18.830002,8.644623,-30.647375,0.005213,0.000664,0.016859,38.453201,1.958899,0.168587,-30.647375,0.017891,0.000000
19.010000,8.750748,-30.691856,0.005230,0.000674,0.017127,38.925270,1.982948,0.171274,-30.691856,0.018194,0.000000
19.190001,8.999870,-30.691856,0.005290,0.000689,0.017492,40.033424,2.039400,0.174919,-30.691856,0.018498,0.000000
19.370001,9.187546,-30.691856,0.005277,0.000700,0.017787,40.868244,2.081928,0.177867,-30.691856,0.018793,0.000000
19.550001,9.288086,-30.602894,0.005273,0.000708,0.017995,41.315468,2.104710,0.179949,-30.602894,0.019096,0.000000
19.730001,9.288460,-30.647375,0.005277,0.000716,0.018194,41.317131,2.104795,0.181944,-30.647375,0.019391,0.000000
19.910002,9.774773,-30.691856,0.005295,0.000733,0.018619,43.480362,2.214995,0.186190,-30.691856,0.019695,0.000000
20.090000,10.063362,-30.647375,0.005303,0.000750,0.019053,44.764069,2.280390,0.190528,-30.647375,0.019998,0.000000
20.270000,10.184013,-30.647375,0.005312,0.000760,0.019304,45.300755,2.307730,0.193045,-30.647375,0.020293,0.000000
20.450001,10.306892,-30.691856,0.005316,0.000771,0.019582,45.847347,2.335575,0.195819,-30.691856,0.020597,0.000000
20.630001,10.420097,-30.647375,0.005346,0.000780,0.019825,46.350906,2.361228,0.198245,-30.647375,0.020891,0.000000
20.810001,10.583939,-30.647375,0.005364,0.000792,0.020111,47.079712,2.398355,0.201107,-30.647375,0.021195,0.000000
20.990002,10.767891,-30.780819,0.005376,0.000803,0.020406,47.897972,2.440039,0.204055,-30.780819,0.021499,0.000000
21.170000,11.090370,-30.736338,0.005372,0.000818,0.020770,49.332432,2.513114,0.207700,-30.736338,0.021793,0.000000
21.350000,11.303368,-30.691856,0.005411,0.000831,0.021108,50.279892,2.561380,0.211080,-30.691856,0.022097,0.000000
21.530001,11.239319,-30.647375,0.005381,0.000834,0.021178,49.994987,2.546866,0.211776,-30.647375,0.022392,0.000000
21.710001,11.199097,-30.691856,0.005398,0.000840,0.021334,49.816071,2.537752,0.213336,-30.691856,0.022695,0.000000
21.890001,11.994858,-30.691856,0.005441,0.000868,0.022036,53.355793,2.718074,0.220360,-30.691856,0.022999,0.000000
22.070002,12.259621,-30.736338,0.005463,0.000882,0.022400,54.533516,2.778070,0.224001,-30.736338,0.023293,0.000000
22.250002,12.267807,-30.691856,0.005463,0.000890,0.022600,54.569931,2.779925,0.225996,-30.691856,0.023597,0.000000
22.430000,12.292755,-30.691856,0.005445,0.000897,0.022791,54.680904,2.785578,0.227907,-30.691856,0.023892,0.000000
22.610001,12.514694,-30.691856,0.005463,0.000909,0.023094,55.668140,2.835870,0.230939,-30.691856,0.024195,0.000000
22.790001,12.689331,-30.736338,0.005458,0.000924,0.023458,56.444965,2.875444,0.234584,-30.736338,0.024499,0.000000
22.970001,13.201347,-30.736338,0.005501,0.000939,0.023840,58.722527,2.991468,0.238399,-30.736338,0.024794,0.000000
23.150002,13.239700,-30.691856,0.005493,0.000947,0.024057,58.893127,3.000159,0.240568,-30.691856,0.025097,0.000000
23.330002,13.352531,-30.647375,0.005519,0.000956,0.024291,59.395027,3.025727,0.242907,-30.647375,0.025392,0.000000
23.510000,13.453072,-30.691856,0.005536,0.000965,0.024508,59.842251,3.048510,0.245076,-30.691856,0.025696,0.000000
23.690001,13.613564,-30.736338,0.005514,0.000979,0.024863,60.556156,3.084877,0.248634,-30.736338,0.025999,0.000000
23.870001,14.121849,-30.691856,0.005536,0.000994,0.025245,62.817123,3.200057,0.252449,-30.691856,0.026294,0.000000
24.050001,14.393684,-30.691856,0.005566,0.001009,0.025618,64.026306,3.261656,0.256177,-30.691856,0.026598,0.000000
24.230001,14.458473,-30.691856,0.005583,0.001016,0.025808,64.314499,3.276337,0.258084,-30.691856,0.026892,0.000000
24.410002,14.598488,-30.691856,0.005583,0.001027,0.026086,64.937317,3.308065,0.260859,-30.691856,0.027196,0.000000
24.590002,14.749672,-30.691856,0.005618,0.001037,0.026329,65.609818,3.342323,0.263289,-30.691856,0.027500,0.000000
24.770000,15.189072,-30.691856,0.005605,0.001055,0.026788,67.564362,3.441893,0.267884,-30.691856,0.027794,0.000000
24.950001,15.446754,-30.691856,0.005618,0.001067,0.027101,68.710594,3.500284,0.271006,-30.691856,0.028098,0.000000
25.130001,15.588257,-30.647375,0.005639,0.001077,0.027361,69.340027,3.532349,0.273610,-30.647375,0.028393,0.000000
25.310001,15.697731,-30.736338,0.005635,0.001086,0.027595,69.826996,3.557157,0.275949,-30.736338,0.028696,0.000000
25.490002,15.791199,-30.780819,0.005665,0.001094,0.027786,70.242760,3.578337,0.277857,-30.780819,0.029000,0.000000
25.670002,15.960999,-30.736338,0.005648,0.001105,0.028063,70.998070,3.616814,0.280635,-30.736338,0.029295,0.000000
25.850000,16.593658,-30.736338,0.005657,0.001123,0.028523,73.812279,3.760177,0.285230,-30.736338,0.029598,0.000000
26.030001,17.000664,-30.691856,0.005678,0.001139,0.028922,75.622726,3.852406,0.289219,-30.691856,0.029893,0.000000
26.210001,16.953003,-30.736338,0.005721,0.001147,0.029139,75.410721,3.841605,0.291388,-30.736338,0.030197,0.000000
26.390001,17.090034,-30.691856,0.005713,0.001156,0.029373,76.020271,3.872657,0.293727,-30.691856,0.030491,0.000000
26.570002,17.267654,-30.647375,0.005717,0.001168,0.029668,76.810364,3.912906,0.296675,-30.647375,0.030795,0.000000
26.750002,17.514534,-30.647375,0.005721,0.001177,0.029902,77.908539,3.968850,0.299018,-30.647375,0.031099,0.000000
26.930002,17.998619,-30.691856,0.005734,0.001192,0.030266,80.061859,4.078545,0.302659,-30.691856,0.031393,0.000000
27.110001,18.182571,-30.736338,0.005747,0.001204,0.030569,80.880119,4.120229,0.305695,-30.736338,0.031697,0.000000
27.290001,18.338226,-30.736338,0.005769,0.001216,0.030890,81.572502,4.155502,0.308904,-30.736338,0.031992,0.000000
27.470001,18.485313,-30.736338,0.005773,0.001223,0.031064,82.226784,4.188832,0.310638,-30.736338,0.032295,0.000000
27.650002,18.874069,-30.691856,0.005769,0.001235,0.031376,83.956055,4.276925,0.313760,-30.691856,0.032599,0.000000
27.830002,19.581573,-30.736338,0.005821,0.001257,0.031940,87.103188,4.437248,0.319400,-30.736338,0.032894,0.000000
28.010002,19.642647,-30.736338,0.005795,0.001267,0.032191,87.374855,4.451087,0.321913,-30.736338,0.033197,0.000000
28.190001,19.669830,-30.780819,0.005833,0.001274,0.032365,87.495773,4.457247,0.323646,-30.780819,0.033492,0.000000
28.370001,19.905167,-30.691856,0.005829,0.001286,0.032668,88.542603,4.510575,0.326682,-30.691856,0.033796,0.000000
28.550001,20.317757,-30.780819,0.005829,0.001300,0.033015,90.377899,4.604069,0.330153,-30.780819,0.034099,0.000000
28.730001,20.236206,-30.736338,0.005855,0.001305,0.033154,90.015137,4.585590,0.331538,-30.736338,0.034394,0.000000
28.910002,20.632408,-30.869780,0.005855,0.001318,0.033466,91.777534,4.675371,0.334660,-30.869780,0.034698,0.000000
29.090002,20.939621,-30.736338,0.005859,0.001328,0.033735,93.144089,4.744986,0.337348,-30.736338,0.034992,0.000000
29.270000,21.443436,-30.691856,0.005877,0.001343,0.034108,95.385162,4.859152,0.341080,-30.691856,0.035296,0.000000
29.450001,21.466896,-30.736338,0.005872,0.001352,0.034333,95.489525,4.864468,0.343332,-30.736338,0.035600,0.000000
29.630001,22.174408,-30.780819,0.005924,0.001369,0.034767,98.636696,5.024793,0.347669,-30.780819,0.035894,0.000000
29.810001,22.646950,-30.736338,0.005890,0.001386,0.035209,100.738663,5.131872,0.352094,-30.736338,0.036198,0.000000
29.990002,22.814514,-30.780819,0.005924,0.001394,0.035418,101.484024,5.169843,0.354175,-30.780819,0.036493,0.000000
30.170002,23.076668,-30.736338,0.005933,0.001409,0.035782,102.650146,5.229248,0.357816,-30.736338,0.036796,0.000000
30.350002,23.195824,-30.736338,0.005946,0.001417,0.035990,103.180176,5.256249,0.359898,-30.736338,0.037100,0.000000
30.530001,23.344772,-30.780819,0.005954,0.001426,0.036232,103.842735,5.290001,0.362324,-30.780819,0.037395,0.000000
30.710001,23.508247,-30.780819,0.005963,0.001436,0.036484,104.569908,5.327045,0.364841,-30.780819,0.037698,0.000000
30.890001,24.177399,-30.780819,0.005976,0.001452,0.036883,107.546440,5.478677,0.368830,-30.780819,0.037993,0.000000
31.070002,24.728882,-30.780819,0.005989,0.001465,0.037204,109.999557,5.603645,0.372040,-30.780819,0.038297,0.000000
31.250002,24.788460,-30.736338,0.006015,0.001473,0.037421,110.264580,5.617145,0.374205,-30.736338,0.038600,0.000000
31.430002,24.921768,-30.780819,0.006015,0.001480,0.037603,110.857559,5.647353,0.376029,-30.780819,0.038895,0.000000
31.610001,25.625183,-30.736338,0.006006,0.001497,0.038036,113.986504,5.806750,0.380363,-30.736338,0.039199,0.000000
31.790001,26.077240,-30.736338,0.006040,0.001513,0.038418,115.997360,5.909187,0.384178,-30.736338,0.039493,0.000000
31.970001,26.350937,-30.736338,0.006045,0.001523,0.038696,117.214821,5.971208,0.386956,-30.736338,0.039797,0.000000
32.150002,26.760170,-30.736338,0.006062,0.001534,0.038964,119.035179,6.063941,0.389644,-30.736338,0.040100,0.000000
32.330002,26.953438,-30.825298,0.006066,0.001544,0.039216,119.894882,6.107736,0.392157,-30.825298,0.040395,0.000000
32.510002,27.265854,-30.780819,0.006062,0.001558,0.039580,121.284576,6.178531,0.395802,-30.780819,0.040699,0.000000
32.690002,27.911552,-30.780819,0.006079,0.001573,0.039953,124.156784,6.324848,0.399530,-30.780819,0.040994,0.000000
32.870003,28.208328,-30.780819,0.006092,0.001584,0.040222,125.476913,6.392098,0.402217,-30.780819,0.041297,0.000000
33.050003,28.469734,-30.780819,0.006114,0.001593,0.040465,126.639702,6.451334,0.404647,-30.780819,0.041601,0.000000
33.230003,28.676773,-30.780819,0.006105,0.001601,0.040664,127.560654,6.498250,0.406642,-30.780819,0.041895,0.000000
33.410000,29.017120,-30.780819,0.006122,0.001617,0.041080,129.074600,6.575374,0.410805,-30.780819,0.042199,0.000000
33.590000,29.834480,-30.780819,0.006131,0.001629,0.041367,132.710403,6.760590,0.413666,-30.780819,0.042494,0.000000
33.770000,30.497307,-30.780819,0.006161,0.001645,0.041791,135.658798,6.910789,0.417913,-30.780819,0.042797,0.000000
33.950001,30.768387,-30.780819,0.006153,0.001655,0.042034,136.864624,6.972216,0.420343,-30.780819,0.043101,0.000000
34.130001,31.179115,-30.780819,0.006165,0.001669,0.042390,138.691635,7.065289,0.423897,-30.780819,0.043396,0.000000
34.310001,31.353760,-30.780819,0.006178,0.001676,0.042572,139.468491,7.104864,0.425721,-30.780819,0.043699,0.000000
34.490002,31.859444,-30.825298,0.006174,0.001689,0.042910,141.717880,7.219453,0.429101,-30.825298,0.043994,0.000000
34.670002,32.394165,-30.736338,0.006222,0.001702,0.043231,144.096436,7.340623,0.432311,-30.736338,0.044298,0.000000
34.850002,32.842880,-30.736338,0.006209,0.001715,0.043561,146.092422,7.442303,0.435607,-30.736338,0.044592,0.000000
35.030003,33.103165,-30.869780,0.006222,0.001723,0.043769,147.250229,7.501285,0.437689,-30.869780,0.044896,0.000000
35.210003,33.106888,-30.780819,0.006217,0.001728,0.043890,147.266785,7.502128,0.438900,-30.780819,0.045200,0.000000
35.390003,33.728378,-30.825298,0.006230,0.001745,0.044315,150.031326,7.642960,0.443151,-30.825298,0.045494,0.000000
35.570004,34.560257,-30.780819,0.006230,0.001758,0.044653,153.731705,7.831466,0.446534,-30.780819,0.045798,0.000000
35.750000,35.062592,-30.825298,0.006260,0.001775,0.045078,155.966202,7.945297,0.450781,-30.825298,0.046093,0.000000
35.930000,35.470337,-30.736338,0.006234,0.001782,0.045269,157.779938,8.037693,0.452692,-30.736338,0.046396,0.000000
36.110001,36.003204,-30.825298,0.006256,0.001796,0.045616,160.150253,8.158442,0.456159,-30.825298,0.046700,0.000000
36.290001,36.177841,-30.780819,0.006273,0.001804,0.045833,160.927078,8.198016,0.458328,-30.780819,0.046995,0.000000
36.470001,37.057014,-30.780819,0.006278,0.001822,0.046284,164.837830,8.397240,0.462836,-30.780819,0.047298,0.000000
36.650002,37.565674,-30.825298,0.006278,0.001832,0.046535,167.100464,8.512504,0.465353,-30.825298,0.047593,0.000000
36.830002,37.915337,-30.825298,0.006291,0.001842,0.046787,168.655838,8.591738,0.467866,-30.825298,0.047897,0.000000
37.010002,38.126099,-30.825298,0.006282,0.001850,0.046986,169.593353,8.639498,0.469861,-30.825298,0.048200,0.000000
37.190002,38.117531,-30.780819,0.006299,0.001854,0.047099,169.555252,8.637556,0.470989,-30.780819,0.048495,0.000000
37.370003,39.287155,-30.780819,0.006308,0.001874,0.047593,174.757996,8.902596,0.475932,-30.780819,0.048799,0.000000
37.550003,39.413391,-30.825298,0.006334,0.001880,0.047741,175.319519,8.931202,0.477408,-30.825298,0.049093,0.000000
37.730003,40.829521,-30.825298,0.006338,0.001904,0.048374,181.618774,9.252102,0.483736,-30.825298,0.049397,0.000000
37.910004,40.860054,-30.780819,0.006342,0.001912,0.048564,181.754593,9.259020,0.485644,-30.780819,0.049701,0.000000
38.090000,41.375793,-30.780819,0.006372,0.001922,0.048816,184.048721,9.375889,0.488161,-30.780819,0.049995,0.000000
38.270000,41.649483,-30.736338,0.006359,0.001933,0.049102,185.266159,9.437908,0.491022,-30.736338,0.050299,0.000000
38.450001,42.216980,-30.914261,0.006355,0.001942,0.049336,187.790512,9.566504,0.493365,-30.914261,0.050594,0.000000
38.630001,42.921883,-30.869780,0.006359,0.001959,0.049752,190.926071,9.726238,0.497524,-30.869780,0.050897,0.000000
38.810001,43.721741,-30.825298,0.006368,0.001972,0.050082,194.484009,9.907489,0.500821,-30.825298,0.051201,0.000000
38.990002,43.960800,-30.914261,0.006390,0.001978,0.050230,195.547409,9.961659,0.502297,-30.914261,0.051496,0.000000
39.170002,44.008469,-30.869780,0.006403,0.001983,0.050360,195.759445,9.972462,0.503595,-30.869780,0.051799,0.000000
39.350002,45.890060,-30.825298,0.006398,0.002012,0.051114,204.129181,10.398837,0.511142,-30.825298,0.052094,0.000000
39.530003,46.327599,-30.825298,0.006411,0.002024,0.051400,206.075455,10.497984,0.514004,-30.825298,0.052398,0.000000
39.710003,46.764023,-30.825298,0.006437,0.002033,0.051643,208.016769,10.596879,0.516430,-30.825298,0.052701,0.000000
39.890003,47.019470,-30.869780,0.006411,0.002042,0.051860,209.153046,10.654764,0.518599,-30.869780,0.052996,0.000000
40.070004,47.463707,-30.825298,0.006441,0.002055,0.052190,211.129120,10.755429,0.521895,-30.825298,0.053300,0.000000
40.250004,48.341019,-30.825298,0.006433,0.002067,0.052510,215.031586,10.954231,0.525105,-30.825298,0.053594,0.000000
40.430000,48.872398,-30.780819,0.006441,0.002080,0.052840,217.395279,11.074644,0.528398,-30.780819,0.053898,0.000000
40.610001,49.422020,-30.825298,0.006472,0.002092,0.053143,219.840118,11.199189,0.531433,-30.825298,0.054202,0.000000
40.790001,50.116493,-30.825298,0.006459,0.002104,0.053447,222.929291,11.356559,0.534469,-30.825298,0.054496,0.000000
40.970001,50.231926,-30.825298,0.006502,0.002108,0.053551,223.442764,11.382717,0.535510,-30.825298,0.054800,0.000000
41.150002,51.101418,-30.869780,0.006472,0.002125,0.053985,227.310455,11.579746,0.539847,-30.869780,0.055095,0.000000
41.330002,52.323540,-30.780819,0.006515,0.002143,0.054444,232.746735,11.856684,0.544442,-30.780819,0.055398,0.000000
41.510002,52.856033,-30.825298,0.006485,0.002154,0.054722,235.115372,11.977348,0.547216,-30.825298,0.055702,0.000000
41.690002,53.236603,-30.780819,0.006510,0.002163,0.054947,236.808243,12.063587,0.549472,-30.780819,0.055997,0.000000
41.870003,53.736320,-30.869780,0.006485,0.002176,0.055268,239.031097,12.176824,0.552682,-30.869780,0.056300,0.000000
42.050003,54.297859,-30.869780,0.006519,0.002185,0.055502,241.528946,12.304070,0.555025,-30.869780,0.056595,0.000000
42.230003,55.064575,-30.869780,0.006493,0.002198,0.055823,244.939468,12.477812,0.558230,-30.869780,0.056899,0.000000
42.410004,55.491318,-30.825298,0.006506,0.002207,0.056057,246.837708,12.574512,0.560573,-30.825298,0.057194,0.000000
42.590000,56.225258,-30.780819,0.006532,0.002219,0.056361,250.102432,12.740826,0.563609,-30.780819,0.057497,0.000000
42.770000,56.891808,-30.869780,0.006528,0.002231,0.056656,253.067398,12.891868,0.566557,-30.869780,0.057801,0.000000
42.950001,56.911171,-30.869780,0.006532,0.002234,0.056734,253.153534,12.896255,0.567337,-30.869780,0.058095,0.000000
43.130001,57.460419,-30.914261,0.006510,0.002246,0.057037,255.596710,13.020717,0.570372,-30.914261,0.058399,0.000000
43.310001,59.485756,-30.780819,0.006510,0.002273,0.057740,264.605865,13.479665,0.577397,-30.780819,0.058694,0.000000
43.490002,60.139641,-30.825298,0.006541,0.002284,0.058026,267.514496,13.627837,0.580258,-30.825298,0.058997,0.000000
43.670002,60.356735,-30.825298,0.006541,0.002290,0.058173,268.480164,13.677032,0.581735,-30.825298,0.059301,0.000000
43.850002,60.688148,-30.869780,0.006554,0.002299,0.058399,269.954376,13.752131,0.583990,-30.869780,0.059595,0.000000
44.030003,61.359535,-30.825298,0.006549,0.002312,0.058720,272.940857,13.904269,0.587196,-30.825298,0.059899,0.000000
44.210003,62.439041,-30.914261,0.006528,0.002326,0.059075,277.742737,14.148890,0.590754,-30.914261,0.060194,0.000000
44.390003,63.201286,-30.825298,0.006571,0.002339,0.059422,281.133362,14.321616,0.594221,-30.825298,0.060497,0.000000
44.570004,63.674568,-30.869780,0.006541,0.002348,0.059648,283.238617,14.428863,0.596477,-30.869780,0.060801,0.000000
44.750004,64.318779,-30.869780,0.006554,0.002360,0.059943,286.104218,14.574843,0.599425,-30.869780,0.061096,0.000000
44.930000,64.563057,-30.869780,0.006554,0.002364,0.060047,287.190826,14.630198,0.600466,-30.869780,0.061399,0.000000
45.110001,65.735283,-30.869780,0.006562,0.002384,0.060541,292.405151,14.895828,0.605409,-30.869780,0.061694,0.000000
45.290001,66.982735,-30.914261,0.006575,0.002400,0.060966,297.954071,15.178505,0.609660,-30.914261,0.061998,0.000000
45.470001,67.542030,-30.958742,0.006549,0.002401,0.060975,300.441956,15.305243,0.609747,-30.958742,0.061226,0.000000
45.650002,67.189400,-30.914261,0.006588,0.002401,0.060975,298.873383,15.225336,0.609747,-30.914261,0.061226,0.000000
45.830002,66.870277,-30.869780,0.006592,0.002399,0.060931,297.453857,15.153022,0.609311,-30.869780,0.060975,0.000000
46.010002,66.617058,-30.780819,0.006597,0.002397,0.060879,296.327484,15.095640,0.608793,-30.780819,0.060975,0.000000
46.190002,66.402199,-30.825298,0.006588,0.002396,0.060871,295.371735,15.046953,0.608706,-30.825298,0.060975,0.000000
46.370003,66.208565,-30.914261,0.006605,0.002396,0.060862,294.510406,15.003076,0.608619,-30.914261,0.060975,0.000000
46.550003,66.036537,-30.869780,0.006597,0.002396,0.060853,293.745178,14.964093,0.608532,-30.869780,0.060975,0.000000
46.730003,65.881630,-30.825298,0.006579,0.002396,0.060853,293.056122,14.928990,0.608532,-30.825298,0.060975,0.000000
46.910004,65.750542,-30.869780,0.006588,0.002395,0.060844,292.473022,14.899285,0.608445,-30.869780,0.060975,0.000000
47.090004,65.617241,-30.869780,0.006592,0.002395,0.060844,291.880066,14.869080,0.608445,-30.869780,0.060975,0.000000
47.270000,65.501808,-30.914261,0.006597,0.002395,0.060844,291.366608,14.842922,0.608445,-30.914261,0.060975,0.000000
47.450001,65.382652,-30.914261,0.006601,0.002395,0.060836,290.836548,14.815921,0.608358,-30.914261,0.060975,0.000000
47.630001,65.295143,-30.869780,0.006588,0.002395,0.060836,290.447296,14.796091,0.608358,-30.869780,0.060975,0.000000
47.810001,65.195335,-30.914261,0.006597,0.002395,0.060836,290.003326,14.773474,0.608358,-30.914261,0.060975,0.000000
47.990002,65.111931,-30.914261,0.006601,0.002395,0.060836,289.632324,14.754575,0.608358,-30.914261,0.060975,0.000000
48.170002,65.028893,-30.869780,0.006601,0.002395,0.060827,289.262970,14.735758,0.608270,-30.869780,0.060975,0.000000
48.350002,64.943245,-30.869780,0.006605,0.002395,0.060827,288.881989,14.716350,0.608270,-30.869780,0.060975,0.000000
48.530003,64.866158,-30.869780,0.006597,0.002395,0.060827,288.539093,14.698881,0.608270,-30.869780,0.060975,0.000000
48.710003,64.795784,-30.869780,0.006610,0.002395,0.060827,288.226044,14.682934,0.608270,-30.869780,0.060975,0.000000
48.890003,64.736214,-30.869780,0.006614,0.002395,0.060827,287.961060,14.669436,0.608270,-30.869780,0.060975,0.000000
49.070004,64.678490,-30.958742,0.006584,0.002395,0.060827,287.704285,14.656355,0.608270,-30.958742,0.060975,0.000000
49.250004,64.605873,-30.869780,0.006605,0.002395,0.060827,287.381287,14.639900,0.608270,-30.869780,0.060975,0.000000
49.430004,64.542198,-30.914261,0.006601,0.002395,0.060827,287.098022,14.625471,0.608270,-30.914261,0.060975,0.000000
49.610001,64.481880,-30.914261,0.006601,0.002395,0.060827,286.829742,14.611803,0.608270,-30.914261,0.060975,0.000000
49.790001,64.435326,-30.869780,0.006601,0.002395,0.060827,286.622650,14.601254,0.608270,-30.869780,0.060975,0.000000
49.970001,64.392876,-30.914261,0.006584,0.002395,0.060827,286.433807,14.591635,0.608270,-30.914261,0.060975,0.000000
50.150002,64.330315,-30.914261,0.006605,0.002394,0.060818,286.155518,14.577457,0.608183,-30.914261,0.060975,0.000000
50.330002,64.291222,-30.869780,0.006605,0.002394,0.060818,285.981628,14.568599,0.608183,-30.869780,0.060975,0.000000
50.510002,64.242805,-30.869780,0.006631,0.002394,0.060818,285.766266,14.557628,0.608183,-30.869780,0.060975,0.000000
50.690002,64.185844,-30.958742,0.006601,0.002394,0.060818,285.512909,14.544721,0.608183,-30.958742,0.060975,0.000000
50.870003,64.151207,-30.914261,0.006601,0.002394,0.060818,285.358826,14.536872,0.608183,-30.914261,0.060975,0.000000
51.050003,64.116585,-30.958742,0.006610,0.002394,0.060818,285.204803,14.529026,0.608183,-30.958742,0.060975,0.000000
51.230003,64.075249,-30.914261,0.006597,0.002394,0.060818,285.020935,14.519659,0.608183,-30.914261,0.060975,0.000000
51.410004,64.029442,-30.958742,0.006592,0.002394,0.060818,284.817169,14.509278,0.608183,-30.958742,0.060975,0.000000
51.590004,63.979546,-30.958742,0.006610,0.002394,0.060818,284.595245,14.497972,0.608183,-30.958742,0.060975,0.000000
51.770004,63.949013,-30.958742,0.006601,0.002394,0.060818,284.459412,14.491054,0.608183,-30.958742,0.060975,0.000000
51.950001,63.925545,-30.869780,0.006601,0.002394,0.060818,284.355011,14.485736,0.608183,-30.869780,0.060975,0.000000
52.130001,63.877892,-30.914261,0.006601,0.002394,0.060818,284.143066,14.474936,0.608183,-30.914261,0.060975,0.000000
52.310001,63.846977,-30.958742,0.006618,0.002394,0.060818,284.005554,14.467932,0.608183,-30.958742,0.060975,0.000000
52.490002,63.818306,-30.958742,0.006614,0.002394,0.060818,283.877991,14.461434,0.608183,-30.958742,0.060975,0.000000
52.670002,63.778099,-30.958742,0.006618,0.002394,0.060818,283.699158,14.452324,0.608183,-30.958742,0.060975,0.000000
52.850002,63.743462,-30.914261,0.006601,0.002394,0.060818,283.545074,14.444475,0.608183,-30.914261,0.060975,0.000000
53.030003,63.723732,-31.003223,0.006605,0.002394,0.060818,283.457306,14.440003,0.608183,-31.003223,0.060975,0.000000
53.210003,63.690590,-30.869780,0.006605,0.002394,0.060818,283.309906,14.432494,0.608183,-30.869780,0.060975,0.000000
53.390003,63.663033,-30.958742,0.006601,0.002394,0.060818,283.187317,14.426250,0.608183,-30.958742,0.060975,0.000000
53.570004,63.614998,-30.958742,0.006571,0.002394,0.060818,282.973633,14.415364,0.608183,-30.958742,0.060975,0.000000
53.750004,63.604561,-30.914261,0.006597,0.002394,0.060818,282.927216,14.412999,0.608183,-30.914261,0.060975,0.000000
53.930004,63.571800,-30.869780,0.006622,0.002394,0.060818,282.781494,14.405576,0.608183,-30.869780,0.060975,0.000000
54.110004,63.535301,-30.914261,0.006614,0.002394,0.060818,282.619141,14.397305,0.608183,-30.914261,0.060975,0.000000
54.290001,63.515938,-30.958742,0.006601,0.002394,0.060818,282.532990,14.392917,0.608183,-30.958742,0.060975,0.000000
54.470001,63.496208,-30.869780,0.006605,0.002394,0.060818,282.445251,14.388447,0.608183,-30.869780,0.060975,0.000000
54.650002,63.463814,-30.914261,0.006597,0.002394,0.060818,282.301147,14.381106,0.608183,-30.914261,0.060975,0.000000
54.830002,63.442955,-30.914261,0.006601,0.002394,0.060818,282.208344,14.376379,0.608183,-30.914261,0.060975,0.000000
55.010002,63.416893,-30.958742,0.006610,0.002394,0.060818,282.092438,14.370473,0.608183,-30.958742,0.060975,0.000000
55.190002,63.388969,-30.914261,0.006584,0.002394,0.060818,281.968231,14.364145,0.608183,-30.914261,0.060975,0.000000
55.370003,63.365135,-30.958742,0.006610,0.002394,0.060818,281.862213,14.358745,0.608183,-30.958742,0.060975,0.000000
55.550003,63.339439,-30.869780,0.006597,0.002394,0.060810,281.747894,14.352922,0.608096,-30.869780,0.060975,0.000000
55.730003,63.330132,-30.958742,0.006644,0.002394,0.060810,281.706482,14.350813,0.608096,-30.958742,0.060975,0.000000
55.910004,63.291771,-30.914261,0.006592,0.002394,0.060810,281.535858,14.342120,0.608096,-30.914261,0.060975,0.000000
56.090004,63.270546,-30.958742,0.006605,0.002394,0.060810,281.441437,14.337311,0.608096,-30.958742,0.060975,0.000000
56.270004,63.248573,-30.958742,0.006605,0.002394,0.060810,281.343719,14.332332,0.608096,-30.958742,0.060975,0.000000
56.450005,63.237785,-30.958742,0.006601,0.002394,0.060810,281.295715,14.329887,0.608096,-30.958742,0.060975,0.000000
56.630001,63.205757,-30.914261,0.006601,0.002394,0.060810,281.153259,14.322629,0.608096,-30.914261,0.060975,0.000000
56.810001,63.189003,-31.003223,0.006627,0.002394,0.060810,281.078735,14.318832,0.608096,-31.003223,0.060975,0.000000
56.990002,63.166649,-30.958742,0.006635,0.002394,0.060810,280.979279,14.313767,0.608096,-30.958742,0.060975,0.000000
57.170002,63.132027,-31.003223,0.006605,0.002394,0.060810,280.825287,14.305923,0.608096,-31.003223,0.060975,0.000000
57.350002,63.129799,-31.003223,0.006627,0.002394,0.060810,280.815369,14.305417,0.608096,-31.003223,0.060975,0.000000
57.530003,63.107079,-30.958742,0.006610,0.002394,0.060810,280.714294,14.300268,0.608096,-30.958742,0.060975,0.000000
57.710003,63.082130,-31.003223,0.006597,0.002394,0.060810,280.603333,14.294615,0.608096,-31.003223,0.060975,0.000000
57.890003,63.060524,-30.958742,0.006597,0.002394,0.060810,280.507233,14.289720,0.608096,-30.958742,0.060975,0.000000
58.070004,63.045265,-31.003223,0.006618,0.002394,0.060810,280.439331,14.286261,0.608096,-31.003223,0.060975,0.000000
58.250004,63.017708,-30.958742,0.006588,0.002394,0.060810,280.316772,14.280017,0.608096,-30.958742,0.060975,0.000000
58.430004,63.004303,-31.003223,0.006614,0.002394,0.060810,280.257141,14.276979,0.608096,-31.003223,0.060975,0.000000
58.610004,62.990150,-30.958742,0.006592,0.002394,0.060810,280.194183,14.273772,0.608096,-30.958742,0.060975,0.000000
58.790001,62.978607,-30.958742,0.006579,0.002394,0.060810,280.142822,14.271156,0.608096,-30.958742,0.060975,0.000000
58.970001,62.955894,-30.869780,0.006597,0.002394,0.060810,280.041809,14.266010,0.608096,-30.869780,0.060975,0.000000
59.150002,62.929825,-30.914261,0.006597,0.002394,0.060810,279.925842,14.260102,0.608096,-30.914261,0.060975,0.000000
59.330002,62.907112,-30.914261,0.006601,0.002394,0.060810,279.824799,14.254955,0.608096,-30.914261,0.060975,0.000000
59.510002,62.892960,-31.003223,0.006605,0.002394,0.060810,279.761871,14.251749,0.608096,-31.003223,0.060975,0.000000
59.690002,62.872856,-31.003223,0.006597,0.002394,0.060810,279.672424,14.247193,0.608096,-31.003223,0.060975,0.000000
59.870003,62.867638,-31.003223,0.006584,0.002394,0.060810,279.649231,14.246010,0.608096,-31.003223,0.060975,0.000000
60.050003,62.844925,-30.914261,0.006605,0.002394,0.060810,279.548187,14.240864,0.608096,-30.914261,0.060975,0.000000
60.230003,62.830406,-31.003223,0.006610,0.002394,0.060810,279.483612,14.237574,0.608096,-31.003223,0.060975,0.000000
60.410004,62.808060,-31.003223,0.006627,0.002394,0.060810,279.384216,14.232510,0.608096,-31.003223,0.060975,0.000000
60.590004,62.795403,-31.003223,0.006605,0.002394,0.060810,279.327911,14.229642,0.608096,-31.003223,0.060975,0.000000
60.770004,62.771568,-30.958742,0.006592,0.002394,0.060810,279.221893,14.224241,0.608096,-30.958742,0.060975,0.000000
60.950005,62.766731,-30.958742,0.006614,0.002394,0.060810,279.200378,14.223145,0.608096,-30.958742,0.060975,0.000000
61.130001,62.744759,-30.914261,0.006597,0.002394,0.060810,279.102631,14.218165,0.608096,-30.914261,0.060975,0.000000
61.310001,62.728371,-31.003223,0.006622,0.002394,0.060810,279.029724,14.214452,0.608096,-31.003223,0.060975,0.000000
61.490002,62.712364,-31.003223,0.006605,0.002394,0.060810,278.958527,14.210825,0.608096,-31.003223,0.060975,0.000000
61.670002,62.700073,-31.003223,0.006601,0.002394,0.060810,278.903870,14.208039,0.608096,-31.003223,0.060975,0.000000
61.850002,62.687416,-30.958742,0.006601,0.002394,0.060810,278.847565,14.205172,0.608096,-30.958742,0.060975,0.000000
62.030003,62.664330,-31.003223,0.006592,0.002394,0.060810,278.744873,14.199940,0.608096,-31.003223,0.060975,0.000000
62.210003,62.664696,-30.958742,0.006601,0.002394,0.060810,278.746490,14.200024,0.608096,-30.958742,0.060975,0.000000
62.390003,62.645706,-30.958742,0.006588,0.002394,0.060810,278.662018,14.195721,0.608096,-30.958742,0.060975,0.000000
62.570004,62.633049,-30.958742,0.006592,0.002394,0.060810,278.605713,14.192851,0.608096,-30.958742,0.060975,0.000000
62.750004,62.608467,-31.003223,0.006601,0.002394,0.060810,278.496368,14.187281,0.608096,-31.003223,0.060975,0.000000
62.930004,62.593575,-31.047705,0.006618,0.002394,0.060810,278.430115,14.183907,0.608096,-31.047705,0.060975,0.000000
63.110004,62.576073,-31.003223,0.006605,0.002394,0.060810,278.352264,14.179941,0.608096,-31.003223,0.060975,0.000000
63.290005,62.567139,-30.958742,0.006601,0.002394,0.060810,278.312531,14.177917,0.608096,-30.958742,0.060975,0.000000
63.470001,62.564156,-30.958742,0.006622,0.002394,0.060810,278.299255,14.177240,0.608096,-30.958742,0.060975,0.000000
63.650002,62.546654,-31.003223,0.006601,0.002394,0.060810,278.221405,14.173274,0.608096,-31.003223,0.060975,0.000000
63.830002,62.530273,-31.003223,0.006571,0.002394,0.060810,278.148560,14.169562,0.608096,-31.003223,0.060975,0.000000
64.010002,62.515007,-31.003223,0.006605,0.002394,0.060810,278.080627,14.166102,0.608096,-31.003223,0.060975,0.000000
64.190002,62.490799,-31.047705,0.006605,0.002394,0.060810,277.972961,14.160618,0.608096,-31.047705,0.060975,0.000000
64.370003,62.491547,-31.003223,0.006614,0.002394,0.060810,277.976288,14.160787,0.608096,-31.003223,0.060975,0.000000
64.550003,62.477394,-30.958742,0.006605,0.002394,0.060810,277.913330,14.157580,0.608096,-30.958742,0.060975,0.000000
64.730003,62.466225,-31.092184,0.006605,0.002394,0.060810,277.863647,14.155049,0.608096,-31.092184,0.060975,0.000000
64.910004,62.439041,-31.003223,0.006610,0.002394,0.060810,277.742737,14.148890,0.608096,-31.003223,0.060975,0.000000
65.090004,62.438293,-31.003223,0.006601,0.002394,0.060810,277.739410,14.148720,0.608096,-31.003223,0.060975,0.000000
65.270004,62.418190,-30.958742,0.006614,0.002394,0.060810,277.649963,14.144164,0.608096,-30.958742,0.060975,0.000000
65.450005,62.409996,-31.003223,0.006605,0.002394,0.060810,277.613525,14.142307,0.608096,-31.003223,0.060975,0.000000
65.630005,62.390633,-31.003223,0.006618,0.002394,0.060810,277.527405,14.137919,0.608096,-31.003223,0.060975,0.000000
65.810005,62.379837,-31.003223,0.006614,0.002394,0.060810,277.479370,14.135473,0.608096,-31.003223,0.060975,0.000000
65.990005,62.373878,-31.003223,0.006597,0.002394,0.060810,277.452881,14.134123,0.608096,-31.003223,0.060975,0.000000
66.170006,62.360100,-31.003223,0.006610,0.002394,0.060810,277.391571,14.131001,0.608096,-31.003223,0.060975,0.000000
66.350006,62.352280,-31.092184,0.006614,0.002394,0.060810,277.356781,14.129228,0.608096,-31.092184,0.060975,0.000000
66.530006,62.323235,-30.958742,0.006614,0.002394,0.060810,277.227600,14.122647,0.608096,-30.958742,0.060975,0.000000
66.710007,62.316902,-31.047705,0.006618,0.002394,0.060810,277.199432,14.121212,0.608096,-31.047705,0.060975,0.000000
66.889999,62.302383,-31.003223,0.006601,0.002394,0.060810,277.134857,14.117922,0.608096,-31.003223,0.060975,0.000000
67.070000,62.294563,-31.047705,0.006601,0.002394,0.060810,277.100067,14.116150,0.608096,-31.047705,0.060975,0.000000
67.250000,62.290833,-31.003223,0.006592,0.002394,0.060810,277.083466,14.115305,0.608096,-31.003223,0.060975,0.000000
67.430000,62.279289,-31.003223,0.006605,0.002394,0.060810,277.032104,14.112688,0.608096,-31.003223,0.060975,0.000000
67.610001,62.266632,-31.003223,0.006610,0.002394,0.060810,276.975800,14.109820,0.608096,-31.003223,0.060975,0.000000
67.790001,62.246155,-31.047705,0.006601,0.002394,0.060810,276.884735,14.105181,0.608096,-31.047705,0.060975,0.000000
67.970001,62.234612,-31.092184,0.006610,0.002394,0.060810,276.833374,14.102565,0.608096,-31.092184,0.060975,0.000000
68.150002,62.221947,-31.092184,0.006601,0.002394,0.060810,276.777039,14.099694,0.608096,-31.092184,0.060975,0.000000
68.330002,62.217476,-31.092184,0.006588,0.002394,0.060810,276.757141,14.098681,0.608096,-31.092184,0.060975,0.000000
68.510002,62.199608,-31.003223,0.006605,0.002394,0.060810,276.677673,14.094633,0.608096,-31.003223,0.060975,0.000000
68.690002,62.193649,-30.958742,0.006614,0.002394,0.060810,276.651184,14.093282,0.608096,-30.958742,0.060975,0.000000
68.870003,62.183594,-31.047705,0.006614,0.002394,0.060810,276.606445,14.091003,0.608096,-31.047705,0.060975,0.000000
69.050003,62.165344,-31.047705,0.006592,0.002394,0.060810,276.525269,14.086868,0.608096,-31.047705,0.060975,0.000000
69.230003,62.148216,-31.092184,0.006605,0.002394,0.060810,276.449066,14.082987,0.608096,-31.092184,0.060975,0.000000
69.410004,62.140022,-31.003223,0.006601,0.002394,0.060810,276.412628,14.081131,0.608096,-31.003223,0.060975,0.000000
69.590004,62.129227,-31.003223,0.006618,0.002394,0.060810,276.364594,14.078684,0.608096,-31.003223,0.060975,0.000000
69.770004,62.131462,-31.047705,0.006601,0.002394,0.060810,276.374542,14.079190,0.608096,-31.047705,0.060975,0.000000
69.950005,62.103905,-31.047705,0.006592,0.002394,0.060810,276.251953,14.072946,0.608096,-31.047705,0.060975,0.000000
70.130005,62.106514,-31.092184,0.006622,0.002394,0.060810,276.263580,14.073538,0.608096,-31.092184,0.060975,0.000000
70.310005,62.091614,-31.092184,0.006601,0.002394,0.060801,276.197296,14.070161,0.608009,-31.092184,0.060975,0.000000
70.490005,62.080818,-31.047705,0.006618,0.002394,0.060801,276.149261,14.067715,0.608009,-31.047705,0.060975,0.000000
70.670006,62.061829,-31.047705,0.006588,0.002394,0.060801,276.064789,14.063412,0.608009,-31.047705,0.060975,0.000000
70.850006,62.058846,-31.047705,0.006601,0.002394,0.060801,276.051544,14.062736,0.608009,-31.047705,0.060975,0.000000
71.030006,62.041344,-31.047705,0.006605,0.002394,0.060801,275.973694,14.058770,0.608009,-31.047705,0.060975,0.000000
71.210007,62.034271,-31.003223,0.006605,0.002394,0.060801,275.942230,14.057166,0.608009,-31.003223,0.060975,0.000000
71.390007,62.034271,-31.047705,0.006584,0.002394,0.060801,275.942230,14.057166,0.608009,-31.047705,0.060975,0.000000
71.570000,62.017891,-31.003223,0.006618,0.002394,0.060801,275.869354,14.053455,0.608009,-31.003223,0.060975,0.000000
71.750000,62.001129,-31.092184,0.006605,0.002394,0.060801,275.794800,14.049657,0.608009,-31.092184,0.060975,0.000000
71.930000,61.995918,-31.047705,0.006601,0.002394,0.060801,275.771606,14.048475,0.608009,-31.047705,0.060975,0.000000
72.110001,61.988098,-31.092184,0.006601,0.002394,0.060801,275.736847,14.046703,0.608009,-31.092184,0.060975,0.000000
72.290001,61.975433,-30.958742,0.006605,0.002394,0.060801,275.680481,14.043834,0.608009,-30.958742,0.060975,0.000000
72.470001,61.971710,-31.092184,0.006592,0.002394,0.060801,275.663940,14.042991,0.608009,-31.092184,0.060975,0.000000
72.650002,61.960167,-31.047705,0.006610,0.002394,0.060801,275.612579,14.040374,0.608009,-31.047705,0.060975,0.000000
72.830002,61.961288,-31.047705,0.006610,0.002394,0.060801,275.617584,14.040628,0.608009,-31.047705,0.060975,0.000000
73.010002,61.931122,-31.047705,0.006614,0.002394,0.060801,275.483398,14.033793,0.608009,-31.047705,0.060975,0.000000
73.190002,61.942299,-31.003223,0.006618,0.002394,0.060801,275.533112,14.036326,0.608009,-31.003223,0.060975,0.000000
73.370003,61.914368,-31.092184,0.006610,0.002394,0.060801,275.408875,14.029997,0.608009,-31.092184,0.060975,0.000000
73.550003,61.912506,-31.136665,0.006605,0.002394,0.060801,275.400574,14.029574,0.608009,-31.136665,0.060975,0.000000
73.730003,61.903938,-31.047705,0.006618,0.002394,0.060801,275.362457,14.027633,0.608009,-31.047705,0.060975,0.000000
73.910004,61.903938,-31.003223,0.006597,0.002394,0.060801,275.362457,14.027633,0.608009,-31.003223,0.060975,0.000000
74.090004,61.903572,-31.136665,0.006597,0.002394,0.060801,275.360840,14.027550,0.608009,-31.136665,0.060975,0.000000
74.270004,61.870056,-31.092184,0.006610,0.002394,0.060801,275.211761,14.019955,0.608009,-31.092184,0.060975,0.000000
74.450005,61.879738,-31.092184,0.006584,0.002394,0.060801,275.254822,14.022149,0.608009,-31.092184,0.060975,0.000000
74.630005,61.862984,-31.047705,0.006605,0.002394,0.060801,275.180298,14.018353,0.608009,-31.047705,0.060975,0.000000
74.810005,61.849205,-31.047705,0.006605,0.002394,0.060801,275.119019,14.015230,0.608009,-31.047705,0.060975,0.000000
74.990005,61.859253,-31.092184,0.006610,0.002394,0.060801,275.163696,14.017508,0.608009,-31.092184,0.060975,0.000000
75.170006,61.855904,-31.047705,0.006601,0.002394,0.060801,275.148804,14.016748,0.608009,-31.047705,0.060975,0.000000
75.350006,61.834305,-31.136665,0.006614,0.002394,0.060801,275.052734,14.011853,0.608009,-31.136665,0.060975,0.000000
75.530006,61.829842,-31.092184,0.006592,0.002394,0.060801,275.032867,14.010842,0.608009,-31.092184,0.060975,0.000000
75.710007,61.819038,-31.092184,0.006597,0.002394,0.060801,274.984802,14.008394,0.608009,-31.092184,0.060975,0.000000
75.890007,61.811966,-31.136665,0.006610,0.002394,0.060801,274.953369,14.006792,0.608009,-31.136665,0.060975,0.000000
75.900002,61.805260,-31.136665,0.006601,0.002394,0.060801,274.923523,14.005273,0.608009,-31.136665,0.060975,0.000000