File: Data/I-18 Lathed test 4_10242023_165714.csv
Time (sec),S:Load (lbs),S:HL1 (DIM),S:LVDT (in),S:Position (in),Ch:Position (mm),Ch:Load (N),Ch:Stress (MPa),Ch:Strain (mm/mm),Ch:HL1 (DIM),Set Point (),Cycles ()
0.110000,-0.052505,-23.886271,0.010102,-0.006524,-0.165718,-0.233556,-0.011898,-1.657182,-23.886271,-0.165536,0.000000
0.290000,-0.050270,-23.841789,0.010098,-0.006524,-0.165718,-0.223612,-0.011391,-1.657182,-23.841789,-0.165536,0.000000
0.470000,-0.067406,-23.841789,0.010098,-0.006468,-0.164287,-0.299836,-0.015274,-1.642871,-23.841789,-0.163836,0.000000
0.650000,-0.063675,-23.886271,0.010089,-0.006375,-0.161937,-0.283240,-0.014429,-1.619371,-23.886271,-0.160836,0.000000
0.830000,-0.059586,-23.930752,0.010197,-0.006261,-0.159023,-0.265050,-0.013502,-1.590231,-23.930752,-0.157852,0.000000
1.010000,-0.053993,-23.930752,0.010313,-0.006145,-0.156083,-0.240174,-0.012235,-1.560830,-23.930752,-0.154852,0.000000
1.190000,-0.062561,-23.886271,0.010455,-0.006023,-0.152979,-0.278285,-0.014177,-1.529786,-23.886271,-0.151851,0.000000
1.370000,-0.066284,-23.886271,0.010568,-0.005907,-0.150030,-0.294847,-0.015020,-1.500298,-23.886271,-0.148850,0.000000
1.550000,-0.072990,-23.886271,0.010710,-0.005788,-0.147003,-0.324678,-0.016540,-1.470034,-23.886271,-0.145850,0.000000
1.730000,-0.064796,-23.930752,0.010831,-0.005667,-0.143951,-0.288229,-0.014683,-1.439505,-23.930752,-0.142849,0.000000
1.910000,-0.067032,-23.930752,0.010930,-0.005548,-0.140924,-0.298173,-0.015190,-1.409241,-23.930752,-0.139849,0.000000
2.090000,-0.080063,-23.930752,0.011046,-0.005433,-0.138010,-0.356137,-0.018143,-1.380101,-23.930752,-0.136848,0.000000
2.270000,-0.071869,-23.886271,0.011201,-0.005310,-0.134871,-0.319689,-0.016286,-1.348709,-23.886271,-0.133848,0.000000
2.450000,-0.052879,-23.930752,0.011313,-0.005189,-0.131809,-0.235219,-0.011983,-1.318093,-23.930752,-0.130864,0.000000
2.630000,-0.066658,-23.886271,0.011434,-0.005073,-0.128852,-0.296510,-0.015105,-1.288522,-23.886271,-0.127864,0.000000
2.810000,-0.061073,-23.886271,0.011559,-0.004963,-0.126051,-0.271668,-0.013839,-1.260510,-23.886271,-0.124863,0.000000
2.990000,-0.055489,-23.930752,0.011697,-0.004845,-0.123051,-0.246826,-0.012574,-1.230507,-23.930752,-0.121862,0.000000
3.170000,-0.018997,-23.930752,0.011809,-0.004728,-0.120084,-0.084504,-0.004305,-1.200845,-23.930752,-0.118862,0.000000
3.350000,-0.049530,-23.930752,0.011943,-0.004610,-0.117101,-0.220321,-0.011224,-1.171012,-23.930752,-0.115861,0.000000
3.530000,-0.047668,-23.930752,0.012072,-0.004493,-0.114127,-0.212040,-0.010802,-1.141267,-23.930752,-0.112861,0.000000
3.710000,-0.047295,-23.975233,0.012167,-0.004366,-0.110901,-0.210377,-0.010717,-1.109008,-23.975233,-0.109860,0.000000
3.890000,-0.054367,-23.930752,0.012301,-0.004249,-0.107918,-0.241837,-0.012320,-1.079176,-23.930752,-0.106859,0.000000
4.070000,-0.057724,-23.930752,0.012426,-0.004130,-0.104891,-0.256769,-0.013080,-1.048908,-23.930752,-0.103859,0.000000
4.250000,-0.078201,-24.019714,0.012555,-0.004017,-0.102020,-0.347857,-0.017721,-1.020203,-24.019714,-0.100875,0.000000
4.430000,-0.071869,-23.930752,0.012680,-0.003895,-0.098942,-0.319689,-0.016286,-0.989417,-23.930752,-0.097875,0.000000
4.610000,-0.098679,-23.930752,0.012801,-0.003777,-0.095932,-0.438944,-0.022361,-0.959323,-23.930752,-0.094874,0.000000
4.790000,-0.067406,-23.975233,0.012909,-0.003655,-0.092845,-0.299836,-0.015274,-0.928450,-23.975233,-0.091874,0.000000
4.970000,-0.052879,-24.019714,0.013055,-0.003541,-0.089931,-0.235219,-0.011983,-0.899314,-24.019714,-0.088873,0.000000
5.150000,-0.046547,-23.975233,0.013180,-0.003425,-0.087000,-0.207051,-0.010548,-0.870000,-23.975233,-0.085872,0.000000
5.330000,-0.041710,-23.975233,0.013297,-0.003312,-0.084121,-0.185535,-0.009452,-0.841208,-23.975233,-0.082872,0.000000
5.510000,-0.034630,-24.019714,0.013439,-0.003194,-0.081138,-0.154041,-0.007847,-0.811375,-24.019714,-0.079871,0.000000
5.690000,-0.020111,-23.975233,0.013542,-0.003078,-0.078172,-0.089459,-0.004557,-0.781717,-23.975233,-0.076871,0.000000
5.870000,-0.027931,-23.975233,0.013676,-0.002956,-0.075093,-0.124244,-0.006329,-0.750931,-23.975233,-0.073888,0.000000
6.050000,-0.048782,-24.019714,0.013814,-0.002834,-0.071980,-0.216995,-0.011054,-0.719796,-24.019714,-0.070887,0.000000
6.230000,-0.049904,-24.019714,0.013948,-0.002712,-0.068892,-0.221983,-0.011308,-0.688923,-24.019714,-0.067886,0.000000
6.410000,-0.048782,-24.019714,0.014064,-0.002593,-0.065874,-0.216995,-0.011054,-0.658742,-24.019714,-0.064886,0.000000
6.590000,-0.064796,-24.064194,0.014172,-0.002476,-0.062882,-0.288229,-0.014683,-0.628822,-24.064194,-0.061885,0.000000
6.770000,-0.077454,-23.975233,0.014288,-0.002363,-0.060012,-0.344531,-0.017551,-0.600118,-23.975233,-0.058885,0.000000
6.950000,-0.095703,-24.064194,0.014426,-0.002243,-0.056968,-0.425709,-0.021687,-0.569680,-24.064194,-0.055884,0.000000
7.130000,-0.093468,-24.064194,0.014569,-0.002125,-0.053976,-0.415765,-0.021180,-0.539760,-24.064194,-0.052883,0.000000
7.310000,-0.060699,-24.019714,0.014685,-0.002004,-0.050897,-0.270005,-0.013755,-0.508974,-24.019714,-0.049883,0.000000
7.490000,-0.048409,-24.108675,0.014793,-0.001895,-0.048131,-0.215332,-0.010970,-0.481310,-24.108675,-0.046899,0.000000
7.670001,-0.040962,-24.019714,0.014914,-0.001779,-0.045191,-0.182209,-0.009282,-0.451909,-24.019714,-0.043899,0.000000
7.850000,-0.026070,-24.019714,0.015039,-0.001660,-0.042156,-0.115964,-0.005907,-0.421558,-24.019714,-0.040898,0.000000
8.030001,-0.026817,-24.064194,0.015164,-0.001542,-0.039155,-0.119289,-0.006077,-0.391551,-24.064194,-0.037898,0.000000
8.210000,-0.032768,-24.064194,0.015297,-0.001422,-0.036128,-0.145760,-0.007425,-0.361283,-24.064194,-0.034897,0.000000
8.390000,-0.026070,-24.019714,0.015418,-0.001300,-0.033033,-0.115964,-0.005907,-0.330327,-24.019714,-0.031896,0.000000
8.570001,-0.038361,-24.064194,0.015565,-0.001183,-0.030058,-0.170636,-0.008693,-0.300577,-24.064194,-0.028896,0.000000
8.750000,-0.045059,-24.064194,0.015681,-0.001063,-0.027005,-0.200433,-0.010211,-0.270052,-24.064194,-0.025895,0.000000
8.930000,-0.063309,-24.108675,0.015797,-0.000947,-0.024048,-0.281611,-0.014346,-0.240481,-24.108675,-0.022895,0.000000
9.110001,-0.071495,-24.064194,0.015914,-0.000830,-0.021082,-0.318026,-0.016201,-0.210822,-24.064194,-0.019894,0.000000
9.290001,-0.062187,-24.153156,0.016030,-0.000710,-0.018038,-0.276622,-0.014092,-0.180381,-24.153156,-0.016911,0.000000
9.470000,-0.060699,-24.153156,0.016168,-0.000593,-0.015064,-0.270005,-0.013755,-0.150635,-24.153156,-0.013910,0.000000
9.650001,-0.033516,-24.019714,0.016276,-0.000476,-0.012080,-0.149086,-0.007595,-0.120802,-24.019714,-0.010910,0.000000
9.830001,0.027924,-24.064194,0.016410,-0.000359,-0.009114,0.124210,0.006328,-0.091144,-24.064194,-0.007909,0.000000
10.010000,0.167564,-24.108675,0.016548,-0.000231,-0.005880,0.745364,0.037971,-0.058798,-24.108675,-0.004908,0.000000
10.190001,0.483711,-24.108675,0.016664,-0.000115,-0.002922,2.151655,0.109611,-0.029223,-24.108675,-0.001908,0.000000
10.370001,0.608826,-24.108675,0.016690,-0.000000,-0.000000,2.708192,0.137962,-0.000000,-24.108675,0.000234,0.000000
10.550000,0.599144,-24.108675,0.016707,-0.000000,-0.000000,2.665126,0.135768,-0.000000,-24.108675,0.000234,0.000000
10.730000,0.592072,-24.153156,0.016699,-0.000000,-0.000000,2.633666,0.134165,-0.000000,-24.153156,0.000234,0.000000
10.910001,0.731712,-24.153156,0.016711,-0.000000,-0.000000,3.254819,0.165808,-0.000000,-24.153156,0.000434,0.000000
11.090000,0.688141,-24.197638,0.016694,-0.000000,-0.000000,3.061003,0.155935,-0.000000,-24.197638,0.000737,0.000000
11.270000,0.694099,-24.108675,0.016720,0.000001,0.000017,3.087508,0.157285,0.000174,-24.108675,0.001032,0.000000
11.450001,0.773415,-24.108675,0.016711,0.000022,0.000564,3.440320,0.175258,0.005636,-24.108675,0.001335,0.000000
11.630000,0.931671,-24.153156,0.016724,0.000033,0.000850,4.144280,0.211120,0.008497,-24.153156,0.001639,0.000000
11.810000,1.000191,-24.153156,0.016746,0.000041,0.001049,4.449070,0.226646,0.010492,-24.153156,0.001934,0.000000
11.990001,1.094772,-24.197638,0.016746,0.000052,0.001327,4.869791,0.248079,0.013270,-24.197638,0.002237,0.000000
12.170001,1.131264,-24.153156,0.016746,0.000058,0.001466,5.032113,0.256348,0.014655,-24.153156,0.002532,0.000000
12.350000,1.375542,-24.197638,0.016772,0.000082,0.002090,6.118715,0.311702,0.020900,-24.197638,0.002836,0.000000
12.530001,1.478317,-24.197638,0.016802,0.000092,0.002341,6.575883,0.334991,0.023413,-24.197638,0.003130,0.000000
12.710001,1.599709,-24.153156,0.016793,0.000103,0.002619,7.115859,0.362499,0.026191,-24.153156,0.003434,0.000000
12.890000,1.714775,-24.197638,0.016811,0.000114,0.002897,7.627700,0.388574,0.028966,-24.197638,0.003738,0.000000
13.070001,1.854782,-24.197638,0.016811,0.000126,0.003191,8.250483,0.420300,0.031914,-24.197638,0.004032,0.000000
13.250001,2.000381,-24.153156,0.016811,0.000137,0.003486,8.898141,0.453293,0.034863,-24.153156,0.004336,0.000000
13.430000,2.191406,-24.197638,0.016841,0.000149,0.003790,9.747862,0.496580,0.037898,-24.197638,0.004631,0.000000
13.610001,2.379829,-24.153156,0.016854,0.000161,0.004085,10.586010,0.539277,0.040847,-24.153156,0.004934,0.000000
13.790001,2.517235,-24.242119,0.016858,0.000171,0.004353,11.197220,0.570414,0.043534,-24.242119,0.005238,0.000000
13.970000,2.628944,-24.197638,0.016867,0.000178,0.004527,11.694129,0.595727,0.045267,-24.197638,0.005533,0.000000
14.150001,2.877693,-24.197638,0.016867,0.000192,0.004865,12.800618,0.652095,0.048651,-24.197638,0.005836,0.000000
14.330001,3.072815,-24.108675,0.016875,0.000204,0.005177,13.668564,0.696310,0.051774,-24.108675,0.006131,0.000000
14.510000,3.308525,-24.242119,0.016914,0.000219,0.005568,14.717054,0.749722,0.055676,-24.242119,0.006435,0.000000
14.690001,3.445930,-24.242119,0.016901,0.000226,0.005732,15.328264,0.780859,0.057322,-24.242119,0.006738,0.000000
14.870001,3.643288,-24.286600,0.016910,0.000240,0.006105,16.206152,0.825581,0.061050,-24.286600,0.007033,0.000000
15.050001,3.909904,-24.286600,0.016931,0.000251,0.006365,17.392124,0.885997,0.063654,-24.286600,0.007337,0.000000
15.230000,4.178391,-24.197638,0.016944,0.000267,0.006782,18.586409,0.946837,0.067818,-24.197638,0.007631,0.000000
15.410001,4.468842,-24.242119,0.016957,0.000280,0.007120,19.878401,1.012654,0.071198,-24.242119,0.007935,0.000000
15.590001,4.608109,-24.286600,0.016962,0.000287,0.007285,20.497890,1.044212,0.072848,-24.286600,0.008239,0.000000
15.770000,4.759293,-24.242119,0.016970,0.000297,0.007536,21.170391,1.078471,0.075361,-24.242119,0.008533,0.000000
15.950001,5.032608,-24.242119,0.016970,0.000309,0.007848,22.386158,1.140405,0.078484,-24.242119,0.008837,0.000000
16.130001,5.365143,-24.197638,0.016992,0.000322,0.008169,23.865347,1.215759,0.081693,-24.197638,0.009132,0.000000
16.310001,5.759109,-24.286600,0.016992,0.000339,0.008620,25.617798,1.305033,0.086201,-24.286600,0.009435,0.000000
16.490002,6.049561,-24.331079,0.017013,0.000351,0.008915,26.909790,1.370850,0.089149,-24.331079,0.009739,0.000000
16.670000,6.227554,-24.242119,0.017009,0.000362,0.009184,27.701546,1.411184,0.091840,-24.242119,0.010034,0.000000
16.850000,6.500877,-24.242119,0.017009,0.000372,0.009444,28.917347,1.473120,0.094441,-24.242119,0.010337,0.000000
17.030001,6.736961,-24.242119,0.017030,0.000383,0.009722,29.967501,1.526617,0.097215,-24.242119,0.010632,0.000000
17.210001,7.117523,-24.286600,0.017056,0.000398,0.010120,31.660324,1.612854,0.101204,-24.286600,0.010936,0.000000
17.390001,7.338341,-24.286600,0.017056,0.000405,0.010294,32.642570,1.662892,0.102938,-24.286600,0.011239,0.000000
17.570002,7.586342,-24.242119,0.017074,0.000416,0.010563,33.745735,1.719090,0.105629,-24.242119,0.011534,0.000000
17.750000,7.776253,-24.197638,0.017069,0.000424,0.010762,34.590500,1.762124,0.107623,-24.197638,0.011838,0.000000
17.930000,8.247299,-24.242119,0.017087,0.000440,0.011178,36.685818,1.868865,0.111783,-24.242119,0.012132,0.000000
18.110001,8.561211,-24.286600,0.017091,0.000456,0.011595,38.082169,1.939998,0.115946,-24.286600,0.012436,0.000000
18.290001,9.056839,-24.286600,0.017117,0.000471,0.011968,40.286831,2.052309,0.119678,-24.286600,0.012740,0.000000
18.470001,9.308563,-24.331079,0.017121,0.000482,0.012237,41.406559,2.109351,0.122366,-24.331079,0.013034,0.000000
18.650002,9.421021,-24.197638,0.017138,0.000490,0.012436,41.906792,2.134834,0.124360,-24.197638,0.013338,0.000000
18.830002,9.723389,-24.286600,0.017143,0.000502,0.012740,43.251793,2.203351,0.127396,-24.286600,0.013633,0.000000
19.010000,10.039528,-24.375561,0.017138,0.000511,0.012991,44.658051,2.274989,0.129909,-24.375561,0.013936,0.000000
19.190001,10.159065,-24.331079,0.017147,0.000519,0.013182,45.189777,2.302077,0.131817,-24.331079,0.014240,0.000000
19.370001,10.638306,-24.375561,0.017160,0.000535,0.013589,47.321548,2.410674,0.135893,-24.375561,0.014535,0.000000
19.550001,10.911255,-24.286600,0.017160,0.000546,0.013875,48.535686,2.472526,0.138754,-24.286600,0.014838,0.000000
19.730001,11.270226,-24.286600,0.017199,0.000556,0.014110,50.132465,2.553869,0.141097,-24.286600,0.015133,0.000000
19.910002,11.578918,-24.331079,0.017199,0.000567,0.014405,51.505600,2.623820,0.144046,-24.331079,0.015437,0.000000
20.090000,11.720795,-24.331079,0.017212,0.000574,0.014578,52.136700,2.655970,0.145779,-24.331079,0.015732,0.000000
20.270000,12.585068,-24.375561,0.017207,0.000600,0.015246,55.981178,2.851817,0.152459,-24.375561,0.016035,0.000000
20.450001,12.884460,-24.331079,0.017229,0.000613,0.015575,57.312943,2.919661,0.155752,-24.331079,0.016339,0.000000
20.630001,12.959305,-24.331079,0.017225,0.000619,0.015732,57.645866,2.936620,0.157315,-24.331079,0.016633,0.000000
20.810001,13.172676,-24.375561,0.017255,0.000631,0.016026,58.594990,2.984971,0.160264,-24.375561,0.016937,0.000000
20.990002,13.424400,-24.375561,0.017246,0.000639,0.016243,59.714714,3.042013,0.162433,-24.375561,0.017232,0.000000
21.170000,13.660110,-24.375561,0.017272,0.000649,0.016486,60.763206,3.095425,0.164859,-24.375561,0.017535,0.000000
21.350000,14.287186,-24.331079,0.017281,0.000666,0.016911,63.552574,3.237523,0.169109,-24.331079,0.017839,0.000000
21.530001,14.401131,-24.375561,0.017298,0.000674,0.017119,64.059425,3.263343,0.171191,-24.375561,0.018134,0.000000
21.710001,14.696419,-24.420042,0.017311,0.000686,0.017431,65.372932,3.330256,0.174313,-24.420042,0.018437,0.000000
21.890001,15.055389,-24.420042,0.017298,0.000697,0.017709,66.969719,3.411600,0.177088,-24.420042,0.018732,0.000000
22.070002,15.474678,-24.420042,0.017319,0.000711,0.018047,68.834808,3.506612,0.180468,-24.420042,0.019035,0.000000
22.250002,15.960251,-24.375561,0.017324,0.000728,0.018481,70.994743,3.616644,0.184805,-24.375561,0.019339,0.000000
22.430000,16.241394,-24.420042,0.017337,0.000740,0.018793,72.245331,3.680352,0.187928,-24.420042,0.019634,0.000000
22.610001,16.320335,-24.420042,0.017332,0.000747,0.018966,72.596481,3.698241,0.189661,-24.420042,0.019937,0.000000
22.790001,16.528870,-24.420042,0.017354,0.000759,0.019270,73.524086,3.745495,0.192697,-24.420042,0.020232,0.000000
22.970001,16.824905,-24.375561,0.017371,0.000768,0.019513,74.840919,3.812578,0.195126,-24.375561,0.020536,0.000000
23.150002,17.113121,-24.420042,0.017375,0.000780,0.019816,76.122963,3.877889,0.198162,-24.420042,0.020839,0.000000
23.330002,17.536507,-24.420042,0.017393,0.000795,0.020180,78.006279,3.973829,0.201803,-24.420042,0.021134,0.000000
23.510000,17.732002,-24.420042,0.017388,0.000803,0.020397,78.875885,4.018129,0.203972,-24.420042,0.021438,0.000000
23.690001,17.816902,-24.464523,0.017397,0.000812,0.020631,79.253540,4.037368,0.206311,-24.464523,0.021732,0.000000
23.870001,18.377693,-24.375561,0.017401,0.000826,0.020987,81.748062,4.164445,0.209869,-24.375561,0.022036,0.000000
24.050001,18.636124,-24.420042,0.017427,0.000840,0.021325,82.897621,4.223006,0.213249,-24.420042,0.022340,0.000000
24.230001,19.304527,-24.375561,0.017453,0.000858,0.021802,85.870827,4.374469,0.218021,-24.375561,0.022634,0.000000
24.410002,19.546570,-24.375561,0.017470,0.000870,0.022106,86.947487,4.429316,0.221057,-24.375561,0.022938,0.000000
24.590002,19.418106,-24.420042,0.017470,0.000875,0.022235,86.376053,4.400206,0.222355,-24.420042,0.023233,0.000000
24.770000,19.697754,-24.464523,0.017470,0.000887,0.022539,87.619987,4.463575,0.225390,-24.464523,0.023536,0.000000
24.950001,19.852287,-24.420042,0.017475,0.000897,0.022791,88.307381,4.498593,0.227907,-24.420042,0.023840,0.000000
25.130001,20.249611,-24.464523,0.017479,0.000910,0.023112,90.074768,4.588627,0.231117,-24.464523,0.024135,0.000000
25.310001,20.596291,-24.420042,0.017513,0.000923,0.023450,91.616875,4.667186,0.234497,-24.420042,0.024438,0.000000
25.490002,20.697945,-24.464523,0.017488,0.000931,0.023640,92.069054,4.690221,0.236405,-24.464523,0.024733,0.000000
25.670002,21.042023,-24.464523,0.017518,0.000941,0.023901,93.599594,4.768190,0.239009,-24.464523,0.025037,0.000000
25.850000,21.537277,-24.464523,0.017518,0.000956,0.024282,95.802597,4.880416,0.242824,-24.464523,0.025340,0.000000
26.030001,21.574883,-24.420042,0.017544,0.000966,0.024525,95.969872,4.888938,0.245250,-24.420042,0.025635,0.000000
26.210001,21.908157,-24.464523,0.017565,0.000979,0.024863,97.452354,4.964459,0.248634,-24.464523,0.025939,0.000000
26.390001,22.473793,-24.509005,0.017561,0.000993,0.025219,99.968422,5.092635,0.252188,-24.509005,0.026233,0.000000
26.570002,22.643593,-24.464523,0.017587,0.001006,0.025548,100.723732,5.131112,0.255484,-24.464523,0.026537,0.000000
26.750002,22.710991,-24.509005,0.017587,0.001014,0.025757,101.023537,5.146384,0.257566,-24.509005,0.026841,0.000000
26.930002,22.977242,-24.464523,0.017608,0.001026,0.026060,102.207878,5.206717,0.260601,-24.464523,0.027135,0.000000
27.110001,23.493347,-24.509005,0.017617,0.001042,0.026468,104.503624,5.323669,0.264678,-24.509005,0.027439,0.000000
27.290001,23.795341,-24.597965,0.017600,0.001054,0.026771,105.846962,5.392101,0.267713,-24.597965,0.027734,0.000000
27.470001,23.749542,-24.509005,0.017621,0.001059,0.026901,105.643242,5.381723,0.269011,-24.509005,0.028037,0.000000
27.650002,24.089890,-24.464523,0.017634,0.001074,0.027291,107.157181,5.458847,0.272914,-24.464523,0.028341,0.000000
27.830002,24.407150,-24.464523,0.017664,0.001085,0.027569,108.568428,5.530739,0.275692,-24.464523,0.028636,0.000000
28.010002,24.191177,-24.509005,0.017664,0.001086,0.027578,107.607735,5.481799,0.275779,-24.509005,0.028939,0.000000
28.190001,25.037949,-24.509005,0.017664,0.001107,0.028115,111.374359,5.673680,0.281153,-24.509005,0.029234,0.000000
28.370001,25.535065,-24.553486,0.017673,0.001122,0.028506,113.585640,5.786328,0.285056,-24.553486,0.029538,0.000000
28.550001,25.893288,-24.509005,0.017677,0.001136,0.028861,115.179092,5.867503,0.288613,-24.509005,0.029833,0.000000
28.730001,25.847862,-24.509005,0.017690,0.001147,0.029121,114.977036,5.857209,0.291214,-24.509005,0.030136,0.000000
28.910002,26.136818,-24.509005,0.017720,0.001157,0.029390,116.262375,5.922688,0.293901,-24.509005,0.030440,0.000000
29.090002,26.649948,-24.597965,0.017720,0.001171,0.029746,118.544891,6.038965,0.297459,-24.597965,0.030734,0.000000
29.270000,26.668198,-24.597965,0.017725,0.001176,0.029876,118.626068,6.043100,0.298757,-24.597965,0.031038,0.000000
29.450001,27.221169,-24.509005,0.017729,0.001193,0.030301,121.085808,6.168405,0.303007,-24.509005,0.031333,0.000000
29.630001,27.293785,-24.509005,0.017742,0.001202,0.030526,121.408821,6.184860,0.305263,-24.509005,0.031636,0.000000
29.810001,27.492630,-24.553486,0.017742,0.001212,0.030795,122.293327,6.229919,0.307950,-24.553486,0.031940,0.000000
29.990002,28.898338,-24.597965,0.017772,0.001238,0.031446,128.546234,6.548457,0.314457,-24.597965,0.032235,0.000000
30.170002,28.858490,-24.553486,0.017768,0.001247,0.031671,128.368973,6.539427,0.316709,-24.553486,0.032538,0.000000
30.350002,28.970947,-24.553486,0.017789,0.001259,0.031974,128.869217,6.564910,0.319744,-24.553486,0.032833,0.000000
30.530001,29.227882,-24.553486,0.017789,0.001269,0.032244,130.012115,6.623133,0.322435,-24.553486,0.033137,0.000000
30.710001,29.452797,-24.553486,0.017811,0.001278,0.032469,131.012589,6.674099,0.324687,-24.553486,0.033440,0.000000
30.890001,29.979706,-24.597965,0.017807,0.001294,0.032868,133.356384,6.793499,0.328676,-24.597965,0.033735,0.000000
31.070002,30.391174,-24.553486,0.017820,0.001305,0.033137,135.186691,6.886738,0.331368,-24.553486,0.034039,0.000000
31.250002,30.573639,-24.597965,0.017841,0.001316,0.033414,135.998337,6.928086,0.334142,-24.597965,0.034334,0.000000
31.430002,30.699127,-24.597965,0.017841,0.001322,0.033588,136.556534,6.956522,0.335875,-24.597965,0.034637,0.000000
31.610001,30.879730,-24.597965,0.017858,0.001332,0.033822,137.359894,6.997447,0.338218,-24.597965,0.034941,0.000000
31.790001,32.084351,-24.642447,0.017858,0.001355,0.034429,142.718323,7.270418,0.344289,-24.642447,0.035235,0.000000
31.970001,32.431778,-24.597965,0.017888,0.001365,0.034672,144.263748,7.349146,0.346715,-24.597965,0.035539,0.000000
32.150002,32.619827,-24.597965,0.017867,0.001375,0.034932,145.100235,7.391759,0.349319,-24.597965,0.035834,0.000000
32.330002,33.183228,-24.597965,0.017880,0.001390,0.035296,147.606369,7.519427,0.352960,-24.597965,0.036137,0.000000
32.510002,33.457664,-24.642447,0.017910,0.001400,0.035556,148.827118,7.581615,0.355561,-24.642447,0.036441,0.000000
32.690002,33.827057,-24.642447,0.017910,0.001412,0.035868,150.470261,7.665321,0.358683,-24.642447,0.036736,0.000000
32.870003,34.246719,-24.597965,0.017897,0.001424,0.036181,152.337021,7.760418,0.361806,-24.597965,0.037039,0.000000
33.050003,34.631752,-24.642447,0.017914,0.001435,0.036449,154.049728,7.847667,0.364493,-24.642447,0.037334,0.000000
33.230003,34.946411,-24.597965,0.017923,0.001446,0.036718,155.449402,7.918970,0.367184,-24.597965,0.037637,0.000000
33.410000,35.250267,-24.686928,0.017949,0.001454,0.036944,156.801025,7.987824,0.369436,-24.686928,0.037941,0.000000
33.590000,35.449852,-24.686928,0.017940,0.001465,0.037213,157.688812,8.033051,0.372127,-24.686928,0.038236,0.000000
33.770000,36.808273,-24.731409,0.017970,0.001486,0.037750,163.731384,8.340874,0.377502,-24.731409,0.038539,0.000000
33.950001,37.238731,-24.642447,0.017983,0.001499,0.038062,165.646149,8.438417,0.380624,-24.642447,0.038834,0.000000
34.130001,37.329590,-24.642447,0.017970,0.001508,0.038297,166.050308,8.459006,0.382967,-24.642447,0.039138,0.000000
34.310001,37.778297,-24.686928,0.017975,0.001518,0.038557,168.046265,8.560684,0.385567,-24.686928,0.039441,0.000000
34.490002,38.145462,-24.686928,0.017992,0.001529,0.038834,169.679489,8.643886,0.388342,-24.686928,0.039736,0.000000
34.670002,38.523788,-24.775890,0.018018,0.001540,0.039112,171.362366,8.729615,0.391120,-24.775890,0.040040,0.000000
34.850002,39.157196,-24.731409,0.018001,0.001555,0.039485,174.179901,8.873148,0.394848,-24.731409,0.040334,0.000000
35.030003,39.624527,-24.642447,0.018018,0.001565,0.039754,176.258698,8.979047,0.397535,-24.642447,0.040638,0.000000
35.210003,39.952209,-24.686928,0.018026,0.001573,0.039953,177.716309,9.053300,0.399530,-24.686928,0.040942,0.000000
35.390003,40.239311,-24.731409,0.018031,0.001583,0.040205,178.993393,9.118359,0.402047,-24.731409,0.041236,0.000000
35.570004,40.794891,-24.686928,0.018048,0.001593,0.040473,181.464737,9.244254,0.404734,-24.686928,0.041540,0.000000
35.750000,41.770882,-24.775890,0.018048,0.001611,0.040924,185.806168,9.465417,0.409242,-24.775890,0.041835,0.000000
35.930000,42.100426,-24.642447,0.018057,0.001621,0.041176,187.272049,9.540092,0.411759,-24.642447,0.042138,0.000000
36.110001,42.146233,-24.686928,0.018061,0.001627,0.041314,187.475800,9.550472,0.413144,-24.686928,0.042433,0.000000
36.290001,43.124077,-24.731409,0.018052,0.001643,0.041739,191.825470,9.772055,0.417394,-24.731409,0.042737,0.000000
36.470001,43.454750,-24.731409,0.018083,0.001653,0.041991,193.296387,9.846987,0.419911,-24.731409,0.043040,0.000000
36.650002,44.480629,-24.731409,0.018083,0.001671,0.042442,197.859726,10.079454,0.424419,-24.731409,0.043335,0.000000
36.830002,44.960991,-24.686928,0.018087,0.001682,0.042719,199.996475,10.188307,0.427194,-24.686928,0.043639,0.000000
37.010002,45.049614,-24.731409,0.018095,0.001686,0.042832,200.390686,10.208388,0.428321,-24.731409,0.043934,0.000000
37.190002,45.520668,-24.775890,0.018100,0.001698,0.043136,202.486038,10.315131,0.431357,-24.775890,0.044237,0.000000
37.370003,46.455322,-24.775890,0.018108,0.001714,0.043535,206.643600,10.526927,0.435346,-24.775890,0.044541,0.000000
37.550003,47.376572,-24.775890,0.018121,0.001731,0.043960,210.741516,10.735685,0.439597,-24.775890,0.044835,0.000000
37.730003,47.987267,-24.731409,0.018134,0.001742,0.044255,213.458023,10.874070,0.442545,-24.731409,0.045139,0.000000
37.910004,48.473579,-24.775890,0.018126,0.001753,0.044515,215.621246,10.984270,0.445145,-24.775890,0.045434,0.000000
38.090000,48.989693,-24.775890,0.018143,0.001763,0.044792,217.917038,11.101223,0.447923,-24.775890,0.045737,0.000000
38.270000,49.534470,-24.731409,0.018126,0.001776,0.045104,220.340332,11.224671,0.451042,-24.731409,0.046041,0.000000
38.450001,50.247192,-24.820372,0.018156,0.001787,0.045399,223.510681,11.386177,0.453991,-24.820372,0.046336,0.000000
38.630001,50.920441,-24.731409,0.018160,0.001801,0.045737,226.505432,11.538736,0.457374,-24.731409,0.046639,0.000000
38.810001,51.269356,-24.775890,0.018151,0.001809,0.045954,228.057480,11.617803,0.459543,-24.775890,0.046934,0.000000
38.990002,51.687531,-24.864851,0.018169,0.001819,0.046197,229.917618,11.712562,0.461969,-24.864851,0.047238,0.000000
39.170002,52.082619,-24.820372,0.018182,0.001831,0.046500,231.675064,11.802090,0.465005,-24.820372,0.047541,0.000000
39.350002,52.895508,-24.775890,0.018177,0.001840,0.046743,235.290970,11.986294,0.467435,-24.775890,0.047836,0.000000
39.530003,54.331375,-24.775890,0.018186,0.001862,0.047307,241.678024,12.311666,0.473070,-24.775890,0.048140,0.000000
39.710003,55.042976,-24.820372,0.018216,0.001875,0.047637,244.843384,12.472917,0.476367,-24.820372,0.048435,0.000000
39.890003,55.415726,-24.864851,0.018212,0.001883,0.047827,246.501465,12.557383,0.478274,-24.864851,0.048738,0.000000
40.070004,55.827942,-24.820372,0.018212,0.001894,0.048096,248.335083,12.650792,0.480962,-24.820372,0.049042,0.000000
40.250004,56.360428,-24.820372,0.018212,0.001903,0.048348,250.703705,12.771456,0.483479,-24.820372,0.049336,0.000000
40.430000,56.933144,-24.820372,0.018220,0.001913,0.048599,253.251266,12.901235,0.485992,-24.820372,0.049640,0.000000
40.610001,57.546440,-24.820372,0.018233,0.001924,0.048877,255.979355,13.040210,0.488766,-24.820372,0.049935,0.000000
40.790001,58.337730,-24.820372,0.018225,0.001938,0.049224,259.499176,13.219519,0.492237,-24.820372,0.050238,0.000000
40.970001,58.986404,-24.820372,0.018238,0.001948,0.049467,262.384644,13.366510,0.494667,-24.820372,0.050542,0.000000
41.150002,59.679390,-24.775890,0.018242,0.001959,0.049753,265.467194,13.523542,0.497528,-24.775890,0.050837,0.000000
41.330002,60.099052,-24.775890,0.018259,0.001967,0.049969,267.333923,13.618640,0.499693,-24.775890,0.051140,0.000000
41.510002,61.311127,-24.820372,0.018255,0.001986,0.050447,272.725525,13.893300,0.504466,-24.820372,0.051435,0.000000
41.690002,62.569740,-24.820372,0.018259,0.002004,0.050897,278.324097,14.178506,0.508974,-24.820372,0.051739,0.000000
41.870003,63.353958,-24.864851,0.018277,0.002016,0.051201,281.812469,14.356212,0.512009,-24.864851,0.052042,0.000000
42.050003,63.581482,-24.820372,0.018285,0.002023,0.051383,282.824554,14.407770,0.513830,-24.820372,0.052337,0.000000
42.230003,64.126633,-24.820372,0.018281,0.002032,0.051609,285.249512,14.531302,0.516086,-24.820372,0.052641,0.000000
42.410004,64.403305,-24.864851,0.018298,0.002042,0.051869,286.480194,14.593997,0.518686,-24.864851,0.052936,0.000000
42.590000,65.101501,-24.909332,0.018281,0.002055,0.052190,289.585937,14.752212,0.521895,-24.909332,0.053239,0.000000
42.770000,66.379852,-24.909332,0.018311,0.002068,0.052528,295.272339,15.041889,0.525279,-24.909332,0.053543,0.000000
42.950001,66.759308,-24.909332,0.018302,0.002075,0.052693,296.960236,15.127875,0.526926,-24.909332,0.053837,0.000000
43.130001,67.410950,-24.909332,0.018315,0.002076,0.052727,299.858887,15.275539,0.527274,-24.909332,0.052970,0.000000
43.310001,66.967834,-24.909332,0.018320,0.002076,0.052727,297.887817,15.175128,0.527274,-24.909332,0.052970,0.000000
43.490002,66.769363,-24.909332,0.018307,0.002075,0.052710,297.004974,15.130154,0.527100,-24.909332,0.052727,0.000000
43.670002,66.503860,-24.909332,0.018311,0.002074,0.052675,295.823944,15.069990,0.526751,-24.909332,0.052727,0.000000
43.850002,66.297562,-24.909332,0.018324,0.002073,0.052666,294.906281,15.023242,0.526664,-24.909332,0.052727,0.000000
44.030003,66.091644,-24.820372,0.018328,0.002073,0.052658,293.990326,14.976581,0.526577,-24.820372,0.052727,0.000000
44.210003,65.899124,-24.909332,0.018328,0.002073,0.052658,293.133942,14.932955,0.526577,-24.909332,0.052727,0.000000
44.390003,65.749435,-24.953814,0.018328,0.002073,0.052649,292.468109,14.899035,0.526494,-24.953814,0.052727,0.000000
44.570004,65.597137,-24.864851,0.018311,0.002073,0.052649,291.790649,14.864524,0.526494,-24.864851,0.052727,0.000000
44.750004,65.467545,-24.953814,0.018324,0.002072,0.052641,291.214172,14.835157,0.526407,-24.953814,0.052727,0.000000
44.930000,65.350250,-24.909332,0.018311,0.002072,0.052641,290.692444,14.808578,0.526407,-24.909332,0.052727,0.000000
45.110001,65.224380,-24.909332,0.018346,0.002072,0.052641,290.132538,14.780056,0.526407,-24.909332,0.052727,0.000000
45.290001,65.123093,-24.953814,0.018333,0.002072,0.052641,289.681976,14.757104,0.526407,-24.953814,0.052727,0.000000
45.470001,65.015854,-24.909332,0.018320,0.002072,0.052641,289.204956,14.732802,0.526407,-24.909332,0.052727,0.000000
45.650002,64.939148,-24.953814,0.018333,0.002072,0.052641,288.863770,14.715422,0.526407,-24.953814,0.052727,0.000000
45.830002,64.837860,-24.909332,0.018337,0.002072,0.052641,288.413208,14.692470,0.526407,-24.909332,0.052727,0.000000
46.010002,64.761520,-24.953814,0.018328,0.002072,0.052641,288.073639,14.675170,0.526407,-24.953814,0.052727,0.000000
46.190002,64.678482,-25.042776,0.018341,0.002072,0.052641,287.704254,14.656354,0.526407,-25.042776,0.052727,0.000000
46.370003,64.615936,-24.998295,0.018328,0.002072,0.052641,287.426025,14.642180,0.526407,-24.998295,0.052727,0.000000
46.550003,64.532150,-24.909332,0.018337,0.002072,0.052641,287.053345,14.623195,0.526407,-24.909332,0.052727,0.000000
46.730003,64.478897,-24.909332,0.018328,0.002072,0.052641,286.816467,14.611127,0.526407,-24.909332,0.052727,0.000000
46.910004,64.406662,-24.998295,0.018337,0.002072,0.052632,286.495148,14.594758,0.526320,-24.998295,0.052727,0.000000
47.090004,64.347824,-24.998295,0.018341,0.002072,0.052632,286.233429,14.581426,0.526320,-24.998295,0.052727,0.000000
47.270000,64.278931,-25.042776,0.018346,0.002072,0.052632,285.926971,14.565814,0.526320,-25.042776,0.052727,0.000000
47.450001,64.229401,-24.953814,0.018346,0.002072,0.052632,285.706635,14.554590,0.526320,-24.953814,0.052727,0.000000
47.630001,64.166107,-24.953814,0.018337,0.002072,0.052632,285.425110,14.540248,0.526320,-24.953814,0.052727,0.000000
47.810001,64.122910,-24.998295,0.018350,0.002072,0.052632,285.232941,14.530458,0.526320,-24.998295,0.052727,0.000000
47.990002,64.070770,-25.042776,0.018354,0.002072,0.052632,285.001007,14.518644,0.526320,-25.042776,0.052727,0.000000
48.170002,64.029068,-24.953814,0.018350,0.002072,0.052632,284.815521,14.509194,0.526320,-24.953814,0.052727,0.000000
48.350002,63.982529,-24.953814,0.018350,0.002072,0.052632,284.608490,14.498649,0.526320,-24.953814,0.052727,0.000000
48.530003,63.931885,-24.998295,0.018346,0.002072,0.052632,284.383240,14.487172,0.526320,-24.998295,0.052727,0.000000
48.710003,63.892044,-25.042776,0.018354,0.002072,0.052632,284.205994,14.478144,0.526320,-25.042776,0.052727,0.000000
48.890003,63.835068,-25.087255,0.018333,0.002072,0.052632,283.952576,14.465233,0.526320,-25.087255,0.052727,0.000000
49.070004,63.809738,-24.998295,0.018333,0.002072,0.052632,283.839905,14.459494,0.526320,-24.998295,0.052727,0.000000
49.250004,63.767670,-24.998295,0.018346,0.002072,0.052632,283.652771,14.449960,0.526320,-24.998295,0.052727,0.000000
49.430004,63.721863,-24.998295,0.018354,0.002072,0.052632,283.449005,14.439581,0.526320,-24.998295,0.052727,0.000000
49.610001,63.684631,-25.042776,0.018320,0.002072,0.052632,283.283386,14.431144,0.526320,-25.042776,0.052727,0.000000
49.790001,63.645157,-25.087255,0.018346,0.002072,0.052632,283.107788,14.422198,0.526320,-25.087255,0.052727,0.000000
49.970001,63.610901,-24.998295,0.018337,0.002072,0.052632,282.955414,14.414436,0.526320,-24.998295,0.052727,0.000000
50.150002,63.579239,-24.998295,0.018350,0.002072,0.052632,282.814575,14.407262,0.526320,-24.998295,0.052727,0.000000
50.330002,63.531952,-25.042776,0.018346,0.002072,0.052632,282.604248,14.396545,0.526320,-25.042776,0.052727,0.000000
50.510002,63.503281,-24.998295,0.018350,0.002072,0.052632,282.476715,14.390049,0.526320,-24.998295,0.052727,0.000000
50.690002,63.471252,-25.131737,0.018324,0.002072,0.052632,282.334229,14.382791,0.526320,-25.131737,0.052727,0.000000
50.870003,63.448166,-25.087255,0.018328,0.002072,0.052632,282.231537,14.377560,0.526320,-25.087255,0.052727,0.000000
51.050003,63.409073,-25.042776,0.018346,0.002072,0.052632,282.057648,14.368701,0.526320,-25.042776,0.052727,0.000000
51.230003,63.385239,-25.042776,0.018341,0.002072,0.052632,281.951630,14.363300,0.526320,-25.042776,0.052727,0.000000
51.410004,63.343155,-25.042776,0.018346,0.002072,0.052632,281.764435,14.353764,0.526320,-25.042776,0.052727,0.000000
51.590004,63.318588,-25.131737,0.018350,0.002072,0.052632,281.655151,14.348198,0.526320,-25.131737,0.052727,0.000000
51.770004,63.289536,-25.087255,0.018346,0.002072,0.052632,281.525909,14.341614,0.526320,-25.087255,0.052727,0.000000
51.950001,63.272034,-25.042776,0.018350,0.002072,0.052632,281.448059,14.337647,0.526320,-25.042776,0.052727,0.000000
52.130001,63.239273,-25.042776,0.018354,0.002072,0.052632,281.302338,14.330224,0.526320,-25.042776,0.052727,0.000000
52.310001,63.210220,-25.131737,0.018354,0.002072,0.052632,281.173096,14.323641,0.526320,-25.131737,0.052727,0.000000
52.490002,63.175598,-25.087255,0.018350,0.002072,0.052632,281.019104,14.315795,0.526320,-25.087255,0.052727,0.000000
52.670002,63.158829,-25.087255,0.018350,0.002072,0.052632,280.944489,14.311995,0.526320,-25.087255,0.052727,0.000000
52.850002,63.136124,-25.042776,0.018341,0.002072,0.052632,280.843506,14.306850,0.526320,-25.042776,0.052727,0.000000
53.030003,63.107819,-25.131737,0.018346,0.002072,0.052632,280.717590,14.300436,0.526320,-25.131737,0.052727,0.000000
53.210003,63.086594,-25.131737,0.018354,0.002072,0.052632,280.623169,14.295627,0.526320,-25.131737,0.052727,0.000000
53.390003,63.051224,-25.131737,0.018350,0.002072,0.052632,280.465851,14.287612,0.526320,-25.131737,0.052727,0.000000
53.570004,63.036331,-25.087255,0.018341,0.002072,0.052632,280.399597,14.284237,0.526320,-25.087255,0.052727,0.000000
53.750004,63.014725,-25.087255,0.018346,0.002072,0.052632,280.303497,14.279341,0.526320,-25.087255,0.052727,0.000000
53.930004,62.999466,-25.131737,0.018350,0.002072,0.052632,280.235626,14.275884,0.526320,-25.131737,0.052727,0.000000
54.110004,62.966324,-25.131737,0.018346,0.002072,0.052632,280.088196,14.268373,0.526320,-25.131737,0.052727,0.000000
54.290001,62.955887,-25.131737,0.018341,0.002072,0.052632,280.041779,14.266008,0.526320,-25.131737,0.052727,0.000000
54.470001,62.922745,-25.087255,0.018363,0.002072,0.052632,279.894348,14.258497,0.526320,-25.087255,0.052727,0.000000
54.650002,62.906738,-25.131737,0.018341,0.002072,0.052632,279.823151,14.254870,0.526320,-25.131737,0.052727,0.000000
54.830002,62.871735,-25.087255,0.018350,0.002072,0.052632,279.667450,14.246939,0.526320,-25.087255,0.052727,0.000000
55.010002,62.863541,-25.176218,0.018350,0.002072,0.052632,279.630981,14.245083,0.526320,-25.176218,0.052727,0.000000
55.190002,62.834503,-25.176218,0.018354,0.002072,0.052632,279.501831,14.238503,0.526320,-25.176218,0.052727,0.000000
55.370003,62.824448,-25.131737,0.018354,0.002072,0.052632,279.457092,14.236223,0.526320,-25.131737,0.052727,0.000000
55.550003,62.801727,-25.131737,0.018346,0.002072,0.052632,279.356049,14.231074,0.526320,-25.131737,0.052727,0.000000
55.730003,62.783478,-25.131737,0.018354,0.002072,0.052632,279.274872,14.226939,0.526320,-25.131737,0.052727,0.000000
55.910004,62.764862,-25.220699,0.018354,0.002072,0.052632,279.192047,14.222721,0.526320,-25.220699,0.052727,0.000000
56.090004,62.757050,-25.176218,0.018337,0.002072,0.052632,279.157288,14.220951,0.526320,-25.176218,0.052727,0.000000
56.270004,62.725388,-25.176218,0.018363,0.002072,0.052632,279.016449,14.213777,0.526320,-25.176218,0.052727,0.000000
56.450005,62.708267,-25.131737,0.018354,0.002072,0.052632,278.940308,14.209896,0.526320,-25.131737,0.052727,0.000000
56.630001,62.685921,-25.131737,0.018350,0.002072,0.052632,278.840912,14.204832,0.526320,-25.131737,0.052727,0.000000
56.810001,62.662834,-25.220699,0.018341,0.002072,0.052632,278.738220,14.199601,0.526320,-25.220699,0.052727,0.000000
56.990002,62.656502,-25.265181,0.018341,0.002072,0.052623,278.710052,14.198166,0.526233,-25.265181,0.052727,0.000000
57.170002,62.637138,-25.176218,0.018358,0.002072,0.052623,278.623901,14.193778,0.526233,-25.176218,0.052727,0.000000
57.350002,62.610703,-25.131737,0.018350,0.002072,0.052623,278.506317,14.187788,0.526233,-25.131737,0.052727,0.000000
57.530003,62.599159,-25.220699,0.018354,0.002072,0.052623,278.454956,14.185172,0.526233,-25.220699,0.052727,0.000000
57.710003,62.576447,-25.220699,0.018337,0.002072,0.052623,278.353943,14.180025,0.526233,-25.220699,0.052727,0.000000
57.890003,62.580910,-25.265181,0.018337,0.002072,0.052623,278.373779,14.181037,0.526233,-25.265181,0.052727,0.000000
58.070004,62.544052,-25.220699,0.018341,0.002072,0.052623,278.209839,14.172685,0.526233,-25.220699,0.052727,0.000000
58.250004,62.535484,-25.265181,0.018341,0.002072,0.052623,278.171722,14.170744,0.526233,-25.265181,0.052727,0.000000
58.430004,62.518730,-25.220699,0.018346,0.002072,0.052623,278.097198,14.166947,0.526233,-25.220699,0.052727,0.000000
58.610004,62.502342,-25.265181,0.018337,0.002072,0.052623,278.024292,14.163233,0.526233,-25.265181,0.052727,0.000000
58.790001,62.494522,-25.265181,0.018346,0.002072,0.052623,277.989532,14.161461,0.526233,-25.265181,0.052727,0.000000
58.970001,62.474785,-25.220699,0.018341,0.002072,0.052623,277.901733,14.156988,0.526233,-25.220699,0.052727,0.000000
59.150002,62.461754,-25.265181,0.018350,0.002072,0.052623,277.843750,14.154036,0.526233,-25.265181,0.052727,0.000000
59.330002,62.447601,-25.220699,0.018358,0.002072,0.052623,277.780792,14.150828,0.526233,-25.220699,0.052727,0.000000
59.510002,62.438667,-25.265181,0.018376,0.002072,0.052623,277.741058,14.148804,0.526233,-25.265181,0.052727,0.000000
59.690002,62.416321,-25.220699,0.018358,0.002072,0.052623,277.641663,14.143740,0.526233,-25.220699,0.052727,0.000000
59.870003,62.406273,-25.176218,0.018350,0.002072,0.052623,277.596954,14.141464,0.526233,-25.176218,0.052727,0.000000
60.050003,62.377602,-25.309662,0.018341,0.002072,0.052623,277.469421,14.134967,0.526233,-25.309662,0.052727,0.000000
60.230003,62.382065,-25.265181,0.018363,0.002072,0.052623,277.489288,14.135978,0.526233,-25.265181,0.052727,0.000000
60.410004,62.366051,-25.354141,0.018337,0.002072,0.052623,277.418060,14.132349,0.526233,-25.354141,0.052727,0.000000
60.590004,62.355255,-25.354141,0.018354,0.002072,0.052623,277.370026,14.129903,0.526233,-25.354141,0.052727,0.000000
60.770004,62.347809,-25.265181,0.018337,0.002072,0.052623,277.336914,14.128215,0.526233,-25.265181,0.052727,0.000000
60.950005,62.326958,-25.265181,0.018337,0.002072,0.052623,277.244141,14.123490,0.526233,-25.265181,0.052727,0.000000
61.130001,62.309082,-25.309662,0.018358,0.002072,0.052623,277.164642,14.119440,0.526233,-25.309662,0.052727,0.000000
61.310001,62.305733,-25.354141,0.018354,0.002072,0.052623,277.149750,14.118681,0.526233,-25.354141,0.052727,0.000000
61.490002,62.283760,-25.309662,0.018320,0.002072,0.052623,277.052002,14.113701,0.526233,-25.309662,0.052727,0.000000
61.670002,62.273705,-25.309662,0.018337,0.002072,0.052623,277.007263,14.111423,0.526233,-25.309662,0.052727,0.000000
61.850002,62.259186,-25.265181,0.018346,0.002072,0.052623,276.942688,14.108133,0.526233,-25.265181,0.052727,0.000000
62.030003,62.265884,-25.309662,0.018358,0.002072,0.052623,276.972473,14.109652,0.526233,-25.309662,0.052727,0.000000
62.210003,62.236099,-25.354141,0.018341,0.002072,0.052623,276.839996,14.102901,0.526233,-25.354141,0.052727,0.000000
62.390003,62.226044,-25.443104,0.018350,0.002072,0.052623,276.795258,14.100623,0.526233,-25.443104,0.052727,0.000000
62.570004,62.213379,-25.309662,0.018346,0.002072,0.052623,276.738922,14.097754,0.526233,-25.309662,0.052727,0.000000
62.750004,62.206680,-25.309662,0.018354,0.002072,0.052623,276.709137,14.096235,0.526233,-25.309662,0.052727,0.000000
62.930004,62.199974,-25.354141,0.018354,0.002072,0.052623,276.679291,14.094716,0.526233,-25.354141,0.052727,0.000000
63.110004,62.172424,-25.354141,0.018328,0.002072,0.052623,276.556763,14.088472,0.526233,-25.354141,0.052727,0.000000
63.290005,62.155663,-25.443104,0.018363,0.002072,0.052623,276.482208,14.084674,0.526233,-25.443104,0.052727,0.000000
63.470001,62.154175,-25.398623,0.018350,0.002072,0.052623,276.475586,14.084337,0.526233,-25.398623,0.052727,0.000000
63.650002,62.141884,-25.354141,0.018350,0.002072,0.052623,276.420898,14.081552,0.526233,-25.354141,0.052727,0.000000
63.830002,62.133324,-25.354141,0.018358,0.002072,0.052623,276.382812,14.079613,0.526233,-25.354141,0.052727,0.000000
64.010002,62.108742,-25.309662,0.018346,0.002072,0.052623,276.273468,14.074042,0.526233,-25.309662,0.052727,0.000000
64.190002,62.106140,-25.443104,0.018354,0.002072,0.052623,276.261902,14.073452,0.526233,-25.443104,0.052727,0.000000
64.370003,62.097946,-25.398623,0.018341,0.002072,0.052623,276.225464,14.071595,0.526233,-25.398623,0.052727,0.000000
64.550003,62.099434,-25.398623,0.018358,0.002072,0.052623,276.232086,14.071933,0.526233,-25.398623,0.052727,0.000000
64.730003,62.087891,-25.354141,0.018346,0.002072,0.052623,276.180725,14.069317,0.526233,-25.354141,0.052727,0.000000
64.910004,62.067039,-25.398623,0.018363,0.002072,0.052623,276.087982,14.064592,0.526233,-25.398623,0.052727,0.000000
65.090004,62.052887,-25.398623,0.018354,0.002072,0.052623,276.025024,14.061385,0.526233,-25.398623,0.052727,0.000000
65.270004,62.057732,-25.354141,0.018363,0.002072,0.052623,276.046570,14.062483,0.526233,-25.354141,0.052727,0.000000
65.450005,62.050285,-25.398623,0.018346,0.002072,0.052623,276.013458,14.060796,0.526233,-25.398623,0.052727,0.000000
65.630005,62.030922,-25.354141,0.018358,0.002072,0.052623,275.927307,14.056407,0.526233,-25.354141,0.052727,0.000000
65.810005,61.997032,-25.443104,0.018350,0.002072,0.052623,275.776581,14.048728,0.526233,-25.443104,0.052727,0.000000
65.990005,62.001503,-25.398623,0.018350,0.002072,0.052623,275.796448,14.049741,0.526233,-25.398623,0.052727,0.000000
66.170006,61.999268,-25.354141,0.018350,0.002072,0.052623,275.786530,14.049234,0.526233,-25.354141,0.052727,0.000000
66.350006,61.981018,-25.354141,0.018371,0.002072,0.052623,275.705353,14.045099,0.526233,-25.354141,0.052727,0.000000
66.530006,61.966873,-25.398623,0.018346,0.002072,0.052623,275.642426,14.041894,0.526233,-25.398623,0.052727,0.000000
66.710007,61.955330,-25.487585,0.018354,0.002072,0.052623,275.591064,14.039278,0.526233,-25.487585,0.052727,0.000000
66.889999,61.959793,-25.487585,0.018380,0.002072,0.052623,275.610931,14.040290,0.526233,-25.487585,0.052727,0.000000
67.070000,61.940430,-25.487585,0.018346,0.002072,0.052623,275.524780,14.035902,0.526233,-25.487585,0.052727,0.000000
67.250000,61.941551,-25.398623,0.018346,0.002072,0.052623,275.529785,14.036157,0.526233,-25.398623,0.052727,0.000000
67.430000,61.918465,-25.443104,0.018350,0.002072,0.052623,275.427094,14.030925,0.526233,-25.443104,0.052727,0.000000
67.610001,61.923302,-25.487585,0.018363,0.002072,0.052623,275.448608,14.032022,0.526233,-25.487585,0.052727,0.000000
67.790001,61.903198,-25.487585,0.018346,0.002072,0.052623,275.359192,14.027466,0.526233,-25.487585,0.052727,0.000000
67.970001,61.900963,-25.443104,0.018358,0.002072,0.052623,275.349243,14.026958,0.526233,-25.443104,0.052727,0.000000
68.150002,61.881226,-25.398623,0.018358,0.002072,0.052623,275.261444,14.022486,0.526233,-25.398623,0.052727,0.000000
68.330002,61.881599,-25.443104,0.018367,0.002072,0.052623,275.263092,14.022572,0.526233,-25.443104,0.052727,0.000000
68.510002,61.880112,-25.487585,0.018354,0.002072,0.052623,275.256470,14.022234,0.526233,-25.487585,0.052727,0.000000
68.690002,61.850319,-25.487585,0.018363,0.002072,0.052623,275.123962,14.015483,0.526233,-25.487585,0.052727,0.000000
68.870003,61.839890,-25.443104,0.018350,0.002072,0.052623,275.077576,14.013119,0.526233,-25.443104,0.052727,0.000000
69.050003,61.840637,-25.443104,0.018371,0.002072,0.052623,275.080902,14.013288,0.526233,-25.443104,0.052727,0.000000
69.230003,61.841011,-25.532066,0.018371,0.002072,0.052623,275.082550,14.013373,0.526233,-25.532066,0.052727,0.000000
69.410004,61.815689,-25.576548,0.018350,0.002072,0.052623,274.969910,14.007635,0.526233,-25.576548,0.052727,0.000000
69.590004,61.806747,-25.532066,0.018354,0.002072,0.052623,274.930145,14.005610,0.526233,-25.532066,0.052727,0.000000
69.770004,61.810104,-25.576548,0.018358,0.002072,0.052623,274.945068,14.006370,0.526233,-25.576548,0.052727,0.000000
69.950005,61.801537,-25.487585,0.018363,0.002072,0.052623,274.906952,14.004428,0.526233,-25.487585,0.052727,0.000000
70.130005,61.794464,-25.532066,0.018380,0.002072,0.052623,274.875519,14.002826,0.526233,-25.532066,0.052727,0.000000
70.310005,61.779198,-25.532066,0.018363,0.002072,0.052623,274.807587,13.999366,0.526233,-25.532066,0.052727,0.000000
70.490005,61.769882,-25.532066,0.018350,0.002072,0.052623,274.766144,13.997255,0.526233,-25.532066,0.052727,0.000000
70.670006,61.771004,-25.532066,0.018350,0.002072,0.052623,274.771149,13.997509,0.526233,-25.532066,0.052727,0.000000
70.850006,61.765419,-25.487585,0.018354,0.002072,0.052623,274.746307,13.996243,0.526233,-25.487585,0.052727,0.000000
71.030006,61.749031,-25.532066,0.018371,0.002072,0.052623,274.673401,13.992530,0.526233,-25.532066,0.052727,0.000000
71.210007,61.733765,-25.532066,0.018350,0.002072,0.052623,274.605499,13.989071,0.526233,-25.532066,0.052727,0.000000
71.390007,61.736748,-25.576548,0.018350,0.002072,0.052623,274.618774,13.989747,0.526233,-25.576548,0.052727,0.000000
71.570000,61.731903,-25.532066,0.018350,0.002072,0.052623,274.597229,13.988649,0.526233,-25.532066,0.052727,0.000000
71.750000,61.720360,-25.532066,0.018371,0.002072,0.052623,274.545868,13.986033,0.526233,-25.532066,0.052727,0.000000
71.930000,61.712540,-25.532066,0.018363,0.002072,0.052623,274.511078,13.984262,0.526233,-25.532066,0.052727,0.000000
72.110001,61.708817,-25.576548,0.018363,0.002072,0.052623,274.494537,13.983418,0.526233,-25.576548,0.052727,0.000000
72.290001,61.695412,-25.621027,0.018346,0.002072,0.052623,274.434906,13.980380,0.526233,-25.621027,0.052727,0.000000
72.470001,61.680519,-25.576548,0.018363,0.002072,0.052623,274.368652,13.977006,0.526233,-25.576548,0.052727,0.000000
72.650002,61.677536,-25.532066,0.018346,0.002072,0.052623,274.355377,13.976330,0.526233,-25.532066,0.052727,0.000000
72.830002,61.660408,-25.576548,0.018358,0.002072,0.052623,274.279205,13.972448,0.526233,-25.576548,0.052727,0.000000
73.010002,61.668228,-25.621027,0.018354,0.002072,0.052623,274.313965,13.974220,0.526233,-25.621027,0.052727,0.000000
73.190002,61.664131,-25.576548,0.018358,0.002072,0.052623,274.295746,13.973292,0.526233,-25.576548,0.052727,0.000000
73.370003,61.639931,-25.576548,0.018363,0.002072,0.052623,274.188110,13.967808,0.526233,-25.576548,0.052727,0.000000
73.550003,61.643654,-25.621027,0.018341,0.002072,0.052623,274.204681,13.968652,0.526233,-25.621027,0.052727,0.000000
73.600006,61.637321,-25.621027,0.018358,0.002072,0.052623,274.176514,13.967216,0.526233,-25.621027,0.052727,0.000000