File: Data/I-18 Position Control Dwell_07192023_174732.csv
Time (sec),S:Load (lbs),S:HL1 (DIM),S:LVDT (in),S:Position (in),Ch:Position (mm),Ch:Load (N),Ch:Stress (MPa),Ch:Strain (mm/mm),Ch:HL1 (DIM),Set Point (),Cycles ()
0.110000,0.008192,-26.021357,0.000004,-0.000000,-0.000000,0.036441,0.001856,-0.000000,-26.021357,0.000095,0.000000
0.360000,0.002979,-26.021357,0.000000,-0.000000,-0.000000,0.013251,0.000675,-0.000000,-26.021357,0.000095,0.000000
0.610000,0.006703,-26.021357,0.000000,0.000126,0.003209,0.029815,0.001519,0.032086,-26.021357,0.003824,0.000000
0.860000,0.037610,-26.021357,-0.000004,0.000280,0.007111,0.167296,0.008522,0.071112,-26.021357,0.007987,0.000000
1.110000,0.009682,-26.021357,0.000151,0.000438,0.011135,0.043066,0.002194,0.111352,-26.021357,0.012150,0.000000
1.360000,0.021970,-25.976875,0.000285,0.000589,0.014951,0.097727,0.004978,0.149509,-25.976875,0.016312,0.000000
1.610000,0.005958,-26.021357,0.000466,0.000764,0.019408,0.026502,0.001350,0.194085,-26.021357,0.020475,0.000000
1.860000,-0.049153,-25.976875,0.000647,0.000929,0.023606,-0.218644,-0.011138,0.236058,-25.976875,0.024638,0.000000
2.110000,0.014895,-26.021357,0.000802,0.001091,0.027708,0.066256,0.003375,0.277078,-26.021357,0.028800,0.000000
2.360000,0.056228,-26.065838,0.000974,0.001251,0.031784,0.250116,0.012741,0.317838,-26.065838,0.032981,0.000000
2.610000,0.074102,-26.065838,0.001138,0.001426,0.036233,0.329623,0.016792,0.362327,-26.065838,0.037143,0.000000
2.860000,0.015640,-25.976875,0.001293,0.001584,0.040222,0.069568,0.003544,0.402219,-25.976875,0.041306,0.000000
3.110000,0.049525,-26.065838,0.001475,0.001748,0.044393,0.220300,0.011223,0.443932,-26.065838,0.045469,0.000000
3.360000,0.031652,-25.976875,0.001613,0.001909,0.048495,0.140793,0.007172,0.484952,-25.976875,0.049631,0.000000
3.610000,-0.007820,-26.021357,0.001815,0.002079,0.052797,-0.034784,-0.001772,0.527966,-26.021357,0.053794,0.000000
3.860000,0.040961,-26.065838,0.001983,0.002239,0.056881,0.182203,0.009282,0.568813,-26.065838,0.057957,0.000000
4.110000,0.026066,-26.021357,0.002139,0.002403,0.061044,0.115948,0.005907,0.610440,-26.021357,0.062119,0.000000
4.360000,0.053994,-25.976875,0.002311,0.002568,0.065215,0.240177,0.012235,0.652153,-25.976875,0.066299,0.000000
4.610000,0.010799,-26.065838,0.002488,0.002733,0.069430,0.048035,0.002447,0.694301,-26.065838,0.070462,0.000000
4.860000,0.046919,-26.065838,0.002652,0.002894,0.073497,0.208706,0.010632,0.734973,-26.065838,0.074625,0.000000
5.110000,0.059580,-26.021357,0.002807,0.003062,0.077764,0.265023,0.013501,0.777641,-26.021357,0.078787,0.000000
5.360000,0.030535,-26.021357,0.002997,0.003228,0.081979,0.135824,0.006919,0.819788,-26.021357,0.082950,0.000000
5.610000,0.035003,-26.021357,0.003139,0.003378,0.085812,0.155701,0.007932,0.858119,-26.021357,0.087113,0.000000
5.860000,0.026438,-25.976875,0.003316,0.003551,0.090183,0.117604,0.005991,0.901827,-25.976875,0.091275,0.000000
6.110000,0.020480,-26.021357,0.003492,0.003717,0.094423,0.091102,0.004641,0.944235,-26.021357,0.095438,0.000000
6.360000,-0.016384,-26.065838,0.003660,0.003880,0.098560,-0.072882,-0.003713,0.985601,-26.065838,0.099618,0.000000
6.610000,0.068144,-26.065838,0.003820,0.004042,0.102662,0.303120,0.015442,1.026622,-26.065838,0.103781,0.000000
6.860000,0.067399,-26.065838,0.003997,0.004213,0.107007,0.299807,0.015273,1.070069,-26.065838,0.107944,0.000000
7.110000,0.030535,-26.065838,0.004152,0.004374,0.111092,0.135824,0.006919,1.110916,-26.065838,0.112106,0.000000
7.360000,0.059207,-26.021357,0.004324,0.004537,0.115237,0.263367,0.013417,1.152369,-26.021357,0.116269,0.000000
7.610000,0.049153,-26.021357,0.004475,0.004699,0.119348,0.218644,0.011138,1.193475,-26.021357,0.120432,0.000000
7.860001,0.027183,-26.065838,0.004635,0.004864,0.123536,0.120917,0.006160,1.235363,-26.065838,0.124594,0.000000
8.110001,0.045802,-26.110319,0.004790,0.005028,0.127708,0.203737,0.010379,1.277076,-26.110319,0.128774,0.000000
8.360001,0.067399,-26.065838,0.004971,0.005191,0.131844,0.299807,0.015273,1.318443,-26.065838,0.132937,0.000000
8.610001,0.061069,-26.065838,0.005148,0.005355,0.136016,0.271649,0.013838,1.360156,-26.065838,0.137100,0.000000
8.860001,0.031652,-26.021357,0.005316,0.005521,0.140230,0.140793,0.007172,1.402304,-26.021357,0.141262,0.000000
9.110001,0.046174,-26.021357,0.005467,0.005682,0.144332,0.205393,0.010463,1.443323,-26.021357,0.145425,0.000000
9.360001,0.058090,-26.021357,0.005627,0.005840,0.148330,0.258398,0.013163,1.483302,-26.021357,0.149588,0.000000
9.610001,0.050643,-26.021357,0.005808,0.006015,0.152788,0.225270,0.011476,1.527878,-26.021357,0.153750,0.000000
9.860001,0.044685,-26.065838,0.005976,0.006168,0.156664,0.198767,0.010126,1.566643,-26.065838,0.157913,0.000000
10.110001,0.052877,-26.065838,0.006140,0.006338,0.160992,0.235208,0.011982,1.609917,-26.065838,0.162093,0.000000
10.360001,0.036120,-25.976875,0.006303,0.006505,0.165224,0.160670,0.008185,1.652238,-25.976875,0.166256,0.000000
10.610001,-0.010054,-26.065838,0.006480,0.006668,0.169378,-0.044723,-0.002278,1.693778,-26.065838,0.170418,0.000000
10.860001,0.065910,-26.065838,0.006627,0.006828,0.173419,0.293182,0.014935,1.734191,-26.065838,0.174581,0.000000
11.110001,0.083411,-26.021357,0.006799,0.006996,0.177703,0.371032,0.018901,1.777032,-26.021357,0.178744,0.000000
11.360001,0.051387,-26.065838,0.006972,0.007162,0.181918,0.228582,0.011645,1.819179,-26.065838,0.182907,0.000000
11.610001,0.065165,-26.065838,0.007123,0.007324,0.186037,0.289869,0.014767,1.860372,-26.065838,0.187069,0.000000
11.860001,0.082667,-26.065838,0.007282,0.007485,0.190131,0.367720,0.018733,1.901305,-26.065838,0.191232,0.000000
12.110001,0.066282,-26.065838,0.007450,0.007650,0.194302,0.294838,0.015020,1.943019,-26.065838,0.195412,0.000000
12.360001,0.020108,-26.021357,0.007597,0.007815,0.198499,0.089445,0.004557,1.984992,-26.021357,0.199575,0.000000
12.610001,0.059952,-26.065838,0.007769,0.007978,0.202636,0.266680,0.013585,2.026359,-26.065838,0.203737,0.000000
12.860001,0.078943,-26.110319,0.007938,0.008143,0.206842,0.351156,0.017889,2.068419,-26.110319,0.207900,0.000000
13.110001,0.046174,-26.110319,0.008097,0.008307,0.210987,0.205393,0.010463,2.109873,-26.110319,0.212063,0.000000
13.360001,0.074847,-26.065838,0.008261,0.008469,0.215115,0.332935,0.016961,2.151153,-26.065838,0.216225,0.000000
13.610001,0.089369,-26.065838,0.008420,0.008628,0.219157,0.397535,0.020251,2.191566,-26.065838,0.220388,0.000000
13.860001,0.078198,-26.065838,0.008610,0.008803,0.223597,0.347843,0.017720,2.235967,-26.065838,0.224568,0.000000
14.110001,0.051760,-26.110319,0.008752,0.008957,0.227499,0.230239,0.011729,2.274992,-26.110319,0.228731,0.000000
14.360001,0.076336,-26.154799,0.008925,0.009127,0.231827,0.339561,0.017298,2.318267,-26.154799,0.232893,0.000000
14.610001,0.056973,-26.110319,0.009076,0.009288,0.235911,0.253428,0.012910,2.359114,-26.110319,0.237056,0.000000
14.860001,0.006330,-26.065838,0.009248,0.009456,0.240178,0.028159,0.001434,2.401781,-26.065838,0.241219,0.000000
15.110001,0.087507,-26.110319,0.009416,0.009616,0.244237,0.389253,0.019829,2.442367,-26.110319,0.245381,0.000000
15.360001,0.108733,-26.110319,0.009576,0.009779,0.248391,0.483667,0.024639,2.483907,-26.110319,0.249544,0.000000
15.610001,0.077826,-26.021357,0.009744,0.009950,0.252718,0.346187,0.017636,2.527182,-26.021357,0.253707,0.000000
15.860001,0.081922,-26.110319,0.009899,0.010111,0.256811,0.364407,0.018564,2.568115,-26.110319,0.257887,0.000000
16.110001,0.097562,-26.065838,0.010063,0.010272,0.260905,0.433975,0.022108,2.609048,-26.065838,0.262050,0.000000
16.360001,0.081177,-26.065838,0.010223,0.010436,0.265085,0.361094,0.018395,2.650848,-26.065838,0.266212,0.000000
16.610001,0.042450,-26.065838,0.010391,0.010602,0.269291,0.188829,0.009619,2.692909,-26.065838,0.270375,0.000000
16.860001,0.088625,-26.065838,0.010542,0.010765,0.273428,0.394222,0.020083,2.734275,-26.065838,0.274538,0.000000
17.110001,0.103147,-26.021357,0.010718,0.010930,0.277616,0.458821,0.023373,2.776162,-26.021357,0.278700,0.000000
17.360001,0.096817,-26.065838,0.010882,0.011093,0.281753,0.430663,0.021939,2.817529,-26.065838,0.282863,0.000000
17.610001,0.070378,-26.065838,0.011063,0.011255,0.285872,0.313059,0.015948,2.858722,-26.065838,0.287026,0.000000
17.860001,0.107616,-26.065838,0.011236,0.011417,0.289983,0.478698,0.024386,2.899829,-26.065838,0.291206,0.000000
18.110001,0.090859,-26.021357,0.011417,0.011589,0.294354,0.404160,0.020589,2.943537,-26.021357,0.295368,0.000000
18.360001,0.060324,-26.021357,0.011572,0.011750,0.298447,0.268336,0.013670,2.984470,-26.021357,0.299531,0.000000
18.610001,0.080805,-26.021357,0.011745,0.011914,0.302627,0.359438,0.018311,3.026270,-26.021357,0.303694,0.000000
18.860001,0.070378,-26.021357,0.011904,0.012075,0.306694,0.313059,0.015948,3.066943,-26.021357,0.307856,0.000000
19.110001,0.024577,-26.110319,0.012081,0.012242,0.310944,0.109322,0.005569,3.109437,-26.110319,0.312019,0.000000
19.360001,0.085646,-26.110319,0.012245,0.012403,0.315028,0.380971,0.019408,3.150284,-26.110319,0.316182,0.000000
19.610001,0.130330,-26.110319,0.012417,0.012566,0.319182,0.579738,0.029533,3.191824,-26.110319,0.320362,0.000000
19.860001,0.111339,-26.110319,0.012594,0.012738,0.323545,0.495262,0.025230,3.235445,-26.110319,0.324524,0.000000
20.110001,0.093465,-26.110319,0.012758,0.012898,0.327603,0.415755,0.021180,3.276031,-26.110319,0.328687,0.000000
20.360001,0.097562,-26.065838,0.012909,0.013058,0.331670,0.433975,0.022108,3.316705,-26.065838,0.332850,0.000000
20.610001,0.103147,-26.110319,0.013085,0.013222,0.335842,0.458821,0.023373,3.358418,-26.110319,0.337013,0.000000
20.860001,0.055856,-26.065838,0.013249,0.013388,0.340048,0.248459,0.012657,3.400478,-26.065838,0.341175,0.000000
21.110001,0.085273,-26.065838,0.013409,0.013551,0.344193,0.379314,0.019323,3.441931,-26.065838,0.345338,0.000000
21.360001,0.112829,-26.065838,0.013599,0.013718,0.348443,0.501888,0.025567,3.484426,-26.065838,0.349501,0.000000
21.610001,0.107616,-26.065838,0.013771,0.013878,0.352510,0.478698,0.024386,3.525098,-26.065838,0.353681,0.000000
21.860001,0.069634,-26.021357,0.013952,0.014046,0.356768,0.309746,0.015779,3.567679,-26.021357,0.357843,0.000000
22.110001,0.102030,-26.110319,0.014107,0.014207,0.360870,0.453852,0.023120,3.608699,-26.110319,0.362006,0.000000
22.360001,0.091976,-26.065838,0.014267,0.014378,0.365189,0.409130,0.020842,3.651887,-26.065838,0.366169,0.000000
22.610001,0.075964,-26.065838,0.014444,0.014541,0.369334,0.337905,0.017214,3.693340,-26.065838,0.370331,0.000000
22.860001,0.099051,-26.110319,0.014599,0.014700,0.373384,0.440601,0.022445,3.733840,-26.110319,0.374494,0.000000
23.110001,0.085646,-26.065838,0.014780,0.014863,0.377529,0.380971,0.019408,3.775293,-26.065838,0.378657,0.000000
23.360001,0.070006,-26.021357,0.014965,0.015032,0.381813,0.311402,0.015864,3.818134,-26.021357,0.382819,0.000000
23.610001,0.085273,-26.065838,0.015125,0.015192,0.385889,0.379314,0.019323,3.858894,-26.065838,0.386999,0.000000
23.860001,0.123255,-26.110319,0.015289,0.015355,0.390017,0.548267,0.027930,3.900174,-26.110319,0.391162,0.000000
24.110001,0.109850,-26.110319,0.015461,0.015527,0.394388,0.488637,0.024892,3.943882,-26.110319,0.395325,0.000000
24.360001,0.097934,-26.065838,0.015629,0.015687,0.398447,0.435632,0.022192,3.984468,-26.065838,0.399487,0.000000
24.610001,0.100168,-26.065838,0.015802,0.015849,0.402557,0.445570,0.022698,4.025575,-26.065838,0.403650,0.000000
24.860001,0.116925,-26.065838,0.015935,0.016009,0.406633,0.520108,0.026496,4.066334,-26.065838,0.407813,0.000000
25.110001,0.081922,-26.110319,0.016108,0.016176,0.410865,0.364407,0.018564,4.108655,-26.110319,0.411976,0.000000
25.360001,0.058462,-26.110319,0.016276,0.016338,0.414985,0.260054,0.013248,4.149848,-26.110319,0.416156,0.000000
25.610001,0.125117,-26.110319,0.016457,0.016507,0.419278,0.556549,0.028352,4.192776,-26.110319,0.420318,0.000000
25.860001,0.117297,-26.021357,0.016621,0.016665,0.423302,0.521764,0.026580,4.233015,-26.021357,0.424481,0.000000
26.110001,0.083411,-26.065838,0.016793,0.016835,0.427620,0.371032,0.018901,4.276203,-26.065838,0.428644,0.000000
26.360001,0.105009,-26.065838,0.016953,0.016996,0.431688,0.467103,0.023795,4.316875,-26.065838,0.432806,0.000000
26.610001,0.116180,-26.110319,0.017117,0.017162,0.435920,0.516795,0.026327,4.359196,-26.110319,0.436969,0.000000
26.860001,0.095700,-26.065838,0.017285,0.017326,0.440091,0.425694,0.021686,4.400910,-26.065838,0.441132,0.000000
27.110001,0.107243,-26.110319,0.017444,0.017489,0.444210,0.477042,0.024302,4.442103,-26.110319,0.445294,0.000000
27.360001,0.114691,-26.110319,0.017608,0.017652,0.448356,0.510170,0.025989,4.483556,-26.110319,0.449474,0.000000
27.610001,0.097934,-26.021357,0.017768,0.017822,0.452683,0.435632,0.022192,4.526831,-26.021357,0.453637,0.000000
27.860001,0.091604,-26.065838,0.017932,0.017984,0.456794,0.407473,0.020758,4.567938,-26.065838,0.457800,0.000000
28.110001,0.099051,-26.065838,0.018113,0.018145,0.460887,0.440601,0.022445,4.608871,-26.065838,0.461962,0.000000
28.360001,0.135544,-26.065838,0.018277,0.018312,0.465128,0.602928,0.030715,4.651278,-26.065838,0.466125,0.000000
28.610001,0.116553,-26.110319,0.018458,0.018476,0.469299,0.518452,0.026411,4.692992,-26.110319,0.470288,0.000000
28.860001,0.102402,-26.110319,0.018617,0.018637,0.473392,0.455509,0.023205,4.733924,-26.110319,0.474450,0.000000
29.110001,0.123255,-26.154799,0.018781,0.018795,0.477382,0.548267,0.027930,4.773817,-26.154799,0.478630,0.000000
29.360001,0.101285,-26.065838,0.018949,0.018965,0.481718,0.450539,0.022952,4.817178,-26.065838,0.482793,0.000000
29.610001,0.049898,-26.110319,0.019113,0.019127,0.485828,0.221957,0.011307,4.858284,-26.110319,0.486956,0.000000
29.860001,0.137405,-26.065838,0.019277,0.019293,0.490043,0.611210,0.031137,4.900432,-26.065838,0.491118,0.000000
30.110001,0.128468,-26.110319,0.019428,0.019450,0.494041,0.571456,0.029111,4.940411,-26.110319,0.495281,0.000000
30.360001,0.095700,-26.065838,0.019613,0.019624,0.498438,0.425694,0.021686,4.984379,-26.065838,0.499444,0.000000
30.610001,0.121393,-26.065838,0.019773,0.019784,0.502505,0.539985,0.027508,5.025052,-26.065838,0.503607,0.000000
30.860001,0.138150,-26.065838,0.019941,0.019950,0.506737,0.614523,0.031305,5.067372,-26.065838,0.507769,0.000000
31.110001,0.116553,-26.065838,0.020109,0.020112,0.510839,0.518452,0.026411,5.108392,-26.065838,0.511949,0.000000
31.360001,0.080805,-26.065838,0.020286,0.020276,0.515019,0.359438,0.018311,5.150193,-26.065838,0.516112,0.000000
31.610001,0.125862,-26.065838,0.020454,0.020439,0.519139,0.559862,0.028521,5.191386,-26.065838,0.520275,0.000000
31.860001,0.095700,-26.110319,0.020613,0.020609,0.523466,0.425694,0.021686,5.234661,-26.110319,0.524437,0.000000
32.110001,0.110967,-26.110319,0.020769,0.020770,0.527568,0.493606,0.025145,5.275681,-26.110319,0.528600,0.000000
32.360001,0.126979,-26.110319,0.020928,0.020936,0.531765,0.564831,0.028774,5.317655,-26.110319,0.532763,0.000000
32.610001,0.148949,-26.110319,0.021101,0.021094,0.535781,0.662558,0.033752,5.357807,-26.110319,0.536925,0.000000
32.860001,0.138150,-26.065838,0.021273,0.021265,0.540134,0.614523,0.031305,5.401341,-26.065838,0.541088,0.000000
33.110001,0.111712,-26.065838,0.021433,0.021426,0.544210,0.496919,0.025314,5.442101,-26.065838,0.545268,0.000000
33.360001,0.114691,-26.110319,0.021571,0.021581,0.548165,0.510170,0.025989,5.481647,-26.110319,0.549431,0.000000
33.610001,0.111712,-26.065838,0.021743,0.021753,0.552518,0.496919,0.025314,5.525181,-26.065838,0.553594,0.000000
33.860001,0.060697,-26.065838,0.021915,0.021916,0.556655,0.269992,0.013754,5.566548,-26.065838,0.557756,0.000000
34.110001,0.153790,-26.065838,0.022066,0.022078,0.560791,0.684091,0.034849,5.607914,-26.065838,0.561919,0.000000
34.360001,0.148949,-26.110319,0.022230,0.022238,0.564841,0.662558,0.033752,5.648414,-26.110319,0.566082,0.000000
34.610001,0.114318,-26.110319,0.022403,0.022413,0.569290,0.508513,0.025905,5.692903,-26.110319,0.570244,0.000000
34.860001,0.130703,-26.065838,0.022554,0.022571,0.573314,0.581395,0.029618,5.733142,-26.065838,0.574424,0.000000
35.110001,0.174643,-26.065838,0.022722,0.022734,0.577434,0.776849,0.039575,5.774335,-26.065838,0.578587,0.000000
35.360001,0.143736,-26.065838,0.022877,0.022900,0.581666,0.639368,0.032571,5.816656,-26.065838,0.582750,0.000000
35.610001,0.093465,-26.110319,0.023045,0.023065,0.585846,0.415755,0.021180,5.858456,-26.110319,0.586912,0.000000
35.860001,0.137033,-26.110319,0.023192,0.023226,0.589939,0.609553,0.031052,5.899389,-26.110319,0.591075,0.000000
36.110001,0.121393,-26.065838,0.023355,0.023395,0.594223,0.539985,0.027508,5.942230,-26.065838,0.595238,0.000000
36.360001,0.133309,-26.154799,0.023532,0.023557,0.598351,0.592989,0.030208,5.983510,-26.154799,0.599400,0.000000
36.610001,0.130703,-26.065838,0.023718,0.023721,0.602514,0.581395,0.029618,6.025137,-26.065838,0.603563,0.000000
36.860001,0.162354,-26.065838,0.023864,0.023880,0.606546,0.722188,0.036790,6.065463,-26.065838,0.607743,0.000000
37.110001,0.153790,-26.110319,0.024024,0.024053,0.610934,0.684091,0.034849,6.109344,-26.110319,0.611906,0.000000
37.360001,0.127351,-26.110319,0.024209,0.024213,0.615010,0.566487,0.028858,6.150104,-26.110319,0.616068,0.000000
37.610001,0.144853,-26.065838,0.024356,0.024368,0.618948,0.644338,0.032824,6.189476,-26.065838,0.620231,0.000000
37.860001,0.136288,-26.154799,0.024524,0.024539,0.623292,0.606241,0.030883,6.232924,-26.154799,0.624394,0.000000
38.110001,0.081550,-26.154799,0.024692,0.024703,0.627464,0.362750,0.018479,6.274638,-26.154799,0.628556,0.000000
38.360001,0.126979,-26.110319,0.024860,0.024866,0.631609,0.564831,0.028774,6.316091,-26.110319,0.632719,0.000000
38.610001,0.186186,-26.110319,0.025007,0.025028,0.635702,0.828198,0.042190,6.357024,-26.110319,0.636882,0.000000
38.860001,0.168685,-26.110319,0.025192,0.025201,0.640108,0.750347,0.038224,6.401079,-26.110319,0.641062,0.000000
39.110001,0.132565,-26.065838,0.025343,0.025360,0.644132,0.589677,0.030040,6.441319,-26.065838,0.645225,0.000000
39.360001,0.168685,-26.110319,0.025494,0.025522,0.648260,0.750347,0.038224,6.482598,-26.110319,0.649387,0.000000
39.610001,0.160493,-26.021357,0.025666,0.025686,0.652422,0.713906,0.036368,6.524225,-26.021357,0.653550,0.000000
39.860001,0.126979,-26.065838,0.025835,0.025853,0.656655,0.564831,0.028774,6.566546,-26.065838,0.657713,0.000000
40.110001,0.156769,-26.065838,0.025986,0.026012,0.660713,0.697342,0.035524,6.607132,-26.065838,0.661875,0.000000
40.360001,0.158631,-26.065838,0.026149,0.026175,0.664850,0.705624,0.035946,6.648499,-26.065838,0.666038,0.000000
40.610001,0.189538,-26.110319,0.026322,0.026341,0.669073,0.843105,0.042950,6.690732,-26.110319,0.670218,0.000000
40.860001,0.157141,-26.065838,0.026520,0.026506,0.673262,0.698999,0.035609,6.732619,-26.065838,0.674381,0.000000
41.110001,0.181345,-26.065838,0.026671,0.026668,0.677373,0.806665,0.041093,6.773726,-26.065838,0.678543,0.000000
41.360001,0.210018,-26.065838,0.026839,0.026835,0.681605,0.934207,0.047591,6.816047,-26.065838,0.682706,0.000000
41.610001,0.223051,-26.021357,0.027029,0.027001,0.685819,0.992181,0.050544,6.858194,-26.021357,0.686869,0.000000
41.860001,0.338859,-26.065838,0.027158,0.027155,0.689731,1.507320,0.076787,6.897306,-26.065838,0.691031,0.000000
42.110001,0.630799,-26.110319,0.027335,0.000007,0.000182,2.805934,0.142941,0.001821,-26.110319,0.001396,0.000000
42.360001,0.621490,-26.110319,0.027387,0.000012,0.000295,2.764524,0.140832,0.002949,-26.110319,0.000512,0.000000
42.610001,0.603988,-26.065838,0.027382,0.000012,0.000295,2.686673,0.136866,0.002949,-26.065838,0.000512,0.000000
42.860001,0.642342,-26.110319,0.027378,0.000012,0.000304,2.857282,0.145557,0.003035,-26.110319,0.000867,0.000000
43.110001,0.638619,-26.110319,0.027378,0.000018,0.000451,2.840718,0.144713,0.004510,-26.110319,0.001283,0.000000
43.360001,0.722030,-26.065838,0.027365,0.000032,0.000824,3.211751,0.163614,0.008239,-26.065838,0.001700,0.000000
43.610001,0.772673,-26.110319,0.027374,0.000044,0.001127,3.437020,0.175090,0.011274,-26.110319,0.002116,0.000000
43.860001,0.825550,-26.065838,0.027387,0.000063,0.001596,3.672229,0.187072,0.015957,-26.065838,0.002532,0.000000
44.110001,0.876192,-26.065838,0.027404,0.000076,0.001925,3.897498,0.198548,0.019252,-26.065838,0.002949,0.000000
44.360001,0.997586,-26.065838,0.027413,0.000093,0.002350,4.437483,0.226056,0.023502,-26.065838,0.003365,0.000000
44.610001,1.083604,-26.021357,0.027430,0.000109,0.002766,4.820111,0.245548,0.027665,-26.021357,0.003781,0.000000
44.860001,1.166270,-26.110319,0.027438,0.000125,0.003174,5.187830,0.264281,0.031740,-26.110319,0.004197,0.000000
45.110001,1.235904,-26.021357,0.027451,0.000139,0.003521,5.497577,0.280060,0.035209,-26.021357,0.004614,0.000000
45.360001,1.347616,-26.110319,0.027464,0.000160,0.004059,5.994495,0.305374,0.040586,-26.110319,0.005030,0.000000
45.610001,1.437730,-26.065838,0.027486,0.000177,0.004492,6.395343,0.325794,0.044922,-26.065838,0.005446,0.000000
45.860001,1.541250,-26.110319,0.027499,0.000192,0.004882,6.855820,0.349252,0.048825,-26.110319,0.005862,0.000000
46.110001,1.633226,-26.065838,0.027507,0.000206,0.005221,7.264950,0.370094,0.052207,-26.065838,0.006287,0.000000
46.360001,1.873406,-26.065838,0.027512,0.000225,0.005715,8.333325,0.424520,0.057150,-26.065838,0.006704,0.000000
46.610001,2.027568,-26.021357,0.027520,0.000240,0.006097,9.019073,0.459453,0.060966,-26.021357,0.007120,0.000000
46.860001,2.140397,-26.065838,0.027525,0.000257,0.006522,9.520961,0.485021,0.065215,-26.065838,0.007536,0.000000
47.110001,2.364565,-26.065838,0.027546,0.000276,0.007007,10.518111,0.535818,0.070072,-26.065838,0.007952,0.000000
47.360001,2.520589,-26.021357,0.027576,0.000291,0.007389,11.212141,0.571174,0.073888,-26.021357,0.008369,0.000000
47.610001,2.659112,-26.065838,0.027581,0.000308,0.007814,11.828320,0.602563,0.078137,-26.065838,0.008785,0.000000
47.860001,2.853490,-26.110319,0.027602,0.000322,0.008187,12.692958,0.646610,0.081866,-26.110319,0.009201,0.000000
48.110001,3.028133,-26.021357,0.027620,0.000337,0.008560,13.469808,0.686185,0.085595,-26.021357,0.009618,0.000000
48.360001,3.340553,-26.110319,0.027611,0.000355,0.009019,14.859523,0.756980,0.090191,-26.110319,0.010034,0.000000
48.610001,3.642547,-26.021357,0.027637,0.000374,0.009505,16.202860,0.825413,0.095048,-26.021357,0.010450,0.000000
48.860001,3.769899,-26.021357,0.027658,0.000387,0.009834,16.769348,0.854271,0.098343,-26.021357,0.010866,0.000000
49.110001,4.036890,-26.065838,0.027667,0.000404,0.010251,17.956984,0.914772,0.102506,-26.065838,0.011283,0.000000
49.360001,4.319148,-26.065838,0.027680,0.000421,0.010702,19.212530,0.978733,0.107016,-26.065838,0.011699,0.000000
49.610001,4.564542,-26.021357,0.027702,0.000438,0.011127,20.304096,1.034340,0.111265,-26.021357,0.012115,0.000000
49.860001,4.783497,-26.065838,0.027710,0.000453,0.011508,21.278057,1.083956,0.115081,-26.065838,0.012531,0.000000
50.110001,5.049743,-26.021357,0.027727,0.000466,0.011846,22.462378,1.144288,0.118463,-26.021357,0.012948,0.000000
50.360001,5.342055,-26.021357,0.027727,0.000484,0.012289,23.762650,1.210527,0.122886,-26.021357,0.013364,0.000000
50.610001,5.679425,-26.065838,0.027749,0.000500,0.012688,25.263344,1.286976,0.126875,-26.065838,0.013780,0.000000
50.860001,5.830235,-26.065838,0.027762,0.000511,0.012991,25.934183,1.321150,0.129910,-26.065838,0.014196,0.000000
51.110001,6.226812,-26.021357,0.027766,0.000530,0.013468,27.698244,1.411016,0.134680,-26.021357,0.014621,0.000000
51.360001,6.653551,-26.065838,0.027779,0.000552,0.014032,29.596474,1.507716,0.140317,-26.065838,0.015038,0.000000
51.610001,6.960014,-26.021357,0.027805,0.000570,0.014483,30.959688,1.577162,0.144827,-26.021357,0.015454,0.000000
51.860001,7.228122,-26.065838,0.027818,0.000584,0.014838,32.152290,1.637916,0.148382,-26.065838,0.015870,0.000000
52.110001,7.634008,-26.065838,0.027818,0.000603,0.015315,33.957764,1.729891,0.153152,-26.065838,0.016286,0.000000
52.360001,7.856314,-26.065838,0.027831,0.000616,0.015636,34.946632,1.780266,0.156361,-26.065838,0.016703,0.000000
52.610001,8.194428,-26.021357,0.027857,0.000630,0.015992,36.450638,1.856884,0.159916,-26.021357,0.017119,0.000000
52.860001,8.841612,-26.065838,0.027861,0.000655,0.016642,39.329453,2.003538,0.166421,-26.065838,0.017535,0.000000
53.110004,9.158129,-26.065838,0.027870,0.000672,0.017076,40.737392,2.075262,0.170757,-26.065838,0.017952,0.000000
53.360004,9.326068,-26.065838,0.027896,0.000686,0.017414,41.484421,2.113317,0.174139,-26.065838,0.018368,0.000000
53.610004,9.668651,-26.021357,0.027904,0.000701,0.017804,43.008305,2.190948,0.178041,-26.021357,0.018784,0.000000
53.860004,9.985912,-26.021357,0.027926,0.000714,0.018142,44.419556,2.262840,0.181424,-26.021357,0.019200,0.000000
54.110004,10.331474,-25.976875,0.027926,0.000732,0.018585,45.956692,2.341146,0.185847,-25.976875,0.019617,0.000000
54.360004,10.647245,-26.065838,0.027943,0.000746,0.018949,47.361313,2.412700,0.189489,-26.065838,0.020033,0.000000
54.610004,11.044940,-26.021357,0.027956,0.000762,0.019348,49.130348,2.502819,0.193478,-26.021357,0.020449,0.000000
54.860004,11.764363,-26.021357,0.027977,0.000787,0.019998,52.330502,2.665843,0.199982,-26.021357,0.020865,0.000000
55.110004,11.912567,-26.065838,0.027999,0.000801,0.020345,52.989746,2.699426,0.203451,-26.065838,0.021282,0.000000
55.360004,12.344892,-26.065838,0.027977,0.000819,0.020796,54.912819,2.797393,0.207961,-26.065838,0.021698,0.000000
55.610004,12.571294,-26.021357,0.028016,0.000831,0.021100,55.919907,2.848696,0.210996,-26.021357,0.022114,0.000000
55.860004,12.929517,-26.021357,0.028021,0.000847,0.021507,57.513363,2.929870,0.215072,-26.021357,0.022531,0.000000
56.110004,13.321253,-26.065838,0.028016,0.000861,0.021863,59.255894,3.018639,0.218628,-26.065838,0.022947,0.000000
56.360004,13.594201,-26.021357,0.028038,0.000875,0.022218,60.470028,3.080490,0.222183,-26.021357,0.023372,0.000000
56.610004,13.939391,-26.021357,0.028046,0.000891,0.022635,62.005508,3.158711,0.226346,-26.021357,0.023788,0.000000
56.860004,14.631631,-25.976875,0.028059,0.000914,0.023224,65.084747,3.315575,0.232243,-25.976875,0.024204,0.000000
57.110004,14.898994,-26.065838,0.028098,0.000931,0.023649,66.274040,3.376160,0.236492,-26.065838,0.024621,0.000000
57.360004,15.287006,-26.021357,0.028090,0.000948,0.024074,68.000000,3.464085,0.240742,-26.021357,0.025037,0.000000
57.610004,15.520484,-26.065838,0.028111,0.000961,0.024404,69.038559,3.516992,0.244037,-26.065838,0.025453,0.000000
57.860004,16.048136,-26.021357,0.028120,0.000981,0.024907,71.385674,3.636559,0.249067,-26.021357,0.025869,0.000000
58.110004,16.299114,-26.065838,0.028146,0.000994,0.025254,72.502083,3.693432,0.252536,-26.065838,0.026286,0.000000
58.360004,16.748196,-26.021357,0.028163,0.001012,0.025696,74.499695,3.795195,0.256959,-26.021357,0.026702,0.000000
58.610004,17.062851,-25.976875,0.028171,0.001027,0.026086,75.899353,3.866497,0.260861,-25.976875,0.027118,0.000000
58.860004,17.593855,-26.065838,0.028176,0.001049,0.026633,78.261375,3.986825,0.266325,-26.065838,0.027534,0.000000
59.110004,17.713758,-25.976875,0.028189,0.001063,0.026997,78.794731,4.013995,0.269967,-25.976875,0.027951,0.000000
59.360004,18.119272,-25.976875,0.028202,0.001079,0.027413,80.598549,4.105886,0.274130,-25.976875,0.028367,0.000000
59.610004,18.311417,-26.021357,0.028223,0.001092,0.027743,81.453247,4.149426,0.277426,-26.021357,0.028783,0.000000
59.860004,18.709110,-26.065838,0.028223,0.001108,0.028141,83.222282,4.239545,0.281415,-26.065838,0.029199,0.000000
60.110004,18.945194,-26.021357,0.028223,0.001121,0.028471,84.272430,4.293042,0.284710,-26.021357,0.029616,0.000000
60.360004,19.498167,-25.976875,0.028249,0.001139,0.028931,86.732178,4.418347,0.289306,-25.976875,0.030032,0.000000
60.610004,19.910383,-25.976875,0.028262,0.001158,0.029416,88.565811,4.511757,0.294163,-25.976875,0.030448,0.000000
60.860004,20.263391,-26.021357,0.028275,0.001175,0.029850,90.136070,4.591750,0.298499,-26.021357,0.030865,0.000000
61.110004,20.745987,-25.976875,0.028301,0.001195,0.030353,92.282761,4.701108,0.303529,-25.976875,0.031281,0.000000
61.360004,20.971272,-26.065838,0.028296,0.001209,0.030717,93.284874,4.752158,0.307171,-26.065838,0.031706,0.000000
61.610004,20.959356,-25.976875,0.028309,0.001218,0.030934,93.231873,4.749458,0.309339,-25.976875,0.032122,0.000000
61.860004,21.395033,-26.021357,0.028322,0.001233,0.031307,95.169861,4.848184,0.313068,-26.021357,0.032538,0.000000
62.110004,21.748413,-25.976875,0.028335,0.001249,0.031723,96.741776,4.928261,0.317231,-25.976875,0.032955,0.000000
62.360004,22.373999,-26.021357,0.028353,0.001267,0.032191,99.524513,5.070021,0.321914,-26.021357,0.033371,0.000000
62.610004,22.866276,-25.976875,0.028370,0.001287,0.032686,101.714272,5.181572,0.326857,-25.976875,0.033787,0.000000
62.860004,23.267321,-25.976875,0.028378,0.001305,0.033137,103.498215,5.272450,0.331367,-25.976875,0.034203,0.000000
63.110004,23.674696,-26.021357,0.028409,0.001323,0.033614,105.310310,5.364763,0.336137,-26.021357,0.034620,0.000000
63.360004,23.924931,-26.021357,0.028400,0.001338,0.033978,106.423409,5.421467,0.339779,-26.021357,0.035036,0.000000
63.610004,24.320763,-26.065838,0.028413,0.001355,0.034420,108.184158,5.511164,0.344202,-26.065838,0.035452,0.000000
63.860004,24.710636,-25.932394,0.028434,0.001370,0.034793,109.918396,5.599510,0.347931,-25.932394,0.035868,0.000000
64.110001,25.015610,-26.021357,0.028452,0.001384,0.035149,111.274986,5.668618,0.351487,-26.021357,0.036285,0.000000
64.360001,25.596138,-25.976875,0.028447,0.001402,0.035608,113.857307,5.800168,0.356083,-25.976875,0.036701,0.000000
64.610001,26.115971,-26.021357,0.028469,0.001420,0.036068,116.169640,5.917964,0.360679,-26.021357,0.037117,0.000000
64.860001,26.470097,-25.976875,0.028495,0.001436,0.036476,117.744873,5.998209,0.364755,-25.976875,0.037534,0.000000
65.110001,27.097916,-26.021357,0.028486,0.001457,0.036996,120.537552,6.140475,0.369958,-26.021357,0.037950,0.000000
65.360001,27.339586,-25.976875,0.028516,0.001468,0.037291,121.612556,6.195239,0.372907,-25.976875,0.038366,0.000000
65.610001,27.775263,-26.021357,0.028512,0.001484,0.037698,123.550537,6.293964,0.376983,-26.021357,0.038782,0.000000
65.860001,28.232908,-26.021357,0.028534,0.001499,0.038071,125.586250,6.397668,0.380712,-26.021357,0.039199,0.000000
66.110001,28.899082,-25.932394,0.028529,0.001517,0.038531,128.549545,6.548625,0.385308,-25.932394,0.039615,0.000000
66.360001,29.255070,-25.976875,0.028555,0.001532,0.038912,130.133057,6.629294,0.389124,-25.976875,0.040040,0.000000
66.610001,29.989016,-26.021357,0.028585,0.001551,0.039398,133.397797,6.795608,0.393981,-26.021357,0.040456,0.000000
66.860001,30.565077,-25.976875,0.028585,0.001569,0.039840,135.960251,6.926146,0.398403,-25.976875,0.040872,0.000000
67.110001,30.919575,-25.976875,0.028598,0.001584,0.040222,137.537140,7.006476,0.402219,-25.976875,0.041289,0.000000
67.360001,31.249125,-26.021357,0.028603,0.001597,0.040551,139.003052,7.081152,0.405515,-26.021357,0.041705,0.000000
67.610001,32.126808,-25.932394,0.028611,0.001617,0.041063,142.907181,7.280039,0.410631,-25.932394,0.042121,0.000000
67.860001,32.592644,-26.021357,0.028633,0.001632,0.041453,144.979324,7.385599,0.414534,-26.021357,0.042537,0.000000
68.110001,33.154926,-26.065838,0.028633,0.001647,0.041826,147.480484,7.513014,0.418263,-26.065838,0.042954,0.000000
68.360001,34.055325,-25.976875,0.028646,0.001669,0.042381,151.485657,7.717047,0.423813,-25.976875,0.043370,0.000000
68.610001,34.724850,-26.021357,0.028663,0.001687,0.042841,154.463852,7.868763,0.428409,-26.021357,0.043786,0.000000
68.860001,34.922207,-25.976875,0.028667,0.001699,0.043144,155.341736,7.913485,0.431445,-25.976875,0.044202,0.000000
69.110001,35.719082,-26.021357,0.028685,0.001718,0.043630,158.886414,8.094060,0.436301,-26.021357,0.044619,0.000000
69.360001,36.169281,-25.932394,0.028706,0.001731,0.043968,160.888992,8.196076,0.439683,-25.932394,0.045035,0.000000
69.610001,37.022758,-25.932394,0.028715,0.001749,0.044419,164.685455,8.389477,0.444193,-25.932394,0.045451,0.000000
69.860001,37.697872,-25.976875,0.028732,0.001765,0.044836,167.688507,8.542460,0.448356,-25.976875,0.045868,0.000000
70.110001,38.369259,-25.976875,0.028732,0.001780,0.045200,170.674988,8.694598,0.451998,-25.976875,0.046284,0.000000
70.360001,39.085331,-25.976875,0.028745,0.001799,0.045685,173.860229,8.856863,0.456854,-25.976875,0.046700,0.000000
70.610001,39.944023,-26.021357,0.028762,0.001816,0.046136,177.679886,9.051445,0.461364,-26.021357,0.047116,0.000000
70.860001,40.559181,-25.976875,0.028766,0.001831,0.046509,180.416245,9.190843,0.465093,-25.976875,0.047533,0.000000
71.110001,41.311745,-25.976875,0.028788,0.001848,0.046934,183.763824,9.361375,0.469343,-25.976875,0.047949,0.000000
71.360001,41.820034,-25.976875,0.028792,0.001862,0.047290,186.024796,9.476555,0.472898,-25.976875,0.048365,0.000000
71.610001,42.691757,-25.932394,0.028805,0.001879,0.047723,189.902420,9.674090,0.477234,-25.932394,0.048790,0.000000
71.860001,43.318832,-25.976875,0.028801,0.001891,0.048027,192.691788,9.816188,0.480270,-25.976875,0.049206,0.000000
72.110001,44.030437,-25.976875,0.028810,0.001907,0.048426,195.857162,9.977440,0.484259,-25.976875,0.049623,0.000000
72.360001,45.214954,-25.976875,0.028822,0.001928,0.048964,201.126160,10.245855,0.489636,-25.976875,0.050039,0.000000
72.610001,46.098595,-25.976875,0.028835,0.001945,0.049415,205.056793,10.446091,0.494145,-25.976875,0.050455,0.000000
72.860001,46.988937,-25.976875,0.028853,0.001964,0.049874,209.017227,10.647846,0.498742,-25.976875,0.050871,0.000000
73.110001,47.554569,-25.932394,0.028861,0.001979,0.050256,211.533295,10.776019,0.502557,-25.932394,0.051288,0.000000
73.360001,48.641151,-25.976875,0.028879,0.001998,0.050750,216.366653,11.022243,0.507500,-25.976875,0.051704,0.000000
73.610001,49.259663,-25.932394,0.028887,0.002011,0.051071,219.117920,11.162399,0.510709,-25.932394,0.052120,0.000000
73.860001,49.883389,-25.976875,0.028896,0.002025,0.051444,221.892395,11.303738,0.514438,-25.976875,0.052537,0.000000
74.110001,51.158390,-25.976875,0.028896,0.002047,0.051999,227.563889,11.592657,0.519989,-25.976875,0.052953,0.000000
74.360001,52.296734,-25.932394,0.028913,0.002065,0.052458,232.627487,11.850609,0.524585,-25.932394,0.053369,0.000000
74.610001,53.038128,-25.932394,0.028926,0.002081,0.052849,235.925369,12.018612,0.528487,-25.932394,0.053785,0.000000
74.860001,53.789574,-25.976875,0.028926,0.002095,0.053213,239.267975,12.188891,0.532130,-25.976875,0.054202,0.000000
75.110001,54.471016,-26.021357,0.028930,0.002110,0.053595,242.299179,12.343308,0.535945,-26.021357,0.054618,0.000000
75.360001,55.585155,-26.021357,0.028948,0.002126,0.054011,247.255127,12.595777,0.540108,-26.021357,0.055034,0.000000
75.610001,56.431931,-25.976875,0.028956,0.002141,0.054392,251.021759,12.787659,0.543924,-25.976875,0.055450,0.000000
75.860001,57.240723,-25.976875,0.028969,0.002156,0.054757,254.619446,12.970934,0.547566,-25.976875,0.055867,0.000000
76.110001,58.968903,-25.932394,0.028969,0.002180,0.055381,262.306793,13.362544,0.553810,-25.932394,0.056283,0.000000
76.360001,59.724445,-25.976875,0.028982,0.002194,0.055719,265.667603,13.533752,0.557193,-25.976875,0.056699,0.000000
76.610001,60.591331,-26.021357,0.028999,0.002210,0.056144,269.523712,13.730192,0.561442,-26.021357,0.057124,0.000000
76.860001,61.471992,-25.976875,0.029004,0.002225,0.056517,273.441071,13.929752,0.565171,-25.976875,0.057540,0.000000
77.110001,62.251740,-25.976875,0.029021,0.002238,0.056847,276.909576,14.106446,0.568466,-25.976875,0.057957,0.000000
77.360001,63.437374,-25.932394,0.029025,0.002257,0.057332,282.183533,14.375114,0.573323,-25.932394,0.058373,0.000000
77.610001,64.368675,-25.932394,0.029034,0.002272,0.057697,286.326172,14.586150,0.576965,-25.932394,0.058789,0.000000
77.860001,65.183060,-25.976875,0.029047,0.002285,0.058035,289.948730,14.770692,0.580347,-25.976875,0.059205,0.000000
78.110001,67.056458,-25.976875,0.029042,0.002310,0.058668,298.282013,15.195210,0.586678,-25.976875,0.059622,0.000000
78.360001,67.228867,-25.932394,0.029060,0.002309,0.058642,299.048920,15.234279,0.586418,-25.932394,0.058876,0.000000
78.610001,66.773834,-25.932394,0.029073,0.002308,0.058624,297.024841,15.131167,0.586245,-25.932394,0.058642,0.000000
78.860001,66.379120,-25.976875,0.029085,0.002305,0.058546,295.269073,15.041724,0.585464,-25.976875,0.058642,0.000000
79.110001,66.073029,-25.932394,0.029068,0.002304,0.058529,293.907501,14.972362,0.585291,-25.932394,0.058642,0.000000
79.360001,65.806030,-25.932394,0.029085,0.002304,0.058512,292.719849,14.911860,0.585117,-25.932394,0.058642,0.000000
79.610001,65.586700,-25.976875,0.029081,0.002304,0.058512,291.744202,14.862159,0.585117,-25.976875,0.058642,0.000000
79.860001,65.371109,-25.932394,0.029077,0.002303,0.058503,290.785217,14.813306,0.585030,-25.932394,0.058642,0.000000
80.110001,65.205017,-25.976875,0.029085,0.002303,0.058503,290.046417,14.775668,0.585030,-25.976875,0.058642,0.000000
80.360001,65.053467,-25.976875,0.029094,0.002303,0.058503,289.372284,14.741326,0.585030,-25.976875,0.058642,0.000000
80.610001,64.905640,-25.932394,0.029077,0.002303,0.058494,288.714691,14.707828,0.584944,-25.932394,0.058642,0.000000
80.860001,64.774567,-25.887913,0.029077,0.002303,0.058494,288.131653,14.678127,0.584944,-25.887913,0.058642,0.000000
81.110001,64.651672,-25.932394,0.029085,0.002303,0.058494,287.584991,14.650278,0.584944,-25.932394,0.058642,0.000000
81.360001,64.548531,-25.976875,0.029098,0.002303,0.058494,287.126190,14.626905,0.584944,-25.976875,0.058642,0.000000
81.610001,64.453201,-25.976875,0.029090,0.002303,0.058494,286.702148,14.605304,0.584944,-25.976875,0.058642,0.000000
81.860001,64.350800,-25.976875,0.029090,0.002303,0.058494,286.246643,14.582099,0.584944,-25.976875,0.058642,0.000000
82.110001,64.253616,-25.976875,0.029090,0.002303,0.058494,285.814362,14.560078,0.584944,-25.976875,0.058642,0.000000
82.360001,64.181000,-25.976875,0.029090,0.002303,0.058494,285.491333,14.543622,0.584944,-25.976875,0.058642,0.000000
82.610001,64.104294,-25.976875,0.029103,0.002303,0.058486,285.150146,14.526240,0.584857,-25.976875,0.058642,0.000000
82.860001,64.020882,-25.976875,0.029094,0.002303,0.058486,284.779114,14.507339,0.584857,-25.976875,0.058642,0.000000
83.110001,63.952736,-25.887913,0.029094,0.002303,0.058486,284.475983,14.491897,0.584857,-25.887913,0.058642,0.000000
83.360001,63.890549,-25.976875,0.029098,0.002303,0.058486,284.199341,14.477805,0.584857,-25.976875,0.058642,0.000000
83.610001,63.820915,-25.976875,0.029090,0.002303,0.058486,283.889618,14.462027,0.584857,-25.976875,0.058642,0.000000
83.860001,63.766922,-25.932394,0.029085,0.002303,0.058486,283.649445,14.449791,0.584857,-25.932394,0.058642,0.000000
84.110001,63.697662,-25.932394,0.029090,0.002303,0.058486,283.341339,14.434096,0.584857,-25.932394,0.058642,0.000000
84.360001,63.646645,-25.932394,0.029085,0.002303,0.058486,283.114410,14.422536,0.584857,-25.932394,0.058642,0.000000
84.610001,63.598984,-25.887913,0.029085,0.002303,0.058486,282.902405,14.411736,0.584857,-25.887913,0.058642,0.000000
84.860001,63.547966,-25.932394,0.029077,0.002303,0.058486,282.675476,14.400175,0.584857,-25.932394,0.058642,0.000000
85.110001,63.496208,-25.976875,0.029077,0.002303,0.058486,282.445251,14.388447,0.584857,-25.976875,0.058642,0.000000
85.360001,63.440353,-25.932394,0.029085,0.002303,0.058486,282.196777,14.375790,0.584857,-25.932394,0.058642,0.000000
85.610001,63.406467,-25.932394,0.029098,0.002303,0.058486,282.046051,14.368111,0.584857,-25.932394,0.058642,0.000000
85.860001,63.368111,-25.932394,0.029094,0.002303,0.058486,281.875427,14.359420,0.584857,-25.932394,0.058642,0.000000
86.110001,63.308159,-25.932394,0.029098,0.002303,0.058486,281.608765,14.345834,0.584857,-25.932394,0.058642,0.000000
86.360001,63.264591,-25.887913,0.029077,0.002303,0.058486,281.414948,14.335960,0.584857,-25.887913,0.058642,0.000000
86.610001,63.237408,-25.976875,0.029085,0.002303,0.058486,281.294037,14.329802,0.584857,-25.976875,0.058642,0.000000
86.860001,63.193470,-25.932394,0.029090,0.002303,0.058486,281.098602,14.319845,0.584857,-25.932394,0.058642,0.000000
87.110001,63.157349,-25.976875,0.029094,0.002303,0.058486,280.937927,14.311660,0.584857,-25.976875,0.058642,0.000000
87.360001,63.119366,-25.976875,0.029094,0.002303,0.058486,280.768951,14.303053,0.584857,-25.976875,0.058642,0.000000
87.610001,63.083618,-25.887913,0.029081,0.002303,0.058486,280.609955,14.294951,0.584857,-25.887913,0.058642,0.000000
87.860001,63.065746,-25.932394,0.029085,0.002303,0.058486,280.530457,14.290903,0.584857,-25.932394,0.058642,0.000000
88.110001,63.024784,-25.976875,0.029111,0.002303,0.058486,280.348236,14.281620,0.584857,-25.976875,0.058642,0.000000
88.360001,62.979355,-25.932394,0.029098,0.002303,0.058486,280.146149,14.271326,0.584857,-25.932394,0.058642,0.000000
88.610001,62.957756,-25.932394,0.029085,0.002303,0.058486,280.050079,14.266431,0.584857,-25.932394,0.058642,0.000000
88.860001,62.932434,-25.843433,0.029098,0.002303,0.058486,279.937439,14.260694,0.584857,-25.843433,0.058642,0.000000
89.110001,62.896687,-25.887913,0.029081,0.002303,0.058486,279.778442,14.252593,0.584857,-25.887913,0.058642,0.000000
89.360001,62.861313,-25.932394,0.029094,0.002302,0.058477,279.621094,14.244577,0.584770,-25.932394,0.058642,0.000000
89.610001,62.835247,-25.932394,0.029081,0.002302,0.058477,279.505127,14.238670,0.584770,-25.932394,0.058642,0.000000
89.860001,62.805828,-25.932394,0.029094,0.002302,0.058477,279.374268,14.232004,0.584770,-25.932394,0.058642,0.000000
90.110001,62.779392,-25.932394,0.029094,0.002302,0.058477,279.256683,14.226014,0.584770,-25.932394,0.058642,0.000000
90.360001,62.749599,-25.932394,0.029103,0.002302,0.058477,279.124146,14.219262,0.584770,-25.932394,0.058642,0.000000
90.610001,62.729118,-25.976875,0.029090,0.002302,0.058477,279.033051,14.214622,0.584770,-25.976875,0.058642,0.000000
90.860001,62.701565,-25.932394,0.029085,0.002302,0.058477,278.910492,14.208377,0.584770,-25.932394,0.058642,0.000000
91.110001,62.670658,-25.932394,0.029098,0.002302,0.058477,278.773010,14.201374,0.584770,-25.932394,0.058642,0.000000
91.360001,62.644962,-25.932394,0.029090,0.002302,0.058477,278.658722,14.195551,0.584770,-25.932394,0.058642,0.000000
91.610001,62.636028,-25.887913,0.029098,0.002302,0.058477,278.618958,14.193527,0.584770,-25.887913,0.058642,0.000000
91.860001,62.611824,-25.932394,0.029090,0.002302,0.058477,278.511292,14.188042,0.584770,-25.932394,0.058642,0.000000
92.110001,62.579426,-25.976875,0.029090,0.002302,0.058477,278.367187,14.180701,0.584770,-25.976875,0.058642,0.000000
92.360001,62.566395,-25.976875,0.029094,0.002302,0.058477,278.309235,14.177748,0.584770,-25.976875,0.058642,0.000000
92.610001,62.546284,-25.932394,0.029094,0.002302,0.058477,278.219757,14.173190,0.584770,-25.932394,0.058642,0.000000
92.860001,62.521709,-25.887913,0.029090,0.002302,0.058477,278.110443,14.167622,0.584770,-25.887913,0.058642,0.000000
93.110001,62.493782,-25.932394,0.029098,0.002302,0.058477,277.986237,14.161293,0.584770,-25.932394,0.058642,0.000000
93.360008,62.467716,-25.932394,0.029081,0.002302,0.058477,277.870270,14.155387,0.584770,-25.932394,0.058642,0.000000
93.610008,62.460266,-25.932394,0.029077,0.002302,0.058477,277.837128,14.153699,0.584770,-25.932394,0.058642,0.000000
93.860008,62.432339,-25.932394,0.029098,0.002302,0.058477,277.712921,14.147370,0.584770,-25.932394,0.058642,0.000000
94.110008,62.407017,-25.976875,0.029098,0.002302,0.058477,277.600281,14.141632,0.584770,-25.976875,0.058642,0.000000
94.360008,62.402550,-26.021357,0.029085,0.002302,0.058477,277.580414,14.140619,0.584770,-26.021357,0.058642,0.000000
94.610008,62.396217,-25.887913,0.029103,0.002302,0.058477,277.552246,14.139185,0.584770,-25.887913,0.058642,0.000000
94.860008,62.352654,-25.887913,0.029094,0.002302,0.058477,277.358459,14.129313,0.584770,-25.887913,0.058642,0.000000
95.110008,62.332172,-25.887913,0.029098,0.002302,0.058477,277.267365,14.124673,0.584770,-25.887913,0.058642,0.000000
95.360008,62.314297,-25.932394,0.029094,0.002302,0.058477,277.187836,14.120622,0.584770,-25.932394,0.058642,0.000000
95.610008,62.305733,-25.843433,0.029094,0.002302,0.058477,277.149750,14.118681,0.584770,-25.843433,0.058642,0.000000
95.860008,62.278549,-25.932394,0.029090,0.002302,0.058477,277.028809,14.112521,0.584770,-25.932394,0.058642,0.000000
96.110008,62.258812,-25.932394,0.029081,0.002302,0.058477,276.941040,14.108048,0.584770,-25.932394,0.058642,0.000000
96.360008,62.248760,-25.976875,0.029103,0.002302,0.058477,276.896301,14.105770,0.584770,-25.976875,0.058642,0.000000
96.610008,62.229397,-25.932394,0.029098,0.002302,0.058477,276.810181,14.101383,0.584770,-25.932394,0.058642,0.000000
96.860008,62.218597,-25.887913,0.029094,0.002302,0.058477,276.762146,14.098935,0.584770,-25.887913,0.058642,0.000000
97.110008,62.205936,-25.976875,0.029094,0.002302,0.058477,276.705811,14.096066,0.584770,-25.976875,0.058642,0.000000
97.360008,62.192905,-25.932394,0.029090,0.002302,0.058477,276.647858,14.093114,0.584770,-25.932394,0.058642,0.000000
97.610008,62.165348,-25.932394,0.029094,0.002302,0.058477,276.525269,14.086869,0.584770,-25.932394,0.058642,0.000000
97.860008,62.150826,-25.932394,0.029098,0.002302,0.058477,276.460693,14.083578,0.584770,-25.932394,0.058642,0.000000
98.110008,62.133324,-25.843433,0.029094,0.002302,0.058477,276.382812,14.079613,0.584770,-25.843433,0.058642,0.000000
98.360008,62.125134,-25.887913,0.029103,0.002302,0.058477,276.346405,14.077756,0.584770,-25.887913,0.058642,0.000000
98.610008,62.104652,-25.887913,0.029107,0.002302,0.058477,276.255280,14.073115,0.584770,-25.887913,0.058642,0.000000
98.860008,62.093479,-25.843433,0.029090,0.002302,0.058477,276.205597,14.070583,0.584770,-25.843433,0.058642,0.000000
99.110008,62.081192,-25.887913,0.029103,0.002302,0.058477,276.150940,14.067799,0.584770,-25.887913,0.058642,0.000000
99.360008,62.067413,-25.932394,0.029103,0.002302,0.058477,276.089630,14.064677,0.584770,-25.932394,0.058642,0.000000
99.610008,62.048424,-25.843433,0.029098,0.002302,0.058477,276.005188,14.060374,0.584770,-25.843433,0.058642,0.000000
99.860008,62.033157,-25.887913,0.029090,0.002302,0.058477,275.937256,14.056914,0.584770,-25.887913,0.058642,0.000000
100.110008,62.022358,-25.976875,0.029103,0.002302,0.058477,275.889221,14.054467,0.584770,-25.976875,0.058642,0.000000
100.360008,62.010815,-25.843433,0.029090,0.002302,0.058477,275.837891,14.051852,0.584770,-25.843433,0.058642,0.000000
100.610008,61.980652,-25.932394,0.029085,0.002302,0.058477,275.703705,14.045017,0.584770,-25.932394,0.058642,0.000000
100.860008,61.984375,-25.887913,0.029103,0.002302,0.058477,275.720276,14.045860,0.584770,-25.887913,0.058642,0.000000
101.110008,61.975811,-25.887913,0.029103,0.002302,0.058477,275.682190,14.043920,0.584770,-25.887913,0.058642,0.000000
101.360008,61.950863,-25.887913,0.029081,0.002302,0.058477,275.571198,14.038266,0.584770,-25.887913,0.058642,0.000000
101.610008,61.937084,-25.887913,0.029094,0.002302,0.058477,275.509918,14.035144,0.584770,-25.887913,0.058642,0.000000
101.860008,61.928146,-25.932394,0.029094,0.002302,0.058477,275.470154,14.033118,0.584770,-25.932394,0.058642,0.000000
102.110008,61.921070,-25.932394,0.029098,0.002302,0.058477,275.438690,14.031515,0.584770,-25.932394,0.058642,0.000000
102.360008,61.900593,-25.843433,0.029085,0.002302,0.058477,275.347595,14.026875,0.584770,-25.843433,0.058642,0.000000
102.610008,61.883835,-25.887913,0.029098,0.002302,0.058477,275.273041,14.023078,0.584770,-25.887913,0.058642,0.000000
102.860008,61.881599,-25.932394,0.029094,0.002302,0.058477,275.263092,14.022572,0.584770,-25.932394,0.058642,0.000000
103.110008,61.869686,-25.887913,0.029085,0.002302,0.058477,275.210114,14.019872,0.584770,-25.887913,0.058642,0.000000
103.360008,61.854790,-25.887913,0.029098,0.002302,0.058477,275.143860,14.016496,0.584770,-25.887913,0.058642,0.000000
103.610008,61.844734,-25.887913,0.029103,0.002302,0.058477,275.099121,14.014217,0.584770,-25.887913,0.058642,0.000000
103.860008,61.833191,-25.887913,0.029094,0.002302,0.058477,275.047760,14.011600,0.584770,-25.887913,0.058642,0.000000
104.110008,61.818298,-25.887913,0.029090,0.002302,0.058477,274.981537,14.008226,0.584770,-25.887913,0.058642,0.000000
104.360008,61.808617,-25.932394,0.029090,0.002302,0.058477,274.938446,14.006033,0.584770,-25.932394,0.058642,0.000000
104.610008,61.803402,-25.887913,0.029111,0.002302,0.058477,274.915253,14.004851,0.584770,-25.887913,0.058642,0.000000
104.860008,61.797443,-25.843433,0.029085,0.002302,0.058477,274.888763,14.003501,0.584770,-25.843433,0.058642,0.000000
105.110008,61.781059,-25.932394,0.029081,0.002302,0.058477,274.815887,13.999788,0.584770,-25.932394,0.058642,0.000000
105.360008,61.754250,-25.932394,0.029098,0.002302,0.058477,274.696625,13.993712,0.584770,-25.932394,0.058642,0.000000
105.610008,61.751270,-25.887913,0.029094,0.002302,0.058477,274.683380,13.993038,0.584770,-25.887913,0.058642,0.000000
105.860008,61.749779,-25.843433,0.029090,0.002302,0.058477,274.676727,13.992700,0.584770,-25.843433,0.058642,0.000000
106.110008,61.728184,-25.887913,0.029081,0.002302,0.058477,274.580688,13.987806,0.584770,-25.887913,0.058642,0.000000
106.360008,61.722225,-25.843433,0.029090,0.002302,0.058477,274.554169,13.986457,0.584770,-25.843433,0.058642,0.000000
106.610008,61.717384,-25.887913,0.029094,0.002302,0.058477,274.532623,13.985359,0.584770,-25.887913,0.058642,0.000000
106.860008,61.702118,-25.887913,0.029094,0.002302,0.058477,274.464722,13.981900,0.584770,-25.887913,0.058642,0.000000
107.110008,61.696533,-25.887913,0.029094,0.002302,0.058477,274.439880,13.980635,0.584770,-25.887913,0.058642,0.000000
107.360008,61.675304,-25.887913,0.029103,0.002302,0.058477,274.345459,13.975823,0.584770,-25.887913,0.058642,0.000000
107.610008,61.671211,-25.843433,0.029094,0.002302,0.058477,274.327240,13.974896,0.584770,-25.843433,0.058642,0.000000
107.860008,61.651474,-25.932394,0.029090,0.002302,0.058477,274.239441,13.970424,0.584770,-25.932394,0.058642,0.000000
108.110008,61.645145,-25.887913,0.029090,0.002302,0.058477,274.211304,13.968989,0.584770,-25.887913,0.058642,0.000000
108.360008,61.642166,-25.887913,0.029098,0.002302,0.058477,274.198059,13.968314,0.584770,-25.887913,0.058642,0.000000
108.610008,61.635464,-25.976875,0.029098,0.002302,0.058477,274.168243,13.966795,0.584770,-25.976875,0.058642,0.000000
108.700005,61.628761,-25.932394,0.029085,0.002302,0.058477,274.138428,13.965277,0.584770,-25.932394,0.058642,0.000000