File: Data/New new I18 2 new align_08182023_122428.csv
Time (sec),S:Load (lbs),S:HL1 (DIM),S:LVDT (in),S:Position (in),Ch:Position (mm),Ch:Load (N),Ch:Stress (MPa),Ch:Strain (mm/mm),Ch:HL1 (DIM),Set Point (),Cycles ()
0.110000,0.000374,-61.828522,-0.000004,-0.000000,-0.000000,0.001663,0.000085,-0.000000,-61.828522,0.000207,0.000000
0.540000,-0.019363,-61.873001,-0.000013,0.000080,0.002038,-0.086133,-0.004388,0.020378,-61.873001,0.002757,0.000000
0.970000,0.059204,-61.828522,0.000000,0.000347,0.008802,0.263353,0.013416,0.088022,-61.828522,0.009921,0.000000
1.400000,0.110222,-61.917484,0.000108,0.000623,0.015825,0.490291,0.024977,0.158254,-61.917484,0.017084,0.000000
1.830000,0.106499,-61.828522,0.000375,0.000909,0.023094,0.473730,0.024133,0.230939,-61.828522,0.024248,0.000000
2.260000,0.065163,-61.917484,0.000651,0.001195,0.030352,0.289858,0.014766,0.303518,-61.917484,0.031410,0.000000
2.690000,0.052505,-61.917484,0.000936,0.001475,0.037472,0.233556,0.011898,0.374720,-61.917484,0.038574,0.000000
3.120000,0.123253,-61.873001,0.001224,0.001756,0.044592,0.548256,0.027929,0.445921,-61.873001,0.045737,0.000000
3.550000,0.126236,-61.873001,0.001522,0.002037,0.051747,0.561526,0.028605,0.517471,-61.873001,0.052901,0.000000
3.980000,0.101654,-61.961964,0.001811,0.002325,0.059049,0.452180,0.023035,0.590489,-61.961964,0.060063,0.000000
4.410000,0.053619,-61.961964,0.002108,0.002604,0.066151,0.238511,0.012150,0.661509,-61.961964,0.067227,0.000000
4.840000,0.086761,-61.961964,0.002380,0.002882,0.073210,0.385934,0.019660,0.732105,-61.961964,0.074390,0.000000
5.270000,0.133682,-61.917484,0.002682,0.003163,0.080347,0.594648,0.030293,0.803473,-61.917484,0.081554,0.000000
5.700000,0.134796,-61.917484,0.002945,0.003450,0.087632,0.599603,0.030545,0.876324,-61.917484,0.088716,0.000000
6.130000,0.112457,-62.050926,0.003268,0.003733,0.094822,0.500235,0.025483,0.948222,-62.050926,0.095897,0.000000
6.560000,0.071869,-62.006447,0.003553,0.004012,0.101908,0.319689,0.016286,1.019075,-62.006447,0.103060,0.000000
6.990000,0.141876,-62.006447,0.003842,0.004294,0.109061,0.631097,0.032150,1.090610,-62.006447,0.110224,0.000000
7.420001,0.159744,-62.006447,0.004139,0.004574,0.116174,0.710578,0.036199,1.161736,-62.006447,0.117386,0.000000
7.850000,0.144104,-62.006447,0.004437,0.004864,0.123553,0.641007,0.032654,1.235526,-62.006447,0.124550,0.000000
8.280001,0.130699,-62.050926,0.004712,0.005139,0.130543,0.581379,0.029617,1.305425,-62.050926,0.131713,0.000000
8.710000,0.099426,-62.095409,0.005027,0.005419,0.137654,0.442270,0.022530,1.376536,-62.095409,0.138877,0.000000
9.140000,0.156021,-62.139889,0.005320,0.005702,0.144843,0.694017,0.035355,1.448434,-62.139889,0.146039,0.000000
9.570001,0.155647,-62.006447,0.005609,0.005986,0.152033,0.692354,0.035270,1.520332,-62.006447,0.153203,0.000000
10.000000,0.140381,-62.139889,0.005877,0.006273,0.159344,0.624445,0.031811,1.593441,-62.139889,0.160366,0.000000
10.430000,0.140381,-62.050926,0.006196,0.006549,0.166332,0.624445,0.031811,1.663325,-62.050926,0.167530,0.000000
10.860001,0.138519,-62.139889,0.006476,0.006832,0.173531,0.616165,0.031389,1.735314,-62.139889,0.174693,0.000000
11.290001,0.173149,-62.050926,0.006726,0.007108,0.180538,0.770206,0.039236,1.805380,-62.050926,0.181857,0.000000
11.720000,0.172035,-62.095409,0.007054,0.007402,0.188005,0.765251,0.038984,1.880048,-62.095409,0.189019,0.000000
12.150001,0.139641,-62.139889,0.007360,0.007679,0.195048,0.621153,0.031643,1.950477,-62.139889,0.196183,0.000000
12.580001,0.131821,-62.184368,0.007649,0.007957,0.202098,0.586368,0.029871,2.020983,-62.184368,0.203346,0.000000
13.010000,0.153046,-62.228851,0.007912,0.008243,0.209374,0.680781,0.034681,2.093743,-62.228851,0.210510,0.000000
13.440001,0.182091,-62.139889,0.008213,0.008516,0.216302,0.809980,0.041262,2.163022,-62.139889,0.217672,0.000000
13.870001,0.173897,-62.095409,0.008541,0.008812,0.223830,0.773532,0.039406,2.238296,-62.095409,0.224836,0.000000
14.300001,0.161980,-62.184368,0.008808,0.009087,0.230820,0.720522,0.036705,2.308196,-62.184368,0.231999,0.000000
14.730000,0.154907,-62.228851,0.009110,0.009369,0.237965,0.689062,0.035102,2.379654,-62.228851,0.239163,0.000000
15.160001,0.161980,-62.228851,0.009378,0.009648,0.245069,0.720522,0.036705,2.450689,-62.228851,0.246326,0.000000
15.590001,0.163841,-62.184368,0.009662,0.009930,0.252224,0.728802,0.037127,2.522239,-62.184368,0.253490,0.000000
16.020000,0.159004,-62.184368,0.009968,0.010218,0.259533,0.707286,0.036031,2.595333,-62.184368,0.260652,0.000000
16.450001,0.183952,-62.184368,0.010274,0.010499,0.266679,0.818261,0.041684,2.666792,-62.184368,0.267816,0.000000
16.880001,0.170174,-62.184368,0.010563,0.010782,0.273852,0.756970,0.038562,2.738523,-62.184368,0.274979,0.000000
17.310001,0.167564,-62.273331,0.010852,0.011058,0.280885,0.745364,0.037971,2.808846,-62.273331,0.282143,0.000000
17.740002,0.179108,-62.184368,0.011132,0.011345,0.288161,0.796711,0.040586,2.881607,-62.184368,0.289305,0.000000
18.170000,0.150810,-62.139889,0.011443,0.011626,0.295299,0.670837,0.034174,2.952990,-62.139889,0.296469,0.000000
18.600000,0.184326,-62.273331,0.011727,0.011912,0.302557,0.819924,0.041769,3.025569,-62.273331,0.303632,0.000000
19.030001,0.188789,-62.273331,0.011995,0.012190,0.309617,0.839777,0.042780,3.096165,-62.273331,0.310796,0.000000
19.460001,0.165329,-62.228851,0.012296,0.012469,0.316709,0.735420,0.037464,3.167094,-62.228851,0.317958,0.000000
19.890001,0.282631,-62.184368,0.012611,0.012757,0.324020,1.257205,0.064045,3.240203,-62.184368,0.325122,0.000000
20.320002,0.482597,-62.228851,0.012904,0.013038,0.331159,2.146700,0.109358,3.311586,-62.228851,0.332285,0.000000
20.750002,0.439026,-62.273331,0.013154,0.013319,0.338312,1.952885,0.099485,3.383121,-62.273331,0.339449,0.000000
21.180000,0.394341,-62.273331,0.013396,0.013596,0.345337,1.754114,0.089359,3.453368,-62.273331,0.346612,0.000000
21.610001,0.347054,-62.273331,0.013668,0.013884,0.352666,1.543771,0.078643,3.526659,-62.273331,0.353776,0.000000
22.040001,0.311676,-62.228851,0.013987,0.014166,0.359828,1.386404,0.070627,3.598284,-62.228851,0.360938,0.000000
22.470001,0.271828,-62.273331,0.014254,0.014447,0.366949,1.209150,0.061597,3.669486,-62.273331,0.368102,0.000000
22.900002,0.284119,-62.317814,0.014573,0.014727,0.374060,1.263823,0.064382,3.740597,-62.317814,0.375265,0.000000
23.330002,0.266243,-62.317814,0.014888,0.015006,0.381154,1.184308,0.060332,3.811541,-62.317814,0.382429,0.000000
23.760000,0.185814,-62.362293,0.015237,0.015295,0.388491,0.826542,0.042106,3.884907,-62.362293,0.389610,0.000000
24.190001,0.196609,-62.273331,0.015547,0.015576,0.395618,0.874563,0.044552,3.956184,-62.273331,0.396772,0.000000
24.620001,0.204430,-62.362293,0.015841,0.015861,0.402860,0.909348,0.046324,4.028597,-62.362293,0.403936,0.000000
25.050001,0.221931,-62.362293,0.016121,0.016135,0.409824,0.987200,0.050290,4.098239,-62.362293,0.411099,0.000000
25.480001,0.195869,-62.317814,0.016431,0.016423,0.417135,0.871271,0.044385,4.171348,-62.317814,0.418263,0.000000
25.910002,0.164589,-62.317814,0.016724,0.016706,0.424341,0.732128,0.037296,4.243412,-62.317814,0.425425,0.000000
26.340002,0.208527,-62.273331,0.017009,0.016986,0.431436,0.927573,0.047253,4.314356,-62.273331,0.432589,0.000000
26.770000,0.227890,-62.406773,0.017302,0.017268,0.438607,1.013705,0.051641,4.386073,-62.406773,0.439752,0.000000
27.200001,0.257683,-62.406773,0.017578,0.017549,0.445753,1.146230,0.058392,4.457531,-62.406773,0.446916,0.000000
27.630001,0.307205,-62.406773,0.017871,0.017838,0.453073,1.366517,0.069614,4.530731,-62.406773,0.454078,0.000000
28.060001,0.331039,-62.362293,0.018126,0.018113,0.460080,1.472537,0.075015,4.600797,-62.362293,0.461242,0.000000
28.490002,0.516479,-62.273331,0.018410,0.018397,0.467295,2.297415,0.117036,4.672953,-62.273331,0.468405,0.000000
28.920002,0.657982,-62.317814,0.018677,-0.000007,-0.000173,2.926850,0.149101,-0.001726,-62.317814,0.000044,0.000000
29.350002,0.592445,-62.406773,0.018682,-0.000008,-0.000191,2.635329,0.134250,-0.001908,-62.406773,0.000044,0.000000
29.780001,0.598778,-62.406773,0.018665,-0.000008,-0.000191,2.663496,0.135685,-0.001908,-62.406773,0.000651,0.000000
30.210001,0.645691,-62.317814,0.018677,0.000011,0.000288,2.872177,0.146316,0.002877,-62.317814,0.001372,0.000000
30.640001,0.697823,-62.317814,0.018712,0.000042,0.001067,3.104070,0.158129,0.010673,-62.317814,0.002091,0.000000
31.070002,0.722031,-62.406773,0.018738,0.000073,0.001856,3.211753,0.163614,0.018561,-62.406773,0.002802,0.000000
31.500002,0.715324,-62.362293,0.018716,0.000099,0.002516,3.181922,0.162095,0.025162,-62.362293,0.003521,0.000000
31.930002,0.765968,-62.317814,0.018768,0.000129,0.003287,3.407197,0.173571,0.032868,-62.317814,0.004242,0.000000
32.360001,0.801720,-62.362293,0.018785,0.000150,0.003808,3.566227,0.181672,0.038076,-62.362293,0.004952,0.000000
32.790001,0.855713,-62.362293,0.018850,0.000189,0.004796,3.806401,0.193907,0.047962,-62.362293,0.005673,0.000000
33.220001,0.840446,-62.406773,0.018833,0.000209,0.005317,3.738493,0.190448,0.053170,-62.406773,0.006383,0.000000
33.650002,0.892204,-62.451256,0.018897,0.000241,0.006115,3.968723,0.202176,0.061149,-62.451256,0.007103,0.000000
34.080002,0.908958,-62.317814,0.018893,0.000262,0.006652,4.043249,0.205973,0.066523,-62.317814,0.007823,0.000000
34.510002,0.962212,-62.362293,0.018936,0.000297,0.007555,4.280131,0.218040,0.075547,-62.362293,0.008534,0.000000
34.940002,0.984177,-62.362293,0.018975,0.000326,0.008292,4.377836,0.223018,0.082919,-62.362293,0.009253,0.000000
35.370003,0.987900,-62.406773,0.018984,0.000348,0.008846,4.394398,0.223861,0.088461,-62.406773,0.009974,0.000000
35.800003,1.027374,-62.406773,0.018997,0.000380,0.009644,4.569989,0.232806,0.096439,-62.406773,0.010686,0.000000
36.230003,1.076157,-62.451256,0.019005,0.000402,0.010200,4.786983,0.243861,0.101995,-62.451256,0.011405,0.000000
36.660000,1.128288,-62.362293,0.019078,0.000440,0.011170,5.018877,0.255674,0.111700,-62.362293,0.012125,0.000000
37.090000,1.129402,-62.362293,0.019100,0.000462,0.011742,5.023832,0.255926,0.117423,-62.362293,0.012835,0.000000
37.520000,1.186378,-62.406773,0.019126,0.000491,0.012472,5.277275,0.268837,0.124720,-62.406773,0.013556,0.000000
37.950001,1.218033,-62.406773,0.019135,0.000514,0.013061,5.418081,0.276010,0.130609,-62.406773,0.014275,0.000000
38.380001,1.280586,-62.362293,0.019156,0.000551,0.014007,5.696332,0.290185,0.140071,-62.362293,0.014987,0.000000
38.810001,1.303307,-62.451256,0.019199,0.000577,0.014657,5.797397,0.295334,0.146566,-62.451256,0.015706,0.000000
39.240002,1.351707,-62.406773,0.019221,0.000605,0.015368,6.012695,0.306301,0.153682,-62.406773,0.016426,0.000000
39.670002,1.413155,-62.495735,0.019234,0.000634,0.016105,6.286026,0.320225,0.161055,-62.495735,0.017136,0.000000
40.100002,1.403099,-62.451256,0.019272,0.000652,0.016564,6.241296,0.317947,0.165642,-62.451256,0.017857,0.000000
40.530003,1.509972,-62.451256,0.019316,0.000695,0.017648,6.716689,0.342164,0.176482,-62.451256,0.018569,0.000000
40.960003,1.480553,-62.495735,0.019367,0.000716,0.018187,6.585827,0.335498,0.181872,-62.495735,0.019288,0.000000
41.390003,1.558754,-62.495735,0.019350,0.000744,0.018906,6.933684,0.353219,0.189063,-62.495735,0.020007,0.000000
41.820004,1.670090,-62.495735,0.019410,0.000774,0.019660,7.428930,0.378448,0.196603,-62.495735,0.020719,0.000000
42.250004,1.715889,-62.451256,0.019423,0.000801,0.020346,7.632655,0.388826,0.203461,-62.451256,0.021439,0.000000
42.680000,1.775101,-62.451256,0.019466,0.000833,0.021170,7.896042,0.402244,0.211697,-62.451256,0.022158,0.000000
43.110001,1.774353,-62.451256,0.019492,0.000857,0.021768,7.892716,0.402074,0.217677,-62.451256,0.022870,0.000000
43.540001,1.902451,-62.540218,0.019523,0.000888,0.022549,8.462523,0.431101,0.225489,-62.540218,0.023589,0.000000
43.970001,1.962029,-62.451256,0.019553,0.000910,0.023112,8.727539,0.444602,0.231121,-62.451256,0.024310,0.000000
44.400002,2.007088,-62.495735,0.019596,0.000947,0.024049,8.927972,0.454813,0.240492,-62.495735,0.025020,0.000000
44.830002,2.052513,-62.495735,0.019604,0.000975,0.024768,9.130034,0.465106,0.247684,-62.495735,0.025740,0.000000
45.260002,2.058472,-62.495735,0.019643,0.000996,0.025298,9.156539,0.466456,0.252982,-62.495735,0.026459,0.000000
45.690002,2.202209,-62.540218,0.019652,0.001026,0.026069,9.795917,0.499028,0.260688,-62.540218,0.027171,0.000000
46.120003,2.262161,-62.540218,0.019669,0.001046,0.026573,10.062595,0.512613,0.265730,-62.540218,0.027890,0.000000
46.550003,2.331795,-62.451256,0.019742,0.001085,0.027553,10.372341,0.528392,0.275525,-62.451256,0.028602,0.000000
46.980003,2.364937,-62.495735,0.019742,0.001112,0.028238,10.519764,0.535902,0.282383,-62.495735,0.029322,0.000000
47.410004,2.453560,-62.584698,0.019781,0.001142,0.029001,10.913980,0.555985,0.290014,-62.584698,0.030041,0.000000
47.840004,2.472549,-62.495735,0.019811,0.001158,0.029418,10.998449,0.560288,0.294177,-62.495735,0.030753,0.000000
48.270000,2.630440,-62.495735,0.019816,0.001198,0.030432,11.700781,0.596066,0.304321,-62.495735,0.031472,0.000000
48.700001,2.622620,-62.495735,0.019867,0.001223,0.031065,11.665995,0.594294,0.310649,-62.495735,0.032193,0.000000
49.130001,2.711990,-62.584698,0.019915,0.001251,0.031767,12.063536,0.614546,0.317674,-62.584698,0.032903,0.000000
49.560001,2.802475,-62.540218,0.019924,0.001283,0.032582,12.466031,0.635050,0.325819,-62.540218,0.033623,0.000000
49.990002,2.866150,-62.540218,0.019958,0.001313,0.033354,12.749271,0.649479,0.333540,-62.540218,0.034343,0.000000
50.420002,2.937271,-62.495735,0.019997,0.001340,0.034047,13.065635,0.665595,0.340474,-62.495735,0.035054,0.000000
50.850002,2.983078,-62.495735,0.019997,0.001368,0.034742,13.269394,0.675975,0.347423,-62.495735,0.035773,0.000000
51.280003,3.050476,-62.540218,0.020049,0.001397,0.035496,13.569196,0.691248,0.354963,-62.540218,0.036494,0.000000
51.710003,3.069839,-62.629181,0.020044,0.001415,0.035947,13.655328,0.695636,0.359474,-62.629181,0.037204,0.000000
52.140003,3.252670,-62.540218,0.020105,0.001455,0.036953,14.468600,0.737066,0.369527,-62.540218,0.037925,0.000000
52.570004,3.229210,-62.540218,0.020126,0.001481,0.037613,14.364244,0.731749,0.376128,-62.540218,0.038636,0.000000
53.000004,3.277992,-62.495735,0.020161,0.001507,0.038288,14.581238,0.742804,0.382880,-62.495735,0.039355,0.000000
53.430004,3.370712,-62.584698,0.020199,0.001534,0.038974,14.993677,0.763814,0.389738,-62.584698,0.040076,0.000000
53.860004,3.468277,-62.584698,0.020199,0.001560,0.039632,15.427667,0.785923,0.396324,-62.584698,0.040786,0.000000
54.290001,3.504395,-62.540218,0.020277,0.001594,0.040491,15.588326,0.794107,0.404908,-62.540218,0.041507,0.000000
54.720001,3.562859,-62.540218,0.020277,0.001617,0.041081,15.848387,0.807355,0.410812,-62.540218,0.042226,0.000000
55.150002,3.619835,-62.584698,0.020333,0.001647,0.041835,16.101830,0.820266,0.418352,-62.584698,0.042937,0.000000
55.580002,3.769150,-62.584698,0.020350,0.001678,0.042616,16.766016,0.854102,0.426164,-62.584698,0.043656,0.000000
56.010002,3.769524,-62.584698,0.020372,0.001706,0.043328,16.767679,0.854186,0.433280,-62.584698,0.044377,0.000000
56.440002,3.792984,-62.584698,0.020428,0.001733,0.044012,16.872036,0.859502,0.440123,-62.584698,0.045087,0.000000
56.870003,3.941193,-62.495735,0.020445,0.001767,0.044880,17.531300,0.893087,0.448798,-62.495735,0.045808,0.000000
57.300003,3.939331,-62.629181,0.020480,0.001787,0.045382,17.523020,0.892665,0.453824,-62.629181,0.046527,0.000000
57.730003,4.084549,-62.629181,0.020506,0.001816,0.046138,18.168982,0.925572,0.461379,-62.629181,0.047239,0.000000
58.160004,4.058113,-62.584698,0.020549,0.001846,0.046883,18.051388,0.919582,0.468827,-62.584698,0.047958,0.000000
58.590004,4.148232,-62.540218,0.020557,0.001871,0.047534,18.452255,0.940003,0.475337,-62.540218,0.048678,0.000000
59.020004,4.266273,-62.584698,0.020605,0.001902,0.048323,18.977333,0.966751,0.483225,-62.584698,0.049390,0.000000
59.450005,4.324364,-62.629181,0.020613,0.001925,0.048895,19.235731,0.979915,0.488948,-62.629181,0.050109,0.000000
59.880001,4.410751,-62.540218,0.020669,0.001963,0.049867,19.620003,0.999491,0.498667,-62.540218,0.050821,0.000000
60.310001,4.412239,-62.629181,0.020674,0.001985,0.050421,19.626619,0.999828,0.504209,-62.629181,0.051540,0.000000
60.740002,4.440170,-62.540218,0.020717,0.002012,0.051098,19.750864,1.006157,0.510976,-62.540218,0.052260,0.000000
61.170002,4.581673,-62.584698,0.020760,0.002041,0.051844,20.380299,1.038222,0.518440,-62.584698,0.052970,0.000000
61.600002,4.704926,-62.629181,0.020764,0.002068,0.052519,20.928555,1.066151,0.525192,-62.629181,0.053691,0.000000
62.030003,4.733971,-62.629181,0.020833,0.002099,0.053326,21.057753,1.072733,0.533261,-62.629181,0.054410,0.000000
62.460003,4.770462,-62.629181,0.020850,0.002124,0.053942,21.220076,1.081002,0.539423,-62.629181,0.055122,0.000000
62.890003,5.018089,-62.629181,0.020881,0.002156,0.054757,22.321575,1.137115,0.547568,-62.629181,0.055841,0.000000
63.320004,4.960373,-62.584698,0.020911,0.002178,0.055322,22.064840,1.124037,0.553215,-62.584698,0.056561,0.000000
63.750004,5.125336,-62.673660,0.020945,0.002215,0.056250,22.798632,1.161418,0.562496,-62.673660,0.057273,0.000000
64.180000,5.116028,-62.673660,0.020963,0.002237,0.056829,22.757229,1.159308,0.568294,-62.673660,0.057992,0.000000
64.610001,5.230339,-62.584698,0.020967,0.002266,0.057567,23.265711,1.185212,0.575667,-62.584698,0.058711,0.000000
65.040001,5.344658,-62.629181,0.021027,0.002296,0.058313,23.774225,1.211117,0.583131,-62.629181,0.059423,0.000000
65.470001,5.470154,-62.718140,0.021066,0.002324,0.059041,24.332458,1.239555,0.590413,-62.718140,0.060143,0.000000
65.900002,5.576279,-62.673660,0.021070,0.002358,0.059883,24.804527,1.263603,0.598831,-62.673660,0.060854,0.000000
66.330002,5.556541,-62.629181,0.021113,0.002382,0.060498,24.716730,1.259130,0.604978,-62.629181,0.061574,0.000000
66.760002,5.820923,-62.673660,0.021131,0.002413,0.061279,25.892757,1.319040,0.612790,-62.673660,0.062293,0.000000
67.190002,5.777359,-62.673660,0.021170,0.002430,0.061712,25.698977,1.309168,0.617120,-62.673660,0.063005,0.000000
67.620003,6.036530,-62.673660,0.021191,0.002468,0.062675,26.851824,1.367897,0.626748,-62.673660,0.063724,0.000000
68.050003,6.054405,-62.673660,0.021200,0.002494,0.063342,26.931339,1.371948,0.633425,-62.673660,0.064445,0.000000
68.480003,6.165001,-62.673660,0.021234,0.002525,0.064133,27.423294,1.397009,0.641328,-62.673660,0.065155,0.000000
68.910004,6.228302,-62.718140,0.021269,0.002548,0.064713,27.704870,1.411353,0.647126,-62.718140,0.065875,0.000000
69.340004,6.444275,-62.673660,0.021308,0.002578,0.065485,28.665565,1.460294,0.654847,-62.673660,0.066594,0.000000
69.770004,6.476303,-62.718140,0.021342,0.002607,0.066213,28.808035,1.467551,0.662130,-62.718140,0.067306,0.000000
70.200005,6.558968,-62.673660,0.021364,0.002630,0.066812,29.175745,1.486283,0.668125,-62.673660,0.068025,0.000000
70.630005,6.741058,-62.673660,0.021407,0.002667,0.067731,29.985725,1.527546,0.677315,-62.673660,0.068746,0.000000
71.060005,6.760796,-62.673660,0.021445,0.002686,0.068217,30.073521,1.532018,0.682174,-62.673660,0.069457,0.000000
71.490005,6.981613,-62.673660,0.021476,0.002724,0.069197,31.055767,1.582056,0.691970,-62.673660,0.070176,0.000000
71.920006,6.997253,-62.718140,0.021480,0.002750,0.069856,31.125338,1.585600,0.698555,-62.718140,0.070888,0.000000
72.350006,7.107475,-62.629181,0.021493,0.002774,0.070472,31.615629,1.610577,0.704717,-62.629181,0.071607,0.000000
72.780006,7.244133,-62.718140,0.021549,0.002802,0.071183,32.223515,1.641544,0.711833,-62.718140,0.072328,0.000000
73.210007,7.421379,-62.673660,0.021562,0.002826,0.071790,33.011944,1.681709,0.717904,-62.673660,0.073038,0.000000
73.640007,7.588203,-62.673660,0.021601,0.002863,0.072709,33.754013,1.719512,0.727093,-62.673660,0.073759,0.000000
74.070007,7.741249,-62.718140,0.021622,0.002894,0.073507,34.434795,1.754192,0.735072,-62.718140,0.074478,0.000000
74.500000,7.841049,-62.718140,0.021652,0.002919,0.074140,34.878727,1.776807,0.741400,-62.718140,0.075189,0.000000
74.930000,7.825035,-62.718140,0.021674,0.002939,0.074661,34.807495,1.773178,0.746608,-62.718140,0.075908,0.000000
75.360001,8.152725,-62.718140,0.021721,0.002976,0.075596,36.265133,1.847434,0.755965,-62.718140,0.076629,0.000000
75.790001,8.185120,-62.718140,0.021747,0.003002,0.076247,36.409229,1.854775,0.762475,-62.718140,0.077341,0.000000
76.220001,8.394768,-62.718140,0.021773,0.003033,0.077027,37.341793,1.902282,0.770272,-62.718140,0.078060,0.000000
76.650002,8.485626,-62.673660,0.021808,0.003056,0.077634,37.745949,1.922870,0.776343,-62.673660,0.078779,0.000000
77.080002,8.745537,-62.673660,0.021838,0.003091,0.078502,38.902092,1.981767,0.785017,-62.673660,0.079490,0.000000
77.510002,8.799904,-62.807102,0.021868,0.003119,0.079213,39.143929,1.994087,0.792133,-62.807102,0.080211,0.000000
77.940002,8.915344,-62.762623,0.021868,0.003143,0.079837,39.657433,2.020246,0.798371,-62.762623,0.080930,0.000000
78.370003,9.087746,-62.718140,0.021937,0.003175,0.080653,40.424313,2.059313,0.806531,-62.718140,0.081642,0.000000
78.800003,9.221062,-62.718140,0.021941,0.003196,0.081172,41.017330,2.089523,0.811724,-62.718140,0.082361,0.000000
79.230003,9.465706,-62.762623,0.021971,0.003234,0.082135,42.105564,2.144959,0.821352,-62.762623,0.083072,0.000000
79.660004,9.491776,-62.762623,0.022006,0.003255,0.082665,42.221527,2.150867,0.826651,-62.762623,0.083792,0.000000
80.090004,9.677216,-62.762623,0.022028,0.003284,0.083410,43.046406,2.192888,0.834100,-62.762623,0.084512,0.000000
80.520004,9.886864,-62.718140,0.022036,0.003311,0.084105,43.978966,2.240395,0.841049,-62.718140,0.085224,0.000000
80.950005,10.116615,-62.762623,0.022071,0.003339,0.084815,45.000954,2.292458,0.848150,-62.762623,0.085943,0.000000
81.380005,10.264442,-62.762623,0.022122,0.003374,0.085708,45.658520,2.325956,0.857082,-62.762623,0.086662,0.000000
81.810005,10.459572,-62.762623,0.022131,0.003402,0.086403,46.526501,2.370173,0.864031,-62.762623,0.087374,0.000000
82.240005,10.561974,-62.807102,0.022166,0.003427,0.087053,46.982006,2.393378,0.870526,-62.807102,0.088094,0.000000
82.670006,10.651344,-62.762623,0.022196,0.003448,0.087573,47.379547,2.413629,0.875734,-62.762623,0.088813,0.000000
83.100006,11.049034,-62.762623,0.022209,0.003486,0.088544,49.148560,2.503747,0.885438,-62.762623,0.089525,0.000000
83.530006,11.065788,-62.762623,0.022234,0.003510,0.089143,49.223083,2.507543,0.891434,-62.762623,0.090244,0.000000
83.960007,11.163353,-62.807102,0.022260,0.003531,0.089697,49.657074,2.529652,0.896975,-62.807102,0.090965,0.000000
84.390007,11.497742,-62.762623,0.022286,0.003563,0.090488,51.144508,2.605425,0.904878,-62.762623,0.091675,0.000000
84.820007,11.679832,-62.807102,0.022325,0.003591,0.091216,51.954491,2.646688,0.912160,-62.807102,0.092395,0.000000
85.250008,11.944962,-62.807102,0.022355,0.003625,0.092083,53.133842,2.706767,0.920835,-62.807102,0.093105,0.000000
85.680000,11.976242,-62.851585,0.022390,0.003649,0.092691,53.272984,2.713855,0.926906,-62.851585,0.093826,0.000000
86.110001,12.261108,-62.851585,0.022416,0.003680,0.093479,54.540134,2.778407,0.934793,-62.851585,0.094545,0.000000
86.540001,12.295364,-62.762623,0.022424,0.003700,0.093991,54.692513,2.786169,0.939911,-62.762623,0.095257,0.000000
86.970001,12.715775,-62.718140,0.022480,0.003739,0.094980,56.562592,2.881436,0.949797,-62.718140,0.095976,0.000000
87.400002,12.777588,-62.807102,0.022493,0.003761,0.095526,56.837551,2.895443,0.955262,-62.807102,0.096696,0.000000
87.830002,12.986115,-62.851585,0.022528,0.003791,0.096280,57.765121,2.942696,0.962802,-62.851585,0.097408,0.000000
88.260002,13.301888,-62.807102,0.022554,0.003820,0.097017,59.169750,3.014251,0.970175,-62.807102,0.098127,0.000000
88.690002,13.465729,-62.807102,0.022588,0.003843,0.097606,59.898552,3.051378,0.976064,-62.807102,0.098848,0.000000
89.120003,13.862679,-62.718140,0.022610,0.003879,0.098527,61.664272,3.141328,0.985269,-62.718140,0.099558,0.000000
89.550003,13.913322,-62.851585,0.022618,0.003902,0.099116,61.889549,3.152804,0.991158,-62.851585,0.100279,0.000000
89.980003,14.159462,-62.851585,0.022648,0.003933,0.099905,62.984432,3.208580,0.999046,-62.851585,0.100998,0.000000
90.410004,14.218666,-62.896065,0.022670,0.003952,0.100374,63.247784,3.221996,1.003739,-62.896065,0.101709,0.000000
90.840004,14.589554,-62.807102,0.022722,0.003988,0.101302,64.897575,3.306040,1.013020,-62.807102,0.102428,0.000000
91.270004,14.774246,-62.807102,0.022743,0.004016,0.102012,65.719131,3.347892,1.020120,-62.807102,0.103149,0.000000
91.700005,15.045708,-62.851585,0.022791,0.004047,0.102784,66.926651,3.409406,1.027841,-62.851585,0.103859,0.000000
92.130005,15.176414,-62.851585,0.022808,0.004071,0.103391,67.508064,3.439025,1.033912,-62.851585,0.104580,0.000000
92.560005,15.485855,-62.851585,0.022829,0.004101,0.104172,68.884521,3.509145,1.041724,-62.851585,0.105291,0.000000
92.990005,15.765129,-62.762623,0.022860,0.004133,0.104987,70.126793,3.572429,1.049869,-62.762623,0.106010,0.000000
93.420006,15.842583,-62.851585,0.022907,0.004157,0.105577,70.471329,3.589981,1.055774,-62.851585,0.106729,0.000000
93.850006,16.129311,-62.896065,0.022929,0.004188,0.106366,71.746758,3.654954,1.063661,-62.896065,0.107441,0.000000
94.280006,16.192986,-62.851585,0.022942,0.004208,0.106895,72.029999,3.669383,1.068945,-62.851585,0.108162,0.000000
94.710007,16.589561,-62.851585,0.022963,0.004244,0.107788,73.794052,3.759248,1.077878,-62.851585,0.108881,0.000000
95.140007,16.847992,-62.851585,0.023028,0.004273,0.108543,74.943611,3.817810,1.085432,-62.851585,0.109592,0.000000
95.570007,16.939964,-62.851585,0.023032,0.004297,0.109150,75.352722,3.838651,1.091503,-62.851585,0.110312,0.000000
96.000008,17.203979,-62.940544,0.023075,0.004326,0.109879,76.527122,3.898478,1.098785,-62.940544,0.111032,0.000000
96.430008,17.314201,-62.851585,0.023097,0.004349,0.110460,77.017418,3.923454,1.104599,-62.851585,0.111742,0.000000
96.860008,17.856377,-62.896065,0.023136,0.004390,0.111500,79.429131,4.046313,1.115000,-62.896065,0.112463,0.000000
97.290001,17.886536,-62.851585,0.023161,0.004413,0.112081,79.563286,4.053147,1.120813,-62.851585,0.113182,0.000000
97.720001,18.214226,-62.896065,0.023213,0.004443,0.112861,81.020920,4.127403,1.128610,-62.896065,0.113894,0.000000
98.150002,18.223907,-62.851585,0.023196,0.004463,0.113373,81.063988,4.129596,1.133727,-62.851585,0.114613,0.000000
98.580002,18.725494,-62.896065,0.023239,0.004501,0.114336,83.295158,4.243258,1.143356,-62.896065,0.115324,0.000000
99.010002,18.769806,-62.896065,0.023256,0.004524,0.114917,83.492264,4.253299,1.149170,-62.896065,0.116045,0.000000
99.440002,19.192818,-62.851585,0.023274,0.004559,0.115801,85.373917,4.349155,1.158011,-62.851585,0.116764,0.000000
99.870003,19.180534,-62.896065,0.023295,0.004582,0.116373,85.319275,4.346371,1.163734,-62.896065,0.117476,0.000000
100.300003,19.530563,-62.851585,0.023338,0.004611,0.117129,86.876282,4.425689,1.171289,-62.851585,0.118195,0.000000
100.730003,19.723076,-62.851585,0.023377,0.004641,0.117874,87.732620,4.469313,1.178737,-62.851585,0.118915,0.000000
101.160004,19.910751,-62.807102,0.023386,0.004666,0.118507,88.567444,4.511841,1.185066,-62.807102,0.119625,0.000000
101.590004,20.203812,-62.896065,0.023455,0.004695,0.119262,89.871040,4.578249,1.192620,-62.896065,0.120346,0.000000
102.020004,20.215355,-62.940544,0.023450,0.004718,0.119843,89.922386,4.580865,1.198434,-62.940544,0.121065,0.000000
102.450005,20.809288,-62.851585,0.023498,0.004756,0.120805,92.564339,4.715452,1.208048,-62.851585,0.121777,0.000000
102.880005,20.653267,-62.851585,0.023541,0.004775,0.121282,91.870323,4.680097,1.212817,-62.851585,0.122496,0.000000
103.310005,20.960472,-62.896065,0.023580,0.004805,0.122045,93.236839,4.749711,1.220447,-62.896065,0.123216,0.000000
103.740005,21.353325,-62.940544,0.023575,0.004837,0.122870,94.984329,4.838733,1.228698,-62.940544,0.123927,0.000000
104.170006,21.401360,-62.851585,0.023614,0.004861,0.123459,95.197998,4.849617,1.234587,-62.851585,0.124647,0.000000
104.600006,21.841881,-62.896065,0.023666,0.004896,0.124370,97.157539,4.949441,1.243701,-62.896065,0.125359,0.000000
105.030006,21.923431,-62.940544,0.023670,0.004920,0.124968,97.520294,4.967921,1.249681,-62.940544,0.126078,0.000000
105.460007,22.125999,-62.896065,0.023700,0.004948,0.125671,98.421364,5.013824,1.256706,-62.896065,0.126799,0.000000
105.890007,22.309952,-62.896065,0.023744,0.004973,0.126303,99.239624,5.055507,1.263035,-62.896065,0.127509,0.000000
106.320007,22.782120,-62.896065,0.023748,0.005009,0.127222,101.339928,5.162502,1.272224,-62.896065,0.128229,0.000000
106.750008,22.861809,-62.940544,0.023769,0.005033,0.127848,101.694405,5.180560,1.278477,-62.940544,0.128948,0.000000
107.180008,22.915802,-62.851585,0.023821,0.005057,0.128437,101.934578,5.192795,1.284366,-62.851585,0.129660,0.000000
107.610008,23.320938,-62.940544,0.023860,0.005088,0.129225,103.736717,5.284600,1.292254,-62.940544,0.130379,0.000000
108.040009,23.508247,-62.940544,0.023856,0.005116,0.129955,104.569908,5.327045,1.299551,-62.940544,0.131100,0.000000
108.470009,23.880241,-62.940544,0.023873,0.005150,0.130804,106.224617,5.411340,1.308045,-62.940544,0.131810,0.000000
108.900002,24.008713,-62.896065,0.023925,0.005176,0.131481,106.796089,5.440452,1.314812,-62.896065,0.132530,0.000000
109.330002,24.093613,-62.896065,0.023963,0.005198,0.132028,107.173744,5.459691,1.320277,-62.896065,0.133249,0.000000
109.760002,24.296928,-62.985027,0.023981,0.005223,0.132670,108.078133,5.505763,1.326697,-62.985027,0.133961,0.000000
110.190002,24.815269,-62.940544,0.024011,0.005257,0.133528,110.383835,5.623220,1.335281,-62.940544,0.134680,0.000000
110.620003,24.915070,-62.851585,0.024050,0.005286,0.134273,110.827766,5.645836,1.342729,-62.851585,0.135401,0.000000
111.050003,25.208496,-62.985027,0.024063,0.005314,0.134984,112.132988,5.712327,1.349845,-62.985027,0.136112,0.000000
111.480003,25.396545,-62.940544,0.024093,0.005342,0.135687,112.969475,5.754940,1.356870,-62.940544,0.136832,0.000000
111.910004,25.679924,-62.940544,0.024110,0.005367,0.136320,114.230003,5.819154,1.363198,-62.940544,0.137543,0.000000
112.340004,26.021385,-62.985027,0.024162,0.005401,0.137178,115.748901,5.896530,1.371782,-62.985027,0.138262,0.000000
112.770004,26.073143,-62.896065,0.024153,0.005424,0.137769,115.979134,5.908258,1.377687,-62.896065,0.138983,0.000000
113.200005,26.473076,-62.940544,0.024192,0.005459,0.138653,117.758125,5.998885,1.386528,-62.940544,0.139693,0.000000
113.630005,26.620903,-62.896065,0.024239,0.005483,0.139260,118.415688,6.032383,1.392599,-62.896065,0.140414,0.000000
114.060005,27.105736,-62.985027,0.024261,0.005517,0.140135,120.572334,6.142247,1.401350,-62.985027,0.141133,0.000000
114.490005,27.093819,-62.940544,0.024274,0.005541,0.140735,120.519325,6.139547,1.407345,-62.940544,0.141844,0.000000
114.920006,27.377197,-62.940544,0.024326,0.005568,0.141428,121.779854,6.203762,1.414279,-62.940544,0.142563,0.000000
115.350006,27.640091,-62.985027,0.024343,0.005597,0.142156,122.949265,6.263334,1.421561,-62.985027,0.143284,0.000000
115.780006,27.753662,-62.940544,0.024356,0.005617,0.142668,123.454453,6.289070,1.426678,-62.940544,0.143996,0.000000
116.210007,28.452980,-62.985027,0.024377,0.005657,0.143700,126.565178,6.447537,1.437003,-62.985027,0.144715,0.000000
116.640007,28.556496,-62.940544,0.024407,0.005687,0.144445,127.025635,6.470994,1.444452,-62.940544,0.145434,0.000000
117.070007,28.731514,-62.896065,0.024438,0.005713,0.145105,127.804153,6.510654,1.451053,-62.896065,0.146145,0.000000
117.500008,28.804497,-62.940544,0.024451,0.005733,0.145608,128.128799,6.527192,1.456079,-62.940544,0.146866,0.000000
117.930008,29.349655,-63.029507,0.024502,0.005766,0.146457,130.553787,6.650727,1.464573,-63.029507,0.147576,0.000000
118.360008,29.526901,-62.985027,0.024502,0.005796,0.147220,131.342209,6.690892,1.472203,-62.985027,0.148297,0.000000
118.790009,29.886612,-62.985027,0.024571,0.005824,0.147932,132.942291,6.772403,1.479319,-62.985027,0.149016,0.000000
119.220009,30.060883,-62.985027,0.024580,0.005850,0.148583,133.717484,6.811893,1.485829,-62.985027,0.149727,0.000000
119.650009,30.482780,-62.985027,0.024589,0.005882,0.149406,135.594177,6.907497,1.494065,-62.985027,0.150447,0.000000
120.080009,30.807121,-63.029507,0.024636,0.005914,0.150204,137.036926,6.980994,1.502043,-63.029507,0.151167,0.000000
120.510002,30.960159,-62.985027,0.024671,0.005938,0.150820,137.717667,7.015672,1.508205,-62.985027,0.151877,0.000000
120.940002,31.207047,-62.896065,0.024683,0.005967,0.151574,138.815872,7.071618,1.515744,-62.896065,0.152598,0.000000
121.370003,31.179489,-62.985027,0.024679,0.005986,0.152051,138.693298,7.065373,1.520513,-62.985027,0.153317,0.000000
121.800003,31.977112,-62.940544,0.024735,0.006026,0.153049,142.241302,7.246117,1.530490,-62.940544,0.154029,0.000000
122.230003,32.066483,-62.985027,0.024770,0.006050,0.153682,142.638840,7.266368,1.536819,-62.985027,0.154749,0.000000
122.660004,32.215805,-62.985027,0.024778,0.006074,0.154271,143.303055,7.300206,1.542708,-62.985027,0.155468,0.000000
123.090004,32.726326,-62.985027,0.024813,0.006106,0.155103,145.573975,7.415892,1.551035,-62.985027,0.156180,0.000000
123.520004,32.713295,-62.985027,0.024813,0.006128,0.155642,145.516006,7.412939,1.556424,-62.985027,0.156899,0.000000
123.950005,33.350052,-63.029507,0.024834,0.006166,0.156622,148.348434,7.557230,1.566220,-63.029507,0.157611,0.000000
124.380005,33.296799,-62.985027,0.024877,0.006186,0.157134,148.111557,7.545163,1.571337,-62.985027,0.158330,0.000000
124.810005,33.787956,-62.985027,0.024895,0.006217,0.157906,150.296341,7.656460,1.579058,-62.985027,0.159050,0.000000
125.240005,33.945473,-62.985027,0.024946,0.006243,0.158581,150.997009,7.692154,1.585810,-62.985027,0.159760,0.000000
125.670006,34.409821,-62.985027,0.024942,0.006271,0.159293,153.062531,7.797377,1.592926,-62.985027,0.160481,0.000000
126.100006,34.687241,-62.985027,0.024981,0.006305,0.160151,154.296555,7.860241,1.601510,-62.985027,0.161200,0.000000
126.530006,34.765068,-62.985027,0.025011,0.006325,0.160663,154.642746,7.877877,1.606627,-62.985027,0.161912,0.000000
126.960007,35.237976,-62.940544,0.025037,0.006358,0.161504,156.746353,7.985039,1.615045,-62.940544,0.162631,0.000000
127.390007,35.580185,-62.985027,0.025076,0.006384,0.162154,158.268570,8.062585,1.621540,-62.985027,0.163352,0.000000
127.820007,35.902290,-63.029507,0.025097,0.006414,0.162926,159.701370,8.135575,1.629261,-63.029507,0.164063,0.000000
128.250000,36.123108,-63.029507,0.025123,0.006442,0.163638,160.683609,8.185614,1.636377,-63.029507,0.164782,0.000000
128.680008,36.531601,-62.985027,0.025153,0.006470,0.164340,162.500671,8.278179,1.643401,-62.985027,0.165501,0.000000
129.110001,36.695068,-63.029507,0.025175,0.006494,0.164947,163.227814,8.315221,1.649472,-63.029507,0.166213,0.000000
129.540009,37.296455,-63.029507,0.025192,0.006529,0.165831,165.902924,8.451497,1.658314,-63.029507,0.166934,0.000000
129.970001,37.509453,-62.985027,0.025244,0.006556,0.166534,166.850372,8.499763,1.665339,-62.985027,0.167653,0.000000
130.400009,37.770485,-63.029507,0.025244,0.006584,0.167227,168.011505,8.558914,1.672273,-63.029507,0.168364,0.000000
130.830002,38.265366,-63.029507,0.025287,0.006613,0.167965,170.212845,8.671056,1.679646,-63.029507,0.169083,0.000000
131.260010,38.348404,-62.985027,0.025300,0.006633,0.168485,170.582214,8.689873,1.684854,-62.985027,0.169795,0.000000
131.690002,38.928932,-62.985027,0.025322,0.006667,0.169335,173.164536,8.821422,1.693347,-62.985027,0.170514,0.000000
132.120010,39.204117,-63.073990,0.025356,0.006696,0.170081,174.388626,8.883780,1.700811,-63.073990,0.171235,0.000000
132.550003,39.689690,-63.073990,0.025373,0.006727,0.170862,176.548553,8.993813,1.708623,-63.073990,0.171946,0.000000
132.980011,39.567177,-62.985027,0.025403,0.006744,0.171286,176.003586,8.966051,1.712862,-62.985027,0.172665,0.000000
133.410004,40.393845,-63.029507,0.025447,0.006781,0.172232,179.680801,9.153376,1.722324,-63.029507,0.173385,0.000000
133.840012,40.600517,-62.985027,0.025464,0.006808,0.172926,180.600128,9.200209,1.729258,-62.985027,0.174096,0.000000
134.270004,41.076775,-63.029507,0.025455,0.006837,0.173654,182.718613,9.308130,1.736540,-63.029507,0.174817,0.000000
134.700012,41.367599,-63.029507,0.025511,0.006865,0.174366,184.012268,9.374032,1.743656,-63.029507,0.175536,0.000000
135.130005,41.780190,-63.029507,0.025520,0.006892,0.175050,185.847565,9.467525,1.750499,-63.029507,0.176247,0.000000
135.560013,42.309700,-63.029507,0.025567,0.006928,0.175961,188.202942,9.587516,1.759613,-63.029507,0.176967,0.000000
135.990005,42.408752,-63.073990,0.025602,0.006952,0.176576,188.643555,9.609961,1.765759,-63.073990,0.177687,0.000000
136.420013,43.031731,-62.985027,0.025610,0.006982,0.177339,191.414703,9.751129,1.773390,-62.985027,0.178397,0.000000
136.850006,43.075302,-63.029507,0.025654,0.007003,0.177878,191.608521,9.761003,1.778780,-63.029507,0.179118,0.000000
137.280014,43.802917,-63.029507,0.025649,0.007033,0.178641,194.845108,9.925883,1.786410,-63.029507,0.179828,0.000000
137.710007,44.157791,-63.029507,0.025688,0.007064,0.179421,196.423660,10.006299,1.794207,-63.029507,0.180549,0.000000
138.139999,44.600540,-63.073990,0.025740,0.007092,0.180149,198.393112,10.106627,1.801489,-63.073990,0.181268,0.000000
138.570007,45.105103,-63.073990,0.025753,0.007121,0.180870,200.637512,10.220963,1.808695,-63.073990,0.181979,0.000000
139.000000,45.172501,-63.029507,0.025774,0.007140,0.181346,200.937317,10.236235,1.813464,-63.029507,0.182700,0.000000
139.430008,46.287010,-63.029507,0.025787,0.007181,0.182396,205.894897,10.488787,1.823956,-63.029507,0.183419,0.000000
139.860001,46.323135,-62.985027,0.025830,0.007202,0.182924,206.055603,10.496972,1.829240,-62.985027,0.184131,0.000000
140.290009,46.999733,-63.073990,0.025852,0.007233,0.183722,209.065247,10.650291,1.837218,-63.073990,0.184850,0.000000
140.720001,47.094315,-63.029507,0.025865,0.007256,0.184303,209.485977,10.671723,1.843032,-63.029507,0.185570,0.000000
141.150009,48.142921,-63.029507,0.025904,0.007295,0.185301,214.150406,10.909342,1.853009,-63.029507,0.186280,0.000000
141.580002,48.346977,-63.029507,0.025947,0.007320,0.185925,215.058090,10.955582,1.859246,-63.029507,0.187001,0.000000
142.010010,49.007195,-63.029507,0.025947,0.007351,0.186722,217.994888,11.105189,1.867225,-63.029507,0.187720,0.000000
142.440002,49.392227,-63.029507,0.025973,0.007374,0.187287,219.707596,11.192439,1.872872,-63.029507,0.188432,0.000000
142.870010,49.834236,-63.029507,0.025981,0.007397,0.187894,221.673752,11.292599,1.878943,-63.029507,0.189151,0.000000
143.300003,50.944649,-62.985027,0.026037,0.007436,0.188883,226.613113,11.544223,1.888829,-62.985027,0.189872,0.000000
143.730011,51.010559,-63.073990,0.026046,0.007455,0.189367,226.906296,11.559157,1.893674,-63.073990,0.190582,0.000000
144.160004,51.904625,-63.073990,0.026067,0.007487,0.190174,230.883301,11.761756,1.901743,-63.073990,0.191302,0.000000
144.590012,52.130653,-63.073990,0.026072,0.007509,0.190721,231.888733,11.812975,1.907209,-63.073990,0.192014,0.000000
145.020004,53.305489,-63.029507,0.026111,0.007545,0.191649,237.114655,12.079196,1.916489,-63.029507,0.192733,0.000000
145.450012,53.862930,-63.029507,0.026145,0.007571,0.192307,239.594284,12.205514,1.923075,-63.029507,0.193452,0.000000
145.880005,54.551819,-63.029507,0.026167,0.007598,0.192984,242.658615,12.361619,1.929842,-63.029507,0.194164,0.000000
146.310013,55.228050,-63.029507,0.026171,0.007624,0.193661,245.666641,12.514854,1.936610,-63.029507,0.194884,0.000000
146.740005,55.673035,-63.073990,0.026184,0.007648,0.194250,247.646027,12.615689,1.942499,-63.073990,0.195603,0.000000
147.170013,57.244072,-63.029507,0.026236,0.007690,0.195317,254.634354,12.971692,1.953172,-63.029507,0.196315,0.000000
147.600006,57.337914,-63.029507,0.026253,0.007711,0.195855,255.051773,12.992957,1.958547,-63.029507,0.197034,0.000000
148.030014,58.117287,-63.029507,0.026279,0.007734,0.196436,258.518616,13.169565,1.964360,-63.029507,0.197755,0.000000
148.460007,59.168495,-63.029507,0.026292,0.007766,0.197260,263.194611,13.407773,1.972596,-63.029507,0.198465,0.000000
148.890015,60.195496,-63.029507,0.026309,0.007794,0.197962,267.762939,13.640494,1.979621,-63.029507,0.199185,0.000000
149.320007,61.358788,-63.073990,0.026339,0.007829,0.198855,272.937531,13.904099,1.988554,-63.073990,0.199905,0.000000
149.750000,61.873032,-62.985027,0.026339,0.007850,0.199385,275.224976,14.020630,1.993852,-62.985027,0.200616,0.000000
150.180008,63.027763,-63.073990,0.026369,0.007880,0.200148,280.361481,14.282295,2.001483,-63.073990,0.201335,0.000000
150.610001,63.759102,-63.073990,0.026374,0.007902,0.200721,283.614655,14.448019,2.007205,-63.073990,0.202047,0.000000
151.040009,65.348015,-63.029507,0.026425,0.007938,0.201630,290.682495,14.808072,2.016304,-63.029507,0.202767,0.000000
151.470001,66.023125,-63.029507,0.026447,0.007967,0.202359,293.685516,14.961054,2.023587,-63.029507,0.203487,0.000000
151.900009,67.001350,-63.029507,0.026464,0.007989,0.202923,298.036896,15.182723,2.029234,-63.029507,0.204198,0.000000
152.330002,66.903038,-63.029507,0.026473,0.007991,0.202966,297.599579,15.160445,2.029658,-63.029507,0.203244,0.000000
152.760010,66.401085,-63.073990,0.026494,0.007982,0.202749,295.366791,15.046700,2.027493,-63.073990,0.202966,0.000000
153.190002,65.968758,-63.029507,0.026490,0.007982,0.202749,293.443695,14.948733,2.027493,-63.029507,0.202966,0.000000
153.620010,65.627663,-63.073990,0.026486,0.007982,0.202749,291.926422,14.871441,2.027493,-63.073990,0.202966,0.000000
154.050003,65.353966,-63.073990,0.026494,0.007982,0.202749,290.708954,14.809421,2.027493,-63.073990,0.202966,0.000000
154.480011,65.121239,-63.073990,0.026494,0.007982,0.202749,289.673737,14.756683,2.027493,-63.073990,0.202966,0.000000
154.910004,64.914207,-63.118469,0.026512,0.007982,0.202749,288.752808,14.709770,2.027493,-63.118469,0.202966,0.000000
155.340012,64.732491,-63.029507,0.026494,0.007982,0.202749,287.944489,14.668591,2.027493,-63.029507,0.202966,0.000000
155.770004,64.578316,-63.118469,0.026499,0.007982,0.202749,287.258698,14.633656,2.027493,-63.118469,0.202966,0.000000
156.200012,64.416710,-63.073990,0.026499,0.007982,0.202749,286.539825,14.597035,2.027493,-63.073990,0.202966,0.000000
156.630005,64.252861,-63.162949,0.026499,0.007982,0.202740,285.811005,14.559906,2.027402,-63.162949,0.202966,0.000000
157.060013,64.143394,-63.073990,0.026499,0.007982,0.202740,285.324066,14.535101,2.027402,-63.073990,0.202966,0.000000
157.490005,64.040993,-63.073990,0.026516,0.007982,0.202740,284.868561,14.511897,2.027402,-63.073990,0.202966,0.000000
157.920013,63.931145,-63.073990,0.026503,0.007982,0.202740,284.379944,14.487004,2.027402,-63.073990,0.202966,0.000000
158.350006,63.842888,-63.118469,0.026490,0.007982,0.202740,283.987335,14.467005,2.027402,-63.118469,0.202966,0.000000
158.780014,63.759850,-63.118469,0.026499,0.007982,0.202740,283.617981,14.448188,2.027402,-63.118469,0.202966,0.000000
159.210007,63.677559,-63.073990,0.026481,0.007982,0.202740,283.251923,14.429541,2.027402,-63.073990,0.202966,0.000000
159.640015,63.590050,-63.029507,0.026520,0.007982,0.202740,282.862671,14.409711,2.027402,-63.029507,0.202966,0.000000
160.070007,63.519661,-63.029507,0.026503,0.007982,0.202740,282.549561,14.393762,2.027402,-63.029507,0.202966,0.000000
160.500000,63.438866,-63.029507,0.026512,0.007982,0.202740,282.190155,14.375453,2.027402,-63.029507,0.202966,0.000000
160.930008,63.369606,-63.118469,0.026516,0.007982,0.202740,281.882080,14.359758,2.027402,-63.118469,0.202966,0.000000
161.360001,63.321938,-63.073990,0.026499,0.007982,0.202740,281.670044,14.348956,2.027402,-63.073990,0.202966,0.000000
161.790009,63.253426,-63.029507,0.026503,0.007982,0.202740,281.365295,14.333431,2.027402,-63.029507,0.202966,0.000000
162.220001,63.200920,-63.029507,0.026507,0.007982,0.202740,281.131744,14.321533,2.027402,-63.029507,0.202966,0.000000
162.650009,63.138733,-63.073990,0.026512,0.007982,0.202740,280.855103,14.307441,2.027402,-63.073990,0.202966,0.000000
163.080002,63.095535,-63.073990,0.026503,0.007982,0.202740,280.662964,14.297652,2.027402,-63.073990,0.202966,0.000000
163.510010,63.036697,-63.029507,0.026503,0.007982,0.202740,280.401245,14.284320,2.027402,-63.029507,0.202966,0.000000
163.940002,62.996109,-63.073990,0.026503,0.007982,0.202740,280.220703,14.275123,2.027402,-63.073990,0.202966,0.000000
164.370010,62.935783,-63.118469,0.026512,0.007982,0.202740,279.952332,14.261453,2.027402,-63.118469,0.202966,0.000000
164.800003,62.902275,-63.118469,0.026503,0.007982,0.202740,279.803284,14.253860,2.027402,-63.118469,0.202966,0.000000
165.230011,62.849770,-63.073990,0.026529,0.007982,0.202740,279.569733,14.241961,2.027402,-63.073990,0.202966,0.000000
165.660004,62.816628,-63.073990,0.026512,0.007982,0.202740,279.422302,14.234451,2.027402,-63.073990,0.202966,0.000000
166.090012,62.767105,-63.029507,0.026507,0.007982,0.202740,279.202026,14.223229,2.027402,-63.029507,0.202966,0.000000
166.520004,62.717949,-63.118469,0.026512,0.007982,0.202740,278.983368,14.212090,2.027402,-63.118469,0.202966,0.000000
166.950012,62.685921,-63.073990,0.026490,0.007982,0.202740,278.840912,14.204832,2.027402,-63.073990,0.202966,0.000000
167.380005,62.660973,-63.073990,0.026516,0.007982,0.202740,278.729919,14.199179,2.027402,-63.073990,0.202966,0.000000
167.810013,62.634537,-63.073990,0.026503,0.007982,0.202740,278.612335,14.193190,2.027402,-63.073990,0.202966,0.000000
168.240005,62.576447,-63.073990,0.026503,0.007982,0.202740,278.353943,14.180025,2.027402,-63.073990,0.202966,0.000000
168.670013,62.544426,-63.162949,0.026507,0.007982,0.202740,278.211487,14.172769,2.027402,-63.162949,0.202966,0.000000
169.100006,62.521706,-63.073990,0.026499,0.007982,0.202740,278.110443,14.167621,2.027402,-63.073990,0.202966,0.000000
169.530014,62.472183,-63.029507,0.026486,0.007982,0.202740,277.890137,14.156399,2.027402,-63.029507,0.202966,0.000000
169.960007,62.443886,-63.073990,0.026537,0.007982,0.202740,277.764282,14.149987,2.027402,-63.073990,0.202966,0.000000
170.390015,62.418190,-63.073990,0.026503,0.007982,0.202740,277.649963,14.144164,2.027402,-63.073990,0.202966,0.000000
170.820007,62.390633,-63.162949,0.026494,0.007982,0.202740,277.527405,14.137919,2.027402,-63.162949,0.202966,0.000000
171.250015,62.365311,-63.118469,0.026503,0.007982,0.202740,277.414764,14.132181,2.027402,-63.118469,0.202966,0.000000
171.680008,62.330307,-63.073990,0.026507,0.007982,0.202740,277.259064,14.124249,2.027402,-63.073990,0.202966,0.000000
172.110001,62.311317,-63.073990,0.026512,0.007982,0.202740,277.174591,14.119946,2.027402,-63.073990,0.202966,0.000000
172.540009,62.279663,-63.118469,0.026529,0.007982,0.202740,277.033783,14.112774,2.027402,-63.118469,0.202966,0.000000
172.970001,62.249130,-63.162949,0.026512,0.007982,0.202740,276.897949,14.105855,2.027402,-63.162949,0.202966,0.000000
173.400009,62.232376,-63.073990,0.026503,0.007982,0.202740,276.823425,14.102058,2.027402,-63.073990,0.202966,0.000000
173.830002,62.194389,-63.073990,0.026516,0.007982,0.202740,276.654449,14.093451,2.027402,-63.073990,0.202966,0.000000
174.260010,62.163116,-63.073990,0.026524,0.007982,0.202740,276.515350,14.086364,2.027402,-63.073990,0.202966,0.000000
174.690002,62.153061,-63.118469,0.026499,0.007982,0.202740,276.470612,14.084085,2.027402,-63.118469,0.202966,0.000000
175.120010,62.132950,-63.118469,0.026494,0.007982,0.202740,276.381165,14.079528,2.027402,-63.118469,0.202966,0.000000
175.550003,62.100182,-63.029507,0.026516,0.007982,0.202740,276.235413,14.072103,2.027402,-63.029507,0.202966,0.000000
175.980011,62.078957,-63.073990,0.026507,0.007982,0.202740,276.140991,14.067292,2.027402,-63.073990,0.202966,0.000000
176.410004,62.061829,-63.073990,0.026494,0.007982,0.202740,276.064789,14.063412,2.027402,-63.073990,0.202966,0.000000
176.840012,62.045441,-63.118469,0.026520,0.007982,0.202740,275.991913,14.059697,2.027402,-63.118469,0.202966,0.000000
177.270004,62.022728,-63.073990,0.026499,0.007982,0.202740,275.890869,14.054551,2.027402,-63.073990,0.202966,0.000000
177.700012,61.992943,-63.118469,0.026507,0.007982,0.202740,275.758392,14.047802,2.027402,-63.118469,0.202966,0.000000
178.130005,61.982513,-63.118469,0.026520,0.007982,0.202740,275.711975,14.045438,2.027402,-63.118469,0.202966,0.000000
178.560013,61.958305,-63.029507,0.026516,0.007982,0.202740,275.604309,14.039953,2.027402,-63.029507,0.202966,0.000000
178.990005,61.931496,-63.118469,0.026524,0.007982,0.202740,275.485046,14.033877,2.027402,-63.118469,0.202966,0.000000
179.420013,61.917351,-63.118469,0.026507,0.007982,0.202740,275.422119,14.030672,2.027402,-63.118469,0.202966,0.000000
179.850006,61.895378,-63.029507,0.026499,0.007982,0.202740,275.324402,14.025693,2.027402,-63.029507,0.202966,0.000000
180.280014,61.885696,-63.073990,0.026520,0.007982,0.202740,275.281311,14.023499,2.027402,-63.073990,0.202966,0.000000
180.710007,61.871918,-63.118469,0.026524,0.007982,0.202740,275.220032,14.020377,2.027402,-63.118469,0.202966,0.000000
181.140015,61.846970,-63.118469,0.026494,0.007982,0.202740,275.109070,14.014724,2.027402,-63.118469,0.202966,0.000000
181.570007,61.831703,-63.073990,0.026494,0.007982,0.202740,275.041138,14.011264,2.027402,-63.073990,0.202966,0.000000
182.000015,61.812340,-63.118469,0.026520,0.007982,0.202740,274.955017,14.006877,2.027402,-63.118469,0.202966,0.000000
182.430008,61.804146,-63.118469,0.026499,0.007982,0.202740,274.918579,14.005020,2.027402,-63.118469,0.202966,0.000000
182.600006,61.789627,-63.118469,0.026529,0.007982,0.202740,274.853973,14.001730,2.027402,-63.118469,0.202966,0.000000