File: Data/New old I18 6 new align_08182023_121251.csv
Time (sec),S:Load (lbs),S:HL1 (DIM),S:LVDT (in),S:Position (in),Ch:Position (mm),Ch:Load (N),Ch:Stress (MPa),Ch:Strain (mm/mm),Ch:HL1 (DIM),Set Point (),Cycles ()
0.110000,0.001869,-48.261833,0.000009,-0.000000,-0.000000,0.008315,0.000424,-0.000000,-48.261833,0.000207,0.000000
0.510000,-0.014893,-48.350792,-0.000022,0.000063,0.001605,-0.066245,-0.003375,0.016048,-48.350792,0.002150,0.000000
0.910000,0.009682,-48.306313,0.000121,0.000302,0.007674,0.043066,0.002194,0.076743,-48.306313,0.008811,0.000000
1.310000,0.011551,-48.395275,0.000397,0.000569,0.014457,0.051381,0.002617,0.144568,-48.395275,0.015471,0.000000
1.710000,0.032402,-48.395275,0.000668,0.000828,0.021021,0.144131,0.007342,0.210213,-48.395275,0.022131,0.000000
2.110000,0.039474,-48.395275,0.000940,0.001090,0.027681,0.175591,0.008945,0.276812,-48.395275,0.028791,0.000000
2.510000,0.027557,-48.350792,0.001186,0.001353,0.034376,0.122581,0.006245,0.343759,-48.350792,0.035469,0.000000
2.910000,0.064423,-48.439754,0.001444,0.001610,0.040898,0.286566,0.014598,0.408981,-48.439754,0.042129,0.000000
3.310000,0.055862,-48.395275,0.001712,0.001869,0.047481,0.248488,0.012659,0.474808,-48.395275,0.048790,0.000000
3.710000,0.035004,-48.439754,0.002022,0.002134,0.054210,0.155704,0.007932,0.542103,-48.439754,0.055450,0.000000
4.110000,0.035751,-48.439754,0.002268,0.002401,0.060984,0.159030,0.008101,0.609837,-48.439754,0.062128,0.000000
4.510000,0.014153,-48.439754,0.002535,0.002666,0.067704,0.062954,0.003207,0.677042,-48.439754,0.068788,0.000000
4.910000,0.024582,-48.484238,0.002824,0.002929,0.074399,0.109346,0.005570,0.743989,-48.484238,0.075448,0.000000
5.310000,0.051018,-48.484238,0.003104,0.003190,0.081016,0.226938,0.011561,0.810164,-48.484238,0.082108,0.000000
5.710000,0.034637,-48.484238,0.003372,0.003454,0.087720,0.154075,0.007849,0.877202,-48.484238,0.088769,0.000000
6.110000,0.031654,-48.528717,0.003613,0.003712,0.094285,0.140806,0.007173,0.942848,-48.528717,0.095446,0.000000
6.510000,0.005219,-48.528717,0.003889,0.003974,0.100945,0.023213,0.001183,1.009447,-48.528717,0.102107,0.000000
6.910000,-0.016380,-48.528717,0.004186,0.004236,0.107588,-0.072863,-0.003712,1.075879,-48.528717,0.108767,0.000000
7.310000,0.051392,-48.528717,0.004432,0.004502,0.114343,0.228601,0.011646,1.143432,-48.528717,0.115427,0.000000
7.710001,0.048042,-48.484238,0.004712,0.004765,0.121030,0.213703,0.010887,1.210303,-48.484238,0.122087,0.000000
8.110001,0.065910,-48.573200,0.004971,0.005025,0.127646,0.293184,0.014935,1.276463,-48.573200,0.128765,0.000000
8.510000,0.058838,-48.573200,0.005251,0.005287,0.134299,0.261724,0.013333,1.342987,-48.573200,0.135425,0.000000
8.910001,0.062187,-48.573200,0.005519,0.005551,0.140984,0.276622,0.014092,1.409843,-48.573200,0.142086,0.000000
9.310000,0.084908,-48.617680,0.005756,0.005805,0.147453,0.377688,0.019240,1.474535,-48.617680,0.148746,0.000000
9.710000,0.081924,-48.573200,0.006058,0.006069,0.154150,0.364418,0.018564,1.541497,-48.573200,0.155406,0.000000
10.110001,0.068520,-48.662159,0.006303,0.006332,0.160826,0.304790,0.015527,1.608262,-48.662159,0.162084,0.000000
10.510000,0.068520,-48.617680,0.006592,0.006598,0.167591,0.304790,0.015527,1.675906,-48.617680,0.168744,0.000000
10.910001,0.056976,-48.706642,0.006842,0.006862,0.174294,0.253443,0.012911,1.742944,-48.706642,0.175404,0.000000
11.310000,0.050644,-48.617680,0.007123,0.007125,0.180972,0.225275,0.011476,1.809725,-48.617680,0.182066,0.000000
11.710001,0.077454,-48.617680,0.007429,0.007386,0.187598,0.344531,0.017551,1.875976,-48.617680,0.188725,0.000000
12.110001,0.056602,-48.706642,0.007692,0.007650,0.194301,0.251780,0.012826,1.943014,-48.706642,0.195404,0.000000
12.510000,0.068146,-48.662159,0.007912,0.007907,0.200849,0.303127,0.015442,2.008492,-48.662159,0.202063,0.000000
12.910001,0.034264,-48.662159,0.008248,0.008171,0.207535,0.152412,0.007764,2.075349,-48.662159,0.208723,0.000000
13.310000,0.027931,-48.751122,0.008498,0.008435,0.214239,0.124244,0.006329,2.142387,-48.751122,0.215383,0.000000
13.710001,0.074104,-48.662159,0.008761,0.008696,0.220882,0.329632,0.016792,2.208819,-48.662159,0.222061,0.000000
14.110001,0.077454,-48.706642,0.009028,0.008961,0.227621,0.344531,0.017551,2.276206,-48.706642,0.228721,0.000000
14.510000,0.085648,-48.795605,0.009339,0.009222,0.234229,0.380979,0.019408,2.342290,-48.795605,0.235383,0.000000
14.910001,0.093468,-48.751122,0.009610,0.009485,0.240924,0.415765,0.021180,2.409237,-48.751122,0.242043,0.000000
15.310000,0.088257,-48.751122,0.009882,0.009746,0.247558,0.392586,0.019999,2.475579,-48.751122,0.248702,0.000000
15.710001,0.112091,-48.751122,0.010132,0.010002,0.254062,0.498606,0.025400,2.540618,-48.751122,0.255380,0.000000
16.110001,0.102409,-48.795605,0.010412,0.010266,0.260766,0.455540,0.023206,2.607656,-48.795605,0.262040,0.000000
16.510000,0.091606,-48.795605,0.010684,0.010531,0.267486,0.407484,0.020758,2.674861,-48.795605,0.268700,0.000000
16.910002,0.075592,-48.840084,0.010956,0.010798,0.274260,0.336250,0.017129,2.742595,-48.840084,0.275362,0.000000
17.310001,0.074478,-48.840084,0.011232,0.011061,0.280938,0.331295,0.016877,2.809376,-48.840084,0.282022,0.000000
17.710001,0.066658,-48.795605,0.011538,0.011323,0.287598,0.296510,0.015105,2.875975,-48.795605,0.288700,0.000000
18.110001,0.103897,-48.840084,0.011783,0.011583,0.294206,0.462157,0.023543,2.942060,-48.840084,0.295360,0.000000
18.510000,0.080811,-48.840084,0.012081,0.011849,0.300954,0.359463,0.018312,3.009537,-48.840084,0.302019,0.000000
18.910002,0.084908,-48.884563,0.012331,0.012107,0.307518,0.377688,0.019240,3.075182,-48.884563,0.308679,0.000000
19.310001,0.060326,-48.840084,0.012616,0.012370,0.314204,0.268342,0.013670,3.142038,-48.840084,0.315341,0.000000
19.710001,0.063683,-48.884563,0.012878,0.012634,0.320899,0.283274,0.014431,3.208985,-48.884563,0.322017,0.000000
20.110001,0.107246,-48.884563,0.013150,0.012896,0.327568,0.477056,0.024302,3.275675,-48.884563,0.328679,0.000000
20.510000,0.100548,-48.929047,0.013405,0.013161,0.334280,0.447259,0.022784,3.342804,-48.929047,0.335339,0.000000
20.910002,0.120651,-48.929047,0.013693,0.013421,0.340889,0.536684,0.027340,3.408888,-48.929047,0.341999,0.000000
21.310001,0.117676,-48.884563,0.013974,0.013683,0.347541,0.523448,0.026666,3.475412,-48.884563,0.348658,0.000000
21.710001,0.125496,-48.929047,0.014237,0.013943,0.354148,0.558234,0.028438,3.541481,-48.929047,0.355337,0.000000
22.110001,0.162361,-48.929047,0.014538,0.014200,0.360679,0.722218,0.036792,3.606793,-48.929047,0.361996,0.000000
22.510000,0.156769,-48.973526,0.014797,0.014469,0.367504,0.697342,0.035524,3.675042,-48.973526,0.368658,0.000000
22.910002,0.131821,-48.929047,0.015073,0.014734,0.374234,0.586368,0.029871,3.742338,-48.929047,0.375318,0.000000
23.310001,0.124374,-48.929047,0.015340,0.014996,0.380903,0.553245,0.028184,3.809027,-48.929047,0.381996,0.000000
23.710001,0.105385,-48.973526,0.015621,0.015261,0.387632,0.468775,0.023881,3.876323,-48.973526,0.388656,0.000000
24.110001,0.090866,-48.973526,0.015901,0.015521,0.394232,0.404193,0.020591,3.942316,-48.973526,0.395316,0.000000
24.510000,0.112091,-48.973526,0.016155,0.015782,0.400866,0.498606,0.025400,4.008658,-48.973526,0.401976,0.000000
24.910002,0.116554,-49.018009,0.016444,0.016047,0.407588,0.518459,0.026412,4.075878,-49.018009,0.408637,0.000000
25.310001,0.113579,-49.018009,0.016724,0.016307,0.414204,0.505224,0.025737,4.142038,-49.018009,0.415313,0.000000
25.710001,0.102409,-49.018009,0.016996,0.016567,0.420812,0.455540,0.023206,4.208122,-49.018009,0.421975,0.000000
26.110001,0.094589,-48.973526,0.017255,0.016830,0.427490,0.420754,0.021434,4.274903,-48.973526,0.428635,0.000000
26.510002,0.151932,-49.062489,0.017531,0.017093,0.434168,0.675826,0.034428,4.341683,-49.062489,0.435295,0.000000
26.910002,0.147461,-49.018009,0.017811,0.017357,0.440871,0.655939,0.033415,4.408706,-49.018009,0.441955,0.000000
27.310001,0.193268,-49.018009,0.018104,0.017617,0.447462,0.859698,0.043795,4.474624,-49.018009,0.448633,0.000000
27.710001,0.262527,-49.062489,0.018371,0.017879,0.454131,1.167781,0.059490,4.541314,-49.062489,0.455293,0.000000
28.110001,0.496376,-49.018009,0.018660,0.018140,0.460766,2.207991,0.112480,4.607656,-49.018009,0.461954,0.000000
28.510002,0.540688,-49.062489,0.018815,-0.000005,-0.000139,2.405098,0.122522,-0.001393,-49.062489,0.000095,0.000000
28.910002,0.615166,-49.062489,0.018833,-0.000005,-0.000139,2.736394,0.139399,-0.001393,-49.062489,0.000216,0.000000
29.310001,0.590218,-49.062489,0.018815,0.000001,0.000018,2.625419,0.133745,0.000182,-49.062489,0.000884,0.000000
29.710001,0.681816,-49.106972,0.018820,0.000026,0.000668,3.032870,0.154502,0.006677,-49.106972,0.001552,0.000000
30.110001,0.698944,-49.106972,0.018828,0.000048,0.001214,3.109059,0.158383,0.012142,-49.106972,0.002212,0.000000
30.510002,0.744377,-49.106972,0.018846,0.000075,0.001917,3.311155,0.168678,0.019167,-49.106972,0.002880,0.000000
30.910002,0.862045,-49.106972,0.018863,0.000101,0.002568,3.834569,0.195342,0.025677,-49.106972,0.003547,0.000000
31.310001,0.934662,-49.151451,0.018880,0.000122,0.003087,4.157584,0.211797,0.030870,-49.151451,0.004215,0.000000
31.710001,0.981949,-49.151451,0.018928,0.000152,0.003859,4.367927,0.222513,0.038591,-49.151451,0.004883,0.000000
32.110001,1.008385,-49.151451,0.018949,0.000175,0.004440,4.485519,0.228503,0.044404,-49.151451,0.005550,0.000000
32.510002,1.072433,-49.151451,0.018971,0.000204,0.005178,4.770422,0.243017,0.051777,-49.151451,0.006218,0.000000
32.910000,1.158829,-49.195930,0.019005,0.000230,0.005854,5.154727,0.262594,0.058545,-49.195930,0.006885,0.000000
33.310001,1.240379,-49.106972,0.019053,0.000252,0.006400,5.517483,0.281074,0.063995,-49.106972,0.007546,0.000000
33.710003,1.321556,-49.151451,0.019048,0.000285,0.007250,5.878575,0.299469,0.072503,-49.151451,0.008213,0.000000
34.110001,1.335701,-49.151451,0.019066,0.000308,0.007823,5.941495,0.302674,0.078226,-49.151451,0.008881,0.000000
34.510002,1.454491,-49.151451,0.019087,0.000337,0.008569,6.469898,0.329592,0.085690,-49.151451,0.009549,0.000000
34.910000,1.530830,-49.240414,0.019135,0.000363,0.009228,6.809474,0.346891,0.092276,-49.240414,0.010216,0.000000
35.310001,1.617218,-49.240414,0.019147,0.000387,0.009826,7.193745,0.366467,0.098256,-49.240414,0.010884,0.000000
35.710003,1.722595,-49.240414,0.019186,0.000419,0.010633,7.662486,0.390346,0.106325,-49.240414,0.011551,0.000000
36.110001,1.778824,-49.195930,0.019203,0.000445,0.011309,7.912604,0.403087,0.113093,-49.195930,0.012219,0.000000
36.510002,1.873413,-49.195930,0.019229,0.000470,0.011933,8.333358,0.424521,0.119330,-49.195930,0.012878,0.000000
36.910000,1.949371,-49.240414,0.019255,0.000491,0.012470,8.671237,0.441734,0.124705,-49.240414,0.013547,0.000000
37.310001,2.114334,-49.240414,0.019277,0.000520,0.013217,9.405027,0.479115,0.132169,-49.240414,0.014215,0.000000
37.710003,2.216362,-49.240414,0.019337,0.000548,0.013928,9.858871,0.502235,0.139284,-49.240414,0.014882,0.000000
38.110001,2.341850,-49.240414,0.019337,0.000576,0.014638,10.417070,0.530671,0.146385,-49.240414,0.015550,0.000000
38.510002,2.439041,-49.240414,0.019359,0.000601,0.015255,10.849397,0.552695,0.152546,-49.240414,0.016218,0.000000
38.910004,2.524689,-49.329376,0.019376,0.000620,0.015741,11.230376,0.572103,0.157406,-49.329376,0.016885,0.000000
39.310001,2.754440,-49.329376,0.019406,0.000655,0.016641,12.252362,0.624165,0.166414,-49.329376,0.017553,0.000000
39.710003,2.782745,-49.329376,0.019445,0.000676,0.017162,12.378269,0.630579,0.171622,-49.329376,0.018220,0.000000
40.110001,2.917168,-49.284893,0.019449,0.000700,0.017769,12.976210,0.661040,0.177693,-49.284893,0.018879,0.000000
40.510002,3.075424,-49.240414,0.019497,0.000728,0.018490,13.680170,0.696901,0.184900,-49.240414,0.019547,0.000000
40.910004,3.205757,-49.284893,0.019505,0.000750,0.019053,14.259920,0.726435,0.190532,-49.284893,0.020216,0.000000
41.310001,3.401627,-49.329376,0.019527,0.000785,0.019928,15.131190,0.770820,0.199282,-49.329376,0.020884,0.000000
41.710003,3.480194,-49.284893,0.019570,0.000808,0.020519,15.480677,0.788623,0.205187,-49.284893,0.021551,0.000000
42.110001,3.691330,-49.329376,0.019587,0.000840,0.021326,16.419855,0.836467,0.213256,-49.329376,0.022219,0.000000
42.510002,3.727081,-49.373856,0.019626,0.000859,0.021819,16.578886,0.844569,0.218192,-49.373856,0.022887,0.000000
42.910004,3.892784,-49.329376,0.019639,0.000882,0.022391,17.315969,0.882117,0.223914,-49.329376,0.023554,0.000000
43.310001,4.087906,-49.373856,0.019669,0.000916,0.023259,18.183914,0.926333,0.232589,-49.373856,0.024213,0.000000
43.710003,4.128494,-49.329376,0.019686,0.000938,0.023815,18.364460,0.935530,0.238146,-49.329376,0.024880,0.000000
44.110001,4.280800,-49.418335,0.019712,0.000962,0.024438,19.041948,0.970043,0.244383,-49.418335,0.025548,0.000000
44.510002,4.476295,-49.418335,0.019738,0.000991,0.025176,19.911556,1.014343,0.251756,-49.418335,0.026216,0.000000
44.910004,4.543320,-49.373856,0.019773,0.001010,0.025662,20.209696,1.029531,0.256616,-49.373856,0.026883,0.000000
45.310001,4.762276,-49.462818,0.019803,0.001047,0.026597,21.183661,1.079147,0.265972,-49.462818,0.027553,0.000000
45.710003,4.777168,-49.373856,0.019816,0.001065,0.027048,21.249907,1.082522,0.270484,-49.373856,0.028220,0.000000
46.110001,4.932076,-49.418335,0.019846,0.001091,0.027716,21.938967,1.117624,0.277160,-49.418335,0.028888,0.000000
46.510002,5.138374,-49.462818,0.019872,0.001121,0.028479,22.856630,1.164372,0.284791,-49.462818,0.029546,0.000000
46.910004,5.238914,-49.418335,0.019889,0.001145,0.029079,23.303856,1.187155,0.290786,-49.418335,0.030214,0.000000
47.310001,5.428452,-49.507298,0.019928,0.001177,0.029884,24.146959,1.230105,0.298840,-49.507298,0.030882,0.000000
47.710003,5.482819,-49.507298,0.019941,0.001203,0.030553,24.388796,1.242424,0.305532,-49.507298,0.031549,0.000000
48.110001,5.544998,-49.418335,0.019971,0.001221,0.031012,24.665384,1.256515,0.310119,-49.418335,0.032217,0.000000
48.510002,5.747574,-49.507298,0.019997,0.001251,0.031775,25.566484,1.302419,0.317750,-49.507298,0.032885,0.000000
48.910004,5.880508,-49.507298,0.020001,0.001279,0.032477,26.157808,1.332542,0.324774,-49.507298,0.033552,0.000000
49.310001,6.022385,-49.462818,0.020040,0.001306,0.033163,26.788904,1.364692,0.331632,-49.462818,0.034222,0.000000
49.710003,6.029457,-49.551781,0.020074,0.001328,0.033736,26.820364,1.366295,0.337355,-49.551781,0.034880,0.000000
50.110001,6.220856,-49.551781,0.020079,0.001355,0.034412,27.671749,1.409666,0.344123,-49.551781,0.035548,0.000000
50.510002,6.352676,-49.507298,0.020126,0.001382,0.035115,28.258116,1.439537,0.351147,-49.507298,0.036215,0.000000
50.910004,6.513168,-49.551781,0.020122,0.001410,0.035825,28.972019,1.475905,0.358248,-49.551781,0.036883,0.000000
51.310001,6.625626,-49.596260,0.020139,0.001439,0.036545,29.472254,1.501388,0.365454,-49.596260,0.037551,0.000000
51.710003,6.640518,-49.596260,0.020191,0.001461,0.037100,29.538500,1.504763,0.370995,-49.596260,0.038218,0.000000
52.110001,6.911980,-49.596260,0.020208,0.001490,0.037846,30.746021,1.566277,0.378459,-49.596260,0.038886,0.000000
52.510002,6.965599,-49.596260,0.020230,0.001512,0.038402,30.984531,1.578427,0.384015,-49.596260,0.039554,0.000000
52.910004,7.202057,-49.551781,0.020264,0.001540,0.039121,32.036350,1.632009,0.391207,-49.551781,0.040221,0.000000
53.310001,7.278770,-49.596260,0.020294,0.001567,0.039806,32.377586,1.649393,0.398065,-49.596260,0.040881,0.000000
53.710003,7.254562,-49.596260,0.020307,0.001585,0.040265,32.269905,1.643907,0.402652,-49.596260,0.041549,0.000000
54.110004,7.499954,-49.640743,0.020350,0.001619,0.041124,33.361462,1.699514,0.411236,-49.640743,0.042217,0.000000
54.510002,7.574432,-49.596260,0.020342,0.001639,0.041626,33.692757,1.716391,0.416263,-49.596260,0.042884,0.000000
54.910004,7.771416,-49.640743,0.020385,0.001670,0.042424,34.568985,1.761028,0.424241,-49.640743,0.043552,0.000000
55.310001,7.813492,-49.640743,0.020402,0.001694,0.043031,34.756149,1.770563,0.430312,-49.640743,0.044220,0.000000
55.710003,8.024261,-49.596260,0.020415,0.001725,0.043812,35.693699,1.818324,0.438124,-49.596260,0.044887,0.000000
56.110004,8.076759,-49.596260,0.020471,0.001750,0.044445,35.927219,1.830220,0.444453,-49.596260,0.045555,0.000000
56.510002,8.147141,-49.640743,0.020501,0.001772,0.045001,36.240292,1.846168,0.450009,-49.640743,0.046215,0.000000
56.910004,8.433868,-49.685223,0.020510,0.001808,0.045911,37.515720,1.911142,0.459108,-49.685223,0.046883,0.000000
57.310001,8.398865,-49.729702,0.020536,0.001829,0.046457,37.360016,1.903210,0.464573,-49.729702,0.047550,0.000000
57.710003,8.507225,-49.685223,0.020562,0.001853,0.047055,37.842026,1.927765,0.470553,-49.685223,0.048218,0.000000
58.110004,8.665482,-49.729702,0.020587,0.001880,0.047741,38.545986,1.963626,0.477412,-49.729702,0.048886,0.000000
58.510002,8.707191,-49.729702,0.020596,0.001898,0.048209,38.731522,1.973078,0.482090,-49.729702,0.049553,0.000000
58.910004,9.038231,-49.685223,0.020639,0.001938,0.049232,40.204060,2.048092,0.492324,-49.685223,0.050221,0.000000
59.310001,9.115311,-49.685223,0.020695,0.001964,0.049883,40.546928,2.065559,0.498834,-49.685223,0.050889,0.000000
59.710003,9.172653,-49.729702,0.020700,0.001987,0.050472,40.801998,2.078553,0.504723,-49.729702,0.051549,0.000000
60.110004,9.304848,-49.729702,0.020725,0.002013,0.051140,41.390030,2.108509,0.511400,-49.729702,0.052216,0.000000
60.510002,9.505554,-49.729702,0.020751,0.002035,0.051687,42.282818,2.153989,0.516865,-49.729702,0.052884,0.000000
60.910004,9.635513,-49.729702,0.020747,0.002067,0.052503,42.860905,2.183439,0.525025,-49.729702,0.053552,0.000000
61.310001,9.737167,-49.729702,0.020799,0.002091,0.053110,43.313084,2.206474,0.531096,-49.729702,0.054219,0.000000
61.710003,9.893570,-49.729702,0.020820,0.002119,0.053829,44.008797,2.241915,0.538288,-49.729702,0.054887,0.000000
62.110004,9.965805,-49.774185,0.020838,0.002142,0.054410,44.330116,2.258284,0.544101,-49.774185,0.055555,0.000000
62.510002,10.187744,-49.774185,0.020855,0.002172,0.055173,45.317348,2.308576,0.551732,-49.774185,0.056222,0.000000
62.910004,10.245834,-49.818665,0.020898,0.002198,0.055824,45.575748,2.321739,0.558242,-49.818665,0.056881,0.000000
63.310001,10.350098,-49.774185,0.020907,0.002224,0.056483,46.039536,2.345366,0.564827,-49.774185,0.057549,0.000000
63.710003,10.534050,-49.818665,0.020937,0.002254,0.057262,46.857796,2.387050,0.572624,-49.818665,0.058216,0.000000
64.110001,10.506866,-49.818665,0.020941,0.002269,0.057636,46.736877,2.380890,0.576364,-49.818665,0.058885,0.000000
64.510002,10.812210,-49.818665,0.020988,0.002303,0.058486,48.095112,2.450082,0.584857,-49.818665,0.059553,0.000000
64.910004,10.961906,-49.863148,0.021019,0.002334,0.059274,48.760994,2.484004,0.592745,-49.863148,0.060221,0.000000
65.310005,11.016640,-49.863148,0.021019,0.002355,0.059821,49.004459,2.496406,0.598210,-49.863148,0.060888,0.000000
65.710007,11.191284,-49.818665,0.021070,0.002383,0.060533,49.781319,2.535981,0.605326,-49.818665,0.061556,0.000000
66.110001,11.327950,-49.863148,0.021092,0.002405,0.061079,50.389236,2.566950,0.610791,-49.863148,0.062224,0.000000
66.510002,11.632545,-49.863148,0.021122,0.002438,0.061928,51.744148,2.635972,0.619285,-49.863148,0.062882,0.000000
66.910004,11.594193,-49.863148,0.021126,0.002462,0.062545,51.573544,2.627282,0.625446,-49.863148,0.063550,0.000000
67.310005,11.777031,-49.863148,0.021148,0.002487,0.063161,52.386848,2.668713,0.631608,-49.863148,0.064218,0.000000
67.710007,11.992256,-49.907627,0.021187,0.002514,0.063854,53.344219,2.717484,0.638542,-49.907627,0.064885,0.000000
68.110001,11.864906,-49.907627,0.021204,0.002529,0.064227,52.777740,2.688626,0.642266,-49.907627,0.065554,0.000000
68.510002,12.258507,-49.907627,0.021221,0.002565,0.065155,54.528561,2.777817,0.651547,-49.907627,0.066222,0.000000
68.910004,12.340057,-49.863148,0.021243,0.002590,0.065788,54.891315,2.796297,0.657875,-49.863148,0.066890,0.000000
69.310005,12.302818,-49.863148,0.021295,0.002611,0.066308,54.725670,2.787858,0.663083,-49.863148,0.067557,0.000000
69.710007,12.825256,-49.907627,0.021299,0.002644,0.067158,57.049591,2.906245,0.671577,-49.907627,0.068216,0.000000
70.110001,12.742218,-49.907627,0.021316,0.002664,0.067662,56.680218,2.887428,0.676618,-49.907627,0.068884,0.000000
70.510002,12.959679,-49.907627,0.021342,0.002695,0.068458,57.647530,2.936705,0.684582,-49.907627,0.069551,0.000000
70.910004,13.076233,-49.907627,0.021368,0.002722,0.069135,58.165989,2.963117,0.691349,-49.907627,0.070219,0.000000
71.310005,13.243431,-49.952106,0.021407,0.002746,0.069760,58.909725,3.001004,0.697602,-49.952106,0.070887,0.000000
71.710007,13.443764,-49.907627,0.021445,0.002773,0.070444,59.800846,3.046400,0.704445,-49.907627,0.071554,0.000000
72.110001,13.659370,-49.907627,0.021471,0.002801,0.071147,60.759914,3.095258,0.711469,-49.907627,0.072223,0.000000
72.510002,13.837364,-49.996590,0.021480,0.002830,0.071875,61.551670,3.135592,0.718752,-49.996590,0.072891,0.000000
72.910004,13.899551,-49.996590,0.021510,0.002854,0.072491,61.828293,3.149683,0.724913,-49.996590,0.073550,0.000000
73.310005,14.016472,-49.952106,0.021540,0.002875,0.073021,62.348381,3.176178,0.730212,-49.952106,0.074217,0.000000
73.710007,14.246231,-49.996590,0.021549,0.002903,0.073740,63.370399,3.228242,0.737404,-49.996590,0.074885,0.000000
74.110001,14.300598,-49.996590,0.021592,0.002922,0.074217,63.612236,3.240562,0.742172,-49.996590,0.075553,0.000000
74.510002,14.691216,-49.952106,0.021618,0.002958,0.075145,65.349792,3.329077,0.751453,-49.952106,0.076220,0.000000
74.910004,14.791382,-49.952106,0.021635,0.002982,0.075734,65.795349,3.351775,0.757342,-49.952106,0.076888,0.000000
75.310005,15.005867,-49.996590,0.021665,0.003010,0.076446,66.749428,3.400378,0.764458,-49.996590,0.077556,0.000000
75.710007,15.022629,-49.996590,0.021678,0.003029,0.076948,66.823990,3.404176,0.769484,-49.996590,0.078223,0.000000
76.110001,15.362602,-50.085552,0.021691,0.003059,0.077695,68.336266,3.481215,0.776948,-50.085552,0.078883,0.000000
76.510002,15.513786,-50.041069,0.021747,0.003090,0.078484,69.008766,3.515474,0.784836,-50.041069,0.079551,0.000000
76.910004,15.575226,-49.996590,0.021765,0.003111,0.079030,69.282066,3.529397,0.790301,-49.996590,0.080219,0.000000
77.310005,15.880203,-50.085552,0.021786,0.003142,0.079802,70.638672,3.598505,0.798022,-50.085552,0.080886,0.000000
77.710007,15.910736,-50.041069,0.021821,0.003162,0.080305,70.774490,3.605424,0.803049,-50.041069,0.081554,0.000000
78.110001,16.388863,-50.085552,0.021825,0.003196,0.081181,72.901299,3.713769,0.811815,-50.085552,0.082222,0.000000
78.510002,16.367638,-50.041069,0.021881,0.003220,0.081779,72.806885,3.708960,0.817795,-50.041069,0.082889,0.000000
78.910004,16.554192,-50.041069,0.021907,0.003247,0.082473,73.636719,3.751233,0.824729,-50.041069,0.083557,0.000000
79.310005,16.708725,-50.041069,0.021920,0.003273,0.083133,74.324120,3.786251,0.831329,-50.041069,0.084225,0.000000
79.710007,16.716545,-50.041069,0.021933,0.003290,0.083566,74.358910,3.788023,0.835659,-50.041069,0.084885,0.000000
80.110001,17.207336,-50.085552,0.021967,0.003327,0.084511,76.542053,3.899238,0.845106,-50.085552,0.085552,0.000000
80.510002,17.289253,-50.085552,0.021980,0.003353,0.085162,76.906441,3.917801,0.851617,-50.085552,0.086220,0.000000
80.910004,17.419586,-50.085552,0.022040,0.003379,0.085829,77.486191,3.947335,0.858293,-50.085552,0.086888,0.000000
81.310005,17.638168,-50.041069,0.022053,0.003404,0.086462,78.458488,3.996866,0.864621,-50.041069,0.087555,0.000000
81.710007,17.542099,-50.130032,0.022058,0.003418,0.086827,78.031151,3.975096,0.868270,-50.130032,0.088223,0.000000
82.110001,18.102142,-50.085552,0.022109,0.003461,0.087920,80.522354,4.102004,0.879201,-50.085552,0.088891,0.000000
82.510002,18.063423,-50.174511,0.022140,0.003481,0.088414,80.350121,4.093230,0.884136,-50.174511,0.089558,0.000000
82.910004,18.351265,-50.085552,0.022144,0.003508,0.089107,81.630501,4.158456,0.891070,-50.085552,0.090218,0.000000
83.310005,18.501701,-50.130032,0.022200,0.003534,0.089775,82.299675,4.192545,0.897747,-50.130032,0.090886,0.000000
83.710007,18.667404,-50.130032,0.022191,0.003558,0.090382,83.036758,4.230094,0.903818,-50.130032,0.091554,0.000000
84.110001,18.983925,-50.174511,0.022234,0.003590,0.091180,84.444717,4.301819,0.911796,-50.174511,0.092221,0.000000
84.510002,19.055794,-50.130032,0.022252,0.003613,0.091779,84.764404,4.318105,0.917792,-50.130032,0.092889,0.000000
84.910004,19.290016,-50.130032,0.022282,0.003642,0.092498,85.806274,4.371180,0.924983,-50.130032,0.093557,0.000000
85.310005,19.330231,-50.130032,0.022295,0.003662,0.093027,85.985161,4.380293,0.930267,-50.130032,0.094224,0.000000
85.710007,19.581207,-50.174511,0.022295,0.003687,0.093661,87.101562,4.437165,0.936610,-50.174511,0.094892,0.000000
86.110001,19.900703,-50.174511,0.022351,0.003722,0.094527,88.522751,4.509564,0.945270,-50.174511,0.095550,0.000000
86.510002,19.975182,-50.174511,0.022360,0.003744,0.095101,88.854042,4.526441,0.951008,-50.174511,0.096218,0.000000
86.910004,20.096199,-50.218994,0.022398,0.003769,0.095734,89.392357,4.553864,0.957336,-50.218994,0.096887,0.000000
87.310005,20.297653,-50.218994,0.022416,0.003794,0.096357,90.288467,4.599514,0.963574,-50.218994,0.097555,0.000000
87.710007,20.365051,-50.263474,0.022441,0.003816,0.096921,90.588272,4.614787,0.969206,-50.263474,0.098223,0.000000
88.110001,20.745987,-50.174511,0.022467,0.003850,0.097788,92.282761,4.701108,0.977881,-50.174511,0.098890,0.000000
88.510002,20.717690,-50.218994,0.022519,0.003870,0.098300,92.156883,4.694695,0.982998,-50.218994,0.099558,0.000000
88.910004,21.080757,-50.218994,0.022523,0.003898,0.099011,93.771889,4.776968,0.990113,-50.218994,0.100226,0.000000
89.310005,21.291885,-50.218994,0.022536,0.003926,0.099723,94.711037,4.824811,0.997229,-50.218994,0.100884,0.000000
89.710007,21.325027,-50.307957,0.022566,0.003946,0.100216,94.858459,4.832321,1.002164,-50.307957,0.101552,0.000000
90.110001,21.650856,-50.218994,0.022597,0.003977,0.101023,96.307816,4.906154,1.010234,-50.218994,0.102219,0.000000
90.510002,21.851189,-50.218994,0.022644,0.004005,0.101735,97.198944,4.951550,1.017349,-50.218994,0.102887,0.000000
90.910004,21.878006,-50.218994,0.022653,0.004026,0.102263,97.318230,4.957627,1.022633,-50.218994,0.103556,0.000000
91.310005,22.229897,-50.263474,0.022683,0.004055,0.102992,98.883522,5.037367,1.029915,-50.263474,0.104224,0.000000
91.710007,22.542313,-50.307957,0.022713,0.004087,0.103815,100.273216,5.108161,1.038151,-50.307957,0.104892,0.000000
92.110001,22.646576,-50.307957,0.022739,0.004112,0.104457,100.737000,5.131787,1.044570,-50.307957,0.105559,0.000000
92.510002,22.677116,-50.307957,0.022765,0.004135,0.105038,100.872849,5.138708,1.050384,-50.307957,0.106227,0.000000
92.910004,23.177208,-50.263474,0.022786,0.004166,0.105811,103.097366,5.252030,1.058105,-50.263474,0.106885,0.000000
93.310005,23.253548,-50.307957,0.022812,0.004186,0.106322,103.436943,5.269330,1.063222,-50.307957,0.107553,0.000000
93.710007,23.386856,-50.218994,0.022834,0.004214,0.107041,104.029930,5.299537,1.070414,-50.218994,0.108221,0.000000
94.110008,23.551819,-50.307957,0.022842,0.004239,0.107683,104.763725,5.336918,1.076833,-50.307957,0.108888,0.000000
94.510002,23.808754,-50.352436,0.022860,0.004268,0.108395,105.906624,5.395141,1.083948,-50.352436,0.109556,0.000000
94.910004,24.206818,-50.218994,0.022911,0.004295,0.109097,107.677299,5.485343,1.090973,-50.218994,0.110225,0.000000
95.310005,24.230652,-50.307957,0.022924,0.004316,0.109626,107.783325,5.490744,1.096257,-50.307957,0.110893,0.000000
95.710007,24.659256,-50.352436,0.022942,0.004347,0.110407,109.689850,5.587867,1.104069,-50.352436,0.111561,0.000000
96.110008,24.633934,-50.307957,0.022972,0.004368,0.110944,109.577209,5.582129,1.109444,-50.307957,0.112219,0.000000
96.510002,24.984703,-50.396919,0.023006,0.004399,0.111733,111.137512,5.661615,1.117331,-50.396919,0.112887,0.000000
96.910004,24.936295,-50.352436,0.023019,0.004417,0.112193,110.922180,5.650645,1.121934,-50.352436,0.113554,0.000000
97.310005,25.246109,-50.396919,0.023049,0.004447,0.112965,112.300301,5.720850,1.129655,-50.396919,0.114222,0.000000
97.710007,25.766685,-50.352436,0.023092,0.004481,0.113824,114.615944,5.838815,1.138239,-50.352436,0.114890,0.000000
98.110008,25.783447,-50.396919,0.023084,0.004502,0.114352,114.690498,5.842612,1.143523,-50.396919,0.115557,0.000000
98.510002,26.144646,-50.396919,0.023140,0.004532,0.115124,116.297195,5.924461,1.151244,-50.396919,0.116225,0.000000
98.910004,26.264549,-50.396919,0.023157,0.004558,0.115783,116.830551,5.951632,1.157830,-50.396919,0.116894,0.000000
99.310005,26.428764,-50.396919,0.023174,0.004578,0.116278,117.561012,5.988843,1.162780,-50.396919,0.117553,0.000000
99.710007,26.848061,-50.396919,0.023196,0.004614,0.117188,119.426140,6.083858,1.171879,-50.396919,0.118220,0.000000
100.110008,27.021584,-50.396919,0.023230,0.004640,0.117856,120.198006,6.123178,1.178556,-50.396919,0.118888,0.000000
100.510002,27.247238,-50.396919,0.023261,0.004664,0.118472,121.201767,6.174312,1.184718,-50.396919,0.119556,0.000000
100.910004,27.210747,-50.396919,0.023265,0.004684,0.118983,121.039444,6.166043,1.189835,-50.396919,0.120223,0.000000
101.310005,27.715317,-50.441399,0.023282,0.004714,0.119730,123.283890,6.280381,1.197299,-50.441399,0.120891,0.000000
101.710007,28.006508,-50.396919,0.023351,0.004744,0.120493,124.579170,6.346365,1.204929,-50.396919,0.121559,0.000000
102.110008,28.225464,-50.485878,0.023360,0.004771,0.121195,125.553131,6.395982,1.211954,-50.485878,0.122226,0.000000
102.510002,28.348717,-50.441399,0.023373,0.004796,0.121819,126.101387,6.423911,1.218191,-50.441399,0.122886,0.000000
102.910004,28.429527,-50.441399,0.023390,0.004814,0.122279,126.460854,6.442223,1.222794,-50.441399,0.123554,0.000000
103.310005,29.013405,-50.530361,0.023403,0.004848,0.123147,129.058075,6.574531,1.231469,-50.530361,0.124222,0.000000
103.710007,29.060692,-50.530361,0.023433,0.004873,0.123771,129.268417,6.585247,1.237706,-50.530361,0.124889,0.000000
104.110008,29.250977,-50.441399,0.023459,0.004898,0.124403,130.114838,6.628366,1.244034,-50.441399,0.125557,0.000000
104.510002,29.605103,-50.619324,0.023498,0.004924,0.125071,131.690079,6.708612,1.250711,-50.619324,0.126225,0.000000
104.910004,29.759270,-50.530361,0.023515,0.004946,0.125636,132.375839,6.743547,1.256358,-50.530361,0.126892,0.000000
105.310005,30.290268,-50.485878,0.023524,0.004980,0.126494,134.737839,6.863873,1.264942,-50.485878,0.127560,0.000000
105.710007,30.316704,-50.530361,0.023550,0.005004,0.127101,134.855438,6.869864,1.271013,-50.530361,0.128228,0.000000
106.110008,30.643654,-50.574841,0.023584,0.005034,0.127872,136.309784,6.943952,1.278719,-50.574841,0.128888,0.000000
106.510002,30.832069,-50.574841,0.023601,0.005056,0.128428,137.147888,6.986647,1.284275,-50.574841,0.129555,0.000000
106.910004,31.069275,-50.530361,0.023614,0.005078,0.128974,138.203033,7.040398,1.289741,-50.530361,0.130223,0.000000
107.310005,31.487816,-50.530361,0.023657,0.005110,0.129798,140.064804,7.135241,1.297977,-50.530361,0.130891,0.000000
107.710007,31.573090,-50.530361,0.023666,0.005133,0.130379,140.444122,7.154564,1.303790,-50.530361,0.131558,0.000000
108.110008,31.791306,-50.619324,0.023696,0.005157,0.130995,141.414795,7.204013,1.309952,-50.619324,0.132226,0.000000
108.510002,32.228470,-50.574841,0.023739,0.005188,0.131775,143.359390,7.303076,1.317749,-50.574841,0.132894,0.000000
108.910004,32.200165,-50.663803,0.023756,0.005206,0.132235,143.233490,7.296661,1.322351,-50.663803,0.133561,0.000000
109.310005,32.783676,-50.530361,0.023774,0.005242,0.133145,145.829071,7.428887,1.331450,-50.530361,0.134220,0.000000
109.710007,32.744949,-50.574841,0.023813,0.005261,0.133631,145.656815,7.420112,1.336310,-50.574841,0.134889,0.000000
110.110008,33.084549,-50.619324,0.023825,0.005287,0.134282,147.167419,7.497066,1.342820,-50.619324,0.135557,0.000000
110.510002,33.513527,-50.574841,0.023851,0.005317,0.135062,149.075607,7.594274,1.350617,-50.574841,0.136224,0.000000
110.910004,33.586136,-50.574841,0.023856,0.005340,0.135643,149.398590,7.610727,1.356431,-50.574841,0.136892,0.000000
111.310005,34.214333,-50.619324,0.023907,0.005373,0.136467,152.192947,7.753078,1.364667,-50.619324,0.137560,0.000000
111.710007,34.305191,-50.574841,0.023916,0.005399,0.137134,152.597107,7.773667,1.371343,-50.574841,0.138227,0.000000
112.110008,34.373703,-50.574841,0.023942,0.005416,0.137576,152.901871,7.789193,1.375764,-50.574841,0.138895,0.000000
112.510002,35.002640,-50.619324,0.023968,0.005450,0.138427,155.699524,7.931711,1.384272,-50.619324,0.139554,0.000000
112.910004,35.125526,-50.619324,0.024002,0.005474,0.139034,156.246140,7.959558,1.390343,-50.619324,0.140221,0.000000
113.310005,35.497154,-50.663803,0.024007,0.005502,0.139753,157.899231,8.043770,1.397535,-50.663803,0.140889,0.000000
113.710007,35.515770,-50.708282,0.024032,0.005525,0.140326,157.982040,8.047988,1.403257,-50.708282,0.141558,0.000000
114.110008,35.890381,-50.708282,0.024050,0.005551,0.141002,159.648392,8.132876,1.410025,-50.708282,0.142226,0.000000
114.510002,36.094063,-50.663803,0.024084,0.005576,0.141626,160.554413,8.179031,1.416262,-50.663803,0.142893,0.000000
114.910004,36.646294,-50.708282,0.024106,0.005606,0.142398,163.010849,8.304169,1.423983,-50.708282,0.143561,0.000000
115.310005,36.925949,-50.752766,0.024140,0.005634,0.143092,164.254822,8.367540,1.430917,-50.752766,0.144229,0.000000
115.710007,37.014198,-50.708282,0.024153,0.005655,0.143638,164.647385,8.387537,1.436383,-50.708282,0.144887,0.000000
116.110008,37.418221,-50.663803,0.024183,0.005684,0.144366,166.444565,8.479090,1.443665,-50.663803,0.145555,0.000000
116.510002,37.745911,-50.663803,0.024213,0.005708,0.144983,167.902191,8.553345,1.449827,-50.663803,0.146223,0.000000
116.910004,38.000244,-50.752766,0.024188,0.005733,0.145625,169.033524,8.610978,1.456246,-50.752766,0.146890,0.000000
117.310005,38.528641,-50.663803,0.024261,0.005764,0.146406,171.383957,8.730715,1.464058,-50.663803,0.147558,0.000000
117.710007,38.527145,-50.708282,0.024265,0.005785,0.146951,171.377304,8.730376,1.469508,-50.708282,0.148226,0.000000
118.110008,39.114380,-50.752766,0.024300,0.005816,0.147715,173.989456,8.863445,1.477154,-50.752766,0.148895,0.000000
118.510002,39.210075,-50.752766,0.024317,0.005835,0.148200,174.415131,8.885130,1.481998,-50.752766,0.149562,0.000000
118.910004,39.779068,-50.752766,0.024347,0.005867,0.149016,176.946136,9.014066,1.490159,-50.752766,0.150230,0.000000
119.310005,39.904182,-50.752766,0.024364,0.005890,0.149597,177.502670,9.042418,1.495972,-50.752766,0.150889,0.000000
119.710007,40.496628,-50.708282,0.024403,0.005920,0.150377,180.138000,9.176667,1.503769,-50.708282,0.151556,0.000000
120.110008,40.665314,-50.752766,0.024420,0.005945,0.151002,180.888351,9.214891,1.510022,-50.752766,0.152224,0.000000
120.510002,40.905121,-50.708282,0.024429,0.005970,0.151635,181.955063,9.269233,1.516350,-50.708282,0.152892,0.000000
120.910004,41.665504,-50.797245,0.024464,0.006004,0.152510,185.337418,9.441538,1.525101,-50.797245,0.153559,0.000000
121.310005,41.766045,-50.797245,0.024485,0.006029,0.153126,185.784653,9.464321,1.531263,-50.797245,0.154227,0.000000
121.710007,41.997658,-50.797245,0.024524,0.006050,0.153682,186.814911,9.516806,1.536819,-50.797245,0.154895,0.000000
122.110008,42.370773,-50.797245,0.024541,0.006078,0.154392,188.474609,9.601355,1.543919,-50.797245,0.155564,0.000000
122.510002,42.607979,-50.797245,0.024554,0.006099,0.154904,189.529755,9.655106,1.549036,-50.797245,0.156222,0.000000
122.910004,43.427200,-50.752766,0.024589,0.006133,0.155780,193.173828,9.840744,1.557802,-50.752766,0.156890,0.000000
123.310005,43.549706,-50.797245,0.024602,0.006159,0.156430,193.718765,9.868504,1.564297,-50.797245,0.157558,0.000000
123.710007,43.941818,-50.797245,0.024614,0.006183,0.157046,195.462967,9.957358,1.570459,-50.797245,0.158225,0.000000
124.110008,44.178276,-50.797245,0.024645,0.006208,0.157679,196.514786,10.010941,1.576787,-50.797245,0.158893,0.000000
124.510002,44.663475,-50.886208,0.024675,0.006230,0.158251,198.673065,10.120889,1.582510,-50.886208,0.159561,0.000000
124.910004,45.252197,-50.841728,0.024679,0.006266,0.159153,201.291824,10.254294,1.591533,-50.841728,0.160228,0.000000
125.310005,45.486420,-50.841728,0.024731,0.006287,0.159682,202.333694,10.307370,1.596817,-50.841728,0.160896,0.000000
125.710007,45.986885,-50.886208,0.024752,0.006315,0.160402,204.559875,10.420777,1.604023,-50.886208,0.161556,0.000000
126.110008,46.249405,-50.841728,0.024783,0.006338,0.160975,205.727631,10.480265,1.609746,-50.841728,0.162224,0.000000
126.510010,46.964737,-50.886208,0.024808,0.006370,0.161798,208.909576,10.642362,1.617982,-50.886208,0.162891,0.000000
126.910004,47.214600,-50.841728,0.024839,0.006394,0.162396,210.021027,10.698981,1.623962,-50.841728,0.163559,0.000000
127.310005,47.560158,-50.886208,0.024856,0.006419,0.163038,211.558151,10.777286,1.630381,-50.886208,0.164227,0.000000
127.710007,48.237877,-50.886208,0.024873,0.006449,0.163801,214.572800,10.930859,1.638012,-50.886208,0.164894,0.000000
128.110001,48.234901,-50.930691,0.024899,0.006467,0.164270,214.559555,10.930185,1.642705,-50.930691,0.165562,0.000000
128.510010,49.114815,-50.886208,0.024929,0.006498,0.165050,218.473602,11.129577,1.650502,-50.886208,0.166230,0.000000
128.910004,49.640228,-50.886208,0.024951,0.006529,0.165839,220.810760,11.248637,1.658390,-50.886208,0.166890,0.000000
129.310013,49.944458,-50.930691,0.024990,0.006551,0.166385,222.164047,11.317575,1.663855,-50.930691,0.167557,0.000000
129.710007,50.475464,-50.930691,0.025011,0.006578,0.167080,224.526077,11.437903,1.670804,-50.930691,0.168225,0.000000
130.110001,50.869064,-50.930691,0.025024,0.006600,0.167644,226.276901,11.527095,1.676436,-50.930691,0.168893,0.000000
130.510010,51.783981,-50.930691,0.025050,0.006633,0.168467,230.346649,11.734418,1.684672,-50.930691,0.169560,0.000000
130.910004,52.075172,-50.930691,0.025067,0.006658,0.169109,231.641937,11.800403,1.691091,-50.930691,0.170228,0.000000
131.310013,52.606178,-50.975170,0.025123,0.006682,0.169733,234.003967,11.920731,1.697329,-50.975170,0.170896,0.000000
131.710007,53.137184,-50.975170,0.025123,0.006709,0.170402,236.365997,12.041058,1.704020,-50.975170,0.171563,0.000000
132.110001,53.359863,-50.930691,0.025149,0.006729,0.170921,237.356522,12.091517,1.709213,-50.930691,0.172231,0.000000
132.510010,54.331749,-50.975170,0.025179,0.006762,0.171754,241.679687,12.311749,1.717540,-50.975170,0.172891,0.000000
132.910004,54.706360,-50.975170,0.025201,0.006786,0.172361,243.346039,12.396639,1.723611,-50.975170,0.173559,0.000000
133.310013,55.040749,-50.975170,0.025218,0.006807,0.172891,244.833481,12.472412,1.728910,-50.975170,0.174226,0.000000
133.710007,56.268089,-50.975170,0.025240,0.006841,0.173757,250.292969,12.750531,1.737570,-50.975170,0.174894,0.000000
134.110001,56.321709,-50.975170,0.025261,0.006860,0.174243,250.531479,12.762682,1.742429,-50.975170,0.175562,0.000000
134.510010,57.306267,-50.975170,0.025300,0.006891,0.175032,254.911011,12.985785,1.750317,-50.975170,0.176229,0.000000
134.910004,57.847321,-51.019650,0.025313,0.006919,0.175734,257.317719,13.108391,1.757342,-51.019650,0.176897,0.000000
135.310013,58.502327,-50.975170,0.025317,0.006942,0.176334,260.231354,13.256817,1.763337,-50.975170,0.177565,0.000000
135.710007,59.244461,-51.064133,0.025339,0.006970,0.177027,263.532532,13.424987,1.770271,-51.064133,0.178223,0.000000
136.110001,60.037613,-51.064133,0.025369,0.006997,0.177711,267.060638,13.604717,1.777114,-51.064133,0.178891,0.000000
136.510010,60.778267,-50.975170,0.025378,0.007024,0.178414,270.355225,13.772552,1.784139,-50.975170,0.179558,0.000000
136.910004,61.443695,-50.975170,0.025403,0.007050,0.179082,273.315216,13.923341,1.790815,-50.975170,0.180228,0.000000
137.310013,61.929642,-51.019650,0.025412,0.007070,0.179586,275.476807,14.033457,1.795857,-51.019650,0.180895,0.000000
137.710007,62.735825,-51.108612,0.025438,0.007097,0.180261,279.062897,14.216141,1.802609,-51.108612,0.181563,0.000000
138.110001,63.199806,-50.975170,0.025468,0.007115,0.180712,281.126770,14.321280,1.807121,-50.975170,0.182231,0.000000
138.510010,64.773445,-51.108612,0.025498,0.007156,0.181754,288.126678,14.677873,1.817537,-51.108612,0.182898,0.000000
138.910004,65.259773,-51.064133,0.025485,0.007178,0.182317,290.289978,14.788075,1.823169,-51.064133,0.183557,0.000000
139.310013,66.353050,-51.064133,0.025546,0.007206,0.183045,295.153107,15.035816,1.830451,-51.064133,0.184224,0.000000
139.710007,66.793571,-51.064133,0.025559,0.007227,0.183566,297.112640,15.135640,1.835659,-51.064133,0.184892,0.000000
140.110001,66.982368,-51.108612,0.025563,0.007231,0.183678,297.952454,15.178422,1.836779,-51.108612,0.183947,0.000000
140.510010,66.300179,-51.019650,0.025580,0.007223,0.183461,294.917938,15.023836,1.834614,-51.019650,0.183678,0.000000
140.910004,65.836205,-51.064133,0.025576,0.007223,0.183452,292.854065,14.918697,1.834523,-51.064133,0.183678,0.000000
141.310013,65.505165,-51.064133,0.025602,0.007223,0.183452,291.381531,14.843682,1.834523,-51.064133,0.183678,0.000000
141.710007,65.235939,-51.064133,0.025597,0.007223,0.183452,290.183960,14.782675,1.834523,-51.064133,0.183678,0.000000
142.110001,64.987190,-51.064133,0.025580,0.007223,0.183452,289.077454,14.726308,1.834523,-51.064133,0.183678,0.000000
142.510010,64.796913,-51.108612,0.025610,0.007223,0.183452,288.231079,14.683190,1.834523,-51.108612,0.183678,0.000000
142.910004,64.639397,-51.108612,0.025589,0.007223,0.183452,287.530396,14.647496,1.834523,-51.108612,0.183678,0.000000
143.310013,64.480385,-51.108612,0.025597,0.007223,0.183452,286.823090,14.611465,1.834523,-51.108612,0.183678,0.000000
143.710007,64.316170,-51.153095,0.025602,0.007223,0.183452,286.092621,14.574253,1.834523,-51.153095,0.183678,0.000000
144.110001,64.213402,-51.108612,0.025610,0.007223,0.183452,285.635468,14.550964,1.834523,-51.108612,0.183678,0.000000
144.510010,64.080833,-51.153095,0.025606,0.007223,0.183452,285.045776,14.520925,1.834523,-51.153095,0.183678,0.000000
144.910004,63.978065,-51.153095,0.025593,0.007223,0.183452,284.588654,14.497637,1.834523,-51.153095,0.183678,0.000000
145.310013,63.877144,-51.153095,0.025597,0.007223,0.183452,284.139740,14.474768,1.834523,-51.153095,0.183678,0.000000
145.710007,63.778847,-51.153095,0.025606,0.007223,0.183452,283.702484,14.452493,1.834523,-51.153095,0.183678,0.000000
146.110001,63.695808,-51.153095,0.025593,0.007223,0.183452,283.333099,14.433676,1.834523,-51.153095,0.183678,0.000000
146.510010,63.619835,-51.197575,0.025589,0.007223,0.183452,282.995148,14.416461,1.834523,-51.197575,0.183678,0.000000
146.910004,63.549095,-51.197575,0.025589,0.007223,0.183452,282.680481,14.400431,1.834523,-51.197575,0.183678,0.000000
147.310013,63.472374,-51.197575,0.025597,0.007223,0.183452,282.339233,14.383045,1.834523,-51.197575,0.183678,0.000000
147.710007,63.392326,-51.242054,0.025610,0.007223,0.183452,281.983154,14.364906,1.834523,-51.242054,0.183678,0.000000
148.110001,63.323433,-51.197575,0.025610,0.007223,0.183452,281.676697,14.349295,1.834523,-51.197575,0.183678,0.000000
148.510010,63.269066,-51.153095,0.025615,0.007223,0.183452,281.434875,14.336976,1.834523,-51.153095,0.183678,0.000000
148.910004,63.225121,-51.286537,0.025597,0.007223,0.183452,281.239380,14.327017,1.834523,-51.286537,0.183678,0.000000
149.310013,63.159218,-51.242054,0.025602,0.007223,0.183452,280.946228,14.312083,1.834523,-51.242054,0.183678,0.000000
149.710007,63.105217,-51.242054,0.025610,0.007223,0.183452,280.706024,14.299847,1.834523,-51.242054,0.183678,0.000000
150.110001,63.054207,-51.242054,0.025602,0.007223,0.183452,280.479126,14.288287,1.834523,-51.242054,0.183678,0.000000
150.510010,62.981964,-51.197575,0.025602,0.007223,0.183452,280.157776,14.271917,1.834523,-51.197575,0.183678,0.000000
150.910004,62.951431,-51.197575,0.025615,0.007223,0.183452,280.021942,14.264998,1.834523,-51.197575,0.183678,0.000000
151.310013,62.905632,-51.197575,0.025589,0.007223,0.183452,279.818237,14.254620,1.834523,-51.197575,0.183678,0.000000
151.710007,62.857590,-51.242054,0.025615,0.007223,0.183452,279.604523,14.243733,1.834523,-51.242054,0.183678,0.000000
152.110001,62.822960,-51.242054,0.025576,0.007223,0.183452,279.450470,14.235886,1.834523,-51.242054,0.183678,0.000000
152.510010,62.773437,-51.286537,0.025606,0.007223,0.183452,279.230194,14.224664,1.834523,-51.286537,0.183678,0.000000
152.910004,62.739548,-51.242054,0.025610,0.007223,0.183452,279.079437,14.216985,1.834523,-51.242054,0.183678,0.000000
153.310013,62.705666,-51.242054,0.025606,0.007223,0.183452,278.928741,14.209307,1.834523,-51.242054,0.183678,0.000000
153.710007,62.649437,-51.286537,0.025597,0.007223,0.183452,278.678619,14.196566,1.834523,-51.286537,0.183678,0.000000
154.110001,62.617783,-51.242054,0.025597,0.007223,0.183452,278.537811,14.189392,1.834523,-51.242054,0.183678,0.000000
154.510010,62.583527,-51.242054,0.025619,0.007223,0.183452,278.385437,14.181629,1.834523,-51.242054,0.183678,0.000000
154.910004,62.545174,-51.242054,0.025602,0.007223,0.183452,278.214813,14.172938,1.834523,-51.242054,0.183678,0.000000
155.310013,62.519104,-51.331017,0.025610,0.007223,0.183452,278.098877,14.167031,1.834523,-51.331017,0.183678,0.000000
155.710007,62.479263,-51.286537,0.025619,0.007223,0.183452,277.921631,14.158004,1.834523,-51.286537,0.183678,0.000000
156.110001,62.455429,-51.286537,0.025602,0.007223,0.183452,277.815613,14.152602,1.834523,-51.286537,0.183678,0.000000
156.510010,62.428246,-51.286537,0.025606,0.007223,0.183452,277.694702,14.146442,1.834523,-51.286537,0.183678,0.000000
156.910004,62.387657,-51.331017,0.025602,0.007223,0.183452,277.514160,14.137245,1.834523,-51.331017,0.183678,0.000000
157.310013,62.357872,-51.286537,0.025615,0.007223,0.183452,277.381683,14.130495,1.834523,-51.286537,0.183678,0.000000
157.710007,62.338509,-51.286537,0.025602,0.007223,0.183452,277.295532,14.126108,1.834523,-51.286537,0.183678,0.000000
158.110001,62.305733,-51.331017,0.025606,0.007223,0.183452,277.149750,14.118681,1.834523,-51.331017,0.183678,0.000000
158.510010,62.268127,-51.331017,0.025597,0.007223,0.183452,276.982452,14.110160,1.834523,-51.331017,0.183678,0.000000
158.910004,62.262543,-51.286537,0.025597,0.007223,0.183452,276.957611,14.108894,1.834523,-51.286537,0.183678,0.000000
159.310013,62.218231,-51.286537,0.025597,0.007223,0.183452,276.760529,14.098852,1.834523,-51.286537,0.183678,0.000000
159.710007,62.208176,-51.375500,0.025610,0.007223,0.183452,276.715790,14.096574,1.834523,-51.375500,0.183678,0.000000
160.110001,62.165726,-51.331017,0.025615,0.007223,0.183452,276.526947,14.086954,1.834523,-51.331017,0.183678,0.000000
160.510010,62.158646,-51.331017,0.025606,0.007223,0.183452,276.495453,14.085350,1.834523,-51.331017,0.183678,0.000000
160.910004,62.118057,-51.331017,0.025623,0.007223,0.183452,276.314911,14.076153,1.834523,-51.331017,0.183678,0.000000
161.310013,62.104286,-51.375500,0.025615,0.007223,0.183452,276.253662,14.073032,1.834523,-51.375500,0.183678,0.000000
161.710007,62.082314,-51.375500,0.025610,0.007223,0.183452,276.155914,14.068053,1.834523,-51.375500,0.183678,0.000000
162.110001,62.073006,-51.375500,0.025619,0.007223,0.183452,276.114532,14.065945,1.834523,-51.375500,0.183678,0.000000
162.510010,62.026833,-51.375500,0.025615,0.007223,0.183452,275.909119,14.055481,1.834523,-51.375500,0.183678,0.000000
162.910004,62.011559,-51.375500,0.025597,0.007223,0.183452,275.841187,14.052020,1.834523,-51.375500,0.183678,0.000000
163.310013,61.997414,-51.331017,0.025615,0.007223,0.183452,275.778259,14.048815,1.834523,-51.331017,0.183678,0.000000
163.710007,61.970230,-51.375500,0.025602,0.007223,0.183452,275.657349,14.042654,1.834523,-51.375500,0.183678,0.000000
164.110001,61.953102,-51.375500,0.025619,0.007223,0.183452,275.581177,14.038774,1.834523,-51.375500,0.183678,0.000000
164.510010,61.925919,-51.419979,0.025619,0.007223,0.183452,275.460236,14.032614,1.834523,-51.419979,0.183678,0.000000
164.910004,61.919960,-51.419979,0.025602,0.007223,0.183452,275.433746,14.031263,1.834523,-51.419979,0.183678,0.000000
165.310013,61.894264,-51.464462,0.025623,0.007223,0.183452,275.319427,14.025441,1.834523,-51.464462,0.183678,0.000000
165.710007,61.877884,-51.419979,0.025610,0.007223,0.183452,275.246582,14.021729,1.834523,-51.419979,0.183678,0.000000
166.110001,61.848465,-51.375500,0.025623,0.007223,0.183452,275.115723,14.015062,1.834523,-51.375500,0.183678,0.000000
166.510010,61.842133,-51.419979,0.025606,0.007223,0.183452,275.087555,14.013627,1.834523,-51.419979,0.183678,0.000000
166.910004,61.814949,-51.464462,0.025628,0.007223,0.183452,274.966614,14.007467,1.834523,-51.464462,0.183678,0.000000
167.310013,61.794098,-51.419979,0.025619,0.007223,0.183452,274.873871,14.002743,1.834523,-51.419979,0.183678,0.000000
167.710007,61.771751,-51.419979,0.025615,0.007223,0.183452,274.774475,13.997679,1.834523,-51.419979,0.183678,0.000000
168.110001,61.765053,-51.419979,0.025619,0.007223,0.183452,274.744690,13.996161,1.834523,-51.419979,0.183678,0.000000
168.510010,61.751274,-51.508942,0.025615,0.007223,0.183452,274.683380,13.993039,1.834523,-51.508942,0.183678,0.000000
168.910004,61.745689,-51.375500,0.025606,0.007223,0.183452,274.658539,13.991774,1.834523,-51.375500,0.183678,0.000000
169.310013,61.716644,-51.419979,0.025619,0.007223,0.183452,274.529358,13.985191,1.834523,-51.419979,0.183678,0.000000
169.710007,61.701752,-51.464462,0.025602,0.007223,0.183452,274.463104,13.981816,1.834523,-51.464462,0.183678,0.000000
170.110001,61.670471,-51.464462,0.025615,0.007223,0.183452,274.323944,13.974729,1.834523,-51.464462,0.183678,0.000000
170.300003,61.671211,-51.508942,0.025589,0.007223,0.183452,274.327240,13.974896,1.834523,-51.508942,0.183678,0.000000