File: Data/New pin I-18 old sample 3_08172023_175117.csv
Time (sec),S:Load (lbs),S:HL1 (DIM),S:LVDT (in),S:Position (in),Ch:Position (mm),Ch:Load (N),Ch:Stress (MPa),Ch:Strain (mm/mm),Ch:HL1 (DIM),Set Point (),Cycles ()
0.110000,-0.005585,-20.194351,0.000026,-0.000000,-0.000000,-0.024842,-0.001266,-0.000000,-20.194351,0.000174,0.000000
0.320000,-0.013405,-20.149870,0.000013,-0.000000,-0.000000,-0.059628,-0.003038,-0.000000,-20.149870,0.000174,0.000000
0.530000,0.007820,-20.238832,0.000030,0.000082,0.002073,0.034786,0.001772,0.020726,-20.238832,0.002775,0.000000
0.740000,0.001495,-20.283314,0.000052,0.000202,0.005125,0.006652,0.000339,0.051247,-20.283314,0.006278,0.000000
0.950000,0.018997,-20.194351,0.000185,0.000334,0.008472,0.084504,0.004305,0.084721,-20.194351,0.009782,0.000000
1.160000,0.017876,-20.238832,0.000328,0.000477,0.012115,0.079515,0.004051,0.121147,-20.238832,0.013268,0.000000
1.370000,0.004097,-20.238832,0.000461,0.000619,0.015713,0.018224,0.000928,0.157134,-20.238832,0.016772,0.000000
1.580000,-0.002602,-20.238832,0.000642,0.000757,0.019226,-0.011573,-0.000590,0.192258,-20.238832,0.020276,0.000000
1.790000,0.041710,-20.283314,0.000755,0.000892,0.022668,0.185535,0.009452,0.226685,-20.283314,0.023762,0.000000
2.000000,0.040962,-20.283314,0.000901,0.001029,0.026138,0.182209,0.009282,0.261385,-20.283314,0.027265,0.000000
2.210000,-0.001488,-20.238832,0.001035,0.001167,0.029651,-0.006618,-0.000337,0.296509,-20.238832,0.030770,0.000000
2.420000,0.006332,-20.238832,0.001186,0.001307,0.033206,0.028168,0.001435,0.332056,-20.238832,0.034273,0.000000
2.630000,0.025696,-20.238832,0.001324,0.001444,0.036667,0.114301,0.005823,0.366665,-20.238832,0.037760,0.000000
2.840000,0.015266,-20.283314,0.001457,0.001587,0.040300,0.067908,0.003459,0.403000,-20.283314,0.041263,0.000000
3.050000,0.030907,-20.238832,0.001574,0.001719,0.043656,0.137480,0.007004,0.436565,-20.238832,0.044766,0.000000
3.260000,0.026070,-20.283314,0.001750,0.001856,0.047142,0.115964,0.005907,0.471416,-20.283314,0.048253,0.000000
3.470000,0.028679,-20.283314,0.001880,0.001994,0.050646,0.127570,0.006499,0.506464,-20.283314,0.051756,0.000000
3.680000,0.029793,-20.238832,0.002022,0.002132,0.054159,0.132525,0.006751,0.541588,-20.238832,0.055259,0.000000
3.890000,0.038361,-20.327795,0.002143,0.002264,0.057497,0.170636,0.008693,0.574971,-20.327795,0.058763,0.000000
4.100000,0.033890,-20.283314,0.002311,0.002405,0.061087,0.150749,0.007680,0.610867,-20.283314,0.062249,0.000000
4.310000,0.043571,-20.283314,0.002475,0.002550,0.064764,0.193816,0.009873,0.647641,-20.283314,0.065753,0.000000
4.520000,0.033142,-20.238832,0.002587,0.002687,0.068251,0.147423,0.007510,0.682507,-20.238832,0.069256,0.000000
4.730000,0.034264,-20.283314,0.002738,0.002822,0.071677,0.152412,0.007764,0.716768,-20.283314,0.072743,0.000000
4.940000,0.021225,-20.327795,0.002867,0.002957,0.075110,0.094413,0.004810,0.751105,-20.327795,0.076246,0.000000
5.150000,0.029419,-20.283314,0.003009,0.003094,0.078579,0.130862,0.006666,0.785790,-20.283314,0.079751,0.000000
5.360000,0.012291,-20.327795,0.003147,0.003233,0.082110,0.054673,0.002785,0.821095,-20.327795,0.083254,0.000000
5.570000,0.037239,-20.327795,0.003290,0.003371,0.085613,0.165648,0.008438,0.856128,-20.327795,0.086739,0.000000
5.780000,0.023460,-20.327795,0.003454,0.003512,0.089202,0.104357,0.005316,0.892024,-20.327795,0.090244,0.000000
5.990000,0.059586,-20.372276,0.003574,0.003642,0.092515,0.265050,0.013502,0.925149,-20.372276,0.093747,0.000000
6.200000,0.065910,-20.327795,0.003717,0.003778,0.095950,0.293184,0.014935,0.959501,-20.327795,0.097234,0.000000
6.410000,0.059586,-20.372276,0.003854,0.003920,0.099565,0.265050,0.013502,0.995654,-20.372276,0.100737,0.000000
6.620000,0.051018,-20.327795,0.004010,0.004058,0.103070,0.226938,0.011561,1.030703,-20.327795,0.104241,0.000000
6.830000,0.053627,-20.327795,0.004174,0.004205,0.106808,0.238545,0.012152,1.068082,-20.327795,0.107727,0.000000
7.040000,0.052132,-20.416756,0.004303,0.004339,0.110198,0.231893,0.011813,1.101980,-20.416756,0.111230,0.000000
7.250000,0.028305,-20.327795,0.004454,0.004474,0.113650,0.125907,0.006414,1.136498,-20.327795,0.114734,0.000000
7.460001,0.014153,-20.327795,0.004562,0.004610,0.117083,0.062954,0.003207,1.170835,-20.327795,0.118237,0.000000
7.670001,-0.001488,-20.372276,0.004712,0.004747,0.120570,-0.006618,-0.000337,1.205701,-20.372276,0.121724,0.000000
7.880001,0.010056,-20.327795,0.004876,0.004885,0.124092,0.044729,0.002279,1.240916,-20.327795,0.125227,0.000000
8.090000,0.055489,-20.416756,0.005019,0.005023,0.127586,0.246826,0.012574,1.275858,-20.416756,0.128730,0.000000
8.300000,0.053993,-20.372276,0.005170,0.005160,0.131072,0.240174,0.012235,1.310724,-20.372276,0.132217,0.000000
8.510000,0.063675,-20.372276,0.005264,0.005295,0.134499,0.283240,0.014429,1.344985,-20.372276,0.135720,0.000000
8.720000,0.052505,-20.372276,0.005437,0.005429,0.137888,0.233556,0.011898,1.378883,-20.372276,0.139225,0.000000
8.930000,0.058464,-20.372276,0.005583,0.005571,0.141496,0.260061,0.013248,1.414960,-20.372276,0.142728,0.000000
9.140000,0.055862,-20.461237,0.005726,0.005718,0.145225,0.248488,0.012659,1.452249,-20.461237,0.146214,0.000000
9.350000,0.041336,-20.372276,0.005851,0.005855,0.148712,0.183872,0.009367,1.487116,-20.372276,0.149718,0.000000
9.560000,0.039101,-20.461237,0.006028,0.005990,0.152147,0.173928,0.008860,1.521467,-20.461237,0.153222,0.000000
9.770000,-0.002602,-20.416756,0.006170,0.006127,0.155615,-0.011573,-0.000590,1.556152,-20.416756,0.156708,0.000000
9.980000,-0.000740,-20.416756,0.006282,0.006261,0.159040,-0.003292,-0.000168,1.590398,-20.416756,0.160212,0.000000
10.190001,-0.004463,-20.461237,0.006424,0.006402,0.162613,-0.019853,-0.001011,1.626127,-20.461237,0.163715,0.000000
10.400001,0.044312,-20.461237,0.006575,0.006540,0.166108,0.197107,0.010041,1.661084,-20.461237,0.167218,0.000000
10.610001,0.060326,-20.416756,0.006717,0.006678,0.169630,0.268342,0.013670,1.696299,-20.416756,0.170705,0.000000
10.820001,0.048409,-20.416756,0.006855,0.006814,0.173080,0.215332,0.010970,1.730802,-20.416756,0.174208,0.000000
11.030001,0.056602,-20.416756,0.007023,0.006949,0.176506,0.251780,0.012826,1.765063,-20.416756,0.177711,0.000000
11.240001,0.078201,-20.461237,0.007136,0.007087,0.180010,0.347857,0.017721,1.800096,-20.461237,0.181198,0.000000
11.450001,0.055489,-20.416756,0.007308,0.007231,0.183661,0.246826,0.012574,1.836613,-20.416756,0.184701,0.000000
11.660001,0.050644,-20.372276,0.007455,0.007368,0.187155,0.225275,0.011476,1.871555,-20.372276,0.188205,0.000000
11.870001,0.042824,-20.461237,0.007588,0.007506,0.190659,0.190490,0.009704,1.906588,-20.461237,0.191709,0.000000
12.080001,0.028679,-20.372276,0.007739,0.007644,0.194155,0.127570,0.006499,1.941545,-20.372276,0.195195,0.000000
12.290001,-0.008560,-20.505718,0.007886,0.007780,0.197606,-0.038078,-0.001940,1.976063,-20.505718,0.198699,0.000000
12.500001,0.049156,-20.505718,0.008011,0.007915,0.201031,0.218658,0.011139,2.010309,-20.505718,0.202203,0.000000
12.710001,0.043571,-20.505718,0.008157,0.008050,0.204475,0.193816,0.009873,2.044752,-20.505718,0.205688,0.000000
12.920001,0.043198,-20.505718,0.008308,0.008194,0.208116,0.192153,0.009789,2.081162,-20.505718,0.209193,0.000000
13.130001,0.054741,-20.505718,0.008446,0.008335,0.211698,0.243500,0.012404,2.116983,-20.505718,0.212696,0.000000
13.340001,0.067032,-20.505718,0.008597,0.008467,0.215064,0.298173,0.015190,2.150638,-20.505718,0.216183,0.000000
13.550000,0.072990,-20.461237,0.008714,0.008603,0.218507,0.324678,0.016540,2.185065,-20.461237,0.219686,0.000000
13.760000,0.078949,-20.550200,0.008852,0.008736,0.221889,0.351183,0.017890,2.218887,-20.550200,0.223189,0.000000
13.970000,0.047295,-20.550200,0.008998,0.008881,0.225566,0.210377,0.010717,2.255661,-20.550200,0.226692,0.000000
14.180000,0.047668,-20.505718,0.009166,0.009022,0.229147,0.212040,0.010802,2.291466,-20.505718,0.230179,0.000000
14.390000,0.052505,-20.505718,0.009339,0.009162,0.232712,0.233556,0.011898,2.327120,-20.505718,0.233682,0.000000
14.600000,0.073730,-20.461237,0.009451,0.009294,0.236067,0.327969,0.016708,2.360669,-20.461237,0.237186,0.000000
14.810000,0.054741,-20.505718,0.009610,0.009430,0.239510,0.243500,0.012404,2.395097,-20.505718,0.240672,0.000000
15.020000,0.046921,-20.505718,0.009744,0.009570,0.243083,0.208714,0.010632,2.430826,-20.505718,0.244176,0.000000
15.230000,0.056229,-20.505718,0.009891,0.009706,0.246544,0.250117,0.012742,2.465435,-20.505718,0.247679,0.000000
15.440001,0.076340,-20.505718,0.010050,0.009847,0.250116,0.339576,0.017299,2.501165,-20.505718,0.251184,0.000000
15.650001,0.057724,-20.461237,0.010162,0.009985,0.253629,0.256769,0.013080,2.536288,-20.461237,0.254669,0.000000
15.860001,0.072243,-20.505718,0.010313,0.010118,0.257002,0.321352,0.016370,2.570019,-20.505718,0.258174,0.000000
16.070002,0.069267,-20.505718,0.010464,0.010256,0.260498,0.308116,0.015696,2.604977,-20.505718,0.261677,0.000000
16.280001,0.080437,-20.505718,0.010615,0.010392,0.263966,0.357800,0.018227,2.639662,-20.505718,0.265162,0.000000
16.490002,0.063309,-20.550200,0.010744,0.010534,0.267574,0.281611,0.014346,2.675739,-20.550200,0.268667,0.000000
16.700001,0.086769,-20.550200,0.010874,0.010669,0.270991,0.385968,0.019662,2.709909,-20.550200,0.272170,0.000000
16.910002,0.108734,-20.594681,0.011012,0.010809,0.274538,0.483674,0.024640,2.745381,-20.594681,0.275674,0.000000
17.120001,0.095703,-20.550200,0.011184,0.010949,0.278111,0.425709,0.021687,2.781111,-20.550200,0.279160,0.000000
17.330000,0.094215,-20.594681,0.011326,0.011088,0.281631,0.419091,0.021350,2.816310,-20.594681,0.282664,0.000000
17.540001,0.161613,-20.594681,0.011464,0.011220,0.284997,0.718893,0.036622,2.849965,-20.594681,0.286167,0.000000
17.750000,0.238693,-20.550200,0.011615,0.011363,0.288630,1.061761,0.054089,2.886300,-20.550200,0.289653,0.000000
17.960001,0.437172,-20.550200,0.011714,0.011496,0.291986,1.944638,0.099065,2.919865,-20.550200,0.293157,0.000000
18.170000,0.651283,-20.594681,0.011848,0.011587,0.294319,2.897053,0.147583,2.943195,-20.594681,0.294545,0.000000
18.380001,0.631172,-20.505718,0.011865,-0.000000,-0.000000,2.807594,0.143026,-0.000000,-20.505718,0.000226,0.000000
18.590000,0.617393,-20.594681,0.011852,-0.000000,-0.000000,2.746303,0.139903,-0.000000,-20.594681,0.000226,0.000000
18.800001,0.634155,-20.594681,0.011844,-0.000000,-0.000000,2.820863,0.143702,-0.000000,-20.594681,0.000442,0.000000
19.010000,0.594681,-20.594681,0.011839,0.000000,0.000008,2.645272,0.134757,0.000076,-20.594681,0.000789,0.000000
19.220001,0.612930,-20.594681,0.011835,0.000008,0.000191,2.726450,0.138892,0.001908,-20.594681,0.001145,0.000000
19.430000,0.684799,-20.594681,0.011848,0.000019,0.000484,3.046139,0.155178,0.004845,-20.594681,0.001491,0.000000
19.640001,0.810661,-20.683641,0.011844,0.000038,0.000963,3.606002,0.183698,0.009629,-20.683641,0.001838,0.000000
19.850000,0.874702,-20.550200,0.011870,0.000050,0.001275,3.890871,0.198210,0.012748,-20.550200,0.002194,0.000000
20.060001,0.880661,-20.550200,0.011865,0.000059,0.001491,3.917376,0.199561,0.014912,-20.550200,0.002540,0.000000
20.270000,0.967056,-20.683641,0.011870,0.000074,0.001882,4.301681,0.219138,0.018818,-20.683641,0.002887,0.000000
20.480001,1.061638,-20.639162,0.011900,0.000090,0.002298,4.722401,0.240571,0.022982,-20.639162,0.003243,0.000000
20.690001,1.152496,-20.639162,0.011908,0.000107,0.002705,5.126560,0.261159,0.027054,-20.639162,0.003590,0.000000
20.900002,1.225105,-20.594681,0.011926,0.000118,0.003008,5.449541,0.277613,0.030082,-20.594681,0.003945,0.000000
21.110001,1.260857,-20.728123,0.011934,0.000131,0.003322,5.608571,0.285714,0.033216,-20.728123,0.004292,0.000000
21.320002,1.331238,-20.639162,0.011956,0.000143,0.003633,5.921641,0.301663,0.036335,-20.639162,0.004639,0.000000
21.530001,1.407196,-20.639162,0.011956,0.000152,0.003850,6.259521,0.318875,0.038500,-20.639162,0.004995,0.000000
21.740002,1.590408,-20.639162,0.011977,0.000172,0.004371,7.074490,0.360392,0.043708,-20.639162,0.005341,0.000000
21.950001,1.722229,-20.594681,0.011999,0.000184,0.004674,7.660857,0.390263,0.046736,-20.594681,0.005688,0.000000
22.160002,1.805634,-20.683641,0.012008,0.000194,0.004925,8.031859,0.409162,0.049249,-20.683641,0.006044,0.000000
22.370001,1.960915,-20.728123,0.012021,0.000212,0.005394,8.722584,0.444350,0.053942,-20.728123,0.006390,0.000000
22.580002,2.125130,-20.683641,0.012033,0.000229,0.005818,9.453049,0.481561,0.058181,-20.683641,0.006739,0.000000
22.790001,2.240944,-20.728123,0.012064,0.000242,0.006157,9.968216,0.507805,0.061573,-20.728123,0.007093,0.000000
23.000002,2.263657,-20.683641,0.012059,0.000249,0.006330,10.069247,0.512952,0.063299,-20.683641,0.007440,0.000000
23.210001,2.402550,-20.683641,0.012094,0.000264,0.006695,10.687075,0.544426,0.066947,-20.683641,0.007795,0.000000
23.420002,2.589478,-20.728123,0.012085,0.000276,0.007016,11.518571,0.586784,0.070157,-20.728123,0.008142,0.000000
23.630001,2.855728,-20.683641,0.012098,0.000297,0.007536,12.702913,0.647117,0.075365,-20.683641,0.008490,0.000000
23.840002,2.997231,-20.728123,0.012102,0.000308,0.007823,13.332347,0.679182,0.078226,-20.728123,0.008845,0.000000
24.050001,3.194588,-20.728123,0.012107,0.000321,0.008142,14.210236,0.723904,0.081421,-20.728123,0.009193,0.000000
24.260000,3.320450,-20.683641,0.012158,0.000332,0.008430,14.770099,0.752425,0.084297,-20.683641,0.009539,0.000000
24.470001,3.666008,-20.728123,0.012150,0.000354,0.008993,16.307219,0.830729,0.089929,-20.728123,0.009895,0.000000
24.680000,3.797829,-20.728123,0.012171,0.000366,0.009288,16.893585,0.860600,0.092881,-20.728123,0.010242,0.000000
24.890001,3.913261,-20.728123,0.012171,0.000374,0.009505,17.407057,0.886758,0.095046,-20.728123,0.010589,0.000000
25.100000,4.149719,-20.683641,0.012184,0.000388,0.009860,18.458874,0.940340,0.098604,-20.683641,0.010944,0.000000
25.310001,4.379478,-20.728123,0.012189,0.000402,0.010207,19.480892,0.992404,0.102071,-20.728123,0.011291,0.000000
25.520000,4.640884,-20.728123,0.012219,0.000418,0.010605,20.643684,1.051639,0.106053,-20.728123,0.011647,0.000000
25.730001,4.877335,-20.728123,0.012223,0.000429,0.010900,21.695467,1.105220,0.109005,-20.728123,0.011994,0.000000
25.940001,4.942879,-20.728123,0.012223,0.000439,0.011143,21.987022,1.120072,0.111427,-20.728123,0.012340,0.000000
26.150002,5.236679,-20.728123,0.012240,0.000450,0.011421,23.293911,1.186648,0.114213,-20.728123,0.012696,0.000000
26.360001,5.676819,-20.639162,0.012240,0.000474,0.012036,25.251751,1.286386,0.120360,-20.639162,0.013043,0.000000
26.570002,5.802681,-20.817085,0.012266,0.000482,0.012254,25.811615,1.314906,0.122540,-20.817085,0.013389,0.000000
26.780001,6.061111,-20.728123,0.012279,0.000497,0.012635,26.961170,1.373467,0.126355,-20.728123,0.013745,0.000000
26.990002,6.314697,-20.728123,0.012271,0.000511,0.012991,28.089176,1.430931,0.129913,-20.728123,0.014092,0.000000
27.200001,6.614830,-20.772604,0.012305,0.000527,0.013380,29.424234,1.498942,0.133804,-20.772604,0.014439,0.000000
27.410002,6.922035,-20.683641,0.012344,0.000543,0.013789,30.790751,1.568556,0.137891,-20.683641,0.014794,0.000000
27.620001,7.119392,-20.817085,0.012344,0.000554,0.014066,31.668638,1.613277,0.140662,-20.817085,0.015141,0.000000
27.830002,7.238548,-20.683641,0.012361,0.000561,0.014257,32.198669,1.640278,0.142569,-20.683641,0.015488,0.000000
28.040001,7.579269,-20.772604,0.012344,0.000577,0.014648,33.714275,1.717487,0.146475,-20.772604,0.015844,0.000000
28.250002,7.843658,-20.772604,0.012378,0.000590,0.014976,34.890335,1.777398,0.149761,-20.772604,0.016190,0.000000
28.460001,8.245819,-20.772604,0.012374,0.000609,0.015480,36.679234,1.868529,0.154802,-20.772604,0.016546,0.000000
28.670002,8.503502,-20.772604,0.012391,0.000622,0.015809,37.825466,1.926921,0.158087,-20.772604,0.016893,0.000000
28.880001,8.621918,-20.728123,0.012409,0.000633,0.016078,38.352207,1.953755,0.160782,-20.728123,0.017239,0.000000
29.090002,8.889275,-20.861567,0.012417,0.000645,0.016390,39.541470,2.014338,0.163901,-20.861567,0.017595,0.000000
29.300001,9.344315,-20.772604,0.012426,0.000663,0.016850,41.565586,2.117452,0.168504,-20.772604,0.017942,0.000000
29.510002,9.658226,-20.728123,0.012456,0.000678,0.017232,42.961933,2.188585,0.172319,-20.728123,0.018289,0.000000
29.720001,9.947937,-20.772604,0.012469,0.000691,0.017544,44.250633,2.254235,0.175437,-20.772604,0.018644,0.000000
29.930002,9.961342,-20.772604,0.012473,0.000696,0.017674,44.310261,2.257272,0.176739,-20.772604,0.018991,0.000000
30.140001,10.511330,-20.817085,0.012495,0.000717,0.018211,46.756729,2.381901,0.182114,-20.817085,0.019339,0.000000
30.350002,10.906792,-20.861567,0.012508,0.000733,0.018619,48.515831,2.471514,0.186187,-20.861567,0.019694,0.000000
30.560001,11.236717,-20.817085,0.012542,0.000750,0.019044,49.983414,2.546277,0.190441,-20.817085,0.020042,0.000000
30.770002,11.405029,-20.817085,0.012547,0.000762,0.019365,50.732105,2.584416,0.193650,-20.817085,0.020396,0.000000
30.980001,11.756546,-20.772604,0.012538,0.000777,0.019728,52.295727,2.664072,0.197284,-20.772604,0.020744,0.000000
31.190001,11.841820,-20.817085,0.012572,0.000787,0.019989,52.675045,2.683395,0.199888,-20.817085,0.021091,0.000000
31.400002,12.437614,-20.817085,0.012572,0.000807,0.020501,55.325272,2.818404,0.205005,-20.817085,0.021447,0.000000
31.610001,12.454742,-20.817085,0.012594,0.000813,0.020649,55.401463,2.822285,0.206489,-20.817085,0.021793,0.000000
31.820002,12.624550,-20.906048,0.012577,0.000823,0.020900,56.156803,2.860764,0.209002,-20.906048,0.022140,0.000000
32.030003,13.023727,-20.772604,0.012611,0.000836,0.021238,57.932434,2.951219,0.212378,-20.772604,0.022496,0.000000
32.240002,13.559204,-20.772604,0.012624,0.000858,0.021793,60.314354,3.072560,0.217934,-20.772604,0.022843,0.000000
32.450001,13.943115,-20.861567,0.012628,0.000874,0.022201,62.022076,3.159555,0.222007,-20.861567,0.023189,0.000000
32.660000,14.086479,-20.817085,0.012628,0.000886,0.022496,62.659790,3.192042,0.224959,-20.817085,0.023545,0.000000
32.870003,14.405235,-20.906048,0.012663,0.000900,0.022859,64.077690,3.264273,0.228593,-20.906048,0.023892,0.000000
33.080002,14.535934,-20.817085,0.012680,0.000912,0.023164,64.659065,3.293890,0.231636,-20.817085,0.024248,0.000000
33.290001,15.144760,-20.861567,0.012702,0.000930,0.023631,67.367256,3.431852,0.236314,-20.861567,0.024594,0.000000
33.500000,15.157799,-20.817085,0.012689,0.000938,0.023831,67.425255,3.434806,0.238312,-20.817085,0.024941,0.000000
33.710003,15.322388,-20.817085,0.012723,0.000949,0.024099,68.157387,3.472103,0.240992,-20.817085,0.025297,0.000000
33.920002,15.644485,-20.861567,0.012715,0.000963,0.024455,69.590149,3.545091,0.244550,-20.861567,0.025643,0.000000
34.130001,16.408966,-20.817085,0.012741,0.000985,0.025027,72.990730,3.718325,0.250272,-20.817085,0.025990,0.000000
34.340000,16.622337,-20.861567,0.012758,0.000999,0.025383,73.939850,3.766675,0.253830,-20.861567,0.026346,0.000000
34.550003,16.640587,-20.861567,0.012779,0.001009,0.025618,74.021027,3.770811,0.256177,-20.861567,0.026693,0.000000
34.760002,16.922844,-20.817085,0.012762,0.001022,0.025964,75.276573,3.834771,0.259644,-20.817085,0.027039,0.000000
34.970001,17.297447,-20.906048,0.012797,0.001038,0.026372,76.942886,3.919658,0.263716,-20.906048,0.027395,0.000000
35.180000,17.600929,-20.861567,0.012814,0.001051,0.026684,78.292847,3.988428,0.266835,-20.861567,0.027742,0.000000
35.390003,17.898087,-20.950527,0.012805,0.001065,0.027039,79.614662,4.055765,0.270393,-20.950527,0.028088,0.000000
35.600002,17.951332,-20.950527,0.012827,0.001073,0.027256,79.851517,4.067830,0.272558,-20.950527,0.028444,0.000000
35.810001,18.447708,-20.861567,0.012835,0.001090,0.027681,82.059502,4.180310,0.276812,-20.861567,0.028791,0.000000
36.020000,19.023026,-20.995008,0.012870,0.001110,0.028202,84.618645,4.310679,0.282020,-20.995008,0.029147,0.000000
36.230003,19.278099,-20.950527,0.012891,0.001123,0.028531,85.753265,4.368480,0.285305,-20.950527,0.029493,0.000000
36.440002,19.284431,-20.906048,0.012883,0.001135,0.028818,85.781433,4.369915,0.288182,-20.906048,0.029840,0.000000
36.650002,19.565193,-20.906048,0.012891,0.001147,0.029130,87.030327,4.433536,0.291301,-20.906048,0.030196,0.000000
36.860001,20.128593,-20.861567,0.012913,0.001166,0.029607,89.536453,4.561204,0.296070,-20.861567,0.030543,0.000000
37.070004,20.453308,-20.906048,0.012935,0.001180,0.029963,90.980858,4.634786,0.299627,-20.906048,0.030891,0.000000
37.280003,20.494263,-20.861567,0.012930,0.001191,0.030240,91.163033,4.644066,0.302398,-20.861567,0.031245,0.000000
37.490002,20.610077,-20.906048,0.012935,0.001198,0.030431,91.678200,4.670310,0.304306,-20.906048,0.031593,0.000000
37.700001,21.128418,-20.995008,0.012935,0.001217,0.030924,93.983894,4.787768,0.309241,-20.995008,0.031940,0.000000
37.910004,21.656815,-20.950527,0.012973,0.001234,0.031333,96.334320,4.907504,0.313329,-20.950527,0.032296,0.000000
38.120003,22.005730,-20.995008,0.012991,0.001249,0.031731,97.886375,4.986569,0.317310,-20.995008,0.032642,0.000000
38.330002,22.044823,-20.906048,0.013004,0.001261,0.032017,98.060272,4.995428,0.320172,-20.906048,0.032998,0.000000
38.540001,22.239578,-21.039490,0.013025,0.001271,0.032287,98.926582,5.039561,0.322867,-21.039490,0.033345,0.000000
38.750000,22.496513,-20.906048,0.013051,0.001283,0.032589,100.069489,5.097783,0.325895,-20.906048,0.033692,0.000000
38.960003,22.778770,-20.950527,0.013055,0.001294,0.032876,101.325035,5.161743,0.328756,-20.950527,0.034047,0.000000
39.170002,23.362648,-20.950527,0.013051,0.001313,0.033345,103.922249,5.294052,0.333449,-20.950527,0.034394,0.000000
39.380001,23.459839,-20.906048,0.013060,0.001321,0.033543,104.354576,5.316075,0.335433,-20.906048,0.034741,0.000000
39.590000,23.687729,-20.995008,0.013064,0.001333,0.033864,105.368279,5.367716,0.338642,-20.995008,0.035097,0.000000
39.800003,24.154686,-20.950527,0.013077,0.001348,0.034238,107.445412,5.473530,0.342382,-20.950527,0.035443,0.000000
40.010002,25.014496,-20.995008,0.013111,0.001372,0.034845,111.270035,5.668366,0.348453,-20.995008,0.035790,0.000000
40.220001,24.931831,-21.039490,0.013120,0.001381,0.035078,110.902328,5.649633,0.350784,-21.039490,0.036146,0.000000
40.430000,25.111687,-20.950527,0.013085,0.001393,0.035390,111.702362,5.690390,0.353903,-20.950527,0.036492,0.000000
40.640003,25.336967,-20.995008,0.013146,0.001405,0.035695,112.704460,5.741439,0.356946,-20.995008,0.036848,0.000000
40.850002,25.784935,-20.950527,0.013154,0.001420,0.036059,114.697121,5.842950,0.360595,-20.950527,0.037195,0.000000
41.060001,26.340889,-20.995008,0.013154,0.001436,0.036483,117.170128,5.968931,0.364834,-20.995008,0.037542,0.000000
41.270000,26.681976,-20.950527,0.013180,0.001450,0.036822,118.687355,6.046222,0.368225,-20.950527,0.037897,0.000000
41.480003,26.697250,-20.995008,0.013172,0.001458,0.037030,118.755302,6.049683,0.370299,-20.995008,0.038244,0.000000
41.690002,27.156380,-20.995008,0.013193,0.001472,0.037395,120.797607,6.153724,0.373948,-20.995008,0.038591,0.000000
41.900002,27.762604,-21.039490,0.013189,0.001492,0.037906,123.494232,6.291096,0.379065,-21.039490,0.038947,0.000000
42.110001,28.159180,-20.995008,0.013245,0.001506,0.038253,125.258286,6.380961,0.382532,-20.995008,0.039293,0.000000
42.320004,28.374039,-20.995008,0.013236,0.001519,0.038574,126.214027,6.429649,0.385741,-20.995008,0.039640,0.000000
42.530003,28.743057,-20.950527,0.013249,0.001533,0.038937,127.855507,6.513270,0.389375,-20.950527,0.039996,0.000000
42.740002,29.056229,-20.995008,0.013254,0.001546,0.039258,129.248566,6.584236,0.392584,-20.995008,0.040342,0.000000
42.950001,29.419662,-20.950527,0.013262,0.001559,0.039588,130.865189,6.666591,0.395885,-20.950527,0.040689,0.000000
43.160004,30.150253,-20.995008,0.013292,0.001574,0.039979,134.115021,6.832145,0.399791,-20.995008,0.041045,0.000000
43.370003,30.431023,-21.083971,0.013292,0.001586,0.040291,135.363953,6.895768,0.402910,-21.083971,0.041392,0.000000
43.580002,30.429909,-20.995008,0.013305,0.001596,0.040542,135.358994,6.895516,0.405423,-20.995008,0.041747,0.000000
43.790001,31.443878,-21.039490,0.013297,0.001618,0.041098,139.869354,7.125285,0.410979,-21.039490,0.042094,0.000000
44.000004,31.829285,-21.083971,0.013314,0.001632,0.041454,141.583725,7.212619,0.414537,-21.083971,0.042442,0.000000
44.210003,32.222885,-21.039490,0.013361,0.001645,0.041791,143.334549,7.301810,0.417913,-21.039490,0.042797,0.000000
44.420002,32.331985,-21.083971,0.013366,0.001655,0.042043,143.819855,7.326532,0.420426,-21.083971,0.043143,0.000000
44.630001,32.698776,-21.039490,0.013366,0.001667,0.042354,145.451416,7.409648,0.423545,-21.039490,0.043491,0.000000
44.840004,33.240204,-21.083971,0.013396,0.001683,0.042754,147.859818,7.532338,0.427542,-21.083971,0.043846,0.000000
45.050003,34.118256,-21.039490,0.013370,0.001701,0.043205,151.765579,7.731307,0.432053,-21.039490,0.044194,0.000000
45.260002,34.259384,-21.039490,0.013409,0.001712,0.043482,152.393356,7.763287,0.434824,-21.039490,0.044541,0.000000
45.470001,34.758736,-21.083971,0.013413,0.001728,0.043890,154.614578,7.876442,0.438896,-21.083971,0.044896,0.000000
45.680000,35.316925,-21.039490,0.013413,0.001742,0.044255,157.097534,8.002930,0.442545,-21.039490,0.045243,0.000000
45.890003,35.924263,-21.083971,0.013430,0.001757,0.044618,159.799103,8.140554,0.446179,-21.083971,0.045599,0.000000
46.100002,36.294029,-21.083971,0.013417,0.001769,0.044922,161.443909,8.224344,0.449222,-21.083971,0.045946,0.000000
46.310001,36.615761,-21.083971,0.013461,0.001781,0.045234,162.875046,8.297251,0.452340,-21.083971,0.046292,0.000000
46.520000,36.882004,-21.128452,0.013452,0.001794,0.045555,164.059341,8.357582,0.455550,-21.128452,0.046648,0.000000
46.730003,37.376892,-21.083971,0.013469,0.001805,0.045841,166.260727,8.469725,0.458411,-21.083971,0.046995,0.000000
46.940002,38.203186,-21.083971,0.013486,0.001821,0.046248,169.936264,8.656966,0.462484,-21.083971,0.047341,0.000000
47.150002,38.386765,-21.083971,0.013491,0.001829,0.046448,170.752853,8.698565,0.464482,-21.083971,0.047697,0.000000
47.360001,38.813126,-21.083971,0.013499,0.001840,0.046743,172.649399,8.795179,0.467435,-21.083971,0.048044,0.000000
47.570004,39.549309,-21.083971,0.013512,0.001856,0.047142,175.924118,8.962002,0.471416,-21.083971,0.048391,0.000000
47.780003,40.588600,-21.083971,0.013508,0.001877,0.047672,180.547104,9.197509,0.476715,-21.083971,0.048746,0.000000
47.990002,41.019066,-21.083971,0.013512,0.001890,0.048018,182.461914,9.295053,0.480182,-21.083971,0.049093,0.000000
48.200001,41.327019,-21.128452,0.013560,0.001900,0.048270,183.831757,9.364837,0.482695,-21.128452,0.049449,0.000000
48.410004,41.793228,-21.083971,0.013560,0.001916,0.048660,185.905563,9.470481,0.486601,-21.083971,0.049796,0.000000
48.620003,42.472435,-21.128452,0.013573,0.001929,0.049007,188.926834,9.624392,0.490068,-21.128452,0.050142,0.000000
48.830002,43.101372,-21.128452,0.013573,0.001945,0.049405,191.724472,9.766911,0.494050,-21.128452,0.050498,0.000000
49.040001,43.617851,-21.128452,0.013573,0.001958,0.049735,194.021896,9.883946,0.497350,-21.128452,0.050845,0.000000
49.250004,43.623062,-21.083971,0.013611,0.001962,0.049839,194.045074,9.885127,0.498395,-21.083971,0.051191,0.000000
49.460003,44.354774,-21.083971,0.013603,0.001976,0.050195,197.299896,10.050936,0.501953,-21.083971,0.051547,0.000000
49.670002,45.633133,-21.128452,0.013620,0.002001,0.050828,202.986313,10.340616,0.508281,-21.128452,0.051894,0.000000
49.880001,46.217384,-21.128452,0.013629,0.002015,0.051184,205.585190,10.473009,0.511839,-21.128452,0.052241,0.000000
50.090004,46.405060,-21.128452,0.013659,0.002022,0.051347,206.420013,10.515537,0.513474,-21.128452,0.052596,0.000000
50.300003,47.020218,-21.128452,0.013659,0.002038,0.051756,209.156372,10.654933,0.517562,-21.128452,0.052943,0.000000
50.510002,47.749695,-21.172934,0.013668,0.002053,0.052138,212.401245,10.820235,0.521377,-21.172934,0.053299,0.000000
50.720001,48.717491,-21.217413,0.013693,0.002071,0.052615,216.706223,11.039541,0.526146,-21.217413,0.053646,0.000000
50.930004,49.032150,-21.083971,0.013702,0.002082,0.052883,218.105896,11.110844,0.528826,-21.083971,0.053992,0.000000
51.140003,49.594429,-21.217413,0.013689,0.002092,0.053143,220.607040,11.238258,0.531430,-21.217413,0.054348,0.000000
51.350002,49.950043,-21.172934,0.013715,0.002102,0.053394,222.188889,11.318841,0.533943,-21.172934,0.054695,0.000000
51.560001,51.266754,-21.128452,0.013711,0.002124,0.053950,228.045914,11.617212,0.539499,-21.128452,0.055043,0.000000
51.770004,52.244980,-21.217413,0.013732,0.002142,0.054409,232.397278,11.838881,0.544086,-21.217413,0.055397,0.000000
51.980003,52.518669,-21.172934,0.013745,0.002152,0.054652,233.614700,11.900901,0.546524,-21.172934,0.055745,0.000000
52.190002,53.125641,-21.172934,0.013749,0.002166,0.055025,236.314651,12.038443,0.550248,-21.172934,0.056092,0.000000
52.400002,53.756065,-21.172934,0.013775,0.002180,0.055364,239.118927,12.181298,0.553639,-21.172934,0.056448,0.000000
52.610001,54.810249,-21.217413,0.013762,0.002197,0.055797,243.808167,12.420179,0.557969,-21.217413,0.056795,0.000000
52.820004,55.398598,-21.217413,0.013797,0.002209,0.056100,246.425262,12.553502,0.560997,-21.217413,0.057141,0.000000
53.030003,55.455574,-21.172934,0.013793,0.002215,0.056257,246.678711,12.566413,0.562572,-21.172934,0.057497,0.000000
53.240002,55.819756,-21.306376,0.013784,0.002227,0.056577,248.298676,12.648937,0.565766,-21.306376,0.057844,0.000000
53.450001,57.384460,-21.172934,0.013793,0.002249,0.057132,255.258835,13.003505,0.571322,-21.172934,0.058200,0.000000
53.660004,58.389870,-21.172934,0.013831,0.002265,0.057539,259.731110,13.231334,0.575395,-21.172934,0.058546,0.000000
53.870003,58.886238,-21.306376,0.013849,0.002276,0.057818,261.939056,13.343812,0.578181,-21.306376,0.058893,0.000000
54.080002,59.529327,-21.217413,0.013862,0.002292,0.058225,264.799683,13.489538,0.582253,-21.217413,0.059249,0.000000
54.290001,60.135178,-21.306376,0.013849,0.002304,0.058511,267.494629,13.626826,0.585114,-21.306376,0.059595,0.000000
54.500004,60.618889,-21.217413,0.013874,0.002315,0.058789,269.646271,13.736437,0.587885,-21.217413,0.059942,0.000000
54.710003,61.932617,-21.261894,0.013887,0.002334,0.059274,275.490051,14.034132,0.592745,-21.261894,0.060298,0.000000
54.920002,62.199608,-21.306376,0.013887,0.002342,0.059482,276.677673,14.094633,0.594819,-21.306376,0.060645,0.000000
55.130001,62.806580,-21.217413,0.013870,0.002353,0.059768,279.377625,14.232175,0.597680,-21.217413,0.060991,0.000000
55.340004,63.365135,-21.306376,0.013922,0.002363,0.060028,281.862213,14.358745,0.600284,-21.306376,0.061347,0.000000
55.550003,65.316368,-21.217413,0.013939,0.002392,0.060749,290.541718,14.800900,0.607491,-21.217413,0.061694,0.000000
55.760002,65.654106,-21.306376,0.013956,0.002401,0.060991,292.044037,14.877433,0.609913,-21.306376,0.062050,0.000000
55.970001,65.978447,-21.261894,0.013948,0.002413,0.061287,293.486786,14.950930,0.612865,-21.261894,0.062396,0.000000
56.180004,66.745903,-21.217413,0.013948,0.002426,0.061617,296.900604,15.124838,0.616166,-21.217413,0.062743,0.000000
56.390003,67.322334,-21.261894,0.013943,0.002428,0.061668,299.464691,15.255459,0.616681,-21.261894,0.061910,0.000000
56.600002,66.853523,-21.261894,0.013987,0.002428,0.061668,297.379333,15.149225,0.616681,-21.261894,0.061910,0.000000
56.810001,66.503868,-21.261894,0.013969,0.002422,0.061521,295.823975,15.069992,0.615212,-21.261894,0.061668,0.000000
57.020004,66.197395,-21.306376,0.013987,0.002421,0.061494,294.460724,15.000545,0.614939,-21.306376,0.061668,0.000000
57.230003,65.939339,-21.261894,0.013995,0.002420,0.061477,293.312836,14.942067,0.614773,-21.261894,0.061668,0.000000
57.440002,65.728951,-21.261894,0.013995,0.002420,0.061468,292.376984,14.894393,0.614682,-21.261894,0.061668,0.000000
57.650002,65.530861,-21.217413,0.013965,0.002420,0.061468,291.495819,14.849505,0.614682,-21.217413,0.061668,0.000000
57.860004,65.369987,-21.261894,0.014008,0.002420,0.061468,290.780212,14.813051,0.614682,-21.261894,0.061668,0.000000
58.070004,65.212852,-21.306376,0.013987,0.002420,0.061459,290.081268,14.777444,0.614591,-21.306376,0.061668,0.000000
58.280003,65.074699,-21.261894,0.013978,0.002420,0.061459,289.466705,14.746138,0.614591,-21.261894,0.061668,0.000000
58.490002,64.941765,-21.306376,0.013969,0.002420,0.061459,288.875397,14.716014,0.614591,-21.306376,0.061668,0.000000
58.700005,64.824089,-21.261894,0.013995,0.002420,0.061459,288.351959,14.689349,0.614591,-21.261894,0.061668,0.000000
58.910004,64.697853,-21.306376,0.014012,0.002420,0.061459,287.790436,14.660743,0.614591,-21.306376,0.061668,0.000000
59.120003,64.607002,-21.306376,0.013982,0.002420,0.061459,287.386292,14.640156,0.614591,-21.306376,0.061668,0.000000
59.330002,64.503471,-21.261894,0.013974,0.002420,0.061459,286.925781,14.616695,0.614591,-21.261894,0.061668,0.000000
59.540005,64.431236,-21.306376,0.013974,0.002420,0.061459,286.604462,14.600327,0.614591,-21.306376,0.061668,0.000000
59.750004,64.330330,-21.306376,0.013987,0.002420,0.061459,286.155609,14.577461,0.614591,-21.306376,0.061668,0.000000
59.960003,64.269997,-21.350857,0.013982,0.002420,0.061459,285.887238,14.563789,0.614591,-21.350857,0.061668,0.000000
60.170002,64.188820,-21.350857,0.013987,0.002420,0.061459,285.526123,14.545394,0.614591,-21.350857,0.061668,0.000000
60.380001,64.114723,-21.306376,0.013969,0.002420,0.061459,285.196533,14.528604,0.614591,-21.306376,0.061668,0.000000
60.590004,64.038383,-21.350857,0.013995,0.002420,0.061459,284.856964,14.511305,0.614591,-21.350857,0.061668,0.000000
60.800003,63.978432,-21.350857,0.013987,0.002419,0.061452,284.590271,14.497720,0.614516,-21.350857,0.061668,0.000000
61.010002,63.919228,-21.350857,0.013995,0.002419,0.061452,284.326935,14.484303,0.614516,-21.350857,0.061668,0.000000
61.220001,63.862999,-21.350857,0.013982,0.002419,0.061452,284.076813,14.471562,0.614516,-21.350857,0.061668,0.000000
61.430004,63.801933,-21.306376,0.013969,0.002419,0.061452,283.805176,14.457725,0.614516,-21.306376,0.061668,0.000000
61.640003,63.748314,-21.350857,0.013995,0.002419,0.061452,283.566650,14.445575,0.614516,-21.350857,0.061668,0.000000
61.850002,63.693199,-21.395338,0.013991,0.002419,0.061452,283.321503,14.433085,0.614516,-21.395338,0.061668,0.000000
62.060001,63.650002,-21.350857,0.013995,0.002419,0.061452,283.129333,14.423297,0.614516,-21.350857,0.061668,0.000000
62.270004,63.605309,-21.439819,0.013999,0.002419,0.061452,282.930542,14.413169,0.614516,-21.439819,0.061668,0.000000
62.480003,63.546852,-21.306376,0.014004,0.002419,0.061452,282.670502,14.399922,0.614516,-21.306376,0.061668,0.000000
62.690002,63.498817,-21.350857,0.013991,0.002419,0.061452,282.456848,14.389038,0.614516,-21.350857,0.061668,0.000000
62.900002,63.467537,-21.395338,0.013991,0.002419,0.061452,282.317719,14.381949,0.614516,-21.395338,0.061668,0.000000
63.110004,63.409081,-21.350857,0.013999,0.002419,0.061452,282.057678,14.368703,0.614516,-21.350857,0.061668,0.000000
63.320004,63.377800,-21.350857,0.013974,0.002419,0.061452,281.918549,14.361614,0.614516,-21.350857,0.061668,0.000000
63.530003,63.334602,-21.395338,0.013987,0.002419,0.061452,281.726379,14.351826,0.614516,-21.395338,0.061668,0.000000
63.740002,63.308540,-21.439819,0.013999,0.002419,0.061452,281.610443,14.345921,0.614516,-21.439819,0.061668,0.000000
63.950005,63.273903,-21.439819,0.013999,0.002419,0.061452,281.456390,14.338072,0.614516,-21.439819,0.061668,0.000000
64.160004,63.236290,-21.395338,0.013991,0.002419,0.061452,281.289062,14.329548,0.614516,-21.395338,0.061668,0.000000
64.370003,63.196449,-21.350857,0.013974,0.002419,0.061452,281.111847,14.320520,0.614516,-21.350857,0.061668,0.000000
64.580002,63.159218,-21.350857,0.013982,0.002419,0.061452,280.946228,14.312083,0.614516,-21.350857,0.061668,0.000000
64.790001,63.132774,-21.439819,0.013987,0.002419,0.061452,280.828613,14.306091,0.614516,-21.439819,0.061668,0.000000
65.000000,63.096657,-21.439819,0.013995,0.002419,0.061452,280.667938,14.297907,0.614516,-21.439819,0.061668,0.000000
65.210007,63.067238,-21.395338,0.013995,0.002419,0.061452,280.537079,14.291241,0.614516,-21.395338,0.061668,0.000000
65.420006,63.038933,-21.484299,0.013995,0.002419,0.061452,280.411163,14.284826,0.614516,-21.484299,0.061668,0.000000
65.630005,63.000587,-21.439819,0.013999,0.002419,0.061452,280.240601,14.276137,0.614516,-21.439819,0.061668,0.000000
65.840004,62.964088,-21.439819,0.013991,0.002419,0.061452,280.078247,14.267866,0.614516,-21.439819,0.061668,0.000000
66.050003,62.938766,-21.395338,0.013982,0.002419,0.061452,279.965607,14.262128,0.614516,-21.395338,0.061668,0.000000
66.260002,62.920898,-21.439819,0.013999,0.002419,0.061452,279.886139,14.258080,0.614516,-21.439819,0.061668,0.000000
66.470001,62.887756,-21.395338,0.013987,0.002419,0.061452,279.738708,14.250569,0.614516,-21.395338,0.061668,0.000000
66.680000,62.866531,-21.439819,0.013978,0.002419,0.061452,279.644287,14.245759,0.614516,-21.439819,0.061668,0.000000
66.889999,62.826683,-21.484299,0.014008,0.002419,0.061452,279.467041,14.236731,0.614516,-21.484299,0.061668,0.000000
67.100006,62.808441,-21.350857,0.013991,0.002419,0.061452,279.385895,14.232596,0.614516,-21.350857,0.061668,0.000000
67.310005,62.788704,-21.439819,0.014012,0.002419,0.061452,279.298096,14.228124,0.614516,-21.439819,0.061668,0.000000
67.520004,62.760773,-21.484299,0.013978,0.002419,0.061452,279.173859,14.221794,0.614516,-21.484299,0.061668,0.000000
67.730003,62.728752,-21.439819,0.013982,0.002419,0.061452,279.031433,14.214539,0.614516,-21.439819,0.061668,0.000000
67.940002,62.702309,-21.439819,0.014030,0.002419,0.061452,278.913788,14.208547,0.614516,-21.439819,0.061668,0.000000
68.150002,62.683319,-21.439819,0.013956,0.002419,0.061452,278.829315,14.204243,0.614516,-21.439819,0.061668,0.000000
68.360001,62.669540,-21.439819,0.013991,0.002419,0.061452,278.768036,14.201121,0.614516,-21.439819,0.061668,0.000000
68.570000,62.642357,-21.528780,0.014008,0.002419,0.061452,278.647125,14.194962,0.614516,-21.528780,0.061668,0.000000
68.780006,62.620018,-21.439819,0.013982,0.002419,0.061452,278.547760,14.189899,0.614516,-21.439819,0.061668,0.000000
68.990005,62.599167,-21.528780,0.013974,0.002419,0.061452,278.454987,14.185174,0.614516,-21.528780,0.061668,0.000000
69.200005,62.572357,-21.484299,0.014012,0.002419,0.061452,278.335754,14.179098,0.614516,-21.484299,0.061668,0.000000
69.410004,62.554108,-21.484299,0.013995,0.002419,0.061452,278.254578,14.174963,0.614516,-21.484299,0.061668,0.000000
69.620003,62.531021,-21.484299,0.013987,0.002419,0.061452,278.151886,14.169732,0.614516,-21.484299,0.061668,0.000000
69.830002,62.513519,-21.439819,0.014004,0.002419,0.061452,278.074036,14.165766,0.614516,-21.439819,0.061668,0.000000
70.040001,62.492294,-21.528780,0.013995,0.002419,0.061452,277.979614,14.160956,0.614516,-21.528780,0.061668,0.000000
70.250000,62.461388,-21.528780,0.013969,0.002419,0.061452,277.842133,14.153954,0.614516,-21.528780,0.061668,0.000000
70.460007,62.452454,-21.528780,0.013995,0.002419,0.061452,277.802399,14.151929,0.614516,-21.528780,0.061668,0.000000
70.670006,62.440536,-21.573261,0.013987,0.002419,0.061452,277.749390,14.149228,0.614516,-21.573261,0.061668,0.000000
70.880005,62.421913,-21.484299,0.013974,0.002419,0.061452,277.666534,14.145007,0.614516,-21.484299,0.061668,0.000000
71.090004,62.395477,-21.528780,0.013999,0.002419,0.061452,277.548950,14.139017,0.614516,-21.528780,0.061668,0.000000
71.300003,62.381325,-21.528780,0.013969,0.002419,0.061452,277.485992,14.135810,0.614516,-21.528780,0.061668,0.000000
71.510002,62.366432,-21.528780,0.014017,0.002419,0.061452,277.419739,14.132436,0.614516,-21.528780,0.061668,0.000000
71.720001,62.337013,-21.528780,0.013978,0.002419,0.061452,277.288879,14.125770,0.614516,-21.528780,0.061668,0.000000
71.930000,62.322121,-21.484299,0.013999,0.002419,0.061452,277.222626,14.122395,0.614516,-21.484299,0.061668,0.000000
72.140007,62.314301,-21.573261,0.014012,0.002419,0.061452,277.187866,14.120623,0.614516,-21.573261,0.061668,0.000000
72.350006,62.294937,-21.528780,0.013999,0.002419,0.061452,277.101715,14.116234,0.614516,-21.528780,0.061668,0.000000
72.560005,62.278549,-21.573261,0.013995,0.002419,0.061452,277.028809,14.112521,0.614516,-21.573261,0.061668,0.000000
72.770004,62.261421,-21.528780,0.014004,0.002419,0.061452,276.952637,14.108640,0.614516,-21.528780,0.061668,0.000000
72.980003,62.249138,-21.528780,0.013999,0.002419,0.061452,276.897980,14.105857,0.614516,-21.528780,0.061668,0.000000
73.190002,62.227539,-21.573261,0.014004,0.002419,0.061452,276.801910,14.100962,0.614516,-21.573261,0.061668,0.000000
73.400002,62.211899,-21.528780,0.013995,0.002419,0.061452,276.732361,14.097418,0.614516,-21.528780,0.061668,0.000000
73.610001,62.198120,-21.484299,0.013991,0.002419,0.061452,276.671051,14.094296,0.614516,-21.484299,0.061668,0.000000
73.820000,62.181732,-21.573261,0.013987,0.002419,0.061452,276.598145,14.090582,0.614516,-21.573261,0.061668,0.000000
74.030006,62.163864,-21.573261,0.014004,0.002419,0.061452,276.518677,14.086534,0.614516,-21.573261,0.061668,0.000000
74.240005,62.152321,-21.573261,0.013995,0.002419,0.061452,276.467346,14.083918,0.614516,-21.573261,0.061668,0.000000
74.450005,62.144501,-21.573261,0.013978,0.002419,0.061452,276.432556,14.082146,0.614516,-21.573261,0.061668,0.000000
74.660004,62.114708,-21.573261,0.013961,0.002419,0.061452,276.300018,14.075394,0.614516,-21.573261,0.061668,0.000000
74.870003,62.103539,-21.484299,0.013995,0.002419,0.061452,276.250336,14.072863,0.614516,-21.484299,0.061668,0.000000
75.080002,62.090508,-21.573261,0.013982,0.002419,0.061452,276.192383,14.069911,0.614516,-21.573261,0.061668,0.000000
75.290001,62.075233,-21.573261,0.014008,0.002419,0.061452,276.124420,14.066449,0.614516,-21.573261,0.061668,0.000000
75.500000,62.074493,-21.573261,0.013982,0.002419,0.061452,276.121124,14.066281,0.614516,-21.573261,0.061668,0.000000
75.710007,62.051033,-21.617743,0.014012,0.002419,0.061452,276.016785,14.060965,0.614516,-21.617743,0.061668,0.000000
75.920006,62.036507,-21.617743,0.014008,0.002419,0.061452,275.952148,14.057673,0.614516,-21.617743,0.061668,0.000000
76.130005,62.027199,-21.617743,0.014004,0.002419,0.061452,275.910767,14.055564,0.614516,-21.617743,0.061668,0.000000
76.340004,62.011932,-21.617743,0.013982,0.002419,0.061452,275.842865,14.052105,0.614516,-21.617743,0.061668,0.000000
76.550003,61.989594,-21.617743,0.013999,0.002419,0.061452,275.743469,14.047043,0.614516,-21.617743,0.061668,0.000000
76.760002,61.974327,-21.573261,0.013999,0.002419,0.061452,275.675568,14.043583,0.614516,-21.573261,0.061668,0.000000
76.970001,61.968742,-21.617743,0.014004,0.002419,0.061452,275.650726,14.042317,0.614516,-21.617743,0.061668,0.000000
77.180000,61.959427,-21.573261,0.013995,0.002419,0.061452,275.609283,14.040207,0.614516,-21.573261,0.061668,0.000000
77.390007,61.933365,-21.662224,0.014008,0.002419,0.061452,275.493378,14.034302,0.614516,-21.662224,0.061668,0.000000
77.600006,61.924423,-21.528780,0.014004,0.002419,0.061452,275.453583,14.032275,0.614516,-21.528780,0.061668,0.000000
77.810005,61.919960,-21.662224,0.013987,0.002419,0.061452,275.433746,14.031263,0.614516,-21.662224,0.061668,0.000000
78.020004,61.903946,-21.573261,0.013961,0.002419,0.061452,275.362518,14.027635,0.614516,-21.573261,0.061668,0.000000
78.230003,61.897614,-21.617743,0.014021,0.002419,0.061452,275.334351,14.026200,0.614516,-21.617743,0.061668,0.000000
78.440002,61.877510,-21.706703,0.013995,0.002419,0.061452,275.244904,14.021645,0.614516,-21.706703,0.061668,0.000000
78.650002,61.869316,-21.573261,0.014012,0.002419,0.061452,275.208466,14.019788,0.614516,-21.573261,0.061668,0.000000
78.860001,61.858147,-21.751184,0.013995,0.002419,0.061452,275.158783,14.017257,0.614516,-21.751184,0.061668,0.000000
79.070007,61.843620,-21.617743,0.013999,0.002419,0.061452,275.094177,14.013965,0.614516,-21.617743,0.061668,0.000000
79.280006,61.835060,-21.706703,0.013965,0.002419,0.061452,275.056091,14.012025,0.614516,-21.706703,0.061668,0.000000
79.490005,61.823883,-21.706703,0.014021,0.002419,0.061452,275.006378,14.009492,0.614516,-21.706703,0.061668,0.000000
79.700005,61.804893,-21.617743,0.013999,0.002419,0.061452,274.921906,14.005189,0.614516,-21.617743,0.061668,0.000000
79.910004,61.800423,-21.706703,0.014030,0.002419,0.061452,274.902008,14.004176,0.614516,-21.706703,0.061668,0.000000
80.120003,61.773613,-21.662224,0.013987,0.002419,0.061452,274.782745,13.998100,0.614516,-21.662224,0.061668,0.000000
80.330002,61.779572,-21.706703,0.014012,0.002419,0.061452,274.809265,13.999452,0.614516,-21.706703,0.061668,0.000000
80.540001,61.758720,-21.706703,0.013999,0.002419,0.061452,274.716522,13.994726,0.614516,-21.706703,0.061668,0.000000
80.750008,61.753136,-21.706703,0.013991,0.002419,0.061452,274.691681,13.993461,0.614516,-21.706703,0.061668,0.000000
80.960007,61.730789,-21.706703,0.014004,0.002419,0.061452,274.592255,13.988397,0.614516,-21.706703,0.061668,0.000000
81.170006,61.736382,-21.662224,0.014004,0.002419,0.061452,274.617126,13.989664,0.614516,-21.662224,0.061668,0.000000
81.380005,61.720741,-21.662224,0.014012,0.002419,0.061452,274.547577,13.986119,0.614516,-21.662224,0.061668,0.000000
81.590004,61.711800,-21.706703,0.014004,0.002419,0.061452,274.507782,13.984094,0.614516,-21.706703,0.061668,0.000000
81.800003,61.705475,-21.662224,0.014025,0.002419,0.061452,274.479675,13.982660,0.614516,-21.662224,0.061668,0.000000
82.010002,61.689835,-21.706703,0.014017,0.002419,0.061452,274.410095,13.979116,0.614516,-21.706703,0.061668,0.000000
82.220001,61.677917,-21.706703,0.013999,0.002419,0.061452,274.357086,13.976416,0.614516,-21.706703,0.061668,0.000000
82.430000,61.658554,-21.617743,0.014012,0.002419,0.061452,274.270935,13.972028,0.614516,-21.617743,0.061668,0.000000
82.640007,61.654083,-21.706703,0.013987,0.002419,0.061452,274.251068,13.971015,0.614516,-21.706703,0.061668,0.000000
82.850006,61.647751,-21.706703,0.014017,0.002419,0.061452,274.222900,13.969580,0.614516,-21.706703,0.061668,0.000000
83.060005,61.642540,-21.706703,0.014017,0.002419,0.061452,274.199707,13.968399,0.614516,-21.706703,0.061668,0.000000
83.270004,61.630249,-21.706703,0.013987,0.002419,0.061452,274.145050,13.965614,0.614516,-21.706703,0.061668,0.000000
83.480003,61.615356,-21.662224,0.013999,0.002419,0.061452,274.078796,13.962240,0.614516,-21.662224,0.061668,0.000000
83.690002,61.616104,-21.751184,0.013987,0.002419,0.061452,274.082123,13.962409,0.614516,-21.751184,0.061668,0.000000
83.900002,61.604187,-21.706703,0.013991,0.002419,0.061452,274.029114,13.959708,0.614516,-21.706703,0.061668,0.000000
84.110001,61.597115,-21.795666,0.013999,0.002419,0.061452,273.997650,13.958105,0.614516,-21.795666,0.061668,0.000000
84.320007,61.577003,-21.751184,0.014008,0.002419,0.061452,273.908203,13.953548,0.614516,-21.751184,0.061668,0.000000
84.530006,61.570297,-21.795666,0.014008,0.002419,0.061452,273.878357,13.952028,0.614516,-21.795666,0.061668,0.000000
84.740005,61.567322,-21.795666,0.014004,0.002419,0.061452,273.865112,13.951355,0.614516,-21.795666,0.061668,0.000000
84.950005,61.552795,-21.706703,0.013999,0.002419,0.061452,273.800507,13.948063,0.614516,-21.706703,0.061668,0.000000
85.160004,61.556519,-21.795666,0.013982,0.002419,0.061452,273.817078,13.948906,0.614516,-21.795666,0.061668,0.000000
85.370003,61.536789,-21.751184,0.013995,0.002419,0.061452,273.729309,13.944436,0.614516,-21.751184,0.061668,0.000000
85.580002,61.537529,-21.751184,0.013991,0.002419,0.061452,273.732605,13.944603,0.614516,-21.751184,0.061668,0.000000
85.790001,61.511841,-21.795666,0.013987,0.002419,0.061452,273.618347,13.938782,0.614516,-21.795666,0.061668,0.000000
86.000008,61.509605,-21.795666,0.014008,0.002419,0.061452,273.608398,13.938275,0.614516,-21.795666,0.061668,0.000000
86.210007,61.497688,-21.751184,0.013999,0.002419,0.061452,273.555389,13.935575,0.614516,-21.751184,0.061668,0.000000
86.420006,61.493965,-21.795666,0.013991,0.002419,0.061452,273.538818,13.934732,0.614516,-21.795666,0.061668,0.000000
86.630005,61.485771,-21.840147,0.014004,0.002419,0.061452,273.502380,13.932875,0.614516,-21.840147,0.061668,0.000000
86.800003,61.485397,-21.706703,0.014025,0.002419,0.061452,273.500702,13.932791,0.614516,-21.706703,0.061668,0.000000