File: Data/New pin align test AD 5_08172023_165203.csv
Time (sec),S:Load (lbs),S:HL1 (DIM),S:LVDT (in),S:Position (in),Ch:Position (mm),Ch:Load (N),Ch:Stress (MPa),Ch:Strain (mm/mm),Ch:HL1 (DIM),Set Point (),Cycles ()
0.010000,-0.003724,-150.523544,0.000047,-0.000000,-0.000000,-0.016564,-0.000844,-0.000000,-150.523544,0.000251,0.000000
0.190000,-0.002607,-150.479065,0.000052,-0.000000,-0.000000,-0.011595,-0.000591,-0.000000,-150.479065,0.000251,0.000000
0.370000,-0.022342,-150.568024,0.000039,0.000006,0.000148,-0.099384,-0.005063,0.001484,-150.568024,0.000772,0.000000
0.550000,-0.016757,-150.523544,0.000017,0.000116,0.002940,-0.074538,-0.003797,0.029401,-150.523544,0.003773,0.000000
0.730000,-0.056973,-150.523544,0.000108,0.000215,0.005473,-0.253428,-0.012910,0.054730,-150.523544,0.006773,0.000000
0.910000,-0.070006,-150.479065,0.000160,0.000335,0.008507,-0.311402,-0.015864,0.085069,-150.479065,0.009774,0.000000
1.090000,-0.051015,-150.479065,0.000341,0.000460,0.011673,-0.226926,-0.011560,0.116726,-150.479065,0.012775,0.000000
1.270000,-0.002607,-150.479065,0.000470,0.000576,0.014638,-0.011595,-0.000591,0.146385,-150.479065,0.015775,0.000000
1.450000,0.017129,-150.523544,0.000535,0.000694,0.017632,0.076194,0.003882,0.176316,-150.523544,0.018776,0.000000
1.630000,0.017874,-150.568024,0.000716,0.000816,0.020728,0.079507,0.004050,0.207276,-150.568024,0.021759,0.000000
1.810000,0.016757,-150.479065,0.000836,0.000926,0.023519,0.074538,0.003797,0.235193,-150.479065,0.024759,0.000000
1.990000,0.009682,-150.479065,0.000944,0.001042,0.026459,0.043066,0.002194,0.264594,-150.479065,0.027760,0.000000
2.170000,0.022715,-150.479065,0.001022,0.001163,0.029537,0.101040,0.005147,0.295373,-150.479065,0.030761,0.000000
2.350000,0.001490,-150.523544,0.001168,0.001277,0.032443,0.006626,0.000338,0.324426,-150.523544,0.033761,0.000000
2.530000,0.002234,-150.523544,0.001285,0.001396,0.035461,0.009938,0.000506,0.354614,-150.523544,0.036762,0.000000
2.710000,-0.001862,-150.390091,0.001431,0.001525,0.038739,-0.008282,-0.000422,0.387392,-150.390091,0.039763,0.000000
2.890000,0.002607,-150.479065,0.001509,0.001633,0.041489,0.011595,0.000591,0.414885,-150.479065,0.042763,0.000000
3.070000,-0.027928,-150.479065,0.001690,0.001758,0.044654,-0.124230,-0.006329,0.446542,-150.479065,0.045764,0.000000
3.250000,-0.035748,-150.523544,0.001785,0.001877,0.047672,-0.159014,-0.008101,0.476715,-150.523544,0.048765,0.000000
3.430000,-0.000000,-150.434570,0.001923,0.001994,0.050646,-0.000000,-0.000000,0.506464,-150.434570,0.051747,0.000000
3.610000,-0.001862,-150.479065,0.002035,0.002110,0.053587,-0.008282,-0.000422,0.535865,-150.479065,0.054748,0.000000
3.790000,-0.014150,-150.434570,0.002151,0.002232,0.056690,-0.062943,-0.003206,0.566902,-150.434570,0.057748,0.000000
3.970000,0.010054,-150.434570,0.002272,0.002355,0.059804,0.044723,0.002278,0.598044,-150.434570,0.060749,0.000000
4.150000,0.006330,-150.345612,0.002384,0.002473,0.062822,0.028159,0.001434,0.628217,-150.345612,0.063750,0.000000
4.330000,0.019363,-150.434570,0.002514,0.002589,0.065762,0.086132,0.004388,0.657618,-150.434570,0.066750,0.000000
4.510000,0.006703,-150.434570,0.002634,0.002707,0.068746,0.029815,0.001519,0.687458,-150.434570,0.069751,0.000000
4.690000,0.029790,-150.390091,0.002768,0.002811,0.071391,0.132512,0.006750,0.713907,-150.390091,0.072752,0.000000
4.870000,0.009309,-150.390091,0.002880,0.002940,0.074677,0.041410,0.002110,0.746775,-150.390091,0.075752,0.000000
5.050000,0.008565,-150.390091,0.003005,0.003062,0.077764,0.038097,0.001941,0.777645,-150.390091,0.078735,0.000000
5.230000,0.005586,-150.390091,0.003130,0.003178,0.080730,0.024846,0.001266,0.807303,-150.390091,0.081736,0.000000
5.410000,0.018619,-150.345612,0.003203,0.003294,0.083670,0.082820,0.004219,0.836704,-150.345612,0.084736,0.000000
5.590000,0.023459,-150.434570,0.003385,0.003412,0.086653,0.104353,0.005316,0.866529,-150.434570,0.087737,0.000000
5.770000,0.011916,-150.390091,0.003488,0.003528,0.089602,0.053005,0.002700,0.896021,-150.390091,0.090738,0.000000
5.950000,0.003351,-150.301132,0.003609,0.003650,0.092698,0.014907,0.000759,0.926981,-150.301132,0.093738,0.000000
6.130000,0.005958,-150.345612,0.003704,0.003768,0.095715,0.026502,0.001350,0.957155,-150.345612,0.096739,0.000000
6.310000,0.029790,-150.345612,0.003842,0.003885,0.098690,0.132512,0.006750,0.986904,-150.345612,0.099740,0.000000
6.490000,0.015640,-150.345612,0.003992,0.004004,0.101700,0.069569,0.003544,1.017001,-150.345612,0.102740,0.000000
6.670001,0.023087,-150.345612,0.004113,0.004122,0.104708,0.102696,0.005232,1.047084,-150.345612,0.105741,0.000000
6.850000,0.033514,-150.345612,0.004217,0.004239,0.107667,0.149076,0.007594,1.076666,-150.345612,0.108725,0.000000
7.030000,0.012288,-150.345612,0.004286,0.004356,0.110642,0.054661,0.002785,1.106416,-150.345612,0.111726,0.000000
7.210001,0.013405,-150.345612,0.004471,0.004477,0.113710,0.059630,0.003038,1.137104,-150.345612,0.114726,0.000000
7.390000,0.029417,-150.301132,0.004549,0.004594,0.116676,0.130855,0.006666,1.166762,-150.301132,0.117725,0.000000
7.570000,0.050270,-150.301132,0.004656,0.004706,0.119521,0.223613,0.011391,1.195209,-150.301132,0.120726,0.000000
7.750000,0.031279,-150.301132,0.004799,0.004825,0.122547,0.139137,0.007088,1.225473,-150.301132,0.123727,0.000000
7.930000,0.033886,-150.301132,0.004945,0.004947,0.125662,0.150732,0.007679,1.256615,-150.301132,0.126727,0.000000
8.110001,0.021598,-150.301132,0.005075,0.005067,0.128705,0.096071,0.004894,1.287046,-150.301132,0.129728,0.000000
8.290000,0.038727,-150.256653,0.005191,0.005185,0.131705,0.172265,0.008776,1.317053,-150.256653,0.132729,0.000000
8.470000,0.043568,-150.301132,0.005333,0.005301,0.134636,0.193798,0.009873,1.346363,-150.301132,0.135713,0.000000
8.650001,0.032024,-150.301132,0.005415,0.005416,0.137569,0.142450,0.007257,1.375688,-150.301132,0.138713,0.000000
8.830001,0.016384,-150.301132,0.005575,0.005537,0.140630,0.072882,0.003713,1.406300,-150.301132,0.141714,0.000000
9.010000,0.018619,-150.256653,0.005644,0.005657,0.143691,0.082820,0.004219,1.436913,-150.256653,0.144715,0.000000
9.190001,0.020481,-150.256653,0.005816,0.005773,0.146639,0.091102,0.004641,1.466389,-150.256653,0.147715,0.000000
9.370001,0.030535,-150.256653,0.005872,0.005896,0.149753,0.135825,0.006919,1.497532,-150.256653,0.150716,0.000000
9.550000,0.016757,-150.301132,0.006040,0.006013,0.152727,0.074538,0.003797,1.527266,-150.301132,0.153717,0.000000
9.730000,0.071496,-150.256653,0.006131,0.006119,0.155415,0.318028,0.016201,1.554154,-150.256653,0.156716,0.000000
9.910001,0.062931,-150.212173,0.006247,0.006234,0.158346,0.279931,0.014260,1.583464,-150.212173,0.159717,0.000000
10.090000,0.068144,-150.167694,0.006385,0.006360,0.161538,0.303120,0.015442,1.615378,-150.167694,0.162717,0.000000
10.270000,0.039472,-150.212173,0.006528,0.006478,0.164548,0.175578,0.008944,1.645476,-150.212173,0.165701,0.000000
10.450001,0.055111,-150.256653,0.006635,0.006602,0.167678,0.245146,0.012488,1.676784,-150.256653,0.168702,0.000000
10.630000,0.057718,-150.212173,0.006748,0.006721,0.170723,0.256741,0.013079,1.707230,-150.212173,0.171703,0.000000
10.810000,0.041333,-150.123215,0.006903,0.006839,0.173722,0.183860,0.009366,1.737221,-150.123215,0.174703,0.000000
10.990001,0.035375,-150.078735,0.006998,0.006951,0.176550,0.157358,0.008016,1.765502,-150.078735,0.177704,0.000000
11.170000,0.013778,-150.167694,0.007127,0.007071,0.179611,0.061287,0.003122,1.796114,-150.167694,0.180705,0.000000
11.350000,0.007075,-150.167694,0.007282,0.007190,0.182621,0.031471,0.001603,1.826212,-150.167694,0.183705,0.000000
11.530001,0.030535,-150.167694,0.007364,0.007309,0.185648,0.135825,0.006919,1.856476,-150.167694,0.186706,0.000000
11.710001,0.043940,-150.123215,0.007498,0.007430,0.188735,0.195455,0.009957,1.887345,-150.123215,0.189707,0.000000
11.890000,0.070006,-150.078735,0.007644,0.007542,0.191570,0.311402,0.015864,1.915702,-150.078735,0.192689,0.000000
12.070001,0.070378,-150.078735,0.007804,0.007659,0.194545,0.313059,0.015948,1.945451,-150.078735,0.195690,0.000000
12.250001,0.072985,-150.123215,0.007899,0.007774,0.197467,0.324653,0.016539,1.974671,-150.123215,0.198690,0.000000
12.430000,0.074847,-150.167694,0.008019,0.007888,0.200356,0.332935,0.016961,2.003557,-150.167694,0.201691,0.000000
12.610001,0.063676,-150.078735,0.008157,0.008008,0.203391,0.283244,0.014429,2.033912,-150.078735,0.204692,0.000000
12.790001,0.061441,-150.078735,0.008278,0.008134,0.206608,0.273305,0.013923,2.066083,-150.078735,0.207692,0.000000
12.970000,0.068889,-150.034241,0.008390,0.008253,0.209618,0.306433,0.015610,2.096181,-150.034241,0.210693,0.000000
13.150001,0.072985,-150.034241,0.008532,0.008367,0.212514,0.324653,0.016539,2.125143,-150.034241,0.213694,0.000000
13.330001,0.055111,-150.034241,0.008614,0.008483,0.215480,0.245146,0.012488,2.154801,-150.034241,0.216694,0.000000
13.510000,0.040216,-150.078735,0.008817,0.008603,0.218507,0.178891,0.009113,2.185065,-150.078735,0.219677,0.000000
13.690001,0.017502,-150.034241,0.008890,0.008721,0.221516,0.077851,0.003966,2.215163,-150.034241,0.222677,0.000000
13.870001,0.033514,-150.078735,0.009037,0.008841,0.224550,0.149076,0.007594,2.245502,-150.078735,0.225678,0.000000
14.050000,0.107243,-150.034241,0.009145,0.008960,0.227595,0.477042,0.024302,2.275948,-150.034241,0.228679,0.000000
14.230000,0.110595,-149.989761,0.009313,0.009077,0.230561,0.491949,0.025061,2.305607,-149.989761,0.231679,0.000000
14.410001,0.135544,-149.945282,0.009438,0.009199,0.233657,0.602928,0.030715,2.336567,-149.945282,0.234680,0.000000
14.590001,0.144108,-149.989761,0.009524,0.009305,0.236355,0.641025,0.032655,2.363546,-149.989761,0.237681,0.000000
14.770000,0.160120,-149.989761,0.009623,0.009422,0.239311,0.712250,0.036284,2.393113,-149.989761,0.240681,0.000000
14.950001,0.287844,-150.034241,0.009804,0.009547,0.242503,1.280394,0.065226,2.425028,-150.034241,0.243682,0.000000
15.130001,0.713838,-149.989761,0.009899,0.000009,0.000235,3.175310,0.161758,0.002347,-149.989761,0.001397,0.000000
15.310000,0.644577,-149.900803,0.009882,0.000000,0.000009,2.867220,0.146063,0.000091,-149.900803,0.000253,0.000000
15.490001,0.641225,-149.945282,0.009951,0.000000,0.000009,2.852313,0.145304,0.000091,-149.945282,0.000253,0.000000
15.670001,0.637129,-149.945282,0.009960,0.000000,0.000009,2.834093,0.144376,0.000091,-149.945282,0.000260,0.000000
15.850000,0.659844,-149.945282,0.009925,0.000000,0.000009,2.935133,0.149523,0.000091,-149.945282,0.000556,0.000000
16.030001,0.668781,-149.945282,0.009899,0.000001,0.000018,2.974886,0.151548,0.000182,-149.945282,0.000860,0.000000
16.210001,0.716817,-149.900803,0.009938,0.000009,0.000235,3.188561,0.162433,0.002347,-149.900803,0.001163,0.000000
16.390001,0.760385,-149.811844,0.009968,0.000018,0.000460,3.382360,0.172306,0.004602,-149.811844,0.001458,0.000000
16.570002,0.908589,-149.900803,0.009955,0.000037,0.000946,4.041605,0.205889,0.009462,-149.900803,0.001761,0.000000
16.750000,0.999075,-149.856323,0.009947,0.000050,0.001276,4.444109,0.226394,0.012763,-149.856323,0.002056,0.000000
16.930000,1.081742,-149.856323,0.009981,0.000058,0.001467,4.811829,0.245126,0.014670,-149.856323,0.002360,0.000000
17.110001,1.187496,-149.856323,0.009994,0.000069,0.001744,5.282245,0.269090,0.017441,-149.856323,0.002663,0.000000
17.290001,1.269790,-149.811844,0.009968,0.000080,0.002021,5.648309,0.287739,0.020211,-149.811844,0.002958,0.000000
17.470001,1.363256,-149.811844,0.010016,0.000089,0.002265,6.064064,0.308918,0.022649,-149.811844,0.003261,0.000000
17.650002,1.523003,-149.856323,0.010007,0.000102,0.002602,6.774657,0.345118,0.026025,-149.856323,0.003556,0.000000
17.830000,1.630991,-149.811844,0.009990,0.000111,0.002828,7.255013,0.369588,0.028281,-149.811844,0.003861,0.000000
18.010000,1.702859,-149.811844,0.009998,0.000117,0.002967,7.574697,0.385873,0.029674,-149.811844,0.004163,0.000000
18.190001,1.871172,-149.722885,0.010003,0.000131,0.003331,8.323387,0.424014,0.033307,-149.722885,0.004459,0.000000
18.370001,2.012301,-149.767365,0.010046,0.000143,0.003635,8.951160,0.455994,0.036350,-149.767365,0.004761,0.000000
18.550001,2.271100,-149.767365,0.010007,0.000163,0.004138,10.102355,0.514639,0.041376,-149.767365,0.005057,0.000000
18.730001,2.463616,-149.767365,0.010003,0.000178,0.004528,10.958712,0.558263,0.045282,-149.767365,0.005361,0.000000
18.910002,2.614799,-149.722885,0.010067,0.000189,0.004805,11.631209,0.592522,0.048053,-149.722885,0.005655,0.000000
19.090000,2.686295,-149.722885,0.010093,0.000197,0.005005,11.949237,0.608723,0.050051,-149.722885,0.005959,0.000000
19.270000,2.821094,-149.767365,0.010076,0.000208,0.005282,12.548852,0.639269,0.052822,-149.767365,0.006262,0.000000
19.450001,2.987172,-149.767365,0.010089,0.000220,0.005585,13.287604,0.676903,0.055850,-149.767365,0.006557,0.000000
19.630001,3.037814,-149.767365,0.010141,0.000224,0.005699,13.512874,0.688379,0.056985,-149.767365,0.006860,0.000000
19.810001,3.418751,-149.722885,0.010111,0.000246,0.006236,15.207366,0.774700,0.062360,-149.722885,0.007155,0.000000
19.990002,3.610896,-149.678406,0.010132,0.000259,0.006574,16.062065,0.818241,0.065736,-149.678406,0.007459,0.000000
20.170000,3.719629,-149.678406,0.010132,0.000267,0.006792,16.545734,0.842880,0.067916,-149.678406,0.007762,0.000000
20.350000,3.931881,-149.722885,0.010158,0.000280,0.007113,17.489880,0.890977,0.071126,-149.722885,0.008057,0.000000
20.530001,4.071893,-149.678406,0.010171,0.000288,0.007311,18.112684,0.922704,0.073109,-149.678406,0.008360,0.000000
20.710001,4.432350,-149.678406,0.010175,0.000307,0.007788,19.716076,1.004385,0.077878,-149.678406,0.008655,0.000000
20.890001,4.615929,-149.589432,0.010197,0.000318,0.008066,20.532679,1.045985,0.080664,-149.589432,0.008960,0.000000
21.070002,4.752217,-149.678406,0.010205,0.000328,0.008327,21.138918,1.076868,0.083268,-149.678406,0.009262,0.000000
21.250002,4.977875,-149.633926,0.010192,0.000337,0.008569,22.142694,1.128003,0.085690,-149.633926,0.009558,0.000000
21.430000,5.132410,-149.633926,0.010201,0.000347,0.008804,22.830101,1.163021,0.088037,-149.633926,0.009860,0.000000
21.610001,5.270560,-149.633926,0.010201,0.000353,0.008967,23.444620,1.194326,0.089672,-149.633926,0.010156,0.000000
21.790001,5.861887,-149.589432,0.010240,0.000378,0.009592,26.074978,1.328323,0.095924,-149.589432,0.010460,0.000000
21.970001,6.037647,-149.589432,0.010261,0.000387,0.009818,26.856796,1.368150,0.098180,-149.589432,0.010763,0.000000
22.150002,6.275221,-149.589432,0.010270,0.000398,0.010113,27.913576,1.421985,0.101132,-149.589432,0.011058,0.000000
22.330002,6.501623,-149.589432,0.010227,0.000410,0.010407,28.920664,1.473289,0.104069,-149.589432,0.011361,0.000000
22.510000,6.899317,-149.500473,0.010270,0.000425,0.010798,30.689695,1.563408,0.107975,-149.500473,0.011656,0.000000
22.690001,7.207642,-149.500473,0.010322,0.000438,0.011135,32.061192,1.633275,0.111352,-149.500473,0.011960,0.000000
22.870001,7.386008,-149.544952,0.010326,0.000446,0.011335,32.854603,1.673693,0.113350,-149.544952,0.012263,0.000000
23.050001,7.516338,-149.544952,0.010326,0.000455,0.011561,33.434341,1.703227,0.115606,-149.544952,0.012558,0.000000
23.230001,7.816471,-149.544952,0.010305,0.000467,0.011865,34.769398,1.771237,0.118649,-149.544952,0.012861,0.000000
23.410002,8.291990,-149.500473,0.010339,0.000482,0.012246,36.884613,1.878992,0.122464,-149.500473,0.013156,0.000000
23.590002,8.682981,-149.455994,0.010369,0.000496,0.012593,38.623829,1.967592,0.125931,-149.455994,0.013461,0.000000
23.770000,8.961887,-149.500473,0.010335,0.000506,0.012854,39.864468,2.030793,0.128535,-149.500473,0.013763,0.000000
23.950001,9.112327,-149.500473,0.010365,0.000514,0.013061,40.533653,2.064883,0.130609,-149.500473,0.014059,0.000000
24.130001,9.539065,-149.455994,0.010361,0.000529,0.013433,42.431881,2.161583,0.134333,-149.455994,0.014361,0.000000
24.310001,9.994849,-149.455994,0.010391,0.000543,0.013798,44.459309,2.264865,0.137982,-149.455994,0.014657,0.000000
24.490002,10.258489,-149.455994,0.010417,0.000553,0.014050,45.632038,2.324607,0.140495,-149.455994,0.014961,0.000000
24.670002,10.680759,-149.500473,0.010455,0.000567,0.014405,47.510391,2.420295,0.144053,-149.500473,0.015264,0.000000
24.850000,10.811834,-149.455994,0.010417,0.000573,0.014552,48.093441,2.449997,0.145522,-149.455994,0.015559,0.000000
25.030001,11.006957,-149.455994,0.010404,0.000584,0.014838,48.961391,2.494212,0.148383,-149.455994,0.015862,0.000000
25.210001,11.441144,-149.411514,0.010434,0.000597,0.015159,50.892750,2.592600,0.151593,-149.411514,0.016157,0.000000
25.390001,11.834742,-149.367035,0.010460,0.000607,0.015412,52.643559,2.681791,0.154121,-149.367035,0.016461,0.000000
25.570002,12.460327,-149.411514,0.010481,0.000624,0.015845,55.426304,2.823551,0.158451,-149.411514,0.016764,0.000000
25.750002,12.643535,-149.455994,0.010499,0.000631,0.016036,56.241253,2.865066,0.160358,-149.455994,0.017059,0.000000
25.930000,12.953348,-149.367035,0.010499,0.000643,0.016322,57.619370,2.935271,0.163220,-149.367035,0.017362,0.000000
26.110001,13.011810,-149.411514,0.010494,0.000646,0.016401,57.879421,2.948518,0.164007,-149.411514,0.017657,0.000000
26.290001,13.460892,-149.322556,0.010486,0.000657,0.016694,59.877037,3.050282,0.166944,-149.322556,0.017962,0.000000
26.470001,14.351606,-149.367035,0.010524,0.000682,0.017311,63.839134,3.252120,0.173106,-149.367035,0.018255,0.000000
26.650002,14.594021,-149.411514,0.010520,0.000692,0.017580,64.917450,3.307052,0.175801,-149.411514,0.018560,0.000000
26.830002,14.958574,-149.367035,0.010563,0.000704,0.017892,66.539062,3.389661,0.178920,-149.367035,0.018862,0.000000
27.010002,15.266153,-149.367035,0.010529,0.000714,0.018143,67.907242,3.459360,0.181433,-149.367035,0.019158,0.000000
27.190001,15.784496,-149.278076,0.010563,0.000726,0.018438,70.212944,3.576818,0.184385,-149.278076,0.019462,0.000000
27.370001,16.214214,-149.322556,0.010593,0.000739,0.018759,72.124428,3.674194,0.187595,-149.322556,0.019756,0.000000
27.550001,16.537806,-149.322556,0.010576,0.000749,0.019027,73.563835,3.747520,0.190274,-149.322556,0.020060,0.000000
27.730001,17.000292,-149.322556,0.010602,0.000762,0.019348,75.621078,3.852321,0.193484,-149.322556,0.020363,0.000000
27.910002,17.054287,-149.322556,0.010611,0.000767,0.019479,75.861259,3.864557,0.194786,-149.322556,0.020658,0.000000
28.090002,17.635559,-149.233597,0.010602,0.000784,0.019904,78.446884,3.996275,0.199040,-149.233597,0.020962,0.000000
28.270000,18.209759,-149.278076,0.010649,0.000796,0.020216,81.001053,4.126390,0.202159,-149.278076,0.021256,0.000000
28.450001,18.814117,-149.322556,0.010637,0.000810,0.020572,83.689377,4.263340,0.205717,-149.322556,0.021560,0.000000
28.630001,19.131380,-149.233597,0.010624,0.000821,0.020858,85.100632,4.335232,0.208578,-149.233597,0.021863,0.000000
28.810001,19.412149,-149.278076,0.010662,0.000830,0.021091,86.349556,4.398856,0.210909,-149.278076,0.022158,0.000000
28.990002,19.964748,-149.189117,0.010649,0.000843,0.021421,88.807632,4.524076,0.214210,-149.189117,0.022463,0.000000
29.170002,20.301746,-149.278076,0.010701,0.000854,0.021690,90.306679,4.600441,0.216905,-149.278076,0.022756,0.000000
29.350002,21.036810,-149.278076,0.010701,0.000870,0.022089,93.576401,4.767009,0.220886,-149.278076,0.023061,0.000000
29.530001,21.354071,-149.233597,0.010675,0.000879,0.022332,94.987648,4.838902,0.223324,-149.233597,0.023363,0.000000
29.710001,21.681013,-149.189117,0.010731,0.000891,0.022635,96.441963,4.912988,0.226352,-149.189117,0.023659,0.000000
29.890001,22.003117,-149.144623,0.010701,0.000899,0.022826,97.874748,4.985978,0.228259,-149.144623,0.023963,0.000000
30.070002,22.587368,-149.144623,0.010714,0.000913,0.023191,100.473633,5.118371,0.231908,-149.144623,0.024257,0.000000
30.250002,23.343657,-149.189117,0.010718,0.000930,0.023615,103.837769,5.289748,0.236147,-149.189117,0.024561,0.000000
30.430002,23.867584,-149.189117,0.010753,0.000943,0.023954,106.168320,5.408472,0.239538,-149.189117,0.024864,0.000000
30.610001,24.225435,-149.100143,0.010762,0.000952,0.024187,107.760117,5.489562,0.241870,-149.100143,0.025159,0.000000
30.790001,24.521471,-149.100143,0.010770,0.000964,0.024491,109.076950,5.556645,0.244913,-149.100143,0.025462,0.000000
30.970001,25.120247,-149.100143,0.010800,0.000976,0.024787,111.740440,5.692329,0.247865,-149.100143,0.025757,0.000000
31.150002,25.498203,-149.144623,0.010796,0.000986,0.025054,113.421677,5.777976,0.250545,-149.144623,0.026061,0.000000
31.330002,26.188583,-149.144623,0.010818,0.001001,0.025428,116.492638,5.934418,0.254284,-149.144623,0.026364,0.000000
31.510002,26.507706,-149.100143,0.010813,0.001009,0.025627,117.912163,6.006732,0.256268,-149.100143,0.026659,0.000000
31.690002,26.759058,-149.100143,0.010826,0.001017,0.025836,119.030235,6.063689,0.258357,-149.100143,0.026962,0.000000
31.870001,27.046902,-149.055664,0.010831,0.001026,0.026052,120.310631,6.128916,0.260522,-149.055664,0.027257,0.000000
32.050003,27.564499,-149.100143,0.010852,0.001037,0.026347,122.613014,6.246205,0.263474,-149.100143,0.027562,0.000000
32.230003,28.629856,-149.100143,0.010809,0.001059,0.026911,127.351959,6.487618,0.269106,-149.100143,0.027864,0.000000
32.410000,29.309437,-148.966705,0.010865,0.001072,0.027241,130.374893,6.641613,0.272406,-148.966705,0.028160,0.000000
32.590000,29.621485,-149.011185,0.010895,0.001082,0.027474,131.762939,6.712325,0.274738,-149.011185,0.028462,0.000000
32.770000,30.023647,-149.100143,0.010882,0.001094,0.027778,133.551849,6.803456,0.277781,-149.100143,0.028758,0.000000
32.950001,30.563587,-149.011185,0.010839,0.001106,0.028099,135.953629,6.925808,0.280991,-149.011185,0.029062,0.000000
33.130001,30.953833,-149.055664,0.010874,0.001117,0.028359,137.689529,7.014239,0.283595,-149.055664,0.029365,0.000000
33.310001,31.742889,-148.966705,0.010874,0.001132,0.028758,141.199417,7.193041,0.287576,-148.966705,0.029660,0.000000
33.490002,31.952164,-148.966705,0.010930,0.001139,0.028923,142.130325,7.240464,0.289227,-148.966705,0.029963,0.000000
33.670002,32.207985,-149.011185,0.010938,0.001147,0.029122,143.268265,7.298433,0.291225,-149.011185,0.030258,0.000000
33.850002,32.343155,-148.966705,0.010938,0.001152,0.029253,143.869537,7.329064,0.292527,-148.966705,0.030562,0.000000
34.030003,33.075615,-148.966705,0.010947,0.001166,0.029616,147.127686,7.495041,0.296160,-148.966705,0.030865,0.000000
34.210003,34.410568,-148.966705,0.010938,0.001190,0.030232,153.065857,7.797546,0.302322,-148.966705,0.031160,0.000000
34.390003,34.892792,-148.922226,0.010994,0.001202,0.030527,155.210892,7.906820,0.305274,-148.922226,0.031463,0.000000
34.570004,35.179516,-148.922226,0.010981,0.001211,0.030753,156.486298,7.971792,0.307530,-148.922226,0.031758,0.000000
34.750000,35.630459,-148.877747,0.010968,0.001222,0.031039,158.492203,8.073977,0.310392,-148.877747,0.032063,0.000000
34.930000,36.047520,-148.966705,0.011007,0.001232,0.031300,160.347382,8.168485,0.312996,-148.966705,0.032356,0.000000
35.110001,36.899879,-148.833267,0.011007,0.001249,0.031716,164.138855,8.361631,0.317159,-148.833267,0.032661,0.000000
35.290001,37.302414,-148.922226,0.010999,0.001260,0.032002,165.929428,8.452848,0.320020,-148.922226,0.032963,0.000000
35.470001,37.711651,-148.922226,0.011007,0.001268,0.032209,167.749802,8.545582,0.322095,-148.922226,0.033259,0.000000
35.650002,38.195362,-148.877747,0.011037,0.001279,0.032496,169.901459,8.655193,0.324956,-148.877747,0.033563,0.000000
35.830002,38.534592,-148.922226,0.011037,0.001291,0.032782,171.410431,8.732063,0.327817,-148.922226,0.033857,0.000000
36.010002,39.497921,-148.833267,0.011016,0.001307,0.033198,175.695526,8.950356,0.331981,-148.833267,0.034161,0.000000
36.190002,40.174892,-148.833267,0.011055,0.001320,0.033528,178.706848,9.103761,0.335281,-148.833267,0.034464,0.000000
36.370003,40.564770,-148.788788,0.011063,0.001329,0.033761,180.441101,9.192109,0.337613,-148.788788,0.034759,0.000000
36.550003,40.924850,-148.877747,0.011072,0.001340,0.034047,182.042831,9.273704,0.340474,-148.877747,0.035063,0.000000
36.730003,41.439842,-148.877747,0.011068,0.001352,0.034343,184.333618,9.390402,0.343426,-148.877747,0.035357,0.000000
36.910000,42.200974,-148.788788,0.011081,0.001367,0.034733,187.719299,9.562878,0.347332,-148.788788,0.035661,0.000000
37.090000,42.956516,-148.744293,0.011111,0.001380,0.035054,191.080124,9.734085,0.350542,-148.744293,0.035964,0.000000
37.270000,43.306545,-148.788788,0.011111,0.001389,0.035289,192.637131,9.813403,0.352888,-148.788788,0.036259,0.000000
37.450001,43.665886,-148.744293,0.011128,0.001400,0.035557,194.235565,9.894832,0.355568,-148.744293,0.036564,0.000000
37.630001,44.166355,-148.788788,0.011102,0.001410,0.035808,196.461761,10.008239,0.358081,-148.788788,0.036857,0.000000
37.810001,45.035473,-148.699814,0.011150,0.001426,0.036224,200.327789,10.205184,0.362245,-148.699814,0.037162,0.000000
37.990002,45.720638,-148.744293,0.011128,0.001439,0.036545,203.375549,10.360445,0.365454,-148.744293,0.037464,0.000000
38.170002,46.234138,-148.744293,0.011171,0.001451,0.036850,205.659714,10.476806,0.368497,-148.744293,0.037760,0.000000
38.350002,46.537251,-148.788788,0.011171,0.001459,0.037057,207.008026,10.545492,0.370571,-148.788788,0.038064,0.000000
38.530003,46.912601,-148.699814,0.011163,0.001468,0.037283,208.677673,10.630548,0.372827,-148.699814,0.038358,0.000000
38.710003,47.448818,-148.655334,0.011158,0.001479,0.037569,211.062881,10.752056,0.375689,-148.655334,0.038662,0.000000
38.890003,47.944817,-148.655334,0.011240,0.001490,0.037838,213.269196,10.864450,0.378384,-148.655334,0.038965,0.000000
39.070004,48.672062,-148.699814,0.011188,0.001503,0.038185,216.504150,11.029247,0.381850,-148.699814,0.039260,0.000000
39.250000,49.073853,-148.610855,0.011219,0.001511,0.038376,218.291397,11.120294,0.383758,-148.610855,0.039564,0.000000
39.430000,49.681564,-148.699814,0.011219,0.001522,0.038671,220.994629,11.258003,0.386710,-148.699814,0.039858,0.000000
39.610001,50.103462,-148.610855,0.011180,0.001533,0.038939,222.871338,11.353607,0.389390,-148.610855,0.040162,0.000000
39.790001,50.468388,-148.655334,0.011236,0.001543,0.039199,224.494598,11.436300,0.391994,-148.655334,0.040465,0.000000
39.970001,51.810043,-148.610855,0.011249,0.001564,0.039728,230.462585,11.740324,0.397278,-148.610855,0.040760,0.000000
40.150002,52.630753,-148.699814,0.011219,0.001579,0.040118,234.113281,11.926299,0.401184,-148.699814,0.041065,0.000000
40.330002,53.070526,-148.655334,0.011253,0.001590,0.040379,236.069489,12.025953,0.403788,-148.655334,0.041358,0.000000
40.510002,53.391136,-148.566376,0.011279,0.001600,0.040639,237.495636,12.098604,0.406392,-148.566376,0.041663,0.000000
40.690002,53.861443,-148.566376,0.011279,0.001609,0.040874,239.587662,12.205177,0.408738,-148.566376,0.041965,0.000000
40.870003,54.545494,-148.610855,0.011266,0.001620,0.041160,242.630478,12.360186,0.411600,-148.610855,0.042261,0.000000
41.050003,54.747692,-148.610855,0.011305,0.001628,0.041342,243.529892,12.406005,0.413417,-148.610855,0.042565,0.000000
41.230003,56.039822,-148.566376,0.011322,0.001648,0.041862,249.277573,12.698805,0.418625,-148.566376,0.042859,0.000000
41.410004,56.599873,-148.432938,0.011313,0.001658,0.042121,251.768814,12.825714,0.421213,-148.432938,0.043163,0.000000
41.590000,57.075390,-148.521896,0.011318,0.001670,0.042426,253.884018,12.933469,0.424256,-148.521896,0.043466,0.000000
41.770000,57.699116,-148.566376,0.011292,0.001681,0.042694,256.658478,13.074807,0.426936,-148.566376,0.043761,0.000000
41.950001,58.383533,-148.566376,0.011318,0.001696,0.043075,259.702942,13.229897,0.430751,-148.566376,0.044064,0.000000
42.130001,59.125301,-148.521896,0.011369,0.001708,0.043389,263.002472,13.397985,0.433885,-148.521896,0.044359,0.000000
42.310001,59.379261,-148.477417,0.011339,0.001716,0.043596,264.132141,13.455533,0.435959,-148.477417,0.044663,0.000000
42.490002,59.968353,-148.521896,0.011365,0.001729,0.043908,266.752563,13.589024,0.439078,-148.521896,0.044957,0.000000
42.670002,60.521324,-148.477417,0.011374,0.001740,0.044186,269.212280,13.714329,0.441864,-148.477417,0.045261,0.000000
42.850002,60.886993,-148.477417,0.011369,0.001747,0.044368,270.838867,13.797190,0.443681,-148.477417,0.045564,0.000000
43.030003,61.211704,-148.477417,0.011357,0.001757,0.044638,272.283264,13.870770,0.446375,-148.477417,0.045859,0.000000
43.210003,63.062023,-148.432938,0.011426,0.001780,0.045210,280.513885,14.290058,0.452098,-148.432938,0.046164,0.000000
43.390003,63.362156,-148.432938,0.011395,0.001787,0.045382,281.848938,14.358069,0.453824,-148.432938,0.046457,0.000000
43.570004,63.973965,-148.388458,0.011400,0.001800,0.045712,284.570404,14.496708,0.457124,-148.388458,0.046762,0.000000
43.750004,64.649818,-148.432938,0.011413,0.001812,0.046024,287.576752,14.649858,0.460243,-148.432938,0.047064,0.000000
43.930000,65.677193,-148.432938,0.011408,0.001828,0.046432,292.146759,14.882665,0.464316,-148.432938,0.047360,0.000000
44.110001,66.270004,-148.343979,0.011460,0.001839,0.046701,294.783691,15.016998,0.467011,-148.343979,0.047664,0.000000
44.290001,66.695999,-148.432938,0.011447,0.001849,0.046952,296.678619,15.113529,0.469524,-148.432938,0.047958,0.000000
44.470001,67.027039,-148.388458,0.011438,0.001858,0.047187,298.151154,15.188543,0.471870,-148.388458,0.048262,0.000000
44.650002,67.388611,-148.477417,0.011464,0.001856,0.047152,299.759521,15.270477,0.471522,-148.477417,0.047385,0.000000
44.830002,67.024437,-148.388458,0.011477,0.001856,0.047152,298.139587,15.187954,0.471522,-148.388458,0.047385,0.000000
45.010002,66.799149,-148.388458,0.011469,0.001855,0.047117,297.137451,15.136904,0.471174,-148.388458,0.047152,0.000000
45.190002,66.547424,-148.299484,0.011460,0.001853,0.047064,296.017731,15.079863,0.470644,-148.299484,0.047152,0.000000
45.370003,66.337776,-148.388458,0.011486,0.001852,0.047048,295.085175,15.032355,0.470478,-148.388458,0.047152,0.000000
45.550003,66.157921,-148.388458,0.011456,0.001852,0.047039,294.285126,14.991599,0.470387,-148.388458,0.047152,0.000000
45.730003,65.991470,-148.343979,0.011490,0.001852,0.047031,293.544708,14.953881,0.470311,-148.343979,0.047152,0.000000
45.910004,65.840286,-148.299484,0.011451,0.001852,0.047031,292.872223,14.919622,0.470311,-148.299484,0.047152,0.000000
46.090004,65.704002,-148.299484,0.011477,0.001851,0.047022,292.265991,14.888740,0.470220,-148.299484,0.047152,0.000000
46.270000,65.578888,-148.388458,0.011490,0.001851,0.047022,291.709473,14.860388,0.470220,-148.388458,0.047152,0.000000
46.450001,65.467545,-148.343979,0.011456,0.001851,0.047013,291.214172,14.835157,0.470129,-148.343979,0.047152,0.000000
46.630001,65.370354,-148.299484,0.011451,0.001851,0.047013,290.781860,14.813134,0.470129,-148.299484,0.047152,0.000000
46.810001,65.268700,-148.255005,0.011520,0.001851,0.047013,290.329681,14.790098,0.470129,-148.255005,0.047152,0.000000
46.990002,65.170395,-148.210526,0.011507,0.001851,0.047013,289.892395,14.767822,0.470129,-148.210526,0.047152,0.000000
47.170002,65.091446,-148.210526,0.011503,0.001851,0.047013,289.541199,14.749933,0.470129,-148.210526,0.047152,0.000000
47.350002,65.019951,-148.255005,0.011477,0.001851,0.047004,289.223175,14.733731,0.470039,-148.255005,0.047152,0.000000
47.530003,64.946968,-148.255005,0.011490,0.001851,0.047004,288.898529,14.717194,0.470039,-148.255005,0.047152,0.000000
47.710003,64.863930,-148.210526,0.011490,0.001851,0.047004,288.529175,14.698377,0.470039,-148.210526,0.047152,0.000000
47.890003,64.784988,-148.121567,0.011503,0.001851,0.047004,288.178009,14.680489,0.470039,-148.121567,0.047152,0.000000
48.070004,64.731369,-148.210526,0.011477,0.001851,0.047004,287.939514,14.668338,0.470039,-148.210526,0.047152,0.000000
48.250004,64.660614,-148.255005,0.011490,0.001851,0.047004,287.624786,14.652305,0.470039,-148.255005,0.047152,0.000000
48.430004,64.616676,-148.210526,0.011464,0.001850,0.046996,287.429321,14.642348,0.469963,-148.210526,0.047152,0.000000
48.610001,64.561935,-148.166046,0.011460,0.001850,0.046996,287.185822,14.629944,0.469963,-148.166046,0.047152,0.000000
48.790001,64.510551,-148.166046,0.011486,0.001850,0.046996,286.957275,14.618300,0.469963,-148.166046,0.047152,0.000000
48.970001,64.452087,-148.166046,0.011490,0.001850,0.046996,286.697205,14.605051,0.469963,-148.166046,0.047152,0.000000
49.150002,64.405540,-148.166046,0.011507,0.001850,0.046996,286.490143,14.594504,0.469963,-148.166046,0.047152,0.000000
49.330002,64.367561,-148.121567,0.011486,0.001850,0.046996,286.321198,14.585897,0.469963,-148.121567,0.047152,0.000000
49.510002,64.306488,-148.121567,0.011482,0.001850,0.046996,286.049530,14.572059,0.469963,-148.121567,0.047152,0.000000
49.690002,64.259567,-148.121567,0.011486,0.001850,0.046996,285.840820,14.561426,0.469963,-148.121567,0.047152,0.000000
49.870003,64.219353,-148.121567,0.011503,0.001850,0.046996,285.661957,14.552313,0.469963,-148.121567,0.047152,0.000000
50.050003,64.194405,-148.166046,0.011451,0.001850,0.046996,285.550964,14.546659,0.469963,-148.166046,0.047152,0.000000
50.230003,64.140785,-148.032608,0.011447,0.001850,0.046987,285.312469,14.534510,0.469872,-148.032608,0.047152,0.000000
50.410004,64.109505,-148.032608,0.011499,0.001850,0.046987,285.173309,14.527422,0.469872,-148.032608,0.047152,0.000000
50.590004,64.075249,-148.077087,0.011469,0.001850,0.046987,285.020935,14.519659,0.469872,-148.077087,0.047152,0.000000
50.770004,64.034286,-148.032608,0.011473,0.001850,0.046987,284.838745,14.510377,0.469872,-148.032608,0.047152,0.000000
50.950001,63.997051,-148.121567,0.011464,0.001850,0.046987,284.673096,14.501939,0.469872,-148.121567,0.047152,0.000000
51.130001,63.972847,-148.077087,0.011451,0.001850,0.046987,284.565430,14.496454,0.469872,-148.077087,0.047152,0.000000
51.310001,63.920715,-148.032608,0.011460,0.001850,0.046987,284.333557,14.484642,0.469872,-148.032608,0.047152,0.000000
51.490002,63.906563,-148.032608,0.011516,0.001850,0.046987,284.270599,14.481434,0.469872,-148.032608,0.047152,0.000000
51.670002,63.865231,-148.032608,0.011495,0.001850,0.046987,284.086731,14.472068,0.469872,-148.032608,0.047152,0.000000
51.850002,63.826504,-148.032608,0.011495,0.001850,0.046987,283.914459,14.463293,0.469872,-148.032608,0.047152,0.000000
52.030003,63.801182,-148.032608,0.011460,0.001850,0.046987,283.801819,14.457554,0.469872,-148.032608,0.047152,0.000000
52.210003,63.791126,-148.032608,0.011464,0.001850,0.046987,283.757111,14.455276,0.469872,-148.032608,0.047152,0.000000
52.390003,63.757244,-147.988129,0.011473,0.001850,0.046987,283.606384,14.447598,0.469872,-147.988129,0.047152,0.000000
52.570004,63.723358,-147.943649,0.011469,0.001850,0.046987,283.455658,14.439919,0.469872,-147.943649,0.047152,0.000000
52.750004,63.699154,-147.988129,0.011464,0.001850,0.046987,283.347992,14.434434,0.469872,-147.988129,0.047152,0.000000
52.930004,63.649254,-147.988129,0.011482,0.001850,0.046987,283.126007,14.423127,0.469872,-147.988129,0.047152,0.000000
53.110004,63.640690,-147.943649,0.011456,0.001850,0.046987,283.087921,14.421186,0.469872,-147.943649,0.047152,0.000000
53.290001,63.619835,-147.899155,0.011495,0.001850,0.046987,282.995148,14.416461,0.469872,-147.899155,0.047152,0.000000
53.470001,63.584835,-147.943649,0.011482,0.001850,0.046987,282.839478,14.408530,0.469872,-147.943649,0.047152,0.000000
53.650002,63.575523,-147.943649,0.011495,0.001850,0.046987,282.798065,14.406419,0.469872,-147.943649,0.047152,0.000000
53.830002,63.544991,-147.899155,0.011490,0.001850,0.046987,282.662231,14.399501,0.469872,-147.899155,0.047152,0.000000
54.010002,63.525627,-147.854675,0.011512,0.001850,0.046987,282.576111,14.395113,0.469872,-147.854675,0.047152,0.000000
54.190002,63.501793,-147.854675,0.011520,0.001850,0.046978,282.470093,14.389712,0.469781,-147.854675,0.047152,0.000000
54.370003,63.473495,-147.899155,0.011503,0.001850,0.046978,282.344208,14.383299,0.469781,-147.899155,0.047152,0.000000
54.550003,63.466419,-147.943649,0.011490,0.001850,0.046978,282.312744,14.381696,0.469781,-147.943649,0.047152,0.000000
54.730003,63.412426,-147.899155,0.011464,0.001850,0.046978,282.072571,14.369461,0.469781,-147.899155,0.047152,0.000000
54.910004,63.417637,-147.899155,0.011495,0.001850,0.046978,282.095734,14.370642,0.469781,-147.899155,0.047152,0.000000
55.090004,63.397903,-147.854675,0.011499,0.001850,0.046978,282.007965,14.366170,0.469781,-147.854675,0.047152,0.000000
55.270004,63.364388,-147.810196,0.011499,0.001850,0.046978,281.858887,14.358575,0.469781,-147.810196,0.047152,0.000000
55.450001,63.348377,-147.810196,0.011499,0.001850,0.046978,281.787659,14.354947,0.469781,-147.810196,0.047152,0.000000
55.630001,63.321938,-147.810196,0.011451,0.001850,0.046978,281.670044,14.348956,0.469781,-147.810196,0.047152,0.000000
55.810001,63.306297,-147.765717,0.011456,0.001850,0.046978,281.600464,14.345412,0.469781,-147.765717,0.047152,0.000000
55.990002,63.286564,-147.765717,0.011499,0.001850,0.046978,281.512695,14.340940,0.469781,-147.765717,0.047152,0.000000
56.170002,63.276508,-147.810196,0.011499,0.001850,0.046978,281.467957,14.338661,0.469781,-147.810196,0.047152,0.000000
56.350002,63.253422,-147.810196,0.011499,0.001850,0.046978,281.365265,14.333430,0.469781,-147.810196,0.047152,0.000000
56.530003,63.247463,-147.721237,0.011503,0.001850,0.046978,281.338776,14.332080,0.469781,-147.721237,0.047152,0.000000
56.710003,63.222141,-147.765717,0.011490,0.001850,0.046978,281.226135,14.326343,0.469781,-147.765717,0.047152,0.000000
56.890003,63.217300,-147.721237,0.011512,0.001850,0.046978,281.204590,14.325245,0.469781,-147.721237,0.047152,0.000000
57.070004,63.183414,-147.810196,0.011495,0.001850,0.046978,281.053864,14.317566,0.469781,-147.810196,0.047152,0.000000
57.250004,63.164799,-147.721237,0.011482,0.001850,0.046978,280.971069,14.313348,0.469781,-147.721237,0.047152,0.000000
57.430004,63.152138,-147.721237,0.011490,0.001850,0.046978,280.914734,14.310478,0.469781,-147.721237,0.047152,0.000000
57.610004,63.137615,-147.765717,0.011495,0.001850,0.046978,280.850128,14.307189,0.469781,-147.765717,0.047152,0.000000
57.790001,63.118252,-147.721237,0.011460,0.001850,0.046978,280.764008,14.302800,0.469781,-147.721237,0.047152,0.000000
57.970001,63.104099,-147.721237,0.011477,0.001850,0.046978,280.701050,14.299594,0.469781,-147.721237,0.047152,0.000000
58.150002,63.080643,-147.676758,0.011490,0.001850,0.046978,280.596710,14.294278,0.469781,-147.676758,0.047152,0.000000
58.330002,63.066120,-147.721237,0.011477,0.001850,0.046978,280.532104,14.290987,0.469781,-147.721237,0.047152,0.000000
58.510002,63.047501,-147.587799,0.011477,0.001850,0.046978,280.449280,14.286768,0.469781,-147.587799,0.047152,0.000000
58.690002,63.039307,-147.632278,0.011499,0.001850,0.046978,280.412842,14.284911,0.469781,-147.632278,0.047152,0.000000
58.870003,63.011009,-147.632278,0.011495,0.001850,0.046978,280.286957,14.278499,0.469781,-147.632278,0.047152,0.000000
59.050003,63.003189,-147.632278,0.011482,0.001850,0.046978,280.252167,14.276727,0.469781,-147.632278,0.047152,0.000000
59.230003,62.991272,-147.587799,0.011477,0.001850,0.046978,280.199158,14.274026,0.469781,-147.587799,0.047152,0.000000
59.410004,62.987549,-147.587799,0.011486,0.001850,0.046978,280.182617,14.273183,0.469781,-147.587799,0.047152,0.000000
59.590004,62.962971,-147.543320,0.011482,0.001850,0.046978,280.073273,14.267613,0.469781,-147.543320,0.047152,0.000000
59.770004,62.951427,-147.632278,0.011516,0.001850,0.046978,280.021942,14.264997,0.469781,-147.632278,0.047152,0.000000
59.950005,62.926853,-147.587799,0.011490,0.001850,0.046978,279.912628,14.259429,0.469781,-147.587799,0.047152,0.000000
60.130001,62.920151,-147.587799,0.011490,0.001850,0.046978,279.882812,14.257910,0.469781,-147.587799,0.047152,0.000000
60.310001,62.907490,-147.543320,0.011477,0.001850,0.046978,279.826477,14.255041,0.469781,-147.543320,0.047152,0.000000
60.490002,62.899296,-147.498840,0.011464,0.001850,0.046978,279.790039,14.253183,0.469781,-147.498840,0.047152,0.000000
60.670002,62.886265,-147.543320,0.011482,0.001850,0.046978,279.732086,14.250232,0.469781,-147.543320,0.047152,0.000000
60.850002,62.867645,-147.587799,0.011512,0.001850,0.046978,279.649261,14.246012,0.469781,-147.587799,0.047152,0.000000
61.030003,62.860943,-147.498840,0.011486,0.001850,0.046978,279.619446,14.244493,0.469781,-147.498840,0.047152,0.000000
61.210003,62.848282,-147.498840,0.011499,0.001850,0.046978,279.563110,14.241624,0.469781,-147.498840,0.047152,0.000000
61.390003,62.851261,-147.498840,0.011507,0.001850,0.046978,279.576385,14.242300,0.469781,-147.498840,0.047152,0.000000
61.570004,62.838226,-147.498840,0.011486,0.001850,0.046978,279.518402,14.239346,0.469781,-147.498840,0.047152,0.000000
61.750004,62.807693,-147.498840,0.011516,0.001850,0.046978,279.382568,14.232427,0.469781,-147.498840,0.047152,0.000000
61.930004,62.785351,-147.543320,0.011495,0.001850,0.046978,279.283203,14.227364,0.469781,-147.543320,0.047152,0.000000
62.110004,62.787212,-147.409866,0.011469,0.001850,0.046978,279.291473,14.227786,0.469781,-147.409866,0.047152,0.000000
62.290005,62.768593,-147.454346,0.011507,0.001850,0.046978,279.208649,14.223566,0.469781,-147.454346,0.047152,0.000000
62.470001,62.781628,-147.454346,0.011495,0.001850,0.046978,279.266632,14.226521,0.469781,-147.454346,0.047152,0.000000
62.650002,62.747368,-147.409866,0.011486,0.001850,0.046978,279.114227,14.218757,0.469781,-147.409866,0.047152,0.000000
62.830002,62.737686,-147.365387,0.011464,0.001850,0.046978,279.071167,14.216563,0.469781,-147.365387,0.047152,0.000000
63.010002,62.726887,-147.409866,0.011516,0.001850,0.046978,279.023132,14.214116,0.469781,-147.409866,0.047152,0.000000
63.190002,62.709385,-147.409866,0.011495,0.001850,0.046978,278.945282,14.210150,0.469781,-147.409866,0.047152,0.000000
63.370003,62.706779,-147.454346,0.011499,0.001850,0.046978,278.933685,14.209559,0.469781,-147.454346,0.047152,0.000000
63.550003,62.701939,-147.454346,0.011495,0.001850,0.046978,278.912140,14.208463,0.469781,-147.454346,0.047152,0.000000
63.730003,62.682575,-147.365387,0.011482,0.001850,0.046978,278.826019,14.204074,0.469781,-147.365387,0.047152,0.000000
63.910004,62.673637,-147.365387,0.011529,0.001850,0.046978,278.786255,14.202048,0.469781,-147.365387,0.047152,0.000000
64.090004,62.672520,-147.365387,0.011499,0.001850,0.046978,278.781281,14.201797,0.469781,-147.365387,0.047152,0.000000
64.270004,62.635284,-147.365387,0.011507,0.001850,0.046978,278.615662,14.193358,0.469781,-147.365387,0.047152,0.000000
64.450005,62.627838,-147.409866,0.011490,0.001850,0.046978,278.582550,14.191671,0.469781,-147.409866,0.047152,0.000000
64.630005,62.626720,-147.276428,0.011460,0.001850,0.046978,278.577576,14.191418,0.469781,-147.276428,0.047152,0.000000
64.810005,62.611454,-147.276428,0.011516,0.001850,0.046978,278.509644,14.187958,0.469781,-147.276428,0.047152,0.000000
64.990005,62.608475,-147.276428,0.011486,0.001850,0.046978,278.496399,14.187284,0.469781,-147.276428,0.047152,0.000000
65.170006,62.607727,-147.320908,0.011477,0.001850,0.046978,278.493073,14.187114,0.469781,-147.320908,0.047152,0.000000
65.350006,62.591717,-147.320908,0.011473,0.001850,0.046978,278.421875,14.183486,0.469781,-147.320908,0.047152,0.000000
65.530006,62.575333,-147.231949,0.011516,0.001850,0.046978,278.348969,14.179773,0.469781,-147.231949,0.047152,0.000000
65.710007,62.559319,-147.231949,0.011464,0.001849,0.046969,278.277740,14.176145,0.469690,-147.231949,0.047152,0.000000
65.889999,62.566395,-147.231949,0.011469,0.001849,0.046969,278.309235,14.177748,0.469690,-147.231949,0.047152,0.000000
66.070000,62.538467,-147.276428,0.011482,0.001849,0.046969,278.184998,14.171419,0.469690,-147.276428,0.047152,0.000000
66.250000,62.539955,-147.231949,0.011477,0.001849,0.046969,278.191620,14.171757,0.469690,-147.231949,0.047152,0.000000
66.430000,62.532509,-147.187469,0.011451,0.001849,0.046969,278.158478,14.170069,0.469690,-147.187469,0.047152,0.000000
66.610001,62.522083,-147.142990,0.011477,0.001849,0.046969,278.112122,14.167706,0.469690,-147.142990,0.047152,0.000000
66.790001,62.522453,-147.142990,0.011473,0.001849,0.046969,278.113770,14.167790,0.469690,-147.142990,0.047152,0.000000
66.970001,62.498997,-147.187469,0.011473,0.001849,0.046969,278.009430,14.162475,0.469690,-147.187469,0.047152,0.000000
67.150002,62.497879,-147.187469,0.011482,0.001849,0.046969,278.004456,14.162222,0.469690,-147.187469,0.047152,0.000000
67.330002,62.484474,-147.187469,0.011503,0.001849,0.046969,277.944824,14.159184,0.469690,-147.187469,0.047152,0.000000
67.510002,62.479633,-147.142990,0.011507,0.001849,0.046969,277.923279,14.158088,0.469690,-147.142990,0.047152,0.000000
67.690002,62.460270,-147.187469,0.011503,0.001849,0.046969,277.837158,14.153700,0.469690,-147.187469,0.047152,0.000000
67.870003,62.464367,-147.187469,0.011499,0.001849,0.046969,277.855377,14.154628,0.469690,-147.187469,0.047152,0.000000
68.050003,62.451332,-147.142990,0.011477,0.001849,0.046969,277.797394,14.151674,0.469690,-147.142990,0.047152,0.000000
68.230003,62.447979,-147.098511,0.011507,0.001849,0.046969,277.782471,14.150914,0.469690,-147.098511,0.047152,0.000000
68.410004,62.439415,-147.054031,0.011490,0.001849,0.046969,277.744385,14.148973,0.469690,-147.054031,0.047152,0.000000
68.590004,62.426754,-147.142990,0.011486,0.001849,0.046969,277.688080,14.146105,0.469690,-147.142990,0.047152,0.000000
68.770004,62.410744,-147.142990,0.011473,0.001849,0.046969,277.616852,14.142477,0.469690,-147.142990,0.047152,0.000000
68.950005,62.409252,-147.098511,0.011473,0.001849,0.046969,277.610229,14.142138,0.469690,-147.098511,0.047152,0.000000
69.130005,62.396595,-147.098511,0.011499,0.001849,0.046969,277.553925,14.139271,0.469690,-147.098511,0.047152,0.000000
69.310005,62.395477,-147.054031,0.011495,0.001849,0.046969,277.548950,14.139017,0.469690,-147.054031,0.047152,0.000000
69.490005,62.376114,-147.054031,0.011469,0.001849,0.046969,277.462799,14.134630,0.469690,-147.054031,0.047152,0.000000
69.670006,62.381325,-147.098511,0.011507,0.001849,0.046969,277.485992,14.135810,0.469690,-147.098511,0.047152,0.000000
69.850006,62.370899,-147.009537,0.011464,0.001849,0.046969,277.439606,14.133448,0.469690,-147.009537,0.047152,0.000000
70.030006,62.363079,-147.009537,0.011507,0.001849,0.046969,277.404816,14.131676,0.469690,-147.009537,0.047152,0.000000
70.210007,62.357494,-147.054031,0.011490,0.001849,0.046969,277.379974,14.130410,0.469690,-147.054031,0.047152,0.000000
70.390007,62.342972,-147.009537,0.011529,0.001849,0.046969,277.315399,14.127119,0.469690,-147.009537,0.047152,0.000000
70.570000,62.334408,-147.098511,0.011503,0.001849,0.046969,277.277283,14.125179,0.469690,-147.098511,0.047152,0.000000
70.750000,62.321373,-147.054031,0.011477,0.001849,0.046969,277.219299,14.122225,0.469690,-147.054031,0.047152,0.000000
70.930000,62.313553,-147.009537,0.011482,0.001849,0.046969,277.184540,14.120453,0.469690,-147.009537,0.047152,0.000000
71.110001,62.316906,-146.965057,0.011477,0.001849,0.046969,277.199432,14.121213,0.469690,-146.965057,0.047152,0.000000
71.290001,62.307224,-146.965057,0.011525,0.001849,0.046969,277.156372,14.119019,0.469690,-146.965057,0.047152,0.000000
71.470001,62.303871,-147.009537,0.011495,0.001849,0.046969,277.141449,14.118258,0.469690,-147.009537,0.047152,0.000000
71.650002,62.294189,-146.920578,0.011460,0.001849,0.046969,277.098389,14.116065,0.469690,-146.920578,0.047152,0.000000
71.830002,62.287487,-146.876099,0.011469,0.001849,0.046969,277.068573,14.114547,0.469690,-146.876099,0.047152,0.000000
72.010002,62.281158,-146.876099,0.011486,0.001849,0.046969,277.040436,14.113112,0.469690,-146.876099,0.047152,0.000000
72.190002,62.266636,-146.876099,0.011507,0.001849,0.046969,276.975830,14.109821,0.469690,-146.876099,0.047152,0.000000
72.370003,62.256954,-146.920578,0.011477,0.001849,0.046969,276.932770,14.107628,0.469690,-146.920578,0.047152,0.000000
72.550003,62.255836,-146.876099,0.011503,0.001849,0.046969,276.927795,14.107374,0.469690,-146.876099,0.047152,0.000000
72.730003,62.240196,-146.831619,0.011507,0.001849,0.046969,276.858215,14.103830,0.469690,-146.831619,0.047152,0.000000
72.910004,62.230145,-146.876099,0.011512,0.001849,0.046969,276.813507,14.101553,0.469690,-146.876099,0.047152,0.000000
73.090004,62.234612,-146.876099,0.011473,0.001849,0.046969,276.833374,14.102565,0.469690,-146.876099,0.047152,0.000000
73.270004,62.220089,-146.920578,0.011495,0.001849,0.046969,276.768768,14.099274,0.469690,-146.920578,0.047152,0.000000
73.450005,62.223068,-146.831619,0.011490,0.001849,0.046969,276.782043,14.099948,0.469690,-146.831619,0.047152,0.000000
73.630005,62.218227,-146.831619,0.011469,0.001849,0.046969,276.760498,14.098852,0.469690,-146.831619,0.047152,0.000000
73.810005,62.201099,-146.787140,0.011512,0.001849,0.046969,276.684296,14.094971,0.469690,-146.787140,0.047152,0.000000
73.990005,62.202587,-146.831619,0.011516,0.001849,0.046969,276.690918,14.095307,0.469690,-146.831619,0.047152,0.000000
74.170006,62.184711,-146.831619,0.011516,0.001849,0.046969,276.611420,14.091257,0.469690,-146.831619,0.047152,0.000000
74.350006,62.172798,-146.787140,0.011477,0.001849,0.046969,276.558411,14.088557,0.469690,-146.787140,0.047152,0.000000
74.530006,62.173916,-146.742661,0.011460,0.001849,0.046969,276.563385,14.088811,0.469690,-146.742661,0.047152,0.000000
74.710007,62.169075,-146.787140,0.011495,0.001849,0.046969,276.541870,14.087713,0.469690,-146.787140,0.047152,0.000000
74.890007,62.163486,-146.831619,0.011473,0.001849,0.046969,276.516998,14.086447,0.469690,-146.831619,0.047152,0.000000
75.070007,62.157532,-146.787140,0.011477,0.001849,0.046969,276.490509,14.085098,0.469690,-146.787140,0.047152,0.000000
75.100006,62.150829,-146.742661,0.011460,0.001849,0.046969,276.460693,14.083579,0.469690,-146.742661,0.047152,0.000000