File: Data/New pin align test AD 6_08172023_165409.csv
Time (sec),S:Load (lbs),S:HL1 (DIM),S:LVDT (in),S:Position (in),Ch:Position (mm),Ch:Load (N),Ch:Stress (MPa),Ch:Strain (mm/mm),Ch:HL1 (DIM),Set Point (),Cycles ()
0.010000,-0.001117,-145.897522,0.000060,-0.000000,-0.000000,-0.004969,-0.000253,-0.000000,-145.897522,0.000218,0.000000
0.170000,-0.001117,-145.808563,0.000056,-0.000000,-0.000000,-0.004969,-0.000253,-0.000000,-145.808563,0.000218,0.000000
0.330000,0.000745,-145.942001,0.000034,-0.000000,-0.000000,0.003313,0.000169,-0.000000,-145.942001,0.000218,0.000000
0.490000,0.010799,-145.853043,0.000052,0.000085,0.002170,0.048035,0.002447,0.021695,-145.853043,0.002802,0.000000
0.650000,0.027556,-145.808563,0.000047,0.000173,0.004406,0.122573,0.006244,0.044056,-145.808563,0.005455,0.000000
0.810000,0.042823,-145.897522,0.000129,0.000278,0.007051,0.190485,0.009704,0.070505,-145.897522,0.008127,0.000000
0.970000,0.033886,-145.808563,0.000285,0.000377,0.009583,0.150732,0.007679,0.095834,-145.808563,0.010798,0.000000
1.130000,0.034631,-145.897522,0.000371,0.000482,0.012254,0.154045,0.007847,0.122540,-145.897522,0.013452,0.000000
1.290000,0.006703,-145.808563,0.000487,0.000591,0.015003,0.029815,0.001519,0.150033,-145.808563,0.016122,0.000000
1.450000,-0.023832,-145.808563,0.000629,0.000696,0.017666,-0.106009,-0.005400,0.176664,-145.808563,0.018793,0.000000
1.610000,0.020480,-145.808563,0.000681,0.000806,0.020484,0.091102,0.004641,0.204839,-145.808563,0.021447,0.000000
1.770000,0.017129,-145.764084,0.000849,0.000910,0.023112,0.076194,0.003882,0.231121,-145.764084,0.024119,0.000000
1.930000,0.056973,-145.808563,0.000957,0.001008,0.025601,0.253428,0.012910,0.256010,-145.808563,0.026789,0.000000
2.090000,0.037982,-145.719589,0.001043,0.001116,0.028350,0.168952,0.008607,0.283504,-145.719589,0.029443,0.000000
2.250000,0.024577,-145.764084,0.001173,0.001218,0.030944,0.109322,0.005569,0.309438,-145.764084,0.032114,0.000000
2.410000,-0.000745,-145.764084,0.001268,0.001325,0.033658,-0.003313,-0.000169,0.336583,-145.764084,0.034785,0.000000
2.570000,0.043940,-145.719589,0.001380,0.001430,0.036320,0.195455,0.009957,0.363199,-145.719589,0.037439,0.000000
2.730000,0.036865,-145.808563,0.001479,0.001529,0.038844,0.163983,0.008354,0.388436,-145.808563,0.040109,0.000000
2.890000,0.039471,-145.719589,0.001638,0.001638,0.041610,0.175578,0.008944,0.416096,-145.719589,0.042781,0.000000
3.050000,0.028300,-145.719589,0.001772,0.001749,0.044412,0.125886,0.006413,0.444120,-145.719589,0.045452,0.000000
3.210000,0.014150,-145.764084,0.001815,0.001849,0.046952,0.062943,0.003206,0.469524,-145.764084,0.048106,0.000000
3.370000,-0.002234,-145.719589,0.001957,0.001956,0.049676,-0.009939,-0.000506,0.496760,-145.719589,0.050777,0.000000
3.530000,0.004096,-145.808563,0.002061,0.002062,0.052363,0.018220,0.000928,0.523633,-145.808563,0.053447,0.000000
3.690000,0.009682,-145.630630,0.002160,0.002168,0.055070,0.043066,0.002194,0.550702,-145.630630,0.056101,0.000000
3.850000,0.020480,-145.719589,0.002251,0.002272,0.057715,0.091102,0.004641,0.577151,-145.719589,0.058772,0.000000
4.010000,0.010426,-145.675110,0.002397,0.002374,0.060299,0.046379,0.002363,0.602994,-145.675110,0.061444,0.000000
4.170000,0.021970,-145.630630,0.002496,0.002478,0.062935,0.097727,0.004978,0.629352,-145.630630,0.064098,0.000000
4.330000,0.047291,-145.719589,0.002570,0.002583,0.065606,0.210362,0.010716,0.656059,-145.719589,0.066769,0.000000
4.490000,0.054366,-145.675110,0.002703,0.002690,0.068329,0.241834,0.012320,0.683295,-145.675110,0.069439,0.000000
4.650000,0.044685,-145.675110,0.002807,0.002786,0.070767,0.198767,0.010126,0.707669,-145.675110,0.072093,0.000000
4.810000,0.043195,-145.675110,0.002940,0.002901,0.073680,0.192142,0.009788,0.736798,-145.675110,0.074764,0.000000
4.970000,0.074474,-145.586151,0.003083,0.003009,0.076420,0.331279,0.016876,0.764201,-145.586151,0.077436,0.000000
5.130000,0.148577,-145.719589,0.003139,0.003110,0.078997,0.660902,0.033668,0.789968,-145.719589,0.080088,0.000000
5.290000,0.520949,-145.630630,0.003272,0.003219,0.081754,2.317297,0.118049,0.817537,-145.630630,0.082761,0.000000
5.450000,0.680697,-145.630630,0.003320,-0.000000,-0.000000,3.027891,0.154248,-0.000000,-145.630630,0.000226,0.000000
5.610000,0.668036,-145.586151,0.003333,-0.000000,-0.000000,2.971573,0.151379,-0.000000,-145.586151,0.000226,0.000000
5.770000,0.661333,-145.586151,0.003346,-0.000000,-0.000000,2.941758,0.149860,-0.000000,-145.586151,0.000226,0.000000
5.930000,0.651279,-145.630630,0.003320,-0.000000,-0.000000,2.897036,0.147582,-0.000000,-145.630630,0.000286,0.000000
6.090000,0.650162,-145.541672,0.003354,-0.000000,-0.000000,2.892066,0.147329,-0.000000,-145.541672,0.000556,0.000000
6.250000,0.634523,-145.586151,0.003350,-0.000000,-0.000000,2.822498,0.143785,-0.000000,-145.586151,0.000825,0.000000
6.410000,0.628192,-145.497192,0.003294,-0.000000,-0.000000,2.794339,0.142350,-0.000000,-145.497192,0.001084,0.000000
6.570000,0.747724,-145.497192,0.003337,0.000018,0.000451,3.326042,0.169437,0.004512,-145.497192,0.001353,0.000000
6.730000,0.786823,-145.541672,0.003341,0.000023,0.000590,3.499963,0.178297,0.005904,-145.541672,0.001623,0.000000
6.890000,0.832252,-145.497192,0.003333,0.000032,0.000816,3.702044,0.188591,0.008160,-145.497192,0.001891,0.000000
7.050000,0.905982,-145.541672,0.003333,0.000043,0.001084,4.030010,0.205298,0.010840,-145.541672,0.002151,0.000000
7.210001,0.955508,-145.452713,0.003393,0.000048,0.001223,4.250310,0.216521,0.012233,-145.452713,0.002421,0.000000
7.370000,1.066475,-145.497192,0.003406,0.000067,0.001700,4.743917,0.241667,0.017002,-145.497192,0.002689,0.000000
7.530000,1.196433,-145.586151,0.003380,0.000083,0.002107,5.321999,0.271116,0.021074,-145.586151,0.002958,0.000000
7.690001,1.285802,-145.452713,0.003389,0.000095,0.002403,5.719533,0.291367,0.024027,-145.452713,0.003219,0.000000
7.850000,1.352457,-145.452713,0.003402,0.000103,0.002612,6.016028,0.306471,0.026116,-145.452713,0.003487,0.000000
8.010000,1.369958,-145.452713,0.003410,0.000110,0.002784,6.093879,0.310437,0.027842,-145.452713,0.003756,0.000000
8.170000,1.460445,-145.452713,0.003441,0.000120,0.003045,6.496382,0.330941,0.030446,-145.452713,0.004024,0.000000
8.330000,1.575508,-145.541672,0.003423,0.000134,0.003391,7.008209,0.357015,0.033913,-145.541672,0.004285,0.000000
8.490001,1.601946,-145.408234,0.003428,0.000137,0.003470,7.125813,0.363006,0.034700,-145.408234,0.004554,0.000000
8.650001,1.771003,-145.452713,0.003436,0.000152,0.003868,7.877817,0.401315,0.038682,-145.452713,0.004822,0.000000
8.810000,1.917346,-145.408234,0.003441,0.000166,0.004224,8.528780,0.434477,0.042239,-145.408234,0.005091,0.000000
8.970000,1.945646,-145.452713,0.003479,0.000171,0.004354,8.654666,0.440890,0.043541,-145.452713,0.005352,0.000000
9.130000,2.049911,-145.408234,0.003471,0.000182,0.004615,9.118458,0.464516,0.046145,-145.408234,0.005620,0.000000
9.290001,2.123268,-145.363754,0.003475,0.000193,0.004892,9.444766,0.481139,0.048916,-145.363754,0.005889,0.000000
9.450001,2.258439,-145.497192,0.003527,0.000207,0.005256,10.046039,0.511770,0.052565,-145.497192,0.006157,0.000000
9.610001,2.389142,-145.408234,0.003523,0.000219,0.005559,10.627433,0.541387,0.055593,-145.408234,0.006418,0.000000
9.770000,2.477767,-145.363754,0.003561,0.000228,0.005803,11.021656,0.561470,0.058030,-145.363754,0.006687,0.000000
9.930000,2.542559,-145.408234,0.003548,0.000237,0.006019,11.309868,0.576152,0.060195,-145.408234,0.006955,0.000000
10.090000,2.670283,-145.363754,0.003523,0.000249,0.006322,11.878012,0.605095,0.063223,-145.363754,0.007225,0.000000
10.250001,2.690391,-145.363754,0.003574,0.000254,0.006452,11.967457,0.609651,0.064525,-145.363754,0.007485,0.000000
10.410001,2.809178,-145.363754,0.003561,0.000262,0.006652,12.495848,0.636569,0.066523,-145.363754,0.007753,0.000000
10.570001,2.951052,-145.363754,0.003561,0.000273,0.006938,13.126934,0.668718,0.069385,-145.363754,0.008022,0.000000
10.730000,3.190487,-145.363754,0.003561,0.000291,0.007381,14.191997,0.722975,0.073805,-145.363754,0.008292,0.000000
10.890000,3.284698,-145.319260,0.003596,0.000298,0.007580,14.611064,0.744323,0.075804,-145.319260,0.008551,0.000000
11.050000,3.405346,-145.363754,0.003617,0.000309,0.007848,15.147736,0.771662,0.078484,-145.363754,0.008820,0.000000
11.210001,3.507004,-145.319260,0.003643,0.000319,0.008101,15.599932,0.794698,0.081012,-145.319260,0.009090,0.000000
11.370001,3.741971,-145.319260,0.003695,0.000333,0.008465,16.645119,0.847943,0.084645,-145.319260,0.009358,0.000000
11.530001,3.902091,-145.274780,0.003639,0.000346,0.008785,17.357368,0.884227,0.087855,-145.274780,0.009618,0.000000
11.690001,4.019761,-145.274780,0.003682,0.000355,0.009028,17.880789,0.910891,0.090277,-145.274780,0.009888,0.000000
11.850000,4.127377,-145.274780,0.003648,0.000362,0.009202,18.359488,0.935277,0.092018,-145.274780,0.010156,0.000000
12.010000,4.219725,-145.230301,0.003686,0.000372,0.009444,18.770273,0.956203,0.094441,-145.230301,0.010425,0.000000
12.170001,4.331064,-145.274780,0.003699,0.000381,0.009670,19.265535,0.981433,0.096696,-145.274780,0.010686,0.000000
12.330001,4.543689,-145.274780,0.003695,0.000392,0.009965,20.211338,1.029615,0.099649,-145.274780,0.010953,0.000000
12.490001,4.855364,-145.274780,0.003734,0.000408,0.010372,21.597738,1.100241,0.103721,-145.274780,0.011223,0.000000
12.650001,4.987184,-145.274780,0.003751,0.000418,0.010616,22.184103,1.130112,0.106159,-145.274780,0.011491,0.000000
12.810000,5.074692,-145.185822,0.003773,0.000424,0.010781,22.573357,1.149942,0.107809,-145.185822,0.011751,0.000000
12.970000,5.287316,-145.185822,0.003764,0.000436,0.011067,23.519157,1.198123,0.110670,-145.185822,0.012021,0.000000
13.130001,5.494728,-145.230301,0.003768,0.000449,0.011396,24.441771,1.245123,0.113956,-145.230301,0.012289,0.000000
13.290001,5.656338,-145.185822,0.003798,0.000458,0.011630,25.160646,1.281744,0.116302,-145.185822,0.012558,0.000000
13.450001,5.906199,-145.185822,0.003760,0.000471,0.011968,26.272087,1.338364,0.119678,-145.185822,0.012819,0.000000
13.610001,6.093131,-145.141342,0.003781,0.000481,0.012212,27.103598,1.380723,0.122116,-145.141342,0.013087,0.000000
13.770000,6.275220,-145.185822,0.003829,0.000489,0.012428,27.913574,1.421985,0.124281,-145.185822,0.013356,0.000000
13.930000,6.446139,-145.185822,0.003803,0.000500,0.012688,28.673861,1.460716,0.126885,-145.185822,0.013624,0.000000
14.090001,6.639029,-145.141342,0.003820,0.000509,0.012931,29.531874,1.504425,0.129307,-145.141342,0.013885,0.000000
14.250001,6.768614,-145.185822,0.003807,0.000517,0.013131,30.108299,1.533790,0.131306,-145.185822,0.014154,0.000000
14.410001,7.104494,-145.096863,0.003850,0.000530,0.013468,31.602367,1.609901,0.134682,-145.096863,0.014422,0.000000
14.570001,7.388987,-145.052383,0.003867,0.000541,0.013747,32.867855,1.674368,0.137467,-145.052383,0.014691,0.000000
14.730000,7.522668,-145.096863,0.003854,0.000548,0.013928,33.462502,1.704661,0.139284,-145.096863,0.014952,0.000000
14.890000,7.680927,-145.096863,0.003902,0.000556,0.014128,34.166470,1.740523,0.141283,-145.096863,0.015220,0.000000
15.050001,7.953503,-145.141342,0.003885,0.000566,0.014387,35.378948,1.802290,0.143871,-145.141342,0.015489,0.000000
15.210001,8.120326,-145.096863,0.003876,0.000575,0.014596,36.121014,1.840092,0.145961,-145.096863,0.015759,0.000000
15.370001,8.614465,-145.096863,0.003906,0.000594,0.015082,38.319054,1.952066,0.150820,-145.096863,0.016018,0.000000
15.530001,8.814801,-145.096863,0.003941,0.000604,0.015333,39.210194,1.997463,0.153334,-145.096863,0.016287,0.000000
15.690001,8.983486,-145.052383,0.003958,0.000613,0.015567,39.960541,2.035687,0.155665,-145.052383,0.016557,0.000000
15.850000,9.069504,-145.141342,0.003958,0.000619,0.015715,40.343166,2.055179,0.157149,-145.141342,0.016825,0.000000
16.010000,9.439270,-145.052383,0.003936,0.000632,0.016062,41.987968,2.138969,0.160616,-145.052383,0.017085,0.000000
16.170000,9.820951,-145.052383,0.003962,0.000644,0.016364,43.685776,2.225459,0.163644,-145.052383,0.017353,0.000000
16.330000,10.153852,-145.096863,0.003967,0.000656,0.016660,45.166592,2.300896,0.166596,-145.096863,0.017622,0.000000
16.490002,10.235775,-145.052383,0.003992,0.000664,0.016859,45.531002,2.319460,0.168594,-145.052383,0.017892,0.000000
16.650002,10.710177,-145.052383,0.003992,0.000676,0.017180,47.641247,2.426961,0.171804,-145.052383,0.018151,0.000000
16.810001,10.698261,-145.052383,0.003988,0.000678,0.017232,47.588242,2.424261,0.172319,-145.052383,0.018420,0.000000
16.970001,10.885192,-145.052383,0.004023,0.000691,0.017545,48.419750,2.466620,0.175453,-145.052383,0.018690,0.000000
17.130001,11.400556,-144.963425,0.004031,0.000702,0.017822,50.712204,2.583403,0.178223,-144.963425,0.018958,0.000000
17.290001,11.968796,-145.007904,0.004023,0.000718,0.018239,53.239864,2.712168,0.182387,-145.007904,0.019218,0.000000
17.450001,12.133385,-145.007904,0.004027,0.000726,0.018429,53.971992,2.749464,0.184294,-145.007904,0.019488,0.000000
17.610001,12.419367,-144.963425,0.004031,0.000735,0.018681,55.244102,2.814269,0.186807,-144.963425,0.019756,0.000000
17.770000,12.753013,-144.963425,0.004053,0.000747,0.018976,56.728233,2.889874,0.189759,-144.963425,0.020025,0.000000
17.930000,13.017397,-144.918945,0.004049,0.000756,0.019209,57.904274,2.949784,0.192091,-144.918945,0.020286,0.000000
18.090000,13.399078,-144.963425,0.004079,0.000769,0.019530,59.602077,3.036275,0.195301,-144.963425,0.020553,0.000000
18.250000,13.720436,-144.963425,0.004087,0.000779,0.019790,61.031548,3.109095,0.197905,-144.963425,0.020823,0.000000
18.410002,14.168400,-144.874451,0.004079,0.000790,0.020077,63.024189,3.210605,0.200766,-144.874451,0.021091,0.000000
18.570002,14.414538,-144.963425,0.004087,0.000800,0.020328,64.119072,3.266381,0.203279,-144.963425,0.021360,0.000000
18.730001,14.777601,-144.874451,0.004092,0.000810,0.020572,65.734055,3.348652,0.205717,-144.874451,0.021621,0.000000
18.890001,15.068052,-144.918945,0.004092,0.000819,0.020805,67.026047,3.414469,0.208048,-144.918945,0.021889,0.000000
19.050001,15.388292,-144.874451,0.004100,0.000831,0.021118,68.450546,3.487037,0.211182,-144.874451,0.022158,0.000000
19.210001,16.131174,-144.918945,0.004139,0.000848,0.021533,71.755043,3.655376,0.215330,-144.918945,0.022426,0.000000
19.370001,16.447691,-144.918945,0.004148,0.000858,0.021786,73.162987,3.727100,0.217859,-144.918945,0.022687,0.000000
19.530001,16.769794,-144.874451,0.004143,0.000867,0.022028,74.595772,3.800090,0.220281,-144.874451,0.022956,0.000000
19.690001,16.966034,-144.829971,0.004165,0.000875,0.022228,75.468689,3.844558,0.222279,-144.829971,0.023224,0.000000
19.850000,17.646358,-144.874451,0.004195,0.000891,0.022626,78.494926,3.998722,0.226261,-144.874451,0.023494,0.000000
20.010000,17.862333,-144.874451,0.004208,0.000899,0.022826,79.455627,4.047663,0.228259,-144.874451,0.023754,0.000000
20.170000,18.269709,-144.829971,0.004195,0.000910,0.023121,81.267723,4.139976,0.231212,-144.829971,0.024022,0.000000
20.330002,18.651392,-144.874451,0.004234,0.000919,0.023347,82.965538,4.226466,0.233467,-144.874451,0.024291,0.000000
20.490002,18.708736,-144.874451,0.004225,0.000925,0.023503,83.220619,4.239460,0.235027,-144.874451,0.024561,0.000000
20.650002,19.041265,-144.874451,0.004234,0.000934,0.023719,84.699776,4.314812,0.237192,-144.874451,0.024820,0.000000
20.810001,19.259848,-144.785492,0.004212,0.000939,0.023840,85.672081,4.364344,0.238403,-144.785492,0.025089,0.000000
20.970001,19.732016,-144.785492,0.004247,0.000949,0.024110,87.772392,4.471339,0.241098,-144.785492,0.025359,0.000000
21.130001,20.228388,-144.741013,0.004251,0.000967,0.024552,89.980362,4.583818,0.245519,-144.741013,0.025627,0.000000
21.290001,21.059151,-144.741013,0.004251,0.000980,0.024889,93.675781,4.772072,0.248895,-144.741013,0.025887,0.000000
21.450001,21.545469,-144.829971,0.004277,0.000993,0.025210,95.839035,4.882273,0.252104,-144.829971,0.026157,0.000000
21.610001,21.903320,-144.785492,0.004264,0.001003,0.025480,97.430832,4.963363,0.254799,-144.785492,0.026425,0.000000
21.770000,22.280905,-144.785492,0.004303,0.001013,0.025740,99.110413,5.048925,0.257403,-144.785492,0.026694,0.000000
21.930000,22.663332,-144.741013,0.004294,0.001023,0.025992,100.811539,5.135584,0.259916,-144.741013,0.026955,0.000000
22.090000,23.007404,-144.741013,0.004281,0.001032,0.026217,102.342049,5.213552,0.262172,-144.741013,0.027222,0.000000
22.250002,23.642672,-144.696533,0.004342,0.001046,0.026564,105.167854,5.357506,0.265639,-144.696533,0.027492,0.000000
22.410002,23.842264,-144.741013,0.004316,0.001052,0.026729,106.055687,5.402734,0.267289,-144.741013,0.027760,0.000000
22.570002,24.011692,-144.785492,0.004286,0.001058,0.026885,106.809341,5.441127,0.268849,-144.785492,0.028020,0.000000
22.730001,24.339752,-144.652054,0.004320,0.001068,0.027118,108.268623,5.515467,0.271180,-144.652054,0.028290,0.000000
22.890001,24.934431,-144.785492,0.004346,0.001080,0.027431,110.913887,5.650223,0.274314,-144.785492,0.028558,0.000000
23.050001,25.974096,-144.652054,0.004381,0.001099,0.027925,115.538551,5.885814,0.279250,-144.652054,0.028827,0.000000
23.210001,26.359129,-144.696533,0.004355,0.001110,0.028185,117.251259,5.973064,0.281854,-144.696533,0.029088,0.000000
23.370001,26.584787,-144.696533,0.004359,0.001118,0.028393,118.255043,6.024199,0.283928,-144.696533,0.029356,0.000000
23.530001,26.870024,-144.607574,0.004381,0.001126,0.028611,119.523834,6.088835,0.286108,-144.607574,0.029625,0.000000
23.690001,27.352991,-144.607574,0.004389,0.001137,0.028888,121.672180,6.198277,0.288878,-144.607574,0.029893,0.000000
23.850000,28.113749,-144.696533,0.004406,0.001152,0.029253,125.056198,6.370667,0.292527,-144.696533,0.030153,0.000000
24.010000,28.537136,-144.652054,0.004437,0.001163,0.029539,126.939522,6.466608,0.295388,-144.652054,0.030423,0.000000
24.170002,28.928127,-144.696533,0.004402,0.001172,0.029772,128.678741,6.555208,0.297720,-144.696533,0.030691,0.000000
24.330002,29.234961,-144.607574,0.004428,0.001180,0.029981,130.043594,6.624737,0.299809,-144.607574,0.030960,0.000000
24.490002,29.558554,-144.652054,0.004432,0.001189,0.030188,131.483017,6.698064,0.301883,-144.652054,0.031221,0.000000
24.650002,29.732822,-144.607574,0.004437,0.001194,0.030328,132.258194,6.737554,0.303276,-144.607574,0.031489,0.000000
24.810001,30.470865,-144.563095,0.004432,0.001209,0.030709,135.541183,6.904797,0.307091,-144.563095,0.031758,0.000000
24.970001,31.141136,-144.607574,0.004493,0.001223,0.031074,138.522690,7.056682,0.310740,-144.607574,0.032028,0.000000
25.130001,31.785713,-144.607574,0.004475,0.001236,0.031403,141.389908,7.202746,0.314025,-144.607574,0.032287,0.000000
25.290001,32.023289,-144.607574,0.004501,0.001243,0.031584,142.446701,7.256581,0.315842,-144.607574,0.032556,0.000000
25.450001,32.299217,-144.518616,0.004484,0.001252,0.031810,143.674088,7.319108,0.318098,-144.518616,0.032826,0.000000
25.610001,32.796703,-144.563095,0.004510,0.001264,0.032105,145.887024,7.431839,0.321050,-144.563095,0.033094,0.000000
25.770000,33.084179,-144.563095,0.004518,0.001271,0.032279,147.165771,7.496982,0.322791,-144.563095,0.033354,0.000000
25.930000,34.052719,-144.474136,0.004497,0.001289,0.032730,151.474060,7.716456,0.327303,-144.474136,0.033623,0.000000
26.090002,34.451530,-144.563095,0.004501,0.001297,0.032956,153.248062,7.806828,0.329558,-144.563095,0.033891,0.000000
26.250002,34.638832,-144.474136,0.004549,0.001305,0.033147,154.081223,7.849272,0.331466,-144.474136,0.034161,0.000000
26.410002,34.976200,-144.518616,0.004527,0.001312,0.033337,155.581909,7.925720,0.333374,-144.518616,0.034421,0.000000
26.570002,35.532154,-144.518616,0.004523,0.001324,0.033623,158.054916,8.051702,0.336235,-144.518616,0.034689,0.000000
26.730001,36.045284,-144.518616,0.004566,0.001336,0.033944,160.337433,8.167978,0.339445,-144.518616,0.034959,0.000000
26.890001,36.691723,-144.518616,0.004575,0.001350,0.034282,163.212936,8.314463,0.342821,-144.518616,0.035227,0.000000
27.050001,37.324757,-144.474136,0.004544,0.001362,0.034603,166.028809,8.457911,0.346030,-144.474136,0.035487,0.000000
27.210001,37.487480,-144.518616,0.004592,0.001369,0.034768,166.752640,8.494784,0.347680,-144.518616,0.035757,0.000000
27.370001,37.997261,-144.429642,0.004583,0.001379,0.035028,169.020264,8.610302,0.350284,-144.429642,0.036025,0.000000
27.530001,38.515602,-144.474136,0.004626,0.001390,0.035296,171.325958,8.727760,0.352964,-144.474136,0.036294,0.000000
27.690001,38.736046,-144.518616,0.004622,0.001397,0.035496,172.306534,8.777714,0.354963,-144.518616,0.036555,0.000000
27.850000,39.024261,-144.385162,0.004622,0.001405,0.035678,173.588577,8.843023,0.356779,-144.385162,0.036822,0.000000
28.010002,39.769753,-144.429642,0.004626,0.001419,0.036050,176.904694,9.011955,0.360504,-144.429642,0.037092,0.000000
28.170002,40.139519,-144.429642,0.004613,0.001427,0.036250,178.549500,9.095745,0.362502,-144.429642,0.037360,0.000000
28.330002,40.499229,-144.429642,0.004626,0.001435,0.036441,180.149567,9.177257,0.364410,-144.429642,0.037620,0.000000
28.490002,40.915169,-144.429642,0.004661,0.001445,0.036710,181.999756,9.271509,0.367105,-144.429642,0.037890,0.000000
28.650002,41.422714,-144.429642,0.004678,0.001455,0.036962,184.257431,9.386521,0.369618,-144.429642,0.038158,0.000000
28.810001,42.353645,-144.385162,0.004656,0.001472,0.037378,188.398422,9.597473,0.373781,-144.385162,0.038427,0.000000
28.970001,42.994125,-144.385162,0.004652,0.001486,0.037734,191.247421,9.742608,0.377339,-144.385162,0.038688,0.000000
29.130001,43.463314,-144.340683,0.004682,0.001496,0.038002,193.334473,9.848927,0.380019,-144.340683,0.038956,0.000000
29.290001,43.747063,-144.385162,0.004700,0.001505,0.038220,194.596649,9.913226,0.382199,-144.385162,0.039225,0.000000
29.450001,44.069538,-144.296204,0.004717,0.001514,0.038444,196.031097,9.986300,0.384439,-144.296204,0.039495,0.000000
29.610001,44.470211,-144.385162,0.004743,0.001527,0.038774,197.813385,10.077094,0.387740,-144.385162,0.039754,0.000000
29.770002,44.991158,-144.340683,0.004738,0.001532,0.038922,200.130661,10.195142,0.389223,-144.340683,0.040023,0.000000
29.930002,45.204155,-144.296204,0.004730,0.001543,0.039181,201.078125,10.243408,0.391812,-144.296204,0.040292,0.000000
30.090002,46.290741,-144.385162,0.004747,0.001559,0.039590,205.911499,10.489632,0.395900,-144.385162,0.040560,0.000000
30.250002,46.813549,-144.340683,0.004743,0.001569,0.039841,208.237061,10.608102,0.398413,-144.340683,0.040821,0.000000
30.410002,46.810200,-144.296204,0.004743,0.001572,0.039937,208.222168,10.607344,0.399367,-144.296204,0.041090,0.000000
30.570002,47.408974,-144.296204,0.004760,0.001586,0.040283,210.885651,10.743028,0.402834,-144.296204,0.041358,0.000000
30.730001,48.128025,-144.296204,0.004764,0.001598,0.040579,214.084152,10.905967,0.405786,-144.296204,0.041628,0.000000
30.890001,48.792336,-144.340683,0.004799,0.001612,0.040933,217.039154,11.056501,0.409329,-144.340683,0.041888,0.000000
31.050001,49.270462,-144.251724,0.004790,0.001621,0.041186,219.165955,11.164845,0.411857,-144.251724,0.042156,0.000000
31.210001,49.585117,-144.296204,0.004794,0.001630,0.041393,220.565613,11.236148,0.413931,-144.296204,0.042426,0.000000
31.370001,49.877060,-144.251724,0.004803,0.001639,0.041628,221.864243,11.302303,0.416278,-144.251724,0.042694,0.000000
31.530001,50.384975,-144.251724,0.004833,0.001649,0.041896,224.123566,11.417398,0.418958,-144.251724,0.042954,0.000000
31.690002,50.674309,-144.251724,0.004803,0.001657,0.042079,225.410583,11.482963,0.420789,-144.251724,0.043224,0.000000
31.850002,50.956940,-144.162766,0.004846,0.001663,0.042242,226.667786,11.547008,0.422425,-144.162766,0.043491,0.000000
32.010002,51.989899,-144.251724,0.004820,0.001679,0.042651,231.262619,11.781079,0.426512,-144.251724,0.043761,0.000000
32.170002,52.990093,-144.207245,0.004838,0.001696,0.043068,235.711700,12.007727,0.430676,-144.207245,0.044021,0.000000
32.330002,53.045574,-144.251724,0.004859,0.001701,0.043198,235.958496,12.020299,0.431978,-144.251724,0.044289,0.000000
32.490002,53.674511,-144.207245,0.004846,0.001713,0.043501,238.756149,12.162818,0.435006,-144.207245,0.044559,0.000000
32.650002,54.357815,-144.162766,0.004855,0.001725,0.043822,241.795639,12.317657,0.438215,-144.162766,0.044827,0.000000
32.810001,55.162514,-144.251724,0.004881,0.001740,0.044186,245.375122,12.500005,0.441864,-144.251724,0.045087,0.000000
32.970001,55.589622,-144.162766,0.004902,0.001750,0.044438,247.274994,12.596788,0.444377,-144.162766,0.045357,0.000000
33.130001,55.953804,-144.162766,0.004902,0.001759,0.044689,248.894958,12.679313,0.446890,-144.162766,0.045625,0.000000
33.290001,56.179089,-144.162766,0.004915,0.001766,0.044862,249.897064,12.730364,0.448616,-144.162766,0.045894,0.000000
33.450001,56.671368,-144.162766,0.004902,0.001776,0.045105,252.086838,12.841915,0.451054,-144.162766,0.046155,0.000000
33.610001,57.348713,-144.162766,0.004928,0.001789,0.045434,255.099823,12.995404,0.454339,-144.162766,0.046422,0.000000
33.770000,58.007439,-144.118286,0.004907,0.001801,0.045738,258.029968,13.144673,0.457382,-144.118286,0.046692,0.000000
33.930000,58.786816,-144.118286,0.004950,0.001813,0.046050,261.496826,13.321283,0.460501,-144.118286,0.046961,0.000000
34.090000,59.117481,-144.162766,0.004988,0.001821,0.046241,262.967682,13.396213,0.462408,-144.162766,0.047220,0.000000
34.250000,59.273132,-144.029312,0.004945,0.001828,0.046422,263.660065,13.431484,0.464225,-144.029312,0.047490,0.000000
34.410000,60.067402,-144.162766,0.004993,0.001840,0.046736,267.193146,13.611468,0.467359,-144.162766,0.047759,0.000000
34.570004,60.682190,-144.029312,0.004963,0.001852,0.047030,269.927856,13.750781,0.470296,-144.029312,0.048027,0.000000
34.730003,61.125687,-144.073807,0.004971,0.001861,0.047264,271.900635,13.851279,0.472643,-144.073807,0.048288,0.000000
34.890003,61.830959,-144.118286,0.004971,0.001874,0.047594,275.037842,14.011095,0.475943,-144.118286,0.048557,0.000000
35.050003,62.206310,-144.029312,0.005010,0.001882,0.047811,276.707489,14.096151,0.478108,-144.029312,0.048825,0.000000
35.210003,62.531391,-144.073807,0.005040,0.001888,0.047967,278.153534,14.169816,0.479667,-144.073807,0.049095,0.000000
35.370003,63.145805,-144.029312,0.004997,0.001901,0.048288,280.886566,14.309044,0.482877,-144.029312,0.049355,0.000000
35.530003,64.042107,-144.029312,0.005040,0.001915,0.048643,284.873505,14.512149,0.486435,-144.029312,0.049623,0.000000
35.690002,64.060722,-144.029312,0.005040,0.001920,0.048774,284.956329,14.516367,0.487737,-144.029312,0.049892,0.000000
35.850002,64.881058,-144.073807,0.005010,0.001930,0.049034,288.605347,14.702257,0.490341,-144.073807,0.050160,0.000000
36.010002,65.423607,-144.029312,0.005049,0.001940,0.049285,291.018738,14.825201,0.492854,-144.029312,0.050421,0.000000
36.170002,65.769165,-144.029312,0.005049,0.001950,0.049519,292.555847,14.903506,0.495185,-144.029312,0.050690,0.000000
36.330002,66.065201,-143.940353,0.005027,0.001955,0.049649,293.872681,14.970588,0.496487,-143.940353,0.050958,0.000000
36.490002,66.716110,-143.984833,0.005070,0.001966,0.049944,296.768066,15.118087,0.499440,-143.984833,0.051228,0.000000
36.650002,67.626190,-143.984833,0.005092,0.001980,0.050291,300.816315,15.324314,0.502907,-143.984833,0.051479,0.000000
36.810001,67.318611,-143.984833,0.005066,0.001972,0.050091,299.448151,15.254616,0.500908,-143.984833,0.050351,0.000000
36.970001,67.021454,-143.940353,0.005088,0.001972,0.050091,298.126312,15.187278,0.500908,-143.940353,0.050351,0.000000
37.130001,66.709038,-143.940353,0.005057,0.001969,0.050005,296.736633,15.116484,0.500045,-143.940353,0.050091,0.000000
37.290001,66.485611,-143.940353,0.005092,0.001967,0.049962,295.742767,15.065855,0.499621,-143.940353,0.050091,0.000000
37.450001,66.305008,-143.895874,0.005062,0.001966,0.049944,294.939392,15.024930,0.499440,-143.895874,0.050091,0.000000
37.610001,66.127762,-143.984833,0.005062,0.001966,0.049935,294.150970,14.984765,0.499349,-143.984833,0.050091,0.000000
37.770000,65.975090,-143.895874,0.005083,0.001966,0.049927,293.471863,14.950169,0.499273,-143.895874,0.050091,0.000000
37.930000,65.844017,-143.940353,0.005070,0.001966,0.049927,292.888824,14.920467,0.499273,-143.940353,0.050091,0.000000
38.090000,65.710335,-143.940353,0.005109,0.001965,0.049918,292.294159,14.890174,0.499182,-143.940353,0.050091,0.000000
38.250000,65.601227,-143.940353,0.005096,0.001965,0.049918,291.808838,14.865450,0.499182,-143.940353,0.050091,0.000000
38.410004,65.494728,-143.940353,0.005096,0.001965,0.049918,291.335114,14.841318,0.499182,-143.940353,0.050091,0.000000
38.570004,65.388603,-143.851395,0.005101,0.001965,0.049918,290.863037,14.817269,0.499182,-143.851395,0.050091,0.000000
38.730003,65.281731,-143.895874,0.005105,0.001965,0.049909,290.387634,14.793052,0.499091,-143.895874,0.050091,0.000000
38.890003,65.201302,-143.851395,0.005075,0.001965,0.049909,290.029877,14.774826,0.499091,-143.851395,0.050091,0.000000
39.050003,65.113792,-143.851395,0.005113,0.001965,0.049909,289.640625,14.754995,0.499091,-143.851395,0.050091,0.000000
39.210003,65.036713,-143.851395,0.005113,0.001965,0.049909,289.297760,14.737530,0.499091,-143.851395,0.050091,0.000000
39.370003,64.962982,-143.806915,0.005092,0.001965,0.049909,288.969788,14.720822,0.499091,-143.806915,0.050091,0.000000
39.530003,64.894836,-143.851395,0.005066,0.001965,0.049900,288.666656,14.705380,0.499001,-143.851395,0.050091,0.000000
39.690002,64.829674,-143.806915,0.005057,0.001965,0.049900,288.376801,14.690615,0.499001,-143.806915,0.050091,0.000000
39.850002,64.779404,-143.806915,0.005109,0.001965,0.049900,288.153168,14.679223,0.499001,-143.806915,0.050091,0.000000
40.010002,64.706421,-143.806915,0.005070,0.001965,0.049900,287.828522,14.662684,0.499001,-143.806915,0.050091,0.000000
40.170002,64.654282,-143.806915,0.005083,0.001965,0.049900,287.596619,14.650869,0.499001,-143.806915,0.050091,0.000000
40.330002,64.585770,-143.806915,0.005070,0.001965,0.049900,287.291840,14.635345,0.499001,-143.806915,0.050091,0.000000
40.490002,64.542198,-143.806915,0.005079,0.001964,0.049892,287.098022,14.625471,0.498925,-143.806915,0.050091,0.000000
40.650002,64.484856,-143.806915,0.005096,0.001964,0.049892,286.842957,14.612477,0.498925,-143.806915,0.050091,0.000000
40.810001,64.430489,-143.851395,0.005070,0.001964,0.049892,286.601135,14.600157,0.498925,-143.851395,0.050091,0.000000
40.970001,64.388786,-143.717957,0.005101,0.001964,0.049892,286.415619,14.590708,0.498925,-143.717957,0.050091,0.000000
41.130001,64.343353,-143.762436,0.005105,0.001964,0.049892,286.213531,14.580413,0.498925,-143.762436,0.050091,0.000000
41.290001,64.301277,-143.673477,0.005062,0.001964,0.049892,286.026367,14.570877,0.498925,-143.673477,0.050091,0.000000
41.450001,64.256592,-143.673477,0.005066,0.001964,0.049892,285.827606,14.560751,0.498925,-143.673477,0.050091,0.000000
41.610001,64.207809,-143.717957,0.005088,0.001964,0.049892,285.610596,14.549698,0.498925,-143.717957,0.050091,0.000000
41.770000,64.186584,-143.717957,0.005079,0.001964,0.049892,285.516174,14.544888,0.498925,-143.717957,0.050091,0.000000
41.930000,64.126259,-143.762436,0.005079,0.001964,0.049892,285.247833,14.531218,0.498925,-143.762436,0.050091,0.000000
42.090000,64.100937,-143.673477,0.005079,0.001964,0.049892,285.135193,14.525480,0.498925,-143.673477,0.050091,0.000000
42.250004,64.058121,-143.673477,0.005113,0.001964,0.049892,284.944763,14.515778,0.498925,-143.673477,0.050091,0.000000
42.410004,64.014175,-143.673477,0.005066,0.001964,0.049892,284.749268,14.505819,0.498925,-143.673477,0.050091,0.000000
42.570004,63.998913,-143.628998,0.005092,0.001964,0.049892,284.681396,14.502360,0.498925,-143.628998,0.050091,0.000000
42.730003,63.966515,-143.673477,0.005079,0.001964,0.049892,284.537262,14.495019,0.498925,-143.673477,0.050091,0.000000
42.890003,63.933002,-143.673477,0.005070,0.001964,0.049892,284.388184,14.487425,0.498925,-143.673477,0.050091,0.000000
43.050003,63.896881,-143.673477,0.005109,0.001964,0.049883,284.227509,14.479239,0.498834,-143.673477,0.050091,0.000000
43.210003,63.859272,-143.673477,0.005092,0.001964,0.049883,284.060242,14.470718,0.498834,-143.673477,0.050091,0.000000
43.370003,63.835812,-143.628998,0.005105,0.001964,0.049883,283.955872,14.465402,0.498834,-143.628998,0.050091,0.000000
43.530003,63.806023,-143.628998,0.005113,0.001964,0.049883,283.823364,14.458651,0.498834,-143.628998,0.050091,0.000000
43.690002,63.785915,-143.584503,0.005079,0.001964,0.049883,283.733917,14.454096,0.498834,-143.584503,0.050091,0.000000
43.850002,63.748306,-143.628998,0.005075,0.001964,0.049883,283.566620,14.445573,0.498834,-143.628998,0.050091,0.000000
44.010002,63.729687,-143.584503,0.005053,0.001964,0.049883,283.483795,14.441353,0.498834,-143.584503,0.050091,0.000000
44.170002,63.699898,-143.584503,0.005070,0.001964,0.049883,283.351288,14.434603,0.498834,-143.584503,0.050091,0.000000
44.330002,63.668243,-143.628998,0.005101,0.001964,0.049883,283.210480,14.427430,0.498834,-143.628998,0.050091,0.000000
44.490002,63.645157,-143.540024,0.005105,0.001964,0.049883,283.107788,14.422198,0.498834,-143.540024,0.050091,0.000000
44.650002,63.610901,-143.584503,0.005096,0.001964,0.049883,282.955414,14.414436,0.498834,-143.584503,0.050091,0.000000
44.810001,63.603451,-143.495544,0.005092,0.001964,0.049883,282.922272,14.412747,0.498834,-143.495544,0.050091,0.000000
44.970001,63.577759,-143.540024,0.005075,0.001964,0.049883,282.807983,14.406926,0.498834,-143.540024,0.050091,0.000000
45.130001,63.530838,-143.628998,0.005083,0.001964,0.049883,282.599274,14.396295,0.498834,-143.628998,0.050091,0.000000
45.290001,63.519295,-143.451065,0.005109,0.001964,0.049883,282.547943,14.393678,0.498834,-143.451065,0.050091,0.000000
45.450001,63.493229,-143.540024,0.005101,0.001964,0.049883,282.431976,14.387772,0.498834,-143.540024,0.050091,0.000000
45.610001,63.473495,-143.495544,0.005066,0.001964,0.049883,282.344208,14.383299,0.498834,-143.495544,0.050091,0.000000
45.770000,63.449291,-143.451065,0.005092,0.001964,0.049883,282.236542,14.377815,0.498834,-143.451065,0.050091,0.000000
45.930000,63.426575,-143.495544,0.005096,0.001964,0.049883,282.135498,14.372667,0.498834,-143.495544,0.050091,0.000000
46.090004,63.418011,-143.451065,0.005118,0.001964,0.049883,282.097412,14.370727,0.498834,-143.451065,0.050091,0.000000
46.250004,63.387478,-143.495544,0.005101,0.001964,0.049883,281.961578,14.363808,0.498834,-143.495544,0.050091,0.000000
46.410004,63.380028,-143.451065,0.005066,0.001964,0.049883,281.928436,14.362120,0.498834,-143.451065,0.050091,0.000000
46.570004,63.355080,-143.451065,0.005105,0.001964,0.049883,281.817474,14.356466,0.498834,-143.451065,0.050091,0.000000
46.730003,63.328640,-143.451065,0.005079,0.001964,0.049883,281.699860,14.350475,0.498834,-143.451065,0.050091,0.000000
46.890003,63.305183,-143.451065,0.005096,0.001964,0.049883,281.595520,14.345160,0.498834,-143.451065,0.050091,0.000000
47.050003,63.292149,-143.451065,0.005079,0.001964,0.049883,281.537537,14.342206,0.498834,-143.451065,0.050091,0.000000
47.210003,63.275764,-143.362106,0.005070,0.001964,0.049883,281.464661,14.338492,0.498834,-143.362106,0.050091,0.000000
47.370003,63.256027,-143.362106,0.005101,0.001964,0.049883,281.376862,14.334021,0.498834,-143.362106,0.050091,0.000000
47.530003,63.238155,-143.451065,0.005096,0.001964,0.049883,281.297363,14.329971,0.498834,-143.451065,0.050091,0.000000
47.690002,63.233685,-143.362106,0.005092,0.001964,0.049883,281.277466,14.328958,0.498834,-143.362106,0.050091,0.000000
47.850002,63.201290,-143.406586,0.005088,0.001964,0.049883,281.133392,14.321617,0.498834,-143.406586,0.050091,0.000000
48.010002,63.191982,-143.362106,0.005075,0.001964,0.049883,281.091980,14.319508,0.498834,-143.362106,0.050091,0.000000
48.170002,63.170383,-143.406586,0.005083,0.001964,0.049883,280.995911,14.314613,0.498834,-143.406586,0.050091,0.000000
48.330002,63.140594,-143.451065,0.005075,0.001964,0.049883,280.863403,14.307863,0.498834,-143.451065,0.050091,0.000000
48.490002,63.138733,-143.362106,0.005105,0.001964,0.049883,280.855103,14.307441,0.498834,-143.362106,0.050091,0.000000
48.650002,63.116390,-143.362106,0.005101,0.001964,0.049883,280.755737,14.302379,0.498834,-143.362106,0.050091,0.000000
48.810001,63.099258,-143.273148,0.005092,0.001964,0.049883,280.679504,14.298496,0.498834,-143.273148,0.050091,0.000000
48.970001,63.079151,-143.317627,0.005118,0.001964,0.049883,280.590088,14.293940,0.498834,-143.317627,0.050091,0.000000
49.130001,63.065746,-143.317627,0.005088,0.001964,0.049883,280.530457,14.290903,0.498834,-143.317627,0.050091,0.000000
49.290001,63.063885,-143.273148,0.005122,0.001964,0.049883,280.522156,14.290481,0.498834,-143.273148,0.050091,0.000000
49.450001,63.044147,-143.317627,0.005096,0.001964,0.049883,280.434387,14.286008,0.498834,-143.317627,0.050091,0.000000
49.610001,63.033348,-143.273148,0.005083,0.001964,0.049883,280.386322,14.283561,0.498834,-143.273148,0.050091,0.000000
49.770000,63.025902,-143.273148,0.005092,0.001964,0.049883,280.353210,14.281874,0.498834,-143.273148,0.050091,0.000000
49.930004,62.990528,-143.273148,0.005066,0.001964,0.049883,280.195862,14.273858,0.498834,-143.273148,0.050091,0.000000
50.090004,62.990154,-143.273148,0.005105,0.001964,0.049883,280.194214,14.273773,0.498834,-143.273148,0.050091,0.000000
50.250004,62.976006,-143.228668,0.005070,0.001964,0.049883,280.131256,14.270567,0.498834,-143.228668,0.050091,0.000000
50.410004,62.963715,-143.184189,0.005113,0.001964,0.049883,280.076599,14.267782,0.498834,-143.184189,0.050091,0.000000
50.570004,62.947704,-143.228668,0.005126,0.001964,0.049883,280.005371,14.264153,0.498834,-143.228668,0.050091,0.000000
50.730003,62.924244,-143.273148,0.005101,0.001964,0.049883,279.901031,14.258838,0.498834,-143.273148,0.050091,0.000000
50.890003,62.921638,-143.273148,0.005075,0.001964,0.049883,279.889435,14.258246,0.498834,-143.273148,0.050091,0.000000
51.050003,62.904510,-143.228668,0.005070,0.001964,0.049883,279.813232,14.254366,0.498834,-143.228668,0.050091,0.000000
51.210003,62.887009,-143.184189,0.005118,0.001964,0.049883,279.735382,14.250400,0.498834,-143.184189,0.050091,0.000000
51.370003,62.872112,-143.273148,0.005096,0.001964,0.049883,279.669128,14.247025,0.498834,-143.273148,0.050091,0.000000
51.530003,62.860195,-143.184189,0.005092,0.001964,0.049883,279.616119,14.244325,0.498834,-143.184189,0.050091,0.000000
51.690002,62.861313,-143.139694,0.005075,0.001964,0.049883,279.621094,14.244577,0.498834,-143.139694,0.050091,0.000000
51.850002,62.838600,-143.184189,0.005105,0.001964,0.049883,279.520050,14.239430,0.498834,-143.184189,0.050091,0.000000
52.010002,62.824078,-143.139694,0.005118,0.001964,0.049883,279.455444,14.236139,0.498834,-143.139694,0.050091,0.000000
52.170002,62.816257,-143.139694,0.005109,0.001964,0.049883,279.420654,14.234367,0.498834,-143.139694,0.050091,0.000000
52.330002,62.799873,-143.139694,0.005088,0.001964,0.049883,279.347778,14.230655,0.498834,-143.139694,0.050091,0.000000
52.490002,62.786839,-143.139694,0.005101,0.001964,0.049883,279.289795,14.227701,0.498834,-143.139694,0.050091,0.000000
52.650002,62.768967,-143.184189,0.005079,0.001964,0.049883,279.210297,14.223651,0.498834,-143.184189,0.050091,0.000000
52.810001,62.773808,-143.139694,0.005083,0.001964,0.049883,279.231842,14.224749,0.498834,-143.139694,0.050091,0.000000
52.970001,62.751465,-143.139694,0.005105,0.001964,0.049883,279.132446,14.219686,0.498834,-143.139694,0.050091,0.000000
53.130001,62.749229,-143.050735,0.005096,0.001964,0.049883,279.122528,14.219179,0.498834,-143.050735,0.050091,0.000000
53.290001,62.747368,-143.095215,0.005096,0.001964,0.049883,279.114227,14.218757,0.498834,-143.095215,0.050091,0.000000
53.450001,62.713856,-143.095215,0.005101,0.001964,0.049883,278.965149,14.211163,0.498834,-143.095215,0.050091,0.000000
53.610004,62.723164,-143.095215,0.005113,0.001964,0.049883,279.006561,14.213272,0.498834,-143.095215,0.050091,0.000000
53.770004,62.705662,-143.095215,0.005122,0.001964,0.049883,278.928711,14.209306,0.498834,-143.095215,0.050091,0.000000
53.930004,62.689278,-143.050735,0.005122,0.001964,0.049883,278.855835,14.205593,0.498834,-143.050735,0.050091,0.000000
54.090004,62.681831,-143.050735,0.005113,0.001964,0.049883,278.822723,14.203906,0.498834,-143.050735,0.050091,0.000000
54.250004,62.671402,-143.095215,0.005101,0.001964,0.049883,278.776306,14.201543,0.498834,-143.095215,0.050091,0.000000
54.410004,62.665073,-143.006256,0.005088,0.001964,0.049883,278.748169,14.200109,0.498834,-143.006256,0.050091,0.000000
54.570004,62.649063,-143.006256,0.005101,0.001964,0.049883,278.676941,14.196481,0.498834,-143.006256,0.050091,0.000000
54.730003,62.634911,-143.006256,0.005088,0.001964,0.049883,278.613983,14.193274,0.498834,-143.006256,0.050091,0.000000
54.890003,62.615177,-143.006256,0.005092,0.001964,0.049883,278.526215,14.188802,0.498834,-143.006256,0.050091,0.000000
55.050003,62.620018,-143.095215,0.005083,0.001964,0.049883,278.547760,14.189899,0.498834,-143.095215,0.050091,0.000000
55.210003,62.608101,-142.961777,0.005105,0.001964,0.049883,278.494751,14.187199,0.498834,-142.961777,0.050091,0.000000
55.370003,62.591717,-143.050735,0.005092,0.001964,0.049883,278.421875,14.183486,0.498834,-143.050735,0.050091,0.000000
55.530003,62.593952,-142.961777,0.005088,0.001964,0.049883,278.431793,14.183992,0.498834,-142.961777,0.050091,0.000000
55.690002,62.578682,-143.006256,0.005126,0.001964,0.049883,278.363892,14.180532,0.498834,-143.006256,0.050091,0.000000
55.850002,62.567513,-143.006256,0.005122,0.001964,0.049883,278.314209,14.178001,0.498834,-143.006256,0.050091,0.000000
56.010002,62.569000,-142.917297,0.005105,0.001964,0.049883,278.320801,14.178338,0.498834,-142.917297,0.050091,0.000000
56.170002,62.530273,-142.961777,0.005092,0.001964,0.049883,278.148560,14.169562,0.498834,-142.961777,0.050091,0.000000
56.330002,62.546288,-142.917297,0.005096,0.001964,0.049883,278.219788,14.173191,0.498834,-142.917297,0.050091,0.000000
56.490002,62.523945,-142.917297,0.005113,0.001964,0.049874,278.120392,14.168128,0.498743,-142.917297,0.050091,0.000000
56.650002,62.504208,-142.961777,0.005113,0.001964,0.049874,278.032593,14.163656,0.498743,-142.961777,0.050091,0.000000
56.810001,62.506069,-142.917297,0.005101,0.001964,0.049874,278.040894,14.164078,0.498743,-142.917297,0.050091,0.000000
56.970001,62.505699,-143.006256,0.005088,0.001964,0.049874,278.039246,14.163994,0.498743,-143.006256,0.050091,0.000000
57.130001,62.486706,-142.872818,0.005126,0.001964,0.049874,277.954742,14.159690,0.498743,-142.872818,0.050091,0.000000
57.290001,62.476654,-142.872818,0.005096,0.001964,0.049874,277.910034,14.157412,0.498743,-142.872818,0.050091,0.000000
57.450005,62.471066,-142.872818,0.005113,0.001964,0.049874,277.885193,14.156146,0.498743,-142.872818,0.050091,0.000000
57.610004,62.455055,-142.872818,0.005096,0.001964,0.049874,277.813965,14.152518,0.498743,-142.872818,0.050091,0.000000
57.770004,62.443886,-142.917297,0.005105,0.001964,0.049874,277.764282,14.149987,0.498743,-142.917297,0.050091,0.000000
57.930004,62.453938,-142.828339,0.005109,0.001964,0.049874,277.808990,14.152265,0.498743,-142.828339,0.050091,0.000000
58.090004,62.421169,-142.872818,0.005062,0.001964,0.049874,277.663239,14.144839,0.498743,-142.872818,0.050091,0.000000
58.250004,62.424522,-142.872818,0.005088,0.001964,0.049874,277.678131,14.145599,0.498743,-142.872818,0.050091,0.000000
58.410004,62.412231,-142.828339,0.005101,0.001964,0.049874,277.623474,14.142814,0.498743,-142.828339,0.050091,0.000000
58.570004,62.406273,-142.828339,0.005088,0.001964,0.049874,277.596954,14.141464,0.498743,-142.828339,0.050091,0.000000
58.730003,62.396221,-142.783859,0.005075,0.001964,0.049874,277.552246,14.139186,0.498743,-142.783859,0.050091,0.000000
58.890003,62.381699,-142.872818,0.005070,0.001964,0.049874,277.487640,14.135896,0.498743,-142.872818,0.050091,0.000000
59.050003,62.385422,-142.828339,0.005062,0.001964,0.049874,277.504211,14.136739,0.498743,-142.828339,0.050091,0.000000
59.210003,62.368294,-142.872818,0.005113,0.001964,0.049874,277.428040,14.132857,0.498743,-142.872818,0.050091,0.000000
59.370003,62.359730,-142.783859,0.005105,0.001964,0.049874,277.389923,14.130917,0.498743,-142.783859,0.050091,0.000000
59.530003,62.348183,-142.739365,0.005126,0.001964,0.049874,277.338562,14.128301,0.498743,-142.739365,0.050091,0.000000
59.690002,62.358982,-142.783859,0.005105,0.001964,0.049874,277.386597,14.130747,0.498743,-142.783859,0.050091,0.000000
59.850002,62.343342,-142.739365,0.005083,0.001964,0.049874,277.317047,14.127204,0.498743,-142.739365,0.050091,0.000000
60.010002,62.329937,-142.739365,0.005088,0.001964,0.049874,277.257416,14.124166,0.498743,-142.739365,0.050091,0.000000
60.170002,62.334408,-142.783859,0.005105,0.001964,0.049874,277.277283,14.125179,0.498743,-142.783859,0.050091,0.000000
60.330002,62.332546,-142.739365,0.005079,0.001964,0.049874,277.269012,14.124757,0.498743,-142.739365,0.050091,0.000000
60.490002,62.300892,-142.783859,0.005105,0.001964,0.049874,277.128204,14.117584,0.498743,-142.783859,0.050091,0.000000
60.650002,62.292702,-142.694885,0.005096,0.001964,0.049874,277.091766,14.115727,0.498743,-142.694885,0.050091,0.000000
60.810001,62.294189,-142.739365,0.005092,0.001964,0.049874,277.098389,14.116065,0.498743,-142.739365,0.050091,0.000000
60.970001,62.299030,-142.694885,0.005113,0.001964,0.049874,277.119934,14.117162,0.498743,-142.694885,0.050091,0.000000
61.130001,62.254719,-142.605927,0.005101,0.001964,0.049874,276.922821,14.107121,0.498743,-142.605927,0.050091,0.000000
61.290005,62.264774,-142.694885,0.005066,0.001964,0.049874,276.967560,14.109400,0.498743,-142.694885,0.050091,0.000000
61.450005,62.280041,-142.605927,0.005088,0.001964,0.049874,277.035461,14.112859,0.498743,-142.605927,0.050091,0.000000
61.610004,62.261421,-142.650406,0.005109,0.001964,0.049874,276.952637,14.108640,0.498743,-142.650406,0.050091,0.000000
61.770004,62.262539,-142.650406,0.005101,0.001964,0.049874,276.957611,14.108893,0.498743,-142.650406,0.050091,0.000000
61.930004,62.264400,-142.694885,0.005113,0.001964,0.049874,276.965881,14.109315,0.498743,-142.694885,0.050091,0.000000
62.090004,62.240940,-142.694885,0.005101,0.001964,0.049874,276.861542,14.103998,0.498743,-142.694885,0.050091,0.000000
62.250004,62.225674,-142.605927,0.005096,0.001964,0.049874,276.793610,14.100539,0.498743,-142.605927,0.050091,0.000000
62.410004,62.226418,-142.694885,0.005092,0.001964,0.049874,276.796936,14.100707,0.498743,-142.694885,0.050091,0.000000
62.570004,62.211151,-142.605927,0.005092,0.001964,0.049874,276.729034,14.097248,0.498743,-142.605927,0.050091,0.000000
62.730003,62.218597,-142.605927,0.005092,0.001964,0.049874,276.762146,14.098935,0.498743,-142.605927,0.050091,0.000000
62.890003,62.203331,-142.650406,0.005109,0.001964,0.049874,276.694244,14.095476,0.498743,-142.650406,0.050091,0.000000
63.050003,62.193279,-142.605927,0.005092,0.001964,0.049874,276.649536,14.093199,0.498743,-142.605927,0.050091,0.000000
63.210003,62.204449,-142.605927,0.005075,0.001964,0.049874,276.699219,14.095730,0.498743,-142.605927,0.050091,0.000000
63.370003,62.190300,-142.605927,0.005122,0.001964,0.049874,276.636261,14.092524,0.498743,-142.605927,0.050091,0.000000
63.530003,62.169445,-142.561447,0.005079,0.001964,0.049874,276.543518,14.087798,0.498743,-142.561447,0.050091,0.000000
63.690002,62.162743,-142.561447,0.005109,0.001964,0.049874,276.513702,14.086279,0.498743,-142.561447,0.050091,0.000000
63.850002,62.166840,-142.516968,0.005105,0.001964,0.049874,276.531921,14.087207,0.498743,-142.516968,0.050091,0.000000
64.010002,62.150826,-142.561447,0.005118,0.001964,0.049874,276.460693,14.083578,0.498743,-142.561447,0.050091,0.000000
64.170006,62.150082,-142.561447,0.005088,0.001964,0.049874,276.457367,14.083409,0.498743,-142.561447,0.050091,0.000000
64.330002,62.147846,-142.561447,0.005122,0.001964,0.049874,276.447418,14.082904,0.498743,-142.561447,0.050091,0.000000
64.490005,62.139656,-142.516968,0.005118,0.001964,0.049874,276.410980,14.081047,0.498743,-142.516968,0.050091,0.000000
64.650002,62.139282,-142.561447,0.005096,0.001964,0.049874,276.409332,14.080963,0.498743,-142.561447,0.050091,0.000000
64.810005,62.128487,-142.516968,0.005083,0.001964,0.049874,276.361298,14.078516,0.498743,-142.516968,0.050091,0.000000
64.970001,62.105396,-142.472488,0.005109,0.001964,0.049874,276.258606,14.073284,0.498743,-142.472488,0.050091,0.000000
65.130005,62.104282,-142.516968,0.005092,0.001964,0.049874,276.253632,14.073031,0.498743,-142.516968,0.050091,0.000000
65.290001,62.091621,-142.516968,0.005070,0.001964,0.049874,276.197327,14.070162,0.498743,-142.516968,0.050091,0.000000
65.450005,62.090130,-142.428009,0.005083,0.001964,0.049874,276.190704,14.069824,0.498743,-142.428009,0.050091,0.000000
65.610001,62.083054,-142.472488,0.005096,0.001964,0.049874,276.159210,14.068221,0.498743,-142.472488,0.050091,0.000000
65.770004,62.073002,-142.428009,0.005049,0.001964,0.049874,276.114502,14.065944,0.498743,-142.428009,0.050091,0.000000
65.930000,62.090130,-142.383530,0.005083,0.001964,0.049874,276.190704,14.069824,0.498743,-142.383530,0.050091,0.000000
66.090004,62.065926,-142.472488,0.005101,0.001964,0.049874,276.083038,14.064341,0.498743,-142.472488,0.050091,0.000000
66.250000,62.068161,-142.428009,0.005113,0.001964,0.049874,276.092957,14.064847,0.498743,-142.428009,0.050091,0.000000
66.410004,62.066299,-142.472488,0.005101,0.001964,0.049874,276.084686,14.064425,0.498743,-142.472488,0.050091,0.000000
66.570000,62.041721,-142.383530,0.005070,0.001964,0.049874,275.975372,14.058855,0.498743,-142.383530,0.050091,0.000000
66.730003,62.048798,-142.428009,0.005109,0.001964,0.049874,276.006836,14.060458,0.498743,-142.428009,0.050091,0.000000
66.889999,62.036880,-142.428009,0.005105,0.001964,0.049874,275.953827,14.057758,0.498743,-142.428009,0.050091,0.000000
67.050003,62.039486,-142.383530,0.005083,0.001964,0.049874,275.965424,14.058349,0.498743,-142.383530,0.050091,0.000000
67.200005,62.039860,-142.339050,0.005079,0.001964,0.049874,275.967072,14.058433,0.498743,-142.339050,0.050091,0.000000