File: Data/New new I18 4 new align_08182023_123207.csv
Time (sec),S:Load (lbs),S:HL1 (DIM),S:LVDT (in),S:Position (in),Ch:Position (mm),Ch:Load (N),Ch:Stress (MPa),Ch:Strain (mm/mm),Ch:HL1 (DIM),Set Point (),Cycles ()
0.110000,0.012665,-66.009735,0.001246,-0.018180,-0.461781,0.056336,0.002870,-4.617814,-66.009735,-0.461572,0.000000
0.720000,-0.007820,-66.054214,0.001302,-0.017998,-0.457159,-0.034786,-0.001772,-4.571593,-66.054214,-0.456092,0.000000
1.330000,0.014526,-66.054214,0.001712,-0.017596,-0.446951,0.064617,0.003292,-4.469507,-66.054214,-0.445929,0.000000
1.940000,0.014153,-66.054214,0.002139,-0.017203,-0.436953,0.062954,0.003207,-4.369525,-66.054214,-0.435764,0.000000
2.550000,0.039101,-66.054214,0.002531,-0.016804,-0.426823,0.173928,0.008860,-4.268226,-66.054214,-0.425601,0.000000
3.160000,0.032028,-66.009735,0.002962,-0.016409,-0.416781,0.142469,0.007258,-4.167805,-66.009735,-0.415436,0.000000
3.770000,0.027184,-66.098694,0.003372,-0.015997,-0.406313,0.120918,0.006160,-4.063130,-66.098694,-0.405273,0.000000
4.380000,-0.004463,-66.054214,0.003777,-0.015598,-0.396185,-0.019853,-0.001011,-3.961846,-66.054214,-0.395126,0.000000
4.990000,0.016014,-66.098694,0.004186,-0.015200,-0.386090,0.071234,0.003629,-3.860896,-66.098694,-0.384962,0.000000
5.600000,0.018997,-66.098694,0.004626,-0.014795,-0.375796,0.084504,0.004305,-3.757962,-66.098694,-0.374798,0.000000
6.210001,0.028305,-66.098694,0.005036,-0.014402,-0.365806,0.125907,0.006414,-3.658056,-66.098694,-0.364634,0.000000
6.820000,0.045059,-66.143173,0.005437,-0.014005,-0.355736,0.200433,0.010211,-3.557362,-66.143173,-0.354471,0.000000
7.430000,0.046547,-66.098694,0.005877,-0.013608,-0.345634,0.207051,0.010548,-3.456336,-66.098694,-0.344306,0.000000
8.040000,0.039474,-66.187653,0.006321,-0.013195,-0.335148,0.175591,0.008945,-3.351479,-66.187653,-0.334143,0.000000
8.650001,0.020485,-66.143173,0.006696,-0.012798,-0.325071,0.091121,0.004642,-3.250710,-66.143173,-0.323979,0.000000
9.260000,0.028305,-66.143173,0.007101,-0.012399,-0.314924,0.125907,0.006414,-3.149245,-66.143173,-0.313815,0.000000
9.870001,0.024956,-66.187653,0.007515,-0.011995,-0.304666,0.111009,0.005655,-3.046659,-66.187653,-0.303652,0.000000
10.480000,0.056976,-66.143173,0.007929,-0.011596,-0.294536,0.253443,0.012911,-2.945360,-66.143173,-0.293487,0.000000
11.090000,0.052879,-66.232140,0.008377,-0.011207,-0.284668,0.235219,0.011983,-2.846680,-66.232140,-0.283324,0.000000
11.700001,0.050644,-66.187653,0.008770,-0.010805,-0.274443,0.225275,0.011476,-2.744427,-66.187653,-0.273159,0.000000
12.310000,0.040962,-66.187653,0.009192,-0.010393,-0.263993,0.182209,0.009282,-2.639934,-66.187653,-0.263012,0.000000
12.920001,0.024956,-66.276619,0.009649,-0.009997,-0.253933,0.111009,0.005655,-2.539331,-66.276619,-0.252849,0.000000
13.530001,0.051392,-66.232140,0.010054,-0.009599,-0.243803,0.228601,0.011646,-2.438033,-66.232140,-0.242684,0.000000
14.140000,0.029793,-66.321098,0.010464,-0.009195,-0.233545,0.132525,0.006751,-2.335447,-66.321098,-0.232521,0.000000
14.750001,0.046181,-66.232140,0.010891,-0.008797,-0.223442,0.205422,0.010465,-2.234420,-66.232140,-0.222357,0.000000
15.360001,0.068146,-66.276619,0.011292,-0.008407,-0.213529,0.303127,0.015442,-2.135286,-66.276619,-0.212193,0.000000
15.970001,0.067032,-66.276619,0.011710,-0.008003,-0.203278,0.298173,0.015190,-2.032776,-66.276619,-0.202030,0.000000
16.580000,0.059212,-66.276619,0.012180,-0.007592,-0.192828,0.263387,0.013418,-1.928283,-66.276619,-0.191865,0.000000
17.190001,0.176880,-66.276619,0.012538,-0.007197,-0.182803,0.786801,0.040082,-1.828029,-66.276619,-0.181702,0.000000
17.800001,0.548508,-66.232140,0.012900,-0.000000,-0.000000,2.439884,0.124294,-0.000000,-66.232140,0.000224,0.000000
18.410002,0.602501,-66.321098,0.012896,-0.000000,-0.000000,2.680058,0.136529,-0.000000,-66.321098,0.000572,0.000000
19.020000,0.675484,-66.276619,0.012904,0.000023,0.000589,3.004702,0.153067,0.005889,-66.276619,0.001587,0.000000
19.630001,0.799858,-66.321098,0.012978,0.000069,0.001743,3.557946,0.181250,0.017426,-66.321098,0.002601,0.000000
20.240002,0.811028,-66.232140,0.012999,0.000108,0.002731,3.607631,0.183781,0.027312,-66.232140,0.003624,0.000000
20.850000,0.850128,-66.276619,0.013060,0.000142,0.003599,3.781559,0.192642,0.035987,-66.276619,0.004639,0.000000
21.460001,0.923119,-66.232140,0.013064,0.000187,0.004752,4.106236,0.209182,0.047523,-66.232140,0.005653,0.000000
22.070002,0.867630,-66.276619,0.013142,0.000223,0.005662,3.859411,0.196608,0.056622,-66.276619,0.006669,0.000000
22.680000,0.912315,-66.321098,0.013163,0.000265,0.006730,4.058181,0.206734,0.067295,-66.321098,0.007691,0.000000
23.290001,0.924232,-66.232140,0.013206,0.000297,0.007553,4.111191,0.209434,0.075531,-66.232140,0.008707,0.000000
23.900002,0.880295,-66.321098,0.013249,0.000342,0.008680,3.915747,0.199478,0.086795,-66.321098,0.009721,0.000000
24.510000,0.908218,-66.321098,0.013323,0.000383,0.009730,4.039957,0.205805,0.097302,-66.321098,0.010735,0.000000
25.120001,0.925346,-66.321098,0.013361,0.000416,0.010554,4.116146,0.209686,0.105538,-66.321098,0.011750,0.000000
25.730001,0.897049,-66.321098,0.013396,0.000459,0.011654,3.990273,0.203274,0.116544,-66.321098,0.012773,0.000000
26.340002,0.903008,-66.365578,0.013486,0.000505,0.012834,4.016778,0.204624,0.128338,-66.365578,0.013788,0.000000
26.950001,0.882896,-66.365578,0.013482,0.000536,0.013606,3.927320,0.200067,0.136059,-66.365578,0.014803,0.000000
27.560001,0.867256,-66.321098,0.013525,0.000584,0.014829,3.857748,0.196523,0.148292,-66.321098,0.015818,0.000000
28.170002,0.854599,-66.321098,0.013594,0.000620,0.015739,3.801446,0.193655,0.157391,-66.321098,0.016841,0.000000
28.780001,0.840073,-66.410057,0.013646,0.000656,0.016667,3.736830,0.190363,0.166672,-66.410057,0.017856,0.000000
29.390001,0.841568,-66.365578,0.013715,0.000706,0.017933,3.743481,0.190702,0.179328,-66.365578,0.018870,0.000000
30.000002,0.792786,-66.410057,0.013758,0.000739,0.018758,3.526487,0.179648,0.187579,-66.410057,0.019884,0.000000
30.610001,0.844170,-66.365578,0.013780,0.000784,0.019902,3.755054,0.191292,0.199025,-66.365578,0.020908,0.000000
31.220001,0.804703,-66.410057,0.013836,0.000822,0.020891,3.579497,0.182348,0.208911,-66.410057,0.021922,0.000000
31.830002,0.736557,-66.365578,0.013870,0.000860,0.021836,3.276369,0.166906,0.218358,-66.365578,0.022938,0.000000
32.440002,0.789436,-66.410057,0.013961,0.000903,0.022929,3.511588,0.178889,0.229289,-66.410057,0.023952,0.000000
33.050003,0.770073,-66.410057,0.013956,0.000941,0.023892,3.425456,0.174501,0.238918,-66.410057,0.024976,0.000000
33.660000,0.698578,-66.410057,0.014030,0.000979,0.024855,3.107430,0.158300,0.248546,-66.410057,0.025990,0.000000
34.270000,0.743256,-66.410057,0.014060,0.001019,0.025877,3.306166,0.168424,0.258766,-66.410057,0.027004,0.000000
34.880001,0.735435,-66.365578,0.014099,0.001056,0.026814,3.271380,0.166652,0.268137,-66.365578,0.028019,0.000000
35.490002,0.704529,-66.365578,0.014168,0.001100,0.027951,3.133901,0.159649,0.279507,-66.365578,0.029042,0.000000
36.100002,0.663940,-66.410057,0.014185,0.001141,0.028973,2.953355,0.150451,0.289726,-66.410057,0.030057,0.000000
36.710003,0.713844,-66.410057,0.014263,0.001172,0.029770,3.175338,0.161759,0.297705,-66.410057,0.031072,0.000000
37.320004,0.702667,-66.410057,0.014306,0.001222,0.031045,3.125620,0.159227,0.310452,-66.410057,0.032087,0.000000
37.930000,0.682190,-66.365578,0.014340,0.001262,0.032052,3.034532,0.154586,0.320520,-66.365578,0.033110,0.000000
38.540001,0.673996,-66.365578,0.014370,0.001295,0.032894,2.998084,0.152730,0.328938,-66.365578,0.034125,0.000000
39.150002,0.685539,-66.410057,0.014431,0.001343,0.034125,3.049431,0.155345,0.341246,-66.410057,0.035139,0.000000
39.760002,0.653145,-66.499023,0.014482,0.001381,0.035069,2.905333,0.148005,0.350693,-66.499023,0.036153,0.000000
40.370003,0.650909,-66.410057,0.014530,0.001421,0.036085,2.895390,0.147498,0.360852,-66.410057,0.037169,0.000000
40.980003,0.662827,-66.410057,0.014577,0.001464,0.037195,2.948400,0.150199,0.371949,-66.410057,0.038193,0.000000
41.590000,0.617393,-66.499023,0.014616,0.001503,0.038165,2.746303,0.139903,0.381654,-66.499023,0.039207,0.000000
42.200001,0.621864,-66.410057,0.014642,0.001539,0.039103,2.766191,0.140916,0.391025,-66.410057,0.040221,0.000000
42.810001,0.633034,-66.454544,0.014724,0.001581,0.040170,2.815875,0.143448,0.401698,-66.454544,0.041236,0.000000
43.420002,0.579788,-66.543503,0.014758,0.001621,0.041184,2.579027,0.131382,0.411842,-66.543503,0.042259,0.000000
44.030003,0.617393,-66.454544,0.014810,0.001663,0.042242,2.746303,0.139903,0.422425,-66.454544,0.043273,0.000000
44.640003,0.601761,-66.543503,0.014832,0.001696,0.043066,2.676766,0.136361,0.430660,-66.543503,0.044288,0.000000
45.250004,0.576439,-66.454544,0.014870,0.001741,0.044220,2.564128,0.130623,0.442197,-66.454544,0.045304,0.000000
45.860001,0.572342,-66.499023,0.014926,0.001784,0.045304,2.545904,0.129695,0.453037,-66.499023,0.046327,0.000000
46.470001,0.561539,-66.499023,0.014952,0.001819,0.046214,2.497849,0.127246,0.462136,-66.499023,0.047341,0.000000
47.080002,0.547760,-66.454544,0.015004,0.001865,0.047367,2.436558,0.124124,0.473672,-66.454544,0.048356,0.000000
47.690002,0.513130,-66.543503,0.015069,0.001906,0.048400,2.282517,0.116277,0.483997,-66.543503,0.049370,0.000000
48.300003,0.521698,-66.499023,0.015073,0.001936,0.049179,2.320629,0.118218,0.491794,-66.499023,0.050394,0.000000
48.910004,0.486320,-66.543503,0.015146,0.001984,0.050394,2.163262,0.110202,0.503936,-66.543503,0.051408,0.000000
49.520000,0.474403,-66.499023,0.015177,0.002019,0.051287,2.110252,0.107501,0.512868,-66.499023,0.052422,0.000000
50.130001,0.459137,-66.543503,0.015211,0.002054,0.052163,2.042343,0.104042,0.521634,-66.543503,0.053438,0.000000
50.740002,0.452438,-66.499023,0.015237,0.002108,0.053534,2.012546,0.102524,0.535336,-66.499023,0.054462,0.000000
51.350002,0.409988,-66.499023,0.015289,0.002143,0.054427,1.823720,0.092905,0.544268,-66.499023,0.055476,0.000000
51.960003,0.415199,-66.499023,0.015358,0.002182,0.055423,1.846899,0.094085,0.554230,-66.499023,0.056490,0.000000
52.570004,0.384293,-66.499023,0.015349,0.002222,0.056439,1.709419,0.087082,0.564388,-66.499023,0.057505,0.000000
53.180004,0.322105,-66.543503,0.015431,0.002263,0.057479,1.432796,0.072990,0.574789,-66.543503,0.058528,0.000000
53.790001,0.379082,-66.543503,0.015457,0.002305,0.058546,1.686240,0.085901,0.585463,-66.543503,0.059542,0.000000
54.400002,0.360832,-66.499023,0.015521,0.002339,0.059412,1.605062,0.081766,0.594123,-66.499023,0.060558,0.000000
55.010002,0.295670,-66.587982,0.015513,0.002379,0.060428,1.315204,0.067000,0.604281,-66.587982,0.061573,0.000000
55.620003,0.322479,-66.499023,0.015569,0.002423,0.061555,1.434459,0.073075,0.615545,-66.499023,0.062587,0.000000
56.230003,0.315033,-66.499023,0.015608,0.002459,0.062457,1.401337,0.071387,0.624568,-66.499023,0.063610,0.000000
56.840004,0.284126,-66.543503,0.015659,0.002500,0.063489,1.263857,0.064384,0.634893,-66.543503,0.064625,0.000000
57.450005,0.253586,-66.499023,0.015681,0.002540,0.064513,1.128006,0.057463,0.645128,-66.499023,0.065639,0.000000
58.060001,0.310188,-66.543503,0.015677,0.002574,0.065388,1.379786,0.070290,0.653878,-66.543503,0.066654,0.000000
58.670002,0.265129,-66.499023,0.015759,0.002622,0.066593,1.179353,0.060079,0.665930,-66.499023,0.067677,0.000000
59.280003,0.236458,-66.587982,0.015789,0.002666,0.067721,1.051817,0.053582,0.677209,-66.587982,0.068693,0.000000
59.890003,0.227898,-66.543503,0.015810,0.002694,0.068423,1.013739,0.051642,0.684233,-66.543503,0.069707,0.000000
60.500004,0.216721,-66.587982,0.015879,0.002743,0.069681,0.964021,0.049110,0.696814,-66.587982,0.070722,0.000000
61.110004,0.191032,-66.543503,0.015866,0.002781,0.070643,0.849755,0.043289,0.706428,-66.543503,0.071745,0.000000
61.720001,0.185448,-66.587982,0.015944,0.002821,0.071650,0.824913,0.042023,0.716496,-66.587982,0.072759,0.000000
62.330002,0.197357,-66.587982,0.015931,0.002868,0.072846,0.877889,0.044722,0.728456,-66.587982,0.073774,0.000000
62.940002,0.133682,-66.454544,0.016000,0.002907,0.073834,0.594648,0.030293,0.738342,-66.454544,0.074790,0.000000
63.550003,0.046181,-66.632462,0.015961,0.002941,0.074711,0.205422,0.010465,0.747108,-66.632462,0.075811,0.000000
64.160004,0.084908,-66.587982,0.015991,0.002988,0.075890,0.377688,0.019240,0.758902,-66.587982,0.076827,0.000000
64.770004,0.064423,-66.543503,0.016039,0.003022,0.076749,0.286566,0.014598,0.767486,-66.543503,0.077842,0.000000
65.380005,0.062187,-66.587982,0.016035,0.003065,0.077842,0.276622,0.014092,0.778417,-66.587982,0.078856,0.000000
65.990005,0.077454,-66.543503,0.016056,0.003104,0.078847,0.344531,0.017551,0.788469,-66.543503,0.079879,0.000000
66.600006,0.088631,-66.632462,0.016116,0.003145,0.079889,0.394249,0.020084,0.798885,-66.632462,0.080894,0.000000
67.210007,0.079689,-66.543503,0.016142,0.003185,0.080894,0.354474,0.018058,0.808938,-66.543503,0.081908,0.000000
67.820000,0.084160,-66.632462,0.016190,0.003225,0.081908,0.374362,0.019071,0.819082,-66.632462,0.082924,0.000000
68.430000,0.083412,-66.632462,0.016246,0.003264,0.082915,0.371036,0.018901,0.829149,-66.632462,0.083947,0.000000
69.040001,0.064796,-66.587982,0.016302,0.003306,0.083973,0.288229,0.014683,0.839732,-66.587982,0.084962,0.000000
69.650002,0.088997,-66.632462,0.016336,0.003336,0.084745,0.395878,0.020167,0.847453,-66.632462,0.085976,0.000000
70.260002,0.059952,-66.587982,0.016388,0.003387,0.086020,0.266679,0.013585,0.860201,-66.587982,0.086991,0.000000
70.870003,0.064423,-66.676949,0.016405,0.003419,0.086851,0.286566,0.014598,0.868512,-66.676949,0.088005,0.000000
71.480003,0.074478,-66.587982,0.016453,0.003460,0.087875,0.331295,0.016877,0.878747,-66.587982,0.089028,0.000000
72.090004,0.068893,-66.676949,0.016509,0.003507,0.089081,0.306453,0.015611,0.890813,-66.676949,0.090043,0.000000
72.700005,0.029419,-66.632462,0.016539,0.003544,0.090017,0.130862,0.006666,0.900169,-66.632462,0.091059,0.000000
73.310005,0.075966,-66.632462,0.016569,0.003581,0.090954,0.337913,0.017214,0.909541,-66.632462,0.092073,0.000000
73.920006,0.054001,-66.632462,0.016621,0.003626,0.092099,0.240208,0.012237,0.920986,-66.632462,0.093096,0.000000
74.530006,0.022346,-66.587982,0.016655,0.003666,0.093113,0.099402,0.005064,0.931130,-66.587982,0.094111,0.000000
75.140007,0.069267,-66.587982,0.016724,0.003706,0.094136,0.308116,0.015696,0.941364,-66.587982,0.095125,0.000000
75.750000,0.054367,-66.676949,0.016759,0.003742,0.095039,0.241837,0.012320,0.950387,-66.676949,0.096139,0.000000
76.360001,0.002609,-66.632462,0.016815,0.003784,0.096105,0.011607,0.000591,0.961045,-66.632462,0.097163,0.000000
76.970001,0.062935,-66.676949,0.016832,0.003827,0.097216,0.279948,0.014261,0.972158,-66.676949,0.098177,0.000000
77.580002,0.065544,-66.587982,0.016897,0.003861,0.098082,0.291555,0.014853,0.980818,-66.587982,0.099193,0.000000
78.190002,0.021599,-66.632462,0.016888,0.003905,0.099193,0.096076,0.004894,0.991930,-66.632462,0.100207,0.000000
78.800003,0.042824,-66.587982,0.016936,0.003940,0.100068,0.190490,0.009704,1.000681,-66.587982,0.101231,0.000000
79.410004,0.110970,-66.676949,0.016979,0.003978,0.101031,0.493617,0.025146,1.010310,-66.676949,0.102245,0.000000
80.020004,0.092728,-66.632462,0.017022,0.004023,0.102194,0.412473,0.021012,1.021937,-66.632462,0.103260,0.000000
80.630005,0.079315,-66.587982,0.017091,0.004068,0.103329,0.352812,0.017973,1.033291,-66.587982,0.104274,0.000000
81.240005,0.087883,-66.632462,0.017095,0.004094,0.103997,0.390923,0.019915,1.039968,-66.632462,0.105297,0.000000
81.850006,0.091606,-66.587982,0.017156,0.004146,0.105297,0.407484,0.020758,1.052973,-66.587982,0.106313,0.000000
82.460007,0.056602,-66.721428,0.017186,0.004183,0.106251,0.251780,0.012826,1.062511,-66.721428,0.107328,0.000000
83.070007,0.093094,-66.676949,0.017233,0.004220,0.107188,0.414102,0.021095,1.071882,-66.676949,0.108342,0.000000
83.680000,0.105759,-66.721428,0.017281,0.004271,0.108472,0.470438,0.023965,1.084721,-66.721428,0.109365,0.000000
84.290001,0.077087,-66.676949,0.017328,0.004306,0.109374,0.342902,0.017468,1.093744,-66.676949,0.110380,0.000000
84.900002,0.086769,-66.632462,0.017375,0.004340,0.110240,0.385968,0.019662,1.102404,-66.632462,0.111394,0.000000
85.510002,0.103523,-66.721428,0.017410,0.004389,0.111489,0.460494,0.023459,1.114894,-66.721428,0.112408,0.000000
86.120003,0.078201,-66.587982,0.017470,0.004422,0.112322,0.347857,0.017721,1.123221,-66.587982,0.113424,0.000000
86.730003,0.082672,-66.676949,0.017509,0.004464,0.113389,0.367744,0.018734,1.133894,-66.676949,0.114448,0.000000
87.340004,0.106133,-66.676949,0.017509,0.004505,0.114420,0.472101,0.024050,1.144204,-66.676949,0.115462,0.000000
87.950005,0.093468,-66.676949,0.017582,0.004544,0.115418,0.415765,0.021180,1.154181,-66.676949,0.116476,0.000000
88.560005,0.100174,-66.676949,0.017625,0.004584,0.116425,0.445596,0.022700,1.164249,-66.676949,0.117491,0.000000
89.170006,0.099052,-66.632462,0.017664,0.004629,0.117577,0.440607,0.022446,1.175770,-66.632462,0.118514,0.000000
89.780006,0.103149,-66.721428,0.017703,0.004664,0.118470,0.458832,0.023374,1.184702,-66.721428,0.119528,0.000000
90.390007,0.079315,-66.676949,0.017759,0.004707,0.119547,0.352812,0.017973,1.195467,-66.676949,0.120544,0.000000
91.000008,0.094589,-66.676949,0.017781,0.004738,0.120335,0.420754,0.021434,1.203354,-66.676949,0.121559,0.000000
91.610001,0.100174,-66.632462,0.017854,0.004790,0.121662,0.445596,0.022700,1.216617,-66.632462,0.122582,0.000000
92.220001,0.070381,-66.721428,0.017884,0.004824,0.122522,0.313071,0.015949,1.225216,-66.721428,0.123596,0.000000
92.830002,0.105011,-66.676949,0.017901,0.004860,0.123448,0.467112,0.023796,1.234481,-66.676949,0.124611,0.000000
93.440002,0.078949,-66.632462,0.017992,0.004908,0.124662,0.351183,0.017890,1.246623,-66.632462,0.125625,0.000000
94.050003,0.046181,-66.721428,0.017983,0.004943,0.125565,0.205422,0.010465,1.255646,-66.721428,0.126649,0.000000
94.660004,0.088997,-66.676949,0.018048,0.004984,0.126588,0.395878,0.020167,1.265881,-66.676949,0.127663,0.000000
95.270004,0.071503,-66.676949,0.018104,0.005029,0.127742,0.318060,0.016203,1.277417,-66.676949,0.128679,0.000000
95.880005,0.024956,-66.721428,0.018121,0.005065,0.128661,0.111009,0.005655,1.286607,-66.721428,0.129693,0.000000
96.490005,0.084908,-66.676949,0.018182,0.005108,0.129736,0.377688,0.019240,1.297356,-66.676949,0.130717,0.000000
97.100006,0.086769,-66.721428,0.018212,0.005150,0.130803,0.385968,0.019662,1.308029,-66.721428,0.131731,0.000000
97.710007,0.019737,-66.676949,0.018238,0.005183,0.131645,0.087796,0.004473,1.316447,-66.676949,0.132745,0.000000
98.320007,0.084908,-66.721428,0.018285,0.005229,0.132815,0.377688,0.019240,1.328150,-66.721428,0.133760,0.000000
98.930008,0.072990,-66.676949,0.018311,0.005263,0.133682,0.324678,0.016540,1.336825,-66.676949,0.134783,0.000000
99.540001,0.048409,-66.676949,0.018367,0.005305,0.134757,0.215332,0.010970,1.347574,-66.676949,0.135797,0.000000
100.150002,0.095703,-66.676949,0.018423,0.005343,0.135720,0.425709,0.021687,1.357203,-66.676949,0.136813,0.000000
100.760002,0.127357,-66.632462,0.018440,0.005378,0.136614,0.566514,0.028860,1.366135,-66.632462,0.137828,0.000000
101.370003,0.102036,-66.676949,0.018488,0.005423,0.137732,0.453877,0.023122,1.377323,-66.676949,0.138842,0.000000
101.980003,0.083046,-66.676949,0.018552,0.005468,0.138886,0.369407,0.018818,1.388860,-66.676949,0.139865,0.000000
102.590004,0.118042,-66.676949,0.018604,0.005493,0.139519,0.525077,0.026749,1.395188,-66.676949,0.140880,0.000000
103.200005,0.102776,-66.721428,0.018617,0.005546,0.140871,0.457169,0.023289,1.408708,-66.721428,0.141894,0.000000
103.810005,0.097939,-66.676949,0.018673,0.005584,0.141826,0.435652,0.022193,1.418261,-66.676949,0.142910,0.000000
104.420006,0.123260,-66.765907,0.018699,0.005620,0.142745,0.548290,0.027931,1.427450,-66.765907,0.143932,0.000000
105.030006,0.142624,-66.721428,0.018729,0.005670,0.144020,0.634423,0.032319,1.440198,-66.721428,0.144948,0.000000
105.640007,0.093094,-66.721428,0.018820,0.005705,0.144904,0.414102,0.021095,1.449039,-66.721428,0.145962,0.000000
106.250008,0.131081,-66.632462,0.018828,0.005740,0.145788,0.583076,0.029703,1.457881,-66.632462,0.146977,0.000000
106.860008,0.170547,-66.676949,0.018897,0.005789,0.147037,0.758633,0.038647,1.470371,-66.676949,0.148000,0.000000
107.470009,0.142624,-66.721428,0.018928,0.005824,0.147921,0.634423,0.032319,1.479213,-66.721428,0.149014,0.000000
108.080002,0.170921,-66.721428,0.018988,0.005863,0.148910,0.760296,0.038731,1.489099,-66.721428,0.150029,0.000000
108.690002,0.194008,-66.721428,0.019009,0.005907,0.150029,0.862990,0.043963,1.500287,-66.721428,0.151045,0.000000
109.300003,0.210770,-66.721428,0.019113,0.005943,0.150940,0.937550,0.047761,1.509401,-66.721428,0.152068,0.000000
109.910004,0.233482,-66.765907,0.019130,0.005982,0.151954,1.038581,0.052908,1.519544,-66.765907,0.153082,0.000000
110.520004,0.254333,-66.765907,0.019152,0.006028,0.153117,1.131332,0.057633,1.531172,-66.765907,0.154097,0.000000
111.130005,0.264015,-66.721428,0.019229,0.006063,0.154010,1.174398,0.059827,1.540104,-66.721428,0.155111,0.000000
111.740005,0.268486,-66.765907,0.019247,0.006106,0.155094,1.194286,0.060840,1.550944,-66.765907,0.156134,0.000000
112.350006,0.312050,-66.676949,0.019294,0.006146,0.156100,1.388067,0.070712,1.560997,-66.676949,0.157149,0.000000
112.960007,0.338493,-66.765907,0.019354,0.006189,0.157193,1.505694,0.076704,1.571927,-66.765907,0.158163,0.000000
113.570007,0.339607,-66.721428,0.019402,0.006226,0.158130,1.510648,0.076956,1.581299,-66.721428,0.159179,0.000000
114.180008,0.402168,-66.765907,0.019467,0.006260,0.158996,1.788934,0.091133,1.589959,-66.765907,0.160202,0.000000
114.790009,0.386528,-66.765907,0.019484,0.006305,0.160159,1.719362,0.087589,1.601586,-66.765907,0.161217,0.000000
115.400009,0.408493,-66.721428,0.019544,0.006342,0.161078,1.817068,0.092566,1.610776,-66.721428,0.162231,0.000000
116.010002,0.441261,-66.765907,0.019587,0.006381,0.162084,1.962828,0.099991,1.620843,-66.765907,0.163246,0.000000
116.620003,0.478127,-66.676949,0.019613,0.006427,0.163255,2.126813,0.108345,1.632546,-66.676949,0.164260,0.000000
117.230003,0.465843,-66.765907,0.019682,0.006464,0.164192,2.072174,0.105562,1.641918,-66.765907,0.165283,0.000000
117.840004,0.551117,-66.721428,0.019721,0.006507,0.165276,2.451491,0.124885,1.652758,-66.721428,0.166299,0.000000
118.450005,0.585373,-66.721428,0.019781,0.006549,0.166332,2.603869,0.132647,1.663325,-66.721428,0.167314,0.000000
119.060005,0.557816,-66.810387,0.019829,0.006584,0.167244,2.481287,0.126403,1.672439,-66.810387,0.168328,0.000000
119.670006,0.667664,-66.721428,0.019846,0.006628,0.168354,2.969916,0.151295,1.683536,-66.721428,0.169351,0.000000
120.280006,0.701553,-66.721428,0.019885,0.006664,0.169265,3.120665,0.158974,1.692650,-66.721428,0.170366,0.000000
120.890007,0.719429,-66.676949,0.019941,0.006708,0.170391,3.200180,0.163025,1.703914,-66.676949,0.171380,0.000000
121.500008,0.844543,-66.721428,0.019997,0.006746,0.171345,3.756717,0.191376,1.713452,-66.721428,0.172394,0.000000
122.110008,0.908592,-66.765907,0.020023,0.006777,0.172143,4.041620,0.205890,1.721431,-66.765907,0.173418,0.000000
122.720009,0.973755,-66.721428,0.020079,0.006822,0.173288,4.331478,0.220656,1.732876,-66.721428,0.174434,0.000000
123.330009,1.017326,-66.721428,0.020130,0.006866,0.174406,4.525294,0.230529,1.744064,-66.721428,0.175448,0.000000
123.940002,1.062752,-66.721428,0.020135,0.006892,0.175057,4.727356,0.240823,1.750574,-66.721428,0.176462,0.000000
124.550003,1.188248,-66.721428,0.020217,0.006944,0.176384,5.285590,0.269261,1.763837,-66.721428,0.177486,0.000000
125.160004,1.280594,-66.721428,0.020238,0.006984,0.177381,5.696366,0.290187,1.773814,-66.721428,0.178500,0.000000
125.770004,1.392677,-66.810387,0.020294,0.007024,0.178405,6.194938,0.315585,1.784048,-66.810387,0.179515,0.000000
126.380005,1.502525,-66.765907,0.020359,0.007071,0.179593,6.683567,0.340477,1.795933,-66.765907,0.180529,0.000000
126.990005,1.525238,-66.721428,0.020368,0.007105,0.180477,6.784598,0.345624,1.804774,-66.721428,0.181552,0.000000
127.600006,1.635094,-66.810387,0.020432,0.007143,0.181440,7.273260,0.370518,1.814403,-66.810387,0.182568,0.000000
128.210007,1.786644,-66.721428,0.020475,0.007189,0.182611,7.947389,0.404859,1.826106,-66.721428,0.183583,0.000000
128.820007,1.869682,-66.765907,0.020506,0.007228,0.183583,8.316762,0.423676,1.835825,-66.765907,0.184597,0.000000
129.430008,1.942299,-66.676949,0.020557,0.007262,0.184467,8.639777,0.440131,1.844667,-66.676949,0.185620,0.000000
130.040009,2.109123,-66.765907,0.020579,0.007308,0.185611,9.381848,0.477934,1.856112,-66.765907,0.186635,0.000000
130.650009,2.179131,-66.765907,0.020605,0.007343,0.186514,9.693256,0.493798,1.865136,-66.765907,0.187649,0.000000
131.260010,2.283020,-66.721428,0.020682,0.007384,0.187554,10.155380,0.517340,1.875537,-66.721428,0.188665,0.000000
131.870010,2.440163,-66.810387,0.020747,0.007427,0.188656,10.854385,0.552949,1.886558,-66.810387,0.189679,0.000000
132.480011,2.488937,-66.632462,0.020756,0.007464,0.189575,11.071346,0.564001,1.895748,-66.632462,0.190703,0.000000
133.090012,2.613686,-66.765907,0.020816,0.007506,0.190659,11.626254,0.592270,1.906588,-66.765907,0.191717,0.000000
133.700012,2.720932,-66.721428,0.020855,0.007539,0.191482,12.103310,0.616572,1.914824,-66.721428,0.192731,0.000000
134.310013,2.866524,-66.721428,0.020919,0.007587,0.192722,12.750935,0.649564,1.927223,-66.721428,0.193746,0.000000
134.920013,3.004303,-66.765907,0.020932,0.007625,0.193676,13.363807,0.680785,1.936761,-66.765907,0.194769,0.000000
135.530014,3.102608,-66.765907,0.020980,0.007659,0.194527,13.801088,0.703061,1.945269,-66.765907,0.195784,0.000000
136.139999,3.172241,-66.765907,0.021010,0.007705,0.195706,14.110834,0.718840,1.957063,-66.765907,0.196799,0.000000
136.750000,3.257515,-66.721428,0.021075,0.007741,0.196625,14.490150,0.738163,1.966253,-66.721428,0.197814,0.000000
137.360001,3.434769,-66.721428,0.021131,0.007782,0.197665,15.278614,0.778330,1.976654,-66.721428,0.198837,0.000000
137.970001,3.604568,-66.765907,0.021131,0.007828,0.198837,16.033922,0.816807,1.988372,-66.765907,0.199852,0.000000
138.580002,3.622070,-66.721428,0.021208,0.007863,0.199721,16.111773,0.820773,1.997213,-66.721428,0.200866,0.000000
139.190002,3.820541,-66.765907,0.021221,0.007907,0.200831,16.994617,0.865747,2.008311,-66.765907,0.201880,0.000000
139.800003,3.975082,-66.721428,0.021273,0.007948,0.201889,17.682049,0.900767,2.018893,-66.721428,0.202904,0.000000
140.410004,3.994812,-66.721428,0.021312,0.007983,0.202766,17.769812,0.905237,2.027659,-66.721428,0.203918,0.000000
141.020004,4.188446,-66.676949,0.021355,0.008027,0.203885,18.631138,0.949115,2.038847,-66.676949,0.204934,0.000000
141.630005,4.337395,-66.810387,0.021428,0.008065,0.204846,19.293695,0.982868,2.048461,-66.810387,0.205948,0.000000
142.240005,4.455811,-66.765907,0.021445,0.008107,0.205930,19.820435,1.009701,2.059301,-66.765907,0.206972,0.000000
142.850006,4.652794,-66.676949,0.021471,0.008147,0.206937,20.696661,1.054338,2.069369,-66.676949,0.207986,0.000000
143.460007,4.764511,-66.721428,0.021484,0.008178,0.207717,21.193604,1.079654,2.077166,-66.721428,0.209000,0.000000
144.070007,4.904892,-66.676949,0.021540,0.008221,0.208819,21.818048,1.111465,2.088187,-66.676949,0.210015,0.000000
144.680008,5.103371,-66.721428,0.021575,0.008268,0.210007,22.700926,1.156440,2.100072,-66.721428,0.211038,0.000000
145.290009,5.197952,-66.676949,0.021627,0.008299,0.210787,23.121647,1.177873,2.107869,-66.676949,0.212054,0.000000
145.900009,5.416534,-66.765907,0.021683,0.008344,0.211940,24.093948,1.227404,2.119405,-66.765907,0.213068,0.000000
146.510010,5.610168,-66.721428,0.021687,0.008386,0.213008,24.955276,1.271282,2.130078,-66.721428,0.214083,0.000000
147.120010,5.787415,-66.721428,0.021756,0.008423,0.213936,25.743706,1.311447,2.139359,-66.721428,0.215097,0.000000
147.730011,6.049942,-66.765907,0.021773,0.008472,0.215183,26.911486,1.370936,2.151834,-66.765907,0.216121,0.000000
148.340012,6.085312,-66.676949,0.021838,0.008502,0.215946,27.068819,1.378951,2.159464,-66.676949,0.217135,0.000000
148.950012,6.306877,-66.765907,0.021872,0.008542,0.216970,28.054390,1.429159,2.169699,-66.765907,0.218149,0.000000
149.560013,6.661003,-66.676949,0.021928,0.008591,0.218211,29.629622,1.509405,2.182113,-66.676949,0.219165,0.000000
150.170013,6.786118,-66.721428,0.021967,0.008626,0.219112,30.186159,1.537756,2.191121,-66.721428,0.220189,0.000000
150.780014,6.936188,-66.721428,0.021997,0.008663,0.220031,30.853704,1.571763,2.200311,-66.721428,0.221203,0.000000
151.390015,7.286591,-66.721428,0.022049,0.008707,0.221168,32.412373,1.651165,2.211681,-66.721428,0.222217,0.000000
152.000000,7.384148,-66.765907,0.022084,0.008743,0.222070,32.846329,1.673272,2.220704,-66.765907,0.223232,0.000000
152.610001,7.653748,-66.676949,0.022118,0.008787,0.223180,34.045570,1.734364,2.231801,-66.676949,0.224255,0.000000
153.220001,7.926323,-66.676949,0.022178,0.008827,0.224211,35.258045,1.796131,2.242111,-66.676949,0.225269,0.000000
153.830002,8.124428,-66.676949,0.022209,0.008867,0.225218,36.139259,1.841022,2.252179,-66.676949,0.226284,0.000000
154.440002,8.303535,-66.632462,0.022247,0.008908,0.226267,36.935970,1.881608,2.262671,-66.632462,0.227300,0.000000
155.050003,8.595474,-66.721428,0.022291,0.008947,0.227247,38.234577,1.947762,2.272466,-66.721428,0.228323,0.000000
155.660004,8.763420,-66.676949,0.022338,0.008988,0.228305,38.981640,1.985819,2.283049,-66.676949,0.229337,0.000000
156.270004,9.037483,-66.721428,0.022385,0.009025,0.229224,40.200733,2.047923,2.292238,-66.721428,0.230352,0.000000
156.880005,9.196114,-66.721428,0.022407,0.009057,0.230057,40.906357,2.083869,2.300565,-66.721428,0.231366,0.000000
157.490005,9.530128,-66.676949,0.022437,0.009109,0.231375,42.392128,2.159558,2.313752,-66.676949,0.232390,0.000000
158.100006,9.695465,-66.721428,0.022489,0.009146,0.232320,43.127583,2.197024,2.323199,-66.721428,0.233404,0.000000
158.710007,9.977348,-66.676949,0.022528,0.009183,0.233240,44.381462,2.260899,2.332404,-66.676949,0.234420,0.000000
159.320007,10.339668,-66.676949,0.022566,0.009228,0.234402,45.993141,2.343002,2.344016,-66.676949,0.235434,0.000000
159.930008,10.448402,-66.676949,0.022644,0.009261,0.235234,46.476814,2.367642,2.352343,-66.676949,0.236458,0.000000
160.540009,10.837158,-66.676949,0.022683,0.009308,0.236423,48.206089,2.455735,2.364227,-66.676949,0.237472,0.000000
161.150009,11.120537,-66.676949,0.022704,0.009348,0.237428,49.466618,2.519949,2.374280,-66.676949,0.238486,0.000000
161.760010,11.247513,-66.721428,0.022752,0.009385,0.238391,50.031437,2.548723,2.383909,-66.721428,0.239501,0.000000
162.370010,11.578926,-66.676949,0.022773,0.009427,0.239449,51.505634,2.623822,2.394491,-66.676949,0.240515,0.000000
162.980011,11.866028,-66.676949,0.022812,0.009466,0.240438,52.782726,2.688880,2.404377,-66.676949,0.241538,0.000000
163.590012,12.092430,-66.721428,0.022860,0.009508,0.241513,53.789814,2.740184,2.415126,-66.721428,0.242554,0.000000
164.200012,12.449905,-66.632462,0.022911,0.009548,0.242510,55.379944,2.821189,2.425103,-66.632462,0.243569,0.000000
164.810013,12.563103,-66.721428,0.022937,0.009580,0.243334,55.883472,2.846840,2.433339,-66.721428,0.244583,0.000000
165.420013,12.806641,-66.676949,0.022972,0.009620,0.244357,56.966782,2.902026,2.443574,-66.676949,0.245606,0.000000
166.030014,13.188690,-66.632462,0.023041,0.009668,0.245562,58.666225,2.988600,2.455625,-66.632462,0.246621,0.000000
166.640015,13.451584,-66.721428,0.023067,0.009701,0.246413,59.835632,3.048172,2.464133,-66.721428,0.247635,0.000000
167.250015,13.698097,-66.587982,0.023092,0.009745,0.247523,60.932178,3.104033,2.475230,-66.587982,0.248651,0.000000
167.860001,13.958755,-66.721428,0.023131,0.009786,0.248572,62.091644,3.163099,2.485722,-66.721428,0.249673,0.000000
168.470001,14.197449,-66.632462,0.023166,0.009821,0.249456,63.153404,3.217188,2.494564,-66.632462,0.250689,0.000000
169.080002,14.599236,-66.632462,0.023226,0.009870,0.250705,64.940643,3.308234,2.507054,-66.632462,0.251703,0.000000
169.690002,14.687119,-66.676949,0.023261,0.009904,0.251573,65.331566,3.328149,2.515729,-66.676949,0.252717,0.000000
170.300003,14.970863,-66.632462,0.023291,0.009942,0.252518,66.593727,3.392446,2.525176,-66.632462,0.253741,0.000000
170.910004,15.435959,-66.721428,0.023360,0.009990,0.253750,68.662575,3.497838,2.537500,-66.721428,0.254755,0.000000
171.520004,15.615067,-66.632462,0.023399,0.010026,0.254660,69.459282,3.538425,2.546598,-66.632462,0.255770,0.000000
172.130005,15.806099,-66.676949,0.023442,0.010062,0.255579,70.309036,3.581713,2.555788,-66.676949,0.256785,0.000000
172.740005,16.339333,-66.587982,0.023481,0.010110,0.256785,72.680984,3.702546,2.567854,-66.587982,0.257809,0.000000
173.350006,16.418648,-66.632462,0.023532,0.010145,0.257679,73.033791,3.720519,2.576787,-66.632462,0.258823,0.000000
173.960007,16.791023,-66.676949,0.023519,0.010188,0.258763,74.690201,3.804900,2.587627,-66.676949,0.259838,0.000000
174.570007,17.091530,-66.587982,0.023571,0.010230,0.259854,76.026924,3.872996,2.598542,-66.587982,0.260852,0.000000
175.180008,17.311600,-66.676949,0.023593,0.010267,0.260775,77.005844,3.922865,2.607747,-66.676949,0.261875,0.000000
175.790009,17.552521,-66.632462,0.023640,0.010307,0.261806,78.077515,3.977458,2.618057,-66.632462,0.262890,0.000000
176.400009,17.880585,-66.632462,0.023709,0.010345,0.262760,79.536812,4.051798,2.627595,-66.632462,0.263904,0.000000
177.010010,18.113319,-66.587982,0.023726,0.010387,0.263827,80.572067,4.104537,2.638269,-66.587982,0.264920,0.000000
177.620010,18.457390,-66.587982,0.023769,0.010423,0.264737,82.102570,4.182505,2.647367,-66.587982,0.265934,0.000000
178.230011,18.702042,-66.632462,0.023769,0.010460,0.265674,83.190834,4.237943,2.656739,-66.632462,0.266958,0.000000
178.840012,19.053185,-66.587982,0.023847,0.010508,0.266897,84.752800,4.317513,2.668972,-66.587982,0.267972,0.000000
179.450012,19.185379,-66.632462,0.023877,0.010540,0.267721,85.340828,4.347469,2.677208,-66.632462,0.268986,0.000000
180.060013,19.612114,-66.543503,0.023903,0.010583,0.268805,87.239037,4.444169,2.688048,-66.543503,0.270001,0.000000
180.670013,20.050026,-66.632462,0.023959,0.010630,0.270001,89.186966,4.543401,2.700008,-66.632462,0.271024,0.000000
181.280014,20.119286,-66.632462,0.023994,0.010662,0.270817,89.495049,4.559095,2.708168,-66.632462,0.272039,0.000000
181.890015,20.607468,-66.587982,0.024045,0.010706,0.271943,91.666595,4.669719,2.719432,-66.587982,0.273054,0.000000
182.500015,20.912071,-66.632462,0.024067,0.010747,0.272976,93.021538,4.738743,2.729757,-66.632462,0.274069,0.000000
183.110016,21.102348,-66.587982,0.024101,0.010785,0.273948,93.867935,4.781860,2.739477,-66.587982,0.275092,0.000000
183.720001,21.510101,-66.587982,0.024157,0.010826,0.274988,95.681709,4.874259,2.749878,-66.587982,0.276107,0.000000
184.330002,21.815819,-66.587982,0.024218,0.010865,0.275960,97.041611,4.943535,2.759597,-66.587982,0.277121,0.000000
184.940002,22.155045,-66.587982,0.024231,0.010909,0.277095,98.550560,5.020405,2.770952,-66.587982,0.278135,0.000000
185.550003,22.527794,-66.587982,0.024261,0.010947,0.278058,100.208633,5.104871,2.780581,-66.587982,0.279159,0.000000
186.160004,22.768715,-66.587982,0.024304,0.010982,0.278942,101.280304,5.159465,2.789422,-66.587982,0.280175,0.000000
186.770004,23.073692,-66.632462,0.024356,0.011025,0.280035,102.636909,5.228574,2.800353,-66.632462,0.281189,0.000000
187.380005,23.535057,-66.587982,0.024395,0.011069,0.281163,104.689163,5.333120,2.811632,-66.587982,0.282203,0.000000
187.990005,23.826256,-66.587982,0.024407,0.011104,0.282038,105.984482,5.399107,2.820383,-66.587982,0.283227,0.000000
188.600006,24.118942,-66.543503,0.024464,0.011148,0.283166,107.286415,5.465430,2.831662,-66.543503,0.284241,0.000000
189.210007,24.581802,-66.543503,0.024524,0.011191,0.284259,109.345322,5.570316,2.842592,-66.543503,0.285255,0.000000
189.820007,24.814903,-66.587982,0.024520,0.011226,0.285152,110.382202,5.623137,2.851525,-66.587982,0.286270,0.000000
190.430008,25.201797,-66.587982,0.024610,0.011269,0.286244,112.103195,5.710809,2.862440,-66.587982,0.287293,0.000000
191.040009,25.339203,-66.632462,0.024597,0.011304,0.287112,112.714401,5.741946,2.871115,-66.632462,0.288309,0.000000
191.650009,25.633751,-66.587982,0.024653,0.011341,0.288056,114.024620,5.808691,2.880563,-66.587982,0.289323,0.000000
192.260010,26.280563,-66.587982,0.024696,0.011390,0.289305,116.901787,5.955261,2.893053,-66.587982,0.290338,0.000000
192.870010,26.442543,-66.543503,0.024722,0.011425,0.290191,117.622307,5.991966,2.901909,-66.543503,0.291352,0.000000
193.480011,26.744164,-66.543503,0.024748,0.011464,0.291187,118.963982,6.060314,2.911871,-66.543503,0.292376,0.000000
194.090012,27.449066,-66.543503,0.024804,0.011510,0.292366,122.099541,6.220047,2.923665,-66.543503,0.293390,0.000000
194.700012,27.482956,-66.543503,0.024826,0.011545,0.293243,122.250290,6.227727,2.932431,-66.543503,0.294406,0.000000
195.310013,27.968155,-66.543503,0.024860,0.011587,0.294301,124.408569,6.337675,2.943013,-66.543503,0.295420,0.000000
195.920013,28.543098,-66.499023,0.024934,0.011633,0.295472,126.966042,6.467958,2.954716,-66.499023,0.296444,0.000000
196.530014,28.729652,-66.499023,0.024916,0.011670,0.296425,127.795876,6.510232,2.964254,-66.499023,0.297458,0.000000
197.140015,29.006332,-66.543503,0.024968,0.011707,0.297353,129.026611,6.572929,2.973535,-66.543503,0.298472,0.000000
197.750015,29.486687,-66.499023,0.024998,0.011748,0.298394,131.163330,6.681779,2.983936,-66.499023,0.299487,0.000000
198.360016,29.768204,-66.543503,0.025024,0.011787,0.299384,132.415588,6.745571,2.993837,-66.543503,0.300510,0.000000
198.970016,30.130524,-66.499023,0.025054,0.011822,0.300284,134.027267,6.827674,3.002845,-66.499023,0.301524,0.000000
199.580017,30.531563,-66.587982,0.025089,0.011862,0.301291,135.811172,6.918551,3.012913,-66.587982,0.302540,0.000000
200.190002,31.036873,-66.454544,0.025171,0.011907,0.302436,138.058899,7.033056,3.024358,-66.454544,0.303555,0.000000
200.800003,31.200348,-66.454544,0.025192,0.011939,0.303243,138.786072,7.070100,3.032428,-66.454544,0.304578,0.000000
201.410004,31.758537,-66.454544,0.025209,0.011982,0.304334,141.269028,7.196587,3.043343,-66.454544,0.305592,0.000000
202.020004,32.436996,-66.499023,0.025274,0.012030,0.305567,144.286972,7.350328,3.055667,-66.499023,0.306607,0.000000
202.630005,32.472374,-66.499023,0.025300,0.012063,0.306390,144.444336,7.358345,3.063903,-66.499023,0.307621,0.000000
203.240005,33.117317,-66.454544,0.025347,0.012106,0.307483,147.313187,7.504491,3.074834,-66.454544,0.308645,0.000000
203.850006,33.707901,-66.499023,0.025391,0.012150,0.308619,149.940231,7.638320,3.086188,-66.499023,0.309659,0.000000
204.460007,33.870628,-66.454544,0.025403,0.012185,0.309503,150.664078,7.675194,3.095030,-66.454544,0.310675,0.000000
205.070007,34.371101,-66.499023,0.025447,0.012228,0.310579,152.890289,7.788603,3.105794,-66.499023,0.311689,0.000000
205.680008,35.097969,-66.499023,0.025477,0.012272,0.311715,156.123566,7.953313,3.117149,-66.499023,0.312713,0.000000
206.290009,35.331818,-66.454544,0.025520,0.012308,0.312625,157.163773,8.006305,3.126248,-66.454544,0.313727,0.000000
206.900009,35.853142,-66.454544,0.025537,0.012348,0.313632,159.482742,8.124438,3.136315,-66.454544,0.314741,0.000000
207.510010,36.123482,-66.410057,0.025585,0.012381,0.314473,160.685272,8.185698,3.144733,-66.410057,0.315756,0.000000
208.120010,36.568100,-66.454544,0.025602,0.012425,0.315583,162.663040,8.286449,3.155830,-66.454544,0.316771,0.000000
208.730011,37.304276,-66.454544,0.025658,0.012469,0.316718,165.937698,8.453269,3.167185,-66.454544,0.317793,0.000000
209.340012,37.688568,-66.499023,0.025697,0.012503,0.317569,167.647125,8.540351,3.175694,-66.499023,0.318809,0.000000
209.950012,38.223289,-66.499023,0.025718,0.012548,0.318731,170.025681,8.661521,3.187305,-66.499023,0.319824,0.000000
210.560013,38.755043,-66.454544,0.025809,0.012590,0.319780,172.391037,8.782019,3.197797,-66.454544,0.320838,0.000000
211.170013,39.134857,-66.499023,0.025804,0.012625,0.320673,174.080536,8.868086,3.206730,-66.499023,0.321861,0.000000
211.780014,39.700119,-66.365578,0.025848,0.012669,0.321783,176.594955,8.996176,3.217827,-66.365578,0.322876,0.000000
212.390015,39.930992,-66.499023,0.025852,0.012706,0.322720,177.621918,9.048491,3.227198,-66.499023,0.323890,0.000000
213.000015,40.344696,-66.410057,0.025929,0.012739,0.323578,179.462173,9.142240,3.235782,-66.410057,0.324906,0.000000
213.610016,41.326271,-66.410057,0.025998,0.012788,0.324827,183.828430,9.364667,3.248273,-66.410057,0.325929,0.000000
214.220016,41.586189,-66.454544,0.026011,0.012824,0.325720,184.984604,9.423566,3.257205,-66.454544,0.326944,0.000000
214.830017,42.103783,-66.410057,0.026059,0.012864,0.326735,187.286972,9.540854,3.267349,-66.410057,0.327958,0.000000
215.440018,43.003807,-66.543503,0.026063,0.012909,0.327898,191.290482,9.744802,3.278976,-66.543503,0.328972,0.000000
216.050003,43.257393,-66.365578,0.026106,0.012945,0.328791,192.418488,9.802265,3.287908,-66.365578,0.329996,0.000000
216.660004,43.914261,-66.454544,0.026141,0.012985,0.329831,195.340393,9.951114,3.298309,-66.454544,0.331010,0.000000
217.270004,44.791939,-66.410057,0.026205,0.013031,0.330994,199.244492,10.149999,3.309936,-66.410057,0.332025,0.000000
217.880005,45.187027,-66.365578,0.026236,0.013069,0.331947,201.001938,10.239527,3.319474,-66.365578,0.333040,0.000000
218.490005,45.667763,-66.410057,0.026253,0.013107,0.332910,203.140350,10.348463,3.329103,-66.410057,0.334064,0.000000
219.100006,46.721207,-66.410057,0.026313,0.013153,0.334090,207.826309,10.587176,3.340897,-66.410057,0.335078,0.000000
219.710007,46.908882,-66.365578,0.026330,0.013188,0.334974,208.661133,10.629704,3.349738,-66.365578,0.336093,0.000000
220.320007,47.726982,-66.321098,0.026378,0.013226,0.335937,212.300217,10.815089,3.359367,-66.321098,0.337107,0.000000
220.930008,48.221123,-66.410057,0.026382,0.013260,0.336795,214.498260,10.927062,3.367951,-66.410057,0.338130,0.000000
221.540009,49.169922,-66.365578,0.026425,0.013305,0.337958,218.718735,11.142064,3.379578,-66.365578,0.339145,0.000000
222.150009,49.874825,-66.365578,0.026460,0.013343,0.338912,221.854294,11.301797,3.389116,-66.365578,0.340161,0.000000
222.760010,50.542862,-66.365578,0.026503,0.013381,0.339873,224.825882,11.453176,3.398730,-66.365578,0.341175,0.000000
223.370010,51.799622,-66.321098,0.026537,0.013430,0.341114,230.416229,11.737963,3.411144,-66.321098,0.342189,0.000000
223.980011,52.254662,-66.454544,0.026563,0.013464,0.341989,232.440338,11.841076,3.419895,-66.454544,0.343213,0.000000
224.590012,53.459282,-66.365578,0.026615,0.013504,0.343004,237.798767,12.114046,3.430038,-66.365578,0.344227,0.000000
225.200012,54.691833,-66.365578,0.026624,0.013549,0.344141,243.281433,12.393347,3.441408,-66.365578,0.345241,0.000000
225.810013,55.391899,-66.321098,0.026662,0.013584,0.345025,246.395477,12.551984,3.450250,-66.321098,0.346256,0.000000
226.420013,56.589073,-66.321098,0.026693,0.013626,0.346100,251.720764,12.823268,3.460999,-66.321098,0.347279,0.000000
227.030014,57.568413,-66.365578,0.026701,0.013665,0.347088,256.077087,13.045189,3.470885,-66.365578,0.348295,0.000000
227.640015,59.002419,-66.321098,0.026744,0.013707,0.348147,262.455872,13.370139,3.481467,-66.321098,0.349309,0.000000
228.250015,60.206673,-66.321098,0.026805,0.013745,0.349119,267.812653,13.643027,3.491187,-66.321098,0.350324,0.000000
228.860016,61.257881,-66.321098,0.026822,0.013779,0.349994,272.488678,13.881234,3.499938,-66.321098,0.351347,0.000000
229.470016,62.669540,-66.321098,0.026839,0.013824,0.351122,278.768036,14.201121,3.511217,-66.321098,0.352362,0.000000
230.080017,64.494164,-66.276619,0.026874,0.013868,0.352240,286.884369,14.614587,3.522405,-66.276619,0.353376,0.000000
230.690018,65.720024,-66.321098,0.026900,0.013901,0.353082,292.337280,14.892370,3.530823,-66.321098,0.354390,0.000000
231.300018,67.557304,-66.321098,0.026930,0.013941,0.354104,300.509888,15.308703,3.541042,-66.321098,0.355388,0.000000
231.910004,66.350441,-66.321098,0.026964,0.013931,0.353845,295.141510,15.035225,3.538453,-66.321098,0.353966,0.000000
232.520004,65.679436,-66.365578,0.026947,0.013929,0.353801,292.156708,14.883173,3.538014,-66.365578,0.353966,0.000000
233.130005,65.225502,-66.276619,0.026981,0.013929,0.353785,290.137512,14.780310,3.537847,-66.276619,0.353966,0.000000
233.740005,64.864311,-66.276619,0.026986,0.013928,0.353776,288.530853,14.698462,3.537756,-66.276619,0.353966,0.000000
234.350006,64.578697,-66.276619,0.026947,0.013928,0.353776,287.260406,14.633741,3.537756,-66.276619,0.353966,0.000000
234.960007,64.325859,-66.276619,0.026960,0.013928,0.353767,286.135712,14.576447,3.537666,-66.276619,0.353966,0.000000
235.570007,64.115089,-66.321098,0.026977,0.013928,0.353767,285.198151,14.528687,3.537666,-66.321098,0.353966,0.000000
236.180008,63.933754,-66.232140,0.026960,0.013928,0.353767,284.391541,14.487596,3.537666,-66.232140,0.353966,0.000000
236.790009,63.773628,-66.276619,0.027007,0.013928,0.353767,283.679260,14.451311,3.537666,-66.276619,0.353966,0.000000
237.400009,63.622078,-66.276619,0.026977,0.013928,0.353767,283.005127,14.416969,3.537666,-66.276619,0.353966,0.000000
238.010010,63.481316,-66.321098,0.026973,0.013927,0.353757,282.378998,14.385072,3.537575,-66.321098,0.353966,0.000000
238.620010,63.361046,-66.321098,0.026964,0.013927,0.353757,281.843994,14.357818,3.537575,-66.321098,0.353966,0.000000
239.230011,63.232201,-66.276619,0.026977,0.013927,0.353757,281.270874,14.328622,3.537575,-66.276619,0.353966,0.000000
239.840012,63.128304,-66.276619,0.026990,0.013927,0.353757,280.808716,14.305078,3.537575,-66.276619,0.353966,0.000000
240.450012,63.033722,-66.232140,0.026981,0.013927,0.353757,280.388000,14.283646,3.537575,-66.232140,0.353966,0.000000
241.060013,62.945847,-66.232140,0.026999,0.013927,0.353757,279.997101,14.263733,3.537575,-66.232140,0.353966,0.000000
241.670013,62.866531,-66.187653,0.026964,0.013927,0.353757,279.644287,14.245759,3.537575,-66.187653,0.353966,0.000000
242.280014,62.785355,-66.232140,0.026990,0.013927,0.353750,279.283203,14.227365,3.537499,-66.232140,0.353966,0.000000
242.890015,62.708267,-66.232140,0.026986,0.013927,0.353750,278.940308,14.209896,3.537499,-66.232140,0.353966,0.000000
243.500015,62.636032,-66.187653,0.026994,0.013927,0.353750,278.618988,14.193527,3.537499,-66.187653,0.353966,0.000000
244.110016,62.579803,-66.232140,0.026977,0.013927,0.353750,278.368866,14.180786,3.537499,-66.232140,0.353966,0.000000
244.720016,62.514641,-66.143173,0.026986,0.013927,0.353750,278.079010,14.166020,3.537499,-66.143173,0.353966,0.000000
245.330017,62.442398,-66.276619,0.026964,0.013927,0.353750,277.757660,14.149650,3.537499,-66.276619,0.353966,0.000000
245.940018,62.384682,-66.143173,0.026986,0.013927,0.353750,277.500916,14.136571,3.537499,-66.143173,0.353966,0.000000
246.550018,62.337387,-66.187653,0.026956,0.013927,0.353750,277.290558,14.125854,3.537499,-66.187653,0.353966,0.000000
247.160019,62.281532,-66.187653,0.026973,0.013927,0.353750,277.042084,14.113197,3.537499,-66.187653,0.353966,0.000000
247.770004,62.229774,-66.187653,0.026977,0.013927,0.353750,276.811859,14.101468,3.537499,-66.187653,0.353966,0.000000
248.380005,62.177269,-66.232140,0.026960,0.013927,0.353750,276.578308,14.089571,3.537499,-66.232140,0.353966,0.000000
248.990005,62.133331,-66.098694,0.026986,0.013927,0.353750,276.382874,14.079615,3.537499,-66.098694,0.353966,0.000000
249.600006,62.084549,-66.232140,0.026969,0.013927,0.353750,276.165863,14.068560,3.537499,-66.232140,0.353966,0.000000
250.210007,62.036880,-66.187653,0.026986,0.013927,0.353750,275.953827,14.057758,3.537499,-66.187653,0.353966,0.000000
250.820007,61.995552,-66.187653,0.026999,0.013927,0.353750,275.769989,14.048393,3.537499,-66.187653,0.353966,0.000000
251.430008,61.967247,-66.187653,0.026969,0.013927,0.353750,275.644073,14.041979,3.537499,-66.187653,0.353966,0.000000
252.040009,61.916611,-66.143173,0.026973,0.013927,0.353750,275.418854,14.030505,3.537499,-66.143173,0.353966,0.000000
252.650009,61.884956,-66.143173,0.026990,0.013927,0.353750,275.278046,14.023332,3.537499,-66.143173,0.353966,0.000000
253.260010,61.846970,-66.009735,0.026969,0.013927,0.353750,275.109070,14.014724,3.537499,-66.009735,0.353966,0.000000
253.870010,61.802292,-66.187653,0.026981,0.013927,0.353750,274.910339,14.004600,3.537499,-66.187653,0.353966,0.000000
254.480011,61.768402,-66.143173,0.026999,0.013927,0.353750,274.759583,13.996921,3.537499,-66.143173,0.353966,0.000000
255.090012,61.747551,-66.143173,0.026973,0.013927,0.353750,274.666840,13.992195,3.537499,-66.143173,0.353966,0.000000
255.700012,61.705475,-66.098694,0.027003,0.013927,0.353750,274.479675,13.982660,3.537499,-66.098694,0.353966,0.000000
256.309998,61.668236,-66.098694,0.026973,0.013927,0.353750,274.314026,13.974222,3.537499,-66.098694,0.353966,0.000000
256.920013,61.632484,-66.098694,0.026990,0.013927,0.353750,274.154968,13.966121,3.537499,-66.098694,0.353966,0.000000
257.529999,61.605675,-66.054214,0.026977,0.013927,0.353750,274.035736,13.960046,3.537499,-66.054214,0.353966,0.000000
258.140015,61.580727,-66.054214,0.026973,0.013927,0.353750,273.924744,13.954392,3.537499,-66.054214,0.353966,0.000000
258.750000,61.542747,-66.054214,0.026986,0.013927,0.353750,273.755798,13.945786,3.537499,-66.054214,0.353966,0.000000
259.360016,61.521523,-66.143173,0.026973,0.013927,0.353750,273.661407,13.940976,3.537499,-66.143173,0.353966,0.000000
259.970001,61.490982,-66.098694,0.026951,0.013927,0.353750,273.525543,13.934056,3.537499,-66.098694,0.353966,0.000000
260.580017,61.470879,-66.098694,0.026960,0.013927,0.353750,273.436127,13.929501,3.537499,-66.098694,0.353966,0.000000
261.190002,61.440346,-66.054214,0.026960,0.013927,0.353750,273.300293,13.922582,3.537499,-66.054214,0.353966,0.000000
261.800018,61.419487,-66.098694,0.027003,0.013927,0.353750,273.207520,13.917854,3.537499,-66.098694,0.353966,0.000000