File: Data/New new I18 3 new align_08182023_122823.csv
Time (sec),S:Load (lbs),S:HL1 (DIM),S:LVDT (in),S:Position (in),Ch:Position (mm),Ch:Load (N),Ch:Stress (MPa),Ch:Strain (mm/mm),Ch:HL1 (DIM),Set Point (),Cycles ()
0.110000,-0.001488,-64.363937,0.000030,-0.000000,-0.000000,-0.006618,-0.000337,-0.000000,-64.363937,0.000077,0.000000
0.500000,-0.033882,-64.274971,0.000026,0.000055,0.001405,-0.150715,-0.007678,0.014050,-64.274971,0.001985,0.000000
0.890000,0.011177,-64.319458,0.000017,0.000294,0.007474,0.049718,0.002533,0.074744,-64.319458,0.008490,0.000000
1.280000,0.023834,-64.363937,0.000250,0.000549,0.013953,0.106020,0.005401,0.139526,-64.363937,0.014994,0.000000
1.670000,-0.002602,-64.319458,0.000474,0.000803,0.020396,-0.011573,-0.000590,0.203960,-64.319458,0.021480,0.000000
2.060000,-0.021965,-64.363937,0.000742,0.001061,0.026962,-0.097705,-0.004977,0.269621,-64.363937,0.027986,0.000000
2.450000,0.017136,-64.363937,0.001018,0.001315,0.033396,0.076223,0.003883,0.333964,-64.363937,0.034471,0.000000
2.840000,0.013412,-64.408417,0.001302,0.001569,0.039849,0.059662,0.003039,0.398489,-64.408417,0.040975,0.000000
3.230000,0.043945,-64.363937,0.001578,0.001824,0.046335,0.195479,0.009958,0.463347,-64.363937,0.047481,0.000000
3.620000,0.025696,-64.363937,0.001798,0.002081,0.052857,0.114301,0.005823,0.528568,-64.363937,0.053967,0.000000
4.010000,-0.026062,-64.452896,0.002087,0.002339,0.059421,-0.115930,-0.005906,0.594213,-64.452896,0.060471,0.000000
4.400000,-0.019730,-64.408417,0.002358,0.002594,0.065900,-0.087762,-0.004471,0.658996,-64.408417,0.066958,0.000000
4.790000,0.026070,-64.452896,0.002587,0.002846,0.072301,0.115964,0.005907,0.723006,-64.452896,0.073462,0.000000
5.180000,0.021599,-64.452896,0.002893,0.003105,0.078856,0.096076,0.004894,0.788560,-64.452896,0.079966,0.000000
5.570000,0.032776,-64.452896,0.003156,0.003360,0.085352,0.145794,0.007427,0.853524,-64.452896,0.086453,0.000000
5.960001,0.001862,-64.452896,0.003419,0.003616,0.091838,0.008281,0.000422,0.918382,-64.452896,0.092957,0.000000
6.350000,-0.027550,-64.497375,0.003673,0.003871,0.098335,-0.122547,-0.006243,0.983346,-64.497375,0.099444,0.000000
6.740000,0.039848,-64.452896,0.003902,0.004126,0.104804,0.177254,0.009030,1.048037,-64.452896,0.105948,0.000000
7.130000,0.024208,-64.541862,0.004208,0.004381,0.111282,0.107683,0.005486,1.112820,-64.541862,0.112452,0.000000
7.520000,0.062187,-64.541862,0.004493,0.004634,0.117716,0.276622,0.014092,1.177163,-64.541862,0.118940,0.000000
7.910000,0.042824,-64.541862,0.004704,0.004891,0.124229,0.190490,0.009704,1.242293,-64.541862,0.125444,0.000000
8.300000,0.004845,-64.541862,0.004997,0.005146,0.130717,0.021550,0.001098,1.307166,-64.541862,0.131931,0.000000
8.690001,-0.004837,-64.497375,0.005277,0.005407,0.137334,-0.021516,-0.001096,1.373342,-64.497375,0.138435,0.000000
9.080001,0.053627,-64.586342,0.005523,0.005660,0.143759,0.238545,0.012152,1.437594,-64.586342,0.144939,0.000000
9.470000,0.058838,-64.497375,0.005760,0.005917,0.150282,0.261724,0.013333,1.502815,-64.497375,0.151426,0.000000
9.860001,0.043198,-64.497375,0.006058,0.006177,0.156898,0.192153,0.009789,1.568975,-64.497375,0.157930,0.000000
10.250001,0.026443,-64.586342,0.006334,0.006429,0.163306,0.117626,0.005992,1.633061,-64.586342,0.164417,0.000000
10.640000,-0.008186,-64.497375,0.006579,0.006683,0.169751,-0.036415,-0.001855,1.697510,-64.497375,0.170921,0.000000
11.030001,0.045433,-64.586342,0.006855,0.006942,0.176316,0.202096,0.010295,1.763155,-64.586342,0.177425,0.000000
11.420000,0.046547,-64.541862,0.007131,0.007198,0.182820,0.207051,0.010548,1.828195,-64.541862,0.183913,0.000000
11.810000,0.060326,-64.586342,0.007394,0.007453,0.189298,0.268342,0.013670,1.892977,-64.586342,0.190417,0.000000
12.200001,0.045059,-64.675301,0.007644,0.007704,0.195690,0.200433,0.010211,1.956897,-64.675301,0.196904,0.000000
12.590000,0.042458,-64.541862,0.007933,0.007963,0.202254,0.188861,0.009621,2.022542,-64.541862,0.203408,0.000000
12.980000,0.058090,-64.541862,0.008205,0.008218,0.208732,0.258398,0.013163,2.087324,-64.541862,0.209912,0.000000
13.370001,0.050270,-64.586342,0.008464,0.008477,0.215306,0.223612,0.011391,2.153060,-64.586342,0.216399,0.000000
13.760000,0.057724,-64.586342,0.008714,0.008732,0.221792,0.256769,0.013080,2.217918,-64.586342,0.222903,0.000000
14.150001,0.045059,-64.630821,0.009015,0.008986,0.228244,0.200433,0.010211,2.282443,-64.630821,0.229389,0.000000
14.540001,0.058464,-64.630821,0.009265,0.009245,0.234818,0.260061,0.013248,2.348179,-64.630821,0.235894,0.000000
14.930000,0.053627,-64.675301,0.009528,0.009499,0.241279,0.238545,0.012152,2.412795,-64.675301,0.242398,0.000000
15.320001,0.069633,-64.675301,0.009791,0.009755,0.247765,0.309745,0.015779,2.477653,-64.675301,0.248884,0.000000
15.710001,0.059586,-64.586342,0.010063,0.010012,0.254296,0.265050,0.013502,2.542965,-64.586342,0.255390,0.000000
16.100000,0.086395,-64.630821,0.010348,0.010265,0.260731,0.384305,0.019577,2.607308,-64.630821,0.261894,0.000000
16.490002,0.063309,-64.630821,0.010611,0.010522,0.267270,0.281611,0.014346,2.672696,-64.630821,0.268379,0.000000
16.880001,0.056976,-64.630821,0.010895,0.010777,0.273748,0.253443,0.012911,2.737478,-64.630821,0.274885,0.000000
17.270000,0.072617,-64.630821,0.011141,0.011032,0.280217,0.323015,0.016455,2.802170,-64.630821,0.281371,0.000000
17.660002,0.071869,-64.586342,0.011417,0.011286,0.286660,0.319689,0.016286,2.866604,-64.586342,0.287875,0.000000
18.050001,0.076714,-64.675301,0.011658,0.011541,0.293139,0.341239,0.017384,2.931386,-64.675301,0.294380,0.000000
18.440001,0.058464,-64.586342,0.011926,0.011794,0.299574,0.260061,0.013248,2.995744,-64.586342,0.300866,0.000000
18.830002,0.066658,-64.675301,0.012206,0.012055,0.306190,0.296510,0.015105,3.061904,-64.675301,0.307370,0.000000
19.220001,0.067032,-64.675301,0.012460,0.012311,0.312687,0.298173,0.015190,3.126868,-64.675301,0.313857,0.000000
19.610001,0.097565,-64.675301,0.012710,0.012561,0.319044,0.433989,0.022108,3.190439,-64.675301,0.320361,0.000000
20.000000,0.111717,-64.675301,0.012969,0.012819,0.325608,0.496943,0.025315,3.256085,-64.675301,0.326865,0.000000
20.390001,0.215981,-64.719788,0.013210,0.013076,0.332129,0.960729,0.048942,3.321291,-64.719788,0.333352,0.000000
20.780001,0.463234,-64.630821,0.013508,0.013332,0.338635,2.060568,0.104970,3.386346,-64.630821,0.339856,0.000000
21.170000,0.423393,-64.719788,0.013706,0.013588,0.345129,1.883347,0.095942,3.451294,-64.719788,0.346344,0.000000
21.560001,0.402534,-64.675301,0.013918,0.013840,0.351547,1.790563,0.091216,3.515471,-64.675301,0.352848,0.000000
21.950001,0.399933,-64.764267,0.014133,0.014099,0.358121,1.778990,0.090626,3.581207,-64.764267,0.359352,0.000000
22.340000,0.352638,-64.675301,0.014370,0.014351,0.364520,1.568613,0.079909,3.645202,-64.675301,0.365839,0.000000
22.730001,0.328812,-64.675301,0.014629,0.014612,0.371147,1.462627,0.074510,3.711468,-64.675301,0.372343,0.000000
23.120001,0.289337,-64.719788,0.014888,0.014864,0.377546,1.287036,0.065565,3.775463,-64.719788,0.378830,0.000000
23.510000,0.281143,-64.719788,0.015164,0.015122,0.384102,1.250587,0.063708,3.841017,-64.719788,0.385334,0.000000
23.900002,0.295296,-64.719788,0.015440,0.015374,0.390503,1.313541,0.066915,3.905028,-64.719788,0.391838,0.000000
24.290001,0.255447,-64.675301,0.015715,0.015631,0.397032,1.136287,0.057885,3.970325,-64.675301,0.398325,0.000000
24.680000,0.237579,-64.719788,0.015970,0.015892,0.403659,1.056806,0.053836,4.036591,-64.719788,0.404829,0.000000
25.070002,0.223427,-64.719788,0.016229,0.016146,0.410110,0.993852,0.050629,4.101100,-64.719788,0.411317,0.000000
25.460001,0.148582,-64.675301,0.016569,0.016402,0.416623,0.660928,0.033669,4.166231,-64.675301,0.417821,0.000000
25.850000,0.091606,-64.675301,0.016974,0.016656,0.423066,0.407484,0.020758,4.230665,-64.675301,0.424325,0.000000
26.240002,0.127724,-64.764267,0.017233,0.016919,0.429745,0.568143,0.028943,4.297445,-64.764267,0.430812,0.000000
26.630001,0.104637,-64.675301,0.017462,0.017167,0.436041,0.465449,0.023711,4.360411,-64.675301,0.437316,0.000000
27.020000,0.093094,-64.675301,0.017755,0.017428,0.442675,0.414102,0.021095,4.426753,-64.675301,0.443802,0.000000
27.410002,0.090492,-64.675301,0.018035,0.017684,0.449170,0.402530,0.020506,4.491702,-64.675301,0.450307,0.000000
27.800001,0.093094,-64.764267,0.018281,0.017940,0.455683,0.414102,0.021095,4.556832,-64.764267,0.456811,0.000000
28.190001,0.120651,-64.764267,0.018557,0.018195,0.462161,0.536684,0.027340,4.621614,-64.764267,0.463297,0.000000
28.580002,0.125862,-64.719788,0.018811,0.018449,0.468614,0.559863,0.028521,4.686139,-64.719788,0.469802,0.000000
28.970001,0.143364,-64.719788,0.019048,0.018710,0.475239,0.637715,0.032487,4.752390,-64.719788,0.476288,0.000000
29.360001,0.173531,-64.764267,0.019294,0.018968,0.481796,0.771903,0.039323,4.817959,-64.764267,0.482792,0.000000
29.750002,0.268112,-64.719788,0.019505,0.019221,0.488221,1.192623,0.060755,4.882212,-64.719788,0.489298,0.000000
30.140001,0.508667,-64.764267,0.019725,0.019474,0.494648,2.262664,0.115266,4.946479,-64.764267,0.495783,0.000000
30.530001,0.620003,-64.764267,0.019876,0.000016,0.000407,2.757910,0.140495,0.004073,-64.764267,0.000607,0.000000
30.920002,0.572716,-64.764267,0.019885,0.000016,0.000407,2.547567,0.129779,0.004073,-64.764267,0.000728,0.000000
31.310001,0.617393,-64.764267,0.019876,0.000016,0.000416,2.746303,0.139903,0.004163,-64.764267,0.001378,0.000000
31.700001,0.662453,-64.675301,0.019906,0.000042,0.001066,2.946737,0.150114,0.010658,-64.675301,0.002029,0.000000
32.090000,0.723152,-64.764267,0.019893,0.000068,0.001733,3.216742,0.163869,0.017335,-64.764267,0.002680,0.000000
32.480003,0.775284,-64.764267,0.019936,0.000092,0.002331,3.448635,0.175682,0.023315,-64.764267,0.003329,0.000000
32.870003,0.875076,-64.719788,0.019941,0.000119,0.003026,3.892534,0.198295,0.030264,-64.719788,0.003980,0.000000
33.260002,0.927582,-64.764267,0.019954,0.000150,0.003806,4.126090,0.210193,0.038061,-64.764267,0.004630,0.000000
33.650002,0.918274,-64.764267,0.019997,0.000169,0.004283,4.084686,0.208084,0.042830,-64.764267,0.005281,0.000000
34.040001,0.959976,-64.764267,0.020005,0.000193,0.004899,4.270187,0.217534,0.048992,-64.764267,0.005932,0.000000
34.430000,1.056793,-64.764267,0.020044,0.000222,0.005636,4.700851,0.239473,0.056365,-64.764267,0.006581,0.000000
34.820004,1.117493,-64.764267,0.020066,0.000239,0.006062,4.970856,0.253227,0.060619,-64.764267,0.007232,0.000000
35.210003,1.229202,-64.764267,0.020092,0.000272,0.006920,5.467765,0.278541,0.069203,-64.764267,0.007883,0.000000
35.600002,1.241867,-64.764267,0.020113,0.000296,0.007518,5.524101,0.281411,0.075183,-64.764267,0.008533,0.000000
35.990002,1.318199,-64.764267,0.020135,0.000316,0.008030,5.863643,0.298708,0.080300,-64.764267,0.009184,0.000000
36.380001,1.409431,-64.808746,0.020165,0.000346,0.008784,6.269464,0.319382,0.087840,-64.808746,0.009833,0.000000
36.770000,1.443695,-64.764267,0.020178,0.000363,0.009209,6.421876,0.327146,0.092094,-64.764267,0.010484,0.000000
37.160004,1.627640,-64.808746,0.020208,0.000403,0.010224,7.240103,0.368828,0.102238,-64.808746,0.011135,0.000000
37.550003,1.683502,-64.764267,0.020243,0.000422,0.010726,7.488592,0.381487,0.107264,-64.764267,0.011777,0.000000
37.940002,1.792229,-64.764267,0.020264,0.000446,0.011326,7.972231,0.406125,0.113259,-64.764267,0.012427,0.000000
38.330002,1.866333,-64.764267,0.020277,0.000469,0.011924,8.301864,0.422917,0.119239,-64.764267,0.013078,0.000000
38.720001,2.006721,-64.764267,0.020290,0.000499,0.012678,8.926343,0.454730,0.126779,-64.764267,0.013727,0.000000
39.110001,2.133698,-64.764267,0.020333,0.000528,0.013406,9.491160,0.483503,0.134061,-64.764267,0.014378,0.000000
39.500000,2.207054,-64.808746,0.020346,0.000552,0.014013,9.817467,0.500126,0.140132,-64.808746,0.015029,0.000000
39.890003,2.369034,-64.719788,0.020398,0.000580,0.014734,10.537989,0.536831,0.147338,-64.719788,0.015679,0.000000
40.280003,2.426384,-64.808746,0.020393,0.000599,0.015211,10.793095,0.549827,0.152107,-64.808746,0.016330,0.000000
40.670002,2.534370,-64.764267,0.020432,0.000616,0.015653,11.273442,0.574297,0.156528,-64.764267,0.016979,0.000000
41.060001,2.773430,-64.808746,0.020450,0.000658,0.016720,12.336832,0.628468,0.167202,-64.808746,0.017630,0.000000
41.450001,2.816254,-64.764267,0.020475,0.000677,0.017205,12.527322,0.638172,0.172046,-64.764267,0.018281,0.000000
41.840000,2.951431,-64.764267,0.020510,0.000698,0.017735,13.128622,0.668804,0.177345,-64.764267,0.018931,0.000000
42.230003,3.101494,-64.764267,0.020519,0.000730,0.018532,13.796134,0.702809,0.185324,-64.764267,0.019582,0.000000
42.620003,3.198685,-64.808746,0.020570,0.000747,0.018984,14.228460,0.724832,0.189835,-64.808746,0.020231,0.000000
43.010002,3.448547,-64.764267,0.020570,0.000787,0.019989,15.339905,0.781452,0.199888,-64.764267,0.020882,0.000000
43.400002,3.498070,-64.764267,0.020596,0.000806,0.020484,15.560191,0.792674,0.204839,-64.764267,0.021533,0.000000
43.790001,3.607178,-64.719788,0.020631,0.000827,0.020996,16.045528,0.817398,0.209956,-64.719788,0.022183,0.000000
44.180000,3.841766,-64.808746,0.020656,0.000860,0.021836,17.089029,0.870557,0.218358,-64.808746,0.022834,0.000000
44.570004,3.890549,-64.764267,0.020665,0.000875,0.022217,17.306025,0.881611,0.222173,-64.764267,0.023485,0.000000
44.960003,4.099449,-64.764267,0.020721,0.000913,0.023180,18.235260,0.928948,0.231802,-64.764267,0.024134,0.000000
45.350002,4.136314,-64.853226,0.020725,0.000934,0.023718,18.399246,0.937302,0.237177,-64.853226,0.024785,0.000000
45.740002,4.212280,-64.764267,0.020747,0.000953,0.024195,18.737158,0.954516,0.241946,-64.764267,0.025434,0.000000
46.130001,4.478157,-64.764267,0.020790,0.000983,0.024958,19.919838,1.014765,0.249576,-64.764267,0.026085,0.000000
46.520000,4.558212,-64.808746,0.020777,0.001004,0.025504,20.275940,1.032906,0.255041,-64.808746,0.026727,0.000000
46.910004,4.741051,-64.808746,0.020833,0.001037,0.026337,21.089247,1.074337,0.263368,-64.808746,0.027378,0.000000
47.300003,4.797279,-64.808746,0.020868,0.001064,0.027023,21.339365,1.087079,0.270226,-64.808746,0.028028,0.000000
47.690002,4.832283,-64.808746,0.020863,0.001083,0.027500,21.495068,1.095011,0.274995,-64.808746,0.028679,0.000000
48.080002,5.089966,-64.808746,0.020924,0.001112,0.028253,22.641298,1.153403,0.282535,-64.808746,0.029328,0.000000
48.470001,5.213966,-64.853226,0.020937,0.001138,0.028904,23.192881,1.181502,0.289045,-64.853226,0.029979,0.000000
48.860001,5.397545,-64.764267,0.020967,0.001167,0.029649,24.009480,1.223101,0.296494,-64.764267,0.030630,0.000000
49.250004,5.453773,-64.764267,0.020980,0.001194,0.030317,24.259596,1.235843,0.303170,-64.764267,0.031280,0.000000
49.640003,5.503296,-64.853226,0.021010,0.001214,0.030838,24.479883,1.247065,0.308378,-64.853226,0.031931,0.000000
50.030003,5.708847,-64.764267,0.021036,0.001240,0.031496,25.394220,1.293643,0.314964,-64.764267,0.032580,0.000000
50.420002,5.824654,-64.853226,0.021032,0.001259,0.031982,25.909353,1.319885,0.319824,-64.853226,0.033231,0.000000
50.810001,5.967270,-64.764267,0.021079,0.001290,0.032764,26.543743,1.352203,0.327636,-64.764267,0.033882,0.000000
51.200001,6.041748,-64.808746,0.021101,0.001318,0.033483,26.875038,1.369080,0.334827,-64.808746,0.034532,0.000000
51.590004,6.165749,-64.808746,0.021122,0.001339,0.034020,27.426620,1.397179,0.340201,-64.808746,0.035183,0.000000
51.980003,6.300919,-64.808746,0.021174,0.001366,0.034706,28.027885,1.427809,0.347060,-64.808746,0.035834,0.000000
52.370003,6.490082,-64.808746,0.021195,0.001389,0.035269,28.869326,1.470674,0.352692,-64.808746,0.036483,0.000000
52.760002,6.634567,-64.897705,0.021217,0.001420,0.036067,29.512030,1.503414,0.360670,-64.897705,0.037134,0.000000
53.150002,6.664352,-64.808746,0.021208,0.001440,0.036588,29.644520,1.510164,0.365878,-64.808746,0.037784,0.000000
53.540001,6.853149,-64.897705,0.021251,0.001471,0.037351,30.484331,1.552946,0.373509,-64.897705,0.038435,0.000000
53.930004,6.895966,-64.853226,0.021299,0.001495,0.037967,30.674788,1.562648,0.379670,-64.853226,0.039086,0.000000
54.320004,7.112320,-64.897705,0.021308,0.001521,0.038642,31.637178,1.611675,0.386423,-64.897705,0.039735,0.000000
54.710003,7.309303,-64.853226,0.021346,0.001553,0.039449,32.513405,1.656312,0.394492,-64.853226,0.040386,0.000000
55.100002,7.324196,-64.808746,0.021351,0.001572,0.039935,32.579651,1.659687,0.399352,-64.808746,0.041036,0.000000
55.490002,7.403885,-64.853226,0.021385,0.001598,0.040594,32.934124,1.677744,0.405938,-64.853226,0.041687,0.000000
55.880001,7.552834,-64.808746,0.021411,0.001623,0.041227,33.596684,1.711497,0.412266,-64.808746,0.042329,0.000000
56.270004,7.630661,-64.853226,0.021428,0.001641,0.041687,33.942875,1.729132,0.416868,-64.853226,0.042980,0.000000
56.660004,7.905472,-64.808746,0.021454,0.001678,0.042624,35.165295,1.791405,0.426240,-64.808746,0.043629,0.000000
57.050003,7.947548,-64.853226,0.021476,0.001700,0.043187,35.352459,1.800940,0.431872,-64.853226,0.044280,0.000000
57.440002,8.064850,-64.897705,0.021502,0.001725,0.043811,35.874245,1.827521,0.438109,-64.897705,0.044930,0.000000
57.830002,8.147888,-64.764267,0.021532,0.001749,0.044418,36.243618,1.846338,0.444180,-64.764267,0.045581,0.000000
58.220001,8.236511,-64.853226,0.021540,0.001767,0.044869,36.637833,1.866420,0.448692,-64.853226,0.046232,0.000000
58.610004,8.533287,-64.808746,0.021605,0.001806,0.045876,37.957958,1.933670,0.458760,-64.808746,0.046881,0.000000
59.000004,8.566063,-64.853226,0.021605,0.001827,0.046395,38.103752,1.941098,0.463952,-64.853226,0.047532,0.000000
59.390003,8.728043,-64.853226,0.021618,0.001855,0.047116,38.824272,1.977803,0.471159,-64.853226,0.048182,0.000000
59.780003,8.847198,-64.897705,0.021661,0.001877,0.047679,39.354305,2.004804,0.476791,-64.897705,0.048833,0.000000
60.170002,9.016632,-64.808746,0.021691,0.001905,0.048382,40.107983,2.043198,0.483816,-64.808746,0.049484,0.000000
60.560001,9.178986,-64.897705,0.021687,0.001935,0.049154,40.830166,2.079988,0.491537,-64.897705,0.050133,0.000000
60.950005,9.242661,-64.853226,0.021726,0.001959,0.049752,41.113407,2.094417,0.497517,-64.853226,0.050784,0.000000
61.340004,9.383415,-64.853226,0.021743,0.001986,0.050454,41.739517,2.126312,0.504542,-64.853226,0.051435,0.000000
61.730003,9.438904,-64.853226,0.021765,0.002005,0.050931,41.986340,2.138886,0.509311,-64.853226,0.052085,0.000000
62.120003,9.672752,-64.853226,0.021799,0.002034,0.051668,43.026550,2.191877,0.516684,-64.853226,0.052736,0.000000
62.510002,9.762489,-64.897705,0.021851,0.002063,0.052397,43.425720,2.212212,0.523966,-64.897705,0.053385,0.000000
62.900002,9.831757,-64.808746,0.021872,0.002085,0.052952,43.733837,2.227908,0.529522,-64.808746,0.054036,0.000000
63.290005,10.038048,-64.897705,0.021872,0.002109,0.053576,44.651466,2.274654,0.535759,-64.897705,0.054687,0.000000
63.680004,10.120338,-64.897705,0.021920,0.002133,0.054166,45.017513,2.293301,0.541664,-64.897705,0.055337,0.000000
64.070000,10.263336,-64.853226,0.021937,0.002160,0.054869,45.653599,2.325705,0.548689,-64.853226,0.055988,0.000000
64.460007,10.385475,-64.897705,0.021959,0.002190,0.055623,46.196899,2.353382,0.556228,-64.897705,0.056637,0.000000
64.850006,10.452873,-64.853226,0.021976,0.002211,0.056169,46.496704,2.368655,0.561694,-64.853226,0.057279,0.000000
65.240005,10.804390,-64.853226,0.021971,0.002243,0.056967,48.060326,2.448310,0.569672,-64.853226,0.057930,0.000000
65.630005,10.850937,-64.853226,0.021997,0.002265,0.057530,48.267380,2.458858,0.575304,-64.853226,0.058581,0.000000
66.020004,11.015900,-64.808746,0.022045,0.002288,0.058112,49.001167,2.496238,0.581118,-64.808746,0.059231,0.000000
66.410004,11.152931,-64.897705,0.022105,0.002318,0.058884,49.610714,2.527290,0.588839,-64.897705,0.059882,0.000000
66.800003,11.228523,-64.897705,0.022105,0.002341,0.059456,49.946964,2.544420,0.594562,-64.897705,0.060531,0.000000
67.190002,11.405029,-64.942192,0.022131,0.002365,0.060063,50.732105,2.584416,0.600633,-64.942192,0.061182,0.000000
67.580002,11.595306,-64.897705,0.022157,0.002390,0.060714,51.578499,2.627534,0.607143,-64.897705,0.061833,0.000000
67.970001,11.764366,-64.853226,0.022174,0.002416,0.061364,52.330513,2.665843,0.613637,-64.853226,0.062483,0.000000
68.360001,11.911827,-64.808746,0.022196,0.002445,0.062110,52.986454,2.699259,0.621101,-64.808746,0.063134,0.000000
68.750000,11.933426,-64.853226,0.022239,0.002468,0.062691,53.082531,2.704153,0.626915,-64.853226,0.063785,0.000000
69.140007,12.133018,-64.853226,0.022260,0.002493,0.063333,53.970364,2.749381,0.633334,-64.853226,0.064434,0.000000
69.530006,12.253662,-64.897705,0.022282,0.002517,0.063922,54.507011,2.776720,0.639223,-64.897705,0.065085,0.000000
69.920006,12.442459,-64.853226,0.022286,0.002544,0.064625,55.346821,2.819502,0.646248,-64.853226,0.065735,0.000000
70.310005,12.678169,-64.897705,0.022351,0.002574,0.065388,56.395313,2.872914,0.653878,-64.897705,0.066386,0.000000
70.700005,12.693436,-64.853226,0.022360,0.002598,0.065978,56.463223,2.876374,0.659783,-64.853226,0.067037,0.000000
71.090004,12.838661,-64.808746,0.022390,0.002619,0.066525,57.109219,2.909282,0.665248,-64.808746,0.067686,0.000000
71.480003,13.041229,-64.853226,0.022416,0.002644,0.067167,58.010284,2.955185,0.671667,-64.853226,0.068337,0.000000
71.870003,13.276947,-64.808746,0.022420,0.002670,0.067825,59.058811,3.008599,0.678253,-64.808746,0.068987,0.000000
72.260002,13.491432,-64.808746,0.022454,0.002700,0.068570,60.012886,3.057202,0.685702,-64.808746,0.069638,0.000000
72.650002,13.509300,-64.897705,0.022476,0.002721,0.069126,60.092369,3.061251,0.691258,-64.897705,0.070289,0.000000
73.040001,13.833641,-64.897705,0.022502,0.002754,0.069942,61.535110,3.134748,0.699418,-64.897705,0.070938,0.000000
73.430000,13.811668,-64.897705,0.022541,0.002772,0.070401,61.437370,3.129769,0.704006,-64.897705,0.071589,0.000000
73.820000,14.037697,-64.853226,0.022541,0.002798,0.071068,62.442795,3.180988,0.710682,-64.853226,0.072231,0.000000
74.210007,14.239151,-64.808746,0.022562,0.002825,0.071754,63.338905,3.226638,0.717540,-64.808746,0.072880,0.000000
74.600006,14.344910,-64.897705,0.022605,0.002849,0.072352,63.809345,3.250603,0.723521,-64.897705,0.073531,0.000000
74.990005,14.617485,-64.853226,0.022635,0.002880,0.073150,65.021820,3.312370,0.731499,-64.853226,0.074182,0.000000
75.380005,14.661049,-64.942192,0.022674,0.002899,0.073636,65.215599,3.322241,0.736359,-64.942192,0.074832,0.000000
75.770004,15.042358,-64.897705,0.022674,0.002933,0.074494,66.911751,3.408647,0.744943,-64.897705,0.075483,0.000000
76.160004,15.122421,-64.897705,0.022709,0.002957,0.075110,67.267891,3.426790,0.751105,-64.897705,0.076132,0.000000
76.550003,15.154816,-64.897705,0.022739,0.002980,0.075683,67.411987,3.434130,0.756828,-64.897705,0.076783,0.000000
76.940002,15.421066,-64.897705,0.022765,0.003006,0.076350,68.596329,3.494464,0.763504,-64.897705,0.077434,0.000000
77.330002,15.479530,-64.942192,0.022773,0.003027,0.076888,68.856392,3.507712,0.768879,-64.942192,0.078084,0.000000
77.720001,15.739067,-64.897705,0.022799,0.003054,0.077565,70.010864,3.566524,0.775646,-64.897705,0.078735,0.000000
78.110001,15.894722,-64.897705,0.022825,0.003081,0.078249,70.703255,3.601795,0.782489,-64.897705,0.079386,0.000000
78.500000,16.077187,-64.897705,0.022847,0.003109,0.078960,71.514900,3.643142,0.789605,-64.897705,0.080035,0.000000
78.890007,16.256294,-64.853226,0.022886,0.003133,0.079577,72.311607,3.683729,0.795767,-64.853226,0.080686,0.000000
79.280006,16.288689,-64.897705,0.022937,0.003153,0.080088,72.455704,3.691070,0.800884,-64.897705,0.081336,0.000000
79.670006,16.761230,-64.942192,0.022924,0.003185,0.080894,74.557678,3.798149,0.808938,-64.942192,0.081987,0.000000
80.060005,16.799217,-64.897705,0.022980,0.003211,0.081554,74.726654,3.806757,0.815539,-64.897705,0.082638,0.000000
80.450005,16.884857,-64.897705,0.022972,0.003233,0.082108,75.107597,3.826164,0.821080,-64.897705,0.083287,0.000000
80.840004,17.211060,-64.808746,0.023006,0.003263,0.082871,76.558617,3.900082,0.828710,-64.808746,0.083938,0.000000
81.230003,17.301170,-64.853226,0.023015,0.003286,0.083452,76.959450,3.920501,0.834524,-64.853226,0.084588,0.000000
81.620003,17.603539,-64.897705,0.023088,0.003318,0.084276,78.304451,3.989019,0.842760,-64.897705,0.085239,0.000000
82.010002,17.705200,-64.808746,0.023080,0.003341,0.084866,78.756660,4.012056,0.848664,-64.808746,0.085890,0.000000
82.400002,17.802383,-64.897705,0.023105,0.003361,0.085378,79.188957,4.034078,0.853781,-64.897705,0.086539,0.000000
82.790001,18.022461,-64.897705,0.023144,0.003391,0.086123,80.167908,4.083948,0.861230,-64.897705,0.087181,0.000000
83.180000,18.030281,-64.853226,0.023144,0.003409,0.086583,80.202698,4.085720,0.865833,-64.853226,0.087832,0.000000
83.570007,18.565002,-64.897705,0.023200,0.003445,0.087511,82.581253,4.206890,0.875113,-64.897705,0.088482,0.000000
83.960007,18.672249,-64.897705,0.023218,0.003470,0.088144,83.058311,4.231192,0.881441,-64.897705,0.089133,0.000000
84.350006,18.698685,-64.897705,0.023226,0.003491,0.088673,83.175903,4.237183,0.886725,-64.897705,0.089784,0.000000
84.740005,19.053185,-64.853226,0.023269,0.003519,0.089384,84.752800,4.317513,0.893841,-64.853226,0.090433,0.000000
85.130005,19.163780,-64.853226,0.023287,0.003541,0.089940,85.244751,4.342575,0.899397,-64.853226,0.091084,0.000000
85.520004,19.612114,-64.897705,0.023304,0.003576,0.090833,87.239037,4.444169,0.908329,-64.897705,0.091735,0.000000
85.910004,19.507111,-64.897705,0.023338,0.003595,0.091319,86.771965,4.420374,0.913189,-64.897705,0.092385,0.000000
86.300003,19.793091,-64.942192,0.023355,0.003623,0.092012,88.044067,4.485179,0.920123,-64.942192,0.093036,0.000000
86.690002,19.964378,-64.853226,0.023373,0.003646,0.092619,88.805992,4.523993,0.926194,-64.853226,0.093685,0.000000
87.080002,19.976669,-64.853226,0.023412,0.003665,0.093096,88.860664,4.526778,0.930963,-64.853226,0.094336,0.000000
87.470001,20.487190,-64.942192,0.023437,0.003703,0.094050,91.131577,4.642464,0.940501,-64.942192,0.094987,0.000000
87.860001,20.480858,-64.942192,0.023481,0.003723,0.094562,91.103409,4.641029,0.945618,-64.942192,0.095637,0.000000
88.250008,20.585129,-64.986671,0.023493,0.003746,0.095151,91.567223,4.664657,0.951507,-64.986671,0.096288,0.000000
88.640007,20.953026,-64.942192,0.023524,0.003773,0.095827,93.203712,4.748024,0.958275,-64.942192,0.096937,0.000000
89.030006,20.957497,-64.853226,0.023519,0.003793,0.096330,93.223602,4.749036,0.963301,-64.853226,0.097588,0.000000
89.420006,21.448288,-64.942192,0.023571,0.003828,0.097232,95.406754,4.860251,0.972324,-64.942192,0.098239,0.000000
89.810005,21.447914,-64.897705,0.023601,0.003850,0.097797,95.405090,4.860167,0.977971,-64.897705,0.098889,0.000000
90.200005,21.538773,-64.942192,0.023610,0.003874,0.098412,95.809242,4.880755,0.984118,-64.942192,0.099540,0.000000
90.590004,21.916359,-64.853226,0.023640,0.003900,0.099072,97.488831,4.966318,0.990719,-64.853226,0.100191,0.000000
90.980003,22.024345,-64.853226,0.023657,0.003923,0.099644,97.969185,4.990788,0.996442,-64.853226,0.100840,0.000000
91.370003,22.323730,-64.942192,0.023696,0.003951,0.100363,99.300911,5.058630,1.003633,-64.942192,0.101491,0.000000
91.760002,22.495026,-64.897705,0.023726,0.003978,0.101049,100.062874,5.097445,1.010491,-64.897705,0.102133,0.000000
92.150002,22.625351,-64.897705,0.023765,0.004004,0.101690,100.642586,5.126977,1.016895,-64.897705,0.102783,0.000000
92.540001,23.013367,-64.853226,0.023761,0.004032,0.102419,102.368568,5.214903,1.024193,-64.853226,0.103434,0.000000
92.930008,22.914688,-64.853226,0.023774,0.004048,0.102817,101.929626,5.192543,1.028174,-64.853226,0.104083,0.000000
93.320007,23.368607,-64.942192,0.023813,0.004080,0.103633,103.948753,5.295402,1.036335,-64.942192,0.104734,0.000000
93.710007,23.504524,-64.853226,0.023838,0.004105,0.104266,104.553345,5.326201,1.042663,-64.853226,0.105385,0.000000
94.100006,23.821411,-64.942192,0.023869,0.004133,0.104985,105.962929,5.398009,1.049854,-64.942192,0.106035,0.000000
94.490005,23.950256,-64.986671,0.023886,0.004159,0.105636,106.536064,5.427206,1.056364,-64.986671,0.106686,0.000000
94.880005,23.905197,-64.897705,0.023907,0.004175,0.106044,106.335625,5.416995,1.060437,-64.897705,0.107337,0.000000
95.270004,24.465988,-64.942192,0.023942,0.004208,0.106885,108.830154,5.544072,1.068854,-64.942192,0.107986,0.000000
95.660004,24.574722,-64.853226,0.023981,0.004233,0.107509,109.313828,5.568712,1.075092,-64.853226,0.108637,0.000000
96.050003,24.839478,-64.942192,0.023976,0.004259,0.108186,110.491516,5.628706,1.081859,-64.942192,0.109287,0.000000
96.440002,25.070724,-64.897705,0.024015,0.004286,0.108854,111.520149,5.681108,1.088536,-64.897705,0.109938,0.000000
96.830002,25.200310,-64.897705,0.024054,0.004309,0.109461,112.096573,5.710472,1.094607,-64.897705,0.110589,0.000000
97.220001,25.545128,-64.942192,0.024063,0.004339,0.110207,113.630402,5.788609,1.102071,-64.942192,0.111238,0.000000
97.610008,25.606194,-64.853226,0.024080,0.004360,0.110752,113.902039,5.802446,1.107521,-64.853226,0.111889,0.000000
98.000008,25.886223,-64.853226,0.024114,0.004387,0.111438,115.147667,5.865902,1.114379,-64.853226,0.112539,0.000000
98.390007,26.163261,-64.942192,0.024123,0.004414,0.112124,116.379997,5.928680,1.121237,-64.942192,0.113190,0.000000
98.780006,26.161400,-64.853226,0.024175,0.004431,0.112548,116.371719,5.928258,1.125476,-64.853226,0.113841,0.000000
99.170006,26.789970,-64.942192,0.024179,0.004467,0.113450,119.167740,6.070694,1.134500,-64.942192,0.114490,0.000000
99.560005,26.801514,-64.897705,0.024188,0.004489,0.114013,119.219086,6.073310,1.140131,-64.897705,0.115141,0.000000
99.950005,26.975410,-64.897705,0.024209,0.004511,0.114585,119.992622,6.112715,1.145854,-64.897705,0.115792,0.000000
100.340004,27.395821,-64.942192,0.024257,0.004541,0.115348,121.862694,6.207982,1.153485,-64.942192,0.116442,0.000000
100.730003,27.350761,-64.897705,0.024265,0.004558,0.115774,121.662262,6.197772,1.157739,-64.897705,0.117083,0.000000
101.120003,28.016937,-64.897705,0.024295,0.004594,0.116685,124.625565,6.348729,1.166853,-64.897705,0.117734,0.000000
101.510002,27.968529,-64.897705,0.024321,0.004620,0.117344,124.410233,6.337759,1.173439,-64.897705,0.118384,0.000000
101.900002,28.240730,-64.897705,0.024343,0.004641,0.117890,125.621040,6.399441,1.178904,-64.897705,0.119035,0.000000
102.290009,28.391914,-64.986671,0.024369,0.004665,0.118497,126.293541,6.433700,1.184975,-64.986671,0.119686,0.000000
102.680008,28.721466,-64.942192,0.024390,0.004694,0.119226,127.759460,6.508378,1.192257,-64.942192,0.120335,0.000000
103.070007,29.137405,-64.942192,0.024429,0.004725,0.120005,129.609650,6.602630,1.200054,-64.942192,0.120986,0.000000
103.460007,29.319496,-64.897705,0.024438,0.004750,0.120640,130.419632,6.643893,1.206397,-64.897705,0.121636,0.000000
103.850006,29.563026,-64.897705,0.024476,0.004775,0.121273,131.502914,6.699078,1.212726,-64.897705,0.122287,0.000000
104.240005,29.561539,-64.897705,0.024485,0.004795,0.121784,131.496292,6.698740,1.217843,-64.897705,0.122938,0.000000
104.630005,29.856453,-64.897705,0.024494,0.004819,0.122391,132.808136,6.765569,1.223914,-64.897705,0.123587,0.000000
105.020004,30.414642,-64.853226,0.024545,0.004854,0.123292,135.291092,6.892056,1.232922,-64.853226,0.124238,0.000000
105.410004,30.358788,-64.897705,0.024554,0.004872,0.123752,135.042633,6.879399,1.237524,-64.897705,0.124888,0.000000
105.800003,30.590027,-64.897705,0.024589,0.004895,0.124325,136.071228,6.931799,1.243247,-64.897705,0.125539,0.000000
106.190002,31.132202,-64.942192,0.024619,0.004927,0.125157,138.482956,7.054658,1.251574,-64.942192,0.126190,0.000000
106.580002,31.031288,-64.853226,0.024623,0.004946,0.125618,138.034058,7.031791,1.256176,-64.853226,0.126839,0.000000
106.970009,31.752945,-64.942192,0.024658,0.004983,0.126571,141.244156,7.195320,1.265714,-64.942192,0.127490,0.000000
107.360008,31.710495,-64.853226,0.024696,0.005003,0.127074,141.055328,7.185701,1.270741,-64.853226,0.128141,0.000000
107.750008,31.854233,-64.853226,0.024692,0.005025,0.127646,141.694702,7.218273,1.276463,-64.853226,0.128791,0.000000
108.140007,32.040047,-64.942192,0.024722,0.005050,0.128270,142.521240,7.260378,1.282701,-64.942192,0.129442,0.000000
108.530006,32.330872,-64.897705,0.024757,0.005070,0.128782,143.814896,7.326280,1.287818,-64.897705,0.130091,0.000000
108.920006,33.054016,-64.853226,0.024774,0.005110,0.129798,147.031601,7.490147,1.297977,-64.853226,0.130742,0.000000
109.310005,33.040611,-64.942192,0.024791,0.005133,0.130387,146.971985,7.487110,1.303866,-64.942192,0.131393,0.000000
109.700005,33.080460,-64.853226,0.024826,0.005153,0.130889,147.149231,7.496140,1.308892,-64.853226,0.132034,0.000000
110.090004,33.641624,-64.986671,0.024817,0.005181,0.131610,149.645416,7.623302,1.316099,-64.986671,0.132685,0.000000
110.480003,33.847916,-64.897705,0.024839,0.005203,0.132164,150.563049,7.670047,1.321640,-64.897705,0.133336,0.000000
110.870003,34.276520,-64.942192,0.024882,0.005234,0.132936,152.469574,7.767170,1.329361,-64.942192,0.133985,0.000000
111.260002,34.486908,-64.986671,0.024908,0.005260,0.133596,153.405426,7.814845,1.335962,-64.986671,0.134636,0.000000
111.650002,34.709213,-64.897705,0.024908,0.005282,0.134168,154.394287,7.865220,1.341685,-64.897705,0.135287,0.000000
112.040009,35.004135,-64.897705,0.024959,0.005308,0.134818,155.706177,7.932050,1.348180,-64.897705,0.135937,0.000000
112.430008,35.264420,-64.853226,0.024990,0.005334,0.135478,156.863968,7.991032,1.354780,-64.853226,0.136588,0.000000
112.820007,35.802498,-64.853226,0.024994,0.005363,0.136223,159.257462,8.112962,1.362229,-64.853226,0.137237,0.000000
113.210007,35.859100,-64.897705,0.025024,0.005389,0.136874,159.509247,8.125789,1.368739,-64.897705,0.137888,0.000000
113.600006,36.011024,-64.808746,0.025041,0.005409,0.137386,160.185043,8.160214,1.373856,-64.808746,0.138539,0.000000
113.990005,36.472771,-64.942192,0.025089,0.005436,0.138070,162.238983,8.264848,1.380699,-64.942192,0.139189,0.000000
114.380005,36.566231,-64.942192,0.025097,0.005453,0.138512,162.654724,8.286026,1.385120,-64.942192,0.139840,0.000000
114.770004,37.012337,-64.942192,0.025106,0.005483,0.139258,164.639099,8.387115,1.392584,-64.942192,0.140489,0.000000
115.160004,37.264809,-64.942192,0.025136,0.005510,0.139952,165.762146,8.444326,1.399518,-64.942192,0.141140,0.000000
115.550003,37.587654,-64.853226,0.025184,0.005535,0.140585,167.198242,8.517485,1.405846,-64.853226,0.141791,0.000000
115.940002,37.889275,-64.942192,0.025188,0.005562,0.141280,168.539917,8.585833,1.412795,-64.942192,0.142441,0.000000
116.330002,38.189781,-64.897705,0.025197,0.005584,0.141843,169.876633,8.653929,1.418427,-64.897705,0.143092,0.000000
116.720009,38.709610,-64.897705,0.025248,0.005616,0.142641,172.188950,8.771723,1.426406,-64.897705,0.143743,0.000000
117.110008,38.827652,-64.897705,0.025261,0.005637,0.143178,172.714020,8.798471,1.431780,-64.897705,0.144392,0.000000
117.500008,39.262581,-64.853226,0.025274,0.005665,0.143881,174.648682,8.897028,1.438805,-64.853226,0.145043,0.000000
117.890007,39.373177,-64.897705,0.025287,0.005687,0.144462,175.140640,8.922090,1.444619,-64.897705,0.145693,0.000000
118.280006,39.851303,-64.897705,0.025339,0.005715,0.145155,177.267456,9.030434,1.451553,-64.897705,0.146344,0.000000
118.670006,40.460136,-64.853226,0.025360,0.005748,0.146006,179.975677,9.168398,1.460061,-64.853226,0.146986,0.000000
119.060005,40.485085,-64.986671,0.025399,0.005768,0.146518,180.086655,9.174051,1.465178,-64.986671,0.147637,0.000000
119.450005,40.736061,-64.897705,0.025395,0.005795,0.147185,181.203049,9.230924,1.471855,-64.897705,0.148286,0.000000
119.840004,41.114395,-64.897705,0.025421,0.005820,0.147818,182.885971,9.316655,1.478183,-64.897705,0.148937,0.000000
120.230003,41.205994,-64.853226,0.025434,0.005836,0.148242,183.293411,9.337411,1.482422,-64.853226,0.149587,0.000000
120.620003,41.979416,-64.897705,0.025468,0.005869,0.149075,186.733765,9.512671,1.490749,-64.897705,0.150238,0.000000
121.010002,42.262047,-64.897705,0.025498,0.005895,0.149743,187.990967,9.576716,1.497426,-64.897705,0.150889,0.000000
121.400009,42.530899,-64.897705,0.025524,0.005920,0.150368,189.186890,9.637640,1.503678,-64.897705,0.151538,0.000000
121.790009,42.763626,-64.853226,0.025541,0.005943,0.150949,190.222107,9.690376,1.509492,-64.853226,0.152189,0.000000
122.180008,42.987801,-64.897705,0.025546,0.005962,0.151426,191.219284,9.741175,1.514261,-64.897705,0.152839,0.000000
122.570007,43.938095,-64.897705,0.025559,0.006002,0.152440,195.446411,9.956514,1.524404,-64.897705,0.153490,0.000000
122.960007,44.002144,-64.897705,0.025589,0.006022,0.152969,195.731308,9.971028,1.529688,-64.897705,0.154141,0.000000
123.350006,44.289612,-64.942192,0.025641,0.006049,0.153636,197.010040,10.036169,1.536365,-64.942192,0.154790,0.000000
123.740005,44.832901,-64.853226,0.025666,0.006073,0.154244,199.426697,10.159281,1.542436,-64.853226,0.155441,0.000000
124.130005,45.310654,-64.897705,0.025684,0.006101,0.154964,201.551849,10.267541,1.549642,-64.897705,0.156092,0.000000
124.520004,45.857674,-64.897705,0.025701,0.006131,0.155736,203.985123,10.391498,1.557363,-64.897705,0.156742,0.000000
124.910004,46.136208,-64.942192,0.025735,0.006154,0.156316,205.224106,10.454615,1.563162,-64.942192,0.157393,0.000000
125.300003,46.629227,-64.897705,0.025761,0.006182,0.157011,207.417160,10.566334,1.570111,-64.897705,0.158042,0.000000
125.690002,46.668701,-64.853226,0.025787,0.006200,0.157479,207.592758,10.575279,1.574789,-64.853226,0.158693,0.000000
126.080009,47.409721,-64.897705,0.025813,0.006229,0.158225,210.888977,10.743196,1.582253,-64.897705,0.159344,0.000000
126.470009,47.936996,-64.897705,0.025830,0.006258,0.158963,213.234406,10.862679,1.589626,-64.897705,0.159994,0.000000
126.860008,48.163773,-64.897705,0.025839,0.006279,0.159491,214.243164,10.914066,1.594909,-64.897705,0.160645,0.000000
127.250008,48.714516,-64.853226,0.025860,0.006305,0.160142,216.692993,11.038867,1.601419,-64.853226,0.161294,0.000000
127.640007,49.149818,-64.853226,0.025921,0.006328,0.160722,218.629318,11.137508,1.607218,-64.853226,0.161945,0.000000
128.029999,49.584373,-64.942192,0.025873,0.006353,0.161356,220.562302,11.235980,1.613561,-64.942192,0.162587,0.000000
128.420013,50.255394,-64.853226,0.025934,0.006385,0.162180,223.547150,11.388035,1.621797,-64.853226,0.163238,0.000000
128.810013,50.490730,-64.808746,0.025951,0.006405,0.162699,224.593979,11.441363,1.626990,-64.808746,0.163887,0.000000
129.200012,51.265640,-64.897705,0.025968,0.006435,0.163454,228.040955,11.616960,1.634545,-64.897705,0.164538,0.000000
129.590012,51.821220,-64.853226,0.026007,0.006460,0.164096,230.512299,11.742857,1.640964,-64.853226,0.165188,0.000000
129.980011,52.359665,-64.897705,0.026020,0.006484,0.164703,232.907425,11.864869,1.647035,-64.897705,0.165839,0.000000
130.370010,53.093613,-64.853226,0.026029,0.006512,0.165414,236.172180,12.031184,1.654135,-64.853226,0.166490,0.000000
130.760010,53.576210,-64.853226,0.026067,0.006536,0.166021,238.318878,12.140543,1.660206,-64.853226,0.167139,0.000000
131.150009,53.750107,-64.942192,0.026089,0.006553,0.166455,239.092422,12.179949,1.664551,-64.942192,0.167790,0.000000
131.540009,54.948029,-64.897705,0.026111,0.006586,0.167279,244.421036,12.451402,1.672787,-64.897705,0.168440,0.000000
131.930008,55.615692,-64.853226,0.026115,0.006611,0.167930,247.390961,12.602695,1.679297,-64.853226,0.169091,0.000000
132.320007,56.308678,-64.853226,0.026145,0.006640,0.168649,250.473511,12.759728,1.686489,-64.853226,0.169742,0.000000
132.710007,56.901123,-64.853226,0.026158,0.006663,0.169238,253.108841,12.893978,1.692378,-64.853226,0.170391,0.000000
133.100006,57.611237,-64.853226,0.026180,0.006688,0.169872,256.267578,13.054893,1.698721,-64.853226,0.171042,0.000000
133.490005,58.315018,-64.853226,0.026201,0.006712,0.170479,259.398163,13.214372,1.704792,-64.853226,0.171693,0.000000
133.880005,59.030724,-64.853226,0.026231,0.006737,0.171129,262.581787,13.376554,1.711287,-64.853226,0.172343,0.000000
134.270004,60.205185,-64.897705,0.026261,0.006769,0.171927,267.806030,13.642690,1.719266,-64.897705,0.172994,0.000000
134.660004,60.743263,-64.808746,0.026274,0.006791,0.172491,270.199524,13.764620,1.724913,-64.808746,0.173643,0.000000
135.050003,61.182663,-64.897705,0.026287,0.006813,0.173054,272.154083,13.864189,1.730545,-64.897705,0.174294,0.000000
135.440002,62.208549,-64.853226,0.026292,0.006838,0.173696,276.717438,14.096660,1.736964,-64.853226,0.174945,0.000000
135.830002,62.997604,-64.897705,0.026330,0.006860,0.174250,280.227325,14.275461,1.742505,-64.897705,0.175595,0.000000
136.220001,64.522835,-64.897705,0.026335,0.006895,0.175127,287.011902,14.621083,1.751271,-64.897705,0.176246,0.000000
136.610001,65.137627,-64.942192,0.026335,0.006916,0.175674,289.746643,14.760398,1.756736,-64.942192,0.176895,0.000000
137.000000,66.344109,-64.853226,0.026369,0.006947,0.176462,295.113342,15.033791,1.764624,-64.853226,0.177537,0.000000
137.389999,66.637550,-64.897705,0.026425,0.006963,0.176853,296.418640,15.100285,1.768530,-64.897705,0.178188,0.000000
137.780014,67.163338,-64.897705,0.026408,0.006970,0.177026,298.757446,15.219430,1.770256,-64.897705,0.177304,0.000000
138.170013,66.493431,-64.897705,0.026412,0.006961,0.176809,295.777557,15.067626,1.768091,-64.897705,0.177026,0.000000
138.560013,66.051064,-64.853226,0.026425,0.006961,0.176809,293.809814,14.967385,1.768091,-64.853226,0.177026,0.000000
138.950012,65.711449,-64.897705,0.026425,0.006961,0.176809,292.299133,14.890427,1.768091,-64.897705,0.177026,0.000000
139.340012,65.417656,-64.853226,0.026430,0.006961,0.176809,290.992279,14.823853,1.768091,-64.853226,0.177026,0.000000
139.730011,65.191994,-64.808746,0.026417,0.006961,0.176809,289.988464,14.772717,1.768091,-64.808746,0.177026,0.000000
140.120010,64.980492,-64.897705,0.026434,0.006961,0.176809,289.047668,14.724790,1.768091,-64.897705,0.177026,0.000000
140.510010,64.792809,-64.853226,0.026443,0.006961,0.176809,288.212799,14.682261,1.768091,-64.853226,0.177026,0.000000
140.900009,64.625252,-64.853226,0.026447,0.006961,0.176809,287.467468,14.644292,1.768091,-64.853226,0.177026,0.000000
141.290009,64.474434,-64.853226,0.026425,0.006961,0.176809,286.796600,14.610115,1.768091,-64.853226,0.177026,0.000000
141.680008,64.359749,-64.808746,0.026464,0.006961,0.176809,286.286469,14.584127,1.768091,-64.808746,0.177026,0.000000
142.070007,64.227180,-64.897705,0.026434,0.006961,0.176809,285.696777,14.554087,1.768091,-64.897705,0.177026,0.000000
142.460007,64.117699,-64.897705,0.026455,0.006961,0.176809,285.209778,14.529279,1.768091,-64.897705,0.177026,0.000000
142.850006,64.003380,-64.808746,0.026430,0.006961,0.176809,284.701263,14.503373,1.768091,-64.808746,0.177026,0.000000
143.240005,63.910286,-64.853226,0.026447,0.006961,0.176809,284.287140,14.482278,1.768091,-64.853226,0.177026,0.000000
143.630005,63.819435,-64.853226,0.026455,0.006961,0.176809,283.883026,14.461690,1.768091,-64.853226,0.177026,0.000000
144.020004,63.696541,-64.897705,0.026438,0.006961,0.176800,283.336365,14.433843,1.768000,-64.897705,0.177026,0.000000
144.410004,63.615364,-64.853226,0.026434,0.006961,0.176800,282.975281,14.415448,1.768000,-64.853226,0.177026,0.000000
144.800003,63.553185,-64.853226,0.026438,0.006961,0.176800,282.698669,14.401357,1.768000,-64.853226,0.177026,0.000000
145.190002,63.479454,-64.808746,0.026473,0.006961,0.176800,282.370728,14.384650,1.768000,-64.808746,0.177026,0.000000
145.580002,63.413551,-64.764267,0.026447,0.006961,0.176800,282.077576,14.369716,1.768000,-64.764267,0.177026,0.000000
145.970001,63.328270,-64.853226,0.026455,0.006961,0.176800,281.698212,14.350390,1.768000,-64.853226,0.177026,0.000000
146.360001,63.259758,-64.897705,0.026438,0.006961,0.176800,281.393463,14.334866,1.768000,-64.897705,0.177026,0.000000
146.750000,63.206505,-64.808746,0.026438,0.006961,0.176800,281.156586,14.322799,1.768000,-64.808746,0.177026,0.000000
147.139999,63.165916,-64.808746,0.026443,0.006961,0.176800,280.976044,14.313601,1.768000,-64.808746,0.177026,0.000000
147.530014,63.105598,-64.808746,0.026447,0.006961,0.176800,280.707733,14.299933,1.768000,-64.808746,0.177026,0.000000
147.920013,63.065376,-64.897705,0.026438,0.006961,0.176800,280.528809,14.290818,1.768000,-64.897705,0.177026,0.000000
148.310013,63.012497,-64.853226,0.026447,0.006961,0.176800,280.293579,14.278836,1.768000,-64.853226,0.177026,0.000000
148.700012,62.949944,-64.808746,0.026451,0.006961,0.176800,280.015320,14.264661,1.768000,-64.808746,0.177026,0.000000
149.090012,62.900040,-64.853226,0.026451,0.006961,0.176800,279.793365,14.253353,1.768000,-64.853226,0.177026,0.000000
149.480011,62.857590,-64.808746,0.026430,0.006961,0.176800,279.604523,14.243733,1.768000,-64.808746,0.177026,0.000000
149.870010,62.823334,-64.808746,0.026464,0.006961,0.176800,279.452148,14.235971,1.768000,-64.808746,0.177026,0.000000
150.260010,62.770454,-64.897705,0.026434,0.006961,0.176800,279.216919,14.223989,1.768000,-64.897705,0.177026,0.000000
150.650009,62.729866,-64.808746,0.026447,0.006961,0.176800,279.036377,14.214791,1.768000,-64.808746,0.177026,0.000000
151.040009,62.688164,-64.897705,0.026455,0.006961,0.176800,278.850891,14.205340,1.768000,-64.897705,0.177026,0.000000
151.430008,62.662094,-64.853226,0.026460,0.006961,0.176800,278.734924,14.199433,1.768000,-64.853226,0.177026,0.000000
151.820007,62.623367,-64.808746,0.026425,0.006961,0.176800,278.562653,14.190659,1.768000,-64.808746,0.177026,0.000000
152.210007,62.577194,-64.808746,0.026447,0.006961,0.176800,278.357269,14.180195,1.768000,-64.808746,0.177026,0.000000
152.600006,62.556343,-64.808746,0.026443,0.006961,0.176800,278.264526,14.175469,1.768000,-64.808746,0.177026,0.000000
152.990005,62.518364,-64.897705,0.026451,0.006961,0.176800,278.095581,14.166863,1.768000,-64.897705,0.177026,0.000000
153.380005,62.481499,-64.853226,0.026455,0.006961,0.176800,277.931580,14.158510,1.768000,-64.853226,0.177026,0.000000
153.770004,62.449844,-64.764267,0.026438,0.006961,0.176800,277.790771,14.151337,1.768000,-64.764267,0.177026,0.000000
154.160004,62.418938,-64.853226,0.026464,0.006961,0.176800,277.653290,14.144334,1.768000,-64.853226,0.177026,0.000000
154.550003,62.399574,-64.853226,0.026460,0.006961,0.176800,277.567169,14.139946,1.768000,-64.853226,0.177026,0.000000
154.940002,62.375000,-64.808746,0.026438,0.006961,0.176800,277.457855,14.134377,1.768000,-64.808746,0.177026,0.000000
155.330002,62.328079,-64.853226,0.026460,0.006961,0.176800,277.249146,14.123745,1.768000,-64.853226,0.177026,0.000000
155.720001,62.309464,-64.808746,0.026434,0.006961,0.176800,277.166351,14.119526,1.768000,-64.808746,0.177026,0.000000
156.110001,62.262917,-64.853226,0.026438,0.006961,0.176800,276.959290,14.108978,1.768000,-64.853226,0.177026,0.000000
156.500000,62.250999,-64.764267,0.026473,0.006961,0.176800,276.906281,14.106277,1.768000,-64.764267,0.177026,0.000000
156.890015,62.213760,-64.764267,0.026468,0.006961,0.176800,276.740631,14.097839,1.768000,-64.764267,0.177026,0.000000
157.280014,62.204453,-64.853226,0.026455,0.006961,0.176800,276.699219,14.095731,1.768000,-64.853226,0.177026,0.000000
157.670013,62.163490,-64.808746,0.026455,0.006961,0.176800,276.517029,14.086448,1.768000,-64.808746,0.177026,0.000000
158.060013,62.152321,-64.808746,0.026434,0.006961,0.176800,276.467346,14.083918,1.768000,-64.808746,0.177026,0.000000
158.450012,62.105400,-64.808746,0.026464,0.006961,0.176800,276.258606,14.073285,1.768000,-64.808746,0.177026,0.000000
158.840012,62.096092,-64.764267,0.026451,0.006961,0.176800,276.217224,14.071176,1.768000,-64.764267,0.177026,0.000000
159.230011,62.071510,-64.808746,0.026460,0.006961,0.176800,276.107880,14.065606,1.768000,-64.808746,0.177026,0.000000
159.620010,62.050285,-64.853226,0.026464,0.006961,0.176800,276.013458,14.060796,1.768000,-64.853226,0.177026,0.000000
160.010010,62.032417,-64.808746,0.026451,0.006961,0.176800,275.933960,14.056746,1.768000,-64.808746,0.177026,0.000000
160.400009,62.001877,-64.808746,0.026434,0.006961,0.176800,275.798126,14.049827,1.768000,-64.808746,0.177026,0.000000
160.790009,61.978424,-64.764267,0.026473,0.006961,0.176800,275.693787,14.044512,1.768000,-64.764267,0.177026,0.000000
161.180008,61.966881,-64.808746,0.026443,0.006961,0.176800,275.642456,14.041896,1.768000,-64.808746,0.177026,0.000000
161.570007,61.927032,-64.808746,0.026473,0.006961,0.176800,275.465210,14.032866,1.768000,-64.808746,0.177026,0.000000
161.960007,61.906181,-64.853226,0.026430,0.006961,0.176800,275.372437,14.028141,1.768000,-64.853226,0.177026,0.000000
162.350006,61.899109,-64.853226,0.026447,0.006961,0.176800,275.340973,14.026539,1.768000,-64.853226,0.177026,0.000000
162.740005,61.862244,-64.764267,0.026464,0.006961,0.176800,275.177002,14.018185,1.768000,-64.764267,0.177026,0.000000
163.130005,61.852188,-64.853226,0.026451,0.006961,0.176800,275.132263,14.015905,1.768000,-64.853226,0.177026,0.000000
163.520004,61.836548,-64.808746,0.026460,0.006961,0.176800,275.062714,14.012362,1.768000,-64.808746,0.177026,0.000000
163.910004,61.838409,-64.808746,0.026464,0.006961,0.176800,275.070984,14.012784,1.768000,-64.808746,0.177026,0.000000
164.300003,61.794098,-64.808746,0.026447,0.006961,0.176800,274.873871,14.002743,1.768000,-64.808746,0.177026,0.000000
164.690002,61.776970,-64.764267,0.026455,0.006961,0.176800,274.797699,13.998861,1.768000,-64.764267,0.177026,0.000000
165.080002,61.771011,-64.808746,0.026447,0.006961,0.176800,274.771179,13.997511,1.768000,-64.808746,0.177026,0.000000
165.470001,61.739731,-64.808746,0.026464,0.006961,0.176800,274.632050,13.990423,1.768000,-64.808746,0.177026,0.000000
165.860001,61.719994,-64.764267,0.026451,0.006961,0.176800,274.544250,13.985950,1.768000,-64.764267,0.177026,0.000000
166.250015,61.695419,-64.853226,0.026451,0.006961,0.176800,274.434937,13.980382,1.768000,-64.853226,0.177026,0.000000
166.640015,61.702866,-64.808746,0.026473,0.006961,0.176800,274.468048,13.982069,1.768000,-64.808746,0.177026,0.000000
167.030014,61.673073,-64.808746,0.026460,0.006961,0.176800,274.335541,13.975318,1.768000,-64.808746,0.177026,0.000000
167.420013,61.678291,-64.853226,0.026434,0.006961,0.176800,274.358734,13.976501,1.768000,-64.853226,0.177026,0.000000
167.810013,61.643288,-64.764267,0.026443,0.006961,0.176800,274.203033,13.968568,1.768000,-64.764267,0.177026,0.000000
168.100006,61.638443,-64.808746,0.026455,0.006961,0.176800,274.181488,13.967471,1.768000,-64.808746,0.177026,0.000000