File: Data/New pin I-18-4_08172023_171119.csv
Time (sec),S:Load (lbs),S:HL1 (DIM),S:LVDT (in),S:Position (in),Ch:Position (mm),Ch:Load (N),Ch:Stress (MPa),Ch:Strain (mm/mm),Ch:HL1 (DIM),Set Point (),Cycles ()
0.010000,-0.009682,-120.765785,-0.000009,-0.000000,-0.000000,-0.043066,-0.002194,-0.000000,-120.765785,0.000104,0.000000
0.220000,-0.008937,-120.676819,0.000030,-0.000000,-0.000000,-0.039754,-0.002025,-0.000000,-120.676819,0.000104,0.000000
0.430000,-0.008565,-120.765785,0.000009,0.000044,0.001111,-0.038097,-0.001941,0.011112,-120.765785,0.001684,0.000000
0.640000,-0.008192,-120.721298,-0.000026,0.000171,0.004337,-0.036441,-0.001856,0.043375,-120.721298,0.005169,0.000000
0.850000,0.020480,-120.721298,-0.000013,0.000298,0.007562,0.091102,0.004641,0.075622,-120.721298,0.008673,0.000000
1.060000,0.030162,-120.721298,0.000155,0.000427,0.010858,0.134168,0.006835,0.108581,-120.721298,0.012177,0.000000
1.270000,0.037610,-120.676819,0.000272,0.000567,0.014396,0.167296,0.008522,0.143962,-120.676819,0.015680,0.000000
1.480000,0.032024,-120.676819,0.000431,0.000709,0.018004,0.142450,0.007257,0.180040,-120.676819,0.019167,0.000000
1.690000,0.028673,-120.721298,0.000543,0.000852,0.021647,0.127542,0.006497,0.216466,-120.721298,0.022670,0.000000
1.900000,0.027556,-120.676819,0.000694,0.000991,0.025159,0.122573,0.006244,0.251590,-120.676819,0.026173,0.000000
2.110000,0.007820,-120.676819,0.000836,0.001126,0.028611,0.034784,0.001772,0.286108,-120.676819,0.029660,0.000000
2.320000,-0.025321,-120.676819,0.000949,0.001260,0.032010,-0.112635,-0.005738,0.320096,-120.676819,0.033163,0.000000
2.530000,-0.020481,-120.676819,0.001117,0.001397,0.035496,-0.091102,-0.004641,0.354963,-120.676819,0.036667,0.000000
2.740000,0.026438,-120.676819,0.001272,0.001539,0.039086,0.117604,0.005991,0.390859,-120.676819,0.040171,0.000000
2.950000,0.038727,-120.587860,0.001418,0.001676,0.042572,0.172265,0.008776,0.425725,-120.587860,0.043656,0.000000
3.160000,0.039099,-120.632339,0.001556,0.001815,0.046103,0.173921,0.008860,0.461030,-120.632339,0.047160,0.000000
3.370000,0.031279,-120.543381,0.001681,0.001949,0.049502,0.139137,0.007088,0.495019,-120.543381,0.050665,0.000000
3.580000,0.055856,-120.587860,0.001824,0.002083,0.052919,0.248459,0.012657,0.529189,-120.587860,0.054150,0.000000
3.790000,0.051760,-120.587860,0.001966,0.002223,0.056466,0.230239,0.011729,0.564661,-120.587860,0.057655,0.000000
4.000000,0.039844,-120.587860,0.002100,0.002356,0.059830,0.177234,0.009029,0.598301,-120.587860,0.061158,0.000000
4.210000,0.028300,-120.632339,0.002268,0.002500,0.063508,0.125886,0.006413,0.635075,-120.632339,0.064661,0.000000
4.420000,0.029045,-120.587860,0.002397,0.002644,0.067159,0.129199,0.006582,0.671592,-120.587860,0.068148,0.000000
4.630000,-0.011544,-120.543381,0.002544,0.002778,0.070567,-0.051348,-0.002616,0.705671,-120.543381,0.071651,0.000000
4.840000,0.020480,-120.587860,0.002686,0.002915,0.074045,0.091102,0.004641,0.740447,-120.587860,0.075154,0.000000
5.050000,0.027183,-120.543381,0.002824,0.003052,0.077513,0.120917,0.006160,0.775131,-120.543381,0.078641,0.000000
5.260000,0.017874,-120.543381,0.002979,0.003193,0.081112,0.079507,0.004050,0.811118,-120.543381,0.082144,0.000000
5.470000,0.043940,-120.587860,0.003104,0.003331,0.084608,0.195455,0.009957,0.846075,-120.587860,0.085648,0.000000
5.680000,0.046174,-120.543381,0.003251,0.003469,0.088120,0.205393,0.010463,0.881199,-120.543381,0.089151,0.000000
5.890000,0.030535,-120.543381,0.003397,0.003602,0.091493,0.135824,0.006919,0.914930,-120.543381,0.092638,0.000000
6.100000,0.055856,-120.543381,0.003557,0.003736,0.094884,0.248459,0.012657,0.948843,-120.543381,0.096141,0.000000
6.310000,0.042823,-120.498894,0.003643,0.003878,0.098492,0.190485,0.009704,0.984921,-120.498894,0.099646,0.000000
6.520000,0.037237,-120.543381,0.003816,0.004017,0.102021,0.165639,0.008438,1.020211,-120.543381,0.103131,0.000000
6.730000,0.034258,-120.454414,0.003958,0.004160,0.105664,0.152388,0.007763,1.056637,-120.454414,0.106634,0.000000
6.940001,0.055856,-120.498894,0.004083,0.004297,0.109150,0.248459,0.012657,1.091503,-120.498894,0.110139,0.000000
7.150001,0.037237,-120.454414,0.004238,0.004431,0.112549,0.165639,0.008438,1.125491,-120.454414,0.113624,0.000000
7.360000,0.027928,-120.498894,0.004389,0.004569,0.116062,0.124230,0.006329,1.160615,-120.498894,0.117129,0.000000
7.570000,0.037982,-120.409935,0.004527,0.004706,0.119522,0.168952,0.008607,1.195224,-120.409935,0.120632,0.000000
7.780000,0.059580,-120.498894,0.004717,0.004846,0.123095,0.265023,0.013501,1.230954,-120.498894,0.124135,0.000000
7.990000,0.037610,-120.409935,0.004803,0.004985,0.126624,0.167296,0.008522,1.266244,-120.409935,0.127622,0.000000
8.200001,0.054366,-120.454414,0.004971,0.005118,0.129990,0.241834,0.012320,1.299899,-120.454414,0.131125,0.000000
8.410001,0.049898,-120.454414,0.005148,0.005256,0.133501,0.221957,0.011307,1.335008,-120.454414,0.134629,0.000000
8.620001,0.055111,-120.409935,0.005226,0.005394,0.137013,0.245146,0.012488,1.370132,-120.409935,0.138115,0.000000
8.830001,0.058835,-120.365456,0.005411,0.005533,0.140535,0.261710,0.013332,1.405347,-120.365456,0.141619,0.000000
9.040000,0.069261,-120.454414,0.005519,0.005669,0.143996,0.308089,0.015695,1.439956,-120.454414,0.145122,0.000000
9.250000,0.059952,-120.409935,0.005696,0.005811,0.147602,0.266680,0.013585,1.476018,-120.409935,0.148625,0.000000
9.460000,0.087135,-120.409935,0.005838,0.005950,0.151132,0.387596,0.019745,1.511324,-120.409935,0.152112,0.000000
9.670000,0.050270,-120.320976,0.005946,0.006088,0.154636,0.223613,0.011391,1.546357,-120.320976,0.155615,0.000000
9.880000,0.072613,-120.365456,0.006088,0.006218,0.157948,0.322997,0.016454,1.579482,-120.365456,0.159120,0.000000
10.090000,0.054739,-120.365456,0.006239,0.006359,0.161514,0.243490,0.012404,1.615136,-120.365456,0.162605,0.000000
10.300000,0.059207,-120.276489,0.006394,0.006494,0.164956,0.263367,0.013417,1.649563,-120.276489,0.166108,0.000000
10.510000,0.067027,-120.320976,0.006549,0.006637,0.168590,0.298151,0.015189,1.685898,-120.320976,0.169613,0.000000
10.720000,0.068144,-120.232010,0.006679,0.006771,0.171989,0.303120,0.015442,1.719887,-120.232010,0.173117,0.000000
10.930000,0.068516,-120.276489,0.006838,0.006911,0.175527,0.304777,0.015526,1.755268,-120.276489,0.176603,0.000000
11.140000,0.111712,-120.320976,0.006972,0.007043,0.178892,0.496919,0.025314,1.788923,-120.320976,0.180106,0.000000
11.350000,0.112456,-120.232010,0.007153,0.007185,0.182500,0.500231,0.025483,1.825001,-120.232010,0.183610,0.000000
11.560000,0.132192,-120.276489,0.007278,0.007325,0.186055,0.588020,0.029955,1.860548,-120.276489,0.187096,0.000000
11.770000,0.144853,-120.187531,0.007437,0.007458,0.189437,0.644338,0.032824,1.894370,-120.187531,0.190600,0.000000
11.980000,0.164589,-120.187531,0.007562,0.007602,0.193098,0.732127,0.037296,1.930978,-120.187531,0.194103,0.000000
12.190001,0.170547,-120.187531,0.007705,0.007738,0.196548,0.758629,0.038646,1.965481,-120.187531,0.197606,0.000000
12.400001,0.207411,-120.143051,0.007856,0.007874,0.199992,0.922612,0.047000,1.999923,-120.143051,0.201093,0.000000
12.610001,0.248372,-120.187531,0.007981,0.008011,0.203477,1.104816,0.056282,2.034775,-120.187531,0.204596,0.000000
12.820001,0.367904,-120.187531,0.008123,0.008145,0.206894,1.636518,0.083368,2.068945,-120.187531,0.208100,0.000000
13.030001,0.556324,-120.187531,0.008257,0.008287,0.210486,2.474655,0.126065,2.104856,-120.187531,0.211586,0.000000
13.240001,0.673994,-120.143051,0.008295,-0.000000,-0.000000,2.998075,0.152729,-0.000000,-120.143051,0.000156,0.000000
13.450001,0.661333,-120.143051,0.008321,-0.000000,-0.000009,2.941758,0.149860,-0.000091,-120.143051,0.000156,0.000000
13.660001,0.665057,-120.187531,0.008330,-0.000000,-0.000009,2.958322,0.150704,-0.000091,-120.187531,0.000156,0.000000
13.870001,0.627448,-120.098564,0.008330,-0.000000,-0.000009,2.791026,0.142182,-0.000091,-120.098564,0.000477,0.000000
14.080001,0.627820,-120.143051,0.008300,0.000001,0.000017,2.792683,0.142266,0.000167,-120.143051,0.000824,0.000000
14.290001,0.660589,-120.143051,0.008308,0.000014,0.000347,2.938446,0.149692,0.003467,-120.143051,0.001170,0.000000
14.500001,0.645694,-120.098564,0.008351,0.000021,0.000528,2.872190,0.146316,0.005284,-120.098564,0.001526,0.000000
14.710001,0.679580,-120.098564,0.008351,0.000035,0.000893,3.022922,0.153995,0.008932,-120.098564,0.001873,0.000000
14.920001,0.711604,-120.054085,0.008364,0.000048,0.001214,3.165372,0.161252,0.012142,-120.054085,0.002229,0.000000
15.130001,0.822571,-120.054085,0.008369,0.000064,0.001638,3.658978,0.186397,0.016381,-120.054085,0.002575,0.000000
15.340001,0.856457,-120.054085,0.008351,0.000075,0.001917,3.809709,0.194076,0.019167,-120.054085,0.002922,0.000000
15.550001,0.865766,-120.009605,0.008407,0.000083,0.002115,3.851119,0.196185,0.021150,-120.009605,0.003278,0.000000
15.760001,0.926835,-120.098564,0.008382,0.000099,0.002506,4.122768,0.210024,0.025056,-120.098564,0.003624,0.000000
15.970001,0.969285,-120.009605,0.008412,0.000123,0.003122,4.311597,0.219643,0.031218,-120.009605,0.003971,0.000000
16.180000,1.009874,-120.009605,0.008420,0.000135,0.003425,4.492145,0.228841,0.034246,-120.009605,0.004327,0.000000
16.390001,1.010991,-120.009605,0.008433,0.000145,0.003694,4.497114,0.229094,0.036941,-120.009605,0.004674,0.000000
16.600000,1.060889,-119.965126,0.008446,0.000161,0.004085,4.719070,0.240401,0.040847,-119.965126,0.005020,0.000000
16.810001,1.097382,-120.009605,0.008446,0.000173,0.004397,4.881397,0.248670,0.043965,-120.009605,0.005376,0.000000
17.020000,1.155844,-119.920647,0.008459,0.000188,0.004778,5.141451,0.261918,0.047781,-119.920647,0.005723,0.000000
17.230001,1.219520,-119.965126,0.008468,0.000202,0.005143,5.424695,0.276347,0.051429,-119.965126,0.006079,0.000000
17.440001,1.261225,-119.920647,0.008464,0.000212,0.005394,5.610211,0.285798,0.053942,-119.920647,0.006425,0.000000
17.650002,1.305910,-119.965126,0.008476,0.000225,0.005723,5.808979,0.295923,0.057228,-119.965126,0.006772,0.000000
17.860001,1.383364,-119.920647,0.008485,0.000243,0.006183,6.153509,0.313475,0.061830,-119.920647,0.007128,0.000000
18.070002,1.428421,-119.831680,0.008558,0.000257,0.006539,6.353933,0.323685,0.065388,-119.831680,0.007474,0.000000
18.280001,1.474595,-119.920647,0.008537,0.000268,0.006816,6.559326,0.334148,0.068158,-119.920647,0.007823,0.000000
18.490002,1.530078,-119.831680,0.008545,0.000282,0.007163,6.806129,0.346721,0.071625,-119.831680,0.008177,0.000000
18.700001,1.581093,-119.876160,0.008554,0.000296,0.007527,7.033055,0.358281,0.075274,-119.876160,0.008525,0.000000
18.910002,1.654078,-119.920647,0.008550,0.000312,0.007926,7.357708,0.374820,0.079256,-119.920647,0.008872,0.000000
19.120001,1.712169,-119.876160,0.008576,0.000325,0.008265,7.616106,0.387983,0.082647,-119.876160,0.009228,0.000000
19.330002,1.792229,-119.831680,0.008567,0.000336,0.008525,7.972231,0.406125,0.085251,-119.831680,0.009574,0.000000
19.540001,1.866331,-119.831680,0.008545,0.000348,0.008837,8.301854,0.422917,0.088370,-119.831680,0.009930,0.000000
19.750000,2.007460,-119.787201,0.008619,0.000369,0.009384,8.929627,0.454897,0.093835,-119.787201,0.010277,0.000000
19.960001,2.073370,-119.787201,0.008623,0.000382,0.009712,9.222811,0.469832,0.097120,-119.787201,0.010623,0.000000
20.170000,2.123268,-119.787201,0.008619,0.000394,0.009998,9.444766,0.481139,0.099982,-119.787201,0.010979,0.000000
20.380001,2.185826,-119.831680,0.008658,0.000408,0.010363,9.723041,0.495315,0.103630,-119.831680,0.011326,0.000000
20.590000,2.285622,-119.787201,0.008662,0.000421,0.010684,10.166955,0.517929,0.106840,-119.787201,0.011673,0.000000
20.800001,2.435316,-119.787201,0.008653,0.000437,0.011109,10.832826,0.551850,0.111094,-119.787201,0.012028,0.000000
21.010000,2.563412,-119.742722,0.008679,0.000451,0.011447,11.402626,0.580877,0.114470,-119.742722,0.012375,0.000000
21.220001,2.604373,-119.698242,0.008692,0.000460,0.011673,11.584829,0.590159,0.116726,-119.698242,0.012722,0.000000
21.430000,2.654271,-119.742722,0.008705,0.000465,0.011819,11.806787,0.601466,0.118195,-119.742722,0.013078,0.000000
21.640001,2.784974,-119.742722,0.008709,0.000478,0.012140,12.388182,0.631084,0.121404,-119.742722,0.013424,0.000000
21.850000,3.110799,-119.742722,0.008714,0.000506,0.012843,13.837526,0.704917,0.128429,-119.742722,0.013771,0.000000
22.060001,3.231076,-119.787201,0.008761,0.000520,0.013199,14.372542,0.732172,0.131987,-119.787201,0.014127,0.000000
22.270000,3.344277,-119.653755,0.008765,0.000534,0.013554,14.876086,0.757824,0.135545,-119.653755,0.014473,0.000000
22.480001,3.443700,-119.698242,0.008770,0.000544,0.013815,15.318344,0.780354,0.138149,-119.698242,0.014829,0.000000
22.690001,3.556157,-119.609276,0.008795,0.000554,0.014075,15.818577,0.805837,0.140753,-119.609276,0.015176,0.000000
22.900002,3.873418,-119.698242,0.008817,0.000576,0.014638,17.229826,0.877729,0.146385,-119.698242,0.015523,0.000000
23.110001,3.966884,-119.653755,0.008843,0.000586,0.014890,17.645580,0.898909,0.148898,-119.653755,0.015878,0.000000
23.320002,4.038752,-119.653755,0.008817,0.000593,0.015071,17.965265,0.915194,0.150715,-119.653755,0.016225,0.000000
23.530001,4.271857,-119.609276,0.008843,0.000609,0.015462,19.002169,0.968017,0.154621,-119.609276,0.016572,0.000000
23.740002,4.666572,-119.564796,0.008864,0.000634,0.016095,20.757948,1.057460,0.160949,-119.564796,0.016928,0.000000
23.950001,4.825202,-119.609276,0.008899,0.000645,0.016373,21.463573,1.093406,0.163735,-119.609276,0.017274,0.000000
24.160002,4.905262,-119.609276,0.008886,0.000652,0.016572,21.819696,1.111548,0.165718,-119.609276,0.017621,0.000000
24.370001,5.138740,-119.564796,0.008899,0.000665,0.016902,22.858257,1.164455,0.169018,-119.564796,0.017977,0.000000
24.580002,5.469779,-119.564796,0.008916,0.000684,0.017362,24.330791,1.239470,0.173621,-119.564796,0.018323,0.000000
24.790001,5.646656,-119.520317,0.008938,0.000697,0.017709,25.117580,1.279550,0.177088,-119.520317,0.018679,0.000000
25.000002,5.926680,-119.564796,0.008933,0.000711,0.018065,26.363190,1.343005,0.180645,-119.564796,0.019026,0.000000
25.210001,6.044722,-119.564796,0.008959,0.000719,0.018272,26.888268,1.369754,0.182720,-119.564796,0.019374,0.000000
25.420002,6.331821,-119.564796,0.008942,0.000735,0.018663,28.165348,1.434811,0.186626,-119.564796,0.019728,0.000000
25.630001,6.710152,-119.564796,0.008968,0.000755,0.019165,29.848246,1.520542,0.191652,-119.564796,0.020077,0.000000
25.840002,6.959641,-119.475838,0.009007,0.000770,0.019547,30.958031,1.577077,0.195467,-119.475838,0.020423,0.000000
26.050001,7.106729,-119.564796,0.008998,0.000779,0.019790,31.612307,1.610408,0.197905,-119.564796,0.020779,0.000000
26.260002,7.374837,-119.475838,0.009028,0.000792,0.020128,32.804913,1.671162,0.201281,-119.475838,0.021126,0.000000
26.470001,7.704386,-119.386871,0.009033,0.000809,0.020561,34.270821,1.745839,0.205611,-119.386871,0.021472,0.000000
26.680002,7.954248,-119.475838,0.009050,0.000823,0.020900,35.382263,1.802458,0.209002,-119.475838,0.021828,0.000000
26.890001,8.105059,-119.431351,0.009063,0.000833,0.021161,36.053101,1.836632,0.211606,-119.431351,0.022175,0.000000
27.100000,8.374657,-119.431351,0.009080,0.000846,0.021482,37.252335,1.897724,0.214815,-119.431351,0.022531,0.000000
27.310001,8.584302,-119.431351,0.009063,0.000857,0.021759,38.184883,1.945231,0.217586,-119.431351,0.022877,0.000000
27.520000,9.122380,-119.431351,0.009132,0.000879,0.022331,40.578373,2.067161,0.223309,-119.431351,0.023224,0.000000
27.730001,9.378945,-119.431351,0.009093,0.000893,0.022687,41.719631,2.125299,0.226867,-119.431351,0.023580,0.000000
27.940001,9.501456,-119.342392,0.009110,0.000902,0.022903,42.264587,2.153061,0.229032,-119.342392,0.023927,0.000000
28.150002,9.848880,-119.431351,0.009132,0.000917,0.023285,43.810005,2.231788,0.232847,-119.431351,0.024273,0.000000
28.360001,10.025756,-119.342392,0.009132,0.000927,0.023545,44.596790,2.271869,0.235451,-119.342392,0.024629,0.000000
28.570002,10.407438,-119.386871,0.009158,0.000944,0.023970,46.294598,2.358359,0.239705,-119.386871,0.024976,0.000000
28.780001,10.641288,-119.297913,0.009184,0.000953,0.024204,47.334812,2.411350,0.242036,-119.297913,0.025322,0.000000
28.990002,10.820026,-119.297913,0.009214,0.000963,0.024455,48.129883,2.451853,0.244550,-119.297913,0.025678,0.000000
29.200001,11.140639,-119.386871,0.009184,0.000976,0.024802,49.556038,2.524505,0.248017,-119.386871,0.026025,0.000000
29.410002,11.408375,-119.342392,0.009214,0.000989,0.025123,50.746986,2.585175,0.251226,-119.342392,0.026372,0.000000
29.620001,12.115883,-119.297913,0.009222,0.001016,0.025808,53.894138,2.745498,0.258084,-119.297913,0.026727,0.000000
29.830002,12.257012,-119.253433,0.009222,0.001028,0.026111,54.521915,2.777479,0.261112,-119.253433,0.027074,0.000000
30.040001,12.477456,-119.297913,0.009253,0.001040,0.026425,55.502495,2.827432,0.264246,-119.297913,0.027430,0.000000
30.250002,12.809985,-119.342392,0.009257,0.001055,0.026797,56.981659,2.902784,0.267971,-119.342392,0.027777,0.000000
30.460001,12.941805,-119.253433,0.009278,0.001064,0.027014,57.568024,2.932655,0.270136,-119.253433,0.028123,0.000000
30.670002,13.351788,-119.253433,0.009291,0.001081,0.027448,59.391716,3.025558,0.274481,-119.253433,0.028479,0.000000
30.880001,13.717085,-119.208946,0.009296,0.001096,0.027830,61.016640,3.108336,0.278296,-119.208946,0.028826,0.000000
31.090002,13.887259,-119.208946,0.009313,0.001106,0.028081,61.773613,3.146898,0.280809,-119.208946,0.029172,0.000000
31.300001,14.189998,-119.208946,0.009309,0.001121,0.028470,63.120262,3.215499,0.284700,-119.208946,0.029528,0.000000
31.510002,14.471884,-119.164467,0.009343,0.001134,0.028800,64.374153,3.279376,0.288000,-119.164467,0.029875,0.000000
31.720001,15.041241,-119.208946,0.009347,0.001154,0.029312,66.906776,3.408394,0.293117,-119.208946,0.030223,0.000000
31.930002,15.063210,-119.208946,0.009356,0.001165,0.029589,67.004509,3.413372,0.295888,-119.208946,0.030577,0.000000
32.140003,15.468352,-119.164467,0.009395,0.001180,0.029963,68.806671,3.505179,0.299627,-119.164467,0.030926,0.000000
32.350002,15.514154,-119.164467,0.009386,0.001190,0.030214,69.010406,3.515558,0.302141,-119.164467,0.031280,0.000000
32.560001,15.881685,-119.164467,0.009390,0.001201,0.030509,70.645264,3.598841,0.305093,-119.164467,0.031628,0.000000
32.770000,16.373589,-119.119987,0.009429,0.001220,0.030994,72.833359,3.710308,0.309937,-119.119987,0.031975,0.000000
32.980003,16.392208,-119.119987,0.009421,0.001229,0.031212,72.916183,3.714528,0.312118,-119.119987,0.032329,0.000000
33.190002,16.651007,-119.119987,0.009459,0.001242,0.031549,74.067375,3.773172,0.315494,-119.119987,0.032677,0.000000
33.400002,17.304148,-119.075508,0.009494,0.001263,0.032087,76.972694,3.921176,0.320868,-119.075508,0.033024,0.000000
33.610001,17.491079,-119.075508,0.009485,0.001277,0.032443,77.804207,3.963535,0.324426,-119.075508,0.033380,0.000000
33.820004,17.657530,-119.119987,0.009503,0.001289,0.032729,78.544617,4.001254,0.327287,-119.119987,0.033726,0.000000
34.030003,17.686573,-119.031029,0.009494,0.001299,0.032989,78.673805,4.007834,0.329891,-119.031029,0.034073,0.000000
34.240002,17.992664,-119.031029,0.009494,0.001314,0.033371,80.035370,4.077196,0.333707,-119.031029,0.034429,0.000000
34.450001,18.433180,-119.075508,0.009516,0.001330,0.033787,81.994881,4.177019,0.337870,-119.075508,0.034776,0.000000
34.660000,18.749697,-119.031029,0.009541,0.001344,0.034134,83.402817,4.248742,0.341337,-119.031029,0.035131,0.000000
34.870003,18.797361,-119.075508,0.009528,0.001353,0.034368,83.614838,4.259543,0.343684,-119.075508,0.035478,0.000000
35.080002,19.206226,-119.031029,0.009576,0.001370,0.034810,85.433563,4.352193,0.348104,-119.031029,0.035825,0.000000
35.290001,19.662010,-118.986542,0.009602,0.001388,0.035243,87.460991,4.455475,0.352434,-118.986542,0.036181,0.000000
35.500000,19.873518,-119.031029,0.009589,0.001402,0.035616,88.401825,4.503404,0.356159,-119.031029,0.036527,0.000000
35.710003,20.048904,-118.986542,0.009610,0.001415,0.035929,89.181984,4.543147,0.359293,-118.986542,0.036874,0.000000
35.920002,19.943523,-118.986542,0.009606,0.001422,0.036128,88.713226,4.519267,0.361276,-118.986542,0.037230,0.000000
36.130001,20.324089,-118.942062,0.009623,0.001436,0.036476,90.406067,4.605505,0.364758,-118.942062,0.037576,0.000000
36.340000,20.674864,-118.942062,0.009653,0.001451,0.036848,91.966385,4.684991,0.368482,-118.942062,0.037923,0.000000
36.550003,21.050587,-118.986542,0.009623,0.001467,0.037255,93.637688,4.770131,0.372555,-118.986542,0.038279,0.000000
36.760002,21.120220,-118.942062,0.009658,0.001475,0.037472,93.947433,4.785910,0.374720,-118.942062,0.038626,0.000000
36.970001,21.260605,-118.942062,0.009675,0.001488,0.037802,94.571892,4.817722,0.378020,-118.942062,0.038972,0.000000
37.180000,21.745434,-118.853104,0.009697,0.001506,0.038253,96.728523,4.927586,0.382532,-118.853104,0.039328,0.000000
37.390003,22.376232,-118.897583,0.009740,0.001526,0.038756,99.534454,5.070527,0.387558,-118.897583,0.039675,0.000000
37.600002,22.439535,-118.942062,0.009714,0.001538,0.039060,99.816040,5.084871,0.390601,-118.942062,0.040031,0.000000
37.810001,22.413843,-118.853104,0.009757,0.001547,0.039286,99.701752,5.079050,0.392857,-118.853104,0.040377,0.000000
38.020000,22.911331,-118.942062,0.009740,0.001564,0.039735,101.914688,5.191782,0.397353,-118.942062,0.040724,0.000000
38.230003,23.202154,-118.853104,0.009744,0.001579,0.040117,103.208336,5.257683,0.401169,-118.853104,0.041080,0.000000
38.440002,23.554047,-118.853104,0.009783,0.001594,0.040498,104.773636,5.337423,0.404984,-118.853104,0.041426,0.000000
38.650002,23.640810,-118.942062,0.009779,0.001604,0.040751,105.159576,5.357084,0.407512,-118.942062,0.041775,0.000000
38.860001,23.971476,-118.808617,0.009800,0.001618,0.041089,106.630447,5.432014,0.410888,-118.808617,0.042129,0.000000
39.070004,24.410875,-118.808617,0.009817,0.001635,0.041522,108.584999,5.531583,0.415218,-118.808617,0.042476,0.000000
39.280003,24.664833,-118.719658,0.009822,0.001648,0.041861,109.714661,5.589131,0.418609,-118.719658,0.042824,0.000000
39.490002,25.023056,-118.764137,0.009852,0.001663,0.042233,111.308113,5.670306,0.422334,-118.764137,0.043178,0.000000
39.700001,24.900919,-118.764137,0.009878,0.001669,0.042380,110.764816,5.642629,0.423802,-118.764137,0.043526,0.000000
39.910004,25.253927,-118.719658,0.009856,0.001685,0.042797,112.335075,5.722622,0.427966,-118.719658,0.043881,0.000000
40.120003,25.616617,-118.808617,0.009878,0.001699,0.043152,113.948402,5.804808,0.431523,-118.808617,0.044229,0.000000
40.330002,26.217255,-118.675179,0.009929,0.001716,0.043594,116.620171,5.940915,0.435944,-118.675179,0.044575,0.000000
40.540001,26.386312,-118.764137,0.009895,0.001728,0.043890,117.372177,5.979224,0.438896,-118.764137,0.044931,0.000000
40.750004,26.494673,-118.764137,0.009929,0.001737,0.044124,117.854187,6.003779,0.441243,-118.764137,0.045278,0.000000
40.960003,26.768738,-118.675179,0.009934,0.001751,0.044488,119.073296,6.065883,0.444877,-118.675179,0.045625,0.000000
41.170002,27.565243,-118.719658,0.009951,0.001772,0.045018,122.616325,6.246373,0.450175,-118.719658,0.045980,0.000000
41.380001,27.860163,-118.630699,0.009973,0.001787,0.045390,123.928192,6.313203,0.453900,-118.630699,0.046327,0.000000
41.590000,27.988258,-118.675179,0.009990,0.001799,0.045685,124.497993,6.342230,0.456852,-118.675179,0.046674,0.000000
41.800003,28.415369,-118.675179,0.009985,0.001814,0.046076,126.397873,6.439015,0.460758,-118.675179,0.047030,0.000000
42.010002,28.562084,-118.675179,0.010011,0.001825,0.046353,127.050499,6.472261,0.463529,-118.675179,0.047376,0.000000
42.220001,29.089363,-118.675179,0.009990,0.001842,0.046778,129.395950,6.591744,0.467783,-118.675179,0.047732,0.000000
42.430000,29.359333,-118.630699,0.010007,0.001853,0.047072,130.596832,6.652920,0.470720,-118.630699,0.048079,0.000000
42.640003,29.406998,-118.630699,0.010024,0.001861,0.047263,130.808853,6.663721,0.472627,-118.630699,0.048425,0.000000
42.850002,29.648666,-118.630699,0.010029,0.001872,0.047549,131.883850,6.718484,0.475489,-118.630699,0.048781,0.000000
43.060001,29.838577,-118.630699,0.010063,0.001885,0.047870,132.728622,6.761518,0.478698,-118.630699,0.049128,0.000000
43.270000,31.101292,-118.630699,0.010072,0.001909,0.048495,138.345459,7.047653,0.484951,-118.630699,0.049475,0.000000
43.480003,31.322853,-118.586212,0.010067,0.001920,0.048763,139.331009,7.097860,0.487631,-118.586212,0.049830,0.000000
43.690002,31.734697,-118.541733,0.010115,0.001936,0.049179,141.162979,7.191185,0.491794,-118.541733,0.050177,0.000000
43.900002,31.935034,-118.541733,0.010119,0.001946,0.049432,142.054123,7.236582,0.494322,-118.541733,0.050524,0.000000
44.110001,32.714039,-118.541733,0.010085,0.001966,0.049935,145.519318,7.413107,0.499349,-118.541733,0.050880,0.000000
44.320004,32.987362,-118.586212,0.010111,0.001977,0.050221,146.735107,7.475043,0.502210,-118.586212,0.051226,0.000000
44.530003,33.084179,-118.452774,0.010123,0.001988,0.050489,147.165771,7.496982,0.504890,-118.452774,0.051582,0.000000
44.740002,33.332550,-118.497253,0.010171,0.001997,0.050733,148.270584,7.553264,0.507327,-118.497253,0.051929,0.000000
44.950001,34.256405,-118.497253,0.010154,0.002021,0.051331,152.380096,7.762612,0.513307,-118.497253,0.052275,0.000000
45.160004,34.892418,-118.497253,0.010188,0.002036,0.051712,155.209229,7.906735,0.517123,-118.497253,0.052631,0.000000
45.370003,34.998543,-118.541733,0.010210,0.002046,0.051973,155.681290,7.930783,0.519727,-118.541733,0.052978,0.000000
45.580002,35.354904,-118.408295,0.010214,0.002058,0.052285,157.266464,8.011536,0.522845,-118.408295,0.053325,0.000000
45.790001,36.013260,-118.452774,0.010227,0.002075,0.052701,160.194977,8.160722,0.527009,-118.452774,0.053680,0.000000
46.000004,36.512611,-118.408295,0.010240,0.002090,0.053073,162.416214,8.273876,0.530733,-118.408295,0.054027,0.000000
46.210003,36.791519,-118.452774,0.010253,0.002099,0.053325,163.656845,8.337077,0.533246,-118.452774,0.054375,0.000000
46.420002,37.170219,-118.363808,0.010257,0.002112,0.053655,165.341400,8.422892,0.536547,-118.363808,0.054730,0.000000
46.630001,37.158306,-118.363808,0.010248,0.002118,0.053803,165.288406,8.420192,0.538030,-118.363808,0.055078,0.000000
46.840004,38.197968,-118.408295,0.010274,0.002142,0.054401,169.913040,8.655784,0.544011,-118.408295,0.055424,0.000000
47.050003,39.093525,-118.363808,0.010317,0.002161,0.054895,173.896683,8.858720,0.548946,-118.363808,0.055780,0.000000
47.260002,39.256622,-118.408295,0.010317,0.002170,0.055111,174.622177,8.895678,0.551111,-118.408295,0.056127,0.000000
47.470001,39.658413,-118.408295,0.010309,0.002184,0.055467,176.409424,8.986725,0.554669,-118.408295,0.056483,0.000000
47.680004,40.012165,-118.319328,0.010309,0.002195,0.055753,177.983002,9.066887,0.557530,-118.319328,0.056829,0.000000
47.890003,40.998211,-118.319328,0.010322,0.002216,0.056274,182.369156,9.290327,0.562738,-118.319328,0.057176,0.000000
48.100002,41.233921,-118.230370,0.010352,0.002226,0.056534,183.417648,9.343740,0.565342,-118.230370,0.057532,0.000000
48.310001,41.450642,-118.319328,0.010378,0.002236,0.056786,184.381668,9.392850,0.567855,-118.319328,0.057879,0.000000
48.520000,41.988346,-118.319328,0.010386,0.002249,0.057116,186.773499,9.514695,0.571156,-118.319328,0.058225,0.000000
48.730003,42.817993,-118.230370,0.010369,0.002267,0.057583,190.463943,9.702696,0.575834,-118.230370,0.058581,0.000000
48.940002,43.670727,-118.274849,0.010382,0.002285,0.058044,194.257095,9.895928,0.580436,-118.274849,0.058928,0.000000
49.150002,43.855423,-118.274849,0.010412,0.002293,0.058251,195.078659,9.937781,0.582510,-118.274849,0.059274,0.000000
49.360001,44.319027,-118.319328,0.010430,0.002306,0.058572,197.140884,10.042835,0.585720,-118.319328,0.059630,0.000000
49.570004,44.765129,-118.230370,0.010417,0.002319,0.058902,199.125244,10.143923,0.589020,-118.230370,0.059977,0.000000
49.780003,45.128937,-118.230370,0.010447,0.002330,0.059179,200.743530,10.226363,0.591791,-118.230370,0.060333,0.000000
49.990002,46.194668,-118.230370,0.010451,0.002349,0.059665,205.484146,10.467862,0.596651,-118.230370,0.060679,0.000000
50.200001,46.395748,-118.230370,0.010442,0.002359,0.059925,206.378601,10.513427,0.599255,-118.230370,0.061026,0.000000
50.410004,46.678005,-118.230370,0.010477,0.002369,0.060177,207.634140,10.577387,0.601768,-118.230370,0.061382,0.000000
50.620003,47.321465,-118.230370,0.010468,0.002381,0.060489,210.496384,10.723198,0.604887,-118.230370,0.061729,0.000000
50.830002,48.011471,-118.141403,0.010486,0.002401,0.060975,213.565689,10.879555,0.609747,-118.141403,0.062075,0.000000
51.040001,49.214607,-118.185890,0.010486,0.002420,0.061461,218.917511,11.152189,0.614606,-118.185890,0.062431,0.000000
51.250004,49.635761,-118.096924,0.010516,0.002432,0.061773,220.790894,11.247624,0.617725,-118.096924,0.062778,0.000000
51.460003,50.055424,-118.141403,0.010533,0.002444,0.062066,222.657639,11.342721,0.620662,-118.141403,0.063124,0.000000
51.670002,50.555149,-118.141403,0.010511,0.002454,0.062336,224.880539,11.455960,0.623357,-118.141403,0.063480,0.000000
51.880001,51.453312,-118.096924,0.010533,0.002472,0.062787,228.875763,11.659487,0.627869,-118.096924,0.063827,0.000000
52.090004,52.113899,-118.096924,0.010555,0.002488,0.063185,231.814209,11.809178,0.631850,-118.096924,0.064183,0.000000
52.300003,52.561493,-118.052444,0.010550,0.002497,0.063429,233.805191,11.910604,0.634288,-118.052444,0.064529,0.000000
52.510002,52.927162,-118.096924,0.010580,0.002511,0.063775,235.431778,11.993466,0.637755,-118.096924,0.064876,0.000000
52.720001,53.730740,-118.052444,0.010576,0.002525,0.064131,239.006271,12.175559,0.641313,-118.052444,0.065232,0.000000
52.930004,54.407715,-118.096924,0.010580,0.002542,0.064564,242.017609,12.328964,0.645643,-118.096924,0.065579,0.000000
53.140003,55.311832,-118.141403,0.010589,0.002557,0.064946,246.039322,12.533840,0.649458,-118.141403,0.065927,0.000000
53.350002,55.550896,-117.963486,0.010615,0.002567,0.065197,247.102722,12.588014,0.651971,-117.963486,0.066281,0.000000
53.560001,56.357456,-118.052444,0.010615,0.002582,0.065588,250.690491,12.770782,0.655877,-118.052444,0.066629,0.000000
53.770004,56.572689,-118.052444,0.010619,0.002590,0.065778,251.647888,12.819554,0.657784,-118.052444,0.066976,0.000000
53.980003,57.656662,-118.007965,0.010632,0.002607,0.066221,256.469635,13.065187,0.662205,-118.007965,0.067332,0.000000
54.190002,58.397312,-117.963486,0.010632,0.002621,0.066576,259.764221,13.233020,0.665763,-117.963486,0.067678,0.000000
54.400002,58.894428,-117.918999,0.010658,0.002633,0.066881,261.975494,13.345669,0.668806,-117.918999,0.068025,0.000000
54.610004,59.633961,-118.052444,0.010662,0.002651,0.067332,265.265106,13.513248,0.673318,-118.052444,0.068381,0.000000
54.820004,60.859440,-117.963486,0.010688,0.002669,0.067790,270.716309,13.790946,0.677905,-117.963486,0.068728,0.000000
55.030003,61.345387,-117.963486,0.010697,0.002680,0.068077,272.877899,13.901063,0.680766,-117.963486,0.069083,0.000000
55.240002,61.614609,-118.007965,0.010680,0.002687,0.068258,274.075470,13.962070,0.682583,-118.007965,0.069430,0.000000
55.450001,62.224186,-117.918999,0.010718,0.002703,0.068658,276.787018,14.100202,0.686580,-117.918999,0.069777,0.000000
55.660004,63.018826,-118.007965,0.010723,0.002716,0.068988,280.321747,14.280271,0.689880,-118.007965,0.070133,0.000000
55.870003,64.245796,-117.918999,0.010727,0.002737,0.069516,285.779572,14.558306,0.695164,-117.918999,0.070479,0.000000
56.080002,64.528053,-117.963486,0.010731,0.002745,0.069733,287.035126,14.622266,0.697329,-117.963486,0.070826,0.000000
56.290001,65.198692,-117.918999,0.010731,0.002759,0.070080,290.018280,14.774235,0.700796,-117.918999,0.071182,0.000000
56.500004,66.220482,-117.874519,0.010757,0.002775,0.070488,294.563416,15.005776,0.704884,-117.874519,0.071528,0.000000
56.710003,66.966347,-117.874519,0.010740,0.002791,0.070887,297.881195,15.174790,0.708865,-117.874519,0.071875,0.000000
56.920002,67.241158,-117.830040,0.010783,0.002791,0.070887,299.103607,15.237064,0.708865,-117.830040,0.071068,0.000000
57.130001,66.784996,-117.830040,0.010792,0.002790,0.070861,297.074493,15.133697,0.708608,-117.830040,0.071068,0.000000
57.340004,66.454704,-117.830040,0.010787,0.002789,0.070843,295.605286,15.058851,0.708426,-117.830040,0.070861,0.000000
57.550003,66.161278,-117.785561,0.010774,0.002788,0.070826,294.300049,14.992360,0.708260,-117.785561,0.070861,0.000000
57.760002,65.922585,-117.874519,0.010805,0.002788,0.070817,293.238312,14.938271,0.708169,-117.874519,0.070861,0.000000
57.970001,65.707726,-117.785561,0.010787,0.002788,0.070809,292.282562,14.889584,0.708093,-117.785561,0.070861,0.000000
58.180004,65.526382,-117.830040,0.010792,0.002787,0.070800,291.475922,14.848491,0.708002,-117.830040,0.070861,0.000000
58.390003,65.350250,-117.785561,0.010770,0.002787,0.070800,290.692444,14.808578,0.708002,-117.785561,0.070861,0.000000
58.600002,65.192734,-117.785561,0.010800,0.002787,0.070800,289.991760,14.772885,0.708002,-117.785561,0.070861,0.000000
58.810001,65.049370,-117.785561,0.010796,0.002787,0.070791,289.354034,14.740397,0.707912,-117.785561,0.070861,0.000000
59.020004,64.917923,-117.696594,0.010800,0.002787,0.070791,288.769348,14.710611,0.707912,-117.696594,0.070861,0.000000
59.230003,64.797279,-117.785561,0.010796,0.002787,0.070791,288.232697,14.683273,0.707912,-117.785561,0.070861,0.000000
59.440002,64.687798,-117.785561,0.010787,0.002787,0.070791,287.745697,14.658464,0.707912,-117.785561,0.070861,0.000000
59.650002,64.580559,-117.696594,0.010813,0.002787,0.070791,287.268677,14.634164,0.707912,-117.696594,0.070861,0.000000
59.860004,64.479271,-117.785561,0.010792,0.002787,0.070791,286.818115,14.611212,0.707912,-117.785561,0.070861,0.000000
60.070004,64.404427,-117.652115,0.010783,0.002787,0.070782,286.485199,14.594252,0.707821,-117.652115,0.070861,0.000000
60.280003,64.320641,-117.696594,0.010800,0.002787,0.070782,286.112488,14.575265,0.707821,-117.696594,0.070861,0.000000
60.490002,64.213020,-117.696594,0.010796,0.002787,0.070782,285.633789,14.550879,0.707821,-117.696594,0.070861,0.000000
60.700005,64.150841,-117.652115,0.010796,0.002787,0.070782,285.357178,14.536788,0.707821,-117.652115,0.070861,0.000000
60.910004,64.070030,-117.785561,0.010783,0.002787,0.070782,284.997742,14.518476,0.707821,-117.785561,0.070861,0.000000
61.120003,64.004494,-117.607635,0.010818,0.002787,0.070782,284.706207,14.503626,0.707821,-117.607635,0.070861,0.000000
61.330002,63.934120,-117.607635,0.010774,0.002787,0.070782,284.393158,14.487679,0.707821,-117.607635,0.070861,0.000000
61.540005,63.876030,-117.607635,0.010774,0.002787,0.070782,284.134766,14.474516,0.707821,-117.607635,0.070861,0.000000
61.750004,63.807140,-117.607635,0.010805,0.002787,0.070782,283.828339,14.458904,0.707821,-117.607635,0.070861,0.000000
61.960003,63.749050,-117.652115,0.010826,0.002787,0.070782,283.569946,14.445742,0.707821,-117.652115,0.070861,0.000000
62.170002,63.691704,-117.563156,0.010809,0.002787,0.070782,283.314850,14.432747,0.707821,-117.563156,0.070861,0.000000
62.380001,63.625423,-117.607635,0.010813,0.002787,0.070782,283.020020,14.417727,0.707821,-117.607635,0.070861,0.000000
62.590004,63.578876,-117.607635,0.010813,0.002787,0.070782,282.812958,14.407179,0.707821,-117.607635,0.070861,0.000000
62.800003,63.533447,-117.518669,0.010800,0.002787,0.070782,282.610901,14.396885,0.707821,-117.518669,0.070861,0.000000
63.010002,63.487270,-117.607635,0.010787,0.002787,0.070782,282.405487,14.386421,0.707821,-117.607635,0.070861,0.000000
63.220001,63.442589,-117.518669,0.010805,0.002787,0.070782,282.206726,14.376296,0.707821,-117.518669,0.070861,0.000000
63.430004,63.389709,-117.607635,0.010796,0.002787,0.070782,281.971497,14.364313,0.707821,-117.607635,0.070861,0.000000
63.640003,63.340557,-117.518669,0.010818,0.002786,0.070775,281.752869,14.353175,0.707745,-117.518669,0.070861,0.000000
63.850002,63.315235,-117.518669,0.010800,0.002786,0.070775,281.640228,14.347438,0.707745,-117.518669,0.070861,0.000000
64.060005,63.273903,-117.563156,0.010818,0.002786,0.070775,281.456390,14.338072,0.707745,-117.563156,0.070861,0.000000
64.270004,63.233315,-117.429710,0.010800,0.002786,0.070775,281.275818,14.328875,0.707745,-117.429710,0.070861,0.000000
64.480003,63.186024,-117.474190,0.010792,0.002786,0.070775,281.065460,14.318158,0.707745,-117.474190,0.070861,0.000000
64.690002,63.147667,-117.474190,0.010826,0.002786,0.070775,280.894836,14.309465,0.707745,-117.474190,0.070861,0.000000
64.900002,63.107079,-117.518669,0.010818,0.002786,0.070775,280.714294,14.300268,0.707745,-117.518669,0.070861,0.000000
65.110001,63.060905,-117.429710,0.010792,0.002786,0.070775,280.508911,14.289805,0.707745,-117.429710,0.070861,0.000000
65.320000,63.024040,-117.385231,0.010800,0.002786,0.070775,280.344940,14.281451,0.707745,-117.385231,0.070861,0.000000
65.530006,62.973026,-117.429710,0.010809,0.002786,0.070775,280.118011,14.269892,0.707745,-117.429710,0.070861,0.000000
65.740005,62.948822,-117.429710,0.010792,0.002786,0.070775,280.010345,14.264406,0.707745,-117.429710,0.070861,0.000000
65.950005,62.935417,-117.340752,0.010809,0.002786,0.070775,279.950714,14.261370,0.707745,-117.340752,0.070861,0.000000
66.160004,62.900414,-117.429710,0.010818,0.002786,0.070775,279.795013,14.253437,0.707745,-117.429710,0.070861,0.000000
66.370003,62.861687,-117.340752,0.010809,0.002786,0.070775,279.622742,14.244662,0.707745,-117.340752,0.070861,0.000000
66.580002,62.831898,-117.385231,0.010813,0.002786,0.070775,279.490234,14.237911,0.707745,-117.385231,0.070861,0.000000
66.790001,62.796520,-117.340752,0.010792,0.002786,0.070775,279.332886,14.229895,0.707745,-117.340752,0.070861,0.000000
67.000000,62.774921,-117.340752,0.010813,0.002786,0.070775,279.236786,14.225000,0.707745,-117.340752,0.070861,0.000000
67.210007,62.739548,-117.340752,0.010774,0.002786,0.070775,279.079437,14.216985,0.707745,-117.340752,0.070861,0.000000
67.420006,62.708267,-117.296265,0.010813,0.002786,0.070775,278.940308,14.209896,0.707745,-117.296265,0.070861,0.000000
67.630005,62.672894,-117.296265,0.010792,0.002786,0.070775,278.782959,14.201880,0.707745,-117.296265,0.070861,0.000000
67.840004,62.661350,-117.296265,0.010835,0.002786,0.070775,278.731598,14.199265,0.707745,-117.296265,0.070861,0.000000
68.050003,62.621132,-117.296265,0.010809,0.002786,0.070775,278.552704,14.190151,0.707745,-117.296265,0.070861,0.000000
68.260002,62.598045,-117.296265,0.010822,0.002786,0.070775,278.450012,14.184919,0.707745,-117.296265,0.070861,0.000000
68.470001,62.569744,-117.207306,0.010818,0.002786,0.070775,278.324127,14.178507,0.707745,-117.207306,0.070861,0.000000
68.680000,62.545540,-117.296265,0.010822,0.002786,0.070775,278.216461,14.173021,0.707745,-117.296265,0.070861,0.000000
68.890007,62.521336,-117.251785,0.010826,0.002786,0.070775,278.108795,14.167537,0.707745,-117.251785,0.070861,0.000000
69.100006,62.490059,-117.207306,0.010818,0.002786,0.070775,277.969666,14.160450,0.707745,-117.207306,0.070861,0.000000
69.310005,62.473675,-117.296265,0.010831,0.002786,0.070775,277.896790,14.156737,0.707745,-117.296265,0.070861,0.000000
69.520004,62.449841,-117.207306,0.010813,0.002786,0.070775,277.790771,14.151336,0.707745,-117.207306,0.070861,0.000000
69.730003,62.423405,-117.207306,0.010800,0.002786,0.070775,277.673187,14.145346,0.707745,-117.207306,0.070861,0.000000
69.940002,62.404041,-117.162827,0.010787,0.002786,0.070775,277.587036,14.140959,0.707745,-117.162827,0.070861,0.000000
70.150002,62.383560,-117.118347,0.010792,0.002786,0.070775,277.495941,14.136316,0.707745,-117.118347,0.070861,0.000000
70.360001,62.350044,-117.118347,0.010818,0.002786,0.070775,277.346863,14.128721,0.707745,-117.118347,0.070861,0.000000
70.570000,62.338501,-117.118347,0.010800,0.002786,0.070775,277.295502,14.126106,0.707745,-117.118347,0.070861,0.000000
70.780006,62.313927,-117.162827,0.010818,0.002786,0.070775,277.186188,14.120538,0.707745,-117.162827,0.070861,0.000000
70.990005,62.296425,-117.162827,0.010800,0.002786,0.070775,277.108337,14.116571,0.707745,-117.162827,0.070861,0.000000
71.200005,62.268124,-117.118347,0.010813,0.002786,0.070775,276.982452,14.110159,0.707745,-117.118347,0.070861,0.000000
71.410004,62.259560,-117.162827,0.010813,0.002786,0.070775,276.944366,14.108218,0.707745,-117.162827,0.070861,0.000000
71.620003,62.227161,-117.118347,0.010818,0.002786,0.070775,276.800232,14.100876,0.707745,-117.118347,0.070861,0.000000
71.830002,62.228279,-117.029381,0.010826,0.002786,0.070775,276.805206,14.101130,0.707745,-117.029381,0.070861,0.000000
72.040001,62.185829,-117.029381,0.010822,0.002786,0.070775,276.616394,14.091510,0.707745,-117.029381,0.070861,0.000000
72.250000,62.169445,-117.073860,0.010822,0.002786,0.070775,276.543518,14.087798,0.707745,-117.073860,0.070861,0.000000
72.460007,62.150455,-117.029381,0.010792,0.002786,0.070775,276.459045,14.083495,0.707745,-117.029381,0.070861,0.000000
72.670006,62.145615,-117.029381,0.010800,0.002786,0.070775,276.437500,14.082398,0.707745,-117.029381,0.070861,0.000000
72.880005,62.119549,-117.073860,0.010800,0.002786,0.070775,276.321564,14.076490,0.707745,-117.073860,0.070861,0.000000
73.090004,62.096088,-116.984901,0.010792,0.002786,0.070775,276.217194,14.071175,0.707745,-116.984901,0.070861,0.000000
73.300003,62.069649,-117.073860,0.010800,0.002786,0.070775,276.099579,14.065184,0.707745,-117.073860,0.070861,0.000000
73.510002,62.068161,-117.029381,0.010822,0.002786,0.070775,276.092957,14.064847,0.707745,-117.029381,0.070861,0.000000
73.720001,62.042095,-117.029381,0.010835,0.002786,0.070775,275.977020,14.058939,0.707745,-117.029381,0.070861,0.000000
73.930000,62.032784,-117.029381,0.010826,0.002786,0.070775,275.935608,14.056829,0.707745,-117.029381,0.070861,0.000000
74.140007,62.011189,-116.895943,0.010805,0.002786,0.070775,275.839539,14.051936,0.707745,-116.895943,0.070861,0.000000
74.350006,62.009327,-116.984901,0.010813,0.002786,0.070775,275.831268,14.051514,0.707745,-116.984901,0.070861,0.000000
74.560005,61.978420,-116.940422,0.010818,0.002786,0.070775,275.693787,14.044511,0.707745,-116.940422,0.070861,0.000000
74.770004,61.963524,-116.940422,0.010818,0.002786,0.070775,275.627533,14.041135,0.707745,-116.940422,0.070861,0.000000
74.980003,61.951607,-116.895943,0.010831,0.002786,0.070775,275.574524,14.038435,0.707745,-116.895943,0.070861,0.000000
75.190002,61.938576,-116.851456,0.010826,0.002786,0.070775,275.516541,14.035481,0.707745,-116.851456,0.070861,0.000000
75.400002,61.917351,-116.940422,0.010792,0.002786,0.070765,275.422119,14.030672,0.707654,-116.940422,0.070861,0.000000
75.610001,61.894634,-116.895943,0.010809,0.002786,0.070765,275.321075,14.025524,0.707654,-116.895943,0.070861,0.000000
75.820007,61.892029,-116.895943,0.010800,0.002786,0.070765,275.309509,14.024935,0.707654,-116.895943,0.070861,0.000000
76.030006,61.868195,-116.895943,0.010796,0.002786,0.070765,275.203461,14.019534,0.707654,-116.895943,0.070861,0.000000
76.240005,61.847717,-116.806976,0.010796,0.002786,0.070765,275.112396,14.014893,0.707654,-116.806976,0.070861,0.000000
76.450005,61.827980,-116.806976,0.010805,0.002786,0.070765,275.024597,14.010421,0.707654,-116.806976,0.070861,0.000000
76.660004,61.827236,-116.762497,0.010796,0.002786,0.070765,275.021271,14.010252,0.707654,-116.762497,0.070861,0.000000
76.870003,61.812340,-116.806976,0.010835,0.002786,0.070765,274.955017,14.006877,0.707654,-116.806976,0.070861,0.000000
77.080002,61.799309,-116.806976,0.010809,0.002786,0.070765,274.897064,14.003923,0.707654,-116.806976,0.070861,0.000000
77.290001,61.792606,-116.762497,0.010835,0.002786,0.070765,274.867249,14.002404,0.707654,-116.762497,0.070861,0.000000
77.500000,61.770634,-116.806976,0.010826,0.002786,0.070765,274.769501,13.997426,0.707654,-116.806976,0.070861,0.000000
77.710007,61.762070,-116.806976,0.010787,0.002786,0.070765,274.731415,13.995485,0.707654,-116.806976,0.070861,0.000000
77.920006,61.742706,-116.851456,0.010805,0.002786,0.070765,274.645264,13.991097,0.707654,-116.851456,0.070861,0.000000
78.130005,61.740471,-116.762497,0.010792,0.002786,0.070765,274.635345,13.990591,0.707654,-116.762497,0.070861,0.000000
78.340004,61.715523,-116.762497,0.010831,0.002786,0.070765,274.524353,13.984938,0.707654,-116.762497,0.070861,0.000000
78.550003,61.689831,-116.718018,0.010835,0.002786,0.070765,274.410065,13.979115,0.707654,-116.718018,0.070861,0.000000
78.760002,61.689831,-116.718018,0.010818,0.002786,0.070765,274.410065,13.979115,0.707654,-116.718018,0.070861,0.000000
78.970001,61.678658,-116.718018,0.010792,0.002786,0.070765,274.360382,13.976583,0.707654,-116.718018,0.070861,0.000000
79.180000,61.665627,-116.718018,0.010843,0.002786,0.070765,274.302399,13.973630,0.707654,-116.718018,0.070861,0.000000
79.390007,61.649612,-116.673538,0.010835,0.002786,0.070765,274.231171,13.970002,0.707654,-116.673538,0.070861,0.000000
79.600006,61.645889,-116.718018,0.010792,0.002786,0.070765,274.214600,13.969158,0.707654,-116.718018,0.070861,0.000000
79.810005,61.620567,-116.629051,0.010813,0.002786,0.070765,274.101959,13.963420,0.707654,-116.629051,0.070861,0.000000
80.020004,61.612747,-116.629051,0.010818,0.002786,0.070765,274.067200,13.961648,0.707654,-116.629051,0.070861,0.000000
80.230003,61.599342,-116.629051,0.010787,0.002786,0.070765,274.007568,13.958611,0.707654,-116.629051,0.070861,0.000000
80.440002,61.591152,-116.629051,0.010826,0.002786,0.070765,273.971130,13.956755,0.707654,-116.629051,0.070861,0.000000
80.650002,61.574768,-116.629051,0.010813,0.002786,0.070765,273.898254,13.953041,0.707654,-116.629051,0.070861,0.000000
80.860001,61.565456,-116.629051,0.010818,0.002786,0.070765,273.856842,13.950932,0.707654,-116.629051,0.070861,0.000000
81.070007,61.555405,-116.584572,0.010822,0.002786,0.070765,273.812103,13.948654,0.707654,-116.584572,0.070861,0.000000
81.280006,61.533432,-116.584572,0.010792,0.002786,0.070765,273.714386,13.943675,0.707654,-116.584572,0.070861,0.000000
81.490005,61.528591,-116.584572,0.010822,0.002786,0.070765,273.692841,13.942577,0.707654,-116.584572,0.070861,0.000000
81.700005,61.517422,-116.584572,0.010826,0.002786,0.070765,273.643158,13.940046,0.707654,-116.584572,0.070861,0.000000
81.910004,61.524124,-116.584572,0.010809,0.002786,0.070765,273.672974,13.941566,0.707654,-116.584572,0.070861,0.000000
82.120003,61.488003,-116.584572,0.010805,0.002786,0.070765,273.512299,13.933380,0.707654,-116.584572,0.070861,0.000000
82.330002,61.495079,-116.495613,0.010818,0.002786,0.070765,273.543762,13.934983,0.707654,-116.495613,0.070861,0.000000
82.540001,61.474972,-116.540092,0.010826,0.002786,0.070765,273.454346,13.930429,0.707654,-116.540092,0.070861,0.000000
82.750008,61.467522,-116.540092,0.010831,0.002786,0.070765,273.421204,13.928740,0.707654,-116.540092,0.070861,0.000000
82.960007,61.463055,-116.495613,0.010800,0.002786,0.070765,273.401337,13.927728,0.707654,-116.495613,0.070861,0.000000
83.170006,61.444809,-116.540092,0.010822,0.002786,0.070765,273.320160,13.923593,0.707654,-116.540092,0.070861,0.000000
83.380005,61.425819,-116.495613,0.010800,0.002786,0.070765,273.235687,13.919290,0.707654,-116.495613,0.070861,0.000000
83.590004,61.413528,-116.495613,0.010792,0.002786,0.070765,273.181030,13.916505,0.707654,-116.495613,0.070861,0.000000
83.800003,61.399380,-116.451126,0.010822,0.002786,0.070765,273.118073,13.913298,0.707654,-116.451126,0.070861,0.000000
84.010002,61.415020,-116.451126,0.010796,0.002786,0.070765,273.187653,13.916842,0.707654,-116.451126,0.070861,0.000000
84.220001,61.389324,-116.451126,0.010783,0.002786,0.070765,273.073364,13.911019,0.707654,-116.451126,0.070861,0.000000
84.430000,61.386719,-116.406647,0.010813,0.002786,0.070765,273.061768,13.910429,0.707654,-116.406647,0.070861,0.000000
84.640007,61.384857,-116.362167,0.010822,0.002786,0.070765,273.053467,13.910007,0.707654,-116.362167,0.070861,0.000000
84.850006,61.377037,-116.451126,0.010805,0.002786,0.070765,273.018707,13.908235,0.707654,-116.451126,0.070861,0.000000
85.060005,61.353951,-116.406647,0.010822,0.002786,0.070765,272.916016,13.903004,0.707654,-116.406647,0.070861,0.000000
85.270004,61.326767,-116.406647,0.010826,0.002786,0.070765,272.795074,13.896844,0.707654,-116.406647,0.070861,0.000000
85.480003,61.331982,-116.362167,0.010839,0.002786,0.070765,272.818268,13.898026,0.707654,-116.362167,0.070861,0.000000
85.690002,61.314106,-116.406647,0.010818,0.002786,0.070765,272.738770,13.893974,0.707654,-116.406647,0.070861,0.000000
85.900002,61.311871,-116.317688,0.010822,0.002786,0.070765,272.728821,13.893468,0.707654,-116.317688,0.070861,0.000000
86.110001,61.310753,-116.273209,0.010800,0.002786,0.070765,272.723846,13.893215,0.707654,-116.273209,0.070861,0.000000
86.320007,61.285805,-116.362167,0.010826,0.002786,0.070765,272.612885,13.887562,0.707654,-116.362167,0.070861,0.000000
86.530006,61.284687,-116.273209,0.010800,0.002786,0.070765,272.607910,13.887308,0.707654,-116.273209,0.070861,0.000000
86.740005,61.283199,-116.317688,0.010800,0.002786,0.070765,272.601288,13.886971,0.707654,-116.317688,0.070861,0.000000
86.950005,61.271282,-116.317688,0.010805,0.002786,0.070765,272.548279,13.884271,0.707654,-116.317688,0.070861,0.000000
87.160004,61.264954,-116.273209,0.010826,0.002786,0.070765,272.520111,13.882837,0.707654,-116.273209,0.070861,0.000000
87.300003,61.254528,-116.273209,0.010813,0.002786,0.070765,272.473755,13.880474,0.707654,-116.273209,0.070861,0.000000