File: Data/New pin I-18 old sample 5_08172023_175638.csv
Time (sec),S:Load (lbs),S:HL1 (DIM),S:LVDT (in),S:Position (in),Ch:Position (mm),Ch:Load (N),Ch:Stress (MPa),Ch:Strain (mm/mm),Ch:HL1 (DIM),Set Point (),Cycles ()
0.110000,-0.034256,-26.599609,0.001229,-0.010597,-0.269161,-0.152378,-0.007763,-2.691605,-26.599609,-0.268979,0.000000
0.310000,-0.021591,-26.599609,0.001216,-0.010597,-0.269161,-0.096042,-0.004893,-2.691605,-26.599609,-0.268979,0.000000
0.510000,-0.035004,-26.644089,0.001212,-0.010521,-0.267226,-0.155704,-0.007932,-2.672257,-26.644089,-0.266585,0.000000
0.710000,-0.017502,-26.644089,0.001250,-0.010403,-0.264225,-0.077852,-0.003966,-2.642250,-26.644089,-0.263236,0.000000
0.910000,-0.000000,-26.644089,0.001388,-0.010274,-0.260956,-0.000000,-0.000000,-2.609564,-26.644089,-0.259907,0.000000
1.110000,-0.012657,-26.688570,0.001496,-0.010143,-0.257644,-0.056302,-0.002868,-2.576439,-26.688570,-0.256577,0.000000
1.310000,0.001495,-26.688570,0.001613,-0.010017,-0.254434,0.006652,0.000339,-2.544343,-26.688570,-0.253247,0.000000
1.510000,0.002983,-26.688570,0.001776,-0.009885,-0.251079,0.013269,0.000676,-2.510793,-26.688570,-0.249917,0.000000
1.710000,0.001495,-26.644089,0.001919,-0.009751,-0.247679,0.006652,0.000339,-2.476790,-26.644089,-0.246586,0.000000
1.910000,-0.000740,-26.644089,0.002044,-0.009621,-0.244383,-0.003292,-0.000168,-2.443831,-26.644089,-0.243257,0.000000
2.110000,0.037239,-26.688570,0.002164,-0.009496,-0.241210,0.165648,0.008438,-2.412098,-26.688570,-0.239926,0.000000
2.310000,0.029793,-26.644089,0.002298,-0.009368,-0.237949,0.132525,0.006751,-2.379488,-26.644089,-0.236595,0.000000
2.510000,0.027931,-26.733051,0.002419,-0.009232,-0.234488,0.124244,0.006329,-2.344879,-26.733051,-0.233248,0.000000
2.710000,0.007820,-26.733051,0.002552,-0.009106,-0.231289,0.034786,0.001772,-2.312889,-26.733051,-0.229919,0.000000
2.910000,0.013779,-26.688570,0.002690,-0.008968,-0.227776,0.061291,0.003122,-2.277765,-26.688570,-0.226588,0.000000
3.110000,0.015266,-26.688570,0.002833,-0.008835,-0.224420,0.067908,0.003459,-2.244200,-26.688570,-0.223257,0.000000
3.310000,0.008568,-26.644089,0.003005,-0.008702,-0.221029,0.038112,0.001941,-2.210288,-26.644089,-0.219928,0.000000
3.510000,0.004845,-26.688570,0.003117,-0.008568,-0.217630,0.021550,0.001098,-2.176300,-26.688570,-0.216597,0.000000
3.710000,-0.015266,-26.688570,0.003255,-0.008436,-0.214283,-0.067908,-0.003459,-2.142826,-26.688570,-0.213268,0.000000
3.910000,-0.015640,-26.733051,0.003415,-0.008304,-0.210917,-0.069571,-0.003544,-2.109171,-26.733051,-0.209938,0.000000
4.110000,-0.016006,-26.688570,0.003553,-0.008174,-0.207614,-0.071200,-0.003627,-2.076136,-26.688570,-0.206607,0.000000
4.310000,0.011917,-26.688570,0.003691,-0.008046,-0.204362,0.053010,0.002700,-2.043616,-26.688570,-0.203278,0.000000
4.510000,-0.001114,-26.733051,0.003820,-0.007914,-0.201014,-0.004955,-0.000252,-2.010143,-26.733051,-0.199930,0.000000
4.710000,-0.015640,-26.688570,0.003954,-0.007782,-0.197658,-0.069571,-0.003544,-1.976578,-26.688570,-0.196600,0.000000
4.910000,-0.012283,-26.733051,0.004083,-0.007651,-0.194327,-0.054639,-0.002783,-1.943271,-26.733051,-0.193269,0.000000
5.110000,0.016014,-26.777533,0.004208,-0.007522,-0.191058,0.071234,0.003629,-1.910585,-26.777533,-0.189940,0.000000
5.310000,-0.002975,-26.733051,0.004342,-0.007390,-0.187719,-0.013236,-0.000674,-1.877187,-26.733051,-0.186609,0.000000
5.510000,-0.009308,-26.688570,0.004506,-0.007260,-0.184406,-0.041403,-0.002109,-1.844061,-26.688570,-0.183278,0.000000
5.710000,-0.019363,-26.733051,0.004596,-0.007130,-0.181110,-0.086133,-0.004388,-1.811103,-26.733051,-0.179949,0.000000
5.910000,-0.030533,-26.777533,0.004773,-0.007000,-0.177789,-0.135817,-0.006919,-1.777886,-26.777533,-0.176618,0.000000
6.110000,-0.042816,-26.822014,0.004902,-0.006866,-0.174406,-0.190456,-0.009702,-1.744064,-26.822014,-0.173289,0.000000
6.310000,-0.021591,-26.822014,0.005049,-0.006736,-0.171094,-0.096042,-0.004893,-1.710939,-26.822014,-0.169940,0.000000
6.510000,0.027931,-26.777533,0.005182,-0.006603,-0.167721,0.124244,0.006329,-1.677208,-26.777533,-0.166611,0.000000
6.710001,0.011177,-26.777533,0.005295,-0.006471,-0.164355,0.049718,0.002533,-1.643553,-26.777533,-0.163280,0.000000
6.910000,0.001862,-26.777533,0.005428,-0.006337,-0.160947,0.008281,0.000422,-1.609474,-26.777533,-0.159951,0.000000
7.110000,0.012291,-26.777533,0.005562,-0.006206,-0.157644,0.054673,0.002785,-1.576439,-26.777533,-0.156620,0.000000
7.310000,0.027184,-26.777533,0.005717,-0.006078,-0.154374,0.120918,0.006160,-1.543738,-26.777533,-0.153290,0.000000
7.510000,0.014153,-26.777533,0.005851,-0.005946,-0.151019,0.062954,0.003207,-1.510188,-26.777533,-0.149961,0.000000
7.710001,0.038727,-26.822014,0.005980,-0.005820,-0.147818,0.172265,0.008776,-1.478183,-26.822014,-0.146630,0.000000
7.910000,0.024948,-26.822014,0.006127,-0.005687,-0.144453,0.110975,0.005653,-1.444528,-26.822014,-0.143299,0.000000
8.110001,0.021225,-26.733051,0.006239,-0.005553,-0.141036,0.094413,0.004810,-1.410358,-26.733051,-0.139970,0.000000
8.310000,0.027184,-26.733051,0.006385,-0.005422,-0.137707,0.120918,0.006160,-1.377066,-26.733051,-0.136623,0.000000
8.510000,0.061073,-26.777533,0.006519,-0.005295,-0.134489,0.271668,0.013839,-1.344894,-26.777533,-0.133292,0.000000
8.710000,0.054367,-26.777533,0.006644,-0.005167,-0.131236,0.241837,0.012320,-1.312359,-26.777533,-0.129961,0.000000
8.910001,0.047295,-26.866495,0.006743,-0.005030,-0.127751,0.210377,0.010717,-1.277508,-26.866495,-0.126632,0.000000
9.110001,0.039101,-26.822014,0.006885,-0.004904,-0.124559,0.173928,0.008860,-1.245594,-26.822014,-0.123301,0.000000
9.310000,0.043945,-26.866495,0.007041,-0.004767,-0.121073,0.195479,0.009958,-1.210727,-26.866495,-0.119972,0.000000
9.510000,0.053253,-26.777533,0.007209,-0.004634,-0.117707,0.236882,0.012067,-1.177072,-26.777533,-0.116641,0.000000
9.710000,0.021973,-26.822014,0.007312,-0.004500,-0.114299,0.097739,0.004979,-1.142993,-26.822014,-0.113311,0.000000
9.910001,0.031281,-26.822014,0.007468,-0.004369,-0.110978,0.139143,0.007088,-1.109777,-26.822014,-0.109981,0.000000
10.110001,0.014153,-26.822014,0.007580,-0.004240,-0.107691,0.062954,0.003207,-1.076909,-26.822014,-0.106634,0.000000
10.310000,0.023087,-26.777533,0.007722,-0.004106,-0.104301,0.102694,0.005231,-1.043011,-26.777533,-0.103303,0.000000
10.510000,0.015266,-26.866495,0.007877,-0.003975,-0.100954,0.067908,0.003459,-1.009537,-26.866495,-0.099973,0.000000
10.710000,0.040588,-26.822014,0.008006,-0.003848,-0.097744,0.180546,0.009197,-0.977442,-26.822014,-0.096644,0.000000
10.910001,0.039101,-26.777533,0.008140,-0.003718,-0.094441,0.173928,0.008860,-0.944407,-26.777533,-0.093313,0.000000
11.110001,0.018997,-26.777533,0.008261,-0.003584,-0.091040,0.084504,0.004305,-0.910403,-26.777533,-0.089982,0.000000
11.310000,0.027931,-26.910975,0.008390,-0.003451,-0.087651,0.124244,0.006329,-0.876506,-26.910975,-0.086653,0.000000
11.510000,0.051392,-26.866495,0.008545,-0.003325,-0.084450,0.228601,0.011646,-0.844501,-26.866495,-0.083322,0.000000
11.710001,0.031654,-26.822014,0.008679,-0.003193,-0.081094,0.140806,0.007173,-0.810936,-26.822014,-0.079993,0.000000
11.910001,0.024948,-26.866495,0.008791,-0.003062,-0.077781,0.110975,0.005653,-0.777811,-26.866495,-0.076662,0.000000
12.110001,0.011543,-26.822014,0.008951,-0.002932,-0.074485,0.051347,0.002616,-0.744852,-26.822014,-0.073315,0.000000
12.310000,0.002609,-26.866495,0.009080,-0.002804,-0.071217,0.011607,0.000591,-0.712166,-26.866495,-0.069984,0.000000
12.510000,-0.003723,-26.866495,0.009235,-0.002667,-0.067739,-0.016561,-0.000844,-0.677390,-26.866495,-0.066655,0.000000
12.710001,0.028679,-26.866495,0.009356,-0.002537,-0.064434,0.127570,0.006499,-0.644341,-26.866495,-0.063324,0.000000
12.910001,0.046921,-26.866495,0.009485,-0.002404,-0.061070,0.208714,0.010632,-0.610700,-26.866495,-0.059994,0.000000
13.110001,0.048782,-26.866495,0.009649,-0.002272,-0.057705,0.216995,0.011054,-0.577045,-26.866495,-0.056664,0.000000
13.310000,0.048409,-26.866495,0.009770,-0.002140,-0.054348,0.215332,0.010970,-0.543481,-26.866495,-0.053334,0.000000
13.510000,0.047668,-26.866495,0.009951,-0.002009,-0.051036,0.212040,0.010802,-0.510355,-26.866495,-0.050003,0.000000
13.710001,0.060326,-26.822014,0.010042,-0.001881,-0.047774,0.268342,0.013670,-0.477745,-26.822014,-0.046674,0.000000
13.910001,0.038727,-26.866495,0.010197,-0.001749,-0.044436,0.172265,0.008776,-0.444362,-26.866495,-0.043343,0.000000
14.110001,0.064796,-26.822014,0.010322,-0.001623,-0.041227,0.288229,0.014683,-0.412266,-26.822014,-0.039996,0.000000
14.310000,0.056229,-26.866495,0.010460,-0.001490,-0.037837,0.250117,0.012742,-0.378368,-26.866495,-0.036665,0.000000
14.510000,0.064796,-26.866495,0.010589,-0.001355,-0.034420,0.288229,0.014683,-0.344198,-26.866495,-0.033336,0.000000
14.710001,0.059952,-26.866495,0.010710,-0.001226,-0.031133,0.266679,0.013585,-0.311330,-26.866495,-0.030005,0.000000
14.910001,0.088631,-26.866495,0.010865,-0.001099,-0.027907,0.394249,0.020084,-0.279068,-26.866495,-0.026676,0.000000
15.110001,0.085648,-26.866495,0.010994,-0.000971,-0.024655,0.380979,0.019408,-0.246548,-26.866495,-0.023345,0.000000
15.310000,0.099426,-26.866495,0.011124,-0.000834,-0.021177,0.442270,0.022530,-0.211772,-26.866495,-0.020015,0.000000
15.510001,0.103523,-26.910975,0.011300,-0.000709,-0.018002,0.460494,0.023459,-0.180025,-26.910975,-0.016685,0.000000
15.710001,0.086021,-26.822014,0.011434,-0.000571,-0.014508,0.382642,0.019493,-0.145083,-26.822014,-0.013355,0.000000
15.910001,0.120277,-26.866495,0.011589,-0.000437,-0.011091,0.535021,0.027255,-0.110913,-26.866495,-0.010007,0.000000
16.110001,0.179115,-26.910975,0.011723,-0.000303,-0.007692,0.796745,0.040588,-0.076924,-26.910975,-0.006677,0.000000
16.310001,0.347801,-26.866495,0.011809,-0.000172,-0.004378,1.547097,0.078813,-0.043784,-26.866495,-0.003347,0.000000
16.510000,0.755173,-26.866495,0.011960,-0.000004,-0.000104,3.359176,0.171125,-0.001045,-26.866495,0.000026,0.000000
16.710001,0.653145,-26.955456,0.011982,-0.000008,-0.000191,2.905333,0.148005,-0.001908,-26.955456,0.000026,0.000000
16.910002,0.627449,-26.866495,0.011969,-0.000008,-0.000191,2.791033,0.142182,-0.001908,-26.866495,0.000026,0.000000
17.110001,0.666924,-26.866495,0.011973,-0.000008,-0.000191,2.966624,0.151127,-0.001908,-26.866495,0.000209,0.000000
17.310001,0.668785,-26.910975,0.011956,-0.000007,-0.000182,2.974905,0.151549,-0.001817,-26.910975,0.000547,0.000000
17.510000,0.668785,-26.910975,0.011986,0.000002,0.000061,2.974905,0.151549,0.000606,-26.910975,0.000877,0.000000
17.710001,0.731346,-26.910975,0.011982,0.000015,0.000372,3.253190,0.165725,0.003724,-26.910975,0.001214,0.000000
17.910002,0.820343,-26.866495,0.011986,0.000025,0.000624,3.649068,0.185892,0.006238,-26.866495,0.001544,0.000000
18.110001,0.812149,-26.910975,0.011969,0.000035,0.000893,3.612619,0.184036,0.008932,-26.910975,0.001873,0.000000
18.310001,0.897423,-26.910975,0.012012,0.000047,0.001198,3.991936,0.203359,0.011975,-26.910975,0.002212,0.000000
18.510000,0.969658,-26.910975,0.011990,0.000056,0.001422,4.313254,0.219728,0.014216,-26.910975,0.002540,0.000000
18.710001,1.128288,-26.910975,0.012021,0.000073,0.001865,5.018877,0.255674,0.018652,-26.910975,0.002880,0.000000
18.910002,1.246704,-26.910975,0.012046,0.000089,0.002263,5.545617,0.282507,0.022634,-26.910975,0.003208,0.000000
19.110001,1.280220,-26.910975,0.012038,0.000097,0.002454,5.694703,0.290102,0.024541,-26.910975,0.003547,0.000000
19.310001,1.465660,-26.910975,0.012055,0.000117,0.002984,6.519582,0.332123,0.029840,-26.910975,0.003877,0.000000
19.510000,1.577744,-26.910975,0.012085,0.000131,0.003331,7.018154,0.357522,0.033307,-26.910975,0.004215,0.000000
19.710001,1.692810,-26.866495,0.012111,0.000144,0.003668,7.529995,0.383596,0.036683,-26.866495,0.004545,0.000000
19.910002,1.802284,-26.955456,0.012051,0.000154,0.003920,8.016961,0.408403,0.039196,-26.955456,0.004873,0.000000
20.110001,1.848831,-26.910975,0.012072,0.000164,0.004171,8.224011,0.418951,0.041710,-26.910975,0.005213,0.000000
20.310001,1.972832,-26.955456,0.012102,0.000178,0.004527,8.775594,0.447050,0.045267,-26.955456,0.005541,0.000000
20.510000,2.166466,-26.910975,0.012098,0.000192,0.004883,9.636921,0.490928,0.048825,-26.910975,0.005880,0.000000
20.710001,2.468460,-26.955456,0.012128,0.000210,0.005334,10.980259,0.559361,0.053337,-26.955456,0.006209,0.000000
20.910002,2.554848,-26.955456,0.012133,0.000219,0.005568,11.364531,0.578937,0.055683,-26.955456,0.006548,0.000000
21.110001,2.697472,-26.999937,0.012167,0.000229,0.005820,11.998953,0.611256,0.058197,-26.999937,0.006878,0.000000
21.310001,2.980843,-26.955456,0.012163,0.000249,0.006313,13.259450,0.675469,0.063132,-26.955456,0.007216,0.000000
21.510000,3.164055,-26.955456,0.012176,0.000263,0.006669,14.074419,0.716985,0.066690,-26.955456,0.007546,0.000000
21.710001,3.326408,-26.999937,0.012202,0.000273,0.006946,14.796603,0.753775,0.069460,-26.999937,0.007874,0.000000
21.910002,3.465302,-26.910975,0.012206,0.000282,0.007164,15.414431,0.785249,0.071640,-26.910975,0.008213,0.000000
22.110001,3.647018,-26.910975,0.012236,0.000296,0.007527,16.222748,0.826426,0.075274,-26.910975,0.008542,0.000000
22.310001,3.883476,-26.955456,0.012206,0.000309,0.007839,17.274565,0.880008,0.078393,-26.955456,0.008881,0.000000
22.510000,4.091263,-26.955456,0.012232,0.000322,0.008169,18.198847,0.927093,0.081693,-26.955456,0.009209,0.000000
22.710001,4.383942,-26.955456,0.012232,0.000336,0.008534,19.500746,0.993415,0.085342,-26.955456,0.009549,0.000000
22.910002,4.557098,-26.999937,0.012262,0.000345,0.008751,20.270987,1.032653,0.087507,-26.999937,0.009877,0.000000
23.110001,4.754456,-26.999937,0.012275,0.000357,0.009072,21.148874,1.077375,0.090716,-26.999937,0.010207,0.000000
23.310001,5.193855,-26.999937,0.012292,0.000376,0.009558,23.103422,1.176944,0.095576,-26.999937,0.010546,0.000000
23.510000,5.391212,-26.955456,0.012331,0.000389,0.009869,23.981310,1.221666,0.098695,-26.955456,0.010875,0.000000
23.710001,5.628044,-26.999937,0.012318,0.000401,0.010190,25.034790,1.275333,0.101905,-26.999937,0.011214,0.000000
23.910002,5.776993,-27.044418,0.012318,0.000411,0.010442,25.697348,1.309085,0.104418,-27.044418,0.011542,0.000000
24.110001,6.042122,-26.955456,0.012340,0.000423,0.010737,26.876701,1.369164,0.107370,-26.955456,0.011882,0.000000
24.310001,6.338158,-26.999937,0.012340,0.000436,0.011084,28.193533,1.436247,0.110837,-26.999937,0.012210,0.000000
24.510000,6.685577,-26.955456,0.012365,0.000453,0.011500,29.738934,1.514973,0.115000,-26.955456,0.012549,0.000000
24.710001,6.888519,-26.999937,0.012383,0.000463,0.011759,30.641665,1.560961,0.117589,-26.999937,0.012878,0.000000
24.910002,7.027412,-26.999937,0.012352,0.000471,0.011959,31.259491,1.592435,0.119588,-26.999937,0.013208,0.000000
25.110001,7.512619,-26.955456,0.012348,0.000490,0.012454,33.417797,1.702384,0.124538,-26.955456,0.013545,0.000000
25.310001,7.813126,-27.044418,0.012404,0.000503,0.012766,34.754517,1.770480,0.127657,-27.044418,0.013875,0.000000
25.510002,8.100220,-27.044418,0.012387,0.000518,0.013164,36.031578,1.835536,0.131639,-27.044418,0.014215,0.000000
25.710001,8.384712,-26.955456,0.012434,0.000531,0.013485,37.297062,1.900003,0.134848,-26.955456,0.014543,0.000000
25.910002,8.585419,-27.044418,0.012430,0.000542,0.013754,38.189850,1.945484,0.137543,-27.044418,0.014882,0.000000
26.110001,8.968224,-27.044418,0.012465,0.000557,0.014152,39.892651,2.032228,0.141525,-27.044418,0.015211,0.000000
26.310001,9.267982,-26.999937,0.012473,0.000571,0.014508,41.226044,2.100155,0.145083,-26.999937,0.015550,0.000000
26.510002,9.616150,-26.999937,0.012482,0.000582,0.014794,42.774773,2.179051,0.147944,-26.999937,0.015878,0.000000
26.710001,9.781487,-27.044418,0.012482,0.000595,0.015124,43.510223,2.216516,0.151244,-27.044418,0.016208,0.000000
26.910002,10.074539,-26.999937,0.012495,0.000604,0.015341,44.813789,2.282923,0.153409,-26.999937,0.016546,0.000000
27.110001,10.378769,-27.044418,0.012503,0.000618,0.015688,46.167068,2.351862,0.156876,-27.044418,0.016876,0.000000
27.310001,10.958923,-27.044418,0.012499,0.000637,0.016174,48.747726,2.483328,0.161736,-27.044418,0.017215,0.000000
27.510002,11.356987,-27.044418,0.012551,0.000655,0.016625,50.518402,2.573530,0.166248,-27.044418,0.017544,0.000000
27.710001,11.445984,-27.044418,0.012568,0.000663,0.016841,50.914280,2.593697,0.168413,-27.044418,0.017883,0.000000
27.910002,11.717072,-26.999937,0.012559,0.000678,0.017223,52.120136,2.655126,0.172228,-26.999937,0.018211,0.000000
28.110001,11.986298,-27.044418,0.012585,0.000689,0.017492,53.317715,2.716134,0.174923,-27.044418,0.018541,0.000000
28.310001,12.481552,-27.088900,0.012581,0.000703,0.017848,55.520718,2.828360,0.178481,-27.088900,0.018879,0.000000
28.510002,12.793976,-27.044418,0.012607,0.000717,0.018220,56.910446,2.899156,0.182205,-27.044418,0.019209,0.000000
28.710001,12.803658,-27.088900,0.012594,0.000724,0.018402,56.953514,2.901350,0.184022,-27.088900,0.019547,0.000000
28.910002,13.006599,-27.044418,0.012628,0.000734,0.018637,57.856243,2.947337,0.186368,-27.044418,0.019877,0.000000
29.110001,13.368919,-27.088900,0.012616,0.000746,0.018940,59.467922,3.029441,0.189396,-27.088900,0.020214,0.000000
29.310001,14.207504,-27.044418,0.012624,0.000770,0.019565,63.198135,3.219466,0.195649,-27.044418,0.020544,0.000000
29.510002,14.325546,-27.133381,0.012667,0.000781,0.019833,63.723213,3.246215,0.198328,-27.133381,0.020884,0.000000
29.710001,14.479706,-27.044418,0.012663,0.000793,0.020154,64.408951,3.281148,0.201538,-27.044418,0.021212,0.000000
29.910002,14.974586,-27.044418,0.012689,0.000809,0.020553,66.610291,3.393290,0.205535,-27.044418,0.021542,0.000000
30.110001,15.090767,-27.088900,0.012680,0.000818,0.020779,67.127083,3.419617,0.207791,-27.088900,0.021880,0.000000
30.310001,15.750984,-27.088900,0.012706,0.000839,0.021300,70.063873,3.569224,0.212999,-27.088900,0.022210,0.000000
30.510002,15.629967,-27.088900,0.012706,0.000844,0.021429,69.525566,3.541801,0.214286,-27.088900,0.022547,0.000000
30.710001,15.916321,-27.133381,0.012728,0.000856,0.021742,70.799332,3.606690,0.217420,-27.133381,0.022877,0.000000
30.910002,15.818382,-27.088900,0.012753,0.000865,0.021968,70.363678,3.584496,0.219675,-27.088900,0.023215,0.000000
31.110001,16.567970,-27.088900,0.012741,0.000881,0.022375,73.698013,3.754356,0.223748,-27.088900,0.023545,0.000000
31.310001,17.242706,-27.133381,0.012766,0.000904,0.022964,76.699387,3.907253,0.229637,-27.133381,0.023875,0.000000
31.510002,17.164886,-27.088900,0.012775,0.000911,0.023138,76.353226,3.889619,0.231378,-27.088900,0.024213,0.000000
31.710001,17.388306,-27.088900,0.012810,0.000924,0.023475,77.347046,3.940246,0.234754,-27.088900,0.024543,0.000000
31.910002,17.654556,-27.088900,0.012831,0.000937,0.023787,78.531387,4.000580,0.237873,-27.088900,0.024880,0.000000
32.110001,18.165451,-27.133381,0.012827,0.000954,0.024238,80.803963,4.116350,0.242385,-27.133381,0.025210,0.000000
32.310001,18.192635,-27.088900,0.012848,0.000966,0.024525,80.924881,4.122510,0.245246,-27.088900,0.025548,0.000000
32.510002,18.563515,-27.133381,0.012853,0.000979,0.024855,82.574638,4.206553,0.248546,-27.133381,0.025878,0.000000
32.710003,18.629425,-27.133381,0.012857,0.000985,0.025011,82.867821,4.221488,0.250106,-27.133381,0.026216,0.000000
32.910000,19.081482,-27.133381,0.012857,0.001002,0.025445,84.878670,4.323926,0.254451,-27.133381,0.026546,0.000000
33.110001,19.729416,-27.133381,0.012879,0.001022,0.025964,87.760826,4.470749,0.259644,-27.133381,0.026876,0.000000
33.310001,19.714516,-27.088900,0.012917,0.001031,0.026199,87.694542,4.467373,0.261990,-27.088900,0.027213,0.000000
33.510002,19.905548,-27.133381,0.012917,0.001043,0.026502,88.544304,4.510662,0.265018,-27.133381,0.027543,0.000000
33.710003,20.117424,-27.088900,0.012960,0.001057,0.026841,89.486771,4.558673,0.268410,-27.088900,0.027881,0.000000
33.910000,20.634651,-27.133381,0.012939,0.001074,0.027283,91.787514,4.675879,0.272830,-27.133381,0.028211,0.000000
34.110001,20.858818,-27.133381,0.012947,0.001087,0.027604,92.784660,4.726676,0.276040,-27.133381,0.028549,0.000000
34.310001,20.906479,-27.088900,0.012952,0.001098,0.027890,92.996666,4.737475,0.278901,-27.088900,0.028879,0.000000
34.510002,21.100861,-27.133381,0.012960,0.001107,0.028125,93.861313,4.781524,0.281248,-27.133381,0.029216,0.000000
34.710003,21.220016,-27.177860,0.012999,0.001119,0.028411,94.391350,4.808525,0.284109,-27.177860,0.029546,0.000000
34.910000,21.845604,-27.133381,0.012999,0.001137,0.028879,97.174103,4.950284,0.288787,-27.133381,0.029876,0.000000
35.110001,22.303627,-27.133381,0.013008,0.001154,0.029312,99.211487,5.054074,0.293117,-27.133381,0.030214,0.000000
35.310001,22.287613,-27.133381,0.013042,0.001162,0.029512,99.140251,5.050445,0.295116,-27.133381,0.030544,0.000000
35.510002,22.464485,-27.177860,0.013038,0.001175,0.029842,99.927017,5.090525,0.298416,-27.177860,0.030882,0.000000
35.710003,22.726265,-27.133381,0.013090,0.001186,0.030119,101.091476,5.149845,0.301187,-27.133381,0.031212,0.000000
35.910000,22.854736,-27.133381,0.013038,0.001196,0.030379,101.662941,5.178957,0.303791,-27.133381,0.031549,0.000000
36.110001,23.536552,-27.177860,0.013064,0.001215,0.030865,104.695816,5.333459,0.308651,-27.177860,0.031879,0.000000
36.310001,23.708588,-27.133381,0.013068,0.001227,0.031159,105.461067,5.372443,0.311588,-27.133381,0.032209,0.000000
36.510002,23.600594,-27.133381,0.013098,0.001232,0.031298,104.980682,5.347971,0.312981,-27.133381,0.032547,0.000000
36.710003,23.958450,-27.133381,0.013085,0.001246,0.031637,106.572510,5.429062,0.316372,-27.133381,0.032877,0.000000
36.910000,24.295074,-27.177860,0.013142,0.001261,0.032035,108.069885,5.505342,0.320354,-27.177860,0.033215,0.000000
37.110001,25.213715,-27.177860,0.013111,0.001283,0.032582,112.156204,5.713509,0.325819,-27.177860,0.033545,0.000000
37.310001,25.174240,-27.177860,0.013146,0.001292,0.032824,111.980614,5.704565,0.328241,-27.177860,0.033882,0.000000
37.510002,25.226006,-27.222342,0.013142,0.001304,0.033128,112.210876,5.716294,0.331284,-27.222342,0.034212,0.000000
37.710003,25.483315,-27.222342,0.013176,0.001313,0.033362,113.355446,5.774601,0.333616,-27.222342,0.034550,0.000000
37.910004,25.712318,-27.177860,0.013185,0.001323,0.033614,114.374107,5.826495,0.336144,-27.177860,0.034880,0.000000
38.110001,26.215027,-27.222342,0.013193,0.001338,0.033996,116.610260,5.940410,0.339959,-27.222342,0.035210,0.000000
38.310001,26.648468,-27.177860,0.013202,0.001356,0.034455,118.538307,6.038629,0.344547,-27.177860,0.035548,0.000000
38.510002,26.898697,-27.133381,0.013219,0.001365,0.034671,119.651382,6.095332,0.346712,-27.133381,0.035878,0.000000
38.710003,27.299004,-27.222342,0.013223,0.001379,0.035036,121.432030,6.186042,0.350360,-27.222342,0.036215,0.000000
38.910004,27.961449,-27.177860,0.013262,0.001400,0.035548,124.378738,6.336155,0.355477,-27.177860,0.036545,0.000000
39.110001,28.327118,-27.222342,0.013262,0.001414,0.035920,126.005310,6.419017,0.359202,-27.222342,0.036883,0.000000
39.310001,28.431015,-27.222342,0.013275,0.001424,0.036181,126.467468,6.442560,0.361806,-27.222342,0.037213,0.000000
39.510002,28.445908,-27.222342,0.013262,0.001434,0.036432,126.533714,6.445935,0.364319,-27.222342,0.037551,0.000000
39.710003,28.860359,-27.222342,0.013292,0.001445,0.036710,128.377289,6.539851,0.367105,-27.222342,0.037881,0.000000
39.910004,29.005585,-27.177860,0.013279,0.001455,0.036953,129.023285,6.572760,0.369527,-27.177860,0.038209,0.000000
40.110001,29.824059,-27.177860,0.013284,0.001473,0.037421,132.664032,6.758228,0.374205,-27.177860,0.038548,0.000000
40.310001,30.334953,-27.222342,0.013344,0.001488,0.037802,134.936615,6.873999,0.378020,-27.222342,0.038878,0.000000
40.510002,30.346123,-27.222342,0.013336,0.001498,0.038053,134.986298,6.876530,0.380533,-27.222342,0.039216,0.000000
40.710003,31.310944,-27.222342,0.013340,0.001519,0.038583,139.278030,7.095161,0.385832,-27.222342,0.039546,0.000000
40.910004,31.633415,-27.222342,0.013370,0.001533,0.038939,140.712463,7.168234,0.389390,-27.222342,0.039884,0.000000
41.110001,31.991264,-27.266823,0.013361,0.001546,0.039277,142.304245,7.249324,0.392766,-27.266823,0.040214,0.000000
41.310001,32.062386,-27.222342,0.013379,0.001553,0.039442,142.620621,7.265440,0.394416,-27.222342,0.040542,0.000000
41.510002,32.304428,-27.222342,0.013387,0.001567,0.039797,143.697266,7.320288,0.397974,-27.222342,0.040881,0.000000
41.710003,33.054016,-27.177860,0.013400,0.001582,0.040188,147.031601,7.490147,0.401880,-27.177860,0.041210,0.000000
41.910004,33.318771,-27.222342,0.013422,0.001594,0.040500,148.209290,7.550142,0.404999,-27.222342,0.041549,0.000000
42.110001,34.139107,-27.177860,0.013422,0.001612,0.040933,151.858337,7.736032,0.409329,-27.177860,0.041879,0.000000
42.310001,34.196831,-27.177860,0.013448,0.001621,0.041177,152.115097,7.749113,0.411766,-27.177860,0.042217,0.000000
42.510002,34.730812,-27.133381,0.013409,0.001636,0.041549,154.490372,7.870115,0.415491,-27.133381,0.042547,0.000000
42.710003,35.351181,-27.222342,0.013452,0.001650,0.041905,157.249908,8.010692,0.419048,-27.222342,0.042884,0.000000
42.910004,35.830795,-27.177860,0.013482,0.001664,0.042261,159.383331,8.119374,0.422606,-27.177860,0.043214,0.000000
43.110001,36.239288,-27.266823,0.013473,0.001677,0.042598,161.200409,8.211940,0.425982,-27.266823,0.043543,0.000000
43.310001,36.294029,-27.222342,0.013491,0.001683,0.042754,161.443909,8.224344,0.427542,-27.222342,0.043882,0.000000
43.510002,36.766945,-27.222342,0.013495,0.001696,0.043066,163.547546,8.331509,0.430660,-27.222342,0.044211,0.000000
43.710003,37.232033,-27.222342,0.013486,0.001709,0.043405,165.616348,8.436899,0.434052,-27.222342,0.044550,0.000000
43.910004,37.841606,-27.222342,0.013517,0.001724,0.043787,168.327866,8.575031,0.437867,-27.222342,0.044878,0.000000
44.110001,38.438522,-27.266823,0.013495,0.001736,0.044099,170.983093,8.710294,0.440986,-27.266823,0.045217,0.000000
44.310001,38.694717,-27.222342,0.013525,0.001747,0.044368,172.122696,8.768349,0.443681,-27.222342,0.045547,0.000000
44.510002,39.284927,-27.222342,0.013534,0.001761,0.044722,174.748077,8.902091,0.447223,-27.222342,0.045876,0.000000
44.710003,40.192772,-27.222342,0.013568,0.001778,0.045166,178.786377,9.107812,0.451659,-27.222342,0.046215,0.000000
44.910004,40.672760,-27.311304,0.013577,0.001791,0.045504,180.921478,9.216579,0.455035,-27.311304,0.046544,0.000000
45.110001,41.024651,-27.311304,0.013590,0.001803,0.045806,182.486755,9.296319,0.458063,-27.311304,0.046883,0.000000
45.310001,41.398880,-27.222342,0.013586,0.001816,0.046120,184.151413,9.381121,0.461197,-27.222342,0.047211,0.000000
45.510002,41.862862,-27.266823,0.013594,0.001830,0.046474,186.215302,9.486260,0.464740,-27.266823,0.047550,0.000000
45.710003,42.451584,-27.222342,0.013590,0.001843,0.046822,188.834076,9.619666,0.468222,-27.222342,0.047879,0.000000
45.910004,43.115524,-27.311304,0.013594,0.001855,0.047116,191.787430,9.770118,0.471159,-27.311304,0.048218,0.000000
46.110001,43.594017,-27.266823,0.013650,0.001867,0.047420,193.915878,9.878546,0.474202,-27.266823,0.048548,0.000000
46.310001,43.455872,-27.266823,0.013650,0.001871,0.047532,193.301376,9.847241,0.475322,-27.266823,0.048877,0.000000
46.510002,44.871254,-27.311304,0.013650,0.001893,0.048079,199.597305,10.167972,0.480788,-27.311304,0.049216,0.000000
46.710003,45.111435,-27.311304,0.013646,0.001907,0.048435,200.665680,10.222397,0.484345,-27.311304,0.049544,0.000000
46.910004,46.133224,-27.266823,0.013655,0.001924,0.048860,205.210831,10.453938,0.488600,-27.266823,0.049883,0.000000
47.110001,46.310104,-27.311304,0.013711,0.001930,0.049016,205.997635,10.494020,0.490159,-27.311304,0.050212,0.000000
47.310001,46.992661,-27.266823,0.013685,0.001946,0.049432,209.033798,10.648689,0.494322,-27.266823,0.050551,0.000000
47.510002,47.663681,-27.311304,0.013706,0.001960,0.049796,212.018646,10.800744,0.497956,-27.311304,0.050880,0.000000
47.710003,48.297081,-27.311304,0.013706,0.001974,0.050144,214.836151,10.944275,0.501438,-27.311304,0.051219,0.000000
47.910004,48.870911,-27.311304,0.013706,0.001986,0.050456,217.388672,11.074306,0.504557,-27.311304,0.051547,0.000000
48.110001,49.359093,-27.311304,0.013741,0.001997,0.050724,219.560211,11.184930,0.507236,-27.311304,0.051877,0.000000
48.310001,49.802216,-27.311304,0.013706,0.002012,0.051105,221.531326,11.285343,0.511052,-27.311304,0.052216,0.000000
48.510002,50.668350,-27.266823,0.013728,0.002024,0.051419,225.384079,11.481612,0.514186,-27.266823,0.052545,0.000000
48.710003,51.620506,-27.400267,0.013745,0.002043,0.051903,229.619476,11.697373,0.519030,-27.400267,0.052884,0.000000
48.910004,52.247581,-27.311304,0.013788,0.002055,0.052207,232.408844,11.839471,0.522073,-27.311304,0.053213,0.000000
49.110001,52.354828,-27.355785,0.013801,0.002064,0.052415,232.885910,11.863773,0.524147,-27.355785,0.053552,0.000000
49.310001,53.511040,-27.355785,0.013758,0.002082,0.052875,238.028992,12.125775,0.528750,-27.355785,0.053880,0.000000
49.510002,53.618660,-27.355785,0.013810,0.002088,0.053031,238.507706,12.150163,0.530309,-27.355785,0.054210,0.000000
49.710003,54.919357,-27.266823,0.013775,0.002110,0.053603,244.293503,12.444903,0.536032,-27.266823,0.054548,0.000000
49.910004,55.154320,-27.266823,0.013810,0.002119,0.053812,245.338669,12.498148,0.538121,-27.266823,0.054878,0.000000
50.110001,55.350937,-27.355785,0.013849,0.002126,0.054003,246.213257,12.542702,0.540029,-27.355785,0.055216,0.000000
50.310001,55.947845,-27.355785,0.013853,0.002136,0.054254,248.868439,12.677963,0.542542,-27.355785,0.055546,0.000000
50.510002,57.355789,-27.400267,0.013857,0.002157,0.054783,255.131287,12.997007,0.547826,-27.400267,0.055885,0.000000
50.710003,58.190651,-27.355785,0.013849,0.002174,0.055208,258.844940,13.186190,0.552080,-27.355785,0.056213,0.000000
50.910004,58.650902,-27.400267,0.013879,0.002183,0.055450,260.892242,13.290484,0.554502,-27.400267,0.056552,0.000000
51.110001,59.262337,-27.400267,0.013870,0.002197,0.055797,263.612030,13.429037,0.557969,-27.400267,0.056881,0.000000
51.310001,60.102409,-27.400267,0.013887,0.002210,0.056144,267.348877,13.619401,0.561436,-27.400267,0.057211,0.000000
51.510002,60.426369,-27.400267,0.013918,0.002219,0.056369,268.789917,13.692811,0.563692,-27.400267,0.057549,0.000000
51.710003,61.861496,-27.355785,0.013922,0.002240,0.056890,275.173676,14.018016,0.568900,-27.355785,0.057879,0.000000
51.910004,61.940811,-27.311304,0.013943,0.002248,0.057106,275.526489,14.035988,0.571065,-27.311304,0.058216,0.000000
52.110001,62.391754,-27.400267,0.013913,0.002256,0.057297,277.532379,14.138174,0.572973,-27.400267,0.058546,0.000000
52.310001,63.075050,-27.444746,0.013926,0.002269,0.057627,280.571838,14.293011,0.576273,-27.444746,0.058885,0.000000
52.510002,64.643486,-27.355785,0.013939,0.002289,0.058148,287.548584,14.648423,0.581481,-27.355785,0.059214,0.000000
52.710003,65.504417,-27.311304,0.013935,0.002305,0.058546,291.378204,14.843513,0.585463,-27.311304,0.059553,0.000000
52.910004,65.620598,-27.400267,0.013952,0.002314,0.058772,291.894989,14.869841,0.587718,-27.400267,0.059882,0.000000
53.110004,66.376884,-27.400267,0.013948,0.002326,0.059076,295.259125,15.041217,0.590762,-27.400267,0.060212,0.000000
53.310001,67.055717,-27.355785,0.013961,0.002337,0.059362,298.278717,15.195043,0.593623,-27.355785,0.060549,0.000000
53.510002,67.197227,-27.400267,0.013995,0.002334,0.059293,298.908203,15.227109,0.592927,-27.400267,0.059544,0.000000
53.710003,66.787987,-27.444746,0.013999,0.002334,0.059293,297.087799,15.134375,0.592927,-27.444746,0.059544,0.000000
53.910004,66.483009,-27.400267,0.013995,0.002329,0.059153,295.731201,15.065265,0.591534,-27.400267,0.059293,0.000000
54.110004,66.223839,-27.355785,0.014025,0.002328,0.059128,294.578339,15.006536,0.591276,-27.355785,0.059293,0.000000
54.310001,65.992973,-27.400267,0.013978,0.002327,0.059109,293.551392,14.954222,0.591095,-27.400267,0.059293,0.000000
54.510002,65.801567,-27.444746,0.014012,0.002327,0.059109,292.699982,14.910849,0.591095,-27.444746,0.059293,0.000000
54.710003,65.623573,-27.355785,0.014004,0.002327,0.059102,291.908234,14.870514,0.591019,-27.355785,0.059293,0.000000
54.910004,65.453026,-27.400267,0.013991,0.002327,0.059102,291.149597,14.831867,0.591019,-27.400267,0.059293,0.000000
55.110004,65.315620,-27.444746,0.014004,0.002326,0.059093,290.538391,14.800731,0.590928,-27.444746,0.059293,0.000000
55.310001,65.182686,-27.400267,0.014021,0.002326,0.059093,289.947083,14.770608,0.590928,-27.400267,0.059293,0.000000
55.510002,65.072456,-27.444746,0.014025,0.002326,0.059093,289.456757,14.745629,0.590928,-27.444746,0.059293,0.000000
55.710003,64.950325,-27.400267,0.014043,0.002326,0.059093,288.913483,14.717954,0.590928,-27.400267,0.059293,0.000000
55.910004,64.853142,-27.444746,0.014030,0.002326,0.059093,288.481171,14.695932,0.590928,-27.444746,0.059293,0.000000
56.110004,64.750740,-27.400267,0.014025,0.002326,0.059093,288.025665,14.672727,0.590928,-27.400267,0.059293,0.000000
56.310001,64.664345,-27.444746,0.013995,0.002326,0.059084,287.641357,14.653150,0.590837,-27.444746,0.059293,0.000000
56.510002,64.573860,-27.400267,0.014012,0.002326,0.059084,287.238861,14.632646,0.590837,-27.400267,0.059293,0.000000
56.710003,64.493050,-27.444746,0.014030,0.002326,0.059084,286.879425,14.614334,0.590837,-27.444746,0.059293,0.000000
56.910004,64.423042,-27.444746,0.014008,0.002326,0.059084,286.567993,14.598471,0.590837,-27.444746,0.059293,0.000000
57.110004,64.348946,-27.400267,0.014025,0.002326,0.059084,286.238403,14.581679,0.590837,-27.400267,0.059293,0.000000
57.310001,64.281914,-27.444746,0.013999,0.002326,0.059084,285.940247,14.566490,0.590837,-27.444746,0.059293,0.000000
57.510002,64.214149,-27.489227,0.014021,0.002326,0.059084,285.638794,14.551134,0.590837,-27.489227,0.059293,0.000000
57.710003,64.140419,-27.444746,0.014008,0.002326,0.059084,285.310822,14.534427,0.590837,-27.444746,0.059293,0.000000
57.910004,64.081215,-27.444746,0.013995,0.002326,0.059084,285.047485,14.521010,0.590837,-27.444746,0.059293,0.000000
58.110004,64.026100,-27.400267,0.014030,0.002326,0.059084,284.802307,14.508521,0.590837,-27.400267,0.059293,0.000000
58.310001,63.976570,-27.489227,0.014012,0.002326,0.059084,284.582001,14.497298,0.590837,-27.489227,0.059293,0.000000
58.510002,63.921089,-27.444746,0.014017,0.002326,0.059084,284.335205,14.484726,0.590837,-27.444746,0.059293,0.000000
58.710003,63.864494,-27.444746,0.014017,0.002326,0.059084,284.083466,14.471902,0.590837,-27.444746,0.059293,0.000000
58.910004,63.814583,-27.444746,0.013991,0.002326,0.059084,283.861450,14.460591,0.590837,-27.444746,0.059293,0.000000
59.110004,63.768791,-27.400267,0.014004,0.002326,0.059084,283.657745,14.450214,0.590837,-27.400267,0.059293,0.000000
59.310001,63.729683,-27.444746,0.014034,0.002326,0.059084,283.483795,14.441352,0.590837,-27.444746,0.059293,0.000000
59.510002,63.687981,-27.444746,0.013991,0.002326,0.059084,283.298279,14.431902,0.590837,-27.444746,0.059293,0.000000
59.710003,63.635857,-27.489227,0.014017,0.002326,0.059084,283.066437,14.420092,0.590837,-27.489227,0.059293,0.000000
59.910004,63.594887,-27.444746,0.014021,0.002326,0.059084,282.884186,14.410808,0.590837,-27.444746,0.059293,0.000000
60.110004,63.563606,-27.533709,0.014021,0.002326,0.059084,282.745056,14.403719,0.590837,-27.533709,0.059293,0.000000
60.310001,63.520042,-27.533709,0.014025,0.002326,0.059084,282.551270,14.393847,0.590837,-27.533709,0.059293,0.000000
60.510002,63.476845,-27.489227,0.013999,0.002326,0.059084,282.359100,14.384058,0.590837,-27.489227,0.059293,0.000000
60.710003,63.434029,-27.489227,0.014034,0.002326,0.059084,282.168640,14.374356,0.590837,-27.489227,0.059293,0.000000
60.910004,63.423973,-27.533709,0.014030,0.002326,0.059084,282.123932,14.372077,0.590837,-27.533709,0.059293,0.000000
61.110004,63.390083,-27.400267,0.014038,0.002326,0.059084,281.973175,14.364398,0.590837,-27.400267,0.059293,0.000000
61.310001,63.342415,-27.489227,0.013995,0.002326,0.059084,281.761139,14.353597,0.590837,-27.489227,0.059293,0.000000
61.510002,63.313377,-27.444746,0.014008,0.002326,0.059084,281.631958,14.347016,0.590837,-27.444746,0.059293,0.000000
61.710003,63.282463,-27.533709,0.014021,0.002326,0.059084,281.494446,14.340011,0.590837,-27.533709,0.059293,0.000000
61.910004,63.252312,-27.533709,0.014008,0.002326,0.059084,281.360321,14.333179,0.590837,-27.533709,0.059293,0.000000
62.110004,63.225121,-27.533709,0.014030,0.002326,0.059076,281.239380,14.327017,0.590762,-27.533709,0.059293,0.000000
62.310001,63.181557,-27.489227,0.014017,0.002326,0.059076,281.045593,14.317145,0.590762,-27.489227,0.059293,0.000000
62.510002,63.166664,-27.489227,0.014030,0.002326,0.059076,280.979370,14.313770,0.590762,-27.489227,0.059293,0.000000
62.710003,63.144325,-27.444746,0.014008,0.002326,0.059076,280.879974,14.308709,0.590762,-27.444746,0.059293,0.000000
62.910004,63.111549,-27.533709,0.014017,0.002326,0.059076,280.734192,14.301281,0.590762,-27.533709,0.059293,0.000000
63.110004,63.084740,-27.533709,0.014043,0.002326,0.059076,280.614929,14.295206,0.590762,-27.533709,0.059293,0.000000
63.310001,63.053459,-27.489227,0.014004,0.002326,0.059076,280.475800,14.288118,0.590762,-27.489227,0.059293,0.000000
63.510002,63.030739,-27.489227,0.014021,0.002326,0.059076,280.374725,14.282969,0.590762,-27.489227,0.059293,0.000000
63.710003,63.003563,-27.489227,0.014030,0.002326,0.059076,280.253845,14.276812,0.590762,-27.489227,0.059293,0.000000
63.910004,62.980095,-27.533709,0.014030,0.002326,0.059076,280.149445,14.271493,0.590762,-27.533709,0.059293,0.000000
64.110001,62.949944,-27.578190,0.014021,0.002326,0.059076,280.015320,14.264661,0.590762,-27.578190,0.059293,0.000000
64.310005,62.931320,-27.489227,0.014012,0.002326,0.059076,279.932495,14.260441,0.590762,-27.489227,0.059293,0.000000
64.510002,62.901161,-27.533709,0.013995,0.002326,0.059076,279.798340,14.253607,0.590762,-27.533709,0.059293,0.000000
64.710007,62.878815,-27.533709,0.014030,0.002326,0.059076,279.698944,14.248543,0.590762,-27.533709,0.059293,0.000000
64.910004,62.862434,-27.533709,0.014030,0.002326,0.059076,279.626068,14.244832,0.590762,-27.533709,0.059293,0.000000
65.110001,62.839714,-27.489227,0.014047,0.002326,0.059076,279.524994,14.239682,0.590762,-27.489227,0.059293,0.000000
65.310005,62.817001,-27.489227,0.014017,0.002326,0.059076,279.423981,14.234536,0.590762,-27.489227,0.059293,0.000000
65.510002,62.792053,-27.533709,0.013991,0.002326,0.059076,279.312988,14.228883,0.590762,-27.533709,0.059293,0.000000
65.710007,62.774925,-27.578190,0.014017,0.002326,0.059076,279.236816,14.225001,0.590762,-27.578190,0.059293,0.000000
65.910004,62.746628,-27.578190,0.014030,0.002326,0.059076,279.110931,14.218590,0.590762,-27.578190,0.059293,0.000000
66.110001,62.730614,-27.578190,0.014012,0.002326,0.059076,279.039703,14.214960,0.590762,-27.578190,0.059293,0.000000
66.310005,62.719810,-27.533709,0.013991,0.002326,0.059076,278.991638,14.212513,0.590762,-27.533709,0.059293,0.000000
66.510002,62.688904,-27.578190,0.013999,0.002326,0.059076,278.854156,14.205508,0.590762,-27.578190,0.059293,0.000000
66.710007,62.669914,-27.578190,0.014008,0.002326,0.059076,278.769714,14.201205,0.590762,-27.578190,0.059293,0.000000
66.910004,62.655769,-27.578190,0.014025,0.002326,0.059076,278.706787,14.198001,0.590762,-27.578190,0.059293,0.000000
67.110001,62.631561,-27.578190,0.013995,0.002326,0.059076,278.599091,14.192514,0.590762,-27.578190,0.059293,0.000000
67.310005,62.614433,-27.578190,0.014012,0.002326,0.059076,278.522919,14.188634,0.590762,-27.578190,0.059293,0.000000
67.510002,62.599907,-27.578190,0.014030,0.002326,0.059076,278.458282,14.185342,0.590762,-27.578190,0.059293,0.000000
67.710007,62.587250,-27.578190,0.014025,0.002326,0.059076,278.401978,14.182474,0.590762,-27.578190,0.059293,0.000000
67.910004,62.551872,-27.622671,0.013991,0.002326,0.059076,278.244629,14.174457,0.590762,-27.622671,0.059293,0.000000
68.110001,62.541817,-27.578190,0.014021,0.002326,0.059076,278.199890,14.172178,0.590762,-27.578190,0.059293,0.000000
68.310005,62.524689,-27.622671,0.014004,0.002326,0.059076,278.123718,14.168297,0.590762,-27.622671,0.059293,0.000000
68.510002,62.506447,-27.578190,0.014030,0.002326,0.059076,278.042572,14.164164,0.590762,-27.578190,0.059293,0.000000
68.710007,62.481865,-27.667152,0.014030,0.002326,0.059076,277.933228,14.158593,0.590762,-27.667152,0.059293,0.000000
68.910004,62.474419,-27.578190,0.014008,0.002326,0.059076,277.900085,14.156905,0.590762,-27.578190,0.059293,0.000000
69.110001,62.459900,-27.578190,0.014021,0.002326,0.059076,277.835510,14.153615,0.590762,-27.578190,0.059293,0.000000
69.310005,62.447983,-27.622671,0.014025,0.002326,0.059076,277.782501,14.150915,0.590762,-27.622671,0.059293,0.000000
69.510002,62.421547,-27.578190,0.014012,0.002326,0.059076,277.664917,14.144924,0.590762,-27.578190,0.059293,0.000000
69.710007,62.422287,-27.622671,0.014021,0.002326,0.059076,277.668213,14.145093,0.590762,-27.622671,0.059293,0.000000
69.910004,62.404411,-27.578190,0.014012,0.002326,0.059076,277.588684,14.141042,0.590762,-27.578190,0.059293,0.000000
70.110001,62.376862,-27.622671,0.014034,0.002326,0.059076,277.466125,14.134798,0.590762,-27.622671,0.059293,0.000000
70.310005,62.363823,-27.622671,0.014021,0.002326,0.059076,277.408142,14.131845,0.590762,-27.622671,0.059293,0.000000
70.510002,62.347816,-27.578190,0.014008,0.002326,0.059076,277.336945,14.128218,0.590762,-27.578190,0.059293,0.000000
70.710007,62.344093,-27.667152,0.014043,0.002326,0.059076,277.320374,14.127374,0.590762,-27.667152,0.059293,0.000000
70.910004,62.319138,-27.578190,0.013999,0.002326,0.059076,277.209381,14.121718,0.590762,-27.578190,0.059293,0.000000
71.110001,62.314301,-27.622671,0.014043,0.002326,0.059076,277.187866,14.120623,0.590762,-27.622671,0.059293,0.000000
71.310005,62.298286,-27.667152,0.014017,0.002326,0.059076,277.116608,14.116993,0.590762,-27.667152,0.059293,0.000000
71.510002,62.273712,-27.667152,0.014038,0.002326,0.059076,277.007294,14.111425,0.590762,-27.667152,0.059293,0.000000
71.710007,62.271103,-27.622671,0.013987,0.002326,0.059076,276.995697,14.110833,0.590762,-27.622671,0.059293,0.000000
71.910004,62.259560,-27.622671,0.014004,0.002326,0.059076,276.944366,14.108218,0.590762,-27.622671,0.059293,0.000000
72.110001,62.239456,-27.622671,0.014004,0.002326,0.059076,276.854919,14.103662,0.590762,-27.622671,0.059293,0.000000
72.310005,62.224930,-27.667152,0.014012,0.002326,0.059076,276.790314,14.100370,0.590762,-27.667152,0.059293,0.000000
72.510002,62.217110,-27.622671,0.014034,0.002326,0.059076,276.755524,14.098598,0.590762,-27.622671,0.059293,0.000000
72.710007,62.213387,-27.711632,0.014021,0.002326,0.059076,276.738953,14.097755,0.590762,-27.711632,0.059293,0.000000
72.910004,62.186951,-27.622671,0.013995,0.002326,0.059076,276.621368,14.091764,0.590762,-27.622671,0.059293,0.000000
73.110001,62.176147,-27.622671,0.013999,0.002326,0.059076,276.573303,14.089316,0.590762,-27.622671,0.059293,0.000000
73.310005,62.163864,-27.667152,0.013991,0.002326,0.059076,276.518677,14.086534,0.590762,-27.667152,0.059293,0.000000
73.510002,62.156044,-27.667152,0.014021,0.002326,0.059076,276.483887,14.084761,0.590762,-27.667152,0.059293,0.000000
73.710007,62.139282,-27.667152,0.014021,0.002326,0.059076,276.409332,14.080963,0.590762,-27.667152,0.059293,0.000000
73.910004,62.130348,-27.711632,0.014043,0.002326,0.059076,276.369598,14.078938,0.590762,-27.711632,0.059293,0.000000
74.110001,62.116196,-27.667152,0.013995,0.002326,0.059076,276.306641,14.075731,0.590762,-27.667152,0.059293,0.000000
74.310005,62.110611,-27.756113,0.014021,0.002326,0.059076,276.281799,14.074465,0.590762,-27.756113,0.059293,0.000000
74.510002,62.094231,-27.667152,0.014017,0.002326,0.059076,276.208923,14.070754,0.590762,-27.667152,0.059293,0.000000
74.710007,62.085289,-27.622671,0.014038,0.002326,0.059076,276.169159,14.068727,0.590762,-27.622671,0.059293,0.000000
74.910004,62.067787,-27.622671,0.014004,0.002326,0.059076,276.091309,14.064761,0.590762,-27.622671,0.059293,0.000000
75.110001,62.058105,-27.667152,0.014017,0.002326,0.059076,276.048248,14.062568,0.590762,-27.667152,0.059293,0.000000
75.310005,62.058105,-27.667152,0.014017,0.002326,0.059076,276.048248,14.062568,0.590762,-27.667152,0.059293,0.000000
75.510002,62.043587,-27.622671,0.014008,0.002326,0.059076,275.983643,14.059278,0.590762,-27.622671,0.059293,0.000000
75.710007,62.033531,-27.711632,0.014025,0.002326,0.059076,275.938934,14.056999,0.590762,-27.711632,0.059293,0.000000
75.910004,62.010071,-27.667152,0.014025,0.002326,0.059076,275.834564,14.051683,0.590762,-27.667152,0.059293,0.000000
76.110001,62.002625,-27.756113,0.013991,0.002326,0.059076,275.801453,14.049995,0.590762,-27.756113,0.059293,0.000000
76.310005,61.988106,-27.667152,0.014056,0.002326,0.059076,275.736877,14.046705,0.590762,-27.667152,0.059293,0.000000
76.510002,61.982887,-27.667152,0.014038,0.002326,0.059076,275.713654,14.045524,0.590762,-27.667152,0.059293,0.000000
76.710007,61.968369,-27.667152,0.014017,0.002326,0.059076,275.649078,14.042233,0.590762,-27.667152,0.059293,0.000000
76.910004,61.965012,-27.622671,0.014038,0.002326,0.059076,275.634125,14.041472,0.590762,-27.622671,0.059293,0.000000
77.110001,61.962784,-27.711632,0.014025,0.002326,0.059076,275.624237,14.040968,0.590762,-27.711632,0.059293,0.000000
77.310005,61.937828,-27.667152,0.014051,0.002326,0.059076,275.513214,14.035313,0.590762,-27.667152,0.059293,0.000000
77.510002,61.938950,-27.667152,0.014030,0.002326,0.059076,275.518219,14.035567,0.590762,-27.667152,0.059293,0.000000
77.710007,61.927032,-27.711632,0.014021,0.002326,0.059076,275.465210,14.032866,0.590762,-27.711632,0.059293,0.000000
77.910004,61.916603,-27.711632,0.014056,0.002326,0.059076,275.418793,14.030503,0.590762,-27.711632,0.059293,0.000000
78.110001,61.900597,-27.711632,0.014043,0.002326,0.059076,275.347595,14.026875,0.590762,-27.711632,0.059293,0.000000
78.310005,61.893150,-27.667152,0.014034,0.002326,0.059076,275.314484,14.025188,0.590762,-27.667152,0.059293,0.000000
78.510002,61.884583,-27.711632,0.013991,0.002326,0.059076,275.276367,14.023247,0.590762,-27.711632,0.059293,0.000000
78.710007,61.880486,-27.756113,0.014004,0.002326,0.059076,275.258148,14.022319,0.590762,-27.756113,0.059293,0.000000
78.910004,61.869690,-27.711632,0.014038,0.002326,0.059076,275.210114,14.019873,0.590762,-27.711632,0.059293,0.000000
79.110001,61.862244,-27.756113,0.014021,0.002326,0.059076,275.177002,14.018185,0.590762,-27.756113,0.059293,0.000000
79.310005,61.843994,-27.711632,0.014008,0.002326,0.059076,275.095825,14.014050,0.590762,-27.711632,0.059293,0.000000
79.510002,61.842506,-27.756113,0.014008,0.002326,0.059076,275.089203,14.013713,0.590762,-27.756113,0.059293,0.000000
79.710007,61.822395,-27.711632,0.014021,0.002326,0.059076,274.999756,14.009155,0.590762,-27.711632,0.059293,0.000000
79.910004,61.814949,-27.711632,0.014021,0.002326,0.059076,274.966614,14.007467,0.590762,-27.711632,0.059293,0.000000
80.110001,61.804893,-27.756113,0.014038,0.002326,0.059076,274.921906,14.005189,0.590762,-27.756113,0.059293,0.000000
80.310005,61.798195,-27.800594,0.014030,0.002326,0.059076,274.892090,14.003671,0.590762,-27.800594,0.059293,0.000000
80.510002,61.794098,-27.711632,0.014051,0.002326,0.059076,274.873871,14.002743,0.590762,-27.711632,0.059293,0.000000
80.710007,61.785156,-27.756113,0.014017,0.002326,0.059076,274.834106,14.000717,0.590762,-27.756113,0.059293,0.000000
80.910004,61.772499,-27.800594,0.014047,0.002326,0.059076,274.777802,13.997848,0.590762,-27.800594,0.059293,0.000000
81.110001,61.776596,-27.756113,0.014017,0.002326,0.059076,274.796021,13.998776,0.590762,-27.756113,0.059293,0.000000
81.310005,61.753883,-27.756113,0.014030,0.002326,0.059076,274.695007,13.993630,0.590762,-27.756113,0.059293,0.000000
81.510002,61.750526,-27.756113,0.014043,0.002326,0.059076,274.680054,13.992869,0.590762,-27.756113,0.059293,0.000000
81.710007,61.737495,-27.756113,0.014043,0.002326,0.059076,274.622101,13.989916,0.590762,-27.756113,0.059293,0.000000
81.910004,61.719620,-27.800594,0.014012,0.002326,0.059076,274.542572,13.985866,0.590762,-27.800594,0.059293,0.000000
82.110001,61.724091,-27.800594,0.014008,0.002326,0.059076,274.562469,13.986878,0.590762,-27.800594,0.059293,0.000000
82.310005,61.718132,-27.800594,0.014012,0.002326,0.059076,274.535950,13.985529,0.590762,-27.800594,0.059293,0.000000
82.510002,61.697281,-27.756113,0.014012,0.002326,0.059076,274.443207,13.980803,0.590762,-27.756113,0.059293,0.000000
82.710007,61.690201,-27.756113,0.014038,0.002326,0.059076,274.411713,13.979199,0.590762,-27.756113,0.059293,0.000000
82.910004,61.693924,-27.800594,0.014038,0.002326,0.059076,274.428284,13.980042,0.590762,-27.800594,0.059293,0.000000
83.110001,61.688339,-27.800594,0.014012,0.002326,0.059076,274.403442,13.978777,0.590762,-27.800594,0.059293,0.000000
83.310005,61.680519,-27.756113,0.014021,0.002326,0.059076,274.368652,13.977006,0.590762,-27.756113,0.059293,0.000000
83.510002,61.658180,-27.800594,0.014008,0.002326,0.059076,274.269287,13.971944,0.590762,-27.800594,0.059293,0.000000
83.710007,61.657806,-27.800594,0.014021,0.002326,0.059076,274.267609,13.971858,0.590762,-27.800594,0.059293,0.000000
83.800003,61.642540,-27.800594,0.014021,0.002326,0.059076,274.199707,13.968399,0.590762,-27.800594,0.059293,0.000000