File: Data/New old I18 4 new align_08182023_120245.csv
Time (sec),S:Load (lbs),S:HL1 (DIM),S:LVDT (in),S:Position (in),Ch:Position (mm),Ch:Load (N),Ch:Stress (MPa),Ch:Strain (mm/mm),Ch:HL1 (DIM),Set Point (),Cycles ()
0.110000,-0.009682,-30.469452,0.000052,-0.000000,-0.000000,-0.043066,-0.002194,-0.000000,-30.469452,0.000207,0.000000
0.490000,-0.030167,-30.513933,0.000056,0.000053,0.001352,-0.134188,-0.006836,0.013520,-30.513933,0.001908,0.000000
0.870000,0.009682,-30.513933,0.000147,0.000279,0.007076,0.043066,0.002194,0.070762,-30.513933,0.008237,0.000000
1.250000,-0.009315,-30.469452,0.000392,0.000527,0.013380,-0.041437,-0.002111,0.133804,-30.469452,0.014569,0.000000
1.630000,0.035744,-30.424971,0.000647,0.000767,0.019486,0.158996,0.008100,0.194862,-30.424971,0.020899,0.000000
2.010000,0.049896,-30.513933,0.000867,0.001020,0.025911,0.221950,0.011307,0.259114,-30.513933,0.027230,0.000000
2.390000,0.030533,-30.558413,0.001138,0.001269,0.032243,0.135817,0.006919,0.322428,-30.558413,0.033561,0.000000
2.770000,0.028297,-30.558413,0.001440,0.001520,0.038607,0.125873,0.006412,0.386074,-30.558413,0.039891,0.000000
3.150000,0.022339,-30.513933,0.001699,0.001771,0.044983,0.099368,0.005062,0.449827,-30.513933,0.046223,0.000000
3.530000,0.018616,-30.513933,0.001919,0.002019,0.051278,0.082807,0.004218,0.512778,-30.513933,0.052553,0.000000
3.910000,0.030159,-30.602894,0.002169,0.002268,0.057609,0.134154,0.006834,0.576091,-30.602894,0.058884,0.000000
4.290000,0.027184,-30.558413,0.002462,0.002522,0.064069,0.120918,0.006160,0.640692,-30.558413,0.065215,0.000000
4.670000,0.037605,-30.602894,0.002721,0.002772,0.070419,0.167277,0.008521,0.704187,-30.602894,0.071545,0.000000
5.050000,0.042076,-30.558413,0.002992,0.003021,0.076723,0.187164,0.009535,0.767228,-30.558413,0.077876,0.000000
5.430000,0.022713,-30.602894,0.003238,0.003267,0.082985,0.101031,0.005147,0.829846,-30.602894,0.084206,0.000000
5.810000,0.000740,-30.602894,0.003505,0.003517,0.089333,0.003292,0.000168,0.893326,-30.602894,0.090538,0.000000
6.190000,0.027184,-30.736338,0.003781,0.003767,0.095672,0.120918,0.006160,0.956715,-30.736338,0.096869,0.000000
6.570000,0.033508,-30.602894,0.004049,0.004016,0.102010,0.149052,0.007593,1.020105,-30.602894,0.103199,0.000000
6.950000,0.025322,-30.602894,0.004303,0.004270,0.108463,0.112638,0.005738,1.084630,-30.602894,0.109530,0.000000
7.330000,-0.008942,-30.602894,0.004562,0.004515,0.114690,-0.039774,-0.002026,1.146899,-30.602894,0.115860,0.000000
7.710001,-0.016762,-30.691856,0.004838,0.004765,0.121021,-0.074560,-0.003798,1.210213,-30.691856,0.122192,0.000000
8.090000,0.025322,-30.691856,0.005075,0.005016,0.127395,0.112638,0.005738,1.273950,-30.691856,0.128521,0.000000
8.470000,0.013405,-30.647375,0.005346,0.005266,0.133752,0.059628,0.003038,1.337521,-30.647375,0.134853,0.000000
8.850000,0.036118,-30.647375,0.005614,0.005516,0.140100,0.160659,0.008184,1.401002,-30.647375,0.141184,0.000000
9.230000,0.042816,-30.736338,0.005855,0.005764,0.146413,0.190456,0.009702,1.464134,-30.736338,0.147514,0.000000
9.610001,0.014893,-30.691856,0.006109,0.006017,0.152831,0.066245,0.003375,1.528310,-30.691856,0.153845,0.000000
9.990001,0.026062,-30.780819,0.006372,0.006266,0.159144,0.115930,0.005906,1.591442,-30.780819,0.160175,0.000000
10.370001,0.065910,-30.736338,0.006648,0.006510,0.165362,0.293184,0.014935,1.653621,-30.736338,0.166507,0.000000
10.750001,0.067772,-30.691856,0.006877,0.006760,0.171692,0.301465,0.015357,1.716919,-30.691856,0.172838,0.000000
11.130000,0.070747,-30.780819,0.007166,0.007010,0.178049,0.314700,0.016032,1.780490,-30.780819,0.179168,0.000000
11.510000,0.097183,-30.780819,0.007407,0.007250,0.184146,0.432293,0.022022,1.841457,-30.780819,0.185499,0.000000
11.890000,0.126602,-30.825298,0.007653,0.007502,0.190563,0.563155,0.028688,1.905634,-30.825298,0.191829,0.000000
12.270000,0.242409,-30.825298,0.007881,0.007750,0.196851,1.078288,0.054931,1.968509,-30.825298,0.198160,0.000000
12.650001,0.376091,-30.780819,0.008132,0.008001,0.203234,1.672936,0.085223,2.032337,-30.780819,0.204492,0.000000
13.030001,0.564140,-30.825298,0.008343,0.008250,0.209556,2.509422,0.127836,2.095560,-30.825298,0.210822,0.000000
13.410001,0.603615,-30.914261,0.008468,-0.000005,-0.000129,2.685013,0.136781,-0.001287,-30.914261,0.000079,0.000000
13.790001,0.499352,-30.869780,0.008485,-0.000005,-0.000138,2.221226,0.113155,-0.001378,-30.869780,0.000165,0.000000
14.170001,0.609573,-30.869780,0.008476,-0.000005,-0.000129,2.711518,0.138131,-0.001287,-30.869780,0.000798,0.000000
14.550001,0.588715,-30.780819,0.008494,-0.000004,-0.000095,2.618733,0.133405,-0.000954,-30.780819,0.001432,0.000000
14.930000,0.708992,-30.914261,0.008489,0.000045,0.001137,3.153754,0.160660,0.011370,-30.914261,0.002065,0.000000
15.310000,0.723518,-30.869780,0.008502,0.000069,0.001744,3.218370,0.163952,0.017441,-30.869780,0.002698,0.000000
15.690001,0.729843,-30.914261,0.008537,0.000092,0.002325,3.246505,0.165385,0.023254,-30.914261,0.003331,0.000000
16.070002,0.781982,-30.869780,0.008558,0.000120,0.003045,3.478431,0.177200,0.030446,-30.869780,0.003964,0.000000
16.450001,0.808418,-30.958742,0.008580,0.000138,0.003505,3.596024,0.183190,0.035048,-30.958742,0.004596,0.000000
16.830000,0.848633,-30.958742,0.008610,0.000163,0.004147,3.774907,0.192303,0.041467,-30.958742,0.005231,0.000000
17.210001,0.879166,-30.958742,0.008619,0.000194,0.004926,3.910724,0.199222,0.049264,-30.958742,0.005864,0.000000
17.590000,0.893692,-31.003223,0.008645,0.000216,0.005499,3.975341,0.202514,0.054987,-31.003223,0.006496,0.000000
17.970001,0.933907,-30.914261,0.008658,0.000238,0.006045,4.154224,0.211626,0.060452,-30.914261,0.007129,0.000000
18.350000,1.006523,-30.958742,0.008696,0.000265,0.006731,4.477239,0.228081,0.067311,-30.958742,0.007762,0.000000
18.730001,1.029610,-30.958742,0.008709,0.000283,0.007181,4.579933,0.233313,0.071807,-30.958742,0.008395,0.000000
19.110001,1.063118,-31.047705,0.008714,0.000317,0.008048,4.728985,0.240906,0.080482,-31.047705,0.009037,0.000000
19.490002,1.064613,-30.958742,0.008739,0.000334,0.008483,4.735637,0.241245,0.084827,-30.958742,0.009670,0.000000
19.870001,1.103340,-31.003223,0.008778,0.000361,0.009167,4.907902,0.250020,0.091670,-31.003223,0.010304,0.000000
20.250002,1.200897,-31.003223,0.008795,0.000391,0.009922,5.341857,0.272127,0.099225,-31.003223,0.010937,0.000000
20.630001,1.239998,-31.003223,0.008817,0.000408,0.010365,5.515786,0.280988,0.103646,-31.003223,0.011570,0.000000
21.010000,1.301811,-31.047705,0.008834,0.000444,0.011284,5.790746,0.294995,0.112835,-31.047705,0.012203,0.000000
21.390001,1.302559,-31.047705,0.008877,0.000462,0.011742,5.794071,0.295164,0.117423,-31.047705,0.012835,0.000000
21.770000,1.349472,-30.958742,0.008877,0.000486,0.012333,6.002751,0.305795,0.123327,-30.958742,0.013468,0.000000
22.150002,1.483154,-31.047705,0.008903,0.000515,0.013070,6.597400,0.336088,0.130700,-31.047705,0.014101,0.000000
22.530001,1.504753,-31.092184,0.008921,0.000533,0.013538,6.693476,0.340982,0.135378,-31.092184,0.014735,0.000000
22.910002,1.579971,-31.092184,0.008946,0.000565,0.014361,7.028063,0.358027,0.143614,-31.092184,0.015368,0.000000
23.290001,1.613113,-31.047705,0.008955,0.000588,0.014926,7.175487,0.365537,0.149261,-31.047705,0.016001,0.000000
23.670002,1.638435,-31.003223,0.009002,0.000610,0.015498,7.288125,0.371275,0.154984,-31.003223,0.016634,0.000000
24.050001,1.799301,-31.092184,0.009024,0.000641,0.016271,8.003692,0.407727,0.162705,-31.092184,0.017267,0.000000
24.430000,1.867073,-31.136665,0.009058,0.000660,0.016764,8.305156,0.423085,0.167641,-31.136665,0.017900,0.000000
24.810001,1.949364,-31.136665,0.009046,0.000692,0.017580,8.671203,0.441732,0.175801,-31.136665,0.018534,0.000000
25.190001,2.003357,-31.092184,0.009058,0.000713,0.018118,8.911377,0.453967,0.181175,-31.092184,0.019167,0.000000
25.570002,2.071129,-31.136665,0.009115,0.000742,0.018837,9.212841,0.469324,0.188367,-31.136665,0.019800,0.000000
25.950001,2.214867,-31.136665,0.009123,0.000763,0.019383,9.852219,0.501896,0.193832,-31.136665,0.020432,0.000000
26.330002,2.299400,-31.136665,0.009115,0.000782,0.019851,10.228244,0.521052,0.198510,-31.136665,0.021065,0.000000
26.710001,2.360840,-31.181147,0.009153,0.000803,0.020388,10.501540,0.534974,0.203885,-31.181147,0.021698,0.000000
27.090002,2.523193,-31.181147,0.009184,0.000837,0.021265,11.223724,0.571764,0.212651,-31.181147,0.022332,0.000000
27.470001,2.598412,-31.181147,0.009188,0.000862,0.021898,11.558311,0.588808,0.218979,-31.181147,0.022965,0.000000
27.850000,2.741028,-31.181147,0.009192,0.000888,0.022549,12.192700,0.621126,0.225489,-31.181147,0.023598,0.000000
28.230001,2.808800,-31.270109,0.009222,0.000903,0.022947,12.494165,0.636483,0.229471,-31.270109,0.024231,0.000000
28.610001,2.963333,-31.181147,0.009248,0.000932,0.023668,13.181564,0.671501,0.236677,-31.181147,0.024864,0.000000
28.990002,3.142448,-31.225628,0.009296,0.000963,0.024466,13.978309,0.712089,0.244656,-31.225628,0.025497,0.000000
29.370001,3.257881,-31.225628,0.009304,0.000986,0.025045,14.491779,0.738246,0.250454,-31.225628,0.026131,0.000000
29.750002,3.461197,-31.314590,0.009326,0.001015,0.025783,15.396173,0.784318,0.257827,-31.314590,0.026764,0.000000
30.130001,3.596741,-31.314590,0.009326,0.001037,0.026338,15.999102,0.815033,0.263383,-31.314590,0.027406,0.000000
30.510002,3.808998,-31.270109,0.009369,0.001066,0.027067,16.943270,0.863131,0.270665,-31.270109,0.028039,0.000000
30.890001,3.941185,-31.314590,0.009403,0.001090,0.027674,17.531267,0.893085,0.276736,-31.314590,0.028671,0.000000
31.270002,4.067795,-31.314590,0.009403,0.001116,0.028341,18.094456,0.921775,0.283413,-31.314590,0.029304,0.000000
31.650002,4.198494,-31.359070,0.009416,0.001143,0.029027,18.675835,0.951392,0.290271,-31.359070,0.029937,0.000000
32.030003,4.250259,-31.403551,0.009442,0.001161,0.029495,18.906097,0.963123,0.294949,-31.403551,0.030570,0.000000
32.410000,4.461388,-31.314590,0.009459,0.001188,0.030172,19.845243,1.010965,0.301717,-31.314590,0.031204,0.000000
32.790001,4.556343,-31.314590,0.009498,0.001214,0.030830,20.267626,1.032482,0.308302,-31.314590,0.031837,0.000000
33.170002,4.667313,-31.314590,0.009524,0.001238,0.031456,20.761244,1.057628,0.314555,-31.314590,0.032470,0.000000
33.550003,4.788338,-31.403551,0.009563,0.001263,0.032088,21.299589,1.085053,0.320883,-31.403551,0.033103,0.000000
33.930000,4.843445,-31.403551,0.009576,0.001286,0.032661,21.544718,1.097540,0.326606,-31.403551,0.033736,0.000000
34.310001,4.987923,-31.359070,0.009589,0.001307,0.033189,22.187387,1.130280,0.331890,-31.359070,0.034368,0.000000
34.690002,5.154373,-31.403551,0.009623,0.001341,0.034056,22.927797,1.167998,0.340565,-31.403551,0.035001,0.000000
35.070004,5.222519,-31.403551,0.009649,0.001362,0.034603,23.230925,1.183440,0.346030,-31.403551,0.035636,0.000000
35.450001,5.415039,-31.448032,0.009701,0.001389,0.035287,24.087297,1.227065,0.352873,-31.448032,0.036268,0.000000
35.830002,5.430305,-31.492514,0.009671,0.001409,0.035799,24.155205,1.230525,0.357991,-31.492514,0.036901,0.000000
36.210003,5.667503,-31.403551,0.009710,0.001437,0.036502,25.210314,1.284275,0.365015,-31.403551,0.037534,0.000000
36.590000,5.737137,-31.448032,0.009735,0.001465,0.037204,25.520060,1.300054,0.372040,-31.448032,0.038167,0.000000
36.970001,5.820175,-31.448032,0.009770,0.001488,0.037794,25.889433,1.318871,0.377944,-31.448032,0.038800,0.000000
37.350002,6.008224,-31.448032,0.009809,0.001516,0.038514,26.725918,1.361483,0.385136,-31.448032,0.039434,0.000000
37.730003,6.051422,-31.492514,0.009813,0.001536,0.039025,26.918070,1.371272,0.390253,-31.492514,0.040067,0.000000
38.110001,6.192177,-31.492514,0.009839,0.001560,0.039616,27.544178,1.403167,0.396157,-31.492514,0.040700,0.000000
38.490002,6.378365,-31.492514,0.009852,0.001591,0.040405,28.372383,1.445358,0.404045,-31.492514,0.041333,0.000000
38.870003,6.373154,-31.536995,0.009886,0.001613,0.040977,28.349203,1.444177,0.409768,-31.536995,0.041965,0.000000
39.250000,6.445763,-31.536995,0.009916,0.001632,0.041446,28.672184,1.460631,0.414461,-31.536995,0.042598,0.000000
39.630001,6.660622,-31.448032,0.009938,0.001661,0.042200,29.627924,1.509318,0.422001,-31.448032,0.043233,0.000000
40.010002,6.684456,-31.536995,0.009938,0.001679,0.042642,29.733944,1.514719,0.426421,-31.536995,0.043865,0.000000
40.390003,6.936920,-31.536995,0.009990,0.001716,0.043579,30.856962,1.571929,0.435793,-31.536995,0.044498,0.000000
40.770000,6.921288,-31.536995,0.010020,0.001732,0.043996,30.787424,1.568386,0.439956,-31.536995,0.045131,0.000000
41.150002,7.074326,-31.581474,0.010033,0.001758,0.044645,31.468172,1.603065,0.446451,-31.581474,0.045773,0.000000
41.530003,7.280624,-31.536995,0.010059,0.001788,0.045417,32.385834,1.649813,0.454172,-31.536995,0.046406,0.000000
41.910004,7.316002,-31.536995,0.010067,0.001804,0.045824,32.543201,1.657830,0.458245,-31.536995,0.047039,0.000000
42.290001,7.472771,-31.581474,0.010106,0.001835,0.046615,33.240543,1.693354,0.466148,-31.581474,0.047672,0.000000
42.670002,7.562508,-31.581474,0.010145,0.001858,0.047204,33.639713,1.713689,0.472037,-31.581474,0.048306,0.000000
43.050003,7.581871,-31.581474,0.010154,0.001882,0.047802,33.725845,1.718076,0.478017,-31.581474,0.048939,0.000000
43.430000,7.873810,-31.581474,0.010167,0.001911,0.048548,35.024456,1.784231,0.485481,-31.581474,0.049572,0.000000
43.810001,7.846626,-31.581474,0.010188,0.001928,0.048974,34.903538,1.778071,0.489735,-31.581474,0.050204,0.000000
44.190002,8.092766,-31.670437,0.010223,0.001961,0.049814,35.998421,1.833847,0.498138,-31.670437,0.050837,0.000000
44.570004,8.192566,-31.670437,0.010240,0.001985,0.050421,36.442352,1.856462,0.504209,-31.670437,0.051470,0.000000
44.950001,8.220863,-31.670437,0.010266,0.002005,0.050923,36.568226,1.862874,0.509235,-31.670437,0.052103,0.000000
45.330002,8.488976,-31.625956,0.010305,0.002038,0.051774,37.760849,1.923629,0.517743,-31.625956,0.052737,0.000000
45.710003,8.415611,-31.670437,0.010322,0.002053,0.052138,37.434509,1.907005,0.521377,-31.670437,0.053370,0.000000
46.090004,8.719841,-31.714918,0.010356,0.002089,0.053066,38.787788,1.975944,0.530657,-31.714918,0.054003,0.000000
46.470001,8.722076,-31.759399,0.010369,0.002110,0.053587,38.797733,1.976451,0.535865,-31.759399,0.054636,0.000000
46.850002,8.835281,-31.759399,0.010386,0.002136,0.054245,39.301296,2.002103,0.542451,-31.759399,0.055269,0.000000
47.230003,9.073967,-31.714918,0.010417,0.002160,0.054870,40.363022,2.056190,0.548704,-31.714918,0.055901,0.000000
47.610001,9.151047,-31.714918,0.010434,0.002180,0.055364,40.705891,2.073657,0.553639,-31.714918,0.056536,0.000000
47.990002,9.300369,-31.714918,0.010464,0.002204,0.055989,41.370110,2.107494,0.559892,-31.714918,0.057169,0.000000
48.370003,9.446342,-31.803881,0.010473,0.002235,0.056778,42.019428,2.140572,0.567780,-31.803881,0.057801,0.000000
48.750004,9.474640,-31.714918,0.010520,0.002256,0.057306,42.145302,2.146984,0.573063,-31.714918,0.058434,0.000000
49.130001,9.688385,-31.759399,0.010516,0.002283,0.057983,43.096088,2.195419,0.579831,-31.759399,0.059067,0.000000
49.510002,9.717430,-31.803881,0.010559,0.002302,0.058469,43.225288,2.202001,0.584691,-31.803881,0.059700,0.000000
49.890003,9.902496,-31.803881,0.010589,0.002327,0.059111,44.048504,2.243938,0.591110,-31.803881,0.060334,0.000000
50.270004,10.056664,-31.803881,0.010589,0.002361,0.059960,44.734272,2.278873,0.599603,-31.803881,0.060967,0.000000
50.650002,10.173210,-31.803881,0.010589,0.002382,0.060498,45.252697,2.305282,0.604978,-31.803881,0.061600,0.000000
51.030003,10.386955,-31.759399,0.010667,0.002412,0.061261,46.203484,2.353718,0.612608,-31.759399,0.062233,0.000000
51.410004,10.415253,-31.848360,0.010684,0.002431,0.061756,46.329357,2.360130,0.617559,-31.848360,0.062866,0.000000
51.790001,10.624901,-31.848360,0.010688,0.002459,0.062467,47.261921,2.407637,0.624674,-31.848360,0.063508,0.000000
52.170002,10.722832,-31.937323,0.010727,0.002486,0.063152,47.697536,2.429828,0.631517,-31.937323,0.064140,0.000000
52.550003,10.866196,-31.803881,0.010757,0.002513,0.063819,48.335251,2.462315,0.638194,-31.803881,0.064773,0.000000
52.930004,10.996155,-31.803881,0.010762,0.002536,0.064426,48.913338,2.491764,0.644265,-31.803881,0.065408,0.000000
53.310001,11.022591,-31.892841,0.010809,0.002555,0.064887,49.030933,2.497755,0.648867,-31.892841,0.066040,0.000000
53.690002,11.393105,-31.892841,0.010805,0.002585,0.065659,50.679062,2.581714,0.656588,-31.892841,0.066673,0.000000
54.070004,11.456039,-31.892841,0.010835,0.002612,0.066352,50.959007,2.595976,0.663522,-31.892841,0.067306,0.000000
54.450001,11.559555,-31.892841,0.010861,0.002636,0.066950,51.419468,2.619432,0.669502,-31.892841,0.067939,0.000000
54.830002,11.597908,-31.892841,0.010882,0.002657,0.067480,51.590073,2.628124,0.674801,-31.892841,0.068572,0.000000
55.210003,11.711113,-31.937323,0.010921,0.002679,0.068034,52.093632,2.653776,0.680342,-31.937323,0.069205,0.000000
55.590004,11.951660,-31.981804,0.010908,0.002702,0.068632,53.163639,2.708285,0.686323,-31.981804,0.069839,0.000000
55.970001,12.189606,-31.981804,0.010956,0.002735,0.069474,54.222073,2.762204,0.694740,-31.981804,0.070472,0.000000
56.350002,12.232803,-31.937323,0.010960,0.002756,0.069995,54.414227,2.771993,0.699948,-31.937323,0.071105,0.000000
56.730003,12.359413,-31.937323,0.010999,0.002782,0.070672,54.977417,2.800683,0.706716,-31.937323,0.071737,0.000000
57.110004,12.499054,-32.026283,0.011016,0.002806,0.071279,55.598568,2.832326,0.712787,-32.026283,0.072370,0.000000
57.490002,12.653961,-32.026283,0.011025,0.002829,0.071851,56.287632,2.867429,0.718509,-32.026283,0.073003,0.000000
57.870003,12.912384,-31.981804,0.011089,0.002860,0.072649,57.437153,2.925988,0.726488,-31.981804,0.073637,0.000000
58.250004,12.996170,-31.937323,0.011089,0.002883,0.073229,57.809853,2.944974,0.732286,-31.937323,0.074270,0.000000
58.630001,13.274704,-32.026283,0.011141,0.002914,0.074019,59.048832,3.008091,0.740189,-32.026283,0.074903,0.000000
59.010002,13.338379,-32.026283,0.011154,0.002935,0.074547,59.332073,3.022520,0.745473,-32.026283,0.075536,0.000000
59.390003,13.490677,-32.026283,0.011171,0.002957,0.075110,60.009529,3.057031,0.751105,-32.026283,0.076169,0.000000
59.770004,13.736069,-32.026283,0.011193,0.002988,0.075892,61.101086,3.112638,0.758917,-32.026283,0.076802,0.000000
60.150002,13.701439,-32.070766,0.011206,0.003004,0.076299,60.947044,3.104790,0.762989,-32.070766,0.077436,0.000000
60.530003,13.831024,-32.026283,0.011275,0.003027,0.076897,61.523468,3.134155,0.768970,-32.026283,0.078069,0.000000
60.910004,14.176216,-32.115246,0.011253,0.003058,0.077678,63.058960,3.212377,0.776782,-32.115246,0.078702,0.000000
61.290005,14.149780,-32.070766,0.011283,0.003072,0.078034,62.941364,3.206386,0.780339,-32.070766,0.079334,0.000000
61.670002,14.589546,-32.115246,0.011344,0.003113,0.079065,64.897545,3.306038,0.790649,-32.115246,0.079967,0.000000
62.050003,14.512840,-32.070766,0.011344,0.003130,0.079509,64.556335,3.288656,0.795085,-32.070766,0.080600,0.000000
62.430004,14.674454,-32.159729,0.011369,0.003152,0.080054,65.275230,3.325279,0.800536,-32.159729,0.081234,0.000000
62.810001,14.891914,-32.115246,0.011395,0.003182,0.080826,66.242546,3.374556,0.808257,-32.115246,0.081875,0.000000
63.190002,14.998413,-32.115246,0.011400,0.003202,0.081330,66.716270,3.398689,0.813298,-32.115246,0.082509,0.000000
63.570004,15.340256,-32.159729,0.011438,0.003234,0.082135,68.236862,3.476152,0.821352,-32.159729,0.083142,0.000000
63.950005,15.349937,-32.159729,0.011473,0.003256,0.082708,68.279930,3.478346,0.827075,-32.159729,0.083775,0.000000
64.330002,15.474678,-32.204208,0.011464,0.003276,0.083212,68.834808,3.506612,0.832117,-32.204208,0.084408,0.000000
64.710007,15.607613,-32.159729,0.011495,0.003295,0.083696,69.426125,3.536736,0.836961,-32.159729,0.085041,0.000000
65.090004,15.819122,-32.248688,0.011525,0.003323,0.084417,70.366974,3.584664,0.844168,-32.248688,0.085673,0.000000
65.470001,16.201553,-32.204208,0.011551,0.003357,0.085257,72.068108,3.671324,0.852570,-32.204208,0.086308,0.000000
65.850006,16.229477,-32.204208,0.011598,0.003380,0.085847,72.192322,3.677652,0.858475,-32.204208,0.086941,0.000000
66.230003,16.371727,-32.248688,0.011628,0.003403,0.086436,72.825081,3.709887,0.864364,-32.248688,0.087573,0.000000
66.610001,16.556046,-32.204208,0.011632,0.003429,0.087104,73.644966,3.751654,0.871041,-32.204208,0.088206,0.000000
66.990005,16.646538,-32.248688,0.011650,0.003449,0.087616,74.047501,3.772159,0.876158,-32.248688,0.088839,0.000000
67.370003,16.954857,-32.293171,0.011689,0.003482,0.088441,75.418968,3.842026,0.884409,-32.293171,0.089472,0.000000
67.750000,17.000664,-32.248688,0.011697,0.003502,0.088953,75.622726,3.852406,0.889526,-32.248688,0.090105,0.000000
68.130005,17.113487,-32.293171,0.011727,0.003526,0.089551,76.124596,3.877972,0.895506,-32.293171,0.090739,0.000000
68.510002,17.266167,-32.248688,0.011766,0.003548,0.090114,76.803749,3.912569,0.901138,-32.248688,0.091372,0.000000
68.890007,17.546562,-32.293171,0.011788,0.003574,0.090791,78.051010,3.976108,0.907905,-32.293171,0.092005,0.000000
69.270004,17.661247,-32.248688,0.011801,0.003594,0.091277,78.561150,4.002096,0.912765,-32.248688,0.092638,0.000000
69.650002,18.028412,-32.337650,0.011818,0.003628,0.092161,80.194382,4.085297,0.921607,-32.337650,0.093270,0.000000
70.030006,18.071602,-32.337650,0.011865,0.003651,0.092724,80.386497,4.095084,0.927239,-32.337650,0.093903,0.000000
70.410004,18.237312,-32.382133,0.011865,0.003676,0.093375,81.123619,4.132634,0.933749,-32.382133,0.094538,0.000000
70.790001,18.341576,-32.382133,0.011895,0.003697,0.093896,81.587402,4.156260,0.938957,-32.382133,0.095170,0.000000
71.170006,18.695702,-32.337650,0.011917,0.003723,0.094571,83.162636,4.236506,0.945709,-32.337650,0.095803,0.000000
71.550003,18.902740,-32.293171,0.011960,0.003754,0.095361,84.083588,4.283422,0.953612,-32.293171,0.096436,0.000000
71.930000,18.938858,-32.426613,0.011995,0.003778,0.095950,84.244247,4.291607,0.959501,-32.426613,0.097069,0.000000
72.310005,19.148132,-32.382133,0.011990,0.003803,0.096601,85.175148,4.339029,0.966011,-32.382133,0.097702,0.000000
72.690002,19.238251,-32.337650,0.012025,0.003825,0.097155,85.576012,4.359450,0.971552,-32.337650,0.098336,0.000000
73.070000,19.461670,-32.382133,0.012064,0.003850,0.097780,86.569832,4.410077,0.977805,-32.382133,0.098969,0.000000
73.450005,19.812447,-32.426613,0.012085,0.003882,0.098595,88.130165,4.489564,0.985950,-32.426613,0.099602,0.000000
73.830002,19.832558,-32.426613,0.012085,0.003905,0.099176,88.219620,4.494122,0.991764,-32.426613,0.100244,0.000000
74.210007,19.830696,-32.426613,0.012124,0.003922,0.099628,88.211342,4.493700,0.996275,-32.426613,0.100877,0.000000
74.590004,20.125237,-32.382133,0.012180,0.003950,0.100330,89.521523,4.560444,1.003300,-32.382133,0.101509,0.000000
74.970001,20.200455,-32.426613,0.012163,0.003971,0.100867,89.856110,4.577489,1.008675,-32.426613,0.102142,0.000000
75.350006,20.630920,-32.471096,0.012215,0.004005,0.101735,91.770920,4.675034,1.017349,-32.471096,0.102775,0.000000
75.730003,20.713585,-32.471096,0.012219,0.004027,0.102291,92.138626,4.693765,1.022906,-32.471096,0.103409,0.000000
76.110001,20.692360,-32.471096,0.012258,0.004046,0.102767,92.044212,4.688956,1.027675,-32.471096,0.104042,0.000000
76.490005,21.010742,-32.471096,0.012279,0.004074,0.103478,93.460449,4.761102,1.034775,-32.471096,0.104675,0.000000
76.870003,21.128784,-32.471096,0.012284,0.004094,0.103998,93.985527,4.787851,1.039983,-32.471096,0.105308,0.000000
77.250000,21.646378,-32.515575,0.012322,0.004133,0.104987,96.287895,4.905139,1.049869,-32.515575,0.105941,0.000000
77.630005,21.567436,-32.515575,0.012322,0.004153,0.105482,95.936745,4.887251,1.054820,-32.515575,0.106574,0.000000
78.010002,21.805756,-32.515575,0.012413,0.004176,0.106062,96.996849,4.941255,1.060618,-32.515575,0.107206,0.000000
78.390007,22.043327,-32.471096,0.012396,0.004204,0.106773,98.053619,4.995089,1.067734,-32.471096,0.107841,0.000000
78.770004,22.075729,-32.471096,0.012417,0.004224,0.107285,98.197746,5.002432,1.072851,-32.471096,0.108474,0.000000
79.150002,22.478630,-32.560055,0.012443,0.004257,0.108127,99.989937,5.093730,1.081269,-32.560055,0.109106,0.000000
79.530006,22.465599,-32.604538,0.012486,0.004276,0.108604,99.931976,5.090777,1.086038,-32.604538,0.109739,0.000000
79.910004,22.884148,-32.560055,0.012503,0.004305,0.109358,101.793770,5.185622,1.093577,-32.560055,0.110372,0.000000
80.290001,22.900528,-32.515575,0.012516,0.004329,0.109956,101.866638,5.189334,1.099557,-32.515575,0.111005,0.000000
80.670006,23.053574,-32.604538,0.012547,0.004351,0.110520,102.547417,5.224015,1.105204,-32.604538,0.111639,0.000000
81.050003,23.267319,-32.604538,0.012603,0.004376,0.111144,103.498199,5.272449,1.111442,-32.604538,0.112272,0.000000
81.430000,23.418503,-32.649017,0.012603,0.004401,0.111777,104.170700,5.306708,1.117770,-32.649017,0.112905,0.000000
81.810005,23.609528,-32.604538,0.012598,0.004424,0.112367,105.020424,5.349995,1.123675,-32.604538,0.113538,0.000000
82.190002,23.887321,-32.604538,0.012654,0.004451,0.113052,106.256111,5.412944,1.130518,-32.604538,0.114171,0.000000
82.570007,23.975197,-32.604538,0.012672,0.004471,0.113556,106.647003,5.432857,1.135559,-32.604538,0.114803,0.000000
82.950005,24.533760,-32.693501,0.012684,0.004507,0.114475,109.131615,5.559430,1.144749,-32.693501,0.115438,0.000000
83.330002,24.374756,-32.649017,0.012706,0.004527,0.114987,108.424332,5.523399,1.149866,-32.649017,0.116071,0.000000
83.710007,24.553864,-32.649017,0.012715,0.004550,0.115576,109.221039,5.563985,1.155756,-32.649017,0.116703,0.000000
84.090004,24.916183,-32.649017,0.012766,0.004577,0.116261,110.832718,5.646088,1.162614,-32.649017,0.117336,0.000000
84.470001,24.884529,-32.649017,0.012775,0.004595,0.116703,110.691917,5.638915,1.167035,-32.649017,0.117969,0.000000
84.850006,25.334358,-32.737980,0.012788,0.004626,0.117501,112.692856,5.740848,1.175013,-32.737980,0.118611,0.000000
85.230003,25.407341,-32.693501,0.012805,0.004651,0.118125,113.017494,5.757386,1.181251,-32.693501,0.119244,0.000000
85.610001,25.608421,-32.649017,0.012844,0.004674,0.118732,113.911949,5.802951,1.187322,-32.649017,0.119877,0.000000
85.990005,25.594276,-32.649017,0.012840,0.004694,0.119227,113.849030,5.799746,1.192272,-32.649017,0.120511,0.000000
86.370003,26.022499,-32.737980,0.012896,0.004722,0.119937,115.753860,5.896782,1.199373,-32.737980,0.121144,0.000000
86.750008,26.238106,-32.693501,0.012922,0.004748,0.120597,116.712921,5.945640,1.205974,-32.693501,0.121777,0.000000
87.130005,26.420197,-32.737980,0.012926,0.004776,0.121316,117.522903,5.986902,1.213165,-32.737980,0.122410,0.000000
87.510002,26.510307,-32.693501,0.012952,0.004796,0.121828,117.923737,6.007321,1.218282,-32.693501,0.123042,0.000000
87.890007,26.785866,-32.737980,0.012995,0.004822,0.122470,119.149483,6.069764,1.224701,-32.737980,0.123675,0.000000
88.270004,26.958275,-32.826942,0.013008,0.004845,0.123051,119.916397,6.108832,1.230515,-32.826942,0.124308,0.000000
88.650002,27.373466,-32.737980,0.013034,0.004875,0.123824,121.763260,6.202916,1.238236,-32.737980,0.124942,0.000000
89.030006,27.500450,-32.782459,0.013060,0.004900,0.124456,122.328110,6.231691,1.244564,-32.782459,0.125575,0.000000
89.410004,27.646042,-32.826942,0.013085,0.004922,0.125029,122.975739,6.264683,1.250287,-32.826942,0.126208,0.000000
89.790001,27.695946,-32.782459,0.013098,0.004945,0.125592,123.197723,6.275991,1.255919,-32.782459,0.126841,0.000000
90.170006,28.068687,-32.826942,0.013107,0.004971,0.126252,124.855759,6.360456,1.262520,-32.826942,0.127474,0.000000
90.550003,28.331955,-32.871422,0.013154,0.004990,0.126755,126.026833,6.420113,1.267546,-32.871422,0.128107,0.000000
90.930008,28.747154,-32.826942,0.013167,0.005025,0.127639,127.873726,6.514198,1.276388,-32.826942,0.128741,0.000000
91.310005,28.834290,-32.826942,0.013202,0.005049,0.128237,128.261322,6.533944,1.282368,-32.826942,0.129374,0.000000
91.690002,28.883064,-32.871422,0.013232,0.005070,0.128767,128.478287,6.544996,1.287667,-32.871422,0.130007,0.000000
92.070007,29.197350,-32.915905,0.013254,0.005095,0.129416,129.876297,6.616214,1.294162,-32.915905,0.130639,0.000000
92.450005,29.501205,-32.871422,0.013275,0.005121,0.130076,131.227921,6.685069,1.300762,-32.871422,0.131272,0.000000
92.830002,29.832993,-32.826942,0.013310,0.005150,0.130821,132.703781,6.760252,1.308211,-32.826942,0.131905,0.000000
93.210007,29.925339,-32.871422,0.013331,0.005172,0.131360,133.114548,6.781179,1.313601,-32.871422,0.132539,0.000000
93.590004,30.265312,-32.960384,0.013340,0.005200,0.132070,134.626831,6.858218,1.320701,-32.960384,0.133172,0.000000
93.970001,30.372185,-32.960384,0.013374,0.005222,0.132642,135.102219,6.882435,1.326424,-32.960384,0.133805,0.000000
94.350006,30.621674,-32.915905,0.013387,0.005245,0.133224,136.212006,6.938970,1.332238,-32.915905,0.134438,0.000000
94.730003,31.114693,-32.960384,0.013439,0.005278,0.134073,138.405060,7.050690,1.340731,-32.960384,0.135071,0.000000
95.110008,31.132195,-32.960384,0.013439,0.005299,0.134603,138.482910,7.054656,1.346030,-32.960384,0.135704,0.000000
95.490005,31.213745,-32.960384,0.013461,0.005320,0.135124,138.845673,7.073135,1.351238,-32.960384,0.136346,0.000000
95.870003,31.579041,-33.004868,0.013473,0.005347,0.135817,140.470581,7.155913,1.358172,-33.004868,0.136978,0.000000
96.250008,31.625587,-32.960384,0.013517,0.005365,0.136276,140.677643,7.166461,1.362759,-32.960384,0.137613,0.000000
96.630005,32.230324,-33.004868,0.013542,0.005400,0.137162,143.367645,7.303496,1.371616,-33.004868,0.138246,0.000000
97.010002,32.377037,-33.004868,0.013542,0.005424,0.137776,144.020248,7.336741,1.377762,-33.004868,0.138878,0.000000
97.390007,32.352837,-32.960384,0.013577,0.005442,0.138236,143.912598,7.331257,1.382365,-32.960384,0.139511,0.000000
97.770004,32.834686,-33.049347,0.013603,0.005471,0.138974,146.055984,7.440446,1.389738,-33.049347,0.140144,0.000000
98.150002,32.892403,-33.004868,0.013607,0.005491,0.139467,146.312714,7.453525,1.394673,-33.004868,0.140777,0.000000
98.530006,33.620392,-33.004868,0.013668,0.005529,0.140430,149.550980,7.618490,1.404302,-33.004868,0.141410,0.000000
98.910004,33.526176,-33.004868,0.013698,0.005546,0.140865,149.131882,7.597140,1.408647,-33.004868,0.142044,0.000000
99.290001,33.916428,-33.093826,0.013668,0.005572,0.141540,150.867798,7.685573,1.415399,-33.093826,0.142677,0.000000
99.670006,34.170013,-33.049347,0.013706,0.005599,0.142217,151.995804,7.743036,1.422167,-33.049347,0.143310,0.000000
100.050003,34.110802,-33.049347,0.013741,0.005614,0.142607,151.732422,7.729618,1.426073,-33.049347,0.143943,0.000000
100.430008,34.853683,-33.049347,0.013762,0.005652,0.143570,155.036926,7.897957,1.435701,-33.049347,0.144575,0.000000
100.810005,34.825386,-33.138309,0.013784,0.005672,0.144056,154.911057,7.891545,1.440561,-33.138309,0.145208,0.000000
101.190002,35.338516,-33.093826,0.013801,0.005703,0.144845,157.193573,8.007822,1.448449,-33.093826,0.145843,0.000000
101.570007,35.218239,-33.093826,0.013827,0.005721,0.145322,156.658554,7.980567,1.453218,-33.093826,0.146475,0.000000
101.950005,35.594711,-33.093826,0.013840,0.005745,0.145929,158.333191,8.065877,1.459289,-33.093826,0.147108,0.000000
102.330002,35.808075,-33.138309,0.013862,0.005771,0.146571,159.282272,8.114226,1.465708,-33.138309,0.147741,0.000000
102.710007,36.206886,-33.138309,0.013918,0.005798,0.147264,161.056274,8.204597,1.472642,-33.138309,0.148374,0.000000
103.090004,36.308548,-33.138309,0.013939,0.005818,0.147785,161.508484,8.227634,1.477850,-33.138309,0.149007,0.000000
103.470001,36.638840,-33.138309,0.013961,0.005846,0.148495,162.977692,8.302480,1.484951,-33.138309,0.149641,0.000000
103.850006,36.753159,-33.138309,0.013974,0.005869,0.149067,163.486221,8.328385,1.490673,-33.138309,0.150274,0.000000
104.230003,37.492691,-33.182789,0.013978,0.005901,0.149883,166.775818,8.495965,1.498834,-33.182789,0.150907,0.000000
104.610008,37.489708,-33.182789,0.013999,0.005922,0.150412,166.762543,8.495289,1.504117,-33.182789,0.151540,0.000000
104.990005,37.581688,-33.227272,0.014060,0.005940,0.150881,167.171692,8.516132,1.508811,-33.227272,0.152172,0.000000
105.370003,38.050880,-33.182789,0.014038,0.005972,0.151679,169.258774,8.622453,1.516789,-33.182789,0.152805,0.000000
105.750008,38.246376,-33.138309,0.014060,0.005992,0.152207,170.128372,8.666753,1.522073,-33.138309,0.153440,0.000000
106.130005,38.899139,-33.182789,0.014112,0.006023,0.152996,173.032013,8.814672,1.529961,-33.182789,0.154072,0.000000
106.510002,38.942711,-33.271751,0.014129,0.006048,0.153630,173.225830,8.824545,1.536304,-33.271751,0.154714,0.000000
106.890007,39.107300,-33.271751,0.014155,0.006073,0.154254,173.957962,8.861840,1.542542,-33.271751,0.155347,0.000000
107.270004,39.262207,-33.182789,0.014150,0.006092,0.154731,174.647018,8.896943,1.547310,-33.182789,0.155980,0.000000
107.650002,39.756714,-33.227272,0.014176,0.006120,0.155450,176.846695,9.009000,1.554502,-33.227272,0.156613,0.000000
108.030006,40.041954,-33.271751,0.014185,0.006143,0.156041,178.115509,9.073636,1.560406,-33.271751,0.157246,0.000000
108.410004,40.366661,-33.360714,0.014224,0.006171,0.156752,179.559875,9.147216,1.567522,-33.360714,0.157879,0.000000
108.790009,40.520081,-33.271751,0.014250,0.006194,0.157324,180.242325,9.181982,1.573245,-33.271751,0.158513,0.000000
109.170006,40.966179,-33.227272,0.014262,0.006220,0.157992,182.226669,9.283069,1.579921,-33.227272,0.159146,0.000000
109.550003,41.160187,-33.316231,0.014284,0.006243,0.158573,183.089661,9.327031,1.585735,-33.316231,0.159779,0.000000
109.930008,41.633842,-33.316231,0.014310,0.006272,0.159311,185.196579,9.434363,1.593108,-33.316231,0.160411,0.000000
110.310005,41.870674,-33.227272,0.014353,0.006297,0.159951,186.250061,9.488030,1.599512,-33.227272,0.161044,0.000000
110.690002,42.117928,-33.316231,0.014362,0.006321,0.160551,187.349899,9.544059,1.605507,-33.316231,0.161677,0.000000
111.070007,42.290710,-33.316231,0.014383,0.006342,0.161088,188.118469,9.583212,1.610882,-33.316231,0.162310,0.000000
111.450005,42.649307,-33.271751,0.014426,0.006363,0.161626,189.713593,9.664472,1.616256,-33.271751,0.162944,0.000000
111.830002,42.934914,-33.360714,0.014452,0.006387,0.162224,190.984039,9.729191,1.622236,-33.360714,0.163577,0.000000
112.210007,43.512093,-33.405193,0.014431,0.006418,0.163021,193.551453,9.859982,1.630215,-33.405193,0.164210,0.000000
112.590004,43.792114,-33.360714,0.014487,0.006444,0.163672,194.797058,9.923435,1.636725,-33.360714,0.164843,0.000000
112.970009,43.954094,-33.360714,0.014500,0.006465,0.164219,195.517578,9.960140,1.642190,-33.360714,0.165476,0.000000
113.350006,44.415840,-33.405193,0.014543,0.006492,0.164887,197.571518,10.064773,1.648867,-33.405193,0.166108,0.000000
113.730003,44.675758,-33.405193,0.014560,0.006511,0.165380,198.727692,10.123672,1.653802,-33.405193,0.166743,0.000000
114.110008,45.354591,-33.360714,0.014551,0.006546,0.166266,201.747299,10.277497,1.662659,-33.360714,0.167376,0.000000
114.490005,45.417152,-33.360714,0.014582,0.006566,0.166785,202.025589,10.291675,1.667852,-33.360714,0.168008,0.000000
114.870003,45.869957,-33.449677,0.014616,0.006594,0.167497,204.039764,10.394281,1.674967,-33.449677,0.168641,0.000000
115.250008,46.040497,-33.449677,0.014620,0.006617,0.168069,204.798355,10.432925,1.680690,-33.449677,0.169274,0.000000
115.630005,46.554375,-33.405193,0.014659,0.006641,0.168693,207.084198,10.549373,1.686928,-33.405193,0.169907,0.000000
116.010002,47.195969,-33.449677,0.014685,0.006673,0.169500,209.938156,10.694759,1.694997,-33.449677,0.170541,0.000000
116.390007,47.284599,-33.449677,0.014702,0.006696,0.170090,210.332397,10.714844,1.700902,-33.449677,0.171174,0.000000
116.770004,47.553825,-33.449677,0.014732,0.006717,0.170619,211.529984,10.775850,1.706185,-33.449677,0.171807,0.000000
117.150009,47.936249,-33.494156,0.014758,0.006745,0.171321,213.231079,10.862510,1.713210,-33.494156,0.172440,0.000000
117.530006,48.048706,-33.538635,0.014776,0.006762,0.171746,213.731323,10.887993,1.717464,-33.538635,0.173082,0.000000
117.910004,48.985970,-33.449677,0.014789,0.006796,0.172614,217.900482,11.100379,1.726139,-33.449677,0.173715,0.000000
118.290009,49.014267,-33.449677,0.014823,0.006816,0.173133,218.026352,11.106791,1.731332,-33.449677,0.174347,0.000000
118.670006,49.393341,-33.449677,0.014845,0.006840,0.173724,219.712555,11.192691,1.737236,-33.449677,0.174980,0.000000
119.050003,50.066963,-33.583118,0.014836,0.006869,0.174469,222.708969,11.345336,1.744685,-33.583118,0.175615,0.000000
119.430008,49.992493,-33.494156,0.014862,0.006885,0.174877,222.377716,11.328461,1.748773,-33.494156,0.176247,0.000000
119.810005,51.052635,-33.538635,0.014883,0.006920,0.175771,227.093460,11.568693,1.757705,-33.538635,0.176880,0.000000
120.190002,50.917831,-33.494156,0.014922,0.006938,0.176213,226.493820,11.538146,1.762126,-33.494156,0.177513,0.000000
120.570007,51.748970,-33.538635,0.014961,0.006971,0.177053,230.190918,11.726483,1.770528,-33.538635,0.178146,0.000000
120.950005,52.015213,-33.538635,0.014952,0.006996,0.177687,231.375229,11.786816,1.776872,-33.538635,0.178779,0.000000
121.330009,52.119850,-33.627598,0.015008,0.007012,0.178094,231.840668,11.810527,1.780944,-33.627598,0.179412,0.000000
121.710007,53.067543,-33.538635,0.015004,0.007047,0.178997,236.056213,12.025277,1.789968,-33.538635,0.180046,0.000000
122.090004,53.137177,-33.538635,0.015034,0.007066,0.179474,236.365967,12.041057,1.794737,-33.538635,0.180679,0.000000
122.470009,53.501358,-33.627598,0.015017,0.007091,0.180114,237.985931,12.123581,1.801141,-33.627598,0.181312,0.000000
122.850006,54.015228,-33.672081,0.015077,0.007118,0.180791,240.271729,12.240026,1.807908,-33.672081,0.181944,0.000000
123.230003,54.501549,-33.627598,0.015103,0.007143,0.181433,242.434998,12.350228,1.814327,-33.627598,0.182577,0.000000
123.610008,55.002014,-33.627598,0.015120,0.007167,0.182031,244.661179,12.463634,1.820307,-33.627598,0.183210,0.000000
123.990005,55.545677,-33.627598,0.015164,0.007196,0.182768,247.079514,12.586830,1.827680,-33.627598,0.183844,0.000000
124.370003,55.861824,-33.627598,0.015168,0.007216,0.183280,248.485809,12.658470,1.832798,-33.627598,0.184477,0.000000
124.750008,56.423737,-33.672081,0.015181,0.007241,0.183913,250.985321,12.785801,1.839126,-33.672081,0.185110,0.000000
125.130005,56.470284,-33.672081,0.015198,0.007259,0.184389,251.192368,12.796350,1.843895,-33.672081,0.185743,0.000000
125.510010,57.126404,-33.672081,0.015211,0.007288,0.185127,254.110931,12.945028,1.851268,-33.672081,0.186376,0.000000
125.890007,57.706558,-33.627598,0.015233,0.007317,0.185864,256.691589,13.076492,1.858641,-33.627598,0.187009,0.000000
126.270004,57.968704,-33.672081,0.015254,0.007337,0.186359,257.857666,13.135897,1.863591,-33.672081,0.187643,0.000000
126.650009,58.763351,-33.761044,0.015293,0.007365,0.187062,261.392456,13.315966,1.870616,-33.761044,0.188276,0.000000
127.030006,59.156204,-33.672081,0.015315,0.007390,0.187711,263.139954,13.404988,1.877111,-33.672081,0.188909,0.000000
127.410004,59.760567,-33.672081,0.015332,0.007416,0.188379,265.828278,13.541939,1.883788,-33.672081,0.189541,0.000000
127.790009,60.354500,-33.672081,0.015375,0.007442,0.189030,268.470215,13.676525,1.890298,-33.672081,0.190174,0.000000
128.170013,60.780495,-33.761044,0.015401,0.007466,0.189628,270.365143,13.773057,1.896278,-33.761044,0.190807,0.000000
128.550003,60.974869,-33.761044,0.015392,0.007486,0.190132,271.229767,13.817102,1.901319,-33.761044,0.191449,0.000000
128.930008,61.842125,-33.716560,0.015418,0.007514,0.190868,275.087524,14.013625,1.908677,-33.716560,0.192082,0.000000
129.310013,62.295677,-33.716560,0.015457,0.007537,0.191449,277.105011,14.116403,1.914491,-33.716560,0.192716,0.000000
129.690002,63.196823,-33.716560,0.015487,0.007567,0.192205,281.113495,14.320604,1.922045,-33.716560,0.193349,0.000000
130.070007,63.456726,-33.805523,0.015487,0.007588,0.192742,282.269623,14.379499,1.927420,-33.805523,0.193982,0.000000
130.450012,64.376114,-33.850002,0.015504,0.007617,0.193461,286.359253,14.587836,1.934611,-33.850002,0.194615,0.000000
130.830002,64.791321,-33.761044,0.015534,0.007640,0.194059,288.206177,14.681923,1.940591,-33.761044,0.195248,0.000000
131.210007,65.584091,-33.716560,0.015560,0.007666,0.194727,291.732605,14.861567,1.947268,-33.716560,0.195880,0.000000
131.590012,66.181015,-33.805523,0.015586,0.007691,0.195361,294.387848,14.996832,1.953611,-33.805523,0.196513,0.000000
131.970001,66.727280,-33.850002,0.015599,0.007715,0.195968,296.817749,15.120618,1.959682,-33.850002,0.197148,0.000000
132.350006,67.273926,-33.850002,0.015612,0.007736,0.196506,299.249359,15.244490,1.965057,-33.850002,0.197780,0.000000
132.730011,67.354721,-33.850002,0.015629,0.007741,0.196627,299.608765,15.262798,1.966268,-33.850002,0.196878,0.000000
133.110001,66.619293,-33.805523,0.015642,0.007733,0.196410,296.337402,15.096148,1.964103,-33.805523,0.196627,0.000000
133.490005,66.213028,-33.894485,0.015659,0.007733,0.196410,294.530273,15.004086,1.964103,-33.894485,0.196627,0.000000
133.870010,65.904343,-33.894485,0.015646,0.007732,0.196401,293.157166,14.934137,1.964012,-33.894485,0.196627,0.000000
134.250000,65.659317,-33.894485,0.015664,0.007732,0.196401,292.067230,14.878613,1.964012,-33.894485,0.196627,0.000000
134.630005,65.453766,-33.894485,0.015672,0.007732,0.196401,291.152893,14.832035,1.964012,-33.894485,0.196627,0.000000
135.010010,65.275024,-33.850002,0.015664,0.007732,0.196401,290.357819,14.791532,1.964012,-33.850002,0.196627,0.000000
135.389999,65.126450,-33.938965,0.015651,0.007732,0.196401,289.696930,14.757865,1.964012,-33.938965,0.196627,0.000000
135.770004,64.974152,-33.938965,0.015646,0.007732,0.196401,289.019470,14.723353,1.964012,-33.938965,0.196627,0.000000
136.150009,64.857971,-33.894485,0.015672,0.007732,0.196401,288.502655,14.697026,1.964012,-33.894485,0.196627,0.000000
136.530014,64.817749,-33.938965,0.015668,0.007732,0.196401,288.323761,14.687912,1.964012,-33.938965,0.196627,0.000000
136.910004,64.726898,-33.938965,0.015672,0.007732,0.196401,287.919617,14.667325,1.964012,-33.938965,0.196627,0.000000
137.290009,64.624863,-33.938965,0.015672,0.007732,0.196401,287.465759,14.644203,1.964012,-33.938965,0.196627,0.000000
137.670013,64.543686,-33.938965,0.015677,0.007732,0.196401,287.104645,14.625809,1.964012,-33.938965,0.196627,0.000000
138.050003,64.453949,-33.938965,0.015685,0.007732,0.196401,286.705475,14.605474,1.964012,-33.938965,0.196627,0.000000
138.430008,64.382446,-33.894485,0.015681,0.007732,0.196401,286.387421,14.589271,1.964012,-33.894485,0.196627,0.000000
138.810013,64.299789,-33.938965,0.015685,0.007732,0.196401,286.019745,14.570540,1.964012,-33.938965,0.196627,0.000000
139.190002,64.222336,-33.983448,0.015672,0.007732,0.196401,285.675232,14.552989,1.964012,-33.983448,0.196627,0.000000
139.570007,64.166107,-34.027927,0.015668,0.007732,0.196401,285.425110,14.540248,1.964012,-34.027927,0.196627,0.000000
139.950012,64.089767,-33.983448,0.015655,0.007732,0.196401,285.085510,14.522949,1.964012,-33.983448,0.196627,0.000000
140.330002,64.048431,-33.983448,0.015664,0.007732,0.196401,284.901642,14.513582,1.964012,-33.983448,0.196627,0.000000
140.710007,63.978424,-34.027927,0.015685,0.007732,0.196401,284.590240,14.497718,1.964012,-34.027927,0.196627,0.000000
141.090012,63.927414,-34.027927,0.015646,0.007732,0.196401,284.363342,14.486158,1.964012,-34.027927,0.196627,0.000000
141.470001,63.871933,-34.072407,0.015655,0.007732,0.196401,284.116547,14.473587,1.964012,-34.072407,0.196627,0.000000
141.850006,63.818314,-34.027927,0.015677,0.007732,0.196401,283.878052,14.461436,1.964012,-34.027927,0.196627,0.000000
142.230011,63.759842,-33.983448,0.015664,0.007732,0.196401,283.617950,14.448187,1.964012,-33.983448,0.196627,0.000000
142.610001,63.728561,-34.072407,0.015685,0.007732,0.196401,283.478790,14.441098,1.964012,-34.072407,0.196627,0.000000
142.990005,63.673447,-34.116890,0.015681,0.007732,0.196401,283.233643,14.428609,1.964012,-34.116890,0.196627,0.000000
143.370010,63.629517,-34.116890,0.015668,0.007732,0.196401,283.038239,14.418654,1.964012,-34.116890,0.196627,0.000000
143.750000,63.582596,-34.027927,0.015672,0.007732,0.196401,282.829498,14.408023,1.964012,-34.027927,0.196627,0.000000
144.130005,63.554291,-34.116890,0.015685,0.007732,0.196401,282.703613,14.401608,1.964012,-34.116890,0.196627,0.000000
144.510010,63.524872,-34.116890,0.015655,0.007732,0.196401,282.572754,14.394941,1.964012,-34.116890,0.196627,0.000000
144.889999,63.466415,-34.116890,0.015672,0.007732,0.196401,282.312714,14.381695,1.964012,-34.116890,0.196627,0.000000
145.270004,63.464920,-34.072407,0.015668,0.007732,0.196401,282.306061,14.381356,1.964012,-34.072407,0.196627,0.000000
145.650009,63.407578,-34.072407,0.015677,0.007732,0.196401,282.050995,14.368362,1.964012,-34.072407,0.196627,0.000000
146.030014,63.384872,-34.072407,0.015664,0.007732,0.196401,281.949982,14.363217,1.964012,-34.072407,0.196627,0.000000
146.410004,63.328644,-34.161369,0.015672,0.007732,0.196401,281.699890,14.350476,1.964012,-34.161369,0.196627,0.000000
146.790009,63.302948,-34.161369,0.015672,0.007732,0.196401,281.585571,14.344653,1.964012,-34.161369,0.196627,0.000000
147.170013,63.262360,-34.161369,0.015659,0.007732,0.196401,281.405029,14.335456,1.964012,-34.161369,0.196627,0.000000
147.550003,63.248947,-34.116890,0.015685,0.007732,0.196401,281.345367,14.332417,1.964012,-34.116890,0.196627,0.000000
147.930008,63.221390,-34.161369,0.015685,0.007732,0.196401,281.222778,14.326172,1.964012,-34.161369,0.196627,0.000000
148.310013,63.194580,-34.205853,0.015664,0.007732,0.196401,281.103546,14.320096,1.964012,-34.205853,0.196627,0.000000
148.690002,63.152130,-34.205853,0.015681,0.007732,0.196401,280.914703,14.310477,1.964012,-34.205853,0.196627,0.000000
149.070007,63.131287,-34.205853,0.015698,0.007732,0.196401,280.821991,14.305754,1.964012,-34.205853,0.196627,0.000000
149.450012,63.109680,-34.205853,0.015685,0.007732,0.196401,280.725891,14.300858,1.964012,-34.205853,0.196627,0.000000
149.830002,63.079147,-34.250332,0.015677,0.007732,0.196401,280.590057,14.293939,1.964012,-34.250332,0.196627,0.000000
150.210007,63.044144,-34.294815,0.015685,0.007732,0.196401,280.434357,14.286007,1.964012,-34.294815,0.196627,0.000000
150.590012,63.021057,-34.250332,0.015672,0.007732,0.196401,280.331665,14.280776,1.964012,-34.250332,0.196627,0.000000
150.970001,62.996475,-34.205853,0.015685,0.007732,0.196401,280.222321,14.275206,1.964012,-34.205853,0.196627,0.000000
151.350006,62.978973,-34.250332,0.015698,0.007732,0.196401,280.144470,14.271239,1.964012,-34.250332,0.196627,0.000000
151.730011,62.952545,-34.294815,0.015681,0.007732,0.196401,280.026917,14.265251,1.964012,-34.294815,0.196627,0.000000
152.110001,62.858337,-34.383774,0.015677,0.007732,0.196401,279.607849,14.243903,1.964012,-34.383774,0.196627,0.000000
152.490005,62.910828,-34.339294,0.015664,0.007732,0.196401,279.841339,14.255797,1.964012,-34.339294,0.196627,0.000000
152.870010,62.882156,-34.294815,0.015685,0.007732,0.196401,279.713806,14.249300,1.964012,-34.294815,0.196627,0.000000
153.250000,62.870239,-34.294815,0.015694,0.007732,0.196401,279.660797,14.246599,1.964012,-34.294815,0.196627,0.000000
153.630005,62.842690,-34.339294,0.015694,0.007732,0.196401,279.538239,14.240357,1.964012,-34.339294,0.196627,0.000000
154.010010,62.825935,-34.383774,0.015681,0.007732,0.196401,279.463715,14.236561,1.964012,-34.383774,0.196627,0.000000
154.390015,62.812157,-34.339294,0.015664,0.007732,0.196401,279.402435,14.233438,1.964012,-34.339294,0.196627,0.000000
154.770004,62.787209,-34.339294,0.015677,0.007732,0.196401,279.291443,14.227785,1.964012,-34.339294,0.196627,0.000000
155.150009,62.771568,-34.339294,0.015677,0.007732,0.196401,279.221893,14.224241,1.964012,-34.339294,0.196627,0.000000
155.530014,62.740662,-34.383774,0.015685,0.007732,0.196401,279.084412,14.217237,1.964012,-34.383774,0.196627,0.000000
155.910004,62.720551,-34.428257,0.015659,0.007732,0.196401,278.994934,14.212680,1.964012,-34.428257,0.196627,0.000000
156.290009,62.704544,-34.383774,0.015681,0.007732,0.196401,278.923737,14.209053,1.964012,-34.383774,0.196627,0.000000
156.670013,62.686668,-34.339294,0.015694,0.007732,0.196401,278.844238,14.205002,1.964012,-34.339294,0.196627,0.000000
157.050003,62.669540,-34.383774,0.015681,0.007732,0.196401,278.768036,14.201121,1.964012,-34.383774,0.196627,0.000000
157.430008,62.645332,-34.428257,0.015672,0.007732,0.196401,278.660370,14.195635,1.964012,-34.428257,0.196627,0.000000
157.810013,62.627457,-34.428257,0.015685,0.007732,0.196401,278.580841,14.191585,1.964012,-34.428257,0.196627,0.000000
158.190002,62.622246,-34.383774,0.015690,0.007732,0.196401,278.557648,14.190404,1.964012,-34.383774,0.196627,0.000000
158.570007,62.596924,-34.428257,0.015694,0.007732,0.196401,278.445038,14.184666,1.964012,-34.428257,0.196627,0.000000
158.950012,62.582405,-34.472736,0.015685,0.007732,0.196401,278.380432,14.181376,1.964012,-34.472736,0.196627,0.000000
159.330002,62.561920,-34.472736,0.015681,0.007732,0.196401,278.289307,14.176734,1.964012,-34.472736,0.196627,0.000000
159.710007,62.543678,-34.472736,0.015690,0.007732,0.196401,278.208191,14.172600,1.964012,-34.472736,0.196627,0.000000
160.090012,62.523941,-34.472736,0.015690,0.007732,0.196401,278.120392,14.168127,1.964012,-34.472736,0.196627,0.000000
160.470001,62.501595,-34.517220,0.015681,0.007732,0.196401,278.020966,14.163063,1.964012,-34.517220,0.196627,0.000000
160.850006,62.493408,-34.561699,0.015690,0.007732,0.196401,277.984558,14.161209,1.964012,-34.561699,0.196627,0.000000
161.230011,62.475906,-34.561699,0.015677,0.007732,0.196401,277.906708,14.157242,1.964012,-34.561699,0.196627,0.000000
161.610001,62.463242,-34.517220,0.015677,0.007732,0.196401,277.850372,14.154372,1.964012,-34.517220,0.196627,0.000000
161.990005,62.447227,-34.472736,0.015690,0.007732,0.196401,277.779144,14.150744,1.964012,-34.472736,0.196627,0.000000
162.370010,62.445366,-34.472736,0.015659,0.007732,0.196401,277.770874,14.150322,1.964012,-34.472736,0.196627,0.000000
162.750015,62.420418,-34.517220,0.015698,0.007732,0.196401,277.659882,14.144669,1.964012,-34.517220,0.196627,0.000000
163.000015,62.409996,-34.606178,0.015672,0.007732,0.196401,277.613525,14.142307,1.964012,-34.606178,0.196627,0.000000