File: Data/New pin align test AD_08172023_162204.csv
Time (sec),S:Load (lbs),S:HL1 (DIM),S:LVDT (in),S:Position (in),Ch:Position (mm),Ch:Load (N),Ch:Stress (MPa),Ch:Strain (mm/mm),Ch:HL1 (DIM),Set Point (),Cycles ()
0.010000,0.001117,-172.897461,0.000013,-0.000000,-0.000000,0.004969,0.000253,-0.000000,-172.897461,0.000044,0.000000
0.180000,-0.005213,-172.897461,0.000013,-0.000000,-0.000000,-0.023190,-0.001181,-0.000000,-172.897461,0.000044,0.000000
0.350000,0.007820,-172.897461,0.000013,-0.000000,-0.000000,0.034784,0.001772,-0.000000,-172.897461,0.000200,0.000000
0.520000,-0.012288,-172.897461,0.000022,0.000097,0.002463,-0.054661,-0.002785,0.024632,-172.897461,0.003028,0.000000
0.690000,-0.025321,-172.941940,0.000022,0.000198,0.005022,-0.112635,-0.005738,0.050218,-172.941940,0.005854,0.000000
0.860000,-0.045429,-172.986420,0.000013,0.000299,0.007606,-0.202080,-0.010294,0.076061,-172.986420,0.008699,0.000000
1.030000,-0.016384,-172.941940,0.000017,0.000413,0.010502,-0.072881,-0.003713,0.105023,-172.941940,0.011526,0.000000
1.200000,-0.018246,-172.852982,0.000009,0.000527,0.013382,-0.081164,-0.004135,0.133819,-172.852982,0.014354,0.000000
1.370000,-0.016757,-172.941940,0.000004,0.000635,0.016140,-0.074538,-0.003797,0.161403,-172.941940,0.017197,0.000000
1.540000,0.031652,-173.030899,0.000017,0.000742,0.018837,0.140793,0.007172,0.188367,-173.030899,0.020025,0.000000
1.710000,0.002979,-172.941940,0.000004,0.000853,0.021656,0.013251,0.000675,0.216557,-172.941940,0.022852,0.000000
1.880000,-0.004841,-172.986420,0.000013,0.000966,0.024535,-0.021533,-0.001097,0.245352,-172.986420,0.025680,0.000000
2.050000,-0.019736,-172.897461,0.000017,0.001080,0.027439,-0.087789,-0.004472,0.274390,-172.897461,0.028523,0.000000
2.220000,-0.001117,-172.941940,0.000009,0.001196,0.030372,-0.004969,-0.000253,0.303715,-172.941940,0.031351,0.000000
2.390000,0.002607,-172.986420,0.000026,0.001308,0.033224,0.011595,0.000591,0.332238,-172.986420,0.034178,0.000000
2.560000,0.017129,-172.986420,0.000013,0.001416,0.035964,0.076194,0.003882,0.359641,-172.986420,0.037022,0.000000
2.730000,0.024949,-172.986420,0.000004,0.001525,0.038723,0.110978,0.005654,0.387225,-172.986420,0.039850,0.000000
2.900000,0.018991,-172.941940,0.000026,0.001635,0.041523,0.084476,0.004303,0.415233,-172.941940,0.042677,0.000000
3.070000,-0.002979,-172.986420,0.000030,0.001751,0.044463,-0.013251,-0.000675,0.444634,-172.986420,0.045504,0.000000
3.240000,0.007075,-172.986420,0.000009,0.001857,0.047160,0.031471,0.001603,0.471598,-172.986420,0.048348,0.000000
3.410000,-0.056228,-173.030899,0.000034,0.001969,0.050014,-0.250116,-0.012742,0.500136,-173.030899,0.051176,0.000000
3.580000,-0.040216,-172.986420,0.000009,0.002081,0.052858,-0.178891,-0.009113,0.528583,-172.986420,0.054003,0.000000
3.750000,0.017874,-173.030899,0.000022,0.002195,0.055745,0.079507,0.004050,0.557454,-173.030899,0.056848,0.000000
3.920000,0.020481,-173.030899,0.000030,0.002309,0.058660,0.091102,0.004641,0.586598,-173.030899,0.059674,0.000000
4.090000,0.026066,-173.030899,-0.000004,0.002410,0.061209,0.115948,0.005907,0.612093,-173.030899,0.062502,0.000000
4.260000,0.021970,-173.030899,0.000009,0.002522,0.064054,0.097727,0.004978,0.640540,-173.030899,0.065329,0.000000
4.430000,-0.003724,-173.030899,0.000017,0.002643,0.067124,-0.016564,-0.000844,0.671244,-173.030899,0.068174,0.000000
4.600000,0.012661,-172.986420,0.000026,0.002757,0.070021,0.056317,0.002869,0.700206,-172.986420,0.071000,0.000000
4.770000,-0.006330,-173.030899,0.000004,0.002865,0.072777,-0.028159,-0.001434,0.727775,-173.030899,0.073828,0.000000
4.940000,-0.016757,-173.119858,0.000000,0.002977,0.075606,-0.074538,-0.003797,0.756055,-173.119858,0.076671,0.000000
5.110000,-0.001117,-173.030899,-0.000009,0.003089,0.078458,-0.004969,-0.000253,0.784578,-173.030899,0.079499,0.000000
5.280000,-0.011171,-173.075378,0.000017,0.003200,0.081268,-0.049692,-0.002531,0.812678,-173.075378,0.082326,0.000000
5.450000,-0.006330,-173.075378,0.000030,0.003309,0.084052,-0.028159,-0.001434,0.840519,-173.075378,0.085154,0.000000
5.620000,0.015640,-173.119858,0.000009,0.003420,0.086871,0.069569,0.003544,0.868709,-173.119858,0.087997,0.000000
5.790000,0.025694,-173.030899,0.000017,0.003532,0.089707,0.114291,0.005822,0.897066,-173.030899,0.090825,0.000000
5.960001,0.007820,-173.075378,0.000022,0.003641,0.092482,0.034784,0.001772,0.924816,-173.075378,0.093652,0.000000
6.130000,-0.001862,-173.075378,-0.000017,0.003753,0.095317,-0.008282,-0.000422,0.953173,-173.075378,0.096497,0.000000
6.300000,-0.020853,-173.119858,-0.000004,0.003870,0.098292,-0.092758,-0.004725,0.982922,-173.119858,0.099325,0.000000
6.470000,0.003724,-173.075378,0.000043,0.003984,0.101188,0.016564,0.000844,1.011884,-173.075378,0.102151,0.000000
6.640000,0.016012,-173.119858,-0.000004,0.004095,0.104015,0.071225,0.003628,1.040150,-173.119858,0.104996,0.000000
6.810000,0.029790,-173.119858,0.000013,0.004201,0.106695,0.132512,0.006750,1.066947,-173.119858,0.107823,0.000000
6.980000,0.017501,-173.164337,0.000017,0.004310,0.109479,0.077850,0.003966,1.094788,-173.164337,0.110651,0.000000
7.150001,0.013405,-173.075378,-0.000013,0.004422,0.112307,0.059630,0.003038,1.123069,-173.075378,0.113477,0.000000
7.320000,-0.002607,-173.075378,-0.000004,0.004532,0.115117,-0.011595,-0.000591,1.151168,-173.075378,0.116322,0.000000
7.490000,-0.035748,-173.208817,0.000009,0.004645,0.117987,-0.159014,-0.008101,1.179873,-173.208817,0.119148,0.000000
7.660000,-0.047291,-173.075378,0.000030,0.004756,0.120814,-0.210362,-0.010716,1.208138,-173.075378,0.121977,0.000000
7.830000,-0.021225,-173.119858,0.000017,0.004869,0.123684,-0.094414,-0.004810,1.236843,-173.119858,0.124820,0.000000
8.000000,0.026811,-173.119858,0.000039,0.004980,0.126503,0.119260,0.006075,1.265033,-173.119858,0.127648,0.000000
8.170000,0.026066,-173.119858,0.000017,0.005091,0.129321,0.115948,0.005907,1.293208,-173.119858,0.130474,0.000000
8.340000,0.033514,-173.208817,0.000017,0.005200,0.132088,0.149076,0.007594,1.320883,-173.208817,0.133302,0.000000
8.510000,-0.002234,-173.208817,0.000030,0.005314,0.134984,-0.009938,-0.000506,1.349845,-173.208817,0.136146,0.000000
8.680000,0.000372,-173.164337,0.000043,0.005429,0.137906,0.001657,0.000084,1.379064,-173.164337,0.138974,0.000000
8.850000,0.002607,-173.119858,0.000026,0.005544,0.140812,0.011595,0.000591,1.408117,-173.119858,0.141800,0.000000
9.020000,-0.000372,-173.164337,0.000013,0.005649,0.143491,-0.001657,-0.000084,1.434914,-173.164337,0.144645,0.000000
9.190001,-0.010054,-173.208817,-0.000004,0.005765,0.146422,-0.044723,-0.002278,1.464224,-173.208817,0.147473,0.000000
9.360001,-0.002607,-173.164337,0.000047,0.005877,0.149276,-0.011595,-0.000591,1.492763,-173.164337,0.150300,0.000000
9.530001,-0.014150,-173.119858,0.000004,0.005988,0.152095,-0.062943,-0.003206,1.520952,-173.119858,0.153126,0.000000
9.700001,0.024204,-173.208817,-0.000009,0.006097,0.154861,0.107666,0.005485,1.548612,-173.208817,0.155971,0.000000
9.870001,-0.005958,-173.208817,0.000000,0.006207,0.157653,-0.026502,-0.001350,1.576530,-173.208817,0.158799,0.000000
10.040001,0.029045,-173.208817,0.000017,0.006319,0.160507,0.129199,0.006582,1.605068,-173.208817,0.161626,0.000000
10.210000,0.002979,-173.208817,0.000026,0.006429,0.163299,0.013251,0.000675,1.632985,-173.208817,0.164470,0.000000
10.380000,-0.003724,-173.164337,-0.000004,0.006543,0.166196,-0.016564,-0.000844,1.661963,-173.164337,0.167297,0.000000
10.550000,-0.013778,-173.164337,-0.000009,0.006656,0.169067,-0.061286,-0.003122,1.690667,-173.164337,0.170125,0.000000
10.720000,0.018246,-173.208817,0.000030,0.006770,0.171954,0.081164,0.004135,1.719538,-173.208817,0.172952,0.000000
10.890000,0.019363,-173.253311,0.000009,0.006878,0.174694,0.086133,0.004388,1.746941,-173.253311,0.175796,0.000000
11.060000,0.032024,-173.208817,0.000022,0.006985,0.177409,0.142450,0.007257,1.774086,-173.208817,0.178623,0.000000
11.230000,0.010799,-173.164337,-0.000013,0.007099,0.180305,0.048036,0.002447,1.803048,-173.164337,0.181451,0.000000
11.400001,0.009682,-173.208817,0.000013,0.007213,0.183210,0.043066,0.002194,1.832101,-173.208817,0.184294,0.000000
11.570001,-0.017129,-173.208817,0.000030,0.007319,0.185899,-0.076194,-0.003882,1.858989,-173.208817,0.187122,0.000000
11.740001,-0.048036,-173.297791,0.000034,0.007434,0.188822,-0.213675,-0.010885,1.888224,-173.297791,0.189949,0.000000
11.910001,-0.062559,-173.297791,-0.000009,0.007546,0.191666,-0.278274,-0.014176,1.916656,-173.297791,0.192777,0.000000
12.080001,-0.010054,-173.253311,0.000034,0.007658,0.194519,-0.044723,-0.002278,1.945194,-173.253311,0.195620,0.000000
12.250001,0.010799,-173.253311,-0.000004,0.007769,0.197329,0.048036,0.002447,1.973293,-173.253311,0.198448,0.000000
12.420001,0.029790,-173.253311,0.000039,0.007879,0.200130,0.132512,0.006750,2.001301,-173.253311,0.201275,0.000000
12.590000,0.032396,-173.297791,0.000030,0.007990,0.202958,0.144107,0.007341,2.029582,-173.297791,0.204119,0.000000
12.760000,0.008192,-173.208817,0.000004,0.008103,0.205829,0.036441,0.001856,2.058286,-173.208817,0.206947,0.000000
12.930000,0.002979,-173.253311,0.000013,0.008217,0.208699,0.013251,0.000675,2.086991,-173.253311,0.209774,0.000000
13.100000,0.023087,-173.297791,-0.000017,0.008328,0.211526,0.102697,0.005232,2.115257,-173.297791,0.212601,0.000000
13.270000,-0.011916,-173.297791,0.000004,0.008440,0.214387,-0.053005,-0.002700,2.143871,-173.297791,0.215445,0.000000
13.440001,0.014895,-173.297791,0.000022,0.008555,0.217301,0.066256,0.003375,2.173014,-173.297791,0.218273,0.000000
13.610001,0.011916,-173.297791,-0.000013,0.008663,0.220033,0.053005,0.002700,2.200326,-173.297791,0.221100,0.000000
13.780001,-0.008937,-173.253311,-0.000009,0.008772,0.222817,-0.039754,-0.002025,2.228168,-173.253311,0.223945,0.000000
13.950001,0.013405,-173.253311,0.000013,0.008885,0.225678,0.059630,0.003038,2.256782,-173.253311,0.226771,0.000000
14.120001,0.005586,-173.253311,0.000013,0.008997,0.228523,0.024846,0.001266,2.285229,-173.253311,0.229599,0.000000
14.290001,0.014895,-173.386749,-0.000004,0.009107,0.231324,0.066256,0.003375,2.313237,-173.386749,0.232443,0.000000
14.460001,-0.011916,-173.297791,0.000022,0.009220,0.234187,-0.053005,-0.002700,2.341866,-173.297791,0.235271,0.000000
14.630001,-0.000745,-173.253311,0.000009,0.009332,0.237031,-0.003313,-0.000169,2.370313,-173.253311,0.238097,0.000000
14.800001,0.015267,-173.342270,0.000009,0.009446,0.239937,0.067912,0.003460,2.399366,-173.342270,0.240925,0.000000
14.970000,0.031652,-173.342270,0.000017,0.009557,0.242737,0.140793,0.007172,2.427374,-173.342270,0.243768,0.000000
15.140000,0.013033,-173.431229,-0.000009,0.009663,0.245443,0.057974,0.002953,2.454429,-173.431229,0.246597,0.000000
15.310000,0.037610,-173.386749,0.000017,0.009772,0.248209,0.167296,0.008522,2.482089,-173.386749,0.249423,0.000000
15.480000,0.003351,-173.342270,0.000017,0.009887,0.251132,0.014907,0.000759,2.511323,-173.342270,0.252268,0.000000
15.650001,0.015640,-173.342270,0.000022,0.009998,0.253959,0.069569,0.003544,2.539589,-173.342270,0.255094,0.000000
15.820001,-0.026811,-173.386749,0.000013,0.010110,0.256785,-0.119260,-0.006075,2.567854,-173.386749,0.257922,0.000000
15.990001,-0.037610,-173.342270,0.000030,0.010222,0.259639,-0.167296,-0.008522,2.596393,-173.342270,0.260749,0.000000
16.160000,0.001862,-173.386749,0.000039,0.010334,0.262493,0.008282,0.000422,2.624931,-173.386749,0.263594,0.000000
16.330000,-0.012661,-173.342270,0.000013,0.010448,0.265371,-0.056317,-0.002869,2.653711,-173.342270,0.266422,0.000000
16.500000,0.033514,-173.342270,-0.000009,0.010553,0.268043,0.149076,0.007594,2.680432,-173.342270,0.269248,0.000000
16.670000,0.037982,-173.386749,0.000004,0.010662,0.270818,0.168952,0.008607,2.708183,-173.386749,0.272093,0.000000
16.840000,0.013778,-173.431229,0.000009,0.010779,0.273784,0.061286,0.003122,2.737842,-173.431229,0.274920,0.000000
17.010000,-0.014523,-173.386749,0.000034,0.010892,0.276664,-0.064600,-0.003291,2.766637,-173.386749,0.277748,0.000000
17.180000,-0.009682,-173.386749,0.000026,0.011004,0.279490,-0.043066,-0.002194,2.794903,-173.386749,0.280574,0.000000
17.350000,0.015640,-173.386749,0.000000,0.011115,0.282326,0.069569,0.003544,2.823259,-173.386749,0.283419,0.000000
17.520000,0.001490,-173.386749,-0.000013,0.011228,0.285180,0.006626,0.000338,2.851797,-173.386749,0.286246,0.000000
17.690001,-0.004096,-173.431229,0.000004,0.011343,0.288118,-0.018221,-0.000928,2.881183,-173.431229,0.289074,0.000000
17.860001,0.006330,-173.431229,0.000030,0.011449,0.290798,0.028159,0.001434,2.907980,-173.431229,0.291917,0.000000
18.030001,0.023832,-173.431229,0.000047,0.011561,0.293652,0.106009,0.005400,2.936518,-173.431229,0.294745,0.000000
18.200001,0.040216,-173.431229,0.000034,0.011673,0.296497,0.178891,0.009113,2.964966,-173.431229,0.297571,0.000000
18.370001,0.058463,-173.475708,0.000026,0.011784,0.299306,0.260054,0.013248,2.993065,-173.475708,0.300400,0.000000
18.540001,0.046547,-173.520187,0.000022,0.011893,0.302072,0.207050,0.010548,3.020725,-173.520187,0.303243,0.000000
18.710001,0.118414,-173.475708,0.000043,0.012006,0.304952,0.526734,0.026833,3.049520,-173.475708,0.306071,0.000000
18.880001,0.133682,-173.431229,0.000026,0.012119,0.307813,0.594646,0.030293,3.078134,-173.431229,0.308897,0.000000
19.050001,0.164589,-173.431229,0.000047,0.012235,0.310763,0.732127,0.037296,3.107626,-173.431229,0.311742,0.000000
19.220001,0.153790,-173.386749,0.000017,0.012336,0.313329,0.684092,0.034849,3.133287,-173.386749,0.314569,0.000000
19.390001,0.140384,-173.475708,0.000009,0.012448,0.316183,0.624461,0.031812,3.161826,-173.475708,0.317397,0.000000
19.560001,0.146342,-173.475708,0.000017,0.012563,0.319097,0.650963,0.033162,3.190969,-173.475708,0.320223,0.000000
19.730001,0.124745,-173.475708,0.000034,0.012678,0.322019,0.554892,0.028268,3.220189,-173.475708,0.323068,0.000000
19.900002,0.125117,-173.431229,0.000026,0.012785,0.324733,0.556549,0.028352,3.247334,-173.431229,0.325896,0.000000
20.070002,0.087880,-173.431229,0.000022,0.012896,0.327569,0.390909,0.019914,3.275690,-173.431229,0.328723,0.000000
20.240002,0.084156,-173.475708,0.000043,0.013010,0.330465,0.374345,0.019070,3.304652,-173.475708,0.331567,0.000000
20.410002,0.110595,-173.520187,0.000065,0.013124,0.333345,0.491949,0.025061,3.333448,-173.520187,0.334394,0.000000
20.580002,0.112084,-173.475708,0.000022,0.013236,0.336199,0.498575,0.025399,3.361986,-173.475708,0.337222,0.000000
20.750002,0.156769,-173.475708,0.000026,0.013340,0.338843,0.697342,0.035524,3.388435,-173.475708,0.340049,0.000000
20.920000,0.140012,-173.520187,-0.000004,0.013452,0.341688,0.622805,0.031727,3.416882,-173.520187,0.342893,0.000000
21.090000,0.132565,-173.564667,0.000017,0.013570,0.344680,0.589677,0.030040,3.446798,-173.564667,0.345720,0.000000
21.260000,0.125862,-173.520187,0.000047,0.013679,0.347455,0.559862,0.028521,3.474549,-173.520187,0.348548,0.000000
21.430000,0.123628,-173.520187,0.000017,0.013792,0.350307,0.549923,0.028014,3.503072,-173.520187,0.351391,0.000000
21.600000,0.139267,-173.475708,0.000030,0.013904,0.353161,0.619492,0.031558,3.531610,-173.475708,0.354219,0.000000
21.770000,0.137405,-173.564667,0.000047,0.014019,0.356075,0.611210,0.031137,3.560754,-173.564667,0.357046,0.000000
21.940001,0.117297,-173.520187,0.000026,0.014131,0.358928,0.521764,0.026580,3.589277,-173.520187,0.359891,0.000000
22.110001,0.141502,-173.564667,0.000030,0.014231,0.361460,0.629430,0.032065,3.614605,-173.564667,0.362717,0.000000
22.280001,0.134426,-173.564667,0.000060,0.014349,0.364452,0.597959,0.030461,3.644521,-173.564667,0.365545,0.000000
22.450001,0.129213,-173.475708,0.000047,0.014459,0.367262,0.574769,0.029280,3.672620,-173.475708,0.368372,0.000000
22.620001,0.104637,-173.520187,0.000052,0.014570,0.370081,0.465447,0.023711,3.700810,-173.520187,0.371216,0.000000
22.790001,0.085646,-173.609146,0.000026,0.014681,0.372908,0.380971,0.019408,3.729075,-173.609146,0.374045,0.000000
22.960001,0.136661,-173.564667,0.000039,0.014793,0.375736,0.607897,0.030968,3.757356,-173.564667,0.376871,0.000000
23.130001,0.134054,-173.564667,0.000013,0.014907,0.378632,0.596302,0.030377,3.786318,-173.564667,0.379716,0.000000
23.300001,0.150811,-173.564667,0.000034,0.015020,0.381502,0.670840,0.034174,3.815023,-173.564667,0.382542,0.000000
23.470001,0.144480,-173.564667,0.000043,0.015119,0.384026,0.642681,0.032740,3.840261,-173.564667,0.385370,0.000000
23.640001,0.131447,-173.653625,0.000017,0.015237,0.387018,0.584707,0.029786,3.870176,-173.653625,0.388197,0.000000
23.810001,0.127351,-173.564667,0.000039,0.015355,0.390009,0.566487,0.028858,3.900092,-173.564667,0.391042,0.000000
23.980001,0.113201,-173.609146,0.000043,0.015468,0.392898,0.503544,0.025652,3.928978,-173.609146,0.393868,0.000000
24.150002,0.104637,-173.609146,0.000043,0.015573,0.395550,0.465447,0.023711,3.955503,-173.609146,0.396696,0.000000
24.320002,0.076336,-173.609146,0.000034,0.015687,0.398439,0.339561,0.017298,3.984389,-173.609146,0.399540,0.000000
24.490002,0.097562,-173.698120,0.000026,0.015799,0.401300,0.433976,0.022108,4.013003,-173.698120,0.402368,0.000000
24.660002,0.100913,-173.609146,0.000022,0.015911,0.404136,0.448883,0.022867,4.041359,-173.609146,0.405194,0.000000
24.830002,0.103520,-173.653625,0.000009,0.016022,0.406955,0.460478,0.023458,4.069550,-173.653625,0.408022,0.000000
25.000002,0.150438,-173.609146,0.000017,0.016128,0.409660,0.669184,0.034090,4.096604,-173.609146,0.410865,0.000000
25.170002,0.139267,-173.653625,0.000026,0.016241,0.412531,0.619492,0.031558,4.125309,-173.653625,0.413694,0.000000
25.340002,0.118042,-173.698120,0.000034,0.016355,0.415427,0.525078,0.026749,4.154271,-173.698120,0.416520,0.000000
25.510002,0.093838,-173.609146,0.000013,0.016468,0.418281,0.417412,0.021264,4.182808,-173.609146,0.419365,0.000000
25.680000,0.118042,-173.653625,0.000026,0.016582,0.421177,0.525078,0.026749,4.211771,-173.653625,0.422191,0.000000
25.850000,0.141874,-173.653625,0.000052,0.016694,0.424040,0.631087,0.032149,4.240399,-173.653625,0.425019,0.000000
26.020000,0.147460,-173.609146,0.000039,0.016805,0.426857,0.655933,0.033415,4.268574,-173.609146,0.427846,0.000000
26.190001,0.134426,-173.653625,0.000034,0.016913,0.429598,0.597959,0.030461,4.295977,-173.653625,0.430691,0.000000
26.360001,0.141874,-173.653625,0.000052,0.017018,0.432252,0.631087,0.032149,4.322516,-173.653625,0.433519,0.000000
26.530001,0.131447,-173.653625,-0.000017,0.017137,0.435270,0.584707,0.029786,4.352705,-173.653625,0.436345,0.000000
26.700001,0.124372,-173.609146,0.000030,0.017241,0.437932,0.553236,0.028183,4.379320,-173.609146,0.439190,0.000000
26.870001,0.070006,-173.698120,0.000043,0.017357,0.440863,0.311402,0.015864,4.408630,-173.698120,0.442017,0.000000
27.040001,0.088252,-173.742599,0.000017,0.017468,0.443699,0.392566,0.019998,4.436987,-173.742599,0.444845,0.000000
27.210001,0.142991,-173.742599,0.000017,0.017581,0.446552,0.636056,0.032402,4.465525,-173.742599,0.447671,0.000000
27.380001,0.146342,-173.653625,0.000056,0.017696,0.449467,0.650963,0.033162,4.494669,-173.653625,0.450516,0.000000
27.550001,0.148949,-173.742599,0.000017,0.017801,0.452147,0.662558,0.033752,4.521466,-173.742599,0.453343,0.000000
27.720001,0.150438,-173.698120,0.000000,0.017909,0.454896,0.669184,0.034090,4.548959,-173.698120,0.456171,0.000000
27.890001,0.120276,-173.742599,0.000034,0.018027,0.457888,0.535016,0.027255,4.578875,-173.742599,0.459014,0.000000
28.060001,0.130330,-173.742599,0.000017,0.018143,0.460835,0.579738,0.029533,4.608352,-173.742599,0.461842,0.000000
28.230001,0.116925,-173.698120,0.000022,0.018255,0.463671,0.520108,0.026496,4.636708,-173.698120,0.464669,0.000000
28.400002,0.110595,-173.698120,0.000004,0.018363,0.466420,0.491949,0.025061,4.664202,-173.698120,0.467497,0.000000
28.570002,0.117297,-173.698120,0.000034,0.018475,0.469265,0.521764,0.026580,4.692649,-173.698120,0.470340,0.000000
28.740002,0.107616,-173.742599,0.000004,0.018588,0.472126,0.478698,0.024386,4.721263,-173.742599,0.473168,0.000000
28.910002,0.129586,-173.742599,0.000017,0.018700,0.474971,0.576426,0.029365,4.749710,-173.742599,0.475994,0.000000
29.080002,0.146715,-173.742599,0.000052,0.018808,0.477711,0.652620,0.033246,4.777113,-173.742599,0.478839,0.000000
29.250002,0.140384,-173.653625,0.000026,0.018920,0.480565,0.624461,0.031812,4.805651,-173.653625,0.481666,0.000000
29.420002,0.141874,-173.742599,0.000026,0.019029,0.483340,0.631087,0.032149,4.833402,-173.742599,0.484494,0.000000
29.590002,0.113574,-173.787079,0.000030,0.019140,0.486167,0.505200,0.025736,4.861667,-173.787079,0.487339,0.000000
29.760002,0.100541,-173.787079,0.000026,0.019256,0.489099,0.447227,0.022783,4.890993,-173.787079,0.490165,0.000000
29.930002,0.122138,-173.787079,0.000022,0.019372,0.492038,0.543298,0.027677,4.920379,-173.787079,0.492993,0.000000
30.100002,0.132192,-173.831558,0.000039,0.019484,0.494892,0.588021,0.029955,4.948917,-173.831558,0.495820,0.000000
30.270002,0.136661,-173.831558,0.000034,0.019591,0.497606,0.607897,0.030968,4.976062,-173.831558,0.498664,0.000000
30.440001,0.130703,-173.831558,0.000009,0.019699,0.500356,0.581395,0.029618,5.003555,-173.831558,0.501491,0.000000
30.610001,0.120276,-173.742599,0.000039,0.019808,0.503131,0.535016,0.027255,5.031306,-173.742599,0.504319,0.000000
30.780001,0.122511,-173.831558,0.000013,0.019922,0.506010,0.544954,0.027761,5.060102,-173.831558,0.507162,0.000000
30.950001,0.075219,-173.742599,0.000026,0.020030,0.508767,0.334592,0.017045,5.087671,-173.742599,0.509990,0.000000
31.120001,0.062186,-173.787079,0.000047,0.020143,0.511621,0.276618,0.014092,5.116209,-173.787079,0.512817,0.000000
31.290001,0.076336,-173.787079,0.000026,0.020258,0.514552,0.339561,0.017298,5.145519,-173.787079,0.515645,0.000000
31.460001,0.133682,-173.831558,0.000026,0.020370,0.517404,0.594646,0.030293,5.174042,-173.831558,0.518488,0.000000
31.630001,0.145598,-173.787079,0.000030,0.020484,0.520293,0.647650,0.032993,5.202929,-173.787079,0.521316,0.000000
31.800001,0.151183,-173.787079,0.000030,0.020586,0.522894,0.672497,0.034259,5.228939,-173.787079,0.524143,0.000000
31.970001,0.140384,-173.787079,0.000043,0.020699,0.525764,0.624461,0.031812,5.257643,-173.787079,0.526988,0.000000
32.140003,0.129586,-173.876038,0.000034,0.020818,0.528783,0.576426,0.029365,5.287831,-173.876038,0.529814,0.000000
32.310001,0.144853,-173.876038,0.000047,0.020930,0.531619,0.644338,0.032824,5.316188,-173.876038,0.532642,0.000000
32.480003,0.129586,-173.831558,0.000022,0.021038,0.534368,0.576426,0.029365,5.343681,-173.831558,0.535469,0.000000
32.650002,0.115808,-173.831558,0.000030,0.021154,0.537299,0.515139,0.026242,5.372992,-173.831558,0.538314,0.000000
32.820000,0.138523,-173.876038,0.000013,0.021264,0.540118,0.616179,0.031390,5.401181,-173.876038,0.541140,0.000000
32.990002,0.128469,-173.920517,0.000009,0.021373,0.542884,0.571456,0.029111,5.428842,-173.920517,0.543968,0.000000
33.160000,0.118042,-173.920517,0.000030,0.021485,0.545711,0.525078,0.026749,5.457107,-173.920517,0.546813,0.000000
33.330002,0.141874,-173.831558,0.000026,0.021595,0.548521,0.631087,0.032149,5.485206,-173.831558,0.549639,0.000000
33.500000,0.140012,-173.831558,0.000030,0.021707,0.551349,0.622805,0.031727,5.513487,-173.831558,0.552467,0.000000
33.670002,0.125117,-173.876038,0.000030,0.021818,0.554166,0.556549,0.028352,5.541662,-173.876038,0.555294,0.000000
33.840000,0.127351,-173.876038,0.000047,0.021929,0.557002,0.566487,0.028858,5.570018,-173.876038,0.558139,0.000000
34.010002,0.109105,-173.876038,0.000047,0.022045,0.559942,0.485324,0.024724,5.599419,-173.876038,0.560965,0.000000
34.180000,0.138895,-173.876038,0.000030,0.022161,0.562891,0.617835,0.031474,5.628911,-173.876038,0.563793,0.000000
34.350002,0.148577,-173.876038,0.000009,0.022270,0.565648,0.660902,0.033668,5.656480,-173.876038,0.566637,0.000000
34.520000,0.151556,-173.876038,0.000004,0.022379,0.568416,0.674153,0.034343,5.684155,-173.876038,0.569465,0.000000
34.690002,0.149321,-173.920517,0.000013,0.022487,0.571165,0.664214,0.033837,5.711649,-173.920517,0.572291,0.000000
34.860001,0.143736,-173.876038,0.000017,0.022597,0.573957,0.639369,0.032571,5.739566,-173.876038,0.575119,0.000000
35.030003,0.122138,-173.876038,0.000017,0.022706,0.576732,0.543298,0.027677,5.767317,-173.876038,0.577963,0.000000
35.200001,0.086763,-173.920517,0.000004,0.022819,0.579593,0.385940,0.019661,5.795931,-173.920517,0.580791,0.000000
35.370003,0.064420,-173.920517,0.000000,0.022932,0.582482,0.286557,0.014598,5.824817,-173.920517,0.583617,0.000000
35.540001,0.103520,-173.920517,0.000004,0.023046,0.585369,0.460478,0.023458,5.853688,-173.920517,0.586462,0.000000
35.710003,0.138150,-173.964996,0.000017,0.023154,0.588118,0.614523,0.031305,5.881182,-173.964996,0.589288,0.000000
35.880001,0.148204,-173.964996,0.000039,0.023266,0.590963,0.659245,0.033584,5.909629,-173.964996,0.592117,0.000000
36.050003,0.161982,-173.920517,0.000034,0.023378,0.593799,0.720532,0.036706,5.937985,-173.920517,0.594943,0.000000
36.220001,0.124372,-173.920517,0.000017,0.023491,0.596660,0.553236,0.028183,5.966599,-173.920517,0.597788,0.000000
36.390003,0.126607,-173.920517,0.000013,0.023604,0.599549,0.563174,0.028689,5.995486,-173.920517,0.600616,0.000000
36.560001,0.158258,-174.009476,0.000034,0.023716,0.602375,0.703968,0.035862,6.023751,-174.009476,0.603442,0.000000
36.730003,0.145970,-173.964996,0.000013,0.023826,0.605168,0.649307,0.033077,6.051684,-173.964996,0.606287,0.000000
36.900002,0.184697,-173.920517,0.000013,0.023941,0.608108,0.821572,0.041853,6.081085,-173.920517,0.609114,0.000000
37.070004,0.209273,-173.920517,0.000034,0.024053,0.610935,0.930894,0.047422,6.109350,-173.920517,0.611942,0.000000
37.240002,0.220072,-174.009476,-0.000017,0.024161,0.613684,0.978930,0.049869,6.136844,-174.009476,0.614785,0.000000
37.410004,0.230126,-174.009476,0.000022,0.024271,0.616476,1.023652,0.052147,6.164761,-174.009476,0.617613,0.000000
37.580002,0.208529,-174.009476,0.000022,0.024382,0.619313,0.927581,0.047253,6.193133,-174.009476,0.620440,0.000000
37.750000,0.200336,-174.009476,0.000047,0.024493,0.622114,0.891141,0.045397,6.221141,-174.009476,0.623268,0.000000
37.920002,0.168312,-174.009476,-0.000017,0.024606,0.624992,0.748691,0.038140,6.249921,-174.009476,0.626111,0.000000
38.090000,0.164216,-173.964996,0.000017,0.024718,0.627846,0.730470,0.037212,6.278460,-173.964996,0.628939,0.000000
38.260002,0.148204,-174.053955,0.000022,0.024833,0.630751,0.659245,0.033584,6.307512,-174.053955,0.631766,0.000000
38.430000,0.188048,-174.053955,0.000017,0.024944,0.633587,0.836480,0.042612,6.335869,-174.053955,0.634610,0.000000
38.600002,0.165706,-174.009476,0.000047,0.025047,0.636206,0.737096,0.037549,6.362060,-174.009476,0.637437,0.000000
38.770000,0.191399,-174.009476,0.000022,0.025161,0.639086,0.851387,0.043372,6.390856,-174.009476,0.640265,0.000000
38.940002,0.151928,-174.053955,0.000039,0.025275,0.641973,0.675809,0.034427,6.419727,-174.053955,0.643091,0.000000
39.110001,0.162727,-174.009476,-0.000017,0.025385,0.644783,0.723845,0.036874,6.447826,-174.009476,0.645936,0.000000
39.280003,0.124000,-174.053955,0.000026,0.025496,0.647611,0.551580,0.028099,6.476107,-174.053955,0.648763,0.000000
39.450001,0.113946,-174.009476,0.000009,0.025609,0.650472,0.506857,0.025821,6.504721,-174.009476,0.651591,0.000000
39.620003,0.119532,-174.053955,0.000022,0.025723,0.653359,0.531703,0.027086,6.533592,-174.053955,0.654436,0.000000
39.790001,0.149694,-174.098450,0.000043,0.025837,0.656248,0.665871,0.033921,6.562478,-174.098450,0.657262,0.000000
39.960003,0.181345,-174.098450,0.000017,0.025940,0.658876,0.806664,0.041093,6.588760,-174.098450,0.660090,0.000000
40.130001,0.203315,-174.053955,0.000004,0.026051,0.661686,0.904392,0.046072,6.616859,-174.053955,0.662917,0.000000
40.300003,0.179484,-173.964996,0.000034,0.026166,0.664608,0.798383,0.040672,6.646079,-173.964996,0.665761,0.000000
40.470001,0.175387,-174.053955,0.000034,0.026280,0.667522,0.780162,0.039743,6.675222,-174.053955,0.668588,0.000000
40.640003,0.195123,-174.098450,0.000017,0.026389,0.670279,0.867951,0.044216,6.702792,-174.098450,0.671416,0.000000
40.810001,0.218583,-174.098450,0.000043,0.026500,0.673107,0.972304,0.049532,6.731072,-174.098450,0.674259,0.000000
40.980003,0.221562,-174.053955,0.000030,0.026615,0.676020,0.985555,0.050207,6.760201,-174.053955,0.677087,0.000000
41.150002,0.248372,-174.009476,0.000022,0.026729,0.678916,1.104816,0.056282,6.789163,-174.009476,0.679914,0.000000
41.320004,0.287472,-174.053955,0.000004,0.026837,0.681658,1.278737,0.065142,6.816581,-174.053955,0.682742,0.000000
41.490002,0.315027,-174.098450,0.000013,0.026946,0.684424,1.401311,0.071386,6.844241,-174.098450,0.685585,0.000000
41.660004,0.379075,-174.098450,0.000013,0.027058,0.687269,1.686211,0.085900,6.872688,-174.098450,0.688413,0.000000
41.830002,0.433069,-174.098450,0.000000,0.027170,0.690130,1.926388,0.098135,6.901302,-174.098450,0.691240,0.000000
42.000004,0.472168,-174.053955,0.000030,0.027280,0.692905,2.100309,0.106995,6.929053,-174.053955,0.694085,0.000000
42.170002,0.627075,-174.098450,0.000026,0.027394,0.695801,2.789370,0.142097,6.958014,-174.098450,0.696911,0.000000
42.340000,0.543291,-174.142929,0.000030,0.000014,0.000347,2.416681,0.123112,0.003467,-174.142929,0.000580,0.000000
42.510002,0.514619,-174.187408,0.000017,0.000014,0.000347,2.289139,0.116614,0.003467,-174.187408,0.000580,0.000000
42.680000,0.501958,-174.187408,0.000030,0.000014,0.000347,2.232821,0.113745,0.003467,-174.187408,0.000580,0.000000
42.850002,0.604733,-174.098450,0.000017,0.000014,0.000347,2.689986,0.137034,0.003467,-174.098450,0.000719,0.000000
43.020000,0.599892,-174.142929,0.000013,0.000014,0.000356,2.668453,0.135937,0.003558,-174.142929,0.001005,0.000000
43.190002,0.594679,-174.098450,0.000013,0.000015,0.000372,2.645263,0.134756,0.003724,-174.098450,0.001282,0.000000
43.360001,0.588721,-174.142929,0.000017,0.000022,0.000554,2.618761,0.133406,0.005541,-174.142929,0.001568,0.000000
43.530003,0.650907,-174.142929,0.000009,0.000034,0.000858,2.895379,0.147498,0.008584,-174.142929,0.001855,0.000000
43.700001,0.684793,-174.098450,-0.000022,0.000049,0.001249,3.046111,0.155176,0.012490,-174.098450,0.002133,0.000000
43.870003,0.688144,-174.098450,-0.000004,0.000062,0.001578,3.061019,0.155936,0.015775,-174.098450,0.002419,0.000000
44.040001,0.715700,-174.187408,0.000017,0.000070,0.001786,3.183592,0.162180,0.017865,-174.187408,0.002705,0.000000
44.210003,0.707135,-174.187408,0.000030,0.000080,0.002020,3.145495,0.160239,0.020196,-174.187408,0.002982,0.000000
44.380001,0.729478,-174.142929,0.000034,0.000095,0.002410,3.244879,0.165302,0.024102,-174.142929,0.003269,0.000000
44.550003,0.719796,-174.187408,0.000004,0.000103,0.002610,3.201812,0.163108,0.026101,-174.187408,0.003555,0.000000
44.720001,0.732084,-174.187408,0.000030,0.000110,0.002801,3.256474,0.165893,0.028008,-174.187408,0.003833,0.000000
44.890003,0.798367,-174.187408,0.000013,0.000129,0.003278,3.551312,0.180912,0.032777,-174.187408,0.004119,0.000000
45.060001,0.795015,-174.231888,0.000017,0.000138,0.003503,3.536404,0.180153,0.035033,-174.231888,0.004406,0.000000
45.230003,0.812889,-174.231888,0.000013,0.000147,0.003738,3.615911,0.184203,0.037380,-174.231888,0.004683,0.000000
45.400002,0.836721,-174.142929,0.000043,0.000158,0.004015,3.721921,0.189604,0.040150,-174.142929,0.004969,0.000000
45.570004,0.845285,-174.142929,0.000030,0.000163,0.004145,3.760018,0.191544,0.041452,-174.142929,0.005255,0.000000
45.740002,0.880661,-174.187408,-0.000004,0.000185,0.004699,3.917375,0.199561,0.046993,-174.187408,0.005532,0.000000
45.910004,0.886619,-174.231888,0.000043,0.000197,0.005013,3.943878,0.200911,0.050127,-174.231888,0.005818,0.000000
46.080002,0.906727,-174.187408,0.000009,0.000206,0.005229,4.033323,0.205467,0.052292,-174.187408,0.006104,0.000000
46.250004,0.875820,-174.187408,0.000043,0.000217,0.005506,3.895842,0.198464,0.055063,-174.187408,0.006383,0.000000
46.420002,0.895183,-174.231888,-0.000004,0.000228,0.005792,3.981975,0.202851,0.057924,-174.231888,0.006669,0.000000
46.590004,0.910823,-174.187408,0.000047,0.000237,0.006018,4.051543,0.206395,0.060180,-174.187408,0.006955,0.000000
46.760002,0.924601,-174.231888,0.000017,0.000245,0.006234,4.112830,0.209518,0.062345,-174.231888,0.007232,0.000000
46.930004,0.972265,-174.231888,0.000017,0.000260,0.006616,4.324849,0.220318,0.066160,-174.231888,0.007518,0.000000
47.100002,0.961838,-174.231888,-0.000004,0.000269,0.006842,4.278470,0.217956,0.068416,-174.231888,0.007804,0.000000
47.270000,0.973009,-174.231888,0.000013,0.000277,0.007032,4.328161,0.220487,0.070323,-174.231888,0.008082,0.000000
47.440002,0.996096,-174.276367,0.000022,0.000286,0.007258,4.430858,0.225719,0.072579,-174.276367,0.008368,0.000000
47.610001,1.030355,-174.320847,0.000004,0.000293,0.007440,4.583246,0.233482,0.074396,-174.320847,0.008654,0.000000
47.780003,1.085838,-174.276367,0.000009,0.000320,0.008116,4.830049,0.246054,0.081163,-174.276367,0.008932,0.000000
47.950001,1.090307,-174.231888,0.000043,0.000328,0.008333,4.849926,0.247067,0.083328,-174.231888,0.009218,0.000000
48.120003,1.083231,-174.276367,-0.000009,0.000340,0.008628,4.818454,0.245464,0.086280,-174.276367,0.009505,0.000000
48.290001,1.101478,-174.276367,0.000009,0.000349,0.008863,4.899618,0.249598,0.088627,-174.276367,0.009782,0.000000
48.460003,1.116745,-174.276367,0.000022,0.000359,0.009114,4.967530,0.253058,0.091140,-174.276367,0.010068,0.000000
48.630001,1.137226,-174.320847,0.000039,0.000370,0.009391,5.058632,0.257699,0.093911,-174.320847,0.010354,0.000000
48.800003,1.186006,-174.276367,0.000017,0.000384,0.009756,5.275620,0.268753,0.097559,-174.276367,0.010631,0.000000
48.970001,1.196805,-174.320847,-0.000004,0.000393,0.009972,5.323655,0.271200,0.099724,-174.320847,0.010917,0.000000
49.140003,1.205742,-174.276367,0.000026,0.000400,0.010172,5.363408,0.273225,0.101723,-174.276367,0.011203,0.000000
49.310001,1.220637,-174.276367,0.000043,0.000408,0.010354,5.429665,0.276600,0.103540,-174.276367,0.011482,0.000000
49.480003,1.266811,-174.365326,0.000009,0.000420,0.010675,5.635057,0.287064,0.106749,-174.365326,0.011768,0.000000
49.650002,1.321922,-174.231888,0.000039,0.000442,0.011231,5.880204,0.299552,0.112305,-174.231888,0.012054,0.000000
49.820004,1.339796,-174.320847,0.000009,0.000453,0.011508,5.959711,0.303602,0.115076,-174.320847,0.012331,0.000000
49.990002,1.352829,-174.320847,0.000013,0.000461,0.011707,6.017684,0.306555,0.117074,-174.320847,0.012617,0.000000
50.160004,1.358042,-174.365326,-0.000013,0.000471,0.011975,6.040874,0.307737,0.119754,-174.365326,0.012903,0.000000
50.330002,1.374799,-174.320847,0.000034,0.000482,0.012254,6.115412,0.311534,0.122540,-174.320847,0.013182,0.000000
50.500004,1.419484,-174.365326,0.000034,0.000495,0.012575,6.314179,0.321660,0.125749,-174.365326,0.013468,0.000000
50.670002,1.436613,-174.320847,0.000022,0.000506,0.012861,6.390374,0.325541,0.128611,-174.320847,0.013754,0.000000
50.840004,1.439592,-174.320847,0.000000,0.000518,0.013147,6.403625,0.326216,0.131472,-174.320847,0.014031,0.000000
51.010002,1.443688,-174.365326,0.000017,0.000528,0.013399,6.421845,0.327144,0.133985,-174.365326,0.014318,0.000000
51.180004,1.409430,-174.409805,0.000026,0.000533,0.013529,6.269457,0.319381,0.135287,-174.409805,0.014604,0.000000
51.350002,1.467520,-174.365326,0.000004,0.000548,0.013910,6.527854,0.332545,0.139102,-174.365326,0.014890,0.000000
51.520004,1.468637,-174.320847,0.000047,0.000560,0.014231,6.532824,0.332798,0.142312,-174.320847,0.015167,0.000000
51.690002,1.473105,-174.409805,0.000004,0.000575,0.014595,6.552700,0.333810,0.145946,-174.409805,0.015453,0.000000
51.860001,1.455232,-174.409805,0.000004,0.000583,0.014811,6.473193,0.329760,0.148111,-174.409805,0.015739,0.000000
52.030003,1.454859,-174.454285,-0.000004,0.000591,0.015020,6.471537,0.329676,0.150200,-174.454285,0.016018,0.000000
52.200001,1.441826,-174.365326,0.000013,0.000604,0.015350,6.413563,0.326722,0.153500,-174.365326,0.016304,0.000000
52.370003,1.453742,-174.365326,0.000017,0.000614,0.015601,6.466568,0.329423,0.156013,-174.365326,0.016590,0.000000
52.540001,1.489490,-174.320847,0.000043,0.000630,0.016009,6.625582,0.337523,0.160086,-174.320847,0.016867,0.000000
52.710003,1.469009,-174.409805,0.000043,0.000640,0.016251,6.534480,0.332882,0.162508,-174.409805,0.017153,0.000000
52.880001,1.474223,-174.454285,0.000043,0.000650,0.016520,6.557669,0.334064,0.165203,-174.454285,0.017439,0.000000
53.050003,1.473850,-174.409805,0.000047,0.000659,0.016728,6.556013,0.333979,0.167277,-174.409805,0.017716,0.000000
53.220001,1.500289,-174.409805,0.000022,0.000670,0.017023,6.673617,0.339970,0.170229,-174.409805,0.018002,0.000000
53.390003,1.503640,-174.409805,0.000026,0.000684,0.017379,6.688525,0.340730,0.173787,-174.409805,0.018289,0.000000
53.560001,1.513694,-174.409805,0.000000,0.000699,0.017751,6.733247,0.343008,0.177512,-174.409805,0.018567,0.000000
53.730003,1.487628,-174.498764,0.000043,0.000708,0.017995,6.617300,0.337101,0.179949,-174.498764,0.018853,0.000000
53.900002,1.501033,-174.409805,0.000030,0.000720,0.018281,6.676930,0.340139,0.182810,-174.409805,0.019139,0.000000
54.070004,1.501033,-174.454285,0.000013,0.000730,0.018532,6.676930,0.340139,0.185324,-174.454285,0.019417,0.000000
54.240002,1.486138,-174.365326,0.000030,0.000737,0.018723,6.610674,0.336764,0.187231,-174.365326,0.019703,0.000000
54.410004,1.476084,-174.543259,0.000026,0.000746,0.018949,6.565952,0.334486,0.189487,-174.543259,0.019989,0.000000
54.580002,1.506619,-174.454285,0.000039,0.000758,0.019244,6.701776,0.341405,0.192439,-174.454285,0.020266,0.000000
54.750004,1.522631,-174.454285,0.000017,0.000769,0.019530,6.773001,0.345033,0.195301,-174.454285,0.020553,0.000000
54.920002,1.521514,-174.498764,0.000043,0.000777,0.019737,6.768032,0.344780,0.197375,-174.498764,0.020840,0.000000
55.090004,1.511460,-174.454285,0.000022,0.000787,0.019980,6.723309,0.342502,0.199797,-174.454285,0.021117,0.000000
55.260002,1.539388,-174.498764,0.000039,0.000797,0.020240,6.847538,0.348830,0.202401,-174.498764,0.021403,0.000000
55.430004,1.564709,-174.498764,0.000047,0.000817,0.020752,6.960174,0.354568,0.207518,-174.498764,0.021689,0.000000
55.600002,1.559496,-174.498764,0.000000,0.000831,0.021099,6.936985,0.353387,0.210985,-174.498764,0.021966,0.000000
55.770004,1.548697,-174.454285,0.000034,0.000840,0.021333,6.888948,0.350940,0.213332,-174.454285,0.022252,0.000000
55.940002,1.523003,-174.498764,0.000017,0.000848,0.021550,6.774657,0.345118,0.215497,-174.498764,0.022538,0.000000
56.110004,1.518535,-174.543259,0.000026,0.000859,0.021810,6.754781,0.344105,0.218101,-174.543259,0.022817,0.000000
56.280003,1.495075,-174.498764,0.000013,0.000869,0.022061,6.650428,0.338789,0.220614,-174.498764,0.023103,0.000000
56.450005,1.509226,-174.543259,0.000026,0.000878,0.022296,6.713371,0.341995,0.222961,-174.543259,0.023389,0.000000
56.620003,1.555400,-174.498764,0.000022,0.000889,0.022591,6.918764,0.352459,0.225913,-174.498764,0.023666,0.000000
56.790001,1.584072,-174.543259,-0.000009,0.000905,0.022999,7.046306,0.358956,0.229985,-174.543259,0.023952,0.000000
56.960003,1.571784,-174.543259,0.000013,0.000913,0.023189,6.991645,0.356171,0.231893,-174.543259,0.024238,0.000000
57.130001,1.582583,-174.587738,0.000013,0.000924,0.023457,7.039680,0.358618,0.234573,-174.587738,0.024516,0.000000
57.300003,1.584817,-174.543259,0.000000,0.000938,0.023831,7.049619,0.359125,0.238312,-174.543259,0.024802,0.000000
57.470001,1.597106,-174.498764,0.000017,0.000949,0.024099,7.104280,0.361909,0.240992,-174.498764,0.025088,0.000000
57.640003,1.597850,-174.543259,0.000013,0.000960,0.024394,7.107593,0.362078,0.243944,-174.543259,0.025366,0.000000
57.810001,1.584072,-174.543259,0.000017,0.000971,0.024664,7.046306,0.358956,0.246639,-174.543259,0.025653,0.000000
57.980003,1.550559,-174.543259,0.000022,0.000982,0.024941,6.897231,0.351362,0.249409,-174.543259,0.025939,0.000000
58.150002,1.547952,-174.543259,0.000013,0.000991,0.025183,6.885636,0.350771,0.251832,-174.543259,0.026216,0.000000
58.320004,1.548325,-174.587738,0.000017,0.001000,0.025392,6.887292,0.350855,0.253921,-174.587738,0.026502,0.000000
58.490002,1.599712,-174.543259,0.000000,0.001012,0.025695,7.115875,0.362500,0.256949,-174.543259,0.026788,0.000000
58.660004,1.620193,-174.543259,0.000034,0.001026,0.026060,7.206976,0.367141,0.260598,-174.543259,0.027065,0.000000
58.830002,1.617958,-174.587738,0.000017,0.001037,0.026328,7.197038,0.366635,0.263277,-174.587738,0.027351,0.000000
59.000004,1.631364,-174.632217,0.000034,0.001047,0.026588,7.256669,0.369672,0.265881,-174.632217,0.027637,0.000000
59.170002,1.612373,-174.587738,0.000034,0.001058,0.026883,7.172192,0.365369,0.268834,-174.587738,0.027916,0.000000
59.340004,1.648493,-174.587738,0.000034,0.001074,0.027283,7.332862,0.373554,0.272830,-174.587738,0.028202,0.000000
59.510002,1.623544,-174.632217,0.000039,0.001083,0.027516,7.221884,0.367900,0.275162,-174.632217,0.028488,0.000000
59.680004,1.627640,-174.587738,0.000026,0.001095,0.027811,7.240104,0.368829,0.278114,-174.587738,0.028774,0.000000
59.850002,1.577370,-174.543259,0.000030,0.001106,0.028081,7.016491,0.357437,0.280809,-174.543259,0.029051,0.000000
60.020004,1.562102,-174.587738,0.000022,0.001114,0.028306,6.948579,0.353977,0.283065,-174.587738,0.029337,0.000000
60.190002,1.593382,-174.587738,-0.000017,0.001128,0.028653,7.087716,0.361065,0.286532,-174.587738,0.029624,0.000000
60.360004,1.585934,-174.676697,0.000043,0.001135,0.028835,7.054588,0.359378,0.288348,-174.676697,0.029902,0.000000
60.530003,1.674931,-174.587738,0.000056,0.001151,0.029233,7.450467,0.379545,0.292330,-174.587738,0.030188,0.000000
60.700005,1.655940,-174.587738,0.000034,0.001161,0.029493,7.365990,0.375241,0.294934,-174.587738,0.030474,0.000000
60.870003,1.658175,-174.632217,0.000047,0.001170,0.029710,7.375928,0.375748,0.297099,-174.632217,0.030752,0.000000
61.040005,1.662271,-174.587738,0.000043,0.001182,0.030014,7.394149,0.376676,0.300142,-174.587738,0.031038,0.000000
61.210003,1.671580,-174.632217,0.000043,0.001197,0.030405,7.435559,0.378785,0.304048,-174.632217,0.031324,0.000000
61.380001,1.654823,-174.632217,-0.000004,0.001208,0.030691,7.361021,0.374988,0.306910,-174.632217,0.031601,0.000000
61.550003,1.654451,-174.632217,0.000004,0.001219,0.030951,7.359365,0.374904,0.309514,-174.632217,0.031887,0.000000
61.720001,1.656313,-174.632217,0.000034,0.001228,0.031203,7.367647,0.375326,0.312027,-174.632217,0.032173,0.000000
61.890003,1.626151,-174.632217,0.000009,0.001239,0.031480,7.233479,0.368491,0.314797,-174.632217,0.032452,0.000000
62.060001,1.636949,-174.632217,0.000043,0.001250,0.031757,7.281514,0.370938,0.317568,-174.632217,0.032738,0.000000
62.230003,1.619820,-174.721176,0.000030,0.001258,0.031948,7.205320,0.367056,0.319475,-174.721176,0.033024,0.000000
62.400002,1.724457,-174.676697,0.000047,0.001273,0.032338,7.670767,0.390768,0.323381,-174.676697,0.033301,0.000000
62.570004,1.713658,-174.676697,0.000034,0.001284,0.032608,7.622732,0.388320,0.326076,-174.676697,0.033587,0.000000
62.740002,1.708817,-174.632217,0.000000,0.001293,0.032850,7.601199,0.387224,0.328499,-174.632217,0.033873,0.000000
62.910004,1.721106,-174.676697,0.000022,0.001299,0.032997,7.655860,0.390008,0.329967,-174.676697,0.034150,0.000000
63.080002,1.722223,-174.721176,0.000017,0.001308,0.033231,7.660829,0.390261,0.332314,-174.721176,0.034436,0.000000
63.250004,1.739352,-174.676697,0.000013,0.001328,0.033726,7.737023,0.394143,0.337264,-174.676697,0.034723,0.000000
63.420002,1.738979,-174.676697,0.000004,0.001341,0.034064,7.735366,0.394058,0.340641,-174.676697,0.035001,0.000000
63.590004,1.708817,-174.676697,0.000000,0.001348,0.034229,7.601199,0.387224,0.342291,-174.676697,0.035287,0.000000
63.760002,1.687592,-174.721176,0.000017,0.001360,0.034550,7.506784,0.382414,0.345500,-174.721176,0.035573,0.000000
63.930004,1.712541,-174.721176,0.000034,0.001375,0.034913,7.617763,0.388067,0.349134,-174.721176,0.035851,0.000000
64.100006,1.701370,-174.810135,0.000013,0.001382,0.035104,7.568071,0.385536,0.351041,-174.810135,0.036137,0.000000
64.270004,1.728553,-174.676697,0.000017,0.001395,0.035425,7.688987,0.391696,0.354251,-174.676697,0.036423,0.000000
64.440002,1.756109,-174.721176,0.000026,0.001406,0.035711,7.811561,0.397940,0.357112,-174.721176,0.036700,0.000000
64.610001,1.730787,-174.765656,0.000013,0.001413,0.035894,7.698926,0.392202,0.358944,-174.765656,0.036986,0.000000
64.780006,1.736000,-174.676697,0.000026,0.001420,0.036059,7.722116,0.393383,0.360595,-174.676697,0.037272,0.000000
64.950005,1.771376,-174.765656,0.000009,0.001436,0.036474,7.879473,0.401399,0.364743,-174.765656,0.037551,0.000000
65.120003,1.793718,-174.676697,0.000000,0.001454,0.036925,7.978857,0.406462,0.369254,-174.676697,0.037837,0.000000
65.290001,1.759460,-174.721176,0.000004,0.001463,0.037151,7.826468,0.398699,0.371510,-174.721176,0.038123,0.000000
65.460007,1.750523,-174.765656,-0.000009,0.001472,0.037386,7.786715,0.396674,0.373857,-174.765656,0.038400,0.000000
65.630005,1.741586,-174.765656,0.000013,0.001484,0.037688,7.746961,0.394649,0.376885,-174.765656,0.038686,0.000000
65.800003,1.733766,-174.721176,0.000039,0.001494,0.037949,7.712177,0.392877,0.379489,-174.721176,0.038972,0.000000
65.970001,1.733394,-174.721176,0.000017,0.001507,0.038270,7.710521,0.392793,0.382698,-174.721176,0.039251,0.000000
66.139999,1.785526,-174.765656,0.000047,0.001520,0.038609,7.942417,0.404606,0.386090,-174.765656,0.039537,0.000000
66.310005,1.778823,-174.765656,0.000034,0.001532,0.038912,7.912601,0.403087,0.389117,-174.765656,0.039823,0.000000
66.480003,1.759832,-174.810135,0.000030,0.001542,0.039163,7.828125,0.398784,0.391631,-174.810135,0.040100,0.000000
66.650002,1.744193,-174.810135,0.000013,0.001550,0.039363,7.758556,0.395240,0.393629,-174.810135,0.040386,0.000000
66.820000,1.793718,-174.765656,0.000030,0.001559,0.039605,7.978857,0.406462,0.396051,-174.765656,0.040672,0.000000
66.990005,1.832445,-174.765656,0.000034,0.001577,0.040056,8.151122,0.415238,0.400563,-174.765656,0.040950,0.000000
67.160004,1.812709,-174.810135,0.000047,0.001591,0.040403,8.063333,0.410766,0.404030,-174.810135,0.041236,0.000000
67.330002,1.800048,-174.854614,0.000026,0.001602,0.040682,8.007015,0.407897,0.406816,-174.854614,0.041522,0.000000
67.500000,1.779940,-174.943573,0.000022,0.001611,0.040924,7.917570,0.403340,0.409238,-174.943573,0.041800,0.000000
67.670006,1.767652,-174.810135,0.000034,0.001622,0.041193,7.862909,0.400556,0.411933,-174.810135,0.042087,0.000000
67.840004,1.754247,-174.765656,0.000022,0.001632,0.041452,7.803279,0.397518,0.414522,-174.765656,0.042373,0.000000
68.010002,1.736745,-174.765656,0.000004,0.001639,0.041643,7.725428,0.393552,0.416429,-174.765656,0.042659,0.000000
68.180000,1.788505,-174.899094,0.000013,0.001655,0.042026,7.955667,0.405281,0.420260,-174.899094,0.042936,0.000000
68.350006,1.759832,-174.854614,0.000004,0.001662,0.042217,7.828125,0.398784,0.422167,-174.854614,0.043222,0.000000
68.520004,1.758715,-174.854614,0.000009,0.001672,0.042459,7.823156,0.398531,0.424590,-174.854614,0.043508,0.000000
68.690002,1.748289,-174.854614,0.000047,0.001677,0.042598,7.776776,0.396168,0.425982,-174.854614,0.043785,0.000000
68.860001,1.786271,-174.810135,0.000009,0.001688,0.042884,7.945729,0.404775,0.428844,-174.810135,0.044071,0.000000
69.030006,1.873406,-174.810135,-0.000009,0.001713,0.043517,8.333325,0.424520,0.435172,-174.810135,0.044357,0.000000
69.200005,1.814571,-174.899094,0.000026,0.001724,0.043794,8.071615,0.411188,0.437943,-174.899094,0.044636,0.000000
69.370003,1.797442,-174.899094,0.000026,0.001735,0.044064,7.995420,0.407306,0.440637,-174.899094,0.044922,0.000000
69.540001,1.731904,-174.854614,0.000039,0.001740,0.044185,7.703895,0.392455,0.441849,-174.854614,0.044332,0.000000
69.600006,1.717009,-174.854614,0.000004,0.001739,0.044176,7.637640,0.389080,0.441758,-174.854614,0.044332,0.000000