File: Data/New pin align test AD 2_08172023_164117.csv
Time (sec),S:Load (lbs),S:HL1 (DIM),S:LVDT (in),S:Position (in),Ch:Position (mm),Ch:Load (N),Ch:Stress (MPa),Ch:Strain (mm/mm),Ch:HL1 (DIM),Set Point (),Cycles ()
0.010000,-0.017501,-177.701401,-0.000022,-0.000000,-0.000000,-0.077850,-0.003966,-0.000000,-177.701401,0.000174,0.000000
0.400000,-0.013778,-177.656921,-0.000009,0.000032,0.000816,-0.061286,-0.003122,0.008160,-177.656921,0.001284,0.000000
0.790000,-0.032396,-177.656921,0.000026,0.000269,0.006826,-0.144106,-0.007341,0.068264,-177.656921,0.007788,0.000000
1.180000,-0.029417,-177.656921,0.000013,0.000522,0.013261,-0.130855,-0.006666,0.132608,-177.656921,0.014275,0.000000
1.570000,0.012661,-177.612442,0.000082,0.000769,0.019522,0.056318,0.002869,0.195225,-177.612442,0.020779,0.000000
1.960000,0.010427,-177.612442,0.000065,0.001023,0.025973,0.046379,0.002363,0.259735,-177.612442,0.027283,0.000000
2.350000,0.005213,-177.656921,0.000017,0.001289,0.032747,0.023190,0.001181,0.327469,-177.656921,0.033770,0.000000
2.740000,0.003351,-177.612442,0.000082,0.001544,0.039216,0.014908,0.000759,0.392161,-177.612442,0.040274,0.000000
3.130000,-0.023832,-177.701401,0.000000,0.001798,0.045669,-0.106009,-0.005400,0.456685,-177.701401,0.046762,0.000000
3.520000,0.014150,-177.567963,0.000009,0.002052,0.052121,0.062943,0.003206,0.521210,-177.567963,0.053266,0.000000
3.910000,0.021970,-177.656921,0.000026,0.002312,0.058720,0.097728,0.004978,0.587204,-177.656921,0.059770,0.000000
4.300000,0.000372,-177.567963,0.000086,0.002571,0.065303,0.001657,0.000084,0.653031,-177.567963,0.066257,0.000000
4.690000,-0.007075,-177.567963,0.000047,0.002825,0.071763,-0.031471,-0.001603,0.717631,-177.567963,0.072761,0.000000
5.080000,-0.025694,-177.656921,0.000056,0.003079,0.078199,-0.114291,-0.005822,0.781990,-177.656921,0.079248,0.000000
5.470000,-0.010799,-177.567963,0.000078,0.003332,0.084633,-0.048036,-0.002447,0.846333,-177.567963,0.085752,0.000000
5.860000,0.007447,-177.612442,0.000030,0.003588,0.091137,0.033128,0.001688,0.911372,-177.612442,0.092256,0.000000
6.250000,-0.001862,-177.656921,0.000056,0.003850,0.097790,-0.008282,-0.000422,0.977896,-177.656921,0.098743,0.000000
6.640000,0.013033,-177.567963,0.000052,0.004102,0.104180,0.057974,0.002953,1.041800,-177.567963,0.105247,0.000000
7.030000,-0.021225,-177.612442,0.000056,0.004357,0.110667,-0.094414,-0.004810,1.106673,-177.612442,0.111751,0.000000
7.420001,-0.022715,-177.523483,-0.000030,0.004612,0.117146,-0.101040,-0.005147,1.171455,-177.523483,0.118239,0.000000
7.810000,0.010799,-177.523483,0.000060,0.004867,0.123615,0.048036,0.002447,1.236147,-177.523483,0.124743,0.000000
8.200001,-0.029790,-177.567963,-0.000022,0.005126,0.130197,-0.132512,-0.006750,1.301974,-177.567963,0.131230,0.000000
8.590000,-0.001117,-177.523483,-0.000017,0.005382,0.136701,-0.004969,-0.000253,1.367013,-177.523483,0.137734,0.000000
8.980000,-0.036865,-177.656921,0.000047,0.005636,0.143145,-0.163983,-0.008354,1.431447,-177.656921,0.144238,0.000000
9.370001,-0.053249,-177.523483,0.000078,0.005889,0.149571,-0.236864,-0.012066,1.495715,-177.523483,0.150725,0.000000
9.760000,-0.047291,-177.567963,-0.000026,0.006147,0.156127,-0.210362,-0.010716,1.561269,-177.567963,0.157229,0.000000
10.150001,-0.024577,-177.567963,0.000099,0.006401,0.162588,-0.109322,-0.005569,1.625885,-177.567963,0.163715,0.000000
10.540001,-0.020480,-177.478989,-0.000022,0.006661,0.169197,-0.091101,-0.004641,1.691969,-177.478989,0.170220,0.000000
10.930000,-0.009682,-177.567963,-0.000009,0.006914,0.175615,-0.043066,-0.002194,1.756146,-177.567963,0.176724,0.000000
11.320001,-0.043568,-177.523483,0.000026,0.007167,0.182049,-0.193798,-0.009873,1.820489,-177.523483,0.183210,0.000000
11.710001,-0.067399,-177.523483,0.000043,0.007425,0.188597,-0.299807,-0.015273,1.885968,-177.523483,0.189716,0.000000
12.100000,-0.002607,-177.567963,0.000039,0.007680,0.195083,-0.011594,-0.000591,1.950826,-177.567963,0.196201,0.000000
12.490001,-0.028300,-177.523483,0.000073,0.007938,0.201630,-0.125886,-0.006413,2.016304,-177.523483,0.202705,0.000000
12.880001,0.010054,-177.612442,0.000078,0.008192,0.208065,0.044723,0.002278,2.080648,-177.612442,0.209211,0.000000
13.270000,-0.014150,-177.612442,-0.000022,0.008447,0.214552,-0.062943,-0.003206,2.145521,-177.612442,0.215697,0.000000
13.660001,-0.043568,-177.478989,0.000030,0.008700,0.220979,-0.193798,-0.009873,2.209788,-177.478989,0.222201,0.000000
14.050000,-0.059580,-177.478989,0.000039,0.008959,0.227569,-0.265023,-0.013501,2.275691,-177.478989,0.228688,0.000000
14.440001,-0.020108,-177.478989,0.000009,0.009212,0.233978,-0.089445,-0.004557,2.339777,-177.478989,0.235192,0.000000
14.830001,-0.004468,-177.523483,0.000078,0.009471,0.240560,-0.019877,-0.001013,2.405604,-177.523483,0.241696,0.000000
15.220000,-0.008564,-177.523483,0.000065,0.009730,0.247143,-0.038097,-0.001941,2.471431,-177.523483,0.248183,0.000000
15.610001,-0.020853,-177.478989,0.000060,0.009980,0.253491,-0.092758,-0.004725,2.534911,-177.478989,0.254687,0.000000
16.000000,-0.054739,-177.478989,0.000009,0.010237,0.260012,-0.243490,-0.012404,2.600117,-177.478989,0.261174,0.000000
16.390001,-0.004841,-177.478989,0.000030,0.010494,0.266543,-0.021533,-0.001097,2.665429,-177.478989,0.267678,0.000000
16.780001,-0.012661,-177.478989,0.000065,0.010749,0.273012,-0.056317,-0.002869,2.730120,-177.478989,0.274182,0.000000
17.170000,-0.002234,-177.434509,0.000000,0.011010,0.279664,-0.009938,-0.000506,2.796644,-177.434509,0.280670,0.000000
17.560001,-0.009682,-177.390030,0.000060,0.011261,0.286029,-0.043066,-0.002194,2.860291,-177.390030,0.287174,0.000000
17.950001,-0.027555,-177.434509,0.000017,0.011512,0.292395,-0.122573,-0.006244,2.923953,-177.434509,0.293661,0.000000
18.340000,-0.003724,-177.434509,0.000078,0.011772,0.299020,-0.016564,-0.000844,2.990203,-177.434509,0.300165,0.000000
18.730001,-0.017129,-177.390030,-0.000022,0.012032,0.305611,-0.076194,-0.003882,3.056106,-177.390030,0.306669,0.000000
19.120001,-0.008937,-177.478989,0.000065,0.012287,0.312098,-0.039753,-0.002025,3.120979,-177.478989,0.313156,0.000000
19.510000,-0.002979,-177.390030,-0.000009,0.012545,0.318637,-0.013251,-0.000675,3.186367,-177.390030,0.319660,0.000000
19.900002,-0.006703,-177.478989,-0.000004,0.012795,0.325003,-0.029815,-0.001519,3.250029,-177.478989,0.326147,0.000000
20.290001,-0.011916,-177.434509,0.000009,0.013053,0.331542,-0.053005,-0.002700,3.315417,-177.434509,0.332651,0.000000
20.680000,0.002234,-177.390030,-0.000030,0.013309,0.338046,0.009938,0.000506,3.380456,-177.390030,0.339155,0.000000
21.070002,-0.006330,-177.434509,0.000060,0.013566,0.344575,-0.028158,-0.001434,3.445753,-177.434509,0.345643,0.000000
21.460001,0.007075,-177.390030,0.000078,0.013823,0.351097,0.031471,0.001603,3.510975,-177.390030,0.352147,0.000000
21.850000,0.007820,-177.434509,0.000052,0.014073,0.357462,0.034785,0.001772,3.574621,-177.434509,0.358634,0.000000
22.240002,-0.007820,-177.390030,-0.000022,0.014329,0.363949,-0.034784,-0.001772,3.639494,-177.390030,0.365138,0.000000
22.630001,0.007075,-177.390030,0.000047,0.014588,0.370540,0.031471,0.001603,3.705397,-177.390030,0.371642,0.000000
23.020000,-0.004468,-177.434509,0.000017,0.014844,0.377027,-0.019877,-0.001013,3.770270,-177.434509,0.378129,0.000000
23.410002,-0.018246,-177.345551,0.000086,0.015099,0.383514,-0.081163,-0.004135,3.835143,-177.345551,0.384633,0.000000
23.800001,-0.018246,-177.434509,0.000039,0.015354,0.389993,-0.081163,-0.004135,3.899925,-177.434509,0.391119,0.000000
24.190001,-0.008937,-177.345551,-0.000017,0.015611,0.396522,-0.039753,-0.002025,3.965223,-177.345551,0.397624,0.000000
24.580002,-0.009309,-177.345551,0.000047,0.015866,0.402984,-0.041410,-0.002110,4.029838,-177.345551,0.404128,0.000000
24.970001,0.005958,-177.345551,0.000056,0.016115,0.409314,0.026502,0.001350,4.093137,-177.345551,0.410614,0.000000
25.360001,0.000372,-177.345551,0.000026,0.016376,0.415939,0.001657,0.000084,4.159388,-177.345551,0.417120,0.000000
25.750002,0.014895,-177.390030,-0.000022,0.016631,0.422435,0.066256,0.003375,4.224351,-177.390030,0.423605,0.000000
26.140001,-0.005213,-177.345551,-0.000039,0.016881,0.428774,-0.023189,-0.001181,4.287741,-177.345551,0.430109,0.000000
26.530001,-0.005586,-177.345551,0.000039,0.017140,0.435357,-0.024846,-0.001266,4.353568,-177.345551,0.436615,0.000000
26.920002,0.036865,-177.390030,0.000030,0.017397,0.441886,0.163983,0.008354,4.418865,-177.390030,0.443101,0.000000
27.310001,0.026066,-177.345551,0.000030,0.017653,0.448390,0.115948,0.005907,4.483904,-177.345551,0.449605,0.000000
27.700001,0.004096,-177.390030,0.000052,0.017906,0.454808,0.018221,0.000928,4.548081,-177.390030,0.456110,0.000000
28.090002,0.012661,-177.345551,-0.000026,0.018166,0.461426,0.056318,0.002869,4.614256,-177.345551,0.462596,0.000000
28.480001,0.004841,-177.345551,-0.000043,0.018422,0.467921,0.021533,0.001097,4.679205,-177.345551,0.469100,0.000000
28.870001,0.006703,-177.390030,0.000065,0.018678,0.474434,0.029815,0.001519,4.744336,-177.390030,0.475587,0.000000
29.260002,0.074475,-177.301071,-0.000022,0.018927,0.480747,0.331279,0.016876,4.807467,-177.301071,0.482091,0.000000
29.650002,0.118787,-177.345551,0.000026,0.019183,0.487260,0.528390,0.026917,4.872598,-177.345551,0.488595,0.000000
30.040001,0.189165,-177.301071,0.000026,0.019446,0.493929,0.841449,0.042865,4.939288,-177.301071,0.495082,0.000000
30.430002,0.231243,-177.212112,-0.000030,0.019693,0.500207,1.028622,0.052400,5.002072,-177.212112,0.501586,0.000000
30.820002,0.272577,-177.301071,0.000034,0.019955,0.506850,1.212482,0.061767,5.068504,-177.301071,0.508074,0.000000
31.210001,0.318379,-177.301071,0.000272,0.020206,0.513233,1.416218,0.072146,5.132333,-177.301071,0.514578,0.000000
31.600002,0.315772,-177.256592,0.000573,0.020466,0.519842,1.404624,0.071555,5.198417,-177.256592,0.521082,0.000000
31.990002,0.297153,-177.256592,0.000755,0.020721,0.526303,1.321804,0.067336,5.263033,-177.256592,0.527569,0.000000
32.380001,0.312048,-177.301071,0.001009,0.020983,0.532972,1.388059,0.070711,5.329722,-177.301071,0.534073,0.000000
32.770000,0.293802,-177.301071,0.001268,0.021238,0.539450,1.306896,0.066576,5.394505,-177.301071,0.540560,0.000000
33.160000,0.307952,-177.167633,0.001496,0.021495,0.545962,1.369839,0.069783,5.459620,-177.167633,0.547064,0.000000
33.550003,0.334391,-177.256592,0.001789,0.021751,0.552467,1.487443,0.075774,5.524675,-177.256592,0.553568,0.000000
33.940002,0.329922,-177.256592,0.002061,0.022003,0.558867,1.467566,0.074761,5.588670,-177.256592,0.560055,0.000000
34.330002,0.339231,-177.212112,0.002328,0.022267,0.565587,1.508976,0.076871,5.655875,-177.212112,0.566559,0.000000
34.720001,0.316517,-177.212112,0.002561,0.022519,0.571979,1.407936,0.071724,5.719794,-177.212112,0.573047,0.000000
35.110001,0.331039,-177.212112,0.002897,0.022773,0.578432,1.472536,0.075015,5.784319,-177.212112,0.579551,0.000000
35.500000,0.328805,-177.212112,0.003130,0.023027,0.584892,1.462597,0.074508,5.848919,-177.212112,0.586055,0.000000
35.890003,0.353754,-177.167633,0.003410,0.023287,0.591500,1.573576,0.080162,5.915004,-177.167633,0.592542,0.000000
36.280003,0.330667,-177.212112,0.003613,0.023546,0.598065,1.470879,0.074930,5.980649,-177.212112,0.599046,0.000000
36.670002,0.316517,-177.167633,0.003893,0.023802,0.604578,1.407936,0.071724,6.045779,-177.167633,0.605532,0.000000
37.060001,0.306463,-177.078659,0.004169,0.024056,0.611014,1.363214,0.069445,6.110137,-177.078659,0.612037,0.000000
37.450001,0.298270,-177.212112,0.004441,0.024309,0.617457,1.326773,0.067589,6.174572,-177.212112,0.618541,0.000000
37.840000,0.330667,-177.167633,0.004743,0.024564,0.623935,1.470879,0.074930,6.239354,-177.167633,0.625027,0.000000
38.230003,0.344817,-177.123154,0.004924,0.024825,0.630551,1.533822,0.078137,6.305514,-177.123154,0.631532,0.000000
38.620003,0.329550,-177.167633,0.005269,0.025078,0.636987,1.465910,0.074677,6.369872,-177.167633,0.638018,0.000000
39.010002,0.320613,-177.078659,0.005463,0.025334,0.643473,1.426157,0.072652,6.434730,-177.078659,0.644522,0.000000
39.400002,0.319868,-177.123154,0.005756,0.025588,0.649925,1.422844,0.072483,6.499255,-177.123154,0.651028,0.000000
39.790001,0.344445,-177.078659,0.006036,0.025844,0.656439,1.532166,0.078052,6.564385,-177.078659,0.657513,0.000000
40.180000,0.324336,-177.078659,0.006222,0.026102,0.663003,1.442721,0.073496,6.630031,-177.078659,0.664017,0.000000
40.570004,0.353754,-177.078659,0.006549,0.026359,0.669507,1.573576,0.080162,6.695070,-177.078659,0.670505,0.000000
40.960003,0.319496,-176.989700,0.006821,0.026613,0.675969,1.421188,0.072399,6.759686,-176.989700,0.677009,0.000000
41.350002,0.296036,-177.034180,0.007101,0.026864,0.682351,1.316834,0.067083,6.823514,-177.034180,0.683513,0.000000
41.740002,0.319123,-176.945221,0.007286,0.027122,0.688899,1.419531,0.072314,6.888993,-176.945221,0.690000,0.000000
42.130001,0.326571,-176.989700,0.007584,0.027377,0.695378,1.452659,0.074002,6.953775,-176.989700,0.696504,0.000000
42.520000,0.342583,-176.989700,0.007838,0.027638,0.701994,1.523884,0.077630,7.019936,-176.989700,0.702991,0.000000
42.910004,0.351892,-176.945221,0.008084,0.027888,0.708367,1.565294,0.079740,7.083673,-176.945221,0.709495,0.000000
43.300003,0.318751,-176.989700,0.008330,0.028144,0.714855,1.417875,0.072230,7.148546,-176.989700,0.715999,0.000000
43.690002,0.303111,-176.945221,0.008675,0.028399,0.721342,1.348306,0.068686,7.213419,-176.945221,0.722486,0.000000
44.080002,0.341838,-176.856262,0.008895,0.028658,0.727906,1.520571,0.077462,7.279065,-176.856262,0.728990,0.000000
44.470001,0.336252,-176.945221,0.009162,0.028914,0.734419,1.495725,0.076196,7.344195,-176.945221,0.735478,0.000000
44.860001,0.362691,-176.856262,0.009390,0.029167,0.740846,1.613329,0.082187,7.408463,-176.856262,0.741982,0.000000
45.250004,0.340348,-176.945221,0.009675,0.029423,0.747341,1.513946,0.077124,7.473412,-176.945221,0.748486,0.000000
45.640003,0.323964,-176.856262,0.010011,0.029677,0.753801,1.441064,0.073411,7.538012,-176.856262,0.754973,0.000000
46.030003,0.310931,-176.900742,0.010244,0.029935,0.760341,1.383090,0.070458,7.603415,-176.900742,0.761477,0.000000
46.420002,0.362691,-176.856262,0.010503,0.030190,0.766820,1.613329,0.082187,7.668197,-176.856262,0.767964,0.000000
46.810001,0.361201,-176.767303,0.010731,0.030447,0.773358,1.606704,0.081849,7.733585,-176.767303,0.774468,0.000000
47.200001,0.373490,-176.811783,0.011037,0.030706,0.779923,1.661365,0.084634,7.799230,-176.811783,0.780972,0.000000
47.590004,0.337742,-176.767303,0.011275,0.030955,0.786245,1.502351,0.076533,7.862453,-176.767303,0.787459,0.000000
47.980003,0.319123,-176.722824,0.011520,0.031213,0.792810,1.419531,0.072314,7.928098,-176.722824,0.793963,0.000000
48.370003,0.367159,-176.767303,0.011753,0.031469,0.799305,1.633206,0.083199,7.993047,-176.767303,0.800467,0.000000
48.760002,0.362318,-176.678345,0.012115,0.031727,0.805878,1.611673,0.082103,8.058784,-176.678345,0.806955,0.000000
49.150002,0.384661,-176.722824,0.012383,0.031985,0.812426,1.711057,0.087165,8.124262,-176.722824,0.813459,0.000000
49.540001,0.370511,-176.678345,0.012555,0.032236,0.818792,1.648114,0.083959,8.187923,-176.678345,0.819945,0.000000
49.930004,0.342210,-176.633850,0.012848,0.032487,0.825166,1.522228,0.077546,8.251661,-176.633850,0.826450,0.000000
50.320004,0.401045,-176.678345,0.013094,0.032747,0.831782,1.783938,0.090878,8.317822,-176.678345,0.832954,0.000000
50.710003,0.589466,-176.589371,0.013357,0.033006,0.838365,2.622074,0.133575,8.383648,-176.589371,0.839440,0.000000
51.100002,0.589093,-176.589371,0.013478,-0.000004,-0.000103,2.620418,0.133490,-0.001029,-176.589371,0.000139,0.000000
51.490002,0.607340,-176.544891,0.013417,-0.000004,-0.000103,2.701581,0.137625,-0.001029,-176.544891,0.000391,0.000000
51.880001,0.620000,-176.544891,0.013469,0.000001,0.000027,2.757899,0.140494,0.000273,-176.544891,0.001042,0.000000
52.270004,0.710487,-176.544891,0.013435,0.000036,0.000902,3.160403,0.160999,0.009023,-176.544891,0.001691,0.000000
52.660004,0.696337,-176.455933,0.013525,0.000057,0.001458,3.097460,0.157792,0.014579,-176.455933,0.002342,0.000000
53.050003,0.749586,-176.455933,0.013564,0.000083,0.002117,3.334324,0.169859,0.021165,-176.455933,0.002993,0.000000
53.440002,0.790174,-176.455933,0.013594,0.000106,0.002689,3.514871,0.179056,0.026888,-176.455933,0.003643,0.000000
53.830002,0.837838,-176.411453,0.013577,0.000124,0.003140,3.726890,0.189857,0.031399,-176.411453,0.004294,0.000000
54.220001,0.907472,-176.411453,0.013538,0.000162,0.004112,4.036636,0.205636,0.041119,-176.411453,0.004943,0.000000
54.610004,0.930559,-176.322495,0.013599,0.000184,0.004675,4.139332,0.210868,0.046751,-176.322495,0.005594,0.000000
55.000004,0.968168,-176.366974,0.013693,0.000209,0.005299,4.306628,0.219390,0.052989,-176.366974,0.006245,0.000000
55.390003,1.010991,-176.366974,0.013637,0.000230,0.005854,4.497114,0.229094,0.058545,-176.366974,0.006895,0.000000
55.780003,1.069454,-176.322495,0.013620,0.000249,0.006322,4.757168,0.242342,0.063223,-176.322495,0.007546,0.000000
56.170002,1.182655,-176.322495,0.013698,0.000289,0.007337,5.260712,0.267993,0.073366,-176.322495,0.008197,0.000000
56.560001,1.214307,-176.233521,0.013771,0.000309,0.007848,5.401505,0.275166,0.078484,-176.233521,0.008846,0.000000
56.950005,1.293994,-176.278015,0.013719,0.000340,0.008630,5.755974,0.293223,0.086296,-176.278015,0.009497,0.000000
57.340004,1.373310,-176.233521,0.013788,0.000363,0.009228,6.108787,0.311196,0.092276,-176.233521,0.010147,0.000000
57.730003,1.433262,-176.189041,0.013775,0.000389,0.009869,6.375466,0.324782,0.098695,-176.189041,0.010798,0.000000
58.120003,1.524121,-176.233521,0.013823,0.000416,0.010555,6.779627,0.345371,0.105553,-176.233521,0.011449,0.000000
58.510002,1.554283,-176.100082,0.013857,0.000439,0.011153,6.913795,0.352205,0.111533,-176.100082,0.012098,0.000000
58.900002,1.677166,-176.100082,0.013935,0.000467,0.011872,7.460405,0.380051,0.118725,-176.100082,0.012749,0.000000
59.290001,1.721850,-176.100082,0.013965,0.000488,0.012384,7.659173,0.390177,0.123842,-176.100082,0.013399,0.000000
59.680004,1.847712,-176.055603,0.013905,0.000517,0.013131,8.219035,0.418698,0.131306,-176.055603,0.014050,0.000000
60.070004,1.907292,-176.055603,0.013965,0.000543,0.013798,8.484057,0.432198,0.137982,-176.055603,0.014701,0.000000
60.460003,1.953838,-176.100082,0.014043,0.000566,0.014380,8.691107,0.442746,0.143796,-176.100082,0.015342,0.000000
60.850002,1.966871,-176.055603,0.013987,0.000588,0.014934,8.749081,0.445699,0.149337,-176.055603,0.015992,0.000000
61.240002,1.969106,-176.011124,0.014043,0.000612,0.015541,8.759019,0.446206,0.155408,-176.011124,0.016643,0.000000
61.630001,1.944529,-175.966644,0.014025,0.000634,0.016105,8.649697,0.440637,0.161055,-175.966644,0.017292,0.000000
62.020004,1.918091,-176.055603,0.014107,0.000671,0.017041,8.532093,0.434646,0.170411,-176.055603,0.017943,0.000000
62.410004,1.841382,-175.966644,0.014120,0.000692,0.017571,8.190875,0.417263,0.175710,-175.966644,0.018594,0.000000
62.800003,1.862607,-175.922165,0.014137,0.000715,0.018160,8.285291,0.422073,0.181599,-175.922165,0.019244,0.000000
63.190002,1.915856,-175.966644,0.014150,0.000743,0.018871,8.522155,0.434139,0.188715,-175.966644,0.019895,0.000000
63.580002,1.906547,-175.833206,0.014146,0.000765,0.019435,8.480745,0.432030,0.194347,-175.833206,0.020544,0.000000
63.970001,1.932241,-175.877686,0.014142,0.000798,0.020258,8.595036,0.437852,0.202583,-175.877686,0.021195,0.000000
64.360001,1.897610,-175.877686,0.014133,0.000821,0.020865,8.440991,0.430005,0.208654,-175.877686,0.021846,0.000000
64.750000,1.892397,-175.833206,0.014211,0.000840,0.021335,8.417802,0.428823,0.213347,-175.833206,0.022496,0.000000
65.139999,1.946018,-175.833206,0.014189,0.000867,0.022019,8.656322,0.440974,0.220190,-175.833206,0.023147,0.000000
65.530006,1.970968,-175.788712,0.014185,0.000896,0.022765,8.767302,0.446628,0.227654,-175.788712,0.023798,0.000000
65.920006,1.988841,-175.788712,0.014228,0.000925,0.023503,8.846807,0.450678,0.235027,-175.788712,0.024447,0.000000
66.310005,1.931496,-175.744232,0.014271,0.000948,0.024075,8.591723,0.437683,0.240750,-175.744232,0.025098,0.000000
66.700005,1.985862,-175.699753,0.014224,0.000974,0.024734,8.833557,0.450003,0.247335,-175.699753,0.025748,0.000000
67.090004,2.001502,-175.744232,0.014297,0.000999,0.025385,8.903126,0.453547,0.253845,-175.744232,0.026399,0.000000
67.480003,2.039856,-175.744232,0.014301,0.001028,0.026104,9.073734,0.462238,0.261037,-175.744232,0.027050,0.000000
67.870003,2.038739,-175.655273,0.014362,0.001054,0.026764,9.068765,0.461985,0.267637,-175.655273,0.027699,0.000000
68.260002,1.985862,-175.610794,0.014370,0.001077,0.027353,8.833557,0.450003,0.273527,-175.610794,0.028350,0.000000
68.650002,2.024589,-175.610794,0.014426,0.001099,0.027916,9.005822,0.458778,0.279159,-175.610794,0.029000,0.000000
69.040001,2.078583,-175.610794,0.014383,0.001128,0.028653,9.246000,0.471014,0.286532,-175.610794,0.029651,0.000000
69.430000,2.094223,-175.610794,0.014370,0.001149,0.029174,9.315568,0.474558,0.291740,-175.610794,0.030293,0.000000
69.820000,2.110235,-175.566315,0.014448,0.001180,0.029963,9.386793,0.478186,0.299627,-175.566315,0.030944,0.000000
70.210007,2.101670,-175.566315,0.014457,0.001204,0.030570,9.348697,0.476245,0.305698,-175.566315,0.031593,0.000000
70.600006,2.128481,-175.477356,0.014478,0.001231,0.031256,9.467956,0.482321,0.312557,-175.477356,0.032244,0.000000
70.990005,2.118055,-175.521835,0.014487,0.001248,0.031707,9.421577,0.479958,0.317068,-175.521835,0.032894,0.000000
71.380005,2.210775,-175.521835,0.014521,0.001286,0.032661,9.834020,0.500969,0.326606,-175.521835,0.033545,0.000000
71.770004,2.137418,-175.477356,0.014573,0.001307,0.033198,9.507710,0.484346,0.331981,-175.477356,0.034196,0.000000
72.160004,2.127736,-175.432877,0.014517,0.001331,0.033796,9.464643,0.482152,0.337961,-175.432877,0.034845,0.000000
72.550003,2.148217,-175.299423,0.014526,0.001358,0.034482,9.555745,0.486793,0.344819,-175.299423,0.035496,0.000000
72.940002,2.183964,-175.388397,0.014633,0.001383,0.035131,9.714759,0.494893,0.351314,-175.388397,0.036147,0.000000
73.330002,2.228277,-175.343903,0.014620,0.001409,0.035799,9.911870,0.504935,0.357991,-175.343903,0.036797,0.000000
73.720001,2.223808,-175.254944,0.014612,0.001438,0.036536,9.891994,0.503922,0.365363,-175.254944,0.037448,0.000000
74.110001,2.192529,-175.343903,0.014681,0.001462,0.037136,9.752857,0.496834,0.371359,-175.343903,0.038097,0.000000
74.500000,2.199976,-175.299423,0.014702,0.001487,0.037776,9.785984,0.498522,0.377763,-175.299423,0.038748,0.000000
74.890007,2.182847,-175.254944,0.014707,0.001511,0.038367,9.709790,0.494640,0.383667,-175.254944,0.039399,0.000000
75.280006,2.197370,-175.254944,0.014754,0.001527,0.038783,9.774390,0.497931,0.387831,-175.254944,0.040049,0.000000
75.670006,2.232001,-175.165985,0.014758,0.001565,0.039763,9.928434,0.505779,0.397626,-175.165985,0.040700,0.000000
76.060005,2.204445,-175.210464,0.014806,0.001591,0.040414,9.805861,0.499534,0.404136,-175.210464,0.041349,0.000000
76.450005,2.231628,-175.165985,0.014806,0.001618,0.041107,9.926778,0.505694,0.411070,-175.165985,0.042000,0.000000
76.840004,2.199976,-175.165985,0.014836,0.001638,0.041610,9.785984,0.498522,0.416096,-175.165985,0.042651,0.000000
77.230003,2.288229,-175.165985,0.014896,0.001669,0.042391,10.178551,0.518520,0.423908,-175.165985,0.043301,0.000000
77.620003,2.249875,-175.077026,0.014935,0.001695,0.043049,10.007942,0.509829,0.430494,-175.077026,0.043952,0.000000
78.010002,2.251736,-175.077026,0.014944,0.001717,0.043605,10.016223,0.510251,0.436050,-175.077026,0.044603,0.000000
78.400002,2.245406,-175.077026,0.014922,0.001744,0.044289,9.988066,0.508816,0.442893,-175.077026,0.045243,0.000000
78.790001,2.248013,-175.077026,0.014948,0.001766,0.044862,9.999660,0.509407,0.448616,-175.077026,0.045894,0.000000
79.180000,2.297166,-175.032547,0.015017,0.001796,0.045608,10.218304,0.520545,0.456080,-175.032547,0.046545,0.000000
79.570007,2.267748,-174.988068,0.015000,0.001821,0.046241,10.087448,0.513879,0.462408,-174.988068,0.047195,0.000000
79.960007,2.246151,-174.988068,0.015043,0.001843,0.046822,9.991378,0.508985,0.468222,-174.988068,0.047846,0.000000
80.350006,2.249875,-174.943573,0.015129,0.001872,0.047550,10.007942,0.509829,0.475504,-174.943573,0.048495,0.000000
80.740005,2.223436,-174.899094,0.015155,0.001890,0.048002,9.890337,0.503838,0.480016,-174.899094,0.049146,0.000000
81.130005,2.282271,-174.943573,0.015090,0.001922,0.048816,10.152048,0.517170,0.488161,-174.943573,0.049797,0.000000
81.520004,2.276685,-174.899094,0.015125,0.001948,0.049467,10.127202,0.515904,0.494671,-174.899094,0.050447,0.000000
81.910004,2.272589,-174.854614,0.015159,0.001971,0.050065,10.108982,0.514976,0.500651,-174.854614,0.051098,0.000000
82.300003,2.301634,-174.810135,0.015246,0.001996,0.050690,10.238181,0.521558,0.506903,-174.810135,0.051749,0.000000
82.690002,2.297910,-174.810135,0.015194,0.002015,0.051175,10.221616,0.520714,0.511748,-174.810135,0.052398,0.000000
83.080002,2.372385,-174.854614,0.015263,0.002050,0.052060,10.552896,0.537590,0.520605,-174.854614,0.053049,0.000000
83.470001,2.300145,-174.721176,0.015250,0.002075,0.052710,10.231554,0.521220,0.527100,-174.721176,0.053699,0.000000
83.860001,2.296049,-174.810135,0.015258,0.002101,0.053378,10.213334,0.520292,0.533776,-174.810135,0.054350,0.000000
84.250008,2.300145,-174.765656,0.015396,0.002120,0.053847,10.231554,0.521220,0.538469,-174.765656,0.055001,0.000000
84.640007,2.320998,-174.721176,0.015349,0.002148,0.054557,10.324313,0.525946,0.545570,-174.721176,0.055650,0.000000
85.030006,2.369034,-174.721176,0.015396,0.002180,0.055373,10.537989,0.536831,0.553730,-174.721176,0.056301,0.000000
85.420006,2.310199,-174.676697,0.015418,0.002201,0.055910,10.276278,0.523499,0.559105,-174.676697,0.056951,0.000000
85.810005,2.283760,-174.676697,0.015461,0.002227,0.056561,10.158673,0.517507,0.565615,-174.676697,0.057602,0.000000
86.200005,2.346691,-174.632217,0.015470,0.002251,0.057185,10.438603,0.531768,0.571852,-174.632217,0.058253,0.000000
86.590004,2.379088,-174.587738,0.015504,0.002277,0.057827,10.582710,0.539109,0.578271,-174.587738,0.058902,0.000000
86.980003,2.356001,-174.587738,0.015461,0.002302,0.058478,10.480015,0.533877,0.584781,-174.587738,0.059553,0.000000
87.370003,2.372757,-174.543259,0.015547,0.002329,0.059153,10.554552,0.537675,0.591534,-174.543259,0.060195,0.000000
87.760002,2.320625,-174.543259,0.015565,0.002354,0.059795,10.322657,0.525861,0.597953,-174.543259,0.060844,0.000000
88.150002,2.386535,-174.498764,0.015586,0.002380,0.060455,10.615839,0.540797,0.604554,-174.498764,0.061495,0.000000
88.540001,2.364938,-174.454285,0.015655,0.002399,0.060932,10.519768,0.535903,0.609323,-174.454285,0.062146,0.000000
88.930008,2.408877,-174.498764,0.015625,0.002430,0.061730,10.715221,0.545859,0.617301,-174.498764,0.062796,0.000000
89.320007,2.408133,-174.409805,0.015629,0.002458,0.062424,10.711909,0.545691,0.624235,-174.409805,0.063447,0.000000
89.710007,2.366799,-174.409805,0.015651,0.002482,0.063047,10.528049,0.536324,0.630473,-174.409805,0.064098,0.000000
90.100006,2.471064,-174.365326,0.015772,0.002509,0.063733,10.991840,0.559951,0.637331,-174.365326,0.064747,0.000000
90.490005,2.446115,-174.320847,0.015685,0.002530,0.064254,10.880862,0.554298,0.642539,-174.320847,0.065398,0.000000
90.880005,2.511652,-174.409805,0.015789,0.002557,0.064947,11.172388,0.569149,0.649473,-174.409805,0.066048,0.000000
91.270004,2.530271,-174.276367,0.015797,0.002587,0.065719,11.255208,0.573368,0.657194,-174.276367,0.066699,0.000000
91.660004,2.500481,-174.320847,0.015806,0.002612,0.066334,11.122696,0.566617,0.663341,-174.320847,0.067350,0.000000
92.050003,2.479628,-174.320847,0.015862,0.002633,0.066890,11.029938,0.561892,0.668897,-174.320847,0.067999,0.000000
92.440002,2.482980,-174.276367,0.015905,0.002653,0.067376,11.044846,0.562651,0.673757,-174.276367,0.068650,0.000000
92.830002,2.594319,-174.320847,0.015944,0.002694,0.068425,11.540107,0.587881,0.684248,-174.320847,0.069300,0.000000
93.220001,2.509046,-174.231888,0.015957,0.002712,0.068876,11.160792,0.568558,0.688760,-174.231888,0.069951,0.000000
93.610008,2.557827,-174.231888,0.015940,0.002739,0.069560,11.377781,0.579612,0.695603,-174.231888,0.070602,0.000000
94.000008,2.589478,-174.231888,0.015983,0.002767,0.070281,11.518574,0.586784,0.702810,-174.231888,0.071251,0.000000
94.390007,2.532505,-174.098450,0.016017,0.002783,0.070697,11.265145,0.573874,0.706973,-174.098450,0.071902,0.000000
94.780006,2.659857,-174.187408,0.016030,0.002819,0.071598,11.831633,0.602732,0.715981,-174.187408,0.072553,0.000000
95.170006,2.603256,-174.142929,0.016017,0.002841,0.072154,11.579860,0.589906,0.721537,-174.142929,0.073203,0.000000
95.560005,2.614427,-174.098450,0.016073,0.002870,0.072891,11.629553,0.592438,0.728910,-174.098450,0.073854,0.000000
95.950005,2.647568,-174.142929,0.016116,0.002893,0.073472,11.776972,0.599948,0.734724,-174.142929,0.074503,0.000000
96.340004,2.624109,-174.009476,0.016172,0.002911,0.073940,11.672619,0.594632,0.739402,-174.009476,0.075145,0.000000
96.730003,2.802475,-174.009476,0.016172,0.002949,0.074903,12.466032,0.635050,0.749031,-174.009476,0.075796,0.000000
97.120003,2.697466,-174.009476,0.016134,0.002973,0.075527,11.998929,0.611255,0.755268,-174.009476,0.076446,0.000000
97.510002,2.706031,-174.009476,0.016241,0.002997,0.076117,12.037026,0.613195,0.761173,-174.009476,0.077097,0.000000
97.900002,2.742896,-173.964996,0.016181,0.003024,0.076802,12.201009,0.621549,0.768016,-173.964996,0.077748,0.000000
98.290001,2.723532,-173.920517,0.016229,0.003039,0.077201,12.114877,0.617161,0.772013,-173.920517,0.078397,0.000000
98.680008,2.875088,-173.876038,0.016272,0.003077,0.078164,12.789029,0.651504,0.781641,-173.876038,0.079048,0.000000
99.070007,2.795773,-173.920517,0.016315,0.003097,0.078667,12.436217,0.633531,0.786668,-173.920517,0.079699,0.000000
99.460007,2.888493,-173.831558,0.016345,0.003126,0.079404,12.848659,0.654542,0.794041,-173.831558,0.080349,0.000000
99.850006,2.922751,-173.876038,0.016358,0.003151,0.080046,13.001048,0.662305,0.800460,-173.876038,0.081000,0.000000
100.240005,2.889610,-173.831558,0.016367,0.003167,0.080435,12.853628,0.654795,0.804351,-173.831558,0.081649,0.000000
100.630005,3.028133,-173.831558,0.016375,0.003208,0.081486,13.469808,0.686185,0.814858,-173.831558,0.082300,0.000000
101.020004,3.020313,-173.787079,0.016388,0.003229,0.082023,13.435023,0.684413,0.820232,-173.787079,0.082951,0.000000
101.410004,3.096649,-173.787079,0.016397,0.003257,0.082726,13.774585,0.701711,0.827257,-173.787079,0.083601,0.000000
101.800003,3.079893,-173.742599,0.016436,0.003278,0.083254,13.700047,0.697914,0.832541,-173.742599,0.084252,0.000000
102.190002,3.159208,-173.653625,0.016461,0.003300,0.083826,14.052859,0.715887,0.838263,-173.653625,0.084901,0.000000
102.580002,3.267568,-173.698120,0.016448,0.003334,0.084685,14.534870,0.740442,0.846848,-173.698120,0.085552,0.000000
102.970001,3.266451,-173.653625,0.016543,0.003354,0.085180,14.529902,0.740188,0.851798,-173.653625,0.086203,0.000000
103.360008,3.351352,-173.520187,0.016556,0.003376,0.085752,14.907559,0.759427,0.857521,-173.520187,0.086853,0.000000
103.750008,3.468277,-173.653625,0.016561,0.003401,0.086376,15.427668,0.785923,0.863758,-173.653625,0.087504,0.000000
104.140007,3.544614,-173.609146,0.016599,0.003420,0.086878,15.767229,0.803221,0.868785,-173.609146,0.088155,0.000000
104.530006,3.774740,-173.564667,0.016595,0.003459,0.087860,16.790880,0.855368,0.878595,-173.564667,0.088804,0.000000
104.920006,3.785911,-173.564667,0.016569,0.003481,0.088414,16.840572,0.857900,0.884136,-173.564667,0.089455,0.000000
105.310005,3.904698,-173.520187,0.016599,0.003503,0.088978,17.368963,0.884817,0.889783,-173.520187,0.090097,0.000000
105.700005,4.213022,-173.564667,0.016621,0.003533,0.089732,18.740459,0.954684,0.897323,-173.564667,0.090747,0.000000
106.090004,4.380589,-173.475708,0.016634,0.003555,0.090295,19.485836,0.992656,0.902955,-173.475708,0.091398,0.000000
106.480003,4.670668,-173.475708,0.016638,0.003585,0.091068,20.776167,1.058388,0.910676,-173.475708,0.092049,0.000000
106.870003,4.856854,-173.475708,0.016690,0.003609,0.091666,21.604366,1.100579,0.916656,-173.475708,0.092698,0.000000
107.260002,5.087353,-173.431229,0.016703,0.003630,0.092205,22.629675,1.152811,0.922046,-173.431229,0.093349,0.000000
107.650002,5.484302,-173.386749,0.016724,0.003658,0.092924,24.395391,1.242760,0.929237,-173.386749,0.093999,0.000000
108.040009,5.806776,-173.342270,0.016720,0.003682,0.093522,25.829830,1.315834,0.935217,-173.342270,0.094650,0.000000
108.430008,6.161275,-173.386749,0.016811,0.003710,0.094242,27.406719,1.396165,0.942424,-173.386749,0.095301,0.000000
108.820007,6.516891,-173.386749,0.016815,0.003737,0.094927,28.988577,1.476748,0.949267,-173.386749,0.095950,0.000000
109.210007,6.885167,-173.297791,0.016871,0.003763,0.095569,30.626753,1.560201,0.955686,-173.297791,0.096601,0.000000
109.600006,7.353984,-173.297791,0.016845,0.003789,0.096245,32.712154,1.666437,0.962453,-173.297791,0.097251,0.000000
109.990005,7.773275,-173.164337,0.016841,0.003814,0.096878,34.577255,1.761449,0.968782,-173.164337,0.097902,0.000000
110.380005,8.134477,-173.253311,0.016858,0.003837,0.097469,36.183960,1.843299,0.974686,-173.253311,0.098553,0.000000
110.770004,8.619306,-173.253311,0.016888,0.003865,0.098171,38.340588,1.953163,0.981711,-173.253311,0.099202,0.000000
111.160004,8.974176,-173.119858,0.016901,0.003889,0.098778,39.919132,2.033577,0.987782,-173.119858,0.099853,0.000000
111.550003,9.601624,-173.119858,0.016996,0.003914,0.099411,42.710155,2.175759,0.994110,-173.119858,0.100504,0.000000
111.940002,10.086452,-173.164337,0.016918,0.003937,0.100009,44.866783,2.285623,1.000090,-173.164337,0.101154,0.000000
112.330002,10.709432,-173.075378,0.017000,0.003967,0.100755,47.637932,2.426792,1.007554,-173.075378,0.101805,0.000000
112.720009,11.210645,-173.075378,0.017069,0.003992,0.101397,49.867439,2.540368,1.013973,-173.075378,0.102454,0.000000
113.110008,11.800483,-173.030899,0.017022,0.004017,0.102038,52.491169,2.674028,1.020377,-173.030899,0.103105,0.000000
113.500008,12.466658,-173.075378,0.017052,0.004045,0.102733,55.454464,2.824985,1.027326,-173.075378,0.103756,0.000000
113.890007,12.797324,-172.986420,0.017147,0.004062,0.103175,56.925343,2.899915,1.031747,-172.986420,0.104406,0.000000
114.280006,13.886141,-172.986420,0.017160,0.004097,0.104059,61.768639,3.146645,1.040589,-172.986420,0.105057,0.000000
114.670006,14.406345,-172.986420,0.017112,0.004119,0.104614,64.082626,3.264524,1.046145,-172.986420,0.105698,0.000000
115.060005,15.114225,-172.941940,0.017173,0.004142,0.105194,67.231430,3.424932,1.051943,-172.941940,0.106348,0.000000
115.450005,15.941637,-172.941940,0.017190,0.004170,0.105924,70.911942,3.612427,1.059241,-172.941940,0.106999,0.000000
115.840004,16.634995,-172.897461,0.017207,0.004192,0.106471,73.996155,3.769544,1.064706,-172.897461,0.107650,0.000000
116.230003,17.843718,-172.897461,0.017233,0.004228,0.107380,79.372818,4.043444,1.073805,-172.897461,0.108299,0.000000
116.620003,18.495741,-172.852982,0.017207,0.004251,0.107988,82.273163,4.191195,1.079876,-172.852982,0.108950,0.000000
117.010002,19.236763,-172.852982,0.017250,0.004276,0.108611,85.569397,4.359113,1.086113,-172.852982,0.109600,0.000000
117.400009,20.015392,-172.852982,0.017281,0.004299,0.109184,89.032913,4.535553,1.091836,-172.852982,0.110251,0.000000
117.790009,20.823069,-172.808502,0.017259,0.004319,0.109695,92.625633,4.718575,1.096953,-172.808502,0.110902,0.000000
118.180008,22.227657,-172.719528,0.017319,0.004356,0.110632,98.873558,5.036859,1.106325,-172.719528,0.111551,0.000000
118.570007,23.036077,-172.764008,0.017393,0.004378,0.111205,102.469589,5.220050,1.112048,-172.764008,0.112202,0.000000
118.960007,23.768162,-172.719528,0.017371,0.004402,0.111821,105.726067,5.385942,1.118209,-172.719528,0.112852,0.000000
119.350006,24.653664,-172.719528,0.017393,0.004426,0.112410,109.664970,5.586600,1.124099,-172.719528,0.113503,0.000000
119.740005,25.440487,-172.675049,0.017380,0.004446,0.112940,113.164940,5.764897,1.129398,-172.675049,0.114154,0.000000
120.130005,27.039082,-172.586090,0.017397,0.004484,0.113894,120.275841,6.127143,1.138935,-172.586090,0.114803,0.000000
120.520004,27.788668,-172.586090,0.017444,0.004504,0.114405,123.610168,6.297002,1.144053,-172.586090,0.115454,0.000000
120.910004,28.963503,-172.630569,0.017483,0.004534,0.115159,128.836090,6.563224,1.151592,-172.630569,0.116105,0.000000
121.300003,29.818842,-172.586090,0.017483,0.004556,0.115731,132.640839,6.757046,1.157315,-172.586090,0.116755,0.000000
121.690002,30.841749,-172.497131,0.017513,0.004580,0.116339,137.190948,6.988840,1.163386,-172.497131,0.117406,0.000000
122.080009,32.261234,-172.497131,0.017578,0.004612,0.117136,143.505142,7.310500,1.171364,-172.497131,0.118055,0.000000
122.470009,33.025341,-172.541611,0.017505,0.004632,0.117657,146.904053,7.483649,1.176572,-172.541611,0.118706,0.000000
122.860008,34.433655,-172.497131,0.017591,0.004662,0.118420,153.168549,7.802777,1.184203,-172.497131,0.119357,0.000000
123.250008,35.038761,-172.452652,0.017578,0.004682,0.118914,155.860199,7.939897,1.189138,-172.452652,0.120007,0.000000
123.640007,36.488407,-172.408173,0.017621,0.004710,0.119644,162.308548,8.268391,1.196436,-172.408173,0.120649,0.000000
124.030006,37.737717,-172.452652,0.017656,0.004738,0.120346,167.865753,8.551489,1.203460,-172.452652,0.121300,0.000000
124.420006,38.680191,-172.408173,0.017600,0.004761,0.120918,172.058090,8.765057,1.209183,-172.408173,0.121949,0.000000
124.810005,39.304287,-172.319199,0.017617,0.004780,0.121412,174.834198,8.906479,1.214119,-172.319199,0.122600,0.000000
125.200005,40.588970,-172.319199,0.017694,0.004805,0.122054,180.548752,9.197592,1.220538,-172.319199,0.123251,0.000000
125.590004,41.535172,-172.274719,0.017690,0.004827,0.122600,184.757675,9.412004,1.226003,-172.274719,0.123901,0.000000
125.980003,43.464432,-172.230240,0.017720,0.004864,0.123545,193.339447,9.849180,1.235450,-172.230240,0.124552,0.000000
126.370003,44.288864,-172.319199,0.017742,0.004885,0.124082,197.006714,10.035999,1.240825,-172.319199,0.125201,0.000000
126.760010,45.193729,-172.185760,0.017776,0.004909,0.124682,201.031754,10.241046,1.246820,-172.185760,0.125852,0.000000
127.150009,46.852276,-172.230240,0.017716,0.004938,0.125436,208.409332,10.616878,1.254360,-172.230240,0.126503,0.000000
127.540009,47.782463,-172.185760,0.017755,0.004960,0.125982,212.547012,10.827661,1.259825,-172.185760,0.127153,0.000000
127.930008,49.349777,-172.141281,0.017742,0.004992,0.126797,219.518768,11.182819,1.267970,-172.141281,0.127804,0.000000
128.320007,50.260227,-172.185760,0.017832,0.005016,0.127397,223.568649,11.389130,1.273965,-172.185760,0.128453,0.000000
128.710007,51.086151,-172.052322,0.017828,0.005033,0.127830,227.242554,11.576288,1.278295,-172.052322,0.129104,0.000000
129.100006,52.663895,-172.141281,0.017824,0.005062,0.128567,234.260696,11.933809,1.285668,-172.141281,0.129755,0.000000
129.490005,53.918415,-172.052322,0.017824,0.005088,0.129225,239.841095,12.218088,1.292254,-172.052322,0.130405,0.000000
129.880005,55.344231,-172.052322,0.017820,0.005114,0.129902,246.183426,12.541183,1.299021,-172.052322,0.131056,0.000000
130.270004,56.530983,-172.007843,0.017893,0.005141,0.130570,251.462372,12.810103,1.305698,-172.007843,0.131707,0.000000
130.660004,57.713264,-172.007843,0.017906,0.005166,0.131212,256.721436,13.078012,1.312117,-172.007843,0.132356,0.000000
131.050003,59.202381,-171.963364,0.017936,0.005193,0.131905,263.345337,13.415452,1.319051,-171.963364,0.133007,0.000000
131.440002,60.571594,-171.918869,0.017940,0.005219,0.132573,269.435913,13.725719,1.325728,-171.918869,0.133657,0.000000
131.830002,61.721107,-171.918869,0.017996,0.005246,0.133249,274.549194,13.986203,1.332495,-171.918869,0.134308,0.000000
132.220001,63.075054,-171.918869,0.017983,0.005270,0.133857,280.571869,14.293012,1.338566,-171.918869,0.134959,0.000000
132.610001,64.338516,-171.918869,0.018022,0.005294,0.134473,286.192017,14.579316,1.344728,-171.918869,0.135601,0.000000
133.000000,65.610168,-171.829910,0.018044,0.005319,0.135097,291.848602,14.867476,1.350965,-171.829910,0.136250,0.000000
133.389999,66.642014,-171.829910,0.018035,0.005337,0.135566,296.438477,15.101296,1.355659,-171.829910,0.136901,0.000000
133.779999,66.951454,-171.785431,0.018014,0.005344,0.135738,297.814941,15.171416,1.357384,-171.785431,0.135982,0.000000
134.170013,66.393265,-171.785431,0.018078,0.005339,0.135601,295.332001,15.044929,1.356007,-171.785431,0.135738,0.000000
134.560013,65.959450,-171.651993,0.018074,0.005338,0.135573,293.402283,14.946625,1.355734,-171.651993,0.135738,0.000000
134.950012,65.627670,-171.740952,0.018061,0.005337,0.135557,291.926453,14.871443,1.355568,-171.740952,0.135738,0.000000
135.340012,65.368500,-171.740952,0.018070,0.005337,0.135557,290.773621,14.812714,1.355568,-171.740952,0.135738,0.000000
135.730011,65.123100,-171.651993,0.018035,0.005337,0.135548,289.682007,14.757106,1.355477,-171.651993,0.135738,0.000000
136.120010,64.920532,-171.740952,0.018091,0.005336,0.135539,288.780945,14.711203,1.355386,-171.740952,0.135738,0.000000
136.510010,64.763016,-171.696472,0.018057,0.005336,0.135531,288.080292,14.675508,1.355310,-171.696472,0.135738,0.000000
136.900009,64.604759,-171.607513,0.018018,0.005336,0.135531,287.376312,14.639647,1.355310,-171.607513,0.135738,0.000000
137.290009,64.469215,-171.607513,0.018044,0.005336,0.135531,286.773407,14.608933,1.355310,-171.607513,0.135738,0.000000
137.680008,64.341118,-171.607513,0.018048,0.005336,0.135531,286.203583,14.579906,1.355310,-171.607513,0.135738,0.000000
138.070007,64.237602,-171.607513,0.018048,0.005336,0.135531,285.743134,14.556449,1.355310,-171.607513,0.135738,0.000000
138.460007,64.122162,-171.474060,0.018078,0.005336,0.135531,285.229614,14.530290,1.355310,-171.474060,0.135738,0.000000
138.850006,64.031303,-171.563034,0.018078,0.005336,0.135531,284.825470,14.509701,1.355310,-171.563034,0.135738,0.000000
139.240005,63.940075,-171.563034,0.018065,0.005336,0.135531,284.419647,14.489028,1.355310,-171.563034,0.135738,0.000000
139.630005,63.859642,-171.385101,0.018082,0.005336,0.135531,284.061890,14.470801,1.355310,-171.385101,0.135738,0.000000
140.020004,63.776234,-171.429581,0.018057,0.005336,0.135531,283.690857,14.451901,1.355310,-171.429581,0.135738,0.000000
140.410004,63.714790,-171.385101,0.018026,0.005336,0.135522,283.417542,14.437978,1.355219,-171.385101,0.135738,0.000000
140.800003,63.641060,-171.340622,0.018070,0.005336,0.135522,283.089569,14.421270,1.355219,-171.340622,0.135738,0.000000
141.190002,63.576641,-171.385101,0.018100,0.005336,0.135522,282.803009,14.406672,1.355219,-171.385101,0.135738,0.000000
141.580002,63.508495,-171.296143,0.018113,0.005336,0.135522,282.499908,14.391232,1.355219,-171.296143,0.135738,0.000000
141.970001,63.454128,-171.296143,0.018065,0.005336,0.135522,282.258057,14.378911,1.355219,-171.296143,0.135738,0.000000
142.360001,63.387848,-171.296143,0.018039,0.005336,0.135522,281.963226,14.363892,1.355219,-171.296143,0.135738,0.000000
142.750000,63.334225,-171.207184,0.018117,0.005336,0.135522,281.724701,14.351740,1.355219,-171.207184,0.135738,0.000000
143.139999,63.295128,-171.296143,0.018044,0.005336,0.135522,281.550781,14.342881,1.355219,-171.296143,0.135738,0.000000
143.530014,63.244484,-171.207184,0.018082,0.005336,0.135522,281.325500,14.331406,1.355219,-171.207184,0.135738,0.000000
143.920013,63.193096,-171.162704,0.018048,0.005336,0.135522,281.096924,14.319760,1.355219,-171.162704,0.135738,0.000000
144.310013,63.150272,-171.207184,0.018044,0.005336,0.135522,280.906433,14.310057,1.355219,-171.207184,0.135738,0.000000
144.700012,63.110432,-171.118225,0.018044,0.005336,0.135522,280.729218,14.301028,1.355219,-171.118225,0.135738,0.000000
145.090012,63.058300,-171.162704,0.018022,0.005336,0.135522,280.497314,14.289215,1.355219,-171.162704,0.135738,0.000000
145.480011,63.023666,-171.118225,0.018091,0.005336,0.135522,280.343262,14.281367,1.355219,-171.118225,0.135738,0.000000
145.870010,62.974888,-171.029251,0.018057,0.005336,0.135522,280.126282,14.270314,1.355219,-171.029251,0.135738,0.000000
146.260010,62.944351,-171.118225,0.018095,0.005336,0.135522,279.990448,14.263393,1.355219,-171.118225,0.135738,0.000000
146.650009,62.905624,-170.984772,0.018065,0.005336,0.135522,279.818207,14.254619,1.355219,-170.984772,0.135738,0.000000
147.040009,62.868389,-171.029251,0.018070,0.005336,0.135522,279.652557,14.246181,1.355219,-171.029251,0.135738,0.000000
147.430008,62.846790,-171.029251,0.018026,0.005336,0.135522,279.556488,14.241286,1.355219,-171.029251,0.135738,0.000000
147.820007,62.815510,-170.895813,0.018108,0.005336,0.135522,279.417328,14.234199,1.355219,-170.895813,0.135738,0.000000
148.210007,62.768967,-170.940292,0.018039,0.005336,0.135522,279.210297,14.223651,1.355219,-170.940292,0.135738,0.000000
148.600006,62.744389,-170.895813,0.018061,0.005336,0.135522,279.100983,14.218081,1.355219,-170.895813,0.135738,0.000000
148.990005,62.717949,-170.895813,0.018087,0.005336,0.135522,278.983368,14.212090,1.355219,-170.895813,0.135738,0.000000
149.380005,62.672150,-170.895813,0.018078,0.005336,0.135522,278.779633,14.201712,1.355219,-170.895813,0.135738,0.000000
149.770004,62.657627,-170.806854,0.018057,0.005336,0.135522,278.715057,14.198421,1.355219,-170.806854,0.135738,0.000000
150.160004,62.623741,-170.851334,0.018061,0.005336,0.135522,278.564301,14.190742,1.355219,-170.851334,0.135738,0.000000
150.550003,62.588737,-170.806854,0.018087,0.005336,0.135522,278.408600,14.182811,1.355219,-170.806854,0.135738,0.000000
150.940002,62.571236,-170.717896,0.018078,0.005336,0.135522,278.330750,14.178844,1.355219,-170.717896,0.135738,0.000000
151.330002,62.537350,-170.717896,0.018057,0.005336,0.135522,278.180023,14.171165,1.355219,-170.717896,0.135738,0.000000
151.720001,62.519474,-170.673416,0.018065,0.005336,0.135522,278.100525,14.167115,1.355219,-170.673416,0.135738,0.000000
152.110001,62.486336,-170.673416,0.018078,0.005336,0.135522,277.953094,14.159606,1.355219,-170.673416,0.135738,0.000000
152.500000,62.472183,-170.628922,0.018100,0.005336,0.135522,277.890137,14.156399,1.355219,-170.628922,0.135738,0.000000
152.890015,62.434948,-170.628922,0.018117,0.005336,0.135522,277.724518,14.147962,1.355219,-170.628922,0.135738,0.000000
153.280014,62.414837,-170.584442,0.018091,0.005336,0.135522,277.635071,14.143404,1.355219,-170.584442,0.135738,0.000000
153.670013,62.393242,-170.539963,0.018044,0.005336,0.135522,277.539001,14.138511,1.355219,-170.539963,0.135738,0.000000
154.060013,62.367546,-170.628922,0.018095,0.005336,0.135522,277.424713,14.132688,1.355219,-170.628922,0.135738,0.000000
154.450012,62.364941,-170.539963,0.018070,0.005336,0.135522,277.413116,14.132098,1.355219,-170.539963,0.135738,0.000000
154.840012,62.325840,-170.451004,0.018082,0.005336,0.135522,277.239197,14.123238,1.355219,-170.451004,0.135738,0.000000
155.230011,62.312065,-170.584442,0.018070,0.005336,0.135522,277.177917,14.120116,1.355219,-170.584442,0.135738,0.000000
155.620010,62.287487,-170.495483,0.018026,0.005336,0.135522,277.068573,14.114547,1.355219,-170.495483,0.135738,0.000000
156.010010,62.259933,-170.451004,0.018078,0.005336,0.135522,276.946014,14.108302,1.355219,-170.451004,0.135738,0.000000
156.400009,62.242058,-170.406525,0.018052,0.005336,0.135522,276.866486,14.104252,1.355219,-170.406525,0.135738,0.000000
156.790009,62.212269,-170.362045,0.018100,0.005336,0.135522,276.733978,14.097502,1.355219,-170.362045,0.135738,0.000000
157.180008,62.207054,-170.362045,0.018061,0.005336,0.135522,276.710785,14.096320,1.355219,-170.362045,0.135738,0.000000
157.570007,62.181732,-170.317566,0.018082,0.005336,0.135522,276.598145,14.090582,1.355219,-170.317566,0.135738,0.000000
157.960007,62.162743,-170.317566,0.018048,0.005336,0.135522,276.513702,14.086279,1.355219,-170.317566,0.135738,0.000000
158.350006,62.146358,-170.273087,0.018065,0.005336,0.135522,276.440796,14.082566,1.355219,-170.273087,0.135738,0.000000
158.740005,62.121780,-170.317566,0.018052,0.005336,0.135522,276.331482,14.076997,1.355219,-170.317566,0.135738,0.000000
159.130005,62.103909,-170.273087,0.018044,0.005336,0.135522,276.251984,14.072947,1.355219,-170.273087,0.135738,0.000000
159.520004,62.098324,-170.184113,0.018100,0.005336,0.135522,276.227142,14.071681,1.355219,-170.184113,0.135738,0.000000
159.910004,62.071884,-170.228607,0.018052,0.005336,0.135522,276.109528,14.065690,1.355219,-170.228607,0.135738,0.000000
160.300003,62.045444,-170.184113,0.018048,0.005336,0.135522,275.991913,14.059698,1.355219,-170.184113,0.135738,0.000000
160.690002,62.040234,-170.139633,0.018095,0.005336,0.135522,275.968750,14.058518,1.355219,-170.139633,0.135738,0.000000
161.080002,62.026455,-170.184113,0.018026,0.005336,0.135522,275.907440,14.055395,1.355219,-170.184113,0.135738,0.000000
161.470001,62.017517,-170.139633,0.018022,0.005336,0.135522,275.867706,14.053370,1.355219,-170.139633,0.135738,0.000000
161.860001,61.978046,-170.095154,0.018052,0.005336,0.135522,275.692108,14.044426,1.355219,-170.095154,0.135738,0.000000
162.250015,61.970600,-170.095154,0.018082,0.005336,0.135522,275.658997,14.042739,1.355219,-170.095154,0.135738,0.000000
162.640015,61.948627,-169.961716,0.018082,0.005336,0.135522,275.561249,14.037760,1.355219,-169.961716,0.135738,0.000000
163.030014,61.940807,-170.050674,0.018095,0.005336,0.135522,275.526459,14.035987,1.355219,-170.050674,0.135738,0.000000
163.420013,61.928894,-170.006195,0.018044,0.005336,0.135522,275.473480,14.033288,1.355219,-170.006195,0.135738,0.000000
163.810013,61.912880,-169.961716,0.018061,0.005336,0.135522,275.402252,14.029658,1.355219,-169.961716,0.135738,0.000000
164.000015,61.910645,-169.961716,0.018095,0.005336,0.135522,275.392303,14.029152,1.355219,-169.961716,0.135738,0.000000