File: Data/New new I18 5 new align_08182023_123735.csv
Time (sec),S:Load (lbs),S:HL1 (DIM),S:LVDT (in),S:Position (in),Ch:Position (mm),Ch:Load (N),Ch:Stress (MPa),Ch:Strain (mm/mm),Ch:HL1 (DIM),Set Point (),Cycles ()
0.110000,-0.000748,-67.210716,-0.000060,-0.000000,-0.000000,-0.003326,-0.000169,-0.000000,-67.210716,0.000198,0.000000
0.490000,0.013771,-67.166237,-0.000009,0.000052,0.001310,0.061257,0.003121,0.013096,-67.166237,0.001917,0.000000
0.870000,0.015266,-67.210716,0.000103,0.000280,0.007102,0.067908,0.003459,0.071020,-67.210716,0.008247,0.000000
1.250000,0.011543,-67.210716,0.000341,0.000529,0.013441,0.051347,0.002616,0.134409,-67.210716,0.014578,0.000000
1.630000,-0.009682,-67.210716,0.000586,0.000771,0.019591,-0.043066,-0.002194,0.195906,-67.210716,0.020908,0.000000
2.010000,-0.011917,-67.166237,0.000858,0.001028,0.026120,-0.053010,-0.002700,0.261203,-67.166237,0.027239,0.000000
2.390000,-0.008942,-67.210716,0.001121,0.001275,0.032391,-0.039774,-0.002026,0.323911,-67.210716,0.033571,0.000000
2.770000,0.009682,-67.210716,0.001371,0.001527,0.038782,0.043066,0.002194,0.387815,-67.210716,0.039900,0.000000
3.150000,0.011909,-67.210716,0.001634,0.001777,0.045148,0.052976,0.002699,0.451477,-67.210716,0.046232,0.000000
3.530000,-0.016014,-67.210716,0.001893,0.002025,0.051426,-0.071234,-0.003629,0.514261,-67.210716,0.052562,0.000000
3.910000,-0.049156,-67.255196,0.002207,0.002274,0.057748,-0.218658,-0.011139,0.577484,-67.255196,0.058893,0.000000
4.290000,0.010796,-67.299683,0.002427,0.002522,0.064071,0.048021,0.002446,0.640707,-67.299683,0.065224,0.000000
4.670000,0.005211,-67.255196,0.002682,0.002772,0.070401,0.023179,0.001181,0.704006,-67.255196,0.071554,0.000000
5.050000,0.022339,-67.299683,0.002949,0.003025,0.076827,0.099368,0.005062,0.768273,-67.299683,0.077886,0.000000
5.430000,0.010796,-67.166237,0.003212,0.003274,0.083150,0.048021,0.002446,0.831496,-67.166237,0.084215,0.000000
5.810000,0.005951,-67.210716,0.003436,0.003523,0.089489,0.026471,0.001348,0.894885,-67.210716,0.090547,0.000000
6.190000,0.006699,-67.210716,0.003712,0.003772,0.095802,0.029797,0.001518,0.958017,-67.210716,0.096877,0.000000
6.570000,0.027176,-67.299683,0.003958,0.004017,0.102029,0.120884,0.006158,1.020287,-67.299683,0.103208,0.000000
6.950000,0.036118,-67.210716,0.004260,0.004270,0.108446,0.160659,0.008184,1.084463,-67.210716,0.109539,0.000000
7.330000,0.033134,-67.255196,0.004501,0.004518,0.114760,0.147389,0.007508,1.147595,-67.255196,0.115869,0.000000
7.710001,0.025688,-67.255196,0.004747,0.004759,0.120891,0.114267,0.005821,1.208911,-67.255196,0.122201,0.000000
8.090000,0.029411,-67.299683,0.005023,0.005012,0.127316,0.130828,0.006665,1.273163,-67.299683,0.128530,0.000000
8.470000,0.053993,-67.255196,0.005312,0.005255,0.133483,0.240174,0.012235,1.334826,-67.255196,0.134862,0.000000
8.850000,0.043938,-67.210716,0.005523,0.005511,0.139987,0.195445,0.009956,1.399866,-67.210716,0.141193,0.000000
9.230000,0.031647,-67.210716,0.005812,0.005755,0.146188,0.140772,0.007171,1.461878,-67.210716,0.147523,0.000000
9.610001,0.030159,-67.255196,0.006062,0.006010,0.152657,0.134154,0.006834,1.526569,-67.255196,0.153854,0.000000
9.990001,0.027550,-67.255196,0.006372,0.006262,0.159049,0.122547,0.006243,1.590489,-67.255196,0.160184,0.000000
10.370001,0.025688,-67.255196,0.006592,0.006513,0.165432,0.114267,0.005821,1.654317,-67.255196,0.166516,0.000000
10.750001,0.032021,-67.255196,0.006885,0.006762,0.171754,0.142435,0.007256,1.717540,-67.255196,0.172847,0.000000
11.130000,0.040955,-67.255196,0.007140,0.007011,0.178084,0.182175,0.009280,1.780838,-67.255196,0.179177,0.000000
11.510000,0.072609,-67.344162,0.007381,0.007261,0.184441,0.322981,0.016453,1.844410,-67.344162,0.185508,0.000000
11.890000,0.139633,-67.299683,0.007653,0.007504,0.190607,0.621119,0.031641,1.906073,-67.299683,0.191838,0.000000
12.270000,0.315399,-67.210716,0.007894,0.007755,0.196964,1.402966,0.071470,1.969644,-67.210716,0.198170,0.000000
12.650001,0.507912,-67.210716,0.008188,0.008006,0.203347,2.259304,0.115094,2.033473,-67.210716,0.204499,0.000000
13.030001,0.584251,-67.344162,0.008494,0.008251,0.209573,2.598880,0.132393,2.095727,-67.344162,0.210831,0.000000
13.410001,0.621117,-67.299683,0.008834,0.008506,0.216043,2.762865,0.140747,2.160433,-67.299683,0.217162,0.000000
13.790001,0.616646,-67.299683,0.009097,0.008753,0.222331,2.742978,0.139734,2.223308,-67.299683,0.223492,0.000000
14.170001,0.580154,-67.299683,0.009408,0.009004,0.228695,2.580656,0.131465,2.286955,-67.299683,0.229823,0.000000
14.550001,0.578293,-67.210716,0.009679,0.009255,0.235078,2.572375,0.131043,2.350783,-67.210716,0.236153,0.000000
14.930000,0.616272,-67.299683,0.009934,0.009504,0.241392,2.741315,0.139649,2.413915,-67.299683,0.242485,0.000000
15.310000,0.566750,-67.299683,0.010231,0.009755,0.247765,2.521028,0.128427,2.477653,-67.299683,0.248816,0.000000
15.690001,0.504562,-67.255196,0.010494,0.010006,0.254157,2.244406,0.114335,2.541572,-67.255196,0.255146,0.000000
16.070002,0.415565,-67.255196,0.010723,0.010254,0.260445,1.848528,0.094168,2.604447,-67.255196,0.261477,0.000000
16.450001,0.353378,-67.255196,0.010977,0.010500,0.266706,1.571905,0.080077,2.667064,-67.255196,0.267807,0.000000
16.830000,0.268105,-67.299683,0.011206,0.010747,0.272985,1.192589,0.060753,2.729848,-67.299683,0.274138,0.000000
17.210001,0.243156,-67.299683,0.011451,0.010993,0.279221,1.081614,0.055100,2.792208,-67.299683,0.280470,0.000000
17.590000,0.206665,-67.299683,0.011697,0.011244,0.285585,0.919292,0.046831,2.855855,-67.299683,0.286800,0.000000
17.970001,0.078941,-67.255196,0.011848,0.011494,0.291943,0.351149,0.017888,2.919426,-67.255196,0.293131,0.000000
18.350000,0.062927,-67.210716,0.012102,0.011740,0.298195,0.279914,0.014260,2.981952,-67.210716,0.299461,0.000000
18.730001,0.062553,-67.299683,0.012352,0.011996,0.304690,0.278251,0.014175,3.046901,-67.299683,0.305792,0.000000
19.110001,0.063301,-67.255196,0.012616,0.012242,0.310943,0.281577,0.014344,3.109427,-67.255196,0.312122,0.000000
19.490002,0.053246,-67.299683,0.012857,0.012494,0.317344,0.236848,0.012066,3.173438,-67.299683,0.318453,0.000000
19.870001,0.056595,-67.166237,0.013146,0.012744,0.323692,0.251746,0.012825,3.236918,-67.166237,0.324785,0.000000
20.250002,0.047287,-67.210716,0.013366,0.012992,0.329996,0.210343,0.010715,3.299959,-67.210716,0.331115,0.000000
20.630001,0.051010,-67.299683,0.013663,0.013242,0.336336,0.226904,0.011559,3.363364,-67.299683,0.337446,0.000000
21.010000,0.046173,-67.210716,0.013909,0.013490,0.342640,0.205388,0.010463,3.426405,-67.210716,0.343776,0.000000
21.390001,0.071121,-67.255196,0.014224,0.013742,0.349049,0.316363,0.016116,3.490491,-67.255196,0.350107,0.000000
21.770000,0.080429,-67.299683,0.014482,0.013989,0.355327,0.357766,0.018225,3.553275,-67.299683,0.356439,0.000000
22.150002,0.144104,-67.255196,0.014763,0.014238,0.361641,0.641007,0.032654,3.616407,-67.255196,0.362769,0.000000
22.530001,0.192886,-67.299683,0.015043,0.014484,0.367902,0.858001,0.043709,3.679024,-67.299683,0.369100,0.000000
22.910002,0.276299,-67.255196,0.015353,0.014736,0.374303,1.229037,0.062610,3.743034,-67.255196,0.375430,0.000000
23.290001,0.470673,-67.210716,0.015603,0.014988,0.380694,2.093656,0.106656,3.806938,-67.210716,0.381761,0.000000
23.670002,0.527649,-67.255196,0.015789,0.000008,0.000198,2.347100,0.119567,0.001983,-67.255196,0.000416,0.000000
24.050001,0.507164,-67.255196,0.015776,0.000008,0.000198,2.255978,0.114925,0.001983,-67.255196,0.000433,0.000000
24.430000,0.577171,-67.255196,0.015802,0.000008,0.000207,2.567386,0.130789,0.002074,-67.255196,0.001066,0.000000
24.810001,0.677711,-67.255196,0.015797,0.000031,0.000798,3.014611,0.153572,0.007979,-67.255196,0.001699,0.000000
25.190001,0.654625,-67.255196,0.015823,0.000041,0.001040,2.911917,0.148340,0.010401,-67.255196,0.002333,0.000000
25.570002,0.762985,-67.255196,0.015871,0.000081,0.002054,3.393928,0.172895,0.020544,-67.255196,0.002966,0.000000
25.950001,0.764481,-67.255196,0.015862,0.000104,0.002636,3.400579,0.173234,0.026358,-67.255196,0.003599,0.000000
26.330002,0.774529,-67.210716,0.015927,0.000125,0.003182,3.445275,0.175511,0.031823,-67.210716,0.004232,0.000000
26.710001,0.844910,-67.166237,0.015948,0.000156,0.003954,3.758346,0.191459,0.039545,-67.166237,0.004864,0.000000
27.090002,0.929436,-67.210716,0.015974,0.000183,0.004639,4.134336,0.210613,0.046388,-67.210716,0.005497,0.000000
27.470001,0.951408,-67.255196,0.015966,0.000207,0.005264,4.232076,0.215592,0.052640,-67.255196,0.006130,0.000000
27.850000,0.984924,-67.210716,0.016043,0.000228,0.005783,4.381162,0.223187,0.057833,-67.210716,0.006764,0.000000
28.230001,0.995720,-67.210716,0.016082,0.000252,0.006409,4.429183,0.225633,0.064086,-67.210716,0.007405,0.000000
28.610001,1.085091,-67.210716,0.016091,0.000279,0.007085,4.826724,0.245885,0.070853,-67.210716,0.008039,0.000000
28.990002,1.084717,-67.210716,0.016069,0.000294,0.007467,4.825061,0.245800,0.074668,-67.210716,0.008672,0.000000
29.370001,1.242973,-67.210716,0.016125,0.000333,0.008463,5.529021,0.281662,0.084630,-67.210716,0.009305,0.000000
29.750002,1.278351,-67.166237,0.016181,0.000356,0.009035,5.686388,0.289678,0.090353,-67.166237,0.009938,0.000000
30.130001,1.319313,-67.166237,0.016181,0.000378,0.009608,5.868598,0.298961,0.096076,-67.166237,0.010570,0.000000
30.510002,1.379639,-67.166237,0.016216,0.000402,0.010207,6.136940,0.312631,0.102071,-67.166237,0.011203,0.000000
30.890001,1.413895,-67.255196,0.016233,0.000420,0.010666,6.289318,0.320393,0.106658,-67.255196,0.011838,0.000000
31.270002,1.513687,-67.210716,0.016272,0.000449,0.011412,6.733217,0.343006,0.114122,-67.210716,0.012470,0.000000
31.650002,1.581459,-67.166237,0.016302,0.000477,0.012124,7.034681,0.358364,0.121238,-67.166237,0.013103,0.000000
32.030003,1.646629,-67.166237,0.016306,0.000499,0.012678,7.324573,0.373132,0.126779,-67.166237,0.013736,0.000000
32.410000,1.719986,-67.210716,0.016379,0.000529,0.013424,7.650880,0.389754,0.134243,-67.210716,0.014369,0.000000
32.790001,1.794830,-67.299683,0.016384,0.000546,0.013875,7.983804,0.406714,0.138754,-67.299683,0.015002,0.000000
33.170002,1.907661,-67.255196,0.016414,0.000577,0.014664,8.485702,0.432282,0.146642,-67.255196,0.015636,0.000000
33.550003,1.974686,-67.210716,0.016431,0.000603,0.015306,8.783840,0.447470,0.153061,-67.210716,0.016269,0.000000
33.930000,2.048042,-67.166237,0.016470,0.000627,0.015913,9.110147,0.464093,0.159132,-67.166237,0.016902,0.000000
34.310001,2.144493,-67.166237,0.016522,0.000653,0.016590,9.539182,0.485949,0.165900,-67.166237,0.017535,0.000000
34.690002,2.211891,-67.210716,0.016535,0.000671,0.017041,9.838984,0.501222,0.170411,-67.210716,0.018167,0.000000
35.070004,2.360840,-67.210716,0.016543,0.000702,0.017821,10.501540,0.534974,0.178208,-67.210716,0.018800,0.000000
35.450001,2.425629,-67.166237,0.016565,0.000728,0.018488,10.789735,0.549655,0.184885,-67.166237,0.019435,0.000000
35.830002,2.495636,-67.166237,0.016595,0.000748,0.019009,11.101143,0.565519,0.190093,-67.166237,0.020068,0.000000
36.210003,2.639374,-67.210716,0.016621,0.000774,0.019659,11.740520,0.598091,0.196587,-67.210716,0.020700,0.000000
36.590000,2.698952,-67.210716,0.016668,0.000795,0.020189,12.005537,0.611591,0.201886,-67.210716,0.021333,0.000000
36.970001,2.866150,-67.210716,0.016690,0.000821,0.020847,12.749271,0.649479,0.208472,-67.210716,0.021966,0.000000
37.350002,2.947327,-67.121758,0.016716,0.000852,0.021645,13.110364,0.667874,0.216451,-67.121758,0.022599,0.000000
37.730003,3.010628,-67.121758,0.016729,0.000872,0.022140,13.391941,0.682218,0.221401,-67.121758,0.023232,0.000000
38.110001,3.164787,-67.166237,0.016772,0.000901,0.022885,14.077677,0.717151,0.228850,-67.166237,0.023866,0.000000
38.490002,3.308525,-67.166237,0.016780,0.000925,0.023492,14.717054,0.749722,0.234921,-67.166237,0.024499,0.000000
38.870003,3.405716,-67.166237,0.016815,0.000947,0.024048,15.149381,0.771746,0.240477,-67.166237,0.025141,0.000000
39.250000,3.530457,-67.166237,0.016832,0.000976,0.024802,15.704255,0.800013,0.248017,-67.166237,0.025774,0.000000
39.630001,3.602699,-67.166237,0.016910,0.001001,0.025427,16.025606,0.816383,0.254269,-67.166237,0.026406,0.000000
40.010002,3.720367,-67.255196,0.016931,0.001021,0.025930,16.549021,0.843047,0.259296,-67.255196,0.027039,0.000000
40.390003,3.921448,-67.166237,0.016927,0.001050,0.026676,17.443470,0.888613,0.266759,-67.166237,0.027672,0.000000
40.770000,3.907303,-67.166237,0.016962,0.001065,0.027048,17.380550,0.885408,0.270484,-67.166237,0.028305,0.000000
41.150002,4.169075,-67.166237,0.016992,0.001100,0.027933,18.544971,0.944726,0.279325,-67.166237,0.028939,0.000000
41.530003,4.216743,-67.166237,0.017039,0.001119,0.028435,18.757011,0.955528,0.284352,-67.166237,0.029572,0.000000
41.910004,4.335159,-67.121758,0.017043,0.001145,0.029077,19.283752,0.982361,0.290771,-67.121758,0.030205,0.000000
42.290001,4.566025,-67.121758,0.017069,0.001175,0.029840,20.310692,1.034676,0.298401,-67.121758,0.030838,0.000000
42.670002,4.645340,-67.077271,0.017052,0.001194,0.030326,20.663504,1.052649,0.303261,-67.077271,0.031471,0.000000
43.050003,4.860947,-67.210716,0.017151,0.001226,0.031150,21.622570,1.101506,0.311497,-67.210716,0.032103,0.000000
43.430000,4.891853,-67.121758,0.017121,0.001249,0.031714,21.760050,1.108510,0.317144,-67.121758,0.032738,0.000000
43.810001,5.043037,-67.121758,0.017160,0.001274,0.032356,22.432550,1.142769,0.323563,-67.121758,0.033371,0.000000
44.190002,5.284706,-67.166237,0.017194,0.001300,0.033024,23.507547,1.197532,0.330240,-67.166237,0.034003,0.000000
44.570004,5.279121,-67.121758,0.017220,0.001313,0.033362,23.482704,1.196266,0.333616,-67.121758,0.034636,0.000000
44.950001,5.510361,-67.077271,0.017237,0.001347,0.034220,24.511309,1.248666,0.342200,-67.077271,0.035269,0.000000
45.330002,5.598244,-67.166237,0.017237,0.001371,0.034818,24.902231,1.268580,0.348180,-67.166237,0.035902,0.000000
45.710003,5.720009,-67.166237,0.017315,0.001396,0.035452,25.443871,1.296173,0.354524,-67.166237,0.036536,0.000000
46.090004,5.887207,-67.077271,0.017289,0.001423,0.036146,26.187605,1.334060,0.361457,-67.077271,0.037169,0.000000
46.470001,5.928169,-67.077271,0.017354,0.001438,0.036527,26.369814,1.343342,0.365273,-67.077271,0.037802,0.000000
46.850002,6.171700,-67.166237,0.017375,0.001468,0.037281,27.453091,1.398527,0.372812,-67.166237,0.038435,0.000000
47.230003,6.252876,-67.166237,0.017406,0.001495,0.037967,27.814182,1.416922,0.379670,-67.166237,0.039068,0.000000
47.610001,6.406662,-67.121758,0.017423,0.001518,0.038556,28.498257,1.451770,0.385560,-67.121758,0.039701,0.000000
47.990002,6.536621,-67.077271,0.017444,0.001547,0.039293,29.076344,1.481219,0.392933,-67.077271,0.040333,0.000000
48.370003,6.622269,-67.121758,0.017470,0.001569,0.039849,29.457323,1.500628,0.398489,-67.121758,0.040968,0.000000
48.750004,6.850159,-67.121758,0.017505,0.001600,0.040629,30.471027,1.552268,0.406286,-67.121758,0.041601,0.000000
49.130001,6.898567,-67.121758,0.017548,0.001621,0.041175,30.686359,1.563238,0.411751,-67.121758,0.042233,0.000000
49.510002,7.081779,-67.077271,0.017556,0.001650,0.041912,31.501328,1.604754,0.419124,-67.077271,0.042866,0.000000
49.890003,7.188278,-67.032791,0.017591,0.001673,0.042485,31.975058,1.628887,0.424847,-67.032791,0.043508,0.000000
50.270004,7.257538,-67.077271,0.017625,0.001691,0.042945,32.283142,1.644582,0.429449,-67.077271,0.044141,0.000000
50.650002,7.535324,-67.121758,0.017621,0.001720,0.043699,33.518795,1.707529,0.436989,-67.121758,0.044774,0.000000
51.030003,7.536812,-67.077271,0.017634,0.001747,0.044385,33.525414,1.707866,0.443847,-67.077271,0.045407,0.000000
51.410004,7.692093,-67.121758,0.017669,0.001775,0.045078,34.216137,1.743053,0.450781,-67.121758,0.046041,0.000000
51.790001,7.836578,-67.121758,0.017699,0.001799,0.045685,34.858841,1.775794,0.456852,-67.121758,0.046674,0.000000
52.170002,7.881256,-67.077271,0.017725,0.001817,0.046153,35.057579,1.785918,0.461530,-67.077271,0.047307,0.000000
52.550003,8.100586,-67.121758,0.017776,0.001843,0.046821,36.033207,1.835619,0.468207,-67.121758,0.047939,0.000000
52.930004,8.249161,-67.121758,0.017772,0.001873,0.047584,36.694099,1.869287,0.475837,-67.121758,0.048572,0.000000
53.310001,8.292358,-67.077271,0.017811,0.001895,0.048121,36.886253,1.879075,0.481212,-67.077271,0.049205,0.000000
53.690002,8.463280,-67.077271,0.017828,0.001921,0.048789,37.646549,1.917807,0.487888,-67.077271,0.049839,0.000000
54.070004,8.492699,-67.077271,0.017845,0.001940,0.049267,37.777409,1.924473,0.492672,-67.077271,0.050472,0.000000
54.450001,8.839371,-67.166237,0.017884,0.001975,0.050177,39.319485,2.003030,0.501771,-67.166237,0.051105,0.000000
54.830002,8.896721,-67.121758,0.017914,0.001999,0.050768,39.574593,2.016026,0.507676,-67.121758,0.051738,0.000000
55.210003,9.000984,-67.032791,0.017936,0.002022,0.051356,40.038376,2.039652,0.513565,-67.032791,0.052371,0.000000
55.590004,9.138016,-67.032791,0.017936,0.002050,0.052076,40.647923,2.070704,0.520756,-67.032791,0.053004,0.000000
55.970001,9.192757,-67.077271,0.017966,0.002069,0.052554,40.891422,2.083108,0.525540,-67.077271,0.053638,0.000000
56.350002,9.369629,-67.121758,0.018001,0.002095,0.053204,41.678192,2.123188,0.532035,-67.121758,0.054271,0.000000
56.730003,9.532730,-67.077271,0.018014,0.002124,0.053950,42.403702,2.160147,0.539499,-67.077271,0.054904,0.000000
57.110004,9.530495,-67.032791,0.018035,0.002146,0.054504,42.393757,2.159641,0.545040,-67.032791,0.055537,0.000000
57.490002,9.734558,-67.077271,0.018087,0.002171,0.055138,43.301476,2.205883,0.551383,-67.077271,0.056169,0.000000
57.870003,9.864143,-67.077271,0.018087,0.002194,0.055727,43.877903,2.235247,0.557273,-67.077271,0.056802,0.000000
58.250004,10.049583,-67.077271,0.018087,0.002218,0.056343,44.702778,2.277268,0.563435,-67.077271,0.057435,0.000000
58.630001,10.211937,-66.988312,0.018143,0.002250,0.057158,45.424965,2.314058,0.571580,-66.988312,0.058069,0.000000
59.010002,10.211937,-67.032791,0.018177,0.002270,0.057653,45.424965,2.314058,0.576530,-67.032791,0.058702,0.000000
59.390003,10.302055,-67.077271,0.018199,0.002290,0.058172,45.825832,2.334479,0.581723,-67.077271,0.059335,0.000000
59.770004,10.599953,-67.121758,0.018203,0.002322,0.058988,47.150944,2.401984,0.589883,-67.121758,0.059968,0.000000
60.150002,10.589523,-67.077271,0.018238,0.002337,0.059352,47.104553,2.399620,0.593517,-67.077271,0.060601,0.000000
60.530003,10.883324,-67.032791,0.018264,0.002372,0.060245,48.411442,2.466197,0.602449,-67.032791,0.061234,0.000000
60.910004,10.917213,-67.032791,0.018302,0.002392,0.060749,48.562191,2.473876,0.607491,-67.032791,0.061875,0.000000
61.290005,10.987961,-66.988312,0.018333,0.002413,0.061287,48.876892,2.489908,0.612865,-66.988312,0.062508,0.000000
61.670002,11.284370,-67.032791,0.018354,0.002443,0.062040,50.195385,2.557075,0.620405,-67.032791,0.063143,0.000000
62.050003,11.320862,-67.121758,0.018358,0.002464,0.062587,50.357708,2.565344,0.625870,-67.121758,0.063775,0.000000
62.430004,11.639984,-67.077271,0.018376,0.002497,0.063429,51.777237,2.637658,0.634288,-67.077271,0.064408,0.000000
62.810001,11.681694,-67.077271,0.018436,0.002518,0.063948,51.962769,2.647110,0.639481,-67.077271,0.065041,0.000000
63.190002,11.745743,-67.032791,0.018453,0.002541,0.064548,52.247673,2.661623,0.645476,-67.032791,0.065674,0.000000
63.570004,12.041779,-67.077271,0.018483,0.002572,0.065318,53.564507,2.728706,0.653182,-67.077271,0.066307,0.000000
63.950005,12.079018,-66.988312,0.018501,0.002589,0.065753,53.730152,2.737144,0.657527,-66.988312,0.066941,0.000000
64.330002,12.283821,-66.988312,0.018522,0.002617,0.066464,54.641167,2.783554,0.664643,-66.988312,0.067574,0.000000
64.710007,12.371696,-67.032791,0.018509,0.002641,0.067079,55.032055,2.803467,0.670789,-67.032791,0.068207,0.000000
65.090004,12.508736,-67.077271,0.018561,0.002667,0.067739,55.641636,2.834520,0.677390,-67.077271,0.068840,0.000000
65.470001,12.823387,-66.988312,0.018565,0.002694,0.068423,57.041275,2.905821,0.684233,-66.988312,0.069472,0.000000
65.850006,12.822639,-67.077271,0.018604,0.002712,0.068874,57.037949,2.905652,0.688745,-67.077271,0.070105,0.000000
66.230003,13.134315,-66.943832,0.018665,0.002741,0.069621,58.424355,2.976278,0.696209,-66.943832,0.070740,0.000000
66.610001,13.241188,-66.988312,0.018634,0.002767,0.070270,58.899746,3.000496,0.702704,-66.988312,0.071373,0.000000
66.990005,13.311943,-66.988312,0.018682,0.002788,0.070826,59.214481,3.016530,0.708260,-66.988312,0.072005,0.000000
67.370003,13.593079,-67.121758,0.018716,0.002819,0.071615,60.465034,3.080235,0.716148,-67.121758,0.072638,0.000000
67.750000,13.584892,-67.032791,0.018751,0.002835,0.072005,60.428619,3.078381,0.720054,-67.032791,0.073271,0.000000
68.130005,13.910713,-66.988312,0.018738,0.002862,0.072699,61.877941,3.152213,0.726987,-66.988312,0.073904,0.000000
68.510002,14.078651,-66.943832,0.018785,0.002892,0.073445,62.624969,3.190268,0.734451,-66.943832,0.074538,0.000000
68.890007,14.136375,-66.988312,0.018803,0.002913,0.073999,62.881737,3.203348,0.739992,-66.988312,0.075171,0.000000
69.270004,14.406715,-67.032791,0.018833,0.002943,0.074755,64.084274,3.264608,0.747547,-67.032791,0.075804,0.000000
69.650002,14.459221,-66.943832,0.018815,0.002963,0.075248,64.317825,3.276506,0.752483,-66.943832,0.076437,0.000000
70.030006,14.802917,-66.988312,0.018906,0.002995,0.076072,65.846664,3.354389,0.760718,-66.988312,0.077070,0.000000
70.410004,14.899361,-67.032791,0.018906,0.003019,0.076688,66.275665,3.376243,0.766880,-67.032791,0.077702,0.000000
70.790001,14.946655,-67.032791,0.018949,0.003039,0.077200,66.486046,3.386961,0.771997,-67.032791,0.078335,0.000000
71.170006,15.191307,-67.032791,0.018936,0.003068,0.077937,67.574310,3.442400,0.779370,-67.032791,0.078970,0.000000
71.550003,15.296310,-66.943832,0.018949,0.003089,0.078465,68.041389,3.466194,0.784654,-66.943832,0.079602,0.000000
71.930000,15.562561,-67.032791,0.018997,0.003115,0.079126,69.225731,3.526527,0.791255,-67.032791,0.080244,0.000000
72.310005,15.717468,-66.988312,0.019057,0.003143,0.079836,69.914787,3.561629,0.798355,-66.988312,0.080877,0.000000
72.690002,15.766617,-66.988312,0.019053,0.003165,0.080391,70.133415,3.572767,0.803912,-66.988312,0.081510,0.000000
73.070000,15.946106,-67.032791,0.019066,0.003187,0.080947,70.931824,3.613439,0.809468,-67.032791,0.082143,0.000000
73.450005,16.147552,-66.899353,0.019091,0.003214,0.081640,71.827904,3.659088,0.816402,-66.899353,0.082776,0.000000
73.830002,16.356461,-66.943832,0.019126,0.003238,0.082256,72.757172,3.706427,0.822564,-66.943832,0.083408,0.000000
74.210007,16.691963,-66.988312,0.019156,0.003272,0.083097,74.249557,3.782453,0.830966,-66.988312,0.084043,0.000000
74.590004,16.707977,-66.943832,0.019135,0.003291,0.083592,74.320793,3.786082,0.835917,-66.943832,0.084676,0.000000
74.970001,16.973480,-66.943832,0.019178,0.003317,0.084259,75.501808,3.846246,0.842593,-66.943832,0.085308,0.000000
75.350006,17.064713,-66.943832,0.019264,0.003338,0.084788,75.907631,3.866919,0.847877,-66.943832,0.085941,0.000000
75.730003,17.440063,-66.899353,0.019221,0.003371,0.085629,77.577278,3.951975,0.856295,-66.899353,0.086574,0.000000
76.110001,17.548424,-66.988312,0.019264,0.003395,0.086227,78.059288,3.976530,0.862275,-66.988312,0.087207,0.000000
76.490005,17.737587,-66.988312,0.019316,0.003418,0.086818,78.900726,4.019395,0.868179,-66.988312,0.087841,0.000000
76.870003,17.965851,-66.988312,0.019320,0.003446,0.087537,79.916100,4.071120,0.875371,-66.988312,0.088474,0.000000
77.250000,18.016121,-66.988312,0.019372,0.003466,0.088049,80.139709,4.082511,0.880488,-66.988312,0.089107,0.000000
77.630005,18.246994,-66.988312,0.019350,0.003490,0.088656,81.166679,4.134828,0.886559,-66.988312,0.089740,0.000000
78.010002,18.561272,-66.988312,0.019385,0.003521,0.089445,82.564659,4.206045,0.894446,-66.988312,0.090373,0.000000
78.390007,18.477859,-66.988312,0.019380,0.003541,0.089931,82.193626,4.187143,0.899306,-66.988312,0.091006,0.000000
78.770004,18.629791,-66.943832,0.019419,0.003560,0.090417,82.869453,4.221571,0.904166,-66.943832,0.091640,0.000000
79.150002,18.976097,-66.943832,0.019471,0.003589,0.091154,84.409897,4.300045,0.911539,-66.943832,0.092273,0.000000
79.530006,18.981308,-66.943832,0.019501,0.003605,0.091578,84.433075,4.301226,0.915778,-66.943832,0.092906,0.000000
79.910004,19.537262,-66.943832,0.019561,0.003647,0.092628,86.906082,4.427207,0.926285,-66.943832,0.093538,0.000000
80.290001,19.489601,-66.899353,0.019535,0.003665,0.093087,86.694077,4.416407,0.930872,-66.899353,0.094171,0.000000
80.670006,19.636314,-66.899353,0.019535,0.003686,0.093625,87.346687,4.449652,0.936247,-66.899353,0.094804,0.000000
81.050003,20.001984,-66.899353,0.019613,0.003715,0.094362,88.973267,4.532514,0.943620,-66.899353,0.095437,0.000000
81.430000,19.949104,-66.943832,0.019574,0.003735,0.094857,88.738045,4.520532,0.948570,-66.943832,0.096071,0.000000
81.810005,20.404518,-66.943832,0.019613,0.003767,0.095672,90.763832,4.623730,0.956715,-66.943832,0.096704,0.000000
82.190002,20.502823,-66.943832,0.019665,0.003790,0.096270,91.201111,4.646006,0.962696,-66.943832,0.097337,0.000000
82.570007,20.617142,-66.899353,0.019648,0.003811,0.096799,91.709625,4.671911,0.967994,-66.899353,0.097979,0.000000
82.950005,20.931427,-66.899353,0.019717,0.003838,0.097493,93.107635,4.743129,0.974928,-66.899353,0.098612,0.000000
83.330002,20.969780,-66.899353,0.019734,0.003857,0.097970,93.278236,4.751820,0.979697,-66.899353,0.099244,0.000000
83.710007,21.501152,-66.899353,0.019738,0.003895,0.098933,95.641899,4.872231,0.989326,-66.899353,0.099877,0.000000
84.090004,21.573395,-66.899353,0.019790,0.003916,0.099461,95.963249,4.888601,0.994610,-66.899353,0.100510,0.000000
84.470001,21.608025,-66.854866,0.019803,0.003938,0.100026,96.117294,4.896448,1.000257,-66.854866,0.101145,0.000000
84.850006,22.045189,-66.899353,0.019824,0.003966,0.100736,98.061897,4.995512,1.007357,-66.899353,0.101777,0.000000
85.230003,22.126740,-66.899353,0.019842,0.003986,0.101240,98.424652,5.013991,1.012399,-66.899353,0.102410,0.000000
85.610001,22.389259,-66.899353,0.019867,0.004013,0.101933,99.592400,5.073479,1.019333,-66.899353,0.103043,0.000000
85.990005,22.573212,-66.854866,0.019889,0.004039,0.102592,100.410660,5.115163,1.025918,-66.854866,0.103676,0.000000
86.370003,22.617897,-66.854866,0.019915,0.004062,0.103173,100.609428,5.125288,1.031732,-66.854866,0.104309,0.000000
86.750008,22.841324,-66.899353,0.019915,0.004086,0.103789,101.603287,5.175918,1.037894,-66.899353,0.104943,0.000000
87.130005,23.126930,-66.854866,0.019984,0.004108,0.104353,102.873726,5.240637,1.043526,-66.854866,0.105576,0.000000
87.510002,23.542130,-66.899353,0.020010,0.004138,0.105116,104.720619,5.334723,1.051156,-66.899353,0.106209,0.000000
87.890007,23.697037,-66.854866,0.020036,0.004164,0.105774,105.409683,5.369825,1.057742,-66.854866,0.106842,0.000000
88.270004,23.821411,-66.810387,0.020018,0.004187,0.106348,105.962929,5.398009,1.063480,-66.810387,0.107474,0.000000
88.650002,24.144630,-66.810387,0.020049,0.004217,0.107102,107.400681,5.471251,1.071019,-66.810387,0.108107,0.000000
89.030006,24.142395,-66.899353,0.020044,0.004233,0.107527,107.390739,5.470745,1.075274,-66.899353,0.108742,0.000000
89.410004,24.512901,-66.899353,0.020109,0.004258,0.108160,109.038834,5.554703,1.081602,-66.899353,0.109374,0.000000
89.790001,24.816383,-66.899353,0.020118,0.004289,0.108949,110.388786,5.623473,1.089490,-66.899353,0.110007,0.000000
90.170006,24.870750,-66.854866,0.020152,0.004310,0.109470,110.630623,5.635793,1.094698,-66.854866,0.110640,0.000000
90.550003,25.319466,-66.854866,0.020174,0.004342,0.110275,112.626610,5.737473,1.102752,-66.854866,0.111273,0.000000
90.930008,25.361168,-66.810387,0.020217,0.004361,0.110770,112.812111,5.746923,1.107702,-66.810387,0.111906,0.000000
91.310005,25.672096,-66.854866,0.020217,0.004391,0.111524,114.195190,5.817380,1.115242,-66.854866,0.112539,0.000000
91.690002,25.894035,-66.854866,0.020268,0.004417,0.112192,115.182419,5.867672,1.121919,-66.854866,0.113173,0.000000
92.070007,26.004997,-66.765907,0.020264,0.004437,0.112696,115.676003,5.892817,1.126960,-66.765907,0.113806,0.000000
92.450005,26.331940,-66.810387,0.020273,0.004465,0.113398,117.130318,5.966903,1.133985,-66.810387,0.114439,0.000000
92.830002,26.444771,-66.854866,0.020312,0.004485,0.113927,117.632217,5.992471,1.139269,-66.854866,0.115071,0.000000
93.210007,26.721817,-66.899353,0.020342,0.004509,0.114525,118.864578,6.055250,1.145249,-66.899353,0.115704,0.000000
93.590004,27.071472,-66.854866,0.020385,0.004541,0.115341,120.419922,6.134483,1.153409,-66.854866,0.116346,0.000000
93.970001,27.113182,-66.765907,0.020372,0.004563,0.115895,120.605461,6.143935,1.158950,-66.765907,0.116979,0.000000
94.350006,27.349266,-66.854866,0.020385,0.004585,0.116467,121.655609,6.197433,1.164673,-66.854866,0.117612,0.000000
94.730003,27.553696,-66.854866,0.020428,0.004610,0.117102,122.564957,6.243757,1.171016,-66.854866,0.118246,0.000000
95.110008,27.625938,-66.810387,0.020419,0.004628,0.117544,122.886314,6.260127,1.175437,-66.810387,0.118879,0.000000
95.490005,28.331581,-66.810387,0.020484,0.004668,0.118567,126.025169,6.420028,1.185671,-66.810387,0.119512,0.000000
95.870003,28.353928,-66.810387,0.020527,0.004687,0.119044,126.124573,6.425092,1.190440,-66.810387,0.120145,0.000000
96.250008,28.726295,-66.765907,0.020549,0.004715,0.119763,127.780945,6.509471,1.197632,-66.765907,0.120778,0.000000
96.630005,28.803749,-66.854866,0.020544,0.004736,0.120301,128.125473,6.527023,1.203006,-66.854866,0.121410,0.000000
97.010002,29.247993,-66.810387,0.020587,0.004764,0.121003,130.101578,6.627690,1.210031,-66.810387,0.122045,0.000000
97.390007,29.435669,-66.810387,0.020570,0.004791,0.121689,130.936401,6.670218,1.216889,-66.810387,0.122678,0.000000
97.770004,29.754791,-66.765907,0.020600,0.004817,0.122357,132.355927,6.742532,1.223566,-66.765907,0.123310,0.000000
98.150002,29.927940,-66.765907,0.020648,0.004842,0.122998,133.126129,6.781768,1.229985,-66.765907,0.123943,0.000000
98.530006,29.921616,-66.810387,0.020669,0.004857,0.123371,133.097992,6.780335,1.233709,-66.810387,0.124576,0.000000
98.910004,30.214294,-66.810387,0.020678,0.004882,0.123995,134.399887,6.846657,1.239947,-66.810387,0.125209,0.000000
99.290001,30.817169,-66.765907,0.020725,0.004917,0.124888,137.081619,6.983270,1.248879,-66.765907,0.125843,0.000000
99.670006,30.775467,-66.765907,0.020704,0.004935,0.125348,136.896118,6.973820,1.253482,-66.765907,0.126476,0.000000
100.050003,30.997398,-66.721428,0.020725,0.004956,0.125877,137.883316,7.024111,1.258765,-66.721428,0.127109,0.000000
100.430008,31.389877,-66.810387,0.020743,0.004986,0.126649,139.629150,7.113048,1.266486,-66.810387,0.127742,0.000000
100.810005,31.493027,-66.765907,0.020794,0.005003,0.127074,140.087982,7.136422,1.270741,-66.765907,0.128375,0.000000
101.190002,32.126801,-66.765907,0.020816,0.005041,0.128037,142.907150,7.280037,1.280369,-66.765907,0.129007,0.000000
101.570007,32.147659,-66.765907,0.020825,0.005061,0.128556,142.999924,7.284764,1.285562,-66.765907,0.129642,0.000000
101.950005,32.419113,-66.765907,0.020876,0.005084,0.129138,144.207413,7.346276,1.291376,-66.765907,0.130275,0.000000
102.330002,32.798935,-66.721428,0.020898,0.005112,0.129849,145.896942,7.432345,1.298491,-66.721428,0.130907,0.000000
102.710007,32.747551,-66.765907,0.020885,0.005129,0.130282,145.668381,7.420701,1.302821,-66.765907,0.131540,0.000000
103.090004,33.493408,-66.721428,0.020919,0.005163,0.131150,148.986115,7.589715,1.311496,-66.721428,0.132173,0.000000
103.470001,33.582779,-66.721428,0.020958,0.005188,0.131782,149.383667,7.609967,1.317825,-66.721428,0.132806,0.000000
103.850006,33.716835,-66.810387,0.020958,0.005210,0.132321,149.979965,7.640344,1.323214,-66.810387,0.133439,0.000000
104.230003,34.101868,-66.721428,0.020993,0.005233,0.132919,151.692688,7.727594,1.329195,-66.721428,0.134073,0.000000
104.610008,34.196823,-66.721428,0.021001,0.005255,0.133483,152.115067,7.749111,1.334826,-66.721428,0.134715,0.000000
104.990005,34.852943,-66.721428,0.021032,0.005290,0.134359,155.033630,7.897790,1.343592,-66.721428,0.135348,0.000000
105.370003,34.959816,-66.721428,0.021083,0.005314,0.134983,155.509033,7.922008,1.349830,-66.721428,0.135981,0.000000
105.750008,35.128868,-66.765907,0.021075,0.005333,0.135469,156.261017,7.960315,1.354690,-66.765907,0.136614,0.000000
106.130005,35.617050,-66.721428,0.021113,0.005363,0.136232,158.432556,8.070939,1.362320,-66.721428,0.137246,0.000000
106.510002,35.770470,-66.632462,0.021109,0.005384,0.136760,159.114990,8.105704,1.367604,-66.632462,0.137879,0.000000
106.890007,36.051979,-66.676949,0.021161,0.005409,0.137386,160.367218,8.169496,1.373856,-66.676949,0.138512,0.000000
107.270004,36.422493,-66.721428,0.021200,0.005436,0.138070,162.015335,8.253454,1.380699,-66.721428,0.139146,0.000000
107.650002,36.600113,-66.765907,0.021217,0.005458,0.138626,162.805435,8.293705,1.386256,-66.765907,0.139779,0.000000
108.030006,36.752411,-66.676949,0.021243,0.005479,0.139172,163.482895,8.328216,1.391721,-66.676949,0.140412,0.000000
108.410004,37.195168,-66.632462,0.021234,0.005506,0.139849,165.452362,8.428545,1.398488,-66.632462,0.141045,0.000000
108.790009,37.632706,-66.632462,0.021247,0.005530,0.140473,167.398636,8.527694,1.404726,-66.632462,0.141678,0.000000
109.170006,38.045662,-66.632462,0.021295,0.005559,0.141201,169.235550,8.621270,1.412008,-66.632462,0.142311,0.000000
109.550003,38.060188,-66.721428,0.021295,0.005581,0.141766,169.300171,8.624561,1.417655,-66.721428,0.142945,0.000000
109.930008,38.806046,-66.676949,0.021338,0.005614,0.142597,172.617905,8.793575,1.425967,-66.676949,0.143578,0.000000
110.310005,38.540176,-66.632462,0.021355,0.005627,0.142927,171.435272,8.733329,1.429267,-66.632462,0.144211,0.000000
110.690002,39.217148,-66.632462,0.021364,0.005657,0.143681,174.446579,8.886733,1.436807,-66.632462,0.144843,0.000000
111.070007,39.551910,-66.676949,0.021433,0.005684,0.144366,175.935684,8.962591,1.443665,-66.676949,0.145476,0.000000
111.450005,39.547066,-66.676949,0.021402,0.005704,0.144869,175.914139,8.961493,1.448691,-66.676949,0.146109,0.000000
111.830002,40.267235,-66.587982,0.021433,0.005736,0.145685,179.117599,9.124686,1.456851,-66.587982,0.146743,0.000000
112.210007,40.427361,-66.587982,0.021480,0.005758,0.146248,179.829880,9.160971,1.462483,-66.587982,0.147376,0.000000
112.590004,40.823563,-66.632462,0.021437,0.005782,0.146865,181.592270,9.250751,1.468645,-66.632462,0.148009,0.000000
112.970009,41.274132,-66.676949,0.021523,0.005811,0.147609,183.596512,9.352852,1.476094,-66.676949,0.148642,0.000000
113.350006,41.468513,-66.632462,0.021566,0.005834,0.148191,184.461166,9.396899,1.481907,-66.632462,0.149275,0.000000
113.730003,41.728424,-66.632462,0.021545,0.005860,0.148849,185.617294,9.455796,1.488493,-66.632462,0.149908,0.000000
114.110008,42.038239,-66.632462,0.021605,0.005881,0.149370,186.995422,9.526001,1.493701,-66.632462,0.150540,0.000000
114.490005,42.162239,-66.632462,0.021562,0.005899,0.149847,187.547012,9.554100,1.498470,-66.632462,0.151175,0.000000
114.870003,43.044022,-66.632462,0.021640,0.005935,0.150749,191.469376,9.753915,1.507493,-66.632462,0.151808,0.000000
115.250008,43.292763,-66.632462,0.021631,0.005958,0.151338,192.575821,9.810281,1.513383,-66.632462,0.152440,0.000000
115.630005,43.614868,-66.632462,0.021665,0.005983,0.151964,194.008621,9.883270,1.519635,-66.632462,0.153082,0.000000
116.010002,43.912766,-66.632462,0.021708,0.006005,0.152519,195.333740,9.950775,1.525192,-66.632462,0.153715,0.000000
116.390007,44.038254,-66.587982,0.021734,0.006024,0.153004,195.891937,9.979211,1.530036,-66.587982,0.154348,0.000000
116.770004,45.013496,-66.587982,0.021739,0.006060,0.153923,200.230026,10.200204,1.539226,-66.587982,0.154981,0.000000
117.150009,45.077545,-66.587982,0.021777,0.006083,0.154496,200.514938,10.214718,1.544964,-66.587982,0.155614,0.000000
117.530006,45.632004,-66.587982,0.021812,0.006109,0.155172,202.981293,10.340360,1.551716,-66.587982,0.156248,0.000000
117.910004,45.836067,-66.587982,0.021808,0.006129,0.155676,203.889008,10.386600,1.556758,-66.587982,0.156881,0.000000
118.290009,46.282913,-66.632462,0.021846,0.006153,0.156274,205.876678,10.487858,1.562738,-66.632462,0.157514,0.000000
118.670006,46.952065,-66.632462,0.021855,0.006185,0.157106,208.853210,10.639490,1.571064,-66.632462,0.158147,0.000000
119.050003,47.117401,-66.587982,0.021855,0.006206,0.157635,209.588669,10.676956,1.576348,-66.587982,0.158779,0.000000
119.430008,47.854698,-66.587982,0.021920,0.006236,0.158389,212.868332,10.844029,1.583888,-66.587982,0.159412,0.000000
119.810005,48.051308,-66.587982,0.021911,0.006256,0.158893,213.742889,10.888582,1.588929,-66.587982,0.160047,0.000000
120.190002,48.458687,-66.587982,0.021954,0.006277,0.159439,215.555008,10.980896,1.594395,-66.587982,0.160679,0.000000
120.570007,49.223541,-66.587982,0.021946,0.006309,0.160245,218.957245,11.154214,1.602449,-66.587982,0.161312,0.000000
120.950005,49.513618,-66.587982,0.022006,0.006332,0.160835,220.247574,11.219947,1.608353,-66.587982,0.161945,0.000000
121.330009,49.999939,-66.543503,0.022028,0.006354,0.161389,222.410843,11.330149,1.613894,-66.543503,0.162578,0.000000
121.710007,50.629616,-66.587982,0.022058,0.006379,0.162031,225.211777,11.472835,1.620314,-66.587982,0.163211,0.000000
122.090004,51.007576,-66.543503,0.022045,0.006400,0.162552,226.893036,11.558482,1.625522,-66.543503,0.163845,0.000000
122.470009,52.155975,-66.499023,0.022084,0.006435,0.163436,232.001358,11.818713,1.634363,-66.499023,0.164478,0.000000
122.850006,52.272896,-66.543503,0.022097,0.006454,0.163940,232.521454,11.845207,1.639405,-66.543503,0.165111,0.000000
123.230003,52.977425,-66.543503,0.022114,0.006480,0.164599,235.655350,12.004856,1.645990,-66.543503,0.165744,0.000000
123.610008,53.428368,-66.543503,0.022105,0.006503,0.165180,237.661255,12.107040,1.651804,-66.543503,0.166376,0.000000
123.990005,54.025284,-66.543503,0.022118,0.006525,0.165734,240.316467,12.242305,1.657345,-66.543503,0.167009,0.000000
124.370003,54.761093,-66.632462,0.022153,0.006552,0.166411,243.589508,12.409041,1.664112,-66.632462,0.167642,0.000000
124.750008,55.538979,-66.499023,0.022183,0.006578,0.167088,247.049713,12.585313,1.670880,-66.499023,0.168276,0.000000
125.130005,56.051361,-66.499023,0.022191,0.006606,0.167781,249.328903,12.701420,1.677814,-66.499023,0.168909,0.000000
125.510010,56.782700,-66.587982,0.022260,0.006628,0.168363,252.582062,12.867144,1.683627,-66.587982,0.169542,0.000000
125.890007,57.676765,-66.543503,0.022260,0.006652,0.168961,256.559052,13.069742,1.689607,-66.543503,0.170175,0.000000
126.270004,58.473640,-66.499023,0.022252,0.006678,0.169612,260.103729,13.250317,1.696117,-66.499023,0.170817,0.000000
126.650009,59.421333,-66.454544,0.022273,0.006707,0.170366,264.319305,13.465067,1.703657,-66.454544,0.171450,0.000000
127.030006,59.814186,-66.454544,0.022316,0.006728,0.170886,266.066803,13.554088,1.708865,-66.454544,0.172083,0.000000
127.410004,60.846771,-66.499023,0.022325,0.006755,0.171589,270.659943,13.788075,1.715890,-66.499023,0.172715,0.000000
127.790009,61.450386,-66.499023,0.022329,0.006776,0.172117,273.344971,13.924857,1.721173,-66.499023,0.173350,0.000000
128.170013,62.333282,-66.454544,0.022351,0.006801,0.172750,277.272278,14.124924,1.727502,-66.454544,0.173983,0.000000
128.550003,63.639572,-66.454544,0.022390,0.006830,0.173487,283.082947,14.420933,1.734875,-66.454544,0.174615,0.000000
128.930008,64.417084,-66.499023,0.022411,0.006853,0.174078,286.541504,14.597119,1.740779,-66.499023,0.175248,0.000000
129.310013,65.107452,-66.454544,0.022420,0.006875,0.174615,289.612427,14.753560,1.746154,-66.454544,0.175881,0.000000
129.690002,66.134842,-66.454544,0.022433,0.006899,0.175239,294.182465,14.986369,1.752391,-66.454544,0.176514,0.000000
130.070007,66.884796,-66.454544,0.022429,0.006921,0.175786,297.518433,15.156312,1.757857,-66.454544,0.177148,0.000000
130.450012,66.755951,-66.454544,0.022493,0.006917,0.175690,296.945312,15.127114,1.756903,-66.454544,0.175995,0.000000
130.830002,66.248032,-66.499023,0.022467,0.006908,0.175474,294.685974,15.012018,1.754738,-66.499023,0.175690,0.000000
131.210007,65.866348,-66.499023,0.022510,0.006908,0.175474,292.988159,14.925528,1.754738,-66.499023,0.175690,0.000000
131.590012,65.542023,-66.454544,0.022506,0.006908,0.175474,291.545471,14.852035,1.754738,-66.454544,0.175690,0.000000
131.970001,65.301086,-66.410057,0.022502,0.006908,0.175474,290.473755,14.797438,1.754738,-66.410057,0.175690,0.000000
132.350006,65.060165,-66.454544,0.022476,0.006908,0.175474,289.402069,14.742845,1.754738,-66.454544,0.175690,0.000000
132.730011,64.872864,-66.410057,0.022472,0.006908,0.175474,288.568909,14.700401,1.754738,-66.410057,0.175690,0.000000
133.110001,64.686310,-66.499023,0.022476,0.006908,0.175465,287.739075,14.658128,1.754647,-66.499023,0.175690,0.000000
133.490005,64.521713,-66.410057,0.022459,0.006908,0.175465,287.006927,14.620829,1.754647,-66.410057,0.175690,0.000000
133.870010,64.386917,-66.410057,0.022528,0.006908,0.175465,286.407318,14.590283,1.754647,-66.410057,0.175690,0.000000
134.250000,64.278183,-66.410057,0.022493,0.006908,0.175465,285.923645,14.565645,1.754647,-66.410057,0.175690,0.000000
134.630005,64.144882,-66.499023,0.022510,0.006908,0.175465,285.330688,14.535438,1.754647,-66.499023,0.175690,0.000000
135.010010,64.050659,-66.454544,0.022476,0.006908,0.175465,284.911560,14.514087,1.754647,-66.454544,0.175690,0.000000
135.389999,63.926300,-66.321098,0.022497,0.006908,0.175465,284.358398,14.485908,1.754647,-66.321098,0.175690,0.000000
135.770004,63.845490,-66.410057,0.022506,0.006908,0.175465,283.998932,14.467595,1.754647,-66.410057,0.175690,0.000000
136.150009,63.751648,-66.410057,0.022480,0.006908,0.175465,283.581482,14.446330,1.754647,-66.410057,0.175690,0.000000
136.530014,63.671585,-66.499023,0.022489,0.006908,0.175465,283.225342,14.428187,1.754647,-66.499023,0.175690,0.000000
136.910004,63.599350,-66.454544,0.022510,0.006908,0.175465,282.904053,14.411819,1.754647,-66.454544,0.175690,0.000000
137.290009,63.530838,-66.410057,0.022485,0.006908,0.175465,282.599274,14.396295,1.754647,-66.410057,0.175690,0.000000
137.670013,63.451523,-66.410057,0.022506,0.006908,0.175465,282.246460,14.378321,1.754647,-66.410057,0.175690,0.000000
138.050003,63.381516,-66.410057,0.022489,0.006908,0.175465,281.935059,14.362457,1.754647,-66.410057,0.175690,0.000000
138.430008,63.323425,-66.365578,0.022510,0.006908,0.175465,281.676666,14.349294,1.754647,-66.365578,0.175690,0.000000
138.810013,63.249695,-66.365578,0.022515,0.006908,0.175465,281.348694,14.332585,1.754647,-66.365578,0.175690,0.000000
139.190002,63.205750,-66.321098,0.022523,0.006908,0.175465,281.153229,14.322627,1.754647,-66.321098,0.175690,0.000000
139.570007,63.172989,-66.410057,0.022493,0.006908,0.175465,281.007477,14.315204,1.754647,-66.410057,0.175690,0.000000
139.950012,63.100372,-66.410057,0.022497,0.006908,0.175465,280.684479,14.298748,1.754647,-66.410057,0.175690,0.000000
140.330002,63.039673,-66.365578,0.022510,0.006908,0.175465,280.414459,14.284994,1.754647,-66.365578,0.175690,0.000000
140.710007,63.009140,-66.321098,0.022497,0.006908,0.175465,280.278656,14.278075,1.754647,-66.321098,0.175690,0.000000
141.090012,62.951424,-66.365578,0.022493,0.006908,0.175465,280.021912,14.264997,1.754647,-66.365578,0.175690,0.000000
141.470001,62.900406,-66.410057,0.022519,0.006908,0.175465,279.794983,14.253435,1.754647,-66.410057,0.175690,0.000000
141.850006,62.858330,-66.410057,0.022515,0.006908,0.175465,279.607819,14.243901,1.754647,-66.410057,0.175690,0.000000
142.230011,62.831894,-66.365578,0.022493,0.006908,0.175465,279.490234,14.237910,1.754647,-66.365578,0.175690,0.000000
142.610001,62.789810,-66.321098,0.022485,0.006908,0.175465,279.303040,14.228374,1.754647,-66.321098,0.175690,0.000000
142.990005,62.748856,-66.365578,0.022485,0.006908,0.175465,279.120850,14.219093,1.754647,-66.365578,0.175690,0.000000
143.370010,62.704910,-66.365578,0.022489,0.006908,0.175465,278.925385,14.209135,1.754647,-66.365578,0.175690,0.000000
143.750000,62.682571,-66.410057,0.022467,0.006908,0.175465,278.825989,14.204073,1.754647,-66.410057,0.175690,0.000000
144.130005,62.636024,-66.321098,0.022502,0.006908,0.175465,278.618958,14.193526,1.754647,-66.321098,0.175690,0.000000
144.510010,62.598412,-66.276619,0.022506,0.006908,0.175465,278.451630,14.185003,1.754647,-66.276619,0.175690,0.000000
144.889999,62.574585,-66.321098,0.022497,0.006908,0.175465,278.345642,14.179604,1.754647,-66.321098,0.175690,0.000000
145.270004,62.535858,-66.321098,0.022506,0.006908,0.175465,278.173401,14.170828,1.754647,-66.321098,0.175690,0.000000
145.650009,62.508301,-66.321098,0.022502,0.006908,0.175465,278.050812,14.164583,1.754647,-66.321098,0.175690,0.000000
146.030014,62.466591,-66.321098,0.022493,0.006908,0.175465,277.865265,14.155131,1.754647,-66.321098,0.175690,0.000000
146.410004,62.451324,-66.232140,0.022489,0.006908,0.175465,277.797363,14.151672,1.754647,-66.232140,0.175690,0.000000
146.790009,62.415581,-66.365578,0.022493,0.006908,0.175465,277.638367,14.143573,1.754647,-66.365578,0.175690,0.000000
147.170013,62.367912,-66.321098,0.022489,0.006908,0.175465,277.426331,14.132771,1.754647,-66.321098,0.175690,0.000000
147.550003,62.363449,-66.276619,0.022519,0.006908,0.175465,277.406464,14.131760,1.754647,-66.276619,0.175690,0.000000
147.930008,62.332909,-66.276619,0.022502,0.006908,0.175465,277.270630,14.124839,1.754647,-66.276619,0.175690,0.000000
148.310013,62.307594,-66.321098,0.022541,0.006908,0.175465,277.158020,14.119103,1.754647,-66.321098,0.175690,0.000000
148.690002,62.284500,-66.276619,0.022528,0.006908,0.175465,277.055298,14.113870,1.754647,-66.276619,0.175690,0.000000
149.070007,62.249870,-66.276619,0.022497,0.006908,0.175465,276.901245,14.106022,1.754647,-66.276619,0.175690,0.000000
149.450012,62.228279,-66.232140,0.022506,0.006908,0.175465,276.805206,14.101130,1.754647,-66.232140,0.175690,0.000000
149.830002,62.197739,-66.276619,0.022485,0.006908,0.175465,276.669373,14.094209,1.754647,-66.276619,0.175690,0.000000
150.210007,62.178375,-66.232140,0.022515,0.006908,0.175465,276.583221,14.089822,1.754647,-66.232140,0.175690,0.000000
150.590012,62.150826,-66.276619,0.022519,0.006908,0.175465,276.460693,14.083578,1.754647,-66.276619,0.175690,0.000000
150.970001,62.122520,-66.232140,0.022506,0.006908,0.175465,276.334778,14.077165,1.754647,-66.232140,0.175690,0.000000
151.350006,62.105019,-66.276619,0.022506,0.006908,0.175465,276.256927,14.073198,1.754647,-66.276619,0.175690,0.000000
151.730011,62.064430,-66.232140,0.022515,0.006908,0.175465,276.076385,14.064001,1.754647,-66.232140,0.175690,0.000000
152.110001,62.067413,-66.321098,0.022480,0.006908,0.175465,276.089630,14.064677,1.754647,-66.321098,0.175690,0.000000
152.490005,62.047302,-66.276619,0.022485,0.006908,0.175465,276.000183,14.060120,1.754647,-66.276619,0.175690,0.000000
152.870010,62.004105,-66.232140,0.022497,0.006908,0.175465,275.808044,14.050331,1.754647,-66.232140,0.175690,0.000000
153.250000,61.991447,-66.276619,0.022506,0.006908,0.175465,275.751740,14.047462,1.754647,-66.276619,0.175690,0.000000
153.630005,61.978783,-66.187653,0.022541,0.006908,0.175465,275.695404,14.044593,1.754647,-66.187653,0.175690,0.000000
154.010010,61.952721,-66.276619,0.022493,0.006908,0.175465,275.579468,14.038688,1.754647,-66.276619,0.175690,0.000000
154.390015,61.925163,-66.276619,0.022493,0.006908,0.175465,275.456879,14.032442,1.754647,-66.276619,0.175690,0.000000
154.770004,61.922928,-66.187653,0.022493,0.006908,0.175465,275.446930,14.031936,1.754647,-66.187653,0.175690,0.000000
155.150009,61.907288,-66.187653,0.022497,0.006908,0.175465,275.377380,14.028392,1.754647,-66.187653,0.175690,0.000000
155.530014,61.884949,-66.187653,0.022489,0.006908,0.175465,275.278015,14.023330,1.754647,-66.187653,0.175690,0.000000
155.910004,61.863350,-66.232140,0.022523,0.006908,0.175465,275.181915,14.018435,1.754647,-66.232140,0.175690,0.000000
156.290009,61.841751,-66.187653,0.022497,0.006908,0.175465,275.085846,14.013541,1.754647,-66.187653,0.175690,0.000000
156.670013,61.822014,-66.187653,0.022519,0.006908,0.175465,274.998047,14.009068,1.754647,-66.187653,0.175690,0.000000
157.050003,61.804886,-66.187653,0.022515,0.006908,0.175465,274.921875,14.005187,1.754647,-66.187653,0.175690,0.000000
157.430008,61.797440,-66.232140,0.022532,0.006908,0.175465,274.888733,14.003500,1.754647,-66.232140,0.175690,0.000000
157.810013,61.774353,-66.187653,0.022536,0.006908,0.175465,274.786041,13.998268,1.754647,-66.187653,0.175690,0.000000
158.190002,61.746056,-66.232140,0.022506,0.006908,0.175465,274.660187,13.991857,1.754647,-66.232140,0.175690,0.000000
158.570007,61.733765,-66.143173,0.022519,0.006908,0.175465,274.605499,13.989071,1.754647,-66.143173,0.175690,0.000000
158.950012,61.725571,-66.098694,0.022510,0.006908,0.175465,274.569061,13.987215,1.754647,-66.098694,0.175690,0.000000
159.330002,61.702484,-66.143173,0.022528,0.006908,0.175465,274.466370,13.981982,1.754647,-66.143173,0.175690,0.000000
159.710007,61.676422,-66.187653,0.022472,0.006908,0.175465,274.350433,13.976077,1.754647,-66.187653,0.175690,0.000000
160.090012,61.695412,-66.143173,0.022493,0.006908,0.175465,274.434906,13.980380,1.754647,-66.143173,0.175690,0.000000
160.470001,61.661896,-66.187653,0.022467,0.006908,0.175465,274.285797,13.972785,1.754647,-66.187653,0.175690,0.000000
160.600006,61.656311,-66.143173,0.022489,0.006908,0.175465,274.260956,13.971519,1.754647,-66.143173,0.175690,0.000000