File: Data/New pin I-18-2_08172023_170006.csv
Time (sec),S:Load (lbs),S:HL1 (DIM),S:LVDT (in),S:Position (in),Ch:Position (mm),Ch:Load (N),Ch:Stress (MPa),Ch:Strain (mm/mm),Ch:HL1 (DIM),Set Point (),Cycles ()
0.010000,-0.007075,-135.222092,0.000022,-0.000000,-0.000000,-0.031472,-0.001603,-0.000000,-135.222092,-0.000000,0.000000
0.230000,0.002979,-135.177612,-0.000013,-0.000000,-0.000000,0.013251,0.000675,-0.000000,-135.177612,-0.000000,0.000000
0.450000,0.013405,-135.177612,0.000017,0.000056,0.001422,0.059630,0.003038,0.014216,-135.177612,0.001908,0.000000
0.670000,0.015640,-135.177612,0.000030,0.000173,0.004397,0.069568,0.003544,0.043965,-135.177612,0.005567,0.000000
0.890000,0.042078,-135.133133,0.000229,0.000325,0.008247,0.187173,0.009535,0.082465,-135.133133,0.009244,0.000000
1.110000,0.051387,-135.133133,0.000332,0.000466,0.011845,0.228582,0.011645,0.118452,-135.133133,0.012903,0.000000
1.330000,0.029045,-135.133133,0.000535,0.000609,0.015480,0.129199,0.006582,0.154802,-135.133133,0.016564,0.000000
1.550000,0.024949,-135.177612,0.000711,0.000747,0.018974,0.110978,0.005654,0.189744,-135.177612,0.020223,0.000000
1.770000,0.049525,-135.177612,0.000880,0.000901,0.022894,0.220300,0.011223,0.228941,-135.177612,0.023901,0.000000
1.990000,0.083784,-135.044174,0.001018,0.001035,0.026285,0.372689,0.018986,0.262853,-135.044174,0.027560,0.000000
2.210000,0.071495,-135.088654,0.001147,0.001180,0.029979,0.318028,0.016201,0.299794,-135.088654,0.031219,0.000000
2.430000,0.058090,-135.088654,0.001341,0.001335,0.033899,0.258398,0.013163,0.338990,-135.088654,0.034897,0.000000
2.650000,0.043940,-135.177612,0.001522,0.001480,0.037593,0.195455,0.009957,0.375931,-135.177612,0.038556,0.000000
2.870000,0.048781,-135.133133,0.001669,0.001619,0.041133,0.216988,0.011054,0.411327,-135.133133,0.042217,0.000000
3.090000,0.032396,-135.088654,0.001819,0.001766,0.044853,0.144106,0.007341,0.448525,-135.088654,0.045893,0.000000
3.310000,0.046174,-135.133133,0.001962,0.001909,0.048477,0.205393,0.010463,0.484769,-135.133133,0.049553,0.000000
3.530000,0.043195,-135.088654,0.002134,0.002053,0.052138,0.192142,0.009788,0.521377,-135.088654,0.053213,0.000000
3.750000,0.034258,-135.133133,0.002302,0.002199,0.055848,0.152388,0.007763,0.558484,-135.133133,0.056890,0.000000
3.970000,0.029045,-135.088654,0.002445,0.002343,0.059517,0.129199,0.006582,0.595167,-135.088654,0.060549,0.000000
4.190000,0.064048,-135.088654,0.002604,0.002487,0.063159,0.284900,0.014513,0.631593,-135.088654,0.064208,0.000000
4.410000,0.024577,-135.088654,0.002772,0.002629,0.066767,0.109322,0.005569,0.667671,-135.088654,0.067886,0.000000
4.630000,0.020853,-135.088654,0.002902,0.002775,0.070496,0.092758,0.004725,0.704959,-135.088654,0.071545,0.000000
4.850000,0.037610,-135.133133,0.003083,0.002921,0.074190,0.167296,0.008522,0.741900,-135.133133,0.075206,0.000000
5.070000,0.052877,-135.133133,0.003212,0.003065,0.077842,0.235208,0.011982,0.778417,-135.133133,0.078882,0.000000
5.290000,0.062186,-135.044174,0.003410,0.003206,0.081440,0.276618,0.014092,0.814403,-135.044174,0.082543,0.000000
5.510000,0.051387,-135.088654,0.003527,0.003347,0.085006,0.228582,0.011645,0.850057,-135.088654,0.086202,0.000000
5.730000,0.039099,-134.999680,0.003643,0.003498,0.088847,0.173921,0.008860,0.888466,-134.999680,0.089861,0.000000
5.950000,-0.015267,-135.044174,0.003691,0.003639,0.092438,-0.067912,-0.003460,0.924377,-135.044174,0.093538,0.000000
6.170000,-0.028300,-135.088654,0.003794,0.003783,0.096079,-0.125886,-0.006413,0.960788,-135.088654,0.097198,0.000000
6.390000,0.023459,-135.044174,0.003967,0.003929,0.099791,0.104353,0.005316,0.997910,-135.044174,0.100858,0.000000
6.610000,0.020108,-135.044174,0.004126,0.004076,0.103529,0.089445,0.004557,1.035290,-135.044174,0.104534,0.000000
6.830000,0.024204,-134.999680,0.004255,0.004212,0.106997,0.107666,0.005485,1.069975,-134.999680,0.108195,0.000000
7.050000,0.030907,-134.999680,0.004467,0.004352,0.110545,0.137481,0.007004,1.105447,-134.999680,0.111854,0.000000
7.270000,0.030907,-135.088654,0.004609,0.004509,0.114517,0.137481,0.007004,1.145173,-135.088654,0.115532,0.000000
7.490000,0.028673,-134.999680,0.004751,0.004653,0.118186,0.127542,0.006497,1.181856,-134.999680,0.119191,0.000000
7.710001,-0.016384,-134.910721,0.004928,0.004794,0.121775,-0.072882,-0.003713,1.217752,-134.910721,0.122850,0.000000
7.930000,-0.010799,-134.999680,0.005066,0.004935,0.125348,-0.048036,-0.002447,1.253482,-134.999680,0.126528,0.000000
8.150001,0.023832,-134.999680,0.005204,0.005086,0.129172,0.106009,0.005400,1.291724,-134.999680,0.130187,0.000000
8.370001,0.055483,-134.999680,0.005372,0.005225,0.132720,0.246803,0.012573,1.327196,-134.999680,0.133848,0.000000
8.590000,0.068144,-134.999680,0.005562,0.005367,0.136327,0.303120,0.015442,1.363274,-134.999680,0.137525,0.000000
8.810000,0.063676,-134.955200,0.005708,0.005518,0.140152,0.283243,0.014429,1.401516,-134.955200,0.141184,0.000000
9.030001,0.063676,-134.910721,0.005868,0.005663,0.143846,0.283243,0.014429,1.438457,-134.910721,0.144843,0.000000
9.250000,0.046547,-134.955200,0.005989,0.005807,0.147488,0.207049,0.010548,1.474883,-134.955200,0.148503,0.000000
9.470000,0.041333,-135.044174,0.006131,0.005948,0.151070,0.183860,0.009366,1.510703,-135.044174,0.152180,0.000000
9.690001,0.042450,-134.910721,0.006308,0.006093,0.154773,0.188829,0.009619,1.547734,-134.910721,0.155841,0.000000
9.910001,0.046547,-134.910721,0.006454,0.006237,0.158416,0.207049,0.010548,1.584160,-134.910721,0.159500,0.000000
10.130000,0.058462,-134.866241,0.006588,0.006382,0.162110,0.260054,0.013248,1.621101,-134.866241,0.163177,0.000000
10.350000,0.038354,-134.910721,0.006730,0.006528,0.165822,0.170609,0.008691,1.658223,-134.910721,0.166837,0.000000
10.570001,0.071123,-134.955200,0.006890,0.006670,0.169421,0.316371,0.016117,1.694210,-134.955200,0.170496,0.000000
10.790001,0.065538,-134.910721,0.007058,0.006815,0.173106,0.291525,0.014851,1.731060,-134.910721,0.174173,0.000000
11.010000,0.041706,-134.866241,0.007187,0.006959,0.176767,0.185516,0.009451,1.767667,-134.866241,0.177833,0.000000
11.230000,0.058462,-134.866241,0.007291,0.007101,0.180365,0.260054,0.013248,1.803654,-134.866241,0.181493,0.000000
11.450001,0.072985,-134.910721,0.007506,0.007250,0.184138,0.324653,0.016539,1.841382,-134.910721,0.185169,0.000000
11.670001,0.062931,-134.910721,0.007683,0.007392,0.187746,0.279931,0.014260,1.877459,-134.910721,0.188830,0.000000
11.890000,0.082294,-134.821762,0.007791,0.007528,0.191214,0.366063,0.018648,1.912144,-134.821762,0.192489,0.000000
12.110001,0.063303,-134.821762,0.007942,0.007680,0.195073,0.281587,0.014345,1.950735,-134.821762,0.196167,0.000000
12.330001,0.057345,-134.866241,0.008106,0.007827,0.198802,0.255085,0.012995,1.988024,-134.866241,0.199826,0.000000
12.550000,0.015267,-134.910721,0.008231,0.007968,0.202393,0.067912,0.003460,2.023935,-134.910721,0.203485,0.000000
12.770000,0.086390,-134.866241,0.008386,0.008111,0.206027,0.384284,0.019576,2.060270,-134.866241,0.207162,0.000000
12.990001,0.080432,-134.866241,0.008528,0.008260,0.209816,0.357781,0.018226,2.098164,-134.866241,0.210822,0.000000
13.210001,0.085646,-134.777283,0.008658,0.008403,0.213424,0.380971,0.019408,2.134242,-134.777283,0.214482,0.000000
13.430000,0.089742,-134.777283,0.008808,0.008539,0.216902,0.399191,0.020336,2.169017,-134.777283,0.218142,0.000000
13.650001,0.094955,-134.866241,0.008925,0.008690,0.220735,0.422381,0.021517,2.207351,-134.866241,0.221819,0.000000
13.870001,0.094210,-134.866241,0.009106,0.008841,0.224568,0.419068,0.021348,2.245684,-134.866241,0.225478,0.000000
14.090001,0.049153,-134.732803,0.009248,0.008981,0.228114,0.218644,0.011138,2.281141,-134.732803,0.229138,0.000000
14.310000,0.026438,-134.777283,0.009369,0.009119,0.231619,0.117604,0.005991,2.316189,-134.777283,0.232815,0.000000
14.530001,0.021598,-134.732803,0.009485,0.009265,0.235339,0.096071,0.004894,2.353387,-134.732803,0.236474,0.000000
14.750001,0.079688,-134.732803,0.009666,0.009411,0.239042,0.354468,0.018057,2.390419,-134.732803,0.240135,0.000000
14.970000,0.073730,-134.732803,0.009774,0.009552,0.242624,0.327966,0.016707,2.426239,-134.732803,0.243811,0.000000
15.190001,0.083039,-134.777283,0.009921,0.009700,0.246369,0.369376,0.018817,2.463694,-134.777283,0.247472,0.000000
15.410001,0.079315,-134.688324,0.010080,0.009840,0.249942,0.352812,0.017973,2.499424,-134.688324,0.251131,0.000000
15.630001,0.067772,-134.732803,0.010210,0.009994,0.253854,0.301464,0.015357,2.538544,-134.732803,0.254808,0.000000
15.850000,0.041333,-134.688324,0.010391,0.010134,0.257393,0.183860,0.009366,2.573925,-134.688324,0.258467,0.000000
16.070002,0.043940,-134.688324,0.010503,0.010277,0.261026,0.195455,0.009957,2.610260,-134.688324,0.262127,0.000000
16.290001,0.053994,-134.688324,0.010649,0.010422,0.264711,0.240177,0.012235,2.647110,-134.688324,0.265804,0.000000
16.510000,0.053249,-134.643845,0.010800,0.010565,0.268363,0.236864,0.012066,2.683627,-134.643845,0.269463,0.000000
16.730001,0.054739,-134.688324,0.010951,0.010713,0.272101,0.243490,0.012404,2.721006,-134.688324,0.273124,0.000000
16.950001,0.067772,-134.643845,0.011085,0.010850,0.275578,0.301464,0.015357,2.755782,-134.643845,0.276800,0.000000
17.170000,0.071123,-134.688324,0.011283,0.011002,0.279463,0.316371,0.016117,2.794630,-134.688324,0.280461,0.000000
17.390001,0.046174,-134.688324,0.011430,0.011144,0.283045,0.205393,0.010463,2.830451,-134.688324,0.284120,0.000000
17.610001,0.061069,-134.643845,0.011572,0.011288,0.286704,0.271649,0.013838,2.867043,-134.643845,0.287779,0.000000
17.830000,0.099796,-134.599365,0.011723,0.011433,0.290407,0.443914,0.022614,2.904074,-134.599365,0.291457,0.000000
18.050001,0.100168,-134.643845,0.011921,0.011577,0.294050,0.445570,0.022698,2.940500,-134.643845,0.295116,0.000000
18.270000,0.156024,-134.643845,0.012077,0.011714,0.297544,0.694030,0.035356,2.975442,-134.643845,0.298777,0.000000
18.490002,0.224541,-134.599365,0.012245,0.011862,0.301300,0.998806,0.050882,3.013004,-134.599365,0.302452,0.000000
18.710001,0.393598,-134.554871,0.012396,0.012011,0.305072,1.750810,0.089191,3.050716,-134.554871,0.306113,0.000000
18.930000,0.705646,-134.554871,0.012559,0.000011,0.000286,3.138869,0.159902,0.002861,-134.554871,0.001344,0.000000
19.150002,0.658355,-134.554871,0.012551,0.000005,0.000121,2.928507,0.149185,0.001211,-134.554871,0.000312,0.000000
19.370001,0.651279,-134.599365,0.012564,0.000004,0.000112,2.897035,0.147582,0.001120,-134.599365,0.000312,0.000000
19.590000,0.643087,-134.510391,0.012564,0.000004,0.000112,2.860595,0.145726,0.001120,-134.510391,0.000512,0.000000
19.810001,0.634523,-134.554871,0.012564,0.000005,0.000121,2.822498,0.143785,0.001211,-134.554871,0.000875,0.000000
20.030001,0.651652,-134.510391,0.012551,0.000015,0.000391,2.898692,0.147666,0.003906,-134.510391,0.001249,0.000000
20.250002,0.680697,-134.465912,0.012581,0.000028,0.000702,3.027891,0.154248,0.007025,-134.465912,0.001612,0.000000
20.470001,0.703412,-134.465912,0.012590,0.000040,0.001005,3.128931,0.159395,0.010053,-134.465912,0.001977,0.000000
20.690001,0.735808,-134.421432,0.012594,0.000051,0.001300,3.273037,0.166736,0.013005,-134.421432,0.002350,0.000000
20.910002,0.852361,-134.465912,0.012585,0.000066,0.001682,3.791489,0.193148,0.016820,-134.465912,0.002715,0.000000
21.130001,0.882895,-134.421432,0.012594,0.000081,0.002064,3.927313,0.200067,0.020635,-134.421432,0.003078,0.000000
21.350000,0.953646,-134.465912,0.012620,0.000091,0.002324,4.242029,0.216099,0.023239,-134.465912,0.003443,0.000000
21.570002,1.010619,-134.465912,0.012641,0.000112,0.002836,4.495457,0.229009,0.028356,-134.465912,0.003815,0.000000
21.790001,1.059027,-134.376953,0.012676,0.000128,0.003243,4.710788,0.239979,0.032429,-134.376953,0.004180,0.000000
22.010000,1.085838,-134.421432,0.012672,0.000140,0.003564,4.830049,0.246054,0.035639,-134.421432,0.004543,0.000000
22.230001,1.146907,-134.376953,0.012672,0.000157,0.003980,5.101697,0.259893,0.039802,-134.376953,0.004917,0.000000
22.450001,1.204252,-134.421432,0.012684,0.000171,0.004345,5.356782,0.272888,0.043451,-134.421432,0.005281,0.000000
22.670002,1.261225,-134.421432,0.012736,0.000184,0.004674,5.610211,0.285798,0.046736,-134.421432,0.005646,0.000000
22.890001,1.286547,-134.376953,0.012749,0.000196,0.004985,5.722846,0.291536,0.049855,-134.376953,0.006009,0.000000
23.110001,1.360277,-134.332474,0.012732,0.000206,0.005238,6.050812,0.308243,0.052383,-134.332474,0.006383,0.000000
23.330002,1.469754,-134.287994,0.012753,0.000227,0.005758,6.537793,0.333051,0.057576,-134.287994,0.006746,0.000000
23.550001,1.535664,-134.332474,0.012766,0.000242,0.006157,6.830975,0.347986,0.061573,-134.332474,0.007111,0.000000
23.770000,1.599340,-134.332474,0.012818,0.000258,0.006555,7.114218,0.362416,0.065554,-134.332474,0.007483,0.000000
23.990002,1.651099,-134.376953,0.012835,0.000269,0.006834,7.344457,0.374144,0.068340,-134.376953,0.007848,0.000000
24.210001,1.703232,-134.287994,0.012848,0.000283,0.007188,7.576353,0.385958,0.071883,-134.287994,0.008212,0.000000
24.430000,1.840637,-134.243515,0.012853,0.000302,0.007674,8.187562,0.417094,0.076743,-134.243515,0.008577,0.000000
24.650002,1.952349,-134.376953,0.012861,0.000318,0.008074,8.684482,0.442409,0.080739,-134.376953,0.008949,0.000000
24.870001,2.035016,-134.332474,0.012891,0.000330,0.008386,9.052201,0.461141,0.083858,-134.332474,0.009314,0.000000
25.090002,2.108745,-134.199036,0.012900,0.000340,0.008646,9.380167,0.477848,0.086462,-134.199036,0.009677,0.000000
25.310001,2.190667,-134.243515,0.012887,0.000350,0.008879,9.744575,0.496412,0.088794,-134.243515,0.010051,0.000000
25.530001,2.396217,-134.243515,0.012909,0.000375,0.009530,10.658905,0.542991,0.095304,-134.243515,0.010415,0.000000
25.750002,2.499736,-134.243515,0.012935,0.000387,0.009835,11.119383,0.566448,0.098347,-134.243515,0.010779,0.000000
25.970001,2.555220,-134.243515,0.012956,0.000400,0.010172,11.366184,0.579021,0.101723,-134.243515,0.011143,0.000000
26.190001,2.715340,-134.199036,0.012978,0.000418,0.010614,12.078436,0.615305,0.106144,-134.199036,0.011517,0.000000
26.410002,2.823700,-134.199036,0.012943,0.000429,0.010900,12.560447,0.639860,0.109005,-134.199036,0.011880,0.000000
26.630001,3.000950,-134.110062,0.012991,0.000446,0.011317,13.348890,0.680025,0.113168,-134.110062,0.012245,0.000000
26.850000,3.091436,-134.199036,0.013004,0.000456,0.011594,13.751395,0.700529,0.115939,-134.199036,0.012617,0.000000
27.070002,3.230331,-134.154541,0.013034,0.000465,0.011812,14.369231,0.732004,0.118119,-134.154541,0.012982,0.000000
27.290001,3.355076,-134.154541,0.013016,0.000475,0.012063,14.924123,0.760271,0.120632,-134.154541,0.013346,0.000000
27.510002,3.771388,-134.065582,0.013073,0.000504,0.012808,16.775972,0.854609,0.128081,-134.065582,0.013710,0.000000
27.730001,3.904325,-134.065582,0.013073,0.000517,0.013138,17.367306,0.884733,0.131381,-134.065582,0.014083,0.000000
27.950001,4.058115,-134.154541,0.013094,0.000532,0.013503,18.051397,0.919582,0.135030,-134.154541,0.014448,0.000000
28.170002,4.183232,-134.154541,0.013098,0.000544,0.013815,18.607946,0.947934,0.138149,-134.154541,0.014813,0.000000
28.390001,4.417827,-134.021103,0.013142,0.000558,0.014178,19.651474,1.001094,0.141782,-134.021103,0.015176,0.000000
28.610001,4.761154,-134.021103,0.013094,0.000576,0.014638,21.178671,1.078893,0.146385,-134.021103,0.015548,0.000000
28.830002,4.875100,-134.021103,0.013159,0.000587,0.014908,21.685528,1.104713,0.149079,-134.021103,0.015913,0.000000
29.050001,4.966331,-134.065582,0.013129,0.000595,0.015106,22.091345,1.125387,0.151063,-134.065582,0.016278,0.000000
29.270000,5.187148,-134.110062,0.013172,0.000610,0.015488,23.073587,1.175424,0.154878,-134.110062,0.016651,0.000000
29.490002,5.739004,-134.065582,0.013210,0.000637,0.016183,25.528366,1.300477,0.161827,-134.065582,0.017014,0.000000
29.710001,5.888698,-134.021103,0.013228,0.000649,0.016485,26.194235,1.334398,0.164855,-134.021103,0.017379,0.000000
29.930002,6.119197,-133.976624,0.013176,0.000660,0.016772,27.219547,1.386630,0.167716,-133.976624,0.017744,0.000000
30.150002,6.297563,-134.065582,0.013228,0.000673,0.017093,28.012957,1.427048,0.170926,-134.065582,0.018116,0.000000
30.370001,6.680362,-133.976624,0.013275,0.000691,0.017544,29.715733,1.513792,0.175437,-133.976624,0.018481,0.000000
30.590002,6.917191,-134.021103,0.013262,0.000706,0.017925,30.769199,1.567458,0.179253,-134.021103,0.018844,0.000000
30.810001,7.129071,-133.976624,0.013297,0.000717,0.018220,31.711693,1.615471,0.182205,-133.976624,0.019217,0.000000
31.030001,7.354356,-133.976624,0.013284,0.000730,0.018541,32.713810,1.666521,0.185414,-133.976624,0.019582,0.000000
31.250002,7.798969,-133.976624,0.013301,0.000750,0.019044,34.691547,1.767272,0.190441,-133.976624,0.019946,0.000000
31.470001,8.144158,-133.976624,0.013314,0.000766,0.019460,36.227024,1.845493,0.194604,-133.976624,0.020310,0.000000
31.690002,8.285660,-133.932144,0.013305,0.000776,0.019721,36.856457,1.877557,0.197208,-133.932144,0.020684,0.000000
31.910002,8.547065,-133.976624,0.013340,0.000791,0.020102,38.019241,1.936793,0.201023,-133.976624,0.021047,0.000000
32.130001,8.928002,-133.887665,0.013353,0.000808,0.020519,39.713737,2.023114,0.205187,-133.887665,0.021412,0.000000
32.350002,9.245263,-133.887665,0.013379,0.000821,0.020865,41.124985,2.095007,0.208654,-133.887665,0.021784,0.000000
32.570000,9.456026,-133.887665,0.013366,0.000833,0.021168,42.062504,2.142766,0.211682,-133.887665,0.022149,0.000000
32.790001,9.734933,-133.887665,0.013387,0.000846,0.021498,43.303143,2.205967,0.214982,-133.887665,0.022513,0.000000
33.010002,10.099858,-133.932144,0.013400,0.000864,0.021940,44.926414,2.288661,0.219403,-133.932144,0.022877,0.000000
33.230003,10.560110,-133.887665,0.013426,0.000883,0.022417,46.973717,2.392955,0.224172,-133.887665,0.023250,0.000000
33.450001,10.781672,-133.843185,0.013422,0.000895,0.022721,47.959274,2.443162,0.227215,-133.843185,0.023615,0.000000
33.670002,10.998020,-133.887665,0.013469,0.000906,0.023008,48.921638,2.492187,0.230076,-133.887665,0.023978,0.000000
33.890003,11.254585,-133.798706,0.013456,0.000919,0.023345,50.062897,2.550326,0.233452,-133.798706,0.024352,0.000000
34.110001,11.526045,-133.798706,0.013491,0.000931,0.023657,51.270409,2.611839,0.236571,-133.798706,0.024715,0.000000
34.330002,12.045505,-133.843185,0.013504,0.000951,0.024143,53.581081,2.729550,0.241431,-133.843185,0.025080,0.000000
34.550003,12.129661,-133.754227,0.013508,0.000962,0.024429,53.955425,2.748620,0.244292,-133.754227,0.025444,0.000000
34.770000,12.454741,-133.798706,0.013495,0.000973,0.024706,55.401459,2.822285,0.247063,-133.798706,0.025818,0.000000
34.990002,12.684495,-133.843185,0.013508,0.000984,0.024992,56.423450,2.874348,0.249924,-133.843185,0.026181,0.000000
35.210003,13.392003,-133.754227,0.013534,0.001009,0.025634,59.570606,3.034671,0.256343,-133.754227,0.026546,0.000000
35.430000,13.638885,-133.709732,0.013560,0.001025,0.026025,60.668793,3.090616,0.260249,-133.709732,0.026918,0.000000
35.650002,13.744639,-133.754227,0.013581,0.001035,0.026285,61.139210,3.114580,0.262853,-133.754227,0.027283,0.000000
35.870003,13.993384,-133.754227,0.013581,0.001047,0.026597,62.245682,3.170946,0.265972,-133.754227,0.027646,0.000000
36.090000,14.315859,-133.665253,0.013573,0.001061,0.026944,63.680122,3.244020,0.269439,-133.665253,0.028011,0.000000
36.310001,14.656580,-133.709732,0.013607,0.001074,0.027291,65.195724,3.321229,0.272906,-133.709732,0.028384,0.000000
36.530003,15.137685,-133.709732,0.013624,0.001094,0.027777,67.335785,3.430248,0.277766,-133.709732,0.028749,0.000000
36.750000,15.290730,-133.709732,0.013629,0.001105,0.028063,68.016563,3.464929,0.280627,-133.709732,0.029112,0.000000
36.970001,15.621397,-133.754227,0.013646,0.001120,0.028453,69.487442,3.539859,0.284533,-133.754227,0.029486,0.000000
37.190002,15.952064,-133.665253,0.013689,0.001136,0.028844,70.958321,3.614789,0.288439,-133.665253,0.029849,0.000000
37.410004,16.330395,-133.620773,0.013680,0.001151,0.029225,72.641220,3.700520,0.292254,-133.620773,0.030214,0.000000
37.630001,16.443596,-133.576294,0.013672,0.001164,0.029554,73.144768,3.726172,0.295540,-133.576294,0.030577,0.000000
37.850002,16.869217,-133.665253,0.013711,0.001179,0.029937,75.038025,3.822619,0.299370,-133.665253,0.030951,0.000000
38.070004,16.924328,-133.620773,0.013702,0.001188,0.030179,75.283173,3.835108,0.301792,-133.620773,0.031315,0.000000
38.290001,17.282923,-133.620773,0.013711,0.001203,0.030561,76.878281,3.916366,0.305608,-133.620773,0.031680,0.000000
38.510002,17.864941,-133.531815,0.013745,0.001222,0.031047,79.467224,4.048254,0.310467,-133.531815,0.032052,0.000000
38.730003,17.941650,-133.576294,0.013749,0.001234,0.031350,79.808449,4.065636,0.313495,-133.576294,0.032417,0.000000
38.950001,18.301361,-133.620773,0.013745,0.001249,0.031714,81.408524,4.147148,0.317144,-133.620773,0.032780,0.000000
39.170002,18.789169,-133.576294,0.013797,0.001268,0.032208,83.578400,4.257687,0.322079,-133.576294,0.033145,0.000000
39.390003,18.974239,-133.576294,0.013818,0.001282,0.032555,84.401634,4.299624,0.325546,-133.576294,0.033518,0.000000
39.610001,18.959343,-133.531815,0.013823,0.001291,0.032798,84.335373,4.296248,0.327984,-133.531815,0.033882,0.000000
39.830002,19.290010,-133.531815,0.013810,0.001305,0.033154,85.806252,4.371179,0.331542,-133.531815,0.034246,0.000000
40.050003,19.730900,-133.487335,0.013831,0.001324,0.033622,87.767426,4.471086,0.336220,-133.487335,0.034620,0.000000
40.270000,20.284245,-133.531815,0.013840,0.001341,0.034073,90.228828,4.596476,0.340731,-133.531815,0.034983,0.000000
40.490002,20.327068,-133.487335,0.013887,0.001353,0.034359,90.419319,4.606180,0.343593,-133.487335,0.035348,0.000000
40.710003,20.717314,-133.442856,0.013874,0.001368,0.034757,92.155212,4.694611,0.347574,-133.442856,0.035711,0.000000
40.930000,20.837963,-133.398376,0.013905,0.001379,0.035036,92.691887,4.721950,0.350360,-133.398376,0.036085,0.000000
41.150002,21.357794,-133.442856,0.013883,0.001399,0.035530,95.004211,4.839746,0.355296,-133.442856,0.036449,0.000000
41.370003,21.521267,-133.487335,0.013918,0.001411,0.035841,95.731377,4.876789,0.358414,-133.487335,0.036813,0.000000
41.590000,21.598347,-133.398376,0.013900,0.001424,0.036162,96.074242,4.894255,0.361624,-133.398376,0.037178,0.000000
41.810001,21.965134,-133.353897,0.013935,0.001437,0.036502,97.705795,4.977370,0.365015,-133.353897,0.037551,0.000000
42.030003,22.171801,-133.353897,0.013948,0.001450,0.036822,98.625092,5.024202,0.368225,-133.353897,0.037914,0.000000
42.250004,22.613062,-133.442856,0.013982,0.001465,0.037221,100.587921,5.124193,0.372207,-133.442856,0.038279,0.000000
42.470001,22.820475,-133.442856,0.013974,0.001479,0.037567,101.510544,5.171194,0.375674,-133.442856,0.038651,0.000000
42.690002,22.959368,-133.309418,0.013995,0.001489,0.037819,102.128372,5.202667,0.378187,-133.309418,0.039016,0.000000
42.910004,23.590912,-133.398376,0.014012,0.001509,0.038323,104.937614,5.345777,0.383228,-133.398376,0.039381,0.000000
43.130001,24.028450,-133.353897,0.014025,0.001525,0.038747,106.883881,5.444924,0.387467,-133.353897,0.039744,0.000000
43.350002,24.204582,-133.309418,0.014030,0.001538,0.039060,107.667358,5.484837,0.390601,-133.309418,0.040117,0.000000
43.570004,24.411621,-133.398376,0.014060,0.001552,0.039433,108.588310,5.531752,0.394325,-133.398376,0.040482,0.000000
43.790001,24.800751,-133.353897,0.014081,0.001568,0.039840,110.319252,5.619930,0.398398,-133.353897,0.040847,0.000000
44.010002,25.192858,-133.264923,0.014081,0.001583,0.040212,112.063431,5.708783,0.402122,-133.264923,0.041219,0.000000
44.230003,25.289303,-133.309418,0.014133,0.001598,0.040577,112.492439,5.730638,0.405771,-133.309418,0.041582,0.000000
44.450001,25.489639,-133.309418,0.014133,0.001605,0.040768,113.383575,5.776035,0.407679,-133.309418,0.041947,0.000000
44.670002,26.082085,-133.264923,0.014112,0.001624,0.041254,116.018906,5.910285,0.412538,-133.264923,0.042312,0.000000
44.890003,26.484247,-133.309418,0.014137,0.001640,0.041652,117.807816,6.001416,0.416520,-133.309418,0.042685,0.000000
45.110001,26.919922,-133.264923,0.014150,0.001657,0.042087,119.745796,6.100142,0.420865,-133.264923,0.043049,0.000000
45.330002,26.963118,-133.309418,0.014181,0.001667,0.042347,119.937935,6.109930,0.423469,-133.309418,0.043413,0.000000
45.550003,27.394325,-133.264923,0.014159,0.001682,0.042710,121.856041,6.207643,0.427103,-133.264923,0.043785,0.000000
45.770000,27.899633,-133.309418,0.014206,0.001700,0.043171,124.103767,6.322147,0.431705,-133.309418,0.044150,0.000000
45.990002,28.385952,-133.175964,0.014215,0.001716,0.043578,126.267021,6.432348,0.435778,-133.175964,0.044515,0.000000
46.210003,28.534157,-133.220444,0.014245,0.001729,0.043908,126.926270,6.465932,0.439078,-133.220444,0.044878,0.000000
46.430000,28.735611,-133.131485,0.014202,0.001739,0.044167,127.822380,6.511582,0.441667,-133.131485,0.045252,0.000000
46.650002,28.951960,-133.175964,0.014258,0.001748,0.044410,128.784744,6.560608,0.444104,-133.175964,0.045616,0.000000
46.870003,30.032583,-133.175964,0.014275,0.001775,0.045078,133.591599,6.805481,0.450781,-133.175964,0.045980,0.000000
47.090004,30.213184,-133.175964,0.014245,0.001788,0.045408,134.394958,6.846406,0.454081,-133.175964,0.046353,0.000000
47.310001,30.422831,-133.131485,0.014314,0.001800,0.045711,135.327515,6.893912,0.457109,-133.131485,0.046718,0.000000
47.530003,31.054747,-133.175964,0.014319,0.001817,0.046153,138.138412,7.037106,0.461530,-133.175964,0.047081,0.000000
47.750004,31.196247,-133.131485,0.014306,0.001829,0.046457,138.767838,7.069170,0.464573,-133.131485,0.047446,0.000000
47.970001,31.862795,-133.175964,0.014323,0.001846,0.046881,141.732788,7.220212,0.468812,-133.175964,0.047818,0.000000
48.190002,31.963335,-133.131485,0.014331,0.001856,0.047142,142.180008,7.242995,0.471416,-133.131485,0.048183,0.000000
48.410004,32.110794,-133.131485,0.014375,0.001863,0.047325,142.835953,7.276410,0.473248,-133.131485,0.048547,0.000000
48.630001,32.467529,-133.087006,0.014353,0.001874,0.047611,144.422791,7.357247,0.476110,-133.087006,0.048921,0.000000
48.850002,33.792057,-133.131485,0.014357,0.001903,0.048339,150.314575,7.657390,0.483392,-133.131485,0.049284,0.000000
49.070004,34.063889,-133.087006,0.014405,0.001916,0.048668,151.523743,7.718987,0.486677,-133.087006,0.049649,0.000000
49.290001,34.431049,-133.087006,0.014405,0.001930,0.049033,153.156952,7.802187,0.490326,-133.087006,0.050012,0.000000
49.510002,34.769535,-133.087006,0.014388,0.001944,0.049370,154.662613,7.878889,0.493702,-133.087006,0.050386,0.000000
49.730003,35.209679,-132.998047,0.014418,0.001958,0.049735,156.620468,7.978627,0.497350,-132.998047,0.050749,0.000000
49.950001,35.979374,-133.042526,0.014435,0.001975,0.050168,160.044250,8.153043,0.501680,-133.042526,0.051114,0.000000
50.170002,36.161465,-133.042526,0.014444,0.001985,0.050428,160.854233,8.194305,0.504284,-133.042526,0.051487,0.000000
50.390003,36.187901,-132.953568,0.014457,0.001993,0.050628,160.971817,8.200295,0.506283,-132.953568,0.051852,0.000000
50.610001,36.567348,-132.953568,0.014478,0.002008,0.051001,162.659683,8.286280,0.510007,-132.953568,0.052215,0.000000
50.830002,38.155148,-132.953568,0.014504,0.002035,0.051696,169.722580,8.646080,0.516956,-132.953568,0.052580,0.000000
51.050003,38.391232,-132.998047,0.014500,0.002048,0.052024,170.772720,8.699577,0.520241,-132.998047,0.052952,0.000000
51.270004,38.742748,-132.998047,0.014526,0.002059,0.052303,172.336349,8.779232,0.523027,-132.998047,0.053317,0.000000
51.490002,39.119217,-132.953568,0.014530,0.002072,0.052640,174.010971,8.864541,0.526403,-132.953568,0.053680,0.000000
51.710003,39.975674,-132.909088,0.014569,0.002090,0.053073,177.820679,9.058617,0.530733,-132.909088,0.054054,0.000000
51.930004,40.389008,-132.909088,0.014569,0.002105,0.053464,179.659271,9.152280,0.534639,-132.909088,0.054418,0.000000
52.150002,40.820961,-132.909088,0.014551,0.002117,0.053776,181.580704,9.250162,0.537758,-132.909088,0.054783,0.000000
52.370003,41.275253,-132.953568,0.014573,0.002130,0.054106,183.601501,9.353106,0.541058,-132.953568,0.055146,0.000000
52.590004,42.237839,-132.909088,0.014582,0.002150,0.054601,187.883286,9.571231,0.546009,-132.909088,0.055520,0.000000
52.810001,42.875340,-132.864594,0.014616,0.002165,0.054982,190.719040,9.715691,0.549824,-132.864594,0.055883,0.000000
53.030003,43.063015,-132.864594,0.014638,0.002175,0.055250,191.553864,9.758219,0.552504,-132.864594,0.056248,0.000000
53.250004,43.636097,-132.820114,0.014603,0.002190,0.055623,194.103058,9.888081,0.556228,-132.820114,0.056611,0.000000
53.470001,44.388660,-132.864594,0.014607,0.002207,0.056057,197.450623,10.058614,0.560573,-132.864594,0.056985,0.000000
53.690002,45.072708,-132.909088,0.014655,0.002221,0.056421,200.493423,10.213622,0.564207,-132.909088,0.057349,0.000000
53.910004,45.423111,-132.820114,0.014642,0.002233,0.056707,202.052094,10.293024,0.567068,-132.820114,0.057714,0.000000
54.130001,45.942570,-132.820114,0.014625,0.002246,0.057046,204.362762,10.410735,0.570459,-132.820114,0.058086,0.000000
54.350002,46.774452,-132.820114,0.014685,0.002264,0.057505,208.063156,10.599242,0.575047,-132.820114,0.058451,0.000000
54.570004,47.704639,-132.909088,0.014694,0.002283,0.057983,212.200836,10.810026,0.579831,-132.909088,0.058814,0.000000
54.790001,48.032700,-132.775635,0.014698,0.002293,0.058242,213.660126,10.884366,0.582420,-132.775635,0.059179,0.000000
55.010002,48.443424,-132.775635,0.014689,0.002305,0.058555,215.487106,10.977437,0.585554,-132.775635,0.059552,0.000000
55.230003,48.966606,-132.731155,0.014728,0.002319,0.058902,217.814346,11.095991,0.589020,-132.731155,0.059916,0.000000
55.450001,49.476387,-132.775635,0.014732,0.002331,0.059196,220.081955,11.211510,0.591958,-132.775635,0.060280,0.000000
55.670002,50.460937,-132.820114,0.014745,0.002349,0.059674,224.461456,11.434612,0.596742,-132.820114,0.060654,0.000000
55.890003,50.807617,-132.731155,0.014750,0.002360,0.059951,226.003571,11.513171,0.599512,-132.731155,0.061017,0.000000
56.110004,51.347187,-132.731155,0.014776,0.002371,0.060219,228.403702,11.635439,0.602192,-132.731155,0.061382,0.000000
56.330002,51.754562,-132.686676,0.014767,0.002382,0.060498,230.215790,11.727752,0.604978,-132.686676,0.061747,0.000000
56.550003,53.309216,-132.686676,0.014758,0.002409,0.061191,237.131241,12.080041,0.611912,-132.686676,0.062119,0.000000
56.770004,53.927353,-132.731155,0.014767,0.002424,0.061564,239.880844,12.220113,0.615636,-132.731155,0.062483,0.000000
56.990002,54.231583,-132.642197,0.014793,0.002434,0.061833,241.234131,12.289052,0.618331,-132.642197,0.062847,0.000000
57.210003,54.770779,-132.642197,0.014832,0.002447,0.062154,243.632599,12.411236,0.621540,-132.642197,0.063220,0.000000
57.430004,55.417587,-132.686676,0.014827,0.002459,0.062466,246.509735,12.557805,0.624659,-132.686676,0.063585,0.000000
57.650002,56.119511,-132.597717,0.014819,0.002474,0.062847,249.632050,12.716863,0.628474,-132.597717,0.063950,0.000000
57.870003,57.172951,-132.686676,0.014862,0.002493,0.063324,254.317993,12.955576,0.633243,-132.686676,0.064313,0.000000
58.090004,57.658897,-132.686676,0.014819,0.002505,0.063620,256.479584,13.065693,0.636195,-132.686676,0.064685,0.000000
58.310001,58.514236,-132.553238,0.014870,0.002522,0.064062,260.284332,13.259515,0.640616,-132.553238,0.065050,0.000000
58.530003,59.071678,-132.508759,0.014857,0.002534,0.064373,262.763947,13.385833,0.643735,-132.508759,0.065415,0.000000
58.750004,59.928883,-132.553238,0.014857,0.002549,0.064755,266.576996,13.580078,0.647550,-132.553238,0.065788,0.000000
58.970001,60.322849,-132.597717,0.014879,0.002561,0.065059,268.329437,13.669353,0.650593,-132.597717,0.066151,0.000000
59.190002,61.078396,-132.597717,0.014892,0.002577,0.065467,271.690277,13.840563,0.654666,-132.597717,0.066516,0.000000
59.410004,61.533806,-132.553238,0.014892,0.002587,0.065701,273.716034,13.943760,0.657012,-132.553238,0.066881,0.000000
59.630001,62.363453,-132.508759,0.014918,0.002601,0.066074,277.406494,14.131760,0.660737,-132.508759,0.067253,0.000000
59.850002,63.701759,-132.508759,0.014935,0.002621,0.066576,283.359589,14.435025,0.665763,-132.508759,0.067618,0.000000
60.070004,64.029816,-132.464279,0.014909,0.002633,0.066872,284.818848,14.509364,0.668715,-132.464279,0.067981,0.000000
60.290005,64.968567,-132.553238,0.014944,0.002647,0.067244,288.994629,14.722088,0.672440,-132.553238,0.068354,0.000000
60.510002,66.075264,-132.464279,0.014952,0.002667,0.067739,293.917450,14.972869,0.677390,-132.464279,0.068719,0.000000
60.730003,66.722816,-132.464279,0.014978,0.002680,0.068077,296.797913,15.119607,0.680766,-132.464279,0.069083,0.000000
60.950005,67.034119,-132.419785,0.014965,0.002689,0.068311,298.182648,15.190148,0.683113,-132.419785,0.069447,0.000000
61.170002,67.487671,-132.464279,0.015004,0.002691,0.068354,300.200165,15.292924,0.683537,-132.464279,0.068588,0.000000
61.390003,67.040077,-132.375305,0.015013,0.002691,0.068354,298.209167,15.191499,0.683537,-132.375305,0.068588,0.000000
61.610004,66.766380,-132.375305,0.015013,0.002688,0.068286,296.991699,15.129478,0.682856,-132.375305,0.068354,0.000000
61.830002,66.476303,-132.375305,0.014995,0.002687,0.068251,295.701355,15.063745,0.682507,-132.375305,0.068354,0.000000
62.050003,66.237244,-132.375305,0.015008,0.002686,0.068225,294.637970,15.009574,0.682250,-132.375305,0.068354,0.000000
62.270004,66.026855,-132.419785,0.014970,0.002686,0.068216,293.702118,14.961899,0.682159,-132.419785,0.068354,0.000000
62.490002,65.835823,-132.419785,0.015013,0.002685,0.068207,292.852356,14.918611,0.682068,-132.419785,0.068354,0.000000
62.710003,65.669373,-132.330826,0.015008,0.002685,0.068198,292.111969,14.880893,0.681978,-132.330826,0.068354,0.000000
62.930004,65.508881,-132.375305,0.014991,0.002685,0.068198,291.398041,14.844524,0.681978,-132.375305,0.068354,0.000000
63.150002,65.371475,-132.330826,0.015004,0.002685,0.068190,290.786835,14.813388,0.681902,-132.330826,0.068354,0.000000
63.370003,65.244499,-132.419785,0.015021,0.002685,0.068190,290.222015,14.784615,0.681902,-132.419785,0.068354,0.000000
63.590004,65.132416,-132.375305,0.015026,0.002684,0.068181,289.723450,14.759216,0.681811,-132.375305,0.068354,0.000000
63.810001,65.007668,-132.286346,0.015004,0.002684,0.068181,289.168549,14.730948,0.681811,-132.286346,0.068354,0.000000
64.030006,64.914200,-132.286346,0.014995,0.002684,0.068181,288.752777,14.709768,0.681811,-132.286346,0.068354,0.000000
64.250000,64.803978,-132.241867,0.015008,0.002684,0.068181,288.262482,14.684792,0.681811,-132.241867,0.068354,0.000000
64.470001,64.714607,-132.286346,0.015013,0.002684,0.068172,287.864960,14.664539,0.681720,-132.286346,0.068354,0.000000
64.690002,64.642372,-132.330826,0.015017,0.002684,0.068172,287.543640,14.648171,0.681720,-132.330826,0.068354,0.000000
64.910004,64.551140,-132.286346,0.014991,0.002684,0.068172,287.137817,14.627498,0.681720,-132.286346,0.068354,0.000000
65.130005,64.476288,-132.241867,0.015013,0.002684,0.068172,286.804840,14.610536,0.681720,-132.241867,0.068354,0.000000
65.350006,64.413734,-132.241867,0.015021,0.002684,0.068172,286.526611,14.596360,0.681720,-132.241867,0.068354,0.000000
65.570000,64.342613,-132.197388,0.014987,0.002684,0.068172,286.210236,14.580244,0.681720,-132.197388,0.068354,0.000000
65.790001,64.270370,-132.197388,0.015000,0.002684,0.068172,285.888885,14.563874,0.681720,-132.197388,0.068354,0.000000
66.010002,64.213768,-132.241867,0.015034,0.002684,0.068163,285.637115,14.551047,0.681629,-132.241867,0.068354,0.000000
66.230003,64.158287,-132.241867,0.015004,0.002684,0.068163,285.390320,14.538476,0.681629,-132.241867,0.068354,0.000000
66.450005,64.097961,-132.197388,0.015021,0.002684,0.068163,285.121979,14.524805,0.681629,-132.197388,0.068354,0.000000
66.670006,64.035027,-132.152908,0.014991,0.002684,0.068163,284.842010,14.510544,0.681629,-132.152908,0.068354,0.000000
66.889999,63.984016,-132.152908,0.015017,0.002684,0.068163,284.615112,14.498985,0.681629,-132.152908,0.068354,0.000000
67.110001,63.928905,-132.241867,0.015034,0.002684,0.068163,284.369965,14.486497,0.681629,-132.241867,0.068354,0.000000
67.330002,63.874538,-132.152908,0.015004,0.002684,0.068163,284.128143,14.474177,0.681629,-132.152908,0.068354,0.000000
67.550003,63.838421,-132.108429,0.015013,0.002684,0.068163,283.967468,14.465993,0.681629,-132.108429,0.068354,0.000000
67.770004,63.777351,-132.108429,0.014983,0.002684,0.068163,283.695831,14.452154,0.681629,-132.108429,0.068354,0.000000
67.990005,63.731174,-132.152908,0.015013,0.002684,0.068163,283.490417,14.441690,0.681629,-132.152908,0.068354,0.000000
68.210007,63.695057,-132.063950,0.015021,0.002684,0.068163,283.329773,14.433507,0.681629,-132.063950,0.068354,0.000000
68.430000,63.649998,-132.108429,0.015026,0.002683,0.068155,283.129333,14.423296,0.681554,-132.108429,0.068354,0.000000
68.650002,63.594887,-132.063950,0.014991,0.002683,0.068155,282.884186,14.410808,0.681554,-132.063950,0.068354,0.000000
68.870003,63.557652,-132.019470,0.015004,0.002683,0.068155,282.718567,14.402369,0.681554,-132.019470,0.068354,0.000000
69.090004,63.540894,-132.063950,0.014991,0.002683,0.068155,282.644012,14.398572,0.681554,-132.063950,0.068354,0.000000
69.310005,63.493977,-132.019470,0.014991,0.002683,0.068155,282.435303,14.387941,0.681554,-132.019470,0.068354,0.000000
69.530006,63.458225,-131.974976,0.015013,0.002683,0.068155,282.276276,14.379840,0.681554,-131.974976,0.068354,0.000000
69.750000,63.438866,-131.930496,0.015013,0.002683,0.068155,282.190155,14.375453,0.681554,-131.930496,0.068354,0.000000
69.970001,63.388966,-132.019470,0.015013,0.002683,0.068155,281.968201,14.364144,0.681554,-132.019470,0.068354,0.000000
70.190002,63.355824,-132.019470,0.015017,0.002683,0.068155,281.820770,14.356635,0.681554,-132.019470,0.068354,0.000000
70.410004,63.314491,-132.019470,0.015030,0.002683,0.068155,281.636932,14.347269,0.681554,-132.019470,0.068354,0.000000
70.630005,63.286938,-131.930496,0.015021,0.002683,0.068155,281.514374,14.341024,0.681554,-131.930496,0.068354,0.000000
70.850006,63.260498,-131.930496,0.015039,0.002683,0.068155,281.396759,14.335033,0.681554,-131.930496,0.068354,0.000000
71.070000,63.212833,-131.930496,0.015026,0.002683,0.068155,281.184723,14.324232,0.681554,-131.930496,0.068354,0.000000
71.290001,63.206131,-131.930496,0.014995,0.002683,0.068155,281.154907,14.322714,0.681554,-131.930496,0.068354,0.000000
71.510002,63.160702,-131.974976,0.015021,0.002683,0.068155,280.952820,14.312420,0.681554,-131.974976,0.068354,0.000000
71.730003,63.123837,-131.930496,0.014987,0.002683,0.068155,280.788849,14.304066,0.681554,-131.930496,0.068354,0.000000
71.950005,63.108940,-131.886017,0.015017,0.002683,0.068155,280.722595,14.300691,0.681554,-131.886017,0.068354,0.000000
72.170006,63.077663,-131.886017,0.015017,0.002683,0.068155,280.583466,14.293603,0.681554,-131.886017,0.068354,0.000000
72.390007,63.059788,-131.886017,0.015013,0.002683,0.068155,280.503937,14.289552,0.681554,-131.886017,0.068354,0.000000
72.610001,63.028511,-131.930496,0.015039,0.002683,0.068155,280.364807,14.282464,0.681554,-131.930496,0.068354,0.000000
72.830002,62.980846,-131.841537,0.014991,0.002683,0.068155,280.152802,14.271664,0.681554,-131.841537,0.068354,0.000000
73.050003,62.977123,-131.841537,0.015013,0.002683,0.068155,280.136230,14.270821,0.681554,-131.841537,0.068354,0.000000
73.270004,62.951801,-131.797058,0.015000,0.002683,0.068155,280.023590,14.265082,0.681554,-131.797058,0.068354,0.000000
73.490005,62.925735,-131.797058,0.014995,0.002683,0.068155,279.907654,14.259175,0.681554,-131.797058,0.068354,0.000000
73.710007,62.896317,-131.886017,0.014991,0.002683,0.068155,279.776794,14.252509,0.681554,-131.886017,0.068354,0.000000
73.930000,62.875092,-131.797058,0.015030,0.002683,0.068155,279.682373,14.247700,0.681554,-131.797058,0.068354,0.000000
74.150002,62.849770,-131.752579,0.014987,0.002683,0.068155,279.569733,14.241961,0.681554,-131.752579,0.068354,0.000000
74.370003,62.824821,-131.708099,0.015013,0.002683,0.068155,279.458771,14.236308,0.681554,-131.708099,0.068354,0.000000
74.590004,62.793171,-131.752579,0.015043,0.002683,0.068155,279.317963,14.229136,0.681554,-131.752579,0.068354,0.000000
74.810005,62.777531,-131.797058,0.015026,0.002683,0.068155,279.248413,14.225592,0.681554,-131.797058,0.068354,0.000000
75.030006,62.765244,-131.708099,0.014991,0.002683,0.068155,279.193756,14.222808,0.681554,-131.708099,0.068354,0.000000
75.250000,62.748112,-131.708099,0.015026,0.002683,0.068155,279.117554,14.218925,0.681554,-131.708099,0.068354,0.000000
75.470001,62.716835,-131.708099,0.014978,0.002683,0.068155,278.978424,14.211838,0.681554,-131.708099,0.068354,0.000000
75.690002,62.703056,-131.708099,0.015030,0.002683,0.068155,278.917114,14.208716,0.681554,-131.708099,0.068354,0.000000
75.910004,62.691883,-131.708099,0.014991,0.002683,0.068155,278.867432,14.206184,0.681554,-131.708099,0.068354,0.000000
76.130005,62.669540,-131.708099,0.015017,0.002683,0.068155,278.768036,14.201121,0.681554,-131.708099,0.068354,0.000000
76.350006,62.631931,-131.619141,0.015017,0.002683,0.068155,278.600739,14.192598,0.681554,-131.619141,0.068354,0.000000
76.570007,62.614059,-131.663620,0.015000,0.002683,0.068146,278.521240,14.188548,0.681463,-131.663620,0.068354,0.000000
76.790001,62.603634,-131.574646,0.015034,0.002683,0.068146,278.474884,14.186186,0.681463,-131.574646,0.068354,0.000000
77.010002,62.577938,-131.619141,0.015013,0.002683,0.068146,278.360565,14.180363,0.681463,-131.619141,0.068354,0.000000
77.230003,62.558949,-131.708099,0.015017,0.002683,0.068146,278.276093,14.176060,0.681463,-131.708099,0.068354,0.000000
77.450005,62.532509,-131.619141,0.015026,0.002683,0.068146,278.158478,14.170069,0.681463,-131.619141,0.068354,0.000000
77.670006,62.525063,-131.574646,0.015021,0.002683,0.068146,278.125366,14.168382,0.681463,-131.574646,0.068354,0.000000
77.890007,62.514637,-131.574646,0.015008,0.002683,0.068146,278.078979,14.166019,0.681463,-131.574646,0.068354,0.000000
78.110001,62.484474,-131.663620,0.015013,0.002683,0.068146,277.944824,14.159184,0.681463,-131.663620,0.068354,0.000000
78.330002,62.463249,-131.574646,0.015013,0.002683,0.068146,277.850403,14.154374,0.681463,-131.574646,0.068354,0.000000
78.550003,62.463619,-131.530167,0.015026,0.002683,0.068146,277.852051,14.154459,0.681463,-131.530167,0.068354,0.000000
78.770004,62.447609,-131.485687,0.015013,0.002683,0.068146,277.780823,14.150830,0.681463,-131.485687,0.068354,0.000000
78.990005,62.418564,-131.619141,0.015008,0.002683,0.068146,277.651642,14.144248,0.681463,-131.619141,0.068354,0.000000
79.210007,62.409252,-131.574646,0.015030,0.002683,0.068146,277.610229,14.142138,0.681463,-131.574646,0.068354,0.000000
79.430000,62.385048,-131.530167,0.015004,0.002683,0.068146,277.502563,14.136654,0.681463,-131.530167,0.068354,0.000000
79.650002,62.360100,-131.485687,0.015026,0.002683,0.068146,277.391571,14.131001,0.681463,-131.485687,0.068354,0.000000
79.870003,62.363823,-131.441208,0.015021,0.002683,0.068146,277.408142,14.131845,0.681463,-131.441208,0.068354,0.000000
80.090004,62.315044,-131.441208,0.015008,0.002683,0.068146,277.191162,14.120790,0.681463,-131.441208,0.068354,0.000000
80.310005,62.296051,-131.485687,0.015017,0.002683,0.068146,277.106689,14.116487,0.681463,-131.485687,0.068354,0.000000
80.530006,62.298660,-131.441208,0.015021,0.002683,0.068146,277.118286,14.117079,0.681463,-131.441208,0.068354,0.000000
80.750008,62.283394,-131.441208,0.015034,0.002683,0.068146,277.050385,14.113619,0.681463,-131.441208,0.068354,0.000000
80.970001,62.276688,-131.441208,0.015017,0.002683,0.068146,277.020538,14.112099,0.681463,-131.441208,0.068354,0.000000
81.190002,62.259560,-131.396729,0.015017,0.002683,0.068146,276.944366,14.108218,0.681463,-131.396729,0.068354,0.000000
81.410004,62.248760,-131.485687,0.015030,0.002683,0.068146,276.896301,14.105770,0.681463,-131.485687,0.068354,0.000000
81.630005,62.228279,-131.441208,0.015013,0.002683,0.068146,276.805206,14.101130,0.681463,-131.441208,0.068354,0.000000
81.850006,62.210407,-131.396729,0.015039,0.002683,0.068146,276.725708,14.097079,0.681463,-131.396729,0.068354,0.000000
82.070007,62.208172,-131.352249,0.015000,0.002683,0.068146,276.715759,14.096573,0.681463,-131.352249,0.068354,0.000000
82.290001,62.186947,-131.352249,0.015000,0.002683,0.068146,276.621368,14.091763,0.681463,-131.352249,0.068354,0.000000
82.510002,62.170189,-131.396729,0.015030,0.002683,0.068146,276.546814,14.087966,0.681463,-131.396729,0.068354,0.000000
82.730003,62.161255,-131.441208,0.015034,0.002683,0.068146,276.507080,14.085941,0.681463,-131.441208,0.068354,0.000000
82.950005,62.141518,-131.352249,0.015013,0.002683,0.068146,276.419281,14.081470,0.681463,-131.352249,0.068354,0.000000
83.170006,62.132580,-131.352249,0.014991,0.002683,0.068146,276.379517,14.079444,0.681463,-131.352249,0.068354,0.000000
83.390007,62.121037,-131.307770,0.015021,0.002683,0.068146,276.328186,14.076828,0.681463,-131.307770,0.068354,0.000000
83.610001,62.096462,-131.352249,0.015013,0.002683,0.068146,276.218872,14.071259,0.681463,-131.352249,0.068354,0.000000
83.830002,62.097950,-131.307770,0.015008,0.002683,0.068146,276.225464,14.071596,0.681463,-131.307770,0.068354,0.000000
84.050003,62.097206,-131.218811,0.015004,0.002683,0.068146,276.222168,14.071427,0.681463,-131.218811,0.068354,0.000000
84.270004,62.062202,-131.218811,0.015013,0.002683,0.068146,276.066467,14.063496,0.681463,-131.218811,0.068354,0.000000
84.490005,62.062202,-131.307770,0.015013,0.002683,0.068146,276.066467,14.063496,0.681463,-131.307770,0.068354,0.000000
84.710007,62.037624,-131.307770,0.015013,0.002683,0.068146,275.957123,14.057926,0.681463,-131.307770,0.068354,0.000000
84.930000,62.033531,-131.352249,0.015000,0.002683,0.068146,275.938934,14.056999,0.681463,-131.352249,0.068354,0.000000
85.150002,62.021988,-131.263290,0.014995,0.002683,0.068146,275.887573,14.054384,0.681463,-131.263290,0.068354,0.000000
85.370003,62.019379,-131.174332,0.015026,0.002683,0.068146,275.875977,14.053792,0.681463,-131.174332,0.068354,0.000000
85.590004,61.984005,-131.218811,0.015004,0.002683,0.068146,275.718628,14.045776,0.681463,-131.218811,0.068354,0.000000
85.810005,61.984379,-131.218811,0.015021,0.002683,0.068146,275.720276,14.045861,0.681463,-131.218811,0.068354,0.000000
86.030006,61.969482,-131.129837,0.015026,0.002683,0.068146,275.654022,14.042485,0.681463,-131.129837,0.068354,0.000000
86.250008,61.947884,-131.174332,0.015004,0.002683,0.068146,275.557953,14.037592,0.681463,-131.174332,0.068354,0.000000
86.470001,61.950863,-131.129837,0.014983,0.002683,0.068146,275.571198,14.038266,0.681463,-131.129837,0.068354,0.000000
86.690002,61.936714,-131.218811,0.015043,0.002683,0.068146,275.508270,14.035061,0.681463,-131.218811,0.068354,0.000000
86.910004,61.919212,-131.174332,0.015008,0.002683,0.068146,275.430420,14.031094,0.681463,-131.174332,0.068354,0.000000
87.130005,61.905060,-131.174332,0.015017,0.002683,0.068146,275.367462,14.027886,0.681463,-131.174332,0.068354,0.000000
87.350006,61.902454,-131.174332,0.015013,0.002683,0.068146,275.355865,14.027297,0.681463,-131.174332,0.068354,0.000000
87.570007,61.893147,-131.085358,0.014995,0.002683,0.068146,275.314453,14.025187,0.681463,-131.085358,0.068354,0.000000
87.790001,61.880856,-131.085358,0.015021,0.002683,0.068146,275.259796,14.022403,0.681463,-131.085358,0.068354,0.000000
88.010002,61.868942,-131.174332,0.015013,0.002683,0.068146,275.206787,14.019703,0.681463,-131.174332,0.068354,0.000000
88.230003,61.868198,-131.040878,0.015039,0.002683,0.068146,275.203491,14.019534,0.681463,-131.040878,0.068354,0.000000
88.450005,61.849949,-131.129837,0.015013,0.002683,0.068146,275.122314,14.015398,0.681463,-131.129837,0.068354,0.000000
88.670006,61.844364,-131.040878,0.015017,0.002683,0.068146,275.097473,14.014132,0.681463,-131.040878,0.068354,0.000000
88.890007,61.833565,-130.996399,0.015039,0.002683,0.068146,275.049438,14.011686,0.681463,-130.996399,0.068354,0.000000
89.110001,61.820534,-131.085358,0.015000,0.002683,0.068146,274.991455,14.008733,0.681463,-131.085358,0.068354,0.000000
89.330002,61.800426,-131.040878,0.015017,0.002683,0.068146,274.902039,14.004176,0.681463,-131.040878,0.068354,0.000000
89.550003,61.787018,-130.951920,0.015039,0.002683,0.068146,274.842377,14.001138,0.681463,-130.951920,0.068354,0.000000
89.770004,61.783669,-130.951920,0.014991,0.002683,0.068146,274.827484,14.000379,0.681463,-130.951920,0.068354,0.000000
89.990005,61.773987,-130.951920,0.015034,0.002683,0.068146,274.784424,13.998186,0.681463,-130.951920,0.068354,0.000000
90.210007,61.768402,-130.996399,0.015008,0.002683,0.068146,274.759583,13.996921,0.681463,-130.996399,0.068354,0.000000
90.430008,61.759838,-131.085358,0.015000,0.002683,0.068146,274.721466,13.994979,0.681463,-131.085358,0.068354,0.000000
90.650002,61.733025,-130.996399,0.015008,0.002683,0.068146,274.602203,13.988903,0.681463,-130.996399,0.068354,0.000000
90.870003,61.738239,-130.907440,0.015047,0.002683,0.068146,274.625397,13.990085,0.681463,-130.907440,0.068354,0.000000
91.090004,61.726696,-130.951920,0.015021,0.002683,0.068146,274.574066,13.987470,0.681463,-130.951920,0.068354,0.000000
91.310005,61.708076,-130.951920,0.015021,0.002683,0.068146,274.491241,13.983250,0.681463,-130.951920,0.068354,0.000000
91.530006,61.702118,-130.951920,0.015004,0.002683,0.068146,274.464722,13.981900,0.681463,-130.951920,0.068354,0.000000
91.600006,61.701374,-130.907440,0.015000,0.002683,0.068146,274.461426,13.981731,0.681463,-130.907440,0.068354,0.000000