File: Data/New old I18 5 new align_08182023_120847.csv
Time (sec),S:Load (lbs),S:HL1 (DIM),S:LVDT (in),S:Position (in),Ch:Position (mm),Ch:Load (N),Ch:Stress (MPa),Ch:Strain (mm/mm),Ch:HL1 (DIM),Set Point (),Cycles ()
0.110000,0.007446,-41.901054,-0.000026,-0.000000,-0.000000,0.033123,0.001687,-0.000000,-41.901054,0.000026,0.000000
0.510000,-0.000000,-41.901054,0.000009,0.000059,0.001508,-0.000000,-0.000000,0.015079,-41.901054,0.002020,0.000000
0.910000,0.024208,-41.945538,-0.000013,0.000296,0.007518,0.107683,0.005486,0.075183,-41.945538,0.008680,0.000000
1.310000,0.018990,-41.945538,0.000293,0.000558,0.014169,0.084470,0.004303,0.141691,-41.945538,0.015341,0.000000
1.710000,0.026436,-41.990017,0.000535,0.000821,0.020865,0.117593,0.005990,0.208654,-41.990017,0.022017,0.000000
2.110000,0.021599,-41.945538,0.000815,0.001085,0.027568,0.096076,0.004894,0.275677,-41.945538,0.028679,0.000000
2.510000,0.026070,-41.990017,0.001091,0.001345,0.034159,0.115964,0.005907,0.341594,-41.990017,0.035339,0.000000
2.910000,0.044312,-42.034500,0.001350,0.001602,0.040689,0.197107,0.010041,0.406891,-42.034500,0.041999,0.000000
3.310000,0.050270,-42.034500,0.001621,0.001862,0.047288,0.223612,0.011391,0.472885,-42.034500,0.048677,0.000000
3.710000,0.038353,-42.034500,0.001897,0.002127,0.054036,0.170603,0.008691,0.540362,-42.034500,0.055337,0.000000
4.110000,0.042824,-42.078979,0.002156,0.002383,0.060540,0.190490,0.009704,0.605402,-42.078979,0.061997,0.000000
4.510000,0.014893,-42.034500,0.002414,0.002654,0.067418,0.066245,0.003375,0.674181,-42.034500,0.068658,0.000000
4.910000,0.053619,-41.990017,0.002695,0.002916,0.074078,0.238511,0.012150,0.740780,-41.990017,0.075318,0.000000
5.310000,0.053619,-42.034500,0.002979,0.003185,0.080903,0.238511,0.012150,0.809029,-42.034500,0.081996,0.000000
5.710000,0.049156,-42.034500,0.003251,0.003446,0.087520,0.218658,0.011139,0.875204,-42.034500,0.088656,0.000000
6.110000,0.017128,-42.034500,0.003501,0.003711,0.094250,0.076189,0.003881,0.942499,-42.034500,0.095316,0.000000
6.510000,-0.000000,-42.078979,0.003751,0.003970,0.100849,-0.000000,-0.000000,1.008493,-42.078979,0.101976,0.000000
6.910000,-0.009308,-42.078979,0.004010,0.004231,0.107458,-0.041403,-0.002109,1.074577,-42.078979,0.108637,0.000000
7.310000,0.045799,-42.078979,0.004303,0.004494,0.114143,0.203725,0.010378,1.141433,-42.078979,0.115314,0.000000
7.710001,0.048782,-42.123459,0.004553,0.004756,0.120812,0.216995,0.011054,1.208123,-42.123459,0.121975,0.000000
8.110001,0.054741,-42.078979,0.004842,0.005019,0.127472,0.243500,0.012404,1.274722,-42.078979,0.128635,0.000000
8.510000,0.042824,-42.167942,0.005113,0.005283,0.134194,0.190490,0.009704,1.341942,-42.167942,0.135295,0.000000
8.910001,0.055481,-42.078979,0.005389,0.005541,0.140742,0.246792,0.012572,1.407421,-42.078979,0.141955,0.000000
9.310000,0.088623,-42.167942,0.005657,0.005798,0.147272,0.394215,0.020082,1.472718,-42.167942,0.148633,0.000000
9.710000,0.086388,-42.123459,0.005911,0.006060,0.153915,0.384271,0.019576,1.539150,-42.123459,0.155293,0.000000
10.110001,0.078568,-42.167942,0.006213,0.006329,0.160766,0.349486,0.017804,1.607657,-42.167942,0.161954,0.000000
10.510000,0.066284,-42.167942,0.006476,0.006585,0.167261,0.294847,0.015020,1.672606,-42.167942,0.168614,0.000000
10.910001,0.053253,-42.167942,0.006786,0.006855,0.174113,0.236882,0.012067,1.741127,-42.167942,0.175274,0.000000
11.310000,0.082664,-42.212421,0.007019,0.007116,0.180738,0.367710,0.018732,1.807378,-42.212421,0.181952,0.000000
11.710001,0.082664,-42.167942,0.007308,0.007381,0.187476,0.367710,0.018732,1.874764,-42.167942,0.188612,0.000000
12.110001,0.088997,-42.167942,0.007601,0.007643,0.194127,0.395878,0.020167,1.941273,-42.167942,0.195272,0.000000
12.510000,0.064796,-42.212421,0.007869,0.007906,0.200814,0.288229,0.014683,2.008144,-42.212421,0.201933,0.000000
12.910001,0.030159,-42.212421,0.008119,0.008166,0.207414,0.134154,0.006834,2.074138,-42.212421,0.208610,0.000000
13.310000,0.020477,-42.301384,0.008399,0.008430,0.214118,0.091088,0.004640,2.141176,-42.301384,0.215271,0.000000
13.710001,0.075592,-42.301384,0.008670,0.008691,0.220761,0.336250,0.017129,2.207608,-42.301384,0.221931,0.000000
14.110001,0.067398,-42.212421,0.008955,0.008955,0.227456,0.299802,0.015273,2.274555,-42.212421,0.228591,0.000000
14.510000,0.081177,-42.212421,0.009227,0.009216,0.234081,0.361092,0.018395,2.340806,-42.212421,0.235251,0.000000
14.910001,0.064423,-42.256905,0.009507,0.009481,0.240810,0.286566,0.014598,2.408102,-42.256905,0.241929,0.000000
15.310000,0.089371,-42.301384,0.009770,0.009742,0.247437,0.397541,0.020252,2.474368,-42.301384,0.248589,0.000000
15.710001,0.103523,-42.345867,0.010050,0.009997,0.253923,0.460494,0.023459,2.539226,-42.345867,0.255250,0.000000
16.110001,0.103149,-42.345867,0.010305,0.010261,0.260617,0.458832,0.023374,2.606173,-42.345867,0.261910,0.000000
16.510000,0.100914,-42.301384,0.010580,0.010529,0.267444,0.448888,0.022867,2.674437,-42.301384,0.268570,0.000000
16.910002,0.083412,-42.390347,0.010856,0.010791,0.274085,0.371036,0.018901,2.740855,-42.390347,0.275248,0.000000
17.310001,0.086021,-42.390347,0.011128,0.011056,0.280815,0.382642,0.019493,2.808150,-42.390347,0.281908,0.000000
17.710001,0.102776,-42.434826,0.011421,0.011317,0.287442,0.457169,0.023289,2.874416,-42.434826,0.288568,0.000000
18.110001,0.079689,-42.390347,0.011697,0.011581,0.294153,0.354474,0.018058,2.941530,-42.390347,0.295229,0.000000
18.510000,0.094208,-42.390347,0.011956,0.011842,0.300796,0.419057,0.021348,3.007962,-42.390347,0.301889,0.000000
18.910002,0.074478,-42.390347,0.012240,0.012105,0.307474,0.331295,0.016877,3.074743,-42.390347,0.308567,0.000000
19.310001,0.049522,-42.434826,0.012508,0.012365,0.314074,0.220287,0.011222,3.140736,-42.434826,0.315227,0.000000
19.710001,0.052505,-42.434826,0.012771,0.012630,0.320794,0.233556,0.011898,3.207941,-42.434826,0.321887,0.000000
20.110001,0.094208,-42.434826,0.013042,0.012892,0.327463,0.419057,0.021348,3.274631,-42.434826,0.328547,0.000000
20.510000,0.106125,-42.479309,0.013344,0.013155,0.334141,0.472067,0.024048,3.341411,-42.479309,0.335208,0.000000
20.910002,0.107246,-42.523788,0.013611,0.013415,0.340733,0.477056,0.024302,3.407329,-42.523788,0.341885,0.000000
21.310001,0.119164,-42.479309,0.013874,0.013679,0.347435,0.530066,0.027003,3.474352,-42.479309,0.348546,0.000000
21.710001,0.163101,-42.479309,0.014103,0.013939,0.354044,0.725510,0.036959,3.540436,-42.479309,0.355206,0.000000
22.110001,0.204063,-42.523788,0.014323,0.014196,0.360566,0.907719,0.046241,3.605658,-42.523788,0.361866,0.000000
22.510000,0.214485,-42.568272,0.014560,0.014459,0.367260,0.954078,0.048603,3.672605,-42.568272,0.368544,0.000000
22.910002,0.231613,-42.523788,0.014793,0.014727,0.374069,1.030267,0.052484,3.740687,-42.523788,0.375204,0.000000
23.310001,0.229012,-42.523788,0.015030,0.014991,0.380773,1.018694,0.051895,3.807725,-42.523788,0.381864,0.000000
23.710001,0.249115,-42.523788,0.015297,0.015254,0.387458,1.108119,0.056450,3.874582,-42.523788,0.388526,0.000000
24.110001,0.312790,-42.523788,0.015556,0.015515,0.394083,1.391359,0.070879,3.940833,-42.523788,0.395185,0.000000
24.510000,0.330666,-42.568272,0.015832,0.015778,0.400770,1.470874,0.074930,4.007704,-42.568272,0.401863,0.000000
24.910002,0.444244,-42.612751,0.016078,0.016038,0.407353,1.976098,0.100667,4.073531,-42.612751,0.408523,0.000000
25.310001,0.553345,-42.612751,0.016323,0.016302,0.414064,2.461400,0.125390,4.140645,-42.612751,0.415183,0.000000
25.710001,0.541061,-42.568272,0.016487,-0.000000,-0.000000,2.406761,0.122606,-0.000000,-42.568272,0.000216,0.000000
26.110001,0.658730,-42.612751,0.016496,-0.000000,-0.000000,2.930175,0.149270,-0.000000,-42.612751,0.000268,0.000000
26.510002,0.603241,-42.612751,0.016500,-0.000000,-0.000000,2.683350,0.136696,-0.000000,-42.612751,0.000936,0.000000
26.910002,0.669525,-42.612751,0.016487,0.000025,0.000642,2.978197,0.151717,0.006419,-42.612751,0.001603,0.000000
27.310001,0.708626,-42.701714,0.016504,0.000046,0.001170,3.152125,0.160577,0.011703,-42.701714,0.002271,0.000000
27.710001,0.747353,-42.612751,0.016535,0.000078,0.001994,3.324390,0.169353,0.019939,-42.612751,0.002931,0.000000
28.110001,0.730225,-42.657230,0.016552,0.000102,0.002592,3.248201,0.165471,0.025919,-42.657230,0.003599,0.000000
28.510002,0.773415,-42.612751,0.016556,0.000123,0.003113,3.440320,0.175258,0.031127,-42.612751,0.004266,0.000000
28.910002,0.839699,-42.657230,0.016591,0.000155,0.003936,3.735167,0.190278,0.039363,-42.657230,0.004934,0.000000
29.310001,0.897789,-42.657230,0.016617,0.000182,0.004613,3.993565,0.203442,0.046130,-42.657230,0.005602,0.000000
29.710001,0.918640,-42.657230,0.016638,0.000209,0.005299,4.086316,0.208167,0.052989,-42.657230,0.006269,0.000000
30.110001,0.900772,-42.657230,0.016647,0.000232,0.005897,4.006835,0.204118,0.058969,-42.657230,0.006937,0.000000
30.510002,1.008385,-42.657230,0.016686,0.000260,0.006616,4.485519,0.228503,0.066160,-42.657230,0.007605,0.000000
30.910002,1.043762,-42.701714,0.016681,0.000282,0.007172,4.642886,0.236520,0.071716,-42.701714,0.008265,0.000000
31.310001,1.133133,-42.701714,0.016699,0.000315,0.007995,5.040427,0.256772,0.079952,-42.701714,0.008932,0.000000
31.710001,1.189362,-42.701714,0.016742,0.000340,0.008637,5.290545,0.269513,0.086371,-42.701714,0.009600,0.000000
32.110001,1.181908,-42.701714,0.016742,0.000361,0.009175,5.257388,0.267824,0.091746,-42.701714,0.010268,0.000000
32.510002,1.366982,-42.746193,0.016798,0.000393,0.009982,6.080637,0.309762,0.099815,-42.746193,0.010935,0.000000
32.910000,1.423584,-42.701714,0.016780,0.000413,0.010493,6.332418,0.322589,0.104932,-42.701714,0.011603,0.000000
33.310001,1.482788,-42.701714,0.016815,0.000428,0.010866,6.595771,0.336005,0.108657,-42.701714,0.012271,0.000000
33.710003,1.627640,-42.701714,0.016832,0.000467,0.011872,7.240103,0.368828,0.118725,-42.701714,0.012938,0.000000
34.110001,1.689827,-42.790676,0.016871,0.000491,0.012470,7.516726,0.382920,0.124705,-42.790676,0.013598,0.000000
34.510002,1.810844,-42.746193,0.016910,0.000521,0.013224,8.055038,0.410343,0.132244,-42.746193,0.014266,0.000000
34.910000,1.868568,-42.746193,0.016923,0.000539,0.013685,8.311808,0.423424,0.136847,-42.746193,0.014934,0.000000
35.310001,2.030174,-42.790676,0.016953,0.000575,0.014595,9.030666,0.460044,0.145946,-42.790676,0.015601,0.000000
35.710003,2.093109,-42.746193,0.016966,0.000602,0.015297,9.310615,0.474305,0.152970,-42.746193,0.016269,0.000000
36.110001,2.188065,-42.790676,0.016987,0.000627,0.015913,9.732997,0.495823,0.159132,-42.790676,0.016937,0.000000
36.510002,2.289719,-42.790676,0.017013,0.000652,0.016555,10.185177,0.518858,0.165551,-42.790676,0.017604,0.000000
36.910000,2.425262,-42.746193,0.017039,0.000677,0.017197,10.788106,0.549572,0.171970,-42.746193,0.018272,0.000000
37.310001,2.589104,-42.835155,0.017065,0.000710,0.018037,11.516909,0.586699,0.180373,-42.835155,0.018940,0.000000
37.710003,2.617035,-42.790676,0.017082,0.000732,0.018602,11.641152,0.593029,0.186020,-42.790676,0.019598,0.000000
38.110001,2.724281,-42.835155,0.017117,0.000757,0.019226,12.118209,0.617331,0.192258,-42.835155,0.020267,0.000000
38.510002,2.871735,-42.835155,0.017151,0.000785,0.019928,12.774114,0.650744,0.199282,-42.835155,0.020935,0.000000
38.910004,2.978981,-42.835155,0.017130,0.000802,0.020370,13.251169,0.675047,0.203703,-42.835155,0.021603,0.000000
39.310001,3.155113,-42.879639,0.017203,0.000839,0.021317,14.034644,0.714959,0.213165,-42.879639,0.022270,0.000000
39.710003,3.266449,-42.879639,0.017212,0.000864,0.021940,14.529891,0.740188,0.219403,-42.879639,0.022938,0.000000
40.110001,3.326401,-42.879639,0.017220,0.000883,0.022417,14.796570,0.753773,0.224172,-42.879639,0.023606,0.000000
40.510002,3.451523,-42.879639,0.017268,0.000908,0.023076,15.353140,0.782126,0.230757,-42.879639,0.024273,0.000000
40.910004,3.660049,-42.924118,0.017259,0.000936,0.023778,16.280712,0.829379,0.237782,-42.924118,0.024932,0.000000
41.310001,3.797081,-42.968597,0.017332,0.000970,0.024629,16.890261,0.860431,0.246291,-42.968597,0.025600,0.000000
41.710003,3.906189,-42.924118,0.017350,0.000991,0.025167,17.375597,0.885155,0.251665,-42.924118,0.026267,0.000000
42.110001,4.083809,-42.968597,0.017375,0.001020,0.025920,18.165689,0.925404,0.259205,-42.968597,0.026936,0.000000
42.510002,4.205574,-42.968597,0.017384,0.001045,0.026537,18.707327,0.952997,0.265367,-42.968597,0.027604,0.000000
42.910004,4.362717,-43.013081,0.017419,0.001072,0.027222,19.406334,0.988606,0.272225,-43.013081,0.028272,0.000000
43.310001,4.474426,-42.924118,0.017449,0.001098,0.027890,19.903242,1.013919,0.278901,-42.924118,0.028939,0.000000
43.710003,4.585022,-42.968597,0.017449,0.001123,0.028531,20.395197,1.038981,0.285305,-42.968597,0.029607,0.000000
44.110001,4.695618,-43.013081,0.017513,0.001152,0.029268,20.887150,1.064042,0.292678,-43.013081,0.030266,0.000000
44.510002,4.789452,-43.057560,0.017500,0.001172,0.029780,21.304544,1.085305,0.297796,-43.057560,0.030933,0.000000
44.910004,4.978996,-43.057560,0.017574,0.001203,0.030552,22.147682,1.128257,0.305517,-43.057560,0.031601,0.000000
45.310001,5.056076,-43.013081,0.017574,0.001231,0.031272,22.490549,1.145723,0.312723,-43.013081,0.032268,0.000000
45.710003,5.176353,-43.057560,0.017621,0.001256,0.031896,23.025570,1.172979,0.318961,-43.057560,0.032936,0.000000
46.110001,5.347267,-43.102043,0.017621,0.001279,0.032494,23.785831,1.211708,0.324941,-43.102043,0.033604,0.000000
46.510002,5.433289,-43.102043,0.017630,0.001305,0.033154,24.168474,1.231201,0.331542,-43.102043,0.034273,0.000000
46.910004,5.651497,-43.146523,0.017664,0.001335,0.033908,25.139114,1.280648,0.339081,-43.146523,0.034941,0.000000
47.310001,5.677933,-43.102043,0.017729,0.001359,0.034506,25.256706,1.286638,0.345061,-43.102043,0.035599,0.000000
47.710003,5.763580,-43.146523,0.017742,0.001386,0.035192,25.637686,1.306046,0.351920,-43.146523,0.036267,0.000000
48.110001,5.935616,-43.146523,0.017768,0.001414,0.035911,26.402937,1.345030,0.359111,-43.146523,0.036935,0.000000
48.510002,5.965782,-43.191002,0.017785,0.001432,0.036371,26.537125,1.351866,0.363713,-43.191002,0.037602,0.000000
48.910004,6.218620,-43.102043,0.017815,0.001465,0.037221,27.661804,1.409159,0.372207,-43.102043,0.038270,0.000000
49.310001,6.270378,-43.146523,0.017828,0.001488,0.037793,27.892035,1.420888,0.377929,-43.146523,0.038937,0.000000
49.710003,6.302406,-43.146523,0.017867,0.001510,0.038358,28.034504,1.428146,0.383576,-43.146523,0.039605,0.000000
50.110001,6.651314,-43.146523,0.017888,0.001547,0.039284,29.586521,1.507209,0.392842,-43.146523,0.040273,0.000000
50.510002,6.557106,-43.191002,0.017914,0.001562,0.039675,29.167465,1.485862,0.396748,-43.191002,0.040942,0.000000
50.910004,6.807716,-43.191002,0.017936,0.001594,0.040498,30.282234,1.542651,0.404984,-43.191002,0.041601,0.000000
51.310001,6.844208,-43.191002,0.017962,0.001620,0.041158,30.444557,1.550920,0.411585,-43.191002,0.042268,0.000000
51.710003,7.032623,-43.146523,0.018005,0.001647,0.041843,31.282671,1.593615,0.418428,-43.146523,0.042936,0.000000
52.110001,7.120506,-43.235485,0.018039,0.001674,0.042520,31.673594,1.613530,0.425195,-43.235485,0.043604,0.000000
52.510002,7.305573,-43.235485,0.018039,0.001702,0.043222,32.496811,1.655466,0.432220,-43.235485,0.044271,0.000000
52.910004,7.388985,-43.235485,0.018074,0.001730,0.043950,32.867844,1.674368,0.439502,-43.235485,0.044939,0.000000
53.310001,7.352119,-43.235485,0.018083,0.001748,0.044410,32.703861,1.666014,0.444104,-43.235485,0.045606,0.000000
53.710003,7.537933,-43.279964,0.018143,0.001776,0.045122,33.530403,1.708120,0.451220,-43.279964,0.046274,0.000000
54.110004,7.680183,-43.279964,0.018164,0.001801,0.045737,34.163162,1.740354,0.457367,-43.279964,0.046934,0.000000
54.510002,7.795242,-43.279964,0.018169,0.001821,0.046257,34.674969,1.766427,0.462575,-43.279964,0.047602,0.000000
54.910004,7.972122,-43.279964,0.018212,0.001856,0.047151,35.461769,1.806509,0.471507,-43.279964,0.048270,0.000000
55.310001,8.083092,-43.279964,0.018208,0.001881,0.047767,35.955387,1.831655,0.477669,-43.279964,0.048937,0.000000
55.710003,8.225708,-43.279964,0.018259,0.001909,0.048495,36.589775,1.863972,0.484951,-43.279964,0.049605,0.000000
56.110004,8.253265,-43.279964,0.018285,0.001929,0.048989,36.712357,1.870217,0.489887,-43.279964,0.050272,0.000000
56.510002,8.496796,-43.235485,0.018281,0.001958,0.049735,37.795635,1.925401,0.497350,-43.235485,0.050940,0.000000
56.910004,8.643135,-43.324448,0.018328,0.001988,0.050507,38.446587,1.958562,0.505072,-43.324448,0.051608,0.000000
57.310001,8.604042,-43.324448,0.018358,0.002010,0.051045,38.272690,1.949704,0.510446,-43.324448,0.052268,0.000000
57.710003,8.857628,-43.324448,0.018363,0.002043,0.051903,39.400696,2.007167,0.519030,-43.324448,0.052936,0.000000
58.110004,8.890022,-43.324448,0.018406,0.002063,0.052389,39.544796,2.014508,0.523890,-43.324448,0.053603,0.000000
58.510002,9.149567,-43.324448,0.018436,0.002096,0.053229,40.699306,2.073321,0.532292,-43.324448,0.054271,0.000000
58.910004,9.175255,-43.324448,0.018449,0.002120,0.053845,40.813572,2.079142,0.538454,-43.324448,0.054939,0.000000
59.310001,9.339844,-43.324448,0.018458,0.002147,0.054539,41.545700,2.116439,0.545388,-43.324448,0.055606,0.000000
59.710003,9.428841,-43.368927,0.018492,0.002174,0.055216,41.941578,2.136606,0.552156,-43.368927,0.056274,0.000000
60.110004,9.465706,-43.368927,0.018522,0.002192,0.055667,42.105564,2.144959,0.556667,-43.368927,0.056941,0.000000
60.510002,9.758392,-43.368927,0.018527,0.002226,0.056551,43.407497,2.211283,0.565509,-43.368927,0.057600,0.000000
60.910004,9.738289,-43.368927,0.018578,0.002248,0.057088,43.318073,2.206728,0.570883,-43.368927,0.058268,0.000000
61.310001,9.872337,-43.368927,0.018587,0.002275,0.057791,43.914349,2.237103,0.577908,-43.368927,0.058937,0.000000
61.710003,10.106934,-43.457890,0.018617,0.002305,0.058537,44.957886,2.290264,0.585372,-43.457890,0.059605,0.000000
62.110004,10.116241,-43.457890,0.018617,0.002322,0.058979,44.999290,2.292373,0.589793,-43.457890,0.060272,0.000000
62.510002,10.332222,-43.502369,0.018682,0.002356,0.059838,45.960018,2.341315,0.598377,-43.502369,0.060940,0.000000
62.910004,10.357170,-43.413406,0.018708,0.002380,0.060445,46.070995,2.346968,0.604448,-43.413406,0.061607,0.000000
63.310001,10.649483,-43.413406,0.018712,0.002408,0.061156,47.371265,2.413207,0.611563,-43.413406,0.062275,0.000000
63.710003,10.642036,-43.413406,0.018742,0.002429,0.061703,47.338142,2.411520,0.617029,-43.413406,0.062943,0.000000
64.110001,10.812950,-43.502369,0.018798,0.002455,0.062352,48.098404,2.450249,0.623524,-43.502369,0.063601,0.000000
64.510002,11.003235,-43.457890,0.018794,0.002488,0.063203,48.944832,2.493369,0.632032,-43.457890,0.064269,0.000000
64.910004,11.079575,-43.502369,0.018824,0.002513,0.063827,49.284409,2.510668,0.638270,-43.502369,0.064937,0.000000
65.310005,11.356987,-43.546852,0.018863,0.002546,0.064660,50.518402,2.573530,0.646596,-43.546852,0.065606,0.000000
65.710007,11.340233,-43.502369,0.018889,0.002564,0.065137,50.443874,2.569734,0.651365,-43.502369,0.066274,0.000000
66.110001,11.561790,-43.546852,0.018919,0.002592,0.065839,51.429413,2.619939,0.658390,-43.546852,0.066941,0.000000
66.510002,11.704041,-43.546852,0.018923,0.002622,0.066594,52.062172,2.652174,0.665945,-43.546852,0.067609,0.000000
66.910004,11.789314,-43.502369,0.018958,0.002646,0.067209,52.441490,2.671497,0.672091,-43.502369,0.068276,0.000000
67.310005,11.989647,-43.546852,0.018971,0.002674,0.067921,53.332615,2.716893,0.679207,-43.546852,0.068935,0.000000
67.710007,12.033592,-43.591331,0.018988,0.002695,0.068458,53.528091,2.726851,0.684582,-43.591331,0.069603,0.000000
68.110001,12.223129,-43.546852,0.019040,0.002718,0.069040,54.371193,2.769801,0.690395,-43.546852,0.070270,0.000000
68.510002,12.327019,-43.502369,0.019044,0.002750,0.069846,54.833317,2.793342,0.698465,-43.502369,0.070938,0.000000
68.910004,12.377289,-43.591331,0.019070,0.002772,0.070401,55.056931,2.804734,0.704006,-43.591331,0.071606,0.000000
69.310005,12.742584,-43.635815,0.019126,0.002806,0.071277,56.681847,2.887511,0.712771,-43.635815,0.072275,0.000000
69.710007,12.708328,-43.591331,0.019135,0.002828,0.071824,56.529469,2.879748,0.718237,-43.591331,0.072942,0.000000
70.110001,12.912018,-43.635815,0.019147,0.002853,0.072457,57.435524,2.925905,0.724565,-43.635815,0.073610,0.000000
70.510002,13.094849,-43.591331,0.019165,0.002881,0.073168,58.248795,2.967335,0.731681,-43.591331,0.074269,0.000000
70.910004,13.291092,-43.680294,0.019191,0.002907,0.073843,59.121731,3.011804,0.738433,-43.680294,0.074936,0.000000
71.310005,13.305984,-43.635815,0.019212,0.002927,0.074347,59.187977,3.015179,0.743474,-43.635815,0.075604,0.000000
71.710007,13.558456,-43.680294,0.019255,0.002956,0.075083,60.311028,3.072390,0.750832,-43.680294,0.076272,0.000000
72.110001,13.766609,-43.680294,0.019281,0.002983,0.075769,61.236935,3.119558,0.757691,-43.680294,0.076939,0.000000
72.510002,13.940506,-43.769257,0.019329,0.003011,0.076481,62.010468,3.158964,0.764806,-43.769257,0.077607,0.000000
72.910004,13.921143,-43.724773,0.019320,0.003035,0.077088,61.924335,3.154576,0.770877,-43.724773,0.078275,0.000000
73.310005,14.365387,-43.724773,0.019363,0.003068,0.077928,63.900433,3.255243,0.779280,-43.724773,0.078944,0.000000
73.710007,14.438744,-43.724773,0.019389,0.003088,0.078440,64.226738,3.271866,0.784397,-43.724773,0.079602,0.000000
74.110001,14.645035,-43.680294,0.019419,0.003120,0.079256,65.144371,3.318612,0.792557,-43.680294,0.080270,0.000000
74.510002,14.706108,-43.769257,0.019462,0.003141,0.079775,65.416039,3.332452,0.797750,-43.769257,0.080938,0.000000
74.910004,14.994324,-43.724773,0.019467,0.003172,0.080573,66.698082,3.397763,0.805728,-43.724773,0.081605,0.000000
75.310005,15.150345,-43.813736,0.019488,0.003195,0.081154,67.392097,3.433117,0.811542,-43.813736,0.082273,0.000000
75.710007,15.146248,-43.769257,0.019488,0.003212,0.081596,67.373878,3.432189,0.815963,-43.769257,0.082941,0.000000
76.110001,15.653046,-43.769257,0.019523,0.003247,0.082464,69.628227,3.547031,0.824638,-43.769257,0.083608,0.000000
76.510002,15.561821,-43.769257,0.019570,0.003268,0.083001,69.222435,3.526359,0.830012,-43.769257,0.084276,0.000000
76.910004,15.874237,-43.813736,0.019587,0.003298,0.083773,70.612137,3.597153,0.837734,-43.813736,0.084944,0.000000
77.310005,15.934937,-43.858219,0.019613,0.003324,0.084432,70.882141,3.610908,0.844319,-43.858219,0.085604,0.000000
77.710007,16.109581,-43.769257,0.019613,0.003346,0.084978,71.658997,3.650483,0.849785,-43.769257,0.086271,0.000000
78.110001,16.416412,-43.902699,0.019682,0.003377,0.085785,73.023849,3.720012,0.857854,-43.902699,0.086939,0.000000
78.510002,16.460724,-43.769257,0.019708,0.003402,0.086411,73.220955,3.730053,0.864107,-43.769257,0.087607,0.000000
78.910004,16.757133,-43.813736,0.019712,0.003432,0.087165,74.539452,3.797221,0.871646,-43.813736,0.088274,0.000000
79.310005,16.756760,-43.813736,0.019734,0.003452,0.087693,74.537788,3.797136,0.876930,-43.813736,0.088942,0.000000
79.710007,17.095245,-43.813736,0.019777,0.003479,0.088370,76.043449,3.873838,0.883697,-43.813736,0.089610,0.000000
80.110001,17.338036,-43.858219,0.019798,0.003513,0.089237,77.123436,3.928855,0.892372,-43.858219,0.090277,0.000000
80.510002,17.382721,-43.858219,0.019829,0.003536,0.089819,77.322205,3.938981,0.898186,-43.858219,0.090937,0.000000
80.910004,17.697372,-43.858219,0.019842,0.003565,0.090563,78.721848,4.010282,0.905635,-43.858219,0.091605,0.000000
81.310005,17.687691,-43.858219,0.019876,0.003585,0.091068,78.678780,4.008088,0.910676,-43.858219,0.092273,0.000000
81.710007,17.992668,-43.947178,0.019902,0.003614,0.091803,80.035385,4.077197,0.918034,-43.947178,0.092940,0.000000
82.110001,18.217209,-43.813736,0.019945,0.003643,0.092533,81.034195,4.128078,0.925331,-43.813736,0.093608,0.000000
82.510002,18.305084,-43.858219,0.019971,0.003669,0.093201,81.425079,4.147992,0.932008,-43.858219,0.094276,0.000000
82.910004,18.554207,-43.858219,0.019984,0.003692,0.093781,82.533234,4.204443,0.937806,-43.858219,0.094943,0.000000
83.310005,18.535583,-43.902699,0.019993,0.003712,0.094276,82.450394,4.200223,0.942757,-43.902699,0.095611,0.000000
83.710007,19.157448,-43.991661,0.020036,0.003752,0.095290,85.216583,4.341140,0.952900,-43.991661,0.096270,0.000000
84.110001,19.047226,-43.902699,0.020066,0.003772,0.095820,84.726295,4.316163,0.958199,-43.902699,0.096939,0.000000
84.510002,19.196175,-43.947178,0.020100,0.003796,0.096418,85.388847,4.349916,0.964179,-43.947178,0.097606,0.000000
84.910004,19.501144,-43.902699,0.020105,0.003827,0.097198,86.745422,4.419023,0.971976,-43.902699,0.098274,0.000000
85.310005,19.622910,-43.991661,0.020143,0.003848,0.097744,87.287064,4.446615,0.977442,-43.991661,0.098942,0.000000
85.710007,19.874634,-43.947178,0.020143,0.003878,0.098507,88.406784,4.503656,0.985072,-43.947178,0.099609,0.000000
86.110001,19.971825,-43.991661,0.020191,0.003903,0.099142,88.839111,4.525681,0.991415,-43.991661,0.100277,0.000000
86.510002,20.047043,-43.991661,0.020208,0.003924,0.099670,89.173698,4.542725,0.996699,-43.991661,0.100945,0.000000
86.910004,20.309196,-43.991661,0.020234,0.003955,0.100450,90.339821,4.602129,1.004496,-43.991661,0.101603,0.000000
87.310005,20.557564,-44.036140,0.020277,0.003979,0.101066,91.444611,4.658411,1.010658,-44.036140,0.102271,0.000000
87.710007,20.791786,-43.947178,0.020286,0.004009,0.101821,92.486481,4.711486,1.018212,-43.947178,0.102939,0.000000
88.110001,20.908340,-44.036140,0.020312,0.004033,0.102445,93.004944,4.737898,1.024450,-44.036140,0.103608,0.000000
88.510002,21.063995,-43.991661,0.020337,0.004059,0.103087,93.697334,4.773170,1.030869,-43.991661,0.104275,0.000000
88.910004,21.401733,-43.991661,0.020376,0.004088,0.103832,95.199661,4.849702,1.038318,-43.991661,0.104943,0.000000
89.310005,21.347000,-43.991661,0.020389,0.004105,0.104266,94.956200,4.837299,1.042663,-43.991661,0.105611,0.000000
89.710007,21.899223,-44.080624,0.020432,0.004144,0.105264,97.412613,4.962435,1.052640,-44.080624,0.106278,0.000000
90.110001,21.787888,-44.036140,0.020441,0.004162,0.105714,96.917366,4.937206,1.057136,-44.036140,0.106937,0.000000
90.510002,21.954338,-44.036140,0.020462,0.004186,0.106330,97.657776,4.974924,1.063298,-44.036140,0.107605,0.000000
90.910004,22.321495,-44.036140,0.020497,0.004218,0.107137,99.290970,5.058123,1.071368,-44.036140,0.108272,0.000000
91.310005,22.338249,-44.080624,0.020527,0.004236,0.107605,99.365494,5.061920,1.076046,-44.080624,0.108940,0.000000
91.710007,22.886757,-44.125103,0.020527,0.004274,0.108551,101.805382,5.186213,1.085508,-44.125103,0.109608,0.000000
92.110001,22.910957,-44.125103,0.020575,0.004296,0.109123,101.913025,5.191697,1.091231,-44.125103,0.110277,0.000000
92.510002,22.972778,-44.080624,0.020592,0.004317,0.109651,102.188019,5.205706,1.096514,-44.080624,0.110944,0.000000
92.910004,23.348869,-44.125103,0.020618,0.004350,0.110493,103.860954,5.290929,1.104932,-44.125103,0.111612,0.000000
93.310005,23.467285,-44.125103,0.020661,0.004373,0.111082,104.387695,5.317763,1.110821,-44.125103,0.112280,0.000000
93.710007,23.782684,-44.169586,0.020669,0.004402,0.111819,105.790665,5.389234,1.118194,-44.169586,0.112938,0.000000
94.110008,23.799812,-44.125103,0.020682,0.004424,0.112366,105.866852,5.393115,1.123660,-44.125103,0.113606,0.000000
94.510002,24.030685,-44.080624,0.020717,0.004452,0.113068,106.893829,5.445431,1.130684,-44.080624,0.114274,0.000000
94.910004,24.238098,-44.169586,0.020756,0.004476,0.113685,107.816444,5.492431,1.136846,-44.169586,0.114941,0.000000
95.310005,24.667068,-44.125103,0.020756,0.004508,0.114499,109.724602,5.589638,1.144991,-44.125103,0.115609,0.000000
95.710007,24.804474,-44.214066,0.020803,0.004534,0.115176,110.335808,5.620774,1.151759,-44.214066,0.116277,0.000000
96.110008,24.882301,-44.214066,0.020812,0.004555,0.115697,110.682007,5.638410,1.156967,-44.214066,0.116946,0.000000
96.510002,25.177963,-44.169586,0.020859,0.004584,0.116425,111.997177,5.705408,1.164249,-44.169586,0.117613,0.000000
96.910004,25.411072,-44.303028,0.020855,0.004608,0.117041,113.034096,5.758231,1.170411,-44.303028,0.118272,0.000000
97.310005,25.409584,-44.303028,0.020902,0.004622,0.117404,113.027473,5.757894,1.174044,-44.303028,0.118940,0.000000
97.710007,26.033676,-44.258545,0.020919,0.004663,0.118437,115.803574,5.899315,1.184369,-44.258545,0.119607,0.000000
98.110008,25.980057,-44.258545,0.020932,0.004685,0.118991,115.565063,5.887165,1.189910,-44.258545,0.120275,0.000000
98.510002,26.368439,-44.303028,0.020976,0.004716,0.119781,117.292671,5.975173,1.197813,-44.303028,0.120943,0.000000
98.910004,26.373650,-44.258545,0.020988,0.004736,0.120284,117.315849,5.976355,1.202840,-44.258545,0.121610,0.000000
99.310005,26.942635,-44.303028,0.021019,0.004769,0.121126,119.846825,6.105288,1.211257,-44.303028,0.122278,0.000000
99.710007,26.957535,-44.303028,0.021053,0.004794,0.121775,119.913101,6.108665,1.217752,-44.303028,0.122945,0.000000
100.110008,27.278519,-44.347507,0.021075,0.004822,0.122469,121.340912,6.181401,1.224686,-44.347507,0.123606,0.000000
100.510002,27.458374,-44.347507,0.021101,0.004846,0.123094,122.140945,6.222157,1.230939,-44.347507,0.124273,0.000000
100.910004,27.521675,-44.347507,0.021114,0.004868,0.123648,122.422523,6.236501,1.236480,-44.347507,0.124941,0.000000
101.310005,28.104439,-44.258545,0.021135,0.004904,0.124559,125.014786,6.368557,1.245594,-44.258545,0.125609,0.000000
101.710007,28.052307,-44.303028,0.021170,0.004926,0.125132,124.782898,6.356743,1.251317,-44.303028,0.126276,0.000000
102.110008,28.373291,-44.347507,0.021191,0.004952,0.125774,126.210701,6.429480,1.257736,-44.347507,0.126944,0.000000
102.510002,28.552773,-44.347507,0.021204,0.004976,0.126397,127.009079,6.470150,1.263973,-44.347507,0.127612,0.000000
102.910004,28.805618,-44.303028,0.021234,0.005000,0.126988,128.133789,6.527447,1.269878,-44.303028,0.128279,0.000000
103.310005,29.375343,-44.347507,0.021273,0.005036,0.127907,130.668060,6.656548,1.279067,-44.347507,0.128939,0.000000
103.710007,29.497116,-44.436470,0.021290,0.005060,0.128523,131.209732,6.684142,1.285229,-44.436470,0.129607,0.000000
104.110008,29.400665,-44.436470,0.021333,0.005077,0.128965,130.780685,6.662286,1.289650,-44.436470,0.130275,0.000000
104.510002,29.733566,-44.347507,0.021359,0.005106,0.129702,132.261505,6.737722,1.297023,-44.347507,0.130942,0.000000
104.910004,29.897415,-44.391991,0.021372,0.005127,0.130222,132.990341,6.774851,1.302216,-44.391991,0.131610,0.000000
105.310005,30.507729,-44.436470,0.021420,0.005166,0.131210,135.705154,6.913150,1.312102,-44.436470,0.132278,0.000000
105.710007,30.575134,-44.391991,0.021420,0.005186,0.131731,136.004990,6.928425,1.317310,-44.391991,0.132945,0.000000
106.110008,31.048416,-44.347507,0.021450,0.005217,0.132503,138.110260,7.035672,1.325031,-44.347507,0.133613,0.000000
106.510002,31.219337,-44.391991,0.021471,0.005241,0.133119,138.870544,7.074403,1.331193,-44.391991,0.134281,0.000000
106.910004,31.313919,-44.347507,0.021502,0.005262,0.133664,139.291275,7.095836,1.336643,-44.347507,0.134941,0.000000
107.310005,31.735817,-44.347507,0.021536,0.005293,0.134455,141.167969,7.191439,1.344546,-44.347507,0.135608,0.000000
107.710007,31.960358,-44.391991,0.021540,0.005319,0.135113,142.166779,7.242321,1.351132,-44.391991,0.136276,0.000000
108.110008,32.188248,-44.480949,0.021571,0.005348,0.135850,143.180481,7.293961,1.358505,-44.480949,0.136944,0.000000
108.510002,32.292137,-44.391991,0.021592,0.005369,0.136362,143.642593,7.317503,1.363622,-44.391991,0.137611,0.000000
108.910004,32.811600,-44.391991,0.021614,0.005400,0.137160,145.953278,7.435215,1.371601,-44.391991,0.138279,0.000000
109.310005,32.986244,-44.436470,0.021631,0.005427,0.137844,146.730148,7.474790,1.378444,-44.436470,0.138947,0.000000
109.710007,33.280792,-44.480949,0.021661,0.005452,0.138486,148.040359,7.541535,1.384863,-44.480949,0.139614,0.000000
110.110008,33.564537,-44.480949,0.021683,0.005475,0.139059,149.302521,7.605833,1.390586,-44.480949,0.140273,0.000000
110.510002,33.828918,-44.480949,0.021713,0.005501,0.139726,150.478546,7.665742,1.397262,-44.480949,0.140940,0.000000
110.910004,34.285454,-44.391991,0.021704,0.005532,0.140507,152.509308,7.769195,1.405074,-44.391991,0.141610,0.000000
111.310005,34.398277,-44.480949,0.021769,0.005555,0.141089,153.011185,7.794761,1.410888,-44.480949,0.142277,0.000000
111.710007,34.523026,-44.480949,0.021769,0.005582,0.141773,153.566086,7.823030,1.417731,-44.480949,0.142945,0.000000
112.110008,35.054024,-44.480949,0.021808,0.005610,0.142503,155.928085,7.943356,1.425028,-44.480949,0.143613,0.000000
112.510002,35.042114,-44.480949,0.021816,0.005632,0.143040,155.875107,7.940657,1.430403,-44.480949,0.144280,0.000000
112.910004,35.688553,-44.480949,0.021846,0.005663,0.143838,158.750610,8.087142,1.438381,-44.480949,0.144948,0.000000
113.310005,35.701210,-44.525433,0.021859,0.005684,0.144376,158.806915,8.090010,1.443756,-44.525433,0.145606,0.000000
113.710007,35.835266,-44.569912,0.021898,0.005708,0.144992,159.403229,8.120387,1.449918,-44.569912,0.146274,0.000000
114.110008,36.695076,-44.525433,0.021911,0.005743,0.145876,163.227844,8.315223,1.458759,-44.525433,0.146942,0.000000
114.510002,36.512985,-44.525433,0.021954,0.005760,0.146309,162.417877,8.273961,1.463089,-44.525433,0.147609,0.000000
114.910004,37.091652,-44.525433,0.021950,0.005792,0.147116,164.991913,8.405088,1.471158,-44.525433,0.148279,0.000000
115.310005,37.232780,-44.525433,0.021984,0.005818,0.147783,165.619675,8.437069,1.477835,-44.525433,0.148946,0.000000
115.710007,37.650208,-44.614395,0.022019,0.005844,0.148434,167.476486,8.531659,1.484345,-44.614395,0.149614,0.000000
116.110008,37.910866,-44.525433,0.022045,0.005869,0.149084,168.635956,8.590725,1.490840,-44.525433,0.150282,0.000000
116.510002,38.361443,-44.525433,0.022066,0.005899,0.149847,170.640213,8.692827,1.498470,-44.525433,0.150940,0.000000
116.910004,38.601250,-44.569912,0.022075,0.005926,0.150524,171.706940,8.747169,1.505238,-44.569912,0.151608,0.000000
117.310005,38.487305,-44.614395,0.022131,0.005944,0.150984,171.200089,8.721348,1.509840,-44.614395,0.152275,0.000000
117.710007,39.049583,-44.569912,0.022148,0.005972,0.151686,173.701218,8.848763,1.516865,-44.569912,0.152943,0.000000
118.110008,39.365730,-44.614395,0.022140,0.005997,0.152319,175.107513,8.920402,1.523193,-44.614395,0.153611,0.000000
118.510002,39.611496,-44.658875,0.022187,0.006020,0.152917,176.200729,8.976093,1.529173,-44.658875,0.154278,0.000000
118.910004,40.090736,-44.614395,0.022217,0.006051,0.153699,178.332504,9.084691,1.536985,-44.614395,0.154946,0.000000
119.310005,40.460503,-44.614395,0.022252,0.006077,0.154366,179.977310,9.168481,1.543662,-44.614395,0.155615,0.000000
119.710007,40.993370,-44.658875,0.022273,0.006109,0.155164,182.347610,9.289230,1.551640,-44.658875,0.156283,0.000000
120.110008,40.985924,-44.658875,0.022282,0.006128,0.155658,182.314499,9.287542,1.556576,-44.658875,0.156941,0.000000
120.510002,41.537033,-44.658875,0.022291,0.006156,0.156369,184.765945,9.412426,1.563691,-44.658875,0.157609,0.000000
120.910004,42.041969,-44.614395,0.022329,0.006189,0.157193,187.012024,9.526846,1.571927,-44.614395,0.158277,0.000000
121.310005,42.056488,-44.703358,0.022351,0.006208,0.157695,187.076599,9.530136,1.576954,-44.703358,0.158944,0.000000
121.710007,42.706284,-44.703358,0.022355,0.006241,0.158511,189.967041,9.677382,1.585114,-44.703358,0.159612,0.000000
122.110008,42.887253,-44.658875,0.022385,0.006262,0.159058,190.772034,9.718390,1.590579,-44.658875,0.160280,0.000000
122.510002,43.619339,-44.658875,0.022411,0.006295,0.159882,194.028503,9.884283,1.598815,-44.658875,0.160947,0.000000
122.910004,43.668121,-44.747837,0.022463,0.006317,0.160445,194.245499,9.895338,1.604447,-44.747837,0.161615,0.000000
123.310005,44.131348,-44.747837,0.022480,0.006345,0.161165,196.306046,10.000306,1.611654,-44.747837,0.162275,0.000000
123.710007,44.512291,-44.747837,0.022502,0.006372,0.161850,198.000565,10.086629,1.618497,-44.747837,0.162943,0.000000
124.110008,44.527184,-44.658875,0.022519,0.006388,0.162257,198.066803,10.090004,1.622569,-44.658875,0.163610,0.000000
124.510002,45.496468,-44.792316,0.022545,0.006425,0.163194,202.378403,10.309647,1.631941,-44.792316,0.164278,0.000000
124.910004,45.530357,-44.792316,0.022571,0.006448,0.163785,202.529144,10.317327,1.637845,-44.792316,0.164946,0.000000
125.310005,45.909058,-44.792316,0.022579,0.006472,0.164399,204.213684,10.403141,1.643992,-44.792316,0.165613,0.000000
125.710007,46.557732,-44.792316,0.022614,0.006501,0.165120,207.099136,10.550133,1.651198,-44.792316,0.166281,0.000000
126.110008,46.695511,-44.792316,0.022648,0.006523,0.165674,207.712006,10.581353,1.656739,-44.792316,0.166949,0.000000
126.510010,47.486801,-44.836800,0.022653,0.006557,0.166541,211.231842,10.760663,1.665414,-44.836800,0.167609,0.000000
126.910004,47.633514,-44.792316,0.022670,0.006578,0.167071,211.884460,10.793908,1.670713,-44.792316,0.168276,0.000000
127.310005,48.158928,-44.836800,0.022709,0.006604,0.167730,214.221603,10.912969,1.677299,-44.836800,0.168944,0.000000
127.710007,48.567055,-44.792316,0.022713,0.006631,0.168423,216.037048,11.005451,1.684233,-44.792316,0.169612,0.000000
128.110001,48.856758,-44.836800,0.022756,0.006653,0.168986,217.325714,11.071099,1.689865,-44.836800,0.170279,0.000000
128.510010,49.777260,-44.792316,0.022756,0.006688,0.169872,221.420303,11.279688,1.698721,-44.792316,0.170947,0.000000
128.910004,49.958977,-44.881279,0.022799,0.006710,0.170435,222.228622,11.320866,1.704353,-44.881279,0.171615,0.000000
129.310013,50.761444,-44.881279,0.022812,0.006742,0.171251,225.798187,11.502708,1.712514,-44.881279,0.172282,0.000000
129.710007,50.905548,-44.881279,0.022834,0.006763,0.171780,226.439194,11.535362,1.717797,-44.881279,0.172942,0.000000
130.110001,51.401550,-44.881279,0.022855,0.006789,0.172438,228.645508,11.647758,1.724383,-44.881279,0.173610,0.000000
130.510010,52.082245,-44.881279,0.022890,0.006818,0.173176,231.673401,11.802005,1.731756,-44.881279,0.174278,0.000000
130.910004,52.411423,-44.881279,0.022894,0.006843,0.173801,233.137650,11.876598,1.738009,-44.881279,0.174945,0.000000
131.310013,52.637825,-44.925762,0.022929,0.006866,0.174408,234.144745,11.927902,1.744080,-44.925762,0.175613,0.000000
131.710007,53.313309,-44.881279,0.022955,0.006890,0.175015,237.149445,12.080969,1.750151,-44.881279,0.176281,0.000000
132.110001,53.696106,-44.925762,0.022967,0.006914,0.175604,238.852203,12.167712,1.756040,-44.925762,0.176948,0.000000
132.510010,54.495590,-44.881279,0.022998,0.006945,0.176411,242.408493,12.348877,1.764109,-44.881279,0.177616,0.000000
132.910004,54.707474,-44.925762,0.023036,0.006967,0.176957,243.350998,12.396891,1.769575,-44.925762,0.178284,0.000000
133.310013,55.780281,-44.925762,0.023036,0.007001,0.177833,248.123077,12.639993,1.778325,-44.925762,0.178942,0.000000
133.710007,56.058067,-45.014721,0.023075,0.007024,0.178397,249.358734,12.702940,1.783972,-45.014721,0.179611,0.000000
134.110001,56.675835,-44.925762,0.023075,0.007048,0.179021,252.106705,12.842928,1.790210,-44.925762,0.180279,0.000000
134.510010,57.274979,-44.970242,0.023101,0.007078,0.179793,254.771835,12.978696,1.797931,-44.970242,0.180947,0.000000
134.910004,57.859230,-45.014721,0.023127,0.007103,0.180417,257.370697,13.111089,1.804169,-45.014721,0.181614,0.000000
135.310013,58.283363,-44.970242,0.023153,0.007127,0.181015,259.257355,13.207199,1.810149,-44.970242,0.182282,0.000000
135.710007,58.927940,-44.970242,0.023157,0.007151,0.181640,262.124573,13.353262,1.816401,-44.970242,0.182950,0.000000
136.110001,59.612366,-45.059204,0.023179,0.007180,0.182368,265.169037,13.508355,1.823684,-45.059204,0.183617,0.000000
136.510010,60.701180,-44.970242,0.023218,0.007211,0.183166,270.012329,13.755084,1.831662,-44.970242,0.184276,0.000000
136.910004,60.920883,-44.925762,0.023239,0.007231,0.183661,270.989624,13.804869,1.836613,-44.925762,0.184944,0.000000
137.310013,62.105400,-45.014721,0.023243,0.007265,0.184527,276.258606,14.073285,1.845273,-45.014721,0.185611,0.000000
137.710007,62.517242,-45.014721,0.023282,0.007286,0.185074,278.090576,14.166610,1.850738,-45.014721,0.186279,0.000000
138.110001,63.459351,-44.970242,0.023299,0.007317,0.185846,282.281281,14.380095,1.858459,-44.970242,0.186948,0.000000
138.510010,63.897629,-45.014721,0.023330,0.007337,0.186367,284.230835,14.479409,1.863667,-45.014721,0.187616,0.000000
138.910004,64.977875,-45.014721,0.023364,0.007367,0.187121,289.036011,14.724196,1.871207,-45.014721,0.188283,0.000000
139.310013,65.562881,-45.059204,0.023368,0.007388,0.187651,291.638275,14.856761,1.876505,-45.059204,0.188951,0.000000
139.710007,65.874557,-45.059204,0.023394,0.007406,0.188118,293.024658,14.927388,1.881184,-45.059204,0.189610,0.000000
140.110001,67.369629,-45.059204,0.023390,0.007430,0.188725,299.675079,15.266175,1.887255,-45.059204,0.188993,0.000000
140.510010,66.378006,-45.059204,0.023424,0.007422,0.188517,295.264130,15.041471,1.885165,-45.059204,0.188725,0.000000
140.910004,65.861145,-45.059204,0.023450,0.007422,0.188509,292.964996,14.924349,1.885090,-45.059204,0.188725,0.000000
141.310013,65.487656,-45.103683,0.023433,0.007422,0.188509,291.303650,14.839715,1.885090,-45.103683,0.188725,0.000000
141.710007,65.201309,-45.059204,0.023450,0.007422,0.188509,290.029907,14.774827,1.885090,-45.059204,0.188725,0.000000
142.110001,64.948456,-45.103683,0.023442,0.007422,0.188509,288.905151,14.717530,1.885090,-45.103683,0.188725,0.000000
142.510010,64.766373,-45.103683,0.023459,0.007422,0.188509,288.095215,14.676270,1.885090,-45.103683,0.188725,0.000000
142.910004,64.583908,-45.103683,0.023455,0.007422,0.188509,287.283569,14.634923,1.885090,-45.103683,0.188725,0.000000
143.310013,64.425278,-45.103683,0.023446,0.007422,0.188509,286.577942,14.598977,1.885090,-45.103683,0.188725,0.000000
143.710007,64.279312,-45.059204,0.023446,0.007422,0.188509,285.928650,14.565901,1.885090,-45.059204,0.188725,0.000000
144.110001,64.140411,-45.103683,0.023468,0.007422,0.188509,285.310791,14.534425,1.885090,-45.103683,0.188725,0.000000
144.510010,63.984009,-45.103683,0.023455,0.007421,0.188500,284.615082,14.498983,1.884999,-45.103683,0.188725,0.000000
144.910004,63.893906,-45.059204,0.023446,0.007421,0.188500,284.214294,14.478566,1.884999,-45.059204,0.188725,0.000000
145.310013,63.772888,-45.103683,0.023468,0.007421,0.188500,283.675964,14.451143,1.884999,-45.103683,0.188725,0.000000
145.710007,63.704742,-45.148167,0.023459,0.007421,0.188500,283.372833,14.435700,1.884999,-45.148167,0.188725,0.000000
146.110001,63.603073,-45.148167,0.023455,0.007421,0.188500,282.920593,14.412663,1.884999,-45.148167,0.188725,0.000000
146.510010,63.523026,-45.148167,0.023433,0.007421,0.188500,282.564545,14.394524,1.884999,-45.148167,0.188725,0.000000
146.910004,63.463806,-45.148167,0.023459,0.007421,0.188500,282.301117,14.381104,1.884999,-45.148167,0.188725,0.000000
147.310013,63.383011,-45.103683,0.023459,0.007421,0.188500,281.941711,14.362796,1.884999,-45.103683,0.188725,0.000000
147.710007,63.318588,-45.148167,0.023468,0.007421,0.188500,281.655151,14.348198,1.884999,-45.148167,0.188725,0.000000
148.110001,63.256027,-45.103683,0.023450,0.007421,0.188500,281.376862,14.334021,1.884999,-45.103683,0.188725,0.000000
148.510010,63.176712,-45.192646,0.023455,0.007421,0.188500,281.024048,14.316048,1.884999,-45.192646,0.188725,0.000000
148.910004,63.132767,-45.237125,0.023455,0.007421,0.188500,280.828583,14.306089,1.884999,-45.237125,0.188725,0.000000
149.310013,63.083618,-45.192646,0.023455,0.007421,0.188500,280.609955,14.294951,1.884999,-45.192646,0.188725,0.000000
149.710007,63.022919,-45.192646,0.023472,0.007421,0.188500,280.339935,14.281198,1.884999,-45.192646,0.188725,0.000000
150.110001,62.978989,-45.237125,0.023450,0.007421,0.188500,280.144531,14.271242,1.884999,-45.237125,0.188725,0.000000
150.510010,62.910095,-45.237125,0.023442,0.007421,0.188500,279.838074,14.255631,1.884999,-45.237125,0.188725,0.000000
150.910004,62.876205,-45.237125,0.023459,0.007421,0.188500,279.687317,14.247952,1.884999,-45.237125,0.188725,0.000000
151.310013,62.831520,-45.281609,0.023481,0.007421,0.188500,279.488556,14.237826,1.884999,-45.281609,0.188725,0.000000
151.710007,62.768219,-45.237125,0.023459,0.007421,0.188500,279.206970,14.223482,1.884999,-45.237125,0.188725,0.000000
152.110001,62.727257,-45.237125,0.023455,0.007421,0.188500,279.024780,14.214199,1.884999,-45.237125,0.188725,0.000000
152.510010,62.706032,-45.237125,0.023459,0.007421,0.188500,278.930359,14.209390,1.884999,-45.237125,0.188725,0.000000
152.910004,62.657997,-45.326088,0.023481,0.007421,0.188500,278.716705,14.198505,1.884999,-45.326088,0.188725,0.000000
153.310013,62.615921,-45.281609,0.023463,0.007421,0.188500,278.529541,14.188971,1.884999,-45.281609,0.188725,0.000000
153.710007,62.577934,-45.326088,0.023463,0.007421,0.188500,278.360565,14.180363,1.884999,-45.326088,0.188725,0.000000
154.110001,62.544800,-45.281609,0.023481,0.007421,0.188500,278.213165,14.172854,1.884999,-45.281609,0.188725,0.000000
154.510010,62.508675,-45.281609,0.023472,0.007421,0.188500,278.052460,14.164668,1.884999,-45.281609,0.188725,0.000000
154.910004,62.481865,-45.281609,0.023459,0.007421,0.188500,277.933228,14.158593,1.884999,-45.281609,0.188725,0.000000
155.310013,62.444626,-45.326088,0.023472,0.007421,0.188500,277.767578,14.150155,1.884999,-45.326088,0.188725,0.000000
155.710007,62.413719,-45.326088,0.023463,0.007421,0.188500,277.630096,14.143150,1.884999,-45.326088,0.188725,0.000000
156.110001,62.388397,-45.326088,0.023463,0.007421,0.188500,277.517456,14.137413,1.884999,-45.326088,0.188725,0.000000
156.510010,62.350792,-45.370571,0.023450,0.007421,0.188500,277.350189,14.128891,1.884999,-45.370571,0.188725,0.000000
156.910004,62.321373,-45.370571,0.023446,0.007421,0.188500,277.219299,14.122225,1.884999,-45.370571,0.188725,0.000000
157.310013,62.307594,-45.370571,0.023481,0.007421,0.188500,277.158020,14.119103,1.884999,-45.370571,0.188725,0.000000
157.710007,62.276688,-45.370571,0.023459,0.007421,0.188500,277.020538,14.112099,1.884999,-45.370571,0.188725,0.000000
158.110001,62.227165,-45.370571,0.023468,0.007421,0.188500,276.800262,14.100877,1.884999,-45.370571,0.188725,0.000000
158.510010,62.211899,-45.370571,0.023472,0.007421,0.188500,276.732361,14.097418,1.884999,-45.370571,0.188725,0.000000
158.910004,62.183220,-45.370571,0.023472,0.007421,0.188500,276.604767,14.090919,1.884999,-45.370571,0.188725,0.000000
159.310013,62.170937,-45.415051,0.023463,0.007421,0.188500,276.550140,14.088136,1.884999,-45.415051,0.188725,0.000000
159.710007,62.138535,-45.370571,0.023476,0.007421,0.188500,276.406006,14.080793,1.884999,-45.370571,0.188725,0.000000
160.110001,62.110237,-45.415051,0.023459,0.007421,0.188500,276.280121,14.074381,1.884999,-45.415051,0.188725,0.000000
160.510010,62.091248,-45.415051,0.023463,0.007421,0.188500,276.195648,14.070078,1.884999,-45.415051,0.188725,0.000000
160.910004,62.080078,-45.415051,0.023450,0.007421,0.188500,276.145966,14.067547,1.884999,-45.415051,0.188725,0.000000
161.310013,62.035019,-45.415051,0.023472,0.007421,0.188500,275.945557,14.057336,1.884999,-45.415051,0.188725,0.000000
161.710007,62.030174,-45.459534,0.023476,0.007421,0.188500,275.923981,14.056238,1.884999,-45.459534,0.188725,0.000000
162.110001,62.001503,-45.415051,0.023463,0.007421,0.188500,275.796448,14.049741,1.884999,-45.415051,0.188725,0.000000
162.510010,61.980652,-45.459534,0.023468,0.007421,0.188500,275.703705,14.045017,1.884999,-45.459534,0.188725,0.000000
162.910004,61.954956,-45.459534,0.023459,0.007421,0.188500,275.589417,14.039194,1.884999,-45.459534,0.188725,0.000000
163.310013,61.943039,-45.459534,0.023442,0.007421,0.188500,275.536407,14.036493,1.884999,-45.459534,0.188725,0.000000
163.710007,61.914742,-45.415051,0.023476,0.007421,0.188500,275.410522,14.030081,1.884999,-45.415051,0.188725,0.000000
164.110001,61.901337,-45.504013,0.023455,0.007421,0.188500,275.350891,14.027043,1.884999,-45.504013,0.188725,0.000000
164.510010,61.877876,-45.548492,0.023485,0.007421,0.188500,275.246552,14.021727,1.884999,-45.548492,0.188725,0.000000
164.910004,61.864845,-45.504013,0.023485,0.007421,0.188500,275.188568,14.018775,1.884999,-45.504013,0.188725,0.000000
165.310013,61.852928,-45.548492,0.023459,0.007421,0.188500,275.135559,14.016074,1.884999,-45.548492,0.188725,0.000000
165.710007,61.819412,-45.504013,0.023459,0.007421,0.188500,274.986481,14.008479,1.884999,-45.504013,0.188725,0.000000
166.110001,61.804520,-45.504013,0.023463,0.007421,0.188500,274.920227,14.005104,1.884999,-45.504013,0.188725,0.000000
166.510010,61.780685,-45.548492,0.023472,0.007421,0.188500,274.814209,13.999703,1.884999,-45.548492,0.188725,0.000000
166.910004,61.760208,-45.548492,0.023455,0.007421,0.188500,274.723114,13.995063,1.884999,-45.548492,0.188725,0.000000
167.310013,61.746429,-45.548492,0.023468,0.007421,0.188500,274.661835,13.991940,1.884999,-45.548492,0.188725,0.000000
167.710007,61.728180,-45.548492,0.023459,0.007421,0.188500,274.580658,13.987805,1.884999,-45.548492,0.188725,0.000000
168.110001,61.719246,-45.548492,0.023472,0.007421,0.188500,274.540924,13.985781,1.884999,-45.548492,0.188725,0.000000
168.510010,61.702118,-45.548492,0.023472,0.007421,0.188500,274.464722,13.981900,1.884999,-45.548492,0.188725,0.000000
168.910004,61.676422,-45.592976,0.023463,0.007421,0.188500,274.350433,13.976077,1.884999,-45.592976,0.188725,0.000000
169.310013,61.652962,-45.637455,0.023472,0.007421,0.188500,274.246063,13.970761,1.884999,-45.637455,0.188725,0.000000
169.710007,61.638817,-45.548492,0.023481,0.007421,0.188500,274.183136,13.967555,1.884999,-45.548492,0.188725,0.000000
170.110001,61.620567,-45.592976,0.023476,0.007421,0.188500,274.101959,13.963420,1.884999,-45.592976,0.188725,0.000000
170.500015,61.628761,-45.504013,0.023459,0.007421,0.188500,274.138428,13.965277,1.884999,-45.504013,0.188725,0.000000