File: Data/New pin I-18-1_08172023_165722.csv
Time (sec),S:Load (lbs),S:HL1 (DIM),S:LVDT (in),S:Position (in),Ch:Position (mm),Ch:Load (N),Ch:Stress (MPa),Ch:Strain (mm/mm),Ch:HL1 (DIM),Set Point (),Cycles ()
0.010000,-0.013033,-141.315979,0.000030,-0.000000,-0.000000,-0.057974,-0.002953,-0.000000,-141.315979,0.000191,0.000000
0.240000,-0.010799,-141.360458,0.000009,-0.000000,-0.000000,-0.048036,-0.002447,-0.000000,-141.360458,0.000191,0.000000
0.470000,-0.055111,-141.315979,0.000026,0.000072,0.001821,-0.245146,-0.012488,0.018213,-141.315979,0.002445,0.000000
0.700000,-0.009682,-141.360458,0.000056,0.000203,0.005169,-0.043066,-0.002194,0.051687,-141.360458,0.006278,0.000000
0.930000,-0.002234,-141.360458,0.000259,0.000356,0.009053,-0.009938,-0.000506,0.090535,-141.360458,0.010112,0.000000
1.160000,0.014895,-141.404938,0.000375,0.000497,0.012635,0.066256,0.003375,0.126355,-141.404938,0.013945,0.000000
1.390000,0.020108,-141.360458,0.000535,0.000655,0.016641,0.089445,0.004557,0.166414,-141.360458,0.017778,0.000000
1.620000,-0.001117,-141.315979,0.000698,0.000808,0.020519,-0.004969,-0.000253,0.205187,-141.315979,0.021610,0.000000
1.850000,-0.001862,-141.271500,0.000828,0.000954,0.024229,-0.008282,-0.000422,0.242294,-141.271500,0.025444,0.000000
2.080000,0.001489,-141.360458,0.000979,0.001105,0.028072,0.006625,0.000338,0.280718,-141.360458,0.029277,0.000000
2.310000,0.013033,-141.360458,0.001121,0.001260,0.032010,0.057974,0.002953,0.320096,-141.360458,0.033094,0.000000
2.540000,-0.009309,-141.271500,0.001233,0.001408,0.035764,-0.041410,-0.002110,0.357642,-141.271500,0.036925,0.000000
2.770000,0.040961,-141.315979,0.001423,0.001560,0.039632,0.182203,0.009282,0.396324,-141.315979,0.040759,0.000000
3.000000,0.009309,-141.271500,0.001565,0.001710,0.043431,0.041410,0.002110,0.434309,-141.271500,0.044592,0.000000
3.230000,0.007820,-141.315979,0.001733,0.001864,0.047351,0.034784,0.001772,0.473505,-141.315979,0.048425,0.000000
3.460000,0.012288,-141.271500,0.001897,0.002011,0.051079,0.054661,0.002785,0.510794,-141.271500,0.052259,0.000000
3.690000,0.040216,-141.315979,0.002039,0.002162,0.054904,0.178891,0.009113,0.549037,-141.315979,0.056092,0.000000
3.920000,0.015640,-141.271500,0.002190,0.002321,0.058963,0.069569,0.003544,0.589626,-141.271500,0.059925,0.000000
4.150000,-0.021598,-141.271500,0.002350,0.002465,0.062622,-0.096071,-0.004894,0.626218,-141.271500,0.063757,0.000000
4.380000,-0.021225,-141.315979,0.002509,0.002611,0.066316,-0.094414,-0.004810,0.663159,-141.315979,0.067591,0.000000
4.610000,0.000745,-141.360458,0.002652,0.002771,0.070393,0.003313,0.000169,0.703930,-141.360458,0.071424,0.000000
4.840000,0.047291,-141.271500,0.002824,0.002912,0.073973,0.210362,0.010716,0.739735,-141.271500,0.075257,0.000000
5.070000,0.025321,-141.271500,0.002936,0.003067,0.077893,0.112635,0.005738,0.778931,-141.271500,0.079091,0.000000
5.300000,0.020481,-141.271500,0.003134,0.003223,0.081875,0.091102,0.004641,0.818748,-141.271500,0.082906,0.000000
5.530000,0.015640,-141.315979,0.003294,0.003375,0.085716,0.069569,0.003544,0.857158,-141.315979,0.086739,0.000000
5.760000,0.024949,-141.271500,0.003445,0.003526,0.089558,0.110978,0.005654,0.895582,-141.271500,0.090573,0.000000
5.990000,0.030535,-141.315979,0.003579,0.003671,0.093236,0.135825,0.006919,0.932356,-141.315979,0.094406,0.000000
6.220000,0.020481,-141.182541,0.003755,0.003820,0.097016,0.091102,0.004641,0.970159,-141.182541,0.098239,0.000000
6.450000,0.010426,-141.271500,0.003915,0.003976,0.100996,0.046379,0.002363,1.009961,-141.271500,0.102073,0.000000
6.680000,-0.036120,-141.271500,0.004096,0.004123,0.104727,-0.160670,-0.008185,1.047265,-141.271500,0.105906,0.000000
6.910000,-0.015640,-141.271500,0.004221,0.004274,0.108567,-0.069569,-0.003544,1.085674,-141.271500,0.109738,0.000000
7.140000,0.034258,-141.227020,0.004389,0.004426,0.112410,0.152388,0.007763,1.124099,-141.227020,0.113571,0.000000
7.370000,0.061069,-141.227020,0.004583,0.004574,0.116181,0.271649,0.013838,1.161811,-141.227020,0.117404,0.000000
7.600000,0.046547,-141.271500,0.004695,0.004728,0.120102,0.207050,0.010548,1.201023,-141.271500,0.121238,0.000000
7.830000,0.027183,-141.227020,0.004850,0.004881,0.123978,0.120917,0.006160,1.239780,-141.227020,0.125071,0.000000
8.060000,0.025321,-141.315979,0.005001,0.005032,0.127820,0.112635,0.005738,1.278204,-141.315979,0.128886,0.000000
8.290000,0.035375,-141.271500,0.005170,0.005182,0.131619,0.157357,0.008016,1.316190,-141.271500,0.132720,0.000000
8.520000,0.021225,-141.227020,0.005364,0.005333,0.135469,0.094414,0.004810,1.354690,-141.227020,0.136553,0.000000
8.750000,0.014895,-141.271500,0.005519,0.005486,0.139337,0.066256,0.003375,1.393371,-141.271500,0.140386,0.000000
8.980000,-0.000745,-141.227020,0.005652,0.005638,0.143196,-0.003313,-0.000169,1.431962,-141.227020,0.144220,0.000000
9.210000,0.028300,-141.182541,0.005808,0.005784,0.146916,0.125886,0.006413,1.469160,-141.182541,0.148053,0.000000
9.440001,0.022342,-141.182541,0.005963,0.005939,0.150845,0.099384,0.005063,1.508447,-141.182541,0.151885,0.000000
9.670000,0.034631,-141.182541,0.006118,0.006083,0.154513,0.154045,0.007847,1.545130,-141.182541,0.155718,0.000000
9.900001,0.040589,-141.182541,0.006265,0.006230,0.158242,0.180547,0.009198,1.582419,-141.182541,0.159551,0.000000
10.130000,0.046547,-141.182541,0.006416,0.006394,0.162396,0.207050,0.010548,1.623962,-141.182541,0.163385,0.000000
10.360001,0.019736,-141.227020,0.006575,0.006540,0.166116,0.087789,0.004472,1.661160,-141.227020,0.167218,0.000000
10.590000,0.016757,-141.182541,0.006756,0.006689,0.169907,0.074538,0.003797,1.699070,-141.182541,0.171052,0.000000
10.820001,0.036493,-141.182541,0.006864,0.006841,0.173774,0.162327,0.008269,1.737736,-141.182541,0.174885,0.000000
11.050000,0.033141,-141.182541,0.007058,0.006991,0.177581,0.147419,0.007510,1.775812,-141.182541,0.178700,0.000000
11.280001,0.061814,-141.138062,0.007222,0.007144,0.181449,0.274962,0.014007,1.814494,-141.138062,0.182533,0.000000
11.510000,0.036865,-141.227020,0.007360,0.007293,0.185230,0.163983,0.008354,1.852297,-141.227020,0.186367,0.000000
11.740001,0.011916,-141.138062,0.007558,0.007447,0.189142,0.053005,0.002700,1.891418,-141.138062,0.190200,0.000000
11.970000,0.027928,-141.093582,0.007726,0.007599,0.193018,0.124230,0.006329,1.930175,-141.093582,0.194033,0.000000
12.200001,0.040216,-141.138062,0.007864,0.007743,0.196678,0.178891,0.009113,1.966783,-141.138062,0.197865,0.000000
12.430000,0.028300,-141.049103,0.008032,0.007900,0.200649,0.125886,0.006413,2.006494,-141.049103,0.201699,0.000000
12.660001,0.019363,-141.138062,0.008175,0.008053,0.204543,0.086132,0.004388,2.045433,-141.138062,0.205532,0.000000
12.890000,-0.012661,-141.138062,0.008343,0.008200,0.208272,-0.056318,-0.002869,2.082722,-141.138062,0.209365,0.000000
13.120001,0.034631,-141.093582,0.008476,0.008351,0.212106,0.154045,0.007847,2.121055,-141.093582,0.213199,0.000000
13.350000,0.051015,-141.093582,0.008614,0.008497,0.215834,0.226926,0.011560,2.158344,-141.093582,0.217032,0.000000
13.580001,0.057718,-141.093582,0.008761,0.008650,0.219712,0.256741,0.013079,2.197116,-141.093582,0.220865,0.000000
13.810000,0.067027,-141.093582,0.008921,0.008809,0.223743,0.298151,0.015189,2.237433,-141.093582,0.224680,0.000000
14.040001,0.030535,-141.093582,0.009093,0.008957,0.227507,0.135825,0.006919,2.275070,-141.093582,0.228514,0.000000
14.270000,0.056973,-141.093582,0.009235,0.009107,0.231306,0.253428,0.012910,2.313055,-141.093582,0.232347,0.000000
14.500001,0.029417,-141.004608,0.009382,0.009257,0.235122,0.130855,0.006666,2.351222,-141.004608,0.236180,0.000000
14.730000,0.062186,-141.093582,0.009520,0.009399,0.238730,0.276618,0.014092,2.387300,-141.093582,0.240012,0.000000
14.960001,0.039099,-141.049103,0.009710,0.009557,0.242754,0.173921,0.008860,2.427541,-141.049103,0.243846,0.000000
15.190001,-0.016757,-141.004608,0.009873,0.009710,0.246639,-0.074538,-0.003797,2.466389,-141.004608,0.247679,0.000000
15.420001,-0.011544,-141.049103,0.010016,0.009858,0.250403,-0.051348,-0.002616,2.504026,-141.049103,0.251512,0.000000
15.650001,0.050270,-141.049103,0.010201,0.010011,0.254271,0.223613,0.011391,2.542708,-141.049103,0.255346,0.000000
15.880001,0.079688,-141.004608,0.010343,0.010158,0.258007,0.354469,0.018057,2.580072,-141.004608,0.259179,0.000000
16.110001,0.071496,-141.004608,0.010486,0.010302,0.261677,0.318028,0.016201,2.616771,-141.004608,0.263012,0.000000
16.340000,0.066282,-141.004608,0.010671,0.010467,0.265856,0.294838,0.015020,2.658556,-141.004608,0.266846,0.000000
16.570002,0.044685,-140.960129,0.010805,0.010612,0.269542,0.198768,0.010126,2.695421,-140.960129,0.270678,0.000000
16.800001,0.058463,-140.915649,0.010925,0.010762,0.273357,0.260054,0.013248,2.733572,-140.915649,0.274494,0.000000
17.030001,0.056973,-140.960129,0.011111,0.010915,0.277251,0.253428,0.012910,2.772511,-140.960129,0.278328,0.000000
17.260000,0.035748,-141.004608,0.011279,0.011066,0.281068,0.159014,0.008101,2.810678,-141.004608,0.282161,0.000000
17.490002,0.048408,-140.960129,0.011413,0.011221,0.285013,0.215332,0.010970,2.850132,-140.960129,0.285993,0.000000
17.720001,0.055111,-140.871170,0.011581,0.011365,0.288672,0.245146,0.012488,2.886724,-140.871170,0.289826,0.000000
17.950001,0.058835,-140.871170,0.011693,0.011520,0.292601,0.261710,0.013332,2.926012,-140.871170,0.293659,0.000000
18.180000,0.062559,-140.915649,0.011908,0.011669,0.296400,0.278275,0.014176,2.963997,-140.915649,0.297493,0.000000
18.410002,0.066655,-140.915649,0.012038,0.011811,0.300007,0.296495,0.015104,3.000074,-140.915649,0.301326,0.000000
18.640001,0.071123,-140.915649,0.012189,0.011973,0.304110,0.316371,0.016117,3.041103,-140.915649,0.305159,0.000000
18.870001,0.040589,-140.826691,0.012370,0.012123,0.307925,0.180547,0.009198,3.079254,-140.826691,0.308993,0.000000
19.100000,0.033886,-140.871170,0.012508,0.012272,0.311715,0.150732,0.007679,3.117149,-140.871170,0.312825,0.000000
19.330002,0.058463,-140.826691,0.012684,0.012419,0.315444,0.260054,0.013248,3.154438,-140.826691,0.316658,0.000000
19.560001,0.074102,-140.871170,0.012822,0.012573,0.319365,0.329623,0.016792,3.193649,-140.871170,0.320491,0.000000
19.790001,0.077081,-140.871170,0.013004,0.012722,0.323129,0.342874,0.017467,3.231286,-140.871170,0.324308,0.000000
20.020000,0.081922,-140.826691,0.013154,0.012874,0.327004,0.364407,0.018564,3.270043,-140.826691,0.328140,0.000000
20.250002,0.045802,-140.826691,0.013301,0.013030,0.330950,0.203737,0.010379,3.309497,-140.826691,0.331973,0.000000
20.480001,0.063676,-140.782211,0.013486,0.013182,0.334818,0.283244,0.014429,3.348179,-140.782211,0.335806,0.000000
20.710001,0.071496,-140.826691,0.013624,0.013329,0.338547,0.318028,0.016201,3.385468,-140.826691,0.339640,0.000000
20.940001,0.066655,-140.826691,0.013767,0.013480,0.342389,0.296495,0.015104,3.423892,-140.826691,0.343473,0.000000
21.170000,0.065538,-140.737732,0.013943,0.013637,0.346378,0.291526,0.014851,3.463784,-140.737732,0.347306,0.000000
21.400002,0.026438,-140.737732,0.014094,0.013781,0.350047,0.117604,0.005991,3.500468,-140.737732,0.351140,0.000000
21.630001,0.014150,-140.737732,0.014237,0.013930,0.353827,0.062943,0.003206,3.538271,-140.737732,0.354972,0.000000
21.860001,0.084901,-140.737732,0.014379,0.014083,0.357704,0.377658,0.019239,3.577044,-140.737732,0.358805,0.000000
22.090000,0.102775,-140.782211,0.014534,0.014228,0.361389,0.457165,0.023289,3.613894,-140.782211,0.362638,0.000000
22.320002,0.105754,-140.648773,0.014711,0.014385,0.365388,0.470416,0.023964,3.653877,-140.648773,0.366472,0.000000
22.550001,0.074475,-140.648773,0.014879,0.014541,0.369333,0.331279,0.016876,3.693331,-140.648773,0.370288,0.000000
22.780001,0.097189,-140.737732,0.015021,0.014686,0.373020,0.432319,0.022023,3.730196,-140.737732,0.374120,0.000000
23.010000,0.086390,-140.693253,0.015177,0.014841,0.376965,0.384284,0.019576,3.769650,-140.693253,0.377954,0.000000
23.240002,0.095327,-140.693253,0.015336,0.014983,0.380573,0.424037,0.021601,3.805727,-140.693253,0.381787,0.000000
23.470001,0.093838,-140.648773,0.015500,0.015137,0.384476,0.417412,0.021264,3.844757,-140.648773,0.385620,0.000000
23.700001,0.132565,-140.604294,0.015694,0.015294,0.388456,0.589677,0.030040,3.884559,-140.604294,0.389454,0.000000
23.930000,0.249490,-140.604294,0.015853,0.015440,0.392176,1.109785,0.056535,3.921757,-140.604294,0.393287,0.000000
24.160002,0.662823,-140.604294,0.015957,-0.000005,-0.000139,2.948384,0.150198,-0.001393,-140.604294,0.000086,0.000000
24.390001,0.644577,-140.604294,0.015957,-0.000005,-0.000139,2.867220,0.146063,-0.001393,-140.604294,0.000086,0.000000
24.620001,0.646439,-140.559799,0.015927,-0.000005,-0.000139,2.875503,0.146485,-0.001393,-140.559799,0.000095,0.000000
24.850000,0.677718,-140.559799,0.015948,-0.000005,-0.000139,3.014640,0.153573,-0.001393,-140.559799,0.000477,0.000000
25.080002,0.676228,-140.559799,0.015935,-0.000004,-0.000114,3.008014,0.153236,-0.001135,-140.559799,0.000858,0.000000
25.310001,0.729850,-140.604294,0.015961,0.000010,0.000242,3.246535,0.165386,0.002422,-140.604294,0.001240,0.000000
25.540001,0.824433,-140.559799,0.015966,0.000028,0.000702,3.667259,0.186819,0.007025,-140.559799,0.001621,0.000000
25.770000,0.905237,-140.559799,0.015970,0.000041,0.001040,4.026697,0.205130,0.010401,-140.559799,0.002012,0.000000
26.000002,1.001310,-140.470840,0.015966,0.000055,0.001396,4.454047,0.226900,0.013959,-140.470840,0.002394,0.000000
26.230001,1.108925,-140.515320,0.015991,0.000070,0.001777,4.932746,0.251286,0.017774,-140.515320,0.002775,0.000000
26.460001,1.126427,-140.515320,0.016013,0.000073,0.001864,5.010596,0.255252,0.018637,-140.515320,0.003157,0.000000
26.690001,1.351340,-140.559799,0.016030,0.000100,0.002533,6.011059,0.306218,0.025329,-140.559799,0.003547,0.000000
26.920002,1.516301,-140.470840,0.016017,0.000118,0.002992,6.744842,0.343599,0.029916,-140.470840,0.003929,0.000000
27.150002,1.640301,-140.426361,0.016069,0.000131,0.003338,7.296422,0.371697,0.033383,-140.426361,0.004310,0.000000
27.380001,1.754619,-140.470840,0.016086,0.000149,0.003780,7.804935,0.397602,0.037804,-140.470840,0.004692,0.000000
27.610001,1.911016,-140.470840,0.016099,0.000164,0.004171,8.500622,0.433042,0.041710,-140.470840,0.005073,0.000000
27.840002,2.054007,-140.470840,0.016099,0.000176,0.004466,9.136678,0.465445,0.044662,-140.470840,0.005464,0.000000
28.070002,2.299772,-140.381882,0.016099,0.000195,0.004952,10.229897,0.521136,0.049522,-140.381882,0.005845,0.000000
28.300001,2.375736,-140.470840,0.016142,0.000203,0.005169,10.567802,0.538350,0.051687,-140.470840,0.006227,0.000000
28.530001,2.590595,-140.381882,0.016134,0.000216,0.005490,11.523543,0.587037,0.054896,-140.381882,0.006608,0.000000
28.760002,2.875088,-140.381882,0.016164,0.000241,0.006132,12.789029,0.651504,0.061315,-140.381882,0.006990,0.000000
28.990002,3.026644,-140.381882,0.016168,0.000253,0.006418,13.463182,0.685847,0.064177,-140.381882,0.007381,0.000000
29.220001,3.160697,-140.337402,0.016177,0.000267,0.006790,14.059484,0.716224,0.067901,-140.337402,0.007762,0.000000
29.450001,3.395292,-140.381882,0.016203,0.000284,0.007216,15.103014,0.769384,0.072155,-140.381882,0.008144,0.000000
29.680002,3.488385,-140.292923,0.016254,0.000294,0.007476,15.517113,0.790479,0.074759,-140.292923,0.008525,0.000000
29.910002,3.798944,-140.337402,0.016280,0.000313,0.007953,16.898546,0.860853,0.079528,-140.337402,0.008907,0.000000
30.140001,3.955713,-140.381882,0.016241,0.000325,0.008256,17.595890,0.896377,0.082556,-140.381882,0.009297,0.000000
30.370001,4.042848,-140.292923,0.016246,0.000331,0.008404,17.983484,0.916122,0.084040,-140.292923,0.009679,0.000000
30.600002,4.232013,-140.248444,0.016276,0.000346,0.008793,18.824932,0.958988,0.087931,-140.248444,0.010060,0.000000
30.830002,4.782007,-140.114990,0.016293,0.000376,0.009556,21.271431,1.083618,0.095561,-140.114990,0.010442,0.000000
31.060001,4.980109,-140.248444,0.016289,0.000390,0.009912,22.152632,1.128509,0.099119,-140.248444,0.010823,0.000000
31.290001,5.165178,-140.248444,0.016336,0.000404,0.010268,22.975861,1.170446,0.102677,-140.248444,0.011214,0.000000
31.520002,5.469779,-140.248444,0.016323,0.000420,0.010658,24.330791,1.239470,0.106583,-140.248444,0.011595,0.000000
31.750002,5.687245,-140.203964,0.016349,0.000436,0.011066,25.298128,1.288748,0.110655,-140.203964,0.011977,0.000000
31.980001,5.915509,-140.159470,0.016418,0.000447,0.011352,26.313499,1.340474,0.113517,-140.159470,0.012358,0.000000
32.210003,6.085683,-140.203964,0.016401,0.000458,0.011621,27.070471,1.379036,0.116211,-140.203964,0.012740,0.000000
32.440002,6.347461,-140.203964,0.016410,0.000470,0.011933,28.234919,1.438355,0.119330,-140.203964,0.013129,0.000000
32.670002,6.898200,-140.159470,0.016436,0.000497,0.012617,30.684727,1.563154,0.126173,-140.159470,0.013511,0.000000
32.900002,7.175990,-140.159470,0.016444,0.000512,0.013000,31.920397,1.626103,0.130004,-140.159470,0.013894,0.000000
33.130001,7.302224,-140.114990,0.016479,0.000523,0.013286,32.481915,1.654708,0.132865,-140.114990,0.014275,0.000000
33.360001,7.690609,-140.159470,0.016487,0.000538,0.013668,34.209534,1.742717,0.136680,-140.159470,0.014657,0.000000
33.590000,8.086440,-140.114990,0.016474,0.000558,0.014162,35.970284,1.832414,0.141616,-140.114990,0.015046,0.000000
33.820004,8.328855,-140.159470,0.016504,0.000572,0.014534,37.048595,1.887345,0.145340,-140.159470,0.015427,0.000000
34.050003,8.572387,-140.070511,0.016526,0.000583,0.014813,38.131882,1.942531,0.148126,-140.070511,0.015809,0.000000
34.280003,8.826716,-140.070511,0.016517,0.000596,0.015150,39.263195,2.000162,0.151502,-140.070511,0.016190,0.000000
34.510002,9.269840,-140.026031,0.016578,0.000614,0.015601,41.234310,2.100576,0.156013,-140.026031,0.016573,0.000000
34.740002,9.672003,-140.114990,0.016591,0.000633,0.016078,43.023216,2.191707,0.160782,-140.114990,0.016962,0.000000
34.970001,9.758020,-140.070511,0.016586,0.000643,0.016320,43.405842,2.211199,0.163205,-140.070511,0.017344,0.000000
35.200001,10.140075,-139.981552,0.016578,0.000659,0.016729,45.105305,2.297774,0.167292,-139.981552,0.017725,0.000000
35.430000,10.608520,-140.026031,0.016595,0.000678,0.017232,47.189053,2.403925,0.172319,-140.026031,0.018107,0.000000
35.660000,10.818537,-140.026031,0.016604,0.000692,0.017569,48.123257,2.451515,0.175695,-140.026031,0.018498,0.000000
35.890003,11.064675,-140.026031,0.016617,0.000705,0.017909,49.218136,2.507291,0.179086,-140.026031,0.018879,0.000000
36.120003,11.292195,-140.026031,0.016634,0.000717,0.018211,50.230194,2.558848,0.182114,-140.026031,0.019261,0.000000
36.350002,11.778886,-139.937073,0.016642,0.000736,0.018697,52.395100,2.669134,0.186974,-139.937073,0.019642,0.000000
36.580002,12.195198,-139.937073,0.016694,0.000754,0.019158,54.246952,2.763472,0.191576,-139.937073,0.020024,0.000000
36.810001,12.303186,-139.981552,0.016703,0.000766,0.019460,54.727306,2.787942,0.194604,-139.981552,0.020414,0.000000
37.040001,12.645769,-139.937073,0.016703,0.000781,0.019842,56.251190,2.865572,0.198419,-139.937073,0.020796,0.000000
37.270000,12.871427,-139.892593,0.016742,0.000792,0.020111,57.254967,2.916707,0.201114,-139.892593,0.021177,0.000000
37.500000,13.343595,-139.937073,0.016733,0.000810,0.020570,59.355274,3.023702,0.205701,-139.937073,0.021559,0.000000
37.730003,13.528664,-139.848114,0.016776,0.000821,0.020865,60.178501,3.065639,0.208654,-139.848114,0.021940,0.000000
37.960003,13.742033,-139.937073,0.016737,0.000835,0.021221,61.127617,3.113989,0.212211,-139.937073,0.022331,0.000000
38.190002,14.037325,-139.937073,0.016750,0.000849,0.021559,62.441139,3.180903,0.215588,-139.937073,0.022712,0.000000
38.420002,14.776856,-139.937073,0.016793,0.000874,0.022201,65.730743,3.348484,0.222007,-139.937073,0.023094,0.000000
38.650002,14.986875,-139.892593,0.016819,0.000890,0.022600,66.664948,3.396074,0.226004,-139.892593,0.023475,0.000000
38.880001,15.041241,-139.803635,0.016819,0.000901,0.022877,66.906776,3.408394,0.228774,-139.803635,0.023857,0.000000
39.110001,15.284400,-139.848114,0.016845,0.000914,0.023207,67.988403,3.463495,0.232075,-139.848114,0.024248,0.000000
39.340000,15.572244,-139.848114,0.016828,0.000927,0.023536,69.268799,3.528721,0.235360,-139.848114,0.024629,0.000000
39.570004,16.052605,-139.892593,0.016841,0.000945,0.024005,71.405548,3.637572,0.240053,-139.892593,0.025011,0.000000
39.800003,16.420507,-139.759155,0.016880,0.000962,0.024438,73.042068,3.720940,0.244383,-139.759155,0.025392,0.000000
40.030003,16.541901,-139.803635,0.016875,0.000973,0.024715,73.582047,3.748448,0.247154,-139.803635,0.025774,0.000000
40.260002,16.981674,-139.759155,0.016905,0.000991,0.025167,75.538261,3.848102,0.251665,-139.759155,0.026164,0.000000
40.490002,17.219248,-139.803635,0.016936,0.001005,0.025531,76.595039,3.901937,0.255314,-139.803635,0.026546,0.000000
40.720001,17.509699,-139.759155,0.016953,0.001021,0.025939,77.887032,3.967754,0.259386,-139.759155,0.026927,0.000000
40.950001,17.694767,-139.714661,0.016949,0.001036,0.026311,78.710258,4.009692,0.263111,-139.714661,0.027309,0.000000
41.180000,17.993782,-139.714661,0.016957,0.001050,0.026676,80.040337,4.077449,0.266759,-139.714661,0.027690,0.000000
41.410004,18.024317,-139.714661,0.016979,0.001060,0.026918,80.176163,4.084369,0.269182,-139.714661,0.028081,0.000000
41.640003,18.836088,-139.759155,0.016996,0.001083,0.027509,83.787102,4.268319,0.275086,-139.759155,0.028462,0.000000
41.870003,18.811512,-139.714661,0.017000,0.001092,0.027742,83.677788,4.262750,0.277418,-139.714661,0.028844,0.000000
42.100002,19.232292,-139.714661,0.017018,0.001109,0.028176,85.549507,4.358099,0.281763,-139.714661,0.029225,0.000000
42.330002,19.641903,-139.625702,0.017013,0.001127,0.028635,87.371552,4.450919,0.286350,-139.625702,0.029607,0.000000
42.560001,20.053373,-139.670181,0.017074,0.001145,0.029086,89.201859,4.544159,0.290862,-139.670181,0.029998,0.000000
42.790001,20.054119,-139.714661,0.017056,0.001155,0.029330,89.205177,4.544328,0.293299,-139.714661,0.030379,0.000000
43.020000,20.295788,-139.670181,0.017074,0.001171,0.029737,90.280174,4.599091,0.297372,-139.670181,0.030761,0.000000
43.250004,20.587357,-139.581223,0.017082,0.001184,0.030075,91.577133,4.665162,0.300748,-139.581223,0.031142,0.000000
43.480003,21.305290,-139.581223,0.017117,0.001207,0.030665,94.770660,4.827847,0.306652,-139.581223,0.031524,0.000000
43.710003,21.223742,-139.625702,0.017108,0.001214,0.030847,94.407921,4.809369,0.308469,-139.625702,0.031914,0.000000
43.940002,21.656065,-139.625702,0.017160,0.001234,0.031333,96.330986,4.907334,0.313329,-139.625702,0.032296,0.000000
44.170002,21.840389,-139.625702,0.017130,0.001247,0.031670,97.150902,4.949103,0.316705,-139.625702,0.032677,0.000000
44.400002,22.390757,-139.581223,0.017164,0.001266,0.032156,99.599060,5.073818,0.321565,-139.581223,0.033059,0.000000
44.630001,22.514757,-139.492264,0.017173,0.001279,0.032487,100.150642,5.101917,0.324865,-139.492264,0.033449,0.000000
44.860001,22.759405,-139.581223,0.017203,0.001293,0.032842,101.238892,5.157355,0.328423,-139.581223,0.033831,0.000000
45.090004,23.036823,-139.536743,0.017190,0.001305,0.033154,102.472908,5.220219,0.331542,-139.536743,0.034212,0.000000
45.320004,23.382011,-139.536743,0.017207,0.001322,0.033587,104.008385,5.298440,0.335872,-139.536743,0.034594,0.000000
45.550003,23.787525,-139.492264,0.017212,0.001335,0.033917,105.812195,5.390330,0.339172,-139.492264,0.034975,0.000000
45.780003,23.900726,-139.581223,0.017250,0.001346,0.034187,106.315742,5.415982,0.341867,-139.581223,0.035366,0.000000
46.010002,24.348318,-139.492264,0.017250,0.001361,0.034576,108.306725,5.517408,0.345758,-139.492264,0.035748,0.000000
46.240002,25.106840,-139.492264,0.017298,0.001386,0.035201,111.680801,5.689291,0.352010,-139.492264,0.036129,0.000000
46.470001,25.124714,-139.492264,0.017306,0.001397,0.035487,111.760307,5.693342,0.354872,-139.492264,0.036511,0.000000
46.700001,25.291164,-139.403305,0.017293,0.001408,0.035764,112.500717,5.731060,0.357642,-139.403305,0.036892,0.000000
46.930004,25.784559,-139.403305,0.017341,0.001429,0.036285,114.695450,5.842865,0.362850,-139.403305,0.037281,0.000000
47.160004,26.112247,-139.403305,0.017324,0.001444,0.036667,116.153076,5.917120,0.366665,-139.403305,0.037664,0.000000
47.390003,26.390409,-139.447784,0.017345,0.001456,0.036995,117.390404,5.980152,0.369951,-139.447784,0.038046,0.000000
47.620003,26.673784,-139.403305,0.017354,0.001468,0.037299,118.650917,6.044366,0.372994,-139.403305,0.038427,0.000000
47.850002,26.514408,-139.358826,0.017384,0.001478,0.037551,117.941978,6.008251,0.375507,-139.358826,0.038809,0.000000
48.080002,27.545135,-139.314346,0.017388,0.001500,0.038097,122.526878,6.241817,0.380972,-139.314346,0.039198,0.000000
48.310001,28.067947,-139.358826,0.017431,0.001518,0.038548,124.852463,6.360288,0.385484,-139.358826,0.039579,0.000000
48.540001,28.324884,-139.403305,0.017406,0.001531,0.038886,125.995377,6.418511,0.388860,-139.403305,0.039961,0.000000
48.770000,28.833918,-139.358826,0.017431,0.001548,0.039311,128.259674,6.533859,0.393114,-139.358826,0.040344,0.000000
49.000004,29.236824,-139.269852,0.017453,0.001565,0.039763,130.051895,6.625159,0.397626,-139.269852,0.040725,0.000000
49.230003,29.400667,-139.314346,0.017475,0.001575,0.040005,130.780701,6.662286,0.400048,-139.314346,0.041115,0.000000
49.460003,30.086950,-139.269852,0.017483,0.001594,0.040500,133.833435,6.817800,0.404999,-139.269852,0.041496,0.000000
49.690002,30.152115,-139.314346,0.017492,0.001606,0.040786,134.123306,6.832567,0.407860,-139.314346,0.041878,0.000000
49.920002,30.454109,-139.225372,0.017513,0.001618,0.041107,135.466644,6.901000,0.411070,-139.225372,0.042259,0.000000
50.150002,31.632296,-139.225372,0.017557,0.001644,0.041747,140.707474,7.167980,0.417474,-139.225372,0.042642,0.000000
50.380001,31.900776,-139.225372,0.017539,0.001658,0.042121,141.901733,7.228819,0.421213,-139.225372,0.043031,0.000000
50.610001,32.189365,-139.225372,0.017561,0.001671,0.042450,143.185455,7.294214,0.424499,-139.225372,0.043413,0.000000
50.840004,32.574398,-139.225372,0.017591,0.001685,0.042789,144.898163,7.381464,0.427890,-139.225372,0.043794,0.000000
51.070004,33.190674,-139.269852,0.017561,0.001702,0.043231,147.639496,7.521114,0.432311,-139.269852,0.044176,0.000000
51.300003,33.476284,-139.180893,0.017613,0.001714,0.043526,148.909943,7.585835,0.435263,-139.180893,0.044557,0.000000
51.530003,33.782001,-139.180893,0.017587,0.001728,0.043882,150.269852,7.655111,0.438821,-139.180893,0.044948,0.000000
51.760002,33.866528,-139.180893,0.017625,0.001737,0.044124,150.645844,7.674265,0.441243,-139.180893,0.045329,0.000000
51.990002,34.244858,-139.180893,0.017643,0.001745,0.044315,152.328735,7.759995,0.443151,-139.180893,0.045711,0.000000
52.220001,35.881809,-139.136414,0.017656,0.001778,0.045164,159.610260,8.130934,0.451644,-139.136414,0.046092,0.000000
52.450001,36.234074,-139.091934,0.017669,0.001793,0.045538,161.177216,8.210758,0.455383,-139.091934,0.046474,0.000000
52.680004,36.554687,-139.091934,0.017656,0.001805,0.045859,162.603378,8.283410,0.458593,-139.091934,0.046865,0.000000
52.910004,37.175804,-139.091934,0.017686,0.001822,0.046283,165.366241,8.424158,0.462832,-139.091934,0.047246,0.000000
53.140003,37.854637,-139.091934,0.017707,0.001840,0.046725,168.385834,8.577983,0.467253,-139.091934,0.047628,0.000000
53.370003,37.908260,-139.091934,0.017716,0.001847,0.046925,168.624359,8.590135,0.469251,-139.091934,0.048009,0.000000
53.600002,38.137642,-139.091934,0.017738,0.001858,0.047204,169.644699,8.642113,0.472037,-139.091934,0.048400,0.000000
53.830002,38.779984,-139.002975,0.017751,0.001876,0.047662,172.501984,8.787670,0.476624,-139.002975,0.048781,0.000000
54.060001,40.042328,-139.047455,0.017763,0.001899,0.048244,178.117172,9.073721,0.482438,-139.047455,0.049163,0.000000
54.290001,40.502205,-139.091934,0.017785,0.001913,0.048590,180.162811,9.177931,0.485905,-139.091934,0.049544,0.000000
54.520004,40.877186,-139.047455,0.017742,0.001925,0.048902,181.830811,9.262903,0.489024,-139.047455,0.049926,0.000000
54.750004,41.346001,-139.002975,0.017794,0.001940,0.049267,183.916199,9.369138,0.492672,-139.002975,0.050316,0.000000
54.980003,42.344334,-138.958496,0.017798,0.001960,0.049788,188.357010,9.595363,0.497880,-138.958496,0.050698,0.000000
55.210003,42.791180,-139.002975,0.017828,0.001973,0.050107,190.344681,9.696620,0.501075,-139.002975,0.051079,0.000000
55.440002,43.145306,-138.958496,0.017850,0.001984,0.050395,191.919907,9.776866,0.503951,-138.958496,0.051461,0.000000
55.670002,43.758976,-138.958496,0.017828,0.002000,0.050802,194.649643,9.915926,0.508024,-138.958496,0.051842,0.000000
55.900002,44.536118,-138.958496,0.017845,0.002019,0.051288,198.106552,10.092028,0.512884,-138.958496,0.052233,0.000000
56.130001,45.283840,-138.914017,0.017832,0.002034,0.051652,201.432587,10.261465,0.516517,-138.914017,0.052615,0.000000
56.360004,45.538544,-138.825043,0.017854,0.002046,0.051973,202.565552,10.319181,0.519727,-138.825043,0.052996,0.000000
56.590004,46.226688,-138.825043,0.017919,0.002059,0.052310,205.626587,10.475117,0.523103,-138.825043,0.053378,0.000000
56.820004,47.344551,-138.914017,0.017910,0.002082,0.052875,210.599075,10.728429,0.528750,-138.914017,0.053759,0.000000
57.050003,47.818954,-138.914017,0.017910,0.002095,0.053204,212.709335,10.835930,0.532035,-138.914017,0.054150,0.000000
57.280003,48.133980,-138.869522,0.017919,0.002105,0.053456,214.110641,10.907316,0.534563,-138.869522,0.054531,0.000000
57.510002,48.786003,-138.869522,0.017936,0.002120,0.053855,217.010986,11.055066,0.538545,-138.869522,0.054913,0.000000
57.740002,49.846519,-138.869522,0.017966,0.002141,0.054392,221.728394,11.295382,0.543920,-138.869522,0.055294,0.000000
57.970001,50.513439,-138.914017,0.017975,0.002157,0.054783,224.694992,11.446509,0.547826,-138.914017,0.055676,0.000000
58.200005,51.029549,-138.825043,0.017932,0.002169,0.055094,226.990768,11.563461,0.550944,-138.825043,0.056066,0.000000
58.430004,51.570232,-138.825043,0.017949,0.002181,0.055406,229.395844,11.685982,0.554063,-138.825043,0.056448,0.000000
58.660004,52.092300,-138.736084,0.017970,0.002194,0.055727,231.718124,11.804284,0.557273,-138.736084,0.056829,0.000000
58.890003,52.893646,-138.780563,0.018014,0.002209,0.056101,235.282684,11.985871,0.561012,-138.780563,0.057211,0.000000
59.120003,53.424274,-138.780563,0.017983,0.002224,0.056483,237.643036,12.106114,0.564827,-138.780563,0.057592,0.000000
59.350002,54.122845,-138.780563,0.017996,0.002237,0.056811,240.750443,12.264412,0.568113,-138.780563,0.057983,0.000000
59.580002,54.740612,-138.691605,0.018014,0.002250,0.057159,243.498398,12.404400,0.571595,-138.691605,0.058365,0.000000
59.810001,56.294895,-138.691605,0.018052,0.002277,0.057827,250.412201,12.756606,0.578271,-138.691605,0.058746,0.000000
60.040005,56.869839,-138.691605,0.018057,0.002291,0.058181,252.969681,12.886890,0.581814,-138.691605,0.059128,0.000000
60.270004,57.288013,-138.780563,0.018052,0.002304,0.058521,254.829803,12.981649,0.585205,-138.780563,0.059509,0.000000
60.500004,57.972805,-138.780563,0.018095,0.002320,0.058919,257.875916,13.136826,0.589187,-138.780563,0.059900,0.000000
60.730003,58.389118,-138.647125,0.018095,0.002326,0.059075,259.727783,13.231163,0.590746,-138.647125,0.060281,0.000000
60.960003,59.581455,-138.647125,0.018108,0.002348,0.059639,265.031555,13.501350,0.596393,-138.647125,0.060663,0.000000
61.190002,60.405144,-138.647125,0.018104,0.002362,0.059995,268.695496,13.688001,0.599951,-138.647125,0.061044,0.000000
61.420002,60.870235,-138.647125,0.018117,0.002374,0.060307,270.764343,13.793392,0.603070,-138.647125,0.061435,0.000000
61.650002,61.740471,-138.647125,0.018126,0.002390,0.060714,274.635345,13.990591,0.607143,-138.647125,0.061816,0.000000
61.880001,62.454681,-138.602646,0.018100,0.002408,0.061156,277.812286,14.152433,0.611563,-138.602646,0.062198,0.000000
62.110004,63.344276,-138.558167,0.018139,0.002422,0.061521,281.769409,14.354018,0.615212,-138.558167,0.062579,0.000000
62.340004,63.924805,-138.647125,0.018173,0.002437,0.061894,284.351746,14.485568,0.618936,-138.647125,0.062961,0.000000
62.570004,64.701202,-138.602646,0.018151,0.002449,0.062206,287.805328,14.661502,0.622055,-138.602646,0.063350,0.000000
62.800003,65.202423,-138.602646,0.018156,0.002463,0.062570,290.034851,14.775080,0.625704,-138.602646,0.063732,0.000000
63.030003,66.703079,-138.558167,0.018156,0.002484,0.063099,296.710114,15.115133,0.630987,-138.558167,0.064115,0.000000
63.260002,67.072105,-138.513687,0.018203,0.002493,0.063317,298.351624,15.198757,0.633168,-138.513687,0.064496,0.000000
63.490002,67.181580,-138.558167,0.018216,0.002490,0.063255,298.838593,15.223563,0.632547,-138.558167,0.063508,0.000000
63.720001,66.763779,-138.558167,0.018208,0.002490,0.063255,296.980133,15.128888,0.632547,-138.558167,0.063508,0.000000
63.950005,66.423805,-138.558167,0.018225,0.002485,0.063117,295.467834,15.051850,0.631169,-138.558167,0.063255,0.000000
64.180000,66.148247,-138.513687,0.018195,0.002484,0.063099,294.242096,14.989407,0.630987,-138.513687,0.063255,0.000000
64.410004,65.914772,-138.424713,0.018225,0.002484,0.063091,293.203552,14.936501,0.630912,-138.424713,0.063255,0.000000
64.639999,65.702888,-138.469208,0.018212,0.002484,0.063091,292.261047,14.888488,0.630912,-138.469208,0.063255,0.000000
64.870003,65.511490,-138.558167,0.018208,0.002484,0.063082,291.409668,14.845116,0.630821,-138.558167,0.063255,0.000000
65.100006,65.342056,-138.513687,0.018229,0.002484,0.063082,290.655975,14.806722,0.630821,-138.513687,0.063255,0.000000
65.330002,65.209869,-138.424713,0.018225,0.002484,0.063082,290.067993,14.776768,0.630821,-138.424713,0.063255,0.000000
65.560005,65.070602,-138.469208,0.018268,0.002484,0.063082,289.448486,14.745210,0.630821,-138.469208,0.063255,0.000000
65.790001,64.932076,-138.424713,0.018233,0.002484,0.063082,288.832306,14.713819,0.630821,-138.424713,0.063255,0.000000
66.020004,64.812172,-138.513687,0.018238,0.002484,0.063082,288.298950,14.686648,0.630821,-138.513687,0.063255,0.000000
66.250000,64.712379,-138.424713,0.018229,0.002483,0.063073,287.855042,14.664035,0.630730,-138.424713,0.063255,0.000000
66.480003,64.616302,-138.380234,0.018251,0.002483,0.063073,287.427673,14.642263,0.630730,-138.380234,0.063255,0.000000
66.710007,64.517624,-138.335754,0.018212,0.002483,0.063073,286.988739,14.619903,0.630730,-138.335754,0.063255,0.000000
66.940002,64.412987,-138.335754,0.018255,0.002483,0.063073,286.523285,14.596191,0.630730,-138.335754,0.063255,0.000000
67.170006,64.332932,-138.335754,0.018242,0.002483,0.063073,286.167175,14.578051,0.630730,-138.335754,0.063255,0.000000
67.400002,64.252495,-138.335754,0.018238,0.002483,0.063073,285.809357,14.559824,0.630730,-138.335754,0.063255,0.000000
67.630005,64.173927,-138.246796,0.018203,0.002483,0.063073,285.459900,14.542020,0.630730,-138.246796,0.063255,0.000000
67.860001,64.102806,-138.291275,0.018238,0.002483,0.063073,285.143524,14.525904,0.630730,-138.291275,0.063255,0.000000
68.090004,64.056625,-138.291275,0.018216,0.002483,0.063073,284.938110,14.515438,0.630730,-138.291275,0.063255,0.000000
68.320000,63.974705,-138.335754,0.018220,0.002483,0.063064,284.573700,14.496876,0.630639,-138.335754,0.063255,0.000000
68.550003,63.898739,-138.291275,0.018203,0.002483,0.063064,284.235779,14.479661,0.630639,-138.291275,0.063255,0.000000
68.780006,63.849216,-138.246796,0.018225,0.002483,0.063064,284.015503,14.468439,0.630639,-138.246796,0.063255,0.000000
69.010002,63.788517,-138.246796,0.018225,0.002483,0.063064,283.745483,14.454684,0.630639,-138.246796,0.063255,0.000000
69.240005,63.723354,-138.246796,0.018216,0.002483,0.063064,283.455627,14.439919,0.630639,-138.246796,0.063255,0.000000
69.470001,63.674946,-138.291275,0.018238,0.002483,0.063064,283.240295,14.428949,0.630639,-138.291275,0.063255,0.000000
69.700005,63.614246,-138.202316,0.018225,0.002483,0.063064,282.970306,14.415195,0.630639,-138.202316,0.063255,0.000000
69.930000,63.574406,-138.202316,0.018246,0.002483,0.063064,282.793091,14.406166,0.630639,-138.202316,0.063255,0.000000
70.160004,63.500301,-138.157837,0.018229,0.002483,0.063064,282.463440,14.389374,0.630639,-138.157837,0.063255,0.000000
70.390007,63.479820,-138.157837,0.018203,0.002483,0.063064,282.372345,14.384733,0.630639,-138.157837,0.063255,0.000000
70.620003,63.426571,-138.202316,0.018225,0.002483,0.063064,282.135468,14.372666,0.630639,-138.202316,0.063255,0.000000
70.850006,63.387100,-138.113358,0.018229,0.002483,0.063064,281.959900,14.363723,0.630639,-138.113358,0.063255,0.000000
71.080002,63.348373,-138.113358,0.018229,0.002483,0.063064,281.787628,14.354946,0.630639,-138.113358,0.063255,0.000000
71.310005,63.305923,-138.113358,0.018229,0.002483,0.063064,281.598816,14.345327,0.630639,-138.113358,0.063255,0.000000
71.540001,63.256771,-138.113358,0.018246,0.002483,0.063064,281.380157,14.334189,0.630639,-138.113358,0.063255,0.000000
71.770004,63.229588,-138.113358,0.018242,0.002483,0.063064,281.259247,14.328029,0.630639,-138.113358,0.063255,0.000000
72.000000,63.182667,-138.113358,0.018216,0.002483,0.063056,281.050537,14.317397,0.630563,-138.113358,0.063255,0.000000
72.230003,63.155857,-138.113358,0.018238,0.002483,0.063056,280.931274,14.311322,0.630563,-138.113358,0.063255,0.000000
72.460007,63.106705,-138.068878,0.018229,0.002483,0.063056,280.712646,14.300183,0.630563,-138.068878,0.063255,0.000000
72.690002,63.073936,-138.068878,0.018242,0.002483,0.063056,280.566895,14.292759,0.630563,-138.068878,0.063255,0.000000
72.920006,63.050476,-138.068878,0.018225,0.002483,0.063056,280.462524,14.287442,0.630563,-138.068878,0.063255,0.000000
73.150002,63.016216,-138.068878,0.018242,0.002483,0.063056,280.310120,14.279678,0.630563,-138.068878,0.063255,0.000000
73.380005,62.981960,-138.024384,0.018199,0.002483,0.063056,280.157745,14.271916,0.630563,-138.024384,0.063255,0.000000
73.610001,62.937275,-137.935425,0.018220,0.002483,0.063056,279.958984,14.261790,0.630563,-137.935425,0.063255,0.000000
73.840004,62.911209,-138.024384,0.018233,0.002483,0.063056,279.843048,14.255884,0.630563,-138.024384,0.063255,0.000000
74.070007,62.879559,-138.068878,0.018212,0.002483,0.063056,279.702240,14.248712,0.630563,-138.068878,0.063255,0.000000
74.300003,62.853119,-137.979904,0.018203,0.002483,0.063056,279.584625,14.242720,0.630563,-137.979904,0.063255,0.000000
74.530006,62.820351,-137.935425,0.018220,0.002483,0.063056,279.438873,14.235295,0.630563,-137.935425,0.063255,0.000000
74.760002,62.787952,-137.935425,0.018246,0.002483,0.063056,279.294769,14.227953,0.630563,-137.935425,0.063255,0.000000
74.990005,62.773060,-137.935425,0.018216,0.002483,0.063056,279.228516,14.224579,0.630563,-137.935425,0.063255,0.000000
75.220001,62.735447,-137.979904,0.018242,0.002483,0.063056,279.061218,14.216055,0.630563,-137.979904,0.063255,0.000000
75.450005,62.701561,-137.935425,0.018255,0.002483,0.063056,278.910461,14.208377,0.630563,-137.935425,0.063255,0.000000
75.680000,62.697838,-137.890945,0.018203,0.002483,0.063056,278.893921,14.207533,0.630563,-137.890945,0.063255,0.000000
75.910004,62.656879,-137.890945,0.018225,0.002483,0.063056,278.711731,14.198253,0.630563,-137.890945,0.063255,0.000000
76.140007,62.625599,-137.890945,0.018238,0.002483,0.063056,278.572571,14.191164,0.630563,-137.890945,0.063255,0.000000
76.370003,62.606609,-137.890945,0.018246,0.002483,0.063056,278.488098,14.186861,0.630563,-137.890945,0.063255,0.000000
76.600006,62.584267,-137.890945,0.018233,0.002483,0.063056,278.388733,14.181798,0.630563,-137.890945,0.063255,0.000000
76.830002,62.564156,-137.846466,0.018246,0.002483,0.063056,278.299255,14.177240,0.630563,-137.846466,0.063255,0.000000
77.060005,62.528408,-137.801987,0.018212,0.002483,0.063056,278.140259,14.169140,0.630563,-137.801987,0.063255,0.000000
77.290001,62.506439,-137.801987,0.018255,0.002483,0.063056,278.042542,14.164162,0.630563,-137.801987,0.063255,0.000000
77.520004,62.494152,-137.846466,0.018242,0.002483,0.063056,277.987885,14.161378,0.630563,-137.846466,0.063255,0.000000
77.750000,62.472553,-137.801987,0.018255,0.002483,0.063056,277.891785,14.156484,0.630563,-137.801987,0.063255,0.000000
77.980003,62.449841,-137.801987,0.018246,0.002483,0.063056,277.790771,14.151336,0.630563,-137.801987,0.063255,0.000000
78.210007,62.417442,-137.757507,0.018264,0.002483,0.063056,277.646637,14.143994,0.630563,-137.757507,0.063255,0.000000
78.440002,62.411858,-137.757507,0.018220,0.002483,0.063056,277.621796,14.142729,0.630563,-137.757507,0.063255,0.000000
78.670006,62.383556,-137.757507,0.018220,0.002483,0.063056,277.495911,14.136315,0.630563,-137.757507,0.063255,0.000000
78.900002,62.370525,-137.757507,0.018229,0.002483,0.063056,277.437958,14.133364,0.630563,-137.757507,0.063255,0.000000
79.130005,62.360844,-137.624069,0.018246,0.002483,0.063056,277.394897,14.131169,0.630563,-137.624069,0.063255,0.000000
79.360001,62.331425,-137.624069,0.018255,0.002483,0.063056,277.264038,14.124503,0.630563,-137.624069,0.063255,0.000000
79.590004,62.313549,-137.713028,0.018259,0.002483,0.063056,277.184509,14.120452,0.630563,-137.713028,0.063255,0.000000
79.820007,62.302753,-137.713028,0.018225,0.002483,0.063056,277.136475,14.118006,0.630563,-137.713028,0.063255,0.000000
80.050003,62.252110,-137.713028,0.018264,0.002483,0.063056,276.911224,14.106529,0.630563,-137.713028,0.063255,0.000000
80.280006,62.240192,-137.668549,0.018242,0.002483,0.063056,276.858215,14.103829,0.630563,-137.668549,0.063255,0.000000
80.510002,62.228279,-137.624069,0.018264,0.002483,0.063056,276.805206,14.101130,0.630563,-137.624069,0.063255,0.000000
80.740005,62.220085,-137.668549,0.018272,0.002483,0.063056,276.768768,14.099273,0.630563,-137.668549,0.063255,0.000000
80.970001,62.190666,-137.624069,0.018238,0.002483,0.063056,276.637909,14.092607,0.630563,-137.624069,0.063255,0.000000
81.200005,62.175030,-137.579575,0.018225,0.002483,0.063056,276.568359,14.089064,0.630563,-137.579575,0.063255,0.000000
81.430000,62.156036,-137.535095,0.018225,0.002483,0.063056,276.483856,14.084760,0.630563,-137.535095,0.063255,0.000000
81.660004,62.147099,-137.579575,0.018238,0.002483,0.063056,276.444092,14.082734,0.630563,-137.579575,0.063255,0.000000
81.890007,62.131088,-137.579575,0.018238,0.002483,0.063056,276.372894,14.079106,0.630563,-137.579575,0.063255,0.000000
82.120003,62.108372,-137.579575,0.018255,0.002483,0.063056,276.271851,14.073957,0.630563,-137.579575,0.063255,0.000000
82.350006,62.099064,-137.535095,0.018272,0.002483,0.063056,276.230438,14.071849,0.630563,-137.535095,0.063255,0.000000
82.580002,62.090874,-137.490616,0.018229,0.002483,0.063056,276.194000,14.069993,0.630563,-137.490616,0.063255,0.000000
82.810005,62.061455,-137.579575,0.018246,0.002483,0.063056,276.063141,14.063327,0.630563,-137.579575,0.063255,0.000000
83.040001,62.036133,-137.535095,0.018259,0.002483,0.063056,275.950500,14.057589,0.630563,-137.535095,0.063255,0.000000
83.270004,62.026825,-137.535095,0.018242,0.002483,0.063056,275.909088,14.055480,0.630563,-137.535095,0.063255,0.000000
83.500008,62.017143,-137.535095,0.018255,0.002483,0.063056,275.866028,14.053286,0.630563,-137.535095,0.063255,0.000000
83.730003,62.007088,-137.446136,0.018216,0.002483,0.063056,275.821289,14.051006,0.630563,-137.446136,0.063255,0.000000
83.960007,61.998150,-137.401657,0.018255,0.002483,0.063056,275.781555,14.048982,0.630563,-137.401657,0.063255,0.000000
84.190002,61.964264,-137.490616,0.018246,0.002483,0.063056,275.630798,14.041303,0.630563,-137.490616,0.063255,0.000000
84.420006,61.959797,-137.446136,0.018225,0.002482,0.063047,275.610931,14.040291,0.630473,-137.446136,0.063255,0.000000
84.650002,61.951603,-137.401657,0.018242,0.002482,0.063047,275.574493,14.038434,0.630473,-137.401657,0.063255,0.000000
84.880005,61.920696,-137.446136,0.018233,0.002482,0.063047,275.437012,14.031430,0.630473,-137.446136,0.063255,0.000000
85.110001,61.921444,-137.446136,0.018246,0.002482,0.063047,275.440338,14.031600,0.630473,-137.446136,0.063255,0.000000
85.340004,61.907665,-137.401657,0.018242,0.002482,0.063047,275.379059,14.028478,0.630473,-137.401657,0.063255,0.000000
85.570007,61.883461,-137.401657,0.018242,0.002482,0.063047,275.271393,14.022992,0.630473,-137.401657,0.063255,0.000000
85.800003,61.876385,-137.357178,0.018212,0.002482,0.063047,275.239899,14.021389,0.630473,-137.357178,0.063255,0.000000
86.030006,61.859257,-137.312698,0.018238,0.002482,0.063047,275.163727,14.017509,0.630473,-137.312698,0.063255,0.000000
86.260002,61.841011,-137.312698,0.018264,0.002482,0.063047,275.082550,14.013373,0.630473,-137.312698,0.063255,0.000000
86.490005,61.832817,-137.357178,0.018255,0.002482,0.063047,275.046112,14.011517,0.630473,-137.357178,0.063255,0.000000
86.720001,61.816063,-137.312698,0.018255,0.002482,0.063047,274.971588,14.007720,0.630473,-137.312698,0.063255,0.000000
86.950005,61.804516,-137.312698,0.018255,0.002482,0.063047,274.920227,14.005103,0.630473,-137.312698,0.063255,0.000000
87.180008,61.788132,-137.268219,0.018229,0.002482,0.063047,274.847351,14.001390,0.630473,-137.268219,0.063255,0.000000
87.410004,61.777336,-137.268219,0.018259,0.002482,0.063047,274.799316,13.998944,0.630473,-137.268219,0.063255,0.000000
87.640007,61.775845,-137.268219,0.018246,0.002482,0.063047,274.792694,13.998606,0.630473,-137.268219,0.063255,0.000000
87.870003,61.758717,-137.312698,0.018225,0.002482,0.063047,274.716492,13.994725,0.630473,-137.312698,0.063255,0.000000
88.100006,61.755737,-137.223740,0.018259,0.002482,0.063047,274.703247,13.994050,0.630473,-137.223740,0.063255,0.000000
88.330002,61.735630,-137.268219,0.018212,0.002482,0.063047,274.613800,13.989494,0.630473,-137.268219,0.063255,0.000000
88.560005,61.706585,-137.268219,0.018259,0.002482,0.063047,274.484589,13.982912,0.630473,-137.268219,0.063255,0.000000
88.790001,61.703606,-137.268219,0.018259,0.002482,0.063047,274.471344,13.982237,0.630473,-137.268219,0.063255,0.000000
89.020004,61.698021,-137.179260,0.018238,0.002482,0.063047,274.446503,13.980971,0.630473,-137.179260,0.063255,0.000000
89.250008,61.677540,-137.179260,0.018225,0.002482,0.063047,274.355408,13.976331,0.630473,-137.179260,0.063255,0.000000
89.480003,61.651100,-137.179260,0.018251,0.002482,0.063047,274.237793,13.970339,0.630473,-137.179260,0.063255,0.000000
89.710007,61.661156,-137.134766,0.018242,0.002482,0.063047,274.282532,13.972617,0.630473,-137.134766,0.063255,0.000000
89.940002,61.641045,-137.134766,0.018251,0.002482,0.063047,274.193054,13.968060,0.630473,-137.134766,0.063255,0.000000
90.170006,61.635460,-137.134766,0.018246,0.002482,0.063047,274.168213,13.966794,0.630473,-137.134766,0.063255,0.000000
90.400002,61.622799,-137.179260,0.018238,0.002482,0.063047,274.111908,13.963925,0.630473,-137.179260,0.063255,0.000000
90.630005,61.609394,-137.045807,0.018255,0.002482,0.063047,274.052277,13.960888,0.630473,-137.045807,0.063255,0.000000
90.860001,61.597851,-137.045807,0.018238,0.002482,0.063047,274.000916,13.958273,0.630473,-137.045807,0.063255,0.000000
91.090004,61.590031,-137.134766,0.018242,0.002482,0.063047,273.966125,13.956500,0.630473,-137.134766,0.063255,0.000000
91.320007,61.578861,-137.090286,0.018242,0.002482,0.063047,273.916443,13.953969,0.630473,-137.090286,0.063255,0.000000
91.550003,61.566200,-137.001328,0.018264,0.002482,0.063047,273.860138,13.951100,0.630473,-137.001328,0.063255,0.000000
91.780006,61.553539,-137.001328,0.018233,0.002482,0.063047,273.803802,13.948232,0.630473,-137.001328,0.063255,0.000000
92.010002,61.546837,-137.045807,0.018242,0.002482,0.063047,273.774017,13.946713,0.630473,-137.045807,0.063255,0.000000
92.240005,61.520397,-137.045807,0.018264,0.002482,0.063047,273.656403,13.940722,0.630473,-137.045807,0.063255,0.000000
92.470001,61.517048,-137.090286,0.018246,0.002482,0.063047,273.641510,13.939962,0.630473,-137.090286,0.063255,0.000000
92.700005,61.508854,-137.001328,0.018208,0.002482,0.063047,273.605042,13.938106,0.630473,-137.001328,0.063255,0.000000
92.930008,61.504013,-137.001328,0.018255,0.002482,0.063047,273.583527,13.937008,0.630473,-137.001328,0.063255,0.000000
93.160004,61.480927,-137.001328,0.018238,0.002482,0.063047,273.480835,13.931777,0.630473,-137.001328,0.063255,0.000000
93.390007,61.474594,-136.956848,0.018246,0.002482,0.063047,273.452637,13.930342,0.630473,-136.956848,0.063255,0.000000
93.620003,61.471615,-137.001328,0.018255,0.002482,0.063047,273.439392,13.929667,0.630473,-137.001328,0.063255,0.000000
93.850006,61.463425,-136.912369,0.018255,0.002482,0.063047,273.402954,13.927811,0.630473,-136.912369,0.063255,0.000000
93.900002,61.461189,-136.912369,0.018255,0.002482,0.063047,273.393036,13.927304,0.630473,-136.912369,0.063255,0.000000