File: Data/New pin I-18 old sample 1_08172023_174518.csv
Time (sec),S:Load (lbs),S:HL1 (DIM),S:LVDT (in),S:Position (in),Ch:Position (mm),Ch:Load (N),Ch:Stress (MPa),Ch:Strain (mm/mm),Ch:HL1 (DIM),Set Point (),Cycles ()
0.110000,-0.006332,-11.431604,0.000030,-0.000000,-0.000000,-0.028168,-0.001435,-0.000000,-11.431604,0.000035,0.000000
0.350000,-0.011543,-11.431604,0.000034,-0.000000,-0.000000,-0.051347,-0.002616,-0.000000,-11.431604,0.000035,0.000000
0.590000,0.007820,-11.520566,0.000013,0.000114,0.002905,0.034786,0.001772,0.029053,-11.520566,0.003591,0.000000
0.830000,0.014519,-11.476086,0.000013,0.000254,0.006443,0.064583,0.003290,0.064434,-11.476086,0.007580,0.000000
1.070000,-0.031654,-11.476086,-0.000009,0.000417,0.010589,-0.140806,-0.007173,0.105886,-11.476086,0.011586,0.000000
1.310000,-0.074852,-11.476086,0.000013,0.000570,0.014475,-0.332958,-0.016962,0.144750,-11.476086,0.015576,0.000000
1.550000,0.012657,-11.476086,0.000009,0.000728,0.018499,0.056302,0.002868,0.184991,-11.476086,0.019583,0.000000
1.790000,0.010056,-11.520566,0.000009,0.000875,0.022235,0.044729,0.002279,0.222355,-11.520566,0.023572,0.000000
2.030000,0.021225,-11.476086,0.000026,0.001040,0.026425,0.094413,0.004810,0.264246,-11.476086,0.027578,0.000000
2.270000,-0.014526,-11.565047,0.000009,0.001200,0.030493,-0.064617,-0.003292,0.304926,-11.565047,0.031568,0.000000
2.510000,0.006325,-11.476086,-0.000017,0.001359,0.034524,0.028134,0.001433,0.345243,-11.476086,0.035573,0.000000
2.750000,0.002602,-11.565047,0.000013,0.001510,0.038349,0.011573,0.000590,0.383486,-11.565047,0.039581,0.000000
2.990000,-0.012665,-11.565047,0.000022,0.001665,0.042295,-0.056336,-0.002870,0.422954,-11.565047,0.043570,0.000000
3.230000,-0.042450,-11.565047,0.000026,0.001830,0.046492,-0.188827,-0.009619,0.464921,-11.565047,0.047576,0.000000
3.470000,-0.077827,-11.609529,-0.000009,0.001983,0.050360,-0.346194,-0.017636,0.503603,-11.609529,0.051565,0.000000
3.710000,0.009308,-11.565047,0.000022,0.002139,0.054324,0.041403,0.002109,0.543238,-11.565047,0.055573,0.000000
3.950000,0.017502,-11.565047,0.000022,0.002295,0.058295,0.077852,0.003966,0.582950,-11.565047,0.059562,0.000000
4.190000,0.017128,-11.654009,0.000043,0.002462,0.062528,0.076189,0.003881,0.625280,-11.654009,0.063568,0.000000
4.430000,-0.002983,-11.565047,0.000013,0.002614,0.066404,-0.013269,-0.000676,0.664037,-11.565047,0.067557,0.000000
4.670000,-0.000374,-11.609529,-0.000009,0.002772,0.070419,-0.001663,-0.000085,0.704187,-11.609529,0.071563,0.000000
4.910000,0.005585,-11.609529,0.000009,0.002928,0.074366,0.024842,0.001266,0.743656,-11.609529,0.075553,0.000000
5.150000,-0.004097,-11.609529,0.000026,0.003093,0.078553,-0.018224,-0.000928,0.785532,-11.609529,0.079560,0.000000
5.390000,-0.052132,-11.654009,0.000000,0.003244,0.082405,-0.231893,-0.011813,0.824047,-11.654009,0.083549,0.000000
5.630000,-0.015640,-11.565047,0.000013,0.003405,0.086489,-0.069571,-0.003544,0.864894,-11.565047,0.087555,0.000000
5.870000,0.021599,-11.654009,0.000022,0.003551,0.090183,0.096076,0.004894,0.901834,-11.654009,0.091544,0.000000
6.110000,0.014145,-11.654009,0.000022,0.003718,0.094433,0.062920,0.003205,0.944331,-11.654009,0.095552,0.000000
6.350000,-0.020111,-11.609529,0.000009,0.003876,0.098457,-0.089459,-0.004557,0.984572,-11.609529,0.099541,0.000000
6.590000,-0.005585,-11.654009,0.000013,0.004033,0.102437,-0.024842,-0.001266,1.024374,-11.654009,0.103547,0.000000
6.830000,0.017502,-11.698490,0.000013,0.004186,0.106322,0.077852,0.003966,1.063222,-11.698490,0.107536,0.000000
7.070000,-0.005219,-11.698490,0.000017,0.004349,0.110467,-0.023213,-0.001183,1.104675,-11.698490,0.111542,0.000000
7.310000,-0.048035,-11.698490,0.000022,0.004506,0.114448,-0.213669,-0.010885,1.144477,-11.698490,0.115532,0.000000
7.550000,-0.037613,-11.698490,0.000022,0.004659,0.118334,-0.167311,-0.008523,1.183340,-11.698490,0.119539,0.000000
7.790000,-0.007080,-11.698490,0.000047,0.004819,0.122410,-0.031494,-0.001604,1.224096,-11.698490,0.123545,0.000000
8.030001,0.011543,-11.654009,0.000000,0.004972,0.126285,0.051347,0.002616,1.262853,-11.654009,0.127534,0.000000
8.270000,0.011917,-11.787452,-0.000009,0.005132,0.130344,0.053010,0.002700,1.303442,-11.787452,0.131542,0.000000
8.510000,-0.013039,-11.698490,0.000017,0.005291,0.134386,-0.057999,-0.002955,1.343865,-11.698490,0.135531,0.000000
8.750000,-0.011917,-11.698490,0.000013,0.005449,0.138409,-0.053010,-0.002700,1.384091,-11.698490,0.139537,0.000000
8.990001,0.004463,-11.787452,0.000013,0.005603,0.142312,0.019853,0.001011,1.423120,-11.787452,0.143526,0.000000
9.230000,0.013405,-11.742971,0.000009,0.005766,0.146466,0.059628,0.003038,1.464664,-11.742971,0.147532,0.000000
9.470000,0.023827,-11.831933,0.000030,0.005921,0.150395,0.105986,0.005399,1.503951,-11.831933,0.151521,0.000000
9.710000,0.078194,-11.742971,0.000034,0.006077,0.154350,0.347823,0.017719,1.543495,-11.742971,0.155529,0.000000
9.950001,0.124741,-11.742971,0.000052,0.006238,0.158434,0.554874,0.028267,1.584342,-11.742971,0.159518,0.000000
10.190001,0.175011,-11.787452,0.000039,0.006396,0.162449,0.778486,0.039658,1.624492,-11.787452,0.163524,0.000000
10.430000,0.182457,-11.742971,0.000030,0.006547,0.166299,0.811609,0.041345,1.662992,-11.742971,0.167513,0.000000
10.670000,0.234962,-11.787452,0.000052,0.006711,0.170472,1.045165,0.053243,1.704717,-11.787452,0.171521,0.000000
10.910001,0.267731,-11.787452,0.000047,0.006859,0.174217,1.190926,0.060669,1.742172,-11.787452,0.175510,0.000000
11.150001,0.296410,-11.787452,0.000164,0.007026,0.178467,1.318496,0.067167,1.784669,-11.787452,0.179516,0.000000
11.390000,0.267731,-11.831933,0.000302,0.007180,0.182370,1.190926,0.060669,1.823699,-11.831933,0.183505,0.000000
11.630000,0.286728,-11.831933,0.000453,0.007334,0.186280,1.275429,0.064973,1.862804,-11.831933,0.187513,0.000000
11.870001,0.289330,-11.787452,0.000629,0.007496,0.190400,1.287002,0.065563,1.903999,-11.787452,0.191501,0.000000
12.110001,0.284119,-11.787452,0.000767,0.007658,0.194510,1.263823,0.064382,1.945103,-11.787452,0.195508,0.000000
12.350000,0.289330,-11.876414,0.000931,0.007810,0.198378,1.287002,0.065563,1.983785,-11.876414,0.199514,0.000000
12.590000,0.273689,-11.920895,0.001104,0.007965,0.202316,1.217431,0.062019,2.023163,-11.920895,0.203503,0.000000
12.830001,0.299385,-11.831933,0.001250,0.008122,0.206287,1.331731,0.067842,2.062874,-11.831933,0.207511,0.000000
13.070001,0.300499,-11.876414,0.001410,0.008281,0.210328,1.336686,0.068094,2.103281,-11.876414,0.211500,0.000000
13.310000,0.278908,-11.876414,0.001582,0.008440,0.214387,1.240644,0.063201,2.143871,-11.876414,0.215506,0.000000
13.550000,0.277786,-11.831933,0.001750,0.008596,0.218341,1.235655,0.062947,2.183415,-11.831933,0.219495,0.000000
13.790001,0.300873,-11.920895,0.001919,0.008757,0.222435,1.338349,0.068179,2.224353,-11.920895,0.223503,0.000000
14.030001,0.283745,-11.831933,0.002052,0.008911,0.226346,1.262160,0.064297,2.263458,-11.831933,0.227492,0.000000
14.270000,0.278160,-11.920895,0.002233,0.009072,0.230430,1.237318,0.063032,2.304305,-11.920895,0.231498,0.000000
14.510000,0.297150,-11.876414,0.002393,0.009227,0.234377,1.321788,0.067335,2.343774,-11.876414,0.235487,0.000000
14.750001,0.301994,-11.920895,0.002552,0.009385,0.238383,1.343338,0.068433,2.383833,-11.920895,0.239493,0.000000
14.990001,0.315025,-11.920895,0.002703,0.009532,0.242121,1.401303,0.071386,2.421212,-11.920895,0.243482,0.000000
15.230000,0.314278,-11.876414,0.002897,0.009704,0.246492,1.397977,0.071216,2.464921,-11.876414,0.247490,0.000000
15.470000,0.290451,-11.965376,0.003031,0.009854,0.250300,1.291991,0.065817,2.502996,-11.965376,0.251479,0.000000
15.710001,0.302734,-11.920895,0.003203,0.010015,0.254375,1.346630,0.068601,2.543752,-11.920895,0.255485,0.000000
15.950001,0.304970,-11.920895,0.003376,0.010172,0.258364,1.356573,0.069107,2.583645,-11.920895,0.259474,0.000000
16.190001,0.284866,-11.920895,0.003553,0.010333,0.262466,1.267149,0.064552,2.624658,-11.920895,0.263482,0.000000
16.430000,0.254326,-11.965376,0.003682,0.010486,0.266343,1.131298,0.057631,2.663431,-11.965376,0.267471,0.000000
16.670000,0.293800,-12.009857,0.003867,0.010647,0.270428,1.306889,0.066576,2.704277,-12.009857,0.271477,0.000000
16.910002,0.341835,-11.920895,0.004031,0.010798,0.274261,1.520558,0.077461,2.742611,-11.920895,0.275483,0.000000
17.150002,0.332901,-12.009857,0.004169,0.010959,0.278362,1.480818,0.075436,2.783624,-12.009857,0.279472,0.000000
17.390001,0.305344,-12.009857,0.004389,0.011117,0.282370,1.358236,0.069192,2.823698,-12.009857,0.283480,0.000000
17.630001,0.303108,-12.009857,0.004510,0.011280,0.286515,1.348293,0.068685,2.865150,-12.009857,0.287469,0.000000
17.870001,0.303108,-12.009857,0.004687,0.011426,0.290226,1.348293,0.068685,2.902257,-12.009857,0.291475,0.000000
18.110001,0.291939,-12.054338,0.004855,0.011590,0.294380,1.298609,0.066154,2.943800,-12.054338,0.295464,0.000000
18.350000,0.237572,-12.009857,0.005001,0.011748,0.298395,1.056772,0.053835,2.983951,-12.009857,0.299471,0.000000
18.590000,0.256935,-12.098819,0.005161,0.011903,0.302333,1.142905,0.058222,3.023329,-12.098819,0.303461,0.000000
18.830002,0.309067,-12.009857,0.005320,0.012058,0.306271,1.374798,0.070036,3.062707,-12.009857,0.307467,0.000000
19.070002,0.331413,-12.009857,0.005527,0.012216,0.310286,1.474200,0.075099,3.102857,-12.009857,0.311456,0.000000
19.310001,0.307579,-12.098819,0.005674,0.012380,0.314448,1.368180,0.069698,3.144476,-12.098819,0.315462,0.000000
19.550001,0.314278,-12.009857,0.005846,0.012536,0.318411,1.397977,0.071216,3.184111,-12.009857,0.319451,0.000000
19.790001,0.293053,-12.098819,0.005984,0.012691,0.322356,1.303563,0.066407,3.223565,-12.098819,0.323459,0.000000
20.030001,0.315025,-12.009857,0.006148,0.012841,0.326164,1.401303,0.071386,3.261641,-12.009857,0.327448,0.000000
20.270000,0.295662,-12.143300,0.006321,0.013010,0.330465,1.315170,0.066998,3.304652,-12.143300,0.331454,0.000000
20.510000,0.243530,-11.965376,0.006497,0.013162,0.334308,1.083277,0.055185,3.343077,-11.965376,0.335443,0.000000
20.750002,0.315025,-12.098819,0.006657,0.013320,0.338339,1.401303,0.071386,3.383393,-12.098819,0.339451,0.000000
20.990002,0.337364,-12.098819,0.006821,0.013474,0.342233,1.500671,0.076448,3.422332,-12.098819,0.343440,0.000000
21.230001,0.317261,-12.054338,0.006993,0.013640,0.346448,1.411246,0.071892,3.464481,-12.054338,0.347446,0.000000
21.470001,0.291565,-12.054338,0.007166,0.013795,0.350386,1.296946,0.066070,3.503859,-12.054338,0.351435,0.000000
21.710001,0.312790,-12.098819,0.007312,0.013953,0.354401,1.391359,0.070879,3.544009,-12.098819,0.355441,0.000000
21.950001,0.315773,-12.098819,0.007476,0.014104,0.358243,1.404629,0.071555,3.582433,-12.098819,0.359448,0.000000
22.190001,0.306458,-12.143300,0.007679,0.014267,0.362389,1.363191,0.069444,3.623886,-12.143300,0.363438,0.000000
22.430000,0.250603,-12.054338,0.007838,0.014424,0.366360,1.114737,0.056787,3.663597,-12.054338,0.367444,0.000000
22.670002,0.275925,-12.187780,0.007989,0.014581,0.370367,1.227374,0.062525,3.703671,-12.187780,0.371433,0.000000
22.910002,0.323219,-12.187780,0.008127,0.014732,0.374200,1.437751,0.073243,3.742005,-12.187780,0.375440,0.000000
23.150002,0.326569,-12.098819,0.008291,0.014896,0.378362,1.452650,0.074001,3.783623,-12.098819,0.379430,0.000000
23.390001,0.290817,-12.143300,0.008472,0.015054,0.382377,1.293620,0.065900,3.823773,-12.143300,0.383436,0.000000
23.630001,0.309067,-12.098819,0.008632,0.015205,0.386202,1.374798,0.070036,3.862016,-12.098819,0.387425,0.000000
23.870001,0.315025,-12.187780,0.008791,0.015366,0.390304,1.401303,0.071386,3.903044,-12.187780,0.391431,0.000000
24.110001,0.312050,-12.143300,0.008964,0.015525,0.394329,1.388067,0.070712,3.943285,-12.143300,0.395420,0.000000
24.350000,0.297150,-12.232262,0.009149,0.015684,0.398378,1.321788,0.067335,3.983784,-12.232262,0.399428,0.000000
24.590002,0.266243,-12.187780,0.009300,0.015837,0.402254,1.184308,0.060332,4.022541,-12.187780,0.403417,0.000000
24.830002,0.307579,-12.232262,0.009451,0.015998,0.406357,1.368180,0.069698,4.063569,-12.232262,0.407423,0.000000
25.070002,0.327682,-12.276743,0.009602,0.016147,0.410146,1.457605,0.074254,4.101464,-12.276743,0.411412,0.000000
25.310001,0.329918,-12.187780,0.009779,0.016310,0.414275,1.467548,0.074760,4.142749,-12.187780,0.415419,0.000000
25.550001,0.296776,-12.232262,0.009955,0.016469,0.418325,1.320125,0.067250,4.183248,-12.232262,0.419409,0.000000
25.790001,0.314278,-12.187780,0.010128,0.016629,0.422366,1.397977,0.071216,4.223655,-12.187780,0.423415,0.000000
26.030001,0.339973,-12.232262,0.010274,0.016779,0.426190,1.512277,0.077039,4.261898,-12.232262,0.427404,0.000000
26.270000,0.311302,-12.276743,0.010438,0.016946,0.430430,1.384741,0.070542,4.304304,-12.276743,0.431410,0.000000
26.510002,0.284492,-12.232262,0.010615,0.017097,0.434264,1.265486,0.064467,4.342637,-12.232262,0.435417,0.000000
26.750002,0.303482,-12.232262,0.010727,0.017253,0.438227,1.349956,0.068770,4.382273,-12.232262,0.439407,0.000000
26.990002,0.333641,-12.187780,0.010921,0.017412,0.442259,1.484110,0.075604,4.422589,-12.187780,0.443413,0.000000
27.230001,0.341095,-12.232262,0.011089,0.017573,0.446344,1.517266,0.077293,4.463436,-12.232262,0.447402,0.000000
27.470001,0.322472,-12.232262,0.011257,0.017724,0.450177,1.434425,0.073073,4.501769,-12.232262,0.451409,0.000000
27.710001,0.317635,-12.232262,0.011417,0.017885,0.454287,1.412909,0.071977,4.542873,-12.232262,0.455399,0.000000
27.950001,0.318748,-12.232262,0.011581,0.018038,0.458165,1.417864,0.072229,4.581645,-12.232262,0.459404,0.000000
28.190001,0.327316,-12.276743,0.011758,0.018201,0.462301,1.455976,0.074171,4.623007,-12.276743,0.463394,0.000000
28.430002,0.301994,-12.232262,0.011904,0.018359,0.466316,1.343338,0.068433,4.663157,-12.232262,0.467400,0.000000
28.670002,0.292686,-12.232262,0.012077,0.018514,0.470253,1.301934,0.066324,4.702535,-12.232262,0.471389,0.000000
28.910002,0.329178,-12.276743,0.012240,0.018672,0.474278,1.464256,0.074593,4.742776,-12.276743,0.475396,0.000000
29.150002,0.301247,-12.321223,0.012413,0.018833,0.478353,1.340012,0.068263,4.783532,-12.321223,0.479386,0.000000
29.390001,0.328056,-12.232262,0.012564,0.018987,0.482282,1.459267,0.074339,4.822819,-12.232262,0.483392,0.000000
29.630001,0.313911,-12.321223,0.012715,0.019141,0.486176,1.396348,0.071133,4.861758,-12.321223,0.487381,0.000000
29.870001,0.332901,-12.276743,0.012887,0.019301,0.490251,1.480818,0.075436,4.902514,-12.276743,0.491388,0.000000
30.110001,0.348167,-12.321223,0.013060,0.019452,0.494085,1.548726,0.078896,4.940847,-12.321223,0.495378,0.000000
30.350002,0.336624,-12.365705,0.013228,0.019619,0.498325,1.497379,0.076280,4.983253,-12.365705,0.499384,0.000000
30.590002,0.318748,-12.276743,0.013370,0.019772,0.502203,1.417864,0.072229,5.022026,-12.276743,0.503373,0.000000
30.830002,0.315025,-12.321223,0.013551,0.019928,0.506166,1.401303,0.071386,5.061661,-12.321223,0.507380,0.000000
31.070002,0.332901,-12.321223,0.013745,0.020085,0.510155,1.480818,0.075436,5.101554,-12.321223,0.511386,0.000000
31.310001,0.315025,-12.276743,0.013913,0.020249,0.514317,1.401303,0.071386,5.143173,-12.276743,0.515375,0.000000
31.550001,0.323959,-12.321223,0.014068,0.020400,0.518160,1.441043,0.073410,5.181597,-12.321223,0.519381,0.000000
31.790001,0.322472,-12.365705,0.014241,0.020559,0.522200,1.434425,0.073073,5.222004,-12.365705,0.523371,0.000000
32.030003,0.340347,-12.365705,0.014418,0.020709,0.526016,1.513940,0.077124,5.260156,-12.365705,0.527378,0.000000
32.270000,0.348907,-12.410186,0.014599,0.020877,0.530274,1.552018,0.079064,5.302744,-12.410186,0.531367,0.000000
32.510002,0.330666,-12.321223,0.014754,0.021032,0.534220,1.470874,0.074930,5.342197,-12.321223,0.535373,0.000000
32.750000,0.343697,-12.365705,0.014922,0.021189,0.538209,1.528839,0.077883,5.382091,-12.365705,0.539363,0.000000
32.990002,0.410355,-12.410186,0.015060,0.021346,0.542198,1.825348,0.092988,5.421983,-12.410186,0.543370,0.000000
33.230003,0.643829,-12.365705,0.015233,0.021504,0.546213,2.863896,0.145894,5.462133,-12.365705,0.547359,0.000000
33.470001,0.684044,-12.410186,0.015271,-0.000000,-0.000009,3.042779,0.155007,-0.000091,-12.410186,0.000207,0.000000
33.710003,0.675110,-12.365705,0.015276,-0.000000,-0.000009,3.003039,0.152982,-0.000091,-12.365705,0.000207,0.000000
33.950001,0.702667,-12.454666,0.015254,-0.000000,-0.000000,3.125620,0.159227,-0.000000,-12.454666,0.000494,0.000000
34.190002,0.705269,-12.365705,0.015271,0.000000,0.000008,3.137192,0.159816,0.000076,-12.365705,0.000893,0.000000
34.430000,0.741020,-12.410186,0.015280,0.000016,0.000398,3.296222,0.167918,0.003982,-12.410186,0.001291,0.000000
34.670002,0.800224,-12.365705,0.015284,0.000026,0.000668,3.559576,0.181333,0.006677,-12.365705,0.001691,0.000000
34.910000,0.797989,-12.365705,0.015319,0.000041,0.001040,3.549632,0.180827,0.010401,-12.365705,0.002089,0.000000
35.150002,0.911194,-12.454666,0.015302,0.000058,0.001466,4.053193,0.206479,0.014655,-12.454666,0.002497,0.000000
35.390003,1.045250,-12.365705,0.015340,0.000074,0.001873,4.649504,0.236857,0.018728,-12.365705,0.002896,0.000000
35.630001,1.146164,-12.410186,0.015345,0.000088,0.002245,5.098392,0.259724,0.022452,-12.410186,0.003294,0.000000
35.870003,1.306282,-12.454666,0.015340,0.000108,0.002748,5.810633,0.296008,0.027478,-12.454666,0.003694,0.000000
36.110001,1.432144,-12.454666,0.015375,0.000125,0.003182,6.370495,0.324529,0.031823,-12.454666,0.004092,0.000000
36.350002,1.555397,-12.454666,0.015396,0.000139,0.003538,6.918752,0.352458,0.035381,-12.454666,0.004492,0.000000
36.590000,1.664879,-12.454666,0.015418,0.000151,0.003841,7.405751,0.377267,0.038409,-12.454666,0.004890,0.000000
36.830002,1.801910,-12.454666,0.015414,0.000167,0.004248,8.015298,0.408319,0.042482,-12.454666,0.005290,0.000000
37.070004,1.951599,-12.499147,0.015418,0.000181,0.004604,8.681147,0.442239,0.046039,-12.499147,0.005697,0.000000
37.310001,2.221947,-12.499147,0.015418,0.000201,0.005099,9.883713,0.503500,0.050990,-12.499147,0.006095,0.000000
37.550003,2.366798,-12.454666,0.015435,0.000209,0.005306,10.528045,0.536324,0.053064,-12.454666,0.006495,0.000000
37.790001,2.508675,-12.454666,0.015470,0.000220,0.005593,11.159142,0.568474,0.055926,-12.454666,0.006893,0.000000
38.030003,2.686295,-12.365705,0.015465,0.000238,0.006035,11.949235,0.608723,0.060346,-12.365705,0.007293,0.000000
38.270000,3.121597,-12.543628,0.015491,0.000264,0.006695,13.885558,0.707364,0.066947,-12.543628,0.007691,0.000000
38.510002,3.317467,-12.454666,0.015530,0.000277,0.007032,14.756829,0.751749,0.070323,-12.454666,0.008091,0.000000
38.750000,3.549080,-12.499147,0.015517,0.000292,0.007423,15.787096,0.804233,0.074229,-12.499147,0.008498,0.000000
38.990002,3.844742,-12.499147,0.015534,0.000308,0.007821,17.102266,0.871231,0.078211,-12.499147,0.008898,0.000000
39.230003,4.148224,-12.499147,0.015569,0.000324,0.008237,18.452221,0.940001,0.082374,-12.499147,0.009296,0.000000
39.470001,4.374260,-12.543628,0.015590,0.000339,0.008602,19.457680,0.991221,0.086023,-12.543628,0.009695,0.000000
39.710003,4.475174,-12.499147,0.015565,0.000344,0.008742,19.906569,1.014089,0.087416,-12.499147,0.010094,0.000000
39.950001,5.098892,-12.499147,0.015595,0.000373,0.009470,22.681005,1.155426,0.094698,-12.499147,0.010493,0.000000
40.190002,5.331253,-12.543628,0.015608,0.000385,0.009782,23.714598,1.208079,0.097817,-12.543628,0.010891,0.000000
40.430000,5.613510,-12.543628,0.015621,0.000400,0.010154,24.970140,1.272040,0.101541,-12.543628,0.011291,0.000000
40.670002,5.916626,-12.543628,0.015616,0.000415,0.010536,26.318466,1.340727,0.105356,-12.543628,0.011698,0.000000
40.910004,6.302773,-12.454666,0.015634,0.000432,0.010970,28.036133,1.428229,0.109701,-12.454666,0.012097,0.000000
41.150002,6.666954,-12.543628,0.015646,0.000452,0.011482,29.656094,1.510753,0.114819,-12.543628,0.012496,0.000000
41.390003,6.974159,-12.499147,0.015677,0.000464,0.011794,31.022610,1.580367,0.117937,-12.499147,0.012894,0.000000
41.630001,7.130562,-12.543628,0.015698,0.000475,0.012071,31.718323,1.615808,0.120708,-12.543628,0.013294,0.000000
41.870003,7.526016,-12.543628,0.015711,0.000493,0.012531,33.477394,1.705420,0.125310,-12.543628,0.013692,0.000000
42.110001,8.199638,-12.543628,0.015737,0.000516,0.013103,36.473812,1.858065,0.131033,-12.543628,0.014092,0.000000
42.350002,8.442802,-12.632590,0.015724,0.000531,0.013476,37.555462,1.913166,0.134757,-12.632590,0.014490,0.000000
42.590000,8.744797,-12.588109,0.015772,0.000546,0.013875,38.898800,1.981599,0.138754,-12.588109,0.014899,0.000000
42.830002,9.063171,-12.588109,0.015772,0.000560,0.014231,40.314999,2.053744,0.142312,-12.588109,0.015297,0.000000
43.070004,9.534966,-12.588109,0.015797,0.000578,0.014681,42.413647,2.160654,0.146809,-12.588109,0.015697,0.000000
43.310001,9.801582,-12.543628,0.015789,0.000592,0.015029,43.599617,2.221070,0.150291,-12.543628,0.016095,0.000000
43.550003,9.915901,-12.632590,0.015797,0.000601,0.015253,44.108131,2.246975,0.152531,-12.632590,0.016495,0.000000
43.790001,10.243591,-12.632590,0.015819,0.000614,0.015601,45.565769,2.321231,0.156013,-12.632590,0.016893,0.000000
44.030003,11.100418,-12.632590,0.015832,0.000642,0.016311,49.377125,2.515391,0.163114,-12.632590,0.017292,0.000000
44.270000,11.196121,-12.588109,0.015853,0.000655,0.016632,49.802834,2.537077,0.166323,-12.588109,0.017691,0.000000
44.510002,11.658234,-12.588109,0.015884,0.000672,0.017058,51.858414,2.641793,0.170578,-12.588109,0.018098,0.000000
44.750004,11.848892,-12.677071,0.015901,0.000685,0.017388,52.706505,2.684998,0.173878,-12.677071,0.018498,0.000000
44.990002,12.338188,-12.632590,0.015892,0.000704,0.017890,54.883003,2.795873,0.178904,-12.632590,0.018896,0.000000
45.230003,12.616348,-12.632590,0.015901,0.000718,0.018228,56.120319,2.858905,0.182281,-12.632590,0.019295,0.000000
45.470001,12.736626,-12.632590,0.015931,0.000727,0.018454,56.655342,2.886161,0.184536,-12.632590,0.019694,0.000000
45.710003,13.242310,-12.588109,0.015944,0.000744,0.018888,58.904736,3.000750,0.188881,-12.588109,0.020093,0.000000
45.950001,13.953537,-12.677071,0.015970,0.000770,0.019563,62.068432,3.161917,0.195634,-12.677071,0.020491,0.000000
46.190002,14.047005,-12.632590,0.015978,0.000782,0.019859,62.484196,3.183097,0.198586,-12.632590,0.020891,0.000000
46.430000,14.327400,-12.677071,0.015983,0.000796,0.020214,63.731461,3.246635,0.202144,-12.677071,0.021298,0.000000
46.670002,14.798828,-12.677071,0.016004,0.000815,0.020700,65.828476,3.353462,0.207003,-12.677071,0.021698,0.000000
46.910004,15.085548,-12.632590,0.016009,0.000828,0.021038,67.103874,3.418434,0.210380,-12.632590,0.022096,0.000000
47.150002,15.348816,-12.721552,0.015996,0.000844,0.021438,68.274940,3.478091,0.214376,-12.721552,0.022496,0.000000
47.390003,15.576340,-12.677071,0.016035,0.000856,0.021750,69.287018,3.529649,0.217495,-12.677071,0.022894,0.000000
47.630001,15.991905,-12.677071,0.016060,0.000874,0.022192,71.135544,3.623817,0.221916,-12.677071,0.023294,0.000000
47.870003,16.585464,-12.721552,0.016065,0.000895,0.022738,73.775833,3.758320,0.227381,-12.721552,0.023692,0.000000
48.110001,16.671486,-12.677071,0.016086,0.000908,0.023068,74.158470,3.777813,0.230682,-12.677071,0.024092,0.000000
48.350002,16.914276,-12.721552,0.016104,0.000923,0.023432,75.238457,3.832830,0.234315,-12.721552,0.024499,0.000000
48.590004,17.122429,-12.721552,0.016116,0.000934,0.023727,76.164368,3.879998,0.237267,-12.721552,0.024897,0.000000
48.830002,17.810944,-12.677071,0.016121,0.000958,0.024334,79.227036,4.036017,0.243338,-12.677071,0.025297,0.000000
49.070004,17.875740,-12.766033,0.016142,0.000970,0.024646,79.515266,4.050701,0.246457,-12.766033,0.025695,0.000000
49.310001,17.900314,-12.721552,0.016160,0.000979,0.024871,79.624573,4.056269,0.248713,-12.721552,0.026095,0.000000
49.550003,18.581009,-12.810513,0.016172,0.000999,0.025366,82.652458,4.210517,0.253664,-12.810513,0.026493,0.000000
49.790001,19.129143,-12.766033,0.016177,0.001021,0.025939,85.090675,4.334725,0.259386,-12.766033,0.026892,0.000000
50.030003,19.179787,-12.721552,0.016220,0.001032,0.026216,85.315948,4.346202,0.262157,-12.721552,0.027291,0.000000
50.270004,19.346985,-12.766033,0.016224,0.001049,0.026632,86.059685,4.384089,0.266320,-12.766033,0.027698,0.000000
50.510002,19.689568,-12.766033,0.016229,0.001063,0.026988,87.583572,4.461720,0.269878,-12.766033,0.028098,0.000000
50.750004,20.241791,-12.766033,0.016246,0.001081,0.027465,90.039986,4.586855,0.274647,-12.766033,0.028496,0.000000
50.990002,20.437286,-12.766033,0.016263,0.001094,0.027786,90.909592,4.631155,0.277857,-12.766033,0.028895,0.000000
51.230003,20.432449,-12.766033,0.016289,0.001101,0.027967,90.888077,4.630059,0.279673,-12.766033,0.029294,0.000000
51.470001,20.833496,-12.810513,0.016310,0.001119,0.028435,92.672020,4.720938,0.284352,-12.810513,0.029693,0.000000
51.710003,21.870926,-12.766033,0.016276,0.001148,0.029147,97.286736,4.956022,0.291467,-12.766033,0.030091,0.000000
51.950001,21.860870,-12.810513,0.016302,0.001159,0.029451,97.242004,4.953744,0.294510,-12.810513,0.030500,0.000000
52.190002,22.038490,-12.766033,0.016354,0.001177,0.029901,98.032104,4.993993,0.299007,-12.766033,0.030898,0.000000
52.430004,22.402672,-12.854995,0.016358,0.001191,0.030249,99.652061,5.076518,0.302489,-12.854995,0.031298,0.000000
52.670002,22.360962,-12.766033,0.016375,0.001203,0.030568,99.466530,5.067067,0.305683,-12.766033,0.031696,0.000000
52.910004,23.226357,-12.766033,0.016362,0.001222,0.031047,103.315994,5.263167,0.310467,-12.766033,0.032096,0.000000
53.150002,23.360786,-12.899476,0.016401,0.001235,0.031375,103.913971,5.293630,0.313753,-12.899476,0.032494,0.000000
53.390003,23.588676,-12.810513,0.016397,0.001252,0.031792,104.927673,5.345270,0.317916,-12.810513,0.032894,0.000000
53.630001,24.121544,-12.854995,0.016418,0.001271,0.032294,107.297989,5.466020,0.322942,-12.854995,0.033292,0.000000
53.870003,24.464867,-12.854995,0.016444,0.001288,0.032720,108.825165,5.543818,0.327197,-12.854995,0.033699,0.000000
54.110004,24.605995,-12.810513,0.016453,0.001300,0.033015,109.452934,5.575798,0.330149,-12.810513,0.034099,0.000000
54.350002,24.933311,-12.854995,0.016466,0.001317,0.033457,110.908905,5.649969,0.334570,-12.854995,0.034497,0.000000
54.590004,24.986191,-12.810513,0.016492,0.001325,0.033648,111.144127,5.661952,0.336477,-12.810513,0.034897,0.000000
54.830002,25.665024,-12.854995,0.016474,0.001344,0.034134,114.163727,5.815778,0.341337,-12.854995,0.035295,0.000000
55.070004,26.072777,-12.854995,0.016509,0.001361,0.034567,115.977501,5.908176,0.345667,-12.854995,0.035695,0.000000
55.310001,26.235870,-12.810513,0.016500,0.001372,0.034844,116.702980,5.945133,0.348437,-12.810513,0.036093,0.000000
55.550003,27.154884,-12.899476,0.016539,0.001396,0.035460,120.790955,6.153385,0.354599,-12.899476,0.036492,0.000000
55.790001,27.577904,-12.854995,0.016548,0.001414,0.035911,122.672646,6.249242,0.359111,-12.854995,0.036900,0.000000
56.030003,27.675461,-12.899476,0.016569,0.001425,0.036188,123.106598,6.271349,0.361881,-12.899476,0.037299,0.000000
56.270004,27.865005,-12.854995,0.016582,0.001440,0.036570,123.949738,6.314301,0.365697,-12.854995,0.037698,0.000000
56.510002,28.463776,-12.899476,0.016591,0.001456,0.036995,126.613197,6.449984,0.369951,-12.899476,0.038097,0.000000
56.750004,28.853653,-12.988438,0.016617,0.001473,0.037402,128.347458,6.538331,0.374023,-12.988438,0.038495,0.000000
56.990002,29.262512,-12.854995,0.016617,0.001489,0.037819,130.166153,6.630980,0.378187,-12.854995,0.038895,0.000000
57.230003,29.867249,-12.943956,0.016642,0.001507,0.038279,132.856155,6.768015,0.382789,-12.943956,0.039293,0.000000
57.470001,30.304413,-12.899476,0.016664,0.001523,0.038686,134.800766,6.867078,0.386862,-12.899476,0.039693,0.000000
57.710003,30.703972,-12.899476,0.016673,0.001538,0.039068,136.578094,6.957620,0.390677,-12.899476,0.040100,0.000000
57.950005,30.970589,-12.943956,0.016677,0.001550,0.039380,137.764053,7.018036,0.393796,-12.943956,0.040498,0.000000
58.190002,31.438286,-12.899476,0.016690,0.001565,0.039761,139.844482,7.124017,0.397611,-12.899476,0.040898,0.000000
58.430004,31.822578,-12.943956,0.016686,0.001579,0.040117,141.553894,7.211099,0.401169,-12.943956,0.041296,0.000000
58.670002,32.467155,-12.943956,0.016716,0.001599,0.040603,144.421127,7.357163,0.406028,-12.943956,0.041696,0.000000
58.910004,32.686111,-12.943956,0.016729,0.001607,0.040828,145.395081,7.406779,0.408284,-12.943956,0.042094,0.000000
59.150002,32.967995,-12.988438,0.016742,0.001619,0.041115,146.648972,7.470654,0.411146,-12.988438,0.042494,0.000000
59.390003,33.445747,-12.943956,0.016742,0.001636,0.041557,148.774109,7.578915,0.415566,-12.943956,0.042892,0.000000
59.630001,34.780701,-12.988438,0.016767,0.001663,0.042233,154.712280,7.881419,0.422334,-12.988438,0.043299,0.000000
59.870003,35.090889,-12.899476,0.016759,0.001677,0.042589,156.092072,7.951709,0.425892,-12.899476,0.043699,0.000000
60.110004,35.511673,-12.988438,0.016802,0.001691,0.042962,157.963806,8.047060,0.429616,-12.988438,0.044097,0.000000
60.350002,36.031502,-13.032919,0.016815,0.001706,0.043343,160.276123,8.164855,0.433431,-13.032919,0.044497,0.000000
60.590004,36.575539,-12.943956,0.016815,0.001724,0.043778,162.696121,8.288136,0.437776,-12.943956,0.044895,0.000000
60.830002,37.022011,-13.032919,0.016824,0.001736,0.044106,164.682129,8.389307,0.441061,-13.032919,0.045295,0.000000
61.070004,37.024994,-12.988438,0.016845,0.001747,0.044367,164.695404,8.389984,0.443665,-12.988438,0.045693,0.000000
61.310001,38.540550,-12.988438,0.016858,0.001773,0.045034,171.436935,8.733414,0.450342,-12.988438,0.046092,0.000000
61.550003,38.771416,-12.988438,0.016884,0.001784,0.045320,172.463867,8.785728,0.453203,-12.988438,0.046500,0.000000
61.790005,39.243958,-12.988438,0.016862,0.001799,0.045685,174.565842,8.892808,0.456852,-12.988438,0.046899,0.000000
62.030003,39.824120,-13.032919,0.016897,0.001814,0.046067,177.146530,9.024274,0.460667,-13.032919,0.047298,0.000000
62.270004,40.588226,-12.988438,0.016910,0.001831,0.046509,180.545441,9.197423,0.465088,-12.988438,0.047697,0.000000
62.510002,41.500168,-13.077399,0.016914,0.001852,0.047030,184.601959,9.404073,0.470296,-13.077399,0.048095,0.000000
62.750004,41.861366,-13.032919,0.016914,0.001864,0.047358,186.208664,9.485922,0.473581,-13.032919,0.048495,0.000000
62.990002,42.184586,-12.988438,0.016940,0.001875,0.047637,187.646408,9.559163,0.476367,-12.988438,0.048893,0.000000
63.230003,42.877945,-13.077399,0.016949,0.001894,0.048114,190.730621,9.716281,0.481136,-13.077399,0.049293,0.000000
63.470001,44.057617,-13.032919,0.016966,0.001916,0.048660,195.978073,9.983599,0.486601,-13.032919,0.049700,0.000000
63.710003,44.555855,-13.077399,0.016987,0.001929,0.048998,198.194336,10.096501,0.489977,-13.077399,0.050098,0.000000
63.950005,45.095795,-13.077399,0.017000,0.001945,0.049414,200.596115,10.218854,0.494141,-13.077399,0.050498,0.000000
64.190002,45.733292,-13.077399,0.017000,0.001959,0.049761,203.431839,10.363312,0.497608,-13.077399,0.050896,0.000000
64.430000,46.623634,-13.166362,0.017022,0.001977,0.050221,207.392288,10.565066,0.502210,-13.166362,0.051296,0.000000
64.670006,47.087616,-13.077399,0.017052,0.001990,0.050542,209.456177,10.670206,0.505420,-13.077399,0.051694,0.000000
64.910004,47.352371,-13.077399,0.017022,0.002000,0.050801,210.633865,10.730201,0.508009,-13.077399,0.052094,0.000000
65.150002,48.168983,-13.077399,0.017039,0.002019,0.051278,214.266342,10.915248,0.512778,-13.077399,0.052501,0.000000
65.389999,49.686775,-13.077399,0.017065,0.002042,0.051859,221.017807,11.259184,0.518591,-13.077399,0.052901,0.000000
65.630005,50.068825,-13.166362,0.017052,0.002054,0.052180,222.717255,11.345757,0.521801,-13.166362,0.053299,0.000000
65.870003,50.870544,-13.077399,0.017099,0.002070,0.052580,226.283478,11.527431,0.525798,-13.077399,0.053699,0.000000
66.110001,51.319252,-13.166362,0.017091,0.002083,0.052908,228.279434,11.629108,0.529083,-13.166362,0.054097,0.000000
66.350006,52.513451,-13.166362,0.017112,0.002106,0.053481,233.591492,11.899718,0.534806,-13.166362,0.054496,0.000000
66.590004,52.905563,-13.077399,0.017121,0.002115,0.053733,235.335693,11.988572,0.537334,-13.077399,0.054895,0.000000
66.830002,53.216866,-13.166362,0.017138,0.002125,0.053976,236.720444,12.059114,0.539756,-13.166362,0.055294,0.000000
67.070000,54.199928,-13.121881,0.017151,0.002142,0.054409,241.093323,12.281879,0.544086,-13.121881,0.055702,0.000000
67.310005,55.790703,-13.166362,0.017156,0.002169,0.055085,248.169434,12.642354,0.550854,-13.166362,0.056100,0.000000
67.550003,56.267342,-13.166362,0.017173,0.002180,0.055381,250.289642,12.750361,0.553806,-13.166362,0.056499,0.000000
67.790001,56.855690,-13.166362,0.017168,0.002194,0.055736,252.906738,12.883683,0.557364,-13.166362,0.056898,0.000000
68.030006,57.545692,-13.121881,0.017181,0.002211,0.056153,255.976028,13.040040,0.561527,-13.121881,0.057297,0.000000
68.270004,58.660576,-13.077399,0.017203,0.002227,0.056560,260.935272,13.292676,0.565600,-13.077399,0.057695,0.000000
68.510002,59.321167,-13.166362,0.017207,0.002241,0.056923,263.873718,13.442369,0.569233,-13.166362,0.058095,0.000000
68.750000,59.848076,-13.166362,0.017203,0.002254,0.057262,266.217529,13.561768,0.572624,-13.166362,0.058493,0.000000
68.990005,60.839325,-13.210842,0.017220,0.002271,0.057679,270.626831,13.786388,0.576788,-13.210842,0.058902,0.000000
69.230003,62.087151,-13.210842,0.017237,0.002291,0.058181,276.177429,14.069149,0.581814,-13.210842,0.059300,0.000000
69.470001,62.777153,-13.121881,0.017268,0.002305,0.058546,279.246735,14.225507,0.585463,-13.121881,0.059700,0.000000
69.710007,63.395287,-13.210842,0.017302,0.002320,0.058919,281.996307,14.365578,0.589187,-13.210842,0.060098,0.000000
69.950005,64.045830,-13.210842,0.017272,0.002332,0.059221,284.890076,14.512993,0.592215,-13.210842,0.060498,0.000000
70.190002,65.569954,-13.166362,0.017311,0.002355,0.059821,291.669708,14.858364,0.598210,-13.166362,0.060896,0.000000
70.430000,66.056267,-13.210842,0.017328,0.002366,0.060107,293.832947,14.968564,0.601072,-13.210842,0.061296,0.000000
70.670006,66.412254,-13.210842,0.017298,0.002375,0.060333,295.416473,15.049232,0.603327,-13.210842,0.061694,0.000000
70.910004,67.700661,-13.299805,0.017324,0.002386,0.060601,301.147583,15.341189,0.606007,-13.299805,0.062059,0.000000
71.150002,67.094063,-13.255323,0.017332,0.002385,0.060575,298.449310,15.203732,0.605750,-13.255323,0.060852,0.000000
71.390007,66.680733,-13.210842,0.017332,0.002377,0.060384,296.610718,15.110070,0.603842,-13.210842,0.060575,0.000000
71.630005,66.361244,-13.255323,0.017345,0.002377,0.060368,295.189545,15.037673,0.603676,-13.255323,0.060575,0.000000
71.870003,66.112129,-13.210842,0.017337,0.002376,0.060358,294.081451,14.981222,0.603585,-13.210842,0.060575,0.000000
72.110001,65.868217,-13.255323,0.017337,0.002376,0.060358,292.996460,14.925951,0.603585,-13.255323,0.060575,0.000000
72.350006,65.672356,-13.210842,0.017345,0.002376,0.060358,292.125214,14.881569,0.603585,-13.210842,0.060575,0.000000
72.590004,65.480202,-13.299805,0.017332,0.002376,0.060358,291.270477,14.838026,0.603585,-13.299805,0.060575,0.000000
72.830002,65.314125,-13.299805,0.017337,0.002376,0.060358,290.531738,14.800392,0.603585,-13.299805,0.060575,0.000000
73.070000,65.191994,-13.255323,0.017341,0.002376,0.060358,289.988464,14.772717,0.603585,-13.255323,0.060575,0.000000
73.310005,65.045280,-13.255323,0.017332,0.002376,0.060358,289.335846,14.739471,0.603585,-13.255323,0.060575,0.000000
73.550003,64.935799,-13.210842,0.017345,0.002376,0.060358,288.848846,14.714663,0.603585,-13.210842,0.060575,0.000000
73.790001,64.805092,-13.255323,0.017332,0.002376,0.060358,288.267456,14.685044,0.603585,-13.255323,0.060575,0.000000
74.030006,64.714241,-13.255323,0.017328,0.002376,0.060358,287.863312,14.664456,0.603585,-13.255323,0.060575,0.000000
74.270004,64.615929,-13.255323,0.017345,0.002376,0.060358,287.425995,14.642179,0.603585,-13.255323,0.060575,0.000000
74.510002,64.527672,-13.299805,0.017345,0.002376,0.060358,287.033417,14.622180,0.603585,-13.299805,0.060575,0.000000
74.750000,64.445381,-13.255323,0.017380,0.002376,0.060358,286.667358,14.603533,0.603585,-13.255323,0.060575,0.000000
74.990005,64.351540,-13.299805,0.017337,0.002376,0.060358,286.249939,14.582268,0.603585,-13.299805,0.060575,0.000000
75.230003,64.272972,-13.344285,0.017350,0.002376,0.060358,285.900452,14.564464,0.603585,-13.344285,0.060575,0.000000
75.470001,64.208931,-13.299805,0.017362,0.002376,0.060358,285.615601,14.549952,0.603585,-13.299805,0.060575,0.000000
75.710007,64.130363,-13.344285,0.017358,0.002376,0.060358,285.266113,14.532148,0.603585,-13.344285,0.060575,0.000000
75.950005,64.067055,-13.344285,0.017362,0.002376,0.060358,284.984497,14.517802,0.603585,-13.344285,0.060575,0.000000
76.190002,64.001518,-13.433248,0.017337,0.002376,0.060358,284.692963,14.502951,0.603585,-13.433248,0.060575,0.000000
76.430000,63.940819,-13.299805,0.017362,0.002376,0.060358,284.422974,14.489196,0.603585,-13.299805,0.060575,0.000000
76.670006,63.877510,-13.255323,0.017358,0.002376,0.060358,284.141357,14.474851,0.603585,-13.255323,0.060575,0.000000
76.910004,63.826866,-13.344285,0.017341,0.002376,0.060358,283.916077,14.463375,0.603585,-13.344285,0.060575,0.000000
77.150002,63.775490,-13.299805,0.017354,0.002376,0.060358,283.687561,14.451733,0.603585,-13.299805,0.060575,0.000000
77.390007,63.739738,-13.344285,0.017350,0.002376,0.060358,283.528503,14.443631,0.603585,-13.344285,0.060575,0.000000
77.630005,63.669731,-13.388766,0.017358,0.002376,0.060358,283.217102,14.427767,0.603585,-13.388766,0.060575,0.000000
77.870003,63.635475,-13.344285,0.017341,0.002376,0.060358,283.064728,14.420005,0.603585,-13.344285,0.060575,0.000000
78.110001,63.580360,-13.388766,0.017367,0.002376,0.060358,282.819580,14.407516,0.603585,-13.388766,0.060575,0.000000
78.350006,63.529350,-13.344285,0.017350,0.002376,0.060358,282.592651,14.395956,0.603585,-13.344285,0.060575,0.000000
78.590004,63.490623,-13.433248,0.017332,0.002376,0.060358,282.420410,14.387181,0.603585,-13.433248,0.060575,0.000000
78.830002,63.453011,-13.344285,0.017345,0.002376,0.060358,282.253082,14.378657,0.603585,-13.344285,0.060575,0.000000
79.070007,63.407204,-13.388766,0.017332,0.002376,0.060358,282.049316,14.368278,0.603585,-13.388766,0.060575,0.000000
79.310005,63.376305,-13.388766,0.017375,0.002376,0.060358,281.911896,14.361276,0.603585,-13.388766,0.060575,0.000000
79.550003,63.333473,-13.344285,0.017332,0.002376,0.060358,281.721344,14.351570,0.603585,-13.344285,0.060575,0.000000
79.790001,63.292152,-13.388766,0.017337,0.002376,0.060358,281.537567,14.342207,0.603585,-13.388766,0.060575,0.000000
80.030006,63.256767,-13.433248,0.017384,0.002376,0.060358,281.380157,14.334188,0.603585,-13.433248,0.060575,0.000000
80.270004,63.212090,-13.433248,0.017362,0.002376,0.060358,281.181427,14.324064,0.603585,-13.433248,0.060575,0.000000
80.510002,63.193474,-13.433248,0.017354,0.002376,0.060358,281.098602,14.319845,0.603585,-13.433248,0.060575,0.000000
80.750008,63.150642,-13.388766,0.017358,0.002376,0.060358,280.908081,14.310140,0.603585,-13.388766,0.060575,0.000000
80.990005,63.122345,-13.433248,0.017345,0.002376,0.060358,280.782227,14.303728,0.603585,-13.433248,0.060575,0.000000
81.230003,63.082870,-13.433248,0.017345,0.002376,0.060358,280.606628,14.294783,0.603585,-13.433248,0.060575,0.000000
81.470001,63.061272,-13.433248,0.017337,0.002376,0.060358,280.510559,14.289889,0.603585,-13.433248,0.060575,0.000000
81.710007,63.019196,-13.477728,0.017350,0.002376,0.060358,280.323395,14.280354,0.603585,-13.477728,0.060575,0.000000
81.950005,62.998344,-13.388766,0.017380,0.002376,0.060358,280.230621,14.275629,0.603585,-13.388766,0.060575,0.000000
82.190002,62.976746,-13.522209,0.017367,0.002376,0.060358,280.134552,14.270734,0.603585,-13.522209,0.060575,0.000000
82.430000,62.952171,-13.388766,0.017371,0.002376,0.060358,280.025238,14.265165,0.603585,-13.388766,0.060575,0.000000
82.670006,62.911957,-13.477728,0.017332,0.002376,0.060358,279.846375,14.256054,0.603585,-13.477728,0.060575,0.000000
82.910004,62.886635,-13.477728,0.017358,0.002376,0.060358,279.733734,14.250315,0.603585,-13.477728,0.060575,0.000000
83.150002,62.864662,-13.433248,0.017350,0.002376,0.060358,279.635986,14.245337,0.603585,-13.433248,0.060575,0.000000
83.390007,62.828545,-13.477728,0.017332,0.002376,0.060358,279.475311,14.237151,0.603585,-13.477728,0.060575,0.000000
83.630005,62.804337,-13.477728,0.017371,0.002376,0.060358,279.367645,14.231667,0.603585,-13.477728,0.060575,0.000000
83.870003,62.793541,-13.477728,0.017354,0.002376,0.060358,279.319611,14.229219,0.603585,-13.477728,0.060575,0.000000
84.110001,62.758911,-13.522209,0.017362,0.002376,0.060358,279.165588,14.221373,0.603585,-13.522209,0.060575,0.000000
84.350006,62.730232,-13.477728,0.017358,0.002376,0.060358,279.037994,14.214874,0.603585,-13.477728,0.060575,0.000000
84.590004,62.711990,-13.477728,0.017358,0.002376,0.060358,278.956879,14.210740,0.603585,-13.477728,0.060575,0.000000
84.830002,62.684433,-13.522209,0.017362,0.002376,0.060358,278.834290,14.204495,0.603585,-13.522209,0.060575,0.000000
85.070007,62.662460,-13.477728,0.017358,0.002376,0.060358,278.736542,14.199517,0.603585,-13.477728,0.060575,0.000000
85.310005,62.650177,-13.611171,0.017380,0.002376,0.060358,278.681915,14.196733,0.603585,-13.611171,0.060575,0.000000
85.550003,62.632301,-13.566690,0.017350,0.002376,0.060358,278.602386,14.192682,0.603585,-13.566690,0.060575,0.000000
85.790001,62.598785,-13.611171,0.017354,0.002376,0.060358,278.453308,14.185087,0.603585,-13.611171,0.060575,0.000000
86.030006,62.579056,-13.522209,0.017375,0.002376,0.060358,278.365540,14.180616,0.603585,-13.522209,0.060575,0.000000
86.270004,62.551125,-13.611171,0.017350,0.002376,0.060358,278.241302,14.174287,0.603585,-13.611171,0.060575,0.000000
86.510002,62.536232,-13.566690,0.017362,0.002376,0.060358,278.175049,14.170913,0.603585,-13.566690,0.060575,0.000000
86.750008,62.526917,-13.566690,0.017380,0.002376,0.060358,278.133606,14.168802,0.603585,-13.566690,0.060575,0.000000
86.990005,62.500854,-13.566690,0.017341,0.002376,0.060358,278.017700,14.162896,0.603585,-13.566690,0.060575,0.000000
87.230003,62.490425,-13.477728,0.017345,0.002376,0.060358,277.971283,14.160532,0.603585,-13.477728,0.060575,0.000000
87.470001,62.471062,-13.566690,0.017380,0.002376,0.060358,277.885162,14.156145,0.603585,-13.566690,0.060575,0.000000
87.710007,62.444626,-13.566690,0.017350,0.002376,0.060358,277.767578,14.150155,0.603585,-13.566690,0.060575,0.000000
87.950005,62.424149,-13.566690,0.017362,0.002376,0.060358,277.676483,14.145514,0.603585,-13.566690,0.060575,0.000000
88.190002,62.403290,-13.611171,0.017358,0.002376,0.060358,277.583710,14.140788,0.603585,-13.611171,0.060575,0.000000
88.430008,62.390633,-13.566690,0.017375,0.002376,0.060358,277.527405,14.137919,0.603585,-13.566690,0.060575,0.000000
88.670006,62.379089,-13.611171,0.017358,0.002376,0.060358,277.476044,14.135303,0.603585,-13.611171,0.060575,0.000000
88.910004,62.350418,-13.655652,0.017375,0.002376,0.060358,277.348511,14.128807,0.603585,-13.655652,0.060575,0.000000
89.150002,62.350044,-13.611171,0.017362,0.002376,0.060358,277.346863,14.128721,0.603585,-13.611171,0.060575,0.000000
89.390007,62.330681,-13.611171,0.017367,0.002376,0.060358,277.260712,14.124334,0.603585,-13.611171,0.060575,0.000000
89.630005,62.299400,-13.611171,0.017375,0.002376,0.060358,277.121582,14.117246,0.603585,-13.611171,0.060575,0.000000
89.870003,62.285622,-13.655652,0.017397,0.002376,0.060358,277.060272,14.114123,0.603585,-13.655652,0.060575,0.000000
90.110001,62.272964,-13.655652,0.017354,0.002376,0.060358,277.003967,14.111256,0.603585,-13.655652,0.060575,0.000000
90.350006,62.259186,-13.611171,0.017367,0.002376,0.060358,276.942688,14.108133,0.603585,-13.611171,0.060575,0.000000
90.590004,62.245407,-13.611171,0.017367,0.002376,0.060358,276.881409,14.105011,0.603585,-13.611171,0.060575,0.000000
90.830002,62.228653,-13.611171,0.017362,0.002376,0.060358,276.806885,14.101213,0.603585,-13.611171,0.060575,0.000000
91.070007,62.209290,-13.655652,0.017354,0.002376,0.060358,276.720734,14.096827,0.603585,-13.655652,0.060575,0.000000
91.310005,62.200348,-13.655652,0.017384,0.002376,0.060358,276.680969,14.094800,0.603585,-13.655652,0.060575,0.000000
91.550003,62.176888,-13.611171,0.017362,0.002376,0.060358,276.576599,14.089484,0.603585,-13.611171,0.060575,0.000000
91.790001,62.157898,-13.700133,0.017371,0.002376,0.060358,276.492126,14.085180,0.603585,-13.700133,0.060575,0.000000
92.030006,62.157524,-13.700133,0.017375,0.002376,0.060358,276.490479,14.085096,0.603585,-13.700133,0.060575,0.000000
92.270004,62.129227,-13.655652,0.017380,0.002376,0.060358,276.364594,14.078684,0.603585,-13.655652,0.060575,0.000000
92.510002,62.121780,-13.700133,0.017375,0.002376,0.060358,276.331482,14.076997,0.603585,-13.700133,0.060575,0.000000
92.750008,62.098694,-13.655652,0.017354,0.002376,0.060358,276.228790,14.071765,0.603585,-13.655652,0.060575,0.000000
92.990005,62.097572,-13.655652,0.017354,0.002376,0.060358,276.223785,14.071511,0.603585,-13.655652,0.060575,0.000000
93.230003,62.079330,-13.700133,0.017380,0.002376,0.060358,276.142639,14.067378,0.603585,-13.700133,0.060575,0.000000
93.470001,62.056984,-13.655652,0.017337,0.002376,0.060358,276.043243,14.062314,0.603585,-13.655652,0.060575,0.000000
93.710007,62.044327,-13.744614,0.017388,0.002376,0.060358,275.986938,14.059445,0.603585,-13.744614,0.060575,0.000000
93.950005,62.040230,-13.744614,0.017362,0.002376,0.060358,275.968719,14.058517,0.603585,-13.744614,0.060575,0.000000
94.190002,62.021240,-13.744614,0.017350,0.002376,0.060358,275.884247,14.054214,0.603585,-13.744614,0.060575,0.000000
94.430008,62.020493,-13.744614,0.017358,0.002376,0.060358,275.880920,14.054045,0.603585,-13.744614,0.060575,0.000000
94.670006,61.992935,-13.744614,0.017367,0.002376,0.060358,275.758362,14.047800,0.603585,-13.744614,0.060575,0.000000
94.910004,61.980652,-13.789095,0.017354,0.002376,0.060358,275.703705,14.045017,0.603585,-13.789095,0.060575,0.000000
95.150002,61.965752,-13.655652,0.017362,0.002376,0.060358,275.637421,14.041639,0.603585,-13.655652,0.060575,0.000000
95.390007,61.961662,-13.700133,0.017358,0.002376,0.060358,275.619232,14.040713,0.603585,-13.700133,0.060575,0.000000
95.630005,61.957932,-13.744614,0.017375,0.002376,0.060358,275.602631,14.039867,0.603585,-13.744614,0.060575,0.000000
95.870003,61.943787,-13.744614,0.017380,0.002376,0.060358,275.539734,14.036663,0.603585,-13.744614,0.060575,0.000000
96.110008,61.928520,-13.833576,0.017358,0.002376,0.060358,275.471802,14.033203,0.603585,-13.833576,0.060575,0.000000
96.350006,61.918465,-13.744614,0.017380,0.002376,0.060358,275.427094,14.030925,0.603585,-13.744614,0.060575,0.000000
96.590004,61.904686,-13.789095,0.017358,0.002376,0.060358,275.365784,14.027802,0.603585,-13.789095,0.060575,0.000000
96.830002,61.892395,-13.744614,0.017345,0.002376,0.060358,275.311127,14.025017,0.603585,-13.744614,0.060575,0.000000
97.070007,61.887184,-13.789095,0.017371,0.002376,0.060358,275.287933,14.023836,0.603585,-13.789095,0.060575,0.000000
97.310005,61.867821,-13.789095,0.017375,0.002376,0.060358,275.201813,14.019448,0.603585,-13.789095,0.060575,0.000000
97.550003,61.843987,-13.744614,0.017367,0.002376,0.060358,275.095795,14.014048,0.603585,-13.744614,0.060575,0.000000
97.790001,61.841751,-13.789095,0.017358,0.002376,0.060358,275.085846,14.013541,0.603585,-13.789095,0.060575,0.000000
98.030006,61.835800,-13.789095,0.017367,0.002376,0.060358,275.059387,14.012193,0.603585,-13.789095,0.060575,0.000000
98.270004,61.816063,-13.744614,0.017371,0.002376,0.060358,274.971588,14.007720,0.603585,-13.744614,0.060575,0.000000
98.510002,61.820526,-13.878057,0.017350,0.002376,0.060358,274.991425,14.008731,0.603585,-13.878057,0.060575,0.000000
98.750008,61.810844,-13.744614,0.017358,0.002376,0.060358,274.948364,14.006538,0.603585,-13.744614,0.060575,0.000000
98.990005,61.796326,-13.878057,0.017358,0.002376,0.060358,274.883789,14.003248,0.603585,-13.878057,0.060575,0.000000
99.230003,61.789253,-13.833576,0.017362,0.002376,0.060358,274.852325,14.001644,0.603585,-13.833576,0.060575,0.000000
99.470001,61.767654,-13.789095,0.017371,0.002376,0.060358,274.756256,13.996751,0.603585,-13.789095,0.060575,0.000000
99.710007,61.757973,-13.878057,0.017358,0.002376,0.060358,274.713196,13.994556,0.603585,-13.878057,0.060575,0.000000
99.950005,61.761322,-13.744614,0.017375,0.002376,0.060358,274.728088,13.995316,0.603585,-13.744614,0.060575,0.000000
100.190002,61.735260,-13.878057,0.017375,0.002376,0.060358,274.612152,13.989409,0.603585,-13.878057,0.060575,0.000000
100.430008,61.733765,-13.833576,0.017375,0.002376,0.060358,274.605499,13.989071,0.603585,-13.833576,0.060575,0.000000
100.670006,61.726318,-13.833576,0.017371,0.002376,0.060358,274.572388,13.987384,0.603585,-13.833576,0.060575,0.000000
100.910004,61.716263,-13.878057,0.017358,0.002376,0.060358,274.527649,13.985105,0.603585,-13.878057,0.060575,0.000000
101.150002,61.706955,-13.833576,0.017367,0.002376,0.060358,274.486237,13.982996,0.603585,-13.833576,0.060575,0.000000
101.300003,61.694298,-13.833576,0.017362,0.002376,0.060358,274.429932,13.980128,0.603585,-13.833576,0.060575,0.000000