File: Data/New pin I-18-5_08172023_171354.csv
Time (sec),S:Load (lbs),S:HL1 (DIM),S:LVDT (in),S:Position (in),Ch:Position (mm),Ch:Load (N),Ch:Stress (MPa),Ch:Strain (mm/mm),Ch:HL1 (DIM),Set Point (),Cycles ()
0.010000,0.118787,-115.383591,-0.005605,-0.013579,-0.344896,0.528390,0.026917,-3.448963,-115.383591,-0.344715,0.000000
0.240000,0.122138,-115.383591,-0.005592,-0.013579,-0.344896,0.543298,0.027677,-3.448963,-115.383591,-0.344715,0.000000
0.470000,0.131447,-115.383591,-0.005614,-0.013511,-0.343187,0.584707,0.029786,-3.431870,-115.383591,-0.342512,0.000000
0.700000,0.214114,-115.383591,-0.005558,-0.013382,-0.339909,0.952427,0.048519,-3.399093,-115.383591,-0.338678,0.000000
0.930000,0.197357,-115.339104,-0.005325,-0.013227,-0.335964,0.877889,0.044722,-3.359639,-115.339104,-0.334845,0.000000
1.160000,0.196240,-115.383591,-0.005191,-0.013073,-0.332061,0.872920,0.044469,-3.320610,-115.383591,-0.331012,0.000000
1.390000,0.175015,-115.383591,-0.005010,-0.012926,-0.328323,0.778506,0.039659,-3.283230,-115.383591,-0.327178,0.000000
1.620000,0.155279,-115.294624,-0.004820,-0.012784,-0.324708,0.690717,0.035187,-3.247077,-115.294624,-0.323345,0.000000
1.850000,0.180973,-115.383591,-0.004652,-0.012623,-0.320631,0.805008,0.041009,-3.206306,-115.383591,-0.319512,0.000000
2.080000,0.202198,-115.339104,-0.004514,-0.012482,-0.317041,0.899423,0.045819,-3.170410,-115.339104,-0.315680,0.000000
2.310000,0.157886,-115.383591,-0.004316,-0.012320,-0.312938,0.702312,0.035777,-3.129381,-115.383591,-0.311847,0.000000
2.540000,0.108360,-115.339104,-0.004113,-0.012171,-0.309149,0.482011,0.024555,-3.091487,-115.339104,-0.308013,0.000000
2.770000,0.107243,-115.339104,-0.003949,-0.012019,-0.305290,0.477042,0.024302,-3.052896,-115.339104,-0.304197,0.000000
3.000000,0.112084,-115.294624,-0.003824,-0.011869,-0.301482,0.498575,0.025399,-3.014820,-115.294624,-0.300365,0.000000
3.230000,0.084901,-115.294624,-0.003673,-0.011724,-0.297780,0.377658,0.019239,-2.977804,-115.294624,-0.296531,0.000000
3.460000,0.058090,-115.383591,-0.003557,-0.011565,-0.293756,0.258398,0.013163,-2.937563,-115.383591,-0.292698,0.000000
3.690000,0.020108,-115.339104,-0.003380,-0.011417,-0.289993,0.089445,0.004557,-2.899926,-115.339104,-0.288865,0.000000
3.920000,0.005213,-115.339104,-0.003238,-0.011269,-0.286236,0.023189,0.001181,-2.862365,-115.339104,-0.285031,0.000000
4.150000,0.074102,-115.294624,-0.003065,-0.011117,-0.282370,0.329623,0.016792,-2.823698,-115.294624,-0.281198,0.000000
4.380000,0.095327,-115.339104,-0.002910,-0.010967,-0.278562,0.424037,0.021601,-2.785622,-115.339104,-0.277365,0.000000
4.610000,0.075219,-115.294624,-0.002798,-0.010812,-0.274633,0.334592,0.017045,-2.746335,-115.294624,-0.273531,0.000000
4.840000,0.056973,-115.205666,-0.002656,-0.010658,-0.270723,0.253428,0.012910,-2.707229,-115.205666,-0.269699,0.000000
5.070000,0.056973,-115.205666,-0.002471,-0.010511,-0.266985,0.253428,0.012910,-2.669850,-115.205666,-0.265866,0.000000
5.300000,0.042823,-115.250145,-0.002354,-0.010356,-0.263038,0.190485,0.009704,-2.630381,-115.250145,-0.262033,0.000000
5.530000,0.067027,-115.250145,-0.002195,-0.010215,-0.259458,0.298151,0.015189,-2.594576,-115.250145,-0.258216,0.000000
5.760000,0.045057,-115.294624,-0.002044,-0.010062,-0.255571,0.200424,0.010210,-2.555712,-115.294624,-0.254384,0.000000
5.990000,0.028300,-115.250145,-0.002026,-0.009906,-0.251609,0.125886,0.006413,-2.516092,-115.250145,-0.250551,0.000000
6.220000,-0.023832,-115.250145,-0.001850,-0.009756,-0.247802,-0.106009,-0.005400,-2.478016,-115.250145,-0.246718,0.000000
6.450000,0.011544,-115.161179,-0.001677,-0.009604,-0.243933,0.051348,0.002616,-2.439335,-115.161179,-0.242884,0.000000
6.680000,0.033141,-115.205666,-0.001509,-0.009451,-0.240065,0.147419,0.007510,-2.400653,-115.205666,-0.239051,0.000000
6.910000,0.052132,-115.250145,-0.001367,-0.009312,-0.236536,0.231895,0.011813,-2.365363,-115.250145,-0.235218,0.000000
7.140000,0.043195,-115.250145,-0.001181,-0.009147,-0.232321,0.192142,0.009788,-2.323214,-115.250145,-0.231384,0.000000
7.370000,0.022342,-115.161179,-0.001035,-0.009001,-0.228618,0.099384,0.005063,-2.286183,-115.161179,-0.227552,0.000000
7.600000,0.032396,-115.250145,-0.000841,-0.008853,-0.224864,0.144106,0.007341,-2.248636,-115.250145,-0.223719,0.000000
7.830000,0.040961,-115.250145,-0.000703,-0.008700,-0.220970,0.182203,0.009282,-2.209697,-115.250145,-0.219886,0.000000
8.060000,0.057345,-115.250145,-0.000504,-0.008550,-0.217180,0.255085,0.012995,-2.171803,-115.250145,-0.216052,0.000000
8.290000,0.032396,-115.161179,-0.000366,-0.008398,-0.213312,0.144106,0.007341,-2.133121,-115.161179,-0.212219,0.000000
8.520000,0.062559,-115.161179,-0.000207,-0.008246,-0.209444,0.278274,0.014176,-2.094440,-115.161179,-0.208404,0.000000
8.750000,0.052877,-115.205666,-0.000026,-0.008100,-0.205741,0.235208,0.011982,-2.057408,-115.205666,-0.204571,0.000000
8.980000,0.036120,-115.205666,0.000147,-0.007941,-0.201700,0.160670,0.008185,-2.017001,-115.205666,-0.200737,0.000000
9.210000,0.035003,-115.161179,0.000177,-0.007796,-0.198023,0.155701,0.007932,-1.980227,-115.161179,-0.196904,0.000000
9.440001,0.049898,-115.161179,0.000319,-0.007647,-0.194233,0.221957,0.011307,-1.942332,-115.161179,-0.193071,0.000000
9.670000,0.032396,-115.116699,0.000526,-0.007488,-0.190191,0.144106,0.007341,-1.901910,-115.116699,-0.189237,0.000000
9.900001,0.007820,-115.116699,0.000716,-0.007342,-0.186489,0.034784,0.001772,-1.864893,-115.116699,-0.185404,0.000000
10.130000,0.000372,-115.161179,0.000823,-0.007195,-0.182759,0.001656,0.000084,-1.827590,-115.161179,-0.181572,0.000000
10.360001,0.039844,-115.161179,0.001018,-0.007040,-0.178823,0.177234,0.009029,-1.788227,-115.161179,-0.177739,0.000000
10.590000,0.073357,-115.116699,0.001194,-0.006895,-0.175136,0.326310,0.016623,-1.751362,-115.116699,-0.173905,0.000000
10.820001,0.058090,-115.072220,0.001319,-0.006737,-0.171130,0.258398,0.013163,-1.711302,-115.072220,-0.170072,0.000000
11.050000,0.042823,-115.116699,0.001479,-0.006587,-0.167314,0.190485,0.009704,-1.673136,-115.116699,-0.166239,0.000000
11.280001,0.033886,-115.161179,0.001608,-0.006438,-0.163533,0.150732,0.007679,-1.635332,-115.161179,-0.162423,0.000000
11.510000,0.045057,-115.161179,0.001716,-0.006284,-0.159623,0.200424,0.010210,-1.596226,-115.161179,-0.158590,0.000000
11.740001,0.045429,-115.027740,0.001897,-0.006139,-0.155936,0.202080,0.010294,-1.559362,-115.027740,-0.154757,0.000000
11.970000,0.038354,-115.072220,0.002044,-0.005993,-0.152233,0.170609,0.008691,-1.522330,-115.072220,-0.150923,0.000000
12.200001,0.014895,-115.072220,0.002233,-0.005832,-0.148132,0.066256,0.003375,-1.481317,-115.072220,-0.147090,0.000000
12.430000,-0.020481,-115.072220,0.002380,-0.005685,-0.144410,-0.091102,-0.004641,-1.444104,-115.072220,-0.143257,0.000000
12.660001,0.011544,-115.027740,0.002539,-0.005536,-0.140621,0.051348,0.002616,-1.406210,-115.027740,-0.139425,0.000000
12.890000,0.051760,-114.983261,0.002708,-0.005383,-0.136727,0.230239,0.011729,-1.367271,-114.983261,-0.135592,0.000000
13.120001,0.079315,-114.983261,0.002859,-0.005232,-0.132894,0.352812,0.017973,-1.328937,-114.983261,-0.131758,0.000000
13.350000,0.072985,-115.027740,0.003035,-0.005079,-0.129018,0.324653,0.016539,-1.290180,-115.027740,-0.127925,0.000000
13.580001,0.065165,-115.072220,0.003203,-0.004931,-0.125254,0.289869,0.014767,-1.252543,-115.072220,-0.124092,0.000000
13.810000,0.055856,-114.983261,0.003346,-0.004775,-0.121291,0.248459,0.012657,-1.212907,-114.983261,-0.120258,0.000000
14.040001,0.061814,-115.027740,0.003518,-0.004629,-0.117588,0.274962,0.014007,-1.175876,-115.027740,-0.116425,0.000000
14.270000,0.070751,-114.983261,0.003673,-0.004480,-0.113789,0.314715,0.016032,-1.137891,-114.983261,-0.112610,0.000000
14.500001,0.053622,-114.983261,0.003807,-0.004326,-0.109879,0.238521,0.012151,-1.098785,-114.983261,-0.108776,0.000000
14.730000,0.020108,-115.027740,0.004005,-0.004173,-0.105992,0.089445,0.004557,-1.059922,-115.027740,-0.104943,0.000000
14.960001,0.054739,-114.938774,0.004109,-0.004024,-0.102203,0.243490,0.012404,-1.022028,-114.938774,-0.101110,0.000000
15.190001,0.048408,-114.894295,0.004243,-0.003871,-0.098335,0.215331,0.010969,-0.983346,-114.894295,-0.097276,0.000000
15.420001,0.051387,-114.938774,0.004389,-0.003725,-0.094624,0.228582,0.011645,-0.946239,-114.938774,-0.093445,0.000000
15.650001,0.063303,-114.894295,0.004544,-0.003572,-0.090738,0.281587,0.014345,-0.907376,-114.894295,-0.089611,0.000000
15.880001,0.068144,-114.983261,0.004730,-0.003417,-0.086792,0.303120,0.015442,-0.867922,-114.983261,-0.085778,0.000000
16.110001,0.038727,-114.894295,0.004889,-0.003270,-0.083063,0.172265,0.008776,-0.830633,-114.894295,-0.081944,0.000000
16.340000,0.051015,-114.894295,0.005075,-0.003121,-0.079265,0.226926,0.011560,-0.792648,-114.894295,-0.078111,0.000000
16.570002,0.061814,-114.849815,0.005200,-0.002970,-0.075431,0.274962,0.014007,-0.754314,-114.849815,-0.074278,0.000000
16.800001,0.052132,-114.849815,0.005342,-0.002816,-0.071538,0.231895,0.011813,-0.715375,-114.849815,-0.070444,0.000000
17.030001,0.065538,-114.894295,0.005493,-0.002662,-0.067609,0.291525,0.014851,-0.676088,-114.894295,-0.066629,0.000000
17.260000,0.042078,-114.894295,0.005618,-0.002516,-0.063898,0.187173,0.009535,-0.638981,-114.894295,-0.062796,0.000000
17.490002,0.046547,-114.849815,0.005821,-0.002361,-0.059977,0.207049,0.010548,-0.599770,-114.849815,-0.058963,0.000000
17.720001,0.066655,-114.760857,0.005950,-0.002209,-0.056118,0.296495,0.015104,-0.561179,-114.760857,-0.055129,0.000000
17.950001,0.083784,-114.849815,0.006101,-0.002067,-0.052503,0.372689,0.018986,-0.525025,-114.849815,-0.051297,0.000000
18.180000,0.065538,-114.849815,0.006256,-0.001907,-0.048427,0.291525,0.014851,-0.484270,-114.849815,-0.047464,0.000000
18.410002,0.065538,-114.805336,0.006403,-0.001756,-0.044610,0.291525,0.014851,-0.446103,-114.805336,-0.043631,0.000000
18.640001,0.026066,-114.716370,0.006554,-0.001611,-0.040907,0.115948,0.005907,-0.409071,-114.716370,-0.039797,0.000000
18.870001,0.064793,-114.849815,0.006700,-0.001461,-0.037100,0.288213,0.014682,-0.370995,-114.849815,-0.035964,0.000000
19.100000,0.096072,-114.894295,0.006877,-0.001313,-0.033345,0.427350,0.021770,-0.333449,-114.894295,-0.032131,0.000000
19.330002,0.100913,-114.760857,0.007045,-0.001161,-0.029486,0.448883,0.022867,-0.294858,-114.760857,-0.028297,0.000000
19.560001,0.118414,-114.760857,0.007217,-0.001004,-0.025497,0.526734,0.026833,-0.254966,-114.760857,-0.024466,0.000000
19.790001,0.112829,-114.716370,0.007416,-0.000853,-0.021672,0.501888,0.025567,-0.216723,-114.716370,-0.020632,0.000000
20.020000,0.154162,-114.716370,0.007558,-0.000702,-0.017830,0.685748,0.034934,-0.178299,-114.716370,-0.016816,0.000000
20.250002,0.177622,-114.760857,0.007743,-0.000556,-0.014119,0.790101,0.040250,-0.141192,-114.760857,-0.012982,0.000000
20.480001,0.255448,-114.716370,0.007877,-0.000412,-0.010468,1.136287,0.057885,-0.104675,-114.716370,-0.009150,0.000000
20.710001,0.333646,-114.671890,0.008041,-0.000254,-0.006462,1.484130,0.075605,-0.064616,-114.671890,-0.005317,0.000000
20.940001,0.443123,-114.627411,0.008196,-0.000102,-0.002593,1.971111,0.100413,-0.025934,-114.627411,-0.001484,0.000000
21.170000,0.675856,-114.716370,0.008334,0.000048,0.001214,3.006358,0.153151,0.012142,-114.716370,0.002350,0.000000
21.400002,0.657610,-114.627411,0.008347,-0.000001,-0.000026,2.925194,0.149016,-0.000257,-114.627411,0.000216,0.000000
21.630001,0.649418,-114.716370,0.008360,-0.000001,-0.000026,2.888753,0.147160,-0.000257,-114.716370,0.000216,0.000000
21.860001,0.661706,-114.582932,0.008343,-0.000001,-0.000026,2.943415,0.149945,-0.000257,-114.582932,0.000495,0.000000
22.090000,0.659099,-114.582932,0.008338,-0.000001,-0.000026,2.931820,0.149354,-0.000257,-114.582932,0.000877,0.000000
22.320002,0.650907,-114.627411,0.008338,0.000012,0.000295,2.895379,0.147498,0.002952,-114.627411,0.001258,0.000000
22.550001,0.768949,-114.627411,0.008356,0.000025,0.000633,3.420456,0.174246,0.006328,-114.627411,0.001640,0.000000
22.780001,0.800973,-114.627411,0.008343,0.000039,0.000981,3.562907,0.181503,0.009810,-114.627411,0.002030,0.000000
23.010000,0.848264,-114.493965,0.008360,0.000053,0.001344,3.773269,0.192219,0.013444,-114.493965,0.002412,0.000000
23.240002,0.916036,-114.538452,0.008399,0.000076,0.001942,4.074733,0.207577,0.019424,-114.538452,0.002793,0.000000
23.470001,0.926835,-114.538452,0.008412,0.000087,0.002221,4.122768,0.210024,0.022210,-114.538452,0.003175,0.000000
23.700001,0.981201,-114.538452,0.008416,0.000102,0.002602,4.364602,0.222343,0.026025,-114.538452,0.003556,0.000000
23.930000,0.991628,-114.538452,0.008412,0.000117,0.002984,4.410981,0.224706,0.029840,-114.538452,0.003947,0.000000
24.160002,1.044877,-114.493965,0.008420,0.000133,0.003373,4.647845,0.236773,0.033731,-114.493965,0.004328,0.000000
24.390001,1.102967,-114.493965,0.008489,0.000147,0.003738,4.906243,0.249936,0.037380,-114.493965,0.004710,0.000000
24.620001,1.170367,-114.493965,0.008468,0.000162,0.004119,5.206051,0.265209,0.041195,-114.493965,0.005091,0.000000
24.850000,1.178186,-114.493965,0.008489,0.000167,0.004241,5.240835,0.266981,0.042406,-114.493965,0.005473,0.000000
25.080002,1.267556,-114.493965,0.008494,0.000186,0.004727,5.638370,0.287232,0.047266,-114.493965,0.005862,0.000000
25.310001,1.353574,-114.493965,0.008507,0.000209,0.005317,6.020998,0.306724,0.053170,-114.493965,0.006245,0.000000
25.540001,1.431027,-114.449486,0.008541,0.000225,0.005715,6.365528,0.324275,0.057152,-114.449486,0.006627,0.000000
25.770000,1.411664,-114.493965,0.008571,0.000235,0.005976,6.279395,0.319888,0.059756,-114.493965,0.007008,0.000000
26.000002,1.508853,-114.493965,0.008558,0.000249,0.006322,6.711714,0.341911,0.063223,-114.493965,0.007390,0.000000
26.230001,1.594499,-114.449486,0.008576,0.000268,0.006808,7.092685,0.361319,0.068083,-114.449486,0.007779,0.000000
26.460001,1.680517,-114.360527,0.008558,0.000283,0.007199,7.475313,0.380811,0.071989,-114.360527,0.008160,0.000000
26.690001,1.738979,-114.316048,0.008614,0.000296,0.007511,7.735366,0.394058,0.075107,-114.316048,0.008543,0.000000
26.920002,1.838030,-114.405006,0.008619,0.000310,0.007874,8.175968,0.416504,0.078741,-114.405006,0.008925,0.000000
27.150002,1.965009,-114.405006,0.008649,0.000331,0.008395,8.740799,0.445277,0.083949,-114.405006,0.009306,0.000000
27.380001,2.051028,-114.360527,0.008662,0.000347,0.008802,9.123426,0.464769,0.088022,-114.360527,0.009695,0.000000
27.610001,2.083052,-114.405006,0.008658,0.000356,0.009046,9.265877,0.472026,0.090459,-114.405006,0.010077,0.000000
27.840002,2.190295,-114.316048,0.008692,0.000376,0.009549,9.742918,0.496328,0.095485,-114.316048,0.010458,0.000000
28.070002,2.265514,-114.271561,0.008722,0.000389,0.009869,10.077509,0.513373,0.098695,-114.271561,0.010840,0.000000
28.300001,2.431592,-114.316048,0.008722,0.000405,0.010295,10.816261,0.551007,0.102949,-114.316048,0.011223,0.000000
28.530001,2.504205,-114.316048,0.008735,0.000417,0.010589,11.139259,0.567461,0.105886,-114.316048,0.011612,0.000000
28.760002,2.588733,-114.271561,0.008770,0.000426,0.010814,11.515261,0.586615,0.108142,-114.271561,0.011994,0.000000
28.990002,2.707892,-114.227081,0.008752,0.000438,0.011128,12.045307,0.613617,0.111276,-114.227081,0.012375,0.000000
29.220001,2.985310,-114.271561,0.008778,0.000465,0.011803,13.279323,0.676481,0.118028,-114.271561,0.012757,0.000000
29.450001,3.142079,-114.316048,0.008800,0.000480,0.012203,13.976665,0.712005,0.122025,-114.316048,0.013138,0.000000
29.680002,3.259376,-114.182602,0.008826,0.000495,0.012584,14.498428,0.738585,0.125840,-114.182602,0.013529,0.000000
29.910002,3.350235,-114.227081,0.008830,0.000507,0.012879,14.902590,0.759174,0.128792,-114.227081,0.013910,0.000000
30.140001,3.610896,-114.271561,0.008847,0.000527,0.013391,16.062065,0.818241,0.133910,-114.271561,0.014292,0.000000
30.370001,3.758728,-114.182602,0.008847,0.000539,0.013694,16.719656,0.851740,0.136937,-114.182602,0.014673,0.000000
30.600002,3.871929,-114.227081,0.008864,0.000549,0.013945,17.223200,0.877392,0.139451,-114.227081,0.015064,0.000000
30.830002,4.067797,-114.182602,0.008890,0.000562,0.014284,18.094463,0.921776,0.142842,-114.182602,0.015445,0.000000
31.060001,4.448734,-114.138123,0.008921,0.000587,0.014899,19.788956,1.008098,0.148989,-114.138123,0.015827,0.000000
31.290001,4.650932,-114.138123,0.008938,0.000603,0.015306,20.688377,1.053916,0.153061,-114.138123,0.016208,0.000000
31.520002,4.748866,-114.182602,0.008964,0.000612,0.015541,21.124012,1.076108,0.155408,-114.182602,0.016590,0.000000
31.750002,5.019581,-114.182602,0.008946,0.000628,0.015948,22.328211,1.137453,0.159480,-114.182602,0.016981,0.000000
31.980001,5.286944,-114.138123,0.008985,0.000644,0.016348,23.517504,1.198039,0.163477,-114.138123,0.017362,0.000000
32.210003,5.521167,-114.093643,0.008994,0.000659,0.016738,24.559376,1.251114,0.167383,-114.093643,0.017744,0.000000
32.440002,5.770284,-114.182602,0.009007,0.000674,0.017111,25.667503,1.307565,0.171108,-114.182602,0.018125,0.000000
32.670002,5.863005,-114.093643,0.009011,0.000681,0.017292,26.079947,1.328576,0.172924,-114.093643,0.018507,0.000000
32.900002,6.331821,-114.093643,0.009058,0.000705,0.017918,28.165348,1.434811,0.179177,-114.093643,0.018897,0.000000
33.130001,6.666956,-114.093643,0.009046,0.000724,0.018386,29.656103,1.510754,0.183855,-114.093643,0.019279,0.000000
33.360001,6.725791,-114.004677,0.009046,0.000731,0.018560,29.917814,1.524086,0.185596,-114.004677,0.019660,0.000000
33.590000,7.081779,-114.049156,0.009084,0.000749,0.019027,31.501328,1.604754,0.190274,-114.049156,0.020042,0.000000
33.820004,7.484314,-114.049156,0.009097,0.000769,0.019530,33.291893,1.695970,0.195301,-114.049156,0.020423,0.000000
34.050003,7.729708,-114.004677,0.009110,0.000783,0.019895,34.383457,1.751577,0.198949,-114.004677,0.020814,0.000000
34.280003,7.914404,-114.049156,0.009115,0.000795,0.020189,35.205029,1.793430,0.201886,-114.049156,0.021195,0.000000
34.510002,8.128518,-113.960197,0.009123,0.000806,0.020484,36.157455,1.841949,0.204839,-113.960197,0.021577,0.000000
34.740002,8.542969,-114.049156,0.009158,0.000825,0.020953,38.001022,1.935864,0.209532,-114.049156,0.021958,0.000000
34.970001,8.978645,-114.004677,0.009201,0.000846,0.021482,39.939011,2.034590,0.214815,-114.004677,0.022340,0.000000
35.200001,9.139882,-113.960197,0.009184,0.000857,0.021759,40.656227,2.071127,0.217586,-113.960197,0.022731,0.000000
35.430000,9.377456,-113.960197,0.009188,0.000868,0.022045,41.713005,2.124962,0.220447,-113.960197,0.023112,0.000000
35.660000,9.672748,-113.960197,0.009214,0.000882,0.022410,43.026531,2.191876,0.224096,-113.960197,0.023494,0.000000
35.890003,10.062621,-113.960197,0.009222,0.000900,0.022861,44.760773,2.280223,0.228608,-113.960197,0.023875,0.000000
36.120003,10.273011,-113.960197,0.009248,0.000912,0.023156,45.696636,2.327898,0.231560,-113.960197,0.024257,0.000000
36.350002,10.513937,-113.915718,0.009265,0.000923,0.023433,46.768326,2.382492,0.234330,-113.915718,0.024647,0.000000
36.580002,10.740711,-113.871231,0.009261,0.000938,0.023815,47.777069,2.433880,0.238146,-113.871231,0.025029,0.000000
36.810001,11.075474,-113.871231,0.009274,0.000951,0.024145,49.266167,2.509738,0.241446,-113.871231,0.025410,0.000000
37.040001,11.805696,-113.915718,0.009287,0.000980,0.024880,52.514362,2.675209,0.248804,-113.915718,0.025792,0.000000
37.270000,11.993000,-113.871231,0.009291,0.000992,0.025201,53.347530,2.717653,0.252013,-113.871231,0.026173,0.000000
37.500000,12.171367,-113.915718,0.009343,0.001005,0.025531,54.140942,2.758071,0.255314,-113.915718,0.026564,0.000000
37.730003,12.415271,-113.826752,0.009365,0.001016,0.025808,55.225883,2.813341,0.258084,-113.826752,0.026945,0.000000
37.960003,12.821901,-113.871231,0.009343,0.001033,0.026251,57.034664,2.905484,0.262505,-113.871231,0.027327,0.000000
38.190002,13.143258,-113.782272,0.009369,0.001051,0.026694,58.464130,2.978305,0.266941,-113.782272,0.027708,0.000000
38.420002,13.393493,-113.826752,0.009378,0.001061,0.026945,59.577232,3.035009,0.269454,-113.826752,0.028090,0.000000
38.650002,13.645589,-113.782272,0.009356,0.001077,0.027344,60.698612,3.092134,0.273436,-113.782272,0.028481,0.000000
38.880001,14.131163,-113.782272,0.009429,0.001094,0.027786,62.858551,3.202167,0.277857,-113.782272,0.028862,0.000000
39.110001,14.514707,-113.737793,0.009455,0.001112,0.028237,64.564636,3.289080,0.282368,-113.737793,0.029244,0.000000
39.340000,14.760472,-113.782272,0.009421,0.001126,0.028602,65.657860,3.344771,0.286017,-113.782272,0.029625,0.000000
39.570004,15.040869,-113.737793,0.009459,0.001142,0.029000,66.905128,3.408309,0.289999,-113.737793,0.030016,0.000000
39.800003,15.143643,-113.737793,0.009490,0.001151,0.029235,67.362289,3.431599,0.292345,-113.737793,0.030397,0.000000
40.030003,15.667571,-113.782272,0.009472,0.001168,0.029668,69.692841,3.550323,0.296675,-113.782272,0.030779,0.000000
40.260002,16.013132,-113.737793,0.009472,0.001185,0.030111,71.229973,3.628628,0.301111,-113.737793,0.031160,0.000000
40.490002,16.220545,-113.693314,0.009520,0.001197,0.030414,72.152588,3.675628,0.304139,-113.693314,0.031542,0.000000
40.720001,16.625313,-113.693314,0.009516,0.001215,0.030856,73.953087,3.767350,0.308560,-113.693314,0.031931,0.000000
40.950001,16.947414,-113.693314,0.009550,0.001232,0.031281,75.385864,3.840339,0.312814,-113.693314,0.032314,0.000000
41.180000,17.175306,-113.648827,0.009576,0.001248,0.031689,76.399582,3.891980,0.316887,-113.648827,0.032695,0.000000
41.410004,17.294838,-113.604347,0.009572,0.001257,0.031931,76.931282,3.919066,0.319309,-113.604347,0.033077,0.000000
41.640003,17.599066,-113.693314,0.009576,0.001274,0.032356,78.284554,3.988005,0.323563,-113.693314,0.033458,0.000000
41.870003,17.943884,-113.693314,0.009606,0.001288,0.032712,79.818382,4.066142,0.327121,-113.693314,0.033848,0.000000
42.100002,18.427595,-113.559868,0.009615,0.001307,0.033189,81.970039,4.175753,0.331890,-113.559868,0.034229,0.000000
42.330002,18.729961,-113.648827,0.009615,0.001321,0.033561,83.315033,4.244270,0.335614,-113.648827,0.034611,0.000000
42.560001,18.947054,-113.648827,0.009628,0.001337,0.033961,84.280708,4.293464,0.339611,-113.648827,0.034994,0.000000
42.790001,19.382359,-113.604347,0.009675,0.001355,0.034429,86.217033,4.392105,0.344289,-113.604347,0.035375,0.000000
43.020000,19.536892,-113.604347,0.009679,0.001368,0.034750,86.904434,4.427123,0.347499,-113.604347,0.035764,0.000000
43.250004,19.683979,-113.559868,0.009658,0.001380,0.035054,87.558708,4.460454,0.350542,-113.559868,0.036146,0.000000
43.480003,20.064173,-113.604347,0.009697,0.001395,0.035436,89.249901,4.546607,0.354357,-113.604347,0.036527,0.000000
43.710003,20.318502,-113.515388,0.009701,0.001410,0.035817,90.381210,4.604239,0.358172,-113.515388,0.036909,0.000000
43.940002,20.734442,-113.559868,0.009727,0.001427,0.036234,92.231400,4.698492,0.362336,-113.559868,0.037290,0.000000
44.170002,20.889349,-113.604347,0.009731,0.001438,0.036520,92.920464,4.733594,0.365197,-113.604347,0.037681,0.000000
44.400002,21.218155,-113.515388,0.009740,0.001452,0.036875,94.383064,4.808103,0.368755,-113.515388,0.038062,0.000000
44.630001,21.991199,-113.470909,0.009757,0.001475,0.037473,97.821739,4.983277,0.374735,-113.470909,0.038444,0.000000
44.860001,22.041098,-113.515388,0.009804,0.001489,0.037820,98.043701,4.994584,0.378202,-113.515388,0.038825,0.000000
45.090004,22.226540,-113.515388,0.009800,0.001502,0.038158,98.868584,5.036606,0.381578,-113.515388,0.039207,0.000000
45.320004,22.445866,-113.559868,0.009809,0.001516,0.038497,99.844200,5.086306,0.384969,-113.559868,0.039598,0.000000
45.550003,22.836485,-113.426422,0.009813,0.001532,0.038921,101.581757,5.174821,0.389208,-113.426422,0.039979,0.000000
45.780003,23.132149,-113.426422,0.009830,0.001549,0.039346,102.896935,5.241820,0.393463,-113.426422,0.040361,0.000000
46.010002,23.354082,-113.426422,0.009878,0.001561,0.039658,103.884148,5.292111,0.396581,-113.426422,0.040742,0.000000
46.240002,23.187260,-113.381943,0.009848,0.001568,0.039832,103.142082,5.254308,0.398322,-113.381943,0.041124,0.000000
46.470001,23.853062,-113.470909,0.009882,0.001588,0.040335,106.103714,5.405181,0.403349,-113.470909,0.041514,0.000000
46.700001,24.590359,-113.426422,0.009891,0.001611,0.040916,109.383377,5.572255,0.409162,-113.426422,0.041896,0.000000
46.930004,24.845806,-113.337463,0.009921,0.001625,0.041272,110.519669,5.630140,0.412720,-113.337463,0.042277,0.000000
47.160004,24.872990,-113.381943,0.009929,0.001637,0.041584,110.640587,5.636300,0.415839,-113.381943,0.042659,0.000000
47.390003,25.174612,-113.381943,0.009938,0.001648,0.041870,111.982269,5.704649,0.418700,-113.381943,0.043049,0.000000
47.620003,25.725723,-113.381943,0.009947,0.001668,0.042356,114.433731,5.829532,0.423560,-113.381943,0.043431,0.000000
47.850002,26.088413,-113.292984,0.009951,0.001683,0.042754,116.047058,5.911719,0.427542,-113.292984,0.043812,0.000000
48.080002,26.289867,-113.337463,0.009985,0.001695,0.043040,116.943169,5.957369,0.430403,-113.337463,0.044194,0.000000
48.310001,26.665218,-113.381943,0.009985,0.001710,0.043431,118.612816,6.042425,0.434309,-113.381943,0.044575,0.000000
48.540001,27.310913,-113.381943,0.010011,0.001730,0.043943,121.485008,6.188742,0.439426,-113.381943,0.044966,0.000000
48.770000,27.695574,-113.337463,0.010037,0.001746,0.044350,123.196068,6.275907,0.443499,-113.337463,0.045348,0.000000
49.000004,27.734301,-113.292984,0.010059,0.001760,0.044697,123.368332,6.284682,0.446966,-113.292984,0.045729,0.000000
49.230003,28.445532,-113.292984,0.010059,0.001778,0.045157,126.532043,6.445849,0.451568,-113.292984,0.046111,0.000000
49.460003,28.581820,-113.292984,0.010076,0.001791,0.045487,127.138283,6.476733,0.454869,-113.292984,0.046492,0.000000
49.690002,29.086758,-113.292984,0.010076,0.001807,0.045894,129.384354,6.591154,0.458941,-113.292984,0.046883,0.000000
49.920002,29.194744,-113.248505,0.010080,0.001818,0.046171,129.864700,6.615623,0.461712,-113.248505,0.047264,0.000000
50.150002,29.205544,-113.204018,0.010089,0.001826,0.046371,129.912750,6.618071,0.463710,-113.204018,0.047646,0.000000
50.380001,29.688139,-113.292984,0.010089,0.001840,0.046736,132.059433,6.727428,0.467359,-113.292984,0.048027,0.000000
50.610001,30.807863,-113.248505,0.010136,0.001865,0.047369,137.040222,6.981162,0.473687,-113.248505,0.048409,0.000000
50.840004,31.179117,-113.248505,0.010154,0.001879,0.047732,138.691635,7.065289,0.477321,-113.248505,0.048799,0.000000
51.070004,31.545532,-113.204018,0.010162,0.001894,0.048114,140.321533,7.148320,0.481136,-113.204018,0.049181,0.000000
51.300003,31.886997,-113.159538,0.010184,0.001909,0.048495,141.840454,7.225697,0.484951,-113.159538,0.049562,0.000000
51.530003,32.510723,-113.159538,0.010171,0.001927,0.048955,144.614914,7.367035,0.489553,-113.159538,0.049944,0.000000
51.760002,32.708824,-113.159538,0.010205,0.001939,0.049241,145.496109,7.411925,0.492415,-113.159538,0.050325,0.000000
51.990002,32.949749,-113.159538,0.010231,0.001950,0.049537,146.567810,7.466520,0.495367,-113.159538,0.050716,0.000000
52.220001,33.307602,-113.204018,0.010214,0.001965,0.049900,148.159607,7.547611,0.499001,-113.204018,0.051098,0.000000
52.450001,34.407963,-113.115059,0.010248,0.001988,0.050490,153.054260,7.796956,0.504905,-113.115059,0.051479,0.000000
52.680004,34.797462,-113.115059,0.010261,0.002003,0.050889,154.786850,7.885218,0.508887,-113.115059,0.051861,0.000000
52.910004,34.904335,-113.115059,0.010270,0.002014,0.051167,155.262238,7.909435,0.511672,-113.115059,0.052242,0.000000
53.140003,35.590618,-113.115059,0.010266,0.002032,0.051600,158.314972,8.064950,0.516002,-113.115059,0.052633,0.000000
53.370003,36.152897,-113.070580,0.010279,0.002048,0.052017,160.816116,8.192364,0.520166,-113.070580,0.053014,0.000000
53.600002,36.622833,-112.981613,0.010274,0.002063,0.052398,162.906494,8.298853,0.523981,-112.981613,0.053396,0.000000
53.830002,36.942329,-113.026100,0.010326,0.002075,0.052693,164.327682,8.371251,0.526933,-113.026100,0.053777,0.000000
54.060001,36.916264,-113.070580,0.010322,0.002082,0.052875,164.211746,8.365345,0.528750,-113.070580,0.054159,0.000000
54.290001,38.337234,-113.026100,0.010356,0.002108,0.053552,170.532532,8.687342,0.535517,-113.026100,0.054549,0.000000
54.520004,38.957237,-112.981613,0.010365,0.002125,0.053977,173.290451,8.827836,0.539771,-112.981613,0.054931,0.000000
54.750004,39.106556,-112.937134,0.010374,0.002135,0.054228,173.954651,8.861672,0.542285,-112.937134,0.055312,0.000000
54.980003,39.680382,-112.981613,0.010374,0.002151,0.054627,176.507156,8.991703,0.546266,-112.981613,0.055694,0.000000
55.210003,40.614666,-113.026100,0.010395,0.002170,0.055129,180.663055,9.203415,0.551293,-113.026100,0.056075,0.000000
55.440002,41.031723,-112.981613,0.010408,0.002185,0.055494,182.518219,9.297921,0.554941,-112.981613,0.056466,0.000000
55.670002,41.267433,-112.981613,0.010404,0.002196,0.055780,183.566711,9.351334,0.557803,-112.981613,0.056848,0.000000
55.900002,41.677044,-112.981613,0.010421,0.002207,0.056057,185.388748,9.444154,0.560573,-112.981613,0.057229,0.000000
56.130001,42.716709,-112.892654,0.010477,0.002230,0.056639,190.013412,9.679745,0.566387,-112.892654,0.057611,0.000000
56.360004,43.484913,-112.937134,0.010442,0.002248,0.057099,193.430557,9.853823,0.570989,-112.937134,0.058000,0.000000
56.590004,43.787651,-112.892654,0.010494,0.002259,0.057376,194.777206,9.922423,0.573760,-112.892654,0.058381,0.000000
56.820004,44.028576,-112.892654,0.010455,0.002273,0.057723,195.848892,9.977018,0.577227,-112.892654,0.058764,0.000000
57.050003,44.711506,-112.892654,0.010503,0.002286,0.058062,198.886719,10.131773,0.580618,-112.892654,0.059146,0.000000
57.280003,45.385502,-112.803696,0.010499,0.002302,0.058469,201.884796,10.284501,0.584691,-112.803696,0.059527,0.000000
57.510002,45.890438,-112.892654,0.010507,0.002314,0.058772,204.130859,10.398922,0.587718,-112.892654,0.059916,0.000000
57.740002,46.112373,-112.892654,0.010520,0.002323,0.059016,205.118088,10.449213,0.590156,-112.892654,0.060298,0.000000
57.970001,46.833286,-112.848175,0.010537,0.002339,0.059405,208.324860,10.612575,0.594047,-112.848175,0.060679,0.000000
58.200005,47.404133,-112.803696,0.010546,0.002356,0.059848,210.864120,10.741930,0.598483,-112.803696,0.061061,0.000000
58.430004,48.862343,-112.803696,0.010550,0.002379,0.060421,217.350555,11.072365,0.604205,-112.803696,0.061444,0.000000
58.660004,49.289825,-112.848175,0.010559,0.002392,0.060758,219.252090,11.169234,0.607582,-112.848175,0.061833,0.000000
58.890003,49.815990,-112.803696,0.010580,0.002406,0.061105,221.592590,11.288465,0.611049,-112.803696,0.062215,0.000000
59.120003,50.108303,-112.803696,0.010598,0.002419,0.061435,222.892868,11.354704,0.614349,-112.803696,0.062596,0.000000
59.350002,51.062691,-112.759209,0.010589,0.002435,0.061859,227.138199,11.570971,0.618588,-112.759209,0.062978,0.000000
59.580002,51.904625,-112.759209,0.010628,0.002450,0.062242,230.883301,11.761756,0.622418,-112.759209,0.063359,0.000000
59.810001,52.288170,-112.803696,0.010615,0.002464,0.062589,232.589401,11.848668,0.625885,-112.803696,0.063750,0.000000
60.040005,53.258202,-112.803696,0.010637,0.002483,0.063065,236.904312,12.068481,0.630654,-112.803696,0.064131,0.000000
60.270004,53.751965,-112.714729,0.010658,0.002494,0.063359,239.100677,12.180369,0.633591,-112.714729,0.064513,0.000000
60.500004,54.621826,-112.714729,0.010667,0.002512,0.063803,242.970016,12.377483,0.638027,-112.714729,0.064894,0.000000
60.730003,55.156181,-112.714729,0.010697,0.002525,0.064124,245.346954,12.498569,0.641237,-112.714729,0.065276,0.000000
60.960003,55.966839,-112.670250,0.010693,0.002542,0.064557,248.952927,12.682267,0.645567,-112.670250,0.065666,0.000000
61.190002,56.164566,-112.625771,0.010688,0.002549,0.064757,249.832474,12.727073,0.647565,-112.625771,0.066048,0.000000
61.420002,57.213539,-112.670250,0.010714,0.002568,0.065224,254.498535,12.964774,0.652243,-112.670250,0.066429,0.000000
61.650002,58.197350,-112.670250,0.010718,0.002587,0.065701,258.874725,13.187708,0.657012,-112.670250,0.066811,0.000000
61.880001,58.757023,-112.670250,0.010710,0.002599,0.066022,261.364288,13.314531,0.660222,-112.670250,0.067192,0.000000
62.110004,59.786633,-112.714729,0.010727,0.002618,0.066499,265.944214,13.547845,0.664991,-112.714729,0.067583,0.000000
62.340004,60.525795,-112.670250,0.010783,0.002634,0.066899,269.232178,13.715342,0.668988,-112.670250,0.067965,0.000000
62.570004,61.260483,-112.625771,0.010766,0.002647,0.067236,272.500244,13.881824,0.672364,-112.625771,0.068346,0.000000
62.800003,61.539391,-112.581284,0.010770,0.002659,0.067548,273.740875,13.945025,0.675483,-112.581284,0.068728,0.000000
63.030003,62.666191,-112.625771,0.010800,0.002676,0.067974,278.753143,14.200362,0.679737,-112.625771,0.069109,0.000000
63.260002,63.537914,-112.625771,0.010796,0.002693,0.068407,282.630768,14.397898,0.684067,-112.625771,0.069500,0.000000
63.490002,64.232018,-112.581284,0.010813,0.002707,0.068753,285.718292,14.555183,0.687534,-112.581284,0.069881,0.000000
63.720001,65.008408,-112.536804,0.010818,0.002723,0.069153,289.171844,14.731116,0.691531,-112.536804,0.070263,0.000000
63.950005,65.825394,-112.536804,0.010818,0.002739,0.069560,292.805969,14.916247,0.695603,-112.536804,0.070644,0.000000
64.180000,66.820000,-112.536804,0.010839,0.002756,0.070002,297.230194,15.141628,0.700024,-112.536804,0.071026,0.000000
64.410004,67.399040,-112.536804,0.010848,0.002767,0.070289,299.805908,15.272841,0.702885,-112.536804,0.071416,0.000000
64.639999,67.092575,-112.536804,0.010852,0.002762,0.070158,298.442688,15.203395,0.701583,-112.536804,0.070384,0.000000
64.870003,66.750740,-112.403366,0.010869,0.002761,0.070133,296.922119,15.125935,0.701326,-112.403366,0.070158,0.000000
65.100006,66.423798,-112.492325,0.010878,0.002760,0.070098,295.467804,15.051847,0.700978,-112.492325,0.070158,0.000000
65.330002,66.126274,-112.492325,0.010856,0.002759,0.070081,294.144348,14.984428,0.700811,-112.492325,0.070158,0.000000
65.560005,65.900612,-112.447845,0.010874,0.002759,0.070072,293.140564,14.933292,0.700720,-112.447845,0.070158,0.000000
65.790001,65.696556,-112.358879,0.010878,0.002758,0.070063,292.232880,14.887053,0.700629,-112.358879,0.070158,0.000000
66.020004,65.509621,-112.403366,0.010891,0.002758,0.070055,291.401337,14.844692,0.700554,-112.403366,0.070158,0.000000
66.250000,65.358070,-112.358879,0.010874,0.002758,0.070055,290.727203,14.810350,0.700554,-112.358879,0.070158,0.000000
66.480003,65.189758,-112.492325,0.010865,0.002758,0.070046,289.978516,14.772210,0.700463,-112.492325,0.070158,0.000000
66.710007,65.044159,-112.403366,0.010865,0.002758,0.070046,289.330872,14.739217,0.700463,-112.403366,0.070158,0.000000
66.940002,64.924629,-112.403366,0.010852,0.002758,0.070046,288.799164,14.712132,0.700463,-112.403366,0.070158,0.000000
67.170006,64.796906,-112.358879,0.010878,0.002757,0.070037,288.231018,14.683188,0.700372,-112.358879,0.070158,0.000000
67.400002,64.707161,-112.358879,0.010887,0.002757,0.070037,287.831818,14.662852,0.700372,-112.358879,0.070158,0.000000
67.630005,64.601410,-112.447845,0.010856,0.002757,0.070037,287.361420,14.638888,0.700372,-112.447845,0.070158,0.000000
67.860001,64.495285,-112.358879,0.010869,0.002757,0.070037,286.889343,14.614841,0.700372,-112.358879,0.070158,0.000000
68.090004,64.409637,-112.269920,0.010852,0.002757,0.070037,286.508362,14.595432,0.700372,-112.269920,0.070158,0.000000
68.320000,64.335159,-112.314400,0.010861,0.002757,0.070037,286.177094,14.578555,0.700372,-112.314400,0.070158,0.000000
68.550003,64.250633,-112.358879,0.010869,0.002757,0.070037,285.801086,14.559402,0.700372,-112.358879,0.070158,0.000000
68.780006,64.162750,-112.358879,0.010895,0.002757,0.070028,285.410156,14.539487,0.700281,-112.358879,0.070158,0.000000
69.010002,64.095726,-112.314400,0.010882,0.002757,0.070028,285.112030,14.524299,0.700281,-112.314400,0.070158,0.000000
69.240005,64.023857,-112.225441,0.010874,0.002757,0.070028,284.792328,14.508013,0.700281,-112.225441,0.070158,0.000000
69.470001,63.962048,-112.180962,0.010869,0.002757,0.070028,284.517395,14.494007,0.700281,-112.180962,0.070158,0.000000
69.700005,63.898373,-112.269920,0.010856,0.002757,0.070028,284.234161,14.479579,0.700281,-112.269920,0.070158,0.000000
69.930000,63.833576,-112.314400,0.010878,0.002757,0.070028,283.945923,14.464895,0.700281,-112.314400,0.070158,0.000000
70.160004,63.775116,-112.269920,0.010882,0.002757,0.070028,283.685883,14.451648,0.700281,-112.269920,0.070158,0.000000
70.390007,63.723354,-112.225441,0.010869,0.002757,0.070028,283.455627,14.439919,0.700281,-112.225441,0.070158,0.000000
70.620003,63.657818,-112.225441,0.010861,0.002757,0.070028,283.164124,14.425068,0.700281,-112.225441,0.070158,0.000000
70.850006,63.613506,-112.225441,0.010882,0.002757,0.070028,282.967010,14.415027,0.700281,-112.225441,0.070158,0.000000
71.080002,63.552063,-112.225441,0.010843,0.002757,0.070028,282.693695,14.401103,0.700281,-112.225441,0.070158,0.000000
71.310005,63.511848,-112.136475,0.010887,0.002757,0.070028,282.514801,14.391991,0.700281,-112.136475,0.070158,0.000000
71.540001,63.467907,-112.136475,0.010865,0.002757,0.070028,282.319336,14.382032,0.700281,-112.136475,0.070158,0.000000
71.770004,63.418385,-112.180962,0.010882,0.002757,0.070028,282.099060,14.370811,0.700281,-112.180962,0.070158,0.000000
72.000000,63.375931,-112.136475,0.010861,0.002757,0.070028,281.910217,14.361192,0.700281,-112.136475,0.070158,0.000000
72.230003,63.351727,-112.180962,0.010865,0.002757,0.070028,281.802551,14.355706,0.700281,-112.180962,0.070158,0.000000
72.460007,63.298851,-112.136475,0.010865,0.002757,0.070028,281.567352,14.343724,0.700281,-112.136475,0.070158,0.000000
72.690002,63.255283,-112.136475,0.010874,0.002757,0.070028,281.373566,14.333852,0.700281,-112.136475,0.070158,0.000000
72.920006,63.226238,-112.091995,0.010882,0.002757,0.070021,281.244354,14.327270,0.700206,-112.091995,0.070158,0.000000
73.150002,63.192352,-112.091995,0.010908,0.002757,0.070021,281.093628,14.319592,0.700206,-112.091995,0.070158,0.000000
73.380005,63.142826,-112.091995,0.010900,0.002757,0.070021,280.873322,14.308369,0.700206,-112.091995,0.070158,0.000000
73.610001,63.109314,-112.047516,0.010878,0.002757,0.070021,280.724243,14.300775,0.700206,-112.047516,0.070158,0.000000
73.840004,63.067608,-112.003036,0.010856,0.002757,0.070021,280.538727,14.291324,0.700206,-112.003036,0.070158,0.000000
74.070007,63.028137,-112.091995,0.010887,0.002757,0.070021,280.363159,14.282380,0.700206,-112.091995,0.070158,0.000000
74.300003,63.000954,-112.003036,0.010874,0.002757,0.070021,280.242249,14.276220,0.700206,-112.003036,0.070158,0.000000
74.530006,62.972279,-112.047516,0.010904,0.002757,0.070021,280.114685,14.269722,0.700206,-112.047516,0.070158,0.000000
74.760002,62.935043,-112.003036,0.010891,0.002757,0.070021,279.949066,14.261285,0.700206,-112.003036,0.070158,0.000000
74.990005,62.903019,-112.003036,0.010874,0.002757,0.070021,279.806610,14.254028,0.700206,-112.003036,0.070158,0.000000
75.220001,62.877327,-112.003036,0.010869,0.002757,0.070021,279.692322,14.248206,0.700206,-112.003036,0.070158,0.000000
75.450005,62.852375,-111.958557,0.010865,0.002757,0.070021,279.581329,14.242552,0.700206,-111.958557,0.070158,0.000000
75.680000,62.827057,-111.958557,0.010865,0.002757,0.070021,279.468719,14.236814,0.700206,-111.958557,0.070158,0.000000
75.910004,62.790192,-111.958557,0.010856,0.002757,0.070021,279.304718,14.228460,0.700206,-111.958557,0.070158,0.000000
76.140007,62.773060,-111.914070,0.010865,0.002757,0.070021,279.228516,14.224579,0.700206,-111.914070,0.070158,0.000000
76.370003,62.743645,-111.958557,0.010891,0.002757,0.070021,279.097656,14.217914,0.700206,-111.958557,0.070158,0.000000
76.600006,62.705662,-111.914070,0.010861,0.002757,0.070021,278.928711,14.209306,0.700206,-111.914070,0.070158,0.000000
76.830002,62.676617,-111.869591,0.010861,0.002757,0.070021,278.799530,14.202724,0.700206,-111.869591,0.070158,0.000000
77.060005,62.659489,-111.825111,0.010891,0.002757,0.070021,278.723328,14.198843,0.700206,-111.825111,0.070158,0.000000
77.290001,62.633049,-111.825111,0.010887,0.002757,0.070021,278.605713,14.192851,0.700206,-111.825111,0.070158,0.000000
77.520004,62.602516,-111.825111,0.010895,0.002757,0.070021,278.469910,14.185933,0.700206,-111.825111,0.070158,0.000000
77.750000,62.582779,-111.914070,0.010882,0.002757,0.070021,278.382111,14.181460,0.700206,-111.914070,0.070158,0.000000
77.980003,62.554852,-111.780632,0.010852,0.002757,0.070021,278.257874,14.175132,0.700206,-111.780632,0.070158,0.000000
78.210007,62.532883,-111.825111,0.010856,0.002757,0.070021,278.160156,14.170154,0.700206,-111.825111,0.070158,0.000000
78.440002,62.507931,-111.825111,0.010882,0.002757,0.070021,278.049164,14.164499,0.700206,-111.825111,0.070158,0.000000
78.670006,62.485588,-111.869591,0.010865,0.002757,0.070021,277.949768,14.159436,0.700206,-111.869591,0.070158,0.000000
78.900002,62.467716,-111.825111,0.010861,0.002757,0.070021,277.870270,14.155387,0.700206,-111.825111,0.070158,0.000000
79.130005,62.433086,-111.780632,0.010895,0.002757,0.070021,277.716248,14.147539,0.700206,-111.780632,0.070158,0.000000
79.360001,62.410000,-111.736153,0.010874,0.002757,0.070021,277.613556,14.142308,0.700206,-111.736153,0.070158,0.000000
79.590004,62.398827,-111.780632,0.010887,0.002757,0.070021,277.563843,14.139776,0.700206,-111.780632,0.070158,0.000000
79.820007,62.382816,-111.736153,0.010856,0.002757,0.070021,277.492615,14.136148,0.700206,-111.736153,0.070158,0.000000
80.050003,62.342598,-111.780632,0.010861,0.002757,0.070021,277.313721,14.127035,0.700206,-111.780632,0.070158,0.000000
80.280006,62.331429,-111.736153,0.010869,0.002757,0.070021,277.264038,14.124504,0.700206,-111.736153,0.070158,0.000000
80.510002,62.320629,-111.736153,0.010865,0.002757,0.070021,277.216003,14.122056,0.700206,-111.736153,0.070158,0.000000
80.740005,62.291210,-111.736153,0.010878,0.002757,0.070021,277.085144,14.115390,0.700206,-111.736153,0.070158,0.000000
80.970001,62.277435,-111.736153,0.010878,0.002757,0.070021,277.023865,14.112268,0.700206,-111.736153,0.070158,0.000000
81.200005,62.271847,-111.691666,0.010878,0.002757,0.070021,276.999023,14.111002,0.700206,-111.691666,0.070158,0.000000
81.430000,62.245037,-111.647186,0.010865,0.002757,0.070021,276.879761,14.104927,0.700206,-111.647186,0.070158,0.000000
81.660004,62.219715,-111.647186,0.010843,0.002757,0.070021,276.767120,14.099189,0.700206,-111.647186,0.070158,0.000000
81.890007,62.190300,-111.647186,0.010895,0.002757,0.070021,276.636261,14.092524,0.700206,-111.647186,0.070158,0.000000
82.120003,62.188808,-111.691666,0.010878,0.002757,0.070021,276.629639,14.092185,0.700206,-111.691666,0.070158,0.000000
82.350006,62.160137,-111.558228,0.010865,0.002757,0.070021,276.502106,14.085688,0.700206,-111.558228,0.070158,0.000000
82.580002,62.140030,-111.602707,0.010917,0.002757,0.070021,276.412659,14.081133,0.700206,-111.602707,0.070158,0.000000
82.810005,62.129601,-111.602707,0.010878,0.002757,0.070021,276.366272,14.078769,0.700206,-111.602707,0.070158,0.000000
83.040001,62.099812,-111.647186,0.010856,0.002757,0.070021,276.233765,14.072019,0.700206,-111.647186,0.070158,0.000000
83.270004,62.080448,-111.602707,0.010869,0.002756,0.070011,276.147614,14.067631,0.700115,-111.602707,0.070158,0.000000
83.500008,62.062946,-111.558228,0.010891,0.002756,0.070011,276.069763,14.063664,0.700115,-111.558228,0.070158,0.000000
83.730003,62.061459,-111.558228,0.010869,0.002756,0.070011,276.063141,14.063328,0.700115,-111.558228,0.070158,0.000000
83.960007,62.027943,-111.513741,0.010874,0.002756,0.070011,275.914062,14.055733,0.700115,-111.513741,0.070158,0.000000
84.190002,62.013050,-111.647186,0.010874,0.002756,0.070011,275.847809,14.052359,0.700115,-111.647186,0.070158,0.000000
84.420006,62.008209,-111.558228,0.010874,0.002756,0.070011,275.826294,14.051261,0.700115,-111.558228,0.070158,0.000000
84.650002,61.997410,-111.558228,0.010874,0.002756,0.070011,275.778259,14.048814,0.700115,-111.558228,0.070158,0.000000
84.880005,61.976185,-111.513741,0.010887,0.002756,0.070011,275.683838,14.044004,0.700115,-111.513741,0.070158,0.000000
85.110001,61.956448,-111.513741,0.010852,0.002756,0.070011,275.596039,14.039532,0.700115,-111.513741,0.070158,0.000000
85.340004,61.940807,-111.469261,0.010852,0.002756,0.070011,275.526459,14.035987,0.700115,-111.469261,0.070158,0.000000
85.570007,61.930382,-111.469261,0.010852,0.002756,0.070011,275.480103,14.033626,0.700115,-111.469261,0.070158,0.000000
85.800003,61.899849,-111.424782,0.010882,0.002756,0.070011,275.344269,14.026707,0.700115,-111.424782,0.070158,0.000000
86.030006,61.890911,-111.424782,0.010900,0.002756,0.070011,275.304535,14.024681,0.700115,-111.424782,0.070158,0.000000
86.260002,61.877506,-111.424782,0.010878,0.002756,0.070011,275.244904,14.021644,0.700115,-111.424782,0.070158,0.000000
86.490005,61.856281,-111.424782,0.010874,0.002756,0.070011,275.150482,14.016833,0.700115,-111.424782,0.070158,0.000000
86.720001,61.854790,-111.424782,0.010865,0.002756,0.070011,275.143860,14.016496,0.700115,-111.424782,0.070158,0.000000
86.950005,61.834309,-111.424782,0.010895,0.002756,0.070011,275.052734,14.011854,0.700115,-111.424782,0.070158,0.000000
87.180008,61.821651,-111.335823,0.010874,0.002756,0.070011,274.996429,14.008986,0.700115,-111.335823,0.070158,0.000000
87.410004,61.819786,-111.380302,0.010874,0.002756,0.070011,274.988129,14.008563,0.700115,-111.380302,0.070158,0.000000
87.640007,61.798561,-111.424782,0.010865,0.002756,0.070011,274.893738,14.003755,0.700115,-111.424782,0.070158,0.000000
87.870003,61.789253,-111.380302,0.010856,0.002756,0.070011,274.852325,14.001644,0.700115,-111.380302,0.070158,0.000000
88.100006,61.778454,-111.380302,0.010895,0.002756,0.070011,274.804291,13.999198,0.700115,-111.380302,0.070158,0.000000
88.330002,61.757229,-111.291336,0.010878,0.002756,0.070011,274.709869,13.994389,0.700115,-111.291336,0.070158,0.000000
88.560005,61.740845,-111.291336,0.010869,0.002756,0.070011,274.636993,13.990675,0.700115,-111.291336,0.070158,0.000000
88.790001,61.736004,-111.335823,0.010882,0.002756,0.070011,274.615448,13.989578,0.700115,-111.335823,0.070158,0.000000
89.020004,61.711426,-111.291336,0.010878,0.002756,0.070011,274.506134,13.984009,0.700115,-111.291336,0.070158,0.000000
89.250008,61.696159,-111.246857,0.010891,0.002756,0.070011,274.438232,13.980549,0.700115,-111.246857,0.070158,0.000000
89.480003,61.686478,-111.246857,0.010891,0.002756,0.070011,274.395172,13.978355,0.700115,-111.246857,0.070158,0.000000
89.710007,61.683128,-111.246857,0.010904,0.002756,0.070011,274.380249,13.977597,0.700115,-111.246857,0.070158,0.000000
89.940002,61.668976,-111.291336,0.010878,0.002756,0.070011,274.317291,13.974389,0.700115,-111.291336,0.070158,0.000000
90.170006,61.655571,-111.291336,0.010869,0.002756,0.070011,274.257690,13.971352,0.700115,-111.291336,0.070158,0.000000
90.400002,61.642166,-111.202377,0.010861,0.002756,0.070011,274.198059,13.968314,0.700115,-111.202377,0.070158,0.000000
90.630005,61.628017,-111.202377,0.010887,0.002756,0.070011,274.135101,13.965109,0.700115,-111.202377,0.070158,0.000000
90.860001,61.621685,-111.246857,0.010852,0.002756,0.070011,274.106934,13.963674,0.700115,-111.246857,0.070158,0.000000
91.090004,61.611259,-111.202377,0.010882,0.002756,0.070011,274.060577,13.961311,0.700115,-111.202377,0.070158,0.000000
91.320007,61.599342,-111.157898,0.010882,0.002756,0.070011,274.007568,13.958611,0.700115,-111.157898,0.070158,0.000000
91.550003,61.583332,-111.202377,0.010856,0.002756,0.070011,273.936340,13.954983,0.700115,-111.202377,0.070158,0.000000
91.780006,61.586681,-111.202377,0.010904,0.002756,0.070011,273.951233,13.955742,0.700115,-111.202377,0.070158,0.000000
92.010002,61.554287,-111.246857,0.010887,0.002756,0.070011,273.807129,13.948400,0.700115,-111.246857,0.070158,0.000000
92.240005,61.550190,-111.113419,0.010891,0.002756,0.070011,273.788910,13.947473,0.700115,-111.113419,0.070158,0.000000
92.470001,61.544605,-111.113419,0.010882,0.002756,0.070011,273.764069,13.946207,0.700115,-111.113419,0.070158,0.000000
92.700005,61.539021,-111.113419,0.010887,0.002756,0.070011,273.739227,13.944942,0.700115,-111.113419,0.070158,0.000000
92.930008,61.527847,-111.068932,0.010891,0.002756,0.070011,273.689545,13.942410,0.700115,-111.068932,0.070158,0.000000
93.160004,61.508114,-111.157898,0.010904,0.002756,0.070011,273.601746,13.937938,0.700115,-111.157898,0.070158,0.000000
93.390007,61.497314,-111.024452,0.010861,0.002756,0.070011,273.553711,13.935491,0.700115,-111.024452,0.070158,0.000000
93.620003,61.490238,-111.068932,0.010856,0.002756,0.070011,273.522247,13.933887,0.700115,-111.068932,0.070158,0.000000
93.850006,61.482792,-111.024452,0.010865,0.002756,0.070011,273.489105,13.932200,0.700115,-111.024452,0.070158,0.000000
94.080002,61.469757,-111.068932,0.010865,0.002756,0.070011,273.431122,13.929246,0.700115,-111.068932,0.070158,0.000000
94.310005,61.454491,-111.068932,0.010878,0.002756,0.070011,273.363220,13.925786,0.700115,-111.068932,0.070158,0.000000
94.540001,61.444435,-111.024452,0.010869,0.002756,0.070011,273.318512,13.923508,0.700115,-111.024452,0.070158,0.000000
94.770004,61.442204,-110.935493,0.010882,0.002756,0.070011,273.308563,13.923002,0.700115,-110.935493,0.070158,0.000000
94.900002,61.428795,-110.979973,0.010908,0.002756,0.070011,273.248932,13.919964,0.700115,-110.979973,0.070158,0.000000