File: Data/New new I18 1 new align_08182023_122046.csv
Time (sec),S:Load (lbs),S:HL1 (DIM),S:LVDT (in),S:Position (in),Ch:Position (mm),Ch:Load (N),Ch:Stress (MPa),Ch:Strain (mm/mm),Ch:HL1 (DIM),Set Point (),Cycles ()
0.110000,-0.020477,-58.492451,-0.000009,-0.000000,-0.000000,-0.091088,-0.004640,-0.000000,-58.492451,0.000191,0.000000
0.510000,-0.007072,-58.536930,-0.000004,0.000067,0.001691,-0.031460,-0.001603,0.016911,-58.536930,0.002289,0.000000
0.910000,0.039101,-58.581413,0.000009,0.000307,0.007804,0.173928,0.008860,0.078045,-58.581413,0.008949,0.000000
1.310000,0.108734,-58.536930,0.000009,0.000571,0.014499,0.483674,0.024640,0.144992,-58.536930,0.015627,0.000000
1.710000,0.134804,-58.581413,0.000190,0.000829,0.021047,0.599637,0.030547,0.210470,-58.581413,0.022287,0.000000
2.110000,0.129959,-58.581413,0.000397,0.001089,0.027655,0.578087,0.029449,0.276555,-58.581413,0.028948,0.000000
2.510000,0.124748,-58.581413,0.000707,0.001353,0.034368,0.554908,0.028268,0.343684,-58.581413,0.035608,0.000000
2.910000,0.148209,-58.581413,0.000927,0.001611,0.040924,0.659265,0.033585,0.409238,-58.581413,0.042286,0.000000
3.310000,0.143738,-58.625893,0.001229,0.001885,0.047879,0.639378,0.032571,0.478789,-58.625893,0.048946,0.000000
3.710000,0.127724,-58.625893,0.001518,0.002151,0.054627,0.568143,0.028943,0.546266,-58.625893,0.055606,0.000000
4.110000,0.112457,-58.670376,0.001802,0.002410,0.061217,0.500235,0.025483,0.612169,-58.670376,0.062266,0.000000
4.510000,0.115807,-58.625893,0.002052,0.002673,0.067895,0.515133,0.026242,0.678950,-58.625893,0.068927,0.000000
4.910000,0.103897,-58.625893,0.002320,0.002929,0.074399,0.462157,0.023543,0.743989,-58.625893,0.075604,0.000000
5.310000,0.116554,-58.714855,0.002604,0.003192,0.081068,0.518459,0.026412,0.810679,-58.714855,0.082265,0.000000
5.710000,0.126236,-58.714855,0.002850,0.003459,0.087850,0.561526,0.028605,0.878504,-58.714855,0.088925,0.000000
6.110000,0.132195,-58.759335,0.003165,0.003722,0.094536,0.588031,0.029956,0.945361,-58.759335,0.095585,0.000000
6.510000,0.109482,-58.714855,0.003406,0.003980,0.101084,0.486999,0.024809,1.010839,-58.714855,0.102245,0.000000
6.910000,0.120277,-58.714855,0.003695,0.004243,0.107760,0.535021,0.027255,1.077605,-58.714855,0.108923,0.000000
7.310000,0.147461,-58.759335,0.003962,0.004504,0.114404,0.655939,0.033415,1.144037,-58.759335,0.115583,0.000000
7.710001,0.136292,-58.714855,0.004234,0.004768,0.121108,0.606255,0.030884,1.211076,-58.714855,0.122245,0.000000
8.110001,0.154533,-58.714855,0.004493,0.005026,0.127672,0.687399,0.035018,1.276721,-58.714855,0.128904,0.000000
8.510000,0.154167,-58.714855,0.004751,0.005287,0.134290,0.685770,0.034935,1.342896,-58.714855,0.135564,0.000000
8.910001,0.147835,-58.803818,0.005019,0.005550,0.140968,0.657602,0.033500,1.409677,-58.803818,0.142242,0.000000
9.310000,0.178368,-58.714855,0.005299,0.005809,0.147558,0.793419,0.040419,1.475579,-58.714855,0.148902,0.000000
9.710000,0.167572,-58.803818,0.005592,0.006083,0.154513,0.745398,0.037972,1.545130,-58.803818,0.155562,0.000000
10.110001,0.154907,-58.848297,0.005855,0.006347,0.161208,0.689062,0.035102,1.612078,-58.848297,0.162224,0.000000
10.510000,0.140015,-58.803818,0.006135,0.006608,0.167842,0.622816,0.031728,1.678419,-58.803818,0.168884,0.000000
10.910001,0.125122,-58.803818,0.006390,0.006871,0.174511,0.556571,0.028353,1.745109,-58.803818,0.175562,0.000000
11.310000,0.127724,-58.848297,0.006644,0.007127,0.181016,0.568143,0.028943,1.810164,-58.848297,0.182221,0.000000
11.710001,0.135918,-58.892780,0.006942,0.007390,0.187711,0.604592,0.030799,1.877111,-58.892780,0.188881,0.000000
12.110001,0.159752,-58.892780,0.007183,0.007654,0.194415,0.710612,0.036200,1.944149,-58.892780,0.195541,0.000000
12.510000,0.150444,-58.937260,0.007459,0.007918,0.201110,0.669208,0.034091,2.011096,-58.937260,0.202219,0.000000
12.910001,0.140015,-58.892780,0.007739,0.008175,0.207658,0.622816,0.031728,2.076575,-58.892780,0.208879,0.000000
13.310000,0.138527,-58.848297,0.007998,0.008438,0.214334,0.616198,0.031391,2.143341,-58.848297,0.215541,0.000000
13.710001,0.179115,-58.892780,0.008278,0.008701,0.221003,0.796745,0.040588,2.210031,-58.892780,0.222201,0.000000
14.110001,0.170921,-58.892780,0.008520,0.008963,0.227672,0.760296,0.038731,2.276720,-58.892780,0.228860,0.000000
14.510000,0.177994,-58.937260,0.008808,0.009225,0.234306,0.791756,0.040334,2.343062,-58.937260,0.235539,0.000000
14.910001,0.181351,-58.892780,0.009076,0.009483,0.240872,0.806688,0.041095,2.408722,-58.892780,0.242198,0.000000
15.310000,0.182091,-58.892780,0.009322,0.009747,0.247576,0.809980,0.041262,2.475760,-58.892780,0.248858,0.000000
15.710001,0.199219,-58.937260,0.009563,0.010007,0.254166,0.886169,0.045144,2.541663,-58.937260,0.255520,0.000000
16.110001,0.199593,-58.981743,0.009891,0.010280,0.261105,0.887832,0.045228,2.611048,-58.981743,0.262180,0.000000
16.510000,0.192894,-58.937260,0.010158,0.010545,0.267834,0.858035,0.043710,2.678343,-58.937260,0.268858,0.000000
16.910002,0.188797,-58.981743,0.010442,0.010804,0.274434,0.839811,0.042782,2.744337,-58.981743,0.275518,0.000000
17.310001,0.159004,-58.981743,0.010680,0.011066,0.281084,0.707286,0.036031,2.810845,-58.981743,0.282178,0.000000
17.710001,0.142250,-58.937260,0.010951,0.011326,0.287684,0.632760,0.032234,2.876838,-58.937260,0.288837,0.000000
18.110001,0.176506,-59.026222,0.011236,0.011586,0.294292,0.785138,0.039997,2.942922,-59.026222,0.295499,0.000000
18.510000,0.188423,-59.026222,0.011482,0.011851,0.301014,0.838148,0.042697,3.010142,-59.026222,0.302175,0.000000
18.910002,0.193260,-59.026222,0.011770,0.012115,0.307718,0.859664,0.043793,3.077180,-59.026222,0.308837,0.000000
19.310001,0.186188,-58.981743,0.012012,0.012374,0.314292,0.828204,0.042191,3.142916,-58.981743,0.315497,0.000000
19.710001,0.179115,-59.026222,0.012279,0.012636,0.320961,0.796745,0.040588,3.209606,-59.026222,0.322157,0.000000
20.110001,0.210022,-59.070702,0.012577,0.012898,0.327621,0.934224,0.047592,3.276205,-59.070702,0.328817,0.000000
20.510000,0.211510,-59.026222,0.012840,0.013161,0.334280,0.940842,0.047929,3.342804,-59.026222,0.335495,0.000000
20.910002,0.214485,-59.026222,0.013107,0.013423,0.340940,0.954078,0.048603,3.409403,-59.026222,0.342155,0.000000
21.310001,0.206299,-59.026222,0.013400,0.013681,0.347506,0.917663,0.046748,3.475064,-59.026222,0.348816,0.000000
21.710001,0.200340,-59.026222,0.013655,0.013946,0.354227,0.891158,0.045398,3.542268,-59.026222,0.355476,0.000000
22.110001,0.221939,-58.981743,0.013922,0.014205,0.360809,0.987234,0.050292,3.608095,-58.981743,0.362154,0.000000
22.510000,0.223053,-59.070702,0.014224,0.014479,0.367772,0.992189,0.050545,3.677722,-59.070702,0.368814,0.000000
22.910002,0.223801,-59.070702,0.014508,0.014744,0.374485,0.995515,0.050714,3.744851,-59.070702,0.375474,0.000000
23.310001,0.421158,-59.070702,0.014763,0.015003,0.381084,1.873404,0.095436,3.810844,-59.070702,0.382134,0.000000
23.710001,0.341095,-59.070702,0.015000,0.015266,0.387744,1.517266,0.077293,3.877443,-59.070702,0.388795,0.000000
24.110001,0.292313,-59.070702,0.015250,0.015524,0.394318,1.300272,0.066239,3.943179,-59.070702,0.395472,0.000000
24.510000,0.322105,-59.070702,0.015504,0.015785,0.400935,1.432796,0.072990,4.009355,-59.070702,0.402133,0.000000
24.910002,0.307953,-59.070702,0.015772,0.016048,0.407630,1.369843,0.069783,4.076302,-59.070702,0.408793,0.000000
25.310001,0.265877,-59.026222,0.016129,0.016314,0.414378,1.182679,0.060249,4.143779,-59.026222,0.415453,0.000000
25.710001,0.186562,-59.070702,0.016504,0.016573,0.420951,0.829867,0.042275,4.209515,-59.070702,0.422113,0.000000
26.110001,0.183952,-59.070702,0.016759,0.016835,0.427611,0.818261,0.041684,4.276114,-59.070702,0.428791,0.000000
26.510002,0.207787,-59.070702,0.017056,0.017097,0.434271,0.924281,0.047085,4.342713,-59.070702,0.435451,0.000000
26.910002,0.198479,-59.115185,0.017311,0.017357,0.440880,0.882877,0.044976,4.408797,-59.115185,0.442112,0.000000
27.310001,0.219330,-59.070702,0.017574,0.017620,0.447558,0.975628,0.049701,4.475578,-59.070702,0.448772,0.000000
27.710001,0.214119,-59.070702,0.017867,0.017879,0.454122,0.952449,0.048520,4.541223,-59.070702,0.455432,0.000000
28.110001,0.194756,-59.070702,0.018143,0.018145,0.460887,0.866316,0.044132,4.608867,-59.070702,0.462110,0.000000
28.510002,0.226776,-59.115185,0.018397,0.018405,0.467495,1.008751,0.051388,4.674951,-59.115185,0.468770,0.000000
28.910002,0.262894,-59.070702,0.018673,0.018677,0.474406,1.169410,0.059573,4.744063,-59.070702,0.475430,0.000000
29.310001,0.334389,-59.159664,0.018889,0.018940,0.481075,1.487435,0.075774,4.810753,-59.159664,0.482091,0.000000
29.710001,0.429718,-59.115185,0.019126,0.019199,0.487667,1.911481,0.097375,4.876671,-59.115185,0.488768,0.000000
30.110001,0.573082,-59.159664,0.019385,0.019462,0.494336,2.549196,0.129862,4.943360,-59.159664,0.495429,0.000000
30.510002,0.592819,-59.115185,0.019441,-0.000011,-0.000268,2.636992,0.134335,-0.002680,-59.115185,-0.000042,0.000000
30.910002,0.605476,-59.159664,0.019454,-0.000010,-0.000259,2.693293,0.137203,-0.002589,-59.159664,0.000304,0.000000
31.310001,0.640854,-59.115185,0.019467,-0.000001,-0.000017,2.850660,0.145220,-0.000167,-59.115185,0.000972,0.000000
31.710001,0.688515,-59.159664,0.019441,0.000026,0.000651,3.062666,0.156020,0.006510,-59.159664,0.001631,0.000000
32.110001,0.716820,-59.204147,0.019479,0.000056,0.001423,3.188574,0.162434,0.014231,-59.204147,0.002298,0.000000
32.510002,0.685539,-59.204147,0.019523,0.000076,0.001926,3.049431,0.155345,0.019258,-59.204147,0.002966,0.000000
32.910000,0.764107,-59.159664,0.019548,0.000101,0.002577,3.398916,0.173149,0.025768,-59.159664,0.003635,0.000000
33.310001,0.810287,-59.204147,0.019566,0.000124,0.003149,3.604339,0.183614,0.031490,-59.204147,0.004303,0.000000
33.710003,0.849380,-59.204147,0.019583,0.000156,0.003973,3.778233,0.192472,0.039726,-59.204147,0.004970,0.000000
34.110001,0.884758,-59.159664,0.019604,0.000183,0.004657,3.935600,0.200489,0.046569,-59.159664,0.005638,0.000000
34.510002,0.863533,-59.159664,0.019622,0.000207,0.005256,3.841187,0.195679,0.052565,-59.159664,0.006306,0.000000
34.910000,0.991257,-59.159664,0.019656,0.000234,0.005950,4.409330,0.224622,0.059499,-59.159664,0.006973,0.000000
35.310001,1.034828,-59.159664,0.019678,0.000256,0.006505,4.603146,0.234495,0.065055,-59.159664,0.007632,0.000000
35.710003,1.082115,-59.159664,0.019708,0.000283,0.007199,4.813488,0.245211,0.071989,-59.159664,0.008300,0.000000
36.110001,1.118980,-59.159664,0.019734,0.000310,0.007883,4.977473,0.253565,0.078832,-59.159664,0.008967,0.000000
36.510002,1.152496,-59.159664,0.019768,0.000334,0.008474,5.126560,0.261159,0.084736,-59.159664,0.009635,0.000000
36.910000,1.218781,-59.204147,0.019794,0.000364,0.009246,5.421406,0.276180,0.092457,-59.204147,0.010304,0.000000
37.310001,1.273888,-59.248627,0.019842,0.000384,0.009757,5.666535,0.288667,0.097575,-59.248627,0.010972,0.000000
37.710003,1.368095,-59.293106,0.019850,0.000420,0.010667,6.085592,0.310015,0.106673,-59.293106,0.011639,0.000000
38.110001,1.387459,-59.293106,0.019863,0.000443,0.011240,6.171725,0.314403,0.112396,-59.293106,0.012307,0.000000
38.510002,1.440338,-59.248627,0.019889,0.000471,0.011960,6.406944,0.326385,0.119603,-59.248627,0.012966,0.000000
38.910004,1.518906,-59.293106,0.019928,0.000496,0.012593,6.756430,0.344189,0.125931,-59.293106,0.013633,0.000000
39.310001,1.632111,-59.293106,0.019945,0.000524,0.013321,7.259991,0.369842,0.133213,-59.293106,0.014301,0.000000
39.710003,1.698769,-59.293106,0.019984,0.000553,0.014050,7.556500,0.384946,0.140495,-59.293106,0.014969,0.000000
40.110001,1.732277,-59.293106,0.020005,0.000577,0.014648,7.705553,0.392540,0.146475,-59.293106,0.015636,0.000000
40.510002,1.783669,-59.248627,0.020036,0.000597,0.015159,7.934154,0.404185,0.151593,-59.248627,0.016304,0.000000
40.910004,1.885696,-59.293106,0.020074,0.000628,0.015950,8.387997,0.427305,0.159495,-59.293106,0.016973,0.000000
41.310001,1.945274,-59.293106,0.020070,0.000644,0.016366,8.653012,0.440805,0.163659,-59.293106,0.017641,0.000000
41.710003,2.071136,-59.293106,0.020143,0.000681,0.017302,9.212875,0.469326,0.173015,-59.293106,0.018299,0.000000
42.110001,2.163116,-59.293106,0.020148,0.000705,0.017918,9.622023,0.490169,0.179177,-59.293106,0.018967,0.000000
42.510002,2.213753,-59.337589,0.020174,0.000726,0.018438,9.847264,0.501644,0.184385,-59.337589,0.019635,0.000000
42.910004,2.343712,-59.337589,0.020195,0.000756,0.019202,10.425351,0.531093,0.192015,-59.337589,0.020302,0.000000
43.310001,2.496017,-59.293106,0.020230,0.000780,0.019800,11.102840,0.565606,0.197995,-59.293106,0.020970,0.000000
43.710003,2.642731,-59.293106,0.020256,0.000816,0.020719,11.755453,0.598851,0.207185,-59.293106,0.021637,0.000000
44.110001,2.711243,-59.337589,0.020312,0.000837,0.021248,12.060210,0.614376,0.212484,-59.337589,0.022305,0.000000
44.510002,2.862801,-59.337589,0.020324,0.000863,0.021933,12.734373,0.648720,0.219327,-59.337589,0.022973,0.000000
44.910004,2.979355,-59.293106,0.020342,0.000887,0.022523,13.252832,0.675131,0.225232,-59.293106,0.023633,0.000000
45.310001,3.160324,-59.337589,0.020372,0.000917,0.023294,14.057824,0.716140,0.232938,-59.337589,0.024301,0.000000
45.710003,3.281349,-59.337589,0.020402,0.000942,0.023919,14.596170,0.743564,0.239190,-59.337589,0.024968,0.000000
46.110001,3.397156,-59.382069,0.020437,0.000966,0.024534,15.111303,0.769807,0.245337,-59.382069,0.025636,0.000000
46.510002,3.532700,-59.337589,0.020454,0.000994,0.025236,15.714232,0.800521,0.252362,-59.337589,0.026304,0.000000
46.910004,3.625046,-59.426552,0.020475,0.001012,0.025715,16.125010,0.821447,0.257146,-59.426552,0.026971,0.000000
47.310001,3.901344,-59.382069,0.020523,0.001048,0.026615,17.354046,0.884057,0.266154,-59.382069,0.027639,0.000000
47.710003,3.976196,-59.471031,0.020562,0.001074,0.027275,17.687004,0.901019,0.272755,-59.471031,0.028306,0.000000
48.110001,4.134453,-59.382069,0.020549,0.001096,0.027848,18.390965,0.936880,0.278477,-59.382069,0.028974,0.000000
48.510002,4.344475,-59.337589,0.020609,0.001125,0.028585,19.325190,0.984472,0.285850,-59.337589,0.029634,0.000000
48.910004,4.509064,-59.337589,0.020631,0.001148,0.029165,20.057318,1.021768,0.291649,-59.337589,0.030302,0.000000
49.310001,4.720940,-59.426552,0.020639,0.001182,0.030016,20.999788,1.069780,0.300157,-59.426552,0.030970,0.000000
49.710003,4.767113,-59.426552,0.020691,0.001202,0.030518,21.205177,1.080243,0.305184,-59.426552,0.031637,0.000000
50.110001,4.971916,-59.426552,0.020721,0.001231,0.031256,22.116188,1.126652,0.312557,-59.426552,0.032305,0.000000
50.510002,5.089218,-59.426552,0.020743,0.001254,0.031845,22.637974,1.153233,0.318446,-59.426552,0.032972,0.000000
50.910004,5.176353,-59.426552,0.020769,0.001276,0.032409,23.025570,1.172979,0.324093,-59.426552,0.033640,0.000000
51.310001,5.393074,-59.471031,0.020769,0.001308,0.033215,23.989592,1.222088,0.332147,-59.471031,0.034308,0.000000
51.710003,5.504410,-59.471031,0.020833,0.001336,0.033944,24.484838,1.247317,0.339445,-59.471031,0.034968,0.000000
52.110001,5.530479,-59.382069,0.020842,0.001355,0.034412,24.600801,1.253224,0.344123,-59.382069,0.035636,0.000000
52.510002,5.737892,-59.471031,0.020881,0.001380,0.035054,25.523418,1.300225,0.350542,-59.471031,0.036303,0.000000
52.910004,5.844391,-59.426552,0.020881,0.001403,0.035643,25.997149,1.324358,0.356431,-59.426552,0.036971,0.000000
53.310001,6.028343,-59.471031,0.020932,0.001438,0.036529,26.815411,1.366042,0.365288,-59.471031,0.037639,0.000000
53.710003,6.074883,-59.471031,0.020950,0.001466,0.037231,27.022427,1.376588,0.372313,-59.471031,0.038306,0.000000
54.110004,6.180641,-59.515514,0.020971,0.001488,0.037804,27.492865,1.400553,0.378035,-59.515514,0.038974,0.000000
54.510002,6.417099,-59.515514,0.021001,0.001516,0.038506,28.544682,1.454135,0.385060,-59.515514,0.039641,0.000000
54.910004,6.640144,-59.426552,0.021023,0.001545,0.039251,29.536837,1.504678,0.392509,-59.426552,0.040300,0.000000
55.310001,6.700844,-59.382069,0.021049,0.001573,0.039953,29.806843,1.518433,0.399534,-59.382069,0.040968,0.000000
55.710003,6.763031,-59.471031,0.021070,0.001598,0.040595,30.083464,1.532525,0.405953,-59.471031,0.041637,0.000000
56.110004,6.818138,-59.471031,0.021105,0.001618,0.041107,30.328592,1.545012,0.411070,-59.471031,0.042305,0.000000
56.510002,7.028160,-59.515514,0.021126,0.001645,0.041775,31.262817,1.592604,0.417746,-59.515514,0.042972,0.000000
56.910004,7.147316,-59.515514,0.021157,0.001669,0.042400,31.792849,1.619605,0.423999,-59.515514,0.043640,0.000000
57.310001,7.383774,-59.515514,0.021191,0.001702,0.043240,32.844666,1.673187,0.432402,-59.515514,0.044307,0.000000
57.710003,7.409096,-59.515514,0.021217,0.001724,0.043778,32.957302,1.678925,0.437776,-59.515514,0.044975,0.000000
58.110004,7.681671,-59.515514,0.021234,0.001758,0.044645,34.169781,1.740692,0.446451,-59.515514,0.045634,0.000000
58.510002,7.668266,-59.515514,0.021243,0.001775,0.045096,34.110153,1.737654,0.450963,-59.515514,0.046301,0.000000
58.910004,7.875679,-59.515514,0.021277,0.001807,0.045903,35.032768,1.784654,0.459032,-59.515514,0.046969,0.000000
59.310001,7.933022,-59.471031,0.021316,0.001831,0.046510,35.287842,1.797648,0.465103,-59.471031,0.047637,0.000000
59.710003,8.052559,-59.559994,0.021325,0.001858,0.047187,35.819572,1.824736,0.471870,-59.559994,0.048304,0.000000
60.110004,8.216774,-59.515514,0.021364,0.001886,0.047906,36.550037,1.861948,0.479062,-59.515514,0.048974,0.000000
60.510002,8.296089,-59.515514,0.021381,0.001909,0.048488,36.902847,1.879921,0.484875,-59.515514,0.049641,0.000000
60.910004,8.569412,-59.559994,0.021415,0.001941,0.049311,38.118649,1.941857,0.493111,-59.559994,0.050309,0.000000
61.310001,8.559731,-59.515514,0.021424,0.001965,0.049909,38.075584,1.939663,0.499091,-59.515514,0.050976,0.000000
61.710003,8.681870,-59.515514,0.021445,0.001990,0.050534,38.618885,1.967340,0.505344,-59.515514,0.051635,0.000000
62.110004,8.871407,-59.515514,0.021471,0.002018,0.051263,39.461987,2.010289,0.512626,-59.515514,0.052303,0.000000
62.510002,8.828583,-59.515514,0.021480,0.002034,0.051661,39.271496,2.000586,0.516608,-59.515514,0.052970,0.000000
62.910004,9.230743,-59.559994,0.021527,0.002073,0.052658,41.060398,2.091716,0.526585,-59.559994,0.053638,0.000000
63.310001,9.222549,-59.515514,0.021540,0.002096,0.053240,41.023949,2.089860,0.532398,-59.515514,0.054306,0.000000
63.710003,9.278778,-59.515514,0.021571,0.002120,0.053838,41.274067,2.102601,0.538379,-59.515514,0.054973,0.000000
64.110001,9.473526,-59.559994,0.021596,0.002149,0.054592,42.140347,2.146732,0.545918,-59.559994,0.055642,0.000000
64.510002,9.478745,-59.515514,0.021609,0.002168,0.055078,42.163563,2.147914,0.550778,-59.515514,0.056310,0.000000
64.910004,9.799728,-59.559994,0.021648,0.002200,0.055885,43.591370,2.220650,0.558847,-59.559994,0.056969,0.000000
65.310005,9.807549,-59.559994,0.021687,0.002226,0.056543,43.626156,2.222422,0.565433,-59.559994,0.057636,0.000000
65.710007,10.017197,-59.559994,0.021696,0.002253,0.057220,44.558716,2.269929,0.572200,-59.559994,0.058304,0.000000
66.110001,10.083473,-59.604473,0.021734,0.002278,0.057853,44.853527,2.284948,0.578529,-59.604473,0.058972,0.000000
66.510002,10.289398,-59.559994,0.021760,0.002304,0.058521,45.769527,2.331611,0.585205,-59.559994,0.059639,0.000000
66.910004,10.420471,-59.604473,0.021777,0.002335,0.059302,46.352570,2.361313,0.593017,-59.604473,0.060307,0.000000
67.310005,10.456963,-59.559994,0.021786,0.002356,0.059848,46.514893,2.369582,0.598483,-59.559994,0.060975,0.000000
67.710007,10.771622,-59.559994,0.021829,0.002390,0.060707,47.914566,2.440884,0.607067,-59.559994,0.061642,0.000000
68.110001,10.729912,-59.515514,0.021868,0.002410,0.061209,47.729031,2.431433,0.612093,-59.515514,0.062302,0.000000
68.510002,11.085533,-59.559994,0.021894,0.002440,0.061981,49.310913,2.512018,0.619814,-59.559994,0.062970,0.000000
68.910004,11.062447,-59.604473,0.021946,0.002466,0.062631,49.208221,2.506786,0.626309,-59.604473,0.063638,0.000000
69.310005,11.136917,-59.604473,0.021933,0.002491,0.063265,49.539482,2.523662,0.632653,-59.604473,0.064305,0.000000
69.710007,11.305229,-59.604473,0.021946,0.002515,0.063880,50.288170,2.561802,0.638799,-59.604473,0.064973,0.000000
70.110001,11.389389,-59.604473,0.021980,0.002537,0.064436,50.662533,2.580873,0.644356,-59.604473,0.065641,0.000000
70.510002,11.702553,-59.604473,0.022023,0.002571,0.065294,52.055553,2.651836,0.652940,-59.604473,0.066308,0.000000
70.910004,11.676109,-59.604473,0.022049,0.002594,0.065884,51.937927,2.645844,0.658844,-59.604473,0.066976,0.000000
71.310005,11.820969,-59.648956,0.022101,0.002619,0.066525,52.582294,2.678670,0.665248,-59.648956,0.067636,0.000000
71.710007,12.014229,-59.604473,0.022084,0.002645,0.067194,53.441959,2.722463,0.671940,-59.604473,0.068304,0.000000
72.110001,12.118492,-59.648956,0.022127,0.002670,0.067827,53.905746,2.746090,0.678268,-59.648956,0.068971,0.000000
72.510002,12.320686,-59.648956,0.022148,0.002695,0.068460,54.805149,2.791907,0.684597,-59.648956,0.069639,0.000000
72.910004,12.436501,-59.604473,0.022170,0.002725,0.069223,55.320316,2.818151,0.692227,-59.604473,0.070307,0.000000
73.310005,12.561241,-59.648956,0.022196,0.002750,0.069856,55.875191,2.846418,0.698555,-59.648956,0.070974,0.000000
73.710007,12.863983,-59.693436,0.022187,0.002777,0.070541,57.221855,2.915020,0.705414,-59.693436,0.071642,0.000000
74.110001,12.842758,-59.604473,0.022239,0.002797,0.071044,57.127441,2.910211,0.710440,-59.604473,0.072310,0.000000
74.510002,13.194275,-59.648956,0.022269,0.002831,0.071919,58.691067,2.989866,0.719191,-59.648956,0.072977,0.000000
74.910004,13.304497,-59.648956,0.022308,0.002858,0.072605,59.181358,3.014842,0.726049,-59.648956,0.073637,0.000000
75.310005,13.271729,-59.648956,0.022308,0.002879,0.073133,59.035599,3.007416,0.731333,-59.648956,0.074305,0.000000
75.710007,13.566650,-59.648956,0.022334,0.002908,0.073863,60.347473,3.074247,0.738630,-59.648956,0.074973,0.000000
76.110001,13.705170,-59.648956,0.022360,0.002931,0.074443,60.963638,3.105636,0.744428,-59.648956,0.075640,0.000000
76.510002,13.841087,-59.737919,0.022381,0.002962,0.075233,61.568230,3.136435,0.752331,-59.737919,0.076308,0.000000
76.910004,13.923378,-59.648956,0.022398,0.002984,0.075796,61.934280,3.155083,0.757963,-59.648956,0.076976,0.000000
77.310005,14.136002,-59.693436,0.022446,0.003013,0.076525,62.880077,3.203264,0.765245,-59.693436,0.077643,0.000000
77.710007,14.430176,-59.693436,0.022472,0.003039,0.077201,64.188629,3.269925,0.772013,-59.693436,0.078311,0.000000
78.110001,14.500183,-59.737919,0.022497,0.003059,0.077704,64.500038,3.285789,0.777039,-59.737919,0.078970,0.000000
78.510002,14.734779,-59.648956,0.022506,0.003090,0.078485,65.543571,3.338949,0.784851,-59.648956,0.079637,0.000000
78.910004,14.845375,-59.782398,0.022558,0.003116,0.079144,66.035530,3.364010,0.791437,-59.782398,0.080306,0.000000
79.310005,15.005867,-59.648956,0.022566,0.003142,0.079795,66.749428,3.400378,0.797947,-59.648956,0.080974,0.000000
79.710007,15.201363,-59.737919,0.022597,0.003169,0.080505,67.619041,3.444678,0.805047,-59.737919,0.081642,0.000000
80.110001,15.436699,-59.782398,0.022614,0.003198,0.081225,68.665863,3.498006,0.812254,-59.782398,0.082309,0.000000
80.510002,15.632195,-59.693436,0.022661,0.003226,0.081935,69.535477,3.542306,0.819354,-59.693436,0.082977,0.000000
80.910004,15.702950,-59.782398,0.022679,0.003247,0.082474,69.850204,3.558339,0.824744,-59.782398,0.083645,0.000000
81.310005,15.902916,-59.693436,0.022692,0.003277,0.083228,70.739700,3.603652,0.832283,-59.693436,0.084303,0.000000
81.710007,16.082771,-59.826878,0.022722,0.003303,0.083896,71.539742,3.644408,0.838960,-59.826878,0.084971,0.000000
82.110001,16.288315,-59.782398,0.022735,0.003327,0.084503,72.454041,3.690985,0.845031,-59.782398,0.085639,0.000000
82.510002,16.487907,-59.782398,0.022782,0.003357,0.085275,73.341873,3.736213,0.852752,-59.782398,0.086306,0.000000
82.910004,16.563499,-59.782398,0.022812,0.003379,0.085838,73.678123,3.753343,0.858384,-59.782398,0.086975,0.000000
83.310005,16.834961,-59.826878,0.022821,0.003409,0.086585,74.885643,3.814857,0.865848,-59.826878,0.087643,0.000000
83.710007,16.827141,-59.826878,0.022851,0.003430,0.087113,74.850861,3.813085,0.871131,-59.826878,0.088311,0.000000
84.110001,17.203613,-59.737919,0.022886,0.003459,0.087850,76.525497,3.898395,0.878504,-59.737919,0.088978,0.000000
84.510002,17.282181,-59.782398,0.022903,0.003486,0.088544,76.874977,3.916198,0.885438,-59.782398,0.089637,0.000000
84.910004,17.520500,-59.782398,0.022907,0.003515,0.089290,77.935074,3.970202,0.892902,-59.782398,0.090305,0.000000
85.310005,17.761047,-59.826878,0.022933,0.003540,0.089914,79.005081,4.024711,0.899140,-59.826878,0.090972,0.000000
85.710007,17.763283,-59.782398,0.022993,0.003561,0.090444,79.015030,4.025218,0.904438,-59.782398,0.091640,0.000000
86.110001,18.067139,-59.826878,0.022985,0.003590,0.091198,80.366646,4.094072,0.911978,-59.826878,0.092308,0.000000
86.510002,18.220932,-59.782398,0.023015,0.003620,0.091944,81.050751,4.128922,0.919442,-59.782398,0.092975,0.000000
86.910004,18.353867,-59.826878,0.023054,0.003645,0.092586,81.642075,4.159045,0.925861,-59.826878,0.093644,0.000000
87.310005,18.571335,-59.826878,0.023084,0.003670,0.093228,82.609421,4.208325,0.932280,-59.826878,0.094312,0.000000
87.710007,18.675972,-59.826878,0.023101,0.003691,0.093747,83.074875,4.232036,0.937473,-59.826878,0.094980,0.000000
88.110001,18.986900,-59.871361,0.023144,0.003725,0.094606,84.457954,4.302493,0.946057,-59.871361,0.095638,0.000000
88.510002,19.078506,-59.826878,0.023149,0.003748,0.095187,84.865433,4.323251,0.951871,-59.826878,0.096306,0.000000
88.910004,19.348473,-59.782398,0.023183,0.003779,0.095994,86.066307,4.384427,0.959940,-59.782398,0.096974,0.000000
89.310005,19.408058,-59.871361,0.023218,0.003800,0.096515,86.331352,4.397929,0.965148,-59.871361,0.097641,0.000000
89.710007,19.456093,-59.826878,0.023226,0.003817,0.096957,86.545021,4.408814,0.969569,-59.826878,0.098309,0.000000
90.110001,19.939430,-59.782398,0.023269,0.003859,0.098023,88.695015,4.518340,0.980227,-59.782398,0.098977,0.000000
90.510002,19.939056,-59.871361,0.023287,0.003881,0.098578,88.693352,4.518255,0.985783,-59.871361,0.099644,0.000000
90.910004,20.101410,-59.871361,0.023325,0.003902,0.099099,89.415535,4.555045,0.990991,-59.871361,0.100313,0.000000
91.310005,20.427238,-59.826878,0.023334,0.003932,0.099862,90.864891,4.628878,0.998622,-59.826878,0.100972,0.000000
91.710007,20.420532,-59.871361,0.023377,0.003952,0.100381,90.835068,4.627358,1.003815,-59.871361,0.101640,0.000000
92.110001,20.907227,-59.871361,0.023373,0.003990,0.101353,92.999985,4.737645,1.013534,-59.871361,0.102307,0.000000
92.510002,20.875572,-59.871361,0.023412,0.004010,0.101847,92.859184,4.730472,1.018470,-59.871361,0.102975,0.000000
92.910004,20.881531,-59.915840,0.023412,0.004032,0.102403,92.885689,4.731822,1.024026,-59.915840,0.103643,0.000000
93.310005,21.347000,-59.871361,0.023455,0.004062,0.103175,94.956200,4.837299,1.031747,-59.871361,0.104310,0.000000
93.710007,21.558876,-59.826878,0.023481,0.004087,0.103808,95.898666,4.885311,1.038076,-59.826878,0.104978,0.000000
94.110008,21.859383,-59.871361,0.023519,0.004120,0.104649,97.235390,4.953407,1.046493,-59.871361,0.105646,0.000000
94.510002,21.841133,-59.871361,0.023524,0.004140,0.105161,97.154213,4.949271,1.051610,-59.871361,0.106306,0.000000
94.910004,21.912628,-59.915840,0.023571,0.004160,0.105673,97.472237,4.965473,1.056728,-59.915840,0.106973,0.000000
95.310005,22.321495,-59.915840,0.023571,0.004192,0.106487,99.290970,5.058123,1.064873,-59.915840,0.107641,0.000000
95.710007,22.644714,-59.915840,0.023588,0.004220,0.107199,100.728722,5.131366,1.071988,-59.915840,0.108309,0.000000
96.110008,22.792549,-59.871361,0.023640,0.004249,0.107927,101.386322,5.164865,1.079270,-59.871361,0.108976,0.000000
96.510002,22.791061,-59.960323,0.023666,0.004270,0.108464,101.379707,5.164528,1.084645,-59.960323,0.109644,0.000000
96.910004,23.054695,-59.915840,0.023679,0.004295,0.109097,102.552406,5.224269,1.090973,-59.915840,0.110312,0.000000
97.310005,23.189499,-59.871361,0.023722,0.004318,0.109679,103.152046,5.254816,1.096787,-59.871361,0.110979,0.000000
97.710007,23.689224,-59.915840,0.023756,0.004352,0.110537,105.374931,5.368055,1.105371,-59.915840,0.111639,0.000000
98.110008,23.827370,-59.915840,0.023782,0.004380,0.111249,105.989433,5.399359,1.112487,-59.915840,0.112307,0.000000
98.510002,23.870193,-59.915840,0.023795,0.004403,0.111838,106.179924,5.409063,1.118376,-59.915840,0.112975,0.000000
98.910004,24.220596,-60.004803,0.023830,0.004429,0.112489,107.738594,5.488465,1.124886,-60.004803,0.113642,0.000000
99.310005,24.324860,-59.871361,0.023847,0.004452,0.113070,108.202377,5.512092,1.130700,-59.871361,0.114310,0.000000
99.710007,24.743782,-59.915840,0.023864,0.004481,0.113807,110.065842,5.607021,1.138072,-59.915840,0.114978,0.000000
100.110008,24.864799,-59.871361,0.023890,0.004507,0.114482,110.604149,5.634444,1.144825,-59.871361,0.115645,0.000000
100.510002,25.033859,-59.871361,0.023916,0.004534,0.115168,111.356171,5.672753,1.151683,-59.871361,0.116313,0.000000
100.910004,25.273293,-59.915840,0.023929,0.004560,0.115827,112.421219,5.727010,1.158269,-59.915840,0.116981,0.000000
101.310005,25.398041,-59.960323,0.023968,0.004583,0.116417,112.976128,5.755278,1.164173,-59.960323,0.117639,0.000000
101.710007,25.908936,-59.960323,0.023985,0.004616,0.117258,115.248703,5.871049,1.172576,-59.960323,0.118308,0.000000
102.110008,25.883987,-59.915840,0.024007,0.004638,0.117813,115.137726,5.865395,1.178132,-59.915840,0.118976,0.000000
102.510002,26.276093,-59.960323,0.024045,0.004668,0.118560,116.881897,5.954247,1.185596,-59.960323,0.119644,0.000000
102.910004,26.435471,-59.960323,0.024058,0.004692,0.119183,117.590843,5.990363,1.191833,-59.960323,0.120311,0.000000
103.310005,26.756828,-59.960323,0.024114,0.004720,0.119877,119.020317,6.063184,1.198767,-59.960323,0.120979,0.000000
103.710007,26.999985,-59.960323,0.024101,0.004749,0.120614,120.101929,6.118284,1.206140,-59.960323,0.121647,0.000000
104.110008,26.979874,-59.960323,0.024145,0.004772,0.121212,120.012474,6.113727,1.212120,-59.960323,0.122314,0.000000
104.510002,27.187660,-59.960323,0.024157,0.004794,0.121768,120.936752,6.160812,1.217676,-59.960323,0.122973,0.000000
104.910004,27.539925,-60.004803,0.024192,0.004823,0.122496,122.503700,6.240636,1.224959,-60.004803,0.123640,0.000000
105.310005,27.628548,-59.960323,0.024231,0.004842,0.122991,122.897919,6.260718,1.229909,-59.960323,0.124308,0.000000
105.710007,28.219879,-59.915840,0.024252,0.004880,0.123961,125.528290,6.394716,1.239614,-59.915840,0.124977,0.000000
106.110008,28.291748,-60.004803,0.024274,0.004902,0.124517,125.847984,6.411002,1.245170,-60.004803,0.125645,0.000000
106.510002,28.394516,-60.004803,0.024295,0.004927,0.125133,126.305115,6.434289,1.251332,-60.004803,0.126313,0.000000
106.910004,28.748642,-59.960323,0.024317,0.004953,0.125817,127.880348,6.514535,1.258175,-59.960323,0.126980,0.000000
107.310005,28.980637,-59.915840,0.024326,0.004975,0.126364,128.912308,6.567106,1.263640,-59.915840,0.127648,0.000000
107.710007,29.538445,-59.960323,0.024360,0.005012,0.127309,131.393570,6.693507,1.273087,-59.960323,0.128306,0.000000
108.110008,29.532120,-59.960323,0.024377,0.005034,0.127855,131.365433,6.692074,1.278553,-59.960323,0.128974,0.000000
108.510002,29.804321,-59.915840,0.024416,0.005061,0.128541,132.576248,6.753756,1.285411,-59.915840,0.129642,0.000000
108.910004,29.959229,-59.960323,0.024442,0.005084,0.129130,133.265305,6.788858,1.291300,-59.960323,0.130309,0.000000
109.310005,30.518532,-60.004803,0.024455,0.005117,0.129963,135.753204,6.915598,1.299627,-60.004803,0.130977,0.000000
109.710007,30.513687,-59.960323,0.024494,0.005139,0.130518,135.731659,6.914500,1.305183,-59.960323,0.131646,0.000000
110.110008,30.705093,-60.004803,0.024494,0.005164,0.131160,136.583084,6.957874,1.311602,-60.004803,0.132314,0.000000
110.510002,31.013786,-60.004803,0.024550,0.005191,0.131854,137.956207,7.027824,1.318536,-60.004803,0.132982,0.000000
110.910004,31.131828,-60.004803,0.024554,0.005215,0.132461,138.481293,7.054574,1.324607,-60.004803,0.133640,0.000000
111.310005,31.722038,-59.960323,0.024545,0.005246,0.133259,141.106674,7.188316,1.332586,-59.960323,0.134308,0.000000
111.710007,31.953651,-60.004803,0.024606,0.005274,0.133952,142.136948,7.240801,1.339520,-60.004803,0.134975,0.000000
112.110008,31.981583,-59.960323,0.024645,0.005292,0.134429,142.261185,7.247130,1.344289,-59.960323,0.135643,0.000000
112.510002,32.458221,-59.960323,0.024649,0.005323,0.135201,144.381378,7.355138,1.352010,-59.960323,0.136311,0.000000
112.910004,32.581848,-60.004803,0.024671,0.005344,0.135738,144.931305,7.383152,1.357384,-60.004803,0.136978,0.000000
113.310005,33.147110,-59.960323,0.024709,0.005380,0.136650,147.445709,7.511242,1.366498,-59.960323,0.137646,0.000000
113.710007,33.126625,-60.004803,0.024718,0.005402,0.137213,147.354584,7.506601,1.372130,-60.004803,0.138315,0.000000
114.110008,33.438301,-59.960323,0.024748,0.005426,0.137820,148.740997,7.577228,1.378201,-59.960323,0.138983,0.000000
114.510002,33.793549,-60.004803,0.024774,0.005456,0.138592,150.321213,7.657728,1.385923,-60.004803,0.139641,0.000000
114.910004,33.758919,-60.004803,0.024774,0.005473,0.139009,150.167175,7.649880,1.390086,-60.004803,0.140309,0.000000
115.310005,34.443336,-60.004803,0.024796,0.005511,0.139979,153.211609,7.804972,1.399790,-60.004803,0.140977,0.000000
115.710007,34.500679,-60.004803,0.024826,0.005532,0.140516,153.466690,7.817966,1.405165,-60.004803,0.141644,0.000000
116.110008,34.533821,-60.049282,0.024882,0.005554,0.141072,153.614105,7.825476,1.410721,-60.049282,0.142312,0.000000
116.510002,35.015305,-60.004803,0.024877,0.005582,0.141793,155.755859,7.934581,1.417928,-60.004803,0.142980,0.000000
116.910004,35.223831,-60.004803,0.024916,0.005606,0.142391,156.683426,7.981834,1.423908,-60.004803,0.143647,0.000000
117.310005,35.754837,-59.960323,0.024946,0.005638,0.143205,159.045456,8.102162,1.432053,-59.960323,0.144315,0.000000
117.710007,35.966713,-60.004803,0.024964,0.005664,0.143865,159.987930,8.150173,1.438654,-60.004803,0.144975,0.000000
118.110008,36.143219,-60.049282,0.024977,0.005688,0.144463,160.773071,8.190170,1.444634,-60.049282,0.145643,0.000000
118.510002,36.456383,-60.004803,0.024985,0.005712,0.145096,162.166092,8.261135,1.450962,-60.004803,0.146310,0.000000
118.910004,36.952011,-60.093765,0.025037,0.005741,0.145834,164.370758,8.373446,1.458335,-60.093765,0.146978,0.000000
119.310005,37.183250,-60.004803,0.025059,0.005769,0.146527,165.399353,8.425845,1.465269,-60.004803,0.147646,0.000000
119.710007,37.446152,-60.049282,0.025067,0.005796,0.147220,166.568802,8.485419,1.472203,-60.049282,0.148313,0.000000
120.110008,37.535889,-60.049282,0.025102,0.005819,0.147802,166.967972,8.505754,1.478017,-60.049282,0.148981,0.000000
120.510002,37.913849,-60.049282,0.025136,0.005843,0.148409,168.649216,8.591401,1.484088,-60.049282,0.149649,0.000000
120.910004,38.225525,-60.049282,0.025158,0.005865,0.148964,170.035629,8.662027,1.489644,-60.049282,0.150309,0.000000
121.310005,38.860794,-60.004803,0.025188,0.005901,0.149874,172.861450,8.805982,1.498743,-60.004803,0.150976,0.000000
121.710007,38.953514,-60.004803,0.025214,0.005923,0.150439,173.273880,8.826992,1.504390,-60.004803,0.151644,0.000000
122.110008,39.565323,-60.049282,0.025218,0.005955,0.151253,175.995346,8.965631,1.512535,-60.049282,0.152312,0.000000
122.510002,39.475204,-60.004803,0.025231,0.005974,0.151730,175.594482,8.945210,1.517304,-60.004803,0.152979,0.000000
122.910004,40.004349,-59.960323,0.025270,0.006003,0.152484,177.948227,9.065115,1.524843,-59.960323,0.153647,0.000000
123.310005,40.231125,-60.049282,0.025278,0.006030,0.153161,178.956985,9.116504,1.531611,-60.049282,0.154315,0.000000
123.710007,40.670891,-60.049282,0.025304,0.006057,0.153854,180.913162,9.216156,1.538545,-60.049282,0.154982,0.000000
124.110008,40.972145,-60.093765,0.025343,0.006084,0.154531,182.253204,9.284421,1.545312,-60.093765,0.155641,0.000000
124.510002,41.179558,-60.049282,0.025356,0.006105,0.155069,183.175827,9.331422,1.550687,-60.049282,0.156310,0.000000
124.910004,41.802536,-60.093765,0.025382,0.006138,0.155910,185.946960,9.472589,1.559104,-60.093765,0.156978,0.000000
125.310005,41.939194,-60.049282,0.025412,0.006161,0.156483,186.554855,9.503557,1.564827,-60.049282,0.157645,0.000000
125.710007,42.285126,-60.093765,0.025429,0.006187,0.157150,188.093628,9.581946,1.571504,-60.093765,0.158313,0.000000
126.110008,42.714104,-60.049282,0.025477,0.006215,0.157862,190.001816,9.679154,1.578619,-60.049282,0.158981,0.000000
126.510010,42.591965,-60.049282,0.025481,0.006231,0.158260,189.458527,9.651477,1.582601,-60.049282,0.159648,0.000000
126.910004,43.716904,-60.138245,0.025503,0.006269,0.159241,194.462494,9.906392,1.592411,-60.138245,0.160316,0.000000
127.310005,43.767914,-60.093765,0.025524,0.006294,0.159865,194.689407,9.917952,1.598649,-60.093765,0.160984,0.000000
127.710007,44.034904,-60.049282,0.025563,0.006315,0.160411,195.877045,9.978452,1.604114,-60.049282,0.161642,0.000000
128.110001,44.624748,-60.093765,0.025576,0.006345,0.161165,198.500793,10.112112,1.611654,-60.093765,0.162310,0.000000
128.510010,44.540215,-60.093765,0.025623,0.006360,0.161556,198.124771,10.092957,1.615560,-60.093765,0.162979,0.000000
128.910004,45.561264,-60.093765,0.025610,0.006400,0.162570,202.666626,10.324330,1.625703,-60.093765,0.163647,0.000000
129.310013,45.832718,-60.049282,0.025658,0.006424,0.163177,203.874115,10.385842,1.631774,-60.049282,0.164314,0.000000
129.710007,46.319038,-60.049282,0.025658,0.006454,0.163933,206.037369,10.496044,1.639329,-60.049282,0.164982,0.000000
130.110001,46.694016,-60.093765,0.025684,0.006477,0.164513,207.705353,10.581015,1.645127,-60.093765,0.165650,0.000000
130.510010,47.238800,-60.093765,0.025718,0.006505,0.165233,210.128677,10.704465,1.652334,-60.093765,0.166317,0.000000
130.910004,47.756767,-60.093765,0.025740,0.006534,0.165971,212.432709,10.821838,1.659707,-60.093765,0.166976,0.000000
131.310013,47.895668,-60.093765,0.025766,0.006555,0.166490,213.050568,10.853313,1.664900,-60.093765,0.167644,0.000000
131.710007,48.745422,-60.093765,0.025800,0.006585,0.167271,216.830475,11.045871,1.672712,-60.093765,0.168311,0.000000
132.110001,48.832924,-60.138245,0.025796,0.006606,0.167792,217.219696,11.065699,1.677920,-60.138245,0.168979,0.000000
132.510010,49.799980,-60.093765,0.025848,0.006639,0.168641,221.521378,11.284837,1.686413,-60.093765,0.169647,0.000000
132.910004,50.009254,-60.093765,0.025878,0.006662,0.169214,222.452271,11.332259,1.692136,-60.093765,0.170316,0.000000
133.310013,50.357788,-60.138245,0.025891,0.006686,0.169821,224.002625,11.411238,1.698207,-60.138245,0.170983,0.000000
133.710007,50.995293,-60.049282,0.025908,0.006713,0.170506,226.838394,11.555698,1.705065,-60.049282,0.171651,0.000000
134.110001,51.305855,-60.138245,0.025938,0.006732,0.171000,228.219833,11.626073,1.710000,-60.138245,0.172310,0.000000
134.510010,52.189117,-60.182728,0.025951,0.006765,0.171833,232.148788,11.826222,1.718327,-60.182728,0.172977,0.000000
134.910004,52.678413,-60.182728,0.025986,0.006792,0.172519,234.325287,11.937099,1.725185,-60.182728,0.173645,0.000000
135.310013,53.132713,-60.138245,0.025998,0.006814,0.173073,236.346115,12.040045,1.730726,-60.138245,0.174313,0.000000
135.710007,53.869637,-60.182728,0.026037,0.006842,0.173775,239.624115,12.207034,1.737751,-60.182728,0.174980,0.000000
136.110001,54.441971,-60.182728,0.026042,0.006866,0.174408,242.169983,12.336727,1.744080,-60.182728,0.175648,0.000000
136.510010,55.067558,-60.138245,0.026072,0.006892,0.175050,244.952728,12.478487,1.750499,-60.138245,0.176316,0.000000
136.910004,55.907257,-60.138245,0.026111,0.006922,0.175831,248.687897,12.668766,1.758311,-60.138245,0.176985,0.000000
137.310013,56.498955,-60.138245,0.026111,0.006946,0.176429,251.319901,12.802846,1.764291,-60.138245,0.177643,0.000000
137.710007,57.365097,-60.182728,0.026128,0.006974,0.177141,255.172699,12.999116,1.771407,-60.182728,0.178311,0.000000
138.110001,57.733376,-60.182728,0.026145,0.006994,0.177643,256.810883,13.082570,1.776433,-60.182728,0.178979,0.000000
138.510010,58.976723,-60.182728,0.026180,0.007025,0.178441,262.341553,13.364317,1.784411,-60.182728,0.179646,0.000000
138.910004,59.747536,-60.227207,0.026210,0.007054,0.179178,265.770325,13.538985,1.791784,-60.227207,0.180314,0.000000
139.310013,60.103523,-60.182728,0.026240,0.007077,0.179751,267.353821,13.619653,1.797507,-60.182728,0.180982,0.000000
139.710007,61.138718,-60.182728,0.026231,0.007105,0.180462,271.958588,13.854231,1.804623,-60.182728,0.181649,0.000000
140.110001,61.826866,-60.182728,0.026236,0.007128,0.181042,275.019623,14.010168,1.810421,-60.182728,0.182317,0.000000
140.510010,62.879936,-60.182728,0.026270,0.007160,0.181858,279.703918,14.248797,1.818581,-60.182728,0.182985,0.000000
140.910004,63.511101,-60.227207,0.026305,0.007183,0.182440,282.511475,14.391821,1.824395,-60.227207,0.183645,0.000000
141.310013,64.440544,-60.138245,0.026318,0.007209,0.183098,286.645844,14.602436,1.830981,-60.138245,0.184312,0.000000
141.710007,65.647026,-60.227207,0.026348,0.007235,0.183766,292.012543,14.875829,1.837657,-60.227207,0.184980,0.000000
142.110001,65.934502,-60.182728,0.026348,0.007255,0.184287,293.291321,14.940971,1.842865,-60.182728,0.185648,0.000000
142.510010,67.348030,-60.227207,0.026374,0.007272,0.184720,299.579010,15.261282,1.847195,-60.227207,0.184989,0.000000
142.910004,66.462151,-60.227207,0.026425,0.007266,0.184547,295.638397,15.060539,1.845469,-60.227207,0.184720,0.000000
143.310013,65.945305,-60.182728,0.026399,0.007264,0.184503,293.339355,14.943420,1.845030,-60.182728,0.184720,0.000000
143.710007,65.546486,-60.227207,0.026404,0.007264,0.184503,291.565338,14.853046,1.845030,-60.227207,0.184720,0.000000
144.110001,65.241142,-60.227207,0.026391,0.007264,0.184503,290.207092,14.783854,1.845030,-60.227207,0.184720,0.000000
144.510010,64.975273,-60.227207,0.026408,0.007264,0.184503,289.024445,14.723607,1.845030,-60.227207,0.184720,0.000000
144.910004,64.768227,-60.271690,0.026430,0.007264,0.184503,288.103455,14.676690,1.845030,-60.271690,0.184720,0.000000
145.310013,64.582420,-60.227207,0.026417,0.007264,0.184503,287.276947,14.634586,1.845030,-60.227207,0.184720,0.000000
145.710007,64.406288,-60.227207,0.026417,0.007264,0.184503,286.493469,14.594674,1.845030,-60.227207,0.184720,0.000000
146.110001,64.241325,-60.316170,0.026425,0.007264,0.184503,285.759674,14.557293,1.845030,-60.316170,0.184720,0.000000
146.510010,64.119194,-60.227207,0.026430,0.007264,0.184503,285.216431,14.529616,1.845030,-60.227207,0.184720,0.000000
146.910004,63.980293,-60.316170,0.026421,0.007264,0.184503,284.598572,14.498142,1.845030,-60.316170,0.184720,0.000000
147.310013,63.858528,-60.271690,0.026434,0.007264,0.184503,284.056915,14.470550,1.845030,-60.271690,0.184720,0.000000
147.710007,63.748299,-60.227207,0.026412,0.007264,0.184503,283.566589,14.445571,1.845030,-60.227207,0.184720,0.000000
148.110001,63.659309,-60.271690,0.026395,0.007264,0.184503,283.170746,14.425406,1.845030,-60.271690,0.184720,0.000000
148.510010,63.560631,-60.227207,0.026408,0.007264,0.184503,282.731812,14.403045,1.845030,-60.227207,0.184720,0.000000
148.910004,63.468285,-60.271690,0.026412,0.007264,0.184503,282.321045,14.382119,1.845030,-60.271690,0.184720,0.000000
149.310013,63.387474,-60.227207,0.026421,0.007264,0.184503,281.961578,14.363807,1.845030,-60.227207,0.184720,0.000000
149.710007,63.320076,-60.271690,0.026421,0.007264,0.184503,281.661774,14.348535,1.845030,-60.271690,0.184720,0.000000
150.110001,63.242989,-60.227207,0.026421,0.007264,0.184503,281.318878,14.331066,1.845030,-60.227207,0.184720,0.000000
150.510010,63.170387,-60.316170,0.026434,0.007264,0.184503,280.995911,14.314614,1.845030,-60.316170,0.184720,0.000000
150.910004,63.106339,-60.271690,0.026408,0.007264,0.184503,280.710999,14.300101,1.845030,-60.271690,0.184720,0.000000
151.310013,63.047127,-60.271690,0.026425,0.007264,0.184503,280.447632,14.286683,1.845030,-60.271690,0.184720,0.000000
151.710007,62.977867,-60.316170,0.026425,0.007264,0.184503,280.139557,14.270988,1.845030,-60.316170,0.184720,0.000000
152.110001,62.924248,-60.271690,0.026425,0.007264,0.184503,279.901031,14.258839,1.845030,-60.271690,0.184720,0.000000
152.510010,62.872482,-60.271690,0.026404,0.007264,0.184503,279.670776,14.247108,1.845030,-60.271690,0.184720,0.000000
152.910004,62.811043,-60.271690,0.026425,0.007264,0.184503,279.397461,14.233186,1.845030,-60.271690,0.184720,0.000000
153.310013,62.762260,-60.227207,0.026430,0.007264,0.184503,279.180481,14.222131,1.845030,-60.227207,0.184720,0.000000
153.710007,62.709389,-60.227207,0.026404,0.007264,0.184503,278.945282,14.210151,1.845030,-60.227207,0.184720,0.000000
154.110001,62.664703,-60.271690,0.026438,0.007264,0.184503,278.746521,14.200026,1.845030,-60.271690,0.184720,0.000000
154.510010,62.646454,-60.271690,0.026417,0.007264,0.184503,278.665344,14.195889,1.845030,-60.271690,0.184720,0.000000
154.910004,62.589485,-60.271690,0.026421,0.007264,0.184503,278.411926,14.182981,1.845030,-60.271690,0.184720,0.000000
155.310013,62.529160,-60.271690,0.026404,0.007264,0.184503,278.143585,14.169311,1.845030,-60.271690,0.184720,0.000000
155.710007,62.500854,-60.316170,0.026417,0.007264,0.184503,278.017700,14.162896,1.845030,-60.316170,0.184720,0.000000
156.110001,62.452820,-60.316170,0.026417,0.007264,0.184503,277.804016,14.152011,1.845030,-60.316170,0.184720,0.000000
156.510010,62.421173,-60.316170,0.026412,0.007264,0.184503,277.663239,14.144840,1.845030,-60.316170,0.184720,0.000000
156.910004,62.374252,-60.360649,0.026412,0.007264,0.184503,277.454529,14.134208,1.845030,-60.360649,0.184720,0.000000
157.310013,62.344086,-60.316170,0.026430,0.007264,0.184503,277.320343,14.127372,1.845030,-60.316170,0.184720,0.000000
157.710007,62.306107,-60.271690,0.026421,0.007264,0.184503,277.151398,14.118765,1.845030,-60.271690,0.184720,0.000000
158.110001,62.263657,-60.316170,0.026430,0.007264,0.184503,276.962585,14.109147,1.845030,-60.316170,0.184720,0.000000
158.510010,62.242058,-60.316170,0.026417,0.007264,0.184503,276.866486,14.104252,1.845030,-60.316170,0.184720,0.000000
158.910004,62.189178,-60.271690,0.026412,0.007264,0.184494,276.631287,14.092269,1.844939,-60.271690,0.184720,0.000000
159.310013,62.153809,-60.316170,0.026421,0.007264,0.184494,276.473938,14.084254,1.844939,-60.316170,0.184720,0.000000
159.710007,62.117683,-60.271690,0.026412,0.007264,0.184494,276.313263,14.076069,1.844939,-60.271690,0.184720,0.000000
160.110001,62.077843,-60.360649,0.026421,0.007264,0.184494,276.136047,14.067040,1.844939,-60.360649,0.184720,0.000000
160.510010,62.053635,-60.316170,0.026434,0.007264,0.184494,276.028351,14.061555,1.844939,-60.316170,0.184720,0.000000
160.910004,62.029808,-60.316170,0.026404,0.007264,0.184494,275.922363,14.056155,1.844939,-60.316170,0.184720,0.000000
161.310013,61.995918,-60.316170,0.026417,0.007264,0.184494,275.771606,14.048475,1.844939,-60.316170,0.184720,0.000000
161.710007,61.967995,-60.316170,0.026425,0.007264,0.184494,275.647400,14.042148,1.844939,-60.316170,0.184720,0.000000
162.110001,61.940063,-60.316170,0.026430,0.007264,0.184494,275.523163,14.035819,1.844939,-60.316170,0.184720,0.000000
162.510010,61.930756,-60.360649,0.026438,0.007264,0.184494,275.481750,14.033710,1.844939,-60.360649,0.184720,0.000000
162.910004,61.899101,-60.360649,0.026425,0.007264,0.184494,275.340942,14.026537,1.844939,-60.360649,0.184720,0.000000
163.310013,61.868942,-60.316170,0.026421,0.007264,0.184494,275.206787,14.019703,1.844939,-60.316170,0.184720,0.000000
163.710007,61.849579,-60.360649,0.026434,0.007264,0.184494,275.120667,14.015315,1.844939,-60.360649,0.184720,0.000000
164.110001,61.811600,-60.316170,0.026430,0.007264,0.184494,274.951721,14.006708,1.844939,-60.316170,0.184720,0.000000
164.510010,61.782181,-60.316170,0.026412,0.007264,0.184494,274.820862,14.000042,1.844939,-60.316170,0.184720,0.000000
164.910004,61.763931,-60.271690,0.026417,0.007264,0.184494,274.739685,13.995907,1.844939,-60.271690,0.184720,0.000000
165.310013,61.760208,-60.316170,0.026434,0.007264,0.184494,274.723114,13.995063,1.844939,-60.316170,0.184720,0.000000
165.710007,61.725578,-60.360649,0.026412,0.007264,0.184494,274.569092,13.987216,1.844939,-60.360649,0.184720,0.000000
166.110001,61.711426,-60.316170,0.026434,0.007264,0.184494,274.506134,13.984009,1.844939,-60.316170,0.184720,0.000000
166.510010,61.686852,-60.360649,0.026430,0.007264,0.184494,274.396820,13.978440,1.844939,-60.360649,0.184720,0.000000
166.910004,61.657806,-60.360649,0.026430,0.007264,0.184494,274.267609,13.971858,1.844939,-60.360649,0.184720,0.000000
167.310013,61.645149,-60.360649,0.026425,0.007264,0.184494,274.211304,13.968990,1.844939,-60.360649,0.184720,0.000000
167.710007,61.627647,-60.360649,0.026430,0.007264,0.184494,274.133453,13.965024,1.844939,-60.360649,0.184720,0.000000
168.110001,61.594131,-60.316170,0.026430,0.007264,0.184494,273.984375,13.957430,1.844939,-60.316170,0.184720,0.000000
168.510010,61.592644,-60.316170,0.026447,0.007264,0.184494,273.977753,13.957092,1.844939,-60.316170,0.184720,0.000000
168.910004,61.552055,-60.316170,0.026438,0.007264,0.184494,273.797211,13.947895,1.844939,-60.316170,0.184720,0.000000
169.310013,61.556892,-60.360649,0.026430,0.007264,0.184494,273.818726,13.948992,1.844939,-60.360649,0.184720,0.000000
169.710007,61.528221,-60.316170,0.026451,0.007264,0.184494,273.691193,13.942494,1.844939,-60.316170,0.184720,0.000000
170.110001,61.497314,-60.360649,0.026425,0.007264,0.184494,273.553711,13.935491,1.844939,-60.360649,0.184720,0.000000
170.510010,61.492844,-60.316170,0.026447,0.007264,0.184494,273.533844,13.934477,1.844939,-60.316170,0.184720,0.000000
170.910004,61.471992,-60.316170,0.026412,0.007264,0.184494,273.441071,13.929752,1.844939,-60.316170,0.184720,0.000000
171.310013,61.455238,-60.360649,0.026438,0.007264,0.184494,273.366547,13.925956,1.844939,-60.360649,0.184720,0.000000
171.710007,61.451141,-60.360649,0.026434,0.007264,0.184494,273.348328,13.925027,1.844939,-60.360649,0.184720,0.000000
172.110001,61.419861,-60.360649,0.026438,0.007264,0.184494,273.209198,13.917940,1.844939,-60.360649,0.184720,0.000000
172.510010,61.400124,-60.316170,0.026443,0.007264,0.184494,273.121399,13.913466,1.844939,-60.316170,0.184720,0.000000
172.900009,61.382996,-60.405132,0.026430,0.007264,0.184494,273.045197,13.909586,1.844939,-60.405132,0.184720,0.000000