File: Data/New old I18 2_08182023_115420.csv
Time (sec),S:Load (lbs),S:HL1 (DIM),S:LVDT (in),S:Position (in),Ch:Position (mm),Ch:Load (N),Ch:Stress (MPa),Ch:Strain (mm/mm),Ch:HL1 (DIM),Set Point (),Cycles ()
0.110000,-0.097931,-15.301447,0.000034,-0.019702,-0.500424,-0.435618,-0.022191,-5.004237,-15.301447,-0.500233,0.000000
0.460000,-0.064041,-15.345928,0.000047,-0.019670,-0.499626,-0.284869,-0.014512,-4.996258,-15.345928,-0.498966,0.000000
0.810000,-0.064415,-15.345928,0.000056,-0.019464,-0.494388,-0.286532,-0.014597,-4.943875,-15.345928,-0.493138,0.000000
1.160000,-0.087875,-15.390409,0.000047,-0.019228,-0.488386,-0.390889,-0.019913,-4.883862,-15.390409,-0.487311,0.000000
1.510000,-0.095322,-15.345928,0.000052,-0.019001,-0.482636,-0.424012,-0.021600,-4.826362,-15.345928,-0.481483,0.000000
1.860000,-0.113945,-15.390409,0.000047,-0.018773,-0.476826,-0.506853,-0.025820,-4.768256,-15.390409,-0.475655,0.000000
2.210000,-0.095695,-15.434890,0.000060,-0.018544,-0.471015,-0.425675,-0.021685,-4.710150,-15.434890,-0.469810,0.000000
2.560000,-0.062553,-15.434890,0.000043,-0.018323,-0.465413,-0.278251,-0.014175,-4.654134,-15.434890,-0.463983,0.000000
2.910000,-0.081177,-15.479371,0.000034,-0.018085,-0.459352,-0.361092,-0.018395,-4.593515,-15.479371,-0.458154,0.000000
3.260000,-0.094948,-15.434890,0.000030,-0.017851,-0.453411,-0.422349,-0.021515,-4.534107,-15.434890,-0.452327,0.000000
3.610000,-0.087502,-15.390409,0.000017,-0.017624,-0.447644,-0.389226,-0.019828,-4.476441,-15.390409,-0.446499,0.000000
3.960000,-0.096809,-15.434890,0.000056,-0.017395,-0.441833,-0.430630,-0.021937,-4.418335,-15.434890,-0.440654,0.000000
4.310000,-0.088249,-15.479371,0.000034,-0.017172,-0.436170,-0.392552,-0.019998,-4.361698,-15.479371,-0.434827,0.000000
4.660000,-0.077820,-15.434890,0.000065,-0.016942,-0.430326,-0.346160,-0.017634,-4.303259,-15.434890,-0.428998,0.000000
5.010000,-0.083038,-15.479371,0.000056,-0.016705,-0.424306,-0.369373,-0.018817,-4.243064,-15.479371,-0.423171,0.000000
5.360000,-0.038727,-15.479371,0.000078,-0.016475,-0.418453,-0.172265,-0.008776,-4.184535,-15.479371,-0.417344,0.000000
5.710000,0.038727,-15.523852,0.000052,-0.016244,-0.412608,0.172265,0.008776,-4.126081,-15.523852,-0.411515,0.000000
6.060000,0.086395,-15.434890,0.000086,-0.016025,-0.407040,0.384305,0.019577,-4.070397,-15.434890,-0.405670,0.000000
6.410000,0.123260,-15.523852,0.000069,-0.015792,-0.401108,0.548290,0.027931,-4.011080,-15.523852,-0.399842,0.000000
6.760000,0.158264,-15.523852,0.000095,-0.015561,-0.395237,0.703994,0.035863,-3.952369,-15.523852,-0.394015,0.000000
7.110000,0.204437,-15.523852,0.000229,-0.015329,-0.389349,0.909382,0.046326,-3.893491,-15.523852,-0.388186,0.000000
7.460001,0.221939,-15.568333,0.000457,-0.015093,-0.383364,0.987234,0.050292,-3.833644,-15.568333,-0.382359,0.000000
7.810000,0.227150,-15.523852,0.000655,-0.014873,-0.377772,1.010414,0.051473,-3.777719,-15.523852,-0.376514,0.000000
8.160001,0.220818,-15.523852,0.000867,-0.014645,-0.371987,0.982246,0.050038,-3.719871,-15.523852,-0.370687,0.000000
8.510000,0.205551,-15.568333,0.001138,-0.014412,-0.366064,0.914337,0.046579,-3.660645,-15.568333,-0.364858,0.000000
8.860001,0.177254,-15.657295,0.001345,-0.014181,-0.360193,0.788464,0.040166,-3.601933,-15.657295,-0.359031,0.000000
9.210000,0.219330,-15.568333,0.001600,-0.013947,-0.354243,0.975628,0.049701,-3.542435,-15.568333,-0.353203,0.000000
9.560000,0.253586,-15.612814,0.001828,-0.013721,-0.348519,1.128006,0.057463,-3.485192,-15.612814,-0.347375,0.000000
9.910001,0.240555,-15.657295,0.002078,-0.013497,-0.342831,1.070041,0.054511,-3.428313,-15.657295,-0.341531,0.000000
10.260000,0.229385,-15.657295,0.002320,-0.013263,-0.336881,1.020357,0.051979,-3.368814,-15.657295,-0.335702,0.000000
10.610001,0.182091,-15.701776,0.002557,-0.013034,-0.331063,0.809980,0.041262,-3.310632,-15.701776,-0.329875,0.000000
10.960001,0.199226,-15.657295,0.002785,-0.012801,-0.325157,0.886203,0.045145,-3.251573,-15.657295,-0.324048,0.000000
11.310000,0.236092,-15.701776,0.003009,-0.012576,-0.319433,1.050188,0.053499,-3.194330,-15.701776,-0.318219,0.000000
11.660001,0.254707,-15.701776,0.003264,-0.012354,-0.313797,1.132995,0.057718,-3.137966,-15.701776,-0.312373,0.000000
12.010000,0.250237,-15.657295,0.003484,-0.012111,-0.307621,1.113108,0.056704,-3.076211,-15.657295,-0.306546,0.000000
12.360001,0.231621,-15.701776,0.003725,-0.011887,-0.301941,1.030301,0.052486,-3.019408,-15.701776,-0.300719,0.000000
12.710001,0.206673,-15.701776,0.003945,-0.011657,-0.296079,0.919326,0.046833,-2.960787,-15.701776,-0.294890,0.000000
13.060000,0.229012,-15.701776,0.004186,-0.011423,-0.290156,1.018694,0.051895,-2.901561,-15.701776,-0.289063,0.000000
13.410001,0.276306,-15.701776,0.004424,-0.011204,-0.284588,1.229071,0.062612,-2.845878,-15.701776,-0.283236,0.000000
13.760000,0.230499,-15.657295,0.004674,-0.010964,-0.278491,1.025312,0.052232,-2.784911,-15.657295,-0.277390,0.000000
14.110001,0.259918,-15.701776,0.004876,-0.010738,-0.272741,1.156174,0.058898,-2.727411,-15.701776,-0.271562,0.000000
14.460001,0.230499,-15.790737,0.005139,-0.010506,-0.266844,1.025312,0.052232,-2.668442,-15.790737,-0.265734,0.000000
14.810000,0.228271,-15.790737,0.005351,-0.010276,-0.261017,1.015402,0.051727,-2.610170,-15.790737,-0.259907,0.000000
15.160001,0.256569,-15.835218,0.005618,-0.010050,-0.255267,1.141276,0.058139,-2.552670,-15.835218,-0.254078,0.000000
15.510001,0.268112,-15.835218,0.005842,-0.009821,-0.249456,1.192623,0.060755,-2.494564,-15.835218,-0.248235,0.000000
15.860001,0.248001,-15.835218,0.006079,-0.009588,-0.243534,1.103164,0.056198,-2.435338,-15.835218,-0.242406,0.000000
16.210001,0.277420,-15.879700,0.006321,-0.009361,-0.237775,1.234026,0.062864,-2.377747,-15.879700,-0.236579,0.000000
16.560001,0.254333,-15.790737,0.006588,-0.009127,-0.231817,1.131332,0.057633,-2.318172,-15.790737,-0.230751,0.000000
16.910002,0.239067,-15.835218,0.006791,-0.008905,-0.226181,1.063424,0.054173,-2.261808,-15.835218,-0.224923,0.000000
17.260000,0.240929,-15.835218,0.007015,-0.008676,-0.220370,1.071704,0.054595,-2.203702,-15.835218,-0.219095,0.000000
17.610001,0.263641,-15.879700,0.007256,-0.008442,-0.214439,1.172735,0.059742,-2.144385,-15.879700,-0.213250,0.000000
17.960001,0.240929,-15.879700,0.007489,-0.008209,-0.208507,1.071704,0.054595,-2.085068,-15.879700,-0.207423,0.000000
18.310001,0.271835,-15.835218,0.007739,-0.007978,-0.202652,1.209184,0.061599,-2.026524,-15.835218,-0.201594,0.000000
18.660002,0.259178,-15.879700,0.007976,-0.007756,-0.197007,1.152882,0.058731,-1.970068,-15.879700,-0.195767,0.000000
19.010000,0.261780,-15.879700,0.008209,-0.007525,-0.191136,1.164455,0.059320,-1.911357,-15.879700,-0.189940,0.000000
19.360001,0.239815,-15.924180,0.008446,-0.007297,-0.185334,1.066749,0.054343,-1.853342,-15.924180,-0.184094,0.000000
19.710001,0.258430,-15.968661,0.008670,-0.007068,-0.179533,1.149556,0.058561,-1.795327,-15.968661,-0.178266,0.000000
20.060001,0.280029,-15.968661,0.008921,-0.006830,-0.173471,1.245633,0.063456,-1.734708,-15.968661,-0.172438,0.000000
20.410002,0.278542,-15.924180,0.009132,-0.006609,-0.167860,1.239015,0.063118,-1.678601,-15.924180,-0.166611,0.000000
20.760000,0.274071,-15.968661,0.009378,-0.006382,-0.162110,1.219128,0.062105,-1.621101,-15.968661,-0.160782,0.000000
21.110001,0.260292,-15.924180,0.009602,-0.006149,-0.156195,1.157837,0.058983,-1.561950,-15.924180,-0.154955,0.000000
21.460001,0.202576,-15.924180,0.009865,-0.005920,-0.150377,0.901102,0.045904,-1.503769,-15.924180,-0.149110,0.000000
21.810001,0.303116,-16.013142,0.010093,-0.005687,-0.144444,1.348327,0.068687,-1.444437,-16.013142,-0.143282,0.000000
22.160002,0.303116,-15.924180,0.010356,-0.005457,-0.138600,1.348327,0.068687,-1.385998,-15.924180,-0.137455,0.000000
22.510000,0.287102,-15.968661,0.010593,-0.005232,-0.132892,1.277092,0.065058,-1.328922,-15.968661,-0.131627,0.000000
22.860001,0.281891,-15.968661,0.010805,-0.004996,-0.126909,1.253913,0.063877,-1.269090,-15.968661,-0.125799,0.000000
23.210001,0.241676,-16.057623,0.011046,-0.004773,-0.121229,1.075030,0.054765,-1.212287,-16.057623,-0.119954,0.000000
23.560001,0.241302,-16.013142,0.011279,-0.004538,-0.115271,1.073367,0.054680,-1.152712,-16.013142,-0.114127,0.000000
23.910002,0.295296,-16.057623,0.011525,-0.004310,-0.109486,1.313541,0.066915,-1.094864,-16.057623,-0.108298,0.000000
24.260000,0.300880,-16.057623,0.011809,-0.004087,-0.103806,1.338383,0.068180,-1.038060,-16.057623,-0.102471,0.000000
24.610001,0.284866,-16.057623,0.012012,-0.003849,-0.097762,1.267149,0.064552,-0.977623,-16.057623,-0.096644,0.000000
24.960001,0.281143,-16.057623,0.012284,-0.003621,-0.091968,1.250587,0.063708,-0.919684,-16.057623,-0.090815,0.000000
25.310001,0.252846,-16.057623,0.012534,-0.003392,-0.086149,1.124714,0.057296,-0.861488,-16.057623,-0.084969,0.000000
25.660002,0.276306,-16.102104,0.012758,-0.003158,-0.080217,1.229071,0.062612,-0.802171,-16.102104,-0.079142,0.000000
26.010002,0.323967,-16.057623,0.012999,-0.002940,-0.074685,1.441077,0.073412,-0.746851,-16.057623,-0.073315,0.000000
26.360001,0.296410,-16.146585,0.013236,-0.002704,-0.068693,1.318496,0.067167,-0.686928,-16.146585,-0.067486,0.000000
26.710001,0.284866,-16.102104,0.013495,-0.002474,-0.062829,1.267149,0.064552,-0.628293,-16.102104,-0.061659,0.000000
27.060001,0.280403,-16.146585,0.013706,-0.002245,-0.057028,1.247295,0.063540,-0.570278,-16.146585,-0.055814,0.000000
27.410002,0.282265,-16.146585,0.013969,-0.002012,-0.051105,1.255576,0.063962,-0.511052,-16.146585,-0.049986,0.000000
27.760002,0.287849,-16.191067,0.014176,-0.001788,-0.045407,1.280418,0.065228,-0.454066,-16.191067,-0.044159,0.000000
28.110001,0.315773,-16.146585,0.014452,-0.001558,-0.039570,1.404629,0.071555,-0.395703,-16.146585,-0.038330,0.000000
28.460001,0.291573,-16.191067,0.014702,-0.001325,-0.033648,1.296980,0.066071,-0.336477,-16.191067,-0.032503,0.000000
28.810001,0.278542,-16.235548,0.014918,-0.001092,-0.027733,1.239015,0.063118,-0.277327,-16.235548,-0.026658,0.000000
29.160002,0.307213,-16.146585,0.015146,-0.000863,-0.021922,1.366551,0.069615,-0.219221,-16.146585,-0.020831,0.000000
29.510002,0.313171,-16.191067,0.015362,-0.000645,-0.016381,1.393056,0.070966,-0.163810,-16.191067,-0.015002,0.000000
29.860001,0.306465,-16.191067,0.015629,-0.000410,-0.010415,1.363225,0.069446,-0.104145,-16.191067,-0.009175,0.000000
30.210001,0.271835,-16.235548,0.015884,-0.000178,-0.004527,1.209184,0.061599,-0.045267,-16.235548,-0.003347,0.000000
30.560001,0.290451,-16.235548,0.016112,0.000050,0.001276,1.291991,0.065817,0.012763,-16.235548,0.002481,0.000000
30.910002,0.328438,-16.191067,0.016345,0.000286,0.007259,1.460964,0.074425,0.072594,-16.191067,0.008327,0.000000
31.260002,0.322479,-16.280027,0.016582,0.000507,0.012888,1.434459,0.073075,0.128883,-16.280027,0.014154,0.000000
31.610001,0.308701,-16.280027,0.016806,0.000738,0.018741,1.373169,0.069953,0.187413,-16.280027,0.019981,0.000000
31.960001,0.293808,-16.235548,0.017061,0.000968,0.024578,1.306923,0.066578,0.245776,-16.235548,0.025810,0.000000
32.310001,0.259544,-16.324509,0.017293,0.001199,0.030458,1.154511,0.058814,0.304578,-16.324509,0.031637,0.000000
32.660000,0.312798,-16.324509,0.017548,0.001434,0.036415,1.391393,0.070881,0.364152,-16.324509,0.037483,0.000000
33.010002,0.340355,-16.324509,0.017768,0.001654,0.042018,1.513974,0.077126,0.420184,-16.324509,0.043310,0.000000
33.360001,0.335510,-16.324509,0.018018,0.001886,0.047915,1.492424,0.076028,0.479153,-16.324509,0.049137,0.000000
33.710003,0.307587,-16.324509,0.018268,0.002116,0.053742,1.368214,0.069700,0.537425,-16.324509,0.054966,0.000000
34.060001,0.274071,-16.324509,0.018492,0.002348,0.059639,1.219128,0.062105,0.596393,-16.324509,0.060793,0.000000
34.410000,0.280029,-16.413471,0.018755,0.002582,0.065580,1.245633,0.063456,0.655801,-16.413471,0.066622,0.000000
34.760002,0.328064,-16.413471,0.018975,0.002808,0.071312,1.459301,0.074340,0.713120,-16.413471,0.072466,0.000000
35.110001,0.334023,-16.324509,0.019225,0.003029,0.076924,1.485806,0.075691,0.769242,-16.324509,0.078294,0.000000
35.460003,0.329552,-16.324509,0.019471,0.003269,0.083021,1.465919,0.074677,0.830209,-16.324509,0.084122,0.000000
35.810001,0.313171,-16.368990,0.019691,0.003493,0.088735,1.393056,0.070966,0.887346,-16.368990,0.089949,0.000000
36.160000,0.309814,-16.413471,0.019928,0.003724,0.094598,1.378124,0.070205,0.945982,-16.413471,0.095778,0.000000
36.510002,0.301994,-16.368990,0.020195,0.003959,0.100546,1.343338,0.068433,1.005465,-16.368990,0.101623,0.000000
36.860001,0.365677,-16.413471,0.020393,0.004178,0.106122,1.626612,0.082864,1.061224,-16.413471,0.107450,0.000000
37.210003,0.323967,-16.413471,0.020648,0.004418,0.112212,1.441077,0.073412,1.122115,-16.413471,0.113277,0.000000
37.560001,0.348915,-16.413471,0.020868,0.004644,0.117952,1.552052,0.079065,1.179525,-16.413471,0.119106,0.000000
37.910004,0.329552,-16.368990,0.021139,0.004875,0.123824,1.465919,0.074677,1.238236,-16.368990,0.124933,0.000000
38.260002,0.312798,-16.413471,0.021381,0.005102,0.129599,1.391393,0.070881,1.295993,-16.413471,0.130761,0.000000
38.610001,0.387268,-16.457952,0.021618,0.005333,0.135452,1.722654,0.087756,1.354523,-16.457952,0.136606,0.000000
38.960003,0.487442,-16.457952,0.021868,0.005561,0.141237,2.168250,0.110456,1.412371,-16.457952,0.142433,0.000000
39.310001,0.674370,-16.457952,0.022028,-0.000000,-0.000000,2.999747,0.152814,-0.000000,-16.457952,0.000268,0.000000
39.660004,0.657242,-16.457952,0.022036,-0.000000,-0.000000,2.923558,0.148933,-0.000000,-16.457952,0.000268,0.000000
40.010002,0.643089,-16.546913,0.022058,-0.000000,-0.000000,2.860604,0.145726,-0.000000,-16.546913,0.000737,0.000000
40.360001,0.648674,-16.502434,0.022015,0.000005,0.000138,2.885446,0.146992,0.001378,-16.502434,0.001317,0.000000
40.710003,0.764854,-16.502434,0.022049,0.000040,0.001005,3.402242,0.173318,0.010053,-16.502434,0.001899,0.000000
41.060001,0.802467,-16.546913,0.022075,0.000062,0.001568,3.569553,0.181842,0.015685,-16.546913,0.002480,0.000000
41.410004,0.824806,-16.546913,0.022088,0.000086,0.002176,3.668921,0.186904,0.021756,-16.546913,0.003069,0.000000
41.760002,0.847153,-16.546913,0.022097,0.000100,0.002550,3.768323,0.191968,0.025495,-16.546913,0.003650,0.000000
42.110001,0.939125,-16.502434,0.022135,0.000127,0.003226,4.177437,0.212809,0.032262,-16.502434,0.004232,0.000000
42.460003,0.980461,-16.546913,0.022135,0.000142,0.003608,4.361309,0.222176,0.036078,-16.546913,0.004822,0.000000
42.810001,1.116379,-16.591394,0.022174,0.000177,0.004492,4.965901,0.252975,0.044919,-16.591394,0.005402,0.000000
43.160004,1.136482,-16.591394,0.022213,0.000195,0.004943,5.055326,0.257531,0.049431,-16.591394,0.005983,0.000000
43.510002,1.196068,-16.591394,0.022234,0.000219,0.005558,5.320375,0.271033,0.055577,-16.591394,0.006565,0.000000
43.860001,1.261971,-16.591394,0.022226,0.000239,0.006079,5.613525,0.285967,0.060785,-16.591394,0.007153,0.000000
44.210003,1.338684,-16.591394,0.022252,0.000265,0.006720,5.954764,0.303350,0.067205,-16.591394,0.007735,0.000000
44.560001,1.362518,-16.591394,0.022286,0.000277,0.007041,6.060784,0.308751,0.070414,-16.591394,0.008316,0.000000
44.910004,1.525986,-16.635876,0.022299,0.000311,0.007909,6.787923,0.345793,0.079089,-16.635876,0.008898,0.000000
45.260002,1.588921,-16.591394,0.022342,0.000331,0.008412,7.067872,0.360055,0.084116,-16.591394,0.009486,0.000000
45.610001,1.664879,-16.591394,0.022347,0.000352,0.008949,7.405751,0.377267,0.089490,-16.591394,0.010068,0.000000
45.960003,1.759460,-16.635876,0.022372,0.000381,0.009670,7.826471,0.398699,0.096696,-16.635876,0.010649,0.000000
46.310001,1.794464,-16.635876,0.022403,0.000392,0.009956,7.982175,0.406631,0.099558,-16.635876,0.011238,0.000000
46.660004,1.932617,-16.635876,0.022424,0.000427,0.010849,8.596710,0.437937,0.108490,-16.635876,0.011819,0.000000
47.010002,1.992943,-16.635876,0.022459,0.000447,0.011352,8.865052,0.451607,0.113517,-16.635876,0.012401,0.000000
47.360001,2.069275,-16.635876,0.022476,0.000468,0.011898,9.204595,0.468904,0.118982,-16.635876,0.012982,0.000000
47.710003,2.199982,-16.680357,0.022497,0.000495,0.012575,9.786007,0.498523,0.125749,-16.680357,0.013571,0.000000
48.060001,2.268127,-16.680357,0.022515,0.000512,0.013008,10.089135,0.513965,0.130079,-16.680357,0.014152,0.000000
48.410004,2.385796,-16.769318,0.022523,0.000536,0.013606,10.612549,0.540629,0.136059,-16.769318,0.014734,0.000000
48.760002,2.535484,-16.680357,0.022584,0.000565,0.014361,11.278398,0.574549,0.143614,-16.680357,0.015315,0.000000
49.110001,2.565651,-16.724838,0.022579,0.000584,0.014846,11.412585,0.581385,0.148459,-16.724838,0.015904,0.000000
49.460003,2.683693,-16.724838,0.022605,0.000603,0.015315,11.937662,0.608133,0.153152,-16.724838,0.016485,0.000000
49.810001,2.840836,-16.769318,0.022648,0.000628,0.015948,12.636668,0.643743,0.159480,-16.769318,0.017067,0.000000
50.160004,2.957382,-16.769318,0.022653,0.000648,0.016460,13.155093,0.670152,0.164598,-16.769318,0.017648,0.000000
50.510002,3.105965,-16.724838,0.022696,0.000675,0.017136,13.816021,0.703822,0.171365,-16.724838,0.018237,0.000000
50.860001,3.225494,-16.769318,0.022696,0.000700,0.017769,14.347715,0.730907,0.177693,-16.769318,0.018818,0.000000
51.210003,3.277252,-16.769318,0.022730,0.000717,0.018202,14.577946,0.742636,0.182023,-16.769318,0.019400,0.000000
51.560001,3.496208,-16.724838,0.022752,0.000743,0.018870,15.551910,0.792252,0.188700,-16.724838,0.019989,0.000000
51.910004,3.649628,-16.813799,0.022786,0.000764,0.019400,16.234354,0.827017,0.193999,-16.813799,0.020570,0.000000
52.260002,3.751656,-16.769318,0.022808,0.000784,0.019919,16.688198,0.850137,0.199191,-16.769318,0.021152,0.000000
52.610001,3.992584,-16.769318,0.022817,0.000816,0.020735,17.759901,0.904733,0.207352,-16.769318,0.021733,0.000000
52.960003,4.115837,-16.724838,0.022847,0.000833,0.021168,18.308157,0.932662,0.211682,-16.724838,0.022322,0.000000
53.310001,4.234253,-16.813799,0.022873,0.000853,0.021654,18.834898,0.959495,0.216541,-16.813799,0.022903,0.000000
53.660004,4.531403,-16.813799,0.022894,0.000879,0.022322,20.156685,1.026831,0.223218,-16.813799,0.023485,0.000000
54.010002,4.642372,-16.858280,0.022894,0.000897,0.022773,20.650303,1.051977,0.227730,-16.858280,0.024064,0.000000
54.360004,4.927238,-16.813799,0.022937,0.000929,0.023597,21.917452,1.116528,0.235965,-16.813799,0.024655,0.000000
54.710003,5.104485,-16.813799,0.022950,0.000953,0.024204,22.705881,1.156693,0.242036,-16.813799,0.025236,0.000000
55.060001,5.187523,-16.813799,0.023011,0.000969,0.024611,23.075254,1.175509,0.246109,-16.813799,0.025818,0.000000
55.410004,5.424728,-16.858280,0.022998,0.000994,0.025244,24.130398,1.229261,0.252437,-16.858280,0.026406,0.000000
55.760002,5.702141,-16.858280,0.023015,0.001016,0.025808,25.364389,1.292124,0.258084,-16.858280,0.026988,0.000000
56.110004,6.003021,-16.858280,0.023041,0.001046,0.026571,26.702772,1.360304,0.265715,-16.858280,0.027569,0.000000
56.460003,6.195534,-16.858280,0.023071,0.001070,0.027179,27.559111,1.403928,0.271786,-16.858280,0.028149,0.000000
56.810001,6.356026,-16.813799,0.023092,0.001089,0.027672,28.273014,1.440296,0.276721,-16.813799,0.028739,0.000000
57.160004,6.543701,-16.858280,0.023110,0.001108,0.028141,29.107836,1.482824,0.281415,-16.858280,0.029321,0.000000
57.510002,6.891876,-16.858280,0.023123,0.001134,0.028809,30.656597,1.561722,0.288091,-16.858280,0.029902,0.000000
57.860004,7.072845,-16.947243,0.023144,0.001150,0.029216,31.461588,1.602730,0.292164,-16.947243,0.030482,0.000000
58.210003,7.377823,-16.902761,0.023187,0.001176,0.029875,32.818195,1.671839,0.298749,-16.902761,0.031072,0.000000
58.560001,7.656723,-16.947243,0.023209,0.001202,0.030543,34.058804,1.735038,0.305426,-16.947243,0.031654,0.000000
58.910004,7.804184,-16.902761,0.023226,0.001222,0.031029,34.714745,1.768453,0.310286,-16.902761,0.032234,0.000000
59.260002,8.116234,-16.902761,0.023248,0.001243,0.031575,36.102810,1.839165,0.315751,-16.902761,0.032815,0.000000
59.610004,8.442062,-16.947243,0.023269,0.001270,0.032261,37.552170,1.912999,0.322609,-16.947243,0.033405,0.000000
59.960003,8.646866,-16.947243,0.023282,0.001290,0.032754,38.463181,1.959408,0.327545,-16.947243,0.033985,0.000000
60.310001,9.027428,-16.947243,0.023351,0.001317,0.033448,40.156002,2.045644,0.334479,-16.947243,0.034567,0.000000
60.660004,9.235214,-16.947243,0.023343,0.001338,0.033994,41.080284,2.092730,0.339944,-16.947243,0.035157,0.000000
61.010002,9.516724,-16.947243,0.023351,0.001362,0.034585,42.332500,2.156520,0.345849,-16.947243,0.035738,0.000000
61.360004,9.857819,-16.991724,0.023377,0.001387,0.035218,43.849766,2.233814,0.352177,-16.991724,0.036318,0.000000
61.710003,10.019058,-16.991724,0.023381,0.001402,0.035616,44.566998,2.270351,0.356159,-16.991724,0.036900,0.000000
62.060001,10.448029,-17.036203,0.023399,0.001430,0.036318,46.475151,2.367557,0.363183,-17.036203,0.037490,0.000000
62.410004,10.792099,-16.991724,0.023433,0.001457,0.037013,48.005653,2.445525,0.370132,-16.991724,0.038070,0.000000
62.760002,10.978287,-16.991724,0.023455,0.001477,0.037507,48.833858,2.487715,0.375068,-16.991724,0.038651,0.000000
63.110004,11.193146,-16.991724,0.023472,0.001495,0.037967,49.789600,2.536403,0.379670,-16.991724,0.039233,0.000000
63.460003,11.622864,-16.991724,0.023489,0.001524,0.038704,51.701080,2.633779,0.387043,-16.991724,0.039823,0.000000
63.810001,11.733833,-16.991724,0.023519,0.001535,0.038998,52.194698,2.658925,0.389980,-16.991724,0.040403,0.000000
64.160004,12.343781,-17.036203,0.023532,0.001573,0.039952,54.907879,2.797141,0.399518,-17.036203,0.040984,0.000000
64.510002,12.522888,-17.036203,0.023562,0.001590,0.040377,55.704590,2.837727,0.403773,-17.036203,0.041575,0.000000
64.860001,12.900101,-17.080685,0.023575,0.001617,0.041071,57.382515,2.923204,0.410707,-17.080685,0.042155,0.000000
65.210007,13.190178,-17.036203,0.023601,0.001637,0.041591,58.672840,2.988937,0.415915,-17.036203,0.042736,0.000000
65.560005,13.514145,-17.080685,0.023640,0.001662,0.042217,60.113918,3.062349,0.422167,-17.080685,0.043317,0.000000
65.910004,13.540581,-17.036203,0.023640,0.001670,0.042424,60.231510,3.068340,0.424241,-17.036203,0.043908,0.000000
66.260002,14.268196,-17.080685,0.023653,0.001710,0.043431,63.468105,3.233219,0.434309,-17.080685,0.044488,0.000000
66.610001,14.478592,-17.169647,0.023692,0.001730,0.043934,64.403992,3.280896,0.439335,-17.169647,0.045069,0.000000
66.960007,14.808884,-17.080685,0.023692,0.001750,0.044462,65.873207,3.355741,0.444619,-17.080685,0.045650,0.000000
67.310005,15.256104,-17.125166,0.023709,0.001778,0.045173,67.862541,3.457083,0.451735,-17.125166,0.046239,0.000000
67.660004,15.357758,-17.125166,0.023748,0.001790,0.045476,68.314720,3.480118,0.454763,-17.125166,0.046821,0.000000
68.010002,15.921532,-17.125166,0.023756,0.001824,0.046318,70.822510,3.607871,0.463180,-17.125166,0.047402,0.000000
68.360001,16.176239,-17.169647,0.023778,0.001845,0.046855,71.955505,3.665588,0.468555,-17.169647,0.047983,0.000000
68.710007,16.458122,-17.125166,0.023791,0.001865,0.047367,73.209381,3.729464,0.473672,-17.125166,0.048572,0.000000
69.060005,16.938858,-17.169647,0.023825,0.001893,0.048070,75.347801,3.838400,0.480697,-17.169647,0.049154,0.000000
69.410004,17.159302,-17.169647,0.023834,0.001911,0.048530,76.328384,3.888353,0.485299,-17.169647,0.049735,0.000000
69.760002,17.523476,-17.169647,0.023843,0.001932,0.049076,77.948311,3.970876,0.490765,-17.169647,0.050324,0.000000
70.110001,18.119278,-17.169647,0.023847,0.001964,0.049891,80.598572,4.105887,0.498910,-17.169647,0.050905,0.000000
70.460007,18.191147,-17.125166,0.023881,0.001979,0.050256,80.918266,4.122173,0.502558,-17.125166,0.051487,0.000000
70.810005,18.550484,-17.214128,0.023907,0.002000,0.050810,82.516670,4.203599,0.508099,-17.214128,0.052068,0.000000
71.160004,19.005150,-17.169647,0.023933,0.002027,0.051478,84.539131,4.306629,0.514776,-17.169647,0.052657,0.000000
71.510002,19.178299,-17.169647,0.023916,0.002043,0.051886,85.309334,4.345865,0.518864,-17.169647,0.053238,0.000000
71.860001,19.767395,-17.214128,0.023985,0.002073,0.052666,87.929764,4.479356,0.526661,-17.214128,0.053820,0.000000
72.210007,19.973694,-17.258610,0.023989,0.002093,0.053169,88.847427,4.526103,0.531687,-17.258610,0.054401,0.000000
72.560005,20.199348,-17.303089,0.024015,0.002113,0.053680,89.851189,4.577238,0.536804,-17.303089,0.054990,0.000000
72.910004,20.483093,-17.303089,0.024041,0.002136,0.054245,91.113350,4.641535,0.542451,-17.303089,0.055571,0.000000
73.260002,21.090805,-17.258610,0.024045,0.002162,0.054920,93.816589,4.779245,0.549203,-17.258610,0.056153,0.000000
73.610001,21.219650,-17.347570,0.024071,0.002179,0.055337,94.389717,4.808442,0.553367,-17.347570,0.056734,0.000000
73.960007,21.787888,-17.258610,0.024088,0.002212,0.056195,96.917366,4.937206,0.561951,-17.258610,0.057323,0.000000
74.310005,21.999023,-17.214128,0.024101,0.002231,0.056664,97.856544,4.985050,0.566644,-17.214128,0.057904,0.000000
74.660004,22.317406,-17.303089,0.024140,0.002253,0.057237,99.272781,5.057196,0.572367,-17.303089,0.058486,0.000000
75.010002,22.840584,-17.347570,0.024162,0.002278,0.057853,101.599991,5.175750,0.578529,-17.347570,0.059075,0.000000
75.360001,23.028633,-17.347570,0.024175,0.002296,0.058312,102.436478,5.218363,0.583116,-17.347570,0.059656,0.000000
75.710007,23.651985,-17.392052,0.024192,0.002328,0.059119,105.209282,5.359616,0.591185,-17.392052,0.060237,0.000000
76.060005,23.927910,-17.347570,0.024213,0.002352,0.059735,106.436661,5.422142,0.597347,-17.347570,0.060819,0.000000
76.410004,24.006111,-17.392052,0.024248,0.002367,0.060124,106.784515,5.439862,0.601238,-17.392052,0.061408,0.000000
76.760002,24.429871,-17.347570,0.024248,0.002391,0.060740,108.669495,5.535888,0.607400,-17.347570,0.061989,0.000000
77.110001,24.903526,-17.347570,0.024274,0.002415,0.061330,110.776421,5.643220,0.613304,-17.347570,0.062570,0.000000
77.460007,25.410698,-17.392052,0.024282,0.002442,0.062031,113.032433,5.758146,0.620314,-17.392052,0.063150,0.000000
77.810005,25.834831,-17.392052,0.024347,0.002470,0.062726,114.919067,5.854257,0.627263,-17.392052,0.063741,0.000000
78.160004,26.016922,-17.392052,0.024347,0.002488,0.063194,115.729050,5.895519,0.631941,-17.392052,0.064322,0.000000
78.510002,26.236992,-17.436533,0.024373,0.002507,0.063680,116.707970,5.945387,0.636801,-17.436533,0.064903,0.000000
78.860001,26.784386,-17.436533,0.024382,0.002533,0.064330,119.142899,6.069428,0.643296,-17.436533,0.065492,0.000000
79.210007,26.945992,-17.436533,0.024412,0.002550,0.064764,119.861755,6.106049,0.647641,-17.436533,0.066074,0.000000
79.560005,27.496735,-17.436533,0.024399,0.002574,0.065371,122.311584,6.230849,0.653712,-17.436533,0.066655,0.000000
79.910004,27.946182,-17.481014,0.024438,0.002602,0.066099,124.310829,6.332695,0.660994,-17.481014,0.067235,0.000000
80.260002,28.280205,-17.525496,0.024464,0.002625,0.066672,125.796631,6.408386,0.666717,-17.525496,0.067825,0.000000
80.610001,28.570656,-17.525496,0.024485,0.002644,0.067167,127.088623,6.474203,0.671667,-17.525496,0.068407,0.000000
80.960007,29.057343,-17.481014,0.024511,0.002669,0.067790,129.253510,6.584488,0.677905,-17.481014,0.068988,0.000000
81.310005,29.448708,-17.569975,0.024511,0.002693,0.068398,130.994400,6.673172,0.683976,-17.569975,0.069568,0.000000
81.660004,29.958855,-17.525496,0.024528,0.002715,0.068970,133.263641,6.788773,0.689699,-17.525496,0.070158,0.000000
82.010002,30.248192,-17.525496,0.024584,0.002739,0.069568,134.550674,6.854339,0.695679,-17.525496,0.070740,0.000000
82.360001,30.608650,-17.525496,0.024606,0.002760,0.070114,136.154083,6.936019,0.701144,-17.525496,0.071320,0.000000
82.710007,31.158638,-17.569975,0.024623,0.002786,0.070775,138.600540,7.060648,0.707745,-17.569975,0.071901,0.000000
83.060005,31.336266,-17.525496,0.024623,0.002802,0.071182,139.390671,7.100900,0.711818,-17.525496,0.072491,0.000000
83.410004,32.019569,-17.614456,0.024662,0.002830,0.071875,142.430161,7.255738,0.718752,-17.614456,0.073073,0.000000
83.760002,32.559883,-17.569975,0.024666,0.002857,0.072561,144.833588,7.378175,0.725610,-17.569975,0.073653,0.000000
84.110001,32.821281,-17.569975,0.024701,0.002879,0.073124,145.996353,7.437408,0.731242,-17.569975,0.074243,0.000000
84.460007,33.011566,-17.614456,0.024718,0.002897,0.073575,146.842773,7.480528,0.735753,-17.614456,0.074824,0.000000
84.810005,33.712746,-17.569975,0.024718,0.002924,0.074269,149.961777,7.639417,0.742687,-17.569975,0.075404,0.000000
85.160004,33.713486,-17.614456,0.024778,0.002935,0.074546,149.965073,7.639585,0.745458,-17.614456,0.075986,0.000000
85.510002,34.811989,-17.569975,0.024774,0.002972,0.075483,154.851456,7.888509,0.754829,-17.569975,0.076576,0.000000
85.860001,34.986259,-17.569975,0.024817,0.002991,0.075976,155.626648,7.927999,0.759765,-17.569975,0.077156,0.000000
86.210007,35.520241,-17.614456,0.024830,0.003015,0.076593,158.001923,8.049002,0.765926,-17.614456,0.077737,0.000000
86.560005,35.870270,-17.614456,0.024852,0.003037,0.077139,159.558929,8.128319,0.771392,-17.614456,0.078319,0.000000
86.910004,36.265358,-17.614456,0.024869,0.003062,0.077763,161.316376,8.217848,0.777629,-17.614456,0.078909,0.000000
87.260002,36.206520,-17.658937,0.024899,0.003076,0.078137,161.054642,8.204515,0.781369,-17.658937,0.079489,0.000000
87.610001,37.132988,-17.703419,0.024946,0.003110,0.078986,165.175781,8.414455,0.789862,-17.703419,0.080070,0.000000
87.960007,37.264435,-17.658937,0.024959,0.003128,0.079463,165.760483,8.444242,0.794631,-17.658937,0.080661,0.000000
88.310005,37.592491,-17.658937,0.024964,0.003150,0.080010,167.219757,8.518580,0.800097,-17.658937,0.081240,0.000000
88.660004,38.120148,-17.658937,0.024998,0.003178,0.080721,169.566879,8.638149,0.807212,-17.658937,0.081822,0.000000
89.010002,37.991676,-17.703419,0.024994,0.003189,0.080998,168.995422,8.609036,0.809983,-17.703419,0.082403,0.000000
89.360001,38.920372,-17.747900,0.025011,0.003225,0.081926,173.126465,8.819483,0.819263,-17.747900,0.082994,0.000000
89.710007,38.983307,-17.703419,0.025071,0.003246,0.082447,173.406403,8.833744,0.824471,-17.703419,0.083574,0.000000
90.060005,39.251411,-17.703419,0.025084,0.003266,0.082950,174.598999,8.894498,0.829498,-17.703419,0.084155,0.000000
90.410004,39.640167,-17.703419,0.025128,0.003292,0.083626,176.328278,8.982591,0.836265,-17.703419,0.084736,0.000000
90.760002,39.790977,-17.747900,0.025132,0.003309,0.084050,176.999115,9.016765,0.840504,-17.747900,0.085325,0.000000
91.110001,40.249374,-17.658937,0.025132,0.003333,0.084657,179.038162,9.120639,0.846575,-17.658937,0.085907,0.000000
91.460007,40.866394,-17.792381,0.025166,0.003362,0.085404,181.782806,9.260457,0.854039,-17.792381,0.086488,0.000000
91.810005,40.759521,-17.747900,0.025184,0.003378,0.085794,181.307404,9.236239,0.857945,-17.747900,0.087069,0.000000
92.160004,41.099495,-17.747900,0.025222,0.003399,0.086332,182.819687,9.313278,0.863319,-17.747900,0.087658,0.000000
92.510002,41.643906,-17.792381,0.025218,0.003428,0.087060,185.241348,9.436644,0.870602,-17.792381,0.088240,0.000000
92.860001,41.860252,-17.747900,0.025257,0.003445,0.087502,186.203705,9.485669,0.875022,-17.747900,0.088821,0.000000
93.210007,42.425140,-17.792381,0.025257,0.003472,0.088196,188.716446,9.613674,0.881956,-17.792381,0.089410,0.000000
93.560005,42.476158,-17.792381,0.025296,0.003494,0.088742,188.943390,9.625236,0.887422,-17.792381,0.089991,0.000000
93.910004,42.654900,-17.792381,0.025313,0.003512,0.089211,189.738464,9.665738,0.892115,-17.792381,0.090573,0.000000
94.260002,43.134140,-17.836861,0.025322,0.003538,0.089861,191.870239,9.774335,0.898610,-17.836861,0.091154,0.000000
94.610008,43.766060,-17.836861,0.025356,0.003563,0.090494,194.681152,9.917531,0.904938,-17.836861,0.091743,0.000000
94.960007,43.632744,-17.881342,0.025369,0.003579,0.090903,194.088135,9.887321,0.909026,-17.881342,0.092324,0.000000
95.310005,44.552505,-17.836861,0.025403,0.003616,0.091838,198.179443,10.095742,0.918382,-17.836861,0.092906,0.000000
95.660004,44.519737,-17.836861,0.025429,0.003632,0.092247,198.033676,10.088317,0.922470,-17.836861,0.093487,0.000000
96.010002,44.982224,-17.836861,0.025442,0.003656,0.092871,200.090927,10.193117,0.928707,-17.836861,0.094076,0.000000
96.360008,45.690475,-17.836861,0.025455,0.003684,0.093573,203.241379,10.353610,0.935732,-17.836861,0.094657,0.000000
96.710007,45.586960,-17.881342,0.025464,0.003698,0.093929,202.780930,10.330153,0.939290,-17.881342,0.095239,0.000000
97.060005,46.244568,-17.925823,0.025503,0.003729,0.094709,205.706116,10.479169,0.947087,-17.925823,0.095827,0.000000
97.410004,46.550659,-17.881342,0.025511,0.003752,0.095308,207.067673,10.548531,0.953082,-17.881342,0.096409,0.000000
97.760002,46.523102,-17.881342,0.025537,0.003769,0.095741,206.945099,10.542286,0.957412,-17.881342,0.096990,0.000000
98.110008,47.149429,-17.925823,0.025546,0.003794,0.096365,209.731140,10.684213,0.963649,-17.925823,0.097572,0.000000
98.460007,47.595535,-17.925823,0.025572,0.003820,0.097025,211.715515,10.785303,0.970250,-17.925823,0.098160,0.000000
98.810005,48.030090,-17.881342,0.025610,0.003843,0.097614,213.648514,10.883774,0.976140,-17.881342,0.098742,0.000000
99.160004,48.484390,-17.925823,0.025628,0.003870,0.098291,215.669342,10.986720,0.982907,-17.925823,0.099323,0.000000
99.510002,48.500397,-17.925823,0.025641,0.003887,0.098725,215.740540,10.990347,0.987252,-17.925823,0.099905,0.000000
99.860008,48.768135,-17.925823,0.025658,0.003908,0.099263,216.931503,11.051017,0.992627,-17.925823,0.100493,0.000000
100.210007,49.340843,-17.925823,0.025679,0.003932,0.099861,219.479034,11.180795,0.998607,-17.925823,0.101075,0.000000
100.560005,49.421646,-17.970304,0.025701,0.003951,0.100347,219.838455,11.199105,1.003466,-17.970304,0.101656,0.000000
100.910004,50.194321,-17.925823,0.025692,0.003980,0.101084,223.275482,11.374196,1.010839,-17.925823,0.102236,0.000000
101.260002,50.524246,-18.014786,0.025727,0.004004,0.101699,224.743073,11.448957,1.016986,-18.014786,0.102827,0.000000
101.610008,50.745430,-17.925823,0.025744,0.004023,0.102194,225.726944,11.499079,1.021937,-17.925823,0.103408,0.000000
101.960007,51.193771,-18.014786,0.025774,0.004049,0.102836,227.721268,11.600674,1.028356,-18.014786,0.103989,0.000000
102.310005,51.387405,-17.970304,0.025817,0.004068,0.103320,228.582596,11.644553,1.033201,-17.970304,0.104578,0.000000
102.660004,51.982826,-17.970304,0.025809,0.004094,0.103997,231.231155,11.779477,1.039968,-17.970304,0.105160,0.000000
103.010002,52.355576,-17.970304,0.025856,0.004119,0.104630,232.889236,11.863942,1.046296,-17.970304,0.105741,0.000000
103.360008,52.493347,-18.014786,0.025852,0.004139,0.105141,233.502075,11.895163,1.051414,-18.014786,0.106321,0.000000
103.710007,52.956207,-18.014786,0.025886,0.004164,0.105767,235.560974,12.000048,1.057666,-18.014786,0.106911,0.000000
104.060005,53.270119,-18.014786,0.025899,0.004185,0.106287,236.957321,12.071182,1.062874,-18.014786,0.107493,0.000000
104.410004,53.298416,-18.014786,0.025929,0.004201,0.106711,237.083191,12.077594,1.067113,-18.014786,0.108074,0.000000
104.760002,53.992149,-18.059267,0.025942,0.004232,0.107493,240.169083,12.234796,1.074925,-18.059267,0.108654,0.000000
105.110008,54.481071,-18.059267,0.025968,0.004259,0.108169,242.343903,12.345587,1.081693,-18.059267,0.109244,0.000000
105.460007,54.870949,-18.014786,0.025973,0.004284,0.108819,244.078171,12.433934,1.088188,-18.014786,0.109826,0.000000
105.810005,54.857170,-18.059267,0.026011,0.004304,0.109314,244.016876,12.430812,1.093138,-18.059267,0.110405,0.000000
106.160004,55.315559,-18.059267,0.026050,0.004322,0.109791,246.055893,12.534685,1.097907,-18.059267,0.110996,0.000000
106.510002,55.192307,-18.059267,0.026055,0.004338,0.110180,245.507645,12.506755,1.101798,-18.059267,0.111577,0.000000
106.860008,56.496353,-18.059267,0.026072,0.004372,0.111056,251.308334,12.802257,1.110564,-18.059267,0.112159,0.000000
107.210007,56.340698,-18.059267,0.026089,0.004390,0.111498,250.615936,12.766985,1.114985,-18.059267,0.112738,0.000000
107.560005,56.926819,-18.103746,0.026119,0.004414,0.112124,253.223145,12.899801,1.121237,-18.103746,0.113329,0.000000
107.910004,57.501389,-18.103746,0.026106,0.004442,0.112834,255.778946,13.030001,1.128338,-18.103746,0.113910,0.000000
108.260002,57.619431,-18.059267,0.026158,0.004460,0.113285,256.304016,13.056749,1.132849,-18.059267,0.114490,0.000000
108.610008,57.718849,-18.148228,0.026162,0.004475,0.113676,256.746277,13.079278,1.136755,-18.148228,0.115071,0.000000
108.960007,58.549240,-18.059267,0.026201,0.004507,0.114473,260.440033,13.267447,1.144734,-18.059267,0.115662,0.000000
109.310005,58.747719,-18.148228,0.026214,0.004527,0.114985,261.322906,13.312424,1.149851,-18.148228,0.116242,0.000000
109.660004,59.157326,-18.148228,0.026201,0.004551,0.115592,263.144928,13.405242,1.155922,-18.148228,0.116823,0.000000
110.010002,59.765785,-18.192709,0.026244,0.004578,0.116269,265.851501,13.543120,1.162689,-18.192709,0.117404,0.000000
110.360008,59.510338,-18.103746,0.026283,0.004590,0.116597,264.715210,13.485235,1.165975,-18.103746,0.117995,0.000000
110.710007,60.725761,-18.148228,0.026292,0.004626,0.117500,270.121674,13.760654,1.174998,-18.148228,0.118575,0.000000
111.060005,60.825180,-18.192709,0.026313,0.004645,0.117995,270.563904,13.783182,1.179949,-18.192709,0.119156,0.000000
111.410004,61.136490,-18.192709,0.026343,0.004668,0.118567,271.948700,13.853726,1.185671,-18.192709,0.119747,0.000000
111.760002,61.682014,-18.148228,0.026352,0.004693,0.119191,274.375305,13.977345,1.191909,-18.148228,0.120326,0.000000
112.110008,61.761703,-18.192709,0.026391,0.004710,0.119624,274.729767,13.995402,1.196239,-18.192709,0.120908,0.000000
112.460007,62.470322,-18.148228,0.026395,0.004736,0.120284,277.881866,14.155977,1.202840,-18.148228,0.121489,0.000000
112.810005,63.050484,-18.237190,0.026417,0.004761,0.120933,280.462555,14.287444,1.209334,-18.237190,0.122080,0.000000
113.160004,63.319710,-18.237190,0.026443,0.004785,0.121541,281.660126,14.348452,1.215405,-18.237190,0.122659,0.000000
113.510002,63.384132,-18.192709,0.026464,0.004799,0.121905,281.946716,14.363050,1.219054,-18.192709,0.123241,0.000000
113.860008,64.243187,-18.237190,0.026473,0.004828,0.122643,285.767975,14.557714,1.226427,-18.237190,0.123822,0.000000
114.210007,64.355278,-18.237190,0.026486,0.004845,0.123059,286.266571,14.583114,1.230590,-18.237190,0.124411,0.000000
114.560005,65.076195,-18.192709,0.026503,0.004874,0.123787,289.473358,14.746476,1.237873,-18.192709,0.124992,0.000000
114.910004,65.321205,-18.281672,0.026503,0.004895,0.124343,290.563232,14.801996,1.243429,-18.281672,0.125574,0.000000
115.260002,65.515953,-18.281672,0.026559,0.004913,0.124793,291.429504,14.846127,1.247925,-18.281672,0.126155,0.000000
115.610008,66.337791,-18.237190,0.026542,0.004940,0.125478,295.085236,15.032358,1.254784,-18.237190,0.126744,0.000000
115.960007,66.710152,-18.326151,0.026576,0.004965,0.126111,296.741577,15.116736,1.261112,-18.326151,0.127325,0.000000
116.310005,67.051628,-18.281672,0.026593,0.004986,0.126632,298.260529,15.194116,1.266320,-18.281672,0.127907,0.000000
116.660004,66.699730,-18.326151,0.026619,0.004983,0.126581,296.695221,15.114375,1.265805,-18.326151,0.126839,0.000000
117.010002,66.086433,-18.326151,0.026624,0.004976,0.126381,293.967133,14.975400,1.263807,-18.326151,0.126581,0.000000
117.360008,65.683525,-18.370632,0.026641,0.004975,0.126372,292.174927,14.884100,1.263716,-18.370632,0.126581,0.000000
117.710007,65.388985,-18.370632,0.026654,0.004975,0.126363,290.864716,14.817355,1.263625,-18.370632,0.126581,0.000000
118.060005,65.144707,-18.326151,0.026628,0.004975,0.126363,289.778137,14.762002,1.263625,-18.326151,0.126581,0.000000
118.410004,64.947716,-18.326151,0.026645,0.004975,0.126363,288.901855,14.717363,1.263625,-18.326151,0.126581,0.000000
118.760002,64.767113,-18.326151,0.026641,0.004975,0.126363,288.098511,14.676437,1.263625,-18.326151,0.126581,0.000000
119.110008,64.618172,-18.370632,0.026645,0.004975,0.126363,287.435974,14.642687,1.263625,-18.370632,0.126581,0.000000
119.460007,64.475548,-18.370632,0.026649,0.004975,0.126363,286.801575,14.610368,1.263625,-18.370632,0.126581,0.000000
119.810005,64.342979,-18.370632,0.026611,0.004975,0.126363,286.211853,14.580327,1.263625,-18.370632,0.126581,0.000000
120.160004,64.230156,-18.370632,0.026654,0.004975,0.126363,285.709991,14.554761,1.263625,-18.370632,0.126581,0.000000
120.510002,64.127754,-18.415113,0.026658,0.004975,0.126363,285.254486,14.531557,1.263625,-18.415113,0.126581,0.000000
120.860008,64.029823,-18.415113,0.026649,0.004975,0.126363,284.818878,14.509366,1.263625,-18.415113,0.126581,0.000000
121.210007,63.941566,-18.415113,0.026641,0.004975,0.126363,284.426300,14.489366,1.263625,-18.415113,0.126581,0.000000
121.560005,63.861137,-18.459595,0.026688,0.004975,0.126363,284.068512,14.471141,1.263625,-18.459595,0.126581,0.000000
121.910004,63.784798,-18.459595,0.026649,0.004975,0.126363,283.728943,14.453842,1.263625,-18.459595,0.126581,0.000000
122.260002,63.707726,-18.504076,0.026654,0.004975,0.126363,283.386108,14.436377,1.263625,-18.504076,0.126581,0.000000
122.610008,63.652977,-18.459595,0.026641,0.004975,0.126363,283.142578,14.423970,1.263625,-18.459595,0.126581,0.000000
122.960007,63.577766,-18.459595,0.026641,0.004975,0.126363,282.808044,14.406927,1.263625,-18.459595,0.126581,0.000000
123.310005,63.508873,-18.459595,0.026649,0.004975,0.126363,282.501587,14.391316,1.263625,-18.459595,0.126581,0.000000
123.660004,63.449669,-18.459595,0.026649,0.004975,0.126363,282.238220,14.377900,1.263625,-18.459595,0.126581,0.000000
124.010002,63.392326,-18.504076,0.026667,0.004975,0.126363,281.983154,14.364906,1.263625,-18.504076,0.126581,0.000000
124.360008,63.350243,-18.459595,0.026649,0.004975,0.126363,281.795959,14.355371,1.263625,-18.459595,0.126581,0.000000
124.710007,63.281349,-18.548557,0.026649,0.004975,0.126363,281.489502,14.339758,1.263625,-18.548557,0.126581,0.000000
125.060005,63.238152,-18.504076,0.026645,0.004975,0.126363,281.297333,14.329970,1.263625,-18.504076,0.126581,0.000000
125.410004,63.197563,-18.548557,0.026654,0.004975,0.126363,281.116791,14.320773,1.263625,-18.548557,0.126581,0.000000
125.760010,63.138741,-18.548557,0.026658,0.004975,0.126363,280.855133,14.307444,1.263625,-18.548557,0.126581,0.000000
126.110008,63.096657,-18.593037,0.026654,0.004975,0.126363,280.667938,14.297907,1.263625,-18.593037,0.126581,0.000000
126.460007,63.063881,-18.548557,0.026645,0.004975,0.126363,280.522156,14.290480,1.263625,-18.548557,0.126581,0.000000
126.810005,63.034843,-18.548557,0.026658,0.004975,0.126363,280.392975,14.283899,1.263625,-18.548557,0.126581,0.000000
127.160004,62.987549,-18.548557,0.026658,0.004975,0.126363,280.182617,14.273183,1.263625,-18.548557,0.126581,0.000000
127.510010,62.943985,-18.637518,0.026667,0.004975,0.126363,279.988831,14.263310,1.263625,-18.637518,0.126581,0.000000
127.860008,62.915680,-18.593037,0.026649,0.004975,0.126363,279.862915,14.256897,1.263625,-18.593037,0.126581,0.000000
128.210007,62.869133,-18.593037,0.026667,0.004975,0.126363,279.655884,14.246349,1.263625,-18.593037,0.126581,0.000000
128.560013,62.842697,-18.548557,0.026667,0.004975,0.126363,279.538269,14.240358,1.263625,-18.548557,0.126581,0.000000
128.910004,62.810303,-18.637518,0.026662,0.004975,0.126363,279.394196,14.233018,1.263625,-18.637518,0.126581,0.000000
129.260010,62.770088,-18.681999,0.026649,0.004975,0.126363,279.215302,14.223905,1.263625,-18.681999,0.126581,0.000000
129.610001,62.739548,-18.637518,0.026654,0.004975,0.126363,279.079437,14.216985,1.263625,-18.637518,0.126581,0.000000
129.960007,62.719818,-18.681999,0.026658,0.004975,0.126363,278.991699,14.212514,1.263625,-18.681999,0.126581,0.000000
130.310013,62.696724,-18.637518,0.026658,0.004975,0.126363,278.888947,14.207281,1.263625,-18.637518,0.126581,0.000000
130.660004,62.646088,-18.637518,0.026654,0.004975,0.126363,278.663727,14.195807,1.263625,-18.637518,0.126581,0.000000
131.010010,62.625977,-18.681999,0.026658,0.004975,0.126363,278.574249,14.191249,1.263625,-18.681999,0.126581,0.000000
131.360001,62.603264,-18.726480,0.026667,0.004975,0.126363,278.473236,14.186103,1.263625,-18.726480,0.126581,0.000000
131.710007,62.589859,-18.637518,0.026662,0.004975,0.126363,278.413605,14.183064,1.263625,-18.637518,0.126581,0.000000
132.060013,62.546661,-18.637518,0.026658,0.004975,0.126363,278.221436,14.173277,1.263625,-18.637518,0.126581,0.000000
132.410004,62.529160,-18.726480,0.026645,0.004975,0.126363,278.143585,14.169311,1.263625,-18.726480,0.126581,0.000000
132.760010,62.493042,-18.726480,0.026654,0.004975,0.126363,277.982941,14.161126,1.263625,-18.726480,0.126581,0.000000
133.110001,62.471817,-18.770962,0.026667,0.004975,0.126363,277.888519,14.156316,1.263625,-18.770962,0.126581,0.000000
133.460007,62.452820,-18.726480,0.026658,0.004975,0.126363,277.804016,14.152011,1.263625,-18.726480,0.126581,0.000000
133.810013,62.426384,-18.770962,0.026654,0.004975,0.126363,277.686432,14.146020,1.263625,-18.770962,0.126581,0.000000
134.160004,62.411491,-18.726480,0.026667,0.004975,0.126363,277.620178,14.142646,1.263625,-18.726480,0.126581,0.000000
134.510010,62.386917,-18.815443,0.026658,0.004975,0.126363,277.510864,14.137077,1.263625,-18.815443,0.126581,0.000000
134.860001,62.374252,-18.815443,0.026662,0.004975,0.126363,277.454529,14.134208,1.263625,-18.815443,0.126581,0.000000
135.210007,62.345581,-18.815443,0.026654,0.004975,0.126363,277.326996,14.127711,1.263625,-18.815443,0.126581,0.000000
135.560013,62.324730,-18.770962,0.026649,0.004975,0.126363,277.234253,14.122986,1.263625,-18.770962,0.126581,0.000000
135.910004,62.300522,-18.815443,0.026637,0.004975,0.126363,277.126556,14.117499,1.263625,-18.815443,0.126581,0.000000
136.260010,62.280418,-18.815443,0.026649,0.004975,0.126363,277.037140,14.112945,1.263625,-18.815443,0.126581,0.000000
136.610001,62.249138,-18.815443,0.026662,0.004975,0.126363,276.897980,14.105857,1.263625,-18.815443,0.126581,0.000000
136.960007,62.241318,-18.770962,0.026654,0.004975,0.126363,276.863220,14.104084,1.263625,-18.770962,0.126581,0.000000
137.310013,62.223816,-18.859922,0.026654,0.004975,0.126363,276.785370,14.100118,1.263625,-18.859922,0.126581,0.000000
137.660004,62.210411,-18.859922,0.026658,0.004975,0.126363,276.725739,14.097080,1.263625,-18.859922,0.126581,0.000000
138.010010,62.188438,-18.815443,0.026671,0.004975,0.126363,276.627991,14.092102,1.263625,-18.815443,0.126581,0.000000
138.360001,62.174660,-18.904404,0.026667,0.004975,0.126363,276.566711,14.088979,1.263625,-18.904404,0.126581,0.000000
138.710007,62.163864,-18.859922,0.026649,0.004975,0.126363,276.518677,14.086534,1.263625,-18.859922,0.126581,0.000000
139.060013,62.135559,-18.904404,0.026654,0.004975,0.126363,276.392761,14.080119,1.263625,-18.904404,0.126581,0.000000
139.410004,62.114708,-18.815443,0.026658,0.004975,0.126363,276.300018,14.075394,1.263625,-18.815443,0.126581,0.000000
139.760010,62.111359,-18.948885,0.026658,0.004975,0.126363,276.285126,14.074635,1.263625,-18.948885,0.126581,0.000000
140.110001,62.089386,-18.948885,0.026654,0.004975,0.126363,276.187378,14.069655,1.263625,-18.948885,0.126581,0.000000
140.460007,62.089760,-18.904404,0.026662,0.004975,0.126363,276.189056,14.069741,1.263625,-18.904404,0.126581,0.000000
140.810013,62.074493,-18.948885,0.026654,0.004975,0.126363,276.121124,14.066281,1.263625,-18.948885,0.126581,0.000000
141.160004,62.042099,-18.948885,0.026658,0.004975,0.126363,275.977051,14.058940,1.263625,-18.948885,0.126581,0.000000
141.510010,62.032417,-18.904404,0.026658,0.004975,0.126363,275.933960,14.056746,1.263625,-18.904404,0.126581,0.000000
141.860001,62.010445,-18.993366,0.026662,0.004975,0.126363,275.836243,14.051767,1.263625,-18.993366,0.126581,0.000000
142.210007,62.013054,-18.993366,0.026680,0.004975,0.126363,275.847839,14.052360,1.263625,-18.993366,0.126581,0.000000
142.560013,61.982887,-18.948885,0.026658,0.004975,0.126363,275.713654,14.045524,1.263625,-18.948885,0.126581,0.000000
142.910004,61.969482,-19.037848,0.026671,0.004975,0.126363,275.654022,14.042485,1.263625,-19.037848,0.126581,0.000000
143.260010,61.956825,-18.993366,0.026675,0.004975,0.126363,275.597717,14.039617,1.263625,-18.993366,0.126581,0.000000
143.610001,61.932617,-19.037848,0.026675,0.004975,0.126363,275.490051,14.034132,1.263625,-19.037848,0.126581,0.000000
143.960007,61.924057,-18.993366,0.026654,0.004975,0.126363,275.451965,14.032191,1.263625,-18.993366,0.126581,0.000000
144.310013,61.900223,-19.082329,0.026671,0.004975,0.126363,275.345947,14.026791,1.263625,-19.082329,0.126581,0.000000
144.660004,61.900970,-18.993366,0.026671,0.004975,0.126363,275.349274,14.026960,1.263625,-18.993366,0.126581,0.000000
145.010010,61.879745,-19.082329,0.026649,0.004975,0.126363,275.254852,14.022151,1.263625,-19.082329,0.126581,0.000000
145.360001,61.878998,-19.037848,0.026667,0.004975,0.126363,275.251526,14.021981,1.263625,-19.037848,0.126581,0.000000
145.710007,61.854790,-19.037848,0.026662,0.004975,0.126363,275.143860,14.016496,1.263625,-19.037848,0.126581,0.000000
146.060013,61.844368,-19.037848,0.026667,0.004975,0.126363,275.097473,14.014133,1.263625,-19.037848,0.126581,0.000000
146.410004,61.845482,-19.037848,0.026662,0.004975,0.126363,275.102448,14.014386,1.263625,-19.037848,0.126581,0.000000
146.760010,61.820908,-19.082329,0.026671,0.004975,0.126363,274.993134,14.008819,1.263625,-19.082329,0.126581,0.000000
146.900009,61.814949,-19.037848,0.026671,0.004975,0.126363,274.966614,14.007467,1.263625,-19.037848,0.126581,0.000000