File: Data/New pin I-18-3_08172023_170343.csv
Time (sec),S:Load (lbs),S:HL1 (DIM),S:LVDT (in),S:Position (in),Ch:Position (mm),Ch:Load (N),Ch:Stress (MPa),Ch:Strain (mm/mm),Ch:HL1 (DIM),Set Point (),Cycles ()
0.010000,-0.007820,-129.750931,0.000000,-0.000000,-0.000000,-0.034784,-0.001772,-0.000000,-129.750931,0.000026,0.000000
0.290000,0.000745,-129.750931,-0.000017,-0.000000,-0.000000,0.003313,0.000169,-0.000000,-129.750931,0.000026,0.000000
0.570000,0.000372,-129.795410,-0.000009,0.000130,0.003303,0.001656,0.000084,0.033035,-129.795410,0.003964,0.000000
0.850000,0.017129,-129.706451,0.000034,0.000297,0.007536,0.076194,0.003882,0.075365,-129.706451,0.008628,0.000000
1.130000,0.041333,-129.661972,0.000198,0.000475,0.012054,0.183860,0.009366,0.120541,-129.661972,0.013294,0.000000
1.410000,0.030535,-129.706451,0.000418,0.000666,0.016928,0.135824,0.006919,0.169276,-129.706451,0.017960,0.000000
1.690000,0.037982,-129.750931,0.000573,0.000843,0.021412,0.168952,0.008607,0.214119,-129.750931,0.022626,0.000000
1.970000,-0.013033,-129.706451,0.000746,0.001031,0.026199,-0.057974,-0.002953,0.261990,-129.706451,0.027292,0.000000
2.250000,0.032396,-129.706451,0.000979,0.001215,0.030856,0.144106,0.007341,0.308560,-129.706451,0.031957,0.000000
2.530000,-0.016012,-129.706451,0.001151,0.001399,0.035522,-0.071225,-0.003628,0.355220,-129.706451,0.036623,0.000000
2.810000,0.036492,-129.706451,0.001311,0.001583,0.040196,0.162327,0.008269,0.401956,-129.706451,0.041270,0.000000
3.090000,0.049153,-129.750931,0.001531,0.001768,0.044896,0.218644,0.011138,0.448964,-129.750931,0.045937,0.000000
3.370000,0.018246,-129.750931,0.001725,0.001954,0.049631,0.081163,0.004135,0.496306,-129.750931,0.050603,0.000000
3.650000,0.049898,-129.661972,0.001867,0.002133,0.054175,0.221957,0.011307,0.541755,-129.661972,0.055269,0.000000
3.930000,0.012661,-129.661972,0.002104,0.002316,0.058823,0.056317,0.002869,0.588233,-129.661972,0.059935,0.000000
4.210000,0.016384,-129.661972,0.002294,0.002497,0.063420,0.072881,0.003713,0.634197,-129.661972,0.064599,0.000000
4.490000,-0.023087,-129.661972,0.002462,0.002682,0.068121,-0.102696,-0.005232,0.681205,-129.661972,0.069265,0.000000
4.770000,0.062186,-129.661972,0.002665,0.002867,0.072829,0.276618,0.014092,0.728289,-129.661972,0.073931,0.000000
5.050000,0.031652,-129.617493,0.002854,0.003052,0.077521,0.140793,0.007172,0.775207,-129.617493,0.078597,0.000000
5.330000,0.025694,-129.661972,0.003035,0.003235,0.082170,0.114291,0.005822,0.821701,-129.661972,0.083262,0.000000
5.610000,0.047291,-129.661972,0.003255,0.003426,0.087025,0.210362,0.010716,0.870253,-129.661972,0.087928,0.000000
5.890000,0.039844,-129.661972,0.003436,0.003606,0.091605,0.177234,0.009029,0.916051,-129.661972,0.092594,0.000000
6.170000,0.016012,-129.573013,0.003566,0.003784,0.096115,0.071225,0.003628,0.961151,-129.573013,0.097260,0.000000
6.450000,-0.004469,-129.617493,0.003811,0.003967,0.100763,-0.019877,-0.001013,1.007630,-129.617493,0.101924,0.000000
6.730000,0.032396,-129.573013,0.003988,0.004153,0.105480,0.144106,0.007341,1.054805,-129.573013,0.106590,0.000000
7.010000,0.031652,-129.661972,0.004182,0.004334,0.110094,0.140793,0.007172,1.100935,-129.661972,0.111256,0.000000
7.290000,0.071868,-129.573013,0.004355,0.004518,0.114769,0.319684,0.016285,1.147686,-129.573013,0.115922,0.000000
7.570000,0.029790,-129.528534,0.004562,0.004708,0.119591,0.132512,0.006750,1.195906,-129.528534,0.120588,0.000000
7.850000,0.050270,-129.528534,0.004747,0.004889,0.124178,0.223613,0.011391,1.241779,-129.528534,0.125253,0.000000
8.130000,0.044685,-129.573013,0.004937,0.005076,0.128921,0.198768,0.010126,1.289211,-129.573013,0.129902,0.000000
8.410001,0.042078,-129.528534,0.005126,0.005255,0.133475,0.187173,0.009535,1.334751,-129.528534,0.134567,0.000000
8.690001,0.026438,-129.573013,0.005329,0.005441,0.138202,0.117604,0.005991,1.382017,-129.573013,0.139233,0.000000
8.970000,0.001862,-129.528534,0.005471,0.005621,0.142763,0.008282,0.000422,1.427632,-129.528534,0.143899,0.000000
9.250000,0.070378,-129.528534,0.005665,0.005802,0.147360,0.313059,0.015948,1.473596,-129.528534,0.148565,0.000000
9.530001,0.031652,-129.528534,0.005872,0.005991,0.152180,0.140793,0.007172,1.521800,-129.528534,0.153231,0.000000
9.810000,0.059580,-129.573013,0.006075,0.006168,0.156655,0.265023,0.013501,1.566553,-129.573013,0.157895,0.000000
10.090000,0.044312,-129.528534,0.006282,0.006359,0.161512,0.197111,0.010041,1.615121,-129.528534,0.162561,0.000000
10.370001,0.060697,-129.484055,0.006433,0.006536,0.166022,0.269993,0.013754,1.660221,-129.484055,0.167227,0.000000
10.650001,0.036865,-129.484055,0.006635,0.006727,0.170861,0.163983,0.008354,1.708608,-129.484055,0.171893,0.000000
10.930000,0.046547,-129.484055,0.006847,0.006911,0.175534,0.207049,0.010548,1.755343,-129.484055,0.176558,0.000000
11.210001,0.064420,-129.484055,0.006998,0.007095,0.180200,0.286556,0.014598,1.802004,-129.484055,0.181224,0.000000
11.490001,0.056228,-129.484055,0.007209,0.007273,0.184745,0.250116,0.012741,1.847453,-129.484055,0.185890,0.000000
11.770000,0.070006,-129.439575,0.007386,0.007449,0.189202,0.311402,0.015864,1.892024,-129.439575,0.190556,0.000000
12.050000,0.065165,-129.395081,0.007584,0.007642,0.194103,0.289869,0.014767,1.941030,-129.395081,0.195220,0.000000
12.330001,0.069634,-129.439575,0.007765,0.007822,0.198690,0.309746,0.015779,1.986903,-129.439575,0.199886,0.000000
12.610001,0.032396,-129.484055,0.007959,0.008009,0.203424,0.144106,0.007341,2.034245,-129.484055,0.204552,0.000000
12.890000,0.067027,-129.439575,0.008170,0.008194,0.208125,0.298151,0.015189,2.081253,-129.439575,0.209218,0.000000
13.170001,0.046547,-129.395081,0.008364,0.008381,0.212878,0.207049,0.010548,2.128776,-129.395081,0.213866,0.000000
13.450001,0.067027,-129.350601,0.008550,0.008561,0.217457,0.298151,0.015189,2.174574,-129.350601,0.218532,0.000000
13.730000,0.090114,-129.395081,0.008705,0.008746,0.222157,0.400848,0.020420,2.221567,-129.395081,0.223198,0.000000
14.010000,0.065910,-129.350601,0.008942,0.008929,0.226806,0.293182,0.014935,2.268060,-129.350601,0.227863,0.000000
14.290001,0.081550,-129.439575,0.009145,0.009108,0.231340,0.362750,0.018479,2.313404,-129.439575,0.232529,0.000000
14.570001,0.050270,-129.395081,0.009317,0.009296,0.236111,0.223613,0.011391,2.361108,-129.395081,0.237195,0.000000
14.850000,0.075219,-129.306122,0.009494,0.009477,0.240716,0.334592,0.017045,2.407163,-129.306122,0.241861,0.000000
15.130001,0.051015,-129.306122,0.009727,0.009661,0.245381,0.226926,0.011560,2.453808,-129.306122,0.246527,0.000000
15.410001,0.107243,-129.395081,0.009895,0.009847,0.250126,0.477042,0.024302,2.501256,-129.395081,0.251191,0.000000
15.690001,0.159375,-129.306122,0.010072,0.010030,0.254757,0.708937,0.036115,2.547567,-129.306122,0.255857,0.000000
15.970001,0.274811,-129.261642,0.010274,0.010217,0.259500,1.222420,0.062273,2.595000,-129.261642,0.260523,0.000000
16.250000,0.521321,-129.306122,0.010464,0.010400,0.264157,2.318954,0.118133,2.641569,-129.306122,0.265189,0.000000
16.530001,0.638619,-129.261642,0.010589,-0.000000,-0.000000,2.840718,0.144713,-0.000000,-129.261642,0.000130,0.000000
16.810001,0.604733,-129.261642,0.010628,-0.000000,-0.000009,2.689986,0.137034,-0.000091,-129.261642,0.000130,0.000000
17.090000,0.587231,-129.217163,0.010598,-0.000000,-0.000009,2.612136,0.133069,-0.000091,-129.217163,0.000312,0.000000
17.370001,0.603988,-129.217163,0.010637,-0.000000,-0.000000,2.686673,0.136866,-0.000000,-129.217163,0.000781,0.000000
17.650002,0.633033,-129.217163,0.010619,0.000017,0.000442,2.815872,0.143447,0.004421,-129.217163,0.001249,0.000000
17.930000,0.660589,-129.261642,0.010632,0.000032,0.000824,2.938446,0.149692,0.008236,-129.261642,0.001709,0.000000
18.210001,0.658727,-129.217163,0.010649,0.000049,0.001240,2.930163,0.149270,0.012399,-129.217163,0.002177,0.000000
18.490002,0.680697,-129.172684,0.010684,0.000073,0.001856,3.027891,0.154248,0.018561,-129.172684,0.002645,0.000000
18.770000,0.700060,-129.172684,0.010654,0.000086,0.002177,3.114023,0.158636,0.021771,-129.172684,0.003114,0.000000
19.050001,0.712721,-129.083725,0.010710,0.000100,0.002550,3.170341,0.161505,0.025495,-129.083725,0.003582,0.000000
19.330002,0.725754,-129.172684,0.010697,0.000126,0.003210,3.228315,0.164458,0.032096,-129.172684,0.004041,0.000000
19.610001,0.715700,-129.083725,0.010727,0.000146,0.003703,3.183592,0.162180,0.037031,-129.083725,0.004510,0.000000
19.890001,0.722403,-129.083725,0.010744,0.000160,0.004059,3.213407,0.163699,0.040589,-129.083725,0.004978,0.000000
20.170000,0.710859,-129.083725,0.010757,0.000177,0.004492,3.162059,0.161083,0.044919,-129.083725,0.005446,0.000000
20.450001,0.710859,-129.039246,0.010796,0.000192,0.004873,3.162059,0.161083,0.048734,-129.039246,0.005915,0.000000
20.730001,0.753309,-129.083725,0.010839,0.000213,0.005403,3.350888,0.170702,0.054033,-129.083725,0.006383,0.000000
21.010000,0.751448,-129.083725,0.010852,0.000227,0.005767,3.342606,0.170280,0.057667,-129.083725,0.006843,0.000000
21.290001,0.757778,-129.128204,0.010861,0.000247,0.006262,3.370764,0.171715,0.062617,-129.128204,0.007311,0.000000
21.570002,0.786823,-129.039246,0.010904,0.000272,0.006911,3.499963,0.178297,0.069112,-129.039246,0.007779,0.000000
21.850000,0.786078,-128.950272,0.010930,0.000287,0.007294,3.496650,0.178128,0.072942,-128.950272,0.008248,0.000000
22.130001,0.781237,-129.039246,0.010921,0.000307,0.007804,3.475118,0.177031,0.078045,-129.039246,0.008716,0.000000
22.410002,0.816985,-129.039246,0.010930,0.000324,0.008221,3.634132,0.185131,0.082208,-129.039246,0.009176,0.000000
22.690001,0.835231,-128.994751,0.010968,0.000344,0.008733,3.715295,0.189266,0.087325,-128.994751,0.009644,0.000000
22.970001,0.828529,-128.950272,0.010964,0.000358,0.009088,3.685480,0.187747,0.090883,-128.950272,0.010112,0.000000
23.250002,0.831135,-128.905792,0.010999,0.000377,0.009574,3.697075,0.188338,0.095743,-128.905792,0.010580,0.000000
23.530001,0.856457,-128.950272,0.011020,0.000399,0.010137,3.809709,0.194076,0.101375,-128.950272,0.011049,0.000000
23.810001,0.850126,-128.950272,0.011059,0.000414,0.010511,3.781551,0.192641,0.105114,-128.950272,0.011517,0.000000
24.090002,0.834859,-128.950272,0.011068,0.000433,0.010996,3.713638,0.189182,0.109959,-128.950272,0.011977,0.000000
24.370001,0.845658,-128.905792,0.011098,0.000446,0.011317,3.761674,0.191629,0.113168,-128.905792,0.012445,0.000000
24.650002,0.906727,-128.905792,0.011115,0.000471,0.011959,4.033323,0.205467,0.119588,-128.905792,0.012913,0.000000
24.930000,0.923856,-128.816833,0.011111,0.000486,0.012349,4.109517,0.209349,0.123494,-128.816833,0.013382,0.000000
25.210001,0.928325,-128.861313,0.011145,0.000507,0.012887,4.129394,0.210361,0.128868,-128.861313,0.013850,0.000000
25.490002,0.929069,-128.816833,0.011167,0.000524,0.013321,4.132707,0.210530,0.133213,-128.816833,0.014310,0.000000
25.770000,0.936517,-128.816833,0.011150,0.000541,0.013738,4.165834,0.212218,0.137377,-128.816833,0.014778,0.000000
26.050001,0.904120,-128.816833,0.011197,0.000559,0.014205,4.021728,0.204877,0.142055,-128.816833,0.015246,0.000000
26.330002,0.964072,-128.861313,0.011219,0.000580,0.014743,4.288408,0.218462,0.147429,-128.861313,0.015715,0.000000
26.610001,0.986415,-128.816833,0.011249,0.000599,0.015203,4.387791,0.223525,0.152032,-128.816833,0.016183,0.000000
26.890001,1.023280,-128.816833,0.011244,0.000615,0.015627,4.551775,0.231878,0.156271,-128.816833,0.016643,0.000000
27.170002,1.038547,-128.727875,0.011283,0.000636,0.016157,4.619687,0.235338,0.161570,-128.727875,0.017111,0.000000
27.450001,1.048229,-128.727875,0.011292,0.000656,0.016660,4.662753,0.237532,0.166596,-128.727875,0.017579,0.000000
27.730001,1.035568,-128.727875,0.011283,0.000668,0.016962,4.606435,0.234663,0.169624,-128.727875,0.018046,0.000000
28.010002,1.021790,-128.772354,0.011339,0.000686,0.017423,4.545149,0.231541,0.174226,-128.772354,0.018516,0.000000
28.290001,1.045249,-128.727875,0.011365,0.000702,0.017839,4.649502,0.236857,0.178390,-128.727875,0.018984,0.000000
28.570002,1.117117,-128.727875,0.011365,0.000727,0.018455,4.969186,0.253142,0.184551,-128.727875,0.019444,0.000000
28.850002,1.149141,-128.683395,0.011391,0.000742,0.018844,5.111636,0.260399,0.188442,-128.683395,0.019912,0.000000
29.130001,1.177814,-128.683395,0.011400,0.000768,0.019495,5.239178,0.266896,0.194952,-128.683395,0.020379,0.000000
29.410002,1.164781,-128.727875,0.011426,0.000781,0.019833,5.181205,0.263943,0.198328,-128.727875,0.020849,0.000000
29.690001,1.165898,-128.683395,0.011438,0.000797,0.020233,5.186174,0.264196,0.202325,-128.683395,0.021317,0.000000
29.970001,1.189730,-128.683395,0.011456,0.000816,0.020735,5.292183,0.269597,0.207352,-128.683395,0.021777,0.000000
30.250002,1.196433,-128.638916,0.011499,0.000836,0.021230,5.321999,0.271116,0.212302,-128.638916,0.022245,0.000000
30.530001,1.252661,-128.638916,0.011499,0.000856,0.021733,5.572114,0.283857,0.217329,-128.638916,0.022712,0.000000
30.810001,1.267556,-128.638916,0.011495,0.000868,0.022054,5.638370,0.287232,0.220538,-128.638916,0.023182,0.000000
31.090002,1.288036,-128.594437,0.011559,0.000887,0.022540,5.729472,0.291873,0.225398,-128.594437,0.023650,0.000000
31.370001,1.291388,-128.638916,0.011581,0.000906,0.023017,5.744380,0.292633,0.230167,-128.638916,0.024117,0.000000
31.650002,1.289153,-128.549942,0.011611,0.000929,0.023589,5.734441,0.292126,0.235890,-128.549942,0.024578,0.000000
31.930002,1.298835,-128.594437,0.011589,0.000946,0.024022,5.777507,0.294320,0.240220,-128.594437,0.025045,0.000000
32.210003,1.331232,-128.638916,0.011624,0.000968,0.024578,5.921614,0.301661,0.245776,-128.638916,0.025513,0.000000
32.490002,1.359532,-128.594437,0.011650,0.000982,0.024950,6.047500,0.308074,0.249500,-128.594437,0.025983,0.000000
32.770000,1.402727,-128.505463,0.011658,0.000997,0.025322,6.239641,0.317862,0.253225,-128.505463,0.026450,0.000000
33.050003,1.458955,-128.505463,0.011693,0.001024,0.025999,6.489757,0.330604,0.259992,-128.505463,0.026911,0.000000
33.330002,1.435496,-128.505463,0.011689,0.001040,0.026416,6.385405,0.325288,0.264155,-128.505463,0.027378,0.000000
33.610001,1.395280,-128.505463,0.011684,0.001057,0.026858,6.206514,0.316175,0.268576,-128.505463,0.027846,0.000000
33.890003,1.427676,-128.416504,0.011701,0.001074,0.027292,6.350620,0.323516,0.272921,-128.416504,0.028316,0.000000
34.170002,1.460072,-128.416504,0.011740,0.001095,0.027820,6.494726,0.330857,0.278205,-128.416504,0.028783,0.000000
34.450001,1.486138,-128.460983,0.011727,0.001110,0.028202,6.610674,0.336764,0.282020,-128.460983,0.029244,0.000000
34.730003,1.491352,-128.505463,0.011775,0.001122,0.028506,6.633864,0.337945,0.285063,-128.505463,0.029711,0.000000
35.010002,1.595616,-128.460983,0.011788,0.001151,0.029225,7.097654,0.361572,0.292254,-128.460983,0.030179,0.000000
35.290001,1.568805,-128.505463,0.011814,0.001169,0.029686,6.978394,0.355496,0.296857,-128.505463,0.030649,0.000000
35.570004,1.570295,-128.372025,0.011826,0.001187,0.030144,6.985019,0.355834,0.301444,-128.372025,0.031116,0.000000
35.850002,1.602691,-128.372025,0.011861,0.001202,0.030526,7.129126,0.363175,0.305259,-128.372025,0.031584,0.000000
36.130001,1.643652,-128.372025,0.011908,0.001226,0.031151,7.311329,0.372457,0.311512,-128.372025,0.032044,0.000000
36.410000,1.640301,-128.372025,0.011891,0.001238,0.031446,7.296422,0.371697,0.314464,-128.372025,0.032512,0.000000
36.690002,1.693178,-128.416504,0.011887,0.001252,0.031810,7.531630,0.383680,0.318098,-128.416504,0.032980,0.000000
36.970001,1.736745,-128.327545,0.011904,0.001282,0.032556,7.725428,0.393552,0.325562,-128.327545,0.033449,0.000000
37.250000,1.732277,-128.283066,0.011943,0.001296,0.032929,7.705552,0.392540,0.329286,-128.283066,0.033917,0.000000
37.530003,1.750523,-128.327545,0.011939,0.001311,0.033310,7.786715,0.396674,0.333101,-128.327545,0.034377,0.000000
37.810001,1.804517,-128.372025,0.011956,0.001334,0.033873,8.026892,0.408909,0.338733,-128.372025,0.034845,0.000000
38.090000,1.824625,-128.283066,0.011969,0.001351,0.034324,8.116338,0.413466,0.343245,-128.283066,0.035313,0.000000
38.370003,1.819039,-128.238586,0.011990,0.001366,0.034689,8.091492,0.412200,0.346893,-128.238586,0.035782,0.000000
38.650002,1.893142,-128.194107,0.012025,0.001384,0.035166,8.421114,0.428992,0.351662,-128.194107,0.036250,0.000000
38.930000,1.911016,-128.283066,0.012016,0.001408,0.035773,8.500622,0.433042,0.357733,-128.283066,0.036718,0.000000
39.210003,1.895376,-128.238586,0.012021,0.001425,0.036190,8.431052,0.429498,0.361897,-128.238586,0.037178,0.000000
39.490002,1.913994,-128.238586,0.012042,0.001443,0.036648,8.513872,0.433717,0.366484,-128.238586,0.037646,0.000000
39.770000,1.965009,-128.194107,0.012094,0.001464,0.037187,8.740799,0.445277,0.371873,-128.194107,0.038115,0.000000
40.050003,1.938943,-128.194107,0.012102,0.001477,0.037525,8.624851,0.439371,0.375250,-128.194107,0.038583,0.000000
40.330002,1.969105,-128.194107,0.012107,0.001491,0.037872,8.759019,0.446206,0.378717,-128.194107,0.039051,0.000000
40.610001,2.017514,-128.238586,0.012111,0.001516,0.038497,8.974350,0.457175,0.384969,-128.238586,0.039511,0.000000
40.890003,2.044325,-128.149612,0.012137,0.001541,0.039137,9.093611,0.463251,0.391373,-128.149612,0.039979,0.000000
41.170002,2.010439,-128.149612,0.012141,0.001551,0.039407,8.942879,0.455572,0.394068,-128.149612,0.040447,0.000000
41.450001,2.031292,-128.149612,0.012150,0.001571,0.039893,9.035637,0.460297,0.398928,-128.149612,0.040916,0.000000
41.730003,2.067784,-128.194107,0.012180,0.001587,0.040317,9.197964,0.468567,0.403167,-128.194107,0.041384,0.000000
42.010002,2.102415,-128.149612,0.012210,0.001603,0.040716,9.352008,0.476414,0.407164,-128.149612,0.041844,0.000000
42.290001,2.094967,-128.105133,0.012189,0.001617,0.041072,9.318880,0.474726,0.410722,-128.105133,0.042312,0.000000
42.570004,2.175772,-128.105133,0.012202,0.001639,0.041619,9.678318,0.493037,0.416187,-128.105133,0.042780,0.000000
42.850002,2.196625,-128.060654,0.012262,0.001667,0.042338,9.771077,0.497762,0.423378,-128.060654,0.043249,0.000000
43.130001,2.187316,-128.149612,0.012232,0.001681,0.042703,9.729668,0.495653,0.427027,-128.149612,0.043717,0.000000
43.410004,2.177262,-128.149612,0.012258,0.001698,0.043136,9.684944,0.493375,0.431357,-128.149612,0.044185,0.000000
43.690002,2.201094,-128.016174,0.012279,0.001713,0.043517,9.790954,0.498775,0.435172,-128.016174,0.044645,0.000000
43.970001,2.306847,-128.060654,0.012266,0.001737,0.044124,10.261370,0.522739,0.441243,-128.060654,0.045113,0.000000
44.250004,2.288229,-128.060654,0.012309,0.001751,0.044463,10.178550,0.518520,0.444634,-128.060654,0.045582,0.000000
44.530003,2.323604,-128.016174,0.012327,0.001769,0.044922,10.335907,0.526536,0.449222,-128.016174,0.046050,0.000000
44.810001,2.375364,-128.016174,0.012348,0.001790,0.045469,10.566146,0.538265,0.454687,-128.016174,0.046518,0.000000
45.090004,2.386908,-127.971695,0.012331,0.001809,0.045955,10.617496,0.540881,0.459547,-127.971695,0.046978,0.000000
45.370003,2.409250,-127.927216,0.012365,0.001829,0.046466,10.716878,0.545944,0.464664,-127.927216,0.047446,0.000000
45.650002,2.396589,-127.927216,0.012374,0.001841,0.046753,10.660561,0.543075,0.467525,-127.927216,0.047914,0.000000
45.930000,2.521706,-127.927216,0.012391,0.001865,0.047376,11.217110,0.571427,0.473763,-127.927216,0.048383,0.000000
46.210003,2.512769,-127.882736,0.012417,0.001880,0.047750,11.177357,0.569402,0.477502,-127.882736,0.048851,0.000000
46.490002,2.562295,-127.927216,0.012434,0.001902,0.048313,11.397657,0.580624,0.483134,-127.927216,0.049319,0.000000
46.770000,2.562295,-127.838257,0.012452,0.001919,0.048746,11.397657,0.580624,0.487464,-127.838257,0.049779,0.000000
47.050003,2.619640,-127.882736,0.012465,0.001938,0.049232,11.652742,0.593619,0.492324,-127.882736,0.050247,0.000000
47.330002,2.579052,-127.882736,0.012452,0.001952,0.049579,11.472195,0.584422,0.495791,-127.882736,0.050716,0.000000
47.610001,2.648685,-127.882736,0.012469,0.001971,0.050074,11.781940,0.600201,0.500742,-127.882736,0.051184,0.000000
47.890003,2.738799,-127.793770,0.012508,0.001994,0.050646,12.182788,0.620621,0.506464,-127.793770,0.051652,0.000000
48.170002,2.756673,-127.793770,0.012529,0.002007,0.050967,12.262296,0.624671,0.509674,-127.793770,0.052112,0.000000
48.450001,2.846787,-127.793770,0.012508,0.002029,0.051540,12.663143,0.645091,0.515397,-127.793770,0.052580,0.000000
48.730003,2.886259,-127.793770,0.012547,0.002051,0.052103,12.838720,0.654036,0.521029,-127.793770,0.053048,0.000000
49.010002,2.901526,-127.838257,0.012555,0.002065,0.052450,12.906633,0.657495,0.524496,-127.838257,0.053517,0.000000
49.290001,2.917166,-127.749290,0.012568,0.002081,0.052857,12.976201,0.661039,0.528568,-127.749290,0.053985,0.000000
49.570004,2.995364,-127.704811,0.012603,0.002098,0.053300,13.324044,0.678759,0.533004,-127.704811,0.054445,0.000000
49.850002,3.166283,-127.749290,0.012607,0.002123,0.053915,14.084330,0.717490,0.539151,-127.749290,0.054913,0.000000
50.130001,3.180433,-127.793770,0.012628,0.002135,0.054228,14.147273,0.720696,0.542285,-127.793770,0.055381,0.000000
50.410004,3.297358,-127.749290,0.012628,0.002161,0.054887,14.667381,0.747192,0.548870,-127.749290,0.055850,0.000000
50.690002,3.335712,-127.704811,0.012663,0.002178,0.055320,14.837990,0.755883,0.553200,-127.704811,0.056318,0.000000
50.970001,3.408325,-127.704811,0.012667,0.002193,0.055702,15.160987,0.772337,0.557015,-127.704811,0.056786,0.000000
51.250004,3.503652,-127.660332,0.012654,0.002215,0.056257,15.585024,0.793939,0.562572,-127.660332,0.057246,0.000000
51.530003,3.591905,-127.704811,0.012667,0.002234,0.056743,15.977590,0.813937,0.567431,-127.704811,0.057714,0.000000
51.810001,3.684253,-127.660332,0.012719,0.002252,0.057194,16.388376,0.834864,0.571943,-127.660332,0.058183,0.000000
52.090004,3.746439,-127.615852,0.012732,0.002266,0.057567,16.664993,0.848955,0.575667,-127.615852,0.058651,0.000000
52.370003,3.803785,-127.615852,0.012732,0.002280,0.057923,16.920078,0.861950,0.579225,-127.615852,0.059119,0.000000
52.650002,3.918475,-127.615852,0.012766,0.002302,0.058477,17.430248,0.887939,0.584766,-127.615852,0.059579,0.000000
52.930004,3.985875,-127.615852,0.012775,0.002323,0.059007,17.730057,0.903212,0.590065,-127.615852,0.060047,0.000000
53.210003,4.103545,-127.660332,0.012753,0.002342,0.059483,18.253479,0.929877,0.594834,-127.660332,0.060514,0.000000
53.490002,4.213022,-127.571365,0.012771,0.002361,0.059969,18.740459,0.954684,0.599694,-127.571365,0.060984,0.000000
53.770004,4.375377,-127.482407,0.012810,0.002380,0.060463,19.462648,0.991475,0.604629,-127.482407,0.061452,0.000000
54.050003,4.475917,-127.526886,0.012814,0.002394,0.060819,19.909872,1.014257,0.608187,-127.526886,0.061919,0.000000
54.330002,4.606247,-127.526886,0.012848,0.002415,0.061330,20.489613,1.043791,0.613304,-127.526886,0.062380,0.000000
54.610004,4.777166,-127.526886,0.012866,0.002436,0.061886,21.249897,1.082521,0.618861,-127.526886,0.062847,0.000000
54.890003,4.830788,-127.526886,0.012878,0.002451,0.062268,21.488419,1.094672,0.622676,-127.526886,0.063317,0.000000
55.170002,5.022560,-127.482407,0.012874,0.002473,0.062805,22.341463,1.138128,0.628050,-127.482407,0.063785,0.000000
55.450001,5.193851,-127.482407,0.012904,0.002491,0.063282,23.103405,1.176944,0.632819,-127.482407,0.064252,0.000000
55.730003,5.316362,-127.482407,0.012926,0.002507,0.063680,23.648359,1.204705,0.636801,-127.482407,0.064713,0.000000
56.010002,5.359930,-127.482407,0.012922,0.002514,0.063854,23.842157,1.214577,0.638542,-127.482407,0.065180,0.000000
56.290001,5.559521,-127.437927,0.012930,0.002532,0.064313,24.729986,1.259806,0.643129,-127.437927,0.065650,0.000000
56.570004,6.038764,-127.437927,0.012930,0.002566,0.065164,26.861767,1.368404,0.651638,-127.437927,0.066118,0.000000
56.850002,6.217131,-127.437927,0.012982,0.002585,0.065650,27.655178,1.408822,0.656498,-127.437927,0.066585,0.000000
57.130001,6.386188,-127.393440,0.012982,0.002600,0.066031,28.407183,1.447131,0.660313,-127.393440,0.067055,0.000000
57.410004,6.719089,-127.393440,0.013021,0.002622,0.066594,29.888000,1.522567,0.665945,-127.393440,0.067513,0.000000
57.690002,6.882933,-127.348961,0.013038,0.002636,0.066950,30.616814,1.559695,0.669502,-127.348961,0.067981,0.000000
57.970001,6.974164,-127.348961,0.013038,0.002647,0.067245,31.022631,1.580368,0.672455,-127.348961,0.068451,0.000000
58.250004,7.649275,-127.393440,0.013042,0.002678,0.068016,34.025677,1.733351,0.680161,-127.393440,0.068918,0.000000
58.530003,7.855197,-127.437927,0.013068,0.002695,0.068451,34.941662,1.780013,0.684506,-127.437927,0.069386,0.000000
58.810001,8.089791,-127.393440,0.013077,0.002710,0.068823,35.985188,1.833173,0.688230,-127.393440,0.069846,0.000000
59.090004,8.431257,-127.304482,0.013081,0.002730,0.069344,37.504105,1.910550,0.693438,-127.304482,0.070314,0.000000
59.370003,8.752615,-127.348961,0.013098,0.002748,0.069812,38.933575,1.983371,0.698116,-127.348961,0.070784,0.000000
59.650002,9.026308,-127.304482,0.013146,0.002763,0.070184,40.151024,2.045391,0.701841,-127.304482,0.071251,0.000000
59.930004,9.364795,-127.348961,0.013172,0.002781,0.070628,41.656689,2.122093,0.706277,-127.348961,0.071719,0.000000
60.210003,9.894681,-127.348961,0.013150,0.002805,0.071251,44.013741,2.242167,0.712514,-127.348961,0.072179,0.000000
60.490002,10.109540,-127.260002,0.013198,0.002823,0.071703,44.969479,2.290854,0.717026,-127.260002,0.072647,0.000000
60.770004,10.509468,-127.260002,0.013198,0.002841,0.072161,46.748447,2.381480,0.721613,-127.260002,0.073117,0.000000
61.050003,10.936579,-127.215523,0.013245,0.002862,0.072691,48.648331,2.478264,0.726912,-127.215523,0.073584,0.000000
61.330002,11.163726,-127.215523,0.013232,0.002876,0.073055,49.658733,2.529737,0.730545,-127.215523,0.074052,0.000000
61.610004,11.429600,-127.171036,0.013215,0.002890,0.073410,50.841400,2.589984,0.734103,-127.171036,0.074522,0.000000
61.890003,11.948315,-127.260002,0.013232,0.002913,0.073983,53.148758,2.707527,0.739826,-127.260002,0.074980,0.000000
62.170002,12.499799,-127.126556,0.013292,0.002937,0.074599,55.601883,2.832495,0.745988,-127.126556,0.075448,0.000000
62.450005,12.663642,-127.215523,0.013314,0.002950,0.074920,56.330692,2.869622,0.749197,-127.215523,0.075917,0.000000
62.730003,13.055378,-127.171036,0.013297,0.002968,0.075380,58.073223,2.958391,0.753800,-127.171036,0.076385,0.000000
63.010002,13.333168,-127.171036,0.013331,0.002984,0.075804,59.308895,3.021339,0.758039,-127.171036,0.076853,0.000000
63.290005,13.775174,-127.126556,0.013357,0.003002,0.076238,61.275036,3.121499,0.762384,-127.126556,0.077313,0.000000
63.570004,13.966574,-127.082077,0.013374,0.003015,0.076585,62.126423,3.164871,0.765851,-127.082077,0.077781,0.000000
63.850002,14.524760,-127.126556,0.013374,0.003036,0.077113,64.609360,3.291358,0.771134,-127.126556,0.078250,0.000000
64.130005,15.250514,-127.126556,0.013374,0.003063,0.077790,67.837677,3.455816,0.777902,-127.126556,0.078718,0.000000
64.410004,15.448988,-127.037598,0.013439,0.003078,0.078181,68.720528,3.500791,0.781808,-127.037598,0.079186,0.000000
64.690002,15.679859,-126.993118,0.013430,0.003094,0.078597,69.747498,3.553107,0.785971,-126.993118,0.079655,0.000000
64.970001,16.087980,-127.037598,0.013448,0.003111,0.079021,71.562912,3.645588,0.790210,-127.037598,0.080114,0.000000
65.250000,16.617495,-127.037598,0.013456,0.003134,0.079595,73.918304,3.765578,0.795948,-127.037598,0.080583,0.000000
65.530006,16.976833,-127.037598,0.013465,0.003148,0.079958,75.516724,3.847005,0.799582,-127.037598,0.081051,0.000000
65.810005,17.181267,-126.993118,0.013504,0.003165,0.080393,76.426094,3.893331,0.803927,-126.993118,0.081519,0.000000
66.090004,17.823236,-126.904152,0.013517,0.003188,0.080965,79.281715,4.038803,0.809650,-126.904152,0.081988,0.000000
66.370003,18.206779,-127.037598,0.013547,0.003206,0.081442,80.987801,4.125715,0.814419,-127.037598,0.082447,0.000000
66.650002,18.673363,-127.037598,0.013551,0.003227,0.081954,83.063263,4.231444,0.819536,-127.037598,0.082915,0.000000
66.930000,18.885614,-126.993118,0.013560,0.003239,0.082275,84.007408,4.279541,0.822745,-126.993118,0.083384,0.000000
67.210007,19.557747,-126.993118,0.013564,0.003263,0.082882,86.997200,4.431849,0.828816,-126.993118,0.083852,0.000000
67.490005,19.778936,-126.948631,0.013616,0.003277,0.083245,87.981102,4.481971,0.832450,-126.948631,0.084320,0.000000
67.770004,20.199345,-126.948631,0.013646,0.003298,0.083775,89.851173,4.577237,0.837749,-126.948631,0.084780,0.000000
68.050003,20.699068,-126.948631,0.013616,0.003316,0.084225,92.074051,4.690476,0.842245,-126.948631,0.085248,0.000000
68.330002,21.136234,-126.948631,0.013642,0.003337,0.084754,94.018669,4.789539,0.847544,-126.948631,0.085717,0.000000
68.610001,21.339550,-126.859673,0.013655,0.003351,0.085118,94.923058,4.835611,0.851177,-126.859673,0.086185,0.000000
68.890007,21.891405,-126.770714,0.013676,0.003371,0.085613,97.377831,4.960663,0.856128,-126.770714,0.086653,0.000000
69.170006,22.465603,-126.859673,0.013698,0.003393,0.086176,99.931992,5.090778,0.861760,-126.859673,0.087122,0.000000
69.450005,22.509544,-126.859673,0.013711,0.003406,0.086515,100.127457,5.100736,0.865151,-126.859673,0.087581,0.000000
69.730003,23.203646,-126.859673,0.013715,0.003427,0.087053,103.214973,5.258021,0.870526,-126.859673,0.088050,0.000000
70.010002,23.715658,-126.770714,0.013736,0.003448,0.087590,105.492516,5.374045,0.875900,-126.770714,0.088518,0.000000
70.290001,23.888067,-126.770714,0.013762,0.003461,0.087920,106.259430,5.413113,0.879201,-126.770714,0.088986,0.000000
70.570000,24.195274,-126.770714,0.013793,0.003478,0.088336,107.625954,5.482728,0.883364,-126.770714,0.089454,0.000000
70.850006,24.719946,-126.770714,0.013810,0.003496,0.088795,109.959808,5.601620,0.887951,-126.770714,0.089914,0.000000
71.130005,25.576403,-126.815193,0.013797,0.003520,0.089420,113.769524,5.795696,0.894204,-126.815193,0.090382,0.000000
71.410004,25.647526,-126.681747,0.013818,0.003532,0.089723,114.085892,5.811812,0.897232,-126.681747,0.090851,0.000000
71.690002,26.214277,-126.770714,0.013831,0.003553,0.090244,116.606926,5.940240,0.902440,-126.770714,0.091319,0.000000
71.970001,26.808956,-126.681747,0.013857,0.003575,0.090807,119.252190,6.074996,0.908072,-126.681747,0.091787,0.000000
72.250000,27.116163,-126.726227,0.013862,0.003590,0.091198,120.618721,6.144610,0.911978,-126.726227,0.092256,0.000000
72.530006,27.579395,-126.681747,0.013887,0.003610,0.091700,122.679276,6.249580,0.917004,-126.681747,0.092715,0.000000
72.810005,28.120825,-126.592789,0.013909,0.003630,0.092212,125.087677,6.372270,0.922122,-126.592789,0.093184,0.000000
73.090004,28.696140,-126.637268,0.013887,0.003649,0.092689,127.646805,6.502638,0.926890,-126.637268,0.093652,0.000000
73.370003,28.900572,-126.681747,0.013913,0.003663,0.093036,128.556168,6.548964,0.930357,-126.681747,0.094120,0.000000
73.650002,29.232355,-126.637268,0.013948,0.003677,0.093401,130.032013,6.624146,0.934006,-126.637268,0.094589,0.000000
73.930000,30.152117,-126.637268,0.013969,0.003700,0.093990,134.123322,6.832568,0.939895,-126.637268,0.095048,0.000000
74.210007,30.621305,-126.681747,0.013999,0.003718,0.094441,136.210373,6.938887,0.944407,-126.681747,0.095516,0.000000
74.490005,31.132946,-126.592789,0.013995,0.003739,0.094978,138.486267,7.054827,0.949782,-126.592789,0.095985,0.000000
74.770004,31.663948,-126.592789,0.014017,0.003757,0.095429,140.848282,7.175153,0.954293,-126.592789,0.096453,0.000000
75.050003,32.021423,-126.592789,0.014025,0.003774,0.095864,142.438400,7.256158,0.958638,-126.592789,0.096921,0.000000
75.330002,32.592644,-126.548309,0.014034,0.003791,0.096297,144.979324,7.385599,0.962968,-126.548309,0.097381,0.000000
75.610001,32.700634,-126.503822,0.014094,0.003802,0.096566,145.459686,7.410069,0.965663,-126.503822,0.097849,0.000000
75.890007,34.220657,-126.459343,0.014086,0.003834,0.097381,152.221085,7.754512,0.973808,-126.459343,0.098318,0.000000
76.170006,34.500309,-126.592789,0.014103,0.003849,0.097771,153.465042,7.817882,0.977714,-126.592789,0.098786,0.000000
76.450005,35.170952,-126.548309,0.014133,0.003870,0.098292,156.448212,7.969851,0.982922,-126.548309,0.099254,0.000000
76.730003,35.854626,-126.503822,0.014125,0.003888,0.098760,159.489334,8.124775,0.987600,-126.503822,0.099723,0.000000
77.010002,36.218063,-126.459343,0.014112,0.003904,0.099151,161.105988,8.207130,0.991506,-126.459343,0.100182,0.000000
77.290001,36.289928,-126.459343,0.014155,0.003912,0.099376,161.425659,8.223414,0.993762,-126.459343,0.100651,0.000000
77.570007,36.845509,-126.459343,0.014172,0.003928,0.099765,163.897003,8.349312,0.997653,-126.459343,0.101119,0.000000
77.850006,38.473892,-126.459343,0.014211,0.003962,0.100642,171.140427,8.718308,1.006419,-126.459343,0.101587,0.000000
78.130005,39.032452,-126.414864,0.014228,0.003981,0.101128,173.625015,8.844880,1.011279,-126.414864,0.102056,0.000000
78.410004,39.420094,-126.370384,0.014211,0.003996,0.101509,175.349335,8.932721,1.015094,-126.370384,0.102515,0.000000
78.690002,40.314159,-126.325897,0.014232,0.004018,0.102056,179.326340,9.135319,1.020559,-126.325897,0.102982,0.000000
78.970001,40.638496,-126.414864,0.014241,0.004032,0.102419,180.769058,9.208815,1.024193,-126.414864,0.103452,0.000000
79.250000,40.844788,-126.370384,0.014262,0.004041,0.102654,181.686691,9.255562,1.026539,-126.370384,0.103920,0.000000
79.530006,42.483227,-126.370384,0.014280,0.004073,0.103452,188.974838,9.626837,1.034518,-126.370384,0.104387,0.000000
79.810005,43.083118,-126.281418,0.014293,0.004092,0.103938,191.643280,9.762774,1.039378,-126.281418,0.104857,0.000000
80.090004,43.281593,-126.236938,0.014310,0.004106,0.104292,192.526138,9.807750,1.042920,-126.236938,0.105315,0.000000
80.370003,44.314182,-126.370384,0.014349,0.004125,0.104787,197.119324,10.041738,1.047871,-126.370384,0.105785,0.000000
80.650002,45.045525,-126.325897,0.014314,0.004144,0.105264,200.372498,10.207462,1.052640,-126.325897,0.106253,0.000000
80.930000,45.635361,-126.236938,0.014353,0.004161,0.105697,202.996216,10.341121,1.056970,-126.236938,0.106720,0.000000
81.210007,45.678185,-126.236938,0.014379,0.004169,0.105888,203.186707,10.350824,1.058877,-126.236938,0.107190,0.000000
81.490005,47.277523,-126.236938,0.014409,0.004198,0.106625,210.300919,10.713240,1.066250,-126.236938,0.107648,0.000000
81.770004,48.092648,-126.281418,0.014392,0.004218,0.107129,213.926773,10.897949,1.071292,-126.281418,0.108118,0.000000
82.050003,48.714138,-126.236938,0.014413,0.004235,0.107571,216.691315,11.038781,1.075713,-126.236938,0.108586,0.000000
82.330002,49.761620,-126.192459,0.014426,0.004257,0.108125,221.350739,11.276145,1.081254,-126.192459,0.109053,0.000000
82.610001,50.431892,-126.192459,0.014426,0.004274,0.108551,224.332260,11.428030,1.085508,-126.192459,0.109523,0.000000
82.890007,50.845222,-126.236938,0.014444,0.004288,0.108907,226.170853,11.521692,1.089066,-126.236938,0.109981,0.000000
83.170006,51.725140,-126.192459,0.014448,0.004307,0.109409,230.084915,11.721084,1.094092,-126.192459,0.110449,0.000000
83.450005,53.153191,-126.147980,0.014491,0.004333,0.110068,236.437195,12.044684,1.100678,-126.147980,0.110919,0.000000
83.730003,53.401932,-126.103493,0.014474,0.004346,0.110389,237.543655,12.101051,1.103887,-126.103493,0.111386,0.000000
84.010002,54.414413,-126.103493,0.014513,0.004364,0.110858,242.047394,12.330482,1.108581,-126.103493,0.111854,0.000000
84.290001,54.911533,-126.103493,0.014508,0.004378,0.111205,244.258698,12.443130,1.112048,-126.103493,0.112324,0.000000
84.570007,55.913212,-126.147980,0.014504,0.004399,0.111726,248.714386,12.670115,1.117256,-126.147980,0.112782,0.000000
84.850006,56.464325,-126.103493,0.014551,0.004411,0.112028,251.165863,12.794999,1.120283,-126.103493,0.113252,0.000000
85.130005,57.302906,-126.059013,0.014560,0.004430,0.112514,254.896057,12.985024,1.125143,-126.059013,0.113719,0.000000
85.410004,58.903366,-126.059013,0.014586,0.004457,0.113208,262.015259,13.347693,1.132077,-126.059013,0.114187,0.000000
85.690002,59.746044,-126.059013,0.014582,0.004475,0.113659,265.763672,13.538648,1.136589,-126.059013,0.114657,0.000000
85.970001,60.240181,-126.059013,0.014603,0.004489,0.114022,267.961700,13.650620,1.140222,-126.059013,0.115115,0.000000
86.250008,60.948063,-125.970055,0.014616,0.004504,0.114413,271.110535,13.811028,1.144128,-125.970055,0.115585,0.000000
86.530006,61.943787,-126.059013,0.014625,0.004526,0.114959,275.539734,14.036663,1.149594,-126.059013,0.116052,0.000000
86.810005,63.209480,-125.970055,0.014629,0.004546,0.115480,281.169800,14.323473,1.154802,-125.970055,0.116520,0.000000
87.090004,63.645527,-125.970055,0.014642,0.004559,0.115792,283.109436,14.422283,1.157920,-125.970055,0.116990,0.000000
87.370003,64.833771,-126.014534,0.014685,0.004581,0.116355,288.395020,14.691543,1.163552,-126.014534,0.117457,0.000000
87.650002,65.840294,-125.970055,0.014676,0.004601,0.116859,292.872253,14.919623,1.168594,-125.970055,0.117916,0.000000
87.930008,66.493805,-125.925575,0.014676,0.004616,0.117258,295.779205,15.067712,1.172576,-125.925575,0.118385,0.000000
88.210007,67.342819,-125.925575,0.014702,0.004623,0.117413,299.555817,15.260101,1.174135,-125.925575,0.117657,0.000000
88.490005,66.763405,-125.925575,0.014720,0.004623,0.117413,296.978455,15.128804,1.174135,-125.925575,0.117657,0.000000
88.770004,66.382095,-125.925575,0.014745,0.004618,0.117309,295.282318,15.042397,1.173090,-125.925575,0.117413,0.000000
89.050003,66.062599,-125.925575,0.014728,0.004618,0.117292,293.861115,14.969999,1.172924,-125.925575,0.117413,0.000000
89.330002,65.789650,-125.881088,0.014694,0.004617,0.117283,292.646973,14.908148,1.172833,-125.881088,0.117413,0.000000
89.610001,65.562874,-125.836609,0.014750,0.004617,0.117283,291.638214,14.856759,1.172833,-125.836609,0.117413,0.000000
89.890007,65.354721,-125.792130,0.014745,0.004617,0.117276,290.712311,14.809591,1.172757,-125.792130,0.117413,0.000000
90.170006,65.170769,-125.881088,0.014741,0.004617,0.117276,289.894043,14.767907,1.172757,-125.881088,0.117413,0.000000
90.450005,65.018845,-125.836609,0.014728,0.004617,0.117267,289.218262,14.733480,1.172666,-125.836609,0.117413,0.000000
90.730003,64.856483,-125.792130,0.014750,0.004617,0.117267,288.496033,14.696689,1.172666,-125.792130,0.117413,0.000000
91.010002,64.744026,-125.792130,0.014707,0.004617,0.117267,287.995819,14.671206,1.172666,-125.792130,0.117413,0.000000
91.290001,64.602898,-125.792130,0.014745,0.004617,0.117267,287.368042,14.639226,1.172666,-125.792130,0.117413,0.000000
91.570007,64.501984,-125.747650,0.014741,0.004617,0.117267,286.919159,14.616359,1.172666,-125.747650,0.117413,0.000000
91.850006,64.397720,-125.747650,0.014728,0.004616,0.117258,286.455353,14.592731,1.172576,-125.747650,0.117413,0.000000
92.130005,64.280800,-125.792130,0.014728,0.004616,0.117258,285.935272,14.566237,1.172576,-125.792130,0.117413,0.000000
92.410004,64.209671,-125.703171,0.014741,0.004616,0.117258,285.618896,14.550119,1.172576,-125.703171,0.117413,0.000000
92.690002,64.120308,-125.703171,0.014715,0.004616,0.117258,285.221375,14.529869,1.172576,-125.703171,0.117413,0.000000
92.970001,64.019394,-125.703171,0.014728,0.004616,0.117258,284.772491,14.507002,1.172576,-125.703171,0.117413,0.000000
93.250008,63.954597,-125.703171,0.014715,0.004616,0.117258,284.484253,14.492319,1.172576,-125.703171,0.117413,0.000000
93.530006,63.854801,-125.658684,0.014745,0.004616,0.117258,284.040344,14.469705,1.172576,-125.658684,0.117413,0.000000
93.810005,63.806767,-125.658684,0.014741,0.004616,0.117258,283.826660,14.458819,1.172576,-125.658684,0.117413,0.000000
94.090004,63.735641,-125.658684,0.014702,0.004616,0.117258,283.510284,14.442703,1.172576,-125.658684,0.117413,0.000000
94.370003,63.673084,-125.703171,0.014745,0.004616,0.117258,283.232025,14.428527,1.172576,-125.703171,0.117413,0.000000
94.650002,63.612759,-125.614204,0.014745,0.004616,0.117258,282.963684,14.414857,1.172576,-125.614204,0.117413,0.000000
94.930008,63.560627,-125.614204,0.014732,0.004616,0.117258,282.731781,14.403044,1.172576,-125.614204,0.117413,0.000000
95.210007,63.504772,-125.569725,0.014732,0.004616,0.117258,282.483337,14.390387,1.172576,-125.569725,0.117413,0.000000
95.490005,63.454128,-125.569725,0.014754,0.004616,0.117248,282.258057,14.378911,1.172485,-125.569725,0.117413,0.000000
95.770004,63.389709,-125.569725,0.014754,0.004616,0.117248,281.971497,14.364313,1.172485,-125.569725,0.117413,0.000000
96.050003,63.352097,-125.569725,0.014737,0.004616,0.117248,281.804199,14.355790,1.172485,-125.569725,0.117413,0.000000
96.330002,63.302200,-125.569725,0.014737,0.004616,0.117248,281.582245,14.344483,1.172485,-125.569725,0.117413,0.000000
96.610008,63.254536,-125.569725,0.014732,0.004616,0.117248,281.370239,14.333683,1.172485,-125.569725,0.117413,0.000000
96.890007,63.211712,-125.569725,0.014754,0.004616,0.117248,281.179749,14.323978,1.172485,-125.569725,0.117413,0.000000
97.170006,63.153252,-125.569725,0.014728,0.004616,0.117248,280.919708,14.310731,1.172485,-125.569725,0.117413,0.000000
97.450005,63.110058,-125.480766,0.014732,0.004616,0.117248,280.727570,14.300943,1.172485,-125.480766,0.117413,0.000000
97.730003,63.076172,-125.436279,0.014745,0.004616,0.117248,280.576813,14.293265,1.172485,-125.436279,0.117413,0.000000
98.010002,63.049358,-125.391800,0.014737,0.004616,0.117248,280.457550,14.287189,1.172485,-125.391800,0.117413,0.000000
98.290001,63.006535,-125.480766,0.014724,0.004616,0.117248,280.267059,14.277485,1.172485,-125.480766,0.117413,0.000000
98.570007,62.968925,-125.480766,0.014724,0.004616,0.117248,280.099762,14.268962,1.172485,-125.480766,0.117413,0.000000
98.850006,62.924988,-125.436279,0.014724,0.004616,0.117248,279.904327,14.259006,1.172485,-125.436279,0.117413,0.000000
99.130005,62.890358,-125.391800,0.014745,0.004616,0.117248,279.750275,14.251159,1.172485,-125.391800,0.117413,0.000000
99.410004,62.849396,-125.347321,0.014745,0.004616,0.117248,279.568085,14.241877,1.172485,-125.347321,0.117413,0.000000
99.690002,62.824818,-125.391800,0.014732,0.004616,0.117248,279.458740,14.236307,1.172485,-125.391800,0.117413,0.000000
99.970001,62.788700,-125.391800,0.014745,0.004616,0.117248,279.298096,14.228123,1.172485,-125.391800,0.117413,0.000000
100.250008,62.746994,-125.302841,0.014720,0.004616,0.117248,279.112579,14.218672,1.172485,-125.302841,0.117413,0.000000
100.530006,62.725395,-125.347321,0.014737,0.004616,0.117248,279.016479,14.213778,1.172485,-125.347321,0.117413,0.000000
100.810005,62.694489,-125.302841,0.014745,0.004616,0.117248,278.879028,14.206774,1.172485,-125.302841,0.117413,0.000000
101.090004,62.652039,-125.302841,0.014754,0.004616,0.117248,278.690186,14.197155,1.172485,-125.302841,0.117413,0.000000
101.370003,62.633793,-125.347321,0.014763,0.004616,0.117248,278.609039,14.193020,1.172485,-125.347321,0.117413,0.000000
101.650002,62.598789,-125.258362,0.014750,0.004616,0.117248,278.453308,14.185088,1.172485,-125.258362,0.117413,0.000000
101.930008,62.596928,-125.213875,0.014732,0.004616,0.117248,278.445038,14.184667,1.172485,-125.213875,0.117413,0.000000
102.210007,62.546658,-125.169395,0.014724,0.004616,0.117248,278.221436,14.173275,1.172485,-125.169395,0.117413,0.000000
102.490005,62.527664,-125.213875,0.014750,0.004616,0.117248,278.136932,14.168972,1.172485,-125.213875,0.117413,0.000000
102.770004,62.505695,-125.258362,0.014724,0.004616,0.117248,278.039215,14.163993,1.172485,-125.258362,0.117413,0.000000
103.050003,62.468460,-125.258362,0.014732,0.004616,0.117248,277.873596,14.155556,1.172485,-125.258362,0.117413,0.000000
103.330002,62.433826,-125.124916,0.014728,0.004616,0.117248,277.719543,14.147707,1.172485,-125.124916,0.117413,0.000000
103.610008,62.420052,-125.169395,0.014728,0.004616,0.117248,277.658264,14.144586,1.172485,-125.169395,0.117413,0.000000
103.890007,62.391376,-125.169395,0.014741,0.004616,0.117241,277.530701,14.138088,1.172409,-125.169395,0.117413,0.000000
104.170006,62.374992,-125.169395,0.014758,0.004616,0.117241,277.457825,14.134376,1.172409,-125.169395,0.117413,0.000000
104.450005,62.340733,-125.124916,0.014737,0.004616,0.117241,277.305420,14.126612,1.172409,-125.124916,0.117413,0.000000
104.730003,62.320625,-125.080437,0.014745,0.004616,0.117241,277.215973,14.122055,1.172409,-125.080437,0.117413,0.000000
105.010002,62.303123,-125.080437,0.014715,0.004616,0.117241,277.138123,14.118090,1.172409,-125.080437,0.117413,0.000000
105.290009,62.277058,-125.080437,0.014741,0.004616,0.117241,277.022186,14.112184,1.172409,-125.080437,0.117413,0.000000
105.570007,62.255833,-125.124916,0.014754,0.004616,0.117241,276.927765,14.107373,1.172409,-125.124916,0.117413,0.000000
105.850006,62.237587,-125.080437,0.014763,0.004616,0.117241,276.846619,14.103238,1.172409,-125.080437,0.117413,0.000000
106.130005,62.206306,-125.080437,0.014732,0.004616,0.117241,276.707458,14.096151,1.172409,-125.080437,0.117413,0.000000
106.410004,62.194763,-124.991470,0.014728,0.004616,0.117241,276.656128,14.093534,1.172409,-124.991470,0.117413,0.000000
106.690002,62.180241,-125.035950,0.014763,0.004616,0.117241,276.591522,14.090243,1.172409,-125.035950,0.117413,0.000000
106.970009,62.137047,-125.035950,0.014754,0.004616,0.117241,276.399384,14.080456,1.172409,-125.035950,0.117413,0.000000
107.250008,62.131462,-124.991470,0.014737,0.004616,0.117241,276.374542,14.079190,1.172409,-124.991470,0.117413,0.000000
107.530006,62.096832,-124.946991,0.014728,0.004616,0.117241,276.220520,14.071343,1.172409,-124.946991,0.117413,0.000000
107.810005,62.083797,-124.946991,0.014715,0.004616,0.117241,276.162537,14.068389,1.172409,-124.946991,0.117413,0.000000
108.090004,62.059219,-124.991470,0.014728,0.004616,0.117241,276.053192,14.062820,1.172409,-124.991470,0.117413,0.000000
108.370003,62.035763,-124.991470,0.014737,0.004616,0.117241,275.948853,14.057505,1.172409,-124.991470,0.117413,0.000000
108.650002,62.030922,-124.902512,0.014750,0.004616,0.117241,275.927307,14.056407,1.172409,-124.902512,0.117413,0.000000
108.930008,62.021240,-124.902512,0.014732,0.004616,0.117241,275.884247,14.054214,1.172409,-124.902512,0.117413,0.000000
109.210007,61.993313,-124.902512,0.014754,0.004616,0.117241,275.760040,14.047886,1.172409,-124.902512,0.117413,0.000000
109.490005,61.979534,-124.902512,0.014780,0.004616,0.117241,275.698730,14.044764,1.172409,-124.902512,0.117413,0.000000
109.770004,61.964268,-124.858032,0.014724,0.004616,0.117241,275.630829,14.041304,1.172409,-124.858032,0.117413,0.000000
110.050003,61.944904,-124.902512,0.014745,0.004616,0.117241,275.544708,14.036916,1.172409,-124.902512,0.117413,0.000000
110.330002,61.925911,-124.769066,0.014758,0.004616,0.117241,275.460205,14.032612,1.172409,-124.769066,0.117413,0.000000
110.610008,61.895004,-124.813545,0.014732,0.004616,0.117241,275.322723,14.025608,1.172409,-124.813545,0.117413,0.000000
110.890007,61.892025,-124.858032,0.014745,0.004616,0.117241,275.309479,14.024934,1.172409,-124.858032,0.117413,0.000000
111.170006,61.880482,-124.813545,0.014763,0.004616,0.117241,275.258118,14.022318,1.172409,-124.813545,0.117413,0.000000
111.450005,61.857395,-124.902512,0.014732,0.004616,0.117241,275.155426,14.017086,1.172409,-124.902512,0.117413,0.000000
111.730003,61.854042,-124.769066,0.014732,0.004616,0.117241,275.140533,14.016326,1.172409,-124.769066,0.117413,0.000000
112.010002,61.837658,-124.724586,0.014758,0.004616,0.117241,275.067627,14.012613,1.172409,-124.724586,0.117413,0.000000
112.290009,61.827232,-124.724586,0.014737,0.004616,0.117241,275.021271,14.010251,1.172409,-124.724586,0.117413,0.000000
112.570007,61.796700,-124.813545,0.014745,0.004616,0.117241,274.885437,14.003332,1.172409,-124.813545,0.117413,0.000000
112.850006,61.771748,-124.769066,0.014745,0.004616,0.117241,274.774445,13.997679,1.172409,-124.769066,0.117413,0.000000
113.130005,61.770634,-124.724586,0.014754,0.004616,0.117241,274.769501,13.997426,1.172409,-124.724586,0.117413,0.000000
113.410004,61.742702,-124.680107,0.014758,0.004616,0.117241,274.645264,13.991096,1.172409,-124.680107,0.117413,0.000000
113.690002,61.731907,-124.724586,0.014754,0.004616,0.117241,274.597229,13.988649,1.172409,-124.724586,0.117413,0.000000
113.970009,61.702488,-124.724586,0.014728,0.004616,0.117241,274.466370,13.981983,1.172409,-124.724586,0.117413,0.000000
114.250008,61.701370,-124.680107,0.014754,0.004616,0.117241,274.461395,13.981730,1.172409,-124.680107,0.117413,0.000000
114.530006,61.680889,-124.680107,0.014741,0.004616,0.117241,274.370300,13.977089,1.172409,-124.680107,0.117413,0.000000
114.810005,61.669720,-124.591141,0.014754,0.004616,0.117241,274.320618,13.974558,1.172409,-124.591141,0.117413,0.000000
115.090004,61.657433,-124.591141,0.014728,0.004616,0.117241,274.265961,13.971774,1.172409,-124.591141,0.117413,0.000000
115.370003,61.648121,-124.546661,0.014754,0.004616,0.117241,274.224548,13.969665,1.172409,-124.546661,0.117413,0.000000
115.650009,61.628014,-124.635628,0.014728,0.004616,0.117241,274.135101,13.965108,1.172409,-124.635628,0.117413,0.000000
115.930008,61.612747,-124.591141,0.014724,0.004616,0.117241,274.067200,13.961648,1.172409,-124.591141,0.117413,0.000000
116.210007,61.607906,-124.502182,0.014758,0.004616,0.117241,274.045654,13.960551,1.172409,-124.502182,0.117413,0.000000
116.490005,61.582211,-124.546661,0.014771,0.004616,0.117241,273.931366,13.954728,1.172409,-124.546661,0.117413,0.000000
116.770004,61.574390,-124.546661,0.014763,0.004616,0.117241,273.896576,13.952956,1.172409,-124.546661,0.117413,0.000000
117.050003,61.553539,-124.546661,0.014724,0.004616,0.117241,273.803802,13.948232,1.172409,-124.546661,0.117413,0.000000
117.330002,61.536411,-124.546661,0.014754,0.004616,0.117241,273.727631,13.944350,1.172409,-124.546661,0.117413,0.000000
117.610008,61.530823,-124.502182,0.014771,0.004616,0.117241,273.702759,13.943084,1.172409,-124.502182,0.117413,0.000000
117.890007,61.530453,-124.502182,0.014741,0.004616,0.117241,273.701111,13.943000,1.172409,-124.502182,0.117413,0.000000
118.170006,61.506992,-124.502182,0.014745,0.004616,0.117241,273.596771,13.937684,1.172409,-124.502182,0.117413,0.000000
118.450005,61.488373,-124.502182,0.014767,0.004616,0.117241,273.513947,13.933464,1.172409,-124.502182,0.117413,0.000000
118.600006,61.487629,-124.457703,0.014728,0.004616,0.117241,273.510620,13.933296,1.172409,-124.457703,0.117413,0.000000