File: Data/New old I18 3_08182023_115753.csv
Time (sec),S:Load (lbs),S:HL1 (DIM),S:LVDT (in),S:Position (in),Ch:Position (mm),Ch:Load (N),Ch:Stress (MPa),Ch:Strain (mm/mm),Ch:HL1 (DIM),Set Point (),Cycles ()
0.110000,-0.004097,-21.306376,-0.000013,-0.000000,-0.000000,-0.018224,-0.000928,-0.000000,-21.306376,0.000174,0.000000
0.400000,-0.023834,-21.172934,-0.000034,0.000001,0.000018,-0.106020,-0.005401,0.000182,-21.172934,0.000416,0.000000
0.690000,-0.038361,-21.350857,-0.000034,0.000160,0.004076,-0.170636,-0.008693,0.040756,-21.350857,0.005238,0.000000
0.980000,0.014893,-21.261894,0.000129,0.000344,0.008742,0.066245,0.003375,0.087416,-21.261894,0.010077,0.000000
1.270000,-0.016014,-21.306376,0.000341,0.000545,0.013850,-0.071234,-0.003629,0.138497,-21.306376,0.014899,0.000000
1.560000,0.014893,-21.306376,0.000560,0.000727,0.018464,0.066245,0.003375,0.184642,-21.306376,0.019739,0.000000
1.850000,0.017128,-21.306376,0.000742,0.000922,0.023424,0.076189,0.003881,0.234240,-21.306376,0.024578,0.000000
2.140000,0.014145,-21.350857,0.000949,0.001109,0.028160,0.062920,0.003205,0.281596,-21.350857,0.029400,0.000000
2.430000,-0.007820,-21.306376,0.001143,0.001300,0.033024,-0.034786,-0.001772,0.330240,-21.306376,0.034238,0.000000
2.720000,0.006699,-21.306376,0.001311,0.001486,0.037734,0.029797,0.001518,0.377339,-21.306376,0.039060,0.000000
3.010000,0.034256,-21.350857,0.001522,0.001680,0.042668,0.152378,0.007763,0.426679,-21.350857,0.043899,0.000000
3.300000,0.036865,-21.350857,0.001725,0.001870,0.047490,0.163985,0.008354,0.474898,-21.350857,0.048721,0.000000
3.590000,0.023827,-21.395338,0.001927,0.002065,0.052459,0.105986,0.005399,0.524586,-21.395338,0.053561,0.000000
3.880000,0.036491,-21.395338,0.002126,0.002251,0.057176,0.162322,0.008269,0.571761,-21.395338,0.058381,0.000000
4.170000,0.010796,-21.395338,0.002324,0.002445,0.062112,0.048021,0.002446,0.621116,-21.395338,0.063221,0.000000
4.460000,0.030533,-21.395338,0.002539,0.002633,0.066890,0.135817,0.006919,0.668897,-21.395338,0.068060,0.000000
4.750000,0.010048,-21.350857,0.002712,0.002824,0.071737,0.044695,0.002277,0.717374,-21.350857,0.072882,0.000000
5.040000,0.031647,-21.484299,0.002915,0.003010,0.076464,0.140772,0.007171,0.764640,-21.484299,0.077721,0.000000
5.330000,0.031647,-21.350857,0.003143,0.003205,0.081407,0.140772,0.007171,0.814070,-21.350857,0.082543,0.000000
5.620000,0.024948,-21.439819,0.003328,0.003394,0.086211,0.110975,0.005653,0.862108,-21.439819,0.087383,0.000000
5.910000,0.027184,-21.439819,0.003579,0.003588,0.091128,0.120918,0.006160,0.911282,-21.439819,0.092203,0.000000
6.200000,0.022713,-21.439819,0.003747,0.003773,0.095829,0.101031,0.005147,0.958290,-21.439819,0.097043,0.000000
6.490000,-0.001495,-21.484299,0.003936,0.003969,0.100807,-0.006652,-0.000339,1.008069,-21.484299,0.101865,0.000000
6.780000,0.033134,-21.484299,0.004130,0.004154,0.105506,0.147389,0.007508,1.055062,-21.484299,0.106704,0.000000
7.070000,0.010422,-21.439819,0.004329,0.004347,0.110416,0.046358,0.002362,1.104160,-21.439819,0.111526,0.000000
7.360000,0.051384,-21.528780,0.004518,0.004535,0.115185,0.228567,0.011644,1.151850,-21.528780,0.116364,0.000000
7.650001,0.045425,-21.439819,0.004712,0.004730,0.120146,0.202062,0.010294,1.201462,-21.439819,0.121204,0.000000
7.940001,0.031647,-21.528780,0.004915,0.004920,0.124959,0.140772,0.007171,1.249591,-21.528780,0.126025,0.000000
8.230000,0.046547,-21.439819,0.005139,0.005107,0.129728,0.207051,0.010548,1.297280,-21.439819,0.130865,0.000000
8.520000,0.038727,-21.484299,0.005329,0.005299,0.134585,0.172265,0.008776,1.345848,-21.484299,0.135687,0.000000
8.810000,0.017868,-21.484299,0.005532,0.005488,0.139398,0.079481,0.004049,1.393977,-21.484299,0.140526,0.000000
9.100000,0.028671,-21.484299,0.005713,0.005676,0.144177,0.127536,0.006497,1.441772,-21.484299,0.145348,0.000000
9.390000,0.051758,-21.528780,0.005946,0.005868,0.149058,0.230230,0.011728,1.490582,-21.528780,0.150186,0.000000
9.680000,0.045799,-21.484299,0.006144,0.006059,0.153889,0.203725,0.010378,1.538893,-21.484299,0.155008,0.000000
9.970000,0.049149,-21.484299,0.006347,0.006253,0.158823,0.218624,0.011137,1.588233,-21.484299,0.159847,0.000000
10.260000,0.028297,-21.573261,0.006584,0.006441,0.163594,0.125873,0.006412,1.635938,-21.573261,0.164687,0.000000
10.550000,0.037605,-21.573261,0.006760,0.006632,0.168441,0.167277,0.008521,1.684415,-21.573261,0.169509,0.000000
10.840000,0.028671,-21.617743,0.006942,0.006821,0.173254,0.127536,0.006497,1.732543,-21.617743,0.174347,0.000000
11.130000,0.031273,-21.484299,0.007131,0.007011,0.178067,0.139109,0.007087,1.780672,-21.484299,0.179169,0.000000
11.420000,0.052872,-21.573261,0.007338,0.007199,0.182863,0.235185,0.011981,1.828634,-21.573261,0.184008,0.000000
11.710001,0.056229,-21.573261,0.007524,0.007393,0.187772,0.250117,0.012742,1.877717,-21.573261,0.188830,0.000000
12.000001,0.032768,-21.528780,0.007743,0.007584,0.192645,0.145760,0.007425,1.926451,-21.528780,0.193669,0.000000
12.290001,0.051010,-21.617743,0.007938,0.007776,0.197520,0.226904,0.011559,1.975200,-21.617743,0.198490,0.000000
12.580001,0.028671,-21.617743,0.008144,0.007960,0.202194,0.127536,0.006497,2.021936,-21.617743,0.203331,0.000000
12.870001,0.039093,-21.662224,0.008343,0.008156,0.207155,0.173894,0.008859,2.071549,-21.662224,0.208169,0.000000
13.160001,0.036865,-21.617743,0.008515,0.008340,0.211847,0.163985,0.008354,2.118466,-21.617743,0.212991,0.000000
13.450001,0.017502,-21.617743,0.008727,0.008534,0.216772,0.077852,0.003966,2.167715,-21.617743,0.217830,0.000000
13.740001,0.055855,-21.662224,0.008908,0.008722,0.221542,0.248455,0.012657,2.215420,-21.662224,0.222652,0.000000
14.030001,0.070000,-21.662224,0.009119,0.008917,0.226485,0.311374,0.015862,2.264851,-21.662224,0.227490,0.000000
14.320001,0.043190,-21.617743,0.009304,0.009103,0.231228,0.192119,0.009787,2.312283,-21.617743,0.232312,0.000000
14.610001,0.060318,-21.706703,0.009528,0.009295,0.236085,0.268308,0.013668,2.360851,-21.706703,0.237152,0.000000
14.900001,0.040955,-21.662224,0.009710,0.009480,0.240786,0.182175,0.009280,2.407859,-21.662224,0.241973,0.000000
15.190001,0.028671,-21.751184,0.009899,0.009676,0.245780,0.127536,0.006497,2.457805,-21.751184,0.246813,0.000000
15.480000,0.046913,-21.662224,0.010123,0.009863,0.250516,0.208680,0.010631,2.505162,-21.662224,0.251635,0.000000
15.770000,0.053619,-21.706703,0.010305,0.010053,0.255355,0.238511,0.012150,2.553548,-21.706703,0.256474,0.000000
16.060001,0.052872,-21.706703,0.010516,0.010245,0.260221,0.235185,0.011981,2.602206,-21.706703,0.261312,0.000000
16.350000,0.085640,-21.706703,0.010701,0.010436,0.265076,0.380946,0.019406,2.650759,-21.706703,0.266134,0.000000
16.640001,0.061440,-21.795666,0.010900,0.010626,0.269890,0.273297,0.013922,2.698903,-21.795666,0.270974,0.000000
16.930000,0.052872,-21.706703,0.011094,0.010814,0.274668,0.235185,0.011981,2.746683,-21.706703,0.275795,0.000000
17.220001,0.037979,-21.751184,0.011292,0.011001,0.279437,0.168940,0.008606,2.794373,-21.751184,0.280635,0.000000
17.510000,0.054733,-21.795666,0.011507,0.011196,0.284373,0.243466,0.012403,2.843728,-21.795666,0.285457,0.000000
17.800001,0.046913,-21.751184,0.011693,0.011384,0.289142,0.208680,0.010631,2.891418,-21.751184,0.290295,0.000000
18.090000,0.075592,-21.795666,0.011900,0.011575,0.293999,0.336250,0.017129,2.939985,-21.795666,0.295117,0.000000
18.380001,0.054733,-21.751184,0.012102,0.011767,0.298890,0.243466,0.012403,2.988901,-21.751184,0.299956,0.000000
18.670000,0.077454,-21.751184,0.012284,0.011958,0.303738,0.344531,0.017551,3.037378,-21.751184,0.304796,0.000000
18.960001,0.057716,-21.795666,0.012512,0.012148,0.308567,0.256735,0.013079,3.085674,-21.795666,0.309617,0.000000
19.250000,0.057343,-21.751184,0.012693,0.012336,0.313347,0.255072,0.012994,3.133469,-21.751184,0.314457,0.000000
19.540001,0.030907,-21.840147,0.012866,0.012522,0.318046,0.137480,0.007004,3.180462,-21.840147,0.319279,0.000000
19.830002,0.071495,-21.751184,0.013090,0.012719,0.323068,0.318026,0.016201,3.230680,-21.751184,0.324117,0.000000
20.120001,0.084152,-21.840147,0.013279,0.012905,0.327776,0.374328,0.019069,3.277765,-21.840147,0.328939,0.000000
20.410002,0.147453,-21.840147,0.013482,0.013098,0.332685,0.655905,0.033413,3.326847,-21.840147,0.333778,0.000000
20.700001,0.189537,-21.795666,0.013685,0.013285,0.337429,0.843103,0.042950,3.374295,-21.795666,0.338600,0.000000
20.990002,0.450569,-21.840147,0.013866,0.013478,0.342338,2.004232,0.102100,3.423377,-21.840147,0.343438,0.000000
21.280001,0.671753,-21.840147,0.014008,-0.000002,-0.000051,2.988106,0.152221,-0.000515,-21.840147,0.000165,0.000000
21.570002,0.638985,-21.884628,0.014021,-0.000002,-0.000051,2.842346,0.144796,-0.000515,-21.884628,0.000165,0.000000
21.860001,0.635635,-21.884628,0.014030,-0.000002,-0.000051,2.827447,0.144037,-0.000515,-21.884628,0.000372,0.000000
22.150002,0.633034,-21.751184,0.014008,-0.000001,-0.000026,2.815875,0.143448,-0.000257,-21.751184,0.000858,0.000000
22.440001,0.676224,-21.929110,0.014017,0.000019,0.000486,3.007993,0.153234,0.004860,-21.929110,0.001344,0.000000
22.730001,0.734314,-21.884628,0.014034,0.000038,0.000963,3.266392,0.166398,0.009629,-21.884628,0.001821,0.000000
23.020000,0.767830,-21.884628,0.014043,0.000053,0.001353,3.415478,0.173993,0.013535,-21.884628,0.002307,0.000000
23.310001,0.811028,-21.929110,0.014068,0.000066,0.001682,3.607631,0.183781,0.016820,-21.929110,0.002792,0.000000
23.600000,0.920502,-21.840147,0.014077,0.000092,0.002333,4.094596,0.208589,0.023330,-21.840147,0.003278,0.000000
23.890001,0.935394,-21.884628,0.014120,0.000105,0.002663,4.160841,0.211963,0.026631,-21.884628,0.003755,0.000000
24.180000,1.005028,-21.884628,0.014120,0.000127,0.003217,4.470587,0.227743,0.032172,-21.884628,0.004241,0.000000
24.470001,1.096260,-21.884628,0.014133,0.000154,0.003920,4.876409,0.248416,0.039196,-21.884628,0.004727,0.000000
24.760000,1.126793,-21.973589,0.014159,0.000166,0.004206,5.012225,0.255335,0.042058,-21.973589,0.005213,0.000000
25.050001,1.153610,-21.884628,0.014181,0.000185,0.004692,5.131515,0.261412,0.046918,-21.884628,0.005689,0.000000
25.340002,1.246696,-21.973589,0.014189,0.000204,0.005178,5.545583,0.282505,0.051777,-21.973589,0.006174,0.000000
25.630001,1.338303,-21.929110,0.014215,0.000223,0.005671,5.953067,0.303264,0.056713,-21.929110,0.006660,0.000000
25.920002,1.405327,-21.929110,0.014224,0.000241,0.006132,6.251206,0.318452,0.061315,-21.929110,0.007146,0.000000
26.210001,1.510338,-21.973589,0.014258,0.000264,0.006695,6.718318,0.342247,0.066947,-21.973589,0.007623,0.000000
26.500002,1.596359,-21.973589,0.014271,0.000283,0.007190,7.100961,0.361740,0.071898,-21.973589,0.008109,0.000000
26.790001,1.638809,-21.929110,0.014288,0.000297,0.007553,7.289787,0.371359,0.075531,-21.929110,0.008595,0.000000
27.080002,1.702110,-22.018070,0.014327,0.000315,0.008013,7.571365,0.385704,0.080134,-22.018070,0.009072,0.000000
27.370001,1.812706,-21.973589,0.014319,0.000335,0.008499,8.063319,0.410765,0.084994,-21.973589,0.009556,0.000000
27.660002,1.925163,-21.973589,0.014357,0.000352,0.008932,8.563554,0.436248,0.089324,-21.973589,0.010042,0.000000
27.950001,2.010811,-21.929110,0.014366,0.000367,0.009323,8.944533,0.455656,0.093230,-21.929110,0.010528,0.000000
28.240002,2.145607,-22.018070,0.014409,0.000394,0.010016,9.544137,0.486201,0.100163,-22.018070,0.011005,0.000000
28.530001,2.225670,-21.973589,0.014422,0.000413,0.010493,9.900274,0.504344,0.104932,-21.973589,0.011491,0.000000
28.820002,2.249496,-21.973589,0.014431,0.000430,0.010926,10.006260,0.509743,0.109262,-21.973589,0.011977,0.000000
29.110001,2.355621,-22.018070,0.014457,0.000447,0.011343,10.478327,0.533791,0.113426,-22.018070,0.012461,0.000000
29.400002,2.541069,-22.018070,0.014482,0.000471,0.011959,11.303240,0.575814,0.119588,-22.018070,0.012938,0.000000
29.690001,2.599159,-22.062551,0.014482,0.000480,0.012193,11.561638,0.588978,0.121934,-22.062551,0.013424,0.000000
29.980001,2.767471,-22.062551,0.014478,0.000508,0.012913,12.310328,0.627118,0.129125,-22.062551,0.013910,0.000000
30.270002,2.882530,-22.062551,0.014513,0.000529,0.013442,12.822135,0.653191,0.134424,-22.062551,0.014396,0.000000
30.560001,3.009140,-22.107033,0.014521,0.000546,0.013859,13.385324,0.681881,0.138588,-22.107033,0.014873,0.000000
30.850002,3.090317,-22.018070,0.014573,0.000564,0.014327,13.746415,0.700276,0.143266,-22.018070,0.015359,0.000000
31.140001,3.187508,-22.107033,0.014564,0.000581,0.014752,14.178742,0.722300,0.147520,-22.107033,0.015844,0.000000
31.430002,3.393799,-22.062551,0.014599,0.000599,0.015211,15.096371,0.769046,0.152107,-22.062551,0.016330,0.000000
31.720001,3.492851,-22.107033,0.014590,0.000614,0.015601,15.536979,0.791491,0.156013,-22.107033,0.016806,0.000000
32.010002,3.623924,-22.151514,0.014629,0.000629,0.015966,16.120020,0.821193,0.159662,-22.151514,0.017292,0.000000
32.300003,3.849586,-22.062551,0.014646,0.000660,0.016772,17.123816,0.872329,0.167716,-22.062551,0.017778,0.000000
32.590000,3.956825,-22.151514,0.014655,0.000676,0.017180,17.600838,0.896629,0.171804,-22.151514,0.018255,0.000000
32.880001,4.055504,-22.062551,0.014685,0.000690,0.017535,18.039782,0.918990,0.175347,-22.062551,0.018741,0.000000
33.170002,4.179504,-22.107033,0.014694,0.000709,0.018012,18.591364,0.947089,0.180116,-22.107033,0.019226,0.000000
33.460003,4.416336,-22.195995,0.014724,0.000733,0.018611,19.644844,1.000756,0.186111,-22.195995,0.019712,0.000000
33.750000,4.467720,-22.107033,0.014732,0.000742,0.018837,19.873411,1.012400,0.188367,-22.107033,0.020189,0.000000
34.040001,4.741417,-22.240475,0.014754,0.000767,0.019469,21.090876,1.074420,0.194695,-22.240475,0.020675,0.000000
34.330002,4.962234,-22.151514,0.014793,0.000793,0.020154,22.073122,1.124458,0.201538,-22.151514,0.021161,0.000000
34.620003,5.083252,-22.195995,0.014789,0.000808,0.020535,22.611435,1.151881,0.205353,-22.195995,0.021647,0.000000
34.910000,5.262733,-22.240475,0.014797,0.000829,0.021056,23.409807,1.192552,0.210561,-22.240475,0.022123,0.000000
35.200001,5.486908,-22.151514,0.014827,0.000851,0.021612,24.406986,1.243351,0.216118,-22.151514,0.022608,0.000000
35.490002,5.626175,-22.240475,0.014827,0.000865,0.021958,25.026476,1.274909,0.219584,-22.240475,0.023094,0.000000
35.780003,5.881622,-22.195995,0.014866,0.000887,0.022522,26.162764,1.332795,0.225216,-22.195995,0.023580,0.000000
36.070004,6.090149,-22.195995,0.014883,0.000905,0.022989,27.090336,1.380047,0.229895,-22.195995,0.024057,0.000000
36.360001,6.299797,-22.240475,0.014892,0.000926,0.023519,28.022898,1.427554,0.235193,-22.240475,0.024543,0.000000
36.650002,6.424164,-22.240475,0.014914,0.000942,0.023936,28.576107,1.455736,0.239357,-22.240475,0.025029,0.000000
36.940002,6.611473,-22.240475,0.014939,0.000958,0.024326,29.409302,1.498181,0.243263,-22.240475,0.025513,0.000000
37.230003,6.967827,-22.195995,0.014952,0.000986,0.025045,30.994442,1.578932,0.250454,-22.195995,0.025990,0.000000
37.520000,7.039696,-22.240475,0.014978,0.000996,0.025297,31.314131,1.595218,0.252967,-22.240475,0.026476,0.000000
37.810001,7.317863,-22.284956,0.014987,0.001017,0.025834,32.551483,1.658252,0.258342,-22.284956,0.026962,0.000000
38.100002,7.632889,-22.284956,0.015013,0.001043,0.026494,33.952785,1.729637,0.264943,-22.284956,0.027439,0.000000
38.390003,7.802315,-22.284956,0.015039,0.001057,0.026849,34.706429,1.768030,0.268485,-22.284956,0.027925,0.000000
38.680000,8.033562,-22.284956,0.015047,0.001075,0.027300,35.735065,1.820431,0.272997,-22.284956,0.028411,0.000000
38.970001,8.130379,-22.329437,0.015043,0.001086,0.027595,36.165730,1.842370,0.275949,-22.329437,0.028895,0.000000
39.260002,8.546692,-22.373919,0.015069,0.001114,0.028297,38.017586,1.936708,0.282974,-22.373919,0.029372,0.000000
39.550003,8.662872,-22.284956,0.015095,0.001125,0.028584,38.534382,1.963035,0.285835,-22.284956,0.029858,0.000000
39.840000,9.104874,-22.373919,0.015086,0.001155,0.029347,40.500500,2.063194,0.293466,-22.373919,0.030344,0.000000
40.130001,9.400909,-22.284956,0.015125,0.001175,0.029842,41.817333,2.130277,0.298416,-22.284956,0.030830,0.000000
40.420002,9.549118,-22.284956,0.015142,0.001190,0.030231,42.476597,2.163861,0.302307,-22.284956,0.031307,0.000000
40.710003,9.768440,-22.418400,0.015164,0.001207,0.030665,43.452194,2.213560,0.306652,-22.418400,0.031793,0.000000
41.000004,10.111771,-22.284956,0.015177,0.001227,0.031159,44.979401,2.291360,0.311588,-22.284956,0.032278,0.000000
41.290001,10.403709,-22.373919,0.015198,0.001248,0.031689,46.278011,2.357514,0.316887,-22.373919,0.032764,0.000000
41.580002,10.564201,-22.329437,0.015181,0.001263,0.032079,46.991913,2.393882,0.320793,-22.329437,0.033240,0.000000
41.870003,11.021103,-22.329437,0.015207,0.001287,0.032677,49.024315,2.497417,0.326773,-22.329437,0.033726,0.000000
42.160004,11.273949,-22.329437,0.015258,0.001303,0.033085,50.149029,2.554713,0.330845,-22.329437,0.034212,0.000000
42.450001,11.515991,-22.329437,0.015258,0.001322,0.033580,51.225689,2.609561,0.335796,-22.329437,0.034697,0.000000
42.740002,11.924477,-22.373919,0.015280,0.001346,0.034194,53.042721,2.702125,0.341943,-22.373919,0.035175,0.000000
43.030003,12.141945,-22.329437,0.015284,0.001361,0.034559,54.010067,2.751404,0.345591,-22.329437,0.035660,0.000000
43.320004,12.335953,-22.418400,0.015297,0.001375,0.034915,54.873058,2.795367,0.349149,-22.418400,0.036146,0.000000
43.610001,12.693802,-22.418400,0.015332,0.001399,0.035522,56.464851,2.876457,0.355220,-22.418400,0.036623,0.000000
43.900002,13.126129,-22.418400,0.015371,0.001423,0.036137,58.387939,2.974423,0.361367,-22.418400,0.037109,0.000000
44.190002,13.405403,-22.462881,0.015353,0.001440,0.036571,59.630211,3.037708,0.365712,-22.462881,0.037595,0.000000
44.480003,13.599785,-22.418400,0.015358,0.001454,0.036944,60.494865,3.081755,0.369436,-22.418400,0.038079,0.000000
44.770000,13.779266,-22.418400,0.015383,0.001470,0.037334,61.293240,3.122426,0.373342,-22.418400,0.038557,0.000000
45.060001,14.206009,-22.418400,0.015422,0.001490,0.037855,63.191483,3.219128,0.378550,-22.418400,0.039042,0.000000
45.350002,14.451775,-22.462881,0.015401,0.001510,0.038358,64.284706,3.274819,0.383576,-22.462881,0.039528,0.000000
45.640003,14.758606,-22.507360,0.015431,0.001528,0.038816,65.649559,3.344348,0.388164,-22.507360,0.040014,0.000000
45.930000,15.257957,-22.418400,0.015465,0.001555,0.039493,67.870781,3.457503,0.394931,-22.418400,0.040491,0.000000
46.220001,15.404305,-22.507360,0.015465,0.001571,0.039909,68.521767,3.490665,0.399094,-22.507360,0.040977,0.000000
46.510002,15.727150,-22.462881,0.015491,0.001589,0.040370,69.957855,3.563823,0.403697,-22.462881,0.041461,0.000000
46.800003,15.970680,-22.462881,0.015496,0.001606,0.040803,71.041130,3.619008,0.408027,-22.462881,0.041947,0.000000
47.090004,16.384010,-22.507360,0.015513,0.001626,0.041305,72.879715,3.712670,0.413053,-22.507360,0.042424,0.000000
47.380001,16.404121,-22.462881,0.015530,0.001636,0.041566,72.969177,3.717227,0.415657,-22.462881,0.042910,0.000000
47.670002,17.022629,-22.551842,0.015521,0.001666,0.042329,75.720436,3.857383,0.423288,-22.551842,0.043396,0.000000
47.960003,17.297073,-22.551842,0.015565,0.001685,0.042806,76.941223,3.919573,0.428056,-22.551842,0.043882,0.000000
48.250004,17.510811,-22.507360,0.015573,0.001706,0.043326,77.891975,3.968006,0.433264,-22.507360,0.044359,0.000000
48.540001,17.655289,-22.507360,0.015603,0.001718,0.043647,78.534645,4.000746,0.436474,-22.507360,0.044843,0.000000
48.830002,18.228371,-22.507360,0.015603,0.001741,0.044229,81.083839,4.130608,0.442288,-22.507360,0.045329,0.000000
49.120003,18.296143,-22.551842,0.015634,0.001756,0.044592,81.385307,4.145966,0.445921,-22.551842,0.045806,0.000000
49.410004,18.567230,-22.596323,0.015629,0.001771,0.044983,82.591164,4.207395,0.449827,-22.596323,0.046292,0.000000
49.700001,19.147758,-22.551842,0.015672,0.001800,0.045729,85.173485,4.338944,0.457291,-22.551842,0.046778,0.000000
49.990002,19.394272,-22.596323,0.015690,0.001821,0.046241,86.270027,4.394804,0.462408,-22.596323,0.047264,0.000000
50.280003,19.489601,-22.551842,0.015698,0.001835,0.046604,86.694077,4.416407,0.466042,-22.551842,0.047741,0.000000
50.570004,19.822128,-22.596323,0.015698,0.001853,0.047073,88.173233,4.491758,0.470735,-22.596323,0.048226,0.000000
50.860001,20.171783,-22.551842,0.015724,0.001872,0.047541,89.728577,4.570992,0.475413,-22.551842,0.048712,0.000000
51.150002,20.235092,-22.640804,0.015720,0.001883,0.047837,90.010185,4.585337,0.478365,-22.640804,0.049198,0.000000
51.440002,20.877800,-22.596323,0.015733,0.001912,0.048556,92.869095,4.730977,0.485557,-22.596323,0.049674,0.000000
51.730003,21.157082,-22.640804,0.015784,0.001932,0.049067,94.111397,4.794263,0.490674,-22.640804,0.050160,0.000000
52.020004,21.312363,-22.685286,0.015802,0.001948,0.049484,94.802124,4.829451,0.494837,-22.685286,0.050646,0.000000
52.310001,21.504509,-22.640804,0.015823,0.001966,0.049935,95.656830,4.872992,0.499349,-22.640804,0.051131,0.000000
52.600002,21.785278,-22.596323,0.015819,0.001986,0.050456,96.905754,4.936615,0.504557,-22.596323,0.051608,0.000000
52.890003,22.196747,-22.640804,0.015853,0.002005,0.050923,98.736061,5.029854,0.509235,-22.640804,0.052094,0.000000
53.180004,22.236961,-22.640804,0.015853,0.002015,0.051184,98.914948,5.038968,0.511839,-22.640804,0.052580,0.000000
53.470001,22.733711,-22.685286,0.015866,0.002041,0.051833,101.124596,5.151533,0.518334,-22.685286,0.053066,0.000000
53.760002,23.128792,-22.640804,0.015914,0.002061,0.052354,102.882004,5.241059,0.523542,-22.640804,0.053543,0.000000
54.050003,23.258751,-22.596323,0.015892,0.002080,0.052822,103.460091,5.270508,0.528220,-22.596323,0.054029,0.000000
54.340004,23.748421,-22.640804,0.015944,0.002103,0.053412,105.638252,5.381469,0.534124,-22.640804,0.054513,0.000000
54.630001,24.003502,-22.640804,0.015953,0.002121,0.053873,106.772911,5.439271,0.538727,-22.640804,0.054990,0.000000
54.920002,24.207184,-22.685286,0.015978,0.002138,0.054297,107.678932,5.485426,0.542966,-22.685286,0.055476,0.000000
55.210003,24.440666,-22.640804,0.015974,0.002152,0.054671,108.717514,5.538334,0.546705,-22.640804,0.055962,0.000000
55.500004,24.907249,-22.640804,0.015991,0.002176,0.055278,110.792976,5.644063,0.552776,-22.640804,0.056448,0.000000
55.790001,25.313133,-22.640804,0.016000,0.002198,0.055832,112.598442,5.736038,0.558317,-22.640804,0.056925,0.000000
56.080002,25.414787,-22.640804,0.016026,0.002214,0.056248,113.050621,5.759073,0.562481,-22.640804,0.057411,0.000000
56.370003,25.832588,-22.729767,0.016035,0.002237,0.056811,114.909088,5.853748,0.568113,-22.729767,0.057895,0.000000
56.660004,26.171822,-22.685286,0.016073,0.002254,0.057255,116.418076,5.930620,0.572549,-22.685286,0.058381,0.000000
56.950005,26.309975,-22.729767,0.016065,0.002269,0.057627,117.032616,5.961926,0.576273,-22.729767,0.058858,0.000000
57.240002,26.735596,-22.729767,0.016086,0.002290,0.058156,118.925873,6.058372,0.581557,-22.729767,0.059344,0.000000
57.530003,27.334740,-22.774246,0.016099,0.002317,0.058841,121.590996,6.194140,0.588415,-22.774246,0.059830,0.000000
57.820004,27.418900,-22.729767,0.016138,0.002331,0.059214,121.965355,6.213212,0.592139,-22.729767,0.060316,0.000000
58.110004,27.763718,-22.729767,0.016147,0.002352,0.059744,123.499184,6.291348,0.597438,-22.729767,0.060793,0.000000
58.400002,28.177048,-22.774246,0.016142,0.002371,0.060212,125.337769,6.385010,0.602116,-22.774246,0.061277,0.000000
58.690002,28.381851,-22.729767,0.016164,0.002386,0.060610,126.248779,6.431419,0.606098,-22.729767,0.061763,0.000000
58.980003,28.469360,-22.774246,0.016194,0.002397,0.060896,126.638039,6.451249,0.608959,-22.774246,0.062249,0.000000
59.270004,29.173515,-22.818727,0.016190,0.002424,0.061582,129.770279,6.610813,0.615818,-22.818727,0.062726,0.000000
59.560001,29.694466,-22.774246,0.016229,0.002447,0.062163,132.087585,6.728862,0.621631,-22.774246,0.063212,0.000000
59.850002,29.859428,-22.818727,0.016246,0.002465,0.062614,132.821365,6.766243,0.626143,-22.818727,0.063698,0.000000
60.140003,30.116364,-22.818727,0.016259,0.002480,0.063003,133.964279,6.824466,0.630034,-22.818727,0.064175,0.000000
60.430004,30.632103,-22.818727,0.016267,0.002504,0.063610,136.258392,6.941334,0.636105,-22.818727,0.064660,0.000000
60.720001,30.816055,-22.818727,0.016298,0.002519,0.063984,137.076660,6.983018,0.639844,-22.818727,0.065146,0.000000
61.010002,30.849190,-22.818727,0.016302,0.002529,0.064227,137.224045,6.990526,0.642266,-22.818727,0.065632,0.000000
61.300003,31.963333,-22.863209,0.016319,0.002563,0.065094,142.180008,7.242995,0.650941,-22.863209,0.066108,0.000000
61.590004,32.107437,-22.774246,0.016358,0.002580,0.065520,142.821014,7.275649,0.655196,-22.774246,0.066594,0.000000
61.880001,32.356186,-22.863209,0.016362,0.002597,0.065969,143.927505,7.332016,0.659692,-22.863209,0.067080,0.000000
62.170002,32.699142,-22.863209,0.016371,0.002612,0.066351,145.453049,7.409732,0.663507,-22.863209,0.067565,0.000000
62.460003,33.149712,-22.818727,0.016405,0.002634,0.066897,147.457275,7.511832,0.668973,-22.818727,0.068042,0.000000
62.750004,33.288605,-22.907690,0.016423,0.002648,0.067262,148.075104,7.543306,0.672621,-22.907690,0.068528,0.000000
63.040005,33.839714,-22.863209,0.016444,0.002673,0.067895,150.526566,7.668189,0.678950,-22.863209,0.069014,0.000000
63.330002,34.218788,-22.907690,0.016448,0.002695,0.068458,152.212769,7.754088,0.684582,-22.907690,0.069500,0.000000
63.620003,34.360664,-22.907690,0.016487,0.002711,0.068858,152.843872,7.786238,0.688578,-22.907690,0.069977,0.000000
63.910004,34.553185,-22.907690,0.016517,0.002730,0.069335,153.700241,7.829864,0.693347,-22.907690,0.070463,0.000000
64.200005,34.895020,-22.996653,0.016522,0.002752,0.069890,155.220795,7.907325,0.698904,-22.996653,0.070947,0.000000
64.490005,34.934868,-22.907690,0.016539,0.002766,0.070245,155.398056,7.916354,0.702446,-22.907690,0.071433,0.000000
64.780006,35.141533,-22.952171,0.016543,0.002780,0.070619,156.317352,7.963185,0.706186,-22.952171,0.071910,0.000000
65.070000,35.755203,-22.952171,0.016569,0.002807,0.071286,159.047089,8.102245,0.712862,-22.952171,0.072396,0.000000
65.360001,35.986816,-22.952171,0.016599,0.002827,0.071798,160.077347,8.154729,0.717979,-22.952171,0.072882,0.000000
65.650002,36.016235,-22.996653,0.016586,0.002845,0.072257,160.208221,8.161395,0.722567,-22.996653,0.073359,0.000000
65.940002,36.179337,-22.996653,0.016634,0.002860,0.072656,160.933731,8.198355,0.726564,-22.996653,0.073845,0.000000
66.230003,36.769547,-22.907690,0.016625,0.002883,0.073229,163.559113,8.332098,0.732286,-22.907690,0.074329,0.000000
66.520004,36.922585,-22.952171,0.016651,0.002898,0.073619,164.239853,8.366777,0.736192,-22.952171,0.074815,0.000000
66.810005,36.900993,-22.952171,0.016694,0.002910,0.073913,164.143814,8.361884,0.739129,-22.952171,0.075292,0.000000
67.100006,37.800270,-23.085613,0.016699,0.002943,0.074764,168.143997,8.565663,0.747638,-23.085613,0.075778,0.000000
67.389999,37.694885,-22.952171,0.016737,0.002959,0.075171,167.675217,8.541783,0.751710,-22.952171,0.076264,0.000000
67.680000,37.835274,-23.041132,0.016733,0.002975,0.075553,168.299698,8.573596,0.755526,-23.041132,0.076750,0.000000
67.970001,38.170784,-22.952171,0.016763,0.002994,0.076039,169.792130,8.649624,0.760385,-22.952171,0.077227,0.000000
68.260002,38.587463,-22.996653,0.016776,0.003015,0.076576,171.645615,8.744043,0.765760,-22.996653,0.077711,0.000000
68.550003,38.740135,-23.041132,0.016793,0.003032,0.077018,172.324722,8.778640,0.770181,-23.041132,0.078197,0.000000
68.840004,38.654495,-22.996653,0.016806,0.003046,0.077365,171.943787,8.759233,0.773648,-22.996653,0.078683,0.000000
69.130005,39.354553,-23.085613,0.016828,0.003072,0.078032,175.057800,8.917869,0.780324,-23.085613,0.079160,0.000000
69.420006,39.452118,-23.041132,0.016845,0.003091,0.078502,175.491791,8.939978,0.785017,-23.041132,0.079646,0.000000
69.710007,39.868797,-23.041132,0.016858,0.003112,0.079056,177.345261,9.034399,0.790559,-23.041132,0.080132,0.000000
70.000000,39.941040,-23.085613,0.016862,0.003124,0.079342,177.666626,9.050769,0.793420,-23.085613,0.080617,0.000000
70.290001,40.411346,-23.041132,0.016905,0.003147,0.079923,179.758652,9.157342,0.799234,-23.041132,0.081094,0.000000
70.580002,40.495132,-23.085613,0.016910,0.003161,0.080296,180.131348,9.176329,0.802958,-23.085613,0.081580,0.000000
70.870003,40.898781,-23.085613,0.016931,0.003185,0.080895,181.926865,9.267797,0.808953,-23.085613,0.082066,0.000000
71.160004,41.209343,-23.130095,0.016944,0.003205,0.081398,183.308319,9.338170,0.813980,-23.130095,0.082543,0.000000
71.450005,41.388077,-23.174576,0.016957,0.003221,0.081823,184.103363,9.378672,0.818234,-23.174576,0.083028,0.000000
71.740005,41.677788,-23.041132,0.016974,0.003241,0.082326,185.392059,9.444322,0.823260,-23.041132,0.083514,0.000000
72.030006,41.967865,-23.174576,0.016974,0.003261,0.082838,186.682388,9.510054,0.828377,-23.174576,0.083999,0.000000
72.320000,42.114952,-23.085613,0.017009,0.003276,0.083219,187.336670,9.543385,0.832192,-23.085613,0.084476,0.000000
72.610001,42.408005,-23.130095,0.017013,0.003293,0.083636,188.640228,9.609791,0.836356,-23.130095,0.084962,0.000000
72.900002,42.986305,-23.130095,0.017022,0.003319,0.084303,191.212631,9.740836,0.843032,-23.130095,0.085448,0.000000
73.190002,43.232437,-23.130095,0.017069,0.003341,0.084857,192.307480,9.796610,0.848573,-23.130095,0.085934,0.000000
73.480003,43.086472,-23.219057,0.017074,0.003353,0.085178,191.658203,9.763534,0.851783,-23.219057,0.086411,0.000000
73.770004,43.671837,-23.130095,0.017095,0.003375,0.085725,194.262039,9.896179,0.857248,-23.130095,0.086897,0.000000
74.060005,44.145866,-23.085613,0.017091,0.003395,0.086237,196.370621,10.003596,0.862366,-23.085613,0.087381,0.000000
74.350006,43.967873,-23.219057,0.017143,0.003405,0.086497,195.578873,9.963263,0.864970,-23.219057,0.087867,0.000000
74.640007,44.425522,-23.174576,0.017125,0.003424,0.086957,197.614594,10.066967,0.869572,-23.174576,0.088344,0.000000
74.930000,45.149788,-23.263536,0.017151,0.003452,0.087685,200.836288,10.231089,0.876854,-23.263536,0.088830,0.000000
75.220001,45.289055,-23.174576,0.017181,0.003471,0.088162,201.455780,10.262647,0.881623,-23.174576,0.089316,0.000000
75.510002,45.463692,-23.219057,0.017181,0.003487,0.088570,202.232605,10.302219,0.885696,-23.219057,0.089800,0.000000
75.800003,45.663284,-23.263536,0.017212,0.003505,0.089030,203.120438,10.347448,0.890298,-23.263536,0.090279,0.000000
76.090004,46.107903,-23.219057,0.017229,0.003527,0.089584,205.098190,10.448199,0.895839,-23.219057,0.090763,0.000000
76.380005,46.037148,-23.219057,0.017246,0.003538,0.089853,204.783463,10.432166,0.898534,-23.219057,0.091249,0.000000
76.670006,46.701462,-23.174576,0.017259,0.003561,0.090451,207.738480,10.582703,0.904514,-23.174576,0.091735,0.000000
76.960007,47.161339,-23.263536,0.017276,0.003586,0.091084,209.784119,10.686913,0.910843,-23.263536,0.092212,0.000000
77.250000,47.201561,-23.263536,0.017319,0.003603,0.091519,209.963028,10.696027,0.915188,-23.263536,0.092698,0.000000
77.540001,47.576538,-23.174576,0.017315,0.003622,0.092003,211.631012,10.780998,0.920032,-23.174576,0.093183,0.000000
77.830002,47.875549,-23.308018,0.017324,0.003640,0.092463,212.961075,10.848755,0.924635,-23.308018,0.093661,0.000000
78.120003,48.166000,-23.219057,0.017332,0.003658,0.092924,214.253067,10.914572,0.929237,-23.219057,0.094145,0.000000
78.410004,48.594604,-23.219057,0.017332,0.003679,0.093435,216.159592,11.011695,0.934354,-23.219057,0.094631,0.000000
78.700005,49.008682,-23.352499,0.017375,0.003699,0.093955,218.001511,11.105526,0.939547,-23.352499,0.095117,0.000000
78.990005,49.401161,-23.174576,0.017393,0.003722,0.094527,219.747345,11.194464,0.945270,-23.174576,0.095594,0.000000
79.280006,49.569099,-23.308018,0.017414,0.003739,0.094962,220.494370,11.232518,0.949615,-23.308018,0.096080,0.000000
79.570007,49.826042,-23.308018,0.017431,0.003755,0.095369,221.637299,11.290743,0.953688,-23.308018,0.096565,0.000000
79.860001,50.510834,-23.352499,0.017427,0.003782,0.096055,224.683411,11.445918,0.960546,-23.352499,0.097051,0.000000
80.150002,50.304535,-23.352499,0.017488,0.003789,0.096245,223.765747,11.399171,0.962453,-23.352499,0.097528,0.000000
80.440002,50.538017,-23.308018,0.017496,0.003806,0.096669,224.804321,11.452079,0.966692,-23.308018,0.098014,0.000000
80.730003,51.521080,-23.308018,0.017513,0.003834,0.097390,229.177216,11.674844,0.973899,-23.308018,0.098500,0.000000
81.020004,51.584381,-23.308018,0.017522,0.003850,0.097788,229.458786,11.689188,0.977881,-23.308018,0.098986,0.000000
81.310005,52.061394,-23.352499,0.017539,0.003871,0.098326,231.580643,11.797281,0.983255,-23.352499,0.099462,0.000000
81.600006,51.972397,-23.396980,0.017565,0.003883,0.098630,231.184769,11.777113,0.986298,-23.396980,0.099947,0.000000
81.890007,52.831085,-23.308018,0.017578,0.003910,0.099314,235.004410,11.971695,0.993141,-23.308018,0.100433,0.000000
82.180000,52.793846,-23.352499,0.017587,0.003922,0.099628,234.838760,11.963257,0.996275,-23.352499,0.100919,0.000000
82.470001,53.137177,-23.352499,0.017621,0.003940,0.100077,236.365967,12.041057,1.000772,-23.352499,0.101396,0.000000
82.760002,54.020073,-23.352499,0.017630,0.003970,0.100840,240.293289,12.241123,1.008402,-23.352499,0.101882,0.000000
83.050003,54.018951,-23.441462,0.017638,0.003983,0.101170,240.288300,12.240870,1.011702,-23.441462,0.102368,0.000000
83.340004,54.293762,-23.441462,0.017669,0.004000,0.101605,241.510712,12.303143,1.016047,-23.441462,0.102845,0.000000
83.630005,54.914139,-23.396980,0.017682,0.004023,0.102194,244.270294,12.443722,1.021937,-23.396980,0.103329,0.000000
83.920006,55.178146,-23.308018,0.017699,0.004041,0.102645,245.444656,12.503547,1.026448,-23.308018,0.103815,0.000000
84.210007,55.247780,-23.396980,0.017694,0.004058,0.103078,245.754395,12.519326,1.030778,-23.396980,0.104301,0.000000
84.500008,56.036469,-23.441462,0.017725,0.004082,0.103677,249.262665,12.698046,1.036774,-23.441462,0.104778,0.000000
84.790001,56.331757,-23.352499,0.017742,0.004100,0.104145,250.576172,12.764959,1.041452,-23.352499,0.105264,0.000000
85.080002,56.589066,-23.530422,0.017763,0.004118,0.104596,251.720734,12.823266,1.045963,-23.530422,0.105750,0.000000
85.370003,57.235130,-23.396980,0.017772,0.004141,0.105185,254.594574,12.969666,1.051853,-23.396980,0.106234,0.000000
85.660004,57.368446,-23.396980,0.017785,0.004158,0.105602,255.187592,12.999875,1.056016,-23.396980,0.106711,0.000000
85.950005,57.549416,-23.485943,0.017815,0.004171,0.105948,255.992584,13.040884,1.059483,-23.485943,0.107197,0.000000
86.240005,57.738579,-23.396980,0.017832,0.004192,0.106478,256.834015,13.083749,1.064782,-23.396980,0.107683,0.000000
86.530006,58.603233,-23.530422,0.017858,0.004215,0.107050,260.680206,13.279682,1.070505,-23.530422,0.108169,0.000000
86.820007,59.025497,-23.441462,0.017858,0.004236,0.107597,262.558533,13.375369,1.075970,-23.441462,0.108646,0.000000
87.110001,59.121948,-23.396980,0.017888,0.004251,0.107969,262.987549,13.397224,1.079694,-23.396980,0.109132,0.000000
87.400002,59.213547,-23.530422,0.017897,0.004263,0.108281,263.395020,13.417982,1.082813,-23.530422,0.109617,0.000000
87.690002,60.054367,-23.485943,0.017927,0.004287,0.108897,267.135162,13.608514,1.088975,-23.485943,0.110103,0.000000
87.980003,60.076332,-23.530422,0.017940,0.004302,0.109279,267.232880,13.613492,1.092790,-23.530422,0.110579,0.000000
88.270004,60.631172,-23.530422,0.017949,0.004321,0.109765,269.700928,13.739221,1.097650,-23.530422,0.111065,0.000000
88.560005,61.468636,-23.530422,0.017975,0.004350,0.110484,273.426147,13.928992,1.104841,-23.530422,0.111551,0.000000
88.850006,61.394905,-23.530422,0.017996,0.004366,0.110884,273.098175,13.912284,1.108838,-23.530422,0.112028,0.000000
89.140007,61.658546,-23.530422,0.018001,0.004379,0.111230,274.270905,13.972027,1.112305,-23.530422,0.112514,0.000000
89.430008,62.202583,-23.619385,0.018026,0.004400,0.111751,276.690918,14.095306,1.117513,-23.619385,0.112999,0.000000
89.720001,62.895935,-23.530422,0.018026,0.004423,0.112349,279.775085,14.252422,1.123493,-23.530422,0.113485,0.000000
90.010002,63.002441,-23.485943,0.018052,0.004437,0.112705,280.248871,14.276557,1.127051,-23.485943,0.113962,0.000000
90.300003,63.706970,-23.574903,0.018078,0.004461,0.113312,283.382751,14.436206,1.133122,-23.574903,0.114448,0.000000
90.590004,63.982147,-23.530422,0.018091,0.004480,0.113797,284.606812,14.498562,1.137967,-23.530422,0.114934,0.000000
90.880005,64.093857,-23.619385,0.018108,0.004494,0.114152,285.103729,14.523876,1.141524,-23.619385,0.115420,0.000000
91.170006,64.474792,-23.530422,0.018113,0.004512,0.114595,286.798187,14.610197,1.145945,-23.530422,0.115897,0.000000
91.460007,65.087723,-23.574903,0.018126,0.004535,0.115202,289.524658,14.749088,1.152016,-23.574903,0.116381,0.000000
91.750008,65.298111,-23.574903,0.018151,0.004548,0.115532,290.460510,14.796764,1.155316,-23.574903,0.116867,0.000000
92.040001,65.765442,-23.619385,0.018164,0.004567,0.115992,292.539307,14.902661,1.159919,-23.619385,0.117353,0.000000
92.330002,66.549286,-23.619385,0.018177,0.004592,0.116625,296.026001,15.080283,1.166247,-23.619385,0.117830,0.000000
92.620003,67.004318,-23.574903,0.018212,0.004614,0.117188,298.050079,15.183395,1.171879,-23.574903,0.118316,0.000000
92.910004,67.121628,-23.574903,0.018199,0.004628,0.117553,298.571899,15.209979,1.175528,-23.574903,0.118802,0.000000
93.200005,67.515213,-23.663866,0.018225,0.004635,0.117734,300.322662,15.299166,1.177345,-23.663866,0.117995,0.000000
93.490005,66.824463,-23.619385,0.018264,0.004635,0.117734,297.250061,15.142640,1.177345,-23.619385,0.117995,0.000000
93.780006,66.357513,-23.663866,0.018246,0.004627,0.117518,295.172974,15.036827,1.175180,-23.663866,0.117734,0.000000
94.070007,66.047699,-23.663866,0.018264,0.004627,0.117518,293.794830,14.966622,1.175180,-23.663866,0.117734,0.000000
94.360008,65.807144,-23.663866,0.018272,0.004627,0.117518,292.724792,14.912112,1.175180,-23.663866,0.117734,0.000000
94.650002,65.578140,-23.663866,0.018264,0.004627,0.117518,291.706146,14.860219,1.175180,-23.663866,0.117734,0.000000
94.940002,65.391953,-23.663866,0.018268,0.004627,0.117518,290.877930,14.818028,1.175180,-23.663866,0.117734,0.000000
95.230003,65.208374,-23.708347,0.018268,0.004627,0.117518,290.061340,14.776429,1.175180,-23.708347,0.117734,0.000000
95.520004,65.077667,-23.708347,0.018259,0.004627,0.117518,289.479919,14.746810,1.175180,-23.708347,0.117734,0.000000
95.810005,64.955902,-23.663866,0.018264,0.004627,0.117518,288.938293,14.719218,1.175180,-23.663866,0.117734,0.000000
96.100006,64.835251,-23.708347,0.018255,0.004627,0.117518,288.401611,14.691878,1.175180,-23.708347,0.117734,0.000000
96.390007,64.724289,-23.663866,0.018259,0.004627,0.117518,287.908020,14.666734,1.175180,-23.663866,0.117734,0.000000
96.680008,64.622253,-23.663866,0.018268,0.004627,0.117518,287.454132,14.643612,1.175180,-23.663866,0.117734,0.000000
96.970001,64.541824,-23.708347,0.018264,0.004627,0.117518,287.096375,14.625386,1.175180,-23.708347,0.117734,0.000000
97.260002,64.444641,-23.708347,0.018289,0.004627,0.117518,286.664093,14.603365,1.175180,-23.708347,0.117734,0.000000
97.550003,64.370163,-23.752829,0.018281,0.004627,0.117518,286.332794,14.586488,1.175180,-23.752829,0.117734,0.000000
97.840004,64.285263,-23.708347,0.018281,0.004627,0.117518,285.955139,14.567249,1.175180,-23.708347,0.117734,0.000000
98.130005,64.216370,-23.797308,0.018277,0.004627,0.117518,285.648682,14.551638,1.175180,-23.797308,0.117734,0.000000
98.420006,64.159775,-23.752829,0.018277,0.004627,0.117518,285.396942,14.538813,1.175180,-23.752829,0.117734,0.000000
98.710007,64.091263,-23.752829,0.018289,0.004627,0.117518,285.092163,14.523288,1.175180,-23.752829,0.117734,0.000000
99.000008,64.014923,-23.797308,0.018285,0.004627,0.117518,284.752594,14.505988,1.175180,-23.797308,0.117734,0.000000
99.290001,63.960922,-23.708347,0.018277,0.004627,0.117518,284.512390,14.493752,1.175180,-23.708347,0.117734,0.000000
99.580002,63.914383,-23.797308,0.018281,0.004627,0.117518,284.305389,14.483207,1.175180,-23.797308,0.117734,0.000000
99.870003,63.871552,-23.752829,0.018285,0.004627,0.117518,284.114838,14.473500,1.175180,-23.752829,0.117734,0.000000
100.160004,63.800812,-23.841789,0.018264,0.004627,0.117518,283.800171,14.457471,1.175180,-23.841789,0.117734,0.000000
100.450005,63.750900,-23.797308,0.018277,0.004627,0.117518,283.578156,14.446160,1.175180,-23.797308,0.117734,0.000000
100.740005,63.697281,-23.797308,0.018281,0.004627,0.117518,283.339661,14.434011,1.175180,-23.797308,0.117734,0.000000
101.030006,63.658936,-23.841789,0.018285,0.004627,0.117518,283.169098,14.425322,1.175180,-23.841789,0.117734,0.000000
101.320007,63.609039,-23.797308,0.018259,0.004627,0.117518,282.947144,14.414014,1.175180,-23.797308,0.117734,0.000000
101.610008,63.563232,-23.841789,0.018264,0.004627,0.117518,282.743378,14.403634,1.175180,-23.841789,0.117734,0.000000
101.900002,63.541260,-23.841789,0.018281,0.004627,0.117518,282.645630,14.398656,1.175180,-23.841789,0.117734,0.000000
102.190002,63.496201,-23.797308,0.018289,0.004627,0.117518,282.445221,14.388445,1.175180,-23.797308,0.117734,0.000000
102.480003,63.455994,-23.886271,0.018264,0.004627,0.117518,282.266357,14.379333,1.175180,-23.886271,0.117734,0.000000
102.770004,63.406097,-23.797308,0.018285,0.004627,0.117518,282.044403,14.368027,1.175180,-23.797308,0.117734,0.000000
103.060005,63.373322,-23.886271,0.018285,0.004627,0.117518,281.898621,14.360600,1.175180,-23.886271,0.117734,0.000000
103.350006,63.346146,-23.886271,0.018281,0.004627,0.117518,281.777740,14.354442,1.175180,-23.886271,0.117734,0.000000
103.640007,63.317093,-23.886271,0.018311,0.004627,0.117518,281.648499,14.347858,1.175180,-23.886271,0.117734,0.000000
103.930008,63.276505,-23.930752,0.018281,0.004627,0.117518,281.467957,14.338661,1.175180,-23.930752,0.117734,0.000000
104.220001,63.235916,-23.841789,0.018285,0.004627,0.117518,281.287415,14.329463,1.175180,-23.841789,0.117734,0.000000
104.510002,63.216553,-23.930752,0.018246,0.004627,0.117518,281.201263,14.325076,1.175180,-23.930752,0.117734,0.000000
104.800003,63.189377,-23.886271,0.018289,0.004627,0.117518,281.080383,14.318918,1.175180,-23.886271,0.117734,0.000000
105.090004,63.151016,-23.930752,0.018294,0.004627,0.117518,280.909760,14.310225,1.175180,-23.930752,0.117734,0.000000
105.380005,63.120102,-23.930752,0.018272,0.004627,0.117518,280.772247,14.303220,1.175180,-23.930752,0.117734,0.000000
105.670006,63.113037,-23.886271,0.018285,0.004627,0.117518,280.740814,14.301619,1.175180,-23.886271,0.117734,0.000000
105.960007,63.070206,-23.975233,0.018294,0.004627,0.117518,280.550293,14.291912,1.175180,-23.975233,0.117734,0.000000
106.250008,63.040421,-23.975233,0.018281,0.004627,0.117518,280.417786,14.285164,1.175180,-23.975233,0.117734,0.000000
106.540009,63.030365,-23.930752,0.018264,0.004627,0.117518,280.373077,14.282885,1.175180,-23.930752,0.117734,0.000000
106.830002,63.000946,-23.930752,0.018289,0.004627,0.117518,280.242218,14.276218,1.175180,-23.930752,0.117734,0.000000
107.120003,62.978241,-23.930752,0.018277,0.004627,0.117518,280.141205,14.271073,1.175180,-23.930752,0.117734,0.000000
107.410004,62.952545,-23.975233,0.018277,0.004627,0.117518,280.026917,14.265251,1.175180,-23.975233,0.117734,0.000000
107.700005,62.932434,-23.975233,0.018272,0.004627,0.117518,279.937439,14.260694,1.175180,-23.975233,0.117734,0.000000
107.990005,62.900787,-23.975233,0.018289,0.004627,0.117518,279.796661,14.253523,1.175180,-23.975233,0.117734,0.000000
108.280006,62.877701,-23.975233,0.018307,0.004627,0.117518,279.693970,14.248290,1.175180,-23.975233,0.117734,0.000000
108.570007,62.847153,-23.975233,0.018281,0.004627,0.117518,279.558105,14.241368,1.175180,-23.975233,0.117734,0.000000
108.860008,62.835983,-23.975233,0.018285,0.004627,0.117518,279.508423,14.238837,1.175180,-23.975233,0.117734,0.000000
109.150002,62.806564,-24.019714,0.018272,0.004627,0.117518,279.377563,14.232171,1.175180,-24.019714,0.117734,0.000000
109.440002,62.795403,-23.930752,0.018298,0.004627,0.117518,279.327911,14.229642,1.175180,-23.930752,0.117734,0.000000
109.730003,62.767471,-24.064194,0.018294,0.004627,0.117518,279.203644,14.223312,1.175180,-24.064194,0.117734,0.000000
110.020004,62.746620,-24.019714,0.018302,0.004627,0.117518,279.110901,14.218587,1.175180,-24.019714,0.117734,0.000000
110.310005,62.729858,-24.064194,0.018302,0.004627,0.117518,279.036346,14.214789,1.175180,-24.064194,0.117734,0.000000
110.600006,62.713478,-24.064194,0.018289,0.004627,0.117518,278.963470,14.211078,1.175180,-24.064194,0.117734,0.000000
110.890007,62.697838,-24.064194,0.018307,0.004627,0.117518,278.893921,14.207533,1.175180,-24.064194,0.117734,0.000000
111.180008,62.678101,-24.064194,0.018289,0.004627,0.117518,278.806122,14.203060,1.175180,-24.064194,0.117734,0.000000
111.470009,62.663208,-24.064194,0.018285,0.004627,0.117518,278.739868,14.199686,1.175180,-24.064194,0.117734,0.000000
111.760002,62.644958,-24.108675,0.018294,0.004627,0.117518,278.658691,14.195551,1.175180,-24.108675,0.117734,0.000000
112.050003,62.625595,-24.064194,0.018289,0.004627,0.117518,278.572571,14.191163,1.175180,-24.064194,0.117734,0.000000
112.340004,62.603996,-24.108675,0.018294,0.004627,0.117518,278.476471,14.186268,1.175180,-24.108675,0.117734,0.000000
112.630005,62.580170,-24.064194,0.018264,0.004627,0.117518,278.370483,14.180869,1.175180,-24.064194,0.117734,0.000000
112.920006,62.567139,-24.064194,0.018285,0.004627,0.117518,278.312531,14.177917,1.175180,-24.064194,0.117734,0.000000
113.210007,62.549637,-24.153156,0.018302,0.004627,0.117518,278.234680,14.173950,1.175180,-24.153156,0.117734,0.000000
113.500008,62.541817,-24.153156,0.018281,0.004627,0.117518,278.199890,14.172178,1.175180,-24.153156,0.117734,0.000000
113.790009,62.522079,-24.108675,0.018298,0.004627,0.117518,278.112091,14.167706,1.175180,-24.108675,0.117734,0.000000
114.080002,62.501968,-24.197638,0.018294,0.004627,0.117518,278.022644,14.163149,1.175180,-24.197638,0.117734,0.000000
114.370003,62.482979,-24.108675,0.018277,0.004627,0.117518,277.938171,14.158846,1.175180,-24.108675,0.117734,0.000000
114.660004,62.465851,-24.108675,0.018294,0.004627,0.117518,277.861969,14.154964,1.175180,-24.108675,0.117734,0.000000
114.950005,62.459518,-24.153156,0.018294,0.004627,0.117518,277.833801,14.153529,1.175180,-24.153156,0.117734,0.000000
115.240005,62.447601,-24.108675,0.018298,0.004627,0.117518,277.780792,14.150828,1.175180,-24.108675,0.117734,0.000000
115.530006,62.439415,-24.197638,0.018285,0.004627,0.117518,277.744385,14.148973,1.175180,-24.197638,0.117734,0.000000
115.820007,62.410736,-24.108675,0.018289,0.004627,0.117518,277.616821,14.142474,1.175180,-24.108675,0.117734,0.000000
116.110008,62.396217,-24.242119,0.018281,0.004627,0.117518,277.552246,14.139185,1.175180,-24.242119,0.117734,0.000000
116.400009,62.391373,-24.153156,0.018307,0.004627,0.117518,277.530701,14.138087,1.175180,-24.153156,0.117734,0.000000
116.690002,62.374245,-24.197638,0.018294,0.004627,0.117518,277.454498,14.134206,1.175180,-24.197638,0.117734,0.000000
116.980003,62.342964,-24.242119,0.018302,0.004627,0.117518,277.315369,14.127117,1.175180,-24.242119,0.117734,0.000000
117.270004,62.334778,-24.153156,0.018281,0.004627,0.117518,277.278931,14.125262,1.175180,-24.153156,0.117734,0.000000
117.560005,62.334778,-24.197638,0.018277,0.004627,0.117518,277.278931,14.125262,1.175180,-24.197638,0.117734,0.000000
117.850006,62.313919,-24.197638,0.018294,0.004627,0.117518,277.186157,14.120536,1.175180,-24.197638,0.117734,0.000000
118.140007,62.292328,-24.242119,0.018294,0.004627,0.117518,277.090118,14.115644,1.175180,-24.242119,0.117734,0.000000
118.430008,62.285995,-24.197638,0.018281,0.004627,0.117518,277.061951,14.114208,1.175180,-24.197638,0.117734,0.000000
118.720009,62.268120,-24.242119,0.018281,0.004627,0.117518,276.982422,14.110158,1.175180,-24.242119,0.117734,0.000000
119.010002,62.266632,-24.286600,0.018281,0.004627,0.117518,276.975800,14.109820,1.175180,-24.286600,0.117734,0.000000
119.300003,62.254715,-24.286600,0.018281,0.004627,0.117518,276.922791,14.107121,1.175180,-24.286600,0.117734,0.000000
119.590004,62.223808,-24.286600,0.018298,0.004627,0.117518,276.785309,14.100117,1.175180,-24.286600,0.117734,0.000000
119.880005,62.214874,-24.286600,0.018298,0.004627,0.117518,276.745575,14.098092,1.175180,-24.286600,0.117734,0.000000
120.170006,62.214500,-24.242119,0.018285,0.004627,0.117518,276.743927,14.098007,1.175180,-24.242119,0.117734,0.000000
120.460007,62.203697,-24.286600,0.018277,0.004627,0.117518,276.695862,14.095559,1.175180,-24.286600,0.117734,0.000000
120.750008,62.188805,-24.286600,0.018277,0.004627,0.117518,276.629608,14.092185,1.175180,-24.286600,0.117734,0.000000
121.040009,62.178749,-24.331079,0.018289,0.004627,0.117518,276.584900,14.089906,1.175180,-24.331079,0.117734,0.000000
121.330009,62.170189,-24.331079,0.018285,0.004627,0.117518,276.546814,14.087966,1.175180,-24.331079,0.117734,0.000000
121.620003,62.152313,-24.242119,0.018294,0.004627,0.117518,276.467285,14.083915,1.175180,-24.242119,0.117734,0.000000
121.910004,62.144493,-24.331079,0.018289,0.004627,0.117518,276.432526,14.082143,1.175180,-24.331079,0.117734,0.000000
122.200005,62.135185,-24.331079,0.018298,0.004627,0.117518,276.391113,14.080034,1.175180,-24.331079,0.117734,0.000000
122.490005,62.120285,-24.331079,0.018298,0.004627,0.117518,276.324829,14.076658,1.175180,-24.331079,0.117734,0.000000
122.780006,62.105766,-24.286600,0.018268,0.004627,0.117518,276.260254,14.073368,1.175180,-24.286600,0.117734,0.000000
123.070007,62.097572,-24.331079,0.018294,0.004627,0.117518,276.223785,14.071511,1.175180,-24.331079,0.117734,0.000000
123.360008,62.089378,-24.375561,0.018285,0.004627,0.117518,276.187347,14.069654,1.175180,-24.375561,0.117734,0.000000
123.600006,62.072624,-24.331079,0.018298,0.004627,0.117518,276.112823,14.065858,1.175180,-24.331079,0.117734,0.000000