File: Data/New pin I-18 old sample 2_08172023_174820.csv
Time (sec),S:Load (lbs),S:HL1 (DIM),S:LVDT (in),S:Position (in),Ch:Position (mm),Ch:Load (N),Ch:Stress (MPa),Ch:Strain (mm/mm),Ch:HL1 (DIM),Set Point (),Cycles ()
0.110000,-0.011169,-16.235548,-0.000026,-0.000000,-0.000000,-0.049684,-0.002531,-0.000000,-16.235548,-0.000251,0.000000
0.320000,-0.008568,-16.235548,-0.000034,-0.000000,-0.000000,-0.038112,-0.001941,-0.000000,-16.235548,-0.000251,0.000000
0.530000,0.020477,-16.235548,-0.000026,0.000088,0.002229,0.091088,0.004640,0.022285,-16.235548,0.002749,0.000000
0.740000,0.041702,-16.280027,-0.000034,0.000211,0.005368,0.185501,0.009450,0.053685,-16.280027,0.006234,0.000000
0.950000,0.060699,-16.280027,0.000082,0.000342,0.008698,0.270005,0.013755,0.086977,-16.280027,0.009739,0.000000
1.160000,0.048035,-16.235548,0.000198,0.000474,0.012037,0.213669,0.010885,0.120375,-16.235548,0.013243,0.000000
1.370000,0.059578,-16.280027,0.000354,0.000608,0.015445,0.265016,0.013501,0.154454,-16.280027,0.016746,0.000000
1.580000,0.034630,-16.324509,0.000487,0.000749,0.019026,0.154041,0.007847,0.190259,-16.324509,0.020233,0.000000
1.790000,0.035744,-16.324509,0.000604,0.000892,0.022661,0.158996,0.008100,0.226609,-16.324509,0.023736,0.000000
2.000000,0.026810,-16.235548,0.000832,0.001032,0.026225,0.119255,0.006075,0.262248,-16.235548,0.027239,0.000000
2.210000,0.053246,-16.324509,0.000927,0.001167,0.029633,0.236848,0.012066,0.296327,-16.324509,0.030726,0.000000
2.420000,0.058830,-16.235548,0.001056,0.001302,0.033066,0.261690,0.013331,0.330664,-16.235548,0.034229,0.000000
2.630000,0.035378,-16.235548,0.001229,0.001443,0.036648,0.157367,0.008017,0.366484,-16.235548,0.037732,0.000000
2.840000,0.037605,-16.324509,0.001350,0.001581,0.040161,0.167277,0.008521,0.401608,-16.324509,0.041236,0.000000
3.050000,0.061440,-16.324509,0.001505,0.001720,0.043699,0.273297,0.013922,0.436989,-16.324509,0.044722,0.000000
3.260000,0.037239,-16.368990,0.001613,0.001859,0.047229,0.165648,0.008438,0.472294,-16.368990,0.048226,0.000000
3.470000,0.045059,-16.324509,0.001763,0.001992,0.050603,0.200433,0.010211,0.506025,-16.324509,0.051730,0.000000
3.680000,0.046173,-16.324509,0.001923,0.002131,0.054132,0.205388,0.010463,0.541316,-16.324509,0.055216,0.000000
3.890000,0.071869,-16.368990,0.002039,0.002267,0.057592,0.319689,0.016286,0.575925,-16.368990,0.058719,0.000000
4.100000,0.056602,-16.368990,0.002199,0.002406,0.061105,0.251780,0.012826,0.611049,-16.368990,0.062224,0.000000
4.310000,0.067024,-16.413471,0.002345,0.002543,0.064590,0.298139,0.015188,0.645900,-16.413471,0.065709,0.000000
4.520000,0.074471,-16.324509,0.002479,0.002683,0.068146,0.331261,0.016875,0.681463,-16.324509,0.069214,0.000000
4.730000,0.084152,-16.324509,0.002630,0.002824,0.071728,0.374328,0.019069,0.717283,-16.324509,0.072717,0.000000
4.940000,0.052505,-16.368990,0.002746,0.002961,0.075215,0.233556,0.011898,0.752149,-16.368990,0.076220,0.000000
5.150000,0.069633,-16.368990,0.002910,0.003094,0.078597,0.309745,0.015779,0.785971,-16.368990,0.079707,0.000000
5.360000,0.056969,-16.413471,0.003061,0.003236,0.082187,0.253409,0.012909,0.821867,-16.413471,0.083210,0.000000
5.570000,0.063301,-16.368990,0.003208,0.003373,0.085664,0.281577,0.014344,0.856643,-16.368990,0.086713,0.000000
5.780000,0.070747,-16.324509,0.003320,0.003507,0.089072,0.314700,0.016032,0.890722,-16.324509,0.090200,0.000000
5.990000,0.061066,-16.368990,0.003484,0.003644,0.092568,0.271634,0.013838,0.925679,-16.368990,0.093703,0.000000
6.200000,0.064789,-16.368990,0.003630,0.003783,0.096097,0.288195,0.014681,0.960970,-16.368990,0.097207,0.000000
6.410000,0.097557,-16.502434,0.003760,0.003915,0.099435,0.433956,0.022107,0.994352,-16.502434,0.100710,0.000000
6.620000,0.091606,-16.413471,0.003898,0.004053,0.102957,0.407484,0.020758,1.029567,-16.413471,0.104197,0.000000
6.830000,0.086761,-16.413471,0.004049,0.004196,0.106581,0.385934,0.019660,1.065811,-16.413471,0.107700,0.000000
7.040000,0.086761,-16.413471,0.004199,0.004340,0.110224,0.385934,0.019660,1.102237,-16.413471,0.111205,0.000000
7.250000,0.090858,-16.368990,0.004368,0.004478,0.113736,0.404159,0.020589,1.137361,-16.368990,0.114690,0.000000
7.460001,0.050270,-16.502434,0.004501,0.004610,0.117102,0.223612,0.011391,1.171016,-16.502434,0.118193,0.000000
7.670001,0.051384,-16.413471,0.004618,0.004748,0.120605,0.228567,0.011644,1.206049,-16.413471,0.121698,0.000000
7.880001,0.027184,-16.413471,0.004760,0.004886,0.124099,0.120918,0.006160,1.240991,-16.413471,0.125201,0.000000
8.090000,0.038727,-16.413471,0.004889,0.005021,0.127534,0.172265,0.008776,1.275343,-16.413471,0.128688,0.000000
8.300000,0.058464,-16.457952,0.005057,0.005162,0.131115,0.260061,0.013248,1.311148,-16.457952,0.132191,0.000000
8.510000,0.085274,-16.502434,0.005213,0.005298,0.134559,0.379317,0.019323,1.345591,-16.502434,0.135695,0.000000
8.720000,0.087135,-16.457952,0.005333,0.005431,0.137949,0.387597,0.019745,1.379488,-16.457952,0.139181,0.000000
8.930000,0.093094,-16.502434,0.005493,0.005570,0.141470,0.414102,0.021095,1.414703,-16.502434,0.142684,0.000000
9.140000,0.092720,-16.457952,0.005596,0.005705,0.144904,0.412439,0.021011,1.449039,-16.457952,0.146188,0.000000
9.350000,0.096443,-16.413471,0.005769,0.005852,0.148633,0.429001,0.021854,1.486328,-16.413471,0.149691,0.000000
9.560000,0.086014,-16.502434,0.005924,0.005993,0.152224,0.382608,0.019491,1.522239,-16.502434,0.153178,0.000000
9.770000,0.080063,-16.502434,0.006049,0.006128,0.155658,0.356137,0.018143,1.556576,-16.502434,0.156681,0.000000
9.980000,0.039467,-16.457952,0.006204,0.006265,0.159135,0.175557,0.008943,1.591352,-16.457952,0.160184,0.000000
10.190001,0.010056,-16.502434,0.006321,0.006402,0.162613,0.044729,0.002279,1.626127,-16.502434,0.163671,0.000000
10.400001,0.018616,-16.546913,0.006472,0.006536,0.166022,0.082807,0.004218,1.660221,-16.546913,0.167174,0.000000
10.610001,0.046173,-16.502434,0.006610,0.006674,0.169507,0.205388,0.010463,1.695073,-16.502434,0.170679,0.000000
10.820001,0.074471,-16.502434,0.006748,0.006815,0.173106,0.331261,0.016875,1.731060,-16.502434,0.174164,0.000000
11.030001,0.075218,-16.502434,0.006920,0.006952,0.176576,0.334587,0.017045,1.765759,-16.502434,0.177668,0.000000
11.240001,0.078941,-16.502434,0.007036,0.007086,0.179993,0.351149,0.017888,1.799929,-16.502434,0.181172,0.000000
11.450001,0.090111,-16.502434,0.007183,0.007221,0.183410,0.400833,0.020419,1.834100,-16.502434,0.184676,0.000000
11.660001,0.092720,-16.591394,0.007347,0.007366,0.187104,0.412439,0.021011,1.871040,-16.591394,0.188162,0.000000
11.870001,0.082291,-16.502434,0.007493,0.007507,0.190668,0.366047,0.018647,1.906679,-16.502434,0.191666,0.000000
12.080001,0.062927,-16.546913,0.007636,0.007645,0.194189,0.279914,0.014260,1.941893,-16.546913,0.195169,0.000000
12.290001,0.063301,-16.591394,0.007769,0.007781,0.197641,0.281577,0.014344,1.976412,-16.591394,0.198656,0.000000
12.500001,0.016014,-16.591394,0.007916,0.007916,0.201066,0.071234,0.003629,2.010657,-16.591394,0.202159,0.000000
12.710001,0.040215,-16.591394,0.008050,0.008053,0.204534,0.178883,0.009113,2.045342,-16.591394,0.205662,0.000000
12.920001,0.078941,-16.591394,0.008183,0.008190,0.208030,0.351149,0.017888,2.080299,-16.591394,0.209165,0.000000
13.130001,0.081551,-16.546913,0.008334,0.008328,0.211533,0.362755,0.018480,2.115332,-16.546913,0.212652,0.000000
13.340001,0.075218,-16.546913,0.008464,0.008471,0.215167,0.334587,0.017045,2.151667,-16.546913,0.216155,0.000000
13.550000,0.088249,-16.546913,0.008640,0.008607,0.218619,0.392552,0.019998,2.186186,-16.546913,0.219659,0.000000
13.760000,0.096069,-16.635876,0.008752,0.008741,0.222010,0.427338,0.021770,2.220098,-16.635876,0.223145,0.000000
13.970000,0.111710,-16.591394,0.008886,0.008878,0.225513,0.496909,0.025314,2.255131,-16.591394,0.226649,0.000000
14.180000,0.103516,-16.591394,0.009046,0.009012,0.228912,0.460460,0.023457,2.289120,-16.591394,0.230153,0.000000
14.390000,0.074104,-16.591394,0.009175,0.009154,0.232520,0.329632,0.016792,2.325197,-16.591394,0.233657,0.000000
14.600000,0.077454,-16.591394,0.009334,0.009297,0.236153,0.344531,0.017551,2.361532,-16.591394,0.237142,0.000000
14.810000,0.080803,-16.635876,0.009468,0.009435,0.239640,0.359429,0.018310,2.396399,-16.635876,0.240647,0.000000
15.020000,0.091232,-16.591394,0.009606,0.009567,0.243013,0.405822,0.020674,2.430130,-16.591394,0.244150,0.000000
15.230000,0.087509,-16.635876,0.009753,0.009703,0.246465,0.389260,0.019830,2.464648,-16.635876,0.247637,0.000000
15.440001,0.071869,-16.635876,0.009916,0.009847,0.250116,0.319689,0.016286,2.501165,-16.635876,0.251140,0.000000
15.650001,0.096069,-16.591394,0.010037,0.009984,0.253603,0.427338,0.021770,2.536031,-16.591394,0.254643,0.000000
15.860001,0.105751,-16.680357,0.010214,0.010124,0.257149,0.470404,0.023964,2.571488,-16.680357,0.258146,0.000000
16.070002,0.088249,-16.591394,0.010330,0.010260,0.260601,0.392552,0.019998,2.606006,-16.591394,0.261633,0.000000
16.280001,0.102028,-16.680357,0.010477,0.010390,0.263913,0.453843,0.023120,2.639132,-16.680357,0.265136,0.000000
16.490002,0.092346,-16.680357,0.010611,0.010532,0.267504,0.410776,0.020926,2.675043,-16.680357,0.268640,0.000000
16.700001,0.087135,-16.680357,0.010762,0.010671,0.271033,0.387597,0.019745,2.710333,-16.680357,0.272126,0.000000
16.910002,0.081924,-16.680357,0.010895,0.010813,0.274641,0.364418,0.018564,2.746411,-16.680357,0.275630,0.000000
17.120001,0.106125,-16.635876,0.011046,0.010950,0.278128,0.472067,0.024048,2.781277,-16.635876,0.279133,0.000000
17.330000,0.111336,-16.680357,0.011214,0.011085,0.281554,0.495246,0.025229,2.815538,-16.680357,0.282620,0.000000
17.540001,0.081924,-16.680357,0.011365,0.011224,0.285092,0.364418,0.018564,2.850919,-16.680357,0.286123,0.000000
17.750000,0.082291,-16.635876,0.011477,0.011362,0.288604,0.366047,0.018647,2.886043,-16.635876,0.289628,0.000000
17.960001,0.110596,-16.724838,0.011611,0.011497,0.292029,0.491954,0.025061,2.920289,-16.724838,0.293131,0.000000
18.170000,0.101288,-16.635876,0.011779,0.011639,0.295628,0.450551,0.022952,2.956275,-16.635876,0.296616,0.000000
18.380001,0.108360,-16.724838,0.011921,0.011773,0.299045,0.482011,0.024555,2.990446,-16.724838,0.300121,0.000000
18.590000,0.109108,-16.680357,0.012042,0.011910,0.302515,0.485336,0.024724,3.025146,-16.680357,0.303624,0.000000
18.800001,0.112457,-16.680357,0.012197,0.012049,0.306034,0.500235,0.025483,3.060345,-16.680357,0.307111,0.000000
19.010000,0.116554,-16.724838,0.012348,0.012185,0.309495,0.518459,0.026412,3.094954,-16.724838,0.310614,0.000000
19.220001,0.131447,-16.680357,0.012456,0.012317,0.312852,0.584705,0.029786,3.128519,-16.680357,0.314118,0.000000
19.430000,0.127724,-16.680357,0.012633,0.012460,0.316476,0.568143,0.028943,3.164763,-16.680357,0.317621,0.000000
19.640001,0.135544,-16.724838,0.012801,0.012602,0.320101,0.602929,0.030715,3.201007,-16.724838,0.321107,0.000000
19.850000,0.130333,-16.635876,0.012930,0.012741,0.323622,0.579750,0.029534,3.236222,-16.635876,0.324611,0.000000
20.060001,0.130699,-16.680357,0.013085,0.012874,0.327004,0.581379,0.029617,3.270043,-16.680357,0.328114,0.000000
20.270000,0.156395,-16.635876,0.013228,0.013011,0.330482,0.695680,0.035440,3.304819,-16.635876,0.331601,0.000000
20.480001,0.200706,-16.680357,0.013383,0.013147,0.333925,0.892787,0.045481,3.339246,-16.680357,0.335104,0.000000
20.690001,0.326569,-16.680357,0.013512,0.013285,0.337437,1.452650,0.074001,3.374370,-16.680357,0.338607,0.000000
20.900002,0.755913,-16.680357,0.013650,0.013401,0.340386,3.362468,0.171292,3.403862,-16.680357,0.341731,0.000000
21.110001,0.666176,-16.813799,0.013637,-0.000003,-0.000079,2.963298,0.150958,-0.000787,-16.813799,0.000147,0.000000
21.320002,0.646812,-16.680357,0.013633,-0.000003,-0.000079,2.877165,0.146570,-0.000787,-16.680357,0.000147,0.000000
21.530001,0.678459,-16.769318,0.013650,-0.000003,-0.000079,3.017937,0.153741,-0.000787,-16.769318,0.000312,0.000000
21.740002,0.664314,-16.680357,0.013650,-0.000003,-0.000079,2.955018,0.150536,-0.000787,-16.680357,0.000668,0.000000
21.950001,0.644951,-16.680357,0.013672,-0.000003,-0.000070,2.868885,0.146148,-0.000696,-16.680357,0.001014,0.000000
22.160002,0.789803,-16.724838,0.013650,0.000017,0.000433,3.513217,0.178972,0.004330,-16.724838,0.001361,0.000000
22.370001,0.839699,-16.680357,0.013668,0.000026,0.000659,3.735167,0.190278,0.006586,-16.680357,0.001717,0.000000
22.580002,0.945824,-16.724838,0.013668,0.000040,0.001023,4.207234,0.214327,0.010234,-16.724838,0.002064,0.000000
22.790001,1.015457,-16.769318,0.013668,0.000057,0.001447,4.516979,0.230106,0.014473,-16.769318,0.002410,0.000000
23.000002,1.151001,-16.724838,0.013706,0.000074,0.001873,5.119908,0.260821,0.018728,-16.724838,0.002766,0.000000
23.210001,1.278351,-16.813799,0.013711,0.000088,0.002229,5.686388,0.289678,0.022285,-16.813799,0.003113,0.000000
23.420002,1.388947,-16.724838,0.013719,0.000098,0.002497,6.178343,0.314740,0.024965,-16.724838,0.003459,0.000000
23.630001,1.418739,-16.813799,0.013741,0.000109,0.002775,6.310868,0.321491,0.027751,-16.813799,0.003815,0.000000
23.840002,1.551300,-16.813799,0.013754,0.000123,0.003131,6.900527,0.351530,0.031309,-16.813799,0.004162,0.000000
24.050001,1.782547,-16.769318,0.013775,0.000139,0.003520,7.929165,0.403931,0.035200,-16.769318,0.004509,0.000000
24.260000,2.002243,-16.858280,0.013771,0.000155,0.003936,8.906422,0.453715,0.039363,-16.858280,0.004864,0.000000
24.470001,2.099060,-16.769318,0.013775,0.000165,0.004180,9.337086,0.475654,0.041800,-16.769318,0.005211,0.000000
24.680000,2.318390,-16.902761,0.013788,0.000181,0.004587,10.312714,0.525355,0.045873,-16.902761,0.005567,0.000000
24.890001,2.574951,-16.769318,0.013823,0.000198,0.005038,11.453955,0.583492,0.050385,-16.769318,0.005914,0.000000
25.100000,2.773056,-16.813799,0.013810,0.000212,0.005376,12.335169,0.628383,0.053761,-16.813799,0.006260,0.000000
25.310001,2.945465,-16.858280,0.013849,0.000223,0.005662,13.102083,0.667452,0.056622,-16.858280,0.006616,0.000000
25.520000,3.058296,-16.769318,0.013857,0.000235,0.005974,13.603981,0.693020,0.059741,-16.769318,0.006963,0.000000
25.730001,3.335709,-16.813799,0.013870,0.000249,0.006322,14.837973,0.755882,0.063223,-16.813799,0.007311,0.000000
25.940001,3.517059,-16.813799,0.013853,0.000259,0.006574,15.644661,0.796977,0.065736,-16.813799,0.007665,0.000000
26.150002,3.900970,-16.813799,0.013866,0.000274,0.006955,17.352383,0.883973,0.069551,-16.813799,0.008013,0.000000
26.360001,4.051041,-16.813799,0.013896,0.000283,0.007181,18.019928,0.917979,0.071807,-16.813799,0.008360,0.000000
26.570002,4.261803,-16.813799,0.013892,0.000294,0.007474,18.957445,0.965738,0.074744,-16.813799,0.008716,0.000000
26.780001,4.705299,-16.813799,0.013939,0.000315,0.008004,20.930218,1.066236,0.080043,-16.813799,0.009063,0.000000
26.990002,5.032982,-16.858280,0.013948,0.000331,0.008412,22.387821,1.140490,0.084116,-16.858280,0.009418,0.000000
27.200001,5.264229,-16.813799,0.013935,0.000343,0.008723,23.416460,1.192891,0.087234,-16.813799,0.009765,0.000000
27.410002,5.482437,-16.813799,0.013935,0.000355,0.009010,24.387098,1.242338,0.090096,-16.813799,0.010112,0.000000
27.620001,5.783691,-16.858280,0.013978,0.000369,0.009374,25.727144,1.310603,0.093744,-16.858280,0.010468,0.000000
27.830002,6.172073,-16.902761,0.013965,0.000384,0.009756,27.454754,1.398612,0.097559,-16.902761,0.010814,0.000000
28.040001,6.440178,-16.813799,0.013987,0.000397,0.010077,28.647343,1.459365,0.100769,-16.813799,0.011161,0.000000
28.250002,6.786484,-16.858280,0.014008,0.000412,0.010458,30.187788,1.537839,0.104584,-16.858280,0.011517,0.000000
28.460001,6.853142,-16.902761,0.014004,0.000416,0.010554,30.484297,1.552944,0.105538,-16.902761,0.011863,0.000000
28.670002,7.450424,-16.858280,0.014017,0.000438,0.011126,33.141144,1.688290,0.111261,-16.858280,0.012210,0.000000
28.880001,7.828384,-16.858280,0.014047,0.000453,0.011499,34.822392,1.773937,0.114985,-16.858280,0.012566,0.000000
29.090002,8.220497,-16.858280,0.014051,0.000469,0.011915,36.566597,1.862791,0.119148,-16.858280,0.012913,0.000000
29.300001,8.328857,-16.902761,0.014077,0.000477,0.012124,37.048607,1.887346,0.121238,-16.902761,0.013268,0.000000
29.510002,8.719475,-16.947243,0.014060,0.000491,0.012470,38.786160,1.975861,0.124705,-16.947243,0.013615,0.000000
29.720001,9.070244,-16.858280,0.014090,0.000505,0.012834,40.346458,2.055346,0.128338,-16.858280,0.013962,0.000000
29.930002,9.413948,-16.902761,0.014094,0.000520,0.013217,41.875332,2.133231,0.132169,-16.902761,0.014318,0.000000
30.140001,9.766586,-16.902761,0.014094,0.000533,0.013545,43.443947,2.213140,0.135454,-16.902761,0.014664,0.000000
30.350002,9.963196,-16.902761,0.014116,0.000544,0.013815,44.318508,2.257693,0.138149,-16.902761,0.015011,0.000000
30.560001,10.338921,-16.947243,0.014137,0.000557,0.014143,45.989815,2.342833,0.141434,-16.947243,0.015367,0.000000
30.770002,10.940674,-16.902761,0.014150,0.000578,0.014690,48.666546,2.479192,0.146899,-16.902761,0.015713,0.000000
30.980001,11.350281,-16.902761,0.014168,0.000595,0.015115,50.488571,2.572010,0.151154,-16.902761,0.016060,0.000000
31.190001,11.510406,-16.947243,0.014159,0.000606,0.015392,51.200844,2.608295,0.153924,-16.947243,0.016416,0.000000
31.400002,11.732712,-16.947243,0.014198,0.000619,0.015722,52.189709,2.658670,0.157225,-16.947243,0.016763,0.000000
31.610001,12.166153,-16.991724,0.014185,0.000634,0.016113,54.117752,2.756890,0.161131,-16.991724,0.017109,0.000000
31.820002,12.499054,-16.858280,0.014215,0.000649,0.016476,55.598568,2.832326,0.164764,-16.858280,0.017465,0.000000
32.030003,12.792854,-16.991724,0.014237,0.000660,0.016763,56.905457,2.898902,0.167625,-16.991724,0.017812,0.000000
32.240002,12.858017,-16.947243,0.014232,0.000667,0.016946,57.195316,2.913668,0.169457,-16.947243,0.018167,0.000000
32.450001,13.002876,-16.947243,0.014250,0.000675,0.017136,57.839684,2.946494,0.171365,-16.947243,0.018514,0.000000
32.660000,13.853371,-17.036203,0.014262,0.000701,0.017795,61.622871,3.139219,0.177951,-17.036203,0.018862,0.000000
32.870003,14.271919,-16.902761,0.014271,0.000717,0.018220,63.484669,3.234063,0.182205,-16.902761,0.019217,0.000000
33.080002,14.419006,-16.947243,0.014293,0.000730,0.018541,64.138947,3.267394,0.185414,-16.947243,0.019565,0.000000
33.290001,14.582848,-16.991724,0.014301,0.000742,0.018853,64.867744,3.304520,0.188533,-16.991724,0.019912,0.000000
33.500000,14.981659,-16.902761,0.014310,0.000757,0.019217,66.641747,3.394892,0.192167,-16.902761,0.020267,0.000000
33.710003,14.977562,-16.947243,0.014319,0.000767,0.019469,66.623520,3.393964,0.194695,-16.947243,0.020614,0.000000
33.920002,15.774445,-16.991724,0.014336,0.000787,0.019989,70.168236,3.574540,0.199888,-16.991724,0.020961,0.000000
34.130001,15.768112,-17.036203,0.014349,0.000795,0.020205,70.140068,3.573105,0.202053,-17.036203,0.021317,0.000000
34.340000,15.801628,-17.036203,0.014366,0.000803,0.020405,70.289154,3.580700,0.204051,-17.036203,0.021663,0.000000
34.550003,16.142342,-16.991724,0.014336,0.000818,0.020787,71.804718,3.657907,0.207866,-16.991724,0.022019,0.000000
34.760002,17.065460,-16.991724,0.014422,0.000844,0.021438,75.910957,3.867089,0.214376,-16.991724,0.022366,0.000000
34.970001,17.078117,-16.947243,0.014418,0.000854,0.021698,75.967262,3.869957,0.216980,-16.947243,0.022712,0.000000
35.180000,17.164139,-16.991724,0.014439,0.000865,0.021975,76.349899,3.889449,0.219751,-16.991724,0.023068,0.000000
35.390003,17.523102,-17.036203,0.014435,0.000880,0.022357,77.946648,3.970792,0.223566,-17.036203,0.023415,0.000000
35.600002,17.958778,-16.991724,0.014474,0.000896,0.022747,79.884636,4.069518,0.227472,-16.991724,0.023762,0.000000
35.810001,18.118523,-17.080685,0.014491,0.000909,0.023085,80.595215,4.105716,0.230848,-17.080685,0.024117,0.000000
36.020000,18.363548,-16.991724,0.014482,0.000923,0.023432,81.685143,4.161240,0.234315,-16.991724,0.024464,0.000000
36.230003,18.456268,-16.991724,0.014495,0.000930,0.023615,82.097580,4.182250,0.236147,-16.991724,0.024811,0.000000
36.440002,18.910934,-17.080685,0.014495,0.000949,0.024108,84.120041,4.285279,0.241083,-17.080685,0.025167,0.000000
36.650002,19.532425,-17.036203,0.014517,0.000968,0.024585,86.884567,4.426111,0.245852,-17.036203,0.025513,0.000000
36.860001,19.566307,-17.080685,0.014534,0.000979,0.024862,87.035278,4.433789,0.248622,-17.080685,0.025869,0.000000
37.070004,19.654190,-16.991724,0.014521,0.000990,0.025157,87.426201,4.453703,0.251574,-16.991724,0.026216,0.000000
37.280003,19.923416,-17.036203,0.014560,0.001003,0.025469,88.623779,4.514710,0.254693,-17.036203,0.026562,0.000000
37.490002,20.542297,-17.080685,0.014577,0.001023,0.025973,91.376701,4.654951,0.259735,-17.080685,0.026918,0.000000
37.700001,20.664810,-17.125166,0.014577,0.001034,0.026267,91.921669,4.682713,0.262672,-17.125166,0.027265,0.000000
37.910004,20.754547,-17.080685,0.014599,0.001046,0.026571,92.320839,4.703048,0.265715,-17.080685,0.027612,0.000000
38.120003,20.887489,-17.080685,0.014607,0.001055,0.026806,92.912193,4.733173,0.268061,-17.080685,0.027967,0.000000
38.330002,21.420723,-17.080685,0.014633,0.001073,0.027248,95.284134,4.854005,0.272482,-17.080685,0.028314,0.000000
38.540001,21.861244,-17.080685,0.014620,0.001091,0.027716,97.243668,4.953829,0.277160,-17.080685,0.028661,0.000000
38.750000,22.017265,-16.991724,0.014676,0.001103,0.028020,97.937691,4.989184,0.280203,-16.991724,0.029017,0.000000
38.960003,22.213875,-17.125166,0.014659,0.001115,0.028332,98.812248,5.033736,0.283322,-17.125166,0.029363,0.000000
39.170002,22.375114,-17.080685,0.014685,0.001127,0.028618,99.529480,5.070273,0.286183,-17.080685,0.029719,0.000000
39.380001,22.601517,-17.036203,0.014698,0.001139,0.028921,100.536568,5.121577,0.289211,-17.036203,0.030066,0.000000
39.590000,23.225990,-17.125166,0.014702,0.001158,0.029416,103.314362,5.263085,0.294162,-17.125166,0.030414,0.000000
39.800003,23.215935,-17.125166,0.014724,0.001167,0.029649,103.269638,5.260806,0.296494,-17.125166,0.030768,0.000000
40.010002,23.253540,-17.125166,0.014745,0.001175,0.029840,103.436913,5.269328,0.298401,-17.125166,0.031116,0.000000
40.220001,23.518303,-17.125166,0.014711,0.001186,0.030119,104.614639,5.329324,0.301187,-17.125166,0.031463,0.000000
40.430000,24.445137,-17.036203,0.014767,0.001213,0.030821,108.737404,5.539347,0.308212,-17.036203,0.031819,0.000000
40.640003,24.788460,-17.080685,0.014763,0.001228,0.031194,110.264580,5.617145,0.311936,-17.080685,0.032166,0.000000
40.850002,24.821228,-17.036203,0.014797,0.001239,0.031463,110.410339,5.624570,0.314631,-17.036203,0.032512,0.000000
41.060001,25.018585,-17.125166,0.014771,0.001251,0.031784,111.288223,5.669292,0.317840,-17.125166,0.032868,0.000000
41.270000,25.378296,-17.080685,0.014801,0.001265,0.032122,112.888298,5.750804,0.321216,-17.080685,0.033215,0.000000
41.480003,25.578636,-17.169647,0.014827,0.001277,0.032424,113.779457,5.796202,0.324244,-17.169647,0.033561,0.000000
41.690002,26.262688,-17.169647,0.014827,0.001295,0.032903,116.822266,5.951210,0.329028,-17.169647,0.033917,0.000000
41.900002,26.352051,-17.169647,0.014840,0.001307,0.033197,117.219780,5.971460,0.331966,-17.169647,0.034264,0.000000
42.110001,26.568031,-17.214128,0.014853,0.001317,0.033457,118.180504,6.020402,0.334570,-17.214128,0.034620,0.000000
42.320004,27.189888,-17.214128,0.014857,0.001335,0.033908,120.946663,6.161316,0.339081,-17.214128,0.034966,0.000000
42.530003,27.536568,-17.125166,0.014892,0.001349,0.034255,122.488770,6.239875,0.342548,-17.125166,0.035313,0.000000
42.740002,27.822182,-17.169647,0.014896,0.001363,0.034627,123.759247,6.304596,0.346272,-17.169647,0.035669,0.000000
42.950001,28.024010,-17.125166,0.014914,0.001376,0.034948,124.657021,6.350331,0.349482,-17.125166,0.036016,0.000000
43.160004,28.376266,-17.258610,0.014905,0.001389,0.035278,126.223938,6.430154,0.352782,-17.258610,0.036362,0.000000
43.370003,28.583679,-17.125166,0.014926,0.001398,0.035520,127.146553,6.477154,0.355205,-17.125166,0.036718,0.000000
43.580002,29.285233,-17.214128,0.014926,0.001416,0.035955,130.267227,6.636128,0.359550,-17.214128,0.037065,0.000000
43.790001,29.694466,-17.125166,0.014948,0.001433,0.036388,132.087585,6.728862,0.363880,-17.125166,0.037411,0.000000
44.000004,29.762985,-17.125166,0.014952,0.001439,0.036562,132.392365,6.744389,0.365621,-17.125166,0.037767,0.000000
44.210003,30.533051,-17.214128,0.014970,0.001460,0.037074,135.817795,6.918888,0.370738,-17.214128,0.038114,0.000000
44.420002,31.005966,-17.125166,0.014978,0.001474,0.037437,137.921432,7.026052,0.374372,-17.125166,0.038470,0.000000
44.630001,31.420784,-17.258610,0.015017,0.001489,0.037811,139.766632,7.120051,0.378111,-17.258610,0.038816,0.000000
44.840004,31.526543,-17.258610,0.015000,0.001498,0.038037,140.237061,7.144017,0.380367,-17.258610,0.039163,0.000000
45.050003,31.738052,-17.169647,0.015021,0.001511,0.038383,141.177902,7.191946,0.383834,-17.169647,0.039519,0.000000
45.260002,32.298470,-17.258610,0.015004,0.001527,0.038782,143.670761,7.318938,0.387815,-17.258610,0.039866,0.000000
45.470001,32.932251,-17.169647,0.015060,0.001542,0.039172,146.489975,7.462555,0.391721,-17.169647,0.040212,0.000000
45.680000,33.419312,-17.214128,0.015052,0.001555,0.039502,148.656525,7.572924,0.395022,-17.214128,0.040568,0.000000
45.890003,33.623741,-17.258610,0.015056,0.001566,0.039788,149.565872,7.619249,0.397883,-17.258610,0.040915,0.000000
46.100002,34.183044,-17.214128,0.015069,0.001582,0.040177,152.053772,7.745988,0.401774,-17.214128,0.041263,0.000000
46.310001,34.912155,-17.347570,0.015103,0.001599,0.040621,155.297028,7.911207,0.406210,-17.347570,0.041617,0.000000
46.520000,35.327721,-17.214128,0.015103,0.001613,0.040959,157.145554,8.005376,0.409586,-17.214128,0.041965,0.000000
46.730003,35.608116,-17.258610,0.015116,0.001623,0.041228,158.392807,8.068914,0.412281,-17.258610,0.042320,0.000000
46.940002,35.933197,-17.258610,0.015125,0.001635,0.041540,159.838837,8.142579,0.415400,-17.258610,0.042666,0.000000
47.150002,36.570328,-17.258610,0.015116,0.001651,0.041931,162.672943,8.286955,0.419306,-17.258610,0.043015,0.000000
47.360001,36.882378,-17.347570,0.015151,0.001662,0.042208,164.061005,8.357666,0.422076,-17.347570,0.043369,0.000000
47.570004,37.476311,-17.258610,0.015146,0.001678,0.042615,166.702957,8.492254,0.426149,-17.258610,0.043717,0.000000
47.780003,37.586906,-17.303089,0.015164,0.001685,0.042797,167.194916,8.517315,0.427966,-17.303089,0.044064,0.000000
47.990002,37.952576,-17.303089,0.015172,0.001694,0.043031,168.821487,8.600176,0.430312,-17.303089,0.044420,0.000000
48.200001,39.523613,-17.258610,0.015172,0.001722,0.043743,175.809814,8.956179,0.437428,-17.258610,0.044766,0.000000
48.410004,39.930618,-17.303089,0.015211,0.001735,0.044064,177.620255,9.048408,0.440637,-17.303089,0.045113,0.000000
48.620003,40.127602,-17.303089,0.015215,0.001745,0.044324,178.496490,9.093044,0.443241,-17.303089,0.045469,0.000000
48.830002,40.609077,-17.303089,0.015224,0.001761,0.044722,180.638199,9.202148,0.447223,-17.303089,0.045815,0.000000
49.040001,41.338181,-17.347570,0.015233,0.001774,0.045060,183.881409,9.367366,0.450599,-17.347570,0.046162,0.000000
49.250004,41.938446,-17.303089,0.015254,0.001790,0.045469,186.551529,9.503387,0.454687,-17.303089,0.046518,0.000000
49.460003,42.352898,-17.303089,0.015254,0.001801,0.045737,188.395096,9.597303,0.457367,-17.303089,0.046865,0.000000
49.670002,42.781128,-17.303089,0.015267,0.001811,0.046006,190.299957,9.694342,0.460062,-17.303089,0.047220,0.000000
49.880001,42.556213,-17.303089,0.015267,0.001815,0.046111,189.299484,9.643375,0.461106,-17.303089,0.047567,0.000000
50.090004,44.218857,-17.347570,0.015263,0.001844,0.046846,196.695297,10.020136,0.468464,-17.347570,0.047914,0.000000
50.300003,44.773689,-17.303089,0.015280,0.001857,0.047160,199.163315,10.145864,0.471598,-17.303089,0.048270,0.000000
50.510002,45.330391,-17.347570,0.015297,0.001870,0.047506,201.639648,10.272013,0.475065,-17.347570,0.048616,0.000000
50.720001,45.588074,-17.347570,0.015284,0.001881,0.047767,202.785873,10.330405,0.477669,-17.347570,0.048963,0.000000
50.930004,46.229668,-17.303089,0.015319,0.001894,0.048104,205.639832,10.475793,0.481045,-17.303089,0.049319,0.000000
51.140003,47.108841,-17.347570,0.015323,0.001911,0.048547,209.550583,10.675015,0.485466,-17.347570,0.049665,0.000000
51.350002,47.852470,-17.303089,0.015340,0.001926,0.048921,212.858414,10.843525,0.489205,-17.303089,0.050012,0.000000
51.560001,48.259842,-17.303089,0.015366,0.001937,0.049207,214.670502,10.935837,0.492067,-17.303089,0.050368,0.000000
51.770004,48.370438,-17.347570,0.015362,0.001944,0.049379,215.162445,10.960897,0.493793,-17.347570,0.050715,0.000000
51.980003,49.353500,-17.347570,0.015362,0.001963,0.049865,219.535339,11.183662,0.498652,-17.347570,0.051070,0.000000
52.190002,50.479927,-17.347570,0.015383,0.001982,0.050333,224.545929,11.438915,0.503330,-17.347570,0.051417,0.000000
52.400002,51.150940,-17.303089,0.015392,0.001997,0.050715,227.530746,11.590968,0.507146,-17.303089,0.051764,0.000000
52.610001,51.516983,-17.392052,0.015418,0.002009,0.051026,229.158981,11.673915,0.510264,-17.392052,0.052120,0.000000
52.820004,52.380142,-17.347570,0.015409,0.002026,0.051461,232.998505,11.869510,0.514609,-17.347570,0.052466,0.000000
53.030003,52.792732,-17.347570,0.015444,0.002035,0.051677,234.833801,11.963004,0.516774,-17.347570,0.052813,0.000000
53.240002,53.914322,-17.392052,0.015444,0.002055,0.052189,239.822876,12.217160,0.521892,-17.392052,0.053169,0.000000
53.450001,54.237167,-17.392052,0.015452,0.002063,0.052398,241.258972,12.290318,0.523981,-17.392052,0.053515,0.000000
53.660004,54.554802,-17.347570,0.015448,0.002073,0.052657,242.671875,12.362295,0.526570,-17.347570,0.053864,0.000000
53.870003,54.899246,-17.392052,0.015435,0.002080,0.052831,244.204041,12.440348,0.528311,-17.392052,0.054218,0.000000
54.080002,56.466934,-17.436533,0.015474,0.002106,0.053482,251.177475,12.795590,0.534821,-17.436533,0.054566,0.000000
54.290001,57.470848,-17.481014,0.015474,0.002122,0.053889,255.643097,13.023081,0.538893,-17.481014,0.054920,0.000000
54.500004,57.962006,-17.392052,0.015500,0.002135,0.054227,257.827881,13.134378,0.542269,-17.392052,0.055269,0.000000
54.710003,58.593925,-17.392052,0.015504,0.002148,0.054557,260.638794,13.277574,0.545570,-17.392052,0.055615,0.000000
54.920002,59.242599,-17.392052,0.015487,0.002160,0.054852,263.524231,13.424565,0.548522,-17.392052,0.055971,0.000000
55.130001,59.925529,-17.347570,0.015526,0.002175,0.055234,266.562073,13.579319,0.552337,-17.347570,0.056318,0.000000
55.340004,60.801720,-17.347570,0.015526,0.002187,0.055562,270.459564,13.777866,0.555623,-17.347570,0.056664,0.000000
55.550003,61.087700,-17.436533,0.015552,0.002196,0.055771,271.731659,13.842670,0.557712,-17.436533,0.057020,0.000000
55.760002,61.537529,-17.481014,0.015578,0.002206,0.056022,273.732605,13.944603,0.560225,-17.481014,0.057367,0.000000
55.970001,63.092552,-17.392052,0.015547,0.002232,0.056699,280.649689,14.296976,0.566992,-17.392052,0.057714,0.000000
56.180004,64.301277,-17.436533,0.015599,0.002247,0.057072,286.026367,14.570877,0.570717,-17.436533,0.058069,0.000000
56.390003,64.500862,-17.525496,0.015612,0.002258,0.057349,286.914154,14.616104,0.573487,-17.525496,0.058416,0.000000
56.600002,65.090706,-17.436533,0.015612,0.002267,0.057592,289.537933,14.749764,0.575925,-17.436533,0.058763,0.000000
56.810001,65.895027,-17.481014,0.015603,0.002281,0.057948,293.115723,14.932027,0.579483,-17.481014,0.059119,0.000000
57.020004,66.999489,-17.436533,0.015603,0.002299,0.058398,298.028625,15.182302,0.583979,-17.436533,0.059465,0.000000
57.230003,67.486549,-17.436533,0.015616,0.002301,0.058442,300.195160,15.292670,0.584418,-17.436533,0.058642,0.000000
57.440002,66.956291,-17.481014,0.015621,0.002300,0.058425,297.836456,15.172512,0.584252,-17.481014,0.058642,0.000000
57.650002,66.655037,-17.392052,0.015646,0.002297,0.058337,296.496399,15.104247,0.583373,-17.392052,0.058425,0.000000
57.860004,66.350441,-17.481014,0.015642,0.002294,0.058277,295.141510,15.035225,0.582768,-17.481014,0.058425,0.000000
58.070004,66.092018,-17.481014,0.015638,0.002294,0.058260,293.991974,14.976665,0.582601,-17.481014,0.058425,0.000000
58.280003,65.879021,-17.481014,0.015646,0.002293,0.058251,293.044525,14.928400,0.582510,-17.481014,0.058425,0.000000
58.490002,65.691719,-17.525496,0.015621,0.002293,0.058242,292.211365,14.885957,0.582420,-17.525496,0.058425,0.000000
58.700005,65.518929,-17.481014,0.015668,0.002293,0.058234,291.442749,14.846802,0.582344,-17.481014,0.058425,0.000000
58.910004,65.378929,-17.481014,0.015646,0.002292,0.058225,290.820007,14.815078,0.582253,-17.481014,0.058425,0.000000
59.120003,65.215828,-17.525496,0.015646,0.002292,0.058225,290.094482,14.778117,0.582253,-17.525496,0.058425,0.000000
59.330002,65.102623,-17.436533,0.015634,0.002292,0.058225,289.590942,14.752465,0.582253,-17.436533,0.058425,0.000000
59.540005,64.967445,-17.525496,0.015638,0.002292,0.058216,288.989624,14.721833,0.582162,-17.525496,0.058425,0.000000
59.750004,64.857979,-17.481014,0.015642,0.002292,0.058216,288.502686,14.697028,0.582162,-17.481014,0.058425,0.000000
59.960003,64.762276,-17.481014,0.015638,0.002292,0.058216,288.076996,14.675342,0.582162,-17.481014,0.058425,0.000000
60.170002,64.675133,-17.525496,0.015646,0.002292,0.058216,287.689362,14.655595,0.582162,-17.525496,0.058425,0.000000
60.380001,64.594337,-17.525496,0.015642,0.002292,0.058216,287.329956,14.637286,0.582162,-17.525496,0.058425,0.000000
60.590004,64.509056,-17.569975,0.015651,0.002292,0.058216,286.950623,14.617961,0.582162,-17.569975,0.058425,0.000000
60.800003,64.439430,-17.525496,0.015646,0.002292,0.058216,286.640900,14.602183,0.582162,-17.525496,0.058425,0.000000
61.010002,64.354149,-17.525496,0.015659,0.002292,0.058216,286.261566,14.582858,0.582162,-17.525496,0.058425,0.000000
61.220001,64.295311,-17.525496,0.015642,0.002292,0.058216,285.999817,14.569526,0.582162,-17.525496,0.058425,0.000000
61.430004,64.222328,-17.481014,0.015634,0.002292,0.058216,285.675171,14.552988,0.582162,-17.481014,0.058425,0.000000
61.640003,64.149345,-17.525496,0.015638,0.002292,0.058216,285.350525,14.536449,0.582162,-17.525496,0.058425,0.000000
61.850002,64.064079,-17.525496,0.015655,0.002292,0.058216,284.971252,14.517128,0.582162,-17.525496,0.058425,0.000000
62.060001,64.025719,-17.481014,0.015664,0.002292,0.058216,284.800629,14.508435,0.582162,-17.481014,0.058425,0.000000
62.270004,63.900230,-17.614456,0.015642,0.002292,0.058207,284.242432,14.479999,0.582071,-17.614456,0.058425,0.000000
62.480003,63.868584,-17.569975,0.015646,0.002292,0.058207,284.101654,14.472828,0.582071,-17.569975,0.058425,0.000000
62.690002,63.809364,-17.569975,0.015651,0.002292,0.058207,283.838226,14.459409,0.582071,-17.569975,0.058425,0.000000
62.900002,63.763939,-17.525496,0.015646,0.002292,0.058207,283.636169,14.449115,0.582071,-17.525496,0.058425,0.000000
63.110004,63.714043,-17.525496,0.015668,0.002292,0.058207,283.414215,14.437809,0.582071,-17.525496,0.058425,0.000000
63.320004,63.659676,-17.658937,0.015668,0.002292,0.058207,283.172394,14.425488,0.582071,-17.658937,0.058425,0.000000
63.530003,63.621696,-17.569975,0.015651,0.002292,0.058207,283.003448,14.416883,0.582071,-17.569975,0.058425,0.000000
63.740002,63.571800,-17.614456,0.015646,0.002292,0.058207,282.781494,14.405576,0.582071,-17.614456,0.058425,0.000000
63.950005,63.534935,-17.525496,0.015655,0.002292,0.058207,282.617493,14.397222,0.582071,-17.525496,0.058425,0.000000
64.160004,63.485405,-17.525496,0.015664,0.002292,0.058207,282.397186,14.385999,0.582071,-17.525496,0.058425,0.000000
64.370003,63.459343,-17.569975,0.015664,0.002292,0.058207,282.281250,14.380093,0.582071,-17.569975,0.058425,0.000000
64.580002,63.400139,-17.569975,0.015664,0.002292,0.058207,282.017914,14.366676,0.582071,-17.569975,0.058425,0.000000
64.790001,63.378532,-17.614456,0.015659,0.002292,0.058207,281.921783,14.361781,0.582071,-17.614456,0.058425,0.000000
65.000000,63.342796,-17.569975,0.015659,0.002292,0.058207,281.762817,14.353683,0.582071,-17.569975,0.058425,0.000000
65.210007,63.317833,-17.658937,0.015655,0.002292,0.058207,281.651794,14.348026,0.582071,-17.658937,0.058425,0.000000
65.420006,63.267204,-17.658937,0.015642,0.002292,0.058207,281.426575,14.336554,0.582071,-17.658937,0.058425,0.000000
65.630005,63.234062,-17.525496,0.015646,0.002292,0.058207,281.279144,14.329043,0.582071,-17.525496,0.058425,0.000000
65.840004,63.212837,-17.658937,0.015664,0.002292,0.058207,281.184753,14.324233,0.582071,-17.658937,0.058425,0.000000
66.050003,63.162926,-17.569975,0.015638,0.002292,0.058207,280.962738,14.312923,0.582071,-17.569975,0.058425,0.000000
66.260002,63.131279,-17.614456,0.015659,0.002292,0.058207,280.821960,14.305753,0.582071,-17.614456,0.058425,0.000000
66.470001,63.101112,-17.658937,0.015634,0.002292,0.058207,280.687775,14.298917,0.582071,-17.658937,0.058425,0.000000
66.680000,63.076546,-17.614456,0.015668,0.002292,0.058207,280.578491,14.293349,0.582071,-17.614456,0.058425,0.000000
66.889999,63.032234,-17.614456,0.015664,0.002292,0.058207,280.381378,14.283309,0.582071,-17.614456,0.058425,0.000000
67.100006,63.014351,-17.614456,0.015655,0.002292,0.058207,280.301819,14.279256,0.582071,-17.614456,0.058425,0.000000
67.310005,62.993507,-17.569975,0.015664,0.002292,0.058207,280.209106,14.274532,0.582071,-17.569975,0.058425,0.000000
67.520004,62.965576,-17.658937,0.015668,0.002292,0.058207,280.084869,14.268203,0.582071,-17.658937,0.058425,0.000000
67.730003,62.934296,-17.614456,0.015642,0.002292,0.058207,279.945740,14.261116,0.582071,-17.614456,0.058425,0.000000
67.940002,62.919029,-17.703419,0.015659,0.002292,0.058207,279.877808,14.257656,0.582071,-17.703419,0.058425,0.000000
68.150002,62.889984,-17.658937,0.015677,0.002292,0.058207,279.748627,14.251074,0.582071,-17.658937,0.058425,0.000000
68.360001,62.875092,-17.658937,0.015677,0.002292,0.058207,279.682373,14.247700,0.582071,-17.658937,0.058425,0.000000
68.570000,62.843063,-17.703419,0.015664,0.002292,0.058207,279.539917,14.240441,0.582071,-17.703419,0.058425,0.000000
68.780006,62.811783,-17.703419,0.015646,0.002292,0.058207,279.400757,14.233353,0.582071,-17.703419,0.058425,0.000000
68.990005,62.795403,-17.658937,0.015659,0.002292,0.058207,279.327911,14.229642,0.582071,-17.658937,0.058425,0.000000
69.200005,62.782738,-17.703419,0.015655,0.002292,0.058207,279.271576,14.226772,0.582071,-17.703419,0.058425,0.000000
69.410004,62.755188,-17.658937,0.015651,0.002292,0.058207,279.149017,14.220529,0.582071,-17.658937,0.058425,0.000000
69.620003,62.734329,-17.703419,0.015672,0.002292,0.058207,279.056244,14.215803,0.582071,-17.703419,0.058425,0.000000
69.830002,62.703423,-17.658937,0.015655,0.002292,0.058207,278.918762,14.208798,0.582071,-17.658937,0.058425,0.000000
70.040001,62.698959,-17.703419,0.015672,0.002292,0.058207,278.898895,14.207788,0.582071,-17.703419,0.058425,0.000000
70.250000,62.653900,-17.747900,0.015664,0.002292,0.058207,278.698456,14.197577,0.582071,-17.747900,0.058425,0.000000
70.460007,62.637146,-17.658937,0.015681,0.002292,0.058207,278.623932,14.193780,0.582071,-17.658937,0.058425,0.000000
70.670006,62.609962,-17.747900,0.015672,0.002292,0.058207,278.503021,14.187620,0.582071,-17.747900,0.058425,0.000000
70.880005,62.604004,-17.703419,0.015664,0.002292,0.058207,278.476532,14.186271,0.582071,-17.703419,0.058425,0.000000
71.090004,62.586876,-17.658937,0.015651,0.002292,0.058207,278.400330,14.182388,0.582071,-17.658937,0.058425,0.000000
71.300003,62.569000,-17.703419,0.015655,0.002292,0.058207,278.320801,14.178338,0.582071,-17.703419,0.058425,0.000000
71.510002,62.538094,-17.703419,0.015651,0.002292,0.058207,278.183319,14.171334,0.582071,-17.703419,0.058425,0.000000
71.720001,62.525803,-17.703419,0.015668,0.002292,0.058207,278.128662,14.168550,0.582071,-17.703419,0.058425,0.000000
71.930000,62.514259,-17.703419,0.015681,0.002292,0.058207,278.077301,14.165934,0.582071,-17.703419,0.058425,0.000000
72.140007,62.482613,-17.792381,0.015677,0.002292,0.058207,277.936554,14.158762,0.582071,-17.792381,0.058425,0.000000
72.350006,62.455055,-17.703419,0.015668,0.002292,0.058207,277.813965,14.152518,0.582071,-17.703419,0.058425,0.000000
72.560005,62.444252,-17.703419,0.015651,0.002292,0.058207,277.765900,14.150069,0.582071,-17.703419,0.058425,0.000000
72.770004,62.432709,-17.747900,0.015681,0.002292,0.058207,277.714569,14.147454,0.582071,-17.747900,0.058425,0.000000
72.980003,62.418564,-17.747900,0.015672,0.002292,0.058207,277.651642,14.144248,0.582071,-17.747900,0.058425,0.000000
73.190002,62.411858,-17.792381,0.015664,0.002292,0.058207,277.621796,14.142729,0.582071,-17.792381,0.058425,0.000000
73.400002,62.384674,-17.747900,0.015672,0.002292,0.058207,277.500885,14.136569,0.582071,-17.747900,0.058425,0.000000
73.610001,62.374992,-17.792381,0.015655,0.002292,0.058207,277.457825,14.134376,0.582071,-17.792381,0.058425,0.000000
73.820000,62.360840,-17.792381,0.015655,0.002292,0.058207,277.394867,14.131168,0.582071,-17.792381,0.058425,0.000000
74.030006,62.347069,-17.792381,0.015651,0.002292,0.058207,277.333618,14.128048,0.582071,-17.792381,0.058425,0.000000
74.240005,62.324348,-17.792381,0.015668,0.002292,0.058207,277.232544,14.122900,0.582071,-17.792381,0.058425,0.000000
74.450005,62.321747,-17.747900,0.015664,0.002292,0.058207,277.220978,14.122310,0.582071,-17.747900,0.058425,0.000000
74.660004,62.300148,-17.747900,0.015672,0.002292,0.058207,277.124908,14.117415,0.582071,-17.747900,0.058425,0.000000
74.870003,62.279297,-17.836861,0.015672,0.002292,0.058207,277.032135,14.112691,0.582071,-17.836861,0.058425,0.000000
75.080002,62.255463,-17.747900,0.015664,0.002292,0.058207,276.926117,14.107289,0.582071,-17.747900,0.058425,0.000000
75.290001,62.240570,-17.792381,0.015646,0.002292,0.058207,276.859894,14.103914,0.582071,-17.792381,0.058425,0.000000
75.500000,62.217110,-17.836861,0.015634,0.002292,0.058207,276.755524,14.098598,0.582071,-17.836861,0.058425,0.000000
75.710007,62.229393,-17.792381,0.015664,0.002292,0.058207,276.810150,14.101382,0.582071,-17.792381,0.058425,0.000000
75.920006,62.202957,-17.792381,0.015672,0.002292,0.058207,276.692566,14.095392,0.582071,-17.792381,0.058425,0.000000
76.130005,62.188065,-17.747900,0.015655,0.002292,0.058207,276.626312,14.092016,0.582071,-17.747900,0.058425,0.000000
76.340004,62.176521,-17.792381,0.015646,0.002292,0.058207,276.574982,14.089401,0.582071,-17.792381,0.058425,0.000000
76.550003,62.172050,-17.792381,0.015655,0.002292,0.058207,276.555084,14.088388,0.582071,-17.792381,0.058425,0.000000
76.760002,62.147102,-17.836861,0.015681,0.002292,0.058207,276.444122,14.082735,0.582071,-17.836861,0.058425,0.000000
76.970001,62.133324,-17.792381,0.015655,0.002292,0.058207,276.382812,14.079613,0.582071,-17.792381,0.058425,0.000000
77.180000,62.126617,-17.792381,0.015664,0.002292,0.058207,276.352997,14.078094,0.582071,-17.792381,0.058425,0.000000
77.390007,62.092735,-17.881342,0.015668,0.002292,0.058207,276.202271,14.070415,0.582071,-17.881342,0.058425,0.000000
77.600006,62.093849,-17.836861,0.015638,0.002292,0.058207,276.207245,14.070667,0.582071,-17.836861,0.058425,0.000000
77.810005,62.077469,-17.836861,0.015668,0.002292,0.058207,276.134369,14.066956,0.582071,-17.836861,0.058425,0.000000
78.020004,62.059967,-17.836861,0.015646,0.002292,0.058207,276.056519,14.062989,0.582071,-17.836861,0.058425,0.000000
78.230003,62.047302,-17.836861,0.015642,0.002292,0.058207,276.000183,14.060120,0.582071,-17.836861,0.058425,0.000000
78.440002,62.035019,-17.881342,0.015655,0.002292,0.058207,275.945557,14.057336,0.582071,-17.881342,0.058425,0.000000
78.650002,62.024963,-17.836861,0.015659,0.002292,0.058207,275.900818,14.055058,0.582071,-17.836861,0.058425,0.000000
78.860001,62.011185,-17.881342,0.015659,0.002292,0.058207,275.839539,14.051935,0.582071,-17.881342,0.058425,0.000000
79.070007,62.000755,-17.881342,0.015690,0.002292,0.058207,275.793121,14.049572,0.582071,-17.881342,0.058425,0.000000
79.280006,61.995918,-17.792381,0.015685,0.002292,0.058207,275.771606,14.048475,0.582071,-17.792381,0.058425,0.000000
79.490005,61.977303,-17.925823,0.015646,0.002292,0.058207,275.688812,14.044258,0.582071,-17.925823,0.058425,0.000000
79.700005,61.970970,-17.881342,0.015672,0.002292,0.058207,275.660645,14.042823,0.582071,-17.881342,0.058425,0.000000
79.910004,61.947510,-17.881342,0.015659,0.002292,0.058207,275.556274,14.037506,0.582071,-17.881342,0.058425,0.000000
80.120003,61.932617,-17.881342,0.015659,0.002292,0.058207,275.490051,14.034132,0.582071,-17.881342,0.058425,0.000000
80.330002,61.926285,-17.881342,0.015668,0.002292,0.058207,275.461884,14.032697,0.582071,-17.881342,0.058425,0.000000
80.540001,61.915115,-17.925823,0.015664,0.002292,0.058207,275.412201,14.030166,0.582071,-17.925823,0.058425,0.000000
80.750008,61.905060,-17.925823,0.015651,0.002292,0.058207,275.367462,14.027886,0.582071,-17.925823,0.058425,0.000000
80.960007,61.896866,-17.881342,0.015664,0.002292,0.058207,275.331024,14.026031,0.582071,-17.881342,0.058425,0.000000
81.170006,61.887184,-17.970304,0.015655,0.002292,0.058207,275.287933,14.023836,0.582071,-17.970304,0.058425,0.000000
81.380005,61.876015,-17.836861,0.015672,0.002292,0.058207,275.238251,14.021306,0.582071,-17.836861,0.058425,0.000000
81.590004,61.870056,-17.881342,0.015677,0.002292,0.058207,275.211761,14.019955,0.582071,-17.881342,0.058425,0.000000
81.800003,61.856651,-17.925823,0.015672,0.002292,0.058207,275.152130,14.016917,0.582071,-17.925823,0.058425,0.000000
82.010002,61.844360,-17.881342,0.015681,0.002292,0.058207,275.097443,14.014132,0.582071,-17.881342,0.058425,0.000000
82.220001,61.813080,-17.970304,0.015659,0.002292,0.058207,274.958313,14.007045,0.582071,-17.970304,0.058425,0.000000
82.430000,61.823883,-17.970304,0.015677,0.002292,0.058207,275.006378,14.009492,0.582071,-17.970304,0.058425,0.000000
82.640007,61.819038,-17.925823,0.015681,0.002292,0.058207,274.984802,14.008394,0.582071,-17.925823,0.058425,0.000000
82.850006,61.798935,-17.881342,0.015651,0.002292,0.058207,274.895386,14.003839,0.582071,-17.881342,0.058425,0.000000
83.060005,61.789993,-17.881342,0.015659,0.002292,0.058207,274.855621,14.001813,0.582071,-17.881342,0.058425,0.000000
83.270004,61.789627,-17.925823,0.015672,0.002292,0.058207,274.853973,14.001730,0.582071,-17.925823,0.058425,0.000000
83.480003,61.775848,-17.925823,0.015659,0.002292,0.058207,274.792694,13.998607,0.582071,-17.925823,0.058425,0.000000
83.690002,61.761696,-18.014786,0.015690,0.002292,0.058207,274.729736,13.995400,0.582071,-18.014786,0.058425,0.000000
83.900002,61.763931,-17.925823,0.015672,0.002292,0.058207,274.739685,13.995907,0.582071,-17.925823,0.058425,0.000000
84.110001,61.767281,-17.970304,0.015685,0.002292,0.058207,274.754578,13.996666,0.582071,-17.970304,0.058425,0.000000
84.320007,61.724083,-17.970304,0.015668,0.002292,0.058207,274.562439,13.986876,0.582071,-17.970304,0.058425,0.000000
84.530006,61.730789,-17.925823,0.015659,0.002292,0.058207,274.592255,13.988397,0.582071,-17.925823,0.058425,0.000000
84.740005,61.712540,-18.059267,0.015672,0.002292,0.058207,274.511078,13.984262,0.582071,-18.059267,0.058425,0.000000
84.950005,61.703232,-17.970304,0.015651,0.002292,0.058207,274.469696,13.982152,0.582071,-17.970304,0.058425,0.000000
85.160004,61.704353,-17.970304,0.015685,0.002292,0.058207,274.474670,13.982407,0.582071,-17.970304,0.058425,0.000000
85.370003,61.691689,-17.970304,0.015664,0.002292,0.058207,274.418335,13.979536,0.582071,-17.970304,0.058425,0.000000
85.580002,61.676422,-17.970304,0.015677,0.002292,0.058207,274.350433,13.976077,0.582071,-17.970304,0.058425,0.000000
85.790001,61.662270,-17.970304,0.015672,0.002292,0.058207,274.287476,13.972870,0.582071,-17.970304,0.058425,0.000000
86.000008,61.663765,-17.970304,0.015659,0.002292,0.058207,274.294128,13.973209,0.582071,-17.970304,0.058425,0.000000
86.210007,61.647751,-17.970304,0.015655,0.002292,0.058207,274.222900,13.969580,0.582071,-17.970304,0.058425,0.000000
86.420006,61.638069,-18.014786,0.015664,0.002292,0.058207,274.179840,13.967386,0.582071,-18.014786,0.058425,0.000000
86.630005,61.621315,-17.970304,0.015681,0.002292,0.058207,274.105286,13.963590,0.582071,-17.970304,0.058425,0.000000
86.840004,61.613495,-18.059267,0.015681,0.002292,0.058207,274.070526,13.961818,0.582071,-18.059267,0.058425,0.000000
87.050003,61.607162,-17.970304,0.015681,0.002292,0.058207,274.042358,13.960382,0.582071,-17.970304,0.058425,0.000000
87.260002,61.605675,-18.059267,0.015694,0.002292,0.058207,274.035736,13.960046,0.582071,-18.059267,0.058425,0.000000
87.470001,61.612000,-18.014786,0.015668,0.002292,0.058207,274.063873,13.961479,0.582071,-18.014786,0.058425,0.000000
87.600006,61.593010,-17.970304,0.015638,0.002292,0.058207,273.979401,13.957176,0.582071,-17.970304,0.058425,0.000000