File: Data/New pin align test AD 4_08172023_165008.csv
Time (sec),S:Load (lbs),S:HL1 (DIM),S:LVDT (in),S:Position (in),Ch:Position (mm),Ch:Load (N),Ch:Stress (MPa),Ch:Strain (mm/mm),Ch:HL1 (DIM),Set Point (),Cycles ()
0.010000,0.020480,-155.060593,-0.000034,-0.000000,-0.000000,0.091102,0.004641,-0.000000,-155.060593,0.000068,0.000000
0.200000,0.013033,-155.016113,0.000013,-0.000000,-0.000000,0.057974,0.002953,-0.000000,-155.016113,0.000068,0.000000
0.390000,0.002979,-155.060593,-0.000026,0.000019,0.000477,0.013251,0.000675,0.004769,-155.060593,0.000970,0.000000
0.580000,0.006703,-155.016113,-0.000043,0.000141,0.003590,0.029815,0.001519,0.035896,-155.016113,0.004145,0.000000
0.770000,0.010799,-155.016113,-0.000017,0.000247,0.006278,0.048035,0.002447,0.062784,-155.016113,0.007302,0.000000
0.960000,0.044685,-155.060593,0.000069,0.000362,0.009191,0.198767,0.010126,0.091912,-155.060593,0.010475,0.000000
1.150000,0.017874,-155.016113,0.000194,0.000495,0.012583,0.079507,0.004050,0.125825,-155.016113,0.013632,0.000000
1.340000,0.019736,-155.016113,0.000358,0.000621,0.015774,0.087789,0.004472,0.157739,-155.016113,0.016806,0.000000
1.530000,0.033141,-155.016113,0.000457,0.000743,0.018879,0.147419,0.007510,0.188791,-155.016113,0.019963,0.000000
1.720000,0.064793,-154.971634,0.000604,0.000861,0.021871,0.288213,0.014682,0.218706,-154.971634,0.023136,0.000000
1.910000,0.036120,-155.016113,0.000703,0.000982,0.024932,0.160670,0.008185,0.249319,-155.016113,0.026293,0.000000
2.100000,0.052504,-154.971634,0.000845,0.001109,0.028158,0.233552,0.011898,0.281581,-154.971634,0.029468,0.000000
2.290000,0.040216,-154.971634,0.000957,0.001235,0.031366,0.178891,0.009113,0.313662,-154.971634,0.032624,0.000000
2.480000,0.037610,-154.971634,0.001082,0.001358,0.034497,0.167296,0.008522,0.344970,-154.971634,0.035799,0.000000
2.670000,0.043940,-154.927155,0.001255,0.001490,0.037844,0.195455,0.009957,0.378444,-154.927155,0.038956,0.000000
2.860000,0.047291,-154.971634,0.001371,0.001612,0.040940,0.210362,0.010716,0.409405,-154.971634,0.042129,0.000000
3.050000,0.033886,-154.971634,0.001487,0.001733,0.044029,0.150732,0.007679,0.440289,-154.971634,0.045286,0.000000
3.240000,0.028673,-154.971634,0.001634,0.001866,0.047384,0.127542,0.006497,0.473839,-154.971634,0.048460,0.000000
3.430000,0.024577,-155.016113,0.001759,0.001989,0.050515,0.109322,0.005569,0.505147,-155.016113,0.051617,0.000000
3.620000,0.036865,-154.927155,0.001841,0.002116,0.053741,0.163983,0.008354,0.537410,-154.927155,0.054790,0.000000
3.810000,0.053622,-154.971634,0.001979,0.002241,0.056916,0.238521,0.012151,0.569157,-154.971634,0.057947,0.000000
4.000000,0.038354,-154.882675,0.002104,0.002362,0.059986,0.170609,0.008691,0.599860,-154.882675,0.061122,0.000000
4.190000,0.038354,-154.882675,0.002289,0.002488,0.063194,0.170609,0.008691,0.631941,-154.882675,0.064278,0.000000
4.380000,0.043568,-154.927155,0.002393,0.002614,0.066402,0.193798,0.009873,0.664022,-154.927155,0.067453,0.000000
4.570000,0.032024,-154.927155,0.002539,0.002739,0.069559,0.142450,0.007257,0.695588,-154.927155,0.070609,0.000000
4.760000,0.046919,-154.971634,0.002626,0.002865,0.072768,0.208706,0.010632,0.727684,-154.971634,0.073783,0.000000
4.950000,0.037610,-154.882675,0.002781,0.002989,0.075916,0.167296,0.008522,0.759159,-154.882675,0.076939,0.000000
5.140000,0.033513,-154.882675,0.002880,0.003109,0.078960,0.149075,0.007594,0.789605,-154.882675,0.080114,0.000000
5.330000,0.020108,-154.971634,0.003048,0.003235,0.082161,0.089445,0.004557,0.821610,-154.971634,0.083271,0.000000
5.520000,-0.005586,-154.838196,0.003160,0.003355,0.085213,-0.024846,-0.001266,0.852131,-154.838196,0.086444,0.000000
5.710000,-0.029417,-154.882675,0.003328,0.003481,0.088414,-0.130855,-0.006666,0.884136,-154.882675,0.089601,0.000000
5.900000,-0.013405,-154.838196,0.003393,0.003610,0.091700,-0.059630,-0.003038,0.917004,-154.838196,0.092775,0.000000
6.090000,0.041706,-154.882675,0.003544,0.003733,0.094830,0.185516,0.009451,0.948298,-154.882675,0.095932,0.000000
6.280000,0.032769,-154.882675,0.003725,0.003857,0.097961,0.145763,0.007425,0.979607,-154.882675,0.099105,0.000000
6.470000,0.024577,-154.793716,0.003807,0.003984,0.101187,0.109322,0.005569,1.011869,-154.793716,0.102263,0.000000
6.660000,0.039844,-154.927155,0.003936,0.004110,0.104387,0.177234,0.009029,1.043874,-154.927155,0.105437,0.000000
6.850000,0.050270,-154.838196,0.004070,0.004232,0.107483,0.223613,0.011391,1.074834,-154.838196,0.108593,0.000000
7.040000,0.026811,-154.882675,0.004139,0.004357,0.110675,0.119260,0.006075,1.106749,-154.882675,0.111768,0.000000
7.230000,0.028673,-154.838196,0.004342,0.004482,0.113841,0.127542,0.006497,1.138406,-154.838196,0.114925,0.000000
7.420001,0.009682,-154.838196,0.004480,0.004606,0.116997,0.043066,0.002194,1.169972,-154.838196,0.118098,0.000000
7.610000,0.013405,-154.838196,0.004553,0.004732,0.120189,0.059630,0.003038,1.201886,-154.838196,0.121254,0.000000
7.800000,0.008937,-154.749222,0.004721,0.004857,0.123371,0.039753,0.002025,1.233709,-154.749222,0.124429,0.000000
7.990000,0.027556,-154.838196,0.004807,0.004983,0.126571,0.122573,0.006244,1.265714,-154.838196,0.127586,0.000000
8.180000,0.057718,-154.749222,0.004980,0.005107,0.129719,0.256741,0.013079,1.297189,-154.749222,0.130759,0.000000
8.370001,0.062931,-154.793716,0.005075,0.005230,0.132832,0.279931,0.014260,1.328316,-154.793716,0.133916,0.000000
8.560000,0.077081,-154.793716,0.005195,0.005358,0.136085,0.342874,0.017467,1.360851,-154.793716,0.137090,0.000000
8.750000,0.083039,-154.793716,0.005359,0.005482,0.139242,0.369376,0.018817,1.392417,-154.793716,0.140247,0.000000
8.940001,0.069634,-154.838196,0.005458,0.005608,0.142450,0.309746,0.015779,1.424498,-154.838196,0.143422,0.000000
9.130000,0.069261,-154.749222,0.005575,0.005733,0.145616,0.308089,0.015695,1.456155,-154.749222,0.146578,0.000000
9.320001,0.070006,-154.793716,0.005743,0.005857,0.148763,0.311402,0.015864,1.487630,-154.793716,0.149752,0.000000
9.510000,0.063303,-154.793716,0.005803,0.005977,0.151824,0.281587,0.014345,1.518242,-154.793716,0.152908,0.000000
9.700001,0.044685,-154.793716,0.005959,0.006102,0.154990,0.198767,0.010126,1.549899,-154.793716,0.156083,0.000000
9.890000,0.040589,-154.749222,0.006062,0.006230,0.158233,0.180547,0.009197,1.582328,-154.749222,0.159240,0.000000
10.080001,0.050643,-154.749222,0.006209,0.006353,0.161373,0.225270,0.011476,1.613728,-154.749222,0.162413,0.000000
10.270000,0.080432,-154.749222,0.006273,0.006471,0.164373,0.357781,0.018226,1.643734,-154.749222,0.165569,0.000000
10.460000,0.081177,-154.793716,0.006450,0.006596,0.167530,0.361094,0.018395,1.675300,-154.793716,0.168744,0.000000
10.650001,0.098306,-154.704742,0.006627,0.006722,0.170731,0.437288,0.022277,1.707306,-154.704742,0.171901,0.000000
10.840000,0.093093,-154.660263,0.006687,0.006840,0.173739,0.414099,0.021095,1.737388,-154.660263,0.175076,0.000000
11.030001,0.082667,-154.704742,0.006847,0.006963,0.176862,0.367720,0.018733,1.768621,-154.704742,0.178232,0.000000
11.220000,0.094583,-154.704742,0.007028,0.007096,0.180244,0.420724,0.021433,1.802443,-154.704742,0.181405,0.000000
11.410001,0.083411,-154.704742,0.007092,0.007219,0.183357,0.371032,0.018901,1.833570,-154.704742,0.184562,0.000000
11.600000,0.088252,-154.615784,0.007209,0.007340,0.186427,0.392566,0.019998,1.864273,-154.615784,0.187737,0.000000
11.790001,0.096072,-154.615784,0.007351,0.007471,0.189766,0.427350,0.021770,1.897655,-154.615784,0.190893,0.000000
11.980000,0.084901,-154.660263,0.007502,0.007599,0.193008,0.377658,0.019239,1.930084,-154.660263,0.194067,0.000000
12.170001,0.079688,-154.615784,0.007644,0.007720,0.196088,0.354468,0.018057,1.960878,-154.615784,0.197223,0.000000
12.360001,0.093838,-154.660263,0.007769,0.007844,0.199235,0.417412,0.021264,1.992354,-154.660263,0.200398,0.000000
12.550000,0.096817,-154.615784,0.007894,0.007967,0.202366,0.430663,0.021939,2.023662,-154.615784,0.203555,0.000000
12.740001,0.086390,-154.660263,0.008011,0.008096,0.205636,0.384284,0.019576,2.056364,-154.660263,0.206728,0.000000
12.930000,0.077826,-154.615784,0.008127,0.008219,0.208758,0.346187,0.017636,2.087582,-154.615784,0.209886,0.000000
13.120001,0.078198,-154.615784,0.008269,0.008348,0.212027,0.347843,0.017720,2.120268,-154.615784,0.213059,0.000000
13.310000,0.091976,-154.615784,0.008425,0.008473,0.215211,0.409130,0.020842,2.152107,-154.615784,0.216216,0.000000
13.500001,0.087135,-154.571304,0.008545,0.008596,0.218341,0.387596,0.019745,2.183415,-154.571304,0.219391,0.000000
13.690001,0.092348,-154.615784,0.008636,0.008716,0.221385,0.410786,0.020926,2.213846,-154.615784,0.222547,0.000000
13.880001,0.081177,-154.526825,0.008787,0.008842,0.224576,0.361094,0.018395,2.245760,-154.526825,0.225721,0.000000
14.070001,0.046547,-154.571304,0.008929,0.008960,0.227595,0.207049,0.010548,2.275948,-154.571304,0.228877,0.000000
14.260000,0.058835,-154.526825,0.009080,0.009095,0.231003,0.261710,0.013332,2.310027,-154.526825,0.232052,0.000000
14.450001,0.074102,-154.526825,0.009192,0.009218,0.234134,0.329623,0.016792,2.341336,-154.526825,0.235209,0.000000
14.640000,0.074847,-154.526825,0.009330,0.009342,0.237290,0.332935,0.016961,2.372902,-154.526825,0.238382,0.000000
14.830001,0.070751,-154.526825,0.009468,0.009466,0.240429,0.314715,0.016032,2.404286,-154.526825,0.241538,0.000000
15.020000,0.064793,-154.526825,0.009658,0.009590,0.243578,0.288213,0.014682,2.435777,-154.526825,0.244713,0.000000
15.210001,0.063303,-154.526825,0.009787,0.009716,0.246786,0.281587,0.014345,2.467858,-154.526825,0.247870,0.000000
15.400001,0.096072,-154.482346,0.009878,0.009840,0.249933,0.427350,0.021770,2.499333,-154.482346,0.251045,0.000000
15.590001,0.074474,-154.526825,0.010020,0.009966,0.253143,0.331279,0.016876,2.531429,-154.526825,0.254201,0.000000
15.780001,0.075964,-154.482346,0.010154,0.010087,0.256204,0.337905,0.017214,2.562041,-154.482346,0.257374,0.000000
15.970001,0.049525,-154.526825,0.010283,0.010211,0.259352,0.220300,0.011223,2.593516,-154.526825,0.260531,0.000000
16.160000,0.042078,-154.482346,0.010434,0.010336,0.262526,0.187173,0.009535,2.625264,-154.482346,0.263706,0.000000
16.350000,0.019363,-154.393387,0.010520,0.010461,0.265718,0.086132,0.004388,2.657178,-154.393387,0.266862,0.000000
16.540001,0.023832,-154.437866,0.010714,0.010587,0.268917,0.106009,0.005400,2.689168,-154.437866,0.270036,0.000000
16.730001,0.068516,-154.348907,0.010856,0.010713,0.272101,0.304777,0.015526,2.721006,-154.348907,0.273192,0.000000
16.920000,0.075219,-154.393387,0.010951,0.010835,0.275204,0.334592,0.017045,2.752043,-154.393387,0.276367,0.000000
17.110001,0.084156,-154.393387,0.011081,0.010962,0.278430,0.374345,0.019070,2.784305,-154.393387,0.279524,0.000000
17.300001,0.195123,-154.348907,0.011236,0.011092,0.281726,0.867951,0.044216,2.817264,-154.348907,0.282698,0.000000
17.490002,0.498979,-154.393387,0.011344,0.011213,0.284822,2.219570,0.113070,2.848224,-154.393387,0.285855,0.000000
17.680000,0.697081,-154.393387,0.011430,-0.000001,-0.000027,3.100772,0.157961,-0.000273,-154.393387,0.000173,0.000000
17.870001,0.678463,-154.348907,0.011421,-0.000001,-0.000035,3.017952,0.153742,-0.000348,-154.348907,0.000173,0.000000
18.060001,0.603243,-154.348907,0.011387,-0.000002,-0.000044,2.683360,0.136697,-0.000439,-154.348907,0.000173,0.000000
18.250000,0.643087,-154.348907,0.011395,-0.000001,-0.000035,2.860595,0.145726,-0.000348,-154.348907,0.000450,0.000000
18.440001,0.646811,-154.304413,0.011430,-0.000001,-0.000035,2.877159,0.146569,-0.000348,-154.304413,0.000771,0.000000
18.630001,0.713838,-154.259933,0.011400,0.000010,0.000251,3.175310,0.161758,0.002513,-154.259933,0.001084,0.000000
18.820002,0.784589,-154.304413,0.011447,0.000019,0.000477,3.490025,0.177790,0.004769,-154.304413,0.001405,0.000000
19.010000,0.810282,-154.304413,0.011426,0.000025,0.000640,3.604316,0.183613,0.006404,-154.304413,0.001717,0.000000
19.200001,0.927952,-154.215454,0.011451,0.000048,0.001222,4.127738,0.210277,0.012218,-154.215454,0.002038,0.000000
19.390001,1.015460,-154.259933,0.011443,0.000061,0.001543,4.516990,0.230106,0.015427,-154.259933,0.002350,0.000000
19.580002,1.091424,-154.259933,0.011430,0.000072,0.001838,4.854895,0.247320,0.018379,-154.259933,0.002671,0.000000
19.770000,1.152120,-154.259933,0.011451,0.000083,0.002107,5.124887,0.261074,0.021074,-154.259933,0.002982,0.000000
19.960001,1.216913,-154.215454,0.011495,0.000095,0.002410,5.413100,0.275756,0.024102,-154.215454,0.003303,0.000000
20.150002,1.328997,-154.215454,0.011512,0.000110,0.002801,5.911675,0.301155,0.028008,-154.215454,0.003624,0.000000
20.340000,1.420601,-154.215454,0.011538,0.000122,0.003104,6.319149,0.321913,0.031036,-154.215454,0.003936,0.000000
20.530001,1.493214,-154.126495,0.011529,0.000131,0.003338,6.642146,0.338367,0.033383,-154.126495,0.004257,0.000000
20.720001,1.591892,-154.215454,0.011507,0.000143,0.003624,7.081090,0.360728,0.036244,-154.215454,0.004569,0.000000
20.910002,1.700253,-154.215454,0.011525,0.000154,0.003901,7.563101,0.385283,0.039015,-154.215454,0.004890,0.000000
21.100000,1.829838,-154.170975,0.011589,0.000170,0.004318,8.139527,0.414647,0.043178,-154.170975,0.005202,0.000000
21.290001,1.941922,-154.215454,0.011559,0.000185,0.004708,8.638103,0.440046,0.047084,-154.215454,0.005523,0.000000
21.480001,2.043208,-154.126495,0.011620,0.000197,0.005004,9.088641,0.462997,0.050036,-154.126495,0.005836,0.000000
21.670000,2.116937,-154.170975,0.011628,0.000206,0.005220,9.416608,0.479705,0.052201,-154.170975,0.006157,0.000000
21.860001,2.215988,-154.126495,0.011598,0.000218,0.005541,9.857208,0.502150,0.055411,-154.126495,0.006469,0.000000
22.050001,2.319508,-154.082016,0.011645,0.000228,0.005792,10.317687,0.525608,0.057924,-154.082016,0.006790,0.000000
22.240002,2.452445,-154.126495,0.011628,0.000242,0.006157,10.909020,0.555732,0.061573,-154.126495,0.007102,0.000000
22.430000,2.599160,-154.082016,0.011654,0.000253,0.006434,11.561640,0.588978,0.064343,-154.082016,0.007423,0.000000
22.620001,2.679592,-154.082016,0.011615,0.000264,0.006702,11.919421,0.607204,0.067023,-154.082016,0.007735,0.000000
22.810001,2.717574,-154.170975,0.011632,0.000266,0.006764,12.088373,0.615811,0.067644,-154.170975,0.008056,0.000000
23.000002,2.939881,-154.082016,0.011645,0.000283,0.007197,13.077242,0.666186,0.071974,-154.082016,0.008368,0.000000
23.190001,3.177827,-154.126495,0.011684,0.000303,0.007691,14.135679,0.720106,0.076909,-154.126495,0.008689,0.000000
23.380001,3.355448,-154.082016,0.011740,0.000319,0.008091,14.925779,0.760355,0.080906,-154.082016,0.009000,0.000000
23.570002,3.522271,-154.082016,0.011732,0.000331,0.008412,15.667845,0.798158,0.084116,-154.082016,0.009321,0.000000
23.760000,3.582223,-154.037537,0.011723,0.000339,0.008611,15.934525,0.811743,0.086114,-154.037537,0.009635,0.000000
23.950001,3.763196,-153.993057,0.011719,0.000351,0.008914,16.739532,0.852752,0.089142,-153.993057,0.009956,0.000000
24.140001,3.962415,-154.037537,0.011770,0.000364,0.009253,17.625704,0.897896,0.092533,-154.037537,0.010268,0.000000
24.330002,4.124397,-153.993057,0.011775,0.000374,0.009512,18.346235,0.934602,0.095122,-153.993057,0.010589,0.000000
24.520000,4.467352,-154.037537,0.011796,0.000393,0.009989,19.871777,1.012316,0.099891,-154.037537,0.010900,0.000000
24.710001,4.614067,-153.948578,0.011818,0.000401,0.010198,20.524395,1.045563,0.101980,-153.948578,0.011221,0.000000
24.900002,4.814031,-153.948578,0.011826,0.000412,0.010466,21.413879,1.090875,0.104660,-153.948578,0.011533,0.000000
25.090002,5.104109,-153.993057,0.011809,0.000429,0.010891,22.704212,1.156608,0.108914,-153.993057,0.011854,0.000000
25.280001,5.349875,-153.904083,0.011835,0.000441,0.011203,23.797432,1.212299,0.112033,-153.904083,0.012166,0.000000
25.470001,5.621335,-153.948578,0.011809,0.000454,0.011542,25.004946,1.273813,0.115424,-153.948578,0.012487,0.000000
25.660002,5.865239,-153.948578,0.011826,0.000466,0.011838,26.089884,1.329082,0.118376,-153.948578,0.012808,0.000000
25.850000,6.109888,-153.904083,0.011887,0.000479,0.012166,27.178137,1.384520,0.121662,-153.904083,0.013120,0.000000
26.040001,6.222716,-153.948578,0.011865,0.000486,0.012349,27.680025,1.410088,0.123494,-153.948578,0.013441,0.000000
26.230001,6.442044,-153.904083,0.011857,0.000494,0.012548,28.655642,1.459788,0.125477,-153.904083,0.013753,0.000000
26.420002,6.932458,-153.948578,0.011874,0.000513,0.013025,30.837112,1.570917,0.130246,-153.948578,0.014074,0.000000
26.610001,7.322332,-153.904083,0.011926,0.000528,0.013399,32.571358,1.659264,0.133985,-153.904083,0.014387,0.000000
26.800001,7.587089,-153.815125,0.011895,0.000540,0.013710,33.749058,1.719259,0.137104,-153.815125,0.014708,0.000000
26.990002,7.836951,-153.904083,0.011900,0.000550,0.013962,34.860497,1.775878,0.139617,-153.904083,0.015020,0.000000
27.180002,8.285660,-153.904083,0.011926,0.000567,0.014395,36.856457,1.877557,0.143947,-153.904083,0.015341,0.000000
27.370001,8.693407,-153.904083,0.011926,0.000581,0.014769,38.670204,1.969954,0.147687,-153.904083,0.015653,0.000000
27.560001,8.981624,-153.815125,0.011943,0.000592,0.015037,39.952259,2.035265,0.150366,-153.815125,0.015974,0.000000
27.750002,9.197599,-153.859604,0.011960,0.000602,0.015288,40.912964,2.084206,0.152879,-153.859604,0.016286,0.000000
27.940001,9.449323,-153.859604,0.011986,0.000613,0.015567,42.032688,2.141247,0.155665,-153.859604,0.016607,0.000000
28.130001,9.877551,-153.815125,0.012003,0.000627,0.015913,43.937542,2.238285,0.159132,-153.815125,0.016918,0.000000
28.320002,10.460315,-153.815125,0.012012,0.000644,0.016355,46.529804,2.370341,0.163553,-153.815125,0.017239,0.000000
28.510002,10.684111,-153.770645,0.012025,0.000652,0.016572,47.525299,2.421054,0.165718,-153.770645,0.017551,0.000000
28.700001,10.858008,-153.726166,0.012008,0.000662,0.016806,48.298832,2.460460,0.168064,-153.726166,0.017872,0.000000
28.890001,11.303738,-153.770645,0.012016,0.000676,0.017170,50.281536,2.561464,0.171698,-153.770645,0.018186,0.000000
29.080002,11.730476,-153.726166,0.012016,0.000690,0.017535,52.179764,2.658164,0.175347,-153.726166,0.018507,0.000000
29.270000,12.216423,-153.726166,0.012055,0.000705,0.017900,54.341362,2.768281,0.178995,-153.726166,0.018818,0.000000
29.460001,12.573900,-153.681686,0.012055,0.000715,0.018151,55.931503,2.849287,0.181508,-153.681686,0.019139,0.000000
29.650002,12.898237,-153.726166,0.012081,0.000728,0.018479,57.374226,2.922782,0.184794,-153.726166,0.019451,0.000000
29.840002,13.232255,-153.770645,0.012059,0.000740,0.018793,58.860008,2.998472,0.187928,-153.770645,0.019772,0.000000
30.030001,13.593828,-153.637207,0.012089,0.000750,0.019044,60.468369,3.080405,0.190441,-153.637207,0.020084,0.000000
30.220001,14.187762,-153.681686,0.012107,0.000763,0.019382,63.110317,3.214993,0.193817,-153.681686,0.020405,0.000000
30.410002,14.457360,-153.637207,0.012085,0.000773,0.019642,64.309547,3.276085,0.196421,-153.637207,0.020717,0.000000
30.600002,14.866225,-153.681686,0.012072,0.000785,0.019937,66.128273,3.368735,0.199373,-153.681686,0.021038,0.000000
30.790001,15.316051,-153.681686,0.012171,0.000797,0.020240,68.129196,3.470667,0.202401,-153.681686,0.021350,0.000000
30.980001,15.715980,-153.637207,0.012158,0.000811,0.020605,69.908165,3.561292,0.206050,-153.637207,0.021671,0.000000
31.170002,16.262623,-153.637207,0.012167,0.000826,0.020986,72.339760,3.685163,0.209865,-153.637207,0.021992,0.000000
31.360001,16.798466,-153.637207,0.012163,0.000840,0.021342,74.723305,3.806587,0.213423,-153.637207,0.022304,0.000000
31.550001,17.095621,-153.592728,0.012171,0.000850,0.021603,76.045120,3.873923,0.216027,-153.592728,0.022625,0.000000
31.740002,17.493687,-153.637207,0.012202,0.000864,0.021949,77.815804,3.964126,0.219494,-153.637207,0.022938,0.000000
31.930002,17.949842,-153.592728,0.012158,0.000875,0.022217,79.844887,4.067492,0.222173,-153.592728,0.023259,0.000000
32.120003,18.446960,-153.592728,0.012206,0.000889,0.022573,82.056175,4.180141,0.225731,-153.592728,0.023571,0.000000
32.310001,18.834227,-153.592728,0.012171,0.000900,0.022868,83.778824,4.267897,0.228683,-153.592728,0.023892,0.000000
32.500000,19.137339,-153.503769,0.012219,0.000908,0.023059,85.127136,4.336583,0.230591,-153.503769,0.024204,0.000000
32.690002,19.017807,-153.548248,0.012249,0.000910,0.023101,84.595428,4.309496,0.231015,-153.548248,0.024525,0.000000
32.880001,20.350901,-153.548248,0.012262,0.000940,0.023874,90.525330,4.611580,0.238736,-153.548248,0.024836,0.000000
33.070000,20.902012,-153.592728,0.012249,0.000953,0.024195,92.976791,4.736464,0.241946,-153.592728,0.025157,0.000000
33.260002,21.160810,-153.459274,0.012245,0.000963,0.024455,94.127983,4.795108,0.244550,-153.459274,0.025469,0.000000
33.450001,21.577868,-153.637207,0.012271,0.000973,0.024715,95.983147,4.889615,0.247154,-153.637207,0.025790,0.000000
33.640003,22.134565,-153.503769,0.012296,0.000986,0.025036,98.459465,5.015764,0.250363,-153.503769,0.026102,0.000000
33.830002,22.539705,-153.459274,0.012296,0.000997,0.025332,100.261620,5.107570,0.253315,-153.459274,0.026423,0.000000
34.020000,23.129543,-153.592728,0.012340,0.001011,0.025678,102.885345,5.241230,0.256782,-153.592728,0.026736,0.000000
34.210003,23.606552,-153.459274,0.012331,0.001024,0.026007,105.007187,5.349321,0.260068,-153.459274,0.027057,0.000000
34.400002,24.161015,-153.459274,0.012348,0.001037,0.026346,107.473564,5.474964,0.263459,-153.459274,0.027369,0.000000
34.590000,24.277195,-153.414795,0.012340,0.001045,0.026537,107.990356,5.501291,0.265367,-153.414795,0.027690,0.000000
34.780003,25.143705,-153.414795,0.012344,0.001062,0.026970,111.844788,5.697645,0.269696,-153.414795,0.028002,0.000000
34.970001,25.995695,-153.459274,0.012357,0.001080,0.027421,115.634628,5.890708,0.274208,-153.459274,0.028323,0.000000
35.160000,26.417965,-153.414795,0.012426,0.001091,0.027716,117.512978,5.986396,0.277160,-153.414795,0.028635,0.000000
35.350002,26.603779,-153.459274,0.012391,0.001098,0.027898,118.339516,6.028502,0.278977,-153.459274,0.028956,0.000000
35.540001,27.274422,-153.414795,0.012396,0.001115,0.028323,121.322685,6.180472,0.283231,-153.414795,0.029268,0.000000
35.730003,27.608812,-153.414795,0.012396,0.001124,0.028540,122.810127,6.256246,0.285396,-153.414795,0.029589,0.000000
35.920002,28.322277,-153.370316,0.012396,0.001140,0.028965,125.983780,6.417920,0.289650,-153.370316,0.029901,0.000000
36.110001,28.834290,-153.370316,0.012430,0.001151,0.029242,128.261322,6.533944,0.292421,-153.370316,0.030222,0.000000
36.300003,29.162722,-153.414795,0.012421,0.001159,0.029433,129.722260,6.608367,0.294329,-153.414795,0.030535,0.000000
36.490002,29.456896,-153.370316,0.012478,0.001167,0.029642,131.030823,6.675028,0.296418,-153.370316,0.030854,0.000000
36.680000,29.972631,-153.325836,0.012447,0.001179,0.029945,133.324921,6.791895,0.299446,-153.325836,0.031175,0.000000
36.870003,30.967611,-153.370316,0.012434,0.001199,0.030456,137.750809,7.017361,0.304563,-153.370316,0.031489,0.000000
37.060001,31.832632,-153.281357,0.012473,0.001216,0.030882,141.598618,7.213377,0.308817,-153.281357,0.031810,0.000000
37.250000,32.076908,-153.325836,0.012503,0.001225,0.031107,142.685211,7.268731,0.311073,-153.325836,0.032122,0.000000
37.440002,32.620571,-153.236877,0.012482,0.001238,0.031436,145.103546,7.391927,0.314358,-153.236877,0.032443,0.000000
37.630001,33.210785,-153.281357,0.012516,0.001251,0.031775,147.728943,7.525671,0.317750,-153.281357,0.032754,0.000000
37.820004,33.680717,-153.325836,0.012512,0.001262,0.032052,149.819321,7.632160,0.320520,-153.325836,0.033075,0.000000
38.010002,34.404610,-153.236877,0.012534,0.001277,0.032434,153.039352,7.796196,0.324335,-153.236877,0.033387,0.000000
38.200001,34.702133,-153.325836,0.012503,0.001286,0.032668,154.362793,7.863616,0.326682,-153.325836,0.033708,0.000000
38.390003,34.967636,-153.281357,0.012585,0.001293,0.032833,155.543808,7.923779,0.328332,-153.281357,0.034020,0.000000
38.580002,35.290485,-153.236877,0.012577,0.001302,0.033075,156.979919,7.996938,0.330754,-153.236877,0.034341,0.000000
38.770000,36.418026,-153.192398,0.012547,0.001323,0.033604,161.995468,8.252443,0.336038,-153.192398,0.034653,0.000000
38.960003,37.445404,-153.192398,0.012568,0.001342,0.034081,166.565475,8.485250,0.340807,-153.192398,0.034974,0.000000
39.150002,37.679996,-153.236877,0.012581,0.001349,0.034264,167.608994,8.538409,0.342639,-153.236877,0.035287,0.000000
39.340000,38.106735,-153.147919,0.012620,0.001361,0.034567,169.507217,8.635110,0.345667,-153.147919,0.035608,0.000000
39.530003,38.603855,-153.192398,0.012633,0.001372,0.034844,171.718521,8.747759,0.348437,-153.192398,0.035920,0.000000
39.720001,39.529945,-153.281357,0.012659,0.001389,0.035269,175.837982,8.957613,0.352692,-153.281357,0.036241,0.000000
39.910004,39.995781,-153.058960,0.012646,0.001400,0.035564,177.910126,9.063173,0.355644,-153.058960,0.036553,0.000000
40.100002,40.512264,-153.192398,0.012633,0.001412,0.035860,180.207550,9.180210,0.358596,-153.192398,0.036874,0.000000
40.290001,40.969162,-153.192398,0.012654,0.001421,0.036102,182.239929,9.283745,0.361018,-153.192398,0.037186,0.000000
40.480003,41.520275,-153.103439,0.012646,0.001435,0.036458,184.691406,9.408628,0.364576,-153.103439,0.037507,0.000000
40.670002,42.351784,-153.192398,0.012676,0.001450,0.036839,188.390137,9.597052,0.368391,-153.192398,0.037819,0.000000
40.860001,43.231327,-153.058960,0.012663,0.001467,0.037255,192.302551,9.796359,0.372555,-153.058960,0.038140,0.000000
41.050003,43.465176,-153.192398,0.012710,0.001476,0.037490,193.342758,9.849349,0.374901,-153.192398,0.038452,0.000000
41.240002,44.042725,-153.058960,0.012672,0.001488,0.037784,195.911819,9.980224,0.377838,-153.058960,0.038772,0.000000
41.430000,44.563301,-153.147919,0.012680,0.001498,0.038044,198.227463,10.098188,0.380443,-153.147919,0.039086,0.000000
41.620003,45.469284,-153.103439,0.012693,0.001514,0.038452,202.257477,10.303487,0.384515,-153.103439,0.039407,0.000000
41.810001,45.924698,-153.058960,0.012745,0.001525,0.038730,204.283264,10.406685,0.387301,-153.058960,0.039719,0.000000
42.000004,46.335052,-153.103439,0.012732,0.001535,0.038990,206.108612,10.499673,0.389905,-153.103439,0.040040,0.000000
42.190002,46.666462,-153.014465,0.012775,0.001542,0.039172,207.582794,10.574772,0.391721,-153.014465,0.040361,0.000000
42.380001,47.480095,-153.058960,0.012762,0.001557,0.039535,211.202011,10.759144,0.395355,-153.058960,0.040672,0.000000
42.570004,48.494438,-153.014465,0.012762,0.001577,0.040047,215.714035,10.988997,0.400472,-153.014465,0.040993,0.000000
42.760002,49.170666,-153.014465,0.012801,0.001590,0.040395,218.722046,11.142233,0.403954,-153.014465,0.041305,0.000000
42.950001,49.465214,-153.014465,0.012810,0.001599,0.040603,220.032257,11.208978,0.406028,-153.014465,0.041626,0.000000
43.140003,50.050209,-152.969986,0.012771,0.001609,0.040872,222.634445,11.341539,0.408723,-152.969986,0.041938,0.000000
43.330002,50.555519,-153.014465,0.012818,0.001621,0.041166,224.882187,11.456044,0.411660,-153.014465,0.042259,0.000000
43.520000,51.013538,-153.058960,0.012814,0.001632,0.041445,226.919556,11.559834,0.414446,-153.058960,0.042571,0.000000
43.710003,51.641731,-152.969986,0.012840,0.001642,0.041703,229.713898,11.702184,0.417035,-152.969986,0.042892,0.000000
43.900002,52.398766,-152.969986,0.012844,0.001657,0.042077,233.081345,11.873730,0.420774,-152.969986,0.043204,0.000000
44.090004,52.788639,-152.969986,0.012840,0.001665,0.042285,234.815598,11.962077,0.422848,-152.969986,0.043525,0.000000
44.280003,53.327087,-152.925507,0.012831,0.001675,0.042545,237.210739,12.084090,0.425452,-152.925507,0.043838,0.000000
44.470001,54.008530,-152.881027,0.012818,0.001691,0.042945,240.241943,12.238508,0.429449,-152.881027,0.044159,0.000000
44.660004,55.197514,-152.881027,0.012904,0.001711,0.043457,245.530807,12.507936,0.434566,-152.881027,0.044471,0.000000
44.850002,56.014874,-152.925507,0.012848,0.001724,0.043794,249.166595,12.693152,0.437943,-152.925507,0.044792,0.000000
45.040001,56.452038,-152.925507,0.012909,0.001734,0.044055,251.111206,12.792215,0.440547,-152.925507,0.045104,0.000000
45.230003,56.822178,-152.836548,0.012935,0.001744,0.044306,252.757675,12.876089,0.443060,-152.836548,0.045425,0.000000
45.420002,57.710285,-152.881027,0.012913,0.001758,0.044662,256.708160,13.077338,0.446618,-152.881027,0.045737,0.000000
45.610001,57.876736,-152.881027,0.012887,0.001765,0.044827,257.448578,13.115056,0.448268,-152.881027,0.046058,0.000000
45.800003,58.817719,-152.836548,0.012909,0.001781,0.045234,261.634277,13.328285,0.452340,-152.836548,0.046370,0.000000
45.990002,59.890900,-152.881027,0.012956,0.001798,0.045667,266.408020,13.571472,0.456670,-152.881027,0.046690,0.000000
46.180000,60.083042,-152.792068,0.012960,0.001807,0.045893,267.262726,13.615012,0.458926,-152.792068,0.047002,0.000000
46.370003,60.717194,-152.881027,0.012935,0.001817,0.046153,270.083557,13.758713,0.461530,-152.881027,0.047323,0.000000
46.560001,61.699883,-152.792068,0.012939,0.001833,0.046569,274.454773,13.981394,0.465693,-152.792068,0.047637,0.000000
46.750004,62.294933,-152.792068,0.012978,0.001847,0.046916,277.101715,14.116233,0.469160,-152.792068,0.047958,0.000000
46.940002,62.879559,-152.792068,0.012969,0.001857,0.047176,279.702240,14.248712,0.471764,-152.792068,0.048270,0.000000
47.130001,63.295128,-152.792068,0.012969,0.001868,0.047437,281.550781,14.342881,0.474368,-152.792068,0.048590,0.000000
47.320004,64.159027,-152.747589,0.013008,0.001881,0.047765,285.393616,14.538644,0.477654,-152.747589,0.048902,0.000000
47.510002,64.405167,-152.747589,0.012969,0.001888,0.047965,286.488495,14.594419,0.479652,-152.747589,0.049223,0.000000
47.700001,65.294388,-152.836548,0.013008,0.001906,0.048416,290.443939,14.795919,0.484164,-152.836548,0.049544,0.000000
47.890003,66.614449,-152.703110,0.013021,0.001923,0.048851,296.315857,15.095050,0.488509,-152.703110,0.049856,0.000000
48.080002,67.044914,-152.747589,0.013008,0.001932,0.049067,298.230682,15.192595,0.490674,-152.747589,0.050177,0.000000
48.270000,67.204659,-152.703110,0.012995,0.001930,0.049014,298.941254,15.228794,0.490144,-152.703110,0.049249,0.000000
48.460003,66.811066,-152.658630,0.013025,0.001930,0.049014,297.190460,15.139604,0.490144,-152.658630,0.049249,0.000000
48.650002,66.568649,-152.747589,0.013064,0.001926,0.048928,296.112152,15.084671,0.489281,-152.747589,0.049014,0.000000
48.840004,66.318413,-152.658630,0.013060,0.001925,0.048884,294.999023,15.027967,0.488842,-152.658630,0.049014,0.000000
49.030003,66.086426,-152.703110,0.013034,0.001924,0.048868,293.967102,14.975398,0.488675,-152.703110,0.049014,0.000000
49.220001,65.911781,-152.747589,0.013021,0.001924,0.048858,293.190247,14.935823,0.488585,-152.747589,0.049014,0.000000
49.410004,65.752785,-152.658630,0.013042,0.001924,0.048858,292.483002,14.899794,0.488585,-152.658630,0.049014,0.000000
49.600002,65.597504,-152.658630,0.013047,0.001923,0.048851,291.792267,14.864607,0.488509,-152.658630,0.049014,0.000000
49.790001,65.483185,-152.658630,0.013047,0.001923,0.048851,291.283752,14.838701,0.488509,-152.658630,0.049014,0.000000
49.980003,65.366631,-152.703110,0.013038,0.001923,0.048851,290.765289,14.812291,0.488509,-152.703110,0.049014,0.000000
50.170002,65.235184,-152.658630,0.013073,0.001923,0.048851,290.180603,14.782503,0.488509,-152.658630,0.049014,0.000000
50.360001,65.118629,-152.569656,0.013038,0.001923,0.048851,289.662140,14.756093,0.488509,-152.569656,0.049014,0.000000
50.550003,65.037453,-152.614136,0.013051,0.001923,0.048842,289.301025,14.737697,0.488418,-152.614136,0.049014,0.000000
50.740002,64.948830,-152.525177,0.013060,0.001923,0.048842,288.906830,14.717615,0.488418,-152.525177,0.049014,0.000000
50.930004,64.850151,-152.569656,0.013060,0.001923,0.048842,288.467865,14.695254,0.488418,-152.569656,0.049014,0.000000
51.120003,64.787590,-152.614136,0.013064,0.001923,0.048842,288.189606,14.681078,0.488418,-152.614136,0.049014,0.000000
51.310001,64.714981,-152.614136,0.013051,0.001923,0.048842,287.866608,14.664624,0.488418,-152.614136,0.049014,0.000000
51.500004,64.632690,-152.569656,0.013055,0.001923,0.048842,287.500580,14.645977,0.488418,-152.569656,0.049014,0.000000
51.690002,64.565659,-152.525177,0.013068,0.001923,0.048842,287.202393,14.630788,0.488418,-152.525177,0.049014,0.000000
51.880001,64.501984,-152.525177,0.013051,0.001923,0.048842,286.919159,14.616359,0.488418,-152.525177,0.049014,0.000000
52.070004,64.436447,-152.525177,0.013012,0.001923,0.048842,286.627625,14.601508,0.488418,-152.525177,0.049014,0.000000
52.260002,64.390648,-152.480698,0.013073,0.001923,0.048842,286.423920,14.591129,0.488418,-152.480698,0.049014,0.000000
52.450001,64.327339,-152.525177,0.013068,0.001923,0.048842,286.142303,14.576783,0.488418,-152.525177,0.049014,0.000000
52.640003,64.274467,-152.436218,0.013068,0.001923,0.048833,285.907104,14.564802,0.488327,-152.436218,0.049014,0.000000
52.830002,64.213768,-152.436218,0.013060,0.001923,0.048833,285.637115,14.551047,0.488327,-152.436218,0.049014,0.000000
53.020004,64.200737,-152.525177,0.013055,0.001923,0.048833,285.579132,14.548095,0.488327,-152.525177,0.049014,0.000000
53.210003,64.143387,-152.436218,0.013073,0.001923,0.048833,285.324036,14.535099,0.488327,-152.436218,0.049014,0.000000
53.400002,64.081947,-152.525177,0.013034,0.001923,0.048833,285.050751,14.521176,0.488327,-152.525177,0.049014,0.000000
53.590004,64.041733,-152.480698,0.013085,0.001923,0.048833,284.871857,14.512064,0.488327,-152.480698,0.049014,0.000000
53.780003,64.023483,-152.436218,0.013025,0.001923,0.048833,284.790680,14.507929,0.488327,-152.436218,0.049014,0.000000
53.970001,63.953480,-152.436218,0.013055,0.001923,0.048833,284.479279,14.492066,0.488327,-152.436218,0.049014,0.000000
54.160004,63.923691,-152.347260,0.013029,0.001923,0.048833,284.346771,14.485315,0.488327,-152.347260,0.049014,0.000000
54.350002,63.894646,-152.436218,0.013051,0.001923,0.048833,284.217590,14.478733,0.488327,-152.436218,0.049014,0.000000
54.540001,63.846237,-152.347260,0.013042,0.001923,0.048833,284.002258,14.467764,0.488327,-152.347260,0.049014,0.000000
54.730003,63.822033,-152.391739,0.013012,0.001923,0.048833,283.894592,14.462279,0.488327,-152.391739,0.049014,0.000000
54.920002,63.788895,-152.391739,0.013068,0.001923,0.048833,283.747162,14.454770,0.488327,-152.391739,0.049014,0.000000
55.110004,63.749420,-152.347260,0.013073,0.001923,0.048833,283.571594,14.445825,0.488327,-152.347260,0.049014,0.000000
55.300003,63.734528,-152.391739,0.013042,0.001923,0.048833,283.505341,14.442451,0.488327,-152.391739,0.049014,0.000000
55.490002,63.699894,-152.302780,0.013068,0.001923,0.048833,283.351288,14.434603,0.488327,-152.302780,0.049014,0.000000
55.680004,63.654465,-152.347260,0.013055,0.001923,0.048833,283.149200,14.424309,0.488327,-152.347260,0.049014,0.000000
55.870003,63.611271,-152.347260,0.013034,0.001923,0.048833,282.957062,14.414520,0.488327,-152.347260,0.049014,0.000000
56.060001,63.603451,-152.258301,0.013064,0.001923,0.048833,282.922272,14.412747,0.488327,-152.258301,0.049014,0.000000
56.250004,63.577759,-152.302780,0.013012,0.001923,0.048833,282.807983,14.406926,0.488327,-152.302780,0.049014,0.000000
56.440002,63.542755,-152.258301,0.013042,0.001923,0.048833,282.652283,14.398994,0.488327,-152.258301,0.049014,0.000000
56.630001,63.520412,-152.258301,0.013034,0.001923,0.048833,282.552917,14.393931,0.488327,-152.258301,0.049014,0.000000
56.820004,63.493973,-152.258301,0.013085,0.001923,0.048833,282.435303,14.387940,0.488327,-152.258301,0.049014,0.000000
57.010002,63.463066,-152.213821,0.013042,0.001923,0.048833,282.297821,14.380937,0.488327,-152.213821,0.049014,0.000000
57.200005,63.438862,-152.258301,0.013064,0.001923,0.048833,282.190155,14.375452,0.488327,-152.258301,0.049014,0.000000
57.390003,63.415775,-152.169327,0.013090,0.001923,0.048833,282.087463,14.370220,0.488327,-152.169327,0.049014,0.000000
57.580002,63.385612,-152.213821,0.013029,0.001923,0.048833,281.953278,14.363385,0.488327,-152.213821,0.049014,0.000000
57.770004,63.361038,-152.169327,0.013060,0.001923,0.048833,281.843964,14.357816,0.488327,-152.169327,0.049014,0.000000
57.960003,63.349121,-152.213821,0.013068,0.001923,0.048833,281.790955,14.355116,0.488327,-152.213821,0.049014,0.000000
58.150002,63.320450,-152.124847,0.013047,0.001923,0.048833,281.663422,14.348619,0.488327,-152.124847,0.049014,0.000000
58.340004,63.289913,-152.080368,0.013034,0.001923,0.048833,281.527588,14.341700,0.488327,-152.080368,0.049014,0.000000
58.530003,63.267200,-152.124847,0.013055,0.001923,0.048833,281.426575,14.336553,0.488327,-152.124847,0.049014,0.000000
58.720001,63.258263,-152.169327,0.013064,0.001922,0.048824,281.386810,14.334527,0.488236,-152.169327,0.049014,0.000000
58.910004,63.221024,-152.080368,0.013051,0.001922,0.048824,281.221161,14.326089,0.488236,-152.080368,0.049014,0.000000
59.100002,63.207249,-152.080368,0.013047,0.001922,0.048824,281.159882,14.322967,0.488236,-152.080368,0.049014,0.000000
59.290001,63.199055,-152.080368,0.013060,0.001922,0.048824,281.123444,14.321111,0.488236,-152.080368,0.049014,0.000000
59.480003,63.168148,-152.124847,0.013060,0.001922,0.048824,280.985962,14.314107,0.488236,-152.124847,0.049014,0.000000
59.670002,63.146923,-152.080368,0.013051,0.001922,0.048824,280.891541,14.309298,0.488236,-152.080368,0.049014,0.000000
59.860004,63.123463,-152.080368,0.013034,0.001922,0.048824,280.787170,14.303981,0.488236,-152.080368,0.049014,0.000000
60.050003,63.101864,-152.080368,0.013073,0.001922,0.048824,280.691101,14.299088,0.488236,-152.080368,0.049014,0.000000
60.240002,63.111546,-152.035889,0.013060,0.001922,0.048824,280.734161,14.301280,0.488236,-152.035889,0.049014,0.000000
60.430004,63.070957,-152.035889,0.013038,0.001922,0.048824,280.553619,14.292083,0.488236,-152.035889,0.049014,0.000000
60.620003,63.058670,-152.080368,0.013090,0.001922,0.048824,280.498962,14.289299,0.488236,-152.080368,0.049014,0.000000
60.810001,63.037445,-151.991409,0.013073,0.001922,0.048824,280.404572,14.284489,0.488236,-151.991409,0.049014,0.000000
61.000004,63.028881,-152.080368,0.013068,0.001922,0.048824,280.366455,14.282549,0.488236,-152.080368,0.049014,0.000000
61.190002,63.013985,-151.991409,0.013098,0.001922,0.048824,280.300201,14.279173,0.488236,-151.991409,0.049014,0.000000
61.380001,62.990898,-151.991409,0.013047,0.001922,0.048824,280.197510,14.273942,0.488236,-151.991409,0.049014,0.000000
61.570004,62.968929,-152.035889,0.013068,0.001922,0.048824,280.099792,14.268963,0.488236,-152.035889,0.049014,0.000000
61.760002,62.955151,-151.946930,0.013051,0.001922,0.048824,280.038483,14.265841,0.488236,-151.946930,0.049014,0.000000
61.950005,62.932808,-151.946930,0.013060,0.001922,0.048824,279.939117,14.260777,0.488236,-151.946930,0.049014,0.000000
62.140003,62.919403,-151.946930,0.013073,0.001922,0.048824,279.879486,14.257740,0.488236,-151.946930,0.049014,0.000000
62.330002,62.922009,-151.991409,0.013051,0.001922,0.048824,279.891083,14.258331,0.488236,-151.991409,0.049014,0.000000
62.520004,62.888123,-151.902451,0.013047,0.001922,0.048824,279.740326,14.250652,0.488236,-151.902451,0.049014,0.000000
62.710003,62.878815,-151.946930,0.013081,0.001922,0.048824,279.698944,14.248543,0.488236,-151.946930,0.049014,0.000000
62.900002,62.863548,-151.946930,0.013068,0.001922,0.048824,279.631042,14.245084,0.488236,-151.946930,0.049014,0.000000
63.090004,62.853493,-151.902451,0.013085,0.001922,0.048824,279.586304,14.242805,0.488236,-151.902451,0.049014,0.000000
63.280003,62.831894,-151.902451,0.013055,0.001922,0.048824,279.490234,14.237910,0.488236,-151.902451,0.049014,0.000000
63.470001,62.810669,-151.857971,0.013077,0.001922,0.048824,279.395813,14.233101,0.488236,-151.857971,0.049014,0.000000
63.660004,62.804340,-151.902451,0.013103,0.001922,0.048824,279.367645,14.231668,0.488236,-151.902451,0.049014,0.000000
63.850002,62.789074,-151.902451,0.013029,0.001922,0.048824,279.299744,14.228208,0.488236,-151.902451,0.049014,0.000000
64.040001,62.778645,-151.769012,0.013085,0.001922,0.048824,279.253357,14.225844,0.488236,-151.769012,0.049014,0.000000
64.230003,62.749599,-151.902451,0.013051,0.001922,0.048824,279.124146,14.219262,0.488236,-151.902451,0.049014,0.000000
64.420006,62.754070,-151.946930,0.013060,0.001922,0.048824,279.144043,14.220276,0.488236,-151.946930,0.049014,0.000000
64.610001,62.736568,-151.813492,0.013073,0.001922,0.048824,279.066193,14.216311,0.488236,-151.813492,0.049014,0.000000
64.800003,62.721302,-151.857971,0.013073,0.001922,0.048824,278.998291,14.212851,0.488236,-151.857971,0.049014,0.000000
64.990005,62.700821,-151.724518,0.013077,0.001922,0.048824,278.907196,14.208209,0.488236,-151.724518,0.049014,0.000000
65.180000,62.690765,-151.857971,0.013038,0.001922,0.048824,278.862457,14.205931,0.488236,-151.857971,0.049014,0.000000
65.370003,62.674755,-151.769012,0.013085,0.001922,0.048824,278.791229,14.202303,0.488236,-151.769012,0.049014,0.000000
65.560005,62.671402,-151.769012,0.013060,0.001922,0.048824,278.776306,14.201543,0.488236,-151.769012,0.049014,0.000000
65.750000,62.650551,-151.813492,0.013090,0.001922,0.048824,278.683563,14.196817,0.488236,-151.813492,0.049014,0.000000
65.940002,62.640495,-151.769012,0.013038,0.001922,0.048824,278.638824,14.194539,0.488236,-151.769012,0.049014,0.000000
66.130005,62.625973,-151.813492,0.013077,0.001922,0.048824,278.574249,14.191248,0.488236,-151.813492,0.049014,0.000000
66.320000,62.619270,-151.680038,0.013034,0.001922,0.048824,278.544434,14.189730,0.488236,-151.680038,0.049014,0.000000
66.510002,62.604004,-151.724518,0.013051,0.001922,0.048824,278.476532,14.186271,0.488236,-151.724518,0.049014,0.000000
66.700005,62.594696,-151.680038,0.013051,0.001922,0.048824,278.435120,14.184160,0.488236,-151.680038,0.049014,0.000000
66.889999,62.590969,-151.635559,0.013098,0.001922,0.048824,278.418549,14.183316,0.488236,-151.635559,0.049014,0.000000
67.080002,62.585384,-151.769012,0.013034,0.001922,0.048824,278.393707,14.182051,0.488236,-151.769012,0.049014,0.000000
67.270004,62.574585,-151.546600,0.013073,0.001922,0.048824,278.345642,14.179604,0.488236,-151.546600,0.049014,0.000000
67.460007,62.557831,-151.680038,0.013073,0.001922,0.048824,278.271118,14.175807,0.488236,-151.680038,0.049014,0.000000
67.650002,62.541447,-151.680038,0.013077,0.001922,0.048824,278.198242,14.172094,0.488236,-151.680038,0.049014,0.000000
67.840004,62.527668,-151.680038,0.013055,0.001922,0.048824,278.136963,14.168972,0.488236,-151.680038,0.049014,0.000000
68.030006,62.515377,-151.680038,0.013064,0.001922,0.048824,278.082275,14.166187,0.488236,-151.680038,0.049014,0.000000
68.220001,62.516869,-151.635559,0.013081,0.001922,0.048824,278.088928,14.166525,0.488236,-151.635559,0.049014,0.000000
68.410004,62.495644,-151.591080,0.013064,0.001922,0.048824,277.994507,14.161716,0.488236,-151.591080,0.049014,0.000000
68.600006,62.485962,-151.591080,0.013051,0.001922,0.048824,277.951447,14.159521,0.488236,-151.591080,0.049014,0.000000
68.790001,62.485218,-151.591080,0.013047,0.001922,0.048824,277.948120,14.159353,0.488236,-151.591080,0.049014,0.000000
68.980003,62.468460,-151.591080,0.013090,0.001922,0.048824,277.873596,14.155556,0.488236,-151.591080,0.049014,0.000000
69.170006,62.444256,-151.591080,0.013068,0.001922,0.048824,277.765930,14.150070,0.488236,-151.591080,0.049014,0.000000
69.360001,62.437553,-151.546600,0.013060,0.001922,0.048824,277.736115,14.148552,0.488236,-151.546600,0.049014,0.000000
69.550003,62.436062,-151.546600,0.013055,0.001922,0.048824,277.729462,14.148213,0.488236,-151.546600,0.049014,0.000000
69.740005,62.429359,-151.502121,0.013068,0.001922,0.048824,277.699646,14.146695,0.488236,-151.502121,0.049014,0.000000
69.930000,62.420795,-151.502121,0.013081,0.001922,0.048824,277.661560,14.144754,0.488236,-151.502121,0.049014,0.000000
70.120003,62.412975,-151.546600,0.013073,0.001922,0.048824,277.626770,14.142982,0.488236,-151.546600,0.049014,0.000000
70.310005,62.412605,-151.546600,0.013055,0.001922,0.048824,277.625122,14.142899,0.488236,-151.546600,0.049014,0.000000
70.500000,62.388401,-151.546600,0.013025,0.001922,0.048824,277.517456,14.137414,0.488236,-151.546600,0.049014,0.000000
70.690002,62.388771,-151.457642,0.013055,0.001922,0.048816,277.519104,14.137498,0.488161,-151.457642,0.049014,0.000000
70.880005,62.377972,-151.546600,0.013055,0.001922,0.048816,277.471069,14.135050,0.488161,-151.546600,0.049014,0.000000
71.070000,62.356377,-151.502121,0.013085,0.001922,0.048816,277.375031,14.130157,0.488161,-151.502121,0.049014,0.000000
71.260002,62.344460,-151.457642,0.013090,0.001922,0.048816,277.322021,14.127456,0.488161,-151.457642,0.049014,0.000000
71.450005,62.347065,-151.502121,0.013060,0.001922,0.048816,277.333588,14.128047,0.488161,-151.502121,0.049014,0.000000
71.640007,62.336639,-151.413162,0.013068,0.001922,0.048816,277.287231,14.125685,0.488161,-151.413162,0.049014,0.000000
71.830002,62.329567,-151.502121,0.013073,0.001922,0.048816,277.255768,14.124082,0.488161,-151.502121,0.049014,0.000000
72.020004,62.332916,-151.413162,0.013038,0.001922,0.048816,277.270660,14.124841,0.488161,-151.413162,0.049014,0.000000
72.210007,62.315414,-151.457642,0.013055,0.001922,0.048816,277.192810,14.120875,0.488161,-151.457642,0.049014,0.000000
72.400002,62.308712,-151.413162,0.013077,0.001922,0.048816,277.162994,14.119356,0.488161,-151.413162,0.049014,0.000000
72.590004,62.299404,-151.368683,0.013034,0.001922,0.048816,277.121582,14.117247,0.488161,-151.368683,0.049014,0.000000
72.780006,62.285625,-151.413162,0.013064,0.001922,0.048816,277.060303,14.114124,0.488161,-151.413162,0.049014,0.000000
72.970001,62.293816,-151.368683,0.013060,0.001922,0.048816,277.096741,14.115980,0.488161,-151.368683,0.049014,0.000000
73.160004,62.272221,-151.368683,0.013038,0.001922,0.048816,277.000671,14.111087,0.488161,-151.368683,0.049014,0.000000
73.350006,62.263657,-151.368683,0.013047,0.001922,0.048816,276.962585,14.109147,0.488161,-151.368683,0.049014,0.000000
73.540001,62.259186,-151.279709,0.013047,0.001922,0.048816,276.942688,14.108133,0.488161,-151.279709,0.049014,0.000000
73.730003,62.259186,-151.324188,0.013055,0.001922,0.048816,276.942688,14.108133,0.488161,-151.324188,0.049014,0.000000
73.920006,62.233864,-151.324188,0.013051,0.001922,0.048816,276.830048,14.102395,0.488161,-151.324188,0.049014,0.000000
74.110001,62.229771,-151.279709,0.013034,0.001922,0.048816,276.811859,14.101467,0.488161,-151.279709,0.049014,0.000000
74.300003,62.224182,-151.324188,0.013064,0.001922,0.048816,276.786987,14.100201,0.488161,-151.324188,0.049014,0.000000
74.490005,62.212639,-151.279709,0.013081,0.001922,0.048816,276.735626,14.097586,0.488161,-151.279709,0.049014,0.000000
74.680000,62.204819,-151.279709,0.013085,0.001922,0.048816,276.700867,14.095813,0.488161,-151.279709,0.049014,0.000000
74.870003,62.189926,-151.279709,0.013098,0.001922,0.048816,276.634613,14.092439,0.488161,-151.279709,0.049014,0.000000
75.060005,62.196629,-151.235229,0.013081,0.001922,0.048816,276.664429,14.093958,0.488161,-151.235229,0.049014,0.000000
75.250000,62.192158,-151.235229,0.013051,0.001922,0.048816,276.644531,14.092944,0.488161,-151.235229,0.049014,0.000000
75.440002,62.188808,-151.235229,0.013068,0.001922,0.048816,276.629639,14.092185,0.488161,-151.235229,0.049014,0.000000
75.630005,62.173168,-151.235229,0.013073,0.001922,0.048816,276.560059,14.088641,0.488161,-151.235229,0.049014,0.000000
75.820007,62.181732,-151.235229,0.013042,0.001922,0.048816,276.598145,14.090582,0.488161,-151.235229,0.049014,0.000000
76.010002,62.161999,-151.190750,0.013090,0.001922,0.048816,276.510376,14.086110,0.488161,-151.190750,0.049014,0.000000
76.200005,62.175030,-151.146271,0.013107,0.001922,0.048816,276.568359,14.089064,0.488161,-151.146271,0.049014,0.000000
76.390007,62.151199,-151.235229,0.013051,0.001922,0.048816,276.462341,14.083664,0.488161,-151.235229,0.049014,0.000000
76.580002,62.141144,-151.190750,0.013051,0.001922,0.048816,276.417603,14.081385,0.488161,-151.190750,0.049014,0.000000
76.770004,62.138538,-151.146271,0.013042,0.001922,0.048816,276.406036,14.080793,0.488161,-151.146271,0.049014,0.000000
76.960007,62.130718,-151.190750,0.013042,0.001922,0.048816,276.371246,14.079021,0.488161,-151.190750,0.049014,0.000000
77.150002,62.122154,-151.146271,0.013047,0.001922,0.048816,276.333130,14.077082,0.488161,-151.146271,0.049014,0.000000
77.340004,62.108376,-151.146271,0.013090,0.001922,0.048816,276.271851,14.073958,0.488161,-151.146271,0.049014,0.000000
77.530006,62.105770,-151.146271,0.013047,0.001922,0.048816,276.260254,14.073369,0.488161,-151.146271,0.049014,0.000000
77.720001,62.094227,-151.101791,0.013081,0.001922,0.048816,276.208923,14.070753,0.488161,-151.101791,0.049014,0.000000
77.910004,62.087151,-151.057312,0.013047,0.001922,0.048816,276.177429,14.069149,0.488161,-151.057312,0.049014,0.000000
78.100006,62.084171,-151.057312,0.013064,0.001922,0.048816,276.164185,14.068475,0.488161,-151.057312,0.049014,0.000000
78.290001,62.074490,-151.057312,0.013047,0.001922,0.048816,276.121124,14.066280,0.488161,-151.057312,0.049014,0.000000
78.480003,62.065552,-151.057312,0.013077,0.001922,0.048816,276.081360,14.064255,0.488161,-151.057312,0.049014,0.000000
78.670006,62.069275,-151.057312,0.013047,0.001922,0.048816,276.097931,14.065099,0.488161,-151.057312,0.049014,0.000000
78.700005,62.066299,-151.146271,0.013073,0.001922,0.048816,276.084686,14.064425,0.488161,-151.146271,0.049014,0.000000