File: Data/New pin align test AD 3_08172023_164742.csv
Time (sec),S:Load (lbs),S:HL1 (DIM),S:LVDT (in),S:Position (in),Ch:Position (mm),Ch:Load (N),Ch:Stress (MPa),Ch:Strain (mm/mm),Ch:HL1 (DIM),Set Point (),Cycles ()
0.010000,0.011171,-161.021042,-0.000034,-0.000000,-0.000000,0.049692,0.002531,-0.000000,-161.021042,0.000062,0.000000
0.230000,-0.001117,-160.932083,-0.000009,-0.000000,-0.000000,-0.004969,-0.000253,-0.000000,-160.932083,0.000062,0.000000
0.450000,-0.059580,-160.932083,-0.000026,0.000055,0.001405,-0.265023,-0.013501,0.014050,-160.932083,0.001970,0.000000
0.670000,-0.047291,-160.976562,0.000030,0.000186,0.004727,-0.210363,-0.010716,0.047266,-160.976562,0.005629,0.000000
0.890000,-0.050270,-160.976562,0.000004,0.000320,0.008136,-0.223614,-0.011391,0.081360,-160.976562,0.009306,0.000000
1.110000,-0.003351,-161.021042,-0.000013,0.000465,0.011804,-0.014907,-0.000759,0.118043,-161.021042,0.012966,0.000000
1.330000,0.006330,-160.932083,-0.000013,0.000607,0.015420,0.028158,0.001434,0.154197,-160.932083,0.016625,0.000000
1.550000,0.005213,-160.932083,-0.000004,0.000748,0.018993,0.023189,0.001181,0.189926,-160.932083,0.020286,0.000000
1.770000,0.002979,-161.021042,-0.000017,0.000895,0.022721,0.013251,0.000675,0.227215,-161.021042,0.023961,0.000000
1.990000,0.001862,-160.976562,0.000004,0.001046,0.026581,0.008282,0.000422,0.265806,-160.976562,0.027622,0.000000
2.210000,-0.024577,-160.976562,0.000017,0.001189,0.030206,-0.109322,-0.005569,0.302065,-160.976562,0.031281,0.000000
2.430000,-0.038727,-160.932083,0.000017,0.001332,0.033831,-0.172265,-0.008776,0.338309,-160.932083,0.034959,0.000000
2.650000,-0.022715,-160.976562,0.000022,0.001472,0.037378,-0.101040,-0.005147,0.373781,-160.976562,0.038618,0.000000
2.870000,-0.012661,-161.021042,-0.000047,0.001621,0.041177,-0.056318,-0.002869,0.411766,-161.021042,0.042277,0.000000
3.090000,0.030535,-160.976562,0.000017,0.001760,0.044715,0.135824,0.006919,0.447147,-160.976562,0.045955,0.000000
3.310000,0.042078,-160.976562,0.000030,0.001910,0.048513,0.187172,0.009535,0.485133,-160.976562,0.049614,0.000000
3.530000,0.076336,-160.932083,0.000000,0.002056,0.052216,0.339561,0.017298,0.522164,-160.932083,0.053275,0.000000
3.750000,0.082667,-160.932083,0.000017,0.002204,0.055989,0.367720,0.018733,0.559892,-160.932083,0.056952,0.000000
3.970000,0.123628,-161.021042,0.000004,0.002343,0.059509,0.549923,0.028014,0.595091,-161.021042,0.060611,0.000000
4.190000,0.142991,-160.932083,0.000000,0.002490,0.063256,0.636055,0.032402,0.632562,-160.932083,0.064271,0.000000
4.410000,0.179484,-160.976562,0.000004,0.002629,0.066769,0.798383,0.040672,0.667686,-160.976562,0.067948,0.000000
4.630000,0.217465,-160.932083,-0.000004,0.002776,0.070514,0.967335,0.049278,0.705141,-160.932083,0.071607,0.000000
4.850000,0.252096,-160.887604,0.000013,0.002919,0.074140,1.121379,0.057126,0.741400,-160.887604,0.075268,0.000000
5.070000,0.266619,-160.976562,-0.000013,0.003065,0.077852,1.185979,0.060417,0.778523,-160.976562,0.078944,0.000000
5.290000,0.321357,-160.932083,0.000091,0.003206,0.081425,1.429469,0.072821,0.814252,-160.932083,0.082605,0.000000
5.510000,0.300132,-160.843124,0.000323,0.003351,0.085110,1.335055,0.068011,0.851102,-160.843124,0.086264,0.000000
5.730000,0.278535,-160.887604,0.000457,0.003497,0.088830,1.238984,0.063117,0.888300,-160.887604,0.089923,0.000000
5.950000,0.302366,-160.932083,0.000595,0.003643,0.092526,1.344993,0.068517,0.925255,-160.932083,0.093600,0.000000
6.170000,0.300877,-161.021042,0.000694,0.003788,0.096211,1.338367,0.068180,0.962105,-161.021042,0.097260,0.000000
6.390000,0.320985,-161.021042,0.000901,0.003926,0.099732,1.427813,0.072736,0.997320,-161.021042,0.100920,0.000000
6.610000,0.297526,-160.887604,0.001013,0.004072,0.103417,1.323460,0.067420,1.034170,-160.887604,0.104596,0.000000
6.830000,0.303484,-160.932083,0.001181,0.004221,0.107225,1.349962,0.068770,1.072246,-160.932083,0.108257,0.000000
7.050000,0.272577,-160.932083,0.001298,0.004362,0.110798,1.212481,0.061767,1.107975,-160.932083,0.111916,0.000000
7.270000,0.262523,-160.932083,0.001462,0.004506,0.114457,1.167759,0.059488,1.144567,-160.932083,0.115594,0.000000
7.490000,0.314655,-160.932083,0.001604,0.004651,0.118125,1.399654,0.071302,1.181251,-160.932083,0.119253,0.000000
7.710001,0.319868,-160.887604,0.001712,0.004795,0.121786,1.422844,0.072483,1.217858,-160.887604,0.122912,0.000000
7.930000,0.321730,-160.887604,0.001863,0.004934,0.125315,1.431126,0.072905,1.253148,-160.887604,0.126590,0.000000
8.150001,0.317261,-160.932083,0.002031,0.005076,0.128932,1.411249,0.071892,1.289317,-160.932083,0.130249,0.000000
8.370001,0.332901,-160.976562,0.002164,0.005230,0.132851,1.480817,0.075436,1.328513,-160.976562,0.133910,0.000000
8.590000,0.308324,-160.932083,0.002298,0.005374,0.136501,1.371495,0.069867,1.365015,-160.932083,0.137585,0.000000
8.810000,0.283748,-160.932083,0.002436,0.005516,0.140102,1.262173,0.064298,1.401017,-160.932083,0.141246,0.000000
9.030001,0.274811,-160.887604,0.002634,0.005657,0.143682,1.222420,0.062273,1.436822,-160.887604,0.144905,0.000000
9.250000,0.315027,-160.843124,0.002790,0.005806,0.147473,1.401310,0.071386,1.474731,-160.843124,0.148583,0.000000
9.470000,0.329177,-160.887604,0.002889,0.005948,0.151072,1.464253,0.074593,1.510718,-160.887604,0.152242,0.000000
9.690001,0.353381,-160.932083,0.003078,0.006087,0.154601,1.571919,0.080077,1.546008,-160.932083,0.155901,0.000000
9.910001,0.350775,-160.887604,0.003212,0.006236,0.158399,1.560324,0.079487,1.583994,-160.887604,0.159562,0.000000
10.130000,0.348913,-160.843124,0.003354,0.006386,0.162215,1.552042,0.079065,1.622145,-160.843124,0.163238,0.000000
10.350000,0.323592,-160.887604,0.003488,0.006529,0.165840,1.439408,0.073327,1.658405,-160.887604,0.166899,0.000000
10.570001,0.318006,-160.932083,0.003665,0.006671,0.169439,1.414562,0.072061,1.694391,-160.932083,0.170558,0.000000
10.790001,0.320240,-160.887604,0.003768,0.006813,0.173038,1.424500,0.072567,1.730378,-160.887604,0.174235,0.000000
11.010000,0.320985,-160.887604,0.003898,0.006962,0.176827,1.427813,0.072736,1.768273,-160.887604,0.177895,0.000000
11.230000,0.338114,-160.843124,0.004061,0.007104,0.180453,1.504007,0.076618,1.804532,-160.843124,0.181554,0.000000
11.450001,0.311676,-160.887604,0.004238,0.007251,0.184165,1.386403,0.070627,1.841654,-160.887604,0.185231,0.000000
11.670001,0.353754,-160.887604,0.004368,0.007393,0.187772,1.573575,0.080162,1.877717,-160.887604,0.188890,0.000000
11.890000,0.342955,-160.887604,0.004549,0.007534,0.191363,1.525540,0.077715,1.913628,-160.887604,0.192551,0.000000
12.110001,0.316517,-160.843124,0.004756,0.007682,0.195126,1.407936,0.071724,1.951265,-160.843124,0.196227,0.000000
12.330001,0.331784,-160.932083,0.004876,0.007826,0.198778,1.475848,0.075183,1.987781,-160.932083,0.199888,0.000000
12.550000,0.344445,-160.887604,0.005001,0.007974,0.202542,1.532166,0.078052,2.025419,-160.887604,0.203547,0.000000
12.770000,0.331411,-160.887604,0.005148,0.008114,0.206088,1.474192,0.075099,2.060875,-160.887604,0.207225,0.000000
12.990001,0.346306,-160.843124,0.005312,0.008253,0.209627,1.540447,0.078474,2.096272,-160.843124,0.210884,0.000000
13.210001,0.326198,-160.843124,0.005433,0.008405,0.213494,1.451002,0.073918,2.134938,-160.843124,0.214543,0.000000
13.430000,0.313538,-160.798645,0.005562,0.008549,0.217136,1.394685,0.071049,2.171364,-160.798645,0.218204,0.000000
13.650001,0.287844,-160.798645,0.005764,0.008690,0.220735,1.280393,0.065226,2.207351,-160.798645,0.221880,0.000000
13.870001,0.327315,-160.843124,0.005911,0.008835,0.224412,1.455971,0.074171,2.244125,-160.843124,0.225540,0.000000
14.090001,0.322847,-160.843124,0.006053,0.008983,0.228167,1.436095,0.073158,2.281671,-160.843124,0.229200,0.000000
14.310000,0.336252,-160.798645,0.006183,0.009124,0.231758,1.495725,0.076196,2.317582,-160.798645,0.232877,0.000000
14.530001,0.349285,-160.798645,0.006342,0.009263,0.235280,1.553699,0.079149,2.352797,-160.798645,0.236536,0.000000
14.750001,0.356360,-160.754150,0.006536,0.009415,0.239146,1.585170,0.080752,2.391463,-160.754150,0.240195,0.000000
14.970000,0.329922,-160.754150,0.006691,0.009561,0.242859,1.467566,0.074761,2.428586,-160.754150,0.243873,0.000000
15.190001,0.313165,-160.843124,0.006786,0.009704,0.246475,1.393028,0.070964,2.464754,-160.843124,0.247534,0.000000
15.410001,0.302739,-160.709671,0.006933,0.009843,0.250023,1.346649,0.068602,2.500226,-160.709671,0.251193,0.000000
15.630001,0.284493,-160.709671,0.007071,0.009987,0.253682,1.265486,0.064467,2.536818,-160.709671,0.254870,0.000000
15.850000,0.356733,-160.754150,0.007222,0.010135,0.257420,1.586827,0.080837,2.574198,-160.754150,0.258530,0.000000
16.070002,0.357105,-160.754150,0.007420,0.010272,0.260897,1.588483,0.080921,2.608974,-160.754150,0.262189,0.000000
16.290001,0.364180,-160.798645,0.007541,0.010419,0.264643,1.619954,0.082524,2.646429,-160.798645,0.265866,0.000000
16.510000,0.361946,-160.709671,0.007670,0.010565,0.268355,1.610016,0.082018,2.683551,-160.709671,0.269525,0.000000
16.730001,0.368276,-160.754150,0.007834,0.010717,0.272214,1.638175,0.083453,2.722142,-160.754150,0.273186,0.000000
16.950001,0.345934,-160.754150,0.008032,0.010855,0.275708,1.538791,0.078390,2.757084,-160.754150,0.276862,0.000000
17.170000,0.332156,-160.754150,0.008132,0.010998,0.279343,1.477504,0.075268,2.793434,-160.754150,0.280523,0.000000
17.390001,0.338487,-160.709671,0.008338,0.011142,0.283012,1.505663,0.076702,2.830117,-160.709671,0.284182,0.000000
17.610001,0.348168,-160.665192,0.008438,0.011290,0.286757,1.548729,0.078896,2.867573,-160.665192,0.287841,0.000000
17.830000,0.353381,-160.665192,0.008571,0.011432,0.290365,1.571919,0.080077,2.903650,-160.665192,0.291519,0.000000
18.050001,0.368649,-160.665192,0.008757,0.011575,0.294008,1.639831,0.083537,2.940076,-160.665192,0.295178,0.000000
18.270000,0.341093,-160.620712,0.008864,0.011723,0.297762,1.517258,0.077293,2.977622,-160.620712,0.298839,0.000000
18.490002,0.322847,-160.665192,0.009007,0.011867,0.301431,1.436095,0.073158,3.014306,-160.665192,0.302515,0.000000
18.710001,0.338487,-160.620712,0.009227,0.012010,0.305056,1.505663,0.076702,3.050565,-160.620712,0.306175,0.000000
18.930000,0.373117,-160.620712,0.009365,0.012158,0.308802,1.659708,0.084550,3.088020,-160.620712,0.309835,0.000000
19.150002,0.345562,-160.665192,0.009481,0.012299,0.312393,1.537135,0.078305,3.123931,-160.665192,0.313512,0.000000
19.370001,0.367159,-160.620712,0.009636,0.012437,0.315896,1.633206,0.083199,3.158964,-160.620712,0.317171,0.000000
19.590000,0.340721,-160.576233,0.009757,0.012586,0.319695,1.515602,0.077208,3.196949,-160.576233,0.320830,0.000000
19.810001,0.342955,-160.576233,0.009895,0.012736,0.323484,1.525540,0.077715,3.234844,-160.576233,0.324508,0.000000
20.030001,0.342210,-160.531754,0.010076,0.012877,0.327075,1.522227,0.077546,3.270755,-160.531754,0.328167,0.000000
20.250002,0.358595,-160.576233,0.010214,0.013019,0.330674,1.595109,0.081259,3.306742,-160.576233,0.331828,0.000000
20.470001,0.349658,-160.576233,0.010378,0.013164,0.334368,1.555355,0.079234,3.343682,-160.576233,0.335504,0.000000
20.690001,0.358595,-160.576233,0.010494,0.013312,0.338115,1.595109,0.081259,3.381153,-160.576233,0.339164,0.000000
20.910002,0.354871,-160.531754,0.010667,0.013450,0.341635,1.578545,0.080415,3.416352,-160.531754,0.342824,0.000000
21.130001,0.379075,-160.576233,0.010779,0.013597,0.345357,1.686210,0.085900,3.453565,-160.576233,0.346501,0.000000
21.350000,0.352264,-160.620712,0.010994,0.013744,0.349085,1.566950,0.079824,3.490854,-160.620712,0.350160,0.000000
21.570002,0.359712,-160.531754,0.011098,0.013889,0.352770,1.600078,0.081512,3.527704,-160.531754,0.353820,0.000000
21.790001,0.326943,-160.487274,0.011227,0.014029,0.356327,1.454315,0.074086,3.563267,-160.487274,0.357480,0.000000
22.010000,0.305718,-160.531754,0.011357,0.014171,0.359951,1.359901,0.069277,3.599511,-160.531754,0.361156,0.000000
22.230001,0.374607,-160.487274,0.011581,0.014319,0.363698,1.666334,0.084887,3.636981,-160.487274,0.364817,0.000000
22.450001,0.375724,-160.576233,0.011714,0.014460,0.367288,1.671303,0.085140,3.672877,-160.576233,0.368476,0.000000
22.670002,0.399183,-160.398315,0.011831,0.014603,0.370905,1.775656,0.090456,3.709046,-160.398315,0.372154,0.000000
22.890001,0.385405,-160.442795,0.011977,0.014745,0.374521,1.714369,0.087334,3.745214,-160.442795,0.375813,0.000000
23.110001,0.374979,-160.487274,0.012141,0.014900,0.378467,1.667990,0.084971,3.784668,-160.487274,0.379472,0.000000
23.330002,0.361946,-160.442795,0.012322,0.015041,0.382049,1.610016,0.082018,3.820488,-160.442795,0.383149,0.000000
23.550001,0.349285,-160.487274,0.012473,0.015184,0.385664,1.553699,0.079149,3.856642,-160.487274,0.386809,0.000000
23.770000,0.353754,-160.442795,0.012542,0.015326,0.389290,1.573575,0.080162,3.892901,-160.442795,0.390469,0.000000
23.990002,0.374234,-160.487274,0.012766,0.015472,0.392984,1.664677,0.084803,3.929841,-160.487274,0.394145,0.000000
24.210001,0.366414,-160.353836,0.012947,0.015615,0.396627,1.629893,0.083031,3.966267,-160.353836,0.397806,0.000000
24.430000,0.410354,-160.442795,0.013021,0.015759,0.400286,1.825348,0.092988,4.002860,-160.442795,0.401465,0.000000
24.650002,0.389502,-160.442795,0.013198,0.015909,0.404101,1.732589,0.088262,4.041011,-160.442795,0.405143,0.000000
24.870001,0.390619,-160.353836,0.013366,0.016054,0.407771,1.737559,0.088515,4.077710,-160.353836,0.408802,0.000000
25.090002,0.380565,-160.353836,0.013508,0.016199,0.411465,1.692836,0.086237,4.114650,-160.353836,0.412461,0.000000
25.310001,0.395460,-160.353836,0.013616,0.016339,0.415003,1.759092,0.089612,4.150032,-160.353836,0.416122,0.000000
25.530001,0.381309,-160.353836,0.013780,0.016488,0.418793,1.696149,0.086406,4.187926,-160.353836,0.419799,0.000000
25.750002,0.393598,-160.398315,0.013982,0.016625,0.422279,1.750810,0.089191,4.222792,-160.398315,0.423459,0.000000
25.970001,0.388012,-160.309341,0.014090,0.016771,0.425982,1.725964,0.087925,4.259824,-160.309341,0.427118,0.000000
26.190001,0.377586,-160.220383,0.014297,0.016917,0.429702,1.679585,0.085562,4.297021,-160.220383,0.430795,0.000000
26.410002,0.364180,-160.353836,0.014409,0.017063,0.433389,1.619954,0.082524,4.333887,-160.353836,0.434454,0.000000
26.630001,0.383544,-160.220383,0.014577,0.017204,0.436978,1.706087,0.086912,4.369782,-160.220383,0.438114,0.000000
26.850000,0.373862,-160.309341,0.014737,0.017349,0.440672,1.663021,0.084718,4.406723,-160.309341,0.441791,0.000000
27.070002,0.372372,-160.220383,0.014866,0.017493,0.444333,1.656395,0.084381,4.443330,-160.220383,0.445452,0.000000
27.290001,0.374234,-160.220383,0.015052,0.017639,0.448036,1.664677,0.084803,4.480362,-160.220383,0.449111,0.000000
27.510002,0.403652,-160.220383,0.015220,0.017781,0.451642,1.795532,0.091469,4.516424,-160.220383,0.452789,0.000000
27.730001,0.383916,-160.264862,0.015302,0.017925,0.455294,1.707744,0.086997,4.552941,-160.264862,0.456448,0.000000
27.950001,0.380937,-160.220383,0.015491,0.018072,0.459041,1.694492,0.086322,4.590412,-160.220383,0.460107,0.000000
28.170002,0.357478,-160.175903,0.015621,0.018216,0.462691,1.590140,0.081006,4.626913,-160.175903,0.463784,0.000000
28.390001,0.331039,-160.175903,0.015810,0.018356,0.466248,1.472535,0.075015,4.662476,-160.175903,0.467444,0.000000
28.610001,0.340721,-160.175903,0.015983,0.018502,0.469951,1.515602,0.077208,4.699507,-160.175903,0.471104,0.000000
28.830002,0.401417,-160.264862,0.016121,0.018646,0.473619,1.785594,0.090962,4.736190,-160.264862,0.474780,0.000000
29.050001,0.439027,-160.175903,0.016237,0.018788,0.477227,1.952890,0.099485,4.772268,-160.175903,0.478441,0.000000
29.270000,0.578294,-160.131424,0.016384,0.018926,0.480721,2.572382,0.131043,4.807210,-160.131424,0.482100,0.000000
29.490002,0.666547,-160.086945,0.016483,-0.000000,-0.000009,2.964947,0.151042,-0.000091,-160.086945,0.000182,0.000000
29.710001,0.671015,-160.086945,0.016474,-0.000000,-0.000009,2.984824,0.152054,-0.000091,-160.086945,0.000182,0.000000
29.930002,0.689634,-160.175903,0.016457,-0.000001,-0.000018,3.067644,0.156273,-0.000182,-160.175903,0.000259,0.000000
30.150002,0.684421,-160.131424,0.016500,-0.000000,-0.000009,3.044455,0.155092,-0.000091,-160.131424,0.000624,0.000000
30.370001,0.686282,-160.131424,0.016522,-0.000000,-0.000009,3.052737,0.155514,-0.000091,-160.131424,0.000989,0.000000
30.590002,0.708252,-160.042465,0.016453,0.000021,0.000545,3.150464,0.160492,0.005450,-160.042465,0.001361,0.000000
30.810001,0.768577,-160.042465,0.016474,0.000031,0.000780,3.418800,0.174162,0.007797,-160.042465,0.001726,0.000000
31.030001,0.825550,-160.131424,0.016509,0.000048,0.001222,3.672229,0.187072,0.012218,-160.131424,0.002089,0.000000
31.250002,0.909334,-160.042465,0.016526,0.000063,0.001596,4.044918,0.206058,0.015957,-160.042465,0.002454,0.000000
31.470001,0.954391,-159.997986,0.016535,0.000073,0.001864,4.245341,0.216268,0.018637,-159.997986,0.002827,0.000000
31.690002,0.979340,-159.997986,0.016517,0.000078,0.001977,4.356320,0.221922,0.019772,-159.997986,0.003191,0.000000
31.910002,1.073922,-160.042465,0.016548,0.000092,0.002331,4.777044,0.243354,0.023315,-160.042465,0.003555,0.000000
32.130001,1.245958,-159.953506,0.016578,0.000124,0.003157,5.542299,0.282338,0.031566,-159.953506,0.003927,0.000000
32.350002,1.320060,-159.997986,0.016556,0.000134,0.003408,5.871922,0.299130,0.034079,-159.997986,0.004292,0.000000
32.570000,1.428048,-159.997986,0.016556,0.000146,0.003720,6.352276,0.323600,0.037198,-159.997986,0.004657,0.000000
32.790001,1.512577,-159.953506,0.016625,0.000160,0.004057,6.728278,0.342755,0.040574,-159.953506,0.005020,0.000000
33.010002,1.666739,-159.864532,0.016595,0.000178,0.004518,7.414026,0.377688,0.045177,-159.864532,0.005394,0.000000
33.230003,1.780313,-159.909012,0.016630,0.000191,0.004848,7.919227,0.403425,0.048477,-159.909012,0.005758,0.000000
33.450001,1.831328,-159.953506,0.016681,0.000203,0.005150,8.146152,0.414985,0.051505,-159.953506,0.006122,0.000000
33.670002,1.956817,-159.864532,0.016634,0.000218,0.005532,8.704358,0.443421,0.055320,-159.864532,0.006495,0.000000
33.890003,2.023472,-159.864532,0.016694,0.000235,0.005957,9.000853,0.458525,0.059574,-159.864532,0.006860,0.000000
34.110001,2.109862,-159.909012,0.016677,0.000252,0.006400,9.385137,0.478102,0.063995,-159.909012,0.007223,0.000000
34.330002,2.161250,-159.864532,0.016707,0.000263,0.006669,9.613719,0.489746,0.066690,-159.864532,0.007588,0.000000
34.550003,2.233118,-159.864532,0.016707,0.000277,0.007023,9.933403,0.506032,0.070233,-159.864532,0.007960,0.000000
34.770000,2.378343,-159.864532,0.016737,0.000294,0.007474,10.579397,0.538940,0.074744,-159.864532,0.008325,0.000000
34.990002,2.440157,-159.775574,0.016767,0.000305,0.007753,10.854359,0.552947,0.077530,-159.775574,0.008689,0.000000
35.210003,2.532133,-159.820053,0.016767,0.000318,0.008065,11.263489,0.573789,0.080649,-159.820053,0.009063,0.000000
35.430000,2.666559,-159.820053,0.016772,0.000331,0.008412,11.861448,0.604251,0.084116,-159.820053,0.009426,0.000000
35.650002,2.792793,-159.820053,0.016776,0.000348,0.008828,12.422965,0.632856,0.088279,-159.820053,0.009791,0.000000
35.870003,2.977118,-159.731094,0.016824,0.000365,0.009261,13.242881,0.674625,0.092609,-159.731094,0.010154,0.000000
36.090000,3.129791,-159.775574,0.016867,0.000379,0.009626,13.922004,0.709221,0.096257,-159.775574,0.010528,0.000000
36.310001,3.259748,-159.775574,0.016815,0.000392,0.009956,14.500085,0.738670,0.099558,-159.775574,0.010891,0.000000
36.530003,3.361779,-159.775574,0.016867,0.000403,0.010233,14.953938,0.761790,0.102328,-159.775574,0.011256,0.000000
36.750000,3.524878,-159.775574,0.016862,0.000415,0.010545,15.679439,0.798749,0.105447,-159.775574,0.011620,0.000000
36.970001,3.731172,-159.686615,0.016867,0.000431,0.010952,16.597082,0.845496,0.109520,-159.686615,0.011994,0.000000
37.190002,3.865226,-159.642136,0.016867,0.000442,0.011221,17.193386,0.875873,0.112215,-159.642136,0.012357,0.000000
37.410004,4.117322,-159.731094,0.016927,0.000457,0.011620,18.314764,0.932999,0.116196,-159.731094,0.012722,0.000000
37.630001,4.329202,-159.731094,0.016905,0.000470,0.011950,19.257254,0.981011,0.119497,-159.731094,0.013094,0.000000
37.850002,4.694499,-159.731094,0.016918,0.000494,0.012557,20.882177,1.063789,0.125568,-159.731094,0.013459,0.000000
38.070004,4.898560,-159.642136,0.016944,0.000508,0.012894,21.789881,1.110029,0.128944,-159.642136,0.013822,0.000000
38.290001,5.032241,-159.597656,0.016987,0.000518,0.013155,22.384527,1.140322,0.131548,-159.597656,0.014187,0.000000
38.510002,5.276890,-159.642136,0.016992,0.000532,0.013511,23.472780,1.195760,0.135106,-159.642136,0.014560,0.000000
38.730003,5.537179,-159.642136,0.016953,0.000546,0.013875,24.630600,1.254743,0.138754,-159.642136,0.014925,0.000000
38.950001,5.819065,-159.553177,0.017026,0.000563,0.014292,25.884493,1.318619,0.142918,-159.553177,0.015288,0.000000
39.170002,6.206704,-159.553177,0.017074,0.000579,0.014699,27.608799,1.406459,0.146990,-159.553177,0.015662,0.000000
39.390003,6.332194,-159.553177,0.017082,0.000589,0.014967,28.167006,1.434896,0.149670,-159.553177,0.016025,0.000000
39.610001,6.693768,-159.642136,0.017074,0.000606,0.015401,29.775366,1.516829,0.154015,-159.642136,0.016390,0.000000
39.830002,7.136891,-159.642136,0.017056,0.000624,0.015853,31.746477,1.617243,0.158527,-159.642136,0.016753,0.000000
40.050003,7.397924,-159.553177,0.017104,0.000637,0.016190,32.907608,1.676394,0.161903,-159.553177,0.017127,0.000000
40.270000,7.638476,-159.508698,0.017099,0.000650,0.016511,33.977638,1.730904,0.165112,-159.508698,0.017491,0.000000
40.490002,7.941215,-159.553177,0.017130,0.000663,0.016850,35.324287,1.799505,0.168504,-159.553177,0.017856,0.000000
40.710003,8.220494,-159.508698,0.017125,0.000675,0.017144,36.566586,1.862791,0.171441,-159.508698,0.018228,0.000000
40.930000,8.717984,-159.508698,0.017177,0.000692,0.017579,38.779530,1.975523,0.175786,-159.508698,0.018593,0.000000
41.150002,9.084771,-159.508698,0.017168,0.000706,0.017925,40.411079,2.058639,0.179253,-159.508698,0.018956,0.000000
41.370003,9.470549,-159.464203,0.017125,0.000721,0.018316,42.127106,2.146057,0.183159,-159.464203,0.019321,0.000000
41.590000,9.789672,-159.419724,0.017186,0.000734,0.018653,43.546635,2.218371,0.186535,-159.419724,0.019694,0.000000
41.810001,10.312483,-159.508698,0.017212,0.000751,0.019079,45.872215,2.336842,0.190789,-159.508698,0.020058,0.000000
42.030003,10.707198,-159.464203,0.017233,0.000766,0.019460,47.627995,2.426286,0.194604,-159.464203,0.020423,0.000000
42.250004,10.917961,-159.419724,0.017216,0.000776,0.019721,48.565517,2.474045,0.197208,-159.419724,0.020796,0.000000
42.470001,11.373000,-159.375244,0.017259,0.000790,0.020075,50.589630,2.577159,0.200751,-159.375244,0.021159,0.000000
42.690002,11.753192,-159.330765,0.017220,0.000806,0.020466,52.280807,2.663311,0.204657,-159.330765,0.021524,0.000000
42.910004,12.436868,-159.419724,0.017233,0.000825,0.020943,55.321949,2.818234,0.209426,-159.419724,0.021889,0.000000
43.130001,12.570550,-159.419724,0.017289,0.000833,0.021168,55.916599,2.848527,0.211682,-159.419724,0.022261,0.000000
43.350002,13.230021,-159.330765,0.017302,0.000852,0.021628,58.850075,2.997966,0.216284,-159.330765,0.022625,0.000000
43.570004,13.787835,-159.375244,0.017276,0.000868,0.022036,61.331352,3.124368,0.220357,-159.375244,0.022989,0.000000
43.790001,14.190742,-159.330765,0.017345,0.000880,0.022357,63.123577,3.215668,0.223566,-159.330765,0.023362,0.000000
44.010002,14.691956,-159.330765,0.017328,0.000895,0.022738,65.353081,3.329245,0.227381,-159.330765,0.023727,0.000000
44.230003,15.047199,-159.330765,0.017375,0.000908,0.023059,66.933289,3.409744,0.230591,-159.330765,0.024092,0.000000
44.450001,15.673530,-159.286285,0.017393,0.000924,0.023475,69.719345,3.551673,0.234754,-159.286285,0.024455,0.000000
44.670002,16.081276,-159.241806,0.017375,0.000937,0.023787,71.533089,3.644069,0.237873,-159.241806,0.024827,0.000000
44.890003,16.753036,-159.286285,0.017388,0.000953,0.024195,74.521225,3.796292,0.241946,-159.286285,0.025192,0.000000
45.110001,17.070297,-159.241806,0.017375,0.000964,0.024481,75.932472,3.868185,0.244807,-159.241806,0.025557,0.000000
45.330002,17.644495,-159.286285,0.017397,0.000977,0.024827,78.486633,3.998300,0.248274,-159.286285,0.025930,0.000000
45.550003,18.139006,-159.241806,0.017419,0.000992,0.025209,80.686325,4.110357,0.252089,-159.241806,0.026294,0.000000
45.770000,18.856195,-159.241806,0.017423,0.001010,0.025643,83.876549,4.272875,0.256434,-159.241806,0.026658,0.000000
45.990002,19.291872,-159.241806,0.017444,0.001023,0.025973,85.814529,4.371601,0.259735,-159.241806,0.027023,0.000000
46.210003,19.713024,-159.241806,0.017444,0.001037,0.026328,87.687912,4.467035,0.263277,-159.241806,0.027395,0.000000
46.430000,20.409361,-159.241806,0.017436,0.001052,0.026727,90.785370,4.624827,0.267274,-159.241806,0.027760,0.000000
46.650002,21.146286,-159.152847,0.017522,0.001069,0.027153,94.063377,4.791817,0.271528,-159.152847,0.028123,0.000000
46.870003,21.541000,-159.108368,0.017483,0.001080,0.027439,95.819153,4.881260,0.274390,-159.108368,0.028496,0.000000
47.090004,21.913002,-159.152847,0.017513,0.001089,0.027665,97.473900,4.965557,0.276646,-159.152847,0.028861,0.000000
47.310001,22.870743,-159.197327,0.017557,0.001113,0.028263,101.734146,5.182584,0.282626,-159.197327,0.029225,0.000000
47.530003,23.576017,-159.108368,0.017513,0.001128,0.028661,104.871361,5.342402,0.286607,-159.108368,0.029589,0.000000
47.750004,23.875404,-159.108368,0.017544,0.001138,0.028912,106.203102,5.410244,0.289121,-159.108368,0.029963,0.000000
47.970001,24.392630,-159.108368,0.017565,0.001150,0.029198,108.503838,5.527449,0.291982,-159.108368,0.030326,0.000000
48.190002,25.181686,-159.063889,0.017587,0.001166,0.029624,112.013733,5.706252,0.296236,-159.063889,0.030691,0.000000
48.410004,25.666515,-159.063889,0.017569,0.001181,0.029988,114.170364,5.816115,0.299885,-159.063889,0.031063,0.000000
48.630001,26.633940,-159.108368,0.017613,0.001200,0.030474,118.473679,6.035337,0.304745,-159.108368,0.031428,0.000000
48.850002,26.777304,-159.063889,0.017621,0.001208,0.030682,119.111397,6.067824,0.306819,-159.063889,0.031792,0.000000
49.070004,27.329905,-159.019394,0.017647,0.001220,0.030994,121.569489,6.193045,0.309937,-159.019394,0.032156,0.000000
49.290001,28.016932,-159.063889,0.017656,0.001235,0.031368,124.625534,6.348727,0.313677,-159.063889,0.032529,0.000000
49.510002,29.184690,-158.974915,0.017634,0.001257,0.031940,129.819992,6.613345,0.319400,-158.974915,0.032894,0.000000
49.730003,29.787561,-159.019394,0.017677,0.001273,0.032329,132.501694,6.749958,0.323291,-159.019394,0.033257,0.000000
49.950001,30.233292,-158.885956,0.017694,0.001284,0.032615,134.484390,6.850962,0.326152,-158.885956,0.033622,0.000000
50.170002,30.885315,-158.930435,0.017651,0.001298,0.032980,137.384735,6.998713,0.329801,-158.930435,0.033994,0.000000
50.390003,31.360464,-158.974915,0.017712,0.001310,0.033275,139.498306,7.106383,0.332753,-158.974915,0.034359,0.000000
50.610001,32.232189,-158.974915,0.017746,0.001329,0.033769,143.375931,7.303918,0.337688,-158.974915,0.034723,0.000000
50.830002,32.643661,-158.885956,0.017694,0.001338,0.033994,145.206253,7.397160,0.339944,-158.885956,0.035097,0.000000
51.050003,32.975815,-158.885956,0.017716,0.001348,0.034246,146.683746,7.472426,0.342457,-158.885956,0.035460,0.000000
51.270004,33.651302,-158.885956,0.017759,0.001362,0.034592,149.688461,7.625494,0.345924,-158.885956,0.035825,0.000000
51.490002,35.067806,-158.885956,0.017738,0.001387,0.035234,155.989395,7.946478,0.352343,-158.885956,0.036188,0.000000
51.710003,35.426773,-158.930435,0.017742,0.001398,0.035504,157.586151,8.027822,0.355038,-158.930435,0.036562,0.000000
51.930004,36.190136,-158.885956,0.017785,0.001414,0.035920,160.981766,8.200802,0.359202,-158.885956,0.036925,0.000000
52.150002,36.721512,-158.885956,0.017789,0.001429,0.036293,163.345444,8.321214,0.362926,-158.885956,0.037290,0.000000
52.370003,37.112129,-158.885956,0.017802,0.001439,0.036544,165.082993,8.409728,0.365439,-158.885956,0.037663,0.000000
52.590004,38.191265,-158.752518,0.017815,0.001459,0.037047,169.883224,8.654264,0.370466,-158.752518,0.038028,0.000000
52.810001,38.610558,-158.885956,0.017798,0.001469,0.037307,171.748337,8.749277,0.373070,-158.885956,0.038391,0.000000
53.030003,38.797859,-158.796997,0.017841,0.001476,0.037481,172.581497,8.791720,0.374811,-158.796997,0.038756,0.000000
53.250004,39.561970,-158.752518,0.017798,0.001491,0.037872,175.980423,8.964870,0.378717,-158.752518,0.039128,0.000000
53.470001,40.967674,-158.796997,0.017876,0.001518,0.038547,182.233322,9.283407,0.385469,-158.796997,0.039493,0.000000
53.690002,41.545223,-158.796997,0.017884,0.001530,0.038851,184.802383,9.414282,0.388512,-158.796997,0.039856,0.000000
53.910004,42.144001,-158.841476,0.017867,0.001544,0.039207,187.465881,9.549967,0.392070,-158.841476,0.040230,0.000000
54.130001,42.642979,-158.752518,0.017880,0.001555,0.039493,189.685440,9.663036,0.394931,-158.752518,0.040594,0.000000
54.350002,43.715782,-158.708038,0.017927,0.001576,0.040021,194.457504,9.906137,0.400215,-158.708038,0.040959,0.000000
54.570004,44.288490,-158.708038,0.017893,0.001589,0.040352,197.005051,10.035915,0.403515,-158.708038,0.041322,0.000000
54.790001,44.767365,-158.752518,0.017945,0.001600,0.040647,199.135178,10.144429,0.406467,-158.752518,0.041696,0.000000
55.010002,45.117393,-158.752518,0.017966,0.001613,0.040975,200.692184,10.223747,0.409753,-158.752518,0.042059,0.000000
55.230003,46.349575,-158.708038,0.017919,0.001631,0.041419,206.173203,10.502964,0.414189,-158.708038,0.042424,0.000000
55.450001,47.252579,-158.708038,0.017932,0.001649,0.041887,210.189972,10.707587,0.418867,-158.708038,0.042797,0.000000
55.670002,47.636494,-158.619064,0.018001,0.001659,0.042147,211.897705,10.794583,0.421471,-158.619064,0.043161,0.000000
55.890003,48.174942,-158.663559,0.017970,0.001672,0.042459,214.292847,10.916597,0.424590,-158.663559,0.043525,0.000000
56.110004,48.900326,-158.708038,0.017979,0.001689,0.042910,217.519516,11.080973,0.429101,-158.708038,0.043890,0.000000
56.330002,49.896049,-158.574585,0.018026,0.001703,0.043266,221.948715,11.306606,0.432659,-158.574585,0.044262,0.000000
56.550003,50.370823,-158.530106,0.018026,0.001716,0.043594,224.060608,11.414192,0.435944,-158.530106,0.044627,0.000000
56.770004,50.700375,-158.574585,0.018035,0.001728,0.043890,225.526535,11.488869,0.438896,-158.574585,0.044992,0.000000
56.990002,51.659233,-158.574585,0.018061,0.001745,0.044332,229.791748,11.706150,0.443317,-158.574585,0.045364,0.000000
57.210003,52.590164,-158.574585,0.018039,0.001762,0.044748,233.932739,11.917101,0.447481,-158.574585,0.045728,0.000000
57.430004,53.421299,-158.574585,0.018091,0.001778,0.045155,237.629807,12.105439,0.451553,-158.574585,0.046092,0.000000
57.650002,53.937778,-158.574585,0.018091,0.001790,0.045476,239.927216,12.222476,0.454763,-158.574585,0.046457,0.000000
57.870003,54.541023,-158.530106,0.018108,0.001801,0.045737,242.610596,12.359173,0.457367,-158.530106,0.046830,0.000000
58.090004,55.063461,-158.530106,0.018108,0.001813,0.046041,244.934509,12.477559,0.460410,-158.530106,0.047193,0.000000
58.310001,55.729263,-158.574585,0.018070,0.001828,0.046439,247.896149,12.628431,0.464391,-158.574585,0.047558,0.000000
58.530003,56.451294,-158.485626,0.018100,0.001839,0.046716,251.107895,12.792046,0.467162,-158.485626,0.047930,0.000000
58.750004,56.970383,-158.485626,0.018078,0.001853,0.047055,253.416916,12.909673,0.470553,-158.485626,0.048295,0.000000
58.970001,57.608253,-158.530106,0.018117,0.001866,0.047385,256.254303,13.054217,0.473854,-158.530106,0.048660,0.000000
59.190002,59.050827,-158.574585,0.018143,0.001889,0.047983,262.671204,13.381109,0.479834,-158.574585,0.049023,0.000000
59.410004,59.974308,-158.485626,0.018126,0.001905,0.048382,266.779053,13.590373,0.483816,-158.485626,0.049396,0.000000
59.630001,60.396206,-158.441147,0.018160,0.001915,0.048633,268.655731,13.685975,0.486329,-158.441147,0.049761,0.000000
59.850002,61.081371,-158.396667,0.018169,0.001930,0.049014,271.703522,13.841236,0.490144,-158.396667,0.050126,0.000000
60.070004,61.933735,-158.352188,0.018182,0.001944,0.049370,275.495026,14.034385,0.493702,-158.352188,0.050498,0.000000
60.290005,62.144123,-158.396667,0.018195,0.001953,0.049614,276.430878,14.082060,0.496139,-158.396667,0.050863,0.000000
60.510002,63.676437,-158.441147,0.018182,0.001976,0.050186,283.246948,14.429287,0.501862,-158.441147,0.051226,0.000000
60.730003,64.001144,-158.396667,0.018216,0.001987,0.050463,284.691315,14.502867,0.504632,-158.396667,0.051591,0.000000
60.950005,64.865791,-158.352188,0.018233,0.002001,0.050836,288.537445,14.698799,0.508357,-158.352188,0.051964,0.000000
61.170002,66.017914,-158.352188,0.018272,0.002020,0.051313,293.662354,14.959873,0.513126,-158.352188,0.052328,0.000000
61.390003,66.641632,-158.352188,0.018216,0.002033,0.051626,296.436798,15.101210,0.516260,-158.352188,0.052692,0.000000
61.610004,67.260887,-158.352188,0.018255,0.002045,0.051954,299.191376,15.241535,0.519545,-158.352188,0.053064,0.000000
61.830002,67.248978,-158.307709,0.018246,0.002043,0.051894,299.138397,15.238836,0.518939,-158.307709,0.052110,0.000000
62.050003,66.846809,-158.218750,0.018259,0.002043,0.051894,297.349457,15.147703,0.518939,-158.218750,0.052110,0.000000
62.270004,66.560455,-158.307709,0.018281,0.002041,0.051833,296.075684,15.082814,0.518334,-158.307709,0.051894,0.000000
62.490002,66.297935,-158.263229,0.018259,0.002040,0.051824,294.907959,15.023327,0.518243,-158.263229,0.051894,0.000000
62.710003,66.076004,-158.307709,0.018277,0.002040,0.051817,293.920746,14.973037,0.518167,-158.307709,0.051894,0.000000
62.930004,65.879761,-158.218750,0.018251,0.002040,0.051808,293.047821,14.928567,0.518076,-158.218750,0.051894,0.000000
63.150002,65.709587,-158.174255,0.018289,0.002039,0.051799,292.290833,14.890005,0.517986,-158.174255,0.051894,0.000000
63.370003,65.559151,-158.218750,0.018272,0.002039,0.051799,291.621674,14.855916,0.517986,-158.218750,0.051894,0.000000
63.590004,65.414665,-158.218750,0.018264,0.002039,0.051789,290.978973,14.823174,0.517895,-158.218750,0.051894,0.000000
63.810001,65.288437,-158.218750,0.018298,0.002039,0.051789,290.417480,14.794571,0.517895,-158.218750,0.051894,0.000000
64.030006,65.173744,-158.174255,0.018277,0.002039,0.051789,289.907288,14.768581,0.517895,-158.174255,0.051894,0.000000
64.250000,65.083633,-158.174255,0.018298,0.002039,0.051789,289.506470,14.748162,0.517895,-158.174255,0.051894,0.000000
64.470001,64.969315,-158.085297,0.018298,0.002039,0.051789,288.997955,14.722258,0.517895,-158.085297,0.051894,0.000000
64.690002,64.881805,-158.218750,0.018289,0.002039,0.051782,288.608673,14.702427,0.517819,-158.218750,0.051894,0.000000
64.910004,64.795418,-158.085297,0.018285,0.002039,0.051782,288.224426,14.682852,0.517819,-158.085297,0.051894,0.000000
65.130005,64.716469,-158.129776,0.018324,0.002039,0.051782,287.873230,14.664962,0.517819,-158.129776,0.051894,0.000000
65.350006,64.641624,-158.129776,0.018281,0.002039,0.051782,287.540314,14.648002,0.517819,-158.129776,0.051894,0.000000
65.570000,64.565285,-158.040817,0.018246,0.002039,0.051782,287.200745,14.630702,0.517819,-158.040817,0.051894,0.000000
65.790001,64.506454,-158.129776,0.018333,0.002039,0.051782,286.939026,14.617372,0.517819,-158.129776,0.051894,0.000000
66.010002,64.429741,-158.129776,0.018307,0.002039,0.051782,286.597809,14.599988,0.517819,-158.129776,0.051894,0.000000
66.230003,64.372025,-157.996338,0.018268,0.002039,0.051782,286.341064,14.586909,0.517819,-157.996338,0.051894,0.000000
66.450005,64.311333,-158.040817,0.018264,0.002038,0.051773,286.071106,14.573156,0.517728,-158.040817,0.051894,0.000000
66.670006,64.252495,-157.996338,0.018294,0.002038,0.051773,285.809357,14.559824,0.517728,-157.996338,0.051894,0.000000
66.889999,64.215630,-158.085297,0.018289,0.002038,0.051773,285.645386,14.551470,0.517728,-158.085297,0.051894,0.000000
67.110001,64.169456,-158.040817,0.018281,0.002038,0.051773,285.440002,14.541007,0.517728,-158.040817,0.051894,0.000000
67.330002,64.110619,-157.996338,0.018281,0.002038,0.051773,285.178284,14.527675,0.517728,-157.996338,0.051894,0.000000
67.550003,64.061844,-157.862900,0.018264,0.002038,0.051773,284.961304,14.516622,0.517728,-157.862900,0.051894,0.000000
67.770004,64.020134,-157.996338,0.018281,0.002038,0.051773,284.775787,14.507170,0.517728,-157.996338,0.051894,0.000000
67.990005,63.969494,-158.040817,0.018259,0.002038,0.051773,284.550507,14.495694,0.517728,-158.040817,0.051894,0.000000
68.210007,63.928905,-157.951859,0.018285,0.002038,0.051773,284.369965,14.486497,0.517728,-157.951859,0.051894,0.000000
68.430000,63.896881,-157.862900,0.018315,0.002038,0.051773,284.227509,14.479239,0.517728,-157.862900,0.051894,0.000000
68.650002,63.860760,-157.862900,0.018311,0.002038,0.051773,284.066833,14.471055,0.517728,-157.862900,0.051894,0.000000
68.870003,63.812725,-157.862900,0.018264,0.002038,0.051773,283.853180,14.460170,0.517728,-157.862900,0.051894,0.000000
69.090004,63.789265,-157.907379,0.018311,0.002038,0.051773,283.748810,14.454854,0.517728,-157.907379,0.051894,0.000000
69.310005,63.745327,-157.862900,0.018328,0.002038,0.051773,283.553375,14.444897,0.517728,-157.862900,0.051894,0.000000
69.530006,63.702877,-157.818420,0.018289,0.002038,0.051773,283.364563,14.435279,0.517728,-157.818420,0.051894,0.000000
69.750000,63.680534,-157.818420,0.018298,0.002038,0.051773,283.265167,14.430216,0.517728,-157.818420,0.051894,0.000000
69.970001,63.643669,-157.818420,0.018302,0.002038,0.051773,283.101166,14.421862,0.517728,-157.818420,0.051894,0.000000
70.190002,63.593025,-157.818420,0.018315,0.002038,0.051773,282.875916,14.410386,0.517728,-157.818420,0.051894,0.000000
70.410004,63.574036,-157.818420,0.018307,0.002038,0.051773,282.791443,14.406082,0.517728,-157.818420,0.051894,0.000000
70.630005,63.550201,-157.818420,0.018285,0.002038,0.051764,282.685425,14.400681,0.517637,-157.818420,0.051894,0.000000
70.850006,63.518925,-157.729446,0.018268,0.002038,0.051764,282.546295,14.393594,0.517637,-157.729446,0.051894,0.000000
71.070000,63.495834,-157.773926,0.018268,0.002038,0.051764,282.443573,14.388361,0.517637,-157.773926,0.051894,0.000000
71.290001,63.463814,-157.818420,0.018289,0.002038,0.051764,282.301147,14.381106,0.517637,-157.818420,0.051894,0.000000
71.510002,63.432159,-157.818420,0.018307,0.002038,0.051764,282.160339,14.373933,0.517637,-157.818420,0.051894,0.000000
71.730003,63.412052,-157.729446,0.018302,0.002038,0.051764,282.070892,14.369376,0.517637,-157.729446,0.051894,0.000000
71.950005,63.386730,-157.729446,0.018307,0.002038,0.051764,281.958252,14.363638,0.517637,-157.729446,0.051894,0.000000
72.170006,63.364388,-157.773926,0.018268,0.002038,0.051764,281.858887,14.358575,0.517637,-157.773926,0.051894,0.000000
72.390007,63.342419,-157.729446,0.018285,0.002038,0.051764,281.761139,14.353598,0.517637,-157.729446,0.051894,0.000000
72.610001,63.322311,-157.640488,0.018251,0.002038,0.051764,281.671722,14.349041,0.517637,-157.640488,0.051894,0.000000
72.830002,63.280979,-157.640488,0.018298,0.002038,0.051764,281.487854,14.339675,0.517637,-157.640488,0.051894,0.000000
73.050003,63.281349,-157.640488,0.018285,0.002038,0.051764,281.489502,14.339758,0.517637,-157.640488,0.051894,0.000000
73.270004,63.248581,-157.640488,0.018289,0.002038,0.051764,281.343750,14.332333,0.517637,-157.640488,0.051894,0.000000
73.490005,63.224003,-157.640488,0.018264,0.002038,0.051764,281.234406,14.326763,0.517637,-157.640488,0.051894,0.000000
73.710007,63.207993,-157.640488,0.018320,0.002038,0.051764,281.163208,14.323135,0.517637,-157.640488,0.051894,0.000000
73.930000,63.182297,-157.596008,0.018285,0.002038,0.051764,281.048889,14.317313,0.517637,-157.596008,0.051894,0.000000
74.150002,63.157349,-157.551529,0.018294,0.002038,0.051764,280.937927,14.311660,0.517637,-157.551529,0.051894,0.000000
74.370003,63.130913,-157.551529,0.018289,0.002038,0.051764,280.820312,14.305670,0.517637,-157.551529,0.051894,0.000000
74.590004,63.110802,-157.640488,0.018281,0.002038,0.051764,280.730865,14.301112,0.517637,-157.640488,0.051894,0.000000
74.810005,63.093674,-157.640488,0.018298,0.002038,0.051764,280.654663,14.297231,0.517637,-157.640488,0.051894,0.000000
75.030006,63.089577,-157.507050,0.018315,0.002038,0.051764,280.636444,14.296303,0.517637,-157.507050,0.051894,0.000000
75.250000,63.051598,-157.551529,0.018320,0.002038,0.051764,280.467499,14.287696,0.517637,-157.551529,0.051894,0.000000
75.470001,63.044521,-157.507050,0.018255,0.002038,0.051764,280.436035,14.286093,0.517637,-157.507050,0.051894,0.000000
75.690002,63.019943,-157.507050,0.018302,0.002038,0.051764,280.326721,14.280523,0.517637,-157.507050,0.051894,0.000000
75.910004,62.997231,-157.507050,0.018255,0.002038,0.051764,280.225677,14.275377,0.517637,-157.507050,0.051894,0.000000
76.130005,62.987919,-157.507050,0.018324,0.002038,0.051764,280.184265,14.273266,0.517637,-157.507050,0.051894,0.000000
76.350006,62.964462,-157.507050,0.018289,0.002038,0.051764,280.079926,14.267951,0.517637,-157.507050,0.051894,0.000000
76.570007,62.952171,-157.462570,0.018277,0.002038,0.051764,280.025238,14.265165,0.517637,-157.462570,0.051894,0.000000
76.790001,62.934299,-157.418091,0.018281,0.002038,0.051764,279.945740,14.261117,0.517637,-157.418091,0.051894,0.000000
77.010002,62.918659,-157.462570,0.018311,0.002038,0.051764,279.876160,14.257572,0.517637,-157.462570,0.051894,0.000000
77.230003,62.893337,-157.418091,0.018320,0.002038,0.051764,279.763550,14.251834,0.517637,-157.418091,0.051894,0.000000
77.450005,62.866154,-157.418091,0.018311,0.002038,0.051764,279.642609,14.245674,0.517637,-157.418091,0.051894,0.000000
77.670006,62.854984,-157.418091,0.018255,0.002038,0.051764,279.592926,14.243143,0.517637,-157.418091,0.051894,0.000000
77.890007,62.847164,-157.418091,0.018324,0.002038,0.051764,279.558136,14.241371,0.517637,-157.418091,0.051894,0.000000
78.110001,62.843441,-157.373611,0.018315,0.002038,0.051764,279.541595,14.240527,0.517637,-157.373611,0.051894,0.000000
78.330002,62.812904,-157.329117,0.018246,0.002038,0.051764,279.405762,14.233607,0.517637,-157.329117,0.051894,0.000000
78.550003,62.800243,-157.284637,0.018277,0.002038,0.051756,279.349426,14.230739,0.517562,-157.284637,0.051894,0.000000
78.770004,62.786095,-157.284637,0.018298,0.002038,0.051756,279.286499,14.227532,0.517562,-157.284637,0.051894,0.000000
78.990005,62.763752,-157.373611,0.018281,0.002038,0.051756,279.187103,14.222469,0.517562,-157.373611,0.051894,0.000000
79.210007,62.759285,-157.329117,0.018294,0.002038,0.051756,279.167236,14.221457,0.517562,-157.329117,0.051894,0.000000
79.430000,62.748486,-157.284637,0.018294,0.002038,0.051756,279.119202,14.219010,0.517562,-157.284637,0.051894,0.000000
79.650002,62.732101,-157.240158,0.018302,0.002038,0.051756,279.046326,14.215298,0.517562,-157.240158,0.051894,0.000000
79.870003,62.718323,-157.284637,0.018298,0.002038,0.051756,278.985046,14.212174,0.517562,-157.284637,0.051894,0.000000
80.090004,62.704544,-157.284637,0.018277,0.002038,0.051756,278.923737,14.209053,0.517562,-157.284637,0.051894,0.000000
80.310005,62.687416,-157.240158,0.018268,0.002038,0.051756,278.847565,14.205172,0.517562,-157.240158,0.051894,0.000000
80.530006,62.682575,-157.240158,0.018272,0.002038,0.051756,278.826019,14.204074,0.517562,-157.240158,0.051894,0.000000
80.750008,62.659115,-157.240158,0.018281,0.002038,0.051756,278.721649,14.198759,0.517562,-157.240158,0.051894,0.000000
80.970001,62.655018,-157.151199,0.018302,0.002038,0.051756,278.703430,14.197830,0.517562,-157.151199,0.051894,0.000000
81.190002,62.639008,-157.240158,0.018277,0.002038,0.051756,278.632233,14.194202,0.517562,-157.240158,0.051894,0.000000
81.410004,62.643475,-157.240158,0.018289,0.002038,0.051756,278.652100,14.195214,0.517562,-157.240158,0.051894,0.000000
81.630005,62.619270,-157.151199,0.018294,0.002038,0.051756,278.544434,14.189730,0.517562,-157.151199,0.051894,0.000000
81.850006,62.586876,-157.195679,0.018311,0.002038,0.051756,278.400330,14.182388,0.517562,-157.195679,0.051894,0.000000
82.070007,62.587246,-157.106720,0.018311,0.002038,0.051756,278.401978,14.182473,0.517562,-157.106720,0.051894,0.000000
82.290001,62.572353,-157.151199,0.018294,0.002038,0.051756,278.335724,14.179097,0.517562,-157.151199,0.051894,0.000000
82.510002,62.561180,-157.106720,0.018328,0.002038,0.051756,278.286041,14.176566,0.517562,-157.106720,0.051894,0.000000
82.730003,62.554108,-157.062241,0.018264,0.002038,0.051756,278.254578,14.174963,0.517562,-157.062241,0.051894,0.000000
82.950005,62.545914,-157.106720,0.018315,0.002038,0.051756,278.218109,14.173107,0.517562,-157.106720,0.051894,0.000000
83.170006,62.529530,-157.106720,0.018298,0.002038,0.051756,278.145233,14.169394,0.517562,-157.106720,0.051894,0.000000
83.390007,62.517986,-157.106720,0.018277,0.002038,0.051756,278.093903,14.166779,0.517562,-157.106720,0.051894,0.000000
83.610001,62.502346,-157.017761,0.018302,0.002038,0.051756,278.024323,14.163234,0.517562,-157.017761,0.051894,0.000000
83.830002,62.505325,-157.017761,0.018289,0.002038,0.051756,278.037567,14.163910,0.517562,-157.017761,0.051894,0.000000
84.050003,62.501602,-157.062241,0.018302,0.002038,0.051756,278.021027,14.163065,0.517562,-157.062241,0.051894,0.000000
84.270004,62.477398,-157.017761,0.018337,0.002038,0.051756,277.913361,14.157581,0.517562,-157.017761,0.051894,0.000000
84.490005,62.462132,-157.106720,0.018255,0.002038,0.051756,277.845428,14.154121,0.517562,-157.106720,0.051894,0.000000
84.710007,62.455429,-157.017761,0.018281,0.002038,0.051756,277.815613,14.152602,0.517562,-157.017761,0.051894,0.000000
84.930000,62.452450,-156.973282,0.018277,0.002038,0.051756,277.802368,14.151928,0.517562,-156.973282,0.051894,0.000000
85.150002,62.432339,-156.973282,0.018285,0.002038,0.051756,277.712921,14.147370,0.517562,-156.973282,0.051894,0.000000
85.370003,62.419308,-157.017761,0.018277,0.002038,0.051756,277.654938,14.144417,0.517562,-157.017761,0.051894,0.000000
85.590004,62.411114,-156.973282,0.018281,0.002038,0.051756,277.618500,14.142561,0.517562,-156.973282,0.051894,0.000000
85.810005,62.379089,-156.928802,0.018277,0.002038,0.051756,277.476044,14.135303,0.517562,-156.928802,0.051894,0.000000
86.030006,62.396965,-156.928802,0.018294,0.002038,0.051756,277.555573,14.139354,0.517562,-156.928802,0.051894,0.000000
86.250008,62.386539,-156.928802,0.018268,0.002038,0.051756,277.509186,14.136992,0.517562,-156.928802,0.051894,0.000000
86.470001,62.364941,-156.928802,0.018298,0.002038,0.051756,277.413116,14.132098,0.517562,-156.928802,0.051894,0.000000
86.690002,62.344833,-156.973282,0.018315,0.002038,0.051756,277.323669,14.127542,0.517562,-156.973282,0.051894,0.000000
86.910004,62.352280,-156.928802,0.018307,0.002038,0.051756,277.356781,14.129228,0.517562,-156.928802,0.051894,0.000000
87.130005,62.334034,-156.884308,0.018285,0.002038,0.051756,277.275635,14.125093,0.517562,-156.884308,0.051894,0.000000
87.350006,62.327332,-156.839828,0.018307,0.002038,0.051756,277.245819,14.123575,0.517562,-156.839828,0.051894,0.000000
87.570007,62.328075,-156.839828,0.018337,0.002038,0.051756,277.249115,14.123744,0.517562,-156.839828,0.051894,0.000000
87.790001,62.312065,-156.839828,0.018328,0.002038,0.051756,277.177917,14.120116,0.517562,-156.839828,0.051894,0.000000
88.010002,62.304245,-156.795349,0.018298,0.002038,0.051756,277.143127,14.118344,0.517562,-156.795349,0.051894,0.000000
88.230003,62.285625,-156.750870,0.018354,0.002038,0.051756,277.060303,14.114124,0.517562,-156.750870,0.051894,0.000000
88.450005,62.284138,-156.750870,0.018307,0.002038,0.051756,277.053680,14.113788,0.517562,-156.750870,0.051894,0.000000
88.670006,62.265518,-156.750870,0.018307,0.002038,0.051756,276.970856,14.109568,0.517562,-156.750870,0.051894,0.000000
88.890007,62.258816,-156.795349,0.018255,0.002038,0.051756,276.941040,14.108049,0.517562,-156.795349,0.051894,0.000000
89.110001,62.251740,-156.795349,0.018294,0.002038,0.051756,276.909576,14.106446,0.517562,-156.795349,0.051894,0.000000
89.330002,62.235355,-156.661911,0.018298,0.002038,0.051756,276.836700,14.102733,0.517562,-156.661911,0.051894,0.000000
89.550003,62.233494,-156.750870,0.018281,0.002038,0.051756,276.828400,14.102311,0.517562,-156.750870,0.051894,0.000000
89.770004,62.234238,-156.706390,0.018320,0.002038,0.051756,276.831726,14.102479,0.517562,-156.706390,0.051894,0.000000
89.990005,62.212269,-156.750870,0.018285,0.002038,0.051756,276.733978,14.097502,0.517562,-156.750870,0.051894,0.000000
90.210007,62.199608,-156.661911,0.018307,0.002038,0.051756,276.677673,14.094633,0.517562,-156.661911,0.051894,0.000000
90.430008,62.207798,-156.617432,0.018324,0.002038,0.051756,276.714111,14.096489,0.517562,-156.617432,0.051894,0.000000
90.650002,62.188065,-156.617432,0.018294,0.002038,0.051756,276.626312,14.092016,0.517562,-156.617432,0.051894,0.000000
90.870003,62.191044,-156.706390,0.018268,0.002038,0.051756,276.639587,14.092692,0.517562,-156.706390,0.051894,0.000000
91.090004,62.189926,-156.661911,0.018268,0.002038,0.051756,276.634613,14.092439,0.517562,-156.661911,0.051894,0.000000
91.310005,62.163116,-156.617432,0.018311,0.002038,0.051756,276.515350,14.086364,0.517562,-156.617432,0.051894,0.000000
91.530006,62.161255,-156.572952,0.018294,0.002038,0.051756,276.507080,14.085941,0.517562,-156.572952,0.051894,0.000000
91.750008,62.147102,-156.572952,0.018251,0.002038,0.051756,276.444122,14.082735,0.517562,-156.572952,0.051894,0.000000
91.970001,62.154552,-156.617432,0.018289,0.002038,0.051756,276.477264,14.084422,0.517562,-156.617432,0.051894,0.000000
92.190002,62.136303,-156.572952,0.018264,0.002038,0.051756,276.396088,14.080287,0.517562,-156.572952,0.051894,0.000000
92.200005,62.148220,-156.617432,0.018264,0.002038,0.051756,276.449097,14.082988,0.517562,-156.617432,0.051894,0.000000