File: Data/New old I18 1_08182023_114853.csv
Time (sec),S:Load (lbs),S:HL1 (DIM),S:LVDT (in),S:Position (in),Ch:Position (mm),Ch:Load (N),Ch:Stress (MPa),Ch:Strain (mm/mm),Ch:HL1 (DIM),Set Point (),Cycles ()
0.110000,-0.024574,-7.072471,-0.000017,-0.000000,-0.000000,-0.109312,-0.005569,-0.000000,-7.072471,0.000044,0.000000
0.730000,0.001495,-7.072471,-0.000004,0.000183,0.004640,0.006652,0.000339,0.046403,-7.072471,0.005577,0.000000
1.350000,-0.002602,-7.072471,0.000013,0.000576,0.014631,-0.011573,-0.000590,0.146309,-7.072471,0.015897,0.000000
1.970000,0.031654,-7.072471,-0.000013,0.000977,0.024820,0.140806,0.007173,0.248198,-7.072471,0.026234,0.000000
2.590000,0.022720,-7.161433,-0.000017,0.001396,0.035452,0.101065,0.005149,0.354524,-7.161433,0.036555,0.000000
3.210000,-0.048409,-7.205914,0.000000,0.001800,0.045720,-0.215332,-0.010970,0.457200,-7.205914,0.046892,0.000000
3.830000,-0.004089,-7.205914,0.000013,0.002208,0.056075,-0.018190,-0.000927,0.560755,-7.205914,0.057211,0.000000
4.450000,0.013039,-7.161433,-0.000009,0.002609,0.066257,0.057999,0.002955,0.662569,-7.161433,0.067548,0.000000
5.070000,0.011177,-7.161433,-0.000017,0.003011,0.076473,0.049718,0.002533,0.764730,-7.161433,0.077869,0.000000
5.690000,-0.018242,-7.205914,0.000009,0.003429,0.087096,-0.081144,-0.004134,0.870965,-7.205914,0.088206,0.000000
6.310000,-0.015266,-7.205914,0.000009,0.003834,0.097373,-0.067908,-0.003459,0.973732,-7.205914,0.098525,0.000000
6.930000,-0.001862,-7.250395,0.000030,0.004244,0.107806,-0.008281,-0.000422,1.078059,-7.250395,0.108863,0.000000
7.550000,0.004471,-7.250395,0.000026,0.004647,0.118030,0.019887,0.001013,1.180297,-7.250395,0.119183,0.000000
8.170000,0.014153,-7.250395,-0.000009,0.005050,0.128263,0.062954,0.003207,1.282625,-7.250395,0.129521,0.000000
8.790000,-0.011909,-7.294876,0.000022,0.005465,0.138818,-0.052976,-0.002699,1.388178,-7.294876,0.139841,0.000000
9.410001,-0.037231,-7.294876,0.000022,0.005862,0.148895,-0.165614,-0.008437,1.488947,-7.294876,0.150179,0.000000
10.030001,0.003357,-7.294876,-0.000009,0.006275,0.159397,0.014932,0.000761,1.593971,-7.294876,0.160498,0.000000
10.650001,-0.006699,-7.294876,0.000017,0.006674,0.169516,-0.029797,-0.001518,1.695164,-7.294876,0.170835,0.000000
11.270000,0.013039,-7.339357,0.000013,0.007082,0.179881,0.057999,0.002955,1.798809,-7.339357,0.181156,0.000000
11.890000,-0.018990,-7.428319,-0.000013,0.007497,0.190417,-0.084470,-0.004303,1.904166,-7.428319,0.191493,0.000000
12.510000,-0.018990,-7.383838,-0.000004,0.007897,0.200590,-0.084470,-0.004303,2.005903,-7.383838,0.201830,0.000000
13.130001,0.004097,-7.472800,0.000013,0.008308,0.211023,0.018224,0.000928,2.110230,-7.472800,0.212149,0.000000
13.750001,-0.002228,-7.472800,-0.000004,0.008712,0.221282,-0.009910,-0.000505,2.212816,-7.472800,0.222487,0.000000
14.370001,0.016388,-7.472800,0.000013,0.009113,0.231463,0.072897,0.003714,2.314630,-7.472800,0.232807,0.000000
14.990001,0.009315,-7.472800,0.000013,0.009530,0.242061,0.041437,0.002111,2.420607,-7.472800,0.243145,0.000000
15.610001,-0.030533,-7.517281,-0.000013,0.009932,0.252268,-0.135817,-0.006919,2.522678,-7.517281,0.253464,0.000000
16.230001,-0.024948,-7.606243,0.000013,0.010341,0.262649,-0.110975,-0.005653,2.626490,-7.606243,0.263801,0.000000
16.850000,-0.005211,-7.517281,0.000009,0.010741,0.272830,-0.023179,-0.001181,2.728304,-7.517281,0.274122,0.000000
17.470001,0.007080,-7.561762,0.000017,0.011148,0.283150,0.031494,0.001604,2.831495,-7.561762,0.284459,0.000000
18.090000,-0.030159,-7.472800,-0.000004,0.011565,0.293756,-0.134154,-0.006834,2.937563,-7.472800,0.294780,0.000000
18.710001,-0.023453,-7.561762,-0.000022,0.011963,0.303850,-0.104323,-0.005314,3.038499,-7.561762,0.305117,0.000000
19.330002,-0.018616,-7.606243,0.000000,0.012372,0.314248,-0.082807,-0.004218,3.142477,-7.606243,0.315436,0.000000
19.950001,-0.006325,-7.650723,0.000017,0.012777,0.324543,-0.028134,-0.001433,3.245426,-7.650723,0.325773,0.000000
20.570002,-0.011169,-7.606243,0.000030,0.013186,0.334922,-0.049684,-0.002531,3.349223,-7.606243,0.336094,0.000000
21.190001,0.017136,-7.606243,0.000030,0.013597,0.345373,0.076223,0.003883,3.453732,-7.606243,0.346431,0.000000
21.810001,-0.012283,-7.650723,0.000022,0.014000,0.355589,-0.054639,-0.002783,3.555894,-7.650723,0.356751,0.000000
22.430000,-0.016006,-7.739686,0.000017,0.014407,0.365943,-0.071200,-0.003627,3.659433,-7.739686,0.367088,0.000000
23.050001,0.008942,-7.695205,0.000000,0.014809,0.376150,0.039774,0.002026,3.761504,-7.695205,0.377409,0.000000
23.670002,-0.000740,-7.695205,0.000000,0.015214,0.386427,-0.003292,-0.000168,3.864272,-7.695205,0.387746,0.000000
24.290001,-0.014145,-7.695205,0.000047,0.015631,0.397025,-0.062920,-0.003205,3.970249,-7.695205,0.398066,0.000000
24.910002,-0.062553,-7.739686,0.000004,0.016033,0.407250,-0.278251,-0.014175,4.072502,-7.739686,0.408404,0.000000
25.530001,-0.012657,-7.739686,0.000022,0.016441,0.417613,-0.056302,-0.002868,4.176132,-7.739686,0.418741,0.000000
26.150002,-0.005585,-7.784166,0.000043,0.016843,0.427820,-0.024842,-0.001266,4.278203,-7.784166,0.429060,0.000000
26.770000,-0.026062,-7.784166,0.000009,0.017250,0.438149,-0.115930,-0.005906,4.381485,-7.784166,0.439398,0.000000
27.390001,0.006332,-7.784166,0.000030,0.017661,0.448590,0.028168,0.001435,4.485903,-7.784166,0.449718,0.000000
28.010002,0.009315,-7.828648,0.000017,0.018066,0.458876,0.041437,0.002111,4.588761,-7.828648,0.460056,0.000000
28.630001,-0.043190,-7.873128,0.000034,0.018473,0.469221,-0.192119,-0.009787,4.692210,-7.873128,0.470375,0.000000
29.250002,0.006706,-7.828648,0.000039,0.018877,0.479472,0.029831,0.001520,4.794720,-7.828648,0.480712,0.000000
29.870001,0.005592,-7.873128,0.000017,0.019279,0.489679,0.024876,0.001267,4.896791,-7.873128,0.491033,0.000000
30.490002,-0.014519,-7.828648,0.000017,0.019696,0.500286,-0.064583,-0.003290,5.002859,-7.828648,0.501370,0.000000
31.110001,-0.067772,-7.917609,-0.000004,0.020099,0.510502,-0.301465,-0.015357,5.105021,-7.917609,0.511689,0.000000
31.730001,-0.020477,-8.006571,0.000047,0.020507,0.520874,-0.091088,-0.004640,5.208742,-8.006571,0.522026,0.000000
32.350002,0.000748,-7.962090,0.000017,0.020912,0.531168,0.003326,0.000169,5.311676,-7.962090,0.532347,0.000000
32.970001,-0.010796,-7.962090,0.000030,0.021314,0.541384,-0.048021,-0.002446,5.413838,-7.962090,0.542684,0.000000
33.590000,0.000374,-7.962090,0.000022,0.021730,0.551938,0.001663,0.000085,5.519376,-7.962090,0.553005,0.000000
34.210003,-0.025688,-7.962090,0.000013,0.022137,0.562275,-0.114267,-0.005821,5.622749,-7.962090,0.563342,0.000000
34.830002,-0.034256,-8.006571,-0.000004,0.022534,0.572361,-0.152378,-0.007763,5.723609,-8.006571,0.573661,0.000000
35.450001,-0.020103,-8.095533,0.000026,0.022945,0.582810,-0.089425,-0.004556,5.828103,-8.095533,0.583999,0.000000
36.070004,0.019363,-8.051052,0.000009,0.023343,0.592914,0.086133,0.004388,5.929144,-8.051052,0.594319,0.000000
36.690002,-0.002228,-8.051052,0.000013,0.023757,0.603433,-0.009910,-0.000505,6.034334,-8.051052,0.604657,0.000000
37.310001,-0.063301,-8.051052,0.000004,0.024166,0.613815,-0.281577,-0.014344,6.138146,-8.051052,0.614976,0.000000
37.930000,-0.025314,-8.140014,0.000004,0.024570,0.624073,-0.112604,-0.005736,6.240732,-8.140014,0.625313,0.000000
38.550003,-0.007812,-8.140014,-0.000004,0.024980,0.634497,-0.034752,-0.001770,6.344968,-8.140014,0.635650,0.000000
39.170002,0.004845,-8.184495,0.000017,0.025375,0.644515,0.021550,0.001098,6.445146,-8.184495,0.645971,0.000000
39.790001,-0.032021,-8.140014,0.000034,0.025796,0.655215,-0.142435,-0.007256,6.552153,-8.140014,0.656308,0.000000
40.410004,-0.032768,-8.228976,-0.000004,0.026198,0.665441,-0.145760,-0.007425,6.654406,-8.228976,0.666627,0.000000
41.030003,-0.022713,-8.228976,0.000013,0.026609,0.675864,-0.101031,-0.005147,6.758642,-8.228976,0.676965,0.000000
41.650002,-0.016380,-8.228976,0.000013,0.027012,0.686115,-0.072863,-0.003712,6.861152,-8.228976,0.687285,0.000000
42.270000,0.006706,-8.184495,-0.000013,0.027407,0.696141,0.029831,0.001520,6.961406,-8.184495,0.697623,0.000000
42.890003,0.001869,-8.184495,0.000013,0.027829,0.706859,0.008315,0.000424,7.068594,-8.184495,0.707943,0.000000
43.510002,-0.049522,-8.273457,0.000030,0.028232,0.717083,-0.220287,-0.011222,7.170832,-8.273457,0.718281,0.000000
44.130001,-0.070747,-8.317938,-0.000017,0.028639,0.727430,-0.314700,-0.016032,7.274296,-8.317938,0.728600,0.000000
44.750004,-0.017494,-8.362419,0.000034,0.029048,0.737827,-0.077818,-0.003964,7.378274,-8.362419,0.738937,0.000000
45.370003,0.003731,-8.362419,0.000013,0.029446,0.747939,0.016595,0.000845,7.479392,-8.362419,0.749258,0.000000
45.990002,-0.035744,-8.273457,0.000026,0.029863,0.758528,-0.158996,-0.008100,7.585278,-8.273457,0.759595,0.000000
46.610001,-0.030159,-8.362419,0.000022,0.030264,0.768709,-0.134154,-0.006834,7.687091,-8.362419,0.769914,0.000000
47.230003,-0.007072,-8.362419,0.000009,0.030671,0.779056,-0.031460,-0.001603,7.790555,-8.362419,0.780252,0.000000
47.850002,-0.023453,-8.406899,0.000034,0.031080,0.789444,-0.104323,-0.005314,7.894443,-8.406899,0.790572,0.000000
48.470001,0.008942,-8.451381,0.000009,0.031479,0.799565,0.039774,0.002026,7.995651,-8.451381,0.800910,0.000000
49.090004,0.003731,-8.406899,0.000060,0.031895,0.810128,0.016595,0.000845,8.101280,-8.406899,0.811229,0.000000
49.710003,-0.029785,-8.362419,0.000039,0.032300,0.820414,-0.132491,-0.006749,8.204139,-8.362419,0.821567,0.000000
50.330002,-0.094582,-8.451381,0.000026,0.032705,0.830716,-0.420720,-0.021432,8.307163,-8.451381,0.831887,0.000000
50.950001,0.013412,-8.495862,0.000004,0.033112,0.841035,0.059662,0.003039,8.410355,-8.495862,0.842224,0.000000
51.570004,0.105011,-8.495862,0.000026,0.033513,0.851235,0.467112,0.023796,8.512350,-8.495862,0.852561,0.000000
52.190002,0.165710,-8.540342,0.000039,0.033927,0.861754,0.737117,0.037551,8.617539,-8.540342,0.862882,0.000000
52.810001,0.260666,-8.451381,0.000052,0.034333,0.872047,1.159500,0.059068,8.720473,-8.451381,0.873219,0.000000
53.430004,0.281517,-8.584824,0.000448,0.034739,0.882368,1.252250,0.063793,8.823680,-8.584824,0.883538,0.000000
54.050003,0.286362,-8.584824,0.000811,0.035144,0.892661,1.273800,0.064890,8.926614,-8.584824,0.893876,0.000000
54.670002,0.297157,-8.584824,0.001224,0.035551,0.903008,1.321822,0.067337,9.030078,-8.584824,0.904196,0.000000
55.290001,0.329926,-8.540342,0.001638,0.035964,0.913492,1.467582,0.074762,9.134920,-8.540342,0.914534,0.000000
55.910004,0.309074,-8.584824,0.002061,0.036365,0.923682,1.374832,0.070037,9.236824,-8.584824,0.924853,0.000000
56.530003,0.262154,-8.540342,0.002475,0.036770,0.933959,1.166118,0.059405,9.339592,-8.540342,0.935190,0.000000
57.150002,0.326576,-8.629305,0.002910,0.037178,0.944331,1.452684,0.074003,9.443313,-8.629305,0.945511,0.000000
57.770004,0.310562,-8.673785,0.003298,0.037579,0.954513,1.381449,0.070374,9.545127,-8.673785,0.955848,0.000000
58.390003,0.310188,-8.629305,0.003725,0.037989,0.964927,1.379786,0.070290,9.649272,-8.629305,0.966169,0.000000
59.010002,0.288963,-8.673785,0.004143,0.038399,0.975343,1.285373,0.065480,9.753432,-8.673785,0.976506,0.000000
59.630001,0.317268,-8.673785,0.004570,0.038805,0.985655,1.411280,0.071894,9.856547,-8.673785,0.986825,0.000000
60.250004,0.322479,-8.762748,0.004967,0.039213,0.996018,1.434459,0.073075,9.960178,-8.762748,0.997162,0.000000
60.870003,0.331039,-8.762748,0.005368,0.039613,1.006173,1.472537,0.075015,10.061734,-8.762748,1.007483,0.000000
61.490002,0.337372,-8.762748,0.005808,0.040024,1.016615,1.500705,0.076450,10.166152,-8.762748,1.017820,0.000000
62.110004,0.342216,-8.807228,0.006234,0.040431,1.026960,1.522255,0.077547,10.269601,-8.807228,1.028139,0.000000
62.730003,0.294548,-8.807228,0.006627,0.040835,1.037202,1.310215,0.066746,10.372020,-8.807228,1.038477,0.000000
63.350002,0.333649,-8.762748,0.007067,0.041242,1.047548,1.484143,0.075606,10.475484,-8.762748,1.048797,0.000000
63.970001,0.343330,-8.896191,0.007468,0.041642,1.057695,1.527210,0.077800,10.576949,-8.896191,1.059135,0.000000
64.590004,0.335884,-8.851709,0.007933,0.042056,1.068232,1.494087,0.076112,10.682321,-8.851709,1.069472,0.000000
65.210007,0.320244,-8.851709,0.008347,0.042465,1.078612,1.424516,0.072568,10.786118,-8.851709,1.079791,0.000000
65.830002,0.332161,-8.851709,0.008744,0.042870,1.088907,1.477526,0.075269,10.889067,-8.851709,1.090128,0.000000
66.450005,0.358223,-8.851709,0.009201,0.043280,1.099305,1.593455,0.081174,10.993046,-8.851709,1.100449,0.000000
67.070000,0.348175,-8.896191,0.009619,0.043681,1.109486,1.548760,0.078898,11.094859,-8.896191,1.110786,0.000000
67.690002,0.357483,-8.851709,0.010024,0.044089,1.119849,1.590163,0.081007,11.198490,-8.851709,1.121107,0.000000
68.310005,0.342957,-8.985152,0.010455,0.044504,1.130395,1.525547,0.077715,11.303952,-8.985152,1.131444,0.000000
68.930000,0.337372,-8.940671,0.010908,0.044903,1.140524,1.500705,0.076450,11.405236,-8.940671,1.141763,0.000000
69.550003,0.340721,-8.896191,0.011283,0.045311,1.150905,1.515603,0.077209,11.509048,-8.896191,1.152101,0.000000
70.170006,0.355621,-8.985152,0.011701,0.045708,1.160991,1.581883,0.080585,11.609908,-8.985152,1.162421,0.000000
70.790001,0.363815,-8.940671,0.012141,0.046123,1.171535,1.618331,0.082442,11.715355,-8.940671,1.172759,0.000000
71.410004,0.351524,-9.074114,0.012603,0.046532,1.181924,1.563658,0.079657,11.819242,-9.074114,1.183078,0.000000
72.030006,0.353012,-9.029634,0.013016,0.046936,1.192184,1.570276,0.079994,11.921844,-9.029634,1.193415,0.000000
72.650002,0.364555,-8.985152,0.013405,0.047349,1.202669,1.621623,0.082609,12.026686,-8.985152,1.203736,0.000000
73.270004,0.381310,-9.029634,0.013857,0.047748,1.212789,1.696149,0.086406,12.127893,-9.029634,1.214073,0.000000
73.890007,0.360458,-9.074114,0.014262,0.048161,1.223301,1.603399,0.081681,12.233007,-9.074114,1.224392,0.000000
74.510002,0.353012,-9.118595,0.014728,0.048569,1.233655,1.570276,0.079994,12.336547,-9.118595,1.234731,0.000000
75.130005,0.360085,-9.118595,0.015155,0.048974,1.243931,1.601736,0.081596,12.439315,-9.118595,1.245050,0.000000
75.750000,0.378334,-9.118595,0.015586,0.049376,1.254157,1.682914,0.085732,12.541568,-9.118595,1.255388,0.000000
76.370003,0.592079,-9.118595,0.016022,0.049775,1.264276,2.633700,0.134167,12.642760,-9.118595,1.265708,0.000000
76.990005,0.582764,-9.163075,0.016095,0.000010,0.000253,2.592262,0.132056,0.002528,-9.163075,0.000565,0.000000
77.610001,0.711235,-9.207557,0.016099,0.000027,0.000695,3.163732,0.161168,0.006949,-9.207557,0.001596,0.000000
78.230003,0.767090,-9.163075,0.016155,0.000066,0.001684,3.412186,0.173825,0.016835,-9.163075,0.002628,0.000000
78.850006,0.797623,-9.207557,0.016151,0.000095,0.002421,3.548003,0.180744,0.024208,-9.207557,0.003661,0.000000
79.470001,0.878799,-9.163075,0.016224,0.000148,0.003765,3.909095,0.199139,0.037652,-9.163075,0.004692,0.000000
80.090004,0.869118,-9.252038,0.016259,0.000185,0.004701,3.866029,0.196945,0.047008,-9.252038,0.005733,0.000000
80.710007,0.928703,-9.207557,0.016289,0.000224,0.005680,4.131079,0.210447,0.056804,-9.207557,0.006764,0.000000
81.330002,1.013229,-9.341000,0.016310,0.000275,0.006973,4.507069,0.229601,0.069733,-9.341000,0.007797,0.000000
81.950005,1.010620,-9.296518,0.016328,0.000308,0.007823,4.495463,0.229010,0.078226,-9.296518,0.008829,0.000000
82.570007,1.067970,-9.296518,0.016410,0.000350,0.008890,4.750569,0.242006,0.088900,-9.296518,0.009860,0.000000
83.190002,1.156219,-9.252038,0.016453,0.000395,0.010035,5.143121,0.262003,0.100345,-9.252038,0.010893,0.000000
83.810005,1.184891,-9.296518,0.016461,0.000429,0.010902,5.270657,0.268500,0.109020,-9.296518,0.011933,0.000000
84.430000,1.228836,-9.341000,0.016504,0.000472,0.011995,5.466136,0.278458,0.119951,-9.341000,0.012966,0.000000
85.050003,1.292511,-9.341000,0.016535,0.000514,0.013061,5.749376,0.292887,0.130609,-9.341000,0.013998,0.000000
85.670006,1.311501,-9.385481,0.016586,0.000550,0.013963,5.833846,0.297190,0.139632,-9.385481,0.015029,0.000000
86.290001,1.362144,-9.341000,0.016621,0.000591,0.015021,6.059121,0.308666,0.150215,-9.341000,0.016062,0.000000
86.910004,1.441833,-9.385481,0.016638,0.000631,0.016027,6.413596,0.326724,0.160268,-9.385481,0.017094,0.000000
87.530006,1.488747,-9.385481,0.016711,0.000677,0.017206,6.622276,0.337355,0.172061,-9.385481,0.018134,0.000000
88.150002,1.558754,-9.429961,0.016707,0.000716,0.018178,6.933684,0.353219,0.181781,-9.429961,0.019167,0.000000
88.770004,1.602325,-9.518924,0.016776,0.000749,0.019037,7.127500,0.363092,0.190365,-9.518924,0.020198,0.000000
89.390007,1.628387,-9.429961,0.016819,0.000791,0.020095,7.243429,0.368998,0.200948,-9.429961,0.021230,0.000000
90.010002,1.686852,-9.429961,0.016845,0.000833,0.021170,7.503490,0.382246,0.211697,-9.429961,0.022263,0.000000
90.630005,1.743454,-9.429961,0.016923,0.000871,0.022123,7.755270,0.395072,0.221235,-9.429961,0.023294,0.000000
91.250008,1.806381,-9.474442,0.016962,0.000920,0.023363,8.035185,0.409332,0.233634,-9.474442,0.024335,0.000000
91.870003,1.872292,-9.563404,0.016983,0.000958,0.024335,8.328369,0.424267,0.243354,-9.563404,0.025366,0.000000
92.490005,1.910271,-9.563404,0.017035,0.000992,0.025194,8.497309,0.432874,0.251938,-9.563404,0.026399,0.000000
93.110001,1.984749,-9.518924,0.017087,0.001042,0.026478,8.828604,0.449751,0.264776,-9.518924,0.027431,0.000000
93.730003,2.002998,-9.474442,0.017087,0.001078,0.027371,8.909781,0.453886,0.273708,-9.474442,0.028462,0.000000
94.350006,2.064064,-9.563404,0.017134,0.001110,0.028194,9.181416,0.467724,0.281944,-9.563404,0.029495,0.000000
94.970001,2.204079,-9.607885,0.017216,0.001166,0.029608,9.804232,0.499451,0.296085,-9.607885,0.030527,0.000000
95.590004,2.199234,-9.607885,0.017242,0.001203,0.030544,9.782681,0.498354,0.305441,-9.607885,0.031568,0.000000
96.210007,2.347443,-9.652367,0.017311,0.001238,0.031437,10.441946,0.531938,0.314373,-9.652367,0.032600,0.000000
96.830002,2.434944,-9.518924,0.017345,0.001287,0.032695,10.831173,0.551766,0.326954,-9.518924,0.033631,0.000000
97.450005,2.472183,-9.607885,0.017380,0.001324,0.033631,10.996820,0.560205,0.336311,-9.607885,0.034664,0.000000
98.070007,2.547401,-9.607885,0.017431,0.001362,0.034594,11.331408,0.577249,0.345939,-9.607885,0.035696,0.000000
98.690002,2.656509,-9.652367,0.017483,0.001406,0.035722,11.816744,0.601974,0.357218,-9.652367,0.036727,0.000000
99.310005,2.702682,-9.696847,0.017531,0.001448,0.036771,12.022132,0.612437,0.367710,-9.696847,0.037769,0.000000
99.930008,2.801735,-9.696847,0.017608,0.001485,0.037716,12.462739,0.634882,0.377157,-9.696847,0.038800,0.000000
100.550003,2.953293,-9.696847,0.017621,0.001532,0.038913,13.136903,0.669226,0.389133,-9.696847,0.039832,0.000000
101.170006,2.993134,-9.741328,0.017664,0.001573,0.039953,13.314123,0.678254,0.399534,-9.741328,0.040865,0.000000
101.790009,3.086601,-9.785810,0.017729,0.001613,0.040969,13.729888,0.699434,0.409692,-9.785810,0.041896,0.000000
102.410004,3.121231,-9.741328,0.017759,0.001640,0.041654,13.883929,0.707281,0.416535,-9.741328,0.042928,0.000000
103.030006,3.291405,-9.741328,0.017820,0.001694,0.043024,14.640900,0.745843,0.430237,-9.741328,0.043968,0.000000
103.650002,3.400879,-9.741328,0.017863,0.001734,0.044056,15.127865,0.770650,0.440562,-9.741328,0.045001,0.000000
104.270004,3.456367,-9.741328,0.017901,0.001767,0.044871,15.374690,0.783224,0.448707,-9.741328,0.046033,0.000000
104.890007,3.572174,-9.830290,0.017953,0.001810,0.045980,15.889824,0.809466,0.459804,-9.830290,0.047064,0.000000
105.510002,3.699898,-9.874771,0.018005,0.001854,0.047083,16.457968,0.838409,0.470826,-9.874771,0.048097,0.000000
106.130005,3.880501,-9.919252,0.018031,0.001892,0.048062,17.261330,0.879334,0.480621,-9.919252,0.049129,0.000000
106.750008,3.937843,-9.785810,0.018087,0.001935,0.049155,17.516401,0.892328,0.491552,-9.785810,0.050170,0.000000
107.370003,4.104668,-9.830290,0.018126,0.001981,0.050318,18.258474,0.930131,0.503179,-9.830290,0.051202,0.000000
107.990005,4.192917,-9.874771,0.018190,0.002011,0.051089,18.651026,0.950129,0.510885,-9.874771,0.052233,0.000000
108.610008,4.298302,-9.919252,0.018199,0.002056,0.052225,19.119801,0.974009,0.522255,-9.919252,0.053266,0.000000
109.230003,4.437569,-9.963733,0.018242,0.002092,0.053135,19.739292,1.005567,0.531354,-9.963733,0.054298,0.000000
109.850006,4.619659,-9.919252,0.018298,0.002135,0.054238,20.549271,1.046830,0.542375,-9.919252,0.055329,0.000000
110.470009,4.756317,-9.919252,0.018371,0.002181,0.055391,21.157156,1.077797,0.553912,-9.919252,0.056371,0.000000
111.090004,4.865791,-9.919252,0.018397,0.002217,0.056301,21.644121,1.102604,0.563011,-9.919252,0.057402,0.000000
111.710007,5.027405,-9.963733,0.018445,0.002258,0.057350,22.363014,1.139226,0.573502,-9.963733,0.058434,0.000000
112.330002,5.272057,-10.008214,0.018479,0.002306,0.058564,23.451279,1.194665,0.585644,-10.008214,0.059467,0.000000
112.950005,5.285461,-10.008214,0.018527,0.002340,0.059432,23.510906,1.197703,0.594319,-10.008214,0.060498,0.000000
113.570007,5.537926,-10.008214,0.018570,0.002382,0.060490,24.633924,1.254912,0.604902,-10.008214,0.061530,0.000000
114.190002,5.698044,-9.919252,0.018617,0.002426,0.061626,25.346165,1.291195,0.616257,-9.919252,0.062570,0.000000
114.810005,5.771774,-10.008214,0.018677,0.002461,0.062510,25.674135,1.307903,0.625098,-10.008214,0.063603,0.000000
115.430008,6.011215,-10.052695,0.018690,0.002504,0.063612,26.739222,1.362161,0.636120,-10.052695,0.064635,0.000000
116.050003,6.181015,-10.141657,0.018729,0.002547,0.064687,27.494528,1.400638,0.646869,-10.141657,0.065666,0.000000
116.670006,6.307251,-10.052695,0.018785,0.002585,0.065666,28.056053,1.429244,0.656664,-10.052695,0.066699,0.000000
117.290009,6.568283,-10.097176,0.018824,0.002623,0.066629,29.217182,1.488394,0.666293,-10.097176,0.067731,0.000000
117.910004,6.899323,-10.141657,0.018803,0.002670,0.067809,30.689720,1.563409,0.678087,-10.141657,0.068762,0.000000
118.530006,6.961510,-10.141657,0.018893,0.002706,0.068728,30.966341,1.577501,0.687276,-10.141657,0.069804,0.000000
119.150009,7.239296,-10.141657,0.018953,0.002749,0.069830,32.201996,1.640448,0.698298,-10.141657,0.070835,0.000000
119.770004,7.480591,-10.275100,0.018966,0.002787,0.070802,33.275330,1.695126,0.708018,-10.275100,0.071868,0.000000
120.390007,7.638855,-10.141657,0.019040,0.002829,0.071851,33.979324,1.730989,0.718509,-10.141657,0.072900,0.000000
121.010002,7.964310,-10.186138,0.019044,0.002873,0.072970,35.427017,1.804738,0.729697,-10.186138,0.073931,0.000000
121.630005,8.243210,-10.186138,0.019109,0.002910,0.073914,36.667629,1.867938,0.739145,-10.186138,0.074964,0.000000
122.250008,8.391045,-10.230618,0.019156,0.002954,0.075024,37.325230,1.901438,0.750242,-10.230618,0.076004,0.000000
122.870003,8.776077,-10.319581,0.019195,0.002999,0.076169,39.037941,1.988688,0.761687,-10.319581,0.077036,0.000000
123.490005,8.744423,-10.319581,0.019234,0.003023,0.076776,38.897137,1.981515,0.767758,-10.319581,0.078069,0.000000
124.110008,9.214363,-10.230618,0.019268,0.003076,0.078138,40.987534,2.088005,0.781384,-10.230618,0.079100,0.000000
124.730003,9.409111,-10.319581,0.019298,0.003113,0.079065,41.853817,2.132135,0.790649,-10.319581,0.080132,0.000000
125.350006,9.676102,-10.319581,0.019350,0.003151,0.080046,43.041451,2.192636,0.800460,-10.319581,0.081165,0.000000
125.970009,9.999321,-10.364061,0.019419,0.003197,0.081207,44.479202,2.265878,0.812072,-10.364061,0.082205,0.000000
126.590004,10.224236,-10.364061,0.019423,0.003235,0.082179,45.479671,2.316845,0.821792,-10.364061,0.083237,0.000000
127.210007,10.471115,-10.364061,0.019484,0.003274,0.083159,46.577847,2.372789,0.831587,-10.364061,0.084268,0.000000
127.830009,10.879982,-10.319581,0.019548,0.003320,0.084338,48.396576,2.465439,0.843381,-10.319581,0.085301,0.000000
128.450012,11.016273,-10.319581,0.019557,0.003356,0.085240,49.002831,2.496323,0.852404,-10.319581,0.086333,0.000000
129.070007,11.268364,-10.364061,0.019613,0.003397,0.086290,50.124187,2.553448,0.862895,-10.364061,0.087364,0.000000
129.690002,11.626213,-10.497504,0.019661,0.003440,0.087374,51.715981,2.634538,0.873735,-10.497504,0.088406,0.000000
130.310013,11.798256,-10.408543,0.019721,0.003478,0.088346,52.481262,2.673523,0.883455,-10.408543,0.089437,0.000000
130.930008,12.020561,-10.408543,0.019760,0.003518,0.089351,53.470127,2.723898,0.893508,-10.408543,0.090470,0.000000
131.550003,12.424957,-10.408543,0.019773,0.003563,0.090488,55.268970,2.815536,0.904878,-10.408543,0.091502,0.000000
132.170013,12.595871,-10.453024,0.019816,0.003598,0.091398,56.029232,2.854265,0.913976,-10.453024,0.092533,0.000000
132.790009,12.902336,-10.497504,0.019859,0.003640,0.092447,57.392456,2.923711,0.924468,-10.497504,0.093566,0.000000
133.410004,13.183853,-10.541986,0.019885,0.003682,0.093522,58.644707,2.987504,0.935217,-10.541986,0.094606,0.000000
134.029999,13.298912,-10.497504,0.019949,0.003723,0.094563,59.156517,3.013577,0.945633,-10.497504,0.095638,0.000000
134.650009,13.494781,-10.453024,0.019975,0.003756,0.095413,60.027786,3.057961,0.954127,-10.453024,0.096671,0.000000
135.270004,13.860077,-10.453024,0.020001,0.003803,0.096601,61.652702,3.140738,0.966011,-10.453024,0.097702,0.000000
135.889999,14.105103,-10.586467,0.020040,0.003846,0.097685,62.742630,3.196262,0.976851,-10.586467,0.098734,0.000000
136.510010,14.307297,-10.586467,0.020105,0.003886,0.098699,63.642033,3.242080,0.986995,-10.586467,0.099767,0.000000
137.130005,14.676689,-10.586467,0.020135,0.003929,0.099802,65.285172,3.325785,0.998016,-10.586467,0.100798,0.000000
137.750000,14.792870,-10.586467,0.020195,0.003968,0.100798,65.801971,3.352112,1.007978,-10.586467,0.101839,0.000000
138.370010,14.956718,-10.630947,0.020221,0.004005,0.101718,66.530807,3.389241,1.017183,-10.630947,0.102870,0.000000
138.990005,15.194664,-10.630947,0.020260,0.004040,0.102612,67.589241,3.443160,1.026115,-10.630947,0.103903,0.000000
139.610001,15.582298,-10.675428,0.020294,0.004090,0.103886,69.313522,3.530999,1.038863,-10.675428,0.104935,0.000000
140.230011,15.741676,-10.630947,0.020346,0.004127,0.104831,70.022476,3.567115,1.048310,-10.630947,0.105966,0.000000
140.850006,15.883926,-10.630947,0.020381,0.004162,0.105715,70.655235,3.599349,1.057151,-10.630947,0.106999,0.000000
141.470001,16.401520,-10.675428,0.020419,0.004215,0.107050,72.957603,3.716638,1.070505,-10.675428,0.108039,0.000000
142.090012,16.582863,-10.719910,0.020445,0.004253,0.108022,73.764259,3.757730,1.080224,-10.719910,0.109072,0.000000
142.710007,16.707985,-10.764390,0.020506,0.004289,0.108932,74.320831,3.786083,1.089323,-10.764390,0.110104,0.000000
143.330002,17.136581,-10.764390,0.020527,0.004339,0.110216,76.227318,3.883205,1.102161,-10.764390,0.111135,0.000000
143.950012,17.237869,-10.764390,0.020587,0.004377,0.111179,76.677872,3.906157,1.111790,-10.764390,0.112168,0.000000
144.570007,17.393890,-10.719910,0.020618,0.004414,0.112116,77.371887,3.941512,1.121162,-10.719910,0.113200,0.000000
145.190002,17.908516,-10.764390,0.020656,0.004459,0.113252,79.661057,4.058128,1.132516,-10.764390,0.114240,0.000000
145.810013,18.022087,-10.853352,0.020669,0.004500,0.114292,80.166245,4.083863,1.142917,-10.853352,0.115273,0.000000
146.430008,18.188538,-10.853352,0.020725,0.004536,0.115212,80.906654,4.121582,1.152122,-10.853352,0.116304,0.000000
147.050003,18.747093,-10.853352,0.020764,0.004584,0.116426,83.391235,4.248152,1.164264,-10.853352,0.117336,0.000000
147.670013,18.696449,-10.808871,0.020816,0.004617,0.117267,83.165962,4.236676,1.172666,-10.808871,0.118369,0.000000
148.290009,19.062492,-10.808871,0.020881,0.004662,0.118404,84.794205,4.319623,1.184036,-10.808871,0.119400,0.000000
148.910004,19.119843,-10.808871,0.020885,0.004695,0.119244,85.049309,4.332618,1.192439,-10.808871,0.120441,0.000000
149.530014,19.488861,-10.897833,0.020963,0.004741,0.120432,86.690781,4.416239,1.204323,-10.897833,0.121472,0.000000
150.150009,19.727554,-10.897833,0.020984,0.004784,0.121516,87.752541,4.470328,1.215163,-10.897833,0.122505,0.000000
150.770004,19.905922,-10.853352,0.021019,0.004818,0.122375,88.545959,4.510746,1.223747,-10.853352,0.123537,0.000000
151.390015,20.236588,-10.897833,0.021075,0.004863,0.123528,90.016838,4.585676,1.235284,-10.897833,0.124568,0.000000
152.010010,20.381813,-10.942314,0.021079,0.004901,0.124491,90.662834,4.618585,1.244913,-10.942314,0.125601,0.000000
152.630005,20.534111,-11.031276,0.021118,0.004933,0.125289,91.340286,4.653096,1.252891,-11.031276,0.126641,0.000000
153.250000,20.891586,-10.986794,0.021191,0.004979,0.126468,92.930420,4.734101,1.264685,-10.986794,0.127674,0.000000
153.870010,21.070328,-10.942314,0.021195,0.005017,0.127431,93.725502,4.774604,1.274314,-10.942314,0.128706,0.000000
154.490005,21.293747,-10.897833,0.021273,0.005057,0.128446,94.719315,4.825232,1.284457,-10.897833,0.129737,0.000000
155.110001,21.766663,-10.986794,0.021282,0.005105,0.129669,96.822952,4.932396,1.296690,-10.986794,0.130770,0.000000
155.730011,21.983383,-11.075757,0.021308,0.005146,0.130700,97.786972,4.981506,1.307000,-11.075757,0.131802,0.000000
156.350006,22.126373,-11.075757,0.021385,0.005182,0.131611,98.423027,5.013908,1.316114,-11.075757,0.132842,0.000000
156.970001,22.519226,-11.075757,0.021415,0.005231,0.132860,100.170517,5.102930,1.328604,-11.075757,0.133875,0.000000
157.590012,22.619766,-11.031276,0.021458,0.005265,0.133719,100.617744,5.125712,1.337188,-11.031276,0.134906,0.000000
158.210007,22.985809,-11.075757,0.021484,0.005309,0.134838,102.245987,5.208659,1.348376,-11.075757,0.135938,0.000000
158.830002,23.375313,-11.120237,0.021523,0.005356,0.136043,103.978584,5.296922,1.360427,-11.120237,0.136971,0.000000
159.450012,23.447556,-11.075757,0.021562,0.005392,0.136953,104.299934,5.313292,1.369526,-11.075757,0.138002,0.000000
160.070007,23.673210,-11.120237,0.021618,0.005427,0.137855,105.303696,5.364426,1.378550,-11.120237,0.139034,0.000000
160.690002,24.249268,-11.120237,0.021644,0.005476,0.139078,107.866127,5.494962,1.390782,-11.120237,0.140074,0.000000
161.310013,24.245544,-11.120237,0.021687,0.005511,0.139971,107.849571,5.494119,1.399715,-11.120237,0.141107,0.000000
161.930008,24.543816,-11.209200,0.021730,0.005553,0.141046,109.176346,5.561708,1.410464,-11.209200,0.142139,0.000000
162.550003,24.858475,-11.209200,0.021765,0.005593,0.142061,110.576019,5.633011,1.420607,-11.209200,0.143170,0.000000
163.170013,24.945236,-11.209200,0.021825,0.005630,0.142998,110.961952,5.652671,1.429979,-11.209200,0.144203,0.000000
163.790009,25.279625,-11.164719,0.021851,0.005676,0.144159,112.449387,5.728445,1.441591,-11.164719,0.145235,0.000000
164.410004,25.788284,-11.209200,0.021898,0.005720,0.145278,114.712021,5.843709,1.452779,-11.209200,0.146276,0.000000
165.030014,25.726097,-11.253680,0.021915,0.005759,0.146267,114.435394,5.829617,1.462665,-11.253680,0.147308,0.000000
165.650009,26.323761,-11.253680,0.021967,0.005805,0.147438,117.093941,5.965049,1.474383,-11.253680,0.148339,0.000000
166.270004,26.193428,-11.342643,0.022019,0.005830,0.148088,116.514191,5.935515,1.480878,-11.342643,0.149372,0.000000
166.890015,26.660385,-11.209200,0.022058,0.005883,0.149432,118.591316,6.041330,1.494322,-11.209200,0.150404,0.000000
167.510010,26.983231,-11.253680,0.022088,0.005924,0.150481,120.027405,6.114487,1.504814,-11.253680,0.151435,0.000000
168.130005,26.943016,-11.298162,0.022097,0.005952,0.151175,119.848518,6.105375,1.511748,-11.298162,0.152477,0.000000
168.750015,27.454277,-11.342643,0.022161,0.005999,0.152372,122.122726,6.221228,1.523723,-11.342643,0.153508,0.000000
169.370010,27.771545,-11.476086,0.022174,0.006038,0.153370,123.534004,6.293122,1.533700,-11.476086,0.154540,0.000000
169.990005,27.866867,-11.342643,0.022243,0.006076,0.154333,123.958015,6.314722,1.543329,-11.342643,0.155573,0.000000
170.610001,28.291374,-11.342643,0.022273,0.006123,0.155529,125.846321,6.410917,1.555289,-11.342643,0.156604,0.000000
171.230011,28.710663,-11.387123,0.022321,0.006168,0.156673,127.711403,6.505929,1.566735,-11.387123,0.157636,0.000000
171.850006,28.658905,-11.387123,0.022355,0.006200,0.157480,127.481178,6.494201,1.574804,-11.387123,0.158676,0.000000
172.470001,29.275185,-11.431604,0.022385,0.006249,0.158729,130.222519,6.633852,1.587294,-11.431604,0.159709,0.000000
173.090012,29.303108,-11.476086,0.022446,0.006284,0.159623,130.346741,6.640179,1.596226,-11.476086,0.160741,0.000000
173.710007,29.494141,-11.387123,0.022437,0.006321,0.160558,131.196487,6.683468,1.605583,-11.387123,0.161772,0.000000
174.330002,30.120094,-11.476086,0.022506,0.006370,0.161800,133.980865,6.825311,1.617997,-11.476086,0.162805,0.000000
174.950012,30.007637,-11.476086,0.022549,0.006402,0.162623,133.480637,6.799828,1.626233,-11.476086,0.163838,0.000000
175.570007,30.574760,-11.520566,0.022575,0.006447,0.163742,136.003326,6.928340,1.637421,-11.520566,0.164878,0.000000
176.190002,30.930008,-11.565047,0.022623,0.006489,0.164826,137.583542,7.008840,1.648261,-11.565047,0.165910,0.000000
176.810013,30.957558,-11.476086,0.022674,0.006525,0.165727,137.706100,7.015083,1.657269,-11.476086,0.166941,0.000000
177.430008,31.334030,-11.476086,0.022713,0.006566,0.166785,139.380722,7.100393,1.667852,-11.476086,0.167974,0.000000
178.050003,31.966690,-11.565047,0.022739,0.006612,0.167948,142.194946,7.243756,1.679479,-11.565047,0.169006,0.000000
178.670013,31.769333,-11.520566,0.022791,0.006648,0.168867,141.317047,7.199033,1.688669,-11.520566,0.170037,0.000000
179.290009,32.143936,-11.609529,0.022808,0.006689,0.169899,142.983368,7.283920,1.698994,-11.609529,0.171079,0.000000
179.910004,32.445190,-11.565047,0.022838,0.006730,0.170939,144.323410,7.352185,1.709395,-11.565047,0.172110,0.000000
180.530014,32.770645,-11.609529,0.022911,0.006773,0.172023,145.771103,7.425934,1.720235,-11.609529,0.173142,0.000000
181.150009,33.122910,-11.609529,0.022937,0.006813,0.173038,147.338058,7.505758,1.730378,-11.609529,0.174175,0.000000
181.770004,32.996300,-11.698490,0.022980,0.006839,0.173705,146.774872,7.477068,1.737055,-11.698490,0.175206,0.000000
182.390015,33.778656,-11.698490,0.023024,0.006894,0.175110,150.254959,7.654353,1.751104,-11.698490,0.176238,0.000000
183.010010,34.240395,-11.698490,0.023067,0.006937,0.176194,152.308884,7.758984,1.761944,-11.698490,0.177271,0.000000
183.630005,34.038574,-11.654009,0.023110,0.006968,0.176992,151.411133,7.713251,1.769923,-11.654009,0.178311,0.000000
184.250015,34.770653,-11.698490,0.023131,0.007018,0.178267,154.667587,7.879142,1.782670,-11.698490,0.179343,0.000000
184.870010,34.979553,-11.698490,0.023170,0.007059,0.179290,155.596817,7.926480,1.792905,-11.698490,0.180374,0.000000
185.490005,34.881622,-11.742971,0.023205,0.007087,0.180002,155.161209,7.904289,1.800020,-11.742971,0.181407,0.000000
186.110016,35.662483,-11.698490,0.023269,0.007143,0.181424,158.634644,8.081234,1.814236,-11.698490,0.182440,0.000000
186.730011,35.717598,-11.698490,0.023312,0.007177,0.182291,158.879807,8.093723,1.822911,-11.698490,0.183471,0.000000
187.350006,35.940277,-11.787452,0.023304,0.007215,0.183272,159.870331,8.144183,1.832722,-11.787452,0.184512,0.000000
187.970016,36.564369,-11.831933,0.023364,0.007259,0.184382,162.646439,8.285604,1.843819,-11.831933,0.185543,0.000000
188.590012,36.721512,-11.742971,0.023424,0.007300,0.185413,163.345444,8.321214,1.854129,-11.742971,0.186576,0.000000
189.210007,37.048088,-11.787452,0.023429,0.007341,0.186471,164.798126,8.395216,1.864712,-11.787452,0.187608,0.000000
189.830002,37.632706,-11.742971,0.023468,0.007386,0.187616,167.398636,8.527694,1.876157,-11.742971,0.188639,0.000000
190.450012,37.634201,-11.831933,0.023519,0.007421,0.188483,167.405289,8.528031,1.884832,-11.831933,0.189672,0.000000
191.070007,38.114189,-11.876414,0.023554,0.007465,0.189602,169.540375,8.636799,1.896020,-11.876414,0.190712,0.000000
191.690002,38.593803,-11.920895,0.023606,0.007506,0.190644,171.673813,8.745481,1.906436,-11.920895,0.191744,0.000000
192.310013,38.547256,-11.920895,0.023636,0.007541,0.191554,171.466766,8.734934,1.915535,-11.920895,0.192777,0.000000
192.930008,38.909576,-11.876414,0.023687,0.007584,0.192628,173.078445,8.817036,1.926284,-11.876414,0.193808,0.000000
193.550003,39.220131,-11.876414,0.023718,0.007624,0.193643,174.459854,8.887409,1.936428,-11.876414,0.194840,0.000000
194.170013,39.498299,-11.876414,0.023756,0.007667,0.194745,175.697205,8.950442,1.947450,-11.876414,0.195873,0.000000
194.790009,40.036743,-11.965376,0.023782,0.007707,0.195768,178.092331,9.072456,1.957684,-11.965376,0.196913,0.000000
195.410004,40.108238,-11.965376,0.023821,0.007742,0.196643,178.410355,9.088656,1.966435,-11.965376,0.197945,0.000000
196.030014,40.407631,-11.965376,0.023881,0.007783,0.197685,179.742126,9.156501,1.976851,-11.965376,0.198976,0.000000
196.650009,40.952034,-12.009857,0.023916,0.007826,0.198778,182.163742,9.279863,1.987781,-12.009857,0.200009,0.000000
197.270004,41.020927,-11.965376,0.023912,0.007861,0.199662,182.470200,9.295475,1.996623,-11.965376,0.201042,0.000000
197.890015,41.387344,-12.009857,0.023976,0.007908,0.200858,184.100098,9.378507,2.008583,-12.009857,0.202073,0.000000
198.510010,41.662895,-12.054338,0.024024,0.007945,0.201805,185.325821,9.440947,2.018045,-12.054338,0.203114,0.000000
199.130005,41.964516,-12.054338,0.024063,0.007982,0.202740,186.667496,9.509295,2.027402,-12.054338,0.204145,0.000000
199.750015,42.544678,-12.054338,0.024093,0.008034,0.204059,189.248184,9.640762,2.040588,-12.054338,0.205178,0.000000
200.370010,42.743523,-12.054338,0.024140,0.008069,0.204952,190.132690,9.685821,2.049521,-12.054338,0.206210,0.000000
200.990005,43.120361,-12.054338,0.024153,0.008109,0.205966,191.808945,9.771214,2.059664,-12.054338,0.207241,0.000000
201.610016,43.754143,-12.098819,0.024192,0.008159,0.207234,194.628143,9.914830,2.072336,-12.098819,0.208274,0.000000
202.230011,43.843140,-12.143300,0.024201,0.008194,0.208127,195.024033,9.934998,2.081268,-12.143300,0.209314,0.000000
202.850006,44.139175,-12.143300,0.024278,0.008231,0.209055,196.340851,10.002080,2.090549,-12.143300,0.210346,0.000000
203.470016,44.671295,-12.143300,0.024321,0.008273,0.210146,198.707840,10.122661,2.101465,-12.143300,0.211379,0.000000
204.090012,44.741302,-12.143300,0.024369,0.008313,0.211153,199.019257,10.138524,2.111532,-12.143300,0.212410,0.000000
204.710007,45.276772,-12.232262,0.024403,0.008355,0.212219,201.401138,10.259864,2.122191,-12.232262,0.213442,0.000000
205.330017,45.773148,-12.232262,0.024425,0.008398,0.213321,203.609131,10.372344,2.133212,-12.232262,0.214475,0.000000
205.950012,46.059868,-12.143300,0.024485,0.008436,0.214275,204.884521,10.437316,2.142750,-12.143300,0.215506,0.000000
206.570007,46.244568,-12.232262,0.024489,0.008476,0.215280,205.706116,10.479169,2.152803,-12.232262,0.216547,0.000000
207.190002,47.052986,-12.232262,0.024524,0.008521,0.216443,209.302139,10.662359,2.164430,-12.232262,0.217578,0.000000
207.810013,47.160973,-12.276743,0.024567,0.008562,0.217476,209.782486,10.686830,2.174755,-12.276743,0.218611,0.000000
208.430008,47.691231,-12.276743,0.024614,0.008604,0.218550,212.141190,10.806988,2.185504,-12.276743,0.219644,0.000000
209.050003,47.553825,-12.276743,0.024614,0.008631,0.219218,211.529984,10.775850,2.192181,-12.276743,0.220675,0.000000
209.670013,48.460182,-12.276743,0.024662,0.008686,0.220632,215.561661,10.981234,2.206321,-12.276743,0.221707,0.000000
210.290009,48.930489,-12.276743,0.024701,0.008727,0.221656,217.653687,11.087808,2.216556,-12.276743,0.222747,0.000000
210.910004,48.552902,-12.321223,0.024727,0.008752,0.222288,215.974091,11.002245,2.222884,-12.321223,0.223780,0.000000
211.530014,49.299515,-12.365705,0.024770,0.008801,0.223554,219.295197,11.171430,2.235541,-12.365705,0.224812,0.000000
212.150009,49.867378,-12.321223,0.024817,0.008843,0.224612,221.821182,11.300110,2.246123,-12.321223,0.225843,0.000000
212.770004,49.866264,-12.365705,0.024856,0.008881,0.225575,221.816223,11.299857,2.255752,-12.365705,0.226876,0.000000
213.390015,50.598717,-12.365705,0.024886,0.008926,0.226729,225.074326,11.465834,2.267288,-12.365705,0.227908,0.000000
214.010010,51.221329,-12.365705,0.024929,0.008972,0.227881,227.843857,11.606919,2.278810,-12.365705,0.228948,0.000000
214.630005,50.969604,-12.410186,0.024985,0.008997,0.228523,226.724121,11.549877,2.285229,-12.410186,0.229981,0.000000
215.250015,51.766853,-12.410186,0.025020,0.009048,0.229816,230.270462,11.730536,2.298158,-12.410186,0.231012,0.000000
215.870010,51.935905,-12.410186,0.025041,0.009084,0.230735,231.022446,11.768845,2.307348,-12.410186,0.232044,0.000000
216.490005,52.316849,-12.410186,0.025089,0.009124,0.231749,232.716965,11.855167,2.317491,-12.410186,0.233077,0.000000
217.110016,53.167343,-12.454666,0.025106,0.009171,0.232954,236.500153,12.047893,2.329542,-12.454666,0.234108,0.000000
217.730011,53.088028,-12.499147,0.025162,0.009207,0.233866,236.147339,12.029919,2.338656,-12.499147,0.235149,0.000000
218.350006,53.765747,-12.454666,0.025214,0.009250,0.234959,239.161987,12.183493,2.349587,-12.454666,0.236180,0.000000
218.970016,54.439743,-12.499147,0.025244,0.009296,0.236112,242.160065,12.336223,2.361124,-12.499147,0.237213,0.000000
219.590012,54.544006,-12.499147,0.025278,0.009332,0.237031,242.623856,12.359848,2.370313,-12.499147,0.238246,0.000000
220.210007,55.076500,-12.499147,0.025326,0.009374,0.238097,244.992508,12.480513,2.380971,-12.499147,0.239277,0.000000
220.830017,55.584038,-12.543628,0.025334,0.009417,0.239181,247.250153,12.595523,2.391811,-12.543628,0.240309,0.000000
221.450012,55.655533,-12.588109,0.025395,0.009453,0.240100,247.568176,12.611724,2.401001,-12.588109,0.241349,0.000000
222.070007,56.536942,-12.588109,0.025438,0.009499,0.241272,251.488876,12.811454,2.412719,-12.588109,0.242382,0.000000
222.690018,56.782333,-12.588109,0.025442,0.009538,0.242261,252.580429,12.867061,2.422605,-12.588109,0.243414,0.000000
223.310013,56.989006,-12.632590,0.025485,0.009576,0.243231,253.499756,12.913894,2.432310,-12.632590,0.244445,0.000000
223.930008,57.588898,-12.677071,0.025520,0.009615,0.244220,256.168213,13.049831,2.442196,-12.677071,0.245478,0.000000
224.550003,58.188789,-12.677071,0.025572,0.009653,0.245192,258.836670,13.185768,2.451916,-12.677071,0.246510,0.000000
225.170013,58.551849,-12.632590,0.025615,0.009697,0.246301,260.451630,13.268039,2.463013,-12.632590,0.247550,0.000000
225.790009,59.073540,-12.632590,0.025645,0.009740,0.247403,262.772217,13.386255,2.474035,-12.632590,0.248583,0.000000
226.410004,59.700249,-12.677071,0.025671,0.009779,0.248392,265.559967,13.528270,2.483921,-12.677071,0.249614,0.000000
227.030014,59.864090,-12.677071,0.025701,0.009818,0.249388,266.288757,13.565397,2.493882,-12.677071,0.250646,0.000000
227.650009,60.450203,-12.721552,0.025727,0.009862,0.250490,268.895935,13.698212,2.504904,-12.721552,0.251679,0.000000
228.270004,61.184525,-12.632590,0.025779,0.009902,0.251505,272.162354,13.864612,2.515048,-12.632590,0.252710,0.000000
228.890015,61.573280,-12.677071,0.025835,0.009945,0.252607,273.891632,13.952704,2.526069,-12.677071,0.253742,0.000000
229.510010,61.884956,-12.721552,0.025860,0.009988,0.253698,275.278046,14.023332,2.536985,-12.721552,0.254782,0.000000
230.130005,61.941185,-12.810513,0.025895,0.010015,0.254375,275.528137,14.036074,2.543752,-12.810513,0.255815,0.000000
230.750015,63.261238,-12.810513,0.025942,0.010068,0.255729,281.400055,14.335202,2.557287,-12.810513,0.256848,0.000000
231.370010,63.318596,-12.721552,0.025990,0.010103,0.256622,281.655182,14.348199,2.566219,-12.721552,0.257879,0.000000
231.990005,63.777718,-12.810513,0.026024,0.010143,0.257636,283.697449,14.452237,2.576363,-12.810513,0.258911,0.000000
232.610016,64.730247,-12.854995,0.026042,0.010190,0.258816,287.934509,14.668084,2.588157,-12.854995,0.259944,0.000000
233.230011,64.876595,-12.810513,0.026076,0.010224,0.259691,288.585510,14.701246,2.596907,-12.810513,0.260984,0.000000
233.850006,65.521538,-12.854995,0.026141,0.010268,0.260802,291.454346,14.847392,2.608020,-12.854995,0.262016,0.000000
234.470016,66.414497,-12.810513,0.026149,0.010313,0.261956,295.426453,15.049740,2.619556,-12.810513,0.263047,0.000000
235.090012,66.551521,-12.899476,0.026197,0.010349,0.262875,296.035950,15.080791,2.628746,-12.899476,0.264080,0.000000
235.710007,67.061684,-12.899476,0.026227,0.010390,0.263898,298.305267,15.196394,2.638980,-12.899476,0.265112,0.000000
236.330017,66.750374,-12.943956,0.026274,0.010397,0.264089,296.920502,15.125851,2.640888,-12.943956,0.264445,0.000000
236.950012,65.880882,-12.899476,0.026283,0.010389,0.263871,293.052795,14.928821,2.638708,-12.899476,0.264089,0.000000
237.570007,65.386742,-12.899476,0.026300,0.010389,0.263871,290.854767,14.816847,2.638708,-12.899476,0.264089,0.000000
238.190018,65.030006,-12.988438,0.026287,0.010389,0.263871,289.267914,14.736011,2.638708,-12.988438,0.264089,0.000000
238.810013,64.738823,-12.988438,0.026318,0.010389,0.263871,287.972656,14.670027,2.638708,-12.988438,0.264089,0.000000
239.430008,64.501244,-12.988438,0.026318,0.010388,0.263863,286.915863,14.616191,2.638632,-12.988438,0.264089,0.000000
240.050018,64.286751,-12.988438,0.026296,0.010388,0.263863,285.961761,14.567586,2.638632,-12.988438,0.264089,0.000000
240.670013,64.112862,-12.988438,0.026305,0.010388,0.263863,285.188263,14.528183,2.638632,-12.988438,0.264089,0.000000
241.290009,63.969124,-13.032919,0.026318,0.010388,0.263863,284.548889,14.495611,2.638632,-13.032919,0.264089,0.000000
241.910019,63.828743,-13.032919,0.026292,0.010388,0.263863,283.924438,14.463800,2.638632,-13.032919,0.264089,0.000000
242.530014,63.715172,-13.077399,0.026305,0.010388,0.263863,283.419250,14.438065,2.638632,-13.077399,0.264089,0.000000
243.150009,63.614632,-13.032919,0.026313,0.010388,0.263863,282.972015,14.415281,2.638632,-13.032919,0.264089,0.000000
243.770004,63.513710,-13.077399,0.026300,0.010388,0.263863,282.523102,14.392412,2.638632,-13.077399,0.264089,0.000000
244.390015,63.410942,-13.077399,0.026318,0.010388,0.263863,282.065948,14.369125,2.638632,-13.077399,0.264089,0.000000
245.010010,63.334969,-13.121881,0.026292,0.010388,0.263863,281.727997,14.351909,2.638632,-13.121881,0.264089,0.000000
245.630005,63.250069,-13.121881,0.026296,0.010388,0.263863,281.350372,14.332671,2.638632,-13.121881,0.264089,0.000000
246.250015,63.170006,-13.121881,0.026296,0.010388,0.263863,280.994232,14.314528,2.638632,-13.121881,0.264089,0.000000
246.870010,63.113045,-13.166362,0.026305,0.010388,0.263863,280.740845,14.301620,2.638632,-13.166362,0.264089,0.000000
247.490005,63.040794,-13.077399,0.026305,0.010388,0.263863,280.419464,14.285248,2.638632,-13.077399,0.264089,0.000000
248.110016,62.986435,-13.210842,0.026296,0.010388,0.263863,280.177643,14.272930,2.638632,-13.210842,0.264089,0.000000
248.730011,62.923126,-13.210842,0.026309,0.010388,0.263863,279.896057,14.258585,2.638632,-13.210842,0.264089,0.000000
249.350006,62.881798,-13.210842,0.026313,0.010388,0.263863,279.712219,14.249219,2.638632,-13.210842,0.264089,0.000000
249.970016,62.825195,-13.166362,0.026296,0.010388,0.263863,279.460419,14.236392,2.638632,-13.166362,0.264089,0.000000
250.590012,62.752953,-13.210842,0.026318,0.010388,0.263863,279.139069,14.220022,2.638632,-13.210842,0.264089,0.000000
251.210007,62.706406,-13.255323,0.026335,0.010388,0.263863,278.932037,14.209475,2.638632,-13.255323,0.264089,0.000000
251.830017,62.659119,-13.255323,0.026330,0.010388,0.263863,278.721680,14.198760,2.638632,-13.255323,0.264089,0.000000
252.450012,62.614433,-13.210842,0.026322,0.010388,0.263863,278.522919,14.188634,2.638632,-13.210842,0.264089,0.000000
253.070007,62.573845,-13.344285,0.026300,0.010388,0.263863,278.342377,14.179437,2.638632,-13.344285,0.264089,0.000000
253.690018,62.535492,-13.299805,0.026335,0.010388,0.263863,278.171753,14.170746,2.638632,-13.299805,0.264089,0.000000
254.310013,62.509422,-13.344285,0.026326,0.010388,0.263863,278.055786,14.164837,2.638632,-13.344285,0.264089,0.000000
254.930008,62.461761,-13.344285,0.026309,0.010388,0.263863,277.843781,14.154037,2.638632,-13.344285,0.264089,0.000000
255.550018,62.430481,-13.344285,0.026322,0.010388,0.263863,277.704651,14.146949,2.638632,-13.344285,0.264089,0.000000
256.170013,62.389893,-13.344285,0.026326,0.010388,0.263863,277.524109,14.137752,2.638632,-13.344285,0.264089,0.000000
256.790009,62.358612,-13.344285,0.026322,0.010388,0.263863,277.384949,14.130663,2.638632,-13.344285,0.264089,0.000000
257.410004,62.316162,-13.433248,0.026313,0.010388,0.263863,277.196136,14.121044,2.638632,-13.433248,0.264089,0.000000
258.029999,62.276321,-13.433248,0.026326,0.010388,0.263863,277.018921,14.112017,2.638632,-13.433248,0.264089,0.000000
258.650024,62.270363,-13.433248,0.026335,0.010388,0.263863,276.992401,14.110666,2.638632,-13.433248,0.264089,0.000000
259.270020,62.230515,-13.344285,0.026348,0.010388,0.263863,276.815155,14.101636,2.638632,-13.344285,0.264089,0.000000
259.890015,62.193649,-13.433248,0.026330,0.010388,0.263863,276.651184,14.093282,2.638632,-13.433248,0.264089,0.000000
260.510010,62.166840,-13.522209,0.026309,0.010388,0.263863,276.531921,14.087207,2.638632,-13.522209,0.264089,0.000000
261.130005,62.135559,-13.522209,0.026326,0.010388,0.263863,276.392761,14.080119,2.638632,-13.522209,0.264089,0.000000
261.750000,62.115456,-13.477728,0.026309,0.010388,0.263863,276.303345,14.075563,2.638632,-13.477728,0.264089,0.000000
262.370026,62.090508,-13.566690,0.026335,0.010388,0.263863,276.192383,14.069911,2.638632,-13.566690,0.264089,0.000000
262.990021,62.060715,-13.433248,0.026309,0.010388,0.263863,276.059845,14.063159,2.638632,-13.433248,0.264089,0.000000
263.610016,62.042839,-13.522209,0.026318,0.010388,0.263863,275.980347,14.059108,2.638632,-13.522209,0.264089,0.000000
264.230011,62.016029,-13.566690,0.026300,0.010388,0.263863,275.861084,14.053033,2.638632,-13.566690,0.264089,0.000000
264.850006,61.995552,-13.566690,0.026326,0.010388,0.263863,275.769989,14.048393,2.638632,-13.566690,0.264089,0.000000
265.470001,61.963524,-13.522209,0.026335,0.010388,0.263863,275.627533,14.041135,2.638632,-13.522209,0.264089,0.000000
266.090027,61.939697,-13.566690,0.026335,0.010388,0.263863,275.521545,14.035736,2.638632,-13.566690,0.264089,0.000000
266.500000,61.915863,-13.611171,0.026326,0.010388,0.263863,275.415527,14.030335,2.638632,-13.611171,0.264089,0.000000