File: Data/New pin I-18-6_08172023_171616.csv
Time (sec),S:Load (lbs),S:HL1 (DIM),S:LVDT (in),S:Position (in),Ch:Position (mm),Ch:Load (N),Ch:Stress (MPa),Ch:Strain (mm/mm),Ch:HL1 (DIM),Set Point (),Cycles ()
0.010000,-0.002979,-110.312759,-0.001884,-0.010143,-0.257626,-0.013251,-0.000675,-2.576257,-110.312759,-0.257558,0.000000
0.220000,-0.018619,-110.312759,-0.001893,-0.010143,-0.257626,-0.082820,-0.004219,-2.576257,-110.312759,-0.257558,0.000000
0.430000,-0.031279,-110.179314,-0.001888,-0.010098,-0.256490,-0.139137,-0.007088,-2.564902,-110.179314,-0.255962,0.000000
0.640000,-0.016012,-110.268280,-0.001876,-0.009972,-0.253282,-0.071225,-0.003628,-2.532821,-110.268280,-0.252475,0.000000
0.850000,0.006703,-110.268280,-0.001871,-0.009843,-0.250003,0.029815,0.001519,-2.500029,-110.268280,-0.248972,0.000000
1.060000,0.033886,-110.312759,-0.001772,-0.009709,-0.246621,0.150732,0.007679,-2.466207,-110.312759,-0.245469,0.000000
1.270000,0.031652,-110.223793,-0.001638,-0.009565,-0.242961,0.140793,0.007172,-2.429615,-110.223793,-0.241964,0.000000
1.480000,0.042450,-110.312759,-0.001466,-0.009426,-0.239414,0.188829,0.009619,-2.394143,-110.312759,-0.238479,0.000000
1.690000,0.028673,-110.268280,-0.001332,-0.009289,-0.235946,0.127542,0.006497,-2.359458,-110.268280,-0.234974,0.000000
1.900000,0.025321,-110.223793,-0.001199,-0.009156,-0.232573,0.112635,0.005738,-2.325727,-110.223793,-0.231471,0.000000
2.110000,0.027183,-110.223793,-0.001056,-0.009017,-0.229025,0.120917,0.006160,-2.290255,-110.223793,-0.227984,0.000000
2.320000,0.023087,-110.223793,-0.000931,-0.008882,-0.225608,0.102696,0.005232,-2.256085,-110.223793,-0.224481,0.000000
2.530000,0.024204,-110.223793,-0.000785,-0.008746,-0.222148,0.107666,0.005485,-2.221476,-110.223793,-0.220977,0.000000
2.740000,0.021225,-110.312759,-0.000647,-0.008607,-0.218628,0.094414,0.004810,-2.186276,-110.312759,-0.217474,0.000000
2.950000,0.027183,-110.179314,-0.000461,-0.008467,-0.215062,0.120917,0.006160,-2.150623,-110.179314,-0.213987,0.000000
3.160000,0.062186,-110.179314,-0.000354,-0.008336,-0.211724,0.276618,0.014092,-2.117240,-110.179314,-0.210484,0.000000
3.370000,0.049898,-110.179314,-0.000216,-0.008193,-0.208107,0.221957,0.011307,-2.081072,-110.179314,-0.206981,0.000000
3.580000,0.066282,-110.223793,-0.000043,-0.008054,-0.204578,0.294838,0.015020,-2.045781,-110.223793,-0.203494,0.000000
3.790000,0.059207,-110.223793,0.000056,-0.007915,-0.201031,0.263367,0.013417,-2.010309,-110.223793,-0.199991,0.000000
4.000000,0.049525,-110.179314,0.000237,-0.007774,-0.197467,0.220300,0.011223,-1.974671,-110.179314,-0.196488,0.000000
4.210000,0.023832,-110.223793,0.000388,-0.007643,-0.194120,0.106009,0.005400,-1.941197,-110.223793,-0.193001,0.000000
4.420000,0.008192,-110.179314,0.000526,-0.007503,-0.190582,0.036441,0.001856,-1.905816,-110.179314,-0.189498,0.000000
4.630000,-0.000745,-110.179314,0.000647,-0.007366,-0.187095,-0.003313,-0.000169,-1.870949,-110.179314,-0.185994,0.000000
4.840000,0.003351,-110.179314,0.000780,-0.007231,-0.183661,0.014907,0.000759,-1.836613,-110.179314,-0.182489,0.000000
5.050000,0.024204,-110.179314,0.000936,-0.007090,-0.180088,0.107666,0.005485,-1.800883,-110.179314,-0.179004,0.000000
5.260000,0.057718,-110.179314,0.001074,-0.006953,-0.176618,0.256741,0.013079,-1.766183,-110.179314,-0.175500,0.000000
5.470000,0.050270,-110.090355,0.001220,-0.006816,-0.173133,0.223613,0.011391,-1.731332,-110.090355,-0.171996,0.000000
5.680000,0.077453,-110.134834,0.001375,-0.006681,-0.169690,0.344530,0.017551,-1.696905,-110.134834,-0.168510,0.000000
5.890000,0.058835,-110.134834,0.001526,-0.006549,-0.166351,0.261710,0.013332,-1.663507,-110.134834,-0.165006,0.000000
6.100000,0.043568,-110.134834,0.001664,-0.006400,-0.162552,0.193798,0.009873,-1.625522,-110.134834,-0.161503,0.000000
6.310000,0.041706,-110.179314,0.001798,-0.006259,-0.158970,0.185516,0.009451,-1.589701,-110.179314,-0.158000,0.000000
6.520000,0.046547,-110.090355,0.001957,-0.006122,-0.155493,0.207049,0.010548,-1.554926,-110.090355,-0.154513,0.000000
6.730000,0.002979,-110.134834,0.002082,-0.005986,-0.152033,0.013251,0.000675,-1.520332,-110.134834,-0.151010,0.000000
6.940001,-0.000000,-110.134834,0.002225,-0.005852,-0.148642,-0.000000,-0.000000,-1.486419,-110.134834,-0.147506,0.000000
7.150001,-0.009309,-110.045876,0.002376,-0.005715,-0.145155,-0.041410,-0.002110,-1.451553,-110.045876,-0.144020,0.000000
7.360000,0.001117,-110.134834,0.002492,-0.005578,-0.141687,0.004969,0.000253,-1.416868,-110.134834,-0.140516,0.000000
7.570000,0.036120,-110.001389,0.002634,-0.005435,-0.138037,0.160670,0.008185,-1.380366,-110.001389,-0.137013,0.000000
7.780000,0.040961,-110.134834,0.002824,-0.005297,-0.134541,0.182203,0.009282,-1.345409,-110.134834,-0.133508,0.000000
7.990000,0.040961,-110.090355,0.002958,-0.005166,-0.131210,0.182203,0.009282,-1.312102,-110.090355,-0.130023,0.000000
8.200001,0.062186,-110.001389,0.003109,-0.005028,-0.127716,0.276618,0.014092,-1.277160,-110.001389,-0.126520,0.000000
8.410001,0.070006,-110.090355,0.003229,-0.004889,-0.124169,0.311402,0.015864,-1.241688,-110.090355,-0.123015,0.000000
8.620001,0.049525,-110.045876,0.003380,-0.004744,-0.120500,0.220300,0.011223,-1.205005,-110.045876,-0.119530,0.000000
8.830001,0.040589,-110.045876,0.003527,-0.004609,-0.117067,0.180547,0.009197,-1.170668,-110.045876,-0.116025,0.000000
9.040000,0.036865,-110.045876,0.003660,-0.004472,-0.113597,0.163983,0.008354,-1.135968,-110.045876,-0.112522,0.000000
9.250000,-0.005586,-110.001389,0.003794,-0.004335,-0.110119,-0.024846,-0.001266,-1.101192,-110.001389,-0.109019,0.000000
9.460000,-0.000000,-110.045876,0.003936,-0.004198,-0.106634,-0.000000,-0.000000,-1.066341,-110.045876,-0.105532,0.000000
9.670000,0.056601,-110.001389,0.004079,-0.004061,-0.103138,0.251772,0.012826,-1.031384,-110.001389,-0.102029,0.000000
9.880000,0.058462,-110.045876,0.004255,-0.003922,-0.099618,0.260054,0.013248,-0.996184,-110.045876,-0.098525,0.000000
10.090000,0.036492,-109.956909,0.004376,-0.003780,-0.096018,0.162327,0.008269,-0.960182,-109.956909,-0.095039,0.000000
10.300000,0.053249,-109.956909,0.004562,-0.003645,-0.092585,0.236864,0.012066,-0.925846,-109.956909,-0.091535,0.000000
10.510000,0.062931,-110.001389,0.004691,-0.003512,-0.089202,0.279931,0.014260,-0.892024,-110.001389,-0.088032,0.000000
10.720000,0.078943,-109.912430,0.004829,-0.003374,-0.085708,0.351156,0.017889,-0.857082,-109.912430,-0.084545,0.000000
10.930000,0.065165,-110.045876,0.004967,-0.003242,-0.082352,0.289869,0.014767,-0.823517,-110.045876,-0.081042,0.000000
11.140000,0.045429,-109.956909,0.005148,-0.003097,-0.078665,0.202080,0.010294,-0.786653,-109.956909,-0.077539,0.000000
11.350000,0.056601,-110.001389,0.005295,-0.002953,-0.075006,0.251772,0.012826,-0.750060,-110.001389,-0.074034,0.000000
11.560000,0.055856,-109.956909,0.005454,-0.002816,-0.071519,0.248459,0.012657,-0.715194,-109.956909,-0.070549,0.000000
11.770000,0.050643,-109.867950,0.005618,-0.002682,-0.068111,0.225270,0.011476,-0.681115,-109.867950,-0.067046,0.000000
11.980000,0.059580,-109.956909,0.005739,-0.002548,-0.064713,0.265023,0.013501,-0.647126,-109.956909,-0.063541,0.000000
12.190001,0.044685,-109.867950,0.005898,-0.002405,-0.061087,0.198767,0.010126,-0.610867,-109.867950,-0.060056,0.000000
12.400001,0.064048,-109.956909,0.006032,-0.002265,-0.057539,0.284900,0.014513,-0.575395,-109.956909,-0.056551,0.000000
12.610001,0.087880,-109.912430,0.006148,-0.002127,-0.054036,0.390909,0.019914,-0.540362,-109.912430,-0.053048,0.000000
12.820001,0.067399,-109.867950,0.006355,-0.001991,-0.050577,0.299807,0.015273,-0.505768,-109.867950,-0.049544,0.000000
13.030001,0.087880,-109.867950,0.006502,-0.001858,-0.047202,0.390909,0.019914,-0.472022,-109.867950,-0.046058,0.000000
13.240001,0.091231,-109.823471,0.006640,-0.001718,-0.043638,0.405817,0.020673,-0.436383,-109.823471,-0.042554,0.000000
13.450001,0.081177,-109.912430,0.006786,-0.001579,-0.040100,0.361094,0.018395,-0.401002,-109.912430,-0.039051,0.000000
13.660001,0.086018,-109.867950,0.006954,-0.001436,-0.036483,0.382627,0.019492,-0.364834,-109.867950,-0.035564,0.000000
13.870001,0.131820,-109.823471,0.007170,-0.001300,-0.033015,0.586364,0.029871,-0.330149,-109.823471,-0.032061,0.000000
14.080001,0.129213,-109.867950,0.007274,-0.001166,-0.029624,0.574769,0.029280,-0.296236,-109.867950,-0.028558,0.000000
14.290001,0.112456,-109.778984,0.007446,-0.001028,-0.026111,0.500231,0.025483,-0.261112,-109.778984,-0.025054,0.000000
14.500001,0.139267,-109.778984,0.007580,-0.000889,-0.022591,0.619492,0.031558,-0.225913,-109.778984,-0.021568,0.000000
14.710001,0.180601,-109.823471,0.007726,-0.000753,-0.019130,0.803352,0.040925,-0.191304,-109.823471,-0.018065,0.000000
14.920001,0.179856,-109.778984,0.007877,-0.000612,-0.015557,0.800039,0.040756,-0.155574,-109.778984,-0.014560,0.000000
15.130001,0.227520,-109.823471,0.008058,-0.000480,-0.012193,1.012058,0.051557,-0.121934,-109.823471,-0.011075,0.000000
15.340001,0.280396,-109.778984,0.008196,-0.000344,-0.008742,1.247266,0.063539,-0.087416,-109.778984,-0.007570,0.000000
15.550001,0.406631,-109.823471,0.008360,-0.000202,-0.005134,1.808784,0.092144,-0.051338,-109.823471,-0.004066,0.000000
15.760001,0.654258,-109.734505,0.008515,-0.000066,-0.001673,2.910287,0.148257,-0.016729,-109.734505,-0.000563,0.000000
15.970001,0.686655,-109.690025,0.008545,-0.000008,-0.000191,3.054393,0.155598,-0.001908,-109.690025,-0.000035,0.000000
16.180000,0.665430,-109.778984,0.008545,-0.000008,-0.000191,2.959979,0.150789,-0.001908,-109.778984,-0.000035,0.000000
16.390001,0.593189,-109.734505,0.008550,-0.000008,-0.000200,2.638638,0.134419,-0.001998,-109.734505,0.000095,0.000000
16.600000,0.647928,-109.778984,0.008563,-0.000007,-0.000183,2.882128,0.146823,-0.001832,-109.778984,0.000451,0.000000
16.810001,0.684421,-109.690025,0.008554,0.000003,0.000086,3.044455,0.155092,0.000863,-109.690025,0.000798,0.000000
17.020000,0.706763,-109.645546,0.008563,0.000013,0.000329,3.143838,0.160155,0.003285,-109.645546,0.001154,0.000000
17.230001,0.711231,-109.734505,0.008554,0.000022,0.000547,3.163715,0.161167,0.005465,-109.734505,0.001500,0.000000
17.440001,0.757778,-109.601067,0.008558,0.000036,0.000919,3.370764,0.171715,0.009190,-109.601067,0.001847,0.000000
17.650002,0.760012,-109.734505,0.008571,0.000046,0.001179,3.380703,0.172221,0.011794,-109.734505,0.002203,0.000000
17.860001,0.894811,-109.690025,0.008597,0.000063,0.001612,3.980318,0.202767,0.016124,-109.690025,0.002550,0.000000
18.070002,0.924601,-109.645546,0.008645,0.000076,0.001942,4.112830,0.209518,0.019424,-109.645546,0.002896,0.000000
18.280001,0.957370,-109.645546,0.008610,0.000084,0.002133,4.258593,0.216943,0.021332,-109.645546,0.003252,0.000000
18.490002,1.025514,-109.601067,0.008610,0.000097,0.002463,4.561713,0.232385,0.024632,-109.601067,0.003599,0.000000
18.700001,1.099988,-109.690025,0.008666,0.000122,0.003104,4.892992,0.249261,0.031036,-109.690025,0.003945,0.000000
18.910002,1.133874,-109.690025,0.008679,0.000133,0.003390,5.043724,0.256940,0.033898,-109.690025,0.004301,0.000000
19.120001,1.177442,-109.601067,0.008688,0.000143,0.003643,5.237522,0.266812,0.036426,-109.601067,0.004648,0.000000
19.330002,1.201646,-109.645546,0.008696,0.000157,0.003980,5.345188,0.272297,0.039802,-109.645546,0.005004,0.000000
19.540001,1.292505,-109.601067,0.008718,0.000173,0.004387,5.749349,0.292886,0.043875,-109.601067,0.005350,0.000000
19.750000,1.371448,-109.556580,0.008727,0.000189,0.004804,6.100504,0.310775,0.048038,-109.556580,0.005697,0.000000
19.960001,1.403844,-109.556580,0.008757,0.000199,0.005048,6.244610,0.318116,0.050475,-109.556580,0.006053,0.000000
20.170000,1.447039,-109.512100,0.008761,0.000206,0.005238,6.436753,0.327904,0.052383,-109.512100,0.006400,0.000000
20.380001,1.568433,-109.601067,0.008774,0.000225,0.005706,6.976737,0.355412,0.057061,-109.601067,0.006746,0.000000
20.590000,1.669718,-109.556580,0.008778,0.000244,0.006209,7.427277,0.378364,0.062087,-109.556580,0.007102,0.000000
20.800001,1.750895,-109.556580,0.008778,0.000257,0.006539,7.788371,0.396759,0.065388,-109.556580,0.007449,0.000000
21.010000,1.759460,-109.556580,0.008821,0.000266,0.006746,7.826468,0.398699,0.067462,-109.556580,0.007795,0.000000
21.220001,1.836913,-109.512100,0.008813,0.000280,0.007111,8.170999,0.416251,0.071111,-109.512100,0.008151,0.000000
21.430000,1.952721,-109.512100,0.008852,0.000297,0.007544,8.686137,0.442493,0.075441,-109.512100,0.008498,0.000000
21.640001,2.065178,-109.467621,0.008852,0.000310,0.007874,9.186369,0.467976,0.078741,-109.467621,0.008854,0.000000
21.850000,2.172049,-109.556580,0.008890,0.000324,0.008230,9.661755,0.492193,0.082299,-109.556580,0.009200,0.000000
22.060001,2.253971,-109.467621,0.008886,0.000335,0.008498,10.026162,0.510757,0.084978,-109.467621,0.009549,0.000000
22.270000,2.392865,-109.512100,0.008921,0.000348,0.008837,10.643997,0.542231,0.088370,-109.512100,0.009903,0.000000
22.480001,2.568998,-109.423141,0.008933,0.000367,0.009314,11.427472,0.582143,0.093139,-109.423141,0.010249,0.000000
22.690001,2.736193,-109.423141,0.008942,0.000383,0.009721,12.171193,0.620030,0.097211,-109.423141,0.010598,0.000000
22.900002,2.827424,-109.467621,0.008946,0.000394,0.010007,12.577010,0.640703,0.100073,-109.467621,0.010952,0.000000
23.110001,2.914559,-109.378662,0.008977,0.000407,0.010328,12.964607,0.660449,0.103282,-109.378662,0.011300,0.000000
23.320002,3.068349,-109.423141,0.008964,0.000421,0.010693,13.648698,0.695298,0.106931,-109.423141,0.011647,0.000000
23.530001,3.227725,-109.378662,0.008981,0.000437,0.011091,14.357635,0.731413,0.110913,-109.378662,0.012003,0.000000
23.740002,3.413166,-109.423141,0.009015,0.000449,0.011403,15.182521,0.773435,0.114031,-109.423141,0.012349,0.000000
23.950001,3.515196,-109.423141,0.009002,0.000458,0.011621,15.636372,0.796555,0.116211,-109.423141,0.012696,0.000000
24.160002,3.646271,-109.289696,0.009050,0.000469,0.011924,16.219425,0.826257,0.119239,-109.289696,0.013052,0.000000
24.370001,3.777346,-109.378662,0.009050,0.000476,0.012098,16.802475,0.855959,0.120980,-109.378662,0.013399,0.000000
24.580002,4.236482,-109.334175,0.009084,0.000506,0.012852,18.844812,0.960000,0.128520,-109.334175,0.013754,0.000000
24.790001,4.409262,-109.378662,0.009102,0.000519,0.013173,19.613379,0.999153,0.131729,-109.378662,0.014101,0.000000
25.000002,4.534379,-109.378662,0.009102,0.000532,0.013511,20.169928,1.027505,0.135106,-109.378662,0.014448,0.000000
25.210001,4.749983,-109.289696,0.009106,0.000544,0.013815,21.128981,1.076362,0.138149,-109.289696,0.014803,0.000000
25.420002,4.917179,-109.378662,0.009123,0.000556,0.014127,21.872704,1.114249,0.141267,-109.378662,0.015150,0.000000
25.630001,5.261250,-109.289696,0.009162,0.000575,0.014613,23.403212,1.192216,0.146127,-109.289696,0.015497,0.000000
25.840002,5.396794,-109.378662,0.009162,0.000586,0.014890,24.006140,1.222931,0.148898,-109.378662,0.015853,0.000000
26.050001,5.498079,-109.289696,0.009166,0.000591,0.015020,24.456678,1.245883,0.150200,-109.289696,0.016199,0.000000
26.260002,5.650007,-109.245216,0.009184,0.000602,0.015297,25.132488,1.280310,0.152970,-109.245216,0.016546,0.000000
26.470001,6.279317,-109.289696,0.009218,0.000633,0.016069,27.931797,1.422914,0.160691,-109.289696,0.016902,0.000000
26.680002,6.405551,-109.245216,0.009222,0.000644,0.016346,28.493313,1.451519,0.163462,-109.245216,0.017249,0.000000
26.890001,6.515028,-109.289696,0.009248,0.000652,0.016555,28.980293,1.476327,0.165551,-109.289696,0.017604,0.000000
27.100000,6.798032,-109.334175,0.009214,0.000666,0.016911,30.239155,1.540456,0.169109,-109.334175,0.017951,0.000000
27.310001,7.156254,-109.200737,0.009240,0.000682,0.017327,31.832609,1.621630,0.173272,-109.200737,0.018298,0.000000
27.520000,7.313767,-109.289696,0.009257,0.000692,0.017588,32.533264,1.657323,0.175876,-109.289696,0.018653,0.000000
27.730001,7.722260,-109.200737,0.009283,0.000711,0.018055,34.350327,1.749889,0.180555,-109.200737,0.019000,0.000000
27.940001,7.841047,-109.245216,0.009309,0.000720,0.018281,34.878719,1.776807,0.182810,-109.245216,0.019347,0.000000
28.150002,8.050693,-109.245216,0.009300,0.000732,0.018602,35.811268,1.824313,0.186020,-109.245216,0.019703,0.000000
28.360001,8.551906,-109.156258,0.009322,0.000754,0.019139,38.040775,1.937889,0.191395,-109.156258,0.020049,0.000000
28.570002,8.836771,-109.200737,0.009339,0.000768,0.019503,39.307922,2.002441,0.195028,-109.200737,0.020396,0.000000
28.780001,8.954813,-109.200737,0.009373,0.000777,0.019737,39.832996,2.029190,0.197375,-109.200737,0.020752,0.000000
28.990002,9.215846,-109.245216,0.009356,0.000792,0.020110,40.994129,2.088341,0.201099,-109.245216,0.021099,0.000000
29.200001,9.688014,-109.156258,0.009347,0.000809,0.020553,43.094440,2.195335,0.205535,-109.156258,0.021454,0.000000
29.410002,9.928940,-109.156258,0.009390,0.000822,0.020891,44.166130,2.249930,0.208911,-109.156258,0.021801,0.000000
29.620001,9.998945,-109.156258,0.009390,0.000833,0.021168,44.477531,2.265793,0.211682,-109.156258,0.022149,0.000000
29.830002,10.389565,-109.111771,0.009386,0.000846,0.021489,46.215092,2.354309,0.214891,-109.111771,0.022503,0.000000
30.040001,10.542609,-109.111771,0.009403,0.000855,0.021715,46.895866,2.388989,0.217147,-109.111771,0.022852,0.000000
30.250002,11.147342,-109.111771,0.009416,0.000879,0.022322,49.585854,2.526024,0.223218,-109.111771,0.023198,0.000000
30.460001,11.369276,-109.111771,0.009459,0.000892,0.022652,50.573067,2.576315,0.226518,-109.111771,0.023554,0.000000
30.670002,11.489924,-109.156258,0.009472,0.000901,0.022885,51.109737,2.603654,0.228850,-109.156258,0.023901,0.000000
30.880001,11.804207,-109.022812,0.009455,0.000914,0.023224,52.507736,2.674871,0.232241,-109.022812,0.024248,0.000000
31.090002,11.987414,-109.111771,0.009477,0.000925,0.023501,53.322681,2.716387,0.235012,-109.111771,0.024603,0.000000
31.300001,12.392928,-109.022812,0.009507,0.000942,0.023936,55.126499,2.808278,0.239357,-109.022812,0.024950,0.000000
31.510002,12.627522,-109.111771,0.009520,0.000953,0.024213,56.170025,2.861438,0.242127,-109.111771,0.025297,0.000000
31.720001,12.869192,-109.067291,0.009516,0.000965,0.024508,57.245026,2.916201,0.245080,-109.067291,0.025653,0.000000
31.930002,13.108255,-109.022812,0.009511,0.000976,0.024802,58.308434,2.970373,0.248017,-109.022812,0.025999,0.000000
32.140003,13.365565,-109.067291,0.009528,0.000988,0.025106,59.453003,3.028681,0.251060,-109.067291,0.026355,0.000000
32.350002,14.124087,-109.022812,0.009559,0.001015,0.025790,62.827080,3.200564,0.257903,-109.022812,0.026702,0.000000
32.560001,14.217925,-108.978333,0.009580,0.001028,0.026111,63.244488,3.221828,0.261112,-108.978333,0.027048,0.000000
32.770000,14.259631,-108.933846,0.009567,0.001039,0.026381,63.430008,3.231279,0.263807,-108.933846,0.027404,0.000000
32.980003,14.617481,-108.978333,0.009602,0.001054,0.026779,65.021805,3.312369,0.267789,-108.978333,0.027751,0.000000
33.190002,14.766058,-108.978333,0.009610,0.001062,0.026979,65.682709,3.346037,0.269787,-108.978333,0.028098,0.000000
33.400002,15.053157,-108.978333,0.009636,0.001074,0.027291,66.959785,3.411094,0.272906,-108.978333,0.028453,0.000000
33.610001,15.526070,-108.978333,0.009636,0.001093,0.027751,69.063408,3.518258,0.277508,-108.978333,0.028800,0.000000
33.820004,15.626983,-108.978333,0.009632,0.001101,0.027967,69.512291,3.541125,0.279673,-108.978333,0.029147,0.000000
34.030003,16.091331,-108.889366,0.009628,0.001121,0.028462,71.577820,3.646348,0.284624,-108.889366,0.029502,0.000000
34.240002,16.338587,-108.933846,0.009679,0.001134,0.028800,72.677666,3.702377,0.288000,-108.933846,0.029849,0.000000
34.450001,16.770910,-108.889366,0.009705,0.001152,0.029251,74.600731,3.800343,0.292512,-108.889366,0.030205,0.000000
34.660000,16.691595,-108.978333,0.009697,0.001162,0.029502,74.247925,3.782369,0.295025,-108.978333,0.030552,0.000000
34.870003,17.126526,-108.889366,0.009697,0.001176,0.029858,76.182594,3.880926,0.298583,-108.889366,0.030898,0.000000
35.080002,17.213661,-108.844887,0.009748,0.001186,0.030128,76.570190,3.900671,0.301278,-108.844887,0.031254,0.000000
35.290001,17.634069,-108.889366,0.009714,0.001201,0.030500,78.440262,3.995937,0.305002,-108.889366,0.031601,0.000000
35.500000,18.082033,-108.889366,0.009753,0.001219,0.030959,80.432899,4.097447,0.309589,-108.889366,0.031948,0.000000
35.710003,18.065649,-108.844887,0.009783,0.001229,0.031212,80.360023,4.093735,0.312118,-108.844887,0.032303,0.000000
35.920002,18.471907,-108.889366,0.009774,0.001245,0.031636,82.167145,4.185794,0.316357,-108.889366,0.032650,0.000000
36.130001,18.888592,-108.844887,0.009779,0.001262,0.032061,84.020653,4.280216,0.320611,-108.844887,0.032998,0.000000
36.340000,19.093769,-108.844887,0.009804,0.001276,0.032408,84.933327,4.326710,0.324078,-108.844887,0.033352,0.000000
36.550003,19.279583,-108.800407,0.009787,0.001288,0.032712,85.759865,4.368816,0.327121,-108.800407,0.033701,0.000000
36.760002,19.253145,-108.889366,0.009804,0.001297,0.032945,85.642265,4.362825,0.329452,-108.889366,0.034055,0.000000
36.970001,19.507475,-108.844887,0.009843,0.001312,0.033327,86.773582,4.420457,0.333268,-108.844887,0.034403,0.000000
37.180000,19.997890,-108.755928,0.009826,0.001327,0.033701,88.955063,4.531587,0.337007,-108.755928,0.034750,0.000000
37.390003,20.420904,-108.844887,0.009865,0.001344,0.034134,90.836716,4.627443,0.341337,-108.844887,0.035106,0.000000
37.600002,20.506924,-108.755928,0.009882,0.001356,0.034436,91.219353,4.646935,0.344365,-108.755928,0.035452,0.000000
37.810001,20.759020,-108.800407,0.009869,0.001368,0.034750,92.340729,4.704061,0.347499,-108.800407,0.035799,0.000000
38.020000,21.246826,-108.755928,0.009895,0.001388,0.035243,94.510605,4.814600,0.352434,-108.755928,0.036155,0.000000
38.230003,21.460941,-108.755928,0.009921,0.001402,0.035608,95.463036,4.863119,0.356083,-108.755928,0.036502,0.000000
38.440002,21.529831,-108.755928,0.009925,0.001412,0.035860,95.769470,4.878729,0.358596,-108.755928,0.036848,0.000000
38.650002,21.492966,-108.666962,0.009947,0.001422,0.036128,95.605484,4.870376,0.361276,-108.666962,0.037204,0.000000
38.860001,21.949867,-108.755928,0.009964,0.001436,0.036476,97.637886,4.973911,0.364758,-108.755928,0.037551,0.000000
39.070004,22.068653,-108.711441,0.009964,0.001447,0.036744,98.166275,5.000828,0.367438,-108.711441,0.037897,0.000000
39.280003,22.643969,-108.711441,0.009994,0.001463,0.037160,100.725403,5.131197,0.371601,-108.711441,0.038253,0.000000
39.490002,22.911331,-108.711441,0.010003,0.001478,0.037551,101.914688,5.191782,0.375507,-108.711441,0.038600,0.000000
39.700001,22.847656,-108.666962,0.010024,0.001483,0.037672,101.631454,5.177353,0.376718,-108.666962,0.038956,0.000000
39.910004,23.202900,-108.711441,0.010016,0.001499,0.038072,103.211655,5.257853,0.380715,-108.711441,0.039302,0.000000
40.120003,24.057495,-108.622482,0.010016,0.001523,0.038686,107.013084,5.451506,0.386862,-108.622482,0.039649,0.000000
40.330002,24.094358,-108.666962,0.010046,0.001535,0.038981,107.177055,5.459860,0.389814,-108.666962,0.040005,0.000000
40.540001,24.065687,-108.666962,0.010042,0.001545,0.039242,107.049522,5.453363,0.392418,-108.666962,0.040352,0.000000
40.750004,24.405291,-108.578003,0.010080,0.001560,0.039623,108.560158,5.530318,0.396233,-108.578003,0.040698,0.000000
40.960003,24.799261,-108.711441,0.010067,0.001574,0.039970,110.312622,5.619593,0.399700,-108.711441,0.041054,0.000000
41.170002,25.311646,-108.578003,0.010115,0.001591,0.040403,112.591820,5.735701,0.404030,-108.578003,0.041401,0.000000
41.380001,25.355585,-108.578003,0.010102,0.001600,0.040647,112.787277,5.745658,0.406467,-108.578003,0.041747,0.000000
41.590000,25.214083,-108.622482,0.010145,0.001605,0.040759,112.157845,5.713593,0.407588,-108.622482,0.042103,0.000000
41.800003,26.209806,-108.578003,0.010141,0.001629,0.041384,116.587044,5.939227,0.413840,-108.578003,0.042450,0.000000
42.010002,26.680113,-108.578003,0.010136,0.001647,0.041826,118.679070,6.045800,0.418261,-108.578003,0.042806,0.000000
42.220001,26.868906,-108.578003,0.010167,0.001660,0.042156,119.518860,6.088581,0.421562,-108.578003,0.043152,0.000000
42.430000,26.811562,-108.622482,0.010184,0.001668,0.042373,119.263779,6.075587,0.423727,-108.622482,0.043499,0.000000
42.640003,27.277027,-108.533524,0.010149,0.001682,0.042719,121.334274,6.181063,0.427194,-108.533524,0.043855,0.000000
42.850002,27.689243,-108.622482,0.010197,0.001696,0.043075,123.167908,6.274472,0.430751,-108.622482,0.044202,0.000000
43.060001,28.006876,-108.533524,0.010192,0.001713,0.043499,124.580803,6.346449,0.434990,-108.533524,0.044550,0.000000
43.270000,28.447021,-108.489037,0.010231,0.001726,0.043838,126.538673,6.446187,0.438382,-108.489037,0.044904,0.000000
43.480003,28.474205,-108.578003,0.010231,0.001735,0.044064,126.659592,6.452347,0.440637,-108.578003,0.045252,0.000000
43.690002,28.954937,-108.444557,0.010248,0.001749,0.044427,128.797989,6.561282,0.444271,-108.444557,0.045599,0.000000
43.900002,29.733196,-108.533524,0.010274,0.001770,0.044948,132.259857,6.737638,0.449479,-108.533524,0.045953,0.000000
44.110001,30.202385,-108.533524,0.010283,0.001786,0.045355,134.346924,6.843958,0.453552,-108.533524,0.046301,0.000000
44.320004,30.214674,-108.400078,0.010292,0.001795,0.045599,134.401581,6.846743,0.455989,-108.400078,0.046656,0.000000
44.530003,30.849195,-108.489037,0.010317,0.001813,0.046050,137.224075,6.990528,0.460501,-108.489037,0.047004,0.000000
44.740002,30.951225,-108.400078,0.010305,0.001823,0.046301,137.677933,7.013648,0.463014,-108.400078,0.047351,0.000000
44.950001,31.656126,-108.444557,0.010343,0.001841,0.046751,140.813477,7.173381,0.467510,-108.444557,0.047706,0.000000
45.160004,31.816620,-108.400078,0.010356,0.001851,0.047011,141.527390,7.209749,0.470114,-108.400078,0.048053,0.000000
45.370003,31.890722,-108.444557,0.010356,0.001860,0.047246,141.857025,7.226541,0.472461,-108.444557,0.048400,0.000000
45.580002,32.197186,-108.444557,0.010361,0.001871,0.047523,143.220230,7.295987,0.475231,-108.444557,0.048756,0.000000
45.790001,32.213943,-108.400078,0.010361,0.001880,0.047741,143.294785,7.299784,0.477412,-108.400078,0.049102,0.000000
46.000004,33.853127,-108.444557,0.010374,0.001909,0.048477,150.586227,7.671228,0.484769,-108.444557,0.049449,0.000000
46.210003,34.115650,-108.400078,0.010395,0.001923,0.048833,151.753998,7.730717,0.488327,-108.400078,0.049805,0.000000
46.420002,34.471264,-108.400078,0.010430,0.001934,0.049128,153.335846,7.811300,0.491279,-108.400078,0.050151,0.000000
46.630001,34.848476,-108.355598,0.010408,0.001949,0.049500,155.013763,7.896778,0.495004,-108.355598,0.050507,0.000000
46.840004,35.207073,-108.355598,0.010421,0.001962,0.049847,156.608887,7.978037,0.498471,-108.355598,0.050854,0.000000
47.050003,35.855747,-108.400078,0.010425,0.001976,0.050195,159.494324,8.125029,0.501953,-108.400078,0.051201,0.000000
47.260002,36.038952,-108.311119,0.010442,0.001987,0.050472,160.309265,8.166543,0.504723,-108.311119,0.051556,0.000000
47.470001,36.287697,-108.311119,0.010473,0.001997,0.050715,161.415741,8.222910,0.507146,-108.311119,0.051903,0.000000
47.680004,36.478352,-108.311119,0.010473,0.002010,0.051045,162.263809,8.266112,0.510446,-108.311119,0.052250,0.000000
47.890003,37.969330,-108.266632,0.010499,0.002035,0.051687,168.896011,8.603972,0.516865,-108.266632,0.052605,0.000000
48.100002,38.141369,-108.355598,0.010499,0.002046,0.051964,169.661285,8.642958,0.519636,-108.355598,0.052952,0.000000
48.310001,38.501453,-108.266632,0.010507,0.002057,0.052259,171.263016,8.724554,0.522588,-108.266632,0.053299,0.000000
48.520000,39.091663,-108.222153,0.010507,0.002071,0.052615,173.888397,8.858297,0.526146,-108.222153,0.053655,0.000000
48.730003,39.550053,-108.266632,0.010529,0.002087,0.053013,175.927414,8.962170,0.530128,-108.266632,0.054001,0.000000
48.940002,40.106750,-108.222153,0.010572,0.002099,0.053317,178.403732,9.088320,0.533171,-108.222153,0.054348,0.000000
49.150002,40.583015,-108.222153,0.010563,0.002113,0.053664,180.522263,9.196243,0.536638,-108.222153,0.054704,0.000000
49.360001,40.600143,-108.222153,0.010559,0.002118,0.053803,180.598465,9.200124,0.538030,-108.222153,0.055051,0.000000
49.570004,41.707207,-108.177673,0.010585,0.002141,0.054392,185.522919,9.450988,0.543920,-108.177673,0.055406,0.000000
49.780003,42.390137,-108.222153,0.010598,0.002158,0.054808,188.560745,9.605742,0.548083,-108.222153,0.055753,0.000000
49.990002,42.794163,-108.177673,0.010598,0.002168,0.055078,190.357941,9.697296,0.550778,-108.177673,0.056100,0.000000
50.200001,42.949814,-108.222153,0.010619,0.002179,0.055346,191.050308,9.732567,0.553458,-108.222153,0.056455,0.000000
50.410004,43.556034,-108.133194,0.010624,0.002192,0.055676,193.746918,9.869939,0.556758,-108.133194,0.056802,0.000000
50.620003,44.660492,-108.177673,0.010671,0.002214,0.056230,198.659790,10.120212,0.562299,-108.177673,0.057150,0.000000
50.830002,44.963230,-108.177673,0.010637,0.002225,0.056508,200.006439,10.188814,0.565085,-108.177673,0.057505,0.000000
51.040001,45.530727,-108.133194,0.010649,0.002238,0.056846,202.530792,10.317410,0.568461,-108.133194,0.057853,0.000000
51.250004,45.911663,-108.177673,0.010662,0.002249,0.057116,204.225281,10.403731,0.571156,-108.177673,0.058200,0.000000
51.460003,46.872757,-108.088715,0.010688,0.002269,0.057627,208.500443,10.621518,0.576273,-108.088715,0.058555,0.000000
51.670002,47.499458,-108.177673,0.010701,0.002284,0.058016,211.288147,10.763531,0.580164,-108.177673,0.058902,0.000000
51.880001,47.840179,-108.088715,0.010697,0.002294,0.058277,212.803741,10.840739,0.582768,-108.088715,0.059258,0.000000
52.090004,48.319050,-108.088715,0.010727,0.002306,0.058563,214.933868,10.949254,0.585629,-108.088715,0.059605,0.000000
52.300003,48.765526,-108.088715,0.010701,0.002318,0.058876,216.919891,11.050426,0.588763,-108.088715,0.059951,0.000000
52.510002,49.220192,-108.044228,0.010740,0.002329,0.059144,218.942352,11.153455,0.591443,-108.044228,0.060307,0.000000
52.720001,50.122078,-108.044228,0.010723,0.002347,0.059612,222.954132,11.357825,0.596121,-108.044228,0.060654,0.000000
52.930004,50.362259,-107.999748,0.010736,0.002356,0.059830,224.022522,11.412251,0.598301,-107.999748,0.061000,0.000000
53.140003,51.061573,-107.999748,0.010779,0.002369,0.060168,227.133224,11.570718,0.601677,-107.999748,0.061356,0.000000
53.350002,51.341599,-108.088715,0.010774,0.002379,0.060419,228.378830,11.634172,0.604190,-108.088715,0.061703,0.000000
53.560001,51.799618,-107.999748,0.010757,0.002389,0.060670,230.416214,11.737962,0.606704,-107.999748,0.062050,0.000000
53.770004,53.625732,-108.044228,0.010796,0.002418,0.061417,238.539169,12.151765,0.614167,-108.044228,0.062405,0.000000
53.980003,53.968685,-107.955269,0.010787,0.002431,0.061738,240.064697,12.229479,0.617377,-107.955269,0.062752,0.000000
54.190002,54.447559,-107.999748,0.010805,0.002442,0.062024,242.194839,12.337994,0.620238,-107.999748,0.063108,0.000000
54.400002,55.041492,-107.999748,0.010818,0.002454,0.062319,244.836792,12.472580,0.623191,-107.999748,0.063455,0.000000
54.610004,55.528557,-107.955269,0.010848,0.002466,0.062640,247.003357,12.582952,0.626400,-107.955269,0.063801,0.000000
54.820004,56.170525,-107.955269,0.010852,0.002480,0.062994,249.858978,12.728423,0.629943,-107.955269,0.064157,0.000000
55.030003,57.257481,-107.999748,0.010848,0.002497,0.063429,254.694000,12.974730,0.634288,-107.999748,0.064504,0.000000
55.240002,57.535271,-107.955269,0.010882,0.002507,0.063671,255.929672,13.037679,0.636710,-107.955269,0.064850,0.000000
55.450001,58.477371,-107.910789,0.010891,0.002523,0.064096,260.120331,13.251162,0.640964,-107.910789,0.065206,0.000000
55.660004,59.244461,-107.910789,0.010904,0.002541,0.064548,263.532532,13.424987,0.645476,-107.910789,0.065553,0.000000
55.870003,59.820892,-107.955269,0.010887,0.002551,0.064808,266.096619,13.555608,0.648080,-107.955269,0.065900,0.000000
56.080002,60.208904,-107.866310,0.010912,0.002565,0.065146,267.822571,13.643533,0.651456,-107.866310,0.066255,0.000000
56.290001,61.129410,-107.866310,0.010934,0.002579,0.065518,271.917206,13.852122,0.655180,-107.866310,0.066602,0.000000
56.500004,61.511463,-107.910789,0.010934,0.002588,0.065736,273.616669,13.938697,0.657361,-107.910789,0.066949,0.000000
56.710003,62.541817,-107.866310,0.010930,0.002605,0.066160,278.199890,14.172178,0.661600,-107.866310,0.067305,0.000000
56.920002,63.519669,-107.866310,0.010930,0.002622,0.066594,282.549591,14.393763,0.665945,-107.866310,0.067651,0.000000
57.130001,63.835068,-107.866310,0.010951,0.002633,0.066881,283.952576,14.465233,0.668806,-107.866310,0.068007,0.000000
57.340004,65.046394,-107.866310,0.010977,0.002652,0.067365,289.340820,14.739723,0.673651,-107.866310,0.068354,0.000000
57.550003,65.837311,-107.866310,0.010977,0.002666,0.067721,292.858978,14.918947,0.677209,-107.866310,0.068702,0.000000
57.760002,66.591362,-107.821823,0.010999,0.002681,0.068095,296.213165,15.089819,0.680948,-107.821823,0.069056,0.000000
57.970001,66.821861,-107.821823,0.010999,0.002688,0.068276,297.238495,15.142051,0.682765,-107.821823,0.069404,0.000000
58.180004,67.382286,-107.732864,0.010999,0.002703,0.068658,299.731384,15.269045,0.686580,-107.732864,0.069751,0.000000
58.390003,67.164444,-107.821823,0.011020,0.002695,0.068441,298.762360,15.219681,0.684415,-107.821823,0.068675,0.000000
58.600002,66.865059,-107.821823,0.011016,0.002692,0.068389,297.430634,15.151838,0.683885,-107.821823,0.068441,0.000000
58.810001,66.558968,-107.821823,0.011016,0.002689,0.068311,296.069061,15.082478,0.683113,-107.821823,0.068441,0.000000
59.020004,66.299797,-107.821823,0.011029,0.002689,0.068293,294.916229,15.023748,0.682931,-107.821823,0.068441,0.000000
59.230003,66.090149,-107.732864,0.011020,0.002688,0.068276,293.983673,14.976241,0.682765,-107.732864,0.068441,0.000000
59.440002,65.892418,-107.688385,0.011046,0.002688,0.068267,293.104126,14.931435,0.682674,-107.688385,0.068441,0.000000
59.650002,65.725227,-107.732864,0.011016,0.002688,0.068267,292.360413,14.893550,0.682674,-107.732864,0.068441,0.000000
59.860004,65.565475,-107.688385,0.011007,0.002687,0.068258,291.649811,14.857348,0.682583,-107.688385,0.068441,0.000000
60.070004,65.430679,-107.732864,0.011016,0.002687,0.068258,291.050201,14.826804,0.682583,-107.732864,0.068441,0.000000
60.280003,65.295135,-107.732864,0.011012,0.002687,0.068251,290.447266,14.796089,0.682507,-107.732864,0.068441,0.000000
60.490002,65.168159,-107.688385,0.011037,0.002687,0.068251,289.882446,14.767316,0.682507,-107.688385,0.068441,0.000000
60.700005,65.063896,-107.732864,0.011050,0.002687,0.068251,289.418671,14.743690,0.682507,-107.732864,0.068441,0.000000
60.910004,64.948830,-107.643898,0.011016,0.002687,0.068242,288.906830,14.717615,0.682417,-107.643898,0.068441,0.000000
61.120003,64.843079,-107.777344,0.011046,0.002687,0.068242,288.436432,14.693652,0.682417,-107.777344,0.068441,0.000000
61.330002,64.751099,-107.599419,0.011037,0.002687,0.068242,288.027283,14.672809,0.682417,-107.599419,0.068441,0.000000
61.540005,64.669556,-107.643898,0.011042,0.002687,0.068242,287.664551,14.654330,0.682417,-107.643898,0.068441,0.000000
61.750004,64.592842,-107.599419,0.011012,0.002687,0.068242,287.323303,14.636948,0.682417,-107.599419,0.068441,0.000000
61.960003,64.501610,-107.688385,0.011029,0.002687,0.068242,286.917480,14.616274,0.682417,-107.688385,0.068441,0.000000
62.170002,64.434959,-107.643898,0.011012,0.002687,0.068242,286.621002,14.601171,0.682417,-107.643898,0.068441,0.000000
62.380001,64.368675,-107.599419,0.011033,0.002686,0.068233,286.326172,14.586150,0.682326,-107.599419,0.068441,0.000000
62.590004,64.290848,-107.599419,0.011007,0.002686,0.068233,285.979980,14.568515,0.682326,-107.599419,0.068441,0.000000
62.800003,64.232384,-107.599419,0.011033,0.002686,0.068233,285.719910,14.555266,0.682326,-107.599419,0.068441,0.000000
63.010002,64.181000,-107.554939,0.011025,0.002686,0.068233,285.491333,14.543622,0.682326,-107.554939,0.068441,0.000000
63.220001,64.105782,-107.554939,0.011020,0.002686,0.068233,285.156769,14.526578,0.682326,-107.554939,0.068441,0.000000
63.430004,64.046570,-107.510460,0.011016,0.002686,0.068233,284.893372,14.513161,0.682326,-107.510460,0.068441,0.000000
63.640003,63.997795,-107.554939,0.011029,0.002686,0.068233,284.676422,14.502108,0.682326,-107.554939,0.068441,0.000000
63.850002,63.938587,-107.510460,0.011046,0.002686,0.068233,284.413055,14.488690,0.682326,-107.510460,0.068441,0.000000
64.060005,63.884594,-107.510460,0.011055,0.002686,0.068233,284.172852,14.476456,0.682326,-107.510460,0.068441,0.000000
64.270004,63.840652,-107.554939,0.011016,0.002686,0.068233,283.977417,14.466498,0.682326,-107.554939,0.068441,0.000000
64.480003,63.782936,-107.510460,0.011025,0.002686,0.068233,283.720673,14.453420,0.682326,-107.510460,0.068441,0.000000
64.690002,63.756496,-107.510460,0.011033,0.002686,0.068233,283.603058,14.447429,0.682326,-107.510460,0.068441,0.000000
64.900002,63.701385,-107.421494,0.011012,0.002686,0.068233,283.357910,14.434940,0.682326,-107.421494,0.068441,0.000000
65.110001,63.656330,-107.465981,0.011042,0.002686,0.068233,283.157501,14.424730,0.682326,-107.465981,0.068441,0.000000
65.320000,63.607174,-107.465981,0.011037,0.002686,0.068233,282.938843,14.413591,0.682326,-107.465981,0.068441,0.000000
65.530006,63.575897,-107.421494,0.011059,0.002686,0.068233,282.799713,14.406505,0.682326,-107.421494,0.068441,0.000000
65.740005,63.528606,-107.510460,0.011037,0.002686,0.068233,282.589355,14.395788,0.682326,-107.510460,0.068441,0.000000
65.950005,63.491367,-107.421494,0.011029,0.002686,0.068233,282.423706,14.387349,0.682326,-107.421494,0.068441,0.000000
66.160004,63.455994,-107.421494,0.011037,0.002686,0.068233,282.266357,14.379333,0.682326,-107.421494,0.068441,0.000000
66.370003,63.422852,-107.377014,0.011025,0.002686,0.068233,282.118927,14.371823,0.682326,-107.377014,0.068441,0.000000
66.580002,63.393433,-107.377014,0.011050,0.002686,0.068233,281.988068,14.365157,0.682326,-107.377014,0.068441,0.000000
66.790001,63.355080,-107.421494,0.011046,0.002686,0.068233,281.817474,14.356466,0.682326,-107.421494,0.068441,0.000000
67.000000,63.310394,-107.332535,0.011042,0.002686,0.068233,281.618713,14.346340,0.682326,-107.332535,0.068441,0.000000
67.210007,63.285446,-107.421494,0.011025,0.002686,0.068233,281.507721,14.340687,0.682326,-107.421494,0.068441,0.000000
67.420006,63.250069,-107.332535,0.011029,0.002686,0.068233,281.350372,14.332671,0.682326,-107.332535,0.068441,0.000000
67.630005,63.223633,-107.332535,0.011037,0.002686,0.068233,281.232758,14.326680,0.682326,-107.332535,0.068441,0.000000
67.840004,63.186394,-107.377014,0.011029,0.002686,0.068233,281.067108,14.318241,0.682326,-107.377014,0.068441,0.000000
68.050003,63.164799,-107.288055,0.011012,0.002686,0.068233,280.971069,14.313348,0.682326,-107.288055,0.068441,0.000000
68.260002,63.130913,-107.332535,0.011033,0.002686,0.068233,280.820312,14.305670,0.682326,-107.332535,0.068441,0.000000
68.470001,63.094048,-107.332535,0.011016,0.002686,0.068233,280.656342,14.297316,0.682326,-107.332535,0.068441,0.000000
68.680000,63.064255,-107.243576,0.011059,0.002686,0.068233,280.523804,14.290565,0.682326,-107.243576,0.068441,0.000000
68.890007,63.040051,-107.332535,0.011033,0.002686,0.068233,280.416138,14.285080,0.682326,-107.332535,0.068441,0.000000
69.100006,63.022179,-107.243576,0.011033,0.002686,0.068233,280.336639,14.281030,0.682326,-107.243576,0.068441,0.000000
69.310005,62.993877,-107.332535,0.011037,0.002686,0.068233,280.210754,14.274617,0.682326,-107.332535,0.068441,0.000000
69.520004,62.969673,-107.288055,0.011042,0.002686,0.068233,280.103088,14.269132,0.682326,-107.288055,0.068441,0.000000
69.730003,62.939140,-107.243576,0.011042,0.002686,0.068233,279.967285,14.262213,0.682326,-107.243576,0.068441,0.000000
69.940002,62.913445,-107.199089,0.011020,0.002686,0.068233,279.852966,14.256391,0.682326,-107.199089,0.068441,0.000000
70.150002,62.881050,-107.199089,0.011046,0.002686,0.068233,279.708893,14.249049,0.682326,-107.199089,0.068441,0.000000
70.360001,62.866154,-107.199089,0.011033,0.002686,0.068233,279.642609,14.245674,0.682326,-107.199089,0.068441,0.000000
70.570000,62.831898,-107.199089,0.011042,0.002686,0.068233,279.490234,14.237911,0.682326,-107.199089,0.068441,0.000000
70.780006,62.819237,-107.199089,0.011042,0.002686,0.068233,279.433929,14.235043,0.682326,-107.199089,0.068441,0.000000
70.990005,62.794285,-107.199089,0.011033,0.002686,0.068233,279.322937,14.229388,0.682326,-107.199089,0.068441,0.000000
71.200005,62.783489,-107.199089,0.011037,0.002686,0.068233,279.274902,14.226942,0.682326,-107.199089,0.068441,0.000000
71.410004,62.748486,-107.243576,0.011050,0.002686,0.068233,279.119202,14.219010,0.682326,-107.243576,0.068441,0.000000
71.620003,62.698215,-107.154610,0.011042,0.002686,0.068225,278.895599,14.207619,0.682250,-107.154610,0.068441,0.000000
71.830002,62.694862,-107.154610,0.011029,0.002686,0.068225,278.880676,14.206859,0.682250,-107.154610,0.068441,0.000000
72.040001,62.672520,-107.154610,0.011037,0.002686,0.068225,278.781281,14.201797,0.682250,-107.154610,0.068441,0.000000
72.250000,62.655018,-107.110130,0.011055,0.002686,0.068225,278.703430,14.197830,0.682250,-107.110130,0.068441,0.000000
72.460007,62.624485,-107.110130,0.011029,0.002686,0.068225,278.567627,14.190911,0.682250,-107.110130,0.068441,0.000000
72.670006,62.614803,-107.065651,0.011033,0.002686,0.068225,278.524567,14.188717,0.682250,-107.065651,0.068441,0.000000
72.880005,62.584641,-107.110130,0.011059,0.002686,0.068225,278.390381,14.181882,0.682250,-107.110130,0.068441,0.000000
73.090004,62.564159,-107.110130,0.011029,0.002686,0.068225,278.299286,14.177241,0.682250,-107.110130,0.068441,0.000000
73.300003,62.544426,-107.065651,0.011029,0.002686,0.068225,278.211487,14.172769,0.682250,-107.065651,0.068441,0.000000
73.510002,62.538467,-107.065651,0.011059,0.002686,0.068225,278.184998,14.171419,0.682250,-107.065651,0.068441,0.000000
73.720001,62.513519,-106.976685,0.011046,0.002686,0.068225,278.074036,14.165766,0.682250,-106.976685,0.068441,0.000000
73.930000,62.499741,-107.021172,0.011007,0.002686,0.068225,278.012726,14.162644,0.682250,-107.021172,0.068441,0.000000
74.140007,62.481121,-107.021172,0.011016,0.002686,0.068225,277.929901,14.158424,0.682250,-107.021172,0.068441,0.000000
74.350006,62.466225,-107.021172,0.011029,0.002686,0.068225,277.863647,14.155049,0.682250,-107.021172,0.068441,0.000000
74.560005,62.455429,-107.021172,0.011050,0.002686,0.068225,277.815613,14.152602,0.682250,-107.021172,0.068441,0.000000
74.770004,62.421543,-106.976685,0.011050,0.002686,0.068225,277.664886,14.144924,0.682250,-106.976685,0.068441,0.000000
74.980003,62.411114,-106.976685,0.011055,0.002686,0.068225,277.618500,14.142561,0.682250,-106.976685,0.068441,0.000000
75.190002,62.388027,-106.976685,0.011055,0.002686,0.068225,277.515808,14.137329,0.682250,-106.976685,0.068441,0.000000
75.400002,62.376858,-106.976685,0.011055,0.002686,0.068225,277.466125,14.134798,0.682250,-106.976685,0.068441,0.000000
75.610001,62.351162,-106.976685,0.011012,0.002686,0.068225,277.351807,14.128975,0.682250,-106.976685,0.068441,0.000000
75.820007,62.351536,-106.932205,0.011029,0.002686,0.068225,277.353485,14.129060,0.682250,-106.932205,0.068441,0.000000
76.030006,62.327705,-106.976685,0.011037,0.002686,0.068225,277.247467,14.123660,0.682250,-106.976685,0.068441,0.000000
76.240005,62.308342,-106.932205,0.011055,0.002686,0.068225,277.161346,14.119271,0.682250,-106.932205,0.068441,0.000000
76.450005,62.296425,-106.932205,0.011029,0.002686,0.068225,277.108337,14.116571,0.682250,-106.932205,0.068441,0.000000
76.660004,62.286369,-106.932205,0.011016,0.002686,0.068225,277.063599,14.114293,0.682250,-106.932205,0.068441,0.000000
76.870003,62.264027,-106.843246,0.011033,0.002686,0.068225,276.964233,14.109230,0.682250,-106.843246,0.068441,0.000000
77.080002,62.238708,-106.932205,0.011063,0.002686,0.068225,276.851593,14.103493,0.682250,-106.932205,0.068441,0.000000
77.290001,62.243919,-106.887726,0.011033,0.002686,0.068225,276.874786,14.104673,0.682250,-106.887726,0.068441,0.000000
77.500000,62.219345,-106.887726,0.011042,0.002686,0.068225,276.765472,14.099105,0.682250,-106.887726,0.068441,0.000000
77.710007,62.208172,-106.932205,0.011042,0.002686,0.068225,276.715759,14.096573,0.682250,-106.932205,0.068441,0.000000
77.920006,62.204823,-106.887726,0.011050,0.002686,0.068225,276.700867,14.095814,0.682250,-106.887726,0.068441,0.000000
78.130005,62.183224,-106.887726,0.011042,0.002686,0.068225,276.604797,14.090919,0.682250,-106.887726,0.068441,0.000000
78.340004,62.171307,-106.843246,0.011033,0.002686,0.068225,276.551788,14.088219,0.682250,-106.843246,0.068441,0.000000
78.550003,62.155666,-106.843246,0.011042,0.002686,0.068225,276.482208,14.084675,0.682250,-106.843246,0.068441,0.000000
78.760002,62.140030,-106.843246,0.011055,0.002686,0.068225,276.412659,14.081133,0.682250,-106.843246,0.068441,0.000000
78.970001,62.118801,-106.754280,0.011059,0.002686,0.068225,276.318237,14.076322,0.682250,-106.754280,0.068441,0.000000
79.180000,62.105396,-106.798767,0.011033,0.002686,0.068225,276.258606,14.073284,0.682250,-106.798767,0.068441,0.000000
79.390007,62.107632,-106.754280,0.011037,0.002686,0.068225,276.268555,14.073791,0.682250,-106.754280,0.068441,0.000000
79.600006,62.093483,-106.798767,0.011050,0.002686,0.068225,276.205597,14.070584,0.682250,-106.798767,0.068441,0.000000
79.810005,62.060341,-106.798767,0.011042,0.002686,0.068225,276.058197,14.063075,0.682250,-106.798767,0.068441,0.000000
80.020004,62.058849,-106.754280,0.011037,0.002686,0.068225,276.051544,14.062736,0.682250,-106.754280,0.068441,0.000000
80.230003,62.039116,-106.798767,0.011033,0.002686,0.068225,275.963776,14.058265,0.682250,-106.798767,0.068441,0.000000
80.440002,62.037254,-106.665321,0.011068,0.002686,0.068225,275.955475,14.057842,0.682250,-106.665321,0.068441,0.000000
80.650002,62.021240,-106.709801,0.011042,0.002686,0.068225,275.884247,14.054214,0.682250,-106.709801,0.068441,0.000000
80.860001,62.016399,-106.709801,0.011042,0.002686,0.068225,275.862732,14.053118,0.682250,-106.709801,0.068441,0.000000
81.070007,62.006348,-106.709801,0.011046,0.002686,0.068225,275.818024,14.050839,0.682250,-106.709801,0.068441,0.000000
81.280006,62.001507,-106.709801,0.011033,0.002686,0.068225,275.796478,14.049742,0.682250,-106.709801,0.068441,0.000000
81.490005,61.976185,-106.665321,0.011029,0.002686,0.068225,275.683838,14.044004,0.682250,-106.665321,0.068441,0.000000
81.700005,61.962780,-106.709801,0.011033,0.002686,0.068225,275.624207,14.040967,0.682250,-106.709801,0.068441,0.000000
81.910004,61.944904,-106.709801,0.011037,0.002686,0.068225,275.544708,14.036916,0.682250,-106.709801,0.068441,0.000000
82.120003,61.943417,-106.665321,0.011055,0.002686,0.068225,275.538086,14.036579,0.682250,-106.665321,0.068441,0.000000
82.330002,61.941555,-106.665321,0.011033,0.002686,0.068225,275.529785,14.036157,0.682250,-106.665321,0.068441,0.000000
82.540001,61.910275,-106.620842,0.011050,0.002686,0.068225,275.390656,14.029069,0.682250,-106.620842,0.068441,0.000000
82.750008,61.893890,-106.709801,0.011033,0.002686,0.068225,275.317780,14.025355,0.682250,-106.709801,0.068441,0.000000
82.960007,61.882717,-106.620842,0.011033,0.002686,0.068225,275.268066,14.022823,0.682250,-106.620842,0.068441,0.000000
83.170006,61.878624,-106.620842,0.011068,0.002686,0.068225,275.249878,14.021896,0.682250,-106.620842,0.068441,0.000000
83.380005,61.870056,-106.620842,0.011059,0.002686,0.068225,275.211761,14.019955,0.682250,-106.620842,0.068441,0.000000
83.590004,61.866707,-106.576355,0.011042,0.002686,0.068225,275.196869,14.019196,0.682250,-106.576355,0.068441,0.000000
83.800003,61.853672,-106.620842,0.011059,0.002686,0.068225,275.138885,14.016243,0.682250,-106.620842,0.068441,0.000000
84.010002,61.828724,-106.576355,0.011068,0.002686,0.068225,275.027893,14.010589,0.682250,-106.576355,0.068441,0.000000
84.220001,61.834309,-106.576355,0.011059,0.002686,0.068225,275.052734,14.011854,0.682250,-106.576355,0.068441,0.000000
84.430000,61.821651,-106.576355,0.011029,0.002686,0.068225,274.996429,14.008986,0.682250,-106.576355,0.068441,0.000000
84.640007,61.814201,-106.531876,0.011059,0.002686,0.068225,274.963287,14.007298,0.682250,-106.531876,0.068441,0.000000
84.850006,61.801914,-106.576355,0.011055,0.002686,0.068225,274.908630,14.004515,0.682250,-106.576355,0.068441,0.000000
85.060005,61.803032,-106.487396,0.011050,0.002686,0.068225,274.913605,14.004767,0.682250,-106.487396,0.068441,0.000000
85.270004,61.788879,-106.531876,0.011059,0.002686,0.068225,274.850677,14.001560,0.682250,-106.531876,0.068441,0.000000
85.480003,61.778454,-106.487396,0.011037,0.002686,0.068225,274.804291,13.999198,0.682250,-106.487396,0.068441,0.000000
85.690002,61.765423,-106.487396,0.011042,0.002686,0.068225,274.746307,13.996244,0.682250,-106.487396,0.068441,0.000000
85.900002,61.753132,-106.531876,0.011029,0.002686,0.068225,274.691650,13.993460,0.682250,-106.531876,0.068441,0.000000
86.110001,61.750900,-106.442917,0.011033,0.002686,0.068225,274.681732,13.992954,0.682250,-106.442917,0.068441,0.000000
86.320007,61.727810,-106.487396,0.011046,0.002686,0.068225,274.579010,13.987722,0.682250,-106.487396,0.068441,0.000000
86.530006,61.722599,-106.442917,0.011042,0.002686,0.068225,274.555847,13.986541,0.682250,-106.442917,0.068441,0.000000
86.740005,61.674564,-106.442917,0.011037,0.002686,0.068225,274.342163,13.975656,0.682250,-106.442917,0.068441,0.000000
86.950005,61.676426,-106.487396,0.011063,0.002686,0.068225,274.350433,13.976078,0.682250,-106.487396,0.068441,0.000000
87.160004,61.676426,-106.398437,0.011033,0.002686,0.068225,274.350433,13.976078,0.682250,-106.398437,0.068441,0.000000
87.370003,61.670837,-106.398437,0.011042,0.002686,0.068225,274.325592,13.974812,0.682250,-106.398437,0.068441,0.000000
87.580002,61.664883,-106.398437,0.011020,0.002686,0.068225,274.299103,13.973462,0.682250,-106.398437,0.068441,0.000000
87.790001,61.651848,-106.398437,0.011033,0.002686,0.068225,274.241119,13.970509,0.682250,-106.398437,0.068441,0.000000
88.000008,61.642166,-106.442917,0.011042,0.002686,0.068225,274.198059,13.968314,0.682250,-106.442917,0.068441,0.000000
88.210007,61.646263,-106.309471,0.011050,0.002686,0.068225,274.216278,13.969243,0.682250,-106.309471,0.068441,0.000000
88.420006,61.639187,-106.398437,0.011042,0.002686,0.068225,274.184784,13.967640,0.682250,-106.398437,0.068441,0.000000
88.630005,61.627644,-106.309471,0.011029,0.002686,0.068225,274.133453,13.965023,0.682250,-106.309471,0.068441,0.000000
88.700005,61.619450,-106.353951,0.011055,0.002686,0.068225,274.097015,13.963166,0.682250,-106.353951,0.068441,0.000000