File: Data/New pin I-18 old sample 4_08172023_175409.csv
Time (sec),S:Load (lbs),S:HL1 (DIM),S:LVDT (in),S:Position (in),Ch:Position (mm),Ch:Load (N),Ch:Stress (MPa),Ch:Strain (mm/mm),Ch:HL1 (DIM),Set Point (),Cycles ()
0.110000,-0.010048,-23.797308,-0.002699,-0.014285,-0.362840,-0.044695,-0.002277,-3.628397,-23.797308,-0.362640,0.000000
0.320000,-0.008186,-23.752829,-0.002729,-0.014285,-0.362840,-0.036415,-0.001855,-3.628397,-23.752829,-0.362640,0.000000
0.530000,-0.015640,-23.797308,-0.002703,-0.014189,-0.360411,-0.069571,-0.003544,-3.604113,-23.797308,-0.359621,0.000000
0.740000,-0.021965,-23.797308,-0.002677,-0.014062,-0.357176,-0.097705,-0.004977,-3.571760,-23.797308,-0.356136,0.000000
0.950000,-0.015640,-23.752829,-0.002583,-0.013929,-0.353785,-0.069571,-0.003544,-3.537847,-23.752829,-0.352631,0.000000
1.160000,-0.011543,-23.752829,-0.002432,-0.013790,-0.350256,-0.051347,-0.002616,-3.502557,-23.752829,-0.349128,0.000000
1.370000,-0.014519,-23.752829,-0.002285,-0.013652,-0.346769,-0.064583,-0.003290,-3.467690,-23.752829,-0.345643,0.000000
1.580000,0.003723,-23.797308,-0.002121,-0.013520,-0.343405,0.016561,0.000844,-3.434050,-23.797308,-0.342138,0.000000
1.790000,-0.002228,-23.841789,-0.002013,-0.013378,-0.339797,-0.009910,-0.000505,-3.397973,-23.841789,-0.338635,0.000000
2.000000,0.013779,-23.797308,-0.001880,-0.013237,-0.336215,0.061291,0.003122,-3.362153,-23.797308,-0.335131,0.000000
2.210000,0.016762,-23.886271,-0.001677,-0.013099,-0.332703,0.074560,0.003798,-3.327029,-23.886271,-0.331645,0.000000
2.420000,-0.003349,-23.797308,-0.001578,-0.012964,-0.329286,-0.014898,-0.000759,-3.292859,-23.797308,-0.328141,0.000000
2.630000,-0.005959,-23.841789,-0.001431,-0.012827,-0.325808,-0.026505,-0.001350,-3.258083,-23.841789,-0.324638,0.000000
2.840000,-0.020851,-23.841789,-0.001319,-0.012691,-0.322356,-0.092750,-0.004725,-3.223565,-23.841789,-0.321151,0.000000
3.050000,-0.024574,-23.841789,-0.001160,-0.012555,-0.318897,-0.109312,-0.005569,-3.188971,-23.841789,-0.317648,0.000000
3.260000,-0.012283,-23.797308,-0.001022,-0.012416,-0.315376,-0.054639,-0.002783,-3.153756,-23.797308,-0.314145,0.000000
3.470000,-0.011169,-23.886271,-0.000884,-0.012273,-0.311725,-0.049684,-0.002531,-3.117255,-23.886271,-0.310640,0.000000
3.680000,0.019363,-23.886271,-0.000703,-0.012138,-0.308308,0.086133,0.004388,-3.083085,-23.886271,-0.307155,0.000000
3.890000,0.022346,-23.886271,-0.000591,-0.012006,-0.304943,0.099402,0.005064,-3.049429,-23.886271,-0.303652,0.000000
4.100000,0.021225,-23.841789,-0.000444,-0.011863,-0.301326,0.094413,0.004810,-3.013261,-23.841789,-0.300147,0.000000
4.310000,0.020485,-23.886271,-0.000285,-0.011727,-0.297876,0.091121,0.004642,-2.978758,-23.886271,-0.296662,0.000000
4.520000,0.006332,-23.841789,-0.000181,-0.011581,-0.294145,0.028168,0.001435,-2.941454,-23.841789,-0.293157,0.000000
4.730000,0.008568,-23.886271,0.000000,-0.011446,-0.290730,0.038112,0.001941,-2.907299,-23.886271,-0.289653,0.000000
4.940000,-0.019730,-23.886271,0.000112,-0.011308,-0.287234,-0.087762,-0.004471,-2.872342,-23.886271,-0.286168,0.000000
5.150000,-0.032394,-23.841789,0.000272,-0.011172,-0.283766,-0.144098,-0.007341,-2.837657,-23.841789,-0.282664,0.000000
5.360000,-0.042450,-23.886271,0.000384,-0.011039,-0.280383,-0.188827,-0.009619,-2.803835,-23.886271,-0.279160,0.000000
5.570000,-0.026062,-23.886271,0.000535,-0.010896,-0.276767,-0.115930,-0.005906,-2.767667,-23.886271,-0.275657,0.000000
5.780000,0.023834,-23.886271,0.000690,-0.010759,-0.273289,0.106020,0.005401,-2.732891,-23.886271,-0.272170,0.000000
5.990000,0.027931,-23.930752,0.000824,-0.010623,-0.269821,0.124244,0.006329,-2.698206,-23.930752,-0.268667,0.000000
6.200000,0.023834,-23.930752,0.000940,-0.010487,-0.266360,0.106020,0.005401,-2.663597,-23.930752,-0.265164,0.000000
6.410000,0.028679,-23.930752,0.001104,-0.010352,-0.262935,0.127570,0.006499,-2.629351,-23.930752,-0.261677,0.000000
6.620000,0.016014,-23.930752,0.001229,-0.010213,-0.259414,0.071234,0.003629,-2.594137,-23.930752,-0.258174,0.000000
6.830000,0.030167,-23.886271,0.001388,-0.010067,-0.255711,0.134188,0.006836,-2.557105,-23.886271,-0.254670,0.000000
7.040000,0.004845,-23.975233,0.001531,-0.009928,-0.252163,0.021550,0.001098,-2.521633,-23.975233,-0.251166,0.000000
7.250000,0.003723,-23.975233,0.001664,-0.009792,-0.248711,0.016561,0.000844,-2.487115,-23.975233,-0.247681,0.000000
7.460001,-0.036118,-24.019714,0.001811,-0.009658,-0.245304,-0.160659,-0.008184,-2.453036,-24.019714,-0.244177,0.000000
7.670001,-0.046913,-23.930752,0.001932,-0.009520,-0.241817,-0.208680,-0.010631,-2.418169,-23.930752,-0.240672,0.000000
7.880001,-0.029045,-23.930752,0.002121,-0.009381,-0.238279,-0.129199,-0.006582,-2.382788,-23.930752,-0.237187,0.000000
8.090000,0.016014,-23.975233,0.002242,-0.009241,-0.234733,0.071234,0.003629,-2.347331,-23.975233,-0.233682,0.000000
8.300000,0.024948,-23.975233,0.002376,-0.009105,-0.231256,0.110975,0.005653,-2.312556,-23.975233,-0.230179,0.000000
8.510000,0.002609,-24.019714,0.002531,-0.008969,-0.227820,0.011607,0.000591,-2.278204,-24.019714,-0.226676,0.000000
8.720000,0.023834,-23.975233,0.002647,-0.008836,-0.224429,0.106020,0.005401,-2.244291,-23.975233,-0.223189,0.000000
8.930000,0.035751,-23.930752,0.002794,-0.008697,-0.220909,0.159030,0.008101,-2.209092,-23.930752,-0.219686,0.000000
9.140000,0.021973,-24.019714,0.002962,-0.008556,-0.217311,0.097739,0.004979,-2.173105,-24.019714,-0.216183,0.000000
9.350000,0.017136,-24.019714,0.003117,-0.008417,-0.213780,0.076223,0.003883,-2.137800,-24.019714,-0.212696,0.000000
9.560000,0.010803,-24.019714,0.003260,-0.008275,-0.210181,0.048055,0.002448,-2.101813,-24.019714,-0.209193,0.000000
9.770000,-0.002602,-24.064194,0.003406,-0.008138,-0.206704,-0.011573,-0.000590,-2.067037,-24.064194,-0.205689,0.000000
9.980000,-0.039841,-23.975233,0.003544,-0.008003,-0.203270,-0.177220,-0.009028,-2.032701,-23.975233,-0.202186,0.000000
10.190001,0.020485,-24.019714,0.003673,-0.007867,-0.199827,0.091121,0.004642,-1.998273,-24.019714,-0.198699,0.000000
10.400001,0.018623,-23.975233,0.003837,-0.007729,-0.196323,0.082841,0.004220,-1.963225,-23.975233,-0.195196,0.000000
10.610001,0.018997,-24.019714,0.003949,-0.007590,-0.192777,0.084504,0.004305,-1.927768,-24.019714,-0.191691,0.000000
10.820001,0.021599,-24.019714,0.004126,-0.007449,-0.189211,0.096076,0.004894,-1.892114,-24.019714,-0.188206,0.000000
11.030001,0.044685,-23.975233,0.004260,-0.007315,-0.185813,0.198770,0.010126,-1.858126,-23.975233,-0.184703,0.000000
11.240001,0.026817,-24.064194,0.004411,-0.007180,-0.182377,0.119289,0.006077,-1.823774,-24.064194,-0.181198,0.000000
11.450001,0.044685,-24.019714,0.004544,-0.007048,-0.179030,0.198770,0.010126,-1.790301,-24.019714,-0.177713,0.000000
11.660001,0.016762,-24.108675,0.004700,-0.006905,-0.175380,0.074560,0.003798,-1.753799,-24.108675,-0.174208,0.000000
11.870001,0.016388,-24.019714,0.004838,-0.006762,-0.171746,0.072897,0.003714,-1.717464,-24.019714,-0.170705,0.000000
12.080001,0.007454,-24.019714,0.004984,-0.006622,-0.168208,0.033157,0.001689,-1.682083,-24.019714,-0.167202,0.000000
12.290001,0.027557,-24.108675,0.005105,-0.006488,-0.164791,0.122581,0.006245,-1.647913,-24.108675,-0.163715,0.000000
12.500001,0.025696,-24.019714,0.005269,-0.006355,-0.161426,0.114301,0.005823,-1.614258,-24.019714,-0.160212,0.000000
12.710001,0.007820,-24.108675,0.005424,-0.006211,-0.157757,0.034786,0.001772,-1.577574,-24.108675,-0.156708,0.000000
12.920001,0.015640,-24.108675,0.005540,-0.006078,-0.154375,0.069571,0.003544,-1.543753,-24.108675,-0.153222,0.000000
13.130001,0.049904,-24.064194,0.005708,-0.005936,-0.150786,0.221983,0.011308,-1.507857,-24.064194,-0.149718,0.000000
13.340001,0.028305,-24.108675,0.005842,-0.005797,-0.147238,0.125907,0.006414,-1.472385,-24.108675,-0.146215,0.000000
13.550000,0.030907,-24.064194,0.006006,-0.005666,-0.143917,0.137480,0.007004,-1.439168,-24.064194,-0.142712,0.000000
13.760000,0.033516,-24.064194,0.006127,-0.005525,-0.140344,0.149086,0.007595,-1.403439,-24.064194,-0.139225,0.000000
13.970000,0.045433,-24.108675,0.006252,-0.005389,-0.136892,0.202096,0.010295,-1.368921,-24.108675,-0.135722,0.000000
14.180000,0.020111,-24.064194,0.006428,-0.005248,-0.133310,0.089459,0.004557,-1.333101,-24.064194,-0.132217,0.000000
14.390000,0.051765,-24.108675,0.006536,-0.005110,-0.129790,0.230264,0.011730,-1.297901,-24.108675,-0.128732,0.000000
14.600000,0.047295,-24.064194,0.006670,-0.004973,-0.126303,0.210377,0.010717,-1.263035,-24.064194,-0.125229,0.000000
14.810000,0.048042,-24.108675,0.006834,-0.004832,-0.122740,0.213703,0.010887,-1.227396,-24.108675,-0.121724,0.000000
15.020000,0.027557,-24.153156,0.006972,-0.004696,-0.119270,0.122581,0.006245,-1.192696,-24.153156,-0.118220,0.000000
15.230000,0.059586,-24.108675,0.007110,-0.004562,-0.115880,0.265050,0.013502,-1.158799,-24.108675,-0.114734,0.000000
15.440001,0.044312,-24.153156,0.007278,-0.004420,-0.112272,0.197107,0.010041,-1.122721,-24.153156,-0.111230,0.000000
15.650001,0.037987,-24.064194,0.007368,-0.004285,-0.108846,0.168974,0.008608,-1.088460,-24.064194,-0.107727,0.000000
15.860001,0.047295,-24.108675,0.007541,-0.004150,-0.105403,0.210377,0.010717,-1.054033,-24.108675,-0.104241,0.000000
16.070002,0.040962,-24.153156,0.007670,-0.004010,-0.101847,0.182209,0.009282,-1.018470,-24.153156,-0.100737,0.000000
16.280001,0.047295,-24.064194,0.007808,-0.003872,-0.098344,0.210377,0.010717,-0.983437,-24.064194,-0.097234,0.000000
16.490002,0.081924,-24.153156,0.007950,-0.003738,-0.094945,0.364418,0.018564,-0.949448,-24.153156,-0.093731,0.000000
16.700001,0.067032,-24.153156,0.008097,-0.003599,-0.091423,0.298173,0.015190,-0.914234,-24.153156,-0.090244,0.000000
16.910002,0.068146,-24.153156,0.008248,-0.003457,-0.087816,0.303127,0.015442,-0.878156,-24.153156,-0.086741,0.000000
17.120001,0.068520,-24.153156,0.008369,-0.003317,-0.084261,0.304790,0.015527,-0.842608,-24.153156,-0.083237,0.000000
17.330000,0.061813,-24.108675,0.008511,-0.003181,-0.080809,0.274960,0.014007,-0.808090,-24.108675,-0.079751,0.000000
17.540001,0.038727,-24.197638,0.008688,-0.003045,-0.077331,0.172265,0.008776,-0.773315,-24.197638,-0.076247,0.000000
17.750000,0.038727,-24.197638,0.008826,-0.002907,-0.073845,0.172265,0.008776,-0.738448,-24.197638,-0.072743,0.000000
17.960001,0.013779,-24.153156,0.008977,-0.002770,-0.070358,0.061291,0.003122,-0.703582,-24.153156,-0.069258,0.000000
18.170000,0.010429,-24.153156,0.009102,-0.002637,-0.066985,0.046392,0.002363,-0.669851,-24.153156,-0.065754,0.000000
18.380001,0.036499,-24.153156,0.009261,-0.002492,-0.063308,0.162356,0.008271,-0.633077,-24.153156,-0.062249,0.000000
18.590000,0.059952,-24.197638,0.009429,-0.002356,-0.059830,0.266679,0.013585,-0.598301,-24.197638,-0.058746,0.000000
18.800001,0.071495,-24.153156,0.009563,-0.002227,-0.056569,0.318026,0.016201,-0.565690,-24.153156,-0.055259,0.000000
19.010000,0.081177,-24.153156,0.009688,-0.002084,-0.052945,0.361092,0.018395,-0.529446,-24.153156,-0.051756,0.000000
19.220001,0.053253,-24.197638,0.009822,-0.001951,-0.049562,0.236882,0.012067,-0.495624,-24.197638,-0.048253,0.000000
19.430000,0.059952,-24.108675,0.009998,-0.001804,-0.045824,0.266679,0.013585,-0.458245,-24.108675,-0.044766,0.000000
19.640001,0.052505,-24.197638,0.010149,-0.001665,-0.042286,0.233556,0.011898,-0.422864,-24.197638,-0.041263,0.000000
19.850000,0.042084,-24.153156,0.010287,-0.001527,-0.038792,0.187198,0.009536,-0.387921,-24.153156,-0.037760,0.000000
20.060001,0.020485,-24.197638,0.010447,-0.001393,-0.035375,0.091121,0.004642,-0.353751,-24.197638,-0.034256,0.000000
20.270000,0.009682,-24.197638,0.010529,-0.001258,-0.031966,0.043066,0.002194,-0.319657,-24.197638,-0.030770,0.000000
20.480001,0.016014,-24.108675,0.010675,-0.001119,-0.028411,0.071234,0.003629,-0.284109,-24.108675,-0.027266,0.000000
20.690001,0.041710,-24.242119,0.010861,-0.000983,-0.024968,0.185535,0.009452,-0.249682,-24.242119,-0.023763,0.000000
20.900002,0.083038,-24.197638,0.010973,-0.000843,-0.021404,0.369373,0.018817,-0.214043,-24.197638,-0.020276,0.000000
21.110001,0.084908,-24.242119,0.011141,-0.000705,-0.017900,0.377688,0.019240,-0.178995,-24.242119,-0.016773,0.000000
21.320002,0.095329,-24.197638,0.011257,-0.000572,-0.014526,0.424046,0.021602,-0.145264,-24.197638,-0.013268,0.000000
21.530001,0.100914,-24.108675,0.011387,-0.000435,-0.011040,0.448888,0.022867,-0.110398,-24.108675,-0.009765,0.000000
21.740002,0.128471,-24.197638,0.011551,-0.000293,-0.007441,0.571469,0.029112,-0.074411,-24.197638,-0.006280,0.000000
21.950001,0.159378,-24.242119,0.011701,-0.000150,-0.003799,0.708949,0.036116,-0.037985,-24.242119,-0.002775,0.000000
22.160002,0.248375,-24.197638,0.011848,-0.000012,-0.000304,1.104827,0.056283,-0.003043,-24.197638,0.000728,0.000000
22.370001,0.519089,-24.242119,0.011973,0.000123,0.003131,2.309022,0.117627,0.031309,-24.242119,0.004215,0.000000
22.580002,0.594307,-24.197638,0.012051,-0.000000,-0.000000,2.643609,0.134672,-0.000000,-24.197638,0.000218,0.000000
22.790001,0.561913,-24.242119,0.012059,-0.000000,-0.000000,2.499512,0.127331,-0.000000,-24.242119,0.000218,0.000000
23.000002,0.662079,-24.242119,0.012055,-0.000000,-0.000000,2.945074,0.150029,-0.000000,-24.242119,0.000269,0.000000
23.210001,0.623352,-24.197638,0.012033,-0.000000,-0.000000,2.772808,0.141254,-0.000000,-24.197638,0.000625,0.000000
23.420002,0.625587,-24.286600,0.012051,0.000000,0.000009,2.782752,0.141760,0.000091,-24.286600,0.000972,0.000000
23.630001,0.738045,-24.197638,0.012055,0.000017,0.000435,3.282987,0.167243,0.004345,-24.197638,0.001328,0.000000
23.840002,0.790176,-24.242119,0.012081,0.000027,0.000686,3.514880,0.179057,0.006858,-24.242119,0.001674,0.000000
24.050001,0.876198,-24.242119,0.012033,0.000037,0.000946,3.897522,0.198549,0.009462,-24.242119,0.002021,0.000000
24.260000,0.959236,-24.286600,0.012059,0.000054,0.001370,4.266895,0.217366,0.013701,-24.286600,0.002377,0.000000
24.470001,1.083611,-24.286600,0.012089,0.000072,0.001821,4.820140,0.245550,0.018213,-24.286600,0.002724,0.000000
24.680000,1.188988,-24.242119,0.012094,0.000086,0.002177,5.288882,0.269428,0.021771,-24.242119,0.003070,0.000000
24.890001,1.170372,-24.286600,0.012120,0.000094,0.002394,5.206075,0.265210,0.023936,-24.286600,0.003426,0.000000
25.100000,1.336823,-24.197638,0.012115,0.000109,0.002775,5.946484,0.302928,0.027751,-24.197638,0.003773,0.000000
25.310001,1.448158,-24.242119,0.012124,0.000124,0.003149,6.441730,0.328157,0.031490,-24.242119,0.004119,0.000000
25.520000,1.619453,-24.331079,0.012120,0.000137,0.003470,7.203689,0.366973,0.034700,-24.331079,0.004475,0.000000
25.730001,1.763557,-24.286600,0.012137,0.000151,0.003833,7.844695,0.399628,0.038333,-24.286600,0.004822,0.000000
25.940001,1.918839,-24.286600,0.012180,0.000163,0.004138,8.535420,0.434815,0.041376,-24.286600,0.005178,0.000000
26.150002,2.002251,-24.331079,0.012158,0.000174,0.004424,8.906456,0.453716,0.044238,-24.331079,0.005524,0.000000
26.360001,2.276314,-24.286600,0.012215,0.000195,0.004943,10.125549,0.515820,0.049431,-24.286600,0.005871,0.000000
26.570002,2.445000,-24.331079,0.012189,0.000208,0.005282,10.875902,0.554045,0.052822,-24.331079,0.006227,0.000000
26.780001,2.524689,-24.286600,0.012240,0.000217,0.005517,11.230376,0.572103,0.055169,-24.286600,0.006574,0.000000
26.990002,2.722046,-24.286600,0.012245,0.000232,0.005898,12.108265,0.616824,0.058984,-24.286600,0.006922,0.000000
27.200001,2.895943,-24.286600,0.012245,0.000245,0.006227,12.881797,0.656230,0.062269,-24.286600,0.007276,0.000000
27.410002,3.192726,-24.286600,0.012271,0.000261,0.006627,14.201955,0.723482,0.066266,-24.286600,0.007623,0.000000
27.620001,3.388962,-24.331079,0.012271,0.000273,0.006929,15.074855,0.767950,0.069294,-24.331079,0.007971,0.000000
27.830002,3.557274,-24.331079,0.012301,0.000282,0.007164,15.823545,0.806090,0.071640,-24.331079,0.008325,0.000000
28.040001,3.731178,-24.331079,0.012271,0.000292,0.007424,16.597111,0.845497,0.074244,-24.331079,0.008673,0.000000
28.250002,4.162384,-24.375561,0.012309,0.000318,0.008074,18.515209,0.943210,0.080739,-24.375561,0.009028,0.000000
28.460001,4.316170,-24.331079,0.012331,0.000329,0.008369,19.199282,0.978058,0.083692,-24.331079,0.009376,0.000000
28.670002,4.509430,-24.331079,0.012327,0.000341,0.008655,20.058947,1.021851,0.086553,-24.331079,0.009723,0.000000
28.880001,4.801376,-24.331079,0.012365,0.000356,0.009055,21.357588,1.088007,0.090550,-24.331079,0.010078,0.000000
29.090002,5.071716,-24.331079,0.012365,0.000370,0.009402,22.560122,1.149267,0.094017,-24.331079,0.010425,0.000000
29.300001,5.390091,-24.286600,0.012340,0.000385,0.009783,23.976322,1.221412,0.097832,-24.286600,0.010772,0.000000
29.510002,5.632507,-24.242119,0.012396,0.000397,0.010078,25.054644,1.276344,0.100784,-24.242119,0.011128,0.000000
29.720001,5.749809,-24.286600,0.012387,0.000404,0.010269,25.576429,1.302925,0.102692,-24.286600,0.011474,0.000000
29.930002,5.871574,-24.331079,0.012400,0.000413,0.010495,26.118067,1.330518,0.104948,-24.331079,0.011821,0.000000
30.140001,6.386192,-24.375561,0.012434,0.000436,0.011067,28.407202,1.447132,0.110670,-24.375561,0.012177,0.000000
30.350002,6.770851,-24.375561,0.012426,0.000452,0.011474,30.118250,1.534297,0.114743,-24.375561,0.012523,0.000000
30.560001,7.040451,-24.375561,0.012443,0.000464,0.011777,31.317490,1.595389,0.117771,-24.375561,0.012870,0.000000
30.770002,7.213600,-24.375561,0.012456,0.000475,0.012072,32.087696,1.634625,0.120723,-24.375561,0.013226,0.000000
30.980001,7.634010,-24.375561,0.012482,0.000492,0.012505,33.957775,1.729891,0.125053,-24.375561,0.013573,0.000000
31.190001,7.988884,-24.331079,0.012508,0.000506,0.012861,35.536331,1.810307,0.128611,-24.331079,0.013928,0.000000
31.400002,8.307632,-24.331079,0.012508,0.000521,0.013235,36.954193,1.882536,0.132350,-24.331079,0.014275,0.000000
31.610001,8.523605,-24.286600,0.012521,0.000532,0.013521,37.914890,1.931477,0.135212,-24.286600,0.014622,0.000000
31.820002,8.832306,-24.420042,0.012495,0.000546,0.013868,39.288059,2.001429,0.138679,-24.420042,0.014978,0.000000
32.030003,9.172279,-24.375561,0.012538,0.000560,0.014224,40.800335,2.078468,0.142236,-24.375561,0.015324,0.000000
32.240002,9.532738,-24.331079,0.012547,0.000575,0.014613,42.403736,2.160149,0.146127,-24.331079,0.015671,0.000000
32.450001,9.972137,-24.420042,0.012564,0.000593,0.015056,44.358284,2.259719,0.150563,-24.420042,0.016027,0.000000
32.660000,10.092789,-24.286600,0.012603,0.000605,0.015368,44.894966,2.287059,0.153682,-24.286600,0.016373,0.000000
32.870003,10.506493,-24.375561,0.012594,0.000619,0.015724,46.735214,2.380805,0.157240,-24.375561,0.016720,0.000000
33.080002,10.533676,-24.375561,0.012590,0.000625,0.015880,46.856133,2.386965,0.158799,-24.375561,0.017076,0.000000
33.290001,11.265762,-24.375561,0.012624,0.000649,0.016495,50.112614,2.552858,0.164946,-24.375561,0.017423,0.000000
33.500000,11.270599,-24.375561,0.012646,0.000656,0.016652,50.134129,2.553954,0.166520,-24.375561,0.017778,0.000000
33.710003,11.450455,-24.375561,0.012628,0.000665,0.016903,50.934166,2.594710,0.169033,-24.375561,0.018125,0.000000
33.920002,11.759155,-24.420042,0.012667,0.000677,0.017206,52.307335,2.664663,0.172061,-24.420042,0.018472,0.000000
34.130001,12.449532,-24.420042,0.012676,0.000702,0.017831,55.378281,2.821104,0.178314,-24.420042,0.018828,0.000000
34.340000,12.827492,-24.420042,0.012693,0.000717,0.018204,57.059532,2.906751,0.182038,-24.420042,0.019174,0.000000
34.550003,12.941063,-24.464523,0.012672,0.000728,0.018499,57.564724,2.932487,0.184991,-24.464523,0.019522,0.000000
34.760002,13.283646,-24.420042,0.012697,0.000744,0.018888,59.088608,3.010117,0.188881,-24.420042,0.019877,0.000000
34.970001,13.416954,-24.420042,0.012697,0.000750,0.019062,59.681591,3.040325,0.190622,-24.420042,0.020225,0.000000
35.180000,14.050735,-24.375561,0.012732,0.000773,0.019644,62.500793,3.183942,0.196436,-24.375561,0.020572,0.000000
35.390003,14.114037,-24.420042,0.012745,0.000782,0.019851,62.782372,3.198286,0.198510,-24.420042,0.020927,0.000000
35.600002,14.197449,-24.420042,0.012762,0.000789,0.020051,63.153404,3.217188,0.200509,-24.420042,0.021274,0.000000
35.810001,14.592163,-24.464523,0.012749,0.000804,0.020432,64.909180,3.306632,0.204324,-24.464523,0.021630,0.000000
36.020000,15.191681,-24.464523,0.012784,0.000826,0.020979,67.575974,3.442484,0.209789,-24.464523,0.021977,0.000000
36.230003,15.615440,-24.420042,0.012784,0.000841,0.021351,69.460945,3.538509,0.213513,-24.420042,0.022323,0.000000
36.440002,15.544319,-24.420042,0.012822,0.000850,0.021603,69.144585,3.522393,0.216027,-24.420042,0.022679,0.000000
36.650002,15.853760,-24.464523,0.012827,0.000862,0.021898,70.521042,3.592513,0.218979,-24.464523,0.023026,0.000000
36.860001,16.126335,-24.420042,0.012810,0.000875,0.022237,71.733521,3.654280,0.222370,-24.420042,0.023372,0.000000
37.070004,16.613029,-24.509005,0.012870,0.000892,0.022652,73.898445,3.764566,0.226518,-24.509005,0.023728,0.000000
37.280003,16.905716,-24.464523,0.012874,0.000908,0.023052,75.200378,3.830890,0.230515,-24.464523,0.024075,0.000000
37.490002,16.958588,-24.420042,0.012874,0.000917,0.023294,75.435562,3.842871,0.232938,-24.420042,0.024422,0.000000
37.700001,17.059875,-24.509005,0.012874,0.000930,0.023615,75.886116,3.865823,0.236147,-24.509005,0.024777,0.000000
37.910004,17.796059,-24.420042,0.012913,0.000948,0.024092,79.160820,4.032644,0.240916,-24.420042,0.025124,0.000000
38.120003,18.205292,-24.464523,0.012935,0.000966,0.024543,80.981186,4.125378,0.245428,-24.464523,0.025471,0.000000
38.330002,18.199707,-24.464523,0.012909,0.000976,0.024787,80.956337,4.124113,0.247865,-24.464523,0.025827,0.000000
38.540001,18.472282,-24.509005,0.012943,0.000989,0.025115,82.168816,4.185879,0.251150,-24.509005,0.026173,0.000000
38.750000,18.722145,-24.509005,0.012939,0.001005,0.025531,83.280258,4.242499,0.255314,-24.509005,0.026529,0.000000
38.960003,19.294113,-24.464523,0.012978,0.001021,0.025931,85.824501,4.372108,0.259311,-24.464523,0.026876,0.000000
39.170002,19.300438,-24.509005,0.012991,0.001029,0.026148,85.852638,4.373541,0.261476,-24.509005,0.027222,0.000000
39.380001,19.438965,-24.553486,0.012978,0.001040,0.026425,86.468834,4.404932,0.264246,-24.553486,0.027578,0.000000
39.590000,19.888412,-24.509005,0.012995,0.001058,0.026876,88.468079,4.506779,0.268758,-24.509005,0.027925,0.000000
39.800003,20.310684,-24.509005,0.013021,0.001074,0.027275,90.346436,4.602467,0.272755,-24.509005,0.028272,0.000000
40.010002,20.702797,-24.509005,0.013029,0.001091,0.027708,92.090637,4.691321,0.277085,-24.509005,0.028627,0.000000
40.220001,20.770195,-24.509005,0.013060,0.001103,0.028011,92.390442,4.706594,0.280113,-24.509005,0.028974,0.000000
40.430000,20.943718,-24.553486,0.013073,0.001114,0.028290,93.162308,4.745914,0.282898,-24.553486,0.029321,0.000000
40.640003,21.140335,-24.509005,0.013081,0.001124,0.028558,94.036903,4.790469,0.285578,-24.509005,0.029677,0.000000
40.850002,21.391312,-24.553486,0.013077,0.001137,0.028871,95.153305,4.847341,0.288712,-24.553486,0.030023,0.000000
41.060001,22.016525,-24.553486,0.013094,0.001155,0.029339,97.934395,4.989016,0.293390,-24.553486,0.030379,0.000000
41.270000,22.037003,-24.509005,0.013098,0.001163,0.029539,98.025482,4.993656,0.295388,-24.509005,0.030726,0.000000
41.480003,22.199730,-24.553486,0.013120,0.001175,0.029842,98.749329,5.030531,0.298416,-24.553486,0.031074,0.000000
41.690002,22.650299,-24.509005,0.013120,0.001189,0.030206,100.753563,5.132631,0.302065,-24.509005,0.031428,0.000000
41.900002,23.397285,-24.553486,0.013133,0.001213,0.030805,104.076324,5.301901,0.308045,-24.553486,0.031776,0.000000
42.110001,23.418510,-24.509005,0.013159,0.001224,0.031091,104.170738,5.306710,0.310906,-24.509005,0.032123,0.000000
42.320004,23.547722,-24.553486,0.013172,0.001235,0.031360,104.745499,5.335990,0.313601,-24.553486,0.032479,0.000000
42.530003,23.715286,-24.553486,0.013159,0.001248,0.031707,105.490860,5.373961,0.317068,-24.553486,0.032826,0.000000
42.740002,24.061592,-24.597965,0.013189,0.001260,0.032010,107.031303,5.452435,0.320096,-24.597965,0.033172,0.000000
42.950001,24.438065,-24.597965,0.013215,0.001275,0.032374,108.705940,5.537745,0.323745,-24.597965,0.033528,0.000000
43.160004,24.954170,-24.553486,0.013219,0.001292,0.032807,111.001694,5.654696,0.328075,-24.553486,0.033875,0.000000
43.370003,25.023804,-24.597965,0.013232,0.001302,0.033068,111.311440,5.670475,0.330679,-24.597965,0.034231,0.000000
43.580002,25.376816,-24.597965,0.013249,0.001315,0.033398,112.881714,5.750469,0.333979,-24.597965,0.034577,0.000000
43.790001,25.980804,-24.553486,0.013249,0.001336,0.033926,115.568390,5.887334,0.339263,-24.553486,0.034924,0.000000
44.000004,26.297691,-24.642447,0.013301,0.001349,0.034265,116.977974,5.959142,0.342654,-24.642447,0.035280,0.000000
44.210003,26.258965,-24.597965,0.013284,0.001358,0.034499,116.805710,5.950366,0.344986,-24.597965,0.035626,0.000000
44.420002,26.629478,-24.553486,0.013301,0.001372,0.034845,118.453835,6.034326,0.348453,-24.553486,0.035973,0.000000
44.630001,26.834282,-24.642447,0.013318,0.001383,0.035124,119.364845,6.080735,0.351238,-24.642447,0.036329,0.000000
44.840004,26.930725,-24.597965,0.013331,0.001391,0.035340,119.793846,6.102590,0.353403,-24.597965,0.036676,0.000000
45.050003,28.048210,-24.553486,0.013323,0.001417,0.035982,124.764671,6.355815,0.359822,-24.553486,0.037022,0.000000
45.260002,28.211311,-24.553486,0.013366,0.001428,0.036259,125.490181,6.392775,0.362593,-24.553486,0.037378,0.000000
45.470001,28.317070,-24.553486,0.013374,0.001436,0.036485,125.960617,6.416740,0.364849,-24.553486,0.037725,0.000000
45.680000,29.072983,-24.642447,0.013357,0.001456,0.036988,129.323090,6.588032,0.369875,-24.642447,0.038072,0.000000
45.890003,29.604729,-24.509005,0.013374,0.001472,0.037387,131.688416,6.708528,0.373872,-24.509005,0.038427,0.000000
46.100002,29.987900,-24.642447,0.013370,0.001488,0.037794,133.392838,6.795355,0.377944,-24.642447,0.038774,0.000000
46.310001,29.984177,-24.642447,0.013400,0.001498,0.038046,133.376282,6.794512,0.380458,-24.642447,0.039130,0.000000
46.520000,30.392670,-24.597965,0.013417,0.001511,0.038376,135.193344,6.887077,0.383758,-24.597965,0.039476,0.000000
46.730003,30.910271,-24.597965,0.013426,0.001526,0.038748,137.495758,7.004367,0.387482,-24.597965,0.039823,0.000000
46.940002,31.469948,-24.553486,0.013452,0.001543,0.039181,139.985321,7.131192,0.391812,-24.553486,0.040179,0.000000
47.150002,31.597672,-24.686928,0.013461,0.001550,0.039372,140.553467,7.160135,0.393720,-24.686928,0.040526,0.000000
47.360001,31.999458,-24.597965,0.013461,0.001565,0.039754,142.340698,7.251181,0.397535,-24.597965,0.040872,0.000000
47.570004,32.237778,-24.642447,0.013495,0.001577,0.040049,143.400803,7.305185,0.400487,-24.642447,0.041228,0.000000
47.780003,33.239082,-24.642447,0.013469,0.001597,0.040551,147.854828,7.532084,0.405514,-24.642447,0.041575,0.000000
47.990002,33.539963,-24.553486,0.013517,0.001611,0.040907,149.193207,7.600265,0.409071,-24.553486,0.041923,0.000000
48.200001,33.725029,-24.642447,0.013495,0.001622,0.041202,150.016418,7.642201,0.412024,-24.642447,0.042277,0.000000
48.410004,34.184166,-24.642447,0.013495,0.001636,0.041549,152.058762,7.746243,0.415491,-24.642447,0.042625,0.000000
48.620003,34.572922,-24.597965,0.013551,0.001646,0.041800,153.788040,7.834336,0.418004,-24.597965,0.042980,0.000000
48.830002,35.366821,-24.642447,0.013547,0.001663,0.042235,157.319473,8.014236,0.422349,-24.642447,0.043326,0.000000
49.040001,35.563805,-24.642447,0.013555,0.001671,0.042451,158.195709,8.058873,0.424514,-24.642447,0.043675,0.000000
49.250004,35.825211,-24.686928,0.013568,0.001684,0.042763,159.358490,8.118109,0.427633,-24.686928,0.044029,0.000000
49.460003,36.470535,-24.642447,0.013573,0.001700,0.043180,162.229050,8.264341,0.431796,-24.642447,0.044377,0.000000
49.670002,37.534401,-24.642447,0.013581,0.001720,0.043682,166.961349,8.505417,0.436822,-24.642447,0.044724,0.000000
49.880001,37.768250,-24.686928,0.013594,0.001732,0.043996,168.001572,8.558408,0.439956,-24.686928,0.045080,0.000000
50.090004,38.057213,-24.642447,0.013616,0.001743,0.044264,169.286942,8.623888,0.442636,-24.642447,0.045426,0.000000
50.300003,38.596779,-24.642447,0.013637,0.001756,0.044603,171.687042,8.746156,0.446027,-24.642447,0.045773,0.000000
50.510002,39.233162,-24.642447,0.013633,0.001772,0.045018,174.517822,8.890362,0.450175,-24.642447,0.046129,0.000000
50.720001,39.777946,-24.642447,0.013672,0.001786,0.045357,176.941147,9.013811,0.453567,-24.642447,0.046475,0.000000
50.930004,40.296661,-24.686928,0.013646,0.001800,0.045720,179.248505,9.131354,0.457200,-24.686928,0.046831,0.000000
51.140003,40.267616,-24.686928,0.013655,0.001804,0.045834,179.119308,9.124772,0.458336,-24.686928,0.047178,0.000000
51.350002,41.525864,-24.731409,0.013668,0.001828,0.046432,184.716263,9.409895,0.464316,-24.731409,0.047525,0.000000
51.560001,42.238586,-24.686928,0.013680,0.001844,0.046848,187.886612,9.571400,0.468479,-24.686928,0.047880,0.000000
51.770004,42.499245,-24.686928,0.013711,0.001855,0.047117,189.046082,9.630466,0.471174,-24.686928,0.048227,0.000000
51.980003,42.825439,-24.686928,0.013680,0.001864,0.047351,190.497070,9.704384,0.473505,-24.686928,0.048574,0.000000
52.190002,43.508377,-24.642447,0.013724,0.001881,0.047767,193.534927,9.859139,0.477669,-24.642447,0.048930,0.000000
52.400002,44.227425,-24.731409,0.013724,0.001895,0.048123,196.733414,10.022078,0.481227,-24.731409,0.049276,0.000000
52.610001,44.920036,-24.686928,0.013754,0.001914,0.048609,199.814301,10.179026,0.486086,-24.686928,0.049623,0.000000
52.820004,45.310654,-24.642447,0.013749,0.001922,0.048825,201.551849,10.267541,0.488251,-24.642447,0.049979,0.000000
53.030003,45.775749,-24.686928,0.013749,0.001935,0.049137,203.620697,10.372933,0.491370,-24.686928,0.050325,0.000000
53.240002,46.370804,-24.686928,0.013784,0.001948,0.049476,206.267639,10.507774,0.494761,-24.686928,0.050681,0.000000
53.450001,46.965111,-24.731409,0.013767,0.001961,0.049814,208.911240,10.642446,0.498138,-24.731409,0.051028,0.000000
53.660004,48.144409,-24.686928,0.013801,0.001983,0.050378,214.157028,10.909679,0.503785,-24.686928,0.051375,0.000000
53.870003,48.572266,-24.686928,0.013818,0.001994,0.050656,216.060226,11.006633,0.506555,-24.686928,0.051730,0.000000
54.080002,49.013153,-24.731409,0.013818,0.002008,0.050993,218.021393,11.106539,0.509931,-24.731409,0.052077,0.000000
54.290001,49.664436,-24.731409,0.013836,0.002020,0.051297,220.918442,11.254122,0.512974,-24.731409,0.052424,0.000000
54.500004,50.611382,-24.731409,0.013810,0.002039,0.051791,225.130676,11.468703,0.517910,-24.731409,0.052780,0.000000
54.710003,51.275688,-24.731409,0.013840,0.002051,0.052095,228.085648,11.619237,0.520953,-24.731409,0.053126,0.000000
54.920002,51.194885,-24.731409,0.013862,0.002058,0.052268,227.726227,11.600926,0.522679,-24.731409,0.053473,0.000000
55.130001,51.859940,-24.775890,0.013866,0.002070,0.052572,230.684540,11.751630,0.525722,-24.775890,0.053829,0.000000
55.340004,52.518669,-24.731409,0.013879,0.002087,0.053005,233.614700,11.900901,0.530052,-24.731409,0.054175,0.000000
55.550003,53.983208,-24.686928,0.013879,0.002106,0.053482,240.129303,12.232770,0.534821,-24.686928,0.054524,0.000000
55.760002,54.492241,-24.820372,0.013892,0.002117,0.053777,242.393600,12.348118,0.537773,-24.820372,0.054878,0.000000
55.970001,55.039261,-24.731409,0.013900,0.002132,0.054150,244.826859,12.472075,0.541497,-24.731409,0.055226,0.000000
56.180004,55.698730,-24.775890,0.013922,0.002145,0.054489,247.760330,12.621512,0.544889,-24.775890,0.055580,0.000000
56.390003,56.171646,-24.731409,0.013931,0.002155,0.054731,249.863968,12.728677,0.547311,-24.731409,0.055929,0.000000
56.600002,57.432121,-24.731409,0.013948,0.002175,0.055252,255.470840,13.014305,0.552519,-24.731409,0.056275,0.000000
56.810001,57.681244,-24.775890,0.013939,0.002185,0.055494,256.578979,13.070757,0.554941,-24.775890,0.056631,0.000000
57.020004,57.828331,-24.686928,0.013987,0.002190,0.055624,257.233276,13.104087,0.556243,-24.686928,0.056978,0.000000
57.230003,58.802086,-24.820372,0.013948,0.002206,0.056041,261.564728,13.324742,0.560407,-24.820372,0.057325,0.000000
57.440002,60.093842,-24.775890,0.013943,0.002227,0.056578,267.310760,13.617459,0.565781,-24.775890,0.057680,0.000000
57.650002,61.080627,-24.775890,0.013987,0.002243,0.056969,271.700195,13.841068,0.569687,-24.775890,0.058027,0.000000
57.860004,61.404968,-24.820372,0.013995,0.002254,0.057246,273.142944,13.914564,0.572458,-24.820372,0.058374,0.000000
58.070004,62.070770,-24.731409,0.014004,0.002267,0.057585,276.104584,14.065437,0.575849,-24.731409,0.058729,0.000000
58.280003,62.904137,-24.820372,0.013999,0.002281,0.057932,279.811584,14.254281,0.579316,-24.820372,0.059076,0.000000
58.490002,63.616859,-24.820372,0.014012,0.002295,0.058287,282.981934,14.415787,0.582874,-24.820372,0.059432,0.000000
58.700005,64.566780,-24.775890,0.014047,0.002309,0.058660,287.207367,14.631042,0.586598,-24.775890,0.059779,0.000000
58.910004,65.025551,-24.775890,0.014060,0.002318,0.058885,289.248108,14.735001,0.588854,-24.775890,0.060125,0.000000
59.120003,65.801933,-24.686928,0.014038,0.002333,0.059267,292.701630,14.910932,0.592669,-24.686928,0.060481,0.000000
59.330002,67.013634,-24.864851,0.014056,0.002353,0.059770,298.091522,15.185506,0.597695,-24.864851,0.060828,0.000000
59.540005,67.017357,-24.775890,0.014073,0.002348,0.059632,298.108093,15.186350,0.596318,-24.775890,0.059856,0.000000
59.750004,66.590248,-24.775890,0.014077,0.002348,0.059632,296.208221,15.089566,0.596318,-24.775890,0.059856,0.000000
59.960003,66.272987,-24.864851,0.014112,0.002346,0.059597,294.796967,15.017673,0.595970,-24.864851,0.059632,0.000000
60.170002,65.985893,-24.775890,0.014094,0.002346,0.059579,293.519897,14.952618,0.595788,-24.775890,0.059632,0.000000
60.380001,65.749443,-24.775890,0.014086,0.002345,0.059570,292.468140,14.899036,0.595697,-24.775890,0.059632,0.000000
60.590004,65.534203,-24.820372,0.014081,0.002345,0.059562,291.510681,14.850263,0.595621,-24.820372,0.059632,0.000000
60.800003,65.349876,-24.775890,0.014094,0.002345,0.059562,290.690765,14.808494,0.595621,-24.775890,0.059632,0.000000
61.010002,65.168907,-24.909332,0.014068,0.002345,0.059553,289.885773,14.767486,0.595531,-24.909332,0.059632,0.000000
61.220001,65.015862,-24.775890,0.014099,0.002345,0.059553,289.204987,14.732804,0.595531,-24.775890,0.059632,0.000000
61.430004,64.897820,-24.864851,0.014086,0.002345,0.059553,288.679932,14.706056,0.595531,-24.864851,0.059632,0.000000
61.640003,64.754463,-24.820372,0.014103,0.002345,0.059553,288.042236,14.673572,0.595531,-24.820372,0.059632,0.000000
61.850002,64.647591,-24.775890,0.014107,0.002344,0.059544,287.566833,14.649354,0.595440,-24.775890,0.059632,0.000000
62.060001,64.523964,-24.864851,0.014081,0.002344,0.059544,287.016937,14.621340,0.595440,-24.864851,0.059632,0.000000
62.270004,64.431236,-24.775890,0.014094,0.002344,0.059544,286.604462,14.600327,0.595440,-24.775890,0.059632,0.000000
62.480003,64.346703,-24.820372,0.014103,0.002344,0.059544,286.228424,14.581172,0.595440,-24.820372,0.059632,0.000000
62.690002,64.243935,-24.909332,0.014099,0.002344,0.059544,285.771301,14.557883,0.595440,-24.909332,0.059632,0.000000
62.900002,64.182121,-24.820372,0.014094,0.002344,0.059536,285.496338,14.543877,0.595364,-24.820372,0.059632,0.000000
63.110004,64.091255,-24.864851,0.014094,0.002344,0.059536,285.092133,14.523286,0.595364,-24.864851,0.059632,0.000000
63.320004,64.014549,-24.820372,0.014094,0.002344,0.059536,284.750946,14.505904,0.595364,-24.820372,0.059632,0.000000
63.530003,63.935616,-24.864851,0.014107,0.002344,0.059536,284.399811,14.488018,0.595364,-24.864851,0.059632,0.000000
63.740002,63.869331,-24.909332,0.014125,0.002344,0.059536,284.104980,14.472998,0.595364,-24.909332,0.059632,0.000000
63.950005,63.826881,-24.820372,0.014086,0.002344,0.059536,283.916138,14.463378,0.595364,-24.820372,0.059632,0.000000
64.160004,63.747566,-24.909332,0.014103,0.002344,0.059536,283.563324,14.445405,0.595364,-24.909332,0.059632,0.000000
64.370003,63.696175,-24.820372,0.014086,0.002344,0.059536,283.334747,14.433760,0.595364,-24.820372,0.059632,0.000000
64.580002,63.642555,-24.864851,0.014073,0.002344,0.059536,283.096222,14.421609,0.595364,-24.864851,0.059632,0.000000
64.790001,63.579994,-24.864851,0.014116,0.002344,0.059536,282.817932,14.407433,0.595364,-24.864851,0.059632,0.000000
65.000000,63.534187,-24.820372,0.014120,0.002344,0.059536,282.614166,14.397052,0.595364,-24.820372,0.059632,0.000000
65.210007,63.473869,-24.909332,0.014099,0.002344,0.059527,282.345886,14.383385,0.595273,-24.909332,0.059632,0.000000
65.420006,63.442589,-24.864851,0.014090,0.002344,0.059527,282.206726,14.376296,0.595273,-24.864851,0.059632,0.000000
65.630005,63.390083,-24.864851,0.014086,0.002344,0.059527,281.973175,14.364398,0.595273,-24.864851,0.059632,0.000000
65.840004,63.336464,-24.864851,0.014081,0.002344,0.059527,281.734650,14.352248,0.595273,-24.864851,0.059632,0.000000
66.050003,63.310020,-24.864851,0.014099,0.002344,0.059527,281.617035,14.346255,0.595273,-24.864851,0.059632,0.000000
66.260002,63.263100,-24.909332,0.014107,0.002344,0.059527,281.408325,14.335623,0.595273,-24.909332,0.059632,0.000000
66.470001,63.218056,-24.820372,0.014137,0.002344,0.059527,281.207947,14.325416,0.595273,-24.820372,0.059632,0.000000
66.680000,63.172615,-24.909332,0.014086,0.002344,0.059527,281.005829,14.315120,0.595273,-24.909332,0.059632,0.000000
66.889999,63.146553,-24.909332,0.014094,0.002344,0.059527,280.889893,14.309213,0.595273,-24.909332,0.059632,0.000000
67.100006,63.101494,-24.909332,0.014094,0.002344,0.059527,280.689453,14.299003,0.595273,-24.909332,0.059632,0.000000
67.310005,63.063148,-24.909332,0.014099,0.002343,0.059518,280.518890,14.290314,0.595182,-24.909332,0.059632,0.000000
67.520004,63.020683,-24.864851,0.014081,0.002343,0.059518,280.329987,14.280690,0.595182,-24.864851,0.059632,0.000000
67.730003,62.983452,-24.909332,0.014112,0.002343,0.059518,280.164398,14.272254,0.595182,-24.909332,0.059632,0.000000
67.940002,62.973778,-24.953814,0.014090,0.002343,0.059518,280.121368,14.270062,0.595182,-24.953814,0.059632,0.000000
68.150002,62.920525,-24.909332,0.014103,0.002343,0.059518,279.884460,14.257995,0.595182,-24.909332,0.059632,0.000000
68.360001,62.901535,-24.998295,0.014112,0.002343,0.059518,279.799988,14.253692,0.595182,-24.998295,0.059632,0.000000
68.570000,62.867271,-24.953814,0.014107,0.002343,0.059518,279.647583,14.245928,0.595182,-24.953814,0.059632,0.000000
68.780006,62.844559,-24.909332,0.014112,0.002343,0.059518,279.546570,14.240781,0.595182,-24.909332,0.059632,0.000000
68.990005,62.814400,-24.953814,0.014103,0.002343,0.059518,279.412415,14.233947,0.595182,-24.953814,0.059632,0.000000
69.200005,62.778648,-24.864851,0.014129,0.002343,0.059518,279.253387,14.225845,0.595182,-24.864851,0.059632,0.000000
69.410004,62.746994,-25.042776,0.014073,0.002343,0.059518,279.112579,14.218672,0.595182,-25.042776,0.059632,0.000000
69.620003,62.726143,-24.953814,0.014086,0.002343,0.059518,279.019806,14.213947,0.595182,-24.953814,0.059632,0.000000
69.830002,62.698959,-24.909332,0.014107,0.002343,0.059518,278.898895,14.207788,0.595182,-24.909332,0.059632,0.000000
70.040001,62.676994,-24.909332,0.014094,0.002343,0.059518,278.801208,14.202810,0.595182,-24.909332,0.059632,0.000000
70.250000,62.647575,-24.953814,0.014112,0.002343,0.059518,278.670319,14.196143,0.595182,-24.953814,0.059632,0.000000
70.460007,62.616669,-24.998295,0.014112,0.002343,0.059518,278.532867,14.189140,0.595182,-24.998295,0.059632,0.000000
70.670006,62.599167,-24.953814,0.014099,0.002343,0.059518,278.454987,14.185174,0.595182,-24.953814,0.059632,0.000000
70.880005,62.573845,-24.953814,0.014103,0.002343,0.059518,278.342377,14.179437,0.595182,-24.953814,0.059632,0.000000
71.090004,62.550758,-24.998295,0.014086,0.002343,0.059518,278.239655,14.174204,0.595182,-24.998295,0.059632,0.000000
71.300003,62.525436,-24.998295,0.014120,0.002343,0.059518,278.127045,14.168467,0.595182,-24.998295,0.059632,0.000000
71.510002,62.506073,-24.998295,0.014064,0.002343,0.059518,278.040894,14.164079,0.595182,-24.998295,0.059632,0.000000
71.720001,62.481125,-24.953814,0.014107,0.002343,0.059518,277.929932,14.158425,0.595182,-24.953814,0.059632,0.000000
71.930000,62.457291,-24.953814,0.014137,0.002343,0.059518,277.823914,14.153025,0.595182,-24.953814,0.059632,0.000000
72.140007,62.441277,-24.998295,0.014086,0.002343,0.059518,277.752655,14.149396,0.595182,-24.998295,0.059632,0.000000
72.350006,62.420425,-24.953814,0.014081,0.002343,0.059518,277.659912,14.144670,0.595182,-24.953814,0.059632,0.000000
72.560005,62.396965,-24.998295,0.014107,0.002343,0.059518,277.555573,14.139354,0.595182,-24.998295,0.059632,0.000000
72.770004,62.377228,-24.953814,0.014107,0.002343,0.059509,277.467773,14.134882,0.595091,-24.953814,0.059632,0.000000
72.980003,62.364197,-25.042776,0.014094,0.002343,0.059509,277.409790,14.131928,0.595091,-25.042776,0.059632,0.000000
73.190002,62.337761,-24.998295,0.014125,0.002343,0.059509,277.292206,14.125939,0.595091,-24.998295,0.059632,0.000000
73.400002,62.329193,-24.998295,0.014099,0.002343,0.059509,277.254089,14.123997,0.595091,-24.998295,0.059632,0.000000
73.610001,62.302383,-24.998295,0.014107,0.002343,0.059509,277.134857,14.117922,0.595091,-24.998295,0.059632,0.000000
73.820000,62.284508,-24.953814,0.014129,0.002343,0.059509,277.055328,14.113871,0.595091,-24.953814,0.059632,0.000000
74.030006,62.275948,-24.998295,0.014103,0.002343,0.059509,277.017242,14.111932,0.595091,-24.998295,0.059632,0.000000
74.240005,62.247276,-24.998295,0.014081,0.002343,0.059509,276.889709,14.105434,0.595091,-24.998295,0.059632,0.000000
74.450005,62.222321,-24.998295,0.014120,0.002343,0.059509,276.778717,14.099779,0.595091,-24.998295,0.059632,0.000000
74.660004,62.210037,-25.042776,0.014103,0.002343,0.059509,276.724060,14.096996,0.595091,-25.042776,0.059632,0.000000
74.870003,62.191788,-25.042776,0.014125,0.002343,0.059509,276.642883,14.092861,0.595091,-25.042776,0.059632,0.000000
75.080002,62.164230,-25.087255,0.014107,0.002343,0.059509,276.520294,14.086616,0.595091,-25.087255,0.059632,0.000000
75.290001,62.160881,-25.042776,0.014107,0.002343,0.059509,276.505402,14.085856,0.595091,-25.042776,0.059632,0.000000
75.500000,62.136307,-25.042776,0.014133,0.002343,0.059509,276.396088,14.080288,0.595091,-25.042776,0.059632,0.000000
75.710007,62.130722,-25.042776,0.014107,0.002343,0.059509,276.371246,14.079022,0.595091,-25.042776,0.059632,0.000000
75.920006,62.117317,-25.042776,0.014090,0.002343,0.059509,276.311615,14.075985,0.595091,-25.042776,0.059632,0.000000
76.130005,62.104279,-25.042776,0.014064,0.002343,0.059509,276.253632,14.073030,0.595091,-25.042776,0.059632,0.000000
76.340004,62.080826,-25.087255,0.014133,0.002343,0.059509,276.149292,14.067717,0.595091,-25.087255,0.059632,0.000000
76.550003,62.066299,-25.042776,0.014107,0.002343,0.059509,276.084686,14.064425,0.595091,-25.042776,0.059632,0.000000
76.760002,62.054008,-24.998295,0.014081,0.002343,0.059509,276.030029,14.061640,0.595091,-24.998295,0.059632,0.000000
76.970001,62.030556,-25.042776,0.014116,0.002343,0.059509,275.925690,14.056325,0.595091,-25.042776,0.059632,0.000000
77.180000,62.013794,-24.998295,0.014107,0.002343,0.059509,275.851135,14.052526,0.595091,-24.998295,0.059632,0.000000
77.390007,62.010071,-25.042776,0.014090,0.002343,0.059509,275.834564,14.051683,0.595091,-25.042776,0.059632,0.000000
77.600006,61.988472,-25.042776,0.014103,0.002343,0.059509,275.738495,14.046789,0.595091,-25.042776,0.059632,0.000000
77.810005,61.982513,-25.042776,0.014107,0.002343,0.059509,275.711975,14.045438,0.595091,-25.042776,0.059632,0.000000
78.020004,61.959427,-25.087255,0.014099,0.002343,0.059509,275.609283,14.040207,0.595091,-25.087255,0.059632,0.000000
78.230003,61.952728,-24.998295,0.014090,0.002343,0.059509,275.579498,14.038689,0.595091,-24.998295,0.059632,0.000000
78.440002,61.932617,-25.042776,0.014090,0.002343,0.059509,275.490051,14.034132,0.595091,-25.042776,0.059632,0.000000
78.650002,61.930756,-25.087255,0.014146,0.002343,0.059509,275.481750,14.033710,0.595091,-25.087255,0.059632,0.000000
78.860001,61.905434,-25.131737,0.014103,0.002343,0.059509,275.369110,14.027972,0.595091,-25.131737,0.059632,0.000000
79.070007,61.891655,-25.087255,0.014107,0.002343,0.059509,275.307831,14.024849,0.595091,-25.087255,0.059632,0.000000
79.280006,61.883469,-25.131737,0.014112,0.002343,0.059509,275.271423,14.022994,0.595091,-25.131737,0.059632,0.000000
79.490005,61.873787,-25.131737,0.014112,0.002343,0.059509,275.228363,14.020801,0.595091,-25.131737,0.059632,0.000000
79.700005,61.863731,-25.042776,0.014116,0.002343,0.059509,275.183624,14.018522,0.595091,-25.042776,0.059632,0.000000
79.910004,61.830215,-25.087255,0.014090,0.002343,0.059509,275.034546,14.010927,0.595091,-25.087255,0.059632,0.000000
80.120003,61.833199,-25.087255,0.014086,0.002343,0.059509,275.047791,14.011602,0.595091,-25.087255,0.059632,0.000000
80.330002,61.819420,-25.087255,0.014103,0.002343,0.059509,274.986511,14.008481,0.595091,-25.087255,0.059632,0.000000
80.540001,61.807129,-25.087255,0.014112,0.002343,0.059509,274.931854,14.005695,0.595091,-25.087255,0.059632,0.000000
80.750008,61.795212,-25.087255,0.014107,0.002343,0.059509,274.878845,14.002995,0.595091,-25.087255,0.059632,0.000000
80.960007,61.785156,-25.176218,0.014090,0.002343,0.059509,274.834106,14.000717,0.595091,-25.176218,0.059632,0.000000
81.170006,61.762817,-25.087255,0.014107,0.002343,0.059509,274.734741,13.995655,0.595091,-25.087255,0.059632,0.000000
81.380005,61.746803,-25.176218,0.014094,0.002343,0.059509,274.663513,13.992026,0.595091,-25.176218,0.059632,0.000000
81.590004,61.744202,-25.131737,0.014103,0.002343,0.059509,274.651917,13.991436,0.595091,-25.131737,0.059632,0.000000
81.800003,61.733025,-25.176218,0.014120,0.002343,0.059509,274.602203,13.988903,0.595091,-25.176218,0.059632,0.000000
82.010002,61.723717,-25.131737,0.014086,0.002343,0.059509,274.560791,13.986794,0.595091,-25.131737,0.059632,0.000000
82.220001,61.715523,-25.131737,0.014107,0.002343,0.059509,274.524353,13.984938,0.595091,-25.131737,0.059632,0.000000
82.430000,61.703606,-25.131737,0.014103,0.002343,0.059509,274.471344,13.982237,0.595091,-25.131737,0.059632,0.000000
82.640007,61.687225,-25.176218,0.014103,0.002343,0.059509,274.398468,13.978525,0.595091,-25.176218,0.059632,0.000000
82.850006,61.673073,-25.131737,0.014099,0.002343,0.059509,274.335541,13.975318,0.595091,-25.131737,0.059632,0.000000
83.060005,61.670837,-25.176218,0.014112,0.002343,0.059509,274.325592,13.974812,0.595091,-25.176218,0.059632,0.000000
83.270004,61.660042,-25.087255,0.014103,0.002343,0.059509,274.277557,13.972364,0.595091,-25.087255,0.059632,0.000000
83.480003,61.646263,-25.176218,0.014112,0.002343,0.059509,274.216278,13.969243,0.595091,-25.176218,0.059632,0.000000
83.690002,61.626160,-25.176218,0.014112,0.002343,0.059509,274.126862,13.964687,0.595091,-25.176218,0.059632,0.000000
83.900002,61.624290,-25.131737,0.014116,0.002343,0.059509,274.118530,13.964263,0.595091,-25.131737,0.059632,0.000000
84.110001,61.603065,-25.176218,0.014120,0.002343,0.059502,274.024109,13.959455,0.595016,-25.176218,0.059632,0.000000
84.320007,61.605675,-25.176218,0.014116,0.002343,0.059502,274.035736,13.960046,0.595016,-25.176218,0.059632,0.000000
84.530006,61.585564,-25.176218,0.014120,0.002343,0.059502,273.946259,13.955488,0.595016,-25.176218,0.059632,0.000000
84.740005,61.569931,-25.176218,0.014112,0.002343,0.059502,273.876740,13.951945,0.595016,-25.176218,0.059632,0.000000
84.950005,61.567696,-25.087255,0.014107,0.002343,0.059502,273.866791,13.951439,0.595016,-25.087255,0.059632,0.000000
85.160004,61.550194,-25.176218,0.014060,0.002343,0.059502,273.788940,13.947474,0.595016,-25.176218,0.059632,0.000000
85.370003,61.548706,-25.131737,0.014103,0.002343,0.059502,273.782318,13.947136,0.595016,-25.131737,0.059632,0.000000
85.580002,61.527107,-25.176218,0.014090,0.002343,0.059502,273.686249,13.942242,0.595016,-25.176218,0.059632,0.000000
85.790001,61.528969,-25.176218,0.014120,0.002343,0.059502,273.694519,13.942664,0.595016,-25.176218,0.059632,0.000000
86.000008,61.516304,-25.131737,0.014090,0.002343,0.059502,273.638184,13.939794,0.595016,-25.131737,0.059632,0.000000
86.210007,61.512581,-25.176218,0.014073,0.002343,0.059502,273.621613,13.938950,0.595016,-25.176218,0.059632,0.000000
86.420006,61.492844,-25.176218,0.014112,0.002343,0.059502,273.533844,13.934477,0.595016,-25.176218,0.059632,0.000000
86.630005,61.480560,-25.176218,0.014120,0.002343,0.059502,273.479187,13.931694,0.595016,-25.176218,0.059632,0.000000
86.840004,61.472740,-25.131737,0.014094,0.002343,0.059502,273.444397,13.929922,0.595016,-25.131737,0.059632,0.000000
87.050003,61.469391,-25.131737,0.014090,0.002343,0.059502,273.429504,13.929163,0.595016,-25.131737,0.059632,0.000000
87.260002,61.465660,-25.176218,0.014077,0.002343,0.059502,273.412903,13.928317,0.595016,-25.176218,0.059632,0.000000
87.470001,61.457474,-25.176218,0.014125,0.002343,0.059502,273.376495,13.926462,0.595016,-25.176218,0.059632,0.000000
87.680008,61.446671,-25.220699,0.014081,0.002343,0.059502,273.328430,13.924014,0.595016,-25.220699,0.059632,0.000000
87.890007,61.431778,-25.176218,0.014112,0.002343,0.059502,273.262207,13.920640,0.595016,-25.176218,0.059632,0.000000
88.100006,61.418747,-25.220699,0.014116,0.002343,0.059502,273.204224,13.917687,0.595016,-25.220699,0.059632,0.000000
88.310005,61.419487,-25.265181,0.014103,0.002343,0.059502,273.207520,13.917854,0.595016,-25.265181,0.059632,0.000000
88.520004,61.407570,-25.220699,0.014090,0.002343,0.059502,273.154510,13.915154,0.595016,-25.220699,0.059632,0.000000
88.730003,61.400124,-25.220699,0.014103,0.002343,0.059502,273.121399,13.913466,0.595016,-25.220699,0.059632,0.000000
88.940002,61.382996,-25.176218,0.014103,0.002343,0.059502,273.045197,13.909586,0.595016,-25.176218,0.059632,0.000000
89.150002,61.380386,-25.220699,0.014103,0.002343,0.059502,273.033600,13.908994,0.595016,-25.220699,0.059632,0.000000
89.360001,61.370705,-25.265181,0.014081,0.002343,0.059502,272.990540,13.906800,0.595016,-25.265181,0.059632,0.000000
89.570007,61.359909,-25.220699,0.014125,0.002343,0.059502,272.942505,13.904354,0.595016,-25.220699,0.059632,0.000000
89.780006,61.361397,-25.265181,0.014107,0.002343,0.059502,272.949127,13.904691,0.595016,-25.265181,0.059632,0.000000
89.900002,61.356560,-25.220699,0.014116,0.002343,0.059502,272.927612,13.903595,0.595016,-25.220699,0.059632,0.000000