File: Data/New old I18 7 new align_08182023_121647.csv
Time (sec),S:Load (lbs),S:HL1 (DIM),S:LVDT (in),S:Position (in),Ch:Position (mm),Ch:Load (N),Ch:Stress (MPa),Ch:Strain (mm/mm),Ch:HL1 (DIM),Set Point (),Cycles ()
0.110000,-0.009308,-53.732990,-0.000017,-0.000000,-0.000000,-0.041403,-0.002109,-0.000000,-53.732990,0.000216,0.000000
0.470000,0.091606,-53.777470,-0.000030,0.000041,0.001031,0.407484,0.020758,0.010310,-53.777470,0.001603,0.000000
0.830000,0.038353,-53.777470,0.000060,0.000257,0.006521,0.170603,0.008691,0.065206,-53.777470,0.007605,0.000000
1.190000,0.099426,-53.777470,0.000289,0.000490,0.012436,0.442270,0.022530,0.124357,-53.777470,0.013606,0.000000
1.550000,0.120651,-53.777470,0.000565,0.000731,0.018558,0.536684,0.027340,0.185581,-53.777470,0.019607,0.000000
1.910000,0.116180,-53.821949,0.000802,0.000963,0.024464,0.516796,0.026327,0.244640,-53.821949,0.025592,0.000000
2.270000,0.118042,-53.777470,0.001005,0.001190,0.030222,0.525077,0.026749,0.302216,-53.777470,0.031593,0.000000
2.630000,0.110970,-53.821949,0.001268,0.001434,0.036423,0.493617,0.025146,0.364228,-53.821949,0.037593,0.000000
2.990000,0.106499,-53.866432,0.001500,0.001674,0.042520,0.473730,0.024133,0.425195,-53.866432,0.043594,0.000000
3.350000,0.109108,-53.777470,0.001746,0.001906,0.048416,0.485336,0.024724,0.484164,-53.777470,0.049596,0.000000
3.710000,0.098679,-53.910912,0.001966,0.002143,0.054436,0.438944,0.022361,0.544359,-53.910912,0.055580,0.000000
4.070000,0.113945,-53.866432,0.002242,0.002384,0.060558,0.506853,0.025820,0.605583,-53.866432,0.061582,0.000000
4.430000,0.112083,-53.866432,0.002470,0.002616,0.066437,0.498572,0.025398,0.664370,-53.866432,0.067583,0.000000
4.790000,0.115807,-53.821949,0.002725,0.002849,0.072370,0.515133,0.026242,0.723702,-53.821949,0.073583,0.000000
5.150000,0.101654,-53.910912,0.002979,0.003088,0.078423,0.452180,0.023035,0.784230,-53.910912,0.079568,0.000000
5.510000,0.119904,-53.866432,0.003186,0.003325,0.084450,0.533358,0.027171,0.844501,-53.866432,0.085569,0.000000
5.870000,0.118416,-53.955395,0.003441,0.003560,0.090417,0.526740,0.026833,0.904166,-53.955395,0.091570,0.000000
6.230000,0.136292,-53.955395,0.003704,0.003797,0.096435,0.606255,0.030884,0.964346,-53.955395,0.097572,0.000000
6.590000,0.115067,-53.910912,0.003949,0.004035,0.102480,0.511841,0.026074,1.024798,-53.910912,0.103573,0.000000
6.950000,0.095703,-53.910912,0.004208,0.004267,0.108377,0.425709,0.021687,1.083767,-53.910912,0.109556,0.000000
7.310000,0.122139,-53.955395,0.004437,0.004500,0.114299,0.543301,0.027677,1.142993,-53.955395,0.115557,0.000000
7.670001,0.127724,-53.999874,0.004661,0.004736,0.120293,0.568143,0.028943,1.202930,-53.999874,0.121559,0.000000
8.030001,0.119530,-53.999874,0.004919,0.004978,0.126441,0.531695,0.027086,1.264412,-53.999874,0.127560,0.000000
8.390000,0.139641,-53.955395,0.005165,0.005211,0.132364,0.621153,0.031643,1.323638,-53.955395,0.133561,0.000000
8.750000,0.104263,-53.955395,0.005415,0.005450,0.138435,0.463786,0.023626,1.384348,-53.955395,0.139545,0.000000
9.110001,0.111710,-53.999874,0.005657,0.005688,0.144471,0.496909,0.025314,1.444710,-53.999874,0.145546,0.000000
9.470000,0.115433,-53.999874,0.005894,0.005923,0.150437,0.513470,0.026157,1.504375,-53.999874,0.151547,0.000000
9.830001,0.149323,-54.044357,0.006127,0.006150,0.156222,0.664220,0.033837,1.562223,-54.044357,0.157549,0.000000
10.190001,0.139267,-53.999874,0.006385,0.006390,0.162317,0.619490,0.031558,1.623175,-53.999874,0.163532,0.000000
10.550000,0.140015,-54.044357,0.006648,0.006630,0.168407,0.622816,0.031728,1.684066,-54.044357,0.169533,0.000000
10.910001,0.122139,-54.044357,0.006868,0.006861,0.174278,0.543301,0.027677,1.742778,-54.044357,0.175534,0.000000
11.270000,0.083786,-54.044357,0.007123,0.007102,0.180400,0.372699,0.018986,1.804002,-54.044357,0.181536,0.000000
11.630000,0.111336,-54.133316,0.007381,0.007341,0.186470,0.495246,0.025229,1.864697,-54.133316,0.187537,0.000000
11.990001,0.131447,-54.044357,0.007640,0.007575,0.192403,0.584705,0.029786,1.924029,-54.044357,0.193522,0.000000
12.350000,0.143738,-54.133316,0.007864,0.007802,0.198179,0.639378,0.032571,1.981786,-54.133316,0.199521,0.000000
12.710001,0.139641,-54.088837,0.008119,0.008045,0.204353,0.621153,0.031643,2.043525,-54.088837,0.205523,0.000000
13.070001,0.129585,-54.088837,0.008369,0.008280,0.210302,0.576424,0.029364,2.103024,-54.088837,0.211524,0.000000
13.430000,0.077454,-54.177799,0.008597,0.008516,0.216295,0.344531,0.017551,2.162946,-54.177799,0.217525,0.000000
13.790001,0.085648,-54.088837,0.008852,0.008756,0.222399,0.380979,0.019408,2.223989,-54.088837,0.223510,0.000000
14.150001,0.137032,-54.177799,0.009084,0.008994,0.228444,0.609547,0.031052,2.284441,-54.177799,0.229511,0.000000
14.510000,0.153793,-54.133316,0.009347,0.009226,0.234341,0.684107,0.034850,2.343410,-54.133316,0.235511,0.000000
14.870001,0.159004,-54.177799,0.009585,0.009460,0.240291,0.707286,0.036031,2.402909,-54.177799,0.241513,0.000000
15.230000,0.143738,-54.222279,0.009830,0.009697,0.246292,0.639378,0.032571,2.462922,-54.222279,0.247514,0.000000
15.590001,0.113571,-54.133316,0.010063,0.009929,0.252198,0.505190,0.025736,2.521981,-54.133316,0.253499,0.000000
15.950001,0.093468,-54.266762,0.010283,0.010171,0.258355,0.415765,0.021180,2.583554,-54.266762,0.259500,0.000000
16.310001,0.130333,-54.177799,0.010572,0.010405,0.264295,0.579750,0.029534,2.642947,-54.177799,0.265501,0.000000
16.670000,0.167564,-54.222279,0.010800,0.010646,0.270417,0.745364,0.037971,2.704171,-54.222279,0.271501,0.000000
17.030001,0.157143,-54.222279,0.011042,0.010879,0.276315,0.699005,0.035609,2.763155,-54.222279,0.277486,0.000000
17.390001,0.172783,-54.222279,0.011296,0.011110,0.282187,0.768577,0.039153,2.821866,-54.222279,0.283487,0.000000
17.750000,0.148575,-54.177799,0.011525,0.011349,0.288274,0.660894,0.033668,2.882743,-54.177799,0.289488,0.000000
18.110001,0.175385,-54.222279,0.011783,0.011590,0.294379,0.780149,0.039743,2.943785,-54.222279,0.295490,0.000000
18.470001,0.149696,-54.266762,0.012016,0.011821,0.300250,0.665883,0.033922,3.002497,-54.266762,0.301491,0.000000
18.830002,0.145599,-54.222279,0.012279,0.012062,0.306365,0.647658,0.032993,3.063645,-54.222279,0.307474,0.000000
19.190001,0.157883,-54.311241,0.012516,0.012299,0.312383,0.702297,0.035777,3.123825,-54.311241,0.313476,0.000000
19.550001,0.146339,-54.400204,0.012741,0.012530,0.318254,0.650950,0.033161,3.182537,-54.400204,0.319477,0.000000
19.910002,0.156021,-54.266762,0.012991,0.012763,0.324169,0.694017,0.035355,3.241687,-54.266762,0.325478,0.000000
20.270000,0.169060,-54.355721,0.013228,0.013000,0.330205,0.752015,0.038309,3.302048,-54.355721,0.331480,0.000000
20.630001,0.171288,-54.266762,0.013491,0.013244,0.336388,0.761925,0.038814,3.363878,-54.266762,0.337463,0.000000
20.990002,0.155281,-54.266762,0.013732,0.013476,0.342303,0.690725,0.035187,3.423029,-54.266762,0.343464,0.000000
21.350000,0.159744,-54.355721,0.013969,0.013714,0.348330,0.710578,0.036199,3.483299,-54.355721,0.349465,0.000000
21.710001,0.166451,-54.311241,0.014237,0.013953,0.354418,0.740409,0.037718,3.544176,-54.311241,0.355467,0.000000
22.070002,0.153046,-54.355721,0.014435,0.014179,0.360158,0.680781,0.034681,3.601585,-54.355721,0.361450,0.000000
22.430000,0.201828,-54.355721,0.014702,0.014414,0.366116,0.897776,0.045735,3.661159,-54.355721,0.367451,0.000000
22.790001,0.183205,-54.400204,0.015008,0.014657,0.372282,0.814935,0.041515,3.722823,-54.400204,0.373453,0.000000
23.150002,0.172035,-54.266762,0.015211,0.014894,0.378300,0.765251,0.038984,3.783003,-54.266762,0.379454,0.000000
23.510000,0.182091,-54.311241,0.015478,0.015131,0.384320,0.809980,0.041262,3.843198,-54.311241,0.385455,0.000000
23.870001,0.138519,-54.355721,0.015703,0.015366,0.390286,0.616165,0.031389,3.902863,-54.355721,0.391440,0.000000
24.230001,0.174271,-54.355721,0.015953,0.015604,0.396330,0.775194,0.039490,3.963300,-54.355721,0.397440,0.000000
24.590002,0.195122,-54.355721,0.016198,0.015835,0.402201,0.867945,0.044215,4.022011,-54.355721,0.403441,0.000000
24.950001,0.206291,-54.355721,0.016440,0.016073,0.408246,0.917629,0.046746,4.082463,-54.355721,0.409442,0.000000
25.310001,0.170921,-54.400204,0.016699,0.016308,0.414229,0.760296,0.038731,4.142295,-54.400204,0.415444,0.000000
25.670002,0.175385,-54.400204,0.016953,0.016550,0.420361,0.780149,0.039743,4.203610,-54.400204,0.421428,0.000000
26.030001,0.153046,-54.444683,0.017190,0.016783,0.426284,0.680781,0.034681,4.262836,-54.444683,0.427430,0.000000
26.390001,0.126610,-54.489166,0.017449,0.017019,0.432294,0.563189,0.028690,4.322940,-54.489166,0.433430,0.000000
26.750002,0.200706,-54.355721,0.017690,0.017256,0.438304,0.892787,0.045481,4.383045,-54.355721,0.439431,0.000000
27.110001,0.209648,-54.444683,0.017919,0.017495,0.444374,0.932561,0.047507,4.443739,-54.444683,0.445432,0.000000
27.470001,0.185814,-54.444683,0.018160,0.017719,0.450072,0.826542,0.042106,4.500725,-54.444683,0.451417,0.000000
27.830002,0.196983,-54.400204,0.018423,0.017961,0.456221,0.876226,0.044637,4.562206,-54.400204,0.457418,0.000000
28.190001,0.183952,-54.444683,0.018677,0.018196,0.462187,0.818261,0.041684,4.621871,-54.444683,0.463419,0.000000
28.550001,0.132568,-54.400204,0.018915,0.018433,0.468207,0.589693,0.030040,4.682066,-54.400204,0.469421,0.000000
28.910002,0.191025,-54.489166,0.019165,0.018670,0.474225,0.849721,0.043287,4.742246,-54.489166,0.475404,0.000000
29.270000,0.214859,-54.489166,0.019410,0.018912,0.480356,0.955741,0.048688,4.803562,-54.489166,0.481405,0.000000
29.630001,0.210388,-54.400204,0.019652,0.019141,0.486183,0.935853,0.047675,4.861834,-54.400204,0.487407,0.000000
29.990002,0.249115,-54.444683,0.019898,0.019378,0.492203,1.108119,0.056450,4.922029,-54.444683,0.493408,0.000000
30.350002,0.402534,-54.489166,0.020165,0.019614,0.498195,1.790563,0.091216,4.981951,-54.489166,0.499409,0.000000
30.710001,0.652397,-54.489166,0.020312,-0.000000,-0.000000,2.902008,0.147835,-0.000000,-54.489166,0.000226,0.000000
31.070002,0.620003,-54.444683,0.020307,-0.000000,-0.000000,2.757910,0.140495,-0.000000,-54.444683,0.000233,0.000000
31.430002,0.652771,-54.444683,0.020294,0.000000,0.000008,2.903670,0.147920,0.000076,-54.444683,0.000833,0.000000
31.790001,0.679207,-54.489166,0.020290,0.000011,0.000268,3.021263,0.153910,0.002680,-54.489166,0.001431,0.000000
32.150002,0.781609,-54.533646,0.020299,0.000038,0.000954,3.476769,0.177115,0.009538,-54.533646,0.002038,0.000000
32.510002,0.902260,-54.533646,0.020337,0.000064,0.001631,4.013452,0.204455,0.016305,-54.533646,0.002636,0.000000
32.870003,0.931679,-54.489166,0.020359,0.000085,0.002150,4.144314,0.211121,0.021498,-54.489166,0.003234,0.000000
33.230003,1.085464,-54.533646,0.020402,0.000111,0.002817,4.828387,0.245970,0.028175,-54.533646,0.003833,0.000000
33.590000,1.222496,-54.533646,0.020393,0.000130,0.003294,5.437934,0.277022,0.032944,-54.533646,0.004431,0.000000
33.950001,1.410919,-54.622608,0.020419,0.000159,0.004032,6.276082,0.319719,0.040317,-54.622608,0.005029,0.000000
34.310001,1.541992,-54.533646,0.020450,0.000186,0.004717,6.859124,0.349420,0.047175,-54.533646,0.005636,0.000000
34.670002,1.602318,-54.533646,0.020480,0.000208,0.005272,7.127466,0.363090,0.052716,-54.533646,0.006234,0.000000
35.030003,1.807121,-54.489166,0.020484,0.000231,0.005879,8.038477,0.409500,0.058787,-54.489166,0.006832,0.000000
35.390003,1.973572,-54.533646,0.020506,0.000249,0.006321,8.778886,0.447218,0.063208,-54.533646,0.007432,0.000000
35.750000,2.120659,-54.578129,0.020519,0.000268,0.006807,9.433162,0.480548,0.068068,-54.578129,0.008030,0.000000
36.110001,2.363075,-54.533646,0.020557,0.000299,0.007605,10.511484,0.535480,0.076046,-54.533646,0.008637,0.000000
36.470001,2.523941,-54.489166,0.020570,0.000322,0.008177,11.227051,0.571933,0.081769,-54.489166,0.009235,0.000000
36.830002,2.634537,-54.578129,0.020592,0.000340,0.008646,11.719005,0.596995,0.086462,-54.578129,0.009833,0.000000
37.190002,2.897804,-54.533646,0.020622,0.000371,0.009426,12.890078,0.656652,0.094259,-54.533646,0.010433,0.000000
37.550003,3.007652,-54.667088,0.020648,0.000386,0.009800,13.378706,0.681544,0.097998,-54.667088,0.011031,0.000000
37.910004,3.297356,-54.578129,0.020631,0.000416,0.010563,14.667371,0.747191,0.105629,-54.578129,0.011638,0.000000
38.270000,3.543121,-54.578129,0.020704,0.000443,0.011247,15.760591,0.802883,0.112472,-54.578129,0.012236,0.000000
38.630001,3.646645,-54.622608,0.020700,0.000459,0.011664,16.221085,0.826342,0.116635,-54.622608,0.012834,0.000000
38.990002,3.924065,-54.578129,0.020717,0.000488,0.012401,17.455111,0.889206,0.124008,-54.578129,0.013433,0.000000
39.350002,4.100197,-54.667088,0.020743,0.000508,0.012894,18.238586,0.929118,0.128944,-54.667088,0.014031,0.000000
39.710003,4.369049,-54.578129,0.020747,0.000534,0.013564,19.434502,0.990041,0.135635,-54.578129,0.014638,0.000000
40.070004,4.633057,-54.578129,0.020807,0.000559,0.014204,20.608866,1.049866,0.142040,-54.578129,0.015236,0.000000
40.430000,4.761528,-54.622608,0.020799,0.000579,0.014699,21.180334,1.078978,0.146990,-54.622608,0.015834,0.000000
40.790001,5.013992,-54.578129,0.020846,0.000605,0.015367,22.303352,1.136187,0.153667,-54.578129,0.016434,0.000000
41.150002,5.257156,-54.622608,0.020868,0.000629,0.015965,23.385000,1.191289,0.159647,-54.622608,0.017032,0.000000
41.510002,5.320084,-54.578129,0.020855,0.000646,0.016399,23.664913,1.205548,0.163992,-54.578129,0.017639,0.000000
41.870003,5.576279,-54.622608,0.020902,0.000673,0.017102,24.804527,1.263603,0.171017,-54.622608,0.018237,0.000000
42.230003,5.635109,-54.622608,0.020919,0.000701,0.017795,25.066217,1.276934,0.177951,-54.622608,0.018835,0.000000
42.590000,5.698792,-54.622608,0.020954,0.000724,0.018402,25.349491,1.291365,0.184022,-54.622608,0.019435,0.000000
42.950001,5.811241,-54.622608,0.020984,0.000743,0.018870,25.849691,1.316846,0.188700,-54.622608,0.020033,0.000000
43.310001,5.864868,-54.667088,0.020997,0.000765,0.019442,26.088236,1.328998,0.194422,-54.667088,0.020631,0.000000
43.670002,5.988495,-54.667088,0.021006,0.000784,0.019919,26.638155,1.357012,0.199191,-54.667088,0.021238,0.000000
44.030003,6.173187,-54.622608,0.021057,0.000818,0.020770,27.459709,1.398864,0.207700,-54.622608,0.021836,0.000000
44.390003,6.212662,-54.667088,0.021075,0.000837,0.021264,27.635300,1.407809,0.212635,-54.667088,0.022434,0.000000
44.750004,6.433853,-54.667088,0.021083,0.000863,0.021924,28.619207,1.457932,0.219236,-54.667088,0.023033,0.000000
45.110001,6.458427,-54.622608,0.021131,0.000885,0.022469,28.728519,1.463501,0.224687,-54.622608,0.023631,0.000000
45.470001,6.555618,-54.756050,0.021139,0.000907,0.023033,29.160847,1.485524,0.230334,-54.756050,0.024238,0.000000
45.830002,6.810318,-54.667088,0.021195,0.000939,0.023839,30.293808,1.543240,0.238388,-54.667088,0.024836,0.000000
46.190002,6.807343,-54.756050,0.021191,0.000958,0.024325,30.280571,1.542566,0.243248,-54.756050,0.025434,0.000000
46.550003,6.924263,-54.711571,0.021213,0.000980,0.024897,30.800659,1.569060,0.248970,-54.711571,0.026034,0.000000
46.910004,7.092575,-54.711571,0.021247,0.001009,0.025625,31.549349,1.607200,0.256253,-54.711571,0.026632,0.000000
47.270000,7.127213,-54.800533,0.021260,0.001024,0.026016,31.703424,1.615049,0.260159,-54.800533,0.027239,0.000000
47.630001,7.331642,-54.711571,0.021277,0.001051,0.026684,32.612774,1.661374,0.266835,-54.711571,0.027837,0.000000
47.990002,7.528252,-54.800533,0.021308,0.001079,0.027404,33.487335,1.705926,0.274042,-54.800533,0.028435,0.000000
48.350002,7.570335,-54.756050,0.021329,0.001101,0.027967,33.674534,1.715463,0.279673,-54.756050,0.029035,0.000000
48.710003,7.739014,-54.800533,0.021359,0.001123,0.028514,34.424850,1.753686,0.285139,-54.800533,0.029633,0.000000
49.070004,7.856316,-54.756050,0.021394,0.001146,0.029121,34.946636,1.780267,0.291210,-54.756050,0.030240,0.000000
49.430004,7.920738,-54.711571,0.021411,0.001164,0.029563,35.233204,1.794865,0.295631,-54.711571,0.030838,0.000000
49.790001,8.181023,-54.800533,0.021428,0.001199,0.030447,36.391006,1.853846,0.304472,-54.800533,0.031436,0.000000
50.150002,8.159050,-54.756050,0.021467,0.001214,0.030829,36.293266,1.848867,0.308287,-54.756050,0.032035,0.000000
50.510002,8.422691,-54.845013,0.021471,0.001242,0.031549,37.466003,1.908609,0.315494,-54.845013,0.032633,0.000000
50.870003,8.563080,-54.800533,0.021506,0.001264,0.032113,38.090481,1.940422,0.321126,-54.800533,0.033231,0.000000
51.230003,8.628990,-54.756050,0.021532,0.001284,0.032624,38.383667,1.955357,0.326243,-54.756050,0.033838,0.000000
51.590004,8.802513,-54.756050,0.021523,0.001310,0.033266,39.155533,1.994678,0.332662,-54.756050,0.034436,0.000000
51.950001,8.972313,-54.756050,0.021588,0.001336,0.033943,39.910843,2.033155,0.339429,-54.756050,0.035036,0.000000
52.310001,9.049026,-54.756050,0.021592,0.001357,0.034480,40.252079,2.050539,0.344804,-54.756050,0.035634,0.000000
52.670002,9.162971,-54.800533,0.021614,0.001376,0.034948,40.758934,2.076359,0.349482,-54.800533,0.036232,0.000000
53.030003,9.374847,-54.756050,0.021661,0.001402,0.035599,41.701405,2.124371,0.355992,-54.756050,0.036839,0.000000
53.390003,9.551353,-54.889492,0.021661,0.001423,0.036137,42.486542,2.164367,0.361367,-54.889492,0.037437,0.000000
53.750004,9.760628,-54.800533,0.021704,0.001453,0.036909,43.417442,2.211790,0.369088,-54.800533,0.038037,0.000000
54.110004,9.795258,-54.845013,0.021743,0.001475,0.037455,43.571484,2.219637,0.374553,-54.845013,0.038635,0.000000
54.470001,10.028366,-54.845013,0.021730,0.001502,0.038149,44.608398,2.272460,0.381487,-54.845013,0.039233,0.000000
54.830002,10.194443,-54.800533,0.021782,0.001525,0.038739,45.347145,2.310094,0.387392,-54.800533,0.039840,0.000000
55.190002,10.378769,-54.845013,0.021795,0.001546,0.039258,46.167068,2.351862,0.392584,-54.845013,0.040438,0.000000
55.550003,10.497177,-54.845013,0.021834,0.001575,0.039996,46.693775,2.378694,0.399957,-54.845013,0.041036,0.000000
55.910004,10.634956,-54.800533,0.021859,0.001597,0.040559,47.306648,2.409915,0.405589,-54.800533,0.041635,0.000000
56.270004,10.693794,-54.845013,0.021877,0.001618,0.041089,47.568371,2.423248,0.410888,-54.845013,0.042233,0.000000
56.630001,10.989456,-54.845013,0.021907,0.001644,0.041756,48.883541,2.490247,0.417565,-54.845013,0.042840,0.000000
56.990002,10.996162,-54.933975,0.021920,0.001661,0.042189,48.913372,2.491766,0.421895,-54.933975,0.043438,0.000000
57.350002,11.276924,-54.889492,0.021928,0.001681,0.042694,50.162262,2.555387,0.426936,-54.889492,0.044036,0.000000
57.710003,11.471680,-54.889492,0.021971,0.001713,0.043499,51.028580,2.599520,0.434990,-54.889492,0.044636,0.000000
58.070004,11.658607,-54.845013,0.021980,0.001736,0.044089,51.860077,2.641878,0.440895,-54.845013,0.045234,0.000000
58.430004,11.788193,-54.933975,0.022019,0.001761,0.044731,52.436501,2.671242,0.447314,-54.933975,0.045832,0.000000
58.790001,11.922997,-54.933975,0.022045,0.001783,0.045278,53.036137,2.701790,0.452779,-54.933975,0.046439,0.000000
59.150002,12.124817,-54.845013,0.022058,0.001801,0.045746,53.933880,2.747523,0.457458,-54.845013,0.047037,0.000000
59.510002,12.390320,-54.889492,0.022092,0.001834,0.046588,55.114895,2.807687,0.465875,-54.889492,0.047637,0.000000
59.870003,12.424576,-54.889492,0.022114,0.001857,0.047160,55.267273,2.815449,0.471598,-54.889492,0.048235,0.000000
60.230003,12.672951,-54.933975,0.022127,0.001880,0.047740,56.372101,2.871732,0.477396,-54.933975,0.048833,0.000000
60.590004,12.797325,-54.933975,0.022183,0.001903,0.048347,56.925346,2.899915,0.483467,-54.933975,0.049440,0.000000
60.950005,12.811478,-54.933975,0.022174,0.001917,0.048693,56.988300,2.903122,0.486934,-54.933975,0.050038,0.000000
61.310001,13.248642,-54.978455,0.022213,0.001953,0.049596,58.932903,3.002185,0.495957,-54.978455,0.050637,0.000000
61.670002,13.315666,-54.889492,0.022226,0.001974,0.050151,59.231041,3.017373,0.501514,-54.889492,0.051235,0.000000
62.030003,13.448601,-54.933975,0.022260,0.002000,0.050801,59.822365,3.047497,0.508009,-54.933975,0.051833,0.000000
62.390003,13.722298,-54.978455,0.022278,0.002023,0.051382,61.039829,3.109517,0.513822,-54.978455,0.052440,0.000000
62.750004,13.714104,-54.933975,0.022316,0.002041,0.051842,61.003380,3.107660,0.518425,-54.933975,0.053038,0.000000
63.110004,14.013123,-54.978455,0.022312,0.002063,0.052397,62.333481,3.175419,0.523966,-54.978455,0.053638,0.000000
63.470001,14.267448,-54.889492,0.022364,0.002095,0.053222,63.464779,3.233050,0.532217,-54.889492,0.054236,0.000000
63.830002,14.330009,-54.978455,0.022385,0.002115,0.053724,63.743065,3.247226,0.537243,-54.978455,0.054834,0.000000
64.190002,14.430176,-54.978455,0.022403,0.002134,0.054210,64.188629,3.269925,0.542103,-54.978455,0.055441,0.000000
64.550003,14.721375,-55.022938,0.022416,0.002161,0.054895,65.483948,3.335911,0.548946,-55.022938,0.056039,0.000000
64.910004,14.683388,-54.978455,0.022446,0.002177,0.055285,65.314972,3.327303,0.552852,-54.978455,0.056639,0.000000
65.270004,15.205086,-54.978455,0.022467,0.002212,0.056188,67.635597,3.445522,0.561875,-54.978455,0.057237,0.000000
65.630005,15.233757,-55.022938,0.022528,0.002234,0.056734,67.763138,3.452019,0.567341,-55.022938,0.057835,0.000000
65.990005,15.364464,-54.978455,0.022549,0.002255,0.057279,68.344551,3.481637,0.572791,-54.978455,0.058433,0.000000
66.350006,15.684700,-55.022938,0.022566,0.002282,0.057974,69.769028,3.554204,0.579740,-55.022938,0.059040,0.000000
66.710007,15.752472,-54.978455,0.022584,0.002303,0.058486,70.070496,3.569561,0.584857,-54.978455,0.059638,0.000000
67.070000,16.069359,-54.978455,0.022592,0.002327,0.059100,71.480080,3.641369,0.591004,-54.978455,0.060237,0.000000
67.430000,16.216080,-55.022938,0.022614,0.002352,0.059733,72.132729,3.674616,0.597332,-55.022938,0.060835,0.000000
67.790001,16.358696,-55.022938,0.022648,0.002373,0.060280,72.767113,3.706933,0.602798,-55.022938,0.061433,0.000000
68.150002,16.664413,-55.022938,0.022683,0.002402,0.061000,74.127014,3.776210,0.610004,-55.022938,0.062040,0.000000
68.510002,16.726227,-55.067417,0.022696,0.002421,0.061494,74.401970,3.790217,0.614939,-55.067417,0.062638,0.000000
68.870003,16.995079,-54.978455,0.022726,0.002444,0.062066,75.597885,3.851140,0.620662,-54.978455,0.063238,0.000000
69.230003,17.208824,-55.067417,0.022748,0.002471,0.062769,76.548676,3.899575,0.627687,-55.067417,0.063836,0.000000
69.590004,17.291115,-55.022938,0.022773,0.002491,0.063280,76.914719,3.918223,0.632804,-55.022938,0.064434,0.000000
69.950005,17.472458,-55.067417,0.022773,0.002513,0.063818,77.721375,3.959316,0.638179,-55.067417,0.065041,0.000000
70.310005,17.768867,-54.978455,0.022821,0.002537,0.064452,79.039871,4.026483,0.644522,-54.978455,0.065639,0.000000
70.670006,17.943512,-55.111897,0.022821,0.002559,0.064999,79.816727,4.066058,0.649988,-55.111897,0.066239,0.000000
71.030006,18.408607,-55.067417,0.022842,0.002591,0.065822,81.885574,4.171450,0.658224,-55.067417,0.066837,0.000000
71.390007,18.319611,-55.022938,0.022898,0.002612,0.066342,81.489700,4.151283,0.663416,-55.022938,0.067435,0.000000
71.750000,18.427597,-55.111897,0.022916,0.002631,0.066837,81.970047,4.175753,0.668367,-55.111897,0.068042,0.000000
72.110001,18.674850,-55.022938,0.022924,0.002656,0.067453,83.069885,4.231781,0.674529,-55.022938,0.068640,0.000000
72.470001,18.884125,-55.156380,0.022955,0.002680,0.068060,84.000786,4.279204,0.680600,-55.156380,0.069239,0.000000
72.830002,19.083344,-55.111897,0.022963,0.002701,0.068605,84.886955,4.324347,0.686050,-55.111897,0.069837,0.000000
73.190002,19.402840,-55.022938,0.023015,0.002733,0.069412,86.308144,4.396747,0.694119,-55.022938,0.070435,0.000000
73.550003,19.458694,-55.111897,0.023015,0.002753,0.069933,86.556595,4.409403,0.699327,-55.111897,0.071033,0.000000
73.910004,19.626266,-55.067417,0.023067,0.002772,0.070419,87.301994,4.447376,0.704187,-55.067417,0.071640,0.000000
74.270004,19.991188,-55.156380,0.023084,0.002798,0.071077,88.925247,4.530068,0.710773,-55.156380,0.072240,0.000000
74.630005,20.043694,-55.067417,0.023092,0.002818,0.071580,89.158798,4.541966,0.715799,-55.067417,0.072838,0.000000
74.990005,20.449951,-55.111897,0.023114,0.002848,0.072335,90.965927,4.634025,0.723354,-55.111897,0.073436,0.000000
75.350006,20.545654,-55.156380,0.023140,0.002870,0.072908,91.391632,4.655712,0.729077,-55.156380,0.074034,0.000000
75.710007,20.647682,-55.156380,0.023153,0.002893,0.073471,91.845474,4.678832,0.734709,-55.156380,0.074641,0.000000
76.070007,20.979836,-55.156380,0.023200,0.002918,0.074129,93.322968,4.754098,0.741294,-55.156380,0.075241,0.000000
76.430000,20.946320,-55.111897,0.023205,0.002935,0.074546,93.173882,4.746504,0.745458,-55.111897,0.075839,0.000000
76.790001,21.393539,-55.200859,0.023248,0.002965,0.075301,95.163216,4.847846,0.753012,-55.200859,0.076437,0.000000
77.150002,21.565948,-55.156380,0.023269,0.002992,0.075995,95.930130,4.886914,0.759946,-55.156380,0.077035,0.000000
77.510002,21.670586,-55.156380,0.023287,0.003012,0.076497,96.395576,4.910625,0.764973,-55.156380,0.077642,0.000000
77.870003,21.893265,-55.156380,0.023325,0.003036,0.077113,97.386108,4.961085,0.771134,-55.156380,0.078240,0.000000
78.230003,21.987846,-55.156380,0.023325,0.003054,0.077565,97.806824,4.982517,0.775646,-55.156380,0.078839,0.000000
78.590004,22.207550,-55.200859,0.023360,0.003074,0.078076,98.784119,5.032303,0.780763,-55.200859,0.079437,0.000000
78.950005,22.612320,-55.156380,0.023386,0.003105,0.078856,100.584625,5.124025,0.788560,-55.156380,0.080035,0.000000
79.310005,22.722542,-55.200859,0.023429,0.003129,0.079472,101.074913,5.149001,0.794722,-55.200859,0.080642,0.000000
79.670006,22.983574,-55.200859,0.023437,0.003154,0.080114,102.236046,5.208152,0.801141,-55.200859,0.081240,0.000000
80.030006,23.091187,-55.200859,0.023463,0.003177,0.080695,102.714729,5.232538,0.806955,-55.200859,0.081840,0.000000
80.390007,23.148537,-55.245342,0.023489,0.003193,0.081103,102.969833,5.245533,0.811027,-55.245342,0.082438,0.000000
80.750008,23.725342,-55.200859,0.023511,0.003227,0.081978,105.535591,5.376239,0.819778,-55.200859,0.083036,0.000000
81.110001,23.726082,-55.200859,0.023528,0.003248,0.082499,105.538879,5.376407,0.824986,-55.200859,0.083634,0.000000
81.470001,23.935730,-55.200859,0.023541,0.003272,0.083115,106.471443,5.423914,0.831148,-55.200859,0.084241,0.000000
81.830002,24.304008,-55.156380,0.023593,0.003299,0.083799,108.109627,5.507367,0.837991,-55.156380,0.084841,0.000000
82.190002,24.322624,-55.200859,0.023593,0.003316,0.084215,108.192436,5.511585,0.842154,-55.200859,0.085439,0.000000
82.550003,24.864799,-55.200859,0.023614,0.003348,0.085048,110.604149,5.634444,0.850481,-55.200859,0.086037,0.000000
82.910004,24.935181,-55.245342,0.023644,0.003371,0.085620,110.917221,5.650393,0.856204,-55.245342,0.086635,0.000000
83.270004,25.090088,-55.200859,0.023679,0.003391,0.086141,111.606285,5.685495,0.861412,-55.200859,0.087242,0.000000
83.630005,25.449051,-55.200859,0.023705,0.003419,0.086853,113.203033,5.766837,0.868527,-55.200859,0.087841,0.000000
83.990005,25.418892,-55.245342,0.023731,0.003436,0.087277,113.068878,5.760004,0.872766,-55.245342,0.088439,0.000000
84.350006,25.634117,-55.289822,0.023731,0.003460,0.087876,114.026245,5.808774,0.878762,-55.289822,0.089037,0.000000
84.710007,26.112244,-55.245342,0.023782,0.003488,0.088604,116.153061,5.917119,0.886044,-55.245342,0.089635,0.000000
85.070007,26.160286,-55.156380,0.023761,0.003511,0.089184,116.366760,5.928005,0.891842,-55.156380,0.090242,0.000000
85.430000,26.275345,-55.245342,0.023817,0.003529,0.089644,116.878571,5.954078,0.896445,-55.245342,0.090842,0.000000
85.790001,26.748634,-55.289822,0.023830,0.003559,0.090391,118.983871,6.061327,0.903909,-55.289822,0.091440,0.000000
86.150002,26.678627,-55.245342,0.023843,0.003573,0.090747,118.672462,6.045463,0.907466,-55.245342,0.092038,0.000000
86.510002,27.300484,-55.334305,0.023869,0.003607,0.091613,121.438614,6.186378,0.916126,-55.334305,0.092636,0.000000
86.870003,27.318359,-55.289822,0.023899,0.003627,0.092117,121.518135,6.190429,0.921168,-55.289822,0.093243,0.000000
87.230003,27.500824,-55.289822,0.023946,0.003649,0.092680,122.329773,6.231776,0.926800,-55.289822,0.093843,0.000000
87.590004,27.776749,-55.334305,0.023942,0.003673,0.093296,123.557152,6.294302,0.932961,-55.334305,0.094441,0.000000
87.950005,27.960701,-55.245342,0.023963,0.003696,0.093885,124.375412,6.335985,0.938851,-55.245342,0.095039,0.000000
88.310005,28.298820,-55.289822,0.023976,0.003721,0.094501,125.879440,6.412604,0.945013,-55.289822,0.095637,0.000000
88.670006,28.651451,-55.245342,0.024019,0.003750,0.095246,127.448021,6.492512,0.952461,-55.245342,0.096244,0.000000
89.030006,28.683853,-55.378784,0.024050,0.003768,0.095715,127.592148,6.499854,0.957155,-55.378784,0.096842,0.000000
89.390007,29.027550,-55.245342,0.024050,0.003793,0.096348,129.120987,6.577737,0.963483,-55.245342,0.097441,0.000000
89.750008,29.173149,-55.289822,0.024101,0.003817,0.096946,129.768646,6.610730,0.969463,-55.289822,0.098039,0.000000
90.110001,29.420029,-55.289822,0.024093,0.003838,0.097484,130.866821,6.666674,0.974838,-55.289822,0.098637,0.000000
90.470001,29.747345,-55.289822,0.024127,0.003864,0.098135,132.322800,6.740845,0.981348,-55.289822,0.099235,0.000000
90.830002,30.014336,-55.334305,0.024144,0.003887,0.098733,133.510437,6.801345,0.987328,-55.334305,0.099842,0.000000
91.190002,30.123070,-55.334305,0.024175,0.003907,0.099244,133.994110,6.825985,0.992445,-55.334305,0.100442,0.000000
91.550003,30.512947,-55.334305,0.024192,0.003932,0.099870,135.728363,6.914333,0.998698,-55.334305,0.101040,0.000000
91.910004,30.473099,-55.334305,0.024205,0.003950,0.100319,135.551117,6.905303,1.003194,-55.334305,0.101638,0.000000
92.270004,30.883453,-55.378784,0.024244,0.003978,0.101040,137.376465,6.998291,1.010400,-55.378784,0.102236,0.000000
92.630005,31.274445,-55.378784,0.024270,0.004007,0.101777,139.115677,7.086890,1.017773,-55.378784,0.102843,0.000000
92.990005,31.346313,-55.334305,0.024278,0.004025,0.102245,139.435364,7.103176,1.022452,-55.334305,0.103443,0.000000
93.350006,31.675865,-55.334305,0.024313,0.004049,0.102836,140.901291,7.177854,1.028356,-55.334305,0.104041,0.000000
93.710007,32.048233,-55.334305,0.024313,0.004073,0.103450,142.557663,7.262233,1.034503,-55.334305,0.104639,0.000000
94.070007,32.015099,-55.289822,0.024334,0.004090,0.103876,142.410278,7.254725,1.038757,-55.289822,0.105237,0.000000
94.430008,32.832825,-55.378784,0.024373,0.004128,0.104855,146.047699,7.440024,1.048552,-55.378784,0.105844,0.000000
94.790001,32.752762,-55.289822,0.024390,0.004147,0.105325,145.691559,7.421882,1.053245,-55.289822,0.106443,0.000000
95.150002,32.923683,-55.378784,0.024412,0.004167,0.105844,146.451859,7.460613,1.058438,-55.378784,0.107041,0.000000
95.510002,33.538841,-55.378784,0.024425,0.004194,0.106539,149.188217,7.600010,1.065387,-55.378784,0.107639,0.000000
95.870003,33.433830,-55.378784,0.024446,0.004210,0.106946,148.721100,7.576214,1.069460,-55.378784,0.108237,0.000000
96.230003,34.068359,-55.423264,0.024476,0.004241,0.107726,151.543625,7.720000,1.077257,-55.423264,0.108844,0.000000
96.590004,34.259010,-55.334305,0.024533,0.004265,0.108325,152.391693,7.763203,1.083252,-55.334305,0.109444,0.000000
96.950005,34.257523,-55.423264,0.024520,0.004285,0.108837,152.385071,7.762866,1.088369,-55.423264,0.110042,0.000000
97.310005,34.736389,-55.378784,0.024550,0.004312,0.109530,154.515182,7.871378,1.095303,-55.378784,0.110640,0.000000
97.670006,34.678299,-55.378784,0.024567,0.004329,0.109956,154.256775,7.858215,1.099557,-55.378784,0.111238,0.000000
98.030006,35.371284,-55.423264,0.024584,0.004361,0.110779,157.339325,8.015247,1.107793,-55.423264,0.111838,0.000000
98.390007,35.601044,-55.334305,0.024623,0.004385,0.111368,158.361359,8.067311,1.113683,-55.334305,0.112445,0.000000
98.750008,35.852768,-55.467747,0.024632,0.004408,0.111975,159.481079,8.124353,1.119754,-55.467747,0.113043,0.000000
99.110008,36.067993,-55.378784,0.024649,0.004430,0.112513,160.438446,8.173124,1.125128,-55.378784,0.113641,0.000000
99.470001,36.365150,-55.423264,0.024675,0.004451,0.113050,161.760269,8.240460,1.130503,-55.423264,0.114239,0.000000
99.830002,36.553200,-55.378784,0.024688,0.004470,0.113545,162.596756,8.283073,1.135453,-55.378784,0.114837,0.000000
100.190002,37.135216,-55.423264,0.024714,0.004499,0.114274,165.185684,8.414960,1.142735,-55.423264,0.115444,0.000000
100.550003,37.225700,-55.467747,0.024739,0.004522,0.114855,165.588181,8.435464,1.148549,-55.467747,0.116043,0.000000
100.910004,37.556366,-55.423264,0.024761,0.004546,0.115462,167.059067,8.510394,1.154620,-55.423264,0.116641,0.000000
101.270004,37.852776,-55.467747,0.024778,0.004571,0.116095,168.377548,8.577562,1.160948,-55.467747,0.117239,0.000000
101.630005,37.782402,-55.378784,0.024808,0.004587,0.116502,168.064514,8.561615,1.165021,-55.378784,0.117837,0.000000
101.990005,38.606834,-55.423264,0.024834,0.004617,0.117283,171.731781,8.748434,1.172833,-55.423264,0.118445,0.000000
102.350006,38.828766,-55.423264,0.024847,0.004644,0.117968,172.718979,8.798724,1.179676,-55.423264,0.119044,0.000000
102.710007,38.909195,-55.423264,0.024877,0.004663,0.118437,173.076736,8.816950,1.184369,-55.423264,0.119642,0.000000
103.070007,39.356415,-55.467747,0.024895,0.004689,0.119112,175.066071,8.918291,1.191122,-55.467747,0.120240,0.000000
103.430008,39.643517,-55.423264,0.024929,0.004713,0.119719,176.343170,8.983350,1.197193,-55.423264,0.120838,0.000000
103.790009,40.029297,-55.512226,0.024929,0.004738,0.120335,178.059204,9.070768,1.203354,-55.512226,0.121445,0.000000
104.150002,40.482101,-55.467747,0.024964,0.004765,0.121029,180.073380,9.173375,1.210288,-55.467747,0.122045,0.000000
104.510002,40.592697,-55.467747,0.025002,0.004784,0.121524,180.565338,9.198437,1.215239,-55.467747,0.122643,0.000000
104.870003,40.787819,-55.556709,0.025020,0.004806,0.122080,181.433273,9.242652,1.220795,-55.556709,0.123241,0.000000
105.230003,41.162422,-55.467747,0.025015,0.004831,0.122703,183.099594,9.327538,1.227033,-55.467747,0.123839,0.000000
105.590004,41.122955,-55.512226,0.025050,0.004845,0.123059,182.924042,9.318595,1.230590,-55.512226,0.124438,0.000000
105.950005,42.120911,-55.467747,0.025059,0.004880,0.123943,187.363174,9.544735,1.239432,-55.467747,0.125045,0.000000
106.310005,42.191292,-55.467747,0.025102,0.004901,0.124490,187.676239,9.560683,1.244897,-55.467747,0.125643,0.000000
106.670006,42.619888,-55.423264,0.025123,0.004926,0.125113,189.582733,9.657805,1.251135,-55.423264,0.126241,0.000000
107.030006,43.084610,-55.512226,0.025128,0.004950,0.125739,191.649918,9.763112,1.257388,-55.512226,0.126839,0.000000
107.390007,42.975876,-55.512226,0.025158,0.004965,0.126120,191.166245,9.738473,1.261203,-55.512226,0.127439,0.000000
107.750008,43.573540,-55.467747,0.025175,0.004993,0.126823,193.824783,9.873905,1.268227,-55.467747,0.128046,0.000000
108.110008,44.163376,-55.467747,0.025205,0.005024,0.127602,196.448502,10.007565,1.276024,-55.467747,0.128644,0.000000
108.470009,44.286255,-55.467747,0.025214,0.005040,0.128028,196.995102,10.035409,1.280279,-55.467747,0.129242,0.000000
108.830002,44.924500,-55.467747,0.025248,0.005069,0.128756,199.834152,10.180037,1.287561,-55.467747,0.129840,0.000000
109.190002,45.203407,-55.556709,0.025257,0.005090,0.129286,201.074799,10.243238,1.292860,-55.556709,0.130440,0.000000
109.550003,45.500191,-55.556709,0.025291,0.005112,0.129840,202.394958,10.310490,1.298401,-55.556709,0.131045,0.000000
109.910004,46.211792,-55.601189,0.025300,0.005143,0.130621,205.560318,10.471742,1.306213,-55.601189,0.131645,0.000000
110.270004,46.358879,-55.556709,0.025326,0.005163,0.131142,206.214600,10.505073,1.311421,-55.556709,0.132243,0.000000
110.630005,47.069740,-55.512226,0.025352,0.005189,0.131792,209.376663,10.666156,1.317916,-55.512226,0.132841,0.000000
110.990005,47.166931,-55.556709,0.025373,0.005209,0.132312,209.808990,10.688179,1.323124,-55.556709,0.133439,0.000000
111.350006,47.516586,-55.512226,0.025395,0.005230,0.132833,211.364334,10.767412,1.328332,-55.512226,0.134046,0.000000
111.710007,48.139198,-55.601189,0.025408,0.005256,0.133492,214.133850,10.908498,1.334917,-55.601189,0.134645,0.000000
112.070007,48.469490,-55.556709,0.025416,0.005280,0.134125,215.603058,10.983343,1.341246,-55.556709,0.135243,0.000000
112.430008,48.877609,-55.601189,0.025442,0.005300,0.134620,217.418457,11.075825,1.346196,-55.601189,0.135841,0.000000
112.790009,49.422394,-55.512226,0.025485,0.005326,0.135278,219.841782,11.199275,1.352782,-55.512226,0.136439,0.000000
113.150009,49.747475,-55.601189,0.025472,0.005345,0.135772,221.287827,11.272939,1.357718,-55.601189,0.137039,0.000000
113.510002,50.321671,-55.601189,0.025507,0.005369,0.136362,223.841965,11.403053,1.363622,-55.601189,0.137646,0.000000
113.870003,51.221695,-55.601189,0.025528,0.005401,0.137195,227.845474,11.607002,1.371949,-55.601189,0.138244,0.000000
114.230003,51.383675,-55.556709,0.025554,0.005420,0.137663,228.565994,11.643706,1.376627,-55.556709,0.138842,0.000000
114.590004,51.811905,-55.601189,0.025576,0.005441,0.138193,230.470871,11.740746,1.381926,-55.601189,0.139440,0.000000
114.950005,52.507126,-55.601189,0.025589,0.005466,0.138825,233.563354,11.898285,1.388254,-55.601189,0.140040,0.000000
115.310005,52.644157,-55.645668,0.025589,0.005486,0.139337,234.172913,11.929337,1.393371,-55.645668,0.140647,0.000000
115.670006,53.676003,-55.601189,0.025623,0.005517,0.140126,238.762787,12.163157,1.401259,-55.601189,0.141245,0.000000
116.030006,54.104233,-55.645668,0.025636,0.005539,0.140682,240.667648,12.260195,1.406815,-55.645668,0.141843,0.000000
116.390007,54.628899,-55.601189,0.025662,0.005560,0.141236,243.001480,12.379086,1.412356,-55.601189,0.142441,0.000000
116.750008,55.131607,-55.645668,0.025658,0.005579,0.141713,245.237640,12.493000,1.417125,-55.645668,0.143040,0.000000
117.110008,55.683464,-55.601189,0.025688,0.005605,0.142354,247.692413,12.618053,1.423544,-55.601189,0.143647,0.000000
117.470009,56.226753,-55.556709,0.025714,0.005627,0.142927,250.109085,12.741164,1.429267,-55.556709,0.144245,0.000000
117.830002,57.371796,-55.645668,0.025748,0.005657,0.143690,255.202499,13.000634,1.436898,-55.645668,0.144843,0.000000
118.190002,57.707306,-55.645668,0.025753,0.005677,0.144192,256.694916,13.076662,1.441924,-55.645668,0.145441,0.000000
118.550003,58.600624,-55.690151,0.025774,0.005704,0.144887,260.668610,13.279091,1.448873,-55.690151,0.146041,0.000000
118.910004,59.071304,-55.601189,0.025796,0.005724,0.145381,262.762299,13.385749,1.453808,-55.601189,0.146648,0.000000
119.270004,60.019363,-55.601189,0.025804,0.005753,0.146118,266.979462,13.600582,1.461181,-55.601189,0.147246,0.000000
119.630005,60.897423,-55.690151,0.025830,0.005777,0.146743,270.885254,13.799554,1.467434,-55.690151,0.147844,0.000000
119.990005,61.203140,-55.601189,0.025839,0.005795,0.147185,272.245178,13.868830,1.471855,-55.601189,0.148442,0.000000
120.350006,62.246529,-55.690151,0.025865,0.005824,0.147923,276.886383,14.105265,1.479228,-55.690151,0.149042,0.000000
120.710007,62.926102,-55.601189,0.025904,0.005844,0.148425,279.909271,14.259258,1.484254,-55.601189,0.149640,0.000000
121.070007,63.393799,-55.645668,0.025908,0.005862,0.148884,281.989716,14.365240,1.488841,-55.645668,0.150247,0.000000
121.430008,64.437561,-55.645668,0.025904,0.005890,0.149596,286.632599,14.601761,1.495957,-55.645668,0.150845,0.000000
121.790009,65.693954,-55.645668,0.025938,0.005916,0.150272,292.221313,14.886463,1.502724,-55.645668,0.151443,0.000000
122.150009,66.083817,-55.734631,0.025947,0.005935,0.150740,293.955505,14.974807,1.507403,-55.734631,0.152041,0.000000
122.510002,67.366653,-55.734631,0.025990,0.005965,0.151521,299.661835,15.265502,1.515215,-55.734631,0.152640,0.000000
122.870003,66.574982,-55.690151,0.026020,0.005957,0.151296,296.140320,15.086106,1.512959,-55.690151,0.151573,0.000000
123.230003,66.083450,-55.690151,0.025986,0.005948,0.151079,293.953857,14.974725,1.510794,-55.690151,0.151296,0.000000
123.590004,65.698044,-55.690151,0.025994,0.005948,0.151079,292.239502,14.887390,1.510794,-55.690151,0.151296,0.000000
123.950005,65.394196,-55.690151,0.026011,0.005948,0.151079,290.887909,14.818537,1.510794,-55.690151,0.151296,0.000000
124.310005,65.154007,-55.645668,0.026024,0.005948,0.151079,289.819489,14.764109,1.510794,-55.645668,0.151296,0.000000
124.670006,64.938034,-55.734631,0.026007,0.005948,0.151079,288.858795,14.715169,1.510794,-55.734631,0.151296,0.000000
125.030006,64.723923,-55.690151,0.026033,0.005948,0.151070,287.906403,14.666650,1.510703,-55.690151,0.151296,0.000000
125.390007,64.586517,-55.734631,0.026016,0.005948,0.151070,287.295166,14.635514,1.510703,-55.734631,0.151296,0.000000
125.750008,64.428253,-55.690151,0.026046,0.005948,0.151070,286.591187,14.599650,1.510703,-55.690151,0.151296,0.000000
126.110008,64.285645,-55.734631,0.026011,0.005948,0.151070,285.956818,14.567335,1.510703,-55.734631,0.151296,0.000000
126.470009,64.163864,-55.734631,0.026011,0.005948,0.151070,285.415131,14.539740,1.510703,-55.734631,0.151296,0.000000
126.830009,64.061096,-55.645668,0.026029,0.005948,0.151070,284.957977,14.516452,1.510703,-55.645668,0.151296,0.000000
127.190002,63.949005,-55.734631,0.026003,0.005948,0.151070,284.459381,14.491052,1.510703,-55.734631,0.151296,0.000000
127.550003,63.880127,-55.690151,0.026024,0.005948,0.151070,284.152985,14.475443,1.510703,-55.690151,0.151296,0.000000
127.910004,63.763947,-55.690151,0.026020,0.005948,0.151070,283.636200,14.449117,1.510703,-55.690151,0.151296,0.000000
128.270004,63.692444,-55.734631,0.026016,0.005948,0.151070,283.318146,14.432914,1.510703,-55.734631,0.151296,0.000000
128.630005,63.616104,-55.690151,0.026033,0.005948,0.151070,282.978577,14.415615,1.510703,-55.690151,0.151296,0.000000
128.990005,63.537918,-55.779114,0.026037,0.005948,0.151070,282.630768,14.397899,1.510703,-55.779114,0.151296,0.000000
129.350006,63.448547,-55.645668,0.026029,0.005948,0.151070,282.233246,14.377646,1.510703,-55.645668,0.151296,0.000000
129.710007,63.384491,-55.734631,0.026033,0.005948,0.151070,281.948303,14.363131,1.510703,-55.734631,0.151296,0.000000
130.070007,63.309280,-55.779114,0.026020,0.005948,0.151070,281.613739,14.346087,1.510703,-55.779114,0.151296,0.000000
130.430008,63.250809,-55.779114,0.026033,0.005948,0.151070,281.353638,14.332838,1.510703,-55.779114,0.151296,0.000000
130.790009,63.189377,-55.779114,0.026024,0.005948,0.151070,281.080383,14.318918,1.510703,-55.779114,0.151296,0.000000
131.150009,63.143570,-55.734631,0.026029,0.005948,0.151070,280.876617,14.308537,1.510703,-55.734631,0.151296,0.000000
131.510010,63.084740,-55.779114,0.026037,0.005948,0.151070,280.614929,14.295206,1.510703,-55.779114,0.151296,0.000000
131.870010,63.043030,-55.734631,0.026011,0.005948,0.151070,280.429413,14.285754,1.510703,-55.734631,0.151296,0.000000
132.230011,62.995735,-55.779114,0.026020,0.005948,0.151070,280.219025,14.275038,1.510703,-55.779114,0.151296,0.000000
132.590012,62.948074,-55.779114,0.026024,0.005948,0.151070,280.007019,14.264237,1.510703,-55.779114,0.151296,0.000000
132.950012,62.912331,-55.779114,0.026016,0.005948,0.151070,279.848022,14.256138,1.510703,-55.779114,0.151296,0.000000
133.310013,62.848282,-55.868076,0.026024,0.005948,0.151070,279.563110,14.241624,1.510703,-55.868076,0.151296,0.000000
133.670013,62.815514,-55.779114,0.026020,0.005948,0.151070,279.417358,14.234199,1.510703,-55.779114,0.151296,0.000000
134.029999,62.776039,-55.823593,0.026050,0.005948,0.151070,279.241760,14.225254,1.510703,-55.823593,0.151296,0.000000
134.389999,62.726883,-55.734631,0.026042,0.005948,0.151070,279.023102,14.214115,1.510703,-55.734631,0.151296,0.000000
134.750000,62.704170,-55.779114,0.026020,0.005948,0.151070,278.922089,14.208968,1.510703,-55.779114,0.151296,0.000000
135.110001,62.642357,-55.779114,0.026033,0.005948,0.151070,278.647125,14.194962,1.510703,-55.779114,0.151296,0.000000
135.470001,62.619270,-55.734631,0.026029,0.005948,0.151070,278.544434,14.189730,1.510703,-55.734631,0.151296,0.000000
135.830002,62.601021,-55.823593,0.026042,0.005948,0.151070,278.463257,14.185595,1.510703,-55.823593,0.151296,0.000000
136.190002,62.551125,-55.823593,0.026046,0.005948,0.151070,278.241302,14.174287,1.510703,-55.823593,0.151296,0.000000
136.550003,62.515747,-55.823593,0.026046,0.005948,0.151070,278.083923,14.166271,1.510703,-55.823593,0.151296,0.000000
136.910004,62.477768,-55.868076,0.026037,0.005948,0.151070,277.914978,14.157664,1.510703,-55.868076,0.151296,0.000000
137.270004,62.447983,-55.779114,0.026037,0.005948,0.151070,277.782501,14.150915,1.510703,-55.779114,0.151296,0.000000
137.630005,62.422287,-55.868076,0.026020,0.005948,0.151070,277.668213,14.145093,1.510703,-55.868076,0.151296,0.000000
137.990005,62.383934,-55.823593,0.026016,0.005948,0.151070,277.497589,14.136402,1.510703,-55.823593,0.151296,0.000000
138.350006,62.359352,-55.823593,0.026024,0.005948,0.151070,277.388245,14.130832,1.510703,-55.823593,0.151296,0.000000
138.710007,62.325844,-55.779114,0.026007,0.005948,0.151070,277.239197,14.123239,1.510703,-55.779114,0.151296,0.000000
139.070007,62.293442,-55.868076,0.026020,0.005948,0.151070,277.095062,14.115895,1.510703,-55.868076,0.151296,0.000000
139.430008,62.275940,-55.868076,0.026059,0.005948,0.151070,277.017212,14.111929,1.510703,-55.868076,0.151296,0.000000
139.790009,62.233124,-55.779114,0.026024,0.005948,0.151070,276.826752,14.102227,1.510703,-55.779114,0.151296,0.000000
140.150009,62.222694,-55.912556,0.026037,0.005948,0.151070,276.780365,14.099864,1.510703,-55.912556,0.151296,0.000000
140.510010,62.201469,-55.823593,0.026037,0.005948,0.151070,276.685944,14.095055,1.510703,-55.823593,0.151296,0.000000
140.870010,62.175034,-55.868076,0.026046,0.005948,0.151070,276.568359,14.089065,1.510703,-55.868076,0.151296,0.000000
141.230011,62.146355,-55.912556,0.026042,0.005948,0.151070,276.440796,14.082565,1.510703,-55.912556,0.151296,0.000000
141.590012,62.130348,-55.823593,0.026029,0.005948,0.151070,276.369598,14.078938,1.510703,-55.823593,0.151296,0.000000
141.950012,62.105400,-55.957035,0.026037,0.005948,0.151070,276.258606,14.073285,1.510703,-55.957035,0.151296,0.000000
142.310013,62.079330,-55.868076,0.026037,0.005948,0.151070,276.142639,14.067378,1.510703,-55.868076,0.151296,0.000000
142.670013,62.066299,-55.868076,0.026033,0.005948,0.151070,276.084686,14.064425,1.510703,-55.868076,0.151296,0.000000
143.030014,62.036133,-55.868076,0.026029,0.005948,0.151070,275.950500,14.057589,1.510703,-55.868076,0.151296,0.000000
143.389999,62.002991,-55.823593,0.026046,0.005948,0.151070,275.803070,14.050079,1.510703,-55.823593,0.151296,0.000000
143.750000,62.001503,-55.957035,0.026037,0.005948,0.151070,275.796448,14.049741,1.510703,-55.957035,0.151296,0.000000
144.110001,61.974319,-55.823593,0.026037,0.005948,0.151070,275.675537,14.043582,1.510703,-55.823593,0.151296,0.000000
144.470001,61.950119,-55.912556,0.026042,0.005948,0.151070,275.567902,14.038098,1.510703,-55.912556,0.151296,0.000000
144.830002,61.930756,-55.868076,0.026037,0.005948,0.151070,275.481750,14.033710,1.510703,-55.868076,0.151296,0.000000
145.190002,61.912880,-55.868076,0.026042,0.005948,0.151070,275.402252,14.029658,1.510703,-55.868076,0.151296,0.000000
145.550003,61.892029,-55.957035,0.026033,0.005948,0.151070,275.309509,14.024935,1.510703,-55.957035,0.151296,0.000000
145.910004,61.872665,-55.912556,0.026046,0.005948,0.151070,275.223358,14.020547,1.510703,-55.912556,0.151296,0.000000
146.270004,61.848831,-55.868076,0.026037,0.005948,0.151070,275.117340,14.015145,1.510703,-55.868076,0.151296,0.000000
146.630005,61.833565,-55.868076,0.026046,0.005948,0.151070,275.049438,14.011686,1.510703,-55.868076,0.151296,0.000000
146.990005,61.816063,-55.912556,0.026020,0.005948,0.151070,274.971588,14.007720,1.510703,-55.912556,0.151296,0.000000
147.350006,61.801910,-55.912556,0.026024,0.005948,0.151070,274.908630,14.004514,1.510703,-55.912556,0.151296,0.000000
147.710007,61.782547,-55.912556,0.026037,0.005948,0.151070,274.822510,14.000125,1.510703,-55.912556,0.151296,0.000000
148.070007,61.766541,-55.957035,0.026020,0.005948,0.151070,274.751282,13.996498,1.510703,-55.957035,0.151296,0.000000
148.430008,61.757225,-55.957035,0.026046,0.005948,0.151070,274.709869,13.994388,1.510703,-55.957035,0.151296,0.000000
148.790009,61.746429,-55.957035,0.026054,0.005948,0.151070,274.661835,13.991940,1.510703,-55.957035,0.151296,0.000000
149.150009,61.730042,-55.912556,0.026024,0.005948,0.151070,274.588928,13.988228,1.510703,-55.912556,0.151296,0.000000
149.510010,61.702858,-55.957035,0.026046,0.005948,0.151070,274.468018,13.982067,1.510703,-55.957035,0.151296,0.000000
149.870010,61.682007,-56.001518,0.026050,0.005948,0.151070,274.375275,13.977343,1.510703,-56.001518,0.151296,0.000000
150.230011,61.669724,-55.868076,0.026046,0.005948,0.151070,274.320618,13.974559,1.510703,-55.868076,0.151296,0.000000
150.590012,61.649612,-56.045998,0.026037,0.005948,0.151070,274.231171,13.970002,1.510703,-56.045998,0.151296,0.000000
150.950012,61.633224,-55.957035,0.026050,0.005948,0.151070,274.158264,13.966288,1.510703,-55.957035,0.151296,0.000000
151.310013,61.631737,-55.957035,0.026046,0.005948,0.151070,274.151672,13.965951,1.510703,-55.957035,0.151296,0.000000
151.670013,61.599716,-55.957035,0.026029,0.005948,0.151070,274.009216,13.958695,1.510703,-55.957035,0.151296,0.000000
152.030014,61.591522,-56.045998,0.026029,0.005948,0.151070,273.972778,13.956838,1.510703,-56.045998,0.151296,0.000000
152.390015,61.577370,-56.001518,0.026029,0.005948,0.151070,273.909821,13.953631,1.510703,-56.001518,0.151296,0.000000
152.750000,61.564713,-56.001518,0.026037,0.005948,0.151070,273.853516,13.950763,1.510703,-56.001518,0.151296,0.000000
153.100006,61.564713,-55.957035,0.026037,0.005948,0.151070,273.853516,13.950763,1.510703,-55.957035,0.151296,0.000000