File: Data/PDMS0040002 10N recovery test 3_10242023_183310.csv
Time (sec),S:Load (lbs),S:HL1 (DIM),S:LVDT (in),S:Position (in),Ch:Position (mm),Ch:Load (N),Ch:Stress (MPa),Ch:Strain (mm/mm),Ch:HL1 (DIM),Set Point (),Cycles ()
0.110000,0.000366,-87.405067,-0.000017,-0.000000,-0.000000,0.001629,0.000083,-0.000000,-87.405067,0.000182,0.000000
0.400000,0.000366,-87.405067,0.000004,-0.000000,-0.000000,0.001629,0.000083,-0.000000,-87.405067,0.000182,0.000000
0.690000,-0.038361,-87.360588,0.000000,0.000013,0.000329,-0.170636,-0.008693,0.003293,-87.360588,0.000641,0.000000
0.980000,-0.005585,-87.405067,0.000000,0.000028,0.000720,-0.024842,-0.001266,0.007199,-87.405067,0.001127,0.000000
1.270000,-0.058464,-87.494034,0.000000,0.000045,0.001135,-0.260061,-0.013248,0.011355,-87.494034,0.001613,0.000000
1.560000,0.002602,-87.405067,0.000000,0.000059,0.001500,0.011573,0.000590,0.015003,-87.405067,0.002090,0.000000
1.850000,0.031647,-87.449547,0.000009,0.000075,0.001908,0.140772,0.007171,0.019076,-87.449547,0.002575,0.000000
2.140000,-0.004097,-87.449547,0.000000,0.000089,0.002272,-0.018224,-0.000928,0.022717,-87.449547,0.003061,0.000000
2.430000,0.019730,-87.494034,0.000000,0.000104,0.002645,0.087762,0.004471,0.026449,-87.494034,0.003546,0.000000
2.720000,0.029785,-87.449547,0.000000,0.000119,0.003035,0.132491,0.006749,0.030347,-87.449547,0.004023,0.000000
3.010000,0.077820,-87.405067,0.000009,0.000138,0.003512,0.346160,0.017634,0.035124,-87.405067,0.004509,0.000000
3.300000,0.110222,-87.494034,0.000013,0.000154,0.003911,0.490291,0.024977,0.039113,-87.494034,0.004995,0.000000
3.590000,0.197731,-87.449547,0.000026,0.000172,0.004379,0.879551,0.044806,0.043791,-87.449547,0.005481,0.000000
3.880000,0.246880,-87.449547,0.000056,-0.000007,-0.000182,1.098175,0.055944,-0.001817,-87.449547,0.000095,0.000000
4.170000,0.245018,-87.538513,0.000034,-0.000007,-0.000182,1.089895,0.055522,-0.001817,-87.538513,0.000095,0.000000
4.460000,0.174271,-87.405067,0.000030,-0.000007,-0.000182,0.775194,0.039490,-0.001817,-87.405067,0.000122,0.000000
4.750000,0.234589,-87.494034,0.000039,-0.000007,-0.000182,1.043502,0.053159,-0.001817,-87.494034,0.000174,0.000000
5.040000,0.200333,-87.538513,0.000047,-0.000007,-0.000182,0.891124,0.045396,-0.001817,-87.538513,0.000217,0.000000
5.330000,0.210014,-87.494034,0.000056,-0.000007,-0.000182,0.934190,0.047590,-0.001817,-87.494034,0.000269,0.000000
5.620000,0.177620,-87.582993,0.000030,-0.000007,-0.000182,0.790093,0.040249,-0.001817,-87.582993,0.000321,0.000000
5.910000,0.182091,-87.494034,0.000022,-0.000007,-0.000182,0.809980,0.041262,-0.001817,-87.494034,0.000365,0.000000
6.200000,0.185814,-87.538513,0.000017,-0.000007,-0.000182,0.826542,0.042106,-0.001817,-87.538513,0.000416,0.000000
6.490000,0.205917,-87.538513,0.000039,-0.000007,-0.000182,0.915966,0.046662,-0.001817,-87.538513,0.000460,0.000000
6.780000,0.198097,-87.538513,0.000039,-0.000007,-0.000182,0.881180,0.044889,-0.001817,-87.538513,0.000512,0.000000
7.070000,0.183952,-87.538513,0.000030,-0.000007,-0.000182,0.818261,0.041684,-0.001817,-87.538513,0.000556,0.000000
7.360000,0.178734,-87.582993,0.000004,-0.000007,-0.000182,0.795048,0.040502,-0.001817,-87.582993,0.000607,0.000000
7.650001,0.171288,-87.582993,0.000022,-0.000007,-0.000182,0.761925,0.038814,-0.001817,-87.582993,0.000659,0.000000
7.940001,0.188049,-87.538513,0.000017,-0.000007,-0.000182,0.836485,0.042613,-0.001817,-87.538513,0.000702,0.000000
8.230000,0.190277,-87.538513,0.000043,-0.000007,-0.000182,0.846395,0.043117,-0.001817,-87.538513,0.000755,0.000000
8.520000,0.166451,-87.582993,0.000030,-0.000007,-0.000182,0.740409,0.037718,-0.001817,-87.582993,0.000798,0.000000
8.810000,0.158257,-87.627472,0.000039,-0.000007,-0.000182,0.703960,0.035861,-0.001817,-87.627472,0.000850,0.000000
9.100000,0.162354,-87.627472,0.000047,-0.000007,-0.000182,0.722184,0.036790,-0.001817,-87.627472,0.000893,0.000000
9.390000,0.153046,-87.582993,0.000034,-0.000007,-0.000173,0.680781,0.034681,-0.001733,-87.582993,0.000945,0.000000
9.680000,0.178368,-87.538513,0.000047,-0.000007,-0.000173,0.793419,0.040419,-0.001733,-87.538513,0.000998,0.000000
9.970000,0.157883,-87.627472,0.000030,-0.000007,-0.000173,0.702297,0.035777,-0.001733,-87.627472,0.001041,0.000000
10.260000,0.157509,-87.582993,0.000043,-0.000007,-0.000173,0.700634,0.035692,-0.001733,-87.582993,0.001093,0.000000
10.550000,0.150063,-87.671951,0.000034,-0.000007,-0.000173,0.667512,0.034005,-0.001733,-87.671951,0.001136,0.000000
10.840000,0.163094,-87.671951,0.000030,-0.000007,-0.000173,0.725476,0.036958,-0.001733,-87.671951,0.001188,0.000000
11.130000,0.169800,-87.627472,0.000034,-0.000007,-0.000173,0.755307,0.038477,-0.001733,-87.627472,0.001232,0.000000
11.420000,0.139267,-87.760918,0.000030,-0.000006,-0.000164,0.619490,0.031558,-0.001643,-87.760918,0.001284,0.000000
11.710001,0.264755,-87.627472,0.000052,0.000015,0.000382,1.177690,0.059994,0.003823,-87.627472,0.001336,0.000000
12.000001,0.245018,-87.671951,0.000039,0.000017,0.000425,1.089895,0.055522,0.004254,-87.671951,0.001379,0.000000
12.290001,0.271454,-87.716438,0.000043,0.000017,0.000443,1.207487,0.061512,0.004428,-87.716438,0.001431,0.000000
12.580001,0.250229,-87.627472,0.000043,0.000017,0.000434,1.113074,0.056703,0.004337,-87.627472,0.001475,0.000000
12.870001,0.240547,-87.671951,0.000056,0.000019,0.000478,1.070007,0.054509,0.004777,-87.671951,0.001527,0.000000
13.160001,0.256187,-87.582993,0.000034,0.000021,0.000529,1.139579,0.058053,0.005291,-87.582993,0.001570,0.000000
13.450001,0.307579,-87.627472,0.000043,0.000025,0.000634,1.368180,0.069698,0.006336,-87.627472,0.001622,0.000000
13.740001,0.298271,-87.671951,0.000060,0.000026,0.000659,1.326777,0.067589,0.006593,-87.671951,0.001674,0.000000
14.030001,0.298637,-87.760918,0.000047,0.000026,0.000659,1.328405,0.067672,0.006593,-87.760918,0.001718,0.000000
14.320001,0.331039,-87.716438,0.000056,0.000030,0.000764,1.472537,0.075015,0.007638,-87.716438,0.001770,0.000000
14.610001,0.331779,-87.716438,0.000056,0.000030,0.000764,1.475829,0.075182,0.007638,-87.716438,0.001813,0.000000
14.900001,0.338860,-87.716438,0.000043,0.000030,0.000764,1.507323,0.076787,0.007638,-87.716438,0.001865,0.000000
15.190001,0.340721,-87.805397,0.000065,0.000032,0.000824,1.515603,0.077209,0.008244,-87.805397,0.001908,0.000000
15.480000,0.355988,-87.760918,0.000065,0.000033,0.000850,1.583512,0.080668,0.008501,-87.760918,0.001961,0.000000
15.770000,0.359337,-87.760918,0.000043,0.000035,0.000885,1.598410,0.081427,0.008849,-87.760918,0.002012,0.000000
16.060001,0.367157,-87.760918,0.000052,0.000037,0.000945,1.633196,0.083199,0.009455,-87.760918,0.002056,0.000000
16.350000,0.380188,-87.671951,0.000060,0.000041,0.001041,1.691161,0.086152,0.010408,-87.671951,0.002107,0.000000
16.640001,0.414452,-87.805397,0.000082,0.000043,0.001101,1.843573,0.093916,0.011014,-87.805397,0.002151,0.000000
16.930000,0.430084,-87.760918,0.000056,0.000046,0.001171,1.913110,0.097458,0.011710,-87.760918,0.002203,0.000000
17.220001,0.437904,-87.760918,0.000078,0.000046,0.001171,1.947896,0.099231,0.011710,-87.760918,0.002247,0.000000
17.510000,0.429344,-87.805397,0.000069,0.000046,0.001171,1.909818,0.097291,0.011710,-87.805397,0.002298,0.000000
17.800001,0.452431,-87.849876,0.000056,0.000051,0.001284,2.012512,0.102522,0.012838,-87.849876,0.002350,0.000000
18.090000,0.475517,-87.805397,0.000069,0.000053,0.001344,2.115206,0.107754,0.013444,-87.805397,0.002394,0.000000
18.380001,0.478493,-87.760918,0.000078,0.000053,0.001353,2.128442,0.108428,0.013535,-87.760918,0.002446,0.000000
18.670000,0.481102,-87.760918,0.000082,0.000054,0.001371,2.140049,0.109019,0.013709,-87.760918,0.002489,0.000000
18.960001,0.500839,-87.849876,0.000078,0.000059,0.001509,2.227844,0.113492,0.015094,-87.849876,0.002541,0.000000
19.250000,0.508659,-87.805397,0.000086,0.000062,0.001570,2.262630,0.115264,0.015700,-87.805397,0.002584,0.000000
19.540001,0.517967,-87.849876,0.000103,0.000062,0.001578,2.304033,0.117373,0.015783,-87.849876,0.002637,0.000000
19.830002,0.513870,-87.849876,0.000082,0.000062,0.001578,2.285809,0.116445,0.015783,-87.849876,0.002689,0.000000
20.120001,0.522064,-87.805397,0.000078,0.000062,0.001578,2.322258,0.118301,0.015783,-87.805397,0.002732,0.000000
20.410002,0.508286,-87.849876,0.000095,0.000062,0.001578,2.260967,0.115179,0.015783,-87.849876,0.002784,0.000000
20.700001,0.506798,-87.894356,0.000103,0.000062,0.001578,2.254349,0.114842,0.015783,-87.894356,0.002827,0.000000
20.990002,0.561905,-87.894356,0.000116,0.000071,0.001796,2.499478,0.127329,0.017956,-87.894356,0.002880,0.000000
21.280001,0.580154,-87.938843,0.000078,0.000074,0.001874,2.580656,0.131465,0.018735,-87.938843,0.002923,0.000000
21.570002,0.634148,-87.938843,0.000091,0.000079,0.002012,2.820830,0.143700,0.020121,-87.938843,0.002975,0.000000
21.860001,0.647179,-87.938843,0.000099,0.000081,0.002056,2.878794,0.146653,0.020560,-87.938843,0.003027,0.000000
22.150002,0.648674,-87.894356,0.000099,0.000082,0.002090,2.885446,0.146992,0.020900,-87.894356,0.003070,0.000000
22.440001,0.642342,-87.983322,0.000116,0.000082,0.002090,2.857278,0.145557,0.020900,-87.983322,0.003123,0.000000
22.730001,0.636757,-87.938843,0.000116,0.000082,0.002090,2.832436,0.144291,0.020900,-87.938843,0.003166,0.000000
23.020000,0.682182,-87.938843,0.000108,0.000088,0.002247,3.034498,0.154585,0.022467,-87.938843,0.003218,0.000000
23.310001,0.704895,-87.938843,0.000116,0.000092,0.002325,3.135530,0.159731,0.023247,-87.938843,0.003261,0.000000
23.600000,0.727989,-87.983322,0.000108,0.000092,0.002333,3.238258,0.164965,0.023330,-87.983322,0.003313,0.000000
23.890001,0.714951,-88.027802,0.000099,0.000093,0.002368,3.180259,0.162010,0.023678,-88.027802,0.003366,0.000000
24.180000,0.729477,-88.027802,0.000116,0.000095,0.002411,3.244875,0.165302,0.024110,-88.027802,0.003409,0.000000
24.470001,0.749580,-87.983322,0.000116,0.000097,0.002463,3.334300,0.169857,0.024632,-87.983322,0.003461,0.000000
24.760000,0.739532,-88.027802,0.000121,0.000097,0.002463,3.289605,0.167580,0.024632,-88.027802,0.003504,0.000000
25.050001,0.748840,-87.938843,0.000116,0.000099,0.002506,3.331008,0.169690,0.025064,-87.938843,0.003556,0.000000
25.340002,0.753304,-88.027802,0.000112,0.000099,0.002515,3.350862,0.170701,0.025154,-88.027802,0.003608,0.000000
25.630001,0.761871,-87.983322,0.000125,0.000103,0.002611,3.388973,0.172643,0.026108,-87.983322,0.003652,0.000000
25.920002,0.774162,-87.938843,0.000125,0.000103,0.002628,3.443646,0.175428,0.026282,-87.938843,0.003703,0.000000
26.210001,0.771179,-88.027802,0.000121,0.000105,0.002663,3.430376,0.174752,0.026631,-88.027802,0.003747,0.000000
26.500002,0.798737,-88.027802,0.000121,0.000109,0.002758,3.552958,0.180996,0.027584,-88.027802,0.003799,0.000000
26.790001,0.793526,-88.072281,0.000116,0.000111,0.002827,3.529778,0.179815,0.028273,-88.072281,0.003842,0.000000
27.080002,0.825172,-88.072281,0.000134,0.000112,0.002836,3.670550,0.186987,0.028364,-88.072281,0.003894,0.000000
27.370001,0.842300,-88.027802,0.000142,0.000115,0.002914,3.746739,0.190868,0.029144,-88.027802,0.003946,0.000000
27.660002,0.823685,-88.116760,0.000138,0.000115,0.002923,3.663933,0.186650,0.029227,-88.116760,0.003989,0.000000
27.950001,0.867996,-88.027802,0.000142,0.000117,0.002975,3.861040,0.196691,0.029749,-88.027802,0.004042,0.000000
28.240002,0.881401,-88.072281,0.000129,0.000121,0.003070,3.920668,0.199728,0.030703,-88.072281,0.004085,0.000000
28.530001,0.905983,-88.072281,0.000142,0.000123,0.003123,4.030014,0.205299,0.031225,-88.072281,0.004137,0.000000
28.820002,0.921249,-88.116760,0.000142,0.000125,0.003174,4.097922,0.208758,0.031740,-88.116760,0.004180,0.000000
29.110001,0.928696,-88.116760,0.000138,0.000126,0.003191,4.131045,0.210445,0.031914,-88.116760,0.004232,0.000000
29.400002,0.903748,-88.116760,0.000155,0.000126,0.003201,4.020070,0.204792,0.032005,-88.116760,0.004285,0.000000
29.690001,0.939491,-88.161247,0.000147,0.000129,0.003278,4.179066,0.212892,0.032785,-88.161247,0.004328,0.000000
29.980001,0.945076,-88.161247,0.000164,0.000129,0.003278,4.203908,0.214157,0.032785,-88.161247,0.004380,0.000000
30.270002,0.956619,-88.116760,0.000155,0.000129,0.003278,4.255255,0.216773,0.032785,-88.116760,0.004423,0.000000
30.560001,0.978218,-88.205727,0.000142,0.000133,0.003366,4.351331,0.221667,0.033655,-88.205727,0.004475,0.000000
30.850002,1.008011,-88.161247,0.000142,0.000134,0.003391,4.483856,0.228419,0.033913,-88.161247,0.004518,0.000000
31.140001,0.978592,-88.116760,0.000164,0.000134,0.003409,4.352994,0.221752,0.034087,-88.116760,0.004571,0.000000
31.430002,1.016205,-88.161247,0.000151,0.000137,0.003478,4.520305,0.230275,0.034776,-88.161247,0.004623,0.000000
31.720001,1.048225,-88.116760,0.000168,0.000139,0.003521,4.662739,0.237531,0.035215,-88.116760,0.004666,0.000000
32.010002,1.051949,-88.205727,0.000160,0.000139,0.003521,4.679301,0.238375,0.035215,-88.205727,0.004718,0.000000
32.300003,1.032959,-88.205727,0.000172,0.000139,0.003521,4.594831,0.234072,0.035215,-88.205727,0.004761,0.000000
32.590000,1.025887,-88.161247,0.000160,0.000139,0.003521,4.563371,0.232469,0.035215,-88.161247,0.004814,0.000000
32.880001,1.136475,-88.205727,0.000172,0.000146,0.003712,5.055292,0.257529,0.037122,-88.205727,0.004857,0.000000
33.170002,1.138710,-88.161247,0.000164,0.000149,0.003781,5.065235,0.258035,0.037811,-88.161247,0.004909,0.000000
33.460003,1.155098,-88.250206,0.000164,0.000150,0.003799,5.138133,0.261749,0.037985,-88.250206,0.004960,0.000000
33.750000,1.159935,-88.250206,0.000181,0.000150,0.003799,5.159648,0.262845,0.037985,-88.250206,0.005004,0.000000
34.040001,1.189354,-88.205727,0.000172,0.000153,0.003894,5.290511,0.269511,0.038939,-88.205727,0.005057,0.000000
34.330002,1.215424,-88.294685,0.000181,0.000154,0.003920,5.406474,0.275419,0.039204,-88.294685,0.005100,0.000000
34.620003,1.212440,-88.250206,0.000164,0.000154,0.003920,5.393205,0.274743,0.039204,-88.250206,0.005152,0.000000
34.910000,1.259361,-88.294685,0.000177,0.000159,0.004051,5.601919,0.285375,0.040506,-88.294685,0.005195,0.000000
35.200001,1.258614,-88.250206,0.000168,0.000159,0.004051,5.598593,0.285206,0.040506,-88.250206,0.005247,0.000000
35.490002,1.256752,-88.250206,0.000172,0.000160,0.004076,5.590312,0.284784,0.040763,-88.250206,0.005299,0.000000
35.780003,1.293991,-88.250206,0.000172,0.000165,0.004197,5.755960,0.293223,0.041974,-88.250206,0.005343,0.000000
36.070004,1.325272,-88.294685,0.000198,0.000166,0.004215,5.895103,0.300311,0.042149,-88.294685,0.005394,0.000000
36.360001,1.326019,-88.383652,0.000177,0.000167,0.004250,5.898428,0.300480,0.042497,-88.383652,0.005438,0.000000
36.650002,1.351334,-88.294685,0.000190,0.000170,0.004319,6.011032,0.306217,0.043193,-88.294685,0.005490,0.000000
36.940002,1.407936,-88.294685,0.000168,0.000173,0.004406,6.262813,0.319043,0.044056,-88.294685,0.005534,0.000000
37.230003,1.436607,-88.339172,0.000203,0.000176,0.004475,6.390349,0.325540,0.044753,-88.339172,0.005585,0.000000
37.520000,1.459328,-88.339172,0.000194,0.000178,0.004510,6.491414,0.330688,0.045101,-88.339172,0.005637,0.000000
37.810001,1.458954,-88.383652,0.000177,0.000179,0.004536,6.489751,0.330604,0.045358,-88.383652,0.005680,0.000000
38.100002,1.468636,-88.339172,0.000190,0.000179,0.004553,6.532817,0.332798,0.045532,-88.339172,0.005733,0.000000
38.390003,1.500656,-88.339172,0.000190,0.000182,0.004623,6.675252,0.340054,0.046229,-88.339172,0.005776,0.000000
38.680000,1.525978,-88.428131,0.000194,0.000183,0.004658,6.787889,0.345792,0.046577,-88.428131,0.005828,0.000000
38.970001,1.508102,-88.339172,0.000203,0.000183,0.004658,6.708375,0.341741,0.046577,-88.339172,0.005871,0.000000
39.260002,1.498421,-88.383652,0.000194,0.000185,0.004692,6.665308,0.339547,0.046918,-88.383652,0.005923,0.000000
39.550003,1.576622,-88.428131,0.000207,0.000189,0.004805,7.013165,0.357268,0.048045,-88.428131,0.005976,0.000000
39.840000,1.562469,-88.339172,0.000216,0.000189,0.004805,6.950212,0.354061,0.048045,-88.339172,0.006019,0.000000
40.130001,1.560608,-88.472610,0.000203,0.000189,0.004805,6.941931,0.353639,0.048045,-88.472610,0.006071,0.000000
40.420002,1.549438,-88.428131,0.000198,0.000189,0.004805,6.892247,0.351108,0.048045,-88.428131,0.006114,0.000000
40.710003,1.536034,-88.428131,0.000198,0.000189,0.004805,6.832619,0.348070,0.048045,-88.428131,0.006166,0.000000
41.000004,1.865211,-88.472610,0.000216,0.000208,0.005281,8.296875,0.422663,0.052814,-88.472610,0.006209,0.000000
41.290001,1.875641,-88.428131,0.000216,0.000210,0.005334,8.343267,0.425026,0.053337,-88.428131,0.006262,0.000000
41.580002,1.873405,-88.561577,0.000229,0.000211,0.005351,8.333323,0.424520,0.053511,-88.561577,0.006314,0.000000
41.870003,1.903938,-88.428131,0.000224,0.000213,0.005412,8.469140,0.431439,0.054116,-88.428131,0.006357,0.000000
42.160004,1.927773,-88.472610,0.000211,0.000216,0.005481,8.575160,0.436839,0.054813,-88.472610,0.006409,0.000000
42.450001,1.964264,-88.472610,0.000241,0.000219,0.005551,8.737482,0.445109,0.055509,-88.472610,0.006452,0.000000
42.740002,1.981392,-88.428131,0.000224,0.000220,0.005577,8.813671,0.448990,0.055767,-88.428131,0.006505,0.000000
43.030003,1.988464,-88.561577,0.000250,0.000220,0.005594,8.845131,0.450592,0.055941,-88.561577,0.006548,0.000000
43.320004,1.997772,-88.472610,0.000224,0.000222,0.005629,8.886535,0.452702,0.056289,-88.472610,0.006600,0.000000
43.610001,2.026077,-88.517090,0.000241,0.000224,0.005689,9.012442,0.459116,0.056895,-88.517090,0.006652,0.000000
43.900002,2.058098,-88.517090,0.000229,0.000226,0.005750,9.154877,0.466372,0.057500,-88.517090,0.006695,0.000000
44.190002,2.048416,-88.428131,0.000241,0.000226,0.005750,9.111810,0.464178,0.057500,-88.428131,0.006748,0.000000
44.480003,2.062195,-88.517090,0.000237,0.000230,0.005845,9.173100,0.467300,0.058454,-88.517090,0.006791,0.000000
44.770000,2.141136,-88.472610,0.000246,0.000232,0.005898,9.524249,0.485188,0.058976,-88.472610,0.006843,0.000000
45.060001,2.135551,-88.517090,0.000233,0.000234,0.005941,9.499408,0.483923,0.059408,-88.517090,0.006886,0.000000
45.350002,2.207420,-88.561577,0.000250,0.000236,0.005993,9.819097,0.500209,0.059930,-88.561577,0.006938,0.000000
45.640003,2.191406,-88.561577,0.000246,0.000237,0.006019,9.747862,0.496580,0.060187,-88.561577,0.006990,0.000000
45.930000,2.239075,-88.606056,0.000263,0.000239,0.006062,9.959902,0.507382,0.060619,-88.606056,0.007034,0.000000
46.220001,2.262535,-88.517090,0.000259,0.000236,0.006001,10.064259,0.512698,0.060013,-88.517090,0.007085,0.000000
46.510002,2.269608,-88.517090,0.000246,0.000232,0.005880,10.095718,0.514300,0.058802,-88.517090,0.006097,0.000000
46.800003,2.220825,-88.517090,0.000259,0.000231,0.005863,9.878724,0.503246,0.058628,-88.517090,0.006071,0.000000
47.090004,2.210030,-88.561577,0.000267,0.000230,0.005845,9.830703,0.500800,0.058454,-88.561577,0.006028,0.000000
47.380001,2.193268,-88.606056,0.000267,0.000230,0.005837,9.756143,0.497002,0.058371,-88.606056,0.005976,0.000000
47.670002,2.180984,-88.517090,0.000263,0.000229,0.005828,9.701504,0.494218,0.058280,-88.517090,0.005932,0.000000
47.960003,2.163109,-88.606056,0.000276,0.000229,0.005828,9.621988,0.490167,0.058280,-88.606056,0.005880,0.000000
48.250004,2.156410,-88.606056,0.000237,0.000229,0.005828,9.592192,0.488650,0.058280,-88.606056,0.005828,0.000000
48.540001,2.144859,-88.606056,0.000263,0.000229,0.005820,9.540811,0.486032,0.058197,-88.606056,0.005785,0.000000
48.830002,2.121033,-88.695015,0.000263,0.000229,0.005820,9.434825,0.480633,0.058197,-88.695015,0.005733,0.000000
49.120003,2.133690,-88.606056,0.000280,0.000229,0.005820,9.491127,0.483501,0.058197,-88.606056,0.005689,0.000000
49.410004,2.127365,-88.606056,0.000267,0.000229,0.005820,9.462993,0.482068,0.058197,-88.606056,0.005637,0.000000
49.700001,2.114700,-88.650536,0.000254,0.000228,0.005785,9.406657,0.479198,0.057848,-88.650536,0.005594,0.000000
49.990002,2.104645,-88.650536,0.000272,0.000226,0.005733,9.361928,0.476919,0.057326,-88.650536,0.005542,0.000000
50.280003,2.097198,-88.695015,0.000250,0.000224,0.005689,9.328805,0.475232,0.056895,-88.695015,0.005490,0.000000
50.570004,2.097198,-88.695015,0.000254,0.000222,0.005637,9.328805,0.475232,0.056372,-88.695015,0.005446,0.000000
50.860001,2.048042,-88.695015,0.000267,0.000220,0.005594,9.110147,0.464093,0.055941,-88.695015,0.005394,0.000000
51.150002,2.042831,-88.650536,0.000254,0.000219,0.005551,9.086968,0.462912,0.055509,-88.650536,0.005351,0.000000
51.440002,1.997772,-88.695015,0.000250,0.000216,0.005499,8.886535,0.452702,0.054987,-88.695015,0.005299,0.000000
51.730003,2.038734,-88.695015,0.000250,0.000215,0.005456,9.068744,0.461984,0.054555,-88.695015,0.005256,0.000000
52.020004,1.907661,-88.695015,0.000267,0.000213,0.005421,8.485702,0.432282,0.054207,-88.695015,0.005203,0.000000
52.310001,1.955322,-88.695015,0.000267,0.000212,0.005386,8.697708,0.443082,0.053859,-88.695015,0.005152,0.000000
52.600002,1.995911,-88.783981,0.000263,0.000210,0.005343,8.878254,0.452280,0.053428,-88.783981,0.005108,0.000000
52.890003,2.024590,-88.739494,0.000246,0.000209,0.005308,9.005824,0.458779,0.053079,-88.739494,0.005057,0.000000
53.180004,1.985489,-88.739494,0.000263,0.000208,0.005273,8.831896,0.449918,0.052731,-88.739494,0.005013,0.000000
53.470001,2.040596,-88.695015,0.000272,0.000205,0.005203,9.077024,0.462406,0.052035,-88.695015,0.004960,0.000000
53.760002,2.021233,-88.739494,0.000250,0.000203,0.005169,8.990891,0.458018,0.051687,-88.739494,0.004917,0.000000
54.050003,1.967239,-88.783981,0.000254,0.000202,0.005126,8.750718,0.445783,0.051255,-88.783981,0.004865,0.000000
54.340004,1.943039,-88.739494,0.000246,0.000201,0.005117,8.643069,0.440299,0.051172,-88.739494,0.004814,0.000000
54.630001,1.940804,-88.783981,0.000246,0.000199,0.005065,8.633125,0.439792,0.050649,-88.783981,0.004770,0.000000
54.920002,2.023468,-88.783981,0.000267,0.000198,0.005039,9.000835,0.458524,0.050392,-88.783981,0.004718,0.000000
55.210003,2.027191,-88.739494,0.000250,0.000197,0.004995,9.017397,0.459368,0.049953,-88.739494,0.004674,0.000000
55.500004,2.003365,-88.828461,0.000272,0.000196,0.004970,8.911410,0.453969,0.049696,-88.828461,0.004623,0.000000
55.790001,1.972458,-88.828461,0.000267,0.000195,0.004952,8.773931,0.446965,0.049522,-88.828461,0.004571,0.000000
56.080002,1.948250,-88.872940,0.000241,0.000193,0.004900,8.666248,0.441480,0.048999,-88.872940,0.004527,0.000000
56.370003,1.972458,-88.872940,0.000259,0.000192,0.004865,8.773931,0.446965,0.048651,-88.872940,0.004475,0.000000
56.660004,1.990700,-88.872940,0.000276,0.000192,0.004865,8.855075,0.451099,0.048651,-88.872940,0.004432,0.000000
56.950005,2.004105,-88.872940,0.000259,0.000189,0.004796,8.914702,0.454137,0.047962,-88.872940,0.004380,0.000000
57.240002,1.996658,-88.783981,0.000241,0.000185,0.004692,8.881579,0.452449,0.046918,-88.783981,0.004337,0.000000
57.530003,1.954582,-88.961899,0.000233,0.000183,0.004658,8.694416,0.442915,0.046577,-88.961899,0.004285,0.000000
57.820004,1.924789,-88.872940,0.000267,0.000179,0.004545,8.561891,0.436164,0.045449,-88.872940,0.004232,0.000000
58.110004,1.905800,-88.828461,0.000276,0.000176,0.004458,8.477421,0.431860,0.044578,-88.828461,0.004189,0.000000
58.400002,1.915855,-88.917419,0.000267,0.000174,0.004415,8.522150,0.434139,0.044147,-88.917419,0.004137,0.000000
58.690002,1.900215,-88.828461,0.000241,0.000173,0.004388,8.452579,0.430595,0.043882,-88.828461,0.004094,0.000000
58.980003,1.898354,-88.961899,0.000254,0.000170,0.004319,8.444299,0.430173,0.043193,-88.961899,0.004042,0.000000
59.270004,1.888672,-88.872940,0.000254,0.000168,0.004275,8.401232,0.427979,0.042754,-88.872940,0.003998,0.000000
59.560001,1.927025,-88.961899,0.000237,0.000167,0.004250,8.571835,0.436670,0.042497,-88.961899,0.003946,0.000000
59.850002,1.956070,-88.917419,0.000267,0.000166,0.004224,8.701034,0.443252,0.042239,-88.917419,0.003894,0.000000
60.140003,1.940430,-88.917419,0.000267,0.000166,0.004224,8.631462,0.439708,0.042239,-88.917419,0.003851,0.000000
60.430004,1.963890,-89.006386,0.000246,0.000166,0.004215,8.735820,0.445024,0.042149,-89.006386,0.003799,0.000000
60.720001,1.950485,-88.872940,0.000267,0.000163,0.004146,8.676191,0.441986,0.041460,-88.872940,0.003755,0.000000
61.010002,1.967239,-88.917419,0.000267,0.000163,0.004129,8.750718,0.445783,0.041286,-88.917419,0.003703,0.000000
61.300003,1.909897,-89.050865,0.000254,0.000163,0.004129,8.495646,0.432789,0.041286,-89.050865,0.003660,0.000000
61.590004,1.911011,-88.961899,0.000267,0.000161,0.004085,8.500600,0.433041,0.040847,-88.961899,0.003608,0.000000
61.880001,1.908775,-89.006386,0.000250,0.000160,0.004059,8.490657,0.432535,0.040589,-89.006386,0.003556,0.000000
62.170002,1.893509,-89.006386,0.000254,0.000157,0.003998,8.422749,0.429075,0.039984,-89.006386,0.003512,0.000000
62.460003,1.909149,-88.961899,0.000250,0.000155,0.003938,8.492320,0.432619,0.039378,-88.961899,0.003461,0.000000
62.750004,1.890533,-89.006386,0.000246,0.000154,0.003903,8.409513,0.428401,0.039030,-89.006386,0.003417,0.000000
63.040005,1.899094,-88.961899,0.000267,0.000154,0.003903,8.447591,0.430341,0.039030,-88.961899,0.003366,0.000000
63.330002,1.912872,-89.050865,0.000246,0.000151,0.003825,8.508881,0.433463,0.038250,-89.050865,0.003322,0.000000
63.620003,1.911011,-89.006386,0.000250,0.000150,0.003799,8.500600,0.433041,0.037985,-89.006386,0.003269,0.000000
63.910004,1.921440,-89.050865,0.000263,0.000147,0.003730,8.546992,0.435405,0.037296,-89.050865,0.003218,0.000000
64.200005,1.917343,-89.095345,0.000267,0.000142,0.003617,8.528769,0.434476,0.036168,-89.095345,0.003174,0.000000
64.490005,1.895004,-89.006386,0.000276,0.000142,0.003617,8.429400,0.429414,0.036168,-89.006386,0.003123,0.000000
64.780006,1.893509,-89.006386,0.000276,0.000140,0.003556,8.422749,0.429075,0.035563,-89.006386,0.003079,0.000000
65.070000,1.888672,-89.050865,0.000254,0.000138,0.003512,8.401232,0.427979,0.035124,-89.050865,0.003027,0.000000
65.360001,1.884949,-89.050865,0.000259,0.000136,0.003461,8.384670,0.427135,0.034609,-89.050865,0.002983,0.000000
65.650002,1.903938,-89.095345,0.000263,0.000136,0.003452,8.469140,0.431439,0.034518,-89.095345,0.002932,0.000000
65.940002,1.893509,-89.095345,0.000263,0.000135,0.003426,8.422749,0.429075,0.034261,-89.095345,0.002880,0.000000
66.230003,1.936333,-89.050865,0.000246,0.000128,0.003261,8.613238,0.438779,0.032611,-89.050865,0.002836,0.000000
66.520004,1.925911,-89.095345,0.000267,0.000127,0.003218,8.566880,0.436418,0.032179,-89.095345,0.002784,0.000000
66.810005,1.910637,-89.050865,0.000254,0.000125,0.003183,8.498938,0.432957,0.031831,-89.050865,0.002741,0.000000
67.100006,1.874146,-89.139824,0.000254,0.000125,0.003174,8.336616,0.424687,0.031740,-89.139824,0.002689,0.000000
67.389999,1.882339,-89.139824,0.000259,0.000122,0.003096,8.373064,0.426544,0.030960,-89.139824,0.002646,0.000000
67.680000,1.865959,-89.095345,0.000241,0.000121,0.003079,8.300200,0.422832,0.030786,-89.095345,0.002593,0.000000
67.970001,1.884949,-89.184303,0.000276,0.000121,0.003070,8.384670,0.427135,0.030703,-89.184303,0.002541,0.000000
68.260002,1.883461,-89.139824,0.000285,0.000121,0.003062,8.378053,0.426798,0.030620,-89.139824,0.002498,0.000000
68.550003,1.878990,-89.139824,0.000254,0.000114,0.002905,8.358166,0.425785,0.029053,-89.139824,0.002446,0.000000
68.840004,1.876381,-89.184303,0.000280,0.000114,0.002905,8.346560,0.425194,0.029053,-89.184303,0.002403,0.000000
69.130005,1.865211,-89.184303,0.000267,0.000111,0.002827,8.296875,0.422663,0.028273,-89.184303,0.002350,0.000000
69.420006,1.875641,-89.228790,0.000263,0.000111,0.002819,8.343267,0.425026,0.028190,-89.228790,0.002307,0.000000
69.710007,1.874893,-89.184303,0.000272,0.000111,0.002819,8.339941,0.424857,0.028190,-89.184303,0.002255,0.000000
70.000000,1.889786,-89.228790,0.000259,0.000111,0.002810,8.406187,0.428232,0.028099,-89.228790,0.002203,0.000000
70.290001,1.869682,-89.228790,0.000254,0.000100,0.002550,8.316762,0.423676,0.025503,-89.228790,0.002160,0.000000
70.580002,1.879364,-89.184303,0.000276,0.000099,0.002515,8.359829,0.425870,0.025154,-89.184303,0.002107,0.000000
70.870003,1.906548,-89.273270,0.000267,0.000097,0.002472,8.480747,0.432030,0.024723,-89.273270,0.002064,0.000000
71.160004,1.878242,-89.184303,0.000263,0.000095,0.002403,8.354840,0.425616,0.024027,-89.184303,0.002012,0.000000
71.450005,1.865959,-89.184303,0.000259,0.000093,0.002350,8.300200,0.422832,0.023504,-89.184303,0.001969,0.000000
71.740005,1.864098,-89.184303,0.000263,0.000090,0.002298,8.291921,0.422411,0.022982,-89.184303,0.001917,0.000000
72.030006,1.860001,-89.228790,0.000263,0.000088,0.002247,8.273696,0.421482,0.022467,-89.228790,0.001865,0.000000
72.320000,1.874146,-89.317749,0.000263,0.000087,0.002203,8.336616,0.424687,0.022028,-89.317749,0.001821,0.000000
72.610001,1.840263,-89.228790,0.000259,0.000084,0.002142,8.185901,0.417010,0.021423,-89.228790,0.001770,0.000000
72.900002,1.848824,-89.273270,0.000250,0.000082,0.002090,8.223978,0.418949,0.020900,-89.273270,0.001726,0.000000
73.190002,1.871544,-89.317749,0.000259,0.000081,0.002056,8.325043,0.424098,0.020560,-89.317749,0.001674,0.000000
73.480003,1.845474,-89.273270,0.000250,0.000079,0.002004,8.209080,0.418190,0.020037,-89.273270,0.001631,0.000000
73.770004,1.883827,-89.362228,0.000246,0.000078,0.001977,8.379682,0.426881,0.019772,-89.362228,0.001578,0.000000
74.060005,1.864464,-89.228790,0.000280,0.000076,0.001926,8.293550,0.422494,0.019258,-89.228790,0.001527,0.000000
74.350006,1.900589,-89.273270,0.000263,0.000074,0.001891,8.454242,0.430680,0.018909,-89.273270,0.001483,0.000000
74.640007,1.905426,-89.362228,0.000267,0.000073,0.001848,8.475759,0.431776,0.018478,-89.362228,0.001431,0.000000
74.930000,1.897232,-89.273270,0.000241,0.000071,0.001796,8.439310,0.429919,0.017956,-89.273270,0.001388,0.000000
75.220001,1.893883,-89.406715,0.000246,0.000069,0.001761,8.424411,0.429160,0.017607,-89.406715,0.001336,0.000000
75.510002,1.890160,-89.317749,0.000246,0.000067,0.001709,8.407850,0.428316,0.017085,-89.317749,0.001292,0.000000
75.800003,1.857391,-89.362228,0.000241,0.000066,0.001674,8.262090,0.420891,0.016744,-89.362228,0.001241,0.000000
76.090004,1.874893,-89.362228,0.000254,0.000064,0.001622,8.339941,0.424857,0.016222,-89.362228,0.001188,0.000000
76.380005,1.870796,-89.317749,0.000263,0.000062,0.001578,8.321717,0.423928,0.015783,-89.317749,0.001145,0.000000
76.670006,1.854042,-89.406715,0.000254,0.000061,0.001544,8.247190,0.420132,0.015442,-89.406715,0.001093,0.000000
76.960007,1.845100,-89.317749,0.000263,0.000059,0.001509,8.207417,0.418106,0.015094,-89.317749,0.001050,0.000000
77.250000,1.878990,-89.406715,0.000267,0.000056,0.001431,8.358166,0.425785,0.014314,-89.406715,0.000998,0.000000
77.540001,1.880104,-89.362228,0.000267,0.000055,0.001388,8.363121,0.426038,0.013875,-89.362228,0.000945,0.000000
77.830002,1.846596,-89.317749,0.000241,0.000054,0.001362,8.214068,0.418445,0.013618,-89.317749,0.000902,0.000000
78.120003,1.835052,-89.451195,0.000267,0.000052,0.001319,8.162721,0.415829,0.013187,-89.451195,0.000850,0.000000
78.410004,1.836914,-89.362228,0.000233,0.000051,0.001301,8.171001,0.416251,0.013012,-89.362228,0.000807,0.000000
78.700005,1.842873,-89.362228,0.000263,0.000050,0.001276,8.197507,0.417601,0.012755,-89.362228,0.000755,0.000000
78.990005,1.862602,-89.451195,0.000254,0.000042,0.001076,8.285269,0.422072,0.010757,-89.451195,0.000712,0.000000
79.280006,1.854782,-89.451195,0.000267,0.000041,0.001050,8.250483,0.420300,0.010499,-89.451195,0.000659,0.000000
79.570007,1.872658,-89.495674,0.000237,0.000041,0.001050,8.329998,0.424350,0.010499,-89.495674,0.000607,0.000000
79.860001,1.834679,-89.495674,0.000276,0.000041,0.001050,8.161058,0.415744,0.010499,-89.495674,0.000564,0.000000
80.150002,1.836540,-89.495674,0.000246,0.000041,0.001050,8.169339,0.416166,0.010499,-89.495674,0.000512,0.000000
80.440002,1.847710,-89.495674,0.000259,0.000041,0.001050,8.219023,0.418697,0.010499,-89.495674,0.000469,0.000000
80.730003,1.860741,-89.406715,0.000254,0.000041,0.001050,8.276988,0.421650,0.010499,-89.406715,0.000416,0.000000
81.020004,1.833557,-89.451195,0.000263,0.000035,0.000893,8.156070,0.415490,0.008932,-89.451195,0.000373,0.000000
81.310005,1.839516,-89.495674,0.000254,0.000035,0.000893,8.182574,0.416840,0.008932,-89.495674,0.000321,0.000000
81.600006,1.833931,-89.451195,0.000263,0.000033,0.000850,8.157732,0.415575,0.008501,-89.451195,0.000269,0.000000
81.890007,1.867073,-89.495674,0.000259,0.000033,0.000833,8.305156,0.423085,0.008327,-89.495674,0.000226,0.000000
82.180000,1.857391,-89.495674,0.000250,0.000032,0.000807,8.262090,0.420891,0.008069,-89.495674,0.000174,0.000000
82.470001,1.847336,-89.540154,0.000241,0.000031,0.000798,8.217360,0.418612,0.007979,-89.540154,0.000130,0.000000
82.760002,1.838776,-89.540154,0.000285,0.000026,0.000668,8.179282,0.416673,0.006684,-89.540154,0.000079,0.000000
83.050003,1.845100,-89.495674,0.000250,0.000025,0.000625,8.207417,0.418106,0.006245,-89.495674,0.000035,0.000000
83.340004,1.837654,-89.540154,0.000285,0.000024,0.000616,8.174294,0.416418,0.006162,-89.540154,-0.000017,0.000000
83.630005,1.840263,-89.584633,0.000263,0.000024,0.000616,8.185901,0.417010,0.006162,-89.584633,-0.000069,0.000000
83.920006,1.832817,-89.584633,0.000254,0.000020,0.000512,8.152778,0.415322,0.005117,-89.584633,-0.000113,0.000000
84.210007,1.824249,-89.540154,0.000259,0.000020,0.000512,8.114666,0.413381,0.005117,-89.540154,-0.000164,0.000000
84.500008,1.822014,-89.584633,0.000267,0.000018,0.000460,8.104722,0.412874,0.004602,-89.584633,-0.000208,0.000000
84.790001,1.815689,-89.584633,0.000272,0.000015,0.000391,8.076589,0.411441,0.003906,-89.584633,-0.000260,0.000000
85.080002,1.821274,-89.584633,0.000272,0.000012,0.000304,8.101431,0.412707,0.003035,-89.584633,-0.000304,0.000000
85.370003,1.813454,-89.584633,0.000280,0.000009,0.000226,8.066645,0.410934,0.002256,-89.584633,-0.000355,0.000000
85.660004,1.823875,-89.629120,0.000267,0.000009,0.000226,8.113003,0.413296,0.002256,-89.629120,-0.000407,0.000000
85.950005,1.823135,-89.584633,0.000272,0.000007,0.000174,8.109712,0.413128,0.001741,-89.584633,-0.000450,0.000000
86.240005,1.820900,-89.629120,0.000272,0.000006,0.000157,8.099768,0.412622,0.001567,-89.629120,-0.000503,0.000000
86.530006,1.814194,-89.629120,0.000272,0.000004,0.000113,8.069937,0.411102,0.001128,-89.629120,-0.000546,0.000000
86.820007,1.799675,-89.629120,0.000272,0.000002,0.000052,8.005354,0.407812,0.000522,-89.629120,-0.000598,0.000000
87.110001,1.789246,-89.673599,0.000267,0.000002,0.000052,7.958962,0.405449,0.000522,-89.673599,-0.000641,0.000000
87.400002,1.776962,-89.673599,0.000276,0.000001,0.000017,7.904323,0.402665,0.000174,-89.673599,-0.000693,0.000000
87.690002,1.763184,-89.673599,0.000272,0.000000,0.000009,7.843032,0.399543,0.000091,-89.673599,-0.000746,0.000000
87.980003,1.780312,-89.673599,0.000263,-0.000006,-0.000147,7.919221,0.403424,-0.001469,-89.673599,-0.000789,0.000000
88.270004,1.740097,-89.718079,0.000267,-0.000012,-0.000294,7.740338,0.394312,-0.002945,-89.718079,-0.000841,0.000000
88.560005,1.751640,-89.629120,0.000250,-0.000012,-0.000304,7.791685,0.396927,-0.003035,-89.629120,-0.000884,0.000000
88.850006,1.718124,-89.673599,0.000259,-0.000014,-0.000364,7.642599,0.389333,-0.003641,-89.673599,-0.000936,0.000000
89.140007,1.756851,-89.718079,0.000241,-0.000015,-0.000372,7.814865,0.398108,-0.003724,-89.718079,-0.000980,0.000000
89.430008,1.746056,-89.673599,0.000263,-0.000016,-0.000399,7.766843,0.395662,-0.003989,-89.673599,-0.001032,0.000000
89.720001,1.749779,-89.718079,0.000276,-0.000016,-0.000399,7.783405,0.396506,-0.003989,-89.718079,-0.001084,0.000000
90.010002,1.712914,-89.718079,0.000272,-0.000016,-0.000416,7.619420,0.388152,-0.004156,-89.718079,-0.001127,0.000000
90.300003,1.670830,-89.673599,0.000259,-0.000021,-0.000546,7.432222,0.378615,-0.005458,-89.673599,-0.001179,0.000000
90.590004,1.590401,-89.807037,0.000276,-0.000027,-0.000676,7.074456,0.360390,-0.006760,-89.807037,-0.001223,0.000000
90.880005,1.580719,-89.718079,0.000254,-0.000028,-0.000719,7.031389,0.358196,-0.007191,-89.718079,-0.001275,0.000000
91.170006,1.559120,-89.762558,0.000267,-0.000030,-0.000763,6.935313,0.353302,-0.007630,-89.762558,-0.001318,0.000000
91.460007,1.533058,-89.807037,0.000267,-0.000033,-0.000832,6.819383,0.347396,-0.008319,-89.807037,-0.001370,0.000000
91.750008,1.490974,-89.762558,0.000276,-0.000034,-0.000876,6.632185,0.337860,-0.008758,-89.762558,-0.001422,0.000000
92.040001,1.444061,-89.807037,0.000267,-0.000037,-0.000927,6.423505,0.327229,-0.009273,-89.807037,-0.001466,0.000000
92.330002,1.431396,-89.807037,0.000280,-0.000039,-0.000980,6.367169,0.324359,-0.009795,-89.807037,-0.001517,0.000000
92.620003,1.411659,-89.762558,0.000259,-0.000041,-0.001040,6.279374,0.319887,-0.010401,-89.762558,-0.001561,0.000000
92.910004,1.406822,-89.807037,0.000250,-0.000044,-0.001118,6.257858,0.318790,-0.011181,-89.807037,-0.001612,0.000000
93.200005,1.396019,-89.762558,0.000267,-0.000045,-0.001145,6.209803,0.316342,-0.011446,-89.762558,-0.001656,0.000000
93.490005,1.388199,-89.851524,0.000280,-0.000046,-0.001170,6.175017,0.314570,-0.011703,-89.851524,-0.001708,0.000000
93.780006,1.369957,-89.762558,0.000289,-0.000048,-0.001231,6.093873,0.310437,-0.012308,-89.762558,-0.001760,0.000000
94.070007,1.333466,-89.807037,0.000267,-0.000051,-0.001283,5.931551,0.302168,-0.012831,-89.807037,-0.001804,0.000000
94.360008,1.328247,-89.851524,0.000267,-0.000051,-0.001292,5.908338,0.300985,-0.012922,-89.851524,-0.001855,0.000000
94.650002,1.320061,-89.807037,0.000276,-0.000052,-0.001326,5.871923,0.299130,-0.013262,-89.807037,-0.001899,0.000000
94.940002,1.324158,-89.896004,0.000250,-0.000054,-0.001361,5.890148,0.300058,-0.013610,-89.896004,-0.001951,0.000000
95.230003,1.304420,-89.807037,0.000285,-0.000055,-0.001388,5.802352,0.295586,-0.013875,-89.807037,-0.001995,0.000000
95.520004,1.293991,-89.851524,0.000259,-0.000056,-0.001422,5.755960,0.293223,-0.014216,-89.851524,-0.002046,0.000000
95.810005,1.271278,-89.896004,0.000259,-0.000057,-0.001439,5.654929,0.288076,-0.014390,-89.896004,-0.002098,0.000000
96.100006,1.255264,-89.807037,0.000272,-0.000058,-0.001474,5.583694,0.284447,-0.014738,-89.807037,-0.002141,0.000000
96.390007,1.235901,-89.940483,0.000263,-0.000059,-0.001509,5.497561,0.280059,-0.015087,-89.940483,-0.002194,0.000000
96.680008,1.178558,-89.940483,0.000276,-0.000063,-0.001596,5.242489,0.267065,-0.015957,-89.940483,-0.002237,0.000000
96.970001,1.182655,-89.896004,0.000276,-0.000063,-0.001612,5.260714,0.267994,-0.016124,-89.896004,-0.002289,0.000000
97.260002,1.161797,-89.984962,0.000267,-0.000065,-0.001639,5.167929,0.263267,-0.016389,-89.984962,-0.002332,0.000000
97.550003,1.136108,-89.896004,0.000280,-0.000065,-0.001656,5.053663,0.257446,-0.016563,-89.896004,-0.002384,0.000000
97.840004,1.149887,-89.984962,0.000263,-0.000067,-0.001699,5.114953,0.260568,-0.016994,-89.984962,-0.002437,0.000000
98.130005,1.122704,-89.896004,0.000280,-0.000069,-0.001752,4.994035,0.254408,-0.017516,-89.896004,-0.002480,0.000000
98.420006,1.107803,-89.896004,0.000267,-0.000070,-0.001769,4.927755,0.251032,-0.017691,-89.896004,-0.002532,0.000000
98.710007,1.093285,-89.984962,0.000272,-0.000073,-0.001847,4.863173,0.247742,-0.018470,-89.984962,-0.002575,0.000000
99.000008,1.063118,-89.940483,0.000289,-0.000075,-0.001899,4.728985,0.240906,-0.018993,-89.940483,-0.002627,0.000000
99.290001,1.038918,-89.940483,0.000254,-0.000075,-0.001916,4.621336,0.235422,-0.019159,-89.940483,-0.002671,0.000000
99.580002,1.061630,-89.940483,0.000272,-0.000076,-0.001925,4.722367,0.240569,-0.019250,-89.940483,-0.002723,0.000000
99.870003,1.066475,-89.940483,0.000276,-0.000076,-0.001933,4.743917,0.241667,-0.019333,-89.940483,-0.002775,0.000000
100.160004,1.023651,-89.984962,0.000272,-0.000079,-0.001995,4.553428,0.231963,-0.019946,-89.984962,-0.002818,0.000000
100.450005,1.034447,-89.896004,0.000263,-0.000079,-0.001995,4.601449,0.234409,-0.019946,-89.896004,-0.002870,0.000000
100.740005,1.047852,-90.029442,0.000250,-0.000079,-0.002003,4.661077,0.237447,-0.020030,-90.029442,-0.002914,0.000000
101.030006,0.863159,-89.940483,0.000263,-0.000092,-0.002341,3.839524,0.195595,-0.023413,-89.940483,-0.002966,0.000000
101.320007,0.862038,-90.073929,0.000246,-0.000093,-0.002367,3.834535,0.195341,-0.023671,-90.073929,-0.003017,0.000000
101.610008,0.861298,-90.073929,0.000276,-0.000093,-0.002367,3.831243,0.195173,-0.023671,-90.073929,-0.003061,0.000000
101.900002,0.848259,-89.984962,0.000267,-0.000093,-0.002367,3.773244,0.192218,-0.023671,-89.984962,-0.003113,0.000000
102.190002,0.860550,-89.984962,0.000259,-0.000093,-0.002367,3.827917,0.195003,-0.023671,-89.984962,-0.003157,0.000000
102.480003,0.848633,-89.984962,0.000250,-0.000096,-0.002428,3.774907,0.192303,-0.024276,-89.984962,-0.003208,0.000000
102.770004,0.846031,-89.984962,0.000250,-0.000096,-0.002428,3.763335,0.191713,-0.024276,-89.984962,-0.003252,0.000000
103.060005,0.856827,-90.118408,0.000267,-0.000096,-0.002428,3.811356,0.194160,-0.024276,-90.118408,-0.003303,0.000000
103.350006,0.860924,-90.029442,0.000280,-0.000096,-0.002428,3.829580,0.195088,-0.024276,-90.029442,-0.003356,0.000000
103.640007,0.769318,-90.029442,0.000250,-0.000102,-0.002593,3.422096,0.174330,-0.025927,-90.029442,-0.003399,0.000000
103.930008,0.778259,-90.073929,0.000254,-0.000102,-0.002593,3.461870,0.176356,-0.025927,-90.073929,-0.003451,0.000000
104.220001,0.779747,-90.073929,0.000259,-0.000102,-0.002601,3.468488,0.176693,-0.026010,-90.073929,-0.003494,0.000000
104.510002,0.772301,-90.073929,0.000254,-0.000102,-0.002601,3.435365,0.175006,-0.026010,-90.073929,-0.003546,0.000000
104.800003,0.678459,-90.073929,0.000263,-0.000111,-0.002809,3.017937,0.153741,-0.028091,-90.073929,-0.003590,0.000000
105.090004,0.677345,-90.118408,0.000250,-0.000111,-0.002818,3.012982,0.153489,-0.028182,-90.118408,-0.003642,0.000000
105.380005,0.654999,-90.118408,0.000280,-0.000114,-0.002888,2.913580,0.148425,-0.028879,-90.118408,-0.003694,0.000000
105.670006,0.641220,-90.118408,0.000259,-0.000116,-0.002939,2.852289,0.145303,-0.029393,-90.118408,-0.003737,0.000000
105.960007,0.624092,-90.162888,0.000250,-0.000117,-0.002983,2.776100,0.141421,-0.029833,-90.162888,-0.003789,0.000000
106.250008,0.624840,-90.118408,0.000272,-0.000120,-0.003044,2.779426,0.141591,-0.030438,-90.118408,-0.003833,0.000000
106.540009,0.595795,-90.118408,0.000259,-0.000122,-0.003096,2.650227,0.135009,-0.030960,-90.118408,-0.003885,0.000000
106.830002,0.583878,-90.162888,0.000259,-0.000123,-0.003130,2.597217,0.132309,-0.031301,-90.162888,-0.003928,0.000000
107.120003,0.554459,-90.162888,0.000246,-0.000128,-0.003243,2.466355,0.125642,-0.032429,-90.162888,-0.003980,0.000000
107.410004,0.534721,-90.207367,0.000259,-0.000129,-0.003287,2.378559,0.121170,-0.032868,-90.207367,-0.004032,0.000000
107.700005,0.535095,-90.118408,0.000246,-0.000130,-0.003295,2.380222,0.121254,-0.032951,-90.118408,-0.004076,0.000000
107.990005,0.519081,-90.162888,0.000259,-0.000130,-0.003303,2.308988,0.117625,-0.033035,-90.162888,-0.004128,0.000000
108.280006,0.486313,-90.207367,0.000233,-0.000134,-0.003416,2.163228,0.110200,-0.034162,-90.207367,-0.004171,0.000000
108.570007,0.482590,-90.118408,0.000241,-0.000137,-0.003468,2.146666,0.109356,-0.034685,-90.118408,-0.004223,0.000000
108.860008,0.460251,-90.251846,0.000220,-0.000137,-0.003486,2.047298,0.104294,-0.034859,-90.251846,-0.004266,0.000000
109.150002,0.477379,-90.207367,0.000229,-0.000138,-0.003512,2.123487,0.108176,-0.035116,-90.207367,-0.004319,0.000000
109.440002,0.460251,-90.207367,0.000254,-0.000140,-0.003556,2.047298,0.104294,-0.035555,-90.207367,-0.004371,0.000000
109.730003,0.435303,-90.296333,0.000250,-0.000143,-0.003633,1.936323,0.098641,-0.036335,-90.296333,-0.004414,0.000000
110.020004,0.385406,-90.251846,0.000237,-0.000149,-0.003781,1.714374,0.087334,-0.037811,-90.251846,-0.004466,0.000000
110.310005,0.388382,-90.251846,0.000229,-0.000150,-0.003807,1.727609,0.088009,-0.038068,-90.251846,-0.004509,0.000000
110.600006,0.369766,-90.251846,0.000224,-0.000150,-0.003807,1.644802,0.083790,-0.038068,-90.251846,-0.004562,0.000000
110.890007,0.383545,-90.251846,0.000237,-0.000150,-0.003807,1.706093,0.086913,-0.038068,-90.251846,-0.004605,0.000000
111.180008,0.382050,-90.251846,0.000229,-0.000152,-0.003867,1.699441,0.086574,-0.038674,-90.251846,-0.004657,0.000000
111.470009,0.354866,-90.207367,0.000211,-0.000154,-0.003902,1.578523,0.080414,-0.039022,-90.207367,-0.004708,0.000000
111.760002,0.354500,-90.296333,0.000229,-0.000154,-0.003920,1.576894,0.080331,-0.039196,-90.296333,-0.004752,0.000000
112.050003,0.366043,-90.251846,0.000229,-0.000155,-0.003945,1.628241,0.082947,-0.039454,-90.251846,-0.004804,0.000000
112.340004,0.320236,-90.296333,0.000233,-0.000159,-0.004041,1.424482,0.072567,-0.040408,-90.296333,-0.004848,0.000000
112.630005,0.313538,-90.340813,0.000233,-0.000160,-0.004076,1.394685,0.071049,-0.040756,-90.340813,-0.004899,0.000000
112.920006,0.289330,-90.340813,0.000198,-0.000163,-0.004145,1.287002,0.065563,-0.041452,-90.340813,-0.004943,0.000000
113.210007,0.275925,-90.385292,0.000229,-0.000164,-0.004171,1.227374,0.062525,-0.041710,-90.385292,-0.004995,0.000000
113.500008,0.266617,-90.296333,0.000216,-0.000166,-0.004214,1.185971,0.060416,-0.042141,-90.296333,-0.005047,0.000000
113.790009,0.249115,-90.340813,0.000211,-0.000168,-0.004275,1.108119,0.056450,-0.042754,-90.340813,-0.005090,0.000000
114.080002,0.223793,-90.340813,0.000224,-0.000171,-0.004353,0.995481,0.050712,-0.043534,-90.340813,-0.005142,0.000000
114.370003,0.227142,-90.296333,0.000220,-0.000172,-0.004379,1.010380,0.051471,-0.043791,-90.296333,-0.005185,0.000000
114.660004,0.232361,-90.385292,0.000194,-0.000173,-0.004388,1.033593,0.052654,-0.043882,-90.385292,-0.005238,0.000000
114.950005,0.192139,-90.340813,0.000224,-0.000177,-0.004484,0.854675,0.043539,-0.044836,-90.340813,-0.005281,0.000000
115.240005,0.187302,-90.340813,0.000211,-0.000178,-0.004527,0.833159,0.042443,-0.045267,-90.340813,-0.005333,0.000000
115.530006,0.184692,-90.385292,0.000220,-0.000180,-0.004562,0.821553,0.041852,-0.045616,-90.385292,-0.005385,0.000000
115.820007,0.179482,-90.385292,0.000203,-0.000182,-0.004613,0.798374,0.040671,-0.046130,-90.385292,-0.005428,0.000000
116.110008,0.156769,-90.385292,0.000220,-0.000183,-0.004648,0.697342,0.035524,-0.046479,-90.385292,-0.005481,0.000000
116.400009,0.164955,-90.429771,0.000233,-0.000184,-0.004683,0.733757,0.037379,-0.046827,-90.429771,-0.005524,0.000000
116.690002,0.163094,-90.385292,0.000216,-0.000186,-0.004717,0.725476,0.036958,-0.047175,-90.385292,-0.005576,0.000000
116.980003,0.165703,-90.340813,0.000211,-0.000186,-0.004726,0.737083,0.037549,-0.047258,-90.340813,-0.005619,0.000000
117.270004,0.162354,-90.340813,0.000229,-0.000188,-0.004787,0.722184,0.036790,-0.047871,-90.340813,-0.005671,0.000000
117.560005,0.148201,-90.429771,0.000203,-0.000190,-0.004821,0.659231,0.033583,-0.048212,-90.429771,-0.005724,0.000000
117.850006,0.158630,-90.429771,0.000203,-0.000192,-0.004873,0.705623,0.035946,-0.048734,-90.429771,-0.005767,0.000000
118.140007,0.155647,-90.429771,0.000198,-0.000194,-0.004926,0.692354,0.035270,-0.049257,-90.429771,-0.005819,0.000000
118.430008,0.160118,-90.474251,0.000190,-0.000195,-0.004943,0.712241,0.036283,-0.049431,-90.474251,-0.005862,0.000000
118.720009,0.130325,-90.429771,0.000185,-0.000196,-0.004978,0.579716,0.029532,-0.049779,-90.429771,-0.005914,0.000000
119.010002,0.147453,-90.518738,0.000216,-0.000198,-0.005029,0.655905,0.033413,-0.050294,-90.518738,-0.005957,0.000000
119.300003,0.137772,-90.429771,0.000211,-0.000201,-0.005099,0.612839,0.031219,-0.050990,-90.429771,-0.006010,0.000000
119.590004,0.119904,-90.474251,0.000216,-0.000203,-0.005151,0.533358,0.027171,-0.051512,-90.474251,-0.006062,0.000000
119.880005,0.084152,-90.563217,0.000198,-0.000208,-0.005281,0.374328,0.019069,-0.052814,-90.563217,-0.006105,0.000000
120.170006,0.076706,-90.429771,0.000194,-0.000210,-0.005333,0.341205,0.017382,-0.053329,-90.429771,-0.006157,0.000000
120.460007,0.048409,-90.518738,0.000181,-0.000213,-0.005420,0.215332,0.010970,-0.054200,-90.518738,-0.006200,0.000000
120.750008,0.074471,-90.474251,0.000177,-0.000214,-0.005428,0.331261,0.016875,-0.054283,-90.474251,-0.006253,0.000000
121.040009,0.090858,-90.429771,0.000181,-0.000214,-0.005437,0.404159,0.020589,-0.054374,-90.429771,-0.006296,0.000000
121.330009,0.067024,-90.563217,0.000181,-0.000218,-0.005541,0.298139,0.015188,-0.055411,-90.563217,-0.006348,0.000000
121.620003,0.063301,-90.563217,0.000181,-0.000219,-0.005550,0.281577,0.014344,-0.055502,-90.563217,-0.006400,0.000000
121.910004,0.050644,-90.563217,0.000172,-0.000221,-0.005602,0.225275,0.011476,-0.056016,-90.563217,-0.006443,0.000000
122.200005,0.062927,-90.563217,0.000194,-0.000222,-0.005646,0.279914,0.014260,-0.056455,-90.563217,-0.006495,0.000000
122.490005,0.048775,-90.518738,0.000160,-0.000224,-0.005689,0.216961,0.011053,-0.056887,-90.518738,-0.006539,0.000000
122.780006,0.034630,-90.563217,0.000155,-0.000228,-0.005784,0.154041,0.007847,-0.057841,-90.563217,-0.006590,0.000000
123.070007,0.027550,-90.563217,0.000160,-0.000229,-0.005810,0.122547,0.006243,-0.058098,-90.563217,-0.006642,0.000000
123.360008,0.043190,-90.607697,0.000155,-0.000229,-0.005827,0.192119,0.009787,-0.058272,-90.607697,-0.006686,0.000000
123.650009,0.027924,-90.563217,0.000172,-0.000232,-0.005897,0.124210,0.006328,-0.058969,-90.563217,-0.006738,0.000000
123.940002,0.046547,-90.563217,0.000177,-0.000232,-0.005897,0.207051,0.010548,-0.058969,-90.563217,-0.006781,0.000000
124.230003,0.018616,-90.607697,0.000164,-0.000236,-0.006001,0.082807,0.004218,-0.060006,-90.607697,-0.006833,0.000000
124.520004,0.032768,-90.652176,0.000160,-0.000236,-0.006001,0.145760,0.007425,-0.060006,-90.652176,-0.006876,0.000000
124.810005,0.026062,-90.607697,0.000160,-0.000236,-0.006001,0.115930,0.005906,-0.060006,-90.607697,-0.006929,0.000000
125.100006,0.011917,-90.652176,0.000172,-0.000237,-0.006010,0.053010,0.002700,-0.060097,-90.652176,-0.006981,0.000000
125.390007,0.002975,-90.607697,0.000164,-0.000237,-0.006010,0.013236,0.000674,-0.060097,-90.607697,-0.007024,0.000000
125.680008,0.003349,-90.696663,0.000164,-0.000239,-0.006062,0.014898,0.000759,-0.060619,-90.696663,-0.007076,0.000000
125.970009,0.010796,-90.652176,0.000134,-0.000241,-0.006131,0.048021,0.002446,-0.061308,-90.652176,-0.007119,0.000000
126.260010,0.006325,-90.607697,0.000147,-0.000241,-0.006131,0.028134,0.001433,-0.061308,-90.607697,-0.007172,0.000000
126.400009,-0.000374,-90.652176,0.000164,-0.000238,-0.006044,-0.001663,-0.000085,-0.060445,-90.652176,-0.006131,0.000000