File: Data/PDMS0040002 10N recovery test 1_10242023_182643.csv
Time (sec),S:Load (lbs),S:HL1 (DIM),S:LVDT (in),S:Position (in),Ch:Position (mm),Ch:Load (N),Ch:Stress (MPa),Ch:Strain (mm/mm),Ch:HL1 (DIM),Set Point (),Cycles ()
0.110000,0.003723,-77.352371,0.000034,-0.000000,-0.000000,0.016561,0.000844,-0.000000,-77.352371,-0.000191,0.000000
0.410000,0.000748,-77.352371,0.000034,-0.000000,-0.000000,0.003326,0.000169,-0.000000,-77.352371,-0.000182,0.000000
0.710000,-0.056595,-77.396858,0.000039,-0.000000,-0.000000,-0.251746,-0.012825,-0.000000,-77.396858,0.000321,0.000000
1.010000,-0.064049,-77.307892,0.000060,0.000013,0.000338,-0.284903,-0.014514,0.003384,-77.307892,0.000815,0.000000
1.310000,-0.076706,-77.396858,0.000043,0.000033,0.000850,-0.341205,-0.017382,0.008501,-77.396858,0.001318,0.000000
1.610000,-0.027184,-77.307892,0.000022,0.000050,0.001257,-0.120918,-0.006160,0.012573,-77.307892,0.001821,0.000000
1.910000,-0.023087,-77.396858,0.000030,0.000070,0.001786,-0.102694,-0.005231,0.017865,-77.396858,0.002316,0.000000
2.210000,0.002235,-77.352371,0.000047,0.000086,0.002185,0.009944,0.000507,0.021854,-77.352371,0.002818,0.000000
2.510000,0.023834,-77.352371,0.000030,0.000104,0.002637,0.106020,0.005401,0.026366,-77.352371,0.003322,0.000000
2.810000,0.011177,-77.396858,0.000022,0.000122,0.003104,0.049718,0.002533,0.031044,-77.396858,0.003816,0.000000
3.110000,0.008194,-77.441338,0.000034,0.000139,0.003521,0.036449,0.001857,0.035207,-77.441338,0.004319,0.000000
3.410000,0.021599,-77.396858,0.000056,0.000156,0.003963,0.096076,0.004894,0.039628,-77.396858,0.004822,0.000000
3.710000,0.071495,-77.396858,0.000060,0.000174,0.004423,0.318026,0.016201,0.044230,-77.396858,0.005316,0.000000
4.010000,0.107620,-77.485817,0.000065,0.000190,0.004822,0.478719,0.024387,0.048220,-77.485817,0.005819,0.000000
4.310000,0.179115,-77.441338,0.000073,0.000213,0.005420,0.796745,0.040588,0.054200,-77.441338,0.006322,0.000000
4.610000,0.185448,-77.396858,0.000108,0.000230,0.005836,0.824913,0.042023,0.058363,-77.396858,0.006817,0.000000
4.910000,0.210022,-77.396858,0.000121,-0.000000,-0.000000,0.934224,0.047592,-0.000000,-77.396858,0.000129,0.000000
5.210000,0.188797,-77.485817,0.000099,-0.000000,-0.000000,0.839811,0.042782,-0.000000,-77.485817,0.000129,0.000000
5.510000,0.180603,-77.441338,0.000099,-0.000000,-0.000000,0.803362,0.040925,-0.000000,-77.441338,0.000164,0.000000
5.810000,0.158630,-77.441338,0.000103,-0.000000,-0.000000,0.705623,0.035946,-0.000000,-77.441338,0.000216,0.000000
6.110000,0.202202,-77.441338,0.000112,-0.000000,-0.000000,0.899439,0.045820,-0.000000,-77.441338,0.000269,0.000000
6.410000,0.148209,-77.441338,0.000086,-0.000000,-0.000000,0.659265,0.033585,-0.000000,-77.441338,0.000312,0.000000
6.710001,0.179855,-77.485817,0.000116,-0.000000,-0.000000,0.800037,0.040756,-0.000000,-77.485817,0.000364,0.000000
7.010000,0.214493,-77.485817,0.000108,-0.000000,-0.000000,0.954112,0.048605,-0.000000,-77.485817,0.000416,0.000000
7.310000,0.156403,-77.485817,0.000112,-0.000000,-0.000000,0.695713,0.035441,-0.000000,-77.485817,0.000468,0.000000
7.610000,0.172409,-77.530296,0.000099,-0.000000,-0.000000,0.766914,0.039068,-0.000000,-77.530296,0.000511,0.000000
7.910000,0.158630,-77.485817,0.000112,-0.000000,-0.000000,0.705623,0.035946,-0.000000,-77.485817,0.000563,0.000000
8.210000,0.179855,-77.530296,0.000099,-0.000000,-0.000000,0.800037,0.040756,-0.000000,-77.530296,0.000615,0.000000
8.510000,0.186935,-77.574776,0.000108,-0.000000,-0.000000,0.831530,0.042360,-0.000000,-77.574776,0.000668,0.000000
8.810000,0.186935,-77.574776,0.000091,0.000000,0.000008,0.831530,0.042360,0.000083,-77.574776,0.000719,0.000000
9.110001,0.148209,-77.530296,0.000095,0.000001,0.000017,0.659265,0.033585,0.000167,-77.530296,0.000763,0.000000
9.410001,0.157516,-77.574776,0.000099,0.000001,0.000026,0.700668,0.035694,0.000257,-77.574776,0.000815,0.000000
9.710000,0.170547,-77.530296,0.000099,0.000001,0.000026,0.758633,0.038647,0.000257,-77.530296,0.000867,0.000000
10.010000,0.167198,-77.530296,0.000095,0.000002,0.000043,0.743735,0.037888,0.000431,-77.530296,0.000919,0.000000
10.310000,0.168312,-77.574776,0.000103,0.000002,0.000043,0.748689,0.038140,0.000431,-77.574776,0.000962,0.000000
10.610001,0.178368,-77.619263,0.000121,0.000004,0.000104,0.793419,0.040419,0.001037,-77.619263,0.001014,0.000000
10.910001,0.185448,-77.574776,0.000108,0.000004,0.000104,0.824913,0.042023,0.001037,-77.574776,0.001067,0.000000
11.210001,0.190659,-77.663742,0.000112,0.000009,0.000234,0.848092,0.043204,0.002339,-77.663742,0.001118,0.000000
11.510000,0.197357,-77.574776,0.000108,0.000009,0.000234,0.877889,0.044722,0.002339,-77.574776,0.001162,0.000000
11.810000,0.201454,-77.663742,0.000095,0.000010,0.000251,0.896113,0.045650,0.002513,-77.663742,0.001213,0.000000
12.110001,0.181717,-77.619263,0.000108,0.000010,0.000260,0.808317,0.041178,0.002596,-77.619263,0.001266,0.000000
12.410001,0.189171,-77.663742,0.000121,0.000013,0.000338,0.841474,0.042867,0.003376,-77.663742,0.001318,0.000000
12.710001,0.231621,-77.663742,0.000129,0.000018,0.000468,1.030301,0.052486,0.004678,-77.663742,0.001361,0.000000
13.010000,0.218956,-77.708221,0.000099,0.000019,0.000477,0.973965,0.049616,0.004769,-77.708221,0.001413,0.000000
13.310000,0.232735,-77.663742,0.000121,0.000019,0.000477,1.035256,0.052738,0.004769,-77.663742,0.001466,0.000000
13.610001,0.226776,-77.619263,0.000129,0.000019,0.000477,1.008751,0.051388,0.004769,-77.619263,0.001517,0.000000
13.910001,0.218216,-77.708221,0.000108,0.000019,0.000477,0.970673,0.049448,0.004769,-77.708221,0.001569,0.000000
14.210001,0.222679,-77.752701,0.000112,0.000019,0.000477,0.990526,0.050460,0.004769,-77.752701,0.001612,0.000000
14.510000,0.226402,-77.708221,0.000108,0.000019,0.000477,1.007088,0.051303,0.004769,-77.708221,0.001665,0.000000
14.810000,0.218216,-77.752701,0.000116,0.000019,0.000485,0.970673,0.049448,0.004852,-77.752701,0.001717,0.000000
15.110001,0.262901,-77.708221,0.000142,0.000030,0.000771,1.169443,0.059574,0.007714,-77.708221,0.001769,0.000000
15.410001,0.291199,-77.752701,0.000129,0.000033,0.000849,1.295317,0.065987,0.008493,-77.752701,0.001812,0.000000
15.710001,0.272583,-77.752701,0.000147,0.000033,0.000849,1.212510,0.061768,0.008493,-77.752701,0.001864,0.000000
16.010000,0.288963,-77.752701,0.000147,0.000039,0.000989,1.285373,0.065480,0.009886,-77.752701,0.001916,0.000000
16.310001,0.311310,-77.752701,0.000129,0.000040,0.001023,1.384775,0.070544,0.010227,-77.752701,0.001968,0.000000
16.610001,0.294548,-77.797180,0.000147,0.000042,0.001075,1.310215,0.066746,0.010749,-77.797180,0.002011,0.000000
16.910002,0.314285,-77.708221,0.000151,0.000045,0.001145,1.398011,0.071218,0.011446,-77.708221,0.002064,0.000000
17.210001,0.341095,-77.797180,0.000147,0.000047,0.001197,1.517266,0.077293,0.011968,-77.797180,0.002116,0.000000
17.510000,0.332161,-77.797180,0.000138,0.000048,0.001223,1.477526,0.075269,0.012225,-77.797180,0.002168,0.000000
17.810001,0.336624,-77.797180,0.000147,0.000050,0.001257,1.497379,0.076280,0.012573,-77.797180,0.002211,0.000000
18.110001,0.323967,-77.797180,0.000155,0.000052,0.001318,1.441077,0.073412,0.013179,-77.797180,0.002263,0.000000
18.410002,0.343704,-77.797180,0.000147,0.000053,0.001344,1.528873,0.077884,0.013436,-77.797180,0.002315,0.000000
18.710001,0.346306,-77.841667,0.000151,0.000056,0.001422,1.540445,0.078474,0.014216,-77.841667,0.002367,0.000000
19.010000,0.358597,-77.797180,0.000147,0.000057,0.001448,1.595118,0.081259,0.014481,-77.797180,0.002419,0.000000
19.310001,0.351524,-77.797180,0.000164,0.000058,0.001466,1.563658,0.079657,0.014655,-77.797180,0.002462,0.000000
19.610001,0.388016,-77.797180,0.000155,0.000061,0.001543,1.725980,0.087926,0.015435,-77.797180,0.002515,0.000000
19.910002,0.373863,-77.797180,0.000160,0.000061,0.001552,1.663027,0.084719,0.015518,-77.797180,0.002567,0.000000
20.210001,0.371628,-77.841667,0.000142,0.000062,0.001569,1.653083,0.084212,0.015692,-77.841667,0.002618,0.000000
20.510000,0.383545,-77.797180,0.000172,0.000064,0.001621,1.706093,0.086913,0.016214,-77.797180,0.002662,0.000000
20.810001,0.391739,-77.841667,0.000155,0.000065,0.001647,1.742542,0.088769,0.016472,-77.841667,0.002714,0.000000
21.110001,0.379082,-77.841667,0.000164,0.000068,0.001734,1.686240,0.085901,0.017342,-77.841667,0.002766,0.000000
21.410002,0.390251,-77.841667,0.000151,0.000068,0.001734,1.735924,0.088432,0.017342,-77.841667,0.002818,0.000000
21.710001,0.419296,-77.930626,0.000177,0.000073,0.001855,1.865123,0.095014,0.018554,-77.930626,0.002861,0.000000
22.010000,0.449829,-77.886147,0.000168,0.000075,0.001899,2.000940,0.101933,0.018993,-77.886147,0.002914,0.000000
22.310001,0.474403,-77.930626,0.000160,0.000077,0.001960,2.110252,0.107501,0.019598,-77.930626,0.002966,0.000000
22.610001,0.468445,-77.930626,0.000172,0.000079,0.001995,2.083747,0.106151,0.019946,-77.930626,0.003017,0.000000
22.910002,0.469193,-77.930626,0.000168,0.000079,0.001995,2.087073,0.106321,0.019946,-77.930626,0.003070,0.000000
23.210001,0.515739,-77.930626,0.000181,0.000083,0.002107,2.294124,0.116868,0.021067,-77.930626,0.003113,0.000000
23.510000,0.551117,-77.886147,0.000172,0.000087,0.002219,2.451491,0.124885,0.022195,-77.886147,0.003165,0.000000
23.810001,0.551857,-77.930626,0.000172,0.000089,0.002272,2.454782,0.125053,0.022717,-77.930626,0.003217,0.000000
24.110001,0.561913,-77.886147,0.000216,0.000090,0.002289,2.499512,0.127331,0.022891,-77.886147,0.003269,0.000000
24.410002,0.551857,-78.019585,0.000198,0.000090,0.002298,2.454782,0.125053,0.022982,-78.019585,0.003313,0.000000
24.710001,0.541801,-77.975105,0.000203,0.000090,0.002298,2.410053,0.122774,0.022982,-77.975105,0.003365,0.000000
25.010002,0.569733,-77.930626,0.000181,0.000094,0.002394,2.534297,0.129103,0.023936,-77.930626,0.003416,0.000000
25.310001,0.574203,-77.975105,0.000194,0.000096,0.002437,2.554185,0.130116,0.024367,-77.975105,0.003468,0.000000
25.610001,0.586121,-78.064072,0.000194,0.000096,0.002445,2.607195,0.132817,0.024450,-78.064072,0.003512,0.000000
25.910002,0.580902,-78.019585,0.000194,0.000098,0.002489,2.583982,0.131634,0.024889,-78.019585,0.003564,0.000000
26.210001,0.651283,-77.975105,0.000207,0.000103,0.002610,2.897053,0.147583,0.026101,-77.975105,0.003616,0.000000
26.510002,0.685539,-78.064072,0.000198,0.000106,0.002697,3.049431,0.155345,0.026971,-78.064072,0.003668,0.000000
26.810001,0.679955,-78.064072,0.000224,0.000106,0.002697,3.024589,0.154080,0.026971,-78.064072,0.003711,0.000000
27.110001,0.699318,-77.975105,0.000194,0.000110,0.002792,3.110722,0.158468,0.027925,-77.975105,0.003764,0.000000
27.410002,0.690010,-78.108551,0.000211,0.000110,0.002801,3.069318,0.156359,0.028008,-78.108551,0.003815,0.000000
27.710001,0.692245,-78.019585,0.000220,0.000111,0.002827,3.079262,0.156865,0.028266,-78.019585,0.003867,0.000000
28.010002,0.726128,-78.064072,0.000207,0.000113,0.002879,3.229977,0.164543,0.028788,-78.064072,0.003920,0.000000
28.310001,0.723152,-78.064072,0.000220,0.000114,0.002888,3.216742,0.163869,0.028879,-78.064072,0.003963,0.000000
28.610001,0.722031,-78.064072,0.000211,0.000116,0.002939,3.211753,0.163614,0.029393,-78.064072,0.004015,0.000000
28.910002,0.736931,-78.064072,0.000211,0.000120,0.003044,3.278032,0.166991,0.030438,-78.064072,0.004067,0.000000
29.210001,0.788689,-78.108551,0.000211,0.000125,0.003174,3.508262,0.178719,0.031740,-78.108551,0.004119,0.000000
29.510002,0.804329,-78.108551,0.000211,0.000125,0.003182,3.577834,0.182264,0.031823,-78.108551,0.004163,0.000000
29.810001,0.774910,-78.064072,0.000216,0.000125,0.003182,3.446972,0.175597,0.031823,-78.064072,0.004214,0.000000
30.110001,0.794647,-78.108551,0.000224,0.000128,0.003260,3.534767,0.180070,0.032603,-78.108551,0.004266,0.000000
30.410002,0.813263,-78.153030,0.000229,0.000130,0.003303,3.617574,0.184288,0.033035,-78.153030,0.004319,0.000000
30.710001,0.828156,-78.153030,0.000224,0.000133,0.003373,3.683820,0.187663,0.033731,-78.153030,0.004362,0.000000
31.010002,0.811401,-78.197510,0.000224,0.000133,0.003382,3.609293,0.183866,0.033822,-78.197510,0.004414,0.000000
31.310001,0.885132,-78.108551,0.000216,0.000138,0.003503,3.937263,0.200574,0.035033,-78.108551,0.004466,0.000000
31.610001,0.896675,-78.153030,0.000224,0.000141,0.003590,3.988610,0.203189,0.035904,-78.153030,0.004518,0.000000
31.910002,0.919762,-78.153030,0.000233,0.000142,0.003607,4.091304,0.208421,0.036070,-78.153030,0.004562,0.000000
32.210003,0.891464,-78.108551,0.000237,0.000142,0.003607,3.965431,0.202009,0.036070,-78.108551,0.004613,0.000000
32.510002,0.914925,-78.153030,0.000237,0.000144,0.003668,4.069788,0.207325,0.036683,-78.153030,0.004665,0.000000
32.810001,0.919762,-78.197510,0.000259,0.000145,0.003677,4.091304,0.208421,0.036766,-78.197510,0.004717,0.000000
33.110001,0.917526,-78.153030,0.000229,0.000145,0.003677,4.081360,0.207914,0.036766,-78.153030,0.004770,0.000000
33.410000,0.992378,-78.153030,0.000250,0.000153,0.003876,4.414319,0.224876,0.038765,-78.153030,0.004813,0.000000
33.710003,0.997215,-78.241989,0.000259,0.000153,0.003885,4.435835,0.225972,0.038848,-78.241989,0.004865,0.000000
34.010002,1.011742,-78.197510,0.000254,0.000155,0.003945,4.500452,0.229264,0.039454,-78.197510,0.004917,0.000000
34.310001,1.009132,-78.241989,0.000254,0.000156,0.003963,4.488845,0.228673,0.039628,-78.241989,0.004969,0.000000
34.610001,1.022163,-78.197510,0.000254,0.000158,0.004023,4.546810,0.231626,0.040233,-78.197510,0.005012,0.000000
34.910000,1.051208,-78.241989,0.000254,0.000161,0.004093,4.676009,0.238207,0.040930,-78.241989,0.005064,0.000000
35.210003,1.050835,-78.241989,0.000267,0.000162,0.004119,4.674346,0.238123,0.041187,-78.241989,0.005116,0.000000
35.510002,1.030731,-78.286476,0.000246,0.000163,0.004136,4.584921,0.233567,0.041361,-78.286476,0.005169,0.000000
35.810001,1.048973,-78.330956,0.000259,0.000165,0.004180,4.666065,0.237701,0.041800,-78.330956,0.005212,0.000000
36.110001,1.099617,-78.330956,0.000259,0.000169,0.004292,4.891341,0.249177,0.042921,-78.330956,0.005264,0.000000
36.410000,1.124939,-78.330956,0.000254,0.000172,0.004362,5.003978,0.254915,0.043617,-78.330956,0.005316,0.000000
36.710003,1.117493,-78.330956,0.000272,0.000172,0.004362,4.970856,0.253227,0.043617,-78.330956,0.005368,0.000000
37.010002,1.117493,-78.286476,0.000254,0.000173,0.004388,4.970856,0.253227,0.043882,-78.286476,0.005411,0.000000
37.310001,1.105576,-78.286476,0.000254,0.000175,0.004440,4.917846,0.250527,0.044397,-78.286476,0.005463,0.000000
37.610001,1.146164,-78.330956,0.000263,0.000177,0.004492,5.098392,0.259724,0.044919,-78.330956,0.005515,0.000000
37.910004,1.179680,-78.286476,0.000263,0.000181,0.004587,5.247478,0.267319,0.045873,-78.286476,0.005568,0.000000
38.210003,1.187126,-78.286476,0.000272,0.000181,0.004605,5.280601,0.269007,0.046047,-78.286476,0.005619,0.000000
38.510002,1.222504,-78.330956,0.000276,0.000184,0.004665,5.437968,0.277023,0.046653,-78.330956,0.005663,0.000000
38.810001,1.219147,-78.330956,0.000285,0.000185,0.004708,5.423036,0.276263,0.047084,-78.330956,0.005714,0.000000
39.110001,1.199783,-78.375435,0.000293,0.000186,0.004717,5.336903,0.271875,0.047175,-78.375435,0.005767,0.000000
39.410004,1.222130,-78.375435,0.000280,0.000189,0.004795,5.436305,0.276939,0.047955,-78.375435,0.005819,0.000000
39.710003,1.258247,-78.375435,0.000280,0.000189,0.004795,5.596964,0.285123,0.047955,-78.375435,0.005862,0.000000
40.010002,1.278358,-78.419914,0.000289,0.000192,0.004883,5.686422,0.289680,0.048825,-78.419914,0.005914,0.000000
40.310001,1.308891,-78.419914,0.000280,0.000194,0.004917,5.822239,0.296599,0.049166,-78.419914,0.005967,0.000000
40.610001,1.309639,-78.419914,0.000276,0.000194,0.004934,5.825565,0.296768,0.049340,-78.419914,0.006018,0.000000
40.910004,1.321182,-78.375435,0.000297,0.000195,0.004943,5.876912,0.299384,0.049431,-78.375435,0.006062,0.000000
41.210003,1.330864,-78.419914,0.000276,0.000197,0.005004,5.919979,0.301578,0.050036,-78.419914,0.006113,0.000000
41.510002,1.374054,-78.419914,0.000297,0.000199,0.005047,6.112097,0.311365,0.050468,-78.419914,0.006166,0.000000
41.810001,1.457100,-78.419914,0.000289,0.000206,0.005220,6.481504,0.330184,0.052201,-78.419914,0.006218,0.000000
42.110001,1.452255,-78.464401,0.000276,0.000206,0.005220,6.459954,0.329086,0.052201,-78.464401,0.006261,0.000000
42.410004,1.446297,-78.419914,0.000302,0.000206,0.005229,6.433449,0.327736,0.052292,-78.419914,0.006313,0.000000
42.710003,1.493958,-78.419914,0.000280,0.000211,0.005350,6.645455,0.338536,0.053503,-78.419914,0.006365,0.000000
43.010002,1.503273,-78.464401,0.000289,0.000211,0.005350,6.686893,0.340647,0.053503,-78.464401,0.006417,0.000000
43.310001,1.501038,-78.464401,0.000302,0.000211,0.005350,6.676949,0.340140,0.053503,-78.464401,0.006469,0.000000
43.610001,1.527473,-78.464401,0.000297,0.000214,0.005437,6.794541,0.346130,0.054374,-78.464401,0.006512,0.000000
43.910004,1.561363,-78.464401,0.000319,0.000217,0.005515,6.945291,0.353810,0.055153,-78.464401,0.006565,0.000000
44.210003,1.574768,-78.553360,0.000293,0.000220,0.005576,7.004918,0.356848,0.055759,-78.553360,0.006617,0.000000
44.510002,1.595993,-78.508881,0.000293,0.000220,0.005593,7.099331,0.361657,0.055933,-78.508881,0.006669,0.000000
44.810001,1.611259,-78.464401,0.000315,0.000221,0.005619,7.167240,0.365117,0.056191,-78.464401,0.006712,0.000000
45.110001,1.636955,-78.508881,0.000306,0.000224,0.005697,7.281541,0.370939,0.056970,-78.508881,0.006764,0.000000
45.410004,1.650726,-78.419914,0.000297,0.000225,0.005714,7.342797,0.374060,0.057144,-78.419914,0.006816,0.000000
45.710003,1.667488,-78.508881,0.000328,0.000226,0.005749,7.417357,0.377858,0.057493,-78.508881,0.006868,0.000000
46.010002,1.674187,-78.508881,0.000319,0.000229,0.005810,7.447155,0.379376,0.058098,-78.508881,0.006911,0.000000
46.310001,1.678284,-78.508881,0.000319,0.000229,0.005810,7.465379,0.380305,0.058098,-78.508881,0.006963,0.000000
46.610001,1.675682,-78.508881,0.000306,0.000229,0.005810,7.453806,0.379715,0.058098,-78.508881,0.007016,0.000000
46.910004,1.667114,-78.553360,0.000332,0.000229,0.005810,7.415695,0.377773,0.058098,-78.553360,0.007068,0.000000
47.210003,1.660408,-78.508881,0.000336,0.000229,0.005810,7.385864,0.376254,0.058098,-78.508881,0.007119,0.000000
47.510002,1.651100,-78.553360,0.000328,0.000229,0.005810,7.344460,0.374145,0.058098,-78.553360,0.007163,0.000000
47.810001,1.655945,-78.553360,0.000310,0.000229,0.005810,7.366011,0.375242,0.058098,-78.553360,0.007215,0.000000
48.110001,1.894264,-78.553360,0.000332,0.000242,0.006148,8.426108,0.429246,0.061482,-78.553360,0.007267,0.000000
48.410004,1.883835,-78.642319,0.000319,0.000243,0.006175,8.379716,0.426883,0.061747,-78.642319,0.007319,0.000000
48.710003,1.903946,-78.553360,0.000336,0.000246,0.006261,8.469174,0.431440,0.062610,-78.553360,0.007362,0.000000
49.010002,1.967621,-78.597839,0.000323,0.000249,0.006322,8.752415,0.445869,0.063215,-78.597839,0.007415,0.000000
49.310001,1.957939,-78.597839,0.000354,0.000249,0.006322,8.709349,0.443675,0.063215,-78.597839,0.007467,0.000000
49.610001,1.940811,-78.597839,0.000328,0.000249,0.006322,8.633160,0.439794,0.063215,-78.597839,0.007518,0.000000
49.910004,1.926285,-78.553360,0.000323,0.000249,0.006322,8.568542,0.436502,0.063215,-78.553360,0.007562,0.000000
50.210003,2.101303,-78.642319,0.000341,0.000260,0.006599,9.347063,0.476162,0.065993,-78.642319,0.007614,0.000000
50.510002,2.121033,-78.642319,0.000332,0.000261,0.006625,9.434825,0.480633,0.066251,-78.642319,0.007666,0.000000
50.810001,2.203331,-78.597839,0.000354,0.000266,0.006755,9.800906,0.499282,0.067553,-78.597839,0.007718,0.000000
51.110001,2.221581,-78.686806,0.000336,0.000268,0.006798,9.882084,0.503417,0.067984,-78.686806,0.007761,0.000000
51.410004,2.232750,-78.686806,0.000328,0.000270,0.006851,9.931767,0.505948,0.068507,-78.686806,0.007814,0.000000
51.710003,2.210403,-78.642319,0.000336,0.000263,0.006686,9.832366,0.500885,0.066856,-78.642319,0.006868,0.000000
52.010002,2.195885,-78.642319,0.000358,0.000263,0.006669,9.767783,0.497595,0.066690,-78.642319,0.006868,0.000000
52.310001,2.165352,-78.686806,0.000354,0.000263,0.006669,9.631967,0.490676,0.066690,-78.686806,0.006816,0.000000
52.610001,2.153061,-78.686806,0.000354,0.000262,0.006660,9.577293,0.487891,0.066599,-78.686806,0.006764,0.000000
52.910004,2.147476,-78.686806,0.000358,0.000262,0.006660,9.552451,0.486625,0.066599,-78.686806,0.006720,0.000000
53.210003,2.126625,-78.731285,0.000345,0.000262,0.006660,9.459701,0.481900,0.066599,-78.731285,0.006669,0.000000
53.510002,2.103905,-78.775764,0.000341,0.000262,0.006660,9.358636,0.476752,0.066599,-78.775764,0.006617,0.000000
53.810001,2.101669,-78.686806,0.000362,0.000262,0.006660,9.348692,0.476245,0.066599,-78.686806,0.006565,0.000000
54.110004,2.098320,-78.731285,0.000358,0.000262,0.006660,9.333794,0.475486,0.066599,-78.731285,0.006512,0.000000
54.410004,2.091988,-78.686806,0.000371,0.000262,0.006652,9.305626,0.474051,0.066516,-78.686806,0.006469,0.000000
54.710003,2.077469,-78.731285,0.000336,0.000260,0.006608,9.241043,0.470761,0.066077,-78.731285,0.006417,0.000000
55.010002,2.035767,-78.731285,0.000354,0.000258,0.006556,9.055542,0.461311,0.065562,-78.731285,0.006365,0.000000
55.310001,2.045074,-78.731285,0.000349,0.000256,0.006512,9.096946,0.463421,0.065123,-78.731285,0.006313,0.000000
55.610004,2.035019,-78.775764,0.000354,0.000255,0.006469,9.052217,0.461142,0.064691,-78.775764,0.006270,0.000000
55.910004,2.017143,-78.731285,0.000336,0.000253,0.006417,8.972701,0.457091,0.064169,-78.731285,0.006218,0.000000
56.210003,1.978043,-78.775764,0.000332,0.000251,0.006365,8.798773,0.448231,0.063654,-78.775764,0.006166,0.000000
56.510002,2.018631,-78.775764,0.000358,0.000249,0.006322,8.979319,0.457428,0.063215,-78.775764,0.006113,0.000000
56.810001,1.979904,-78.731285,0.000354,0.000247,0.006278,8.807054,0.448653,0.062784,-78.731285,0.006070,0.000000
57.110004,2.002625,-78.775764,0.000362,0.000245,0.006226,8.908119,0.453801,0.062262,-78.775764,0.006018,0.000000
57.410004,1.904686,-78.775764,0.000354,0.000243,0.006183,8.472466,0.431608,0.061830,-78.775764,0.005967,0.000000
57.710003,1.914368,-78.775764,0.000349,0.000242,0.006140,8.515532,0.433802,0.061399,-78.775764,0.005914,0.000000
58.010002,1.894630,-78.775764,0.000345,0.000240,0.006096,8.427737,0.429329,0.060960,-78.775764,0.005862,0.000000
58.310001,1.937828,-78.864723,0.000362,0.000238,0.006053,8.619890,0.439118,0.060528,-78.864723,0.005819,0.000000
58.610004,2.001129,-78.864723,0.000366,0.000237,0.006010,8.901467,0.453462,0.060097,-78.864723,0.005767,0.000000
58.910004,1.874901,-78.820244,0.000371,0.000234,0.005932,8.339975,0.424859,0.059317,-78.820244,0.005714,0.000000
59.210003,1.873405,-78.864723,0.000362,0.000232,0.005897,8.333323,0.424520,0.058969,-78.864723,0.005663,0.000000
59.510002,1.860748,-78.909210,0.000366,0.000230,0.005836,8.277021,0.421652,0.058363,-78.909210,0.005619,0.000000
59.810001,1.868942,-78.864723,0.000358,0.000228,0.005792,8.313471,0.423508,0.057924,-78.864723,0.005568,0.000000
60.110004,1.975815,-78.864723,0.000371,0.000227,0.005758,8.788863,0.447726,0.057583,-78.864723,0.005515,0.000000
60.410004,1.875267,-78.820244,0.000362,0.000227,0.005758,8.341604,0.424942,0.057583,-78.820244,0.005463,0.000000
60.710003,1.993683,-78.820244,0.000354,0.000227,0.005758,8.868344,0.451775,0.057583,-78.820244,0.005420,0.000000
61.010002,1.944534,-78.909210,0.000362,0.000227,0.005758,8.649720,0.440638,0.057583,-78.909210,0.005368,0.000000
61.310001,1.969856,-78.909210,0.000362,0.000227,0.005758,8.762359,0.446376,0.057583,-78.909210,0.005316,0.000000
61.610004,1.940437,-78.820244,0.000345,0.000220,0.005584,8.631496,0.439709,0.055842,-78.820244,0.005264,0.000000
61.910004,1.964638,-78.909210,0.000366,0.000219,0.005558,8.739145,0.445193,0.055585,-78.909210,0.005220,0.000000
62.210003,1.926285,-78.909210,0.000358,0.000218,0.005541,8.568542,0.436502,0.055411,-78.909210,0.005169,0.000000
62.510002,1.955704,-78.953690,0.000349,0.000217,0.005524,8.699405,0.443169,0.055237,-78.953690,0.005116,0.000000
62.810001,1.965012,-78.953690,0.000358,0.000215,0.005463,8.740808,0.445278,0.054631,-78.953690,0.005064,0.000000
63.110004,1.942673,-78.953690,0.000362,0.000214,0.005428,8.641439,0.440216,0.054283,-78.953690,0.005012,0.000000
63.410004,1.896866,-78.998169,0.000354,0.000213,0.005420,8.437680,0.429836,0.054200,-78.998169,0.004969,0.000000
63.710003,1.908783,-78.953690,0.000362,0.000213,0.005420,8.490690,0.432536,0.054200,-78.953690,0.004917,0.000000
64.010002,1.903946,-78.909210,0.000366,0.000211,0.005350,8.469174,0.431440,0.053503,-78.909210,0.004865,0.000000
64.310005,1.896492,-78.998169,0.000371,0.000210,0.005342,8.436018,0.429751,0.053420,-78.998169,0.004813,0.000000
64.610001,1.897614,-79.042648,0.000362,0.000207,0.005255,8.441007,0.430005,0.052549,-79.042648,0.004770,0.000000
64.910004,1.889046,-78.998169,0.000358,0.000205,0.005194,8.402895,0.428064,0.051944,-78.998169,0.004717,0.000000
65.210007,1.903572,-78.953690,0.000354,0.000205,0.005194,8.467511,0.431356,0.051944,-78.953690,0.004665,0.000000
65.510002,1.895752,-78.998169,0.000366,0.000200,0.005073,8.432726,0.429584,0.050733,-78.998169,0.004613,0.000000
65.810005,1.871178,-78.998169,0.000362,0.000198,0.005029,8.323414,0.424015,0.050294,-78.998169,0.004570,0.000000
66.110001,1.874901,-79.087128,0.000354,0.000196,0.004986,8.339975,0.424859,0.049862,-79.087128,0.004518,0.000000
66.410004,1.895378,-79.087128,0.000371,0.000196,0.004969,8.431063,0.429499,0.049688,-79.087128,0.004466,0.000000
66.710007,1.906174,-79.042648,0.000358,0.000190,0.004821,8.479084,0.431945,0.048212,-79.042648,0.004414,0.000000
67.010002,1.873779,-79.042648,0.000358,0.000190,0.004821,8.334987,0.424604,0.048212,-79.042648,0.004371,0.000000
67.310005,1.874901,-79.087128,0.000362,0.000188,0.004786,8.339975,0.424859,0.047864,-79.087128,0.004319,0.000000
67.610001,1.870430,-79.042648,0.000354,0.000186,0.004735,8.320088,0.423845,0.047349,-79.042648,0.004266,0.000000
67.910004,1.920326,-79.131615,0.000354,0.000183,0.004648,8.542038,0.435152,0.046479,-79.131615,0.004214,0.000000
68.210007,1.869316,-79.042648,0.000362,0.000183,0.004648,8.315133,0.423593,0.046479,-79.042648,0.004163,0.000000
68.510002,1.904686,-79.087128,0.000345,0.000180,0.004562,8.472466,0.431608,0.045616,-79.087128,0.004119,0.000000
68.810005,1.857399,-79.087128,0.000366,0.000179,0.004544,8.262123,0.420893,0.045441,-79.087128,0.004067,0.000000
69.110001,1.907669,-79.131615,0.000358,0.000172,0.004379,8.485736,0.432284,0.043791,-79.131615,0.004015,0.000000
69.410004,1.909157,-79.131615,0.000354,0.000172,0.004379,8.492353,0.432621,0.043791,-79.131615,0.003963,0.000000
69.710007,1.861122,-79.131615,0.000362,0.000172,0.004379,8.278685,0.421736,0.043791,-79.131615,0.003920,0.000000
70.010002,1.866707,-79.087128,0.000371,0.000172,0.004379,8.303527,0.423002,0.043791,-79.087128,0.003867,0.000000
70.310005,1.888306,-79.131615,0.000366,0.000164,0.004171,8.399603,0.427896,0.041710,-79.131615,0.003815,0.000000
70.610001,1.891655,-79.131615,0.000366,0.000163,0.004128,8.414501,0.428655,0.041278,-79.131615,0.003764,0.000000
70.910004,1.889046,-79.176094,0.000336,0.000163,0.004128,8.402895,0.428064,0.041278,-79.176094,0.003720,0.000000
71.210007,1.898361,-79.176094,0.000345,0.000158,0.004015,8.444332,0.430175,0.040150,-79.176094,0.003668,0.000000
71.510002,1.874527,-79.176094,0.000362,0.000156,0.003972,8.338312,0.424774,0.039719,-79.176094,0.003616,0.000000
71.810005,1.866707,-79.176094,0.000362,0.000155,0.003937,8.303527,0.423002,0.039370,-79.176094,0.003564,0.000000
72.110001,1.861496,-79.176094,0.000362,0.000153,0.003893,8.280348,0.421821,0.038931,-79.176094,0.003521,0.000000
72.410004,1.826118,-79.220573,0.000362,0.000151,0.003833,8.122981,0.413804,0.038326,-79.220573,0.003468,0.000000
72.710007,1.851814,-79.220573,0.000366,0.000149,0.003772,8.237281,0.419627,0.037720,-79.220573,0.003416,0.000000
73.010002,1.829842,-79.220573,0.000341,0.000147,0.003737,8.139542,0.414648,0.037372,-79.220573,0.003365,0.000000
73.310005,1.845856,-79.220573,0.000362,0.000145,0.003686,8.210776,0.418277,0.036857,-79.220573,0.003313,0.000000
73.610001,1.834312,-79.220573,0.000362,0.000143,0.003633,8.159430,0.415661,0.036335,-79.220573,0.003269,0.000000
73.910004,1.838776,-79.265053,0.000354,0.000141,0.003590,8.179282,0.416673,0.035904,-79.265053,0.003217,0.000000
74.210007,1.861496,-79.265053,0.000358,0.000139,0.003521,8.280348,0.421821,0.035207,-79.265053,0.003165,0.000000
74.510002,1.826118,-79.220573,0.000345,0.000138,0.003494,8.122981,0.413804,0.034942,-79.220573,0.003113,0.000000
74.810005,1.848831,-79.220573,0.000349,0.000136,0.003460,8.224011,0.418951,0.034602,-79.220573,0.003070,0.000000
75.110001,1.849953,-79.220573,0.000366,0.000134,0.003408,8.229001,0.419205,0.034079,-79.220573,0.003017,0.000000
75.410004,1.887932,-79.265053,0.000366,0.000133,0.003373,8.397941,0.427811,0.033731,-79.265053,0.002966,0.000000
75.710007,1.887932,-79.265053,0.000362,0.000131,0.003338,8.397941,0.427811,0.033383,-79.265053,0.002914,0.000000
76.010002,1.855164,-79.265053,0.000362,0.000130,0.003303,8.252180,0.420386,0.033035,-79.265053,0.002870,0.000000
76.310005,1.871918,-79.309532,0.000358,0.000128,0.003243,8.326706,0.424183,0.032429,-79.309532,0.002818,0.000000
76.610001,1.858513,-79.354019,0.000362,0.000126,0.003191,8.267078,0.421145,0.031914,-79.354019,0.002766,0.000000
76.910004,1.849205,-79.309532,0.000362,0.000124,0.003157,8.225675,0.419036,0.031566,-79.309532,0.002714,0.000000
77.210007,1.868568,-79.354019,0.000379,0.000122,0.003087,8.311808,0.423424,0.030870,-79.354019,0.002662,0.000000
77.510002,1.846596,-79.309532,0.000366,0.000121,0.003061,8.214068,0.418445,0.030612,-79.309532,0.002618,0.000000
77.810005,1.830956,-79.265053,0.000366,0.000119,0.003035,8.144497,0.414900,0.030347,-79.265053,0.002567,0.000000
78.110001,1.836540,-79.398499,0.000362,0.000116,0.002957,8.169339,0.416166,0.029568,-79.398499,0.002515,0.000000
78.410004,1.860748,-79.309532,0.000358,0.000114,0.002905,8.277021,0.421652,0.029045,-79.309532,0.002462,0.000000
78.710007,1.843620,-79.309532,0.000345,0.000113,0.002861,8.200832,0.417770,0.028614,-79.309532,0.002419,0.000000
79.010002,1.861496,-79.354019,0.000366,0.000110,0.002792,8.280348,0.421821,0.027925,-79.354019,0.002367,0.000000
79.310005,1.859261,-79.309532,0.000345,0.000108,0.002731,8.270404,0.421314,0.027312,-79.309532,0.002315,0.000000
79.610001,1.829842,-79.354019,0.000336,0.000105,0.002662,8.139542,0.414648,0.026623,-79.354019,0.002263,0.000000
79.910004,1.856651,-79.398499,0.000358,0.000104,0.002636,8.258798,0.420723,0.026358,-79.398499,0.002219,0.000000
80.210007,1.840271,-79.354019,0.000375,0.000101,0.002567,8.185934,0.417011,0.025669,-79.354019,0.002168,0.000000
80.510002,1.849205,-79.354019,0.000362,0.000100,0.002550,8.225675,0.419036,0.025495,-79.354019,0.002116,0.000000
80.810005,1.840637,-79.398499,0.000349,0.000099,0.002506,8.187563,0.417094,0.025056,-79.398499,0.002064,0.000000
81.110001,1.841385,-79.398499,0.000349,0.000097,0.002462,8.190889,0.417264,0.024625,-79.398499,0.002020,0.000000
81.410004,1.839897,-79.442978,0.000358,0.000095,0.002402,8.184271,0.416927,0.024019,-79.442978,0.001968,0.000000
81.710007,1.808990,-79.398499,0.000345,0.000094,0.002384,8.046791,0.409923,0.023845,-79.398499,0.001916,0.000000
82.010002,1.814949,-79.442978,0.000354,0.000094,0.002384,8.073297,0.411273,0.023845,-79.442978,0.001864,0.000000
82.310005,1.800423,-79.398499,0.000358,0.000091,0.002307,8.008680,0.407982,0.023065,-79.398499,0.001812,0.000000
82.610001,1.812340,-79.442978,0.000349,0.000089,0.002272,8.061690,0.410682,0.022717,-79.442978,0.001769,0.000000
82.910004,1.802284,-79.487457,0.000375,0.000087,0.002211,8.016961,0.408403,0.022111,-79.487457,0.001717,0.000000
83.210007,1.802284,-79.442978,0.000371,0.000085,0.002151,8.016961,0.408403,0.021506,-79.442978,0.001665,0.000000
83.510002,1.800797,-79.442978,0.000362,0.000084,0.002133,8.010343,0.408066,0.021332,-79.442978,0.001612,0.000000
83.810005,1.802284,-79.487457,0.000366,0.000084,0.002133,8.016961,0.408403,0.021332,-79.487457,0.001569,0.000000
84.110001,1.817924,-79.398499,0.000354,0.000084,0.002133,8.086532,0.411948,0.021332,-79.398499,0.001517,0.000000
84.410004,1.798935,-79.531944,0.000366,0.000079,0.002011,8.002062,0.407644,0.020113,-79.531944,0.001466,0.000000
84.710007,1.795952,-79.531944,0.000354,0.000077,0.001951,7.988793,0.406969,0.019507,-79.531944,0.001413,0.000000
85.010002,1.806755,-79.487457,0.000366,0.000077,0.001951,8.036848,0.409417,0.019507,-79.487457,0.001370,0.000000
85.310005,1.806381,-79.531944,0.000366,0.000074,0.001890,8.035185,0.409332,0.018902,-79.531944,0.001318,0.000000
85.610001,1.789253,-79.531944,0.000366,0.000070,0.001777,7.958996,0.405451,0.017774,-79.531944,0.001266,0.000000
85.910004,1.796700,-79.531944,0.000349,0.000069,0.001743,7.992119,0.407138,0.017426,-79.531944,0.001213,0.000000
86.210007,1.785904,-79.531944,0.000366,0.000068,0.001734,7.944098,0.404692,0.017342,-79.531944,0.001170,0.000000
86.510002,1.808990,-79.531944,0.000354,0.000067,0.001699,8.046791,0.409923,0.016994,-79.531944,0.001118,0.000000
86.810005,1.806007,-79.576424,0.000362,0.000065,0.001656,8.033522,0.409247,0.016563,-79.576424,0.001067,0.000000
87.110001,1.804520,-79.576424,0.000362,0.000064,0.001630,8.026904,0.408910,0.016298,-79.576424,0.001014,0.000000
87.410004,1.790741,-79.531944,0.000362,0.000061,0.001561,7.965614,0.405788,0.015609,-79.531944,0.000962,0.000000
87.710007,1.793724,-79.620903,0.000354,0.000061,0.001543,7.978883,0.406464,0.015435,-79.620903,0.000919,0.000000
88.010002,1.739357,-79.576424,0.000371,0.000056,0.001413,7.737046,0.394144,0.014133,-79.576424,0.000867,0.000000
88.310005,1.751274,-79.620903,0.000366,0.000055,0.001388,7.790056,0.396844,0.013875,-79.620903,0.000815,0.000000
88.610001,1.743454,-79.620903,0.000358,0.000053,0.001335,7.755270,0.395072,0.013353,-79.620903,0.000763,0.000000
88.910004,1.715523,-79.620903,0.000366,0.000049,0.001248,7.631026,0.388743,0.012483,-79.620903,0.000719,0.000000
89.210007,1.712914,-79.709862,0.000358,0.000048,0.001223,7.619420,0.388152,0.012225,-79.709862,0.000668,0.000000
89.510002,1.736374,-79.665382,0.000354,0.000048,0.001223,7.723777,0.393468,0.012225,-79.665382,0.000615,0.000000
89.810005,1.704353,-79.665382,0.000354,0.000045,0.001145,7.581342,0.386212,0.011446,-79.665382,0.000563,0.000000
90.110001,1.723717,-79.665382,0.000358,0.000044,0.001118,7.667475,0.390600,0.011181,-79.665382,0.000520,0.000000
90.410004,1.723343,-79.665382,0.000371,0.000043,0.001101,7.665812,0.390515,0.011014,-79.665382,0.000468,0.000000
90.710007,1.630623,-79.665382,0.000349,0.000035,0.000893,7.253373,0.369504,0.008932,-79.665382,0.000416,0.000000
91.010002,1.638443,-79.665382,0.000354,0.000032,0.000824,7.288158,0.371276,0.008236,-79.665382,0.000364,0.000000
91.310005,1.612373,-79.665382,0.000349,0.000031,0.000789,7.172195,0.365369,0.007888,-79.665382,0.000320,0.000000
91.610001,1.598228,-79.709862,0.000354,0.000030,0.000754,7.109275,0.362164,0.007540,-79.709862,0.000269,0.000000
91.910004,1.572906,-79.709862,0.000341,0.000028,0.000702,6.996637,0.356426,0.007025,-79.709862,0.000216,0.000000
92.210007,1.565086,-79.709862,0.000358,0.000026,0.000668,6.961852,0.354654,0.006677,-79.709862,0.000164,0.000000
92.510002,1.534554,-79.665382,0.000345,0.000025,0.000624,6.826035,0.347735,0.006238,-79.665382,0.000112,0.000000
92.810005,1.518913,-79.754349,0.000362,0.000023,0.000581,6.756464,0.344191,0.005806,-79.754349,0.000069,0.000000
93.110001,1.490982,-79.754349,0.000379,0.000019,0.000494,6.632219,0.337861,0.004943,-79.754349,0.000017,0.000000
93.410004,1.482048,-79.754349,0.000358,0.000017,0.000425,6.592479,0.335837,0.004247,-79.754349,-0.000035,0.000000
93.710007,1.473480,-79.754349,0.000358,0.000015,0.000382,6.554368,0.333895,0.003815,-79.754349,-0.000087,0.000000
94.010002,1.486511,-79.754349,0.000358,0.000014,0.000364,6.612332,0.336848,0.003641,-79.754349,-0.000130,0.000000
94.310005,1.466034,-79.754349,0.000362,0.000013,0.000338,6.521245,0.332208,0.003376,-79.754349,-0.000182,0.000000
94.610008,1.454491,-79.798828,0.000371,0.000011,0.000286,6.469898,0.329592,0.002861,-79.798828,-0.000235,0.000000
94.910004,1.425819,-79.754349,0.000366,0.000009,0.000225,6.342361,0.323095,0.002248,-79.754349,-0.000287,0.000000
95.210007,1.387466,-79.798828,0.000371,0.000008,0.000199,6.171759,0.314404,0.001991,-79.798828,-0.000330,0.000000
95.510002,1.378151,-79.843307,0.000371,0.000006,0.000156,6.130322,0.312293,0.001559,-79.843307,-0.000382,0.000000
95.810005,1.382622,-79.843307,0.000358,0.000005,0.000129,6.150209,0.313307,0.001294,-79.843307,-0.000434,0.000000
96.110008,1.374054,-79.798828,0.000366,0.000004,0.000095,6.112097,0.311365,0.000954,-79.798828,-0.000486,0.000000
96.410004,1.373688,-79.798828,0.000362,0.000002,0.000061,6.110468,0.311282,0.000606,-79.798828,-0.000529,0.000000
96.710007,1.368103,-79.887787,0.000371,0.000001,0.000034,6.085626,0.310017,0.000341,-79.887787,-0.000581,0.000000
97.010002,1.336823,-79.843307,0.000362,-0.000001,-0.000035,5.946484,0.302928,-0.000348,-79.843307,-0.000634,0.000000
97.310005,1.306282,-79.887787,0.000366,-0.000003,-0.000079,5.810633,0.296008,-0.000787,-79.887787,-0.000685,0.000000
97.610008,1.305542,-79.843307,0.000358,-0.000004,-0.000104,5.807341,0.295840,-0.001045,-79.843307,-0.000737,0.000000
97.910004,1.299957,-79.843307,0.000366,-0.000005,-0.000130,5.782499,0.294575,-0.001302,-79.843307,-0.000781,0.000000
98.210007,1.303680,-79.887787,0.000366,-0.000006,-0.000148,5.799060,0.295418,-0.001476,-79.887787,-0.000833,0.000000
98.510002,1.299957,-79.887787,0.000358,-0.000009,-0.000217,5.782499,0.294575,-0.002173,-79.887787,-0.000885,0.000000
98.810005,1.268303,-79.932266,0.000366,-0.000010,-0.000260,5.641693,0.287402,-0.002604,-79.932266,-0.000937,0.000000
99.110008,1.244102,-79.932266,0.000362,-0.000013,-0.000330,5.534044,0.281918,-0.003300,-79.932266,-0.000980,0.000000
99.410004,1.219894,-79.976753,0.000366,-0.000014,-0.000365,5.426362,0.276432,-0.003649,-79.976753,-0.001033,0.000000
99.710007,1.211700,-79.976753,0.000375,-0.000015,-0.000391,5.389913,0.274575,-0.003906,-79.976753,-0.001084,0.000000
100.010002,1.177444,-79.976753,0.000362,-0.000016,-0.000408,5.237535,0.266813,-0.004080,-79.976753,-0.001136,0.000000
100.310005,1.182289,-79.976753,0.000349,-0.000016,-0.000416,5.259085,0.267911,-0.004163,-79.976753,-0.001180,0.000000
100.610008,1.167389,-79.932266,0.000349,-0.000019,-0.000478,5.192805,0.264534,-0.004777,-79.932266,-0.001232,0.000000
100.910004,1.165154,-79.976753,0.000354,-0.000019,-0.000478,5.182862,0.264028,-0.004777,-79.976753,-0.001284,0.000000
101.210007,1.165154,-80.021233,0.000349,-0.000019,-0.000478,5.182862,0.264028,-0.004777,-80.021233,-0.001336,0.000000
101.510002,1.018814,-79.976753,0.000319,-0.000030,-0.000755,4.531911,0.230867,-0.007547,-79.976753,-0.001388,0.000000
101.810005,1.020302,-79.976753,0.000362,-0.000033,-0.000833,4.538529,0.231204,-0.008327,-79.976753,-0.001431,0.000000
102.110008,0.993492,-79.976753,0.000362,-0.000036,-0.000902,4.419274,0.225129,-0.009023,-79.976753,-0.001483,0.000000
102.410004,0.992004,-79.976753,0.000371,-0.000036,-0.000902,4.412656,0.224791,-0.009023,-79.976753,-0.001535,0.000000
102.710007,0.982697,-79.976753,0.000362,-0.000036,-0.000920,4.371253,0.222682,-0.009197,-79.976753,-0.001587,0.000000
103.010002,0.945457,-80.110191,0.000349,-0.000039,-0.000998,4.205605,0.214244,-0.009977,-80.110191,-0.001631,0.000000
103.310005,0.942474,-80.065712,0.000358,-0.000041,-0.001033,4.192335,0.213568,-0.010325,-80.065712,-0.001683,0.000000
103.610008,0.936516,-80.065712,0.000345,-0.000041,-0.001050,4.165830,0.212218,-0.010499,-80.065712,-0.001735,0.000000
103.910004,0.920509,-80.021233,0.000358,-0.000041,-0.001050,4.094630,0.208590,-0.010499,-80.021233,-0.001786,0.000000
104.210007,0.916039,-80.065712,0.000328,-0.000042,-0.001076,4.074743,0.207577,-0.010757,-80.065712,-0.001830,0.000000
104.510002,0.923111,-80.021233,0.000362,-0.000042,-0.001076,4.106203,0.209180,-0.010757,-80.021233,-0.001882,0.000000
104.810005,0.877312,-80.065712,0.000336,-0.000047,-0.001206,3.902477,0.198802,-0.012059,-80.065712,-0.001934,0.000000
105.110008,0.863907,-80.110191,0.000362,-0.000050,-0.001276,3.842850,0.195764,-0.012755,-80.110191,-0.001986,0.000000
105.410004,0.819221,-80.110191,0.000354,-0.000051,-0.001292,3.644079,0.185638,-0.012922,-80.110191,-0.002029,0.000000
105.710007,0.806931,-80.065712,0.000349,-0.000054,-0.001362,3.589406,0.182853,-0.013618,-80.065712,-0.002082,0.000000
106.010002,0.816246,-80.110191,0.000349,-0.000054,-0.001362,3.630844,0.184964,-0.013618,-80.110191,-0.002134,0.000000
106.310005,0.791298,-80.154671,0.000349,-0.000056,-0.001431,3.519869,0.179311,-0.014314,-80.154671,-0.002185,0.000000
106.610008,0.770065,-80.065712,0.000354,-0.000058,-0.001466,3.425421,0.174499,-0.014663,-80.065712,-0.002238,0.000000
106.910004,0.761505,-80.154671,0.000354,-0.000059,-0.001492,3.387344,0.172560,-0.014920,-80.154671,-0.002281,0.000000
107.210007,0.755547,-80.154671,0.000349,-0.000062,-0.001579,3.360839,0.171209,-0.015791,-80.154671,-0.002333,0.000000
107.510002,0.678841,-80.154671,0.000366,-0.000066,-0.001665,3.019634,0.153827,-0.016654,-80.154671,-0.002385,0.000000
107.810005,0.678841,-80.154671,0.000341,-0.000068,-0.001718,3.019634,0.153827,-0.017176,-80.154671,-0.002437,0.000000
108.110008,0.672882,-80.154671,0.000336,-0.000070,-0.001770,2.993129,0.152477,-0.017698,-80.154671,-0.002481,0.000000
108.410004,0.657242,-80.199158,0.000345,-0.000072,-0.001839,2.923558,0.148933,-0.018387,-80.199158,-0.002533,0.000000
108.710007,0.630798,-80.199158,0.000345,-0.000074,-0.001882,2.805931,0.142941,-0.018818,-80.199158,-0.002584,0.000000
109.010002,0.619255,-80.199158,0.000332,-0.000075,-0.001899,2.754584,0.140325,-0.018993,-80.199158,-0.002637,0.000000
109.310005,0.610695,-80.199158,0.000336,-0.000078,-0.001977,2.716506,0.138385,-0.019772,-80.199158,-0.002680,0.000000
109.610008,0.580162,-80.199158,0.000341,-0.000081,-0.002047,2.580690,0.131467,-0.020469,-80.199158,-0.002732,0.000000
109.910004,0.568619,-80.243637,0.000332,-0.000082,-0.002090,2.529343,0.128851,-0.020900,-80.243637,-0.002784,0.000000
110.210007,0.560051,-80.199158,0.000345,-0.000083,-0.002117,2.491231,0.126909,-0.021165,-80.199158,-0.002836,0.000000
110.510002,0.541061,-80.243637,0.000336,-0.000087,-0.002212,2.406761,0.122606,-0.022119,-80.243637,-0.002880,0.000000
110.810005,0.508667,-80.243637,0.000315,-0.000088,-0.002247,2.262664,0.115266,-0.022467,-80.243637,-0.002932,0.000000
111.110008,0.513878,-80.243637,0.000345,-0.000090,-0.002290,2.285843,0.116446,-0.022899,-80.243637,-0.002983,0.000000
111.410004,0.491905,-80.243637,0.000341,-0.000092,-0.002325,2.188104,0.111467,-0.023247,-80.243637,-0.003035,0.000000
111.710007,0.472916,-80.199158,0.000328,-0.000094,-0.002376,2.103634,0.107164,-0.023762,-80.199158,-0.003088,0.000000
112.010002,0.457275,-80.243637,0.000336,-0.000094,-0.002376,2.034063,0.103620,-0.023762,-80.243637,-0.003131,0.000000
112.310005,0.468079,-80.288116,0.000332,-0.000094,-0.002385,2.082118,0.106068,-0.023852,-80.288116,-0.003183,0.000000
112.610008,0.454300,-80.288116,0.000345,-0.000096,-0.002446,2.020827,0.102946,-0.024458,-80.288116,-0.003235,0.000000
112.910004,0.409988,-80.288116,0.000315,-0.000100,-0.002550,1.823720,0.092905,-0.025503,-80.288116,-0.003287,0.000000
113.210007,0.389130,-80.288116,0.000328,-0.000102,-0.002602,1.730935,0.088178,-0.026017,-80.288116,-0.003331,0.000000
113.510002,0.370888,-80.288116,0.000341,-0.000104,-0.002646,1.649791,0.084044,-0.026456,-80.288116,-0.003382,0.000000
113.810005,0.366791,-80.332596,0.000302,-0.000105,-0.002663,1.631567,0.083116,-0.026631,-80.332596,-0.003434,0.000000
114.110008,0.362694,-80.332596,0.000328,-0.000106,-0.002697,1.613343,0.082188,-0.026971,-80.332596,-0.003487,0.000000
114.410004,0.342216,-80.332596,0.000319,-0.000109,-0.002767,1.522255,0.077547,-0.027668,-80.332596,-0.003530,0.000000
114.710007,0.306091,-80.332596,0.000315,-0.000112,-0.002836,1.361562,0.069361,-0.028364,-80.332596,-0.003582,0.000000
115.010002,0.304977,-80.332596,0.000319,-0.000113,-0.002862,1.356607,0.069109,-0.028621,-80.332596,-0.003634,0.000000
115.310005,0.291573,-80.377075,0.000315,-0.000115,-0.002932,1.296980,0.066071,-0.029318,-80.377075,-0.003686,0.000000
115.610008,0.278908,-80.332596,0.000302,-0.000117,-0.002975,1.240644,0.063201,-0.029749,-80.332596,-0.003730,0.000000
115.910004,0.255447,-80.377075,0.000315,-0.000119,-0.003018,1.136287,0.057885,-0.030181,-80.377075,-0.003781,0.000000
116.210007,0.258057,-80.332596,0.000310,-0.000120,-0.003053,1.147893,0.058476,-0.030529,-80.332596,-0.003833,0.000000
116.510002,0.252472,-80.377075,0.000302,-0.000123,-0.003113,1.123051,0.057211,-0.031135,-80.377075,-0.003886,0.000000
116.810005,0.252846,-80.421562,0.000297,-0.000124,-0.003140,1.124714,0.057296,-0.031399,-80.421562,-0.003938,0.000000
117.110008,0.229759,-80.377075,0.000302,-0.000126,-0.003191,1.022020,0.052064,-0.031914,-80.377075,-0.003981,0.000000
117.410004,0.238693,-80.377075,0.000310,-0.000126,-0.003209,1.061761,0.054089,-0.032088,-80.377075,-0.004033,0.000000
117.710007,0.228638,-80.421562,0.000293,-0.000129,-0.003270,1.017031,0.051810,-0.032701,-80.421562,-0.004085,0.000000
118.010002,0.218956,-80.421562,0.000323,-0.000130,-0.003304,0.973965,0.049616,-0.033042,-80.421562,-0.004137,0.000000
118.310005,0.224541,-80.466042,0.000285,-0.000130,-0.003313,0.998807,0.050882,-0.033133,-80.466042,-0.004180,0.000000
118.610008,0.223801,-80.466042,0.000310,-0.000134,-0.003391,0.995515,0.050714,-0.033913,-80.466042,-0.004232,0.000000
118.910004,0.229385,-80.421562,0.000285,-0.000135,-0.003434,1.020357,0.051979,-0.034344,-80.421562,-0.004285,0.000000
119.210007,0.226036,-80.377075,0.000285,-0.000136,-0.003452,1.005459,0.051221,-0.034518,-80.377075,-0.004337,0.000000
119.510002,0.222313,-80.510521,0.000293,-0.000137,-0.003487,0.988897,0.050377,-0.034866,-80.510521,-0.004380,0.000000
119.810005,0.195496,-80.466042,0.000302,-0.000139,-0.003521,0.869608,0.044300,-0.035215,-80.466042,-0.004432,0.000000
120.110008,0.196991,-80.377075,0.000306,-0.000141,-0.003582,0.876260,0.044639,-0.035820,-80.377075,-0.004484,0.000000
120.410004,0.214859,-80.466042,0.000289,-0.000142,-0.003608,0.955741,0.048688,-0.036078,-80.466042,-0.004536,0.000000
120.710007,0.189911,-80.466042,0.000289,-0.000143,-0.003634,0.844766,0.043034,-0.036343,-80.466042,-0.004579,0.000000
121.010002,0.123627,-80.510521,0.000297,-0.000151,-0.003842,0.549919,0.028014,-0.038424,-80.510521,-0.004631,0.000000
121.310005,0.117302,-80.510521,0.000285,-0.000154,-0.003911,0.521785,0.026581,-0.039113,-80.510521,-0.004683,0.000000
121.610008,0.128471,-80.421562,0.000285,-0.000155,-0.003929,0.571469,0.029112,-0.039287,-80.421562,-0.004736,0.000000
121.910004,0.137039,-80.466042,0.000280,-0.000155,-0.003929,0.609581,0.031054,-0.039287,-80.466042,-0.004787,0.000000
122.210007,0.150444,-80.555000,0.000276,-0.000155,-0.003929,0.669208,0.034091,-0.039287,-80.555000,-0.004831,0.000000
122.510002,0.143364,-80.466042,0.000272,-0.000155,-0.003929,0.637715,0.032487,-0.039287,-80.466042,-0.004883,0.000000
122.810005,0.137779,-80.555000,0.000285,-0.000155,-0.003929,0.612873,0.031221,-0.039287,-80.555000,-0.004935,0.000000
123.110008,0.116928,-80.510521,0.000272,-0.000163,-0.004129,0.520122,0.026496,-0.041286,-80.510521,-0.004987,0.000000
123.410004,0.125496,-80.555000,0.000259,-0.000163,-0.004129,0.558234,0.028438,-0.041286,-80.555000,-0.005030,0.000000
123.710007,0.119164,-80.555000,0.000267,-0.000163,-0.004129,0.530066,0.027003,-0.041286,-80.555000,-0.005082,0.000000
124.010002,0.116554,-80.510521,0.000237,-0.000163,-0.004129,0.518459,0.026412,-0.041286,-80.510521,-0.005135,0.000000
124.310005,0.115814,-80.510521,0.000246,-0.000164,-0.004172,0.515167,0.026244,-0.041717,-80.510521,-0.005186,0.000000
124.610008,0.052132,-80.555000,0.000259,-0.000174,-0.004432,0.231893,0.011813,-0.044321,-80.555000,-0.005230,0.000000
124.910004,0.070007,-80.555000,0.000254,-0.000175,-0.004440,0.311408,0.015864,-0.044404,-80.555000,-0.005281,0.000000
125.210007,0.056602,-80.555000,0.000237,-0.000177,-0.004484,0.251780,0.012826,-0.044836,-80.555000,-0.005334,0.000000
125.510010,0.064796,-80.599480,0.000237,-0.000177,-0.004493,0.288229,0.014683,-0.044927,-80.599480,-0.005386,0.000000
125.810005,0.069267,-80.555000,0.000254,-0.000177,-0.004493,0.308116,0.015696,-0.044927,-80.555000,-0.005438,0.000000
126.110008,0.061447,-80.599480,0.000259,-0.000177,-0.004493,0.273331,0.013924,-0.044927,-80.599480,-0.005481,0.000000
126.410004,0.059586,-80.643967,0.000250,-0.000179,-0.004553,0.265050,0.013502,-0.045532,-80.643967,-0.005534,0.000000
126.710007,0.060326,-80.643967,0.000241,-0.000182,-0.004614,0.268342,0.013670,-0.046138,-80.643967,-0.005585,0.000000
127.010010,0.049904,-80.599480,0.000241,-0.000182,-0.004614,0.221983,0.011308,-0.046138,-80.599480,-0.005637,0.000000
127.310005,0.039101,-80.643967,0.000250,-0.000182,-0.004614,0.173928,0.008860,-0.046138,-80.643967,-0.005680,0.000000
127.610008,0.063309,-80.643967,0.000246,-0.000182,-0.004614,0.281611,0.014346,-0.046138,-80.643967,-0.005733,0.000000
127.910004,0.029045,-80.643967,0.000233,-0.000193,-0.004900,0.129199,0.006582,-0.048999,-80.643967,-0.005785,0.000000
128.210007,0.013405,-80.599480,0.000237,-0.000194,-0.004917,0.059628,0.003038,-0.049173,-80.599480,-0.005837,0.000000
128.500000,0.013405,-80.688446,0.000211,-0.000192,-0.004874,0.059628,0.003038,-0.048742,-80.688446,-0.004944,0.000000