File: Data/PDMS 0040002 test 1_10242023_175339.csv
Time (sec),S:Load (lbs),S:HL1 (DIM),S:LVDT (in),S:Position (in),Ch:Position (mm),Ch:Load (N),Ch:Stress (MPa),Ch:Strain (mm/mm),Ch:HL1 (DIM),Set Point (),Cycles ()
0.110000,-0.061073,-30.602894,0.000047,-0.000000,-0.000000,-0.271668,-0.013839,-0.000000,-30.602894,0.000182,0.000000
0.320000,-0.044685,-30.558413,0.000043,-0.000000,-0.000000,-0.198770,-0.010126,-0.000000,-30.558413,0.000182,0.000000
0.530000,-0.054367,-30.558413,0.000052,0.000060,0.001527,-0.241837,-0.012320,0.015268,-30.558413,0.002246,0.000000
0.740000,-0.051758,-30.513933,0.000060,0.000181,0.004588,-0.230230,-0.011728,0.045880,-30.513933,0.005750,0.000000
0.950000,-0.038727,-30.558413,0.000211,0.000318,0.008083,-0.172265,-0.008776,0.080830,-30.558413,0.009253,0.000000
1.160000,-0.067398,-30.647375,0.000328,0.000452,0.011483,-0.299802,-0.015273,0.114826,-30.647375,0.012740,0.000000
1.370000,-0.042450,-30.558413,0.000492,0.000588,0.014934,-0.188827,-0.009619,0.149337,-30.558413,0.016243,0.000000
1.580000,-0.070007,-30.602894,0.000638,0.000726,0.018446,-0.311408,-0.015864,0.184461,-30.602894,0.019747,0.000000
1.790000,-0.078201,-30.558413,0.000806,0.000867,0.022011,-0.347857,-0.017721,0.220107,-30.558413,0.023233,0.000000
2.000000,-0.075592,-30.513933,0.000944,0.001003,0.025479,-0.336250,-0.017129,0.254792,-30.513933,0.026736,0.000000
2.210000,-0.052132,-30.647375,0.001087,0.001135,0.028836,-0.231893,-0.011813,0.288356,-30.647375,0.030241,0.000000
2.420000,-0.057716,-30.602894,0.001233,0.001280,0.032504,-0.256735,-0.013079,0.325039,-30.602894,0.033744,0.000000
2.630000,-0.075966,-30.691856,0.001380,0.001424,0.036172,-0.337913,-0.017214,0.361722,-30.691856,0.037230,0.000000
2.840000,-0.059212,-30.602894,0.001509,0.001559,0.039589,-0.263387,-0.013418,0.395892,-30.602894,0.040734,0.000000
3.050000,-0.045059,-30.602894,0.001681,0.001694,0.043032,-0.200433,-0.010211,0.430320,-30.602894,0.044237,0.000000
3.260000,-0.074478,-30.647375,0.001802,0.001829,0.046457,-0.331295,-0.016877,0.464573,-30.647375,0.047724,0.000000
3.470000,-0.058090,-30.602894,0.001962,0.001967,0.049961,-0.258398,-0.013163,0.499614,-30.602894,0.051227,0.000000
3.680000,-0.049530,-30.691856,0.002104,0.002107,0.053517,-0.220321,-0.011224,0.535169,-30.691856,0.054731,0.000000
3.890000,-0.048782,-30.602894,0.002225,0.002248,0.057098,-0.216995,-0.011054,0.570982,-30.602894,0.058217,0.000000
4.100000,-0.059212,-30.602894,0.002406,0.002380,0.060446,-0.263387,-0.013418,0.604455,-30.602894,0.061721,0.000000
4.310000,-0.037987,-30.647375,0.002552,0.002522,0.064062,-0.168974,-0.008608,0.640624,-30.647375,0.065224,0.000000
4.520000,-0.043198,-30.602894,0.002682,0.002658,0.067513,-0.192153,-0.009789,0.675134,-30.602894,0.068728,0.000000
4.730000,-0.030907,-30.647375,0.002828,0.002798,0.071061,-0.137480,-0.007004,0.710606,-30.647375,0.072214,0.000000
4.940000,-0.055115,-30.558413,0.002997,0.002937,0.074590,-0.245163,-0.012489,0.745904,-30.558413,0.075718,0.000000
5.150000,-0.054367,-30.691856,0.003134,0.003076,0.078120,-0.241837,-0.012320,0.781202,-30.691856,0.079222,0.000000
5.360000,-0.058838,-30.647375,0.003260,0.003210,0.081528,-0.261724,-0.013333,0.815282,-30.647375,0.082708,0.000000
5.570000,-0.068146,-30.647375,0.003423,0.003342,0.084893,-0.303127,-0.015442,0.848929,-30.647375,0.086211,0.000000
5.780000,-0.059952,-30.736338,0.003579,0.003484,0.088483,-0.266679,-0.013585,0.884833,-30.736338,0.089715,0.000000
5.990000,-0.054741,-30.647375,0.003691,0.003626,0.092091,-0.243500,-0.012404,0.920910,-30.647375,0.093218,0.000000
6.200000,-0.046173,-30.691856,0.003850,0.003757,0.095430,-0.205388,-0.010463,0.954301,-30.691856,0.096705,0.000000
6.410000,-0.024208,-30.691856,0.003997,0.003898,0.099003,-0.107683,-0.005486,0.990030,-30.691856,0.100208,0.000000
6.620000,-0.041710,-30.691856,0.004130,0.004034,0.102471,-0.185535,-0.009452,1.024715,-30.691856,0.103711,0.000000
6.830000,-0.030167,-30.691856,0.004277,0.004172,0.105966,-0.134188,-0.006836,1.059665,-30.691856,0.107198,0.000000
7.040000,-0.014526,-30.691856,0.004432,0.004315,0.109609,-0.064617,-0.003292,1.096090,-30.691856,0.110701,0.000000
7.250000,-0.027184,-30.691856,0.004583,0.004450,0.113034,-0.120918,-0.006160,1.130344,-30.691856,0.114205,0.000000
7.460001,-0.064049,-30.691856,0.004730,0.004589,0.116555,-0.284903,-0.014514,1.165551,-30.691856,0.117709,0.000000
7.670001,-0.059578,-30.780819,0.004872,0.004727,0.120067,-0.265016,-0.013501,1.200675,-30.780819,0.121195,0.000000
7.880001,-0.071869,-30.736338,0.005049,0.004863,0.123510,-0.319689,-0.016286,1.235102,-30.736338,0.124699,0.000000
8.090000,-0.069260,-30.691856,0.005182,0.004999,0.126979,-0.308082,-0.015694,1.269794,-30.691856,0.128202,0.000000
8.300000,-0.045059,-30.691856,0.005303,0.005137,0.130474,-0.200433,-0.010211,1.304744,-30.691856,0.131689,0.000000
8.510000,-0.043938,-30.780819,0.005463,0.005275,0.133978,-0.195445,-0.009956,1.339777,-30.780819,0.135192,0.000000
8.720000,-0.045059,-30.780819,0.005614,0.005411,0.137430,-0.200433,-0.010211,1.374295,-30.780819,0.138696,0.000000
8.930000,-0.008568,-30.780819,0.005739,0.005549,0.140933,-0.038112,-0.001941,1.409328,-30.780819,0.142199,0.000000
9.140000,-0.024208,-30.736338,0.005907,0.005691,0.144541,-0.107683,-0.005486,1.445406,-30.736338,0.145685,0.000000
9.350000,-0.022346,-30.780819,0.006053,0.005827,0.148010,-0.099402,-0.005064,1.480098,-30.780819,0.149189,0.000000
9.560000,-0.037239,-30.780819,0.006178,0.005967,0.151565,-0.165648,-0.008438,1.515654,-30.780819,0.152692,0.000000
9.770000,-0.038353,-30.780819,0.006342,0.006105,0.155078,-0.170603,-0.008691,1.550777,-30.780819,0.156179,0.000000
9.980000,-0.069260,-30.825298,0.006493,0.006245,0.158624,-0.308082,-0.015694,1.586242,-30.825298,0.159682,0.000000
10.190001,-0.077080,-30.736338,0.006622,0.006379,0.162033,-0.342868,-0.017467,1.620329,-30.736338,0.163186,0.000000
10.400001,-0.087135,-30.869780,0.006782,0.006520,0.165606,-0.387597,-0.019745,1.656058,-30.869780,0.166672,0.000000
10.610001,-0.071495,-30.736338,0.006937,0.006653,0.168979,-0.318026,-0.016201,1.689789,-30.736338,0.170176,0.000000
10.820001,-0.034256,-30.780819,0.007045,0.006791,0.172500,-0.152378,-0.007763,1.725004,-30.780819,0.173680,0.000000
11.030001,-0.024948,-30.825298,0.007252,0.006929,0.175995,-0.110975,-0.005653,1.759953,-30.825298,0.177183,0.000000
11.240001,-0.019363,-30.780819,0.007360,0.007067,0.179499,-0.086133,-0.004388,1.794986,-30.780819,0.180670,0.000000
11.450001,-0.023087,-30.780819,0.007519,0.007203,0.182959,-0.102694,-0.005231,1.829588,-30.780819,0.184173,0.000000
11.660001,-0.029793,-30.825298,0.007653,0.007344,0.186541,-0.132525,-0.006751,1.865408,-30.825298,0.187676,0.000000
11.870001,-0.045807,-30.869780,0.007787,0.007480,0.189984,-0.203759,-0.010380,1.899836,-30.869780,0.191163,0.000000
12.080001,-0.021973,-30.825298,0.007942,0.007621,0.193574,-0.097739,-0.004979,1.935739,-30.825298,0.194666,0.000000
12.290001,-0.037239,-30.825298,0.008080,0.007757,0.197034,-0.165648,-0.008438,1.970341,-30.825298,0.198170,0.000000
12.500001,-0.066284,-30.825298,0.008231,0.007897,0.200590,-0.294847,-0.015020,2.005896,-30.825298,0.201674,0.000000
12.710001,-0.067032,-30.825298,0.008386,0.008033,0.204041,-0.298173,-0.015190,2.040414,-30.825298,0.205159,0.000000
12.920001,-0.047668,-30.825298,0.008515,0.008169,0.207502,-0.212040,-0.010802,2.075016,-30.825298,0.208664,0.000000
13.130001,-0.037987,-30.825298,0.008675,0.008307,0.211005,-0.168974,-0.008608,2.110049,-30.825298,0.212167,0.000000
13.340001,-0.026443,-30.780819,0.008804,0.008447,0.214560,-0.117626,-0.005992,2.145604,-30.780819,0.215653,0.000000
13.550000,-0.019363,-30.869780,0.008951,0.008582,0.217995,-0.086133,-0.004388,2.179948,-30.869780,0.219157,0.000000
13.760000,-0.018623,-30.869780,0.009123,0.008722,0.221550,-0.082841,-0.004220,2.215503,-30.869780,0.222660,0.000000
13.970000,-0.022346,-30.869780,0.009261,0.008854,0.224898,-0.099402,-0.005064,2.248977,-30.869780,0.226164,0.000000
14.180000,-0.020485,-30.869780,0.009386,0.008995,0.228471,-0.091121,-0.004642,2.284706,-30.869780,0.229650,0.000000
14.390000,-0.042450,-30.825298,0.009546,0.009129,0.231888,-0.188827,-0.009619,2.318877,-30.825298,0.233154,0.000000
14.600000,-0.040588,-30.869780,0.009684,0.009273,0.235530,-0.180546,-0.009197,2.355302,-30.869780,0.236657,0.000000
14.810000,-0.039101,-30.869780,0.009813,0.009411,0.239051,-0.173928,-0.008860,2.390509,-30.869780,0.240144,0.000000
15.020000,-0.039848,-30.869780,0.009955,0.009544,0.242425,-0.177254,-0.009030,2.424248,-30.869780,0.243647,0.000000
15.230000,-0.041710,-30.914261,0.010119,0.009686,0.246023,-0.185535,-0.009452,2.460235,-30.914261,0.247151,0.000000
15.440001,-0.054741,-30.869780,0.010266,0.009826,0.249579,-0.243500,-0.012404,2.495790,-30.869780,0.250655,0.000000
15.650001,-0.027557,-30.914261,0.010417,0.009962,0.253031,-0.122581,-0.006245,2.530308,-30.914261,0.254141,0.000000
15.860001,-0.018623,-30.825298,0.010550,0.010100,0.256543,-0.082841,-0.004220,2.565432,-30.825298,0.257645,0.000000
16.070002,-0.042450,-30.958742,0.010675,0.010233,0.259916,-0.188827,-0.009619,2.599163,-30.958742,0.261148,0.000000
16.280001,-0.025322,-30.869780,0.010822,0.010371,0.263429,-0.112638,-0.005738,2.634287,-30.869780,0.264634,0.000000
16.490002,-0.013405,-30.914261,0.010968,0.010509,0.266932,-0.059628,-0.003038,2.669320,-30.914261,0.268138,0.000000
16.700001,-0.038727,-30.869780,0.011141,0.010647,0.270444,-0.172265,-0.008776,2.704444,-30.869780,0.271641,0.000000
16.910002,-0.031654,-30.958742,0.011270,0.010784,0.273905,-0.140806,-0.007173,2.739045,-30.958742,0.275128,0.000000
17.120001,-0.018990,-30.914261,0.011421,0.010921,0.277399,-0.084470,-0.004303,2.773995,-30.914261,0.278631,0.000000
17.330000,-0.016388,-30.958742,0.011555,0.011063,0.281007,-0.072897,-0.003714,2.810073,-30.958742,0.282134,0.000000
17.540001,-0.040588,-30.914261,0.011710,0.011204,0.284580,-0.180546,-0.009197,2.845802,-30.914261,0.285638,0.000000
17.750000,-0.049530,-30.958742,0.011870,0.011342,0.288075,-0.220321,-0.011224,2.880752,-30.958742,0.289124,0.000000
17.960001,-0.029419,-30.958742,0.012003,0.011478,0.291553,-0.130862,-0.006666,2.915527,-30.958742,0.292628,0.000000
18.170000,-0.033516,-31.003223,0.012163,0.011612,0.294952,-0.149086,-0.007595,2.949523,-31.003223,0.296132,0.000000
18.380001,-0.045433,-30.914261,0.012262,0.011749,0.298422,-0.202096,-0.010295,2.984215,-30.914261,0.299618,0.000000
18.590000,-0.023460,-30.958742,0.012434,0.011890,0.302003,-0.104357,-0.005316,3.020028,-30.958742,0.303122,0.000000
18.800001,-0.021599,-31.047705,0.012577,0.012028,0.305524,-0.096076,-0.004894,3.055235,-31.047705,0.306625,0.000000
19.010000,-0.016762,-30.958742,0.012723,0.012160,0.308872,-0.074560,-0.003798,3.088717,-30.958742,0.310129,0.000000
19.220001,-0.009682,-30.958742,0.012874,0.012301,0.312445,-0.043066,-0.002194,3.124446,-30.958742,0.313615,0.000000
19.430000,-0.004097,-31.003223,0.013029,0.012440,0.315974,-0.018224,-0.000928,3.159736,-31.003223,0.317119,0.000000
19.640001,-0.000000,-30.958742,0.013163,0.012578,0.319478,-0.000000,-0.000000,3.194777,-30.958742,0.320622,0.000000
19.850000,-0.002983,-31.003223,0.013301,0.012719,0.323068,-0.013269,-0.000676,3.230680,-31.003223,0.324108,0.000000
20.060001,-0.022713,-31.047705,0.013448,0.012856,0.326554,-0.101031,-0.005147,3.265539,-31.047705,0.327612,0.000000
20.270000,-0.058090,-31.047705,0.013607,0.012994,0.330058,-0.258398,-0.013163,3.300580,-31.047705,0.331115,0.000000
20.480001,-0.020851,-31.047705,0.013719,0.013125,0.333371,-0.092750,-0.004725,3.333705,-31.047705,0.334620,0.000000
20.690001,-0.036125,-31.003223,0.013892,0.013263,0.336891,-0.160693,-0.008186,3.368912,-31.003223,0.338105,0.000000
20.900002,-0.015640,-31.003223,0.014030,0.013405,0.340499,-0.069571,-0.003544,3.404990,-31.003223,0.341609,0.000000
21.110001,-0.013779,-31.003223,0.014172,0.013541,0.343942,-0.061291,-0.003122,3.439417,-31.003223,0.345113,0.000000
21.320002,-0.001862,-31.092184,0.014319,0.013679,0.347437,-0.008281,-0.000422,3.474367,-31.092184,0.348599,0.000000
21.530001,0.016380,-31.003223,0.014457,0.013817,0.350949,0.072863,0.003712,3.509491,-31.003223,0.352103,0.000000
21.740002,0.009682,-31.003223,0.014594,0.013952,0.354374,0.043066,0.002194,3.543744,-31.003223,0.355606,0.000000
21.950001,0.021599,-31.047705,0.014754,0.014094,0.357982,0.096076,0.004894,3.579822,-31.047705,0.359110,0.000000
22.160002,0.015266,-31.047705,0.014892,0.014230,0.361451,0.067908,0.003459,3.614514,-31.047705,0.362596,0.000000
22.370001,0.011169,-31.092184,0.015060,0.014368,0.364946,0.049684,0.002531,3.649464,-31.092184,0.366099,0.000000
22.580002,-0.022713,-31.003223,0.015207,0.014506,0.368450,-0.101031,-0.005147,3.684497,-31.003223,0.369603,0.000000
22.790001,-0.032768,-31.092184,0.015336,0.014644,0.371953,-0.145760,-0.007425,3.719530,-31.092184,0.373089,0.000000
23.000002,-0.035751,-31.092184,0.015496,0.014781,0.375448,-0.159030,-0.008101,3.754480,-31.092184,0.376593,0.000000
23.210001,-0.030533,-31.047705,0.015616,0.014918,0.378908,-0.135817,-0.006919,3.789081,-31.047705,0.380097,0.000000
23.420002,-0.000000,-31.092184,0.015776,0.015055,0.382395,-0.000000,-0.000000,3.823947,-31.092184,0.383582,0.000000
23.630001,0.018616,-31.003223,0.015927,0.015192,0.385881,0.082807,0.004218,3.858806,-31.003223,0.387087,0.000000
23.840002,0.014519,-31.092184,0.016065,0.015330,0.389385,0.064583,0.003290,3.893847,-31.092184,0.390590,0.000000
24.050001,0.036865,-31.092184,0.016224,0.015469,0.392905,0.163985,0.008354,3.929054,-31.092184,0.394094,0.000000
24.260000,0.015640,-31.092184,0.016349,0.015605,0.396357,0.069571,0.003544,3.963572,-31.092184,0.397580,0.000000
24.470001,0.011543,-31.092184,0.016513,0.015746,0.399948,0.051347,0.002616,3.999476,-31.092184,0.401084,0.000000
24.680000,0.003723,-31.092184,0.016664,0.015882,0.403408,0.016561,0.000844,4.034077,-31.092184,0.404587,0.000000
24.890001,0.013031,-31.136665,0.016780,0.016023,0.406981,0.057965,0.002953,4.069807,-31.136665,0.408073,0.000000
25.100000,-0.011917,-31.047705,0.016940,0.016159,0.410441,-0.053010,-0.002700,4.104408,-31.047705,0.411577,0.000000
25.310001,-0.033142,-31.092184,0.017091,0.016298,0.413979,-0.147423,-0.007510,4.139790,-31.092184,0.415080,0.000000
25.520000,-0.016388,-31.225628,0.017225,0.016432,0.417379,-0.072897,-0.003714,4.173785,-31.225628,0.418584,0.000000
25.730001,-0.001488,-31.092184,0.017384,0.016572,0.420926,-0.006618,-0.000337,4.209258,-31.092184,0.422070,0.000000
25.940001,0.010796,-31.136665,0.017535,0.016709,0.424412,0.048021,0.002446,4.244116,-31.136665,0.425574,0.000000
26.150002,0.037239,-31.136665,0.017669,0.016848,0.427941,0.165648,0.008438,4.279414,-31.136665,0.429078,0.000000
26.360001,0.030159,-31.136665,0.017802,0.016982,0.431332,0.134154,0.006834,4.313319,-31.136665,0.432564,0.000000
26.570002,0.043564,-31.136665,0.017962,0.017121,0.434879,0.193782,0.009872,4.348791,-31.136665,0.436068,0.000000
26.780001,0.024200,-31.136665,0.018117,0.017257,0.438322,0.107649,0.005484,4.383219,-31.136665,0.439571,0.000000
26.990002,0.036118,-31.181147,0.018251,0.017398,0.441904,0.160659,0.008184,4.419039,-31.181147,0.443074,0.000000
27.200001,0.030533,-31.225628,0.018380,0.017534,0.445372,0.135817,0.006919,4.453724,-31.225628,0.446561,0.000000
27.410002,0.061813,-31.136665,0.018535,0.017675,0.448945,0.274960,0.014007,4.489453,-31.136665,0.450064,0.000000
27.620001,0.033142,-31.225628,0.018660,0.017815,0.452493,0.147423,0.007510,4.524925,-31.225628,0.453568,0.000000
27.830002,0.072983,-31.181147,0.018833,0.017949,0.455900,0.324644,0.016538,4.559004,-31.181147,0.457054,0.000000
28.040001,0.089737,-31.181147,0.018975,0.018087,0.459413,0.399170,0.020335,4.594128,-31.181147,0.460558,0.000000
28.250002,0.116920,-31.225628,0.019109,0.018226,0.462943,0.520088,0.026495,4.629426,-31.225628,0.464061,0.000000
28.460001,0.156021,-31.225628,0.019264,0.018363,0.466429,0.694017,0.035355,4.664293,-31.225628,0.467565,0.000000
28.670002,0.197357,-31.225628,0.019406,0.018503,0.469985,0.877889,0.044722,4.699848,-31.225628,0.471051,0.000000
28.880001,0.238686,-31.181147,0.019557,0.018635,0.473332,1.061727,0.054087,4.733322,-31.181147,0.474555,0.000000
29.090002,0.322098,-31.225628,0.019682,0.018772,0.476818,1.432763,0.072988,4.768180,-31.225628,0.478059,0.000000
29.300001,0.415939,-31.225628,0.019850,0.018910,0.480322,1.850191,0.094253,4.803221,-31.225628,0.481545,0.000000
29.510002,0.567863,-31.225628,0.019988,0.019050,0.483878,2.525983,0.128680,4.838776,-31.225628,0.485048,0.000000
29.720001,0.630798,-31.270109,0.020053,-0.000011,-0.000278,2.805931,0.142941,-0.002778,-31.270109,-0.000017,0.000000
29.930002,0.587601,-31.225628,0.020070,-0.000011,-0.000278,2.613779,0.133152,-0.002778,-31.225628,-0.000017,0.000000
30.140001,0.555954,-31.270109,0.020079,-0.000011,-0.000278,2.473007,0.125981,-0.002778,-31.270109,-0.000009,0.000000
30.350002,0.476265,-31.225628,0.020053,-0.000011,-0.000278,2.118532,0.107923,-0.002778,-31.225628,0.000338,0.000000
30.560001,0.490044,-31.225628,0.020057,-0.000011,-0.000269,2.179823,0.111045,-0.002695,-31.225628,0.000693,0.000000
30.770002,0.442749,-31.270109,0.020066,-0.000011,-0.000269,1.969446,0.100328,-0.002695,-31.270109,0.001040,0.000000
30.980001,0.599144,-31.270109,0.020066,0.000012,0.000304,2.665126,0.135768,0.003035,-31.270109,0.001388,0.000000
31.190001,0.647179,-31.225628,0.020079,0.000021,0.000537,2.878794,0.146653,0.005375,-31.225628,0.001743,0.000000
31.400002,0.722031,-31.225628,0.020109,0.000041,0.001049,3.211753,0.163614,0.010492,-31.225628,0.002090,0.000000
31.610001,0.757774,-31.225628,0.020113,0.000058,0.001483,3.370749,0.171714,0.014829,-31.225628,0.002437,0.000000
31.820002,0.820709,-31.314590,0.020148,0.000074,0.001882,3.650697,0.185975,0.018818,-31.314590,0.002792,0.000000
32.030003,0.848267,-31.314590,0.020165,0.000089,0.002263,3.773278,0.192220,0.022634,-31.314590,0.003139,0.000000
32.240002,0.876190,-31.270109,0.020191,0.000102,0.002602,3.897489,0.198548,0.026017,-31.270109,0.003486,0.000000
32.450001,0.857201,-31.314590,0.020169,0.000111,0.002818,3.813019,0.194244,0.028182,-31.314590,0.003842,0.000000
32.660000,0.909706,-31.270109,0.020182,0.000124,0.003157,4.046575,0.206142,0.031566,-31.270109,0.004188,0.000000
32.870003,1.032585,-31.359070,0.020212,0.000140,0.003564,4.593168,0.233987,0.035639,-31.359070,0.004544,0.000000
33.080002,1.075035,-31.314590,0.020230,0.000151,0.003824,4.781995,0.243606,0.038243,-31.314590,0.004891,0.000000
33.290001,1.181534,-31.314590,0.020238,0.000167,0.004232,5.255725,0.267739,0.042315,-31.314590,0.005238,0.000000
33.500000,1.260849,-31.314590,0.020234,0.000183,0.004657,5.608536,0.285712,0.046569,-31.314590,0.005593,0.000000
33.710003,1.278725,-31.270109,0.020277,0.000192,0.004883,5.688051,0.289763,0.048825,-31.270109,0.005940,0.000000
33.920002,1.363998,-31.359070,0.020268,0.000205,0.005212,6.067368,0.309086,0.052118,-31.359070,0.006287,0.000000
34.130001,1.468262,-31.270109,0.020299,0.000223,0.005663,6.531154,0.332713,0.056630,-31.270109,0.006642,0.000000
34.340000,1.586304,-31.403551,0.020316,0.000237,0.006018,7.056231,0.359462,0.060180,-31.403551,0.006989,0.000000
34.550003,1.671204,-31.314590,0.020316,0.000250,0.006339,7.433885,0.378700,0.063389,-31.314590,0.007337,0.000000
34.760002,1.760574,-31.359070,0.020346,0.000262,0.006642,7.831426,0.398952,0.066425,-31.359070,0.007692,0.000000
34.970001,1.845100,-31.403551,0.020320,0.000272,0.006911,8.207417,0.418106,0.069112,-31.403551,0.008039,0.000000
35.180000,2.058098,-31.314590,0.020346,0.000290,0.007362,9.154877,0.466372,0.073624,-31.314590,0.008394,0.000000
35.390003,2.045441,-31.359070,0.020363,0.000296,0.007510,9.098575,0.463503,0.075100,-31.359070,0.008742,0.000000
35.600002,2.332542,-31.359070,0.020381,0.000320,0.008134,10.375667,0.528562,0.081345,-31.359070,0.009088,0.000000
35.810001,2.466225,-31.359070,0.020393,0.000333,0.008464,10.970315,0.558855,0.084638,-31.359070,0.009444,0.000000
36.020000,2.556335,-31.403551,0.020419,0.000347,0.008802,11.371148,0.579274,0.088022,-31.403551,0.009791,0.000000
36.230003,2.770821,-31.270109,0.020437,0.000362,0.009201,12.325226,0.627877,0.092011,-31.270109,0.010137,0.000000
36.440002,2.864662,-31.359070,0.020454,0.000371,0.009435,12.742654,0.649142,0.094350,-31.359070,0.010493,0.000000
36.650002,3.134254,-31.359070,0.020441,0.000386,0.009817,13.941860,0.710232,0.098165,-31.359070,0.010840,0.000000
36.860001,3.264961,-31.403551,0.020480,0.000400,0.010155,14.523273,0.739851,0.101549,-31.403551,0.011187,0.000000
37.070004,3.418747,-31.403551,0.020506,0.000410,0.010424,15.207346,0.774699,0.104236,-31.403551,0.011542,0.000000
37.280003,3.559135,-31.314590,0.020475,0.000420,0.010658,15.831825,0.806512,0.106575,-31.314590,0.011889,0.000000
37.490002,3.957573,-31.492514,0.020510,0.000440,0.011178,17.604164,0.896799,0.111783,-31.492514,0.012245,0.000000
37.700001,4.246536,-31.403551,0.020514,0.000457,0.011620,18.889536,0.962279,0.116204,-31.403551,0.012592,0.000000
37.910004,4.535126,-31.403551,0.020544,0.000474,0.012037,20.173246,1.027674,0.120367,-31.403551,0.012939,0.000000
38.120003,4.770836,-31.448032,0.020540,0.000488,0.012393,21.221739,1.081087,0.123925,-31.448032,0.013294,0.000000
38.330002,4.951439,-31.448032,0.020562,0.000498,0.012661,22.025101,1.122012,0.126612,-31.448032,0.013642,0.000000
38.540001,5.323067,-31.448032,0.020566,0.000516,0.013103,23.678183,1.206224,0.131033,-31.448032,0.013988,0.000000
38.750000,5.512604,-31.448032,0.020592,0.000525,0.013329,24.521286,1.249174,0.133289,-31.448032,0.014343,0.000000
38.960003,5.778099,-31.403551,0.020605,0.000537,0.013642,25.702269,1.309336,0.136415,-31.403551,0.014691,0.000000
39.170002,6.156433,-31.492514,0.020600,0.000552,0.014031,27.385181,1.395068,0.140314,-31.492514,0.015037,0.000000
39.380001,6.563805,-31.448032,0.020631,0.000569,0.014456,29.197262,1.487379,0.144560,-31.448032,0.015393,0.000000
39.590000,6.850533,-31.492514,0.020631,0.000583,0.014821,30.472691,1.552353,0.148209,-31.492514,0.015740,0.000000
39.800003,7.190140,-31.448032,0.020644,0.000597,0.015176,31.983339,1.629309,0.151759,-31.448032,0.016087,0.000000
40.010002,7.560646,-31.492514,0.020661,0.000611,0.015523,33.631432,1.713267,0.155234,-31.492514,0.016442,0.000000
40.220001,7.729332,-31.492514,0.020669,0.000621,0.015783,34.381786,1.751492,0.157830,-31.492514,0.016789,0.000000
40.430000,8.182884,-31.448032,0.020687,0.000635,0.016130,36.399288,1.854268,0.161297,-31.448032,0.017145,0.000000
40.640003,8.524345,-31.536995,0.020704,0.000649,0.016485,37.918182,1.931644,0.164855,-31.536995,0.017492,0.000000
40.850002,8.887039,-31.536995,0.020704,0.000661,0.016789,39.531525,2.013832,0.167890,-31.536995,0.017838,0.000000
41.060001,9.151794,-31.492514,0.020721,0.000673,0.017093,40.709213,2.073826,0.170926,-31.492514,0.018194,0.000000
41.270000,9.584122,-31.492514,0.020730,0.000689,0.017492,42.632301,2.171793,0.174915,-31.492514,0.018541,0.000000
41.480003,9.912178,-31.492514,0.020734,0.000698,0.017725,44.091572,2.246132,0.177254,-31.492514,0.018888,0.000000
41.690002,10.557129,-31.536995,0.020760,0.000719,0.018264,46.960453,2.392280,0.182636,-31.536995,0.019243,0.000000
41.900002,11.107124,-31.492514,0.020760,0.000735,0.018663,49.406956,2.516911,0.186626,-31.492514,0.019591,0.000000
42.110001,11.475029,-31.536995,0.020786,0.000748,0.019009,51.043480,2.600279,0.190093,-31.536995,0.019937,0.000000
42.320004,11.655998,-31.536995,0.020794,0.000757,0.019235,51.848469,2.641287,0.192348,-31.536995,0.020293,0.000000
42.530003,12.338188,-31.492514,0.020812,0.000774,0.019669,54.883003,2.795873,0.196686,-31.492514,0.020640,0.000000
42.740002,12.896744,-31.536995,0.020786,0.000790,0.020076,57.367580,2.922444,0.200758,-31.536995,0.020996,0.000000
42.950001,13.191292,-31.536995,0.020833,0.000801,0.020345,58.677795,2.989189,0.203446,-31.536995,0.021342,0.000000
43.160004,13.741287,-31.581474,0.020838,0.000815,0.020692,61.124298,3.113820,0.206920,-31.581474,0.021689,0.000000
43.370003,14.109192,-31.536995,0.020829,0.000826,0.020978,62.760818,3.197189,0.209782,-31.536995,0.022045,0.000000
43.580002,14.644287,-31.536995,0.020846,0.000841,0.021360,65.141045,3.318443,0.213597,-31.536995,0.022391,0.000000
43.790001,15.277695,-31.625956,0.020863,0.000858,0.021793,67.958580,3.461975,0.217934,-31.625956,0.022738,0.000000
44.000004,15.637779,-31.536995,0.020876,0.000869,0.022062,69.560318,3.543571,0.220622,-31.536995,0.023094,0.000000
44.210003,16.097290,-31.625956,0.020894,0.000881,0.022383,71.604324,3.647698,0.223831,-31.625956,0.023441,0.000000
44.420002,16.577652,-31.536995,0.020881,0.000895,0.022730,73.741081,3.756550,0.227298,-31.536995,0.023787,0.000000
44.630001,16.712448,-31.581474,0.020915,0.000898,0.022808,74.340683,3.787095,0.228078,-31.581474,0.024143,0.000000
44.840004,17.753601,-31.581474,0.020915,0.000919,0.023345,78.971962,4.023024,0.233452,-31.581474,0.024490,0.000000
45.050003,18.285721,-31.581474,0.020915,0.000932,0.023666,81.338951,4.143603,0.236662,-31.581474,0.024846,0.000000
45.260002,18.906090,-31.670437,0.020945,0.000950,0.024117,84.098488,4.284181,0.241174,-31.670437,0.025192,0.000000
45.470001,19.871284,-31.670437,0.020945,0.000967,0.024559,88.391891,4.502898,0.245594,-31.670437,0.025540,0.000000
45.680000,20.278282,-31.625956,0.020971,0.000981,0.024906,90.202301,4.595124,0.249061,-31.625956,0.025895,0.000000
45.890003,20.920258,-31.581474,0.020963,0.000993,0.025227,93.057953,4.740598,0.252271,-31.581474,0.026242,0.000000
46.100002,21.252411,-31.581474,0.020976,0.001002,0.025444,94.535446,4.815865,0.254443,-31.581474,0.026589,0.000000
46.310001,22.218346,-31.625956,0.020976,0.001021,0.025930,98.832138,5.034749,0.259296,-31.625956,0.026945,0.000000
46.520000,22.340111,-31.581474,0.020980,0.001023,0.025990,99.373779,5.062342,0.259901,-31.581474,0.027291,0.000000
46.730003,23.292641,-31.670437,0.021006,0.001044,0.026528,103.610840,5.278188,0.265283,-31.670437,0.027638,0.000000
46.940002,24.388161,-31.714918,0.021023,0.001061,0.026962,108.483955,5.526436,0.269621,-31.714918,0.027994,0.000000
47.150002,25.050240,-31.581474,0.021027,0.001074,0.027274,111.429031,5.676466,0.272740,-31.581474,0.028341,0.000000
47.360001,25.880630,-31.670437,0.021045,0.001089,0.027665,115.122795,5.864635,0.276646,-31.670437,0.028687,0.000000
47.570004,26.472702,-31.625956,0.021045,0.001105,0.028054,117.756462,5.998800,0.280544,-31.625956,0.029043,0.000000
47.780003,27.308304,-31.670437,0.021062,0.001118,0.028393,121.473404,6.188150,0.283928,-31.670437,0.029390,0.000000
47.990002,27.939102,-31.670437,0.021045,0.001128,0.028653,124.279335,6.331091,0.286532,-31.670437,0.029745,0.000000
48.200001,28.451859,-31.670437,0.021053,0.001137,0.028887,126.560188,6.447283,0.288871,-31.670437,0.030092,0.000000
48.410004,29.606964,-31.714918,0.021066,0.001156,0.029364,131.698349,6.709034,0.293640,-31.714918,0.030440,0.000000
48.620003,30.424316,-31.670437,0.021079,0.001168,0.029668,135.334122,6.894248,0.296675,-31.670437,0.030795,0.000000
48.830002,31.355621,-31.670437,0.021088,0.001186,0.030119,139.476776,7.105285,0.301187,-31.670437,0.031142,0.000000
49.040001,31.962585,-31.714918,0.021088,0.001196,0.030370,142.176682,7.242825,0.303700,-31.714918,0.031489,0.000000
49.250004,33.246529,-31.670437,0.021092,0.001216,0.030890,147.887939,7.533771,0.308900,-31.670437,0.031844,0.000000
49.460003,33.978241,-31.670437,0.021105,0.001227,0.031168,151.142761,7.699580,0.311679,-31.670437,0.032191,0.000000
49.670002,34.892044,-31.670437,0.021109,0.001242,0.031541,155.207565,7.906650,0.315410,-31.670437,0.032538,0.000000
49.880001,35.708656,-31.714918,0.021122,0.001255,0.031879,158.840042,8.091698,0.318787,-31.714918,0.032894,0.000000
50.090004,36.280251,-31.714918,0.021126,0.001265,0.032131,161.382614,8.221222,0.321307,-31.714918,0.033240,0.000000
50.300003,37.596214,-31.714918,0.021135,0.001282,0.032555,167.236313,8.519423,0.325554,-31.714918,0.033596,0.000000
50.510002,38.369629,-31.714918,0.021152,0.001295,0.032885,170.676636,8.694682,0.328847,-31.714918,0.033943,0.000000
50.720001,39.439453,-31.714918,0.021144,0.001310,0.033275,175.435455,8.937108,0.332753,-31.714918,0.034290,0.000000
50.930004,40.083290,-31.759399,0.021165,0.001319,0.033501,178.299377,9.083003,0.335009,-31.759399,0.034645,0.000000
51.140003,41.335945,-31.759399,0.021161,0.001337,0.033951,183.871460,9.366859,0.339513,-31.759399,0.034992,0.000000
51.350002,42.351036,-31.714918,0.021182,0.001351,0.034307,188.386810,9.596882,0.343070,-31.714918,0.035339,0.000000
51.560001,43.385117,-31.714918,0.021182,0.001367,0.034715,192.986633,9.831208,0.347151,-31.714918,0.035695,0.000000
51.770004,44.263916,-31.803881,0.021204,0.001380,0.035062,196.895737,10.030347,0.350618,-31.803881,0.036041,0.000000
51.980003,45.000839,-31.714918,0.021191,0.001391,0.035330,200.173737,10.197336,0.353305,-31.714918,0.036389,0.000000
52.190002,45.843147,-31.848360,0.021213,0.001404,0.035660,203.920502,10.388206,0.356598,-31.848360,0.036744,0.000000
52.400002,46.739449,-31.759399,0.021200,0.001419,0.036041,207.907455,10.591311,0.360413,-31.759399,0.037091,0.000000
52.610001,47.219803,-31.848360,0.021243,0.001420,0.036068,210.044174,10.700160,0.360678,-31.848360,0.037446,0.000000
52.820004,48.794197,-31.848360,0.021234,0.001440,0.036570,217.047424,11.056923,0.365704,-31.848360,0.037794,0.000000
53.030003,50.171227,-31.759399,0.021230,0.001459,0.037047,223.172760,11.368962,0.370473,-31.759399,0.038140,0.000000
53.240002,51.383301,-31.848360,0.021239,0.001478,0.037542,228.564331,11.643622,0.375416,-31.848360,0.038496,0.000000
53.450001,52.681023,-31.803881,0.021239,0.001492,0.037906,234.336899,11.937690,0.379065,-31.803881,0.038843,0.000000
53.660004,53.445129,-31.803881,0.021251,0.001503,0.038184,237.735809,12.110839,0.381835,-31.803881,0.039190,0.000000
53.870003,53.994751,-31.759399,0.021256,0.001512,0.038409,240.180649,12.235385,0.384091,-31.759399,0.039545,0.000000
54.080002,55.042236,-31.803881,0.021273,0.001525,0.038747,244.840088,12.472749,0.387475,-31.803881,0.039892,0.000000
54.290001,56.538795,-31.848360,0.021282,0.001544,0.039224,251.497116,12.811874,0.392244,-31.848360,0.040239,0.000000
54.500004,57.207581,-31.803881,0.021273,0.001554,0.039467,254.472031,12.963423,0.394674,-31.803881,0.040595,0.000000
54.710003,58.400291,-31.803881,0.021286,0.001568,0.039831,259.777466,13.233695,0.398315,-31.803881,0.040941,0.000000
54.920002,59.801895,-31.803881,0.021290,0.001584,0.040221,266.012115,13.551303,0.402213,-31.803881,0.041297,0.000000
55.130001,60.566376,-31.848360,0.021295,0.001594,0.040482,269.412689,13.724537,0.404817,-31.848360,0.041644,0.000000
55.340004,61.577370,-31.848360,0.021290,0.001608,0.040846,273.909821,13.953631,0.408458,-31.848360,0.041990,0.000000
55.550003,63.001328,-31.759399,0.021316,0.001624,0.041262,280.243896,14.276304,0.412622,-31.759399,0.042346,0.000000
55.760002,64.136688,-31.892841,0.021338,0.001638,0.041601,285.294250,14.533582,0.416005,-31.892841,0.042693,0.000000
55.970001,65.095551,-31.803881,0.021316,0.001649,0.041887,289.559479,14.750862,0.418867,-31.803881,0.043040,0.000000
56.180004,66.205963,-31.848360,0.021325,0.001664,0.042277,294.498840,15.002486,0.422773,-31.848360,0.043395,0.000000
56.390003,67.262756,-31.848360,0.021329,0.001677,0.042589,299.199677,15.241959,0.425892,-31.848360,0.043743,0.000000
56.600002,67.600494,-31.848360,0.021346,0.001675,0.042537,300.702026,15.318491,0.425369,-31.848360,0.042780,0.000000
56.810001,67.383774,-31.892841,0.021342,0.001675,0.042537,299.738007,15.269382,0.425369,-31.892841,0.042780,0.000000
57.020004,67.275040,-31.848360,0.021346,0.001674,0.042511,299.254333,15.244741,0.425112,-31.848360,0.042537,0.000000
57.230003,67.124237,-31.892841,0.021338,0.001673,0.042485,298.583527,15.210569,0.424854,-31.892841,0.042537,0.000000
57.440002,66.979385,-31.892841,0.021355,0.001672,0.042468,297.939178,15.177746,0.424680,-31.892841,0.042537,0.000000
57.650002,66.852402,-31.848360,0.021377,0.001672,0.042459,297.374329,15.148971,0.424590,-31.848360,0.042537,0.000000
57.860004,66.732498,-31.937323,0.021359,0.001671,0.042451,296.840973,15.121800,0.424506,-31.937323,0.042537,0.000000
58.070004,66.623016,-31.892841,0.021359,0.001671,0.042442,296.353973,15.096992,0.424415,-31.892841,0.042537,0.000000
58.280003,66.518753,-31.937323,0.021372,0.001671,0.042442,295.890198,15.073365,0.424415,-31.937323,0.042537,0.000000
58.490002,66.427887,-31.892841,0.021364,0.001671,0.042433,295.485992,15.052774,0.424332,-31.892841,0.042537,0.000000
58.700005,66.342621,-31.848360,0.021364,0.001671,0.042433,295.106720,15.033453,0.424332,-31.848360,0.042537,0.000000
58.910004,66.259583,-31.937323,0.021355,0.001671,0.042433,294.737335,15.014636,0.424332,-31.937323,0.042537,0.000000
59.120003,66.199997,-31.848360,0.021346,0.001671,0.042433,294.472290,15.001134,0.424332,-31.848360,0.042537,0.000000
59.330002,66.119568,-31.937323,0.021385,0.001671,0.042433,294.114532,14.982908,0.424332,-31.937323,0.042537,0.000000
59.540005,66.062592,-31.937323,0.021359,0.001671,0.042433,293.861084,14.969997,0.424332,-31.937323,0.042537,0.000000
59.750004,65.994446,-31.937323,0.021359,0.001671,0.042433,293.557953,14.954555,0.424332,-31.937323,0.042537,0.000000
59.960003,65.944550,-31.937323,0.021351,0.001671,0.042433,293.335999,14.943249,0.424332,-31.937323,0.042537,0.000000
60.170002,65.875290,-31.937323,0.021351,0.001670,0.042424,293.027924,14.927554,0.424241,-31.937323,0.042537,0.000000
60.380001,65.828003,-31.981804,0.021359,0.001670,0.042424,292.817596,14.916839,0.424241,-31.981804,0.042537,0.000000
60.590004,65.764694,-31.937323,0.021359,0.001670,0.042424,292.535980,14.902493,0.424241,-31.937323,0.042537,0.000000
60.800003,65.718155,-31.892841,0.021385,0.001670,0.042424,292.328949,14.891947,0.424241,-31.892841,0.042537,0.000000
61.010002,65.679047,-31.981804,0.021355,0.001670,0.042424,292.154999,14.883085,0.424241,-31.981804,0.042537,0.000000
61.220001,65.620590,-31.937323,0.021351,0.001670,0.042424,291.894958,14.869839,0.424241,-31.937323,0.042537,0.000000
61.430004,65.580368,-31.981804,0.021372,0.001670,0.042424,291.716034,14.860724,0.424241,-31.981804,0.042537,0.000000
61.640003,65.539780,-32.026283,0.021368,0.001670,0.042424,291.535492,14.851526,0.424241,-32.026283,0.042537,0.000000
61.850002,65.492874,-31.981804,0.021359,0.001670,0.042424,291.326843,14.840898,0.424241,-31.981804,0.042537,0.000000
62.060001,65.450790,-32.070766,0.021346,0.001670,0.042424,291.139648,14.831361,0.424241,-32.070766,0.042537,0.000000
62.270004,65.420624,-31.981804,0.021364,0.001670,0.042424,291.005463,14.824526,0.424241,-31.981804,0.042537,0.000000
62.480003,65.382645,-32.070766,0.021359,0.001670,0.042424,290.836517,14.815919,0.424241,-32.070766,0.042537,0.000000
62.690002,65.343170,-31.981804,0.021368,0.001670,0.042424,290.660950,14.806974,0.424241,-31.981804,0.042537,0.000000
62.900002,65.306305,-32.026283,0.021368,0.001670,0.042424,290.496948,14.798620,0.424241,-32.026283,0.042537,0.000000
63.110004,65.265350,-32.070766,0.021385,0.001670,0.042424,290.314789,14.789339,0.424241,-32.070766,0.042537,0.000000
63.320004,65.244873,-31.937323,0.021372,0.001670,0.042424,290.223694,14.784699,0.424241,-31.937323,0.042537,0.000000
63.530003,65.196457,-32.026283,0.021364,0.001670,0.042416,290.008331,14.773728,0.424158,-32.026283,0.042537,0.000000
63.740002,65.173737,-32.026283,0.021372,0.001670,0.042416,289.907257,14.768580,0.424158,-32.026283,0.042537,0.000000
63.950005,65.141342,-32.026283,0.021372,0.001670,0.042416,289.763153,14.761239,0.424158,-32.026283,0.042537,0.000000
64.160004,65.117523,-32.026283,0.021372,0.001670,0.042416,289.657196,14.755842,0.424158,-32.026283,0.042537,0.000000
64.370003,65.085861,-32.026283,0.021372,0.001670,0.042416,289.516357,14.748668,0.424158,-32.026283,0.042537,0.000000
64.580002,65.061295,-32.070766,0.021359,0.001670,0.042416,289.407104,14.743100,0.424158,-32.070766,0.042537,0.000000
64.790001,65.024048,-32.026283,0.021372,0.001670,0.042416,289.241425,14.734660,0.424158,-32.026283,0.042537,0.000000
65.000000,64.995743,-32.026283,0.021359,0.001670,0.042416,289.115509,14.728246,0.424158,-32.026283,0.042537,0.000000
65.210007,64.972656,-32.026283,0.021364,0.001670,0.042416,289.012817,14.723015,0.424158,-32.026283,0.042537,0.000000
65.420006,64.938782,-32.070766,0.021389,0.001670,0.042416,288.862122,14.715339,0.424158,-32.070766,0.042537,0.000000
65.630005,64.917175,-32.115246,0.021377,0.001670,0.042416,288.766022,14.710442,0.424158,-32.115246,0.042537,0.000000
65.840004,64.898560,-32.115246,0.021372,0.001670,0.042416,288.683197,14.706223,0.424158,-32.115246,0.042537,0.000000
66.050003,64.866913,-32.070766,0.021368,0.001670,0.042416,288.542450,14.699053,0.424158,-32.070766,0.042537,0.000000
66.260002,64.836380,-32.115246,0.021372,0.001670,0.042416,288.406616,14.692134,0.424158,-32.115246,0.042537,0.000000
66.470001,64.815521,-32.026283,0.021377,0.001670,0.042416,288.313843,14.687407,0.424158,-32.026283,0.042537,0.000000
66.680000,64.789459,-32.070766,0.021372,0.001670,0.042416,288.197906,14.681501,0.424158,-32.070766,0.042537,0.000000
66.889999,64.780518,-32.070766,0.021359,0.001670,0.042416,288.158142,14.679475,0.424158,-32.070766,0.042537,0.000000
67.100006,64.754822,-32.115246,0.021377,0.001670,0.042416,288.043823,14.673653,0.424158,-32.115246,0.042537,0.000000
67.310005,64.722794,-32.159729,0.021368,0.001670,0.042416,287.901367,14.666394,0.424158,-32.159729,0.042537,0.000000
67.520004,64.713120,-32.070766,0.021385,0.001670,0.042416,287.858337,14.664203,0.424158,-32.070766,0.042537,0.000000
67.730003,64.685944,-32.204208,0.021368,0.001670,0.042416,287.737457,14.658045,0.424158,-32.204208,0.042537,0.000000
67.940002,64.665085,-32.070766,0.021372,0.001670,0.042416,287.644653,14.653317,0.424158,-32.070766,0.042537,0.000000
68.150002,64.638275,-32.159729,0.021377,0.001670,0.042416,287.525421,14.647243,0.424158,-32.159729,0.042537,0.000000
68.360001,64.623001,-32.159729,0.021377,0.001670,0.042416,287.457458,14.643782,0.424158,-32.159729,0.042537,0.000000
68.570000,64.599915,-32.159729,0.021368,0.001670,0.042416,287.354767,14.638550,0.424158,-32.159729,0.042537,0.000000
68.780006,64.569763,-32.115246,0.021381,0.001670,0.042416,287.220642,14.631718,0.424158,-32.115246,0.042537,0.000000
68.990005,64.561935,-32.159729,0.021385,0.001670,0.042416,287.185822,14.629944,0.424158,-32.159729,0.042537,0.000000
69.200005,64.534760,-32.204208,0.021389,0.001670,0.042416,287.064941,14.623785,0.424158,-32.204208,0.042537,0.000000
69.410004,64.520599,-32.115246,0.021368,0.001670,0.042416,287.001953,14.620576,0.424158,-32.115246,0.042537,0.000000
69.620003,64.490067,-32.204208,0.021377,0.001670,0.042416,286.866150,14.613658,0.424158,-32.204208,0.042537,0.000000
69.830002,64.481873,-32.204208,0.021389,0.001670,0.042407,286.829681,14.611801,0.424067,-32.204208,0.042537,0.000000
70.040001,64.468475,-32.159729,0.021377,0.001670,0.042407,286.770111,14.608766,0.424067,-32.159729,0.042537,0.000000
70.250000,64.440536,-32.204208,0.021381,0.001670,0.042407,286.645813,14.602434,0.424067,-32.204208,0.042537,0.000000
70.460007,64.437561,-32.204208,0.021368,0.001670,0.042407,286.632599,14.601761,0.424067,-32.204208,0.042537,0.000000
70.670006,64.413727,-32.159729,0.021372,0.001670,0.042407,286.526581,14.596359,0.424067,-32.159729,0.042537,0.000000
70.880005,64.397354,-32.204208,0.021368,0.001670,0.042407,286.453735,14.592649,0.424067,-32.204208,0.042537,0.000000
71.090004,64.388031,-32.159729,0.021377,0.001670,0.042407,286.412262,14.590536,0.424067,-32.159729,0.042537,0.000000
71.300003,64.365692,-32.248688,0.021377,0.001670,0.042407,286.312897,14.585475,0.424067,-32.248688,0.042537,0.000000
71.510002,64.360855,-32.204208,0.021377,0.001670,0.042407,286.291382,14.584378,0.424067,-32.204208,0.042537,0.000000
71.720001,64.331802,-32.204208,0.021385,0.001670,0.042407,286.162140,14.577794,0.424067,-32.204208,0.042537,0.000000
71.930000,64.319901,-32.293171,0.021359,0.001670,0.042407,286.109192,14.575098,0.424067,-32.293171,0.042537,0.000000
72.140007,64.306854,-32.248688,0.021381,0.001670,0.042407,286.051178,14.572142,0.424067,-32.248688,0.042537,0.000000
72.350006,64.282654,-32.248688,0.021372,0.001670,0.042407,285.943512,14.566658,0.424067,-32.248688,0.042537,0.000000
72.560005,64.274841,-32.293171,0.021385,0.001670,0.042407,285.908783,14.564887,0.424067,-32.293171,0.042537,0.000000
72.770004,64.246536,-32.204208,0.021377,0.001670,0.042407,285.782867,14.558474,0.424067,-32.204208,0.042537,0.000000
72.980003,64.239456,-32.248688,0.021385,0.001670,0.042407,285.751373,14.556869,0.424067,-32.248688,0.042537,0.000000
73.190002,64.225677,-32.248688,0.021385,0.001670,0.042407,285.690094,14.553746,0.424067,-32.248688,0.042537,0.000000
73.400002,64.211533,-32.293171,0.021377,0.001670,0.042407,285.627167,14.550541,0.424067,-32.293171,0.042537,0.000000
73.610001,64.193665,-32.204208,0.021372,0.001670,0.042407,285.547668,14.546492,0.424067,-32.204208,0.042537,0.000000
73.820000,64.175415,-32.248688,0.021377,0.001670,0.042407,285.466492,14.542356,0.424067,-32.248688,0.042537,0.000000
74.030006,64.171310,-32.337650,0.021381,0.001670,0.042407,285.448242,14.541428,0.424067,-32.337650,0.042537,0.000000
74.240005,64.159409,-32.293171,0.021398,0.001670,0.042407,285.395294,14.538730,0.424067,-32.293171,0.042537,0.000000
74.450005,64.138550,-32.337650,0.021385,0.001670,0.042407,285.302521,14.534002,0.424067,-32.337650,0.042537,0.000000
74.660004,64.137436,-32.293171,0.021368,0.001670,0.042407,285.297577,14.533751,0.424067,-32.293171,0.042537,0.000000
74.870003,64.110245,-32.293171,0.021381,0.001670,0.042407,285.176605,14.527589,0.424067,-32.293171,0.042537,0.000000
75.080002,64.088272,-32.248688,0.021372,0.001670,0.042407,285.078857,14.522611,0.424067,-32.248688,0.042537,0.000000
75.290001,64.089767,-32.248688,0.021381,0.001670,0.042407,285.085510,14.522949,0.424067,-32.248688,0.042537,0.000000
75.500000,64.060730,-32.337650,0.021364,0.001670,0.042407,284.956360,14.516369,0.424067,-32.337650,0.042537,0.000000
75.710007,64.060349,-32.293171,0.021381,0.001670,0.042407,284.954651,14.516283,0.424067,-32.293171,0.042537,0.000000
75.920006,64.045456,-32.293171,0.021364,0.001670,0.042407,284.888428,14.512908,0.424067,-32.293171,0.042537,0.000000
76.130005,64.037262,-32.337650,0.021346,0.001670,0.042407,284.851959,14.511051,0.424067,-32.337650,0.042537,0.000000
76.340004,64.033539,-32.293171,0.021381,0.001670,0.042407,284.835419,14.510207,0.424067,-32.293171,0.042537,0.000000
76.550003,64.005615,-32.293171,0.021368,0.001670,0.042407,284.711182,14.503880,0.424067,-32.293171,0.042537,0.000000
76.760002,63.989975,-32.337650,0.021385,0.001670,0.042407,284.641632,14.500336,0.424067,-32.337650,0.042537,0.000000
76.970001,63.981415,-32.293171,0.021372,0.001670,0.042407,284.603546,14.498396,0.424067,-32.293171,0.042537,0.000000
77.180000,63.976944,-32.337650,0.021389,0.001670,0.042407,284.583649,14.497383,0.424067,-32.337650,0.042537,0.000000
77.390007,63.960922,-32.293171,0.021377,0.001670,0.042407,284.512390,14.493752,0.424067,-32.293171,0.042537,0.000000
77.600006,63.951996,-32.382133,0.021389,0.001670,0.042407,284.472687,14.491729,0.424067,-32.382133,0.042537,0.000000
77.810005,63.947144,-32.337650,0.021385,0.001670,0.042407,284.451111,14.490630,0.424067,-32.337650,0.042537,0.000000
78.020004,63.949753,-32.293171,0.021377,0.001670,0.042407,284.462708,14.491220,0.424067,-32.293171,0.042537,0.000000
78.230003,63.913635,-32.382133,0.021359,0.001670,0.042407,284.302063,14.483037,0.424067,-32.382133,0.042537,0.000000
78.440002,63.914749,-32.382133,0.021385,0.001670,0.042407,284.307007,14.483289,0.424067,-32.382133,0.042537,0.000000
78.650002,63.899109,-32.382133,0.021381,0.001670,0.042407,284.237427,14.479745,0.424067,-32.382133,0.042537,0.000000
78.860001,63.889053,-32.293171,0.021372,0.001670,0.042407,284.192688,14.477467,0.424067,-32.293171,0.042537,0.000000
79.070007,63.885330,-32.426613,0.021381,0.001670,0.042407,284.176147,14.476623,0.424067,-32.426613,0.042537,0.000000
79.280006,63.860764,-32.382133,0.021385,0.001670,0.042407,284.066864,14.471056,0.424067,-32.382133,0.042537,0.000000
79.490005,63.852936,-32.382133,0.021398,0.001670,0.042407,284.032043,14.469282,0.424067,-32.382133,0.042537,0.000000
79.700005,63.843628,-32.471096,0.021389,0.001670,0.042407,283.990631,14.467173,0.424067,-32.471096,0.042537,0.000000
79.910004,63.831711,-32.426613,0.021385,0.001670,0.042407,283.937622,14.464472,0.424067,-32.426613,0.042537,0.000000
80.120003,63.837296,-32.471096,0.021372,0.001670,0.042407,283.962463,14.465737,0.424067,-32.471096,0.042537,0.000000
80.330002,63.810120,-32.471096,0.021385,0.001670,0.042407,283.841583,14.459579,0.424067,-32.471096,0.042537,0.000000
80.540001,63.803040,-32.337650,0.021385,0.001670,0.042407,283.810089,14.457975,0.424067,-32.337650,0.042537,0.000000
80.750008,63.802292,-32.471096,0.021394,0.001670,0.042407,283.806763,14.457806,0.424067,-32.471096,0.042537,0.000000
80.960007,63.786285,-32.426613,0.021381,0.001670,0.042407,283.735565,14.454179,0.424067,-32.426613,0.042537,0.000000
81.170006,63.786652,-32.426613,0.021377,0.001670,0.042407,283.737183,14.454262,0.424067,-32.426613,0.042537,0.000000
81.380005,63.769150,-32.426613,0.021381,0.001670,0.042407,283.659332,14.450296,0.424067,-32.426613,0.042537,0.000000
81.590004,63.758728,-32.426613,0.021364,0.001670,0.042407,283.612976,14.447934,0.424067,-32.426613,0.042537,0.000000
81.800003,63.753891,-32.515575,0.021381,0.001670,0.042407,283.591461,14.446838,0.424067,-32.515575,0.042537,0.000000
82.010002,63.726334,-32.426613,0.021381,0.001670,0.042407,283.468903,14.440593,0.424067,-32.426613,0.042537,0.000000
82.220001,63.730057,-32.515575,0.021368,0.001670,0.042407,283.485443,14.441438,0.424067,-32.515575,0.042537,0.000000
82.430000,63.717773,-32.471096,0.021381,0.001670,0.042407,283.430817,14.438654,0.424067,-32.471096,0.042537,0.000000
82.640007,63.703995,-32.426613,0.021394,0.001670,0.042407,283.369507,14.435532,0.424067,-32.426613,0.042537,0.000000
82.850006,63.705856,-32.515575,0.021389,0.001670,0.042407,283.377808,14.435953,0.424067,-32.515575,0.042537,0.000000
83.060005,63.682770,-32.426613,0.021377,0.001670,0.042407,283.275116,14.430722,0.424067,-32.426613,0.042537,0.000000
83.270004,63.673462,-32.471096,0.021377,0.001670,0.042407,283.233704,14.428613,0.424067,-32.471096,0.042537,0.000000
83.480003,63.664139,-32.515575,0.021368,0.001670,0.042407,283.192230,14.426500,0.424067,-32.515575,0.042537,0.000000
83.690002,63.644775,-32.471096,0.021385,0.001670,0.042407,283.106110,14.422112,0.424067,-32.471096,0.042537,0.000000
83.900002,63.653717,-32.560055,0.021385,0.001670,0.042407,283.145874,14.424139,0.424067,-32.560055,0.042537,0.000000
84.110001,63.630264,-32.515575,0.021381,0.001670,0.042407,283.041565,14.418824,0.424067,-32.515575,0.042537,0.000000
84.320007,63.628021,-32.515575,0.021377,0.001670,0.042407,283.031586,14.418316,0.424067,-32.515575,0.042537,0.000000
84.530006,63.633240,-32.515575,0.021364,0.001670,0.042407,283.054779,14.419498,0.424067,-32.515575,0.042537,0.000000
84.740005,63.598602,-32.515575,0.021394,0.001670,0.042407,282.900726,14.411650,0.424067,-32.515575,0.042537,0.000000
84.950005,63.603455,-32.515575,0.021389,0.001670,0.042407,282.922302,14.412748,0.424067,-32.515575,0.042537,0.000000
85.160004,63.597122,-32.515575,0.021394,0.001670,0.042407,282.894135,14.411313,0.424067,-32.515575,0.042537,0.000000
85.370003,63.582230,-32.560055,0.021398,0.001670,0.042407,282.827881,14.407939,0.424067,-32.560055,0.042537,0.000000
85.580002,63.581482,-32.604538,0.021359,0.001670,0.042407,282.824554,14.407770,0.424067,-32.604538,0.042537,0.000000
85.790001,63.566208,-32.560055,0.021372,0.001670,0.042407,282.756622,14.404308,0.424067,-32.560055,0.042537,0.000000
86.000008,63.561005,-32.604538,0.021385,0.001670,0.042407,282.733459,14.403130,0.424067,-32.604538,0.042537,0.000000
86.210007,63.556900,-32.560055,0.021394,0.001670,0.042407,282.715210,14.402200,0.424067,-32.560055,0.042537,0.000000
86.420006,63.545364,-32.560055,0.021381,0.001670,0.042407,282.663910,14.399585,0.424067,-32.560055,0.042537,0.000000
86.630005,63.540894,-32.560055,0.021368,0.001670,0.042407,282.644012,14.398572,0.424067,-32.560055,0.042537,0.000000
86.840004,63.530090,-32.515575,0.021377,0.001670,0.042407,282.595947,14.396125,0.424067,-32.515575,0.042537,0.000000
87.000008,63.515198,-32.604538,0.021372,0.001670,0.042407,282.529724,14.392750,0.424067,-32.604538,0.042537,0.000000