File: Data/PDMS 0040002 test 3_10242023_175816.csv
Time (sec),S:Load (lbs),S:HL1 (DIM),S:LVDT (in),S:Position (in),Ch:Position (mm),Ch:Load (N),Ch:Stress (MPa),Ch:Strain (mm/mm),Ch:HL1 (DIM),Set Point (),Cycles ()
0.110000,-0.042824,-37.052631,0.015470,-0.004802,-0.121975,-0.190490,-0.009704,-1.219751,-37.052631,-0.122080,0.000000
0.260000,-0.038353,-37.052631,0.015444,-0.004802,-0.121975,-0.170603,-0.008691,-1.219751,-37.052631,-0.122080,0.000000
0.410000,-0.040588,-37.097115,0.015440,-0.004802,-0.121975,-0.180546,-0.009197,-1.219751,-37.097115,-0.121888,0.000000
0.560000,-0.082298,-37.052631,0.015457,-0.004740,-0.120405,-0.366081,-0.018649,-1.204051,-37.052631,-0.119373,0.000000
0.710000,-0.066284,-37.052631,0.015504,-0.004643,-0.117934,-0.294847,-0.015020,-1.179335,-37.052631,-0.116876,0.000000
0.860000,-0.061440,-37.141594,0.015621,-0.004545,-0.115436,-0.273297,-0.013922,-1.154363,-37.141594,-0.114378,0.000000
1.010000,-0.049896,-37.052631,0.015685,-0.004455,-0.113164,-0.221950,-0.011307,-1.131638,-37.052631,-0.111881,0.000000
1.160000,-0.082298,-37.097115,0.015797,-0.004351,-0.110528,-0.366081,-0.018649,-1.105280,-37.097115,-0.109383,0.000000
1.310000,-0.042824,-37.097115,0.015905,-0.004257,-0.108134,-0.190490,-0.009704,-1.081344,-37.097115,-0.106885,0.000000
1.460000,-0.048035,-37.097115,0.016013,-0.004159,-0.105646,-0.213669,-0.010885,-1.056455,-37.097115,-0.104387,0.000000
1.610000,-0.047295,-37.141594,0.016099,-0.004063,-0.103191,-0.210377,-0.010717,-1.031906,-37.141594,-0.101890,0.000000
1.760000,-0.055855,-37.097115,0.016216,-0.003961,-0.100598,-0.248455,-0.012657,-1.005980,-37.097115,-0.099393,0.000000
1.910000,-0.052132,-37.052631,0.016336,-0.003859,-0.098022,-0.231893,-0.011813,-0.980220,-37.052631,-0.096895,0.000000
2.060000,-0.038727,-37.052631,0.016410,-0.003764,-0.095594,-0.172265,-0.008776,-0.955943,-37.052631,-0.094398,0.000000
2.210000,-0.026810,-37.097115,0.016539,-0.003667,-0.093140,-0.119255,-0.006075,-0.931402,-37.097115,-0.091900,0.000000
2.360000,-0.042450,-37.097115,0.016630,-0.003568,-0.090616,-0.188827,-0.009619,-0.906164,-37.097115,-0.089402,0.000000
2.510000,-0.058090,-37.141594,0.016750,-0.003466,-0.088040,-0.258398,-0.013163,-0.880404,-37.141594,-0.086887,0.000000
2.660000,-0.050270,-37.052631,0.016832,-0.003369,-0.085578,-0.223612,-0.011391,-0.855780,-37.052631,-0.084390,0.000000
2.810000,-0.060699,-37.141594,0.016944,-0.003275,-0.083175,-0.270005,-0.013755,-0.831753,-37.141594,-0.081892,0.000000
2.960000,-0.053619,-37.141594,0.017030,-0.003172,-0.080556,-0.238511,-0.012150,-0.805562,-37.141594,-0.079394,0.000000
3.110000,-0.070381,-37.141594,0.017143,-0.003075,-0.078111,-0.313071,-0.015949,-0.781111,-37.141594,-0.076897,0.000000
3.260000,-0.066658,-37.186073,0.017255,-0.002979,-0.075656,-0.296510,-0.015105,-0.756563,-37.186073,-0.074399,0.000000
3.410000,-0.043938,-37.097115,0.017354,-0.002881,-0.073167,-0.195445,-0.009956,-0.731673,-37.097115,-0.071902,0.000000
3.560000,-0.035378,-37.141594,0.017470,-0.002785,-0.070731,-0.157367,-0.008017,-0.707306,-37.141594,-0.069404,0.000000
3.710000,-0.067398,-37.141594,0.017552,-0.002688,-0.068276,-0.299802,-0.015273,-0.682765,-37.141594,-0.066906,0.000000
3.860000,-0.063301,-37.097115,0.017669,-0.002580,-0.065545,-0.281577,-0.014344,-0.655445,-37.097115,-0.064408,0.000000
4.010000,-0.024574,-37.186073,0.017785,-0.002483,-0.063065,-0.109312,-0.005569,-0.630647,-37.186073,-0.061911,0.000000
4.160000,-0.029793,-37.186073,0.017867,-0.002392,-0.060757,-0.132525,-0.006751,-0.607574,-37.186073,-0.059414,0.000000
4.310000,-0.031654,-37.186073,0.017979,-0.002287,-0.058087,-0.140806,-0.007173,-0.580868,-37.186073,-0.056916,0.000000
4.460000,-0.063301,-37.141594,0.018087,-0.002190,-0.055633,-0.281577,-0.014344,-0.556327,-37.141594,-0.054401,0.000000
4.610000,-0.041710,-37.141594,0.018169,-0.002090,-0.053074,-0.185535,-0.009452,-0.530741,-37.141594,-0.051903,0.000000
4.760000,-0.046547,-37.186073,0.018277,-0.001992,-0.050593,-0.207051,-0.010548,-0.505934,-37.186073,-0.049406,0.000000
4.910000,-0.033142,-37.186073,0.018393,-0.001893,-0.048087,-0.147423,-0.007510,-0.480871,-37.186073,-0.046908,0.000000
5.060000,-0.078941,-37.186073,0.018475,-0.001803,-0.045790,-0.351149,-0.017888,-0.457897,-37.186073,-0.044410,0.000000
5.210000,-0.072983,-37.186073,0.018570,-0.001697,-0.043093,-0.324644,-0.016538,-0.430925,-37.186073,-0.041913,0.000000
5.360000,-0.043938,-37.186073,0.018682,-0.001600,-0.040638,-0.195445,-0.009956,-0.406377,-37.186073,-0.039415,0.000000
5.510000,-0.010803,-37.186073,0.018794,-0.001506,-0.038244,-0.048055,-0.002448,-0.382441,-37.186073,-0.036918,0.000000
5.660000,-0.037239,-37.186073,0.018902,-0.001407,-0.035729,-0.165648,-0.008438,-0.357294,-37.186073,-0.034420,0.000000
5.810000,-0.067772,-37.186073,0.019005,-0.001307,-0.033206,-0.301465,-0.015357,-0.332056,-37.186073,-0.031923,0.000000
5.960001,-0.020111,-37.186073,0.019100,-0.001204,-0.030586,-0.089459,-0.004557,-0.305865,-37.186073,-0.029425,0.000000
6.110000,-0.013779,-37.186073,0.019221,-0.001107,-0.028115,-0.061291,-0.003122,-0.281150,-37.186073,-0.026927,0.000000
6.260000,-0.023834,-37.186073,0.019311,-0.001011,-0.025678,-0.106020,-0.005401,-0.256782,-37.186073,-0.024413,0.000000
6.410000,-0.032768,-37.230556,0.019428,-0.000904,-0.022964,-0.145760,-0.007425,-0.229637,-37.230556,-0.021915,0.000000
6.560000,-0.049896,-37.186073,0.019535,-0.000809,-0.020544,-0.221950,-0.011307,-0.205444,-37.186073,-0.019417,0.000000
6.710001,-0.024948,-37.230556,0.019639,-0.000713,-0.018116,-0.110975,-0.005653,-0.181160,-37.230556,-0.016919,0.000000
6.860000,-0.017876,-37.230556,0.019725,-0.000620,-0.015757,-0.079515,-0.004051,-0.157573,-37.230556,-0.014422,0.000000
7.010000,-0.038353,-37.230556,0.019837,-0.000515,-0.013078,-0.170603,-0.008691,-0.130776,-37.230556,-0.011924,0.000000
7.160000,-0.078941,-37.230556,0.019932,-0.000421,-0.010701,-0.351149,-0.017888,-0.107014,-37.230556,-0.009427,0.000000
7.310000,-0.021599,-37.186073,0.020053,-0.000318,-0.008065,-0.096076,-0.004894,-0.080649,-37.186073,-0.006929,0.000000
7.460001,0.016754,-37.186073,0.020139,-0.000228,-0.005784,0.074526,0.003797,-0.057841,-37.186073,-0.004431,0.000000
7.610000,0.090485,-37.230556,0.020290,-0.000127,-0.003217,0.402496,0.020504,-0.032172,-37.230556,-0.001934,0.000000
7.760000,0.354126,-37.186073,0.020376,-0.000027,-0.000693,1.575231,0.080246,-0.006934,-37.186073,0.000564,0.000000
7.910000,0.606590,-37.275036,0.020445,-0.000000,-0.000000,2.698248,0.137455,-0.000000,-37.275036,0.000251,0.000000
8.060000,0.555206,-37.186073,0.020454,-0.000000,-0.000000,2.469681,0.125812,-0.000000,-37.186073,0.000251,0.000000
8.210000,0.529884,-37.275036,0.020445,-0.000000,-0.000000,2.357043,0.120074,-0.000000,-37.275036,0.000251,0.000000
8.360001,0.514992,-37.275036,0.020454,-0.000000,-0.000000,2.290798,0.116699,-0.000000,-37.275036,0.000251,0.000000
8.510000,0.596542,-37.275036,0.020445,-0.000000,-0.000000,2.653553,0.135178,-0.000000,-37.275036,0.000459,0.000000
8.660001,0.579407,-37.230556,0.020437,0.000000,0.000008,2.577330,0.131295,0.000083,-37.230556,0.000711,0.000000
8.810000,0.584999,-37.275036,0.020450,0.000003,0.000078,2.602206,0.132563,0.000780,-37.275036,0.000962,0.000000
8.960000,0.600632,-37.230556,0.020445,0.000010,0.000242,2.671743,0.136105,0.002422,-37.230556,0.001214,0.000000
9.110001,0.627815,-37.275036,0.020445,0.000013,0.000329,2.792662,0.142265,0.003293,-37.275036,0.001466,0.000000
9.260000,0.721657,-37.319519,0.020450,0.000027,0.000693,3.210090,0.163530,0.006934,-37.319519,0.001709,0.000000
9.410001,0.817360,-37.319519,0.020458,0.000037,0.000936,3.635798,0.185216,0.009364,-37.319519,0.001960,0.000000
9.560000,0.897041,-37.275036,0.020475,0.000046,0.001170,3.990239,0.203272,0.011703,-37.275036,0.002211,0.000000
9.710000,0.946945,-37.319519,0.020480,0.000057,0.001448,4.212223,0.214581,0.014481,-37.319519,0.002462,0.000000
9.860001,1.024025,-37.275036,0.020501,0.000068,0.001717,4.555090,0.232047,0.017168,-37.275036,0.002714,0.000000
10.010000,1.113022,-37.319519,0.020506,0.000074,0.001882,4.950968,0.252214,0.018818,-37.319519,0.002966,0.000000
10.160001,1.187492,-37.363998,0.020510,0.000081,0.002064,5.282230,0.269090,0.020635,-37.363998,0.003208,0.000000
10.310000,1.353203,-37.363998,0.020510,0.000096,0.002445,6.019347,0.306640,0.024450,-37.363998,0.003460,0.000000
10.460000,1.435867,-37.275036,0.020514,0.000104,0.002653,6.387057,0.325372,0.026532,-37.275036,0.003711,0.000000
10.610001,1.547203,-37.363998,0.020544,0.000112,0.002844,6.882303,0.350601,0.028440,-37.363998,0.003963,0.000000
10.760000,1.564705,-37.275036,0.020540,0.000116,0.002939,6.960155,0.354567,0.029393,-37.275036,0.004214,0.000000
10.910001,1.807121,-37.319519,0.020549,0.000134,0.003400,8.038477,0.409500,0.033996,-37.319519,0.004466,0.000000
11.060000,1.941551,-37.319519,0.020575,0.000144,0.003668,8.636451,0.439962,0.036683,-37.319519,0.004708,0.000000
11.210001,2.099808,-37.363998,0.020566,0.000155,0.003945,9.340411,0.475823,0.039454,-37.363998,0.004960,0.000000
11.360001,2.280037,-37.319519,0.020600,0.000169,0.004293,10.142111,0.516664,0.042928,-37.319519,0.005212,0.000000
11.510000,2.354507,-37.363998,0.020592,0.000178,0.004518,10.473372,0.533539,0.045177,-37.363998,0.005463,0.000000
11.660001,2.540695,-37.319519,0.020613,0.000189,0.004795,11.301577,0.575730,0.047955,-37.319519,0.005714,0.000000
11.810000,2.653900,-37.319519,0.020626,0.000197,0.005004,11.805138,0.601382,0.050036,-37.319519,0.005967,0.000000
11.960001,2.761139,-37.319519,0.020622,0.000205,0.005212,12.282159,0.625683,0.052118,-37.319519,0.006209,0.000000
12.110001,3.042656,-37.319519,0.020644,0.000220,0.005585,13.534410,0.689476,0.055850,-37.319519,0.006461,0.000000
12.260000,3.170006,-37.363998,0.020648,0.000225,0.005724,14.100890,0.718334,0.057235,-37.363998,0.006712,0.000000
12.410001,3.289162,-37.319519,0.020661,0.000234,0.005949,14.630922,0.745335,0.059491,-37.319519,0.006963,0.000000
12.560000,3.418747,-37.319519,0.020669,0.000242,0.006140,15.207346,0.774699,0.061399,-37.319519,0.007215,0.000000
12.710001,3.606796,-37.363998,0.020674,0.000253,0.006426,16.043831,0.817312,0.064260,-37.363998,0.007467,0.000000
12.860001,3.895760,-37.319519,0.020708,0.000264,0.006712,17.329205,0.882792,0.067121,-37.319519,0.007709,0.000000
13.010000,4.132957,-37.363998,0.020700,0.000276,0.007007,18.384314,0.936542,0.070066,-37.363998,0.007961,0.000000
13.160001,4.319519,-37.319519,0.020704,0.000286,0.007259,19.214180,0.978817,0.072587,-37.319519,0.008212,0.000000
13.310000,4.493790,-37.363998,0.020721,0.000295,0.007493,19.989374,1.018307,0.074926,-37.363998,0.008464,0.000000
13.460001,4.731361,-37.408482,0.020721,0.000307,0.007787,21.046146,1.072142,0.077870,-37.408482,0.008715,0.000000
13.610001,4.958138,-37.408482,0.020747,0.000317,0.008039,22.054897,1.123530,0.080391,-37.408482,0.008958,0.000000
13.760000,5.163689,-37.408482,0.020747,0.000325,0.008256,22.969234,1.170109,0.082556,-37.408482,0.009209,0.000000
13.910001,5.289551,-37.363998,0.020769,0.000333,0.008464,23.529097,1.198629,0.084638,-37.363998,0.009461,0.000000
14.060000,5.625801,-37.452961,0.020769,0.000344,0.008733,25.024813,1.274825,0.087325,-37.452961,0.009713,0.000000
14.210001,5.825394,-37.408482,0.020777,0.000355,0.009010,25.912645,1.320053,0.090103,-37.408482,0.009964,0.000000
14.360001,5.960937,-37.363998,0.020773,0.000360,0.009149,26.515574,1.350768,0.091488,-37.363998,0.010215,0.000000
14.510000,6.191811,-37.408482,0.020799,0.000368,0.009340,27.542549,1.403084,0.093396,-37.408482,0.010458,0.000000
14.660001,6.443901,-37.408482,0.020786,0.000379,0.009626,28.663904,1.460209,0.096257,-37.408482,0.010710,0.000000
14.810000,6.731377,-37.452961,0.020807,0.000390,0.009912,29.942659,1.525352,0.099119,-37.452961,0.010962,0.000000
14.960001,7.141357,-37.452961,0.020833,0.000403,0.010233,31.766344,1.618255,0.102328,-37.452961,0.011213,0.000000
15.110001,7.174126,-37.408482,0.020846,0.000411,0.010441,31.912106,1.625680,0.104410,-37.408482,0.011464,0.000000
15.260001,7.644806,-37.408482,0.020846,0.000422,0.010727,34.005795,1.732338,0.107271,-37.408482,0.011716,0.000000
15.410001,7.908447,-37.497440,0.020846,0.000433,0.010996,35.178532,1.792080,0.109959,-37.497440,0.011959,0.000000
15.560000,8.245811,-37.363998,0.020838,0.000444,0.011282,36.679203,1.868528,0.112820,-37.363998,0.012210,0.000000
15.710001,8.576851,-37.408482,0.020868,0.000456,0.011577,38.151737,1.943542,0.115772,-37.408482,0.012461,0.000000
15.860001,8.894112,-37.452961,0.020863,0.000467,0.011855,39.562984,2.015435,0.118550,-37.452961,0.012713,0.000000
16.010000,9.210258,-37.408482,0.020881,0.000476,0.012080,40.969276,2.087075,0.120799,-37.408482,0.012965,0.000000
16.160000,9.508904,-37.452961,0.020894,0.000485,0.012315,42.297714,2.154748,0.123145,-37.452961,0.013216,0.000000
16.310001,9.708122,-37.452961,0.020919,0.000492,0.012496,43.183884,2.199892,0.124962,-37.452961,0.013459,0.000000
16.460001,9.847015,-37.452961,0.020902,0.000498,0.012661,43.801712,2.231365,0.126612,-37.452961,0.013710,0.000000
16.610001,10.234283,-37.408482,0.020928,0.000509,0.012939,45.524368,2.319122,0.129390,-37.408482,0.013962,0.000000
16.760000,10.736610,-37.497440,0.020932,0.000521,0.013234,47.758827,2.432951,0.132335,-37.497440,0.014214,0.000000
16.910002,11.067284,-37.452961,0.020928,0.000532,0.013511,49.229736,2.507882,0.135113,-37.452961,0.014465,0.000000
17.060001,11.362198,-37.497440,0.020932,0.000541,0.013745,50.541580,2.574711,0.137452,-37.497440,0.014716,0.000000
17.210001,11.721542,-37.497440,0.020958,0.000550,0.013962,52.140026,2.656139,0.139617,-37.497440,0.014959,0.000000
17.360001,12.027626,-37.497440,0.020954,0.000561,0.014240,53.501553,2.725499,0.142395,-37.497440,0.015211,0.000000
17.510000,12.494209,-37.497440,0.020967,0.000571,0.014491,55.577019,2.831228,0.144908,-37.497440,0.015462,0.000000
17.660002,12.683380,-37.541924,0.020954,0.000578,0.014691,56.418491,2.874095,0.146907,-37.541924,0.015714,0.000000
17.810001,13.082558,-37.497440,0.020976,0.000589,0.014950,58.194122,2.964550,0.149503,-37.497440,0.015965,0.000000
17.960001,13.543930,-37.408482,0.020988,0.000601,0.015263,60.246410,3.069098,0.152630,-37.408482,0.016217,0.000000
18.110001,13.855232,-37.452961,0.021006,0.000605,0.015367,61.631149,3.139641,0.153667,-37.452961,0.016460,0.000000
18.260000,13.787834,-37.497440,0.021006,0.000608,0.015454,61.331348,3.124368,0.154537,-37.497440,0.016711,0.000000
18.410002,14.727699,-37.452961,0.021006,0.000624,0.015861,65.512077,3.337344,0.158610,-37.452961,0.016962,0.000000
18.560001,15.371536,-37.541924,0.020997,0.000640,0.016252,68.376007,3.483240,0.162516,-37.541924,0.017214,0.000000
18.710001,15.819496,-37.452961,0.021023,0.000649,0.016495,70.368637,3.584749,0.164946,-37.452961,0.017466,0.000000
18.860001,16.083511,-37.541924,0.021040,0.000658,0.016703,71.543030,3.644576,0.167027,-37.541924,0.017717,0.000000
19.010000,16.786919,-37.497440,0.021053,0.000670,0.017024,74.671944,3.803970,0.170237,-37.497440,0.017960,0.000000
19.160002,17.008484,-37.541924,0.021053,0.000678,0.017232,75.657516,3.854178,0.172319,-37.541924,0.018211,0.000000
19.310001,17.481400,-37.497440,0.021057,0.000688,0.017474,77.761147,3.961342,0.174741,-37.497440,0.018463,0.000000
19.460001,18.083893,-37.497440,0.021057,0.000699,0.017752,80.441170,4.097869,0.177519,-37.497440,0.018715,0.000000
19.610001,18.530739,-37.541924,0.021066,0.000707,0.017968,82.428841,4.199125,0.179684,-37.541924,0.018966,0.000000
19.760000,18.674850,-37.497440,0.021062,0.000712,0.018073,83.069885,4.231781,0.180729,-37.497440,0.019217,0.000000
19.910002,19.450874,-37.586403,0.021096,0.000727,0.018463,86.521812,4.407631,0.184627,-37.586403,0.019460,0.000000
20.060001,20.050392,-37.586403,0.021075,0.000737,0.018723,89.188599,4.543484,0.187231,-37.586403,0.019712,0.000000
20.210001,20.446228,-37.541924,0.021088,0.000744,0.018896,90.949364,4.633182,0.188965,-37.541924,0.019963,0.000000
20.360001,20.718056,-37.541924,0.021092,0.000752,0.019105,92.158516,4.694778,0.191046,-37.541924,0.020215,0.000000
20.510000,21.622177,-37.541924,0.021088,0.000767,0.019478,96.180244,4.899655,0.194778,-37.541924,0.020466,0.000000
20.660002,22.186325,-37.452961,0.021101,0.000777,0.019747,98.689705,5.027493,0.197466,-37.452961,0.020709,0.000000
20.810001,22.943726,-37.541924,0.021122,0.000789,0.020041,102.058792,5.199122,0.200410,-37.541924,0.020961,0.000000
20.960001,23.486649,-37.586403,0.021113,0.000797,0.020249,104.473831,5.322151,0.202492,-37.586403,0.021212,0.000000
21.110001,23.721245,-37.586403,0.021126,0.000804,0.020414,105.517365,5.375311,0.204142,-37.586403,0.021463,0.000000
21.260000,24.343475,-37.586403,0.021139,0.000813,0.020648,108.285187,5.516310,0.206481,-37.586403,0.021715,0.000000
21.410002,24.705795,-37.586403,0.021122,0.000821,0.020856,109.896866,5.598413,0.208563,-37.586403,0.021967,0.000000
21.560001,25.228607,-37.586403,0.021148,0.000831,0.021108,112.222450,5.716884,0.211084,-37.586403,0.022209,0.000000
21.710001,25.783440,-37.541924,0.021148,0.000838,0.021273,114.690468,5.842611,0.212726,-37.541924,0.022461,0.000000
21.860001,26.679741,-37.586403,0.021152,0.000853,0.021663,118.677414,6.045716,0.216632,-37.586403,0.022712,0.000000
22.010000,27.559288,-37.586403,0.021178,0.000864,0.021949,122.589836,6.245024,0.219494,-37.586403,0.022964,0.000000
22.160002,28.123428,-37.541924,0.021170,0.000874,0.022209,125.099258,6.372860,0.222090,-37.541924,0.023215,0.000000
22.310001,28.549049,-37.586403,0.021178,0.000881,0.022366,126.992516,6.469307,0.223657,-37.586403,0.023467,0.000000
22.460001,29.032761,-37.630886,0.021187,0.000889,0.022591,129.144165,6.578918,0.225913,-37.630886,0.023709,0.000000
22.610001,29.479607,-37.541924,0.021182,0.000898,0.022816,131.131836,6.680174,0.228161,-37.541924,0.023961,0.000000
22.760000,30.340904,-37.630886,0.021187,0.000911,0.023129,134.963089,6.875348,0.231287,-37.630886,0.024213,0.000000
22.910002,31.537712,-37.586403,0.021200,0.000925,0.023501,140.286743,7.146548,0.235012,-37.586403,0.024464,0.000000
23.060001,31.972641,-37.630886,0.021195,0.000932,0.023675,142.221405,7.245104,0.236753,-37.630886,0.024715,0.000000
23.210001,32.433266,-37.586403,0.021208,0.000940,0.023883,144.270370,7.349483,0.238834,-37.586403,0.024967,0.000000
23.360001,33.067787,-37.630886,0.021226,0.000950,0.024117,147.092865,7.493268,0.241174,-37.630886,0.025210,0.000000
23.510000,33.778275,-37.630886,0.021213,0.000960,0.024378,150.253265,7.654266,0.243778,-37.630886,0.025462,0.000000
23.660002,34.144318,-37.630886,0.021208,0.000966,0.024525,151.881516,7.737213,0.245246,-37.630886,0.025713,0.000000
23.810001,35.195900,-37.675365,0.021226,0.000982,0.024933,156.559189,7.975505,0.249326,-37.675365,0.025964,0.000000
23.960001,36.095924,-37.675365,0.021239,0.000994,0.025244,160.562683,8.179453,0.252445,-37.675365,0.026216,0.000000
24.110001,36.885727,-37.630886,0.021226,0.001003,0.025479,164.075912,8.358425,0.254792,-37.630886,0.026468,0.000000
24.260000,37.144897,-37.630886,0.021247,0.001010,0.025643,165.228760,8.417153,0.256434,-37.630886,0.026710,0.000000
24.410002,37.958160,-37.586403,0.021251,0.001018,0.025869,168.846329,8.601441,0.258690,-37.586403,0.026962,0.000000
24.560001,38.417664,-37.675365,0.021256,0.001026,0.026051,170.890305,8.705566,0.260514,-37.675365,0.027213,0.000000
24.710001,39.540367,-37.675365,0.021260,0.001042,0.026459,175.884338,8.959975,0.264587,-37.675365,0.027465,0.000000
24.860001,40.311180,-37.675365,0.021260,0.001054,0.026771,179.313080,9.134645,0.267713,-37.675365,0.027716,0.000000
25.010002,40.958733,-37.630886,0.021264,0.001062,0.026979,182.193542,9.281382,0.269795,-37.630886,0.027968,0.000000
25.160002,41.434624,-37.630886,0.021277,0.001069,0.027161,184.310410,9.389220,0.271612,-37.630886,0.028210,0.000000
25.310001,42.297417,-37.675365,0.021264,0.001080,0.027422,188.148300,9.584732,0.274216,-37.675365,0.028462,0.000000
25.460001,43.213081,-37.719845,0.021273,0.001093,0.027751,192.221390,9.792225,0.277508,-37.719845,0.028714,0.000000
25.610001,43.446182,-37.719845,0.021295,0.001096,0.027829,193.258270,9.845045,0.278288,-37.719845,0.028965,0.000000
25.760002,43.624176,-37.630886,0.021299,0.001101,0.027959,194.050034,9.885380,0.279590,-37.630886,0.029216,0.000000
25.910002,44.467972,-37.675365,0.021308,0.001110,0.028193,197.803421,10.076587,0.281929,-37.675365,0.029468,0.000000
26.060001,45.244370,-37.675365,0.021312,0.001121,0.028462,201.257004,10.252521,0.284624,-37.675365,0.029711,0.000000
26.210001,45.409332,-37.719845,0.021308,0.001126,0.028601,201.990799,10.289902,0.286009,-37.719845,0.029963,0.000000
26.360001,46.659386,-37.719845,0.021303,0.001141,0.028973,207.551315,10.573168,0.289734,-37.719845,0.030214,0.000000
26.510002,47.473022,-37.719845,0.021316,0.001154,0.029321,211.170547,10.757541,0.293208,-37.719845,0.030465,0.000000
26.660002,48.443047,-37.675365,0.021299,0.001162,0.029512,215.485428,10.977351,0.295116,-37.675365,0.030717,0.000000
26.810001,49.477127,-37.675365,0.021312,0.001176,0.029867,220.085251,11.211677,0.298666,-37.675365,0.030960,0.000000
26.960001,50.150375,-37.719845,0.021325,0.001186,0.030119,223.080017,11.364238,0.301187,-37.719845,0.031211,0.000000
27.110001,50.911133,-37.719845,0.021329,0.001198,0.030431,226.464035,11.536628,0.304306,-37.719845,0.031462,0.000000
27.260002,51.739662,-37.675365,0.021329,0.001207,0.030648,230.149506,11.724375,0.306478,-37.675365,0.031714,0.000000
27.410002,52.356308,-37.719845,0.021342,0.001214,0.030829,232.892487,11.864109,0.308295,-37.719845,0.031966,0.000000
27.560001,52.797203,-37.764328,0.021346,0.001220,0.030995,234.853683,11.964018,0.309945,-37.764328,0.032217,0.000000
27.710001,53.689774,-37.675365,0.021351,0.001230,0.031246,238.824036,12.166277,0.312458,-37.675365,0.032460,0.000000
27.860001,54.463196,-37.675365,0.021346,0.001241,0.031524,242.264389,12.341537,0.315236,-37.675365,0.032711,0.000000
28.010002,55.396736,-37.719845,0.021355,0.001252,0.031810,246.416992,12.553080,0.318098,-37.719845,0.032963,0.000000
28.160002,55.980988,-37.719845,0.021346,0.001259,0.031983,249.015869,12.685472,0.319831,-37.719845,0.033215,0.000000
28.310001,56.722748,-37.808807,0.021355,0.001274,0.032347,252.315384,12.853559,0.323472,-37.808807,0.033466,0.000000
28.460001,57.930351,-37.808807,0.021368,0.001283,0.032590,257.687073,13.127206,0.325902,-37.808807,0.033717,0.000000
28.610001,58.909691,-37.719845,0.021359,0.001294,0.032876,262.043396,13.349127,0.328764,-37.719845,0.033960,0.000000
28.760002,59.229935,-37.808807,0.021372,0.001299,0.032997,263.467896,13.421695,0.329975,-37.808807,0.034212,0.000000
28.910002,60.126236,-37.764328,0.021377,0.001310,0.033275,267.454865,13.624800,0.332753,-37.764328,0.034463,0.000000
29.060001,60.687027,-37.719845,0.021381,0.001319,0.033509,269.949371,13.751877,0.335092,-37.719845,0.034715,0.000000
29.210001,61.850693,-37.764328,0.021398,0.001332,0.033830,275.125610,14.015568,0.338301,-37.764328,0.034966,0.000000
29.360001,62.789070,-37.719845,0.021389,0.001342,0.034091,279.299744,14.228207,0.340905,-37.719845,0.035218,0.000000
29.510002,63.280975,-37.764328,0.021411,0.001348,0.034229,281.487823,14.339674,0.342291,-37.764328,0.035461,0.000000
29.660002,64.274094,-37.764328,0.021415,0.001361,0.034558,285.905457,14.564717,0.345584,-37.764328,0.035712,0.000000
29.810001,65.219543,-37.808807,0.021411,0.001372,0.034836,290.111023,14.778960,0.348362,-37.808807,0.035963,0.000000
29.960001,66.057755,-37.808807,0.021407,0.001380,0.035044,293.839569,14.968902,0.350443,-37.808807,0.036215,0.000000
30.110001,66.583542,-37.764328,0.021424,0.001390,0.035296,296.178375,15.088047,0.352957,-37.764328,0.036467,0.000000
30.260002,67.380798,-37.764328,0.021424,0.001387,0.035218,299.724762,15.268707,0.352177,-37.764328,0.035478,0.000000
30.410002,67.197586,-37.764328,0.021437,0.001387,0.035218,298.909790,15.227190,0.352177,-37.764328,0.035478,0.000000
30.560001,67.043427,-37.719845,0.021420,0.001387,0.035218,298.224060,15.192258,0.352177,-37.719845,0.035478,0.000000
30.710001,66.925751,-37.808807,0.021458,0.001384,0.035165,297.700623,15.165591,0.351655,-37.808807,0.035218,0.000000
30.860001,66.809204,-37.808807,0.021424,0.001383,0.035140,297.182190,15.139182,0.351397,-37.808807,0.035218,0.000000
31.010002,66.703445,-37.853291,0.021445,0.001383,0.035131,296.711731,15.115216,0.351314,-37.853291,0.035218,0.000000
31.160002,66.611847,-37.808807,0.021441,0.001383,0.035122,296.304291,15.094460,0.351223,-37.808807,0.035218,0.000000
31.310001,66.535141,-37.808807,0.021424,0.001383,0.035122,295.963074,15.077079,0.351223,-37.808807,0.035218,0.000000
31.460001,66.446136,-37.808807,0.021441,0.001382,0.035114,295.567169,15.056910,0.351140,-37.808807,0.035218,0.000000
31.610001,66.357895,-37.808807,0.021445,0.001382,0.035105,295.174652,15.036914,0.351049,-37.808807,0.035218,0.000000
31.760002,66.294220,-37.764328,0.021441,0.001382,0.035105,294.891418,15.022485,0.351049,-37.764328,0.035218,0.000000
31.910002,66.225327,-37.764328,0.021441,0.001382,0.035105,294.584961,15.006874,0.351049,-37.764328,0.035218,0.000000
32.060001,66.166489,-37.853291,0.021428,0.001382,0.035105,294.323242,14.993540,0.351049,-37.853291,0.035218,0.000000
32.210003,66.107285,-37.808807,0.021424,0.001382,0.035097,294.059875,14.980125,0.350966,-37.808807,0.035218,0.000000
32.360001,66.054398,-37.808807,0.021450,0.001382,0.035097,293.824646,14.968141,0.350966,-37.808807,0.035218,0.000000
32.510002,65.999664,-37.853291,0.021445,0.001382,0.035097,293.581177,14.955738,0.350966,-37.853291,0.035218,0.000000
32.660000,65.938217,-37.764328,0.021437,0.001382,0.035097,293.307831,14.941813,0.350966,-37.764328,0.035218,0.000000
32.810001,65.877899,-37.808807,0.021437,0.001382,0.035097,293.039520,14.928145,0.350966,-37.808807,0.035218,0.000000
32.960003,65.836197,-37.808807,0.021450,0.001382,0.035097,292.854034,14.918696,0.350966,-37.808807,0.035218,0.000000
33.110001,65.801941,-37.853291,0.021445,0.001382,0.035097,292.701660,14.910933,0.350966,-37.853291,0.035218,0.000000
33.260002,65.767685,-37.897770,0.021450,0.001382,0.035097,292.549286,14.903171,0.350966,-37.897770,0.035218,0.000000
33.410000,65.718903,-37.853291,0.021441,0.001382,0.035097,292.332275,14.892117,0.350966,-37.853291,0.035218,0.000000
33.560001,65.671600,-37.853291,0.021454,0.001382,0.035097,292.121857,14.881397,0.350966,-37.853291,0.035218,0.000000
33.710003,65.623566,-37.853291,0.021441,0.001382,0.035097,291.908203,14.870512,0.350966,-37.853291,0.035218,0.000000
33.860001,65.585220,-37.942253,0.021450,0.001382,0.035097,291.737640,14.861823,0.350966,-37.942253,0.035218,0.000000
34.010002,65.550217,-37.897770,0.021441,0.001381,0.035087,291.581940,14.853891,0.350875,-37.897770,0.035218,0.000000
34.160000,65.513351,-37.897770,0.021454,0.001381,0.035087,291.417938,14.845537,0.350875,-37.897770,0.035218,0.000000
34.310001,65.482071,-37.897770,0.021441,0.001381,0.035087,291.278809,14.838449,0.350875,-37.897770,0.035218,0.000000
34.460003,65.466797,-37.897770,0.021463,0.001381,0.035087,291.210846,14.834989,0.350875,-37.897770,0.035218,0.000000
34.610001,65.421371,-37.897770,0.021445,0.001381,0.035087,291.008789,14.824695,0.350875,-37.897770,0.035218,0.000000
34.760002,65.374084,-37.897770,0.021428,0.001381,0.035087,290.798462,14.813979,0.350875,-37.897770,0.035218,0.000000
34.910000,65.357330,-37.897770,0.021454,0.001381,0.035087,290.723938,14.810183,0.350875,-37.897770,0.035218,0.000000
35.060001,65.329025,-37.897770,0.021467,0.001381,0.035087,290.598022,14.803769,0.350875,-37.897770,0.035218,0.000000
35.210003,65.300720,-37.942253,0.021450,0.001381,0.035087,290.472107,14.797355,0.350875,-37.942253,0.035218,0.000000
35.360001,65.267578,-37.853291,0.021450,0.001381,0.035087,290.324677,14.789845,0.350875,-37.853291,0.035218,0.000000
35.510002,65.243011,-37.986732,0.021454,0.001381,0.035087,290.215424,14.784278,0.350875,-37.986732,0.035218,0.000000
35.660000,65.213211,-37.897770,0.021445,0.001381,0.035087,290.082855,14.777525,0.350875,-37.897770,0.035218,0.000000
35.810001,65.183060,-37.853291,0.021441,0.001381,0.035087,289.948730,14.770692,0.350875,-37.853291,0.035218,0.000000
35.960003,65.165176,-37.986732,0.021450,0.001381,0.035087,289.869171,14.766640,0.350875,-37.986732,0.035218,0.000000
36.110001,65.133148,-37.897770,0.021437,0.001381,0.035087,289.726715,14.759382,0.350875,-37.897770,0.035218,0.000000
36.260002,65.106339,-37.897770,0.021437,0.001381,0.035087,289.607452,14.753307,0.350875,-37.897770,0.035218,0.000000
36.410000,65.088104,-37.897770,0.021428,0.001381,0.035087,289.526337,14.749176,0.350875,-37.897770,0.035218,0.000000
36.560001,65.062775,-37.986732,0.021441,0.001381,0.035087,289.413666,14.743436,0.350875,-37.986732,0.035218,0.000000
36.710003,65.039322,-37.942253,0.021454,0.001381,0.035087,289.309357,14.738121,0.350875,-37.942253,0.035218,0.000000
36.860001,65.012131,-37.942253,0.021450,0.001381,0.035087,289.188416,14.731959,0.350875,-37.942253,0.035218,0.000000
37.010002,64.992401,-37.942253,0.021454,0.001381,0.035087,289.100647,14.727489,0.350875,-37.942253,0.035218,0.000000
37.160004,64.968933,-37.986732,0.021450,0.001381,0.035087,288.996246,14.722170,0.350875,-37.986732,0.035218,0.000000
37.310001,64.948837,-37.897770,0.021445,0.001381,0.035087,288.906860,14.717617,0.350875,-37.897770,0.035218,0.000000
37.460003,64.920532,-38.031212,0.021441,0.001381,0.035087,288.780945,14.711203,0.350875,-38.031212,0.035218,0.000000
37.610001,64.901169,-37.986732,0.021433,0.001381,0.035087,288.694824,14.706815,0.350875,-37.986732,0.035218,0.000000
37.760002,64.874359,-37.986732,0.021454,0.001381,0.035087,288.575562,14.700740,0.350875,-37.986732,0.035218,0.000000
37.910004,64.857224,-37.986732,0.021458,0.001381,0.035087,288.499329,14.696856,0.350875,-37.986732,0.035218,0.000000
38.060001,64.844193,-37.986732,0.021441,0.001381,0.035087,288.441376,14.693904,0.350875,-37.986732,0.035218,0.000000
38.210003,64.838608,-37.986732,0.021441,0.001381,0.035087,288.416534,14.692639,0.350875,-37.986732,0.035218,0.000000
38.360001,64.811432,-37.986732,0.021445,0.001381,0.035087,288.295654,14.686480,0.350875,-37.986732,0.035218,0.000000
38.510002,64.774933,-37.986732,0.021450,0.001381,0.035087,288.133301,14.678209,0.350875,-37.986732,0.035218,0.000000
38.660004,64.756317,-37.986732,0.021437,0.001381,0.035087,288.050476,14.673991,0.350875,-37.986732,0.035218,0.000000
38.810001,64.741791,-38.075695,0.021441,0.001381,0.035087,287.985870,14.670699,0.350875,-38.075695,0.035218,0.000000
38.960003,64.723175,-37.986732,0.021428,0.001381,0.035087,287.903076,14.666481,0.350875,-37.986732,0.035218,0.000000
39.110001,64.727264,-38.031212,0.021463,0.001381,0.035087,287.921265,14.667407,0.350875,-38.031212,0.035218,0.000000
39.260002,64.706787,-38.031212,0.021441,0.001381,0.035087,287.830170,14.662767,0.350875,-38.031212,0.035218,0.000000
39.410004,64.684814,-37.986732,0.021437,0.001381,0.035079,287.732422,14.657789,0.350792,-37.986732,0.035218,0.000000
39.560001,64.665833,-38.031212,0.021450,0.001381,0.035079,287.647980,14.653487,0.350792,-38.031212,0.035218,0.000000
39.710003,64.630081,-37.986732,0.021458,0.001381,0.035079,287.488953,14.645386,0.350792,-37.986732,0.035218,0.000000
39.860001,64.617798,-37.986732,0.021450,0.001381,0.035079,287.434326,14.642602,0.350792,-37.986732,0.035218,0.000000
40.010002,64.608856,-37.942253,0.021463,0.001381,0.035079,287.394531,14.640576,0.350792,-37.942253,0.035218,0.000000
40.160004,64.587997,-37.986732,0.021441,0.001381,0.035079,287.301758,14.635849,0.350792,-37.986732,0.035218,0.000000
40.310001,64.592850,-38.031212,0.021437,0.001381,0.035079,287.323334,14.636950,0.350792,-38.031212,0.035218,0.000000
40.460003,64.569382,-38.031212,0.021450,0.001381,0.035079,287.218964,14.631631,0.350792,-38.031212,0.035218,0.000000
40.610001,64.552994,-38.075695,0.021445,0.001381,0.035079,287.146057,14.627917,0.350792,-38.075695,0.035218,0.000000
40.760002,64.526184,-38.075695,0.021450,0.001381,0.035079,287.026794,14.621842,0.350792,-38.075695,0.035218,0.000000
40.910004,64.512405,-38.031212,0.021450,0.001381,0.035079,286.965515,14.618720,0.350792,-38.031212,0.035218,0.000000
41.060001,64.492676,-38.031212,0.021445,0.001381,0.035079,286.877747,14.614249,0.350792,-38.031212,0.035218,0.000000
41.210003,64.487457,-38.075695,0.021441,0.001381,0.035079,286.854523,14.613067,0.350792,-38.075695,0.035218,0.000000
41.360001,64.475174,-38.120174,0.021454,0.001381,0.035079,286.799896,14.610283,0.350792,-38.120174,0.035218,0.000000
41.510002,64.449112,-38.031212,0.021463,0.001381,0.035079,286.683960,14.604378,0.350792,-38.031212,0.035218,0.000000
41.660004,64.446869,-38.031212,0.021441,0.001381,0.035079,286.673981,14.603869,0.350792,-38.031212,0.035218,0.000000
41.810001,64.421921,-38.075695,0.021463,0.001381,0.035079,286.563019,14.598216,0.350792,-38.075695,0.035218,0.000000
41.960003,64.416336,-38.031212,0.021445,0.001381,0.035079,286.538177,14.596951,0.350792,-38.031212,0.035218,0.000000
42.110001,64.401443,-38.075695,0.021454,0.001381,0.035079,286.471924,14.593575,0.350792,-38.075695,0.035218,0.000000
42.260002,64.398834,-38.031212,0.021450,0.001381,0.035079,286.460327,14.592984,0.350792,-38.031212,0.035218,0.000000
42.410004,64.372772,-38.075695,0.021450,0.001381,0.035079,286.344391,14.587079,0.350792,-38.075695,0.035218,0.000000
42.560001,64.363083,-38.120174,0.021458,0.001381,0.035079,286.301300,14.584883,0.350792,-38.120174,0.035218,0.000000
42.710003,64.353775,-38.120174,0.021441,0.001381,0.035079,286.259888,14.582774,0.350792,-38.120174,0.035218,0.000000
42.860001,64.344467,-38.031212,0.021441,0.001381,0.035079,286.218475,14.580665,0.350792,-38.031212,0.035218,0.000000
43.010002,64.325485,-38.075695,0.021445,0.001381,0.035079,286.134064,14.576364,0.350792,-38.075695,0.035218,0.000000
43.160004,64.327713,-38.075695,0.021467,0.001381,0.035079,286.143951,14.576868,0.350792,-38.075695,0.035218,0.000000
43.310001,64.304626,-38.120174,0.021450,0.001381,0.035079,286.041260,14.571636,0.350792,-38.120174,0.035218,0.000000
43.460003,64.288239,-38.120174,0.021450,0.001381,0.035079,285.968353,14.567924,0.350792,-38.120174,0.035218,0.000000
43.610001,64.261429,-38.120174,0.021450,0.001381,0.035079,285.849121,14.561848,0.350792,-38.120174,0.035218,0.000000
43.760002,64.257706,-38.164658,0.021433,0.001381,0.035079,285.832550,14.561004,0.350792,-38.164658,0.035218,0.000000
43.910004,64.247650,-38.120174,0.021458,0.001381,0.035079,285.787811,14.558726,0.350792,-38.120174,0.035218,0.000000
44.060001,64.245422,-38.120174,0.021450,0.001381,0.035079,285.777924,14.558221,0.350792,-38.120174,0.035218,0.000000
44.210003,64.232010,-38.120174,0.021454,0.001381,0.035079,285.718262,14.555182,0.350792,-38.120174,0.035218,0.000000
44.360001,64.224564,-38.120174,0.021463,0.001381,0.035079,285.685120,14.553494,0.350792,-38.120174,0.035218,0.000000
44.510002,64.198502,-38.120174,0.021454,0.001381,0.035079,285.569183,14.547588,0.350792,-38.120174,0.035218,0.000000
44.660004,64.183975,-38.120174,0.021458,0.001381,0.035079,285.504578,14.544297,0.350792,-38.120174,0.035218,0.000000
44.810001,64.169083,-38.164658,0.021441,0.001381,0.035079,285.438324,14.540922,0.350792,-38.164658,0.035218,0.000000
44.960003,64.169083,-38.164658,0.021471,0.001381,0.035079,285.438324,14.540922,0.350792,-38.164658,0.035218,0.000000
45.110001,64.159027,-38.164658,0.021450,0.001381,0.035079,285.393616,14.538644,0.350792,-38.164658,0.035218,0.000000
45.260002,64.158279,-38.164658,0.021450,0.001381,0.035079,285.390289,14.538474,0.350792,-38.164658,0.035218,0.000000
45.410004,64.148972,-38.209137,0.021433,0.001381,0.035079,285.348877,14.536366,0.350792,-38.209137,0.035218,0.000000
45.560001,64.129608,-38.209137,0.021471,0.001381,0.035079,285.262756,14.531977,0.350792,-38.209137,0.035218,0.000000
45.710003,64.118073,-38.209137,0.021450,0.001381,0.035079,285.211426,14.529363,0.350792,-38.209137,0.035218,0.000000
45.860001,64.104660,-38.120174,0.021463,0.001381,0.035079,285.151764,14.526323,0.350792,-38.120174,0.035218,0.000000
46.010002,64.097961,-38.164658,0.021454,0.001381,0.035079,285.121979,14.524805,0.350792,-38.164658,0.035218,0.000000
46.160004,64.100571,-38.209137,0.021454,0.001381,0.035079,285.133575,14.525397,0.350792,-38.209137,0.035218,0.000000
46.310001,64.079712,-38.120174,0.021463,0.001381,0.035079,285.040802,14.520670,0.350792,-38.120174,0.035218,0.000000
46.460003,64.081955,-38.120174,0.021445,0.001381,0.035079,285.050781,14.521178,0.350792,-38.120174,0.035218,0.000000
46.610001,64.073380,-38.253616,0.021454,0.001381,0.035079,285.012634,14.519235,0.350792,-38.253616,0.035218,0.000000
46.760002,64.041367,-38.209137,0.021454,0.001381,0.035079,284.870239,14.511981,0.350792,-38.209137,0.035218,0.000000
46.910004,64.030930,-38.164658,0.021454,0.001381,0.035079,284.823792,14.509617,0.350792,-38.164658,0.035218,0.000000
47.060001,64.031311,-38.209137,0.021471,0.001381,0.035079,284.825500,14.509703,0.350792,-38.209137,0.035218,0.000000
47.210003,64.012680,-38.164658,0.021441,0.001381,0.035079,284.742615,14.505481,0.350792,-38.164658,0.035218,0.000000
47.360001,64.006729,-38.164658,0.021437,0.001381,0.035079,284.716156,14.504132,0.350792,-38.164658,0.035218,0.000000
47.510002,63.996674,-38.164658,0.021454,0.001381,0.035079,284.671417,14.501853,0.350792,-38.164658,0.035218,0.000000
47.660004,63.987000,-38.209137,0.021445,0.001381,0.035079,284.628387,14.499661,0.350792,-38.209137,0.035218,0.000000
47.810001,63.978058,-38.164658,0.021450,0.001381,0.035079,284.588623,14.497636,0.350792,-38.164658,0.035218,0.000000
47.960003,63.969116,-38.164658,0.021471,0.001381,0.035079,284.548828,14.495609,0.350792,-38.164658,0.035218,0.000000
48.110001,63.959442,-38.209137,0.021445,0.001381,0.035079,284.505798,14.493417,0.350792,-38.209137,0.035218,0.000000
48.260002,63.951996,-38.209137,0.021471,0.001381,0.035079,284.472687,14.491729,0.350792,-38.209137,0.035218,0.000000
48.410004,63.933365,-38.209137,0.021463,0.001381,0.035079,284.389801,14.487508,0.350792,-38.209137,0.035218,0.000000
48.560001,63.925552,-38.253616,0.021437,0.001381,0.035079,284.355072,14.485738,0.350792,-38.253616,0.035218,0.000000
48.710003,63.918854,-38.298100,0.021454,0.001381,0.035079,284.325256,14.484220,0.350792,-38.298100,0.035218,0.000000
48.860001,63.907684,-38.298100,0.021458,0.001381,0.035079,284.275574,14.481688,0.350792,-38.298100,0.035218,0.000000
49.010002,63.910660,-38.253616,0.021441,0.001381,0.035079,284.288818,14.482363,0.350792,-38.253616,0.035218,0.000000
49.160004,63.903214,-38.253616,0.021450,0.001381,0.035079,284.255676,14.480675,0.350792,-38.253616,0.035218,0.000000
49.310001,63.890182,-38.253616,0.021467,0.001381,0.035079,284.197723,14.477722,0.350792,-38.253616,0.035218,0.000000
49.460003,63.873413,-38.209137,0.021458,0.001381,0.035079,284.123138,14.473922,0.350792,-38.209137,0.035218,0.000000
49.610001,63.861496,-38.253616,0.021476,0.001381,0.035079,284.070129,14.471222,0.350792,-38.253616,0.035218,0.000000
49.760002,63.859268,-38.298100,0.021463,0.001381,0.035079,284.060211,14.470717,0.350792,-38.298100,0.035218,0.000000
49.910004,63.868958,-38.253616,0.021458,0.001381,0.035079,284.103302,14.472912,0.350792,-38.253616,0.035218,0.000000
50.060001,63.865601,-38.253616,0.021454,0.001381,0.035079,284.088379,14.472152,0.350792,-38.253616,0.035218,0.000000
50.210003,63.853683,-38.342579,0.021454,0.001381,0.035079,284.035370,14.469452,0.350792,-38.342579,0.035218,0.000000
50.360001,63.835068,-38.253616,0.021454,0.001381,0.035079,283.952576,14.465233,0.350792,-38.253616,0.035218,0.000000
50.510002,63.816071,-38.253616,0.021458,0.001381,0.035079,283.868073,14.460928,0.350792,-38.253616,0.035218,0.000000
50.660004,63.804901,-38.298100,0.021450,0.001381,0.035079,283.818390,14.458397,0.350792,-38.298100,0.035218,0.000000
50.810001,63.797455,-38.253616,0.021441,0.001381,0.035079,283.785248,14.456710,0.350792,-38.253616,0.035218,0.000000
50.960003,63.807144,-38.298100,0.021463,0.001381,0.035079,283.828339,14.458905,0.350792,-38.298100,0.035218,0.000000
51.110001,63.802673,-38.298100,0.021445,0.001381,0.035079,283.808472,14.457892,0.350792,-38.298100,0.035218,0.000000
51.260002,63.799316,-38.298100,0.021471,0.001381,0.035079,283.793518,14.457131,0.350792,-38.298100,0.035218,0.000000
51.410004,63.776978,-38.298100,0.021458,0.001381,0.035079,283.694153,14.452070,0.350792,-38.298100,0.035218,0.000000
51.560001,63.762451,-38.253616,0.021445,0.001381,0.035079,283.629547,14.448778,0.350792,-38.253616,0.035218,0.000000
51.710003,63.752396,-38.298100,0.021450,0.001381,0.035079,283.584808,14.446500,0.350792,-38.298100,0.035218,0.000000
51.860001,63.744202,-38.298100,0.021458,0.001381,0.035079,283.548370,14.444642,0.350792,-38.298100,0.035218,0.000000
52.010002,63.752029,-38.253616,0.021445,0.001381,0.035079,283.583191,14.446416,0.350792,-38.253616,0.035218,0.000000
52.160004,63.737137,-38.298100,0.021450,0.001381,0.035079,283.516937,14.443042,0.350792,-38.298100,0.035218,0.000000
52.310001,63.738617,-38.298100,0.021458,0.001381,0.035079,283.523529,14.443377,0.350792,-38.298100,0.035218,0.000000
52.460003,63.728561,-38.298100,0.021471,0.001381,0.035079,283.478790,14.441098,0.350792,-38.298100,0.035218,0.000000
52.610001,63.716278,-38.298100,0.021476,0.001381,0.035079,283.424164,14.438315,0.350792,-38.298100,0.035218,0.000000
52.760002,63.708832,-38.342579,0.021458,0.001381,0.035079,283.391052,14.436627,0.350792,-38.342579,0.035218,0.000000
52.910004,63.700638,-38.342579,0.021454,0.001381,0.035079,283.354584,14.434772,0.350792,-38.342579,0.035218,0.000000
53.060001,63.691696,-38.298100,0.021450,0.001381,0.035079,283.314819,14.432745,0.350792,-38.298100,0.035218,0.000000
53.210003,63.682770,-38.342579,0.021454,0.001381,0.035079,283.275116,14.430722,0.350792,-38.342579,0.035218,0.000000
53.360004,63.674942,-38.253616,0.021445,0.001381,0.035079,283.240295,14.428948,0.350792,-38.253616,0.035218,0.000000
53.510002,63.667130,-38.342579,0.021450,0.001381,0.035079,283.205536,14.427178,0.350792,-38.342579,0.035218,0.000000
53.660004,63.668243,-38.342579,0.021445,0.001381,0.035079,283.210480,14.427430,0.350792,-38.342579,0.035218,0.000000
53.810001,63.667130,-38.342579,0.021458,0.001381,0.035079,283.205536,14.427178,0.350792,-38.342579,0.035218,0.000000
53.960003,63.655579,-38.298100,0.021445,0.001381,0.035079,283.154144,14.424560,0.350792,-38.298100,0.035218,0.000000
54.110004,63.640320,-38.342579,0.021458,0.001381,0.035079,283.086273,14.421103,0.350792,-38.342579,0.035218,0.000000
54.260002,63.640320,-38.342579,0.021433,0.001381,0.035079,283.086273,14.421103,0.350792,-38.342579,0.035218,0.000000
54.410004,63.627274,-38.342579,0.021463,0.001381,0.035079,283.028259,14.418146,0.350792,-38.342579,0.035218,0.000000
54.560001,63.620575,-38.342579,0.021445,0.001381,0.035070,282.998444,14.416628,0.350701,-38.342579,0.035218,0.000000
54.710003,63.619827,-38.342579,0.021454,0.001381,0.035070,282.995117,14.416459,0.350701,-38.342579,0.035218,0.000000
54.860004,63.617233,-38.387062,0.021454,0.001381,0.035070,282.983582,14.415871,0.350701,-38.387062,0.035218,0.000000
55.010002,63.614624,-38.387062,0.021454,0.001381,0.035070,282.971985,14.415279,0.350701,-38.387062,0.035218,0.000000
55.160004,63.599731,-38.342579,0.021454,0.001381,0.035070,282.905731,14.411905,0.350701,-38.342579,0.035218,0.000000
55.310001,63.594879,-38.431541,0.021450,0.001381,0.035070,282.884155,14.410805,0.350701,-38.431541,0.035218,0.000000
55.460003,63.575516,-38.342579,0.021445,0.001381,0.035070,282.798004,14.406418,0.350701,-38.342579,0.035218,0.000000
55.610004,63.565460,-38.387062,0.021454,0.001381,0.035070,282.753296,14.404139,0.350701,-38.387062,0.035218,0.000000
55.760002,63.575516,-38.387062,0.021458,0.001381,0.035070,282.798004,14.406418,0.350701,-38.387062,0.035218,0.000000
55.910004,63.571793,-38.431541,0.021445,0.001381,0.035070,282.781464,14.405574,0.350701,-38.431541,0.035218,0.000000
56.060001,63.569565,-38.431541,0.021450,0.001381,0.035070,282.771545,14.405069,0.350701,-38.431541,0.035218,0.000000
56.210003,63.557281,-38.431541,0.021428,0.001381,0.035070,282.716919,14.402286,0.350701,-38.431541,0.035218,0.000000
56.360004,63.538651,-38.387062,0.021463,0.001381,0.035070,282.634033,14.398064,0.350701,-38.387062,0.035218,0.000000
56.510002,63.535309,-38.342579,0.021463,0.001381,0.035070,282.619171,14.397306,0.350701,-38.342579,0.035218,0.000000
56.660004,63.536057,-38.342579,0.021450,0.001381,0.035070,282.622498,14.397476,0.350701,-38.342579,0.035218,0.000000
56.810001,63.538651,-38.431541,0.021471,0.001381,0.035070,282.634033,14.398064,0.350701,-38.431541,0.035218,0.000000
56.960003,63.533813,-38.387062,0.021433,0.001381,0.035070,282.612518,14.396968,0.350701,-38.387062,0.035218,0.000000
57.110004,63.529343,-38.387062,0.021463,0.001381,0.035070,282.592621,14.395955,0.350701,-38.387062,0.035218,0.000000
57.260002,63.513702,-38.431541,0.021458,0.001381,0.035070,282.523071,14.392410,0.350701,-38.431541,0.035218,0.000000
57.410004,63.493607,-38.431541,0.021463,0.001381,0.035070,282.433655,14.387856,0.350701,-38.431541,0.035218,0.000000
57.560001,63.489502,-38.431541,0.021445,0.001381,0.035070,282.415405,14.386927,0.350701,-38.431541,0.035218,0.000000
57.710003,63.483551,-38.342579,0.021463,0.001381,0.035070,282.388947,14.385578,0.350701,-38.342579,0.035218,0.000000
57.860004,63.499191,-38.431541,0.021437,0.001381,0.035070,282.458496,14.389122,0.350701,-38.431541,0.035218,0.000000
58.010002,63.478333,-38.431541,0.021471,0.001381,0.035070,282.365723,14.384396,0.350701,-38.431541,0.035218,0.000000
58.160004,63.479446,-38.520504,0.021445,0.001381,0.035070,282.370667,14.384648,0.350701,-38.520504,0.035218,0.000000
58.310001,63.467911,-38.387062,0.021445,0.001381,0.035070,282.319366,14.382033,0.350701,-38.387062,0.035218,0.000000
58.460003,63.462326,-38.431541,0.021467,0.001381,0.035070,282.294525,14.380769,0.350701,-38.431541,0.035218,0.000000
58.610004,63.452637,-38.387062,0.021467,0.001381,0.035070,282.251434,14.378573,0.350701,-38.387062,0.035218,0.000000
58.760002,63.451889,-38.431541,0.021458,0.001381,0.035070,282.248108,14.378404,0.350701,-38.431541,0.035218,0.000000
58.910004,63.450775,-38.476021,0.021428,0.001381,0.035070,282.243134,14.378151,0.350701,-38.476021,0.035218,0.000000
59.060001,63.438858,-38.431541,0.021458,0.001381,0.035070,282.190125,14.375451,0.350701,-38.431541,0.035218,0.000000
59.210003,63.430664,-38.431541,0.021454,0.001381,0.035070,282.153687,14.373593,0.350701,-38.431541,0.035218,0.000000
59.360004,63.426941,-38.476021,0.021471,0.001381,0.035070,282.137115,14.372750,0.350701,-38.476021,0.035218,0.000000
59.510002,63.429916,-38.476021,0.021458,0.001381,0.035070,282.150360,14.373425,0.350701,-38.476021,0.035218,0.000000
59.660004,63.420242,-38.476021,0.021450,0.001381,0.035070,282.107330,14.371232,0.350701,-38.476021,0.035218,0.000000
59.810001,63.401627,-38.520504,0.021467,0.001381,0.035070,282.024506,14.367015,0.350701,-38.520504,0.035218,0.000000
59.960003,63.409439,-38.431541,0.021454,0.001381,0.035070,282.059265,14.368784,0.350701,-38.431541,0.035218,0.000000
60.110004,63.391571,-38.520504,0.021458,0.001381,0.035070,281.979797,14.364736,0.350701,-38.520504,0.035218,0.000000
60.260002,63.381149,-38.476021,0.021450,0.001381,0.035070,281.933441,14.362373,0.350701,-38.476021,0.035218,0.000000
60.410004,63.387100,-38.476021,0.021450,0.001381,0.035070,281.959900,14.363723,0.350701,-38.476021,0.035218,0.000000
60.560001,63.397156,-38.476021,0.021467,0.001381,0.035070,282.004639,14.366000,0.350701,-38.476021,0.035218,0.000000
60.700005,63.376297,-38.476021,0.021471,0.001381,0.035070,281.911835,14.361275,0.350701,-38.476021,0.035218,0.000000