File: Data/PDMS0040002 10N recovery test 2_10242023_182941.csv
Time (sec),S:Load (lbs),S:HL1 (DIM),S:LVDT (in),S:Position (in),Ch:Position (mm),Ch:Load (N),Ch:Stress (MPa),Ch:Strain (mm/mm),Ch:HL1 (DIM),Set Point (),Cycles ()
0.110000,-0.013405,-81.978394,0.000009,-0.000000,-0.000000,-0.059628,-0.003038,-0.000000,-81.978394,0.000208,0.000000
0.430000,-0.111336,-81.978394,0.000000,-0.000000,-0.000000,-0.495246,-0.025229,-0.000000,-81.978394,0.000251,0.000000
0.750000,-0.006699,-81.978394,0.000022,0.000013,0.000338,-0.029797,-0.001518,0.003384,-81.978394,0.000790,0.000000
1.070000,-0.030533,-82.022873,0.000013,0.000037,0.000928,-0.135817,-0.006919,0.009281,-82.022873,0.001319,0.000000
1.390000,-0.014145,-81.978394,-0.000009,0.000056,0.001431,-0.062920,-0.003205,0.014307,-81.978394,0.001856,0.000000
1.710000,-0.051758,-81.978394,0.000000,0.000075,0.001899,-0.230230,-0.011728,0.018993,-81.978394,0.002385,0.000000
2.030000,-0.051384,-82.067352,0.000013,0.000090,0.002290,-0.228567,-0.011644,0.022899,-82.067352,0.002923,0.000000
2.350000,-0.062553,-82.022873,0.000004,0.000108,0.002732,-0.278251,-0.014175,0.027319,-82.022873,0.003452,0.000000
2.670000,-0.028671,-82.067352,-0.000004,0.000130,0.003296,-0.127536,-0.006497,0.032959,-82.067352,0.003989,0.000000
2.990000,-0.047287,-82.022873,0.000039,0.000145,0.003677,-0.210343,-0.010715,0.036774,-82.022873,0.004518,0.000000
3.310000,-0.016380,-82.022873,0.000022,0.000162,0.004111,-0.072863,-0.003712,0.041112,-82.022873,0.005056,0.000000
3.630000,-0.041328,-82.067352,0.000052,0.000182,0.004614,-0.183838,-0.009365,0.046138,-82.067352,0.005585,0.000000
3.950000,-0.027924,-82.067352,0.000078,0.000203,0.005160,-0.124210,-0.006328,0.051603,-82.067352,0.006122,0.000000
4.270000,-0.077820,-82.111839,0.000112,0.000221,0.005620,-0.346160,-0.017634,0.056198,-82.111839,0.006652,0.000000
4.590000,-0.066650,-82.111839,0.000103,0.000242,0.006157,-0.296476,-0.015103,0.061573,-82.111839,0.007190,0.000000
4.910000,-0.026436,-82.022873,0.000116,0.000269,0.006825,-0.117593,-0.005990,0.068249,-82.022873,0.007718,0.000000
5.230000,-0.011543,-82.067352,0.000172,0.000289,0.007328,-0.051347,-0.002616,0.073283,-82.067352,0.008256,0.000000
5.550000,-0.046173,-82.156319,0.000181,0.000306,0.007779,-0.205388,-0.010463,0.077795,-82.156319,0.008785,0.000000
5.870000,-0.028297,-82.067352,0.000207,0.000328,0.008343,-0.125873,-0.006412,0.083427,-82.067352,0.009323,0.000000
6.190000,-0.052872,-82.111839,0.000224,0.000349,0.008872,-0.235185,-0.011981,0.088718,-82.111839,0.009852,0.000000
6.510000,-0.081917,-82.111839,0.000246,0.000369,0.009366,-0.364384,-0.018563,0.093661,-82.111839,0.010390,0.000000
6.830000,-0.020851,-82.156319,0.000250,0.000392,0.009947,-0.092750,-0.004725,0.099475,-82.156319,0.010919,0.000000
7.150001,-0.005211,-82.156319,0.000293,0.000409,0.010380,-0.023179,-0.001181,0.103805,-82.156319,0.011456,0.000000
7.470000,-0.017494,-82.245277,0.000336,0.000432,0.010971,-0.077818,-0.003964,0.109709,-82.245277,0.011985,0.000000
7.790000,0.003731,-82.111839,0.000336,0.000451,0.011448,0.016595,0.000845,0.114478,-82.111839,0.012523,0.000000
8.110001,-0.003723,-82.200798,0.000375,0.000475,0.012055,-0.016561,-0.000844,0.120549,-82.200798,0.013052,0.000000
8.430000,0.001495,-82.200798,0.000375,0.000487,0.012375,0.006652,0.000339,0.123751,-82.200798,0.013589,0.000000
8.750000,0.077087,-82.245277,0.000375,0.000512,0.013000,0.342902,0.017468,0.129996,-82.245277,0.014118,0.000000
9.070001,0.144859,-82.200798,0.000414,0.000532,0.013520,0.644366,0.032826,0.135204,-82.200798,0.014656,0.000000
9.390000,0.170921,-82.156319,0.000453,0.000554,0.014066,0.760296,0.038731,0.140662,-82.156319,0.015185,0.000000
9.710000,0.230133,-82.200798,0.000461,-0.000005,-0.000139,1.023683,0.052149,-0.001385,-82.200798,-0.000000,0.000000
10.030001,0.212997,-82.245277,0.000466,-0.000006,-0.000148,0.947460,0.048266,-0.001476,-82.245277,-0.000000,0.000000
10.350000,0.198853,-82.289757,0.000453,-0.000006,-0.000148,0.884540,0.045061,-0.001476,-82.289757,0.000026,0.000000
10.670000,0.104637,-82.245277,0.000479,-0.000006,-0.000148,0.465449,0.023711,-0.001476,-82.245277,0.000078,0.000000
10.990001,0.191772,-82.200798,0.000483,-0.000006,-0.000148,0.853047,0.043456,-0.001476,-82.200798,0.000130,0.000000
11.310000,0.229385,-82.245277,0.000479,-0.000006,-0.000148,1.020357,0.051979,-0.001476,-82.245277,0.000182,0.000000
11.630000,0.186188,-82.245277,0.000461,-0.000006,-0.000148,0.828204,0.042191,-0.001476,-82.245277,0.000235,0.000000
11.950001,0.228271,-82.289757,0.000470,-0.000006,-0.000148,1.015402,0.051727,-0.001476,-82.289757,0.000295,0.000000
12.270000,0.189171,-82.289757,0.000448,-0.000006,-0.000148,0.841474,0.042867,-0.001476,-82.289757,0.000347,0.000000
12.590000,0.184700,-82.245277,0.000483,-0.000006,-0.000148,0.821587,0.041854,-0.001476,-82.245277,0.000399,0.000000
12.910001,0.217842,-82.245277,0.000453,-0.000006,-0.000148,0.969010,0.049364,-0.001476,-82.245277,0.000451,0.000000
13.230000,0.200714,-82.245277,0.000470,-0.000006,-0.000148,0.892821,0.045482,-0.001476,-82.245277,0.000503,0.000000
13.550000,0.208160,-82.378723,0.000483,-0.000006,-0.000148,0.925944,0.047170,-0.001476,-82.378723,0.000555,0.000000
13.870001,0.180229,-82.334244,0.000453,-0.000006,-0.000148,0.801699,0.040841,-0.001476,-82.334244,0.000607,0.000000
14.190001,0.188423,-82.334244,0.000453,-0.000006,-0.000148,0.838148,0.042697,-0.001476,-82.334244,0.000668,0.000000
14.510000,0.185814,-82.334244,0.000474,-0.000005,-0.000139,0.826542,0.042106,-0.001385,-82.334244,0.000720,0.000000
14.830001,0.185074,-82.289757,0.000457,-0.000005,-0.000139,0.823250,0.041938,-0.001385,-82.289757,0.000772,0.000000
15.150001,0.185448,-82.378723,0.000448,-0.000005,-0.000139,0.824913,0.042023,-0.001385,-82.378723,0.000824,0.000000
15.470000,0.167198,-82.378723,0.000457,-0.000005,-0.000130,0.743735,0.037888,-0.001302,-82.378723,0.000876,0.000000
15.790001,0.172409,-82.334244,0.000457,-0.000004,-0.000095,0.766914,0.039068,-0.000954,-82.334244,0.000928,0.000000
16.110001,0.185814,-82.423203,0.000448,-0.000000,-0.000000,0.826542,0.042106,-0.000000,-82.423203,0.000989,0.000000
16.430000,0.188049,-82.334244,0.000470,-0.000000,-0.000000,0.836485,0.042613,-0.000000,-82.334244,0.001041,0.000000
16.750000,0.190285,-82.423203,0.000444,0.000004,0.000095,0.846429,0.043119,0.000954,-82.423203,0.001093,0.000000
17.070002,0.198105,-82.378723,0.000461,0.000005,0.000130,0.881214,0.044891,0.001302,-82.378723,0.001145,0.000000
17.390001,0.202202,-82.467682,0.000470,0.000008,0.000200,0.899439,0.045820,0.001998,-82.467682,0.001197,0.000000
17.710001,0.221565,-82.378723,0.000474,0.000009,0.000226,0.985571,0.050207,0.002256,-82.378723,0.001249,0.000000
18.030001,0.218590,-82.378723,0.000474,0.000009,0.000226,0.972336,0.049533,0.002256,-82.378723,0.001301,0.000000
18.350000,0.230873,-82.378723,0.000466,0.000013,0.000338,1.026975,0.052317,0.003384,-82.378723,0.001362,0.000000
18.670000,0.226410,-82.512161,0.000483,0.000013,0.000338,1.007122,0.051305,0.003384,-82.512161,0.001414,0.000000
18.990002,0.236832,-82.423203,0.000496,0.000014,0.000347,1.053480,0.053667,0.003475,-82.423203,0.001466,0.000000
19.310001,0.230873,-82.423203,0.000479,0.000014,0.000347,1.026975,0.052317,0.003475,-82.423203,0.001518,0.000000
19.630001,0.258804,-82.423203,0.000487,0.000021,0.000521,1.151219,0.058646,0.005208,-82.423203,0.001570,0.000000
19.950001,0.253960,-82.467682,0.000483,0.000021,0.000538,1.129669,0.057548,0.005382,-82.467682,0.001622,0.000000
20.270000,0.273323,-82.423203,0.000483,0.000023,0.000590,1.215802,0.061936,0.005897,-82.423203,0.001674,0.000000
20.590000,0.268112,-82.512161,0.000492,0.000026,0.000668,1.192623,0.060755,0.006677,-82.512161,0.001735,0.000000
20.910002,0.284866,-82.467682,0.000504,0.000030,0.000763,1.267149,0.064552,0.007630,-82.467682,0.001786,0.000000
21.230001,0.273323,-82.467682,0.000496,0.000032,0.000807,1.215802,0.061936,0.008069,-82.467682,0.001839,0.000000
21.550001,0.312050,-82.467682,0.000492,0.000036,0.000902,1.388067,0.070712,0.009023,-82.467682,0.001891,0.000000
21.870001,0.300880,-82.512161,0.000483,0.000037,0.000937,1.338383,0.068180,0.009371,-82.512161,0.001942,0.000000
22.190001,0.291199,-82.556648,0.000496,0.000038,0.000963,1.295317,0.065987,0.009629,-82.556648,0.001995,0.000000
22.510000,0.319496,-82.556648,0.000487,0.000040,0.001006,1.421190,0.072399,0.010060,-82.556648,0.002055,0.000000
22.830002,0.316895,-82.556648,0.000500,0.000042,0.001076,1.409617,0.071809,0.010757,-82.556648,0.002107,0.000000
23.150002,0.332161,-82.556648,0.000513,0.000045,0.001154,1.477526,0.075269,0.011536,-82.556648,0.002160,0.000000
23.470001,0.301254,-82.556648,0.000487,0.000046,0.001162,1.340046,0.068265,0.011620,-82.556648,0.002212,0.000000
23.790001,0.338120,-82.601128,0.000504,0.000047,0.001188,1.504031,0.076619,0.011885,-82.601128,0.002263,0.000000
24.110001,0.334396,-82.556648,0.000517,0.000047,0.001188,1.487469,0.075775,0.011885,-82.556648,0.002316,0.000000
24.430000,0.335884,-82.601128,0.000500,0.000049,0.001249,1.494087,0.076112,0.012490,-82.601128,0.002368,0.000000
24.750002,0.368279,-82.556648,0.000522,0.000051,0.001284,1.638185,0.083453,0.012838,-82.556648,0.002428,0.000000
25.070002,0.372002,-82.645607,0.000509,0.000052,0.001327,1.654746,0.084297,0.013270,-82.645607,0.002481,0.000000
25.390001,0.370140,-82.645607,0.000522,0.000054,0.001362,1.646465,0.083875,0.013618,-82.645607,0.002533,0.000000
25.710001,0.366417,-82.645607,0.000522,0.000054,0.001379,1.629904,0.083031,0.013792,-82.645607,0.002584,0.000000
26.030001,0.386902,-82.556648,0.000526,0.000060,0.001527,1.721025,0.087673,0.015268,-82.556648,0.002637,0.000000
26.350000,0.441635,-82.645607,0.000526,0.000067,0.001691,1.964491,0.100076,0.016911,-82.645607,0.002689,0.000000
26.670002,0.433449,-82.690086,0.000535,0.000067,0.001709,1.928077,0.098221,0.017085,-82.690086,0.002740,0.000000
26.990002,0.436050,-82.690086,0.000530,0.000067,0.001709,1.939649,0.098810,0.017085,-82.690086,0.002802,0.000000
27.310001,0.450203,-82.645607,0.000543,0.000069,0.001752,2.002603,0.102017,0.017516,-82.645607,0.002853,0.000000
27.630001,0.473289,-82.645607,0.000539,0.000069,0.001752,2.105297,0.107249,0.017516,-82.645607,0.002905,0.000000
27.950001,0.467705,-82.690086,0.000522,0.000074,0.001874,2.080455,0.105983,0.018735,-82.690086,0.002958,0.000000
28.270000,0.487068,-82.690086,0.000517,0.000076,0.001934,2.166587,0.110371,0.019341,-82.690086,0.003010,0.000000
28.590002,0.502708,-82.734566,0.000543,0.000080,0.002029,2.236159,0.113915,0.020295,-82.734566,0.003061,0.000000
28.910002,0.522812,-82.734566,0.000552,0.000080,0.002039,2.325583,0.118471,0.020385,-82.734566,0.003123,0.000000
29.230001,0.522812,-82.779053,0.000556,0.000082,0.002073,2.325583,0.118471,0.020726,-82.779053,0.003174,0.000000
29.550001,0.536964,-82.734566,0.000548,0.000083,0.002107,2.388537,0.121678,0.021074,-82.734566,0.003226,0.000000
29.870001,0.549255,-82.690086,0.000539,0.000084,0.002134,2.443210,0.124463,0.021339,-82.690086,0.003278,0.000000
30.190001,0.537338,-82.779053,0.000539,0.000086,0.002177,2.390200,0.121763,0.021771,-82.779053,0.003331,0.000000
30.510002,0.566383,-82.779053,0.000552,0.000088,0.002238,2.519399,0.128344,0.022376,-82.779053,0.003382,0.000000
30.830002,0.608459,-82.734566,0.000560,0.000093,0.002359,2.706563,0.137879,0.023587,-82.734566,0.003434,0.000000
31.150002,0.618515,-82.779053,0.000565,0.000094,0.002394,2.751292,0.140158,0.023936,-82.779053,0.003495,0.000000
31.470001,0.625214,-82.734566,0.000552,0.000094,0.002394,2.781089,0.141675,0.023936,-82.734566,0.003547,0.000000
31.790001,0.625961,-82.823532,0.000552,0.000094,0.002394,2.784415,0.141845,0.023936,-82.823532,0.003599,0.000000
32.110001,0.656494,-82.823532,0.000565,0.000100,0.002541,2.920232,0.148764,0.025412,-82.823532,0.003651,0.000000
32.430000,0.672882,-82.779053,0.000565,0.000103,0.002611,2.993129,0.152477,0.026108,-82.779053,0.003703,0.000000
32.750000,0.683678,-82.779053,0.000573,0.000103,0.002628,3.041150,0.154924,0.026282,-82.779053,0.003755,0.000000
33.070000,0.685539,-82.779053,0.000569,0.000103,0.002628,3.049431,0.155345,0.026282,-82.779053,0.003808,0.000000
33.390003,0.688148,-82.823532,0.000578,0.000109,0.002775,3.061037,0.155937,0.027751,-82.823532,0.003868,0.000000
33.710003,0.736931,-82.868011,0.000565,0.000114,0.002905,3.278032,0.166991,0.029053,-82.868011,0.003920,0.000000
34.030003,0.746239,-82.868011,0.000586,0.000115,0.002923,3.319436,0.169100,0.029227,-82.868011,0.003972,0.000000
34.350002,0.742889,-82.868011,0.000586,0.000117,0.002966,3.304537,0.168341,0.029658,-82.868011,0.004024,0.000000
34.670002,0.754433,-82.868011,0.000595,0.000118,0.003001,3.355884,0.170957,0.030007,-82.868011,0.004076,0.000000
34.990002,0.764114,-82.868011,0.000569,0.000120,0.003044,3.398951,0.173151,0.030438,-82.868011,0.004129,0.000000
35.310001,0.815125,-82.912491,0.000595,0.000125,0.003183,3.625855,0.184710,0.031831,-82.912491,0.004189,0.000000
35.630001,0.813637,-82.912491,0.000599,0.000125,0.003183,3.619237,0.184373,0.031831,-82.912491,0.004241,0.000000
35.950001,0.807304,-82.956970,0.000604,0.000125,0.003183,3.591069,0.182938,0.031831,-82.956970,0.004293,0.000000
36.270000,0.816246,-82.823532,0.000582,0.000125,0.003183,3.630844,0.184964,0.031831,-82.823532,0.004345,0.000000
36.590000,0.869492,-82.912491,0.000608,0.000134,0.003400,3.867692,0.197030,0.033996,-82.912491,0.004397,0.000000
36.910000,0.881783,-82.956970,0.000595,0.000135,0.003434,3.922365,0.199815,0.034344,-82.956970,0.004449,0.000000
37.230003,0.923485,-82.956970,0.000599,0.000138,0.003512,4.107865,0.209265,0.035124,-82.956970,0.004501,0.000000
37.550003,0.942108,-82.868011,0.000599,0.000141,0.003582,4.190706,0.213485,0.035820,-82.868011,0.004562,0.000000
37.870003,0.951042,-82.868011,0.000625,0.000143,0.003625,4.230447,0.215509,0.036252,-82.868011,0.004614,0.000000
38.190002,0.957748,-82.956970,0.000612,0.000144,0.003660,4.260278,0.217029,0.036600,-82.956970,0.004666,0.000000
38.510002,0.957001,-82.956970,0.000591,0.000146,0.003721,4.256952,0.216859,0.037206,-82.956970,0.004718,0.000000
38.830002,0.971893,-82.956970,0.000621,0.000146,0.003721,4.323197,0.220234,0.037206,-82.956970,0.004770,0.000000
39.150002,0.985672,-82.868011,0.000621,0.000148,0.003764,4.384488,0.223356,0.037637,-82.868011,0.004822,0.000000
39.470001,1.011742,-82.956970,0.000612,0.000151,0.003833,4.500452,0.229264,0.038333,-82.956970,0.004874,0.000000
39.790001,0.998703,-83.001457,0.000625,0.000152,0.003851,4.442453,0.226309,0.038508,-83.001457,0.004935,0.000000
40.110001,0.984932,-83.045937,0.000617,0.000153,0.003876,4.381196,0.223189,0.038765,-83.045937,0.004987,0.000000
40.430000,0.996101,-83.090416,0.000617,0.000153,0.003894,4.430880,0.225720,0.038939,-83.090416,0.005038,0.000000
40.750004,1.036316,-83.001457,0.000625,0.000158,0.004024,4.609764,0.234833,0.040241,-83.001457,0.005091,0.000000
41.070004,1.057167,-82.956970,0.000625,0.000161,0.004102,4.702514,0.239557,0.041021,-82.956970,0.005143,0.000000
41.390003,1.056053,-83.045937,0.000629,0.000163,0.004129,4.697559,0.239305,0.041286,-83.045937,0.005195,0.000000
41.710003,1.079514,-83.090416,0.000625,0.000164,0.004172,4.801916,0.244621,0.041717,-83.090416,0.005256,0.000000
42.030003,1.088074,-83.090416,0.000625,0.000165,0.004197,4.839993,0.246561,0.041974,-83.090416,0.005308,0.000000
42.350002,1.134995,-83.001457,0.000642,0.000170,0.004328,5.048707,0.257193,0.043276,-83.001457,0.005359,0.000000
42.670002,1.140579,-83.045937,0.000634,0.000171,0.004345,5.073550,0.258459,0.043451,-83.045937,0.005412,0.000000
42.990002,1.181915,-83.090416,0.000651,0.000174,0.004415,5.257422,0.267826,0.044147,-83.090416,0.005464,0.000000
43.310001,1.180428,-83.045937,0.000634,0.000175,0.004449,5.250804,0.267489,0.044488,-83.045937,0.005516,0.000000
43.630001,1.169624,-83.134895,0.000629,0.000176,0.004458,5.202749,0.265041,0.044578,-83.134895,0.005568,0.000000
43.950001,1.215431,-83.090416,0.000647,0.000179,0.004536,5.406508,0.275421,0.045358,-83.090416,0.005628,0.000000
44.270000,1.219521,-83.045937,0.000642,0.000179,0.004536,5.424698,0.276347,0.045358,-83.045937,0.005680,0.000000
44.590004,1.254524,-83.134895,0.000629,0.000183,0.004657,5.580402,0.284279,0.046569,-83.134895,0.005733,0.000000
44.910004,1.253036,-83.134895,0.000647,0.000184,0.004666,5.573785,0.283942,0.046660,-83.134895,0.005785,0.000000
45.230003,1.279106,-83.223862,0.000660,0.000184,0.004674,5.689748,0.289850,0.046743,-83.223862,0.005836,0.000000
45.550003,1.284691,-83.179375,0.000655,0.000187,0.004744,5.714591,0.291115,0.047440,-83.179375,0.005889,0.000000
45.870003,1.309265,-83.134895,0.000668,0.000188,0.004779,5.823902,0.296684,0.047788,-83.134895,0.005941,0.000000
46.190002,1.388954,-83.090416,0.000647,0.000195,0.004960,6.178377,0.314741,0.049605,-83.090416,0.006001,0.000000
46.510002,1.412788,-83.179375,0.000651,0.000195,0.004960,6.284397,0.320142,0.049605,-83.179375,0.006054,0.000000
46.830002,1.406082,-83.223862,0.000655,0.000195,0.004960,6.254566,0.318623,0.049605,-83.223862,0.006106,0.000000
47.150002,1.416878,-83.179375,0.000660,0.000196,0.004978,6.302587,0.321069,0.049779,-83.179375,0.006157,0.000000
47.470001,1.406830,-83.134895,0.000668,0.000199,0.005048,6.257892,0.318792,0.050475,-83.134895,0.006209,0.000000
47.790001,1.472366,-83.179375,0.000664,0.000202,0.005134,6.549413,0.333643,0.051338,-83.179375,0.006262,0.000000
48.110001,1.482048,-83.179375,0.000655,0.000204,0.005178,6.592479,0.335837,0.051777,-83.179375,0.006322,0.000000
48.430004,1.505508,-83.268341,0.000673,0.000205,0.005203,6.696836,0.341153,0.052035,-83.268341,0.006375,0.000000
48.750004,1.562851,-83.268341,0.000664,0.000209,0.005308,6.951908,0.354147,0.053079,-83.268341,0.006426,0.000000
49.070004,1.555779,-83.268341,0.000690,0.000210,0.005325,6.920448,0.352544,0.053246,-83.268341,0.006478,0.000000
49.390003,1.568810,-83.179375,0.000673,0.000210,0.005342,6.978413,0.355497,0.053420,-83.179375,0.006530,0.000000
49.710003,1.605675,-83.223862,0.000686,0.000215,0.005455,7.142398,0.363851,0.054548,-83.223862,0.006583,0.000000
50.030003,1.631371,-83.268341,0.000677,0.000216,0.005499,7.256699,0.369674,0.054987,-83.268341,0.006634,0.000000
50.350002,1.657059,-83.268341,0.000677,0.000219,0.005550,7.370965,0.375495,0.055502,-83.268341,0.006695,0.000000
50.670002,1.648872,-83.312820,0.000681,0.000219,0.005550,7.334551,0.373640,0.055502,-83.312820,0.006747,0.000000
50.990002,1.640305,-83.268341,0.000686,0.000219,0.005550,7.296439,0.371698,0.055502,-83.268341,0.006799,0.000000
51.310001,1.617592,-83.312820,0.000660,0.000219,0.005550,7.195408,0.366552,0.055502,-83.312820,0.006851,0.000000
51.630001,1.614235,-83.357300,0.000694,0.000219,0.005550,7.180476,0.365791,0.055502,-83.357300,0.006904,0.000000
51.950001,1.798935,-83.357300,0.000690,0.000228,0.005802,8.002062,0.407644,0.058022,-83.357300,0.006955,0.000000
52.270004,1.829468,-83.312820,0.000690,0.000230,0.005845,8.137879,0.414563,0.058454,-83.312820,0.007007,0.000000
52.590004,1.851440,-83.268341,0.000690,0.000233,0.005906,8.235619,0.419542,0.059060,-83.268341,0.007068,0.000000
52.910004,1.847343,-83.312820,0.000690,0.000235,0.005967,8.217394,0.418614,0.059665,-83.312820,0.007120,0.000000
53.230003,1.917725,-83.357300,0.000698,0.000239,0.006062,8.530465,0.434563,0.060619,-83.357300,0.007172,0.000000
53.550003,1.908043,-83.357300,0.000720,0.000239,0.006062,8.487399,0.432369,0.060619,-83.357300,0.007224,0.000000
53.870003,1.968735,-83.357300,0.000694,0.000244,0.006192,8.757369,0.446122,0.061921,-83.357300,0.007276,0.000000
54.190002,2.124763,-83.357300,0.000703,0.000254,0.006443,9.451420,0.481478,0.064434,-83.357300,0.007328,0.000000
54.510002,2.114334,-83.357300,0.000724,0.000254,0.006461,9.405027,0.479115,0.064608,-83.357300,0.007389,0.000000
54.830002,2.147850,-83.446266,0.000716,0.000257,0.006530,9.554114,0.486710,0.065305,-83.446266,0.007441,0.000000
55.150002,2.134071,-83.401787,0.000716,0.000258,0.006565,9.492824,0.483588,0.065653,-83.401787,0.007493,0.000000
55.470001,2.156784,-83.401787,0.000711,0.000259,0.006591,9.593855,0.488734,0.065910,-83.401787,0.007545,0.000000
55.790001,2.179871,-83.357300,0.000724,0.000262,0.006643,9.696548,0.493966,0.066432,-83.357300,0.007597,0.000000
56.110004,2.223816,-83.401787,0.000711,0.000264,0.006713,9.892027,0.503924,0.067129,-83.401787,0.007649,0.000000
56.430004,2.212265,-83.446266,0.000724,0.000258,0.006565,9.840646,0.501306,0.065653,-83.446266,0.006756,0.000000
56.750004,2.189552,-83.446266,0.000724,0.000258,0.006548,9.739615,0.496160,0.065479,-83.446266,0.006756,0.000000
57.070004,2.167213,-83.535225,0.000733,0.000257,0.006539,9.640246,0.491098,0.065388,-83.535225,0.006704,0.000000
57.390003,2.158646,-83.401787,0.000733,0.000257,0.006539,9.602136,0.489156,0.065388,-83.401787,0.006652,0.000000
57.710003,2.145988,-83.446266,0.000733,0.000257,0.006530,9.545834,0.486288,0.065305,-83.446266,0.006591,0.000000
58.030003,2.130722,-83.446266,0.000724,0.000257,0.006530,9.477925,0.482829,0.065305,-83.446266,0.006539,0.000000
58.350002,2.103165,-83.490746,0.000703,0.000257,0.006530,9.355344,0.476584,0.065305,-83.490746,0.006487,0.000000
58.670002,2.105400,-83.490746,0.000724,0.000257,0.006521,9.365288,0.477090,0.065214,-83.490746,0.006435,0.000000
58.990002,2.107635,-83.490746,0.000733,0.000257,0.006521,9.375231,0.477597,0.065214,-83.490746,0.006383,0.000000
59.310001,2.084541,-83.490746,0.000729,0.000257,0.006521,9.272503,0.472364,0.065214,-83.490746,0.006331,0.000000
59.630001,2.081566,-83.535225,0.000720,0.000255,0.006470,9.259268,0.471690,0.064699,-83.535225,0.006270,0.000000
59.950005,2.063316,-83.579704,0.000729,0.000253,0.006418,9.178089,0.467554,0.064177,-83.579704,0.006218,0.000000
60.270004,2.049545,-83.535225,0.000742,0.000251,0.006365,9.116833,0.464434,0.063654,-83.535225,0.006166,0.000000
60.590004,2.035019,-83.535225,0.000733,0.000249,0.006314,9.052217,0.461142,0.063140,-83.535225,0.006114,0.000000
60.910004,2.026085,-83.490746,0.000716,0.000247,0.006262,9.012476,0.459117,0.062617,-83.490746,0.006062,0.000000
61.230003,1.978043,-83.579704,0.000724,0.000245,0.006218,8.798773,0.448231,0.062178,-83.579704,0.006010,0.000000
61.550003,1.957191,-83.624191,0.000737,0.000243,0.006166,8.706022,0.443506,0.061664,-83.624191,0.005958,0.000000
61.870003,1.932991,-83.535225,0.000729,0.000241,0.006132,8.598373,0.438022,0.061315,-83.535225,0.005898,0.000000
62.190002,2.020866,-83.579704,0.000733,0.000240,0.006097,8.989263,0.457935,0.060967,-83.579704,0.005845,0.000000
62.510002,2.019005,-83.579704,0.000737,0.000237,0.006027,8.980982,0.457513,0.060271,-83.579704,0.005793,0.000000
62.830002,2.021240,-83.579704,0.000737,0.000235,0.005976,8.990926,0.458020,0.059756,-83.579704,0.005741,0.000000
63.150002,2.013420,-83.579704,0.000737,0.000233,0.005923,8.956140,0.456248,0.059234,-83.579704,0.005689,0.000000
63.470001,2.007088,-83.713150,0.000724,0.000232,0.005880,8.927972,0.454813,0.058802,-83.713150,0.005637,0.000000
63.790005,1.942673,-83.624191,0.000733,0.000231,0.005863,8.641439,0.440216,0.058628,-83.624191,0.005585,0.000000
64.110001,1.998901,-83.624191,0.000742,0.000228,0.005785,8.891558,0.452958,0.057848,-83.624191,0.005524,0.000000
64.430000,1.961288,-83.624191,0.000729,0.000226,0.005741,8.724247,0.444434,0.057409,-83.624191,0.005472,0.000000
64.750000,2.004112,-83.624191,0.000733,0.000223,0.005663,8.914737,0.454138,0.056630,-83.624191,0.005421,0.000000
65.070000,1.980278,-83.713150,0.000729,0.000221,0.005611,8.808717,0.448737,0.056115,-83.713150,0.005368,0.000000
65.389999,1.971718,-83.668671,0.000733,0.000219,0.005559,8.770639,0.446798,0.055593,-83.668671,0.005316,0.000000
65.710007,1.970230,-83.668671,0.000742,0.000217,0.005524,8.764021,0.446461,0.055244,-83.668671,0.005264,0.000000
66.030006,1.893517,-83.668671,0.000711,0.000216,0.005490,8.422782,0.429077,0.054896,-83.668671,0.005213,0.000000
66.350006,1.994804,-83.668671,0.000716,0.000216,0.005490,8.873333,0.452029,0.054896,-83.668671,0.005151,0.000000
66.670006,1.950493,-83.802109,0.000720,0.000215,0.005464,8.676226,0.441988,0.054639,-83.802109,0.005100,0.000000
66.990005,1.962036,-83.713150,0.000737,0.000211,0.005368,8.727572,0.444604,0.053685,-83.713150,0.005048,0.000000
67.310005,1.960548,-83.668671,0.000724,0.000211,0.005351,8.720955,0.444267,0.053511,-83.668671,0.004995,0.000000
67.630005,1.946396,-83.713150,0.000724,0.000210,0.005342,8.658001,0.441060,0.053420,-83.713150,0.004943,0.000000
67.950005,1.922935,-83.668671,0.000729,0.000210,0.005342,8.553644,0.435743,0.053420,-83.668671,0.004892,0.000000
68.270004,1.941185,-83.757629,0.000737,0.000208,0.005273,8.634822,0.439879,0.052731,-83.757629,0.004830,0.000000
68.590004,1.915489,-83.668671,0.000737,0.000207,0.005247,8.520521,0.434056,0.052466,-83.668671,0.004779,0.000000
68.910004,1.924049,-83.757629,0.000724,0.000204,0.005178,8.558599,0.435996,0.051777,-83.757629,0.004727,0.000000
69.230003,1.903572,-83.757629,0.000737,0.000203,0.005151,8.467511,0.431356,0.051512,-83.757629,0.004674,0.000000
69.550003,1.919212,-83.757629,0.000724,0.000202,0.005143,8.537083,0.434900,0.051429,-83.757629,0.004623,0.000000
69.870003,1.906548,-83.846596,0.000729,0.000199,0.005065,8.480747,0.432030,0.050649,-83.846596,0.004571,0.000000
70.190002,1.911766,-83.802109,0.000733,0.000198,0.005038,8.503960,0.433212,0.050385,-83.802109,0.004518,0.000000
70.510002,1.915489,-83.713150,0.000742,0.000196,0.004987,8.520521,0.434056,0.049870,-83.713150,0.004458,0.000000
70.830002,1.891655,-83.802109,0.000711,0.000194,0.004935,8.414501,0.428655,0.049347,-83.802109,0.004406,0.000000
71.150002,1.881973,-83.846596,0.000711,0.000190,0.004814,8.371435,0.426461,0.048136,-83.846596,0.004353,0.000000
71.470001,1.881233,-83.846596,0.000724,0.000188,0.004770,8.368143,0.426294,0.047697,-83.846596,0.004302,0.000000
71.790001,1.909157,-83.891075,0.000733,0.000188,0.004770,8.492353,0.432621,0.047697,-83.891075,0.004250,0.000000
72.110001,1.891281,-83.846596,0.000724,0.000186,0.004718,8.412839,0.428570,0.047183,-83.846596,0.004197,0.000000
72.430000,1.911392,-83.846596,0.000737,0.000180,0.004579,8.502297,0.433128,0.045790,-83.846596,0.004145,0.000000
72.750000,1.870430,-83.846596,0.000711,0.000180,0.004562,8.320088,0.423845,0.045616,-83.846596,0.004085,0.000000
73.070000,1.884956,-83.891075,0.000716,0.000177,0.004484,8.384705,0.427137,0.044836,-83.891075,0.004032,0.000000
73.390007,1.893517,-83.891075,0.000729,0.000174,0.004431,8.422782,0.429077,0.044314,-83.891075,0.003981,0.000000
73.710007,1.880486,-83.891075,0.000729,0.000173,0.004388,8.364818,0.426124,0.043882,-83.891075,0.003929,0.000000
74.030006,1.889420,-83.846596,0.000724,0.000170,0.004328,8.404558,0.428149,0.043276,-83.846596,0.003876,0.000000
74.350006,1.884209,-83.891075,0.000737,0.000170,0.004319,8.381379,0.426968,0.043193,-83.891075,0.003825,0.000000
74.670006,1.913254,-83.935555,0.000724,0.000165,0.004197,8.510578,0.433549,0.041974,-83.935555,0.003764,0.000000
74.990005,1.852188,-83.935555,0.000733,0.000165,0.004197,8.238944,0.419712,0.041974,-83.935555,0.003712,0.000000
75.310005,1.903198,-83.935555,0.000746,0.000161,0.004094,8.465849,0.431271,0.040937,-83.935555,0.003660,0.000000
75.630005,1.858887,-83.846596,0.000729,0.000160,0.004076,8.268741,0.421230,0.040763,-83.846596,0.003608,0.000000
75.950005,1.873039,-83.935555,0.000716,0.000160,0.004076,8.331695,0.424437,0.040763,-83.935555,0.003556,0.000000
76.270004,1.880859,-83.980034,0.000707,0.000160,0.004076,8.366481,0.426209,0.040763,-83.980034,0.003504,0.000000
76.590004,1.878624,-83.935555,0.000729,0.000150,0.003816,8.356537,0.425702,0.038159,-83.935555,0.003452,0.000000
76.910004,1.865959,-83.935555,0.000724,0.000149,0.003773,8.300200,0.422832,0.037728,-83.935555,0.003391,0.000000
77.230003,1.874901,-83.980034,0.000742,0.000146,0.003712,8.339975,0.424859,0.037122,-83.980034,0.003339,0.000000
77.550003,1.865959,-83.980034,0.000733,0.000144,0.003668,8.300200,0.422832,0.036683,-83.980034,0.003287,0.000000
77.870003,1.873779,-84.024513,0.000737,0.000142,0.003617,8.334987,0.424604,0.036168,-84.024513,0.003235,0.000000
78.190002,1.838776,-84.024513,0.000737,0.000140,0.003547,8.179282,0.416673,0.035472,-84.024513,0.003183,0.000000
78.510002,1.848457,-84.024513,0.000737,0.000138,0.003495,8.222349,0.418866,0.034950,-84.024513,0.003131,0.000000
78.830002,1.845108,-84.024513,0.000750,0.000136,0.003443,8.207451,0.418107,0.034427,-84.024513,0.003079,0.000000
79.150002,1.859634,-83.980034,0.000729,0.000133,0.003382,8.272067,0.421399,0.033822,-83.980034,0.003018,0.000000
79.470001,1.835426,-84.024513,0.000716,0.000131,0.003339,8.164384,0.415914,0.033390,-84.024513,0.002966,0.000000
79.790001,1.826866,-84.024513,0.000733,0.000129,0.003287,8.126307,0.413974,0.032868,-84.024513,0.002914,0.000000
80.110001,1.831329,-84.024513,0.000742,0.000128,0.003244,8.146160,0.414985,0.032437,-84.024513,0.002862,0.000000
80.430000,1.851440,-83.980034,0.000733,0.000126,0.003201,8.235619,0.419542,0.032005,-83.980034,0.002810,0.000000
80.750008,1.880859,-84.069000,0.000711,0.000124,0.003157,8.366481,0.426209,0.031566,-84.069000,0.002758,0.000000
81.070007,1.885696,-84.113480,0.000729,0.000123,0.003113,8.387997,0.427305,0.031135,-84.113480,0.002697,0.000000
81.390007,1.841385,-84.069000,0.000733,0.000122,0.003096,8.190889,0.417264,0.030960,-84.069000,0.002645,0.000000
81.710007,1.898361,-84.069000,0.000742,0.000119,0.003018,8.444332,0.430175,0.030181,-84.069000,0.002593,0.000000
82.030006,1.873413,-84.113480,0.000724,0.000116,0.002940,8.333358,0.424521,0.029401,-84.113480,0.002541,0.000000
82.350006,1.887184,-84.113480,0.000720,0.000115,0.002914,8.394614,0.427642,0.029144,-84.113480,0.002489,0.000000
82.670006,1.891281,-84.113480,0.000724,0.000112,0.002845,8.412839,0.428570,0.028447,-84.113480,0.002437,0.000000
82.990005,1.880486,-84.069000,0.000733,0.000111,0.002810,8.364818,0.426124,0.028099,-84.069000,0.002385,0.000000
83.310005,1.848091,-84.113480,0.000746,0.000109,0.002775,8.220720,0.418783,0.027751,-84.113480,0.002325,0.000000
83.630005,1.870430,-84.113480,0.000742,0.000106,0.002697,8.320088,0.423845,0.026971,-84.113480,0.002272,0.000000
83.950005,1.864098,-84.113480,0.000724,0.000105,0.002662,8.291921,0.422411,0.026623,-84.113480,0.002220,0.000000
84.270004,1.858887,-84.157959,0.000703,0.000102,0.002602,8.268741,0.421230,0.026017,-84.157959,0.002168,0.000000
84.590004,1.845856,-84.202438,0.000742,0.000101,0.002567,8.210776,0.418277,0.025669,-84.202438,0.002117,0.000000
84.910004,1.867821,-84.202438,0.000733,0.000096,0.002446,8.308481,0.423254,0.024458,-84.202438,0.002064,0.000000
85.230003,1.851814,-84.202438,0.000716,0.000094,0.002385,8.237281,0.419627,0.023852,-84.202438,0.002012,0.000000
85.550003,1.886444,-84.157959,0.000711,0.000094,0.002376,8.391322,0.427474,0.023762,-84.157959,0.001951,0.000000
85.870003,1.858887,-84.202438,0.000720,0.000092,0.002333,8.268741,0.421230,0.023330,-84.202438,0.001899,0.000000
86.190002,1.824631,-84.202438,0.000724,0.000092,0.002333,8.116363,0.413467,0.023330,-84.202438,0.001847,0.000000
86.510002,1.831703,-84.157959,0.000729,0.000090,0.002290,8.147822,0.415070,0.022899,-84.157959,0.001796,0.000000
86.830002,1.827606,-84.157959,0.000733,0.000090,0.002290,8.129599,0.414141,0.022899,-84.157959,0.001743,0.000000
87.150002,1.825371,-84.202438,0.000720,0.000086,0.002177,8.119655,0.413635,0.021771,-84.202438,0.001691,0.000000
87.470001,1.827606,-84.246918,0.000746,0.000084,0.002134,8.129599,0.414141,0.021339,-84.246918,0.001631,0.000000
87.790001,1.827606,-84.291405,0.000733,0.000082,0.002090,8.129599,0.414141,0.020900,-84.291405,0.001578,0.000000
88.110001,1.827980,-84.202438,0.000724,0.000082,0.002082,8.131261,0.414226,0.020817,-84.202438,0.001527,0.000000
88.430008,1.845482,-84.202438,0.000711,0.000081,0.002064,8.209113,0.418192,0.020643,-84.202438,0.001475,0.000000
88.750008,1.816811,-84.246918,0.000729,0.000075,0.001908,8.081577,0.411695,0.019083,-84.246918,0.001422,0.000000
89.070007,1.808617,-84.246918,0.000729,0.000075,0.001899,8.045129,0.409838,0.018993,-84.246918,0.001370,0.000000
89.390007,1.819046,-84.291405,0.000737,0.000074,0.001874,8.091521,0.412202,0.018735,-84.291405,0.001319,0.000000
89.710007,1.849579,-84.335884,0.000737,0.000074,0.001874,8.227338,0.419121,0.018735,-84.335884,0.001257,0.000000
90.030006,1.821648,-84.246918,0.000729,0.000070,0.001769,8.103093,0.412791,0.017691,-84.246918,0.001206,0.000000
90.350006,1.836548,-84.291405,0.000720,0.000070,0.001769,8.169373,0.416168,0.017691,-84.291405,0.001154,0.000000
90.670006,1.836548,-84.380363,0.000716,0.000067,0.001691,8.169373,0.416168,0.016911,-84.380363,0.001101,0.000000
90.990005,1.835800,-84.335884,0.000737,0.000067,0.001691,8.166047,0.415998,0.016911,-84.335884,0.001049,0.000000
91.310005,1.803406,-84.335884,0.000724,0.000060,0.001527,8.021950,0.408658,0.015268,-84.335884,0.000998,0.000000
91.630005,1.797073,-84.335884,0.000724,0.000058,0.001483,7.993782,0.407223,0.014829,-84.335884,0.000945,0.000000
91.950005,1.801910,-84.335884,0.000729,0.000057,0.001440,8.015298,0.408319,0.014398,-84.335884,0.000885,0.000000
92.270004,1.828354,-84.380363,0.000737,0.000057,0.001440,8.132924,0.414311,0.014398,-84.380363,0.000833,0.000000
92.590004,1.822021,-84.380363,0.000720,0.000055,0.001388,8.104756,0.412876,0.013875,-84.380363,0.000780,0.000000
92.910004,1.800797,-84.335884,0.000720,0.000051,0.001301,8.010343,0.408066,0.013012,-84.335884,0.000729,0.000000
93.230003,1.818672,-84.380363,0.000711,0.000051,0.001292,8.089858,0.412117,0.012922,-84.380363,0.000677,0.000000
93.550003,1.804893,-84.380363,0.000733,0.000048,0.001214,8.028567,0.408995,0.012142,-84.380363,0.000625,0.000000
93.870003,1.791489,-84.469330,0.000737,0.000045,0.001154,7.968939,0.405957,0.011536,-84.469330,0.000564,0.000000
94.190002,1.800797,-84.424843,0.000733,0.000044,0.001110,8.010343,0.408066,0.011105,-84.424843,0.000512,0.000000
94.510002,1.777336,-84.424843,0.000737,0.000040,0.001023,7.905986,0.402750,0.010234,-84.424843,0.000459,0.000000
94.830002,1.769142,-84.335884,0.000711,0.000038,0.000963,7.869537,0.400893,0.009629,-84.335884,0.000408,0.000000
95.150002,1.764679,-84.469330,0.000720,0.000035,0.000885,7.849684,0.399882,0.008849,-84.469330,0.000356,0.000000
95.470001,1.771751,-84.513809,0.000729,0.000035,0.000885,7.881144,0.401485,0.008849,-84.513809,0.000304,0.000000
95.790001,1.776596,-84.424843,0.000742,0.000034,0.000858,7.902694,0.402582,0.008584,-84.424843,0.000251,0.000000
96.110008,1.783669,-84.469330,0.000742,0.000033,0.000842,7.934154,0.404185,0.008418,-84.469330,0.000191,0.000000
96.430008,1.767281,-84.469330,0.000737,0.000030,0.000763,7.861257,0.400472,0.007630,-84.469330,0.000139,0.000000
96.750008,1.686478,-84.424843,0.000720,0.000023,0.000572,7.501827,0.382161,0.005723,-84.424843,0.000087,0.000000
97.070007,1.671959,-84.558289,0.000711,0.000021,0.000529,7.437245,0.378871,0.005291,-84.558289,0.000035,0.000000
97.390007,1.675308,-84.513809,0.000733,0.000019,0.000486,7.452143,0.379630,0.004860,-84.513809,-0.000017,0.000000
97.710007,1.644402,-84.469330,0.000737,0.000017,0.000434,7.314663,0.372627,0.004337,-84.469330,-0.000069,0.000000
98.030006,1.602692,-84.513809,0.000724,0.000015,0.000373,7.129128,0.363175,0.003732,-84.513809,-0.000121,0.000000
98.350006,1.584450,-84.469330,0.000737,0.000012,0.000313,7.047985,0.359041,0.003126,-84.469330,-0.000182,0.000000
98.670006,1.579239,-84.558289,0.000729,0.000011,0.000269,7.024806,0.357861,0.002687,-84.558289,-0.000234,0.000000
98.990005,1.547211,-84.602768,0.000729,0.000007,0.000182,6.882337,0.350603,0.001824,-84.602768,-0.000286,0.000000
99.310005,1.555779,-84.513809,0.000750,0.000006,0.000148,6.920448,0.352544,0.001476,-84.513809,-0.000338,0.000000
99.630005,1.548332,-84.513809,0.000755,0.000004,0.000113,6.887326,0.350857,0.001128,-84.513809,-0.000390,0.000000
99.950005,1.546097,-84.513809,0.000742,0.000004,0.000095,6.877382,0.350351,0.000954,-84.513809,-0.000442,0.000000
100.270004,1.518539,-84.602768,0.000720,0.000001,0.000026,6.754801,0.344106,0.000265,-84.602768,-0.000503,0.000000
100.590004,1.480560,-84.558289,0.000733,-0.000001,-0.000026,6.585861,0.335500,-0.000257,-84.558289,-0.000555,0.000000
100.910004,1.467896,-84.558289,0.000707,-0.000002,-0.000043,6.529525,0.332630,-0.000431,-84.558289,-0.000607,0.000000
101.230003,1.444061,-84.558289,0.000724,-0.000004,-0.000113,6.423505,0.327229,-0.001128,-84.558289,-0.000659,0.000000
101.550003,1.462311,-84.602768,0.000742,-0.000005,-0.000139,6.504683,0.331364,-0.001385,-84.602768,-0.000711,0.000000
101.870003,1.452629,-84.602768,0.000716,-0.000007,-0.000173,6.461617,0.329170,-0.001733,-84.602768,-0.000763,0.000000
102.190002,1.435501,-84.602768,0.000733,-0.000008,-0.000199,6.385428,0.325289,-0.001991,-84.602768,-0.000815,0.000000
102.510002,1.429916,-84.602768,0.000737,-0.000010,-0.000243,6.360586,0.324024,-0.002430,-84.602768,-0.000876,0.000000
102.830002,1.392677,-84.691734,0.000720,-0.000013,-0.000321,6.194938,0.315585,-0.003210,-84.691734,-0.000928,0.000000
103.150002,1.373314,-84.647247,0.000742,-0.000014,-0.000355,6.108805,0.311197,-0.003550,-84.647247,-0.000980,0.000000
103.470001,1.359909,-84.691734,0.000729,-0.000015,-0.000390,6.049178,0.308160,-0.003898,-84.691734,-0.001032,0.000000
103.790009,1.360283,-84.691734,0.000724,-0.000016,-0.000399,6.050840,0.308244,-0.003989,-84.691734,-0.001084,0.000000
104.110008,1.352837,-84.602768,0.000733,-0.000019,-0.000477,6.017718,0.306557,-0.004769,-84.602768,-0.001136,0.000000
104.430008,1.334213,-84.691734,0.000737,-0.000020,-0.000503,5.934877,0.302337,-0.005026,-84.691734,-0.001188,0.000000
104.750008,1.303680,-84.691734,0.000724,-0.000023,-0.000572,5.799060,0.295418,-0.005723,-84.691734,-0.001248,0.000000
105.070007,1.279106,-84.691734,0.000737,-0.000025,-0.000625,5.689748,0.289850,-0.006245,-84.691734,-0.001300,0.000000
105.390007,1.267563,-84.691734,0.000742,-0.000026,-0.000650,5.638401,0.287234,-0.006502,-84.691734,-0.001353,0.000000
105.710007,1.243729,-84.691734,0.000733,-0.000026,-0.000668,5.532381,0.281833,-0.006677,-84.691734,-0.001405,0.000000
106.030006,1.258247,-84.647247,0.000720,-0.000027,-0.000676,5.596964,0.285123,-0.006760,-84.647247,-0.001456,0.000000
106.350006,1.205376,-84.780693,0.000724,-0.000029,-0.000737,5.361779,0.273142,-0.007373,-84.780693,-0.001509,0.000000
106.670006,1.232559,-84.780693,0.000746,-0.000029,-0.000737,5.482697,0.279302,-0.007373,-84.780693,-0.001569,0.000000
106.990005,1.235909,-84.780693,0.000746,-0.000029,-0.000737,5.497596,0.280061,-0.007373,-84.780693,-0.001621,0.000000
107.310005,1.123825,-84.691734,0.000742,-0.000039,-0.000989,4.999023,0.254662,-0.009886,-84.691734,-0.001674,0.000000
107.630005,1.104088,-84.736214,0.000759,-0.000040,-0.001006,4.911228,0.250190,-0.010060,-84.736214,-0.001726,0.000000
107.950005,1.094032,-84.736214,0.000724,-0.000041,-0.001041,4.866498,0.247911,-0.010408,-84.736214,-0.001777,0.000000
108.270004,1.083237,-84.780693,0.000742,-0.000041,-0.001041,4.818478,0.245465,-0.010408,-84.780693,-0.001830,0.000000
108.590004,1.053444,-84.780693,0.000733,-0.000046,-0.001162,4.685953,0.238714,-0.011620,-84.780693,-0.001882,0.000000
108.910004,1.034828,-84.780693,0.000737,-0.000046,-0.001162,4.603146,0.234495,-0.011620,-84.780693,-0.001942,0.000000
109.230003,1.046745,-84.780693,0.000733,-0.000046,-0.001162,4.656156,0.237196,-0.011620,-84.780693,-0.001995,0.000000
109.550003,1.078766,-84.869652,0.000724,-0.000046,-0.001170,4.798590,0.244452,-0.011703,-84.869652,-0.002046,0.000000
109.870003,0.974129,-84.825172,0.000724,-0.000053,-0.001335,4.333141,0.220741,-0.013353,-84.825172,-0.002098,0.000000
110.190002,0.971527,-84.825172,0.000724,-0.000053,-0.001335,4.321568,0.220151,-0.013353,-84.825172,-0.002151,0.000000
110.510002,0.995728,-84.780693,0.000737,-0.000053,-0.001335,4.429217,0.225635,-0.013353,-84.780693,-0.002203,0.000000
110.830002,0.908966,-84.825172,0.000724,-0.000058,-0.001483,4.043283,0.205975,-0.014829,-84.825172,-0.002254,0.000000
111.150002,0.891464,-84.869652,0.000724,-0.000061,-0.001561,3.965431,0.202009,-0.015609,-84.869652,-0.002316,0.000000
111.470009,0.857948,-84.914139,0.000711,-0.000064,-0.001631,3.816345,0.194414,-0.016305,-84.914139,-0.002367,0.000000
111.790009,0.878059,-84.825172,0.000729,-0.000064,-0.001631,3.905803,0.198971,-0.016305,-84.825172,-0.002419,0.000000
112.110008,0.857574,-84.869652,0.000733,-0.000066,-0.001674,3.814682,0.194329,-0.016737,-84.869652,-0.002472,0.000000
112.430008,0.826668,-84.869652,0.000707,-0.000069,-0.001752,3.677202,0.187326,-0.017516,-84.869652,-0.002524,0.000000
112.750008,0.794647,-84.869652,0.000694,-0.000072,-0.001839,3.534767,0.180070,-0.018387,-84.869652,-0.002575,0.000000
113.070007,0.805817,-84.914139,0.000716,-0.000072,-0.001839,3.584451,0.182601,-0.018387,-84.914139,-0.002636,0.000000
113.390007,0.772301,-84.914139,0.000729,-0.000076,-0.001925,3.435365,0.175006,-0.019250,-84.914139,-0.002688,0.000000
113.710007,0.739166,-84.869652,0.000724,-0.000078,-0.001977,3.287976,0.167497,-0.019772,-84.869652,-0.002740,0.000000
114.030006,0.722031,-84.869652,0.000711,-0.000081,-0.002055,3.211753,0.163614,-0.020552,-84.869652,-0.002792,0.000000
114.350006,0.695595,-85.003098,0.000716,-0.000084,-0.002125,3.094160,0.157624,-0.021248,-85.003098,-0.002844,0.000000
114.670006,0.700806,-84.958618,0.000724,-0.000085,-0.002168,3.117339,0.158805,-0.021680,-84.958618,-0.002896,0.000000
114.990005,0.663574,-85.003098,0.000720,-0.000088,-0.002229,2.951725,0.150368,-0.022285,-85.003098,-0.002948,0.000000
115.310005,0.646072,-84.914139,0.000724,-0.000090,-0.002298,2.873873,0.146402,-0.022982,-84.914139,-0.003009,0.000000
115.630005,0.631172,-84.914139,0.000694,-0.000090,-0.002298,2.807594,0.143026,-0.022982,-84.914139,-0.003061,0.000000
115.950005,0.619629,-85.003098,0.000703,-0.000093,-0.002359,2.756247,0.140410,-0.023587,-85.003098,-0.003113,0.000000
116.270004,0.604362,-85.003098,0.000703,-0.000093,-0.002367,2.688339,0.136950,-0.023671,-85.003098,-0.003165,0.000000
116.590004,0.582397,-85.047577,0.000711,-0.000099,-0.002506,2.590633,0.131973,-0.025064,-85.047577,-0.003217,0.000000
116.910004,0.567123,-85.003098,0.000720,-0.000099,-0.002524,2.522691,0.128512,-0.025238,-85.003098,-0.003269,0.000000
117.230003,0.550369,-85.047577,0.000686,-0.000102,-0.002602,2.448165,0.124715,-0.026017,-85.047577,-0.003322,0.000000
117.550003,0.535851,-85.047577,0.000707,-0.000104,-0.002636,2.383582,0.121425,-0.026358,-85.047577,-0.003382,0.000000
117.870003,0.538452,-85.092056,0.000690,-0.000104,-0.002645,2.395155,0.122015,-0.026449,-85.092056,-0.003434,0.000000
118.190002,0.541809,-85.047577,0.000698,-0.000106,-0.002680,2.410087,0.122776,-0.026797,-85.047577,-0.003486,0.000000
118.510002,0.528030,-85.047577,0.000686,-0.000108,-0.002740,2.348797,0.119653,-0.027403,-85.047577,-0.003538,0.000000
118.830002,0.476639,-85.003098,0.000698,-0.000111,-0.002827,2.120195,0.108008,-0.028273,-85.003098,-0.003590,0.000000
119.150009,0.449829,-85.092056,0.000690,-0.000114,-0.002888,2.000940,0.101933,-0.028879,-85.092056,-0.003642,0.000000
119.470009,0.437538,-85.092056,0.000707,-0.000115,-0.002914,1.946267,0.099148,-0.029136,-85.092056,-0.003703,0.000000
119.790009,0.427116,-85.181023,0.000694,-0.000116,-0.002948,1.899909,0.096786,-0.029484,-85.181023,-0.003755,0.000000
120.110008,0.423767,-85.092056,0.000707,-0.000118,-0.003009,1.885010,0.096027,-0.030090,-85.092056,-0.003807,0.000000
120.430008,0.395836,-85.047577,0.000694,-0.000121,-0.003070,1.760766,0.089698,-0.030695,-85.047577,-0.003859,0.000000
120.750008,0.393227,-85.136543,0.000690,-0.000123,-0.003113,1.749159,0.089106,-0.031135,-85.136543,-0.003911,0.000000
121.070007,0.378708,-85.092056,0.000690,-0.000124,-0.003139,1.684577,0.085816,-0.031392,-85.092056,-0.003963,0.000000
121.390007,0.367165,-85.136543,0.000681,-0.000127,-0.003226,1.633230,0.083201,-0.032262,-85.136543,-0.004015,0.000000
121.710007,0.341469,-85.092056,0.000698,-0.000129,-0.003278,1.518929,0.077378,-0.032777,-85.092056,-0.004076,0.000000
122.030006,0.331039,-85.092056,0.000677,-0.000131,-0.003322,1.472537,0.075015,-0.033216,-85.092056,-0.004128,0.000000
122.350006,0.331039,-85.136543,0.000677,-0.000133,-0.003373,1.472537,0.075015,-0.033731,-85.136543,-0.004180,0.000000
122.670006,0.329926,-85.181023,0.000698,-0.000134,-0.003408,1.467582,0.074762,-0.034079,-85.181023,-0.004232,0.000000
122.990005,0.296410,-85.181023,0.000686,-0.000136,-0.003451,1.318496,0.067167,-0.034511,-85.181023,-0.004284,0.000000
123.310005,0.327316,-85.136543,0.000690,-0.000137,-0.003478,1.455976,0.074171,-0.034776,-85.136543,-0.004336,0.000000
123.630005,0.294182,-85.181023,0.000681,-0.000139,-0.003530,1.308586,0.066663,-0.035298,-85.181023,-0.004388,0.000000
123.950005,0.300507,-85.181023,0.000647,-0.000140,-0.003564,1.336720,0.068096,-0.035639,-85.181023,-0.004449,0.000000
124.270004,0.311676,-85.269981,0.000673,-0.000142,-0.003616,1.386404,0.070627,-0.036161,-85.269981,-0.004501,0.000000
124.590004,0.303490,-85.225502,0.000664,-0.000144,-0.003668,1.349990,0.068772,-0.036683,-85.225502,-0.004552,0.000000
124.910004,0.306091,-85.225502,0.000651,-0.000145,-0.003694,1.361562,0.069361,-0.036941,-85.225502,-0.004605,0.000000
125.230003,0.293060,-85.181023,0.000677,-0.000146,-0.003721,1.303597,0.066408,-0.037206,-85.181023,-0.004657,0.000000
125.550003,0.278908,-85.225502,0.000660,-0.000149,-0.003772,1.240644,0.063201,-0.037720,-85.225502,-0.004709,0.000000
125.870003,0.263641,-85.269981,0.000677,-0.000153,-0.003876,1.172735,0.059742,-0.038765,-85.269981,-0.004770,0.000000
126.190002,0.261780,-85.225502,0.000668,-0.000155,-0.003937,1.164455,0.059320,-0.039370,-85.225502,-0.004822,0.000000
126.510010,0.212997,-85.225502,0.000660,-0.000159,-0.004050,0.947460,0.048266,-0.040498,-85.225502,-0.004873,0.000000
126.830009,0.172409,-85.225502,0.000638,-0.000163,-0.004128,0.766914,0.039068,-0.041278,-85.225502,-0.004926,0.000000
127.150009,0.179863,-85.269981,0.000651,-0.000164,-0.004163,0.800070,0.040758,-0.041626,-85.269981,-0.004978,0.000000
127.470009,0.210022,-85.269981,0.000642,-0.000165,-0.004180,0.934224,0.047592,-0.041800,-85.269981,-0.005029,0.000000
127.790009,0.173531,-85.358948,0.000668,-0.000169,-0.004284,0.771903,0.039323,-0.042837,-85.358948,-0.005082,0.000000
128.110001,0.138901,-85.269981,0.000660,-0.000171,-0.004336,0.617861,0.031475,-0.043360,-85.269981,-0.005142,0.000000
128.430008,0.158638,-85.269981,0.000634,-0.000171,-0.004336,0.705657,0.035948,-0.043360,-85.269981,-0.005194,0.000000
128.750000,0.173157,-85.314461,0.000647,-0.000171,-0.004336,0.770240,0.039238,-0.043360,-85.314461,-0.005247,0.000000
129.070007,0.178741,-85.358948,0.000642,-0.000173,-0.004397,0.795082,0.040503,-0.043965,-85.358948,-0.005299,0.000000
129.389999,0.164223,-85.358948,0.000647,-0.000179,-0.004535,0.730499,0.037213,-0.045351,-85.358948,-0.005350,0.000000
129.710007,0.137039,-85.314461,0.000625,-0.000180,-0.004562,0.609581,0.031054,-0.045616,-85.314461,-0.005403,0.000000
130.029999,0.130707,-85.314461,0.000642,-0.000183,-0.004640,0.581413,0.029619,-0.046395,-85.314461,-0.005455,0.000000
130.350006,0.143738,-85.403427,0.000634,-0.000183,-0.004640,0.639378,0.032571,-0.046395,-85.403427,-0.005515,0.000000
130.670013,0.143738,-85.403427,0.000634,-0.000183,-0.004640,0.639378,0.032571,-0.046395,-85.403427,-0.005568,0.000000
130.990005,0.146347,-85.314461,0.000634,-0.000183,-0.004640,0.650984,0.033163,-0.046395,-85.314461,-0.005619,0.000000
131.310013,0.111717,-85.403427,0.000617,-0.000187,-0.004752,0.496943,0.025315,-0.047523,-85.403427,-0.005671,0.000000
131.630005,0.106873,-85.403427,0.000612,-0.000187,-0.004752,0.475393,0.024218,-0.047523,-85.403427,-0.005724,0.000000
131.950012,0.120651,-85.358948,0.000629,-0.000189,-0.004795,0.536684,0.027340,-0.047955,-85.358948,-0.005776,0.000000
132.270004,0.122139,-85.447906,0.000595,-0.000192,-0.004873,0.543301,0.027677,-0.048734,-85.447906,-0.005836,0.000000
132.590012,0.098686,-85.403427,0.000638,-0.000194,-0.004934,0.438978,0.022363,-0.049340,-85.403427,-0.005889,0.000000
132.910004,0.094955,-85.403427,0.000617,-0.000200,-0.005082,0.422383,0.021517,-0.050816,-85.403427,-0.005940,0.000000
133.230011,0.093468,-85.403427,0.000595,-0.000200,-0.005082,0.415765,0.021180,-0.050816,-85.403427,-0.005992,0.000000
133.550003,0.090866,-85.492386,0.000591,-0.000203,-0.005160,0.404193,0.020591,-0.051596,-85.492386,-0.006044,0.000000
133.870010,0.067772,-85.403427,0.000612,-0.000203,-0.005169,0.301465,0.015357,-0.051687,-85.403427,-0.006097,0.000000
134.190002,0.065910,-85.403427,0.000612,-0.000208,-0.005281,0.293184,0.014935,-0.052814,-85.403427,-0.006148,0.000000
134.510010,0.053627,-85.447906,0.000595,-0.000210,-0.005342,0.238545,0.012152,-0.053420,-85.447906,-0.006209,0.000000
134.830002,0.059212,-85.358948,0.000612,-0.000212,-0.005385,0.263387,0.013418,-0.053851,-85.358948,-0.006261,0.000000
135.150009,0.061073,-85.492386,0.000591,-0.000214,-0.005437,0.271668,0.013839,-0.054374,-85.492386,-0.006313,0.000000
135.470001,0.051392,-85.536865,0.000612,-0.000216,-0.005490,0.228601,0.011646,-0.054896,-85.536865,-0.006365,0.000000
135.790009,0.061447,-85.536865,0.000582,-0.000218,-0.005533,0.273331,0.013924,-0.055328,-85.536865,-0.006417,0.000000
136.110001,0.073364,-85.492386,0.000578,-0.000218,-0.005533,0.326341,0.016625,-0.055328,-85.492386,-0.006469,0.000000
136.430008,0.058838,-85.447906,0.000591,-0.000218,-0.005533,0.261724,0.013333,-0.055328,-85.447906,-0.006521,0.000000
136.750000,0.045807,-85.536865,0.000578,-0.000219,-0.005568,0.203759,0.010380,-0.055676,-85.536865,-0.006582,0.000000
137.070007,0.037987,-85.536865,0.000578,-0.000227,-0.005767,0.168974,0.008608,-0.057667,-85.536865,-0.006634,0.000000
137.389999,0.041336,-85.581352,0.000569,-0.000230,-0.005845,0.183872,0.009367,-0.058446,-85.581352,-0.006686,0.000000
137.710007,0.037239,-85.536865,0.000578,-0.000230,-0.005854,0.165648,0.008438,-0.058537,-85.536865,-0.006738,0.000000
138.030014,0.036499,-85.536865,0.000573,-0.000231,-0.005862,0.162356,0.008271,-0.058620,-85.536865,-0.006790,0.000000
138.350006,0.032402,-85.536865,0.000552,-0.000231,-0.005879,0.144131,0.007342,-0.058795,-85.536865,-0.006842,0.000000
138.670013,0.048409,-85.625832,0.000565,-0.000236,-0.005984,0.215332,0.010970,-0.059839,-85.625832,-0.006903,0.000000
138.990005,0.019737,-85.625832,0.000560,-0.000239,-0.006062,0.087796,0.004473,-0.060619,-85.625832,-0.006955,0.000000
139.310013,0.001869,-85.625832,0.000565,-0.000241,-0.006114,0.008315,0.000424,-0.061141,-85.625832,-0.007007,0.000000
139.500000,0.008194,-85.536865,0.000565,-0.000236,-0.006001,0.036449,0.001857,-0.060013,-85.536865,-0.006122,0.000000