File: Data/PDMS 0040002 test 2_10242023_175643.csv
Time (sec),S:Load (lbs),S:HL1 (DIM),S:LVDT (in),S:Position (in),Ch:Position (mm),Ch:Load (N),Ch:Stress (MPa),Ch:Strain (mm/mm),Ch:HL1 (DIM),Set Point (),Cycles ()
0.110000,-0.069633,-34.917545,0.017186,-0.002970,-0.075441,-0.309745,-0.015779,-0.754405,-34.917545,-0.075657,0.000000
0.250000,-0.063675,-34.828587,0.017177,-0.002970,-0.075441,-0.283240,-0.014429,-0.754405,-34.828587,-0.075657,0.000000
0.390000,-0.052132,-34.917545,0.017164,-0.002970,-0.075441,-0.231893,-0.011813,-0.754405,-34.917545,-0.075657,0.000000
0.530000,-0.061813,-34.828587,0.017199,-0.002923,-0.074235,-0.274960,-0.014007,-0.742347,-34.828587,-0.073472,0.000000
0.670000,-0.043938,-34.828587,0.017181,-0.002831,-0.071911,-0.195445,-0.009956,-0.719107,-34.828587,-0.071148,0.000000
0.810000,-0.020111,-34.784103,0.017233,-0.002748,-0.069795,-0.089459,-0.004557,-0.697950,-34.784103,-0.068806,0.000000
0.950000,-0.049156,-34.873066,0.017302,-0.002663,-0.067653,-0.218658,-0.011139,-0.676527,-34.873066,-0.066482,0.000000
1.090000,-0.051758,-34.828587,0.017410,-0.002569,-0.065259,-0.230230,-0.011728,-0.652592,-34.828587,-0.064140,0.000000
1.230000,-0.008194,-34.873066,0.017522,-0.002479,-0.062969,-0.036449,-0.001857,-0.629693,-34.873066,-0.061816,0.000000
1.370000,-0.023087,-34.828587,0.017625,-0.002389,-0.060671,-0.102694,-0.005231,-0.606711,-34.828587,-0.059474,0.000000
1.510000,-0.046173,-34.873066,0.017716,-0.002290,-0.058174,-0.205388,-0.010463,-0.581738,-34.873066,-0.057150,0.000000
1.650000,-0.010429,-34.828587,0.017802,-0.002198,-0.055841,-0.046392,-0.002363,-0.558408,-34.828587,-0.054809,0.000000
1.790000,-0.022713,-34.873066,0.017897,-0.002115,-0.053725,-0.101031,-0.005147,-0.537251,-34.873066,-0.052485,0.000000
1.930000,-0.035378,-34.828587,0.018005,-0.002017,-0.051227,-0.157367,-0.008017,-0.512270,-34.828587,-0.050143,0.000000
2.070000,-0.056229,-34.873066,0.018083,-0.001925,-0.048903,-0.250117,-0.012742,-0.489031,-34.873066,-0.047819,0.000000
2.210000,-0.027931,-34.917545,0.018182,-0.001835,-0.046614,-0.124244,-0.006329,-0.466140,-34.917545,-0.045478,0.000000
2.350000,-0.030533,-34.828587,0.018281,-0.001748,-0.044402,-0.135817,-0.006919,-0.444021,-34.828587,-0.043153,0.000000
2.490000,-0.066658,-34.917545,0.018358,-0.001655,-0.042043,-0.296510,-0.015105,-0.420434,-34.917545,-0.040812,0.000000
2.630000,-0.040962,-34.917545,0.018471,-0.001563,-0.039693,-0.182209,-0.009282,-0.396930,-34.917545,-0.038488,0.000000
2.770000,-0.035751,-34.873066,0.018552,-0.001469,-0.037317,-0.159030,-0.008101,-0.373168,-34.873066,-0.036147,0.000000
2.910000,-0.043198,-34.962029,0.018673,-0.001380,-0.035053,-0.192153,-0.009789,-0.350534,-34.962029,-0.033822,0.000000
3.050000,-0.064423,-34.917545,0.018746,-0.001287,-0.032686,-0.286566,-0.014598,-0.326864,-34.917545,-0.031498,0.000000
3.190000,-0.026810,-34.917545,0.018850,-0.001197,-0.030406,-0.119255,-0.006075,-0.304056,-34.917545,-0.029157,0.000000
3.330000,-0.010056,-34.917545,0.018958,-0.001107,-0.028107,-0.044729,-0.002279,-0.281074,-34.917545,-0.026833,0.000000
3.470000,-0.049156,-34.828587,0.019066,-0.001015,-0.025774,-0.218658,-0.011139,-0.257744,-34.828587,-0.024491,0.000000
3.610000,-0.039474,-34.917545,0.019165,-0.000916,-0.023259,-0.175591,-0.008945,-0.232589,-34.917545,-0.022167,0.000000
3.750000,-0.000000,-34.917545,0.019238,-0.000826,-0.020987,-0.000000,-0.000000,-0.209872,-34.917545,-0.019825,0.000000
3.890000,-0.017876,-34.962029,0.019341,-0.000737,-0.018732,-0.079515,-0.004051,-0.187322,-34.962029,-0.017501,0.000000
4.030000,-0.027184,-34.917545,0.019454,-0.000640,-0.016261,-0.120918,-0.006160,-0.162607,-34.917545,-0.015159,0.000000
4.170000,-0.020485,-34.917545,0.019527,-0.000552,-0.014015,-0.091121,-0.004642,-0.140147,-34.917545,-0.012835,0.000000
4.310000,-0.010429,-34.917545,0.019617,-0.000464,-0.011786,-0.046392,-0.002363,-0.117862,-34.917545,-0.010494,0.000000
4.450000,-0.027557,-34.917545,0.019712,-0.000370,-0.009401,-0.122581,-0.006245,-0.094009,-34.917545,-0.008169,0.000000
4.590000,-0.060699,-34.873066,0.019816,-0.000281,-0.007138,-0.270005,-0.013755,-0.071376,-34.873066,-0.005828,0.000000
4.730000,-0.031281,-34.962029,0.019941,-0.000185,-0.004701,-0.139143,-0.007088,-0.047008,-34.962029,-0.003504,0.000000
4.870000,0.002235,-34.962029,0.020010,-0.000090,-0.002298,0.009944,0.000507,-0.022982,-34.962029,-0.001163,0.000000
5.010000,-0.016388,-35.006508,0.020105,0.000001,0.000026,-0.072897,-0.003714,0.000257,-35.006508,0.001162,0.000000
5.150000,0.045799,-34.917545,0.020212,0.000090,0.002281,0.203725,0.010378,0.022808,-34.917545,0.003503,0.000000
5.290000,0.205551,-34.962029,0.020312,0.000179,0.004552,0.914337,0.046579,0.045525,-34.962029,0.005827,0.000000
5.430000,0.565262,-34.917545,0.020406,0.000271,0.006877,2.514410,0.128090,0.068772,-34.917545,0.008169,0.000000
5.570000,0.655373,-35.006508,0.020419,-0.000000,-0.000000,2.915243,0.148510,-0.000000,-35.006508,0.000295,0.000000
5.710000,0.608452,-34.962029,0.020437,-0.000000,-0.000000,2.706529,0.137877,-0.000000,-34.962029,0.000295,0.000000
5.850000,0.594681,-34.873066,0.020450,-0.000000,-0.000000,2.645272,0.134757,-0.000000,-34.873066,0.000295,0.000000
5.990000,0.579781,-35.006508,0.020432,-0.000000,-0.000000,2.578993,0.131380,-0.000000,-35.006508,0.000295,0.000000
6.130000,0.572708,-35.006508,0.020441,-0.000000,-0.000000,2.547533,0.129778,-0.000000,-35.006508,0.000521,0.000000
6.270000,0.572334,-34.962029,0.020428,-0.000000,-0.000000,2.545870,0.129693,-0.000000,-34.962029,0.000746,0.000000
6.410000,0.578293,-35.006508,0.020454,-0.000000,-0.000000,2.572375,0.131043,-0.000000,-35.006508,0.000980,0.000000
6.550000,0.617767,-35.006508,0.020419,0.000010,0.000243,2.747966,0.139988,0.002430,-35.006508,0.001214,0.000000
6.690001,0.628937,-35.006508,0.020441,0.000010,0.000243,2.797651,0.142519,0.002430,-35.006508,0.001448,0.000000
6.830000,0.725380,-34.962029,0.020445,0.000024,0.000616,3.226651,0.164373,0.006162,-34.962029,0.001683,0.000000
6.970000,0.793152,-34.962029,0.020475,0.000034,0.000858,3.528116,0.179731,0.008584,-34.962029,0.001917,0.000000
7.110000,0.862038,-35.006508,0.020437,0.000044,0.001128,3.834535,0.195341,0.011279,-35.006508,0.002151,0.000000
7.250000,0.944710,-34.962029,0.020475,0.000054,0.001362,4.202279,0.214074,0.013618,-34.962029,0.002385,0.000000
7.390000,1.005035,-35.006508,0.020488,0.000062,0.001578,4.470621,0.227744,0.015783,-35.006508,0.002619,0.000000
7.530000,1.034821,-34.962029,0.020480,0.000069,0.001752,4.603112,0.234494,0.017516,-34.962029,0.002853,0.000000
7.670001,1.140579,-34.962029,0.020506,0.000079,0.002004,5.073550,0.258459,0.020037,-34.962029,0.003088,0.000000
7.810000,1.199409,-35.006508,0.020523,0.000089,0.002255,5.335240,0.271790,0.022550,-35.006508,0.003313,0.000000
7.950000,1.298836,-35.006508,0.020527,0.000097,0.002454,5.777510,0.294320,0.024541,-35.006508,0.003547,0.000000
8.090000,1.444801,-35.006508,0.020531,0.000110,0.002802,6.426797,0.327397,0.028016,-35.006508,0.003781,0.000000
8.230000,1.515930,-35.006508,0.020549,0.000115,0.002914,6.743194,0.343515,0.029144,-35.006508,0.004016,0.000000
8.370001,1.641418,-35.050991,0.020519,0.000125,0.003183,7.301394,0.371951,0.031831,-35.050991,0.004250,0.000000
8.510000,1.717751,-34.962029,0.020536,0.000131,0.003331,7.640936,0.389248,0.033307,-34.962029,0.004484,0.000000
8.650001,1.700996,-35.006508,0.020583,0.000132,0.003365,7.566410,0.385451,0.033648,-35.006508,0.004718,0.000000
8.790000,1.991447,-35.050991,0.020575,0.000152,0.003859,8.858400,0.451268,0.038591,-35.050991,0.004952,0.000000
8.930000,2.112465,-35.050991,0.020592,0.000160,0.004076,9.396713,0.478691,0.040763,-35.050991,0.005186,0.000000
9.070001,2.317276,-35.006508,0.020592,0.000175,0.004440,10.307758,0.525102,0.044404,-35.006508,0.005421,0.000000
9.210000,2.447601,-35.006508,0.020609,0.000184,0.004683,10.887474,0.554634,0.046834,-35.006508,0.005655,0.000000
9.350000,2.573090,-35.050991,0.020605,0.000195,0.004952,11.445674,0.583070,0.049522,-35.050991,0.005880,0.000000
9.490001,2.678848,-35.050991,0.020600,0.000203,0.005160,11.916112,0.607036,0.051603,-35.050991,0.006114,0.000000
9.630000,2.818855,-35.050991,0.020639,0.000213,0.005421,12.538895,0.638762,0.054207,-35.050991,0.006348,0.000000
9.770000,2.986801,-35.095470,0.020639,0.000222,0.005628,13.285955,0.676819,0.056281,-35.095470,0.006583,0.000000
9.910001,3.172241,-35.050991,0.020639,0.000231,0.005871,14.110834,0.718840,0.058711,-35.050991,0.006817,0.000000
10.050000,3.311882,-35.050991,0.020656,0.000238,0.006054,14.731987,0.750483,0.060536,-35.050991,0.007051,0.000000
10.190001,3.463806,-35.050991,0.020678,0.000248,0.006287,15.407780,0.784910,0.062875,-35.050991,0.007285,0.000000
10.330001,3.586693,-35.095470,0.020669,0.000254,0.006443,15.954407,0.812756,0.064434,-35.095470,0.007519,0.000000
10.470000,3.702873,-35.050991,0.020678,0.000260,0.006608,16.471203,0.839083,0.066084,-35.050991,0.007753,0.000000
10.610001,3.965767,-35.139950,0.020674,0.000273,0.006947,17.640612,0.898656,0.069468,-35.139950,0.007988,0.000000
10.750001,4.182114,-35.050991,0.020700,0.000285,0.007250,18.602970,0.947681,0.072503,-35.050991,0.008222,0.000000
10.890000,4.417450,-35.050991,0.020725,0.000293,0.007449,19.649799,1.001008,0.074494,-35.050991,0.008447,0.000000
11.030001,4.547783,-35.095470,0.020730,0.000301,0.007658,20.229549,1.030542,0.076576,-35.095470,0.008681,0.000000
11.170000,4.800621,-35.050991,0.020708,0.000313,0.007944,21.354229,1.087836,0.079437,-35.050991,0.008915,0.000000
11.310000,4.999474,-35.095470,0.020717,0.000324,0.008230,22.238770,1.132897,0.082299,-35.095470,0.009150,0.000000
11.450001,5.221779,-35.050991,0.020747,0.000333,0.008455,23.227633,1.183272,0.084555,-35.050991,0.009384,0.000000
11.590000,5.400146,-35.139950,0.020751,0.000341,0.008664,24.021051,1.223691,0.086636,-35.139950,0.009617,0.000000
11.730000,5.517815,-35.050991,0.020756,0.000348,0.008837,24.544466,1.250355,0.088370,-35.050991,0.009852,0.000000
11.870001,5.878273,-35.095470,0.020764,0.000361,0.009158,26.147863,1.332036,0.091579,-35.095470,0.010086,0.000000
12.010000,6.048447,-35.095470,0.020777,0.000367,0.009331,26.904835,1.370598,0.093313,-35.095470,0.010320,0.000000
12.150001,6.170212,-35.139950,0.020790,0.000375,0.009522,27.446472,1.398190,0.095220,-35.139950,0.010555,0.000000
12.290001,6.340012,-35.095470,0.020799,0.000382,0.009713,28.201780,1.436667,0.097128,-35.095470,0.010788,0.000000
12.430000,6.488586,-35.095470,0.020794,0.000390,0.009913,28.862675,1.470335,0.099126,-35.095470,0.011014,0.000000
12.570001,6.801750,-35.139950,0.020825,0.000402,0.010216,30.255695,1.541299,0.102162,-35.139950,0.011248,0.000000
12.710001,7.201309,-35.184433,0.020799,0.000411,0.010450,32.033024,1.631840,0.104501,-35.184433,0.011483,0.000000
12.850000,7.168541,-35.095470,0.020829,0.000420,0.010658,31.887262,1.624415,0.106583,-35.095470,0.011717,0.000000
12.990001,7.877167,-35.095470,0.020825,0.000435,0.011040,35.039387,1.784992,0.110398,-35.095470,0.011950,0.000000
13.130001,7.928177,-35.139950,0.020855,0.000439,0.011144,35.266293,1.796551,0.111442,-35.139950,0.012185,0.000000
13.270000,8.300179,-35.095470,0.020855,0.000452,0.011491,36.921040,1.880847,0.114909,-35.095470,0.012419,0.000000
13.410001,8.408165,-35.139950,0.020872,0.000456,0.011586,37.401386,1.905317,0.115863,-35.139950,0.012653,0.000000
13.550000,8.783524,-35.095470,0.020850,0.000470,0.011933,39.071064,1.990375,0.119330,-35.095470,0.012887,0.000000
13.690001,9.087379,-35.184433,0.020885,0.000479,0.012159,40.422684,2.059230,0.121586,-35.184433,0.013121,0.000000
13.830001,9.332771,-35.139950,0.020876,0.000488,0.012393,41.514240,2.114836,0.123925,-35.139950,0.013347,0.000000
13.970000,9.646683,-35.095470,0.020889,0.000498,0.012645,42.910587,2.185970,0.126446,-35.095470,0.013581,0.000000
14.110001,9.927078,-35.139950,0.020894,0.000505,0.012826,44.157848,2.249508,0.128263,-35.139950,0.013815,0.000000
14.250001,9.995590,-35.184433,0.020919,0.000509,0.012931,44.462605,2.265033,0.129307,-35.184433,0.014050,0.000000
14.390000,10.293488,-35.228912,0.020911,0.000520,0.013208,45.787720,2.332538,0.132078,-35.228912,0.014283,0.000000
14.530001,10.684853,-35.095470,0.020915,0.000529,0.013425,47.528599,2.421222,0.134250,-35.095470,0.014517,0.000000
14.670001,11.208412,-35.139950,0.020907,0.000541,0.013746,49.857506,2.539862,0.137460,-35.139950,0.014752,0.000000
14.810000,11.399811,-35.228912,0.020924,0.000549,0.013937,50.708893,2.583234,0.139367,-35.228912,0.014986,0.000000
14.950001,11.714088,-35.184433,0.020924,0.000558,0.014179,52.106869,2.654450,0.141790,-35.184433,0.015220,0.000000
15.090001,12.020554,-35.228912,0.020950,0.000566,0.014370,53.470093,2.723897,0.143705,-35.228912,0.015454,0.000000
15.230000,12.455482,-35.139950,0.020967,0.000579,0.014717,55.404755,2.822453,0.147172,-35.139950,0.015688,0.000000
15.370001,12.827858,-35.139950,0.020980,0.000587,0.014916,57.061161,2.906834,0.149163,-35.139950,0.015914,0.000000
15.510001,13.062080,-35.184433,0.020988,0.000594,0.015099,58.103035,2.959910,0.150987,-35.184433,0.016148,0.000000
15.650001,13.497009,-35.184433,0.020988,0.000605,0.015367,60.037697,3.058466,0.153674,-35.184433,0.016382,0.000000
15.790001,13.777039,-35.184433,0.020971,0.000612,0.015550,61.283329,3.121922,0.155499,-35.184433,0.016616,0.000000
15.930000,14.282341,-35.228912,0.020988,0.000622,0.015792,63.531025,3.236425,0.157921,-35.228912,0.016850,0.000000
16.070002,14.301338,-35.184433,0.021001,0.000624,0.015862,63.615528,3.240730,0.158617,-35.184433,0.017084,0.000000
16.210001,14.826012,-35.184433,0.021019,0.000636,0.016165,65.949394,3.359622,0.161653,-35.184433,0.017319,0.000000
16.350000,15.189445,-35.139950,0.021006,0.000647,0.016443,67.566025,3.441978,0.164431,-35.139950,0.017553,0.000000
16.490002,15.860832,-35.184433,0.021006,0.000659,0.016747,70.552505,3.594116,0.167466,-35.184433,0.017787,0.000000
16.630001,16.281609,-35.228912,0.021032,0.000669,0.016998,72.424210,3.689465,0.169980,-35.228912,0.018021,0.000000
16.770000,16.710213,-35.228912,0.021027,0.000679,0.017249,74.330742,3.786588,0.172493,-35.228912,0.018255,0.000000
16.910002,17.298935,-35.317875,0.021036,0.000689,0.017501,76.949509,3.919995,0.175006,-35.317875,0.018481,0.000000
17.050001,17.644867,-35.184433,0.021045,0.000699,0.017761,78.488289,3.998384,0.177610,-35.184433,0.018715,0.000000
17.190001,18.030647,-35.273396,0.021045,0.000707,0.017969,80.204323,4.085803,0.179692,-35.273396,0.018949,0.000000
17.330000,18.535957,-35.273396,0.021040,0.000716,0.018186,82.452057,4.200308,0.181857,-35.273396,0.019183,0.000000
17.470001,18.931786,-35.184433,0.021066,0.000724,0.018394,84.212791,4.290004,0.183938,-35.184433,0.019417,0.000000
17.610001,19.076271,-35.317875,0.021075,0.000728,0.018489,84.855492,4.322745,0.184892,-35.317875,0.019651,0.000000
17.750000,19.801277,-35.184433,0.021066,0.000742,0.018845,88.080482,4.487033,0.188450,-35.184433,0.019886,0.000000
17.890001,20.396698,-35.228912,0.021092,0.000753,0.019114,90.729042,4.621958,0.191137,-35.228912,0.020120,0.000000
18.030001,20.783966,-35.273396,0.021079,0.000759,0.019270,92.451698,4.709714,0.192697,-35.273396,0.020354,0.000000
18.170000,20.931053,-35.317875,0.021092,0.000765,0.019426,93.105972,4.743044,0.194264,-35.317875,0.020588,0.000000
18.310001,21.559616,-35.273396,0.021109,0.000776,0.019721,95.901962,4.885479,0.197208,-35.273396,0.020822,0.000000
18.450001,22.392616,-35.228912,0.021113,0.000788,0.020016,99.607330,5.074239,0.200160,-35.228912,0.021048,0.000000
18.590000,22.870743,-35.184433,0.021118,0.000797,0.020250,101.734146,5.182584,0.202499,-35.184433,0.021282,0.000000
18.730001,23.404724,-35.273396,0.021118,0.000806,0.020466,104.109413,5.303586,0.204664,-35.273396,0.021516,0.000000
18.870001,23.976318,-35.273396,0.021126,0.000817,0.020753,106.651993,5.433111,0.207526,-35.273396,0.021750,0.000000
19.010000,24.146866,-35.317875,0.021139,0.000824,0.020918,107.410622,5.471758,0.209176,-35.317875,0.021984,0.000000
19.150002,24.772446,-35.273396,0.021126,0.000830,0.021083,110.193344,5.613517,0.210826,-35.273396,0.022219,0.000000
19.290001,25.247223,-35.362354,0.021148,0.000840,0.021342,112.305260,5.721103,0.213423,-35.362354,0.022453,0.000000
19.430000,25.740990,-35.273396,0.021135,0.000850,0.021594,114.501640,5.832992,0.215943,-35.273396,0.022687,0.000000
19.570002,26.215393,-35.273396,0.021139,0.000855,0.021707,116.611893,5.940493,0.217071,-35.273396,0.022921,0.000000
19.710001,27.368629,-35.273396,0.021165,0.000873,0.022184,121.741745,6.201820,0.221840,-35.273396,0.023155,0.000000
19.850000,27.984909,-35.228912,0.021178,0.000881,0.022366,124.483093,6.341471,0.223657,-35.228912,0.023389,0.000000
19.990002,28.358765,-35.273396,0.021165,0.000889,0.022574,126.146088,6.426188,0.225739,-35.273396,0.023615,0.000000
20.130001,28.905411,-35.273396,0.021182,0.000896,0.022765,128.577682,6.550060,0.227646,-35.273396,0.023849,0.000000
20.270000,29.341087,-35.228912,0.021178,0.000905,0.022982,130.515671,6.648786,0.229819,-35.228912,0.024083,0.000000
20.410002,29.811020,-35.273396,0.021191,0.000911,0.023146,132.606033,6.755273,0.231461,-35.273396,0.024317,0.000000
20.550001,30.509964,-35.273396,0.021170,0.000921,0.023389,135.715103,6.913657,0.233891,-35.273396,0.024551,0.000000
20.690001,31.318008,-35.273396,0.021182,0.000936,0.023771,139.309464,7.096762,0.237707,-35.273396,0.024786,0.000000
20.830002,32.108932,-35.362354,0.021208,0.000944,0.023979,142.827667,7.275988,0.239788,-35.362354,0.025020,0.000000
20.970001,32.430290,-35.273396,0.021208,0.000951,0.024161,144.257141,7.348809,0.241613,-35.273396,0.025254,0.000000
21.110001,32.932991,-35.317875,0.021191,0.000960,0.024387,146.493256,7.462722,0.243868,-35.317875,0.025488,0.000000
21.250002,33.642365,-35.317875,0.021204,0.000970,0.024646,149.648712,7.623469,0.246465,-35.317875,0.025722,0.000000
21.390001,34.189751,-35.273396,0.021213,0.000978,0.024829,152.083603,7.747508,0.248289,-35.273396,0.025956,0.000000
21.530001,34.809380,-35.317875,0.021213,0.000987,0.025063,154.839859,7.887918,0.250628,-35.317875,0.026182,0.000000
21.670000,35.590988,-35.406837,0.021234,0.000999,0.025366,158.316620,8.065033,0.253664,-35.406837,0.026416,0.000000
21.810001,36.325302,-35.317875,0.021226,0.001011,0.025670,161.583008,8.231431,0.256699,-35.317875,0.026650,0.000000
21.950001,37.181389,-35.317875,0.021221,0.001020,0.025895,165.391083,8.425424,0.258955,-35.317875,0.026884,0.000000
22.090000,37.528069,-35.362354,0.021230,0.001024,0.026008,166.933182,8.503983,0.260083,-35.362354,0.027118,0.000000
22.230001,38.342819,-35.228912,0.021230,0.001035,0.026294,170.557373,8.688607,0.262944,-35.228912,0.027353,0.000000
22.370001,38.728600,-35.406837,0.021230,0.001042,0.026477,172.273422,8.776026,0.264769,-35.406837,0.027587,0.000000
22.510000,39.222733,-35.362354,0.021251,0.001053,0.026754,174.471436,8.887999,0.267539,-35.362354,0.027820,0.000000
22.650002,40.421028,-35.317875,0.021247,0.001064,0.027023,179.801712,9.159536,0.270226,-35.317875,0.028055,0.000000
22.790001,40.972137,-35.406837,0.021273,0.001074,0.027275,182.253174,9.284419,0.272747,-35.406837,0.028289,0.000000
22.930000,41.833069,-35.362354,0.021290,0.001083,0.027509,186.082779,9.479508,0.275086,-35.362354,0.028515,0.000000
23.070002,42.399818,-35.406837,0.021251,0.001093,0.027760,188.603806,9.607936,0.277599,-35.406837,0.028749,0.000000
23.210001,43.184036,-35.406837,0.021264,0.001104,0.028046,192.092194,9.785643,0.280461,-35.406837,0.028983,0.000000
23.350000,43.875900,-35.406837,0.021273,0.001112,0.028237,195.169754,9.942421,0.282368,-35.406837,0.029217,0.000000
23.490002,44.156670,-35.406837,0.021277,0.001115,0.028324,196.418671,10.006044,0.283239,-35.406837,0.029451,0.000000
23.630001,44.576706,-35.317875,0.021295,0.001123,0.028523,198.287094,10.101227,0.285230,-35.317875,0.029686,0.000000
23.770000,45.734787,-35.317875,0.021277,0.001136,0.028861,203.438492,10.363650,0.288613,-35.317875,0.029920,0.000000
23.910002,46.068802,-35.317875,0.021295,0.001141,0.028974,204.924271,10.439340,0.289741,-35.317875,0.030153,0.000000
24.050001,46.861214,-35.406837,0.021286,0.001153,0.029278,208.449097,10.618903,0.292777,-35.406837,0.030388,0.000000
24.190001,47.679314,-35.406837,0.021303,0.001163,0.029538,212.088181,10.804287,0.295381,-35.406837,0.030622,0.000000
24.330002,48.252022,-35.317875,0.021320,0.001171,0.029755,214.635712,10.934065,0.297546,-35.317875,0.030856,0.000000
24.470001,48.863457,-35.406837,0.021320,0.001178,0.029928,217.355515,11.072618,0.299279,-35.406837,0.031082,0.000000
24.610001,49.771301,-35.451317,0.021308,0.001190,0.030214,221.393799,11.278337,0.302141,-35.451317,0.031315,0.000000
24.750002,50.455353,-35.406837,0.021316,0.001201,0.030509,224.436615,11.433347,0.305093,-35.406837,0.031550,0.000000
24.890001,51.139397,-35.451317,0.021320,0.001207,0.030657,227.479401,11.588353,0.306569,-35.451317,0.031784,0.000000
25.030001,51.967186,-35.451317,0.021329,0.001220,0.030978,231.161591,11.775933,0.309779,-35.451317,0.032018,0.000000
25.170002,52.577499,-35.406837,0.021333,0.001226,0.031151,233.876404,11.914231,0.311512,-35.406837,0.032253,0.000000
25.310001,53.082436,-35.451317,0.021338,0.001234,0.031342,236.122467,12.028651,0.313420,-35.451317,0.032487,0.000000
25.450001,53.446243,-35.406837,0.021338,0.001238,0.031437,237.740768,12.111092,0.314373,-35.406837,0.032720,0.000000
25.590002,54.235306,-35.406837,0.021329,0.001247,0.031671,241.250687,12.289896,0.316712,-35.406837,0.032955,0.000000
25.730001,55.267517,-35.406837,0.021346,0.001262,0.032044,245.842194,12.523798,0.320444,-35.406837,0.033189,0.000000
25.870001,56.122116,-35.451317,0.021342,0.001271,0.032287,249.643646,12.717453,0.322867,-35.451317,0.033423,0.000000
26.010002,56.569336,-35.451317,0.021359,0.001277,0.032434,251.632980,12.818794,0.324343,-35.451317,0.033648,0.000000
26.150002,57.601547,-35.451317,0.021368,0.001290,0.032755,256.224487,13.052697,0.327552,-35.451317,0.033882,0.000000
26.290001,58.284111,-35.451317,0.021351,0.001298,0.032972,259.260681,13.207368,0.329725,-35.451317,0.034117,0.000000
26.430000,59.170731,-35.406837,0.021351,0.001310,0.033284,263.204559,13.408279,0.332844,-35.406837,0.034351,0.000000
26.570002,59.826103,-35.451317,0.021355,0.001316,0.033432,266.119812,13.556788,0.334320,-35.451317,0.034585,0.000000
26.710001,60.303856,-35.451317,0.021372,0.001322,0.033571,268.244934,13.665049,0.335705,-35.451317,0.034820,0.000000
26.850000,61.032219,-35.451317,0.021381,0.001331,0.033813,271.484863,13.830098,0.338135,-35.451317,0.035053,0.000000
26.990002,61.886436,-35.495800,0.021381,0.001344,0.034134,275.284607,14.023667,0.341345,-35.495800,0.035287,0.000000
27.130001,62.726509,-35.451317,0.021398,0.001353,0.034368,279.021454,14.214030,0.343684,-35.451317,0.035522,0.000000
27.270000,63.454132,-35.451317,0.021385,0.001362,0.034602,282.258087,14.378912,0.346023,-35.451317,0.035756,0.000000
27.410002,63.919220,-35.495800,0.021394,0.001367,0.034724,284.326904,14.484303,0.347241,-35.495800,0.035990,0.000000
27.550001,64.936920,-35.451317,0.021381,0.001380,0.035063,288.853851,14.714916,0.350625,-35.451317,0.036215,0.000000
27.690001,65.607559,-35.540279,0.021411,0.001388,0.035262,291.837006,14.866885,0.352616,-35.540279,0.036450,0.000000
27.830002,66.421936,-35.451317,0.021402,0.001397,0.035487,295.459534,15.051426,0.354872,-35.451317,0.036684,0.000000
27.970001,67.205032,-35.495800,0.021415,0.001409,0.035791,298.942902,15.228878,0.357907,-35.495800,0.036918,0.000000
28.110001,67.445953,-35.495800,0.021428,0.001400,0.035565,300.014587,15.283471,0.355651,-35.495800,0.035843,0.000000
28.250002,67.278763,-35.495800,0.021420,0.001400,0.035565,299.270874,15.245585,0.355651,-35.495800,0.035843,0.000000
28.390001,67.137268,-35.540279,0.021415,0.001400,0.035557,298.641479,15.213523,0.355568,-35.540279,0.035565,0.000000
28.530001,67.000977,-35.451317,0.021428,0.001399,0.035522,298.035217,15.182638,0.355220,-35.451317,0.035565,0.000000
28.670002,66.894852,-35.540279,0.021411,0.001398,0.035513,297.563171,15.158590,0.355129,-35.540279,0.035565,0.000000
28.810001,66.793198,-35.495800,0.021415,0.001398,0.035505,297.110992,15.135554,0.355046,-35.495800,0.035565,0.000000
28.950001,66.711273,-35.540279,0.021420,0.001397,0.035496,296.746552,15.116990,0.354955,-35.540279,0.035565,0.000000
29.090002,66.623383,-35.540279,0.021441,0.001397,0.035496,296.355621,15.097075,0.354955,-35.540279,0.035565,0.000000
29.230001,66.555252,-35.495800,0.021428,0.001397,0.035487,296.052551,15.081636,0.354872,-35.495800,0.035565,0.000000
29.370001,66.486359,-35.495800,0.021437,0.001397,0.035487,295.746094,15.066024,0.354872,-35.495800,0.035565,0.000000
29.510002,66.423050,-35.584763,0.021433,0.001397,0.035487,295.464478,15.051679,0.354872,-35.584763,0.035565,0.000000
29.650002,66.370544,-35.540279,0.021441,0.001397,0.035487,295.230927,15.039781,0.354872,-35.540279,0.035565,0.000000
29.790001,66.284897,-35.584763,0.021420,0.001397,0.035487,294.849945,15.020372,0.354872,-35.584763,0.035565,0.000000
29.930002,66.237610,-35.495800,0.021424,0.001397,0.035478,294.639618,15.009657,0.354781,-35.495800,0.035565,0.000000
30.070002,66.163132,-35.495800,0.021433,0.001397,0.035478,294.308319,14.992780,0.354781,-35.495800,0.035565,0.000000
30.210001,66.122925,-35.540279,0.021420,0.001397,0.035478,294.129456,14.983669,0.354781,-35.540279,0.035565,0.000000
30.350002,66.062973,-35.495800,0.021433,0.001397,0.035478,293.862793,14.970083,0.354781,-35.495800,0.035565,0.000000
30.490002,66.023865,-35.584763,0.021420,0.001397,0.035478,293.688812,14.961221,0.354781,-35.584763,0.035565,0.000000
30.630001,65.980301,-35.540279,0.021437,0.001396,0.035470,293.495026,14.951350,0.354698,-35.540279,0.035565,0.000000
30.770002,65.944550,-35.629242,0.021420,0.001396,0.035470,293.335999,14.943249,0.354698,-35.629242,0.035565,0.000000
30.910002,65.894287,-35.629242,0.021437,0.001396,0.035470,293.112427,14.931859,0.354698,-35.629242,0.035565,0.000000
31.050001,65.853699,-35.495800,0.021445,0.001396,0.035470,292.931885,14.922662,0.354698,-35.495800,0.035565,0.000000
31.190001,65.806412,-35.540279,0.021458,0.001396,0.035470,292.721527,14.911946,0.354698,-35.540279,0.035565,0.000000
31.330002,65.760971,-35.629242,0.021437,0.001396,0.035470,292.519409,14.901649,0.354698,-35.629242,0.035565,0.000000
31.470001,65.717041,-35.584763,0.021437,0.001396,0.035461,292.324005,14.891694,0.354614,-35.584763,0.035565,0.000000
31.610001,65.701019,-35.540279,0.021428,0.001396,0.035461,292.252716,14.888063,0.354614,-35.540279,0.035565,0.000000
31.750002,65.656342,-35.584763,0.021424,0.001396,0.035461,292.053986,14.877939,0.354614,-35.584763,0.035565,0.000000
31.890001,65.626923,-35.584763,0.021428,0.001396,0.035461,291.923126,14.871273,0.354614,-35.584763,0.035565,0.000000
32.030003,65.600861,-35.540279,0.021450,0.001396,0.035461,291.807190,14.865368,0.354614,-35.540279,0.035565,0.000000
32.170002,65.577393,-35.584763,0.021433,0.001396,0.035461,291.702820,14.860049,0.354614,-35.584763,0.035565,0.000000
32.310001,65.534576,-35.584763,0.021420,0.001396,0.035461,291.512360,14.850348,0.354614,-35.584763,0.035565,0.000000
32.450001,65.505905,-35.584763,0.021437,0.001396,0.035461,291.384827,14.843851,0.354614,-35.584763,0.035565,0.000000
32.590000,65.462326,-35.673721,0.021437,0.001396,0.035461,291.190979,14.833976,0.354614,-35.673721,0.035565,0.000000
32.730003,65.435516,-35.584763,0.021445,0.001396,0.035461,291.071716,14.827900,0.354614,-35.584763,0.035565,0.000000
32.870003,65.401642,-35.673721,0.021441,0.001396,0.035461,290.921021,14.820224,0.354614,-35.673721,0.035565,0.000000
33.010002,65.382645,-35.584763,0.021454,0.001396,0.035461,290.836517,14.815919,0.354614,-35.584763,0.035565,0.000000
33.150002,65.364395,-35.584763,0.021433,0.001396,0.035461,290.755341,14.811783,0.354614,-35.584763,0.035565,0.000000
33.290001,65.335358,-35.584763,0.021433,0.001396,0.035461,290.626190,14.805204,0.354614,-35.584763,0.035565,0.000000
33.430000,65.308167,-35.629242,0.021424,0.001396,0.035461,290.505219,14.799042,0.354614,-35.629242,0.035565,0.000000
33.570000,65.282471,-35.584763,0.021450,0.001396,0.035461,290.390930,14.793220,0.354614,-35.584763,0.035565,0.000000
33.710003,65.252686,-35.718204,0.021428,0.001396,0.035461,290.258453,14.786469,0.354614,-35.718204,0.035565,0.000000
33.850002,65.222519,-35.584763,0.021428,0.001396,0.035461,290.124268,14.779634,0.354614,-35.584763,0.035565,0.000000
33.990002,65.191620,-35.629242,0.021445,0.001396,0.035452,289.986816,14.772633,0.354524,-35.629242,0.035565,0.000000
34.130001,65.178589,-35.673721,0.021450,0.001396,0.035452,289.928833,14.769679,0.354524,-35.673721,0.035565,0.000000
34.270000,65.150650,-35.584763,0.021415,0.001396,0.035452,289.804565,14.763348,0.354524,-35.584763,0.035565,0.000000
34.410000,65.135010,-35.673721,0.021450,0.001396,0.035452,289.734985,14.759804,0.354524,-35.673721,0.035565,0.000000
34.550003,65.116776,-35.629242,0.021437,0.001396,0.035452,289.653870,14.755672,0.354524,-35.629242,0.035565,0.000000
34.690002,65.098892,-35.673721,0.021433,0.001396,0.035452,289.574341,14.751619,0.354524,-35.673721,0.035565,0.000000
34.830002,65.082520,-35.673721,0.021441,0.001396,0.035452,289.501495,14.747910,0.354524,-35.673721,0.035565,0.000000
34.970001,65.052353,-35.673721,0.021428,0.001396,0.035452,289.367310,14.741074,0.354524,-35.673721,0.035565,0.000000
35.110001,65.019211,-35.718204,0.021428,0.001396,0.035452,289.219879,14.733563,0.354524,-35.718204,0.035565,0.000000
35.250000,65.012512,-35.629242,0.021433,0.001396,0.035452,289.190094,14.732045,0.354524,-35.629242,0.035565,0.000000
35.390003,64.983841,-35.718204,0.021433,0.001396,0.035452,289.062561,14.725549,0.354524,-35.718204,0.035565,0.000000
35.530003,64.971176,-35.673721,0.021437,0.001396,0.035452,289.006226,14.722679,0.354524,-35.673721,0.035565,0.000000
35.670002,64.956650,-35.673721,0.021437,0.001396,0.035452,288.941620,14.719388,0.354524,-35.673721,0.035565,0.000000
35.810001,64.945480,-35.673721,0.021437,0.001396,0.035452,288.891937,14.716857,0.354524,-35.673721,0.035565,0.000000
35.950001,64.923141,-35.718204,0.021437,0.001396,0.035452,288.792542,14.711794,0.354524,-35.718204,0.035565,0.000000
36.090000,64.904526,-35.718204,0.021441,0.001396,0.035452,288.709747,14.707576,0.354524,-35.718204,0.035565,0.000000
36.230003,64.883667,-35.673721,0.021433,0.001396,0.035452,288.616974,14.702849,0.354524,-35.673721,0.035565,0.000000
36.370003,64.850159,-35.718204,0.021428,0.001396,0.035452,288.467926,14.695256,0.354524,-35.718204,0.035565,0.000000
36.510002,64.834885,-35.673721,0.021450,0.001396,0.035452,288.399963,14.691794,0.354524,-35.673721,0.035565,0.000000
36.650002,64.827805,-35.629242,0.021433,0.001396,0.035452,288.368469,14.690190,0.354524,-35.629242,0.035565,0.000000
36.790001,64.810303,-35.673721,0.021437,0.001396,0.035452,288.290619,14.686224,0.354524,-35.673721,0.035565,0.000000
36.930000,64.802109,-35.673721,0.021445,0.001396,0.035452,288.254181,14.684368,0.354524,-35.673721,0.035565,0.000000
37.070004,64.789459,-35.718204,0.021420,0.001396,0.035452,288.197906,14.681501,0.354524,-35.718204,0.035565,0.000000
37.210003,64.776428,-35.718204,0.021450,0.001396,0.035452,288.139954,14.678548,0.354524,-35.718204,0.035565,0.000000
37.350002,64.760040,-35.673721,0.021454,0.001396,0.035452,288.067047,14.674835,0.354524,-35.673721,0.035565,0.000000
37.490002,64.736206,-35.762684,0.021433,0.001396,0.035452,287.961029,14.669434,0.354524,-35.762684,0.035565,0.000000
37.630001,64.712006,-35.718204,0.021454,0.001396,0.035452,287.853363,14.663950,0.354524,-35.718204,0.035565,0.000000
37.770000,64.702698,-35.762684,0.021437,0.001396,0.035452,287.811981,14.661841,0.354524,-35.762684,0.035565,0.000000
37.910004,64.688919,-35.762684,0.021454,0.001396,0.035452,287.750671,14.658718,0.354524,-35.762684,0.035565,0.000000
38.050003,64.667694,-35.807167,0.021445,0.001396,0.035452,287.656281,14.653909,0.354524,-35.807167,0.035565,0.000000
38.190002,64.661362,-35.718204,0.021437,0.001396,0.035452,287.628113,14.652474,0.354524,-35.718204,0.035565,0.000000
38.330002,64.655396,-35.673721,0.021433,0.001396,0.035452,287.601562,14.651122,0.354524,-35.673721,0.035565,0.000000
38.470001,64.635300,-35.762684,0.021428,0.001396,0.035452,287.512177,14.646568,0.354524,-35.762684,0.035565,0.000000
38.610001,64.621887,-35.762684,0.021433,0.001396,0.035452,287.452515,14.643529,0.354524,-35.762684,0.035565,0.000000
38.750000,64.604385,-35.762684,0.021454,0.001396,0.035452,287.374664,14.639563,0.354524,-35.762684,0.035565,0.000000
38.890003,64.575714,-35.762684,0.021441,0.001396,0.035452,287.247131,14.633066,0.354524,-35.762684,0.035565,0.000000
39.030003,64.571243,-35.807167,0.021437,0.001396,0.035452,287.227234,14.632053,0.354524,-35.807167,0.035565,0.000000
39.170002,64.566772,-35.762684,0.021437,0.001396,0.035452,287.207336,14.631041,0.354524,-35.762684,0.035565,0.000000
39.310001,64.552994,-35.807167,0.021424,0.001396,0.035452,287.146057,14.627917,0.354524,-35.807167,0.035565,0.000000
39.450001,64.545181,-35.718204,0.021445,0.001396,0.035452,287.111298,14.626147,0.354524,-35.718204,0.035565,0.000000
39.590000,64.531769,-35.807167,0.021450,0.001396,0.035452,287.051636,14.623108,0.354524,-35.807167,0.035565,0.000000
39.730003,64.524323,-35.718204,0.021428,0.001396,0.035452,287.018524,14.621421,0.354524,-35.718204,0.035565,0.000000
39.870003,64.506454,-35.762684,0.021445,0.001396,0.035452,286.939026,14.617372,0.354524,-35.762684,0.035565,0.000000
40.010002,64.482620,-35.718204,0.021445,0.001396,0.035452,286.833008,14.611971,0.354524,-35.718204,0.035565,0.000000
40.150002,64.462509,-35.762684,0.021454,0.001395,0.035444,286.743561,14.607413,0.354440,-35.762684,0.035565,0.000000
40.290001,64.445007,-35.807167,0.021437,0.001395,0.035444,286.665710,14.603447,0.354440,-35.807167,0.035565,0.000000
40.430000,64.443146,-35.762684,0.021454,0.001395,0.035444,286.657440,14.603026,0.354440,-35.762684,0.035565,0.000000
40.570004,64.434586,-35.807167,0.021441,0.001395,0.035444,286.619354,14.601086,0.354440,-35.807167,0.035565,0.000000
40.710003,64.431229,-35.807167,0.021433,0.001395,0.035444,286.604431,14.600326,0.354440,-35.807167,0.035565,0.000000
40.850002,64.412247,-35.762684,0.021437,0.001395,0.035444,286.519989,14.596024,0.354440,-35.762684,0.035565,0.000000
40.990002,64.394745,-35.851646,0.021437,0.001395,0.035444,286.442139,14.592057,0.354440,-35.851646,0.035565,0.000000
41.130001,64.386169,-35.807167,0.021441,0.001395,0.035444,286.403992,14.590115,0.354440,-35.807167,0.035565,0.000000
41.270000,64.369049,-35.851646,0.021433,0.001395,0.035444,286.327820,14.586235,0.354440,-35.851646,0.035565,0.000000
41.410004,64.351166,-35.762684,0.021467,0.001395,0.035444,286.248291,14.582183,0.354440,-35.762684,0.035565,0.000000
41.550003,64.347443,-35.762684,0.021433,0.001395,0.035444,286.231720,14.581339,0.354440,-35.762684,0.035565,0.000000
41.690002,64.328461,-35.851646,0.021441,0.001395,0.035444,286.147278,14.577037,0.354440,-35.851646,0.035565,0.000000
41.830002,64.328079,-35.851646,0.021450,0.001395,0.035444,286.145599,14.576951,0.354440,-35.851646,0.035565,0.000000
41.970001,64.311707,-35.807167,0.021428,0.001395,0.035444,286.072754,14.573241,0.354440,-35.807167,0.035565,0.000000
42.110001,64.319901,-35.851646,0.021454,0.001395,0.035444,286.109192,14.575098,0.354440,-35.851646,0.035565,0.000000
42.250004,64.303513,-35.851646,0.021458,0.001395,0.035444,286.036316,14.571384,0.354440,-35.851646,0.035565,0.000000
42.390003,64.291962,-35.851646,0.021450,0.001395,0.035444,285.984924,14.568767,0.354440,-35.851646,0.035565,0.000000
42.530003,64.270737,-35.762684,0.021463,0.001395,0.035444,285.890503,14.563957,0.354440,-35.762684,0.035565,0.000000
42.670002,64.263290,-35.851646,0.021428,0.001395,0.035444,285.857391,14.562269,0.354440,-35.851646,0.035565,0.000000
42.810001,64.255478,-35.896126,0.021441,0.001395,0.035444,285.822632,14.560500,0.354440,-35.896126,0.035565,0.000000
42.950001,64.237976,-35.807167,0.021441,0.001395,0.035444,285.744781,14.556534,0.354440,-35.807167,0.035565,0.000000
43.090000,64.237595,-35.851646,0.021445,0.001395,0.035444,285.743103,14.556447,0.354440,-35.851646,0.035565,0.000000
43.230003,64.230896,-35.807167,0.021450,0.001395,0.035444,285.713287,14.554930,0.354440,-35.807167,0.035565,0.000000
43.370003,64.221588,-35.851646,0.021441,0.001395,0.035444,285.671906,14.552819,0.354440,-35.851646,0.035565,0.000000
43.510002,64.202972,-35.851646,0.021441,0.001395,0.035444,285.589081,14.548602,0.354440,-35.851646,0.035565,0.000000
43.650002,64.204453,-35.851646,0.021454,0.001395,0.035444,285.595673,14.548937,0.354440,-35.851646,0.035565,0.000000
43.790001,64.175034,-35.940609,0.021433,0.001395,0.035444,285.464813,14.542271,0.354440,-35.940609,0.035565,0.000000
43.930000,64.186951,-35.851646,0.021441,0.001395,0.035444,285.517822,14.544971,0.354440,-35.851646,0.035565,0.000000
44.070004,64.161636,-35.851646,0.021441,0.001395,0.035444,285.405212,14.539235,0.354440,-35.851646,0.035565,0.000000
44.210003,64.167221,-35.851646,0.021458,0.001395,0.035444,285.430054,14.540501,0.354440,-35.851646,0.035565,0.000000
44.350002,64.146362,-35.896126,0.021433,0.001395,0.035444,285.337280,14.535773,0.354440,-35.896126,0.035565,0.000000
44.490002,64.139664,-35.896126,0.021467,0.001395,0.035444,285.307465,14.534255,0.354440,-35.896126,0.035565,0.000000
44.630001,64.129608,-35.851646,0.021445,0.001395,0.035444,285.262756,14.531977,0.354440,-35.851646,0.035565,0.000000
44.770000,64.126633,-35.896126,0.021445,0.001395,0.035444,285.249512,14.531302,0.354440,-35.896126,0.035565,0.000000
44.910004,64.124405,-35.851646,0.021428,0.001395,0.035444,285.239594,14.530798,0.354440,-35.851646,0.035565,0.000000
45.050003,64.104294,-35.896126,0.021441,0.001395,0.035444,285.150146,14.526240,0.354440,-35.896126,0.035565,0.000000
45.190002,64.086411,-35.940609,0.021433,0.001395,0.035444,285.070587,14.522188,0.354440,-35.940609,0.035565,0.000000
45.330002,64.080093,-35.896126,0.021463,0.001395,0.035444,285.042480,14.520757,0.354440,-35.896126,0.035565,0.000000
45.470001,64.062210,-35.896126,0.021433,0.001395,0.035444,284.962952,14.516704,0.354440,-35.896126,0.035565,0.000000
45.610001,64.055878,-35.940609,0.021437,0.001395,0.035444,284.934784,14.515269,0.354440,-35.940609,0.035565,0.000000
45.750004,64.046951,-35.896126,0.021445,0.001395,0.035444,284.895081,14.513247,0.354440,-35.896126,0.035565,0.000000
45.890003,64.045090,-35.940609,0.021454,0.001395,0.035444,284.886780,14.512824,0.354440,-35.940609,0.035565,0.000000
46.030003,64.040985,-35.851646,0.021433,0.001395,0.035444,284.868530,14.511895,0.354440,-35.851646,0.035565,0.000000
46.170002,64.034653,-35.940609,0.021450,0.001395,0.035444,284.840363,14.510460,0.354440,-35.940609,0.035565,0.000000
46.310001,64.031677,-35.985088,0.021445,0.001395,0.035444,284.827118,14.509786,0.354440,-35.985088,0.035565,0.000000
46.450001,64.024231,-35.940609,0.021428,0.001395,0.035444,284.794006,14.508099,0.354440,-35.940609,0.035565,0.000000
46.590004,64.006363,-35.985088,0.021441,0.001395,0.035444,284.714508,14.504049,0.354440,-35.985088,0.035565,0.000000
46.730003,63.998169,-35.940609,0.021454,0.001395,0.035444,284.678070,14.502192,0.354440,-35.940609,0.035565,0.000000
46.870003,63.979538,-36.029572,0.021437,0.001395,0.035444,284.595184,14.497971,0.354440,-36.029572,0.035565,0.000000
47.010002,63.983643,-35.940609,0.021433,0.001395,0.035444,284.613464,14.498901,0.354440,-35.940609,0.035565,0.000000
47.150002,63.966141,-35.940609,0.021441,0.001395,0.035444,284.535614,14.494935,0.354440,-35.940609,0.035565,0.000000
47.290001,63.951248,-35.940609,0.021445,0.001395,0.035444,284.469360,14.491560,0.354440,-35.940609,0.035565,0.000000
47.430004,63.947525,-35.896126,0.021437,0.001395,0.035444,284.452789,14.490716,0.354440,-35.896126,0.035565,0.000000
47.570004,63.944916,-35.940609,0.021454,0.001395,0.035444,284.441193,14.490125,0.354440,-35.940609,0.035565,0.000000
47.710003,63.944550,-35.940609,0.021437,0.001395,0.035444,284.439575,14.490043,0.354440,-35.940609,0.035565,0.000000
47.850002,63.936356,-35.940609,0.021467,0.001395,0.035444,284.403107,14.488185,0.354440,-35.940609,0.035565,0.000000
47.990002,63.927414,-36.029572,0.021445,0.001395,0.035444,284.363342,14.486158,0.354440,-36.029572,0.035565,0.000000
48.130001,63.921829,-35.940609,0.021458,0.001395,0.035444,284.338501,14.484894,0.354440,-35.940609,0.035565,0.000000
48.270000,63.910660,-35.985088,0.021445,0.001395,0.035444,284.288818,14.482363,0.354440,-35.985088,0.035565,0.000000
48.410004,63.903214,-36.029572,0.021458,0.001395,0.035444,284.255676,14.480675,0.354440,-36.029572,0.035565,0.000000
48.550003,63.889435,-35.940609,0.021454,0.001395,0.035444,284.194397,14.477553,0.354440,-35.940609,0.035565,0.000000
48.690002,63.886459,-36.029572,0.021441,0.001395,0.035444,284.181152,14.476878,0.354440,-36.029572,0.035565,0.000000
48.830002,63.880493,-35.985088,0.021454,0.001395,0.035444,284.154633,14.475527,0.354440,-35.985088,0.035565,0.000000
48.970001,63.874908,-36.029572,0.021437,0.001395,0.035444,284.129791,14.474261,0.354440,-36.029572,0.035565,0.000000
49.110001,63.861130,-35.985088,0.021463,0.001395,0.035444,284.068481,14.471138,0.354440,-35.985088,0.035565,0.000000
49.250004,63.862625,-35.940609,0.021463,0.001395,0.035444,284.075134,14.471478,0.354440,-35.940609,0.035565,0.000000
49.390003,63.848465,-35.985088,0.021445,0.001395,0.035444,284.012146,14.468268,0.354440,-35.985088,0.035565,0.000000
49.530003,63.846237,-35.985088,0.021454,0.001395,0.035444,284.002258,14.467764,0.354440,-35.985088,0.035565,0.000000
49.670002,63.843262,-35.985088,0.021441,0.001395,0.035444,283.989014,14.467091,0.354440,-35.985088,0.035565,0.000000
49.810001,63.822769,-36.029572,0.021441,0.001395,0.035444,283.897858,14.462446,0.354440,-36.029572,0.035565,0.000000
49.950001,63.827988,-35.985088,0.021458,0.001395,0.035444,283.921082,14.463629,0.354440,-35.985088,0.035565,0.000000
50.090004,63.810867,-36.029572,0.021454,0.001395,0.035444,283.844910,14.459749,0.354440,-36.029572,0.035565,0.000000
50.230003,63.816071,-35.985088,0.021433,0.001395,0.035444,283.868073,14.460928,0.354440,-35.985088,0.035565,0.000000
50.370003,63.794098,-36.029572,0.021445,0.001395,0.035444,283.770325,14.455950,0.354440,-36.029572,0.035565,0.000000
50.510002,63.779953,-36.029572,0.021454,0.001395,0.035444,283.707397,14.452744,0.354440,-36.029572,0.035565,0.000000
50.650002,63.785919,-36.029572,0.021476,0.001395,0.035444,283.733948,14.454096,0.354440,-36.029572,0.035565,0.000000
50.790001,63.779953,-36.118534,0.021445,0.001395,0.035444,283.707397,14.452744,0.354440,-36.118534,0.035565,0.000000
50.930004,63.782181,-35.985088,0.021454,0.001395,0.035444,283.717316,14.453249,0.354440,-35.985088,0.035565,0.000000
51.070004,63.781815,-36.074051,0.021445,0.001395,0.035444,283.715668,14.453166,0.354440,-36.074051,0.035565,0.000000
51.210003,63.773621,-36.074051,0.021454,0.001395,0.035444,283.679230,14.451309,0.354440,-36.074051,0.035565,0.000000
51.350002,63.754257,-36.029572,0.021450,0.001395,0.035444,283.593109,14.446920,0.354440,-36.029572,0.035565,0.000000
51.490002,63.749786,-36.029572,0.021458,0.001395,0.035444,283.573212,14.445908,0.354440,-36.029572,0.035565,0.000000
51.630001,63.754257,-35.985088,0.021454,0.001395,0.035444,283.593109,14.446920,0.354440,-35.985088,0.035565,0.000000
51.770004,63.735641,-36.029572,0.021458,0.001395,0.035444,283.510284,14.442703,0.354440,-36.029572,0.035565,0.000000
51.910004,63.728943,-36.074051,0.021458,0.001395,0.035444,283.480499,14.441185,0.354440,-36.074051,0.035565,0.000000
52.050003,63.727081,-36.029572,0.021454,0.001395,0.035444,283.472229,14.440763,0.354440,-36.029572,0.035565,0.000000
52.190002,63.719254,-36.029572,0.021454,0.001395,0.035444,283.437408,14.438989,0.354440,-36.029572,0.035565,0.000000
52.330002,63.711060,-36.074051,0.021471,0.001395,0.035444,283.400940,14.437133,0.354440,-36.074051,0.035565,0.000000
52.470001,63.705856,-36.074051,0.021428,0.001395,0.035444,283.377808,14.435953,0.354440,-36.074051,0.035565,0.000000
52.610001,63.689835,-36.074051,0.021441,0.001395,0.035444,283.306519,14.432323,0.354440,-36.074051,0.035565,0.000000
52.750004,63.690964,-36.074051,0.021445,0.001395,0.035444,283.311554,14.432579,0.354440,-36.074051,0.035565,0.000000
52.890003,63.686493,-36.118534,0.021450,0.001395,0.035444,283.291656,14.431565,0.354440,-36.118534,0.035565,0.000000
53.030003,63.677551,-36.074051,0.021445,0.001395,0.035444,283.251892,14.429540,0.354440,-36.074051,0.035565,0.000000
53.170002,63.661911,-36.118534,0.021445,0.001395,0.035444,283.182312,14.425995,0.354440,-36.118534,0.035565,0.000000
53.310001,63.660049,-36.074051,0.021476,0.001395,0.035444,283.174042,14.425574,0.354440,-36.074051,0.035565,0.000000
53.450001,63.657074,-36.074051,0.021437,0.001395,0.035444,283.160797,14.424899,0.354440,-36.074051,0.035565,0.000000
53.590004,63.651855,-36.118534,0.021458,0.001395,0.035444,283.137604,14.423717,0.354440,-36.118534,0.035565,0.000000
53.730003,63.653351,-36.029572,0.021454,0.001395,0.035444,283.144257,14.424056,0.354440,-36.029572,0.035565,0.000000
53.870003,63.636215,-36.074051,0.021445,0.001395,0.035444,283.068024,14.420173,0.354440,-36.074051,0.035565,0.000000
54.010002,63.640686,-36.074051,0.021450,0.001395,0.035444,283.087921,14.421185,0.354440,-36.074051,0.035565,0.000000
54.150002,63.630264,-36.074051,0.021467,0.001395,0.035444,283.041565,14.418824,0.354440,-36.074051,0.035565,0.000000
54.290001,63.618347,-36.118534,0.021445,0.001395,0.035444,282.988556,14.416123,0.354440,-36.118534,0.035565,0.000000
54.430004,63.613129,-36.074051,0.021445,0.001395,0.035444,282.965332,14.414941,0.354440,-36.074051,0.035565,0.000000
54.570004,63.616852,-36.163013,0.021467,0.001395,0.035444,282.981903,14.415785,0.354440,-36.163013,0.035565,0.000000
54.710003,63.603455,-36.118534,0.021428,0.001395,0.035444,282.922302,14.412748,0.354440,-36.118534,0.035565,0.000000
54.850002,63.592651,-36.118534,0.021445,0.001395,0.035444,282.874237,14.410301,0.354440,-36.118534,0.035565,0.000000
54.990002,63.583344,-36.163013,0.021458,0.001395,0.035444,282.832825,14.408192,0.354440,-36.163013,0.035565,0.000000
55.130001,63.587067,-36.118534,0.021454,0.001395,0.035444,282.849396,14.409036,0.354440,-36.118534,0.035565,0.000000
55.270004,63.577377,-36.118534,0.021437,0.001395,0.035444,282.806305,14.406839,0.354440,-36.118534,0.035565,0.000000
55.410004,63.577759,-36.163013,0.021454,0.001395,0.035444,282.807983,14.406926,0.354440,-36.163013,0.035565,0.000000
55.550003,63.584457,-36.074051,0.021454,0.001395,0.035444,282.837799,14.408443,0.354440,-36.074051,0.035565,0.000000
55.690002,63.571060,-36.207493,0.021463,0.001395,0.035444,282.778198,14.405408,0.354440,-36.207493,0.035565,0.000000
55.830002,63.578873,-36.118534,0.021441,0.001395,0.035444,282.812958,14.407178,0.354440,-36.118534,0.035565,0.000000
55.970001,63.572174,-36.118534,0.021437,0.001395,0.035444,282.783142,14.405661,0.354440,-36.118534,0.035565,0.000000
56.110004,63.554672,-36.163013,0.021450,0.001395,0.035444,282.705292,14.401695,0.354440,-36.163013,0.035565,0.000000
56.250004,63.542374,-36.163013,0.021445,0.001395,0.035444,282.650604,14.398908,0.354440,-36.163013,0.035565,0.000000
56.390003,63.546478,-36.163013,0.021463,0.001395,0.035444,282.668854,14.399837,0.354440,-36.163013,0.035565,0.000000
56.530003,63.529343,-36.118534,0.021433,0.001395,0.035444,282.592621,14.395955,0.354440,-36.118534,0.035565,0.000000
56.670002,63.521896,-36.163013,0.021441,0.001395,0.035444,282.559509,14.394268,0.354440,-36.163013,0.035565,0.000000
56.810001,63.515198,-36.207493,0.021454,0.001395,0.035444,282.529724,14.392750,0.354440,-36.207493,0.035565,0.000000
56.950005,63.512970,-36.163013,0.021450,0.001395,0.035444,282.519806,14.392245,0.354440,-36.163013,0.035565,0.000000
57.090004,63.516693,-36.163013,0.021441,0.001395,0.035444,282.536377,14.393088,0.354440,-36.163013,0.035565,0.000000
57.230003,63.497330,-36.118534,0.021441,0.001395,0.035444,282.450226,14.388700,0.354440,-36.118534,0.035565,0.000000
57.370003,63.498810,-36.163013,0.021441,0.001395,0.035444,282.456818,14.389036,0.354440,-36.163013,0.035565,0.000000
57.510002,63.489136,-36.163013,0.021445,0.001395,0.035444,282.413788,14.386844,0.354440,-36.163013,0.035565,0.000000
57.650002,63.495087,-36.207493,0.021458,0.001395,0.035444,282.440247,14.388192,0.354440,-36.207493,0.035565,0.000000
57.790001,63.483170,-36.163013,0.021450,0.001395,0.035444,282.387238,14.385491,0.354440,-36.163013,0.035565,0.000000
57.930004,63.483917,-36.207493,0.021450,0.001395,0.035444,282.390564,14.385661,0.354440,-36.207493,0.035565,0.000000
58.070004,63.471634,-36.207493,0.021454,0.001395,0.035444,282.335937,14.382878,0.354440,-36.207493,0.035565,0.000000
58.210003,63.464554,-36.207493,0.021463,0.001395,0.035444,282.304443,14.381273,0.354440,-36.207493,0.035565,0.000000
58.350002,63.458603,-36.163013,0.021441,0.001395,0.035444,282.277954,14.379925,0.354440,-36.163013,0.035565,0.000000
58.490002,63.454132,-36.207493,0.021445,0.001395,0.035444,282.258087,14.378912,0.354440,-36.207493,0.035565,0.000000
58.500004,63.458969,-36.163013,0.021441,0.001395,0.035444,282.279602,14.380009,0.354440,-36.163013,0.035565,0.000000