File: Data/Polished Pin I-18 - 3_08162023_161240.csv
Time (sec),S:Load (lbs),S:HL1 (DIM),S:LVDT (in),S:Position (in),Ch:Position (mm),Ch:Load (N),Ch:Stress (MPa),Ch:Strain (mm/mm),Ch:HL1 (DIM),Set Point (),Cycles ()
0.110000,-0.005213,-42.568272,-0.000004,-0.000000,-0.000000,-0.023190,-0.001181,-0.000000,-42.568272,0.000199,0.000000
0.320000,-0.011544,-42.568272,-0.000022,-0.000000,-0.000000,-0.051348,-0.002616,-0.000000,-42.568272,0.000199,0.000000
0.530000,-0.007075,-42.568272,-0.000004,0.000088,0.002238,-0.031471,-0.001603,0.022376,-42.568272,0.003044,0.000000
0.740000,0.014150,-42.523788,-0.000004,0.000212,0.005394,0.062943,0.003206,0.053942,-42.523788,0.006547,0.000000
0.950000,0.004096,-42.612751,0.000172,0.000351,0.008923,0.018220,0.000928,0.089233,-42.612751,0.010051,0.000000
1.160000,0.002607,-42.657230,0.000289,0.000490,0.012445,0.011595,0.000591,0.124447,-42.657230,0.013537,0.000000
1.370000,0.035748,-42.612751,0.000401,0.000625,0.015887,0.159014,0.008101,0.158875,-42.612751,0.017041,0.000000
1.580000,0.036492,-42.701714,0.000569,0.000763,0.019382,0.162327,0.008269,0.193824,-42.701714,0.020544,0.000000
1.790000,0.036120,-42.657230,0.000690,0.000903,0.022938,0.160670,0.008185,0.229380,-42.657230,0.024048,0.000000
2.000000,0.012661,-42.746193,0.000802,0.001041,0.026441,0.056317,0.002869,0.264413,-42.746193,0.027534,0.000000
2.210000,0.037237,-42.657230,0.000931,0.001179,0.029936,0.165639,0.008438,0.299362,-42.657230,0.031038,0.000000
2.420000,0.018619,-42.701714,0.001065,0.001322,0.033579,0.082820,0.004219,0.335788,-42.701714,0.034542,0.000000
2.630000,0.028673,-42.701714,0.001212,0.001451,0.036857,0.127542,0.006497,0.368573,-42.701714,0.038028,0.000000
2.840000,0.041333,-42.701714,0.001354,0.001589,0.040369,0.183860,0.009366,0.403689,-42.701714,0.041532,0.000000
3.050000,0.044685,-42.746193,0.001496,0.001729,0.043908,0.198767,0.010126,0.439078,-42.746193,0.045035,0.000000
3.260000,0.041333,-42.701714,0.001638,0.001868,0.047446,0.183860,0.009366,0.474459,-42.701714,0.048538,0.000000
3.470000,0.055111,-42.701714,0.001798,0.001999,0.050785,0.245146,0.012488,0.507850,-42.701714,0.052025,0.000000
3.680000,0.058090,-42.746193,0.001923,0.002139,0.054323,0.258398,0.013163,0.543231,-42.746193,0.055528,0.000000
3.890000,0.068889,-42.701714,0.002057,0.002279,0.057887,0.306433,0.015610,0.578869,-42.701714,0.059032,0.000000
4.100000,0.050270,-42.790676,0.002220,0.002421,0.061504,0.223613,0.011391,0.615038,-42.790676,0.062518,0.000000
4.310000,0.050643,-42.790676,0.002376,0.002558,0.064972,0.225270,0.011476,0.649723,-42.790676,0.066021,0.000000
4.520000,0.026811,-42.746193,0.002535,0.002695,0.068450,0.119261,0.006075,0.684498,-42.746193,0.069525,0.000000
4.730000,0.021225,-42.790676,0.002686,0.002829,0.071859,0.094414,0.004810,0.718585,-42.790676,0.073029,0.000000
4.940000,0.024577,-42.746193,0.002850,0.002965,0.075319,0.109322,0.005569,0.753187,-42.746193,0.076515,0.000000
5.150000,0.032396,-42.879639,0.002997,0.003102,0.078787,0.144106,0.007341,0.787871,-42.879639,0.080019,0.000000
5.360000,0.033141,-42.835155,0.003134,0.003246,0.082447,0.147419,0.007510,0.824471,-42.835155,0.083522,0.000000
5.570000,0.056973,-42.790676,0.003277,0.003381,0.085872,0.253428,0.012910,0.858725,-42.790676,0.087009,0.000000
5.780000,0.062931,-42.879639,0.003428,0.003514,0.089264,0.279931,0.014260,0.892637,-42.879639,0.090512,0.000000
5.990000,0.064048,-42.835155,0.003561,0.003651,0.092741,0.284900,0.014513,0.927413,-42.835155,0.094016,0.000000
6.200000,0.060324,-42.924118,0.003686,0.003790,0.096270,0.268336,0.013670,0.962703,-42.924118,0.097502,0.000000
6.410000,0.048781,-42.879639,0.003837,0.003941,0.100104,0.216988,0.011054,1.001037,-42.879639,0.101006,0.000000
6.620000,0.031652,-42.879639,0.003997,0.004074,0.103486,0.140793,0.007172,1.034858,-42.879639,0.104509,0.000000
6.830000,0.027556,-42.924118,0.004139,0.004210,0.106929,0.122573,0.006244,1.069286,-42.924118,0.108013,0.000000
7.040000,0.011916,-42.879639,0.004290,0.004347,0.110406,0.053005,0.002700,1.104061,-42.879639,0.111499,0.000000
7.250000,-0.011916,-42.879639,0.004428,0.004484,0.113893,-0.053005,-0.002700,1.138928,-42.879639,0.115003,0.000000
7.460001,0.002607,-42.968597,0.004579,0.004620,0.117353,0.011595,0.000591,1.173529,-42.968597,0.118507,0.000000
7.670001,0.064793,-42.879639,0.004743,0.004760,0.120900,0.288213,0.014682,1.209001,-42.879639,0.121992,0.000000
7.880001,0.046547,-43.013081,0.004876,0.004897,0.124386,0.207049,0.010548,1.243860,-43.013081,0.125496,0.000000
8.090000,0.053622,-42.879639,0.005032,0.005030,0.127751,0.238521,0.012151,1.277508,-42.879639,0.129000,0.000000
8.300000,0.047664,-42.879639,0.005195,0.005166,0.131220,0.212018,0.010801,1.312200,-42.879639,0.132503,0.000000
8.510000,0.035375,-42.968597,0.005346,0.005302,0.134680,0.157357,0.008016,1.346802,-42.968597,0.135990,0.000000
8.720000,0.061441,-42.924118,0.005493,0.005449,0.138409,0.273305,0.013923,1.384091,-42.924118,0.139493,0.000000
8.930000,0.029417,-43.013081,0.005631,0.005591,0.141999,0.130855,0.006666,1.419994,-43.013081,0.142996,0.000000
9.140000,0.036120,-42.924118,0.005795,0.005727,0.145477,0.160670,0.008185,1.454770,-42.924118,0.146483,0.000000
9.350000,-0.003724,-43.057560,0.005902,0.005861,0.148859,-0.016564,-0.000844,1.488592,-43.057560,0.149986,0.000000
9.560000,-0.009682,-43.013081,0.006053,0.005998,0.152337,-0.043066,-0.002194,1.523367,-43.013081,0.153490,0.000000
9.770000,0.004096,-42.924118,0.006209,0.006136,0.155867,0.018220,0.000928,1.558665,-42.924118,0.156994,0.000000
9.980000,0.035003,-43.057560,0.006342,0.006274,0.159352,0.155701,0.007932,1.593524,-43.057560,0.160480,0.000000
10.190001,0.043195,-42.968597,0.006493,0.006411,0.162839,0.192142,0.009788,1.628391,-42.968597,0.163984,0.000000
10.400001,0.053622,-42.968597,0.006627,0.006548,0.166325,0.238521,0.012151,1.663249,-42.968597,0.167487,0.000000
10.610001,0.045057,-43.013081,0.006769,0.006682,0.169716,0.200424,0.010210,1.697162,-43.013081,0.170974,0.000000
10.820001,0.073730,-43.013081,0.006929,0.006822,0.173289,0.327966,0.016707,1.732891,-43.013081,0.174477,0.000000
11.030001,0.046174,-43.057560,0.007075,0.006963,0.176862,0.205393,0.010463,1.768621,-43.057560,0.177981,0.000000
11.240001,0.039471,-43.013081,0.007235,0.007101,0.180357,0.175578,0.008944,1.803571,-43.013081,0.181484,0.000000
11.450001,0.027928,-43.057560,0.007386,0.007242,0.183947,0.124230,0.006329,1.839474,-43.057560,0.184970,0.000000
11.660001,0.028673,-43.013081,0.007537,0.007378,0.187398,0.127542,0.006497,1.873985,-43.013081,0.188474,0.000000
11.870001,0.017874,-43.013081,0.007705,0.007513,0.190833,0.079507,0.004050,1.908329,-43.013081,0.191977,0.000000
12.080001,0.045429,-43.146523,0.007860,0.007652,0.194363,0.202080,0.010294,1.943627,-43.146523,0.195464,0.000000
12.290001,0.038727,-43.102043,0.007989,0.007790,0.197858,0.172265,0.008776,1.978577,-43.102043,0.198967,0.000000
12.500001,0.042823,-43.102043,0.008127,0.007926,0.201326,0.190485,0.009704,2.013261,-43.102043,0.202471,0.000000
12.710001,0.051760,-43.146523,0.008248,0.008066,0.204882,0.230239,0.011729,2.048817,-43.146523,0.205957,0.000000
12.920001,0.065165,-43.102043,0.008407,0.008204,0.208386,0.289869,0.014767,2.083857,-43.102043,0.209461,0.000000
13.130001,0.057718,-43.146523,0.008567,0.008339,0.211803,0.256741,0.013079,2.118027,-43.146523,0.212965,0.000000
13.340001,0.064420,-43.102043,0.008701,0.008468,0.215098,0.286556,0.014598,2.150979,-43.102043,0.216468,0.000000
13.550000,0.033513,-43.102043,0.008852,0.008613,0.218766,0.149075,0.007594,2.187662,-43.102043,0.219955,0.000000
13.760000,0.047664,-43.102043,0.008985,0.008754,0.222339,0.212018,0.010801,2.223391,-43.102043,0.223458,0.000000
13.970000,0.037982,-43.146523,0.009149,0.008891,0.225842,0.168952,0.008607,2.258424,-43.146523,0.226961,0.000000
14.180000,0.060697,-43.191002,0.009283,0.009031,0.229381,0.269993,0.013754,2.293813,-43.191002,0.230448,0.000000
14.390000,0.055856,-43.146523,0.009421,0.009165,0.232789,0.248459,0.012657,2.327892,-43.146523,0.233951,0.000000
14.600000,0.043940,-43.146523,0.009554,0.009307,0.236397,0.195455,0.009957,2.363970,-43.146523,0.237455,0.000000
14.810000,0.058835,-43.191002,0.009701,0.009441,0.239814,0.261710,0.013332,2.398140,-43.191002,0.240959,0.000000
15.020000,0.077081,-43.235485,0.009856,0.009584,0.243439,0.342874,0.017467,2.434391,-43.235485,0.244444,0.000000
15.230000,0.051015,-43.191002,0.009998,0.009722,0.246933,0.226926,0.011560,2.469334,-43.191002,0.247948,0.000000
15.440001,0.070006,-43.146523,0.010132,0.009852,0.250229,0.311402,0.015864,2.502292,-43.146523,0.251452,0.000000
15.650001,0.057345,-43.235485,0.010296,0.009994,0.253854,0.255085,0.012995,2.538544,-43.235485,0.254938,0.000000
15.860001,0.077081,-43.279964,0.010412,0.010130,0.257315,0.342874,0.017467,2.573146,-43.279964,0.258442,0.000000
16.070002,0.060697,-43.191002,0.010559,0.010267,0.260792,0.269993,0.013754,2.607921,-43.191002,0.261945,0.000000
16.280001,0.083411,-43.279964,0.010697,0.010403,0.264243,0.371032,0.018901,2.642432,-43.279964,0.265449,0.000000
16.490002,0.083039,-43.235485,0.010831,0.010545,0.267834,0.369376,0.018817,2.678335,-43.235485,0.268935,0.000000
16.700001,0.097189,-43.279964,0.011003,0.010683,0.271338,0.432319,0.022023,2.713376,-43.279964,0.272439,0.000000
16.910002,0.055856,-43.235485,0.011154,0.010823,0.274893,0.248459,0.012657,2.748931,-43.235485,0.275942,0.000000
17.120001,0.078198,-43.146523,0.011283,0.010957,0.278301,0.347843,0.017720,2.783010,-43.146523,0.279429,0.000000
17.330000,0.048036,-43.279964,0.011421,0.011100,0.281935,0.213675,0.010885,2.819345,-43.279964,0.282932,0.000000
17.540001,0.055856,-43.279964,0.011542,0.011230,0.285239,0.248459,0.012657,2.852388,-43.279964,0.286436,0.000000
17.750000,0.056228,-43.279964,0.011706,0.011366,0.288699,0.250116,0.012741,2.886989,-43.279964,0.289940,0.000000
17.960001,0.067772,-43.279964,0.011839,0.011507,0.292273,0.301464,0.015357,2.922726,-43.279964,0.293426,0.000000
18.170000,0.078943,-43.279964,0.011973,0.011648,0.295871,0.351156,0.017889,2.958713,-43.279964,0.296930,0.000000
18.380001,0.108733,-43.324448,0.012094,0.011782,0.299262,0.483667,0.024639,2.992618,-43.324448,0.300433,0.000000
18.590000,0.087507,-43.279964,0.012249,0.011917,0.302696,0.389253,0.019829,3.026962,-43.279964,0.303919,0.000000
18.800001,0.104637,-43.279964,0.012383,0.012058,0.306278,0.465447,0.023711,3.062783,-43.279964,0.307423,0.000000
19.010000,0.092721,-43.324448,0.012542,0.012200,0.309885,0.412442,0.021011,3.098852,-43.324448,0.310926,0.000000
19.220001,0.089742,-43.235485,0.012680,0.012340,0.313442,0.399191,0.020336,3.134415,-43.235485,0.314413,0.000000
19.430000,0.062931,-43.368927,0.012827,0.012475,0.316858,0.279931,0.014260,3.168578,-43.368927,0.317916,0.000000
19.640001,0.067399,-43.279964,0.012965,0.012610,0.320284,0.299807,0.015273,3.202839,-43.279964,0.321419,0.000000
19.850000,0.052132,-43.324448,0.013107,0.012745,0.323727,0.231895,0.011813,3.237266,-43.324448,0.324923,0.000000
20.060001,0.042078,-43.324448,0.013254,0.012882,0.327204,0.187173,0.009535,3.272042,-43.324448,0.328409,0.000000
20.270000,0.077826,-43.279964,0.013400,0.013023,0.330785,0.346187,0.017636,3.307854,-43.279964,0.331913,0.000000
20.480001,0.091604,-43.457890,0.013551,0.013159,0.334229,0.407473,0.020758,3.342289,-43.457890,0.335417,0.000000
20.690001,0.095327,-43.279964,0.013689,0.013295,0.337689,0.424037,0.021601,3.376891,-43.279964,0.338903,0.000000
20.900002,0.114691,-43.324448,0.013844,0.013431,0.341158,0.510170,0.025989,3.411576,-43.324448,0.342407,0.000000
21.110001,0.100913,-43.457890,0.013956,0.013566,0.344575,0.448883,0.022867,3.445746,-43.457890,0.345910,0.000000
21.320002,0.112456,-43.324448,0.014099,0.013714,0.348330,0.500231,0.025483,3.483299,-43.324448,0.349414,0.000000
21.530001,0.112829,-43.413406,0.014250,0.013854,0.351885,0.501888,0.025567,3.518855,-43.413406,0.352900,0.000000
21.740002,0.107988,-43.413406,0.014405,0.013991,0.355363,0.480355,0.024470,3.553630,-43.413406,0.356404,0.000000
21.950001,0.090486,-43.368927,0.014538,0.014126,0.358788,0.402504,0.020505,3.587884,-43.368927,0.359907,0.000000
22.160002,0.101285,-43.457890,0.014676,0.014263,0.362275,0.450539,0.022952,3.622750,-43.457890,0.363393,0.000000
22.370001,0.154535,-43.368927,0.014819,0.014400,0.365761,0.687404,0.035018,3.657609,-43.368927,0.366897,0.000000
22.580002,0.382054,-43.457890,0.014970,0.014537,0.369238,1.699462,0.086575,3.692384,-43.457890,0.370400,0.000000
22.790001,0.697826,-43.413406,0.015077,-0.000008,-0.000207,3.104085,0.158130,-0.002074,-43.413406,-0.000008,0.000000
23.000002,0.665430,-43.413406,0.015069,-0.000009,-0.000216,2.959979,0.150789,-0.002165,-43.413406,-0.000008,0.000000
23.210001,0.658727,-43.502369,0.015082,-0.000009,-0.000216,2.930163,0.149270,-0.002165,-43.502369,-0.000008,0.000000
23.420002,0.651279,-43.457890,0.015073,-0.000009,-0.000216,2.897036,0.147582,-0.002165,-43.457890,0.000243,0.000000
23.630001,0.667664,-43.502369,0.015103,-0.000008,-0.000199,2.969917,0.151295,-0.001991,-43.502369,0.000599,0.000000
23.840002,0.716817,-43.457890,0.015082,0.000003,0.000087,3.188561,0.162433,0.000871,-43.457890,0.000945,0.000000
24.050001,0.771556,-43.413406,0.015077,0.000017,0.000434,3.432051,0.174837,0.004337,-43.413406,0.001301,0.000000
24.260000,0.853478,-43.546852,0.015103,0.000028,0.000712,3.796458,0.193401,0.007116,-43.546852,0.001648,0.000000
24.470001,0.941730,-43.457890,0.015090,0.000043,0.001093,4.189024,0.213399,0.010931,-43.457890,0.001995,0.000000
24.680000,1.030727,-43.502369,0.015095,0.000055,0.001397,4.584902,0.233566,0.013966,-43.502369,0.002350,0.000000
24.890001,1.150259,-43.502369,0.015112,0.000071,0.001804,5.116606,0.260652,0.018039,-43.502369,0.002697,0.000000
25.100000,1.176697,-43.502369,0.015151,0.000079,0.001995,5.234210,0.266643,0.019946,-43.502369,0.003045,0.000000
25.310001,1.320060,-43.546852,0.015155,0.000092,0.002333,5.871922,0.299130,0.023330,-43.546852,0.003400,0.000000
25.520000,1.433634,-43.502369,0.015181,0.000110,0.002784,6.377123,0.324866,0.027842,-43.502369,0.003747,0.000000
25.730001,1.577370,-43.502369,0.015168,0.000124,0.003140,7.016491,0.357437,0.031399,-43.502369,0.004094,0.000000
25.940001,1.641045,-43.502369,0.015181,0.000135,0.003417,7.299735,0.371866,0.034170,-43.502369,0.004450,0.000000
26.150002,1.798187,-43.502369,0.015194,0.000152,0.003860,7.998733,0.407475,0.038598,-43.502369,0.004796,0.000000
26.360001,1.925538,-43.546852,0.015220,0.000163,0.004146,8.565221,0.436333,0.041460,-43.546852,0.005152,0.000000
26.570002,2.067039,-43.502369,0.015211,0.000178,0.004527,9.194651,0.468398,0.045275,-43.502369,0.005499,0.000000
26.780001,2.185454,-43.546852,0.015233,0.000189,0.004805,9.721384,0.495231,0.048045,-43.546852,0.005845,0.000000
26.990002,2.380949,-43.502369,0.015246,0.000205,0.005203,10.590992,0.539531,0.052035,-43.502369,0.006201,0.000000
27.200001,2.458775,-43.546852,0.015263,0.000213,0.005412,10.937179,0.557166,0.054116,-43.546852,0.006548,0.000000
27.410002,2.689646,-43.591331,0.015246,0.000232,0.005898,11.964144,0.609483,0.058976,-43.591331,0.006895,0.000000
27.620001,2.935784,-43.502369,0.015271,0.000249,0.006331,13.059021,0.665258,0.063314,-43.502369,0.007250,0.000000
27.830002,3.100745,-43.591331,0.015289,0.000262,0.006652,13.792805,0.702639,0.066523,-43.591331,0.007597,0.000000
28.040001,3.222883,-43.502369,0.015293,0.000276,0.007016,14.336102,0.730316,0.070164,-43.502369,0.007944,0.000000
28.250002,3.447424,-43.502369,0.015323,0.000289,0.007337,15.334908,0.781197,0.073374,-43.502369,0.008300,0.000000
28.460001,3.590788,-43.635815,0.015332,0.000300,0.007614,15.972621,0.813684,0.076145,-43.635815,0.008647,0.000000
28.670002,3.867088,-43.502369,0.015349,0.000317,0.008057,17.201666,0.876295,0.080565,-43.502369,0.009002,0.000000
28.880001,4.032422,-43.591331,0.015345,0.000328,0.008334,17.937107,0.913760,0.083343,-43.591331,0.009349,0.000000
29.090002,4.135569,-43.635815,0.015379,0.000336,0.008525,18.395927,0.937133,0.085251,-43.635815,0.009696,0.000000
29.300001,4.356386,-43.591331,0.015358,0.000349,0.008863,19.378172,0.987171,0.088635,-43.591331,0.010051,0.000000
29.510002,4.869887,-43.635815,0.015375,0.000374,0.009488,21.662338,1.103532,0.094880,-43.635815,0.010399,0.000000
29.720001,4.950319,-43.591331,0.015392,0.000384,0.009757,22.020121,1.121758,0.097567,-43.591331,0.010745,0.000000
29.930002,5.244866,-43.591331,0.015414,0.000401,0.010181,23.330328,1.188504,0.101814,-43.591331,0.011101,0.000000
30.140001,5.404986,-43.591331,0.015401,0.000414,0.010511,24.042580,1.224787,0.105114,-43.591331,0.011448,0.000000
30.350002,5.553563,-43.591331,0.015444,0.000422,0.010728,24.703480,1.258455,0.107279,-43.591331,0.011794,0.000000
30.560001,5.965779,-43.680294,0.015435,0.000440,0.011187,26.537111,1.351865,0.111874,-43.680294,0.012150,0.000000
30.770002,6.195160,-43.591331,0.015448,0.000453,0.011517,27.557449,1.403843,0.115174,-43.591331,0.012497,0.000000
30.980001,6.278200,-43.680294,0.015457,0.000460,0.011691,27.926826,1.422660,0.116908,-43.680294,0.012844,0.000000
31.190001,6.519497,-43.635815,0.015474,0.000474,0.012046,29.000170,1.477339,0.120458,-43.635815,0.013199,0.000000
31.400002,7.210620,-43.680294,0.015496,0.000502,0.012757,32.074440,1.633950,0.127574,-43.680294,0.013546,0.000000
31.610001,7.298500,-43.680294,0.015500,0.000511,0.012991,32.465351,1.653864,0.129913,-43.680294,0.013902,0.000000
31.820002,7.442981,-43.680294,0.015517,0.000523,0.013286,33.108032,1.686604,0.132865,-43.680294,0.014249,0.000000
32.030003,7.708110,-43.680294,0.015509,0.000536,0.013625,34.287384,1.746683,0.136249,-43.680294,0.014596,0.000000
32.240002,8.123305,-43.635815,0.015530,0.000554,0.014075,36.134266,1.840767,0.140753,-43.635815,0.014951,0.000000
32.450001,8.254753,-43.680294,0.015556,0.000564,0.014318,36.718975,1.870554,0.143183,-43.680294,0.015299,0.000000
32.660000,8.594729,-43.769257,0.015560,0.000580,0.014735,38.231266,1.947594,0.147346,-43.769257,0.015645,0.000000
32.870003,8.691545,-43.635815,0.015569,0.000589,0.014960,38.661926,1.969532,0.149602,-43.635815,0.016001,0.000000
33.080002,9.050885,-43.724773,0.015560,0.000604,0.015350,40.260349,2.050960,0.153500,-43.724773,0.016348,0.000000
33.290001,9.420279,-43.769257,0.015595,0.000621,0.015784,41.903492,2.134666,0.157838,-43.769257,0.016694,0.000000
33.500000,9.664927,-43.724773,0.015612,0.000636,0.016148,42.991745,2.190104,0.161479,-43.724773,0.017050,0.000000
33.710003,9.879786,-43.680294,0.015612,0.000647,0.016443,43.947487,2.238792,0.164431,-43.680294,0.017397,0.000000
33.920002,10.080495,-43.724773,0.015634,0.000662,0.016816,44.840282,2.284273,0.168155,-43.724773,0.017753,0.000000
34.130001,10.497552,-43.680294,0.015646,0.000679,0.017241,46.695442,2.378779,0.172410,-43.680294,0.018099,0.000000
34.340000,10.721721,-43.813736,0.015664,0.000691,0.017562,47.692596,2.429577,0.175619,-43.813736,0.018446,0.000000
34.550003,10.823006,-43.724773,0.015668,0.000702,0.017831,48.143135,2.452528,0.178306,-43.724773,0.018802,0.000000
34.760002,10.947378,-43.769257,0.015664,0.000713,0.018117,48.696369,2.480711,0.181168,-43.769257,0.019149,0.000000
34.970001,11.346933,-43.724773,0.015685,0.000729,0.018516,50.473679,2.571252,0.185157,-43.724773,0.019495,0.000000
35.180000,11.772927,-43.724773,0.015690,0.000748,0.018993,52.368595,2.667783,0.189926,-43.724773,0.019851,0.000000
35.390003,11.957624,-43.769257,0.015703,0.000761,0.019322,53.190170,2.709636,0.193219,-43.769257,0.020198,0.000000
35.600002,12.040664,-43.769257,0.015711,0.000771,0.019582,53.559547,2.728453,0.195823,-43.769257,0.020545,0.000000
35.810001,12.374681,-43.858219,0.015741,0.000787,0.019981,55.045334,2.804143,0.199812,-43.858219,0.020900,0.000000
36.020000,12.483415,-43.813736,0.015741,0.000797,0.020242,55.529003,2.828782,0.202416,-43.813736,0.021248,0.000000
36.230003,12.674069,-43.769257,0.015754,0.000810,0.020563,56.377075,2.871985,0.205626,-43.769257,0.021603,0.000000
36.440002,12.969733,-43.769257,0.015759,0.000822,0.020884,57.692253,2.938983,0.208835,-43.769257,0.021950,0.000000
36.650002,13.094850,-43.769257,0.015784,0.000833,0.021152,58.248798,2.967335,0.211523,-43.769257,0.022297,0.000000
36.860001,13.346201,-43.813736,0.015780,0.000846,0.021482,59.366867,3.024292,0.214815,-43.813736,0.022653,0.000000
37.070004,13.641493,-43.813736,0.015789,0.000863,0.021915,60.680389,3.091207,0.219153,-43.813736,0.022999,0.000000
37.280003,14.256280,-43.813736,0.015823,0.000885,0.022488,63.415100,3.230519,0.224876,-43.813736,0.023346,0.000000
37.490002,14.262982,-43.813736,0.015836,0.000897,0.022782,63.444916,3.232038,0.227820,-43.813736,0.023702,0.000000
37.700001,14.293517,-43.813736,0.015836,0.000909,0.023077,63.580738,3.238957,0.230773,-43.813736,0.024048,0.000000
37.910004,14.573541,-43.769257,0.015845,0.000924,0.023468,64.826347,3.302412,0.234679,-43.769257,0.024395,0.000000
38.120003,14.698658,-43.858219,0.015866,0.000932,0.023675,65.382896,3.330764,0.236753,-43.858219,0.024751,0.000000
38.330002,14.922082,-43.769257,0.015871,0.000947,0.024058,66.376732,3.381392,0.240575,-43.769257,0.025098,0.000000
38.540001,15.446754,-43.902699,0.015892,0.000963,0.024465,68.710594,3.500284,0.244648,-43.902699,0.025453,0.000000
38.750000,15.549157,-43.813736,0.015875,0.000975,0.024777,69.166107,3.523489,0.247767,-43.813736,0.025800,0.000000
38.960003,15.711139,-43.858219,0.015910,0.000989,0.025124,69.886635,3.560195,0.251241,-43.858219,0.026148,0.000000
39.170002,16.183680,-43.858219,0.015910,0.001007,0.025566,71.988602,3.667274,0.255662,-43.858219,0.026503,0.000000
39.380001,16.328905,-43.858219,0.015922,0.001018,0.025861,72.634598,3.700183,0.258607,-43.858219,0.026850,0.000000
39.590000,16.440617,-43.947178,0.015931,0.001030,0.026173,73.131516,3.725497,0.261733,-43.947178,0.027197,0.000000
39.800003,16.748569,-43.902699,0.015948,0.001045,0.026555,74.501358,3.795280,0.265548,-43.902699,0.027552,0.000000
40.010002,16.881134,-43.858219,0.015961,0.001058,0.026867,75.091034,3.825320,0.268667,-43.858219,0.027899,0.000000
40.220001,17.093760,-43.947178,0.015953,0.001070,0.027170,76.036842,3.873501,0.271702,-43.947178,0.028246,0.000000
40.430000,17.608377,-43.902699,0.015991,0.001085,0.027569,78.325974,3.990115,0.275692,-43.902699,0.028602,0.000000
40.640003,17.769243,-43.947178,0.015987,0.001098,0.027890,79.041542,4.026568,0.278901,-43.947178,0.028948,0.000000
40.850002,18.012402,-43.902699,0.015996,0.001110,0.028194,80.123161,4.081669,0.281937,-43.902699,0.029295,0.000000
41.060001,18.365784,-43.902699,0.016017,0.001127,0.028619,81.695084,4.161746,0.286191,-43.902699,0.029651,0.000000
41.270000,18.698311,-43.947178,0.016022,0.001143,0.029026,83.174240,4.237098,0.290264,-43.947178,0.029998,0.000000
41.480003,18.853964,-43.902699,0.016065,0.001154,0.029312,83.866623,4.272369,0.293125,-43.902699,0.030353,0.000000
41.690002,19.083717,-43.991661,0.016056,0.001168,0.029659,84.888611,4.324432,0.296592,-43.991661,0.030700,0.000000
41.900002,19.308630,-43.902699,0.016056,0.001181,0.029989,85.889076,4.375398,0.299892,-43.902699,0.031047,0.000000
42.110001,19.588282,-43.902699,0.016069,0.001194,0.030328,87.133026,4.438768,0.303276,-43.902699,0.031403,0.000000
42.320004,20.144979,-43.947178,0.016073,0.001212,0.030778,89.609344,4.564918,0.307780,-43.947178,0.031749,0.000000
42.530003,20.411970,-43.947178,0.016112,0.001224,0.031091,90.796974,4.625419,0.310906,-43.947178,0.032097,0.000000
42.740002,20.573208,-43.991661,0.016116,0.001235,0.031377,91.514198,4.661955,0.313768,-43.991661,0.032452,0.000000
42.950001,20.888235,-43.902699,0.016125,0.001248,0.031689,92.915512,4.733342,0.316887,-43.902699,0.032799,0.000000
43.160004,21.467274,-44.036140,0.016129,0.001267,0.032175,95.491203,4.864554,0.321746,-44.036140,0.033146,0.000000
43.370003,21.648247,-43.991661,0.016129,0.001278,0.032452,96.296211,4.905563,0.324517,-43.991661,0.033502,0.000000
43.580002,21.913004,-43.991661,0.016138,0.001292,0.032817,97.473907,4.965558,0.328166,-43.991661,0.033848,0.000000
43.790001,22.261543,-43.991661,0.016160,0.001306,0.033163,99.024292,5.044538,0.331632,-43.991661,0.034204,0.000000
44.000004,22.570240,-43.991661,0.016155,0.001318,0.033467,100.397438,5.114490,0.334668,-43.991661,0.034551,0.000000
44.210003,22.949688,-43.991661,0.016190,0.001331,0.033805,102.085312,5.200474,0.338052,-43.991661,0.034897,0.000000
44.420002,23.433399,-44.036140,0.016194,0.001347,0.034221,104.236969,5.310084,0.342207,-44.036140,0.035253,0.000000
44.630001,23.821785,-43.947178,0.016203,0.001361,0.034568,105.964592,5.398094,0.345682,-43.947178,0.035600,0.000000
44.840004,23.986746,-43.991661,0.016203,0.001373,0.034880,106.698372,5.435474,0.348801,-43.991661,0.035947,0.000000
45.050003,24.779900,-44.036140,0.016216,0.001392,0.035357,110.226501,5.615206,0.353570,-44.036140,0.036302,0.000000
45.260002,25.006302,-43.947178,0.016254,0.001404,0.035661,111.233589,5.666509,0.356605,-43.947178,0.036649,0.000000
45.470001,25.357449,-44.036140,0.016254,0.001417,0.035991,112.795563,5.746080,0.359906,-44.036140,0.036997,0.000000
45.680000,25.655346,-44.080624,0.016267,0.001432,0.036372,114.120682,5.813584,0.363721,-44.080624,0.037352,0.000000
45.890003,25.986385,-44.036140,0.016293,0.001443,0.036641,115.593216,5.888599,0.366408,-44.036140,0.037698,0.000000
46.100002,26.384825,-43.991661,0.016272,0.001457,0.036997,117.365562,5.978887,0.369966,-43.991661,0.038054,0.000000
46.310001,26.929977,-43.991661,0.016302,0.001470,0.037343,119.790520,6.102420,0.373433,-43.991661,0.038401,0.000000
46.520000,26.950085,-44.125103,0.016293,0.001478,0.037551,119.879967,6.106977,0.375515,-44.125103,0.038748,0.000000
46.730003,27.561150,-44.036140,0.016310,0.001494,0.037950,122.598114,6.245446,0.379504,-44.036140,0.039103,0.000000
46.940002,28.643635,-44.125103,0.016336,0.001517,0.038523,127.413254,6.490740,0.385227,-44.125103,0.039451,0.000000
47.150002,28.642519,-44.036140,0.016349,0.001526,0.038748,127.408287,6.490488,0.387482,-44.036140,0.039797,0.000000
47.360001,29.013773,-44.080624,0.016371,0.001539,0.039095,129.059708,6.574615,0.390949,-44.080624,0.040153,0.000000
47.570004,29.576429,-44.036140,0.016367,0.001552,0.039424,131.562531,6.702115,0.394242,-44.036140,0.040500,0.000000
47.780003,29.999443,-44.125103,0.016367,0.001566,0.039788,133.444183,6.797971,0.397883,-44.125103,0.040847,0.000000
47.990002,30.461185,-44.080624,0.016384,0.001580,0.040136,135.498123,6.902604,0.401358,-44.080624,0.041202,0.000000
48.200001,30.943407,-44.036140,0.016388,0.001593,0.040457,137.643143,7.011876,0.404567,-44.036140,0.041549,0.000000
48.410004,31.370892,-43.991661,0.016405,0.001604,0.040734,139.544693,7.108746,0.407338,-43.991661,0.041896,0.000000
48.620003,31.844921,-44.125103,0.016401,0.001617,0.041072,141.653290,7.216162,0.410722,-44.125103,0.042252,0.000000
48.830002,32.543491,-44.125103,0.016410,0.001634,0.041514,144.760681,7.374461,0.415142,-44.125103,0.042598,0.000000
49.040001,33.357124,-44.125103,0.016427,0.001652,0.041957,148.379898,7.558832,0.419571,-44.125103,0.042954,0.000000
49.250004,33.812164,-44.169586,0.016414,0.001664,0.042277,150.404022,7.661946,0.422773,-44.169586,0.043301,0.000000
49.460003,34.358063,-44.169586,0.016444,0.001679,0.042650,152.832291,7.785648,0.426505,-44.169586,0.043648,0.000000
49.670002,34.681282,-44.169586,0.016453,0.001690,0.042928,154.270050,7.858891,0.429283,-44.169586,0.044003,0.000000
49.880001,35.327351,-44.169586,0.016461,0.001706,0.043345,157.143906,8.005292,0.433446,-44.169586,0.044351,0.000000
50.090004,35.781269,-44.169586,0.016466,0.001719,0.043656,159.163040,8.108151,0.436565,-44.169586,0.044697,0.000000
50.300003,36.054592,-44.169586,0.016496,0.001729,0.043908,160.378830,8.170088,0.439078,-44.169586,0.045053,0.000000
50.510002,36.228863,-44.125103,0.016483,0.001737,0.044125,161.154037,8.209578,0.441251,-44.125103,0.045400,0.000000
50.720001,36.896526,-44.169586,0.016492,0.001749,0.044437,164.123947,8.360872,0.444369,-44.169586,0.045747,0.000000
50.930004,38.553955,-44.214066,0.016504,0.001778,0.045157,171.496552,8.736451,0.451568,-44.214066,0.046102,0.000000
51.140003,38.920372,-44.258545,0.016526,0.001791,0.045486,173.126465,8.819483,0.454861,-44.258545,0.046449,0.000000
51.350002,39.620804,-44.169586,0.016522,0.001806,0.045877,176.242142,8.978202,0.458767,-44.169586,0.046805,0.000000
51.560001,40.047543,-44.125103,0.016548,0.001817,0.046154,178.140366,9.074903,0.461538,-44.125103,0.047151,0.000000
51.770004,40.413212,-44.214066,0.016565,0.001828,0.046441,179.766937,9.157765,0.464407,-44.214066,0.047498,0.000000
51.980003,41.364624,-44.169586,0.016561,0.001847,0.046918,183.999039,9.373358,0.469176,-44.169586,0.047854,0.000000
52.190002,41.713909,-44.214066,0.016573,0.001855,0.047126,185.552734,9.452507,0.471257,-44.214066,0.048201,0.000000
52.400002,41.723591,-44.214066,0.016578,0.001862,0.047290,185.595795,9.454700,0.472900,-44.214066,0.048547,0.000000
52.610001,42.468334,-44.169586,0.016565,0.001875,0.047637,188.908585,9.623463,0.476374,-44.169586,0.048903,0.000000
52.820004,44.368179,-44.303028,0.016595,0.001905,0.048391,197.359512,10.053973,0.483914,-44.303028,0.049250,0.000000
53.030003,44.626232,-44.214066,0.016604,0.001914,0.048617,198.507401,10.112449,0.486170,-44.214066,0.049597,0.000000
53.240002,45.293152,-44.258545,0.016591,0.001929,0.048998,201.473999,10.263575,0.489985,-44.258545,0.049952,0.000000
53.450001,45.742233,-44.303028,0.016591,0.001939,0.049259,203.471619,10.365338,0.492589,-44.303028,0.050300,0.000000
53.660004,46.738705,-44.214066,0.016630,0.001958,0.049744,207.904144,10.591142,0.497441,-44.214066,0.050655,0.000000
53.870003,47.230606,-44.214066,0.016612,0.001970,0.050030,210.092224,10.702608,0.500303,-44.214066,0.051002,0.000000
54.080002,47.856937,-44.303028,0.016625,0.001982,0.050334,212.878296,10.844537,0.503338,-44.303028,0.051349,0.000000
54.290001,48.136215,-44.258545,0.016638,0.001990,0.050551,214.120575,10.907823,0.505511,-44.258545,0.051705,0.000000
54.500004,49.348660,-44.303028,0.016634,0.002012,0.051106,219.513794,11.182566,0.511059,-44.303028,0.052051,0.000000
54.710003,50.168999,-44.214066,0.016655,0.002024,0.051409,223.162857,11.368458,0.514095,-44.214066,0.052398,0.000000
54.920002,51.020985,-44.303028,0.016647,0.002040,0.051808,226.952667,11.561521,0.518084,-44.303028,0.052754,0.000000
55.130001,51.346813,-44.303028,0.016664,0.002050,0.052077,228.402039,11.635355,0.520771,-44.303028,0.053101,0.000000
55.340004,52.153370,-44.303028,0.016664,0.002063,0.052407,231.989777,11.818122,0.524072,-44.303028,0.053447,0.000000
55.550003,53.219101,-44.303028,0.016677,0.002080,0.052840,236.730377,12.059621,0.528402,-44.303028,0.053803,0.000000
55.760002,53.839848,-44.347507,0.016673,0.002092,0.053135,239.491608,12.200284,0.531354,-44.347507,0.054150,0.000000
55.970001,54.500805,-44.303028,0.016673,0.002105,0.053474,242.431686,12.350059,0.534738,-44.303028,0.054497,0.000000
56.180004,54.944302,-44.303028,0.016703,0.002115,0.053716,244.404465,12.450557,0.537160,-44.303028,0.054852,0.000000
56.390003,55.886776,-44.347507,0.016707,0.002130,0.054107,248.596802,12.664124,0.541066,-44.347507,0.055200,0.000000
56.600002,57.247799,-44.347507,0.016686,0.002151,0.054636,254.650925,12.972537,0.546357,-44.347507,0.055555,0.000000
56.810001,57.989937,-44.347507,0.016681,0.002164,0.054974,257.952118,13.140708,0.549741,-44.347507,0.055901,0.000000
57.020004,58.602863,-44.391991,0.016707,0.002176,0.055278,260.678558,13.279598,0.552776,-44.391991,0.056249,0.000000
57.230003,59.241108,-44.391991,0.016720,0.002188,0.055564,263.517609,13.424227,0.555638,-44.391991,0.056604,0.000000
57.440002,59.779930,-44.391991,0.016724,0.002198,0.055841,265.914398,13.546326,0.558408,-44.391991,0.056951,0.000000
57.650002,60.526539,-44.347507,0.016729,0.002213,0.056214,269.235504,13.715509,0.562140,-44.347507,0.057298,0.000000
57.860004,61.433636,-44.347507,0.016746,0.002225,0.056508,273.270447,13.921062,0.565085,-44.347507,0.057654,0.000000
58.070004,61.881973,-44.436470,0.016746,0.002235,0.056761,275.264771,14.022655,0.567606,-44.436470,0.058000,0.000000
58.280003,62.850887,-44.347507,0.016755,0.002250,0.057150,279.574707,14.242214,0.571504,-44.347507,0.058347,0.000000
58.490002,64.175041,-44.391991,0.016767,0.002272,0.057705,285.464844,14.542273,0.577053,-44.391991,0.058703,0.000000
58.700005,65.592659,-44.391991,0.016755,0.002288,0.058122,291.770721,14.863509,0.581216,-44.391991,0.059050,0.000000
58.910004,66.137070,-44.347507,0.016759,0.002299,0.058390,294.192383,14.986874,0.583903,-44.347507,0.059405,0.000000
59.120003,66.794678,-44.436470,0.016763,0.002311,0.058694,297.117554,15.135891,0.586939,-44.436470,0.059752,0.000000
59.330002,67.458992,-44.303028,0.016789,0.002313,0.058755,300.072571,15.286427,0.587552,-44.303028,0.058997,0.000000
59.540005,67.068001,-44.391991,0.016776,0.002313,0.058755,298.333374,15.197826,0.587552,-44.391991,0.058997,0.000000
59.750004,66.802498,-44.391991,0.016793,0.002309,0.058651,297.152344,15.137663,0.586507,-44.391991,0.058755,0.000000
59.960003,66.495667,-44.436470,0.016802,0.002307,0.058608,295.787506,15.068133,0.586076,-44.436470,0.058755,0.000000
60.170002,66.267776,-44.391991,0.016815,0.002307,0.058598,294.773804,15.016493,0.585985,-44.391991,0.058755,0.000000
60.380001,66.053658,-44.436470,0.016793,0.002307,0.058590,293.821350,14.967973,0.585902,-44.436470,0.058755,0.000000
60.590004,65.868965,-44.436470,0.016815,0.002306,0.058582,292.999786,14.926121,0.585818,-44.436470,0.058755,0.000000
60.800003,65.694695,-44.480949,0.016793,0.002306,0.058573,292.224609,14.886631,0.585728,-44.480949,0.058755,0.000000
61.010002,65.547607,-44.436470,0.016819,0.002306,0.058573,291.570312,14.853300,0.585728,-44.436470,0.058755,0.000000
61.220001,65.409454,-44.480949,0.016811,0.002306,0.058573,290.955780,14.821995,0.585728,-44.480949,0.058755,0.000000
61.430004,65.290298,-44.480949,0.016806,0.002306,0.058573,290.425751,14.794993,0.585728,-44.480949,0.058755,0.000000
61.640003,65.176720,-44.480949,0.016811,0.002306,0.058573,289.920532,14.769256,0.585728,-44.480949,0.058755,0.000000
61.850002,65.059799,-44.525433,0.016819,0.002306,0.058564,289.400452,14.742761,0.585644,-44.525433,0.058755,0.000000
62.060001,64.978989,-44.436470,0.016819,0.002306,0.058564,289.040985,14.724449,0.585644,-44.436470,0.058755,0.000000
62.270004,64.860207,-44.480949,0.016811,0.002306,0.058564,288.512604,14.697534,0.585644,-44.480949,0.058755,0.000000
62.480003,64.781639,-44.480949,0.016824,0.002306,0.058564,288.163116,14.679729,0.585644,-44.480949,0.058755,0.000000
62.690002,64.685188,-44.480949,0.016832,0.002306,0.058564,287.734100,14.657873,0.585644,-44.480949,0.058755,0.000000
62.900002,64.614815,-44.569912,0.016811,0.002306,0.058564,287.421051,14.641926,0.585644,-44.569912,0.058755,0.000000
63.110004,64.536987,-44.525433,0.016832,0.002306,0.058564,287.074860,14.624290,0.585644,-44.525433,0.058755,0.000000
63.320004,64.452835,-44.525433,0.016819,0.002306,0.058564,286.700531,14.605221,0.585644,-44.525433,0.058755,0.000000
63.530003,64.409264,-44.525433,0.016824,0.002306,0.058564,286.506714,14.595347,0.585644,-44.525433,0.058755,0.000000
63.740002,64.331436,-44.525433,0.016824,0.002306,0.058564,286.160522,14.577712,0.585644,-44.525433,0.058755,0.000000
63.950005,64.275208,-44.525433,0.016824,0.002306,0.058564,285.910400,14.564970,0.585644,-44.525433,0.058755,0.000000
64.160004,64.213768,-44.525433,0.016841,0.002306,0.058564,285.637115,14.551047,0.585644,-44.525433,0.058755,0.000000
64.370003,64.159027,-44.569912,0.016836,0.002305,0.058555,285.393616,14.538644,0.585554,-44.569912,0.058755,0.000000
64.580002,64.095726,-44.569912,0.016824,0.002305,0.058555,285.112030,14.524299,0.585554,-44.569912,0.058755,0.000000
64.790001,64.059235,-44.569912,0.016836,0.002305,0.058555,284.949707,14.516030,0.585554,-44.569912,0.058755,0.000000
65.000000,64.000771,-44.525433,0.016824,0.002305,0.058555,284.689636,14.502782,0.585554,-44.525433,0.058755,0.000000
65.210007,63.957207,-44.525433,0.016836,0.002305,0.058555,284.495850,14.492910,0.585554,-44.525433,0.058755,0.000000
65.420006,63.906563,-44.614395,0.016819,0.002305,0.058555,284.270599,14.481434,0.585554,-44.614395,0.058755,0.000000
65.630005,63.859272,-44.614395,0.016836,0.002305,0.058555,284.060242,14.470718,0.585554,-44.614395,0.058755,0.000000
65.840004,63.810863,-44.569912,0.016828,0.002305,0.058555,283.844910,14.459748,0.585554,-44.569912,0.058755,0.000000
66.050003,63.767296,-44.525433,0.016819,0.002305,0.058555,283.651093,14.449876,0.585554,-44.525433,0.058755,0.000000
66.260002,63.723354,-44.525433,0.016824,0.002305,0.058555,283.455627,14.439919,0.585554,-44.525433,0.058755,0.000000
66.470001,63.685001,-44.525433,0.016824,0.002305,0.058555,283.285034,14.431228,0.585554,-44.525433,0.058755,0.000000
66.680000,63.634731,-44.614395,0.016819,0.002305,0.058555,283.061432,14.419836,0.585554,-44.614395,0.058755,0.000000
66.889999,63.599354,-44.525433,0.016836,0.002305,0.058555,282.904053,14.411819,0.585554,-44.525433,0.058755,0.000000
67.100006,63.560627,-44.658875,0.016828,0.002305,0.058555,282.731781,14.403044,0.585554,-44.658875,0.058755,0.000000
67.310005,63.517807,-44.569912,0.016824,0.002305,0.058555,282.541321,14.393341,0.585554,-44.569912,0.058755,0.000000
67.520004,63.494347,-44.614395,0.016841,0.002305,0.058555,282.436951,14.388024,0.585554,-44.614395,0.058755,0.000000
67.730003,63.462696,-44.658875,0.016832,0.002305,0.058555,282.296173,14.380853,0.585554,-44.658875,0.058755,0.000000
67.940002,63.431789,-44.569912,0.016824,0.002305,0.058555,282.158691,14.373849,0.585554,-44.569912,0.058755,0.000000
68.150002,63.392689,-44.703358,0.016828,0.002305,0.058555,281.984772,14.364989,0.585554,-44.703358,0.058755,0.000000
68.360001,63.365505,-44.703358,0.016836,0.002305,0.058555,281.863831,14.358829,0.585554,-44.703358,0.058755,0.000000
68.570000,63.328270,-44.658875,0.016828,0.002305,0.058555,281.698212,14.350390,0.585554,-44.658875,0.058755,0.000000
68.780006,63.304066,-44.747837,0.016836,0.002305,0.058555,281.590546,14.344907,0.585554,-44.747837,0.058755,0.000000
68.990005,63.271667,-44.658875,0.016832,0.002305,0.058555,281.446442,14.337565,0.585554,-44.658875,0.058755,0.000000
69.200005,63.242249,-44.703358,0.016836,0.002305,0.058555,281.315582,14.330898,0.585554,-44.703358,0.058755,0.000000
69.410004,63.218792,-44.658875,0.016836,0.002305,0.058555,281.211243,14.325583,0.585554,-44.658875,0.058755,0.000000
69.620003,63.186394,-44.658875,0.016832,0.002305,0.058555,281.067108,14.318241,0.585554,-44.658875,0.058755,0.000000
69.830002,63.152882,-44.747837,0.016819,0.002305,0.058555,280.918060,14.310647,0.585554,-44.747837,0.058755,0.000000
70.040001,63.127186,-44.658875,0.016832,0.002305,0.058555,280.803741,14.304825,0.585554,-44.658875,0.058755,0.000000
70.250000,63.093674,-44.703358,0.016836,0.002305,0.058555,280.654663,14.297231,0.585554,-44.703358,0.058755,0.000000
70.460007,63.071331,-44.658875,0.016828,0.002305,0.058555,280.555298,14.292168,0.585554,-44.658875,0.058755,0.000000
70.670006,63.043777,-44.747837,0.016836,0.002305,0.058555,280.432739,14.285924,0.585554,-44.747837,0.058755,0.000000
70.880005,63.028507,-44.703358,0.016845,0.002305,0.058555,280.364807,14.282463,0.585554,-44.703358,0.058755,0.000000
71.090004,62.997601,-44.658875,0.016845,0.002305,0.058555,280.227325,14.275460,0.585554,-44.658875,0.058755,0.000000
71.300003,62.972652,-44.747837,0.016828,0.002305,0.058555,280.116333,14.269807,0.585554,-44.747837,0.058755,0.000000
71.510002,62.947704,-44.703358,0.016819,0.002305,0.058555,280.005371,14.264153,0.585554,-44.703358,0.058755,0.000000
71.720001,62.919777,-44.703358,0.016858,0.002305,0.058555,279.881134,14.257826,0.585554,-44.703358,0.058755,0.000000
71.930000,62.892963,-44.747837,0.016849,0.002305,0.058555,279.761871,14.251749,0.585554,-44.747837,0.058755,0.000000
72.140007,62.874718,-44.703358,0.016832,0.002305,0.058555,279.680725,14.247614,0.585554,-44.703358,0.058755,0.000000
72.350006,62.840462,-44.792316,0.016845,0.002305,0.058555,279.528320,14.239852,0.585554,-44.792316,0.058755,0.000000
72.560005,62.827801,-44.747837,0.016828,0.002305,0.058555,279.472015,14.236983,0.585554,-44.747837,0.058755,0.000000
72.770004,62.806202,-44.747837,0.016854,0.002305,0.058555,279.375946,14.232088,0.585554,-44.747837,0.058755,0.000000
72.980003,62.779762,-44.792316,0.016819,0.002305,0.058555,279.258331,14.226097,0.585554,-44.792316,0.058755,0.000000
73.190002,62.766357,-44.792316,0.016824,0.002305,0.058555,279.198700,14.223060,0.585554,-44.792316,0.058755,0.000000
73.400002,62.736942,-44.836800,0.016832,0.002305,0.058547,279.067871,14.216394,0.585470,-44.836800,0.058755,0.000000
73.610001,62.711620,-44.703358,0.016832,0.002305,0.058547,278.955231,14.210656,0.585470,-44.703358,0.058755,0.000000
73.820000,62.684437,-44.792316,0.016841,0.002305,0.058547,278.834290,14.204496,0.585470,-44.792316,0.058755,0.000000
74.030006,62.666935,-44.792316,0.016845,0.002305,0.058547,278.756439,14.200531,0.585470,-44.792316,0.058755,0.000000
74.240005,62.651295,-44.792316,0.016824,0.002305,0.058547,278.686890,14.196986,0.585470,-44.792316,0.058755,0.000000
74.450005,62.638264,-44.836800,0.016836,0.002305,0.058547,278.628906,14.194034,0.585470,-44.836800,0.058755,0.000000
74.660004,62.619644,-44.836800,0.016824,0.002305,0.058547,278.546082,14.189814,0.585470,-44.836800,0.058755,0.000000
74.870003,62.597675,-44.747837,0.016841,0.002305,0.058547,278.448364,14.184836,0.585470,-44.747837,0.058755,0.000000
75.080002,62.578682,-44.881279,0.016824,0.002305,0.058547,278.363892,14.180532,0.585470,-44.881279,0.058755,0.000000
75.290001,62.556713,-44.836800,0.016845,0.002305,0.058547,278.266144,14.175553,0.585470,-44.836800,0.058755,0.000000
75.500000,62.533627,-44.881279,0.016828,0.002305,0.058547,278.163452,14.170322,0.585470,-44.881279,0.058755,0.000000
75.710007,62.513889,-44.836800,0.016824,0.002305,0.058547,278.075653,14.165850,0.585470,-44.836800,0.058755,0.000000
75.920006,62.484474,-44.836800,0.016824,0.002305,0.058547,277.944824,14.159184,0.585470,-44.836800,0.058755,0.000000
76.130005,62.466225,-44.836800,0.016841,0.002305,0.058547,277.863647,14.155049,0.585470,-44.836800,0.058755,0.000000
76.340004,62.457661,-44.836800,0.016828,0.002305,0.058547,277.825562,14.153108,0.585470,-44.836800,0.058755,0.000000
76.550003,62.430477,-44.881279,0.016845,0.002305,0.058547,277.704620,14.146948,0.585470,-44.881279,0.058755,0.000000
76.760002,62.405903,-44.836800,0.016828,0.002305,0.058547,277.595306,14.141379,0.585470,-44.836800,0.058755,0.000000
76.970001,62.401806,-44.881279,0.016824,0.002305,0.058547,277.577087,14.140451,0.585470,-44.881279,0.058755,0.000000
77.180000,62.377602,-44.836800,0.016828,0.002305,0.058547,277.469421,14.134967,0.585470,-44.836800,0.058755,0.000000
77.390007,62.375366,-44.881279,0.016854,0.002305,0.058547,277.459473,14.134460,0.585470,-44.881279,0.058755,0.000000
77.600006,62.347813,-44.925762,0.016824,0.002305,0.058547,277.336914,14.128216,0.585470,-44.925762,0.058755,0.000000
77.810005,62.340363,-44.836800,0.016819,0.002305,0.058547,277.303772,14.126528,0.585470,-44.836800,0.058755,0.000000
78.020004,62.312065,-44.881279,0.016819,0.002305,0.058547,277.177917,14.120116,0.585470,-44.881279,0.058755,0.000000
78.230003,62.298286,-44.881279,0.016836,0.002305,0.058547,277.116608,14.116993,0.585470,-44.881279,0.058755,0.000000
78.440002,62.283764,-44.881279,0.016849,0.002305,0.058547,277.052032,14.113702,0.585470,-44.881279,0.058755,0.000000
78.650002,62.268497,-44.925762,0.016845,0.002305,0.058547,276.984100,14.110243,0.585470,-44.925762,0.058755,0.000000
78.860001,62.237217,-44.881279,0.016836,0.002305,0.058547,276.844971,14.103155,0.585470,-44.881279,0.058755,0.000000
79.070007,62.226048,-44.925762,0.016849,0.002305,0.058547,276.795288,14.100624,0.585470,-44.925762,0.058755,0.000000
79.280006,62.231258,-44.881279,0.016836,0.002305,0.058547,276.818451,14.101805,0.585470,-44.881279,0.058755,0.000000
79.490005,62.199982,-44.881279,0.016836,0.002305,0.058547,276.679352,14.094717,0.585470,-44.881279,0.058755,0.000000
79.700005,62.188065,-44.970242,0.016828,0.002305,0.058547,276.626312,14.092016,0.585470,-44.970242,0.058755,0.000000
79.910004,62.170563,-44.970242,0.016841,0.002305,0.058547,276.548462,14.088051,0.585470,-44.970242,0.058755,0.000000
80.120003,62.160507,-44.881279,0.016841,0.002305,0.058547,276.503754,14.085773,0.585470,-44.881279,0.058755,0.000000
80.330002,62.142262,-45.014721,0.016854,0.002305,0.058547,276.422577,14.081638,0.585470,-45.014721,0.058755,0.000000
80.540001,62.126995,-44.881279,0.016845,0.002305,0.058547,276.354675,14.078178,0.585470,-44.881279,0.058755,0.000000
80.750008,62.108006,-44.970242,0.016828,0.002305,0.058547,276.270203,14.073875,0.585470,-44.970242,0.058755,0.000000
80.960007,62.090874,-45.014721,0.016836,0.002305,0.058547,276.194000,14.069993,0.585470,-45.014721,0.058755,0.000000
81.170006,62.077469,-44.970242,0.016828,0.002305,0.058547,276.134369,14.066956,0.585470,-44.970242,0.058755,0.000000
81.380005,62.069649,-45.014721,0.016832,0.002305,0.058547,276.099579,14.065184,0.585470,-45.014721,0.058755,0.000000
81.590004,62.043213,-44.970242,0.016836,0.002305,0.058547,275.981995,14.059193,0.585470,-44.970242,0.058755,0.000000
81.800003,62.030178,-44.970242,0.016841,0.002305,0.058547,275.924011,14.056239,0.585470,-44.970242,0.058755,0.000000
82.010002,62.013794,-44.970242,0.016849,0.002305,0.058547,275.851135,14.052526,0.585470,-44.970242,0.058755,0.000000
82.220001,62.001133,-45.059204,0.016845,0.002305,0.058547,275.794800,14.049658,0.585470,-45.059204,0.058755,0.000000
82.430000,61.986984,-45.059204,0.016841,0.002305,0.058547,275.731873,14.046451,0.585470,-45.059204,0.058755,0.000000
82.640007,61.984005,-44.970242,0.016836,0.002305,0.058547,275.718628,14.045776,0.585470,-44.970242,0.058755,0.000000
82.850006,61.970226,-45.014721,0.016836,0.002305,0.058547,275.657349,14.042654,0.585470,-45.014721,0.058755,0.000000
83.060005,61.944904,-44.970242,0.016845,0.002305,0.058547,275.544708,14.036916,0.585470,-44.970242,0.058755,0.000000
83.270004,61.945278,-45.014721,0.016854,0.002305,0.058547,275.546356,14.037001,0.585470,-45.014721,0.058755,0.000000
83.480003,61.929638,-45.103683,0.016832,0.002305,0.058547,275.476776,14.033456,0.585470,-45.103683,0.058755,0.000000
83.690002,61.918839,-45.059204,0.016841,0.002305,0.058547,275.428741,14.031010,0.585470,-45.059204,0.058755,0.000000
83.900002,61.906921,-45.059204,0.016836,0.002305,0.058547,275.375732,14.028309,0.585470,-45.059204,0.058755,0.000000
84.110001,61.884579,-45.103683,0.016824,0.002305,0.058547,275.276367,14.023246,0.585470,-45.103683,0.058755,0.000000
84.320007,61.875645,-45.103683,0.016854,0.002305,0.058547,275.236603,14.021221,0.585470,-45.103683,0.058755,0.000000
84.530006,61.867081,-45.103683,0.016832,0.002305,0.058547,275.198517,14.019281,0.585470,-45.103683,0.058755,0.000000
84.740005,61.860748,-45.059204,0.016849,0.002305,0.058547,275.170349,14.017846,0.585470,-45.059204,0.058755,0.000000
84.950005,61.842503,-45.103683,0.016854,0.002305,0.058547,275.089203,14.013712,0.585470,-45.103683,0.058755,0.000000
85.160004,61.838779,-45.059204,0.016836,0.002305,0.058547,275.072632,14.012867,0.585470,-45.059204,0.058755,0.000000
85.370003,61.833195,-45.103683,0.016845,0.002305,0.058547,275.047791,14.011601,0.585470,-45.103683,0.058755,0.000000
85.580002,61.812340,-45.103683,0.016828,0.002305,0.058547,274.955017,14.006877,0.585470,-45.103683,0.058755,0.000000
85.790001,61.794838,-45.103683,0.016824,0.002305,0.058547,274.877167,14.002911,0.585470,-45.103683,0.058755,0.000000
86.000008,61.786648,-45.103683,0.016836,0.002305,0.058547,274.840729,14.001055,0.585470,-45.103683,0.058755,0.000000
86.210007,61.756485,-45.059204,0.016828,0.002305,0.058547,274.706573,13.994220,0.585470,-45.059204,0.058755,0.000000
86.420006,61.763187,-45.148167,0.016845,0.002305,0.058547,274.736389,13.995738,0.585470,-45.148167,0.058755,0.000000
86.630005,61.734142,-45.148167,0.016841,0.002305,0.058547,274.607178,13.989157,0.585470,-45.148167,0.058755,0.000000
86.840004,61.738239,-45.148167,0.016841,0.002305,0.058547,274.625397,13.990085,0.585470,-45.148167,0.058755,0.000000
87.050003,61.724461,-45.103683,0.016845,0.002305,0.058547,274.564117,13.986963,0.585470,-45.103683,0.058755,0.000000
87.260002,61.708820,-45.103683,0.016841,0.002305,0.058547,274.494537,13.983418,0.585470,-45.103683,0.058755,0.000000
87.470001,61.704353,-45.192646,0.016858,0.002305,0.058547,274.474670,13.982407,0.585470,-45.192646,0.058755,0.000000
87.680008,61.687222,-45.237125,0.016845,0.002305,0.058547,274.398468,13.978523,0.585470,-45.237125,0.058755,0.000000
87.890007,61.676426,-45.103683,0.016841,0.002305,0.058547,274.350433,13.976078,0.585470,-45.103683,0.058755,0.000000
88.100006,61.656689,-45.192646,0.016836,0.002305,0.058547,274.262634,13.971605,0.585470,-45.192646,0.058755,0.000000
88.310005,61.649612,-45.148167,0.016841,0.002305,0.058547,274.231171,13.970002,0.585470,-45.148167,0.058755,0.000000
88.520004,61.630249,-45.148167,0.016832,0.002305,0.058547,274.145050,13.965614,0.585470,-45.148167,0.058755,0.000000
88.730003,61.637325,-45.237125,0.016828,0.002305,0.058547,274.176514,13.967217,0.585470,-45.237125,0.058755,0.000000
88.940002,61.624664,-45.148167,0.016845,0.002305,0.058547,274.120209,13.964349,0.585470,-45.148167,0.058755,0.000000
89.150002,61.614239,-45.281609,0.016854,0.002305,0.058547,274.073822,13.961987,0.585470,-45.281609,0.058755,0.000000
89.360001,61.607162,-45.192646,0.016845,0.002305,0.058547,274.042358,13.960382,0.585470,-45.192646,0.058755,0.000000
89.570007,61.601948,-45.192646,0.016858,0.002305,0.058547,274.019135,13.959201,0.585470,-45.192646,0.058755,0.000000
89.700005,61.577000,-45.237125,0.016867,0.002305,0.058547,273.908173,13.953547,0.585470,-45.237125,0.058755,0.000000