File: Data/Polished Pin I-18 - 5_08162023_161721.csv
Time (sec),S:Load (lbs),S:HL1 (DIM),S:LVDT (in),S:Position (in),Ch:Position (mm),Ch:Load (N),Ch:Stress (MPa),Ch:Strain (mm/mm),Ch:HL1 (DIM),Set Point (),Cycles ()
0.110000,-0.000372,-53.243698,-0.000017,-0.000000,-0.000000,-0.001657,-0.000084,-0.000000,-53.243698,0.000061,0.000000
0.340000,0.005958,-53.243698,-0.000009,-0.000000,-0.000000,0.026502,0.001350,-0.000000,-53.243698,0.000061,0.000000
0.570000,-0.001117,-53.243698,0.000000,0.000115,0.002923,-0.004969,-0.000253,0.029227,-53.243698,0.003443,0.000000
0.800000,0.006330,-53.243698,-0.000022,0.000247,0.006279,0.028159,0.001434,0.062791,-53.243698,0.007276,0.000000
1.030000,0.028300,-53.332661,0.000073,0.000394,0.010016,0.125886,0.006413,0.100163,-53.332661,0.011109,0.000000
1.260000,0.031279,-53.377140,0.000220,0.000549,0.013954,0.139137,0.007088,0.139542,-53.377140,0.014925,0.000000
1.490000,0.038354,-53.332661,0.000384,0.000688,0.017483,0.170609,0.008691,0.174832,-53.332661,0.018758,0.000000
1.720000,0.017129,-53.377140,0.000535,0.000844,0.021429,0.076194,0.003882,0.214293,-53.377140,0.022591,0.000000
1.950000,0.008192,-53.421623,0.000707,0.000999,0.025366,0.036441,0.001856,0.253664,-53.421623,0.026425,0.000000
2.180000,-0.011916,-53.421623,0.000845,0.001144,0.029070,-0.053005,-0.002700,0.290695,-53.421623,0.030258,0.000000
2.410000,0.034258,-53.377140,0.001022,0.001294,0.032859,0.152388,0.007763,0.328589,-53.377140,0.034091,0.000000
2.640000,0.047291,-53.377140,0.001160,0.001445,0.036701,0.210362,0.010716,0.367014,-53.377140,0.037924,0.000000
2.870000,0.050643,-53.377140,0.001319,0.001593,0.040456,0.225270,0.011476,0.404560,-53.377140,0.041757,0.000000
3.100000,0.053249,-53.377140,0.001492,0.001755,0.044567,0.236864,0.012066,0.445671,-53.377140,0.045590,0.000000
3.330000,0.028673,-53.510586,0.001656,0.001903,0.048339,0.127542,0.006497,0.483392,-53.510586,0.049423,0.000000
3.560000,0.019363,-53.421623,0.001815,0.002052,0.052120,0.086132,0.004388,0.521203,-53.421623,0.053257,0.000000
3.790000,0.033141,-53.466103,0.001983,0.002200,0.055884,0.147419,0.007510,0.558840,-53.466103,0.057090,0.000000
4.020000,0.033513,-53.421623,0.002126,0.002347,0.059605,0.149075,0.007594,0.596045,-53.421623,0.060922,0.000000
4.250000,0.032396,-53.466103,0.002276,0.002501,0.063524,0.144106,0.007341,0.635242,-53.466103,0.064738,0.000000
4.480000,0.061069,-53.510586,0.002440,0.002656,0.067453,0.271649,0.013838,0.674529,-53.510586,0.068572,0.000000
4.710000,0.037982,-53.466103,0.002596,0.002807,0.071286,0.168952,0.008607,0.712862,-53.466103,0.072405,0.000000
4.940000,0.036865,-53.510586,0.002790,0.002962,0.075223,0.163983,0.008354,0.752233,-53.510586,0.076238,0.000000
5.170000,0.054366,-53.510586,0.002940,0.003104,0.078848,0.241834,0.012320,0.788484,-53.510586,0.080071,0.000000
5.400000,0.057718,-53.555065,0.003109,0.003258,0.082760,0.256741,0.013079,0.827598,-53.555065,0.083904,0.000000
5.630000,0.038727,-53.599545,0.003264,0.003416,0.086766,0.172265,0.008776,0.867657,-53.599545,0.087738,0.000000
5.860000,0.011916,-53.555065,0.003428,0.003560,0.090417,0.053005,0.002700,0.904174,-53.555065,0.091570,0.000000
6.090000,-0.007820,-53.510586,0.003609,0.003708,0.094172,-0.034784,-0.001772,0.941720,-53.510586,0.095404,0.000000
6.320000,0.037237,-53.599545,0.003773,0.003859,0.098031,0.165639,0.008438,0.980310,-53.599545,0.099237,0.000000
6.550000,0.072985,-53.599545,0.003906,0.004010,0.101847,0.324653,0.016539,1.018470,-53.599545,0.103070,0.000000
6.780000,0.052504,-53.688507,0.004074,0.004169,0.105888,0.233552,0.011898,1.058885,-53.688507,0.106903,0.000000
7.010000,0.016757,-53.644028,0.004225,0.004319,0.109713,0.074538,0.003797,1.097128,-53.644028,0.110719,0.000000
7.240000,0.034258,-53.599545,0.004393,0.004467,0.113468,0.152388,0.007763,1.134681,-53.599545,0.114552,0.000000
7.470000,0.067027,-53.644028,0.004562,0.004622,0.117397,0.298151,0.015189,1.173968,-53.644028,0.118385,0.000000
7.700000,0.046174,-53.644028,0.004734,0.004765,0.121021,0.205393,0.010463,1.210213,-53.644028,0.122218,0.000000
7.930000,0.044685,-53.732990,0.004868,0.004914,0.124811,0.198767,0.010126,1.248115,-53.732990,0.126051,0.000000
8.160001,0.033886,-53.688507,0.005053,0.005073,0.128844,0.150732,0.007679,1.288439,-53.688507,0.129885,0.000000
8.390000,-0.006703,-53.688507,0.005221,0.005219,0.132573,-0.029815,-0.001519,1.325728,-53.688507,0.133717,0.000000
8.620001,-0.000372,-53.688507,0.005389,0.005366,0.136293,-0.001657,-0.000084,1.362933,-53.688507,0.137551,0.000000
8.850000,0.059580,-53.732990,0.005549,0.005520,0.140196,0.265023,0.013501,1.401955,-53.732990,0.141384,0.000000
9.080001,0.077081,-53.732990,0.005691,0.005669,0.143994,0.342874,0.017467,1.439941,-53.732990,0.145217,0.000000
9.310000,0.058835,-53.777470,0.005846,0.005829,0.148061,0.261710,0.013332,1.480613,-53.777470,0.149050,0.000000
9.540001,0.051387,-53.688507,0.006045,0.005977,0.151825,0.228582,0.011645,1.518250,-53.688507,0.152883,0.000000
9.770000,0.027928,-53.732990,0.006209,0.006131,0.155736,0.124230,0.006329,1.557363,-53.732990,0.156717,0.000000
10.000000,0.062559,-53.777470,0.006338,0.006272,0.159318,0.278274,0.014176,1.593183,-53.777470,0.160533,0.000000
10.230000,0.053994,-53.777470,0.006502,0.006425,0.163203,0.240177,0.012235,1.632032,-53.777470,0.164365,0.000000
10.460000,0.047291,-53.821949,0.006657,0.006580,0.167132,0.210362,0.010716,1.671319,-53.821949,0.168198,0.000000
10.690001,0.043195,-53.732990,0.006812,0.006729,0.170913,0.192142,0.009788,1.709130,-53.732990,0.172032,0.000000
10.920000,0.056973,-53.777470,0.006959,0.006879,0.174737,0.253428,0.012910,1.747373,-53.777470,0.175865,0.000000
11.150001,0.062559,-53.821949,0.007101,0.007032,0.178614,0.278274,0.014176,1.786137,-53.821949,0.179698,0.000000
11.380000,0.070751,-53.866432,0.007256,0.007178,0.182309,0.314715,0.016032,1.823086,-53.866432,0.183531,0.000000
11.610001,0.084529,-53.866432,0.007416,0.007327,0.186107,0.376002,0.019154,1.861071,-53.866432,0.187364,0.000000
11.840000,0.065538,-53.821949,0.007575,0.007488,0.190192,0.291525,0.014851,1.901917,-53.821949,0.191197,0.000000
12.070001,0.042823,-53.821949,0.007735,0.007635,0.193929,0.190485,0.009704,1.939289,-53.821949,0.195030,0.000000
12.300000,0.046174,-53.910912,0.007877,0.007781,0.197649,0.205393,0.010463,1.976495,-53.910912,0.198864,0.000000
12.530001,0.070378,-53.910912,0.008058,0.007932,0.201483,0.313059,0.015948,2.014828,-53.910912,0.202697,0.000000
12.760000,0.070006,-53.910912,0.008201,0.008082,0.205290,0.311402,0.015864,2.052897,-53.910912,0.206513,0.000000
12.990001,0.087135,-53.866432,0.008364,0.008234,0.209149,0.387596,0.019745,2.091488,-53.866432,0.210346,0.000000
13.220000,0.066282,-53.910912,0.008537,0.008388,0.213043,0.294838,0.015020,2.130427,-53.910912,0.214179,0.000000
13.450001,0.060324,-53.955395,0.008709,0.008540,0.216911,0.268336,0.013670,2.169108,-53.955395,0.218012,0.000000
13.680000,0.063303,-53.910912,0.008856,0.008692,0.220770,0.281587,0.014345,2.207699,-53.910912,0.221845,0.000000
13.910001,0.101658,-53.955395,0.009020,0.008840,0.224525,0.452196,0.023036,2.245245,-53.955395,0.225678,0.000000
14.140000,0.070378,-53.955395,0.009158,0.009000,0.228609,0.313059,0.015948,2.286092,-53.955395,0.229511,0.000000
14.370001,0.049898,-53.910912,0.009360,0.009145,0.232277,0.221957,0.011307,2.322775,-53.910912,0.233345,0.000000
14.600000,0.027928,-53.999874,0.009494,0.009291,0.235998,0.124230,0.006329,2.359980,-53.999874,0.237177,0.000000
14.830001,0.069261,-53.999874,0.009649,0.009443,0.239840,0.308089,0.015695,2.398397,-53.999874,0.241011,0.000000
15.060000,0.094210,-53.999874,0.009809,0.009592,0.243638,0.419068,0.021348,2.436382,-53.999874,0.244844,0.000000
15.290001,0.087880,-53.955395,0.009951,0.009744,0.247506,0.390909,0.019914,2.475064,-53.955395,0.248677,0.000000
15.520000,0.091231,-53.999874,0.010136,0.009901,0.251478,0.405817,0.020673,2.514783,-53.999874,0.252510,0.000000
15.750001,0.049153,-53.999874,0.010313,0.010050,0.255277,0.218644,0.011138,2.552768,-53.999874,0.256326,0.000000
15.980000,0.081550,-54.088837,0.010464,0.010204,0.259171,0.362750,0.018479,2.591707,-54.088837,0.260159,0.000000
16.210001,0.060697,-54.044357,0.010649,0.010350,0.262900,0.269992,0.013754,2.628996,-54.044357,0.263993,0.000000
16.440001,0.088625,-53.999874,0.010783,0.010493,0.266533,0.394222,0.020083,2.665331,-53.999874,0.267825,0.000000
16.670000,0.054739,-54.044357,0.010947,0.010655,0.270644,0.243490,0.012404,2.706442,-54.044357,0.271659,0.000000
16.900002,0.005213,-54.088837,0.011111,0.010803,0.274408,0.023189,0.001181,2.744079,-54.088837,0.275492,0.000000
17.130001,0.032769,-54.088837,0.011262,0.010951,0.278163,0.145763,0.007425,2.781625,-54.088837,0.279324,0.000000
17.360001,0.077453,-54.088837,0.011417,0.011106,0.282083,0.344530,0.017551,2.820829,-54.088837,0.283158,0.000000
17.590000,0.102402,-54.044357,0.011563,0.011250,0.285742,0.455509,0.023205,2.857422,-54.044357,0.286991,0.000000
17.820002,0.102030,-54.088837,0.011706,0.011405,0.289688,0.453852,0.023120,2.896883,-54.088837,0.290825,0.000000
18.050001,0.106498,-54.088837,0.011904,0.011561,0.293660,0.473729,0.024133,2.936602,-54.088837,0.294657,0.000000
18.280001,0.070006,-54.088837,0.012038,0.011710,0.297432,0.311402,0.015864,2.974322,-54.088837,0.298490,0.000000
18.510000,0.081177,-54.088837,0.012193,0.011859,0.301213,0.361094,0.018395,3.012133,-54.088837,0.302306,0.000000
18.740002,0.086763,-54.088837,0.012365,0.012009,0.305029,0.385940,0.019661,3.050292,-54.088837,0.306140,0.000000
18.970001,0.077453,-54.177799,0.012521,0.012157,0.308776,0.344530,0.017551,3.087755,-54.177799,0.309972,0.000000
19.200001,0.064793,-54.177799,0.012693,0.012313,0.312739,0.288213,0.014682,3.127391,-54.177799,0.313806,0.000000
19.430000,0.067399,-54.222279,0.012844,0.012461,0.316520,0.299807,0.015273,3.165202,-54.222279,0.317639,0.000000
19.660002,0.072240,-54.133316,0.013034,0.012612,0.320354,0.321341,0.016370,3.203535,-54.133316,0.321472,0.000000
19.890001,0.082294,-54.088837,0.013193,0.012764,0.324213,0.366063,0.018648,3.242126,-54.088837,0.325305,0.000000
20.120001,0.080060,-54.177799,0.013331,0.012907,0.327838,0.356125,0.018142,3.278378,-54.177799,0.329138,0.000000
20.350000,0.079688,-54.222279,0.013508,0.013070,0.331974,0.354468,0.018057,3.319739,-54.222279,0.332972,0.000000
20.580002,0.048408,-54.266762,0.013672,0.013219,0.335755,0.215331,0.010969,3.357550,-54.266762,0.336805,0.000000
20.810001,0.059207,-54.177799,0.013827,0.013367,0.339519,0.263367,0.013417,3.395187,-54.177799,0.340638,0.000000
21.040001,0.085646,-54.133316,0.013987,0.013517,0.343335,0.380971,0.019408,3.433346,-54.133316,0.344471,0.000000
21.270000,0.073730,-54.222279,0.014155,0.013663,0.347038,0.327966,0.016707,3.470378,-54.222279,0.348304,0.000000
21.500002,0.092721,-54.222279,0.014301,0.013815,0.350889,0.412442,0.021011,3.508885,-54.222279,0.352120,0.000000
21.730001,0.086390,-54.222279,0.014482,0.013969,0.354816,0.384284,0.019576,3.548165,-54.222279,0.355953,0.000000
21.960001,0.053249,-54.222279,0.014655,0.014123,0.358728,0.236864,0.012066,3.587278,-54.222279,0.359786,0.000000
22.190001,0.085273,-54.133316,0.014801,0.014272,0.362518,0.379314,0.019323,3.625180,-54.133316,0.363619,0.000000
22.420002,0.093465,-54.222279,0.014965,0.014423,0.366334,0.415755,0.021180,3.663339,-54.222279,0.367452,0.000000
22.650002,0.083039,-54.266762,0.015090,0.014577,0.370262,0.369376,0.018817,3.702619,-54.266762,0.371285,0.000000
22.880001,0.077453,-54.311241,0.015250,0.014729,0.374113,0.344530,0.017551,3.741127,-54.311241,0.375119,0.000000
23.110001,0.037237,-54.222279,0.015414,0.014876,0.377851,0.165639,0.008438,3.778506,-54.222279,0.378952,0.000000
23.340002,0.039844,-54.311241,0.015547,0.015024,0.381605,0.177234,0.009029,3.816052,-54.311241,0.382785,0.000000
23.570002,0.110595,-54.311241,0.015715,0.015173,0.385404,0.491949,0.025061,3.854038,-54.311241,0.386618,0.000000
23.800001,0.109477,-54.311241,0.015879,0.015323,0.389202,0.486980,0.024808,3.892023,-54.311241,0.390451,0.000000
24.030001,0.119532,-54.311241,0.016017,0.015480,0.393183,0.531703,0.027086,3.931832,-54.311241,0.394285,0.000000
24.260000,0.087507,-54.311241,0.016181,0.015632,0.397051,0.389253,0.019829,3.970506,-54.311241,0.398100,0.000000
24.490002,0.109850,-54.311241,0.016341,0.015780,0.400823,0.488637,0.024892,4.008234,-54.311241,0.401933,0.000000
24.720001,0.099051,-54.311241,0.016500,0.015936,0.404778,0.440601,0.022445,4.047779,-54.311241,0.405766,0.000000
24.950001,0.090114,-54.311241,0.016673,0.016074,0.408290,0.400848,0.020420,4.082902,-54.311241,0.409600,0.000000
25.180000,0.079315,-54.355721,0.016819,0.016234,0.412340,0.352812,0.017973,4.123401,-54.355721,0.413432,0.000000
25.410002,0.071123,-54.311241,0.016962,0.016386,0.416207,0.316371,0.016117,4.162075,-54.311241,0.417266,0.000000
25.640001,0.045429,-54.311241,0.017151,0.016533,0.419945,0.202080,0.010294,4.199454,-54.311241,0.421099,0.000000
25.870001,0.096817,-54.311241,0.017293,0.016684,0.423770,0.430663,0.021939,4.237697,-54.311241,0.424932,0.000000
26.100000,0.097562,-54.355721,0.017462,0.016835,0.427612,0.433975,0.022108,4.276121,-54.355721,0.428765,0.000000
26.330002,0.115808,-54.355721,0.017604,0.016981,0.431314,0.515139,0.026242,4.313145,-54.355721,0.432598,0.000000
26.560001,0.115063,-54.400204,0.017768,0.017145,0.435477,0.511826,0.026074,4.354772,-54.400204,0.436432,0.000000
26.790001,0.078571,-54.355721,0.017936,0.017291,0.439198,0.349499,0.017804,4.391977,-54.355721,0.440264,0.000000
27.020000,0.091976,-54.400204,0.018078,0.017439,0.442961,0.409130,0.020842,4.429614,-54.400204,0.444098,0.000000
27.250002,0.088997,-54.444683,0.018220,0.017589,0.446769,0.395878,0.020167,4.467690,-54.444683,0.447914,0.000000
27.480001,0.108360,-54.444683,0.018389,0.017735,0.450480,0.482011,0.024555,4.504805,-54.444683,0.451747,0.000000
27.710001,0.072613,-54.311241,0.018535,0.017892,0.454461,0.322997,0.016454,4.544614,-54.311241,0.455579,0.000000
27.940001,0.124372,-54.400204,0.018703,0.018043,0.458294,0.553236,0.028183,4.582940,-54.400204,0.459413,0.000000
28.170002,0.098306,-54.400204,0.018880,0.018193,0.462110,0.437288,0.022277,4.621099,-54.400204,0.463246,0.000000
28.400002,0.102402,-54.444683,0.019031,0.018347,0.466004,0.455509,0.023205,4.660038,-54.444683,0.467079,0.000000
28.630001,0.123628,-54.444683,0.019186,0.018489,0.469629,0.549923,0.028014,4.696290,-54.444683,0.470912,0.000000
28.860001,0.117670,-54.400204,0.019341,0.018649,0.473687,0.523421,0.026664,4.736872,-54.400204,0.474745,0.000000
29.090002,0.106126,-54.489166,0.019505,0.018802,0.477573,0.472073,0.024049,4.775727,-54.489166,0.478579,0.000000
29.320002,0.078943,-54.444683,0.019648,0.018944,0.481189,0.351156,0.017889,4.811888,-54.444683,0.482412,0.000000
29.550001,0.068144,-54.444683,0.019794,0.019095,0.485005,0.303120,0.015442,4.850048,-54.444683,0.486245,0.000000
29.780001,0.105009,-54.444683,0.019945,0.019248,0.488907,0.467103,0.023795,4.889070,-54.444683,0.490078,0.000000
30.010002,0.151928,-54.444683,0.020092,0.019394,0.492619,0.675809,0.034427,4.926192,-54.444683,0.493894,0.000000
30.240002,0.121021,-54.444683,0.020273,0.019556,0.496712,0.538328,0.027424,4.967122,-54.444683,0.497727,0.000000
30.470001,0.084529,-54.489166,0.020450,0.019706,0.500520,0.376002,0.019154,5.005198,-54.489166,0.501560,0.000000
30.700001,0.108733,-54.533646,0.020596,0.019853,0.504266,0.483667,0.024639,5.042661,-54.533646,0.505393,0.000000
30.930002,0.129586,-54.489166,0.020756,0.020008,0.508194,0.576425,0.029365,5.081941,-54.489166,0.509227,0.000000
31.160002,0.148949,-54.444683,0.020889,0.020153,0.511880,0.662558,0.033752,5.118798,-54.444683,0.513059,0.000000
31.390001,0.138523,-54.400204,0.021045,0.020306,0.515774,0.616179,0.031390,5.157737,-54.400204,0.516892,0.000000
31.620001,0.171664,-54.489166,0.021234,0.020459,0.519659,0.763598,0.038900,5.196593,-54.489166,0.520726,0.000000
31.850002,0.229381,-54.489166,0.021364,0.020606,0.523397,1.020339,0.051979,5.233972,-54.489166,0.524559,0.000000
32.080002,0.529886,-54.533646,0.021536,0.020754,0.527152,2.357051,0.120074,5.271518,-54.533646,0.528392,0.000000
32.310001,0.594679,-54.533646,0.021592,0.000004,0.000113,2.645263,0.134756,0.001128,-54.533646,0.000355,0.000000
32.540001,0.590210,-54.489166,0.021588,0.000004,0.000113,2.625387,0.133744,0.001128,-54.489166,0.000355,0.000000
32.770000,0.652024,-54.489166,0.021601,0.000004,0.000113,2.900348,0.147751,0.001128,-54.489166,0.000537,0.000000
33.000000,0.606967,-54.489166,0.021588,0.000005,0.000130,2.699924,0.137541,0.001302,-54.489166,0.000919,0.000000
33.230003,0.684048,-54.533646,0.021579,0.000015,0.000390,3.042798,0.155008,0.003898,-54.533646,0.001310,0.000000
33.460003,0.724264,-54.533646,0.021592,0.000022,0.000547,3.221689,0.164121,0.005465,-54.533646,0.001691,0.000000
33.690002,0.827412,-54.533646,0.021583,0.000042,0.001067,3.680511,0.187494,0.010666,-54.533646,0.002073,0.000000
33.920002,0.940613,-54.533646,0.021614,0.000062,0.001569,4.184055,0.213146,0.015692,-54.533646,0.002454,0.000000
34.150002,0.976361,-54.533646,0.021631,0.000074,0.001882,4.343069,0.221246,0.018818,-54.533646,0.002844,0.000000
34.380001,1.102595,-54.533646,0.021622,0.000091,0.002324,4.904587,0.249852,0.023239,-54.533646,0.003226,0.000000
34.610001,1.182655,-54.533646,0.021665,0.000105,0.002671,5.260712,0.267993,0.026706,-54.533646,0.003608,0.000000
34.840000,1.333466,-54.533646,0.021661,0.000120,0.003044,5.931552,0.302168,0.030438,-54.533646,0.003989,0.000000
35.070004,1.405706,-54.578129,0.021674,0.000130,0.003304,6.252893,0.318538,0.033042,-54.578129,0.004371,0.000000
35.300003,1.549814,-54.622608,0.021674,0.000145,0.003677,6.893918,0.351193,0.036766,-54.622608,0.004761,0.000000
35.530003,1.766907,-54.533646,0.021700,0.000170,0.004327,7.859596,0.400387,0.043269,-54.533646,0.005142,0.000000
35.760002,1.867448,-54.533646,0.021730,0.000180,0.004562,8.306823,0.423170,0.045616,-54.533646,0.005524,0.000000
35.990002,1.973574,-54.578129,0.021756,0.000195,0.004943,8.778895,0.447218,0.049431,-54.578129,0.005906,0.000000
36.220001,2.115820,-54.667088,0.021739,0.000207,0.005255,9.411639,0.479452,0.052549,-54.667088,0.006287,0.000000
36.450001,2.344829,-54.622608,0.021756,0.000227,0.005776,10.430322,0.531346,0.057757,-54.622608,0.006677,0.000000
36.680000,2.545538,-54.578129,0.021782,0.000240,0.006097,11.323118,0.576827,0.060967,-54.578129,0.007059,0.000000
36.910000,2.719064,-54.578129,0.021782,0.000255,0.006478,12.094999,0.616149,0.064782,-54.578129,0.007440,0.000000
37.140003,2.861682,-54.578129,0.021808,0.000267,0.006782,12.729399,0.648467,0.067818,-54.578129,0.007822,0.000000
37.370003,3.009514,-54.667088,0.021821,0.000281,0.007128,13.386989,0.681966,0.071285,-54.667088,0.008204,0.000000
37.600002,3.406836,-54.578129,0.021825,0.000304,0.007709,15.154362,0.772000,0.077091,-54.578129,0.008594,0.000000
37.830002,3.601586,-54.667088,0.021834,0.000318,0.008074,16.020657,0.816131,0.080739,-54.667088,0.008975,0.000000
38.060001,3.802295,-54.578129,0.021864,0.000333,0.008464,16.913454,0.861612,0.084638,-54.578129,0.009357,0.000000
38.290001,3.972097,-54.667088,0.021877,0.000346,0.008794,17.668770,0.900090,0.087938,-54.667088,0.009739,0.000000
38.520000,4.226800,-54.667088,0.021868,0.000362,0.009193,18.801744,0.957807,0.091928,-54.667088,0.010120,0.000000
38.750000,4.434584,-54.711571,0.021877,0.000374,0.009505,19.726013,1.004891,0.095046,-54.711571,0.010511,0.000000
38.980003,4.614439,-54.756050,0.021881,0.000386,0.009799,20.526052,1.045647,0.097991,-54.756050,0.010892,0.000000
39.210003,4.836746,-54.667088,0.021907,0.000398,0.010120,21.514919,1.096022,0.101201,-54.667088,0.011274,0.000000
39.440002,5.378548,-54.667088,0.021937,0.000425,0.010797,23.924976,1.218796,0.107968,-54.667088,0.011655,0.000000
39.670002,5.496963,-54.711571,0.021933,0.000437,0.011091,24.451710,1.245630,0.110913,-54.711571,0.012037,0.000000
39.900002,5.687989,-54.711571,0.021954,0.000452,0.011482,25.301439,1.288917,0.114819,-54.711571,0.012427,0.000000
40.130001,5.929659,-54.711571,0.021954,0.000467,0.011863,26.376442,1.343680,0.118634,-54.711571,0.012809,0.000000
40.360001,6.104302,-54.667088,0.021963,0.000476,0.012089,27.153292,1.383255,0.120890,-54.667088,0.013190,0.000000
40.590000,6.525827,-54.667088,0.021984,0.000498,0.012653,29.028330,1.478774,0.126529,-54.667088,0.013572,0.000000
40.820004,6.664350,-54.711571,0.021997,0.000508,0.012913,29.644510,1.510163,0.129125,-54.711571,0.013953,0.000000
41.050003,6.745527,-54.756050,0.022010,0.000514,0.013060,30.005604,1.528558,0.130602,-54.756050,0.014344,0.000000
41.280003,7.414308,-54.711571,0.022006,0.000546,0.013867,32.980488,1.680106,0.138671,-54.711571,0.014726,0.000000
41.510002,7.689491,-54.711571,0.022045,0.000561,0.014257,34.204567,1.742464,0.142569,-54.711571,0.015107,0.000000
41.740002,7.828759,-54.711571,0.022058,0.000573,0.014552,34.824059,1.774022,0.145522,-54.711571,0.015489,0.000000
41.970001,8.021647,-54.711571,0.022062,0.000587,0.014899,35.682072,1.817731,0.148989,-54.711571,0.015870,0.000000
42.200001,8.289383,-54.800533,0.022075,0.000603,0.015315,36.873016,1.878401,0.153152,-54.800533,0.016261,0.000000
42.430000,8.666969,-54.756050,0.022066,0.000620,0.015740,38.552605,1.963963,0.157399,-54.756050,0.016642,0.000000
42.660004,8.906404,-54.756050,0.022092,0.000633,0.016087,39.617664,2.018220,0.160866,-54.756050,0.017024,0.000000
42.890003,8.996519,-54.756050,0.022114,0.000643,0.016321,40.018517,2.038640,0.163212,-54.756050,0.017405,0.000000
43.120003,9.399426,-54.711571,0.022122,0.000662,0.016824,41.810734,2.129940,0.168239,-54.711571,0.017795,0.000000
43.350002,9.676099,-54.756050,0.022148,0.000677,0.017197,43.041439,2.192636,0.171970,-54.756050,0.018177,0.000000
43.580002,10.015702,-54.800533,0.022157,0.000695,0.017648,44.552067,2.269591,0.176482,-54.800533,0.018558,0.000000
43.810001,10.170609,-54.711571,0.022178,0.000708,0.017986,45.241131,2.304693,0.179858,-54.711571,0.018940,0.000000
44.040001,10.359402,-54.711571,0.022170,0.000720,0.018289,46.080921,2.347474,0.182894,-54.711571,0.019322,0.000000
44.270000,10.846465,-54.845013,0.022183,0.000742,0.018845,48.247486,2.457844,0.188450,-54.845013,0.019712,0.000000
44.500004,10.964507,-54.800533,0.022191,0.000754,0.019148,48.772564,2.484593,0.191478,-54.800533,0.020093,0.000000
44.730003,11.061324,-54.800533,0.022183,0.000765,0.019426,49.203228,2.506532,0.194256,-54.800533,0.020475,0.000000
44.960003,11.547270,-54.800533,0.022230,0.000784,0.019902,51.364822,2.616649,0.199025,-54.800533,0.020856,0.000000
45.190002,11.917781,-54.756050,0.022226,0.000802,0.020379,53.012936,2.700608,0.203794,-54.756050,0.021238,0.000000
45.420002,12.071198,-54.800533,0.022256,0.000816,0.020718,53.695374,2.735373,0.207178,-54.800533,0.021628,0.000000
45.650002,12.319943,-54.845013,0.022282,0.000830,0.021082,54.801846,2.791739,0.210819,-54.845013,0.022010,0.000000
45.880001,12.458466,-54.845013,0.022269,0.000843,0.021420,55.418022,2.823129,0.214202,-54.845013,0.022391,0.000000
46.110001,12.700880,-54.800533,0.022278,0.000856,0.021750,56.496338,2.878061,0.217495,-54.800533,0.022773,0.000000
46.340004,13.001757,-54.756050,0.022303,0.000873,0.022175,57.834702,2.946240,0.221749,-54.756050,0.023154,0.000000
46.570004,13.033408,-54.889492,0.022299,0.000882,0.022401,57.975494,2.953413,0.224005,-54.889492,0.023545,0.000000
46.800003,13.414346,-54.889492,0.022316,0.000897,0.022782,59.669991,3.039734,0.227820,-54.889492,0.023927,0.000000
47.030003,13.803102,-54.845013,0.022329,0.000916,0.023259,61.399265,3.127828,0.232589,-54.845013,0.024308,0.000000
47.260002,14.310646,-54.845013,0.022364,0.000937,0.023805,63.656933,3.242839,0.238055,-54.845013,0.024690,0.000000
47.490002,14.402622,-54.800533,0.022377,0.000951,0.024143,64.066063,3.263681,0.241431,-54.800533,0.025071,0.000000
47.720001,14.453265,-54.889492,0.022381,0.000963,0.024456,64.291336,3.275157,0.244557,-54.889492,0.025462,0.000000
47.950001,14.817073,-54.889492,0.022381,0.000979,0.024855,65.909630,3.357597,0.248546,-54.889492,0.025843,0.000000
48.180004,14.945541,-54.889492,0.022411,0.000989,0.025132,66.481087,3.386708,0.251317,-54.889492,0.026225,0.000000
48.410004,15.483247,-54.845013,0.022398,0.001009,0.025635,68.872925,3.508554,0.256351,-54.845013,0.026606,0.000000
48.640003,15.659007,-54.933975,0.022437,0.001022,0.025956,69.654739,3.548382,0.259561,-54.933975,0.026988,0.000000
48.870003,15.826947,-54.933975,0.022454,0.001033,0.026242,70.401779,3.586437,0.262422,-54.933975,0.027378,0.000000
49.100002,16.159475,-54.933975,0.022463,0.001049,0.026649,71.880936,3.661789,0.266494,-54.933975,0.027760,0.000000
49.330002,16.693457,-54.933975,0.022463,0.001072,0.027231,74.256203,3.782791,0.272308,-54.933975,0.028141,0.000000
49.560001,16.756016,-54.933975,0.022480,0.001084,0.027525,74.534477,3.796968,0.275253,-54.933975,0.028523,0.000000
49.790001,17.005507,-54.889492,0.022510,0.001098,0.027898,75.644272,3.853503,0.278985,-54.889492,0.028904,0.000000
50.020004,17.211800,-54.933975,0.022506,0.001112,0.028245,76.561905,3.900250,0.282452,-54.933975,0.029294,0.000000
50.250004,17.593481,-54.889492,0.022506,0.001126,0.028609,78.259712,3.986740,0.286093,-54.889492,0.029677,0.000000
50.480003,17.916700,-54.889492,0.022528,0.001138,0.028913,79.697464,4.059982,0.289128,-54.889492,0.030058,0.000000
50.710003,18.076077,-54.889492,0.022549,0.001150,0.029208,80.406403,4.096097,0.292080,-54.889492,0.030440,0.000000
50.940002,18.519571,-54.889492,0.022566,0.001169,0.029693,82.379166,4.196595,0.296933,-54.889492,0.030821,0.000000
51.170002,19.153351,-54.933975,0.022579,0.001189,0.030205,85.198357,4.340211,0.302050,-54.933975,0.031211,0.000000
51.400002,19.427788,-54.978455,0.022605,0.001204,0.030578,86.419113,4.402400,0.305782,-54.978455,0.031593,0.000000
51.630001,19.530191,-54.978455,0.022601,0.001218,0.030942,86.874634,4.425604,0.309423,-54.978455,0.031975,0.000000
51.860001,19.815056,-54.889492,0.022601,0.001231,0.031255,88.141769,4.490156,0.312549,-54.889492,0.032356,0.000000
52.090004,20.066780,-54.978455,0.022627,0.001245,0.031627,89.261497,4.547197,0.316273,-54.978455,0.032746,0.000000
52.320004,20.718060,-54.978455,0.022648,0.001262,0.032061,92.158531,4.694779,0.320611,-54.978455,0.033128,0.000000
52.550003,20.954144,-55.022938,0.022648,0.001274,0.032365,93.208687,4.748277,0.323646,-55.022938,0.033509,0.000000
52.780003,21.261723,-55.067417,0.022653,0.001289,0.032738,94.576866,4.817975,0.327378,-55.067417,0.033891,0.000000
53.010002,21.870180,-54.978455,0.022653,0.001310,0.033267,97.283417,4.955853,0.332670,-54.978455,0.034272,0.000000
53.240002,22.484594,-54.978455,0.022679,0.001326,0.033692,100.016472,5.095082,0.336916,-54.978455,0.034663,0.000000
53.470001,22.589603,-54.978455,0.022700,0.001341,0.034056,100.483574,5.118877,0.340557,-54.978455,0.035044,0.000000
53.700001,22.904631,-54.978455,0.022730,0.001354,0.034385,101.884888,5.190264,0.343850,-54.978455,0.035426,0.000000
53.930004,23.235296,-55.156380,0.022726,0.001366,0.034689,103.355759,5.265193,0.346886,-55.156380,0.035807,0.000000
54.160004,23.753639,-55.022938,0.022739,0.001381,0.035087,105.661461,5.382652,0.350875,-55.022938,0.036189,0.000000
54.390003,24.181124,-55.022938,0.022769,0.001395,0.035435,107.563011,5.479521,0.354349,-55.022938,0.036579,0.000000
54.620003,24.448858,-54.978455,0.022761,0.001408,0.035756,108.753952,5.540191,0.357559,-54.978455,0.036961,0.000000
54.850002,24.835381,-55.022938,0.022765,0.001422,0.036120,110.473289,5.627778,0.361200,-55.022938,0.037343,0.000000
55.080002,25.760727,-55.022938,0.022791,0.001445,0.036710,114.589439,5.837464,0.367097,-55.022938,0.037724,0.000000
55.310001,26.186348,-55.022938,0.022791,0.001461,0.037109,116.482697,5.933911,0.371086,-55.022938,0.038106,0.000000
55.540001,26.464138,-54.978455,0.022804,0.001475,0.037464,117.718369,5.996859,0.374636,-54.978455,0.038496,0.000000
55.770004,27.098661,-55.067417,0.022825,0.001491,0.037872,120.540863,6.140645,0.378717,-55.067417,0.038878,0.000000
56.000004,27.457628,-55.067417,0.022825,0.001506,0.038253,122.137627,6.221988,0.382532,-55.067417,0.039259,0.000000
56.230003,27.978577,-55.111897,0.022842,0.001520,0.038609,124.454926,6.340036,0.386090,-55.111897,0.039641,0.000000
56.460003,28.210937,-54.978455,0.022860,0.001529,0.038825,125.488518,6.392690,0.388255,-54.978455,0.040022,0.000000
56.690002,28.836151,-54.933975,0.022860,0.001548,0.039320,128.269608,6.534365,0.393198,-54.933975,0.040413,0.000000
56.920002,30.055298,-55.067417,0.022877,0.001572,0.039927,133.692642,6.810628,0.399269,-55.067417,0.040794,0.000000
57.150002,30.031094,-55.111897,0.022890,0.001579,0.040109,133.584976,6.805143,0.401093,-55.111897,0.041176,0.000000
57.380001,30.587791,-55.067417,0.022894,0.001595,0.040526,136.061295,6.931293,0.405256,-55.067417,0.041557,0.000000
57.610004,30.989954,-55.067417,0.022903,0.001612,0.040933,137.850204,7.022424,0.409329,-55.067417,0.041939,0.000000
57.840004,31.824440,-55.111897,0.022907,0.001627,0.041323,141.562180,7.211522,0.413235,-55.111897,0.042329,0.000000
58.070004,32.242615,-55.111897,0.022929,0.001639,0.041635,143.422318,7.306281,0.416354,-55.111897,0.042711,0.000000
58.300003,32.816441,-55.156380,0.022929,0.001655,0.042025,145.974823,7.436312,0.420252,-55.156380,0.043093,0.000000
58.530003,33.283394,-55.111897,0.022946,0.001669,0.042381,148.051926,7.542125,0.423810,-55.111897,0.043474,0.000000
58.760002,33.995373,-55.067417,0.022950,0.001684,0.042772,151.218964,7.703462,0.427716,-55.067417,0.043856,0.000000
58.990002,35.058125,-55.067417,0.022967,0.001705,0.043317,155.946320,7.944284,0.433174,-55.067417,0.044245,0.000000
59.220001,35.447250,-55.111897,0.022963,0.001718,0.043630,157.677246,8.032461,0.436300,-55.111897,0.044627,0.000000
59.450005,36.003948,-55.111897,0.022985,0.001735,0.044072,160.153564,8.158611,0.440721,-55.111897,0.045008,0.000000
59.680004,36.488407,-55.156380,0.022980,0.001748,0.044393,162.308548,8.268391,0.443930,-55.156380,0.045391,0.000000
59.910004,37.168358,-55.156380,0.023006,0.001764,0.044801,165.333115,8.422470,0.448010,-55.156380,0.045772,0.000000
60.140003,37.645741,-55.111897,0.023015,0.001777,0.045130,167.456619,8.530646,0.451303,-55.111897,0.046162,0.000000
60.370003,38.058701,-55.156380,0.023015,0.001786,0.045364,169.293549,8.624225,0.453642,-55.156380,0.046544,0.000000
60.600002,38.734184,-55.200859,0.023019,0.001801,0.045746,172.298264,8.777291,0.457458,-55.200859,0.046925,0.000000
60.830002,40.316395,-55.156380,0.023041,0.001829,0.046448,179.336273,9.135825,0.464482,-55.156380,0.047307,0.000000
61.060001,40.593441,-55.200859,0.023054,0.001839,0.046717,180.568649,9.198606,0.467170,-55.200859,0.047697,0.000000
61.290005,41.308395,-55.200859,0.023045,0.001856,0.047142,183.748917,9.360616,0.471424,-55.200859,0.048079,0.000000
61.520004,41.876263,-55.156380,0.023058,0.001869,0.047472,186.274918,9.489297,0.474717,-55.156380,0.048460,0.000000
61.750004,42.400562,-55.200859,0.023067,0.001883,0.047836,188.607117,9.608106,0.478358,-55.200859,0.048842,0.000000
61.980003,43.272659,-55.200859,0.023058,0.001900,0.048252,192.486404,9.805725,0.482521,-55.200859,0.049223,0.000000
62.210003,43.653225,-55.200859,0.023080,0.001908,0.048460,194.179245,9.891963,0.484603,-55.200859,0.049614,0.000000
62.440002,44.243805,-55.200859,0.023084,0.001923,0.048851,196.806274,10.025789,0.488509,-55.200859,0.049995,0.000000
62.670002,45.926929,-55.200859,0.023110,0.001949,0.049501,204.293182,10.407190,0.495011,-55.200859,0.050377,0.000000
62.900002,46.554005,-55.200859,0.023114,0.001962,0.049839,207.082550,10.549288,0.498395,-55.200859,0.050758,0.000000
63.130005,46.985214,-55.245342,0.023105,0.001973,0.050117,209.000671,10.647001,0.501166,-55.245342,0.051140,0.000000
63.360004,47.698677,-55.200859,0.023127,0.001989,0.050515,212.174316,10.808675,0.505155,-55.200859,0.051531,0.000000
63.590004,48.773716,-55.245342,0.023136,0.002008,0.051001,216.956329,11.052281,0.510015,-55.245342,0.051912,0.000000
63.820004,49.408985,-55.289822,0.023140,0.002021,0.051322,219.782135,11.196237,0.513224,-55.289822,0.052294,0.000000
64.050003,50.022282,-55.245342,0.023140,0.002033,0.051634,222.510223,11.335212,0.516343,-55.245342,0.052675,0.000000
64.280006,50.644516,-55.289822,0.023157,0.002048,0.052025,225.278061,11.476211,0.520249,-55.289822,0.053057,0.000000
64.510002,51.741528,-55.245342,0.023166,0.002066,0.052467,230.157806,11.724798,0.524670,-55.245342,0.053447,0.000000
64.740005,52.629635,-55.200859,0.023179,0.002082,0.052892,234.108307,11.926045,0.528916,-55.200859,0.053829,0.000000
64.970001,53.349056,-55.289822,0.023170,0.002093,0.053169,237.308456,12.089069,0.531694,-55.289822,0.054210,0.000000
65.200005,54.154499,-55.289822,0.023179,0.002109,0.053577,240.891235,12.271585,0.535767,-55.289822,0.054592,0.000000
65.430000,54.676937,-55.289822,0.023187,0.002121,0.053863,243.215164,12.389972,0.538628,-55.289822,0.054973,0.000000
65.660004,56.090092,-55.289822,0.023192,0.002142,0.054409,249.501190,12.710196,0.544094,-55.289822,0.055363,0.000000
65.889999,56.705250,-55.245342,0.023209,0.002154,0.054713,252.237549,12.849593,0.547129,-55.245342,0.055745,0.000000
66.120003,57.218006,-55.245342,0.023200,0.002166,0.055008,254.518402,12.965785,0.550081,-55.245342,0.056127,0.000000
66.350006,58.422260,-55.334305,0.023230,0.002184,0.055485,259.875183,13.238673,0.554850,-55.334305,0.056508,0.000000
66.580002,59.761684,-55.334305,0.023222,0.002205,0.055997,265.833252,13.542192,0.559968,-55.334305,0.056890,0.000000
66.810005,60.562286,-55.378784,0.023226,0.002218,0.056335,269.394501,13.723610,0.563351,-55.378784,0.057280,0.000000
67.040001,61.147655,-55.289822,0.023226,0.002230,0.056630,271.998352,13.856256,0.566296,-55.289822,0.057661,0.000000
67.270004,61.903942,-55.289822,0.023252,0.002244,0.057003,275.362488,14.027634,0.570028,-55.289822,0.058043,0.000000
67.500000,62.606236,-55.334305,0.023248,0.002255,0.057280,278.486450,14.186775,0.572798,-55.334305,0.058425,0.000000
67.730003,63.712185,-55.334305,0.023252,0.002273,0.057731,283.405945,14.437387,0.577310,-55.334305,0.058807,0.000000
67.960007,64.343727,-55.378784,0.023256,0.002283,0.057991,286.215179,14.580497,0.579914,-55.378784,0.059197,0.000000
68.190002,65.138741,-55.289822,0.023256,0.002298,0.058364,289.751587,14.760650,0.583638,-55.289822,0.059578,0.000000
68.420006,66.605515,-55.334305,0.023274,0.002321,0.058954,296.276123,15.093025,0.589535,-55.334305,0.059960,0.000000
68.650002,67.198334,-55.289822,0.023287,0.002320,0.058928,298.913116,15.227360,0.589278,-55.289822,0.059171,0.000000
68.880005,66.798775,-55.334305,0.023274,0.002320,0.058928,297.135803,15.136819,0.589278,-55.334305,0.059171,0.000000
69.110001,66.482628,-55.378784,0.023274,0.002318,0.058876,295.729492,15.065179,0.588756,-55.378784,0.058928,0.000000
69.340004,66.204468,-55.289822,0.023295,0.002317,0.058850,294.492187,15.002147,0.588498,-55.289822,0.058928,0.000000
69.570000,65.956093,-55.289822,0.023295,0.002317,0.058841,293.387360,14.945864,0.588407,-55.289822,0.058928,0.000000
69.800003,65.741608,-55.378784,0.023299,0.002316,0.058832,292.433289,14.897261,0.588324,-55.378784,0.058928,0.000000
70.030006,65.572556,-55.378784,0.023287,0.002316,0.058824,291.681305,14.858953,0.588241,-55.378784,0.058928,0.000000
70.260002,65.416901,-55.378784,0.023291,0.002316,0.058824,290.988922,14.823681,0.588241,-55.378784,0.058928,0.000000
70.490005,65.257156,-55.378784,0.023304,0.002316,0.058815,290.278320,14.787483,0.588150,-55.378784,0.058928,0.000000
70.720001,65.141342,-55.334305,0.023304,0.002316,0.058815,289.763153,14.761239,0.588150,-55.334305,0.058928,0.000000
70.950005,65.010643,-55.378784,0.023317,0.002316,0.058815,289.181793,14.731623,0.588150,-55.378784,0.058928,0.000000
71.180000,64.889992,-55.423264,0.023295,0.002315,0.058807,288.645111,14.704282,0.588067,-55.423264,0.058928,0.000000
71.410004,64.784988,-55.423264,0.023304,0.002315,0.058807,288.178009,14.680489,0.588067,-55.423264,0.058928,0.000000
71.640007,64.678490,-55.378784,0.023304,0.002315,0.058807,287.704285,14.656355,0.588067,-55.378784,0.058928,0.000000
71.870003,64.588005,-55.423264,0.023304,0.002315,0.058807,287.301788,14.635851,0.588067,-55.423264,0.058928,0.000000
72.100006,64.526558,-55.423264,0.023299,0.002315,0.058807,287.028473,14.621927,0.588067,-55.423264,0.058928,0.000000
72.330002,64.445007,-55.423264,0.023291,0.002315,0.058798,286.665710,14.603447,0.587976,-55.423264,0.058928,0.000000
72.560005,64.352287,-55.378784,0.023304,0.002315,0.058798,286.253265,14.582438,0.587976,-55.378784,0.058928,0.000000
72.790001,64.287872,-55.423264,0.023295,0.002315,0.058798,285.966736,14.567840,0.587976,-55.423264,0.058928,0.000000
73.020004,64.217865,-55.378784,0.023325,0.002315,0.058798,285.655334,14.551976,0.587976,-55.378784,0.058928,0.000000
73.250000,64.139664,-55.378784,0.023308,0.002315,0.058798,285.307465,14.534255,0.587976,-55.378784,0.058928,0.000000
73.480003,64.095352,-55.467747,0.023308,0.002315,0.058798,285.110352,14.524215,0.587976,-55.467747,0.058928,0.000000
73.710007,64.039871,-55.423264,0.023312,0.002315,0.058798,284.863586,14.511642,0.587976,-55.423264,0.058928,0.000000
73.940002,63.969864,-55.467747,0.023308,0.002315,0.058798,284.552155,14.495778,0.587976,-55.467747,0.058928,0.000000
74.170006,63.910286,-55.378784,0.023308,0.002315,0.058798,284.287140,14.482278,0.587976,-55.378784,0.058928,0.000000
74.400002,63.870815,-55.467747,0.023312,0.002315,0.058798,284.111572,14.473333,0.587976,-55.467747,0.058928,0.000000
74.630005,63.820171,-55.512226,0.023304,0.002315,0.058798,283.886292,14.461858,0.587976,-55.512226,0.058928,0.000000
74.860001,63.773998,-55.512226,0.023299,0.002315,0.058789,283.680908,14.451395,0.587893,-55.512226,0.058928,0.000000
75.090004,63.734898,-55.512226,0.023317,0.002315,0.058789,283.506989,14.442534,0.587893,-55.512226,0.058928,0.000000
75.320007,63.674946,-55.467747,0.023312,0.002315,0.058789,283.240295,14.428949,0.587893,-55.467747,0.058928,0.000000
75.550003,63.640316,-55.467747,0.023317,0.002315,0.058789,283.086273,14.421102,0.587893,-55.467747,0.058928,0.000000
75.780006,63.578503,-55.467747,0.023304,0.002315,0.058789,282.811310,14.407095,0.587893,-55.467747,0.058928,0.000000
76.010002,63.548340,-55.556709,0.023304,0.002315,0.058789,282.677124,14.400260,0.587893,-55.556709,0.058928,0.000000
76.240005,63.506260,-55.556709,0.023308,0.002315,0.058789,282.489960,14.390724,0.587893,-55.556709,0.058928,0.000000
76.470001,63.483921,-55.556709,0.023334,0.002315,0.058789,282.390594,14.385662,0.587893,-55.556709,0.058928,0.000000
76.700005,63.430672,-55.512226,0.023325,0.002315,0.058789,282.153717,14.373595,0.587893,-55.512226,0.058928,0.000000
76.930000,63.413540,-55.601189,0.023312,0.002315,0.058789,282.077515,14.369714,0.587893,-55.601189,0.058928,0.000000
77.160004,63.372952,-55.556709,0.023312,0.002315,0.058789,281.896973,14.360517,0.587893,-55.556709,0.058928,0.000000
77.390007,63.329384,-55.512226,0.023312,0.002315,0.058789,281.703156,14.350643,0.587893,-55.512226,0.058928,0.000000
77.620003,63.301456,-55.556709,0.023312,0.002315,0.058789,281.578949,14.344315,0.587893,-55.556709,0.058928,0.000000
77.850006,63.280605,-55.556709,0.023299,0.002315,0.058789,281.486206,14.339590,0.587893,-55.556709,0.058928,0.000000
78.080002,63.236664,-55.556709,0.023317,0.002315,0.058789,281.290741,14.329633,0.587893,-55.556709,0.058928,0.000000
78.310005,63.202404,-55.556709,0.023304,0.002315,0.058789,281.138336,14.321869,0.587893,-55.556709,0.058928,0.000000
78.540001,63.175224,-55.556709,0.023321,0.002315,0.058789,281.017426,14.315710,0.587893,-55.556709,0.058928,0.000000
78.770004,63.144688,-55.512226,0.023321,0.002314,0.058780,280.881592,14.308791,0.587802,-55.512226,0.058928,0.000000
79.000000,63.124950,-55.512226,0.023308,0.002314,0.058780,280.793793,14.304318,0.587802,-55.512226,0.058928,0.000000
79.230003,63.078033,-55.556709,0.023325,0.002314,0.058780,280.585114,14.293686,0.587802,-55.556709,0.058928,0.000000
79.460007,63.063885,-55.601189,0.023299,0.002314,0.058780,280.522156,14.290481,0.587802,-55.601189,0.058928,0.000000
79.690002,63.035210,-55.645668,0.023312,0.002314,0.058780,280.394623,14.283982,0.587802,-55.645668,0.058928,0.000000
79.920006,63.002815,-55.556709,0.023308,0.002314,0.058780,280.250519,14.276643,0.587802,-55.556709,0.058928,0.000000
80.150002,62.978237,-55.556709,0.023317,0.002314,0.058780,280.141205,14.271073,0.587802,-55.556709,0.058928,0.000000
80.380005,62.958874,-55.512226,0.023312,0.002314,0.058780,280.055054,14.266685,0.587802,-55.512226,0.058928,0.000000
80.610001,62.927967,-55.690151,0.023304,0.002314,0.058780,279.917572,14.259682,0.587802,-55.690151,0.058928,0.000000
80.840004,62.920147,-55.645668,0.023308,0.002314,0.058780,279.882782,14.257909,0.587802,-55.645668,0.058928,0.000000
81.070007,62.888496,-55.556709,0.023321,0.002314,0.058780,279.742004,14.250737,0.587802,-55.556709,0.058928,0.000000
81.300003,62.870251,-55.556709,0.023312,0.002314,0.058780,279.660828,14.246603,0.587802,-55.556709,0.058928,0.000000
81.530006,62.842323,-55.601189,0.023308,0.002314,0.058780,279.536621,14.240274,0.587802,-55.601189,0.058928,0.000000
81.760002,62.824074,-55.645668,0.023321,0.002314,0.058780,279.455444,14.236138,0.587802,-55.645668,0.058928,0.000000
81.990005,62.786095,-55.645668,0.023308,0.002314,0.058780,279.286499,14.227532,0.587802,-55.645668,0.058928,0.000000
82.220001,62.767475,-55.601189,0.023308,0.002314,0.058780,279.203674,14.223313,0.587802,-55.601189,0.058928,0.000000
82.450005,62.755932,-55.601189,0.023321,0.002314,0.058780,279.152313,14.220697,0.587802,-55.601189,0.058928,0.000000
82.680000,62.731354,-55.601189,0.023325,0.002314,0.058780,279.042999,14.215128,0.587802,-55.601189,0.058928,0.000000
82.910004,62.707523,-55.690151,0.023312,0.002314,0.058780,278.936981,14.209728,0.587802,-55.690151,0.058928,0.000000
83.140007,62.692257,-55.690151,0.023321,0.002314,0.058780,278.869080,14.206268,0.587802,-55.690151,0.058928,0.000000
83.370003,62.675499,-55.601189,0.023321,0.002314,0.058780,278.794556,14.202471,0.587802,-55.601189,0.058928,0.000000
83.600006,62.662838,-55.645668,0.023304,0.002314,0.058780,278.738220,14.199602,0.587802,-55.645668,0.058928,0.000000
83.830002,62.632675,-55.690151,0.023325,0.002314,0.058780,278.604065,14.192767,0.587802,-55.690151,0.058928,0.000000
84.060005,62.604748,-55.690151,0.023308,0.002314,0.058780,278.479828,14.186439,0.587802,-55.690151,0.058928,0.000000
84.290001,62.590225,-55.690151,0.023325,0.002314,0.058780,278.415222,14.183147,0.587802,-55.690151,0.058928,0.000000
84.520004,62.575329,-55.690151,0.023321,0.002314,0.058780,278.348969,14.179772,0.587802,-55.690151,0.058928,0.000000
84.750008,62.557831,-55.690151,0.023312,0.002314,0.058780,278.271118,14.175807,0.587802,-55.690151,0.058928,0.000000
84.980003,62.536232,-55.690151,0.023317,0.002314,0.058780,278.175049,14.170913,0.587802,-55.690151,0.058928,0.000000
85.210007,62.513515,-55.690151,0.023325,0.002314,0.058780,278.074005,14.165765,0.587802,-55.690151,0.058928,0.000000
85.440002,62.504951,-55.734631,0.023321,0.002314,0.058780,278.035919,14.163824,0.587802,-55.734631,0.058928,0.000000
85.670006,62.490429,-55.690151,0.023317,0.002314,0.058780,277.971313,14.160533,0.587802,-55.690151,0.058928,0.000000
85.900002,62.461758,-55.645668,0.023312,0.002314,0.058780,277.843781,14.154037,0.587802,-55.645668,0.058928,0.000000
86.130005,62.455799,-55.690151,0.023317,0.002314,0.058780,277.817261,14.152687,0.587802,-55.690151,0.058928,0.000000
86.360001,62.445744,-55.779114,0.023373,0.002314,0.058780,277.772552,14.150408,0.587802,-55.779114,0.058928,0.000000
86.590004,62.418934,-55.779114,0.023373,0.002314,0.058780,277.653290,14.144333,0.587802,-55.779114,0.058928,0.000000
86.820007,62.401062,-55.690151,0.023360,0.002314,0.058780,277.573792,14.140283,0.587802,-55.690151,0.058928,0.000000
87.050003,62.376858,-55.734631,0.023381,0.002314,0.058780,277.466125,14.134798,0.587802,-55.734631,0.058928,0.000000
87.280006,62.369781,-55.734631,0.023381,0.002314,0.058780,277.434631,14.133195,0.587802,-55.734631,0.058928,0.000000
87.510002,62.356377,-55.734631,0.023377,0.002314,0.058780,277.375031,14.130157,0.587802,-55.734631,0.058928,0.000000
87.740005,62.328449,-55.734631,0.023368,0.002314,0.058780,277.250793,14.123828,0.587802,-55.734631,0.058928,0.000000
87.970001,62.326214,-55.734631,0.023364,0.002314,0.058780,277.240845,14.123322,0.587802,-55.734631,0.058928,0.000000
88.200005,62.310200,-55.690151,0.023377,0.002314,0.058780,277.169617,14.119693,0.587802,-55.690151,0.058928,0.000000
88.430008,62.288605,-55.734631,0.023377,0.002314,0.058780,277.073547,14.114799,0.587802,-55.734631,0.058928,0.000000
88.660004,62.275200,-55.779114,0.023373,0.002314,0.058780,277.013916,14.111762,0.587802,-55.779114,0.058928,0.000000
88.890007,62.255089,-55.779114,0.023368,0.002314,0.058780,276.924469,14.107204,0.587802,-55.779114,0.058928,0.000000
89.120003,62.241314,-55.779114,0.023377,0.002314,0.058780,276.863190,14.104084,0.587802,-55.779114,0.058928,0.000000
89.350006,62.239452,-55.690151,0.023373,0.002314,0.058780,276.854919,14.103662,0.587802,-55.690151,0.058928,0.000000
89.580002,62.213383,-55.779114,0.023368,0.002314,0.058780,276.738953,14.097754,0.587802,-55.779114,0.058928,0.000000
89.810005,62.201469,-55.823593,0.023381,0.002314,0.058780,276.685944,14.095055,0.587802,-55.823593,0.058928,0.000000
90.040001,62.181732,-55.868076,0.023373,0.002314,0.058780,276.598145,14.090582,0.587802,-55.868076,0.058928,0.000000
90.270004,62.173168,-55.779114,0.023386,0.002314,0.058780,276.560059,14.088641,0.587802,-55.779114,0.058928,0.000000
90.500008,62.154179,-55.779114,0.023355,0.002314,0.058780,276.475586,14.084338,0.587802,-55.779114,0.058928,0.000000
90.730003,62.135559,-55.779114,0.023390,0.002314,0.058780,276.392761,14.080119,0.587802,-55.779114,0.058928,0.000000
90.960007,62.121410,-55.823593,0.023368,0.002314,0.058780,276.329834,14.076913,0.587802,-55.823593,0.058928,0.000000
91.190002,62.103161,-55.823593,0.023373,0.002314,0.058780,276.248657,14.072778,0.587802,-55.823593,0.058928,0.000000
91.420006,62.110237,-55.868076,0.023364,0.002314,0.058780,276.280121,14.074381,0.587802,-55.868076,0.058928,0.000000
91.650002,62.085289,-55.823593,0.023373,0.002314,0.058780,276.169159,14.068727,0.587802,-55.823593,0.058928,0.000000
91.880005,62.075977,-55.823593,0.023386,0.002314,0.058780,276.127747,14.066618,0.587802,-55.823593,0.058928,0.000000
92.110001,62.059593,-55.779114,0.023386,0.002314,0.058780,276.054871,14.062905,0.587802,-55.779114,0.058928,0.000000
92.340004,62.049541,-55.868076,0.023368,0.002314,0.058780,276.010132,14.060627,0.587802,-55.868076,0.058928,0.000000
92.570007,62.023476,-55.868076,0.023364,0.002314,0.058780,275.894196,14.054721,0.587802,-55.868076,0.058928,0.000000
92.800003,62.023846,-55.823593,0.023355,0.002314,0.058780,275.895844,14.054804,0.587802,-55.823593,0.058928,0.000000
93.030006,62.011185,-55.868076,0.023381,0.002314,0.058780,275.839539,14.051935,0.587802,-55.868076,0.058928,0.000000
93.260002,62.007462,-55.823593,0.023377,0.002314,0.058780,275.822968,14.051092,0.587802,-55.823593,0.058928,0.000000
93.490005,61.980652,-55.912556,0.023360,0.002314,0.058780,275.703705,14.045017,0.587802,-55.912556,0.058928,0.000000
93.720001,61.979908,-55.868076,0.023364,0.002314,0.058780,275.700409,14.044847,0.587802,-55.868076,0.058928,0.000000
93.950005,61.951981,-55.868076,0.023381,0.002314,0.058780,275.576172,14.038519,0.587802,-55.868076,0.058928,0.000000
94.180008,61.946766,-55.912556,0.023368,0.002314,0.058780,275.552979,14.037338,0.587802,-55.912556,0.058928,0.000000
94.410004,61.928146,-55.912556,0.023360,0.002314,0.058780,275.470154,14.033118,0.587802,-55.912556,0.058928,0.000000
94.640007,61.919209,-55.957035,0.023381,0.002314,0.058780,275.430389,14.031094,0.587802,-55.957035,0.058928,0.000000
94.870003,61.914368,-55.957035,0.023368,0.002314,0.058780,275.408875,14.029997,0.587802,-55.957035,0.058928,0.000000
95.100006,61.901337,-55.823593,0.023377,0.002314,0.058780,275.350891,14.027043,0.587802,-55.823593,0.058928,0.000000
95.330002,61.895378,-55.868076,0.023377,0.002314,0.058780,275.324402,14.025693,0.587802,-55.868076,0.058928,0.000000
95.560005,61.887188,-55.912556,0.023373,0.002314,0.058780,275.287964,14.023838,0.587802,-55.912556,0.058928,0.000000
95.790001,61.869312,-55.957035,0.023373,0.002314,0.058780,275.208435,14.019787,0.587802,-55.957035,0.058928,0.000000
96.020004,61.857395,-55.957035,0.023355,0.002314,0.058780,275.155426,14.017086,0.587802,-55.957035,0.058928,0.000000
96.250008,61.845852,-55.868076,0.023390,0.002314,0.058780,275.104095,14.014471,0.587802,-55.868076,0.058928,0.000000
96.480003,61.830585,-55.868076,0.023381,0.002314,0.058780,275.036194,14.011011,0.587802,-55.868076,0.058928,0.000000
96.710007,61.819416,-55.957035,0.023377,0.002314,0.058780,274.986511,14.008480,0.587802,-55.957035,0.058928,0.000000
96.940002,61.813828,-55.957035,0.023373,0.002314,0.058780,274.961639,14.007214,0.587802,-55.957035,0.058928,0.000000
97.170006,61.804893,-55.957035,0.023355,0.002314,0.058780,274.921906,14.005189,0.587802,-55.957035,0.058928,0.000000
97.400002,61.787018,-55.957035,0.023381,0.002314,0.058780,274.842377,14.001138,0.587802,-55.957035,0.058928,0.000000
97.630005,61.769146,-55.912556,0.023373,0.002314,0.058780,274.762878,13.997088,0.587802,-55.912556,0.058928,0.000000
97.860008,61.761326,-55.957035,0.023377,0.002314,0.058780,274.728088,13.995317,0.587802,-55.957035,0.058928,0.000000
98.090004,61.742332,-56.001518,0.023364,0.002314,0.058780,274.643616,13.991013,0.587802,-56.001518,0.058928,0.000000
98.320007,61.739353,-55.957035,0.023373,0.002314,0.058780,274.630371,13.990337,0.587802,-55.957035,0.058928,0.000000
98.550003,61.727810,-55.957035,0.023360,0.002314,0.058780,274.579010,13.987722,0.587802,-55.957035,0.058928,0.000000
98.780006,61.720364,-56.001518,0.023364,0.002314,0.058780,274.545898,13.986034,0.587802,-56.001518,0.058928,0.000000
99.000008,61.706959,-56.001518,0.023368,0.002314,0.058780,274.486267,13.982997,0.587802,-56.001518,0.058928,0.000000