File: Data/Polished old I18 after 1_08182023_173538.csv
Time (sec),S:Load (lbs),S:HL1 (DIM),S:LVDT (in),S:Position (in),Ch:Position (mm),Ch:Load (N),Ch:Stress (MPa),Ch:Strain (mm/mm),Ch:HL1 (DIM),Set Point (),Cycles ()
0.110000,-0.002609,-40.566628,0.000043,-0.000000,-0.000000,-0.011607,-0.000591,-0.000000,-40.566628,0.000078,0.000000
0.430000,0.015266,-40.611107,0.000052,0.000034,0.000867,0.067908,0.003459,0.008671,-40.611107,0.001518,0.000000
0.750000,-0.049156,-40.566628,0.000026,0.000230,0.005836,-0.218658,-0.011139,0.058363,-40.566628,0.006860,0.000000
1.070000,-0.016388,-40.477665,0.000017,0.000435,0.011048,-0.072897,-0.003714,0.110485,-40.477665,0.012184,0.000000
1.390000,0.000374,-40.566628,0.000017,0.000647,0.016434,0.001663,0.000085,0.164340,-40.566628,0.017509,0.000000
1.710000,-0.032394,-40.566628,0.000030,0.000858,0.021802,-0.144098,-0.007341,0.218021,-40.566628,0.022851,0.000000
2.030000,0.010056,-40.566628,0.000022,0.001064,0.027014,0.044729,0.002279,0.270139,-40.566628,0.028176,0.000000
2.350000,-0.008194,-40.566628,0.000034,0.001278,0.032469,-0.036449,-0.001857,0.324687,-40.566628,0.033518,0.000000
2.670000,-0.017502,-40.566628,0.000034,0.001484,0.037690,-0.077852,-0.003966,0.376896,-40.566628,0.038843,0.000000
2.990000,-0.004097,-40.611107,0.000034,0.001691,0.042954,-0.018224,-0.000928,0.429536,-40.611107,0.044168,0.000000
3.310000,-0.023087,-40.566628,0.000013,0.001905,0.048382,-0.102694,-0.005231,0.483823,-40.566628,0.049510,0.000000
3.630000,0.015266,-40.611107,0.000017,0.002112,0.053655,0.067908,0.003459,0.536551,-40.611107,0.054834,0.000000
3.950000,0.016754,-40.566628,0.000013,0.002316,0.058832,0.074526,0.003797,0.588324,-40.566628,0.060159,0.000000
4.270000,0.012291,-40.566628,0.000022,0.002539,0.064478,0.054673,0.002785,0.644783,-40.566628,0.065501,0.000000
4.590000,-0.014526,-40.566628,0.000022,0.002751,0.069881,-0.064617,-0.003292,0.698809,-40.566628,0.070826,0.000000
4.910000,-0.005959,-40.611107,0.000034,0.002951,0.074963,-0.026505,-0.001350,0.749629,-40.611107,0.076151,0.000000
5.230000,-0.059578,-40.611107,0.000026,0.003161,0.080296,-0.265016,-0.013501,0.802962,-40.611107,0.081493,0.000000
5.550000,0.004837,-40.655590,0.000009,0.003373,0.085673,0.021516,0.001096,0.856730,-40.655590,0.086818,0.000000
5.870000,0.004837,-40.566628,0.000065,0.003579,0.090911,0.021516,0.001096,0.909113,-40.566628,0.092160,0.000000
6.190000,-0.008942,-40.566628,0.000026,0.003794,0.096357,-0.039774,-0.002026,0.963574,-40.566628,0.097485,0.000000
6.510000,0.011917,-40.566628,0.000030,0.004003,0.101682,0.053010,0.002700,1.016820,-40.566628,0.102809,0.000000
6.830000,0.004097,-40.655590,0.000017,0.004208,0.106885,0.018224,0.000928,1.068854,-40.655590,0.108151,0.000000
7.150001,-0.048782,-40.611107,0.000017,0.004420,0.112271,-0.216995,-0.011054,1.122710,-40.611107,0.113476,0.000000
7.470000,-0.020111,-40.566628,0.000017,0.004628,0.117544,-0.089459,-0.004557,1.175437,-40.566628,0.118801,0.000000
7.790000,-0.003723,-40.566628,0.000047,0.004841,0.122972,-0.016561,-0.000844,1.229724,-40.566628,0.124143,0.000000
8.110001,-0.018250,-40.611107,0.000022,0.005051,0.128306,-0.081178,-0.004135,1.283060,-40.611107,0.129468,0.000000
8.430000,0.009308,-40.611107,0.000034,0.005254,0.133440,0.041403,0.002109,1.334399,-40.611107,0.134810,0.000000
8.750000,-0.003349,-40.611107,0.000034,0.005473,0.139025,-0.014898,-0.000759,1.390249,-40.611107,0.140135,0.000000
9.070001,-0.013405,-40.611107,0.000060,0.005680,0.144263,-0.059628,-0.003038,1.442628,-40.611107,0.145460,0.000000
9.390000,-0.003723,-40.611107,0.000034,0.005883,0.149440,-0.016561,-0.000844,1.494401,-40.611107,0.150802,0.000000
9.710000,-0.040962,-40.611107,0.000000,0.006096,0.154843,-0.182209,-0.009282,1.548431,-40.611107,0.156127,0.000000
10.030001,0.000374,-40.611107,0.000017,0.006307,0.160202,0.001663,0.000085,1.602025,-40.611107,0.161452,0.000000
10.350000,0.010422,-40.655590,0.000026,0.006512,0.165397,0.046358,0.002362,1.653973,-40.655590,0.166794,0.000000
10.670000,0.029785,-40.611107,0.000022,0.006731,0.170974,0.132491,0.006749,1.709736,-40.611107,0.172118,0.000000
10.990001,0.004837,-40.611107,0.000022,0.006944,0.176385,0.021516,0.001096,1.763848,-40.611107,0.177443,0.000000
11.310000,0.007072,-40.566628,0.000013,0.007145,0.181484,0.031460,0.001603,1.814842,-40.566628,0.182785,0.000000
11.630000,-0.075966,-40.655590,0.000009,0.007355,0.186809,-0.337913,-0.017214,1.868092,-40.655590,0.188110,0.000000
11.950001,0.012291,-40.611107,0.000043,0.007566,0.192186,0.054673,0.002785,1.921860,-40.611107,0.193452,0.000000
12.270000,0.001114,-40.655590,0.000043,0.007775,0.197484,0.004955,0.000252,1.974845,-40.655590,0.198777,0.000000
12.590000,0.000740,-40.655590,0.000043,0.007988,0.202896,0.003292,0.000168,2.028961,-40.655590,0.204102,0.000000
12.910001,0.016380,-40.611107,0.000026,0.008202,0.208342,0.072863,0.003712,2.083422,-40.611107,0.209444,0.000000
13.230000,-0.000000,-40.700069,0.000022,0.008404,0.213450,-0.000000,-0.000000,2.134503,-40.700069,0.214768,0.000000
13.550000,-0.051392,-40.611107,0.000013,0.008616,0.218853,-0.228601,-0.011646,2.188529,-40.611107,0.220093,0.000000
13.870001,-0.031281,-40.566628,0.000043,0.008826,0.224169,-0.139143,-0.007088,2.241691,-40.566628,0.225435,0.000000
14.190001,0.013779,-40.655590,0.000030,0.009039,0.229598,0.061291,0.003122,2.295978,-40.655590,0.230760,0.000000
14.510000,-0.021973,-40.611107,0.000022,0.009248,0.234905,-0.097739,-0.004979,2.349053,-40.611107,0.236085,0.000000
14.830001,0.011917,-40.700069,0.000030,0.009457,0.240195,0.053010,0.002700,2.401955,-40.700069,0.241427,0.000000
15.150001,-0.008568,-40.655590,0.000017,0.009673,0.245685,-0.038112,-0.001941,2.456851,-40.655590,0.246752,0.000000
15.470000,-0.018990,-40.655590,0.000043,0.009878,0.250906,-0.084470,-0.004303,2.509056,-40.655590,0.252094,0.000000
15.790001,-0.013779,-40.611107,0.000013,0.010086,0.256187,-0.061291,-0.003122,2.561871,-40.611107,0.257419,0.000000
16.110001,-0.013405,-40.611107,0.000034,0.010296,0.261520,-0.059628,-0.003038,2.615203,-40.611107,0.262743,0.000000
16.430000,0.011917,-40.700069,-0.000013,0.010507,0.266888,0.053010,0.002700,2.668885,-40.700069,0.268085,0.000000
16.750000,0.016380,-40.655590,0.000022,0.010713,0.272109,0.072863,0.003712,2.721093,-40.655590,0.273410,0.000000
17.070002,-0.002983,-40.655590,0.000026,0.010933,0.277694,-0.013269,-0.000676,2.776943,-40.655590,0.278735,0.000000
17.390001,-0.018250,-40.611107,0.000026,0.011145,0.283089,-0.081178,-0.004135,2.830886,-40.611107,0.284077,0.000000
17.710001,-0.001122,-40.611107,0.000034,0.011344,0.288136,-0.004989,-0.000254,2.881357,-40.611107,0.289402,0.000000
18.030001,-0.055115,-40.655590,0.000026,0.011559,0.293608,-0.245163,-0.012489,2.936079,-40.655590,0.294744,0.000000
18.350000,0.012657,-40.700069,0.000026,0.011769,0.298924,0.056302,0.002868,2.989238,-40.700069,0.300069,0.000000
18.670000,0.014519,-40.700069,0.000052,0.011972,0.304101,0.064583,0.003290,3.041012,-40.700069,0.305393,0.000000
18.990002,-0.000374,-40.611107,0.000026,0.012189,0.309608,-0.001663,-0.000085,3.096082,-40.611107,0.310736,0.000000
19.310001,0.001488,-40.655590,0.000017,0.012405,0.315080,0.006618,0.000337,3.150804,-40.655590,0.316060,0.000000
19.630001,-0.002983,-40.655590,0.000026,0.012606,0.320180,-0.013269,-0.000676,3.201798,-40.655590,0.321385,0.000000
19.950001,-0.040588,-40.655590,0.000013,0.012817,0.325548,-0.180546,-0.009197,3.255479,-40.655590,0.326727,0.000000
20.270000,-0.021225,-40.700069,0.000022,0.013031,0.330985,-0.094413,-0.004810,3.309853,-40.700069,0.332052,0.000000
20.590000,0.005585,-40.700069,0.000039,0.013237,0.336232,0.024842,0.001266,3.362319,-40.700069,0.337377,0.000000
20.910002,-0.017128,-40.611107,0.000022,0.013450,0.341617,-0.076189,-0.003881,3.416174,-40.611107,0.342719,0.000000
21.230001,0.013031,-40.655590,0.000047,0.013662,0.347012,0.057965,0.002953,3.470117,-40.655590,0.348044,0.000000
21.550001,-0.015266,-40.655590,0.000017,0.013870,0.352302,-0.067908,-0.003459,3.523018,-40.655590,0.353386,0.000000
21.870001,-0.032768,-40.700069,0.000043,0.014077,0.357566,-0.145760,-0.007425,3.575658,-40.700069,0.358710,0.000000
22.190001,-0.015266,-40.655590,0.000047,0.014285,0.362839,-0.067908,-0.003459,3.628386,-40.655590,0.364035,0.000000
22.510000,0.011543,-40.700069,0.000056,0.014499,0.368276,0.051347,0.002616,3.682760,-40.700069,0.369377,0.000000
22.830002,0.009308,-40.744553,0.000039,0.014706,0.373531,0.041403,0.002109,3.735313,-40.744553,0.374702,0.000000
23.150002,0.006332,-40.744553,0.000039,0.014913,0.378778,0.028168,0.001435,3.787783,-40.744553,0.380027,0.000000
23.470001,-0.005211,-40.744553,0.000034,0.015133,0.384380,-0.023179,-0.001181,3.843803,-40.744553,0.385369,0.000000
23.790001,-0.021225,-40.700069,0.000034,0.015342,0.389697,-0.094413,-0.004810,3.896966,-40.700069,0.390694,0.000000
24.110001,0.006699,-40.655590,0.000034,0.015541,0.394752,0.029797,0.001518,3.947524,-40.655590,0.396036,0.000000
24.430000,-0.039474,-40.700069,0.000022,0.015758,0.400259,-0.175591,-0.008945,4.002594,-40.700069,0.401360,0.000000
24.750002,0.009682,-40.700069,0.000022,0.015968,0.405584,0.043066,0.002194,4.055840,-40.700069,0.406685,0.000000
25.070002,0.022339,-40.700069,0.000026,0.016171,0.410735,0.099368,0.005062,4.107353,-40.700069,0.412027,0.000000
25.390001,-0.011917,-40.700069,0.000022,0.016386,0.416207,-0.053010,-0.002700,4.162075,-40.700069,0.417352,0.000000
25.710001,0.009308,-40.655590,0.000052,0.016602,0.421680,0.041403,0.002109,4.216797,-40.655590,0.422677,0.000000
26.030001,-0.005211,-40.700069,-0.000004,0.016802,0.426770,-0.023179,-0.001181,4.267704,-40.700069,0.428019,0.000000
26.350000,-0.045799,-40.744553,-0.000004,0.017013,0.432121,-0.203725,-0.010378,4.321211,-40.744553,0.433344,0.000000
26.670002,-0.013031,-40.744553,0.000030,0.017227,0.437576,-0.057965,-0.002953,4.375759,-40.744553,0.438669,0.000000
26.990002,0.001488,-40.700069,0.000022,0.017434,0.442823,0.006618,0.000337,4.428229,-40.700069,0.444011,0.000000
27.310001,-0.032394,-40.700069,0.000022,0.017647,0.448234,-0.144098,-0.007341,4.482341,-40.700069,0.449336,0.000000
27.630001,0.001862,-40.700069,0.000013,0.017856,0.453550,0.008281,0.000422,4.535504,-40.700069,0.454678,0.000000
27.950001,0.011169,-40.744553,0.000026,0.018067,0.458892,0.049684,0.002531,4.588924,-40.744553,0.460003,0.000000
28.270000,0.033882,-40.744553,0.000065,0.018273,0.464130,0.150715,0.007678,4.641303,-40.744553,0.465327,0.000000
28.590002,0.080429,-40.744553,0.000017,0.018484,0.469481,0.357766,0.018225,4.694814,-40.744553,0.470669,0.000000
28.910002,0.145599,-40.744553,0.000034,0.018696,0.474875,0.647658,0.032993,4.748753,-40.744553,0.475994,0.000000
29.230001,0.173149,-40.700069,0.000034,0.018902,0.480122,0.770206,0.039236,4.801222,-40.700069,0.481319,0.000000
29.550001,0.226776,-40.744553,0.000065,0.019108,0.485351,1.008751,0.051388,4.853515,-40.744553,0.486661,0.000000
29.870001,0.246506,-40.789032,0.000078,0.019328,0.490936,1.096512,0.055859,4.909365,-40.789032,0.491986,0.000000
30.190001,0.253586,-40.744553,0.000069,0.019539,0.496296,1.128006,0.057463,4.962959,-40.744553,0.497311,0.000000
30.510002,0.283005,-40.744553,0.000082,0.019735,0.501256,1.258868,0.064130,5.012564,-40.744553,0.502653,0.000000
30.830002,0.259171,-40.744553,0.000056,0.019952,0.506781,1.152848,0.058729,5.067808,-40.744553,0.507978,0.000000
31.150002,0.352264,-40.789032,0.000082,0.020162,0.512123,1.566950,0.079824,5.121228,-40.789032,0.513320,0.000000
31.470001,0.379822,-40.744553,0.000086,0.020365,0.517283,1.689532,0.086069,5.172827,-40.744553,0.518644,0.000000
31.790001,0.371254,-40.789032,0.000181,0.020579,0.522711,1.651420,0.084127,5.227114,-40.789032,0.523969,0.000000
32.110001,0.373116,-40.744553,0.000418,0.020796,0.528218,1.659701,0.084549,5.282184,-40.744553,0.529311,0.000000
32.430000,0.363434,-40.789032,0.000621,0.020997,0.533318,1.616634,0.082355,5.333178,-40.789032,0.534636,0.000000
32.750000,0.299759,-40.789032,0.000854,0.021207,0.538651,1.333394,0.067926,5.386511,-40.789032,0.539961,0.000000
33.070000,0.344444,-40.789032,0.001056,0.021423,0.544141,1.532165,0.078052,5.441407,-40.789032,0.545303,0.000000
33.390003,0.380936,-40.833511,0.001289,0.021629,0.549370,1.694486,0.086321,5.493700,-40.833511,0.550628,0.000000
33.710003,0.362320,-40.833511,0.001513,0.021841,0.554764,1.611680,0.082103,5.547642,-40.833511,0.555970,0.000000
34.030003,0.375725,-40.744553,0.001690,0.022049,0.560054,1.671307,0.085140,5.600543,-40.744553,0.561294,0.000000
34.350002,0.360825,-40.789032,0.001906,0.022261,0.565422,1.605028,0.081764,5.654224,-40.789032,0.566619,0.000000
34.670002,0.326942,-40.833511,0.002130,0.022468,0.570695,1.454313,0.074086,5.706952,-40.833511,0.571961,0.000000
34.990002,0.352264,-40.789032,0.002324,0.022678,0.576020,1.566950,0.079824,5.760198,-40.789032,0.577286,0.000000
35.310001,0.374977,-40.833511,0.002561,0.022890,0.581405,1.667982,0.084971,5.814053,-40.833511,0.582611,0.000000
35.630001,0.378326,-40.700069,0.002768,0.023100,0.586739,1.682880,0.085730,5.867390,-40.700069,0.587953,0.000000
35.950001,0.388756,-40.789032,0.002962,0.023305,0.591942,1.729272,0.088093,5.919421,-40.789032,0.593278,0.000000
36.270000,0.374229,-40.789032,0.003221,0.023525,0.597544,1.664656,0.084802,5.975444,-40.789032,0.598602,0.000000
36.590000,0.347420,-40.833511,0.003449,0.023736,0.602886,1.545400,0.078726,6.028864,-40.833511,0.603945,0.000000
36.910000,0.361946,-40.700069,0.003695,0.023932,0.607873,1.610017,0.082018,6.078731,-40.700069,0.609269,0.000000
37.230003,0.322472,-40.789032,0.003902,0.024151,0.613432,1.434425,0.073073,6.134319,-40.789032,0.614611,0.000000
37.550003,0.380562,-40.789032,0.004130,0.024358,0.618705,1.692824,0.086237,6.187047,-40.789032,0.619936,0.000000
37.870003,0.385406,-40.789032,0.004324,0.024563,0.623891,1.714374,0.087334,6.238907,-40.789032,0.625261,0.000000
38.190002,0.352264,-40.833511,0.004566,0.024778,0.629354,1.566950,0.079824,6.293542,-40.833511,0.630603,0.000000
38.510002,0.371628,-40.833511,0.004842,0.024996,0.634887,1.653083,0.084212,6.348874,-40.833511,0.635928,0.000000
38.830002,0.357475,-40.789032,0.005044,0.025194,0.639934,1.590129,0.081005,6.399345,-40.789032,0.641253,0.000000
39.150002,0.301247,-40.833511,0.005251,0.025405,0.645276,1.340012,0.068263,6.452765,-40.833511,0.646595,0.000000
39.470001,0.349281,-40.833511,0.005476,0.025621,0.650784,1.553681,0.079148,6.507835,-40.833511,0.651919,0.000000
39.790001,0.379448,-40.833511,0.005708,0.025825,0.655961,1.687869,0.085984,6.559609,-40.833511,0.657262,0.000000
40.110001,0.348915,-40.922474,0.005915,0.026038,0.661372,1.552052,0.079065,6.613722,-40.922474,0.662586,0.000000
40.430000,0.365669,-40.744553,0.006122,0.026252,0.666801,1.626578,0.082862,6.668012,-40.744553,0.667911,0.000000
40.750004,0.369019,-40.744553,0.006372,0.026459,0.672065,1.641477,0.083621,6.720653,-40.744553,0.673253,0.000000
41.070004,0.331779,-40.877995,0.006601,0.026666,0.677312,1.475829,0.075182,6.773118,-40.877995,0.678578,0.000000
41.390003,0.347054,-40.877995,0.006786,0.026879,0.682724,1.543771,0.078643,6.827235,-40.877995,0.683903,0.000000
41.710003,0.376465,-40.833511,0.007028,0.027090,0.688074,1.674599,0.085308,6.880742,-40.833511,0.689245,0.000000
42.030003,0.359711,-40.833511,0.007261,0.027298,0.693364,1.600073,0.081512,6.933644,-40.833511,0.694569,0.000000
42.350002,0.394714,-40.744553,0.007468,0.027503,0.698585,1.755777,0.089444,6.985849,-40.744553,0.699894,0.000000
42.670002,0.378326,-40.833511,0.007705,0.027723,0.704152,1.682880,0.085730,7.041524,-40.833511,0.705236,0.000000
42.990002,0.357849,-40.833511,0.007894,0.027934,0.709529,1.591792,0.081090,7.095293,-40.833511,0.710561,0.000000
43.310001,0.372002,-40.833511,0.008093,0.028133,0.714568,1.654746,0.084297,7.145677,-40.833511,0.715903,0.000000
43.630001,0.373116,-40.833511,0.008308,0.028352,0.720144,1.659701,0.084549,7.201440,-40.833511,0.721228,0.000000
43.950001,0.393593,-40.789032,0.008507,0.028559,0.725408,1.750788,0.089189,7.254080,-40.789032,0.726553,0.000000
44.270000,0.415192,-40.833511,0.008727,0.028762,0.730542,1.846865,0.094084,7.305423,-40.833511,0.731895,0.000000
44.590004,0.385780,-40.833511,0.008929,0.028979,0.736058,1.716037,0.087419,7.360576,-40.833511,0.737220,0.000000
44.910004,0.407372,-40.877995,0.009136,0.029194,0.741530,1.812079,0.092312,7.415298,-40.877995,0.742545,0.000000
45.230003,0.401413,-40.833511,0.009339,0.029396,0.746647,1.785574,0.090961,7.466466,-40.833511,0.747887,0.000000
45.550003,0.350777,-40.833511,0.009541,0.029604,0.751954,1.560333,0.079487,7.519542,-40.833511,0.753211,0.000000
45.870003,0.376465,-40.833511,0.009761,0.029823,0.757513,1.674599,0.085308,7.575130,-40.833511,0.758536,0.000000
46.190002,0.405510,-40.789032,0.009977,0.030024,0.762612,1.803798,0.091890,7.626121,-40.789032,0.763878,0.000000
46.510002,0.379448,-40.833511,0.010223,0.030238,0.768041,1.687869,0.085984,7.680411,-40.833511,0.769203,0.000000
46.830002,0.406631,-40.833511,0.010438,0.030456,0.773574,1.808787,0.092144,7.735739,-40.833511,0.774545,0.000000
47.150002,0.398064,-40.833511,0.010675,0.030658,0.778708,1.770676,0.090203,7.787081,-40.833511,0.779870,0.000000
47.470001,0.363434,-40.833511,0.010874,0.030868,0.784059,1.616634,0.082355,7.840588,-40.833511,0.785195,0.000000
47.790001,0.389503,-40.833511,0.011076,0.031080,0.789436,1.732598,0.088263,7.894356,-40.833511,0.790537,0.000000
48.110001,0.423759,-40.877995,0.011296,0.031289,0.794743,1.884976,0.096025,7.947428,-40.877995,0.795862,0.000000
48.430004,0.401787,-40.877995,0.011516,0.031496,0.799990,1.787237,0.091046,7.999898,-40.877995,0.801187,0.000000
48.750004,0.421898,-40.833511,0.011727,0.031703,0.805263,1.876696,0.095603,8.052626,-40.833511,0.806529,0.000000
49.070004,0.400299,-40.833511,0.011930,0.031921,0.810795,1.780619,0.090709,8.107953,-40.833511,0.811853,0.000000
49.390003,0.374603,-40.833511,0.012193,0.032131,0.816137,1.666319,0.084886,8.161373,-40.833511,0.817196,0.000000
49.710003,0.379074,-40.833511,0.012409,0.032334,0.821289,1.686206,0.085899,8.212885,-40.833511,0.822520,0.000000
50.030003,0.394341,-40.877995,0.012654,0.032551,0.826804,1.754114,0.089359,8.268043,-40.877995,0.827845,0.000000
50.350002,0.408867,-40.833511,0.012891,0.032757,0.832025,1.818731,0.092651,8.320248,-40.833511,0.833187,0.000000
50.670002,0.417427,-40.877995,0.013103,0.032961,0.837219,1.856808,0.094590,8.372195,-40.877995,0.838512,0.000000
50.990002,0.406258,-40.877995,0.013327,0.033179,0.842735,1.807124,0.092059,8.427353,-40.877995,0.843837,0.000000
51.310001,0.402534,-40.833511,0.013530,0.033393,0.848181,1.790563,0.091216,8.481813,-40.833511,0.849179,0.000000
51.630001,0.405144,-40.833511,0.013728,0.033592,0.853246,1.802169,0.091807,8.532459,-40.833511,0.854503,0.000000
51.950001,0.361946,-40.833511,0.013969,0.033803,0.858588,1.610017,0.082018,8.585879,-40.833511,0.859828,0.000000
52.270004,0.388008,-40.833511,0.014189,0.034019,0.864095,1.725946,0.087924,8.640949,-40.833511,0.865170,0.000000
52.590004,0.414078,-40.833511,0.014431,0.034220,0.869186,1.841910,0.093831,8.691856,-40.833511,0.870495,0.000000
52.910004,0.395828,-40.877995,0.014616,0.034434,0.874632,1.760732,0.089696,8.746317,-40.877995,0.875837,0.000000
53.230003,0.421898,-40.877995,0.014840,0.034654,0.880208,1.876696,0.095603,8.802080,-40.877995,0.881162,0.000000
53.550003,0.400299,-40.877995,0.015090,0.034856,0.885333,1.780619,0.090709,8.853334,-40.877995,0.886487,0.000000
53.870003,0.381683,-40.877995,0.015276,0.035065,0.890641,1.697812,0.086491,8.906406,-40.877995,0.891829,0.000000
54.190002,0.398437,-40.877995,0.015474,0.035278,0.896070,1.772339,0.090287,8.960697,-40.877995,0.897154,0.000000
54.510002,0.423759,-40.922474,0.015733,0.035485,0.901325,1.884976,0.096025,9.013250,-40.922474,0.902478,0.000000
54.830002,0.404022,-40.922474,0.015961,0.035691,0.906563,1.797181,0.091553,9.065630,-40.922474,0.907820,0.000000
55.150002,0.430092,-40.877995,0.016164,0.035900,0.911853,1.913144,0.097460,9.118531,-40.877995,0.913145,0.000000
55.470001,0.409233,-40.833511,0.016418,0.036117,0.917360,1.820360,0.092734,9.173601,-40.833511,0.918470,0.000000
55.790001,0.389130,-40.833511,0.016642,0.036327,0.922711,1.730935,0.088178,9.227108,-40.833511,0.923812,0.000000
56.110004,0.408119,-40.833511,0.016819,0.036528,0.927810,1.815405,0.092481,9.278098,-40.833511,0.929137,0.000000
56.430004,0.403648,-40.833511,0.017043,0.036749,0.933412,1.795518,0.091468,9.334123,-40.833511,0.934479,0.000000
56.750004,0.424507,-40.877995,0.017259,0.036952,0.938572,1.888302,0.096195,9.385722,-40.877995,0.939804,0.000000
57.070004,0.442001,-40.877995,0.017475,0.037158,0.943810,1.966120,0.100159,9.438105,-40.877995,0.945128,0.000000
57.390003,0.422638,-40.877995,0.017720,0.037376,0.949343,1.879987,0.095771,9.493432,-40.877995,0.950471,0.000000
57.710003,0.419662,-40.966957,0.017906,0.037587,0.954720,1.866752,0.095097,9.547201,-40.966957,0.955795,0.000000
58.030003,0.452805,-40.922474,0.018104,0.037789,0.959845,2.014175,0.102607,9.598452,-40.922474,0.961120,0.000000
58.350002,0.383171,-40.922474,0.018358,0.037998,0.965144,1.704430,0.086828,9.651441,-40.922474,0.966462,0.000000
58.670002,0.450943,-40.877995,0.018552,0.038216,0.970694,2.005895,0.102185,9.706943,-40.877995,0.971787,0.000000
58.990002,0.540680,-40.877995,0.018768,0.038416,0.975767,2.405064,0.122520,9.757675,-40.877995,0.977129,0.000000
59.310001,0.660591,-40.877995,0.018979,0.038630,0.981214,2.938456,0.149692,9.812140,-40.877995,0.982454,0.000000
59.630001,0.550735,-40.922474,0.019018,-0.000000,-0.000000,2.449794,0.124798,-0.000000,-40.922474,0.000226,0.000000
59.950005,0.648674,-40.966957,0.019035,-0.000000,-0.000000,2.885446,0.146992,-0.000000,-40.966957,0.000330,0.000000
60.270004,0.625587,-40.922474,0.019031,-0.000000,-0.000000,2.782752,0.141760,-0.000000,-40.922474,0.000859,0.000000
60.590004,0.682182,-40.877995,0.019048,0.000020,0.000512,3.034498,0.154585,0.005117,-40.877995,0.001396,0.000000
60.910004,0.701920,-40.877995,0.019031,0.000033,0.000850,3.122294,0.159057,0.008501,-40.877995,0.001925,0.000000
61.230003,0.755539,-40.877995,0.019027,0.000060,0.001535,3.360805,0.171208,0.015352,-40.877995,0.002463,0.000000
61.550003,0.777138,-40.966957,0.019057,0.000081,0.002047,3.456881,0.176102,0.020469,-40.966957,0.002992,0.000000
61.870003,0.760384,-40.922474,0.019091,0.000099,0.002506,3.382355,0.172305,0.025064,-40.922474,0.003530,0.000000
62.190002,0.781235,-40.922474,0.019113,0.000118,0.002992,3.475106,0.177030,0.029920,-40.922474,0.004059,0.000000
62.510002,0.826294,-40.833511,0.019126,0.000144,0.003669,3.675539,0.187241,0.036687,-40.833511,0.004596,0.000000
62.830002,0.821083,-40.877995,0.019143,0.000154,0.003911,3.652360,0.186060,0.039113,-40.877995,0.005126,0.000000
63.150002,0.869858,-40.966957,0.019117,0.000183,0.004640,3.869321,0.197113,0.046399,-40.966957,0.005663,0.000000
63.470001,0.916039,-40.966957,0.019165,0.000206,0.005238,4.074743,0.207577,0.052383,-40.966957,0.006192,0.000000
63.790005,0.916405,-40.877995,0.019203,0.000222,0.005637,4.076372,0.207660,0.056372,-40.877995,0.006730,0.000000
64.110001,0.968536,-40.922474,0.019208,0.000243,0.006183,4.308265,0.219473,0.061834,-40.922474,0.007259,0.000000
64.430000,0.992371,-40.922474,0.019225,0.000265,0.006739,4.414285,0.224874,0.067386,-40.922474,0.007797,0.000000
64.750000,1.014343,-40.966957,0.019225,0.000280,0.007120,4.512024,0.229853,0.071201,-40.966957,0.008326,0.000000
65.070000,1.088440,-40.966957,0.019255,0.000309,0.007840,4.841623,0.246644,0.078400,-40.966957,0.008863,0.000000
65.389999,1.113396,-40.922474,0.019281,0.000331,0.008412,4.952631,0.252299,0.084123,-40.922474,0.009392,0.000000
65.710007,1.134987,-40.922474,0.019307,0.000351,0.008915,5.048674,0.257192,0.089153,-40.922474,0.009930,0.000000
66.030006,1.200897,-40.877995,0.019307,0.000373,0.009470,5.341857,0.272127,0.094702,-40.877995,0.010459,0.000000
66.350006,1.228455,-40.922474,0.019337,0.000393,0.009973,5.464439,0.278372,0.099732,-40.922474,0.010997,0.000000
66.670006,1.263084,-41.011436,0.019363,0.000408,0.010372,5.618480,0.286219,0.103721,-41.011436,0.011526,0.000000
66.990005,1.305534,-40.877995,0.019363,0.000420,0.010658,5.807307,0.295838,0.106583,-40.877995,0.012063,0.000000
67.310005,1.408684,-40.877995,0.019410,0.000458,0.011621,6.266139,0.319212,0.116211,-40.877995,0.012592,0.000000
67.630005,1.428795,-40.877995,0.019432,0.000476,0.012081,6.355597,0.323770,0.120806,-40.877995,0.013130,0.000000
67.950005,1.487999,-40.922474,0.019449,0.000492,0.012488,6.618950,0.337185,0.124883,-40.922474,0.013659,0.000000
68.270004,1.566200,-40.922474,0.019449,0.000518,0.013156,6.966807,0.354906,0.131559,-40.922474,0.014197,0.000000
68.590004,1.600082,-40.966957,0.019484,0.000533,0.013546,7.117522,0.362584,0.135461,-40.966957,0.014726,0.000000
68.910004,1.675674,-40.922474,0.019475,0.000554,0.014067,7.453772,0.379713,0.140666,-40.922474,0.015263,0.000000
69.230003,1.755363,-40.966957,0.019497,0.000583,0.014812,7.808247,0.397771,0.148122,-40.966957,0.015792,0.000000
69.550003,1.763184,-40.966957,0.019548,0.000601,0.015263,7.843032,0.399543,0.152633,-40.966957,0.016330,0.000000
69.870003,1.852921,-40.966957,0.019535,0.000619,0.015723,8.242202,0.419878,0.157228,-40.966957,0.016859,0.000000
70.190002,1.911385,-40.966957,0.019583,0.000639,0.016235,8.502263,0.433126,0.162345,-40.966957,0.017397,0.000000
70.510002,2.000008,-40.922474,0.019617,0.000660,0.016755,8.896479,0.453208,0.167550,-40.922474,0.017926,0.000000
70.830002,2.020119,-40.922474,0.019600,0.000678,0.017232,8.985937,0.457765,0.172319,-40.922474,0.018463,0.000000
71.150002,2.151566,-40.966957,0.019652,0.000709,0.018021,9.570642,0.487552,0.180210,-40.966957,0.018992,0.000000
71.470001,2.141884,-40.922474,0.019682,0.000726,0.018446,9.527575,0.485358,0.184461,-40.922474,0.019530,0.000000
71.790001,2.183594,-41.011436,0.019717,0.000744,0.018889,9.713110,0.494809,0.188885,-41.011436,0.020059,0.000000
72.110001,2.384300,-40.966957,0.019725,0.000769,0.019530,10.605897,0.540290,0.195301,-40.966957,0.020597,0.000000
72.430000,2.363449,-40.922474,0.019738,0.000786,0.019973,10.513146,0.535565,0.199725,-40.922474,0.021126,0.000000
72.750000,2.496010,-40.922474,0.019747,0.000812,0.020623,11.102806,0.565604,0.206228,-40.922474,0.021664,0.000000
73.070000,2.550751,-40.966957,0.019781,0.000833,0.021169,11.346306,0.578008,0.211693,-40.966957,0.022192,0.000000
73.390007,2.607353,-40.966957,0.019803,0.000852,0.021629,11.598086,0.590835,0.216288,-40.966957,0.022730,0.000000
73.710007,2.612564,-40.966957,0.019855,0.000870,0.022088,11.621265,0.592016,0.220883,-40.966957,0.023259,0.000000
74.030006,2.774170,-40.966957,0.019855,0.000896,0.022765,12.340124,0.628636,0.227650,-40.966957,0.023797,0.000000
74.350006,2.842316,-40.966957,0.019859,0.000912,0.023155,12.643251,0.644078,0.231552,-40.966957,0.024326,0.000000
74.670006,2.974510,-40.966957,0.019893,0.000934,0.023736,13.231282,0.674034,0.237362,-40.966957,0.024863,0.000000
74.990005,3.179314,-41.011436,0.019924,0.000962,0.024430,14.142294,0.720443,0.244300,-41.011436,0.025392,0.000000
75.310005,3.155113,-40.966957,0.019928,0.000976,0.024794,14.034644,0.714959,0.247941,-40.966957,0.025930,0.000000
75.630005,3.239265,-40.922474,0.019941,0.000994,0.025237,14.408973,0.734028,0.252365,-40.922474,0.026459,0.000000
75.950005,3.499931,-40.966957,0.019962,0.001019,0.025887,15.568472,0.793096,0.258868,-40.966957,0.026997,0.000000
76.270004,3.657066,-40.966957,0.019984,0.001038,0.026372,16.267443,0.828703,0.263724,-40.966957,0.027526,0.000000
76.590004,3.759468,-40.966957,0.020001,0.001054,0.026780,16.722950,0.851908,0.267800,-40.966957,0.028063,0.000000
76.910004,4.061096,-40.966957,0.020036,0.001081,0.027456,18.064657,0.920258,0.274564,-40.966957,0.028593,0.000000
77.230003,4.159401,-40.922474,0.020044,0.001099,0.027925,18.501940,0.942534,0.279250,-40.922474,0.029130,0.000000
77.550003,4.330688,-41.011436,0.020053,0.001119,0.028419,19.263865,0.981348,0.284193,-41.011436,0.029659,0.000000
77.870003,4.753334,-41.011436,0.020096,0.001148,0.029156,21.143887,1.077121,0.291562,-41.011436,0.030197,0.000000
78.190002,4.858711,-40.966957,0.020113,0.001162,0.029512,21.612627,1.101000,0.295120,-40.966957,0.030726,0.000000
78.510002,5.194595,-40.922474,0.020139,0.001184,0.030067,23.106714,1.177112,0.300668,-40.922474,0.031264,0.000000
78.830002,5.469780,-41.011436,0.020139,0.001205,0.030613,24.330797,1.239470,0.306134,-41.011436,0.031793,0.000000
79.150002,5.758736,-41.011436,0.020165,0.001226,0.031151,25.616135,1.304948,0.311508,-41.011436,0.032330,0.000000
79.470001,5.953117,-41.055920,0.020187,0.001244,0.031602,26.480789,1.348996,0.316020,-41.055920,0.032859,0.000000
79.790001,6.354538,-41.011436,0.020225,0.001269,0.032235,28.266397,1.439959,0.322348,-41.011436,0.033397,0.000000
80.110001,6.739571,-40.966957,0.020234,0.001290,0.032773,29.979107,1.527209,0.327726,-40.966957,0.033926,0.000000
80.430000,6.917564,-40.922474,0.020260,0.001306,0.033172,30.770863,1.567542,0.331716,-40.922474,0.034464,0.000000
80.750008,7.537933,-41.011436,0.020256,0.001335,0.033917,33.530403,1.708120,0.339172,-41.011436,0.034993,0.000000
81.070007,7.794868,-40.966957,0.020316,0.001353,0.034360,34.673306,1.766342,0.343597,-40.966957,0.035530,0.000000
81.390007,8.106178,-41.011436,0.020312,0.001375,0.034932,36.058083,1.836886,0.349319,-41.011436,0.036059,0.000000
81.710007,8.333694,-41.011436,0.020355,0.001391,0.035331,37.070126,1.888442,0.353309,-41.011436,0.036597,0.000000
82.030006,8.984978,-41.011436,0.020363,0.001419,0.036042,39.967178,2.036025,0.360420,-41.011436,0.037126,0.000000
82.350006,9.206535,-41.011436,0.020381,0.001433,0.036389,40.952713,2.086231,0.363891,-41.011436,0.037664,0.000000
82.670006,9.954262,-40.966957,0.020415,0.001461,0.037109,44.278767,2.255668,0.371086,-40.966957,0.038193,0.000000
82.990005,10.332962,-41.055920,0.020424,0.001485,0.037724,45.963310,2.341483,0.377244,-41.055920,0.038730,0.000000
83.310005,10.531067,-41.011436,0.020471,0.001502,0.038158,46.844524,2.386374,0.381582,-41.011436,0.039260,0.000000
83.630005,10.840881,-41.011436,0.020497,0.001521,0.038635,48.222649,2.456579,0.386351,-41.011436,0.039797,0.000000
83.950005,11.508545,-41.011436,0.020519,0.001546,0.039277,51.192566,2.607874,0.392770,-41.011436,0.040326,0.000000
84.270004,11.534981,-41.011436,0.020519,0.001558,0.039580,51.310158,2.613864,0.395802,-41.011436,0.040864,0.000000
84.590004,12.622681,-41.055920,0.020540,0.001591,0.040413,56.148487,2.860340,0.404128,-41.055920,0.041393,0.000000
84.910004,12.712425,-41.011436,0.020570,0.001608,0.040838,56.547691,2.880677,0.408379,-41.011436,0.041931,0.000000
85.230003,13.125381,-40.966957,0.020600,0.001628,0.041341,58.384613,2.974254,0.413409,-40.966957,0.042460,0.000000
85.550003,13.709267,-41.011436,0.020600,0.001653,0.041982,60.981865,3.106564,0.419824,-41.011436,0.042997,0.000000
85.870003,13.952797,-41.055920,0.020644,0.001668,0.042373,62.065140,3.161749,0.423727,-41.055920,0.043526,0.000000
86.190002,14.215317,-41.055920,0.020656,0.001683,0.042737,63.232887,3.221237,0.427371,-41.055920,0.044064,0.000000
86.510002,15.260193,-41.011436,0.020656,0.001717,0.043613,67.880730,3.458009,0.436130,-41.011436,0.044593,0.000000
86.830002,15.408768,-41.011436,0.020687,0.001733,0.044021,68.541618,3.491677,0.440206,-41.011436,0.045131,0.000000
87.150002,15.947968,-40.966957,0.020708,0.001756,0.044610,70.940102,3.613861,0.446103,-40.966957,0.045659,0.000000
87.470001,16.481949,-41.055920,0.020747,0.001779,0.045191,73.315369,3.734863,0.451913,-41.055920,0.046197,0.000000
87.790001,16.734421,-41.100399,0.020760,0.001797,0.045634,74.438423,3.792074,0.456337,-41.100399,0.046726,0.000000
88.110001,16.943321,-41.055920,0.020760,0.001809,0.045954,75.367661,3.839411,0.459543,-41.055920,0.047264,0.000000
88.430008,17.855255,-41.055920,0.020782,0.001840,0.046726,79.424141,4.046059,0.467264,-41.055920,0.047793,0.000000
88.750008,18.327797,-41.011436,0.020829,0.001862,0.047307,81.526115,4.153138,0.473074,-41.011436,0.048330,0.000000
89.070007,18.734055,-41.011436,0.020838,0.001882,0.047802,83.333237,4.245197,0.478017,-41.011436,0.048860,0.000000
89.390007,18.894547,-41.100399,0.020851,0.001896,0.048157,84.047142,4.281566,0.481571,-41.100399,0.049397,0.000000
89.710007,19.863091,-41.011436,0.020863,0.001922,0.048825,88.355438,4.501040,0.488251,-41.011436,0.049926,0.000000
90.030006,20.160988,-40.966957,0.020881,0.001938,0.049224,89.680550,4.568545,0.492241,-40.966957,0.050464,0.000000
90.350006,21.335449,-41.011436,0.020898,0.001972,0.050100,94.904816,4.834682,0.500999,-41.011436,0.050993,0.000000
90.670006,21.322044,-41.055920,0.020950,0.001986,0.050447,94.845192,4.831644,0.504466,-41.055920,0.051531,0.000000
90.990005,21.691811,-41.055920,0.020941,0.002002,0.050863,96.489990,4.915435,0.508629,-41.055920,0.052060,0.000000
91.310005,22.127861,-41.055920,0.020963,0.002022,0.051357,98.429642,5.014245,0.513572,-41.055920,0.052598,0.000000
91.630005,22.917664,-41.055920,0.020997,0.002047,0.051982,101.942856,5.193217,0.519817,-41.055920,0.053126,0.000000
91.950005,23.489998,-41.011436,0.020984,0.002063,0.052407,104.488731,5.322910,0.524068,-41.011436,0.053664,0.000000
92.270004,24.260437,-41.055920,0.021006,0.002087,0.053022,107.915817,5.497494,0.530222,-41.055920,0.054193,0.000000
92.590004,25.085983,-41.055920,0.021032,0.002113,0.053682,111.588028,5.684565,0.536815,-41.055920,0.054731,0.000000
92.910004,25.473251,-41.100399,0.021066,0.002132,0.054158,113.310684,5.772321,0.541584,-41.100399,0.055260,0.000000
93.230003,25.896271,-41.011436,0.021092,0.002149,0.054583,115.192368,5.868179,0.545835,-41.011436,0.055797,0.000000
93.550003,26.840607,-41.011436,0.021088,0.002174,0.055225,119.392982,6.082168,0.552250,-41.011436,0.056326,0.000000
93.870003,27.297134,-41.100399,0.021114,0.002189,0.055607,121.423721,6.185619,0.556065,-41.100399,0.056864,0.000000
94.190002,28.195297,-41.100399,0.021109,0.002212,0.056188,125.418945,6.389146,0.561875,-41.100399,0.057393,0.000000
94.510002,28.887161,-41.100399,0.021139,0.002234,0.056751,128.496506,6.545925,0.567515,-41.100399,0.057931,0.000000
94.830002,29.639732,-41.055920,0.021165,0.002258,0.057359,131.844116,6.716459,0.573586,-41.055920,0.058460,0.000000
95.150002,30.512573,-41.055920,0.021187,0.002281,0.057948,135.726700,6.914248,0.579483,-41.055920,0.058997,0.000000
95.470001,31.371635,-41.055920,0.021204,0.002303,0.058486,139.548004,7.108914,0.584857,-41.055920,0.059527,0.000000
95.790001,31.515373,-41.144878,0.021226,0.002316,0.058824,140.187378,7.141486,0.588241,-41.144878,0.060064,0.000000
96.110008,32.472740,-41.055920,0.021230,0.002337,0.059370,144.445969,7.358428,0.593702,-41.055920,0.060593,0.000000
96.430008,33.755562,-41.011436,0.021243,0.002365,0.060064,150.152237,7.649119,0.600644,-41.011436,0.061131,0.000000
96.750008,34.372208,-41.100399,0.021256,0.002385,0.060576,152.895218,7.788854,0.605757,-41.100399,0.061660,0.000000
97.070007,34.838425,-41.055920,0.021269,0.002400,0.060966,154.969055,7.894500,0.609660,-41.055920,0.062198,0.000000
97.390007,35.931335,-41.055920,0.021303,0.002426,0.061617,159.830566,8.142157,0.616166,-41.055920,0.062727,0.000000
97.710007,36.378929,-41.100399,0.021303,0.002439,0.061946,161.821564,8.243584,0.619462,-41.100399,0.063264,0.000000
98.030006,37.147507,-41.055920,0.021308,0.002457,0.062397,165.240356,8.417746,0.623970,-41.055920,0.063793,0.000000
98.350006,38.353615,-41.055920,0.021333,0.002486,0.063134,170.605392,8.691053,0.631343,-41.055920,0.064331,0.000000
98.670006,39.250290,-41.055920,0.021342,0.002507,0.063672,174.594009,8.894242,0.636718,-41.055920,0.064860,0.000000
98.990005,39.995033,-41.100399,0.021346,0.002525,0.064132,177.906799,9.063004,0.641316,-41.100399,0.065398,0.000000
99.310005,41.297966,-41.055920,0.021368,0.002551,0.064791,183.702530,9.358253,0.647906,-41.055920,0.065927,0.000000
99.630005,41.662521,-41.055920,0.021385,0.002564,0.065138,185.324158,9.440863,0.651377,-41.055920,0.066464,0.000000
99.950005,42.816132,-41.011436,0.021398,0.002586,0.065675,190.455658,9.702273,0.656751,-41.011436,0.066993,0.000000
100.270004,44.072144,-41.055920,0.021415,0.002613,0.066360,196.042679,9.986890,0.663602,-41.055920,0.067531,0.000000
100.590004,44.610596,-41.144878,0.021398,0.002626,0.066699,198.437836,10.108906,0.666986,-41.144878,0.068060,0.000000
100.910004,45.515083,-41.100399,0.021424,0.002646,0.067210,202.461197,10.313866,0.672103,-41.100399,0.068598,0.000000
101.230003,47.227257,-41.055920,0.021450,0.002676,0.067973,210.077332,10.701850,0.679733,-41.055920,0.069127,0.000000
101.550003,47.914650,-41.100399,0.021458,0.002693,0.068407,213.135010,10.857615,0.684071,-41.100399,0.069664,0.000000
101.870003,48.782280,-41.055920,0.021450,0.002711,0.068858,216.994415,11.054223,0.688578,-41.055920,0.070194,0.000000
102.190002,50.791229,-41.144878,0.021463,0.002745,0.069716,225.930664,11.509457,0.697163,-41.144878,0.070731,0.000000
102.510002,51.115570,-41.100399,0.021476,0.002760,0.070115,227.373413,11.582954,0.701152,-41.100399,0.071260,0.000000
102.830002,52.266197,-41.100399,0.021497,0.002778,0.070566,232.491653,11.843690,0.705663,-41.100399,0.071798,0.000000
103.150002,53.713982,-41.100399,0.021489,0.002806,0.071260,238.931717,12.171762,0.712601,-41.100399,0.072327,0.000000
103.470001,54.488518,-41.100399,0.021523,0.002823,0.071694,242.377029,12.347275,0.716939,-41.100399,0.072865,0.000000
103.790009,55.158417,-41.100399,0.021536,0.002837,0.072067,245.356888,12.499076,0.720667,-41.100399,0.073394,0.000000
104.110008,57.092888,-41.189362,0.021523,0.002869,0.072882,253.961853,12.937433,0.728819,-41.189362,0.073931,0.000000
104.430008,57.985466,-41.100399,0.021536,0.002886,0.073298,257.932220,13.139695,0.732979,-41.100399,0.074460,0.000000
104.750008,59.203499,-41.100399,0.021553,0.002908,0.073871,263.350311,13.415705,0.738706,-41.100399,0.074998,0.000000
105.070007,60.558929,-41.100399,0.021583,0.002932,0.074478,269.379578,13.722850,0.744776,-41.100399,0.075527,0.000000
105.390007,61.290642,-41.100399,0.021571,0.002948,0.074885,272.634399,13.888658,0.748853,-41.100399,0.076065,0.000000
105.710007,61.962029,-41.144878,0.021588,0.002962,0.075241,275.620880,14.040796,0.752407,-41.144878,0.076593,0.000000
106.030006,64.318398,-41.144878,0.021571,0.002997,0.076125,286.102509,14.574757,0.761252,-41.144878,0.077131,0.000000
106.350006,65.066505,-41.055920,0.021583,0.003011,0.076481,289.430267,14.744281,0.764806,-41.055920,0.077669,0.000000
106.670006,65.903969,-41.100399,0.021601,0.003029,0.076932,293.155487,14.934053,0.769318,-41.100399,0.078198,0.000000
106.990005,67.572197,-41.144878,0.021609,0.003044,0.077313,300.576141,15.312079,0.773133,-41.144878,0.077573,0.000000
107.310005,66.930977,-41.144878,0.021635,0.003041,0.077253,297.723846,15.166776,0.772527,-41.144878,0.077313,0.000000
107.630005,66.453209,-41.144878,0.021635,0.003035,0.077096,295.598633,15.058513,0.770964,-41.144878,0.077313,0.000000
107.950005,66.100578,-41.144878,0.021622,0.003035,0.077088,294.030060,14.978605,0.770877,-41.144878,0.077313,0.000000
108.270004,65.837318,-41.100399,0.021622,0.003035,0.077088,292.859009,14.918950,0.770877,-41.100399,0.077313,0.000000
108.590004,65.613518,-41.100399,0.021609,0.003035,0.077088,291.863495,14.868236,0.770877,-41.100399,0.077313,0.000000
108.910004,65.413551,-41.144878,0.021622,0.003035,0.077088,290.973999,14.822923,0.770877,-41.144878,0.077313,0.000000
109.230003,65.253059,-41.100399,0.021631,0.003035,0.077088,290.260101,14.786554,0.770877,-41.100399,0.077313,0.000000
109.550003,65.096657,-41.100399,0.021644,0.003035,0.077088,289.564392,14.751113,0.770877,-41.100399,0.077313,0.000000
109.870003,64.977135,-41.144878,0.021618,0.003035,0.077088,289.032745,14.724030,0.770877,-41.144878,0.077313,0.000000
110.190002,64.830040,-41.144878,0.021657,0.003035,0.077088,288.378418,14.690697,0.770877,-41.144878,0.077313,0.000000
110.510002,64.728752,-41.144878,0.021605,0.003035,0.077088,287.927856,14.667746,0.770877,-41.144878,0.077313,0.000000
110.830002,64.623375,-41.144878,0.021640,0.003035,0.077088,287.459137,14.643867,0.770877,-41.144878,0.077313,0.000000
111.150002,64.526558,-41.100399,0.021631,0.003035,0.077088,287.028473,14.621927,0.770877,-41.100399,0.077313,0.000000
111.470009,64.436440,-41.144878,0.021648,0.003035,0.077088,286.627594,14.601506,0.770877,-41.144878,0.077313,0.000000
111.790009,64.358253,-41.144878,0.021665,0.003035,0.077088,286.279816,14.583789,0.770877,-41.144878,0.077313,0.000000
112.110008,64.275215,-41.144878,0.021644,0.003035,0.077088,285.910431,14.564972,0.770877,-41.144878,0.077313,0.000000
112.430008,64.205574,-41.144878,0.021661,0.003035,0.077088,285.600647,14.549191,0.770877,-41.144878,0.077313,0.000000
112.750008,64.126259,-41.144878,0.021652,0.003035,0.077088,285.247833,14.531218,0.770877,-41.144878,0.077313,0.000000
113.070007,64.070412,-41.100399,0.021644,0.003035,0.077088,284.999420,14.518563,0.770877,-41.100399,0.077313,0.000000
113.390007,64.002266,-41.100399,0.021635,0.003035,0.077088,284.696289,14.503120,0.770877,-41.100399,0.077313,0.000000
113.710007,63.947517,-41.189362,0.021661,0.003035,0.077088,284.452759,14.490714,0.770877,-41.189362,0.077313,0.000000
114.030006,63.887947,-41.189362,0.021648,0.003035,0.077088,284.187775,14.477216,0.770877,-41.189362,0.077313,0.000000
114.350006,63.839165,-41.144878,0.021652,0.003035,0.077088,283.970795,14.466162,0.770877,-41.144878,0.077313,0.000000
114.670006,63.800438,-41.100399,0.021648,0.003035,0.077088,283.798523,14.457385,0.770877,-41.100399,0.077313,0.000000
114.990005,63.737129,-41.100399,0.021657,0.003035,0.077088,283.516907,14.443040,0.770877,-41.100399,0.077313,0.000000
115.310005,63.703621,-41.189362,0.021661,0.003035,0.077088,283.367859,14.435447,0.770877,-41.189362,0.077313,0.000000
115.630005,63.641426,-41.144878,0.021652,0.003035,0.077088,283.091217,14.421353,0.770877,-41.144878,0.077313,0.000000
115.950005,63.603447,-41.189362,0.021665,0.003035,0.077088,282.922272,14.412747,0.770877,-41.189362,0.077313,0.000000
116.270004,63.558022,-41.144878,0.021670,0.003035,0.077088,282.720215,14.402453,0.770877,-41.144878,0.077313,0.000000
116.590004,63.512215,-41.144878,0.021648,0.003035,0.077088,282.516449,14.392074,0.770877,-41.144878,0.077313,0.000000
116.910004,63.482796,-41.189362,0.021644,0.003035,0.077088,282.385590,14.385407,0.770877,-41.189362,0.077313,0.000000
117.230003,63.440720,-41.144878,0.021652,0.003035,0.077088,282.198425,14.375873,0.770877,-41.144878,0.077313,0.000000
117.550003,63.402740,-41.144878,0.021640,0.003035,0.077088,282.029480,14.367266,0.770877,-41.144878,0.077313,0.000000
117.870003,63.359917,-41.100399,0.021640,0.003035,0.077088,281.838989,14.357562,0.770877,-41.100399,0.077313,0.000000
118.190002,63.342789,-41.144878,0.021631,0.003035,0.077088,281.762787,14.353681,0.770877,-41.144878,0.077313,0.000000
118.510002,63.314117,-41.189362,0.021644,0.003035,0.077088,281.635254,14.347184,0.770877,-41.189362,0.077313,0.000000
118.830002,63.266823,-41.144878,0.021652,0.003035,0.077088,281.424896,14.336467,0.770877,-41.144878,0.077313,0.000000
119.150009,63.231453,-41.233841,0.021661,0.003035,0.077088,281.267548,14.328452,0.770877,-41.233841,0.077313,0.000000
119.470009,63.212456,-41.189362,0.021678,0.003035,0.077088,281.183044,14.324147,0.770877,-41.189362,0.077313,0.000000
119.790009,63.180435,-41.189362,0.021640,0.003035,0.077088,281.040619,14.316892,0.770877,-41.189362,0.077313,0.000000
120.110008,63.150269,-41.189362,0.021661,0.003035,0.077088,280.906433,14.310056,0.770877,-41.189362,0.077313,0.000000
120.430008,63.123093,-41.189362,0.021665,0.003035,0.077088,280.785553,14.303898,0.770877,-41.189362,0.077313,0.000000
120.750008,63.084732,-41.189362,0.021648,0.003035,0.077088,280.614899,14.295204,0.770877,-41.189362,0.077313,0.000000
121.070007,63.071701,-41.189362,0.021674,0.003035,0.077088,280.556946,14.292252,0.770877,-41.189362,0.077313,0.000000
121.390007,63.037445,-41.189362,0.021644,0.003035,0.077088,280.404572,14.284489,0.770877,-41.189362,0.077313,0.000000
121.710007,63.006912,-41.189362,0.021652,0.003035,0.077088,280.268738,14.277570,0.770877,-41.189362,0.077313,0.000000
122.030006,62.988289,-41.278324,0.021661,0.003035,0.077088,280.185913,14.273351,0.770877,-41.278324,0.077313,0.000000
122.350006,62.961105,-41.233841,0.021648,0.003035,0.077088,280.064972,14.267190,0.770877,-41.233841,0.077313,0.000000
122.670006,62.942490,-41.189362,0.021661,0.003035,0.077088,279.982178,14.262972,0.770877,-41.189362,0.077313,0.000000
122.990005,62.919403,-41.144878,0.021648,0.003035,0.077088,279.879486,14.257740,0.770877,-41.144878,0.077313,0.000000
123.310005,62.896317,-41.189362,0.021665,0.003035,0.077088,279.776794,14.252509,0.770877,-41.189362,0.077313,0.000000
123.630005,62.869507,-41.189362,0.021657,0.003035,0.077088,279.657532,14.246434,0.770877,-41.189362,0.077313,0.000000
123.950005,62.846413,-41.189362,0.021661,0.003035,0.077088,279.554810,14.241200,0.770877,-41.189362,0.077313,0.000000
124.270004,62.823700,-41.233841,0.021648,0.003035,0.077088,279.453766,14.236053,0.770877,-41.233841,0.077313,0.000000
124.590004,62.799500,-41.144878,0.021661,0.003035,0.077088,279.346130,14.230571,0.770877,-41.144878,0.077313,0.000000
124.910004,62.789444,-41.233841,0.021635,0.003035,0.077088,279.301392,14.228292,0.770877,-41.233841,0.077313,0.000000
125.230003,62.768219,-41.189362,0.021640,0.003035,0.077088,279.206970,14.223482,0.770877,-41.189362,0.077313,0.000000
125.550003,62.739174,-41.322803,0.021657,0.003035,0.077088,279.077789,14.216900,0.770877,-41.322803,0.077313,0.000000
125.870003,62.733589,-41.233841,0.021670,0.003035,0.077088,279.052948,14.215634,0.770877,-41.233841,0.077313,0.000000
126.190002,62.704170,-41.189362,0.021670,0.003035,0.077088,278.922089,14.208968,0.770877,-41.189362,0.077313,0.000000
126.510010,62.685555,-41.144878,0.021648,0.003035,0.077088,278.839264,14.204749,0.770877,-41.144878,0.077313,0.000000
126.830009,62.664696,-41.278324,0.021665,0.003035,0.077088,278.746490,14.200024,0.770877,-41.278324,0.077313,0.000000
127.150009,62.657997,-41.233841,0.021665,0.003035,0.077088,278.716705,14.198505,0.770877,-41.233841,0.077313,0.000000
127.470009,62.624481,-41.189362,0.021648,0.003035,0.077088,278.567596,14.190910,0.770877,-41.189362,0.077313,0.000000
127.790009,62.612938,-41.233841,0.021640,0.003035,0.077088,278.516266,14.188294,0.770877,-41.233841,0.077313,0.000000
128.110001,62.606239,-41.233841,0.021670,0.003035,0.077088,278.486450,14.186777,0.770877,-41.233841,0.077313,0.000000
128.430008,62.571236,-41.189362,0.021691,0.003035,0.077088,278.330750,14.178844,0.770877,-41.189362,0.077313,0.000000
128.750000,62.549637,-41.233841,0.021640,0.003035,0.077088,278.234680,14.173950,0.770877,-41.233841,0.077313,0.000000
129.070007,62.542931,-41.278324,0.021674,0.003035,0.077088,278.204865,14.172430,0.770877,-41.278324,0.077313,0.000000
129.389999,62.522827,-41.278324,0.021670,0.003035,0.077088,278.115417,14.167875,0.770877,-41.278324,0.077313,0.000000
129.710007,62.513885,-41.189362,0.021670,0.003035,0.077088,278.075653,14.165849,0.770877,-41.189362,0.077313,0.000000
130.029999,62.492287,-41.189362,0.021674,0.003035,0.077088,277.979584,14.160954,0.770877,-41.189362,0.077313,0.000000
130.350006,62.482979,-41.278324,0.021648,0.003035,0.077088,277.938171,14.158846,0.770877,-41.278324,0.077313,0.000000
130.670013,62.453934,-41.278324,0.021670,0.003035,0.077088,277.808960,14.152264,0.770877,-41.278324,0.077313,0.000000
130.990005,62.447975,-41.278324,0.021670,0.003035,0.077088,277.782471,14.150914,0.770877,-41.278324,0.077313,0.000000
131.310013,62.424149,-41.233841,0.021665,0.003035,0.077088,277.676483,14.145514,0.770877,-41.233841,0.077313,0.000000
131.630005,62.423027,-41.233841,0.021657,0.003035,0.077088,277.671478,14.145260,0.770877,-41.233841,0.077313,0.000000
131.950012,62.405899,-41.278324,0.021661,0.003035,0.077088,277.595306,14.141378,0.770877,-41.278324,0.077313,0.000000
132.270004,62.395470,-41.278324,0.021652,0.003035,0.077088,277.548920,14.139015,0.770877,-41.278324,0.077313,0.000000
132.590012,62.373131,-41.233841,0.021674,0.003035,0.077088,277.449554,14.133953,0.770877,-41.233841,0.077313,0.000000
132.910004,62.360474,-41.233841,0.021657,0.003035,0.077088,277.393250,14.131085,0.770877,-41.233841,0.077313,0.000000
133.230011,62.348930,-41.189362,0.021665,0.003035,0.077088,277.341888,14.128470,0.770877,-41.189362,0.077313,0.000000
133.550003,62.330307,-41.278324,0.021670,0.003035,0.077088,277.259064,14.124249,0.770877,-41.278324,0.077313,0.000000
133.870010,62.322861,-41.278324,0.021683,0.003035,0.077088,277.225922,14.122561,0.770877,-41.278324,0.077313,0.000000
134.190002,62.299026,-41.278324,0.021661,0.003035,0.077088,277.119904,14.117161,0.770877,-41.278324,0.077313,0.000000
134.510010,62.304611,-41.322803,0.021657,0.003035,0.077088,277.144745,14.118426,0.770877,-41.322803,0.077313,0.000000
134.830002,62.284134,-41.233841,0.021648,0.003035,0.077088,277.053650,14.113787,0.770877,-41.233841,0.077313,0.000000
135.150009,62.274078,-41.233841,0.021648,0.003035,0.077088,277.008942,14.111508,0.770877,-41.233841,0.077313,0.000000
135.470001,62.254341,-41.278324,0.021657,0.003035,0.077088,276.921143,14.107035,0.770877,-41.278324,0.077313,0.000000
135.790009,62.242058,-41.278324,0.021657,0.003035,0.077088,276.866486,14.104252,0.770877,-41.278324,0.077313,0.000000
136.110001,62.231628,-41.278324,0.021683,0.003035,0.077088,276.820099,14.101889,0.770877,-41.278324,0.077313,0.000000
136.430008,62.221573,-41.233841,0.021670,0.003035,0.077088,276.775391,14.099609,0.770877,-41.233841,0.077313,0.000000
136.750000,62.202583,-41.322803,0.021661,0.003035,0.077088,276.690918,14.095306,0.770877,-41.322803,0.077313,0.000000
137.070007,62.195137,-41.278324,0.021657,0.003035,0.077088,276.657776,14.093620,0.770877,-41.278324,0.077313,0.000000
137.389999,62.181732,-41.278324,0.021657,0.003035,0.077088,276.598145,14.090582,0.770877,-41.278324,0.077313,0.000000
137.400009,62.185455,-41.278324,0.021648,0.003035,0.077088,276.614716,14.091426,0.770877,-41.278324,0.077313,0.000000