File: Data/Polished Pin I-18 - 2_08162023_161036.csv
Time (sec),S:Load (lbs),S:HL1 (DIM),S:LVDT (in),S:Position (in),Ch:Position (mm),Ch:Load (N),Ch:Stress (MPa),Ch:Strain (mm/mm),Ch:HL1 (DIM),Set Point (),Cycles ()
0.110000,-0.005213,-38.031212,0.000000,-0.000000,-0.000000,-0.023189,-0.001181,-0.000000,-38.031212,0.000208,0.000000
0.300000,-0.008565,-38.031212,-0.000039,-0.000000,-0.000000,-0.038097,-0.001941,-0.000000,-38.031212,0.000208,0.000000
0.490000,-0.012288,-38.075695,0.000000,0.000056,0.001414,-0.054661,-0.002785,0.014140,-38.075695,0.002012,0.000000
0.680000,0.032769,-38.075695,0.000004,0.000161,0.004094,0.145763,0.007426,0.040937,-38.075695,0.005186,0.000000
0.870000,0.045802,-38.120174,0.000022,0.000281,0.007129,0.203737,0.010379,0.071292,-38.120174,0.008343,0.000000
1.060000,0.043195,-38.075695,0.000194,0.000410,0.010407,0.192142,0.009788,0.104069,-38.075695,0.011517,0.000000
1.250000,0.035375,-38.075695,0.000319,0.000538,0.013659,0.157358,0.008016,0.136589,-38.075695,0.014674,0.000000
1.440000,0.047291,-38.075695,0.000457,0.000659,0.016747,0.210362,0.010716,0.167466,-38.075695,0.017848,0.000000
1.630000,0.028673,-37.986732,0.000582,0.000784,0.019912,0.127543,0.006497,0.199116,-37.986732,0.021005,0.000000
1.820000,0.015267,-38.120174,0.000729,0.000909,0.023086,0.067912,0.003460,0.230856,-38.120174,0.024179,0.000000
2.010000,0.007447,-38.031212,0.000862,0.001030,0.026164,0.033128,0.001688,0.261642,-38.031212,0.027335,0.000000
2.200000,0.010054,-38.120174,0.001013,0.001158,0.029408,0.044723,0.002278,0.294079,-38.120174,0.030509,0.000000
2.390000,0.010426,-38.164658,0.001155,0.001281,0.032539,0.046379,0.002363,0.325387,-38.164658,0.033666,0.000000
2.580000,0.053994,-38.120174,0.001263,0.001404,0.035652,0.240177,0.012235,0.356522,-38.120174,0.036840,0.000000
2.770000,0.047664,-38.120174,0.001393,0.001526,0.038766,0.212019,0.010801,0.387657,-38.120174,0.039996,0.000000
2.960000,0.061069,-38.164658,0.001522,0.001648,0.041853,0.271649,0.013838,0.418526,-38.164658,0.043171,0.000000
3.150000,0.044312,-38.075695,0.001643,0.001772,0.045018,0.197111,0.010041,0.450183,-38.075695,0.046328,0.000000
3.340000,0.043940,-38.164658,0.001768,0.001900,0.048253,0.195455,0.009957,0.482529,-38.164658,0.049502,0.000000
3.530000,0.064793,-38.120174,0.001893,0.002028,0.051505,0.288213,0.014682,0.515049,-38.120174,0.052658,0.000000
3.720000,0.048781,-38.120174,0.002009,0.002152,0.054653,0.216988,0.011054,0.546531,-38.120174,0.055832,0.000000
3.910000,0.034631,-38.120174,0.002147,0.002273,0.057732,0.154045,0.007847,0.577318,-38.120174,0.058989,0.000000
4.100000,0.032024,-38.120174,0.002281,0.002403,0.061027,0.142450,0.007257,0.610269,-38.120174,0.062163,0.000000
4.290000,0.031279,-38.209137,0.002427,0.002528,0.064210,0.139137,0.007088,0.642100,-38.209137,0.065320,0.000000
4.480000,0.030535,-38.164658,0.002570,0.002655,0.067427,0.135825,0.006919,0.674271,-38.164658,0.068494,0.000000
4.670000,0.054366,-38.209137,0.002669,0.002775,0.070480,0.241834,0.012320,0.704800,-38.209137,0.071650,0.000000
4.860000,0.044685,-38.253616,0.002824,0.002901,0.073689,0.198768,0.010126,0.736889,-38.253616,0.074824,0.000000
5.050000,0.045802,-38.164658,0.002940,0.003026,0.076854,0.203737,0.010379,0.768538,-38.164658,0.077981,0.000000
5.240000,0.038727,-38.209137,0.003074,0.003151,0.080037,0.172265,0.008776,0.800369,-38.209137,0.081156,0.000000
5.430000,0.037982,-38.209137,0.003212,0.003277,0.083228,0.168952,0.008607,0.832283,-38.209137,0.084312,0.000000
5.620000,0.049153,-38.164658,0.003337,0.003406,0.086515,0.218644,0.011138,0.865151,-38.164658,0.087486,0.000000
5.810000,0.036493,-38.253616,0.003458,0.003529,0.089645,0.162327,0.008269,0.896452,-38.253616,0.090643,0.000000
6.000000,0.038727,-38.253616,0.003583,0.003650,0.092698,0.172265,0.008776,0.926981,-38.253616,0.093817,0.000000
6.190000,0.040961,-38.253616,0.003704,0.003774,0.095855,0.182203,0.009282,0.958547,-38.253616,0.096974,0.000000
6.380000,0.018619,-38.298100,0.003820,0.003897,0.098994,0.082820,0.004219,0.989939,-38.298100,0.100148,0.000000
6.570000,-0.008565,-38.209137,0.003949,0.004022,0.102160,-0.038097,-0.001941,1.021596,-38.209137,0.103304,0.000000
6.760000,0.000372,-38.298100,0.004079,0.004149,0.105386,0.001656,0.000084,1.053859,-38.298100,0.106478,0.000000
6.950000,0.037237,-38.209137,0.004199,0.004272,0.108499,0.165639,0.008438,1.084993,-38.209137,0.109635,0.000000
7.140000,0.043940,-38.342579,0.004342,0.004395,0.111639,0.195455,0.009957,1.116385,-38.342579,0.112809,0.000000
7.330000,0.040216,-38.253616,0.004488,0.004522,0.114856,0.178891,0.009113,1.148557,-38.253616,0.115966,0.000000
7.520000,0.051387,-38.298100,0.004592,0.004646,0.118012,0.228583,0.011645,1.180123,-38.298100,0.119140,0.000000
7.710001,0.071868,-38.298100,0.004717,0.004770,0.121151,0.319684,0.016285,1.211515,-38.298100,0.122297,0.000000
7.900001,0.052505,-38.298100,0.004838,0.004897,0.124378,0.233552,0.011898,1.243777,-38.298100,0.125471,0.000000
8.090000,0.048408,-38.253616,0.004945,0.005020,0.127500,0.215332,0.010970,1.275002,-38.253616,0.128627,0.000000
8.280001,0.033141,-38.298100,0.005092,0.005143,0.130622,0.147419,0.007510,1.306220,-38.298100,0.131801,0.000000
8.470000,0.016384,-38.253616,0.005195,0.005269,0.133831,0.072882,0.003713,1.338309,-38.253616,0.134958,0.000000
8.660001,0.006703,-38.298100,0.005325,0.005395,0.137022,0.029815,0.001519,1.370223,-38.298100,0.138132,0.000000
8.850000,0.038354,-38.298100,0.005454,0.005518,0.140161,0.170609,0.008691,1.401615,-38.298100,0.141289,0.000000
9.040000,0.074475,-38.298100,0.005579,0.005639,0.143240,0.331279,0.016876,1.432401,-38.298100,0.144463,0.000000
9.230000,0.081177,-38.298100,0.005691,0.005768,0.146509,0.361094,0.018395,1.465095,-38.298100,0.147619,0.000000
9.420000,0.097562,-38.387062,0.005821,0.005893,0.149692,0.433976,0.022108,1.496918,-38.387062,0.150793,0.000000
9.610001,0.086018,-38.342579,0.005959,0.006021,0.152945,0.382627,0.019492,1.529446,-38.342579,0.153951,0.000000
9.800000,0.083039,-38.298100,0.006058,0.006148,0.156153,0.369376,0.018817,1.561527,-38.298100,0.157125,0.000000
9.990001,0.091976,-38.342579,0.006196,0.006270,0.159249,0.409130,0.020842,1.592487,-38.342579,0.160281,0.000000
10.180000,0.069634,-38.342579,0.006325,0.006395,0.162432,0.309746,0.015779,1.624318,-38.342579,0.163455,0.000000
10.370001,0.074475,-38.387062,0.006446,0.006520,0.165614,0.331279,0.016876,1.656141,-38.387062,0.166612,0.000000
10.560000,0.072613,-38.342579,0.006554,0.006643,0.168728,0.322997,0.016454,1.687276,-38.342579,0.169786,0.000000
10.750001,0.070378,-38.342579,0.006683,0.006767,0.171893,0.313059,0.015948,1.718933,-38.342579,0.172942,0.000000
10.940001,0.065165,-38.342579,0.006812,0.006891,0.175032,0.289869,0.014767,1.750325,-38.342579,0.176116,0.000000
11.130000,0.097189,-38.431541,0.006942,0.007011,0.178068,0.432319,0.022023,1.780680,-38.431541,0.179273,0.000000
11.320001,0.105009,-38.387062,0.007062,0.007136,0.181242,0.467103,0.023795,1.812420,-38.387062,0.182447,0.000000
11.510000,0.126234,-38.387062,0.007213,0.007258,0.184364,0.561518,0.028605,1.843637,-38.387062,0.185604,0.000000
11.700001,0.128469,-38.387062,0.007334,0.007379,0.187434,0.571456,0.029111,1.874341,-38.387062,0.188778,0.000000
11.890000,0.076709,-38.387062,0.007459,0.007506,0.190660,0.341217,0.017382,1.906603,-38.387062,0.191935,0.000000
12.080001,0.121021,-38.342579,0.007601,0.007636,0.193947,0.538328,0.027424,1.939471,-38.342579,0.195109,0.000000
12.270000,0.101658,-38.387062,0.007692,0.007760,0.197112,0.452196,0.023036,1.971120,-38.387062,0.198266,0.000000
12.460001,0.099796,-38.387062,0.007817,0.007881,0.200173,0.443914,0.022614,2.001733,-38.387062,0.201440,0.000000
12.650001,0.114691,-38.431541,0.007929,0.008009,0.203425,0.510170,0.025989,2.034252,-38.431541,0.204596,0.000000
12.840000,0.135171,-38.431541,0.008067,0.008135,0.206626,0.601272,0.030630,2.066257,-38.431541,0.207770,0.000000
13.030001,0.167568,-38.431541,0.008222,0.008261,0.209835,0.745378,0.037971,2.098346,-38.431541,0.210927,0.000000
13.220000,0.272204,-38.387062,0.008321,0.008384,0.212956,1.210825,0.061682,2.129564,-38.387062,0.214101,0.000000
13.410001,0.518342,-38.476021,0.008468,0.008508,0.216105,2.305703,0.117458,2.161046,-38.476021,0.217258,0.000000
13.600000,0.658727,-38.476021,0.008537,-0.000003,-0.000086,2.930163,0.149270,-0.000863,-38.476021,0.000113,0.000000
13.790001,0.638246,-38.520504,0.008554,-0.000004,-0.000095,2.839062,0.144629,-0.000954,-38.520504,0.000113,0.000000
13.980000,0.640481,-38.431541,0.008576,-0.000004,-0.000095,2.849000,0.145135,-0.000954,-38.431541,0.000113,0.000000
14.170001,0.665430,-38.431541,0.008567,-0.000004,-0.000095,2.959979,0.150789,-0.000954,-38.431541,0.000347,0.000000
14.360001,0.635640,-38.520504,0.008563,-0.000004,-0.000095,2.827467,0.144038,-0.000954,-38.520504,0.000668,0.000000
14.550001,0.660589,-38.520504,0.008576,0.000002,0.000044,2.938446,0.149692,0.000439,-38.520504,0.000980,0.000000
14.740001,0.724637,-38.564983,0.008563,0.000016,0.000416,3.223346,0.164205,0.004163,-38.564983,0.001301,0.000000
14.930000,0.779003,-38.431541,0.008576,0.000028,0.000712,3.465179,0.176525,0.007116,-38.431541,0.001613,0.000000
15.120001,0.856084,-38.476021,0.008576,0.000040,0.001023,3.808053,0.193991,0.010234,-38.476021,0.001934,0.000000
15.310000,0.932048,-38.520504,0.008584,0.000055,0.001397,4.145958,0.211205,0.013966,-38.520504,0.002247,0.000000
15.500001,0.991256,-38.431541,0.008589,0.000063,0.001596,4.409325,0.224622,0.015957,-38.431541,0.002567,0.000000
15.690001,1.074295,-38.520504,0.008593,0.000074,0.001874,4.778701,0.243439,0.018735,-38.520504,0.002880,0.000000
15.880001,1.187123,-38.476021,0.008597,0.000086,0.002177,5.280589,0.269006,0.021771,-38.476021,0.003201,0.000000
16.070002,1.234787,-38.476021,0.008601,0.000098,0.002489,5.492608,0.279807,0.024889,-38.476021,0.003521,0.000000
16.260000,1.369586,-38.520504,0.008623,0.000113,0.002880,6.092223,0.310353,0.028795,-38.520504,0.003833,0.000000
16.450001,1.495820,-38.520504,0.008645,0.000126,0.003209,6.653740,0.338958,0.032088,-38.520504,0.004154,0.000000
16.640001,1.567316,-38.564983,0.008649,0.000139,0.003521,6.971768,0.355159,0.035215,-38.564983,0.004466,0.000000
16.830000,1.659664,-38.564983,0.008670,0.000153,0.003886,7.382555,0.376085,0.038856,-38.564983,0.004787,0.000000
17.020000,1.746054,-38.609467,0.008649,0.000163,0.004137,7.766838,0.395662,0.041369,-38.609467,0.005100,0.000000
17.210001,1.926655,-38.520504,0.008683,0.000178,0.004510,8.570190,0.436586,0.045101,-38.520504,0.005421,0.000000
17.400002,2.052145,-38.520504,0.008688,0.000188,0.004787,9.128395,0.465023,0.047871,-38.520504,0.005733,0.000000
17.590000,2.141142,-38.520504,0.008705,0.000197,0.005013,9.524274,0.485190,0.050127,-38.520504,0.006054,0.000000
17.780001,2.223808,-38.564983,0.008705,0.000205,0.005203,9.891994,0.503922,0.052035,-38.564983,0.006365,0.000000
17.970001,2.369406,-38.520504,0.008718,0.000217,0.005507,10.539644,0.536915,0.055070,-38.520504,0.006686,0.000000
18.160002,2.697466,-38.609467,0.008727,0.000241,0.006123,11.998929,0.611255,0.061232,-38.609467,0.006999,0.000000
18.350000,2.831892,-38.564983,0.008752,0.000252,0.006400,12.596887,0.641716,0.064003,-38.564983,0.007320,0.000000
18.540001,2.905250,-38.609467,0.008748,0.000261,0.006634,12.923198,0.658339,0.066342,-38.609467,0.007632,0.000000
18.730001,3.106331,-38.564983,0.008778,0.000276,0.007016,13.817650,0.703905,0.070164,-38.564983,0.007953,0.000000
18.920000,3.249322,-38.564983,0.008765,0.000287,0.007293,14.453706,0.736307,0.072935,-38.564983,0.008265,0.000000
19.110001,3.386355,-38.609467,0.008770,0.000299,0.007597,15.063261,0.767359,0.075970,-38.609467,0.008586,0.000000
19.300001,3.666379,-38.609467,0.008787,0.000315,0.007996,16.308870,0.830813,0.079960,-38.609467,0.008898,0.000000
19.490002,3.765058,-38.609467,0.008821,0.000324,0.008222,16.747814,0.853174,0.082215,-38.609467,0.009218,0.000000
19.680000,3.889058,-38.653946,0.008813,0.000331,0.008404,17.299395,0.881273,0.084040,-38.653946,0.009531,0.000000
19.870001,4.092373,-38.653946,0.008817,0.000343,0.008716,18.203787,0.927345,0.087159,-38.653946,0.009852,0.000000
20.060001,4.274091,-38.653946,0.008834,0.000362,0.009184,19.012108,0.968523,0.091844,-38.653946,0.010164,0.000000
20.250002,4.700085,-38.609467,0.008834,0.000379,0.009627,20.907022,1.065055,0.096265,-38.609467,0.010485,0.000000
20.440001,4.811052,-38.653946,0.008847,0.000389,0.009887,21.400629,1.090200,0.098869,-38.653946,0.010798,0.000000
20.630001,5.012878,-38.609467,0.008869,0.000401,0.010173,22.298395,1.135934,0.101730,-38.609467,0.011118,0.000000
20.820002,5.183797,-38.609467,0.008869,0.000412,0.010459,23.058680,1.174665,0.104592,-38.609467,0.011430,0.000000
21.010000,5.496962,-38.698429,0.008860,0.000427,0.010849,24.451708,1.245629,0.108490,-38.698429,0.011751,0.000000
21.200001,5.635485,-38.609467,0.008912,0.000439,0.011144,25.067888,1.277019,0.111442,-38.609467,0.012063,0.000000
21.390001,5.872686,-38.653946,0.008908,0.000451,0.011456,26.123013,1.330770,0.114561,-38.653946,0.012384,0.000000
21.580002,5.986259,-38.653946,0.008912,0.000459,0.011664,26.628212,1.356506,0.116643,-38.653946,0.012705,0.000000
21.770000,6.228674,-38.609467,0.008925,0.000472,0.011985,27.706526,1.411438,0.119852,-38.609467,0.013017,0.000000
21.960001,6.553383,-38.698429,0.008933,0.000486,0.012349,29.150904,1.485018,0.123494,-38.698429,0.013338,0.000000
22.150002,6.768614,-38.653946,0.008951,0.000502,0.012757,30.108299,1.533790,0.127574,-38.653946,0.013651,0.000000
22.340000,6.990176,-38.698429,0.008942,0.000514,0.013061,31.093855,1.583996,0.130609,-38.698429,0.013972,0.000000
22.530001,7.135773,-38.698429,0.008964,0.000524,0.013303,31.741505,1.616989,0.133031,-38.698429,0.014283,0.000000
22.720001,7.345419,-38.698429,0.008972,0.000535,0.013598,32.674057,1.664496,0.135984,-38.698429,0.014604,0.000000
22.910002,7.727846,-38.787388,0.009002,0.000553,0.014040,34.375175,1.751155,0.140404,-38.787388,0.014916,0.000000
23.100000,7.849239,-38.698429,0.009002,0.000562,0.014283,34.915157,1.778663,0.142834,-38.698429,0.015237,0.000000
23.290001,8.074525,-38.742908,0.008990,0.000576,0.014622,35.917282,1.829713,0.146218,-38.742908,0.015550,0.000000
23.480001,8.173203,-38.742908,0.009020,0.000584,0.014838,36.356224,1.852074,0.148383,-38.742908,0.015871,0.000000
23.670002,8.476315,-38.698429,0.008998,0.000598,0.015194,37.704529,1.920760,0.151941,-38.698429,0.016183,0.000000
23.860001,8.868423,-38.787388,0.009020,0.000615,0.015619,39.448715,2.009613,0.156187,-38.787388,0.016504,0.000000
24.050001,9.016254,-38.698429,0.009050,0.000627,0.015914,40.106304,2.043113,0.159140,-38.698429,0.016816,0.000000
24.240002,9.189780,-38.742908,0.009050,0.000637,0.016191,40.878185,2.082434,0.161910,-38.742908,0.017136,0.000000
24.430000,9.323834,-38.698429,0.009067,0.000648,0.016451,41.474487,2.112811,0.164514,-38.698429,0.017449,0.000000
24.620001,9.541300,-38.742908,0.009076,0.000660,0.016764,42.441822,2.162090,0.167641,-38.742908,0.017769,0.000000
24.810001,9.691365,-38.787388,0.009071,0.000671,0.017033,43.109344,2.196095,0.170328,-38.787388,0.018082,0.000000
25.000002,10.048843,-38.742908,0.009123,0.000686,0.017414,44.699490,2.277101,0.174143,-38.742908,0.018403,0.000000
25.190001,10.280087,-38.698429,0.009097,0.000699,0.017744,45.728107,2.329501,0.177436,-38.698429,0.018715,0.000000
25.380001,10.336687,-38.742908,0.009119,0.000706,0.017943,45.979881,2.342327,0.179434,-38.742908,0.019036,0.000000
25.570002,10.487125,-38.742908,0.009119,0.000718,0.018230,46.649063,2.376416,0.182296,-38.742908,0.019348,0.000000
25.760002,10.888915,-38.876350,0.009132,0.000735,0.018672,48.436314,2.467463,0.186716,-38.876350,0.019669,0.000000
25.950001,11.249372,-38.787388,0.009140,0.000753,0.019114,50.039703,2.549144,0.191137,-38.787388,0.019981,0.000000
26.140001,11.370021,-38.831871,0.009171,0.000764,0.019409,50.576378,2.576484,0.194089,-38.831871,0.020302,0.000000
26.330002,11.340976,-38.876350,0.009162,0.000771,0.019591,50.447178,2.569902,0.195906,-38.876350,0.020614,0.000000
26.520000,11.583017,-38.787388,0.009175,0.000785,0.019938,51.523834,2.624749,0.199381,-38.787388,0.020935,0.000000
26.710001,11.810164,-38.787388,0.009179,0.000799,0.020285,52.534237,2.676222,0.202848,-38.787388,0.021247,0.000000
26.900002,11.919270,-38.831871,0.009196,0.000808,0.020519,53.019558,2.700945,0.205187,-38.831871,0.021568,0.000000
27.090002,12.400747,-38.787388,0.009201,0.000825,0.020952,55.161278,2.810049,0.209524,-38.787388,0.021889,0.000000
27.280001,12.582465,-38.831871,0.009214,0.000837,0.021256,55.969601,2.851227,0.212560,-38.831871,0.022201,0.000000
27.470001,12.643162,-38.876350,0.009222,0.000846,0.021490,56.239594,2.864981,0.214899,-38.876350,0.022522,0.000000
27.660002,12.926538,-38.876350,0.009248,0.000861,0.021880,57.500111,2.929195,0.218805,-38.876350,0.022834,0.000000
27.850000,13.282898,-38.787388,0.009257,0.000876,0.022262,59.085281,3.009948,0.222620,-38.787388,0.023155,0.000000
28.040001,13.386790,-38.787388,0.009257,0.000887,0.022531,59.547417,3.033490,0.225307,-38.787388,0.023467,0.000000
28.230001,13.427379,-38.920834,0.009265,0.000898,0.022799,59.727962,3.042688,0.227995,-38.920834,0.023788,0.000000
28.420002,13.673516,-38.787388,0.009278,0.000912,0.023155,60.822838,3.098463,0.231552,-38.787388,0.024101,0.000000
28.610001,13.804592,-38.876350,0.009296,0.000919,0.023346,61.405891,3.128165,0.233460,-38.876350,0.024422,0.000000
28.800001,14.099511,-38.831871,0.009300,0.000933,0.023710,62.717758,3.194995,0.237101,-38.831871,0.024734,0.000000
28.990002,14.376184,-38.876350,0.009313,0.000948,0.024074,63.948460,3.257690,0.240742,-38.876350,0.025054,0.000000
29.180002,14.554922,-38.876350,0.009317,0.000958,0.024326,64.743530,3.298193,0.243263,-38.876350,0.025366,0.000000
29.370001,14.683764,-38.787388,0.009326,0.000968,0.024595,65.316643,3.327389,0.245950,-38.787388,0.025687,0.000000
29.560001,14.938838,-38.920834,0.009343,0.000982,0.024942,66.451271,3.385189,0.249417,-38.920834,0.026000,0.000000
29.750002,15.272112,-38.920834,0.009352,0.000997,0.025323,67.933746,3.460710,0.253232,-38.920834,0.026320,0.000000
29.940001,15.618791,-38.920834,0.009352,0.001012,0.025714,69.475853,3.539268,0.257138,-38.920834,0.026633,0.000000
30.130001,15.704063,-38.920834,0.009378,0.001022,0.025956,69.855164,3.558592,0.259561,-38.920834,0.026954,0.000000
30.320002,15.720820,-38.876350,0.009386,0.001032,0.026216,69.929703,3.562389,0.262165,-38.876350,0.027266,0.000000
30.510002,15.963608,-38.920834,0.009390,0.001044,0.026528,71.009674,3.617405,0.265283,-38.920834,0.027587,0.000000
30.700001,16.325926,-38.920834,0.009412,0.001058,0.026884,72.621346,3.699508,0.268841,-38.920834,0.027899,0.000000
30.890001,16.617495,-38.965313,0.009408,0.001072,0.027240,73.918304,3.765578,0.272399,-38.965313,0.028219,0.000000
31.080002,16.940714,-38.920834,0.009416,0.001085,0.027569,75.356056,3.838820,0.275692,-38.920834,0.028532,0.000000
31.270002,17.063225,-38.920834,0.009442,0.001096,0.027838,75.901016,3.866582,0.278379,-38.920834,0.028853,0.000000
31.460001,17.198023,-38.965313,0.009434,0.001106,0.028081,76.500626,3.897128,0.280809,-38.965313,0.029165,0.000000
31.650002,17.603165,-38.920834,0.009459,0.001122,0.028506,78.302788,3.988934,0.285056,-38.920834,0.029486,0.000000
31.840002,17.887285,-38.920834,0.009464,0.001135,0.028836,79.566620,4.053317,0.288356,-38.920834,0.029798,0.000000
32.030003,18.054108,-39.009792,0.009477,0.001147,0.029122,80.308685,4.091119,0.291217,-39.009792,0.030119,0.000000
32.220001,18.273436,-38.920834,0.009485,0.001158,0.029425,81.284302,4.140820,0.294253,-38.920834,0.030431,0.000000
32.410000,18.482708,-39.009792,0.009498,0.001169,0.029702,82.215195,4.188241,0.297023,-39.009792,0.030752,0.000000
32.600002,18.894552,-38.920834,0.009520,0.001185,0.030101,84.047165,4.281567,0.301013,-38.920834,0.031073,0.000000
32.790001,18.802948,-39.009792,0.009520,0.001192,0.030266,83.639687,4.260809,0.302663,-39.009792,0.031385,0.000000
32.980003,19.351454,-39.054276,0.009528,0.001207,0.030665,86.079567,4.385102,0.306652,-39.054276,0.031706,0.000000
33.170002,19.679140,-38.965313,0.009554,0.001220,0.030995,87.537186,4.459357,0.309945,-38.965313,0.032018,0.000000
33.360001,19.960281,-39.009792,0.009550,0.001232,0.031290,88.787766,4.523064,0.312897,-39.009792,0.032339,0.000000
33.550003,20.146095,-39.009792,0.009563,0.001242,0.031558,89.614311,4.565170,0.315585,-39.009792,0.032652,0.000000
33.740002,20.611935,-39.009792,0.009563,0.001258,0.031949,91.686462,4.670731,0.319491,-39.009792,0.032972,0.000000
33.930000,20.786949,-39.009792,0.009580,0.001269,0.032226,92.464966,4.710390,0.322261,-39.009792,0.033284,0.000000
34.120003,21.114264,-38.965313,0.009597,0.001284,0.032625,93.920937,4.784560,0.326250,-38.965313,0.033605,0.000000
34.310001,21.350721,-39.009792,0.009610,0.001294,0.032868,94.972755,4.838142,0.328680,-39.009792,0.033917,0.000000
34.500000,21.846722,-39.009792,0.009615,0.001309,0.033241,97.179070,4.950538,0.332412,-39.009792,0.034238,0.000000
34.690002,21.850445,-39.009792,0.009593,0.001318,0.033475,97.195633,4.951382,0.334751,-39.009792,0.034551,0.000000
34.880001,22.349424,-39.054276,0.009623,0.001333,0.033866,99.415207,5.064452,0.338657,-39.054276,0.034871,0.000000
35.070004,22.539705,-39.009792,0.009645,0.001342,0.034091,100.261620,5.107570,0.340905,-39.009792,0.035184,0.000000
35.260002,22.768343,-39.054276,0.009653,0.001355,0.034429,101.278648,5.159380,0.344289,-39.054276,0.035505,0.000000
35.450001,23.085604,-39.009792,0.009658,0.001366,0.034707,102.689896,5.231273,0.347067,-39.009792,0.035816,0.000000
35.640003,23.892908,-39.009792,0.009671,0.001385,0.035184,106.280960,5.414210,0.351836,-39.009792,0.036137,0.000000
35.830002,23.971851,-39.054276,0.009679,0.001394,0.035418,106.632118,5.432099,0.354175,-39.054276,0.036450,0.000000
36.020000,24.304752,-39.054276,0.009675,0.001408,0.035765,108.112938,5.507535,0.357650,-39.054276,0.036770,0.000000
36.210003,24.696859,-39.098755,0.009675,0.001421,0.036085,109.857117,5.596388,0.360852,-39.098755,0.037083,0.000000
36.400002,24.935551,-39.054276,0.009710,0.001430,0.036328,110.918869,5.650476,0.363282,-39.054276,0.037404,0.000000
36.590000,25.284092,-39.143238,0.009710,0.001443,0.036658,112.469261,5.729457,0.366582,-39.143238,0.037716,0.000000
36.780003,25.752535,-39.098755,0.009727,0.001455,0.036961,114.552994,5.835608,0.369610,-39.098755,0.038037,0.000000
36.970001,26.096235,-39.098755,0.009735,0.001470,0.037326,116.081856,5.913491,0.373259,-39.098755,0.038349,0.000000
37.160004,26.139431,-39.098755,0.009722,0.001474,0.037439,116.273994,5.923280,0.374387,-39.098755,0.038670,0.000000
37.350002,26.567659,-39.054276,0.009735,0.001486,0.037742,118.178848,6.020318,0.377422,-39.054276,0.038982,0.000000
37.540001,27.160103,-39.054276,0.009766,0.001503,0.038167,120.814171,6.154567,0.381669,-39.054276,0.039303,0.000000
37.730003,27.870218,-39.098755,0.009770,0.001520,0.038609,123.972923,6.315482,0.386090,-39.098755,0.039624,0.000000
37.920002,28.188969,-39.098755,0.009783,0.001532,0.038922,125.390793,6.387712,0.389216,-39.098755,0.039936,0.000000
38.110001,28.586662,-39.143238,0.009787,0.001548,0.039311,127.159828,6.477830,0.393114,-39.143238,0.040257,0.000000
38.300003,28.975046,-39.098755,0.009804,0.001558,0.039572,128.887436,6.565839,0.395718,-39.098755,0.040569,0.000000
38.490002,29.252464,-39.098755,0.009813,0.001570,0.039866,130.121460,6.628703,0.398663,-39.098755,0.040890,0.000000
38.680000,29.647179,-39.187717,0.009813,0.001581,0.040152,131.877243,6.718147,0.401524,-39.187717,0.041202,0.000000
38.870003,30.025509,-39.143238,0.009830,0.001593,0.040473,133.560135,6.803877,0.404734,-39.143238,0.041523,0.000000
39.060001,30.232922,-39.098755,0.009826,0.001602,0.040682,134.482758,6.850878,0.406816,-39.098755,0.041835,0.000000
39.250000,30.541990,-39.098755,0.009856,0.001613,0.040959,135.857559,6.920914,0.409594,-39.098755,0.042156,0.000000
39.440002,31.277798,-39.098755,0.009830,0.001630,0.041401,139.130600,7.087650,0.414015,-39.098755,0.042468,0.000000
39.630001,32.186012,-39.187717,0.009869,0.001647,0.041827,143.170532,7.293455,0.418269,-39.187717,0.042789,0.000000
39.820004,32.360657,-39.143238,0.009873,0.001657,0.042078,143.947388,7.333030,0.420782,-39.143238,0.043102,0.000000
40.010002,32.944908,-39.187717,0.009860,0.001672,0.042460,146.546265,7.465423,0.424597,-39.187717,0.043423,0.000000
40.200001,33.351540,-39.187717,0.009886,0.001683,0.042746,148.355057,7.557567,0.427458,-39.187717,0.043734,0.000000
40.390003,33.442772,-39.143238,0.009904,0.001690,0.042928,148.760880,7.578241,0.429275,-39.143238,0.044055,0.000000
40.580002,34.245235,-39.187717,0.009886,0.001708,0.043379,152.330414,7.760081,0.433787,-39.187717,0.044367,0.000000
40.770000,34.652237,-39.143238,0.009912,0.001719,0.043674,154.140854,7.852309,0.436739,-39.143238,0.044688,0.000000
40.960003,34.868587,-39.232201,0.009921,0.001729,0.043908,155.103226,7.901335,0.439078,-39.232201,0.045001,0.000000
41.150002,35.429005,-39.187717,0.009904,0.001740,0.044194,157.596085,8.028327,0.441939,-39.187717,0.045321,0.000000
41.340000,35.481140,-39.143238,0.009929,0.001747,0.044376,157.827988,8.040141,0.443764,-39.143238,0.045634,0.000000
41.530003,37.177296,-39.187717,0.009934,0.001775,0.045079,165.372864,8.424496,0.450789,-39.187717,0.045955,0.000000
41.720001,37.396622,-39.143238,0.009951,0.001785,0.045330,166.348480,8.474196,0.453302,-39.143238,0.046267,0.000000
41.910004,37.758198,-39.187717,0.009942,0.001797,0.045642,167.956848,8.556129,0.456420,-39.187717,0.046588,0.000000
42.100002,38.234459,-39.232201,0.009942,0.001808,0.045920,170.075363,8.664052,0.459199,-39.232201,0.046900,0.000000
42.290001,39.037666,-39.143238,0.009973,0.001823,0.046310,173.648209,8.846062,0.463097,-39.143238,0.047220,0.000000
42.480003,39.529198,-39.321159,0.009977,0.001834,0.046588,175.834656,8.957444,0.465875,-39.321159,0.047533,0.000000
42.670002,40.028549,-39.187717,0.009977,0.001847,0.046926,178.055878,9.070599,0.469259,-39.187717,0.047854,0.000000
42.860001,40.314533,-39.232201,0.009990,0.001856,0.047142,179.328003,9.135404,0.471424,-39.232201,0.048166,0.000000
43.050003,40.643337,-39.276680,0.009981,0.001867,0.047411,180.790588,9.209911,0.474111,-39.276680,0.048487,0.000000
43.240002,41.557884,-39.187717,0.010003,0.001883,0.047827,184.858704,9.417150,0.478274,-39.187717,0.048808,0.000000
43.430000,42.100430,-39.232201,0.009998,0.001893,0.048088,187.272064,9.540093,0.480878,-39.232201,0.049120,0.000000
43.620003,42.810917,-39.232201,0.009998,0.001907,0.048444,190.432465,9.701093,0.484436,-39.232201,0.049441,0.000000
43.810001,43.100998,-39.276680,0.010020,0.001916,0.048660,191.722809,9.766826,0.486601,-39.276680,0.049753,0.000000
44.000004,43.722485,-39.321159,0.010024,0.001930,0.049024,194.487320,9.907657,0.490242,-39.321159,0.050074,0.000000
44.190002,44.469837,-39.232201,0.010024,0.001946,0.049432,197.811722,10.077009,0.494322,-39.232201,0.050386,0.000000
44.380001,45.274536,-39.276680,0.010042,0.001959,0.049762,201.391190,10.259356,0.497615,-39.276680,0.050707,0.000000
44.570004,45.628288,-39.276680,0.010063,0.001968,0.049995,202.964767,10.339519,0.499954,-39.276680,0.051019,0.000000
44.760002,46.129875,-39.232201,0.010067,0.001978,0.050248,205.195938,10.453179,0.502475,-39.232201,0.051340,0.000000
44.950001,46.737213,-39.276680,0.010063,0.001992,0.050586,207.897507,10.590804,0.505859,-39.276680,0.051652,0.000000
45.140003,47.280132,-39.276680,0.010080,0.002004,0.050898,210.312531,10.713831,0.508978,-39.276680,0.051973,0.000000
45.330002,48.453480,-39.365643,0.010072,0.002022,0.051366,215.531845,10.979715,0.513663,-39.365643,0.052285,0.000000
45.520000,49.041080,-39.321159,0.010072,0.002034,0.051670,218.145615,11.112867,0.516699,-39.321159,0.052606,0.000000
45.710003,49.572086,-39.276680,0.010080,0.002046,0.051956,220.507660,11.233195,0.519560,-39.276680,0.052918,0.000000
45.900002,50.023029,-39.365643,0.010089,0.002056,0.052216,222.513550,11.335381,0.522157,-39.365643,0.053239,0.000000
46.090004,50.398380,-39.321159,0.010102,0.002064,0.052424,224.183197,11.420436,0.524238,-39.321159,0.053552,0.000000
46.280003,51.064926,-39.321159,0.010093,0.002078,0.052788,227.148132,11.571478,0.527879,-39.321159,0.053872,0.000000
46.470001,52.043522,-39.321159,0.010111,0.002094,0.053179,231.501144,11.793231,0.531785,-39.321159,0.054185,0.000000
46.660004,52.471378,-39.321159,0.010123,0.002100,0.053352,233.404343,11.890184,0.533519,-39.321159,0.054506,0.000000
46.850002,52.973335,-39.365643,0.010128,0.002111,0.053630,235.637161,12.003929,0.536297,-39.365643,0.054817,0.000000
47.040001,53.825695,-39.365643,0.010132,0.002127,0.054020,239.428650,12.197077,0.540195,-39.365643,0.055138,0.000000
47.230003,55.178898,-39.365643,0.010145,0.002147,0.054523,245.447998,12.503716,0.545229,-39.365643,0.055451,0.000000
47.420002,55.883427,-39.365643,0.010145,0.002160,0.054852,248.581894,12.663366,0.548522,-39.365643,0.055771,0.000000
47.610001,56.253193,-39.321159,0.010154,0.002168,0.055060,250.226700,12.747156,0.550604,-39.321159,0.056084,0.000000
47.800003,56.779354,-39.321159,0.010167,0.002179,0.055338,252.567184,12.866385,0.553382,-39.321159,0.056405,0.000000
47.990002,57.552773,-39.276680,0.010145,0.002193,0.055711,256.007507,13.041644,0.557106,-39.276680,0.056717,0.000000
48.180004,58.088615,-39.454605,0.010167,0.002203,0.055954,258.391052,13.163068,0.559536,-39.454605,0.057038,0.000000
48.370003,58.602116,-39.365643,0.010158,0.002212,0.056179,260.675232,13.279428,0.561792,-39.365643,0.057349,0.000000
48.560001,59.821636,-39.410122,0.010167,0.002231,0.056656,266.099915,13.555777,0.566561,-39.410122,0.057670,0.000000
48.750004,60.280773,-39.454605,0.010184,0.002238,0.056847,268.142273,13.659819,0.568469,-39.454605,0.057991,0.000000
48.940002,60.944340,-39.410122,0.010179,0.002251,0.057168,271.093964,13.810184,0.571678,-39.410122,0.058304,0.000000
49.130001,61.877506,-39.321159,0.010171,0.002265,0.057541,275.244904,14.021644,0.575410,-39.321159,0.058625,0.000000
49.320004,62.870251,-39.365643,0.010197,0.002281,0.057940,279.660828,14.246603,0.579399,-39.365643,0.058937,0.000000
49.510002,63.642921,-39.410122,0.010184,0.002292,0.058226,283.097839,14.421692,0.582261,-39.410122,0.059258,0.000000
49.700001,64.026093,-39.454605,0.010205,0.002302,0.058468,284.802277,14.508519,0.584683,-39.454605,0.059570,0.000000
49.890003,64.898560,-39.410122,0.010210,0.002317,0.058850,288.683197,14.706223,0.588498,-39.410122,0.059891,0.000000
50.080002,65.624313,-39.454605,0.010210,0.002327,0.059110,291.911530,14.870682,0.591102,-39.454605,0.060203,0.000000
50.270004,66.148239,-39.499084,0.010214,0.002339,0.059423,294.242065,14.989405,0.594229,-39.499084,0.060524,0.000000
50.460003,67.307434,-39.365643,0.010223,0.002353,0.059778,299.398407,15.252083,0.597779,-39.365643,0.060836,0.000000
50.650002,67.166306,-39.454605,0.010223,0.002348,0.059639,298.770660,15.220102,0.596393,-39.454605,0.059856,0.000000
50.840004,66.836014,-39.499084,0.010218,0.002348,0.059639,297.301453,15.145257,0.596393,-39.499084,0.059856,0.000000
51.030003,66.681107,-39.499084,0.010253,0.002346,0.059587,296.612366,15.110155,0.595871,-39.499084,0.059639,0.000000
51.220001,66.433105,-39.499084,0.010253,0.002345,0.059552,295.509216,15.053957,0.595523,-39.499084,0.059639,0.000000
51.410004,66.213036,-39.454605,0.010236,0.002344,0.059544,294.530304,15.004088,0.595440,-39.454605,0.059639,0.000000
51.600002,66.042114,-39.543564,0.010248,0.002344,0.059536,293.769989,14.965357,0.595356,-39.543564,0.059639,0.000000
51.790001,65.857788,-39.499084,0.010236,0.002344,0.059527,292.950073,14.923589,0.595266,-39.499084,0.059639,0.000000
51.980003,65.712196,-39.454605,0.010248,0.002344,0.059527,292.302460,14.890596,0.595266,-39.454605,0.059639,0.000000
52.170002,65.586700,-39.499084,0.010253,0.002343,0.059518,291.744202,14.862159,0.595182,-39.499084,0.059639,0.000000
52.360001,65.453766,-39.410122,0.010253,0.002343,0.059518,291.152893,14.832035,0.595182,-39.410122,0.059639,0.000000
52.550003,65.333115,-39.588047,0.010244,0.002343,0.059509,290.616211,14.804696,0.595091,-39.588047,0.059639,0.000000
52.740002,65.234436,-39.499084,0.010253,0.002343,0.059509,290.177277,14.782334,0.595091,-39.499084,0.059639,0.000000
52.930004,65.120117,-39.543564,0.010253,0.002343,0.059509,289.668762,14.756430,0.595091,-39.543564,0.059639,0.000000
53.120003,65.030380,-39.543564,0.010261,0.002343,0.059509,289.269592,14.736094,0.595091,-39.543564,0.059639,0.000000
53.310001,64.939896,-39.499084,0.010270,0.002343,0.059509,288.867096,14.715591,0.595091,-39.499084,0.059639,0.000000
53.500004,64.854622,-39.588047,0.010270,0.002343,0.059501,288.487762,14.696267,0.595008,-39.588047,0.059639,0.000000
53.690002,64.771210,-39.543564,0.010266,0.002343,0.059501,288.116730,14.677366,0.595008,-39.543564,0.059639,0.000000
53.880001,64.695618,-39.499084,0.010261,0.002343,0.059501,287.780487,14.660236,0.595008,-39.499084,0.059639,0.000000
54.070004,64.623375,-39.543564,0.010270,0.002343,0.059501,287.459137,14.643867,0.595008,-39.543564,0.059639,0.000000
54.260002,64.555603,-39.543564,0.010244,0.002343,0.059501,287.157654,14.628510,0.595008,-39.543564,0.059639,0.000000
54.450001,64.490814,-39.588047,0.010287,0.002343,0.059501,286.869476,14.613828,0.595008,-39.588047,0.059639,0.000000
54.640003,64.423790,-39.588047,0.010279,0.002343,0.059501,286.571320,14.598639,0.595008,-39.588047,0.059639,0.000000
54.830002,64.358246,-39.499084,0.010261,0.002343,0.059501,286.279785,14.583787,0.595008,-39.499084,0.059639,0.000000
55.020004,64.299416,-39.543564,0.010287,0.002343,0.059501,286.018097,14.570457,0.595008,-39.543564,0.059639,0.000000
55.210003,64.251747,-39.543564,0.010283,0.002343,0.059501,285.806030,14.559654,0.595008,-39.543564,0.059639,0.000000
55.400002,64.188072,-39.588047,0.010257,0.002343,0.059501,285.522797,14.545224,0.595008,-39.588047,0.059639,0.000000
55.590004,64.160889,-39.588047,0.010270,0.002343,0.059501,285.401886,14.539065,0.595008,-39.588047,0.059639,0.000000
55.780003,64.112854,-39.543564,0.010279,0.002343,0.059501,285.188232,14.528181,0.595008,-39.543564,0.059639,0.000000
55.970001,64.044708,-39.632526,0.010279,0.002343,0.059501,284.885101,14.512738,0.595008,-39.632526,0.059639,0.000000
56.160004,64.005241,-39.588047,0.010283,0.002343,0.059501,284.709534,14.503796,0.595008,-39.588047,0.059639,0.000000
56.350002,63.946407,-39.632526,0.010279,0.002343,0.059501,284.447815,14.490462,0.595008,-39.632526,0.059639,0.000000
56.540001,63.908051,-39.588047,0.010287,0.002343,0.059501,284.277222,14.481771,0.595008,-39.588047,0.059639,0.000000
56.730003,63.864857,-39.543564,0.010283,0.002343,0.059501,284.085083,14.471984,0.595008,-39.543564,0.059639,0.000000
56.920002,63.811607,-39.632526,0.010266,0.002343,0.059501,283.848206,14.459916,0.595008,-39.632526,0.059639,0.000000
57.110004,63.773254,-39.588047,0.010283,0.002342,0.059492,283.677612,14.451225,0.594917,-39.588047,0.059639,0.000000
57.300003,63.748306,-39.677010,0.010274,0.002342,0.059492,283.566620,14.445573,0.594917,-39.677010,0.059639,0.000000
57.490002,63.701385,-39.632526,0.010274,0.002342,0.059492,283.357910,14.434940,0.594917,-39.632526,0.059639,0.000000
57.680004,63.663776,-39.632526,0.010270,0.002342,0.059492,283.190613,14.426418,0.594917,-39.632526,0.059639,0.000000
57.870003,63.626167,-39.721489,0.010270,0.002342,0.059492,283.023315,14.417895,0.594917,-39.721489,0.059639,0.000000
58.060001,63.601963,-39.632526,0.010279,0.002342,0.059492,282.915649,14.412411,0.594917,-39.632526,0.059639,0.000000
58.250004,63.570683,-39.632526,0.010274,0.002342,0.059492,282.776520,14.405323,0.594917,-39.632526,0.059639,0.000000
58.440002,63.517807,-39.677010,0.010287,0.002342,0.059492,282.541321,14.393341,0.594917,-39.677010,0.059639,0.000000
58.630001,63.488762,-39.588047,0.010261,0.002342,0.059492,282.412109,14.386759,0.594917,-39.588047,0.059639,0.000000
58.820004,63.461205,-39.721489,0.010274,0.002342,0.059492,282.289551,14.380515,0.594917,-39.721489,0.059639,0.000000
59.010002,63.426201,-39.677010,0.010292,0.002342,0.059492,282.133820,14.372582,0.594917,-39.677010,0.059639,0.000000
59.200005,63.395294,-39.677010,0.010270,0.002342,0.059492,281.996338,14.365580,0.594917,-39.677010,0.059639,0.000000
59.390003,63.362900,-39.677010,0.010283,0.002342,0.059492,281.852264,14.358238,0.594917,-39.677010,0.059639,0.000000
59.580002,63.337204,-39.677010,0.010292,0.002342,0.059492,281.737946,14.352415,0.594917,-39.677010,0.059639,0.000000
59.770004,63.297733,-39.721489,0.010266,0.002342,0.059492,281.562378,14.343472,0.594917,-39.721489,0.059639,0.000000
59.960003,63.266827,-39.677010,0.010292,0.002342,0.059492,281.424896,14.336469,0.594917,-39.677010,0.059639,0.000000
60.150002,63.242249,-39.721489,0.010292,0.002342,0.059492,281.315582,14.330898,0.594917,-39.721489,0.059639,0.000000
60.340004,63.222141,-39.721489,0.010287,0.002342,0.059492,281.226135,14.326343,0.594917,-39.721489,0.059639,0.000000
60.530003,63.193840,-39.721489,0.010296,0.002342,0.059492,281.100250,14.319929,0.594917,-39.721489,0.059639,0.000000
60.720001,63.166660,-39.765972,0.010287,0.002342,0.059492,280.979340,14.313769,0.594917,-39.765972,0.059639,0.000000
60.910004,63.134636,-39.765972,0.010270,0.002342,0.059492,280.836884,14.306513,0.594917,-39.765972,0.059639,0.000000
61.100002,63.110802,-39.721489,0.010283,0.002342,0.059492,280.730865,14.301112,0.594917,-39.721489,0.059639,0.000000
61.290005,63.083992,-39.810452,0.010292,0.002342,0.059492,280.611603,14.295037,0.594917,-39.810452,0.059639,0.000000
61.480003,63.067608,-39.677010,0.010292,0.002342,0.059492,280.538727,14.291324,0.594917,-39.677010,0.059639,0.000000
61.670002,63.033348,-39.721489,0.010270,0.002342,0.059492,280.386322,14.283561,0.594917,-39.721489,0.059639,0.000000
61.860004,63.014732,-39.721489,0.010292,0.002342,0.059492,280.303528,14.279343,0.594917,-39.721489,0.059639,0.000000
62.050003,62.991272,-39.721489,0.010261,0.002342,0.059492,280.199158,14.274026,0.594917,-39.721489,0.059639,0.000000
62.240002,62.976006,-39.765972,0.010270,0.002342,0.059492,280.131256,14.270567,0.594917,-39.765972,0.059639,0.000000
62.430004,62.936531,-39.810452,0.010279,0.002342,0.059492,279.955658,14.261622,0.594917,-39.810452,0.059639,0.000000
62.620003,62.922382,-39.810452,0.010274,0.002342,0.059492,279.892731,14.258416,0.594917,-39.810452,0.059639,0.000000
62.810001,62.891850,-39.810452,0.010296,0.002342,0.059492,279.756927,14.251497,0.594917,-39.810452,0.059639,0.000000
63.000004,62.865780,-39.765972,0.010300,0.002342,0.059492,279.640961,14.245590,0.594917,-39.765972,0.059639,0.000000
63.190002,62.849770,-39.765972,0.010292,0.002342,0.059492,279.569733,14.241961,0.594917,-39.765972,0.059639,0.000000
63.380005,62.811043,-39.765972,0.010283,0.002342,0.059492,279.397461,14.233186,0.594917,-39.765972,0.059639,0.000000
63.570004,62.811043,-39.765972,0.010266,0.002342,0.059492,279.397461,14.233186,0.594917,-39.765972,0.059639,0.000000
63.760002,62.795403,-39.810452,0.010279,0.002342,0.059492,279.327911,14.229642,0.594917,-39.810452,0.059639,0.000000
63.950005,62.754814,-39.810452,0.010283,0.002342,0.059492,279.147369,14.220445,0.594917,-39.810452,0.059639,0.000000
64.139999,62.745876,-39.854931,0.010296,0.002342,0.059492,279.107605,14.218419,0.594917,-39.854931,0.059639,0.000000
64.330002,62.723907,-39.810452,0.010296,0.002342,0.059492,279.009888,14.213440,0.594917,-39.810452,0.059639,0.000000
64.520004,62.695980,-39.810452,0.010274,0.002342,0.059492,278.885651,14.207111,0.594917,-39.810452,0.059639,0.000000
64.710007,62.683319,-39.810452,0.010300,0.002342,0.059492,278.829315,14.204243,0.594917,-39.810452,0.059639,0.000000
64.900002,62.654274,-39.765972,0.010292,0.002342,0.059492,278.700134,14.197661,0.594917,-39.765972,0.059639,0.000000
65.090004,62.644592,-39.854931,0.010283,0.002342,0.059492,278.657074,14.195468,0.594917,-39.854931,0.059639,0.000000
65.280006,62.625229,-39.854931,0.010287,0.002342,0.059492,278.570923,14.191079,0.594917,-39.854931,0.059639,0.000000
65.470001,62.598789,-39.854931,0.010257,0.002342,0.059492,278.453308,14.185088,0.594917,-39.854931,0.059639,0.000000
65.660004,62.582405,-39.899414,0.010292,0.002342,0.059492,278.380432,14.181376,0.594917,-39.899414,0.059639,0.000000
65.850006,62.569000,-39.810452,0.010274,0.002342,0.059492,278.320801,14.178338,0.594917,-39.810452,0.059639,0.000000
66.040001,62.545170,-39.899414,0.010274,0.002342,0.059492,278.214813,14.172938,0.594917,-39.899414,0.059639,0.000000
66.230003,62.523571,-39.810452,0.010287,0.002342,0.059492,278.118744,14.168044,0.594917,-39.810452,0.059639,0.000000
66.420006,62.514263,-39.899414,0.010292,0.002342,0.059483,278.077332,14.165935,0.594834,-39.899414,0.059639,0.000000
66.610001,62.480377,-39.899414,0.010283,0.002342,0.059483,277.926605,14.158256,0.594834,-39.899414,0.059639,0.000000
66.800003,62.480747,-39.810452,0.010283,0.002342,0.059483,277.928253,14.158340,0.594834,-39.810452,0.059639,0.000000
66.990005,62.449471,-39.943893,0.010274,0.002342,0.059483,277.789124,14.151253,0.594834,-39.943893,0.059639,0.000000
67.180000,62.440533,-39.854931,0.010283,0.002342,0.059483,277.749359,14.149227,0.594834,-39.854931,0.059639,0.000000
67.370003,62.424149,-39.854931,0.010283,0.002342,0.059483,277.676483,14.145514,0.594834,-39.854931,0.059639,0.000000
67.560005,62.410744,-39.943893,0.010296,0.002342,0.059483,277.616852,14.142477,0.594834,-39.943893,0.059639,0.000000
67.750000,62.397709,-39.854931,0.010287,0.002342,0.059483,277.558868,14.139524,0.594834,-39.854931,0.059639,0.000000
67.940002,62.370899,-39.943893,0.010305,0.002342,0.059483,277.439606,14.133448,0.594834,-39.943893,0.059639,0.000000
68.130005,62.356003,-39.854931,0.010292,0.002342,0.059483,277.373352,14.130073,0.594834,-39.854931,0.059639,0.000000
68.320000,62.336639,-39.943893,0.010300,0.002342,0.059483,277.287231,14.125685,0.594834,-39.943893,0.059639,0.000000
68.510002,62.328449,-39.943893,0.010283,0.002342,0.059483,277.250793,14.123828,0.594834,-39.943893,0.059639,0.000000
68.700005,62.293819,-39.899414,0.010296,0.002342,0.059483,277.096741,14.115981,0.594834,-39.899414,0.059639,0.000000
68.890007,62.288605,-39.943893,0.010274,0.002342,0.059483,277.073547,14.114799,0.594834,-39.943893,0.059639,0.000000
69.080002,62.279297,-39.988377,0.010292,0.002342,0.059483,277.032135,14.112691,0.594834,-39.988377,0.059639,0.000000
69.270004,62.271103,-39.943893,0.010292,0.002342,0.059483,276.995697,14.110833,0.594834,-39.943893,0.059639,0.000000
69.460007,62.245037,-39.988377,0.010283,0.002342,0.059483,276.879761,14.104927,0.594834,-39.988377,0.059639,0.000000
69.650002,62.230515,-39.854931,0.010274,0.002342,0.059483,276.815155,14.101636,0.594834,-39.854931,0.059639,0.000000
69.840004,62.217480,-40.032856,0.010283,0.002342,0.059483,276.757172,14.098682,0.594834,-40.032856,0.059639,0.000000
70.030006,62.191044,-39.988377,0.010300,0.002342,0.059483,276.639587,14.092692,0.594834,-39.988377,0.059639,0.000000
70.220001,62.186203,-39.943893,0.010292,0.002342,0.059483,276.618042,14.091596,0.594834,-39.943893,0.059639,0.000000
70.410004,62.179127,-39.988377,0.010279,0.002342,0.059483,276.586578,14.089992,0.594834,-39.988377,0.059639,0.000000
70.600006,62.157158,-39.943893,0.010279,0.002342,0.059483,276.488861,14.085013,0.594834,-39.943893,0.059639,0.000000
70.790001,62.140026,-40.032856,0.010283,0.002342,0.059483,276.412628,14.081132,0.594834,-40.032856,0.059639,0.000000
70.980003,62.128113,-39.988377,0.010287,0.002342,0.059483,276.359650,14.078432,0.594834,-39.988377,0.059639,0.000000
71.170006,62.112846,-39.943893,0.010287,0.002342,0.059483,276.291748,14.074972,0.594834,-39.943893,0.059639,0.000000
71.360001,62.099438,-40.077335,0.010283,0.002342,0.059483,276.232086,14.071934,0.594834,-40.077335,0.059639,0.000000
71.550003,62.081192,-39.988377,0.010300,0.002342,0.059483,276.150940,14.067799,0.594834,-39.988377,0.059639,0.000000
71.740005,62.057732,-39.988377,0.010274,0.002342,0.059483,276.046570,14.062483,0.594834,-39.988377,0.059639,0.000000
71.930000,62.046188,-39.988377,0.010287,0.002342,0.059483,275.995239,14.059867,0.594834,-39.988377,0.059639,0.000000
72.120003,62.042465,-40.032856,0.010287,0.002342,0.059483,275.978668,14.059024,0.594834,-40.032856,0.059639,0.000000
72.310005,62.020870,-40.032856,0.010292,0.002342,0.059483,275.882599,14.054130,0.594834,-40.032856,0.059639,0.000000
72.500000,62.013794,-40.077335,0.010300,0.002342,0.059483,275.851135,14.052526,0.594834,-40.077335,0.059639,0.000000
72.690002,62.000759,-40.077335,0.010292,0.002342,0.059483,275.793152,14.049573,0.594834,-40.077335,0.059639,0.000000
72.880005,61.981026,-40.077335,0.010287,0.002342,0.059483,275.705383,14.045101,0.594834,-40.077335,0.059639,0.000000
73.070000,61.979164,-40.032856,0.010300,0.002342,0.059483,275.697083,14.044679,0.594834,-40.032856,0.059639,0.000000
73.260002,61.947884,-40.077335,0.010292,0.002342,0.059483,275.557953,14.037592,0.594834,-40.077335,0.059639,0.000000
73.450005,61.937828,-39.988377,0.010283,0.002342,0.059483,275.513214,14.035313,0.594834,-39.988377,0.059639,0.000000
73.640007,61.932987,-40.121819,0.010287,0.002342,0.059483,275.491699,14.034215,0.594834,-40.121819,0.059639,0.000000
73.830002,61.920326,-40.077335,0.010300,0.002342,0.059483,275.435364,14.031346,0.594834,-40.077335,0.059639,0.000000
74.020004,61.901711,-40.121819,0.010296,0.002342,0.059483,275.352570,14.027127,0.594834,-40.121819,0.059639,0.000000
74.210007,61.894260,-40.077335,0.010296,0.002342,0.059483,275.319427,14.025440,0.594834,-40.077335,0.059639,0.000000
74.400002,61.886070,-40.032856,0.010305,0.002342,0.059483,275.282990,14.023583,0.594834,-40.032856,0.059639,0.000000
74.590004,61.868568,-40.077335,0.010300,0.002342,0.059483,275.205139,14.019618,0.594834,-40.077335,0.059639,0.000000
74.780006,61.852558,-40.121819,0.010296,0.002342,0.059483,275.133911,14.015990,0.594834,-40.121819,0.059639,0.000000
74.970001,61.837288,-40.032856,0.010296,0.002342,0.059483,275.066010,14.012529,0.594834,-40.032856,0.059639,0.000000
75.160004,61.822021,-40.166298,0.010296,0.002342,0.059483,274.998077,14.009069,0.594834,-40.166298,0.059639,0.000000
75.350006,61.819416,-40.121819,0.010292,0.002342,0.059483,274.986511,14.008480,0.594834,-40.121819,0.059639,0.000000
75.540001,61.811966,-40.121819,0.010283,0.002342,0.059483,274.953369,14.006792,0.594834,-40.121819,0.059639,0.000000
75.730003,61.785156,-40.121819,0.010296,0.002342,0.059483,274.834106,14.000717,0.594834,-40.121819,0.059639,0.000000
75.920006,61.785900,-40.077335,0.010287,0.002342,0.059483,274.837402,14.000885,0.594834,-40.077335,0.059639,0.000000
76.110001,61.772869,-40.166298,0.010305,0.002342,0.059483,274.779449,13.997932,0.594834,-40.166298,0.059639,0.000000
76.300003,61.751270,-40.121819,0.010292,0.002342,0.059483,274.683380,13.993038,0.594834,-40.121819,0.059639,0.000000
76.490005,61.747921,-40.166298,0.010305,0.002342,0.059483,274.668457,13.992279,0.594834,-40.166298,0.059639,0.000000
76.680000,61.744942,-40.210781,0.010305,0.002342,0.059483,274.655212,13.991604,0.594834,-40.210781,0.059639,0.000000
76.870003,61.712173,-40.077335,0.010279,0.002342,0.059483,274.509460,13.984179,0.594834,-40.077335,0.059639,0.000000
77.060005,61.704353,-40.210781,0.010283,0.002342,0.059483,274.474670,13.982407,0.594834,-40.210781,0.059639,0.000000
77.250000,61.691319,-40.121819,0.010287,0.002342,0.059483,274.416687,13.979452,0.594834,-40.121819,0.059639,0.000000
77.440002,61.683498,-40.166298,0.010296,0.002342,0.059483,274.381897,13.977680,0.594834,-40.166298,0.059639,0.000000
77.630005,61.667858,-40.210781,0.010296,0.002342,0.059483,274.312347,13.974136,0.594834,-40.210781,0.059639,0.000000
77.820007,61.658924,-40.166298,0.010305,0.002342,0.059483,274.272583,13.972112,0.594834,-40.166298,0.059639,0.000000
78.010002,61.646633,-40.210781,0.010270,0.002342,0.059483,274.217926,13.969326,0.594834,-40.210781,0.059639,0.000000
78.200005,61.644402,-40.166298,0.010300,0.002342,0.059483,274.208008,13.968821,0.594834,-40.166298,0.059639,0.000000
78.390007,61.632858,-40.210781,0.010283,0.002342,0.059483,274.156647,13.966206,0.594834,-40.210781,0.059639,0.000000
78.580002,61.612377,-40.210781,0.010300,0.002342,0.059483,274.065552,13.961564,0.594834,-40.210781,0.059639,0.000000
78.770004,61.599716,-40.166298,0.010305,0.002342,0.059483,274.009216,13.958695,0.594834,-40.166298,0.059639,0.000000
78.960007,61.583702,-40.255260,0.010287,0.002342,0.059483,273.937988,13.955066,0.594834,-40.255260,0.059639,0.000000
79.150002,61.568810,-40.255260,0.010287,0.002342,0.059483,273.871735,13.951692,0.594834,-40.255260,0.059639,0.000000
79.340004,61.562851,-40.166298,0.010270,0.002342,0.059483,273.845245,13.950341,0.594834,-40.166298,0.059639,0.000000
79.530006,61.540508,-40.255260,0.010292,0.002342,0.059483,273.745850,13.945278,0.594834,-40.255260,0.059639,0.000000
79.720001,61.536785,-40.210781,0.010305,0.002342,0.059483,273.729279,13.944435,0.594834,-40.210781,0.059639,0.000000
79.910004,61.523380,-40.255260,0.010279,0.002342,0.059483,273.669678,13.941398,0.594834,-40.255260,0.059639,0.000000
80.100006,61.507366,-40.210781,0.010270,0.002342,0.059483,273.598419,13.937768,0.594834,-40.210781,0.059639,0.000000
80.290001,61.512207,-40.210781,0.010283,0.002342,0.059483,273.619965,13.938866,0.594834,-40.210781,0.059639,0.000000
80.480003,61.499176,-40.299740,0.010287,0.002342,0.059483,273.562012,13.935912,0.594834,-40.299740,0.059639,0.000000
80.670006,61.480930,-40.210781,0.010287,0.002342,0.059483,273.480835,13.931778,0.594834,-40.210781,0.059639,0.000000
80.860001,61.458214,-40.299740,0.010300,0.002342,0.059483,273.379791,13.926631,0.594834,-40.299740,0.059639,0.000000
81.000008,61.467152,-40.210781,0.010292,0.002342,0.059483,273.419556,13.928656,0.594834,-40.210781,0.059639,0.000000