File: Data/Polished old I18 after 2_08182023_173843.csv
Time (sec),S:Load (lbs),S:HL1 (DIM),S:LVDT (in),S:Position (in),Ch:Position (mm),Ch:Load (N),Ch:Stress (MPa),Ch:Strain (mm/mm),Ch:HL1 (DIM),Set Point (),Cycles ()
0.110000,0.274811,-41.634171,0.000091,-0.018885,-0.479680,1.222420,0.062273,-4.796798,-41.634171,-0.479498,0.000000
0.360000,0.252098,-41.589687,0.000086,-0.018882,-0.479610,1.121388,0.057126,-4.796102,-41.589687,-0.479151,0.000000
0.610000,0.262894,-41.589687,0.000060,-0.018741,-0.476011,1.169410,0.059573,-4.760115,-41.589687,-0.474988,0.000000
0.860000,0.259171,-41.589687,0.000086,-0.018580,-0.471944,1.152848,0.058729,-4.719442,-41.589687,-0.470825,0.000000
1.110000,0.333275,-41.589687,0.000078,-0.018414,-0.467721,1.482481,0.075521,-4.677207,-41.589687,-0.466663,0.000000
1.360000,0.372742,-41.589687,0.000091,-0.018257,-0.463731,1.658038,0.084464,-4.637314,-41.589687,-0.462500,0.000000
1.610000,0.373116,-41.589687,0.000121,-0.018086,-0.459387,1.659701,0.084549,-4.593867,-41.589687,-0.458337,0.000000
1.860000,0.376465,-41.545208,0.000224,-0.017925,-0.455302,1.674599,0.085308,-4.553020,-41.545208,-0.454175,0.000000
2.110000,0.346306,-41.634171,0.000401,-0.017768,-0.451304,1.540445,0.078474,-4.513041,-41.634171,-0.449994,0.000000
2.360000,0.361198,-41.500729,0.000552,-0.017596,-0.446933,1.606691,0.081849,-4.469333,-41.500729,-0.445832,0.000000
2.610000,0.317635,-41.589687,0.000720,-0.017434,-0.442814,1.412909,0.071977,-4.428138,-41.589687,-0.441669,0.000000
2.860000,0.360085,-41.634171,0.000871,-0.017268,-0.438617,1.601736,0.081596,-4.386167,-41.634171,-0.437507,0.000000
3.110000,0.383545,-41.634171,0.000983,-0.017114,-0.434697,1.706093,0.086913,-4.346967,-41.634171,-0.433344,0.000000
3.360000,0.372742,-41.589687,0.001233,-0.016943,-0.430352,1.658038,0.084464,-4.303520,-41.589687,-0.429181,0.000000
3.610000,0.360825,-41.634171,0.001337,-0.016779,-0.426189,1.605028,0.081764,-4.261894,-41.634171,-0.425018,0.000000
3.860000,0.372742,-41.545208,0.001535,-0.016622,-0.422200,1.658038,0.084464,-4.222001,-41.545208,-0.420838,0.000000
4.110000,0.383545,-41.589687,0.001643,-0.016447,-0.417751,1.706093,0.086913,-4.177510,-41.589687,-0.416676,0.000000
4.360000,0.369766,-41.634171,0.001841,-0.016288,-0.413710,1.644802,0.083790,-4.137098,-41.634171,-0.412513,0.000000
4.610000,0.362320,-41.589687,0.002031,-0.016120,-0.409452,1.611680,0.082103,-4.094518,-41.589687,-0.408350,0.000000
4.860000,0.343697,-41.589687,0.002208,-0.015958,-0.405332,1.528839,0.077883,-4.053323,-41.589687,-0.404188,0.000000
5.110000,0.338486,-41.589687,0.002376,-0.015793,-0.401152,1.505660,0.076702,-4.011523,-41.589687,-0.400025,0.000000
5.360000,0.378700,-41.589687,0.002565,-0.015627,-0.396920,1.684543,0.085815,-3.969204,-41.589687,-0.395863,0.000000
5.610000,0.386894,-41.634171,0.002708,-0.015473,-0.393018,1.720991,0.087671,-3.930178,-41.634171,-0.391700,0.000000
5.860000,0.380188,-41.634171,0.002884,-0.015298,-0.388560,1.691161,0.086152,-3.885603,-41.634171,-0.387519,0.000000
6.110000,0.382423,-41.545208,0.003087,-0.015138,-0.384502,1.701104,0.086658,-3.845018,-41.545208,-0.383357,0.000000
6.360000,0.367905,-41.634171,0.003268,-0.014975,-0.380374,1.636522,0.083368,-3.803736,-41.634171,-0.379194,0.000000
6.610000,0.352264,-41.634171,0.003423,-0.014812,-0.376220,1.566950,0.079824,-3.762197,-41.634171,-0.375032,0.000000
6.860000,0.308693,-41.634171,0.003570,-0.014645,-0.371970,1.373135,0.069951,-3.719704,-41.634171,-0.370869,0.000000
7.110000,0.332901,-41.589687,0.003786,-0.014481,-0.367816,1.480818,0.075436,-3.678161,-41.589687,-0.366706,0.000000
7.360000,0.399185,-41.634171,0.003941,-0.014323,-0.363792,1.775664,0.090457,-3.637924,-41.634171,-0.362544,0.000000
7.610000,0.389503,-41.589687,0.004105,-0.014155,-0.359543,1.732598,0.088263,-3.595431,-41.589687,-0.358381,0.000000
7.860001,0.349281,-41.589687,0.004286,-0.013993,-0.355424,1.553681,0.079148,-3.554236,-41.589687,-0.354201,0.000000
8.110001,0.380562,-41.589687,0.004449,-0.013828,-0.351244,1.692824,0.086237,-3.512435,-41.589687,-0.350038,0.000000
8.360001,0.379074,-41.634171,0.004631,-0.013661,-0.346994,1.686206,0.085899,-3.469943,-41.634171,-0.345875,0.000000
8.610001,0.360085,-41.545208,0.004807,-0.013499,-0.342866,1.601736,0.081596,-3.428661,-41.545208,-0.341713,0.000000
8.860001,0.364548,-41.589687,0.004984,-0.013334,-0.338677,1.621589,0.082608,-3.386773,-41.589687,-0.337550,0.000000
9.110001,0.366043,-41.589687,0.005148,-0.013172,-0.334558,1.628241,0.082947,-3.345582,-41.589687,-0.333388,0.000000
9.360001,0.357475,-41.589687,0.005295,-0.013006,-0.330361,1.590129,0.081005,-3.303608,-41.589687,-0.329225,0.000000
9.610001,0.367531,-41.589687,0.005458,-0.012846,-0.326294,1.634859,0.083284,-3.262935,-41.589687,-0.325045,0.000000
9.860001,0.389130,-41.589687,0.005622,-0.012682,-0.322131,1.730935,0.088178,-3.221309,-41.589687,-0.320882,0.000000
10.110001,0.380936,-41.634171,0.005808,-0.012515,-0.317882,1.694486,0.086321,-3.178816,-41.634171,-0.316719,0.000000
10.360001,0.399185,-41.678650,0.005976,-0.012352,-0.313753,1.775664,0.090457,-3.137534,-41.678650,-0.312557,0.000000
10.610001,0.370506,-41.589687,0.006161,-0.012186,-0.309513,1.648094,0.083958,-3.095128,-41.589687,-0.308394,0.000000
10.860001,0.375725,-41.678650,0.006303,-0.012030,-0.305558,1.671307,0.085140,-3.055580,-41.678650,-0.304231,0.000000
11.110001,0.355614,-41.634171,0.006485,-0.011857,-0.301178,1.581849,0.080583,-3.011785,-41.634171,-0.300069,0.000000
11.360001,0.324707,-41.678650,0.006666,-0.011696,-0.297068,1.444369,0.073580,-2.970681,-41.678650,-0.295906,0.000000
11.610001,0.399551,-41.589687,0.006825,-0.011532,-0.292922,1.777293,0.090540,-2.929225,-41.589687,-0.291726,0.000000
11.860001,0.388756,-41.634171,0.007011,-0.011371,-0.288812,1.729272,0.088093,-2.888121,-41.634171,-0.287563,0.000000
12.110001,0.363434,-41.678650,0.007183,-0.011204,-0.284580,1.616634,0.082355,-2.845798,-41.678650,-0.283400,0.000000
12.360001,0.385406,-41.678650,0.007338,-0.011039,-0.280383,1.714374,0.087334,-2.803828,-41.678650,-0.279238,0.000000
12.610001,0.391365,-41.634171,0.007537,-0.010879,-0.276315,1.740879,0.088685,-2.763151,-41.634171,-0.275075,0.000000
12.860001,0.367157,-41.634171,0.007726,-0.010709,-0.272014,1.633196,0.083199,-2.720140,-41.634171,-0.270913,0.000000
13.110001,0.369019,-41.678650,0.007851,-0.010548,-0.267929,1.641477,0.083621,-2.679293,-41.678650,-0.266750,0.000000
13.360001,0.399925,-41.634171,0.008011,-0.010381,-0.263671,1.778956,0.090624,-2.636713,-41.634171,-0.262587,0.000000
13.610001,0.368645,-41.634171,0.008196,-0.010216,-0.259491,1.639814,0.083536,-2.594913,-41.634171,-0.258407,0.000000
13.860001,0.384659,-41.634171,0.008343,-0.010058,-0.255476,1.711048,0.087165,-2.554759,-41.634171,-0.254244,0.000000
14.110001,0.408867,-41.678650,0.008520,-0.009892,-0.251261,1.818731,0.092651,-2.512610,-41.678650,-0.250082,0.000000
14.360001,0.412956,-41.634171,0.008675,-0.009731,-0.247176,1.836921,0.093577,-2.471764,-41.634171,-0.245919,0.000000
14.610001,0.396950,-41.634171,0.008877,-0.009562,-0.242884,1.765721,0.089950,-2.428839,-41.634171,-0.241756,0.000000
14.860001,0.383911,-41.634171,0.009028,-0.009394,-0.238608,1.707722,0.086996,-2.386085,-41.634171,-0.237594,0.000000
15.110001,0.404396,-41.678650,0.009214,-0.009239,-0.234680,1.798844,0.091637,-2.346798,-41.678650,-0.233431,0.000000
15.360001,0.375725,-41.634171,0.009369,-0.009068,-0.230318,1.671307,0.085140,-2.303177,-41.634171,-0.229251,0.000000
15.610001,0.341835,-41.678650,0.009546,-0.008909,-0.226277,1.520558,0.077461,-2.262765,-41.678650,-0.225088,0.000000
15.860001,0.396576,-41.678650,0.009727,-0.008740,-0.221992,1.764058,0.089865,-2.219924,-41.678650,-0.220925,0.000000
16.110001,0.402908,-41.634171,0.009891,-0.008582,-0.217977,1.792226,0.091300,-2.179770,-41.634171,-0.216763,0.000000
16.360001,0.362686,-41.678650,0.010067,-0.008414,-0.213710,1.613309,0.082186,-2.137103,-41.678650,-0.212600,0.000000
16.610001,0.382423,-41.678650,0.010218,-0.008248,-0.209487,1.701104,0.086658,-2.094867,-41.678650,-0.208438,0.000000
16.860001,0.406631,-41.723133,0.010399,-0.008089,-0.205472,1.808787,0.092144,-2.054717,-41.723133,-0.204275,0.000000
17.110001,0.395088,-41.723133,0.010563,-0.007919,-0.201135,1.757440,0.089528,-2.011354,-41.723133,-0.200112,0.000000
17.360001,0.364922,-41.678650,0.010766,-0.007759,-0.197086,1.623252,0.082692,-1.970855,-41.678650,-0.195932,0.000000
17.610001,0.399185,-41.678650,0.010930,-0.007591,-0.192819,1.775664,0.090457,-1.928188,-41.678650,-0.191769,0.000000
17.860001,0.389130,-41.678650,0.011076,-0.007430,-0.188717,1.730935,0.088178,-1.887168,-41.678650,-0.187607,0.000000
18.110001,0.398437,-41.678650,0.011240,-0.007268,-0.184606,1.772339,0.090287,-1.846064,-41.678650,-0.183444,0.000000
18.360001,0.405510,-41.678650,0.011408,-0.007103,-0.180426,1.803798,0.091890,-1.804263,-41.678650,-0.179281,0.000000
18.610001,0.408867,-41.678650,0.011589,-0.006946,-0.176428,1.818731,0.092651,-1.764283,-41.678650,-0.175119,0.000000
18.860001,0.414078,-41.634171,0.011792,-0.006770,-0.171953,1.841910,0.093831,-1.719535,-41.634171,-0.170956,0.000000
19.110001,0.395462,-41.678650,0.011926,-0.006605,-0.167765,1.759103,0.089613,-1.677647,-41.678650,-0.166776,0.000000
19.360001,0.404022,-41.678650,0.012115,-0.006448,-0.163767,1.797181,0.091553,-1.637667,-41.678650,-0.162613,0.000000
19.610001,0.384285,-41.678650,0.012271,-0.006278,-0.159465,1.709385,0.087080,-1.594652,-41.678650,-0.158450,0.000000
19.860001,0.353378,-41.723133,0.012465,-0.006121,-0.155467,1.571905,0.080077,-1.554672,-41.723133,-0.154288,0.000000
20.110001,0.409607,-41.723133,0.012624,-0.005951,-0.151166,1.822023,0.092818,-1.511661,-41.723133,-0.150125,0.000000
20.360001,0.412216,-41.678650,0.012792,-0.005795,-0.147194,1.833629,0.093410,-1.471942,-41.678650,-0.145963,0.000000
20.610001,0.376465,-41.723133,0.012991,-0.005623,-0.142832,1.674599,0.085308,-1.428321,-41.723133,-0.141800,0.000000
20.860001,0.392853,-41.678650,0.013124,-0.005462,-0.138730,1.747496,0.089022,-1.387300,-41.678650,-0.137637,0.000000
21.110001,0.425621,-41.723133,0.013327,-0.005302,-0.134671,1.893257,0.096447,-1.346715,-41.723133,-0.133457,0.000000
21.360001,0.397690,-41.723133,0.013469,-0.005128,-0.130248,1.769013,0.090118,-1.302485,-41.723133,-0.129295,0.000000
21.610001,0.367905,-41.723133,0.013624,-0.004975,-0.126355,1.636522,0.083368,-1.263546,-41.723133,-0.125132,0.000000
21.860001,0.413704,-41.723133,0.013827,-0.004804,-0.122010,1.840247,0.093747,-1.220099,-41.723133,-0.120969,0.000000
22.110001,0.402534,-41.723133,0.013974,-0.004643,-0.117943,1.790563,0.091216,-1.179426,-41.723133,-0.116806,0.000000
22.360001,0.411095,-41.678650,0.014129,-0.004480,-0.113797,1.828640,0.093155,-1.137970,-41.678650,-0.112644,0.000000
22.610001,0.396950,-41.678650,0.014310,-0.004319,-0.109695,1.765721,0.089950,-1.096953,-41.678650,-0.108481,0.000000
22.860001,0.418549,-41.723133,0.014495,-0.004156,-0.105558,1.861797,0.094844,-1.055585,-41.723133,-0.104319,0.000000
23.110001,0.418915,-41.767612,0.014676,-0.003979,-0.101075,1.863426,0.094927,-1.010749,-41.767612,-0.100138,0.000000
23.360001,0.396950,-41.767612,0.014823,-0.003819,-0.097008,1.765721,0.089950,-0.970076,-41.767612,-0.095976,0.000000
23.610001,0.407005,-41.767612,0.015052,-0.003657,-0.092889,1.810450,0.092229,-0.928885,-41.767612,-0.091813,0.000000
23.860001,0.386894,-41.812096,0.015211,-0.003493,-0.088734,1.720991,0.087671,-0.887342,-41.812096,-0.087650,0.000000
24.110001,0.359337,-41.723133,0.015383,-0.003333,-0.084658,1.598410,0.081427,-0.846583,-41.723133,-0.083488,0.000000
24.360001,0.410728,-41.678650,0.015556,-0.003167,-0.080444,1.827011,0.093072,-0.804438,-41.678650,-0.079325,0.000000
24.610001,0.427856,-41.767612,0.015733,-0.003009,-0.076437,1.903201,0.096954,-0.764371,-41.767612,-0.075162,0.000000
24.860001,0.420776,-41.723133,0.015871,-0.002835,-0.072014,1.871707,0.095349,-0.720144,-41.723133,-0.070982,0.000000
25.110001,0.402908,-41.723133,0.016073,-0.002677,-0.067999,1.792226,0.091300,-0.679990,-41.723133,-0.066820,0.000000
25.360001,0.422638,-41.767612,0.016272,-0.002515,-0.063871,1.879987,0.095771,-0.638709,-41.767612,-0.062657,0.000000
25.610001,0.406631,-41.767612,0.016440,-0.002346,-0.059587,1.808787,0.092144,-0.595867,-41.767612,-0.058494,0.000000
25.860001,0.377586,-41.767612,0.016599,-0.002187,-0.055554,1.679588,0.085562,-0.555543,-41.767612,-0.054331,0.000000
26.110001,0.399925,-41.767612,0.016759,-0.002023,-0.051392,1.778956,0.090624,-0.513917,-41.767612,-0.050169,0.000000
26.360001,0.417801,-41.767612,0.016940,-0.001857,-0.047177,1.858471,0.094675,-0.471768,-41.767612,-0.046006,0.000000
26.610001,0.433815,-41.767612,0.017112,-0.001695,-0.043040,1.929706,0.098304,-0.430403,-41.767612,-0.041844,0.000000
26.860001,0.398064,-41.812096,0.017289,-0.001535,-0.038982,1.770676,0.090203,-0.389818,-41.812096,-0.037663,0.000000
27.110001,0.423012,-41.723133,0.017444,-0.001366,-0.034706,1.881650,0.095856,-0.347064,-41.723133,-0.033501,0.000000
27.360001,0.419289,-41.767612,0.017625,-0.001202,-0.030535,1.865089,0.095012,-0.305350,-41.767612,-0.029338,0.000000
27.610001,0.413330,-41.723133,0.017811,-0.001038,-0.026355,1.838584,0.093662,-0.263550,-41.723133,-0.025175,0.000000
27.860001,0.421150,-41.812096,0.017983,-0.000874,-0.022201,1.873370,0.095434,-0.222007,-41.812096,-0.021013,0.000000
28.110001,0.430092,-41.723133,0.018147,-0.000712,-0.018082,1.913144,0.097460,-0.180816,-41.723133,-0.016850,0.000000
28.360001,0.447220,-41.767612,0.018311,-0.000549,-0.013945,1.989333,0.101341,-0.139447,-41.767612,-0.012687,0.000000
28.610001,0.447960,-41.767612,0.018501,-0.000382,-0.009704,1.992625,0.101509,-0.097041,-41.767612,-0.008525,0.000000
28.860001,0.564514,-41.767612,0.018690,-0.000223,-0.005663,2.511084,0.127921,-0.056630,-41.767612,-0.004345,0.000000
29.110001,0.673622,-41.767612,0.018837,0.000011,0.000277,2.996421,0.152645,0.002774,-41.767612,0.001439,0.000000
29.360001,0.692612,-41.767612,0.018854,0.000010,0.000243,3.080891,0.156948,0.002426,-41.767612,0.000503,0.000000
29.610001,0.685165,-41.767612,0.018884,0.000010,0.000243,3.047768,0.155261,0.002426,-41.767612,0.000503,0.000000
29.860001,0.634521,-41.723133,0.018897,0.000010,0.000251,2.822493,0.143785,0.002513,-41.723133,0.000867,0.000000
30.110001,0.615532,-41.767612,0.018859,0.000010,0.000251,2.738023,0.139482,0.002513,-41.767612,0.001283,0.000000
30.360001,0.637871,-41.767612,0.018872,0.000010,0.000251,2.837391,0.144544,0.002513,-41.767612,0.001700,0.000000
30.610001,0.666542,-41.812096,0.018867,0.000045,0.001136,2.964927,0.151041,0.011358,-41.812096,0.002116,0.000000
30.860001,0.693726,-41.812096,0.018910,0.000064,0.001613,3.085845,0.157200,0.016131,-41.812096,0.002532,0.000000
31.110001,0.706017,-41.812096,0.018923,0.000078,0.001969,3.140518,0.159986,0.019685,-41.812096,0.002948,0.000000
31.360001,0.730225,-41.767612,0.018910,0.000089,0.002272,3.248201,0.165471,0.022721,-41.767612,0.003365,0.000000
31.610001,0.759270,-41.812096,0.018958,0.000102,0.002584,3.377400,0.172053,0.025843,-41.812096,0.003781,0.000000
31.860001,0.802086,-41.812096,0.018953,0.000129,0.003278,3.567856,0.181755,0.032781,-41.812096,0.004197,0.000000
32.110001,0.797249,-41.812096,0.018984,0.000143,0.003625,3.546340,0.180659,0.036248,-41.812096,0.004613,0.000000
32.360001,0.795761,-41.812096,0.018997,0.000159,0.004050,3.539722,0.180322,0.040498,-41.812096,0.005030,0.000000
32.610001,0.812141,-41.767612,0.018992,0.000174,0.004431,3.612586,0.184034,0.044314,-41.767612,0.005446,0.000000
32.860001,0.843422,-41.812096,0.019009,0.000192,0.004883,3.751728,0.191122,0.048825,-41.812096,0.005862,0.000000
33.110001,0.861298,-41.767612,0.019044,0.000204,0.005186,3.831243,0.195173,0.051861,-41.767612,0.006279,0.000000
33.360001,0.878052,-41.812096,0.019022,0.000216,0.005498,3.905769,0.198969,0.054979,-41.812096,0.006703,0.000000
33.610001,0.901512,-41.812096,0.019048,0.000230,0.005836,4.010126,0.204286,0.058363,-41.812096,0.007120,0.000000
33.860001,0.993858,-41.812096,0.019083,0.000261,0.006625,4.420903,0.225212,0.066255,-41.812096,0.007536,0.000000
34.110001,0.984177,-41.767612,0.019100,0.000271,0.006885,4.377836,0.223018,0.068855,-41.767612,0.007952,0.000000
34.360001,1.014717,-41.812096,0.019109,0.000286,0.007259,4.513687,0.229938,0.072587,-41.812096,0.008369,0.000000
34.610001,1.024765,-41.856575,0.019126,0.000300,0.007631,4.558383,0.232215,0.076315,-41.856575,0.008785,0.000000
34.860001,1.091049,-41.767612,0.019113,0.000322,0.008178,4.853229,0.247235,0.081780,-41.767612,0.009201,0.000000
35.110001,1.104080,-41.767612,0.019147,0.000334,0.008490,4.911194,0.250188,0.084899,-41.767612,0.009617,0.000000
35.360001,1.145790,-41.856575,0.019173,0.000348,0.008828,5.096729,0.259640,0.088283,-41.856575,0.010034,0.000000
35.610001,1.193451,-41.812096,0.019169,0.000365,0.009279,5.308735,0.270440,0.092790,-41.812096,0.010450,0.000000
35.860001,1.244095,-41.767612,0.019199,0.000387,0.009834,5.534010,0.281916,0.098343,-41.767612,0.010866,0.000000
36.110001,1.255638,-41.767612,0.019195,0.000398,0.010103,5.585357,0.284532,0.101030,-41.767612,0.011282,0.000000
36.360001,1.302559,-41.812096,0.019221,0.000416,0.010563,5.794071,0.295164,0.105629,-41.812096,0.011699,0.000000
36.610001,1.352081,-41.856575,0.019229,0.000437,0.011092,6.014358,0.306386,0.110916,-41.856575,0.012115,0.000000
36.860001,1.368095,-41.812096,0.019260,0.000452,0.011473,6.085592,0.310015,0.114732,-41.812096,0.012531,0.000000
37.110001,1.407196,-41.856575,0.019264,0.000464,0.011785,6.259521,0.318875,0.117854,-41.856575,0.012948,0.000000
37.360001,1.440704,-41.767612,0.019294,0.000474,0.012037,6.408573,0.326468,0.120371,-41.767612,0.013364,0.000000
37.610001,1.527473,-41.767612,0.019294,0.000497,0.012635,6.794541,0.346130,0.126355,-41.767612,0.013780,0.000000
37.860001,1.585564,-41.767612,0.019333,0.000520,0.013216,7.052939,0.359294,0.132165,-41.767612,0.014196,0.000000
38.110001,1.588165,-41.856575,0.019324,0.000534,0.013563,7.064512,0.359883,0.135632,-41.856575,0.014613,0.000000
38.360001,1.636200,-41.812096,0.019372,0.000548,0.013910,7.278181,0.370768,0.139102,-41.812096,0.015038,0.000000
38.610001,1.642532,-41.812096,0.019367,0.000557,0.014136,7.306349,0.372203,0.141358,-41.812096,0.015454,0.000000
38.860001,1.750153,-41.812096,0.019389,0.000582,0.014786,7.785068,0.396590,0.147861,-41.812096,0.015870,0.000000
39.110001,1.771378,-41.812096,0.019415,0.000595,0.015124,7.879481,0.401400,0.151244,-41.812096,0.016286,0.000000
39.360001,1.813454,-41.767612,0.019398,0.000606,0.015402,8.066645,0.410934,0.154019,-41.767612,0.016703,0.000000
39.610001,1.946762,-41.767612,0.019428,0.000636,0.016147,8.659630,0.441143,0.161475,-41.767612,0.017119,0.000000
39.860001,1.930008,-41.856575,0.019479,0.000648,0.016468,8.585104,0.437346,0.164685,-41.856575,0.017535,0.000000
40.110001,1.930374,-41.812096,0.019475,0.000656,0.016668,8.586733,0.437429,0.166679,-41.812096,0.017951,0.000000
40.360001,2.001129,-41.856575,0.019484,0.000676,0.017162,8.901467,0.453462,0.171622,-41.856575,0.018368,0.000000
40.610001,2.080444,-41.812096,0.019484,0.000695,0.017657,9.254278,0.471435,0.176565,-41.812096,0.018784,0.000000
40.860001,2.122147,-41.812096,0.019523,0.000711,0.018047,9.439779,0.480885,0.180468,-41.812096,0.019200,0.000000
41.110001,2.195137,-41.812096,0.019514,0.000728,0.018481,9.764457,0.497425,0.184805,-41.812096,0.019616,0.000000
41.360001,2.246521,-41.812096,0.019574,0.000742,0.018853,9.993025,0.509069,0.188533,-41.812096,0.020033,0.000000
41.610001,2.291580,-41.767612,0.019570,0.000762,0.019348,10.193458,0.519280,0.193476,-41.767612,0.020449,0.000000
41.860001,2.361214,-41.812096,0.019583,0.000778,0.019773,10.503203,0.535059,0.197727,-41.812096,0.020865,0.000000
42.110001,2.372383,-41.767612,0.019600,0.000794,0.020172,10.552887,0.537590,0.201716,-41.767612,0.021282,0.000000
42.360001,2.404778,-41.767612,0.019604,0.000807,0.020510,10.696984,0.544930,0.205100,-41.767612,0.021698,0.000000
42.610001,2.449089,-41.812096,0.019630,0.000818,0.020770,10.894093,0.554972,0.207700,-41.812096,0.022114,0.000000
42.860001,2.644958,-41.856575,0.019661,0.000846,0.021499,11.765363,0.599356,0.214986,-41.856575,0.022530,0.000000
43.110001,2.634903,-41.812096,0.019669,0.000856,0.021750,11.720634,0.597078,0.217499,-41.812096,0.022947,0.000000
43.360001,2.744011,-41.812096,0.019708,0.000875,0.022227,12.205970,0.621802,0.222268,-41.812096,0.023363,0.000000
43.610001,2.794655,-41.812096,0.019691,0.000890,0.022617,12.431246,0.633278,0.226170,-41.812096,0.023788,0.000000
43.860001,2.867638,-41.856575,0.019734,0.000907,0.023042,12.755889,0.649816,0.230421,-41.856575,0.024204,0.000000
44.110001,2.930573,-41.812096,0.019734,0.000924,0.023458,13.035837,0.664077,0.234584,-41.812096,0.024620,0.000000
44.360001,3.015099,-41.812096,0.019742,0.000942,0.023927,13.411828,0.683231,0.239266,-41.812096,0.025037,0.000000
44.610001,3.091805,-41.812096,0.019773,0.000959,0.024360,13.753034,0.700613,0.243603,-41.812096,0.025453,0.000000
44.860001,3.247833,-41.812096,0.019790,0.000975,0.024777,14.447083,0.735970,0.247767,-41.812096,0.025869,0.000000
45.110001,3.304802,-41.812096,0.019803,0.000987,0.025080,14.700493,0.748879,0.250802,-41.812096,0.026285,0.000000
45.360001,3.426201,-41.812096,0.019786,0.001006,0.025548,15.240502,0.776388,0.255484,-41.812096,0.026702,0.000000
45.610001,3.563606,-41.767612,0.019846,0.001026,0.026069,15.851712,0.807525,0.260688,-41.767612,0.027118,0.000000
45.860001,3.602699,-41.812096,0.019876,0.001038,0.026355,16.025606,0.816383,0.263550,-41.812096,0.027534,0.000000
46.110001,3.741600,-41.812096,0.019863,0.001056,0.026823,16.643469,0.847859,0.268232,-41.812096,0.027951,0.000000
46.360001,3.884964,-41.812096,0.019872,0.001074,0.027274,17.281183,0.880345,0.272743,-41.812096,0.028367,0.000000
46.610001,4.097588,-41.812096,0.019880,0.001093,0.027760,18.226980,0.928527,0.277599,-41.812096,0.028783,0.000000
46.860001,4.175781,-41.812096,0.019928,0.001106,0.028081,18.574802,0.946246,0.280805,-41.812096,0.029199,0.000000
47.110001,4.331810,-41.812096,0.019928,0.001122,0.028497,19.268854,0.981602,0.284969,-41.812096,0.029616,0.000000
47.360001,4.468468,-41.856575,0.019936,0.001137,0.028878,19.876738,1.012569,0.288784,-41.856575,0.030032,0.000000
47.610001,4.694496,-41.812096,0.019975,0.001158,0.029407,20.882162,1.063788,0.294075,-41.812096,0.030448,0.000000
47.860001,4.680351,-41.856575,0.019975,0.001167,0.029650,20.819242,1.060583,0.296505,-41.856575,0.030864,0.000000
48.110001,4.854622,-41.901054,0.020001,0.001182,0.030032,21.594437,1.100073,0.300320,-41.901054,0.031281,0.000000
48.360001,5.293648,-41.812096,0.020027,0.001208,0.030682,23.547321,1.199558,0.306823,-41.812096,0.031697,0.000000
48.610001,5.362907,-41.856575,0.020014,0.001222,0.031038,23.855404,1.215252,0.310380,-41.856575,0.032122,0.000000
48.860001,5.471642,-41.856575,0.020044,0.001232,0.031298,24.339077,1.239892,0.312981,-41.856575,0.032538,0.000000
49.110001,5.681282,-41.812096,0.020023,0.001245,0.031619,25.271605,1.287397,0.316190,-41.812096,0.032954,0.000000
49.360001,5.844757,-41.812096,0.020066,0.001260,0.031992,25.998777,1.324441,0.319918,-41.812096,0.033371,0.000000
49.610001,6.307991,-41.856575,0.020126,0.001285,0.032651,28.059345,1.429411,0.326508,-41.856575,0.033787,0.000000
49.860001,6.475182,-41.856575,0.020100,0.001302,0.033067,28.803045,1.467297,0.330671,-41.856575,0.034203,0.000000
50.110001,6.533646,-41.856575,0.020100,0.001313,0.033353,29.063107,1.480545,0.333533,-41.856575,0.034620,0.000000
50.360001,6.964478,-41.812096,0.020143,0.001335,0.033908,30.979544,1.578173,0.339085,-41.812096,0.035036,0.000000
50.610001,7.155884,-41.856575,0.020161,0.001349,0.034264,31.830961,1.621546,0.342639,-41.856575,0.035452,0.000000
50.860001,7.285469,-41.767612,0.020182,0.001362,0.034594,32.407387,1.650911,0.345936,-41.767612,0.035868,0.000000
51.110001,7.580757,-41.812096,0.020195,0.001376,0.034949,33.720890,1.717824,0.349490,-41.812096,0.036285,0.000000
51.360001,8.174316,-41.856575,0.020217,0.001404,0.035660,36.361176,1.852327,0.356601,-41.856575,0.036701,0.000000
51.610001,8.278954,-41.856575,0.020230,0.001417,0.035981,36.826626,1.876038,0.359811,-41.856575,0.037117,0.000000
51.860001,8.505730,-41.812096,0.020243,0.001432,0.036363,37.835377,1.927426,0.363626,-41.812096,0.037533,0.000000
52.110001,8.723938,-41.856575,0.020247,0.001446,0.036735,38.806015,1.976873,0.367354,-41.856575,0.037950,0.000000
52.360001,9.231857,-41.812096,0.020277,0.001469,0.037308,41.065353,2.091969,0.373081,-41.812096,0.038366,0.000000
52.610001,9.428467,-41.856575,0.020316,0.001483,0.037672,41.939915,2.136521,0.376722,-41.856575,0.038782,0.000000
52.860001,9.519699,-41.812096,0.020303,0.001493,0.037924,42.345737,2.157195,0.379235,-41.812096,0.039199,0.000000
53.110004,9.697319,-41.856575,0.020316,0.001505,0.038236,43.135830,2.197444,0.382358,-41.856575,0.039615,0.000000
53.360004,10.536652,-41.901054,0.020350,0.001535,0.038999,46.869366,2.387640,0.389992,-41.901054,0.040031,0.000000
53.610004,10.760071,-41.856575,0.020363,0.001549,0.039355,47.863186,2.438267,0.393546,-41.856575,0.040456,0.000000
53.860004,10.962273,-41.812096,0.020381,0.001566,0.039780,48.762623,2.484087,0.397796,-41.812096,0.040872,0.000000
54.110004,11.111221,-41.856575,0.020402,0.001577,0.040048,49.425182,2.517839,0.400484,-41.856575,0.041289,0.000000
54.360004,11.772926,-41.812096,0.020402,0.001600,0.040629,52.368591,2.667783,0.406293,-41.812096,0.041705,0.000000
54.610004,11.909218,-41.856575,0.020432,0.001612,0.040942,52.974846,2.698667,0.409416,-41.856575,0.042121,0.000000
54.860004,11.973633,-41.856575,0.020441,0.001623,0.041228,53.261379,2.713264,0.412277,-41.856575,0.042537,0.000000
55.110004,12.814453,-41.856575,0.020467,0.001653,0.041974,57.001534,2.903796,0.419737,-41.856575,0.042954,0.000000
55.360004,13.210281,-41.812096,0.020467,0.001668,0.042355,58.762268,2.993493,0.423552,-41.812096,0.043370,0.000000
55.610004,13.340240,-41.901054,0.020501,0.001680,0.042676,59.340355,3.022942,0.426762,-41.901054,0.043786,0.000000
55.860004,13.638885,-41.812096,0.020506,0.001694,0.043032,60.668793,3.090616,0.430316,-41.812096,0.044202,0.000000
56.110004,14.360542,-41.856575,0.020540,0.001719,0.043656,63.878883,3.254145,0.436561,-41.856575,0.044619,0.000000
56.360004,14.490875,-41.856575,0.020531,0.001729,0.043925,64.458633,3.283679,0.439248,-41.856575,0.045035,0.000000
56.610004,14.702377,-41.812096,0.020553,0.001741,0.044211,65.399437,3.331606,0.442110,-41.812096,0.045451,0.000000
56.860004,15.276581,-41.856575,0.020553,0.001761,0.044723,67.953629,3.461723,0.447227,-41.856575,0.045868,0.000000
57.110004,15.980362,-41.856575,0.020575,0.001782,0.045269,71.084198,3.621202,0.452692,-41.856575,0.046284,0.000000
57.360004,16.191498,-41.856575,0.020596,0.001796,0.045625,72.023376,3.669046,0.456246,-41.856575,0.046700,0.000000
57.610004,16.307678,-41.856575,0.020605,0.001811,0.046006,72.540176,3.695373,0.460062,-41.856575,0.047116,0.000000
57.860004,17.116096,-41.767612,0.020618,0.001832,0.046535,76.136200,3.878563,0.465353,-41.767612,0.047533,0.000000
58.110004,17.507835,-41.856575,0.020665,0.001848,0.046952,77.878738,3.967332,0.469516,-41.856575,0.047949,0.000000
58.360004,17.629227,-41.856575,0.020661,0.001860,0.047246,78.418716,3.994840,0.472465,-41.856575,0.048365,0.000000
58.610004,17.993408,-41.856575,0.020682,0.001872,0.047559,80.038673,4.077364,0.475587,-41.856575,0.048781,0.000000
58.860004,18.562767,-41.856575,0.020691,0.001892,0.048044,82.571312,4.206383,0.480443,-41.856575,0.049206,0.000000
59.110004,19.429276,-41.856575,0.020708,0.001916,0.048677,86.425735,4.402737,0.486772,-41.856575,0.049623,0.000000
59.360004,19.669083,-41.856575,0.020738,0.001930,0.049016,87.492447,4.457078,0.490155,-41.856575,0.050039,0.000000
59.610004,19.922295,-41.856575,0.020743,0.001942,0.049336,88.618790,4.514456,0.493365,-41.856575,0.050455,0.000000
59.860004,20.232857,-41.812096,0.020764,0.001954,0.049640,90.000244,4.584831,0.496400,-41.812096,0.050871,0.000000
60.110004,20.869987,-41.901054,0.020786,0.001976,0.050186,92.834343,4.729207,0.501862,-41.901054,0.051288,0.000000
60.360004,21.418121,-41.856575,0.020799,0.001992,0.050585,95.272560,4.853415,0.505851,-41.856575,0.051704,0.000000
60.610004,21.612869,-41.812096,0.020777,0.002002,0.050863,96.138847,4.897546,0.508626,-41.812096,0.052120,0.000000
60.860004,22.042961,-41.945538,0.020794,0.002016,0.051210,98.051987,4.995007,0.512096,-41.945538,0.052537,0.000000
61.110004,23.168266,-41.812096,0.020816,0.002046,0.051964,103.057594,5.250004,0.519640,-41.812096,0.052953,0.000000
61.360004,23.200294,-41.901054,0.020812,0.002055,0.052190,103.200066,5.257262,0.521895,-41.901054,0.053369,0.000000
61.610004,23.557396,-41.945538,0.020859,0.002071,0.052597,104.788528,5.338182,0.525972,-41.945538,0.053785,0.000000
61.860004,24.261185,-41.901054,0.020859,0.002088,0.053039,107.919136,5.497663,0.530392,-41.901054,0.054202,0.000000
62.110004,24.883041,-41.901054,0.020876,0.002104,0.053447,110.685295,5.638578,0.534469,-41.901054,0.054618,0.000000
62.360004,25.539536,-41.901054,0.020876,0.002123,0.053924,113.605530,5.787342,0.539242,-41.901054,0.055034,0.000000
62.610004,25.954361,-41.856575,0.020894,0.002139,0.054323,115.450760,5.881342,0.543231,-41.856575,0.055450,0.000000
62.860004,26.618675,-41.856575,0.020898,0.002156,0.054774,118.405785,6.031878,0.547739,-41.856575,0.055867,0.000000
63.110004,27.347404,-41.856575,0.020941,0.002175,0.055251,121.647331,6.197011,0.552508,-41.856575,0.056283,0.000000
63.360004,27.686264,-41.812096,0.020932,0.002190,0.055632,123.154655,6.273797,0.556323,-41.812096,0.056699,0.000000
63.610004,27.924210,-41.856575,0.020954,0.002199,0.055867,124.213089,6.327716,0.558666,-41.856575,0.057115,0.000000
63.860004,28.581078,-41.856575,0.020988,0.002216,0.056283,127.134979,6.476565,0.562829,-41.856575,0.057540,0.000000
64.110001,29.752190,-41.856575,0.020958,0.002241,0.056924,132.344345,6.741943,0.569244,-41.856575,0.057957,0.000000
64.360001,30.082108,-41.901054,0.020993,0.002253,0.057219,133.811905,6.816703,0.572193,-41.901054,0.058373,0.000000
64.610001,30.600822,-41.945538,0.021006,0.002270,0.057653,136.119263,6.934246,0.576530,-41.945538,0.058789,0.000000
64.860001,31.375359,-41.945538,0.021014,0.002287,0.058095,139.564560,7.109758,0.580955,-41.945538,0.059205,0.000000
65.110001,31.789810,-41.945538,0.021036,0.002300,0.058416,141.408142,7.203674,0.584161,-41.945538,0.059622,0.000000
65.360001,32.375549,-41.901054,0.021027,0.002315,0.058798,144.013641,7.336404,0.587980,-41.901054,0.060038,0.000000
65.610001,32.988846,-41.901054,0.021040,0.002330,0.059188,146.741714,7.475379,0.591882,-41.901054,0.060454,0.000000
65.860001,33.901161,-41.901054,0.021075,0.002352,0.059734,150.799896,7.682113,0.597344,-41.901054,0.060871,0.000000
66.110001,34.755386,-41.856575,0.021088,0.002371,0.060229,154.599686,7.875683,0.602287,-41.856575,0.061287,0.000000
66.360001,35.106903,-41.856575,0.021096,0.002383,0.060523,156.163300,7.955338,0.605235,-41.856575,0.061703,0.000000
66.610001,35.772331,-41.901054,0.021118,0.002399,0.060940,159.123276,8.106126,0.609398,-41.901054,0.062119,0.000000
66.860001,36.830986,-41.945538,0.021131,0.002420,0.061478,163.832413,8.346021,0.614777,-41.945538,0.062536,0.000000
67.110001,37.430878,-41.856575,0.021122,0.002434,0.061833,166.500854,8.481958,0.618331,-41.856575,0.062952,0.000000
67.360001,38.034492,-41.856575,0.021131,0.002449,0.062215,169.185867,8.618739,0.622146,-41.856575,0.063368,0.000000
67.610001,39.002663,-41.945538,0.021144,0.002470,0.062735,173.492508,8.838130,0.627350,-41.945538,0.063784,0.000000
67.860001,39.556007,-41.901054,0.021165,0.002485,0.063108,175.953903,8.963520,0.631078,-41.901054,0.064201,0.000000
68.110001,40.424377,-41.901054,0.021165,0.002502,0.063550,179.816605,9.160295,0.635503,-41.901054,0.064617,0.000000
68.360001,40.794518,-41.901054,0.021187,0.002514,0.063845,181.463074,9.244170,0.638451,-41.901054,0.065033,0.000000
68.610001,41.660660,-41.901054,0.021165,0.002530,0.064270,185.315872,9.440440,0.642702,-41.901054,0.065450,0.000000
68.860001,42.636276,-41.945538,0.021200,0.002551,0.064799,189.655624,9.661518,0.647989,-41.945538,0.065874,0.000000
69.110001,43.022049,-41.945538,0.021182,0.002560,0.065016,191.371628,9.748936,0.650158,-41.945538,0.066291,0.000000
69.360001,43.779083,-41.901054,0.021213,0.002575,0.065415,194.739090,9.920483,0.654147,-41.901054,0.066707,0.000000
69.610001,44.998230,-41.901054,0.021200,0.002600,0.066039,200.162125,10.196745,0.660392,-41.901054,0.067123,0.000000
69.860001,45.700897,-41.901054,0.021213,0.002612,0.066351,203.287750,10.355971,0.663515,-41.901054,0.067540,0.000000
70.110001,46.243446,-41.945538,0.021234,0.002626,0.066698,205.701126,10.478914,0.666982,-41.945538,0.067956,0.000000
70.360001,46.540596,-41.945538,0.021247,0.002635,0.066924,207.022903,10.546250,0.669238,-41.945538,0.068372,0.000000
70.610001,47.911674,-41.901054,0.021230,0.002658,0.067513,213.121765,10.856940,0.675134,-41.901054,0.068788,0.000000
70.860001,49.190773,-41.945538,0.021260,0.002681,0.068103,218.811493,11.146788,0.681031,-41.945538,0.069205,0.000000
71.110001,49.658844,-41.945538,0.021260,0.002690,0.068337,220.893570,11.252854,0.683374,-41.945538,0.069621,0.000000
71.360001,50.360023,-41.945538,0.021264,0.002705,0.068719,224.012573,11.411744,0.687189,-41.945538,0.070037,0.000000
71.610001,51.050026,-41.945538,0.021295,0.002723,0.069152,227.081863,11.568101,0.691523,-41.945538,0.070453,0.000000
71.860001,52.465416,-41.945538,0.021269,0.002745,0.069716,233.377823,11.888833,0.697163,-41.945538,0.070870,0.000000
72.110001,53.069405,-41.901054,0.021290,0.002756,0.070002,236.064499,12.025700,0.700024,-41.901054,0.071286,0.000000
72.360001,53.999222,-41.901054,0.021295,0.002773,0.070444,240.200531,12.236398,0.704445,-41.901054,0.071702,0.000000
72.610001,55.476051,-41.945538,0.021290,0.002797,0.071043,246.769806,12.571053,0.710429,-41.945538,0.072119,0.000000
72.860001,56.323944,-41.945538,0.021333,0.002813,0.071442,250.541412,12.763188,0.714418,-41.945538,0.072534,0.000000
73.110001,57.105919,-41.945538,0.021303,0.002828,0.071841,254.019821,12.940387,0.718407,-41.945538,0.072951,0.000000
73.360001,57.865936,-41.901054,0.021312,0.002842,0.072179,257.400543,13.112608,0.721791,-41.901054,0.073367,0.000000
73.610001,58.926826,-41.945538,0.021312,0.002862,0.072700,262.119629,13.353009,0.726995,-41.945538,0.073783,0.000000
73.860001,59.719604,-41.945538,0.021338,0.002877,0.073064,265.646057,13.532656,0.730636,-41.945538,0.074200,0.000000
74.110001,60.299385,-41.945538,0.021351,0.002888,0.073350,268.225067,13.664036,0.733498,-41.945538,0.074625,0.000000
74.360001,60.887733,-41.945538,0.021346,0.002899,0.073645,270.842163,13.797358,0.736446,-41.945538,0.075041,0.000000
74.610001,62.956268,-41.990017,0.021368,0.002929,0.074408,280.043457,14.266094,0.744080,-41.990017,0.075457,0.000000
74.860001,63.709206,-41.945538,0.021381,0.002946,0.074833,283.392700,14.436712,0.748327,-41.945538,0.075874,0.000000
75.110001,64.455437,-41.945538,0.021346,0.002958,0.075136,286.712097,14.605810,0.751362,-41.945538,0.076290,0.000000
75.360001,65.260139,-41.990017,0.021385,0.002973,0.075509,290.291595,14.788159,0.755094,-41.990017,0.076706,0.000000
75.610001,66.380226,-41.990017,0.021394,0.002993,0.076029,295.273987,15.041974,0.760295,-41.990017,0.077122,0.000000
75.860001,67.020332,-41.901054,0.021381,0.003006,0.076342,298.121338,15.187024,0.763417,-41.901054,0.077538,0.000000
76.110001,67.205788,-41.945538,0.021385,0.002999,0.076186,298.946289,15.229050,0.761858,-41.945538,0.076489,0.000000
76.360001,66.924263,-41.945538,0.021402,0.002996,0.076108,297.694000,15.165255,0.761078,-41.945538,0.076186,0.000000
76.610001,66.555244,-41.945538,0.021415,0.002991,0.075969,296.052521,15.081634,0.759689,-41.945538,0.076186,0.000000
76.860001,66.319908,-41.990017,0.021411,0.002991,0.075969,295.005676,15.028306,0.759689,-41.990017,0.076186,0.000000
77.110001,66.134468,-41.990017,0.021407,0.002991,0.075969,294.180817,14.986284,0.759689,-41.990017,0.076186,0.000000
77.360001,65.970253,-41.990017,0.021411,0.002991,0.075969,293.450348,14.949073,0.759689,-41.990017,0.076186,0.000000
77.610001,65.813103,-41.990017,0.021381,0.002991,0.075969,292.751312,14.913463,0.759689,-41.990017,0.076186,0.000000
77.860001,65.673470,-41.990017,0.021394,0.002991,0.075969,292.130188,14.881822,0.759689,-41.990017,0.076186,0.000000
78.110001,65.555428,-41.990017,0.021424,0.002991,0.075969,291.605103,14.855073,0.759689,-41.990017,0.076186,0.000000
78.360001,65.450783,-41.990017,0.021407,0.002991,0.075969,291.139618,14.831359,0.759689,-41.990017,0.076186,0.000000
78.610001,65.347649,-41.945538,0.021433,0.002991,0.075969,290.680847,14.807989,0.759689,-41.945538,0.076186,0.000000
78.860001,65.234444,-42.034500,0.021398,0.002991,0.075969,290.177307,14.782336,0.759689,-42.034500,0.076186,0.000000
79.110001,65.164070,-41.945538,0.021415,0.002991,0.075969,289.864258,14.766389,0.759689,-41.945538,0.076186,0.000000
79.360001,65.070595,-41.990017,0.021398,0.002991,0.075969,289.448456,14.745208,0.759689,-41.990017,0.076186,0.000000
79.610001,64.995750,-41.990017,0.021420,0.002991,0.075969,289.115540,14.728248,0.759689,-41.990017,0.076186,0.000000
79.860001,64.938026,-41.990017,0.021420,0.002991,0.075969,288.858765,14.715167,0.759689,-41.990017,0.076186,0.000000
80.110001,64.852760,-41.990017,0.021415,0.002991,0.075969,288.479492,14.695846,0.759689,-41.990017,0.076186,0.000000
80.360001,64.792442,-42.034500,0.021411,0.002991,0.075969,288.211182,14.682177,0.759689,-42.034500,0.076186,0.000000
80.610001,64.732857,-42.034500,0.021411,0.002991,0.075969,287.946136,14.668674,0.759689,-42.034500,0.076186,0.000000
80.860001,64.669182,-41.990017,0.021415,0.002991,0.075969,287.662903,14.654246,0.759689,-41.990017,0.076186,0.000000
81.110001,64.623756,-41.990017,0.021407,0.002991,0.075969,287.460815,14.643952,0.759689,-41.990017,0.076186,0.000000
81.360001,64.563423,-41.990017,0.021411,0.002991,0.075969,287.192444,14.630281,0.759689,-41.990017,0.076186,0.000000
81.610001,64.508690,-41.990017,0.021420,0.002991,0.075969,286.948975,14.617878,0.759689,-41.990017,0.076186,0.000000
81.860001,64.474052,-42.034500,0.021428,0.002991,0.075969,286.794922,14.610029,0.759689,-42.034500,0.076186,0.000000
82.110001,64.419319,-42.034500,0.021398,0.002991,0.075969,286.551453,14.597626,0.759689,-42.034500,0.076186,0.000000
82.360001,64.357506,-42.034500,0.021415,0.002991,0.075969,286.276489,14.583619,0.759689,-42.034500,0.076186,0.000000
82.610001,64.329582,-42.034500,0.021411,0.002991,0.075969,286.152283,14.577291,0.759689,-42.034500,0.076186,0.000000
82.860001,64.282280,-41.990017,0.021411,0.002991,0.075969,285.941864,14.566572,0.759689,-41.990017,0.076186,0.000000
83.110001,64.262550,-41.990017,0.021420,0.002991,0.075969,285.854095,14.562102,0.759689,-41.990017,0.076186,0.000000
83.360001,64.199242,-41.990017,0.021415,0.002991,0.075969,285.572479,14.547755,0.759689,-41.990017,0.076186,0.000000
83.610001,64.181374,-42.034500,0.021433,0.002991,0.075969,285.493011,14.543708,0.759689,-42.034500,0.076186,0.000000
83.860001,64.157539,-42.034500,0.021424,0.002991,0.075969,285.386993,14.538306,0.759689,-42.034500,0.076186,0.000000
84.110001,64.116951,-41.990017,0.021420,0.002991,0.075969,285.206451,14.529109,0.759689,-41.990017,0.076186,0.000000
84.360001,64.070778,-42.034500,0.021411,0.002991,0.075969,285.001068,14.518645,0.759689,-42.034500,0.076186,0.000000
84.610001,64.028694,-41.990017,0.021424,0.002991,0.075969,284.813843,14.509109,0.759689,-41.990017,0.076186,0.000000
84.860001,64.010460,-42.034500,0.021420,0.002991,0.075969,284.732758,14.504977,0.759689,-42.034500,0.076186,0.000000
85.110001,63.976936,-42.034500,0.021398,0.002991,0.075969,284.583618,14.497381,0.759689,-42.034500,0.076186,0.000000
85.360001,63.934868,-42.034500,0.021428,0.002991,0.075969,284.396484,14.487848,0.759689,-42.034500,0.076186,0.000000
85.610001,63.912895,-41.990017,0.021407,0.002991,0.075969,284.298767,14.482869,0.759689,-41.990017,0.076186,0.000000
85.860001,63.894279,-41.990017,0.021415,0.002991,0.075969,284.215942,14.478651,0.759689,-41.990017,0.076186,0.000000
86.110001,63.863365,-42.034500,0.021398,0.002991,0.075969,284.078430,14.471645,0.759689,-42.034500,0.076186,0.000000
86.360001,63.836922,-42.034500,0.021428,0.002991,0.075969,283.960815,14.465653,0.759689,-42.034500,0.076186,0.000000
86.610001,63.804161,-42.034500,0.021415,0.002991,0.075969,283.815094,14.458230,0.759689,-42.034500,0.076186,0.000000
86.860001,63.783302,-42.034500,0.021420,0.002991,0.075969,283.722290,14.453503,0.759689,-42.034500,0.076186,0.000000
87.110001,63.754631,-42.078979,0.021433,0.002991,0.075969,283.594757,14.447006,0.759689,-42.078979,0.076186,0.000000
87.360001,63.724846,-42.034500,0.021428,0.002991,0.075969,283.462280,14.440256,0.759689,-42.034500,0.076186,0.000000
87.610001,63.717018,-42.034500,0.021420,0.002991,0.075969,283.427460,14.438482,0.759689,-42.034500,0.076186,0.000000
87.860001,63.690208,-42.078979,0.021411,0.002991,0.075969,283.308197,14.432407,0.759689,-42.078979,0.076186,0.000000
88.110001,63.660423,-41.990017,0.021411,0.002991,0.075969,283.175720,14.425658,0.759689,-41.990017,0.076186,0.000000
88.360001,63.641808,-42.123459,0.021415,0.002991,0.075969,283.092896,14.421439,0.759689,-42.123459,0.076186,0.000000
88.610001,63.619469,-42.034500,0.021415,0.002991,0.075969,282.993530,14.416377,0.759689,-42.034500,0.076186,0.000000
88.860001,63.592644,-42.034500,0.021420,0.002991,0.075969,282.874207,14.410298,0.759689,-42.034500,0.076186,0.000000
89.110001,63.585579,-42.034500,0.021420,0.002991,0.075969,282.842773,14.408698,0.759689,-42.034500,0.076186,0.000000
89.360001,63.550194,-42.123459,0.021433,0.002991,0.075969,282.685394,14.400680,0.759689,-42.123459,0.076186,0.000000
89.610001,63.533821,-42.078979,0.021411,0.002991,0.075969,282.612549,14.396970,0.759689,-42.078979,0.076186,0.000000
89.860001,63.505882,-42.034500,0.021458,0.002991,0.075969,282.488281,14.390638,0.759689,-42.034500,0.076186,0.000000
90.110001,63.477592,-42.123459,0.021433,0.002991,0.075969,282.362427,14.384228,0.759689,-42.123459,0.076186,0.000000
90.360001,63.474236,-42.034500,0.021424,0.002991,0.075969,282.347504,14.383468,0.759689,-42.034500,0.076186,0.000000
90.610001,63.465294,-42.123459,0.021437,0.002991,0.075969,282.307739,14.381441,0.759689,-42.123459,0.076186,0.000000
90.860001,63.440720,-42.078979,0.021411,0.002991,0.075969,282.198425,14.375873,0.759689,-42.078979,0.076186,0.000000
91.110001,63.418381,-42.034500,0.021420,0.002991,0.075969,282.099060,14.370811,0.759689,-42.034500,0.076186,0.000000
91.360001,63.415031,-42.078979,0.021428,0.002991,0.075969,282.084137,14.370051,0.759689,-42.078979,0.076186,0.000000
91.610001,63.382629,-42.078979,0.021437,0.002991,0.075969,281.940002,14.362710,0.759689,-42.078979,0.076186,0.000000
91.860001,63.377419,-42.123459,0.021415,0.002991,0.075969,281.916840,14.361528,0.759689,-42.123459,0.076186,0.000000
92.110001,63.337204,-42.078979,0.021441,0.002991,0.075969,281.737946,14.352415,0.759689,-42.078979,0.076186,0.000000
92.360001,63.336082,-42.034500,0.021428,0.002991,0.075969,281.732971,14.352161,0.759689,-42.034500,0.076186,0.000000
92.610001,63.329758,-42.123459,0.021411,0.002991,0.075969,281.704834,14.350729,0.759689,-42.123459,0.076186,0.000000
92.860001,63.299225,-42.167942,0.021428,0.002991,0.075969,281.569000,14.343809,0.759689,-42.167942,0.076186,0.000000
93.110001,63.295494,-42.078979,0.021402,0.002991,0.075969,281.552429,14.342964,0.759689,-42.078979,0.076186,0.000000
93.360008,63.289909,-42.078979,0.021420,0.002991,0.075969,281.527588,14.341699,0.759689,-42.078979,0.076186,0.000000
93.610008,63.250069,-42.167942,0.021415,0.002991,0.075969,281.350372,14.332671,0.759689,-42.167942,0.076186,0.000000
93.860008,63.249321,-42.034500,0.021420,0.002991,0.075969,281.347046,14.332501,0.759689,-42.034500,0.076186,0.000000
94.110008,63.229591,-42.078979,0.021415,0.002991,0.075969,281.259277,14.328030,0.759689,-42.078979,0.076186,0.000000
94.360008,63.219536,-42.078979,0.021420,0.002991,0.075969,281.214539,14.325751,0.759689,-42.078979,0.076186,0.000000
94.610008,63.208359,-42.078979,0.021420,0.002991,0.075969,281.164825,14.323218,0.759689,-42.078979,0.076186,0.000000
94.860008,63.169632,-42.078979,0.021428,0.002991,0.075969,280.992554,14.314444,0.759689,-42.078979,0.076186,0.000000
95.110008,63.175591,-42.034500,0.021411,0.002991,0.075969,281.019073,14.315793,0.759689,-42.034500,0.076186,0.000000
95.360008,63.162560,-42.034500,0.021428,0.002991,0.075969,280.961090,14.312840,0.759689,-42.034500,0.076186,0.000000
95.610008,63.140961,-42.123459,0.021415,0.002991,0.075969,280.865021,14.307946,0.759689,-42.123459,0.076186,0.000000
95.860008,63.129044,-42.034500,0.021428,0.002991,0.075969,280.812012,14.305246,0.759689,-42.034500,0.076186,0.000000
96.110008,63.123833,-42.123459,0.021420,0.002991,0.075969,280.788818,14.304065,0.759689,-42.123459,0.076186,0.000000
96.360008,63.105591,-42.167942,0.021420,0.002991,0.075969,280.707703,14.299932,0.759689,-42.167942,0.076186,0.000000
96.610008,63.083992,-42.078979,0.021428,0.002991,0.075969,280.611603,14.295037,0.759689,-42.078979,0.076186,0.000000
96.860008,63.080635,-42.123459,0.021433,0.002991,0.075969,280.596680,14.294276,0.759689,-42.123459,0.076186,0.000000
97.110008,63.078033,-42.167942,0.021415,0.002991,0.075969,280.585114,14.293686,0.759689,-42.167942,0.076186,0.000000
97.360008,63.051590,-42.078979,0.021428,0.002991,0.075969,280.467468,14.287695,0.759689,-42.078979,0.076186,0.000000
97.610008,63.047501,-42.123459,0.021424,0.002991,0.075969,280.449280,14.286768,0.759689,-42.123459,0.076186,0.000000
97.860008,63.046753,-42.078979,0.021411,0.002991,0.075969,280.445953,14.286599,0.759689,-42.078979,0.076186,0.000000
98.110008,63.010635,-42.123459,0.021433,0.002991,0.075969,280.285309,14.278414,0.759689,-42.123459,0.076186,0.000000
98.360008,63.017708,-42.078979,0.021411,0.002991,0.075969,280.316772,14.280017,0.759689,-42.078979,0.076186,0.000000
98.610008,63.004303,-42.123459,0.021415,0.002991,0.075969,280.257141,14.276979,0.759689,-42.123459,0.076186,0.000000
98.860008,62.983818,-42.123459,0.021428,0.002991,0.075969,280.166016,14.272338,0.759689,-42.123459,0.076186,0.000000
99.110008,62.964828,-42.123459,0.021415,0.002991,0.075969,280.081543,14.268034,0.759689,-42.123459,0.076186,0.000000
99.360008,62.962593,-42.167942,0.021402,0.002991,0.075969,280.071594,14.267528,0.759689,-42.167942,0.076186,0.000000
99.610008,62.943230,-42.123459,0.021428,0.002991,0.075969,279.985474,14.263140,0.759689,-42.123459,0.076186,0.000000
99.860008,62.958870,-42.123459,0.021411,0.002991,0.075969,280.055054,14.266684,0.759689,-42.123459,0.076186,0.000000
100.110008,62.935783,-42.123459,0.021441,0.002991,0.075969,279.952332,14.261453,0.759689,-42.123459,0.076186,0.000000
100.360008,62.909721,-42.078979,0.021411,0.002991,0.075969,279.836426,14.255547,0.759689,-42.078979,0.076186,0.000000
100.610008,62.925362,-42.167942,0.021394,0.002991,0.075969,279.905975,14.259091,0.759689,-42.167942,0.076186,0.000000
100.860008,62.898552,-42.123459,0.021411,0.002991,0.075969,279.786743,14.253016,0.759689,-42.123459,0.076186,0.000000
101.110008,62.881050,-42.123459,0.021398,0.002991,0.075969,279.708893,14.249049,0.759689,-42.123459,0.076186,0.000000
101.360008,62.885887,-42.123459,0.021394,0.002991,0.075969,279.730408,14.250145,0.759689,-42.123459,0.076186,0.000000
101.610008,62.874344,-42.123459,0.021415,0.002991,0.075969,279.679047,14.247530,0.759689,-42.123459,0.076186,0.000000
101.860008,62.846786,-42.167942,0.021424,0.002991,0.075969,279.556458,14.241285,0.759689,-42.167942,0.076186,0.000000
102.110008,62.854980,-42.167942,0.021424,0.002991,0.075969,279.592926,14.243142,0.759689,-42.167942,0.076186,0.000000
102.360008,62.850510,-42.167942,0.021415,0.002991,0.075969,279.573029,14.242129,0.759689,-42.167942,0.076186,0.000000
102.610008,62.828918,-42.212421,0.021428,0.002991,0.075969,279.476990,14.237237,0.759689,-42.212421,0.076186,0.000000
102.860008,62.832268,-42.123459,0.021420,0.002991,0.075969,279.491882,14.237996,0.759689,-42.123459,0.076186,0.000000
103.110008,62.812157,-42.123459,0.021415,0.002991,0.075969,279.402435,14.233438,0.759689,-42.123459,0.076186,0.000000
103.360008,62.795776,-42.123459,0.021402,0.002991,0.075969,279.329559,14.229726,0.759689,-42.123459,0.076186,0.000000
103.610008,62.800987,-42.078979,0.021402,0.002991,0.075969,279.352753,14.230907,0.759689,-42.078979,0.076186,0.000000
103.860008,62.793167,-42.123459,0.021415,0.002991,0.075969,279.317963,14.229136,0.759689,-42.123459,0.076186,0.000000
104.110008,62.775665,-42.167942,0.021437,0.002991,0.075969,279.240112,14.225169,0.759689,-42.167942,0.076186,0.000000
104.360008,62.765236,-42.123459,0.021428,0.002991,0.075969,279.193726,14.222806,0.759689,-42.123459,0.076186,0.000000
104.610008,62.741409,-42.167942,0.021428,0.002991,0.075969,279.087738,14.217406,0.759689,-42.167942,0.076186,0.000000
104.860008,62.758163,-42.078979,0.021445,0.002991,0.075969,279.162262,14.221204,0.759689,-42.078979,0.076186,0.000000
105.110008,62.741035,-42.167942,0.021420,0.002991,0.075969,279.086060,14.217321,0.759689,-42.167942,0.076186,0.000000
105.360008,62.733963,-42.167942,0.021398,0.002991,0.075969,279.054596,14.215719,0.759689,-42.167942,0.076186,0.000000
105.610008,62.735077,-42.167942,0.021415,0.002991,0.075969,279.059570,14.215971,0.759689,-42.167942,0.076186,0.000000
105.860008,62.713852,-42.078979,0.021415,0.002991,0.075969,278.965149,14.211162,0.759689,-42.078979,0.076186,0.000000
106.110008,62.704170,-42.167942,0.021420,0.002991,0.075969,278.922089,14.208968,0.759689,-42.167942,0.076186,0.000000
106.360008,62.699326,-42.212421,0.021411,0.002991,0.075969,278.900543,14.207870,0.759689,-42.212421,0.076186,0.000000
106.400002,62.693375,-42.078979,0.021428,0.002991,0.075969,278.874054,14.206522,0.759689,-42.078979,0.076186,0.000000