File: Data/Polished Pin I-18 - 1_08162023_160535.csv
Time (sec),S:Load (lbs),S:HL1 (DIM),S:LVDT (in),S:Position (in),Ch:Position (mm),Ch:Load (N),Ch:Stress (MPa),Ch:Strain (mm/mm),Ch:HL1 (DIM),Set Point (),Cycles ()
0.010000,0.013778,-20.950527,-0.000013,-0.000000,-0.000000,0.061287,0.003122,-0.000000,-20.950527,0.000226,0.000000
0.250000,0.005213,-20.906048,-0.000009,-0.000000,-0.000000,0.023190,0.001181,-0.000000,-20.906048,0.000226,0.000000
0.490000,-0.004468,-20.906048,-0.000039,0.000066,0.001674,-0.019877,-0.001013,0.016737,-20.906048,0.002272,0.000000
0.730000,0.045802,-20.906048,-0.000026,0.000199,0.005056,0.203737,0.010379,0.050559,-20.906048,0.006262,0.000000
0.970000,0.085273,-20.906048,0.000138,0.000359,0.009123,0.379315,0.019323,0.091231,-20.906048,0.010268,0.000000
1.210000,0.078198,-20.950527,0.000315,0.000514,0.013060,0.347843,0.017720,0.130602,-20.950527,0.014257,0.000000
1.450000,0.064793,-20.906048,0.000453,0.000674,0.017127,0.288213,0.014682,0.171274,-20.906048,0.018264,0.000000
1.690000,0.023087,-20.995008,0.000629,0.000830,0.021074,0.102697,0.005232,0.210735,-20.995008,0.022253,0.000000
1.930000,0.045802,-20.995008,0.000776,0.000987,0.025071,0.203737,0.010379,0.250711,-20.995008,0.026260,0.000000
2.170000,0.096444,-21.039490,0.000927,0.001139,0.028922,0.429007,0.021855,0.289219,-21.039490,0.030249,0.000000
2.410000,0.088997,-21.039490,0.001112,0.001299,0.032998,0.395879,0.020167,0.329982,-21.039490,0.034256,0.000000
2.650000,0.052132,-21.039490,0.001276,0.001462,0.037134,0.231896,0.011813,0.371344,-21.039490,0.038245,0.000000
2.890000,0.075219,-21.039490,0.001457,0.001615,0.041028,0.334592,0.017045,0.410283,-21.039490,0.042252,0.000000
3.130000,0.102775,-21.039490,0.001587,0.001774,0.045052,0.457165,0.023289,0.450524,-21.039490,0.046241,0.000000
3.370000,0.078198,-21.083971,0.001763,0.001934,0.049111,0.347843,0.017720,0.491113,-21.083971,0.050247,0.000000
3.610000,0.056228,-21.083971,0.001932,0.002088,0.053039,0.250116,0.012742,0.530392,-21.083971,0.054236,0.000000
3.850000,0.043568,-21.039490,0.002100,0.002243,0.056968,0.193798,0.009873,0.569680,-21.039490,0.058243,0.000000
4.090000,0.087508,-21.083971,0.002272,0.002406,0.061113,0.389253,0.019829,0.611132,-21.083971,0.062232,0.000000
4.330000,0.095700,-21.128452,0.002393,0.002555,0.064903,0.425694,0.021686,0.649034,-21.128452,0.066239,0.000000
4.570000,0.077081,-21.083971,0.002600,0.002722,0.069135,0.342874,0.017467,0.691349,-21.083971,0.070228,0.000000
4.810000,0.081177,-21.172934,0.002708,0.002876,0.073046,0.361094,0.018395,0.730462,-21.172934,0.074235,0.000000
5.050000,0.091976,-21.128452,0.002923,0.003032,0.077018,0.409130,0.020842,0.770181,-21.128452,0.078241,0.000000
5.290000,0.099423,-21.172934,0.003061,0.003190,0.081016,0.442258,0.022530,0.810164,-21.172934,0.082231,0.000000
5.530000,0.081550,-21.172934,0.003238,0.003350,0.085084,0.362751,0.018479,0.850837,-21.172934,0.086237,0.000000
5.770000,0.051760,-21.128452,0.003410,0.003505,0.089029,0.230239,0.011729,0.890291,-21.128452,0.090226,0.000000
6.010000,0.089369,-21.261894,0.003592,0.003661,0.092993,0.397535,0.020251,0.929926,-21.261894,0.094233,0.000000
6.250000,0.075219,-21.217413,0.003764,0.003820,0.097017,0.334592,0.017045,0.970167,-21.217413,0.098222,0.000000
6.490000,0.092348,-21.261894,0.003915,0.003976,0.100989,0.410786,0.020926,1.009886,-21.261894,0.102228,0.000000
6.730000,0.087880,-21.261894,0.004083,0.004135,0.105030,0.390909,0.019914,1.050301,-21.261894,0.106218,0.000000
6.970000,0.083039,-21.261894,0.004277,0.004293,0.109053,0.369376,0.018817,1.090534,-21.261894,0.110224,0.000000
7.210001,0.096072,-21.261894,0.004441,0.004444,0.112869,0.427350,0.021770,1.128694,-21.261894,0.114214,0.000000
7.450000,0.115063,-21.261894,0.004613,0.004612,0.117136,0.511826,0.026074,1.171364,-21.261894,0.118220,0.000000
7.690001,0.072613,-21.306376,0.004764,0.004764,0.121013,0.322997,0.016454,1.210129,-21.306376,0.122210,0.000000
7.930000,0.090114,-21.395338,0.004932,0.004920,0.124958,0.400848,0.020420,1.249583,-21.395338,0.126216,0.000000
8.170000,0.087135,-21.350857,0.005101,0.005076,0.128939,0.387597,0.019745,1.289393,-21.350857,0.130205,0.000000
8.410001,0.081177,-21.350857,0.005260,0.005240,0.133084,0.361094,0.018395,1.330845,-21.350857,0.134212,0.000000
8.650001,0.088997,-21.350857,0.005441,0.005396,0.137056,0.395879,0.020167,1.370564,-21.350857,0.138201,0.000000
8.890000,0.070006,-21.395338,0.005609,0.005549,0.140933,0.311403,0.015864,1.409328,-21.395338,0.142208,0.000000
9.130000,0.093093,-21.439819,0.005764,0.005707,0.144957,0.414099,0.021095,1.449569,-21.439819,0.146197,0.000000
9.370001,0.103892,-21.350857,0.005963,0.005864,0.148955,0.462134,0.023542,1.489545,-21.350857,0.150204,0.000000
9.610001,0.076709,-21.484299,0.006109,0.006028,0.153117,0.341217,0.017382,1.531172,-21.484299,0.154193,0.000000
9.850000,0.075219,-21.439819,0.006239,0.006177,0.156907,0.334592,0.017045,1.569074,-21.439819,0.158200,0.000000
10.090000,0.088625,-21.439819,0.006450,0.006341,0.161070,0.394222,0.020083,1.610700,-21.439819,0.162206,0.000000
10.330001,0.068517,-21.484299,0.006635,0.006497,0.165024,0.304777,0.015526,1.650244,-21.484299,0.166195,0.000000
10.570001,0.066655,-21.439819,0.006795,0.006655,0.169049,0.296495,0.015104,1.690485,-21.439819,0.170201,0.000000
10.810000,0.079688,-21.528780,0.006954,0.006812,0.173020,0.354469,0.018057,1.730204,-21.528780,0.174191,0.000000
11.050000,0.101658,-21.528780,0.007101,0.006968,0.176983,0.452196,0.023036,1.769832,-21.528780,0.178197,0.000000
11.290001,0.112829,-21.528780,0.007291,0.007120,0.180842,0.501888,0.025567,1.808423,-21.528780,0.182187,0.000000
11.530001,0.108733,-21.573261,0.007476,0.007288,0.185127,0.483667,0.024639,1.851268,-21.573261,0.186193,0.000000
11.770000,0.087508,-21.528780,0.007618,0.007444,0.189081,0.389253,0.019829,1.890812,-21.528780,0.190183,0.000000
12.010000,0.094210,-21.573261,0.007756,0.007598,0.192993,0.419068,0.021348,1.929926,-21.573261,0.194189,0.000000
12.250001,0.091976,-21.617743,0.007959,0.007755,0.196982,0.409130,0.020842,1.969818,-21.617743,0.198179,0.000000
12.490001,0.081922,-21.528780,0.008114,0.007918,0.201127,0.364407,0.018564,2.011271,-21.528780,0.202185,0.000000
12.730000,0.049153,-21.617743,0.008274,0.008072,0.205029,0.218644,0.011138,2.050293,-21.617743,0.206175,0.000000
12.970000,0.084901,-21.617743,0.008433,0.008227,0.208958,0.377658,0.019239,2.089580,-21.617743,0.210181,0.000000
13.210001,0.126607,-21.617743,0.008589,0.008380,0.212844,0.563174,0.028689,2.128436,-21.617743,0.214170,0.000000
13.450001,0.119159,-21.706703,0.008783,0.008542,0.216962,0.530047,0.027002,2.169623,-21.706703,0.218176,0.000000
13.690001,0.103520,-21.662224,0.008955,0.008703,0.221047,0.460478,0.023458,2.210469,-21.662224,0.222166,0.000000
13.930000,0.091976,-21.662224,0.009132,0.008864,0.225141,0.409130,0.020842,2.251407,-21.662224,0.226172,0.000000
14.170001,0.121021,-21.662224,0.009253,0.009011,0.228887,0.538329,0.027424,2.288870,-21.662224,0.230162,0.000000
14.410001,0.086390,-21.662224,0.009447,0.009173,0.232997,0.384284,0.019576,2.329974,-21.662224,0.234168,0.000000
14.650001,0.044685,-21.751184,0.009610,0.009334,0.237082,0.198768,0.010126,2.370820,-21.751184,0.238175,0.000000
14.890000,0.058835,-21.706703,0.009779,0.009488,0.240993,0.261710,0.013332,2.409934,-21.706703,0.242164,0.000000
15.130001,0.105754,-21.751184,0.009912,0.009642,0.244913,0.470416,0.023964,2.449130,-21.751184,0.246171,0.000000
15.370001,0.135171,-21.751184,0.010059,0.009795,0.248799,0.601272,0.030630,2.487986,-21.751184,0.250160,0.000000
15.610001,0.123628,-21.706703,0.010253,0.009963,0.253057,0.549923,0.028014,2.530566,-21.706703,0.254166,0.000000
15.850000,0.114691,-21.706703,0.010404,0.010116,0.256950,0.510170,0.025989,2.569505,-21.706703,0.258156,0.000000
16.090000,0.106126,-21.795666,0.010568,0.010276,0.261018,0.472073,0.024049,2.610177,-21.795666,0.262162,0.000000
16.330000,0.118042,-21.751184,0.010731,0.010428,0.264868,0.525078,0.026749,2.648685,-21.751184,0.266152,0.000000
16.570002,0.100541,-21.795666,0.010887,0.010589,0.268970,0.447227,0.022783,2.689698,-21.795666,0.270158,0.000000
16.810001,0.054366,-21.795666,0.011042,0.010748,0.272994,0.241834,0.012320,2.729939,-21.795666,0.274148,0.000000
17.050001,0.124372,-21.751184,0.011232,0.010908,0.277061,0.553236,0.028183,2.770611,-21.751184,0.278154,0.000000
17.290001,0.140757,-21.795666,0.011374,0.011057,0.280842,0.626117,0.031896,2.808422,-21.795666,0.282143,0.000000
17.530001,0.133309,-21.884628,0.011551,0.011218,0.284927,0.592990,0.030208,2.849269,-21.884628,0.286150,0.000000
17.770000,0.110222,-21.840147,0.011736,0.011378,0.289012,0.490293,0.024977,2.890115,-21.840147,0.290139,0.000000
18.010000,0.140384,-21.884628,0.011883,0.011539,0.293096,0.624461,0.031812,2.930962,-21.884628,0.294145,0.000000
18.250000,0.137778,-21.929110,0.012038,0.011694,0.297016,0.612866,0.031221,2.970159,-21.929110,0.298135,0.000000
18.490002,0.125862,-21.884628,0.012227,0.011852,0.301040,0.559862,0.028521,3.010400,-21.884628,0.302141,0.000000
18.730001,0.074102,-21.929110,0.012340,0.012007,0.304986,0.329623,0.016792,3.049861,-21.929110,0.306131,0.000000
18.970001,0.081550,-21.884628,0.012547,0.012163,0.308932,0.362751,0.018479,3.089322,-21.884628,0.310137,0.000000
19.210001,0.159375,-21.929110,0.012693,0.012320,0.312921,0.708937,0.036115,3.129207,-21.929110,0.314144,0.000000
19.450001,0.130703,-21.929110,0.012853,0.012474,0.316849,0.581395,0.029618,3.168494,-21.929110,0.318133,0.000000
19.690001,0.129958,-21.929110,0.013016,0.012637,0.320986,0.578082,0.029449,3.209863,-21.929110,0.322140,0.000000
19.930000,0.126607,-21.973589,0.013176,0.012794,0.324967,0.563174,0.028689,3.249665,-21.973589,0.326129,0.000000
20.170000,0.137405,-21.973589,0.013348,0.012953,0.329000,0.611210,0.031137,3.289997,-21.973589,0.330135,0.000000
20.410002,0.121393,-21.973589,0.013517,0.013113,0.333058,0.539985,0.027508,3.330579,-21.973589,0.334124,0.000000
20.650002,0.106126,-22.018070,0.013668,0.013269,0.337039,0.472073,0.024049,3.370389,-22.018070,0.338131,0.000000
20.890001,0.081177,-21.973589,0.013844,0.013422,0.340915,0.361094,0.018395,3.409153,-21.973589,0.342120,0.000000
21.130001,0.122511,-21.973589,0.014012,0.013583,0.345000,0.544954,0.027761,3.450000,-21.973589,0.346127,0.000000
21.370001,0.142619,-21.973589,0.014168,0.013735,0.348867,0.634399,0.032318,3.488674,-21.973589,0.350116,0.000000
21.610001,0.144481,-22.018070,0.014353,0.013896,0.352952,0.642681,0.032740,3.529521,-22.018070,0.354123,0.000000
21.850000,0.106871,-22.062551,0.014521,0.014056,0.357011,0.475385,0.024217,3.570110,-22.062551,0.358112,0.000000
22.090000,0.142991,-21.973589,0.014676,0.014213,0.361009,0.636056,0.032402,3.610086,-21.973589,0.362119,0.000000
22.330002,0.154162,-22.107033,0.014840,0.014367,0.364929,0.685748,0.034934,3.649290,-22.107033,0.366108,0.000000
22.570002,0.126979,-22.062551,0.015013,0.014528,0.369022,0.564831,0.028774,3.690220,-22.062551,0.370114,0.000000
22.810001,0.100541,-22.107033,0.015168,0.014683,0.372959,0.447227,0.022783,3.729590,-22.107033,0.374104,0.000000
23.050001,0.128841,-22.107033,0.015319,0.014839,0.376913,0.573113,0.029196,3.769135,-22.107033,0.378110,0.000000
23.290001,0.148204,-22.062551,0.015509,0.014998,0.380946,0.659245,0.033584,3.809459,-22.062551,0.382100,0.000000
23.530001,0.150811,-22.151514,0.015655,0.015153,0.384892,0.670840,0.034174,3.848920,-22.151514,0.386106,0.000000
23.770000,0.143736,-22.151514,0.015836,0.015314,0.388968,0.639369,0.032571,3.889683,-22.151514,0.390096,0.000000
24.010000,0.134054,-22.195995,0.016030,0.015471,0.392966,0.596303,0.030377,3.929660,-22.195995,0.394102,0.000000
24.250002,0.153045,-22.151514,0.016181,0.015623,0.396834,0.680779,0.034681,3.968341,-22.151514,0.398109,0.000000
24.490002,0.162727,-22.195995,0.016323,0.015788,0.401005,0.723845,0.036874,4.010051,-22.195995,0.402098,0.000000
24.730001,0.139267,-22.195995,0.016500,0.015942,0.404934,0.619492,0.031558,4.049338,-22.195995,0.406105,0.000000
24.970001,0.114691,-22.195995,0.016673,0.016098,0.408880,0.510170,0.025989,4.088799,-22.195995,0.410093,0.000000
25.210001,0.127724,-22.240475,0.016828,0.016254,0.412843,0.568144,0.028943,4.128427,-22.240475,0.414100,0.000000
25.450001,0.118042,-22.240475,0.016987,0.016414,0.416927,0.525078,0.026749,4.169274,-22.240475,0.418089,0.000000
25.690001,0.156769,-22.195995,0.017177,0.016572,0.420926,0.697342,0.035524,4.209258,-22.195995,0.422096,0.000000
25.930000,0.142991,-22.284956,0.017328,0.016728,0.424898,0.636056,0.032402,4.248976,-22.284956,0.426085,0.000000
26.170002,0.136661,-22.284956,0.017500,0.016885,0.428878,0.607897,0.030968,4.288778,-22.284956,0.430092,0.000000
26.410002,0.143363,-22.240475,0.017638,0.017036,0.432719,0.637712,0.032487,4.327195,-22.240475,0.434081,0.000000
26.650002,0.164589,-22.329437,0.017815,0.017207,0.437055,0.732127,0.037296,4.370554,-22.329437,0.438088,0.000000
26.890001,0.143736,-22.284956,0.017996,0.017357,0.440871,0.639369,0.032571,4.408714,-22.284956,0.442077,0.000000
27.130001,0.137405,-22.240475,0.018130,0.017518,0.444948,0.611210,0.031137,4.449477,-22.240475,0.446084,0.000000
27.370001,0.157141,-22.373919,0.018277,0.017671,0.448842,0.698999,0.035609,4.488416,-22.373919,0.450072,0.000000
27.610001,0.143736,-22.284956,0.018449,0.017832,0.452935,0.639369,0.032571,4.529346,-22.284956,0.454079,0.000000
27.850000,0.140384,-22.329437,0.018604,0.017988,0.456889,0.624461,0.031812,4.568891,-22.329437,0.458068,0.000000
28.090002,0.144481,-22.373919,0.018794,0.018147,0.460921,0.642681,0.032740,4.609215,-22.373919,0.462075,0.000000
28.330002,0.169802,-22.284956,0.018953,0.018299,0.464790,0.755317,0.038478,4.647896,-22.284956,0.466064,0.000000
28.570002,0.159375,-22.418400,0.019083,0.018462,0.468935,0.708937,0.036115,4.689349,-22.418400,0.470071,0.000000
28.810001,0.142619,-22.373919,0.019268,0.018621,0.472967,0.634399,0.032318,4.729673,-22.373919,0.474078,0.000000
29.050001,0.141502,-22.373919,0.019428,0.018770,0.476757,0.629430,0.032065,4.767575,-22.373919,0.478067,0.000000
29.290001,0.163472,-22.373919,0.019626,0.018934,0.480911,0.727158,0.037043,4.809110,-22.373919,0.482074,0.000000
29.530001,0.154162,-22.373919,0.019755,0.019093,0.484970,0.685748,0.034934,4.849699,-22.373919,0.486063,0.000000
29.770002,0.131075,-22.462881,0.019949,0.019249,0.488916,0.583051,0.029702,4.889161,-22.462881,0.490069,0.000000
30.010002,0.158631,-22.462881,0.020122,0.019404,0.492871,0.705624,0.035946,4.928705,-22.462881,0.494058,0.000000
30.250002,0.170919,-22.418400,0.020268,0.019562,0.496868,0.760286,0.038731,4.968681,-22.418400,0.498065,0.000000
30.490002,0.183580,-22.462881,0.020424,0.019713,0.500719,0.816603,0.041600,5.007189,-22.462881,0.502054,0.000000
30.730001,0.171664,-22.373919,0.020596,0.019881,0.504985,0.763598,0.038900,5.049852,-22.373919,0.506061,0.000000
30.970001,0.163099,-22.462881,0.020756,0.020036,0.508923,0.725501,0.036959,5.089231,-22.462881,0.510050,0.000000
31.210001,0.164589,-22.462881,0.020950,0.020190,0.512834,0.732127,0.037296,5.128336,-22.462881,0.514057,0.000000
31.450001,0.150438,-22.507360,0.021053,0.020349,0.516858,0.669184,0.034090,5.168577,-22.507360,0.518046,0.000000
31.690002,0.151556,-22.551842,0.021239,0.020510,0.520942,0.674153,0.034343,5.209424,-22.551842,0.522053,0.000000
31.930002,0.112457,-22.462881,0.021407,0.020666,0.524914,0.500232,0.025483,5.249142,-22.462881,0.526042,0.000000
32.170002,0.191399,-22.551842,0.021566,0.020822,0.528878,0.851387,0.043372,5.288777,-22.551842,0.530048,0.000000
32.410000,0.195868,-22.507360,0.021739,0.020975,0.532763,0.871264,0.044384,5.327626,-22.507360,0.534037,0.000000
32.650002,0.186931,-22.507360,0.021890,0.021140,0.536952,0.831511,0.042359,5.369517,-22.507360,0.538044,0.000000
32.890003,0.192144,-22.596323,0.022036,0.021294,0.540880,0.854700,0.043541,5.408797,-22.596323,0.542033,0.000000
33.130001,0.174643,-22.551842,0.022239,0.021454,0.544930,0.776849,0.039575,5.449303,-22.551842,0.546040,0.000000
33.370003,0.200709,-22.551842,0.022377,0.021603,0.548711,0.892797,0.045481,5.487113,-22.551842,0.550047,0.000000
33.610001,0.188793,-22.551842,0.022558,0.021768,0.552909,0.839793,0.042781,5.529088,-22.551842,0.554036,0.000000
33.850002,0.209273,-22.685286,0.022726,0.021927,0.556941,0.930894,0.047422,5.569412,-22.685286,0.558043,0.000000
34.090000,0.545526,-22.596323,0.022894,0.022082,0.560878,2.426619,0.123618,5.608783,-22.596323,0.562032,0.000000
34.330002,0.674739,-22.551842,0.022946,-0.000000,-0.000000,3.001389,0.152898,-0.000000,-22.551842,0.000269,0.000000
34.570004,0.669898,-22.640804,0.022955,-0.000000,-0.000000,2.979856,0.151801,-0.000000,-22.640804,0.000269,0.000000
34.810001,0.631916,-22.640804,0.022950,-0.000000,-0.000000,2.810903,0.143194,-0.000000,-22.640804,0.000478,0.000000
35.050003,0.645321,-22.596323,0.022946,0.000001,0.000026,2.870533,0.146232,0.000265,-22.596323,0.000876,0.000000
35.290001,0.696337,-22.685286,0.022929,0.000012,0.000304,3.097460,0.157792,0.003035,-22.685286,0.001275,0.000000
35.530003,0.771183,-22.640804,0.022942,0.000027,0.000685,3.430395,0.174753,0.006851,-22.640804,0.001674,0.000000
35.770000,0.830018,-22.640804,0.022972,0.000043,0.001084,3.692106,0.188085,0.010840,-22.640804,0.002073,0.000000
36.010002,0.937634,-22.685286,0.022985,0.000060,0.001535,4.170804,0.212471,0.015352,-22.685286,0.002481,0.000000
36.250000,1.017694,-22.640804,0.022972,0.000076,0.001926,4.526929,0.230613,0.019258,-22.640804,0.002880,0.000000
36.490002,1.099244,-22.729767,0.022998,0.000091,0.002316,4.889679,0.249092,0.023156,-22.729767,0.003278,0.000000
36.730003,1.221382,-22.685286,0.023049,0.000106,0.002680,5.432977,0.276769,0.026797,-22.685286,0.003677,0.000000
36.970001,1.374427,-22.729767,0.023028,0.000123,0.003113,6.113756,0.311450,0.031135,-22.729767,0.004076,0.000000
37.210003,1.416505,-22.729767,0.023041,0.000131,0.003322,6.300928,0.320985,0.033216,-22.729767,0.004475,0.000000
37.450001,1.574763,-22.774246,0.023045,0.000148,0.003747,7.004897,0.356846,0.037470,-22.774246,0.004874,0.000000
37.690002,1.775844,-22.774246,0.023075,0.000168,0.004258,7.899350,0.402412,0.042580,-22.774246,0.005273,0.000000
37.930000,1.913995,-22.774246,0.023071,0.000182,0.004623,8.513873,0.433717,0.046229,-22.774246,0.005680,0.000000
38.170002,2.133694,-22.818727,0.023088,0.000202,0.005143,9.491146,0.483502,0.051429,-22.818727,0.006079,0.000000
38.410004,2.268865,-22.863209,0.023118,0.000215,0.005455,10.092417,0.514132,0.054548,-22.863209,0.006478,0.000000
38.650002,2.464733,-22.729767,0.023123,0.000229,0.005828,10.963681,0.558517,0.058280,-22.729767,0.006877,0.000000
38.890003,2.683688,-22.818727,0.023140,0.000245,0.006227,11.937642,0.608132,0.062269,-22.818727,0.007276,0.000000
39.130001,2.871364,-22.774246,0.023149,0.000257,0.006540,12.772466,0.650660,0.065395,-22.774246,0.007675,0.000000
39.370003,3.086223,-22.863209,0.023174,0.000272,0.006912,13.728206,0.699348,0.069120,-22.863209,0.008074,0.000000
39.610001,3.441839,-22.907690,0.023174,0.000296,0.007519,15.310063,0.779932,0.075191,-22.907690,0.008482,0.000000
39.850002,3.622067,-22.818727,0.023161,0.000309,0.007857,16.111759,0.820772,0.078574,-22.818727,0.008881,0.000000
40.090000,3.861875,-22.907690,0.023205,0.000326,0.008282,17.178476,0.875113,0.082821,-22.907690,0.009280,0.000000
40.330002,4.136686,-22.818727,0.023205,0.000342,0.008690,18.400898,0.937386,0.086901,-22.818727,0.009679,0.000000
40.570004,4.448734,-22.907690,0.023226,0.000359,0.009124,19.788956,1.008098,0.091239,-22.907690,0.010078,0.000000
40.810001,4.628217,-22.952171,0.023230,0.000372,0.009444,20.587337,1.048769,0.094441,-22.952171,0.010477,0.000000
41.050003,4.912710,-22.863209,0.023248,0.000385,0.009774,21.852825,1.113236,0.097741,-22.863209,0.010876,0.000000
41.290001,5.138368,-22.952171,0.023239,0.000396,0.010069,22.856602,1.164371,0.100686,-22.952171,0.011274,0.000000
41.530003,5.729695,-22.907690,0.023274,0.000424,0.010763,25.486958,1.298368,0.107627,-22.907690,0.011682,0.000000
41.770000,5.835076,-22.952171,0.023282,0.000435,0.011049,25.955715,1.322247,0.110489,-22.952171,0.012081,0.000000
42.010002,6.153827,-22.952171,0.023295,0.000453,0.011508,27.373590,1.394477,0.115084,-22.952171,0.012480,0.000000
42.250004,6.398476,-22.907690,0.023321,0.000467,0.011872,28.461843,1.449915,0.118725,-22.907690,0.012878,0.000000
42.490002,6.761539,-22.996653,0.023338,0.000485,0.012324,30.076830,1.532187,0.123236,-22.996653,0.013277,0.000000
42.730003,7.129071,-22.907690,0.023347,0.000503,0.012775,31.711691,1.615471,0.127748,-22.907690,0.013676,0.000000
42.970001,7.210620,-22.952171,0.023334,0.000509,0.012922,32.074440,1.633950,0.129216,-22.952171,0.014075,0.000000
43.210003,7.509263,-22.996653,0.023360,0.000523,0.013295,33.402870,1.701623,0.132948,-22.996653,0.014474,0.000000
43.450001,8.127401,-22.996653,0.023368,0.000549,0.013945,36.152485,1.841695,0.139451,-22.996653,0.014882,0.000000
43.690002,8.281191,-22.996653,0.023373,0.000563,0.014309,36.836578,1.876545,0.143092,-22.996653,0.015281,0.000000
43.930000,8.458068,-22.996653,0.023390,0.000579,0.014700,37.623363,1.916626,0.146998,-22.996653,0.015680,0.000000
44.170002,8.841612,-23.041132,0.023412,0.000594,0.015081,39.329453,2.003538,0.150813,-23.041132,0.016079,0.000000
44.410004,9.211005,-23.085613,0.023420,0.000612,0.015550,40.972599,2.087244,0.155499,-23.085613,0.016478,0.000000
44.650002,9.474273,-22.996653,0.023442,0.000627,0.015914,42.143669,2.146901,0.159140,-22.996653,0.016877,0.000000
44.890003,9.641095,-23.085613,0.023472,0.000638,0.016200,42.885735,2.184703,0.162001,-23.085613,0.017276,0.000000
45.130001,9.979210,-23.085613,0.023459,0.000655,0.016625,44.389744,2.261321,0.166248,-23.085613,0.017675,0.000000
45.370003,10.316952,-23.085613,0.023472,0.000671,0.017050,45.892094,2.337855,0.170502,-23.085613,0.018082,0.000000
45.610001,10.729168,-23.174576,0.023502,0.000690,0.017518,47.725723,2.431264,0.175180,-23.174576,0.018481,0.000000
45.850002,10.875510,-23.130095,0.023524,0.000704,0.017891,48.376686,2.464426,0.178912,-23.130095,0.018880,0.000000
46.090004,11.091859,-23.085613,0.023515,0.000718,0.018247,49.339054,2.513451,0.182470,-23.085613,0.019279,0.000000
46.330002,11.564027,-23.130095,0.023558,0.000739,0.018759,51.439362,2.620446,0.187587,-23.130095,0.019678,0.000000
46.570004,11.666801,-23.130095,0.023532,0.000751,0.019088,51.896526,2.643735,0.190880,-23.130095,0.020077,0.000000
46.810001,11.892460,-23.130095,0.023558,0.000764,0.019400,52.900303,2.694870,0.193999,-23.130095,0.020476,0.000000
47.050003,12.237649,-23.130095,0.023562,0.000781,0.019825,54.435780,2.773091,0.198253,-23.130095,0.020874,0.000000
47.290001,12.559379,-23.174576,0.023567,0.000798,0.020276,55.866905,2.845996,0.202757,-23.174576,0.021282,0.000000
47.530003,12.834934,-23.219057,0.023606,0.000814,0.020675,57.092640,2.908437,0.206746,-23.219057,0.021681,0.000000
47.770000,13.026706,-23.174576,0.023614,0.000829,0.021057,57.945683,2.951894,0.210569,-23.174576,0.022080,0.000000
48.010002,13.228532,-23.174576,0.023618,0.000843,0.021404,58.843449,2.997628,0.214036,-23.174576,0.022478,0.000000
48.250004,13.338382,-23.174576,0.023627,0.000853,0.021663,59.332085,3.022521,0.216632,-23.174576,0.022877,0.000000
48.490002,13.921144,-23.174576,0.023644,0.000873,0.022184,61.924343,3.154577,0.221840,-23.174576,0.023276,0.000000
48.730003,13.988172,-23.219057,0.023666,0.000885,0.022478,62.222496,3.169765,0.224785,-23.219057,0.023675,0.000000
48.970001,14.319211,-23.219057,0.023670,0.000903,0.022947,63.695030,3.244780,0.229471,-23.219057,0.024074,0.000000
49.210003,14.760099,-23.263536,0.023679,0.000922,0.023416,65.656204,3.344687,0.234156,-23.263536,0.024482,0.000000
49.450001,15.097841,-23.219057,0.023696,0.000942,0.023927,67.158554,3.421220,0.239273,-23.219057,0.024881,0.000000
49.690002,15.105289,-23.219057,0.023713,0.000953,0.024204,67.191681,3.422908,0.242044,-23.219057,0.025280,0.000000
49.930004,15.362226,-23.308018,0.023735,0.000969,0.024612,68.334595,3.481130,0.246124,-23.308018,0.025679,0.000000
50.170002,15.590862,-23.219057,0.023756,0.000983,0.024967,69.351616,3.532940,0.249674,-23.219057,0.026078,0.000000
50.410004,16.084255,-23.308018,0.023769,0.001004,0.025497,71.546341,3.644744,0.254966,-23.308018,0.026477,0.000000
50.650002,16.301722,-23.219057,0.023787,0.001016,0.025800,72.513680,3.694023,0.258001,-23.219057,0.026876,0.000000
50.890003,16.603342,-23.308018,0.023782,0.001033,0.026226,73.855354,3.762371,0.262255,-23.308018,0.027275,0.000000
51.130001,16.886719,-23.352499,0.023808,0.001048,0.026607,75.115875,3.826585,0.266071,-23.352499,0.027682,0.000000
51.370003,17.251270,-23.263536,0.023830,0.001066,0.027084,76.737480,3.909194,0.270840,-23.263536,0.028081,0.000000
51.610001,17.427774,-23.396980,0.023808,0.001080,0.027422,77.522614,3.949190,0.274223,-23.396980,0.028480,0.000000
51.850002,17.812063,-23.352499,0.023825,0.001096,0.027838,79.232018,4.036271,0.278379,-23.352499,0.028879,0.000000
52.090004,17.907763,-23.352499,0.023856,0.001107,0.028125,79.657707,4.057957,0.281248,-23.352499,0.029278,0.000000
52.330002,18.460363,-23.352499,0.023856,0.001127,0.028627,82.115799,4.183178,0.286274,-23.352499,0.029677,0.000000
52.570004,18.534466,-23.308018,0.023873,0.001136,0.028853,82.445419,4.199970,0.288530,-23.308018,0.030076,0.000000
52.810001,18.831991,-23.396980,0.023877,0.001150,0.029209,83.768883,4.267390,0.292088,-23.396980,0.030484,0.000000
53.050003,19.518646,-23.352499,0.023907,0.001174,0.029824,86.823273,4.422988,0.298242,-23.352499,0.030882,0.000000
53.290001,19.946131,-23.352499,0.023920,0.001192,0.030284,88.724823,4.519858,0.302837,-23.352499,0.031281,0.000000
53.530003,20.067152,-23.441462,0.023933,0.001206,0.030622,89.263153,4.547281,0.306221,-23.441462,0.031680,0.000000
53.770004,20.384413,-23.396980,0.023955,0.001221,0.031013,90.674400,4.619174,0.310127,-23.396980,0.032079,0.000000
54.010002,20.705397,-23.441462,0.023938,0.001237,0.031420,92.102203,4.691910,0.314199,-23.441462,0.032478,0.000000
54.250004,21.231188,-23.441462,0.023976,0.001253,0.031827,94.441040,4.811056,0.318272,-23.441462,0.032877,0.000000
54.490002,21.546959,-23.441462,0.023976,0.001267,0.032183,95.845657,4.882611,0.321830,-23.441462,0.033276,0.000000
54.730003,21.863848,-23.530422,0.023998,0.001283,0.032591,97.255249,4.954419,0.325910,-23.530422,0.033683,0.000000
54.970001,22.384798,-23.530422,0.023998,0.001300,0.033024,99.572556,5.072468,0.330240,-23.530422,0.034082,0.000000
55.210003,22.995487,-23.530422,0.024024,0.001318,0.033467,102.289040,5.210852,0.334668,-23.530422,0.034481,0.000000
55.450001,23.216677,-23.485943,0.024041,0.001330,0.033788,103.272934,5.260974,0.337878,-23.485943,0.034880,0.000000
55.690002,23.702623,-23.530422,0.024028,0.001348,0.034247,105.434532,5.371091,0.342472,-23.530422,0.035279,0.000000
55.930004,23.918972,-23.530422,0.024050,0.001361,0.034577,106.396904,5.420116,0.345765,-23.530422,0.035678,0.000000
56.170002,24.372894,-23.530422,0.024071,0.001376,0.034941,108.416046,5.522976,0.349406,-23.530422,0.036077,0.000000
56.410004,25.072954,-23.530422,0.024088,0.001396,0.035461,111.530067,5.681613,0.354614,-23.530422,0.036476,0.000000
56.650002,25.147800,-23.530422,0.024097,0.001404,0.035661,111.863007,5.698573,0.356605,-23.530422,0.036883,0.000000
56.890003,25.955105,-23.530422,0.024106,0.001426,0.036233,115.454071,5.881511,0.362328,-23.530422,0.037282,0.000000
57.130001,26.489458,-23.574903,0.024097,0.001443,0.036641,117.830994,6.002597,0.366408,-23.574903,0.037681,0.000000
57.370003,26.863321,-23.530422,0.024149,0.001458,0.037031,119.494019,6.087316,0.370307,-23.530422,0.038080,0.000000
57.610004,27.400282,-23.619385,0.024145,0.001474,0.037439,121.882538,6.208993,0.374387,-23.619385,0.038479,0.000000
57.850002,27.884739,-23.574903,0.024149,0.001490,0.037846,124.037514,6.318772,0.378459,-23.574903,0.038878,0.000000
58.090004,28.384834,-23.574903,0.024179,0.001505,0.038219,126.262047,6.432095,0.382191,-23.574903,0.039277,0.000000
58.330002,28.921423,-23.708347,0.024179,0.001521,0.038626,128.648911,6.553689,0.386264,-23.708347,0.039676,0.000000
58.570004,28.869663,-23.663866,0.024179,0.001527,0.038782,128.418671,6.541959,0.387823,-23.663866,0.040084,0.000000
58.810001,29.779741,-23.619385,0.024188,0.001547,0.039286,132.466904,6.748186,0.392857,-23.619385,0.040482,0.000000
59.050003,30.646997,-23.708347,0.024205,0.001568,0.039815,136.324646,6.944709,0.398148,-23.708347,0.040881,0.000000
59.290001,31.023094,-23.663866,0.024205,0.001581,0.040153,137.997620,7.029933,0.401532,-23.663866,0.041280,0.000000
59.530003,31.801725,-23.663866,0.024231,0.001601,0.040664,141.461136,7.206374,0.406642,-23.663866,0.041679,0.000000
59.770004,32.180428,-23.619385,0.024244,0.001614,0.040985,143.145691,7.292189,0.409851,-23.619385,0.042078,0.000000
60.010002,32.747181,-23.708347,0.024239,0.001628,0.041358,145.666733,7.420617,0.413583,-23.708347,0.042477,0.000000
60.250004,33.439045,-23.708347,0.024278,0.001643,0.041740,148.744293,7.577396,0.417398,-23.708347,0.042876,0.000000
60.490002,33.831154,-23.663866,0.024278,0.001656,0.042069,150.488495,7.666249,0.420691,-23.663866,0.043283,0.000000
60.730003,34.364391,-23.752829,0.024295,0.001670,0.042425,152.860443,7.787082,0.424249,-23.752829,0.043682,0.000000
60.970001,35.583168,-23.663866,0.024300,0.001695,0.043058,158.281830,8.063261,0.430577,-23.663866,0.044081,0.000000
61.210003,36.202423,-23.752829,0.024295,0.001711,0.043457,161.036423,8.203587,0.434566,-23.752829,0.044480,0.000000
61.450005,36.853703,-23.752829,0.024295,0.001729,0.043917,163.933456,8.351168,0.439169,-23.752829,0.044879,0.000000
61.690002,37.426785,-23.708347,0.024330,0.001743,0.044264,166.482651,8.481030,0.442636,-23.708347,0.045278,0.000000
61.930004,38.090721,-23.797308,0.024330,0.001758,0.044653,169.435989,8.631480,0.446534,-23.797308,0.045677,0.000000
62.170002,38.378567,-23.752829,0.024360,0.001770,0.044957,170.716385,8.696708,0.449570,-23.752829,0.046076,0.000000
62.410004,39.127037,-23.841789,0.024351,0.001783,0.045295,174.045746,8.866314,0.452954,-23.841789,0.046484,0.000000
62.650002,39.688946,-23.797308,0.024369,0.001799,0.045686,176.545242,8.993644,0.456860,-23.797308,0.046883,0.000000
62.890003,41.246208,-23.797308,0.024377,0.001824,0.046319,183.472290,9.346524,0.463188,-23.797308,0.047282,0.000000
63.130005,41.699383,-23.841789,0.024386,0.001838,0.046692,185.488113,9.449215,0.466920,-23.841789,0.047681,0.000000
63.370003,42.476524,-23.797308,0.024420,0.001854,0.047099,188.945023,9.625318,0.470992,-23.797308,0.048080,0.000000
63.610004,43.044395,-23.886271,0.024395,0.001868,0.047446,191.471039,9.754000,0.474459,-23.886271,0.048478,0.000000
63.850002,43.738495,-23.841789,0.024416,0.001886,0.047897,194.558548,9.911284,0.478971,-23.841789,0.048877,0.000000
64.090004,44.730495,-23.841789,0.024420,0.001903,0.048339,198.971176,10.136075,0.483392,-23.841789,0.049276,0.000000
64.330002,44.856358,-23.886271,0.024438,0.001909,0.048478,199.531036,10.164596,0.484784,-23.886271,0.049684,0.000000
64.570000,45.468166,-23.886271,0.024438,0.001922,0.048808,202.252502,10.303234,0.488077,-23.886271,0.050082,0.000000
64.810005,47.055218,-23.930752,0.024420,0.001948,0.049484,209.312057,10.662865,0.494845,-23.930752,0.050481,0.000000
65.050003,47.758629,-23.930752,0.024451,0.001961,0.049822,212.440994,10.822260,0.498221,-23.930752,0.050880,0.000000
65.290001,48.270641,-23.930752,0.024451,0.001978,0.050230,214.718536,10.938283,0.502301,-23.930752,0.051279,0.000000
65.530006,49.264503,-23.975233,0.024459,0.001993,0.050612,219.139450,11.163496,0.506116,-23.975233,0.051678,0.000000
65.770004,50.285549,-23.886271,0.024481,0.002012,0.051106,223.681290,11.394869,0.511059,-23.886271,0.052077,0.000000
66.010002,51.059338,-23.886271,0.024489,0.002026,0.051453,227.123276,11.570211,0.514526,-23.886271,0.052476,0.000000
66.250000,51.538208,-24.019714,0.024472,0.002036,0.051721,229.253403,11.678725,0.517213,-24.019714,0.052884,0.000000
66.490005,52.406956,-24.019714,0.024502,0.002053,0.052147,233.117783,11.875586,0.521468,-24.019714,0.053283,0.000000
66.730003,53.487206,-24.064194,0.024507,0.002071,0.052597,237.922974,12.120375,0.525972,-24.064194,0.053682,0.000000
66.970001,54.684383,-23.975233,0.024524,0.002089,0.053057,243.248291,12.391658,0.530574,-23.975233,0.054081,0.000000
67.210007,55.286510,-23.930752,0.024520,0.002103,0.053412,245.926682,12.528102,0.534124,-23.930752,0.054480,0.000000
67.450005,55.978008,-23.975233,0.024528,0.002115,0.053733,249.002609,12.684798,0.537334,-23.975233,0.054879,0.000000
67.690002,57.215401,-24.019714,0.024528,0.002137,0.054272,254.506821,12.965195,0.542716,-24.019714,0.055278,0.000000
67.930000,58.045792,-24.019714,0.024558,0.002150,0.054609,258.200562,13.153364,0.546092,-24.019714,0.055685,0.000000
68.170006,58.735798,-24.019714,0.024554,0.002162,0.054922,261.269867,13.309722,0.549219,-24.019714,0.056084,0.000000
68.410004,59.734871,-24.019714,0.024554,0.002179,0.055347,265.713989,13.536116,0.553465,-24.019714,0.056483,0.000000
68.650002,60.880291,-24.019714,0.024576,0.002198,0.055823,270.809052,13.795671,0.558234,-24.019714,0.056882,0.000000
68.890007,61.852554,-24.019714,0.024571,0.002214,0.056240,275.133911,14.015989,0.562398,-24.019714,0.057281,0.000000
69.130005,62.649059,-24.108675,0.024593,0.002228,0.056596,278.676941,14.196480,0.565955,-24.108675,0.057680,0.000000
69.370003,63.353588,-24.064194,0.024584,0.002241,0.056916,281.810822,14.356129,0.569165,-24.064194,0.058078,0.000000
69.610001,63.887943,-24.064194,0.024593,0.002251,0.057176,284.187775,14.477215,0.571761,-24.064194,0.058477,0.000000
69.850006,65.510742,-24.108675,0.024602,0.002274,0.057757,291.406342,14.844947,0.577575,-24.108675,0.058885,0.000000
70.090004,66.173943,-24.064194,0.024597,0.002286,0.058061,294.356384,14.995230,0.580610,-24.064194,0.059284,0.000000
70.330002,67.218445,-24.153156,0.024602,0.002303,0.058486,299.002563,15.231917,0.584857,-24.153156,0.059682,0.000000
70.570000,67.075081,-24.108675,0.024619,0.002293,0.058243,298.364868,15.199430,0.582435,-24.108675,0.058547,0.000000
70.810005,66.719093,-24.197638,0.024645,0.002290,0.058174,296.781342,15.118762,0.581738,-24.197638,0.058243,0.000000
71.050003,66.405182,-24.197638,0.024623,0.002288,0.058122,295.385010,15.047629,0.581216,-24.197638,0.058243,0.000000
71.290001,66.129997,-24.108675,0.024649,0.002288,0.058104,294.160919,14.985271,0.581042,-24.108675,0.058243,0.000000
71.530006,65.919983,-24.197638,0.024653,0.002287,0.058096,293.226715,14.937681,0.580959,-24.197638,0.058243,0.000000
71.770004,65.717781,-24.153156,0.024649,0.002287,0.058087,292.327301,14.891862,0.580868,-24.153156,0.058243,0.000000
72.010002,65.536438,-24.197638,0.024632,0.002287,0.058087,291.520630,14.850769,0.580868,-24.197638,0.058243,0.000000
72.250000,65.368126,-24.197638,0.024636,0.002287,0.058078,290.771942,14.812629,0.580785,-24.197638,0.058243,0.000000
72.490005,65.229607,-24.153156,0.024636,0.002286,0.058069,290.155792,14.781240,0.580694,-24.153156,0.058243,0.000000
72.730003,65.079910,-24.197638,0.024645,0.002286,0.058069,289.489899,14.747318,0.580694,-24.197638,0.058243,0.000000
72.970001,64.962982,-24.286600,0.024645,0.002286,0.058069,288.969788,14.720822,0.580694,-24.286600,0.058243,0.000000
73.210007,64.853508,-24.197638,0.024645,0.002286,0.058061,288.482819,14.696015,0.580610,-24.197638,0.058243,0.000000
73.450005,64.748497,-24.286600,0.024649,0.002286,0.058061,288.015686,14.672219,0.580610,-24.286600,0.058243,0.000000
73.690002,64.645348,-24.242119,0.024632,0.002286,0.058061,287.556854,14.648846,0.580610,-24.242119,0.058243,0.000000
73.930000,64.556725,-24.286600,0.024623,0.002286,0.058053,287.162659,14.628763,0.580527,-24.286600,0.058243,0.000000
74.170006,64.456184,-24.286600,0.024666,0.002286,0.058053,286.715424,14.605980,0.580527,-24.286600,0.058243,0.000000
74.410004,64.377243,-24.286600,0.024632,0.002286,0.058053,286.364288,14.588092,0.580527,-24.286600,0.058243,0.000000
74.650002,64.298302,-24.286600,0.024640,0.002286,0.058053,286.013123,14.570204,0.580527,-24.286600,0.058243,0.000000
74.890007,64.225311,-24.286600,0.024649,0.002285,0.058044,285.688446,14.553664,0.580436,-24.286600,0.058243,0.000000
75.130005,64.159401,-24.331079,0.024653,0.002285,0.058044,285.395264,14.538728,0.580436,-24.331079,0.058243,0.000000
75.370003,64.089767,-24.375561,0.024653,0.002285,0.058044,285.085510,14.522949,0.580436,-24.375561,0.058243,0.000000
75.610001,64.019768,-24.331079,0.024649,0.002285,0.058044,284.774139,14.507087,0.580436,-24.331079,0.058243,0.000000
75.850006,63.962044,-24.420042,0.024662,0.002285,0.058044,284.517395,14.494006,0.580436,-24.420042,0.058243,0.000000
76.090004,63.900230,-24.331079,0.024666,0.002285,0.058044,284.242432,14.479999,0.580436,-24.331079,0.058243,0.000000
76.330002,63.837673,-24.420042,0.024645,0.002285,0.058044,283.964142,14.465824,0.580436,-24.420042,0.058243,0.000000
76.570007,63.784794,-24.375561,0.024662,0.002285,0.058044,283.728943,14.453841,0.580436,-24.375561,0.058243,0.000000
76.810005,63.725960,-24.375561,0.024649,0.002285,0.058044,283.467224,14.440509,0.580436,-24.375561,0.058243,0.000000
77.050003,63.667500,-24.375561,0.024658,0.002285,0.058044,283.207184,14.427261,0.580436,-24.375561,0.058243,0.000000
77.290001,63.617229,-24.375561,0.024662,0.002285,0.058044,282.983582,14.415870,0.580436,-24.375561,0.058243,0.000000
77.530006,63.576637,-24.464523,0.024649,0.002285,0.058044,282.803009,14.406672,0.580436,-24.464523,0.058243,0.000000
77.770004,63.528603,-24.464523,0.024671,0.002285,0.058044,282.589325,14.395786,0.580436,-24.464523,0.058243,0.000000
78.010002,63.493229,-24.420042,0.024662,0.002285,0.058044,282.431976,14.387772,0.580436,-24.420042,0.058243,0.000000
78.250000,63.431042,-24.464523,0.024662,0.002285,0.058044,282.155365,14.373680,0.580436,-24.464523,0.058243,0.000000
78.490005,63.379280,-24.464523,0.024666,0.002285,0.058044,281.925110,14.361951,0.580436,-24.464523,0.058243,0.000000
78.730003,63.347260,-24.509005,0.024649,0.002285,0.058044,281.782684,14.354694,0.580436,-24.509005,0.058243,0.000000
78.970001,63.297359,-24.464523,0.024649,0.002285,0.058044,281.560730,14.343387,0.580436,-24.464523,0.058243,0.000000
79.210007,63.257889,-24.509005,0.024645,0.002285,0.058044,281.385132,14.334443,0.580436,-24.509005,0.058243,0.000000
79.450005,63.217670,-24.509005,0.024645,0.002285,0.058044,281.206238,14.325329,0.580436,-24.509005,0.058243,0.000000
79.690002,63.185650,-24.509005,0.024662,0.002285,0.058044,281.063812,14.318072,0.580436,-24.509005,0.058243,0.000000
79.930000,63.142452,-24.553486,0.024675,0.002285,0.058044,280.871643,14.308285,0.580436,-24.553486,0.058243,0.000000
80.170006,63.104469,-24.553486,0.024671,0.002285,0.058044,280.702698,14.299677,0.580436,-24.553486,0.058243,0.000000
80.410004,63.079521,-24.509005,0.024666,0.002285,0.058044,280.591736,14.294024,0.580436,-24.509005,0.058243,0.000000
80.650002,63.035954,-24.597965,0.024658,0.002285,0.058044,280.397919,14.284151,0.580436,-24.597965,0.058243,0.000000
80.890007,63.007282,-24.553486,0.024679,0.002285,0.058044,280.270386,14.277654,0.580436,-24.553486,0.058243,0.000000
81.130005,62.971535,-24.597965,0.024662,0.002285,0.058044,280.111389,14.269554,0.580436,-24.597965,0.058243,0.000000
81.370003,62.927967,-24.553486,0.024653,0.002285,0.058044,279.917572,14.259682,0.580436,-24.553486,0.058243,0.000000
81.610001,62.913445,-24.553486,0.024679,0.002285,0.058044,279.852966,14.256391,0.580436,-24.553486,0.058243,0.000000
81.850006,62.863174,-24.642447,0.024653,0.002285,0.058044,279.629364,14.244999,0.580436,-24.642447,0.058243,0.000000
82.090004,62.841202,-24.597965,0.024683,0.002285,0.058044,279.531616,14.240020,0.580436,-24.597965,0.058243,0.000000
82.330002,62.808064,-24.642447,0.024653,0.002285,0.058044,279.384216,14.232511,0.580436,-24.642447,0.058243,0.000000
82.570007,62.775295,-24.597965,0.024658,0.002285,0.058044,279.238464,14.225085,0.580436,-24.597965,0.058243,0.000000
82.810005,62.722046,-24.642447,0.024645,0.002285,0.058044,279.001587,14.213019,0.580436,-24.642447,0.058243,0.000000
83.050003,62.713852,-24.686928,0.024653,0.002285,0.058044,278.965149,14.211162,0.580436,-24.686928,0.058243,0.000000
83.290001,62.676987,-24.642447,0.024653,0.002285,0.058044,278.801147,14.202807,0.580436,-24.642447,0.058243,0.000000
83.530006,62.653526,-24.686928,0.024653,0.002285,0.058044,278.696808,14.197493,0.580436,-24.686928,0.058243,0.000000
83.770004,62.616291,-24.686928,0.024658,0.002285,0.058044,278.531158,14.189054,0.580436,-24.686928,0.058243,0.000000
84.010002,62.593948,-24.686928,0.024671,0.002285,0.058044,278.431793,14.183991,0.580436,-24.686928,0.058243,0.000000
84.250008,62.563042,-24.686928,0.024671,0.002285,0.058044,278.294312,14.176988,0.580436,-24.686928,0.058243,0.000000
84.490005,62.541073,-24.686928,0.024671,0.002285,0.058044,278.196594,14.172010,0.580436,-24.686928,0.058243,0.000000
84.730003,62.504578,-24.731409,0.024653,0.002285,0.058044,278.034241,14.163740,0.580436,-24.731409,0.058243,0.000000
84.970001,62.481121,-24.686928,0.024666,0.002285,0.058044,277.929901,14.158424,0.580436,-24.686928,0.058243,0.000000
85.210007,62.458405,-24.686928,0.024653,0.002285,0.058035,277.828857,14.153276,0.580353,-24.686928,0.058243,0.000000
85.450005,62.420795,-24.775890,0.024666,0.002285,0.058035,277.661560,14.144754,0.580353,-24.775890,0.058243,0.000000
85.690002,62.397709,-24.775890,0.024679,0.002285,0.058035,277.558868,14.139524,0.580353,-24.775890,0.058243,0.000000
85.930000,62.377602,-24.775890,0.024649,0.002285,0.058035,277.469421,14.134967,0.580353,-24.775890,0.058243,0.000000
86.170006,62.354885,-24.820372,0.024666,0.002285,0.058035,277.368378,14.129819,0.580353,-24.820372,0.058243,0.000000
86.410004,62.319511,-24.775890,0.024653,0.002285,0.058035,277.211029,14.121803,0.580353,-24.775890,0.058243,0.000000
86.650002,62.298283,-24.864851,0.024653,0.002285,0.058035,277.116608,14.116992,0.580353,-24.864851,0.058243,0.000000
86.890007,62.271847,-24.775890,0.024662,0.002285,0.058035,276.999023,14.111002,0.580353,-24.775890,0.058243,0.000000
87.130005,62.262165,-24.820372,0.024653,0.002285,0.058035,276.955933,14.108808,0.580353,-24.820372,0.058243,0.000000
87.370003,62.225674,-24.864851,0.024671,0.002285,0.058035,276.793610,14.100539,0.580353,-24.864851,0.058243,0.000000
87.610001,62.198116,-24.864851,0.024645,0.002285,0.058035,276.671051,14.094295,0.580353,-24.864851,0.058243,0.000000
87.850006,62.188061,-24.909332,0.024658,0.002285,0.058035,276.626312,14.092015,0.580353,-24.909332,0.058243,0.000000
88.090004,62.165718,-24.820372,0.024662,0.002285,0.058035,276.526917,14.086953,0.580353,-24.820372,0.058243,0.000000
88.330002,62.129601,-24.909332,0.024662,0.002285,0.058035,276.366272,14.078769,0.580353,-24.909332,0.058243,0.000000
88.570007,62.110607,-24.953814,0.024675,0.002285,0.058035,276.281769,14.074465,0.580353,-24.953814,0.058243,0.000000
88.810005,62.095715,-24.864851,0.024662,0.002285,0.058035,276.215546,14.071090,0.580353,-24.864851,0.058243,0.000000
89.050003,62.066669,-24.953814,0.024666,0.002285,0.058035,276.086334,14.064508,0.580353,-24.953814,0.058243,0.000000
89.290001,62.044701,-24.909332,0.024675,0.002285,0.058035,275.988617,14.059530,0.580353,-24.909332,0.058243,0.000000
89.530006,62.023102,-24.998295,0.024662,0.002285,0.058035,275.892548,14.054635,0.580353,-24.998295,0.058243,0.000000
89.770004,61.999641,-24.909332,0.024679,0.002285,0.058035,275.788177,14.049320,0.580353,-24.909332,0.058243,0.000000
90.010002,61.979904,-24.953814,0.024658,0.002285,0.058035,275.700378,14.044847,0.580353,-24.953814,0.058243,0.000000
90.250008,61.965012,-24.953814,0.024666,0.002285,0.058035,275.634125,14.041472,0.580353,-24.953814,0.058243,0.000000
90.490005,61.919209,-24.953814,0.024671,0.002285,0.058035,275.430389,14.031094,0.580353,-24.953814,0.058243,0.000000
90.730003,61.941925,-24.953814,0.024649,0.002285,0.058035,275.531433,14.036241,0.580353,-24.953814,0.058243,0.000000
90.970001,61.886066,-24.998295,0.024666,0.002285,0.058035,275.282959,14.023582,0.580353,-24.998295,0.058243,0.000000
91.210007,61.880856,-24.953814,0.024662,0.002285,0.058035,275.259796,14.022403,0.580353,-24.953814,0.058243,0.000000
91.450005,61.863728,-24.998295,0.024679,0.002285,0.058035,275.183594,14.018521,0.580353,-24.998295,0.058243,0.000000
91.690002,61.843990,-24.998295,0.024671,0.002285,0.058035,275.095795,14.014049,0.580353,-24.998295,0.058243,0.000000
91.930008,61.817551,-25.042776,0.024666,0.002285,0.058035,274.978210,14.008057,0.580353,-25.042776,0.058243,0.000000
92.170006,61.796700,-25.042776,0.024649,0.002285,0.058035,274.885437,14.003332,0.580353,-25.042776,0.058243,0.000000
92.410004,61.773613,-25.042776,0.024671,0.002285,0.058035,274.782745,13.998100,0.580353,-25.042776,0.058243,0.000000
92.650002,61.756111,-25.042776,0.024658,0.002285,0.058035,274.704895,13.994135,0.580353,-25.042776,0.058243,0.000000
92.890007,61.735256,-24.998295,0.024671,0.002285,0.058035,274.612122,13.989408,0.580353,-24.998295,0.058243,0.000000
93.130005,61.720734,-25.042776,0.024645,0.002285,0.058035,274.547546,13.986118,0.580353,-25.042776,0.058243,0.000000
93.370003,61.701000,-25.087255,0.024666,0.002285,0.058035,274.459747,13.981647,0.580353,-25.087255,0.058243,0.000000
93.610008,61.696529,-25.087255,0.024675,0.002285,0.058035,274.439880,13.980634,0.580353,-25.087255,0.058243,0.000000
93.850006,61.664505,-25.087255,0.024662,0.002285,0.058035,274.297424,13.973376,0.580353,-25.087255,0.058243,0.000000
94.090004,61.660412,-25.042776,0.024666,0.002285,0.058035,274.279205,13.972449,0.580353,-25.042776,0.058243,0.000000
94.330002,61.624664,-25.220699,0.024671,0.002285,0.058035,274.120209,13.964349,0.580353,-25.220699,0.058243,0.000000
94.570007,61.620937,-25.131737,0.024675,0.002285,0.058035,274.103607,13.963504,0.580353,-25.131737,0.058243,0.000000
94.810005,61.587799,-25.176218,0.024649,0.002285,0.058035,273.956207,13.955995,0.580353,-25.176218,0.058243,0.000000
95.050003,61.565456,-25.176218,0.024649,0.002285,0.058035,273.856842,13.950932,0.580353,-25.176218,0.058243,0.000000
95.290001,61.553539,-25.042776,0.024683,0.002285,0.058035,273.803802,13.948232,0.580353,-25.042776,0.058243,0.000000
95.530006,61.535667,-25.176218,0.024666,0.002285,0.058035,273.724335,13.944182,0.580353,-25.176218,0.058243,0.000000
95.770004,61.529335,-25.265181,0.024658,0.002285,0.058035,273.696136,13.942747,0.580353,-25.265181,0.058243,0.000000
96.010002,61.511463,-25.176218,0.024662,0.002285,0.058035,273.616669,13.938697,0.580353,-25.176218,0.058243,0.000000
96.250008,61.499916,-25.220699,0.024671,0.002285,0.058035,273.565277,13.936080,0.580353,-25.220699,0.058243,0.000000
96.490005,61.476830,-25.176218,0.024649,0.002285,0.058035,273.462585,13.930848,0.580353,-25.176218,0.058243,0.000000
96.730003,61.441456,-25.265181,0.024688,0.002285,0.058035,273.305237,13.922833,0.580353,-25.265181,0.058243,0.000000
96.970001,61.437733,-25.220699,0.024688,0.002285,0.058035,273.288696,13.921988,0.580353,-25.220699,0.058243,0.000000
97.210007,61.416878,-25.220699,0.024666,0.002285,0.058035,273.195923,13.917264,0.580353,-25.220699,0.058243,0.000000
97.450005,61.422092,-25.309662,0.024662,0.002285,0.058035,273.219116,13.918446,0.580353,-25.309662,0.058243,0.000000
97.690002,61.389694,-25.265181,0.024671,0.002285,0.058035,273.075012,13.911104,0.580353,-25.265181,0.058243,0.000000
97.930008,61.351715,-25.309662,0.024679,0.002285,0.058035,272.906067,13.902497,0.580353,-25.309662,0.058243,0.000000
98.170006,61.362511,-25.309662,0.024675,0.002285,0.058035,272.954071,13.904943,0.580353,-25.309662,0.058243,0.000000
98.410004,61.345757,-25.309662,0.024679,0.002285,0.058035,272.879547,13.901148,0.580353,-25.309662,0.058243,0.000000
98.650002,61.320435,-25.309662,0.024671,0.002285,0.058035,272.766907,13.895409,0.580353,-25.309662,0.058243,0.000000
98.890007,61.304794,-25.265181,0.024666,0.002285,0.058035,272.697357,13.891865,0.580353,-25.265181,0.058243,0.000000
99.130005,61.284687,-25.398623,0.024658,0.002285,0.058035,272.607910,13.887308,0.580353,-25.398623,0.058243,0.000000
99.370003,61.276867,-25.309662,0.024675,0.002285,0.058035,272.573120,13.885536,0.580353,-25.309662,0.058243,0.000000
99.610008,61.254524,-25.354141,0.024679,0.002285,0.058035,272.473724,13.880473,0.580353,-25.354141,0.058243,0.000000
99.850006,61.241863,-25.354141,0.024666,0.002285,0.058035,272.417419,13.877604,0.580353,-25.354141,0.058243,0.000000
100.090004,61.238140,-25.309662,0.024683,0.002285,0.058035,272.400848,13.876761,0.580353,-25.309662,0.058243,0.000000
100.330002,61.210957,-25.398623,0.024662,0.002285,0.058035,272.279938,13.870602,0.580353,-25.398623,0.058243,0.000000
100.570007,61.200531,-25.398623,0.024683,0.002285,0.058035,272.233551,13.868238,0.580353,-25.398623,0.058243,0.000000
100.800003,61.191967,-25.354141,0.024675,0.002285,0.058035,272.195465,13.866299,0.580353,-25.354141,0.058243,0.000000