File: Data/Polished Pin I-18 - 4_08162023_161454.csv
Time (sec),S:Load (lbs),S:HL1 (DIM),S:LVDT (in),S:Position (in),Ch:Position (mm),Ch:Load (N),Ch:Stress (MPa),Ch:Strain (mm/mm),Ch:HL1 (DIM),Set Point (),Cycles ()
0.010000,0.001117,-47.505657,0.000009,-0.000000,-0.000000,0.004969,0.000253,-0.000000,-47.505657,0.000078,0.000000
0.230000,-0.003724,-47.461174,-0.000026,-0.000000,-0.000000,-0.016564,-0.000844,-0.000000,-47.461174,0.000078,0.000000
0.450000,-0.024204,-47.461174,-0.000017,0.000040,0.001023,-0.107666,-0.005485,0.010227,-47.461174,0.001534,0.000000
0.670000,-0.020108,-47.505657,-0.000017,0.000170,0.004327,-0.089445,-0.004557,0.043269,-47.505657,0.005194,0.000000
0.890000,-0.008565,-47.550137,-0.000004,0.000304,0.007709,-0.038097,-0.001941,0.077091,-47.550137,0.008854,0.000000
1.110000,0.010799,-47.550137,0.000138,0.000450,0.011430,0.048036,0.002447,0.114296,-47.550137,0.012514,0.000000
1.330000,0.026811,-47.505657,0.000276,0.000593,0.015055,0.119261,0.006075,0.150548,-47.505657,0.016191,0.000000
1.550000,0.038727,-47.550137,0.000453,0.000739,0.018758,0.172265,0.008776,0.187579,-47.550137,0.019850,0.000000
1.770000,0.047291,-47.594616,0.000599,0.000876,0.022244,0.210362,0.010716,0.222438,-47.594616,0.023510,0.000000
1.990000,0.056601,-47.550137,0.000724,0.001025,0.026034,0.251772,0.012826,0.260340,-47.550137,0.027187,0.000000
2.210000,0.030535,-47.639099,0.000910,0.001174,0.029815,0.135825,0.006919,0.298151,-47.639099,0.030847,0.000000
2.430000,0.016757,-47.594616,0.001061,0.001318,0.033474,0.074538,0.003797,0.334744,-47.594616,0.034507,0.000000
2.650000,-0.008192,-47.594616,0.001190,0.001453,0.036918,-0.036441,-0.001856,0.369179,-47.594616,0.038184,0.000000
2.870000,-0.024577,-47.639099,0.001341,0.001600,0.040638,-0.109322,-0.005569,0.406377,-47.639099,0.041844,0.000000
3.090000,0.042078,-47.728062,0.001479,0.001743,0.044263,0.187173,0.009535,0.442628,-47.728062,0.045503,0.000000
3.310000,0.055111,-47.639099,0.001613,0.001887,0.047931,0.245147,0.012488,0.479312,-47.639099,0.049180,0.000000
3.530000,0.080432,-47.683578,0.001746,0.002030,0.051565,0.357782,0.018226,0.515647,-47.683578,0.052839,0.000000
3.750000,0.093838,-47.683578,0.001871,0.002174,0.055207,0.417412,0.021264,0.552072,-47.683578,0.056499,0.000000
3.970000,0.068144,-47.683578,0.002048,0.002332,0.059240,0.303121,0.015442,0.592397,-47.683578,0.060177,0.000000
4.190000,0.039844,-47.683578,0.002182,0.002472,0.062779,0.177234,0.009029,0.627785,-47.683578,0.063836,0.000000
4.410000,0.026811,-47.683578,0.002315,0.002614,0.066403,0.119261,0.006075,0.664030,-47.683578,0.067496,0.000000
4.630000,0.048781,-47.683578,0.002462,0.002755,0.069976,0.216988,0.011054,0.699759,-47.683578,0.071173,0.000000
4.850000,0.061814,-47.683578,0.002630,0.002897,0.073593,0.274962,0.014007,0.735927,-47.683578,0.074833,0.000000
5.070000,0.063303,-47.728062,0.002777,0.003043,0.077296,0.281587,0.014345,0.772959,-47.728062,0.078493,0.000000
5.290000,0.068144,-47.772541,0.002915,0.003180,0.080782,0.303121,0.015442,0.807818,-47.772541,0.082152,0.000000
5.510000,0.071868,-47.772541,0.003091,0.003338,0.084788,0.319684,0.016285,0.847885,-47.772541,0.085829,0.000000
5.730000,0.059207,-47.728062,0.003260,0.003483,0.088465,0.263367,0.013417,0.884651,-47.728062,0.089489,0.000000
5.950000,0.034631,-47.772541,0.003428,0.003627,0.092117,0.154045,0.007847,0.921168,-47.772541,0.093149,0.000000
6.170000,0.067399,-47.861504,0.003574,0.003771,0.095793,0.299808,0.015273,0.957934,-47.861504,0.096825,0.000000
6.390000,0.051387,-47.905983,0.003729,0.003917,0.099487,0.228583,0.011645,0.994875,-47.905983,0.100485,0.000000
6.610000,0.048781,-47.772541,0.003902,0.004049,0.102853,0.216988,0.011054,1.028530,-47.772541,0.104145,0.000000
6.830000,0.049526,-47.772541,0.004061,0.004197,0.106608,0.220301,0.011223,1.066076,-47.772541,0.107822,0.000000
7.050000,0.041706,-47.817024,0.004199,0.004348,0.110441,0.185516,0.009451,1.104410,-47.817024,0.111482,0.000000
7.270000,0.029790,-47.905983,0.004350,0.004491,0.114074,0.132512,0.006750,1.140745,-47.905983,0.115141,0.000000
7.490000,0.058463,-47.861504,0.004501,0.004633,0.117691,0.260054,0.013248,1.176906,-47.861504,0.118818,0.000000
7.710001,0.052877,-47.817024,0.004665,0.004779,0.121385,0.235208,0.011982,1.213854,-47.817024,0.122478,0.000000
7.930000,0.042823,-47.861504,0.004777,0.004925,0.125088,0.190485,0.009704,1.250885,-47.861504,0.126138,0.000000
8.150001,0.042450,-47.861504,0.004958,0.005067,0.128714,0.188829,0.009619,1.287137,-47.861504,0.129815,0.000000
8.370001,0.075219,-47.861504,0.005105,0.005210,0.132330,0.334592,0.017045,1.323298,-47.861504,0.133474,0.000000
8.590000,0.058090,-47.905983,0.005273,0.005359,0.136111,0.258398,0.013163,1.361109,-47.905983,0.137134,0.000000
8.810000,0.056228,-47.905983,0.005407,0.005506,0.139840,0.250116,0.012742,1.398398,-47.905983,0.140811,0.000000
9.030001,0.045429,-47.905983,0.005558,0.005642,0.143309,0.202080,0.010294,1.433090,-47.905983,0.144471,0.000000
9.250000,0.001117,-47.905983,0.005717,0.005786,0.146968,0.004969,0.000253,1.469682,-47.905983,0.148130,0.000000
9.470000,0.016384,-47.950466,0.005868,0.005931,0.150654,0.072882,0.003713,1.506540,-47.950466,0.151790,0.000000
9.690001,0.065165,-47.950466,0.006045,0.006077,0.154366,0.289869,0.014767,1.543662,-47.950466,0.155468,0.000000
9.910001,0.074475,-47.950466,0.006204,0.006218,0.157939,0.331279,0.016876,1.579391,-47.950466,0.159127,0.000000
10.130000,0.073730,-47.905983,0.006359,0.006358,0.161486,0.327966,0.016707,1.614856,-47.905983,0.162787,0.000000
10.350000,0.071123,-47.950466,0.006489,0.006513,0.165440,0.316372,0.016117,1.654400,-47.950466,0.166463,0.000000
10.570001,0.066282,-47.994946,0.006648,0.006658,0.169108,0.294839,0.015020,1.691084,-47.994946,0.170123,0.000000
10.790001,0.034258,-48.039429,0.006808,0.006801,0.172743,0.152389,0.007763,1.727426,-48.039429,0.173783,0.000000
11.010000,0.032769,-47.994946,0.006950,0.006941,0.176306,0.145763,0.007426,1.763065,-47.994946,0.177460,0.000000
11.230000,0.052505,-47.950466,0.007088,0.007083,0.179914,0.233552,0.011898,1.799142,-47.950466,0.181120,0.000000
11.450001,0.060324,-47.994946,0.007252,0.007229,0.183609,0.268336,0.013670,1.836090,-47.994946,0.184779,0.000000
11.670001,0.104264,-48.039429,0.007420,0.007370,0.187208,0.463791,0.023627,1.872077,-48.039429,0.188457,0.000000
11.890000,0.074847,-48.039429,0.007549,0.007520,0.191015,0.332935,0.016961,1.910146,-48.039429,0.192116,0.000000
12.110001,0.099796,-47.994946,0.007705,0.007667,0.194744,0.443914,0.022614,1.947442,-47.994946,0.195776,0.000000
12.330001,0.046919,-48.039429,0.007860,0.007813,0.198438,0.208706,0.010632,1.984383,-48.039429,0.199453,0.000000
12.550000,0.070006,-47.994946,0.008032,0.007954,0.202029,0.311403,0.015864,2.020286,-47.994946,0.203113,0.000000
12.770000,0.056228,-48.039429,0.008175,0.008103,0.205810,0.250116,0.012742,2.058097,-48.039429,0.206773,0.000000
12.990001,0.072613,-48.083908,0.008338,0.008238,0.209244,0.322997,0.016454,2.092441,-48.083908,0.210432,0.000000
13.210001,0.069634,-48.083908,0.008489,0.008385,0.212981,0.309746,0.015779,2.129813,-48.083908,0.214109,0.000000
13.430000,0.055856,-48.039429,0.008645,0.008531,0.216684,0.248459,0.012657,2.166845,-48.039429,0.217768,0.000000
13.650001,0.056601,-48.083908,0.008808,0.008677,0.220388,0.251772,0.012826,2.203876,-48.083908,0.221428,0.000000
13.870001,0.081177,-48.128387,0.008946,0.008819,0.223995,0.361094,0.018395,2.239954,-48.128387,0.225105,0.000000
14.090001,0.060324,-48.128387,0.009106,0.008963,0.227655,0.268336,0.013670,2.276554,-48.128387,0.228765,0.000000
14.310000,0.049526,-48.128387,0.009253,0.009108,0.231332,0.220301,0.011223,2.313320,-48.128387,0.232425,0.000000
14.530001,0.076709,-48.128387,0.009395,0.009253,0.235027,0.341217,0.017382,2.350268,-48.128387,0.236102,0.000000
14.750001,0.078198,-48.128387,0.009541,0.009395,0.238626,0.347843,0.017720,2.386255,-48.128387,0.239762,0.000000
14.970000,0.088625,-48.217350,0.009692,0.009540,0.242311,0.394222,0.020083,2.423112,-48.217350,0.243421,0.000000
15.190001,0.061441,-48.172871,0.009830,0.009683,0.245954,0.273305,0.013923,2.459538,-48.172871,0.247098,0.000000
15.410001,0.062559,-48.128387,0.010016,0.009830,0.249674,0.278275,0.014176,2.496736,-48.128387,0.250758,0.000000
15.630001,0.024577,-48.172871,0.010154,0.009971,0.253273,0.109322,0.005569,2.532731,-48.172871,0.254418,0.000000
15.850000,0.023832,-48.172871,0.010274,0.010115,0.256932,0.106009,0.005400,2.569323,-48.172871,0.258095,0.000000
16.070002,0.082294,-48.172871,0.010438,0.010261,0.260627,0.366064,0.018648,2.606271,-48.172871,0.261754,0.000000
16.290001,0.078943,-48.172871,0.010585,0.010407,0.264330,0.351156,0.017889,2.643302,-48.172871,0.265414,0.000000
16.510000,0.101285,-48.217350,0.010757,0.010545,0.267834,0.450540,0.022952,2.678335,-48.217350,0.269091,0.000000
16.730001,0.086390,-48.172871,0.010891,0.010690,0.271537,0.384284,0.019576,2.715367,-48.172871,0.272751,0.000000
16.950001,0.082294,-48.172871,0.011055,0.010845,0.275456,0.366064,0.018648,2.754563,-48.172871,0.276411,0.000000
17.170000,0.064793,-48.261833,0.011175,0.010986,0.279056,0.288213,0.014682,2.790558,-48.261833,0.280070,0.000000
17.390001,0.055484,-48.261833,0.011326,0.011127,0.282620,0.246803,0.012573,2.826196,-48.261833,0.283748,0.000000
17.610001,0.037237,-48.261833,0.011464,0.011268,0.286202,0.165640,0.008438,2.862016,-48.261833,0.287407,0.000000
17.830000,0.073357,-48.217350,0.011637,0.011412,0.289861,0.326310,0.016623,2.898609,-48.217350,0.291067,0.000000
18.050001,0.105381,-48.172871,0.011822,0.011558,0.293564,0.468760,0.023880,2.935640,-48.172871,0.294743,0.000000
18.270000,0.103520,-48.306313,0.011947,0.011699,0.297163,0.460478,0.023458,2.971635,-48.306313,0.298403,0.000000
18.490002,0.114691,-48.261833,0.012120,0.011849,0.300962,0.510170,0.025989,3.009620,-48.261833,0.302063,0.000000
18.710001,0.097189,-48.217350,0.012262,0.011997,0.304726,0.432319,0.022023,3.047257,-48.217350,0.305740,0.000000
18.930000,0.088997,-48.217350,0.012430,0.012138,0.308316,0.395879,0.020167,3.083160,-48.217350,0.309400,0.000000
19.150002,0.068517,-48.261833,0.012581,0.012287,0.312080,0.304777,0.015526,3.120797,-48.261833,0.313059,0.000000
19.370001,0.091231,-48.306313,0.012723,0.012425,0.315583,0.405817,0.020673,3.155830,-48.306313,0.316737,0.000000
19.590000,0.089369,-48.395275,0.012853,0.012570,0.319269,0.397535,0.020251,3.192688,-48.395275,0.320396,0.000000
19.810001,0.091976,-48.306313,0.012995,0.012711,0.322859,0.409130,0.020842,3.228591,-48.306313,0.324056,0.000000
20.030001,0.082667,-48.261833,0.013137,0.012858,0.326605,0.367720,0.018733,3.266054,-48.261833,0.327733,0.000000
20.250002,0.108733,-48.306313,0.013275,0.013002,0.330248,0.483667,0.024639,3.302480,-48.306313,0.331393,0.000000
20.470001,0.074475,-48.306313,0.013443,0.013149,0.333977,0.331279,0.016876,3.339769,-48.306313,0.335053,0.000000
20.690001,0.068889,-48.350792,0.013594,0.013293,0.337654,0.306433,0.015610,3.376543,-48.350792,0.338729,0.000000
20.910002,0.100541,-48.350792,0.013758,0.013436,0.341270,0.447227,0.022783,3.412704,-48.350792,0.342389,0.000000
21.130001,0.102775,-48.350792,0.013918,0.013583,0.345008,0.457165,0.023289,3.450083,-48.350792,0.346049,0.000000
21.350000,0.099423,-48.350792,0.014056,0.013722,0.348537,0.442258,0.022530,3.485373,-48.350792,0.349708,0.000000
21.570002,0.100913,-48.350792,0.014198,0.013863,0.352111,0.448883,0.022867,3.521111,-48.350792,0.353386,0.000000
21.790001,0.081922,-48.395275,0.014353,0.014013,0.355935,0.364407,0.018564,3.559353,-48.395275,0.357045,0.000000
22.010000,0.086390,-48.350792,0.014526,0.014158,0.359604,0.384284,0.019576,3.596036,-48.350792,0.360705,0.000000
22.230001,0.058463,-48.350792,0.014655,0.014301,0.363246,0.260054,0.013248,3.632462,-48.350792,0.364382,0.000000
22.450001,0.103520,-48.350792,0.014797,0.014446,0.366923,0.460478,0.023458,3.669229,-48.350792,0.368042,0.000000
22.670002,0.101285,-48.395275,0.014944,0.014592,0.370634,0.450540,0.022952,3.706343,-48.395275,0.371702,0.000000
22.890001,0.118042,-48.395275,0.015099,0.014732,0.374182,0.525078,0.026749,3.741815,-48.395275,0.375378,0.000000
23.110001,0.129213,-48.350792,0.015241,0.014874,0.377789,0.574769,0.029280,3.777893,-48.350792,0.379038,0.000000
23.330002,0.152300,-48.395275,0.015388,0.015027,0.381683,0.677466,0.034512,3.816832,-48.395275,0.382698,0.000000
23.550001,0.148204,-48.350792,0.015547,0.015171,0.385342,0.659245,0.033584,3.853424,-48.350792,0.386375,0.000000
23.770000,0.156769,-48.439754,0.015690,0.015311,0.388907,0.697343,0.035524,3.889071,-48.439754,0.390034,0.000000
23.990002,0.237946,-48.439754,0.015849,0.015454,0.392532,1.058437,0.053919,3.925322,-48.439754,0.393694,0.000000
24.210001,0.434186,-48.395275,0.015996,0.015596,0.396140,1.931357,0.098388,3.961400,-48.395275,0.397372,0.000000
24.430000,0.678090,-48.395275,0.016099,0.000010,0.000243,3.016296,0.153657,0.002430,-48.395275,0.000451,0.000000
24.650002,0.649790,-48.395275,0.016108,0.000010,0.000243,2.890410,0.147245,0.002430,-48.395275,0.000451,0.000000
24.870001,0.612180,-48.395275,0.016112,0.000009,0.000235,2.723114,0.138722,0.002347,-48.395275,0.000478,0.000000
25.090002,0.647183,-48.439754,0.016104,0.000010,0.000243,2.878815,0.146654,0.002430,-48.439754,0.000842,0.000000
25.310001,0.660216,-48.395275,0.016121,0.000014,0.000347,2.936789,0.149607,0.003475,-48.395275,0.001214,0.000000
25.530001,0.669898,-48.484238,0.016104,0.000027,0.000677,2.979856,0.151801,0.006767,-48.484238,0.001578,0.000000
25.750002,0.749213,-48.395275,0.016108,0.000040,0.001023,3.332668,0.169774,0.010234,-48.395275,0.001943,0.000000
25.970001,0.783099,-48.484238,0.016121,0.000052,0.001310,3.483400,0.177453,0.013096,-48.484238,0.002316,0.000000
26.190001,0.913057,-48.528717,0.016125,0.000066,0.001665,4.061482,0.206902,0.016654,-48.528717,0.002680,0.000000
26.410002,1.011364,-48.484238,0.016151,0.000083,0.002107,4.498770,0.229178,0.021074,-48.484238,0.003045,0.000000
26.630001,1.099988,-48.528717,0.016147,0.000095,0.002420,4.892992,0.249261,0.024201,-48.528717,0.003409,0.000000
26.850000,1.140205,-48.439754,0.016172,0.000106,0.002697,5.071883,0.258374,0.026971,-48.439754,0.003781,0.000000
27.070002,1.271280,-48.528717,0.016172,0.000126,0.003191,5.654934,0.288076,0.031914,-48.528717,0.004146,0.000000
27.290001,1.359904,-48.528717,0.016207,0.000141,0.003573,6.049156,0.308159,0.035729,-48.528717,0.004510,0.000000
27.510002,1.422835,-48.439754,0.016216,0.000154,0.003920,6.329087,0.322419,0.039204,-48.439754,0.004883,0.000000
27.730001,1.550559,-48.439754,0.016220,0.000170,0.004328,6.897231,0.351362,0.043276,-48.439754,0.005247,0.000000
27.950001,1.578487,-48.573200,0.016246,0.000181,0.004588,7.021461,0.357690,0.045880,-48.573200,0.005611,0.000000
28.170002,1.778079,-48.484238,0.016250,0.000199,0.005065,7.909288,0.402918,0.050649,-48.484238,0.005976,0.000000
28.390001,1.805634,-48.573200,0.016254,0.000207,0.005256,8.031861,0.409163,0.052557,-48.573200,0.006348,0.000000
28.610001,1.991076,-48.528717,0.016276,0.000223,0.005663,8.856747,0.451184,0.056630,-48.528717,0.006713,0.000000
28.830002,2.161250,-48.439754,0.016285,0.000243,0.006184,9.613719,0.489746,0.061838,-48.439754,0.007077,0.000000
29.050001,2.306103,-48.573200,0.016315,0.000258,0.006565,10.258058,0.522570,0.065653,-48.573200,0.007441,0.000000
29.270000,2.347064,-48.573200,0.016319,0.000269,0.006834,10.440260,0.531852,0.068340,-48.573200,0.007814,0.000000
29.490002,2.542932,-48.573200,0.016345,0.000285,0.007242,11.311524,0.576236,0.072420,-48.573200,0.008178,0.000000
29.710001,2.648313,-48.573200,0.016328,0.000299,0.007589,11.780285,0.600116,0.075887,-48.573200,0.008543,0.000000
29.930002,2.847532,-48.528717,0.016358,0.000315,0.008005,12.666456,0.645260,0.080051,-48.528717,0.008916,0.000000
30.150002,2.970043,-48.573200,0.016375,0.000326,0.008274,13.211410,0.673021,0.082738,-48.573200,0.009280,0.000000
30.370001,3.122343,-48.617680,0.016379,0.000338,0.008595,13.888876,0.707533,0.085947,-48.617680,0.009644,0.000000
30.590002,3.302199,-48.617680,0.016392,0.000351,0.008916,14.688915,0.748289,0.089157,-48.617680,0.010008,0.000000
30.810001,3.533815,-48.617680,0.016405,0.000372,0.009461,15.719193,0.800774,0.094615,-48.617680,0.010381,0.000000
31.030001,3.744950,-48.528717,0.016427,0.000387,0.009817,16.658369,0.848618,0.098173,-48.528717,0.010745,0.000000
31.250002,3.886079,-48.573200,0.016423,0.000400,0.010156,17.286142,0.880598,0.101556,-48.573200,0.011109,0.000000
31.470001,4.044710,-48.617680,0.016431,0.000416,0.010572,17.991768,0.916544,0.105720,-48.617680,0.011483,0.000000
31.690002,4.154560,-48.662159,0.016440,0.000427,0.010849,18.480404,0.941437,0.108490,-48.662159,0.011847,0.000000
31.910002,4.461767,-48.617680,0.016487,0.000444,0.011283,19.846931,1.011051,0.112828,-48.617680,0.012211,0.000000
32.130001,4.600662,-48.617680,0.016492,0.000455,0.011561,20.464766,1.042525,0.115606,-48.617680,0.012575,0.000000
32.350002,4.729875,-48.617680,0.016492,0.000467,0.011855,21.039536,1.071805,0.118550,-48.617680,0.012948,0.000000
32.570000,4.907869,-48.662159,0.016504,0.000477,0.012124,21.831293,1.112139,0.121238,-48.662159,0.013312,0.000000
32.790001,5.414668,-48.617680,0.016513,0.000505,0.012835,24.085646,1.226981,0.128353,-48.617680,0.013676,0.000000
33.010002,5.517071,-48.662159,0.016543,0.000516,0.013112,24.541157,1.250186,0.131124,-48.662159,0.014050,0.000000
33.230003,5.705863,-48.617680,0.016561,0.000532,0.013511,25.380947,1.292967,0.135113,-48.617680,0.014414,0.000000
33.450001,5.860398,-48.617680,0.016539,0.000544,0.013807,26.068354,1.327985,0.138065,-48.617680,0.014778,0.000000
33.670002,5.994080,-48.662159,0.016578,0.000554,0.014067,26.662998,1.358278,0.140669,-48.662159,0.015142,0.000000
33.890003,6.350440,-48.751122,0.016591,0.000573,0.014561,28.248169,1.439030,0.145612,-48.751122,0.015515,0.000000
34.110001,6.547425,-48.662159,0.016604,0.000586,0.014891,29.124403,1.483668,0.148905,-48.662159,0.015879,0.000000
34.330002,6.618176,-48.662159,0.016625,0.000593,0.015073,29.439116,1.499700,0.150730,-48.662159,0.016243,0.000000
34.550003,6.877347,-48.706642,0.016617,0.000608,0.015445,30.591967,1.558429,0.154454,-48.706642,0.016616,0.000000
34.770000,7.451918,-48.706642,0.016647,0.000637,0.016174,33.147785,1.688629,0.161744,-48.706642,0.016981,0.000000
34.990002,7.561396,-48.662159,0.016664,0.000648,0.016451,33.634769,1.713437,0.164514,-48.662159,0.017345,0.000000
35.210003,7.739389,-48.706642,0.016673,0.000662,0.016807,34.426525,1.753771,0.168072,-48.706642,0.017709,0.000000
35.430000,7.938236,-48.662159,0.016681,0.000673,0.017093,35.311039,1.798830,0.170933,-48.662159,0.018082,0.000000
35.650002,8.305395,-48.617680,0.016677,0.000691,0.017562,36.944244,1.882029,0.175619,-48.617680,0.018446,0.000000
35.870003,8.513179,-48.751122,0.016703,0.000705,0.017900,37.868511,1.929114,0.178995,-48.751122,0.018810,0.000000
36.090000,8.733996,-48.751122,0.016707,0.000718,0.018230,38.850758,1.979152,0.182296,-48.751122,0.019183,0.000000
36.310001,8.761179,-48.662159,0.016737,0.000726,0.018429,38.971672,1.985312,0.184287,-48.662159,0.019547,0.000000
36.530003,9.297024,-48.662159,0.016724,0.000746,0.018949,41.355228,2.106736,0.189495,-48.662159,0.019912,0.000000
36.750000,9.574814,-48.751122,0.016750,0.000763,0.019374,42.590900,2.169684,0.193741,-48.751122,0.020276,0.000000
36.970001,9.759883,-48.795605,0.016750,0.000775,0.019678,43.414127,2.211621,0.196777,-48.795605,0.020649,0.000000
37.190002,10.029108,-48.795605,0.016776,0.000790,0.020077,44.611702,2.272628,0.200766,-48.795605,0.021013,0.000000
37.410004,10.188483,-48.795605,0.016793,0.000803,0.020406,45.320637,2.308743,0.204059,-48.795605,0.021377,0.000000
37.630001,10.638681,-48.751122,0.016793,0.000822,0.020883,47.323219,2.410760,0.208828,-48.751122,0.021750,0.000000
37.850002,10.743319,-48.751122,0.016806,0.000833,0.021169,47.788670,2.434471,0.211689,-48.751122,0.022114,0.000000
38.070004,10.887053,-48.795605,0.016832,0.000844,0.021438,48.428032,2.467041,0.214384,-48.795605,0.022478,0.000000
38.290001,11.249372,-48.751122,0.016832,0.000860,0.021837,50.039707,2.549144,0.218373,-48.751122,0.022843,0.000000
38.510002,11.715583,-48.795605,0.016841,0.000880,0.022357,52.113514,2.654789,0.223574,-48.795605,0.023216,0.000000
38.730003,11.893577,-48.795605,0.016871,0.000894,0.022704,52.905270,2.695123,0.227041,-48.795605,0.023580,0.000000
38.950001,11.999702,-48.795605,0.016871,0.000906,0.023008,53.377342,2.719172,0.230076,-48.795605,0.023945,0.000000
39.170002,12.327763,-48.795605,0.016871,0.000920,0.023363,54.836628,2.793511,0.233634,-48.795605,0.024317,0.000000
39.390003,12.442081,-48.929047,0.016893,0.000931,0.023658,55.345142,2.819416,0.236579,-48.929047,0.024681,0.000000
39.610001,12.749289,-48.795605,0.016927,0.000947,0.024057,56.711666,2.889030,0.240568,-48.795605,0.025046,0.000000
39.830002,12.989841,-48.840084,0.016905,0.000958,0.024335,57.781700,2.943540,0.243346,-48.840084,0.025410,0.000000
40.050003,13.044952,-48.795605,0.016914,0.000967,0.024569,58.026848,2.956028,0.245685,-48.795605,0.025783,0.000000
40.270000,13.491055,-48.840084,0.016953,0.000985,0.025029,60.011208,3.057117,0.250288,-48.840084,0.026147,0.000000
40.490002,14.136748,-48.840084,0.016953,0.001009,0.025627,62.883396,3.203433,0.256268,-48.840084,0.026512,0.000000
40.710003,14.284953,-48.884563,0.016979,0.001023,0.025991,63.542645,3.237017,0.259909,-48.884563,0.026884,0.000000
40.930000,14.304688,-48.840084,0.017005,0.001034,0.026251,63.630432,3.241489,0.262513,-48.840084,0.027248,0.000000
41.150002,14.497205,-48.840084,0.017009,0.001048,0.026624,64.486786,3.285114,0.266245,-48.840084,0.027613,0.000000
41.370003,14.694562,-48.840084,0.016992,0.001060,0.026919,65.364677,3.329835,0.269189,-48.840084,0.027977,0.000000
41.590000,14.972352,-48.929047,0.017009,0.001074,0.027275,66.600349,3.392783,0.272747,-48.929047,0.028350,0.000000
41.810001,15.478406,-48.884563,0.017030,0.001093,0.027752,68.851387,3.507457,0.277516,-48.884563,0.028714,0.000000
42.030003,15.619908,-48.840084,0.017035,0.001103,0.028012,69.480820,3.539522,0.280120,-48.840084,0.029079,0.000000
42.250004,15.854130,-48.840084,0.017052,0.001116,0.028341,70.522690,3.592597,0.283413,-48.840084,0.029443,0.000000
42.470001,16.326298,-48.884563,0.017069,0.001134,0.028801,72.623001,3.699592,0.288008,-48.884563,0.029816,0.000000
42.690002,16.606321,-48.929047,0.017069,0.001149,0.029191,73.868607,3.763046,0.291914,-48.929047,0.030180,0.000000
42.910004,16.718035,-48.929047,0.017095,0.001163,0.029529,74.365532,3.788361,0.295290,-48.929047,0.030544,0.000000
43.130001,17.089661,-48.929047,0.017104,0.001178,0.029920,76.018608,3.872572,0.299196,-48.929047,0.030917,0.000000
43.350002,17.243824,-48.929047,0.017112,0.001190,0.030223,76.704361,3.907506,0.302231,-48.929047,0.031281,0.000000
43.570004,17.497782,-48.973526,0.017121,0.001204,0.030579,77.834023,3.965054,0.305789,-48.973526,0.031646,0.000000
43.790001,17.880207,-49.018009,0.017138,0.001215,0.030873,79.535133,4.051713,0.308734,-49.018009,0.032010,0.000000
44.010002,18.200821,-48.973526,0.017143,0.001231,0.031264,80.961296,4.124365,0.312640,-48.973526,0.032383,0.000000
44.230003,18.542286,-48.884563,0.017156,0.001245,0.031628,82.480209,4.201742,0.316281,-48.884563,0.032747,0.000000
44.450001,19.014082,-48.973526,0.017156,0.001262,0.032062,84.578857,4.308653,0.320618,-48.973526,0.033111,0.000000
44.670002,19.411404,-48.929047,0.017173,0.001279,0.032496,86.346237,4.398687,0.324956,-48.929047,0.033484,0.000000
44.890003,19.549181,-48.973526,0.017181,0.001292,0.032825,86.959099,4.429908,0.328249,-48.973526,0.033848,0.000000
45.110001,19.843727,-48.973526,0.017207,0.001306,0.033163,88.269310,4.496653,0.331632,-48.973526,0.034212,0.000000
45.330002,20.061565,-48.973526,0.017220,0.001319,0.033493,89.238297,4.546016,0.334925,-48.973526,0.034577,0.000000
45.550003,20.519211,-48.929047,0.017220,0.001333,0.033866,91.274010,4.649720,0.338657,-48.929047,0.034950,0.000000
45.770000,20.926214,-48.973526,0.017212,0.001347,0.034203,93.084450,4.741948,0.342033,-48.973526,0.035314,0.000000
45.990002,21.072557,-49.062489,0.017242,0.001357,0.034473,93.735420,4.775110,0.344728,-49.062489,0.035678,0.000000
46.210003,21.500040,-48.973526,0.017276,0.001371,0.034820,95.636955,4.871979,0.348195,-48.973526,0.036051,0.000000
46.430000,22.442888,-48.973526,0.017276,0.001397,0.035479,99.830956,5.085631,0.354788,-48.973526,0.036415,0.000000
46.650002,22.502468,-48.973526,0.017289,0.001407,0.035748,100.095978,5.099133,0.357476,-48.973526,0.036779,0.000000
46.870003,22.813398,-48.973526,0.017306,0.001421,0.036103,101.479065,5.169590,0.361026,-48.973526,0.037143,0.000000
47.090004,23.131031,-49.018009,0.017315,0.001437,0.036493,102.891968,5.241567,0.364932,-49.018009,0.037517,0.000000
47.310001,23.430420,-48.973526,0.017328,0.001448,0.036779,104.223717,5.309409,0.367793,-48.973526,0.037881,0.000000
47.530003,23.894024,-49.018009,0.017345,0.001461,0.037109,106.285927,5.414463,0.371086,-49.018009,0.038245,0.000000
47.750004,24.491308,-49.062489,0.017345,0.001479,0.037577,108.942780,5.549809,0.375772,-49.062489,0.038618,0.000000
47.970001,24.500990,-49.062489,0.017354,0.001488,0.037803,108.985847,5.552003,0.378028,-49.062489,0.038982,0.000000
48.190002,24.969807,-49.106972,0.017384,0.001503,0.038175,111.071251,5.658239,0.381752,-49.106972,0.039346,0.000000
48.410004,25.802805,-49.062489,0.017358,0.001522,0.038653,114.776611,5.846999,0.386529,-49.062489,0.039710,0.000000
48.630001,26.318913,-49.018009,0.017393,0.001538,0.039069,117.072372,5.963951,0.390692,-49.018009,0.040084,0.000000
48.850002,26.557976,-49.018009,0.017380,0.001550,0.039372,118.135773,6.018123,0.393720,-49.018009,0.040448,0.000000
49.070004,27.176859,-49.062489,0.017406,0.001568,0.039823,120.888702,6.158364,0.398232,-49.062489,0.040812,0.000000
49.290001,27.275166,-49.062489,0.017440,0.001576,0.040040,121.325996,6.180641,0.400404,-49.062489,0.041185,0.000000
49.510002,28.078373,-49.151451,0.017427,0.001597,0.040552,124.898842,6.362650,0.405521,-49.151451,0.041549,0.000000
49.730003,28.304029,-49.062489,0.017431,0.001605,0.040777,125.902611,6.413785,0.407769,-49.062489,0.041913,0.000000
49.950001,28.695395,-49.106972,0.017444,0.001621,0.041185,127.643486,6.502469,0.411850,-49.106972,0.042277,0.000000
50.170002,29.633772,-49.062489,0.017457,0.001643,0.041722,131.817596,6.715109,0.417224,-49.062489,0.042650,0.000000
50.390003,30.314842,-49.151451,0.017488,0.001657,0.042078,134.847153,6.869442,0.420782,-49.151451,0.043015,0.000000
50.610001,30.406818,-49.106972,0.017483,0.001668,0.042355,135.256287,6.890284,0.423552,-49.106972,0.043379,0.000000
50.830002,30.958673,-49.106972,0.017509,0.001683,0.042754,137.711060,7.015336,0.427542,-49.106972,0.043752,0.000000
51.050003,31.408127,-49.062489,0.017500,0.001695,0.043041,139.710327,7.117183,0.430411,-49.062489,0.044116,0.000000
51.270004,32.041534,-49.062489,0.017500,0.001711,0.043457,142.527863,7.260715,0.434566,-49.062489,0.044480,0.000000
51.490002,32.463058,-49.106972,0.017531,0.001724,0.043778,144.402893,7.356234,0.437776,-49.106972,0.044844,0.000000
51.710003,33.077477,-49.151451,0.017556,0.001737,0.044116,147.135971,7.495463,0.441160,-49.151451,0.045217,0.000000
51.930004,33.541077,-49.195930,0.017526,0.001749,0.044429,149.198166,7.600516,0.444286,-49.195930,0.045581,0.000000
52.150002,34.221031,-49.106972,0.017539,0.001767,0.044888,152.222748,7.754597,0.448881,-49.106972,0.045946,0.000000
52.370003,35.224575,-49.151451,0.017561,0.001786,0.045356,156.686737,7.982003,0.453559,-49.151451,0.046319,0.000000
52.590004,35.651314,-49.240414,0.017569,0.001800,0.045712,158.584961,8.078703,0.457117,-49.240414,0.046683,0.000000
52.810001,36.175613,-49.195930,0.017574,0.001815,0.046102,160.917160,8.197511,0.461023,-49.195930,0.047047,0.000000
53.030003,36.563999,-49.151451,0.017591,0.001827,0.046406,162.644791,8.285521,0.464058,-49.151451,0.047412,0.000000
53.250004,37.378006,-49.151451,0.017578,0.001841,0.046770,166.265671,8.469977,0.467699,-49.151451,0.047784,0.000000
53.470001,37.821129,-49.195930,0.017600,0.001854,0.047082,168.236786,8.570390,0.470818,-49.195930,0.048148,0.000000
53.690002,38.205044,-49.240414,0.017595,0.001865,0.047368,169.944519,8.657387,0.473680,-49.240414,0.048513,0.000000
53.910004,38.660454,-49.195930,0.017617,0.001876,0.047654,171.970291,8.760584,0.476541,-49.195930,0.048886,0.000000
54.130001,40.205055,-49.195930,0.017608,0.001904,0.048374,178.841019,9.110596,0.483740,-49.195930,0.049250,0.000000
54.350002,40.760262,-49.195930,0.017630,0.001915,0.048643,181.310699,9.236406,0.486427,-49.195930,0.049614,0.000000
54.570004,41.478943,-49.284893,0.017647,0.001932,0.049068,184.507553,9.399262,0.490681,-49.284893,0.049979,0.000000
54.790001,41.907543,-49.284893,0.017643,0.001945,0.049397,186.414062,9.496386,0.493974,-49.284893,0.050351,0.000000
55.010002,42.230019,-49.195930,0.017651,0.001953,0.049606,187.848511,9.569459,0.496056,-49.195930,0.050715,0.000000
55.230003,43.233562,-49.240414,0.017673,0.001972,0.050082,192.312485,9.796865,0.500825,-49.240414,0.051080,0.000000
55.450001,43.861382,-49.195930,0.017677,0.001986,0.050447,195.105164,9.939132,0.504466,-49.195930,0.051444,0.000000
55.670002,44.029694,-49.240414,0.017694,0.001992,0.050603,195.853851,9.977271,0.506033,-49.240414,0.051817,0.000000
55.890003,44.710018,-49.284893,0.017686,0.002007,0.050967,198.880096,10.131434,0.509674,-49.284893,0.052182,0.000000
56.110004,46.420696,-49.284893,0.017694,0.002036,0.051704,206.489563,10.519080,0.517039,-49.284893,0.052546,0.000000
56.330002,46.927868,-49.284893,0.017703,0.002047,0.051982,208.745575,10.634007,0.519817,-49.284893,0.052918,0.000000
56.550003,47.458126,-49.240414,0.017703,0.002061,0.052338,211.104294,10.754165,0.523375,-49.240414,0.053283,0.000000
56.770004,48.046474,-49.284893,0.017716,0.002072,0.052624,213.721390,10.887486,0.526237,-49.284893,0.053647,0.000000
56.990002,49.091724,-49.284893,0.017725,0.002090,0.053092,218.370895,11.124344,0.530922,-49.284893,0.054011,0.000000
57.210003,49.673744,-49.240414,0.017725,0.002103,0.053412,220.959854,11.256231,0.534124,-49.240414,0.054384,0.000000
57.430004,50.335075,-49.284893,0.017768,0.002115,0.053733,223.901596,11.406091,0.537334,-49.284893,0.054749,0.000000
57.650002,50.663509,-49.240414,0.017742,0.002127,0.054037,225.362549,11.480515,0.540369,-49.240414,0.055113,0.000000
57.870003,51.967186,-49.329376,0.017742,0.002145,0.054480,231.161591,11.775933,0.544798,-49.329376,0.055485,0.000000
58.090004,52.814705,-49.329376,0.017776,0.002161,0.054887,234.931534,11.967983,0.548870,-49.329376,0.055850,0.000000
58.310001,53.503593,-49.373856,0.017768,0.002173,0.055199,237.995865,12.124087,0.551989,-49.373856,0.056214,0.000000
58.530003,54.254669,-49.329376,0.017789,0.002189,0.055590,241.336823,12.294284,0.555895,-49.329376,0.056578,0.000000
58.750004,54.808758,-49.284893,0.017794,0.002198,0.055841,243.801529,12.419842,0.558408,-49.284893,0.056951,0.000000
58.970001,56.147812,-49.284893,0.017772,0.002220,0.056387,249.757935,12.723276,0.563874,-49.284893,0.057315,0.000000
59.190002,56.717915,-49.284893,0.017781,0.002231,0.056674,252.293884,12.852463,0.566735,-49.284893,0.057680,0.000000
59.410004,57.334934,-49.373856,0.017781,0.002242,0.056951,255.038528,12.992282,0.569513,-49.373856,0.058053,0.000000
59.630001,58.201073,-49.373856,0.017824,0.002259,0.057368,258.891296,13.188552,0.573677,-49.373856,0.058417,0.000000
59.850002,59.343510,-49.373856,0.017802,0.002278,0.057862,263.973114,13.447432,0.578620,-49.373856,0.058781,0.000000
60.070004,60.406261,-49.373856,0.017820,0.002293,0.058234,268.700470,13.688254,0.582344,-49.373856,0.059145,0.000000
60.290005,60.902634,-49.373856,0.017802,0.002305,0.058547,270.908447,13.800734,0.585470,-49.373856,0.059518,0.000000
60.510002,61.816063,-49.373856,0.017828,0.002318,0.058885,274.971588,14.007720,0.588846,-49.373856,0.059882,0.000000
60.730003,62.355259,-49.418335,0.017837,0.002330,0.059171,277.370056,14.129904,0.591708,-49.418335,0.060246,0.000000
60.950005,63.040424,-49.373856,0.017820,0.002341,0.059466,280.417816,14.285165,0.594660,-49.373856,0.060620,0.000000
61.170002,63.868580,-49.329376,0.017850,0.002353,0.059778,284.101624,14.472827,0.597779,-49.329376,0.060984,0.000000
61.390003,64.462517,-49.373856,0.017828,0.002364,0.060047,286.743591,14.607415,0.600474,-49.373856,0.061348,0.000000
61.610004,65.600853,-49.418335,0.017837,0.002384,0.060558,291.807159,14.865366,0.605583,-49.418335,0.061712,0.000000
61.830002,67.334618,-49.418335,0.017845,0.002407,0.061149,299.519348,15.258243,0.611488,-49.418335,0.062085,0.000000
62.050003,67.087364,-49.418335,0.017867,0.002399,0.060932,298.419495,15.202214,0.609315,-49.418335,0.061175,0.000000
62.270004,66.752602,-49.418335,0.017863,0.002399,0.060923,296.930389,15.126355,0.609232,-49.418335,0.060932,0.000000
62.490002,66.440926,-49.373856,0.017876,0.002396,0.060862,295.544006,15.055729,0.608619,-49.373856,0.060932,0.000000
62.710003,66.176918,-49.462818,0.017880,0.002395,0.060845,294.369629,14.995904,0.608452,-49.462818,0.060932,0.000000
62.930004,65.950508,-49.418335,0.017880,0.002395,0.060836,293.362518,14.944598,0.608361,-49.418335,0.060932,0.000000
63.150002,65.747200,-49.462818,0.017893,0.002395,0.060828,292.458160,14.898528,0.608278,-49.462818,0.060932,0.000000
63.370003,65.573669,-49.462818,0.017880,0.002394,0.060819,291.686249,14.859206,0.608187,-49.462818,0.060932,0.000000
63.590004,65.406479,-49.418335,0.017897,0.002394,0.060819,290.942535,14.821320,0.608187,-49.418335,0.060932,0.000000
63.810001,65.273537,-49.462818,0.017880,0.002394,0.060810,290.351196,14.791195,0.608104,-49.462818,0.060932,0.000000
64.030006,65.134270,-49.462818,0.017914,0.002394,0.060810,289.731689,14.759637,0.608104,-49.462818,0.060932,0.000000
64.250000,65.022934,-49.507298,0.017884,0.002394,0.060810,289.236450,14.734407,0.608104,-49.507298,0.060932,0.000000
64.470001,64.911591,-49.462818,0.017888,0.002394,0.060810,288.741180,14.709176,0.608104,-49.462818,0.060932,0.000000
64.690002,64.804726,-49.462818,0.017888,0.002394,0.060810,288.265808,14.684960,0.608104,-49.462818,0.060932,0.000000
64.910004,64.713867,-49.507298,0.017897,0.002394,0.060801,287.861664,14.664372,0.608013,-49.507298,0.060932,0.000000
65.130005,64.617050,-49.507298,0.017893,0.002394,0.060801,287.431000,14.642432,0.608013,-49.507298,0.060932,0.000000
65.350006,64.534752,-49.462818,0.017901,0.002394,0.060801,287.064911,14.623784,0.608013,-49.462818,0.060932,0.000000
65.570000,64.461769,-49.462818,0.017914,0.002394,0.060801,286.740265,14.607245,0.608013,-49.462818,0.060932,0.000000
65.790001,64.375381,-49.462818,0.017906,0.002394,0.060801,286.355988,14.587669,0.608013,-49.462818,0.060932,0.000000
66.010002,64.298668,-49.507298,0.017893,0.002394,0.060801,286.014771,14.570287,0.608013,-49.507298,0.060932,0.000000
66.230003,64.218979,-49.551781,0.017897,0.002394,0.060801,285.660278,14.552229,0.608013,-49.551781,0.060932,0.000000
66.450005,64.161636,-49.507298,0.017910,0.002394,0.060801,285.405212,14.539235,0.608013,-49.507298,0.060932,0.000000
66.670006,64.105782,-49.507298,0.017897,0.002394,0.060801,285.156769,14.526578,0.608013,-49.507298,0.060932,0.000000
66.889999,64.056252,-49.507298,0.017897,0.002394,0.060801,284.936432,14.515354,0.608013,-49.507298,0.060932,0.000000
67.110001,63.992210,-49.551781,0.017880,0.002394,0.060801,284.651581,14.500842,0.608013,-49.551781,0.060932,0.000000
67.330002,63.931141,-49.551781,0.017888,0.002394,0.060801,284.379913,14.487003,0.608013,-49.551781,0.060932,0.000000
67.550003,63.881241,-49.507298,0.017914,0.002394,0.060801,284.157959,14.475696,0.608013,-49.507298,0.060932,0.000000
67.770004,63.825386,-49.507298,0.017910,0.002393,0.060793,283.909485,14.463039,0.607930,-49.507298,0.060932,0.000000
67.990005,63.782562,-49.551781,0.017888,0.002393,0.060793,283.718994,14.453336,0.607930,-49.551781,0.060932,0.000000
68.210007,63.736763,-49.596260,0.017884,0.002393,0.060793,283.515289,14.442957,0.607930,-49.596260,0.060932,0.000000
68.430000,63.682396,-49.640743,0.017897,0.002393,0.060793,283.273437,14.430636,0.607930,-49.640743,0.060932,0.000000
68.650002,63.658562,-49.507298,0.017901,0.002393,0.060793,283.167419,14.425236,0.607930,-49.507298,0.060932,0.000000
68.870003,63.595261,-49.551781,0.017888,0.002393,0.060793,282.885834,14.410892,0.607930,-49.551781,0.060932,0.000000
69.090004,63.566216,-49.596260,0.017901,0.002393,0.060793,282.756653,14.404310,0.607930,-49.596260,0.060932,0.000000
69.310005,63.524136,-49.596260,0.017893,0.002393,0.060793,282.569458,14.394775,0.607930,-49.596260,0.060932,0.000000
69.530006,63.474609,-49.640743,0.017906,0.002393,0.060793,282.349152,14.383552,0.607930,-49.640743,0.060932,0.000000
69.750000,63.443333,-49.640743,0.017906,0.002393,0.060793,282.210052,14.376465,0.607930,-49.640743,0.060932,0.000000
69.970001,63.416893,-49.551781,0.017906,0.002393,0.060793,282.092438,14.370473,0.607930,-49.551781,0.060932,0.000000
70.190002,63.365135,-49.596260,0.017893,0.002393,0.060793,281.862213,14.358745,0.607930,-49.596260,0.060932,0.000000
70.410004,63.329014,-49.640743,0.017893,0.002393,0.060793,281.701508,14.350560,0.607930,-49.640743,0.060932,0.000000
70.630005,63.287682,-49.596260,0.017893,0.002393,0.060793,281.517670,14.341193,0.607930,-49.596260,0.060932,0.000000
70.850006,63.258636,-49.596260,0.017897,0.002393,0.060793,281.388458,14.334612,0.607930,-49.596260,0.060932,0.000000
71.070000,63.237782,-49.596260,0.017901,0.002393,0.060793,281.295715,14.329886,0.607930,-49.596260,0.060932,0.000000
71.290001,63.193844,-49.640743,0.017867,0.002393,0.060793,281.100250,14.319930,0.607930,-49.640743,0.060932,0.000000
71.510002,63.160702,-49.685223,0.017910,0.002393,0.060793,280.952820,14.312420,0.607930,-49.685223,0.060932,0.000000
71.730003,63.133892,-49.685223,0.017901,0.002393,0.060793,280.833588,14.306344,0.607930,-49.685223,0.060932,0.000000
71.950005,63.102982,-49.640743,0.017906,0.002393,0.060793,280.696075,14.299340,0.607930,-49.640743,0.060932,0.000000
72.170006,63.081757,-49.685223,0.017906,0.002393,0.060793,280.601654,14.294531,0.607930,-49.685223,0.060932,0.000000
72.390007,63.046009,-49.640743,0.017888,0.002393,0.060793,280.442657,14.286430,0.607930,-49.640743,0.060932,0.000000
72.610001,63.007282,-49.729702,0.017901,0.002393,0.060793,280.270386,14.277654,0.607930,-49.729702,0.060932,0.000000
72.830002,62.997601,-49.685223,0.017906,0.002393,0.060793,280.227325,14.275460,0.607930,-49.685223,0.060932,0.000000
73.050003,62.956268,-49.729702,0.017893,0.002393,0.060793,280.043457,14.266094,0.607930,-49.729702,0.060932,0.000000
73.270004,62.925735,-49.640743,0.017901,0.002393,0.060793,279.907654,14.259175,0.607930,-49.640743,0.060932,0.000000
73.490005,62.912327,-49.640743,0.017897,0.002393,0.060793,279.847992,14.256137,0.607930,-49.640743,0.060932,0.000000
73.710007,62.883656,-49.685223,0.017884,0.002393,0.060793,279.720459,14.249640,0.607930,-49.685223,0.060932,0.000000
73.930000,62.854240,-49.729702,0.017893,0.002393,0.060793,279.589630,14.242974,0.607930,-49.729702,0.060932,0.000000
74.150002,62.833385,-49.729702,0.017919,0.002393,0.060793,279.496857,14.238249,0.607930,-49.729702,0.060932,0.000000
74.370003,62.798382,-49.729702,0.017927,0.002393,0.060793,279.341156,14.230317,0.607930,-49.729702,0.060932,0.000000
74.590004,62.782742,-49.685223,0.017919,0.002393,0.060793,279.271576,14.226773,0.607930,-49.685223,0.060932,0.000000
74.810005,62.755932,-49.685223,0.017914,0.002393,0.060793,279.152313,14.220697,0.607930,-49.685223,0.060932,0.000000
75.030006,62.727631,-49.729702,0.017923,0.002393,0.060793,279.026428,14.214285,0.607930,-49.729702,0.060932,0.000000
75.250000,62.714226,-49.774185,0.017897,0.002393,0.060793,278.966797,14.211247,0.607930,-49.774185,0.060932,0.000000
75.470001,62.681458,-49.729702,0.017914,0.002393,0.060793,278.821045,14.203821,0.607930,-49.729702,0.060932,0.000000
75.690002,62.674755,-49.729702,0.017901,0.002393,0.060793,278.791229,14.202303,0.607930,-49.729702,0.060932,0.000000
75.910004,62.643848,-49.774185,0.017906,0.002393,0.060793,278.653748,14.195299,0.607930,-49.774185,0.060932,0.000000
76.130005,62.622250,-49.729702,0.017914,0.002393,0.060793,278.557678,14.190405,0.607930,-49.729702,0.060932,0.000000
76.350006,62.596184,-49.818665,0.017906,0.002393,0.060793,278.441742,14.184499,0.607930,-49.818665,0.060932,0.000000
76.570007,62.580544,-49.774185,0.017906,0.002393,0.060793,278.372162,14.180954,0.607930,-49.774185,0.060932,0.000000
76.790001,62.561554,-49.774185,0.017906,0.002393,0.060793,278.287689,14.176651,0.607930,-49.774185,0.060932,0.000000
77.010002,62.546288,-49.774185,0.017914,0.002393,0.060793,278.219788,14.173191,0.607930,-49.774185,0.060932,0.000000
77.230003,62.512028,-49.818665,0.017910,0.002393,0.060793,278.067383,14.165428,0.607930,-49.818665,0.060932,0.000000
77.450005,62.500111,-49.818665,0.017919,0.002393,0.060793,278.014374,14.162727,0.607930,-49.818665,0.060932,0.000000
77.670006,62.475163,-49.774185,0.017919,0.002393,0.060793,277.903412,14.157074,0.607930,-49.774185,0.060932,0.000000
77.890007,62.456173,-49.818665,0.017927,0.002393,0.060793,277.818939,14.152771,0.607930,-49.818665,0.060932,0.000000
78.110001,62.433830,-49.774185,0.017906,0.002393,0.060793,277.719543,14.147708,0.607930,-49.774185,0.060932,0.000000
78.330002,62.421543,-49.818665,0.017901,0.002393,0.060793,277.664886,14.144924,0.607930,-49.818665,0.060932,0.000000
78.550003,62.393616,-49.818665,0.017906,0.002393,0.060793,277.540649,14.138596,0.607930,-49.818665,0.060932,0.000000
78.770004,62.377602,-49.818665,0.017914,0.002393,0.060793,277.469421,14.134967,0.607930,-49.818665,0.060932,0.000000
78.990005,62.375740,-49.774185,0.017888,0.002393,0.060793,277.461151,14.134544,0.607930,-49.774185,0.060932,0.000000
79.210007,62.348557,-49.818665,0.017897,0.002393,0.060784,277.340240,14.128385,0.607839,-49.818665,0.060932,0.000000
79.430000,62.332546,-49.818665,0.017897,0.002393,0.060784,277.269012,14.124757,0.607839,-49.818665,0.060932,0.000000
79.650002,62.313927,-49.863148,0.017910,0.002393,0.060784,277.186188,14.120538,0.607839,-49.863148,0.060932,0.000000
79.870003,62.291210,-49.863148,0.017910,0.002393,0.060784,277.085144,14.115390,0.607839,-49.863148,0.060932,0.000000
80.090004,62.273338,-49.818665,0.017910,0.002393,0.060784,277.005646,14.111340,0.607839,-49.818665,0.060932,0.000000
80.310005,62.259933,-49.863148,0.017893,0.002393,0.060784,276.946014,14.108302,0.607839,-49.863148,0.060932,0.000000
80.530006,62.244293,-49.863148,0.017927,0.002393,0.060784,276.876434,14.104758,0.607839,-49.863148,0.060932,0.000000
80.750008,62.227909,-49.907627,0.017914,0.002393,0.060784,276.803558,14.101046,0.607839,-49.907627,0.060932,0.000000
80.970001,62.212269,-49.818665,0.017923,0.002393,0.060784,276.733978,14.097502,0.607839,-49.818665,0.060932,0.000000
81.190002,62.190300,-49.863148,0.017906,0.002393,0.060784,276.636261,14.092524,0.607839,-49.863148,0.060932,0.000000
81.410004,62.188808,-49.863148,0.017906,0.002393,0.060784,276.629639,14.092185,0.607839,-49.863148,0.060932,0.000000
81.630005,62.155666,-49.907627,0.017910,0.002393,0.060784,276.482208,14.084675,0.607839,-49.907627,0.060932,0.000000
81.850006,62.143753,-49.907627,0.017897,0.002393,0.060784,276.429230,14.081976,0.607839,-49.907627,0.060932,0.000000
82.070007,62.134441,-49.907627,0.017914,0.002393,0.060784,276.387787,14.079866,0.607839,-49.907627,0.060932,0.000000
82.290001,62.115826,-49.863148,0.017906,0.002393,0.060784,276.304993,14.075647,0.607839,-49.863148,0.060932,0.000000
82.510002,62.093483,-49.907627,0.017919,0.002393,0.060784,276.205597,14.070584,0.607839,-49.907627,0.060932,0.000000
82.730003,62.083801,-49.952106,0.017910,0.002393,0.060784,276.162537,14.068391,0.607839,-49.952106,0.060932,0.000000
82.950005,62.071140,-49.996590,0.017901,0.002393,0.060784,276.106232,14.065521,0.607839,-49.996590,0.060932,0.000000
83.170006,62.054008,-49.996590,0.017910,0.002393,0.060784,276.030029,14.061640,0.607839,-49.996590,0.060932,0.000000
83.390007,62.041351,-49.907627,0.017910,0.002393,0.060784,275.973724,14.058771,0.607839,-49.907627,0.060932,0.000000
83.610001,62.025711,-49.952106,0.017906,0.002393,0.060784,275.904144,14.055227,0.607839,-49.952106,0.060932,0.000000
83.830002,62.012306,-49.996590,0.017914,0.002393,0.060784,275.844513,14.052190,0.607839,-49.996590,0.060932,0.000000
84.050003,61.998898,-49.952106,0.017914,0.002393,0.060784,275.784882,14.049151,0.607839,-49.952106,0.060932,0.000000
84.270004,61.984375,-49.907627,0.017919,0.002393,0.060784,275.720276,14.045860,0.607839,-49.907627,0.060932,0.000000
84.490005,61.966873,-49.952106,0.017914,0.002393,0.060784,275.642426,14.041894,0.607839,-49.952106,0.060932,0.000000
84.710007,61.947140,-49.907627,0.017914,0.002393,0.060784,275.554626,14.037422,0.607839,-49.907627,0.060932,0.000000
84.930000,61.949375,-49.996590,0.017901,0.002393,0.060784,275.564575,14.037930,0.607839,-49.996590,0.060932,0.000000
85.150002,61.919212,-49.996590,0.017901,0.002393,0.060784,275.430420,14.031094,0.607839,-49.996590,0.060932,0.000000
85.370003,61.909901,-49.907627,0.017901,0.002393,0.060784,275.388977,14.028984,0.607839,-49.907627,0.060932,0.000000
85.590004,61.901337,-49.952106,0.017914,0.002393,0.060784,275.350891,14.027043,0.607839,-49.952106,0.060932,0.000000
85.810005,61.879742,-49.996590,0.017910,0.002393,0.060784,275.254852,14.022150,0.607839,-49.996590,0.060932,0.000000
86.030006,61.863728,-50.041069,0.017914,0.002393,0.060784,275.183594,14.018521,0.607839,-50.041069,0.060932,0.000000
86.250008,61.857769,-50.041069,0.017901,0.002393,0.060784,275.157104,14.017171,0.607839,-50.041069,0.060932,0.000000
86.470001,61.848831,-49.996590,0.017919,0.002393,0.060784,275.117340,14.015145,0.607839,-49.996590,0.060932,0.000000
86.690002,61.838779,-49.996590,0.017906,0.002393,0.060784,275.072632,14.012867,0.607839,-49.996590,0.060932,0.000000
86.910004,61.829842,-50.041069,0.017906,0.002393,0.060784,275.032867,14.010842,0.607839,-50.041069,0.060932,0.000000
87.130005,61.804520,-50.041069,0.017901,0.002393,0.060784,274.920227,14.005104,0.607839,-50.041069,0.060932,0.000000
87.350006,61.803032,-50.041069,0.017914,0.002393,0.060784,274.913605,14.004767,0.607839,-50.041069,0.060932,0.000000
87.570007,61.782177,-50.041069,0.017923,0.002393,0.060784,274.820862,14.000041,0.607839,-50.041069,0.060932,0.000000
87.790001,61.777710,-50.041069,0.017923,0.002393,0.060784,274.800964,13.999029,0.607839,-50.041069,0.060932,0.000000
88.010002,61.753506,-50.041069,0.017927,0.002393,0.060784,274.693298,13.993544,0.607839,-50.041069,0.060932,0.000000
88.230003,61.742706,-50.130032,0.017901,0.002393,0.060784,274.645264,13.991097,0.607839,-50.130032,0.060932,0.000000
88.450005,61.734886,-50.085552,0.017901,0.002393,0.060784,274.610474,13.989326,0.607839,-50.085552,0.060932,0.000000
88.670006,61.725948,-50.041069,0.017919,0.002393,0.060784,274.570740,13.987300,0.607839,-50.041069,0.060932,0.000000
88.890007,61.706215,-50.130032,0.017914,0.002393,0.060784,274.482941,13.982828,0.607839,-50.130032,0.060932,0.000000
89.110001,61.695789,-50.085552,0.017910,0.002393,0.060784,274.436584,13.980466,0.607839,-50.085552,0.060932,0.000000
89.330002,61.675678,-50.085552,0.017893,0.002393,0.060784,274.347107,13.975908,0.607839,-50.085552,0.060932,0.000000
89.550003,61.668232,-50.085552,0.017910,0.002393,0.060784,274.313995,13.974221,0.607839,-50.085552,0.060932,0.000000
89.770004,61.655201,-50.085552,0.017901,0.002393,0.060784,274.256042,13.971269,0.607839,-50.085552,0.060932,0.000000
89.990005,61.644772,-50.130032,0.017910,0.002393,0.060784,274.209625,13.968905,0.607839,-50.130032,0.060932,0.000000
90.210007,61.645145,-50.085552,0.017901,0.002393,0.060784,274.211304,13.968989,0.607839,-50.085552,0.060932,0.000000
90.430008,61.635464,-50.085552,0.017906,0.002393,0.060784,274.168243,13.966795,0.607839,-50.085552,0.060932,0.000000
90.650002,61.618706,-50.174511,0.017906,0.002393,0.060784,274.093689,13.962998,0.607839,-50.174511,0.060932,0.000000
90.870003,61.612377,-50.174511,0.017919,0.002393,0.060784,274.065552,13.961564,0.607839,-50.174511,0.060932,0.000000
91.090004,61.594875,-50.085552,0.017919,0.002393,0.060784,273.987701,13.957598,0.607839,-50.085552,0.060932,0.000000
91.310005,61.587055,-50.130032,0.017906,0.002393,0.060784,273.952911,13.955826,0.607839,-50.130032,0.060932,0.000000
91.530006,61.567692,-50.085552,0.017901,0.002393,0.060784,273.866760,13.951438,0.607839,-50.085552,0.060932,0.000000
91.750008,61.545349,-50.174511,0.017914,0.002393,0.060784,273.767395,13.946375,0.607839,-50.174511,0.060932,0.000000
91.970001,61.536041,-50.130032,0.017906,0.002393,0.060784,273.725983,13.944266,0.607839,-50.130032,0.060932,0.000000
92.190002,61.535667,-50.174511,0.017936,0.002393,0.060784,273.724335,13.944182,0.607839,-50.174511,0.060932,0.000000
92.300003,61.525612,-50.174511,0.017901,0.002393,0.060784,273.679596,13.941903,0.607839,-50.174511,0.060932,0.000000