File: Data/Polished old I18 after 3_08182023_174104.csv
Time (sec),S:Load (lbs),S:HL1 (DIM),S:LVDT (in),S:Position (in),Ch:Position (mm),Ch:Load (N),Ch:Stress (MPa),Ch:Strain (mm/mm),Ch:HL1 (DIM),Set Point (),Cycles ()
0.110000,0.029785,-42.390347,-0.000030,-0.000000,-0.000000,0.132491,0.006749,-0.000000,-42.390347,0.000208,0.000000
0.350000,0.027924,-42.345867,0.000000,0.000001,0.000017,0.124210,0.006328,0.000174,-42.345867,0.000451,0.000000
0.590000,0.034256,-42.345867,-0.000026,0.000137,0.003469,0.152378,0.007763,0.034689,-42.345867,0.004440,0.000000
0.830000,0.090485,-42.301384,0.000000,0.000287,0.007293,0.402496,0.020504,0.072931,-42.301384,0.008447,0.000000
1.070000,0.111336,-42.345867,-0.000004,0.000442,0.011222,0.495246,0.025229,0.112218,-42.345867,0.012436,0.000000
1.310000,0.117668,-42.434826,0.000030,0.000605,0.015367,0.523414,0.026664,0.153671,-42.434826,0.016442,0.000000
1.550000,0.115059,-42.345867,0.000134,0.000764,0.019400,0.511808,0.026073,0.193999,-42.345867,0.020432,0.000000
1.790000,0.115807,-42.434826,0.000280,0.000918,0.023319,0.515133,0.026242,0.233195,-42.434826,0.024438,0.000000
2.030000,0.093460,-42.434826,0.000492,0.001073,0.027266,0.415731,0.021178,0.272656,-42.434826,0.028428,0.000000
2.270000,0.090111,-42.345867,0.000677,0.001230,0.031255,0.400833,0.020419,0.312545,-42.345867,0.032434,0.000000
2.510000,0.038727,-42.434826,0.000832,0.001388,0.035253,0.172265,0.008776,0.352525,-42.434826,0.036424,0.000000
2.750000,0.106499,-42.345867,0.000987,0.001549,0.039346,0.473730,0.024133,0.393459,-42.345867,0.040430,0.000000
2.990000,0.108727,-42.390347,0.001155,0.001703,0.043266,0.483640,0.024638,0.432659,-42.390347,0.044419,0.000000
3.230000,0.103516,-42.434826,0.001350,0.001867,0.047429,0.460460,0.023457,0.474285,-42.434826,0.048426,0.000000
3.470000,0.115807,-42.390347,0.001492,0.002016,0.051201,0.515133,0.026242,0.512009,-42.390347,0.052415,0.000000
3.710000,0.089363,-42.434826,0.001669,0.002179,0.055355,0.397507,0.020250,0.553548,-42.434826,0.056421,0.000000
3.950000,0.108727,-42.434826,0.001824,0.002328,0.059127,0.483640,0.024638,0.591273,-42.434826,0.060428,0.000000
4.190000,0.077080,-42.434826,0.001975,0.002495,0.063368,0.342868,0.017467,0.633682,-42.434826,0.064417,0.000000
4.430000,0.040955,-42.434826,0.002169,0.002648,0.067270,0.182175,0.009280,0.672705,-42.434826,0.068424,0.000000
4.670000,0.084900,-42.390347,0.002328,0.002808,0.071321,0.377654,0.019239,0.713207,-42.390347,0.072413,0.000000
4.910000,0.112083,-42.434826,0.002479,0.002957,0.075102,0.498572,0.025398,0.751018,-42.434826,0.076420,0.000000
5.150000,0.116180,-42.345867,0.002669,0.003123,0.079334,0.516796,0.026327,0.793337,-42.345867,0.080409,0.000000
5.390000,0.075592,-42.434826,0.002850,0.003282,0.083366,0.336250,0.017129,0.833665,-42.434826,0.084416,0.000000
5.630000,0.111336,-42.434826,0.002997,0.003441,0.087390,0.495246,0.025229,0.873902,-42.434826,0.088405,0.000000
5.870000,0.096817,-42.434826,0.003186,0.003592,0.091241,0.430664,0.021939,0.912406,-42.434826,0.092412,0.000000
6.110000,0.083412,-42.479309,0.003333,0.003751,0.095273,0.371036,0.018901,0.952734,-42.479309,0.096401,0.000000
6.350000,0.052872,-42.390347,0.003518,0.003912,0.099367,0.235185,0.011981,0.993667,-42.390347,0.100407,0.000000
6.590000,0.036865,-42.434826,0.003686,0.004064,0.103217,0.163985,0.008354,1.032171,-42.434826,0.104396,0.000000
6.830000,0.113945,-42.434826,0.003824,0.004223,0.107276,0.506853,0.025820,1.072757,-42.434826,0.108403,0.000000
7.070000,0.117668,-42.390347,0.003967,0.004373,0.111074,0.523414,0.026664,1.110742,-42.390347,0.112392,0.000000
7.310000,0.100906,-42.390347,0.004156,0.004540,0.115306,0.448854,0.022866,1.153061,-42.390347,0.116399,0.000000
7.550000,0.095695,-42.390347,0.004333,0.004695,0.119252,0.425675,0.021685,1.192522,-42.390347,0.120388,0.000000
7.790000,0.102776,-42.434826,0.004488,0.004853,0.123276,0.457169,0.023289,1.232759,-42.434826,0.124395,0.000000
8.030001,0.105751,-42.390347,0.004665,0.005006,0.127144,0.470404,0.023964,1.271437,-42.390347,0.128384,0.000000
8.270000,0.092720,-42.345867,0.004812,0.005171,0.131350,0.412439,0.021011,1.313499,-42.345867,0.132391,0.000000
8.510000,0.050270,-42.434826,0.004954,0.005321,0.135157,0.223612,0.011391,1.351571,-42.434826,0.136380,0.000000
8.750000,0.079315,-42.434826,0.005118,0.005484,0.139285,0.352812,0.017973,1.392849,-42.434826,0.140386,0.000000
8.990001,0.140755,-42.434826,0.005290,0.005634,0.143110,0.626108,0.031895,1.431095,-42.434826,0.144393,0.000000
9.230000,0.128464,-42.479309,0.005450,0.005796,0.147220,0.571435,0.029110,1.472203,-42.479309,0.148382,0.000000
9.470000,0.093094,-42.390347,0.005592,0.005953,0.151218,0.414102,0.021095,1.512179,-42.390347,0.152389,0.000000
9.710000,0.122505,-42.479309,0.005756,0.006113,0.155259,0.544930,0.027760,1.552594,-42.479309,0.156378,0.000000
9.950001,0.143364,-42.390347,0.005937,0.006266,0.159162,0.637715,0.032487,1.591617,-42.390347,0.160385,0.000000
10.190001,0.109100,-42.479309,0.006066,0.006430,0.163333,0.485303,0.024722,1.633334,-42.479309,0.164374,0.000000
10.430000,0.087875,-42.434826,0.006256,0.006583,0.167210,0.390889,0.019913,1.672099,-42.434826,0.168381,0.000000
10.670000,0.067398,-42.390347,0.006398,0.006737,0.171112,0.299802,0.015273,1.711121,-42.390347,0.172370,0.000000
10.910001,0.107986,-42.479309,0.006588,0.006900,0.175266,0.480348,0.024470,1.752664,-42.479309,0.176376,0.000000
11.150001,0.130699,-42.434826,0.006709,0.007053,0.179143,0.581379,0.029617,1.791429,-42.434826,0.180365,0.000000
11.390000,0.139267,-42.434826,0.006868,0.007213,0.183219,0.619490,0.031558,1.832188,-42.434826,0.184372,0.000000
11.630000,0.110222,-42.479309,0.007023,0.007367,0.187130,0.490291,0.024977,1.871297,-42.479309,0.188361,0.000000
11.870001,0.131073,-42.434826,0.007200,0.007527,0.191188,0.583042,0.029702,1.911883,-42.434826,0.192368,0.000000
12.110001,0.141502,-42.434826,0.007334,0.007683,0.195161,0.629434,0.032065,1.951605,-42.434826,0.196357,0.000000
12.350000,0.122879,-42.390347,0.007524,0.007848,0.199349,0.546593,0.027845,1.993489,-42.390347,0.200364,0.000000
12.590000,0.084900,-42.434826,0.007653,0.007999,0.203165,0.377654,0.019239,2.031648,-42.434826,0.204353,0.000000
12.830001,0.138145,-42.434826,0.007795,0.008160,0.207276,0.614502,0.031304,2.072756,-42.434826,0.208360,0.000000
13.070001,0.128090,-42.390347,0.007950,0.008315,0.211195,0.569772,0.029026,2.111953,-42.390347,0.212349,0.000000
13.310000,0.147827,-42.479309,0.008071,0.008474,0.215237,0.657568,0.033498,2.152368,-42.479309,0.216355,0.000000
13.550000,0.128090,-42.434826,0.008278,0.008626,0.219096,0.569772,0.029026,2.190958,-42.434826,0.220362,0.000000
13.790001,0.137772,-42.434826,0.008399,0.008791,0.223302,0.612839,0.031219,2.233020,-42.434826,0.224351,0.000000
14.030001,0.140381,-42.434826,0.008580,0.008940,0.227083,0.624445,0.031811,2.270831,-42.434826,0.228358,0.000000
14.270000,0.144104,-42.434826,0.008770,0.009110,0.231393,0.641007,0.032654,2.313930,-42.434826,0.232347,0.000000
14.510000,0.116920,-42.479309,0.008933,0.009261,0.235226,0.520088,0.026495,2.352263,-42.479309,0.236353,0.000000
14.750001,0.125114,-42.479309,0.009127,0.009419,0.239250,0.556537,0.028351,2.392500,-42.479309,0.240343,0.000000
14.990001,0.132187,-42.479309,0.009261,0.009576,0.243239,0.587997,0.029954,2.432393,-42.479309,0.244349,0.000000
15.230000,0.112083,-42.479309,0.009451,0.009735,0.247281,0.498572,0.025398,2.472808,-42.479309,0.248339,0.000000
15.470000,0.109848,-42.479309,0.009610,0.009891,0.251244,0.488628,0.024892,2.512440,-42.479309,0.252345,0.000000
15.710001,0.117294,-42.479309,0.009766,0.010041,0.255051,0.521751,0.026579,2.550508,-42.479309,0.256334,0.000000
15.950001,0.140755,-42.434826,0.009968,0.010206,0.259222,0.626108,0.031895,2.592221,-42.434826,0.260341,0.000000
16.190001,0.148949,-42.479309,0.010072,0.010367,0.263333,0.662557,0.033752,2.633329,-42.479309,0.264330,0.000000
16.430000,0.124741,-42.434826,0.010279,0.010522,0.267270,0.554874,0.028267,2.672704,-42.434826,0.268337,0.000000
16.670000,0.131821,-42.434826,0.010417,0.010680,0.271268,0.586368,0.029871,2.712680,-42.434826,0.272326,0.000000
16.910002,0.140381,-42.434826,0.010576,0.010837,0.275249,0.624445,0.031811,2.752485,-42.434826,0.276333,0.000000
17.150002,0.131821,-42.434826,0.010736,0.010992,0.279203,0.586368,0.029871,2.792034,-42.434826,0.280322,0.000000
17.390001,0.111336,-42.479309,0.010925,0.011152,0.283262,0.495246,0.025229,2.832619,-42.479309,0.284328,0.000000
17.630001,0.128464,-42.523788,0.011076,0.011305,0.287156,0.571435,0.029110,2.871558,-42.523788,0.288318,0.000000
17.870001,0.152672,-42.434826,0.011214,0.011463,0.291171,0.679118,0.034596,2.911708,-42.434826,0.292324,0.000000
18.110001,0.168678,-42.479309,0.011361,0.011617,0.295065,0.750318,0.038223,2.950647,-42.479309,0.296331,0.000000
18.350000,0.164215,-42.479309,0.011576,0.011788,0.299409,0.730465,0.037212,2.994094,-42.479309,0.300320,0.000000
18.590000,0.140381,-42.434826,0.011714,0.011938,0.303234,0.624445,0.031811,3.032341,-42.434826,0.304327,0.000000
18.830002,0.148575,-42.479309,0.011861,0.012097,0.307275,0.660894,0.033668,3.072752,-42.479309,0.308316,0.000000
19.070002,0.151924,-42.434826,0.012055,0.012253,0.311221,0.675792,0.034427,3.112213,-42.434826,0.312323,0.000000
19.310001,0.140381,-42.434826,0.012189,0.012412,0.315262,0.624445,0.031811,3.152624,-42.434826,0.316312,0.000000
19.550001,0.097183,-42.479309,0.012383,0.012568,0.319217,0.432293,0.022022,3.192169,-42.479309,0.320318,0.000000
19.790001,0.158997,-42.434826,0.012516,0.012726,0.323250,0.707252,0.036029,3.232497,-42.434826,0.324308,0.000000
20.030001,0.179482,-42.523788,0.012702,0.012879,0.327118,0.798374,0.040671,3.271175,-42.523788,0.328314,0.000000
20.270000,0.179482,-42.434826,0.012840,0.013043,0.331280,0.798374,0.040671,3.312801,-42.434826,0.332304,0.000000
20.510000,0.159744,-42.479309,0.013021,0.013197,0.335208,0.710578,0.036199,3.352085,-42.479309,0.336310,0.000000
20.750002,0.151184,-42.434826,0.013176,0.013360,0.339354,0.672500,0.034259,3.393541,-42.434826,0.340299,0.000000
20.990002,0.171288,-42.479309,0.013331,0.013511,0.343170,0.761925,0.038814,3.431696,-42.479309,0.344306,0.000000
21.230001,0.140755,-42.523788,0.013495,0.013670,0.347220,0.626108,0.031895,3.472198,-42.523788,0.348295,0.000000
21.470001,0.140755,-42.479309,0.013655,0.013826,0.351174,0.626108,0.031895,3.511743,-42.479309,0.352302,0.000000
21.710001,0.106865,-42.434826,0.013840,0.013985,0.355215,0.475359,0.024216,3.552154,-42.434826,0.356291,0.000000
21.950001,0.157883,-42.434826,0.013978,0.014140,0.359144,0.702297,0.035777,3.591441,-42.434826,0.360297,0.000000
22.190001,0.175385,-42.434826,0.014137,0.014295,0.363099,0.780149,0.039743,3.630986,-42.434826,0.364287,0.000000
22.430000,0.157509,-42.479309,0.014297,0.014460,0.367287,0.700634,0.035692,3.672873,-42.479309,0.368293,0.000000
22.670002,0.172409,-42.434826,0.014478,0.014613,0.371164,0.766914,0.039068,3.711638,-42.434826,0.372283,0.000000
22.910002,0.152672,-42.434826,0.014672,0.014774,0.375257,0.679118,0.034596,3.752572,-42.434826,0.376289,0.000000
23.150002,0.173149,-42.434826,0.014819,0.014923,0.379038,0.770206,0.039236,3.790383,-42.434826,0.380296,0.000000
23.390001,0.144852,-42.434826,0.014983,0.015090,0.383296,0.644332,0.032824,3.832963,-42.434826,0.384285,0.000000
23.630001,0.100540,-42.479309,0.015155,0.015239,0.387069,0.447225,0.022783,3.870687,-42.479309,0.388292,0.000000
23.870001,0.156395,-42.479309,0.015349,0.015401,0.391188,0.695680,0.035440,3.911882,-42.479309,0.392281,0.000000
24.110001,0.175385,-42.434826,0.015504,0.015550,0.394969,0.780149,0.039743,3.949693,-42.434826,0.396287,0.000000
24.350000,0.178734,-42.479309,0.015677,0.015718,0.399236,0.795048,0.040502,3.992360,-42.479309,0.400276,0.000000
24.590002,0.145226,-42.479309,0.015853,0.015874,0.403199,0.645995,0.032909,4.031992,-42.479309,0.404283,0.000000
24.830002,0.165703,-42.479309,0.016009,0.016034,0.407266,0.737083,0.037549,4.072664,-42.479309,0.408272,0.000000
25.070002,0.171661,-42.434826,0.016155,0.016182,0.411030,0.763588,0.038899,4.110301,-42.434826,0.412279,0.000000
25.310001,0.158630,-42.479309,0.016345,0.016349,0.415254,0.705623,0.035946,4.152537,-42.479309,0.416268,0.000000
25.550001,0.105003,-42.434826,0.016509,0.016503,0.419182,0.467078,0.023794,4.191820,-42.434826,0.420275,0.000000
25.790001,0.107239,-42.434826,0.016703,0.016657,0.423093,0.477022,0.024301,4.230934,-42.434826,0.424264,0.000000
26.030001,0.180595,-42.523788,0.016845,0.016815,0.427100,0.803328,0.040924,4.271000,-42.523788,0.428271,0.000000
26.270000,0.161980,-42.390347,0.017005,0.016968,0.430977,0.720522,0.036705,4.309765,-42.390347,0.432260,0.000000
26.510002,0.150063,-42.434826,0.017143,0.017133,0.435182,0.667512,0.034005,4.351823,-42.434826,0.436266,0.000000
26.750002,0.165329,-42.523788,0.017319,0.017287,0.439102,0.735420,0.037464,4.391023,-42.523788,0.440256,0.000000
26.990002,0.177620,-42.479309,0.017500,0.017447,0.443152,0.790093,0.040249,4.431521,-42.479309,0.444262,0.000000
27.230001,0.176132,-42.523788,0.017669,0.017601,0.447072,0.783475,0.039912,4.470722,-42.523788,0.448252,0.000000
27.470001,0.172775,-42.434826,0.017871,0.017761,0.451122,0.768543,0.039151,4.511220,-42.434826,0.452258,0.000000
27.710001,0.136658,-42.523788,0.018014,0.017913,0.454998,0.607884,0.030967,4.549985,-42.523788,0.456265,0.000000
27.950001,0.225655,-42.523788,0.018190,0.018077,0.459161,1.003762,0.051134,4.591611,-42.523788,0.460254,0.000000
28.190001,0.304596,-42.479309,0.018328,0.018228,0.462994,1.354910,0.069022,4.629945,-42.479309,0.464261,0.000000
28.430002,0.404022,-42.479309,0.018496,0.018388,0.467053,1.797181,0.091553,4.670530,-42.479309,0.468250,0.000000
28.670002,0.561539,-42.434826,0.018665,0.018547,0.471103,2.497849,0.127246,4.711029,-42.434826,0.472256,0.000000
28.910002,0.604729,-42.479309,0.018768,-0.000005,-0.000139,2.689968,0.137033,-0.001385,-42.479309,0.000078,0.000000
29.150002,0.587975,-42.479309,0.018751,-0.000005,-0.000139,2.615441,0.133237,-0.001385,-42.479309,0.000078,0.000000
29.390001,0.628937,-42.523788,0.018772,-0.000005,-0.000139,2.797651,0.142519,-0.001385,-42.523788,0.000226,0.000000
29.630001,0.583878,-42.479309,0.018755,-0.000005,-0.000139,2.597217,0.132309,-0.001385,-42.479309,0.000625,0.000000
29.870001,0.601006,-42.523788,0.018764,-0.000004,-0.000104,2.673406,0.136190,-0.001041,-42.523788,0.001023,0.000000
30.110001,0.688889,-42.523788,0.018772,0.000023,0.000590,3.064329,0.156104,0.005897,-42.523788,0.001422,0.000000
30.350002,0.725380,-42.523788,0.018772,0.000037,0.000945,3.226651,0.164373,0.009455,-42.523788,0.001821,0.000000
30.590002,0.728729,-42.434826,0.018777,0.000051,0.001283,3.241549,0.165132,0.012835,-42.434826,0.002220,0.000000
30.830002,0.745117,-42.434826,0.018798,0.000066,0.001682,3.314447,0.168846,0.016824,-42.434826,0.002619,0.000000
31.070002,0.803207,-42.479309,0.018824,0.000083,0.002107,3.572845,0.182009,0.021074,-42.479309,0.003018,0.000000
31.310001,0.805069,-42.479309,0.018820,0.000096,0.002428,3.581126,0.182431,0.024284,-42.479309,0.003426,0.000000
31.550001,0.816612,-42.479309,0.018828,0.000106,0.002680,3.632473,0.185047,0.026797,-42.479309,0.003825,0.000000
31.790001,0.859062,-42.479309,0.018850,0.000125,0.003183,3.821300,0.194666,0.031827,-42.479309,0.004224,0.000000
32.030003,0.917152,-42.523788,0.018863,0.000150,0.003799,4.079698,0.207830,0.037985,-42.523788,0.004622,0.000000
32.270000,0.920502,-42.568272,0.018906,0.000161,0.004093,4.094596,0.208589,0.040934,-42.568272,0.005021,0.000000
32.510002,0.920128,-42.479309,0.018910,0.000172,0.004371,4.092933,0.208504,0.043708,-42.479309,0.005420,0.000000
32.750000,0.955505,-42.523788,0.018910,0.000184,0.004683,4.250300,0.216521,0.046831,-42.523788,0.005819,0.000000
32.990002,1.038170,-42.523788,0.018941,0.000209,0.005316,4.618010,0.235253,0.053163,-42.523788,0.006218,0.000000
33.230003,1.034821,-42.568272,0.018953,0.000220,0.005585,4.603112,0.234494,0.055850,-42.568272,0.006626,0.000000
33.470001,1.069450,-42.523788,0.018962,0.000235,0.005967,4.757153,0.242341,0.059665,-42.523788,0.007025,0.000000
33.710003,1.121582,-42.523788,0.018979,0.000251,0.006374,4.989046,0.254154,0.063741,-42.523788,0.007424,0.000000
33.950001,1.179672,-42.523788,0.019009,0.000272,0.006903,5.247444,0.267318,0.069033,-42.523788,0.007823,0.000000
34.190002,1.194199,-42.479309,0.019027,0.000285,0.007233,5.312061,0.270609,0.072329,-42.479309,0.008222,0.000000
34.430000,1.179298,-42.523788,0.019027,0.000296,0.007519,5.245781,0.267233,0.075191,-42.523788,0.008620,0.000000
34.670002,1.231430,-42.523788,0.019048,0.000315,0.007996,5.477674,0.279046,0.079960,-42.523788,0.009019,0.000000
34.910000,1.291016,-42.479309,0.019048,0.000335,0.008499,5.742724,0.292548,0.084990,-42.479309,0.009418,0.000000
35.150002,1.291756,-42.568272,0.019048,0.000346,0.008785,5.746016,0.292716,0.087851,-42.568272,0.009826,0.000000
35.390003,1.345749,-42.523788,0.019091,0.000361,0.009167,5.986190,0.304951,0.091666,-42.523788,0.010225,0.000000
35.630001,1.344261,-42.523788,0.019096,0.000366,0.009297,5.979572,0.304614,0.092968,-42.523788,0.010623,0.000000
35.870003,1.458580,-42.523788,0.019117,0.000397,0.010086,6.488088,0.330519,0.100860,-42.523788,0.011022,0.000000
36.110001,1.479431,-42.434826,0.019152,0.000411,0.010450,6.580838,0.335244,0.104501,-42.434826,0.011421,0.000000
36.350002,1.478317,-42.568272,0.019169,0.000425,0.010806,6.575883,0.334991,0.108059,-42.568272,0.011820,0.000000
36.590000,1.525978,-42.568272,0.019152,0.000438,0.011135,6.787889,0.345792,0.111352,-42.568272,0.012219,0.000000
36.830002,1.593010,-42.523788,0.019186,0.000458,0.011638,7.086062,0.360981,0.116382,-42.523788,0.012627,0.000000
37.070004,1.646629,-42.523788,0.019191,0.000473,0.012020,7.324573,0.373132,0.120197,-42.523788,0.013026,0.000000
37.310001,1.685730,-42.479309,0.019208,0.000488,0.012393,7.498501,0.381992,0.123929,-42.479309,0.013425,0.000000
37.550003,1.684235,-42.523788,0.019203,0.000495,0.012584,7.491850,0.381653,0.125836,-42.523788,0.013824,0.000000
37.790001,1.845474,-42.523788,0.019238,0.000525,0.013347,8.209080,0.418190,0.133467,-42.523788,0.014222,0.000000
38.030003,1.831696,-42.568272,0.019255,0.000537,0.013642,8.147789,0.415068,0.136415,-42.568272,0.014621,0.000000
38.270000,1.848457,-42.523788,0.019268,0.000545,0.013841,8.222349,0.418866,0.138410,-42.523788,0.015020,0.000000
38.510002,1.906174,-42.523788,0.019285,0.000563,0.014301,8.479084,0.431945,0.143008,-42.523788,0.015419,0.000000
38.750000,1.974686,-42.568272,0.019285,0.000582,0.014786,8.783840,0.447470,0.147864,-42.568272,0.015827,0.000000
38.990002,2.070015,-42.568272,0.019307,0.000599,0.015202,9.207887,0.469072,0.152024,-42.568272,0.016226,0.000000
39.230003,2.129227,-42.523788,0.019316,0.000613,0.015576,9.471273,0.482490,0.155756,-42.523788,0.016625,0.000000
39.470001,2.147469,-42.523788,0.019320,0.000625,0.015870,9.552417,0.486623,0.158704,-42.523788,0.017024,0.000000
39.710003,2.227905,-42.479309,0.019350,0.000643,0.016330,9.910217,0.504851,0.163299,-42.479309,0.017423,0.000000
39.950001,2.347061,-42.568272,0.019367,0.000665,0.016894,10.440249,0.531852,0.168935,-42.568272,0.017822,0.000000
40.190002,2.297905,-42.568272,0.019389,0.000678,0.017232,10.221592,0.520713,0.172319,-42.568272,0.018220,0.000000
40.430000,2.354507,-42.479309,0.019419,0.000689,0.017492,10.473372,0.533539,0.174919,-42.479309,0.018619,0.000000
40.670002,2.439407,-42.523788,0.019389,0.000702,0.017822,10.851026,0.552778,0.178216,-42.523788,0.019027,0.000000
40.910004,2.632301,-42.523788,0.019441,0.000723,0.018368,11.709061,0.596488,0.183681,-42.523788,0.019426,0.000000
41.150002,2.691505,-42.568272,0.019467,0.000742,0.018836,11.972414,0.609904,0.188363,-42.568272,0.019825,0.000000
41.390003,2.728371,-42.568272,0.019475,0.000754,0.019140,12.136399,0.618258,0.191398,-42.568272,0.020224,0.000000
41.630001,2.805450,-42.523788,0.019475,0.000767,0.019469,12.479267,0.635724,0.194695,-42.523788,0.020623,0.000000
41.870003,2.943230,-42.523788,0.019510,0.000787,0.019998,13.092139,0.666945,0.199982,-42.523788,0.021022,0.000000
42.110001,2.984932,-42.479309,0.019535,0.000800,0.020311,13.277640,0.676395,0.203105,-42.479309,0.021421,0.000000
42.350002,3.012115,-42.568272,0.019527,0.000813,0.020658,13.398559,0.682555,0.206576,-42.568272,0.021820,0.000000
42.590000,3.174469,-42.568272,0.019535,0.000833,0.021161,14.120744,0.719345,0.211606,-42.568272,0.022227,0.000000
42.830002,3.323418,-42.568272,0.019548,0.000850,0.021603,14.783300,0.753097,0.216027,-42.568272,0.022626,0.000000
43.070004,3.402740,-42.568272,0.019570,0.000864,0.021941,15.136146,0.771072,0.219410,-42.568272,0.023025,0.000000
43.310001,3.490616,-42.612751,0.019587,0.000877,0.022270,15.527035,0.790985,0.222703,-42.612751,0.023424,0.000000
43.550003,3.600098,-42.568272,0.019609,0.000893,0.022678,16.014034,0.815794,0.226780,-42.568272,0.023823,0.000000
43.790001,3.827240,-42.568272,0.019635,0.000916,0.023268,17.024414,0.867265,0.232676,-42.568272,0.024222,0.000000
44.030003,3.844002,-42.523788,0.019665,0.000926,0.023511,17.098974,0.871063,0.235106,-42.523788,0.024621,0.000000
44.270000,3.964645,-42.612751,0.019669,0.000942,0.023927,17.635624,0.898401,0.239270,-42.612751,0.025020,0.000000
44.510002,4.174667,-42.479309,0.019678,0.000961,0.024404,18.569847,0.945993,0.244039,-42.479309,0.025427,0.000000
44.750004,4.281532,-42.523788,0.019682,0.000974,0.024751,19.045206,0.970209,0.247506,-42.523788,0.025826,0.000000
44.990002,4.472939,-42.568272,0.019708,0.000992,0.025184,19.896624,1.013582,0.251843,-42.568272,0.026225,0.000000
45.230003,4.562675,-42.568272,0.019712,0.001002,0.025444,20.295794,1.033917,0.254443,-42.568272,0.026624,0.000000
45.470001,4.748116,-42.568272,0.019742,0.001020,0.025913,21.120672,1.075938,0.259129,-42.568272,0.027023,0.000000
45.710003,4.923134,-42.523788,0.019734,0.001037,0.026346,21.899193,1.115598,0.263463,-42.523788,0.027422,0.000000
45.950001,5.014740,-42.612751,0.019755,0.001051,0.026693,22.306677,1.136356,0.266934,-42.612751,0.027821,0.000000
46.190002,5.164055,-42.612751,0.019773,0.001065,0.027049,22.970863,1.170192,0.270488,-42.612751,0.028220,0.000000
46.430000,5.400139,-42.568272,0.019807,0.001084,0.027526,24.021017,1.223689,0.275260,-42.568272,0.028627,0.000000
46.670002,5.618355,-42.657230,0.019816,0.001101,0.027968,24.991690,1.273137,0.279681,-42.657230,0.029026,0.000000
46.910004,5.780708,-42.479309,0.019833,0.001116,0.028341,25.713875,1.309927,0.283409,-42.479309,0.029425,0.000000
47.150002,5.809006,-42.568272,0.019846,0.001124,0.028549,25.839748,1.316339,0.285491,-42.568272,0.029824,0.000000
47.390003,6.137810,-42.568272,0.019855,0.001143,0.029043,27.302341,1.390848,0.290434,-42.568272,0.030223,0.000000
47.630001,6.427887,-42.612751,0.019863,0.001161,0.029495,28.592669,1.456580,0.294946,-42.612751,0.030622,0.000000
47.870003,6.666580,-42.612751,0.019889,0.001178,0.029928,29.654430,1.510669,0.299279,-42.612751,0.031021,0.000000
48.110001,6.785744,-42.523788,0.019893,0.001191,0.030249,30.184496,1.537672,0.302489,-42.523788,0.031420,0.000000
48.350002,6.901550,-42.612751,0.019906,0.001203,0.030544,30.699629,1.563914,0.305437,-42.612751,0.031827,0.000000
48.590004,7.295891,-42.612751,0.019928,0.001223,0.031055,32.453743,1.653273,0.310554,-42.612751,0.032226,0.000000
48.830002,7.620598,-42.523788,0.019945,0.001239,0.031480,33.898113,1.726852,0.314805,-42.523788,0.032625,0.000000
49.070004,7.678688,-42.568272,0.019967,0.001251,0.031775,34.156509,1.740016,0.317753,-42.568272,0.033024,0.000000
49.310001,8.154213,-42.568272,0.019975,0.001271,0.032296,36.271751,1.847771,0.322958,-42.568272,0.033423,0.000000
49.550003,8.545570,-42.568272,0.019988,0.001292,0.032816,38.012596,1.936454,0.328158,-42.568272,0.033822,0.000000
49.790001,8.717239,-42.612751,0.020018,0.001305,0.033154,38.776218,1.975355,0.331542,-42.612751,0.034221,0.000000
50.030003,8.941406,-42.568272,0.020040,0.001319,0.033493,39.773361,2.026152,0.334925,-42.568272,0.034628,0.000000
50.270004,9.189034,-42.701714,0.020036,0.001333,0.033857,40.874863,2.082265,0.338566,-42.701714,0.035027,0.000000
50.510002,9.816483,-42.612751,0.020057,0.001356,0.034446,43.665894,2.224447,0.344463,-42.612751,0.035426,0.000000
50.750004,9.920372,-42.612751,0.020092,0.001368,0.034750,44.128017,2.247988,0.347499,-42.612751,0.035825,0.000000
50.990002,10.070808,-42.568272,0.020083,0.001379,0.035019,44.797192,2.282078,0.350186,-42.568272,0.036224,0.000000
51.230003,10.296837,-42.523788,0.020109,0.001391,0.035331,45.802616,2.333297,0.353309,-42.523788,0.036623,0.000000
51.470001,11.196495,-42.612751,0.020130,0.001420,0.036068,49.804497,2.537162,0.360682,-42.612751,0.037022,0.000000
51.710003,11.267242,-42.657230,0.020156,0.001432,0.036363,50.119198,2.553194,0.363630,-42.657230,0.037421,0.000000
51.950001,11.611687,-42.568272,0.020152,0.001448,0.036788,51.651363,2.631246,0.367877,-42.568272,0.037829,0.000000
52.190002,11.823196,-42.657230,0.020182,0.001461,0.037100,52.592205,2.679175,0.370999,-42.657230,0.038227,0.000000
52.430004,12.318825,-42.568272,0.020182,0.001479,0.037577,54.796871,2.791486,0.375768,-42.568272,0.038626,0.000000
52.670002,12.544106,-42.612751,0.020199,0.001493,0.037933,55.798969,2.842535,0.379326,-42.612751,0.039025,0.000000
52.910004,12.748917,-42.612751,0.020217,0.001503,0.038175,56.710014,2.888946,0.381752,-42.612751,0.039424,0.000000
53.150002,13.177513,-42.612751,0.020247,0.001521,0.038626,58.616505,2.986067,0.386264,-42.612751,0.039823,0.000000
53.390003,14.033600,-42.612751,0.020247,0.001549,0.039346,62.424568,3.180059,0.393463,-42.612751,0.040222,0.000000
53.630001,14.112541,-42.612751,0.020273,0.001560,0.039615,62.775719,3.197948,0.396150,-42.612751,0.040621,0.000000
53.870003,14.275269,-42.612751,0.020264,0.001572,0.039919,63.499565,3.234822,0.399185,-42.612751,0.041029,0.000000
54.110004,14.559013,-42.612751,0.020281,0.001584,0.040231,64.761726,3.299120,0.402308,-42.612751,0.041428,0.000000
54.350002,15.443398,-42.568272,0.020281,0.001609,0.040881,68.695663,3.499524,0.408810,-42.568272,0.041826,0.000000
54.590004,15.533516,-42.657230,0.020324,0.001620,0.041158,69.096527,3.519945,0.411585,-42.657230,0.042225,0.000000
54.830002,15.849655,-42.612751,0.020324,0.001633,0.041479,70.502785,3.591583,0.414794,-42.612751,0.042624,0.000000
55.070004,16.319595,-42.612751,0.020342,0.001650,0.041904,72.593185,3.698073,0.419045,-42.612751,0.043023,0.000000
55.310001,17.038269,-42.612751,0.020389,0.001670,0.042425,75.790009,3.860927,0.424249,-42.612751,0.043422,0.000000
55.550003,17.236000,-42.612751,0.020389,0.001683,0.042754,76.669556,3.905734,0.427542,-42.612751,0.043821,0.000000
55.790001,17.410645,-42.657230,0.020406,0.001699,0.043145,77.446411,3.945308,0.431448,-42.657230,0.044229,0.000000
56.030003,17.979630,-42.612751,0.020424,0.001717,0.043622,79.977386,4.074242,0.436217,-42.612751,0.044628,0.000000
56.270004,18.560532,-42.657230,0.020428,0.001734,0.044055,82.561371,4.205876,0.440550,-42.657230,0.045027,0.000000
56.510002,18.726608,-42.612751,0.020450,0.001745,0.044315,83.300117,4.243510,0.443154,-42.612751,0.045426,0.000000
56.750004,19.132118,-42.612751,0.020441,0.001760,0.044714,85.103912,4.335400,0.447144,-42.612751,0.045824,0.000000
56.990002,19.208832,-42.701714,0.020462,0.001772,0.045001,85.445152,4.352783,0.450005,-42.701714,0.046223,0.000000
57.230003,20.367279,-42.612751,0.020488,0.001798,0.045668,90.598183,4.615292,0.456682,-42.612751,0.046622,0.000000
57.470001,20.649910,-42.657230,0.020506,0.001812,0.046015,91.855385,4.679337,0.460152,-42.657230,0.047021,0.000000
57.710003,20.891579,-42.612751,0.020514,0.001827,0.046405,92.930382,4.734099,0.464055,-42.612751,0.047429,0.000000
57.950005,21.195435,-42.612751,0.020553,0.001838,0.046674,94.282005,4.802954,0.466742,-42.612751,0.047827,0.000000
58.190002,22.009445,-42.612751,0.020540,0.001858,0.047186,97.902901,4.987411,0.471859,-42.612751,0.048226,0.000000
58.430004,22.529274,-42.612751,0.020540,0.001875,0.047620,100.215218,5.105206,0.476197,-42.612751,0.048625,0.000000
58.670002,22.781372,-42.612751,0.020566,0.001887,0.047932,101.336601,5.162333,0.479315,-42.612751,0.049024,0.000000
58.910004,22.879303,-42.657230,0.020575,0.001896,0.048166,101.772224,5.184524,0.481658,-42.657230,0.049423,0.000000
59.150002,24.206818,-42.657230,0.020592,0.001927,0.048938,107.677299,5.485343,0.489376,-42.657230,0.049822,0.000000
59.390003,24.277939,-42.657230,0.020635,0.001936,0.049172,107.993668,5.501460,0.491718,-42.657230,0.050221,0.000000
59.630001,24.378853,-42.568272,0.020631,0.001951,0.049562,108.442551,5.524327,0.495621,-42.568272,0.050629,0.000000
59.870003,24.962357,-42.701714,0.020613,0.001962,0.049839,111.038109,5.656551,0.498395,-42.701714,0.051028,0.000000
60.110004,25.592041,-42.612751,0.020669,0.001980,0.050291,113.839081,5.799240,0.502907,-42.612751,0.051427,0.000000
60.350002,26.264915,-42.657230,0.020648,0.001999,0.050785,116.832176,5.951715,0.507850,-42.657230,0.051825,0.000000
60.590004,26.698730,-42.657230,0.020682,0.002012,0.051106,118.761887,6.050019,0.511055,-42.657230,0.052224,0.000000
60.830002,27.021576,-42.612751,0.020678,0.002027,0.051496,120.197975,6.123177,0.514961,-42.612751,0.052623,0.000000
61.070004,27.714935,-42.657230,0.020695,0.002044,0.051930,123.282188,6.280294,0.519295,-42.657230,0.053022,0.000000
61.310001,28.595596,-42.612751,0.020721,0.002065,0.052441,127.199562,6.479855,0.524412,-42.612751,0.053421,0.000000
61.550003,28.961266,-42.612751,0.020721,0.002079,0.052814,128.826141,6.562717,0.528140,-42.612751,0.053829,0.000000
61.790005,29.095695,-42.657230,0.020725,0.002088,0.053031,129.424118,6.593179,0.530309,-42.657230,0.054228,0.000000
62.030003,29.581635,-42.657230,0.020751,0.002101,0.053369,131.585678,6.703294,0.533693,-42.657230,0.054627,0.000000
62.270004,30.504005,-42.657230,0.020760,0.002123,0.053933,135.688599,6.912306,0.539329,-42.657230,0.055026,0.000000
62.510002,31.213371,-42.701714,0.020790,0.002140,0.054367,138.844009,7.073051,0.543666,-42.701714,0.055424,0.000000
62.750004,31.576439,-42.657230,0.020782,0.002153,0.054679,140.459015,7.155324,0.546789,-42.657230,0.055823,0.000000
62.990002,32.037064,-42.701714,0.020777,0.002165,0.054982,142.507980,7.259702,0.549820,-42.701714,0.056222,0.000000
63.230003,32.965759,-42.657230,0.020794,0.002186,0.055529,146.639023,7.470148,0.555286,-42.657230,0.056630,0.000000
63.470001,33.361221,-42.657230,0.020807,0.002200,0.055893,148.398117,7.559761,0.558927,-42.657230,0.057029,0.000000
63.710003,33.876213,-42.657230,0.020816,0.002214,0.056231,150.688919,7.676459,0.562311,-42.657230,0.057428,0.000000
63.950005,34.844749,-42.657230,0.020838,0.002234,0.056743,154.997192,7.895933,0.567428,-42.657230,0.057827,0.000000
64.190002,35.650566,-42.701714,0.020855,0.002253,0.057237,158.581635,8.078533,0.572371,-42.701714,0.058226,0.000000
64.430000,36.064644,-42.657230,0.020863,0.002264,0.057515,160.423553,8.172365,0.575145,-42.657230,0.058625,0.000000
64.670006,36.437759,-42.657230,0.020863,0.002276,0.057818,162.083252,8.256914,0.578181,-42.657230,0.059024,0.000000
64.910004,37.103935,-42.657230,0.020885,0.002293,0.058243,165.046555,8.407872,0.582431,-42.657230,0.059422,0.000000
65.150002,38.367767,-42.612751,0.020907,0.002316,0.058833,170.668350,8.694261,0.588328,-42.612751,0.059830,0.000000
65.389999,38.609810,-42.701714,0.020889,0.002324,0.059041,171.745010,8.749107,0.590410,-42.701714,0.060229,0.000000
65.630005,39.425674,-42.612751,0.020902,0.002343,0.059509,175.374161,8.933986,0.595091,-42.612751,0.060628,0.000000
65.870003,40.268730,-42.612751,0.020941,0.002361,0.059969,179.124252,9.125025,0.599686,-42.612751,0.061027,0.000000
66.110001,40.890587,-42.657230,0.020937,0.002375,0.060333,181.890411,9.265939,0.603331,-42.657230,0.061426,0.000000
66.350006,41.545967,-42.612751,0.020963,0.002390,0.060715,184.805695,9.414451,0.607146,-42.612751,0.061825,0.000000
66.590004,41.937332,-42.657230,0.020950,0.002400,0.060966,186.546570,9.503135,0.609660,-42.657230,0.062224,0.000000
66.830002,42.879807,-42.612751,0.020980,0.002419,0.061443,190.738907,9.716702,0.614432,-42.612751,0.062623,0.000000
67.070000,43.770889,-42.657230,0.020971,0.002437,0.061894,194.702637,9.918625,0.618940,-42.657230,0.063030,0.000000
67.310005,44.319771,-42.657230,0.020971,0.002449,0.062198,197.144180,10.043004,0.621976,-42.657230,0.063429,0.000000
67.550003,45.031372,-42.612751,0.020976,0.002463,0.062562,200.309540,10.204254,0.625617,-42.612751,0.063828,0.000000
67.790001,45.953735,-42.657230,0.020976,0.002484,0.063082,204.412430,10.413265,0.630821,-42.657230,0.064227,0.000000
68.030006,46.862328,-42.657230,0.021010,0.002499,0.063464,208.454041,10.619155,0.634636,-42.657230,0.064626,0.000000
68.270004,47.576538,-42.612751,0.021023,0.002514,0.063863,211.631012,10.780998,0.638625,-42.612751,0.065025,0.000000
68.510002,47.794373,-42.657230,0.021019,0.002522,0.064071,212.599991,10.830360,0.640707,-42.657230,0.065424,0.000000
68.750000,48.850800,-42.657230,0.021023,0.002542,0.064556,217.299210,11.069750,0.645563,-42.657230,0.065823,0.000000
68.990005,49.868492,-42.746193,0.021010,0.002561,0.065042,221.826126,11.300363,0.650419,-42.746193,0.066230,0.000000
69.230003,50.896606,-42.612751,0.021053,0.002578,0.065476,226.399414,11.533336,0.654757,-42.612751,0.066629,0.000000
69.470001,51.441765,-42.657230,0.021040,0.002589,0.065770,228.824402,11.656871,0.657705,-42.657230,0.067028,0.000000
69.710007,51.834618,-42.701714,0.021057,0.002601,0.066074,230.571899,11.745893,0.660740,-42.701714,0.067427,0.000000
69.950005,52.914497,-42.657230,0.021062,0.002621,0.066577,235.375443,11.990597,0.665771,-42.657230,0.067826,0.000000
70.190002,54.096779,-42.746193,0.021053,0.002638,0.067002,240.634491,12.258505,0.670021,-42.746193,0.068225,0.000000
70.430000,54.459099,-42.746193,0.021083,0.002649,0.067297,242.246170,12.340609,0.672969,-42.746193,0.068624,0.000000
70.670006,55.711388,-42.612751,0.021075,0.002669,0.067800,247.816635,12.624380,0.678000,-42.612751,0.069022,0.000000
70.910004,57.099594,-42.701714,0.021096,0.002692,0.068381,253.991684,12.938952,0.683809,-42.701714,0.069430,0.000000
71.150002,57.792946,-42.612751,0.021088,0.002704,0.068693,257.075867,13.096068,0.686932,-42.612751,0.069829,0.000000
71.390007,58.417786,-42.746193,0.021096,0.002717,0.069022,259.855286,13.237659,0.690225,-42.746193,0.070228,0.000000
71.630005,59.142799,-42.657230,0.021105,0.002731,0.069378,263.080322,13.401950,0.693783,-42.657230,0.070627,0.000000
71.870003,60.567123,-42.701714,0.021114,0.002755,0.069977,269.416016,13.724706,0.699767,-42.701714,0.071026,0.000000
72.110001,61.222870,-42.701714,0.021096,0.002769,0.070323,272.332916,13.873301,0.703233,-42.701714,0.071425,0.000000
72.350006,61.698761,-42.657230,0.021101,0.002779,0.070575,274.449799,13.981139,0.705750,-42.657230,0.071824,0.000000
72.590004,62.371269,-42.701714,0.021126,0.002793,0.070930,277.441254,14.133532,0.709304,-42.701714,0.072223,0.000000
72.830002,64.393616,-42.701714,0.021165,0.002819,0.071598,286.437103,14.591802,0.715981,-42.701714,0.072630,0.000000
73.070000,65.014374,-42.657230,0.021144,0.002834,0.071971,289.198364,14.732468,0.719713,-42.657230,0.073029,0.000000
73.310005,65.941208,-42.701714,0.021126,0.002847,0.072309,293.321136,14.942492,0.723093,-42.701714,0.073428,0.000000
73.550003,66.572006,-42.657230,0.021152,0.002860,0.072656,296.127075,15.085432,0.726564,-42.657230,0.073827,0.000000
73.790001,67.538681,-42.701714,0.021170,0.002866,0.072786,300.427063,15.304484,0.727862,-42.701714,0.073055,0.000000
74.030006,67.005447,-42.746193,0.021170,0.002865,0.072769,298.055115,15.183651,0.727691,-42.746193,0.073055,0.000000
74.270004,66.783142,-42.612751,0.021165,0.002856,0.072552,297.066254,15.133276,0.725523,-42.612751,0.072769,0.000000
74.510002,66.525452,-42.701714,0.021178,0.002856,0.072552,295.919983,15.074883,0.725523,-42.701714,0.072769,0.000000
74.750000,66.310593,-42.701714,0.021187,0.002856,0.072552,294.964233,15.026196,0.725523,-42.701714,0.072769,0.000000
74.990005,66.129990,-42.657230,0.021174,0.002856,0.072552,294.160889,14.985270,0.725523,-42.657230,0.072769,0.000000
75.230003,65.964661,-42.701714,0.021191,0.002856,0.072552,293.425476,14.947806,0.725523,-42.701714,0.072769,0.000000
75.470001,65.814972,-42.746193,0.021165,0.002856,0.072552,292.759613,14.913886,0.725523,-42.746193,0.072769,0.000000
75.710007,65.686127,-42.746193,0.021152,0.002856,0.072552,292.186493,14.884689,0.725523,-42.746193,0.072769,0.000000
75.950005,65.568451,-42.657230,0.021178,0.002856,0.072552,291.663025,14.858024,0.725523,-42.657230,0.072769,0.000000
76.190002,65.460846,-42.701714,0.021170,0.002856,0.072552,291.184387,14.833639,0.725523,-42.701714,0.072769,0.000000
76.430000,65.354721,-42.701714,0.021152,0.002856,0.072552,290.712311,14.809591,0.725523,-42.701714,0.072769,0.000000
76.670006,65.276138,-42.701714,0.021195,0.002856,0.072552,290.362762,14.791784,0.725523,-42.701714,0.072769,0.000000
76.910004,65.182312,-42.746193,0.021161,0.002856,0.072552,289.945404,14.770522,0.725523,-42.746193,0.072769,0.000000
77.150002,65.100006,-42.701714,0.021161,0.002856,0.072552,289.579285,14.751872,0.725523,-42.701714,0.072769,0.000000
77.390007,65.010651,-42.701714,0.021182,0.002856,0.072552,289.181824,14.731625,0.725523,-42.701714,0.072769,0.000000
77.630005,64.954788,-42.746193,0.021170,0.002856,0.072552,288.933319,14.718966,0.725523,-42.746193,0.072769,0.000000
77.870003,64.876221,-42.701714,0.021208,0.002856,0.072552,288.583832,14.701161,0.725523,-42.701714,0.072769,0.000000
78.110001,64.815887,-42.701714,0.021170,0.002856,0.072552,288.315460,14.687490,0.725523,-42.701714,0.072769,0.000000
78.350006,64.758179,-42.701714,0.021187,0.002856,0.072552,288.058777,14.674413,0.725523,-42.701714,0.072769,0.000000
78.590004,64.698227,-42.657230,0.021191,0.002856,0.072552,287.792084,14.660829,0.725523,-42.657230,0.072769,0.000000
78.830002,64.651672,-42.746193,0.021174,0.002856,0.072552,287.584991,14.650278,0.725523,-42.746193,0.072769,0.000000
79.070007,64.590973,-42.701714,0.021174,0.002856,0.072552,287.315002,14.636523,0.725523,-42.701714,0.072769,0.000000
79.310005,64.536987,-42.701714,0.021182,0.002856,0.072552,287.074860,14.624290,0.725523,-42.701714,0.072769,0.000000
79.550003,64.486343,-42.746193,0.021187,0.002856,0.072552,286.849579,14.612814,0.725523,-42.746193,0.072769,0.000000
79.790001,64.445007,-42.701714,0.021187,0.002856,0.072552,286.665710,14.603447,0.725523,-42.701714,0.072769,0.000000
80.030006,64.398834,-42.746193,0.021208,0.002856,0.072552,286.460327,14.592984,0.725523,-42.746193,0.072769,0.000000
80.270004,64.357498,-42.657230,0.021187,0.002856,0.072552,286.276459,14.583617,0.725523,-42.657230,0.072769,0.000000
80.510002,64.310211,-42.746193,0.021182,0.002856,0.072552,286.066101,14.572902,0.725523,-42.746193,0.072769,0.000000
80.750008,64.268875,-42.701714,0.021191,0.002856,0.072552,285.882233,14.563535,0.725523,-42.701714,0.072769,0.000000
80.990005,64.244675,-42.701714,0.021170,0.002856,0.072552,285.774597,14.558051,0.725523,-42.701714,0.072769,0.000000
81.230003,64.202225,-42.790676,0.021191,0.002856,0.072552,285.585754,14.548432,0.725523,-42.790676,0.072769,0.000000
81.470001,64.175415,-42.701714,0.021182,0.002856,0.072552,285.466492,14.542356,0.725523,-42.701714,0.072769,0.000000
81.710007,64.136688,-42.790676,0.021170,0.002856,0.072552,285.294250,14.533582,0.725523,-42.790676,0.072769,0.000000
81.950005,64.105774,-42.746193,0.021208,0.002856,0.072552,285.156738,14.526576,0.725523,-42.746193,0.072769,0.000000
82.190002,64.073380,-42.701714,0.021191,0.002856,0.072552,285.012634,14.519235,0.725523,-42.701714,0.072769,0.000000
82.430000,64.024979,-42.790676,0.021174,0.002856,0.072552,284.797333,14.508267,0.725523,-42.790676,0.072769,0.000000
82.670006,63.992203,-42.657230,0.021187,0.002856,0.072552,284.651520,14.500840,0.725523,-42.657230,0.072769,0.000000
82.910004,63.969116,-42.701714,0.021170,0.002856,0.072552,284.548828,14.495609,0.725523,-42.701714,0.072769,0.000000
83.150002,63.931885,-42.790676,0.021200,0.002856,0.072552,284.383240,14.487172,0.725523,-42.790676,0.072769,0.000000
83.390007,63.914383,-42.701714,0.021182,0.002856,0.072552,284.305389,14.483207,0.725523,-42.701714,0.072769,0.000000
83.630005,63.886826,-42.790676,0.021182,0.002856,0.072552,284.182800,14.476961,0.725523,-42.790676,0.072769,0.000000
83.870003,63.852188,-42.701714,0.021187,0.002856,0.072552,284.028717,14.469112,0.725523,-42.701714,0.072769,0.000000
84.110001,63.826492,-42.790676,0.021191,0.002856,0.072552,283.914429,14.463290,0.725523,-42.790676,0.072769,0.000000
84.350006,63.811600,-42.746193,0.021191,0.002856,0.072552,283.848175,14.459915,0.725523,-42.746193,0.072769,0.000000
84.590004,63.770264,-42.746193,0.021191,0.002856,0.072552,283.664307,14.450549,0.725523,-42.746193,0.072769,0.000000
84.830002,63.758728,-42.790676,0.021187,0.002856,0.072552,283.612976,14.447934,0.725523,-42.790676,0.072769,0.000000
85.070007,63.718140,-42.746193,0.021187,0.002856,0.072552,283.432434,14.438737,0.725523,-42.746193,0.072769,0.000000
85.310005,63.706589,-42.746193,0.021191,0.002856,0.072552,283.381073,14.436119,0.725523,-42.746193,0.072769,0.000000
85.550003,63.679779,-42.746193,0.021195,0.002856,0.072552,283.261810,14.430044,0.725523,-42.746193,0.072769,0.000000
85.790001,63.665634,-42.746193,0.021187,0.002856,0.072552,283.198883,14.426839,0.725523,-42.746193,0.072769,0.000000
86.030006,63.637711,-42.746193,0.021187,0.002856,0.072552,283.074677,14.420511,0.725523,-42.746193,0.072769,0.000000
86.270004,63.622437,-42.790676,0.021200,0.002856,0.072552,283.006744,14.417050,0.725523,-42.790676,0.072769,0.000000
86.510002,63.600098,-42.746193,0.021170,0.002856,0.072552,282.907349,14.411988,0.725523,-42.746193,0.072769,0.000000
86.750008,63.574402,-42.790676,0.021182,0.002856,0.072552,282.793060,14.406165,0.725523,-42.790676,0.072769,0.000000
86.990005,63.553543,-42.701714,0.021191,0.002856,0.072552,282.700287,14.401439,0.725523,-42.701714,0.072769,0.000000
87.230003,63.528976,-42.790676,0.021204,0.002856,0.072552,282.591003,14.395872,0.725523,-42.790676,0.072769,0.000000
87.470001,63.514450,-42.746193,0.021200,0.002856,0.072552,282.526398,14.392580,0.725523,-42.746193,0.072769,0.000000
87.710007,63.500305,-42.746193,0.021187,0.002856,0.072552,282.463470,14.389375,0.725523,-42.746193,0.072769,0.000000
87.950005,63.470886,-42.879639,0.021187,0.002856,0.072552,282.332611,14.382709,0.725523,-42.879639,0.072769,0.000000
88.190002,63.458221,-42.790676,0.021213,0.002856,0.072552,282.276276,14.379839,0.725523,-42.790676,0.072769,0.000000
88.430008,63.440353,-42.790676,0.021170,0.002856,0.072552,282.196777,14.375790,0.725523,-42.790676,0.072769,0.000000
88.670006,63.427689,-42.701714,0.021187,0.002856,0.072552,282.140442,14.372920,0.725523,-42.701714,0.072769,0.000000
88.910004,63.399765,-42.701714,0.021191,0.002856,0.072552,282.016235,14.366592,0.725523,-42.701714,0.072769,0.000000
89.150002,63.391937,-42.790676,0.021195,0.002856,0.072552,281.981415,14.364819,0.725523,-42.790676,0.072769,0.000000
89.390007,63.378906,-42.746193,0.021187,0.002856,0.072552,281.923462,14.361865,0.725523,-42.746193,0.072769,0.000000
89.630005,63.365128,-42.746193,0.021191,0.002856,0.072552,281.862152,14.358743,0.725523,-42.746193,0.072769,0.000000
89.870003,63.339066,-42.790676,0.021200,0.002856,0.072552,281.746246,14.352838,0.725523,-42.790676,0.072769,0.000000
90.110001,63.317093,-42.790676,0.021182,0.002856,0.072552,281.648499,14.347858,0.725523,-42.790676,0.072769,0.000000
90.350006,63.301819,-42.879639,0.021200,0.002856,0.072552,281.580566,14.344398,0.725523,-42.879639,0.072769,0.000000
90.590004,63.290649,-42.746193,0.021187,0.002856,0.072552,281.530884,14.341866,0.725523,-42.746193,0.072769,0.000000
90.830002,63.272034,-42.701714,0.021182,0.002856,0.072552,281.448059,14.337647,0.725523,-42.701714,0.072769,0.000000
91.070007,63.260117,-42.790676,0.021195,0.002856,0.072552,281.395050,14.334947,0.725523,-42.790676,0.072769,0.000000
91.310005,63.257141,-42.790676,0.021191,0.002856,0.072552,281.381805,14.334273,0.725523,-42.790676,0.072769,0.000000
91.550003,63.239273,-42.790676,0.021178,0.002856,0.072552,281.302338,14.330224,0.725523,-42.790676,0.072769,0.000000
91.790001,63.228470,-42.746193,0.021213,0.002856,0.072552,281.254272,14.327776,0.725523,-42.746193,0.072769,0.000000
92.030006,63.213577,-42.790676,0.021187,0.002856,0.072552,281.188049,14.324401,0.725523,-42.790676,0.072769,0.000000
92.270004,63.186020,-42.835155,0.021187,0.002856,0.072552,281.065460,14.318157,0.725523,-42.835155,0.072769,0.000000
92.510002,63.183411,-42.701714,0.021195,0.002856,0.072552,281.053833,14.317565,0.725523,-42.701714,0.072769,0.000000
92.750008,63.167397,-42.790676,0.021174,0.002856,0.072552,280.982605,14.313936,0.725523,-42.790676,0.072769,0.000000
92.990005,63.153252,-42.790676,0.021195,0.002856,0.072552,280.919708,14.310731,0.725523,-42.790676,0.072769,0.000000
93.230003,63.135002,-42.790676,0.021170,0.002856,0.072552,280.838501,14.306596,0.725523,-42.790676,0.072769,0.000000
93.470001,63.126808,-42.835155,0.021200,0.002856,0.072552,280.802063,14.304739,0.725523,-42.835155,0.072769,0.000000
93.710007,63.119362,-42.790676,0.021195,0.002856,0.072552,280.768951,14.303052,0.725523,-42.790676,0.072769,0.000000
93.950005,63.104843,-42.835155,0.021200,0.002856,0.072552,280.704376,14.299762,0.725523,-42.835155,0.072769,0.000000
94.190002,63.085854,-42.790676,0.021195,0.002856,0.072552,280.619904,14.295459,0.725523,-42.790676,0.072769,0.000000
94.430008,63.081757,-42.835155,0.021191,0.002856,0.072552,280.601654,14.294531,0.725523,-42.835155,0.072769,0.000000
94.670006,63.064995,-42.790676,0.021195,0.002856,0.072552,280.527100,14.290732,0.725523,-42.790676,0.072769,0.000000
94.910004,63.048988,-42.790676,0.021200,0.002856,0.072552,280.455902,14.287106,0.725523,-42.790676,0.072769,0.000000
95.150002,63.038559,-42.835155,0.021187,0.002856,0.072552,280.409515,14.284741,0.725523,-42.835155,0.072769,0.000000
95.390007,63.026268,-42.790676,0.021230,0.002856,0.072552,280.354828,14.281956,0.725523,-42.790676,0.072769,0.000000
95.630005,63.012123,-42.835155,0.021200,0.002856,0.072552,280.291931,14.278751,0.725523,-42.835155,0.072769,0.000000
95.870003,62.993126,-42.790676,0.021195,0.002856,0.072552,280.207428,14.274446,0.725523,-42.790676,0.072769,0.000000
96.110008,62.996857,-42.701714,0.021182,0.002856,0.072552,280.223999,14.275291,0.725523,-42.701714,0.072769,0.000000
96.350006,62.977493,-42.835155,0.021187,0.002856,0.072552,280.137878,14.270904,0.725523,-42.835155,0.072769,0.000000
96.590004,62.967064,-42.790676,0.021204,0.002856,0.072552,280.091492,14.268541,0.725523,-42.790676,0.072769,0.000000
96.830002,62.957382,-42.835155,0.021200,0.002856,0.072552,280.048431,14.266347,0.725523,-42.835155,0.072769,0.000000
97.070007,62.954399,-42.790676,0.021204,0.002856,0.072552,280.035156,14.265671,0.725523,-42.790676,0.072769,0.000000
97.310005,62.942856,-42.746193,0.021200,0.002856,0.072552,279.983795,14.263055,0.725523,-42.746193,0.072769,0.000000
97.550003,62.919403,-42.835155,0.021200,0.002856,0.072552,279.879486,14.257740,0.725523,-42.835155,0.072769,0.000000
97.790001,62.914932,-42.746193,0.021208,0.002856,0.072552,279.859589,14.256727,0.725523,-42.746193,0.072769,0.000000
98.030006,62.908974,-42.790676,0.021204,0.002856,0.072552,279.833099,14.255377,0.725523,-42.790676,0.072769,0.000000
98.270004,62.882904,-42.835155,0.021221,0.002856,0.072552,279.717133,14.249470,0.725523,-42.835155,0.072769,0.000000
98.510002,62.879555,-42.790676,0.021178,0.002856,0.072552,279.702240,14.248711,0.725523,-42.790676,0.072769,0.000000
98.750008,62.871361,-42.879639,0.021200,0.002856,0.072552,279.665771,14.246854,0.725523,-42.879639,0.072769,0.000000
98.990005,62.862427,-42.790676,0.021208,0.002856,0.072552,279.626038,14.244830,0.725523,-42.790676,0.072769,0.000000
99.230003,62.855721,-42.835155,0.021195,0.002856,0.072552,279.596222,14.243310,0.725523,-42.835155,0.072769,0.000000
99.470001,62.838966,-42.835155,0.021200,0.002856,0.072552,279.521667,14.239513,0.725523,-42.835155,0.072769,0.000000
99.710007,62.838593,-42.790676,0.021217,0.002856,0.072552,279.520020,14.239429,0.725523,-42.790676,0.072769,0.000000
99.950005,62.815132,-42.835155,0.021178,0.002856,0.072552,279.415649,14.234112,0.725523,-42.835155,0.072769,0.000000
100.190002,62.802475,-42.790676,0.021200,0.002856,0.072552,279.359375,14.231244,0.725523,-42.790676,0.072769,0.000000
100.430008,62.797630,-42.790676,0.021195,0.002856,0.072552,279.337799,14.230146,0.725523,-42.790676,0.072769,0.000000
100.670006,62.782738,-42.924118,0.021195,0.002856,0.072552,279.271576,14.226772,0.725523,-42.924118,0.072769,0.000000
100.910004,62.780876,-42.790676,0.021195,0.002856,0.072552,279.263275,14.226350,0.725523,-42.790676,0.072769,0.000000
101.150002,62.772682,-42.879639,0.021200,0.002856,0.072552,279.226837,14.224493,0.725523,-42.879639,0.072769,0.000000
101.390007,62.752953,-42.835155,0.021191,0.002856,0.072552,279.139069,14.220022,0.725523,-42.835155,0.072769,0.000000
101.630005,62.755180,-42.790676,0.021204,0.002856,0.072552,279.148987,14.220527,0.725523,-42.790676,0.072769,0.000000
101.870003,62.742897,-42.835155,0.021191,0.002856,0.072552,279.094330,14.217744,0.725523,-42.835155,0.072769,0.000000
102.110008,62.738052,-42.835155,0.021178,0.002856,0.072552,279.072784,14.216646,0.725523,-42.835155,0.072769,0.000000
102.350006,62.729492,-42.879639,0.021204,0.002856,0.072552,279.034729,14.214705,0.725523,-42.879639,0.072769,0.000000
102.590004,62.701561,-42.879639,0.021182,0.002856,0.072552,278.910461,14.208377,0.725523,-42.879639,0.072769,0.000000
102.830002,62.713104,-42.835155,0.021191,0.002856,0.072552,278.961823,14.210993,0.725523,-42.835155,0.072769,0.000000
103.070007,62.709007,-42.879639,0.021191,0.002856,0.072552,278.943604,14.210064,0.725523,-42.879639,0.072769,0.000000
103.310005,62.685181,-42.746193,0.021187,0.002856,0.072552,278.837616,14.204665,0.725523,-42.746193,0.072769,0.000000
103.550003,62.675125,-42.879639,0.021195,0.002856,0.072552,278.792877,14.202387,0.725523,-42.879639,0.072769,0.000000
103.790009,62.675865,-42.835155,0.021200,0.002856,0.072552,278.796173,14.202554,0.725523,-42.835155,0.072769,0.000000
104.030006,62.662094,-42.924118,0.021195,0.002856,0.072552,278.734924,14.199433,0.725523,-42.924118,0.072769,0.000000
104.270004,62.666931,-42.835155,0.021174,0.002856,0.072552,278.756439,14.200530,0.725523,-42.835155,0.072769,0.000000
104.300003,62.641983,-42.790676,0.021204,0.002856,0.072552,278.645447,14.194876,0.725523,-42.790676,0.072769,0.000000