File: Data/PP LVDT 01mm 2_06192023_135627.csv
Time (sec),S:Load (lbs),S:HL1 (DIM),S:LVDT (in),S:Position (in),Ch:Position (mm),Ch:Load (N),Ch:Stress (MPa),Ch:Strain (mm/mm),Ch:HL1 (DIM),Set Point (),Cycles ()
0.110000,0.003724,-1296.708740,0.000022,-0.000000,-0.000000,0.016564,0.000844,-0.000000,-1296.708740,0.000191,0.000000
0.590000,-0.077081,-1296.575195,0.000086,0.000093,0.002350,-0.342874,-0.017467,0.023501,-1296.575195,0.003157,0.000000
1.070000,-0.008192,-1296.619751,0.000220,0.000395,0.010034,-0.036441,-0.001856,0.100338,-1296.619751,0.011152,0.000000
1.550000,-0.132937,-1296.619751,0.000582,0.000712,0.018090,-0.591333,-0.030124,0.180903,-1296.619751,0.019148,0.000000
2.030000,0.005586,-1296.753174,0.000974,0.001027,0.026077,0.024846,0.001266,0.260775,-1296.753174,0.027162,0.000000
2.510000,-0.007820,-1296.708740,0.001293,0.001342,0.034091,-0.034784,-0.001772,0.340906,-1296.708740,0.035157,0.000000
2.990000,0.001117,-1296.619751,0.001901,0.001657,0.042086,0.004969,0.000253,0.420864,-1296.619751,0.043153,0.000000
3.470000,0.000745,-1296.619751,0.001919,0.001975,0.050178,0.003313,0.000169,0.501777,-1296.619751,0.051149,0.000000
3.950000,0.018991,-1296.619751,0.002341,0.002287,0.058095,0.084476,0.004303,0.580954,-1296.619751,0.059145,0.000000
4.430000,0.007075,-1296.619751,0.002695,0.002607,0.066213,0.031471,0.001603,0.662127,-1296.619751,0.067141,0.000000
4.910000,0.010799,-1296.619751,0.003285,0.002912,0.073974,0.048036,0.002447,0.739744,-1296.619751,0.075136,0.000000
5.390000,0.005586,-1296.619751,0.003320,0.003226,0.081944,0.024846,0.001266,0.819441,-1296.619751,0.083132,0.000000
5.870000,-0.046547,-1296.575195,0.003652,0.003546,0.090061,-0.207049,-0.010548,0.900614,-1296.575195,0.091128,0.000000
6.350000,0.048408,-1296.619751,0.003958,0.003861,0.098057,0.215331,0.010969,0.980572,-1296.619751,0.099124,0.000000
6.830000,-0.032024,-1296.619751,0.004333,0.004171,0.105932,-0.142450,-0.007257,1.059316,-1296.619751,0.107120,0.000000
7.310000,0.013778,-1296.619751,0.004454,0.004487,0.113962,0.061287,0.003122,1.139621,-1296.619751,0.115115,0.000000
7.790000,-0.124372,-1296.619751,0.004846,0.004800,0.121932,-0.553236,-0.028183,1.219319,-1296.619751,0.123111,0.000000
8.270000,0.057718,-1296.575195,0.005273,0.005113,0.129867,0.256741,0.013079,1.298670,-1296.575195,0.131107,0.000000
8.750000,-0.063676,-1296.708740,0.005510,0.005428,0.137880,-0.283244,-0.014429,1.378802,-1296.708740,0.139103,0.000000
9.230000,0.057345,-1296.619751,0.005868,0.005743,0.145867,0.255085,0.012995,1.458674,-1296.619751,0.147099,0.000000
9.710000,-0.077081,-1296.664185,0.006433,0.006057,0.153854,-0.342874,-0.017467,1.538545,-1296.664185,0.155095,0.000000
10.190001,0.070751,-1296.619751,0.006472,0.006375,0.161937,0.314715,0.016032,1.619370,-1296.619751,0.163090,0.000000
10.670000,-0.064048,-1296.619751,0.006950,0.006695,0.170054,-0.284900,-0.014514,1.700543,-1296.619751,0.171086,0.000000
11.150001,0.072240,-1296.664185,0.007205,0.007008,0.178007,0.321341,0.016370,1.780067,-1296.664185,0.179082,0.000000
11.630000,-0.051760,-1296.619751,0.007662,0.007325,0.186055,-0.230239,-0.011729,1.860546,-1296.619751,0.187095,0.000000
12.110001,0.030162,-1296.708740,0.007856,0.007639,0.194042,0.134168,0.006835,1.940417,-1296.708740,0.195091,0.000000
12.590000,0.077453,-1296.664185,0.008067,0.007951,0.201960,0.344530,0.017551,2.019595,-1296.664185,0.203087,0.000000
13.070001,0.077081,-1296.619751,0.008554,0.008268,0.210016,0.342874,0.017467,2.100161,-1296.619751,0.211083,0.000000
13.550000,0.062931,-1296.619751,0.008852,0.008585,0.218064,0.279931,0.014260,2.180639,-1296.619751,0.219079,0.000000
14.030001,0.051760,-1296.664185,0.009326,0.008894,0.225904,0.230239,0.011729,2.259035,-1296.664185,0.227074,0.000000
14.510000,0.075219,-1296.664185,0.009546,0.009214,0.234038,0.334592,0.017045,2.340382,-1296.664185,0.235070,0.000000
14.990001,-0.018619,-1296.708740,0.009787,0.009527,0.241973,-0.082820,-0.004219,2.419733,-1296.708740,0.243066,0.000000
15.470000,0.069261,-1296.619751,0.010201,0.009842,0.249995,0.308089,0.015695,2.499952,-1296.619751,0.251062,0.000000
15.950001,0.015267,-1296.619751,0.010356,0.010154,0.257904,0.067912,0.003460,2.579043,-1296.619751,0.259058,0.000000
16.430000,0.043940,-1296.619751,0.010753,0.010476,0.266082,0.195455,0.009957,2.660821,-1296.619751,0.267053,0.000000
16.910002,-0.027928,-1296.664185,0.011128,0.010780,0.273818,-0.124230,-0.006329,2.738178,-1296.664185,0.275049,0.000000
17.390001,0.087508,-1296.753174,0.011413,0.011101,0.281961,0.389253,0.019829,2.819611,-1296.753174,0.283045,0.000000
17.870001,-0.006330,-1296.708740,0.011723,0.011411,0.289844,-0.028159,-0.001434,2.898442,-1296.708740,0.291041,0.000000
18.350000,0.061814,-1296.708740,0.012085,0.011723,0.297771,0.274962,0.014007,2.977705,-1296.708740,0.299037,0.000000
18.830002,-0.035003,-1296.708740,0.012581,0.012041,0.305836,-0.155701,-0.007932,3.058358,-1296.708740,0.307033,0.000000
19.310001,0.071123,-1296.664185,0.012814,0.012357,0.313866,0.316371,0.016117,3.138664,-1296.664185,0.315028,0.000000
19.790001,0.011171,-1296.708740,0.013154,0.012674,0.321923,0.049692,0.002531,3.219229,-1296.708740,0.323024,0.000000
20.270000,0.092348,-1296.708740,0.013530,0.012985,0.329823,0.410786,0.020926,3.298233,-1296.708740,0.331020,0.000000
20.750002,-0.072240,-1296.664185,0.013749,0.013304,0.337932,-0.321341,-0.016370,3.379319,-1296.664185,0.339033,0.000000
21.230001,0.095327,-1296.664185,0.014176,0.013619,0.345919,0.424037,0.021601,3.459190,-1296.664185,0.347029,0.000000
21.710001,0.023832,-1296.708740,0.014448,0.013935,0.353941,0.106009,0.005400,3.539408,-1296.708740,0.355025,0.000000
22.190001,0.094955,-1296.753174,0.014857,0.014248,0.361911,0.422381,0.021517,3.619105,-1296.753174,0.363021,0.000000
22.670002,0.012288,-1296.708740,0.015043,0.014568,0.370019,0.054661,0.002785,3.700191,-1296.708740,0.371016,0.000000
23.150002,0.107988,-1296.708740,0.015383,0.014878,0.377911,0.480355,0.024470,3.779110,-1296.708740,0.379012,0.000000
23.630001,0.087135,-1296.664185,0.015698,0.015197,0.385993,0.387596,0.019745,3.859934,-1296.664185,0.387008,0.000000
24.110001,0.081177,-1296.708740,0.016069,0.015505,0.393816,0.361094,0.018395,3.938159,-1296.708740,0.395004,0.000000
24.590002,0.074474,-1296.708740,0.016548,0.015821,0.401846,0.331279,0.016876,4.018463,-1296.708740,0.403000,0.000000
25.070002,0.061814,-1296.708740,0.016720,0.016138,0.409894,0.274962,0.014007,4.098943,-1296.708740,0.410995,0.000000
25.550001,0.120276,-1296.708740,0.017099,0.016454,0.417942,0.535016,0.027255,4.179421,-1296.708740,0.418991,0.000000
26.030001,0.042450,-1296.664185,0.017345,0.016762,0.425765,0.188829,0.009619,4.257646,-1296.664185,0.426987,0.000000
26.510002,0.079315,-1296.753174,0.017802,0.017080,0.433821,0.352812,0.017973,4.338211,-1296.753174,0.434983,0.000000
26.990002,-0.049153,-1296.797607,0.018147,0.017392,0.441756,-0.218644,-0.011138,4.417561,-1296.797607,0.442979,0.000000
27.470001,0.135916,-1296.797607,0.018393,0.017704,0.449691,0.604584,0.030799,4.496912,-1296.797607,0.450975,0.000000
27.950001,0.018619,-1296.753174,0.018811,0.018021,0.457722,0.082820,0.004219,4.577217,-1296.753174,0.458971,0.000000
28.430002,0.127351,-1296.664185,0.019117,0.018332,0.465640,0.566487,0.028858,4.656395,-1296.664185,0.466966,0.000000
28.910002,-0.010426,-1296.753174,0.019441,0.018650,0.473722,-0.046379,-0.002363,4.737220,-1296.753174,0.474962,0.000000
29.390001,0.127351,-1296.842163,0.019837,0.018968,0.481787,0.566487,0.028858,4.817872,-1296.842163,0.482958,0.000000
29.870001,-0.007075,-1296.753174,0.020014,0.019285,0.489835,-0.031471,-0.001603,4.898351,-1296.753174,0.490954,0.000000
30.350002,0.131075,-1296.708740,0.020467,0.019599,0.497822,0.583051,0.029702,4.978223,-1296.708740,0.498967,0.000000
30.830002,-0.003351,-1296.753174,0.020708,0.019915,0.505853,-0.014908,-0.000759,5.058527,-1296.753174,0.506963,0.000000
31.310001,0.094583,-1296.753174,0.021342,0.020229,0.513814,0.420724,0.021433,5.138139,-1296.753174,0.514959,0.000000
31.790001,0.068889,-1296.753174,0.021368,0.020544,0.521818,0.306433,0.015610,5.218184,-1296.753174,0.522954,0.000000
32.270000,0.128841,-1296.797607,0.021773,0.020857,0.529779,0.573113,0.029196,5.297795,-1296.797607,0.530950,0.000000
32.750000,0.106126,-1296.708740,0.022174,0.021173,0.537793,0.472073,0.024049,5.377927,-1296.708740,0.538946,0.000000
33.230003,0.090114,-1296.708740,0.022437,0.021486,0.545745,0.400848,0.020420,5.457451,-1296.708740,0.546942,0.000000
33.710003,0.121021,-1296.664185,0.022834,0.021805,0.553854,0.538328,0.027424,5.538537,-1296.664185,0.554938,0.000000
34.190002,0.075964,-1296.797607,0.023256,0.022120,0.561841,0.337905,0.017214,5.618408,-1296.797607,0.562933,0.000000
34.670002,0.129213,-1296.753174,0.023588,0.022432,0.569785,0.574769,0.029280,5.697845,-1296.753174,0.570929,0.000000
35.150002,0.100168,-1296.753174,0.023825,0.022746,0.577746,0.445570,0.022698,5.777457,-1296.753174,0.578925,0.000000
35.630001,0.093466,-1296.753174,0.024149,0.023070,0.585976,0.415755,0.021180,5.859757,-1296.753174,0.586921,0.000000
36.110001,0.013778,-1296.753174,0.024515,0.023374,0.593711,0.061287,0.003122,5.937113,-1296.753174,0.594917,0.000000
36.590000,0.144853,-1296.797607,0.024899,0.023694,0.601829,0.644338,0.032824,6.018286,-1296.797607,0.602913,0.000000
37.070004,0.043940,-1296.708740,0.025244,0.024005,0.609720,0.195455,0.009957,6.097203,-1296.708740,0.610909,0.000000
37.550003,0.102775,-1296.708740,0.025507,0.024316,0.617621,0.457165,0.023289,6.176208,-1296.708740,0.618904,0.000000
38.030003,0.008192,-1296.753174,0.025968,0.024632,0.625651,0.036441,0.001856,6.256513,-1296.753174,0.626900,0.000000
38.510002,0.114691,-1296.708740,0.026231,0.024948,0.633682,0.510170,0.025989,6.336819,-1296.708740,0.634896,0.000000
38.990002,0.059952,-1296.797607,0.026555,0.025264,0.641695,0.266680,0.013585,6.416949,-1296.797607,0.642892,0.000000
39.470001,0.126979,-1296.797607,0.026839,0.025570,0.649474,0.564831,0.028774,6.494740,-1296.797607,0.650888,0.000000
39.950001,-0.018991,-1296.797607,0.027257,0.025893,0.657678,-0.084476,-0.004303,6.576779,-1296.797607,0.658901,0.000000
40.430000,0.150438,-1296.797607,0.027594,0.026208,0.665674,0.669184,0.034090,6.656737,-1296.797607,0.666897,0.000000
40.910004,0.068889,-1296.797607,0.027831,0.026525,0.673730,0.306433,0.015610,6.737302,-1296.797607,0.674892,0.000000
41.390003,0.136661,-1296.842163,0.028253,0.026833,0.681561,0.607897,0.030968,6.815614,-1296.842163,0.682888,0.000000
41.870003,-0.016012,-1296.842163,0.028465,0.027155,0.689739,-0.071225,-0.003628,6.897392,-1296.842163,0.690884,0.000000
42.350002,0.139640,-1296.797607,0.029137,0.027469,0.697700,0.621148,0.031643,6.977004,-1296.797607,0.698880,0.000000
42.830002,0.101658,-1296.797607,0.029245,0.027785,0.705748,0.452196,0.023036,7.057482,-1296.797607,0.706876,0.000000
43.310001,0.126234,-1296.797607,0.029698,0.028099,0.713718,0.561518,0.028605,7.137180,-1296.797607,0.714871,0.000000
43.790001,0.105754,-1296.842163,0.029836,0.028411,0.721627,0.470416,0.023964,7.216271,-1296.842163,0.722867,0.000000
44.270000,0.121393,-1296.842163,0.030314,0.028732,0.729796,0.539985,0.027508,7.297965,-1296.842163,0.730863,0.000000
44.750004,0.153790,-1296.797607,0.030707,0.029051,0.737905,0.684091,0.034849,7.379050,-1296.797607,0.738859,0.000000
45.230003,0.217093,-1296.797607,0.030974,0.029356,0.745641,0.965678,0.049194,7.456406,-1296.797607,0.746855,0.000000
45.710003,0.445730,-1296.797607,0.031237,0.029672,0.753680,1.982705,0.101004,7.536799,-1296.797607,0.754851,0.000000
46.190002,0.632661,-1296.842163,0.031625,0.029987,0.761667,2.814216,0.143363,7.616670,-1296.842163,0.762846,0.000000
46.670002,1.027748,-1296.842163,0.031901,0.030300,0.769619,4.571651,0.232891,7.696194,-1296.842163,0.770842,0.000000
47.150002,1.041898,-1296.842163,0.031961,-0.000009,-0.000234,4.634594,0.236097,-0.002341,-1296.842163,0.000035,0.000000
47.630001,0.996841,-1296.797607,0.031888,-0.000009,-0.000234,4.434171,0.225887,-0.002341,-1296.797607,0.000538,0.000000
48.110001,1.024769,-1296.797607,0.032069,0.000011,0.000277,4.558400,0.232216,0.002774,-1296.797607,0.001336,0.000000
48.590004,1.085838,-1296.886597,0.031914,0.000053,0.001344,4.830049,0.246054,0.013442,-1296.886597,0.002133,0.000000
49.070004,0.967424,-1296.931030,0.032004,0.000079,0.002003,4.303315,0.219221,0.020033,-1296.931030,0.002931,0.000000
49.550003,1.092168,-1296.886597,0.032151,0.000111,0.002827,4.858208,0.247489,0.028271,-1296.886597,0.003738,0.000000
50.030003,1.134246,-1296.842163,0.031897,0.000137,0.003469,5.045380,0.257024,0.034689,-1296.842163,0.004536,0.000000
50.510002,1.180793,-1296.886597,0.032048,0.000177,0.004492,5.252430,0.267572,0.044923,-1296.886597,0.005333,0.000000
50.990002,1.107808,-1296.886597,0.032129,0.000202,0.005125,4.927777,0.251033,0.051253,-1296.886597,0.006131,0.000000
51.470001,1.251916,-1296.886597,0.032142,0.000234,0.005932,5.568801,0.283688,0.059319,-1296.886597,0.006938,0.000000
51.950001,1.276120,-1296.886597,0.032142,0.000256,0.006504,5.676467,0.289173,0.065042,-1296.886597,0.007736,0.000000
52.430004,1.343148,-1296.886597,0.032237,0.000304,0.007710,5.974618,0.304362,0.077096,-1296.886597,0.008533,0.000000
52.910004,1.264949,-1296.931030,0.032104,0.000327,0.008299,5.626775,0.286642,0.082993,-1296.931030,0.009331,0.000000
53.390003,1.393045,-1296.931030,0.032280,0.000359,0.009123,6.196576,0.315669,0.091231,-1296.931030,0.010138,0.000000
53.870003,1.442943,-1296.975586,0.032267,0.000389,0.009869,6.418532,0.326976,0.098689,-1296.975586,0.010936,0.000000
54.350002,1.461190,-1296.886597,0.032306,0.000424,0.010771,6.499696,0.331110,0.107709,-1296.886597,0.011734,0.000000
54.830002,1.417994,-1296.886597,0.032259,0.000452,0.011482,6.307553,0.321322,0.114820,-1296.886597,0.012531,0.000000
55.310001,1.492469,-1296.886597,0.032285,0.000486,0.012341,6.638833,0.338198,0.123406,-1296.886597,0.013338,0.000000
55.790001,1.588541,-1296.931030,0.032423,0.000515,0.013078,7.066183,0.359969,0.130778,-1296.931030,0.014136,0.000000
56.270004,1.625406,-1296.975586,0.032483,0.000553,0.014058,7.230166,0.368322,0.140577,-1296.975586,0.014934,0.000000
56.750004,1.570667,-1296.931030,0.032431,0.000579,0.014708,6.986676,0.355918,0.147081,-1296.931030,0.015732,0.000000
57.230003,1.649238,-1296.886597,0.032392,0.000605,0.015376,7.336175,0.373723,0.153759,-1296.886597,0.016538,0.000000
57.710003,1.744937,-1296.975586,0.032522,0.000638,0.016200,7.761869,0.395408,0.161997,-1296.975586,0.017336,0.000000
58.190002,1.791484,-1296.886597,0.032414,0.000680,0.017275,7.968918,0.405956,0.172752,-1296.886597,0.018134,0.000000
58.670002,1.715520,-1296.975586,0.032582,0.000706,0.017925,7.631014,0.388742,0.179255,-1296.975586,0.018931,0.000000
59.150002,1.859628,-1296.975586,0.032453,0.000732,0.018585,8.272038,0.421398,0.185846,-1296.975586,0.019738,0.000000
59.630001,1.899100,-1296.931030,0.032599,0.000759,0.019287,8.447617,0.430342,0.192871,-1296.931030,0.020536,0.000000
60.110004,1.927400,-1296.931030,0.032548,0.000793,0.020146,8.573503,0.436755,0.201457,-1296.931030,0.021334,0.000000
60.590004,1.901334,-1297.020020,0.032660,0.000827,0.021013,8.457555,0.430848,0.210128,-1297.020020,0.022132,0.000000
61.070004,1.994055,-1296.975586,0.032599,0.000860,0.021837,8.869998,0.451859,0.218368,-1296.975586,0.022938,0.000000
61.550003,2.084913,-1296.975586,0.032612,0.000888,0.022556,9.274158,0.472448,0.225565,-1296.975586,0.023736,0.000000
62.030003,2.159760,-1296.975586,0.032681,0.000931,0.023649,9.607094,0.489409,0.236492,-1296.975586,0.024534,0.000000
62.510002,2.053634,-1296.975586,0.032854,0.000957,0.024300,9.135021,0.465360,0.242996,-1296.975586,0.025332,0.000000
62.990002,2.143748,-1296.975586,0.032733,0.000985,0.025028,9.535869,0.485780,0.250282,-1296.975586,0.026138,0.000000
63.470001,2.272217,-1296.975586,0.032750,0.001016,0.025817,10.107326,0.514892,0.258173,-1296.975586,0.026936,0.000000
63.950005,2.370151,-1296.975586,0.032897,0.001059,0.026893,10.542957,0.537084,0.268926,-1296.975586,0.027734,0.000000
64.430000,2.265142,-1296.886597,0.032802,0.001083,0.027508,10.075853,0.513288,0.275084,-1296.886597,0.028532,0.000000
64.910004,2.361586,-1296.975586,0.032780,0.001114,0.028306,10.504860,0.535143,0.283063,-1296.975586,0.029338,0.000000
65.389999,2.547028,-1296.975586,0.032785,0.001143,0.029026,11.329744,0.577165,0.290260,-1296.975586,0.030136,0.000000
65.870003,2.630067,-1296.975586,0.032970,0.001183,0.030041,11.699121,0.595982,0.300407,-1296.975586,0.030934,0.000000
66.350006,2.548145,-1296.975586,0.032841,0.001208,0.030691,11.334714,0.577418,0.306911,-1296.975586,0.031732,0.000000
66.830002,2.599160,-1296.975586,0.032906,0.001236,0.031402,11.561640,0.588978,0.314021,-1296.975586,0.032538,0.000000
67.310005,2.782739,-1296.975586,0.032923,0.001269,0.032226,12.378243,0.630578,0.322261,-1296.975586,0.033336,0.000000
67.790001,2.853118,-1296.975586,0.032953,0.001303,0.033102,12.691301,0.646526,0.331019,-1296.975586,0.034134,0.000000
68.270004,2.876577,-1297.020020,0.033031,0.001333,0.033856,12.795655,0.651842,0.338565,-1297.020020,0.034932,0.000000
68.750000,2.861682,-1296.975586,0.033263,0.001363,0.034628,12.729399,0.648467,0.346284,-1296.975586,0.035738,0.000000
69.230003,3.015472,-1296.975586,0.033043,0.001398,0.035504,13.413490,0.683316,0.355042,-1296.975586,0.036536,0.000000
69.710007,3.129046,-1296.886597,0.033061,0.001435,0.036449,13.918692,0.709052,0.364495,-1296.886597,0.037334,0.000000
70.190002,3.050103,-1296.975586,0.033022,0.001460,0.037091,13.567535,0.691163,0.370912,-1296.975586,0.038141,0.000000
70.670006,3.118619,-1296.975586,0.033199,0.001491,0.037872,13.872313,0.706689,0.378717,-1296.975586,0.038938,0.000000
71.150002,3.266451,-1296.975586,0.033151,0.001522,0.038652,14.529902,0.740188,0.386523,-1296.975586,0.039736,0.000000
71.630005,3.411304,-1296.931030,0.033272,0.001561,0.039658,15.174239,0.773013,0.396581,-1296.931030,0.040534,0.000000
72.110001,3.444445,-1296.931030,0.033237,0.001584,0.040222,15.321658,0.780522,0.402219,-1296.931030,0.041341,0.000000
72.590004,3.414655,-1297.020020,0.033449,0.001613,0.040976,15.189146,0.773772,0.409764,-1297.020020,0.042139,0.000000
73.070000,3.615364,-1296.975586,0.033242,0.001647,0.041844,16.081944,0.819253,0.418435,-1296.975586,0.042936,0.000000
73.550003,3.719629,-1297.064575,0.033345,0.001685,0.042806,16.545734,0.842880,0.428062,-1297.064575,0.043734,0.000000
74.030006,3.758728,-1296.931030,0.033324,0.001712,0.043483,16.719656,0.851740,0.434828,-1296.931030,0.044541,0.000000
74.510002,3.768409,-1296.931030,0.033397,0.001739,0.044177,16.762722,0.853934,0.441765,-1296.931030,0.045339,0.000000
74.990005,3.944914,-1296.975586,0.033401,0.001775,0.045078,17.547853,0.893930,0.450783,-1296.975586,0.046136,0.000000
75.470001,4.010451,-1297.020020,0.033393,0.001809,0.045946,17.839378,0.908781,0.459456,-1297.020020,0.046934,0.000000
75.950005,4.075616,-1296.975586,0.033410,0.001834,0.046596,18.129248,0.923548,0.465960,-1296.975586,0.047741,0.000000
76.430000,4.083436,-1296.975586,0.033419,0.001869,0.047463,18.164032,0.925320,0.474632,-1296.975586,0.048539,0.000000
76.910004,4.250632,-1296.975586,0.033419,0.001903,0.048339,18.907755,0.963207,0.483392,-1296.975586,0.049336,0.000000
77.390007,4.329947,-1296.975586,0.033548,0.001934,0.049111,19.260567,0.981180,0.491109,-1296.975586,0.050134,0.000000
77.870003,4.382824,-1297.109009,0.033574,0.001963,0.049848,19.495775,0.993162,0.498482,-1297.109009,0.050941,0.000000
78.350006,4.407028,-1297.020020,0.033600,0.001996,0.050698,19.603441,0.998647,0.506979,-1297.020020,0.051739,0.000000
78.830002,4.581671,-1296.975586,0.033626,0.002026,0.051470,20.380289,1.038221,0.514698,-1296.975586,0.052536,0.000000
79.310005,4.638644,-1297.020020,0.033591,0.002055,0.052207,20.633718,1.051132,0.522070,-1297.020020,0.053334,0.000000
79.790001,4.748121,-1297.064575,0.033695,0.002092,0.053144,21.120699,1.075940,0.531435,-1297.064575,0.054141,0.000000
80.270004,4.705298,-1297.064575,0.033703,0.002118,0.053794,20.930212,1.066236,0.537940,-1297.064575,0.054939,0.000000
80.750008,4.905262,-1297.020020,0.033820,0.002151,0.054635,21.819696,1.111548,0.546351,-1297.020020,0.055737,0.000000
81.230003,4.959629,-1297.064575,0.033738,0.002172,0.055173,22.061529,1.123868,0.551728,-1297.064575,0.056534,0.000000
81.710007,5.086607,-1297.020020,0.033703,0.002213,0.056222,22.626360,1.152642,0.562222,-1297.020020,0.057341,0.000000
82.190002,5.055701,-1297.064575,0.033940,0.002242,0.056951,22.488880,1.145638,0.569507,-1297.064575,0.058139,0.000000
82.670006,5.263857,-1297.020020,0.033820,0.002278,0.057861,23.414804,1.192807,0.578612,-1297.020020,0.058937,0.000000
83.150002,5.306680,-1297.064575,0.033975,0.002302,0.058460,23.605289,1.202511,0.584596,-1297.064575,0.059735,0.000000
83.630005,5.444085,-1297.020020,0.033893,0.002345,0.059552,24.216499,1.233647,0.595523,-1297.020020,0.060541,0.000000
84.110001,5.353226,-1296.975586,0.033893,0.002371,0.060211,23.812340,1.213058,0.602114,-1296.975586,0.061339,0.000000
84.590004,5.601599,-1297.064575,0.033975,0.002406,0.061113,24.917156,1.269341,0.611134,-1297.064575,0.062137,0.000000
85.070007,5.674212,-1297.020020,0.033863,0.002437,0.061903,25.240154,1.285795,0.619025,-1297.020020,0.062934,0.000000
85.550003,5.811989,-1297.109009,0.033940,0.002472,0.062787,25.853020,1.317016,0.627871,-1297.109009,0.063741,0.000000
86.030006,5.725971,-1296.975586,0.033932,0.002496,0.063394,25.470392,1.297524,0.633942,-1296.975586,0.064539,0.000000
86.510002,6.010836,-1297.064575,0.034186,0.002534,0.064366,26.737534,1.362075,0.643655,-1297.064575,0.065337,0.000000
86.990005,6.073767,-1296.975586,0.034070,0.002557,0.064947,27.017466,1.376335,0.649465,-1296.975586,0.066135,0.000000
87.470001,6.200374,-1297.109009,0.034100,0.002595,0.065909,27.580639,1.405025,0.659092,-1297.109009,0.066941,0.000000
87.950005,6.134836,-1297.109009,0.034108,0.002621,0.066577,27.289114,1.390174,0.665769,-1297.109009,0.067739,0.000000
88.430008,6.375016,-1297.020020,0.034113,0.002654,0.067418,28.357489,1.444599,0.674181,-1297.020020,0.068537,0.000000
88.910004,6.476674,-1297.064575,0.034203,0.002679,0.068051,28.809685,1.467635,0.680511,-1297.064575,0.069335,0.000000
89.390007,6.609611,-1297.109009,0.034298,0.002718,0.069040,29.401018,1.497759,0.690399,-1297.109009,0.070141,0.000000
89.870003,6.564554,-1297.109009,0.034285,0.002744,0.069708,29.200594,1.487549,0.697075,-1297.109009,0.070939,0.000000
90.350006,6.843089,-1297.109009,0.034268,0.002786,0.070766,30.439579,1.550666,0.707656,-1297.109009,0.071737,0.000000
90.830002,6.909743,-1297.064575,0.034341,0.002808,0.071321,30.736073,1.565770,0.713207,-1297.064575,0.072535,0.000000
91.310005,7.085503,-1297.064575,0.034371,0.002851,0.072405,31.517893,1.605598,0.724047,-1297.064575,0.073341,0.000000
91.790001,7.019966,-1297.064575,0.034346,0.002877,0.073064,31.226366,1.590747,0.730638,-1297.064575,0.074139,0.000000
92.270004,7.245251,-1297.153442,0.034376,0.002909,0.073888,32.228485,1.641797,0.738876,-1297.153442,0.074937,0.000000
92.750008,7.340950,-1297.109009,0.034488,0.002936,0.074564,32.654179,1.663483,0.745641,-1297.109009,0.075735,0.000000
93.230003,7.511869,-1297.109009,0.034432,0.002975,0.075561,33.414463,1.702214,0.755613,-1297.109009,0.076541,0.000000
93.710007,7.514848,-1297.109009,0.034583,0.003000,0.076203,33.427715,1.702889,0.762032,-1297.109009,0.077339,0.000000
94.190002,7.781467,-1297.109009,0.034540,0.003032,0.077001,34.613693,1.763306,0.770010,-1297.109009,0.078137,0.000000
94.670006,7.879401,-1297.153442,0.034544,0.003062,0.077773,35.049328,1.785498,0.777728,-1297.153442,0.078935,0.000000
95.150002,8.099846,-1297.109009,0.034596,0.003104,0.078831,36.029915,1.835451,0.788308,-1297.109009,0.079741,0.000000
95.630005,8.093888,-1297.109009,0.034531,0.003127,0.079429,36.003414,1.834101,0.794292,-1297.109009,0.080539,0.000000
96.110008,8.330717,-1297.153442,0.034669,0.003158,0.080218,37.056881,1.887767,0.802184,-1297.153442,0.081337,0.000000
96.590004,8.476315,-1297.109009,0.034742,0.003189,0.081008,37.704529,1.920760,0.810075,-1297.109009,0.082144,0.000000
97.070007,8.657288,-1297.153442,0.034781,0.003227,0.081970,38.509537,1.961769,0.819702,-1297.153442,0.082941,0.000000
97.550003,8.691545,-1297.109009,0.034803,0.003254,0.082647,38.661926,1.969532,0.826466,-1297.109009,0.083739,0.000000
98.030006,8.947366,-1297.064575,0.034742,0.003288,0.083505,39.799870,2.027502,0.835052,-1297.064575,0.084537,0.000000
98.510002,9.115678,-1297.064575,0.034803,0.003314,0.084173,40.548561,2.065642,0.841728,-1297.064575,0.085344,0.000000
98.990005,9.311546,-1297.109009,0.035001,0.003352,0.085153,41.419827,2.110027,0.851529,-1297.109009,0.086142,0.000000
99.470001,9.356976,-1297.153442,0.034764,0.003380,0.085855,41.621906,2.120321,0.858552,-1297.153442,0.086939,0.000000
99.950005,9.536087,-1297.197998,0.034876,0.003407,0.086540,42.418633,2.160908,0.865405,-1297.197998,0.087737,0.000000
100.430008,9.777757,-1297.153442,0.034876,0.003437,0.087295,43.493633,2.215672,0.872950,-1297.153442,0.088544,0.000000
100.910004,10.039907,-1297.109009,0.034893,0.003480,0.088396,44.659733,2.275075,0.883962,-1297.109009,0.089341,0.000000
101.390007,10.055546,-1297.153442,0.034979,0.003505,0.089029,44.729301,2.278619,0.890294,-1297.153442,0.090139,0.000000
101.870003,10.277853,-1297.153442,0.035074,0.003532,0.089706,45.718174,2.328995,0.897058,-1297.153442,0.090937,0.000000
102.350006,10.489733,-1297.153442,0.035083,0.003559,0.090400,46.660660,2.377007,0.903996,-1297.153442,0.091744,0.000000
102.830002,10.766778,-1297.109009,0.034971,0.003603,0.091527,47.893021,2.439787,0.915269,-1297.109009,0.092542,0.000000
103.310005,10.811090,-1297.109009,0.035001,0.003628,0.092143,48.090130,2.449828,0.921427,-1297.109009,0.093339,0.000000
103.790009,11.151811,-1297.153442,0.035117,0.003661,0.092993,49.605732,2.527036,0.929926,-1297.153442,0.094137,0.000000
104.270004,11.307463,-1297.197998,0.035083,0.003687,0.093643,50.298107,2.562308,0.936430,-1297.197998,0.094944,0.000000
104.750008,11.669409,-1297.153442,0.035135,0.003732,0.094788,51.908123,2.644326,0.947878,-1297.153442,0.095742,0.000000
105.230003,11.678346,-1297.197998,0.035238,0.003757,0.095430,51.947876,2.646351,0.954295,-1297.197998,0.096540,0.000000
105.710007,12.010129,-1297.153442,0.035156,0.003787,0.096193,53.423721,2.721534,0.961927,-1297.153442,0.097337,0.000000
106.190002,12.295739,-1297.153442,0.035238,0.003820,0.097025,54.694180,2.786254,0.970252,-1297.153442,0.098144,0.000000
106.670006,12.656940,-1297.197998,0.035298,0.003862,0.098083,56.300884,2.868104,0.980833,-1297.197998,0.098942,0.000000
107.150002,12.702742,-1297.242432,0.035363,0.003885,0.098690,56.504616,2.878483,0.986902,-1297.242432,0.099740,0.000000
107.630005,13.062081,-1297.153442,0.035363,0.003920,0.099557,58.103039,2.959910,0.995575,-1297.153442,0.100537,0.000000
108.110008,13.459030,-1297.153442,0.035367,0.003948,0.100269,59.868755,3.049860,1.002687,-1297.153442,0.101344,0.000000
108.590004,13.893217,-1297.153442,0.035462,0.003985,0.101231,61.800117,3.148248,1.012312,-1297.153442,0.102142,0.000000
109.070007,14.021313,-1297.242432,0.035376,0.004009,0.101830,62.369915,3.177275,1.018296,-1297.242432,0.102940,0.000000
109.550003,14.367991,-1297.242432,0.035484,0.004037,0.102549,63.912018,3.255834,1.025495,-1297.242432,0.103738,0.000000
110.030006,14.861385,-1297.153442,0.035531,0.004066,0.103287,66.106743,3.367638,1.032866,-1297.153442,0.104544,0.000000
110.510002,15.510430,-1297.242432,0.035583,0.004103,0.104214,68.993843,3.514714,1.042144,-1297.242432,0.105342,0.000000
110.990005,16.027655,-1297.286987,0.035635,0.004134,0.105004,71.294571,3.631919,1.050036,-1297.286987,0.106140,0.000000
111.470009,16.920605,-1297.242432,0.035566,0.004172,0.105958,75.266609,3.834264,1.059576,-1297.242432,0.106938,0.000000
111.950005,17.686203,-1297.197998,0.035949,0.004196,0.106573,78.672157,4.007751,1.065734,-1297.197998,0.107744,0.000000
112.430008,18.922480,-1297.109009,0.035561,0.004237,0.107623,84.171394,4.287895,1.076227,-1297.109009,0.108542,0.000000
112.910004,19.501518,-1297.153442,0.035613,0.004262,0.108264,86.747086,4.419107,1.082645,-1297.153442,0.109340,0.000000
113.390007,20.676353,-1297.197998,0.035695,0.004295,0.109088,91.973015,4.685329,1.090882,-1297.197998,0.110138,0.000000
113.870003,21.786396,-1297.286987,0.035760,0.004323,0.109808,96.910728,4.936868,1.098081,-1297.286987,0.110944,0.000000
114.350006,23.431166,-1297.286987,0.035747,0.004365,0.110875,104.227028,5.309578,1.108747,-1297.286987,0.111742,0.000000
114.830002,24.002756,-1297.197998,0.035773,0.004386,0.111413,106.769592,5.439102,1.114125,-1297.197998,0.112540,0.000000
115.310005,25.334734,-1297.197998,0.035842,0.004417,0.112193,112.694527,5.740933,1.121930,-1297.197998,0.113338,0.000000
115.790009,26.649952,-1297.197998,0.035889,0.004448,0.112982,118.544907,6.038965,1.129821,-1297.197998,0.114144,0.000000
116.270004,28.416487,-1297.242432,0.035958,0.004491,0.114066,126.402847,6.439268,1.140661,-1297.242432,0.114942,0.000000
116.750008,29.212620,-1297.242432,0.035837,0.004513,0.114621,129.944229,6.619674,1.146212,-1297.242432,0.115740,0.000000
117.230003,30.473473,-1297.242432,0.035902,0.004544,0.115428,135.552780,6.905388,1.154278,-1297.242432,0.116538,0.000000
117.710007,31.877689,-1297.153442,0.035889,0.004572,0.116139,141.799042,7.223588,1.161389,-1297.153442,0.117344,0.000000
118.190002,33.370529,-1297.153442,0.036057,0.004609,0.117076,148.439529,7.561870,1.170755,-1297.153442,0.118142,0.000000
118.670006,34.648884,-1297.242432,0.035984,0.004642,0.117917,154.125931,7.851550,1.179167,-1297.242432,0.118940,0.000000
119.150009,35.804729,-1297.331421,0.036238,0.004667,0.118550,159.267395,8.113468,1.185497,-1297.331421,0.119738,0.000000
119.630005,37.512428,-1297.242432,0.036178,0.004704,0.119469,166.863617,8.500438,1.194691,-1297.242432,0.120544,0.000000
120.110008,38.816105,-1297.197998,0.036014,0.004734,0.120241,172.662659,8.795856,1.202408,-1297.197998,0.121342,0.000000
120.590004,40.106003,-1297.197998,0.036074,0.004763,0.120969,178.400406,9.088150,1.209692,-1297.197998,0.122140,0.000000
121.070007,41.460693,-1297.197998,0.036204,0.004794,0.121767,184.426376,9.395127,1.217671,-1297.197998,0.122938,0.000000
121.550003,42.903637,-1297.286987,0.036290,0.004825,0.122565,190.844910,9.722103,1.225649,-1297.286987,0.123744,0.000000
122.030006,44.634426,-1297.286987,0.036200,0.004863,0.123510,198.543839,10.114305,1.235102,-1297.286987,0.124542,0.000000
122.510002,44.800133,-1297.242432,0.036156,0.004862,0.123502,199.280945,10.151855,1.235015,-1297.242432,0.123727,0.000000
122.990005,44.597187,-1297.242432,0.036208,0.004848,0.123137,198.378189,10.105867,1.231374,-1297.242432,0.122938,0.000000
123.470009,44.478401,-1297.242432,0.036277,0.004818,0.122383,197.849808,10.078950,1.223829,-1297.242432,0.122140,0.000000
123.950005,44.343601,-1297.286987,0.036273,0.004792,0.121707,197.250183,10.048404,1.217065,-1297.286987,0.121342,0.000000
124.430008,44.202847,-1297.197998,0.036294,0.004762,0.120961,196.624084,10.016508,1.209607,-1297.197998,0.120536,0.000000
124.910004,44.032673,-1297.286987,0.036187,0.004733,0.120206,195.867111,9.977946,1.202062,-1297.286987,0.119738,0.000000
125.390007,44.021873,-1297.242432,0.036230,0.004697,0.119313,195.819077,9.975499,1.193129,-1297.242432,0.118940,0.000000
125.870003,43.926544,-1297.286987,0.036484,0.004664,0.118472,195.395035,9.953897,1.184718,-1297.286987,0.118142,0.000000
126.350006,43.874786,-1297.286987,0.036187,0.004635,0.117726,195.164795,9.942169,1.177259,-1297.286987,0.117336,0.000000
126.830009,43.649128,-1297.242432,0.036463,0.004608,0.117032,194.161011,9.891034,1.170322,-1297.242432,0.116538,0.000000
127.310005,43.647266,-1297.286987,0.036350,0.004574,0.116174,194.152740,9.890612,1.161736,-1297.286987,0.115740,0.000000
127.790009,43.557152,-1297.242432,0.036187,0.004548,0.115532,193.751892,9.870192,1.155318,-1297.242432,0.114942,0.000000
128.270004,43.457355,-1297.197998,0.036217,0.004518,0.114760,193.307968,9.847577,1.147599,-1297.197998,0.114136,0.000000
128.750000,43.119987,-1297.242432,0.036152,0.004491,0.114084,191.807281,9.771129,1.140836,-1297.242432,0.113338,0.000000
129.230011,42.407265,-1297.375854,0.036208,0.004454,0.113130,188.636932,9.609623,1.131296,-1297.375854,0.112540,0.000000
129.710007,41.743324,-1297.242432,0.036178,0.004432,0.112583,185.683578,9.459173,1.125832,-1297.242432,0.111742,0.000000
130.190002,40.631050,-1297.286987,0.036174,0.004401,0.111794,180.735931,9.207127,1.117941,-1297.286987,0.110935,0.000000
130.670013,39.514675,-1297.286987,0.036264,0.004375,0.111126,175.770050,8.954154,1.111262,-1297.286987,0.110138,0.000000
131.150009,38.322338,-1297.286987,0.036277,0.004349,0.110459,170.466278,8.683967,1.104586,-1297.286987,0.109340,0.000000
131.630005,36.868225,-1297.286987,0.036359,0.004314,0.109583,163.998062,8.354459,1.095826,-1297.286987,0.108542,0.000000
132.110001,35.432358,-1297.286987,0.036342,0.004280,0.108715,157.610992,8.029087,1.087154,-1297.286987,0.107736,0.000000
132.590012,33.626724,-1297.197998,0.036234,0.004249,0.107918,149.579147,7.619925,1.079176,-1297.197998,0.106938,0.000000
133.070007,32.091057,-1297.286987,0.036204,0.004222,0.107241,142.748154,7.271937,1.072410,-1297.286987,0.106140,0.000000
133.550003,30.506615,-1297.242432,0.036277,0.004187,0.106348,135.700195,6.912898,1.063478,-1297.242432,0.105342,0.000000
134.029999,29.410723,-1297.286987,0.036208,0.004161,0.105689,130.825424,6.664565,1.056888,-1297.286987,0.104535,0.000000
134.510010,27.483694,-1297.286987,0.036251,0.004123,0.104735,122.253578,6.227894,1.047349,-1297.286987,0.103738,0.000000
134.990005,26.256727,-1297.286987,0.036273,0.004098,0.104093,116.795753,5.949860,1.040931,-1297.286987,0.102940,0.000000
135.470001,24.620895,-1297.286987,0.036238,0.004059,0.103096,109.519211,5.579175,1.030958,-1297.286987,0.102142,0.000000
135.950012,23.697039,-1297.286987,0.036273,0.004038,0.102558,105.409691,5.369825,1.025582,-1297.286987,0.101335,0.000000
136.430008,21.968859,-1297.331421,0.036165,0.004000,0.101604,97.722366,4.978215,1.016042,-1297.331421,0.100537,0.000000
136.910004,20.591825,-1297.286987,0.036156,0.003967,0.100772,91.597015,4.666174,1.007717,-1297.286987,0.099740,0.000000
137.389999,19.205482,-1297.286987,0.036273,0.003929,0.099800,85.430252,4.352025,0.998003,-1297.286987,0.098942,0.000000
137.870010,18.472654,-1297.331421,0.036204,0.003906,0.099211,82.170471,4.185963,0.992106,-1297.331421,0.098135,0.000000
138.350006,17.034178,-1297.242432,0.036406,0.003870,0.098300,75.771805,3.860000,0.983000,-1297.242432,0.097337,0.000000
138.830002,16.122982,-1297.286987,0.036230,0.003844,0.097641,71.718605,3.653520,0.976408,-1297.286987,0.096540,0.000000
139.310013,14.913890,-1297.375854,0.036346,0.003802,0.096583,66.340294,3.379536,0.965829,-1297.375854,0.095742,0.000000
139.790009,14.399271,-1297.286987,0.036480,0.003780,0.096019,64.051155,3.262922,0.960192,-1297.286987,0.094935,0.000000
140.270004,13.426634,-1297.286987,0.036200,0.003741,0.095022,59.724651,3.042519,0.950219,-1297.286987,0.094137,0.000000
140.750000,12.798442,-1297.331421,0.036131,0.003715,0.094371,56.930313,2.900168,0.943714,-1297.331421,0.093339,0.000000
141.230011,12.359787,-1297.375854,0.036286,0.003681,0.093487,54.979080,2.800768,0.934869,-1297.375854,0.092542,0.000000
141.710007,11.990021,-1297.375854,0.036169,0.003652,0.092767,53.334274,2.716978,0.927670,-1297.375854,0.091735,0.000000
142.190002,11.499979,-1297.331421,0.036143,0.003615,0.091813,51.154461,2.605932,0.918132,-1297.331421,0.090937,0.000000
142.670013,11.120904,-1297.286987,0.036286,0.003591,0.091206,49.468250,2.520033,0.912061,-1297.286987,0.090139,0.000000
143.150009,10.884820,-1297.242432,0.036156,0.003554,0.090270,48.418098,2.466535,0.902696,-1297.242432,0.089333,0.000000
143.630005,10.501649,-1297.286987,0.036230,0.003517,0.089333,46.713669,2.379708,0.893330,-1297.286987,0.088535,0.000000
144.110001,10.229445,-1297.331421,0.036230,0.003488,0.088587,45.502842,2.318025,0.885872,-1297.331421,0.087737,0.000000
144.590012,9.919630,-1297.375854,0.036169,0.003466,0.088041,44.124718,2.247820,0.880408,-1297.375854,0.086939,0.000000
145.070007,9.679078,-1297.375854,0.036225,0.003427,0.087035,43.054691,2.193310,0.870348,-1297.375854,0.086133,0.000000
145.550003,9.453048,-1297.331421,0.036105,0.003397,0.086280,42.049255,2.142091,0.862803,-1297.331421,0.085335,0.000000
146.030014,9.177864,-1297.286987,0.036092,0.003364,0.085448,40.825180,2.079734,0.854478,-1297.286987,0.084537,0.000000
146.510010,8.844591,-1297.286987,0.036031,0.003338,0.084797,39.342705,2.004213,0.847974,-1297.286987,0.083739,0.000000
146.990005,8.667714,-1297.331421,0.035997,0.003299,0.083791,38.555920,1.964132,0.837913,-1297.331421,0.082933,0.000000
147.470001,8.407798,-1297.420410,0.035967,0.003263,0.082872,37.399754,1.905234,0.828720,-1297.420410,0.082135,0.000000
147.950012,8.251774,-1297.331421,0.036113,0.003235,0.082178,36.705723,1.869879,0.821782,-1297.331421,0.081337,0.000000
148.430008,7.873443,-1297.331421,0.035962,0.003206,0.081441,35.022823,1.784148,0.814411,-1297.331421,0.080539,0.000000
148.910004,7.770669,-1297.331421,0.035975,0.003171,0.080548,34.565659,1.760859,0.805479,-1297.331421,0.079733,0.000000
149.390015,7.635497,-1297.331421,0.036083,0.003145,0.079871,33.964386,1.730228,0.798715,-1297.331421,0.078935,0.000000
149.870010,7.429203,-1297.242432,0.035872,0.003113,0.079074,33.046745,1.683482,0.790736,-1297.242432,0.078137,0.000000
150.350006,7.128698,-1297.420410,0.036079,0.003085,0.078354,31.710033,1.615386,0.783538,-1297.420410,0.077339,0.000000
150.830002,7.052362,-1297.375854,0.035949,0.003045,0.077331,31.370472,1.598088,0.773305,-1297.375854,0.076533,0.000000
151.310013,6.948098,-1297.375854,0.035816,0.003022,0.076767,30.906683,1.574461,0.767668,-1297.375854,0.075735,0.000000
151.790009,6.748134,-1297.375854,0.035872,0.002986,0.075839,30.017199,1.529149,0.758389,-1297.375854,0.074937,0.000000
152.270004,6.481143,-1297.286987,0.035734,0.002961,0.075206,28.829561,1.468648,0.752059,-1297.286987,0.074139,0.000000
152.750000,6.402572,-1297.375854,0.035954,0.002920,0.074165,28.480062,1.450844,0.741652,-1297.375854,0.073333,0.000000
153.230011,6.297191,-1297.331421,0.035747,0.002895,0.073541,28.011303,1.426964,0.735407,-1297.331421,0.072535,0.000000
153.710007,6.125899,-1297.375854,0.035669,0.002860,0.072656,27.249361,1.388149,0.726562,-1297.375854,0.071737,0.000000
154.190002,5.829863,-1297.331421,0.035794,0.002831,0.071919,25.932526,1.321066,0.719191,-1297.331421,0.070939,0.000000
154.670013,5.791509,-1297.420410,0.035471,0.002793,0.070939,25.761917,1.312375,0.709390,-1297.420410,0.070133,0.000000
155.150009,5.733046,-1297.420410,0.035600,0.002772,0.070401,25.501862,1.299127,0.704013,-1297.420410,0.069335,0.000000
155.630005,5.532710,-1297.331421,0.035458,0.002731,0.069378,24.610723,1.253730,0.693781,-1297.331421,0.068537,0.000000
156.110001,5.297370,-1297.375854,0.035570,0.002706,0.068745,23.563881,1.200401,0.687450,-1297.375854,0.067739,0.000000
156.590012,5.247845,-1297.420410,0.035523,0.002668,0.067765,23.343578,1.189179,0.677649,-1297.420410,0.066932,0.000000
157.070007,5.169647,-1297.331421,0.035428,0.002644,0.067158,22.995737,1.171459,0.671579,-1297.331421,0.066135,0.000000
157.550003,4.958512,-1297.375854,0.035406,0.002604,0.066143,22.056562,1.123615,0.661433,-1297.375854,0.065337,0.000000
158.030014,4.768602,-1297.331421,0.035385,0.002578,0.065493,21.211802,1.080581,0.654929,-1297.331421,0.064539,0.000000
158.510010,4.705298,-1297.420410,0.035242,0.002539,0.064496,20.930212,1.066236,0.644956,-1297.420410,0.063732,0.000000
158.990005,4.660241,-1297.420410,0.035294,0.002518,0.063958,20.729788,1.056026,0.639579,-1297.420410,0.062934,0.000000
159.470001,4.492674,-1297.420410,0.035091,0.002479,0.062978,19.984411,1.018054,0.629780,-1297.420410,0.062137,0.000000
159.950012,4.265154,-1297.375854,0.035212,0.002453,0.062319,18.972353,0.966498,0.623189,-1297.375854,0.061339,0.000000
160.430008,4.197382,-1297.331421,0.035156,0.002413,0.061295,18.670889,0.951140,0.612954,-1297.331421,0.060532,0.000000
160.910004,4.144506,-1297.331421,0.035100,0.002394,0.060801,18.435680,0.939158,0.608011,-1297.331421,0.059735,0.000000
161.390015,3.957947,-1297.420410,0.035087,0.002352,0.059735,17.605827,0.896884,0.597345,-1297.420410,0.058937,0.000000
161.870010,3.733406,-1297.464844,0.035044,0.002328,0.059127,16.607021,0.846002,0.591274,-1297.464844,0.058139,0.000000
162.350006,3.721118,-1297.420410,0.035130,0.002289,0.058148,16.552359,0.843217,0.581475,-1297.420410,0.057332,0.000000
162.830002,3.649995,-1297.331421,0.034979,0.002263,0.057488,16.235989,0.827101,0.574884,-1297.331421,0.056534,0.000000
163.310013,3.501046,-1297.375854,0.035057,0.002229,0.056613,15.573430,0.793348,0.566126,-1297.375854,0.055737,0.000000
163.790009,3.303316,-1297.331421,0.034936,0.002206,0.056023,14.693884,0.748542,0.560227,-1297.331421,0.054939,0.000000
164.270004,3.307785,-1297.375854,0.034859,0.002164,0.054965,14.713760,0.749555,0.549648,-1297.375854,0.054132,0.000000
164.750015,3.230704,-1297.331421,0.034811,0.002136,0.054262,14.370888,0.732088,0.542623,-1297.331421,0.053334,0.000000
165.230011,3.083989,-1297.375854,0.034859,0.002101,0.053369,13.718266,0.698842,0.533691,-1297.375854,0.052536,0.000000
165.710007,2.873971,-1297.331421,0.034652,0.002078,0.052779,12.784060,0.651251,0.527794,-1297.331421,0.051739,0.000000
166.190002,2.898175,-1297.286987,0.034893,0.002044,0.051921,12.891726,0.656736,0.519208,-1297.286987,0.050932,0.000000
166.670013,2.846415,-1297.331421,0.034703,0.002013,0.051140,12.661487,0.645007,0.511404,-1297.331421,0.050134,0.000000
167.150009,2.702679,-1297.331421,0.034647,0.001977,0.050204,12.022119,0.612436,0.502036,-1297.331421,0.049336,0.000000
167.630005,2.483352,-1297.286987,0.034647,0.001952,0.049579,11.046501,0.562736,0.495793,-1297.286987,0.048539,0.000000
168.110001,2.519472,-1297.331421,0.034583,0.001917,0.048686,11.207171,0.570921,0.486861,-1297.331421,0.047732,0.000000
168.590012,2.446859,-1297.331421,0.034820,0.001884,0.047854,10.884174,0.554466,0.478536,-1297.331421,0.046934,0.000000
169.070007,2.340361,-1297.375854,0.034557,0.001848,0.046952,10.410445,0.530333,0.469516,-1297.375854,0.046136,0.000000
169.550003,2.103904,-1297.375854,0.034768,0.001826,0.046379,9.358635,0.476752,0.463792,-1297.375854,0.045330,0.000000
170.030014,2.138535,-1297.286987,0.034570,0.001786,0.045356,9.512679,0.484599,0.453559,-1297.286987,0.044532,0.000000
170.510010,2.085658,-1297.331421,0.034427,0.001759,0.044679,9.277471,0.472617,0.446794,-1297.331421,0.043734,0.000000
170.990005,1.988841,-1297.375854,0.034397,0.001725,0.043821,8.846807,0.450678,0.438209,-1297.375854,0.042936,0.000000
171.470001,1.779940,-1297.375854,0.034341,0.001696,0.043084,7.917570,0.403340,0.430838,-1297.375854,0.042130,0.000000
171.950012,1.798931,-1297.331421,0.034427,0.001657,0.042087,8.002047,0.407644,0.420865,-1297.331421,0.041332,0.000000
172.430008,1.793718,-1297.331421,0.034246,0.001635,0.041523,7.978857,0.406462,0.415228,-1297.331421,0.040534,0.000000
172.910004,1.708445,-1297.331421,0.034333,0.001604,0.040734,7.599542,0.387139,0.407336,-1297.331421,0.039736,0.000000
173.390015,1.534547,-1297.375854,0.034298,0.001574,0.039988,6.826005,0.347733,0.399878,-1297.375854,0.038930,0.000000
173.870010,1.559496,-1297.375854,0.034333,0.001534,0.038956,6.936985,0.353387,0.389558,-1297.375854,0.038132,0.000000
174.350006,1.519280,-1297.375854,0.034190,0.001512,0.038401,6.758094,0.344274,0.384008,-1297.375854,0.037334,0.000000
174.830002,1.463051,-1297.331421,0.034173,0.001478,0.037533,6.507977,0.331532,0.375335,-1297.331421,0.036536,0.000000
175.310013,1.417250,-1297.375854,0.034134,0.001450,0.036840,6.304241,0.321153,0.368397,-1297.375854,0.035730,0.000000
175.790009,1.301814,-1297.375854,0.034057,0.001406,0.035721,5.790758,0.294995,0.357211,-1297.375854,0.034932,0.000000
176.270004,1.275376,-1297.420410,0.034026,0.001384,0.035149,5.673154,0.289004,0.351486,-1297.420410,0.034134,0.000000
176.750015,1.248565,-1297.331421,0.033992,0.001354,0.034403,5.553894,0.282929,0.344028,-1297.331421,0.033336,0.000000
177.230011,1.071688,-1297.286987,0.033983,0.001320,0.033527,4.767106,0.242848,0.335270,-1297.286987,0.032530,0.000000
177.710007,1.012108,-1297.286987,0.033945,0.001293,0.032842,4.502083,0.229347,0.328417,-1297.286987,0.031732,0.000000
178.190002,1.080997,-1297.375854,0.033845,0.001257,0.031931,4.808516,0.244957,0.319313,-1297.375854,0.030934,0.000000
178.670013,1.037430,-1297.375854,0.033871,0.001226,0.031151,4.614718,0.235085,0.311508,-1297.375854,0.030136,0.000000
179.150009,0.885502,-1297.331421,0.033824,0.001193,0.030292,3.938908,0.200658,0.302922,-1297.331421,0.029330,0.000000
179.630005,0.859436,-1297.420410,0.033889,0.001164,0.029564,3.822961,0.194751,0.295636,-1297.420410,0.028532,0.000000
180.110016,0.941358,-1297.375854,0.033772,0.001128,0.028653,4.187367,0.213315,0.286532,-1297.375854,0.027734,0.000000
180.590012,0.900397,-1297.375854,0.033755,0.001095,0.027820,4.005164,0.204033,0.278205,-1297.375854,0.026936,0.000000
181.070007,0.746979,-1297.420410,0.033703,0.001068,0.027118,3.322729,0.169268,0.271182,-1297.420410,0.026129,0.000000
181.550003,0.727988,-1297.375854,0.033828,0.001039,0.026390,3.238253,0.164964,0.263896,-1297.375854,0.025332,0.000000
182.030014,0.781610,-1297.420410,0.033940,0.001001,0.025436,3.476774,0.177115,0.254356,-1297.420410,0.024534,0.000000
182.510010,0.748469,-1297.420410,0.033634,0.000977,0.024811,3.329355,0.169605,0.248113,-1297.420410,0.023736,0.000000
182.990005,0.701922,-1297.464844,0.033613,0.000942,0.023918,3.122305,0.159058,0.239181,-1297.464844,0.022929,0.000000
183.470001,0.607340,-1297.331421,0.033574,0.000906,0.023016,2.701581,0.137625,0.230161,-1297.331421,0.022132,0.000000
183.950012,0.631171,-1297.375854,0.033488,0.000879,0.022322,2.807590,0.143025,0.223224,-1297.375854,0.021334,0.000000
184.430008,0.597285,-1297.420410,0.033470,0.000847,0.021507,2.656858,0.135347,0.215071,-1297.420410,0.020536,0.000000
184.910004,0.558186,-1297.331421,0.033617,0.000816,0.020718,2.482937,0.126487,0.207179,-1297.331421,0.019729,0.000000
185.390015,0.411472,-1297.420410,0.033350,0.000785,0.019946,1.830317,0.093241,0.199462,-1297.420410,0.018931,0.000000
185.870010,0.542174,-1297.420410,0.033427,0.000753,0.019122,2.411712,0.122858,0.191222,-1297.420410,0.018134,0.000000
186.350006,0.502330,-1297.375854,0.033354,0.000716,0.018177,2.234477,0.113830,0.181770,-1297.375854,0.017336,0.000000
186.830002,0.486691,-1297.331421,0.033294,0.000688,0.017483,2.164909,0.110286,0.174832,-1297.331421,0.016529,0.000000
187.310013,0.344445,-1297.375854,0.033375,0.000660,0.016772,1.532166,0.078052,0.167722,-1297.375854,0.015732,0.000000
187.790009,0.456901,-1297.420410,0.033246,0.000624,0.015862,2.032397,0.103535,0.158615,-1297.420410,0.014934,0.000000
188.270004,0.471796,-1297.331421,0.033203,0.000593,0.015055,2.098653,0.106910,0.150550,-1297.331421,0.014136,0.000000
188.750015,0.436048,-1297.331421,0.033363,0.000564,0.014318,1.939639,0.098810,0.143179,-1297.331421,0.013329,0.000000
189.230011,0.297153,-1297.331421,0.033091,0.000537,0.013642,1.321804,0.067336,0.136415,-1297.331421,0.012531,0.000000
189.710007,0.412961,-1297.375854,0.033035,0.000499,0.012670,1.836943,0.093578,0.126701,-1297.375854,0.011734,0.000000
190.190002,0.388757,-1297.375854,0.033035,0.000464,0.011786,1.729277,0.088094,0.117856,-1297.375854,0.010936,0.000000
190.670013,0.377586,-1297.420410,0.033018,0.000437,0.011101,1.679585,0.085562,0.111005,-1297.420410,0.010129,0.000000
191.150009,0.162354,-1297.331421,0.033035,0.000407,0.010329,0.722188,0.036790,0.103286,-1297.331421,0.009331,0.000000
191.630005,0.300877,-1297.331421,0.033306,0.000371,0.009418,1.338367,0.068180,0.094181,-1297.331421,0.008533,0.000000
192.110016,0.288216,-1297.375854,0.032931,0.000338,0.008594,1.282050,0.065311,0.085942,-1297.375854,0.007736,0.000000
192.590012,0.269970,-1297.420410,0.032931,0.000312,0.007935,1.200886,0.061176,0.079350,-1297.420410,0.006929,0.000000
193.070007,0.107243,-1297.464844,0.032927,0.000283,0.007189,0.477042,0.024302,0.071892,-1297.464844,0.006131,0.000000
193.550003,0.248745,-1297.420410,0.032897,0.000243,0.006183,1.106472,0.056366,0.061834,-1297.420410,0.005333,0.000000
194.030014,0.259171,-1297.331421,0.032793,0.000224,0.005689,1.152851,0.058729,0.056889,-1297.331421,0.004536,0.000000
194.510010,0.236084,-1297.375854,0.032737,0.000188,0.004778,1.050155,0.053497,0.047784,-1297.375854,0.003729,0.000000
194.990005,0.076709,-1297.375854,0.032724,0.000159,0.004041,0.341217,0.017382,0.040413,-1297.375854,0.002931,0.000000
195.470016,0.191399,-1297.375854,0.032716,0.000121,0.003079,0.851387,0.043372,0.030786,-1297.375854,0.002133,0.000000
195.950012,0.217093,-1297.331421,0.032785,0.000097,0.002472,0.965678,0.049194,0.024715,-1297.331421,0.001327,0.000000
196.430008,0.188420,-1297.331421,0.032617,0.000063,0.001596,0.838136,0.042697,0.015957,-1297.331421,0.000529,0.000000
196.910004,0.011171,-1297.375854,0.032522,0.000027,0.000694,0.049692,0.002531,0.006938,-1297.375854,-0.000269,0.000000
197.390015,0.154907,-1297.420410,0.032474,-0.000007,-0.000174,0.689060,0.035102,-0.001735,-1297.420410,-0.001067,0.000000
197.870010,0.176877,-1297.420410,0.032526,-0.000027,-0.000677,0.786788,0.040081,-0.006765,-1297.420410,-0.001873,0.000000
198.350006,0.129958,-1297.375854,0.032582,-0.000065,-0.001648,0.578082,0.029449,-0.016478,-1297.375854,-0.002671,0.000000
198.830002,0.074102,-1297.286987,0.032483,-0.000075,-0.001917,0.329623,0.016792,-0.019167,-1297.286987,-0.002125,0.000000
199.100006,0.146342,-1297.420410,0.032440,-0.000008,-0.000191,0.650963,0.033162,-0.001908,-1297.420410,-0.000000,0.000000