File: Data/compression 4 4 days/AutoNoheating-17-4-4-240226_02262024_164621.csv
Time (sec),S:Load (lbs),S:HL1 (DIM),S:LVDT (in),S:Position (in),Ch:Position (mm),Ch:Load (N),Ch:Stress (MPa),Ch:Strain (mm/mm),Ch:HL1 (DIM),Set Point (),Cycles ()
0.110000,0.005959,-145.363754,-0.000009,0.000000,0.000009,0.026505,0.001350,0.000087,-145.363754,0.000217,0.000000
0.340000,-0.002602,-145.363754,0.000009,-0.000000,-0.000000,-0.011573,-0.000590,-0.000000,-145.363754,0.000217,0.000000
0.570000,0.016388,-145.363754,-0.000009,0.000087,0.002220,0.072897,0.003714,0.022202,-145.363754,0.002922,0.000000
0.800000,-0.008560,-145.319260,0.000082,0.000226,0.005732,-0.038078,-0.001940,0.057322,-145.319260,0.006756,0.000000
1.030000,0.010429,-145.319260,0.000246,0.000373,0.009470,0.046392,0.002363,0.094702,-145.319260,0.010589,0.000000
1.260000,-0.018616,-145.452713,0.000401,0.000528,0.013407,-0.082807,-0.004218,0.134072,-145.452713,0.014422,0.000000
1.490000,-0.003349,-145.408234,0.000530,0.000680,0.017284,-0.014898,-0.000759,0.172837,-145.408234,0.018255,0.000000
1.720000,-0.004097,-145.363754,0.000677,0.000821,0.020857,-0.018224,-0.000928,0.208567,-145.363754,0.022088,0.000000
1.950000,0.000374,-145.452713,0.000849,0.000977,0.024811,0.001663,0.000085,0.248111,-145.452713,0.025921,0.000000
2.180000,0.011177,-145.408234,0.000996,0.001131,0.028731,0.049718,0.002533,0.287311,-145.408234,0.029755,0.000000
2.410000,0.024208,-145.452713,0.001155,0.001278,0.032469,0.107683,0.005486,0.324687,-145.452713,0.033570,0.000000
2.640000,0.013405,-145.452713,0.001306,0.001433,0.036389,0.059628,0.003038,0.363887,-145.452713,0.037403,0.000000
2.870000,-0.018616,-145.408234,0.001449,0.001584,0.040222,-0.082807,-0.004218,0.402217,-145.408234,0.041236,0.000000
3.100000,-0.026436,-145.408234,0.001600,0.001729,0.043925,-0.117593,-0.005990,0.439248,-145.408234,0.045070,0.000000
3.330000,-0.005211,-145.408234,0.001768,0.001885,0.047888,-0.023179,-0.001181,0.478880,-145.408234,0.048903,0.000000
3.560000,0.007820,-145.497192,0.001897,0.002034,0.051660,0.034786,0.001772,0.516604,-145.497192,0.052736,0.000000
3.790000,0.011917,-145.497192,0.002061,0.002185,0.055502,0.053010,0.002700,0.555025,-145.497192,0.056569,0.000000
4.020000,0.008568,-145.452713,0.002207,0.002336,0.059344,0.038112,0.001941,0.593441,-145.452713,0.060402,0.000000
4.250000,-0.006325,-145.408234,0.002363,0.002483,0.063056,-0.028134,-0.001433,0.630560,-145.408234,0.064235,0.000000
4.480000,0.003357,-145.452713,0.002527,0.002638,0.067002,0.014932,0.000761,0.670017,-145.452713,0.068068,0.000000
4.710000,0.017128,-145.452713,0.002686,0.002787,0.070783,0.076189,0.003881,0.707828,-145.452713,0.071902,0.000000
4.940000,0.013039,-145.497192,0.002824,0.002938,0.074616,0.057999,0.002955,0.746162,-145.497192,0.075735,0.000000
5.170000,0.000374,-145.452713,0.002988,0.003094,0.078579,0.001663,0.000085,0.785793,-145.452713,0.079551,0.000000
5.400000,-0.038353,-145.408234,0.003143,0.003239,0.082274,-0.170603,-0.008691,0.822738,-145.408234,0.083384,0.000000
5.630000,-0.030533,-145.541672,0.003285,0.003392,0.086150,-0.135817,-0.006919,0.861503,-145.541672,0.087217,0.000000
5.860000,0.019737,-145.497192,0.003441,0.003544,0.090018,0.087796,0.004473,0.900181,-145.497192,0.091050,0.000000
6.090000,0.040962,-145.497192,0.003587,0.003688,0.093669,0.182209,0.009282,0.936690,-145.497192,0.094883,0.000000
6.320000,0.035751,-145.497192,0.003755,0.003848,0.097736,0.159030,0.008101,0.977362,-145.497192,0.098716,0.000000
6.550000,-0.011917,-145.541672,0.003915,0.003996,0.101500,-0.053010,-0.002700,1.014999,-145.541672,0.102549,0.000000
6.780000,0.024948,-145.541672,0.004061,0.004146,0.105307,0.110975,0.005653,1.053071,-145.541672,0.106382,0.000000
7.010000,0.017128,-145.541672,0.004208,0.004297,0.109140,0.076189,0.003881,1.091405,-145.541672,0.110216,0.000000
7.240000,0.035378,-145.586151,0.004355,0.004444,0.112887,0.157367,0.008017,1.128868,-145.586151,0.114049,0.000000
7.470000,0.003723,-145.541672,0.004501,0.004600,0.116833,0.016561,0.000844,1.168325,-145.541672,0.117882,0.000000
7.700000,0.010803,-145.541672,0.004674,0.004752,0.120692,0.048055,0.002448,1.206916,-145.541672,0.121715,0.000000
7.930000,-0.023087,-145.586151,0.004816,0.004898,0.124421,-0.102694,-0.005231,1.244209,-145.586151,0.125548,0.000000
8.160001,0.011177,-145.586151,0.004971,0.005049,0.128245,0.049718,0.002533,1.282451,-145.586151,0.129364,0.000000
8.390000,0.028305,-145.630630,0.005126,0.005200,0.132070,0.125907,0.006414,1.320697,-145.630630,0.133197,0.000000
8.620001,0.046173,-145.630630,0.005286,0.005359,0.136111,0.205388,0.010463,1.361109,-145.630630,0.137030,0.000000
8.850000,0.031654,-145.541672,0.005428,0.005507,0.139883,0.140806,0.007173,1.398833,-145.541672,0.140864,0.000000
9.080001,-0.014519,-145.586151,0.005583,0.005655,0.143630,-0.064583,-0.003290,1.436300,-145.586151,0.144697,0.000000
9.310000,0.011543,-145.675110,0.005726,0.005804,0.147411,0.051347,0.002616,1.474111,-145.675110,0.148529,0.000000
9.540001,0.010803,-145.586151,0.005877,0.005958,0.151322,0.048055,0.002448,1.513220,-145.586151,0.152363,0.000000
9.770000,0.021973,-145.586151,0.006032,0.006105,0.155069,0.097739,0.004979,1.550687,-145.586151,0.156196,0.000000
10.000000,0.008568,-145.586151,0.006178,0.006262,0.159067,0.038112,0.001941,1.590666,-145.586151,0.160029,0.000000
10.230000,0.024208,-145.630630,0.006329,0.006406,0.162709,0.107683,0.005486,1.627089,-145.630630,0.163862,0.000000
10.460000,0.002609,-145.630630,0.006476,0.006558,0.166577,0.011607,0.000591,1.665766,-145.630630,0.167695,0.000000
10.690001,0.024948,-145.719589,0.006631,0.006712,0.170497,0.110975,0.005653,1.704967,-145.719589,0.171528,0.000000
10.920000,0.036491,-145.630630,0.006782,0.006860,0.174252,0.162322,0.008269,1.742516,-145.630630,0.175344,0.000000
11.150001,0.037987,-145.630630,0.006946,0.007010,0.178059,0.168974,0.008608,1.780589,-145.630630,0.179177,0.000000
11.380000,0.007446,-145.719589,0.007075,0.007167,0.182039,0.033123,0.001687,1.820394,-145.719589,0.183011,0.000000
11.610001,-0.013031,-145.719589,0.007217,0.007311,0.185699,-0.057965,-0.002953,1.856991,-145.719589,0.186844,0.000000
11.840000,0.016762,-145.764084,0.007386,0.007463,0.189567,0.074560,0.003798,1.895668,-145.764084,0.190677,0.000000
12.070001,0.032028,-145.675110,0.007541,0.007617,0.193478,0.142469,0.007258,1.934782,-145.675110,0.194510,0.000000
12.300000,0.155655,-145.719589,0.007675,0.007762,0.197164,0.692388,0.035272,1.971639,-145.719589,0.198343,0.000000
12.530001,0.698570,-145.675110,0.007787,-0.000000,-0.000009,3.107396,0.158298,-0.000087,-145.675110,0.000182,0.000000
12.760000,0.639740,-145.719589,0.007774,-0.000001,-0.000017,2.845706,0.144967,-0.000174,-145.719589,0.000182,0.000000
12.990001,0.624840,-145.719589,0.007778,-0.000001,-0.000017,2.779426,0.141591,-0.000174,-145.719589,0.000208,0.000000
13.220000,0.622612,-145.675110,0.007800,-0.000001,-0.000017,2.769516,0.141086,-0.000174,-145.675110,0.000598,0.000000
13.450001,0.616280,-145.675110,0.007804,-0.000001,-0.000017,2.741349,0.139651,-0.000174,-145.675110,0.000980,0.000000
13.680000,0.590958,-145.719589,0.007795,0.000006,0.000165,2.628711,0.133913,0.001646,-145.719589,0.001361,0.000000
13.910001,0.989769,-145.764084,0.007800,0.000034,0.000867,4.402712,0.224285,0.008671,-145.764084,0.001743,0.000000
14.140000,1.212822,-145.764084,0.007817,0.000051,0.001292,5.394902,0.274829,0.012922,-145.764084,0.002124,0.000000
14.370001,1.399376,-145.719589,0.007825,0.000064,0.001621,6.224735,0.317103,0.016214,-145.719589,0.002515,0.000000
14.600000,1.629135,-145.719589,0.007838,0.000081,0.002055,7.246755,0.369167,0.020552,-145.719589,0.002896,0.000000
14.830001,1.790367,-145.764084,0.007864,0.000092,0.002333,7.963951,0.405703,0.023326,-145.764084,0.003278,0.000000
15.060000,2.137047,-145.808563,0.007877,0.000113,0.002870,9.506059,0.484262,0.028705,-145.808563,0.003660,0.000000
15.290001,2.337387,-145.764084,0.007890,0.000124,0.003157,10.397217,0.529659,0.031566,-145.764084,0.004041,0.000000
15.520000,2.579056,-145.764084,0.007907,0.000138,0.003512,11.472213,0.584422,0.035120,-145.764084,0.004431,0.000000
15.750001,2.711617,-145.764084,0.007912,0.000147,0.003746,12.061872,0.614461,0.037463,-145.764084,0.004813,0.000000
15.980000,3.207619,-145.808563,0.007929,0.000172,0.004362,14.268201,0.726857,0.043621,-145.808563,0.005194,0.000000
16.210001,3.493599,-145.897522,0.007942,0.000188,0.004778,15.540304,0.791661,0.047784,-145.897522,0.005576,0.000000
16.440001,3.603447,-145.764084,0.007942,0.000200,0.005073,16.028933,0.816553,0.050733,-145.764084,0.005967,0.000000
16.670000,3.915497,-145.764084,0.007968,0.000215,0.005463,17.417000,0.887264,0.054635,-145.764084,0.006348,0.000000
16.900002,4.169083,-145.808563,0.007976,0.000230,0.005836,18.545006,0.944728,0.058363,-145.808563,0.006730,0.000000
17.130001,4.559700,-145.853043,0.007998,0.000247,0.006278,20.282558,1.033243,0.062784,-145.853043,0.007111,0.000000
17.360001,4.857597,-145.808563,0.008006,0.000264,0.006695,21.607672,1.100747,0.066947,-145.808563,0.007493,0.000000
17.590000,5.152893,-145.808563,0.008032,0.000281,0.007137,22.921213,1.167662,0.071372,-145.808563,0.007883,0.000000
17.820002,5.474251,-145.808563,0.008037,0.000297,0.007536,24.350683,1.240483,0.075361,-145.808563,0.008264,0.000000
18.050001,5.676079,-145.808563,0.008050,0.000310,0.007865,25.248459,1.286218,0.078654,-145.808563,0.008646,0.000000
18.280001,5.844757,-145.853043,0.008058,0.000322,0.008186,25.998777,1.324441,0.081863,-145.853043,0.009028,0.000000
18.510000,6.069298,-145.897522,0.008071,0.000337,0.008559,26.997585,1.375323,0.085592,-145.897522,0.009409,0.000000
18.740002,6.338524,-145.853043,0.008093,0.000353,0.008958,28.195162,1.436330,0.089581,-145.853043,0.009799,0.000000
18.970001,6.571259,-145.808563,0.008119,0.000367,0.009331,29.230417,1.489068,0.093313,-145.808563,0.010181,0.000000
19.200001,6.880699,-145.942001,0.008110,0.000385,0.009791,30.606878,1.559189,0.097908,-145.942001,0.010563,0.000000
19.430000,6.896339,-145.897522,0.008136,0.000392,0.009964,30.676451,1.562733,0.099641,-145.897522,0.010944,0.000000
19.660002,7.253075,-145.897522,0.008132,0.000413,0.010485,32.263287,1.643570,0.104845,-145.897522,0.011326,0.000000
19.890001,7.555809,-145.897522,0.008162,0.000431,0.010944,33.609917,1.712171,0.109444,-145.897522,0.011716,0.000000
20.120001,7.626564,-145.897522,0.008170,0.000443,0.011248,33.924652,1.728204,0.112476,-145.897522,0.012098,0.000000
20.350000,7.714073,-145.897522,0.008175,0.000456,0.011586,34.313911,1.748034,0.115859,-145.897522,0.012479,0.000000
20.580002,7.947174,-145.942001,0.008192,0.000470,0.011950,35.350796,1.800855,0.119500,-145.942001,0.012861,0.000000
20.810001,8.173950,-145.897522,0.008222,0.000487,0.012366,36.359547,1.852244,0.123664,-145.897522,0.013242,0.000000
21.040001,8.410034,-145.897522,0.008226,0.000505,0.012826,37.409702,1.905741,0.128263,-145.897522,0.013632,0.000000
21.270000,8.492325,-145.986481,0.008248,0.000518,0.013164,37.775749,1.924388,0.131642,-145.986481,0.014014,0.000000
21.500002,8.427536,-145.942001,0.008252,0.000527,0.013390,37.487553,1.909707,0.133898,-145.942001,0.014396,0.000000
21.730001,8.791344,-145.986481,0.008261,0.000547,0.013902,39.105850,1.992147,0.139015,-145.986481,0.014777,0.000000
21.960001,8.958168,-145.942001,0.008282,0.000565,0.014361,39.847923,2.029950,0.143610,-145.942001,0.015159,0.000000
22.190001,9.038223,-145.942001,0.008291,0.000579,0.014699,40.204025,2.048091,0.146994,-145.942001,0.015549,0.000000
22.420002,9.093712,-145.942001,0.008313,0.000592,0.015029,40.450851,2.060664,0.150287,-145.942001,0.015931,0.000000
22.650002,9.135414,-145.942001,0.008330,0.000603,0.015315,40.636353,2.070115,0.153152,-145.942001,0.016313,0.000000
22.880001,9.446350,-146.030960,0.008343,0.000622,0.015792,42.019463,2.140574,0.157921,-146.030960,0.016694,0.000000
23.110001,9.587845,-145.942001,0.008351,0.000638,0.016208,42.648865,2.172637,0.162084,-145.942001,0.017076,0.000000
23.340002,9.423630,-146.030960,0.008382,0.000646,0.016408,41.918400,2.135425,0.164079,-146.030960,0.017466,0.000000
23.570002,9.893570,-145.986481,0.008386,0.000670,0.017023,44.008797,2.241915,0.170233,-145.986481,0.017847,0.000000
23.800001,9.991127,-146.075439,0.008407,0.000686,0.017422,44.442753,2.264022,0.174222,-146.075439,0.018229,0.000000
24.030001,9.946442,-146.075439,0.008416,0.000697,0.017700,44.243980,2.253896,0.177001,-146.075439,0.018610,0.000000
24.260000,10.074913,-146.030960,0.008420,0.000715,0.018151,44.815453,2.283008,0.181508,-146.030960,0.018992,0.000000
24.490002,10.126297,-146.030960,0.008455,0.000729,0.018515,45.044018,2.294652,0.185149,-146.030960,0.019382,0.000000
24.720001,10.309135,-146.030960,0.008464,0.000745,0.018931,45.857327,2.336084,0.189313,-146.030960,0.019764,0.000000
24.950001,10.403343,-146.075439,0.008481,0.000759,0.019278,46.276382,2.357431,0.192784,-146.075439,0.020145,0.000000
25.180000,10.412277,-146.075439,0.008481,0.000772,0.019616,46.316124,2.359456,0.196164,-146.075439,0.020527,0.000000
25.410002,10.559738,-146.075439,0.008498,0.000787,0.019990,46.972061,2.392871,0.199895,-146.075439,0.020917,0.000000
25.640001,10.745552,-146.075439,0.008528,0.000805,0.020440,47.798603,2.434977,0.204403,-146.075439,0.021299,0.000000
25.870001,10.844978,-146.075439,0.008528,0.000821,0.020848,48.240871,2.457507,0.208480,-146.075439,0.021681,0.000000
26.100000,10.907166,-146.119919,0.008550,0.000836,0.021238,48.517494,2.471599,0.212382,-146.119919,0.022062,0.000000
26.330002,10.811836,-146.119919,0.008567,0.000847,0.021507,48.093449,2.449997,0.215069,-146.119919,0.022444,0.000000
26.560001,10.970093,-146.030960,0.008571,0.000862,0.021897,48.797409,2.485859,0.218971,-146.030960,0.022834,0.000000
26.790001,11.207672,-146.030960,0.008593,0.000880,0.022340,49.854214,2.539695,0.223396,-146.030960,0.023215,0.000000
27.020000,11.239693,-146.119919,0.008606,0.000893,0.022686,49.996651,2.546951,0.226863,-146.119919,0.023597,0.000000
27.250002,11.095215,-146.119919,0.008627,0.000901,0.022886,49.353981,2.514212,0.228857,-146.119919,0.023978,0.000000
27.480001,11.463486,-146.119919,0.008632,0.000925,0.023484,50.992130,2.597663,0.234841,-146.119919,0.024360,0.000000
27.710001,11.726013,-146.119919,0.008653,0.000942,0.023935,52.159912,2.657152,0.239353,-146.119919,0.024751,0.000000
27.940001,11.642601,-146.164398,0.008666,0.000953,0.024213,51.788876,2.638251,0.242127,-146.164398,0.025132,0.000000
28.170002,11.710747,-146.119919,0.008683,0.000969,0.024603,52.092003,2.653693,0.246030,-146.119919,0.025514,0.000000
28.400002,11.651161,-146.164398,0.008701,0.000981,0.024915,51.826954,2.640191,0.249152,-146.164398,0.025895,0.000000
28.630001,11.982948,-146.208893,0.008696,0.000999,0.025375,53.302814,2.715375,0.253747,-146.208893,0.026277,0.000000
28.860001,12.170998,-146.075439,0.008722,0.001015,0.025791,54.139301,2.757987,0.257910,-146.075439,0.026667,0.000000
29.090002,12.141953,-146.164398,0.008739,0.001028,0.026103,54.010101,2.751406,0.261033,-146.164398,0.027049,0.000000
29.320002,12.175835,-146.164398,0.008765,0.001041,0.026442,54.160816,2.759084,0.264417,-146.164398,0.027430,0.000000
29.550001,12.544487,-146.208893,0.008783,0.001063,0.027005,55.800667,2.842621,0.270052,-146.208893,0.027812,0.000000
29.780001,12.535545,-146.164398,0.008787,0.001077,0.027352,55.760891,2.840595,0.273523,-146.164398,0.028193,0.000000
30.010002,12.501663,-146.208893,0.008795,0.001089,0.027673,55.610176,2.832917,0.276729,-146.208893,0.028584,0.000000
30.240002,12.538155,-146.164398,0.008808,0.001102,0.028003,55.772495,2.841187,0.280025,-146.164398,0.028965,0.000000
30.470001,12.764183,-146.164398,0.008830,0.001120,0.028436,56.777924,2.892405,0.284363,-146.164398,0.029347,0.000000
30.700001,12.858765,-146.208893,0.008834,0.001134,0.028809,57.198643,2.913838,0.288091,-146.208893,0.029728,0.000000
30.930002,13.113472,-146.297852,0.008834,0.001153,0.029286,58.331638,2.971555,0.292860,-146.297852,0.030110,0.000000
31.160002,13.087402,-146.253372,0.008864,0.001164,0.029572,58.215672,2.965648,0.295721,-146.253372,0.030500,0.000000
31.390001,13.323860,-146.253372,0.008890,0.001183,0.030041,59.267490,3.019230,0.300407,-146.253372,0.030882,0.000000
31.620001,13.468338,-146.253372,0.008895,0.001199,0.030457,59.910160,3.051969,0.304567,-146.253372,0.031263,0.000000
31.850002,13.440788,-146.297852,0.008925,0.001210,0.030743,59.787613,3.045726,0.307428,-146.297852,0.031645,0.000000
32.080002,13.453445,-146.342331,0.008921,0.001224,0.031099,59.843914,3.048594,0.310986,-146.342331,0.032027,0.000000
32.310001,13.487335,-146.253372,0.008951,0.001239,0.031471,59.994663,3.056274,0.314714,-146.253372,0.032417,0.000000
32.540001,13.781876,-146.253372,0.008959,0.001256,0.031905,61.304844,3.123018,0.319052,-146.253372,0.032798,0.000000
32.770000,14.039932,-146.297852,0.008968,0.001274,0.032347,62.452736,3.181494,0.323472,-146.297852,0.033180,0.000000
33.000000,13.888008,-146.297852,0.008994,0.001282,0.032555,61.776947,3.147068,0.325554,-146.297852,0.033561,0.000000
33.230003,14.137871,-146.297852,0.009002,0.001300,0.033024,62.888390,3.203687,0.330240,-146.297852,0.033943,0.000000
33.460003,14.287933,-146.297852,0.009011,0.001316,0.033423,63.555901,3.237692,0.334229,-146.297852,0.034333,0.000000
33.690002,14.360550,-146.297852,0.009028,0.001330,0.033770,63.878918,3.254147,0.337696,-146.297852,0.034715,0.000000
33.920002,14.438744,-146.297852,0.009046,0.001344,0.034134,64.226738,3.271866,0.341337,-146.297852,0.035097,0.000000
34.150002,14.537796,-146.342331,0.009054,0.001357,0.034472,64.667343,3.294312,0.344721,-146.342331,0.035478,0.000000
34.380001,14.679672,-146.386810,0.009067,0.001373,0.034871,65.298447,3.326461,0.348710,-146.386810,0.035868,0.000000
34.610001,15.033051,-146.253372,0.009071,0.001391,0.035330,66.870346,3.406538,0.353305,-146.253372,0.036250,0.000000
34.840000,14.904579,-146.297852,0.009110,0.001403,0.035634,66.298882,3.377426,0.356340,-146.297852,0.036631,0.000000
35.070004,15.046082,-146.297852,0.009106,0.001417,0.035990,66.928314,3.409491,0.359898,-146.297852,0.037013,0.000000
35.300003,15.289246,-146.386810,0.009110,0.001433,0.036389,68.009964,3.464593,0.363887,-146.386810,0.037395,0.000000
35.530003,15.616928,-146.342331,0.009136,0.001452,0.036883,69.467567,3.538846,0.368830,-146.342331,0.037785,0.000000
35.760002,15.528679,-146.386810,0.009149,0.001463,0.037160,69.075012,3.518849,0.371605,-146.386810,0.038167,0.000000
35.990002,15.742050,-146.342331,0.009166,0.001481,0.037620,70.024139,3.567200,0.376200,-146.342331,0.038548,0.000000
36.220001,15.826950,-146.386810,0.009196,0.001494,0.037950,70.401787,3.586438,0.379496,-146.386810,0.038930,0.000000
36.450001,16.202675,-146.386810,0.009209,0.001515,0.038470,72.073097,3.671579,0.384701,-146.386810,0.039311,0.000000
36.680000,16.037712,-146.386810,0.009218,0.001525,0.038739,71.339310,3.634197,0.387388,-146.386810,0.039701,0.000000
36.910000,16.181824,-146.386810,0.009231,0.001539,0.039086,71.980347,3.666854,0.390859,-146.386810,0.040083,0.000000
37.140003,16.515091,-146.342331,0.009240,0.001556,0.039519,73.462791,3.742373,0.395192,-146.342331,0.040465,0.000000
37.370003,16.786179,-146.475769,0.009261,0.001574,0.039988,74.668655,3.803802,0.399878,-146.475769,0.040846,0.000000
37.600002,16.938850,-146.431290,0.009274,0.001590,0.040378,75.347771,3.838398,0.403780,-146.431290,0.041228,0.000000
37.830002,16.889702,-146.386810,0.009291,0.001603,0.040707,75.129143,3.827261,0.407073,-146.386810,0.041618,0.000000
38.060001,17.051308,-146.342331,0.009300,0.001619,0.041124,75.848007,3.863882,0.411236,-146.342331,0.041999,0.000000
38.290001,17.270264,-146.431290,0.009317,0.001635,0.041523,76.821968,3.913498,0.415226,-146.431290,0.042381,0.000000
38.520000,17.431877,-146.431290,0.009334,0.001651,0.041939,77.540863,3.950120,0.419389,-146.431290,0.042763,0.000000
38.750000,17.530922,-146.475769,0.009347,0.001663,0.042242,77.981438,3.972564,0.422425,-146.475769,0.043144,0.000000
38.980003,18.023201,-146.431290,0.009373,0.001685,0.042789,80.171204,4.084116,0.427886,-146.431290,0.043535,0.000000
39.210003,18.191513,-146.475769,0.009382,0.001701,0.043214,80.919891,4.122256,0.432137,-146.475769,0.043916,0.000000
39.440002,18.019478,-146.431290,0.009395,0.001712,0.043474,80.154640,4.083272,0.434737,-146.431290,0.044298,0.000000
39.670002,18.056343,-146.431290,0.009408,0.001726,0.043847,80.318626,4.091626,0.438469,-146.431290,0.044679,0.000000
39.900002,18.116295,-146.564728,0.009416,0.001742,0.044237,80.585304,4.105211,0.442371,-146.564728,0.045061,0.000000
40.130001,18.324821,-146.475769,0.009434,0.001754,0.044558,81.512878,4.152464,0.445581,-146.475769,0.045451,0.000000
40.360001,18.691238,-146.475769,0.009447,0.001774,0.045052,83.142784,4.235495,0.450524,-146.475769,0.045833,0.000000
40.590000,18.922112,-146.475769,0.009459,0.001789,0.045434,84.169754,4.287812,0.454339,-146.475769,0.046214,0.000000
40.820004,18.813751,-146.520248,0.009477,0.001797,0.045651,83.687744,4.263257,0.456508,-146.520248,0.046596,0.000000
41.050003,19.341400,-146.520248,0.009494,0.001818,0.046171,86.034843,4.382824,0.461708,-146.520248,0.046977,0.000000
41.280003,19.515671,-146.520248,0.009503,0.001831,0.046518,86.810036,4.422314,0.465179,-146.520248,0.047368,0.000000
41.510002,19.648605,-146.520248,0.009520,0.001846,0.046891,87.401360,4.452437,0.468907,-146.520248,0.047749,0.000000
41.740002,19.751381,-146.475769,0.009541,0.001860,0.047255,87.858528,4.475727,0.472548,-146.475769,0.048131,0.000000
41.970001,19.758827,-146.609207,0.009546,0.001872,0.047558,87.891655,4.477414,0.475583,-146.609207,0.048513,0.000000
42.200001,20.173653,-146.609207,0.009559,0.001891,0.048027,89.736885,4.571415,0.480269,-146.609207,0.048903,0.000000
42.430000,20.554588,-146.564728,0.009567,0.001908,0.048452,91.431374,4.657736,0.484516,-146.564728,0.049284,0.000000
42.660004,20.450325,-146.520248,0.009580,0.001917,0.048686,90.967590,4.634109,0.486859,-146.520248,0.049666,0.000000
42.890003,20.460754,-146.609207,0.009593,0.001933,0.049102,91.013985,4.636473,0.491022,-146.609207,0.050047,0.000000
43.120003,21.347374,-146.653702,0.009615,0.001954,0.049640,94.957863,4.837384,0.496397,-146.653702,0.050429,0.000000
43.350002,21.360031,-146.609207,0.009636,0.001966,0.049926,95.014160,4.840252,0.499262,-146.609207,0.050819,0.000000
43.580002,21.570793,-146.564728,0.009632,0.001983,0.050377,95.951683,4.888011,0.503770,-146.564728,0.051201,0.000000
43.810001,21.508606,-146.609207,0.009653,0.001993,0.050620,95.675056,4.873919,0.506199,-146.609207,0.051582,0.000000
44.040001,21.529091,-146.653702,0.009658,0.002008,0.050993,95.766182,4.878562,0.509928,-146.653702,0.051964,0.000000
44.270000,22.020622,-146.609207,0.009679,0.002023,0.051392,97.952621,4.989944,0.513917,-146.609207,0.052345,0.000000
44.500004,22.222076,-146.609207,0.009701,0.002037,0.051738,98.848732,5.035594,0.517384,-146.609207,0.052736,0.000000
44.730003,22.054504,-146.609207,0.009705,0.002047,0.051981,98.103333,4.997622,0.519814,-146.609207,0.053117,0.000000
44.960003,23.101242,-146.564728,0.009727,0.002073,0.052649,102.759460,5.234817,0.526490,-146.564728,0.053499,0.000000
45.190002,23.351105,-146.609207,0.009731,0.002089,0.053057,103.870903,5.291436,0.530567,-146.609207,0.053881,0.000000
45.420002,23.554794,-146.698181,0.009748,0.002106,0.053490,104.776955,5.337593,0.534904,-146.698181,0.054262,0.000000
45.650002,23.585701,-146.653702,0.009757,0.002116,0.053742,104.914436,5.344596,0.537417,-146.653702,0.054652,0.000000
45.880001,23.819550,-146.698181,0.009779,0.002132,0.054141,105.954651,5.397587,0.541407,-146.698181,0.055034,0.000000
46.110001,24.172188,-146.653702,0.009779,0.002148,0.054548,107.523262,5.477496,0.545483,-146.653702,0.055415,0.000000
46.340004,24.159897,-146.653702,0.009813,0.002158,0.054817,107.468590,5.474711,0.548170,-146.653702,0.055797,0.000000
46.570004,24.414604,-146.698181,0.009813,0.002173,0.055190,108.601585,5.532429,0.551902,-146.698181,0.056179,0.000000
46.800003,24.826447,-146.698181,0.009813,0.002190,0.055624,110.433548,5.625753,0.556236,-146.698181,0.056569,0.000000
47.030003,25.449425,-146.653702,0.009830,0.002209,0.056118,113.204697,5.766922,0.561179,-146.653702,0.056951,0.000000
47.260002,25.853821,-146.698181,0.009860,0.002226,0.056534,115.003540,5.858560,0.565342,-146.698181,0.057332,0.000000
47.490002,25.847122,-146.698181,0.009865,0.002238,0.056838,114.973740,5.857042,0.568378,-146.698181,0.057714,0.000000
47.720001,25.895531,-146.742661,0.009891,0.002250,0.057150,115.189072,5.868011,0.571500,-146.742661,0.058095,0.000000
47.950001,26.034424,-146.698181,0.009895,0.002265,0.057523,115.806900,5.899485,0.575228,-146.698181,0.058486,0.000000
48.180004,26.691284,-146.653702,0.009912,0.002283,0.057983,118.728760,6.048332,0.579827,-146.653702,0.058867,0.000000
48.410004,26.849174,-146.742661,0.009916,0.002295,0.058295,119.431091,6.084110,0.582946,-146.742661,0.059249,0.000000
48.640003,27.070366,-146.742661,0.009925,0.002309,0.058642,120.415001,6.134233,0.586416,-146.742661,0.059630,0.000000
48.870003,27.672493,-146.698181,0.009947,0.002327,0.059101,123.093399,6.270676,0.591011,-146.698181,0.060012,0.000000
49.100002,28.219879,-146.698181,0.009960,0.002344,0.059535,125.528290,6.394716,0.595349,-146.698181,0.060402,0.000000
49.330002,28.072792,-146.742661,0.009964,0.002357,0.059873,124.874016,6.361386,0.598733,-146.742661,0.060784,0.000000
49.560001,28.518150,-146.787140,0.009977,0.002371,0.060211,126.855072,6.462306,0.602112,-146.787140,0.061165,0.000000
49.790001,28.463783,-146.742661,0.009990,0.002381,0.060472,126.613228,6.449986,0.604716,-146.742661,0.061547,0.000000
50.020004,29.357475,-146.742661,0.010007,0.002401,0.060974,130.588577,6.652499,0.609743,-146.742661,0.061928,0.000000
50.250004,29.627815,-146.787140,0.010020,0.002415,0.061339,131.791107,6.713759,0.613388,-146.787140,0.062319,0.000000
50.480003,29.780487,-146.787140,0.010042,0.002428,0.061660,132.470230,6.748355,0.616597,-146.787140,0.062700,0.000000
50.710003,30.024391,-146.787140,0.010042,0.002440,0.061980,133.555161,6.803624,0.619803,-146.787140,0.063082,0.000000
50.940002,31.086029,-146.831619,0.010067,0.002464,0.062579,138.277557,7.044195,0.625787,-146.831619,0.063463,0.000000
51.170002,31.346687,-146.876099,0.010076,0.002478,0.062934,139.437027,7.103261,0.629345,-146.876099,0.063854,0.000000
51.400002,31.329933,-146.831619,0.010085,0.002490,0.063255,139.362503,7.099464,0.632554,-146.831619,0.064235,0.000000
51.630001,31.631927,-146.831619,0.010089,0.002503,0.063576,140.705841,7.167897,0.635760,-146.831619,0.064617,0.000000
51.860001,32.163673,-146.831619,0.010106,0.002519,0.063984,143.071167,7.288393,0.639836,-146.831619,0.064998,0.000000
52.090004,32.814957,-146.876099,0.010123,0.002536,0.064426,145.968216,7.435976,0.644261,-146.876099,0.065380,0.000000
52.320004,33.488945,-146.876099,0.010123,0.002553,0.064851,148.966263,7.588704,0.648511,-146.876099,0.065770,0.000000
52.550003,33.497139,-146.831619,0.010141,0.002563,0.065102,149.002716,7.590560,0.651025,-146.831619,0.066152,0.000000
52.780003,34.332375,-146.831619,0.010154,0.002584,0.065632,152.718033,7.779827,0.656316,-146.831619,0.066534,0.000000
53.010002,35.011948,-146.876099,0.010167,0.002602,0.066100,155.740921,7.933821,0.660998,-146.876099,0.066915,0.000000
53.240002,34.873055,-146.965057,0.010179,0.002611,0.066325,155.123093,7.902347,0.663254,-146.965057,0.067297,0.000000
53.470001,35.288994,-146.920578,0.010188,0.002629,0.066776,156.973282,7.996600,0.667761,-146.920578,0.067687,0.000000
53.700001,35.685944,-146.876099,0.010197,0.002641,0.067088,158.738998,8.086551,0.670884,-146.876099,0.068068,0.000000
53.930004,36.250832,-146.876099,0.010210,0.002656,0.067470,161.251755,8.214556,0.674699,-146.876099,0.068450,0.000000
54.160004,37.038033,-146.876099,0.010236,0.002674,0.067921,164.753403,8.392938,0.679211,-146.876099,0.068832,0.000000
54.390003,37.335930,-146.920578,0.010240,0.002687,0.068259,166.078506,8.460443,0.682591,-146.920578,0.069213,0.000000
54.620003,37.702713,-146.920578,0.010240,0.002702,0.068632,167.710037,8.543557,0.686323,-146.920578,0.069603,0.000000
54.850002,38.411339,-146.876099,0.010257,0.002718,0.069048,170.862167,8.704134,0.690482,-146.876099,0.069985,0.000000
55.080002,38.652634,-146.920578,0.010279,0.002730,0.069343,171.935501,8.758813,0.693431,-146.920578,0.070366,0.000000
55.310001,39.378387,-146.920578,0.010279,0.002748,0.069794,175.163818,8.923270,0.697942,-146.920578,0.070748,0.000000
55.540001,39.847954,-146.965057,0.010296,0.002761,0.070141,177.252548,9.029675,0.701409,-146.965057,0.071130,0.000000
55.770004,40.495506,-146.965057,0.010305,0.002778,0.070557,180.133011,9.176413,0.705573,-146.965057,0.071520,0.000000
56.000004,40.898788,-146.876099,0.010326,0.002792,0.070913,181.926895,9.267798,0.709130,-146.876099,0.071902,0.000000
56.230003,41.228706,-146.920578,0.010330,0.002804,0.071234,183.394440,9.342558,0.712336,-146.920578,0.072283,0.000000
56.460003,41.667366,-146.965057,0.010343,0.002818,0.071589,185.345703,9.441960,0.715894,-146.965057,0.072665,0.000000
56.690002,42.735329,-147.009537,0.010361,0.002838,0.072075,190.096237,9.683965,0.720750,-147.009537,0.073046,0.000000
56.920002,43.561996,-146.965057,0.010352,0.002855,0.072526,193.773437,9.871289,0.725258,-146.965057,0.073436,0.000000
57.150002,43.808136,-146.965057,0.010374,0.002868,0.072838,194.868317,9.927065,0.728380,-146.965057,0.073818,0.000000
57.380001,44.346581,-147.009537,0.010386,0.002882,0.073211,197.263443,10.049079,0.732108,-147.009537,0.074200,0.000000
57.610004,44.935677,-146.965057,0.010404,0.002900,0.073653,199.883865,10.182570,0.736533,-146.965057,0.074581,0.000000
57.840004,45.999916,-147.009537,0.010417,0.002916,0.074078,204.617844,10.423730,0.740783,-147.009537,0.074963,0.000000
58.070004,46.299675,-147.054031,0.010404,0.002928,0.074382,205.951233,10.491656,0.743819,-147.054031,0.075353,0.000000
58.300003,46.615448,-146.965057,0.010421,0.002940,0.074685,207.355865,10.563211,0.746854,-146.965057,0.075735,0.000000
58.530003,47.370621,-146.965057,0.010447,0.002956,0.075084,210.715042,10.734336,0.750844,-146.965057,0.076116,0.000000
58.760002,48.578224,-147.054031,0.010442,0.002978,0.075639,216.086731,11.007982,0.756392,-147.054031,0.076498,0.000000
58.990002,49.149071,-147.054031,0.010464,0.002992,0.075986,218.625992,11.137339,0.759863,-147.054031,0.076880,0.000000
59.220001,49.437286,-147.098511,0.010464,0.003003,0.076264,219.908035,11.202649,0.762637,-147.098511,0.077270,0.000000
59.450005,50.338432,-147.009537,0.010477,0.003020,0.076715,223.916534,11.406852,0.767145,-147.009537,0.077651,0.000000
59.680004,51.200470,-147.009537,0.010503,0.003039,0.077191,227.751068,11.602192,0.771914,-147.009537,0.078033,0.000000
59.910004,51.836113,-147.098511,0.010494,0.003052,0.077521,230.578552,11.746231,0.775211,-147.098511,0.078414,0.000000
60.140003,52.258385,-147.098511,0.010507,0.003062,0.077773,232.456909,11.841919,0.777728,-147.098511,0.078805,0.000000
60.370003,53.376244,-147.098511,0.010524,0.003082,0.078284,237.429382,12.095230,0.782841,-147.098511,0.079186,0.000000
60.600002,54.571190,-147.098511,0.010520,0.003102,0.078796,242.744781,12.366009,0.787958,-147.098511,0.079568,0.000000
60.830002,54.844139,-147.054031,0.010533,0.003112,0.079056,243.958908,12.427860,0.790562,-147.054031,0.079949,0.000000
61.060001,55.550529,-147.142990,0.010555,0.003127,0.079438,247.101089,12.587930,0.794378,-147.142990,0.080331,0.000000
61.290005,56.504547,-147.142990,0.010550,0.003145,0.079889,251.344772,12.804113,0.798885,-147.142990,0.080721,0.000000
61.520004,57.061989,-147.142990,0.010559,0.003159,0.080227,253.824402,12.930432,0.802269,-147.142990,0.081103,0.000000
61.750004,58.019730,-147.142990,0.010580,0.003175,0.080643,258.084656,13.147459,0.806432,-147.142990,0.081484,0.000000
61.980003,58.800964,-147.098511,0.010593,0.003188,0.080973,261.559753,13.324489,0.809725,-147.098511,0.081866,0.000000
62.210003,58.942841,-147.142990,0.010593,0.003197,0.081216,262.190857,13.356639,0.812155,-147.142990,0.082248,0.000000
62.440002,60.417061,-147.187469,0.010602,0.003220,0.081779,268.748505,13.690701,0.817791,-147.187469,0.082638,0.000000
62.670002,61.291763,-147.098511,0.010611,0.003235,0.082178,272.639374,13.888911,0.821780,-147.098511,0.083019,0.000000
62.900002,61.707329,-147.142990,0.010611,0.003245,0.082430,274.487915,13.983080,0.824297,-147.142990,0.083401,0.000000
63.130005,62.504211,-147.142990,0.010645,0.003261,0.082829,278.032623,14.163657,0.828286,-147.142990,0.083782,0.000000
63.360004,63.467911,-147.142990,0.010628,0.003278,0.083262,282.319366,14.382033,0.832620,-147.142990,0.084164,0.000000
63.590004,64.403687,-147.187469,0.010637,0.003294,0.083661,286.481903,14.594084,0.836609,-147.187469,0.084554,0.000000
63.820004,65.371857,-147.187469,0.010641,0.003310,0.084069,290.788544,14.813475,0.840686,-147.187469,0.084936,0.000000
64.050003,65.674591,-147.142990,0.010654,0.003317,0.084242,292.135162,14.882075,0.842423,-147.142990,0.085318,0.000000
64.280006,66.752609,-147.187469,0.010658,0.003336,0.084745,296.930450,15.126357,0.847453,-147.187469,0.085699,0.000000
64.510002,67.304840,-147.231949,0.010684,0.003341,0.084849,299.386871,15.251495,0.848490,-147.231949,0.084997,0.000000
64.740005,66.556732,-147.187469,0.010697,0.003340,0.084832,296.059143,15.081971,0.848320,-147.187469,0.084997,0.000000
64.970001,65.908066,-147.231949,0.010671,0.003339,0.084823,293.173706,14.934980,0.848233,-147.231949,0.084832,0.000000
65.200005,65.306305,-147.231949,0.010680,0.003339,0.084815,290.496948,14.798620,0.848146,-147.231949,0.084832,0.000000
65.430000,64.774185,-147.231949,0.010701,0.003339,0.084815,288.129974,14.678040,0.848146,-147.231949,0.084832,0.000000
65.660004,64.288239,-147.320908,0.010688,0.003339,0.084815,285.968353,14.567924,0.848146,-147.320908,0.084832,0.000000
65.889999,63.839172,-147.276428,0.010693,0.003339,0.084815,283.970825,14.466164,0.848146,-147.276428,0.084832,0.000000
66.120003,63.415405,-147.231949,0.010705,0.003339,0.084806,282.085815,14.370136,0.848059,-147.231949,0.084832,0.000000
66.350006,63.037819,-147.231949,0.010693,0.003339,0.084806,280.406219,14.284575,0.848059,-147.231949,0.084832,0.000000
66.580002,62.694489,-147.231949,0.010701,0.003339,0.084806,278.879028,14.206774,0.848059,-147.231949,0.084832,0.000000
66.810005,62.361588,-147.276428,0.010701,0.003339,0.084806,277.398193,14.131338,0.848059,-147.276428,0.084832,0.000000
67.040001,62.058479,-147.320908,0.010710,0.003339,0.084806,276.049896,14.062653,0.848059,-147.320908,0.084832,0.000000
67.270004,61.769890,-147.276428,0.010710,0.003339,0.084806,274.766205,13.997257,0.848059,-147.276428,0.084832,0.000000
67.500000,61.501411,-147.276428,0.010705,0.003339,0.084806,273.571930,13.936419,0.848059,-147.276428,0.084832,0.000000
67.730003,61.245964,-147.231949,0.010723,0.003339,0.084806,272.435669,13.878534,0.848059,-147.231949,0.084832,0.000000
67.960007,61.027382,-147.320908,0.010714,0.003339,0.084806,271.463348,13.829002,0.848059,-147.320908,0.084832,0.000000
68.190002,60.788689,-147.365387,0.010723,0.003339,0.084806,270.401581,13.774914,0.848059,-147.365387,0.084832,0.000000
68.420006,60.581650,-147.320908,0.010723,0.003339,0.084806,269.480652,13.727998,0.848059,-147.320908,0.084832,0.000000
68.650002,60.379456,-147.365387,0.010718,0.003338,0.084797,268.581238,13.682179,0.847972,-147.365387,0.084832,0.000000
68.880005,60.197731,-147.320908,0.010723,0.003338,0.084797,267.772888,13.641001,0.847972,-147.320908,0.084832,0.000000
69.110001,59.999634,-147.365387,0.010736,0.003338,0.084797,266.891693,13.596111,0.847972,-147.365387,0.084832,0.000000
69.340004,59.818291,-147.454346,0.010727,0.003338,0.084797,266.085052,13.555018,0.847972,-147.454346,0.084832,0.000000
69.570000,59.677902,-147.365387,0.010727,0.003338,0.084797,265.460571,13.523206,0.847972,-147.365387,0.084832,0.000000
69.800003,59.516296,-147.365387,0.010731,0.003338,0.084797,264.741699,13.486586,0.847972,-147.365387,0.084832,0.000000
70.030006,59.357658,-147.320908,0.010731,0.003338,0.084797,264.036041,13.450638,0.847972,-147.320908,0.084832,0.000000
70.260002,59.191208,-147.409866,0.010744,0.003338,0.084797,263.295654,13.412920,0.847972,-147.409866,0.084832,0.000000
70.490005,59.075035,-147.409866,0.010727,0.003338,0.084797,262.778870,13.386594,0.847972,-147.409866,0.084832,0.000000
70.720001,58.940979,-147.409866,0.010736,0.003338,0.084797,262.182556,13.356216,0.847972,-147.409866,0.084832,0.000000
70.950005,58.812881,-147.409866,0.010736,0.003338,0.084797,261.612762,13.327189,0.847972,-147.409866,0.084832,0.000000
71.180000,58.672501,-147.365387,0.010744,0.003338,0.084797,260.988312,13.295379,0.847972,-147.365387,0.084832,0.000000
71.410004,58.574188,-147.365387,0.010740,0.003338,0.084797,260.550995,13.273101,0.847972,-147.365387,0.084832,0.000000
71.640007,58.448326,-147.454346,0.010749,0.003338,0.084797,259.991150,13.244580,0.847972,-147.454346,0.084832,0.000000
71.870003,58.323959,-147.454346,0.010740,0.003338,0.084797,259.437927,13.216398,0.847972,-147.454346,0.084832,0.000000
72.100006,58.214851,-147.365387,0.010731,0.003338,0.084797,258.952606,13.191674,0.847972,-147.365387,0.084832,0.000000
72.330002,58.125481,-147.365387,0.010744,0.003338,0.084797,258.555054,13.171422,0.847972,-147.365387,0.084832,0.000000
72.560005,58.009674,-147.409866,0.010753,0.003338,0.084797,258.039917,13.145180,0.847972,-147.409866,0.084832,0.000000
72.790001,57.916206,-147.454346,0.010736,0.003338,0.084797,257.624146,13.124000,0.847972,-147.454346,0.084832,0.000000
73.020004,57.831680,-147.454346,0.010736,0.003338,0.084797,257.248169,13.104846,0.847972,-147.454346,0.084832,0.000000
73.250000,57.730019,-147.454346,0.010744,0.003338,0.084797,256.795959,13.081809,0.847972,-147.454346,0.084832,0.000000
73.480003,57.636932,-147.409866,0.010744,0.003338,0.084797,256.381866,13.060715,0.847972,-147.409866,0.084832,0.000000
73.710007,57.550163,-147.454346,0.010757,0.003338,0.084797,255.995911,13.041053,0.847972,-147.454346,0.084832,0.000000
73.940002,57.470108,-147.498840,0.010749,0.003338,0.084797,255.639801,13.022913,0.847972,-147.498840,0.084832,0.000000
74.170006,57.374405,-147.498840,0.010753,0.003338,0.084797,255.214096,13.001226,0.847972,-147.498840,0.084832,0.000000
74.400002,57.299561,-147.454346,0.010740,0.003338,0.084797,254.881180,12.984266,0.847972,-147.454346,0.084832,0.000000
74.630005,57.226578,-147.409866,0.010749,0.003338,0.084797,254.556534,12.967728,0.847972,-147.409866,0.084832,0.000000
74.860001,57.156944,-147.409866,0.010753,0.003338,0.084797,254.246780,12.951948,0.847972,-147.409866,0.084832,0.000000
75.090004,57.060867,-147.454346,0.010753,0.003338,0.084797,253.819412,12.930178,0.847972,-147.454346,0.084832,0.000000
75.320007,57.002403,-147.498840,0.010740,0.003338,0.084797,253.559357,12.916929,0.847972,-147.498840,0.084832,0.000000
75.550003,56.940964,-147.543320,0.010757,0.003338,0.084797,253.286057,12.903007,0.847972,-147.543320,0.084832,0.000000
75.780006,56.860535,-147.498840,0.010753,0.003338,0.084797,252.928284,12.884781,0.847972,-147.498840,0.084832,0.000000
76.010002,56.779724,-147.454346,0.010762,0.003338,0.084797,252.568832,12.866469,0.847972,-147.454346,0.084832,0.000000
76.240005,56.732063,-147.587799,0.010749,0.003338,0.084797,252.356827,12.855669,0.847972,-147.587799,0.084832,0.000000
76.470001,56.666527,-147.587799,0.010753,0.003338,0.084797,252.065308,12.840818,0.847972,-147.587799,0.084832,0.000000
76.700005,56.592796,-147.543320,0.010740,0.003338,0.084797,251.737335,12.824111,0.847972,-147.543320,0.084832,0.000000
76.930000,56.522415,-147.498840,0.010766,0.003338,0.084797,251.424255,12.808162,0.847972,-147.498840,0.084832,0.000000
77.160004,56.475868,-147.543320,0.010753,0.003338,0.084797,251.217209,12.797615,0.847972,-147.543320,0.084832,0.000000
77.390007,56.406982,-147.543320,0.010753,0.003338,0.084797,250.910782,12.782005,0.847972,-147.543320,0.084832,0.000000
77.620003,56.341072,-147.587799,0.010753,0.003338,0.084797,250.617599,12.767070,0.847972,-147.587799,0.084832,0.000000
77.850006,56.276283,-147.543320,0.010744,0.003338,0.084797,250.329407,12.752388,0.847972,-147.543320,0.084832,0.000000
78.080002,56.230103,-147.498840,0.010774,0.003338,0.084797,250.123993,12.741923,0.847972,-147.498840,0.084832,0.000000
78.310005,56.170898,-147.543320,0.010757,0.003338,0.084797,249.860641,12.728507,0.847972,-147.543320,0.084832,0.000000
78.540001,56.114296,-147.632278,0.010766,0.003338,0.084797,249.608856,12.715681,0.847972,-147.632278,0.084832,0.000000
78.770004,56.056580,-147.676758,0.010762,0.003338,0.084797,249.352127,12.702602,0.847972,-147.676758,0.084832,0.000000
79.000000,56.021950,-147.587799,0.010766,0.003338,0.084797,249.198074,12.694756,0.847972,-147.587799,0.084832,0.000000
79.230003,55.964607,-147.587799,0.010757,0.003338,0.084797,248.943008,12.681762,0.847972,-147.587799,0.084832,0.000000
79.460007,55.899437,-147.543320,0.010762,0.003338,0.084797,248.653107,12.666994,0.847972,-147.543320,0.084832,0.000000
79.690002,55.856247,-147.676758,0.010757,0.003338,0.084797,248.460999,12.657207,0.847972,-147.676758,0.084832,0.000000
79.920006,55.817146,-147.721237,0.010757,0.003338,0.084797,248.287064,12.648347,0.847972,-147.721237,0.084832,0.000000
80.150002,55.757195,-147.587799,0.010757,0.003338,0.084797,248.020386,12.634761,0.847972,-147.587799,0.084832,0.000000
80.380005,55.702454,-147.632278,0.010770,0.003338,0.084797,247.776886,12.622355,0.847972,-147.632278,0.084832,0.000000
80.610001,55.667824,-147.587799,0.010762,0.003338,0.084797,247.622849,12.614510,0.847972,-147.587799,0.084832,0.000000
80.840004,55.631706,-147.632278,0.010770,0.003338,0.084797,247.462189,12.606325,0.847972,-147.632278,0.084832,0.000000
81.070007,55.581802,-147.676758,0.010766,0.003338,0.084797,247.240204,12.595016,0.847972,-147.676758,0.084832,0.000000
81.300003,55.526695,-147.765717,0.010757,0.003338,0.084797,246.995071,12.582529,0.847972,-147.765717,0.084832,0.000000
81.530006,55.483124,-147.676758,0.010762,0.003338,0.084797,246.801254,12.572656,0.847972,-147.676758,0.084832,0.000000
81.760002,55.459671,-147.676758,0.010779,0.003338,0.084797,246.696945,12.567341,0.847972,-147.676758,0.084832,0.000000
81.990005,55.408279,-147.721237,0.010766,0.003338,0.084797,246.468338,12.555696,0.847972,-147.721237,0.084832,0.000000
82.220001,55.359123,-147.721237,0.010762,0.003338,0.084797,246.249680,12.544557,0.847972,-147.721237,0.084832,0.000000
82.450005,55.330452,-147.676758,0.010762,0.003338,0.084797,246.122147,12.538059,0.847972,-147.676758,0.084832,0.000000
82.680000,55.276833,-147.676758,0.010757,0.003338,0.084797,245.883636,12.525909,0.847972,-147.676758,0.084832,0.000000
82.910004,55.244064,-147.721237,0.010766,0.003338,0.084797,245.737869,12.518483,0.847972,-147.721237,0.084832,0.000000
83.140007,55.210175,-147.721237,0.010770,0.003338,0.084797,245.587128,12.510804,0.847972,-147.721237,0.084832,0.000000
83.370003,55.162888,-147.810196,0.010770,0.003338,0.084797,245.376785,12.500089,0.847972,-147.810196,0.084832,0.000000
83.600006,55.123039,-147.765717,0.010762,0.003338,0.084797,245.199524,12.491059,0.847972,-147.765717,0.084832,0.000000
83.830002,55.095856,-147.721237,0.010774,0.003338,0.084797,245.078613,12.484900,0.847972,-147.721237,0.084832,0.000000
84.060005,55.069420,-147.721237,0.010753,0.003338,0.084797,244.961014,12.478909,0.847972,-147.721237,0.084832,0.000000
84.290001,55.019150,-147.721237,0.010770,0.003338,0.084797,244.737396,12.467517,0.847972,-147.721237,0.084832,0.000000
84.520004,54.975212,-147.810196,0.010766,0.003338,0.084797,244.541962,12.457561,0.847972,-147.810196,0.084832,0.000000
84.750008,54.961807,-147.765717,0.010766,0.003338,0.084797,244.482330,12.454523,0.847972,-147.765717,0.084832,0.000000
84.980003,54.918610,-147.810196,0.010762,0.003338,0.084797,244.290176,12.444735,0.847972,-147.810196,0.084832,0.000000
85.210007,54.882866,-147.765717,0.010774,0.003338,0.084797,244.131180,12.436635,0.847972,-147.765717,0.084832,0.000000
85.440002,54.853821,-147.854675,0.010770,0.003338,0.084797,244.001984,12.430054,0.847972,-147.854675,0.084832,0.000000
85.670006,54.829613,-147.810196,0.010774,0.003338,0.084797,243.894302,12.424568,0.847972,-147.810196,0.084832,0.000000
85.900002,54.781578,-147.854675,0.010766,0.003338,0.084797,243.680634,12.413683,0.847972,-147.854675,0.084832,0.000000
86.130005,54.738754,-147.810196,0.010757,0.003338,0.084797,243.490143,12.403979,0.847972,-147.810196,0.084832,0.000000
86.360001,54.713806,-147.765717,0.010757,0.003338,0.084797,243.379166,12.398326,0.847972,-147.765717,0.084832,0.000000
86.590004,54.690720,-147.810196,0.010770,0.003338,0.084797,243.276474,12.393094,0.847972,-147.810196,0.084832,0.000000
86.820007,54.653107,-147.943649,0.010766,0.003338,0.084797,243.109161,12.384570,0.847972,-147.943649,0.084832,0.000000
87.050003,54.627785,-147.899155,0.010770,0.003338,0.084797,242.996521,12.378833,0.847972,-147.899155,0.084832,0.000000
87.280006,54.596138,-147.854675,0.010762,0.003338,0.084797,242.855743,12.371662,0.847972,-147.854675,0.084832,0.000000
87.510002,54.556664,-147.810196,0.010779,0.003338,0.084797,242.680161,12.362717,0.847972,-147.810196,0.084832,0.000000
87.740005,54.531342,-147.854675,0.010774,0.003338,0.084797,242.567520,12.356978,0.847972,-147.854675,0.084832,0.000000
87.970001,54.513466,-147.899155,0.010779,0.003338,0.084797,242.488007,12.352928,0.847972,-147.899155,0.084832,0.000000
88.200005,54.476234,-147.943649,0.010766,0.003338,0.084797,242.322388,12.344491,0.847972,-147.943649,0.084832,0.000000
88.430008,54.437874,-147.854675,0.010774,0.003338,0.084797,242.151764,12.335798,0.847972,-147.854675,0.084832,0.000000
88.660004,54.411812,-147.854675,0.010774,0.003338,0.084797,242.035828,12.329893,0.847972,-147.854675,0.084832,0.000000
88.890007,54.394310,-147.899155,0.010757,0.003338,0.084797,241.957977,12.325927,0.847972,-147.899155,0.084832,0.000000
89.120003,54.356697,-147.899155,0.010762,0.003338,0.084797,241.790665,12.317404,0.847972,-147.899155,0.084832,0.000000
89.350006,54.323189,-147.943649,0.010770,0.003338,0.084797,241.641617,12.309811,0.847972,-147.943649,0.084832,0.000000
89.580002,54.304199,-147.899155,0.010766,0.003338,0.084797,241.557144,12.305508,0.847972,-147.899155,0.084832,0.000000
89.810005,54.284088,-147.854675,0.010757,0.003338,0.084797,241.467682,12.300950,0.847972,-147.854675,0.084832,0.000000
90.040001,54.242378,-147.899155,0.010783,0.003338,0.084797,241.282150,12.291499,0.847972,-147.899155,0.084832,0.000000
90.270004,54.215942,-147.943649,0.010774,0.003338,0.084797,241.164551,12.285508,0.847972,-147.943649,0.084832,0.000000
90.500008,54.192108,-147.943649,0.010779,0.003338,0.084797,241.058533,12.280107,0.847972,-147.943649,0.084832,0.000000
90.730003,54.167534,-147.943649,0.010783,0.003338,0.084797,240.949219,12.274538,0.847972,-147.943649,0.084832,0.000000
90.960007,54.145561,-147.899155,0.010774,0.003338,0.084797,240.851486,12.269560,0.847972,-147.899155,0.084832,0.000000
91.190002,54.124336,-147.943649,0.010783,0.003338,0.084797,240.757065,12.264750,0.847972,-147.943649,0.084832,0.000000
91.420006,54.080399,-147.988129,0.010770,0.003338,0.084797,240.561630,12.254794,0.847972,-147.988129,0.084832,0.000000
91.650002,54.059921,-147.988129,0.010770,0.003338,0.084797,240.470535,12.250153,0.847972,-147.988129,0.084832,0.000000
91.880005,54.043533,-147.988129,0.010779,0.003338,0.084797,240.397644,12.246440,0.847972,-147.988129,0.084832,0.000000
92.110001,54.012627,-147.899155,0.010783,0.003338,0.084797,240.260162,12.239436,0.847972,-147.899155,0.084832,0.000000
92.340004,53.980232,-147.943649,0.010774,0.003338,0.084797,240.116058,12.232096,0.847972,-147.943649,0.084832,0.000000
92.570007,53.961617,-148.077087,0.010774,0.003338,0.084797,240.033264,12.227877,0.847972,-148.077087,0.084832,0.000000
92.800003,53.940018,-148.077087,0.010779,0.003338,0.084797,239.937180,12.222983,0.847972,-148.077087,0.084832,0.000000
93.030006,53.915810,-148.077087,0.010770,0.003338,0.084797,239.829498,12.217497,0.847972,-148.077087,0.084832,0.000000
93.260002,53.881927,-148.032608,0.010774,0.003338,0.084797,239.678787,12.209819,0.847972,-148.032608,0.084832,0.000000
93.490005,53.867775,-148.032608,0.010774,0.003338,0.084797,239.615829,12.206612,0.847972,-148.032608,0.084832,0.000000
93.720001,53.838730,-147.988129,0.010770,0.003338,0.084797,239.486633,12.200031,0.847972,-147.988129,0.084832,0.000000
93.950005,53.822342,-148.032608,0.010779,0.003338,0.084797,239.413727,12.196317,0.847972,-148.032608,0.084832,0.000000
94.180008,53.801491,-148.077087,0.010779,0.003338,0.084797,239.320984,12.191591,0.847972,-148.077087,0.084832,0.000000
94.410004,53.781754,-148.077087,0.010774,0.003338,0.084797,239.233185,12.187119,0.847972,-148.077087,0.084832,0.000000
94.640007,53.745262,-148.032608,0.010779,0.003338,0.084797,239.070862,12.178850,0.847972,-148.032608,0.084832,0.000000
94.870003,53.724037,-148.032608,0.010779,0.003338,0.084797,238.976456,12.174042,0.847972,-148.032608,0.084832,0.000000
94.900002,53.740051,-148.121567,0.010766,0.003338,0.084797,239.047684,12.177670,0.847972,-148.121567,0.084832,0.000000