File: Data/compression 4 4 days/AutoNoheating-15-4-3-240226_02262024_163110.csv
Time (sec),S:Load (lbs),S:HL1 (DIM),S:LVDT (in),S:Position (in),Ch:Position (mm),Ch:Load (N),Ch:Stress (MPa),Ch:Strain (mm/mm),Ch:HL1 (DIM),Set Point (),Cycles ()
0.110000,0.008568,-119.564796,0.000009,-0.000000,-0.000000,0.038112,0.001941,-0.000000,-119.564796,0.000217,0.000000
0.340000,0.005211,-119.653755,0.000009,-0.000000,-0.000000,0.023179,0.001181,-0.000000,-119.653755,0.000217,0.000000
0.570000,-0.033516,-119.609276,0.000017,0.000081,0.002046,-0.149086,-0.007595,0.020465,-119.609276,0.002853,0.000000
0.800000,0.026810,-119.564796,0.000099,0.000221,0.005602,0.119255,0.006075,0.056020,-119.564796,0.006686,0.000000
1.030000,0.034256,-119.653755,0.000259,0.000374,0.009487,0.152378,0.007763,0.094872,-119.653755,0.010519,0.000000
1.260000,0.052879,-119.653755,0.000397,0.000524,0.013303,0.235219,0.011983,0.133031,-119.653755,0.014352,0.000000
1.490000,0.032394,-119.653755,0.000556,0.000679,0.017240,0.144098,0.007341,0.172402,-119.653755,0.018186,0.000000
1.720000,-0.005959,-119.564796,0.000711,0.000827,0.020996,-0.026505,-0.001350,0.209956,-119.564796,0.022019,0.000000
1.950000,0.013031,-119.564796,0.000841,0.000973,0.024707,0.057965,0.002953,0.247070,-119.564796,0.025852,0.000000
2.180000,0.019363,-119.564796,0.001009,0.001126,0.028610,0.086133,0.004388,0.286096,-119.564796,0.029685,0.000000
2.410000,0.042076,-119.653755,0.001155,0.001276,0.032408,0.187164,0.009535,0.324082,-119.653755,0.033518,0.000000
2.640000,0.012291,-119.698242,0.001302,0.001424,0.036181,0.054673,0.002785,0.361806,-119.698242,0.037351,0.000000
2.870000,0.043571,-119.609276,0.001444,0.001576,0.040022,0.193816,0.009873,0.400222,-119.609276,0.041185,0.000000
3.100000,0.003723,-119.564796,0.001604,0.001725,0.043821,0.016561,0.000844,0.438208,-119.564796,0.045000,0.000000
3.330000,0.014153,-119.609276,0.001768,0.001883,0.047819,0.062954,0.003207,0.478187,-119.609276,0.048833,0.000000
3.560000,0.029419,-119.653755,0.001914,0.002033,0.051643,0.130862,0.006666,0.516430,-119.653755,0.052666,0.000000
3.790000,0.037979,-119.698242,0.002065,0.002183,0.055442,0.168940,0.008606,0.554415,-119.698242,0.056500,0.000000
4.020000,0.032028,-119.653755,0.002225,0.002336,0.059344,0.142469,0.007258,0.593441,-119.653755,0.060333,0.000000
4.250000,-0.009308,-119.653755,0.002380,0.002482,0.063039,-0.041403,-0.002109,0.630386,-119.653755,0.064166,0.000000
4.480000,-0.018990,-119.698242,0.002518,0.002626,0.066698,-0.084470,-0.004303,0.666982,-119.698242,0.067999,0.000000
4.710000,0.011917,-119.698242,0.002677,0.002786,0.070774,0.053010,0.002700,0.707741,-119.698242,0.071832,0.000000
4.940000,0.039841,-119.742722,0.002833,0.002934,0.074520,0.177220,0.009028,0.745204,-119.742722,0.075665,0.000000
5.170000,0.032028,-119.742722,0.002992,0.003088,0.078423,0.142469,0.007258,0.784230,-119.742722,0.079498,0.000000
5.400000,-0.002609,-119.653755,0.003139,0.003238,0.082248,-0.011607,-0.000591,0.822477,-119.653755,0.083332,0.000000
5.630000,0.028297,-119.742722,0.003294,0.003390,0.086107,0.125873,0.006412,0.861067,-119.742722,0.087165,0.000000
5.860000,0.036865,-119.742722,0.003454,0.003542,0.089975,0.163985,0.008354,0.899745,-119.742722,0.090981,0.000000
6.090000,0.041710,-119.787201,0.003591,0.003686,0.093617,0.185535,0.009452,0.936167,-119.787201,0.094814,0.000000
6.320000,0.022713,-119.742722,0.003742,0.003845,0.097658,0.101031,0.005147,0.976582,-119.742722,0.098647,0.000000
6.550000,0.010056,-119.742722,0.003906,0.003991,0.101361,0.044729,0.002279,1.013614,-119.742722,0.102480,0.000000
6.780000,-0.027557,-119.787201,0.004053,0.004136,0.105055,-0.122581,-0.006245,1.050554,-119.787201,0.106313,0.000000
7.010000,0.019737,-119.787201,0.004195,0.004291,0.108993,0.087796,0.004473,1.089929,-119.787201,0.110146,0.000000
7.240000,0.042076,-119.742722,0.004350,0.004441,0.112800,0.187164,0.009535,1.128001,-119.742722,0.113979,0.000000
7.470000,0.047661,-119.787201,0.004484,0.004592,0.116633,0.212006,0.010800,1.166331,-119.787201,0.117812,0.000000
7.700000,0.063675,-119.787201,0.004652,0.004748,0.120596,0.283240,0.014429,1.205962,-119.787201,0.121646,0.000000
7.930000,0.028671,-119.742722,0.004807,0.004897,0.124377,0.127536,0.006497,1.243773,-119.742722,0.125479,0.000000
8.160001,0.025322,-119.831680,0.004941,0.005046,0.128158,0.112638,0.005738,1.281584,-119.831680,0.129312,0.000000
8.390000,0.042076,-119.920647,0.005101,0.005201,0.132113,0.187164,0.009535,1.321129,-119.920647,0.133145,0.000000
8.620001,0.053993,-119.742722,0.005234,0.005346,0.135790,0.240174,0.012235,1.357899,-119.742722,0.136978,0.000000
8.850000,0.037613,-119.831680,0.005394,0.005500,0.139701,0.167311,0.008523,1.397012,-119.831680,0.140794,0.000000
9.080001,0.003723,-119.787201,0.005553,0.005649,0.143491,0.016561,0.000844,1.434910,-119.787201,0.144627,0.000000
9.310000,0.027931,-119.787201,0.005691,0.005797,0.147237,0.124244,0.006329,1.472373,-119.787201,0.148460,0.000000
9.540001,0.043571,-119.831680,0.005864,0.005954,0.151235,0.193816,0.009873,1.512353,-119.831680,0.152294,0.000000
9.770000,0.068520,-119.920647,0.006010,0.006104,0.155034,0.304790,0.015527,1.550338,-119.920647,0.156127,0.000000
10.000000,0.068146,-119.831680,0.006170,0.006260,0.159014,0.303127,0.015442,1.590144,-119.831680,0.159959,0.000000
10.230000,0.050270,-119.831680,0.006312,0.006406,0.162718,0.223612,0.011391,1.627176,-119.831680,0.163793,0.000000
10.460000,0.018616,-119.876160,0.006467,0.006555,0.166499,0.082807,0.004218,1.664987,-119.876160,0.167626,0.000000
10.690001,0.015266,-119.831680,0.006610,0.006704,0.170271,0.067908,0.003459,1.702711,-119.831680,0.171459,0.000000
10.920000,0.045799,-119.876160,0.006739,0.006855,0.174121,0.203725,0.010378,1.741214,-119.876160,0.175292,0.000000
11.150001,0.049522,-119.876160,0.006907,0.007006,0.177963,0.220287,0.011222,1.779631,-119.876160,0.179125,0.000000
11.380000,0.074844,-119.920647,0.007067,0.007154,0.181701,0.332924,0.016960,1.817011,-119.920647,0.182958,0.000000
11.610001,0.115807,-119.876160,0.007222,0.007308,0.185629,0.515133,0.026242,1.856294,-119.876160,0.186774,0.000000
11.840000,0.739159,-119.876160,0.007343,-0.000002,-0.000052,3.287942,0.167496,-0.000522,-119.876160,0.000095,0.000000
12.070001,0.693359,-119.920647,0.007343,-0.000002,-0.000061,3.084217,0.157117,-0.000609,-119.920647,0.000095,0.000000
12.300000,0.670647,-119.920647,0.007334,-0.000002,-0.000061,2.983185,0.151971,-0.000609,-119.920647,0.000113,0.000000
12.530001,0.663940,-119.965126,0.007338,-0.000002,-0.000061,2.953355,0.150451,-0.000609,-119.965126,0.000494,0.000000
12.760000,0.698196,-119.965126,0.007330,-0.000002,-0.000061,3.105733,0.158214,-0.000609,-119.965126,0.000876,0.000000
12.990001,0.666916,-119.920647,0.007330,-0.000002,-0.000061,2.966590,0.151125,-0.000609,-119.920647,0.001266,0.000000
13.220000,0.949547,-119.965126,0.007347,0.000029,0.000746,4.223795,0.215170,0.007456,-119.965126,0.001648,0.000000
13.450001,1.137970,-119.876160,0.007368,0.000048,0.001214,5.061943,0.257868,0.012138,-119.876160,0.002029,0.000000
13.680000,1.321175,-119.920647,0.007381,0.000062,0.001578,5.876878,0.299382,0.015783,-119.920647,0.002411,0.000000
13.910001,1.461189,-119.965126,0.007394,0.000075,0.001908,6.499694,0.331110,0.019076,-119.965126,0.002801,0.000000
14.140000,1.743820,-119.965126,0.007407,0.000097,0.002454,7.756900,0.395155,0.024541,-119.965126,0.003183,0.000000
14.370001,1.902824,-119.965126,0.007416,0.000111,0.002810,8.464186,0.431186,0.028095,-119.965126,0.003564,0.000000
14.600000,1.997406,-119.965126,0.007446,0.000120,0.003044,8.884906,0.452619,0.030438,-119.965126,0.003946,0.000000
14.830001,2.206306,-119.965126,0.007459,0.000138,0.003503,9.814141,0.499956,0.035033,-119.965126,0.004327,0.000000
15.060000,2.431969,-120.009605,0.007459,0.000154,0.003902,10.817937,0.551092,0.039022,-120.009605,0.004717,0.000000
15.290001,2.606232,-120.054085,0.007472,0.000168,0.004258,11.593098,0.590581,0.042580,-120.054085,0.005099,0.000000
15.520000,2.831894,-120.009605,0.007489,0.000184,0.004666,12.596893,0.641716,0.046656,-120.009605,0.005481,0.000000
15.750001,2.966316,-119.965126,0.007519,0.000196,0.004978,13.194834,0.672177,0.049779,-119.965126,0.005862,0.000000
15.980000,3.157349,-119.965126,0.007524,0.000212,0.005377,14.044588,0.715465,0.053768,-119.965126,0.006244,0.000000
16.210001,3.429176,-120.098564,0.007532,0.000231,0.005871,15.253738,0.777062,0.058711,-120.098564,0.006634,0.000000
16.440001,3.574402,-120.009605,0.007541,0.000245,0.006227,15.899734,0.809971,0.062265,-120.009605,0.007016,0.000000
16.670000,3.673080,-120.009605,0.007562,0.000255,0.006487,16.338678,0.832332,0.064866,-120.009605,0.007397,0.000000
16.900002,3.849586,-120.009605,0.007571,0.000272,0.006903,17.123816,0.872329,0.069029,-120.009605,0.007779,0.000000
17.130001,4.046944,-120.054085,0.007580,0.000286,0.007276,18.001705,0.917051,0.072761,-120.054085,0.008161,0.000000
17.360001,4.226425,-120.098564,0.007597,0.000300,0.007631,18.800077,0.957722,0.076315,-120.098564,0.008551,0.000000
17.590000,4.411125,-120.098564,0.007631,0.000318,0.008065,19.621664,0.999575,0.080652,-120.098564,0.008932,0.000000
17.820002,4.507942,-120.054085,0.007627,0.000331,0.008412,20.052328,1.021514,0.084119,-120.054085,0.009314,0.000000
18.050001,4.706047,-120.009605,0.007631,0.000347,0.008820,20.933542,1.066406,0.088196,-120.009605,0.009695,0.000000
18.280001,4.800995,-120.054085,0.007662,0.000361,0.009167,21.355892,1.087921,0.091666,-120.054085,0.010077,0.000000
18.510000,4.948830,-120.054085,0.007683,0.000378,0.009591,22.013494,1.121421,0.095913,-120.054085,0.010467,0.000000
18.740002,5.077301,-120.143051,0.007692,0.000393,0.009982,22.584963,1.150533,0.099815,-120.143051,0.010849,0.000000
18.970001,5.117889,-120.098564,0.007700,0.000405,0.010294,22.765509,1.159730,0.102938,-120.098564,0.011231,0.000000
19.200001,5.301468,-120.098564,0.007713,0.000422,0.010728,23.582108,1.201330,0.107275,-120.098564,0.011612,0.000000
19.430000,5.458237,-120.098564,0.007731,0.000439,0.011144,24.279449,1.236854,0.111439,-120.098564,0.011994,0.000000
19.660002,5.430679,-120.054085,0.007743,0.000449,0.011404,24.156868,1.230610,0.114039,-120.054085,0.012384,0.000000
19.890001,5.673096,-120.143051,0.007748,0.000469,0.011907,25.235189,1.285542,0.119069,-120.143051,0.012765,0.000000
20.120001,5.813850,-120.098564,0.007778,0.000488,0.012384,25.861298,1.317437,0.123838,-120.098564,0.013147,0.000000
20.350000,5.852577,-120.143051,0.007804,0.000501,0.012731,26.033564,1.326213,0.127309,-120.143051,0.013529,0.000000
20.580002,5.931892,-120.098564,0.007817,0.000516,0.013104,26.386375,1.344186,0.131037,-120.098564,0.013910,0.000000
20.810001,5.936363,-120.098564,0.007808,0.000526,0.013364,26.406263,1.345199,0.133637,-120.098564,0.014300,0.000000
21.040001,6.057755,-120.143051,0.007834,0.000542,0.013771,26.946238,1.372707,0.137713,-120.143051,0.014682,0.000000
21.270000,6.113235,-120.187531,0.007847,0.000555,0.014101,27.193029,1.385279,0.141010,-120.187531,0.015064,0.000000
21.500002,6.283417,-120.187531,0.007877,0.000573,0.014552,27.950033,1.423843,0.145518,-120.187531,0.015445,0.000000
21.730001,6.356026,-120.143051,0.007886,0.000586,0.014890,28.273014,1.440296,0.148902,-120.143051,0.015827,0.000000
21.960001,6.512047,-120.232010,0.007907,0.000607,0.015419,28.967031,1.475651,0.154193,-120.232010,0.016217,0.000000
22.190001,6.504227,-120.232010,0.007907,0.000620,0.015740,28.932245,1.473879,0.157399,-120.232010,0.016599,0.000000
22.420002,6.517265,-120.187531,0.007916,0.000631,0.016026,28.990244,1.476833,0.160264,-120.187531,0.016980,0.000000
22.650002,6.572746,-120.187531,0.007938,0.000646,0.016408,29.237036,1.489406,0.164079,-120.187531,0.017362,0.000000
22.880001,6.572746,-120.187531,0.007950,0.000658,0.016720,29.237036,1.489406,0.167202,-120.187531,0.017752,0.000000
23.110001,6.869156,-120.232010,0.007955,0.000678,0.017231,30.555531,1.556573,0.172315,-120.232010,0.018133,0.000000
23.340002,6.915703,-120.276489,0.007981,0.000693,0.017605,30.762583,1.567121,0.176047,-120.276489,0.018515,0.000000
23.570002,6.852402,-120.187531,0.007985,0.000703,0.017847,30.481005,1.552776,0.178473,-120.187531,0.018897,0.000000
23.800001,6.967461,-120.187531,0.008011,0.000719,0.018272,30.992813,1.578849,0.182723,-120.187531,0.019278,0.000000
24.030001,7.240784,-120.187531,0.008032,0.000743,0.018879,32.208614,1.640785,0.188794,-120.187531,0.019669,0.000000
24.260000,7.174126,-120.276489,0.008045,0.000756,0.019192,31.912106,1.625680,0.191917,-120.276489,0.020050,0.000000
24.490002,7.088486,-120.232010,0.008054,0.000765,0.019426,31.531158,1.606274,0.194256,-120.232010,0.020432,0.000000
24.720001,7.116409,-120.232010,0.008071,0.000779,0.019799,31.655369,1.612601,0.197988,-120.232010,0.020813,0.000000
24.950001,7.092209,-120.232010,0.008075,0.000788,0.020024,31.547720,1.607118,0.200240,-120.232010,0.021195,0.000000
25.180000,7.364037,-120.320976,0.008110,0.000807,0.020501,32.756870,1.668715,0.205013,-120.320976,0.021585,0.000000
25.410002,7.507774,-120.320976,0.008114,0.000825,0.020943,33.396248,1.701286,0.209433,-120.320976,0.021967,0.000000
25.640001,7.653000,-120.320976,0.008132,0.000842,0.021386,34.042244,1.734195,0.213858,-120.320976,0.022348,0.000000
25.870001,7.734177,-120.276489,0.008149,0.000858,0.021802,34.403336,1.752589,0.218018,-120.276489,0.022730,0.000000
26.100000,7.850357,-120.232010,0.008149,0.000878,0.022296,34.920132,1.778916,0.222964,-120.232010,0.023111,0.000000
26.330002,7.821312,-120.320976,0.008175,0.000890,0.022600,34.790932,1.772335,0.225996,-120.320976,0.023502,0.000000
26.560001,7.738647,-120.365456,0.008179,0.000902,0.022912,34.423222,1.753603,0.229119,-120.365456,0.023883,0.000000
26.790001,7.741249,-120.320976,0.008201,0.000914,0.023215,34.434795,1.754192,0.232154,-120.320976,0.024265,0.000000
27.020000,8.044739,-120.276489,0.008222,0.000935,0.023745,35.784786,1.822964,0.237445,-120.276489,0.024646,0.000000
27.250002,8.097610,-120.365456,0.008235,0.000949,0.024109,36.019970,1.834945,0.241086,-120.365456,0.025028,0.000000
27.480001,8.086441,-120.276489,0.008257,0.000961,0.024421,35.970287,1.832414,0.244209,-120.276489,0.025418,0.000000
27.710001,8.129265,-120.365456,0.008252,0.000975,0.024768,36.160774,1.842118,0.247680,-120.365456,0.025800,0.000000
27.940001,8.399605,-120.365456,0.008282,0.000996,0.025297,37.363308,1.903378,0.252967,-120.365456,0.026181,0.000000
28.170002,8.448387,-120.320976,0.008304,0.001012,0.025696,37.580303,1.914432,0.256957,-120.320976,0.026563,0.000000
28.400002,8.343002,-120.320976,0.008304,0.001023,0.025982,37.111526,1.890551,0.259818,-120.320976,0.026945,0.000000
28.630001,8.320663,-120.320976,0.008313,0.001035,0.026294,37.012161,1.885489,0.262940,-120.320976,0.027335,0.000000
28.860001,8.642395,-120.365456,0.008326,0.001055,0.026806,38.443295,1.958395,0.268058,-120.365456,0.027716,0.000000
29.090002,8.820015,-120.320976,0.008351,0.001072,0.027240,39.233387,1.998644,0.272395,-120.320976,0.028098,0.000000
29.320002,8.785385,-120.320976,0.008356,0.001085,0.027560,39.079346,1.990797,0.275605,-120.320976,0.028479,0.000000
29.550001,8.865074,-120.365456,0.008377,0.001099,0.027907,39.433819,2.008855,0.279072,-120.365456,0.028861,0.000000
29.780001,8.805122,-120.409935,0.008395,0.001111,0.028211,39.167141,1.995269,0.282107,-120.409935,0.029252,0.000000
30.010002,9.045670,-120.454414,0.008403,0.001129,0.028670,40.237148,2.049778,0.286702,-120.454414,0.029633,0.000000
30.240002,9.070992,-120.365456,0.008412,0.001142,0.029000,40.349785,2.055516,0.289999,-120.365456,0.030015,0.000000
30.470001,9.177116,-120.409935,0.008438,0.001156,0.029364,40.821854,2.079564,0.293640,-120.409935,0.030396,0.000000
30.700001,9.200211,-120.409935,0.008446,0.001170,0.029728,40.924580,2.084797,0.297285,-120.409935,0.030778,0.000000
30.930002,9.382294,-120.498894,0.008459,0.001187,0.030162,41.734528,2.126058,0.301618,-120.498894,0.031168,0.000000
31.160002,9.606094,-120.498894,0.008476,0.001207,0.030648,42.730042,2.176772,0.306478,-120.498894,0.031549,0.000000
31.390001,9.506668,-120.454414,0.008485,0.001216,0.030882,42.287773,2.154242,0.308817,-120.454414,0.031931,0.000000
31.620001,9.669769,-120.365456,0.008511,0.001234,0.031342,43.013283,2.191201,0.313416,-120.365456,0.032313,0.000000
31.850002,9.835472,-120.409935,0.008524,0.001250,0.031758,43.750366,2.228750,0.317575,-120.409935,0.032703,0.000000
32.080002,9.969902,-120.454414,0.008554,0.001267,0.032183,44.348339,2.259212,0.321826,-120.454414,0.033085,0.000000
32.310001,9.952400,-120.543381,0.008558,0.001281,0.032538,44.270489,2.255246,0.325384,-120.543381,0.033466,0.000000
32.540001,10.009369,-120.543381,0.008580,0.001294,0.032868,44.523895,2.268155,0.328676,-120.543381,0.033848,0.000000
32.770000,10.144547,-120.454414,0.008593,0.001310,0.033267,45.125198,2.298787,0.332666,-120.454414,0.034229,0.000000
33.000000,10.401482,-120.454414,0.008601,0.001329,0.033761,46.268101,2.357009,0.337609,-120.454414,0.034620,0.000000
33.230003,10.287910,-120.543381,0.008623,0.001339,0.034021,45.762913,2.331274,0.340213,-120.543381,0.035001,0.000000
33.460003,10.256256,-120.543381,0.008627,0.001350,0.034290,45.622105,2.324101,0.342900,-120.543381,0.035383,0.000000
33.690002,10.602562,-120.543381,0.008645,0.001371,0.034828,47.162552,2.402575,0.348278,-120.543381,0.035764,0.000000
33.920002,10.860619,-120.498894,0.008658,0.001391,0.035330,48.310444,2.461051,0.353305,-120.498894,0.036146,0.000000
34.150002,10.713531,-120.498894,0.008688,0.001401,0.035591,47.656170,2.427721,0.355909,-120.498894,0.036536,0.000000
34.380001,10.858383,-120.543381,0.008683,0.001417,0.035999,48.300499,2.460545,0.359985,-120.543381,0.036917,0.000000
34.610001,10.846092,-120.543381,0.008714,0.001430,0.036328,48.245827,2.457760,0.363278,-120.543381,0.037299,0.000000
34.840000,11.235596,-120.543381,0.008714,0.001451,0.036848,49.978424,2.546022,0.368482,-120.543381,0.037681,0.000000
35.070004,11.285492,-120.543381,0.008739,0.001466,0.037238,50.200375,2.557329,0.372384,-120.543381,0.038062,0.000000
35.300003,11.414337,-120.632339,0.008748,0.001482,0.037646,50.773506,2.586526,0.376461,-120.632339,0.038453,0.000000
35.530003,11.661591,-120.587860,0.008778,0.001500,0.038089,51.873344,2.642554,0.380885,-120.587860,0.038834,0.000000
35.760002,11.618767,-120.543381,0.008778,0.001513,0.038427,51.682858,2.632850,0.384265,-120.543381,0.039216,0.000000
35.990002,11.685417,-120.543381,0.008791,0.001527,0.038774,51.979332,2.647953,0.387736,-120.543381,0.039598,0.000000
36.220001,11.760269,-120.543381,0.008808,0.001540,0.039120,52.312290,2.664915,0.391203,-120.543381,0.039979,0.000000
36.450001,11.863785,-120.587860,0.008817,0.001555,0.039485,52.772751,2.688372,0.394848,-120.587860,0.040369,0.000000
36.680000,12.000450,-120.543381,0.008834,0.001571,0.039901,53.380669,2.719341,0.399011,-120.543381,0.040751,0.000000
36.910000,12.309517,-120.632339,0.008847,0.001590,0.040378,54.755466,2.789376,0.403780,-120.632339,0.041132,0.000000
37.140003,12.166153,-120.543381,0.008869,0.001600,0.040647,54.117752,2.756890,0.406467,-120.543381,0.041514,0.000000
37.370003,12.318451,-120.632339,0.008873,0.001615,0.041020,54.795208,2.791401,0.410196,-120.632339,0.041895,0.000000
37.600002,12.795837,-120.543381,0.008895,0.001636,0.041557,56.918728,2.899578,0.415574,-120.543381,0.042286,0.000000
37.830002,12.694550,-120.632339,0.008908,0.001647,0.041826,56.468178,2.876626,0.418261,-120.632339,0.042667,0.000000
38.060001,12.741844,-120.632339,0.008916,0.001661,0.042199,56.678555,2.887343,0.421989,-120.632339,0.043049,0.000000
38.290001,12.874405,-120.676819,0.008925,0.001673,0.042502,57.268211,2.917382,0.425025,-120.676819,0.043431,0.000000
38.520000,13.118683,-120.676819,0.008938,0.001689,0.042910,58.354816,2.972736,0.429101,-120.676819,0.043812,0.000000
38.750000,13.323486,-120.632339,0.008964,0.001705,0.043318,59.265827,3.019145,0.433177,-120.632339,0.044202,0.000000
38.980003,13.369286,-120.676819,0.008981,0.001718,0.043639,59.469551,3.029523,0.436387,-120.676819,0.044584,0.000000
39.210003,13.552498,-120.721298,0.008990,0.001735,0.044064,60.284523,3.071040,0.440637,-120.721298,0.044966,0.000000
39.440002,13.778152,-120.676819,0.008990,0.001750,0.044463,61.288284,3.122174,0.444627,-120.676819,0.045347,0.000000
39.670002,14.000832,-120.676819,0.009015,0.001768,0.044913,62.278809,3.172634,0.449135,-120.676819,0.045737,0.000000
39.900002,14.042542,-120.676819,0.009033,0.001782,0.045252,62.464344,3.182086,0.452518,-120.676819,0.046119,0.000000
40.130001,14.184410,-120.721298,0.009050,0.001795,0.045599,63.095406,3.214233,0.455985,-120.721298,0.046500,0.000000
40.360001,14.185532,-120.765785,0.009046,0.001808,0.045911,63.100395,3.214487,0.459108,-120.765785,0.046882,0.000000
40.590000,14.531090,-120.676819,0.009067,0.001823,0.046310,64.637512,3.292792,0.463097,-120.676819,0.047263,0.000000
40.820004,14.768661,-120.676819,0.009089,0.001840,0.046726,65.694290,3.346627,0.467260,-120.676819,0.047654,0.000000
41.050003,14.606682,-120.721298,0.009102,0.001848,0.046943,64.973763,3.309921,0.469429,-120.721298,0.048036,0.000000
41.280003,15.328339,-120.765785,0.009115,0.001874,0.047593,68.183853,3.473451,0.475932,-120.765785,0.048417,0.000000
41.510002,15.537987,-120.721298,0.009123,0.001890,0.048001,69.116417,3.520958,0.480008,-120.721298,0.048799,0.000000
41.740002,15.476547,-120.676819,0.009140,0.001901,0.048287,68.843117,3.507036,0.482869,-120.676819,0.049180,0.000000
41.970001,15.606133,-120.721298,0.009162,0.001917,0.048703,69.419548,3.536400,0.487033,-120.721298,0.049570,0.000000
42.200001,15.680977,-120.765785,0.009166,0.001930,0.049016,69.752472,3.553360,0.490155,-120.765785,0.049952,0.000000
42.430000,15.710770,-120.765785,0.009184,0.001941,0.049310,69.884995,3.560111,0.493104,-120.765785,0.050334,0.000000
42.660004,16.215706,-120.765785,0.009179,0.001961,0.049805,72.131065,3.674531,0.498047,-120.765785,0.050715,0.000000
42.890003,16.360931,-120.810265,0.009209,0.001974,0.050134,72.777054,3.707440,0.501343,-120.810265,0.051097,0.000000
43.120003,16.475990,-120.721298,0.009222,0.001987,0.050481,73.288864,3.733513,0.504810,-120.721298,0.051487,0.000000
43.350002,17.111633,-120.810265,0.009248,0.002010,0.051062,76.116348,3.877552,0.510620,-120.810265,0.051869,0.000000
43.580002,17.085564,-120.765785,0.009253,0.002022,0.051357,76.000381,3.871644,0.513569,-120.765785,0.052250,0.000000
43.810001,17.321648,-120.810265,0.009265,0.002039,0.051782,77.050537,3.925142,0.517819,-120.810265,0.052632,0.000000
44.040001,17.223343,-120.854744,0.009274,0.002048,0.052025,76.613258,3.902865,0.520249,-120.854744,0.053014,0.000000
44.270000,17.268402,-120.765785,0.009287,0.002061,0.052345,76.813690,3.913076,0.523455,-120.765785,0.053404,0.000000
44.500004,17.885048,-120.765785,0.009300,0.002080,0.052840,79.556664,4.052810,0.528398,-120.765785,0.053785,0.000000
44.730003,18.051498,-120.854744,0.009317,0.002094,0.053178,80.297073,4.090528,0.531782,-120.854744,0.054167,0.000000
44.960003,17.886169,-120.765785,0.009313,0.002102,0.053395,79.561653,4.053064,0.533950,-120.765785,0.054548,0.000000
45.190002,18.829018,-120.854744,0.009352,0.002128,0.054063,83.755653,4.266716,0.540627,-120.854744,0.054930,0.000000
45.420002,19.206970,-120.810265,0.009365,0.002145,0.054479,85.436867,4.352362,0.544790,-120.810265,0.055320,0.000000
45.650002,19.143295,-120.854744,0.009382,0.002156,0.054774,85.153633,4.337933,0.547739,-120.854744,0.055702,0.000000
45.880001,18.911308,-120.854744,0.009382,0.002167,0.055034,84.121704,4.285364,0.550339,-120.854744,0.056083,0.000000
46.110001,19.433746,-120.899223,0.009403,0.002184,0.055468,86.445618,4.403750,0.554676,-120.899223,0.056465,0.000000
46.340004,19.732391,-120.810265,0.009403,0.002198,0.055832,87.774063,4.471424,0.558317,-120.810265,0.056846,0.000000
46.570004,19.895119,-120.854744,0.009421,0.002211,0.056153,88.497910,4.508298,0.561527,-120.854744,0.057237,0.000000
46.800003,20.165085,-120.854744,0.009429,0.002225,0.056526,89.698776,4.569474,0.565255,-120.854744,0.057618,0.000000
47.030003,20.656616,-120.943703,0.009447,0.002243,0.056968,91.885216,4.680856,0.569680,-120.943703,0.058000,0.000000
47.260002,20.989143,-120.899223,0.009464,0.002259,0.057367,93.364372,4.756208,0.573669,-120.899223,0.058382,0.000000
47.490002,21.678032,-120.899223,0.009468,0.002280,0.057904,96.428703,4.912312,0.579044,-120.899223,0.058763,0.000000
47.720001,21.570045,-120.899223,0.009498,0.002290,0.058173,95.948357,4.887842,0.581735,-120.899223,0.059153,0.000000
47.950001,21.598351,-120.899223,0.009498,0.002303,0.058503,96.074265,4.894256,0.585027,-120.899223,0.059535,0.000000
48.180004,21.884331,-120.943703,0.009533,0.002319,0.058893,97.346367,4.959060,0.588933,-120.943703,0.059916,0.000000
48.410004,22.504333,-120.943703,0.009524,0.002336,0.059327,100.104279,5.099555,0.593267,-120.943703,0.060298,0.000000
48.640003,22.680832,-120.854744,0.009541,0.002348,0.059639,100.889381,5.139550,0.596390,-120.854744,0.060689,0.000000
48.870003,22.996605,-120.899223,0.009567,0.002364,0.060047,102.294006,5.211105,0.600466,-120.899223,0.061070,0.000000
49.100002,23.618469,-120.943703,0.009567,0.002381,0.060489,105.060196,5.352021,0.604891,-120.943703,0.061452,0.000000
49.330002,23.956581,-120.988190,0.009585,0.002398,0.060914,106.564194,5.428639,0.609137,-120.988190,0.061833,0.000000
49.560001,24.235863,-120.943703,0.009602,0.002413,0.061287,107.806503,5.491925,0.612865,-120.943703,0.062215,0.000000
49.790001,24.163994,-120.943703,0.009610,0.002423,0.061547,107.486816,5.475639,0.615469,-120.943703,0.062605,0.000000
50.020004,24.465614,-120.899223,0.009632,0.002437,0.061894,108.828491,5.543987,0.618936,-120.899223,0.062986,0.000000
50.250004,25.236427,-120.988190,0.009666,0.002457,0.062397,112.257233,5.718657,0.623966,-120.988190,0.063368,0.000000
50.480003,25.793869,-121.077148,0.009653,0.002474,0.062848,114.736862,5.844974,0.628478,-121.077148,0.063750,0.000000
50.710003,25.815468,-120.988190,0.009671,0.002485,0.063108,114.832939,5.849868,0.631078,-120.988190,0.064131,0.000000
50.940002,26.120064,-120.988190,0.009679,0.002500,0.063507,116.187843,5.918891,0.635068,-120.988190,0.064521,0.000000
51.170002,26.537125,-120.943703,0.009675,0.002514,0.063863,118.043022,6.013398,0.638625,-120.943703,0.064903,0.000000
51.400002,27.078552,-121.077148,0.009688,0.002531,0.064296,120.451416,6.136088,0.642959,-121.077148,0.065285,0.000000
51.630001,27.346664,-121.077148,0.009705,0.002546,0.064660,121.644035,6.196843,0.646604,-121.077148,0.065666,0.000000
51.860001,27.627434,-121.077148,0.009710,0.002558,0.064964,122.892960,6.260466,0.649639,-121.077148,0.066048,0.000000
52.090004,28.241104,-121.077148,0.009735,0.002576,0.065423,125.622704,6.399526,0.654234,-121.077148,0.066438,0.000000
52.320004,28.572136,-121.032669,0.009744,0.002590,0.065779,127.095207,6.474539,0.657788,-121.032669,0.066820,0.000000
52.550003,29.224167,-121.077148,0.009748,0.002606,0.066195,129.995590,6.622291,0.661952,-121.077148,0.067201,0.000000
52.780003,29.208893,-121.032669,0.009761,0.002618,0.066490,129.927643,6.618830,0.664900,-121.032669,0.067583,0.000000
53.010002,30.114136,-121.077148,0.009774,0.002637,0.066976,133.954361,6.823961,0.669756,-121.077148,0.067964,0.000000
53.240002,30.605293,-121.077148,0.009783,0.002653,0.067375,136.139145,6.935258,0.673745,-121.077148,0.068354,0.000000
53.470001,30.963142,-121.032669,0.009804,0.002666,0.067704,137.730942,7.016348,0.677042,-121.032669,0.068736,0.000000
53.700001,31.448341,-121.077148,0.009813,0.002683,0.068138,139.889206,7.126296,0.681379,-121.077148,0.069118,0.000000
53.930004,31.887741,-121.077148,0.009822,0.002697,0.068502,141.843750,7.225865,0.685021,-121.077148,0.069499,0.000000
54.160004,32.560249,-121.166107,0.009835,0.002716,0.068979,144.835220,7.378258,0.689790,-121.166107,0.069881,0.000000
54.390003,33.138916,-121.077148,0.009852,0.002731,0.069369,147.409256,7.509386,0.693692,-121.077148,0.070271,0.000000
54.620003,33.033165,-121.077148,0.009865,0.002740,0.069586,146.938858,7.485422,0.695861,-121.077148,0.070653,0.000000
54.850002,33.747002,-121.166107,0.009869,0.002757,0.070029,150.114166,7.647180,0.700285,-121.166107,0.071034,0.000000
55.080002,34.541641,-121.121628,0.009899,0.002776,0.070514,153.648895,7.827248,0.705141,-121.121628,0.071416,0.000000
55.310001,35.362724,-121.121628,0.009895,0.002793,0.070939,157.301254,8.013308,0.709388,-121.121628,0.071798,0.000000
55.540001,35.541092,-121.077148,0.009895,0.002805,0.071251,158.094666,8.053726,0.712510,-121.077148,0.072188,0.000000
55.770004,35.768608,-121.121628,0.009925,0.002818,0.071581,159.106720,8.105282,0.715807,-121.121628,0.072569,0.000000
56.000004,36.708107,-121.166107,0.009929,0.002839,0.072101,163.285812,8.318176,0.721011,-121.166107,0.072951,0.000000
56.230003,37.446892,-121.166107,0.009938,0.002854,0.072491,166.572098,8.485587,0.724913,-121.166107,0.073332,0.000000
56.460003,37.821503,-121.166107,0.009955,0.002866,0.072795,168.238449,8.570476,0.727949,-121.166107,0.073714,0.000000
56.690002,38.754662,-121.121628,0.009973,0.002886,0.073315,172.389343,8.781932,0.733153,-121.121628,0.074104,0.000000
56.920002,39.514305,-121.121628,0.009977,0.002903,0.073731,175.768402,8.954070,0.737313,-121.121628,0.074486,0.000000
57.150002,39.642029,-121.210594,0.009998,0.002912,0.073957,176.336548,8.983012,0.739568,-121.210594,0.074867,0.000000
57.380001,40.109726,-121.255074,0.009981,0.002927,0.074347,178.416977,9.088993,0.743471,-121.255074,0.075249,0.000000
57.610004,40.613174,-121.166107,0.010007,0.002943,0.074746,180.656418,9.203077,0.747460,-121.166107,0.075639,0.000000
57.840004,41.335579,-121.210594,0.010016,0.002957,0.075119,183.869843,9.366776,0.751188,-121.210594,0.076021,0.000000
58.070004,41.919456,-121.210594,0.010024,0.002972,0.075501,186.467056,9.499084,0.755007,-121.210594,0.076403,0.000000
58.300003,43.118126,-121.255074,0.010033,0.002992,0.075995,191.798996,9.770707,0.759950,-121.255074,0.076784,0.000000
58.530003,43.224251,-121.210594,0.010042,0.003000,0.076212,192.271072,9.794756,0.762115,-121.210594,0.077166,0.000000
58.760002,44.359985,-121.255074,0.010054,0.003022,0.076758,197.323074,10.052116,0.767581,-121.255074,0.077556,0.000000
58.990002,45.113297,-121.210594,0.010067,0.003037,0.077140,200.673965,10.222819,0.771396,-121.210594,0.077937,0.000000
59.220001,45.341187,-121.255074,0.010076,0.003047,0.077400,201.687668,10.274460,0.773996,-121.255074,0.078319,0.000000
59.450005,45.994705,-121.255074,0.010085,0.003063,0.077807,204.594666,10.422549,0.778072,-121.255074,0.078700,0.000000
59.680004,46.394630,-121.299553,0.010085,0.003074,0.078085,206.373627,10.513174,0.780850,-121.299553,0.079082,0.000000
59.910004,47.206032,-121.344032,0.010085,0.003092,0.078545,209.982910,10.697040,0.785445,-121.344032,0.079473,0.000000
60.140003,48.155952,-121.210594,0.010111,0.003109,0.078970,214.208374,10.912294,0.789696,-121.210594,0.079854,0.000000
60.370003,48.748772,-121.255074,0.010115,0.003120,0.079256,216.845367,11.046630,0.792557,-121.255074,0.080236,0.000000
60.600002,49.434677,-121.255074,0.010132,0.003135,0.079620,219.896423,11.202059,0.796198,-121.255074,0.080617,0.000000
60.830002,50.464661,-121.299553,0.010128,0.003153,0.080088,224.478027,11.435455,0.800880,-121.299553,0.080999,0.000000
61.060001,51.495758,-121.344032,0.010149,0.003170,0.080513,229.064575,11.669106,0.805130,-121.344032,0.081389,0.000000
61.290005,52.018570,-121.299553,0.010136,0.003184,0.080886,231.390152,11.787576,0.808859,-121.299553,0.081771,0.000000
61.520004,52.543991,-121.255074,0.010171,0.003196,0.081181,233.727341,11.906638,0.811807,-121.255074,0.082152,0.000000
61.750004,52.981529,-121.299553,0.010179,0.003208,0.081493,235.673615,12.005787,0.814930,-121.299553,0.082534,0.000000
61.980003,54.198067,-121.388512,0.010175,0.003226,0.081935,241.085037,12.281457,0.819354,-121.388512,0.082915,0.000000
62.210003,54.993080,-121.255074,0.010184,0.003239,0.082273,244.621445,12.461610,0.822734,-121.255074,0.083306,0.000000
62.440002,55.635796,-121.255074,0.010184,0.003255,0.082672,247.480377,12.607251,0.826723,-121.255074,0.083687,0.000000
62.670002,57.270515,-121.299553,0.010201,0.003276,0.083210,254.751968,12.977684,0.832102,-121.299553,0.084069,0.000000
62.900002,58.188042,-121.299553,0.010205,0.003291,0.083592,258.833344,13.185598,0.835917,-121.299553,0.084450,0.000000
63.130005,58.622971,-121.299553,0.010214,0.003304,0.083913,260.768005,13.284155,0.839126,-121.299553,0.084832,0.000000
63.360004,59.488365,-121.299553,0.010218,0.003318,0.084268,264.617462,13.480256,0.842680,-121.299553,0.085222,0.000000
63.590004,59.997398,-121.344032,0.010231,0.003329,0.084546,266.881744,13.595604,0.845459,-121.344032,0.085604,0.000000
63.820004,60.990883,-121.344032,0.010240,0.003346,0.084988,271.300995,13.820732,0.849879,-121.344032,0.085985,0.000000
64.050003,61.962036,-121.344032,0.010253,0.003361,0.085361,275.620911,14.040798,0.853607,-121.344032,0.086367,0.000000
64.280006,62.676613,-121.388512,0.010266,0.003373,0.085673,278.799500,14.202724,0.856730,-121.388512,0.086748,0.000000
64.510002,63.496582,-121.344032,0.010261,0.003388,0.086055,282.446899,14.388531,0.860545,-121.344032,0.087139,0.000000
64.740005,65.163696,-121.344032,0.010270,0.003409,0.086601,289.862610,14.766305,0.866010,-121.344032,0.087520,0.000000
64.970001,65.848862,-121.432999,0.010287,0.003422,0.086913,292.910370,14.921566,0.869133,-121.432999,0.087902,0.000000
65.200005,66.767868,-121.477478,0.010279,0.003440,0.087373,296.998322,15.129815,0.873728,-121.477478,0.088283,0.000000
65.430000,67.296265,-121.477478,0.010292,0.003449,0.087607,299.348724,15.249552,0.876071,-121.477478,0.088665,0.000000
65.660004,66.996887,-121.388512,0.010287,0.003443,0.087459,298.017029,15.181712,0.874595,-121.388512,0.087694,0.000000
65.889999,66.477417,-121.388512,0.010309,0.003443,0.087451,295.706329,15.063998,0.874508,-121.388512,0.087459,0.000000
66.120003,65.949768,-121.432999,0.010300,0.003442,0.087434,293.359222,14.944431,0.874337,-121.432999,0.087459,0.000000
66.350006,65.465683,-121.477478,0.010313,0.003442,0.087425,291.205902,14.834736,0.874250,-121.477478,0.087459,0.000000
66.580002,65.037079,-121.477478,0.010300,0.003442,0.087416,289.299377,14.737613,0.874163,-121.477478,0.087459,0.000000
66.810005,64.665451,-121.477478,0.010317,0.003441,0.087408,287.646301,14.653400,0.874076,-121.477478,0.087459,0.000000
67.040001,64.307983,-121.432999,0.010309,0.003441,0.087408,286.056183,14.572397,0.874076,-121.432999,0.087459,0.000000
67.270004,64.001144,-121.432999,0.010330,0.003441,0.087408,284.691315,14.502867,0.874076,-121.432999,0.087459,0.000000
67.500000,63.703613,-121.477478,0.010326,0.003441,0.087408,283.367828,14.435445,0.874076,-121.477478,0.087459,0.000000
67.730003,63.447052,-121.521957,0.010317,0.003441,0.087399,282.226593,14.377308,0.873989,-121.521957,0.087459,0.000000
67.960007,63.199051,-121.521957,0.010326,0.003441,0.087399,281.123413,14.321110,0.873989,-121.521957,0.087459,0.000000
68.190002,62.973022,-121.432999,0.010326,0.003441,0.087399,280.117981,14.269891,0.873989,-121.432999,0.087459,0.000000
68.420006,62.763008,-121.432999,0.010343,0.003441,0.087399,279.183807,14.222301,0.873989,-121.432999,0.087459,0.000000
68.650002,62.573471,-121.566437,0.010335,0.003441,0.087399,278.340698,14.179351,0.873989,-121.566437,0.087459,0.000000
68.880005,62.369408,-121.521957,0.010330,0.003441,0.087399,277.432983,14.133110,0.873989,-121.521957,0.087459,0.000000
69.110001,62.207428,-121.521957,0.010330,0.003441,0.087399,276.712463,14.096405,0.873989,-121.521957,0.087459,0.000000
69.340004,62.042465,-121.521957,0.010330,0.003441,0.087399,275.978668,14.059024,0.873989,-121.521957,0.087459,0.000000
69.570000,61.885323,-121.521957,0.010322,0.003441,0.087399,275.279663,14.023415,0.873989,-121.521957,0.087459,0.000000
69.800003,61.731163,-121.566437,0.010339,0.003441,0.087399,274.593933,13.988482,0.873989,-121.566437,0.087459,0.000000
70.030006,61.581093,-121.610924,0.010335,0.003441,0.087399,273.926392,13.954475,0.873989,-121.610924,0.087459,0.000000
70.260002,61.445923,-121.566437,0.010339,0.003441,0.087399,273.325104,13.923845,0.873989,-121.566437,0.087459,0.000000
70.490005,61.336075,-121.566437,0.010348,0.003441,0.087399,272.836487,13.898953,0.873989,-121.566437,0.087459,0.000000
70.720001,61.204254,-121.566437,0.010339,0.003441,0.087390,272.250122,13.869082,0.873902,-121.566437,0.087459,0.000000
70.950005,61.087700,-121.610924,0.010339,0.003441,0.087390,271.731659,13.842670,0.873902,-121.610924,0.087459,0.000000
71.180000,60.975616,-121.610924,0.010348,0.003441,0.087390,271.233093,13.817272,0.873902,-121.610924,0.087459,0.000000
71.410004,60.876564,-121.566437,0.010339,0.003441,0.087390,270.792480,13.794827,0.873902,-121.566437,0.087459,0.000000
71.640007,60.770065,-121.610924,0.010352,0.003441,0.087390,270.318756,13.770694,0.873902,-121.610924,0.087459,0.000000
71.870003,60.665436,-121.566437,0.010352,0.003441,0.087390,269.853333,13.746984,0.873902,-121.566437,0.087459,0.000000
72.100006,60.573082,-121.610924,0.010352,0.003441,0.087390,269.442535,13.726057,0.873902,-121.610924,0.087459,0.000000
72.330002,60.475891,-121.610924,0.010348,0.003441,0.087390,269.010193,13.704033,0.873902,-121.610924,0.087459,0.000000
72.560005,60.384666,-121.566437,0.010348,0.003441,0.087390,268.604401,13.683361,0.873902,-121.566437,0.087459,0.000000
72.790001,60.289711,-121.566437,0.010335,0.003441,0.087390,268.182037,13.661844,0.873902,-121.566437,0.087459,0.000000
73.020004,60.209648,-121.655403,0.010352,0.003441,0.087390,267.825897,13.643701,0.873902,-121.655403,0.087459,0.000000
73.250000,60.137039,-121.699883,0.010348,0.003441,0.087390,267.502899,13.627248,0.873902,-121.699883,0.087459,0.000000
73.480003,60.056976,-121.699883,0.010339,0.003441,0.087390,267.146759,13.609105,0.873902,-121.699883,0.087459,0.000000
73.710007,59.979149,-121.610924,0.010343,0.003441,0.087390,266.800568,13.591469,0.873902,-121.610924,0.087459,0.000000
73.940002,59.891640,-121.655403,0.010352,0.003441,0.087390,266.411316,13.571639,0.873902,-121.655403,0.087459,0.000000
74.170006,59.829826,-121.699883,0.010356,0.003441,0.087390,266.136353,13.557632,0.873902,-121.699883,0.087459,0.000000
74.400002,59.763916,-121.699883,0.010335,0.003441,0.087390,265.843170,13.542697,0.873902,-121.699883,0.087459,0.000000
74.630005,59.698753,-121.699883,0.010348,0.003441,0.087390,265.553314,13.527931,0.873902,-121.699883,0.087459,0.000000
74.860001,59.613106,-121.699883,0.010348,0.003441,0.087390,265.172333,13.508523,0.873902,-121.699883,0.087459,0.000000
75.090004,59.556511,-121.655403,0.010348,0.003441,0.087390,264.920593,13.495698,0.873902,-121.655403,0.087459,0.000000
75.320007,59.499908,-121.655403,0.010348,0.003441,0.087390,264.668823,13.482872,0.873902,-121.655403,0.087459,0.000000
75.550003,59.436600,-121.744362,0.010352,0.003441,0.087390,264.387207,13.468526,0.873902,-121.744362,0.087459,0.000000
75.780006,59.371811,-121.744362,0.010352,0.003441,0.087390,264.098999,13.453845,0.873902,-121.744362,0.087459,0.000000
76.010002,59.304787,-121.744362,0.010352,0.003441,0.087390,263.800873,13.438657,0.873902,-121.744362,0.087459,0.000000
76.240005,59.266800,-121.744362,0.010361,0.003441,0.087390,263.631897,13.430049,0.873902,-121.744362,0.087459,0.000000
76.470001,59.206474,-121.788841,0.010361,0.003441,0.087390,263.363556,13.416378,0.873902,-121.788841,0.087459,0.000000
76.700005,59.142426,-121.744362,0.010361,0.003441,0.087390,263.078644,13.401865,0.873902,-121.744362,0.087459,0.000000
76.930000,59.088432,-121.744362,0.010369,0.003441,0.087390,262.838470,13.389630,0.873902,-121.744362,0.087459,0.000000
77.160004,59.031090,-121.744362,0.010356,0.003441,0.087390,262.583405,13.376636,0.873902,-121.744362,0.087459,0.000000
77.390007,58.994225,-121.744362,0.010356,0.003441,0.087390,262.419403,13.368282,0.873902,-121.744362,0.087459,0.000000
77.620003,58.950661,-121.699883,0.010348,0.003441,0.087390,262.225647,13.358411,0.873902,-121.699883,0.087459,0.000000
77.850006,58.889587,-121.788841,0.010356,0.003441,0.087390,261.953979,13.344571,0.873902,-121.788841,0.087459,0.000000
78.080002,58.835220,-121.788841,0.010356,0.003441,0.087390,261.712128,13.332252,0.873902,-121.788841,0.087459,0.000000
78.310005,58.800217,-121.877808,0.010352,0.003441,0.087390,261.556427,13.324320,0.873902,-121.877808,0.087459,0.000000
78.540001,58.763725,-121.744362,0.010365,0.003441,0.087390,261.394104,13.316051,0.873902,-121.744362,0.087459,0.000000
78.770004,58.721275,-121.788841,0.010365,0.003441,0.087390,261.205292,13.306432,0.873902,-121.788841,0.087459,0.000000
79.000000,58.675850,-121.833328,0.010352,0.003441,0.087390,261.003204,13.296138,0.873902,-121.833328,0.087459,0.000000
79.230003,58.622223,-121.877808,0.010348,0.003441,0.087390,260.764679,13.283985,0.873902,-121.877808,0.087459,0.000000
79.460007,58.580147,-121.833328,0.010365,0.003441,0.087390,260.577515,13.274451,0.873902,-121.833328,0.087459,0.000000
79.690002,58.545517,-121.788841,0.010348,0.003441,0.087390,260.423462,13.266603,0.873902,-121.788841,0.087459,0.000000
79.920006,58.510513,-121.788841,0.010365,0.003441,0.087390,260.267761,13.258672,0.873902,-121.788841,0.087459,0.000000
80.150002,58.455772,-121.833328,0.010365,0.003441,0.087390,260.024261,13.246267,0.873902,-121.833328,0.087459,0.000000
80.380005,58.418907,-121.877808,0.010352,0.003441,0.087390,259.860291,13.237913,0.873902,-121.877808,0.087459,0.000000
80.610001,58.384277,-121.922287,0.010361,0.003441,0.087390,259.706238,13.230066,0.873902,-121.922287,0.087459,0.000000
80.840004,58.352631,-121.833328,0.010356,0.003441,0.087390,259.565460,13.222895,0.873902,-121.833328,0.087459,0.000000
81.070007,58.310547,-121.788841,0.010361,0.003441,0.087390,259.378265,13.213359,0.873902,-121.788841,0.087459,0.000000
81.300003,58.250595,-121.922287,0.010374,0.003441,0.087390,259.111603,13.199774,0.873902,-121.922287,0.087459,0.000000
81.530006,58.228996,-121.922287,0.010361,0.003441,0.087390,259.015503,13.194879,0.873902,-121.922287,0.087459,0.000000
81.760002,58.204796,-121.966766,0.010352,0.003441,0.087390,258.907867,13.189396,0.873902,-121.966766,0.087459,0.000000
81.990005,58.165321,-121.877808,0.010361,0.003441,0.087390,258.732269,13.180450,0.873902,-121.877808,0.087459,0.000000
82.220001,58.123993,-121.922287,0.010369,0.003441,0.087390,258.548431,13.171085,0.873902,-121.922287,0.087459,0.000000
82.450005,58.102020,-121.922287,0.010374,0.003441,0.087390,258.450684,13.166105,0.873902,-121.922287,0.087459,0.000000
82.680000,58.067390,-121.877808,0.010374,0.003441,0.087390,258.296661,13.158259,0.873902,-121.877808,0.087459,0.000000
82.910004,58.032013,-121.877808,0.010361,0.003441,0.087390,258.139282,13.150242,0.873902,-121.877808,0.087459,0.000000
83.140007,58.006691,-121.922287,0.010369,0.003441,0.087390,258.026642,13.144504,0.873902,-121.922287,0.087459,0.000000
83.370003,57.971687,-121.833328,0.010365,0.003441,0.087390,257.870941,13.136572,0.873902,-121.833328,0.087459,0.000000
83.600006,57.932594,-121.966766,0.010369,0.003441,0.087390,257.697052,13.127714,0.873902,-121.966766,0.087459,0.000000
83.830002,57.917320,-121.966766,0.010365,0.003441,0.087390,257.629120,13.124252,0.873902,-121.966766,0.087459,0.000000
84.060005,57.887161,-121.966766,0.010369,0.003441,0.087390,257.494965,13.117418,0.873902,-121.966766,0.087459,0.000000
84.290001,57.849922,-122.011246,0.010356,0.003441,0.087390,257.329315,13.108980,0.873902,-122.011246,0.087459,0.000000
84.520004,57.818642,-121.922287,0.010378,0.003441,0.087390,257.190155,13.101892,0.873902,-121.922287,0.087459,0.000000
84.750008,57.786621,-121.966766,0.010365,0.003441,0.087390,257.047729,13.094636,0.873902,-121.966766,0.087459,0.000000
84.980003,57.762047,-121.922287,0.010378,0.003441,0.087390,256.938416,13.089067,0.873902,-121.922287,0.087459,0.000000
85.210007,57.736351,-122.055733,0.010378,0.003441,0.087390,256.824127,13.083244,0.873902,-122.055733,0.087459,0.000000
85.440002,57.722198,-121.922287,0.010365,0.003441,0.087390,256.761169,13.080037,0.873902,-121.922287,0.087459,0.000000
85.670006,57.680870,-121.922287,0.010361,0.003441,0.087390,256.577332,13.070671,0.873902,-121.922287,0.087459,0.000000
85.900002,57.657784,-122.055733,0.010369,0.003441,0.087390,256.474640,13.065440,0.873902,-122.055733,0.087459,0.000000
86.130005,57.612724,-122.055733,0.010378,0.003441,0.087390,256.274200,13.055230,0.873902,-122.055733,0.087459,0.000000
86.360001,57.602669,-122.100212,0.010369,0.003441,0.087390,256.229462,13.052952,0.873902,-122.100212,0.087459,0.000000
86.590004,57.588150,-122.011246,0.010365,0.003441,0.087390,256.164886,13.049662,0.873902,-122.011246,0.087459,0.000000
86.820007,57.549423,-122.011246,0.010369,0.003441,0.087390,255.992615,13.040885,0.873902,-122.011246,0.087459,0.000000
87.050003,57.512184,-122.011246,0.010374,0.003441,0.087390,255.826965,13.032447,0.873902,-122.011246,0.087459,0.000000
87.280006,57.498032,-122.011246,0.010382,0.003441,0.087390,255.764023,13.029241,0.873902,-122.011246,0.087459,0.000000
87.510002,57.477921,-122.055733,0.010356,0.003441,0.087390,255.674561,13.024683,0.873902,-122.055733,0.087459,0.000000
87.740005,57.452972,-122.055733,0.010356,0.003441,0.087390,255.563583,13.019030,0.873902,-122.055733,0.087459,0.000000
87.970001,57.433983,-122.011246,0.010356,0.003441,0.087390,255.479111,13.014727,0.873902,-122.011246,0.087459,0.000000
88.200005,57.402336,-122.055733,0.010369,0.003441,0.087390,255.338348,13.007556,0.873902,-122.055733,0.087459,0.000000
88.430008,57.372543,-122.100212,0.010369,0.003441,0.087390,255.205826,13.000804,0.873902,-122.100212,0.087459,0.000000
88.660004,57.349083,-122.100212,0.010378,0.003441,0.087390,255.101456,12.995488,0.873902,-122.100212,0.087459,0.000000
88.890007,57.341637,-122.055733,0.010365,0.003441,0.087390,255.068344,12.993801,0.873902,-122.055733,0.087459,0.000000
89.120003,57.327484,-122.100212,0.010374,0.003441,0.087390,255.005386,12.990594,0.873902,-122.100212,0.087459,0.000000
89.350006,57.296204,-122.055733,0.010369,0.003441,0.087390,254.866241,12.983505,0.873902,-122.055733,0.087459,0.000000
89.580002,57.263809,-122.055733,0.010378,0.003441,0.087390,254.722153,12.976165,0.873902,-122.055733,0.087459,0.000000
89.810005,57.233276,-122.100212,0.010374,0.003441,0.087390,254.586334,12.969246,0.873902,-122.100212,0.087459,0.000000
90.040001,57.228806,-122.100212,0.010361,0.003441,0.087390,254.566437,12.968232,0.873902,-122.100212,0.087459,0.000000
90.270004,57.213539,-122.144691,0.010365,0.003441,0.087390,254.498535,12.964774,0.873902,-122.144691,0.087459,0.000000
90.500008,57.185242,-122.144691,0.010378,0.003441,0.087390,254.372665,12.958361,0.873902,-122.144691,0.087459,0.000000
90.730003,57.161407,-122.144691,0.010369,0.003441,0.087390,254.266632,12.952960,0.873902,-122.144691,0.087459,0.000000
90.960007,57.130501,-122.100212,0.010374,0.003441,0.087390,254.129166,12.945957,0.873902,-122.100212,0.087459,0.000000
91.190002,57.114487,-122.189171,0.010369,0.003441,0.087390,254.057922,12.942327,0.873902,-122.189171,0.087459,0.000000
91.420006,57.095123,-122.144691,0.010365,0.003441,0.087390,253.971786,12.937940,0.873902,-122.144691,0.087459,0.000000
91.650002,57.081718,-122.100212,0.010378,0.003441,0.087390,253.912170,12.934902,0.873902,-122.100212,0.087459,0.000000
91.880005,57.062729,-122.189171,0.010369,0.003441,0.087390,253.827698,12.930599,0.873902,-122.189171,0.087459,0.000000
92.110001,57.045975,-122.189171,0.010382,0.003441,0.087390,253.753174,12.926803,0.873902,-122.189171,0.087459,0.000000
92.340004,57.016556,-122.233650,0.010378,0.003441,0.087390,253.622314,12.920136,0.873902,-122.233650,0.087459,0.000000
92.570007,56.993095,-122.189171,0.010365,0.003441,0.087390,253.517944,12.914820,0.873902,-122.189171,0.087459,0.000000
92.800003,56.982300,-122.233650,0.010356,0.003441,0.087390,253.469925,12.912374,0.873902,-122.233650,0.087459,0.000000
93.030006,56.971497,-122.189171,0.010378,0.003441,0.087390,253.421875,12.909925,0.873902,-122.189171,0.087459,0.000000
93.260002,56.940964,-122.189171,0.010382,0.003441,0.087390,253.286057,12.903007,0.873902,-122.189171,0.087459,0.000000
93.490005,56.918991,-122.233650,0.010374,0.003441,0.087390,253.188324,12.898027,0.873902,-122.233650,0.087459,0.000000
93.720001,56.899628,-122.233650,0.010378,0.003441,0.087390,253.102188,12.893640,0.873902,-122.233650,0.087459,0.000000
93.950005,56.888458,-122.189171,0.010369,0.003441,0.087390,253.052505,12.891109,0.873902,-122.189171,0.087459,0.000000
94.180008,56.872078,-122.233650,0.010378,0.003441,0.087390,252.979645,12.887398,0.873902,-122.233650,0.087459,0.000000
94.410004,56.851967,-122.189171,0.010374,0.003441,0.087390,252.890182,12.882840,0.873902,-122.189171,0.087459,0.000000
94.640007,56.837440,-122.278137,0.010382,0.003441,0.087390,252.825562,12.879548,0.873902,-122.278137,0.087459,0.000000
94.870003,56.811378,-122.278137,0.010369,0.003441,0.087390,252.709625,12.873643,0.873902,-122.278137,0.087459,0.000000
95.100006,56.789780,-122.278137,0.010365,0.003441,0.087390,252.613556,12.868748,0.873902,-122.278137,0.087459,0.000000
95.330002,56.774887,-122.322617,0.010378,0.003441,0.087390,252.547318,12.865374,0.873902,-122.322617,0.087459,0.000000
95.560005,56.754776,-122.278137,0.010378,0.003441,0.087390,252.457855,12.860816,0.873902,-122.278137,0.087459,0.000000
95.790001,56.733551,-122.322617,0.010378,0.003441,0.087390,252.363434,12.856007,0.873902,-122.322617,0.087459,0.000000
95.900002,56.725731,-122.278137,0.010374,0.003441,0.087390,252.328659,12.854234,0.873902,-122.278137,0.087459,0.000000