File: Data/compression 4 4 days/AutoNoheating-15-4-2-240226_02262024_162808.csv
Time (sec),S:Load (lbs),S:HL1 (DIM),S:LVDT (in),S:Position (in),Ch:Position (mm),Ch:Load (N),Ch:Stress (MPa),Ch:Strain (mm/mm),Ch:HL1 (DIM),Set Point (),Cycles ()
0.110000,-0.017502,-114.405006,-0.000004,-0.000000,-0.000000,-0.077852,-0.003966,-0.000000,-114.405006,0.000139,0.000000
0.330000,-0.017502,-114.449486,0.000022,-0.000000,-0.000000,-0.077852,-0.003966,-0.000000,-114.449486,0.000139,0.000000
0.550000,-0.018990,-114.449486,-0.000004,0.000070,0.001769,-0.084470,-0.004303,0.017691,-114.449486,0.002359,0.000000
0.770000,-0.018990,-114.493965,0.000017,0.000196,0.004969,-0.084470,-0.004303,0.049692,-114.493965,0.006036,0.000000
0.990000,-0.001114,-114.449486,0.000151,0.000336,0.008542,-0.004955,-0.000252,0.085421,-114.449486,0.009695,0.000000
1.210000,-0.016006,-114.449486,0.000285,0.000483,0.012280,-0.071200,-0.003627,0.122797,-114.449486,0.013355,0.000000
1.430000,0.004845,-114.405006,0.000444,0.000628,0.015957,0.021550,0.001098,0.159567,-114.405006,0.017032,0.000000
1.650000,-0.023460,-114.449486,0.000595,0.000771,0.019591,-0.104357,-0.005316,0.195906,-114.449486,0.020692,0.000000
1.870000,-0.030907,-114.493965,0.000742,0.000915,0.023242,-0.137480,-0.007004,0.232415,-114.493965,0.024352,0.000000
2.090000,0.003723,-114.449486,0.000884,0.001060,0.026927,0.016561,0.000844,0.269273,-114.449486,0.028029,0.000000
2.310000,0.011917,-114.493965,0.001048,0.001207,0.030665,0.053010,0.002700,0.306648,-114.493965,0.031688,0.000000
2.530000,-0.005959,-114.493965,0.001160,0.001341,0.034073,-0.026505,-0.001350,0.340731,-114.493965,0.035348,0.000000
2.750000,-0.011543,-114.493965,0.001337,0.001489,0.037819,-0.051347,-0.002616,0.378194,-114.493965,0.039025,0.000000
2.970000,-0.017868,-114.493965,0.001479,0.001639,0.041618,-0.079481,-0.004049,0.416179,-114.493965,0.042685,0.000000
3.190000,-0.029785,-114.538452,0.001621,0.001780,0.045208,-0.132491,-0.006749,0.452083,-114.538452,0.046345,0.000000
3.410000,-0.054733,-114.582932,0.001759,0.001924,0.048859,-0.243466,-0.012403,0.488592,-114.582932,0.050022,0.000000
3.630000,-0.016006,-114.582932,0.001893,0.002066,0.052484,-0.071200,-0.003627,0.524844,-114.582932,0.053681,0.000000
3.850000,0.007080,-114.627411,0.002031,0.002213,0.056205,0.031494,0.001604,0.562046,-114.627411,0.057341,0.000000
4.070000,0.008568,-114.538452,0.002203,0.002359,0.059908,0.038112,0.001941,0.599077,-114.538452,0.061000,0.000000
4.290000,0.016014,-114.538452,0.002324,0.002502,0.063542,0.071234,0.003629,0.635416,-114.538452,0.064677,0.000000
4.510000,0.015266,-114.538452,0.002471,0.002647,0.067227,0.067908,0.003459,0.672273,-114.538452,0.068337,0.000000
4.730000,-0.002235,-114.582932,0.002621,0.002795,0.070991,-0.009944,-0.000507,0.709910,-114.582932,0.071997,0.000000
4.950000,-0.018990,-114.582932,0.002751,0.002935,0.074538,-0.084470,-0.004303,0.745378,-114.582932,0.075674,0.000000
5.170000,-0.043938,-114.582932,0.002889,0.003073,0.078059,-0.195445,-0.009956,0.780589,-114.582932,0.079334,0.000000
5.390000,-0.061066,-114.538452,0.003031,0.003219,0.081762,-0.271634,-0.013838,0.817617,-114.538452,0.082993,0.000000
5.610000,0.028671,-114.627411,0.003186,0.003366,0.085491,0.127536,0.006497,0.854909,-114.627411,0.086670,0.000000
5.830000,0.032768,-114.538452,0.003324,0.003508,0.089099,0.145760,0.007425,0.890987,-114.538452,0.090330,0.000000
6.050000,0.030533,-114.627411,0.003471,0.003654,0.092801,0.135817,0.006919,0.928015,-114.627411,0.093990,0.000000
6.270000,0.034630,-114.627411,0.003639,0.003802,0.096583,0.154041,0.007847,0.965826,-114.627411,0.097667,0.000000
6.490000,0.008194,-114.538452,0.003764,0.003945,0.100190,0.036449,0.001857,1.001903,-114.538452,0.101327,0.000000
6.710001,-0.014893,-114.627411,0.003919,0.004090,0.103876,-0.066245,-0.003375,1.038761,-114.627411,0.104986,0.000000
6.930000,-0.009308,-114.671890,0.004057,0.004230,0.107449,-0.041403,-0.002109,1.074490,-114.671890,0.108663,0.000000
7.150001,-0.002975,-114.627411,0.004204,0.004373,0.111083,-0.013236,-0.000674,1.110829,-114.627411,0.112323,0.000000
7.370000,0.017128,-114.627411,0.004359,0.004521,0.114838,0.076189,0.003881,1.148379,-114.627411,0.115982,0.000000
7.590000,0.023460,-114.627411,0.004488,0.004663,0.118437,0.104357,0.005316,1.184369,-114.627411,0.119659,0.000000
7.810000,0.031654,-114.627411,0.004622,0.004807,0.122088,0.140806,0.007173,1.220878,-114.627411,0.123319,0.000000
8.030001,0.183952,-114.671890,0.004764,0.004955,0.125869,0.818261,0.041684,1.258690,-114.671890,0.126979,0.000000
8.250000,0.733200,-114.627411,0.004889,-0.000009,-0.000217,3.261437,0.166146,-0.002169,-114.627411,-0.000052,0.000000
8.470000,0.688889,-114.627411,0.004894,-0.000009,-0.000226,3.064329,0.156104,-0.002256,-114.627411,-0.000052,0.000000
8.690001,0.673248,-114.671890,0.004889,-0.000009,-0.000226,2.994758,0.152560,-0.002256,-114.671890,-0.000052,0.000000
8.910001,0.658730,-114.716370,0.004902,-0.000009,-0.000226,2.930175,0.149270,-0.002256,-114.716370,0.000243,0.000000
9.130000,0.653519,-114.671890,0.004889,-0.000009,-0.000217,2.906996,0.148089,-0.002169,-114.671890,0.000615,0.000000
9.350000,0.751450,-114.716370,0.004898,0.000006,0.000156,3.342615,0.170281,0.001559,-114.716370,0.000980,0.000000
9.570001,0.913803,-114.671890,0.004902,0.000021,0.000537,4.064799,0.207071,0.005375,-114.671890,0.001344,0.000000
9.790001,1.018440,-114.671890,0.004919,0.000033,0.000832,4.530249,0.230782,0.008323,-114.671890,0.001708,0.000000
10.010000,1.153984,-114.716370,0.004932,0.000046,0.001162,5.133177,0.261497,0.011620,-114.716370,0.002081,0.000000
10.230000,1.325279,-114.716370,0.004928,0.000062,0.001578,5.895136,0.300313,0.015783,-114.716370,0.002445,0.000000
10.450001,1.513695,-114.716370,0.004954,0.000078,0.001969,6.733251,0.343008,0.019685,-114.716370,0.002810,0.000000
10.670000,1.633972,-114.671890,0.004971,0.000089,0.002263,7.268271,0.370263,0.022634,-114.671890,0.003183,0.000000
10.890000,1.890167,-114.716370,0.004971,0.000108,0.002732,8.407884,0.428318,0.027316,-114.716370,0.003547,0.000000
11.110001,2.082306,-114.671890,0.004984,0.000124,0.003139,9.262559,0.471857,0.031392,-114.671890,0.003911,0.000000
11.330001,2.217850,-114.760857,0.004997,0.000137,0.003469,9.865488,0.502572,0.034689,-114.760857,0.004275,0.000000
11.550000,2.370895,-114.716370,0.005019,0.000149,0.003772,10.546269,0.537253,0.037724,-114.716370,0.004648,0.000000
11.770000,2.519104,-114.671890,0.005040,0.000163,0.004137,11.205534,0.570837,0.041365,-114.671890,0.005012,0.000000
11.990001,2.736938,-114.760857,0.005053,0.000178,0.004509,12.174510,0.620199,0.045093,-114.760857,0.005376,0.000000
12.210001,2.875465,-114.760857,0.005057,0.000189,0.004813,12.790709,0.651590,0.048129,-114.760857,0.005750,0.000000
12.430000,3.130539,-114.760857,0.005062,0.000208,0.005281,13.925333,0.709390,0.052811,-114.760857,0.006114,0.000000
12.650001,3.253792,-114.849815,0.005088,0.000218,0.005541,14.473589,0.737320,0.055415,-114.849815,0.006478,0.000000
12.870001,3.369225,-114.805336,0.005083,0.000232,0.005888,14.987060,0.763477,0.058882,-114.805336,0.006842,0.000000
13.090000,3.641060,-114.760857,0.005088,0.000250,0.006348,16.196243,0.825076,0.063480,-114.760857,0.007215,0.000000
13.310000,3.853310,-114.805336,0.005131,0.000266,0.006764,17.140377,0.873172,0.067644,-114.805336,0.007579,0.000000
13.530001,3.946777,-114.805336,0.005139,0.000278,0.007068,17.556143,0.894352,0.070675,-114.805336,0.007944,0.000000
13.750001,4.106155,-114.805336,0.005139,0.000292,0.007423,18.265091,0.930468,0.074233,-114.805336,0.008317,0.000000
13.970000,4.162384,-114.805336,0.005157,0.000302,0.007683,18.515209,0.943210,0.076833,-114.805336,0.008681,0.000000
14.190001,4.427879,-114.849815,0.005174,0.000321,0.008152,19.696192,1.003372,0.081519,-114.849815,0.009045,0.000000
14.410001,4.609230,-114.849815,0.005187,0.000337,0.008551,20.502880,1.044466,0.085508,-114.849815,0.009409,0.000000
14.630001,4.645721,-114.849815,0.005195,0.000346,0.008793,20.665201,1.052735,0.087934,-114.849815,0.009782,0.000000
14.850000,4.860207,-114.805336,0.005213,0.000363,0.009227,21.619278,1.101339,0.092272,-114.805336,0.010146,0.000000
15.070001,4.997238,-114.849815,0.005230,0.000379,0.009617,22.228825,1.132390,0.096174,-114.849815,0.010511,0.000000
15.290001,5.170395,-114.805336,0.005247,0.000395,0.010034,22.999065,1.171628,0.100338,-114.805336,0.010883,0.000000
15.510001,5.259766,-114.894295,0.005251,0.000412,0.010467,23.396606,1.191880,0.104671,-114.894295,0.011248,0.000000
15.730000,5.297371,-114.894295,0.005256,0.000422,0.010728,23.563883,1.200401,0.107275,-114.894295,0.011612,0.000000
15.950001,5.375198,-114.894295,0.005282,0.000434,0.011031,23.910076,1.218037,0.110311,-114.894295,0.011976,0.000000
16.170000,5.592293,-114.894295,0.005303,0.000454,0.011534,24.875761,1.267232,0.115341,-114.894295,0.012349,0.000000
16.390001,5.655594,-114.849815,0.005312,0.000465,0.011803,25.157337,1.281576,0.118028,-114.849815,0.012713,0.000000
16.610001,5.626549,-114.849815,0.005316,0.000474,0.012037,25.028139,1.274994,0.120367,-114.849815,0.013078,0.000000
16.830000,5.875298,-114.894295,0.005329,0.000495,0.012575,26.134628,1.331362,0.125746,-114.894295,0.013442,0.000000
17.050001,6.062973,-114.894295,0.005342,0.000514,0.013060,26.969452,1.373889,0.130602,-114.894295,0.013815,0.000000
17.270000,6.023872,-114.894295,0.005368,0.000524,0.013312,26.795523,1.365029,0.133119,-114.894295,0.014179,0.000000
17.490002,6.105049,-114.894295,0.005376,0.000539,0.013693,27.156614,1.383424,0.136934,-114.894295,0.014543,0.000000
17.710001,6.088295,-114.894295,0.005381,0.000549,0.013953,27.082088,1.379627,0.139534,-114.894295,0.014916,0.000000
17.930000,6.122925,-114.938774,0.005398,0.000563,0.014292,27.236130,1.387475,0.142918,-114.938774,0.015280,0.000000
18.150002,6.312088,-114.938774,0.005411,0.000577,0.014647,28.077570,1.430340,0.146472,-114.938774,0.015644,0.000000
18.370001,6.449867,-114.938774,0.005433,0.000595,0.015116,28.690443,1.461561,0.151157,-114.938774,0.016009,0.000000
18.590000,6.484497,-114.894295,0.005441,0.000607,0.015419,28.844484,1.469408,0.154189,-114.894295,0.016382,0.000000
18.810001,6.555618,-114.894295,0.005458,0.000622,0.015792,29.160847,1.485524,0.157921,-114.894295,0.016746,0.000000
19.030001,6.755959,-114.983261,0.005471,0.000640,0.016260,30.052004,1.530922,0.162603,-114.983261,0.017110,0.000000
19.250000,6.692650,-114.938774,0.005484,0.000651,0.016546,29.770393,1.516576,0.165464,-114.938774,0.017483,0.000000
19.470001,6.810326,-114.938774,0.005510,0.000667,0.016937,30.293840,1.543242,0.169366,-114.938774,0.017847,0.000000
19.690001,6.733612,-114.983261,0.005501,0.000677,0.017206,29.952602,1.525858,0.172058,-114.983261,0.018211,0.000000
19.910002,6.733612,-115.027740,0.005523,0.000690,0.017518,29.952602,1.525858,0.175176,-115.027740,0.018576,0.000000
20.130001,7.056091,-115.027740,0.005545,0.000711,0.018055,31.387062,1.598933,0.180555,-115.027740,0.018949,0.000000
20.350000,7.031136,-115.027740,0.005553,0.000721,0.018315,31.276052,1.593278,0.183155,-115.027740,0.019313,0.000000
20.570002,7.048637,-114.983261,0.005566,0.000733,0.018628,31.353905,1.597244,0.186277,-114.983261,0.019677,0.000000
20.790001,7.023315,-114.938774,0.005575,0.000744,0.018888,31.241268,1.591506,0.188881,-114.938774,0.020050,0.000000
21.010000,7.421761,-114.983261,0.005601,0.000771,0.019591,33.013641,1.681795,0.195906,-114.983261,0.020414,0.000000
21.230001,7.308929,-115.027740,0.005609,0.000781,0.019833,32.511742,1.656227,0.198332,-115.027740,0.020779,0.000000
21.450001,7.311539,-115.027740,0.005631,0.000795,0.020197,32.523350,1.656818,0.201973,-115.027740,0.021143,0.000000
21.670000,7.237808,-115.072220,0.005648,0.000803,0.020406,32.195377,1.640111,0.204055,-115.072220,0.021516,0.000000
21.890001,7.351006,-114.983261,0.005644,0.000819,0.020796,32.698906,1.665762,0.207957,-114.983261,0.021880,0.000000
22.110001,7.594170,-115.027740,0.005670,0.000838,0.021273,33.780552,1.720863,0.212730,-115.027740,0.022244,0.000000
22.330002,7.675713,-115.072220,0.005674,0.000851,0.021611,34.143276,1.739341,0.216110,-115.072220,0.022617,0.000000
22.550001,7.680183,-115.027740,0.005700,0.000864,0.021941,34.163162,1.740354,0.219407,-115.027740,0.022981,0.000000
22.770000,7.816475,-114.983261,0.005704,0.000879,0.022322,34.769417,1.771238,0.223222,-114.983261,0.023346,0.000000
22.990002,8.002289,-115.027740,0.005721,0.000899,0.022825,35.595959,1.813345,0.228252,-115.027740,0.023710,0.000000
23.210001,8.085327,-115.027740,0.005743,0.000915,0.023233,35.965332,1.832161,0.232328,-115.027740,0.024083,0.000000
23.430000,7.894295,-115.072220,0.005760,0.000923,0.023441,35.115578,1.788873,0.234410,-115.072220,0.024447,0.000000
23.650002,7.836578,-115.072220,0.005764,0.000931,0.023658,34.858841,1.775794,0.236579,-115.072220,0.024811,0.000000
23.870001,8.212303,-115.116699,0.005777,0.000954,0.024221,36.530148,1.860934,0.242214,-115.116699,0.025184,0.000000
24.090002,8.259972,-115.072220,0.005786,0.000968,0.024577,36.742187,1.871736,0.245768,-115.072220,0.025548,0.000000
24.310001,8.315826,-115.116699,0.005812,0.000982,0.024933,36.990643,1.884393,0.249326,-115.116699,0.025913,0.000000
24.530001,8.306145,-115.161179,0.005808,0.000993,0.025227,36.947578,1.882199,0.252275,-115.161179,0.026277,0.000000
24.750002,8.627129,-115.161179,0.005842,0.001017,0.025843,38.375385,1.954935,0.258433,-115.161179,0.026650,0.000000
24.970001,8.671440,-115.072220,0.005851,0.001033,0.026233,38.572491,1.964976,0.262335,-115.072220,0.027014,0.000000
25.190001,8.506477,-115.116699,0.005864,0.001040,0.026407,37.838699,1.927595,0.264068,-115.116699,0.027378,0.000000
25.410002,8.643883,-115.161179,0.005877,0.001057,0.026841,38.449909,1.958732,0.268406,-115.161179,0.027751,0.000000
25.630001,8.560844,-115.116699,0.005894,0.001068,0.027135,38.080540,1.939915,0.271354,-115.116699,0.028115,0.000000
25.850000,8.811455,-115.116699,0.005885,0.001084,0.027534,39.195309,1.996704,0.275344,-115.116699,0.028479,0.000000
26.070002,8.869911,-115.116699,0.005907,0.001098,0.027881,39.455334,2.009951,0.278811,-115.116699,0.028844,0.000000
26.290001,8.874008,-115.116699,0.005911,0.001108,0.028150,39.473560,2.010879,0.281498,-115.116699,0.029217,0.000000
26.510002,9.011040,-115.161179,0.005933,0.001123,0.028532,40.083107,2.041931,0.285317,-115.161179,0.029581,0.000000
26.730001,9.246384,-115.294624,0.005959,0.001142,0.029000,41.129971,2.095261,0.289999,-115.294624,0.029945,0.000000
26.950001,9.242287,-115.161179,0.005971,0.001154,0.029312,41.111744,2.094332,0.293121,-115.161179,0.030318,0.000000
27.170002,9.402405,-115.116699,0.005993,0.001171,0.029745,41.823986,2.130615,0.297455,-115.116699,0.030682,0.000000
27.390001,9.282501,-115.161179,0.005989,0.001180,0.029980,41.290627,2.103445,0.299798,-115.161179,0.031046,0.000000
27.610001,9.349533,-115.250145,0.006006,0.001194,0.030336,41.588799,2.118634,0.303356,-115.250145,0.031411,0.000000
27.830002,9.588966,-115.205666,0.006032,0.001212,0.030778,42.653854,2.172891,0.307776,-115.205666,0.031784,0.000000
28.050001,9.706635,-115.205666,0.006040,0.001227,0.031168,43.177265,2.199555,0.311679,-115.205666,0.032148,0.000000
28.270000,9.646683,-115.161179,0.006058,0.001238,0.031437,42.910587,2.185970,0.314366,-115.161179,0.032512,0.000000
28.490002,9.838455,-115.205666,0.006053,0.001253,0.031836,43.763634,2.229426,0.318355,-115.205666,0.032885,0.000000
28.710001,10.124062,-115.205666,0.006084,0.001273,0.032330,45.034077,2.294145,0.323298,-115.205666,0.033249,0.000000
28.930002,10.223862,-115.250145,0.006101,0.001289,0.032746,45.478008,2.316760,0.327462,-115.250145,0.033614,0.000000
29.150002,10.179550,-115.205666,0.006109,0.001302,0.033067,45.280899,2.306719,0.330671,-115.205666,0.033978,0.000000
29.370001,10.172470,-115.250145,0.006127,0.001314,0.033388,45.249409,2.305115,0.333881,-115.250145,0.034351,0.000000
29.590002,10.321419,-115.205666,0.006131,0.001328,0.033743,45.911964,2.338867,0.337435,-115.205666,0.034715,0.000000
29.810001,10.522133,-115.339104,0.006148,0.001346,0.034195,46.804783,2.384349,0.341946,-115.339104,0.035079,0.000000
30.030001,10.610008,-115.294624,0.006165,0.001360,0.034550,47.195675,2.404262,0.345500,-115.294624,0.035443,0.000000
30.250002,10.582825,-115.250145,0.006174,0.001370,0.034810,47.074757,2.398102,0.348104,-115.250145,0.035816,0.000000
30.470001,10.738106,-115.250145,0.006178,0.001386,0.035209,47.765480,2.433290,0.352094,-115.250145,0.036181,0.000000
30.690001,11.069519,-115.294624,0.006213,0.001405,0.035686,49.239681,2.508389,0.356863,-115.294624,0.036545,0.000000
30.910002,11.143990,-115.339104,0.006213,0.001420,0.036076,49.570942,2.525264,0.360765,-115.339104,0.036917,0.000000
31.130001,11.033768,-115.339104,0.006222,0.001431,0.036354,49.080650,2.500287,0.363539,-115.339104,0.037282,0.000000
31.350002,11.128349,-115.294624,0.006247,0.001446,0.036718,49.501369,2.521720,0.367180,-115.294624,0.037646,0.000000
31.570002,11.260544,-115.294624,0.006260,0.001460,0.037091,50.089401,2.551676,0.370912,-115.294624,0.038010,0.000000
31.790001,11.500725,-115.339104,0.006269,0.001476,0.037498,51.157780,2.606102,0.374985,-115.339104,0.038383,0.000000
32.010002,11.465347,-115.339104,0.006278,0.001488,0.037785,51.000412,2.598085,0.377850,-115.339104,0.038747,0.000000
32.230003,11.748726,-115.339104,0.006291,0.001506,0.038253,52.260944,2.662299,0.382532,-115.339104,0.039112,0.000000
32.450001,11.904747,-115.383591,0.006316,0.001522,0.038670,52.954960,2.697654,0.386695,-115.383591,0.039485,0.000000
32.670002,11.905869,-115.294624,0.006325,0.001535,0.038999,52.959949,2.697908,0.389988,-115.294624,0.039849,0.000000
32.890003,11.961349,-115.383591,0.006342,0.001547,0.039302,53.206741,2.710480,0.393023,-115.383591,0.040213,0.000000
33.110001,12.064499,-115.383591,0.006347,0.001562,0.039676,53.665573,2.733855,0.396755,-115.383591,0.040577,0.000000
33.330002,12.203392,-115.339104,0.006364,0.001577,0.040048,54.283398,2.765328,0.400484,-115.339104,0.040950,0.000000
33.550003,12.245094,-115.339104,0.006372,0.001588,0.040343,54.468899,2.774778,0.403432,-115.339104,0.041314,0.000000
33.770000,12.603317,-115.294624,0.006390,0.001608,0.040846,56.062355,2.855953,0.408462,-115.294624,0.041679,0.000000
33.990002,12.508362,-115.339104,0.006407,0.001618,0.041089,55.639973,2.834435,0.410888,-115.339104,0.042052,0.000000
34.210003,12.555656,-115.383591,0.006411,0.001630,0.041401,55.850349,2.845152,0.414011,-115.383591,0.042416,0.000000
34.430000,13.080704,-115.383591,0.006437,0.001651,0.041948,58.185875,2.964130,0.419476,-115.383591,0.042780,0.000000
34.650002,13.178635,-115.383591,0.006450,0.001666,0.042320,58.621494,2.986321,0.423204,-115.383591,0.043144,0.000000
34.870003,13.098946,-115.383591,0.006459,0.001677,0.042598,58.267021,2.968263,0.425979,-115.383591,0.043517,0.000000
35.090000,13.215874,-115.339104,0.006472,0.001690,0.042936,58.787144,2.994760,0.429362,-115.339104,0.043881,0.000000
35.310001,13.173050,-115.428070,0.006472,0.001702,0.043231,58.596653,2.985056,0.432311,-115.428070,0.044246,0.000000
35.530003,13.523079,-115.472549,0.006497,0.001719,0.043665,60.153660,3.064373,0.436648,-115.472549,0.044619,0.000000
35.750000,13.789696,-115.428070,0.006515,0.001734,0.044046,61.339630,3.124790,0.440463,-115.428070,0.044983,0.000000
35.970001,13.736450,-115.428070,0.006519,0.001745,0.044315,61.102783,3.112724,0.443151,-115.428070,0.045347,0.000000
36.190002,13.982590,-115.472549,0.006532,0.001762,0.044749,62.197666,3.168500,0.447488,-115.472549,0.045711,0.000000
36.410000,14.099884,-115.472549,0.006554,0.001776,0.045122,62.719418,3.195079,0.451216,-115.472549,0.046084,0.000000
36.630001,14.487900,-115.517029,0.006571,0.001794,0.045555,64.445396,3.283005,0.455550,-115.517029,0.046449,0.000000
36.850002,14.650253,-115.428070,0.006579,0.001811,0.045997,65.167580,3.319795,0.459974,-115.428070,0.046813,0.000000
37.070004,14.661423,-115.472549,0.006605,0.001821,0.046257,65.217262,3.322326,0.462575,-115.472549,0.047186,0.000000
37.290001,14.663284,-115.428070,0.006592,0.001833,0.046552,65.225548,3.322748,0.465523,-115.428070,0.047550,0.000000
37.510002,14.986877,-115.561508,0.006610,0.001851,0.047021,66.664963,3.396075,0.470209,-115.561508,0.047914,0.000000
37.730003,15.090767,-115.517029,0.006635,0.001863,0.047316,67.127083,3.419617,0.473157,-115.517029,0.048278,0.000000
37.950001,15.181252,-115.428070,0.006653,0.001876,0.047645,67.529579,3.440121,0.476450,-115.428070,0.048651,0.000000
38.170002,15.656776,-115.472549,0.006648,0.001896,0.048148,69.644821,3.547876,0.481480,-115.472549,0.049016,0.000000
38.390003,15.923019,-115.517029,0.006679,0.001912,0.048564,70.829124,3.608208,0.485644,-115.517029,0.049380,0.000000
38.610001,15.924507,-115.472549,0.006683,0.001924,0.048868,70.835747,3.608545,0.488679,-115.472549,0.049752,0.000000
38.830002,16.054466,-115.517029,0.006700,0.001938,0.049232,71.413834,3.637994,0.492324,-115.517029,0.050117,0.000000
39.050003,15.987816,-115.472549,0.006713,0.001949,0.049492,71.117355,3.622891,0.494924,-115.472549,0.050481,0.000000
39.270000,15.968826,-115.517029,0.006722,0.001961,0.049822,71.032890,3.618588,0.498221,-115.517029,0.050845,0.000000
39.490002,16.372849,-115.517029,0.006722,0.001975,0.050169,72.830070,3.710140,0.501688,-115.517029,0.051218,0.000000
39.710003,16.804054,-115.561508,0.006739,0.001994,0.050637,74.748169,3.807853,0.506370,-115.561508,0.051582,0.000000
39.930000,16.914276,-115.517029,0.006773,0.002006,0.050958,75.238457,3.832830,0.509579,-115.517029,0.051947,0.000000
40.150002,17.254623,-115.517029,0.006773,0.002022,0.051348,76.752396,3.909954,0.513482,-115.517029,0.052319,0.000000
40.370003,17.651947,-115.561508,0.006782,0.002040,0.051817,78.519783,3.999989,0.518167,-115.561508,0.052684,0.000000
40.590000,17.623276,-115.561508,0.006812,0.002051,0.052094,78.392242,3.993491,0.520942,-115.561508,0.053048,0.000000
40.810001,17.878723,-115.605995,0.006821,0.002067,0.052502,79.528534,4.051377,0.525018,-115.605995,0.053412,0.000000
41.030003,17.777061,-115.605995,0.006834,0.002077,0.052762,79.076317,4.028340,0.527618,-115.605995,0.053785,0.000000
41.250004,17.874626,-115.561508,0.006838,0.002091,0.053117,79.510307,4.050448,0.531172,-115.561508,0.054149,0.000000
41.470001,18.464462,-115.561508,0.006838,0.002108,0.053551,82.134033,4.184107,0.535510,-115.561508,0.054513,0.000000
41.690002,18.521805,-115.561508,0.006868,0.002119,0.053820,82.389099,4.197101,0.538197,-115.561508,0.054887,0.000000
41.910004,18.655487,-115.694954,0.006873,0.002132,0.054141,82.983749,4.227394,0.541407,-115.694954,0.055251,0.000000
42.130001,18.645805,-115.650475,0.006885,0.002143,0.054435,82.940681,4.225200,0.544355,-115.650475,0.055615,0.000000
42.350002,19.868309,-115.517029,0.006903,0.002170,0.055129,88.378654,4.502223,0.551293,-115.517029,0.055979,0.000000
42.570004,19.687332,-115.650475,0.006911,0.002180,0.055364,87.573624,4.461213,0.553636,-115.650475,0.056352,0.000000
42.790001,19.817665,-115.694954,0.006937,0.002194,0.055728,88.153374,4.490747,0.557277,-115.694954,0.056716,0.000000
43.010002,19.805748,-115.694954,0.006954,0.002207,0.056057,88.100365,4.488047,0.560573,-115.694954,0.057081,0.000000
43.230003,20.017258,-115.650475,0.006946,0.002218,0.056343,89.041206,4.535975,0.563435,-115.650475,0.057445,0.000000
43.450001,20.562782,-115.605995,0.006972,0.002237,0.056829,91.467827,4.659593,0.568291,-115.605995,0.057818,0.000000
43.670002,20.846527,-115.650475,0.006972,0.002250,0.057150,92.729980,4.723891,0.571500,-115.650475,0.058182,0.000000
43.890003,21.004044,-115.694954,0.006985,0.002262,0.057462,93.430649,4.759584,0.574623,-115.694954,0.058546,0.000000
44.110001,21.447540,-115.650475,0.006998,0.002277,0.057844,95.403427,4.860082,0.578438,-115.650475,0.058919,0.000000
44.330002,22.015404,-115.694954,0.007019,0.002297,0.058356,97.929405,4.988762,0.583555,-115.694954,0.059283,0.000000
44.550003,22.378098,-115.650475,0.007028,0.002314,0.058763,99.542747,5.070949,0.587631,-115.650475,0.059648,0.000000
44.770000,22.155045,-115.650475,0.007041,0.002321,0.058963,98.550560,5.020405,0.589626,-115.650475,0.060012,0.000000
44.990002,22.056366,-115.739433,0.007049,0.002332,0.059240,98.111618,4.998044,0.592400,-115.739433,0.060385,0.000000
45.210003,22.774300,-115.694954,0.007071,0.002350,0.059682,101.305145,5.160730,0.596821,-115.694954,0.060749,0.000000
45.430000,23.269188,-115.694954,0.007088,0.002365,0.060073,103.506516,5.272873,0.600727,-115.694954,0.061113,0.000000
45.650002,23.428185,-115.694954,0.007097,0.002379,0.060428,104.213768,5.308903,0.604281,-115.694954,0.061486,0.000000
45.870003,23.707092,-115.739433,0.007088,0.002391,0.060723,105.454414,5.372104,0.607230,-115.739433,0.061850,0.000000
46.090004,24.638023,-115.739433,0.007118,0.002415,0.061347,109.595398,5.583055,0.613475,-115.739433,0.062215,0.000000
46.310001,25.168282,-115.739433,0.007140,0.002432,0.061772,111.954109,5.703214,0.617721,-115.739433,0.062579,0.000000
46.530003,25.004814,-115.694954,0.007144,0.002443,0.062050,111.226967,5.666172,0.620499,-115.694954,0.062952,0.000000
46.750004,25.186531,-115.694954,0.007153,0.002455,0.062362,112.035286,5.707350,0.623622,-115.694954,0.063316,0.000000
46.970001,25.076309,-115.783913,0.007157,0.002466,0.062648,111.544991,5.682373,0.626483,-115.783913,0.063680,0.000000
47.190002,25.581993,-115.739433,0.007170,0.002480,0.063004,113.794388,5.796963,0.630037,-115.739433,0.064053,0.000000
47.410004,26.040756,-115.694954,0.007192,0.002495,0.063385,115.835068,5.900920,0.633853,-115.694954,0.064417,0.000000
47.630001,26.181511,-115.783913,0.007205,0.002506,0.063646,116.461174,5.932815,0.636457,-115.783913,0.064782,0.000000
47.850002,26.622025,-115.739433,0.007200,0.002519,0.063975,118.420677,6.032637,0.639749,-115.739433,0.065146,0.000000
48.070004,27.541786,-115.783913,0.007217,0.002540,0.064513,122.511986,6.241058,0.645128,-115.783913,0.065519,0.000000
48.290001,27.724991,-115.828400,0.007235,0.002552,0.064825,123.326920,6.282573,0.648250,-115.828400,0.065883,0.000000
48.510002,28.280945,-115.783913,0.007256,0.002569,0.065258,125.799927,6.408554,0.652584,-115.783913,0.066247,0.000000
48.730003,28.321907,-115.783913,0.007252,0.002579,0.065519,125.982132,6.417836,0.655188,-115.783913,0.066620,0.000000
48.950001,28.626137,-115.783913,0.007261,0.002593,0.065874,127.335419,6.486775,0.658742,-115.783913,0.066984,0.000000
49.170002,29.196983,-115.783913,0.007282,0.002610,0.066291,129.874664,6.616131,0.662905,-115.783913,0.067348,0.000000
49.390003,29.812889,-115.917358,0.007308,0.002627,0.066716,132.614349,6.755697,0.667156,-115.917358,0.067713,0.000000
49.610001,29.845657,-115.872879,0.007304,0.002636,0.066967,132.760117,6.763123,0.669669,-115.872879,0.068086,0.000000
49.830002,30.133873,-115.783913,0.007317,0.002650,0.067323,134.042160,6.828433,0.673227,-115.783913,0.068450,0.000000
50.050003,31.356743,-115.828400,0.007325,0.002671,0.067851,139.481766,7.105539,0.678514,-115.828400,0.068814,0.000000
50.270004,31.777153,-115.917358,0.007351,0.002687,0.068250,141.351837,7.200806,0.682504,-115.917358,0.069187,0.000000
50.490002,32.127182,-115.872879,0.007347,0.002701,0.068606,142.908844,7.280124,0.686061,-115.872879,0.069551,0.000000
50.710003,32.413162,-115.828400,0.007360,0.002715,0.068953,144.180954,7.344928,0.689528,-115.828400,0.069916,0.000000
50.930004,32.801178,-115.872879,0.007386,0.002727,0.069265,145.906921,7.432853,0.692651,-115.872879,0.070280,0.000000
51.150002,33.404419,-115.917358,0.007394,0.002744,0.069699,148.590271,7.569550,0.696988,-115.917358,0.070653,0.000000
51.370003,33.852013,-115.961838,0.007394,0.002757,0.070020,150.581268,7.670976,0.700198,-115.961838,0.071017,0.000000
51.590004,34.031494,-115.917358,0.007403,0.002769,0.070340,151.379654,7.711647,0.703404,-115.917358,0.071381,0.000000
51.810001,34.605690,-115.872879,0.007416,0.002783,0.070687,153.933792,7.841762,0.706875,-115.872879,0.071754,0.000000
52.030003,35.732117,-115.872879,0.007424,0.002804,0.071216,158.944397,8.097013,0.712162,-115.872879,0.072118,0.000000
52.250004,36.255676,-115.917358,0.007437,0.002818,0.071589,161.273300,8.215653,0.715894,-115.917358,0.072483,0.000000
52.470001,36.354729,-115.961838,0.007437,0.002829,0.071858,161.713913,8.238099,0.718581,-115.961838,0.072847,0.000000
52.690002,36.903229,-115.917358,0.007463,0.002844,0.072240,164.153763,8.362391,0.722396,-115.917358,0.073220,0.000000
52.910004,37.328476,-115.872879,0.007476,0.002858,0.072587,166.045349,8.458754,0.725867,-115.872879,0.073584,0.000000
53.130001,38.220680,-115.917358,0.007468,0.002875,0.073020,170.014084,8.660930,0.730201,-115.917358,0.073948,0.000000
53.350002,38.527145,-115.872879,0.007480,0.002887,0.073332,171.377304,8.730376,0.733323,-115.872879,0.074321,0.000000
53.570004,39.398872,-115.961838,0.007489,0.002905,0.073792,175.254944,8.927913,0.737922,-115.961838,0.074685,0.000000
53.790001,40.231499,-115.961838,0.007506,0.002922,0.074226,178.958649,9.116588,0.742256,-115.961838,0.075050,0.000000
54.010002,40.502953,-115.961838,0.007519,0.002934,0.074520,180.166138,9.178100,0.745204,-115.961838,0.075414,0.000000
54.230003,40.821335,-115.961838,0.007515,0.002946,0.074824,181.582367,9.250247,0.748240,-115.961838,0.075787,0.000000
54.450001,41.486389,-115.961838,0.007545,0.002961,0.075197,184.540680,9.400950,0.751968,-115.961838,0.076151,0.000000
54.670002,42.188316,-115.961838,0.007545,0.002976,0.075587,187.663010,9.560009,0.755874,-115.961838,0.076515,0.000000
54.890003,42.510040,-115.961838,0.007558,0.002986,0.075856,189.094101,9.632913,0.758561,-115.961838,0.076888,0.000000
55.110004,43.537048,-115.961838,0.007567,0.003006,0.076359,193.662460,9.865636,0.763591,-115.961838,0.077252,0.000000
55.330002,43.811485,-115.961838,0.007580,0.003015,0.076585,194.883224,9.927824,0.765847,-115.961838,0.077616,0.000000
55.550003,44.169708,-116.006317,0.007584,0.003029,0.076931,196.476669,10.008999,0.769314,-116.006317,0.077981,0.000000
55.770004,45.442848,-116.006317,0.007593,0.003050,0.077461,202.139877,10.297496,0.774605,-116.006317,0.078354,0.000000
55.990002,46.169350,-116.050804,0.007601,0.003064,0.077825,205.371521,10.462124,0.778246,-116.050804,0.078718,0.000000
56.210003,46.626617,-115.961838,0.007627,0.003076,0.078119,207.405548,10.565742,0.781195,-115.961838,0.079082,0.000000
56.430004,47.221298,-115.961838,0.007614,0.003090,0.078484,210.050827,10.700499,0.784836,-115.961838,0.079446,0.000000
56.650002,47.558296,-116.006317,0.007627,0.003104,0.078831,211.549866,10.776863,0.788307,-116.006317,0.079819,0.000000
56.870003,48.569290,-116.095284,0.007631,0.003120,0.079238,216.046997,11.005959,0.792383,-116.095284,0.080183,0.000000
57.090004,49.443993,-116.050804,0.007653,0.003134,0.079594,219.937866,11.204169,0.795937,-116.050804,0.080548,0.000000
57.310001,49.806679,-116.050804,0.007666,0.003144,0.079863,221.551178,11.286355,0.798628,-116.050804,0.080921,0.000000
57.530003,50.685104,-116.006317,0.007662,0.003161,0.080296,225.458603,11.485409,0.802962,-116.006317,0.081285,0.000000
57.750004,51.354630,-116.050804,0.007666,0.003175,0.080643,228.436798,11.637126,0.806432,-116.050804,0.081649,0.000000
57.970001,52.440842,-116.139763,0.007692,0.003192,0.081085,233.268509,11.883265,0.810853,-116.139763,0.082013,0.000000
58.190002,53.101807,-116.006317,0.007705,0.003208,0.081484,236.208633,12.033042,0.814842,-116.006317,0.082386,0.000000
58.410004,53.710632,-116.050804,0.007705,0.003220,0.081779,238.916824,12.171003,0.817791,-116.050804,0.082751,0.000000
58.630001,54.164925,-116.050804,0.007709,0.003231,0.082074,240.937622,12.273948,0.820739,-116.050804,0.083115,0.000000
58.850002,55.177040,-116.095284,0.007713,0.003248,0.082499,245.439728,12.503296,0.824990,-116.095284,0.083488,0.000000
59.070004,55.913589,-116.184242,0.007731,0.003260,0.082811,248.716064,12.670200,0.828112,-116.184242,0.083852,0.000000
59.290001,56.428955,-116.095284,0.007731,0.003272,0.083115,251.008530,12.786983,0.831148,-116.095284,0.084216,0.000000
59.510002,57.974297,-116.095284,0.007743,0.003294,0.083661,257.882538,13.137164,0.836609,-116.095284,0.084580,0.000000
59.730003,58.724258,-116.095284,0.007743,0.003307,0.084008,261.218536,13.307107,0.840080,-116.095284,0.084953,0.000000
59.950005,59.698753,-116.139763,0.007743,0.003321,0.084355,265.553314,13.527931,0.843547,-116.139763,0.085318,0.000000
60.170002,60.562286,-116.139763,0.007769,0.003337,0.084754,269.394501,13.723610,0.847536,-116.139763,0.085682,0.000000
60.390003,60.833748,-116.184242,0.007778,0.003346,0.084997,270.602020,13.785125,0.849966,-116.184242,0.086055,0.000000
60.610004,61.196068,-116.095284,0.007778,0.003355,0.085214,272.213715,13.867227,0.852135,-116.095284,0.086419,0.000000
60.830002,62.175774,-116.184242,0.007782,0.003372,0.085656,276.571655,14.089231,0.856556,-116.184242,0.086783,0.000000
61.050003,63.422859,-116.139763,0.007791,0.003390,0.086098,282.118958,14.371825,0.860980,-116.139763,0.087147,0.000000
61.270004,64.290474,-116.184242,0.007800,0.003404,0.086471,285.978302,14.568430,0.864708,-116.184242,0.087520,0.000000
61.490002,65.349129,-116.184242,0.007817,0.003420,0.086861,290.687439,14.808324,0.868611,-116.184242,0.087885,0.000000
61.710003,66.415977,-116.184242,0.007817,0.003436,0.087269,295.433014,15.050076,0.872687,-116.184242,0.088249,0.000000
61.930004,67.240044,-116.139763,0.007812,0.003449,0.087598,299.098663,15.236812,0.875984,-116.139763,0.088621,0.000000
62.150002,67.363670,-116.228722,0.007817,0.003448,0.087572,299.648560,15.264826,0.875723,-116.228722,0.087798,0.000000
62.370003,66.743294,-116.228722,0.007834,0.003448,0.087572,296.889008,15.124247,0.875723,-116.228722,0.087798,0.000000
62.590004,66.217873,-116.184242,0.007834,0.003447,0.087546,294.551819,15.005184,0.875461,-116.184242,0.087572,0.000000
62.810001,65.737526,-116.184242,0.007830,0.003447,0.087546,292.415131,14.896337,0.875461,-116.184242,0.087572,0.000000
63.030003,65.284340,-116.228722,0.007838,0.003446,0.087537,290.399261,14.793643,0.875374,-116.228722,0.087572,0.000000
63.250004,64.880684,-116.228722,0.007856,0.003446,0.087537,288.603699,14.702173,0.875374,-116.228722,0.087572,0.000000
63.470001,64.530281,-116.228722,0.007851,0.003446,0.087537,287.045013,14.622770,0.875374,-116.228722,0.087572,0.000000
63.690002,64.213020,-116.228722,0.007851,0.003446,0.087537,285.633789,14.550879,0.875374,-116.228722,0.087572,0.000000
63.910004,63.924812,-116.228722,0.007851,0.003446,0.087529,284.351776,14.485569,0.875287,-116.228722,0.087572,0.000000
64.130005,63.626915,-116.273209,0.007856,0.003446,0.087529,283.026642,14.418065,0.875287,-116.273209,0.087572,0.000000
64.350006,63.378532,-116.273209,0.007851,0.003446,0.087529,281.921783,14.361781,0.875287,-116.273209,0.087572,0.000000
64.570000,63.148048,-116.273209,0.007860,0.003446,0.087529,280.896545,14.309552,0.875287,-116.273209,0.087572,0.000000
64.790001,62.911957,-116.317688,0.007851,0.003446,0.087529,279.846375,14.256054,0.875287,-116.317688,0.087572,0.000000
65.010002,62.723907,-116.228722,0.007864,0.003446,0.087529,279.009888,14.213440,0.875287,-116.228722,0.087572,0.000000
65.230003,62.516495,-116.273209,0.007856,0.003446,0.087529,278.087250,14.166441,0.875287,-116.273209,0.087572,0.000000
65.450005,62.341858,-116.273209,0.007873,0.003446,0.087529,277.310425,14.126866,0.875287,-116.273209,0.087572,0.000000
65.670006,62.167587,-116.317688,0.007873,0.003446,0.087529,276.535248,14.087377,0.875287,-116.317688,0.087572,0.000000
65.889999,62.005974,-116.273209,0.007869,0.003446,0.087529,275.816345,14.050755,0.875287,-116.273209,0.087572,0.000000
66.110001,61.857025,-116.317688,0.007873,0.003446,0.087529,275.153778,14.017003,0.875287,-116.317688,0.087572,0.000000
66.330002,61.715523,-116.317688,0.007864,0.003446,0.087529,274.524353,13.984938,0.875287,-116.317688,0.087572,0.000000
66.550003,61.572159,-116.317688,0.007873,0.003446,0.087529,273.886627,13.952451,0.875287,-116.317688,0.087572,0.000000
66.770004,61.450020,-116.362167,0.007873,0.003446,0.087529,273.343353,13.924773,0.875287,-116.362167,0.087572,0.000000
66.990005,61.315971,-116.317688,0.007873,0.003446,0.087529,272.747070,13.894398,0.875287,-116.317688,0.087572,0.000000
67.210007,61.200905,-116.273209,0.007873,0.003446,0.087529,272.235229,13.868323,0.875287,-116.273209,0.087572,0.000000
67.430000,61.091057,-116.406647,0.007864,0.003446,0.087529,271.746582,13.843431,0.875287,-116.406647,0.087572,0.000000
67.650002,60.988655,-116.362167,0.007873,0.003446,0.087529,271.291077,13.820227,0.875287,-116.362167,0.087572,0.000000
67.870003,60.873589,-116.317688,0.007881,0.003446,0.087529,270.779236,13.794152,0.875287,-116.317688,0.087572,0.000000
68.090004,60.765228,-116.317688,0.007873,0.003446,0.087529,270.297241,13.769598,0.875287,-116.317688,0.087572,0.000000
68.310005,60.662827,-116.362167,0.007869,0.003446,0.087529,269.841736,13.746393,0.875287,-116.362167,0.087572,0.000000
68.530006,60.571968,-116.362167,0.007877,0.003446,0.087529,269.437561,13.725804,0.875287,-116.362167,0.087572,0.000000
68.750000,60.479248,-116.362167,0.007877,0.003446,0.087529,269.025146,13.704793,0.875287,-116.362167,0.087572,0.000000
68.970001,60.397697,-116.362167,0.007886,0.003446,0.087529,268.662384,13.686315,0.875287,-116.362167,0.087572,0.000000
69.190002,60.311310,-116.362167,0.007881,0.003446,0.087529,268.278107,13.666739,0.875287,-116.362167,0.087572,0.000000
69.410004,60.223801,-116.406647,0.007869,0.003446,0.087520,267.888855,13.646909,0.875204,-116.406647,0.087572,0.000000
69.630005,60.145233,-116.406647,0.007886,0.003446,0.087520,267.539368,13.629105,0.875204,-116.406647,0.087572,0.000000
69.850006,60.062561,-116.406647,0.007886,0.003446,0.087520,267.171600,13.610371,0.875204,-116.406647,0.087572,0.000000
70.070000,60.013412,-116.362167,0.007881,0.003446,0.087520,266.953003,13.599234,0.875204,-116.362167,0.087572,0.000000
70.290001,59.931488,-116.362167,0.007873,0.003446,0.087520,266.588562,13.580669,0.875204,-116.362167,0.087572,0.000000
70.510002,59.860367,-116.451126,0.007881,0.003446,0.087520,266.272217,13.564552,0.875204,-116.451126,0.087572,0.000000
70.730003,59.795570,-116.495613,0.007890,0.003446,0.087520,265.983978,13.549870,0.875204,-116.495613,0.087572,0.000000
70.950005,59.712158,-116.406647,0.007886,0.003446,0.087520,265.612946,13.530968,0.875204,-116.406647,0.087572,0.000000
71.170006,59.664124,-116.451126,0.007869,0.003446,0.087520,265.399261,13.520083,0.875204,-116.451126,0.087572,0.000000
71.390007,59.600075,-116.451126,0.007886,0.003446,0.087520,265.114380,13.505570,0.875204,-116.451126,0.087572,0.000000
71.610001,59.537521,-116.540092,0.007890,0.003446,0.087520,264.836121,13.491395,0.875204,-116.540092,0.087572,0.000000
71.830002,59.467140,-116.495613,0.007881,0.003446,0.087520,264.523041,13.475446,0.875204,-116.495613,0.087572,0.000000
72.050003,59.405701,-116.406647,0.007890,0.003446,0.087520,264.249756,13.461524,0.875204,-116.406647,0.087572,0.000000
72.270004,59.348724,-116.451126,0.007877,0.003446,0.087520,263.996307,13.448613,0.875204,-116.451126,0.087572,0.000000
72.490005,59.304787,-116.495613,0.007890,0.003446,0.087520,263.800873,13.438657,0.875204,-116.495613,0.087572,0.000000
72.710007,59.242973,-116.540092,0.007877,0.003446,0.087520,263.525909,13.424650,0.875204,-116.540092,0.087572,0.000000
72.930000,59.188606,-116.495613,0.007881,0.003446,0.087520,263.284058,13.412331,0.875204,-116.495613,0.087572,0.000000
73.150002,59.129028,-116.495613,0.007886,0.003446,0.087520,263.019043,13.398829,0.875204,-116.495613,0.087572,0.000000
73.370003,59.090668,-116.451126,0.007886,0.003446,0.087520,262.848419,13.390137,0.875204,-116.451126,0.087572,0.000000
73.590004,59.027367,-116.540092,0.007881,0.003446,0.087520,262.566833,13.375793,0.875204,-116.540092,0.087572,0.000000
73.810005,58.989388,-116.495613,0.007877,0.003446,0.087520,262.397888,13.367187,0.875204,-116.495613,0.087572,0.000000
74.030006,58.936134,-116.540092,0.007890,0.003446,0.087520,262.161011,13.355119,0.875204,-116.540092,0.087572,0.000000
74.250000,58.889221,-116.540092,0.007881,0.003446,0.087520,261.952332,13.344488,0.875204,-116.540092,0.087572,0.000000
74.470001,58.847511,-116.540092,0.007890,0.003446,0.087520,261.766815,13.335037,0.875204,-116.540092,0.087572,0.000000
74.690002,58.785698,-116.540092,0.007881,0.003446,0.087520,261.491852,13.321030,0.875204,-116.540092,0.087572,0.000000
74.910004,58.754044,-116.495613,0.007881,0.003446,0.087520,261.351044,13.313857,0.875204,-116.495613,0.087572,0.000000
75.130005,58.703407,-116.584572,0.007890,0.003446,0.087520,261.125793,13.302382,0.875204,-116.584572,0.087572,0.000000
75.350006,58.666168,-116.540092,0.007886,0.003446,0.087520,260.960144,13.293944,0.875204,-116.540092,0.087572,0.000000
75.570007,58.628929,-116.584572,0.007894,0.003446,0.087520,260.794495,13.285505,0.875204,-116.584572,0.087572,0.000000
75.790001,58.586853,-116.584572,0.007881,0.003446,0.087520,260.607330,13.275970,0.875204,-116.584572,0.087572,0.000000
76.010002,58.541794,-116.629051,0.007890,0.003446,0.087520,260.406891,13.265760,0.875204,-116.629051,0.087572,0.000000
76.230003,58.498596,-116.584572,0.007894,0.003446,0.087520,260.214752,13.255971,0.875204,-116.584572,0.087572,0.000000
76.450005,58.459869,-116.584572,0.007899,0.003446,0.087520,260.042480,13.247196,0.875204,-116.584572,0.087572,0.000000
76.670006,58.429337,-116.584572,0.007881,0.003446,0.087520,259.906677,13.240277,0.875204,-116.584572,0.087572,0.000000
76.890007,58.385025,-116.629051,0.007894,0.003446,0.087520,259.709564,13.230235,0.875204,-116.629051,0.087572,0.000000
77.110001,58.365662,-116.629051,0.007890,0.003446,0.087520,259.623444,13.225848,0.875204,-116.629051,0.087572,0.000000
77.330002,58.312042,-116.629051,0.007894,0.003446,0.087520,259.384918,13.213697,0.875204,-116.629051,0.087572,0.000000
77.550003,58.271454,-116.584572,0.007899,0.003446,0.087520,259.204376,13.204500,0.875204,-116.584572,0.087572,0.000000
77.770004,58.240913,-116.584572,0.007886,0.003446,0.087520,259.068512,13.197579,0.875204,-116.584572,0.087572,0.000000
77.990005,58.195488,-116.629051,0.007890,0.003446,0.087520,258.866455,13.187286,0.875204,-116.629051,0.087572,0.000000
78.210007,58.177238,-116.673538,0.007894,0.003446,0.087520,258.785278,13.183150,0.875204,-116.673538,0.087572,0.000000
78.430000,58.130692,-116.673538,0.007890,0.003446,0.087520,258.578217,13.172604,0.875204,-116.673538,0.087572,0.000000
78.650002,58.115059,-116.584572,0.007899,0.003446,0.087520,258.508698,13.169061,0.875204,-116.584572,0.087572,0.000000
78.870003,58.083778,-116.629051,0.007886,0.003446,0.087520,258.369537,13.161972,0.875204,-116.629051,0.087572,0.000000
79.090004,58.041695,-116.718018,0.007903,0.003446,0.087520,258.182343,13.152436,0.875204,-116.718018,0.087572,0.000000
79.310005,58.011909,-116.718018,0.007890,0.003446,0.087520,258.049866,13.145686,0.875204,-116.718018,0.087572,0.000000
79.530006,57.982491,-116.629051,0.007886,0.003446,0.087520,257.919006,13.139020,0.875204,-116.629051,0.087572,0.000000
79.750000,57.962379,-116.718018,0.007886,0.003446,0.087520,257.829529,13.134463,0.875204,-116.718018,0.087572,0.000000
79.970001,57.918442,-116.673538,0.007881,0.003446,0.087520,257.634094,13.124507,0.875204,-116.673538,0.087572,0.000000
80.190002,57.874504,-116.762497,0.007886,0.003446,0.087520,257.438660,13.114551,0.875204,-116.762497,0.087572,0.000000
80.410004,57.855515,-116.718018,0.007899,0.003446,0.087520,257.354187,13.110247,0.875204,-116.718018,0.087572,0.000000
80.630005,57.807846,-116.718018,0.007899,0.003446,0.087520,257.142151,13.099444,0.875204,-116.718018,0.087572,0.000000
80.850006,57.803383,-116.673538,0.007890,0.003446,0.087520,257.122284,13.098434,0.875204,-116.673538,0.087572,0.000000
81.070007,57.762421,-116.673538,0.007886,0.003446,0.087520,256.940094,13.089151,0.875204,-116.673538,0.087572,0.000000
81.290001,57.741936,-116.762497,0.007890,0.003446,0.087520,256.848969,13.084510,0.875204,-116.762497,0.087572,0.000000
81.510002,57.712517,-116.762497,0.007899,0.003446,0.087520,256.718109,13.077844,0.875204,-116.762497,0.087572,0.000000
81.730003,57.676025,-116.762497,0.007907,0.003446,0.087520,256.555786,13.069574,0.875204,-116.762497,0.087572,0.000000
81.950005,57.655174,-116.762497,0.007894,0.003446,0.087520,256.463013,13.064850,0.875204,-116.762497,0.087572,0.000000
82.170006,57.630974,-116.762497,0.007907,0.003446,0.087520,256.355377,13.059365,0.875204,-116.762497,0.087572,0.000000
82.390007,57.601555,-116.762497,0.007894,0.003446,0.087520,256.224518,13.052699,0.875204,-116.762497,0.087572,0.000000
82.610001,57.584793,-116.806976,0.007899,0.003446,0.087520,256.149963,13.048901,0.875204,-116.806976,0.087572,0.000000
82.830002,57.549423,-116.806976,0.007894,0.003446,0.087520,255.992615,13.040885,0.875204,-116.806976,0.087572,0.000000
83.050003,57.528938,-116.762497,0.007903,0.003446,0.087520,255.901505,13.036243,0.875204,-116.762497,0.087572,0.000000
83.270004,57.498032,-116.806976,0.007899,0.003446,0.087520,255.764023,13.029241,0.875204,-116.806976,0.087572,0.000000
83.490005,57.484253,-116.806976,0.007894,0.003446,0.087520,255.702728,13.026117,0.875204,-116.806976,0.087572,0.000000
83.710007,57.458565,-116.806976,0.007899,0.003446,0.087520,255.588455,13.020297,0.875204,-116.806976,0.087572,0.000000
83.930000,57.420578,-116.806976,0.007903,0.003446,0.087520,255.419495,13.011689,0.875204,-116.806976,0.087572,0.000000
84.150002,57.403450,-116.851456,0.007903,0.003446,0.087520,255.343292,13.007808,0.875204,-116.851456,0.087572,0.000000
84.370003,57.368073,-116.895943,0.007894,0.003446,0.087520,255.185928,12.999791,0.875204,-116.895943,0.087572,0.000000
84.590004,57.348343,-116.806976,0.007899,0.003446,0.087520,255.098175,12.995319,0.875204,-116.806976,0.087572,0.000000
84.810005,57.344246,-116.851456,0.007903,0.003446,0.087520,255.079941,12.994392,0.875204,-116.851456,0.087572,0.000000
85.030006,57.298073,-116.806976,0.007894,0.003446,0.087520,254.874557,12.983929,0.875204,-116.806976,0.087572,0.000000
85.250008,57.288017,-116.806976,0.007903,0.003446,0.087520,254.829834,12.981650,0.875204,-116.806976,0.087572,0.000000
85.470001,57.248543,-116.851456,0.007894,0.003446,0.087520,254.654236,12.972706,0.875204,-116.851456,0.087572,0.000000
85.690002,57.231789,-116.851456,0.007903,0.003446,0.087520,254.579712,12.968909,0.875204,-116.851456,0.087572,0.000000
85.910004,57.207214,-116.851456,0.007907,0.003446,0.087520,254.470398,12.963340,0.875204,-116.851456,0.087572,0.000000
86.130005,57.200134,-116.806976,0.007903,0.003446,0.087520,254.438904,12.961736,0.875204,-116.806976,0.087572,0.000000
86.350006,57.185242,-116.895943,0.007894,0.003446,0.087520,254.372665,12.958361,0.875204,-116.895943,0.087572,0.000000
86.570007,57.149490,-116.940422,0.007894,0.003446,0.087520,254.213623,12.950259,0.875204,-116.940422,0.087572,0.000000
86.790001,57.137207,-116.984901,0.007903,0.003446,0.087520,254.158997,12.947476,0.875204,-116.984901,0.087572,0.000000
87.010002,57.091400,-116.940422,0.007899,0.003446,0.087520,253.955231,12.937097,0.875204,-116.940422,0.087572,0.000000
87.230003,57.083580,-116.851456,0.007903,0.003446,0.087520,253.920441,12.935325,0.875204,-116.851456,0.087572,0.000000
87.450005,57.065712,-116.895943,0.007899,0.003446,0.087520,253.840958,12.931275,0.875204,-116.895943,0.087572,0.000000
87.670006,57.046715,-116.895943,0.007899,0.003446,0.087520,253.756454,12.926970,0.875204,-116.895943,0.087572,0.000000
87.890007,57.025864,-116.940422,0.007899,0.003446,0.087520,253.663712,12.922245,0.875204,-116.940422,0.087572,0.000000
88.110001,57.001289,-116.940422,0.007916,0.003446,0.087520,253.554398,12.916677,0.875204,-116.940422,0.087572,0.000000
88.330002,56.988258,-116.940422,0.007894,0.003446,0.087520,253.496429,12.913724,0.875204,-116.940422,0.087572,0.000000
88.550003,56.964050,-116.940422,0.007903,0.003446,0.087520,253.388748,12.908237,0.875204,-116.940422,0.087572,0.000000
88.770004,56.939102,-116.940422,0.007903,0.003446,0.087520,253.277771,12.902585,0.875204,-116.940422,0.087572,0.000000
88.990005,56.923836,-117.029381,0.007894,0.003446,0.087520,253.209869,12.899126,0.875204,-117.029381,0.087572,0.000000
89.210007,56.902985,-116.940422,0.007916,0.003446,0.087520,253.117111,12.894401,0.875204,-116.940422,0.087572,0.000000
89.430008,56.882133,-116.940422,0.007894,0.003446,0.087520,253.024368,12.889676,0.875204,-116.940422,0.087572,0.000000
89.650002,56.869469,-116.984901,0.007894,0.003446,0.087520,252.968033,12.886806,0.875204,-116.984901,0.087572,0.000000
89.870003,56.841171,-116.984901,0.007903,0.003446,0.087520,252.842163,12.880393,0.875204,-116.984901,0.087572,0.000000
90.090004,56.837074,-116.984901,0.007899,0.003446,0.087520,252.823929,12.879465,0.875204,-116.984901,0.087572,0.000000
90.310005,56.810631,-116.984901,0.007912,0.003446,0.087520,252.706314,12.873473,0.875204,-116.984901,0.087572,0.000000
90.530006,56.784195,-116.984901,0.007903,0.003446,0.087520,252.588715,12.867482,0.875204,-116.984901,0.087572,0.000000
90.750008,56.777496,-116.984901,0.007903,0.003446,0.087520,252.558914,12.865964,0.875204,-116.984901,0.087572,0.000000
90.970001,56.755150,-117.073860,0.007907,0.003446,0.087520,252.459518,12.860900,0.875204,-117.073860,0.087572,0.000000
91.190002,56.727592,-117.029381,0.007899,0.003446,0.087520,252.336929,12.854656,0.875204,-117.029381,0.087572,0.000000
91.410004,56.714935,-117.029381,0.007899,0.003446,0.087520,252.280640,12.851789,0.875204,-117.029381,0.087572,0.000000
91.630005,56.694084,-116.984901,0.007899,0.003446,0.087520,252.187881,12.847063,0.875204,-116.984901,0.087572,0.000000
91.850006,56.676208,-116.984901,0.007894,0.003446,0.087520,252.108368,12.843012,0.875204,-116.984901,0.087572,0.000000
92.070007,56.653496,-117.118347,0.007899,0.003446,0.087520,252.007339,12.837866,0.875204,-117.118347,0.087572,0.000000
92.290001,56.636734,-117.073860,0.007890,0.003446,0.087520,251.932770,12.834067,0.875204,-117.073860,0.087572,0.000000
92.400002,56.624817,-117.073860,0.007890,0.003446,0.087520,251.879761,12.831367,0.875204,-117.073860,0.087572,0.000000