File: Data/compression 4 4 days/AutoNoheating-15-4-4-240226_02262024_163353.csv
Time (sec),S:Load (lbs),S:HL1 (DIM),S:LVDT (in),S:Position (in),Ch:Position (mm),Ch:Load (N),Ch:Stress (MPa),Ch:Strain (mm/mm),Ch:HL1 (DIM),Set Point (),Cycles ()
0.110000,-0.008568,-124.235298,0.000000,-0.000000,-0.000000,-0.038112,-0.001941,-0.000000,-124.235298,0.000191,0.000000
0.320000,-0.014153,-124.235298,-0.000004,-0.000000,-0.000000,-0.062954,-0.003207,-0.000000,-124.235298,0.000191,0.000000
0.530000,-0.016014,-124.190819,0.000004,0.000071,0.001795,-0.071234,-0.003629,0.017952,-124.190819,0.002255,0.000000
0.740000,-0.018623,-124.190819,0.000047,0.000186,0.004727,-0.082841,-0.004220,0.047266,-124.190819,0.005758,0.000000
0.950000,-0.022720,-124.146332,0.000172,0.000324,0.008230,-0.101065,-0.005149,0.082299,-124.146332,0.009245,0.000000
1.160000,-0.033516,-124.235298,0.000319,0.000463,0.011768,-0.149086,-0.007595,0.117684,-124.235298,0.012748,0.000000
1.370000,-0.031654,-124.190819,0.000444,0.000598,0.015185,-0.140806,-0.007173,0.151854,-124.190819,0.016252,0.000000
1.580000,-0.019363,-124.190819,0.000573,0.000729,0.018515,-0.086133,-0.004388,0.185153,-124.190819,0.019738,0.000000
1.790000,-0.030167,-124.235298,0.000707,0.000869,0.022071,-0.134188,-0.006836,0.220709,-124.235298,0.023242,0.000000
2.000000,-0.028679,-124.235298,0.000867,0.001014,0.025748,-0.127570,-0.006499,0.257479,-124.235298,0.026745,0.000000
2.210000,-0.007454,-124.235298,0.001000,0.001151,0.029225,-0.033157,-0.001689,0.292254,-124.235298,0.030249,0.000000
2.420000,-0.002609,-124.235298,0.001134,0.001289,0.032747,-0.011607,-0.000591,0.327465,-124.235298,0.033735,0.000000
2.630000,-0.010056,-124.235298,0.001276,0.001421,0.036103,-0.044729,-0.002279,0.361026,-124.235298,0.037239,0.000000
2.840000,0.002602,-124.235298,0.001406,0.001559,0.039606,0.011573,0.000590,0.396063,-124.235298,0.040743,0.000000
3.050000,-0.003357,-124.279778,0.001535,0.001693,0.043006,-0.014932,-0.000761,0.430059,-124.279778,0.044229,0.000000
3.260000,-0.014526,-124.324257,0.001703,0.001836,0.046631,-0.064617,-0.003292,0.466307,-124.324257,0.047732,0.000000
3.470000,-0.019737,-124.324257,0.001837,0.001973,0.050126,-0.087796,-0.004473,0.501256,-124.324257,0.051236,0.000000
3.680000,0.014145,-124.279778,0.001970,0.002110,0.053594,0.062920,0.003205,0.535945,-124.279778,0.054739,0.000000
3.890000,0.024948,-124.235298,0.002108,0.002251,0.057185,0.110975,0.005653,0.571848,-124.235298,0.058226,0.000000
4.100000,0.381676,-124.324257,0.002238,0.002388,0.060654,1.697778,0.086489,0.606537,-124.324257,0.061729,0.000000
4.310000,0.741020,-124.279778,0.002289,-0.000000,-0.000009,3.296222,0.167918,-0.000087,-124.279778,0.000156,0.000000
4.520000,0.714577,-124.324257,0.002276,-0.000001,-0.000017,3.178596,0.161925,-0.000174,-124.324257,0.000156,0.000000
4.730000,0.759636,-124.324257,0.002294,-0.000001,-0.000026,3.379029,0.172136,-0.000261,-124.324257,0.000243,0.000000
4.940000,0.673615,-124.368736,0.002289,-0.000001,-0.000017,2.996387,0.152643,-0.000174,-124.368736,0.000590,0.000000
5.150000,0.670639,-124.324257,0.002276,-0.000001,-0.000017,2.983151,0.151969,-0.000174,-124.324257,0.000945,0.000000
5.360000,0.828896,-124.279778,0.002302,0.000021,0.000537,3.687112,0.187830,0.005375,-124.279778,0.001292,0.000000
5.570000,1.069450,-124.368736,0.002320,0.000037,0.000945,4.757153,0.242341,0.009451,-124.368736,0.001639,0.000000
5.780000,1.251167,-124.235298,0.002320,0.000052,0.001327,5.565470,0.283519,0.013266,-124.235298,0.001995,0.000000
5.990000,1.347237,-124.368736,0.002337,0.000062,0.001587,5.992808,0.305288,0.015870,-124.368736,0.002341,0.000000
6.200000,1.454857,-124.324257,0.002350,0.000072,0.001838,6.471527,0.329675,0.018383,-124.324257,0.002697,0.000000
6.410000,1.605293,-124.368736,0.002363,0.000087,0.002220,7.140701,0.363765,0.022198,-124.368736,0.003044,0.000000
6.620000,1.800415,-124.413223,0.002371,0.000103,0.002610,8.008646,0.407980,0.026101,-124.413223,0.003391,0.000000
6.830000,1.969475,-124.368736,0.002397,0.000116,0.002957,8.760661,0.446289,0.029571,-124.368736,0.003746,0.000000
7.040000,2.148956,-124.413223,0.002410,0.000131,0.003321,9.559035,0.486960,0.033212,-124.413223,0.004093,0.000000
7.250000,2.334030,-124.413223,0.002406,0.000145,0.003677,10.382285,0.528899,0.036770,-124.413223,0.004440,0.000000
7.460001,2.446480,-124.413223,0.002436,0.000153,0.003894,10.882485,0.554380,0.038939,-124.413223,0.004795,0.000000
7.670001,2.694481,-124.457703,0.002427,0.000172,0.004371,11.985650,0.610578,0.043708,-124.457703,0.005143,0.000000
7.880001,2.876945,-124.413223,0.002445,0.000186,0.004726,12.797293,0.651925,0.047262,-124.413223,0.005489,0.000000
8.090000,2.956261,-124.457703,0.002453,0.000195,0.004960,13.150105,0.669898,0.049605,-124.457703,0.005845,0.000000
8.300000,3.118988,-124.368736,0.002475,0.000208,0.005290,13.873952,0.706773,0.052898,-124.368736,0.006192,0.000000
8.510000,3.302940,-124.413223,0.002488,0.000223,0.005672,14.692212,0.748457,0.056717,-124.413223,0.006547,0.000000
8.720000,3.508118,-124.413223,0.002496,0.000238,0.006053,15.604887,0.794951,0.060532,-124.413223,0.006894,0.000000
8.930000,3.648872,-124.457703,0.002505,0.000251,0.006374,16.230995,0.826846,0.063741,-124.457703,0.007241,0.000000
9.140000,3.833199,-124.457703,0.002522,0.000267,0.006781,17.050919,0.868615,0.067814,-124.457703,0.007597,0.000000
9.350000,3.841019,-124.457703,0.002522,0.000272,0.006920,17.085705,0.870387,0.069203,-124.457703,0.007944,0.000000
9.560000,4.135567,-124.502182,0.002557,0.000293,0.007432,18.395920,0.937133,0.074320,-124.502182,0.008290,0.000000
9.770000,4.299034,-124.546661,0.002552,0.000308,0.007814,19.123058,0.974175,0.078135,-124.546661,0.008646,0.000000
9.980000,4.440536,-124.457703,0.002587,0.000321,0.008152,19.752493,1.006240,0.081519,-124.457703,0.008993,0.000000
10.190001,4.514267,-124.502182,0.002591,0.000334,0.008472,20.080462,1.022948,0.084725,-124.502182,0.009340,0.000000
10.400001,4.623001,-124.457703,0.002591,0.000347,0.008811,20.564137,1.047587,0.088109,-124.457703,0.009695,0.000000
10.610001,4.722427,-124.502182,0.002617,0.000358,0.009097,21.006407,1.070117,0.090970,-124.502182,0.010042,0.000000
10.820001,4.895950,-124.502182,0.002634,0.000374,0.009487,21.778275,1.109438,0.094872,-124.502182,0.010398,0.000000
11.030001,5.046013,-124.502182,0.002647,0.000388,0.009852,22.445786,1.143443,0.098517,-124.502182,0.010745,0.000000
11.240001,5.105225,-124.546661,0.002656,0.000398,0.010120,22.709173,1.156860,0.101204,-124.546661,0.011092,0.000000
11.450001,5.294388,-124.502182,0.002665,0.000416,0.010554,23.550613,1.199725,0.105542,-124.502182,0.011447,0.000000
11.660001,5.462326,-124.457703,0.002695,0.000434,0.011014,24.297640,1.237781,0.110137,-124.457703,0.011794,0.000000
11.870001,5.498077,-124.546661,0.002695,0.000446,0.011335,24.456669,1.245882,0.113346,-124.546661,0.012141,0.000000
12.080001,5.520042,-124.502182,0.002716,0.000459,0.011647,24.554375,1.250859,0.116469,-124.502182,0.012497,0.000000
12.290001,5.599731,-124.591141,0.002716,0.000472,0.011976,24.908850,1.268917,0.119762,-124.591141,0.012844,0.000000
12.500001,5.628403,-124.502182,0.002738,0.000481,0.012228,25.036386,1.275414,0.122279,-124.502182,0.013190,0.000000
12.710001,5.711815,-124.502182,0.002751,0.000495,0.012566,25.407421,1.294316,0.125659,-124.502182,0.013546,0.000000
12.920001,5.953117,-124.546661,0.002751,0.000513,0.013034,26.480789,1.348996,0.130344,-124.546661,0.013893,0.000000
13.130001,5.990723,-124.546661,0.002772,0.000525,0.013346,26.648066,1.357517,0.133463,-124.546661,0.014240,0.000000
13.340001,6.022751,-124.635628,0.002785,0.000536,0.013615,26.790533,1.364775,0.136154,-124.635628,0.014595,0.000000
13.550000,6.146378,-124.591141,0.002807,0.000553,0.014057,27.340452,1.392789,0.140575,-124.591141,0.014942,0.000000
13.760000,6.258461,-124.546661,0.002820,0.000569,0.014456,27.839025,1.418187,0.144564,-124.546661,0.015298,0.000000
13.970000,6.239471,-124.591141,0.002824,0.000578,0.014691,27.754555,1.413885,0.146907,-124.591141,0.015644,0.000000
14.180000,6.312080,-124.591141,0.002850,0.000593,0.015072,28.077536,1.430338,0.150722,-124.591141,0.015992,0.000000
14.390000,6.337029,-124.591141,0.002863,0.000606,0.015393,28.188511,1.435991,0.153932,-124.591141,0.016347,0.000000
14.600000,6.440552,-124.546661,0.002867,0.000620,0.015757,28.649006,1.459450,0.157573,-124.546661,0.016694,0.000000
14.810000,6.593971,-124.680107,0.002884,0.000636,0.016147,29.331450,1.494215,0.161475,-124.680107,0.017041,0.000000
15.020000,6.609978,-124.591141,0.002897,0.000648,0.016460,29.402649,1.497842,0.164598,-124.591141,0.017397,0.000000
15.230000,6.570877,-124.635628,0.002915,0.000658,0.016720,29.228722,1.488982,0.167202,-124.635628,0.017743,0.000000
15.440001,6.812920,-124.635628,0.002932,0.000678,0.017214,30.305380,1.543830,0.172145,-124.635628,0.018090,0.000000
15.650001,6.961868,-124.591141,0.002945,0.000694,0.017639,30.967937,1.577582,0.176391,-124.591141,0.018446,0.000000
15.860001,6.935432,-124.591141,0.002962,0.000707,0.017951,30.850344,1.571591,0.179514,-124.591141,0.018793,0.000000
16.070002,6.840851,-124.635628,0.002962,0.000715,0.018168,30.429625,1.550159,0.181683,-124.635628,0.019148,0.000000
16.280001,6.895218,-124.591141,0.002988,0.000730,0.018532,30.671461,1.562479,0.185324,-124.591141,0.019495,0.000000
16.490002,6.942139,-124.680107,0.002988,0.000740,0.018801,30.880175,1.573111,0.188015,-124.680107,0.019842,0.000000
16.700001,7.218811,-124.635628,0.003005,0.000759,0.019287,32.110874,1.635806,0.192871,-124.635628,0.020198,0.000000
16.910002,7.268707,-124.680107,0.003027,0.000772,0.019608,32.332825,1.647113,0.196080,-124.680107,0.020544,0.000000
17.120001,7.285461,-124.724586,0.003044,0.000786,0.019963,32.407352,1.650909,0.199634,-124.724586,0.020891,0.000000
17.330000,7.346909,-124.680107,0.003061,0.000800,0.020310,32.680683,1.664833,0.203101,-124.680107,0.021247,0.000000
17.540001,7.507401,-124.724586,0.003065,0.000818,0.020779,33.394585,1.701201,0.207787,-124.724586,0.021594,0.000000
17.750000,7.557297,-124.680107,0.003087,0.000833,0.021152,33.616535,1.712508,0.211515,-124.680107,0.021941,0.000000
17.960001,7.467926,-124.680107,0.003091,0.000843,0.021403,33.218994,1.692256,0.214028,-124.680107,0.022296,0.000000
18.170000,7.428085,-124.724586,0.003113,0.000853,0.021655,33.041775,1.683228,0.216545,-124.724586,0.022643,0.000000
18.380001,7.701401,-124.724586,0.003122,0.000872,0.022149,34.257542,1.745162,0.221488,-124.724586,0.022999,0.000000
18.590000,7.793755,-124.724586,0.003143,0.000886,0.022496,34.668350,1.766090,0.224959,-124.724586,0.023346,0.000000
18.800001,7.836945,-124.724586,0.003139,0.000900,0.022860,34.860470,1.775877,0.228600,-124.724586,0.023692,0.000000
19.010000,7.818703,-124.724586,0.003165,0.000911,0.023129,34.779327,1.771743,0.231287,-124.724586,0.024048,0.000000
19.220001,7.792259,-124.769066,0.003160,0.000920,0.023363,34.661701,1.765751,0.233630,-124.769066,0.024395,0.000000
19.430000,8.052925,-124.635628,0.003191,0.000940,0.023875,35.821201,1.824819,0.238747,-124.635628,0.024742,0.000000
19.640001,8.190704,-124.724586,0.003208,0.000957,0.024308,36.434074,1.856040,0.243081,-124.724586,0.025097,0.000000
19.850000,8.099838,-124.680107,0.003208,0.000966,0.024525,36.029881,1.835450,0.245250,-124.680107,0.025444,0.000000
20.060001,8.144157,-124.680107,0.003225,0.000979,0.024855,36.227020,1.845492,0.248546,-124.680107,0.025791,0.000000
20.270000,8.172829,-124.724586,0.003242,0.000993,0.025210,36.354557,1.851990,0.252100,-124.724586,0.026147,0.000000
20.480001,8.335182,-124.769066,0.003260,0.001008,0.025600,37.076740,1.888779,0.256003,-124.769066,0.026494,0.000000
20.690001,8.554512,-124.769066,0.003277,0.001026,0.026051,38.052368,1.938480,0.260514,-124.769066,0.026849,0.000000
20.900002,8.485619,-124.769066,0.003285,0.001035,0.026285,37.745918,1.922869,0.262853,-124.769066,0.027196,0.000000
21.110001,8.521744,-124.769066,0.003303,0.001046,0.026580,37.906609,1.931055,0.265802,-124.769066,0.027543,0.000000
21.320002,8.613716,-124.813545,0.003311,0.001061,0.026953,38.315723,1.951896,0.269534,-124.813545,0.027898,0.000000
21.530001,8.707924,-124.769066,0.003328,0.001075,0.027300,38.734779,1.973244,0.273001,-124.769066,0.028246,0.000000
21.740002,8.737343,-124.769066,0.003341,0.001086,0.027595,38.865643,1.979910,0.275949,-124.769066,0.028592,0.000000
21.950001,8.811821,-124.769066,0.003346,0.001101,0.027976,39.196938,1.996787,0.279764,-124.769066,0.028948,0.000000
22.160002,9.018112,-124.769066,0.003372,0.001116,0.028358,40.114567,2.043533,0.283583,-124.769066,0.029295,0.000000
22.370001,9.162590,-124.813545,0.003380,0.001133,0.028766,40.757236,2.076272,0.287656,-124.813545,0.029642,0.000000
22.580002,9.152168,-124.813545,0.003393,0.001145,0.029078,40.710876,2.073911,0.290778,-124.813545,0.029997,0.000000
22.790001,9.060188,-124.858032,0.003406,0.001152,0.029260,40.301731,2.053068,0.292599,-124.858032,0.030344,0.000000
23.000002,9.266113,-124.769066,0.003402,0.001169,0.029685,41.217731,2.099731,0.296849,-124.769066,0.030691,0.000000
23.210001,9.374100,-124.769066,0.003436,0.001183,0.030049,41.698078,2.124201,0.300494,-124.769066,0.031047,0.000000
23.420002,9.683540,-124.902512,0.003445,0.001204,0.030587,43.074539,2.194322,0.305869,-124.902512,0.031393,0.000000
23.630001,9.598640,-124.813545,0.003462,0.001216,0.030890,42.696884,2.175083,0.308904,-124.813545,0.031749,0.000000
23.840002,9.655983,-124.858032,0.003479,0.001229,0.031229,42.951958,2.188077,0.312288,-124.858032,0.032096,0.000000
24.050001,9.645935,-124.813545,0.003479,0.001241,0.031524,42.907261,2.185800,0.315236,-124.813545,0.032443,0.000000
24.260000,9.762856,-124.902512,0.003501,0.001254,0.031845,43.427349,2.212295,0.318446,-124.902512,0.032798,0.000000
24.470001,9.964310,-124.902512,0.003518,0.001271,0.032278,44.323463,2.257945,0.322780,-124.902512,0.033145,0.000000
24.680000,10.079750,-124.813545,0.003544,0.001285,0.032651,44.836967,2.284104,0.326508,-124.813545,0.033492,0.000000
24.890001,9.951653,-124.902512,0.003544,0.001293,0.032850,44.267162,2.255077,0.328502,-124.902512,0.033848,0.000000
25.100000,9.949043,-124.902512,0.003540,0.001309,0.033249,44.255554,2.254485,0.332492,-124.902512,0.034195,0.000000
25.310001,10.535904,-124.902512,0.003570,0.001330,0.033778,46.866043,2.387470,0.337783,-124.902512,0.034541,0.000000
25.520000,10.488235,-124.902512,0.003587,0.001342,0.034099,46.654003,2.376668,0.340993,-124.902512,0.034897,0.000000
25.730001,10.377647,-124.858032,0.003591,0.001354,0.034403,46.162083,2.351609,0.344028,-124.858032,0.035244,0.000000
25.940001,10.524361,-124.902512,0.003617,0.001366,0.034706,46.814693,2.384854,0.347064,-124.902512,0.035600,0.000000
26.150002,10.578728,-124.902512,0.003622,0.001380,0.035044,47.056530,2.397174,0.350443,-124.902512,0.035946,0.000000
26.360001,10.890030,-124.902512,0.003648,0.001399,0.035539,48.441273,2.467716,0.355386,-124.902512,0.036293,0.000000
26.570002,10.877365,-124.946991,0.003652,0.001411,0.035842,48.384937,2.464846,0.358422,-124.946991,0.036649,0.000000
26.780001,10.933968,-124.902512,0.003652,0.001425,0.036198,48.636719,2.477673,0.361980,-124.902512,0.036996,0.000000
26.990002,11.205429,-124.902512,0.003695,0.001442,0.036614,49.844238,2.539187,0.366143,-124.902512,0.037343,0.000000
27.200001,11.348419,-124.946991,0.003704,0.001457,0.036996,50.480289,2.571589,0.369958,-124.946991,0.037698,0.000000
27.410002,11.165955,-124.946991,0.003712,0.001464,0.037187,49.668648,2.530241,0.371866,-124.946991,0.038045,0.000000
27.620001,11.252716,-124.946991,0.003699,0.001479,0.037568,50.054581,2.549902,0.375681,-124.946991,0.038392,0.000000
27.830002,11.368156,-124.902512,0.003734,0.001491,0.037872,50.568085,2.576061,0.378717,-124.902512,0.038747,0.000000
28.040001,11.531258,-124.946991,0.003760,0.001506,0.038262,51.293594,2.613020,0.382619,-124.946991,0.039095,0.000000
28.250002,11.714462,-124.991470,0.003755,0.001522,0.038661,52.108532,2.654535,0.386608,-124.991470,0.039450,0.000000
28.460001,11.864159,-124.946991,0.003773,0.001537,0.039034,52.774414,2.688457,0.390336,-124.946991,0.039797,0.000000
28.670002,11.770317,-125.035950,0.003790,0.001545,0.039250,52.356987,2.667192,0.392505,-125.035950,0.040144,0.000000
28.880001,12.024651,-124.991470,0.003790,0.001563,0.039693,53.488316,2.724825,0.396930,-124.991470,0.040499,0.000000
29.090002,12.244347,-124.946991,0.003816,0.001578,0.040083,54.465572,2.774609,0.400832,-124.946991,0.040846,0.000000
29.300001,12.305046,-124.991470,0.003807,0.001590,0.040395,54.735580,2.788363,0.403954,-124.991470,0.041193,0.000000
29.510002,12.267433,-124.991470,0.003842,0.001601,0.040673,54.568268,2.779840,0.406729,-124.991470,0.041549,0.000000
29.720001,12.422340,-125.035950,0.003837,0.001615,0.041020,55.257328,2.814943,0.410196,-125.035950,0.041895,0.000000
29.930002,12.453247,-125.035950,0.003859,0.001625,0.041271,55.394810,2.821946,0.412713,-125.035950,0.042242,0.000000
30.140001,12.830833,-124.991470,0.003867,0.001644,0.041757,57.074398,2.907509,0.417569,-124.991470,0.042598,0.000000
30.350002,12.895996,-124.991470,0.003885,0.001657,0.042078,57.364254,2.922275,0.420778,-124.991470,0.042945,0.000000
30.560001,12.944778,-125.035950,0.003889,0.001669,0.042390,57.581249,2.933329,0.423897,-125.035950,0.043292,0.000000
30.770002,12.992447,-125.080437,0.003898,0.001680,0.042667,57.793289,2.944130,0.426675,-125.080437,0.043647,0.000000
30.980001,13.386414,-125.035950,0.003928,0.001698,0.043118,59.545742,3.033405,0.431183,-125.035950,0.043994,0.000000
31.190001,13.611328,-125.080437,0.003949,0.001714,0.043543,60.546211,3.084371,0.435433,-125.080437,0.044350,0.000000
31.400002,13.606117,-125.124916,0.003949,0.001725,0.043821,60.523033,3.083190,0.438208,-125.124916,0.044697,0.000000
31.610001,13.727509,-125.080437,0.003962,0.001740,0.044185,61.063007,3.110698,0.441849,-125.080437,0.045044,0.000000
31.820002,13.702187,-125.080437,0.003975,0.001750,0.044445,60.950371,3.104960,0.444453,-125.080437,0.045399,0.000000
32.030003,13.860817,-125.080437,0.003992,0.001763,0.044775,61.655994,3.140906,0.447749,-125.080437,0.045746,0.000000
32.240002,14.097275,-125.080437,0.004001,0.001777,0.045148,62.707809,3.194488,0.451477,-125.080437,0.046093,0.000000
32.450001,14.243988,-125.080437,0.004001,0.001790,0.045469,63.360424,3.227734,0.454687,-125.080437,0.046449,0.000000
32.660000,14.111794,-125.080437,0.004027,0.001797,0.045651,62.772392,3.197778,0.456508,-125.080437,0.046795,0.000000
32.870003,14.892662,-125.169395,0.004040,0.001823,0.046310,66.245872,3.374726,0.463097,-125.169395,0.047142,0.000000
33.080002,15.085175,-125.169395,0.004057,0.001839,0.046709,67.102211,3.418350,0.467086,-125.169395,0.047498,0.000000
33.290001,15.038261,-125.124916,0.004070,0.001850,0.046977,66.893524,3.407719,0.469774,-125.124916,0.047845,0.000000
33.500000,15.189438,-125.169395,0.004074,0.001864,0.047342,67.565994,3.441976,0.473418,-125.169395,0.048200,0.000000
33.710003,15.083687,-125.124916,0.004109,0.001873,0.047584,67.095589,3.418012,0.475845,-125.124916,0.048547,0.000000
33.920002,15.230026,-125.169395,0.004105,0.001886,0.047914,67.746544,3.451173,0.479141,-125.169395,0.048894,0.000000
34.130001,15.597191,-125.169395,0.004122,0.001903,0.048348,69.379768,3.534374,0.483479,-125.169395,0.049250,0.000000
34.340000,15.670547,-125.124916,0.004117,0.001914,0.048608,69.706078,3.550997,0.486079,-125.124916,0.049597,0.000000
34.550003,15.845932,-125.169395,0.004135,0.001927,0.048938,70.486229,3.590739,0.489376,-125.169395,0.049944,0.000000
34.760002,16.071220,-125.169395,0.004174,0.001941,0.049310,71.488358,3.641791,0.493104,-125.169395,0.050299,0.000000
34.970001,16.402634,-125.213875,0.004161,0.001959,0.049752,72.962555,3.716890,0.497524,-125.213875,0.050646,0.000000
35.180000,16.518440,-125.080437,0.004195,0.001970,0.050039,73.477692,3.743132,0.500390,-125.080437,0.050993,0.000000
35.390003,16.815216,-125.213875,0.004195,0.001988,0.050490,74.797813,3.810382,0.504897,-125.213875,0.051348,0.000000
35.600002,16.808517,-125.213875,0.004191,0.001997,0.050724,74.768021,3.808865,0.507240,-125.213875,0.051695,0.000000
35.810001,16.754898,-125.124916,0.004221,0.002008,0.051010,74.529510,3.796714,0.510102,-125.124916,0.052051,0.000000
36.020000,17.086304,-125.258362,0.004221,0.002023,0.051383,76.003677,3.871812,0.513830,-125.258362,0.052398,0.000000
36.230003,17.444153,-125.213875,0.004251,0.002038,0.051773,77.595467,3.952902,0.517732,-125.213875,0.052744,0.000000
36.440002,17.588638,-125.213875,0.004255,0.002050,0.052077,78.238174,3.985642,0.520768,-125.213875,0.053100,0.000000
36.650002,17.678749,-125.213875,0.004260,0.002062,0.052363,78.639000,4.006062,0.523629,-125.213875,0.053447,0.000000
36.860001,18.172516,-125.258362,0.004277,0.002078,0.052771,80.835388,4.117951,0.527705,-125.258362,0.053794,0.000000
37.070004,18.666656,-125.213875,0.004294,0.002097,0.053256,83.033432,4.229925,0.532561,-125.213875,0.054149,0.000000
37.280003,18.644684,-125.213875,0.004307,0.002109,0.053568,82.935699,4.224946,0.535684,-125.213875,0.054496,0.000000
37.490002,18.674850,-125.213875,0.004320,0.002121,0.053872,83.069885,4.231781,0.538719,-125.213875,0.054843,0.000000
37.700001,18.865501,-125.169395,0.004333,0.002133,0.054184,83.917938,4.274984,0.541842,-125.169395,0.055199,0.000000
37.910004,19.009613,-125.258362,0.004324,0.002147,0.054540,84.558983,4.307640,0.545396,-125.258362,0.055546,0.000000
38.120003,19.636314,-125.302841,0.004355,0.002165,0.054982,87.346687,4.449652,0.549820,-125.302841,0.055893,0.000000
38.330002,19.525345,-125.213875,0.004368,0.002172,0.055164,86.853073,4.424507,0.551641,-125.213875,0.056248,0.000000
38.540001,19.997513,-125.258362,0.004381,0.002189,0.055589,88.953377,4.531501,0.555891,-125.258362,0.056595,0.000000
38.750000,20.409355,-125.213875,0.004381,0.002206,0.056031,90.785347,4.624826,0.560312,-125.213875,0.056951,0.000000
38.960003,20.786575,-125.302841,0.004411,0.002222,0.056439,92.463303,4.710305,0.564388,-125.302841,0.057298,0.000000
39.170002,20.954514,-125.258362,0.004415,0.002235,0.056769,93.210335,4.748361,0.567685,-125.258362,0.057644,0.000000
39.380001,20.815987,-125.258362,0.004424,0.002245,0.057029,92.594131,4.716970,0.570285,-125.258362,0.058000,0.000000
39.590000,20.937386,-125.302841,0.004445,0.002255,0.057289,93.134140,4.744480,0.572889,-125.302841,0.058347,0.000000
39.800003,21.541000,-125.302841,0.004458,0.002274,0.057748,95.819153,4.881260,0.577484,-125.302841,0.058694,0.000000
40.010002,21.978165,-125.302841,0.004475,0.002289,0.058139,97.763756,4.980323,0.581386,-125.302841,0.059049,0.000000
40.220001,22.111473,-125.302841,0.004467,0.002300,0.058425,98.356743,5.010531,0.584248,-125.302841,0.059396,0.000000
40.430000,22.360588,-125.302841,0.004480,0.002314,0.058763,99.464867,5.066982,0.587631,-125.302841,0.059743,0.000000
40.640003,22.305855,-125.347321,0.004501,0.002324,0.059041,99.221397,5.054579,0.590406,-125.347321,0.060098,0.000000
40.850002,23.134377,-125.302841,0.004514,0.002344,0.059535,102.906845,5.242325,0.595349,-125.302841,0.060446,0.000000
41.060001,23.606918,-125.391800,0.004531,0.002359,0.059916,105.008820,5.349404,0.599164,-125.391800,0.060801,0.000000
41.270000,23.301949,-125.391800,0.004527,0.002366,0.060098,103.652245,5.280297,0.600985,-125.391800,0.061148,0.000000
41.480003,23.988228,-125.347321,0.004557,0.002386,0.060593,106.704964,5.435811,0.605928,-125.347321,0.061495,0.000000
41.690002,24.291718,-125.347321,0.004557,0.002397,0.060896,108.054955,5.504582,0.608963,-125.347321,0.061850,0.000000
41.900002,24.566154,-125.347321,0.004562,0.002411,0.061235,109.275711,5.566770,0.612347,-125.347321,0.062197,0.000000
42.110001,25.147797,-125.391800,0.004579,0.002427,0.061651,111.862984,5.698572,0.616510,-125.391800,0.062544,0.000000
42.320004,24.980972,-125.347321,0.004579,0.002436,0.061868,111.120918,5.660769,0.618679,-125.347321,0.062900,0.000000
42.530003,25.287811,-125.391800,0.004613,0.002449,0.062215,112.485802,5.730300,0.622146,-125.391800,0.063247,0.000000
42.740002,25.641937,-125.391800,0.004622,0.002462,0.062544,114.061035,5.810546,0.625443,-125.391800,0.063593,0.000000
42.950001,26.365829,-125.391800,0.004626,0.002480,0.062986,117.281067,5.974582,0.629863,-125.391800,0.063949,0.000000
43.160004,26.480888,-125.391800,0.004635,0.002492,0.063290,117.792877,6.000655,0.632899,-125.391800,0.064296,0.000000
43.370003,26.841347,-125.436279,0.004648,0.002504,0.063602,119.396271,6.082336,0.636021,-125.436279,0.064652,0.000000
43.580002,27.112061,-125.391800,0.004644,0.002516,0.063906,120.600471,6.143681,0.639057,-125.391800,0.064998,0.000000
43.790001,27.785683,-125.436279,0.004669,0.002534,0.064374,123.596886,6.296326,0.643739,-125.436279,0.065345,0.000000
44.000004,28.088425,-125.391800,0.004682,0.002548,0.064712,124.943550,6.364928,0.647122,-125.391800,0.065701,0.000000
44.210003,28.074646,-125.480766,0.004695,0.002557,0.064938,124.882263,6.361805,0.649378,-125.480766,0.066048,0.000000
44.420002,28.545700,-125.347321,0.004704,0.002571,0.065302,126.977615,6.468548,0.653019,-125.347321,0.066395,0.000000
44.630001,29.370872,-125.436279,0.004712,0.002590,0.065779,130.648163,6.655535,0.657788,-125.436279,0.066750,0.000000
44.840004,30.235153,-125.480766,0.004730,0.002609,0.066264,134.492676,6.851384,0.662644,-125.480766,0.067097,0.000000
45.050003,30.219887,-125.391800,0.004730,0.002618,0.066499,134.424774,6.847924,0.664987,-125.391800,0.067444,0.000000
45.260002,30.637688,-125.480766,0.004747,0.002631,0.066837,136.283249,6.942599,0.668371,-125.480766,0.067800,0.000000
45.470001,30.959412,-125.480766,0.004764,0.002646,0.067201,137.714340,7.015503,0.672012,-125.480766,0.068147,0.000000
45.680000,31.382057,-125.480766,0.004769,0.002662,0.067618,139.594360,7.111276,0.676175,-125.480766,0.068502,0.000000
45.890003,31.888481,-125.480766,0.004773,0.002674,0.067912,141.847046,7.226033,0.679124,-125.480766,0.068849,0.000000
46.100002,32.295860,-125.480766,0.004790,0.002688,0.068268,143.659164,7.318347,0.682678,-125.480766,0.069196,0.000000
46.310001,32.422470,-125.569725,0.004799,0.002696,0.068485,144.222351,7.347037,0.684846,-125.569725,0.069551,0.000000
46.520000,33.424149,-125.480766,0.004812,0.002717,0.069005,148.678040,7.574020,0.690051,-125.480766,0.069898,0.000000
46.730003,34.109688,-125.525246,0.004825,0.002732,0.069395,151.727463,7.729366,0.693953,-125.525246,0.070245,0.000000
46.940002,34.495094,-125.525246,0.004825,0.002746,0.069742,153.441849,7.816700,0.697420,-125.525246,0.070601,0.000000
47.150002,34.642181,-125.525246,0.004846,0.002756,0.070011,154.096115,7.850031,0.700111,-125.525246,0.070947,0.000000
47.360001,35.289360,-125.525246,0.004855,0.002773,0.070436,156.974915,7.996684,0.704361,-125.525246,0.071295,0.000000
47.570004,35.996872,-125.480766,0.004863,0.002788,0.070826,160.122086,8.157008,0.708264,-125.480766,0.071650,0.000000
47.780003,36.510002,-125.525246,0.004881,0.002802,0.071173,162.404602,8.273284,0.711731,-125.525246,0.071997,0.000000
47.990002,36.832100,-125.525246,0.004876,0.002814,0.071468,163.837357,8.346273,0.714679,-125.525246,0.072344,0.000000
48.200001,37.408531,-125.525246,0.004894,0.002831,0.071902,166.401459,8.476894,0.719016,-125.525246,0.072700,0.000000
48.410004,38.219185,-125.569725,0.004907,0.002845,0.072274,170.007431,8.660591,0.722745,-125.569725,0.073046,0.000000
48.620003,38.645554,-125.525246,0.004911,0.002858,0.072587,171.904007,8.757208,0.725867,-125.525246,0.073402,0.000000
48.830002,38.598267,-125.525246,0.004937,0.002867,0.072812,171.693665,8.746492,0.728123,-125.525246,0.073749,0.000000
49.040001,39.506477,-125.569725,0.004928,0.002884,0.073254,175.733582,8.952295,0.732544,-125.569725,0.074096,0.000000
49.250004,40.106743,-125.569725,0.004954,0.002898,0.073619,178.403702,9.088318,0.736189,-125.569725,0.074451,0.000000
49.460003,40.564392,-125.614204,0.004945,0.002912,0.073957,180.439423,9.192022,0.739568,-125.614204,0.074798,0.000000
49.670002,41.160561,-125.658684,0.004954,0.002925,0.074287,183.091324,9.327117,0.742865,-125.658684,0.075145,0.000000
49.880001,41.962646,-125.569725,0.004975,0.002941,0.074694,186.659180,9.508872,0.746941,-125.569725,0.075501,0.000000
50.090004,42.204315,-125.614204,0.004980,0.002949,0.074911,187.734177,9.563635,0.749110,-125.614204,0.075847,0.000000
50.300003,43.149025,-125.614204,0.004980,0.002967,0.075362,191.936447,9.777709,0.753618,-125.614204,0.076194,0.000000
50.510002,43.669235,-125.658684,0.004988,0.002980,0.075691,194.250458,9.895591,0.756915,-125.658684,0.076550,0.000000
50.720001,44.069160,-125.614204,0.005014,0.002992,0.075986,196.029419,9.986215,0.759863,-125.614204,0.076897,0.000000
50.930004,44.605003,-125.658684,0.005023,0.003004,0.076307,198.412964,10.107638,0.763069,-125.658684,0.077252,0.000000
51.140003,45.192604,-125.614204,0.005010,0.003019,0.076680,201.026749,10.240790,0.766801,-125.614204,0.077599,0.000000
51.350002,46.022629,-125.614204,0.005036,0.003034,0.077053,204.718872,10.428877,0.770529,-125.614204,0.077946,0.000000
51.560001,46.766998,-125.658684,0.005036,0.003047,0.077391,208.029999,10.597553,0.773913,-125.658684,0.078302,0.000000
51.770004,47.448441,-125.658684,0.005044,0.003061,0.077755,211.061203,10.751970,0.777554,-125.658684,0.078649,0.000000
51.980003,47.714684,-125.703171,0.005066,0.003069,0.077964,212.245514,10.812303,0.779635,-125.703171,0.078995,0.000000
52.190002,48.220741,-125.658684,0.005062,0.003084,0.078328,214.496567,10.926976,0.783276,-125.658684,0.079351,0.000000
52.400002,49.388504,-125.614204,0.005075,0.003103,0.078805,219.691040,11.191594,0.788045,-125.614204,0.079698,0.000000
52.610001,50.429657,-125.658684,0.005092,0.003118,0.079195,224.322311,11.427524,0.791948,-125.658684,0.080045,0.000000
52.820004,50.776703,-125.658684,0.005083,0.003130,0.079507,225.866058,11.506166,0.795070,-125.658684,0.080400,0.000000
53.030003,51.368774,-125.747650,0.005101,0.003142,0.079811,228.499725,11.640330,0.798106,-125.747650,0.080747,0.000000
53.240002,51.775780,-125.658684,0.005109,0.003153,0.080097,230.310165,11.732559,0.800967,-125.658684,0.081103,0.000000
53.450001,52.424828,-125.703171,0.005118,0.003166,0.080409,233.197281,11.879636,0.804090,-125.703171,0.081450,0.000000
53.660004,53.564659,-125.703171,0.005122,0.003182,0.080825,238.267502,12.137925,0.808253,-125.703171,0.081796,0.000000
53.870003,54.009270,-125.703171,0.005122,0.003193,0.081103,240.245224,12.238675,0.811027,-125.703171,0.082152,0.000000
54.080002,54.731300,-125.747650,0.005126,0.003208,0.081493,243.456985,12.402290,0.814930,-125.747650,0.082499,0.000000
54.290001,56.294518,-125.703171,0.005139,0.003228,0.081979,250.410522,12.756519,0.819786,-125.703171,0.082846,0.000000
54.500004,57.292107,-125.703171,0.005157,0.003243,0.082369,254.848022,12.982576,0.823692,-125.703171,0.083201,0.000000
54.710003,57.592239,-125.792130,0.005161,0.003253,0.082629,256.183075,13.050589,0.826292,-125.792130,0.083549,0.000000
54.920002,58.409599,-125.747650,0.005170,0.003266,0.082968,259.818878,13.235805,0.829675,-125.747650,0.083895,0.000000
55.130001,58.703400,-125.747650,0.005170,0.003277,0.083245,261.125763,13.302381,0.832450,-125.747650,0.084251,0.000000
55.340004,59.387444,-125.703171,0.005174,0.003288,0.083522,264.168549,13.457387,0.835224,-125.703171,0.084598,0.000000
55.550003,60.661331,-125.792130,0.005195,0.003306,0.083982,269.835083,13.746054,0.839819,-125.792130,0.084945,0.000000
55.760002,61.311867,-125.747650,0.005195,0.003318,0.084285,272.728790,13.893467,0.842854,-125.747650,0.085300,0.000000
55.970001,61.770630,-125.703171,0.005204,0.003329,0.084555,274.769470,13.997425,0.845546,-125.703171,0.085647,0.000000
56.180004,62.765236,-125.747650,0.005208,0.003344,0.084927,279.193726,14.222806,0.849274,-125.747650,0.086003,0.000000
56.390003,63.817932,-125.747650,0.005213,0.003359,0.085309,283.876343,14.461350,0.853089,-125.747650,0.086350,0.000000
56.600002,64.728378,-125.792130,0.005226,0.003373,0.085682,287.926208,14.667660,0.856817,-125.792130,0.086696,0.000000
56.810001,65.898758,-125.792130,0.005213,0.003390,0.086098,293.132324,14.932872,0.860980,-125.792130,0.087052,0.000000
57.020004,66.282288,-125.747650,0.005234,0.003399,0.086341,294.838348,15.019780,0.863410,-125.747650,0.087399,0.000000
57.230003,66.985703,-125.881088,0.005243,0.003411,0.086636,297.967285,15.179177,0.866359,-125.881088,0.087746,0.000000
57.440002,67.166306,-125.792130,0.005251,0.003409,0.086601,298.770660,15.220102,0.866010,-125.792130,0.086835,0.000000
57.650002,66.586899,-125.792130,0.005256,0.003409,0.086601,296.193329,15.088807,0.866010,-125.792130,0.086835,0.000000
57.860004,66.145630,-125.881088,0.005264,0.003407,0.086532,294.230469,14.988814,0.865318,-125.881088,0.086601,0.000000
58.070004,65.683899,-125.792130,0.005256,0.003406,0.086514,292.176575,14.884184,0.865144,-125.792130,0.086601,0.000000
58.280003,65.263855,-125.836609,0.005251,0.003405,0.086497,290.308136,14.789001,0.864970,-125.836609,0.086601,0.000000
58.490002,64.881805,-125.792130,0.005273,0.003405,0.086497,288.608673,14.702427,0.864970,-125.792130,0.086601,0.000000
58.700005,64.540329,-125.881088,0.005269,0.003405,0.086488,287.089722,14.625048,0.864883,-125.881088,0.086601,0.000000
58.910004,64.218613,-125.836609,0.005264,0.003405,0.086488,285.658661,14.552146,0.864883,-125.836609,0.086601,0.000000
59.120003,63.941940,-125.925575,0.005277,0.003405,0.086480,284.427948,14.489450,0.864796,-125.925575,0.086601,0.000000
59.330002,63.653351,-125.925575,0.005282,0.003405,0.086480,283.144257,14.424056,0.864796,-125.925575,0.086601,0.000000
59.540005,63.415405,-125.836609,0.005277,0.003405,0.086480,282.085815,14.370136,0.864796,-125.836609,0.086601,0.000000
59.750004,63.176712,-125.836609,0.005286,0.003405,0.086480,281.024048,14.316048,0.864796,-125.836609,0.086601,0.000000
59.960003,62.966316,-125.836609,0.005282,0.003405,0.086480,280.088165,14.268372,0.864796,-125.836609,0.086601,0.000000
60.170002,62.762260,-125.925575,0.005282,0.003405,0.086480,279.180481,14.222131,0.864796,-125.925575,0.086601,0.000000
60.380001,62.576813,-125.925575,0.005282,0.003404,0.086471,278.355560,14.180108,0.864708,-125.925575,0.086601,0.000000
60.590004,62.406639,-125.836609,0.005299,0.003404,0.086471,277.598602,14.141547,0.864708,-125.836609,0.086601,0.000000
60.800003,62.217476,-125.970055,0.005286,0.003404,0.086471,276.757141,14.098681,0.864708,-125.970055,0.086601,0.000000
61.010002,62.073738,-125.881088,0.005282,0.003404,0.086471,276.117767,14.066111,0.864708,-125.881088,0.086601,0.000000
61.220001,61.912132,-125.925575,0.005299,0.003404,0.086471,275.398926,14.029490,0.864708,-125.925575,0.086601,0.000000
61.430004,61.775467,-125.925575,0.005286,0.003404,0.086471,274.791016,13.998521,0.864708,-125.925575,0.086601,0.000000
61.640003,61.637321,-125.925575,0.005290,0.003404,0.086471,274.176514,13.967216,0.864708,-125.925575,0.086601,0.000000
61.850002,61.510338,-125.881088,0.005299,0.003404,0.086471,273.611633,13.938442,0.864708,-125.881088,0.086601,0.000000
62.060001,61.380753,-125.970055,0.005299,0.003404,0.086471,273.035217,13.909078,0.864708,-125.970055,0.086601,0.000000
62.270004,61.257500,-125.970055,0.005316,0.003404,0.086471,272.486969,13.881147,0.864708,-125.970055,0.086601,0.000000
62.480003,61.156212,-125.970055,0.005299,0.003404,0.086471,272.036407,13.858196,0.864708,-125.970055,0.086601,0.000000
62.690002,61.032219,-125.925575,0.005303,0.003404,0.086471,271.484863,13.830098,0.864708,-125.925575,0.086601,0.000000
62.900002,60.929443,-125.970055,0.005299,0.003404,0.086471,271.027710,13.806809,0.864708,-125.970055,0.086601,0.000000
63.110004,60.824806,-126.014534,0.005303,0.003404,0.086471,270.562256,13.783098,0.864708,-126.014534,0.086601,0.000000
63.320004,60.727615,-125.970055,0.005299,0.003404,0.086471,270.129913,13.761074,0.864708,-125.970055,0.086601,0.000000
63.530003,60.638245,-126.059013,0.005299,0.003404,0.086471,269.732391,13.740823,0.864708,-126.059013,0.086601,0.000000
63.740002,60.552971,-125.970055,0.005312,0.003404,0.086471,269.353058,13.721499,0.864708,-125.970055,0.086601,0.000000
63.950005,60.462860,-126.014534,0.005299,0.003404,0.086471,268.952240,13.701080,0.864708,-126.014534,0.086601,0.000000
64.160004,60.378326,-126.014534,0.005299,0.003404,0.086471,268.576202,13.681924,0.864708,-126.014534,0.086601,0.000000
64.370003,60.294548,-126.103493,0.005307,0.003404,0.086471,268.203552,13.662940,0.864708,-126.103493,0.086601,0.000000
64.580002,60.196236,-126.014534,0.005312,0.003404,0.086471,267.766235,13.640661,0.864708,-126.014534,0.086601,0.000000
64.790001,60.135918,-126.059013,0.005312,0.003404,0.086471,267.497925,13.626994,0.864708,-126.059013,0.086601,0.000000
65.000000,60.042450,-126.103493,0.005312,0.003404,0.086471,267.082153,13.605813,0.864708,-126.103493,0.086601,0.000000
65.210007,59.990692,-126.014534,0.005307,0.003404,0.086471,266.851929,13.594085,0.864708,-126.014534,0.086601,0.000000
65.420006,59.911003,-126.059013,0.005307,0.003404,0.086471,266.497437,13.576027,0.864708,-126.059013,0.086601,0.000000
65.630005,59.841743,-126.059013,0.005295,0.003404,0.086471,266.189362,13.560333,0.864708,-126.059013,0.086601,0.000000
65.840004,59.765404,-126.059013,0.005303,0.003404,0.086471,265.849792,13.543035,0.864708,-126.059013,0.086601,0.000000
66.050003,59.699120,-126.059013,0.005312,0.003404,0.086471,265.554932,13.528014,0.864708,-126.059013,0.086601,0.000000
66.260002,59.643265,-126.059013,0.005299,0.003404,0.086471,265.306488,13.515357,0.864708,-126.059013,0.086601,0.000000
66.470001,59.575119,-126.103493,0.005316,0.003404,0.086471,265.003357,13.499914,0.864708,-126.103493,0.086601,0.000000
66.680000,59.506233,-126.059013,0.005307,0.003404,0.086471,264.696960,13.484305,0.864708,-126.059013,0.086601,0.000000
66.889999,59.436226,-126.014534,0.005312,0.003404,0.086471,264.385529,13.468441,0.864708,-126.014534,0.086601,0.000000
67.100006,59.377396,-126.103493,0.005303,0.003404,0.086471,264.123840,13.455111,0.864708,-126.103493,0.086601,0.000000
67.310005,59.333076,-126.059013,0.005307,0.003404,0.086471,263.926697,13.445067,0.864708,-126.059013,0.086601,0.000000
67.520004,59.263077,-126.103493,0.005307,0.003404,0.086471,263.615326,13.429205,0.864708,-126.103493,0.086601,0.000000
67.730003,59.219131,-126.014534,0.005316,0.003404,0.086471,263.419861,13.419248,0.864708,-126.014534,0.086601,0.000000
67.940002,59.162903,-126.147980,0.005320,0.003404,0.086471,263.169739,13.406506,0.864708,-126.147980,0.086601,0.000000
68.150002,59.106308,-126.236938,0.005316,0.003404,0.086471,262.917999,13.393681,0.864708,-126.236938,0.086601,0.000000
68.360001,59.068695,-126.103493,0.005312,0.003404,0.086471,262.750671,13.385158,0.864708,-126.103493,0.086601,0.000000
68.570000,59.001297,-126.192459,0.005312,0.003404,0.086471,262.450867,13.369885,0.864708,-126.192459,0.086601,0.000000
68.780006,58.962570,-126.147980,0.005307,0.003404,0.086471,262.278625,13.361109,0.864708,-126.147980,0.086601,0.000000
68.990005,58.917137,-126.147980,0.005325,0.003404,0.086471,262.076508,13.350814,0.864708,-126.147980,0.086601,0.000000
69.200005,58.860909,-126.103493,0.005320,0.003404,0.086471,261.826385,13.338073,0.864708,-126.103493,0.086601,0.000000
69.410004,58.822182,-126.147980,0.005325,0.003404,0.086471,261.654144,13.329297,0.864708,-126.147980,0.086601,0.000000
69.620003,58.762978,-126.192459,0.005312,0.003404,0.086471,261.390778,13.315882,0.864708,-126.192459,0.086601,0.000000
69.830002,58.746223,-126.147980,0.005325,0.003404,0.086471,261.316254,13.312085,0.864708,-126.147980,0.086601,0.000000
70.040001,58.678078,-126.236938,0.005307,0.003404,0.086471,261.013123,13.296642,0.864708,-126.236938,0.086601,0.000000
70.250000,58.641586,-126.147980,0.005320,0.003404,0.086471,260.850800,13.288374,0.864708,-126.147980,0.086601,0.000000
70.460007,58.602486,-126.192459,0.005312,0.003404,0.086471,260.676880,13.279513,0.864708,-126.192459,0.086601,0.000000
70.670006,58.547005,-126.236938,0.005320,0.003404,0.086471,260.430084,13.266940,0.864708,-126.236938,0.086601,0.000000
70.880005,58.512001,-126.192459,0.005307,0.003404,0.086471,260.274384,13.259008,0.864708,-126.192459,0.086601,0.000000
71.090004,58.462471,-126.236938,0.005312,0.003404,0.086471,260.054047,13.247786,0.864708,-126.236938,0.086601,0.000000
71.300003,58.434547,-126.236938,0.005316,0.003404,0.086471,259.929840,13.241457,0.864708,-126.236938,0.086601,0.000000
71.510002,58.393959,-126.192459,0.005320,0.003404,0.086471,259.749298,13.232260,0.864708,-126.192459,0.086601,0.000000
71.720001,58.366776,-126.281418,0.005312,0.003404,0.086471,259.628387,13.226100,0.864708,-126.281418,0.086601,0.000000
71.930000,58.326927,-126.192459,0.005325,0.003404,0.086471,259.451141,13.217071,0.864708,-126.192459,0.086601,0.000000
72.140007,58.276657,-126.236938,0.005329,0.003404,0.086471,259.227509,13.205680,0.864708,-126.236938,0.086601,0.000000
72.350006,58.254692,-126.236938,0.005312,0.003404,0.086471,259.129822,13.200702,0.864708,-126.236938,0.086601,0.000000
72.560005,58.212982,-126.236938,0.005320,0.003404,0.086471,258.944275,13.191250,0.864708,-126.236938,0.086601,0.000000
72.770004,58.180214,-126.281418,0.005312,0.003404,0.086471,258.798523,13.183825,0.864708,-126.281418,0.086601,0.000000
72.980003,58.150421,-126.281418,0.005316,0.003404,0.086471,258.665985,13.177073,0.864708,-126.281418,0.086601,0.000000
73.190002,58.110207,-126.325897,0.005312,0.003404,0.086471,258.487122,13.167961,0.864708,-126.325897,0.086601,0.000000
73.400002,58.087868,-126.281418,0.005307,0.003404,0.086471,258.387726,13.162899,0.864708,-126.281418,0.086601,0.000000
73.610001,58.053978,-126.281418,0.005325,0.003404,0.086471,258.237000,13.155220,0.864708,-126.281418,0.086601,0.000000
73.820000,58.021584,-126.325897,0.005307,0.003404,0.086471,258.092896,13.147879,0.864708,-126.325897,0.086601,0.000000
74.030006,57.989929,-126.281418,0.005333,0.003404,0.086471,257.952087,13.140706,0.864708,-126.281418,0.086601,0.000000
74.240005,57.973923,-126.325897,0.005320,0.003404,0.086471,257.880890,13.137078,0.864708,-126.325897,0.086601,0.000000
74.450005,57.942642,-126.236938,0.005320,0.003404,0.086471,257.741760,13.129990,0.864708,-126.236938,0.086601,0.000000
74.660004,57.895348,-126.281418,0.005316,0.003404,0.086471,257.531372,13.119273,0.864708,-126.281418,0.086601,0.000000
74.870003,57.876732,-126.325897,0.005325,0.003404,0.086471,257.448547,13.115055,0.864708,-126.325897,0.086601,0.000000
75.080002,57.845451,-126.236938,0.005325,0.003404,0.086471,257.309418,13.107966,0.864708,-126.236938,0.086601,0.000000
75.290001,57.811195,-126.325897,0.005316,0.003404,0.086471,257.157043,13.100204,0.864708,-126.325897,0.086601,0.000000
75.500000,57.784386,-126.325897,0.005329,0.003404,0.086471,257.037781,13.094130,0.864708,-126.325897,0.086601,0.000000
75.710007,57.758316,-126.325897,0.005325,0.003404,0.086471,256.921814,13.088222,0.864708,-126.325897,0.086601,0.000000
75.920006,57.738579,-126.325897,0.005316,0.003404,0.086471,256.834015,13.083749,0.864708,-126.325897,0.086601,0.000000
76.130005,57.714752,-126.325897,0.005316,0.003404,0.086471,256.728027,13.078350,0.864708,-126.325897,0.086601,0.000000
76.340004,57.673790,-126.325897,0.005316,0.003404,0.086471,256.545837,13.069067,0.864708,-126.325897,0.086601,0.000000
76.550003,57.661499,-126.370384,0.005329,0.003404,0.086471,256.491150,13.066282,0.864708,-126.370384,0.086601,0.000000
76.760002,57.610481,-126.414864,0.005333,0.003404,0.086471,256.264221,13.054722,0.864708,-126.414864,0.086601,0.000000
76.970001,57.594101,-126.414864,0.005325,0.003404,0.086471,256.191345,13.051009,0.864708,-126.414864,0.086601,0.000000
77.180000,57.564682,-126.325897,0.005316,0.003404,0.086471,256.060486,13.044343,0.864708,-126.325897,0.086601,0.000000
77.390007,57.543083,-126.414864,0.005325,0.003404,0.086471,255.964417,13.039450,0.864708,-126.414864,0.086601,0.000000
77.600006,57.520370,-126.370384,0.005316,0.003404,0.086471,255.863388,13.034303,0.864708,-126.370384,0.086601,0.000000
77.810005,57.486488,-126.370384,0.005325,0.003404,0.086471,255.712677,13.026624,0.864708,-126.370384,0.086601,0.000000
78.020004,57.466003,-126.414864,0.005316,0.003404,0.086471,255.621552,13.021982,0.864708,-126.414864,0.086601,0.000000
78.230003,57.441803,-126.370384,0.005333,0.003404,0.086471,255.513901,13.016499,0.864708,-126.370384,0.086601,0.000000
78.440002,57.421692,-126.414864,0.005320,0.003404,0.086471,255.424438,13.011942,0.864708,-126.414864,0.086601,0.000000
78.650002,57.411636,-126.370384,0.005312,0.003404,0.086471,255.379715,13.009663,0.864708,-126.370384,0.086601,0.000000
78.860001,57.364716,-126.459343,0.005329,0.003404,0.086471,255.171005,12.999030,0.864708,-126.459343,0.086601,0.000000
79.070007,57.356529,-126.414864,0.005320,0.003404,0.086471,255.134583,12.997175,0.864708,-126.414864,0.086601,0.000000
79.280006,57.320778,-126.414864,0.005329,0.003404,0.086471,254.975555,12.989074,0.864708,-126.414864,0.086601,0.000000
79.490005,57.308861,-126.503822,0.005325,0.003404,0.086471,254.922546,12.986373,0.864708,-126.503822,0.086601,0.000000
79.700005,57.291733,-126.414864,0.005325,0.003404,0.086471,254.846359,12.982492,0.864708,-126.414864,0.086601,0.000000
79.910004,57.258217,-126.459343,0.005320,0.003404,0.086471,254.697266,12.974897,0.864708,-126.459343,0.086601,0.000000
80.120003,57.247795,-126.414864,0.005329,0.003404,0.086471,254.650909,12.972536,0.864708,-126.414864,0.086601,0.000000
80.330002,57.223221,-126.459343,0.005329,0.003404,0.086471,254.541595,12.966967,0.864708,-126.459343,0.086601,0.000000
80.540001,57.204224,-126.503822,0.005316,0.003404,0.086471,254.457092,12.962662,0.864708,-126.503822,0.086601,0.000000
80.750008,57.188583,-126.459343,0.005325,0.003404,0.086471,254.387527,12.959118,0.864708,-126.459343,0.086601,0.000000
80.960007,57.160286,-126.503822,0.005320,0.003404,0.086471,254.261658,12.952706,0.864708,-126.503822,0.086601,0.000000
81.170006,57.153214,-126.503822,0.005320,0.003404,0.086471,254.230194,12.951103,0.864708,-126.503822,0.086601,0.000000
81.380005,57.120811,-126.459343,0.005329,0.003404,0.086471,254.086060,12.943761,0.864708,-126.459343,0.086601,0.000000
81.590004,57.102196,-126.459343,0.005320,0.003404,0.086471,254.003250,12.939542,0.864708,-126.459343,0.086601,0.000000
81.800003,57.086929,-126.503822,0.005325,0.003404,0.086471,253.935349,12.936083,0.864708,-126.503822,0.086601,0.000000
82.010002,57.066078,-126.548309,0.005329,0.003404,0.086471,253.842590,12.931358,0.864708,-126.548309,0.086601,0.000000
82.220001,57.047455,-126.503822,0.005329,0.003404,0.086471,253.759750,12.927138,0.864708,-126.503822,0.086601,0.000000
82.430000,57.016922,-126.548309,0.005329,0.003404,0.086471,253.623932,12.920218,0.864708,-126.548309,0.086601,0.000000
82.640007,56.999794,-126.503822,0.005329,0.003404,0.086471,253.547745,12.916338,0.864708,-126.503822,0.086601,0.000000
82.850006,56.981918,-126.503822,0.005329,0.003404,0.086471,253.468231,12.912287,0.864708,-126.503822,0.086601,0.000000
83.060005,56.960693,-126.548309,0.005333,0.003404,0.086471,253.373825,12.907477,0.864708,-126.548309,0.086601,0.000000
83.270004,56.957718,-126.503822,0.005325,0.003404,0.086471,253.360580,12.906803,0.864708,-126.503822,0.086601,0.000000
83.480003,56.937233,-126.592789,0.005325,0.003404,0.086471,253.269455,12.902162,0.864708,-126.592789,0.086601,0.000000
83.690002,56.926064,-126.548309,0.005329,0.003404,0.086471,253.219772,12.899631,0.864708,-126.548309,0.086601,0.000000
83.900002,56.895531,-126.503822,0.005333,0.003404,0.086471,253.083954,12.892711,0.864708,-126.503822,0.086601,0.000000
84.110001,56.873558,-126.548309,0.005329,0.003404,0.086471,252.986221,12.887733,0.864708,-126.548309,0.086601,0.000000
84.320007,56.872818,-126.548309,0.005333,0.003404,0.086471,252.982925,12.887565,0.864708,-126.548309,0.086601,0.000000
84.530006,56.843399,-126.637268,0.005329,0.003404,0.086471,252.852066,12.880898,0.864708,-126.637268,0.086601,0.000000
84.740005,56.831108,-126.548309,0.005307,0.003404,0.086471,252.797394,12.878113,0.864708,-126.548309,0.086601,0.000000
84.950005,56.810631,-126.592789,0.005333,0.003404,0.086471,252.706314,12.873473,0.864708,-126.592789,0.086601,0.000000
85.160004,56.788284,-126.548309,0.005325,0.003404,0.086471,252.606903,12.868409,0.864708,-126.548309,0.086601,0.000000
85.370003,56.786049,-126.548309,0.005325,0.003404,0.086471,252.596954,12.867903,0.864708,-126.548309,0.086601,0.000000
85.580002,56.761848,-126.637268,0.005325,0.003404,0.086471,252.489319,12.862418,0.864708,-126.637268,0.086601,0.000000
85.790001,56.749184,-126.592789,0.005320,0.003404,0.086471,252.432983,12.859549,0.864708,-126.592789,0.086601,0.000000
86.000008,56.730568,-126.637268,0.005329,0.003404,0.086471,252.350174,12.855330,0.864708,-126.637268,0.086601,0.000000
86.210007,56.713814,-126.681747,0.005320,0.003404,0.086471,252.275650,12.851534,0.864708,-126.681747,0.086601,0.000000
86.420006,56.712692,-126.592789,0.005333,0.003404,0.086471,252.270660,12.851280,0.864708,-126.592789,0.086601,0.000000
86.630005,56.682907,-126.592789,0.005333,0.003404,0.086471,252.138168,12.844530,0.864708,-126.592789,0.086601,0.000000
86.840004,56.672478,-126.681747,0.005325,0.003404,0.086471,252.091766,12.842167,0.864708,-126.681747,0.086601,0.000000
87.050003,56.646782,-126.637268,0.005329,0.003404,0.086471,251.977478,12.836345,0.864708,-126.637268,0.086601,0.000000
87.260002,56.639336,-126.681747,0.005320,0.003404,0.086471,251.944351,12.834657,0.864708,-126.681747,0.086601,0.000000
87.470001,56.633003,-126.592789,0.005333,0.003404,0.086471,251.916183,12.833222,0.864708,-126.592789,0.086601,0.000000
87.680008,56.603218,-126.681747,0.005316,0.003404,0.086471,251.783691,12.826472,0.864708,-126.681747,0.086601,0.000000
87.800003,56.600983,-126.681747,0.005338,0.003404,0.086471,251.773743,12.825966,0.864708,-126.681747,0.086601,0.000000