File: Data/compression 4 4 days/AutoNoheating-15-4-1-240226_02262024_162514.csv
Time (sec),S:Load (lbs),S:HL1 (DIM),S:LVDT (in),S:Position (in),Ch:Position (mm),Ch:Load (N),Ch:Stress (MPa),Ch:Strain (mm/mm),Ch:HL1 (DIM),Set Point (),Cycles ()
0.110000,-0.003731,-109.512100,0.000000,-0.000000,-0.000000,-0.016595,-0.000845,-0.000000,-109.512100,0.000130,0.000000
0.340000,-0.006332,-109.467621,0.000009,-0.000000,-0.000000,-0.028168,-0.001435,-0.000000,-109.467621,0.000130,0.000000
0.570000,-0.010429,-109.556580,0.000009,0.000081,0.002064,-0.046392,-0.002363,0.020643,-109.556580,0.002645,0.000000
0.800000,0.013405,-109.512100,0.000017,0.000212,0.005377,0.059628,0.003038,0.053768,-109.512100,0.006478,0.000000
1.030000,0.002228,-109.556580,0.000151,0.000363,0.009219,0.009910,0.000505,0.092189,-109.556580,0.010312,0.000000
1.260000,-0.002983,-109.512100,0.000319,0.000523,0.013277,-0.013269,-0.000676,0.132774,-109.512100,0.014145,0.000000
1.490000,-0.043571,-109.512100,0.000466,0.000663,0.016850,-0.193816,-0.009873,0.168504,-109.512100,0.017978,0.000000
1.720000,-0.013779,-109.556580,0.000617,0.000817,0.020753,-0.061291,-0.003122,0.207530,-109.556580,0.021811,0.000000
1.950000,-0.004471,-109.601067,0.000772,0.000968,0.024586,-0.019887,-0.001013,0.245859,-109.601067,0.025644,0.000000
2.180000,0.031273,-109.556580,0.000918,0.001114,0.028289,0.139109,0.007087,0.282891,-109.556580,0.029477,0.000000
2.410000,0.012283,-109.556580,0.001078,0.001273,0.032330,0.054639,0.002783,0.323302,-109.556580,0.033310,0.000000
2.640000,-0.014900,-109.601067,0.001242,0.001420,0.036059,-0.066279,-0.003376,0.360595,-109.601067,0.037143,0.000000
2.870000,-0.000374,-109.601067,0.001380,0.001569,0.039841,-0.001663,-0.000085,0.398406,-109.601067,0.040959,0.000000
3.100000,0.014893,-109.645546,0.001531,0.001722,0.043734,0.066245,0.003375,0.437345,-109.645546,0.044792,0.000000
3.330000,0.011543,-109.556580,0.001673,0.001859,0.047221,0.051347,0.002616,0.472207,-109.556580,0.048625,0.000000
3.560000,-0.012665,-109.601067,0.001854,0.002026,0.051461,-0.056336,-0.002870,0.514613,-109.601067,0.052459,0.000000
3.790000,-0.037239,-109.556580,0.002022,0.002177,0.055286,-0.165648,-0.008438,0.552856,-109.556580,0.056292,0.000000
4.020000,-0.056976,-109.645546,0.002147,0.002321,0.058954,-0.253443,-0.012911,0.589543,-109.645546,0.060125,0.000000
4.250000,0.020851,-109.601067,0.002298,0.002477,0.062917,0.092750,0.004725,0.629174,-109.601067,0.063958,0.000000
4.480000,0.024200,-109.645546,0.002445,0.002623,0.066620,0.107649,0.005484,0.666202,-109.645546,0.067791,0.000000
4.710000,0.042450,-109.645546,0.002596,0.002763,0.070176,0.188827,0.009619,0.701761,-109.645546,0.071624,0.000000
4.940000,0.043190,-109.690025,0.002768,0.002930,0.074425,0.192119,0.009787,0.744254,-109.690025,0.075458,0.000000
5.170000,0.013771,-109.690025,0.002897,0.003078,0.078180,0.061257,0.003121,0.781804,-109.690025,0.079291,0.000000
5.400000,0.006325,-109.690025,0.003044,0.003225,0.081910,0.028134,0.001433,0.819097,-109.690025,0.083124,0.000000
5.630000,0.008934,-109.645546,0.003191,0.003378,0.085795,0.039741,0.002024,0.857949,-109.645546,0.086957,0.000000
5.860000,0.021591,-109.690025,0.003333,0.003523,0.089489,0.096042,0.004893,0.894893,-109.690025,0.090773,0.000000
6.090000,-0.005959,-109.645546,0.003501,0.003685,0.093600,-0.026505,-0.001350,0.935997,-109.645546,0.094606,0.000000
6.320000,-0.041336,-109.734505,0.003639,0.003835,0.097398,-0.183872,-0.009367,0.973982,-109.734505,0.098439,0.000000
6.550000,0.009308,-109.690025,0.003781,0.003978,0.101049,0.041403,0.002109,1.010491,-109.690025,0.102272,0.000000
6.780000,0.030159,-109.734505,0.003945,0.004135,0.105038,0.134154,0.006834,1.050384,-109.734505,0.106105,0.000000
7.010000,0.052132,-109.690025,0.004096,0.004286,0.108854,0.231893,0.011813,1.088543,-109.690025,0.109938,0.000000
7.240000,0.045425,-109.734505,0.004251,0.004440,0.112783,0.202062,0.010294,1.127827,-109.734505,0.113771,0.000000
7.470000,0.034996,-109.734505,0.004411,0.004588,0.116538,0.155670,0.007930,1.165380,-109.734505,0.117605,0.000000
7.700000,0.010796,-109.778984,0.004562,0.004736,0.120302,0.048021,0.002446,1.203017,-109.778984,0.121438,0.000000
7.930000,0.039093,-109.778984,0.004695,0.004888,0.124152,0.173894,0.008859,1.241521,-109.778984,0.125271,0.000000
8.160001,0.078941,-109.690025,0.004855,0.005038,0.127959,0.351149,0.017888,1.279593,-109.690025,0.129104,0.000000
8.390000,0.223045,-109.734505,0.005006,0.005189,0.131810,0.992155,0.050543,1.318097,-109.734505,0.132937,0.000000
8.620001,0.615898,-109.734505,0.005092,-0.000000,-0.000000,2.739652,0.139565,-0.000000,-109.734505,0.000226,0.000000
8.850000,0.573074,-109.778984,0.005096,-0.000000,-0.000000,2.549162,0.129860,-0.000000,-109.778984,0.000226,0.000000
9.080001,0.543289,-109.778984,0.005105,-0.000000,-0.000000,2.416671,0.123111,-0.000000,-109.778984,0.000243,0.000000
9.310000,0.609200,-109.734505,0.005113,-0.000000,-0.000000,2.709855,0.138047,-0.000000,-109.734505,0.000625,0.000000
9.540001,0.598030,-109.778984,0.005118,0.000000,0.000009,2.660171,0.135516,0.000087,-109.778984,0.001006,0.000000
9.770000,0.735435,-109.867950,0.005101,0.000020,0.000503,3.271380,0.166652,0.005030,-109.867950,0.001388,0.000000
10.000000,0.789429,-109.734505,0.005105,0.000030,0.000763,3.511554,0.178887,0.007634,-109.734505,0.001769,0.000000
10.230000,0.979340,-109.823471,0.005131,0.000051,0.001301,4.356320,0.221922,0.013009,-109.823471,0.002160,0.000000
10.460000,1.056046,-109.778984,0.005148,0.000063,0.001596,4.697525,0.239303,0.015957,-109.778984,0.002541,0.000000
10.690001,1.190468,-109.778984,0.005152,0.000080,0.002029,5.295465,0.269764,0.020295,-109.778984,0.002923,0.000000
10.920000,1.285423,-109.823471,0.005165,0.000093,0.002359,5.717848,0.291281,0.023591,-109.823471,0.003304,0.000000
11.150001,1.497307,-109.823471,0.005165,0.000112,0.002836,6.660353,0.339295,0.028360,-109.823471,0.003686,0.000000
11.380000,1.670090,-109.778984,0.005187,0.000128,0.003252,7.428930,0.378448,0.032524,-109.778984,0.004076,0.000000
11.610001,1.813454,-109.778984,0.005204,0.000140,0.003547,8.066645,0.410934,0.035472,-109.778984,0.004457,0.000000
11.840000,1.948997,-109.778984,0.005221,0.000155,0.003937,8.669574,0.441649,0.039374,-109.778984,0.004839,0.000000
12.070001,2.148582,-109.867950,0.005234,0.000170,0.004310,9.557372,0.486876,0.043102,-109.867950,0.005221,0.000000
12.300000,2.375359,-109.912430,0.005234,0.000187,0.004761,10.566123,0.538264,0.047610,-109.912430,0.005602,0.000000
12.530001,2.451698,-109.823471,0.005256,0.000197,0.005013,10.905699,0.555563,0.050127,-109.823471,0.005993,0.000000
12.760000,2.646072,-109.912430,0.005269,0.000214,0.005446,11.770318,0.599609,0.054461,-109.912430,0.006374,0.000000
12.990001,2.812157,-109.867950,0.005282,0.000228,0.005784,12.509098,0.637244,0.057845,-109.867950,0.006756,0.000000
13.220000,3.085846,-109.912430,0.005299,0.000246,0.006253,13.726528,0.699263,0.062526,-109.912430,0.007137,0.000000
13.450001,3.275757,-109.912430,0.005303,0.000262,0.006652,14.571294,0.742297,0.066516,-109.912430,0.007519,0.000000
13.680000,3.370338,-109.867950,0.005316,0.000270,0.006860,14.992014,0.763730,0.068597,-109.867950,0.007909,0.000000
13.910001,3.517052,-109.823471,0.005342,0.000288,0.007320,15.644628,0.796975,0.073196,-109.823471,0.008291,0.000000
14.140000,3.832825,-109.867950,0.005338,0.000307,0.007788,17.049255,0.868531,0.077878,-109.867950,0.008672,0.000000
14.370001,4.016037,-110.001389,0.005368,0.000321,0.008143,17.864225,0.910047,0.081432,-110.001389,0.009054,0.000000
14.600000,4.112106,-109.912430,0.005372,0.000336,0.008542,18.291563,0.931817,0.085421,-109.912430,0.009444,0.000000
14.830001,4.236481,-109.912430,0.005376,0.000348,0.008828,18.844807,0.960000,0.088283,-109.912430,0.009826,0.000000
15.060000,4.426758,-109.912430,0.005398,0.000364,0.009236,19.691202,1.003118,0.092359,-109.912430,0.010207,0.000000
15.290001,4.693008,-109.956909,0.005424,0.000385,0.009782,20.875544,1.063451,0.097824,-109.956909,0.010589,0.000000
15.520000,4.822594,-109.956909,0.005428,0.000400,0.010173,21.451967,1.092815,0.101727,-109.956909,0.010971,0.000000
15.750001,5.071335,-109.956909,0.005450,0.000420,0.010667,22.558424,1.149181,0.106670,-109.956909,0.011361,0.000000
15.980000,5.167038,-109.912430,0.005463,0.000434,0.011031,22.984133,1.170868,0.110311,-109.912430,0.011742,0.000000
16.210001,5.172249,-109.912430,0.005484,0.000445,0.011309,23.007313,1.172048,0.113089,-109.912430,0.012124,0.000000
16.440001,5.271675,-110.001389,0.005493,0.000459,0.011656,23.449581,1.194579,0.116556,-110.001389,0.012506,0.000000
16.670000,5.381523,-110.001389,0.005497,0.000472,0.011985,23.938210,1.219471,0.119852,-110.001389,0.012887,0.000000
16.900002,5.540154,-109.956909,0.005514,0.000489,0.012410,24.643833,1.255417,0.124099,-109.956909,0.013277,0.000000
17.130001,5.584091,-110.045876,0.005527,0.000501,0.012713,24.839277,1.265373,0.127135,-110.045876,0.013659,0.000000
17.360001,5.794113,-110.001389,0.005558,0.000520,0.013199,25.773502,1.312965,0.131994,-110.001389,0.014040,0.000000
17.590000,5.732674,-110.045876,0.005558,0.000528,0.013399,25.500206,1.299042,0.133989,-110.045876,0.014422,0.000000
17.820002,5.728203,-110.001389,0.005566,0.000542,0.013763,25.480318,1.298029,0.137630,-110.001389,0.014803,0.000000
18.050001,6.166481,-110.045876,0.005596,0.000568,0.014431,27.429878,1.397345,0.144307,-110.045876,0.015194,0.000000
18.280001,6.118073,-110.001389,0.005605,0.000577,0.014665,27.214546,1.386375,0.146650,-110.001389,0.015576,0.000000
18.510000,6.204842,-110.045876,0.005622,0.000593,0.015055,27.600513,1.406037,0.150552,-110.045876,0.015957,0.000000
18.740002,6.271492,-110.045876,0.005635,0.000607,0.015419,27.896990,1.421140,0.154193,-110.045876,0.016339,0.000000
18.970001,6.439430,-110.134834,0.005652,0.000624,0.015862,28.644016,1.459196,0.158617,-110.134834,0.016720,0.000000
19.200001,6.511673,-110.001389,0.005661,0.000640,0.016261,28.965368,1.475566,0.162607,-110.001389,0.017110,0.000000
19.430000,6.541092,-110.090355,0.005678,0.000652,0.016556,29.096230,1.482233,0.165555,-110.090355,0.017492,0.000000
19.660002,6.473694,-110.045876,0.005691,0.000661,0.016789,28.796429,1.466960,0.167894,-110.045876,0.017874,0.000000
19.890001,6.791328,-110.045876,0.005713,0.000684,0.017379,30.209337,1.538937,0.173795,-110.045876,0.018255,0.000000
20.120001,6.793930,-110.134834,0.005721,0.000697,0.017691,30.220911,1.539527,0.176914,-110.134834,0.018637,0.000000
20.350000,6.873245,-110.090355,0.005726,0.000715,0.018160,30.573721,1.557500,0.181599,-110.090355,0.019027,0.000000
20.580002,6.904900,-110.090355,0.005743,0.000729,0.018507,30.714527,1.564673,0.185066,-110.090355,0.019409,0.000000
20.810001,6.914955,-110.045876,0.005764,0.000741,0.018819,30.759256,1.566951,0.188189,-110.045876,0.019790,0.000000
21.040001,7.120506,-110.134834,0.005786,0.000759,0.019278,31.673594,1.613530,0.192784,-110.134834,0.020172,0.000000
21.270000,7.006554,-110.179314,0.005790,0.000767,0.019487,31.166708,1.587708,0.194865,-110.179314,0.020553,0.000000
21.500002,7.102257,-110.090355,0.005790,0.000783,0.019877,31.592417,1.609394,0.198768,-110.090355,0.020944,0.000000
21.730001,7.430687,-110.134834,0.005821,0.000807,0.020493,33.053345,1.683818,0.204926,-110.134834,0.021325,0.000000
21.960001,7.416542,-110.090355,0.005846,0.000822,0.020874,32.990425,1.680612,0.208741,-110.090355,0.021707,0.000000
22.190001,7.478722,-110.134834,0.005846,0.000839,0.021299,33.267014,1.694703,0.212991,-110.134834,0.022088,0.000000
22.420002,7.424728,-110.179314,0.005864,0.000850,0.021585,33.026840,1.682467,0.215853,-110.179314,0.022470,0.000000
22.650002,7.482079,-110.179314,0.005877,0.000863,0.021932,33.281948,1.695463,0.219323,-110.179314,0.022860,0.000000
22.880001,7.680923,-110.134834,0.005902,0.000882,0.022409,34.166454,1.740522,0.224092,-110.134834,0.023242,0.000000
23.110001,7.648155,-110.179314,0.005911,0.000894,0.022704,34.020695,1.733097,0.227041,-110.179314,0.023623,0.000000
23.340002,7.694702,-110.223793,0.005924,0.000908,0.023059,34.227745,1.743644,0.230595,-110.223793,0.024005,0.000000
23.570002,7.872322,-110.179314,0.005941,0.000926,0.023519,35.017838,1.783894,0.235193,-110.179314,0.024395,0.000000
23.800001,7.956108,-110.179314,0.005950,0.000943,0.023953,35.390537,1.802880,0.239527,-110.179314,0.024777,0.000000
24.030001,7.920731,-110.223793,0.005976,0.000955,0.024256,35.233170,1.794863,0.242563,-110.223793,0.025158,0.000000
24.260000,7.931900,-110.179314,0.005993,0.000969,0.024603,35.282852,1.797394,0.246033,-110.179314,0.025540,0.000000
24.490002,7.963928,-110.223793,0.005993,0.000984,0.024985,35.425323,1.804652,0.249848,-110.223793,0.025922,0.000000
24.720001,8.157936,-110.223793,0.005997,0.001001,0.025419,36.288311,1.848615,0.254186,-110.223793,0.026312,0.000000
24.950001,8.220116,-110.179314,0.006028,0.001014,0.025765,36.564899,1.862705,0.257653,-110.179314,0.026693,0.000000
25.180000,8.211182,-110.223793,0.006049,0.001026,0.026069,36.525162,1.860680,0.260688,-110.223793,0.027075,0.000000
25.410002,8.242088,-110.223793,0.006049,0.001039,0.026390,36.662640,1.867684,0.263898,-110.223793,0.027456,0.000000
25.640001,8.564560,-110.268280,0.006066,0.001063,0.026988,38.097065,1.940757,0.269882,-110.268280,0.027838,0.000000
25.870001,8.670692,-110.312759,0.006084,0.001079,0.027396,38.569168,1.964807,0.273958,-110.312759,0.028228,0.000000
26.100000,8.648720,-110.223793,0.006096,0.001094,0.027786,38.471428,1.959828,0.277860,-110.223793,0.028610,0.000000
26.330002,8.508331,-110.268280,0.006114,0.001102,0.027986,37.846947,1.928015,0.279855,-110.268280,0.028992,0.000000
26.560001,8.696381,-110.223793,0.006135,0.001120,0.028436,38.683434,1.970628,0.284363,-110.223793,0.029373,0.000000
26.790001,8.866188,-110.268280,0.006148,0.001136,0.028853,39.438774,2.009107,0.288526,-110.268280,0.029755,0.000000
27.020000,8.898956,-110.312759,0.006165,0.001150,0.029208,39.584534,2.016532,0.292084,-110.312759,0.030145,0.000000
27.250002,9.069504,-110.268280,0.006183,0.001166,0.029624,40.343166,2.055179,0.296244,-110.268280,0.030526,0.000000
27.480001,9.052002,-110.312759,0.006187,0.001178,0.029928,40.265316,2.051213,0.299279,-110.312759,0.030908,0.000000
27.710001,9.384155,-110.357239,0.006204,0.001201,0.030518,41.742809,2.126480,0.305176,-110.357239,0.031290,0.000000
27.940001,9.339470,-110.312759,0.006222,0.001217,0.030900,41.544037,2.116354,0.308995,-110.312759,0.031671,0.000000
28.170002,9.213982,-110.312759,0.006239,0.001226,0.031151,40.985836,2.087918,0.311508,-110.312759,0.032061,0.000000
28.400002,9.372986,-110.268280,0.006252,0.001245,0.031610,41.693123,2.123949,0.316103,-110.268280,0.032443,0.000000
28.630001,9.466446,-110.268280,0.006265,0.001259,0.031966,42.108856,2.145127,0.319661,-110.268280,0.032825,0.000000
28.860001,9.601624,-110.357239,0.006291,0.001275,0.032391,42.710155,2.175759,0.323911,-110.357239,0.033206,0.000000
29.090002,9.627686,-110.357239,0.006278,0.001289,0.032738,42.826084,2.181665,0.327378,-110.357239,0.033588,0.000000
29.320002,9.593430,-110.312759,0.006308,0.001302,0.033059,42.673706,2.173902,0.330588,-110.312759,0.033978,0.000000
29.550001,9.981812,-110.312759,0.006321,0.001323,0.033614,44.401314,2.261911,0.336137,-110.312759,0.034360,0.000000
29.780001,9.979576,-110.312759,0.006355,0.001338,0.033978,44.391373,2.261404,0.339781,-110.312759,0.034741,0.000000
30.010002,9.988518,-110.357239,0.006355,0.001352,0.034334,44.431145,2.263431,0.343335,-110.357239,0.035123,0.000000
30.240002,9.939735,-110.357239,0.006372,0.001361,0.034577,44.214149,2.252376,0.345765,-110.357239,0.035504,0.000000
30.470001,10.081978,-110.357239,0.006368,0.001377,0.034975,44.846878,2.284609,0.349755,-110.357239,0.035894,0.000000
30.700001,10.286789,-110.401718,0.006398,0.001394,0.035409,45.757923,2.331020,0.354088,-110.401718,0.036276,0.000000
30.930002,10.394028,-110.401718,0.006411,0.001409,0.035799,46.234943,2.355320,0.357991,-110.401718,0.036658,0.000000
31.160002,10.430893,-110.401718,0.006433,0.001422,0.036111,46.398930,2.363674,0.361113,-110.401718,0.037039,0.000000
31.390001,10.355301,-110.446205,0.006428,0.001433,0.036406,46.062679,2.346545,0.364061,-110.446205,0.037421,0.000000
31.620001,10.696022,-110.446205,0.006454,0.001452,0.036892,47.578281,2.423753,0.368917,-110.446205,0.037811,0.000000
31.850002,10.702354,-110.357239,0.006467,0.001464,0.037195,47.606449,2.425188,0.371953,-110.357239,0.038193,0.000000
32.080002,10.829330,-110.357239,0.006480,0.001480,0.037594,48.171268,2.453961,0.375942,-110.357239,0.038574,0.000000
32.310001,10.814812,-110.401718,0.006489,0.001492,0.037889,48.106686,2.450671,0.378891,-110.401718,0.038956,0.000000
32.540001,11.106750,-110.490685,0.006497,0.001512,0.038401,49.405293,2.516826,0.384008,-110.490685,0.039346,0.000000
32.770000,11.300385,-110.446205,0.006519,0.001528,0.038817,50.266621,2.560704,0.388171,-110.446205,0.039728,0.000000
33.000000,11.269104,-110.446205,0.006536,0.001542,0.039155,50.127480,2.553615,0.391555,-110.446205,0.040109,0.000000
33.230003,11.527901,-110.446205,0.006541,0.001560,0.039615,51.278664,2.612260,0.396150,-110.446205,0.040491,0.000000
33.460003,11.588974,-110.490685,0.006562,0.001573,0.039962,51.550331,2.626099,0.399617,-110.490685,0.040872,0.000000
33.690002,11.673874,-110.446205,0.006575,0.001587,0.040309,51.927986,2.645338,0.403088,-110.446205,0.041263,0.000000
33.920002,11.752815,-110.490685,0.006579,0.001603,0.040725,52.279133,2.663226,0.407251,-110.490685,0.041644,0.000000
34.150002,11.731964,-110.401718,0.006614,0.001616,0.041037,52.186382,2.658501,0.410373,-110.401718,0.042026,0.000000
34.380001,11.963203,-110.490685,0.006635,0.001632,0.041462,53.214985,2.710901,0.414620,-110.490685,0.042407,0.000000
34.610001,12.187004,-110.490685,0.006644,0.001649,0.041896,54.210503,2.761615,0.418958,-110.490685,0.042789,0.000000
34.840000,12.419739,-110.579643,0.006653,0.001668,0.042355,55.245758,2.814353,0.423552,-110.579643,0.043179,0.000000
35.070004,12.091301,-110.535164,0.006653,0.001671,0.042451,53.784794,2.739928,0.424506,-110.535164,0.043561,0.000000
35.300003,12.476334,-110.535164,0.006674,0.001692,0.042988,55.497505,2.827178,0.429885,-110.535164,0.043942,0.000000
35.530003,12.805885,-110.490685,0.006704,0.001712,0.043474,56.963425,2.901855,0.434741,-110.490685,0.044324,0.000000
35.760002,12.831581,-110.535164,0.006709,0.001725,0.043812,57.077724,2.907678,0.438124,-110.535164,0.044706,0.000000
35.990002,12.875893,-110.579643,0.006717,0.001739,0.044159,57.274830,2.917719,0.441591,-110.579643,0.045096,0.000000
36.220001,12.914619,-110.579643,0.006730,0.001752,0.044497,57.447098,2.926495,0.444975,-110.579643,0.045477,0.000000
36.450001,13.039734,-110.490685,0.006760,0.001769,0.044923,58.003632,2.954846,0.449225,-110.490685,0.045859,0.000000
36.680000,13.377106,-110.490685,0.006773,0.001786,0.045356,59.504337,3.031296,0.453559,-110.490685,0.046240,0.000000
36.910000,13.495148,-110.624123,0.006791,0.001800,0.045712,60.029415,3.058044,0.457117,-110.624123,0.046622,0.000000
37.140003,13.838844,-110.624123,0.006786,0.001820,0.046240,61.558254,3.135927,0.462404,-110.624123,0.047013,0.000000
37.370003,13.884277,-110.535164,0.006804,0.001836,0.046639,61.760349,3.146222,0.466394,-110.535164,0.047394,0.000000
37.600002,13.803101,-110.535164,0.006821,0.001848,0.046934,61.399258,3.127827,0.469342,-110.535164,0.047776,0.000000
37.830002,13.944229,-110.579643,0.006838,0.001863,0.047324,62.027027,3.159807,0.473244,-110.579643,0.048157,0.000000
38.060001,14.042908,-110.579643,0.006842,0.001877,0.047680,62.465973,3.182168,0.476802,-110.579643,0.048539,0.000000
38.290001,14.102859,-110.579643,0.006864,0.001888,0.047958,62.732651,3.195754,0.479576,-110.579643,0.048929,0.000000
38.520000,14.478210,-110.579643,0.006868,0.001908,0.048469,64.402298,3.280809,0.484694,-110.579643,0.049310,0.000000
38.750000,14.530342,-110.579643,0.006890,0.001921,0.048782,64.634193,3.292623,0.487816,-110.579643,0.049692,0.000000
38.980003,14.349373,-110.624123,0.006903,0.001929,0.048998,63.829197,3.251614,0.489985,-110.624123,0.050074,0.000000
39.210003,15.447868,-110.624123,0.006920,0.001959,0.049770,68.715553,3.500537,0.497702,-110.624123,0.050455,0.000000
39.440002,15.190186,-110.668610,0.006942,0.001970,0.050030,67.569321,3.442145,0.500303,-110.668610,0.050846,0.000000
39.670002,15.141029,-110.624123,0.006937,0.001982,0.050351,67.350662,3.431006,0.503512,-110.624123,0.051227,0.000000
39.900002,15.367805,-110.668610,0.006950,0.001996,0.050707,68.359413,3.482394,0.507066,-110.668610,0.051609,0.000000
40.130001,15.407280,-110.624123,0.006976,0.002011,0.051080,68.535004,3.491340,0.510798,-110.624123,0.051990,0.000000
40.360001,15.759544,-110.713089,0.006985,0.002027,0.051487,70.101952,3.571164,0.514874,-110.713089,0.052372,0.000000
40.590000,15.876099,-110.713089,0.006998,0.002040,0.051825,70.620415,3.597575,0.518254,-110.713089,0.052762,0.000000
40.820004,15.998978,-110.713089,0.007002,0.002054,0.052173,71.167007,3.625420,0.521725,-110.713089,0.053144,0.000000
41.050003,16.414177,-110.668610,0.007015,0.002072,0.052632,73.013908,3.719506,0.526320,-110.668610,0.053525,0.000000
41.280003,16.627914,-110.624123,0.007041,0.002087,0.053022,73.964661,3.767939,0.530222,-110.624123,0.053907,0.000000
41.510002,16.850967,-110.668610,0.007058,0.002105,0.053456,74.956848,3.818484,0.534560,-110.668610,0.054297,0.000000
41.740002,16.949646,-110.757568,0.007075,0.002118,0.053794,75.395790,3.840845,0.537940,-110.757568,0.054678,0.000000
41.970001,16.949272,-110.757568,0.007084,0.002130,0.054098,75.394127,3.840760,0.540975,-110.757568,0.055060,0.000000
42.200001,17.045715,-110.757568,0.007088,0.002142,0.054410,75.823128,3.862614,0.544098,-110.757568,0.055442,0.000000
42.430000,17.364838,-110.713089,0.007105,0.002159,0.054826,77.242653,3.934928,0.548261,-110.713089,0.055823,0.000000
42.660004,17.282547,-110.802048,0.007118,0.002169,0.055095,76.876610,3.916281,0.550948,-110.802048,0.056214,0.000000
42.890003,17.599808,-110.802048,0.007127,0.002188,0.055572,78.287857,3.988173,0.555721,-110.802048,0.056595,0.000000
43.120003,18.355354,-110.757568,0.007144,0.002210,0.056127,81.648697,4.159383,0.561270,-110.757568,0.056977,0.000000
43.350002,18.488289,-110.668610,0.007166,0.002224,0.056491,82.240013,4.189507,0.564911,-110.668610,0.057359,0.000000
43.580002,18.628304,-110.668610,0.007187,0.002239,0.056873,82.862831,4.221234,0.568726,-110.668610,0.057740,0.000000
43.810001,18.686760,-110.757568,0.007187,0.002253,0.057228,83.122856,4.234480,0.572284,-110.757568,0.058130,0.000000
44.040001,18.786934,-110.846527,0.007196,0.002265,0.057532,83.568459,4.257180,0.575319,-110.846527,0.058512,0.000000
44.270000,19.243462,-110.802048,0.007222,0.002283,0.058000,85.599190,4.360631,0.580001,-110.802048,0.058893,0.000000
44.500004,19.228195,-110.713089,0.007239,0.002293,0.058252,85.531281,4.357172,0.582518,-110.713089,0.059275,0.000000
44.730003,19.529816,-110.757568,0.007243,0.002310,0.058685,86.872955,4.425519,0.586852,-110.757568,0.059656,0.000000
44.960003,20.230621,-110.757568,0.007261,0.002333,0.059257,89.990295,4.584324,0.592575,-110.757568,0.060047,0.000000
45.190002,20.440636,-110.846527,0.007261,0.002347,0.059622,90.924492,4.631914,0.596219,-110.846527,0.060428,0.000000
45.420002,20.498352,-110.802048,0.007291,0.002361,0.059960,91.181221,4.644993,0.599599,-110.802048,0.060810,0.000000
45.650002,20.511017,-110.802048,0.007299,0.002372,0.060246,91.237556,4.647862,0.602464,-110.802048,0.061192,0.000000
45.880001,20.718803,-110.802048,0.007312,0.002386,0.060611,92.161842,4.694948,0.606106,-110.802048,0.061573,0.000000
46.110001,21.121338,-110.802048,0.007321,0.002405,0.061079,93.952400,4.786164,0.610787,-110.802048,0.061963,0.000000
46.340004,21.308266,-110.846527,0.007330,0.002417,0.061391,94.783897,4.828522,0.613910,-110.846527,0.062345,0.000000
46.570004,21.307518,-110.846527,0.007347,0.002426,0.061625,94.780571,4.828352,0.616253,-110.846527,0.062727,0.000000
46.800003,21.532059,-110.891014,0.007347,0.002439,0.061946,95.779381,4.879234,0.619459,-110.891014,0.063108,0.000000
47.030003,22.677483,-110.846527,0.007364,0.002465,0.062605,100.874481,5.138791,0.626052,-110.846527,0.063490,0.000000
47.260002,22.947449,-110.846527,0.007403,0.002481,0.063013,102.075348,5.199966,0.630128,-110.846527,0.063880,0.000000
47.490002,23.014473,-110.846527,0.007411,0.002493,0.063333,102.373489,5.215154,0.633334,-110.846527,0.064261,0.000000
47.720001,22.766479,-110.891014,0.007411,0.002503,0.063568,101.270355,5.158958,0.635677,-110.891014,0.064643,0.000000
47.950001,23.129913,-110.846527,0.007429,0.002517,0.063941,102.886993,5.241313,0.639405,-110.846527,0.065024,0.000000
48.180004,23.557770,-110.846527,0.007433,0.002533,0.064348,104.790192,5.338267,0.643481,-110.846527,0.065406,0.000000
48.410004,24.131592,-110.891014,0.007450,0.002551,0.064791,107.342682,5.468297,0.647906,-110.891014,0.065797,0.000000
48.640003,24.421669,-110.891014,0.007468,0.002566,0.065172,108.633011,5.534029,0.651721,-110.891014,0.066178,0.000000
48.870003,24.584396,-110.935493,0.007463,0.002577,0.065458,109.356857,5.570904,0.654582,-110.935493,0.066560,0.000000
49.100002,25.604324,-110.891014,0.007489,0.002603,0.066109,113.893723,5.802022,0.661089,-110.891014,0.066941,0.000000
49.330002,25.716042,-110.891014,0.007502,0.002617,0.066464,114.390663,5.827338,0.664643,-110.891014,0.067323,0.000000
49.560001,25.660179,-110.935493,0.007524,0.002628,0.066750,114.142174,5.814680,0.667504,-110.935493,0.067713,0.000000
49.790001,26.131607,-110.935493,0.007519,0.002644,0.067158,116.239197,5.921507,0.671580,-110.935493,0.068095,0.000000
50.020004,26.449242,-110.935493,0.007549,0.002659,0.067540,117.652100,5.993484,0.675396,-110.935493,0.068476,0.000000
50.250004,27.093445,-110.935493,0.007558,0.002677,0.067991,120.517662,6.139462,0.679907,-110.935493,0.068858,0.000000
50.480003,27.332138,-110.891014,0.007571,0.002690,0.068320,121.579422,6.193551,0.683200,-110.891014,0.069248,0.000000
50.710003,27.613647,-110.891014,0.007567,0.002706,0.068728,122.831642,6.257342,0.687276,-110.891014,0.069630,0.000000
50.940002,28.465637,-110.979973,0.007593,0.002726,0.069239,126.621475,6.450406,0.692394,-110.979973,0.070011,0.000000
51.170002,28.597084,-110.979973,0.007601,0.002739,0.069560,127.206184,6.480192,0.695603,-110.979973,0.070393,0.000000
51.400002,28.732628,-110.979973,0.007614,0.002751,0.069873,127.809113,6.510907,0.698726,-110.979973,0.070775,0.000000
51.630001,28.696136,-110.979973,0.007623,0.002760,0.070106,127.646790,6.502638,0.701065,-110.979973,0.071165,0.000000
51.860001,29.281876,-111.024452,0.007649,0.002778,0.070566,130.252289,6.635368,0.705663,-111.024452,0.071546,0.000000
52.090004,30.102959,-111.024452,0.007649,0.002798,0.071078,133.904648,6.821428,0.710781,-111.024452,0.071928,0.000000
52.320004,30.547195,-111.024452,0.007657,0.002811,0.071407,135.880707,6.922093,0.714073,-111.024452,0.072309,0.000000
52.550003,30.701363,-110.979973,0.007670,0.002823,0.071711,136.566483,6.957028,0.717109,-110.979973,0.072691,0.000000
52.780003,30.964256,-110.979973,0.007687,0.002839,0.072101,137.735886,7.016601,0.721011,-110.979973,0.073081,0.000000
53.010002,31.677719,-111.024452,0.007696,0.002853,0.072474,140.909531,7.178274,0.724743,-111.024452,0.073463,0.000000
53.240002,32.237770,-111.068932,0.007718,0.002870,0.072890,143.400757,7.305183,0.728903,-111.068932,0.073844,0.000000
53.470001,32.390816,-111.068932,0.007713,0.002882,0.073203,144.081543,7.339864,0.732025,-111.068932,0.074226,0.000000
53.700001,32.777710,-111.024452,0.007731,0.002896,0.073558,145.802536,7.427536,0.735583,-111.024452,0.074607,0.000000
53.930004,33.758163,-111.068932,0.007739,0.002916,0.074078,150.163818,7.649709,0.740783,-111.068932,0.074998,0.000000
54.160004,34.274651,-111.113419,0.007765,0.002931,0.074452,152.461258,7.766747,0.744515,-111.113419,0.075379,0.000000
54.390003,34.421364,-111.068932,0.007765,0.002942,0.074720,153.113876,7.799993,0.747203,-111.068932,0.075761,0.000000
54.620003,35.353409,-111.068932,0.007778,0.002963,0.075249,157.259811,8.011197,0.752494,-111.068932,0.076143,0.000000
54.850002,35.611465,-111.113419,0.007795,0.002975,0.075553,158.407715,8.069674,0.755529,-111.113419,0.076524,0.000000
55.080002,36.056450,-111.024452,0.007817,0.002991,0.075978,160.387100,8.170508,0.759776,-111.024452,0.076914,0.000000
55.310001,36.770287,-111.157898,0.007817,0.003007,0.076377,163.562408,8.332266,0.763765,-111.157898,0.077296,0.000000
55.540001,37.009720,-111.113419,0.007830,0.003020,0.076697,164.627457,8.386522,0.766975,-111.113419,0.077677,0.000000
55.770004,37.756332,-111.113419,0.007843,0.003037,0.077131,167.948547,8.555708,0.771312,-111.113419,0.078059,0.000000
56.000004,38.377823,-111.157898,0.007843,0.003051,0.077504,170.713089,8.696539,0.775041,-111.157898,0.078441,0.000000
56.230003,39.007126,-111.113419,0.007864,0.003066,0.077877,173.512360,8.839141,0.778769,-111.113419,0.078831,0.000000
56.460003,38.632523,-111.113419,0.007873,0.003070,0.077990,171.846039,8.754255,0.779897,-111.113419,0.079213,0.000000
56.690002,39.795067,-111.157898,0.007877,0.003093,0.078562,177.017303,9.017691,0.785619,-111.157898,0.079594,0.000000
56.920002,40.825424,-111.202377,0.007869,0.003112,0.079056,181.600555,9.251174,0.790562,-111.202377,0.079976,0.000000
57.150002,41.343765,-111.157898,0.007890,0.003128,0.079455,183.906250,9.368631,0.794552,-111.157898,0.080357,0.000000
57.380001,41.835670,-111.157898,0.007912,0.003144,0.079845,186.094360,9.480099,0.798454,-111.157898,0.080747,0.000000
57.610004,42.279541,-111.157898,0.007903,0.003156,0.080166,188.068787,9.580681,0.801663,-111.157898,0.081129,0.000000
57.840004,42.974388,-111.202377,0.007933,0.003174,0.080609,191.159622,9.738135,0.806088,-111.202377,0.081511,0.000000
58.070004,43.929520,-111.202377,0.007946,0.003190,0.081025,195.408264,9.954571,0.810251,-111.202377,0.081892,0.000000
58.300003,44.327217,-111.157898,0.007950,0.003201,0.081311,197.177307,10.044690,0.813113,-111.157898,0.082282,0.000000
58.530003,45.657326,-111.113419,0.007959,0.003225,0.081918,203.093933,10.346098,0.819184,-111.113419,0.082664,0.000000
58.760002,46.017044,-111.202377,0.007972,0.003238,0.082239,204.694031,10.427611,0.822390,-111.202377,0.083046,0.000000
58.990002,46.286263,-111.246857,0.007989,0.003250,0.082543,205.891571,10.488617,0.825425,-111.246857,0.083427,0.000000
59.220001,46.919670,-111.246857,0.007989,0.003264,0.082898,208.709122,10.632150,0.828983,-111.246857,0.083809,0.000000
59.450005,47.422005,-111.246857,0.008006,0.003276,0.083219,210.943619,10.745979,0.832192,-111.246857,0.084199,0.000000
59.680004,47.752296,-111.202377,0.008006,0.003287,0.083488,212.412827,10.820825,0.834880,-111.202377,0.084581,0.000000
59.910004,49.153160,-111.202377,0.008024,0.003310,0.084086,218.644180,11.138266,0.840864,-111.202377,0.084962,0.000000
60.140003,49.443237,-111.246857,0.008037,0.003321,0.084346,219.934509,11.203998,0.843464,-111.246857,0.085344,0.000000
60.370003,49.652885,-111.291336,0.008045,0.003330,0.084589,220.867065,11.251505,0.845894,-111.291336,0.085725,0.000000
60.600002,51.866638,-111.246857,0.008045,0.003360,0.085344,230.714325,11.753148,0.853437,-111.246857,0.086115,0.000000
60.830002,52.053200,-111.202377,0.008063,0.003369,0.085569,231.544189,11.795424,0.855693,-111.202377,0.086497,0.000000
61.060001,52.810974,-111.246857,0.008075,0.003385,0.085977,234.914948,11.967138,0.859769,-111.246857,0.086879,0.000000
61.290005,53.314049,-111.246857,0.008063,0.003399,0.086324,237.152740,12.081137,0.863236,-111.246857,0.087260,0.000000
61.520004,54.014114,-111.291336,0.008088,0.003412,0.086653,240.266785,12.239774,0.866533,-111.291336,0.087642,0.000000
61.750004,55.084312,-111.291336,0.008088,0.003431,0.087148,245.027252,12.482284,0.871476,-111.291336,0.088032,0.000000
61.980003,55.474556,-111.291336,0.008114,0.003442,0.087434,246.763153,12.570714,0.874337,-111.291336,0.088414,0.000000
62.210003,56.034233,-111.291336,0.008106,0.003454,0.087720,249.252716,12.697539,0.877199,-111.291336,0.088795,0.000000
62.440002,57.306999,-111.335823,0.008114,0.003473,0.088214,254.914261,12.985952,0.882142,-111.335823,0.089177,0.000000
62.670002,58.386879,-111.291336,0.008127,0.003491,0.088683,259.717804,13.230656,0.886827,-111.291336,0.089559,0.000000
62.900002,59.197533,-111.335823,0.008132,0.003506,0.089047,263.323792,13.414352,0.890468,-111.335823,0.089949,0.000000
63.130005,59.803383,-111.291336,0.008136,0.003519,0.089394,266.018738,13.551641,0.893935,-111.291336,0.090330,0.000000
63.360004,60.368279,-111.291336,0.008157,0.003531,0.089697,268.531525,13.679647,0.896971,-111.291336,0.090712,0.000000
63.590004,61.368843,-111.335823,0.008162,0.003546,0.090079,272.982239,13.906379,0.900790,-111.335823,0.091093,0.000000
63.820004,62.023102,-111.380302,0.008170,0.003561,0.090452,275.892548,14.054635,0.904518,-111.380302,0.091475,0.000000
64.050003,62.411484,-111.424782,0.008175,0.003570,0.090686,277.620148,14.142644,0.906857,-111.424782,0.091865,0.000000
64.280006,64.328079,-111.380302,0.008175,0.003597,0.091362,286.145599,14.576951,0.913624,-111.380302,0.092247,0.000000
64.510002,65.518188,-111.291336,0.008183,0.003613,0.091778,291.439453,14.846633,0.917784,-111.291336,0.092628,0.000000
64.740005,66.156067,-111.291336,0.008201,0.003626,0.092091,294.276886,14.991179,0.920907,-111.291336,0.093010,0.000000
64.970001,66.961868,-111.335823,0.008205,0.003639,0.092438,297.861267,15.173776,0.924377,-111.335823,0.093392,0.000000
65.200005,67.374466,-111.380302,0.008209,0.003641,0.092473,299.696594,15.267273,0.924726,-111.380302,0.092715,0.000000
65.430000,66.693024,-111.380302,0.008218,0.003641,0.092473,296.665375,15.112855,0.924726,-111.380302,0.092715,0.000000
65.660004,66.116211,-111.380302,0.008222,0.003640,0.092446,294.099609,14.982148,0.924464,-111.380302,0.092473,0.000000
65.889999,65.591171,-111.380302,0.008239,0.003639,0.092438,291.764099,14.863172,0.924377,-111.380302,0.092473,0.000000
66.120003,65.113052,-111.424782,0.008235,0.003639,0.092429,289.637329,14.754828,0.924290,-111.424782,0.092473,0.000000
66.350006,64.690033,-111.380302,0.008244,0.003639,0.092429,287.755646,14.658971,0.924290,-111.380302,0.092473,0.000000
66.580002,64.321014,-111.380302,0.008239,0.003639,0.092429,286.114166,14.575351,0.924290,-111.380302,0.092473,0.000000
66.810005,63.968369,-111.424782,0.008235,0.003639,0.092420,284.545502,14.495440,0.924203,-111.424782,0.092473,0.000000
67.040001,63.653717,-111.380302,0.008244,0.003639,0.092420,283.145874,14.424139,0.924203,-111.380302,0.092473,0.000000
67.270004,63.373322,-111.424782,0.008248,0.003639,0.092420,281.898621,14.360600,0.924203,-111.424782,0.092473,0.000000
67.500000,63.112656,-111.469261,0.008248,0.003639,0.092420,280.739105,14.301532,0.924203,-111.469261,0.092473,0.000000
67.730003,62.867638,-111.424782,0.008248,0.003639,0.092420,279.649231,14.246010,0.924203,-111.424782,0.092473,0.000000
67.960007,62.643471,-111.380302,0.008257,0.003639,0.092420,278.652069,14.195213,0.924203,-111.380302,0.092473,0.000000
68.190002,62.430847,-111.469261,0.008257,0.003639,0.092420,277.706268,14.147032,0.924203,-111.469261,0.092473,0.000000
68.420006,62.236839,-111.469261,0.008252,0.003639,0.092420,276.843292,14.103069,0.924203,-111.469261,0.092473,0.000000
68.650002,62.058472,-111.469261,0.008257,0.003639,0.092420,276.049866,14.062651,0.924203,-111.469261,0.092473,0.000000
68.880005,61.875641,-111.469261,0.008244,0.003639,0.092420,275.236603,14.021220,0.924203,-111.469261,0.092473,0.000000
69.110001,61.701370,-111.469261,0.008252,0.003639,0.092420,274.461395,13.981730,0.924203,-111.469261,0.092473,0.000000
69.340004,61.546837,-111.469261,0.008252,0.003638,0.092412,273.774017,13.946713,0.924116,-111.469261,0.092473,0.000000
69.570000,61.406448,-111.469261,0.008261,0.003638,0.092412,273.149536,13.914901,0.924116,-111.469261,0.092473,0.000000
69.800003,61.274628,-111.558228,0.008252,0.003638,0.092412,272.563171,13.885029,0.924116,-111.558228,0.092473,0.000000
70.030006,61.123444,-111.513741,0.008261,0.003638,0.092412,271.890656,13.850771,0.924116,-111.513741,0.092473,0.000000
70.260002,60.994232,-111.513741,0.008265,0.003638,0.092412,271.315887,13.821491,0.924116,-111.513741,0.092473,0.000000
70.490005,60.884010,-111.469261,0.008269,0.003638,0.092412,270.825592,13.796515,0.924116,-111.469261,0.092473,0.000000
70.720001,60.773788,-111.602707,0.008265,0.003638,0.092412,270.335327,13.771537,0.924116,-111.602707,0.092473,0.000000
70.950005,60.652771,-111.513741,0.008269,0.003638,0.092412,269.796997,13.744115,0.924116,-111.513741,0.092473,0.000000
71.180000,60.535095,-111.513741,0.008265,0.003638,0.092412,269.273560,13.717448,0.924116,-111.513741,0.092473,0.000000
71.410004,60.443497,-111.469261,0.008269,0.003638,0.092412,268.866089,13.696692,0.924116,-111.469261,0.092473,0.000000
71.640007,60.341461,-111.469261,0.008269,0.003638,0.092412,268.412231,13.673571,0.924116,-111.469261,0.092473,0.000000
71.870003,60.250977,-111.558228,0.008274,0.003638,0.092412,268.009735,13.653067,0.924116,-111.558228,0.092473,0.000000
72.100006,60.148949,-111.602707,0.008269,0.003638,0.092412,267.555878,13.629947,0.924116,-111.602707,0.092473,0.000000
72.330002,60.048409,-111.602707,0.008278,0.003638,0.092412,267.108673,13.607164,0.924116,-111.602707,0.092473,0.000000
72.560005,59.958290,-111.558228,0.008269,0.003638,0.092412,266.707794,13.586743,0.924116,-111.558228,0.092473,0.000000
72.790001,59.889030,-111.558228,0.008282,0.003638,0.092412,266.399719,13.571049,0.924116,-111.558228,0.092473,0.000000
73.020004,59.815300,-111.602707,0.008278,0.003638,0.092412,266.071747,13.554340,0.924116,-111.602707,0.092473,0.000000
73.250000,59.727051,-111.602707,0.008269,0.003638,0.092412,265.679199,13.534344,0.924116,-111.602707,0.092473,0.000000
73.480003,59.646988,-111.602707,0.008282,0.003638,0.092412,265.323059,13.516200,0.924116,-111.602707,0.092473,0.000000
73.710007,59.572517,-111.602707,0.008282,0.003638,0.092412,264.991791,13.499325,0.924116,-111.602707,0.092473,0.000000
73.940002,59.509209,-111.602707,0.008261,0.003638,0.092412,264.710175,13.484980,0.924116,-111.602707,0.092473,0.000000
74.170006,59.442558,-111.602707,0.008265,0.003638,0.092412,264.413696,13.469876,0.924116,-111.602707,0.092473,0.000000
74.400002,59.373665,-111.647186,0.008287,0.003638,0.092412,264.107239,13.454265,0.924116,-111.647186,0.092473,0.000000
74.630005,59.286903,-111.691666,0.008274,0.003638,0.092412,263.721313,13.434605,0.924116,-111.691666,0.092473,0.000000
74.860001,59.237007,-111.647186,0.008274,0.003638,0.092412,263.499359,13.423298,0.924116,-111.647186,0.092473,0.000000
75.090004,59.184128,-111.602707,0.008278,0.003638,0.092412,263.264160,13.411315,0.924116,-111.602707,0.092473,0.000000
75.320007,59.120453,-111.647186,0.008287,0.003638,0.092412,262.980896,13.396886,0.924116,-111.647186,0.092473,0.000000
75.550003,59.052681,-111.691666,0.008274,0.003638,0.092412,262.679443,13.381528,0.924116,-111.691666,0.092473,0.000000
75.780006,58.987892,-111.647186,0.008274,0.003638,0.092412,262.391235,13.366848,0.924116,-111.647186,0.092473,0.000000
76.010002,58.939484,-111.691666,0.008274,0.003638,0.092412,262.175903,13.355878,0.924116,-111.691666,0.092473,0.000000
76.240005,58.891449,-111.647186,0.008291,0.003638,0.092412,261.962250,13.344993,0.924116,-111.647186,0.092473,0.000000
76.470001,58.834473,-111.647186,0.008282,0.003638,0.092412,261.708801,13.332082,0.924116,-111.647186,0.092473,0.000000
76.700005,58.781593,-111.736153,0.008282,0.003638,0.092412,261.473572,13.320099,0.924116,-111.736153,0.092473,0.000000
76.930000,58.720901,-111.736153,0.008282,0.003638,0.092412,261.203613,13.306346,0.924116,-111.736153,0.092473,0.000000
77.160004,58.662811,-111.691666,0.008287,0.003638,0.092412,260.945221,13.293182,0.924116,-111.691666,0.092473,0.000000
77.390007,58.627060,-111.736153,0.008278,0.003638,0.092412,260.786194,13.285082,0.924116,-111.736153,0.092473,0.000000
77.620003,58.587219,-111.691666,0.008282,0.003638,0.092412,260.608978,13.276053,0.924116,-111.691666,0.092473,0.000000
77.850006,58.520935,-111.736153,0.008274,0.003638,0.092412,260.314117,13.261033,0.924116,-111.736153,0.092473,0.000000
78.080002,58.474014,-111.780632,0.008287,0.003638,0.092412,260.105408,13.250401,0.924116,-111.780632,0.092473,0.000000
78.310005,58.428215,-111.736153,0.008282,0.003638,0.092412,259.901672,13.240023,0.924116,-111.736153,0.092473,0.000000
78.540001,58.382782,-111.736153,0.008282,0.003638,0.092412,259.699585,13.229728,0.924116,-111.736153,0.092473,0.000000
78.770004,58.345177,-111.736153,0.008287,0.003638,0.092412,259.532318,13.221207,0.924116,-111.736153,0.092473,0.000000
79.000000,58.299004,-111.736153,0.008278,0.003638,0.092412,259.326935,13.210743,0.924116,-111.736153,0.092473,0.000000
79.230003,58.255058,-111.780632,0.008269,0.003638,0.092412,259.131439,13.200786,0.924116,-111.780632,0.092473,0.000000
79.460007,58.211494,-111.780632,0.008291,0.003638,0.092412,258.937653,13.190913,0.924116,-111.780632,0.092473,0.000000
79.690002,58.175003,-111.780632,0.008278,0.003638,0.092412,258.775330,13.182644,0.924116,-111.780632,0.092473,0.000000
79.920006,58.132179,-111.825111,0.008287,0.003638,0.092412,258.584839,13.172940,0.924116,-111.825111,0.092473,0.000000
80.150002,58.080421,-111.825111,0.008282,0.003638,0.092412,258.354614,13.161212,0.924116,-111.825111,0.092473,0.000000
80.380005,58.059937,-111.825111,0.008274,0.003638,0.092412,258.263489,13.156569,0.924116,-111.825111,0.092473,0.000000
80.610001,58.004456,-111.825111,0.008287,0.003638,0.092412,258.016693,13.143997,0.924116,-111.825111,0.092473,0.000000
80.840004,57.971687,-111.736153,0.008274,0.003638,0.092412,257.870941,13.136572,0.924116,-111.736153,0.092473,0.000000
81.070007,57.944504,-111.780632,0.008287,0.003638,0.092412,257.750031,13.130412,0.924116,-111.780632,0.092473,0.000000
81.300003,57.905029,-111.825111,0.008282,0.003638,0.092412,257.574432,13.121468,0.924116,-111.825111,0.092473,0.000000
81.530006,57.848434,-111.914070,0.008274,0.003638,0.092412,257.322693,13.108643,0.924116,-111.914070,0.092473,0.000000
81.760002,57.818642,-111.869591,0.008282,0.003638,0.092412,257.190155,13.101892,0.924116,-111.869591,0.092473,0.000000
81.990005,57.788849,-111.825111,0.008287,0.003638,0.092412,257.057648,13.095140,0.924116,-111.825111,0.092473,0.000000
82.220001,57.756081,-111.869591,0.008295,0.003638,0.092412,256.911865,13.087714,0.924116,-111.869591,0.092473,0.000000
82.450005,57.736343,-111.825111,0.008291,0.003638,0.092412,256.824097,13.083242,0.924116,-111.825111,0.092473,0.000000
82.680000,57.693527,-111.869591,0.008278,0.003638,0.092412,256.633636,13.073541,0.924116,-111.869591,0.092473,0.000000
82.910004,57.646606,-111.869591,0.008282,0.003638,0.092412,256.424927,13.062908,0.924116,-111.869591,0.092473,0.000000
83.140007,57.616814,-111.825111,0.008295,0.003638,0.092412,256.292389,13.056156,0.924116,-111.825111,0.092473,0.000000
83.370003,57.607132,-111.869591,0.008287,0.003638,0.092412,256.249329,13.053963,0.924116,-111.869591,0.092473,0.000000
83.600006,57.567291,-111.914070,0.008282,0.003638,0.092412,256.072113,13.044934,0.924116,-111.914070,0.092473,0.000000
83.830002,57.536758,-111.914070,0.008291,0.003638,0.092412,255.936279,13.038015,0.924116,-111.914070,0.092473,0.000000
84.060005,57.490211,-111.914070,0.008261,0.003638,0.092412,255.729233,13.027469,0.924116,-111.914070,0.092473,0.000000
84.290001,57.453712,-111.914070,0.008278,0.003638,0.092412,255.566879,13.019197,0.924116,-111.914070,0.092473,0.000000
84.520004,57.442169,-111.958557,0.008287,0.003638,0.092412,255.515533,13.016582,0.924116,-111.958557,0.092473,0.000000
84.750008,57.414986,-111.958557,0.008291,0.003638,0.092412,255.394608,13.010422,0.924116,-111.958557,0.092473,0.000000
84.980003,57.373283,-111.958557,0.008291,0.003638,0.092412,255.209106,13.000972,0.924116,-111.958557,0.092473,0.000000
85.210007,57.353546,-111.958557,0.008291,0.003638,0.092412,255.121307,12.996499,0.924116,-111.958557,0.092473,0.000000
85.440002,57.325989,-111.958557,0.008287,0.003638,0.092412,254.998734,12.990255,0.924116,-111.958557,0.092473,0.000000
85.670006,57.279076,-111.869591,0.008295,0.003638,0.092412,254.790054,12.979624,0.924116,-111.869591,0.092473,0.000000
85.900002,57.257477,-112.003036,0.008282,0.003638,0.092412,254.693970,12.974730,0.924116,-112.003036,0.092473,0.000000
86.130005,57.253754,-112.003036,0.008291,0.003638,0.092412,254.677414,12.973886,0.924116,-112.003036,0.092473,0.000000
86.360001,57.217262,-111.914070,0.008291,0.003638,0.092412,254.515091,12.965617,0.924116,-111.914070,0.092473,0.000000
86.590004,57.181885,-111.958557,0.008282,0.003638,0.092412,254.357727,12.957600,0.924116,-111.958557,0.092473,0.000000
86.820007,57.162148,-111.958557,0.008291,0.003638,0.092412,254.269928,12.953128,0.924116,-111.958557,0.092473,0.000000
87.050003,57.136826,-112.047516,0.008291,0.003638,0.092412,254.157288,12.947390,0.924116,-112.047516,0.092473,0.000000
87.280006,57.119324,-112.047516,0.008278,0.003638,0.092412,254.079437,12.943424,0.924116,-112.047516,0.092473,0.000000
87.510002,57.100708,-112.047516,0.008287,0.003638,0.092412,253.996628,12.939205,0.924116,-112.047516,0.092473,0.000000
87.740005,57.072037,-112.003036,0.008295,0.003638,0.092412,253.869095,12.932709,0.924116,-112.003036,0.092473,0.000000
87.970001,57.039268,-112.003036,0.008287,0.003638,0.092412,253.723343,12.925282,0.924116,-112.003036,0.092473,0.000000
88.200005,57.015060,-112.047516,0.008291,0.003638,0.092412,253.615662,12.919798,0.924116,-112.047516,0.092473,0.000000
88.430008,56.999794,-112.047516,0.008291,0.003638,0.092412,253.547745,12.916338,0.924116,-112.047516,0.092473,0.000000
88.660004,56.962555,-112.003036,0.008278,0.003638,0.092412,253.382095,12.907900,0.924116,-112.003036,0.092473,0.000000
88.890007,56.948410,-111.958557,0.008295,0.003638,0.092412,253.319183,12.904695,0.924116,-111.958557,0.092473,0.000000
89.120003,56.931274,-112.003036,0.008300,0.003638,0.092412,253.242950,12.900811,0.924116,-112.003036,0.092473,0.000000
89.350006,56.903725,-112.091995,0.008291,0.003638,0.092412,253.120407,12.894568,0.924116,-112.091995,0.092473,0.000000
89.580002,56.886963,-112.091995,0.008291,0.003638,0.092412,253.045853,12.890770,0.924116,-112.091995,0.092473,0.000000
89.810005,56.882126,-112.047516,0.008282,0.003638,0.092412,253.024338,12.889673,0.924116,-112.047516,0.092473,0.000000
90.040001,56.843399,-112.047516,0.008300,0.003638,0.092412,252.852066,12.880898,0.924116,-112.047516,0.092473,0.000000
90.270004,56.812119,-112.047516,0.008291,0.003638,0.092412,252.712921,12.873810,0.924116,-112.047516,0.092473,0.000000
90.500008,56.790146,-112.091995,0.008291,0.003638,0.092412,252.615189,12.868832,0.924116,-112.091995,0.092473,0.000000
90.730003,56.777863,-112.047516,0.008287,0.003638,0.092412,252.560547,12.866048,0.924116,-112.047516,0.092473,0.000000
90.960007,56.758499,-112.091995,0.008300,0.003638,0.092412,252.474411,12.861659,0.924116,-112.091995,0.092473,0.000000
91.190002,56.747322,-112.091995,0.008287,0.003638,0.092412,252.424698,12.859126,0.924116,-112.091995,0.092473,0.000000
91.420006,56.729454,-112.136475,0.008300,0.003638,0.092412,252.345215,12.855079,0.924116,-112.136475,0.092473,0.000000
91.650002,56.697426,-112.136475,0.008291,0.003638,0.092412,252.202744,12.847820,0.924116,-112.136475,0.092473,0.000000
91.880005,56.684769,-112.136475,0.008287,0.003638,0.092412,252.146439,12.844953,0.924116,-112.136475,0.092473,0.000000
92.110001,56.662796,-112.136475,0.008287,0.003638,0.092412,252.048706,12.839972,0.924116,-112.136475,0.092473,0.000000
92.340004,56.640823,-112.136475,0.008304,0.003638,0.092412,251.950958,12.834994,0.924116,-112.136475,0.092473,0.000000
92.570007,56.611038,-112.136475,0.008287,0.003638,0.092412,251.818481,12.828244,0.924116,-112.136475,0.092473,0.000000
92.800003,56.607315,-112.180962,0.008295,0.003638,0.092412,251.801910,12.827401,0.924116,-112.180962,0.092473,0.000000
93.030006,56.597260,-112.180962,0.008291,0.003638,0.092412,251.757187,12.825123,0.924116,-112.180962,0.092473,0.000000
93.260002,56.575287,-112.180962,0.008304,0.003638,0.092412,251.659439,12.820143,0.924116,-112.180962,0.092473,0.000000
93.490005,56.562630,-112.136475,0.008300,0.003638,0.092412,251.603149,12.817275,0.924116,-112.136475,0.092473,0.000000
93.720001,56.532837,-112.136475,0.008304,0.003638,0.092412,251.470612,12.810524,0.924116,-112.136475,0.092473,0.000000
93.950005,56.517944,-112.225441,0.008300,0.003638,0.092412,251.404373,12.807149,0.924116,-112.225441,0.092473,0.000000
94.180008,56.516457,-112.225441,0.008291,0.003638,0.092412,251.397751,12.806812,0.924116,-112.225441,0.092473,0.000000
94.410004,56.480705,-112.180962,0.008295,0.003638,0.092412,251.238724,12.798711,0.924116,-112.180962,0.092473,0.000000
94.640007,56.462463,-112.180962,0.008304,0.003638,0.092412,251.157578,12.794577,0.924116,-112.180962,0.092473,0.000000
94.870003,56.452408,-112.136475,0.008282,0.003638,0.092412,251.112854,12.792298,0.924116,-112.136475,0.092473,0.000000
95.100006,56.436394,-112.225441,0.008291,0.003638,0.092412,251.041611,12.788670,0.924116,-112.225441,0.092473,0.000000
95.330002,56.413681,-112.269920,0.008295,0.003638,0.092412,250.940582,12.783524,0.924116,-112.269920,0.092473,0.000000
95.560005,56.393196,-112.225441,0.008300,0.003638,0.092412,250.849472,12.778881,0.924116,-112.225441,0.092473,0.000000
95.600006,56.395432,-112.314400,0.008300,0.003638,0.092412,250.859406,12.779387,0.924116,-112.314400,0.092473,0.000000