File: Data/compression 4 4 days/AutoNoheating-17-4-2-240226_02262024_164117.csv
Time (sec),S:Load (lbs),S:HL1 (DIM),S:LVDT (in),S:Position (in),Ch:Position (mm),Ch:Load (N),Ch:Stress (MPa),Ch:Strain (mm/mm),Ch:HL1 (DIM),Set Point (),Cycles ()
0.110000,-0.003723,-136.645477,0.000000,-0.000000,-0.000000,-0.016561,-0.000844,-0.000000,-136.645477,0.000182,0.000000
0.330000,-0.000374,-136.645477,0.000004,-0.000000,-0.000000,-0.001663,-0.000085,-0.000000,-136.645477,0.000182,0.000000
0.550000,-0.008942,-136.645477,0.000004,0.000070,0.001786,-0.039774,-0.002026,0.017865,-136.645477,0.002472,0.000000
0.770000,-0.021973,-136.734436,0.000073,0.000199,0.005065,-0.097739,-0.004979,0.050646,-136.734436,0.006131,0.000000
0.990000,-0.010429,-136.645477,0.000211,0.000346,0.008785,-0.046392,-0.002363,0.087847,-136.645477,0.009791,0.000000
1.210000,-0.011917,-136.689957,0.000354,0.000490,0.012436,-0.053010,-0.002700,0.124360,-136.689957,0.013468,0.000000
1.430000,0.010048,-136.734436,0.000500,0.000631,0.016035,0.044695,0.002277,0.160347,-136.734436,0.017127,0.000000
1.650000,0.011909,-136.689957,0.000629,0.000772,0.019599,0.052976,0.002699,0.195993,-136.689957,0.020787,0.000000
1.870000,0.007820,-136.778931,0.000789,0.000923,0.023450,0.034786,0.001772,0.234497,-136.778931,0.024464,0.000000
2.090000,-0.011917,-136.689957,0.000936,0.001064,0.027023,-0.053010,-0.002700,0.270226,-136.689957,0.028124,0.000000
2.310000,-0.008568,-136.734436,0.001099,0.001210,0.030734,-0.038112,-0.001941,0.307345,-136.734436,0.031784,0.000000
2.530000,0.009308,-136.734436,0.001233,0.001354,0.034403,0.041403,0.002109,0.344028,-136.734436,0.035461,0.000000
2.750000,-0.007454,-136.734436,0.001367,0.001497,0.038028,-0.033157,-0.001689,0.380276,-136.734436,0.039120,0.000000
2.970000,0.012283,-136.823410,0.001509,0.001641,0.041670,0.054639,0.002783,0.416702,-136.823410,0.042780,0.000000
3.190000,-0.011917,-136.778931,0.001664,0.001787,0.045382,-0.053010,-0.002700,0.453816,-136.778931,0.046457,0.000000
3.410000,-0.017876,-136.823410,0.001807,0.001932,0.049085,-0.079515,-0.004051,0.490848,-136.823410,0.050117,0.000000
3.630000,-0.012665,-136.778931,0.001949,0.002072,0.052640,-0.056336,-0.002870,0.526403,-136.778931,0.053777,0.000000
3.850000,-0.005219,-136.823410,0.002091,0.002215,0.056257,-0.023213,-0.001183,0.562568,-136.823410,0.057454,0.000000
4.070000,-0.002983,-136.867889,0.002242,0.002362,0.060003,-0.013269,-0.000676,0.600031,-136.867889,0.061113,0.000000
4.290000,0.014893,-136.778931,0.002402,0.002513,0.063836,0.066245,0.003375,0.638364,-136.778931,0.064773,0.000000
4.510000,0.014893,-136.778931,0.002548,0.002654,0.067418,0.066245,0.003375,0.674181,-136.778931,0.068450,0.000000
4.730000,0.041702,-136.778931,0.002673,0.002796,0.071008,0.185501,0.009450,0.710084,-136.778931,0.072110,0.000000
4.950000,-0.000748,-136.778931,0.002833,0.002947,0.074841,-0.003326,-0.000169,0.748414,-136.778931,0.075769,0.000000
5.170000,-0.000000,-136.823410,0.002966,0.003085,0.078354,-0.000000,-0.000000,0.783538,-136.823410,0.079429,0.000000
5.390000,-0.025696,-136.867889,0.003109,0.003227,0.081970,-0.114301,-0.005823,0.819699,-136.867889,0.083106,0.000000
5.610000,-0.048409,-136.867889,0.003268,0.003370,0.085595,-0.215332,-0.010970,0.855950,-136.867889,0.086766,0.000000
5.830000,0.007072,-136.867889,0.003402,0.003517,0.089324,0.031460,0.001603,0.893239,-136.867889,0.090425,0.000000
6.050000,0.030159,-136.867889,0.003544,0.003657,0.092880,0.134154,0.006834,0.928798,-136.867889,0.094102,0.000000
6.270000,0.042816,-136.867889,0.003691,0.003803,0.096600,0.190456,0.009702,0.966000,-136.867889,0.097762,0.000000
6.490000,0.028671,-136.867889,0.003842,0.003954,0.100425,0.127536,0.006497,1.004246,-136.867889,0.101422,0.000000
6.710001,0.017502,-136.867889,0.003992,0.004097,0.104067,0.077852,0.003966,1.040668,-136.867889,0.105099,0.000000
6.930000,-0.007820,-136.912369,0.004143,0.004240,0.107701,-0.034786,-0.001772,1.077007,-136.912369,0.108759,0.000000
7.150001,-0.016014,-136.867889,0.004286,0.004382,0.111291,-0.071234,-0.003629,1.112911,-136.867889,0.112418,0.000000
7.370000,-0.016014,-136.956848,0.004419,0.004522,0.114855,-0.071234,-0.003629,1.148553,-136.956848,0.116095,0.000000
7.590000,0.016380,-136.912369,0.004575,0.004672,0.118663,0.072863,0.003712,1.186625,-136.912369,0.119755,0.000000
7.810000,0.046173,-136.956848,0.004721,0.004814,0.122287,0.205388,0.010463,1.222873,-136.956848,0.123415,0.000000
8.030001,0.439026,-136.912369,0.004846,0.004954,0.125834,1.952885,0.099485,1.258341,-136.912369,0.127092,0.000000
8.250000,0.704529,-136.912369,0.004889,-0.000003,-0.000087,3.133901,0.159649,-0.000867,-136.912369,0.000070,0.000000
8.470000,0.671761,-136.956848,0.004894,-0.000004,-0.000095,2.988140,0.152223,-0.000954,-136.956848,0.000070,0.000000
8.690001,0.693726,-136.956848,0.004889,-0.000004,-0.000095,3.085845,0.157200,-0.000954,-136.956848,0.000182,0.000000
8.910001,0.674362,-136.912369,0.004898,-0.000004,-0.000095,2.999713,0.152813,-0.000954,-136.912369,0.000547,0.000000
9.130000,0.645691,-136.956848,0.004898,-0.000004,-0.000095,2.872177,0.146316,-0.000954,-136.956848,0.000919,0.000000
9.350000,0.644203,-136.912369,0.004894,-0.000003,-0.000087,2.865559,0.145979,-0.000867,-136.912369,0.001283,0.000000
9.570001,0.990509,-136.956848,0.004907,0.000030,0.000763,4.406004,0.224453,0.007634,-136.956848,0.001648,0.000000
9.790001,1.144669,-136.912369,0.004919,0.000042,0.001067,5.091740,0.259386,0.010666,-136.912369,0.002021,0.000000
10.010000,1.405701,-136.956848,0.004941,0.000058,0.001474,6.252869,0.318536,0.014742,-136.956848,0.002385,0.000000
10.230000,1.490601,-136.956848,0.004945,0.000068,0.001717,6.630523,0.337775,0.017172,-136.956848,0.002749,0.000000
10.450001,1.845474,-136.912369,0.004967,0.000089,0.002255,8.209080,0.418190,0.022550,-136.912369,0.003113,0.000000
10.670000,2.065178,-136.956848,0.004980,0.000103,0.002619,9.186370,0.467976,0.026191,-136.956848,0.003486,0.000000
10.890000,2.315033,-136.956848,0.004980,0.000117,0.002983,10.297781,0.524594,0.029833,-136.956848,0.003850,0.000000
11.110001,2.594688,-136.956848,0.005006,0.000135,0.003426,11.541751,0.587965,0.034257,-136.956848,0.004215,0.000000
11.330001,2.780876,-136.956848,0.005010,0.000145,0.003694,12.369955,0.630156,0.036944,-136.956848,0.004588,0.000000
11.550000,2.963341,-136.956848,0.005027,0.000158,0.004007,13.181598,0.671503,0.040067,-136.956848,0.004952,0.000000
11.770000,3.354698,-137.045807,0.005044,0.000178,0.004510,14.922442,0.760185,0.045097,-137.045807,0.005316,0.000000
11.990001,3.626534,-137.045807,0.005057,0.000194,0.004917,16.131626,0.821784,0.049173,-137.045807,0.005680,0.000000
12.210001,3.783302,-137.045807,0.005066,0.000202,0.005126,16.828970,0.857309,0.051255,-137.045807,0.006053,0.000000
12.430000,3.910278,-137.045807,0.005083,0.000212,0.005377,17.393787,0.886082,0.053768,-137.045807,0.006418,0.000000
12.650001,4.420433,-137.001328,0.005092,0.000234,0.005949,19.663069,1.001684,0.059491,-137.001328,0.006782,0.000000
12.870001,4.733223,-137.045807,0.005113,0.000252,0.006392,21.054428,1.072564,0.063916,-137.045807,0.007155,0.000000
13.090000,4.833389,-137.045807,0.005105,0.000262,0.006660,21.499989,1.095262,0.066603,-137.045807,0.007519,0.000000
13.310000,5.008408,-137.045807,0.005135,0.000276,0.006999,22.278509,1.134921,0.069986,-137.045807,0.007883,0.000000
13.530001,5.389343,-137.090286,0.005148,0.000294,0.007467,23.972996,1.221243,0.074668,-137.090286,0.008247,0.000000
13.750001,5.631760,-137.001328,0.005161,0.000307,0.007805,25.051317,1.276175,0.078052,-137.001328,0.008620,0.000000
13.970000,5.822784,-137.045807,0.005170,0.000322,0.008169,25.901039,1.319462,0.081693,-137.045807,0.008985,0.000000
14.190001,5.962799,-137.090286,0.005170,0.000331,0.008404,26.523855,1.351190,0.084036,-137.090286,0.009349,0.000000
14.410001,6.418579,-137.134766,0.005208,0.000353,0.008967,28.551266,1.454471,0.089672,-137.134766,0.009722,0.000000
14.630001,6.671425,-137.045807,0.005221,0.000370,0.009392,29.675980,1.511767,0.093922,-137.045807,0.010086,0.000000
14.850000,6.769730,-137.090286,0.005230,0.000383,0.009722,30.113262,1.534043,0.097215,-137.090286,0.010450,0.000000
15.070001,6.831917,-137.045807,0.005238,0.000394,0.010008,30.389883,1.548134,0.100080,-137.045807,0.010814,0.000000
15.290001,7.033737,-137.090286,0.005234,0.000409,0.010398,31.287626,1.593868,0.103982,-137.090286,0.011187,0.000000
15.510001,7.273178,-137.134766,0.005260,0.000422,0.010719,32.352711,1.648126,0.107188,-137.134766,0.011551,0.000000
15.730000,7.428085,-137.090286,0.005277,0.000436,0.011066,33.041775,1.683228,0.110659,-137.090286,0.011916,0.000000
15.950001,7.715179,-137.045807,0.005290,0.000453,0.011500,34.318832,1.748285,0.114996,-137.045807,0.012289,0.000000
16.170000,7.571449,-137.090286,0.005295,0.000457,0.011612,33.679489,1.715715,0.116121,-137.090286,0.012653,0.000000
16.390001,7.968025,-137.134766,0.005316,0.000478,0.012132,35.443546,1.805580,0.121325,-137.134766,0.013017,0.000000
16.610001,8.225334,-137.179260,0.005320,0.000495,0.012584,36.588112,1.863887,0.125836,-137.179260,0.013381,0.000000
16.830000,8.236877,-137.090286,0.005346,0.000507,0.012870,36.639462,1.866503,0.128698,-137.090286,0.013754,0.000000
17.050001,8.356781,-137.179260,0.005355,0.000521,0.013243,37.172817,1.893674,0.132426,-137.179260,0.014118,0.000000
17.270000,8.508705,-137.134766,0.005376,0.000535,0.013598,37.848610,1.928100,0.135980,-137.134766,0.014483,0.000000
17.490002,8.681488,-137.179260,0.005385,0.000552,0.014032,38.617187,1.967253,0.140317,-137.179260,0.014856,0.000000
17.710001,8.801018,-137.179260,0.005398,0.000566,0.014370,39.148884,1.994339,0.143701,-137.179260,0.015220,0.000000
17.930000,8.925018,-137.179260,0.005415,0.000579,0.014717,39.700462,2.022438,0.147168,-137.179260,0.015584,0.000000
18.150002,8.876610,-137.134766,0.005415,0.000589,0.014951,39.485134,2.011469,0.149511,-137.134766,0.015948,0.000000
18.370001,9.186050,-137.134766,0.005428,0.000608,0.015437,40.861591,2.081589,0.154367,-137.134766,0.016321,0.000000
18.590000,9.380432,-137.223740,0.005445,0.000625,0.015887,41.726246,2.125636,0.158875,-137.223740,0.016685,0.000000
18.810001,9.358086,-137.268219,0.005467,0.000638,0.016208,41.626842,2.120573,0.162084,-137.268219,0.017050,0.000000
19.030001,9.438148,-137.223740,0.005471,0.000652,0.016556,41.982983,2.138715,0.165555,-137.223740,0.017414,0.000000
19.250000,9.472778,-137.223740,0.005480,0.000664,0.016868,42.137024,2.146562,0.168678,-137.223740,0.017787,0.000000
19.470001,9.603111,-137.223740,0.005497,0.000678,0.017232,42.716774,2.176096,0.172319,-137.223740,0.018151,0.000000
19.690001,9.741631,-137.179260,0.005514,0.000693,0.017613,43.332935,2.207485,0.176134,-137.179260,0.018515,0.000000
19.910002,9.704765,-137.268219,0.005523,0.000703,0.017865,43.168953,2.199131,0.178651,-137.268219,0.018888,0.000000
20.130001,9.711472,-137.312698,0.005536,0.000718,0.018238,43.198784,2.200651,0.182379,-137.312698,0.019253,0.000000
20.350000,10.241356,-137.179260,0.005566,0.000741,0.018828,45.555828,2.320724,0.188276,-137.179260,0.019617,0.000000
20.570002,10.382484,-137.268219,0.005575,0.000759,0.019270,46.183598,2.352705,0.192697,-137.268219,0.019981,0.000000
20.790001,10.298698,-137.223740,0.005592,0.000771,0.019582,45.810898,2.333718,0.195819,-137.223740,0.020354,0.000000
21.010000,10.230186,-137.268219,0.005588,0.000781,0.019842,45.506142,2.318193,0.198423,-137.268219,0.020718,0.000000
21.230001,10.271889,-137.268219,0.005618,0.000793,0.020146,45.691643,2.327643,0.201459,-137.268219,0.021082,0.000000
21.450001,10.388443,-137.223740,0.005622,0.000809,0.020536,46.210102,2.354055,0.205361,-137.223740,0.021455,0.000000
21.670000,10.625648,-137.223740,0.005635,0.000824,0.020935,47.265244,2.407806,0.209350,-137.223740,0.021820,0.000000
21.890001,10.612236,-137.268219,0.005652,0.000836,0.021230,47.205582,2.404767,0.212299,-137.268219,0.022184,0.000000
22.110001,10.690437,-137.312698,0.005665,0.000850,0.021594,47.553440,2.422488,0.215940,-137.312698,0.022548,0.000000
22.330002,10.893005,-137.312698,0.005687,0.000867,0.022010,48.454510,2.468390,0.220103,-137.312698,0.022921,0.000000
22.550001,10.964500,-137.312698,0.005700,0.000881,0.022374,48.772533,2.484591,0.223744,-137.312698,0.023285,0.000000
22.770000,11.157768,-137.268219,0.005713,0.000899,0.022826,49.632233,2.528386,0.228256,-137.268219,0.023649,0.000000
22.990002,10.993179,-137.268219,0.005713,0.000908,0.023051,48.900105,2.491090,0.230508,-137.268219,0.024022,0.000000
23.210001,11.049408,-137.357178,0.005734,0.000920,0.023380,49.150223,2.503832,0.233804,-137.357178,0.024386,0.000000
23.430000,11.187553,-137.401657,0.005747,0.000935,0.023745,49.764725,2.535136,0.237445,-137.401657,0.024751,0.000000
23.650002,11.363312,-137.357178,0.005760,0.000950,0.024118,50.546535,2.574963,0.241177,-137.357178,0.025115,0.000000
23.870001,11.313042,-137.268219,0.005777,0.000961,0.024413,50.322922,2.563572,0.244126,-137.268219,0.025488,0.000000
24.090002,11.403534,-137.357178,0.005769,0.000976,0.024803,50.725452,2.584078,0.248028,-137.357178,0.025852,0.000000
24.310001,11.787445,-137.401657,0.005808,0.000995,0.025271,52.433174,2.671073,0.252710,-137.401657,0.026216,0.000000
24.530001,11.813141,-137.357178,0.005812,0.001009,0.025627,52.547474,2.676896,0.256268,-137.357178,0.026589,0.000000
24.750002,11.746483,-137.357178,0.005842,0.001020,0.025895,52.250965,2.661791,0.258955,-137.357178,0.026953,0.000000
24.970001,11.893944,-137.401657,0.005842,0.001037,0.026346,52.906906,2.695206,0.263463,-137.401657,0.027318,0.000000
25.190001,11.873093,-137.357178,0.005842,0.001048,0.026615,52.814156,2.690481,0.266154,-137.357178,0.027682,0.000000
25.410002,12.068588,-137.357178,0.005864,0.001064,0.027023,53.683762,2.734781,0.270230,-137.357178,0.028055,0.000000
25.630001,12.269295,-137.446136,0.005881,0.001080,0.027439,54.576550,2.780262,0.274390,-137.446136,0.028419,0.000000
25.850000,12.269669,-137.401657,0.005907,0.001093,0.027760,54.578213,2.780347,0.277599,-137.401657,0.028783,0.000000
26.070002,12.320686,-137.401657,0.005907,0.001106,0.028098,54.805149,2.791907,0.280983,-137.401657,0.029156,0.000000
26.290001,12.697151,-137.401657,0.005928,0.001128,0.028644,56.479748,2.877216,0.286445,-137.401657,0.029520,0.000000
26.510002,12.778702,-137.446136,0.005928,0.001144,0.029052,56.842503,2.895695,0.290521,-137.446136,0.029885,0.000000
26.730001,12.665871,-137.401657,0.005946,0.001154,0.029304,56.340607,2.870127,0.293038,-137.401657,0.030249,0.000000
26.950001,12.676674,-137.446136,0.005976,0.001168,0.029659,56.388660,2.872576,0.296592,-137.446136,0.030622,0.000000
27.170002,12.903450,-137.446136,0.005980,0.001185,0.030093,57.397411,2.923964,0.300929,-137.446136,0.030986,0.000000
27.390001,12.886322,-137.446136,0.005984,0.001196,0.030388,57.321224,2.920082,0.303878,-137.446136,0.031350,0.000000
27.610001,13.123146,-137.490616,0.006015,0.001213,0.030804,58.374668,2.973747,0.308037,-137.490616,0.031723,0.000000
27.830002,12.988724,-137.446136,0.006036,0.001221,0.031003,57.776730,2.943287,0.310032,-137.446136,0.032088,0.000000
28.050001,13.232994,-137.490616,0.006040,0.001241,0.031524,58.863297,2.998639,0.315236,-137.490616,0.032452,0.000000
28.270000,13.629204,-137.446136,0.006058,0.001260,0.032001,60.625725,3.088422,0.320005,-137.446136,0.032816,0.000000
28.490002,13.587120,-137.446136,0.006066,0.001272,0.032304,60.438530,3.078885,0.323041,-137.446136,0.033189,0.000000
28.710001,13.416206,-137.446136,0.006084,0.001283,0.032582,59.678265,3.040156,0.325819,-137.446136,0.033553,0.000000
28.930002,13.707024,-137.490616,0.006096,0.001299,0.032990,60.971886,3.106056,0.329895,-137.490616,0.033917,0.000000
29.150002,13.728256,-137.490616,0.006109,0.001311,0.033301,61.066334,3.110867,0.333014,-137.490616,0.034290,0.000000
29.370001,13.865662,-137.490616,0.006118,0.001326,0.033683,61.677544,3.142004,0.336833,-137.490616,0.034654,0.000000
29.590002,14.222389,-137.446136,0.006140,0.001344,0.034143,63.264347,3.222839,0.341428,-137.446136,0.035019,0.000000
29.810001,14.272659,-137.535095,0.006131,0.001358,0.034489,63.487961,3.234231,0.344895,-137.535095,0.035383,0.000000
30.030001,14.150894,-137.490616,0.006153,0.001369,0.034776,62.946320,3.206638,0.347760,-137.490616,0.035756,0.000000
30.250002,14.410439,-137.535095,0.006174,0.001385,0.035175,64.100830,3.265452,0.351749,-137.535095,0.036120,0.000000
30.470001,14.460709,-137.490616,0.006191,0.001397,0.035487,64.324448,3.276844,0.354868,-137.490616,0.036484,0.000000
30.690001,14.717278,-137.579575,0.006204,0.001414,0.035921,65.465721,3.334983,0.359205,-137.579575,0.036857,0.000000
30.910002,14.824890,-137.579575,0.006213,0.001428,0.036276,65.944405,3.359368,0.362759,-137.579575,0.037221,0.000000
31.130001,14.869949,-137.579575,0.006234,0.001443,0.036640,66.144836,3.369579,0.366404,-137.579575,0.037586,0.000000
31.350002,15.084435,-137.535095,0.006239,0.001457,0.037005,67.098915,3.418182,0.370045,-137.535095,0.037950,0.000000
31.570002,14.953362,-137.535095,0.006252,0.001468,0.037282,66.515877,3.388480,0.372820,-137.535095,0.038323,0.000000
31.790001,15.231522,-137.535095,0.006273,0.001483,0.037664,67.753189,3.451512,0.376639,-137.535095,0.038687,0.000000
32.010002,15.460899,-137.490616,0.006286,0.001501,0.038123,68.773514,3.503490,0.381234,-137.490616,0.039051,0.000000
32.230003,15.710022,-137.579575,0.006282,0.001517,0.038531,69.881668,3.559942,0.385310,-137.579575,0.039416,0.000000
32.450001,15.804977,-137.579575,0.006321,0.001532,0.038904,70.304054,3.581459,0.389038,-137.579575,0.039788,0.000000
32.670002,15.825081,-137.535095,0.006338,0.001544,0.039225,70.393478,3.586015,0.392248,-137.535095,0.040152,0.000000
32.890003,15.914078,-137.535095,0.006329,0.001560,0.039615,70.789352,3.606182,0.396150,-137.535095,0.040517,0.000000
33.110001,16.262619,-137.579575,0.006338,0.001578,0.040074,72.339745,3.685162,0.400745,-137.579575,0.040890,0.000000
33.330002,16.357948,-137.579575,0.006364,0.001593,0.040456,72.763786,3.706764,0.404560,-137.579575,0.041254,0.000000
33.550003,16.217934,-137.579575,0.006377,0.001601,0.040655,72.140968,3.675036,0.406554,-137.579575,0.041618,0.000000
33.770000,16.117020,-137.579575,0.006390,0.001611,0.040916,71.692085,3.652169,0.409158,-137.579575,0.041982,0.000000
33.990002,16.751915,-137.624069,0.006420,0.001635,0.041523,74.516243,3.796038,0.415229,-137.624069,0.042355,0.000000
34.210003,17.002899,-137.668549,0.006407,0.001650,0.041922,75.632675,3.852912,0.419219,-137.668549,0.042720,0.000000
34.430000,16.879265,-137.713028,0.006424,0.001662,0.042225,75.082718,3.824896,0.422254,-137.713028,0.043084,0.000000
34.650002,16.988373,-137.668549,0.006459,0.001677,0.042590,75.568054,3.849620,0.425895,-137.668549,0.043457,0.000000
34.870003,17.265419,-137.713028,0.006463,0.001694,0.043032,76.800423,3.912400,0.430320,-137.713028,0.043821,0.000000
35.090000,17.435219,-137.624069,0.006476,0.001709,0.043414,77.555725,3.950877,0.434135,-137.624069,0.044185,0.000000
35.310001,17.498894,-137.713028,0.006493,0.001722,0.043734,77.838966,3.965306,0.437341,-137.713028,0.044549,0.000000
35.530003,17.390533,-137.668549,0.006502,0.001732,0.044003,77.356956,3.940751,0.440032,-137.668549,0.044923,0.000000
35.750000,17.917442,-137.668549,0.006515,0.001752,0.044497,79.700768,4.060150,0.444975,-137.668549,0.045287,0.000000
35.970001,18.226143,-137.668549,0.006545,0.001769,0.044931,81.073936,4.130103,0.449309,-137.668549,0.045651,0.000000
36.190002,18.278275,-137.624069,0.006554,0.001783,0.045295,81.305824,4.141916,0.452954,-137.624069,0.046024,0.000000
36.410000,18.192253,-137.624069,0.006545,0.001794,0.045564,80.923187,4.122424,0.455641,-137.624069,0.046388,0.000000
36.630001,18.413818,-137.713028,0.006558,0.001809,0.045954,81.908752,4.172631,0.459543,-137.713028,0.046752,0.000000
36.850002,18.531113,-137.713028,0.006575,0.001824,0.046327,82.430504,4.199210,0.463271,-137.713028,0.047116,0.000000
37.070004,18.642082,-137.668549,0.006597,0.001837,0.046657,82.924126,4.224356,0.466568,-137.668549,0.047489,0.000000
37.290001,19.007378,-137.757507,0.006618,0.001853,0.047064,84.549042,4.307134,0.470644,-137.757507,0.047854,0.000000
37.510002,18.902367,-137.713028,0.006622,0.001861,0.047281,84.081924,4.283338,0.472813,-137.713028,0.048218,0.000000
37.730003,19.140312,-137.713028,0.006635,0.001876,0.047645,85.140358,4.337256,0.476454,-137.713028,0.048591,0.000000
37.950001,19.621048,-137.713028,0.006644,0.001894,0.048114,87.278778,4.446193,0.481136,-137.713028,0.048955,0.000000
38.170002,19.581947,-137.713028,0.006653,0.001906,0.048417,87.104851,4.437333,0.484171,-137.713028,0.049319,0.000000
38.390003,19.846329,-137.757507,0.006666,0.001922,0.048816,88.280876,4.497242,0.488161,-137.757507,0.049684,0.000000
38.610001,19.971825,-137.757507,0.006674,0.001935,0.049146,88.839111,4.525681,0.491457,-137.757507,0.050056,0.000000
38.830002,20.316635,-137.801987,0.006700,0.001952,0.049571,90.372910,4.603815,0.495708,-137.801987,0.050420,0.000000
39.050003,20.535217,-137.713028,0.006722,0.001967,0.049952,91.345207,4.653347,0.499523,-137.713028,0.050785,0.000000
39.270000,20.613045,-137.757507,0.006730,0.001979,0.050273,91.691399,4.670983,0.502732,-137.757507,0.051158,0.000000
39.490002,20.480110,-137.801987,0.006735,0.001988,0.050498,91.100082,4.640859,0.504984,-137.801987,0.051522,0.000000
39.710003,21.087448,-137.757507,0.006748,0.002009,0.051019,93.801651,4.778484,0.510189,-137.757507,0.051886,0.000000
39.930000,21.463173,-137.846466,0.006760,0.002025,0.051444,95.472961,4.863624,0.514439,-137.846466,0.052250,0.000000
40.150002,21.480675,-137.801987,0.006782,0.002037,0.051730,95.550812,4.867590,0.517301,-137.801987,0.052623,0.000000
40.370003,21.615105,-137.801987,0.006804,0.002051,0.052094,96.148788,4.898053,0.520942,-137.801987,0.052987,0.000000
40.590000,21.670212,-137.801987,0.006808,0.002063,0.052406,96.393913,4.910540,0.524064,-137.801987,0.053352,0.000000
40.810001,21.993431,-137.801987,0.006812,0.002080,0.052823,97.831665,4.983782,0.528228,-137.801987,0.053725,0.000000
41.030003,22.296913,-137.846466,0.006825,0.002095,0.053204,99.181625,5.052553,0.532043,-137.846466,0.054089,0.000000
41.250004,22.160629,-137.846466,0.006838,0.002103,0.053404,98.575401,5.021670,0.534037,-137.846466,0.054453,0.000000
41.470001,21.917465,-137.801987,0.006847,0.002110,0.053586,97.493752,4.966568,0.535858,-137.801987,0.054817,0.000000
41.690002,23.415154,-137.801987,0.006864,0.002142,0.054401,104.155807,5.305949,0.544011,-137.801987,0.055190,0.000000
41.910004,23.744698,-137.890945,0.006864,0.002157,0.054800,105.621689,5.380625,0.548000,-137.890945,0.055555,0.000000
42.130001,23.754753,-137.801987,0.006890,0.002171,0.055138,105.666420,5.382904,0.551383,-137.801987,0.055919,0.000000
42.350002,23.616974,-137.890945,0.006911,0.002180,0.055381,105.053543,5.351683,0.553810,-137.890945,0.056292,0.000000
42.570004,23.672829,-137.890945,0.006920,0.002192,0.055685,105.302002,5.364340,0.556845,-137.890945,0.056656,0.000000
42.790001,24.113724,-137.846466,0.006929,0.002208,0.056083,107.263199,5.464248,0.560834,-137.846466,0.057020,0.000000
43.010002,24.439919,-137.935425,0.006954,0.002223,0.056474,108.714188,5.538165,0.564737,-137.935425,0.057384,0.000000
43.230003,24.507317,-137.935425,0.006950,0.002235,0.056769,109.013992,5.553438,0.567685,-137.935425,0.057757,0.000000
43.450001,24.759415,-137.890945,0.006976,0.002248,0.057107,110.135376,5.610563,0.571069,-137.890945,0.058122,0.000000
43.670002,25.239777,-137.935425,0.006985,0.002265,0.057532,112.272133,5.719415,0.575319,-137.935425,0.058486,0.000000
43.890003,25.606186,-137.846466,0.006993,0.002280,0.057922,113.902000,5.802445,0.579221,-137.846466,0.058850,0.000000
44.110001,26.088036,-137.890945,0.006998,0.002298,0.058364,116.045380,5.911633,0.583642,-137.890945,0.059223,0.000000
44.330002,25.853813,-137.935425,0.007019,0.002306,0.058564,115.003502,5.858558,0.585637,-137.935425,0.059587,0.000000
44.550003,26.056389,-137.979904,0.007032,0.002319,0.058911,115.904610,5.904462,0.589108,-137.979904,0.059951,0.000000
44.770000,26.399345,-137.935425,0.007036,0.002333,0.059266,117.430153,5.982177,0.592662,-137.935425,0.060324,0.000000
44.990002,26.798897,-137.890945,0.007054,0.002349,0.059665,119.207443,6.072717,0.596651,-137.890945,0.060689,0.000000
45.210003,27.014130,-137.935425,0.007067,0.002361,0.059977,120.164848,6.121489,0.599773,-137.935425,0.061053,0.000000
45.430000,27.387619,-137.979904,0.007067,0.002376,0.060342,121.826218,6.206123,0.603418,-137.979904,0.061417,0.000000
45.650002,28.085075,-137.979904,0.007092,0.002393,0.060793,124.928658,6.364169,0.607926,-137.979904,0.061790,0.000000
45.870003,28.300674,-137.935425,0.007097,0.002408,0.061174,125.887688,6.413025,0.611741,-137.935425,0.062154,0.000000
46.090004,28.769493,-137.935425,0.007114,0.002424,0.061582,127.973099,6.519260,0.615818,-137.935425,0.062519,0.000000
46.310001,28.846573,-137.979904,0.007118,0.002436,0.061877,128.315964,6.536726,0.618766,-137.979904,0.062891,0.000000
46.530003,29.006691,-137.979904,0.007148,0.002449,0.062215,129.028198,6.573010,0.622150,-137.979904,0.063255,0.000000
46.750004,29.538818,-138.068878,0.007157,0.002465,0.062623,131.395233,6.693592,0.626226,-138.068878,0.063620,0.000000
46.970001,29.935394,-137.979904,0.007161,0.002480,0.062987,133.159286,6.783457,0.629867,-137.979904,0.063984,0.000000
47.190002,30.089928,-137.979904,0.007183,0.002491,0.063282,133.846680,6.818475,0.632816,-137.979904,0.064357,0.000000
47.410004,30.331596,-138.024384,0.007183,0.002504,0.063603,134.921677,6.873238,0.636025,-138.024384,0.064721,0.000000
47.630001,31.202950,-138.024384,0.007196,0.002525,0.064140,138.797653,7.070689,0.641400,-138.024384,0.065085,0.000000
47.850002,31.595055,-138.068878,0.007200,0.002541,0.064539,140.541824,7.159542,0.645389,-138.068878,0.065458,0.000000
48.070004,31.831139,-138.024384,0.007226,0.002553,0.064834,141.591980,7.213039,0.648337,-138.024384,0.065822,0.000000
48.290001,32.031845,-138.068878,0.007230,0.002566,0.065181,142.484756,7.258520,0.651808,-138.068878,0.066187,0.000000
48.510002,32.686852,-138.068878,0.007239,0.002584,0.065623,145.398376,7.406947,0.656229,-138.068878,0.066551,0.000000
48.730003,32.788506,-138.113358,0.007252,0.002595,0.065909,145.850555,7.429982,0.659094,-138.113358,0.066924,0.000000
48.950001,33.371269,-138.068878,0.007269,0.002611,0.066317,148.442825,7.562037,0.663167,-138.068878,0.067288,0.000000
49.170002,33.356750,-138.113358,0.007278,0.002619,0.066525,148.378235,7.558748,0.665248,-138.113358,0.067652,0.000000
49.390003,33.849396,-138.068878,0.007286,0.002638,0.067010,150.569626,7.670382,0.670104,-138.068878,0.068025,0.000000
49.610001,35.067429,-138.068878,0.007299,0.002658,0.067522,155.987717,7.946393,0.675222,-138.068878,0.068390,0.000000
49.830002,35.262924,-138.068878,0.007304,0.002670,0.067817,156.857315,7.990693,0.678170,-138.068878,0.068754,0.000000
50.050003,35.271118,-138.113358,0.007312,0.002682,0.068129,156.893768,7.992549,0.681292,-138.113358,0.069118,0.000000
50.270004,35.954048,-138.157837,0.007347,0.002697,0.068502,159.931595,8.147304,0.685021,-138.157837,0.069491,0.000000
50.490002,36.200928,-138.113358,0.007347,0.002710,0.068823,161.029770,8.203247,0.688230,-138.113358,0.069855,0.000000
50.710003,36.801941,-138.068878,0.007373,0.002726,0.069248,163.703217,8.339438,0.692481,-138.068878,0.070219,0.000000
50.930004,37.519501,-138.113358,0.007368,0.002742,0.069656,166.895081,8.502041,0.696557,-138.113358,0.070592,0.000000
51.150002,37.171707,-138.113358,0.007373,0.002750,0.069838,165.348007,8.423229,0.698377,-138.113358,0.070957,0.000000
51.370003,37.869904,-138.157837,0.007381,0.002764,0.070202,168.453751,8.581443,0.702019,-138.157837,0.071321,0.000000
51.590004,38.598640,-138.113358,0.007403,0.002781,0.070636,171.695328,8.746576,0.706356,-138.113358,0.071685,0.000000
51.810001,39.195923,-138.157837,0.007420,0.002797,0.071052,174.352173,8.881923,0.710519,-138.157837,0.072058,0.000000
52.030003,39.933594,-138.113358,0.007420,0.002813,0.071451,177.633499,9.049082,0.714509,-138.113358,0.072422,0.000000
52.250004,40.400177,-138.202316,0.007437,0.002827,0.071798,179.708969,9.154811,0.717976,-138.202316,0.072786,0.000000
52.470001,40.827286,-138.157837,0.007450,0.002842,0.072196,181.608841,9.251595,0.721965,-138.157837,0.073159,0.000000
52.690002,41.476334,-138.113358,0.007450,0.002855,0.072517,184.495941,9.398672,0.725175,-138.113358,0.073523,0.000000
52.910004,41.626022,-138.068878,0.007468,0.002867,0.072812,185.161789,9.432591,0.728123,-138.068878,0.073888,0.000000
53.130001,42.377098,-138.157837,0.007468,0.002886,0.073298,188.502747,9.602788,0.732979,-138.157837,0.074252,0.000000
53.350002,43.214195,-138.157837,0.007480,0.002901,0.073679,192.226334,9.792477,0.736794,-138.157837,0.074625,0.000000
53.570004,43.773125,-138.202316,0.007498,0.002915,0.074044,194.712585,9.919131,0.740439,-138.202316,0.074989,0.000000
53.790001,44.360359,-138.157837,0.007515,0.002932,0.074469,197.324738,10.052201,0.744686,-138.157837,0.075353,0.000000
54.010002,44.867157,-138.202316,0.007506,0.002944,0.074781,199.579086,10.167043,0.747808,-138.202316,0.075726,0.000000
54.230003,45.317726,-138.157837,0.007524,0.002958,0.075145,201.583313,10.269143,0.751453,-138.157837,0.076090,0.000000
54.450001,46.333931,-138.246796,0.007537,0.002976,0.075596,206.103622,10.499419,0.755961,-138.246796,0.076455,0.000000
54.670002,46.738701,-138.246796,0.007545,0.002990,0.075943,207.904129,10.591141,0.759432,-138.246796,0.076819,0.000000
54.890003,47.089844,-138.202316,0.007554,0.002999,0.076168,209.466080,10.670711,0.761684,-138.202316,0.077192,0.000000
55.110004,47.131180,-138.246796,0.007549,0.003008,0.076394,209.649963,10.680078,0.763939,-138.246796,0.077556,0.000000
55.330002,48.596092,-138.157837,0.007567,0.003032,0.077010,216.166214,11.012032,0.770097,-138.157837,0.077920,0.000000
55.550003,49.481598,-138.246796,0.007584,0.003049,0.077443,220.105133,11.212690,0.774435,-138.246796,0.078293,0.000000
55.770004,49.857315,-138.291275,0.007597,0.003061,0.077747,221.776413,11.297830,0.777470,-138.291275,0.078657,0.000000
55.990002,50.318687,-138.246796,0.007606,0.003074,0.078085,223.828705,11.402377,0.780850,-138.246796,0.079022,0.000000
56.210003,51.001244,-138.246796,0.007614,0.003088,0.078423,226.864868,11.557047,0.784234,-138.246796,0.079386,0.000000
56.430004,52.104958,-138.246796,0.007606,0.003108,0.078935,231.774429,11.807152,0.789351,-138.246796,0.079759,0.000000
56.650002,52.550690,-138.291275,0.007614,0.003119,0.079230,233.757141,11.908156,0.792300,-138.291275,0.080123,0.000000
56.870003,52.821777,-138.335754,0.007631,0.003129,0.079473,234.962997,11.969585,0.794726,-138.335754,0.080487,0.000000
57.090004,54.078903,-138.246796,0.007649,0.003148,0.079958,240.554977,12.254455,0.799582,-138.246796,0.080851,0.000000
57.310001,55.245918,-138.291275,0.007662,0.003167,0.080444,245.746124,12.518904,0.804438,-138.291275,0.081225,0.000000
57.530003,55.720322,-138.291275,0.007670,0.003180,0.080782,247.856369,12.626405,0.807822,-138.291275,0.081589,0.000000
57.750004,56.168289,-138.291275,0.007679,0.003192,0.081077,249.849030,12.727916,0.810770,-138.291275,0.081953,0.000000
57.970001,57.011711,-138.335754,0.007687,0.003207,0.081467,253.600754,12.919039,0.814672,-138.335754,0.082326,0.000000
58.190002,57.678261,-138.291275,0.007705,0.003222,0.081831,256.565704,13.070081,0.818313,-138.291275,0.082690,0.000000
58.410004,58.211868,-138.291275,0.007705,0.003235,0.082161,258.939331,13.190998,0.821610,-138.291275,0.083054,0.000000
58.630001,59.396385,-138.335754,0.007713,0.003251,0.082586,264.208313,13.459413,0.825860,-138.335754,0.083418,0.000000
58.850002,59.181526,-138.380234,0.007718,0.003257,0.082733,263.252563,13.410726,0.827333,-138.380234,0.083792,0.000000
59.070004,60.541428,-138.335754,0.007722,0.003278,0.083254,269.301727,13.718884,0.832537,-138.335754,0.084156,0.000000
59.290001,61.730789,-138.335754,0.007748,0.003293,0.083653,274.592255,13.988397,0.836526,-138.335754,0.084520,0.000000
59.510002,62.267006,-138.335754,0.007735,0.003306,0.083982,276.977478,14.109905,0.839823,-138.335754,0.084893,0.000000
59.730003,63.080261,-138.335754,0.007748,0.003321,0.084346,280.595001,14.294191,0.843464,-138.335754,0.085257,0.000000
59.950005,63.733032,-138.335754,0.007761,0.003333,0.084667,283.498688,14.442111,0.846673,-138.335754,0.085621,0.000000
60.170002,64.917923,-138.424713,0.007765,0.003352,0.085136,288.769348,14.710611,0.851355,-138.424713,0.085986,0.000000
60.390003,65.680176,-138.380234,0.007778,0.003365,0.085474,292.160004,14.883341,0.854739,-138.380234,0.086358,0.000000
60.610004,66.441299,-138.424713,0.007782,0.003376,0.085760,295.545654,15.055814,0.857600,-138.424713,0.086723,0.000000
60.830002,66.823349,-138.291275,0.007782,0.003386,0.086003,297.245087,15.142387,0.860030,-138.291275,0.087087,0.000000
61.050003,67.347275,-138.424713,0.007787,0.003390,0.086107,299.575653,15.261110,0.861067,-138.424713,0.086324,0.000000
61.270004,66.649078,-138.469208,0.007808,0.003390,0.086107,296.469910,15.102897,0.861067,-138.469208,0.086324,0.000000
61.490002,65.982529,-138.424713,0.007800,0.003389,0.086072,293.504944,14.951855,0.860723,-138.424713,0.086107,0.000000
61.710003,65.395676,-138.469208,0.007812,0.003388,0.086055,290.894501,14.818871,0.860549,-138.469208,0.086107,0.000000
61.930004,64.878830,-138.424713,0.007817,0.003388,0.086046,288.595459,14.701753,0.860462,-138.424713,0.086107,0.000000
62.150002,64.391388,-138.469208,0.007804,0.003387,0.086037,286.427185,14.591296,0.860375,-138.469208,0.086107,0.000000
62.370003,63.946030,-138.513687,0.007825,0.003387,0.086029,284.446136,14.490377,0.860288,-138.513687,0.086107,0.000000
62.590004,63.525620,-138.513687,0.007821,0.003387,0.086020,282.576080,14.395111,0.860201,-138.513687,0.086107,0.000000
62.810001,63.146545,-138.469208,0.007834,0.003387,0.086020,280.889862,14.309212,0.860201,-138.469208,0.086107,0.000000
63.030003,62.792419,-138.469208,0.007834,0.003387,0.086020,279.314636,14.228966,0.860201,-138.469208,0.086107,0.000000
63.250004,62.456909,-138.469208,0.007821,0.003386,0.086011,277.822205,14.152938,0.860114,-138.469208,0.086107,0.000000
63.470001,62.135185,-138.469208,0.007830,0.003386,0.086011,276.391113,14.080034,0.860114,-138.469208,0.086107,0.000000
63.690002,61.838402,-138.469208,0.007830,0.003386,0.086011,275.070953,14.012782,0.860114,-138.469208,0.086107,0.000000
63.910004,61.565079,-138.469208,0.007834,0.003386,0.086011,273.855133,13.950847,0.860114,-138.469208,0.086107,0.000000
64.130005,61.298088,-138.469208,0.007838,0.003386,0.086011,272.667511,13.890346,0.860114,-138.469208,0.086107,0.000000
64.350006,61.051949,-138.513687,0.007847,0.003386,0.086011,271.572632,13.834569,0.860114,-138.513687,0.086107,0.000000
64.570000,60.824059,-138.469208,0.007856,0.003386,0.086011,270.558929,13.782928,0.860114,-138.469208,0.086107,0.000000
64.790001,60.595795,-138.469208,0.007851,0.003386,0.086011,269.543549,13.731203,0.860114,-138.469208,0.086107,0.000000
65.010002,60.390244,-138.513687,0.007856,0.003386,0.086011,268.629211,13.684625,0.860114,-138.513687,0.086107,0.000000
65.230003,60.186562,-138.513687,0.007856,0.003386,0.086003,267.723206,13.638470,0.860030,-138.513687,0.086107,0.000000
65.450005,59.990692,-138.513687,0.007856,0.003386,0.086003,266.851929,13.594085,0.860030,-138.513687,0.086107,0.000000
65.670006,59.817162,-138.558167,0.007838,0.003386,0.086003,266.080017,13.554763,0.860030,-138.558167,0.086107,0.000000
65.889999,59.645874,-138.647125,0.007847,0.003386,0.086003,265.318085,13.515947,0.860030,-138.647125,0.086107,0.000000
66.110001,59.467133,-138.602646,0.007851,0.003386,0.086003,264.523010,13.475445,0.860030,-138.602646,0.086107,0.000000
66.330002,59.310364,-138.513687,0.007856,0.003386,0.086003,263.825684,13.439920,0.860030,-138.513687,0.086107,0.000000
66.550003,59.152481,-138.558167,0.007856,0.003386,0.086003,263.123383,13.404143,0.860030,-138.558167,0.086107,0.000000
66.770004,59.013954,-138.558167,0.007860,0.003386,0.086003,262.507172,13.372753,0.860030,-138.558167,0.086107,0.000000
66.990005,58.878410,-138.602646,0.007856,0.003386,0.086003,261.904236,13.342038,0.860030,-138.602646,0.086107,0.000000
67.210007,58.732445,-138.558167,0.007851,0.003386,0.086003,261.254974,13.308962,0.860030,-138.558167,0.086107,0.000000
67.430000,58.609932,-138.602646,0.007860,0.003386,0.086003,260.709991,13.281200,0.860030,-138.602646,0.086107,0.000000
67.650002,58.484818,-138.558167,0.007864,0.003386,0.086003,260.153473,13.252849,0.860030,-138.558167,0.086107,0.000000
67.870003,58.357468,-138.602646,0.007860,0.003386,0.086003,259.586975,13.223991,0.860030,-138.602646,0.086107,0.000000
68.090004,58.236443,-138.647125,0.007860,0.003386,0.086003,259.048645,13.196567,0.860030,-138.647125,0.086107,0.000000
68.310005,58.115051,-138.602646,0.007864,0.003386,0.086003,258.508667,13.169059,0.860030,-138.602646,0.086107,0.000000
68.530006,58.003708,-138.558167,0.007856,0.003386,0.086003,258.013367,13.143828,0.860030,-138.558167,0.086107,0.000000
68.750000,57.891251,-138.647125,0.007860,0.003386,0.086003,257.513153,13.118345,0.860030,-138.647125,0.086107,0.000000
68.970001,57.790344,-138.647125,0.007869,0.003386,0.086003,257.064301,13.095479,0.860030,-138.647125,0.086107,0.000000
69.190002,57.692406,-138.647125,0.007873,0.003386,0.086003,256.628632,13.073286,0.860030,-138.647125,0.086107,0.000000
69.410004,57.587395,-138.647125,0.007877,0.003386,0.086003,256.161530,13.049490,0.860030,-138.647125,0.086107,0.000000
69.630005,57.504730,-138.602646,0.007864,0.003386,0.086003,255.793808,13.030759,0.860030,-138.602646,0.086107,0.000000
69.850006,57.407913,-138.647125,0.007860,0.003386,0.086003,255.363159,13.008819,0.860030,-138.647125,0.086107,0.000000
70.070000,57.319664,-138.647125,0.007860,0.003386,0.086003,254.970596,12.988822,0.860030,-138.647125,0.086107,0.000000
70.290001,57.237366,-138.691605,0.007860,0.003386,0.086003,254.604523,12.970173,0.860030,-138.691605,0.086107,0.000000
70.510002,57.149490,-138.647125,0.007881,0.003386,0.086003,254.213623,12.950259,0.860030,-138.647125,0.086107,0.000000
70.730003,57.057137,-138.736084,0.007881,0.003386,0.086003,253.802826,12.929332,0.860030,-138.736084,0.086107,0.000000
70.950005,56.970375,-138.647125,0.007873,0.003386,0.086003,253.416885,12.909672,0.860030,-138.647125,0.086107,0.000000
71.170006,56.886597,-138.736084,0.007864,0.003386,0.086003,253.044220,12.890688,0.860030,-138.736084,0.086107,0.000000
71.390007,56.824776,-138.736084,0.007873,0.003386,0.086003,252.769226,12.876678,0.860030,-138.736084,0.086107,0.000000
71.610001,56.745461,-138.691605,0.007869,0.003386,0.086003,252.416412,12.858706,0.860030,-138.691605,0.086107,0.000000
71.830002,56.680298,-138.691605,0.007877,0.003386,0.086003,252.126556,12.843939,0.860030,-138.691605,0.086107,0.000000
72.050003,56.612526,-138.647125,0.007877,0.003386,0.086003,251.825089,12.828582,0.860030,-138.647125,0.086107,0.000000
72.270004,56.527626,-138.736084,0.007873,0.003386,0.086003,251.447433,12.809343,0.860030,-138.736084,0.086107,0.000000
72.490005,56.461342,-138.780563,0.007869,0.003386,0.086003,251.152588,12.794323,0.860030,-138.780563,0.086107,0.000000
72.710007,56.390594,-138.691605,0.007886,0.003386,0.086003,250.837891,12.778292,0.860030,-138.691605,0.086107,0.000000
72.930000,56.324684,-138.736084,0.007877,0.003386,0.086003,250.544708,12.763355,0.860030,-138.736084,0.086107,0.000000
73.150002,56.260635,-138.736084,0.007877,0.003386,0.086003,250.259811,12.748842,0.860030,-138.736084,0.086107,0.000000
73.370003,56.188019,-138.780563,0.007873,0.003386,0.086003,249.936783,12.732388,0.860030,-138.780563,0.086107,0.000000
73.590004,56.135147,-138.825043,0.007890,0.003386,0.086003,249.701599,12.720407,0.860030,-138.825043,0.086107,0.000000
73.810005,56.068863,-138.780563,0.007877,0.003386,0.086003,249.406754,12.705386,0.860030,-138.780563,0.086107,0.000000
74.030006,56.018219,-138.780563,0.007869,0.003386,0.086003,249.181488,12.693911,0.860030,-138.780563,0.086107,0.000000
74.250000,55.951195,-138.736084,0.007881,0.003386,0.086003,248.883347,12.678722,0.860030,-138.736084,0.086107,0.000000
74.470001,55.900551,-138.825043,0.007869,0.003386,0.086003,248.658066,12.667246,0.860030,-138.825043,0.086107,0.000000
74.690002,55.851028,-138.825043,0.007877,0.003386,0.086003,248.437790,12.656024,0.860030,-138.825043,0.086107,0.000000
74.910004,55.788094,-138.780563,0.007877,0.003386,0.086003,248.157837,12.641763,0.860030,-138.780563,0.086107,0.000000
75.130005,55.731491,-138.780563,0.007881,0.003386,0.086003,247.906052,12.628936,0.860030,-138.780563,0.086107,0.000000
75.350006,55.683830,-138.736084,0.007881,0.003386,0.086003,247.694046,12.618136,0.860030,-138.736084,0.086107,0.000000
75.570007,55.631699,-138.914017,0.007873,0.003386,0.086003,247.462158,12.606322,0.860030,-138.914017,0.086107,0.000000
75.790001,55.576218,-138.869522,0.007899,0.003386,0.086003,247.215363,12.593751,0.860030,-138.869522,0.086107,0.000000
76.010002,55.520729,-138.825043,0.007894,0.003386,0.086003,246.968536,12.581178,0.860030,-138.825043,0.086107,0.000000
76.230003,55.471947,-138.825043,0.007886,0.003386,0.086003,246.751541,12.570123,0.860030,-138.825043,0.086107,0.000000
76.450005,55.428757,-138.869522,0.007886,0.003386,0.086003,246.559418,12.560336,0.860030,-138.869522,0.086107,0.000000
76.670006,55.376999,-138.825043,0.007881,0.003386,0.086003,246.329193,12.548608,0.860030,-138.825043,0.086107,0.000000
76.890007,55.325981,-138.869522,0.007881,0.003386,0.086003,246.102249,12.537046,0.860030,-138.869522,0.086107,0.000000
77.110001,55.281670,-138.869522,0.007894,0.003386,0.086003,245.905151,12.527005,0.860030,-138.869522,0.086107,0.000000
77.330002,55.238472,-138.869522,0.007877,0.003386,0.086003,245.712997,12.517217,0.860030,-138.869522,0.086107,0.000000
77.550003,55.193047,-138.869522,0.007890,0.003386,0.086003,245.510925,12.506923,0.860030,-138.869522,0.086107,0.000000
77.770004,55.146500,-138.914017,0.007881,0.003386,0.086003,245.303879,12.496376,0.860030,-138.914017,0.086107,0.000000
77.990005,55.107773,-138.958496,0.007890,0.003386,0.086003,245.131622,12.487599,0.860030,-138.958496,0.086107,0.000000
78.210007,55.063828,-139.002975,0.007894,0.003386,0.086003,244.936142,12.477642,0.860030,-139.002975,0.086107,0.000000
78.430000,55.031059,-138.914017,0.007886,0.003386,0.086003,244.790375,12.470217,0.860030,-138.914017,0.086107,0.000000
78.650002,54.979301,-138.914017,0.007881,0.003386,0.086003,244.560150,12.458488,0.860030,-138.914017,0.086107,0.000000
78.870003,54.940575,-138.958496,0.007881,0.003386,0.086003,244.387878,12.449712,0.860030,-138.958496,0.086107,0.000000
79.090004,54.895515,-139.002975,0.007886,0.003386,0.086003,244.187454,12.439502,0.860030,-139.002975,0.086107,0.000000
79.310005,54.851578,-138.958496,0.007881,0.003386,0.086003,243.992004,12.429545,0.860030,-138.958496,0.086107,0.000000
79.530006,54.812103,-138.958496,0.007903,0.003386,0.086003,243.816406,12.420600,0.860030,-138.958496,0.086107,0.000000
79.750000,54.767052,-138.958496,0.007890,0.003386,0.086003,243.616013,12.410392,0.860030,-138.958496,0.086107,0.000000
79.970001,54.738373,-138.958496,0.007877,0.003386,0.086003,243.488449,12.403893,0.860030,-138.958496,0.086107,0.000000
80.190002,54.692574,-138.958496,0.007890,0.003386,0.086003,243.284714,12.393515,0.860030,-138.958496,0.086107,0.000000
80.410004,54.676193,-139.002975,0.007890,0.003386,0.086003,243.211853,12.389803,0.860030,-139.002975,0.086107,0.000000
80.630005,54.630386,-138.958496,0.007881,0.003386,0.086003,243.008102,12.379422,0.860030,-138.958496,0.086107,0.000000
80.850006,54.596130,-138.958496,0.007894,0.003386,0.086003,242.855713,12.371660,0.860030,-138.958496,0.086107,0.000000
81.070007,54.542511,-139.002975,0.007873,0.003386,0.086003,242.617203,12.359509,0.860030,-139.002975,0.086107,0.000000
81.290001,54.507507,-139.002975,0.007881,0.003386,0.086003,242.461502,12.351578,0.860030,-139.002975,0.086107,0.000000
81.510002,54.474365,-139.047455,0.007894,0.003386,0.086003,242.314072,12.344068,0.860030,-139.047455,0.086107,0.000000
81.730003,54.443085,-138.958496,0.007899,0.003386,0.086003,242.174942,12.336980,0.860030,-138.958496,0.086107,0.000000
81.950005,54.408829,-138.958496,0.007881,0.003386,0.086003,242.022552,12.329217,0.860030,-138.958496,0.086107,0.000000
82.170006,54.372337,-139.002975,0.007894,0.003386,0.086003,241.860229,12.320949,0.860030,-139.002975,0.086107,0.000000
82.390007,54.337700,-139.047455,0.007881,0.003386,0.086003,241.706161,12.313099,0.860030,-139.047455,0.086107,0.000000
82.610001,54.313873,-139.047455,0.007899,0.003386,0.086003,241.600174,12.307700,0.860030,-139.047455,0.086107,0.000000
82.830002,54.284454,-139.002975,0.007899,0.003386,0.086003,241.469315,12.301033,0.860030,-139.002975,0.086107,0.000000
83.050003,54.243866,-139.047455,0.007886,0.003386,0.086003,241.288773,12.291836,0.860030,-139.047455,0.086107,0.000000
83.270004,54.208488,-139.002975,0.007899,0.003386,0.086003,241.131393,12.283819,0.860030,-139.002975,0.086107,0.000000
83.490005,54.179443,-139.047455,0.007894,0.003386,0.086003,241.002197,12.277238,0.860030,-139.047455,0.086107,0.000000
83.710007,54.151894,-139.047455,0.007899,0.003386,0.086003,240.879654,12.270994,0.860030,-139.047455,0.086107,0.000000
83.930000,54.114655,-139.091934,0.007894,0.003386,0.086003,240.714005,12.262556,0.860030,-139.091934,0.086107,0.000000
84.150002,54.088959,-139.091934,0.007890,0.003386,0.086003,240.599701,12.256733,0.860030,-139.091934,0.086107,0.000000
84.370003,54.040924,-139.047455,0.007899,0.003386,0.086003,240.386032,12.245849,0.860030,-139.047455,0.086107,0.000000
84.590004,54.020813,-139.091934,0.007894,0.003386,0.086003,240.296585,12.241292,0.860030,-139.091934,0.086107,0.000000
84.810005,53.995491,-139.091934,0.007894,0.003386,0.086003,240.183945,12.235553,0.860030,-139.091934,0.086107,0.000000
85.030006,53.966080,-139.047455,0.007903,0.003386,0.086003,240.053116,12.228889,0.860030,-139.047455,0.086107,0.000000
85.250008,53.928841,-139.091934,0.007894,0.003386,0.086003,239.887466,12.220450,0.860030,-139.091934,0.086107,0.000000
85.470001,53.910217,-139.136414,0.007899,0.003386,0.086003,239.804626,12.216229,0.860030,-139.136414,0.086107,0.000000
85.690002,53.878944,-139.136414,0.007890,0.003386,0.086003,239.665512,12.209143,0.860030,-139.136414,0.086107,0.000000
85.910004,53.856224,-139.091934,0.007903,0.003386,0.086003,239.564453,12.203995,0.860030,-139.091934,0.086107,0.000000
86.130005,53.827553,-139.180893,0.007890,0.003386,0.086003,239.436920,12.197498,0.860030,-139.180893,0.086107,0.000000
86.350006,53.792175,-139.091934,0.007890,0.003386,0.086003,239.279541,12.189481,0.860030,-139.091934,0.086107,0.000000
86.570007,53.771698,-139.136414,0.007890,0.003386,0.086003,239.188461,12.184841,0.860030,-139.136414,0.086107,0.000000
86.790001,53.728874,-139.180893,0.007903,0.003386,0.086003,238.997971,12.175138,0.860030,-139.180893,0.086107,0.000000
87.010002,53.718819,-139.136414,0.007894,0.003386,0.086003,238.953247,12.172858,0.860030,-139.136414,0.086107,0.000000
87.230003,53.676743,-139.136414,0.007903,0.003386,0.086003,238.766083,12.163323,0.860030,-139.136414,0.086107,0.000000
87.450005,53.650673,-139.136414,0.007899,0.003386,0.086003,238.650116,12.157416,0.860030,-139.136414,0.086107,0.000000
87.670006,53.622002,-139.136414,0.007894,0.003386,0.086003,238.522583,12.150920,0.860030,-139.136414,0.086107,0.000000
87.890007,53.594078,-139.180893,0.007899,0.003386,0.086003,238.398361,12.144592,0.860030,-139.180893,0.086107,0.000000
88.110001,53.570244,-139.180893,0.007890,0.003386,0.086003,238.292343,12.139191,0.860030,-139.180893,0.086107,0.000000
88.330002,53.545296,-139.225372,0.007912,0.003386,0.086003,238.181366,12.133537,0.860030,-139.225372,0.086107,0.000000
88.550003,53.515137,-139.225372,0.007894,0.003386,0.086003,238.047211,12.126703,0.860030,-139.225372,0.086107,0.000000
88.770004,53.488693,-139.225372,0.007899,0.003386,0.086003,237.929596,12.120711,0.860030,-139.225372,0.086107,0.000000
88.990005,53.470078,-139.225372,0.007903,0.003386,0.086003,237.846786,12.116492,0.860030,-139.225372,0.086107,0.000000
89.210007,53.444756,-139.225372,0.007907,0.003386,0.086003,237.734146,12.110755,0.860030,-139.225372,0.086107,0.000000
89.430008,53.418686,-139.225372,0.007907,0.003386,0.086003,237.618179,12.104848,0.860030,-139.225372,0.086107,0.000000
89.650002,53.391136,-139.225372,0.007894,0.003386,0.086003,237.495636,12.098604,0.860030,-139.225372,0.086107,0.000000
89.870003,53.368790,-139.225372,0.007899,0.003386,0.086003,237.396240,12.093540,0.860030,-139.225372,0.086107,0.000000
90.090004,53.349052,-139.269852,0.007886,0.003386,0.086003,237.308441,12.089068,0.860030,-139.269852,0.086107,0.000000
90.310005,53.328949,-139.269852,0.007899,0.003386,0.086003,237.219009,12.084513,0.860030,-139.269852,0.086107,0.000000
90.530006,53.302505,-139.225372,0.007894,0.003386,0.086003,237.101379,12.078520,0.860030,-139.225372,0.086107,0.000000
90.750008,53.273834,-139.225372,0.007894,0.003386,0.086003,236.973846,12.072023,0.860030,-139.225372,0.086107,0.000000
90.970001,53.255959,-139.269852,0.007903,0.003386,0.086003,236.894333,12.067973,0.860030,-139.269852,0.086107,0.000000
91.190002,53.234734,-139.269852,0.007894,0.003386,0.086003,236.799927,12.063163,0.860030,-139.269852,0.086107,0.000000
91.400002,53.217606,-139.314346,0.007899,0.003386,0.086003,236.723740,12.059282,0.860030,-139.314346,0.086107,0.000000