File: Data/compression 4 4 days/AutoNoheating-17-4-3-240226_02262024_164351.csv
Time (sec),S:Load (lbs),S:HL1 (DIM),S:LVDT (in),S:Position (in),Ch:Position (mm),Ch:Load (N),Ch:Stress (MPa),Ch:Strain (mm/mm),Ch:HL1 (DIM),Set Point (),Cycles ()
0.110000,0.007820,-141.049103,0.000004,-0.000000,-0.000000,0.034786,0.001772,-0.000000,-141.049103,0.000147,0.000000
0.330000,0.005211,-141.049103,0.000022,-0.000000,-0.000000,0.023179,0.001181,-0.000000,-141.049103,0.000147,0.000000
0.550000,-0.010796,-140.960129,0.000004,0.000077,0.001960,-0.048021,-0.002446,0.019598,-140.960129,0.002541,0.000000
0.770000,0.003723,-141.049103,0.000099,0.000208,0.005273,0.016561,0.000844,0.052727,-141.049103,0.006218,0.000000
0.990000,0.016014,-141.093582,0.000207,0.000342,0.008681,0.071234,0.003629,0.086810,-141.093582,0.009878,0.000000
1.210000,0.039474,-141.138062,0.000354,0.000486,0.012341,0.175591,0.008945,0.123406,-141.138062,0.013537,0.000000
1.430000,0.035744,-141.049103,0.000517,0.000637,0.016182,0.158996,0.008100,0.161823,-141.049103,0.017214,0.000000
1.650000,0.010429,-141.004608,0.000655,0.000781,0.019842,0.046392,0.002363,0.198419,-141.004608,0.020874,0.000000
1.870000,-0.027184,-141.049103,0.000819,0.000923,0.023450,-0.120918,-0.006160,0.234497,-141.049103,0.024534,0.000000
2.090000,-0.002983,-141.093582,0.000957,0.001063,0.026988,-0.013269,-0.000676,0.269882,-141.093582,0.028193,0.000000
2.310000,-0.005211,-141.138062,0.001095,0.001215,0.030865,-0.023179,-0.001181,0.308647,-141.138062,0.031870,0.000000
2.530000,-0.008934,-141.093582,0.001250,0.001361,0.034559,-0.039741,-0.002024,0.345587,-141.093582,0.035530,0.000000
2.750000,-0.000000,-141.138062,0.001393,0.001501,0.038132,-0.000000,-0.000000,0.381317,-141.138062,0.039190,0.000000
2.970000,0.013031,-141.093582,0.001535,0.001642,0.041705,0.057965,0.002953,0.417050,-141.093582,0.042867,0.000000
3.190000,0.028297,-141.182541,0.001681,0.001791,0.045486,0.125873,0.006412,0.454861,-141.182541,0.046527,0.000000
3.410000,-0.018616,-141.138062,0.001824,0.001936,0.049171,-0.082807,-0.004218,0.491715,-141.138062,0.050186,0.000000
3.630000,-0.006706,-141.093582,0.001975,0.002078,0.052788,-0.029831,-0.001520,0.527879,-141.093582,0.053863,0.000000
3.850000,0.013031,-141.093582,0.002117,0.002222,0.056430,0.057965,0.002953,0.564301,-141.093582,0.057523,0.000000
4.070000,0.016014,-141.138062,0.002259,0.002367,0.060116,0.071234,0.003629,0.601159,-141.138062,0.061183,0.000000
4.290000,0.015640,-141.182541,0.002410,0.002512,0.063793,0.069571,0.003544,0.637929,-141.182541,0.064860,0.000000
4.510000,0.008194,-141.182541,0.002561,0.002653,0.067383,0.036449,0.001857,0.673832,-141.182541,0.068519,0.000000
4.730000,-0.002983,-141.138062,0.002703,0.002803,0.071199,-0.013269,-0.000676,0.711992,-141.138062,0.072179,0.000000
4.950000,-0.001114,-141.138062,0.002854,0.002947,0.074850,-0.004955,-0.000252,0.748501,-141.138062,0.075856,0.000000
5.170000,0.003349,-141.138062,0.003001,0.003083,0.078311,0.014898,0.000759,0.783106,-141.138062,0.079516,0.000000
5.390000,0.003349,-141.182541,0.003126,0.003229,0.082022,0.014898,0.000759,0.820221,-141.182541,0.083176,0.000000
5.610000,0.004837,-141.182541,0.003294,0.003379,0.085829,0.021516,0.001096,0.858293,-141.182541,0.086835,0.000000
5.830000,0.010796,-141.227020,0.003449,0.003525,0.089524,0.048021,0.002446,0.895237,-141.227020,0.090512,0.000000
6.050000,0.031654,-141.182541,0.003583,0.003662,0.093010,0.140806,0.007173,0.930100,-141.182541,0.094172,0.000000
6.270000,0.015640,-141.182541,0.003729,0.003811,0.096791,0.069571,0.003544,0.967911,-141.182541,0.097832,0.000000
6.490000,-0.002609,-141.271500,0.003863,0.003956,0.100477,-0.011607,-0.000591,1.004768,-141.271500,0.101509,0.000000
6.710001,-0.039474,-141.315979,0.004014,0.004098,0.104102,-0.175591,-0.008945,1.041016,-141.315979,0.105168,0.000000
6.930000,-0.040962,-141.227020,0.004156,0.004238,0.107649,-0.182209,-0.009282,1.076488,-141.227020,0.108828,0.000000
7.150001,-0.003723,-141.227020,0.004303,0.004386,0.111395,-0.016561,-0.000844,1.113951,-141.227020,0.112505,0.000000
7.370000,0.024948,-141.271500,0.004432,0.004527,0.114994,0.110975,0.005653,1.149942,-141.271500,0.116165,0.000000
7.590000,0.038727,-141.227020,0.004587,0.004673,0.118689,0.172265,0.008776,1.186886,-141.227020,0.119824,0.000000
7.810000,0.037979,-141.271500,0.004747,0.004820,0.122435,0.168940,0.008606,1.224349,-141.271500,0.123502,0.000000
8.030001,0.032394,-141.227020,0.004881,0.004967,0.126155,0.144098,0.007341,1.261551,-141.227020,0.127161,0.000000
8.250000,0.020477,-141.227020,0.005023,0.005109,0.129763,0.091088,0.004640,1.297629,-141.227020,0.130821,0.000000
8.470000,0.007072,-141.227020,0.005161,0.005250,0.133362,0.031460,0.001603,1.333619,-141.227020,0.134498,0.000000
8.690001,-0.010796,-141.360458,0.005295,0.005393,0.136970,-0.048021,-0.002446,1.369697,-141.360458,0.138158,0.000000
8.910001,0.016380,-141.271500,0.005445,0.005539,0.140699,0.072863,0.003712,1.406986,-141.271500,0.141817,0.000000
9.130000,0.034256,-141.315979,0.005605,0.005688,0.144471,0.152378,0.007763,1.444710,-141.315979,0.145494,0.000000
9.350000,0.252838,-141.227020,0.005743,0.005826,0.147983,1.124680,0.057294,1.479833,-141.227020,0.149154,0.000000
9.570001,0.762245,-141.315979,0.005812,-0.000002,-0.000052,3.390636,0.172727,-0.000519,-141.315979,0.000148,0.000000
9.790001,0.696709,-141.360458,0.005825,-0.000002,-0.000061,3.099115,0.157876,-0.000606,-141.360458,0.000148,0.000000
10.010000,0.634148,-141.315979,0.005812,-0.000002,-0.000061,2.820830,0.143700,-0.000606,-141.315979,0.000191,0.000000
10.230000,0.665428,-141.271500,0.005816,-0.000002,-0.000061,2.959972,0.150788,-0.000606,-141.271500,0.000555,0.000000
10.450001,0.657234,-141.271500,0.005825,-0.000002,-0.000061,2.923524,0.148931,-0.000606,-141.271500,0.000919,0.000000
10.670000,0.634521,-141.315979,0.005803,-0.000002,-0.000061,2.822493,0.143785,-0.000606,-141.315979,0.001283,0.000000
10.890000,1.032959,-141.360458,0.005829,0.000029,0.000737,4.594831,0.234072,0.007373,-141.360458,0.001657,0.000000
11.110001,1.142441,-141.404938,0.005829,0.000040,0.001023,5.081831,0.258881,0.010234,-141.404938,0.002021,0.000000
11.330001,1.379265,-141.360458,0.005855,0.000057,0.001440,6.135276,0.312546,0.014398,-141.360458,0.002385,0.000000
11.550000,1.562843,-141.360458,0.005872,0.000071,0.001813,6.951874,0.354145,0.018126,-141.360458,0.002758,0.000000
11.770000,1.866333,-141.360458,0.005890,0.000090,0.002281,8.301864,0.422917,0.022808,-141.360458,0.003122,0.000000
11.990001,2.001129,-141.360458,0.005894,0.000103,0.002619,8.901467,0.453462,0.026191,-141.360458,0.003486,0.000000
12.210001,2.223434,-141.404938,0.005915,0.000115,0.002931,9.890330,0.503837,0.029314,-141.404938,0.003851,0.000000
12.430000,2.519470,-141.315979,0.005928,0.000130,0.003296,11.207163,0.570920,0.032955,-141.315979,0.004224,0.000000
12.650001,2.812157,-141.360458,0.005937,0.000147,0.003729,12.509098,0.637244,0.037293,-141.360458,0.004588,0.000000
12.870001,2.978233,-141.360458,0.005946,0.000160,0.004067,13.247844,0.674877,0.040672,-141.360458,0.004952,0.000000
13.090000,3.204262,-141.493912,0.005959,0.000171,0.004345,14.253268,0.726096,0.043451,-141.493912,0.005325,0.000000
13.310000,3.610519,-141.360458,0.005980,0.000191,0.004856,16.060392,0.818155,0.048564,-141.360458,0.005689,0.000000
13.530001,3.882355,-141.360458,0.005984,0.000208,0.005290,17.269577,0.879754,0.052901,-141.360458,0.006053,0.000000
13.750001,4.108757,-141.404938,0.006006,0.000222,0.005629,18.276665,0.931058,0.056285,-141.404938,0.006418,0.000000
13.970000,4.273346,-141.404938,0.005993,0.000234,0.005941,19.008793,0.968354,0.059408,-141.404938,0.006790,0.000000
14.190001,4.459534,-141.449417,0.006015,0.000245,0.006218,19.836996,1.010545,0.062182,-141.449417,0.007155,0.000000
14.410001,4.644226,-141.493912,0.006036,0.000258,0.006547,20.658550,1.052397,0.065475,-141.493912,0.007519,0.000000
14.630001,5.094429,-141.449417,0.006053,0.000278,0.007059,22.661152,1.154414,0.070592,-141.449417,0.007892,0.000000
14.850000,5.344658,-141.404938,0.006066,0.000294,0.007458,23.774225,1.211117,0.074581,-141.404938,0.008256,0.000000
15.070001,5.484299,-141.449417,0.006075,0.000305,0.007736,24.395378,1.242760,0.077359,-141.449417,0.008620,0.000000
15.290001,5.806030,-141.493912,0.006092,0.000323,0.008204,25.826513,1.315665,0.082041,-141.493912,0.008985,0.000000
15.510001,6.039505,-141.493912,0.006118,0.000337,0.008551,26.865061,1.368571,0.085508,-141.493912,0.009357,0.000000
15.730000,6.176910,-141.493912,0.006109,0.000349,0.008863,27.476271,1.399708,0.088631,-141.493912,0.009722,0.000000
15.950001,6.358261,-141.449417,0.006122,0.000364,0.009245,28.282957,1.440803,0.092446,-141.449417,0.010086,0.000000
16.170000,6.636047,-141.538391,0.006140,0.000378,0.009609,29.518614,1.503750,0.096091,-141.538391,0.010459,0.000000
16.390001,6.838249,-141.538391,0.006161,0.000393,0.009973,30.418051,1.549569,0.099732,-141.538391,0.010823,0.000000
16.610001,7.052734,-141.538391,0.006165,0.000408,0.010372,31.372129,1.598172,0.103721,-141.538391,0.011187,0.000000
16.830000,7.202431,-141.538391,0.006187,0.000421,0.010693,32.038013,1.632094,0.106931,-141.538391,0.011551,0.000000
17.050001,7.187531,-141.538391,0.006183,0.000429,0.010901,31.971733,1.628718,0.109013,-141.538391,0.011924,0.000000
17.270000,7.533096,-141.582870,0.006191,0.000449,0.011396,33.508884,1.707024,0.113956,-141.582870,0.012289,0.000000
17.490002,7.739388,-141.582870,0.006222,0.000465,0.011803,34.426514,1.753770,0.118032,-141.582870,0.012653,0.000000
17.710001,7.864136,-141.538391,0.006243,0.000479,0.012159,34.981422,1.782039,0.121586,-141.538391,0.013017,0.000000
17.930000,8.000420,-141.493912,0.006260,0.000493,0.012523,35.587643,1.812921,0.125227,-141.493912,0.013390,0.000000
18.150002,8.073410,-141.538391,0.006269,0.000504,0.012809,35.912323,1.829461,0.128092,-141.538391,0.013754,0.000000
18.370001,8.332207,-141.493912,0.006260,0.000521,0.013243,37.063507,1.888105,0.132426,-141.493912,0.014118,0.000000
18.590000,8.496796,-141.582870,0.006291,0.000538,0.013668,37.795635,1.925401,0.136676,-141.582870,0.014492,0.000000
18.810001,8.543716,-141.582870,0.006308,0.000549,0.013936,38.004349,1.936034,0.139364,-141.582870,0.014856,0.000000
19.030001,8.499397,-141.538391,0.006321,0.000558,0.014171,37.807209,1.925991,0.141706,-141.538391,0.015220,0.000000
19.250000,8.786873,-141.538391,0.006321,0.000577,0.014656,39.085964,1.991134,0.146562,-141.538391,0.015584,0.000000
19.470001,9.064293,-141.538391,0.006351,0.000596,0.015151,40.319988,2.053998,0.151506,-141.538391,0.015957,0.000000
19.690001,9.073975,-141.627350,0.006347,0.000609,0.015463,40.363056,2.056192,0.154628,-141.627350,0.016321,0.000000
19.910002,9.093338,-141.538391,0.006372,0.000621,0.015784,40.449188,2.060580,0.157838,-141.538391,0.016686,0.000000
20.130001,9.121262,-141.538391,0.006394,0.000633,0.016087,40.573399,2.066907,0.160873,-141.538391,0.017059,0.000000
20.350000,9.409851,-141.582870,0.006398,0.000652,0.016564,41.857109,2.132303,0.165642,-141.582870,0.017423,0.000000
20.570002,9.470924,-141.627350,0.006403,0.000666,0.016911,42.128777,2.146142,0.169109,-141.627350,0.017787,0.000000
20.790001,9.361816,-141.627350,0.006416,0.000673,0.017085,41.643440,2.121418,0.170846,-141.627350,0.018151,0.000000
21.010000,9.742004,-141.627350,0.006433,0.000693,0.017605,43.334599,2.207570,0.176047,-141.627350,0.018524,0.000000
21.230001,9.966545,-141.671829,0.006467,0.000713,0.018099,44.333408,2.258451,0.180990,-141.671829,0.018888,0.000000
21.450001,9.963943,-141.627350,0.006463,0.000725,0.018420,44.321835,2.257862,0.184199,-141.627350,0.019253,0.000000
21.670000,9.987030,-141.671829,0.006480,0.000739,0.018776,44.424530,2.263093,0.187757,-141.671829,0.019625,0.000000
21.890001,9.949417,-141.671829,0.006497,0.000749,0.019036,44.257217,2.254570,0.190358,-141.671829,0.019990,0.000000
22.110001,10.048096,-141.671829,0.006510,0.000765,0.019426,44.696163,2.276931,0.194260,-141.671829,0.020354,0.000000
22.330002,10.291260,-141.671829,0.006515,0.000781,0.019825,45.777809,2.332033,0.198249,-141.671829,0.020718,0.000000
22.550001,10.395523,-141.716309,0.006536,0.000797,0.020241,46.241596,2.355659,0.202412,-141.716309,0.021091,0.000000
22.770000,10.395149,-141.671829,0.006549,0.000807,0.020493,46.239933,2.355575,0.204926,-141.671829,0.021455,0.000000
22.990002,10.568672,-141.716309,0.006558,0.000825,0.020952,47.011803,2.394895,0.209524,-141.716309,0.021820,0.000000
23.210001,10.657669,-141.716309,0.006584,0.000839,0.021317,47.407681,2.415062,0.213165,-141.716309,0.022192,0.000000
23.430000,10.712036,-141.671829,0.006610,0.000853,0.021672,47.649517,2.427382,0.216719,-141.671829,0.022557,0.000000
23.650002,10.808853,-141.671829,0.006610,0.000869,0.022062,48.080181,2.449321,0.220622,-141.671829,0.022921,0.000000
23.870001,10.774971,-141.671829,0.006627,0.000880,0.022357,47.929466,2.441643,0.223574,-141.671829,0.023285,0.000000
24.090002,10.832314,-141.716309,0.006631,0.000892,0.022661,48.184536,2.454637,0.226605,-141.716309,0.023658,0.000000
24.310001,11.123138,-141.716309,0.006648,0.000910,0.023112,49.478191,2.520539,0.231117,-141.716309,0.024022,0.000000
24.530001,11.163727,-141.716309,0.006674,0.000924,0.023458,49.658737,2.529737,0.234584,-141.716309,0.024386,0.000000
24.750002,11.034515,-141.760788,0.006674,0.000931,0.023658,49.083977,2.500457,0.236579,-141.760788,0.024759,0.000000
24.970001,11.412842,-141.760788,0.006696,0.000955,0.024265,50.766857,2.586187,0.242650,-141.760788,0.025124,0.000000
25.190001,11.577057,-141.805267,0.006704,0.000970,0.024647,51.497322,2.623399,0.246469,-141.805267,0.025488,0.000000
25.410002,11.504448,-141.805267,0.006735,0.000981,0.024924,51.174339,2.606945,0.249243,-141.805267,0.025852,0.000000
25.630001,11.466095,-141.716309,0.006735,0.000995,0.025280,51.003738,2.598254,0.252797,-141.716309,0.026225,0.000000
25.850000,11.592697,-141.716309,0.006735,0.001008,0.025601,51.566891,2.626943,0.256007,-141.716309,0.026589,0.000000
26.070002,11.657120,-141.760788,0.006760,0.001023,0.025982,51.853458,2.641541,0.259822,-141.760788,0.026953,0.000000
26.290001,12.115509,-141.805267,0.006769,0.001043,0.026485,53.892475,2.745414,0.264852,-141.805267,0.027327,0.000000
26.510002,12.159447,-141.805267,0.006791,0.001056,0.026832,54.087921,2.755370,0.268323,-141.805267,0.027691,0.000000
26.730001,12.114769,-141.760788,0.006808,0.001069,0.027153,53.889183,2.745246,0.271528,-141.760788,0.028055,0.000000
26.950001,12.245468,-141.760788,0.006821,0.001086,0.027578,54.470562,2.774863,0.275779,-141.760788,0.028419,0.000000
27.170002,12.438728,-141.805267,0.006842,0.001102,0.027986,55.330227,2.818656,0.279855,-141.805267,0.028792,0.000000
27.390001,12.447296,-141.805267,0.006842,0.001115,0.028315,55.368340,2.820598,0.283152,-141.805267,0.029156,0.000000
27.610001,12.397026,-141.805267,0.006864,0.001126,0.028610,55.144726,2.809206,0.286100,-141.805267,0.029521,0.000000
27.830002,12.347496,-141.849747,0.006860,0.001138,0.028896,54.924404,2.797983,0.288962,-141.849747,0.029893,0.000000
28.050001,12.690453,-141.849747,0.006881,0.001155,0.029347,56.449951,2.875698,0.293469,-141.849747,0.030258,0.000000
28.270000,12.906799,-141.805267,0.006903,0.001173,0.029789,57.412312,2.924722,0.297894,-141.805267,0.030622,0.000000
28.490002,12.937706,-141.894241,0.006907,0.001184,0.030084,57.549789,2.931726,0.300842,-141.894241,0.030986,0.000000
28.710001,12.902702,-141.849747,0.006942,0.001196,0.030379,57.394085,2.923794,0.303791,-141.849747,0.031359,0.000000
28.930002,13.254227,-141.894241,0.006946,0.001217,0.030900,58.957745,3.003451,0.308995,-141.894241,0.031723,0.000000
29.150002,13.401688,-141.849747,0.006963,0.001232,0.031298,59.613686,3.036866,0.312984,-141.849747,0.032088,0.000000
29.370001,13.247147,-141.894241,0.006959,0.001241,0.031524,58.926250,3.001846,0.315236,-141.894241,0.032460,0.000000
29.590002,13.333168,-141.894241,0.006963,0.001255,0.031888,59.308895,3.021339,0.318881,-141.894241,0.032825,0.000000
29.810001,13.445999,-141.894241,0.006985,0.001271,0.032287,59.810791,3.046907,0.322870,-141.894241,0.033189,0.000000
30.030001,13.625107,-141.849747,0.007002,0.001284,0.032625,60.607502,3.087493,0.326250,-141.849747,0.033553,0.000000
30.250002,13.911087,-141.894241,0.007023,0.001303,0.033094,61.879604,3.152297,0.330936,-141.894241,0.033926,0.000000
30.470001,13.764374,-141.894241,0.007032,0.001311,0.033301,61.226994,3.119052,0.333014,-141.894241,0.034290,0.000000
30.690001,13.935669,-141.938721,0.007041,0.001326,0.033683,61.988953,3.157868,0.336833,-141.938721,0.034654,0.000000
30.910002,14.206757,-141.938721,0.007058,0.001343,0.034117,63.194809,3.219297,0.341167,-141.938721,0.035019,0.000000
31.130001,14.300591,-141.938721,0.007084,0.001358,0.034481,63.612206,3.240560,0.344811,-141.938721,0.035391,0.000000
31.350002,14.227982,-141.894241,0.007097,0.001367,0.034715,63.289223,3.224107,0.347151,-141.894241,0.035756,0.000000
31.570002,14.391075,-141.938721,0.007097,0.001382,0.035105,64.014702,3.261064,0.351053,-141.938721,0.036120,0.000000
31.790001,14.488640,-141.983200,0.007114,0.001397,0.035496,64.448692,3.283173,0.354955,-141.983200,0.036493,0.000000
32.010002,14.655090,-141.983200,0.007127,0.001410,0.035825,65.189095,3.320891,0.358252,-141.983200,0.036857,0.000000
32.230003,14.776855,-141.938721,0.007161,0.001424,0.036172,65.730736,3.348483,0.361722,-141.938721,0.037221,0.000000
32.450001,15.059860,-142.027679,0.007140,0.001440,0.036588,66.989601,3.412613,0.365882,-142.027679,0.037586,0.000000
32.670002,15.105659,-141.938721,0.007157,0.001454,0.036927,67.193329,3.422992,0.369266,-141.938721,0.037959,0.000000
32.890003,15.186096,-141.983200,0.007183,0.001470,0.037325,67.551132,3.441219,0.373255,-141.983200,0.038323,0.000000
33.110001,15.616180,-142.027679,0.007209,0.001488,0.037794,69.464241,3.538677,0.377937,-142.027679,0.038687,0.000000
33.330002,15.523094,-141.983200,0.007222,0.001502,0.038158,69.050171,3.517583,0.381582,-141.983200,0.039060,0.000000
33.550003,15.636292,-141.983200,0.007226,0.001516,0.038496,69.553696,3.543234,0.384962,-141.983200,0.039424,0.000000
33.770000,15.794922,-141.983200,0.007226,0.001530,0.038861,70.259323,3.579180,0.388607,-141.983200,0.039788,0.000000
33.990002,16.057442,-141.983200,0.007256,0.001546,0.039277,71.427071,3.638668,0.392766,-141.983200,0.040153,0.000000
34.210003,16.093567,-141.983200,0.007274,0.001560,0.039615,71.587761,3.646854,0.396150,-141.983200,0.040526,0.000000
34.430000,16.050743,-142.027679,0.007278,0.001570,0.039884,71.397270,3.637151,0.398837,-142.027679,0.040890,0.000000
34.650002,16.493492,-141.983200,0.007291,0.001590,0.040387,73.366714,3.737479,0.403867,-141.983200,0.041254,0.000000
34.870003,16.709839,-141.983200,0.007325,0.001607,0.040812,74.329079,3.786504,0.408118,-141.983200,0.041627,0.000000
35.090000,16.803307,-141.983200,0.007321,0.001621,0.041167,74.744843,3.807684,0.411672,-141.983200,0.041991,0.000000
35.310001,16.767563,-142.027679,0.007347,0.001633,0.041471,74.585846,3.799584,0.414707,-142.027679,0.042355,0.000000
35.530003,16.722878,-142.072159,0.007355,0.001644,0.041766,74.387077,3.789458,0.417656,-142.072159,0.042720,0.000000
35.750000,17.008484,-142.072159,0.007360,0.001662,0.042217,75.657516,3.854178,0.422167,-142.072159,0.043093,0.000000
35.970001,17.290367,-142.072159,0.007386,0.001677,0.042590,76.911392,3.918053,0.425895,-142.072159,0.043457,0.000000
36.190002,17.464638,-142.072159,0.007394,0.001693,0.042997,77.686592,3.957544,0.429972,-142.072159,0.043821,0.000000
36.410000,17.532410,-142.161118,0.007407,0.001708,0.043379,77.988052,3.972901,0.433787,-142.161118,0.044194,0.000000
36.630001,17.821747,-142.072159,0.007420,0.001724,0.043778,79.275085,4.038465,0.437776,-142.072159,0.044558,0.000000
36.850002,17.945374,-142.072159,0.007437,0.001738,0.044142,79.825005,4.066480,0.441417,-142.072159,0.044923,0.000000
37.070004,17.880211,-142.072159,0.007455,0.001748,0.044393,79.535149,4.051714,0.443934,-142.072159,0.045287,0.000000
37.290001,18.087250,-142.116638,0.007463,0.001764,0.044801,80.456108,4.098629,0.448010,-142.116638,0.045659,0.000000
37.510002,18.289818,-142.161118,0.007468,0.001779,0.045191,81.357170,4.144532,0.451913,-142.161118,0.046024,0.000000
37.730003,18.401154,-142.161118,0.007493,0.001792,0.045512,81.852417,4.169761,0.455122,-142.161118,0.046388,0.000000
37.950001,18.726608,-142.116638,0.007502,0.001811,0.045989,83.300117,4.243510,0.459891,-142.116638,0.046761,0.000000
38.170002,18.706131,-142.072159,0.007524,0.001819,0.046215,83.209030,4.238870,0.462147,-142.072159,0.047125,0.000000
38.390003,18.538193,-142.116638,0.007524,0.001829,0.046449,82.461998,4.200815,0.464486,-142.116638,0.047489,0.000000
38.610001,19.242348,-142.161118,0.007537,0.001851,0.047013,85.594238,4.360378,0.470126,-142.161118,0.047854,0.000000
38.830002,19.442680,-142.205597,0.007554,0.001865,0.047377,86.485359,4.405775,0.473767,-142.205597,0.048226,0.000000
39.050003,19.517159,-142.161118,0.007571,0.001879,0.047723,86.816658,4.422651,0.477234,-142.161118,0.048591,0.000000
39.270000,19.688080,-142.116638,0.007580,0.001892,0.048053,87.576950,4.461383,0.480530,-142.116638,0.048955,0.000000
39.490002,19.635574,-142.205597,0.007588,0.001903,0.048348,87.343399,4.449485,0.483479,-142.205597,0.049328,0.000000
39.710003,20.097687,-142.205597,0.007601,0.001922,0.048816,89.398979,4.554201,0.488164,-142.205597,0.049692,0.000000
39.930000,20.459633,-142.161118,0.007618,0.001938,0.049215,91.008995,4.636219,0.492150,-142.161118,0.050056,0.000000
40.150002,20.375107,-142.205597,0.007627,0.001947,0.049458,90.633003,4.617065,0.494580,-142.205597,0.050420,0.000000
40.370003,20.452927,-142.161118,0.007644,0.001963,0.049848,90.979164,4.634699,0.498482,-142.161118,0.050794,0.000000
40.590000,20.813385,-142.205597,0.007649,0.001977,0.050212,92.582558,4.716381,0.502123,-142.205597,0.051158,0.000000
40.810001,21.335083,-142.250076,0.007666,0.001996,0.050698,94.903191,4.834599,0.506983,-142.250076,0.051522,0.000000
41.030003,21.415512,-142.250076,0.007679,0.002009,0.051036,95.260956,4.852825,0.510363,-142.250076,0.051895,0.000000
41.250004,21.435249,-142.205597,0.007692,0.002021,0.051331,95.348755,4.857297,0.513311,-142.205597,0.052259,0.000000
41.470001,21.456848,-142.205597,0.007718,0.002032,0.051617,95.444824,4.862191,0.516173,-142.205597,0.052623,0.000000
41.690002,21.952103,-142.205597,0.007713,0.002051,0.052086,97.647827,4.974418,0.520858,-142.205597,0.052988,0.000000
41.910004,22.280907,-142.250076,0.007722,0.002066,0.052467,99.110420,5.048925,0.524674,-142.250076,0.053361,0.000000
42.130001,21.981148,-142.294556,0.007748,0.002071,0.052615,97.777031,4.980999,0.526146,-142.294556,0.053725,0.000000
42.350002,22.715836,-142.250076,0.007765,0.002094,0.053179,101.045082,5.147482,0.531785,-142.250076,0.054089,0.000000
42.570004,23.121353,-142.205597,0.007774,0.002110,0.053594,102.848915,5.239373,0.535945,-142.205597,0.054462,0.000000
42.790001,23.272903,-142.250076,0.007791,0.002124,0.053942,103.523048,5.273715,0.539416,-142.250076,0.054826,0.000000
43.010002,23.473984,-142.205597,0.007804,0.002139,0.054323,104.417496,5.319281,0.543231,-142.205597,0.055190,0.000000
43.230003,23.333229,-142.294556,0.007812,0.002148,0.054566,103.791389,5.287385,0.545661,-142.294556,0.055555,0.000000
43.450001,23.603569,-142.250076,0.007821,0.002164,0.054956,104.993919,5.348645,0.549563,-142.250076,0.055928,0.000000
43.670002,24.127502,-142.250076,0.007843,0.002180,0.055364,107.324493,5.467371,0.553639,-142.250076,0.056292,0.000000
43.890003,24.444763,-142.294556,0.007851,0.002196,0.055780,108.735741,5.539262,0.557799,-142.294556,0.056656,0.000000
44.110001,24.483490,-142.294556,0.007860,0.002207,0.056049,108.908005,5.548038,0.560490,-142.294556,0.057020,0.000000
44.330002,24.918419,-142.339050,0.007873,0.002224,0.056491,110.842667,5.646595,0.564911,-142.339050,0.057393,0.000000
44.550003,25.351120,-142.339050,0.007886,0.002240,0.056907,112.767410,5.744646,0.569074,-142.339050,0.057757,0.000000
44.770000,25.566719,-142.339050,0.007907,0.002255,0.057280,113.726448,5.793501,0.572802,-142.339050,0.058122,0.000000
44.990002,25.775246,-142.294556,0.007916,0.002268,0.057601,114.654022,5.840754,0.576012,-142.294556,0.058494,0.000000
45.210003,25.827385,-142.294556,0.007925,0.002280,0.057905,114.885948,5.852569,0.579047,-142.294556,0.058859,0.000000
45.430000,25.914146,-142.383530,0.007925,0.002293,0.058234,115.271881,5.872230,0.582344,-142.383530,0.059223,0.000000
45.650002,26.572128,-142.339050,0.007946,0.002311,0.058694,118.198730,6.021330,0.586939,-142.339050,0.059587,0.000000
45.870003,26.703949,-142.294556,0.007963,0.002322,0.058989,118.785095,6.051201,0.589887,-142.294556,0.059960,0.000000
46.090004,26.597816,-142.383530,0.007968,0.002332,0.059223,118.312996,6.027151,0.592230,-142.383530,0.060324,0.000000
46.310001,27.196220,-142.383530,0.007985,0.002350,0.059700,120.974831,6.162751,0.596999,-142.383530,0.060689,0.000000
46.530003,28.058266,-142.383530,0.007981,0.002369,0.060168,124.809402,6.358094,0.601681,-142.383530,0.061061,0.000000
46.750004,28.066826,-142.428009,0.007998,0.002380,0.060454,124.847473,6.360034,0.604542,-142.428009,0.061426,0.000000
46.970001,28.333450,-142.428009,0.008019,0.002396,0.060862,126.033478,6.420452,0.608619,-142.428009,0.061790,0.000000
47.190002,28.513306,-142.383530,0.008028,0.002407,0.061131,126.833519,6.461207,0.611310,-142.383530,0.062154,0.000000
47.410004,28.670074,-142.339050,0.008037,0.002421,0.061504,127.530861,6.496732,0.615038,-142.339050,0.062527,0.000000
47.630001,29.526154,-142.428009,0.008058,0.002441,0.062007,131.338898,6.690722,0.620068,-142.428009,0.062891,0.000000
47.850002,30.110039,-142.383530,0.008063,0.002455,0.062353,133.936142,6.823032,0.623535,-142.383530,0.063255,0.000000
48.070004,30.152115,-142.339050,0.008067,0.002467,0.062657,134.123306,6.832567,0.626570,-142.339050,0.063629,0.000000
48.290001,30.641037,-142.383530,0.008093,0.002485,0.063117,136.298141,6.943358,0.631169,-142.383530,0.063993,0.000000
48.510002,31.118050,-142.428009,0.008097,0.002500,0.063498,138.419998,7.051451,0.634984,-142.428009,0.064357,0.000000
48.730003,31.351151,-142.472488,0.008101,0.002513,0.063828,139.456879,7.104272,0.638281,-142.472488,0.064721,0.000000
48.950001,31.494888,-142.472488,0.008119,0.002525,0.064132,140.096268,7.136844,0.641316,-142.472488,0.065094,0.000000
49.170002,31.596176,-142.428009,0.008136,0.002537,0.064444,140.546814,7.159796,0.644435,-142.428009,0.065458,0.000000
49.390003,32.169258,-142.472488,0.008157,0.002551,0.064808,143.096008,7.289658,0.648080,-142.472488,0.065823,0.000000
49.610001,33.028320,-142.472488,0.008162,0.002571,0.065302,146.917313,7.484324,0.653023,-142.472488,0.066196,0.000000
49.830002,33.370903,-142.516968,0.008170,0.002583,0.065606,148.441193,7.561955,0.656059,-142.516968,0.066560,0.000000
50.050003,33.449471,-142.516968,0.008179,0.002595,0.065909,148.790680,7.579758,0.659094,-142.516968,0.066924,0.000000
50.270004,34.295128,-142.472488,0.008188,0.002615,0.066421,152.552353,7.771387,0.664211,-142.472488,0.067288,0.000000
50.490002,34.900978,-142.472488,0.008209,0.002631,0.066820,155.247299,7.908675,0.668197,-142.472488,0.067661,0.000000
50.710003,34.810493,-142.472488,0.008222,0.002640,0.067045,154.844803,7.888170,0.670453,-142.472488,0.068025,0.000000
50.930004,35.169830,-142.516968,0.008218,0.002654,0.067401,156.443222,7.969597,0.674010,-142.516968,0.068390,0.000000
51.150002,35.551140,-142.561447,0.008239,0.002670,0.067809,158.139374,8.056004,0.678087,-142.561447,0.068762,0.000000
51.370003,35.895218,-142.516968,0.008252,0.002681,0.068104,159.669907,8.133973,0.681035,-142.516968,0.069127,0.000000
51.590004,36.958710,-142.516968,0.008274,0.002701,0.068607,164.400558,8.374964,0.686065,-142.516968,0.069491,0.000000
51.810001,36.995949,-142.428009,0.008265,0.002710,0.068832,164.566193,8.383402,0.688317,-142.428009,0.069855,0.000000
52.030003,37.392525,-142.516968,0.008282,0.002725,0.069205,166.330261,8.473268,0.692049,-142.516968,0.070228,0.000000
52.250004,38.157379,-142.561447,0.008304,0.002741,0.069630,169.732498,8.646586,0.696296,-142.561447,0.070592,0.000000
52.470001,38.771423,-142.605927,0.008321,0.002757,0.070020,172.463898,8.785729,0.700198,-142.605927,0.070957,0.000000
52.690002,38.806793,-142.472488,0.008317,0.002768,0.070306,172.621231,8.793745,0.703059,-142.472488,0.071329,0.000000
52.910004,39.337799,-142.516968,0.008330,0.002781,0.070636,174.983276,8.914072,0.706356,-142.516968,0.071693,0.000000
53.130001,39.903061,-142.561447,0.008334,0.002798,0.071069,177.497681,9.042163,0.710694,-142.561447,0.072058,0.000000
53.350002,40.434067,-142.605927,0.008351,0.002811,0.071407,179.859711,9.162490,0.714073,-142.605927,0.072422,0.000000
53.570004,40.854469,-142.650406,0.008369,0.002822,0.071685,181.729752,9.257754,0.716852,-142.650406,0.072795,0.000000
53.790001,41.605545,-142.561447,0.008360,0.002839,0.072110,185.070709,9.427952,0.721098,-142.561447,0.073159,0.000000
54.010002,42.039734,-142.516968,0.008369,0.002852,0.072448,187.002075,9.526340,0.724482,-142.516968,0.073523,0.000000
54.230003,42.513763,-142.516968,0.008386,0.002869,0.072865,189.110672,9.633757,0.728645,-142.516968,0.073896,0.000000
54.450001,43.713547,-142.605927,0.008407,0.002886,0.073315,194.447571,9.905631,0.733153,-142.605927,0.074261,0.000000
54.670002,43.943298,-142.650406,0.008416,0.002901,0.073688,195.469559,9.957694,0.736881,-142.650406,0.074625,0.000000
54.890003,44.512283,-142.605927,0.008420,0.002914,0.074026,198.000519,10.086627,0.740265,-142.605927,0.074989,0.000000
55.110004,45.109947,-142.605927,0.008429,0.002929,0.074391,200.659073,10.222060,0.743906,-142.605927,0.075362,0.000000
55.330002,45.874054,-142.605927,0.008425,0.002944,0.074781,204.057983,10.395209,0.747808,-142.605927,0.075726,0.000000
55.550003,46.263924,-142.605927,0.008459,0.002957,0.075110,205.792206,10.483555,0.751105,-142.605927,0.076090,0.000000
55.770004,46.670929,-142.650406,0.008464,0.002968,0.075397,207.602661,10.575784,0.753966,-142.650406,0.076464,0.000000
55.990002,47.468552,-142.605927,0.008468,0.002987,0.075865,211.150665,10.756528,0.758652,-142.605927,0.076828,0.000000
56.210003,48.565933,-142.561447,0.008481,0.003004,0.076299,216.032059,11.005198,0.762986,-142.561447,0.077192,0.000000
56.430004,49.168060,-142.605927,0.008494,0.003018,0.076663,218.710449,11.141642,0.766630,-142.605927,0.077556,0.000000
56.650002,49.581764,-142.650406,0.008498,0.003031,0.076984,220.550705,11.235388,0.769836,-142.650406,0.077929,0.000000
56.870003,49.931419,-142.694885,0.008502,0.003043,0.077296,222.106049,11.314622,0.772959,-142.694885,0.078293,0.000000
57.090004,50.486259,-142.650406,0.008520,0.003058,0.077677,224.574097,11.440351,0.776774,-142.650406,0.078657,0.000000
57.310001,51.642471,-142.605927,0.008528,0.003075,0.078111,229.717178,11.702352,0.781111,-142.605927,0.079022,0.000000
57.530003,52.317955,-142.694885,0.008532,0.003090,0.078493,232.721893,11.855418,0.784927,-142.694885,0.079395,0.000000
57.750004,52.549576,-142.694885,0.008545,0.003102,0.078788,233.752182,11.907904,0.787875,-142.694885,0.079759,0.000000
57.970001,53.540459,-142.694885,0.008563,0.003117,0.079178,238.159851,12.132442,0.791777,-142.694885,0.080123,0.000000
58.190002,54.692574,-142.694885,0.008558,0.003136,0.079646,243.284714,12.393515,0.796463,-142.694885,0.080496,0.000000
58.410004,54.972229,-142.694885,0.008571,0.003146,0.079898,244.528687,12.456885,0.798976,-142.694885,0.080860,0.000000
58.630001,55.769104,-142.694885,0.008584,0.003162,0.080305,248.073364,12.637460,0.803053,-142.694885,0.081225,0.000000
58.850002,56.612160,-142.739365,0.008597,0.003177,0.080695,251.823471,12.828499,0.806955,-142.739365,0.081589,0.000000
59.070004,57.324509,-142.739365,0.008593,0.003191,0.081042,254.992157,12.989919,0.810422,-142.739365,0.081962,0.000000
59.290001,58.177986,-142.783859,0.008606,0.003208,0.081476,258.788605,13.183320,0.814759,-142.783859,0.082326,0.000000
59.510002,58.836708,-142.739365,0.008627,0.003218,0.081736,261.718750,13.332588,0.817363,-142.739365,0.082690,0.000000
59.730003,58.936882,-142.739365,0.008627,0.003227,0.081962,262.164337,13.355288,0.819615,-142.739365,0.083063,0.000000
59.950005,60.310562,-142.783859,0.008619,0.003249,0.082517,268.274780,13.666569,0.825168,-142.783859,0.083427,0.000000
60.170002,61.273514,-142.783859,0.008632,0.003264,0.082898,272.558197,13.884776,0.828983,-142.783859,0.083792,0.000000
60.390003,61.878990,-142.739365,0.008640,0.003276,0.083202,275.251495,14.021979,0.832018,-142.739365,0.084156,0.000000
60.610004,62.614059,-142.739365,0.008649,0.003290,0.083575,278.521240,14.188548,0.835746,-142.739365,0.084528,0.000000
60.830002,63.137611,-142.783859,0.008662,0.003302,0.083878,280.850128,14.307187,0.838782,-142.783859,0.084893,0.000000
61.050003,64.314674,-142.783859,0.008662,0.003320,0.084338,286.085968,14.573914,0.843377,-142.783859,0.085257,0.000000
61.270004,65.403130,-142.872818,0.008679,0.003336,0.084737,290.927643,14.820561,0.847366,-142.872818,0.085630,0.000000
61.490002,65.885353,-142.828339,0.008688,0.003346,0.084980,293.072693,14.929834,0.849796,-142.828339,0.085994,0.000000
61.710003,66.153831,-142.783859,0.008701,0.003355,0.085222,294.266937,14.990672,0.852222,-142.783859,0.086358,0.000000
61.930004,67.419899,-142.783859,0.008696,0.003375,0.085717,299.898682,15.277567,0.857165,-142.783859,0.086723,0.000000
62.150002,66.850533,-142.828339,0.008696,0.003368,0.085543,297.366028,15.148547,0.855432,-142.828339,0.085725,0.000000
62.370003,66.197777,-142.828339,0.008714,0.003367,0.085526,294.462433,15.000630,0.855258,-142.828339,0.085534,0.000000
62.590004,65.609795,-142.872818,0.008705,0.003367,0.085517,291.846954,14.867392,0.855174,-142.872818,0.085534,0.000000
62.810001,65.070229,-142.828339,0.008718,0.003366,0.085509,289.446838,14.745125,0.855087,-142.828339,0.085534,0.000000
63.030003,64.565666,-142.783859,0.008727,0.003366,0.085509,287.202423,14.630790,0.855087,-142.783859,0.085534,0.000000
63.250004,64.097954,-142.872818,0.008735,0.003366,0.085509,285.121948,14.524804,0.855087,-142.872818,0.085534,0.000000
63.470001,63.701759,-142.917297,0.008727,0.003366,0.085500,283.359589,14.435025,0.855000,-142.917297,0.085534,0.000000
63.690002,63.290291,-142.917297,0.008727,0.003366,0.085500,281.529266,14.341784,0.855000,-142.917297,0.085534,0.000000
63.910004,62.949936,-142.917297,0.008744,0.003366,0.085500,280.015289,14.264659,0.855000,-142.917297,0.085534,0.000000
64.130005,62.605118,-142.872818,0.008744,0.003366,0.085500,278.481476,14.186522,0.855000,-142.872818,0.085534,0.000000
64.350006,62.300522,-142.872818,0.008744,0.003366,0.085491,277.126556,14.117499,0.854913,-142.872818,0.085534,0.000000
64.570000,61.998528,-142.961777,0.008744,0.003366,0.085491,275.783234,14.049067,0.854913,-142.961777,0.085534,0.000000
64.790001,61.719620,-142.917297,0.008748,0.003366,0.085491,274.542572,13.985866,0.854913,-142.917297,0.085534,0.000000
65.010002,61.456726,-142.872818,0.008757,0.003366,0.085491,273.373169,13.926292,0.854913,-142.872818,0.085534,0.000000
65.230003,61.208725,-142.917297,0.008757,0.003366,0.085491,272.270020,13.870095,0.854913,-142.917297,0.085534,0.000000
65.450005,60.997963,-142.872818,0.008757,0.003366,0.085491,271.332489,13.822336,0.854913,-142.872818,0.085534,0.000000
65.670006,60.767090,-142.961777,0.008744,0.003366,0.085491,270.305511,13.770019,0.854913,-142.961777,0.085534,0.000000
65.889999,60.567871,-142.917297,0.008752,0.003366,0.085491,269.419342,13.724875,0.854913,-142.917297,0.085534,0.000000
66.110001,60.360085,-142.961777,0.008748,0.003366,0.085491,268.495056,13.677791,0.854913,-142.961777,0.085534,0.000000
66.330002,60.169807,-142.961777,0.008757,0.003366,0.085491,267.648682,13.634673,0.854913,-142.961777,0.085534,0.000000
66.550003,60.001122,-142.961777,0.008761,0.003366,0.085491,266.898315,13.596449,0.854913,-142.961777,0.085534,0.000000
66.770004,59.816795,-142.961777,0.008757,0.003366,0.085491,266.078400,13.554680,0.854913,-142.961777,0.085534,0.000000
66.990005,59.671196,-143.006256,0.008757,0.003366,0.085491,265.430725,13.521687,0.854913,-143.006256,0.085534,0.000000
67.210007,59.501022,-143.050735,0.008778,0.003366,0.085491,264.673767,13.483125,0.854913,-143.050735,0.085534,0.000000
67.430000,59.372551,-142.961777,0.008761,0.003366,0.085491,264.102295,13.454012,0.854913,-142.961777,0.085534,0.000000
67.650002,59.217278,-142.961777,0.008774,0.003366,0.085491,263.411621,13.418827,0.854913,-142.961777,0.085534,0.000000
67.870003,59.067207,-143.006256,0.008761,0.003366,0.085491,262.744049,13.384820,0.854913,-143.006256,0.085534,0.000000
68.090004,58.939857,-143.006256,0.008761,0.003366,0.085491,262.177582,13.355963,0.854913,-143.006256,0.085534,0.000000
68.310005,58.793144,-143.006256,0.008770,0.003366,0.085491,261.524963,13.322718,0.854913,-143.006256,0.085534,0.000000
68.530006,58.692978,-143.006256,0.008778,0.003366,0.085491,261.079407,13.300018,0.854913,-143.006256,0.085534,0.000000
68.750000,58.552589,-143.006256,0.008761,0.003366,0.085491,260.454926,13.268206,0.854913,-143.006256,0.085534,0.000000
68.970001,58.454659,-143.050735,0.008770,0.003366,0.085491,260.019318,13.246015,0.854913,-143.050735,0.085534,0.000000
69.190002,58.341827,-143.095215,0.008765,0.003366,0.085491,259.517395,13.220448,0.854913,-143.095215,0.085534,0.000000
69.410004,58.224533,-143.095215,0.008778,0.003366,0.085491,258.995667,13.193868,0.854913,-143.095215,0.085534,0.000000
69.630005,58.116913,-143.050735,0.008774,0.003366,0.085491,258.516937,13.169481,0.854913,-143.050735,0.085534,0.000000
69.850006,58.016373,-142.961777,0.008774,0.003366,0.085491,258.069702,13.146698,0.854913,-142.961777,0.085534,0.000000
70.070000,57.931473,-143.050735,0.008770,0.003366,0.085491,257.692047,13.127460,0.854913,-143.050735,0.085534,0.000000
70.290001,57.833168,-143.095215,0.008757,0.003366,0.085491,257.254791,13.105184,0.854913,-143.095215,0.085534,0.000000
70.510002,57.743050,-143.095215,0.008770,0.003366,0.085491,256.853912,13.084763,0.854913,-143.095215,0.085534,0.000000
70.730003,57.622780,-143.006256,0.008787,0.003366,0.085491,256.318939,13.057508,0.854913,-143.006256,0.085534,0.000000
70.950005,57.550163,-143.095215,0.008770,0.003366,0.085491,255.995911,13.041053,0.854913,-143.095215,0.085534,0.000000
71.170006,57.455582,-143.095215,0.008783,0.003366,0.085491,255.575195,13.019621,0.854913,-143.095215,0.085534,0.000000
71.390007,57.369934,-143.139694,0.008783,0.003366,0.085491,255.194214,13.000214,0.854913,-143.139694,0.085534,0.000000
71.610001,57.293968,-143.139694,0.008778,0.003366,0.085491,254.856293,12.982999,0.854913,-143.139694,0.085534,0.000000
71.830002,57.217636,-143.139694,0.008791,0.003366,0.085491,254.516754,12.965701,0.854913,-143.139694,0.085534,0.000000
72.050003,57.150238,-143.095215,0.008783,0.003366,0.085491,254.216949,12.950429,0.854913,-143.095215,0.085534,0.000000
72.270004,57.070175,-143.050735,0.008783,0.003366,0.085491,253.860825,12.932286,0.854913,-143.050735,0.085534,0.000000
72.490005,56.988251,-143.139694,0.008774,0.003366,0.085491,253.496399,12.913722,0.854913,-143.139694,0.085534,0.000000
72.710007,56.899628,-143.139694,0.008783,0.003366,0.085491,253.102188,12.893640,0.854913,-143.139694,0.085534,0.000000
72.930000,56.839676,-143.139694,0.008791,0.003366,0.085491,252.835510,12.880054,0.854913,-143.139694,0.085534,0.000000
73.150002,56.785309,-143.095215,0.008778,0.003366,0.085491,252.593674,12.867735,0.854913,-143.095215,0.085534,0.000000
73.370003,56.720894,-143.184189,0.008787,0.003366,0.085491,252.307144,12.853138,0.854913,-143.184189,0.085534,0.000000
73.590004,56.657211,-143.184189,0.008774,0.003366,0.085491,252.023865,12.838707,0.854913,-143.184189,0.085534,0.000000
73.810005,56.579758,-143.184189,0.008787,0.003366,0.085491,251.679337,12.821156,0.854913,-143.184189,0.085534,0.000000
74.030006,56.528748,-143.228668,0.008791,0.003366,0.085491,251.452423,12.809597,0.854913,-143.228668,0.085534,0.000000
74.250000,56.455017,-143.139694,0.008778,0.003366,0.085491,251.124451,12.792890,0.854913,-143.139694,0.085534,0.000000
74.470001,56.403625,-143.139694,0.008787,0.003366,0.085491,250.895859,12.781244,0.854913,-143.139694,0.085534,0.000000
74.690002,56.335487,-143.184189,0.008774,0.003366,0.085491,250.592758,12.765804,0.854913,-143.184189,0.085534,0.000000
74.910004,56.282234,-143.228668,0.008800,0.003366,0.085491,250.355881,12.753737,0.854913,-143.228668,0.085534,0.000000
75.130005,56.223770,-143.228668,0.008778,0.003366,0.085491,250.095825,12.740488,0.854913,-143.228668,0.085534,0.000000
75.350006,56.160843,-143.184189,0.008795,0.003366,0.085491,249.815903,12.726230,0.854913,-143.184189,0.085534,0.000000
75.570007,56.104240,-143.228668,0.008800,0.003366,0.085491,249.564133,12.713403,0.854913,-143.228668,0.085534,0.000000
75.790001,56.052483,-143.273148,0.008791,0.003366,0.085491,249.333893,12.701674,0.854913,-143.273148,0.085534,0.000000
76.010002,56.004448,-143.273148,0.008800,0.003366,0.085491,249.120224,12.690789,0.854913,-143.273148,0.085534,0.000000
76.230003,55.943375,-143.317627,0.008795,0.003366,0.085491,248.848557,12.676950,0.854913,-143.317627,0.085534,0.000000
76.450005,55.912094,-143.228668,0.008783,0.003366,0.085491,248.709412,12.669862,0.854913,-143.228668,0.085534,0.000000
76.670006,55.857361,-143.184189,0.008795,0.003366,0.085491,248.465958,12.657458,0.854913,-143.184189,0.085534,0.000000
76.890007,55.813416,-143.273148,0.008791,0.003366,0.085491,248.270477,12.647500,0.854913,-143.273148,0.085534,0.000000
77.110001,55.755699,-143.317627,0.008787,0.003366,0.085491,248.013733,12.634422,0.854913,-143.317627,0.085534,0.000000
77.330002,55.706177,-143.273148,0.008791,0.003366,0.085491,247.793457,12.623200,0.854913,-143.273148,0.085534,0.000000
77.550003,55.660004,-143.317627,0.008800,0.003366,0.085491,247.588058,12.612738,0.854913,-143.317627,0.085534,0.000000
77.770004,55.619415,-143.228668,0.008787,0.003366,0.085491,247.407516,12.603540,0.854913,-143.228668,0.085534,0.000000
77.990005,55.576218,-143.273148,0.008787,0.003366,0.085491,247.215363,12.593751,0.854913,-143.273148,0.085534,0.000000
78.210007,55.533020,-143.317627,0.008783,0.003366,0.085491,247.023209,12.583962,0.854913,-143.317627,0.085534,0.000000
78.430000,55.480148,-143.362106,0.008795,0.003366,0.085491,246.788025,12.571981,0.854913,-143.362106,0.085534,0.000000
78.650002,55.439186,-143.273148,0.008787,0.003366,0.085491,246.605820,12.562699,0.854913,-143.273148,0.085534,0.000000
78.870003,55.392265,-143.273148,0.008804,0.003366,0.085491,246.397095,12.552067,0.854913,-143.273148,0.085534,0.000000
79.090004,55.363220,-143.273148,0.008791,0.003366,0.085491,246.267899,12.545485,0.854913,-143.273148,0.085534,0.000000
79.310005,55.305504,-143.317627,0.008800,0.003366,0.085491,246.011169,12.532406,0.854913,-143.317627,0.085534,0.000000
79.530006,55.286880,-143.362106,0.008804,0.003366,0.085491,245.928329,12.528187,0.854913,-143.362106,0.085534,0.000000
79.750000,55.242569,-143.317627,0.008795,0.003366,0.085491,245.731216,12.518145,0.854913,-143.317627,0.085534,0.000000
79.970001,55.192673,-143.273148,0.008804,0.003366,0.085491,245.509277,12.506839,0.854913,-143.273148,0.085534,0.000000
80.190002,55.161766,-143.317627,0.008787,0.003366,0.085491,245.371796,12.499835,0.854913,-143.317627,0.085534,0.000000
80.410004,55.098091,-143.406586,0.008787,0.003366,0.085491,245.088547,12.485406,0.854913,-143.406586,0.085534,0.000000
80.630005,55.069046,-143.406586,0.008800,0.003366,0.085491,244.959351,12.478825,0.854913,-143.406586,0.085534,0.000000
80.850006,55.025848,-143.362106,0.008800,0.003366,0.085491,244.767197,12.469035,0.854913,-143.362106,0.085534,0.000000
81.070007,55.011703,-143.317627,0.008795,0.003366,0.085491,244.704285,12.465831,0.854913,-143.317627,0.085534,0.000000
81.290001,54.976700,-143.317627,0.008800,0.003366,0.085491,244.548569,12.457899,0.854913,-143.317627,0.085534,0.000000
81.510002,54.931267,-143.362106,0.008795,0.003366,0.085491,244.346481,12.447603,0.854913,-143.362106,0.085534,0.000000
81.730003,54.890678,-143.362106,0.008787,0.003366,0.085491,244.165939,12.438406,0.854913,-143.362106,0.085534,0.000000
81.950005,54.853073,-143.362106,0.008813,0.003366,0.085491,243.998657,12.429884,0.854913,-143.362106,0.085534,0.000000
82.170006,54.813225,-143.362106,0.008795,0.003366,0.085491,243.821396,12.420855,0.854913,-143.362106,0.085534,0.000000
82.390007,54.775986,-143.406586,0.008795,0.003366,0.085491,243.655746,12.412416,0.854913,-143.406586,0.085534,0.000000
82.610001,54.740242,-143.406586,0.008808,0.003366,0.085491,243.496765,12.404316,0.854913,-143.406586,0.085534,0.000000
82.830002,54.705238,-143.495544,0.008804,0.003366,0.085491,243.341049,12.396384,0.854913,-143.495544,0.085534,0.000000
83.050003,54.687363,-143.406586,0.008808,0.003366,0.085491,243.261536,12.392334,0.854913,-143.406586,0.085534,0.000000
83.270004,54.650497,-143.406586,0.008795,0.003366,0.085491,243.097549,12.383980,0.854913,-143.406586,0.085534,0.000000
83.490005,54.626671,-143.495544,0.008800,0.003366,0.085491,242.991562,12.378581,0.854913,-143.495544,0.085534,0.000000
83.710007,54.587570,-143.495544,0.008800,0.003366,0.085491,242.817642,12.369720,0.854913,-143.495544,0.085534,0.000000
83.930000,54.565971,-143.451065,0.008791,0.003366,0.085491,242.721558,12.364826,0.854913,-143.451065,0.085534,0.000000
84.150002,54.535065,-143.495544,0.008813,0.003366,0.085491,242.584076,12.357821,0.854913,-143.495544,0.085534,0.000000
84.370003,54.500435,-143.451065,0.008808,0.003366,0.085491,242.430038,12.349976,0.854913,-143.451065,0.085534,0.000000
84.590004,54.467667,-143.495544,0.008804,0.003366,0.085491,242.284286,12.342549,0.854913,-143.495544,0.085534,0.000000
84.810005,54.431541,-143.495544,0.008804,0.003366,0.085491,242.123596,12.334363,0.854913,-143.495544,0.085534,0.000000
85.030006,54.402496,-143.540024,0.008791,0.003366,0.085491,241.994385,12.327782,0.854913,-143.540024,0.085534,0.000000
85.250008,54.391327,-143.495544,0.008817,0.003366,0.085491,241.944702,12.325251,0.854913,-143.495544,0.085534,0.000000
85.470001,54.352600,-143.451065,0.008804,0.003366,0.085491,241.772446,12.316475,0.854913,-143.451065,0.085534,0.000000
85.690002,54.318344,-143.451065,0.008804,0.003366,0.085491,241.620056,12.308712,0.854913,-143.451065,0.085534,0.000000
85.910004,54.301216,-143.495544,0.008791,0.003366,0.085491,241.543869,12.304832,0.854913,-143.495544,0.085534,0.000000
86.130005,54.270676,-143.495544,0.008800,0.003366,0.085491,241.408020,12.297911,0.854913,-143.495544,0.085534,0.000000
86.350006,54.246849,-143.540024,0.008808,0.003366,0.085491,241.302032,12.292512,0.854913,-143.540024,0.085534,0.000000
86.570007,54.200676,-143.495544,0.008817,0.003366,0.085491,241.096649,12.282049,0.854913,-143.495544,0.085534,0.000000
86.790001,54.189133,-143.495544,0.008795,0.003366,0.085491,241.045303,12.279432,0.854913,-143.495544,0.085534,0.000000
87.010002,54.165672,-143.495544,0.008791,0.003366,0.085491,240.940948,12.274117,0.854913,-143.495544,0.085534,0.000000
87.230003,54.138115,-143.628998,0.008795,0.003366,0.085491,240.818359,12.267872,0.854913,-143.628998,0.085534,0.000000
87.450005,54.112419,-143.584503,0.008817,0.003366,0.085491,240.704056,12.262050,0.854913,-143.584503,0.085534,0.000000
87.670006,54.084122,-143.540024,0.008804,0.003366,0.085491,240.578186,12.255637,0.854913,-143.540024,0.085534,0.000000
87.890007,54.060661,-143.540024,0.008804,0.003366,0.085491,240.473831,12.250320,0.854913,-143.540024,0.085534,0.000000
88.110001,54.031242,-143.628998,0.008800,0.003366,0.085491,240.342972,12.243654,0.854913,-143.628998,0.085534,0.000000
88.330002,54.014114,-143.584503,0.008808,0.003366,0.085491,240.266785,12.239774,0.854913,-143.584503,0.085534,0.000000
88.550003,53.988052,-143.584503,0.008804,0.003366,0.085491,240.150848,12.233868,0.854913,-143.584503,0.085534,0.000000
88.770004,53.974274,-143.584503,0.008817,0.003366,0.085491,240.089554,12.230745,0.854913,-143.584503,0.085534,0.000000
88.990005,53.941872,-143.540024,0.008813,0.003366,0.085491,239.945435,12.223402,0.854913,-143.540024,0.085534,0.000000
89.210007,53.921021,-143.584503,0.008795,0.003366,0.085491,239.852676,12.218678,0.854913,-143.584503,0.085534,0.000000
89.430008,53.891975,-143.584503,0.008808,0.003366,0.085491,239.723480,12.212096,0.854913,-143.584503,0.085534,0.000000
89.650002,53.868515,-143.628998,0.008800,0.003366,0.085491,239.619125,12.206779,0.854913,-143.628998,0.085534,0.000000
89.870003,53.861069,-143.584503,0.008804,0.003366,0.085491,239.585999,12.205092,0.854913,-143.584503,0.085534,0.000000
90.090004,53.839844,-143.628998,0.008808,0.003366,0.085491,239.491592,12.200283,0.854913,-143.628998,0.085534,0.000000
90.310005,53.812286,-143.584503,0.008804,0.003366,0.085491,239.369003,12.194038,0.854913,-143.584503,0.085534,0.000000
90.530006,53.789200,-143.673477,0.008804,0.003366,0.085491,239.266312,12.188807,0.854913,-143.673477,0.085534,0.000000
90.750008,53.753456,-143.717957,0.008808,0.003366,0.085491,239.107315,12.180708,0.854913,-143.717957,0.085534,0.000000
90.970001,53.735580,-143.584503,0.008826,0.003366,0.085491,239.027802,12.176657,0.854913,-143.584503,0.085534,0.000000
91.190002,53.710258,-143.673477,0.008808,0.003366,0.085491,238.915161,12.170918,0.854913,-143.673477,0.085534,0.000000
91.410004,53.703186,-143.628998,0.008804,0.003366,0.085491,238.883698,12.169316,0.854913,-143.628998,0.085534,0.000000
91.630005,53.668922,-143.673477,0.008813,0.003366,0.085491,238.731293,12.161551,0.854913,-143.673477,0.085534,0.000000
91.850006,53.652916,-143.717957,0.008808,0.003366,0.085491,238.660095,12.157925,0.854913,-143.717957,0.085534,0.000000
92.070007,53.625732,-143.673477,0.008821,0.003366,0.085491,238.539169,12.151765,0.854913,-143.673477,0.085534,0.000000
92.290001,53.603760,-143.717957,0.008817,0.003366,0.085491,238.441437,12.146785,0.854913,-143.717957,0.085534,0.000000
92.400002,53.587379,-143.717957,0.008795,0.003366,0.085491,238.368576,12.143074,0.854913,-143.717957,0.085534,0.000000