File: Data/compression 4 4 days/AutoNoheating-17-4-1-240226_02262024_163853.csv
Time (sec),S:Load (lbs),S:HL1 (DIM),S:LVDT (in),S:Position (in),Ch:Position (mm),Ch:Load (N),Ch:Stress (MPa),Ch:Strain (mm/mm),Ch:HL1 (DIM),Set Point (),Cycles ()
0.110000,-0.001114,-132.642197,-0.000009,-0.000000,-0.000000,-0.004955,-0.000252,-0.000000,-132.642197,0.000139,0.000000
0.340000,0.014893,-132.597717,-0.000004,-0.000000,-0.000000,0.066245,0.003375,-0.000000,-132.597717,0.000139,0.000000
0.570000,0.020111,-132.553238,0.000013,0.000094,0.002385,0.089459,0.004557,0.023849,-132.553238,0.003070,0.000000
0.800000,0.020111,-132.642197,0.000043,0.000229,0.005828,0.089459,0.004557,0.058276,-132.642197,0.006903,0.000000
1.030000,0.000374,-132.642197,0.000181,0.000382,0.009704,0.001663,0.000085,0.097041,-132.642197,0.010736,0.000000
1.260000,-0.012291,-132.642197,0.000358,0.000534,0.013564,-0.054673,-0.002785,0.135635,-132.642197,0.014570,0.000000
1.490000,-0.036865,-132.597717,0.000487,0.000676,0.017180,-0.163985,-0.008354,0.171796,-132.597717,0.018403,0.000000
1.720000,0.024574,-132.642197,0.000638,0.000830,0.021091,0.109312,0.005569,0.210909,-132.642197,0.022235,0.000000
1.950000,0.028671,-132.597717,0.000798,0.000984,0.024994,0.127536,0.006497,0.249936,-132.597717,0.026069,0.000000
2.180000,0.042824,-132.642197,0.000931,0.001135,0.028818,0.190490,0.009704,0.288178,-132.642197,0.029902,0.000000
2.410000,0.022346,-132.686676,0.001099,0.001286,0.032660,0.099402,0.005064,0.326599,-132.686676,0.033735,0.000000
2.640000,-0.009682,-132.597717,0.001224,0.001436,0.036484,-0.043066,-0.002194,0.364841,-132.597717,0.037568,0.000000
2.870000,0.014526,-132.642197,0.001388,0.001587,0.040317,0.064617,0.003292,0.403175,-132.642197,0.041384,0.000000
3.100000,0.008194,-132.642197,0.001535,0.001739,0.044177,0.036449,0.001857,0.441765,-132.642197,0.045217,0.000000
3.330000,0.025322,-132.731155,0.001686,0.001886,0.047905,0.112638,0.005738,0.479054,-132.731155,0.049050,0.000000
3.560000,0.005585,-132.686676,0.001832,0.002041,0.051843,0.024842,0.001266,0.518428,-132.686676,0.052883,0.000000
3.790000,0.017876,-132.642197,0.001983,0.002189,0.055598,0.079515,0.004051,0.555978,-132.642197,0.056717,0.000000
4.020000,0.017876,-132.642197,0.002130,0.002338,0.059388,0.079515,0.004051,0.593877,-132.642197,0.060550,0.000000
4.250000,0.038353,-132.686676,0.002298,0.002497,0.063429,0.170603,0.008691,0.634288,-132.686676,0.064383,0.000000
4.480000,0.026810,-132.686676,0.002453,0.002644,0.067149,0.119255,0.006075,0.671493,-132.686676,0.068216,0.000000
4.710000,0.034256,-132.731155,0.002600,0.002793,0.070948,0.152378,0.007763,0.709479,-132.731155,0.072049,0.000000
4.940000,0.027184,-132.686676,0.002759,0.002948,0.074876,0.120918,0.006160,0.748762,-132.686676,0.075882,0.000000
5.170000,-0.012291,-132.731155,0.002906,0.003093,0.078562,-0.054673,-0.002785,0.785619,-132.731155,0.079716,0.000000
5.400000,0.012291,-132.686676,0.003053,0.003242,0.082352,0.054673,0.002785,0.823517,-132.686676,0.083549,0.000000
5.630000,0.020485,-132.731155,0.003221,0.003398,0.086306,0.091121,0.004642,0.863062,-132.731155,0.087381,0.000000
5.860000,0.059578,-132.820114,0.003350,0.003545,0.090044,0.265016,0.013501,0.900442,-132.820114,0.091197,0.000000
6.090000,0.052505,-132.642197,0.003505,0.003699,0.093946,0.233556,0.011898,0.939464,-132.642197,0.095031,0.000000
6.320000,0.015640,-132.731155,0.003660,0.003848,0.097736,0.069571,0.003544,0.977362,-132.731155,0.098864,0.000000
6.550000,0.032394,-132.731155,0.003816,0.004003,0.101682,0.144098,0.007341,1.016823,-132.731155,0.102697,0.000000
6.780000,0.052879,-132.820114,0.003967,0.004156,0.105559,0.235219,0.011983,1.055588,-132.820114,0.106530,0.000000
7.010000,0.058090,-132.820114,0.004105,0.004297,0.109149,0.258398,0.013163,1.091492,-132.820114,0.110363,0.000000
7.240000,0.032028,-132.775635,0.004264,0.004455,0.113147,0.142469,0.007258,1.131468,-132.775635,0.114196,0.000000
7.470000,0.022713,-132.820114,0.004419,0.004601,0.116859,0.101031,0.005147,1.168586,-132.820114,0.118029,0.000000
7.700000,-0.010056,-132.775635,0.004557,0.004750,0.120648,-0.044729,-0.002279,1.206484,-132.775635,0.121863,0.000000
7.930000,0.043198,-132.820114,0.004691,0.004903,0.124525,0.192153,0.009789,1.245249,-132.820114,0.125696,0.000000
8.160001,0.043571,-132.864594,0.004859,0.005052,0.128315,0.193816,0.009873,1.283148,-132.864594,0.129529,0.000000
8.390000,0.065163,-132.820114,0.005006,0.005204,0.132191,0.289858,0.014766,1.321912,-132.820114,0.133362,0.000000
8.620001,0.062187,-132.775635,0.005178,0.005358,0.136094,0.276622,0.014092,1.360938,-132.775635,0.137178,0.000000
8.850000,0.036865,-132.820114,0.005333,0.005508,0.139901,0.163985,0.008354,1.399007,-132.820114,0.141011,0.000000
9.080001,0.033142,-132.820114,0.005484,0.005657,0.143691,0.147423,0.007510,1.436905,-132.820114,0.144844,0.000000
9.310000,0.041336,-132.864594,0.005627,0.005811,0.147611,0.183872,0.009367,1.476105,-132.864594,0.148677,0.000000
9.540001,0.060326,-132.820114,0.005777,0.005956,0.151279,0.268342,0.013670,1.512788,-132.820114,0.152510,0.000000
9.770000,0.077080,-132.775635,0.005924,0.006115,0.155312,0.342868,0.017467,1.553117,-132.775635,0.156343,0.000000
10.000000,0.644951,-132.775635,0.006066,0.006261,0.159041,2.868885,0.146148,1.590405,-132.775635,0.160177,0.000000
10.230000,0.722778,-132.909088,0.006092,-0.000002,-0.000061,3.215079,0.163784,-0.000606,-132.909088,0.000121,0.000000
10.460000,0.693359,-132.909088,0.006079,-0.000003,-0.000069,3.084217,0.157117,-0.000693,-132.909088,0.000121,0.000000
10.690001,0.698944,-132.909088,0.006084,-0.000003,-0.000069,3.109059,0.158383,-0.000693,-132.909088,0.000355,0.000000
10.920000,0.620377,-132.909088,0.006075,-0.000002,-0.000061,2.759573,0.140579,-0.000606,-132.909088,0.000737,0.000000
11.150001,0.717194,-132.864594,0.006084,0.000008,0.000208,3.190237,0.162518,0.002082,-132.864594,0.001128,0.000000
11.380000,0.951416,-132.909088,0.006096,0.000027,0.000685,4.232110,0.215594,0.006851,-132.909088,0.001509,0.000000
11.610001,1.150635,-132.909088,0.006096,0.000044,0.001110,5.118279,0.260738,0.011101,-132.909088,0.001891,0.000000
11.840000,1.288406,-132.909088,0.006122,0.000055,0.001388,5.731118,0.291957,0.013875,-132.909088,0.002272,0.000000
12.070001,1.472733,-132.864594,0.006131,0.000068,0.001717,6.551042,0.333726,0.017172,-132.864594,0.002654,0.000000
12.300000,1.585190,-132.909088,0.006127,0.000079,0.002003,7.051277,0.359209,0.020033,-132.909088,0.003044,0.000000
12.530001,1.850319,-132.909088,0.006157,0.000098,0.002489,8.230630,0.419288,0.024889,-132.909088,0.003426,0.000000
12.760000,2.071136,-132.953568,0.006170,0.000114,0.002905,9.212875,0.469326,0.029053,-132.953568,0.003807,0.000000
12.990001,2.219711,-132.953568,0.006178,0.000126,0.003191,9.873769,0.502994,0.031914,-132.953568,0.004189,0.000000
13.220000,2.411858,-132.953568,0.006187,0.000139,0.003530,10.728478,0.546535,0.035298,-132.953568,0.004570,0.000000
13.450001,2.745132,-132.909088,0.006213,0.000157,0.003998,12.210959,0.622056,0.039980,-132.909088,0.004960,0.000000
13.680000,3.027763,-132.953568,0.006217,0.000173,0.004388,13.468164,0.686101,0.043882,-132.953568,0.005342,0.000000
13.910001,3.254906,-132.998047,0.006239,0.000186,0.004735,14.478543,0.737572,0.047349,-132.998047,0.005724,0.000000
14.140000,3.545357,-132.998047,0.006239,0.000202,0.005134,15.770535,0.803389,0.051338,-132.998047,0.006105,0.000000
14.370001,3.789261,-132.953568,0.006243,0.000217,0.005524,16.855474,0.858659,0.055241,-132.953568,0.006487,0.000000
14.600000,4.110992,-132.998047,0.006278,0.000235,0.005958,18.286608,0.931564,0.059578,-132.998047,0.006877,0.000000
14.830001,4.399582,-132.998047,0.006278,0.000251,0.006383,19.570318,0.996960,0.063828,-132.998047,0.007259,0.000000
15.060000,4.625237,-133.042526,0.006278,0.000264,0.006713,20.574080,1.048094,0.067125,-133.042526,0.007640,0.000000
15.290001,4.815521,-133.087006,0.006291,0.000277,0.007042,21.420507,1.091213,0.070418,-133.087006,0.008022,0.000000
15.520000,5.231834,-132.998047,0.006321,0.000298,0.007562,23.272362,1.185551,0.075622,-132.998047,0.008404,0.000000
15.750001,5.435524,-133.042526,0.006355,0.000311,0.007892,24.178419,1.231707,0.078919,-133.042526,0.008794,0.000000
15.980000,5.507759,-133.042526,0.006342,0.000320,0.008117,24.499737,1.248076,0.081171,-133.042526,0.009175,0.000000
16.210001,5.862633,-133.042526,0.006372,0.000339,0.008611,26.078293,1.328492,0.086114,-133.042526,0.009557,0.000000
16.440001,6.295326,-133.042526,0.006372,0.000360,0.009149,28.003010,1.426541,0.091492,-133.042526,0.009938,0.000000
16.670000,6.358261,-133.042526,0.006390,0.000371,0.009418,28.282957,1.440803,0.094180,-133.042526,0.010320,0.000000
16.900002,6.547424,-133.087006,0.006407,0.000386,0.009808,29.124397,1.483668,0.098082,-133.087006,0.010710,0.000000
17.130001,6.831917,-133.087006,0.006424,0.000405,0.010285,30.389883,1.548134,0.102855,-133.087006,0.011092,0.000000
17.360001,7.076942,-133.131485,0.006424,0.000421,0.010684,31.479813,1.603658,0.106844,-133.131485,0.011474,0.000000
17.590000,7.250465,-133.087006,0.006441,0.000436,0.011075,32.251682,1.642979,0.110746,-133.087006,0.011855,0.000000
17.820002,7.329407,-133.042526,0.006454,0.000448,0.011387,32.602829,1.660867,0.113869,-133.042526,0.012237,0.000000
18.050001,7.771790,-133.042526,0.006489,0.000469,0.011924,34.570648,1.761113,0.119243,-133.042526,0.012627,0.000000
18.280001,7.797852,-133.131485,0.006502,0.000483,0.012263,34.686577,1.767018,0.122627,-133.131485,0.013008,0.000000
18.510000,7.830246,-133.131485,0.006497,0.000492,0.012497,34.830673,1.774359,0.124966,-133.131485,0.013390,0.000000
18.740002,8.032448,-133.131485,0.006510,0.000508,0.012913,35.730114,1.820179,0.129129,-133.131485,0.013772,0.000000
18.970001,8.225708,-133.175964,0.006532,0.000524,0.013321,36.589775,1.863972,0.133206,-133.175964,0.014162,0.000000
19.200001,8.295715,-133.087006,0.006541,0.000536,0.013615,36.901184,1.879836,0.136154,-133.087006,0.014543,0.000000
19.430000,8.630104,-133.087006,0.006554,0.000558,0.014162,38.388618,1.955610,0.141619,-133.087006,0.014925,0.000000
19.660002,8.560844,-133.131485,0.006588,0.000565,0.014361,38.080540,1.939915,0.143614,-133.131485,0.015306,0.000000
19.890001,8.742187,-133.175964,0.006566,0.000584,0.014830,38.887192,1.981008,0.148296,-133.175964,0.015688,0.000000
20.120001,8.936943,-133.087006,0.006597,0.000599,0.015211,39.753510,2.025140,0.152111,-133.087006,0.016078,0.000000
20.350000,9.065033,-133.131485,0.006618,0.000614,0.015593,40.323280,2.054166,0.155926,-133.131485,0.016460,0.000000
20.580002,9.145844,-133.175964,0.006627,0.000629,0.015965,40.682743,2.072478,0.159654,-133.175964,0.016842,0.000000
20.810001,9.249733,-133.175964,0.006631,0.000644,0.016347,41.144867,2.096020,0.163473,-133.175964,0.017223,0.000000
21.040001,9.383415,-133.220444,0.006657,0.000660,0.016755,41.739517,2.126312,0.167550,-133.220444,0.017605,0.000000
21.270000,9.489166,-133.131485,0.006670,0.000674,0.017119,42.209919,2.150276,0.171191,-133.131485,0.017995,0.000000
21.500002,9.631416,-133.175964,0.006679,0.000690,0.017518,42.842678,2.182510,0.175180,-133.175964,0.018376,0.000000
21.730001,9.511887,-133.175964,0.006687,0.000698,0.017726,42.310986,2.155424,0.177262,-133.175964,0.018758,0.000000
21.960001,9.847763,-133.264923,0.006713,0.000718,0.018247,43.805038,2.231535,0.182466,-133.264923,0.019140,0.000000
22.190001,10.090919,-133.220444,0.006726,0.000739,0.018758,44.886650,2.286635,0.187579,-133.220444,0.019521,0.000000
22.420002,10.089806,-133.175964,0.006743,0.000752,0.019096,44.881699,2.286383,0.190963,-133.175964,0.019912,0.000000
22.650002,10.065598,-133.220444,0.006756,0.000765,0.019426,44.774014,2.280897,0.194260,-133.220444,0.020293,0.000000
22.880001,10.089806,-133.220444,0.006773,0.000778,0.019755,44.881699,2.286383,0.197553,-133.220444,0.020675,0.000000
23.110001,10.344879,-133.264923,0.006765,0.000796,0.020215,46.016319,2.344183,0.202151,-133.264923,0.021056,0.000000
23.340002,10.386589,-133.220444,0.006795,0.000809,0.020536,46.201855,2.353635,0.205361,-133.220444,0.021438,0.000000
23.570002,10.265564,-133.220444,0.006817,0.000819,0.020805,45.663509,2.326210,0.208048,-133.220444,0.021828,0.000000
23.800001,10.668472,-133.264923,0.006825,0.000841,0.021351,47.455734,2.417511,0.213510,-133.264923,0.022210,0.000000
24.030001,10.913490,-133.264923,0.006838,0.000859,0.021828,48.545628,2.473032,0.218282,-133.264923,0.022591,0.000000
24.260000,10.844231,-133.309418,0.006868,0.000873,0.022175,48.237549,2.457338,0.221749,-133.309418,0.022973,0.000000
24.490002,10.898972,-133.264923,0.006860,0.000887,0.022539,48.481049,2.469742,0.225390,-133.264923,0.023354,0.000000
24.720001,10.863594,-133.264923,0.006885,0.000899,0.022843,48.323681,2.461726,0.228426,-133.264923,0.023745,0.000000
24.950001,11.073616,-133.264923,0.006903,0.000916,0.023259,49.257904,2.509317,0.232589,-133.264923,0.024126,0.000000
25.180000,11.197617,-133.309418,0.006916,0.000932,0.023667,49.809486,2.537416,0.236666,-133.309418,0.024508,0.000000
25.410002,11.193520,-133.398376,0.006920,0.000944,0.023979,49.791264,2.536488,0.239788,-133.398376,0.024889,0.000000
25.640001,11.224426,-133.309418,0.006942,0.000957,0.024300,49.928741,2.543491,0.242998,-133.309418,0.025271,0.000000
25.870001,11.482849,-133.264923,0.006950,0.000976,0.024803,51.078262,2.602051,0.248028,-133.264923,0.025661,0.000000
26.100000,11.508171,-133.264923,0.006976,0.000990,0.025149,51.190903,2.607789,0.251495,-133.264923,0.026043,0.000000
26.330002,11.483223,-133.353897,0.006985,0.001004,0.025514,51.079926,2.602136,0.255136,-133.353897,0.026424,0.000000
26.560001,11.565514,-133.353897,0.006989,0.001017,0.025835,51.445972,2.620783,0.258346,-133.353897,0.026806,0.000000
26.790001,11.526787,-133.353897,0.006989,0.001030,0.026164,51.273708,2.612007,0.261642,-133.353897,0.027188,0.000000
27.020000,11.907730,-133.309418,0.007015,0.001049,0.026650,52.968227,2.698330,0.266498,-133.309418,0.027578,0.000000
27.250002,11.966187,-133.220444,0.007036,0.001063,0.026988,53.228256,2.711577,0.269882,-133.220444,0.027959,0.000000
27.480001,11.887245,-133.398376,0.007045,0.001073,0.027257,52.877106,2.693688,0.272569,-133.398376,0.028341,0.000000
27.710001,12.061516,-133.398376,0.007054,0.001091,0.027699,53.652302,2.733179,0.276994,-133.398376,0.028722,0.000000
27.940001,12.485275,-133.398376,0.007075,0.001112,0.028254,55.537277,2.829204,0.282542,-133.398376,0.029113,0.000000
28.170002,12.376915,-133.353897,0.007084,0.001123,0.028532,55.055267,2.804649,0.285317,-133.353897,0.029494,0.000000
28.400002,12.354202,-133.353897,0.007097,0.001137,0.028879,54.954235,2.799502,0.288787,-133.353897,0.029876,0.000000
28.630001,12.435753,-133.398376,0.007123,0.001151,0.029243,55.316990,2.817982,0.292429,-133.398376,0.030258,0.000000
28.860001,12.451019,-133.442856,0.007114,0.001165,0.029590,55.384899,2.821441,0.295899,-133.442856,0.030639,0.000000
29.090002,12.683754,-133.398376,0.007123,0.001180,0.029980,56.420155,2.874180,0.299802,-133.398376,0.031029,0.000000
29.320002,12.915367,-133.398376,0.007157,0.001197,0.030414,57.450420,2.926664,0.304135,-133.398376,0.031411,0.000000
29.550001,13.104530,-133.398376,0.007183,0.001214,0.030830,58.291862,2.969529,0.308299,-133.398376,0.031792,0.000000
29.780001,13.294067,-133.398376,0.007200,0.001233,0.031315,59.134964,3.012479,0.313155,-133.398376,0.032174,0.000000
30.010002,13.414345,-133.442856,0.007213,0.001249,0.031732,59.669987,3.039734,0.317318,-133.442856,0.032556,0.000000
30.240002,13.385300,-133.442856,0.007222,0.001262,0.032061,59.540787,3.033152,0.320615,-133.442856,0.032946,0.000000
30.470001,13.287369,-133.442856,0.007239,0.001274,0.032365,59.105167,3.010961,0.323650,-133.442856,0.033328,0.000000
30.700001,13.586380,-133.398376,0.007248,0.001292,0.032816,60.435238,3.078718,0.328158,-133.398376,0.033709,0.000000
30.930002,13.704056,-133.487335,0.007269,0.001308,0.033215,60.958683,3.105383,0.332147,-133.487335,0.034091,0.000000
31.160002,13.821350,-133.487335,0.007282,0.001322,0.033588,61.480434,3.131963,0.335875,-133.487335,0.034472,0.000000
31.390001,13.651917,-133.487335,0.007278,0.001332,0.033839,60.726757,3.093569,0.338392,-133.487335,0.034863,0.000000
31.620001,14.096535,-133.487335,0.007291,0.001352,0.034342,62.704517,3.194320,0.343422,-133.487335,0.035244,0.000000
31.850002,14.219040,-133.442856,0.007325,0.001368,0.034750,63.249447,3.222080,0.347499,-133.442856,0.035626,0.000000
32.080002,14.239151,-133.487335,0.007338,0.001381,0.035079,63.338905,3.226638,0.350792,-133.487335,0.036007,0.000000
32.310001,14.356445,-133.531815,0.007351,0.001397,0.035487,63.860657,3.253217,0.354868,-133.531815,0.036389,0.000000
32.540001,14.332245,-133.487335,0.007364,0.001409,0.035782,63.753010,3.247733,0.357816,-133.487335,0.036779,0.000000
32.770000,14.516197,-133.531815,0.007377,0.001425,0.036198,64.571274,3.289417,0.361980,-133.531815,0.037160,0.000000
33.000000,14.865479,-133.487335,0.007390,0.001444,0.036684,66.124954,3.368566,0.366836,-133.487335,0.037542,0.000000
33.230003,14.760841,-133.531815,0.007411,0.001455,0.036952,65.659500,3.344854,0.369523,-133.531815,0.037924,0.000000
33.460003,14.831596,-133.576294,0.007420,0.001468,0.037282,65.974236,3.360888,0.372820,-133.576294,0.038305,0.000000
33.690002,14.865479,-133.487335,0.007429,0.001483,0.037672,66.124954,3.368566,0.376722,-133.487335,0.038696,0.000000
33.920002,15.199127,-133.487335,0.007433,0.001500,0.038089,67.609093,3.444171,0.380885,-133.487335,0.039077,0.000000
34.150002,15.453827,-133.531815,0.007459,0.001517,0.038522,68.742058,3.501887,0.385223,-133.531815,0.039459,0.000000
34.380001,15.368553,-133.576294,0.007476,0.001527,0.038791,68.362740,3.482564,0.387910,-133.576294,0.039840,0.000000
34.610001,15.396484,-133.576294,0.007476,0.001542,0.039173,68.486984,3.488893,0.391725,-133.576294,0.040222,0.000000
34.840000,15.723427,-133.531815,0.007480,0.001559,0.039598,69.941292,3.562979,0.395976,-133.531815,0.040612,0.000000
35.070004,15.819130,-133.576294,0.007519,0.001572,0.039936,70.367004,3.584666,0.399356,-133.576294,0.040994,0.000000
35.300003,16.003822,-133.576294,0.007528,0.001588,0.040343,71.188560,3.626518,0.403432,-133.576294,0.041375,0.000000
35.530003,16.174370,-133.576294,0.007549,0.001605,0.040777,71.947189,3.665165,0.407769,-133.576294,0.041757,0.000000
35.760002,16.443970,-133.576294,0.007558,0.001622,0.041202,73.146431,3.726257,0.412020,-133.576294,0.042138,0.000000
35.990002,16.583984,-133.531815,0.007558,0.001637,0.041584,73.769249,3.757984,0.415835,-133.531815,0.042529,0.000000
36.220001,16.713196,-133.531815,0.007584,0.001653,0.041991,74.344009,3.787264,0.419911,-133.531815,0.042910,0.000000
36.450001,16.805168,-133.620773,0.007606,0.001668,0.042364,74.753120,3.808106,0.423640,-133.620773,0.043292,0.000000
36.680000,16.968269,-133.576294,0.007623,0.001686,0.042832,75.478630,3.845065,0.428321,-133.576294,0.043674,0.000000
36.910000,17.126900,-133.665253,0.007631,0.001700,0.043179,76.184258,3.881011,0.431792,-133.665253,0.044064,0.000000
37.140003,17.016304,-133.665253,0.007649,0.001710,0.043422,75.692299,3.855950,0.434218,-133.665253,0.044445,0.000000
37.370003,16.861397,-133.665253,0.007662,0.001718,0.043647,75.003242,3.820847,0.436474,-133.665253,0.044827,0.000000
37.600002,17.660507,-133.620773,0.007670,0.001745,0.044324,78.557861,4.001928,0.443238,-133.620773,0.045208,0.000000
37.830002,17.961014,-133.665253,0.007692,0.001762,0.044766,79.894577,4.070024,0.447662,-133.665253,0.045590,0.000000
38.060001,17.861961,-133.665253,0.007713,0.001776,0.045105,79.453972,4.047578,0.451046,-133.665253,0.045980,0.000000
38.290001,17.857124,-133.620773,0.007709,0.001790,0.045460,79.432457,4.046482,0.454600,-133.620773,0.046362,0.000000
38.520000,18.432068,-133.665253,0.007735,0.001811,0.045989,81.989929,4.176766,0.459891,-133.665253,0.046743,0.000000
38.750000,18.426109,-133.665253,0.007765,0.001824,0.046336,81.963425,4.175416,0.463358,-133.665253,0.047125,0.000000
38.980003,18.433556,-133.709732,0.007765,0.001836,0.046639,81.996552,4.177104,0.466394,-133.709732,0.047506,0.000000
39.210003,18.904236,-133.709732,0.007782,0.001857,0.047168,84.090240,4.283761,0.471685,-133.709732,0.047897,0.000000
39.440002,19.110153,-133.709732,0.007800,0.001873,0.047585,85.006210,4.330423,0.475848,-133.709732,0.048279,0.000000
39.670002,18.922478,-133.665253,0.007812,0.001883,0.047819,84.171387,4.287895,0.478187,-133.665253,0.048660,0.000000
39.900002,18.952644,-133.665253,0.007825,0.001898,0.048200,84.305573,4.294731,0.482003,-133.665253,0.049042,0.000000
40.130001,19.101219,-133.754227,0.007830,0.001911,0.048539,84.966469,4.328398,0.485386,-133.754227,0.049423,0.000000
40.360001,19.246445,-133.754227,0.007838,0.001926,0.048929,85.612465,4.361307,0.489289,-133.754227,0.049813,0.000000
40.590000,19.545456,-133.709732,0.007860,0.001943,0.049354,86.942528,4.429064,0.493539,-133.709732,0.050195,0.000000
40.820004,19.961029,-133.620773,0.007869,0.001961,0.049813,88.791092,4.523233,0.498134,-133.620773,0.050577,0.000000
41.050003,19.864952,-133.709732,0.007894,0.001971,0.050065,88.363724,4.501462,0.500651,-133.709732,0.050958,0.000000
41.280003,20.211258,-133.754227,0.007907,0.001988,0.050490,89.904167,4.579937,0.504897,-133.754227,0.051340,0.000000
41.510002,20.490166,-133.798706,0.007916,0.002005,0.050915,91.144806,4.643138,0.509148,-133.798706,0.051730,0.000000
41.740002,20.571342,-133.754227,0.007933,0.002017,0.051236,91.505905,4.661533,0.512357,-133.754227,0.052112,0.000000
41.970001,20.788063,-133.709732,0.007942,0.002032,0.051609,92.469925,4.710642,0.516086,-133.709732,0.052493,0.000000
42.200001,20.867752,-133.754227,0.007955,0.002044,0.051921,92.824394,4.728701,0.519208,-133.754227,0.052875,0.000000
42.430000,21.344765,-133.798706,0.007968,0.002063,0.052389,94.946259,4.836793,0.523890,-133.798706,0.053257,0.000000
42.660004,21.557762,-133.798706,0.007981,0.002079,0.052814,95.893715,4.885059,0.528140,-133.798706,0.053647,0.000000
42.890003,21.629631,-133.754227,0.007994,0.002090,0.053091,96.213402,4.901344,0.530915,-133.754227,0.054028,0.000000
43.120003,21.521637,-133.754227,0.008002,0.002102,0.053395,95.733025,4.876873,0.533950,-133.754227,0.054410,0.000000
43.350002,22.252975,-133.798706,0.008011,0.002124,0.053942,98.986176,5.042596,0.539416,-133.798706,0.054791,0.000000
43.580002,22.609337,-133.798706,0.008045,0.002140,0.054358,100.571350,5.123349,0.543575,-133.798706,0.055173,0.000000
43.810001,22.546410,-133.843185,0.008050,0.002153,0.054687,100.291435,5.109089,0.546872,-133.843185,0.055563,0.000000
44.040001,22.630196,-133.798706,0.008067,0.002166,0.055026,100.664139,5.128076,0.550256,-133.798706,0.055945,0.000000
44.270000,22.930695,-133.798706,0.008071,0.002182,0.055424,102.000824,5.196170,0.554245,-133.798706,0.056326,0.000000
44.500004,23.295624,-133.798706,0.008080,0.002198,0.055823,103.624107,5.278864,0.558234,-133.798706,0.056708,0.000000
44.730003,23.434143,-133.887665,0.008106,0.002210,0.056136,104.240273,5.310253,0.561357,-133.887665,0.057098,0.000000
44.960003,23.272903,-133.932144,0.008106,0.002219,0.056352,103.523048,5.273715,0.563522,-133.932144,0.057480,0.000000
45.190002,24.352417,-133.843185,0.008110,0.002245,0.057029,108.324959,5.518337,0.570289,-133.843185,0.057861,0.000000
45.420002,24.619034,-133.843185,0.008140,0.002261,0.057428,109.510933,5.578753,0.574278,-133.843185,0.058243,0.000000
45.650002,24.761650,-133.887665,0.008149,0.002276,0.057809,110.145317,5.611070,0.578094,-133.887665,0.058625,0.000000
45.880001,24.854370,-133.976624,0.008170,0.002289,0.058130,110.557762,5.632081,0.581303,-133.976624,0.059015,0.000000
46.110001,24.966827,-133.932144,0.008162,0.002303,0.058494,111.057999,5.657564,0.584944,-133.932144,0.059396,0.000000
46.340004,25.315742,-133.887665,0.008201,0.002317,0.058850,112.610046,5.736629,0.588498,-133.887665,0.059778,0.000000
46.570004,25.606194,-133.887665,0.008209,0.002333,0.059249,113.902039,5.802446,0.592487,-133.887665,0.060159,0.000000
46.800003,25.755890,-133.932144,0.008218,0.002346,0.059587,114.567917,5.836368,0.595871,-133.932144,0.060541,0.000000
47.030003,26.034790,-134.021103,0.008226,0.002361,0.059969,115.808533,5.899568,0.599686,-134.021103,0.060931,0.000000
47.260002,26.618301,-133.932144,0.008235,0.002380,0.060454,118.404121,6.031794,0.604542,-133.932144,0.061313,0.000000
47.490002,26.859970,-133.932144,0.008252,0.002393,0.060793,119.479111,6.086556,0.607926,-133.932144,0.061695,0.000000
47.720001,27.253571,-133.976624,0.008261,0.002411,0.061243,121.229935,6.175747,0.612434,-133.976624,0.062076,0.000000
47.950001,27.172768,-133.887665,0.008287,0.002421,0.061486,120.870506,6.157437,0.614864,-133.887665,0.062458,0.000000
48.180004,27.599503,-133.976624,0.008287,0.002436,0.061877,122.768723,6.254137,0.618766,-133.976624,0.062848,0.000000
48.410004,27.983421,-133.976624,0.008304,0.002451,0.062267,124.476479,6.341134,0.622668,-133.976624,0.063229,0.000000
48.640003,28.168861,-133.932144,0.008313,0.002464,0.062579,125.301353,6.383155,0.625791,-133.932144,0.063611,0.000000
48.870003,28.058640,-133.976624,0.008321,0.002473,0.062813,124.811066,6.358179,0.628130,-133.976624,0.063993,0.000000
49.100002,29.064415,-134.021103,0.008338,0.002498,0.063437,129.284973,6.586091,0.634375,-134.021103,0.064374,0.000000
49.330002,29.720909,-134.021103,0.008351,0.002513,0.063836,132.205200,6.734854,0.638364,-134.021103,0.064764,0.000000
49.560001,29.703407,-133.976624,0.008364,0.002526,0.064149,132.127350,6.730888,0.641487,-133.976624,0.065146,0.000000
49.790001,30.051949,-134.021103,0.008373,0.002542,0.064556,133.677750,6.809869,0.645563,-134.021103,0.065528,0.000000
50.020004,30.233665,-133.976624,0.008395,0.002554,0.064869,134.486053,6.851047,0.648686,-133.976624,0.065909,0.000000
50.250004,30.674927,-134.021103,0.008403,0.002568,0.065224,136.448883,6.951038,0.652240,-134.021103,0.066291,0.000000
50.480003,31.402168,-134.065582,0.008420,0.002586,0.065693,139.683823,7.115833,0.656925,-134.065582,0.066681,0.000000
50.710003,31.429352,-134.021103,0.008429,0.002599,0.066013,139.804733,7.121993,0.660131,-134.021103,0.067063,0.000000
50.940002,31.949188,-134.021103,0.008446,0.002614,0.066386,142.117081,7.239789,0.663863,-134.021103,0.067444,0.000000
51.170002,32.717018,-134.065582,0.008464,0.002633,0.066889,145.532562,7.413783,0.668893,-134.065582,0.067826,0.000000
51.400002,33.265152,-134.065582,0.008464,0.002651,0.067340,147.970779,7.537991,0.673401,-134.065582,0.068207,0.000000
51.630001,33.241692,-134.110062,0.008468,0.002661,0.067600,147.866425,7.532675,0.676001,-134.110062,0.068597,0.000000
51.860001,33.695984,-134.065582,0.008485,0.002678,0.068016,149.887222,7.635619,0.680165,-134.065582,0.068979,0.000000
52.090004,34.022186,-134.065582,0.008494,0.002692,0.068381,151.338242,7.709538,0.683809,-134.065582,0.069361,0.000000
52.320004,34.512222,-134.021103,0.008507,0.002708,0.068779,153.518036,7.820581,0.687795,-134.021103,0.069742,0.000000
52.550003,34.895767,-134.065582,0.008537,0.002721,0.069118,155.224121,7.907494,0.691179,-134.065582,0.070124,0.000000
52.780003,35.180260,-134.021103,0.008528,0.002736,0.069491,156.489609,7.971961,0.694907,-134.021103,0.070514,0.000000
53.010002,36.032997,-134.065582,0.008541,0.002754,0.069942,160.282776,8.165194,0.699418,-134.065582,0.070896,0.000000
53.240002,36.725235,-134.021103,0.008563,0.002772,0.070419,163.362000,8.322057,0.704187,-134.021103,0.071277,0.000000
53.470001,36.712204,-134.065582,0.008580,0.002782,0.070653,163.304047,8.319104,0.706530,-134.065582,0.071659,0.000000
53.700001,37.206337,-134.110062,0.008580,0.002797,0.071052,165.502060,8.431076,0.710519,-134.110062,0.072049,0.000000
53.930004,37.398857,-134.154541,0.008597,0.002811,0.071390,166.358429,8.474703,0.713899,-134.154541,0.072431,0.000000
54.160004,38.279518,-134.154541,0.008610,0.002828,0.071841,170.275803,8.674262,0.718411,-134.154541,0.072812,0.000000
54.390003,38.848503,-134.154541,0.008619,0.002844,0.072240,172.806778,8.803197,0.722400,-134.154541,0.073194,0.000000
54.620003,38.977715,-134.154541,0.008627,0.002853,0.072465,173.381531,8.832477,0.724652,-134.154541,0.073575,0.000000
54.850002,39.319557,-134.154541,0.008640,0.002867,0.072812,174.902130,8.909939,0.728123,-134.154541,0.073966,0.000000
55.080002,40.181221,-134.199036,0.008653,0.002886,0.073298,178.735001,9.105195,0.732979,-134.199036,0.074347,0.000000
55.310001,40.853729,-134.154541,0.008662,0.002901,0.073679,181.726471,9.257587,0.736794,-134.154541,0.074729,0.000000
55.540001,41.469261,-134.154541,0.008666,0.002918,0.074113,184.464493,9.397069,0.741132,-134.154541,0.075110,0.000000
55.770004,41.685234,-134.154541,0.008692,0.002931,0.074443,185.425186,9.446010,0.744428,-134.154541,0.075492,0.000000
56.000004,42.335030,-134.243515,0.008696,0.002945,0.074807,188.315613,9.593255,0.748069,-134.243515,0.075882,0.000000
56.230003,43.142700,-134.199036,0.008705,0.002963,0.075266,191.908310,9.776276,0.752664,-134.199036,0.076264,0.000000
56.460003,43.417511,-134.154541,0.008714,0.002975,0.075553,193.130737,9.838549,0.755526,-134.154541,0.076645,0.000000
56.690002,44.052032,-134.154541,0.008722,0.002990,0.075943,195.953232,9.982334,0.759428,-134.154541,0.077027,0.000000
56.920002,44.723793,-134.199036,0.008735,0.003005,0.076316,198.941360,10.134556,0.763160,-134.199036,0.077409,0.000000
57.150002,45.832718,-134.154541,0.008752,0.003027,0.076880,203.874115,10.385842,0.768795,-134.154541,0.077799,0.000000
57.380001,46.160034,-134.243515,0.008765,0.003038,0.077174,205.330093,10.460013,0.771744,-134.243515,0.078180,0.000000
57.610004,46.924141,-134.154541,0.008765,0.003055,0.077599,208.729004,10.633162,0.775994,-134.154541,0.078562,0.000000
57.840004,47.343811,-134.199036,0.008778,0.003069,0.077964,210.595795,10.728261,0.779635,-134.199036,0.078943,0.000000
58.070004,48.434113,-134.199036,0.008795,0.003088,0.078432,215.445694,10.975327,0.784317,-134.199036,0.079325,0.000000
58.300003,48.894363,-134.243515,0.008791,0.003100,0.078753,217.492996,11.079621,0.787527,-134.243515,0.079716,0.000000
58.530003,48.962135,-134.243515,0.008804,0.003109,0.078978,217.794449,11.094978,0.789783,-134.243515,0.080097,0.000000
58.760002,49.433563,-134.243515,0.008813,0.003127,0.079438,219.891464,11.201806,0.794378,-134.243515,0.080479,0.000000
58.990002,51.213875,-134.243515,0.008830,0.003149,0.079993,227.810699,11.605229,0.799930,-134.243515,0.080860,0.000000
59.220001,51.923615,-134.287994,0.008843,0.003164,0.080357,230.967773,11.766059,0.803571,-134.287994,0.081242,0.000000
59.450005,52.261360,-134.287994,0.008856,0.003176,0.080661,232.470139,11.842594,0.806607,-134.287994,0.081632,0.000000
59.680004,53.158035,-134.199036,0.008860,0.003195,0.081155,236.458755,12.045783,0.811550,-134.199036,0.082013,0.000000
59.910004,54.325050,-134.243515,0.008852,0.003213,0.081606,241.649887,12.310232,0.816061,-134.243515,0.082395,0.000000
60.140003,54.685501,-134.287994,0.008869,0.003224,0.081892,243.253265,12.391912,0.818923,-134.287994,0.082777,0.000000
60.370003,55.129372,-134.332474,0.008895,0.003235,0.082161,245.227692,12.492494,0.821610,-134.332474,0.083158,0.000000
60.600002,56.544388,-134.287994,0.008903,0.003258,0.082759,251.522003,12.813142,0.827594,-134.287994,0.083549,0.000000
60.830002,57.487610,-134.332474,0.008903,0.003275,0.083176,255.717667,13.026878,0.831757,-134.332474,0.083930,0.000000
61.060001,57.705818,-134.332474,0.008925,0.003284,0.083410,256.688293,13.076325,0.834096,-134.332474,0.084312,0.000000
61.290005,58.259537,-134.287994,0.008925,0.003300,0.083809,259.151367,13.201800,0.838086,-134.287994,0.084693,0.000000
61.520004,59.315582,-134.332474,0.008942,0.003318,0.084268,263.848877,13.441104,0.842684,-134.332474,0.085075,0.000000
61.750004,60.064796,-134.332474,0.008929,0.003331,0.084615,267.181549,13.610877,0.846151,-134.332474,0.085465,0.000000
61.980003,60.725014,-134.332474,0.008942,0.003344,0.084945,270.118347,13.760485,0.849448,-134.332474,0.085847,0.000000
62.210003,61.892403,-134.332474,0.008964,0.003361,0.085379,275.311157,14.025019,0.853785,-134.332474,0.086228,0.000000
62.440002,62.141891,-134.287994,0.008968,0.003371,0.085612,276.420929,14.081553,0.856124,-134.287994,0.086610,0.000000
62.670002,63.202400,-134.376953,0.008985,0.003388,0.086064,281.138306,14.321869,0.860636,-134.376953,0.087000,0.000000
62.900002,64.169090,-134.376953,0.008990,0.003405,0.086480,285.438354,14.540924,0.864799,-134.376953,0.087381,0.000000
63.130005,64.761528,-134.376953,0.008985,0.003418,0.086809,288.073669,14.675172,0.868092,-134.376953,0.087763,0.000000
63.360004,65.765450,-134.376953,0.008994,0.003434,0.087217,292.539337,14.902664,0.872168,-134.376953,0.088145,0.000000
63.590004,66.301292,-134.376953,0.008998,0.003446,0.087538,294.922882,15.024087,0.875378,-134.376953,0.088526,0.000000
63.820004,67.254936,-134.376953,0.009011,0.003453,0.087694,299.164886,15.240186,0.876937,-134.376953,0.087911,0.000000
64.050003,66.461037,-134.421432,0.009024,0.003453,0.087694,295.633453,15.060287,0.876937,-134.421432,0.087911,0.000000
64.280006,65.811623,-134.421432,0.009024,0.003450,0.087633,292.744720,14.913127,0.876332,-134.421432,0.087694,0.000000
64.510002,65.190498,-134.421432,0.009037,0.003449,0.087598,289.981812,14.772378,0.875984,-134.421432,0.087694,0.000000
64.740005,64.618904,-134.376953,0.009033,0.003448,0.087581,287.439240,14.642853,0.875810,-134.376953,0.087694,0.000000
64.970001,64.101692,-134.465912,0.009046,0.003448,0.087573,285.138580,14.525651,0.875726,-134.465912,0.087694,0.000000
65.200005,63.603447,-134.465912,0.009037,0.003448,0.087573,282.922272,14.412747,0.875726,-134.465912,0.087694,0.000000
65.430000,63.156609,-134.421432,0.009050,0.003447,0.087564,280.934631,14.311492,0.875639,-134.421432,0.087694,0.000000
65.660004,62.762634,-134.421432,0.009046,0.003447,0.087564,279.182129,14.222217,0.875639,-134.421432,0.087694,0.000000
65.889999,62.392494,-134.421432,0.009054,0.003447,0.087564,277.535675,14.138341,0.875639,-134.421432,0.087694,0.000000
66.120003,62.025711,-134.465912,0.009058,0.003447,0.087555,275.904144,14.055227,0.875552,-134.465912,0.087694,0.000000
66.350006,61.693184,-134.510391,0.009041,0.003447,0.087555,274.424988,13.979876,0.875552,-134.510391,0.087694,0.000000
66.580002,61.383369,-134.510391,0.009067,0.003447,0.087555,273.046875,13.909670,0.875552,-134.510391,0.087694,0.000000
66.810005,61.099243,-134.510391,0.009067,0.003447,0.087555,271.783020,13.845286,0.875552,-134.510391,0.087694,0.000000
67.040001,60.832253,-134.510391,0.009076,0.003447,0.087555,270.595367,13.784785,0.875552,-134.510391,0.087694,0.000000
67.270004,60.558937,-134.510391,0.009076,0.003447,0.087555,269.379608,13.722851,0.875552,-134.510391,0.087694,0.000000
67.500000,60.303856,-134.554871,0.009063,0.003447,0.087555,268.244934,13.665049,0.875552,-134.554871,0.087694,0.000000
67.730003,60.078575,-134.465912,0.009067,0.003447,0.087555,267.242859,13.614000,0.875552,-134.465912,0.087694,0.000000
67.960007,59.862968,-134.465912,0.009080,0.003447,0.087555,266.283783,13.565143,0.875552,-134.465912,0.087694,0.000000
68.190002,59.651459,-134.510391,0.009076,0.003447,0.087555,265.342926,13.517213,0.875552,-134.510391,0.087694,0.000000
68.420006,59.455597,-134.599365,0.009080,0.003447,0.087555,264.471710,13.472831,0.875552,-134.599365,0.087694,0.000000
68.650002,59.261963,-134.554871,0.009071,0.003447,0.087555,263.610382,13.428953,0.875552,-134.554871,0.087694,0.000000
68.880005,59.085083,-134.554871,0.009080,0.003447,0.087547,262.823578,13.388871,0.875465,-134.554871,0.087694,0.000000
69.110001,58.920868,-134.510391,0.009076,0.003447,0.087547,262.093109,13.351660,0.875465,-134.510391,0.087694,0.000000
69.340004,58.757767,-134.510391,0.009076,0.003447,0.087547,261.367615,13.314700,0.875465,-134.510391,0.087694,0.000000
69.570000,58.584991,-134.554871,0.009080,0.003447,0.087547,260.599060,13.275549,0.875465,-134.554871,0.087694,0.000000
69.800003,58.422264,-134.554871,0.009076,0.003447,0.087547,259.875214,13.238674,0.875465,-134.554871,0.087694,0.000000
70.030006,58.280388,-134.599365,0.009089,0.003447,0.087547,259.244110,13.206525,0.875465,-134.599365,0.087694,0.000000
70.260002,58.149681,-134.554871,0.009093,0.003447,0.087547,258.662689,13.176907,0.875465,-134.554871,0.087694,0.000000
70.490005,58.010788,-134.599365,0.009071,0.003447,0.087547,258.044861,13.145432,0.875465,-134.599365,0.087694,0.000000
70.720001,57.871521,-134.599365,0.009084,0.003447,0.087547,257.425385,13.113873,0.875465,-134.599365,0.087694,0.000000
70.950005,57.727783,-134.599365,0.009089,0.003447,0.087547,256.786011,13.081303,0.875465,-134.599365,0.087694,0.000000
71.180000,57.623894,-134.599365,0.009089,0.003447,0.087547,256.323883,13.057761,0.875465,-134.599365,0.087694,0.000000
71.410004,57.501381,-134.599365,0.009102,0.003447,0.087547,255.778915,13.030000,0.875465,-134.599365,0.087694,0.000000
71.640007,57.385948,-134.643845,0.009102,0.003447,0.087547,255.265442,13.003841,0.875465,-134.643845,0.087694,0.000000
71.870003,57.276840,-134.599365,0.009084,0.003447,0.087547,254.780106,12.979117,0.875465,-134.599365,0.087694,0.000000
72.100006,57.165131,-134.599365,0.009093,0.003447,0.087547,254.283203,12.953803,0.875465,-134.599365,0.087694,0.000000
72.330002,57.052299,-134.599365,0.009084,0.003447,0.087547,253.781296,12.928236,0.875465,-134.599365,0.087694,0.000000
72.560005,56.962936,-134.643845,0.009093,0.003447,0.087547,253.383789,12.907986,0.875465,-134.643845,0.087694,0.000000
72.790001,56.863136,-134.688324,0.009093,0.003447,0.087547,252.939865,12.885371,0.875465,-134.688324,0.087694,0.000000
73.020004,56.760361,-134.688324,0.009093,0.003447,0.087547,252.482697,12.862082,0.875465,-134.688324,0.087694,0.000000
73.250000,56.657219,-134.688324,0.009097,0.003447,0.087547,252.023895,12.838709,0.875465,-134.688324,0.087694,0.000000
73.480003,56.580505,-134.599365,0.009097,0.003447,0.087547,251.682663,12.821325,0.875465,-134.599365,0.087694,0.000000
73.710007,56.495232,-134.732803,0.009097,0.003447,0.087547,251.303345,12.802002,0.875465,-134.732803,0.087694,0.000000
73.940002,56.396927,-134.688324,0.009106,0.003447,0.087547,250.866058,12.779727,0.875465,-134.688324,0.087694,0.000000
74.170006,56.303459,-134.732803,0.009102,0.003447,0.087547,250.450302,12.758546,0.875465,-134.732803,0.087694,0.000000
74.400002,56.232338,-134.688324,0.009097,0.003447,0.087547,250.133926,12.742430,0.875465,-134.688324,0.087694,0.000000
74.630005,56.172012,-134.688324,0.009089,0.003447,0.087547,249.865585,12.728760,0.875465,-134.688324,0.087694,0.000000
74.860001,56.081154,-134.688324,0.009102,0.003447,0.087547,249.461426,12.708172,0.875465,-134.688324,0.087694,0.000000
75.090004,55.994766,-134.688324,0.009115,0.003447,0.087547,249.077164,12.688596,0.875465,-134.688324,0.087694,0.000000
75.320007,55.913963,-134.732803,0.009106,0.003447,0.087547,248.717728,12.670285,0.875465,-134.732803,0.087694,0.000000
75.550003,55.851776,-134.732803,0.009093,0.003447,0.087547,248.441101,12.656193,0.875465,-134.732803,0.087694,0.000000
75.780006,55.779533,-134.688324,0.009106,0.003447,0.087547,248.119751,12.639823,0.875465,-134.688324,0.087694,0.000000
76.010002,55.721069,-134.732803,0.009097,0.003447,0.087547,247.859695,12.626575,0.875465,-134.732803,0.087694,0.000000
76.240005,55.633934,-134.777283,0.009110,0.003447,0.087547,247.472092,12.606831,0.875465,-134.777283,0.087694,0.000000
76.470001,55.573608,-134.777283,0.009093,0.003447,0.087547,247.203751,12.593160,0.875465,-134.777283,0.087694,0.000000
76.700005,55.515892,-134.688324,0.009093,0.003447,0.087547,246.947021,12.580081,0.875465,-134.688324,0.087694,0.000000
76.930000,55.454453,-134.732803,0.009110,0.003447,0.087547,246.673721,12.566159,0.875465,-134.732803,0.087694,0.000000
77.160004,55.387428,-134.732803,0.009119,0.003447,0.087547,246.375580,12.550970,0.875465,-134.732803,0.087694,0.000000
77.390007,55.323006,-134.777283,0.009102,0.003447,0.087547,246.089020,12.536372,0.875465,-134.777283,0.087694,0.000000
77.620003,55.270874,-134.821762,0.009102,0.003447,0.087547,245.857132,12.524559,0.875465,-134.821762,0.087694,0.000000
77.850006,55.202728,-134.732803,0.009093,0.003447,0.087547,245.554001,12.509117,0.875465,-134.732803,0.087694,0.000000
78.080002,55.147987,-134.777283,0.009093,0.003447,0.087547,245.310501,12.496713,0.875465,-134.777283,0.087694,0.000000
78.310005,55.092880,-134.821762,0.009115,0.003447,0.087547,245.065369,12.484225,0.875465,-134.821762,0.087694,0.000000
78.540001,55.026222,-134.821762,0.009097,0.003447,0.087547,244.768860,12.469121,0.875465,-134.821762,0.087694,0.000000
78.770004,54.961807,-134.777283,0.009106,0.003447,0.087547,244.482330,12.454523,0.875465,-134.777283,0.087694,0.000000
79.000000,54.925308,-134.821762,0.009115,0.003447,0.087547,244.319977,12.446253,0.875465,-134.821762,0.087694,0.000000
79.230003,54.866478,-134.821762,0.009115,0.003447,0.087547,244.058289,12.432921,0.875465,-134.821762,0.087694,0.000000
79.460007,54.806900,-134.821762,0.009123,0.003447,0.087547,243.793274,12.419420,0.875465,-134.821762,0.087694,0.000000
79.690002,54.758858,-134.910721,0.009115,0.003447,0.087547,243.579559,12.408535,0.875465,-134.910721,0.087694,0.000000
79.920006,54.711197,-134.910721,0.009110,0.003447,0.087547,243.367554,12.397735,0.875465,-134.910721,0.087694,0.000000
80.150002,54.658691,-134.866241,0.009106,0.003447,0.087547,243.134003,12.385836,0.875465,-134.866241,0.087694,0.000000
80.380005,54.603210,-134.821762,0.009110,0.003447,0.087547,242.887207,12.373264,0.875465,-134.821762,0.087694,0.000000
80.610001,54.557777,-134.866241,0.009119,0.003447,0.087547,242.685120,12.362969,0.875465,-134.866241,0.087694,0.000000
80.840004,54.498199,-134.910721,0.009119,0.003447,0.087547,242.420105,12.349469,0.875465,-134.910721,0.087694,0.000000
81.070007,54.466919,-134.999680,0.009102,0.003447,0.087547,242.280960,12.342381,0.875465,-134.999680,0.087694,0.000000
81.300003,54.418510,-134.821762,0.009106,0.003447,0.087547,242.065628,12.331411,0.875465,-134.821762,0.087694,0.000000
81.530006,54.371590,-134.866241,0.009110,0.003447,0.087547,241.856903,12.320779,0.875465,-134.866241,0.087694,0.000000
81.760002,54.316856,-134.866241,0.009119,0.003447,0.087547,241.613449,12.308375,0.875465,-134.866241,0.087694,0.000000
81.990005,54.278503,-134.955200,0.009115,0.003447,0.087547,241.442841,12.299685,0.875465,-134.955200,0.087694,0.000000
82.220001,54.244614,-134.955200,0.009106,0.003447,0.087547,241.292099,12.292006,0.875465,-134.955200,0.087694,0.000000
82.450005,54.191734,-134.866241,0.009106,0.003447,0.087547,241.056870,12.280023,0.875465,-134.866241,0.087694,0.000000
82.680000,54.147797,-134.866241,0.009127,0.003447,0.087547,240.861435,12.270066,0.875465,-134.866241,0.087694,0.000000
82.910004,54.112419,-134.999680,0.009106,0.003447,0.087547,240.704056,12.262050,0.875465,-134.999680,0.087694,0.000000
83.140007,54.050980,-134.955200,0.009119,0.003447,0.087547,240.430771,12.248128,0.875465,-134.955200,0.087694,0.000000
83.370003,54.027145,-134.910721,0.009106,0.003447,0.087547,240.324753,12.242726,0.875465,-134.910721,0.087694,0.000000
83.600006,54.000710,-134.910721,0.009097,0.003447,0.087547,240.207153,12.236736,0.875465,-134.910721,0.087694,0.000000
83.830002,53.953049,-134.955200,0.009123,0.003447,0.087547,239.995148,12.225935,0.875465,-134.955200,0.087694,0.000000
84.060005,53.913948,-134.955200,0.009115,0.003447,0.087547,239.821213,12.217075,0.875465,-134.955200,0.087694,0.000000
84.290001,53.875969,-134.999680,0.009110,0.003447,0.087547,239.652283,12.208469,0.875465,-134.999680,0.087694,0.000000
84.520004,53.839104,-134.955200,0.009123,0.003447,0.087547,239.488297,12.200115,0.875465,-134.955200,0.087694,0.000000
84.750008,53.810059,-134.955200,0.009110,0.003447,0.087547,239.359100,12.193534,0.875465,-134.955200,0.087694,0.000000
84.980003,53.776917,-134.999680,0.009115,0.003447,0.087547,239.211670,12.186024,0.875465,-134.999680,0.087694,0.000000
85.210007,53.737816,-134.999680,0.009119,0.003447,0.087547,239.037750,12.177163,0.875465,-134.999680,0.087694,0.000000
85.440002,53.699089,-135.044174,0.009115,0.003447,0.087547,238.865479,12.168387,0.875465,-135.044174,0.087694,0.000000
85.670006,53.668182,-134.999680,0.009115,0.003447,0.087547,238.727997,12.161385,0.875465,-134.999680,0.087694,0.000000
85.900002,53.645096,-134.999680,0.009119,0.003447,0.087547,238.625305,12.156152,0.875465,-134.999680,0.087694,0.000000
86.130005,53.598923,-135.044174,0.009123,0.003447,0.087547,238.419922,12.145689,0.875465,-135.044174,0.087694,0.000000
86.360001,53.553864,-134.999680,0.009110,0.003447,0.087547,238.219482,12.135479,0.875465,-134.999680,0.087694,0.000000
86.590004,53.528915,-135.044174,0.009115,0.003447,0.087547,238.108505,12.129826,0.875465,-135.044174,0.087694,0.000000
86.820007,53.507317,-135.044174,0.009115,0.003447,0.087547,238.012436,12.124931,0.875465,-135.044174,0.087694,0.000000
87.050003,53.470451,-135.044174,0.009119,0.003447,0.087547,237.848450,12.116578,0.875465,-135.044174,0.087694,0.000000
87.280006,53.428001,-135.044174,0.009115,0.003447,0.087547,237.659622,12.106958,0.875465,-135.044174,0.087694,0.000000
87.510002,53.407150,-135.088654,0.009123,0.003447,0.087547,237.566864,12.102233,0.875465,-135.088654,0.087694,0.000000
87.740005,53.368423,-135.088654,0.009119,0.003447,0.087547,237.394608,12.093457,0.875465,-135.088654,0.087694,0.000000
87.970001,53.349800,-135.088654,0.009127,0.003447,0.087547,237.311768,12.089237,0.875465,-135.088654,0.087694,0.000000
88.200005,53.332298,-135.044174,0.009115,0.003447,0.087547,237.233917,12.085272,0.875465,-135.044174,0.087694,0.000000
88.430008,53.286499,-135.044174,0.009119,0.003447,0.087547,237.030182,12.074893,0.875465,-135.044174,0.087694,0.000000
88.660004,53.252243,-135.088654,0.009115,0.003447,0.087547,236.877808,12.067131,0.875465,-135.088654,0.087694,0.000000
88.890007,53.223198,-135.133133,0.009123,0.003447,0.087547,236.748611,12.060550,0.875465,-135.133133,0.087694,0.000000
89.120003,53.208305,-135.088654,0.009115,0.003447,0.087547,236.682358,12.057174,0.875465,-135.088654,0.087694,0.000000
89.350006,53.185585,-135.088654,0.009119,0.003447,0.087547,236.581299,12.052026,0.875465,-135.088654,0.087694,0.000000
89.580002,53.148720,-135.088654,0.009115,0.003447,0.087547,236.417313,12.043672,0.875465,-135.088654,0.087694,0.000000
89.810005,53.111488,-135.133133,0.009123,0.003447,0.087547,236.251694,12.035235,0.875465,-135.133133,0.087694,0.000000
90.040001,53.093987,-135.133133,0.009123,0.003447,0.087547,236.173843,12.031270,0.875465,-135.133133,0.087694,0.000000
90.270004,53.065681,-135.133133,0.009115,0.003447,0.087547,236.047943,12.024855,0.875465,-135.133133,0.087694,0.000000
90.500008,53.043716,-135.133133,0.009119,0.003447,0.087547,235.950241,12.019878,0.875465,-135.133133,0.087694,0.000000
90.730003,53.032539,-135.177612,0.009115,0.003447,0.087547,235.900513,12.017345,0.875465,-135.177612,0.087694,0.000000
90.960007,52.992699,-135.177612,0.009115,0.003447,0.087547,235.723297,12.008318,0.875465,-135.177612,0.087694,0.000000
91.190002,52.967751,-135.222092,0.009115,0.003447,0.087547,235.612320,12.002664,0.875465,-135.222092,0.087694,0.000000
91.420006,52.936470,-135.177612,0.009106,0.003447,0.087547,235.473175,11.995575,0.875465,-135.177612,0.087694,0.000000
91.650002,52.915619,-135.177612,0.009115,0.003447,0.087547,235.380432,11.990850,0.875465,-135.177612,0.087694,0.000000
91.880005,52.896629,-135.266571,0.009127,0.003447,0.087547,235.295959,11.986547,0.875465,-135.266571,0.087694,0.000000
92.110001,52.855293,-135.222092,0.009123,0.003447,0.087547,235.112091,11.977180,0.875465,-135.222092,0.087694,0.000000
92.340004,52.836304,-135.222092,0.009119,0.003447,0.087547,235.027618,11.972878,0.875465,-135.222092,0.087694,0.000000
92.570007,52.809494,-135.266571,0.009119,0.003447,0.087547,234.908356,11.966802,0.875465,-135.266571,0.087694,0.000000
92.800003,52.790131,-135.222092,0.009127,0.003447,0.087547,234.822235,11.962415,0.875465,-135.222092,0.087694,0.000000
93.030006,52.764061,-135.177612,0.009132,0.003447,0.087547,234.706268,11.956507,0.875465,-135.177612,0.087694,0.000000
93.260002,52.756241,-135.311050,0.009119,0.003447,0.087547,234.671478,11.954735,0.875465,-135.311050,0.087694,0.000000
93.490005,52.736877,-135.222092,0.009136,0.003447,0.087547,234.585342,11.950347,0.875465,-135.222092,0.087694,0.000000
93.720001,52.686234,-135.222092,0.009127,0.003447,0.087547,234.360077,11.938871,0.875465,-135.222092,0.087694,0.000000
93.950005,52.659424,-135.222092,0.009127,0.003447,0.087547,234.240814,11.932796,0.875465,-135.222092,0.087694,0.000000
94.180008,52.651978,-135.222092,0.009132,0.003447,0.087547,234.207687,11.931108,0.875465,-135.222092,0.087694,0.000000
94.200005,52.647881,-135.222092,0.009119,0.003447,0.087547,234.189468,11.930181,0.875465,-135.222092,0.087694,0.000000