File: Data/PDMS compression/PDMS 0017 Punched_1_07152024_151912.csv
Time (sec),S:Load (lbs),S:HL1 (DIM),S:LVDT (in),S:Position (in),Ch:Position (mm),Ch:Load (N),Ch:Stress (MPa),Ch:Strain (mm/mm),Ch:HL1 (DIM),Set Point (),Cycles ()
0.110000,0.002235,-154.704742,0.000026,-0.000000,-0.000000,0.009944,0.000507,-0.000000,-154.704742,0.000208,0.000000
0.860000,-0.003357,-154.838196,0.000026,0.000130,0.003295,-0.014932,-0.000761,0.032954,-154.838196,0.004189,0.000000
1.610000,-0.039848,-154.882675,0.000224,0.000365,0.009271,-0.177254,-0.009030,0.092706,-154.882675,0.010433,0.000000
2.360000,-0.053253,-154.927155,0.000470,0.000615,0.015627,-0.236882,-0.012067,0.156274,-154.927155,0.016685,0.000000
3.110000,-0.003723,-155.060593,0.000763,0.000859,0.021828,-0.016561,-0.000844,0.218281,-155.060593,0.022929,0.000000
3.860000,-0.008194,-155.060593,0.001035,0.001107,0.028115,-0.036449,-0.001857,0.281155,-155.060593,0.029173,0.000000
4.610000,0.011169,-155.149551,0.001276,0.001355,0.034420,0.049684,0.002531,0.344202,-155.149551,0.035426,0.000000
5.360000,0.002235,-155.283005,0.001548,0.001605,0.040760,0.009944,0.000507,0.407596,-155.283005,0.041670,0.000000
6.110000,-0.026070,-155.283005,0.001794,0.001856,0.047134,-0.115964,-0.005907,0.471337,-155.283005,0.047914,0.000000
6.860000,0.017502,-155.371964,0.002061,0.002097,0.053274,0.077852,0.003966,0.532737,-155.371964,0.054167,0.000000
7.610000,0.035370,-155.371964,0.002311,0.002331,0.059214,0.157333,0.008015,0.592142,-155.371964,0.060411,0.000000
8.360001,0.021965,-155.594360,0.002557,0.002580,0.065528,0.097705,0.004977,0.655276,-155.594360,0.066664,0.000000
9.110001,0.015640,-155.505402,0.002837,0.002829,0.071850,0.069571,0.003544,0.718496,-155.505402,0.072908,0.000000
9.860001,-0.000748,-155.638855,0.003070,0.003078,0.078189,-0.003326,-0.000169,0.781891,-155.638855,0.079152,0.000000
10.610001,-0.004097,-155.727814,0.003311,0.003321,0.084364,-0.018224,-0.000928,0.843637,-155.727814,0.085404,0.000000
11.360001,0.032394,-155.816772,0.003570,0.003573,0.090746,0.144098,0.007341,0.907465,-155.816772,0.091648,0.000000
12.110001,0.008186,-155.861252,0.003846,0.003814,0.096886,0.036415,0.001855,0.968865,-155.861252,0.097901,0.000000
12.860001,0.032021,-155.905731,0.004126,0.004065,0.103261,0.142435,0.007256,1.032605,-155.905731,0.104145,0.000000
13.610001,-0.007446,-155.950211,0.004363,0.004303,0.109288,-0.033123,-0.001687,1.092878,-155.950211,0.110389,0.000000
14.360001,-0.026810,-156.083664,0.004618,0.004552,0.115610,-0.119255,-0.006075,1.156098,-156.083664,0.116642,0.000000
15.110001,0.021965,-156.128143,0.004889,0.004799,0.121889,0.097705,0.004977,1.218886,-156.128143,0.122886,0.000000
15.860001,0.268478,-156.217102,0.005135,0.005042,0.128072,1.194252,0.060838,1.280719,-156.217102,0.129139,0.000000
16.610001,0.394714,-156.261581,0.005238,-0.000001,-0.000026,1.755777,0.089444,-0.000260,-156.261581,0.000130,0.000000
17.360001,0.401413,-156.395020,0.005230,-0.000001,-0.000017,1.785574,0.090961,-0.000173,-156.395020,0.001205,0.000000
18.110001,0.507912,-156.395020,0.005299,0.000060,0.001535,2.259304,0.115094,0.015350,-156.395020,0.002463,0.000000
18.860001,0.600266,-156.572952,0.005342,0.000103,0.002619,2.670114,0.136022,0.026190,-156.572952,0.003712,0.000000
19.610001,0.685165,-156.528473,0.005402,0.000158,0.004024,3.047768,0.155261,0.040239,-156.528473,0.004961,0.000000
20.360001,0.806931,-156.617432,0.005450,0.000212,0.005394,3.589406,0.182853,0.053941,-156.617432,0.006209,0.000000
21.110001,0.924973,-156.706390,0.005519,0.000258,0.006548,4.114483,0.209602,0.065476,-156.706390,0.007458,0.000000
21.860001,0.986412,-156.795349,0.005536,0.000305,0.007744,4.387780,0.223524,0.077443,-156.795349,0.008707,0.000000
22.610001,1.118980,-156.795349,0.005614,0.000355,0.009019,4.977473,0.253565,0.090191,-156.795349,0.009956,0.000000
23.360001,1.188614,-156.928802,0.005652,0.000405,0.010277,5.287219,0.269344,0.102766,-156.928802,0.011213,0.000000
24.110001,1.330482,-156.928802,0.005713,0.000456,0.011595,5.918282,0.301492,0.115948,-156.928802,0.012462,0.000000
24.860001,1.403839,-157.062241,0.005743,0.000497,0.012618,6.244588,0.318114,0.126181,-157.062241,0.013711,0.000000
25.610001,1.530075,-157.106720,0.005795,0.000551,0.013988,6.806114,0.346720,0.139884,-157.106720,0.014960,0.000000
26.360001,1.642159,-157.195679,0.005846,0.000597,0.015159,7.304686,0.372118,0.151591,-157.195679,0.016208,0.000000
27.110001,1.810097,-157.284637,0.005902,0.000655,0.016633,8.051712,0.410174,0.166334,-157.284637,0.017457,0.000000
27.860001,1.902824,-157.373611,0.005963,0.000699,0.017761,8.464186,0.431186,0.177608,-157.373611,0.018706,0.000000
28.610001,2.026817,-157.418091,0.006002,0.000753,0.019114,9.015734,0.459283,0.191137,-157.418091,0.019964,0.000000
29.360001,2.115074,-157.462570,0.006058,0.000801,0.020345,9.408319,0.479283,0.203451,-157.462570,0.021212,0.000000
30.110001,2.265137,-157.551529,0.006127,0.000847,0.021525,10.075831,0.513287,0.215245,-157.551529,0.022461,0.000000
30.860001,2.444626,-157.684967,0.006165,0.000905,0.022981,10.874239,0.553960,0.229815,-157.684967,0.023710,0.000000
31.610001,2.477020,-157.640488,0.006187,0.000943,0.023961,11.018336,0.561301,0.239614,-157.640488,0.024959,0.000000
32.360001,2.637886,-157.729446,0.006256,0.000990,0.025141,11.733903,0.597753,0.251409,-157.729446,0.026208,0.000000
33.110001,2.773804,-157.862900,0.006316,0.001044,0.026520,12.338495,0.628553,0.265198,-157.862900,0.027456,0.000000
33.860001,3.027016,-157.862900,0.006368,0.001099,0.027916,13.464838,0.685932,0.279160,-157.862900,0.028714,0.000000
34.610001,3.109680,-157.951859,0.006416,0.001148,0.029156,13.832548,0.704664,0.291561,-157.951859,0.029963,0.000000
35.360001,3.198303,-157.996338,0.006450,0.001191,0.030249,14.226764,0.724746,0.302488,-157.996338,0.031211,0.000000
36.110001,3.349113,-158.085297,0.006510,0.001241,0.031524,14.897601,0.758920,0.315237,-158.085297,0.032460,0.000000
36.860001,3.545357,-158.218750,0.006592,0.001293,0.032851,15.770535,0.803389,0.328505,-158.218750,0.033709,0.000000
37.610001,3.551315,-158.307709,0.006627,0.001337,0.033952,15.797039,0.804740,0.339519,-158.307709,0.034958,0.000000
38.360001,3.731911,-158.352188,0.006661,0.001379,0.035019,16.600368,0.845663,0.350186,-158.352188,0.036215,0.000000
39.110001,3.873047,-158.396667,0.006713,0.001439,0.036554,17.228172,0.877645,0.365536,-158.396667,0.037464,0.000000
39.860001,4.027206,-158.441147,0.006769,0.001487,0.037768,17.913908,0.912578,0.377677,-158.441147,0.038713,0.000000
40.610001,4.250626,-158.485626,0.006817,0.001541,0.039129,18.907726,0.963206,0.391292,-158.485626,0.039962,0.000000
41.360001,4.240204,-158.574585,0.006855,0.001584,0.040239,18.861368,0.960844,0.402393,-158.574585,0.041211,0.000000
42.110001,4.360107,-158.663559,0.006894,0.001629,0.041367,19.394726,0.988014,0.413667,-158.663559,0.042459,0.000000
42.860001,4.485970,-158.708038,0.006950,0.001682,0.042720,19.954590,1.016535,0.427195,-158.708038,0.043708,0.000000
43.610001,4.684441,-158.796997,0.007036,0.001738,0.044133,20.837433,1.061509,0.441331,-158.796997,0.044966,0.000000
44.360001,4.785355,-158.885956,0.007071,0.001787,0.045399,21.286320,1.084377,0.453993,-158.885956,0.046214,0.000000
45.110001,4.818871,-158.974915,0.007097,0.001830,0.046483,21.435408,1.091972,0.464833,-158.974915,0.047463,0.000000
45.860001,4.901161,-159.019394,0.007157,0.001877,0.047680,21.801455,1.110619,0.476801,-159.019394,0.048712,0.000000
46.610001,5.121239,-159.108368,0.007209,0.001933,0.049102,22.780407,1.160489,0.491023,-159.108368,0.049961,0.000000
47.360001,5.121605,-159.197327,0.007261,0.001971,0.050074,22.782036,1.160572,0.500736,-159.197327,0.051210,0.000000
48.110001,5.352478,-159.241806,0.007304,0.002026,0.051470,23.809011,1.212889,0.514699,-159.241806,0.052458,0.000000
48.860001,5.319336,-159.286285,0.007377,0.002075,0.052710,23.661589,1.205379,0.527100,-159.286285,0.053716,0.000000
49.610001,5.556915,-159.375244,0.007437,0.002131,0.054115,24.718393,1.259215,0.541149,-159.375244,0.054965,0.000000
50.360001,5.651497,-159.464203,0.007468,0.002181,0.055407,25.139114,1.280648,0.554071,-159.464203,0.056214,0.000000
51.110001,5.762093,-159.508698,0.007511,0.002227,0.056578,25.631067,1.305709,0.565778,-159.508698,0.057462,0.000000
51.860001,5.872681,-159.553177,0.007571,0.002273,0.057731,26.122988,1.330768,0.577312,-159.553177,0.058711,0.000000
52.610001,5.781082,-159.642136,0.007623,0.002319,0.058902,25.715538,1.310012,0.589020,-159.642136,0.059960,0.000000
53.360004,6.042854,-159.731094,0.007666,0.002372,0.060246,26.879959,1.369330,0.602462,-159.731094,0.061209,0.000000
54.110004,6.152710,-159.820053,0.007748,0.002430,0.061729,27.368620,1.394224,0.617291,-159.820053,0.062466,0.000000
54.860004,6.073395,-159.864532,0.007787,0.002466,0.062631,27.015810,1.376251,0.626310,-159.864532,0.063715,0.000000
55.610004,6.272614,-159.909012,0.007834,0.002520,0.064001,27.901978,1.421395,0.640013,-159.909012,0.064964,0.000000
56.360004,6.277824,-159.997986,0.007886,0.002565,0.065163,27.925158,1.422575,0.651633,-159.997986,0.066213,0.000000
57.110004,6.538483,-160.086945,0.007946,0.002624,0.066655,29.084623,1.481641,0.666550,-160.086945,0.067461,0.000000
57.860004,6.557846,-160.131424,0.008002,0.002669,0.067782,29.170755,1.486029,0.677824,-160.131424,0.068710,0.000000
58.610004,6.593971,-160.175903,0.008019,0.002715,0.068970,29.331450,1.494215,0.689705,-160.175903,0.069968,0.000000
59.360004,6.700836,-160.264862,0.008071,0.002765,0.070219,29.806808,1.518431,0.702193,-160.264862,0.071217,0.000000
60.110004,6.837875,-160.353836,0.008140,0.002821,0.071650,30.416389,1.549485,0.716502,-160.353836,0.072465,0.000000
60.860004,6.872879,-160.442795,0.008183,0.002866,0.072804,30.572092,1.557417,0.728036,-160.442795,0.073714,0.000000
61.610004,6.997993,-160.531754,0.008239,0.002912,0.073957,31.128630,1.585768,0.739570,-160.531754,0.074963,0.000000
62.360004,7.014374,-160.576233,0.008291,0.002964,0.075293,31.201492,1.589480,0.752925,-160.576233,0.076212,0.000000
63.110004,7.000229,-160.665192,0.008360,0.003012,0.076507,31.138573,1.586275,0.765067,-160.665192,0.077461,0.000000
63.860004,7.247108,-160.709671,0.008395,0.003066,0.077877,32.236748,1.642218,0.778769,-160.709671,0.078718,0.000000
64.610001,7.298874,-160.843124,0.008446,0.003115,0.079117,32.467014,1.653949,0.791170,-160.843124,0.079967,0.000000
65.360001,7.267220,-160.843124,0.008494,0.003161,0.080279,32.326206,1.646775,0.802791,-160.843124,0.081216,0.000000
66.110001,7.265358,-160.932083,0.008554,0.003208,0.081493,32.317924,1.646354,0.814932,-160.932083,0.082464,0.000000
66.860001,7.367760,-161.021042,0.008580,0.003259,0.082785,32.773434,1.669558,0.827854,-161.021042,0.083713,0.000000
67.610001,7.594162,-161.065521,0.008653,0.003312,0.084130,33.780521,1.720862,0.841296,-161.065521,0.084962,0.000000
68.360001,7.426598,-161.154480,0.008679,0.003353,0.085162,33.035156,1.682891,0.851616,-161.154480,0.086211,0.000000
69.110001,7.519318,-161.198959,0.008761,0.003402,0.086402,33.447594,1.703902,0.864017,-161.198959,0.087468,0.000000
69.860001,7.658951,-161.243454,0.008813,0.003459,0.087867,34.068714,1.735543,0.878673,-161.243454,0.088717,0.000000
70.610001,7.740875,-161.332413,0.008843,0.003505,0.089021,34.433132,1.754107,0.890207,-161.332413,0.089966,0.000000
71.360001,7.789284,-161.421371,0.008899,0.003558,0.090374,34.648464,1.765077,0.903736,-161.421371,0.091215,0.000000
72.110001,7.726357,-161.510330,0.008972,0.003603,0.091527,34.368549,1.750817,0.915270,-161.510330,0.092464,0.000000
72.860001,7.816841,-161.554810,0.009002,0.003649,0.092689,34.771046,1.771322,0.926891,-161.554810,0.093712,0.000000
73.610001,7.959831,-161.643784,0.009063,0.003710,0.094233,35.407097,1.803724,0.942327,-161.643784,0.094961,0.000000
74.360001,7.836945,-161.688263,0.009106,0.003749,0.095213,34.860470,1.775877,0.952127,-161.688263,0.096219,0.000000
75.110001,8.231293,-161.777222,0.009175,0.003807,0.096687,36.614620,1.865238,0.966870,-161.777222,0.097468,0.000000
75.860001,8.028717,-161.866180,0.009231,0.003850,0.097780,35.713516,1.819333,0.977797,-161.866180,0.098716,0.000000
76.610001,8.244698,-161.910660,0.009287,0.003905,0.099176,36.674248,1.868275,0.991759,-161.910660,0.099965,0.000000
77.360001,8.208946,-162.044098,0.009339,0.003952,0.100373,36.515217,1.860174,1.003727,-162.044098,0.101214,0.000000
78.110001,8.226822,-162.044098,0.009369,0.003994,0.101448,36.594730,1.864224,1.014481,-162.044098,0.102463,0.000000
78.860001,8.211182,-162.133072,0.009429,0.004043,0.102697,36.525162,1.860680,1.026969,-162.133072,0.103712,0.000000
79.610001,8.280075,-162.222031,0.009464,0.004094,0.103998,36.831612,1.876292,1.039977,-162.222031,0.104969,0.000000
80.360001,8.502007,-162.266510,0.009546,0.004144,0.105255,37.818813,1.926582,1.052552,-162.266510,0.106218,0.000000
81.110001,8.759689,-162.310989,0.009572,0.004198,0.106617,38.965046,1.984974,1.066167,-162.310989,0.107467,0.000000
81.860001,8.508339,-162.444427,0.009619,0.004243,0.107770,37.846981,1.928017,1.077701,-162.444427,0.108715,0.000000
82.610001,8.586906,-162.533401,0.009688,0.004291,0.108984,38.196468,1.945821,1.089843,-162.533401,0.109964,0.000000
83.360001,8.812561,-162.533401,0.009731,0.004346,0.110380,39.200230,1.996955,1.103805,-162.533401,0.111213,0.000000
84.110001,8.799904,-162.622360,0.009804,0.004394,0.111603,39.143929,1.994087,1.116033,-162.622360,0.112470,0.000000
84.860001,8.727661,-162.666840,0.009830,0.004437,0.112687,38.822575,1.977716,1.126873,-162.666840,0.113719,0.000000
85.610001,8.825966,-162.800278,0.009886,0.004489,0.114032,39.259857,1.999992,1.140315,-162.800278,0.114968,0.000000
86.360001,8.911987,-162.889236,0.009934,0.004541,0.115341,39.642498,2.019485,1.153410,-162.889236,0.116217,0.000000
87.110001,8.916832,-162.844757,0.010007,0.004592,0.116633,39.664051,2.020583,1.166332,-162.844757,0.117466,0.000000
87.860001,9.034874,-163.022690,0.010037,0.004641,0.117882,40.189125,2.047332,1.178820,-163.022690,0.118715,0.000000
88.610001,8.946991,-163.067169,0.010106,0.004682,0.118931,39.798203,2.027417,1.189313,-163.067169,0.119963,0.000000
89.360001,9.032265,-163.156128,0.010145,0.004736,0.120284,40.177521,2.046741,1.202842,-163.156128,0.121221,0.000000
90.110001,9.187546,-163.156128,0.010201,0.004783,0.121498,40.868244,2.081928,1.214983,-163.156128,0.122470,0.000000
90.860001,9.169670,-163.245087,0.010244,0.004832,0.122721,40.788731,2.077877,1.227211,-163.245087,0.123718,0.000000
91.610001,9.175629,-163.378540,0.010296,0.004881,0.123979,40.815235,2.079227,1.239786,-163.378540,0.124967,0.000000
92.360001,9.270584,-163.423019,0.010356,0.004933,0.125305,41.237617,2.100744,1.253054,-163.423019,0.126216,0.000000
93.110001,9.233719,-163.467499,0.010408,0.004982,0.126554,41.073631,2.092391,1.265543,-163.467499,0.127465,0.000000
93.860008,9.263878,-163.467499,0.010460,0.005025,0.127647,41.207787,2.099225,1.276470,-163.467499,0.128714,0.000000
94.610008,9.770676,-163.511978,0.010520,0.005089,0.129260,43.462135,2.214067,1.292600,-163.511978,0.129971,0.000000
95.360008,9.356232,-163.689896,0.010555,0.005128,0.130257,41.618599,2.120152,1.302573,-163.689896,0.131220,0.000000
96.110008,9.526031,-163.734375,0.010615,0.005176,0.131480,42.373905,2.158629,1.314801,-163.734375,0.132469,0.000000
96.860008,9.553589,-163.778854,0.010658,0.005234,0.132946,42.496487,2.164874,1.329457,-163.778854,0.133718,0.000000
97.610008,9.568855,-163.912308,0.010688,0.005275,0.133986,42.564396,2.168334,1.339864,-163.912308,0.134966,0.000000
98.360008,9.769188,-163.956787,0.010762,0.005330,0.135383,43.455517,2.213730,1.353826,-163.956787,0.136215,0.000000
99.110008,9.759132,-164.045746,0.010809,0.005374,0.136501,43.410789,2.211451,1.365013,-164.045746,0.137464,0.000000
99.860008,9.805679,-164.134705,0.010861,0.005428,0.137872,43.617840,2.221999,1.378715,-164.134705,0.138721,0.000000
100.610008,9.795258,-164.134705,0.010904,0.005474,0.139051,43.571484,2.219637,1.390510,-164.134705,0.139970,0.000000
101.360008,9.828766,-164.223679,0.010951,0.005518,0.140170,43.720535,2.227230,1.401697,-164.223679,0.141219,0.000000
102.110008,9.766953,-164.312637,0.011007,0.005562,0.141280,43.445576,2.213223,1.412797,-164.312637,0.142468,0.000000
102.860008,10.013840,-164.357117,0.011046,0.005626,0.142893,44.543785,2.269169,1.428928,-164.357117,0.143717,0.000000
103.610008,10.070068,-164.446075,0.011102,0.005672,0.144064,44.793900,2.281910,1.440635,-164.446075,0.144965,0.000000
104.360008,9.997078,-164.490555,0.011150,0.005710,0.145026,44.469223,2.265370,1.450261,-164.490555,0.146223,0.000000
105.110008,10.271523,-164.623993,0.011214,0.005772,0.146613,45.690014,2.327560,1.466132,-164.623993,0.147472,0.000000
105.860008,10.148262,-164.668488,0.011266,0.005816,0.147723,45.141724,2.299629,1.477232,-164.668488,0.148721,0.000000
106.610008,10.347855,-164.712967,0.011309,0.005870,0.149102,46.029556,2.344857,1.491021,-164.712967,0.149969,0.000000
107.360008,10.355301,-164.801926,0.011387,0.005918,0.150308,46.062679,2.346545,1.503076,-164.801926,0.151218,0.000000
108.110008,10.558243,-164.846405,0.011438,0.005971,0.151660,46.965408,2.392532,1.516604,-164.846405,0.152467,0.000000
108.860008,10.447281,-164.935364,0.011469,0.006016,0.152805,46.471825,2.367388,1.528052,-164.935364,0.153716,0.000000
109.610008,10.437599,-165.024323,0.011538,0.006063,0.153993,46.428761,2.365194,1.539933,-165.024323,0.154973,0.000000
110.360008,10.655434,-165.157776,0.011598,0.006117,0.155372,47.397736,2.414556,1.553722,-165.157776,0.156222,0.000000
111.110008,10.582451,-165.157776,0.011624,0.006160,0.156465,47.073093,2.398017,1.564649,-165.157776,0.157471,0.000000
111.860008,10.640915,-165.202255,0.011689,0.006206,0.157636,47.333153,2.411266,1.576356,-165.202255,0.158720,0.000000
112.610008,10.671074,-165.291214,0.011727,0.006259,0.158988,47.467308,2.418100,1.589885,-165.291214,0.159968,0.000000
113.360008,10.917213,-165.380173,0.011783,0.006313,0.160341,48.562191,2.473876,1.603414,-165.380173,0.161217,0.000000
114.110008,11.032646,-165.424652,0.011844,0.006366,0.161703,49.075661,2.500033,1.617029,-165.424652,0.162466,0.000000
114.860008,10.806992,-165.602585,0.011887,0.006409,0.162778,48.071899,2.448899,1.627783,-165.602585,0.163724,0.000000
115.610008,10.793213,-165.602585,0.011930,0.006451,0.163854,48.010609,2.445777,1.638536,-165.602585,0.164972,0.000000
116.360008,10.946632,-165.647064,0.012003,0.006510,0.165345,48.693054,2.480542,1.653453,-165.647064,0.166221,0.000000
117.110008,11.155159,-165.691544,0.012046,0.006556,0.166533,49.620625,2.527795,1.665334,-165.691544,0.167470,0.000000
117.860008,11.373367,-165.736023,0.012089,0.006614,0.167999,50.591263,2.577242,1.679990,-165.736023,0.168719,0.000000
118.610008,11.091110,-165.824982,0.012154,0.006655,0.169031,49.335724,2.513281,1.690310,-165.824982,0.169968,0.000000
119.360008,11.350281,-165.913940,0.012206,0.006708,0.170392,50.488571,2.572010,1.703925,-165.913940,0.171216,0.000000
120.110008,11.302994,-166.002914,0.012236,0.006755,0.171572,50.278229,2.561295,1.715719,-166.002914,0.172474,0.000000
120.860008,11.412842,-166.047394,0.012301,0.006802,0.172769,50.766857,2.586187,1.727687,-166.047394,0.173723,0.000000
121.610008,11.390495,-166.180832,0.012357,0.006846,0.173879,50.667454,2.581123,1.738788,-166.180832,0.174971,0.000000
122.360008,11.395714,-166.180832,0.012404,0.006895,0.175145,50.690666,2.582306,1.751449,-166.180832,0.176220,0.000000
123.110008,11.676109,-166.314270,0.012465,0.006949,0.176515,51.937927,2.645844,1.765151,-166.314270,0.177469,0.000000
123.860008,12.127052,-166.358749,0.012495,0.007004,0.177911,53.943821,2.748029,1.779114,-166.358749,0.178718,0.000000
124.610008,11.683556,-166.403244,0.012551,0.007049,0.179047,51.971050,2.647532,1.790474,-166.403244,0.179975,0.000000
125.360008,11.718559,-166.447723,0.012585,0.007091,0.180114,52.126755,2.655463,1.801141,-166.447723,0.181224,0.000000
126.110008,11.871231,-166.536682,0.012654,0.007148,0.181554,52.805874,2.690059,1.815537,-166.536682,0.182473,0.000000
126.860008,12.174339,-166.581161,0.012723,0.007202,0.182933,54.154167,2.758745,1.829326,-166.581161,0.183722,0.000000
127.610008,12.157211,-166.714600,0.012762,0.007243,0.183973,54.077976,2.754864,1.839733,-166.714600,0.184971,0.000000
128.360001,12.072685,-166.759079,0.012818,0.007292,0.185222,53.701984,2.735709,1.852221,-166.759079,0.186219,0.000000
129.110001,12.048477,-166.892532,0.012848,0.007341,0.186471,53.594303,2.730224,1.864709,-166.892532,0.187468,0.000000
129.860001,12.174713,-166.937012,0.012922,0.007393,0.187780,54.155830,2.758830,1.877804,-166.937012,0.188726,0.000000
130.610001,12.292381,-166.937012,0.012965,0.007443,0.189047,54.679241,2.785493,1.890465,-166.937012,0.189974,0.000000
131.360001,12.393669,-167.070450,0.013025,0.007489,0.190217,55.129795,2.808445,1.902173,-167.070450,0.191223,0.000000
132.110001,12.427925,-167.070450,0.013042,0.007540,0.191509,55.282173,2.816208,1.915094,-167.070450,0.192472,0.000000
132.860001,12.617096,-167.159409,0.013116,0.007589,0.192758,56.123646,2.859075,1.927583,-167.159409,0.193721,0.000000
133.610001,12.843124,-167.248383,0.013163,0.007644,0.194154,57.129070,2.910294,1.941545,-167.248383,0.194970,0.000000
134.360001,12.550064,-167.292862,0.013215,0.007683,0.195160,55.825474,2.843885,1.951605,-167.292862,0.196218,0.000000
135.110001,12.731415,-167.381821,0.013249,0.007737,0.196531,56.632160,2.884980,1.965307,-167.381821,0.197476,0.000000
135.860001,12.741837,-167.470779,0.013314,0.007786,0.197762,56.678520,2.887341,1.977621,-167.470779,0.198725,0.000000
136.610001,12.913506,-167.515259,0.013370,0.007836,0.199046,57.442142,2.926242,1.990456,-167.515259,0.199974,0.000000
137.360001,13.289970,-167.559738,0.013435,0.007893,0.200485,59.116741,3.011550,2.004853,-167.559738,0.201222,0.000000
138.110001,13.049049,-167.693192,0.013465,0.007935,0.201543,58.045071,2.956957,2.015432,-167.693192,0.202471,0.000000
138.860001,13.106392,-167.693192,0.013517,0.007982,0.202731,58.300144,2.969951,2.027313,-167.693192,0.203720,0.000000
139.610001,13.127243,-167.737671,0.013573,0.008036,0.204110,58.392895,2.974676,2.041103,-167.737671,0.204969,0.000000
140.360001,13.676125,-167.826630,0.013607,0.008088,0.205428,60.834442,3.099054,2.054284,-167.826630,0.206226,0.000000
141.110001,13.470573,-167.871109,0.013659,0.008135,0.206634,59.920105,3.052475,2.066339,-167.871109,0.207475,0.000000
141.860001,13.527542,-168.004547,0.013736,0.008180,0.207779,60.173512,3.065385,2.077786,-168.004547,0.208724,0.000000
142.610001,13.486954,-168.049026,0.013780,0.008231,0.209062,59.992966,3.056187,2.090621,-168.049026,0.209973,0.000000
143.360001,13.763252,-168.138000,0.013827,0.008282,0.210372,61.222004,3.118798,2.103716,-168.138000,0.211222,0.000000
144.110001,13.710007,-168.182480,0.013862,0.008324,0.211430,60.985157,3.106732,2.114296,-168.182480,0.212470,0.000000
144.860001,13.738304,-168.315918,0.013913,0.008369,0.212583,61.111031,3.113144,2.125830,-168.315918,0.213719,0.000000
145.610001,13.839966,-168.271439,0.013974,0.008427,0.214057,61.563244,3.136181,2.140573,-168.271439,0.214977,0.000000
146.360001,14.009026,-168.449356,0.014030,0.008476,0.215289,62.315258,3.174490,2.152888,-168.449356,0.216225,0.000000
147.110001,14.626419,-168.493835,0.014068,0.008530,0.216668,65.061562,3.314394,2.166677,-168.493835,0.217474,0.000000
147.860001,14.006416,-168.538330,0.014150,0.008571,0.217708,62.303650,3.173899,2.177083,-168.538330,0.218723,0.000000
148.610001,13.986679,-168.582809,0.014168,0.008616,0.218836,62.215855,3.169427,2.188357,-168.582809,0.219972,0.000000
149.360001,14.293144,-168.671768,0.014228,0.008672,0.220275,63.579082,3.238873,2.202753,-168.671768,0.221221,0.000000
150.110001,14.453262,-168.671768,0.014284,0.008721,0.221524,64.291321,3.275156,2.215241,-168.671768,0.222478,0.000000
150.860001,14.703125,-168.805206,0.014340,0.008776,0.222920,65.402763,3.331776,2.229204,-168.805206,0.223727,0.000000
151.610001,14.604446,-168.894165,0.014379,0.008820,0.224039,64.963821,3.309415,2.240391,-168.894165,0.224976,0.000000
152.360001,14.580238,-168.938660,0.014413,0.008865,0.225175,64.856140,3.303929,2.251752,-168.938660,0.226224,0.000000
153.110001,14.853935,-168.983139,0.014495,0.008920,0.226571,66.073601,3.365950,2.265714,-168.983139,0.227473,0.000000
153.860001,14.789139,-169.116577,0.014538,0.008961,0.227621,65.785378,3.351267,2.276207,-169.116577,0.228722,0.000000
154.610001,14.865479,-169.161057,0.014564,0.009007,0.228783,66.124954,3.368566,2.287828,-169.161057,0.229971,0.000000
155.360001,14.992088,-169.161057,0.014638,0.009065,0.230240,66.688141,3.397256,2.302397,-169.161057,0.231228,0.000000
156.110001,15.459785,-169.294495,0.014694,0.009120,0.231653,68.768562,3.503237,2.316533,-169.294495,0.232477,0.000000
156.860001,15.425896,-169.338974,0.014754,0.009171,0.232954,68.617813,3.495558,2.329542,-169.338974,0.233726,0.000000
157.610001,15.097839,-169.383469,0.014801,0.009208,0.233891,67.158546,3.421219,2.338908,-169.383469,0.234975,0.000000
158.360001,15.494041,-169.472427,0.014857,0.009260,0.235192,68.920937,3.511000,2.351916,-169.472427,0.236224,0.000000
159.110001,15.447868,-169.561386,0.014914,0.009311,0.236510,68.715553,3.500537,2.365098,-169.561386,0.237472,0.000000
159.860001,15.822845,-169.605865,0.014935,0.009362,0.237793,70.383530,3.585508,2.377933,-169.605865,0.238721,0.000000
160.610001,16.127075,-169.739304,0.015013,0.009420,0.239259,71.736816,3.654447,2.392589,-169.739304,0.239979,0.000000
161.360001,15.876472,-169.739304,0.015034,0.009458,0.240222,70.622078,3.597660,2.402215,-169.739304,0.241228,0.000000
162.110001,16.059677,-169.828278,0.015103,0.009509,0.241531,71.437012,3.639175,2.415310,-169.828278,0.242476,0.000000
162.860001,16.179207,-169.961716,0.015159,0.009558,0.242762,71.968704,3.666261,2.427625,-169.961716,0.243725,0.000000
163.610001,16.630524,-170.006195,0.015189,0.009610,0.244089,73.976265,3.768531,2.440893,-170.006195,0.244974,0.000000
164.360001,16.734787,-169.961716,0.015258,0.009656,0.245260,74.440048,3.792157,2.452601,-169.961716,0.246223,0.000000
165.110001,16.643929,-170.095154,0.015306,0.009703,0.246457,74.035889,3.771568,2.464569,-170.095154,0.247472,0.000000
165.860001,16.848358,-170.139633,0.015358,0.009752,0.247697,74.945244,3.817892,2.476970,-170.139633,0.248729,0.000000
166.610001,17.233765,-170.228607,0.015422,0.009809,0.249154,76.659615,3.905227,2.491539,-170.228607,0.249978,0.000000
167.360001,17.236374,-170.273087,0.015452,0.009857,0.250359,76.671219,3.905818,2.503594,-170.273087,0.251227,0.000000
168.110001,17.160034,-170.317566,0.015517,0.009897,0.251374,76.331642,3.888519,2.513740,-170.317566,0.252475,0.000000
168.860001,17.440437,-170.406525,0.015560,0.009952,0.252788,77.578941,3.952060,2.527876,-170.406525,0.253724,0.000000
169.610001,17.758812,-170.495483,0.015629,0.010004,0.254106,78.995140,4.024204,2.541058,-170.495483,0.254973,0.000000
170.360001,18.266731,-170.539963,0.015685,0.010055,0.255398,81.254478,4.139300,2.553980,-170.539963,0.256231,0.000000
171.110001,18.189644,-170.673416,0.015728,0.010103,0.256621,80.911575,4.121832,2.566207,-170.673416,0.257479,0.000000
171.860001,18.199699,-170.673416,0.015789,0.010147,0.257731,80.956306,4.124111,2.577308,-170.673416,0.258728,0.000000
172.610001,18.334869,-170.762375,0.015815,0.010197,0.259014,81.557571,4.154740,2.590143,-170.762375,0.259977,0.000000
173.360001,18.825287,-170.806854,0.015871,0.010249,0.260315,83.739059,4.265871,2.603151,-170.806854,0.261226,0.000000
174.110016,18.726234,-170.895813,0.015918,0.010294,0.261460,83.298454,4.243425,2.614599,-170.895813,0.262475,0.000000
174.860016,18.988762,-170.940292,0.015966,0.010343,0.262709,84.466232,4.302915,2.627087,-170.940292,0.263723,0.000000
175.610016,19.259102,-171.073730,0.016017,0.010391,0.263923,85.668762,4.364175,2.639228,-171.073730,0.264981,0.000000
176.360016,19.749519,-171.162704,0.016073,0.010446,0.265336,87.850250,4.475305,2.653364,-171.162704,0.266230,0.000000
177.110016,19.769623,-171.162704,0.016121,0.010490,0.266446,87.939674,4.479861,2.664464,-171.162704,0.267478,0.000000
177.860016,20.165085,-171.251663,0.016168,0.010544,0.267817,89.698776,4.569474,2.678166,-171.251663,0.268727,0.000000
178.610016,20.263763,-171.340622,0.016233,0.010594,0.269083,90.137718,4.591834,2.690828,-171.340622,0.269976,0.000000
179.360016,20.504318,-171.429581,0.016272,0.010640,0.270245,91.207764,4.646345,2.702449,-171.429581,0.271225,0.000000
180.110016,21.077766,-171.474060,0.016332,0.010698,0.271719,93.758591,4.776290,2.717192,-171.474060,0.272474,0.000000
180.860016,20.865517,-171.518555,0.016375,0.010738,0.272734,92.814453,4.728194,2.727338,-171.518555,0.273731,0.000000
181.610016,21.413277,-171.607513,0.016427,0.010787,0.273991,95.251015,4.852318,2.739913,-171.607513,0.274980,0.000000
182.360016,21.522385,-171.696472,0.016483,0.010839,0.275309,95.736351,4.877042,2.753095,-171.696472,0.276229,0.000000
183.110016,22.350540,-171.740952,0.016513,0.010892,0.276654,99.420166,5.064705,2.766537,-171.740952,0.277478,0.000000
183.860016,22.422409,-171.829910,0.016569,0.010939,0.277850,99.739861,5.080990,2.778504,-171.829910,0.278726,0.000000
184.610016,22.541565,-171.874390,0.016604,0.010982,0.278943,100.269890,5.107992,2.789432,-171.874390,0.279975,0.000000
185.360016,22.845795,-171.918869,0.016673,0.011031,0.280183,101.623169,5.176931,2.801833,-171.918869,0.281224,0.000000
186.110016,23.477707,-172.052322,0.016720,0.011083,0.281519,104.434059,5.320125,2.815188,-172.052322,0.282481,0.000000
186.860016,24.001640,-172.052322,0.016759,0.011133,0.282785,106.764626,5.438849,2.827850,-172.052322,0.283730,0.000000
187.610016,23.870186,-172.141281,0.016780,0.011174,0.283808,106.179886,5.409061,2.838083,-172.141281,0.284979,0.000000
188.360016,24.617538,-172.185760,0.016867,0.011233,0.285326,109.504280,5.578414,2.853259,-172.185760,0.286228,0.000000
189.110016,24.862564,-172.319199,0.016914,0.011279,0.286479,110.594208,5.633937,2.864793,-172.319199,0.287477,0.000000
189.860016,25.628159,-172.319199,0.016962,0.011332,0.287824,113.999741,5.807424,2.878235,-172.319199,0.288725,0.000000
190.610016,25.964783,-172.408173,0.017018,0.011381,0.289090,115.497124,5.883704,2.890897,-172.408173,0.289974,0.000000
191.360016,25.982285,-172.497131,0.017043,0.011422,0.290113,115.574974,5.887670,2.901130,-172.497131,0.291232,0.000000
192.110016,26.595215,-172.541611,0.017104,0.011476,0.291501,118.301422,6.026562,2.915006,-172.541611,0.292481,0.000000
192.860016,27.488907,-172.630569,0.017177,0.011530,0.292853,122.276764,6.229075,2.928535,-172.630569,0.293729,0.000000
193.610016,27.802444,-172.764008,0.017216,0.011578,0.294094,123.671448,6.300124,2.940936,-172.764008,0.294978,0.000000
194.360016,28.178535,-172.764008,0.017259,0.011623,0.295230,125.344383,6.385347,2.952296,-172.764008,0.296227,0.000000
195.110016,28.552399,-172.808502,0.017298,0.011668,0.296366,127.007416,6.470066,2.963657,-172.808502,0.297476,0.000000
195.860016,29.397316,-172.852982,0.017345,0.011724,0.297779,130.765793,6.661527,2.977793,-172.852982,0.298733,0.000000
196.610016,29.351883,-172.986420,0.017393,0.011760,0.298707,130.563690,6.651232,2.987072,-172.986420,0.299982,0.000000
197.360016,30.328987,-173.030899,0.017457,0.011817,0.300155,134.910080,6.872646,3.001555,-173.030899,0.301231,0.000000
198.110016,30.741577,-173.119858,0.017500,0.011866,0.301396,136.745361,6.966141,3.013956,-173.119858,0.302480,0.000000
198.860016,31.815125,-173.164337,0.017535,0.011922,0.302818,141.520737,7.209410,3.028179,-173.164337,0.303728,0.000000
199.610016,32.468269,-173.253311,0.017595,0.011974,0.304136,144.426071,7.357415,3.041361,-173.253311,0.304977,0.000000
200.360016,33.170937,-173.342270,0.017638,0.012019,0.305281,147.551697,7.516642,3.052808,-173.342270,0.306226,0.000000
201.110016,33.785355,-173.431229,0.017690,0.012061,0.306356,150.284760,7.655870,3.063562,-173.431229,0.307458,0.000000
201.860016,31.830025,-173.431229,0.017725,0.012048,0.306027,141.587021,7.212787,3.060266,-173.431229,0.305827,0.000000
202.610016,31.024956,-173.564667,0.017707,0.012006,0.304960,138.005890,7.030355,3.049599,-173.564667,0.304578,0.000000
203.360016,30.507355,-173.609146,0.017707,0.011960,0.303789,135.703491,6.913065,3.037892,-173.609146,0.303330,0.000000
204.110016,30.202759,-173.653625,0.017720,0.011907,0.302428,134.348587,6.844043,3.024276,-173.653625,0.302081,0.000000
204.860016,29.892570,-173.742599,0.017725,0.011871,0.301534,132.968796,6.773753,3.015344,-173.742599,0.300832,0.000000
205.610016,29.553711,-173.831558,0.017725,0.011822,0.300286,131.461472,6.696967,3.002856,-173.831558,0.299583,0.000000
206.360016,28.622780,-173.876038,0.017738,0.011782,0.299271,127.320480,6.486015,2.992709,-173.876038,0.298326,0.000000
207.110016,26.482384,-173.964996,0.017716,0.011729,0.297909,117.799522,6.000994,2.979094,-173.964996,0.297077,0.000000
207.860016,24.141647,-173.920517,0.017725,0.011684,0.296782,107.387413,5.470576,2.967820,-173.920517,0.295828,0.000000
208.610016,21.187988,-174.053955,0.017738,0.011638,0.295603,94.248878,4.801267,2.956026,-174.053955,0.294579,0.000000
209.360016,18.089851,-174.142929,0.017729,0.011595,0.294510,80.467674,4.099219,2.945098,-174.142929,0.293330,0.000000
210.110016,13.924492,-174.142929,0.017707,0.011537,0.293036,61.939232,3.155335,2.930356,-174.142929,0.292082,0.000000
210.860016,10.769012,-174.231888,0.017690,0.011493,0.291917,47.902962,2.440293,2.919168,-174.231888,0.290833,0.000000
211.610016,7.466064,-174.320847,0.017673,0.011443,0.290659,33.210712,1.691834,2.906594,-174.320847,0.289575,0.000000
212.360016,4.538101,-174.365326,0.017651,0.011394,0.289419,20.186481,1.028348,2.894192,-174.365326,0.288327,0.000000
213.110016,2.075226,-174.498764,0.017595,0.011343,0.288110,9.231066,0.470253,2.881097,-174.498764,0.287078,0.000000
213.860016,0.973007,-174.543259,0.017535,0.011291,0.286792,4.328152,0.220487,2.867915,-174.543259,0.285829,0.000000
214.610016,0.711227,-174.543259,0.017505,0.011246,0.285647,3.163697,0.161166,2.856468,-174.543259,0.284580,0.000000
215.360016,0.631172,-174.632217,0.017444,0.011193,0.284294,2.807594,0.143026,2.842939,-174.632217,0.283331,0.000000
216.110016,0.636009,-174.721176,0.017380,0.011145,0.283088,2.829110,0.144122,2.830885,-174.721176,0.282074,0.000000
216.860016,0.529884,-174.765656,0.017332,0.011090,0.281692,2.357043,0.120074,2.816922,-174.765656,0.280825,0.000000
217.610016,0.484085,-174.854614,0.017285,0.011041,0.280443,2.153318,0.109695,2.804435,-174.854614,0.279576,0.000000
218.360016,0.446846,-174.899094,0.017229,0.010998,0.279342,1.987670,0.101257,2.793421,-174.899094,0.278327,0.000000
219.110016,0.433067,-174.943573,0.017190,0.010953,0.278215,1.926380,0.098134,2.782147,-174.943573,0.277079,0.000000
219.860016,0.368271,-175.032547,0.017104,0.010888,0.276558,1.638151,0.083451,2.765583,-175.032547,0.275830,0.000000
220.610016,0.334015,-175.121506,0.017061,0.010839,0.275318,1.485772,0.075689,2.753181,-175.121506,0.274581,0.000000
221.360016,0.338860,-175.210464,0.017018,0.010800,0.274330,1.507323,0.076787,2.743295,-175.210464,0.273324,0.000000
222.110016,0.350403,-175.210464,0.016970,0.010752,0.273098,1.558670,0.079402,2.730981,-175.210464,0.272075,0.000000
222.860016,0.324707,-175.299423,0.016914,0.010704,0.271893,1.444369,0.073580,2.718926,-175.299423,0.270826,0.000000
223.610016,0.353378,-175.388397,0.016862,0.010648,0.270453,1.571905,0.080077,2.704530,-175.388397,0.269577,0.000000
224.360016,0.335136,-175.432877,0.016811,0.010599,0.269213,1.490761,0.075943,2.692129,-175.432877,0.268328,0.000000
225.110016,0.305717,-175.521835,0.016759,0.010552,0.268033,1.359899,0.069277,2.680334,-175.521835,0.267080,0.000000
225.860016,0.322098,-175.610794,0.016707,0.010505,0.266837,1.432763,0.072988,2.668367,-175.610794,0.265831,0.000000
226.610016,0.310181,-175.655273,0.016668,0.010455,0.265562,1.379753,0.070288,2.655619,-175.655273,0.264573,0.000000
227.360016,0.290077,-175.699753,0.016617,0.010411,0.264443,1.290328,0.065732,2.644431,-175.699753,0.263324,0.000000
228.110016,0.305717,-175.788712,0.016565,0.010364,0.263246,1.359899,0.069277,2.632463,-175.788712,0.262076,0.000000
228.860016,0.292313,-175.788712,0.016522,0.010309,0.261859,1.300272,0.066239,2.618588,-175.788712,0.260827,0.000000
229.610016,0.299759,-175.877686,0.016461,0.010261,0.260619,1.333394,0.067926,2.606187,-175.877686,0.259578,0.000000
230.360016,0.300133,-175.922165,0.016405,0.010215,0.259457,1.335057,0.068011,2.594566,-175.922165,0.258329,0.000000
231.110016,0.264755,-176.055603,0.016354,0.010161,0.258095,1.177690,0.059994,2.580950,-176.055603,0.257080,0.000000
231.860016,0.274063,-176.055603,0.016298,0.010115,0.256916,1.219094,0.062104,2.569156,-176.055603,0.255823,0.000000
232.610016,0.275551,-176.144562,0.016254,0.010061,0.255554,1.225711,0.062441,2.555541,-176.144562,0.254574,0.000000
233.360016,0.275925,-176.233521,0.016211,0.010010,0.254245,1.227374,0.062525,2.542446,-176.233521,0.253325,0.000000
234.110016,0.304596,-176.278015,0.016155,0.009980,0.253490,1.354910,0.069022,2.534901,-176.278015,0.252076,0.000000
234.860016,0.257309,-176.366974,0.016086,0.009912,0.251756,1.144567,0.058307,2.517556,-176.366974,0.250828,0.000000
235.610016,0.278160,-176.455933,0.016056,0.009868,0.250654,1.237318,0.063032,2.506542,-176.455933,0.249579,0.000000
236.360016,0.278534,-176.500412,0.015987,0.009815,0.249301,1.238981,0.063117,2.493014,-176.500412,0.248321,0.000000
237.110016,0.260284,-176.500412,0.015957,0.009757,0.247836,1.157803,0.058981,2.478358,-176.500412,0.247073,0.000000
237.860016,0.284859,-176.633850,0.015910,0.009728,0.247090,1.267115,0.064550,2.470900,-176.633850,0.245824,0.000000
238.610016,0.296776,-176.678345,0.015836,0.009664,0.245468,1.320125,0.067250,2.454682,-176.678345,0.244575,0.000000
239.360016,0.285980,-176.722824,0.015780,0.009619,0.244332,1.272104,0.064804,2.443322,-176.722824,0.243326,0.000000
240.110016,0.274063,-176.856262,0.015750,0.009572,0.243135,1.219094,0.062104,2.431354,-176.856262,0.242077,0.000000
240.860016,0.307953,-176.856262,0.015685,0.009524,0.241904,1.369843,0.069783,2.419039,-176.856262,0.240829,0.000000
241.610016,0.325455,-176.945221,0.015638,0.009479,0.240768,1.447695,0.073749,2.407679,-176.945221,0.239571,0.000000
242.360016,0.307205,-176.989700,0.015582,0.009421,0.239285,1.366517,0.069614,2.392849,-176.989700,0.238322,0.000000
243.110016,0.351143,-177.078659,0.015526,0.009372,0.238036,1.561962,0.079570,2.380361,-177.078659,0.237073,0.000000
243.860016,0.305717,-177.167633,0.015465,0.009318,0.236666,1.359899,0.069277,2.366659,-177.167633,0.235825,0.000000
244.610016,0.316513,-177.212112,0.015444,0.009276,0.235617,1.407920,0.071723,2.356165,-177.212112,0.234576,0.000000
245.360016,0.374229,-177.301071,0.015366,0.009232,0.234489,1.664656,0.084802,2.344892,-177.301071,0.233327,0.000000
246.110016,0.339226,-177.390030,0.015327,0.009174,0.233024,1.508952,0.076870,2.330235,-177.390030,0.232078,0.000000
246.860016,0.357849,-177.434509,0.015258,0.009120,0.231653,1.591792,0.081090,2.316533,-177.434509,0.230821,0.000000
247.610016,0.360085,-177.478989,0.015211,0.009082,0.230691,1.601736,0.081596,2.306907,-177.478989,0.229572,0.000000
248.360016,0.355240,-177.612442,0.015155,0.009033,0.229433,1.580186,0.080499,2.294332,-177.612442,0.228323,0.000000
249.110016,0.374977,-177.656921,0.015133,0.008988,0.228288,1.667982,0.084971,2.282885,-177.656921,0.227074,0.000000
249.860016,0.351517,-177.745880,0.015073,0.008941,0.227100,1.563625,0.079655,2.271004,-177.745880,0.225826,0.000000
250.610016,0.364548,-177.790359,0.015008,0.008886,0.225704,1.621589,0.082608,2.257042,-177.790359,0.224577,0.000000
251.360016,0.355614,-177.879318,0.014970,0.008832,0.224325,1.581849,0.080583,2.243253,-177.879318,0.223328,0.000000
252.110016,0.332527,-177.923798,0.014909,0.008784,0.223102,1.479155,0.075352,2.231025,-177.923798,0.222070,0.000000
252.860016,0.342949,-177.968292,0.014870,0.008731,0.221767,1.525513,0.077713,2.217669,-177.968292,0.220822,0.000000
253.610016,0.348907,-178.012772,0.014810,0.008686,0.220614,1.552018,0.079064,2.206136,-178.012772,0.219573,0.000000
254.360016,0.344444,-178.101730,0.014758,0.008636,0.219347,1.532165,0.078052,2.193474,-178.101730,0.218324,0.000000
255.110016,0.357849,-178.146210,0.014720,0.008597,0.218376,1.591792,0.081090,2.183761,-178.146210,0.217075,0.000000
255.860016,0.354500,-178.279648,0.014651,0.008537,0.216850,1.576894,0.080331,2.168498,-178.279648,0.215826,0.000000
256.610016,0.361572,-178.368607,0.014582,0.008483,0.215462,1.608354,0.081933,2.154622,-178.368607,0.214569,0.000000
257.360016,0.368271,-178.368607,0.014534,0.008442,0.214430,1.638151,0.083451,2.144302,-178.368607,0.213320,0.000000
258.110016,0.354866,-178.413101,0.014500,0.008390,0.213103,1.578523,0.080414,2.131034,-178.413101,0.212071,0.000000
258.860016,0.409233,-178.457581,0.014461,0.008348,0.212028,1.820360,0.092734,2.120280,-178.457581,0.210823,0.000000
259.610016,0.365295,-178.591019,0.014388,0.008291,0.210580,1.624915,0.082777,2.105798,-178.591019,0.209574,0.000000
260.360016,0.391731,-178.635498,0.014319,0.008237,0.209210,1.742508,0.088768,2.092095,-178.635498,0.208325,0.000000
261.110016,0.355240,-178.768936,0.014301,0.008194,0.208117,1.580186,0.080499,2.081168,-178.768936,0.207076,0.000000
261.860016,0.382423,-178.813431,0.014215,0.008141,0.206781,1.701104,0.086658,2.067813,-178.813431,0.205819,0.000000
262.610016,0.388756,-178.857910,0.014185,0.008090,0.205489,1.729272,0.088093,2.054891,-178.857910,0.204570,0.000000
263.360016,0.400673,-178.857910,0.014103,0.008038,0.204171,1.782282,0.090794,2.041710,-178.857910,0.203321,0.000000
264.110016,0.415192,-178.902390,0.014073,0.007997,0.203113,1.846865,0.094084,2.031129,-178.902390,0.202072,0.000000
264.860016,0.432693,-178.991348,0.014030,0.007953,0.201994,1.924717,0.098050,2.019942,-178.991348,0.200823,0.000000
265.610016,0.393219,-179.124786,0.013982,0.007897,0.200581,1.749125,0.089105,2.005806,-179.124786,0.199575,0.000000
266.360016,0.446846,-179.169266,0.013913,0.007851,0.199419,1.987670,0.101257,1.994185,-179.169266,0.198326,0.000000
267.110016,0.424873,-179.213745,0.013879,0.007799,0.198092,1.889931,0.096278,1.980917,-179.213745,0.197068,0.000000
267.860016,0.391357,-179.302719,0.013823,0.007749,0.196834,1.740845,0.088683,1.968342,-179.302719,0.195820,0.000000
268.610016,0.431206,-179.347198,0.013758,0.007703,0.195655,1.918099,0.097713,1.956548,-179.347198,0.194571,0.000000
269.360016,0.455406,-179.436157,0.013793,0.007655,0.194441,2.025748,0.103197,1.944407,-179.436157,0.193322,0.000000
270.110016,0.444237,-179.480637,0.014064,0.007610,0.193287,1.976064,0.100665,1.932873,-179.480637,0.192073,0.000000
270.860016,0.416313,-179.569595,0.014073,0.007553,0.191856,1.851853,0.094338,1.918563,-179.569595,0.190824,0.000000
271.610016,0.409233,-179.614075,0.014043,0.007503,0.190582,1.820360,0.092734,1.905815,-179.614075,0.189576,0.000000
272.360016,0.410355,-179.703049,0.014056,0.007462,0.189524,1.825348,0.092988,1.895235,-179.703049,0.188318,0.000000
273.110016,0.424500,-179.792007,0.014060,0.007411,0.188249,1.888268,0.096193,1.882487,-179.792007,0.187069,0.000000
273.860016,0.341087,-179.836487,0.014073,0.007358,0.186887,1.517232,0.077291,1.868871,-179.836487,0.185820,0.000000
274.610016,0.365295,-179.880966,0.014073,0.007326,0.186081,1.624915,0.082777,1.860806,-179.880966,0.184572,0.000000
275.360016,0.320236,-179.925446,0.013969,0.007256,0.184311,1.424482,0.072567,1.843115,-179.925446,0.183323,0.000000
276.110016,0.355988,-180.014404,0.013892,0.007206,0.183037,1.583512,0.080668,1.830367,-180.014404,0.182074,0.000000
276.860016,0.341835,-180.103378,0.013771,0.007160,0.181866,1.520558,0.077461,1.818659,-180.103378,0.180825,0.000000
277.610016,0.333641,-180.103378,0.013719,0.007109,0.180565,1.484110,0.075604,1.805651,-180.103378,0.179568,0.000000
278.360016,0.381676,-180.192337,0.013702,0.007069,0.179542,1.697778,0.086489,1.795417,-180.192337,0.178319,0.000000
279.110016,0.352631,-180.281296,0.013680,0.007006,0.177946,1.568579,0.079907,1.779460,-180.281296,0.177070,0.000000
279.860016,0.355988,-180.325775,0.013607,0.006956,0.176671,1.583512,0.080668,1.766712,-180.325775,0.175821,0.000000
280.610016,0.351517,-180.414734,0.013564,0.006922,0.175830,1.563625,0.079655,1.758300,-180.414734,0.174573,0.000000
281.360016,0.349655,-180.459213,0.013517,0.006861,0.174269,1.555344,0.079233,1.742690,-180.459213,0.173324,0.000000
282.110016,0.353752,-180.548187,0.013439,0.006818,0.173176,1.573568,0.080161,1.731763,-180.548187,0.172066,0.000000
282.860016,0.388756,-180.592667,0.013504,0.006769,0.171927,1.729272,0.088093,1.719275,-180.592667,0.170817,0.000000
283.610016,0.381310,-180.637146,0.013504,0.006719,0.170661,1.696149,0.086406,1.706614,-180.637146,0.169569,0.000000
284.360016,0.362686,-180.726105,0.013499,0.006669,0.169404,1.613309,0.082186,1.694039,-180.726105,0.168320,0.000000
285.110016,0.380188,-180.770584,0.012607,0.006615,0.168034,1.691161,0.086152,1.680336,-180.770584,0.167071,0.000000
285.860016,0.409233,-180.859543,0.012542,0.006571,0.166915,1.820360,0.092734,1.669149,-180.859543,0.165822,0.000000
286.610016,0.374603,-180.948502,0.012486,0.006512,0.165415,1.666319,0.084886,1.654146,-180.948502,0.164573,0.000000
287.360016,0.390617,-180.948502,0.012452,0.006471,0.164374,1.737553,0.088515,1.643740,-180.948502,0.163316,0.000000
288.110016,0.420403,-181.037476,0.012430,0.006424,0.163169,1.870044,0.095265,1.631685,-181.037476,0.162067,0.000000
288.860016,0.364548,-181.126434,0.012365,0.006373,0.161885,1.621589,0.082608,1.618850,-181.126434,0.160818,0.000000
289.610016,0.392105,-181.170914,0.012305,0.006319,0.160497,1.744171,0.088852,1.604975,-181.170914,0.159570,0.000000
290.360016,0.376839,-181.259872,0.012292,0.006276,0.159413,1.676262,0.085393,1.594134,-181.259872,0.158321,0.000000
291.110016,0.382050,-181.348831,0.012227,0.006227,0.158173,1.699441,0.086574,1.581733,-181.348831,0.157072,0.000000
291.860016,0.344818,-181.348831,0.012189,0.006183,0.157046,1.533828,0.078137,1.570459,-181.348831,0.155823,0.000000
292.610016,0.351517,-181.482285,0.012120,0.006127,0.155624,1.563625,0.079655,1.556237,-181.482285,0.154566,0.000000
293.360016,0.356361,-181.526764,0.012089,0.006077,0.154357,1.585175,0.080753,1.543575,-181.526764,0.153317,0.000000
294.110016,0.366043,-181.571243,0.012021,0.006027,0.153091,1.628241,0.082947,1.530914,-181.571243,0.152068,0.000000
294.860016,0.342949,-181.660202,0.011977,0.005980,0.151895,1.525513,0.077713,1.518946,-181.660202,0.150819,0.000000
295.610016,0.320236,-181.749161,0.011926,0.005929,0.150585,1.424482,0.072567,1.505851,-181.749161,0.149570,0.000000
296.360016,0.355614,-181.749161,0.011874,0.005893,0.149683,1.581849,0.080583,1.496832,-181.749161,0.148322,0.000000
297.110016,0.325821,-181.882614,0.011814,0.005835,0.148200,1.449324,0.073832,1.482002,-181.882614,0.147073,0.000000
297.860016,0.341835,-181.927094,0.011775,0.005785,0.146943,1.520558,0.077461,1.469427,-181.927094,0.145815,0.000000
298.610016,0.303108,-182.016052,0.011714,0.005732,0.145581,1.348293,0.068685,1.455812,-182.016052,0.144567,0.000000
299.360016,0.325455,-182.060532,0.011658,0.005681,0.144306,1.447695,0.073749,1.443064,-182.060532,0.143318,0.000000
300.110016,0.332527,-182.149490,0.011632,0.005636,0.143153,1.479155,0.075352,1.431530,-182.149490,0.142069,0.000000
300.860016,0.336624,-182.193970,0.011559,0.005587,0.141913,1.497379,0.076280,1.419128,-182.193970,0.140820,0.000000
301.610016,0.360085,-182.282944,0.011525,0.005546,0.140863,1.601736,0.081596,1.408635,-182.282944,0.139571,0.000000
302.360016,0.335876,-182.371902,0.011460,0.005488,0.139398,1.494053,0.076111,1.393979,-182.371902,0.138314,0.000000
303.110016,0.351891,-182.460861,0.011404,0.005432,0.137976,1.565287,0.079740,1.379756,-182.460861,0.137065,0.000000
303.860016,0.338486,-182.460861,0.011352,0.005392,0.136952,1.505660,0.076702,1.369523,-182.460861,0.135816,0.000000
304.610016,0.325821,-182.460861,0.011296,0.005338,0.135582,1.449324,0.073832,1.355821,-182.460861,0.134567,0.000000
305.360016,0.363434,-182.594299,0.011257,0.005292,0.134420,1.616634,0.082355,1.344200,-182.594299,0.133319,0.000000
306.110016,0.357101,-182.683273,0.011201,0.005237,0.133032,1.588467,0.080920,1.330324,-182.683273,0.132070,0.000000
306.860016,0.412956,-182.727753,0.011154,0.005195,0.131948,1.836921,0.093577,1.319484,-182.727753,0.130821,0.000000
307.610016,0.408119,-182.772232,0.011115,0.005148,0.130769,1.815405,0.092481,1.307690,-182.772232,0.129564,0.000000
308.360016,0.389870,-182.861191,0.011033,0.005088,0.129243,1.734227,0.088346,1.292426,-182.861191,0.128315,0.000000
309.110016,0.421150,-182.950150,0.010994,0.005049,0.128237,1.873370,0.095434,1.282367,-182.950150,0.127066,0.000000
309.860016,0.402534,-182.950150,0.010938,0.004998,0.126953,1.790563,0.091216,1.269532,-182.950150,0.125817,0.000000
310.610016,0.376091,-183.083588,0.010887,0.004947,0.125661,1.672936,0.085223,1.256610,-183.083588,0.124568,0.000000
311.360016,0.399925,-183.083588,0.010843,0.004897,0.124386,1.778956,0.090624,1.243862,-183.083588,0.123319,0.000000
312.110016,0.404770,-183.172562,0.010800,0.004851,0.123215,1.800506,0.091722,1.232154,-183.172562,0.122071,0.000000
312.860016,0.378326,-183.217041,0.010744,0.004801,0.121949,1.682880,0.085730,1.219493,-183.217041,0.120813,0.000000
313.610016,0.396950,-183.261520,0.010680,0.004754,0.120744,1.765721,0.089950,1.207438,-183.261520,0.119564,0.000000
314.360016,0.376465,-183.261520,0.010632,0.004698,0.119322,1.674599,0.085308,1.193216,-183.261520,0.118316,0.000000
315.110016,0.378326,-183.394958,0.010568,0.004658,0.118324,1.682880,0.085730,1.183243,-183.394958,0.117067,0.000000
315.860016,0.386894,-183.483917,0.010529,0.004601,0.116876,1.720991,0.087671,1.168760,-183.483917,0.115818,0.000000
316.610016,0.364922,-183.528397,0.010451,0.004547,0.115488,1.623252,0.082692,1.154885,-183.528397,0.114569,0.000000
317.360016,0.385406,-183.528397,0.010442,0.004519,0.114795,1.714374,0.087334,1.147947,-183.528397,0.113320,0.000000
318.110016,0.340721,-183.617371,0.010378,0.004452,0.113086,1.515603,0.077209,1.130862,-183.617371,0.112063,0.000000
318.860016,0.357849,-183.617371,0.010300,0.004408,0.111959,1.591792,0.081090,1.119588,-183.617371,0.110814,0.000000
319.610016,0.355988,-183.795288,0.010257,0.004354,0.110597,1.583512,0.080668,1.105973,-183.795288,0.109565,0.000000
320.360016,0.348167,-183.839767,0.010214,0.004308,0.109427,1.548726,0.078896,1.094265,-183.839767,0.108316,0.000000
320.800018,0.409233,-183.928726,0.010175,0.004287,0.108898,1.820360,0.092734,1.088975,-183.928726,0.108750,0.000000