File: Data/PDMS compression/PDMS 0017 Punched_2_07152024_152553.csv
Time (sec),S:Load (lbs),S:HL1 (DIM),S:LVDT (in),S:Position (in),Ch:Position (mm),Ch:Load (N),Ch:Stress (MPa),Ch:Strain (mm/mm),Ch:HL1 (DIM),Set Point (),Cycles ()
0.110000,0.000748,-190.867767,-0.000004,-0.000000,-0.000000,0.003326,0.000169,-0.000000,-190.867767,0.000165,0.000000
0.760000,0.004837,-190.823273,0.000013,0.000110,0.002801,0.021516,0.001096,0.028011,-190.823273,0.003417,0.000000
1.410000,0.007820,-190.956726,0.000121,0.000303,0.007684,0.034786,0.001772,0.076836,-190.956726,0.008828,0.000000
2.060000,0.038727,-191.001205,0.000332,0.000521,0.013234,0.172265,0.008776,0.132339,-191.001205,0.014249,0.000000
2.710000,0.038727,-190.956726,0.000560,0.000732,0.018602,0.172265,0.008776,0.186020,-190.956726,0.019660,0.000000
3.360000,0.023834,-191.001205,0.000767,0.000947,0.024048,0.106020,0.005401,0.240482,-191.001205,0.025071,0.000000
4.010000,0.018990,-191.134644,0.001018,0.001158,0.029425,0.084470,0.004303,0.294250,-191.134644,0.030492,0.000000
4.660000,0.081177,-191.223602,0.001224,0.001374,0.034897,0.361092,0.018395,0.348972,-191.223602,0.035903,0.000000
5.310000,0.249863,-191.223602,0.001440,0.001586,0.040274,1.111445,0.056620,0.402740,-191.223602,0.041315,0.000000
5.960001,0.428970,-191.312576,0.001604,-0.000000,-0.000009,1.908155,0.097206,-0.000087,-191.312576,0.000199,0.000000
6.610000,0.382423,-191.401535,0.001608,-0.000000,-0.000009,1.701104,0.086658,-0.000087,-191.401535,0.000763,0.000000
7.260000,0.512383,-191.401535,0.001604,0.000029,0.000746,2.279191,0.116108,0.007458,-191.401535,0.001847,0.000000
7.910000,0.566376,-191.446014,0.001669,0.000081,0.002047,2.519365,0.128343,0.020466,-191.446014,0.002931,0.000000
8.560000,0.617767,-191.490494,0.001686,0.000118,0.003009,2.747966,0.139988,0.030093,-191.490494,0.004015,0.000000
9.210000,0.735809,-191.534973,0.001742,0.000159,0.004041,3.273043,0.166737,0.040413,-191.534973,0.005099,0.000000
9.860001,0.809540,-191.623932,0.001785,0.000206,0.005238,3.601013,0.183444,0.052380,-191.623932,0.006183,0.000000
10.510000,0.892578,-191.623932,0.001832,0.000250,0.006339,3.970386,0.202261,0.063394,-191.623932,0.007267,0.000000
11.160001,0.979713,-191.712906,0.001854,0.000285,0.007241,4.357983,0.222006,0.072413,-191.712906,0.008351,0.000000
11.810000,1.060143,-191.801865,0.001927,0.000334,0.008490,4.715749,0.240232,0.084901,-191.801865,0.009435,0.000000
12.460001,1.186378,-191.890823,0.001975,0.000380,0.009644,5.277275,0.268837,0.096435,-191.890823,0.010519,0.000000
13.110001,1.296227,-191.890823,0.001979,0.000425,0.010788,5.765903,0.293729,0.107883,-191.890823,0.011603,0.000000
13.760000,1.314102,-191.979782,0.002048,0.000462,0.011742,5.845418,0.297780,0.117422,-191.979782,0.012687,0.000000
14.410001,1.450760,-192.024261,0.002091,0.000507,0.012870,6.453302,0.328747,0.128696,-192.024261,0.013763,0.000000
15.060000,1.550186,-192.068741,0.002130,0.000547,0.013902,6.895572,0.351277,0.139016,-192.068741,0.014847,0.000000
15.710001,1.639183,-192.068741,0.002186,0.000591,0.015012,7.291451,0.371444,0.150117,-192.068741,0.015931,0.000000
16.360001,1.786644,-192.202194,0.002220,0.000635,0.016122,7.947389,0.404859,0.161217,-192.202194,0.017015,0.000000
17.010000,1.865585,-192.202194,0.002264,0.000674,0.017110,8.298538,0.422748,0.171104,-192.202194,0.018099,0.000000
17.660002,1.931496,-192.246674,0.002311,0.000720,0.018298,8.591722,0.437683,0.182985,-192.246674,0.019183,0.000000
18.310001,2.087891,-192.335632,0.002328,0.000762,0.019365,9.287401,0.473123,0.193651,-192.335632,0.020267,0.000000
18.960001,2.185455,-192.380112,0.002414,0.000808,0.020519,9.721391,0.495231,0.205186,-192.380112,0.021351,0.000000
19.610001,2.232742,-192.469070,0.002427,0.000849,0.021559,9.931734,0.505947,0.215592,-192.469070,0.022435,0.000000
20.260000,2.409248,-192.469070,0.002501,0.000890,0.022600,10.716872,0.545943,0.225999,-192.469070,0.023519,0.000000
20.910002,2.459892,-192.602524,0.002552,0.000931,0.023649,10.942147,0.557420,0.236492,-192.602524,0.024603,0.000000
21.560001,2.528038,-192.558044,0.002574,0.000974,0.024733,11.245275,0.572862,0.247333,-192.558044,0.025687,0.000000
22.210001,2.727997,-192.647003,0.002617,0.001017,0.025826,12.134736,0.618173,0.258260,-192.647003,0.026771,0.000000
22.860001,2.850883,-192.691483,0.002656,0.001062,0.026971,12.681363,0.646019,0.269707,-192.691483,0.027847,0.000000
23.510000,2.868011,-192.735962,0.002708,0.001101,0.027968,12.757552,0.649901,0.279680,-192.735962,0.028931,0.000000
24.160002,3.130531,-192.780441,0.002755,0.001149,0.029191,13.925299,0.709388,0.291908,-192.780441,0.030015,0.000000
24.810001,3.195328,-192.869400,0.002811,0.001192,0.030266,14.213528,0.724072,0.302662,-192.869400,0.031099,0.000000
25.460001,3.226608,-192.913879,0.002828,0.001226,0.031133,14.352671,0.731160,0.311334,-192.913879,0.032183,0.000000
26.110001,3.458221,-192.958359,0.002889,0.001275,0.032382,15.382937,0.783644,0.323822,-192.958359,0.033267,0.000000
26.760002,3.481308,-193.047333,0.002915,0.001311,0.033310,15.485631,0.788876,0.333101,-193.047333,0.034351,0.000000
27.410002,3.540886,-193.136292,0.002971,0.001355,0.034412,15.750648,0.802376,0.344115,-193.136292,0.035435,0.000000
28.060001,3.716278,-193.180771,0.003001,0.001400,0.035565,16.530830,0.842121,0.355649,-193.180771,0.036519,0.000000
28.710001,3.823891,-193.269730,0.003027,0.001439,0.036545,17.009516,0.866506,0.365449,-193.269730,0.037603,0.000000
29.360001,3.886826,-193.269730,0.003074,0.001487,0.037768,17.289463,0.880767,0.377677,-193.269730,0.038687,0.000000
30.010002,4.053276,-193.358688,0.003143,0.001529,0.038843,18.029873,0.918485,0.388430,-193.358688,0.039771,0.000000
30.660002,4.145248,-193.358688,0.003160,0.001568,0.039823,18.438986,0.939327,0.398230,-193.358688,0.040855,0.000000
31.310001,4.215256,-193.358688,0.003242,0.001616,0.041046,18.750395,0.955191,0.410458,-193.358688,0.041939,0.000000
31.960001,4.321754,-193.492142,0.003290,0.001659,0.042130,19.224123,0.979324,0.421298,-193.492142,0.043014,0.000000
32.610001,4.475914,-193.536621,0.003320,0.001698,0.043127,19.909861,1.014257,0.431271,-193.536621,0.044098,0.000000
33.260002,4.532143,-193.625580,0.003337,0.001743,0.044272,20.159977,1.026998,0.442719,-193.625580,0.045182,0.000000
33.910000,4.670296,-193.625580,0.003423,0.001789,0.045443,20.774513,1.058304,0.454426,-193.625580,0.046266,0.000000
34.560001,4.739929,-193.759018,0.003449,0.001832,0.046535,21.084259,1.074083,0.465353,-193.759018,0.047351,0.000000
35.210003,4.805092,-193.759018,0.003488,0.001871,0.047533,21.374117,1.088849,0.475326,-193.759018,0.048435,0.000000
35.860001,4.853127,-193.803497,0.003535,0.001913,0.048582,21.587786,1.099734,0.485820,-193.803497,0.049519,0.000000
36.510002,4.901535,-193.892471,0.003570,0.001952,0.049588,21.803116,1.110704,0.495880,-193.892471,0.050603,0.000000
37.160004,5.028145,-193.892471,0.003609,0.001998,0.050750,22.366304,1.139394,0.507500,-193.892471,0.051687,0.000000
37.810001,5.073578,-193.981430,0.003669,0.002038,0.051773,22.568401,1.149689,0.517734,-193.981430,0.052771,0.000000
38.460003,5.282845,-194.025909,0.003712,0.002084,0.052935,23.499266,1.197110,0.529354,-194.025909,0.053855,0.000000
39.110001,5.250450,-194.070389,0.003747,0.002125,0.053967,23.355169,1.189769,0.539674,-194.070389,0.054939,0.000000
39.760002,5.424347,-194.159348,0.003794,0.002173,0.055182,24.128700,1.229174,0.551816,-194.159348,0.056023,0.000000
40.410004,5.543137,-194.159348,0.003854,0.002219,0.056352,24.657103,1.256093,0.563523,-194.159348,0.057107,0.000000
41.060001,5.483559,-194.248306,0.003889,0.002254,0.057254,24.392088,1.242592,0.572542,-194.248306,0.058182,0.000000
41.710003,5.585960,-194.381760,0.003936,0.002293,0.058243,24.847593,1.265797,0.582429,-194.381760,0.059266,0.000000
42.360001,5.793739,-194.381760,0.003971,0.002347,0.059613,25.771839,1.312880,0.596131,-194.381760,0.060350,0.000000
43.010002,5.715919,-194.337280,0.004001,0.002380,0.060454,25.425680,1.295246,0.604543,-194.337280,0.061434,0.000000
43.660004,5.865608,-194.470718,0.004066,0.002424,0.061564,26.091528,1.329166,0.615643,-194.470718,0.062518,0.000000
44.310001,5.981049,-194.515198,0.004122,0.002472,0.062778,26.605032,1.355325,0.627785,-194.515198,0.063602,0.000000
44.960003,5.904335,-194.559677,0.004156,0.002507,0.063680,26.263794,1.337941,0.636804,-194.559677,0.064686,0.000000
45.610001,6.126274,-194.693115,0.004204,0.002555,0.064886,27.251028,1.388234,0.648858,-194.693115,0.065770,0.000000
46.260002,6.186226,-194.737610,0.004251,0.002597,0.065961,27.517708,1.401819,0.659612,-194.737610,0.066854,0.000000
46.910004,6.200745,-194.737610,0.004277,0.002633,0.066872,27.582289,1.405109,0.668718,-194.737610,0.067938,0.000000
47.560001,6.313950,-194.782089,0.004324,0.002680,0.068060,28.085850,1.430761,0.680599,-194.782089,0.069022,0.000000
48.210003,6.336288,-194.871048,0.004363,0.002717,0.069022,28.185219,1.435823,0.690225,-194.871048,0.070107,0.000000
48.860001,6.394005,-194.915527,0.004424,0.002762,0.070159,28.441954,1.448902,0.701586,-194.915527,0.071191,0.000000
49.510002,6.492310,-194.960007,0.004467,0.002806,0.071277,28.879236,1.471178,0.712773,-194.960007,0.072275,0.000000
50.160004,6.775314,-195.093445,0.004506,0.002853,0.072457,30.138103,1.535308,0.724567,-195.093445,0.073350,0.000000
50.810001,6.605515,-195.093445,0.004557,0.002893,0.073480,29.382795,1.496831,0.734800,-195.093445,0.074434,0.000000
51.460003,6.653549,-195.182419,0.004600,0.002933,0.074495,29.596464,1.507716,0.744947,-195.182419,0.075518,0.000000
52.110001,6.922028,-195.226898,0.004635,0.002983,0.075761,30.790716,1.568554,0.757608,-195.226898,0.076602,0.000000
52.760002,6.862823,-195.226898,0.004687,0.003024,0.076810,30.527363,1.555138,0.768102,-195.226898,0.077686,0.000000
53.410004,6.836761,-195.315857,0.004751,0.003063,0.077807,30.411434,1.549232,0.778075,-195.315857,0.078770,0.000000
54.060001,7.047150,-195.315857,0.004760,0.003109,0.078978,31.347288,1.596907,0.789782,-195.315857,0.079854,0.000000
54.710003,6.953308,-195.404816,0.004803,0.003149,0.079976,30.929859,1.575642,0.799755,-195.404816,0.080938,0.000000
55.360004,7.065765,-195.449295,0.004859,0.003193,0.081094,31.430094,1.601125,0.810943,-195.449295,0.082022,0.000000
56.010002,7.104118,-195.449295,0.004911,0.003237,0.082222,31.600697,1.609816,0.822217,-195.449295,0.083106,0.000000
56.660004,7.116035,-195.582748,0.004937,0.003276,0.083202,31.653708,1.612517,0.832016,-195.582748,0.084190,0.000000
57.310001,7.165932,-195.627228,0.004997,0.003318,0.084286,31.875656,1.623823,0.842857,-195.627228,0.085274,0.000000
57.960003,7.373718,-195.671707,0.005057,0.003366,0.085500,32.799938,1.670908,0.854998,-195.671707,0.086358,0.000000
58.610004,7.257538,-195.760666,0.005070,0.003403,0.086428,32.283142,1.644582,0.864277,-195.760666,0.087442,0.000000
59.260002,7.305946,-195.805145,0.005122,0.003440,0.087373,32.498474,1.655551,0.873730,-195.805145,0.088518,0.000000
59.910004,7.544640,-195.894104,0.005174,0.003496,0.088787,33.560234,1.709640,0.887866,-195.894104,0.089602,0.000000
60.560001,7.491013,-195.894104,0.005200,0.003531,0.089697,33.321690,1.697488,0.896971,-195.894104,0.090686,0.000000
61.210003,7.652252,-195.983063,0.005247,0.003580,0.090929,34.038918,1.734025,0.909286,-195.983063,0.091770,0.000000
61.860004,7.676086,-196.027557,0.005282,0.003625,0.092082,34.144939,1.739426,0.920820,-196.027557,0.092854,0.000000
62.510002,7.665657,-196.116516,0.005346,0.003661,0.093001,34.098545,1.737063,0.930013,-196.116516,0.093938,0.000000
63.160004,7.727844,-196.160995,0.005381,0.003701,0.094007,34.375168,1.751155,0.940073,-196.160995,0.095022,0.000000
63.810001,7.813118,-196.205475,0.005450,0.003753,0.095325,34.754486,1.770478,0.953254,-196.205475,0.096106,0.000000
64.460007,7.812744,-196.249954,0.005471,0.003788,0.096219,34.752823,1.770393,0.962187,-196.249954,0.097190,0.000000
65.110001,7.841415,-196.294434,0.005532,0.003828,0.097233,34.880360,1.776890,0.972333,-196.294434,0.098274,0.000000
65.760002,8.061867,-196.383392,0.005575,0.003882,0.098604,35.860973,1.826845,0.986036,-196.383392,0.099358,0.000000
66.410004,7.921852,-196.472366,0.005588,0.003912,0.099367,35.238159,1.795117,0.993667,-196.472366,0.100442,0.000000
67.060005,8.176926,-196.472366,0.005678,0.003962,0.100624,36.372784,1.852918,1.006242,-196.472366,0.101526,0.000000
67.710007,8.156448,-196.516846,0.005700,0.004004,0.101700,36.281693,1.848278,1.016995,-196.516846,0.102610,0.000000
68.360001,8.127029,-196.605804,0.005721,0.004037,0.102549,36.150833,1.841611,1.025494,-196.605804,0.103685,0.000000
69.010002,8.231667,-196.650284,0.005790,0.004086,0.103790,36.616283,1.865322,1.037896,-196.650284,0.104770,0.000000
69.660004,8.447266,-196.739243,0.005842,0.004129,0.104882,37.575314,1.914178,1.048823,-196.739243,0.105854,0.000000
70.310005,8.402954,-196.783722,0.005872,0.004168,0.105871,37.378208,1.904137,1.058709,-196.783722,0.106938,0.000000
70.960007,8.353058,-196.739243,0.005898,0.004207,0.106860,37.156258,1.892830,1.068595,-196.739243,0.108022,0.000000
71.610001,8.699738,-196.872696,0.005971,0.004262,0.108264,38.698364,1.971389,1.082644,-196.872696,0.109106,0.000000
72.260002,8.574249,-196.917175,0.006023,0.004300,0.109227,38.140167,1.942953,1.092271,-196.917175,0.110190,0.000000
72.910004,8.572388,-196.917175,0.006053,0.004337,0.110164,38.131886,1.942531,1.101637,-196.917175,0.111274,0.000000
73.560005,8.776817,-197.006134,0.006118,0.004387,0.111438,39.041233,1.988855,1.114385,-197.006134,0.112358,0.000000
74.210007,8.670319,-197.050613,0.006135,0.004429,0.112488,38.567505,1.964722,1.124878,-197.050613,0.113442,0.000000
74.860001,8.682610,-197.095093,0.006183,0.004467,0.113468,38.622177,1.967507,1.134678,-197.095093,0.114526,0.000000
75.510002,8.960770,-197.184052,0.006234,0.004518,0.114751,39.859493,2.030540,1.147513,-197.184052,0.115610,0.000000
76.160004,8.893372,-197.228531,0.006278,0.004557,0.115740,39.559692,2.015267,1.157399,-197.228531,0.116694,0.000000
76.810005,9.005455,-197.273026,0.006325,0.004600,0.116833,40.058266,2.040665,1.168326,-197.273026,0.117778,0.000000
77.460007,9.081047,-197.361984,0.006359,0.004645,0.117977,40.394516,2.057795,1.179774,-197.361984,0.118853,0.000000
78.110001,9.123871,-197.406464,0.006416,0.004688,0.119079,40.585003,2.067499,1.190788,-197.406464,0.119937,0.000000
78.760002,9.081421,-197.450943,0.006454,0.004724,0.119981,40.396179,2.057879,1.199807,-197.450943,0.121021,0.000000
79.410004,9.206909,-197.539902,0.006493,0.004773,0.121247,40.954376,2.086315,1.212468,-197.539902,0.122105,0.000000
80.060005,9.090729,-197.539902,0.006541,0.004808,0.122114,40.437580,2.059988,1.221140,-197.539902,0.123189,0.000000
80.710007,9.248611,-197.628860,0.006579,0.004851,0.123224,41.139877,2.095765,1.232241,-197.628860,0.124273,0.000000
81.360001,9.291061,-197.673340,0.006627,0.004899,0.124438,41.328705,2.105385,1.244382,-197.673340,0.125357,0.000000
82.010002,9.244888,-197.673340,0.006670,0.004936,0.125366,41.123318,2.094922,1.253661,-197.673340,0.126441,0.000000
82.660004,9.424744,-197.762314,0.006730,0.004984,0.126589,41.923355,2.135678,1.265889,-197.762314,0.127526,0.000000
83.310005,9.437782,-197.762314,0.006778,0.005031,0.127777,41.981354,2.138632,1.277770,-197.762314,0.128610,0.000000
83.960007,9.440758,-197.806793,0.006786,0.005068,0.128740,41.994587,2.139306,1.287397,-197.806793,0.129694,0.000000
84.610001,9.403519,-197.940231,0.006847,0.005102,0.129598,41.828941,2.130868,1.295982,-197.940231,0.130778,0.000000
85.260002,9.584496,-197.940231,0.006903,0.005159,0.131046,42.633965,2.171878,1.310465,-197.940231,0.131862,0.000000
85.910004,9.530128,-198.029190,0.006929,0.005193,0.131896,42.392128,2.159558,1.318964,-198.029190,0.132946,0.000000
86.560005,9.612419,-198.162643,0.006989,0.005235,0.132963,42.758175,2.178205,1.329630,-198.162643,0.134021,0.000000
87.210007,9.729721,-198.118149,0.007045,0.005286,0.134264,43.279961,2.204786,1.342639,-198.118149,0.135105,0.000000
87.860001,9.606834,-198.162643,0.007071,0.005315,0.135001,42.733334,2.176940,1.350010,-198.162643,0.136189,0.000000
88.510002,9.865639,-198.296082,0.007105,0.005368,0.136337,43.884552,2.235586,1.363365,-198.296082,0.137273,0.000000
89.160004,9.753922,-198.251602,0.007157,0.005406,0.137317,43.387611,2.210270,1.373165,-198.251602,0.138357,0.000000
89.810005,9.817230,-198.296082,0.007192,0.005446,0.138322,43.669220,2.224616,1.383225,-198.296082,0.139441,0.000000
90.460007,9.874199,-198.429520,0.007252,0.005492,0.139493,43.922630,2.237525,1.394933,-198.429520,0.140525,0.000000
91.110001,9.962082,-198.429520,0.007291,0.005533,0.140534,44.313553,2.257440,1.405339,-198.429520,0.141609,0.000000
91.760002,9.981819,-198.473999,0.007321,0.005573,0.141557,44.401348,2.261913,1.415573,-198.473999,0.142693,0.000000
92.410004,9.910690,-198.562973,0.007373,0.005611,0.142529,44.084953,2.245795,1.425285,-198.562973,0.143777,0.000000
93.060005,10.236145,-198.607452,0.007429,0.005669,0.144003,45.532646,2.319544,1.440028,-198.607452,0.144861,0.000000
93.710007,10.147148,-198.696411,0.007463,0.005707,0.144957,45.136768,2.299377,1.449568,-198.696411,0.145945,0.000000
94.360008,10.142311,-198.740891,0.007493,0.005745,0.145928,45.115253,2.298281,1.459281,-198.740891,0.147029,0.000000
95.010002,10.325890,-198.740891,0.007562,0.005794,0.147160,45.931850,2.339880,1.471595,-198.740891,0.148105,0.000000
95.660004,10.411903,-198.829849,0.007562,0.005838,0.148287,46.314461,2.359371,1.482869,-198.829849,0.149189,0.000000
96.310005,10.313225,-198.874329,0.007657,0.005874,0.149198,45.875515,2.337010,1.491975,-198.874329,0.150273,0.000000
96.960007,10.443184,-198.918808,0.007700,0.005923,0.150446,46.453602,2.366459,1.504463,-198.918808,0.151357,0.000000
97.610008,10.561226,-198.963287,0.007739,0.005967,0.151556,46.978680,2.393208,1.515563,-198.963287,0.152441,0.000000
98.260002,10.485260,-199.007782,0.007761,0.006006,0.152562,46.640766,2.375994,1.525623,-199.007782,0.153525,0.000000
98.910004,10.463295,-199.052261,0.007825,0.006048,0.153629,46.543060,2.371017,1.536290,-199.052261,0.154609,0.000000
99.560005,10.704590,-199.141220,0.007825,0.006096,0.154826,47.616394,2.425695,1.548258,-199.141220,0.155693,0.000000
100.210007,10.765289,-199.185699,0.007907,0.006134,0.155814,47.886398,2.439450,1.558144,-199.185699,0.156777,0.000000
100.860008,10.679642,-199.230179,0.007976,0.006179,0.156942,47.505421,2.420042,1.569418,-199.230179,0.157861,0.000000
101.510002,10.712036,-199.230179,0.007994,0.006216,0.157896,47.649517,2.427382,1.578958,-199.230179,0.158945,0.000000
102.160004,10.808113,-199.319138,0.008037,0.006258,0.158954,48.076889,2.449153,1.589538,-199.319138,0.160029,0.000000
102.810005,10.897850,-199.408096,0.008084,0.006308,0.160229,48.476059,2.469488,1.602286,-199.408096,0.161113,0.000000
103.460007,11.048660,-199.452591,0.008132,0.006351,0.161321,49.146896,2.503662,1.613213,-199.452591,0.162197,0.000000
104.110008,11.082176,-199.497070,0.008183,0.006395,0.162440,49.295982,2.511257,1.624400,-199.497070,0.163273,0.000000
104.760002,10.876625,-199.541550,0.008239,0.006433,0.163394,48.381645,2.464679,1.633940,-199.541550,0.164357,0.000000
105.410004,11.063927,-199.630508,0.008261,0.006475,0.164469,49.214806,2.507122,1.644693,-199.630508,0.165441,0.000000
106.060005,11.194633,-199.630508,0.008308,0.006516,0.165519,49.796215,2.536740,1.655187,-199.630508,0.166525,0.000000
106.710007,11.069519,-199.674988,0.008369,0.006562,0.166672,49.239681,2.508389,1.666721,-199.674988,0.167609,0.000000
107.360008,11.166702,-199.763947,0.008403,0.006602,0.167695,49.671974,2.530411,1.676954,-199.763947,0.168693,0.000000
108.010002,11.347305,-199.852921,0.008442,0.006647,0.168840,50.475334,2.571336,1.688402,-199.852921,0.169777,0.000000
108.660004,11.233734,-199.852921,0.008489,0.006691,0.169959,49.970146,2.545600,1.699589,-199.852921,0.170861,0.000000
109.310005,11.457153,-199.986359,0.008532,0.006730,0.170930,50.963963,2.596228,1.709302,-199.986359,0.171945,0.000000
109.960007,11.578918,-199.986359,0.008571,0.006779,0.172196,51.505600,2.623820,1.721963,-199.986359,0.173029,0.000000
110.610008,11.394600,-200.119797,0.008606,0.006813,0.173046,50.685711,2.582053,1.730462,-200.119797,0.174113,0.000000
111.260002,11.374489,-200.075317,0.008645,0.006851,0.174009,50.596252,2.577496,1.740088,-200.075317,0.175197,0.000000
111.910004,11.510780,-200.208755,0.008692,0.006895,0.175136,51.202507,2.608380,1.751362,-200.208755,0.176281,0.000000
112.560005,11.629189,-200.208755,0.008744,0.006942,0.176324,51.729214,2.635212,1.763243,-200.208755,0.177365,0.000000
113.210007,11.558815,-200.342209,0.008770,0.006980,0.177287,51.416176,2.619265,1.772869,-200.342209,0.178440,0.000000
113.860008,11.747604,-200.386688,0.008817,0.007021,0.178345,52.255955,2.662045,1.783450,-200.386688,0.179524,0.000000
114.510002,11.858200,-200.431168,0.008864,0.007075,0.179715,52.747910,2.687107,1.797152,-200.431168,0.180608,0.000000
115.160004,11.863785,-200.475647,0.008921,0.007114,0.180704,52.772751,2.688372,1.807038,-200.475647,0.181692,0.000000
115.810005,11.960228,-200.609085,0.008951,0.007152,0.181649,53.201752,2.710227,1.816491,-200.609085,0.182776,0.000000
116.460007,12.010132,-200.564606,0.008998,0.007201,0.182907,53.423733,2.721535,1.829066,-200.564606,0.183861,0.000000
117.110008,12.084229,-200.609085,0.009063,0.007246,0.184043,53.753334,2.738325,1.840426,-200.609085,0.184945,0.000000
117.760002,12.041405,-200.698044,0.009097,0.007280,0.184919,53.562843,2.728621,1.849185,-200.698044,0.186029,0.000000
118.410004,12.039177,-200.787018,0.009153,0.007328,0.186124,53.552933,2.728117,1.861240,-200.787018,0.187113,0.000000
119.060005,12.271164,-200.831497,0.009201,0.007374,0.187312,54.584862,2.780685,1.873121,-200.831497,0.188197,0.000000
119.710007,12.479317,-200.875977,0.009240,0.007418,0.188405,55.510773,2.827854,1.884048,-200.875977,0.189281,0.000000
120.360008,12.229080,-200.875977,0.009278,0.007456,0.189376,54.397667,2.771149,1.893761,-200.875977,0.190365,0.000000
121.010002,12.452881,-200.964935,0.009330,0.007501,0.190521,55.393181,2.821863,1.905208,-200.964935,0.191449,0.000000
121.660004,12.513947,-201.009415,0.009365,0.007541,0.191535,55.664814,2.835701,1.915355,-201.009415,0.192533,0.000000
122.310005,12.468147,-201.142868,0.009438,0.007586,0.192680,55.461090,2.825322,1.926802,-201.142868,0.193608,0.000000
122.960007,12.695663,-201.187347,0.009455,0.007627,0.193730,56.473133,2.876878,1.937295,-201.187347,0.194692,0.000000
123.610008,12.767532,-201.231827,0.009511,0.007670,0.194822,56.792820,2.893164,1.948222,-201.231827,0.195776,0.000000
124.260002,12.707207,-201.231827,0.009537,0.007715,0.195950,56.524479,2.879494,1.959496,-201.231827,0.196860,0.000000
124.910004,12.779076,-201.365265,0.009589,0.007757,0.197016,56.844166,2.895780,1.970163,-201.365265,0.197944,0.000000
125.560005,12.866959,-201.365265,0.009619,0.007802,0.198170,57.235092,2.915694,1.981697,-201.365265,0.199028,0.000000
126.210007,12.774979,-201.454224,0.009688,0.007842,0.199184,56.825943,2.894852,1.991844,-201.454224,0.200112,0.000000
126.860008,13.044952,-201.498703,0.009735,0.007886,0.200312,58.026848,2.956028,2.003118,-201.498703,0.201196,0.000000
127.510010,13.381577,-201.543182,0.009757,0.007933,0.201491,59.524227,3.032309,2.014912,-201.543182,0.202280,0.000000
128.160004,13.003242,-201.587677,0.009796,0.007970,0.202436,57.841312,2.946577,2.024365,-201.587677,0.203364,0.000000
128.810013,13.220711,-201.676636,0.009852,0.008013,0.203529,58.808659,2.995856,2.035292,-201.676636,0.204448,0.000000
129.460007,13.431099,-201.676636,0.009882,0.008060,0.204717,59.744511,3.043530,2.047173,-201.676636,0.205532,0.000000
130.110001,13.082191,-201.721115,0.009951,0.008094,0.205585,58.192493,2.964467,2.055845,-201.721115,0.206617,0.000000
130.760010,13.619896,-201.854553,0.009977,0.008142,0.206816,60.584324,3.086313,2.068160,-201.854553,0.207701,0.000000
131.410004,13.473183,-201.810074,0.010037,0.008184,0.207865,59.931709,3.053067,2.078653,-201.810074,0.208776,0.000000
132.060013,13.463501,-201.899033,0.010059,0.008221,0.208819,59.888645,3.050873,2.088193,-201.899033,0.209860,0.000000
132.710007,13.830658,-201.899033,0.010106,0.008269,0.210033,61.521839,3.134072,2.100334,-201.899033,0.210944,0.000000
133.360001,13.640373,-201.987991,0.010141,0.008306,0.210979,60.675411,3.090953,2.109787,-201.987991,0.212028,0.000000
134.010010,13.590851,-202.032486,0.010197,0.008348,0.212028,60.455124,3.079731,2.120280,-202.032486,0.213112,0.000000
134.660004,14.044403,-202.076965,0.010236,0.008396,0.213259,62.472626,3.182507,2.132595,-202.076965,0.214196,0.000000
135.310013,14.113289,-202.121445,0.010279,0.008435,0.214257,62.779045,3.198117,2.142568,-202.121445,0.215280,0.000000
135.960007,13.913696,-202.076965,0.010335,0.008481,0.215428,61.891212,3.152889,2.154275,-202.076965,0.216364,0.000000
136.610001,14.147919,-202.210403,0.010369,0.008523,0.216494,62.933086,3.205964,2.164942,-202.210403,0.217448,0.000000
137.260010,14.018707,-202.299362,0.010412,0.008561,0.217439,62.358326,3.176684,2.174395,-202.299362,0.218532,0.000000
137.910004,14.273033,-202.299362,0.010464,0.008609,0.218662,63.489624,3.234315,2.186623,-202.299362,0.219616,0.000000
138.560013,14.395546,-202.343842,0.010499,0.008653,0.219798,64.034584,3.262077,2.197983,-202.343842,0.220700,0.000000
139.210007,14.598488,-202.432816,0.010537,0.008694,0.220839,64.937317,3.308065,2.208390,-202.432816,0.221784,0.000000
139.860001,14.470764,-202.477295,0.010606,0.008736,0.221897,64.369171,3.279122,2.218970,-202.477295,0.222868,0.000000
140.510010,14.682274,-202.521774,0.010632,0.008782,0.223059,65.310013,3.327051,2.230591,-202.521774,0.223944,0.000000
141.160004,14.844254,-202.566254,0.010697,0.008826,0.224186,66.030540,3.363756,2.241865,-202.566254,0.225028,0.000000
141.810013,14.770523,-202.655212,0.010731,0.008864,0.225158,65.702568,3.347049,2.251578,-202.655212,0.226112,0.000000
142.460007,14.726212,-202.699692,0.010762,0.008905,0.226190,65.505463,3.337007,2.261898,-202.699692,0.227196,0.000000
143.110001,15.207321,-202.744171,0.010809,0.008952,0.227387,67.645546,3.446028,2.273866,-202.744171,0.228280,0.000000
143.760010,14.955971,-202.788651,0.010861,0.008990,0.228358,66.527481,3.389071,2.283579,-202.788651,0.229364,0.000000
144.410004,15.165237,-202.922104,0.010912,0.009032,0.229416,67.458344,3.436492,2.294159,-202.922104,0.230448,0.000000
145.060013,15.575592,-202.922104,0.010968,0.009084,0.230725,69.283691,3.529480,2.307254,-202.922104,0.231532,0.000000
145.710007,15.232269,-202.966583,0.010999,0.009120,0.231653,67.756516,3.451682,2.316533,-202.966583,0.232616,0.000000
146.360001,15.652679,-202.966583,0.011037,0.009166,0.232824,69.626595,3.546948,2.328241,-202.966583,0.233700,0.000000
147.010010,15.784866,-203.055542,0.011106,0.009213,0.234021,70.214592,3.576902,2.340208,-203.055542,0.234784,0.000000
147.660004,15.605759,-203.100021,0.011124,0.009249,0.234931,69.417885,3.536315,2.349314,-203.100021,0.235868,0.000000
148.310013,15.696243,-203.100021,0.011184,0.009290,0.235972,69.820374,3.556820,2.359721,-203.100021,0.236952,0.000000
148.960007,16.166924,-203.277939,0.011232,0.009341,0.237256,71.914070,3.663477,2.372556,-203.277939,0.238036,0.000000
149.610001,15.878708,-203.277939,0.011253,0.009376,0.238140,70.632019,3.598166,2.381402,-203.277939,0.239111,0.000000
150.260010,16.168785,-203.366913,0.011309,0.009418,0.239224,71.922348,3.663899,2.392242,-203.366913,0.240195,0.000000
150.910004,16.494240,-203.411392,0.011361,0.009468,0.240482,73.370041,3.737648,2.404817,-203.411392,0.241280,0.000000
151.560013,16.221291,-203.455872,0.011404,0.009501,0.241323,72.155907,3.675797,2.413229,-203.455872,0.242364,0.000000
152.210007,16.595520,-203.500351,0.011443,0.009547,0.242485,73.820557,3.760598,2.424850,-203.500351,0.243448,0.000000
152.860001,16.713562,-203.500351,0.011486,0.009591,0.243621,74.345634,3.787347,2.436210,-203.500351,0.244532,0.000000
153.510010,16.739258,-203.633789,0.011533,0.009626,0.244506,74.459938,3.793170,2.445056,-203.633789,0.245616,0.000000
154.160004,16.966782,-203.633789,0.011585,0.009671,0.245642,75.472015,3.844728,2.456417,-203.633789,0.246700,0.000000
154.810013,17.181641,-203.722763,0.011628,0.009713,0.246717,76.427757,3.893415,2.467170,-203.722763,0.247784,0.000000
155.460007,17.043488,-203.722763,0.011667,0.009752,0.247697,75.813217,3.862109,2.476970,-203.722763,0.248868,0.000000
156.110001,17.399849,-203.811722,0.011697,0.009799,0.248894,77.398392,3.942862,2.488938,-203.811722,0.249952,0.000000
156.760010,17.814301,-203.900681,0.011758,0.009846,0.250082,79.241966,4.036778,2.500819,-203.900681,0.251036,0.000000
157.410004,17.592361,-203.900681,0.011788,0.009887,0.251123,78.254730,3.986486,2.511225,-203.900681,0.252120,0.000000
158.060013,17.738708,-203.989639,0.011848,0.009927,0.252137,78.905716,4.019649,2.521372,-203.989639,0.253204,0.000000
158.710007,18.345673,-204.078598,0.011870,0.009975,0.253369,81.605629,4.157189,2.533686,-204.078598,0.254279,0.000000
159.360001,18.248856,-204.078598,0.011921,0.010017,0.254435,81.174965,4.135250,2.544353,-204.078598,0.255363,0.000000
160.010010,18.119270,-204.167572,0.011973,0.010057,0.255450,80.598541,4.105886,2.554500,-204.167572,0.256447,0.000000
160.660004,18.802574,-204.256531,0.012021,0.010107,0.256716,83.638023,4.260724,2.567161,-204.256531,0.257531,0.000000
161.310013,18.486427,-204.256531,0.012033,0.010144,0.257670,82.231735,4.189084,2.576701,-204.256531,0.258615,0.000000
161.960007,18.649529,-204.256531,0.012085,0.010185,0.258702,82.957245,4.226044,2.587021,-204.256531,0.259699,0.000000
162.610001,18.947800,-204.345490,0.012150,0.010231,0.259873,84.284019,4.293633,2.598728,-204.345490,0.260783,0.000000
163.260010,18.957855,-204.434448,0.012176,0.010272,0.260896,84.328751,4.295912,2.608962,-204.434448,0.261867,0.000000
163.910004,19.066956,-204.478928,0.012223,0.010310,0.261885,84.814056,4.320634,2.618848,-204.478928,0.262951,0.000000
164.560013,19.667969,-204.567886,0.012258,0.010361,0.263177,87.487495,4.456826,2.631770,-204.567886,0.264036,0.000000
165.210007,19.459442,-204.656860,0.012318,0.010397,0.264096,86.559921,4.409573,2.640962,-204.656860,0.265120,0.000000
165.860001,19.451622,-204.656860,0.012344,0.010433,0.264989,86.525139,4.407801,2.649895,-204.656860,0.266204,0.000000
166.510010,20.200462,-204.701340,0.012396,0.010489,0.266429,89.856148,4.577490,2.664291,-204.701340,0.267288,0.000000
167.160004,19.990440,-204.790298,0.012439,0.010524,0.267305,88.921921,4.529899,2.673050,-204.790298,0.268363,0.000000
167.810013,20.474152,-204.790298,0.012460,0.010574,0.268571,91.073578,4.639509,2.685711,-204.790298,0.269447,0.000000
168.460007,20.690132,-204.923737,0.012551,0.010619,0.269733,92.034302,4.688451,2.697332,-204.923737,0.270531,0.000000
169.110001,20.669281,-204.923737,0.012577,0.010654,0.270618,91.941551,4.683726,2.706178,-204.923737,0.271615,0.000000
169.760010,20.817856,-204.923737,0.012598,0.010694,0.271615,92.602448,4.717394,2.716151,-204.923737,0.272699,0.000000
170.410004,21.352585,-205.057190,0.012641,0.010747,0.272977,94.981041,4.838565,2.729766,-205.057190,0.273783,0.000000
171.060013,21.262840,-205.057190,0.012702,0.010781,0.273835,94.581841,4.818229,2.738352,-205.057190,0.274867,0.000000
171.710007,21.417374,-205.146149,0.012728,0.010821,0.274850,95.269234,4.853246,2.748498,-205.146149,0.275951,0.000000
172.360001,22.077591,-205.190628,0.012788,0.010875,0.276220,98.206032,5.002853,2.762201,-205.190628,0.277035,0.000000
173.010010,21.859383,-205.279587,0.012831,0.010905,0.276975,97.235390,4.953407,2.769745,-205.279587,0.278119,0.000000
173.660004,22.568008,-205.324066,0.012861,0.010954,0.278241,100.387512,5.113984,2.782407,-205.324066,0.279203,0.000000
174.310013,22.766853,-205.457520,0.012922,0.010997,0.279333,101.272018,5.159042,2.793334,-205.457520,0.280287,0.000000
174.960007,22.952667,-205.457520,0.012952,0.011035,0.280287,102.098564,5.201149,2.802873,-205.457520,0.281371,0.000000
175.610016,23.403236,-205.457520,0.012982,0.011080,0.281423,104.102798,5.303249,2.814234,-205.457520,0.282455,0.000000
176.260010,23.733902,-205.501999,0.013042,0.011123,0.282516,105.573669,5.378179,2.825161,-205.501999,0.283531,0.000000
176.910004,23.911522,-205.501999,0.013090,0.011160,0.283470,106.363762,5.418428,2.834701,-205.501999,0.284615,0.000000
177.560013,24.226181,-205.635437,0.013120,0.011205,0.284597,107.763435,5.489731,2.845974,-205.635437,0.285699,0.000000
178.210007,25.044655,-205.679916,0.013172,0.011256,0.285907,111.404190,5.675200,2.859070,-205.679916,0.286783,0.000000
178.860016,24.910225,-205.724396,0.013215,0.011295,0.286887,110.806213,5.644738,2.868869,-205.724396,0.287867,0.000000
179.510010,25.028267,-205.768875,0.013258,0.011330,0.287789,111.331291,5.671486,2.877888,-205.768875,0.288951,0.000000
180.160004,25.811745,-205.857849,0.013301,0.011379,0.289029,114.816376,5.849025,2.890290,-205.857849,0.290035,0.000000
180.810013,25.950638,-205.857849,0.013331,0.011423,0.290139,115.434204,5.880498,2.901390,-205.857849,0.291119,0.000000
181.460007,26.132729,-205.902328,0.013357,0.011461,0.291110,116.244179,5.921761,2.911103,-205.902328,0.292203,0.000000
182.110016,27.127708,-206.035767,0.013439,0.011512,0.292411,120.670074,6.147227,2.924111,-206.035767,0.293287,0.000000
182.760010,27.201805,-206.035767,0.013461,0.011550,0.293382,120.999672,6.164017,2.933825,-206.035767,0.294371,0.000000
183.410004,27.627800,-206.035767,0.013504,0.011592,0.294440,122.894592,6.260549,2.944405,-206.035767,0.295455,0.000000
184.060013,28.129761,-206.124725,0.013564,0.011637,0.295577,125.127426,6.374295,2.955765,-206.124725,0.296539,0.000000
184.710007,28.426170,-206.213684,0.013603,0.011681,0.296695,126.445923,6.441462,2.966952,-206.213684,0.297623,0.000000
185.360016,28.569901,-206.213684,0.013629,0.011714,0.297528,127.085266,6.474032,2.975278,-206.213684,0.298699,0.000000
186.010010,29.713829,-206.347137,0.013672,0.011767,0.298872,132.173706,6.733250,2.988720,-206.347137,0.299783,0.000000
186.660004,29.657234,-206.391617,0.013715,0.011802,0.299774,131.921967,6.720426,2.997739,-206.391617,0.300867,0.000000
187.310013,30.428040,-206.391617,0.013736,0.011845,0.300858,135.350677,6.895092,3.008579,-206.391617,0.301951,0.000000
187.960007,31.049530,-206.525055,0.013805,0.011892,0.302063,138.115204,7.035924,3.020634,-206.525055,0.303035,0.000000
188.610016,31.051025,-206.569534,0.013818,0.011927,0.302957,138.121857,7.036263,3.029566,-206.569534,0.304119,0.000000
189.260010,32.057915,-206.569534,0.013879,0.011978,0.304231,142.600723,7.264427,3.042315,-206.569534,0.305203,0.000000
189.910004,32.685738,-206.569534,0.013922,0.012023,0.305394,145.393417,7.406694,3.053935,-206.569534,0.306287,0.000000
190.560013,32.800797,-206.658493,0.013956,0.012060,0.306330,145.905228,7.432767,3.063301,-206.658493,0.307371,0.000000
191.210007,33.267380,-206.747467,0.013995,0.012095,0.307215,147.980698,7.538496,3.072147,-206.747467,0.308455,0.000000
191.860016,32.317085,-206.747467,0.014004,0.012097,0.307258,143.753571,7.323156,3.072581,-206.747467,0.307258,0.000000
192.510010,31.482231,-206.791946,0.014038,0.012068,0.306521,140.039963,7.133976,3.065209,-206.791946,0.306174,0.000000
193.160004,30.935211,-206.836426,0.014017,0.012029,0.305541,137.606689,7.010019,3.055409,-206.836426,0.305090,0.000000
193.810013,30.594490,-206.925385,0.014038,0.011988,0.304500,136.091095,6.932811,3.045003,-206.925385,0.304006,0.000000
194.460007,30.340164,-206.969864,0.014047,0.011951,0.303555,134.959793,6.875179,3.035550,-206.969864,0.302922,0.000000
195.110016,30.067955,-207.058823,0.014056,0.011909,0.302480,133.748947,6.813496,3.024796,-207.058823,0.301838,0.000000
195.760010,29.784210,-207.103302,0.014060,0.011867,0.301422,132.486786,6.749199,3.014216,-207.103302,0.300754,0.000000
196.410004,29.048027,-207.147797,0.014034,0.011833,0.300563,129.212082,6.582377,3.005631,-207.147797,0.299670,0.000000
197.060013,27.657593,-207.192276,0.014073,0.011794,0.299557,123.027115,6.267300,2.995571,-207.192276,0.298586,0.000000
197.710007,25.254669,-207.236755,0.014056,0.011744,0.298300,112.338379,5.722790,2.982996,-207.236755,0.297510,0.000000
198.360016,22.611572,-207.325714,0.014064,0.011702,0.297224,100.581299,5.123856,2.972243,-207.325714,0.296426,0.000000
199.010010,20.883392,-207.370193,0.014068,0.011677,0.296591,92.893967,4.732244,2.965912,-207.370193,0.295342,0.000000
199.660004,17.478790,-207.414673,0.014060,0.011628,0.295351,77.749542,3.960750,2.953511,-207.414673,0.294258,0.000000
200.310013,13.923004,-207.459152,0.014064,0.011578,0.294094,61.932617,3.154998,2.940936,-207.459152,0.293174,0.000000
200.960007,11.129471,-207.548111,0.014047,0.011540,0.293105,49.506359,2.521974,2.931049,-207.548111,0.292090,0.000000
201.610016,8.290497,-207.548111,0.014034,0.011497,0.292021,36.877972,1.878654,2.920209,-207.548111,0.291006,0.000000
202.260010,5.637718,-207.592606,0.013991,0.011457,0.290998,25.077824,1.277525,2.909976,-207.592606,0.289922,0.000000
202.910004,3.594887,-207.681564,0.013974,0.011419,0.290044,15.990855,0.814613,2.900436,-207.681564,0.288838,0.000000
203.560013,1.629128,-207.726044,0.013939,0.011372,0.288856,7.246721,0.369166,2.888555,-207.726044,0.287754,0.000000
204.210007,0.960350,-207.770523,0.013887,0.011327,0.287693,4.271850,0.217618,2.876934,-207.770523,0.286670,0.000000
204.860016,0.723145,-207.815002,0.013844,0.011286,0.286670,3.216707,0.163867,2.866701,-207.815002,0.285586,0.000000
205.510010,0.660591,-207.859482,0.013810,0.011241,0.285517,2.938456,0.149692,2.855167,-207.859482,0.284502,0.000000
206.160004,0.672134,-207.903961,0.013741,0.011197,0.284398,2.989803,0.152308,2.843980,-207.903961,0.283418,0.000000
206.810013,0.563774,-207.992920,0.013702,0.011159,0.283435,2.507792,0.127753,2.834354,-207.992920,0.282343,0.000000
207.460007,0.535469,-207.992920,0.013668,0.011111,0.282221,2.381885,0.121339,2.822213,-207.992920,0.281259,0.000000
208.110016,0.505310,-208.081894,0.013599,0.011069,0.281163,2.247731,0.114505,2.811632,-208.081894,0.280175,0.000000
208.760010,0.443123,-208.126373,0.013577,0.011031,0.280192,1.971109,0.100413,2.801919,-208.126373,0.279091,0.000000
209.410004,0.404022,-208.215332,0.013530,0.010982,0.278943,1.797181,0.091553,2.789431,-208.215332,0.278007,0.000000
210.060013,0.383919,-208.259811,0.013473,0.010936,0.277781,1.707756,0.086997,2.777811,-208.259811,0.276922,0.000000
210.710007,0.346680,-208.215332,0.013443,0.010891,0.276636,1.542108,0.078559,2.766363,-208.215332,0.275838,0.000000
211.360016,0.366043,-208.348770,0.013400,0.010855,0.275717,1.628241,0.082947,2.757171,-208.348770,0.274754,0.000000
212.010010,0.428230,-208.348770,0.013370,0.010819,0.274798,1.904863,0.097038,2.747978,-208.348770,0.273670,0.000000
212.660004,0.379448,-208.482224,0.013314,0.010765,0.273436,1.687869,0.085984,2.734363,-208.482224,0.272586,0.000000
213.310013,0.386520,-208.482224,0.013275,0.010727,0.272465,1.719329,0.087587,2.724650,-208.482224,0.271502,0.000000
213.960007,0.440514,-208.571182,0.013241,0.010691,0.271563,1.959502,0.099822,2.715631,-208.571182,0.270418,0.000000
214.610016,0.380936,-208.615662,0.013193,0.010644,0.270366,1.694486,0.086321,2.703663,-208.615662,0.269334,0.000000
215.260010,0.359711,-208.660141,0.013133,0.010599,0.269213,1.600073,0.081512,2.692129,-208.660141,0.268259,0.000000
215.910004,0.398811,-208.749100,0.013090,0.010555,0.268094,1.774001,0.090372,2.680941,-208.749100,0.267175,0.000000
216.560013,0.367531,-208.793579,0.013055,0.010519,0.267175,1.634859,0.083284,2.671749,-208.793579,0.266091,0.000000
217.210007,0.338860,-208.749100,0.013004,0.010473,0.266013,1.507323,0.076787,2.660128,-208.749100,0.265007,0.000000
217.860016,0.361572,-208.882553,0.012969,0.010435,0.265042,1.608354,0.081933,2.650415,-208.882553,0.263923,0.000000
218.510010,0.357849,-208.882553,0.012913,0.010396,0.264070,1.591792,0.081090,2.640702,-208.882553,0.262839,0.000000
219.160004,0.339973,-208.927032,0.012866,0.010343,0.262700,1.512277,0.077039,2.627000,-208.927032,0.261755,0.000000
219.810013,0.366417,-209.015991,0.012827,0.010300,0.261607,1.629904,0.083031,2.616073,-209.015991,0.260671,0.000000
220.460007,0.332527,-209.060471,0.012775,0.010259,0.260584,1.479155,0.075352,2.605840,-209.060471,0.259587,0.000000
221.110016,0.315399,-209.104950,0.012741,0.010213,0.259405,1.402966,0.071470,2.594045,-209.104950,0.258503,0.000000
221.760010,0.324707,-209.149429,0.012697,0.010172,0.258373,1.444369,0.073580,2.583725,-209.149429,0.257419,0.000000
222.410004,0.359711,-209.238388,0.012663,0.010137,0.257479,1.600073,0.081512,2.574793,-209.238388,0.256335,0.000000
223.060013,0.310928,-209.282867,0.012594,0.010084,0.256126,1.383078,0.070457,2.561264,-209.282867,0.255251,0.000000
223.710007,0.334389,-209.327362,0.012555,0.010042,0.255068,1.487435,0.075774,2.550684,-209.327362,0.254167,0.000000
224.360016,0.340347,-209.327362,0.012525,0.010008,0.254201,1.513940,0.077124,2.542012,-209.327362,0.253091,0.000000
225.010010,0.317261,-209.460800,0.012482,0.009956,0.252874,1.411246,0.071892,2.528743,-209.460800,0.252007,0.000000
225.660004,0.323219,-209.505280,0.012434,0.009918,0.251912,1.437751,0.073243,2.519117,-209.505280,0.250923,0.000000
226.310013,0.319122,-209.549759,0.012383,0.009869,0.250680,1.419527,0.072314,2.506803,-209.549759,0.249839,0.000000
226.960007,0.328056,-209.549759,0.012331,0.009830,0.249692,1.459267,0.074339,2.496916,-209.549759,0.248755,0.000000
227.610016,0.354874,-209.638718,0.012301,0.009795,0.248790,1.578557,0.080416,2.487897,-209.638718,0.247671,0.000000
228.260010,0.327316,-209.683197,0.012253,0.009745,0.247515,1.455976,0.074171,2.475149,-209.683197,0.246587,0.000000
228.910004,0.351891,-209.727692,0.012206,0.009701,0.246413,1.565287,0.079740,2.464135,-209.727692,0.245503,0.000000
229.560013,0.322845,-209.772171,0.012163,0.009664,0.245460,1.436088,0.073158,2.454596,-209.772171,0.244419,0.000000
230.210007,0.312424,-209.905609,0.012098,0.009621,0.244376,1.389730,0.070796,2.443755,-209.905609,0.243335,0.000000
230.860016,0.336998,-209.905609,0.012077,0.009575,0.243213,1.499042,0.076365,2.432134,-209.905609,0.242251,0.000000
231.510010,0.331413,-209.950089,0.012021,0.009536,0.242207,1.474200,0.075099,2.422075,-209.950089,0.241167,0.000000
232.160004,0.350029,-209.994568,0.011973,0.009487,0.240976,1.557007,0.079318,2.409760,-209.994568,0.240083,0.000000
232.810013,0.341469,-210.083527,0.011930,0.009450,0.240022,1.518929,0.077378,2.400220,-210.083527,0.238999,0.000000
233.460007,0.392853,-210.083527,0.011904,0.009413,0.239094,1.747496,0.089022,2.390941,-210.083527,0.237923,0.000000
234.110016,0.344444,-210.172501,0.011848,0.009358,0.237689,1.532165,0.078052,2.376892,-210.172501,0.236839,0.000000
234.760010,0.337738,-210.172501,0.011826,0.009322,0.236770,1.502334,0.076533,2.367699,-210.172501,0.235755,0.000000
235.410004,0.394714,-210.216980,0.011758,0.009286,0.235859,1.755777,0.089444,2.358594,-210.216980,0.234671,0.000000
236.060013,0.368279,-210.305939,0.011714,0.009238,0.234654,1.638185,0.083453,2.346539,-210.305939,0.233587,0.000000
236.710007,0.336250,-210.394897,0.011676,0.009194,0.233518,1.495716,0.076195,2.335178,-210.394897,0.232503,0.000000
237.360016,0.369766,-210.394897,0.011628,0.009156,0.232564,1.644802,0.083790,2.325639,-210.394897,0.231419,0.000000
238.010010,0.344818,-210.439377,0.011594,0.009106,0.231289,1.533828,0.078137,2.312891,-210.439377,0.230335,0.000000
238.660019,0.347054,-210.483856,0.011563,0.009068,0.230326,1.543771,0.078643,2.303265,-210.483856,0.229251,0.000000
239.310013,0.351151,-210.572815,0.011503,0.009028,0.229320,1.561996,0.079572,2.293205,-210.572815,0.228167,0.000000
239.960007,0.357849,-210.617310,0.011473,0.008990,0.228349,1.591792,0.081090,2.283492,-210.617310,0.227083,0.000000
240.610016,0.352638,-210.617310,0.011417,0.008937,0.226996,1.568613,0.079909,2.269963,-210.617310,0.225999,0.000000
241.260010,0.347794,-210.661789,0.011378,0.008893,0.225886,1.547063,0.078811,2.258863,-210.661789,0.224915,0.000000
241.910019,0.342957,-210.750748,0.011305,0.008850,0.224794,1.525547,0.077715,2.247936,-210.750748,0.223831,0.000000
242.560013,0.299759,-210.839706,0.011279,0.008808,0.223736,1.333394,0.067926,2.237355,-210.839706,0.222756,0.000000
243.210007,0.320236,-210.884186,0.011232,0.008765,0.222643,1.424482,0.072567,2.226429,-210.884186,0.221672,0.000000
243.860016,0.344818,-210.839706,0.011197,0.008732,0.221784,1.533828,0.078137,2.217843,-210.839706,0.220588,0.000000
244.510010,0.297523,-210.973145,0.011137,0.008679,0.220457,1.323451,0.067420,2.204574,-210.973145,0.219503,0.000000
245.160019,0.309814,-211.017639,0.011094,0.008638,0.219399,1.378124,0.070205,2.193994,-211.017639,0.218419,0.000000
245.810013,0.299759,-211.062119,0.011072,0.008604,0.218550,1.333394,0.067926,2.185495,-211.062119,0.217335,0.000000
246.460007,0.309067,-211.151077,0.011003,0.008551,0.217197,1.374798,0.070036,2.171967,-211.151077,0.216251,0.000000
247.110016,0.319870,-211.151077,0.010964,0.008516,0.216303,1.422853,0.072484,2.163034,-211.151077,0.215167,0.000000
247.760010,0.306091,-211.195557,0.010921,0.008467,0.215072,1.361562,0.069361,2.150720,-211.195557,0.214083,0.000000
248.410019,0.304604,-211.284515,0.010865,0.008423,0.213945,1.354944,0.069024,2.139446,-211.284515,0.212999,0.000000
249.060013,0.324333,-211.284515,0.010835,0.008388,0.213051,1.442706,0.073495,2.130513,-211.284515,0.211915,0.000000
249.710007,0.293800,-211.373474,0.010779,0.008340,0.211837,1.306889,0.066576,2.118372,-211.373474,0.210831,0.000000
250.360016,0.293060,-211.417953,0.010749,0.008298,0.210762,1.303597,0.066408,2.107619,-211.417953,0.209747,0.000000
251.010010,0.297523,-211.506927,0.010671,0.008259,0.209782,1.323451,0.067420,2.097819,-211.506927,0.208663,0.000000
251.660019,0.296783,-211.595886,0.010658,0.008211,0.208550,1.320159,0.067252,2.085504,-211.595886,0.207588,0.000000
252.310013,0.309067,-211.595886,0.010606,0.008172,0.207579,1.374798,0.070036,2.075791,-211.595886,0.206504,0.000000
252.960007,0.325455,-211.684845,0.010568,0.008130,0.206504,1.447695,0.073749,2.065038,-211.684845,0.205420,0.000000
253.610016,0.299759,-211.684845,0.010507,0.008083,0.205298,1.333394,0.067926,2.052983,-211.684845,0.204336,0.000000
254.260010,0.328056,-211.729324,0.010464,0.008041,0.204240,1.459267,0.074339,2.042403,-211.729324,0.203252,0.000000
254.910019,0.351517,-211.773804,0.010451,0.008014,0.203547,1.563625,0.079655,2.035465,-211.773804,0.202168,0.000000
255.560013,0.332901,-211.818283,0.010382,0.007956,0.202090,1.480818,0.075436,2.020896,-211.818283,0.201084,0.000000
256.210022,0.352264,-211.862762,0.010348,0.007912,0.200971,1.566950,0.079824,2.009709,-211.862762,0.200000,0.000000
256.860016,0.354126,-211.996216,0.010292,0.007872,0.199939,1.575231,0.080246,1.999389,-211.996216,0.198916,0.000000
257.510010,0.319870,-211.996216,0.010244,0.007831,0.198916,1.422853,0.072484,1.989156,-211.996216,0.197832,0.000000
258.160004,0.336250,-212.085175,0.010214,0.007782,0.197658,1.495716,0.076195,1.976581,-212.085175,0.196747,0.000000
258.809998,0.332527,-212.129654,0.010171,0.007743,0.196669,1.479155,0.075352,1.966694,-212.129654,0.195663,0.000000
259.460022,0.341095,-212.218613,0.010115,0.007703,0.195646,1.517266,0.077293,1.956461,-212.218613,0.194579,0.000000
260.110016,0.297523,-212.174133,0.010063,0.007659,0.194545,1.323451,0.067420,1.945447,-212.174133,0.193495,0.000000
260.760010,0.307579,-212.263092,0.010037,0.007616,0.193443,1.368180,0.069698,1.934434,-212.263092,0.192420,0.000000
261.410004,0.325829,-212.352066,0.009981,0.007571,0.192316,1.449358,0.073834,1.923160,-212.352066,0.191336,0.000000
262.059998,0.339973,-212.441025,0.009942,0.007537,0.191431,1.512277,0.077039,1.914314,-212.441025,0.190252,0.000000
262.710022,0.331413,-212.485504,0.009891,0.007489,0.190217,1.474200,0.075099,1.902173,-212.485504,0.189168,0.000000
263.360016,0.336998,-212.529984,0.009848,0.007447,0.189159,1.499042,0.076365,1.891593,-212.529984,0.188084,0.000000
264.010010,0.287842,-212.574463,0.009796,0.007399,0.187945,1.280384,0.065226,1.879451,-212.574463,0.187000,0.000000
264.660004,0.319122,-212.618942,0.009753,0.007365,0.187069,1.419527,0.072314,1.870692,-212.618942,0.185916,0.000000
265.309998,0.310555,-212.663422,0.009727,0.007328,0.186124,1.381415,0.070373,1.861240,-212.663422,0.184832,0.000000
265.960022,0.307579,-212.752396,0.009671,0.007272,0.184719,1.368180,0.069698,1.847191,-212.752396,0.183748,0.000000
266.610016,0.316887,-212.796875,0.009597,0.007233,0.183713,1.409583,0.071808,1.837131,-212.796875,0.182664,0.000000
267.260010,0.309067,-212.885834,0.009580,0.007187,0.182560,1.374798,0.070036,1.825597,-212.885834,0.181580,0.000000
267.910004,0.318008,-212.885834,0.009533,0.007145,0.181493,1.414572,0.072062,1.814930,-212.885834,0.180496,0.000000
268.559998,0.325829,-212.930313,0.009494,0.007110,0.180600,1.449358,0.073834,1.805997,-212.930313,0.179412,0.000000
269.210022,0.328056,-212.974792,0.009447,0.007063,0.179394,1.459267,0.074339,1.793943,-212.974792,0.178328,0.000000
269.860016,0.344070,-213.063751,0.009416,0.007014,0.178163,1.530502,0.077967,1.781628,-213.063751,0.177252,0.000000
270.510010,0.336998,-213.108231,0.009360,0.006982,0.177348,1.499042,0.076365,1.773476,-213.108231,0.176168,0.000000
271.160004,0.330292,-213.152710,0.009326,0.006935,0.176160,1.469211,0.074845,1.761595,-213.152710,0.175084,0.000000
271.810028,0.342583,-213.197205,0.009274,0.006884,0.174841,1.523884,0.077630,1.748414,-213.197205,0.174000,0.000000
272.460022,0.326569,-213.241684,0.009214,0.006846,0.173887,1.452650,0.074001,1.738874,-213.241684,0.172916,0.000000
273.110016,0.328804,-213.286163,0.009179,0.006804,0.172829,1.462593,0.074508,1.728294,-213.286163,0.171832,0.000000
273.760010,0.357101,-213.375122,0.009145,0.006765,0.171823,1.588467,0.080920,1.718234,-213.375122,0.170748,0.000000
274.410004,0.350403,-213.375122,0.009089,0.006720,0.170687,1.558670,0.079402,1.706874,-213.375122,0.169664,0.000000
274.600006,0.374977,-213.419601,0.009067,0.006716,0.170583,1.667982,0.084971,1.705833,-213.419601,0.170479,0.000000