File: Data/PDMS compression/PDMS 0024 Punched_3_16th_1_1_03202024_155725.csv
Time (sec),S:Load (lbs),S:HL1 (DIM),S:LVDT (in),S:Position (in),Ch:Position (mm),Ch:Load (N),Ch:Stress (MPa),Ch:Strain (mm/mm),Ch:HL1 (DIM),Set Point (),Cycles ()
0.110000,-0.006706,-88.205727,-0.000009,-0.000000,-0.000000,-0.029831,-0.001520,-0.000000,-88.205727,0.000182,0.000000
0.890000,-0.020111,-88.250206,0.000125,0.000137,0.003486,-0.089459,-0.004557,0.034863,-88.250206,0.004509,0.000000
1.670000,-0.008568,-88.339172,0.000379,0.000395,0.010025,-0.038112,-0.001941,0.100251,-88.339172,0.011005,0.000000
2.450000,0.007820,-88.294685,0.000655,0.000650,0.016521,0.034786,0.001772,0.165207,-88.294685,0.017509,0.000000
3.230000,-0.014526,-88.383652,0.000927,0.000906,0.023007,-0.064617,-0.003292,0.230072,-88.383652,0.024005,0.000000
4.010000,-0.068146,-88.339172,0.001181,0.001160,0.029460,-0.303127,-0.015442,0.294597,-88.339172,0.030500,0.000000
4.790000,-0.063675,-88.383652,0.001449,0.001415,0.035946,-0.283240,-0.014429,0.359463,-88.383652,0.036996,0.000000
5.570000,-0.025322,-88.472610,0.001707,0.001671,0.042433,-0.112638,-0.005738,0.424332,-88.472610,0.043500,0.000000
6.350000,-0.014526,-88.517090,0.001970,0.001929,0.049007,-0.064617,-0.003292,0.490068,-88.517090,0.049995,0.000000
7.130000,-0.014526,-88.517090,0.002242,0.002185,0.055494,-0.064617,-0.003292,0.554938,-88.517090,0.056491,0.000000
7.910000,-0.045059,-88.472610,0.002505,0.002438,0.061928,-0.200433,-0.010211,0.619285,-88.472610,0.062986,0.000000
8.690001,-0.059204,-88.561577,0.002768,0.002691,0.068363,-0.263353,-0.013416,0.683632,-88.561577,0.069482,0.000000
9.470000,-0.010796,-88.606056,0.003044,0.002950,0.074919,-0.048021,-0.002446,0.749193,-88.606056,0.075986,0.000000
10.250001,-0.014153,-88.695015,0.003320,0.003208,0.081493,-0.062954,-0.003207,0.814930,-88.695015,0.082482,0.000000
11.030001,-0.003723,-88.606056,0.003583,0.003461,0.087902,-0.016561,-0.000844,0.879019,-88.606056,0.088977,0.000000
11.810000,-0.018616,-88.606056,0.003854,0.003716,0.094380,-0.082807,-0.004218,0.943801,-88.606056,0.095473,0.000000
12.590000,-0.031654,-88.606056,0.004118,0.003971,0.100858,-0.140806,-0.007173,1.008584,-88.606056,0.101968,0.000000
13.370001,-0.046173,-88.695015,0.004376,0.004228,0.107397,-0.205388,-0.010463,1.073972,-88.695015,0.108472,0.000000
14.150001,-0.021599,-88.783981,0.004648,0.004486,0.113953,-0.096076,-0.004894,1.139534,-88.783981,0.114968,0.000000
14.930000,-0.004471,-88.783981,0.004915,0.004741,0.120432,-0.019887,-0.001013,1.204316,-88.783981,0.121464,0.000000
15.710001,0.001862,-88.739494,0.005182,0.004993,0.126823,0.008281,0.000422,1.268231,-88.739494,0.127959,0.000000
16.490002,-0.026070,-88.783981,0.005458,0.005248,0.133310,-0.115964,-0.005907,1.333097,-88.783981,0.134455,0.000000
17.270000,-0.029419,-88.828461,0.005717,0.005506,0.139849,-0.130862,-0.006666,1.398488,-88.828461,0.140959,0.000000
18.050001,0.029045,-88.872940,0.005976,0.005764,0.146414,0.129199,0.006582,1.464137,-88.872940,0.147454,0.000000
18.830002,0.128838,-88.961899,0.006260,0.006024,0.153004,0.573098,0.029195,1.530044,-88.961899,0.153950,0.000000
19.610001,0.451691,-88.828461,0.006510,-0.000002,-0.000044,2.009220,0.102355,-0.000435,-88.828461,0.001223,0.000000
20.390001,0.412216,-88.961899,0.006510,-0.000002,-0.000052,1.833629,0.093410,-0.000522,-88.961899,0.000590,0.000000
21.170000,0.491531,-89.050865,0.006549,0.000041,0.001040,2.186441,0.111383,0.010405,-89.050865,0.001891,0.000000
21.950001,0.548874,-89.095345,0.006601,0.000092,0.002333,2.441513,0.124377,0.023326,-89.095345,0.003191,0.000000
22.730001,0.578667,-88.961899,0.006648,0.000138,0.003504,2.574038,0.131128,0.035037,-88.961899,0.004492,0.000000
23.510000,0.671387,-89.139824,0.006700,0.000193,0.004909,2.986477,0.152138,0.049086,-89.139824,0.005784,0.000000
24.290001,0.707138,-89.095345,0.006752,0.000243,0.006166,3.145507,0.160240,0.061660,-89.095345,0.007085,0.000000
25.070002,0.781609,-89.139824,0.006804,0.000291,0.007397,3.476769,0.177115,0.073972,-89.139824,0.008386,0.000000
25.850000,0.852730,-89.184303,0.006855,0.000345,0.008759,3.793132,0.193231,0.087590,-89.184303,0.009687,0.000000
26.630001,0.912682,-89.184303,0.006911,0.000395,0.010042,4.059811,0.206817,0.100425,-89.184303,0.010988,0.000000
27.410002,0.983063,-89.184303,0.006963,0.000447,0.011343,4.372881,0.222765,0.113433,-89.184303,0.012288,0.000000
28.190001,1.025513,-89.184303,0.007023,0.000498,0.012644,4.561708,0.232385,0.126442,-89.184303,0.013589,0.000000
28.970001,1.143555,-89.273270,0.007080,0.000548,0.013928,5.086785,0.259133,0.139277,-89.273270,0.014890,0.000000
29.750002,1.205368,-89.273270,0.007127,0.000602,0.015298,5.361745,0.273140,0.152978,-89.273270,0.016191,0.000000
30.530001,1.197922,-89.317749,0.007157,0.000647,0.016443,5.328622,0.271453,0.164427,-89.317749,0.017492,0.000000
31.310001,1.369957,-89.317749,0.007222,0.000702,0.017839,6.093873,0.310437,0.178390,-89.317749,0.018793,0.000000
32.090000,1.414642,-89.362228,0.007282,0.000754,0.019157,6.292644,0.320563,0.191569,-89.362228,0.020085,0.000000
32.870003,1.543114,-89.406715,0.007330,0.000806,0.020466,6.864112,0.349675,0.204664,-89.406715,0.021386,0.000000
33.650002,1.625778,-89.406715,0.007403,0.000857,0.021767,7.231822,0.368407,0.217673,-89.406715,0.022687,0.000000
34.430000,1.701744,-89.406715,0.007433,0.000909,0.023077,7.569736,0.385621,0.230769,-89.406715,0.023988,0.000000
35.210003,1.767281,-89.495674,0.007480,0.000955,0.024265,7.861257,0.400472,0.242650,-89.495674,0.025288,0.000000
35.990002,1.839890,-89.451195,0.007549,0.001011,0.025670,8.184237,0.416925,0.256699,-89.451195,0.026589,0.000000
36.770000,1.965752,-89.540154,0.007601,0.001061,0.026945,8.744100,0.445446,0.269447,-89.540154,0.027890,0.000000
37.550003,2.058105,-89.540154,0.007644,0.001117,0.028367,9.154910,0.466373,0.283670,-89.540154,0.029191,0.000000
38.330002,2.124756,-89.629120,0.007700,0.001167,0.029642,9.451386,0.481477,0.296418,-89.629120,0.030491,0.000000
39.110001,2.263649,-89.629120,0.007743,0.001219,0.030968,10.069214,0.512950,0.309684,-89.629120,0.031792,0.000000
39.890003,2.301262,-89.629120,0.007800,0.001268,0.032217,10.236525,0.521473,0.322174,-89.629120,0.033093,0.000000
40.670002,2.384300,-89.629120,0.007864,0.001315,0.033397,10.605897,0.540290,0.333968,-89.629120,0.034394,0.000000
41.450001,2.489311,-89.718079,0.007920,0.001369,0.034776,11.073009,0.564086,0.347756,-89.718079,0.035686,0.000000
42.230003,2.598045,-89.762558,0.007972,0.001421,0.036085,11.556683,0.588725,0.360852,-89.762558,0.036987,0.000000
43.010002,2.700447,-89.807037,0.008019,0.001472,0.037395,12.012189,0.611930,0.373948,-89.807037,0.038288,0.000000
43.790001,2.729492,-89.762558,0.008063,0.001521,0.038643,12.141388,0.618512,0.386434,-89.762558,0.039589,0.000000
44.570004,2.818489,-89.851524,0.008114,0.001569,0.039858,12.537266,0.638679,0.398576,-89.851524,0.040890,0.000000
45.350002,2.942856,-89.896004,0.008179,0.001628,0.041358,13.090477,0.666861,0.413579,-89.896004,0.042191,0.000000
46.130001,3.030365,-89.940483,0.008235,0.001677,0.042590,13.479736,0.686691,0.425895,-89.940483,0.043491,0.000000
46.910004,3.123459,-89.896004,0.008282,0.001732,0.043986,13.893839,0.707786,0.439858,-89.896004,0.044792,0.000000
47.690002,3.166283,-89.940483,0.008317,0.001777,0.045130,14.084329,0.717490,0.451303,-89.940483,0.046093,0.000000
48.470001,3.301453,-90.029442,0.008386,0.001830,0.046483,14.685595,0.748120,0.464834,-90.029442,0.047394,0.000000
49.250004,3.390450,-89.984962,0.008442,0.001882,0.047810,15.081472,0.768287,0.478100,-89.984962,0.048695,0.000000
50.030003,3.463806,-90.073929,0.008489,0.001929,0.048998,15.407780,0.784910,0.489981,-90.073929,0.049987,0.000000
50.810001,3.555412,-90.029442,0.008541,0.001980,0.050299,15.815264,0.805668,0.502990,-90.029442,0.051288,0.000000
51.590004,3.573662,-90.118408,0.008597,0.002033,0.051626,15.896441,0.809803,0.516260,-90.118408,0.052588,0.000000
52.370003,3.717392,-90.073929,0.008662,0.002082,0.052883,16.535786,0.842373,0.528833,-90.073929,0.053889,0.000000
53.150002,3.813095,-90.162888,0.008709,0.002139,0.054323,16.961494,0.864060,0.543231,-90.162888,0.055190,0.000000
53.930004,3.901718,-90.207367,0.008757,0.002186,0.055529,17.355709,0.884142,0.555286,-90.207367,0.056491,0.000000
54.710003,4.032051,-90.207367,0.008813,0.002241,0.056916,17.935459,0.913676,0.569161,-90.207367,0.057792,0.000000
55.490002,4.026833,-90.251846,0.008852,0.002288,0.058113,17.912247,0.912493,0.581129,-90.251846,0.059093,0.000000
56.270004,4.120300,-90.207367,0.008908,0.002336,0.059327,18.328011,0.933673,0.593267,-90.207367,0.060394,0.000000
57.050003,4.238342,-90.296333,0.008985,0.002395,0.060836,18.853088,0.960422,0.608358,-90.296333,0.061695,0.000000
57.830002,4.293083,-90.340813,0.009024,0.002445,0.062102,19.096588,0.972827,0.621018,-90.340813,0.062995,0.000000
58.610004,4.404793,-90.385292,0.009063,0.002497,0.063411,19.593496,0.998140,0.634114,-90.385292,0.064296,0.000000
59.390003,4.434586,-90.340813,0.009127,0.002547,0.064704,19.726023,1.004892,0.647035,-90.340813,0.065588,0.000000
60.170002,4.505333,-90.340813,0.009192,0.002594,0.065892,20.040722,1.020923,0.658916,-90.340813,0.066889,0.000000
60.950005,4.577202,-90.385292,0.009227,0.002647,0.067236,20.360411,1.037209,0.672360,-90.385292,0.068190,0.000000
61.730003,4.695618,-90.518738,0.009296,0.002702,0.068641,20.887150,1.064042,0.686410,-90.518738,0.069491,0.000000
62.510002,4.779770,-90.474251,0.009330,0.002752,0.069890,21.261478,1.083111,0.698896,-90.474251,0.070792,0.000000
63.290005,4.834511,-90.429771,0.009390,0.002802,0.071182,21.504978,1.095516,0.711818,-90.429771,0.072092,0.000000
64.070000,4.889992,-90.474251,0.009425,0.002850,0.072379,21.751770,1.108088,0.723785,-90.474251,0.073393,0.000000
64.850006,4.930214,-90.563217,0.009498,0.002905,0.073792,21.930687,1.117202,0.737922,-90.563217,0.074694,0.000000
65.630005,5.028519,-90.652176,0.009554,0.002955,0.075050,22.367968,1.139479,0.750495,-90.652176,0.075995,0.000000
66.410004,5.079903,-90.607697,0.009602,0.003007,0.076385,22.596535,1.151122,0.763852,-90.607697,0.077296,0.000000
67.190002,5.129433,-90.563217,0.009658,0.003057,0.077643,22.816856,1.162346,0.776426,-90.563217,0.078597,0.000000
67.970001,5.280617,-90.652176,0.009727,0.003110,0.078996,23.489357,1.196605,0.789957,-90.652176,0.079889,0.000000
68.750000,5.264603,-90.741142,0.009753,0.003162,0.080305,23.418121,1.192976,0.803049,-90.741142,0.081190,0.000000
69.530006,5.337585,-90.741142,0.009800,0.003210,0.081536,23.742765,1.209514,0.815365,-90.741142,0.082490,0.000000
70.310005,5.419136,-90.741142,0.009860,0.003262,0.082855,24.105520,1.227994,0.828548,-90.741142,0.083791,0.000000
71.090004,5.372215,-90.785622,0.009904,0.003310,0.084078,23.896807,1.217361,0.840777,-90.785622,0.085092,0.000000
71.870003,5.504036,-90.785622,0.009985,0.003361,0.085370,24.483175,1.247232,0.853698,-90.785622,0.086393,0.000000
72.650002,5.469406,-90.874580,0.010037,0.003413,0.086696,24.329134,1.239385,0.866964,-90.874580,0.087694,0.000000
73.430000,5.611282,-90.874580,0.010059,0.003464,0.087997,24.960230,1.271535,0.879973,-90.874580,0.088995,0.000000
74.210007,5.756508,-90.874580,0.010128,0.003520,0.089411,25.606226,1.304443,0.894110,-90.874580,0.090295,0.000000
74.990005,5.747200,-90.919067,0.010167,0.003569,0.090660,25.564823,1.302334,0.906596,-90.919067,0.091596,0.000000
75.770004,5.810875,-90.963547,0.010236,0.003616,0.091839,25.848063,1.316763,0.918390,-90.963547,0.092897,0.000000
76.550003,5.889442,-91.052505,0.010287,0.003672,0.093279,26.197548,1.334567,0.932787,-91.052505,0.094198,0.000000
77.330002,5.976578,-91.052505,0.010343,0.003725,0.094614,26.585146,1.354312,0.946144,-91.052505,0.095490,0.000000
78.110001,6.028709,-91.052505,0.010391,0.003775,0.095889,26.817039,1.366125,0.958892,-91.052505,0.096791,0.000000
78.890007,6.023872,-91.052505,0.010442,0.003825,0.097155,26.795523,1.365029,0.971552,-91.052505,0.098092,0.000000
79.670006,6.143402,-91.141472,0.010507,0.003880,0.098543,27.327217,1.392115,0.985428,-91.141472,0.099393,0.000000
80.450005,6.093132,-91.052505,0.010559,0.003928,0.099774,27.103605,1.380723,0.997744,-91.052505,0.100693,0.000000
81.230003,6.217133,-91.141472,0.010624,0.003982,0.101145,27.655188,1.408822,1.011445,-91.141472,0.101994,0.000000
82.010002,6.252876,-91.141472,0.010667,0.004031,0.102384,27.814182,1.416922,1.023844,-91.141472,0.103295,0.000000
82.790001,6.328842,-91.141472,0.010718,0.004083,0.103720,28.152096,1.434136,1.037201,-91.141472,0.104596,0.000000
83.570007,6.339638,-91.274910,0.010749,0.004131,0.104926,28.200117,1.436582,1.049256,-91.274910,0.105897,0.000000
84.350006,6.388420,-91.230431,0.010813,0.004184,0.106261,28.417112,1.447637,1.062609,-91.230431,0.107198,0.000000
85.130005,6.450233,-91.319389,0.010865,0.004237,0.107614,28.692072,1.461644,1.076140,-91.319389,0.108499,0.000000
85.910004,6.507210,-91.319389,0.010934,0.004288,0.108924,28.945515,1.474555,1.089236,-91.319389,0.109791,0.000000
86.690002,6.486725,-91.363876,0.010973,0.004334,0.110086,28.854393,1.469913,1.100856,-91.363876,0.111092,0.000000
87.470001,6.652809,-91.408356,0.011029,0.004392,0.111568,29.593174,1.507548,1.115685,-91.408356,0.112392,0.000000
88.250008,6.561951,-91.408356,0.011085,0.004441,0.112809,29.189014,1.486959,1.128088,-91.408356,0.113693,0.000000
89.030006,6.583916,-91.363876,0.011141,0.004487,0.113971,29.286720,1.491937,1.139708,-91.363876,0.114994,0.000000
89.810005,6.647964,-91.497314,0.011188,0.004542,0.115367,29.571623,1.506450,1.153670,-91.497314,0.116295,0.000000
90.590004,6.703445,-91.541794,0.011240,0.004592,0.116642,29.818415,1.519022,1.166418,-91.541794,0.117596,0.000000
91.370003,6.780899,-91.541794,0.011292,0.004645,0.117986,30.162945,1.536574,1.179862,-91.541794,0.118896,0.000000
92.150002,6.719460,-91.452835,0.011331,0.004694,0.119217,29.889648,1.522651,1.192174,-91.452835,0.120197,0.000000
92.930008,6.805107,-91.586281,0.011408,0.004745,0.120518,30.270628,1.542059,1.205182,-91.586281,0.121498,0.000000
93.710007,6.882187,-91.630760,0.011456,0.004799,0.121888,30.613497,1.559526,1.218884,-91.630760,0.122799,0.000000
94.490005,6.797661,-91.630760,0.011490,0.004844,0.123042,30.237505,1.540372,1.230420,-91.630760,0.124100,0.000000
95.270004,6.990547,-91.630760,0.011555,0.004898,0.124403,31.095507,1.584081,1.244034,-91.630760,0.125392,0.000000
96.050003,6.918678,-91.719719,0.011615,0.004951,0.125765,30.775818,1.567795,1.257649,-91.719719,0.126693,0.000000
96.830002,7.020714,-91.808685,0.011650,0.005001,0.127023,31.229694,1.590917,1.270226,-91.808685,0.127994,0.000000
97.610008,7.076569,-91.764198,0.011710,0.005053,0.128340,31.478149,1.603573,1.283405,-91.764198,0.129295,0.000000
98.390007,7.116035,-91.764198,0.011758,0.005106,0.129702,31.653708,1.612517,1.297023,-91.764198,0.130596,0.000000
99.170006,7.197212,-91.764198,0.011822,0.005157,0.130994,32.014797,1.630912,1.309945,-91.764198,0.131896,0.000000
99.950005,7.159981,-91.808685,0.011865,0.005209,0.132313,31.849186,1.622475,1.323127,-91.808685,0.133197,0.000000
100.730003,7.222908,-91.897644,0.011926,0.005258,0.133561,32.129101,1.636734,1.335614,-91.897644,0.134498,0.000000
101.510002,7.269829,-91.942123,0.011973,0.005313,0.134958,32.337814,1.647367,1.349576,-91.942123,0.135799,0.000000
102.290009,7.289192,-91.942123,0.012033,0.005363,0.136232,32.423946,1.651755,1.362324,-91.942123,0.137099,0.000000
103.070007,7.393456,-91.942123,0.012081,0.005416,0.137577,32.887733,1.675381,1.375768,-91.942123,0.138400,0.000000
103.850006,7.370743,-91.942123,0.012150,0.005464,0.138791,32.786701,1.670234,1.387906,-91.942123,0.139701,0.000000
104.630005,7.324196,-92.031090,0.012180,0.005510,0.139962,32.579651,1.659687,1.399616,-92.031090,0.140993,0.000000
105.410004,7.483200,-92.031090,0.012240,0.005570,0.141479,33.286938,1.695717,1.414790,-92.031090,0.142294,0.000000
106.190002,7.477242,-92.075569,0.012292,0.005619,0.142719,33.260433,1.694367,1.427193,-92.075569,0.143595,0.000000
106.970009,7.531609,-92.120049,0.012353,0.005667,0.143951,33.502270,1.706687,1.439509,-92.120049,0.144896,0.000000
107.750008,7.448196,-92.120049,0.012387,0.005717,0.145208,33.131233,1.687785,1.452083,-92.120049,0.146197,0.000000
108.530006,7.502563,-92.164528,0.012443,0.005765,0.146422,33.373070,1.700105,1.464224,-92.164528,0.147498,0.000000
109.310005,7.581131,-92.209015,0.012508,0.005825,0.147949,33.722553,1.717909,1.479485,-92.209015,0.148799,0.000000
110.090004,7.633263,-92.209015,0.012559,0.005876,0.149241,33.954449,1.729722,1.492407,-92.209015,0.150099,0.000000
110.870003,7.671616,-92.253494,0.012611,0.005929,0.150585,34.125050,1.738413,1.505851,-92.253494,0.151400,0.000000
111.650002,7.580017,-92.297974,0.012667,0.005972,0.151695,33.717602,1.717656,1.516952,-92.297974,0.152701,0.000000
112.430008,7.690239,-92.297974,0.012710,0.006026,0.153065,34.207890,1.742633,1.530653,-92.297974,0.154002,0.000000
113.210007,7.709969,-92.297974,0.012766,0.006078,0.154392,34.295654,1.747104,1.543923,-92.297974,0.155294,0.000000
113.990005,7.731194,-92.342453,0.012810,0.006127,0.155615,34.390068,1.751914,1.556148,-92.342453,0.156595,0.000000
114.770004,7.817963,-92.342453,0.012874,0.006179,0.156951,34.776035,1.771576,1.569505,-92.342453,0.157896,0.000000
115.550003,7.720398,-92.431419,0.012913,0.006228,0.158199,34.342045,1.749467,1.581991,-92.431419,0.159196,0.000000
116.330002,7.810509,-92.520378,0.012956,0.006278,0.159466,34.742878,1.769887,1.594656,-92.520378,0.160497,0.000000
117.110008,7.824287,-92.431419,0.013029,0.006337,0.160948,34.804169,1.773009,1.609485,-92.431419,0.161798,0.000000
117.890007,7.940094,-92.431419,0.013068,0.006386,0.162206,35.319302,1.799251,1.622058,-92.431419,0.163099,0.000000
118.670006,7.997818,-92.475899,0.013137,0.006438,0.163515,35.576073,1.812332,1.635154,-92.475899,0.164400,0.000000
119.450005,7.964676,-92.564857,0.013176,0.006487,0.164773,35.428646,1.804821,1.647727,-92.564857,0.165701,0.000000
120.230003,7.980316,-92.564857,0.013241,0.006536,0.166013,35.498219,1.808365,1.660131,-92.564857,0.167002,0.000000
121.010002,8.082718,-92.564857,0.013279,0.006592,0.167444,35.953724,1.831570,1.674438,-92.564857,0.168303,0.000000
121.790009,8.071175,-92.564857,0.013348,0.006641,0.168675,35.902378,1.828954,1.686754,-92.564857,0.169603,0.000000
122.570007,8.138947,-92.564857,0.013387,0.006696,0.170072,36.203842,1.844312,1.700716,-92.564857,0.170896,0.000000
123.350006,8.097610,-92.609337,0.013443,0.006744,0.171294,36.019970,1.834945,1.712945,-92.609337,0.172196,0.000000
124.130005,8.130753,-92.698303,0.013482,0.006792,0.172526,36.167393,1.842455,1.725257,-92.698303,0.173497,0.000000
124.910004,8.135963,-92.698303,0.013542,0.006843,0.173818,36.190575,1.843636,1.738179,-92.698303,0.174798,0.000000
125.690002,8.214165,-92.831741,0.013599,0.006897,0.175188,36.538429,1.861356,1.751880,-92.831741,0.176099,0.000000
126.470009,8.287895,-92.831741,0.013650,0.006949,0.176498,36.866398,1.878064,1.764976,-92.831741,0.177400,0.000000
127.250008,8.281563,-92.787262,0.013702,0.006998,0.177755,36.838230,1.876629,1.777553,-92.787262,0.178700,0.000000
128.029999,8.237251,-92.831741,0.013758,0.007047,0.178987,36.641125,1.866588,1.789865,-92.831741,0.180001,0.000000
128.810013,8.286034,-92.920708,0.013818,0.007103,0.180418,36.858120,1.877642,1.804176,-92.920708,0.181302,0.000000
129.590012,8.335556,-92.920708,0.013857,0.007151,0.181632,37.078403,1.888864,1.816318,-92.920708,0.182603,0.000000
130.370010,8.436844,-92.965187,0.013913,0.007207,0.183062,37.528957,1.911816,1.830625,-92.965187,0.183904,0.000000
131.150009,8.368698,-92.965187,0.013965,0.007254,0.184259,37.225830,1.896374,1.842593,-92.965187,0.185196,0.000000
131.930008,8.465515,-92.965187,0.014012,0.007306,0.185578,37.656490,1.918313,1.855776,-92.965187,0.186497,0.000000
132.710007,8.422691,-93.054146,0.014077,0.007358,0.186887,37.466003,1.908609,1.868871,-93.054146,0.187798,0.000000
133.490005,8.516533,-93.098633,0.014129,0.007408,0.188171,37.883430,1.929874,1.881706,-93.098633,0.189099,0.000000
134.270004,8.548927,-93.098633,0.014168,0.007462,0.189523,38.027527,1.937215,1.895233,-93.098633,0.190400,0.000000
135.050003,8.454346,-93.143112,0.014228,0.007506,0.190660,37.606808,1.915782,1.906595,-93.143112,0.191700,0.000000
135.830002,8.537384,-93.098633,0.014275,0.007556,0.191926,37.976181,1.934599,1.919256,-93.098633,0.193001,0.000000
136.610001,8.482643,-93.098633,0.014327,0.007614,0.193400,37.732681,1.922194,1.933998,-93.098633,0.194302,0.000000
137.389999,8.631966,-93.232071,0.014388,0.007663,0.194640,38.396900,1.956031,1.946401,-93.232071,0.195603,0.000000
138.170013,8.791710,-93.232071,0.014439,0.007720,0.196080,39.107479,1.992230,1.960795,-93.232071,0.196903,0.000000
138.950012,8.654305,-93.276558,0.014495,0.007765,0.197233,38.496269,1.961093,1.972332,-93.276558,0.198204,0.000000
139.730011,8.670319,-93.276558,0.014538,0.007812,0.198413,38.567505,1.964722,1.984125,-93.276558,0.199505,0.000000
140.510010,8.725433,-93.321037,0.014599,0.007870,0.199895,38.812668,1.977211,1.998954,-93.321037,0.200797,0.000000
141.290009,8.782776,-93.365517,0.014651,0.007922,0.201222,39.067738,1.990205,2.012224,-93.365517,0.202098,0.000000
142.070007,8.811073,-93.365517,0.014694,0.007971,0.202462,39.193611,1.996618,2.024624,-93.365517,0.203399,0.000000
142.850006,8.862839,-93.365517,0.014745,0.008025,0.203824,39.423874,2.008348,2.038242,-93.365517,0.204700,0.000000
143.630005,8.938797,-93.409996,0.014797,0.008077,0.205159,39.761753,2.025560,2.051595,-93.409996,0.206001,0.000000
144.410004,8.868423,-93.498962,0.014862,0.008125,0.206382,39.448719,2.009614,2.063824,-93.498962,0.207302,0.000000
145.190002,8.953323,-93.543442,0.014909,0.008179,0.207752,39.826370,2.028852,2.077525,-93.543442,0.208603,0.000000
145.970001,8.935448,-93.587921,0.014957,0.008227,0.208975,39.746857,2.024801,2.089754,-93.587921,0.209903,0.000000
146.750000,9.024071,-93.543442,0.015013,0.008279,0.210285,40.141071,2.044884,2.102850,-93.543442,0.211204,0.000000
147.530014,9.086258,-93.587921,0.015047,0.008330,0.211586,40.417694,2.058975,2.115859,-93.587921,0.212505,0.000000
148.310013,9.027428,-93.632401,0.015099,0.008380,0.212852,40.156002,2.045644,2.128519,-93.632401,0.213806,0.000000
149.090012,9.093338,-93.632401,0.015164,0.008434,0.214213,40.449188,2.060580,2.142133,-93.632401,0.215098,0.000000
149.870010,9.163712,-93.632401,0.015215,0.008484,0.215497,40.762226,2.076527,2.154968,-93.632401,0.216399,0.000000
150.650009,9.094078,-93.721367,0.015263,0.008531,0.216694,40.452480,2.060747,2.166936,-93.721367,0.217700,0.000000
151.430008,9.362564,-93.765846,0.015315,0.008588,0.218133,41.646767,2.121587,2.181333,-93.765846,0.219000,0.000000
152.210007,9.193878,-93.765846,0.015358,0.008637,0.219391,40.896412,2.083363,2.193907,-93.765846,0.220301,0.000000
152.990005,9.153656,-93.765846,0.015405,0.008684,0.220570,40.717495,2.074248,2.205701,-93.765846,0.221602,0.000000
153.770004,9.208023,-93.765846,0.015474,0.008737,0.221923,40.959332,2.086568,2.219232,-93.765846,0.222903,0.000000
154.550003,9.327187,-93.810326,0.015517,0.008788,0.223215,41.489399,2.113571,2.232153,-93.810326,0.224204,0.000000
155.330002,9.364426,-93.899284,0.015560,0.008841,0.224551,41.655045,2.122009,2.245506,-93.899284,0.225505,0.000000
156.110001,9.286224,-93.943771,0.015612,0.008891,0.225834,41.307190,2.104288,2.258341,-93.943771,0.226806,0.000000
156.890015,9.385277,-93.899284,0.015659,0.008941,0.227109,41.747795,2.126734,2.271088,-93.899284,0.228106,0.000000
157.670013,9.450439,-93.943771,0.015737,0.008999,0.228566,42.037655,2.141500,2.285660,-93.943771,0.229407,0.000000
158.450012,9.325699,-94.032730,0.015776,0.009042,0.229667,41.482780,2.113234,2.296674,-94.032730,0.230699,0.000000
159.230011,9.561783,-94.077209,0.015828,0.009096,0.231046,42.532936,2.166731,2.310463,-94.077209,0.232000,0.000000
160.010010,9.403893,-94.032730,0.015871,0.009149,0.232390,41.830605,2.130952,2.323903,-94.032730,0.233301,0.000000
160.790009,9.547630,-94.032730,0.015922,0.009197,0.233613,42.469982,2.163524,2.336132,-94.032730,0.234602,0.000000
161.570007,9.552841,-94.077209,0.015996,0.009251,0.234966,42.493160,2.164705,2.349659,-94.077209,0.235903,0.000000
162.350006,9.619125,-94.166176,0.016043,0.009304,0.236310,42.788006,2.179725,2.363103,-94.166176,0.237204,0.000000
163.130005,9.701416,-94.166176,0.016086,0.009355,0.237611,43.154053,2.198372,2.376112,-94.166176,0.238504,0.000000
163.910004,9.707375,-94.166176,0.016129,0.009406,0.238921,43.180557,2.199723,2.389207,-94.166176,0.239805,0.000000
164.690002,9.753181,-94.166176,0.016194,0.009457,0.240195,43.384319,2.210103,2.401955,-94.166176,0.241106,0.000000
165.470001,9.748711,-94.255135,0.016250,0.009510,0.241548,43.364429,2.209089,2.415482,-94.255135,0.242407,0.000000
166.250015,9.812386,-94.299614,0.016289,0.009560,0.242832,43.647671,2.223518,2.428317,-94.299614,0.243708,0.000000
167.030014,9.902130,-94.299614,0.016349,0.009613,0.244167,44.046875,2.243855,2.441674,-94.299614,0.245008,0.000000
167.810013,9.849998,-94.255135,0.016401,0.009660,0.245364,43.814983,2.232042,2.453641,-94.255135,0.246301,0.000000
168.590012,9.768822,-94.344101,0.016444,0.009706,0.246535,43.453888,2.213647,2.465348,-94.344101,0.247601,0.000000
169.370010,10.043259,-94.388580,0.016500,0.009766,0.248061,44.674644,2.275835,2.480613,-94.388580,0.248902,0.000000
170.150009,10.013466,-94.433060,0.016556,0.009815,0.249310,44.542122,2.269084,2.493099,-94.433060,0.250203,0.000000
170.930008,10.011978,-94.433060,0.016608,0.009864,0.250542,44.535503,2.268747,2.505415,-94.433060,0.251504,0.000000
171.710007,9.949791,-94.433060,0.016668,0.009914,0.251808,44.258881,2.254655,2.518075,-94.433060,0.252805,0.000000
172.490005,9.978836,-94.477539,0.016716,0.009960,0.252987,44.388081,2.261236,2.529869,-94.477539,0.254106,0.000000
173.270004,10.141563,-94.522018,0.016763,0.010021,0.254539,45.111927,2.298111,2.545395,-94.522018,0.255407,0.000000
174.050003,10.202263,-94.566505,0.016815,0.010069,0.255753,45.381931,2.311866,2.557533,-94.566505,0.256707,0.000000
174.830002,10.144539,-94.522018,0.016849,0.010119,0.257020,45.125164,2.298785,2.570197,-94.522018,0.258008,0.000000
175.610016,10.134865,-94.566505,0.016923,0.010168,0.258260,45.082130,2.296593,2.582597,-94.566505,0.259309,0.000000
176.390015,10.255882,-94.655464,0.016966,0.010221,0.259621,45.620441,2.324016,2.596215,-94.655464,0.260601,0.000000
177.170013,10.298706,-94.699944,0.017018,0.010275,0.260992,45.810932,2.333720,2.609916,-94.699944,0.261902,0.000000
177.950012,10.366478,-94.655464,0.017065,0.010328,0.262327,46.112396,2.349077,2.623269,-94.655464,0.263203,0.000000
178.730011,10.558624,-94.699944,0.017121,0.010383,0.263732,46.967106,2.392618,2.637319,-94.699944,0.264504,0.000000
179.510010,10.249550,-94.744423,0.017173,0.010424,0.264773,45.592274,2.322581,2.647727,-94.744423,0.265804,0.000000
180.290009,10.395523,-94.833389,0.017216,0.010474,0.266047,46.241596,2.355659,2.660475,-94.833389,0.267105,0.000000
181.070007,10.452126,-94.788910,0.017276,0.010533,0.267548,46.493378,2.368486,2.675478,-94.788910,0.268406,0.000000
181.850006,10.587669,-94.744423,0.017315,0.010583,0.268796,47.096306,2.399200,2.687964,-94.744423,0.269707,0.000000
182.630005,10.634583,-94.833389,0.017388,0.010634,0.270097,47.304985,2.409831,2.700973,-94.833389,0.271008,0.000000
183.410004,10.609261,-94.922348,0.017419,0.010683,0.271338,47.192348,2.404093,2.713376,-94.922348,0.272309,0.000000
184.190002,10.621178,-94.966827,0.017479,0.010733,0.272612,47.245358,2.406793,2.726124,-94.966827,0.273610,0.000000
184.970001,10.791725,-94.922348,0.017531,0.010789,0.274043,48.003990,2.445440,2.740434,-94.922348,0.274911,0.000000
185.750015,10.763802,-94.966827,0.017600,0.010838,0.275275,47.879780,2.439112,2.752747,-94.966827,0.276203,0.000000
186.530014,10.856888,-95.011314,0.017634,0.010893,0.276671,48.293850,2.460206,2.766709,-95.011314,0.277504,0.000000
187.310013,10.800659,-95.011314,0.017703,0.010939,0.277859,48.043732,2.447464,2.778590,-95.011314,0.278804,0.000000
188.090012,10.857262,-95.100273,0.017746,0.010987,0.279082,48.295513,2.460291,2.790819,-95.100273,0.280105,0.000000
188.870010,10.818161,-95.055794,0.017789,0.011039,0.280383,48.121582,2.451430,2.803828,-95.055794,0.281406,0.000000
189.650009,10.987595,-95.011314,0.017845,0.011094,0.281796,48.875263,2.489825,2.817964,-95.011314,0.282707,0.000000
190.430008,11.045311,-95.144753,0.017906,0.011144,0.283045,49.131996,2.502903,2.830451,-95.144753,0.284008,0.000000
191.210007,11.060577,-95.233719,0.017949,0.011194,0.284320,49.199905,2.506363,2.843198,-95.233719,0.285308,0.000000
191.990005,10.993179,-95.233719,0.018001,0.011241,0.285534,48.900105,2.491090,2.855340,-95.233719,0.286609,0.000000
192.770004,11.101166,-95.233719,0.018052,0.011300,0.287008,49.380451,2.515560,2.870082,-95.233719,0.287910,0.000000
193.550003,11.125374,-95.233719,0.018108,0.011347,0.288205,49.488136,2.521046,2.882050,-95.233719,0.289211,0.000000
194.330002,11.261658,-95.233719,0.018160,0.011402,0.289610,50.094357,2.551928,2.896099,-95.233719,0.290503,0.000000
195.110016,11.187927,-95.367157,0.018208,0.011450,0.290824,49.766384,2.535220,2.908241,-95.367157,0.291804,0.000000
195.890015,11.350655,-95.322678,0.018264,0.011501,0.292125,50.490234,2.572095,2.921250,-95.322678,0.293105,0.000000
196.670013,11.383423,-95.322678,0.018315,0.011555,0.293486,50.635994,2.579520,2.934864,-95.322678,0.294406,0.000000
197.450012,11.292564,-95.367157,0.018363,0.011602,0.294683,50.231834,2.558932,2.946832,-95.367157,0.295707,0.000000
198.230011,11.466095,-95.456123,0.018427,0.011657,0.296079,51.003738,2.598254,2.960795,-95.456123,0.297008,0.000000
199.010010,11.348419,-95.500603,0.018466,0.011702,0.297224,50.480289,2.571589,2.972244,-95.500603,0.298308,0.000000
199.790009,11.447098,-95.456123,0.018518,0.011752,0.298490,50.919235,2.593950,2.984905,-95.456123,0.299609,0.000000
200.570007,11.523064,-95.500603,0.018583,0.011811,0.300008,51.257149,2.611163,3.000082,-95.500603,0.300910,0.000000
201.350006,11.577805,-95.500603,0.018626,0.011857,0.301170,51.500648,2.623568,3.011702,-95.500603,0.302211,0.000000
202.130005,11.842934,-95.589561,0.018695,0.011915,0.302644,52.680000,2.683647,3.026444,-95.589561,0.303511,0.000000
202.910004,11.654510,-95.589561,0.018729,0.011962,0.303832,51.841850,2.640950,3.038324,-95.589561,0.304812,0.000000
203.690002,11.631798,-95.589561,0.018772,0.012006,0.304951,51.740822,2.635803,3.049513,-95.589561,0.306105,0.000000
204.470016,11.813889,-95.678528,0.018841,0.012066,0.306477,52.550800,2.677065,3.064773,-95.678528,0.307405,0.000000
205.250015,11.854851,-95.634048,0.018880,0.012116,0.307752,52.733009,2.686348,3.077525,-95.634048,0.308706,0.000000
206.030014,11.921135,-95.723007,0.018936,0.012169,0.309088,53.027855,2.701368,3.090878,-95.723007,0.310007,0.000000
206.810013,11.980713,-95.767487,0.018988,0.012221,0.310423,53.292873,2.714868,3.104235,-95.767487,0.311308,0.000000
207.590012,12.105827,-95.767487,0.019040,0.012274,0.311759,53.849411,2.743220,3.117588,-95.767487,0.312609,0.000000
208.370010,11.995979,-95.767487,0.019096,0.012321,0.312947,53.360783,2.718328,3.129468,-95.767487,0.313910,0.000000
209.150009,12.126678,-95.811966,0.019139,0.012375,0.314317,53.942162,2.747945,3.143174,-95.811966,0.315211,0.000000
209.930008,12.129288,-95.856453,0.019195,0.012424,0.315557,53.953766,2.748536,3.155573,-95.856453,0.316511,0.000000
210.710007,12.264084,-95.856453,0.019251,0.012475,0.316858,54.553371,2.779081,3.168581,-95.856453,0.317812,0.000000
211.490005,12.365372,-95.945412,0.019303,0.012526,0.318150,55.003922,2.802033,3.181503,-95.945412,0.319113,0.000000
212.270004,12.225731,-96.078857,0.019350,0.012575,0.319416,54.382767,2.770390,3.194164,-96.078857,0.320405,0.000000
213.050003,12.330368,-95.989891,0.019415,0.012630,0.320796,54.848217,2.794101,3.207956,-95.989891,0.321706,0.000000
213.830017,12.401489,-96.078857,0.019458,0.012679,0.322053,55.164577,2.810218,3.220529,-96.078857,0.323007,0.000000
214.610016,12.477455,-96.034370,0.019492,0.012731,0.323362,55.502491,2.827432,3.233625,-96.034370,0.324308,0.000000
215.390015,12.793228,-96.034370,0.019566,0.012784,0.324707,56.907120,2.898987,3.247065,-96.034370,0.325608,0.000000
216.170013,12.492348,-96.078857,0.019613,0.012834,0.325973,55.568737,2.830806,3.259726,-96.078857,0.326909,0.000000
216.950012,12.494957,-96.123337,0.019669,0.012878,0.327109,55.580345,2.831398,3.271088,-96.123337,0.328210,0.000000
217.730011,12.671837,-96.167816,0.019717,0.012936,0.328574,56.367146,2.871479,3.285743,-96.167816,0.329511,0.000000
218.510010,12.739609,-96.123337,0.019773,0.012986,0.329832,56.668610,2.886837,3.298320,-96.123337,0.330812,0.000000
219.290009,12.734764,-96.167816,0.019807,0.013034,0.331063,56.647060,2.885739,3.310632,-96.167816,0.332113,0.000000
220.070007,12.706841,-96.212296,0.019863,0.013087,0.332408,56.522850,2.879411,3.324076,-96.212296,0.333414,0.000000
220.850006,12.843124,-96.256775,0.019915,0.013137,0.333674,57.129070,2.910294,3.336737,-96.256775,0.334715,0.000000
221.630005,13.009201,-96.345741,0.019962,0.013195,0.335148,57.867817,2.947927,3.351479,-96.345741,0.336007,0.000000
222.410004,12.770142,-96.301262,0.020023,0.013236,0.336189,56.804428,2.893755,3.361887,-96.301262,0.337308,0.000000
223.190018,13.043465,-96.256775,0.020066,0.013289,0.337541,58.020229,2.955691,3.375415,-96.256775,0.338608,0.000000
223.970016,12.991699,-96.301262,0.020130,0.013345,0.338973,57.789963,2.943961,3.389725,-96.301262,0.339909,0.000000
224.750015,13.128365,-96.390221,0.020182,0.013394,0.340195,58.397881,2.974930,3.401951,-96.390221,0.341210,0.000000
225.530014,13.169327,-96.345741,0.020208,0.013447,0.341557,58.580090,2.984212,3.415569,-96.345741,0.342511,0.000000
226.310013,13.280289,-96.390221,0.020281,0.013500,0.342901,59.073673,3.009356,3.429009,-96.390221,0.343812,0.000000
227.090012,13.386787,-96.390221,0.020333,0.013550,0.344176,59.547405,3.033489,3.441756,-96.390221,0.345112,0.000000
227.870010,13.430359,-96.479179,0.020381,0.013602,0.345503,59.741219,3.043363,3.455026,-96.479179,0.346413,0.000000
228.650009,13.507812,-96.523666,0.020445,0.013652,0.346769,60.085751,3.060914,3.467687,-96.523666,0.347714,0.000000
229.430008,13.504089,-96.568146,0.020484,0.013705,0.348096,60.069191,3.060071,3.480957,-96.568146,0.349015,0.000000
230.210007,13.579308,-96.568146,0.020536,0.013755,0.349388,60.403778,3.077115,3.493878,-96.568146,0.350307,0.000000
230.990005,13.823952,-96.612625,0.020596,0.013810,0.350775,61.492008,3.132552,3.507754,-96.612625,0.351608,0.000000
231.770004,13.676498,-96.657104,0.020644,0.013857,0.351972,60.836102,3.099139,3.519722,-96.657104,0.352909,0.000000
232.550018,13.600906,-96.657104,0.020687,0.013902,0.353100,60.499851,3.082009,3.530997,-96.657104,0.354210,0.000000
233.330017,14.058922,-96.612625,0.020743,0.013962,0.354626,62.537209,3.185797,3.546257,-96.612625,0.355510,0.000000
234.110016,13.969925,-96.701584,0.020799,0.014012,0.355892,62.141331,3.165630,3.558922,-96.701584,0.356811,0.000000
234.890015,14.014610,-96.746071,0.020859,0.014061,0.357158,62.340099,3.175756,3.571582,-96.746071,0.358112,0.000000
235.670013,13.918167,-96.835030,0.020894,0.014109,0.358372,61.911098,3.153902,3.583724,-96.835030,0.359413,0.000000
236.450012,13.945351,-96.835030,0.020950,0.014156,0.359552,62.032017,3.160062,3.595518,-96.835030,0.360714,0.000000
237.230011,14.238403,-96.790550,0.021006,0.014218,0.361139,63.335583,3.226468,3.611388,-96.790550,0.362015,0.000000
238.010010,14.345650,-96.790550,0.021057,0.014267,0.362379,63.812637,3.250771,3.623787,-96.790550,0.363315,0.000000
238.790009,14.342300,-96.835030,0.021105,0.014316,0.363636,63.797737,3.250012,3.636364,-96.835030,0.364616,0.000000
239.570007,14.285698,-96.968475,0.021152,0.014364,0.364833,63.545959,3.237185,3.648332,-96.968475,0.365909,0.000000
240.350006,14.444702,-97.012955,0.021191,0.014413,0.366082,64.253242,3.273216,3.660819,-97.012955,0.367209,0.000000
241.130005,14.595886,-96.968475,0.021256,0.014471,0.367556,64.925743,3.307475,3.675561,-96.968475,0.368510,0.000000
241.910019,14.845741,-97.012955,0.021295,0.014523,0.368883,66.037155,3.364093,3.688831,-97.012955,0.369811,0.000000
242.690018,14.836807,-97.057434,0.021359,0.014570,0.370080,65.997414,3.362069,3.700798,-97.057434,0.371112,0.000000
243.470016,14.671844,-97.146400,0.021415,0.014621,0.371372,65.263626,3.324687,3.713720,-97.146400,0.372413,0.000000
244.250015,14.962669,-97.101913,0.021441,0.014669,0.372586,66.557274,3.390589,3.725862,-97.101913,0.373713,0.000000
245.030014,15.065071,-97.101913,0.021514,0.014731,0.374156,67.012787,3.413794,3.741558,-97.101913,0.375014,0.000000
245.810013,15.241203,-97.101913,0.021571,0.014778,0.375370,67.796257,3.453706,3.753700,-97.101913,0.376315,0.000000
246.590012,15.332809,-97.190880,0.021635,0.014831,0.376705,68.203743,3.474464,3.767053,-97.190880,0.377616,0.000000
247.370010,15.313072,-97.190880,0.021674,0.014879,0.377919,68.115944,3.469992,3.779195,-97.190880,0.378917,0.000000
248.150009,15.373024,-97.279839,0.021721,0.014930,0.379220,68.382629,3.483577,3.792204,-97.279839,0.380218,0.000000
248.930008,15.631454,-97.279839,0.021773,0.014986,0.380634,69.532181,3.542138,3.806340,-97.279839,0.381510,0.000000
249.710007,15.691406,-97.235359,0.021825,0.015033,0.381848,69.798859,3.555723,3.818482,-97.235359,0.382811,0.000000
250.490005,15.913338,-97.279839,0.021877,0.015090,0.383279,70.786064,3.606014,3.832789,-97.279839,0.384112,0.000000
251.270020,15.863068,-97.368805,0.021928,0.015135,0.384433,70.562447,3.594623,3.844325,-97.368805,0.385412,0.000000
252.050018,15.931580,-97.413284,0.021971,0.015184,0.385672,70.867203,3.610147,3.856725,-97.413284,0.386713,0.000000
252.830017,16.210487,-97.413284,0.022036,0.015240,0.387104,72.107849,3.673349,3.871035,-97.413284,0.388014,0.000000
253.610016,16.430565,-97.457764,0.022084,0.015293,0.388431,73.086800,3.723219,3.884305,-97.457764,0.389315,0.000000
254.390015,16.470032,-97.502243,0.022140,0.015340,0.389644,73.262360,3.732163,3.896443,-97.502243,0.390616,0.000000
255.170013,16.578018,-97.546722,0.022183,0.015392,0.390954,73.742706,3.756633,3.909539,-97.546722,0.391916,0.000000
255.950012,16.554565,-97.546722,0.022234,0.015438,0.392125,73.638382,3.751318,3.921246,-97.546722,0.393217,0.000000
256.730011,16.938103,-97.591209,0.022295,0.015497,0.393634,75.344444,3.838229,3.936336,-97.591209,0.394518,0.000000
257.510010,17.058380,-97.591209,0.022347,0.015545,0.394839,75.879463,3.865484,3.948391,-97.591209,0.395810,0.000000
258.290009,17.354790,-97.591209,0.022390,0.015598,0.396192,77.197960,3.932652,3.961918,-97.591209,0.397111,0.000000
259.070007,17.243454,-97.680168,0.022437,0.015646,0.397406,76.702713,3.907423,3.974060,-97.680168,0.398412,0.000000
259.850006,17.636673,-97.680168,0.022485,0.015698,0.398724,78.451843,3.996527,3.987243,-97.680168,0.399713,0.000000
260.630005,17.678757,-97.724648,0.022549,0.015750,0.400051,78.639038,4.006063,4.000513,-97.724648,0.401014,0.000000
261.410004,17.864571,-97.724648,0.022588,0.015799,0.401300,79.465576,4.048170,4.012999,-97.724648,0.402315,0.000000
262.190002,18.173637,-97.769127,0.022648,0.015853,0.402661,80.840378,4.118206,4.026614,-97.769127,0.403616,0.000000
262.970001,18.109962,-97.858093,0.022683,0.015901,0.403884,80.557137,4.103776,4.038843,-97.858093,0.404916,0.000000
263.750000,18.296150,-97.769127,0.022752,0.015948,0.405090,81.385338,4.145967,4.050898,-97.769127,0.406217,0.000000
264.529999,18.647293,-97.813614,0.022795,0.016008,0.406599,82.947304,4.225537,4.065988,-97.813614,0.407518,0.000000
265.309998,18.742622,-97.858093,0.022847,0.016052,0.407726,83.371346,4.247139,4.077263,-97.858093,0.408819,0.000000
266.090027,19.267296,-97.902573,0.022903,0.016114,0.409287,85.705215,4.366032,4.092872,-97.902573,0.410119,0.000000
266.870026,19.150368,-97.902573,0.022950,0.016157,0.410389,85.185089,4.339535,4.103886,-97.902573,0.411412,0.000000
267.650024,19.624397,-97.902573,0.023002,0.016213,0.411802,87.293678,4.446952,4.118022,-97.902573,0.412713,0.000000
268.430023,19.592751,-97.947052,0.023062,0.016262,0.413042,87.152908,4.439781,4.130422,-97.947052,0.414013,0.000000
269.210022,20.004593,-97.991531,0.023110,0.016317,0.414447,88.984871,4.533105,4.144471,-97.991531,0.415314,0.000000
269.990021,20.076836,-98.036018,0.023149,0.016365,0.415679,89.306229,4.549476,4.156787,-98.036018,0.416615,0.000000
270.770020,20.483093,-98.080498,0.023209,0.016417,0.416997,91.113350,4.641535,4.169966,-98.080498,0.417916,0.000000
271.550018,20.915787,-98.124977,0.023252,0.016471,0.418358,93.038063,4.739585,4.183584,-98.124977,0.419217,0.000000
272.330017,20.805565,-98.080498,0.023299,0.016517,0.419520,92.547775,4.714609,4.195204,-98.080498,0.420518,0.000000
273.110016,21.264328,-98.169456,0.023351,0.016571,0.420899,94.588455,4.818566,4.208992,-98.169456,0.421819,0.000000
273.890015,21.491852,-98.213943,0.023412,0.016622,0.422209,95.600533,4.870123,4.222088,-98.213943,0.423119,0.000000
274.670013,21.707077,-98.213943,0.023446,0.016671,0.423432,96.557899,4.918894,4.234317,-98.213943,0.424420,0.000000
275.450012,22.143501,-98.258423,0.023489,0.016722,0.424741,98.499214,5.017789,4.247409,-98.258423,0.425712,0.000000
276.230011,22.257446,-98.302902,0.023554,0.016775,0.426077,99.006065,5.043609,4.260766,-98.302902,0.427013,0.000000
277.010010,22.670776,-98.258423,0.023606,0.016826,0.427377,100.844650,5.137271,4.273775,-98.258423,0.428314,0.000000
277.790009,22.960861,-98.391861,0.023657,0.016875,0.428617,102.135010,5.203006,4.286174,-98.391861,0.429615,0.000000
278.570007,23.272163,-98.391861,0.023696,0.016929,0.429988,103.519753,5.273548,4.299879,-98.391861,0.430916,0.000000
279.350006,23.945038,-98.436348,0.023731,0.016981,0.431306,106.512848,5.426023,4.313058,-98.436348,0.432216,0.000000
280.130005,23.822899,-98.347382,0.023791,0.017029,0.432537,105.969543,5.398346,4.325374,-98.347382,0.433517,0.000000
280.910004,24.006111,-98.436348,0.023847,0.017073,0.433665,106.784515,5.439862,4.336649,-98.436348,0.434818,0.000000
281.690002,24.603020,-98.480827,0.023890,0.017131,0.435139,109.439697,5.575124,4.351391,-98.480827,0.436119,0.000000
282.470001,25.142960,-98.525307,0.023942,0.017183,0.436449,111.841469,5.697476,4.364487,-98.525307,0.437420,0.000000
283.250000,25.444580,-98.480827,0.023989,0.017233,0.437706,113.183144,5.765824,4.377061,-98.480827,0.438721,0.000000
284.029999,25.579384,-98.525307,0.024041,0.017283,0.438981,113.782784,5.796371,4.389808,-98.525307,0.440022,0.000000
284.810028,26.019150,-98.525307,0.024084,0.017332,0.440239,115.738960,5.896024,4.402385,-98.525307,0.441314,0.000000
285.590027,26.756821,-98.614265,0.024136,0.017391,0.441721,119.020279,6.063182,4.417215,-98.614265,0.442615,0.000000
286.370026,26.989555,-98.703232,0.024170,0.017439,0.442953,120.055542,6.115921,4.429527,-98.703232,0.443916,0.000000
287.150024,27.578278,-98.614265,0.024213,0.017490,0.444236,122.674309,6.249327,4.442361,-98.614265,0.445216,0.000000
287.930023,27.706741,-98.658752,0.024282,0.017541,0.445537,123.245743,6.278437,4.455370,-98.658752,0.446517,0.000000
288.710022,28.249664,-98.658752,0.024334,0.017589,0.446769,125.660782,6.401465,4.467686,-98.658752,0.447818,0.000000
289.490021,28.916580,-98.792191,0.024364,0.017645,0.448191,128.627380,6.552591,4.481910,-98.792191,0.449119,0.000000
290.270020,29.635262,-98.747711,0.024420,0.017699,0.449544,131.824234,6.715446,4.495437,-98.747711,0.450420,0.000000
291.050018,30.125679,-98.747711,0.024472,0.017751,0.450871,134.005707,6.826576,4.508707,-98.747711,0.451720,0.000000
291.830017,30.535286,-98.836670,0.024528,0.017798,0.452067,135.827728,6.919395,4.520675,-98.836670,0.453021,0.000000
292.610016,31.101295,-98.836670,0.024580,0.017848,0.453351,138.345474,7.047654,4.533509,-98.836670,0.454322,0.000000
293.390015,31.678841,-98.925636,0.024623,0.017902,0.454704,140.914520,7.178528,4.547037,-98.925636,0.455614,0.000000
294.170013,32.275383,-98.925636,0.024671,0.017951,0.455961,143.568069,7.313706,4.559614,-98.925636,0.456915,0.000000
294.950012,33.180618,-98.970116,0.024705,0.018006,0.457358,147.594757,7.518836,4.573576,-98.970116,0.458216,0.000000
295.730011,33.461388,-98.925636,0.024765,0.018052,0.458528,148.843689,7.582459,4.585283,-98.925636,0.459517,0.000000
296.510010,32.177452,-98.970116,0.024791,0.018056,0.458632,143.132462,7.291515,4.586324,-98.970116,0.458676,0.000000
297.290009,31.156029,-99.059074,0.024804,0.018020,0.457696,138.588943,7.060057,4.576956,-99.059074,0.457375,0.000000
298.070007,30.478310,-99.059074,0.024808,0.017967,0.456369,135.574295,6.906484,4.563686,-99.059074,0.456074,0.000000
298.850006,30.073174,-99.103561,0.024804,0.017925,0.455285,133.772156,6.814679,4.552846,-99.103561,0.454782,0.000000
299.630005,29.746605,-99.103561,0.024808,0.017871,0.453932,132.319504,6.740677,4.539319,-99.103561,0.453481,0.000000
300.410004,29.454659,-99.237000,0.024817,0.017823,0.452700,131.020859,6.674521,4.527003,-99.237000,0.452180,0.000000
301.190002,28.547562,-99.192520,0.024813,0.017771,0.451374,126.985893,6.468970,4.513737,-99.192520,0.450879,0.000000
301.970001,27.148186,-99.192520,0.024796,0.017719,0.450064,120.761162,6.151867,4.500641,-99.192520,0.449579,0.000000
302.750000,25.258400,-99.237000,0.024796,0.017682,0.449119,112.354973,5.723635,4.491187,-99.237000,0.448278,0.000000
303.530029,22.168076,-99.281487,0.024796,0.017630,0.447809,98.608528,5.023357,4.478095,-99.281487,0.446977,0.000000
304.310028,18.616013,-99.325966,0.024765,0.017582,0.446595,82.808159,4.218449,4.465953,-99.325966,0.445676,0.000000
305.090027,15.190933,-99.414925,0.024727,0.017536,0.445407,67.572647,3.442315,4.454072,-99.414925,0.444375,0.000000
305.870026,11.661217,-99.325966,0.024714,0.017487,0.444158,51.871681,2.642469,4.441582,-99.325966,0.443074,0.000000
306.650024,8.385826,-99.325966,0.024662,0.017434,0.442832,37.302017,1.900255,4.428316,-99.325966,0.441773,0.000000
307.430023,5.176720,-99.459404,0.024636,0.017376,0.441357,23.027199,1.173061,4.413570,-99.459404,0.440472,0.000000
308.210022,2.901527,-99.459404,0.024589,0.017324,0.440039,12.906638,0.657495,4.400391,-99.459404,0.439180,0.000000
308.990021,1.791481,-99.503891,0.024545,0.017275,0.438781,7.968905,0.405955,4.387814,-99.503891,0.437879,0.000000
309.770020,1.366608,-99.503891,0.024494,0.017228,0.437585,6.078975,0.309678,4.375846,-99.503891,0.436579,0.000000
310.550018,1.218033,-99.503891,0.024442,0.017169,0.436093,5.418081,0.276010,4.360929,-99.503891,0.435278,0.000000
311.330017,1.119354,-99.548370,0.024382,0.017127,0.435018,4.979136,0.253649,4.350177,-99.548370,0.433977,0.000000
312.110016,0.968170,-99.637329,0.024313,0.017066,0.433465,4.306636,0.219390,4.334655,-99.637329,0.432676,0.000000
312.890015,0.833740,-99.592850,0.024252,0.017014,0.432165,3.708662,0.188928,4.321646,-99.592850,0.431375,0.000000
313.670013,0.762993,-99.592850,0.024209,0.016959,0.430751,3.393962,0.172897,4.307509,-99.592850,0.430075,0.000000
314.450012,0.733574,-99.681808,0.024162,0.016915,0.429650,3.263100,0.166230,4.296495,-99.681808,0.428774,0.000000
315.230011,0.627449,-99.726295,0.024119,0.016872,0.428539,2.791033,0.142182,4.285394,-99.726295,0.427473,0.000000
316.010010,0.568237,-99.726295,0.024067,0.016806,0.426883,2.527646,0.128764,4.268832,-99.726295,0.426172,0.000000
316.790009,0.517601,-99.770775,0.023989,0.016757,0.425617,2.302404,0.117290,4.256171,-99.770775,0.424880,0.000000
317.570007,0.474030,-99.770775,0.023963,0.016718,0.424646,2.108589,0.107417,4.246455,-99.770775,0.423579,0.000000
318.350006,0.457275,-99.815254,0.023899,0.016656,0.423059,2.034063,0.103620,4.230585,-99.815254,0.422278,0.000000
319.130005,0.428230,-99.859734,0.023856,0.016609,0.421870,1.904863,0.097038,4.218705,-99.859734,0.420977,0.000000
319.910004,0.393967,-99.948700,0.023795,0.016552,0.420414,1.752451,0.089274,4.204136,-99.948700,0.419676,0.000000
320.690002,0.360832,-99.993179,0.023739,0.016502,0.419156,1.605062,0.081766,4.191563,-99.993179,0.418375,0.000000
321.470001,0.347420,-99.859734,0.023700,0.016451,0.417847,1.545400,0.078726,4.178467,-99.859734,0.417075,0.000000
322.250031,0.366043,-99.948700,0.023640,0.016407,0.416728,1.628241,0.082947,4.167279,-99.948700,0.415774,0.000000
323.030029,0.350029,-99.993179,0.023610,0.016357,0.415471,1.557007,0.079318,4.154706,-99.993179,0.414473,0.000000
323.810028,0.317261,-100.082138,0.023532,0.016298,0.413979,1.411246,0.071892,4.139790,-100.082138,0.413172,0.000000
324.590027,0.324333,-100.037659,0.023493,0.016251,0.412773,1.442706,0.073495,4.127735,-100.037659,0.411871,0.000000
325.370026,0.332527,-100.082138,0.023442,0.016199,0.411455,1.479155,0.075352,4.114552,-100.082138,0.410571,0.000000
326.150024,0.323219,-100.037659,0.023407,0.016149,0.410180,1.437751,0.073243,4.101804,-100.037659,0.409278,0.000000
326.930023,0.309067,-100.215584,0.023343,0.016097,0.408853,1.374798,0.070036,4.088534,-100.215584,0.407978,0.000000
327.710022,0.335136,-100.260063,0.023282,0.016047,0.407605,1.490761,0.075943,4.076048,-100.260063,0.406677,0.000000
328.490021,0.312424,-100.171104,0.023222,0.015993,0.406226,1.389730,0.070796,4.062260,-100.171104,0.405376,0.000000
329.270020,0.322472,-100.171104,0.023183,0.015935,0.404751,1.434425,0.073073,4.047513,-100.171104,0.404075,0.000000
330.050018,0.325455,-100.260063,0.023144,0.015893,0.403685,1.447695,0.073749,4.036848,-100.260063,0.402774,0.000000
330.830017,0.268478,-100.260063,0.023080,0.015840,0.402341,1.194252,0.060838,4.023407,-100.260063,0.401473,0.000000
331.610016,0.308327,-100.349022,0.023028,0.015787,0.400988,1.371506,0.069868,4.009877,-100.349022,0.400172,0.000000
332.390015,0.285980,-100.393509,0.022976,0.015735,0.399678,1.272104,0.064804,3.996781,-100.393509,0.398872,0.000000
333.170013,0.283005,-100.349022,0.022924,0.015679,0.398256,1.258868,0.064130,3.982561,-100.349022,0.397571,0.000000
333.950012,0.281883,-100.393509,0.022894,0.015635,0.397137,1.253879,0.063876,3.971373,-100.393509,0.396270,0.000000
334.730011,0.275558,-100.482468,0.022829,0.015587,0.395914,1.225745,0.062442,3.959144,-100.482468,0.394969,0.000000
335.510010,0.275185,-100.437988,0.022765,0.015531,0.394484,1.224082,0.062358,3.944837,-100.437988,0.393677,0.000000
336.290009,0.267738,-100.482468,0.022709,0.015479,0.393174,1.190960,0.060670,3.931741,-100.482468,0.392376,0.000000
336.600006,0.291199,-100.482468,0.022722,0.015473,0.393009,1.295317,0.065987,3.930091,-100.482468,0.392949,0.000000