File: Data/PDMS compression/PDMS 0010 Punched_2_07152024_151155.csv
Time (sec),S:Load (lbs),S:HL1 (DIM),S:LVDT (in),S:Position (in),Ch:Position (mm),Ch:Load (N),Ch:Stress (MPa),Ch:Strain (mm/mm),Ch:HL1 (DIM),Set Point (),Cycles ()
0.110000,0.017502,-109.556580,-0.000004,-0.000000,-0.000000,0.077852,0.003966,-0.000000,-109.556580,-0.000260,0.000000
0.370000,-0.000000,-109.601067,0.000000,-0.000000,-0.000000,-0.000000,-0.000000,-0.000000,-109.601067,-0.000260,0.000000
0.630000,-0.013405,-109.645546,0.000000,0.000048,0.001223,-0.059628,-0.003038,0.012228,-109.645546,0.001830,0.000000
0.890000,-0.004471,-109.601067,0.000004,0.000131,0.003321,-0.019887,-0.001013,0.033215,-109.601067,0.003998,0.000000
1.150000,-0.014153,-109.690025,-0.000017,0.000192,0.004882,-0.062954,-0.003207,0.048825,-109.690025,0.006166,0.000000
1.410000,-0.049530,-109.645546,0.000065,0.000284,0.007215,-0.220321,-0.011224,0.072153,-109.645546,0.008325,0.000000
1.670000,-0.006332,-109.690025,0.000172,0.000380,0.009644,-0.028168,-0.001435,0.096436,-109.690025,0.010493,0.000000
1.930000,0.003723,-109.734505,0.000224,0.000449,0.011404,0.016561,0.000844,0.114040,-109.734505,0.012661,0.000000
2.190000,-0.060699,-109.734505,0.000328,0.000542,0.013763,-0.270005,-0.013755,0.137629,-109.734505,0.014830,0.000000
2.450000,-0.004845,-109.823471,0.000418,0.000635,0.016122,-0.021550,-0.001098,0.161217,-109.823471,0.016989,0.000000
2.710000,0.046173,-109.778984,0.000504,0.000710,0.018030,0.205388,0.010463,0.180296,-109.778984,0.019157,0.000000
2.970000,0.038353,-109.912430,0.000595,0.000796,0.020206,0.170603,0.008691,0.202064,-109.912430,0.021325,0.000000
3.230000,0.118416,-109.912430,0.000677,0.000886,0.022513,0.526740,0.026833,0.225132,-109.912430,0.023484,0.000000
3.490000,0.211136,-109.912430,0.000763,0.000966,0.024542,0.939179,0.047844,0.245425,-109.912430,0.025653,0.000000
3.750000,0.380188,-109.956909,0.000858,0.001054,0.026771,1.691161,0.086152,0.267713,-109.956909,0.027821,0.000000
4.010000,0.443123,-109.956909,0.000862,-0.000003,-0.000078,1.971109,0.100413,-0.000781,-109.956909,0.000069,0.000000
4.270000,0.433441,-110.001389,0.000875,-0.000004,-0.000095,1.928043,0.098219,-0.000954,-110.001389,0.000069,0.000000
4.530000,0.415565,-110.045876,0.000888,-0.000004,-0.000095,1.848528,0.094168,-0.000954,-110.045876,0.000416,0.000000
4.790000,0.427856,-110.045876,0.000862,-0.000004,-0.000095,1.903201,0.096954,-0.000954,-110.045876,0.000850,0.000000
5.050000,0.498230,-110.134834,0.000875,0.000014,0.000356,2.216238,0.112901,0.003556,-110.134834,0.001283,0.000000
5.310000,0.529137,-110.090355,0.000880,0.000024,0.000598,2.353717,0.119904,0.005984,-110.090355,0.001717,0.000000
5.570000,0.640854,-110.134834,0.000880,0.000042,0.001075,2.850660,0.145220,0.010754,-110.134834,0.002151,0.000000
5.830000,0.778999,-110.134834,0.000927,0.000067,0.001708,3.465162,0.176524,0.017084,-110.134834,0.002584,0.000000
6.090000,0.813629,-110.179314,0.000944,0.000078,0.001977,3.619203,0.184371,0.019773,-110.179314,0.003018,0.000000
6.350000,0.890717,-110.223793,0.000944,0.000097,0.002463,3.962105,0.201839,0.024629,-110.223793,0.003452,0.000000
6.610000,1.037430,-110.223793,0.001005,0.000118,0.002992,4.614718,0.235085,0.029919,-110.223793,0.003885,0.000000
6.870000,1.136482,-110.312759,0.000983,0.000136,0.003443,5.055326,0.257531,0.034429,-110.312759,0.004319,0.000000
7.130000,1.227341,-110.312759,0.001013,0.000149,0.003772,5.459484,0.278119,0.037724,-110.312759,0.004752,0.000000
7.390000,1.277237,-110.401718,0.001035,0.000159,0.004050,5.681434,0.289426,0.040499,-110.401718,0.005186,0.000000
7.650001,1.502525,-110.357239,0.001035,0.000184,0.004674,6.683567,0.340477,0.046743,-110.357239,0.005620,0.000000
7.910000,1.627266,-110.446205,0.001065,0.000203,0.005160,7.238441,0.368744,0.051600,-110.446205,0.006045,0.000000
8.170000,1.721474,-110.446205,0.001074,0.000219,0.005550,7.657497,0.390092,0.055502,-110.446205,0.006478,0.000000
8.430000,1.841377,-110.490685,0.001112,0.000236,0.005984,8.190855,0.417262,0.059839,-110.490685,0.006912,0.000000
8.690001,1.995918,-110.446205,0.001130,0.000256,0.006513,8.878288,0.452282,0.065129,-110.446205,0.007345,0.000000
8.950001,2.075974,-110.535164,0.001138,0.000271,0.006877,9.234391,0.470422,0.068771,-110.535164,0.007779,0.000000
9.210000,2.137047,-110.535164,0.001147,0.000282,0.007172,9.506059,0.484262,0.071720,-110.535164,0.008213,0.000000
9.470000,2.329185,-110.579643,0.001164,0.000306,0.007762,10.360735,0.527801,0.077617,-110.579643,0.008646,0.000000
9.730000,2.419678,-110.535164,0.001194,0.000323,0.008195,10.763264,0.548307,0.081953,-110.535164,0.009080,0.000000
9.990001,2.401054,-110.668610,0.001212,0.000332,0.008438,10.680424,0.544087,0.084381,-110.668610,0.009513,0.000000
10.250001,2.544418,-110.713089,0.001207,0.000352,0.008941,11.318138,0.576573,0.089411,-110.713089,0.009947,0.000000
10.510000,2.779762,-110.668610,0.001237,0.000374,0.009487,12.365000,0.629903,0.094874,-110.668610,0.010381,0.000000
10.770000,2.735077,-110.713089,0.001246,0.000388,0.009843,12.166229,0.619777,0.098430,-110.713089,0.010814,0.000000
11.030001,2.769707,-110.757568,0.001272,0.000399,0.010147,12.320271,0.627625,0.101465,-110.757568,0.011248,0.000000
11.290001,2.930946,-110.802048,0.001285,0.000419,0.010641,13.037500,0.664162,0.106409,-110.802048,0.011682,0.000000
11.550000,3.117874,-110.757568,0.001311,0.000441,0.011196,13.868997,0.706520,0.111959,-110.757568,0.012115,0.000000
11.810000,3.129044,-110.846527,0.001337,0.000457,0.011612,13.918681,0.709051,0.116122,-110.846527,0.012549,0.000000
12.070001,3.183784,-110.935493,0.001350,0.000473,0.012020,14.162181,0.721456,0.120197,-110.935493,0.012982,0.000000
12.330001,3.284325,-110.891014,0.001332,0.000489,0.012419,14.609406,0.744239,0.124187,-110.891014,0.013416,0.000000
12.590000,3.403481,-110.935493,0.001362,0.000505,0.012826,15.139438,0.771240,0.128263,-110.935493,0.013850,0.000000
12.850000,3.443329,-110.935493,0.001362,0.000521,0.013234,15.316691,0.780269,0.132339,-110.935493,0.014283,0.000000
13.110001,3.313744,-110.979973,0.001388,0.000526,0.013364,14.740268,0.750905,0.133639,-110.979973,0.014717,0.000000
13.370001,3.752396,-111.068932,0.001423,0.000560,0.014214,16.691490,0.850305,0.142138,-111.068932,0.015150,0.000000
13.630001,3.811974,-111.024452,0.001449,0.000581,0.014752,16.956505,0.863806,0.147515,-111.024452,0.015584,0.000000
13.890000,3.688721,-111.068932,0.001457,0.000589,0.014960,16.408249,0.835876,0.149596,-111.068932,0.016018,0.000000
14.150001,3.875648,-111.068932,0.001479,0.000609,0.015480,17.239746,0.878235,0.154800,-111.068932,0.016451,0.000000
14.410001,3.972466,-111.157898,0.001483,0.000627,0.015914,17.670408,0.900174,0.159136,-111.157898,0.016885,0.000000
14.670001,3.976189,-111.157898,0.001496,0.000641,0.016269,17.686970,0.901017,0.162692,-111.157898,0.017318,0.000000
14.930000,4.150093,-111.113419,0.001518,0.000664,0.016859,18.460535,0.940425,0.168589,-111.113419,0.017752,0.000000
15.190001,4.229774,-111.202377,0.001526,0.000680,0.017284,18.814976,0.958481,0.172838,-111.202377,0.018186,0.000000
15.450001,4.318405,-111.202377,0.001539,0.000702,0.017830,19.209225,0.978565,0.178302,-111.202377,0.018619,0.000000
15.710001,4.315422,-111.246857,0.001578,0.000715,0.018168,19.195955,0.977889,0.181684,-111.246857,0.019053,0.000000
15.970001,4.450966,-111.380302,0.001595,0.000731,0.018576,19.798885,1.008603,0.185760,-111.380302,0.019487,0.000000
16.230001,4.396599,-111.291336,0.001595,0.000743,0.018871,19.557049,0.996284,0.188708,-111.291336,0.019920,0.000000
16.490002,4.641624,-111.424782,0.001625,0.000764,0.019417,20.646976,1.051807,0.194172,-111.424782,0.020354,0.000000
16.750000,4.659126,-111.424782,0.001634,0.000779,0.019790,20.724829,1.055773,0.197901,-111.424782,0.020787,0.000000
17.010000,4.676628,-111.424782,0.001660,0.000791,0.020094,20.802681,1.059739,0.200936,-111.424782,0.021212,0.000000
17.270000,5.088470,-111.513741,0.001673,0.000823,0.020909,22.634647,1.153064,0.209088,-111.513741,0.021646,0.000000
17.530001,4.937660,-111.469261,0.001694,0.000839,0.021299,21.963810,1.118890,0.212991,-111.469261,0.022080,0.000000
17.790001,4.893715,-111.558228,0.001712,0.000850,0.021603,21.768332,1.108932,0.216026,-111.558228,0.022513,0.000000
18.050001,5.107834,-111.513741,0.001738,0.000868,0.022045,22.720779,1.157452,0.220449,-111.513741,0.022947,0.000000
18.310001,5.094055,-111.602707,0.001750,0.000881,0.022366,22.659489,1.154329,0.223658,-111.602707,0.023380,0.000000
18.570002,5.206512,-111.558228,0.001763,0.000899,0.022834,23.159723,1.179813,0.228341,-111.558228,0.023814,0.000000
18.830002,5.476105,-111.558228,0.001781,0.000915,0.023250,24.358931,1.240903,0.232503,-111.558228,0.024248,0.000000
19.090000,5.282845,-111.647186,0.001785,0.000924,0.023476,23.499266,1.197110,0.234758,-111.647186,0.024681,0.000000
19.350000,5.566597,-111.602707,0.001832,0.000960,0.024378,24.761459,1.261409,0.243777,-111.602707,0.025115,0.000000
19.610001,5.504410,-111.736153,0.001841,0.000972,0.024699,24.484838,1.247317,0.246986,-111.736153,0.025548,0.000000
19.870001,5.504036,-111.691666,0.001832,0.000986,0.025054,24.483175,1.247232,0.250542,-111.691666,0.025982,0.000000
20.130001,5.561012,-111.780632,0.001871,0.000999,0.025375,24.736618,1.260143,0.253750,-111.780632,0.026416,0.000000
20.390001,5.867096,-111.780632,0.001893,0.001025,0.026025,26.098146,1.329503,0.260254,-111.780632,0.026849,0.000000
20.650002,5.794861,-111.780632,0.001906,0.001038,0.026364,25.776829,1.313134,0.263637,-111.780632,0.027283,0.000000
20.910002,5.883858,-111.914070,0.001919,0.001052,0.026719,26.172707,1.333301,0.267192,-111.914070,0.027717,0.000000
21.170000,5.988869,-111.914070,0.001944,0.001070,0.027179,26.639818,1.357097,0.271789,-111.914070,0.028150,0.000000
21.430000,6.092010,-111.869591,0.001949,0.001088,0.027630,27.098616,1.380469,0.276298,-111.869591,0.028584,0.000000
21.690001,6.133720,-111.958557,0.001970,0.001105,0.028072,27.284151,1.389921,0.280721,-111.958557,0.029017,0.000000
21.950001,6.266281,-111.914070,0.001988,0.001123,0.028532,27.873810,1.419960,0.285317,-111.914070,0.029451,0.000000
22.210001,6.348953,-112.003036,0.002005,0.001143,0.029026,28.241554,1.438693,0.290260,-112.003036,0.029885,0.000000
22.470001,6.405548,-112.003036,0.002022,0.001163,0.029529,28.493301,1.451518,0.295290,-112.003036,0.030318,0.000000
22.730001,6.256599,-112.091995,0.002057,0.001171,0.029746,27.830744,1.417766,0.297458,-112.091995,0.030752,0.000000
22.990002,6.654671,-112.136475,0.002039,0.001192,0.030275,29.601454,1.507970,0.302748,-112.136475,0.031185,0.000000
23.250002,6.791702,-112.091995,0.002065,0.001213,0.030804,30.211000,1.539022,0.308039,-112.091995,0.031619,0.000000
23.510000,6.621155,-112.180962,0.002117,0.001226,0.031151,29.452368,1.500375,0.311507,-112.180962,0.032053,0.000000
23.770000,6.545563,-112.136475,0.002108,0.001238,0.031437,29.116117,1.483246,0.314369,-112.136475,0.032486,0.000000
24.030001,6.712013,-112.180962,0.002134,0.001256,0.031897,29.856525,1.520964,0.318966,-112.180962,0.032920,0.000000
24.290001,6.847557,-112.225441,0.002151,0.001277,0.032426,30.459455,1.551679,0.324256,-112.225441,0.033354,0.000000
24.550001,6.797287,-112.225441,0.002143,0.001294,0.032859,30.235842,1.540287,0.328592,-112.225441,0.033787,0.000000
24.810001,6.919052,-112.269920,0.002177,0.001306,0.033171,30.777481,1.567880,0.331714,-112.269920,0.034221,0.000000
25.070002,7.203918,-112.269920,0.002182,0.001334,0.033883,32.044628,1.632431,0.338825,-112.269920,0.034654,0.000000
25.330002,7.098907,-112.358879,0.002225,0.001349,0.034255,31.577518,1.608635,0.342554,-112.358879,0.035088,0.000000
25.590002,7.094070,-112.447845,0.002233,0.001362,0.034594,31.556002,1.607539,0.345936,-112.447845,0.035522,0.000000
25.850000,7.170776,-112.358879,0.002272,0.001377,0.034975,31.897207,1.624921,0.349752,-112.358879,0.035947,0.000000
26.110001,7.262749,-112.492325,0.002251,0.001394,0.035417,32.306320,1.645762,0.354175,-112.492325,0.036380,0.000000
26.370001,7.382286,-112.447845,0.002298,0.001414,0.035903,32.838047,1.672850,0.359031,-112.447845,0.036814,0.000000
26.630001,7.285469,-112.536804,0.002294,0.001424,0.036172,32.407387,1.650911,0.361720,-112.536804,0.037247,0.000000
26.890001,7.435532,-112.492325,0.002328,0.001442,0.036614,33.074898,1.684916,0.366143,-112.492325,0.037681,0.000000
27.150002,7.771042,-112.536804,0.002350,0.001466,0.037230,34.567322,1.760943,0.372300,-112.536804,0.038115,0.000000
27.410002,7.530861,-112.670250,0.002345,0.001477,0.037516,33.498943,1.706517,0.375162,-112.670250,0.038548,0.000000
27.670002,7.660446,-112.625771,0.002376,0.001496,0.037993,34.075367,1.735882,0.379932,-112.625771,0.038982,0.000000
27.930002,7.834343,-112.714729,0.002393,0.001515,0.038487,34.848900,1.775287,0.384875,-112.714729,0.039415,0.000000
28.190001,7.944191,-112.670250,0.002414,0.001535,0.038999,35.337528,1.800179,0.389991,-112.670250,0.039849,0.000000
28.450001,7.804184,-112.670250,0.002423,0.001547,0.039285,34.714745,1.768453,0.392853,-112.670250,0.040283,0.000000
28.710001,7.819824,-112.759209,0.002440,0.001561,0.039650,34.784317,1.771997,0.396496,-112.759209,0.040716,0.000000
28.970001,7.927437,-112.759209,0.002449,0.001579,0.040101,35.263000,1.796383,0.401005,-112.759209,0.041150,0.000000
29.230001,8.144531,-112.803696,0.002475,0.001602,0.040690,36.228683,1.845577,0.406902,-112.803696,0.041583,0.000000
29.490002,8.134850,-112.848175,0.002483,0.001617,0.041072,36.185619,1.843383,0.410718,-112.848175,0.042017,0.000000
29.750002,8.167618,-112.892654,0.002518,0.001633,0.041471,36.331379,1.850809,0.414707,-112.892654,0.042451,0.000000
30.010002,8.281937,-112.892654,0.002527,0.001654,0.042000,36.839893,1.876714,0.419997,-112.892654,0.042884,0.000000
30.270002,8.307259,-112.848175,0.002539,0.001671,0.042451,36.952534,1.882452,0.424507,-112.848175,0.043318,0.000000
30.530001,8.240601,-112.937134,0.002544,0.001681,0.042702,36.656021,1.867347,0.427022,-112.937134,0.043752,0.000000
30.790001,8.560097,-112.937134,0.002565,0.001705,0.043309,38.077213,1.939746,0.433093,-112.937134,0.044185,0.000000
31.050001,8.469238,-113.026100,0.002600,0.001722,0.043743,37.673054,1.919157,0.437429,-113.026100,0.044619,0.000000
31.310001,8.491577,-112.981613,0.002626,0.001735,0.044081,37.772423,1.924219,0.440811,-112.981613,0.045052,0.000000
31.570002,8.484131,-113.070580,0.002656,0.001752,0.044489,37.739300,1.922531,0.444887,-113.070580,0.045486,0.000000
31.830002,8.745537,-113.115059,0.002656,0.001771,0.044992,38.902092,1.981767,0.449917,-113.115059,0.045920,0.000000
32.090000,8.622284,-113.070580,0.002677,0.001786,0.045373,38.353836,1.953837,0.453732,-113.070580,0.046353,0.000000
32.350002,8.587280,-113.115059,0.002682,0.001799,0.045685,38.198132,1.945906,0.456854,-113.115059,0.046787,0.000000
32.610001,8.859856,-113.159538,0.002708,0.001817,0.046162,39.410606,2.007672,0.461624,-113.159538,0.047220,0.000000
32.870003,9.108231,-113.159538,0.002725,0.001843,0.046804,40.515434,2.063955,0.468042,-113.159538,0.047654,0.000000
33.130001,8.878479,-113.248505,0.002742,0.001858,0.047186,39.493446,2.011892,0.471857,-113.248505,0.048088,0.000000
33.390003,8.908264,-113.248505,0.002768,0.001872,0.047550,39.625938,2.018641,0.475500,-113.248505,0.048521,0.000000
33.650002,9.045670,-113.337463,0.002768,0.001888,0.047949,40.237148,2.049778,0.479489,-113.337463,0.048955,0.000000
33.910000,8.946617,-113.337463,0.002790,0.001902,0.048304,39.796539,2.027332,0.483045,-113.337463,0.049389,0.000000
34.170002,9.090729,-113.337463,0.002815,0.001920,0.048773,40.437580,2.059988,0.487728,-113.337463,0.049822,0.000000
34.430000,9.213242,-113.426422,0.002837,0.001935,0.049146,40.982544,2.087750,0.491457,-113.426422,0.050256,0.000000
34.690002,9.435547,-113.292984,0.002850,0.001957,0.049718,41.971409,2.138125,0.497180,-113.292984,0.050689,0.000000
34.950001,9.451187,-113.426422,0.002871,0.001979,0.050273,42.040981,2.141670,0.502731,-113.426422,0.051114,0.000000
35.210003,9.200951,-113.426422,0.002880,0.001992,0.050603,40.927872,2.084965,0.506026,-113.426422,0.051548,0.000000
35.470001,9.302979,-113.426422,0.002893,0.002007,0.050967,41.381714,2.108085,0.509669,-113.426422,0.051982,0.000000
35.730003,9.272072,-113.515388,0.002923,0.002017,0.051227,41.244236,2.101082,0.512270,-113.515388,0.052415,0.000000
35.990002,9.491776,-113.559868,0.002928,0.002039,0.051791,42.221527,2.150867,0.517907,-113.559868,0.052849,0.000000
36.250000,9.633278,-113.559868,0.002975,0.002062,0.052380,42.850960,2.182932,0.523804,-113.559868,0.053282,0.000000
36.510002,9.794884,-113.559868,0.002966,0.002085,0.052961,43.569820,2.219552,0.529615,-113.559868,0.053716,0.000000
36.770000,9.691368,-113.604347,0.003001,0.002101,0.053360,43.109360,2.196095,0.533604,-113.604347,0.054150,0.000000
37.030003,9.609818,-113.693314,0.003005,0.002113,0.053673,42.746605,2.177616,0.536726,-113.693314,0.054583,0.000000
37.290001,9.813873,-113.604347,0.003014,0.002131,0.054115,43.654289,2.223855,0.541149,-113.604347,0.055017,0.000000
37.550003,9.632904,-113.737793,0.003022,0.002141,0.054392,42.849297,2.182847,0.543924,-113.737793,0.055450,0.000000
37.810001,9.962082,-113.693314,0.003070,0.002164,0.054956,44.313553,2.257440,0.549561,-113.693314,0.055884,0.000000
38.070004,9.922981,-113.737793,0.003087,0.002178,0.055329,44.139626,2.248580,0.553290,-113.737793,0.056318,0.000000
38.330002,9.922234,-113.782272,0.003096,0.002191,0.055650,44.136299,2.248410,0.556499,-113.782272,0.056751,0.000000
38.590000,10.550056,-113.782272,0.003109,0.002223,0.056456,46.928993,2.390677,0.564564,-113.782272,0.057185,0.000000
38.850002,10.149757,-113.826752,0.003126,0.002237,0.056829,45.148376,2.299968,0.568293,-113.826752,0.057618,0.000000
39.110001,10.025757,-113.826752,0.003134,0.002249,0.057124,44.596794,2.271869,0.571242,-113.826752,0.058052,0.000000
39.370003,10.267426,-113.915718,0.003160,0.002266,0.057566,45.671791,2.326632,0.575664,-113.915718,0.058486,0.000000
39.630001,10.196304,-113.871231,0.003186,0.002280,0.057905,45.355427,2.310516,0.579047,-113.871231,0.058919,0.000000
39.890003,10.430893,-113.915718,0.003208,0.002299,0.058390,46.398930,2.363674,0.583903,-113.915718,0.059353,0.000000
40.150002,10.202263,-114.049156,0.003221,0.002308,0.058616,45.381931,2.311866,0.586158,-114.049156,0.059787,0.000000
40.410004,10.319183,-114.004677,0.003212,0.002324,0.059032,45.902020,2.338360,0.590320,-114.004677,0.060220,0.000000
40.670002,10.687088,-114.093643,0.003251,0.002359,0.059908,47.538540,2.421729,0.599079,-114.093643,0.060654,0.000000
40.930000,10.563087,-114.049156,0.003281,0.002371,0.060229,46.986961,2.393630,0.602288,-114.049156,0.061087,0.000000
41.190002,10.531441,-114.004677,0.003281,0.002385,0.060584,46.846188,2.386459,0.605844,-114.004677,0.061521,0.000000
41.450001,10.573143,-114.182602,0.003294,0.002397,0.060888,47.031689,2.395908,0.608879,-114.182602,0.061955,0.000000
41.710003,10.963387,-114.138123,0.003328,0.002423,0.061538,48.767578,2.484339,0.615383,-114.138123,0.062388,0.000000
41.970001,10.815186,-114.227081,0.003363,0.002437,0.061911,48.108349,2.450756,0.619112,-114.227081,0.062822,0.000000
42.230003,10.913864,-114.227081,0.003354,0.002451,0.062258,48.547291,2.473117,0.622581,-114.227081,0.063255,0.000000
42.490002,10.958923,-114.227081,0.003376,0.002469,0.062709,48.747726,2.483328,0.627091,-114.227081,0.063689,0.000000
42.750004,11.023712,-114.316048,0.003397,0.002486,0.063151,49.035919,2.498009,0.631514,-114.316048,0.064123,0.000000
43.010002,11.048286,-114.271561,0.003423,0.002503,0.063585,49.145233,2.503577,0.635850,-114.271561,0.064556,0.000000
43.270000,11.238571,-114.405006,0.003428,0.002521,0.064045,49.991661,2.546697,0.640446,-114.405006,0.064990,0.000000
43.530003,11.237083,-114.316048,0.003454,0.002540,0.064504,49.985043,2.546360,0.645042,-114.316048,0.065424,0.000000
43.790001,11.386406,-114.405006,0.003488,0.002561,0.065042,50.649261,2.580196,0.650419,-114.405006,0.065857,0.000000
44.050003,11.096329,-114.449486,0.003479,0.002568,0.065224,49.358936,2.514464,0.652240,-114.449486,0.066282,0.000000
44.310001,11.462372,-114.405006,0.003523,0.002588,0.065736,50.987175,2.597410,0.657357,-114.405006,0.066716,0.000000
44.570004,11.288841,-114.582932,0.003510,0.002600,0.066031,50.215275,2.558088,0.660306,-114.582932,0.067149,0.000000
44.830002,11.558815,-114.582932,0.003544,0.002625,0.066672,51.416176,2.619265,0.666723,-114.582932,0.067583,0.000000
45.090004,11.443748,-114.582932,0.003544,0.002638,0.066993,50.904335,2.593190,0.669932,-114.582932,0.068017,0.000000
45.350002,11.539078,-114.582932,0.003574,0.002653,0.067392,51.328381,2.614793,0.673921,-114.582932,0.068450,0.000000
45.610001,11.778885,-114.582932,0.003591,0.002675,0.067938,52.395096,2.669133,0.679385,-114.582932,0.068884,0.000000
45.870003,11.817986,-114.671890,0.003609,0.002692,0.068372,52.569027,2.677994,0.683721,-114.671890,0.069317,0.000000
46.130001,11.776276,-114.627411,0.003613,0.002704,0.068693,52.383492,2.668542,0.686929,-114.627411,0.069751,0.000000
46.390003,12.163918,-114.760857,0.003648,0.002732,0.069387,54.107807,2.756383,0.693867,-114.760857,0.070185,0.000000
46.650002,11.989273,-114.716370,0.003678,0.002748,0.069794,53.330952,2.716808,0.697943,-114.716370,0.070618,0.000000
46.910004,11.918526,-114.760857,0.003686,0.002760,0.070115,53.016251,2.700776,0.701152,-114.760857,0.071052,0.000000
47.170002,11.967674,-114.805336,0.003673,0.002775,0.070497,53.234875,2.711914,0.704968,-114.805336,0.071485,0.000000
47.430004,12.052582,-114.849815,0.003725,0.002794,0.070974,53.612560,2.731154,0.709737,-114.849815,0.071919,0.000000
47.690002,12.181419,-114.894295,0.003729,0.002812,0.071425,54.185661,2.760349,0.714247,-114.894295,0.072353,0.000000
47.950001,12.079765,-114.805336,0.003742,0.002823,0.071694,53.733479,2.737314,0.716936,-114.805336,0.072786,0.000000
48.210003,12.200035,-114.983261,0.003768,0.002838,0.072092,54.268467,2.764568,0.720925,-114.983261,0.073220,0.000000
48.470001,12.595123,-114.983261,0.003781,0.002864,0.072743,56.025906,2.854096,0.727429,-114.983261,0.073653,0.000000
48.730003,12.319199,-114.894295,0.003790,0.002875,0.073029,54.798531,2.791570,0.730291,-114.894295,0.074087,0.000000
48.990002,12.500916,-115.072220,0.003794,0.002895,0.073523,55.606850,2.832748,0.735234,-115.072220,0.074521,0.000000
49.250004,12.698647,-115.027740,0.003829,0.002915,0.074035,56.486401,2.877554,0.740351,-115.027740,0.074954,0.000000
49.510002,12.832703,-115.027740,0.003850,0.002935,0.074538,57.082714,2.907932,0.745380,-115.027740,0.075388,0.000000
49.770000,12.599220,-115.072220,0.003859,0.002945,0.074816,56.044132,2.855024,0.748156,-115.072220,0.075822,0.000000
50.030003,12.626404,-115.072220,0.003867,0.002959,0.075171,56.165051,2.861184,0.751711,-115.072220,0.076255,0.000000
50.290001,13.067665,-115.161179,0.003893,0.002984,0.075804,58.127876,2.961175,0.758042,-115.161179,0.076689,0.000000
50.550003,12.964890,-115.205666,0.003923,0.003000,0.076203,57.670708,2.937886,0.762031,-115.205666,0.077122,0.000000
50.810001,12.981277,-115.161179,0.003932,0.003016,0.076611,57.743607,2.941599,0.766107,-115.161179,0.077556,0.000000
51.070004,13.032288,-115.205666,0.003954,0.003032,0.077018,57.970512,2.953159,0.770183,-115.205666,0.077990,0.000000
51.330002,13.151451,-115.250145,0.003997,0.003053,0.077556,58.500576,2.980161,0.775560,-115.250145,0.078423,0.000000
51.590004,13.126129,-115.339104,0.003980,0.003070,0.077972,58.387939,2.974423,0.779723,-115.339104,0.078857,0.000000
51.850002,13.112350,-115.294624,0.003992,0.003081,0.078258,58.326649,2.971301,0.782584,-115.294624,0.079290,0.000000
52.110001,13.386414,-115.383591,0.004023,0.003105,0.078865,59.545742,3.033405,0.788655,-115.383591,0.079724,0.000000
52.370003,13.297417,-115.383591,0.004053,0.003121,0.079282,59.149864,3.013238,0.792818,-115.383591,0.080158,0.000000
52.630001,13.305611,-115.383591,0.004057,0.003134,0.079603,59.186314,3.015095,0.796026,-115.383591,0.080591,0.000000
52.890003,13.355881,-115.472549,0.004079,0.003152,0.080071,59.409924,3.026486,0.800709,-115.472549,0.081025,0.000000
53.150002,13.626228,-115.428070,0.004113,0.003170,0.080522,60.612492,3.087748,0.805219,-115.428070,0.081450,0.000000
53.410004,13.473549,-115.472549,0.004113,0.003185,0.080895,59.933338,3.053150,0.808948,-115.472549,0.081883,0.000000
53.670002,13.442642,-115.517029,0.004105,0.003197,0.081216,59.795860,3.046146,0.812157,-115.517029,0.082317,0.000000
53.930004,13.688042,-115.517029,0.004135,0.003216,0.081693,60.887451,3.101755,0.816927,-115.517029,0.082751,0.000000
54.190002,14.017586,-115.605995,0.004152,0.003241,0.082317,62.353336,3.176430,0.823171,-115.605995,0.083184,0.000000
54.450001,13.751343,-115.650475,0.004161,0.003257,0.082716,61.169029,3.116099,0.827160,-115.650475,0.083618,0.000000
54.710003,13.811668,-115.694954,0.004195,0.003271,0.083080,61.437370,3.129769,0.830802,-115.694954,0.084052,0.000000
54.970001,13.886887,-115.694954,0.004195,0.003286,0.083470,61.771957,3.146814,0.834705,-115.694954,0.084485,0.000000
55.230003,14.000458,-115.694954,0.004225,0.003302,0.083869,62.277145,3.172549,0.838694,-115.694954,0.084919,0.000000
55.490002,13.977745,-115.739433,0.004238,0.003318,0.084277,62.176117,3.167402,0.842770,-115.739433,0.085352,0.000000
55.750004,13.631065,-115.694954,0.004260,0.003331,0.084607,60.634007,3.088844,0.846065,-115.694954,0.085786,0.000000
56.010002,14.298729,-115.872879,0.004264,0.003355,0.085222,63.603924,3.240138,0.852223,-115.872879,0.086220,0.000000
56.270004,14.402992,-115.872879,0.004299,0.003378,0.085795,64.067711,3.263765,0.857946,-115.872879,0.086653,0.000000
56.530003,14.220901,-115.828400,0.004307,0.003392,0.086168,63.257729,3.222502,0.861675,-115.828400,0.087087,0.000000
56.790001,14.169891,-115.961838,0.004307,0.003406,0.086506,63.030827,3.210943,0.865058,-115.961838,0.087520,0.000000
57.050003,14.388100,-115.872879,0.004320,0.003423,0.086948,64.001465,3.260390,0.869480,-115.872879,0.087954,0.000000
57.310001,14.330383,-116.006317,0.004350,0.003440,0.087382,63.744728,3.247311,0.873817,-116.006317,0.088388,0.000000
57.570004,14.528854,-115.917358,0.004381,0.003461,0.087902,64.627571,3.292285,0.879020,-115.917358,0.088821,0.000000
57.830002,14.773880,-116.050804,0.004398,0.003483,0.088457,65.717499,3.347809,0.884570,-116.050804,0.089255,0.000000
58.090004,14.653229,-116.006317,0.004415,0.003500,0.088891,65.180817,3.320469,0.888906,-116.006317,0.089688,0.000000
58.350002,14.534439,-116.006317,0.004415,0.003512,0.089212,64.652412,3.293551,0.892115,-116.006317,0.090122,0.000000
58.610004,14.698288,-116.139763,0.004454,0.003529,0.089645,65.381248,3.330680,0.896451,-116.139763,0.090556,0.000000
58.870003,14.561996,-116.095284,0.004462,0.003541,0.089931,64.774994,3.299796,0.899313,-116.095284,0.090989,0.000000
59.130001,14.999161,-116.095284,0.004484,0.003565,0.090538,66.719597,3.398859,0.905384,-116.095284,0.091423,0.000000
59.390003,14.914261,-116.184242,0.004488,0.003578,0.090877,66.341949,3.379620,0.908766,-116.184242,0.091857,0.000000
59.650002,14.852074,-116.184242,0.004488,0.003590,0.091189,66.065323,3.365528,0.911888,-116.184242,0.092290,0.000000
59.910004,15.555862,-116.228722,0.004549,0.003622,0.091987,69.195930,3.525009,0.919866,-116.228722,0.092724,0.000000
60.170002,15.172318,-116.228722,0.004562,0.003636,0.092351,67.489838,3.438096,0.923509,-116.228722,0.093157,0.000000
60.430004,14.933998,-116.273209,0.004596,0.003646,0.092611,66.429741,3.384092,0.926110,-116.273209,0.093591,0.000000
60.690002,15.298180,-116.317688,0.004579,0.003665,0.093088,68.049698,3.466617,0.930880,-116.317688,0.094025,0.000000
60.950005,15.200241,-116.317688,0.004596,0.003680,0.093461,67.614052,3.444424,0.934609,-116.317688,0.094458,0.000000
61.210003,15.413986,-116.451126,0.004626,0.003698,0.093921,68.564835,3.492859,0.939205,-116.451126,0.094892,0.000000
61.470001,15.443031,-116.406647,0.004631,0.003712,0.094285,68.694031,3.499441,0.942848,-116.406647,0.095325,0.000000
61.730003,15.519363,-116.451126,0.004652,0.003734,0.094831,69.033577,3.516738,0.948311,-116.451126,0.095759,0.000000
61.990002,15.780029,-116.406647,0.004678,0.003757,0.095430,70.193077,3.575806,0.954295,-116.406647,0.096184,0.000000
62.250004,15.543571,-116.495613,0.004682,0.003769,0.095733,69.141258,3.522224,0.957330,-116.495613,0.096618,0.000000
62.510002,15.588997,-116.540092,0.004712,0.003785,0.096132,69.343323,3.532517,0.961320,-116.540092,0.097051,0.000000
62.770004,15.643364,-116.451126,0.004717,0.003798,0.096470,69.585159,3.544837,0.964702,-116.451126,0.097485,0.000000
63.030003,16.064522,-116.584572,0.004730,0.003822,0.097069,71.458565,3.640273,0.970686,-116.584572,0.097918,0.000000
63.290005,15.827690,-116.629051,0.004760,0.003836,0.097424,70.405083,3.586606,0.974241,-116.629051,0.098352,0.000000
63.550003,15.937164,-116.540092,0.004756,0.003850,0.097788,70.892044,3.611413,0.977884,-116.540092,0.098786,0.000000
63.810001,16.085373,-116.673538,0.004790,0.003868,0.098248,71.551315,3.644998,0.982480,-116.673538,0.099219,0.000000
64.070000,16.032494,-116.673538,0.004812,0.003885,0.098690,71.316093,3.633015,0.986903,-116.673538,0.099653,0.000000
64.330002,16.238045,-116.718018,0.004803,0.003902,0.099115,72.230431,3.679594,0.991152,-116.718018,0.100087,0.000000
64.590004,16.429443,-116.718018,0.004833,0.003920,0.099575,73.081818,3.722965,0.995749,-116.718018,0.100520,0.000000
64.850006,16.529610,-116.718018,0.004859,0.003940,0.100069,73.527374,3.745663,1.000692,-116.718018,0.100954,0.000000
65.110001,16.666649,-116.806976,0.004885,0.003960,0.100572,74.136955,3.776717,1.005722,-116.806976,0.101387,0.000000
65.370003,16.244377,-116.806976,0.004907,0.003967,0.100754,72.258598,3.681028,1.007543,-116.806976,0.101821,0.000000
65.630005,16.760109,-116.895943,0.004902,0.003989,0.101309,74.552689,3.797895,1.013093,-116.895943,0.102255,0.000000
65.889999,17.072533,-116.895943,0.004932,0.004010,0.101847,75.942421,3.868691,1.018470,-116.895943,0.102688,0.000000
66.150002,16.800331,-116.895943,0.004967,0.004023,0.102194,74.731606,3.807009,1.021939,-116.895943,0.103122,0.000000
66.410004,16.682655,-116.940422,0.004945,0.004036,0.102523,74.208160,3.780344,1.025234,-116.940422,0.103555,0.000000
66.670006,16.870331,-116.940422,0.004988,0.004054,0.102966,75.042976,3.822872,1.029657,-116.940422,0.103989,0.000000
66.930000,17.173820,-117.029381,0.005010,0.004075,0.103512,76.392967,3.891643,1.035121,-117.029381,0.104423,0.000000
67.190002,17.177910,-117.029381,0.005019,0.004090,0.103894,76.411156,3.892570,1.038936,-117.029381,0.104856,0.000000
67.450005,17.048698,-117.073860,0.005027,0.004103,0.104215,75.836395,3.863290,1.042145,-117.073860,0.105290,0.000000
67.710007,17.643753,-117.073860,0.005040,0.004130,0.104900,78.483330,3.998132,1.048996,-117.073860,0.105723,0.000000
67.970001,17.441177,-117.118347,0.005079,0.004147,0.105325,77.582230,3.952227,1.053246,-117.118347,0.106157,0.000000
68.230003,17.288506,-117.118347,0.005109,0.004160,0.105663,76.903114,3.917631,1.056628,-117.118347,0.106591,0.000000
68.490005,17.373779,-117.162827,0.005122,0.004175,0.106053,77.282433,3.936954,1.060530,-117.162827,0.107024,0.000000
68.750000,17.575607,-117.251785,0.005122,0.004194,0.106539,78.180206,3.982690,1.065387,-117.251785,0.107458,0.000000
69.010002,17.641144,-117.207306,0.005144,0.004209,0.106920,78.471725,3.997540,1.069203,-117.207306,0.107892,0.000000
69.270004,17.535019,-117.251785,0.005161,0.004221,0.107215,77.999657,3.973492,1.072151,-117.251785,0.108325,0.000000
69.530006,17.675400,-117.296265,0.005157,0.004238,0.107649,78.624107,4.005303,1.076487,-117.296265,0.108759,0.000000
69.790001,18.091713,-117.296265,0.005200,0.004259,0.108186,80.475960,4.099641,1.081864,-117.296265,0.109192,0.000000
70.050003,17.963989,-117.385231,0.005217,0.004273,0.108525,79.907814,4.070698,1.085246,-117.385231,0.109626,0.000000
70.310005,18.220932,-117.340752,0.005226,0.004292,0.109010,81.050751,4.128922,1.090103,-117.340752,0.110060,0.000000
70.570000,18.375092,-117.429710,0.005264,0.004313,0.109539,81.736488,4.163855,1.095393,-117.429710,0.110493,0.000000
70.830002,18.589951,-117.429710,0.005238,0.004333,0.110051,82.692230,4.212543,1.100509,-117.429710,0.110927,0.000000
71.090004,18.320724,-117.429710,0.005277,0.004344,0.110337,81.494652,4.151536,1.103371,-117.429710,0.111352,0.000000
71.350006,18.213478,-117.474190,0.005290,0.004357,0.110667,81.017593,4.127233,1.106667,-117.474190,0.111785,0.000000
71.610001,18.677826,-117.518669,0.005325,0.004381,0.111265,83.083122,4.232456,1.112651,-117.518669,0.112219,0.000000
71.870003,18.844650,-117.563156,0.005325,0.004399,0.111725,83.825188,4.270259,1.117247,-117.563156,0.112653,0.000000
72.130005,18.757515,-117.474190,0.005338,0.004414,0.112115,83.437592,4.250514,1.121149,-117.474190,0.113086,0.000000
72.390007,18.900505,-117.607635,0.005372,0.004431,0.112540,84.073647,4.282916,1.125399,-117.607635,0.113520,0.000000
72.650002,19.112762,-117.696594,0.005389,0.004452,0.113078,85.017815,4.331014,1.130776,-117.696594,0.113953,0.000000
72.910004,19.101593,-117.652115,0.005428,0.004468,0.113485,84.968132,4.328483,1.134852,-117.652115,0.114387,0.000000
73.170006,18.805550,-117.696594,0.005415,0.004479,0.113771,83.651260,4.261398,1.137713,-117.696594,0.114821,0.000000
73.430000,19.535034,-117.652115,0.005445,0.004503,0.114387,86.896172,4.426702,1.143871,-117.652115,0.115254,0.000000
73.690002,19.454971,-117.696594,0.005480,0.004519,0.114786,86.540031,4.408560,1.147860,-117.696594,0.115688,0.000000
73.950005,19.384216,-117.785561,0.005467,0.004532,0.115124,86.225304,4.392527,1.151242,-117.785561,0.116122,0.000000
74.210007,19.479172,-117.830040,0.005493,0.004551,0.115584,86.647682,4.414043,1.155838,-117.830040,0.116555,0.000000
74.470001,19.884315,-117.830040,0.005510,0.004569,0.116043,88.449852,4.505850,1.160435,-117.830040,0.116989,0.000000
74.730003,19.700363,-117.874519,0.005536,0.004583,0.116408,87.631592,4.464166,1.164077,-117.874519,0.117422,0.000000
74.990005,19.671318,-117.874519,0.005553,0.004597,0.116763,87.502396,4.457584,1.167633,-117.874519,0.117856,0.000000
75.250000,19.975174,-117.918999,0.005558,0.004615,0.117214,88.854012,4.526439,1.172142,-117.918999,0.118290,0.000000
75.510002,20.369888,-117.918999,0.005579,0.004638,0.117804,90.609787,4.615882,1.178039,-117.918999,0.118723,0.000000
75.770004,20.228020,-117.963486,0.005609,0.004656,0.118255,89.978729,4.583735,1.182549,-117.963486,0.119157,0.000000
76.030006,20.260040,-118.007965,0.005631,0.004670,0.118610,90.121162,4.590991,1.186105,-118.007965,0.119590,0.000000
76.290001,20.347549,-118.007965,0.005644,0.004685,0.118992,90.510422,4.610821,1.189920,-118.007965,0.120024,0.000000
76.550003,20.492401,-118.052444,0.005648,0.004700,0.119391,91.154755,4.643644,1.193910,-118.052444,0.120458,0.000000
76.810005,20.523308,-118.052444,0.005678,0.004717,0.119816,91.292236,4.650648,1.198159,-118.052444,0.120891,0.000000
77.070007,20.640236,-118.096924,0.005704,0.004733,0.120215,91.812355,4.677145,1.202148,-118.096924,0.121325,0.000000
77.330002,20.916534,-118.141403,0.005717,0.004754,0.120744,93.041389,4.739754,1.207438,-118.141403,0.121758,0.000000
77.590004,21.236404,-118.185890,0.005730,0.004777,0.121325,94.464241,4.812238,1.213249,-118.185890,0.122192,0.000000
77.850006,21.082237,-118.230370,0.005743,0.004791,0.121689,93.778473,4.777303,1.216891,-118.230370,0.122626,0.000000
78.110001,20.958984,-118.230370,0.005743,0.004804,0.122027,93.230217,4.749374,1.220273,-118.230370,0.123059,0.000000
78.370003,21.185387,-118.274849,0.005782,0.004821,0.122461,94.237305,4.800677,1.224609,-118.274849,0.123493,0.000000
78.630005,21.281082,-118.319328,0.005795,0.004836,0.122834,94.662979,4.822362,1.228338,-118.319328,0.123927,0.000000
78.890007,21.611008,-118.363808,0.005812,0.004859,0.123424,96.130562,4.897124,1.234236,-118.363808,0.124360,0.000000
79.150002,21.901833,-118.319328,0.005816,0.004881,0.123987,97.424217,4.963026,1.239873,-118.319328,0.124794,0.000000
79.410004,21.850067,-118.408295,0.005842,0.004898,0.124412,97.193954,4.951296,1.244122,-118.408295,0.125227,0.000000
79.670006,21.716019,-118.408295,0.005855,0.004910,0.124716,96.597679,4.920920,1.247157,-118.408295,0.125661,0.000000
79.930000,21.939812,-118.363808,0.005872,0.004927,0.125141,97.593155,4.971632,1.251407,-118.363808,0.126095,0.000000
80.190002,21.850067,-118.497253,0.005902,0.004939,0.125444,97.193954,4.951296,1.254442,-118.497253,0.126520,0.000000
80.450005,22.386284,-118.497253,0.005911,0.004962,0.126043,99.579163,5.072804,1.260426,-118.497253,0.126953,0.000000
80.710007,22.280533,-118.497253,0.005924,0.004976,0.126398,99.108757,5.048841,1.263981,-118.497253,0.127387,0.000000
80.970001,22.230637,-118.586212,0.005941,0.004989,0.126710,98.886810,5.037534,1.267103,-118.586212,0.127820,0.000000
81.230003,23.094910,-118.586212,0.005954,0.005020,0.127500,102.731293,5.233381,1.274995,-118.586212,0.128254,0.000000
81.490005,22.794037,-118.630699,0.005971,0.005034,0.127855,101.392937,5.165203,1.278551,-118.630699,0.128688,0.000000
81.750008,22.594444,-118.675179,0.006002,0.005046,0.128167,100.505104,5.119974,1.281673,-118.675179,0.129121,0.000000
82.010002,23.043900,-118.675179,0.006019,0.005063,0.128610,102.504387,5.221822,1.286096,-118.675179,0.129555,0.000000
82.270004,22.933678,-118.675179,0.006032,0.005076,0.128930,102.014091,5.196846,1.289304,-118.675179,0.129988,0.000000
82.530006,23.010757,-118.675179,0.006028,0.005091,0.129312,102.356964,5.214313,1.293120,-118.675179,0.130422,0.000000
82.790001,23.350357,-118.764137,0.006045,0.005112,0.129832,103.867577,5.291266,1.298324,-118.764137,0.130856,0.000000
83.050003,23.185394,-118.764137,0.006079,0.005120,0.130049,103.133781,5.253885,1.300492,-118.764137,0.131289,0.000000
83.310005,24.147606,-118.808617,0.006096,0.005155,0.130942,107.413918,5.471926,1.309424,-118.808617,0.131723,0.000000
83.570007,23.839653,-118.808617,0.006122,0.005168,0.131272,106.044075,5.402143,1.312719,-118.808617,0.132157,0.000000
83.830002,23.769279,-118.853104,0.006153,0.005183,0.131654,105.731033,5.386196,1.316535,-118.853104,0.132590,0.000000
84.090004,23.829971,-118.897583,0.006140,0.005194,0.131931,106.001007,5.399949,1.319310,-118.897583,0.133024,0.000000
84.350006,24.548279,-118.897583,0.006165,0.005220,0.132581,109.196198,5.562720,1.325815,-118.897583,0.133457,0.000000
84.610001,24.290970,-118.897583,0.006191,0.005233,0.132928,108.051628,5.504413,1.329283,-118.897583,0.133891,0.000000
84.870003,24.284271,-118.986542,0.006191,0.005246,0.133241,108.021835,5.502895,1.332406,-118.986542,0.134325,0.000000
85.130005,24.715477,-118.986542,0.006222,0.005266,0.133752,109.939934,5.600607,1.337522,-118.986542,0.134758,0.000000
85.390007,24.928848,-119.031029,0.006243,0.005287,0.134281,110.889053,5.648958,1.342812,-119.031029,0.135192,0.000000
85.650002,24.937782,-118.986542,0.006252,0.005300,0.134628,110.928795,5.650982,1.346281,-118.986542,0.135625,0.000000
85.910004,25.214081,-119.075508,0.006269,0.005318,0.135088,112.157829,5.713593,1.350877,-119.075508,0.136059,0.000000
86.170006,25.433784,-119.119987,0.006278,0.005338,0.135573,113.135124,5.763378,1.355734,-119.119987,0.136493,0.000000
86.430000,25.734291,-119.164467,0.006312,0.005358,0.136094,114.471848,5.831474,1.360937,-119.164467,0.136926,0.000000
86.690002,25.302711,-119.208946,0.006308,0.005365,0.136258,112.552078,5.733676,1.362585,-119.208946,0.137360,0.000000
86.950005,25.816208,-119.164467,0.006334,0.005384,0.136761,114.836227,5.850037,1.367615,-119.164467,0.137793,0.000000
87.210007,26.252632,-119.208946,0.006347,0.005406,0.137308,116.777542,5.948932,1.373078,-119.208946,0.138227,0.000000
87.470001,26.241089,-119.253433,0.006381,0.005421,0.137681,116.726196,5.946316,1.376807,-119.253433,0.138661,0.000000
87.730003,26.139427,-119.253433,0.006390,0.005435,0.138036,116.273979,5.923279,1.380363,-119.253433,0.139094,0.000000
87.990005,26.339394,-119.297913,0.006377,0.005450,0.138427,117.163475,5.968592,1.384266,-119.297913,0.139528,0.000000
88.250008,26.884544,-119.297913,0.006403,0.005472,0.138990,119.588425,6.092125,1.389903,-119.297913,0.139962,0.000000
88.510002,26.775070,-119.386871,0.006433,0.005488,0.139389,119.101463,6.067318,1.393892,-119.386871,0.140395,0.000000
88.770004,26.929977,-119.342392,0.006420,0.005500,0.139710,119.790520,6.102420,1.397101,-119.342392,0.140829,0.000000
89.030006,27.811378,-119.431351,0.006454,0.005528,0.140413,123.711189,6.302149,1.404125,-119.431351,0.141254,0.000000
89.290001,27.688126,-119.475838,0.006480,0.005544,0.140820,123.162933,6.274219,1.408201,-119.475838,0.141687,0.000000
89.550003,27.649773,-119.431351,0.006489,0.005558,0.141167,122.992332,6.265528,1.411670,-119.431351,0.142121,0.000000
89.810005,27.781593,-119.564796,0.006502,0.005572,0.141540,123.578697,6.295399,1.415399,-119.564796,0.142555,0.000000
90.070007,28.150986,-119.520317,0.006506,0.005593,0.142052,125.221840,6.379105,1.420516,-119.520317,0.142988,0.000000
90.330002,28.365097,-119.564796,0.006549,0.005609,0.142476,126.174255,6.427623,1.424765,-119.564796,0.143422,0.000000
90.590004,28.277588,-119.698242,0.006558,0.005620,0.142737,125.784996,6.407793,1.427367,-119.698242,0.143855,0.000000
90.850006,28.606026,-119.653755,0.006566,0.005637,0.143170,127.245956,6.482218,1.431703,-119.653755,0.144289,0.000000
91.110001,29.271454,-119.698242,0.006584,0.005660,0.143760,130.205933,6.633007,1.437600,-119.698242,0.144723,0.000000
91.370003,29.055107,-119.653755,0.006605,0.005672,0.144064,129.243576,6.583982,1.440635,-119.653755,0.145156,0.000000
91.630005,29.520569,-119.698242,0.006627,0.005693,0.144593,131.314041,6.689456,1.445925,-119.698242,0.145590,0.000000
91.890007,29.887360,-119.698242,0.006622,0.005712,0.145096,132.945618,6.772573,1.450955,-119.698242,0.146023,0.000000
92.150002,30.268669,-119.787201,0.006683,0.005732,0.145581,134.641769,6.858978,1.455812,-119.787201,0.146457,0.000000
92.410004,30.015457,-119.831680,0.006679,0.005742,0.145859,133.515427,6.801600,1.458587,-119.831680,0.146891,0.000000
92.670006,30.111526,-119.787201,0.006683,0.005756,0.146214,133.942764,6.823370,1.462143,-119.787201,0.147324,0.000000
92.930008,30.914734,-119.831680,0.006722,0.005782,0.146865,137.515610,7.005379,1.468647,-119.831680,0.147758,0.000000
93.190002,31.029793,-119.920647,0.006730,0.005797,0.147246,138.027405,7.031452,1.472463,-119.920647,0.148192,0.000000
93.450005,31.156029,-119.876160,0.006748,0.005813,0.147663,138.588943,7.060057,1.476625,-119.876160,0.148625,0.000000
93.710007,31.353012,-119.920647,0.006760,0.005830,0.148079,139.465164,7.104694,1.480788,-119.920647,0.149059,0.000000
93.970001,31.789810,-119.920647,0.006778,0.005850,0.148599,141.408142,7.203674,1.485991,-119.920647,0.149492,0.000000
94.230003,31.971901,-119.920647,0.006791,0.005867,0.149015,142.218124,7.244936,1.490154,-119.920647,0.149926,0.000000
94.490005,31.819595,-120.009605,0.006799,0.005877,0.149267,141.540634,7.210423,1.492669,-120.009605,0.150360,0.000000
94.750008,32.546097,-120.054085,0.006812,0.005901,0.149874,144.772263,7.375051,1.498739,-120.054085,0.150793,0.000000
95.010002,32.809738,-120.098564,0.006825,0.005919,0.150342,145.945007,7.434793,1.503422,-120.098564,0.151227,0.000000
95.270004,32.772499,-120.098564,0.006860,0.005932,0.150663,145.779358,7.426354,1.506631,-120.098564,0.151660,0.000000
95.530006,33.046936,-120.232010,0.006868,0.005951,0.151149,147.000107,7.488543,1.511488,-120.232010,0.152094,0.000000
95.790001,33.530281,-120.098564,0.006860,0.005967,0.151565,149.150146,7.598070,1.515650,-120.098564,0.152528,0.000000
96.050003,33.162376,-120.232010,0.006903,0.005968,0.151600,147.513611,7.514702,1.515997,-120.232010,0.151843,0.000000
96.310005,32.380394,-120.276489,0.006903,0.005968,0.151600,144.035187,7.337502,1.515997,-120.276489,0.151843,0.000000
96.570007,31.979347,-120.232010,0.006903,0.005967,0.151556,142.251236,7.246624,1.515564,-120.232010,0.151470,0.000000
96.830002,31.539948,-120.232010,0.006907,0.005956,0.151288,140.296692,7.147054,1.512875,-120.232010,0.151036,0.000000
97.090004,31.261414,-120.276489,0.006920,0.005943,0.150949,139.057709,7.083938,1.509493,-120.276489,0.150602,0.000000
97.350006,30.980270,-120.320976,0.006920,0.005930,0.150628,137.807129,7.020230,1.506284,-120.320976,0.150169,0.000000
97.610008,30.731895,-120.365456,0.006916,0.005915,0.150238,136.702301,6.963947,1.502382,-120.365456,0.149735,0.000000
97.870003,30.617950,-120.320976,0.006916,0.005894,0.149709,136.195450,6.938127,1.497092,-120.320976,0.149302,0.000000
98.130005,30.404587,-120.454414,0.006920,0.005873,0.149171,135.246353,6.889778,1.491715,-120.454414,0.148868,0.000000
98.390007,30.297714,-120.454414,0.006924,0.005858,0.148790,134.770966,6.865561,1.487899,-120.454414,0.148434,0.000000
98.650002,30.167381,-120.454414,0.006929,0.005847,0.148521,134.191208,6.836027,1.485211,-120.454414,0.148001,0.000000
98.910004,30.063866,-120.543381,0.006929,0.005833,0.148166,133.730759,6.812569,1.481655,-120.543381,0.147567,0.000000
99.170006,29.946564,-120.498894,0.006937,0.005816,0.147732,133.208969,6.785988,1.477319,-120.498894,0.147134,0.000000
99.430008,29.833366,-120.543381,0.006916,0.005795,0.147186,132.705444,6.760337,1.471855,-120.543381,0.146700,0.000000
99.690002,29.727608,-120.498894,0.006933,0.005778,0.146761,132.235001,6.736372,1.467606,-120.498894,0.146266,0.000000
99.950005,29.606964,-120.587860,0.006929,0.005763,0.146388,131.698349,6.709034,1.463877,-120.587860,0.145833,0.000000
100.210007,29.500465,-120.676819,0.006911,0.005741,0.145833,131.224625,6.684901,1.458327,-120.676819,0.145399,0.000000
100.470001,29.327309,-120.721298,0.006933,0.005728,0.145486,130.454391,6.645663,1.454858,-120.721298,0.144965,0.000000
100.730003,29.125854,-120.765785,0.006911,0.005718,0.145226,129.558273,6.600013,1.452256,-120.765785,0.144532,0.000000
100.990005,28.685341,-120.721298,0.006924,0.005704,0.144887,127.598770,6.500191,1.448874,-120.721298,0.144098,0.000000
101.250008,28.044861,-120.721298,0.006946,0.005684,0.144384,124.749771,6.355056,1.443844,-120.721298,0.143665,0.000000
101.510002,27.388367,-120.810265,0.006937,0.005672,0.144064,121.829536,6.206292,1.440635,-120.810265,0.143231,0.000000
101.770004,26.614578,-120.810265,0.006946,0.005654,0.143613,118.387558,6.030950,1.436126,-120.810265,0.142797,0.000000
102.030006,25.656464,-120.899223,0.006946,0.005635,0.143127,114.125648,5.813838,1.431269,-120.899223,0.142364,0.000000
102.290009,24.381828,-120.854744,0.006946,0.005613,0.142581,108.455788,5.525001,1.425806,-120.854744,0.141930,0.000000
102.550003,23.579369,-120.943703,0.006946,0.005602,0.142286,104.886269,5.343162,1.422857,-120.943703,0.141497,0.000000
102.810005,23.125076,-120.943703,0.006937,0.005595,0.142112,102.865479,5.240217,1.421123,-120.943703,0.141063,0.000000
103.070007,21.950241,-120.943703,0.006937,0.005576,0.141627,97.639549,4.973996,1.416266,-120.943703,0.140629,0.000000
103.330002,20.531502,-121.032669,0.006942,0.005553,0.141054,91.328682,4.652505,1.410543,-121.032669,0.140196,0.000000
103.590004,19.642647,-120.988190,0.006954,0.005544,0.140829,87.374855,4.451087,1.408288,-120.988190,0.139762,0.000000
103.850006,18.152786,-121.077148,0.006937,0.005523,0.140291,80.747627,4.113480,1.402911,-121.077148,0.139328,0.000000
104.110008,16.990608,-121.077148,0.006950,0.005505,0.139831,75.578003,3.850127,1.398315,-121.077148,0.138895,0.000000
104.370003,15.171196,-121.121628,0.006937,0.005484,0.139302,67.484848,3.437842,1.393025,-121.121628,0.138461,0.000000
104.630005,14.100624,-121.210594,0.006942,0.005472,0.138990,62.722710,3.195247,1.389903,-121.210594,0.138028,0.000000
104.890007,13.295189,-121.210594,0.006933,0.005462,0.138739,59.139954,3.012733,1.387388,-121.210594,0.137594,0.000000
105.150002,12.270416,-121.210594,0.006907,0.005447,0.138366,54.581539,2.780516,1.383659,-121.210594,0.137160,0.000000
105.410004,9.988892,-121.210594,0.006911,0.005420,0.137672,44.432808,2.263515,1.376721,-121.210594,0.136735,0.000000
105.670006,9.458260,-121.255074,0.006898,0.005407,0.137334,42.072441,2.143272,1.373339,-121.255074,0.136302,0.000000
105.930008,7.809769,-121.255074,0.006898,0.005390,0.136900,34.739586,1.769719,1.369002,-121.255074,0.135868,0.000000
106.190002,6.060364,-121.255074,0.006873,0.005366,0.136302,26.957844,1.373298,1.363019,-121.255074,0.135435,0.000000
106.450005,5.047134,-121.432999,0.006903,0.005353,0.135955,22.450775,1.143697,1.359550,-121.432999,0.135001,0.000000
106.710007,4.309464,-121.388512,0.006890,0.005341,0.135669,19.169451,0.976538,1.356688,-121.388512,0.134567,0.000000
106.970009,3.277252,-121.388512,0.006864,0.005322,0.135183,14.577946,0.742636,1.351831,-121.388512,0.134134,0.000000
107.230003,1.998520,-121.477478,0.006842,0.005301,0.134645,8.889860,0.452871,1.346455,-121.477478,0.133700,0.000000
107.490005,1.514809,-121.432999,0.006842,0.005292,0.134429,6.738205,0.343261,1.344286,-121.432999,0.133267,0.000000
107.750008,0.842674,-121.477478,0.006821,0.005273,0.133943,3.748402,0.190953,1.339430,-121.477478,0.132833,0.000000
108.010002,0.545151,-121.521957,0.006791,0.005259,0.133570,2.424952,0.123533,1.335701,-121.521957,0.132399,0.000000
108.270004,0.260658,-121.566437,0.006791,0.005241,0.133110,1.159466,0.059066,1.331105,-121.566437,0.132980,0.000000
108.300003,0.323593,-121.610924,0.006799,0.005241,0.133110,1.439414,0.073327,1.331105,-121.610924,0.132980,0.000000