File: Data/PDMS compression/PDMS 0010 Punched_1_07152024_150730.csv
Time (sec),S:Load (lbs),S:HL1 (DIM),S:LVDT (in),S:Position (in),Ch:Position (mm),Ch:Load (N),Ch:Stress (MPa),Ch:Strain (mm/mm),Ch:HL1 (DIM),Set Point (),Cycles ()
0.110000,0.011917,-77.574776,0.000009,0.000089,0.002272,0.053010,0.002700,0.022721,-77.574776,0.002437,0.000000
0.420000,0.016380,-77.619263,0.000017,0.000099,0.002515,0.072863,0.003712,0.025149,-77.619263,0.002853,0.000000
0.730000,0.014153,-77.663742,0.000026,0.000180,0.004570,0.062954,0.003207,0.045703,-77.663742,0.005437,0.000000
1.040000,-0.017128,-77.619263,0.000022,0.000276,0.007016,-0.076189,-0.003881,0.070158,-77.619263,0.008013,0.000000
1.350000,-0.049896,-77.752701,0.000121,0.000377,0.009574,-0.221950,-0.011307,0.095742,-77.752701,0.010597,0.000000
1.660000,0.018250,-77.841667,0.000263,0.000478,0.012141,0.081178,0.004135,0.121412,-77.841667,0.013182,0.000000
1.970000,0.027557,-77.797180,0.000349,0.000577,0.014647,0.122581,0.006245,0.146474,-77.797180,0.015766,0.000000
2.280000,0.006332,-77.886147,0.000453,0.000676,0.017171,0.028168,0.001435,0.171711,-77.886147,0.018350,0.000000
2.590000,-0.001488,-77.841667,0.000552,0.000784,0.019903,-0.006618,-0.000337,0.199028,-77.841667,0.020926,0.000000
2.900000,-0.002983,-77.975105,0.000681,0.000885,0.022470,-0.013269,-0.000676,0.224698,-77.975105,0.023510,0.000000
3.210000,0.026062,-78.019585,0.000759,0.000987,0.025080,0.115930,0.005906,0.250802,-78.019585,0.026095,0.000000
3.520000,0.022713,-77.975105,0.000867,0.001088,0.027638,0.101031,0.005147,0.276385,-77.975105,0.028679,0.000000
3.830000,-0.001862,-78.108551,0.000992,0.001186,0.030136,-0.008281,-0.000422,0.301361,-78.108551,0.031255,0.000000
4.140000,0.002235,-78.108551,0.001108,0.001293,0.032851,0.009944,0.000507,0.328505,-78.108551,0.033839,0.000000
4.450000,-0.025322,-78.108551,0.001190,0.001391,0.035339,-0.112638,-0.005738,0.353394,-78.108551,0.036423,0.000000
4.760000,0.014519,-78.197510,0.001324,0.001500,0.038097,0.064583,0.003290,0.380972,-78.197510,0.039008,0.000000
5.070000,0.003723,-78.153030,0.001418,0.001593,0.040473,0.016561,0.000844,0.404734,-78.153030,0.041583,0.000000
5.380000,-0.011543,-78.286476,0.001548,0.001697,0.043101,-0.051347,-0.002616,0.431011,-78.286476,0.044168,0.000000
5.690000,-0.006706,-78.375435,0.001625,0.001801,0.045755,-0.029831,-0.001520,0.457548,-78.375435,0.046752,0.000000
6.000000,-0.005211,-78.330956,0.001742,0.001900,0.048261,-0.023179,-0.001181,0.482611,-78.330956,0.049336,0.000000
6.310000,0.029045,-78.375435,0.001837,0.002004,0.050897,0.129199,0.006582,0.508975,-78.375435,0.051912,0.000000
6.620000,0.043938,-78.330956,0.001923,0.002102,0.053386,0.195445,0.009956,0.533864,-78.330956,0.054496,0.000000
6.930000,0.024200,-78.553360,0.002048,0.002204,0.055988,0.107649,0.005484,0.559881,-78.553360,0.057081,0.000000
7.240000,0.013779,-78.464401,0.002173,0.002310,0.058676,0.061291,0.003122,0.586765,-78.464401,0.059665,0.000000
7.550000,0.012657,-78.553360,0.002255,0.002407,0.061131,0.056302,0.002868,0.611307,-78.553360,0.062241,0.000000
7.860001,0.026062,-78.597839,0.002376,0.002513,0.063836,0.115930,0.005906,0.638365,-78.597839,0.064825,0.000000
8.170000,0.017128,-78.597839,0.002458,0.002609,0.066265,0.076189,0.003881,0.662647,-78.597839,0.067409,0.000000
8.480000,0.017128,-78.731285,0.002591,0.002707,0.068762,0.076189,0.003881,0.687623,-78.731285,0.069994,0.000000
8.790000,-0.009682,-78.642319,0.002686,0.002815,0.071503,-0.043066,-0.002194,0.715028,-78.642319,0.072578,0.000000
9.100000,-0.037613,-78.775764,0.002807,0.002918,0.074122,-0.167311,-0.008523,0.741218,-78.775764,0.075154,0.000000
9.410001,-0.010429,-78.775764,0.002902,0.003021,0.076732,-0.046392,-0.002363,0.767321,-78.775764,0.077738,0.000000
9.720000,0.029045,-78.820244,0.003009,0.003113,0.079074,0.129199,0.006582,0.790736,-78.820244,0.080322,0.000000
10.030001,0.023834,-78.864723,0.003113,0.003222,0.081840,0.106020,0.005401,0.818401,-78.864723,0.082907,0.000000
10.340000,-0.000000,-78.953690,0.003229,0.003326,0.084485,-0.000000,-0.000000,0.844851,-78.953690,0.085482,0.000000
10.650001,0.011543,-78.953690,0.003337,0.003425,0.086983,0.051347,0.002616,0.869827,-78.953690,0.088067,0.000000
10.960001,0.045425,-78.998169,0.003445,0.003532,0.089723,0.202062,0.010294,0.897232,-78.998169,0.090651,0.000000
11.270000,0.045799,-78.909210,0.003548,0.003625,0.092082,0.203725,0.010378,0.920820,-78.909210,0.093235,0.000000
11.580001,0.015640,-79.131615,0.003665,0.003730,0.094736,0.069571,0.003544,0.947357,-79.131615,0.095811,0.000000
11.890000,0.031281,-79.131615,0.003760,0.003839,0.097520,0.139143,0.007088,0.975195,-79.131615,0.098395,0.000000
12.200001,0.007820,-79.176094,0.003893,0.003935,0.099948,0.034786,0.001772,0.999478,-79.176094,0.100980,0.000000
12.510000,0.021225,-79.176094,0.004001,0.004041,0.102653,0.094413,0.004810,1.026535,-79.176094,0.103564,0.000000
12.820001,0.021973,-79.220573,0.004083,0.004138,0.105116,0.097739,0.004979,1.051164,-79.220573,0.106140,0.000000
13.130001,0.035378,-79.309532,0.004191,0.004244,0.107787,0.157367,0.008017,1.077875,-79.309532,0.108724,0.000000
13.440001,-0.005585,-79.265053,0.004277,0.004342,0.110285,-0.024842,-0.001266,1.102851,-79.265053,0.111308,0.000000
13.750001,-0.051758,-79.309532,0.004406,0.004441,0.112809,-0.230230,-0.011728,1.128087,-79.309532,0.113893,0.000000
14.060000,0.009308,-79.398499,0.004514,0.004548,0.115532,0.041403,0.002109,1.155318,-79.398499,0.116468,0.000000
14.370001,0.034630,-79.398499,0.004622,0.004647,0.118029,0.154041,0.007847,1.180294,-79.398499,0.119053,0.000000
14.680000,0.031281,-79.487457,0.004734,0.004749,0.120622,0.139143,0.007088,1.206224,-79.487457,0.121637,0.000000
14.990001,0.013779,-79.487457,0.004816,0.004847,0.123111,0.061291,0.003122,1.231113,-79.487457,0.124221,0.000000
15.300001,0.016754,-79.487457,0.004919,0.004952,0.125782,0.074526,0.003797,1.257824,-79.487457,0.126806,0.000000
15.610001,0.049522,-79.576424,0.005032,0.005056,0.128410,0.220287,0.011222,1.284101,-79.576424,0.129381,0.000000
15.920001,0.046547,-79.620903,0.005144,0.005148,0.130752,0.207051,0.010548,1.307516,-79.620903,0.131966,0.000000
16.230001,0.029045,-79.665382,0.005251,0.005256,0.133509,0.129199,0.006582,1.335094,-79.665382,0.134550,0.000000
16.540001,0.010429,-79.709862,0.005364,0.005361,0.136180,0.046392,0.002363,1.361804,-79.709862,0.137134,0.000000
16.850000,-0.005211,-79.754349,0.005467,0.005458,0.138635,-0.023179,-0.001181,1.386347,-79.754349,0.139710,0.000000
17.160002,0.016014,-79.754349,0.005588,0.005568,0.141418,0.071234,0.003629,1.414185,-79.754349,0.142294,0.000000
17.470001,0.014893,-79.843307,0.005687,0.005671,0.144046,0.066245,0.003375,1.440462,-79.843307,0.144879,0.000000
17.780001,0.018616,-79.887787,0.005786,0.005759,0.146266,0.082807,0.004218,1.462663,-79.887787,0.147463,0.000000
18.090000,-0.016014,-79.887787,0.005911,0.005864,0.148955,-0.071234,-0.003629,1.489547,-79.887787,0.150039,0.000000
18.400002,-0.020477,-79.932266,0.006010,0.005969,0.151617,-0.091088,-0.004640,1.516171,-79.932266,0.152623,0.000000
18.710001,0.019363,-80.065712,0.006118,0.006072,0.154227,0.086133,0.004388,1.542274,-80.065712,0.155207,0.000000
19.020000,0.034256,-80.021233,0.006239,0.006170,0.156725,0.152378,0.007763,1.567250,-80.021233,0.157792,0.000000
19.330002,0.024574,-80.154671,0.006312,0.006271,0.159275,0.109312,0.005569,1.592747,-80.154671,0.160367,0.000000
19.640001,0.013031,-80.110191,0.006428,0.006377,0.161972,0.057965,0.002953,1.619717,-80.110191,0.162952,0.000000
19.950001,0.019363,-80.154671,0.006554,0.006477,0.164521,0.086133,0.004388,1.645214,-80.154671,0.165536,0.000000
20.260000,0.048409,-80.154671,0.006657,0.006580,0.167140,0.215332,0.010970,1.671404,-80.154671,0.168120,0.000000
20.570002,0.034630,-80.199158,0.006765,0.006683,0.169759,0.154041,0.007847,1.697594,-80.199158,0.170696,0.000000
20.880001,0.021225,-80.288116,0.006829,0.006780,0.172205,0.094413,0.004810,1.722050,-80.288116,0.173280,0.000000
21.190001,0.024200,-80.243637,0.006980,0.006882,0.174815,0.107649,0.005484,1.748154,-80.243637,0.175865,0.000000
21.500002,-0.012665,-80.332596,0.007084,0.006983,0.177365,-0.056336,-0.002870,1.773650,-80.332596,0.178449,0.000000
21.810001,0.019363,-80.421562,0.007196,0.007091,0.180123,0.086133,0.004388,1.801228,-80.421562,0.181033,0.000000
22.120001,0.041336,-80.421562,0.007278,0.007185,0.182490,0.183872,0.009367,1.824903,-80.421562,0.183609,0.000000
22.430000,0.002235,-80.510521,0.007394,0.007288,0.185118,0.009944,0.000507,1.851180,-80.510521,0.186193,0.000000
22.740002,0.013405,-80.510521,0.007515,0.007391,0.187728,0.059628,0.003038,1.877283,-80.510521,0.188778,0.000000
23.050001,0.018250,-80.555000,0.007601,0.007492,0.190304,0.081178,0.004135,1.903040,-80.555000,0.191362,0.000000
23.360001,0.052132,-80.599480,0.007705,0.007596,0.192949,0.231893,0.011813,1.929490,-80.599480,0.193938,0.000000
23.670002,0.062927,-80.643967,0.007825,0.007700,0.195585,0.279914,0.014260,1.955854,-80.643967,0.196522,0.000000
23.980001,0.040588,-80.643967,0.007929,0.007799,0.198083,0.180546,0.009197,1.980830,-80.643967,0.199106,0.000000
24.290001,0.032394,-80.688446,0.008032,0.007902,0.200702,0.144098,0.007341,2.007020,-80.688446,0.201691,0.000000
24.600000,0.038727,-80.777405,0.008132,0.008001,0.203217,0.172265,0.008776,2.032170,-80.777405,0.204266,0.000000
24.910002,0.058838,-80.777405,0.008257,0.008105,0.205871,0.261724,0.013333,2.058707,-80.777405,0.206851,0.000000
25.220001,0.050270,-80.821892,0.008360,0.008203,0.208360,0.223612,0.011391,2.083596,-80.821892,0.209435,0.000000
25.530001,0.045425,-80.910851,0.008459,0.008302,0.210883,0.202062,0.010294,2.108833,-80.910851,0.212019,0.000000
25.840002,0.041702,-80.866371,0.008576,0.008405,0.213494,0.185501,0.009450,2.134936,-80.866371,0.214595,0.000000
26.150002,0.003723,-80.955330,0.008692,0.008510,0.216156,0.016561,0.000844,2.161560,-80.955330,0.217179,0.000000
26.460001,0.053993,-80.955330,0.008800,0.008613,0.218775,0.240174,0.012235,2.187750,-80.955330,0.219764,0.000000
26.770000,0.069260,-80.999809,0.008877,0.008707,0.221160,0.308082,0.015694,2.211599,-80.999809,0.222348,0.000000
27.080002,0.091972,-81.088776,0.008985,0.008815,0.223900,0.409113,0.020841,2.239003,-81.088776,0.224924,0.000000
27.390001,0.095695,-81.088776,0.009080,0.008917,0.226485,0.425675,0.021685,2.264847,-81.088776,0.227508,0.000000
27.700001,0.112457,-81.133255,0.009201,0.009016,0.229000,0.500235,0.025483,2.289996,-81.133255,0.230092,0.000000
28.010002,0.256195,-81.177734,0.009343,0.009124,0.231757,1.139613,0.058055,2.317574,-81.177734,0.232677,0.000000
28.320002,0.453918,-81.177734,0.009399,0.009215,0.234056,2.019130,0.102859,2.340555,-81.177734,0.235244,0.000000
28.630001,0.425995,-81.266701,0.009421,-0.000001,-0.000017,1.894920,0.096532,-0.000173,-81.266701,0.000165,0.000000
28.940001,0.393967,-81.266701,0.009425,-0.000001,-0.000026,1.752451,0.089274,-0.000260,-81.266701,0.000269,0.000000
29.250002,0.406258,-81.355659,0.009425,-0.000001,-0.000026,1.807124,0.092059,-0.000260,-81.355659,0.000789,0.000000
29.560001,0.466957,-81.400139,0.009416,0.000011,0.000278,2.077129,0.105814,0.002775,-81.400139,0.001301,0.000000
29.870001,0.573456,-81.444618,0.009442,0.000037,0.000937,2.550859,0.129947,0.009366,-81.444618,0.001821,0.000000
30.180002,0.602501,-81.489105,0.009459,0.000054,0.001370,2.680058,0.136529,0.013702,-81.489105,0.002333,0.000000
30.490002,0.710861,-81.444618,0.009468,0.000073,0.001847,3.162069,0.161083,0.018472,-81.444618,0.002853,0.000000
30.800001,0.813637,-81.578064,0.009507,0.000097,0.002463,3.619237,0.184373,0.024629,-81.578064,0.003365,0.000000
31.110001,0.856827,-81.533585,0.009516,0.000111,0.002818,3.811356,0.194160,0.028185,-81.533585,0.003885,0.000000
31.420002,0.991257,-81.578064,0.009550,0.000129,0.003278,4.409330,0.224622,0.032781,-81.578064,0.004406,0.000000
31.730001,1.221756,-81.667023,0.009550,0.000162,0.004119,5.434642,0.276854,0.041193,-81.667023,0.004917,0.000000
32.040001,1.258621,-81.711510,0.009593,0.000174,0.004414,5.598627,0.285208,0.044142,-81.711510,0.005438,0.000000
32.350002,1.396027,-81.755989,0.009597,0.000195,0.004952,6.209836,0.316344,0.049519,-81.755989,0.005949,0.000000
32.660000,1.571785,-81.800468,0.009615,0.000222,0.005628,6.991649,0.356172,0.056283,-81.800468,0.006470,0.000000
32.970001,1.697273,-81.889427,0.009632,0.000239,0.006079,7.549849,0.384608,0.060793,-81.889427,0.006990,0.000000
33.280003,1.753128,-81.844948,0.009641,0.000253,0.006426,7.798303,0.397264,0.064261,-81.844948,0.007502,0.000000
33.590000,1.989212,-81.889427,0.009679,0.000283,0.007198,8.848457,0.450762,0.071980,-81.889427,0.008022,0.000000
33.900002,2.032036,-81.978394,0.009705,0.000297,0.007554,9.038947,0.460466,0.075535,-81.978394,0.008534,0.000000
34.210003,2.172050,-81.933914,0.009718,0.000318,0.008065,9.661763,0.492194,0.080652,-81.933914,0.009054,0.000000
34.520000,2.331421,-82.022873,0.009748,0.000340,0.008646,10.370678,0.528308,0.086462,-82.022873,0.009565,0.000000
34.830002,2.487823,-82.022873,0.009753,0.000363,0.009219,11.066392,0.563749,0.092186,-82.022873,0.010086,0.000000
35.140003,2.506439,-82.067352,0.009761,0.000376,0.009557,11.149199,0.567967,0.095568,-82.067352,0.010606,0.000000
35.450001,2.609215,-82.156319,0.009791,0.000394,0.010008,11.606367,0.591256,0.100078,-82.156319,0.011118,0.000000
35.760002,2.880676,-82.200798,0.009796,0.000425,0.010806,12.813888,0.652771,0.108056,-82.200798,0.011638,0.000000
36.070004,2.938766,-82.200798,0.009852,0.000441,0.011196,13.072287,0.665934,0.111959,-82.200798,0.012150,0.000000
36.380001,3.052711,-82.200798,0.009852,0.000460,0.011690,13.579139,0.691754,0.116902,-82.200798,0.012670,0.000000
36.690002,3.353584,-82.245277,0.009878,0.000485,0.012323,14.917488,0.759933,0.123233,-82.245277,0.013182,0.000000
37.000000,3.249321,-82.334244,0.009886,0.000498,0.012661,14.453702,0.736307,0.126615,-82.334244,0.013702,0.000000
37.310001,3.499931,-82.423203,0.009904,0.000522,0.013251,15.568472,0.793096,0.132512,-82.423203,0.014223,0.000000
37.620003,3.626534,-82.423203,0.009929,0.000547,0.013893,16.131626,0.821784,0.138930,-82.423203,0.014734,0.000000
37.930000,3.549828,-82.467682,0.009973,0.000563,0.014301,15.790421,0.804402,0.143006,-82.467682,0.015255,0.000000
38.240002,3.675690,-82.512161,0.009973,0.000579,0.014717,16.350285,0.832923,0.147168,-82.512161,0.015766,0.000000
38.550003,3.898743,-82.556648,0.010020,0.000603,0.015307,17.342474,0.883468,0.153065,-82.556648,0.016286,0.000000
38.860001,4.071144,-82.512161,0.010007,0.000628,0.015957,18.109354,0.922534,0.159570,-82.512161,0.016807,0.000000
39.170002,4.230148,-82.690086,0.010046,0.000651,0.016529,18.816639,0.958565,0.165293,-82.690086,0.017318,0.000000
39.480003,4.217491,-82.645607,0.010072,0.000670,0.017015,18.760338,0.955697,0.170150,-82.645607,0.017839,0.000000
39.790001,4.279678,-82.645607,0.010080,0.000686,0.017423,19.036961,0.969789,0.174226,-82.645607,0.018350,0.000000
40.100002,4.371651,-82.779053,0.010080,0.000704,0.017874,19.446074,0.990630,0.178735,-82.779053,0.018871,0.000000
40.410004,4.650932,-82.823532,0.010093,0.000725,0.018411,20.688379,1.053916,0.184112,-82.823532,0.019382,0.000000
40.720001,4.687050,-82.868011,0.010128,0.000745,0.018932,20.849039,1.062101,0.189315,-82.868011,0.019903,0.000000
41.030003,4.822968,-82.823532,0.010128,0.000761,0.019322,21.453630,1.092900,0.193218,-82.823532,0.020423,0.000000
41.340000,5.059425,-82.868011,0.010184,0.000796,0.020206,22.505447,1.146482,0.202064,-82.868011,0.020935,0.000000
41.650002,4.952927,-83.001457,0.010179,0.000809,0.020536,22.031717,1.122349,0.205359,-83.001457,0.021455,0.000000
41.960003,5.059799,-82.912491,0.010214,0.000827,0.021004,22.507111,1.146567,0.210042,-82.912491,0.021967,0.000000
42.270000,5.078789,-83.134895,0.010236,0.000846,0.021490,22.591581,1.150870,0.214899,-83.134895,0.022487,0.000000
42.580002,5.387115,-83.001457,0.010236,0.000868,0.022036,23.963087,1.220738,0.220362,-83.001457,0.023007,0.000000
42.890003,5.434776,-83.134895,0.010261,0.000886,0.022505,24.175093,1.231538,0.225045,-83.134895,0.023519,0.000000
43.200001,5.931145,-83.090416,0.010296,0.000919,0.023337,26.383049,1.344017,0.233370,-83.090416,0.024039,0.000000
43.510002,5.664528,-83.179375,0.010317,0.000934,0.023727,25.197079,1.283600,0.237273,-83.179375,0.024551,0.000000
43.820004,5.701019,-83.268341,0.010339,0.000950,0.024118,25.359400,1.291869,0.241175,-83.268341,0.025071,0.000000
44.130001,5.718147,-83.223862,0.010352,0.000966,0.024525,25.435589,1.295751,0.245251,-83.223862,0.025583,0.000000
44.440002,6.084190,-83.357300,0.010361,0.000994,0.025236,27.063831,1.378697,0.252363,-83.357300,0.026103,0.000000
44.750004,6.006371,-83.357300,0.010395,0.001009,0.025627,26.717670,1.361063,0.256265,-83.357300,0.026624,0.000000
45.060001,6.313202,-83.357300,0.010421,0.001033,0.026234,28.082525,1.430592,0.262336,-83.357300,0.027135,0.000000
45.370003,6.406670,-83.446266,0.010434,0.001053,0.026745,28.498289,1.451772,0.267452,-83.446266,0.027656,0.000000
45.680000,6.512421,-83.357300,0.010460,0.001072,0.027231,28.968695,1.475736,0.272309,-83.357300,0.028167,0.000000
45.990002,6.502739,-83.535225,0.010460,0.001090,0.027691,28.925627,1.473542,0.276905,-83.535225,0.028688,0.000000
46.300003,6.740685,-83.535225,0.010486,0.001115,0.028332,29.984062,1.527461,0.283323,-83.535225,0.029208,0.000000
46.610001,6.756699,-83.535225,0.010520,0.001134,0.028809,30.055296,1.531090,0.288092,-83.535225,0.029720,0.000000
46.920002,6.962616,-83.624191,0.010511,0.001154,0.029312,30.971262,1.577751,0.293122,-83.624191,0.030240,0.000000
47.230003,6.995758,-83.624191,0.010546,0.001175,0.029841,31.118687,1.585261,0.298412,-83.624191,0.030752,0.000000
47.540001,6.971931,-83.668671,0.010559,0.001193,0.030310,31.012699,1.579862,0.303095,-83.668671,0.031272,0.000000
47.850002,7.159233,-83.713150,0.010585,0.001215,0.030865,31.845860,1.622305,0.308646,-83.713150,0.031784,0.000000
48.160004,7.318237,-83.757629,0.010602,0.001236,0.031385,32.553146,1.658336,0.313849,-83.757629,0.032304,0.000000
48.470001,7.283607,-83.802109,0.010611,0.001254,0.031862,32.399105,1.650489,0.318619,-83.802109,0.032824,0.000000
48.780003,7.363663,-83.846596,0.010649,0.001273,0.032322,32.755207,1.668630,0.323215,-83.846596,0.033336,0.000000
49.090004,7.525650,-83.935555,0.010675,0.001298,0.032972,33.475761,1.705337,0.329719,-83.935555,0.033856,0.000000
49.400002,7.581131,-83.891075,0.010688,0.001320,0.033527,33.722553,1.717909,0.335269,-83.891075,0.034368,0.000000
49.710003,7.566605,-83.935555,0.010714,0.001338,0.033987,33.657940,1.714617,0.339866,-83.935555,0.034888,0.000000
50.020004,7.786308,-83.980034,0.010740,0.001358,0.034498,34.635227,1.764403,0.344982,-83.980034,0.035400,0.000000
50.330002,7.816101,-84.024513,0.010753,0.001378,0.034993,34.767754,1.771154,0.349926,-84.024513,0.035920,0.000000
50.640003,7.693588,-84.157959,0.010762,0.001390,0.035313,34.222790,1.743392,0.353134,-84.157959,0.036441,0.000000
50.950001,7.976959,-84.113480,0.010787,0.001414,0.035920,35.483288,1.807605,0.359205,-84.113480,0.036952,0.000000
51.260002,8.095001,-84.291405,0.010813,0.001440,0.036580,36.008366,1.834353,0.365796,-84.291405,0.037473,0.000000
51.570004,8.142670,-84.202438,0.010852,0.001458,0.037039,36.220406,1.845155,0.370392,-84.202438,0.037984,0.000000
51.880001,7.982178,-84.202438,0.010865,0.001475,0.037473,35.506500,1.808787,0.374728,-84.202438,0.038505,0.000000
52.190002,8.372421,-84.291405,0.010865,0.001501,0.038132,37.242390,1.897218,0.381319,-84.291405,0.039025,0.000000
52.500004,8.185120,-84.335884,0.010904,0.001515,0.038470,36.409229,1.854775,0.384701,-84.335884,0.039537,0.000000
52.810001,8.426414,-84.380363,0.010917,0.001534,0.038973,37.482563,1.909453,0.389731,-84.380363,0.040057,0.000000
53.120003,8.569778,-84.380363,0.010951,0.001564,0.039719,38.120277,1.941939,0.397189,-84.380363,0.040569,0.000000
53.430004,8.473709,-84.424843,0.010968,0.001577,0.040066,37.692940,1.920170,0.400658,-84.424843,0.041089,0.000000
53.740002,8.776817,-84.469330,0.010968,0.001604,0.040734,39.041233,1.988855,0.407336,-84.469330,0.041601,0.000000
54.050003,8.731392,-84.469330,0.010990,0.001623,0.041228,38.839172,1.978562,0.412279,-84.469330,0.042121,0.000000
54.360004,8.648720,-84.602768,0.011042,0.001639,0.041636,38.471428,1.959828,0.416355,-84.602768,0.042641,0.000000
54.670002,9.056099,-84.602768,0.011042,0.001665,0.042286,40.283539,2.052141,0.422859,-84.602768,0.043153,0.000000
54.980003,9.051628,-84.647247,0.011098,0.001688,0.042884,40.263653,2.051128,0.428843,-84.647247,0.043673,0.000000
55.290001,9.012901,-84.736214,0.011094,0.001703,0.043249,40.091389,2.042353,0.432485,-84.736214,0.044185,0.000000
55.600002,9.006569,-84.736214,0.011124,0.001722,0.043734,40.063221,2.040918,0.437342,-84.736214,0.044705,0.000000
55.910004,9.242653,-84.736214,0.011119,0.001747,0.044367,41.113373,2.094415,0.443673,-84.736214,0.045226,0.000000
56.220001,9.224037,-84.825172,0.011167,0.001764,0.044818,41.030567,2.090197,0.448182,-84.825172,0.045737,0.000000
56.530003,9.229248,-84.869652,0.011167,0.001780,0.045217,41.053745,2.091377,0.452171,-84.869652,0.046258,0.000000
56.840004,9.594551,-84.914139,0.011188,0.001807,0.045894,42.678696,2.174156,0.458936,-84.914139,0.046769,0.000000
57.150002,9.456398,-84.914139,0.011244,0.001827,0.046405,42.064159,2.142850,0.464052,-84.914139,0.047290,0.000000
57.460003,9.383415,-84.958618,0.011236,0.001842,0.046778,41.739517,2.126312,0.467782,-84.958618,0.047801,0.000000
57.770004,9.617638,-84.914139,0.011266,0.001864,0.047342,42.781387,2.179388,0.473419,-84.914139,0.048322,0.000000
58.080002,9.752434,-85.047577,0.011275,0.001884,0.047854,43.380993,2.209933,0.478535,-85.047577,0.048842,0.000000
58.390003,9.722641,-85.003098,0.011296,0.001899,0.048226,43.248466,2.203182,0.482264,-85.003098,0.049354,0.000000
58.700005,9.998947,-85.136543,0.011300,0.001923,0.048833,44.477539,2.265794,0.488335,-85.136543,0.049874,0.000000
59.010002,10.031342,-85.136543,0.011348,0.001950,0.049527,44.621635,2.273134,0.495273,-85.136543,0.050386,0.000000
59.320004,9.928566,-85.181023,0.011352,0.001966,0.049944,44.164467,2.249845,0.499435,-85.181023,0.050906,0.000000
59.630001,9.835846,-85.225502,0.011374,0.001983,0.050368,43.752029,2.228834,0.503685,-85.225502,0.051418,0.000000
59.940002,10.183640,-85.314461,0.011400,0.002006,0.050941,45.299091,2.307646,0.509408,-85.314461,0.051938,0.000000
60.250004,10.208221,-85.314461,0.011456,0.002030,0.051557,45.408436,2.313216,0.515566,-85.314461,0.052458,0.000000
60.560001,10.354187,-85.403427,0.011451,0.002054,0.052164,46.057724,2.346292,0.521636,-85.403427,0.052970,0.000000
60.870003,10.382492,-85.358948,0.011486,0.002075,0.052701,46.183632,2.352706,0.527013,-85.358948,0.053490,0.000000
61.180004,10.293121,-85.492386,0.011507,0.002090,0.053074,45.786091,2.332454,0.530742,-85.492386,0.054002,0.000000
61.490002,10.363129,-85.447906,0.011512,0.002107,0.053508,46.097500,2.348319,0.535078,-85.447906,0.054522,0.000000
61.800003,10.580589,-85.536865,0.011538,0.002129,0.054089,47.064812,2.397596,0.540889,-85.536865,0.055043,0.000000
62.110004,10.436111,-85.536865,0.011555,0.002145,0.054488,46.422142,2.364857,0.544878,-85.536865,0.055554,0.000000
62.420002,10.655807,-85.536865,0.011555,0.002169,0.055086,47.399399,2.414641,0.550862,-85.536865,0.056075,0.000000
62.730003,10.838272,-85.670311,0.011594,0.002197,0.055815,48.211040,2.455987,0.558146,-85.670311,0.056586,0.000000
63.040005,10.717621,-85.625832,0.011620,0.002212,0.056196,47.674358,2.428648,0.561962,-85.625832,0.057107,0.000000
63.350002,11.026695,-85.714790,0.011650,0.002234,0.056734,49.049191,2.498685,0.567339,-85.714790,0.057618,0.000000
63.660004,11.041588,-85.670311,0.011654,0.002252,0.057194,49.115437,2.502059,0.571935,-85.670311,0.058139,0.000000
63.970001,10.925034,-85.803757,0.011684,0.002270,0.057653,48.596977,2.475648,0.576532,-85.803757,0.058659,0.000000
64.280006,11.043076,-85.848236,0.011693,0.002287,0.058087,49.122055,2.502397,0.580868,-85.848236,0.059171,0.000000
64.590004,11.554718,-85.803757,0.011727,0.002321,0.058945,51.397953,2.618336,0.589453,-85.803757,0.059691,0.000000
64.900002,11.206551,-85.892715,0.011745,0.002335,0.059318,49.849228,2.539441,0.593182,-85.892715,0.060203,0.000000
65.210007,11.212875,-85.937195,0.011749,0.002354,0.059787,49.877361,2.540874,0.597865,-85.937195,0.060723,0.000000
65.520004,11.440773,-85.937195,0.011788,0.002373,0.060272,50.891102,2.592516,0.602722,-85.937195,0.061243,0.000000
65.830002,11.573708,-86.115120,0.011788,0.002395,0.060845,51.482422,2.622640,0.608446,-86.115120,0.061755,0.000000
66.139999,11.483223,-85.981682,0.011801,0.002410,0.061226,51.079926,2.602136,0.612261,-85.981682,0.062275,0.000000
66.450005,11.708504,-86.070641,0.011831,0.002434,0.061825,52.082027,2.653185,0.618245,-86.070641,0.062787,0.000000
66.760002,11.846657,-86.026161,0.011870,0.002457,0.062414,52.696560,2.684491,0.624142,-86.026161,0.063307,0.000000
67.070000,11.720047,-86.115120,0.011900,0.002473,0.062804,52.133373,2.655801,0.628045,-86.115120,0.063819,0.000000
67.380005,11.743507,-86.248566,0.011913,0.002490,0.063238,52.237728,2.661117,0.632381,-86.248566,0.064339,0.000000
67.690002,12.171738,-86.204086,0.011913,0.002520,0.064001,54.142593,2.758155,0.640013,-86.204086,0.064860,0.000000
68.000000,11.857452,-86.293045,0.011943,0.002533,0.064331,52.744583,2.686937,0.643308,-86.293045,0.065371,0.000000
68.310005,12.255150,-86.293045,0.011956,0.002555,0.064886,54.513630,2.777057,0.648858,-86.293045,0.065892,0.000000
68.620003,12.284569,-86.337524,0.011999,0.002580,0.065528,54.644489,2.783723,0.655276,-86.337524,0.066403,0.000000
68.930000,12.077530,-86.382004,0.012008,0.002593,0.065866,53.723537,2.736808,0.658658,-86.382004,0.066924,0.000000
69.240005,12.248444,-86.382004,0.012033,0.002614,0.066403,54.483799,2.775537,0.664035,-86.382004,0.067435,0.000000
69.550003,12.560493,-86.470970,0.012029,0.002638,0.067011,55.871864,2.846248,0.670105,-86.470970,0.067956,0.000000
69.860001,12.369843,-86.515450,0.012064,0.002657,0.067488,55.023808,2.803046,0.674875,-86.515450,0.068476,0.000000
70.170006,12.898239,-86.559929,0.012085,0.002681,0.068103,57.374233,2.922783,0.681032,-86.559929,0.068988,0.000000
70.480003,12.725456,-86.559929,0.012098,0.002702,0.068624,56.605656,2.883630,0.686236,-86.559929,0.069508,0.000000
70.790001,12.700882,-86.648895,0.012146,0.002722,0.069135,56.496346,2.878061,0.691352,-86.648895,0.070020,0.000000
71.100006,12.624168,-86.648895,0.012146,0.002738,0.069534,56.155106,2.860677,0.695342,-86.648895,0.070540,0.000000
71.410004,12.819664,-86.648895,0.012158,0.002760,0.070107,57.024712,2.904977,0.701065,-86.648895,0.071060,0.000000
71.720001,12.836052,-86.826813,0.012171,0.002780,0.070610,57.097610,2.908691,0.706095,-86.826813,0.071572,0.000000
72.030006,12.632362,-86.737854,0.012219,0.002790,0.070870,56.191555,2.862534,0.708697,-86.737854,0.072092,0.000000
72.340004,13.223320,-86.782333,0.012223,0.002822,0.071685,58.820267,2.996447,0.716849,-86.782333,0.072604,0.000000
72.650002,13.117195,-86.915779,0.012227,0.002841,0.072162,58.348198,2.972399,0.721618,-86.915779,0.073124,0.000000
72.960007,13.066551,-86.915779,0.012271,0.002860,0.072647,58.122921,2.960923,0.726475,-86.915779,0.073636,0.000000
73.270004,13.339874,-87.004738,0.012296,0.002884,0.073255,59.338726,3.022859,0.732546,-87.004738,0.074156,0.000000
73.580002,13.260925,-86.915779,0.012314,0.002903,0.073732,58.987541,3.004969,0.737315,-86.915779,0.074677,0.000000
73.890007,13.069153,-87.004738,0.012331,0.002915,0.074035,58.134495,2.961512,0.740351,-87.004738,0.075188,0.000000
74.200005,13.538345,-87.049225,0.012348,0.002939,0.074659,60.221569,3.067833,0.746595,-87.049225,0.075709,0.000000
74.510002,13.544678,-87.049225,0.012387,0.002966,0.075336,60.249737,3.069268,0.753359,-87.049225,0.076220,0.000000
74.820007,13.535736,-87.138184,0.012391,0.002983,0.075761,60.209961,3.067242,0.757608,-87.138184,0.076741,0.000000
75.130005,13.801987,-87.182663,0.012409,0.003008,0.076403,61.394302,3.127575,0.764026,-87.182663,0.077261,0.000000
75.440002,13.630318,-87.271629,0.012460,0.003027,0.076880,60.630680,3.088674,0.768796,-87.271629,0.077773,0.000000
75.750000,13.419556,-87.227142,0.012452,0.003040,0.077218,59.693165,3.040915,0.772178,-87.227142,0.078293,0.000000
76.060005,13.997482,-87.271629,0.012490,0.003067,0.077903,62.263912,3.171875,0.779029,-87.271629,0.078805,0.000000
76.370003,14.009766,-87.360588,0.012508,0.003090,0.078493,62.318550,3.174658,0.784926,-87.360588,0.079325,0.000000
76.680000,13.744637,-87.360588,0.012529,0.003103,0.078813,61.139198,3.114579,0.788135,-87.360588,0.079837,0.000000
76.990005,14.238777,-87.449547,0.012551,0.003130,0.079507,63.337246,3.226553,0.795073,-87.449547,0.080357,0.000000
77.300003,14.124832,-87.405067,0.012572,0.003150,0.080010,62.830391,3.200733,0.800102,-87.405067,0.080877,0.000000
77.610001,13.888374,-87.449547,0.012581,0.003164,0.080366,61.778576,3.147151,0.803658,-87.449547,0.081389,0.000000
77.920006,14.097275,-87.494034,0.012585,0.003183,0.080843,62.707809,3.194488,0.808428,-87.494034,0.081909,0.000000
78.230003,14.478958,-87.538513,0.012637,0.003212,0.081580,64.405624,3.280979,0.815799,-87.538513,0.082421,0.000000
78.540001,14.137863,-87.538513,0.012633,0.003226,0.081953,62.888355,3.203686,0.819528,-87.538513,0.082941,0.000000
78.850006,14.149033,-87.538513,0.012663,0.003244,0.082386,62.938042,3.206217,0.823864,-87.538513,0.083462,0.000000
79.160004,14.295753,-87.671951,0.012702,0.003263,0.082881,63.590687,3.239464,0.828808,-87.671951,0.083973,0.000000
79.470001,14.441345,-87.671951,0.012719,0.003286,0.083462,64.238312,3.272456,0.834618,-87.671951,0.084494,0.000000
79.780006,14.385117,-87.716438,0.012736,0.003302,0.083869,63.988194,3.259714,0.838694,-87.716438,0.085005,0.000000
80.090004,14.618599,-87.805397,0.012745,0.003328,0.084520,65.026779,3.312622,0.845198,-87.805397,0.085526,0.000000
80.400002,14.716904,-87.760918,0.012766,0.003353,0.085170,65.464058,3.334898,0.851702,-87.760918,0.086037,0.000000
80.710007,14.531090,-87.805397,0.012779,0.003368,0.085543,64.637512,3.292792,0.855431,-87.805397,0.086558,0.000000
81.020004,14.647270,-87.938843,0.012792,0.003385,0.085985,65.154312,3.319119,0.859854,-87.938843,0.087078,0.000000
81.330002,14.960060,-87.938843,0.012835,0.003412,0.086671,66.545670,3.389998,0.866705,-87.938843,0.087590,0.000000
81.640007,14.802177,-88.027802,0.012835,0.003430,0.087121,65.843376,3.354221,0.871215,-88.027802,0.088110,0.000000
81.950005,15.057999,-87.983322,0.012874,0.003457,0.087807,66.981323,3.412191,0.878066,-87.983322,0.088622,0.000000
82.260002,15.034538,-88.072281,0.012917,0.003477,0.088310,66.876968,3.406875,0.883096,-88.072281,0.089142,0.000000
82.570007,14.956337,-88.072281,0.012913,0.003493,0.088717,66.529106,3.389154,0.887172,-88.072281,0.089654,0.000000
82.880005,14.861382,-88.161247,0.012935,0.003507,0.089073,66.106728,3.367637,0.890727,-88.161247,0.090174,0.000000
83.190002,15.304878,-88.161247,0.012952,0.003535,0.089801,68.079498,3.468135,0.898012,-88.161247,0.090694,0.000000
83.500008,14.997673,-88.205727,0.012982,0.003546,0.090070,66.712982,3.398521,0.900701,-88.205727,0.091206,0.000000
83.810005,15.753586,-88.250206,0.012986,0.003577,0.090851,70.075447,3.569814,0.908506,-88.250206,0.091726,0.000000
84.120003,15.365952,-88.294685,0.013016,0.003598,0.091380,68.351166,3.481974,0.913796,-88.294685,0.092238,0.000000
84.430000,15.349564,-88.294685,0.013034,0.003614,0.091796,68.278267,3.478261,0.917958,-88.294685,0.092758,0.000000
84.740005,15.403931,-88.428131,0.013034,0.003633,0.092281,68.520103,3.490581,0.922815,-88.428131,0.093279,0.000000
85.050003,15.660866,-88.383652,0.013085,0.003656,0.092863,69.663010,3.548803,0.928625,-88.383652,0.093790,0.000000
85.360001,15.637039,-88.428131,0.013111,0.003673,0.093287,69.557022,3.543404,0.932875,-88.428131,0.094311,0.000000
85.670006,15.532402,-88.517090,0.013111,0.003687,0.093660,69.091576,3.519692,0.936604,-88.517090,0.094822,0.000000
85.980003,16.087982,-88.517090,0.013159,0.003724,0.094580,71.562920,3.645589,0.945796,-88.517090,0.095343,0.000000
86.290001,15.698105,-88.517090,0.013163,0.003737,0.094909,69.828659,3.557241,0.949092,-88.517090,0.095854,0.000000
86.600006,15.890991,-88.606056,0.013198,0.003757,0.095421,70.686661,3.600950,0.954208,-88.606056,0.096375,0.000000
86.910004,16.201927,-88.650536,0.013189,0.003779,0.095985,72.069771,3.671409,0.959845,-88.650536,0.096895,0.000000
87.220001,16.077553,-88.695015,0.013232,0.003798,0.096462,71.516525,3.643225,0.964615,-88.695015,0.097407,0.000000
87.530006,16.181816,-88.739494,0.013245,0.003816,0.096930,71.980316,3.666852,0.969298,-88.739494,0.097927,0.000000
87.840004,16.226128,-88.739494,0.013241,0.003838,0.097494,72.177422,3.676893,0.974935,-88.739494,0.098439,0.000000
88.150002,16.359436,-88.739494,0.013292,0.003858,0.098005,72.770409,3.707101,0.980052,-88.739494,0.098959,0.000000
88.460007,16.426842,-88.783981,0.013305,0.003878,0.098508,73.070244,3.722376,0.985082,-88.783981,0.099479,0.000000
88.770004,16.643188,-88.828461,0.013336,0.003900,0.099072,74.032600,3.771400,0.990719,-88.828461,0.099991,0.000000
89.080002,16.713196,-88.917419,0.013353,0.003924,0.099662,74.344009,3.787264,0.996616,-88.917419,0.100511,0.000000
89.390007,16.321083,-88.872940,0.013379,0.003936,0.099965,72.599800,3.698410,0.999651,-88.872940,0.101023,0.000000
89.700005,16.769791,-88.961899,0.013400,0.003958,0.100537,74.595757,3.800089,1.005375,-88.961899,0.101543,0.000000
90.010002,16.859909,-89.095345,0.013409,0.003983,0.101162,74.996620,3.820510,1.011619,-89.095345,0.102055,0.000000
90.320007,16.807030,-89.050865,0.013443,0.004000,0.101604,74.761398,3.808527,1.016042,-89.050865,0.102575,0.000000
90.630005,16.837196,-89.139824,0.013435,0.004018,0.102046,74.895592,3.815363,1.020464,-89.139824,0.103096,0.000000
90.940002,17.237495,-89.095345,0.013486,0.004042,0.102671,76.676208,3.906072,1.026708,-89.095345,0.103607,0.000000
91.250008,17.132858,-89.228790,0.013508,0.004060,0.103113,76.210762,3.882361,1.031131,-89.228790,0.104128,0.000000
91.560005,17.400223,-89.139824,0.013517,0.004084,0.103729,77.400055,3.942947,1.037289,-89.139824,0.104639,0.000000
91.870003,17.532410,-89.184303,0.013551,0.004107,0.104327,77.988052,3.972901,1.043272,-89.184303,0.105160,0.000000
92.180008,17.436340,-89.317749,0.013573,0.004125,0.104770,77.560715,3.951131,1.047695,-89.317749,0.105671,0.000000
92.490005,17.460541,-89.273270,0.013581,0.004142,0.105203,77.668365,3.956615,1.052032,-89.273270,0.106192,0.000000
92.800003,17.644493,-89.406715,0.013603,0.004166,0.105810,78.486626,3.998299,1.058102,-89.406715,0.106712,0.000000
93.110001,17.663490,-89.451195,0.013620,0.004184,0.106261,78.571129,4.002604,1.062612,-89.451195,0.107224,0.000000
93.420006,17.668327,-89.451195,0.013642,0.004200,0.106686,78.592644,4.003700,1.066861,-89.451195,0.107744,0.000000
93.730003,18.242157,-89.540154,0.013655,0.004226,0.107345,81.145164,4.133732,1.073452,-89.540154,0.108256,0.000000
94.040001,17.839989,-89.495674,0.013676,0.004241,0.107709,79.356232,4.042599,1.077094,-89.495674,0.108776,0.000000
94.350006,17.918190,-89.540154,0.013685,0.004263,0.108282,79.704086,4.060320,1.082818,-89.540154,0.109296,0.000000
94.660004,18.238434,-89.584633,0.013732,0.004286,0.108872,81.128609,4.132888,1.088715,-89.584633,0.109808,0.000000
94.970001,18.149803,-89.629120,0.013754,0.004304,0.109314,80.734360,4.112804,1.093138,-89.629120,0.110328,0.000000
95.280006,18.325569,-89.673599,0.013775,0.004322,0.109791,81.516205,4.152633,1.097908,-89.673599,0.110840,0.000000
95.590004,18.340836,-89.718079,0.013775,0.004341,0.110259,81.584114,4.156093,1.102591,-89.718079,0.111360,0.000000
95.900002,18.511009,-89.762558,0.013805,0.004366,0.110892,82.341080,4.194654,1.108922,-89.762558,0.111872,0.000000
96.210007,18.662193,-89.718079,0.013840,0.004385,0.111369,83.013580,4.228913,1.113691,-89.718079,0.112392,0.000000
96.520004,19.022644,-89.851524,0.013883,0.004413,0.112080,84.616943,4.310593,1.120803,-89.851524,0.112913,0.000000
96.830002,18.920990,-89.851524,0.013887,0.004431,0.112557,84.164764,4.287558,1.125572,-89.851524,0.113424,0.000000
97.140007,18.905350,-89.896004,0.013892,0.004447,0.112947,84.095192,4.284013,1.129475,-89.896004,0.113945,0.000000
97.450005,19.167130,-89.940483,0.013909,0.004473,0.113607,85.259651,4.343334,1.136066,-89.940483,0.114456,0.000000
97.760002,19.091537,-89.940483,0.013956,0.004490,0.114058,84.923401,4.326204,1.140575,-89.940483,0.114977,0.000000
98.070007,19.240860,-90.073929,0.013982,0.004511,0.114569,85.587616,4.360041,1.145692,-90.073929,0.115497,0.000000
98.380005,19.481407,-90.029442,0.013982,0.004533,0.115133,86.657623,4.414550,1.151329,-90.029442,0.116009,0.000000
98.690002,19.453110,-90.118408,0.014021,0.004552,0.115619,86.531754,4.408138,1.156185,-90.118408,0.116529,0.000000
99.000008,19.148880,-90.162888,0.014012,0.004567,0.116009,85.178474,4.339199,1.160088,-90.162888,0.117041,0.000000
99.310005,19.438217,-90.118408,0.014060,0.004585,0.116460,86.465508,4.404763,1.164597,-90.118408,0.117561,0.000000
99.620003,19.930489,-90.207367,0.014103,0.004616,0.117249,88.655243,4.516313,1.172489,-90.207367,0.118073,0.000000
99.930008,19.751007,-90.207367,0.014099,0.004632,0.117657,87.856865,4.475642,1.176565,-90.207367,0.118593,0.000000
100.240005,19.904427,-90.296333,0.014107,0.004651,0.118133,88.539314,4.510407,1.181335,-90.296333,0.119113,0.000000
100.550003,19.931984,-90.385292,0.014133,0.004668,0.118558,88.661896,4.516652,1.185584,-90.385292,0.119625,0.000000
100.860008,19.971077,-90.296333,0.014163,0.004686,0.119018,88.835785,4.525511,1.190181,-90.296333,0.120145,0.000000
101.170006,20.120399,-90.474251,0.014163,0.004705,0.119504,89.500008,4.559348,1.195037,-90.474251,0.120657,0.000000
101.480003,20.886742,-90.429771,0.014206,0.004738,0.120345,92.908867,4.733003,1.203449,-90.429771,0.121177,0.000000
101.790009,20.571716,-90.518738,0.014232,0.004756,0.120805,91.507561,4.661618,1.208045,-90.518738,0.121698,0.000000
102.100006,20.474152,-90.563217,0.014232,0.004771,0.121186,91.073578,4.639509,1.211861,-90.563217,0.122209,0.000000
102.410004,20.735191,-90.518738,0.014258,0.004790,0.121672,92.234741,4.698662,1.216718,-90.518738,0.122730,0.000000
102.720001,21.159691,-90.652176,0.014275,0.004817,0.122348,94.123009,4.794854,1.223482,-90.652176,0.123241,0.000000
103.030006,21.037178,-90.563217,0.014275,0.004836,0.122825,93.578041,4.767093,1.228252,-90.563217,0.123762,0.000000
103.340004,21.389816,-90.652176,0.014340,0.004860,0.123450,95.146652,4.847002,1.234496,-90.652176,0.124273,0.000000
103.650002,21.250923,-90.652176,0.014349,0.004876,0.123857,94.528824,4.815528,1.238572,-90.652176,0.124794,0.000000
103.960007,21.374550,-90.785622,0.014366,0.004895,0.124325,95.078743,4.843543,1.243255,-90.785622,0.125314,0.000000
104.270004,21.097878,-90.830101,0.014383,0.004906,0.124612,93.848045,4.780847,1.246117,-90.830101,0.125826,0.000000
104.580002,21.780067,-90.830101,0.014405,0.004936,0.125366,96.882576,4.935434,1.253662,-90.830101,0.126346,0.000000
104.890007,21.506371,-90.963547,0.014426,0.004949,0.125696,95.665115,4.873413,1.256957,-90.963547,0.126858,0.000000
105.200005,22.641365,-90.874580,0.014448,0.004984,0.126606,100.713821,5.130607,1.266063,-90.874580,0.127378,0.000000
105.510002,22.042587,-90.919067,0.014465,0.004998,0.126962,98.050323,4.994922,1.269618,-90.919067,0.127890,0.000000
105.820007,22.105148,-90.963547,0.014469,0.005017,0.127439,98.328613,5.009098,1.274388,-90.963547,0.128410,0.000000
106.130005,22.249626,-91.008026,0.014517,0.005037,0.127933,98.971283,5.041838,1.279331,-91.008026,0.128930,0.000000
106.440002,22.533371,-91.141472,0.014491,0.005056,0.128427,100.233437,5.106135,1.284275,-91.141472,0.129442,0.000000
106.750008,22.559814,-91.052505,0.014526,0.005075,0.128913,100.351067,5.112127,1.289131,-91.052505,0.129962,0.000000
107.060005,22.457039,-91.141472,0.014556,0.005087,0.129199,99.893898,5.088838,1.291993,-91.141472,0.130474,0.000000
107.370003,23.305672,-91.274910,0.014586,0.005126,0.130188,103.668808,5.281140,1.301879,-91.274910,0.130994,0.000000
107.680008,23.011871,-91.185951,0.014603,0.005141,0.130570,102.361916,5.214564,1.305695,-91.185951,0.131515,0.000000
107.990005,23.055443,-91.274910,0.014616,0.005156,0.130951,102.555733,5.224438,1.309511,-91.274910,0.132026,0.000000
108.300003,23.666130,-91.274910,0.014638,0.005182,0.131619,105.272202,5.362822,1.316188,-91.274910,0.132547,0.000000
108.610008,23.619957,-91.319389,0.014676,0.005200,0.132087,105.066818,5.352359,1.320871,-91.319389,0.133058,0.000000
108.920006,23.836678,-91.363876,0.014689,0.005221,0.132607,106.030838,5.401468,1.326075,-91.363876,0.133579,0.000000
109.230003,24.121170,-91.363876,0.014694,0.005241,0.133128,107.296326,5.465935,1.331278,-91.363876,0.134090,0.000000
109.540009,24.003128,-91.497314,0.014724,0.005259,0.133570,106.771248,5.439187,1.335701,-91.497314,0.134611,0.000000
109.850006,24.216499,-91.408356,0.014750,0.005279,0.134099,107.720367,5.487537,1.340991,-91.408356,0.135131,0.000000
110.160004,24.661484,-91.497314,0.014754,0.005303,0.134697,109.699760,5.588372,1.346975,-91.497314,0.135643,0.000000
110.470009,24.871132,-91.541794,0.014776,0.005325,0.135253,110.632317,5.635879,1.352525,-91.541794,0.136163,0.000000
110.780006,24.550140,-91.586281,0.014806,0.005338,0.135573,109.204475,5.563141,1.355734,-91.586281,0.136675,0.000000
111.090004,25.246109,-91.675240,0.014806,0.005364,0.136250,112.300301,5.720850,1.362498,-91.675240,0.137195,0.000000
111.400002,25.336220,-91.630760,0.014836,0.005386,0.136796,112.701134,5.741269,1.367962,-91.630760,0.137715,0.000000
111.710007,25.314995,-91.764198,0.014849,0.005401,0.137186,112.606720,5.736460,1.371864,-91.764198,0.138227,0.000000
112.020004,25.448677,-91.719719,0.014862,0.005421,0.137681,113.201370,5.766752,1.376808,-91.719719,0.138747,0.000000
112.330002,25.990479,-91.808685,0.014909,0.005444,0.138288,115.611420,5.889527,1.382878,-91.808685,0.139259,0.000000
112.640007,25.784561,-91.853165,0.014918,0.005458,0.138643,114.695457,5.842865,1.386434,-91.853165,0.139779,0.000000
112.950005,26.631706,-91.808685,0.014939,0.005489,0.139433,118.463745,6.034831,1.394325,-91.808685,0.140291,0.000000
113.260002,26.557228,-91.897644,0.014948,0.005509,0.139927,118.132454,6.017954,1.399269,-91.897644,0.140811,0.000000
113.570007,26.503609,-91.897644,0.014987,0.005527,0.140395,117.893936,6.005804,1.403952,-91.897644,0.141332,0.000000
113.880005,26.673409,-91.986610,0.014987,0.005546,0.140881,118.649246,6.044281,1.408808,-91.986610,0.141843,0.000000
114.190002,27.071480,-92.031090,0.015021,0.005567,0.141410,120.419960,6.134485,1.414098,-92.031090,0.142364,0.000000
114.500008,27.074081,-92.031090,0.015034,0.005585,0.141852,120.431526,6.135075,1.418521,-92.031090,0.142875,0.000000
114.810005,27.509384,-92.075569,0.015034,0.005604,0.142338,122.367851,6.233716,1.423378,-92.075569,0.143396,0.000000
115.120003,27.947296,-92.075569,0.015069,0.005629,0.142971,124.315781,6.332948,1.429708,-92.075569,0.143907,0.000000
115.430008,27.845268,-92.164528,0.015082,0.005647,0.143422,123.861938,6.309828,1.434218,-92.164528,0.144428,0.000000
115.740005,28.220619,-92.209015,0.015103,0.005666,0.143925,125.531586,6.394884,1.439248,-92.209015,0.144948,0.000000
116.050003,28.507347,-92.209015,0.015125,0.005689,0.144497,126.807014,6.459857,1.444972,-92.209015,0.145460,0.000000
116.360008,28.437340,-92.342453,0.015138,0.005707,0.144948,126.495605,6.443994,1.449481,-92.342453,0.145980,0.000000
116.670006,28.648476,-92.253494,0.015155,0.005723,0.145364,127.434784,6.491838,1.453644,-92.253494,0.146492,0.000000
116.980003,29.784584,-92.386932,0.015202,0.005754,0.146162,132.488449,6.749283,1.461622,-92.386932,0.147012,0.000000
117.290009,29.336250,-92.342453,0.015198,0.005768,0.146500,130.494156,6.647689,1.465004,-92.342453,0.147532,0.000000
117.600006,29.743622,-92.342453,0.015224,0.005789,0.147038,132.306244,6.740001,1.470381,-92.342453,0.148044,0.000000
117.910004,30.197548,-92.475899,0.015246,0.005813,0.147663,134.325409,6.842862,1.476625,-92.475899,0.148564,0.000000
118.220009,30.323776,-92.475899,0.015250,0.005832,0.148139,134.886887,6.871466,1.481395,-92.475899,0.149076,0.000000
118.530006,30.350960,-92.609337,0.015271,0.005848,0.148547,135.007812,6.877625,1.485471,-92.609337,0.149596,0.000000
118.840004,31.089005,-92.564857,0.015306,0.005875,0.149232,138.290802,7.044869,1.492322,-92.564857,0.150108,0.000000
119.150009,30.938568,-92.609337,0.015319,0.005891,0.149631,137.621628,7.010780,1.496311,-92.609337,0.150628,0.000000
119.460007,31.277794,-92.698303,0.015327,0.005911,0.150143,139.130569,7.087649,1.501428,-92.698303,0.151149,0.000000
119.770004,31.801727,-92.742783,0.015362,0.005934,0.150733,141.461151,7.206374,1.507325,-92.742783,0.151660,0.000000
120.080009,31.994240,-92.787262,0.015383,0.005954,0.151244,142.317490,7.249999,1.512442,-92.787262,0.152181,0.000000
120.390007,32.174095,-92.831741,0.015388,0.005972,0.151686,143.117523,7.290754,1.516865,-92.831741,0.152692,0.000000
120.700005,32.305916,-92.831741,0.015388,0.005987,0.152077,143.703888,7.320625,1.520767,-92.831741,0.153213,0.000000
121.010002,33.155670,-92.920708,0.015431,0.006017,0.152823,147.483780,7.513182,1.528225,-92.920708,0.153733,0.000000
121.320007,33.169075,-92.831741,0.015461,0.006033,0.153230,147.543411,7.516220,1.532301,-92.831741,0.154245,0.000000
121.630005,33.453941,-92.965187,0.015457,0.006050,0.153681,148.810562,7.580771,1.536811,-92.965187,0.154765,0.000000
121.940002,33.891106,-92.965187,0.015478,0.006065,0.154054,150.755173,7.679834,1.540540,-92.965187,0.154193,0.000000
122.250008,32.678665,-93.054146,0.015496,0.006061,0.153959,145.361969,7.405091,1.539586,-93.054146,0.154193,0.000000
122.560005,32.202026,-93.098633,0.015491,0.006059,0.153907,143.241760,7.297083,1.539065,-93.098633,0.153724,0.000000
122.870003,31.762627,-93.054146,0.015500,0.006045,0.153551,141.287216,7.197515,1.535510,-93.054146,0.153204,0.000000
123.180008,31.413338,-93.143112,0.015513,0.006029,0.153143,139.733505,7.118364,1.531434,-93.143112,0.152692,0.000000
123.490005,31.134430,-93.143112,0.015513,0.006008,0.152597,138.492859,7.055162,1.525970,-93.143112,0.152172,0.000000
123.800003,30.919571,-93.232071,0.015504,0.005987,0.152077,137.537125,7.006475,1.520767,-93.232071,0.151660,0.000000
124.110008,30.642532,-93.187592,0.015513,0.005961,0.151418,136.304794,6.943697,1.514176,-93.187592,0.151140,0.000000
124.420006,30.549812,-93.321037,0.015521,0.005946,0.151019,135.892349,6.922687,1.510187,-93.321037,0.150620,0.000000
124.730003,30.362503,-93.321037,0.015496,0.005929,0.150602,135.059158,6.880241,1.506024,-93.321037,0.150108,0.000000
125.040009,30.258240,-93.365517,0.015530,0.005917,0.150299,134.595367,6.856615,1.502989,-93.365517,0.149588,0.000000
125.350006,30.142433,-93.454475,0.015509,0.005893,0.149692,134.080246,6.830373,1.496918,-93.454475,0.149076,0.000000
125.660004,29.957733,-93.498962,0.015521,0.005869,0.149076,133.258652,6.788519,1.490761,-93.498962,0.148556,0.000000
125.970009,29.799103,-93.498962,0.015526,0.005844,0.148443,132.553024,6.752573,1.484430,-93.498962,0.148035,0.000000
126.280006,29.673988,-93.498962,0.015500,0.005828,0.148035,131.996490,6.724222,1.480354,-93.498962,0.147524,0.000000
126.590004,29.493019,-93.543442,0.015530,0.005813,0.147645,131.191498,6.683214,1.476452,-93.543442,0.147003,0.000000
126.900009,29.050636,-93.632401,0.015526,0.005795,0.147194,129.223679,6.582968,1.471942,-93.632401,0.146492,0.000000
127.210007,28.311478,-93.632401,0.015526,0.005774,0.146665,125.935745,6.415473,1.466652,-93.632401,0.145971,0.000000
127.520004,27.600243,-93.721367,0.015526,0.005757,0.146223,122.772011,6.254304,1.462229,-93.721367,0.145460,0.000000
127.830009,26.635803,-93.676880,0.015521,0.005737,0.145720,118.481972,6.035759,1.457199,-93.676880,0.144939,0.000000
128.139999,25.268822,-93.765846,0.015530,0.005713,0.145113,112.401329,5.725996,1.451129,-93.765846,0.144419,0.000000
128.450012,24.314056,-93.854805,0.015543,0.005698,0.144731,108.154327,5.509644,1.447313,-93.854805,0.143907,0.000000
128.760010,23.488884,-93.765846,0.015547,0.005684,0.144384,104.483772,5.322657,1.443844,-93.765846,0.143387,0.000000
129.070007,22.034767,-93.854805,0.015547,0.005663,0.143829,98.015541,4.993150,1.438294,-93.854805,0.142875,0.000000
129.380005,20.371750,-93.899284,0.015534,0.005639,0.143240,90.618073,4.616305,1.432397,-93.899284,0.142355,0.000000
129.690002,19.339905,-93.899284,0.015517,0.005622,0.142806,86.028191,4.382485,1.428061,-93.899284,0.141843,0.000000
130.000000,17.854889,-94.032730,0.015530,0.005608,0.142433,79.422516,4.045976,1.424332,-94.032730,0.141323,0.000000
130.310013,15.417709,-93.943771,0.015530,0.005576,0.141627,68.581398,3.493703,1.416266,-93.943771,0.140803,0.000000
130.620010,14.239525,-94.121689,0.015547,0.005563,0.141288,63.340569,3.226722,1.412884,-94.121689,0.140291,0.000000
130.930008,12.813705,-94.077209,0.015534,0.005543,0.140794,56.998207,2.903627,1.407941,-94.077209,0.139771,0.000000
131.240005,10.603676,-94.210655,0.015526,0.005516,0.140109,47.167507,2.402827,1.401090,-94.210655,0.139259,0.000000
131.550003,9.985909,-94.077209,0.015530,0.005511,0.139979,44.419540,2.262839,1.399789,-94.077209,0.138739,0.000000
131.860001,8.195915,-94.210655,0.015521,0.005485,0.139328,36.457253,1.857221,1.393285,-94.210655,0.138218,0.000000
132.170013,5.839920,-94.299614,0.015526,0.005454,0.138539,25.977262,1.323345,1.385393,-94.299614,0.137707,0.000000
132.480011,4.906754,-94.255135,0.015517,0.005441,0.138192,21.826330,1.111886,1.381924,-94.255135,0.137186,0.000000
132.790009,3.622063,-94.344101,0.015504,0.005422,0.137715,16.111740,0.820771,1.377154,-94.344101,0.136675,0.000000
133.100006,1.943787,-94.299614,0.015491,0.005393,0.136970,8.646395,0.440468,1.369696,-94.299614,0.136154,0.000000
133.410004,1.655937,-94.388580,0.015465,0.005385,0.136788,7.365976,0.375241,1.367875,-94.388580,0.135643,0.000000
133.720001,0.858315,-94.522018,0.015470,0.005361,0.136172,3.817974,0.194497,1.361718,-94.522018,0.135122,0.000000
134.029999,0.208900,-94.388580,0.015448,0.005334,0.135487,0.929236,0.047338,1.354867,-94.388580,0.134619,0.000000
134.100006,0.432693,-94.522018,0.015448,0.005339,0.135608,1.924717,0.098050,1.356081,-94.522018,0.135452,0.000000