File: Data/PDMS compression/PDMS 0017 Punched_3_re_07152024_153649.csv
Time (sec),S:Load (lbs),S:HL1 (DIM),S:LVDT (in),S:Position (in),Ch:Position (mm),Ch:Load (N),Ch:Stress (MPa),Ch:Strain (mm/mm),Ch:HL1 (DIM),Set Point (),Cycles ()
0.110000,-0.005219,-242.109818,0.000194,-0.001312,-0.033336,-0.023213,-0.001183,-0.333361,-242.109818,-0.033536,0.000000
0.750000,-0.001495,-242.154297,0.000203,-0.001230,-0.031246,-0.006652,-0.000339,-0.312461,-242.154297,-0.030448,0.000000
1.390000,0.029045,-242.198776,0.000220,-0.001032,-0.026225,0.129199,0.006582,-0.262249,-242.198776,-0.025124,0.000000
2.030000,0.018990,-242.243256,0.000444,-0.000821,-0.020857,0.084470,0.004303,-0.208568,-242.243256,-0.019790,0.000000
2.670000,0.046547,-242.198776,0.000681,-0.000608,-0.015437,0.207051,0.010548,-0.154366,-242.198776,-0.014457,0.000000
3.310000,0.041328,-242.287735,0.000905,-0.000401,-0.010181,0.183838,0.009365,-0.101812,-242.287735,-0.009123,0.000000
3.950000,0.382050,-242.332214,0.001134,-0.000188,-0.004778,1.699441,0.086574,-0.047784,-242.332214,-0.003798,0.000000
4.590000,0.414818,-242.421188,0.001168,-0.000003,-0.000069,1.845202,0.093999,-0.000694,-242.421188,0.000139,0.000000
5.230000,0.407372,-242.510147,0.001177,-0.000002,-0.000061,1.812079,0.092312,-0.000607,-242.510147,0.001110,0.000000
5.870000,0.547386,-242.510147,0.001212,0.000051,0.001283,2.434895,0.124039,0.012835,-242.510147,0.002177,0.000000
6.510000,0.589088,-242.554626,0.001242,0.000085,0.002168,2.620396,0.133489,0.021681,-242.554626,0.003243,0.000000
7.150001,0.660217,-242.599106,0.001276,0.000134,0.003408,2.936793,0.149607,0.034082,-242.599106,0.004310,0.000000
7.790000,0.726494,-242.599106,0.001324,0.000171,0.004345,3.231606,0.164626,0.043448,-242.599106,0.005377,0.000000
8.430000,0.852356,-242.732544,0.001362,0.000209,0.005307,3.791469,0.193147,0.053074,-242.732544,0.006443,0.000000
9.070001,0.932793,-242.688065,0.001427,0.000262,0.006660,4.149269,0.211374,0.066603,-242.688065,0.007510,0.000000
9.710000,0.991257,-242.777023,0.001475,0.000299,0.007588,4.409330,0.224622,0.075882,-242.777023,0.008577,0.000000
10.350000,1.079132,-242.777023,0.001505,0.000334,0.008473,4.800219,0.244535,0.084728,-242.777023,0.009644,0.000000
10.990001,1.196800,-242.865997,0.001561,0.000384,0.009748,5.323633,0.271199,0.097476,-242.865997,0.010710,0.000000
11.630000,1.289520,-242.910477,0.001600,0.000428,0.010875,5.736073,0.292209,0.108750,-242.910477,0.011777,0.000000
12.270000,1.355804,-242.910477,0.001625,0.000462,0.011725,6.030920,0.307230,0.117249,-242.910477,0.012844,0.000000
12.910001,1.451508,-242.999435,0.001669,0.000512,0.013000,6.456628,0.328916,0.129997,-242.999435,0.013910,0.000000
13.550000,1.565826,-242.999435,0.001729,0.000558,0.014179,6.965144,0.354821,0.141791,-242.999435,0.014977,0.000000
14.190001,1.663010,-243.043915,0.001755,0.000595,0.015124,7.397436,0.376843,0.151244,-243.043915,0.016044,0.000000
14.830001,1.732643,-243.132874,0.001824,0.000636,0.016156,7.707181,0.392623,0.161564,-243.132874,0.017110,0.000000
15.470000,1.856277,-243.132874,0.001850,0.000678,0.017223,8.257134,0.420639,0.172231,-243.132874,0.018177,0.000000
16.110001,1.953461,-243.266327,0.001897,0.000720,0.018281,8.689427,0.442661,0.182811,-243.266327,0.019244,0.000000
16.750000,2.063683,-243.221848,0.001936,0.000766,0.019461,9.179718,0.467637,0.194605,-243.221848,0.020310,0.000000
17.390001,2.142998,-243.266327,0.001970,0.000804,0.020414,9.532530,0.485610,0.204145,-243.266327,0.021377,0.000000
18.030001,2.245407,-243.355286,0.002022,0.000843,0.021403,9.988070,0.508817,0.214031,-243.355286,0.022444,0.000000
18.670000,2.340355,-243.355286,0.002065,0.000891,0.022635,10.410419,0.530332,0.226346,-243.355286,0.023510,0.000000
19.310001,2.356743,-243.488724,0.002100,0.000922,0.023415,10.483315,0.534046,0.234151,-243.488724,0.024577,0.000000
19.950001,2.558571,-243.488724,0.002169,0.000974,0.024733,11.381092,0.579780,0.247333,-243.488724,0.025644,0.000000
20.590000,2.627831,-243.577682,0.002190,0.001017,0.025843,11.689174,0.595475,0.258433,-243.577682,0.026711,0.000000
21.230001,2.650543,-243.577682,0.002255,0.001047,0.026598,11.790205,0.600622,0.265978,-243.577682,0.027777,0.000000
21.870001,2.833008,-243.622162,0.002264,0.001092,0.027743,12.601849,0.641969,0.277425,-243.622162,0.028844,0.000000
22.510000,2.967804,-243.711136,0.002320,0.001144,0.029069,13.201451,0.672514,0.290694,-243.711136,0.029911,0.000000
23.150002,3.045631,-243.711136,0.002354,0.001181,0.029997,13.547646,0.690150,0.299973,-243.711136,0.030977,0.000000
23.790001,3.258629,-243.755615,0.002410,0.001225,0.031116,14.495105,0.738416,0.311160,-243.755615,0.032044,0.000000
24.430000,3.311508,-243.755615,0.002458,0.001272,0.032304,14.730324,0.750398,0.323041,-243.755615,0.033111,0.000000
25.070002,3.344276,-243.844574,0.002501,0.001304,0.033119,14.876084,0.757824,0.331193,-243.844574,0.034177,0.000000
25.710001,3.553551,-243.933533,0.002522,0.001351,0.034316,15.806983,0.805246,0.343161,-243.933533,0.035244,0.000000
26.350000,3.616478,-243.889053,0.002587,0.001392,0.035365,16.086897,0.819506,0.353655,-243.889053,0.036311,0.000000
26.990002,3.711807,-244.066986,0.002604,0.001429,0.036302,16.510942,0.841108,0.363021,-244.066986,0.037377,0.000000
27.630001,3.829475,-244.066986,0.002669,0.001475,0.037464,17.034357,0.867772,0.374641,-244.066986,0.038444,0.000000
28.270000,3.946770,-244.111465,0.002721,0.001519,0.038592,17.556108,0.894351,0.385915,-244.111465,0.039511,0.000000
28.910002,4.055878,-244.244904,0.002742,0.001562,0.039676,18.041445,0.919075,0.396756,-244.244904,0.040577,0.000000
29.550001,4.090134,-244.155945,0.002772,0.001597,0.040551,18.193823,0.926838,0.405515,-244.155945,0.041644,0.000000
30.190001,4.303131,-244.289383,0.002833,0.001647,0.041844,19.141283,0.975103,0.418436,-244.289383,0.042711,0.000000
30.830002,4.315796,-244.289383,0.002880,0.001688,0.042867,19.197618,0.977973,0.428670,-244.289383,0.043778,0.000000
31.470001,4.407394,-244.333862,0.002915,0.001724,0.043795,19.605070,0.998730,0.437949,-244.333862,0.044844,0.000000
32.110001,4.590233,-244.378342,0.002966,0.001772,0.045000,20.418375,1.040162,0.450003,-244.378342,0.045911,0.000000
32.750000,4.547409,-244.378342,0.002988,0.001809,0.045937,20.227886,1.030458,0.459369,-244.378342,0.046978,0.000000
33.390003,4.650932,-244.511795,0.003031,0.001850,0.046995,20.688379,1.053916,0.469950,-244.511795,0.048044,0.000000
34.030003,4.847542,-244.556274,0.003122,0.001900,0.048270,21.562943,1.098469,0.482698,-244.556274,0.049111,0.000000
34.670002,4.900047,-244.556274,0.003122,0.001939,0.049250,21.796499,1.110367,0.492497,-244.556274,0.050178,0.000000
35.310001,4.945473,-244.645233,0.003173,0.001982,0.050334,21.998562,1.120660,0.503338,-244.645233,0.051244,0.000000
35.950001,5.062401,-244.689713,0.003212,0.002027,0.051487,22.518684,1.147156,0.514872,-244.689713,0.052311,0.000000
36.590000,5.051605,-244.689713,0.003247,0.002061,0.052337,22.470663,1.144710,0.523371,-244.689713,0.053378,0.000000
37.230003,5.208374,-244.778671,0.003316,0.002105,0.053456,23.168005,1.180234,0.534558,-244.778671,0.054444,0.000000
37.870003,5.348381,-244.778671,0.003350,0.002152,0.054661,23.790787,1.211960,0.546612,-244.778671,0.055511,0.000000
38.510002,5.337212,-244.867630,0.003419,0.002189,0.055598,23.741102,1.209430,0.555978,-244.867630,0.056578,0.000000
39.150002,5.388969,-244.823151,0.003445,0.002228,0.056595,23.971333,1.221158,0.565951,-244.823151,0.057644,0.000000
39.790001,5.556168,-245.001083,0.003466,0.002280,0.057913,24.715067,1.259046,0.579133,-245.001083,0.058720,0.000000
40.430000,5.523026,-245.001083,0.003510,0.002314,0.058781,24.567644,1.251535,0.587806,-245.001083,0.059787,0.000000
41.070004,5.720009,-245.045563,0.003553,0.002363,0.060029,25.443871,1.296173,0.600294,-245.045563,0.060853,0.000000
41.710003,5.754272,-245.179001,0.003613,0.002406,0.061122,25.596283,1.303937,0.611221,-245.179001,0.061920,0.000000
42.350002,5.707352,-245.179001,0.003656,0.002439,0.061946,25.387568,1.293304,0.619459,-245.179001,0.062987,0.000000
42.990002,5.923698,-245.223480,0.003682,0.002484,0.063099,26.349926,1.342329,0.630993,-245.223480,0.064053,0.000000
43.630001,6.002640,-245.179001,0.003738,0.002533,0.064348,26.701075,1.360218,0.643481,-245.179001,0.065120,0.000000
44.270000,6.009720,-245.223480,0.003781,0.002569,0.065250,26.732569,1.361822,0.652501,-245.223480,0.066187,0.000000
44.910004,6.056267,-245.356934,0.003837,0.002608,0.066247,26.939621,1.372370,0.662474,-245.356934,0.067253,0.000000
45.550003,6.215263,-245.312439,0.003898,0.002658,0.067514,27.646872,1.408399,0.675135,-245.312439,0.068320,0.000000
46.190002,6.180634,-245.445892,0.003911,0.002691,0.068355,27.492830,1.400552,0.683547,-245.445892,0.069387,0.000000
46.830002,6.261070,-245.401413,0.003971,0.002735,0.069465,27.850632,1.418779,0.694648,-245.401413,0.070453,0.000000
47.470001,6.385811,-245.534851,0.004005,0.002780,0.070610,28.405506,1.447045,0.706095,-245.534851,0.071520,0.000000
48.110001,6.390282,-245.579330,0.004036,0.002815,0.071494,28.425392,1.448059,0.714941,-245.579330,0.072587,0.000000
48.750004,6.526939,-245.623810,0.004096,0.002863,0.072717,29.033276,1.479026,0.727169,-245.623810,0.073653,0.000000
49.390003,6.541840,-245.712769,0.004118,0.002900,0.073653,29.099556,1.482402,0.736535,-245.712769,0.074720,0.000000
50.030003,6.558594,-245.668289,0.004182,0.002944,0.074790,29.174082,1.486199,0.747895,-245.668289,0.075787,0.000000
50.670002,6.692650,-245.668289,0.004217,0.002987,0.075874,29.770393,1.516576,0.758736,-245.668289,0.076854,0.000000
51.310001,6.815529,-245.890701,0.004255,0.003029,0.076949,30.316986,1.544421,0.769489,-245.890701,0.077920,0.000000
51.950001,6.831543,-245.846222,0.004316,0.003074,0.078085,30.388222,1.548050,0.780850,-245.846222,0.078987,0.000000
52.590004,6.923515,-245.890701,0.004363,0.003115,0.079108,30.797335,1.568891,0.791083,-245.890701,0.080054,0.000000
53.230003,7.012146,-245.890701,0.004393,0.003153,0.080080,31.191584,1.588975,0.800796,-245.890701,0.081120,0.000000
53.870003,6.980865,-245.935181,0.004432,0.003196,0.081190,31.052441,1.581887,0.811897,-245.935181,0.082187,0.000000
54.510002,7.066139,-246.068619,0.004493,0.003240,0.082300,31.431757,1.601210,0.822997,-246.068619,0.083254,0.000000
55.150002,7.231842,-246.068619,0.004523,0.003284,0.083401,32.168839,1.638759,0.834011,-246.068619,0.084320,0.000000
55.790001,7.204659,-246.113098,0.004583,0.003323,0.084416,32.047920,1.632599,0.844157,-246.113098,0.085387,0.000000
56.430004,7.341324,-246.113098,0.004618,0.003369,0.085578,32.655838,1.663568,0.855778,-246.113098,0.086454,0.000000
57.070004,7.436646,-246.157578,0.004669,0.003415,0.086749,33.079853,1.685168,0.867486,-246.157578,0.087520,0.000000
57.710003,7.378929,-246.291031,0.004678,0.003450,0.087642,32.823116,1.672089,0.876418,-246.291031,0.088587,0.000000
58.350002,7.386749,-246.291031,0.004725,0.003491,0.088665,32.857903,1.673861,0.886652,-246.291031,0.089654,0.000000
58.990002,7.526016,-246.335510,0.004769,0.003531,0.089680,33.477394,1.705420,0.896798,-246.335510,0.090720,0.000000
59.630001,7.482079,-246.379990,0.004820,0.003576,0.090833,33.281948,1.695463,0.908332,-246.379990,0.091787,0.000000
60.270004,7.589691,-246.468948,0.004850,0.003618,0.091900,33.760632,1.719849,0.918999,-246.468948,0.092854,0.000000
60.910004,7.806786,-246.557907,0.004902,0.003664,0.093053,34.726318,1.769043,0.930533,-246.557907,0.093921,0.000000
61.550003,7.648155,-246.468948,0.004945,0.003702,0.094025,34.020695,1.733097,0.940246,-246.468948,0.094987,0.000000
62.190002,7.792633,-246.646881,0.004980,0.003743,0.095083,34.663364,1.765836,0.950826,-246.646881,0.096054,0.000000
62.830002,7.862267,-246.557907,0.005057,0.003790,0.096271,34.973106,1.781615,0.962707,-246.557907,0.097121,0.000000
63.470001,7.756889,-246.646881,0.005070,0.003829,0.097259,34.504368,1.757736,0.972594,-246.646881,0.098187,0.000000
64.110001,8.002281,-246.691360,0.005118,0.003871,0.098326,35.595924,1.813343,0.983260,-246.691360,0.099254,0.000000
64.750000,7.927063,-246.735840,0.005187,0.003907,0.099245,35.261337,1.796298,0.992453,-246.735840,0.100321,0.000000
65.389999,7.972488,-246.913757,0.005213,0.003954,0.100442,35.463398,1.806592,1.004421,-246.913757,0.101387,0.000000
66.030006,8.135963,-246.824799,0.005238,0.003996,0.101491,36.190575,1.843636,1.014914,-246.824799,0.102454,0.000000
66.670006,8.236130,-246.869278,0.005307,0.004041,0.102653,36.636135,1.866334,1.026535,-246.869278,0.103521,0.000000
67.310005,8.098724,-246.958237,0.005359,0.004078,0.103590,36.024925,1.835197,1.035901,-246.958237,0.104587,0.000000
67.950005,8.535889,-246.958237,0.005394,0.004128,0.104856,37.969528,1.934260,1.048563,-246.958237,0.105654,0.000000
68.590004,8.415245,-247.091690,0.005458,0.004167,0.105845,37.432880,1.906922,1.058449,-247.091690,0.106721,0.000000
69.230003,8.315445,-247.047195,0.005493,0.004200,0.106686,36.988945,1.884307,1.066861,-247.047195,0.107787,0.000000
69.870003,8.615204,-247.136169,0.005527,0.004250,0.107944,38.322342,1.952233,1.079436,-247.136169,0.108854,0.000000
70.510002,8.427902,-247.225128,0.005579,0.004285,0.108828,37.489182,1.909790,1.088282,-247.225128,0.109921,0.000000
71.150002,8.534027,-247.269608,0.005614,0.004331,0.110008,37.961250,1.933838,1.100076,-247.269608,0.110988,0.000000
71.790001,8.731018,-247.269608,0.005657,0.004375,0.111135,38.837509,1.978477,1.111350,-247.269608,0.112054,0.000000
72.430000,8.699364,-247.269608,0.005683,0.004411,0.112046,38.696701,1.971304,1.120456,-247.269608,0.113121,0.000000
73.070000,8.707184,-247.358566,0.005743,0.004460,0.113277,38.731487,1.973076,1.132770,-247.358566,0.114188,0.000000
73.710007,8.691170,-247.447525,0.005786,0.004498,0.114248,38.660255,1.969447,1.142483,-247.447525,0.115254,0.000000
74.350006,8.830437,-247.403046,0.005833,0.004536,0.115211,39.279743,2.001006,1.152109,-247.403046,0.116321,0.000000
74.990005,8.797295,-247.536499,0.005864,0.004583,0.116399,39.132320,1.993495,1.163990,-247.536499,0.117388,0.000000
75.630005,8.951088,-247.580978,0.005915,0.004627,0.117535,39.816429,2.028346,1.175351,-247.580978,0.118454,0.000000
76.270004,8.799156,-247.536499,0.005971,0.004660,0.118368,39.140602,1.993917,1.183676,-247.536499,0.119521,0.000000
76.910004,8.906776,-247.669937,0.006028,0.004708,0.119582,39.619320,2.018304,1.195817,-247.669937,0.120588,0.000000
77.550003,9.076950,-247.669937,0.006053,0.004754,0.120753,40.376289,2.056866,1.207525,-247.669937,0.121654,0.000000
78.190002,9.067642,-247.758896,0.006084,0.004792,0.121715,40.334888,2.054757,1.217151,-247.758896,0.122721,0.000000
78.830002,9.035988,-247.758896,0.006148,0.004835,0.122817,40.194080,2.047584,1.228165,-247.758896,0.123788,0.000000
79.470001,9.196106,-247.892334,0.006187,0.004880,0.123944,40.906322,2.083868,1.239439,-247.892334,0.124854,0.000000
80.110001,9.244141,-247.892334,0.006222,0.004917,0.124898,41.119991,2.094752,1.248978,-247.892334,0.125921,0.000000
80.750008,9.262390,-247.981308,0.006243,0.004964,0.126095,41.201168,2.098888,1.260946,-247.981308,0.126988,0.000000
81.390007,9.268723,-248.025787,0.006316,0.005004,0.127109,41.229336,2.100322,1.271093,-248.025787,0.128055,0.000000
82.030006,9.295906,-247.981308,0.006347,0.005042,0.128055,41.350254,2.106483,1.280545,-247.981308,0.129121,0.000000
82.670006,9.388252,-248.114746,0.006403,0.005092,0.129347,41.761032,2.127409,1.293467,-248.114746,0.130188,0.000000
83.310005,9.417297,-248.114746,0.006433,0.005128,0.130257,41.890232,2.133990,1.302573,-248.114746,0.131255,0.000000
83.950005,9.538689,-248.114746,0.006493,0.005176,0.131463,42.430206,2.161498,1.314627,-248.114746,0.132321,0.000000
84.590004,9.415436,-248.248184,0.006528,0.005215,0.132451,41.881950,2.133568,1.324514,-248.248184,0.133388,0.000000
85.230003,9.722641,-248.203705,0.006579,0.005258,0.133553,43.248466,2.203182,1.335528,-248.203705,0.134455,0.000000
85.870003,9.543533,-248.337143,0.006622,0.005292,0.134420,42.451756,2.162596,1.344200,-248.337143,0.135521,0.000000
86.510002,9.623962,-248.337143,0.006687,0.005342,0.135677,42.809525,2.180821,1.356775,-248.337143,0.136588,0.000000
87.150002,9.702538,-248.381638,0.006709,0.005381,0.136683,43.159042,2.198627,1.366834,-248.381638,0.137655,0.000000
87.790001,9.827652,-248.470596,0.006739,0.005422,0.137724,43.715580,2.226978,1.377241,-248.470596,0.138721,0.000000
88.430008,9.780731,-248.470596,0.006817,0.005469,0.138904,43.506866,2.216345,1.389035,-248.470596,0.139788,0.000000
89.070007,9.642586,-248.559555,0.006851,0.005499,0.139667,42.892365,2.185041,1.396667,-248.559555,0.140855,0.000000
89.710007,9.917763,-248.559555,0.006911,0.005550,0.140968,44.116413,2.247397,1.409675,-248.559555,0.141921,0.000000
90.350006,9.881645,-248.604034,0.006924,0.005588,0.141947,43.955753,2.239213,1.419475,-248.604034,0.142988,0.000000
90.990005,9.950531,-248.692993,0.006980,0.005626,0.142910,44.262173,2.254823,1.429101,-248.692993,0.144055,0.000000
91.630005,10.033943,-248.781952,0.007006,0.005672,0.144064,44.633209,2.273724,1.440635,-248.781952,0.145122,0.000000
92.270004,10.198532,-248.781952,0.007045,0.005718,0.145243,45.365337,2.311021,1.452430,-248.781952,0.146188,0.000000
92.910004,10.076027,-248.781952,0.007114,0.005755,0.146180,44.820408,2.283260,1.461795,-248.781952,0.147255,0.000000
93.550003,10.076767,-248.870926,0.007161,0.005793,0.147142,44.823700,2.283428,1.471422,-248.870926,0.148322,0.000000
94.190002,10.326630,-248.915405,0.007192,0.005847,0.148512,45.935143,2.340048,1.485124,-248.915405,0.149388,0.000000
94.830002,10.373924,-249.004364,0.007243,0.005889,0.149570,46.145519,2.350765,1.495704,-249.004364,0.150455,0.000000
95.470001,10.182526,-249.004364,0.007261,0.005921,0.150403,45.294136,2.307393,1.504030,-249.004364,0.151522,0.000000
96.110008,10.473343,-249.004364,0.007338,0.005971,0.151669,46.587757,2.373293,1.516691,-249.004364,0.152588,0.000000
96.750008,10.397751,-249.137802,0.007355,0.006012,0.152692,46.251507,2.356164,1.526924,-249.137802,0.153655,0.000000
97.390007,10.336685,-249.137802,0.007424,0.006048,0.153629,45.979874,2.342326,1.536290,-249.137802,0.154722,0.000000
98.030006,10.576492,-249.182281,0.007450,0.006099,0.154921,47.046589,2.396667,1.549212,-249.182281,0.155788,0.000000
98.670006,10.523247,-249.315735,0.007506,0.006135,0.155840,46.809738,2.384602,1.558404,-249.315735,0.156855,0.000000
99.310005,10.519890,-249.315735,0.007554,0.006179,0.156959,46.794807,2.383841,1.569592,-249.315735,0.157922,0.000000
99.950005,10.664375,-249.404694,0.007597,0.006224,0.158095,47.437511,2.416582,1.580952,-249.404694,0.158988,0.000000
100.590004,10.647614,-249.404694,0.007631,0.006259,0.158988,47.362949,2.412784,1.589885,-249.404694,0.160055,0.000000
101.230003,10.673309,-249.449173,0.007675,0.006301,0.160046,47.477253,2.418607,1.600465,-249.449173,0.161122,0.000000
101.870003,10.921684,-249.493652,0.007735,0.006352,0.161330,48.582077,2.474889,1.613300,-249.493652,0.162189,0.000000
102.510002,10.765282,-249.493652,0.007756,0.006389,0.162293,47.886364,2.439448,1.622926,-249.493652,0.163255,0.000000
103.150002,10.742569,-249.671585,0.007804,0.006425,0.163203,47.785332,2.434301,1.632032,-249.671585,0.164322,0.000000
103.790009,11.056107,-249.582611,0.007869,0.006480,0.164582,49.180019,2.505350,1.645821,-249.582611,0.165389,0.000000
104.430008,10.912369,-249.671585,0.007894,0.006513,0.165432,48.540642,2.472778,1.654320,-249.671585,0.166455,0.000000
105.070007,11.130959,-249.671585,0.007959,0.006557,0.166559,49.512978,2.522311,1.665594,-249.671585,0.167522,0.000000
105.710007,11.206917,-249.760544,0.007985,0.006607,0.167817,49.850857,2.539524,1.678168,-249.760544,0.168589,0.000000
106.350006,11.151436,-249.849503,0.008032,0.006641,0.168675,49.604065,2.526951,1.686754,-249.849503,0.169655,0.000000
106.990005,11.158508,-249.893982,0.008084,0.006680,0.169664,49.635525,2.528554,1.696640,-249.893982,0.170722,0.000000
107.630005,11.351028,-249.938461,0.008123,0.006729,0.170922,50.491898,2.572180,1.709215,-249.938461,0.171789,0.000000
108.270004,11.298523,-249.893982,0.008157,0.006767,0.171875,50.258339,2.560282,1.718755,-249.893982,0.172855,0.000000
108.910004,11.335762,-250.027420,0.008201,0.006807,0.172890,50.423988,2.568721,1.728901,-250.027420,0.173922,0.000000
109.550003,11.512634,-250.027420,0.008231,0.006857,0.174174,51.210754,2.608800,1.741736,-250.027420,0.174989,0.000000
110.190002,11.444862,-250.071899,0.008282,0.006891,0.175032,50.909290,2.593443,1.750322,-250.071899,0.176055,0.000000
110.830002,11.504074,-250.160873,0.008326,0.006935,0.176142,51.172676,2.606860,1.761422,-250.160873,0.177122,0.000000
111.470009,11.635521,-250.160873,0.008395,0.006979,0.177261,51.757381,2.636647,1.772609,-250.160873,0.178189,0.000000
112.110008,11.598656,-250.205353,0.008386,0.007013,0.178119,51.593399,2.628293,1.781195,-250.205353,0.179256,0.000000
112.750008,11.723770,-250.294312,0.008455,0.007059,0.179290,52.149933,2.656644,1.792902,-250.294312,0.180322,0.000000
113.390007,11.858200,-250.294312,0.008498,0.007098,0.180296,52.747910,2.687107,1.802962,-250.294312,0.181389,0.000000
114.030006,11.774788,-250.383270,0.008550,0.007142,0.181415,52.376873,2.668205,1.814149,-250.383270,0.182456,0.000000
114.670006,11.859688,-250.383270,0.008601,0.007184,0.182473,52.754524,2.687444,1.824730,-250.383270,0.183522,0.000000
115.310005,12.255524,-250.427750,0.008645,0.007232,0.183704,54.515293,2.777141,1.837044,-250.427750,0.184589,0.000000
115.950005,11.990395,-250.516724,0.008679,0.007273,0.184728,53.335937,2.717062,1.847277,-250.516724,0.185656,0.000000
116.590004,12.051834,-250.561203,0.008722,0.007313,0.185742,53.609234,2.730985,1.857424,-250.561203,0.186722,0.000000
117.230003,12.149765,-250.605682,0.008761,0.007353,0.186757,54.044853,2.753176,1.867571,-250.605682,0.187789,0.000000
117.870003,12.190727,-250.694641,0.008817,0.007395,0.187832,54.227062,2.762458,1.878324,-250.694641,0.188856,0.000000
118.510002,12.242859,-250.650162,0.008843,0.007439,0.188960,54.458958,2.774271,1.889598,-250.650162,0.189922,0.000000
119.150009,12.748543,-250.739120,0.008899,0.007486,0.190157,56.708351,2.888861,1.901566,-250.739120,0.190989,0.000000
119.790009,12.441704,-250.694641,0.008942,0.007523,0.191093,55.343464,2.819330,1.910932,-250.694641,0.192056,0.000000
120.430008,12.438354,-250.917038,0.008994,0.007568,0.192221,55.328564,2.818571,1.922206,-250.917038,0.193122,0.000000
121.070007,12.653214,-250.828079,0.009024,0.007613,0.193374,56.284306,2.867259,1.933740,-250.828079,0.194189,0.000000
121.710007,12.541130,-250.961533,0.009071,0.007648,0.194250,55.785732,2.841861,1.942499,-250.961533,0.195256,0.000000
122.350006,12.517670,-250.961533,0.009127,0.007688,0.195282,55.681377,2.836545,1.952819,-250.961533,0.196323,0.000000
122.990005,12.699013,-250.961533,0.009158,0.007732,0.196383,56.488029,2.877637,1.963832,-250.961533,0.197389,0.000000
123.630005,12.683746,-251.094971,0.009214,0.007775,0.197493,56.420120,2.874178,1.974933,-251.094971,0.198456,0.000000
124.270004,12.772369,-251.050491,0.009253,0.007815,0.198508,56.814335,2.894260,1.985080,-251.050491,0.199523,0.000000
124.910004,13.254593,-251.228409,0.009283,0.007866,0.199800,58.959373,3.003534,1.998001,-251.228409,0.200589,0.000000
125.550003,12.830833,-251.228409,0.009352,0.007901,0.200676,57.074398,2.907509,2.006760,-251.228409,0.201656,0.000000
126.190002,13.066177,-251.228409,0.009352,0.007945,0.201795,58.121262,2.960838,2.017947,-251.228409,0.202723,0.000000
126.830009,13.288483,-251.272888,0.009442,0.007993,0.203026,59.110123,3.011213,2.030262,-251.272888,0.203789,0.000000
127.470009,13.113091,-251.272888,0.009472,0.008028,0.203911,58.329941,2.971469,2.039108,-251.272888,0.204856,0.000000
128.110001,13.269493,-251.361847,0.009511,0.008070,0.204977,59.025654,3.006910,2.049775,-251.361847,0.205923,0.000000
128.750000,13.250130,-251.450821,0.009546,0.008112,0.206053,58.939522,3.002522,2.060528,-251.450821,0.206989,0.000000
129.389999,13.276939,-251.450821,0.009593,0.008153,0.207093,59.058777,3.008597,2.070935,-251.450821,0.208056,0.000000
130.029999,13.345085,-251.495300,0.009632,0.008192,0.208073,59.361904,3.024040,2.080735,-251.495300,0.209123,0.000000
130.670013,13.676125,-251.495300,0.009671,0.008241,0.209331,60.834442,3.099054,2.093309,-251.495300,0.210189,0.000000
131.310013,13.346199,-251.673218,0.009705,0.008276,0.210215,59.366859,3.024292,2.102155,-251.673218,0.211256,0.000000
131.950012,13.934174,-251.628738,0.009783,0.008326,0.211490,61.982300,3.157529,2.114903,-251.628738,0.212323,0.000000
132.590012,13.747986,-251.762177,0.009800,0.008364,0.212436,61.154095,3.115338,2.124356,-251.762177,0.213390,0.000000
133.230011,13.655640,-251.673218,0.009856,0.008400,0.213355,60.743320,3.094412,2.133548,-251.673218,0.214456,0.000000
133.870010,14.192970,-251.717697,0.009873,0.008450,0.214621,63.133484,3.216173,2.146210,-251.717697,0.215523,0.000000
134.510010,13.943855,-251.895630,0.009934,0.008484,0.215506,62.025368,3.159723,2.155056,-251.895630,0.216590,0.000000
135.150009,13.889114,-251.806671,0.009994,0.008527,0.216598,61.781868,3.147318,2.165983,-251.806671,0.217656,0.000000
135.790009,14.223511,-251.940109,0.010029,0.008574,0.217778,63.269337,3.223094,2.177777,-251.940109,0.218723,0.000000
136.430008,14.310272,-251.940109,0.010080,0.008612,0.218740,63.655270,3.242754,2.187403,-251.940109,0.219790,0.000000
137.070007,14.198189,-251.940109,0.010111,0.008658,0.219920,63.156696,3.217355,2.199198,-251.940109,0.220856,0.000000
137.710007,14.399269,-252.073547,0.010171,0.008701,0.221004,64.051147,3.262921,2.210038,-252.073547,0.221923,0.000000
138.350006,14.369102,-252.029068,0.010188,0.008733,0.221810,63.916962,3.256085,2.218103,-252.029068,0.222990,0.000000
138.990005,14.432037,-252.118027,0.010236,0.008782,0.223050,64.196907,3.270347,2.230504,-252.118027,0.224056,0.000000
139.630005,14.716156,-252.162506,0.010300,0.008828,0.224230,65.460732,3.334729,2.242299,-252.162506,0.225123,0.000000
140.270004,14.535187,-252.206985,0.010317,0.008858,0.225002,64.655739,3.293720,2.250017,-252.206985,0.226190,0.000000
140.910004,14.589554,-252.295959,0.010369,0.008908,0.226251,64.897575,3.306040,2.262505,-252.295959,0.227256,0.000000
141.550003,14.877022,-252.340439,0.010425,0.008952,0.227369,66.176300,3.371181,2.273692,-252.340439,0.228323,0.000000
142.190002,14.970490,-252.384918,0.010464,0.008995,0.228471,66.592064,3.392361,2.284706,-252.384918,0.229390,0.000000
142.830002,14.838295,-252.429398,0.010507,0.009032,0.229416,66.004036,3.362406,2.294159,-252.429398,0.230457,0.000000
143.470001,15.239716,-252.518356,0.010546,0.009078,0.230587,67.789642,3.453369,2.305866,-252.518356,0.231523,0.000000
144.110001,15.158905,-252.473877,0.010593,0.009113,0.231471,67.430176,3.435057,2.314712,-252.473877,0.232590,0.000000
144.750000,15.295197,-252.518356,0.010628,0.009162,0.232720,68.036430,3.465941,2.327200,-252.518356,0.233657,0.000000
145.389999,15.458298,-252.607315,0.010680,0.009203,0.233761,68.761940,3.502900,2.337607,-252.607315,0.234723,0.000000
146.030014,15.384941,-252.607315,0.010718,0.009238,0.234645,68.435638,3.486277,2.346452,-252.607315,0.235790,0.000000
146.670013,15.557716,-252.651794,0.010757,0.009289,0.235929,69.204178,3.525429,2.359288,-252.651794,0.236857,0.000000
147.310013,15.746513,-252.696289,0.010818,0.009327,0.236909,70.043991,3.568211,2.369087,-252.696289,0.237932,0.000000
147.950012,15.934929,-252.740768,0.010865,0.009374,0.238105,70.882103,3.610906,2.381055,-252.740768,0.238999,0.000000
148.590012,15.755074,-252.785248,0.010912,0.009415,0.239129,70.082069,3.570151,2.391288,-252.785248,0.240065,0.000000
149.230011,16.124100,-252.785248,0.010934,0.009454,0.240135,71.723579,3.653773,2.401348,-252.785248,0.241132,0.000000
149.870010,16.035843,-252.918686,0.010986,0.009491,0.241080,71.330994,3.633774,2.410801,-252.918686,0.242199,0.000000
150.510010,16.233200,-252.918686,0.011042,0.009542,0.242355,72.208878,3.678496,2.423549,-252.918686,0.243265,0.000000
151.150009,16.351616,-253.052124,0.011081,0.009581,0.243370,72.735619,3.705329,2.433696,-253.052124,0.244332,0.000000
151.790009,16.496101,-253.052124,0.011128,0.009621,0.244376,73.378326,3.738070,2.443755,-253.052124,0.245399,0.000000
152.430008,16.510994,-253.096619,0.011188,0.009666,0.245512,73.444572,3.741445,2.455116,-253.096619,0.246466,0.000000
153.070007,16.386993,-253.096619,0.011188,0.009699,0.246344,72.892990,3.713346,2.463441,-253.096619,0.247532,0.000000
153.710007,16.868095,-253.185577,0.011253,0.009748,0.247602,75.033035,3.822365,2.476016,-253.185577,0.248599,0.000000
154.350006,16.829369,-253.230057,0.011292,0.009788,0.248625,74.860771,3.813590,2.486249,-253.230057,0.249666,0.000000
154.990005,16.961189,-253.230057,0.011326,0.009824,0.249518,75.447136,3.843460,2.495182,-253.230057,0.250732,0.000000
155.630005,17.158920,-253.274536,0.011378,0.009868,0.250637,76.326691,3.888267,2.506369,-253.274536,0.251799,0.000000
156.270004,17.506714,-253.407974,0.011421,0.009918,0.251912,77.873749,3.967078,2.519117,-253.407974,0.252866,0.000000
156.910004,17.299309,-253.452454,0.011456,0.009950,0.252736,76.951172,3.920079,2.527356,-253.452454,0.253932,0.000000
157.550003,17.343246,-253.452454,0.011516,0.009989,0.253716,77.146614,3.930036,2.537155,-253.452454,0.254999,0.000000
158.190002,17.930473,-253.452454,0.011546,0.010046,0.255172,79.758728,4.063103,2.551725,-253.452454,0.256066,0.000000
158.830002,18.001968,-253.452454,0.011598,0.010086,0.256187,80.076752,4.079304,2.561872,-253.452454,0.257132,0.000000
159.470001,17.724556,-253.630386,0.011650,0.010117,0.256976,78.842766,4.016442,2.569763,-253.630386,0.258199,0.000000
160.110001,18.324074,-253.585907,0.011684,0.010170,0.258321,81.509552,4.152294,2.583205,-253.585907,0.259266,0.000000
160.750015,18.424240,-253.674866,0.011732,0.010213,0.259405,81.955116,4.174993,2.594045,-253.674866,0.260332,0.000000
161.390015,18.289070,-253.674866,0.011740,0.010249,0.260332,81.353844,4.144362,2.603325,-253.674866,0.261399,0.000000
162.030014,18.721397,-253.719345,0.011809,0.010297,0.261555,83.276932,4.242330,2.615553,-253.719345,0.262466,0.000000
162.670013,18.859177,-253.808304,0.011857,0.010339,0.262613,83.889809,4.273551,2.626133,-253.808304,0.263533,0.000000
163.310013,18.817467,-253.808304,0.011908,0.010377,0.263585,83.704269,4.264099,2.635846,-253.808304,0.264599,0.000000
163.950012,19.015198,-253.941757,0.011921,0.010421,0.264686,84.583824,4.308906,2.646859,-253.941757,0.265666,0.000000
164.590012,19.456459,-253.986237,0.011977,0.010464,0.265787,86.546654,4.408896,2.657873,-253.986237,0.266733,0.000000
165.230011,19.412148,-253.986237,0.012021,0.010500,0.266698,86.349548,4.398855,2.666979,-253.986237,0.267799,0.000000
165.870010,19.917458,-254.075195,0.012072,0.010551,0.268007,88.597275,4.513361,2.680074,-254.075195,0.268866,0.000000
166.510010,19.721214,-254.030716,0.012111,0.010585,0.268866,87.724342,4.468891,2.688660,-254.030716,0.269933,0.000000
167.150009,20.064171,-254.164154,0.012158,0.010627,0.269924,89.249886,4.546606,2.699240,-254.164154,0.270999,0.000000
167.790009,20.394089,-254.164154,0.012215,0.010677,0.271199,90.717438,4.621367,2.711988,-254.164154,0.272066,0.000000
168.430008,20.289459,-254.253113,0.012240,0.010711,0.272057,90.252022,4.597657,2.720574,-254.253113,0.273133,0.000000
169.070007,20.707626,-254.253113,0.012275,0.010758,0.273245,92.112122,4.692415,2.732455,-254.253113,0.274199,0.000000
169.710007,20.990257,-254.297592,0.012331,0.010804,0.274416,93.369324,4.756461,2.744162,-254.297592,0.275266,0.000000
170.350006,20.887856,-254.386566,0.012348,0.010836,0.275240,92.913818,4.733255,2.752401,-254.386566,0.276333,0.000000
170.990005,21.111282,-254.431046,0.012409,0.010877,0.276263,93.907677,4.783885,2.762634,-254.431046,0.277399,0.000000
171.630005,21.717880,-254.475525,0.012443,0.010928,0.277582,96.605957,4.921342,2.775816,-254.475525,0.278466,0.000000
172.270004,21.602440,-254.520004,0.012499,0.010963,0.278457,96.092453,4.895183,2.784575,-254.520004,0.279533,0.000000
172.910004,21.962151,-254.608963,0.012547,0.011006,0.279550,97.692528,4.976695,2.795502,-254.608963,0.280600,0.000000
173.550003,22.538956,-254.653442,0.012585,0.011056,0.280816,100.258286,5.107400,2.808164,-254.653442,0.281666,0.000000
174.190002,22.384048,-254.653442,0.012598,0.011087,0.281606,99.569221,5.072298,2.816055,-254.653442,0.282733,0.000000
174.830002,22.828293,-254.697922,0.012654,0.011134,0.282811,101.545319,5.172965,2.828110,-254.697922,0.283800,0.000000
175.470001,23.188751,-254.742401,0.012697,0.011177,0.283895,103.148720,5.254646,2.838950,-254.742401,0.284866,0.000000
176.110016,23.355942,-254.697922,0.012715,0.011212,0.284797,103.892418,5.292532,2.847969,-254.697922,0.285933,0.000000
176.750015,23.700012,-254.875854,0.012775,0.011256,0.285898,105.422920,5.370499,2.858983,-254.875854,0.287000,0.000000
177.390015,24.409760,-254.831375,0.012810,0.011303,0.287095,108.580032,5.531331,2.870951,-254.831375,0.288066,0.000000
178.030014,24.515884,-254.920334,0.012870,0.011342,0.288075,109.052101,5.555379,2.880750,-254.920334,0.289133,0.000000
178.670013,24.687920,-254.964813,0.012922,0.011381,0.289072,109.817352,5.594362,2.890723,-254.964813,0.290200,0.000000
179.310013,25.583099,-255.009293,0.012969,0.011431,0.290347,113.799309,5.797213,2.903471,-255.009293,0.291266,0.000000
179.950012,25.472137,-255.098251,0.013004,0.011471,0.291370,113.305725,5.772069,2.913705,-255.098251,0.292333,0.000000
180.590012,25.821419,-255.187210,0.013038,0.011510,0.292359,114.859406,5.851217,2.923591,-255.187210,0.293400,0.000000
181.230011,26.648834,-255.142731,0.013094,0.011557,0.293547,118.539932,6.038712,2.935472,-255.142731,0.294466,0.000000
181.870010,26.873375,-255.187210,0.013133,0.011597,0.294571,119.538742,6.089594,2.945705,-255.187210,0.295533,0.000000
182.510010,27.058067,-255.276184,0.013154,0.011639,0.295637,120.360298,6.131445,2.956372,-255.276184,0.296600,0.000000
183.150009,28.015442,-255.320663,0.013189,0.011684,0.296782,124.618912,6.348390,2.967820,-255.320663,0.297667,0.000000
183.790009,27.837814,-255.365143,0.013236,0.011722,0.297727,123.828781,6.308139,2.977273,-255.365143,0.298733,0.000000
184.430008,28.398987,-255.409622,0.013288,0.011765,0.298837,126.325005,6.435303,2.988373,-255.409622,0.299800,0.000000
185.070007,29.055107,-255.409622,0.013336,0.011811,0.300008,129.243576,6.583982,3.000080,-255.409622,0.300867,0.000000
185.710007,29.010422,-255.498581,0.013357,0.011846,0.300893,129.044800,6.573855,3.008926,-255.498581,0.301933,0.000000
186.350006,29.357101,-255.543060,0.013426,0.011886,0.301899,130.586914,6.652414,3.018986,-255.543060,0.303000,0.000000
186.990005,30.460434,-255.543060,0.013456,0.011935,0.303139,135.494781,6.902433,3.031387,-255.543060,0.304067,0.000000
187.630005,30.442566,-255.676514,0.013512,0.011972,0.304101,135.415298,6.898384,3.041013,-255.676514,0.305133,0.000000
188.270004,30.934837,-255.632019,0.013555,0.012012,0.305099,137.605026,7.009934,3.050987,-255.632019,0.306200,0.000000
188.910004,32.225479,-255.765472,0.013594,0.012065,0.306443,143.346085,7.302398,3.064429,-255.765472,0.307267,0.000000
189.550003,32.045998,-255.720993,0.013642,0.012100,0.307345,142.547714,7.261727,3.073448,-255.720993,0.308333,0.000000
190.190002,32.948631,-255.809952,0.013685,0.012144,0.308455,146.562836,7.466267,3.084548,-255.809952,0.309400,0.000000
190.830002,33.704918,-255.854431,0.013724,0.012192,0.309669,149.926956,7.637643,3.096689,-255.854431,0.310467,0.000000
191.470016,33.716461,-255.854431,0.013771,0.012218,0.310328,149.978317,7.640259,3.103280,-255.854431,0.311499,0.000000
192.110016,32.155479,-255.943390,0.013762,0.012215,0.310259,143.034714,7.286536,3.102587,-255.943390,0.310085,0.000000
192.750015,31.412964,-256.032349,0.013810,0.012179,0.309357,139.731842,7.118279,3.093567,-256.032349,0.309019,0.000000
193.390015,30.913986,-256.032349,0.013784,0.012139,0.308342,137.512283,7.005209,3.083421,-256.032349,0.307952,0.000000
194.030014,30.585182,-256.121307,0.013780,0.012106,0.307501,136.049683,6.930701,3.075009,-256.121307,0.306885,0.000000
194.670013,30.293617,-256.032349,0.013797,0.012061,0.306339,134.752747,6.864632,3.063388,-256.032349,0.305818,0.000000
195.310013,30.029602,-256.210266,0.013797,0.012020,0.305307,133.578339,6.804805,3.053068,-256.210266,0.304752,0.000000
195.950012,29.684044,-256.254761,0.013784,0.011982,0.304336,132.041229,6.726501,3.043355,-256.254761,0.303685,0.000000
196.590012,28.733002,-256.210266,0.013793,0.011941,0.303295,127.810776,6.510991,3.032948,-256.210266,0.302618,0.000000
197.230011,26.848053,-256.299225,0.013810,0.011894,0.302107,119.426102,6.083856,3.021067,-256.299225,0.301552,0.000000
197.870010,25.472137,-256.299225,0.013805,0.011866,0.301396,113.305725,5.772069,3.013956,-256.299225,0.300485,0.000000
198.510010,22.915054,-256.388214,0.013818,0.011824,0.300329,101.931252,5.192626,3.003289,-256.388214,0.299418,0.000000
199.150009,20.546394,-256.432678,0.013818,0.011788,0.299410,91.394928,4.655879,2.994097,-256.432678,0.298352,0.000000
199.790009,17.327980,-256.477173,0.013810,0.011742,0.298248,77.078705,3.926576,2.982476,-256.477173,0.297285,0.000000
200.430008,16.117020,-256.566132,0.013810,0.011727,0.297875,71.692085,3.652169,2.978747,-256.566132,0.296218,0.000000
201.070007,11.640358,-256.521637,0.013775,0.011663,0.296244,51.778900,2.637743,2.962443,-256.521637,0.295152,0.000000
201.710007,8.532539,-256.655090,0.013762,0.011617,0.295065,37.954632,1.933501,2.950649,-256.655090,0.294085,0.000000
202.350006,6.671425,-256.699554,0.013749,0.011588,0.294336,29.675980,1.511767,2.943364,-256.699554,0.293018,0.000000
202.990005,3.847351,-256.699554,0.013728,0.011538,0.293070,17.113873,0.871822,2.930702,-256.699554,0.291952,0.000000
203.630005,2.175766,-256.699554,0.013711,0.011498,0.292038,9.678290,0.493036,2.920382,-256.699554,0.290885,0.000000
204.270004,1.540504,-256.788544,0.013650,0.011466,0.291249,6.852506,0.349083,2.912491,-256.788544,0.289818,0.000000
204.910004,0.913429,-256.833008,0.013590,0.011411,0.289844,4.063136,0.206986,2.898442,-256.833008,0.288751,0.000000
205.550003,0.819214,-256.833008,0.013551,0.011367,0.288717,3.644045,0.185637,2.887168,-256.833008,0.287685,0.000000
206.190002,0.700058,-256.921967,0.013482,0.011318,0.287477,3.114013,0.158635,2.874766,-256.921967,0.286618,0.000000
206.830017,0.671761,-256.966461,0.013465,0.011281,0.286540,2.988140,0.152223,2.865400,-256.966461,0.285551,0.000000
207.470016,0.594673,-257.010925,0.013413,0.011241,0.285517,2.645238,0.134755,2.855167,-257.010925,0.284485,0.000000
208.110016,0.484451,-257.055420,0.013353,0.011191,0.284251,2.154947,0.109778,2.842505,-257.055420,0.283418,0.000000
208.750015,0.483337,-257.099884,0.013323,0.011156,0.283375,2.149992,0.109526,2.833747,-257.099884,0.282351,0.000000
209.390015,0.462112,-257.144379,0.013249,0.011113,0.282282,2.055579,0.104716,2.822820,-257.144379,0.281285,0.000000
210.030014,0.415192,-257.144379,0.013223,0.011064,0.281016,1.846865,0.094084,2.810158,-257.144379,0.280218,0.000000
210.670013,0.399925,-257.233337,0.013176,0.011031,0.280192,1.778956,0.090624,2.801919,-257.233337,0.279151,0.000000
211.310013,0.432693,-257.233337,0.013137,0.010992,0.279203,1.924717,0.098050,2.792033,-257.233337,0.278085,0.000000
211.950012,0.342209,-257.322296,0.013068,0.010938,0.277816,1.522221,0.077546,2.778157,-257.322296,0.277018,0.000000
212.590012,0.348907,-257.366791,0.013034,0.010902,0.276914,1.552018,0.079064,2.769138,-257.366791,0.275951,0.000000
213.230011,0.411842,-257.411255,0.013008,0.010871,0.276116,1.831966,0.093325,2.761160,-257.411255,0.274885,0.000000
213.870010,0.361198,-257.455750,0.012960,0.010821,0.274850,1.606691,0.081849,2.748498,-257.455750,0.273818,0.000000
214.510010,0.330666,-257.500214,0.012909,0.010776,0.273705,1.470874,0.074930,2.737051,-257.500214,0.272751,0.000000
215.150009,0.356728,-257.544708,0.012870,0.010737,0.272708,1.586804,0.080836,2.727078,-257.544708,0.271684,0.000000
215.790009,0.344818,-257.633667,0.012818,0.010691,0.271563,1.533828,0.078137,2.715631,-257.633667,0.270618,0.000000
216.430008,0.333267,-257.678162,0.012792,0.010653,0.270592,1.482447,0.075519,2.705917,-257.678162,0.269551,0.000000
217.070007,0.341087,-257.678162,0.012741,0.010614,0.269603,1.517232,0.077291,2.696031,-257.678162,0.268484,0.000000
217.710007,0.320984,-257.767120,0.012706,0.010570,0.268476,1.427808,0.072736,2.684757,-257.767120,0.267418,0.000000
218.350006,0.330666,-257.722626,0.012650,0.010525,0.267322,1.470874,0.074930,2.673223,-257.722626,0.266351,0.000000
218.990005,0.339600,-257.856079,0.012594,0.010478,0.266134,1.510615,0.076954,2.661342,-257.856079,0.265284,0.000000
219.630005,0.350029,-257.856079,0.012585,0.010449,0.265414,1.557007,0.079318,2.654144,-257.856079,0.264218,0.000000
220.270004,0.308693,-257.945038,0.012525,0.010400,0.264148,1.373135,0.069951,2.641483,-257.945038,0.263151,0.000000
220.910004,0.316887,-258.033997,0.012465,0.010355,0.263030,1.409583,0.071808,2.630296,-258.033997,0.262084,0.000000
221.550003,0.309067,-257.945038,0.012430,0.010315,0.262006,1.374798,0.070036,2.620062,-257.945038,0.261018,0.000000
222.190018,0.303108,-258.033997,0.012378,0.010272,0.260914,1.348293,0.068685,2.609135,-258.033997,0.259951,0.000000
222.830017,0.313164,-258.078491,0.012340,0.010226,0.259734,1.393022,0.070964,2.597341,-258.078491,0.258884,0.000000
223.470016,0.315025,-258.078491,0.012309,0.010188,0.258763,1.401303,0.071386,2.587628,-258.078491,0.257809,0.000000
224.110016,0.305717,-258.211914,0.012253,0.010147,0.257722,1.359899,0.069277,2.577221,-258.211914,0.256742,0.000000
224.750015,0.335503,-258.167450,0.012184,0.010103,0.256621,1.492390,0.076026,2.566207,-258.167450,0.255675,0.000000
225.390015,0.318748,-258.256409,0.012176,0.010065,0.255641,1.417864,0.072229,2.556408,-258.256409,0.254609,0.000000
226.030014,0.326942,-258.256409,0.012120,0.010020,0.254513,1.454313,0.074086,2.545134,-258.256409,0.253542,0.000000
226.670013,0.353378,-258.300873,0.012077,0.009976,0.253395,1.571905,0.080077,2.533947,-258.300873,0.252475,0.000000
227.310013,0.366409,-258.389832,0.012051,0.009960,0.252987,1.629870,0.083030,2.529871,-258.389832,0.251409,0.000000
227.950012,0.365295,-258.389832,0.011977,0.009891,0.251244,1.624915,0.082777,2.512439,-258.389832,0.250342,0.000000
228.590012,0.350769,-258.478821,0.011943,0.009851,0.250221,1.560299,0.079485,2.502206,-258.478821,0.249275,0.000000
229.230011,0.341461,-258.523285,0.011913,0.009823,0.249492,1.518895,0.077376,2.494922,-258.523285,0.248209,0.000000
229.870010,0.355240,-258.567780,0.011852,0.009767,0.248087,1.580186,0.080499,2.480873,-258.567780,0.247142,0.000000
230.510010,0.380562,-258.656738,0.011783,0.009722,0.246951,1.692824,0.086237,2.469512,-258.656738,0.246075,0.000000
231.150009,0.367905,-258.612244,0.011753,0.009679,0.245841,1.636522,0.083368,2.458411,-258.612244,0.245009,0.000000
231.790009,0.367905,-258.745697,0.011710,0.009642,0.244913,1.636522,0.083368,2.449132,-258.745697,0.243942,0.000000
232.430008,0.394714,-258.790161,0.011671,0.009598,0.243794,1.755777,0.089444,2.437945,-258.790161,0.242875,0.000000
233.070007,0.372368,-258.745697,0.011628,0.009559,0.242806,1.656375,0.084380,2.428058,-258.745697,0.241809,0.000000
233.710007,0.387268,-258.834656,0.011585,0.009514,0.241661,1.722654,0.087756,2.416611,-258.834656,0.240742,0.000000
234.350006,0.433441,-258.834656,0.011555,0.009483,0.240863,1.928043,0.098219,2.408633,-258.834656,0.239675,0.000000
234.990005,0.395088,-258.923615,0.011490,0.009433,0.239597,1.757440,0.089528,2.395971,-258.923615,0.238608,0.000000
235.630005,0.373489,-258.923615,0.011460,0.009388,0.238444,1.661364,0.084634,2.384437,-258.923615,0.237542,0.000000
236.270004,0.382797,-258.968109,0.011395,0.009343,0.237308,1.702767,0.086743,2.373076,-258.968109,0.236475,0.000000
236.910004,0.404396,-259.146027,0.011361,0.009312,0.236527,1.798844,0.091637,2.365271,-259.146027,0.235408,0.000000
237.550018,0.371994,-259.146027,0.011326,0.009267,0.235382,1.654712,0.084295,2.353824,-259.146027,0.234342,0.000000
238.190018,0.382797,-259.190491,0.011270,0.009223,0.234272,1.702767,0.086743,2.342723,-259.190491,0.233275,0.000000
238.830017,0.388008,-259.234985,0.011262,0.009180,0.233171,1.725946,0.087924,2.331710,-259.234985,0.232208,0.000000
239.470016,0.388382,-259.234985,0.011197,0.009139,0.232122,1.727609,0.088009,2.321216,-259.234985,0.231142,0.000000
240.110016,0.364548,-259.279449,0.011132,0.009087,0.230812,1.621589,0.082608,2.308121,-259.279449,0.230075,0.000000
240.750015,0.412216,-259.279449,0.011098,0.009061,0.230162,1.833629,0.093410,2.301617,-259.279449,0.229008,0.000000
241.390015,0.347794,-259.412903,0.011068,0.009016,0.229000,1.547063,0.078811,2.289996,-259.412903,0.227942,0.000000
242.030014,0.368645,-259.457397,0.011033,0.008968,0.227794,1.639814,0.083536,2.277942,-259.457397,0.226875,0.000000
242.670013,0.385406,-259.457397,0.010990,0.008945,0.227213,1.714374,0.087334,2.272131,-259.457397,0.225808,0.000000
243.310013,0.343697,-259.546356,0.010934,0.008889,0.225774,1.528839,0.077883,2.257735,-259.546356,0.224742,0.000000
243.950012,0.355988,-259.546356,0.010882,0.008838,0.224481,1.583512,0.080668,2.244814,-259.546356,0.223675,0.000000
244.590012,0.374977,-259.679779,0.010835,0.008808,0.223718,1.667982,0.084971,2.237182,-259.679779,0.222608,0.000000
245.230011,0.328056,-259.635315,0.010796,0.008761,0.222521,1.459267,0.074339,2.225214,-259.635315,0.221541,0.000000
245.870010,0.360825,-259.635315,0.010753,0.008718,0.221437,1.605028,0.081764,2.214374,-259.635315,0.220475,0.000000
246.510010,0.367531,-259.768768,0.010706,0.008682,0.220518,1.634859,0.083284,2.205182,-259.768768,0.219408,0.000000
247.150009,0.355614,-259.768768,0.010667,0.008642,0.219495,1.581849,0.080583,2.194948,-259.768768,0.218341,0.000000
247.790009,0.360825,-259.768768,0.010598,0.008588,0.218125,1.605028,0.081764,2.181246,-259.768768,0.217275,0.000000
248.430008,0.367905,-259.813232,0.010589,0.008560,0.217422,1.636522,0.083368,2.174222,-259.813232,0.216208,0.000000
249.070007,0.373116,-259.857727,0.010542,0.008512,0.216217,1.659701,0.084549,2.162167,-259.857727,0.215141,0.000000
249.710007,0.348167,-260.035645,0.010451,0.008461,0.214916,1.548726,0.078896,2.149159,-260.035645,0.214075,0.000000
250.350006,0.345932,-259.991150,0.010460,0.008426,0.214023,1.538782,0.078389,2.140226,-259.991150,0.213008,0.000000
250.990005,0.347420,-259.991150,0.010421,0.008400,0.213372,1.545400,0.078726,2.133722,-259.991150,0.211941,0.000000
251.630005,0.358223,-260.124603,0.010352,0.008345,0.211959,1.593455,0.081174,2.119586,-260.124603,0.210875,0.000000
252.270020,0.350029,-260.035645,0.010317,0.008300,0.210831,1.557007,0.079318,2.108312,-260.035645,0.209808,0.000000
252.910019,0.366783,-260.169098,0.010261,0.008256,0.209704,1.631533,0.083114,2.097038,-260.169098,0.208741,0.000000
253.550018,0.382050,-260.213562,0.010227,0.008216,0.208689,1.699441,0.086574,2.086892,-260.213562,0.207675,0.000000
254.190018,0.394341,-260.213562,0.010197,0.008182,0.207813,1.754114,0.089359,2.078133,-260.213562,0.206608,0.000000
254.830017,0.370880,-260.302521,0.010136,0.008131,0.206521,1.649757,0.084043,2.065211,-260.302521,0.205541,0.000000
255.470016,0.399925,-260.347015,0.010098,0.008094,0.205576,1.778956,0.090624,2.055758,-260.347015,0.204474,0.000000
256.110016,0.388382,-260.347015,0.010054,0.008051,0.204483,1.727609,0.088009,2.044831,-260.347015,0.203408,0.000000
256.750000,0.355240,-260.480438,0.010007,0.008005,0.203330,1.580186,0.080499,2.033297,-260.480438,0.202341,0.000000
257.390015,0.367905,-260.435974,0.009960,0.007953,0.201994,1.636522,0.083368,2.019942,-260.435974,0.201274,0.000000
258.029999,0.374603,-260.569397,0.009916,0.007923,0.201240,1.666319,0.084886,2.012397,-260.569397,0.200208,0.000000
258.670013,0.370132,-260.480438,0.009869,0.007882,0.200208,1.646431,0.083873,2.002077,-260.480438,0.199141,0.000000
259.309998,0.341461,-260.658386,0.009804,0.007838,0.199089,1.518895,0.077376,1.990890,-260.658386,0.198074,0.000000
259.950012,0.350029,-260.658386,0.009804,0.007799,0.198092,1.557007,0.079318,1.980917,-260.658386,0.197008,0.000000
260.590027,0.353378,-260.702850,0.009740,0.007753,0.196938,1.571905,0.080077,1.969383,-260.702850,0.195941,0.000000
261.230011,0.371254,-260.791809,0.009697,0.007709,0.195802,1.651420,0.084127,1.958022,-260.791809,0.194874,0.000000
261.870026,0.369392,-260.791809,0.009645,0.007669,0.194796,1.643139,0.083706,1.947962,-260.791809,0.193808,0.000000
262.510010,0.358223,-260.791809,0.009602,0.007629,0.193773,1.593455,0.081174,1.937729,-260.791809,0.192741,0.000000
263.150024,0.325455,-260.925262,0.009576,0.007589,0.192767,1.447695,0.073749,1.927669,-260.925262,0.191674,0.000000
263.790009,0.360085,-260.925262,0.009533,0.007548,0.191709,1.601736,0.081596,1.917089,-260.925262,0.190608,0.000000
264.430023,0.349655,-261.014221,0.009494,0.007515,0.190876,1.555344,0.079233,1.908764,-261.014221,0.189541,0.000000
265.070007,0.325081,-261.014221,0.009434,0.007461,0.189506,1.446032,0.073664,1.895061,-261.014221,0.188474,0.000000
265.710022,0.351891,-260.969727,0.009373,0.007418,0.188413,1.565287,0.079740,1.884135,-260.969727,0.187407,0.000000
266.350006,0.354866,-261.147675,0.009326,0.007372,0.187260,1.578523,0.080414,1.872600,-261.147675,0.186341,0.000000
266.990021,0.336624,-261.147675,0.009300,0.007335,0.186297,1.497379,0.076280,1.862974,-261.147675,0.185274,0.000000
267.630005,0.360451,-261.236633,0.009257,0.007295,0.185291,1.603365,0.081679,1.852914,-261.236633,0.184207,0.000000
268.270020,0.354500,-261.281097,0.009231,0.007245,0.184034,1.576894,0.080331,1.840340,-261.281097,0.183141,0.000000
268.910004,0.355988,-261.281097,0.009179,0.007205,0.183011,1.583512,0.080668,1.830106,-261.281097,0.182074,0.000000
269.550018,0.358963,-261.325592,0.009123,0.007168,0.182065,1.596747,0.081342,1.820654,-261.325592,0.181007,0.000000
270.190002,0.349655,-261.325592,0.009102,0.007125,0.180964,1.555344,0.079233,1.809640,-261.325592,0.179941,0.000000
270.400024,0.407372,-261.370056,0.009080,0.007117,0.180773,1.812079,0.092312,1.807732,-261.370056,0.180617,0.000000