File: Data/PDMS compression/PDMS 0024 Punched_3_16th_1_3_03202024_165240.csv
Time (sec),S:Load (lbs),S:HL1 (DIM),S:LVDT (in),S:Position (in),Ch:Position (mm),Ch:Load (N),Ch:Stress (MPa),Ch:Strain (mm/mm),Ch:HL1 (DIM),Set Point (),Cycles ()
0.110000,-0.002609,-207.325714,-0.000017,-0.000000,-0.000000,-0.011607,-0.000591,-0.000000,-207.325714,-0.000139,0.000000
0.880000,-0.001488,-207.370193,-0.000009,0.000137,0.003486,-0.006618,-0.000337,0.034863,-207.370193,0.004206,0.000000
1.650000,-0.004837,-207.370193,0.000203,0.000383,0.009739,-0.021516,-0.001096,0.097389,-207.370193,0.010615,0.000000
2.420000,0.005211,-207.370193,0.000453,0.000633,0.016070,0.023179,0.001181,0.160699,-207.370193,0.017032,0.000000
3.190000,0.014153,-207.414673,0.000720,0.000885,0.022470,0.062954,0.003207,0.224698,-207.414673,0.023441,0.000000
3.960000,0.018990,-207.414673,0.000987,0.001141,0.028974,0.084470,0.004303,0.289741,-207.414673,0.029859,0.000000
4.730000,0.014526,-207.503632,0.001233,0.001392,0.035357,0.064617,0.003292,0.353570,-207.503632,0.036276,0.000000
5.500000,0.001862,-207.503632,0.001509,0.001642,0.041696,0.008281,0.000422,0.416963,-207.503632,0.042685,0.000000
6.270000,-0.004471,-207.459152,0.001755,0.001898,0.048201,-0.019887,-0.001013,0.482006,-207.459152,0.049103,0.000000
7.040000,0.056229,-207.548111,0.002018,0.002148,0.054549,0.250117,0.012742,0.545487,-207.548111,0.055511,0.000000
7.810000,0.300880,-207.548111,0.002289,0.002403,0.061044,1.338383,0.068180,0.610443,-207.548111,0.061929,0.000000
8.580001,0.326195,-207.681564,0.002410,-0.000000,-0.000000,1.450987,0.073917,-0.000000,-207.681564,0.000217,0.000000
9.350000,0.356361,-207.592606,0.002397,0.000000,0.000009,1.585175,0.080753,0.000087,-207.592606,0.001344,0.000000
10.120001,0.512756,-207.637085,0.002449,0.000066,0.001665,2.280854,0.116192,0.016650,-207.637085,0.002628,0.000000
10.890000,0.554832,-207.726044,0.002509,0.000117,0.002966,2.468018,0.125727,0.029658,-207.726044,0.003911,0.000000
11.660001,0.618507,-207.726044,0.002557,0.000167,0.004232,2.751258,0.140156,0.042319,-207.726044,0.005195,0.000000
12.430000,0.704529,-207.770523,0.002617,0.000221,0.005602,3.133901,0.159649,0.056024,-207.770523,0.006478,0.000000
13.200001,0.736923,-207.681564,0.002665,0.000265,0.006721,3.277998,0.166989,0.067208,-207.681564,0.007762,0.000000
13.970000,0.798737,-207.726044,0.002721,0.000316,0.008022,3.552958,0.180996,0.080217,-207.726044,0.009045,0.000000
14.740001,0.868004,-207.859482,0.002764,0.000371,0.009435,3.861074,0.196692,0.094354,-207.859482,0.010329,0.000000
15.510001,0.939499,-207.859482,0.002828,0.000418,0.010615,4.179100,0.212894,0.106147,-207.859482,0.011612,0.000000
16.280001,1.020676,-207.815002,0.002884,0.000477,0.012115,4.540192,0.231288,0.121151,-207.815002,0.012896,0.000000
17.050001,1.102966,-207.859482,0.002945,0.000523,0.013286,4.906239,0.249936,0.132857,-207.859482,0.014179,0.000000
17.820002,1.173721,-207.903961,0.002979,0.000576,0.014639,5.220973,0.265969,0.146388,-207.903961,0.015463,0.000000
18.590000,1.193085,-207.992920,0.003035,0.000622,0.015810,5.307106,0.270357,0.158095,-207.992920,0.016746,0.000000
19.360001,1.324532,-208.037415,0.003087,0.000675,0.017136,5.891810,0.300143,0.171365,-208.037415,0.018030,0.000000
20.130001,1.397514,-208.037415,0.003139,0.000727,0.018472,6.216455,0.316681,0.184718,-208.037415,0.019313,0.000000
20.900002,1.417252,-207.992920,0.003191,0.000771,0.019591,6.304250,0.321154,0.195906,-207.992920,0.020597,0.000000
21.670000,1.543854,-208.037415,0.003242,0.000823,0.020900,6.867404,0.349842,0.209002,-208.037415,0.021880,0.000000
22.440001,1.613121,-208.126373,0.003294,0.000879,0.022331,7.175521,0.365538,0.223313,-208.126373,0.023164,0.000000
23.210001,1.749031,-208.081894,0.003337,0.000926,0.023511,7.780079,0.396336,0.235106,-208.081894,0.024447,0.000000
23.980001,1.836914,-208.126373,0.003410,0.000979,0.024863,8.171001,0.416251,0.248634,-208.126373,0.025730,0.000000
24.750002,1.908783,-208.170853,0.003449,0.001027,0.026078,8.490690,0.432536,0.260775,-208.170853,0.027014,0.000000
25.520000,1.999268,-208.170853,0.003488,0.001075,0.027317,8.893187,0.453041,0.273175,-208.170853,0.028298,0.000000
26.290001,2.076347,-208.259811,0.003548,0.001129,0.028679,9.236054,0.470507,0.286793,-208.259811,0.029581,0.000000
27.060001,2.179123,-208.259811,0.003604,0.001179,0.029945,9.693223,0.493796,0.299453,-208.259811,0.030865,0.000000
27.830002,2.280411,-208.215332,0.003669,0.001235,0.031359,10.143774,0.516748,0.313590,-208.215332,0.032148,0.000000
28.600002,2.324722,-208.304291,0.003699,0.001283,0.032599,10.340881,0.526790,0.325989,-208.304291,0.033432,0.000000
29.370001,2.424515,-208.393250,0.003747,0.001327,0.033709,10.784781,0.549403,0.337090,-208.393250,0.034715,0.000000
30.140001,2.490051,-208.393250,0.003803,0.001382,0.035105,11.076302,0.564254,0.351053,-208.393250,0.035999,0.000000
30.910002,2.613686,-208.348770,0.003863,0.001434,0.036424,11.626254,0.592270,0.364236,-208.348770,0.037282,0.000000
31.680002,2.730232,-208.393250,0.003919,0.001485,0.037724,12.144680,0.618679,0.377244,-208.393250,0.038565,0.000000
32.450001,2.793907,-208.437744,0.003949,0.001533,0.038947,12.427919,0.633108,0.389469,-208.437744,0.039840,0.000000
33.220001,2.840828,-208.526703,0.004018,0.001578,0.040083,12.636634,0.643741,0.400832,-208.526703,0.041124,0.000000
33.990002,2.924240,-208.482224,0.004057,0.001634,0.041497,13.007669,0.662642,0.414968,-208.482224,0.042407,0.000000
34.760002,3.047493,-208.526703,0.004130,0.001687,0.042841,13.555925,0.690572,0.428408,-208.526703,0.043691,0.000000
35.530003,3.139473,-208.526703,0.004174,0.001740,0.044203,13.965074,0.711415,0.442027,-208.526703,0.044974,0.000000
36.300003,3.156601,-208.704620,0.004208,0.001783,0.045295,14.041263,0.715296,0.452954,-208.704620,0.046258,0.000000
37.070004,3.322678,-208.615662,0.004273,0.001836,0.046639,14.780008,0.752930,0.466394,-208.615662,0.047541,0.000000
37.840000,3.332359,-208.704620,0.004342,0.001889,0.047975,14.823074,0.755123,0.479751,-208.704620,0.048825,0.000000
38.610001,3.463440,-208.660141,0.004372,0.001937,0.049206,15.406150,0.784827,0.492063,-208.660141,0.050108,0.000000
39.380001,3.554665,-208.704620,0.004424,0.001991,0.050568,15.811938,0.805499,0.505681,-208.704620,0.051392,0.000000
40.150002,3.566208,-208.749100,0.004467,0.002034,0.051669,15.863285,0.808114,0.516695,-208.749100,0.052675,0.000000
40.920002,3.760216,-208.793579,0.004549,0.002089,0.053048,16.726274,0.852077,0.530483,-208.793579,0.053959,0.000000
41.690002,3.745323,-208.793579,0.004587,0.002139,0.054323,16.660030,0.848702,0.543231,-208.793579,0.055242,0.000000
42.460003,3.927040,-208.793579,0.004644,0.002192,0.055676,17.468348,0.889880,0.556758,-208.793579,0.056526,0.000000
43.230003,3.973213,-208.882553,0.004687,0.002240,0.056907,17.673735,0.900343,0.569074,-208.882553,0.057809,0.000000
44.000004,3.989227,-208.882553,0.004730,0.002291,0.058191,17.744968,0.903972,0.581909,-208.882553,0.059093,0.000000
44.770000,4.100563,-208.882553,0.004773,0.002335,0.059310,18.240215,0.929201,0.593097,-208.882553,0.060376,0.000000
45.540001,4.208183,-208.882553,0.004833,0.002392,0.060749,18.718935,0.953588,0.607491,-208.882553,0.061660,0.000000
46.310001,4.306862,-208.927032,0.004889,0.002443,0.062050,19.157879,0.975949,0.620499,-208.927032,0.062943,0.000000
47.080002,4.412613,-209.015991,0.004950,0.002494,0.063351,19.628283,0.999912,0.633508,-209.015991,0.064227,0.000000
47.850002,4.401443,-209.060471,0.004997,0.002542,0.064556,19.578598,0.997381,0.645563,-209.060471,0.065510,0.000000
48.620003,4.532143,-208.971512,0.005040,0.002594,0.065892,20.159977,1.026998,0.658920,-208.971512,0.066794,0.000000
49.390003,4.566406,-209.060471,0.005101,0.002645,0.067184,20.312389,1.034762,0.671842,-209.060471,0.068077,0.000000
50.160004,4.640137,-209.060471,0.005165,0.002695,0.068459,20.640360,1.051470,0.684589,-209.060471,0.069361,0.000000
50.930004,4.770836,-209.104950,0.005208,0.002749,0.069829,21.221739,1.081087,0.698290,-209.104950,0.070644,0.000000
51.700001,4.787224,-209.193909,0.005269,0.002799,0.071086,21.294636,1.084800,0.710864,-209.193909,0.071928,0.000000
52.470001,4.781265,-209.193909,0.005307,0.002840,0.072136,21.268129,1.083450,0.721359,-209.193909,0.073211,0.000000
53.240002,4.960373,-209.238388,0.005376,0.002899,0.073636,22.064840,1.124037,0.736363,-209.238388,0.074495,0.000000
54.010002,5.000587,-209.238388,0.005411,0.002951,0.074946,22.243725,1.133149,0.749458,-209.238388,0.075778,0.000000
54.780003,4.968567,-209.238388,0.005463,0.002993,0.076030,22.101290,1.125893,0.760298,-209.238388,0.077062,0.000000
55.550003,5.042297,-209.282867,0.005523,0.003045,0.077331,22.429258,1.142601,0.773307,-209.282867,0.078345,0.000000
56.320004,5.165924,-209.282867,0.005570,0.003098,0.078692,22.979177,1.170615,0.786921,-209.282867,0.079629,0.000000
57.090004,5.229973,-209.327362,0.005631,0.003152,0.080071,23.264082,1.185129,0.800710,-209.327362,0.080912,0.000000
57.860004,5.327530,-209.416321,0.005683,0.003203,0.081346,23.698036,1.207236,0.813457,-209.416321,0.082196,0.000000
58.630001,5.382271,-209.416321,0.005747,0.003256,0.082690,23.941536,1.219640,0.826901,-209.416321,0.083479,0.000000
59.400002,5.343544,-209.460800,0.005773,0.003300,0.083817,23.769270,1.210864,0.838173,-209.460800,0.084763,0.000000
60.170002,5.454887,-209.460800,0.005833,0.003348,0.085049,24.264551,1.236095,0.850489,-209.460800,0.086046,0.000000
60.940002,5.517815,-209.549759,0.005885,0.003406,0.086514,24.544466,1.250355,0.865144,-209.549759,0.087330,0.000000
61.710003,5.597130,-209.549759,0.005933,0.003451,0.087659,24.897278,1.268328,0.876593,-209.549759,0.088613,0.000000
62.480003,5.662666,-209.549759,0.006002,0.003504,0.089012,25.188797,1.283178,0.890120,-209.549759,0.089897,0.000000
63.250004,5.638466,-209.460800,0.006049,0.003554,0.090278,25.081148,1.277695,0.902781,-209.460800,0.091180,0.000000
64.020004,5.785179,-209.594238,0.006096,0.003606,0.091588,25.733763,1.310940,0.915876,-209.594238,0.092463,0.000000
64.790001,5.785179,-209.594238,0.006153,0.003657,0.092880,25.733763,1.310940,0.928798,-209.594238,0.093747,0.000000
65.560005,5.806778,-209.683197,0.006204,0.003704,0.094085,25.829838,1.315835,0.940853,-209.683197,0.095031,0.000000
66.330002,5.922585,-209.638718,0.006252,0.003756,0.095395,26.344973,1.342077,0.953949,-209.638718,0.096314,0.000000
67.100006,5.886467,-209.683197,0.006303,0.003803,0.096592,26.184313,1.333892,0.965917,-209.683197,0.097598,0.000000
67.870003,6.039513,-209.772171,0.006342,0.003857,0.097962,26.865093,1.368573,0.979618,-209.772171,0.098881,0.000000
68.640007,6.047699,-209.816650,0.006398,0.003909,0.099280,26.901508,1.370428,0.992801,-209.816650,0.100165,0.000000
69.410004,6.129250,-209.772171,0.006459,0.003960,0.100590,27.264263,1.388908,1.005896,-209.772171,0.101448,0.000000
70.180000,6.216011,-209.861130,0.006519,0.004014,0.101951,27.650198,1.408568,1.019511,-209.861130,0.102732,0.000000
70.950005,6.146378,-209.861130,0.006562,0.004062,0.103165,27.340452,1.392789,1.031653,-209.861130,0.104015,0.000000
71.720001,6.226814,-209.905609,0.006622,0.004110,0.104388,27.698254,1.411016,1.043878,-209.905609,0.105298,0.000000
72.490005,6.311714,-209.994568,0.006670,0.004162,0.105723,28.075907,1.430255,1.057235,-209.994568,0.106582,0.000000
73.260002,6.324745,-209.905609,0.006735,0.004209,0.106920,28.133871,1.433208,1.069203,-209.905609,0.107866,0.000000
74.030006,6.311714,-209.994568,0.006769,0.004255,0.108082,28.075907,1.430255,1.080822,-209.994568,0.109149,0.000000
74.800003,6.413742,-209.994568,0.006812,0.004310,0.109470,28.529749,1.453375,1.094698,-209.994568,0.110433,0.000000
75.570007,6.417465,-210.083527,0.006873,0.004362,0.110788,28.546310,1.454218,1.107880,-210.083527,0.111716,0.000000
76.340004,6.529549,-210.039047,0.006946,0.004415,0.112141,29.044884,1.479617,1.121411,-210.039047,0.113000,0.000000
77.110001,6.494545,-209.994568,0.006985,0.004460,0.113277,28.889179,1.471685,1.132770,-209.994568,0.114283,0.000000
77.880005,6.506462,-210.128006,0.007023,0.004510,0.114543,28.942188,1.474385,1.145430,-210.128006,0.115566,0.000000
78.650002,6.575356,-210.216980,0.007088,0.004566,0.115974,29.248642,1.489997,1.159741,-210.216980,0.116850,0.000000
79.420006,6.590248,-210.216980,0.007136,0.004611,0.117119,29.314888,1.493372,1.171187,-210.216980,0.118133,0.000000
80.190002,6.671051,-210.216980,0.007196,0.004669,0.118593,29.674316,1.511682,1.185933,-210.216980,0.119417,0.000000
80.960007,6.640892,-210.216980,0.007226,0.004710,0.119642,29.540163,1.504848,1.196424,-210.216980,0.120700,0.000000
81.730003,6.788719,-210.261459,0.007282,0.004768,0.121108,30.197731,1.538346,1.211079,-210.261459,0.121984,0.000000
82.500008,6.723557,-210.394897,0.007347,0.004819,0.122391,29.907873,1.523580,1.223914,-210.394897,0.123268,0.000000
83.270004,6.832291,-210.350418,0.007399,0.004867,0.123614,30.391546,1.548219,1.236143,-210.350418,0.124551,0.000000
84.040001,6.853889,-210.350418,0.007455,0.004920,0.124967,30.487623,1.553114,1.249674,-210.350418,0.125835,0.000000
84.810005,6.807343,-210.394897,0.007502,0.004965,0.126103,30.280571,1.542566,1.261032,-210.394897,0.127118,0.000000
85.580002,6.880325,-210.439377,0.007554,0.005016,0.127404,30.605215,1.559104,1.274041,-210.439377,0.128401,0.000000
86.350006,6.920914,-210.483856,0.007601,0.005073,0.128844,30.785761,1.568301,1.288439,-210.483856,0.129685,0.000000
87.120003,7.010284,-210.394897,0.007649,0.005119,0.130032,31.183302,1.588553,1.300320,-210.394897,0.130968,0.000000
87.890007,7.051987,-210.439377,0.007700,0.005171,0.131342,31.368803,1.598003,1.313415,-210.439377,0.132252,0.000000
88.660004,7.015495,-210.528336,0.007748,0.005218,0.132547,31.206482,1.589734,1.325466,-210.528336,0.133535,0.000000
89.430008,7.097794,-210.572815,0.007804,0.005268,0.133813,31.572563,1.608383,1.338131,-210.572815,0.134819,0.000000
90.200005,7.116035,-210.661789,0.007860,0.005324,0.135235,31.653708,1.612517,1.352351,-210.661789,0.136103,0.000000
90.970001,7.142479,-210.528336,0.007907,0.005373,0.136467,31.771334,1.618509,1.364667,-210.528336,0.137386,0.000000
91.740005,7.242271,-210.617310,0.007972,0.005429,0.137906,32.215233,1.641122,1.379061,-210.617310,0.138669,0.000000
92.510002,7.178596,-210.661789,0.008006,0.005476,0.139103,31.931992,1.626693,1.391028,-210.661789,0.139953,0.000000
93.280006,7.276901,-210.661789,0.008067,0.005522,0.140256,32.369274,1.648969,1.402565,-210.661789,0.141236,0.000000
94.050003,7.276527,-210.706268,0.008119,0.005577,0.141653,32.367611,1.648885,1.416527,-210.706268,0.142520,0.000000
94.820007,7.338341,-210.750748,0.008157,0.005628,0.142945,32.642570,1.662892,1.429449,-210.750748,0.143803,0.000000
95.590004,7.406487,-210.839706,0.008213,0.005677,0.144185,32.945698,1.678334,1.441848,-210.839706,0.145087,0.000000
96.360008,7.304832,-210.839706,0.008257,0.005724,0.145382,32.493519,1.655299,1.453816,-210.839706,0.146370,0.000000
97.130005,7.378189,-210.884186,0.008326,0.005774,0.146648,32.819824,1.671921,1.466480,-210.884186,0.147654,0.000000
97.900002,7.348396,-210.839706,0.008364,0.005825,0.147949,32.687298,1.665170,1.479489,-210.839706,0.148938,0.000000
98.670006,7.491020,-210.839706,0.008420,0.005877,0.149284,33.321724,1.697490,1.492842,-210.839706,0.150221,0.000000
99.440002,7.560280,-210.973145,0.008472,0.005934,0.150715,33.629803,1.713184,1.507153,-210.973145,0.151504,0.000000
100.210007,7.436279,-210.884186,0.008524,0.005976,0.151782,33.078224,1.685085,1.517819,-210.884186,0.152788,0.000000
100.980003,7.612411,-210.973145,0.008580,0.006030,0.153152,33.861698,1.724997,1.531520,-210.973145,0.154071,0.000000
101.750008,7.501068,-210.973145,0.008649,0.006079,0.154418,33.366417,1.699766,1.544180,-210.973145,0.155355,0.000000
102.520004,7.593422,-211.017639,0.008683,0.006131,0.155728,33.777229,1.720694,1.557276,-211.017639,0.156638,0.000000
103.290009,7.655609,-211.062119,0.008722,0.006186,0.157115,34.053852,1.734786,1.571151,-211.062119,0.157922,0.000000
104.060005,7.487663,-211.106598,0.008774,0.006230,0.158234,33.306789,1.696729,1.582340,-211.106598,0.159205,0.000000
104.830002,7.605705,-211.062119,0.008826,0.006281,0.159526,33.831867,1.723477,1.595261,-211.062119,0.160489,0.000000
105.600006,7.667152,-211.106598,0.008864,0.006333,0.160871,34.105198,1.737402,1.608705,-211.106598,0.161772,0.000000
106.370003,7.781837,-211.151077,0.008942,0.006386,0.162206,34.615341,1.763390,1.622058,-211.151077,0.163056,0.000000
107.140007,7.725983,-211.195557,0.008994,0.006434,0.163420,34.366886,1.750733,1.634200,-211.195557,0.164339,0.000000
107.910004,7.699921,-211.240036,0.009037,0.006484,0.164686,34.250957,1.744827,1.646861,-211.240036,0.165623,0.000000
108.680008,7.764709,-211.195557,0.009084,0.006530,0.165874,34.539154,1.759508,1.658742,-211.195557,0.166906,0.000000
109.450005,7.809021,-211.284515,0.009145,0.006584,0.167227,34.736259,1.769549,1.672273,-211.284515,0.168190,0.000000
110.220009,7.812744,-211.373474,0.009196,0.006635,0.168537,34.752823,1.770393,1.685368,-211.373474,0.169473,0.000000
110.990005,7.956856,-211.328995,0.009231,0.006690,0.169916,35.393864,1.803049,1.699157,-211.328995,0.170757,0.000000
111.760002,7.921104,-211.373474,0.009274,0.006736,0.171104,35.234833,1.794948,1.711038,-211.373474,0.172040,0.000000
112.530006,7.960205,-211.373474,0.009339,0.006786,0.172352,35.408760,1.803808,1.723524,-211.373474,0.173324,0.000000
113.300003,7.927063,-211.462448,0.009399,0.006839,0.173714,35.261337,1.796298,1.737138,-211.462448,0.174607,0.000000
114.070007,7.966537,-211.506927,0.009455,0.006890,0.174998,35.436928,1.805243,1.749977,-211.506927,0.175891,0.000000
114.840004,8.102081,-211.417953,0.009485,0.006942,0.176316,36.039856,1.835958,1.763155,-211.417953,0.177174,0.000000
115.610008,8.053299,-211.417953,0.009541,0.006991,0.177582,35.822865,1.824904,1.775820,-211.417953,0.178458,0.000000
116.380005,7.985901,-211.417953,0.009597,0.007035,0.178692,35.523060,1.809631,1.786917,-211.417953,0.179741,0.000000
117.150009,8.179535,-211.595886,0.009662,0.007095,0.180201,36.384388,1.853509,1.802007,-211.595886,0.181025,0.000000
117.920006,8.204109,-211.595886,0.009697,0.007145,0.181484,36.493702,1.859078,1.814842,-211.595886,0.182308,0.000000
118.690002,8.051437,-211.551407,0.009735,0.007187,0.182560,35.814583,1.824482,1.825599,-211.551407,0.183592,0.000000
119.460007,8.121445,-211.640366,0.009791,0.007239,0.183878,36.125992,1.840346,1.838778,-211.640366,0.184875,0.000000
120.230003,8.172455,-211.684845,0.009856,0.007289,0.185153,36.352894,1.851905,1.851525,-211.684845,0.186159,0.000000
121.000008,8.258476,-211.684845,0.009916,0.007346,0.186592,36.735538,1.871397,1.865923,-211.684845,0.187442,0.000000
121.770004,8.306137,-211.640366,0.009968,0.007397,0.187884,36.947544,1.882198,1.878845,-211.640366,0.188726,0.000000
122.540009,8.323639,-211.773804,0.010016,0.007447,0.189159,37.025394,1.886164,1.891592,-211.773804,0.190009,0.000000
123.310005,8.252518,-211.773804,0.010050,0.007495,0.190373,36.709034,1.870047,1.903734,-211.773804,0.191293,0.000000
124.080009,8.287895,-211.862762,0.010115,0.007541,0.191544,36.866398,1.878064,1.915441,-211.862762,0.192567,0.000000
124.850006,8.337044,-211.907257,0.010162,0.007598,0.192984,37.085022,1.889201,1.929838,-211.907257,0.193851,0.000000
125.620003,8.407425,-211.818283,0.010205,0.007645,0.194189,37.398094,1.905150,1.941893,-211.818283,0.195134,0.000000
126.390007,8.453972,-211.818283,0.010261,0.007697,0.195516,37.605145,1.915697,1.955159,-211.818283,0.196418,0.000000
127.160004,8.387688,-211.907257,0.010322,0.007747,0.196782,37.310299,1.900677,1.967824,-211.907257,0.197701,0.000000
127.930008,8.462906,-211.951736,0.010365,0.007798,0.198066,37.644886,1.917722,1.980658,-211.951736,0.198985,0.000000
128.700012,8.539246,-211.951736,0.010430,0.007851,0.199419,37.984463,1.935021,1.994185,-211.951736,0.200268,0.000000
129.470001,8.526955,-211.951736,0.010464,0.007899,0.200633,37.929790,1.932235,2.006327,-211.951736,0.201552,0.000000
130.240005,8.639786,-211.996216,0.010507,0.007950,0.201925,38.431686,1.957803,2.019249,-211.996216,0.202836,0.000000
131.010010,8.563820,-212.040695,0.010559,0.007998,0.203148,38.093773,1.940589,2.031478,-212.040695,0.204119,0.000000
131.779999,8.603668,-212.040695,0.010619,0.008049,0.204448,38.271027,1.949619,2.044483,-212.040695,0.205402,0.000000
132.550003,8.676651,-212.085175,0.010675,0.008101,0.205767,38.595673,1.966157,2.057666,-212.085175,0.206686,0.000000
133.320007,8.680000,-212.129654,0.010723,0.008154,0.207120,38.610569,1.966916,2.071197,-212.129654,0.207969,0.000000
134.090012,8.818893,-212.174133,0.010779,0.008207,0.208446,39.228397,1.998390,2.084463,-212.174133,0.209253,0.000000
134.860001,8.680748,-212.174133,0.010831,0.008253,0.209617,38.613895,1.967086,2.096173,-212.174133,0.210536,0.000000
135.630005,8.766762,-212.174133,0.010874,0.008303,0.210901,38.996506,1.986577,2.109008,-212.174133,0.211820,0.000000
136.400009,8.822250,-212.218613,0.010925,0.008358,0.212288,39.243328,1.999151,2.122883,-212.218613,0.213103,0.000000
137.170013,8.856133,-212.263092,0.010981,0.008405,0.213485,39.394043,2.006828,2.134851,-212.263092,0.214387,0.000000
137.940002,8.857620,-212.352066,0.011029,0.008454,0.214725,39.400661,2.007165,2.147250,-212.352066,0.215670,0.000000
138.710007,8.917946,-212.307587,0.011076,0.008505,0.216026,39.669003,2.020835,2.160259,-212.307587,0.216954,0.000000
139.480011,8.904915,-212.352066,0.011141,0.008557,0.217335,39.611038,2.017883,2.173355,-212.352066,0.218237,0.000000
140.250000,9.015884,-212.396545,0.011193,0.008609,0.218662,40.104656,2.043029,2.186625,-212.396545,0.219521,0.000000
141.020004,8.897842,-212.441025,0.011223,0.008651,0.219729,39.579578,2.016280,2.197290,-212.441025,0.220804,0.000000
141.790009,8.994286,-212.529984,0.011275,0.008704,0.221082,40.008579,2.038134,2.210818,-212.529984,0.222088,0.000000
142.560013,9.025192,-212.529984,0.011344,0.008759,0.222478,40.146061,2.045138,2.224780,-212.529984,0.223371,0.000000
143.330002,8.996521,-212.441025,0.011382,0.008805,0.223649,40.018524,2.038641,2.236487,-212.441025,0.224655,0.000000
144.100006,9.092964,-212.529984,0.011443,0.008860,0.225054,40.447525,2.060495,2.250536,-212.529984,0.225938,0.000000
144.870010,9.078072,-212.574463,0.011477,0.008906,0.226216,40.381279,2.057120,2.262160,-212.574463,0.227222,0.000000
145.639999,9.211380,-212.618942,0.011533,0.008958,0.227534,40.974266,2.087328,2.275339,-212.618942,0.228505,0.000000
146.410004,9.208397,-212.574463,0.011589,0.009013,0.228939,40.960995,2.086653,2.289388,-212.574463,0.229789,0.000000
147.180008,9.254944,-212.618942,0.011637,0.009060,0.230118,41.168045,2.097200,2.301182,-212.618942,0.231072,0.000000
147.950012,9.282875,-212.663422,0.011697,0.009112,0.231454,41.292290,2.103530,2.314539,-212.663422,0.232356,0.000000
148.720001,9.232605,-212.752396,0.011727,0.009160,0.232659,41.068680,2.092138,2.326594,-212.752396,0.233639,0.000000
149.490005,9.294792,-212.752396,0.011796,0.009209,0.233908,41.345299,2.106230,2.339080,-212.752396,0.234923,0.000000
150.260010,9.323463,-212.796875,0.011857,0.009266,0.235365,41.472836,2.112727,2.353652,-212.796875,0.236206,0.000000
151.030014,9.422142,-212.707901,0.011891,0.009313,0.236553,41.911781,2.135088,2.365533,-212.707901,0.237490,0.000000
151.800003,9.477249,-212.796875,0.011956,0.009365,0.237871,42.156910,2.147575,2.378712,-212.796875,0.238773,0.000000
152.570007,9.365913,-212.885834,0.012003,0.009409,0.238999,41.661663,2.122346,2.389987,-212.885834,0.240057,0.000000
153.340012,9.521561,-212.885834,0.012051,0.009464,0.240378,42.354015,2.157616,2.403775,-212.885834,0.241340,0.000000
154.110001,9.534973,-212.841354,0.012102,0.009518,0.241765,42.413677,2.160656,2.417651,-212.841354,0.242624,0.000000
154.880005,9.573326,-212.930313,0.012141,0.009566,0.242979,42.584282,2.169347,2.429793,-212.930313,0.243907,0.000000
155.650009,9.669769,-212.974792,0.012197,0.009623,0.244436,43.013283,2.191201,2.444361,-212.974792,0.245191,0.000000
156.420013,9.579285,-212.974792,0.012253,0.009671,0.245633,42.610786,2.170697,2.456329,-212.974792,0.246474,0.000000
157.190002,9.683548,-212.930313,0.012296,0.009716,0.246795,43.074574,2.194323,2.467952,-212.930313,0.247758,0.000000
157.960007,9.625084,-213.019272,0.012357,0.009767,0.248087,42.814510,2.181075,2.480874,-213.019272,0.249041,0.000000
158.730011,9.769196,-213.063751,0.012409,0.009821,0.249458,43.455551,2.213731,2.494575,-213.063751,0.250325,0.000000
159.500000,9.874947,-213.063751,0.012469,0.009872,0.250758,43.925957,2.237695,2.507584,-213.063751,0.251608,0.000000
160.270004,9.684288,-213.108231,0.012503,0.009915,0.251842,43.077866,2.194491,2.518424,-213.108231,0.252892,0.000000
161.040009,9.817230,-213.108231,0.012555,0.009968,0.253186,43.669220,2.224616,2.531864,-213.108231,0.254175,0.000000
161.810013,9.810524,-213.152710,0.012607,0.010020,0.254513,43.639389,2.223096,2.545134,-213.152710,0.255459,0.000000
162.580002,9.914413,-213.197205,0.012654,0.010070,0.255788,44.101513,2.246638,2.557881,-213.197205,0.256742,0.000000
163.350006,9.937508,-213.241684,0.012702,0.010121,0.257063,44.204243,2.251871,2.570629,-213.241684,0.258026,0.000000
164.120010,9.945320,-213.241684,0.012758,0.010171,0.258347,44.238995,2.253642,2.583467,-213.241684,0.259309,0.000000
164.890015,10.048470,-213.241684,0.012810,0.010221,0.259604,44.697826,2.277016,2.596040,-213.241684,0.260593,0.000000
165.660004,10.047729,-213.286163,0.012853,0.010275,0.260992,44.694534,2.276848,2.609916,-213.286163,0.261876,0.000000
166.430008,10.152733,-213.375122,0.012909,0.010323,0.262214,45.161610,2.300642,2.622145,-213.375122,0.263160,0.000000
167.200012,10.246948,-213.375122,0.012965,0.010379,0.263628,45.580704,2.321992,2.636278,-213.375122,0.264443,0.000000
167.970001,10.003410,-213.330643,0.013016,0.010421,0.264686,44.497391,2.266805,2.646860,-213.330643,0.265727,0.000000
168.740005,10.086823,-213.419601,0.013055,0.010467,0.265874,44.868427,2.285707,2.658741,-213.419601,0.267010,0.000000
169.510010,10.260727,-213.419601,0.013111,0.010529,0.267426,45.641994,2.325114,2.674263,-213.419601,0.268294,0.000000
170.280014,10.326630,-213.464081,0.013150,0.010578,0.268675,45.935143,2.340048,2.686753,-213.464081,0.269577,0.000000
171.050003,10.379883,-213.419601,0.013219,0.010627,0.269933,46.172024,2.352115,2.699327,-213.419601,0.270861,0.000000
171.820007,10.321419,-213.508560,0.013279,0.010677,0.271207,45.911964,2.338867,2.712074,-213.508560,0.272144,0.000000
172.590012,10.398499,-213.508560,0.013310,0.010725,0.272413,46.254833,2.356333,2.724129,-213.508560,0.273428,0.000000
173.360001,10.434990,-213.686493,0.013374,0.010778,0.273766,46.417152,2.364602,2.737660,-213.686493,0.274711,0.000000
174.130005,10.410042,-213.642014,0.013426,0.010824,0.274928,46.306179,2.358949,2.749279,-213.642014,0.275995,0.000000
174.900009,10.608521,-213.597534,0.013473,0.010882,0.276402,47.189056,2.403925,2.764022,-213.597534,0.277278,0.000000
175.670013,10.589531,-213.597534,0.013525,0.010931,0.277660,47.104588,2.399622,2.776595,-213.597534,0.278561,0.000000
176.440002,10.581711,-213.686493,0.013581,0.010980,0.278882,47.069801,2.397850,2.788824,-213.686493,0.279845,0.000000
177.210007,10.597351,-213.730972,0.013637,0.011033,0.280235,47.139374,2.401394,2.802351,-213.730972,0.281129,0.000000
177.980011,10.647621,-213.730972,0.013672,0.011083,0.281510,47.362984,2.412786,2.815103,-213.730972,0.282412,0.000000
178.750015,10.881096,-213.775452,0.013724,0.011137,0.282880,48.401531,2.465692,2.828804,-213.775452,0.283696,0.000000
179.520004,10.826729,-213.775452,0.013784,0.011188,0.284173,48.159695,2.453372,2.841726,-213.775452,0.284979,0.000000
180.290009,10.713158,-213.864410,0.013831,0.011229,0.285222,47.654507,2.427636,2.852217,-213.864410,0.286263,0.000000
181.060013,10.814812,-213.864410,0.013887,0.011281,0.286531,48.106686,2.450671,2.865313,-213.864410,0.287546,0.000000
181.830002,10.990204,-213.819931,0.013961,0.011337,0.287962,48.886868,2.490416,2.879624,-213.819931,0.288830,0.000000
182.600006,11.061325,-213.908890,0.013987,0.011385,0.289168,49.203232,2.506532,2.891679,-213.908890,0.290113,0.000000
183.370010,10.921684,-213.953369,0.014030,0.011434,0.290417,48.582077,2.474889,2.904165,-213.953369,0.291396,0.000000
184.140015,10.953339,-213.997849,0.014094,0.011482,0.291631,48.722885,2.482062,2.916307,-213.997849,0.292680,0.000000
184.910004,11.074730,-214.042343,0.014146,0.011539,0.293088,49.262859,2.509570,2.930875,-214.042343,0.293963,0.000000
185.680008,11.116066,-213.997849,0.014202,0.011586,0.294284,49.446732,2.518936,2.942843,-213.997849,0.295247,0.000000
186.450012,11.298897,-214.042343,0.014241,0.011640,0.295646,50.260002,2.560367,2.956461,-214.042343,0.296531,0.000000
187.220016,11.114944,-214.086823,0.014297,0.011688,0.296877,49.441742,2.518682,2.968773,-214.086823,0.297814,0.000000
187.990005,11.206551,-214.131302,0.014331,0.011735,0.298074,49.849228,2.539441,2.980741,-214.131302,0.299098,0.000000
188.760010,11.244530,-214.086823,0.014400,0.011791,0.299496,50.018166,2.548047,2.994965,-214.086823,0.300381,0.000000
189.530014,11.216232,-214.131302,0.014444,0.011834,0.300589,49.892292,2.541635,3.005892,-214.131302,0.301664,0.000000
190.300003,11.425507,-214.220261,0.014482,0.011891,0.302020,50.823193,2.589057,3.020199,-214.220261,0.302948,0.000000
191.070007,11.367043,-214.220261,0.014560,0.011941,0.303304,50.563129,2.575809,3.033037,-214.220261,0.304231,0.000000
191.840012,11.379333,-214.220261,0.014590,0.011988,0.304483,50.617802,2.578594,3.044831,-214.220261,0.305515,0.000000
192.610016,11.495140,-214.220261,0.014651,0.012044,0.305914,51.132938,2.604836,3.059138,-214.220261,0.306798,0.000000
193.380005,11.410980,-214.264740,0.014702,0.012090,0.307076,50.758575,2.585765,3.070761,-214.264740,0.308082,0.000000
194.150009,11.488434,-214.398178,0.014741,0.012137,0.308273,51.103107,2.603316,3.082729,-214.398178,0.309366,0.000000
194.920013,11.631798,-214.398178,0.014789,0.012192,0.309686,51.740822,2.635803,3.096862,-214.398178,0.310649,0.000000
195.690002,11.727867,-214.353699,0.014849,0.012242,0.310953,52.168159,2.657573,3.109526,-214.353699,0.311933,0.000000
196.460007,11.804581,-214.442657,0.014901,0.012297,0.312331,52.509396,2.674956,3.123314,-214.442657,0.313216,0.000000
197.230011,11.825432,-214.487152,0.014952,0.012349,0.313658,52.602146,2.679681,3.136580,-214.487152,0.314499,0.000000
198.000015,11.964325,-214.531631,0.015013,0.012402,0.315002,53.219975,2.711155,3.150024,-214.531631,0.315783,0.000000
198.770004,11.832878,-214.442657,0.015060,0.012447,0.316164,52.635269,2.681369,3.161644,-214.442657,0.317066,0.000000
199.540009,11.971405,-214.576111,0.015112,0.012499,0.317465,53.251469,2.712759,3.174653,-214.576111,0.318350,0.000000
200.310013,11.971031,-214.576111,0.015155,0.012549,0.318749,53.249805,2.712674,3.187487,-214.576111,0.319633,0.000000
201.080017,11.977730,-214.620590,0.015189,0.012599,0.320015,53.279602,2.714192,3.200151,-214.620590,0.320917,0.000000
201.850006,12.004173,-214.620590,0.015254,0.012644,0.321168,53.397228,2.720184,3.211684,-214.620590,0.322201,0.000000
202.620010,12.204506,-214.665070,0.015310,0.012700,0.322573,54.288353,2.765581,3.225734,-214.665070,0.323484,0.000000
203.390015,12.192589,-214.665070,0.015366,0.012752,0.323892,54.235344,2.762880,3.238916,-214.665070,0.324767,0.000000
204.160004,12.334465,-214.754028,0.015409,0.012803,0.325184,54.866440,2.795030,3.251838,-214.754028,0.326051,0.000000
204.930008,12.178444,-214.709549,0.015457,0.012845,0.326268,54.172424,2.759675,3.262678,-214.709549,0.327334,0.000000
205.700012,12.208977,-214.798508,0.015504,0.012893,0.327490,54.308243,2.766594,3.274903,-214.798508,0.328618,0.000000
206.470016,12.343399,-214.798508,0.015560,0.012953,0.329008,54.906181,2.797054,3.290081,-214.798508,0.329901,0.000000
207.240005,12.314354,-214.842987,0.015603,0.012998,0.330162,54.776981,2.790473,3.301617,-214.842987,0.331185,0.000000
208.010010,12.434631,-214.842987,0.015668,0.013054,0.331575,55.312004,2.817728,3.315750,-214.842987,0.332468,0.000000
208.780014,12.437241,-214.931961,0.015707,0.013100,0.332737,55.323608,2.818319,3.327373,-214.931961,0.333752,0.000000
209.550003,12.547462,-214.887482,0.015767,0.013148,0.333951,55.813900,2.843296,3.339511,-214.887482,0.335036,0.000000
210.320007,12.477455,-214.976440,0.015832,0.013204,0.335382,55.502491,2.827432,3.353822,-214.976440,0.336319,0.000000
211.090012,12.621567,-214.976440,0.015866,0.013250,0.336562,56.143532,2.860088,3.365616,-214.976440,0.337602,0.000000
211.860016,12.687843,-215.065399,0.015927,0.013305,0.337940,56.438347,2.875106,3.379404,-215.065399,0.338886,0.000000
212.630005,12.517303,-215.065399,0.015974,0.013352,0.339146,55.679749,2.836461,3.391459,-215.065399,0.340169,0.000000
213.400009,12.787643,-215.065399,0.016013,0.013403,0.340447,56.882278,2.897722,3.404468,-215.065399,0.341453,0.000000
214.170013,12.764557,-215.109879,0.016082,0.013459,0.341852,56.779583,2.892490,3.418517,-215.109879,0.342736,0.000000
214.940018,12.908661,-215.154358,0.016138,0.013504,0.343005,57.420593,2.925144,3.430050,-215.154358,0.344011,0.000000
215.710007,12.980904,-215.198837,0.016181,0.013558,0.344375,57.741943,2.941515,3.443755,-215.198837,0.345294,0.000000
216.480011,12.921700,-215.109879,0.016220,0.013605,0.345572,57.478592,2.928099,3.455723,-215.109879,0.346578,0.000000
217.250015,12.942551,-215.243317,0.016280,0.013656,0.346864,57.571342,2.932824,3.468644,-215.243317,0.347862,0.000000
218.020004,13.111977,-215.287796,0.016328,0.013711,0.348269,58.324986,2.971216,3.482690,-215.287796,0.349145,0.000000
218.790009,13.096336,-215.287796,0.016388,0.013761,0.349527,58.255413,2.967672,3.495267,-215.287796,0.350429,0.000000
219.560013,13.237099,-215.332291,0.016431,0.013816,0.350923,58.881557,2.999569,3.509230,-215.332291,0.351712,0.000000
220.330017,13.152939,-215.287796,0.016483,0.013863,0.352111,58.507195,2.980499,3.521111,-215.287796,0.352996,0.000000
221.100006,13.051659,-215.287796,0.016526,0.013905,0.353195,58.056679,2.957548,3.531950,-215.287796,0.354279,0.000000
221.870010,13.251991,-215.376770,0.016586,0.013961,0.354609,58.947800,3.002944,3.546087,-215.376770,0.355562,0.000000
222.640015,13.434082,-215.376770,0.016625,0.014014,0.355953,59.757782,3.044206,3.559527,-215.376770,0.356846,0.000000
223.410004,13.472435,-215.332291,0.016681,0.014062,0.357167,59.928383,3.052897,3.571669,-215.332291,0.358129,0.000000
224.180008,13.360725,-215.465729,0.016729,0.014108,0.358346,59.431477,3.027584,3.583463,-215.465729,0.359413,0.000000
224.950012,13.450096,-215.465729,0.016785,0.014160,0.359656,59.829014,3.047835,3.596559,-215.465729,0.360697,0.000000
225.720016,13.656387,-215.510208,0.016841,0.014214,0.361043,60.746643,3.094582,3.610434,-215.510208,0.361980,0.000000
226.490005,13.708519,-215.510208,0.016901,0.014262,0.362249,60.978539,3.106395,3.622489,-215.510208,0.363264,0.000000
227.260010,13.825821,-215.510208,0.016953,0.014314,0.363576,61.500324,3.132976,3.635759,-215.510208,0.364547,0.000000
228.030014,13.763634,-215.554687,0.017000,0.014365,0.364859,61.223701,3.118884,3.648593,-215.554687,0.365831,0.000000
228.800018,13.752831,-215.599167,0.017030,0.014409,0.365978,61.175644,3.116436,3.659778,-215.599167,0.367114,0.000000
229.570007,14.058548,-215.643646,0.017095,0.014469,0.367513,62.535545,3.185713,3.675129,-215.643646,0.368397,0.000000
230.340012,14.141586,-215.643646,0.017143,0.014515,0.368684,62.904919,3.204529,3.686836,-215.643646,0.369681,0.000000
231.110016,14.566467,-215.688126,0.017199,0.014574,0.370184,64.794884,3.300809,3.701839,-215.688126,0.370964,0.000000
231.880005,14.158348,-215.777100,0.017242,0.014615,0.371216,62.979477,3.208328,3.712161,-215.777100,0.372248,0.000000
232.650009,14.184036,-215.777100,0.017306,0.014662,0.372422,63.093746,3.214149,3.724216,-215.777100,0.373531,0.000000
233.420013,14.564232,-215.777100,0.017362,0.014723,0.373956,64.784943,3.300302,3.739563,-215.777100,0.374815,0.000000
234.190018,14.410439,-215.777100,0.017401,0.014768,0.375101,64.100830,3.265452,3.751013,-215.777100,0.376099,0.000000
234.960007,14.874420,-215.866058,0.017440,0.014822,0.376489,66.164726,3.370592,3.764888,-215.866058,0.377382,0.000000
235.730011,14.551201,-215.910538,0.017492,0.014870,0.377703,64.726974,3.297349,3.777030,-215.910538,0.378665,0.000000
236.500015,14.840904,-215.866058,0.017544,0.014917,0.378891,66.015640,3.362997,3.788911,-215.866058,0.379949,0.000000
237.270004,15.006981,-215.910538,0.017591,0.014971,0.380261,66.754387,3.400630,3.802612,-215.910538,0.381232,0.000000
238.040009,15.037514,-215.910538,0.017651,0.015018,0.381467,66.890205,3.407549,3.814667,-215.910538,0.382516,0.000000
238.810013,15.378609,-215.999496,0.017699,0.015075,0.382906,68.407471,3.484843,3.829061,-215.999496,0.383799,0.000000
239.580017,15.386803,-216.043976,0.017759,0.015126,0.384207,68.443916,3.486699,3.842070,-216.043976,0.385083,0.000000
240.350006,15.362968,-215.999496,0.017794,0.015172,0.385378,68.337898,3.481298,3.853776,-215.999496,0.386366,0.000000
241.120010,15.595329,-215.999496,0.017841,0.015228,0.386783,69.371490,3.533952,3.867826,-215.999496,0.387650,0.000000
241.890015,15.729012,-216.132935,0.017901,0.015278,0.388066,69.966141,3.564245,3.880660,-216.132935,0.388934,0.000000
242.660019,16.063034,-216.088455,0.017953,0.015329,0.389358,71.451942,3.639936,3.893582,-216.088455,0.390217,0.000000
243.430008,15.853012,-216.132935,0.018001,0.015377,0.390564,70.517723,3.592344,3.905637,-216.132935,0.391500,0.000000
244.200012,16.095802,-216.132935,0.018039,0.015425,0.391787,71.597702,3.647361,3.917866,-216.132935,0.392784,0.000000
244.970016,16.226501,-216.266388,0.018095,0.015476,0.393079,72.179085,3.676978,3.930788,-216.266388,0.394067,0.000000
245.740005,16.598503,-216.221909,0.018134,0.015529,0.394440,73.833832,3.761275,3.944402,-216.221909,0.395351,0.000000
246.510010,16.750427,-216.221909,0.018208,0.015579,0.395698,74.509621,3.795701,3.956979,-216.221909,0.396634,0.000000
247.280014,16.608559,-216.221909,0.018251,0.015627,0.396929,73.878555,3.763553,3.969291,-216.221909,0.397918,0.000000
248.050018,16.798836,-216.221909,0.018289,0.015675,0.398143,74.724953,3.806671,3.981433,-216.221909,0.399201,0.000000
248.820007,17.145149,-216.355347,0.018354,0.015731,0.399557,76.265434,3.885146,3.995570,-216.355347,0.400485,0.000000
249.590012,17.275101,-216.399826,0.018393,0.015780,0.400806,76.843483,3.914594,4.008056,-216.399826,0.401768,0.000000
250.360016,17.647850,-216.399826,0.018458,0.015834,0.402184,78.501556,3.999060,4.021844,-216.399826,0.403052,0.000000
251.130005,17.411018,-216.399826,0.018483,0.015880,0.403355,77.448074,3.945393,4.033555,-216.399826,0.404335,0.000000
251.900009,17.675034,-216.444305,0.018544,0.015930,0.404622,78.622475,4.005220,4.046216,-216.444305,0.405619,0.000000
252.670013,17.963623,-216.488785,0.018596,0.015984,0.406000,79.906189,4.070615,4.060004,-216.488785,0.406902,0.000000
253.440018,17.959900,-216.533264,0.018647,0.016030,0.407171,79.889626,4.069772,4.071711,-216.533264,0.408186,0.000000
254.210007,18.454033,-216.488785,0.018690,0.016084,0.408524,82.087639,4.181744,4.085241,-216.488785,0.409469,0.000000
254.980011,18.560532,-216.533264,0.018734,0.016135,0.409833,82.561371,4.205876,4.098333,-216.533264,0.410753,0.000000
255.750015,18.637611,-216.622238,0.018777,0.016180,0.410978,82.904236,4.223343,4.109783,-216.622238,0.412036,0.000000
256.520020,19.026375,-216.666718,0.018850,0.016237,0.412409,84.633545,4.311439,4.124094,-216.666718,0.413320,0.000000
257.290009,19.009613,-216.666718,0.018906,0.016282,0.413571,84.558983,4.307640,4.135713,-216.666718,0.414603,0.000000
258.059998,19.236763,-216.622238,0.018932,0.016331,0.414803,85.569397,4.359113,4.148029,-216.622238,0.415887,0.000000
258.830017,19.674675,-216.666718,0.018988,0.016387,0.416225,87.517326,4.458345,4.162249,-216.666718,0.417170,0.000000
259.600006,19.839630,-216.711197,0.019044,0.016437,0.417491,88.251083,4.495724,4.174913,-216.711197,0.418454,0.000000
260.370026,20.167694,-216.711197,0.019100,0.016489,0.418809,89.710381,4.570065,4.188092,-216.711197,0.419737,0.000000
261.140015,20.228760,-216.755676,0.019156,0.016536,0.420023,89.982018,4.583902,4.200234,-216.755676,0.421021,0.000000
261.910004,20.854347,-216.844635,0.019208,0.016593,0.421454,92.764771,4.725663,4.214545,-216.844635,0.422304,0.000000
262.680023,20.658478,-216.844635,0.019251,0.016640,0.422660,91.893501,4.681278,4.226600,-216.844635,0.423588,0.000000
263.450012,21.042770,-216.933594,0.019294,0.016691,0.423952,93.602921,4.768360,4.239522,-216.933594,0.424871,0.000000
264.220001,21.508232,-216.844635,0.019341,0.016742,0.425253,95.673393,4.873835,4.252526,-216.844635,0.426155,0.000000
264.990021,21.459450,-216.933594,0.019393,0.016789,0.426449,95.456398,4.862781,4.264494,-216.933594,0.427438,0.000000
265.760010,21.718254,-216.933594,0.019432,0.016837,0.427664,96.607620,4.921427,4.276636,-216.933594,0.428722,0.000000
266.529999,22.118927,-216.978073,0.019488,0.016891,0.429034,98.389900,5.012220,4.290338,-216.978073,0.430005,0.000000
267.300018,22.727379,-217.022568,0.019540,0.016945,0.430396,101.096428,5.150098,4.303956,-217.022568,0.431289,0.000000
268.070007,23.015968,-217.022568,0.019596,0.016995,0.431679,102.380142,5.215493,4.316790,-217.022568,0.432572,0.000000
268.840027,22.926231,-217.067047,0.019617,0.017038,0.432772,101.980972,5.195158,4.327717,-217.067047,0.433856,0.000000
269.610016,23.363396,-217.156006,0.019665,0.017088,0.434038,103.925575,5.294221,4.340377,-217.156006,0.435139,0.000000
270.380005,23.869446,-217.111526,0.019725,0.017148,0.435547,106.176598,5.408894,4.355468,-217.111526,0.436423,0.000000
271.150024,24.016907,-217.156006,0.019773,0.017192,0.436666,106.832535,5.442309,4.366656,-217.156006,0.437706,0.000000
271.920013,24.709892,-217.156006,0.019824,0.017249,0.438122,109.915092,5.599341,4.381224,-217.156006,0.438990,0.000000
272.690002,24.461891,-217.156006,0.019872,0.017290,0.439163,108.811928,5.543144,4.391633,-217.156006,0.440273,0.000000
273.460022,25.022316,-217.244965,0.019911,0.017342,0.440481,111.304817,5.670138,4.404811,-217.244965,0.441557,0.000000
274.230011,25.440483,-217.289444,0.019967,0.017396,0.441869,113.164917,5.764896,4.418687,-217.289444,0.442840,0.000000
275.000000,26.107033,-217.244965,0.020023,0.017446,0.443135,116.129883,5.915938,4.431351,-217.244965,0.444124,0.000000
275.770020,26.504356,-217.289444,0.020070,0.017499,0.444470,117.897263,6.005973,4.444705,-217.289444,0.445407,0.000000
276.540009,26.574364,-217.289444,0.020100,0.017545,0.445633,118.208672,6.021837,4.456328,-217.289444,0.446691,0.000000
277.310028,27.176117,-217.378403,0.020148,0.017595,0.446925,120.885406,6.158196,4.469249,-217.378403,0.447974,0.000000
278.080017,27.757385,-217.333923,0.020212,0.017652,0.448373,123.471016,6.289913,4.483730,-217.333923,0.449258,0.000000
278.850006,28.034058,-217.333923,0.020243,0.017697,0.449509,124.701714,6.352608,4.495093,-217.333923,0.450541,0.000000
279.620026,28.929245,-217.422882,0.020303,0.017753,0.450923,128.683716,6.555461,4.509225,-217.422882,0.451824,0.000000
280.390015,29.058830,-217.467377,0.020333,0.017800,0.452119,129.260132,6.584825,4.521194,-217.467377,0.453108,0.000000
281.160004,29.514610,-217.511856,0.020402,0.017847,0.453316,131.287537,6.688107,4.533161,-217.511856,0.454391,0.000000
281.930023,30.265320,-217.467377,0.020445,0.017905,0.454782,134.626862,6.858220,4.547820,-217.467377,0.455675,0.000000
282.700012,30.654816,-217.556335,0.020484,0.017951,0.455944,136.359436,6.946480,4.559440,-217.556335,0.456959,0.000000
283.470001,31.437920,-217.645294,0.020540,0.018006,0.457340,139.842850,7.123935,4.573402,-217.645294,0.458242,0.000000
284.240021,32.106323,-217.645294,0.020587,0.018057,0.458658,142.816055,7.275397,4.586585,-217.645294,0.459526,0.000000
285.010010,32.099625,-217.556335,0.020631,0.018098,0.459682,142.786255,7.273879,4.596816,-217.556335,0.460809,0.000000
285.779999,33.020500,-217.645294,0.020691,0.018153,0.461095,146.882523,7.482553,4.610952,-217.645294,0.462093,0.000000
286.550018,32.967621,-217.734253,0.020713,0.018186,0.461919,146.647308,7.470570,4.619192,-217.734253,0.462136,0.000000
287.320007,31.512016,-217.689774,0.020725,0.018167,0.461434,140.172455,7.140725,4.614336,-217.689774,0.461225,0.000000
288.090027,30.787010,-217.778732,0.020734,0.018122,0.460289,136.947464,6.976436,4.602887,-217.778732,0.459942,0.000000
288.860016,30.306274,-217.778732,0.020743,0.018073,0.459049,134.809036,6.867500,4.590487,-217.778732,0.458658,0.000000
289.630005,29.949921,-217.778732,0.020743,0.018024,0.457800,133.223907,6.786749,4.577997,-217.778732,0.457375,0.000000
290.400024,29.621483,-217.867691,0.020751,0.017971,0.456456,131.762939,6.712324,4.564557,-217.867691,0.456091,0.000000
291.170013,29.247253,-217.912186,0.020747,0.017932,0.455484,130.098282,6.627522,4.554845,-217.912186,0.454808,0.000000
291.940002,28.193062,-217.867691,0.020738,0.017880,0.454157,125.409004,6.388639,4.541575,-217.867691,0.453524,0.000000
292.710022,26.287636,-217.912186,0.020747,0.017831,0.452917,116.933243,5.956863,4.529172,-217.912186,0.452241,0.000000
293.480011,23.955467,-217.956665,0.020734,0.017791,0.451894,106.559242,5.428386,4.518941,-217.956665,0.450957,0.000000
294.250000,20.434311,-218.001144,0.020717,0.017738,0.450550,90.896355,4.630481,4.505497,-218.001144,0.449674,0.000000
295.020020,16.843155,-218.045624,0.020687,0.017689,0.449301,74.922096,3.816713,4.493011,-218.045624,0.448390,0.000000
295.790009,13.205818,-218.045624,0.020661,0.017638,0.448009,58.742413,2.992481,4.480089,-218.045624,0.447107,0.000000
296.560028,9.929314,-218.045624,0.020622,0.017589,0.446760,44.167793,2.250015,4.467599,-218.045624,0.445824,0.000000
297.330017,6.447998,-218.134583,0.020575,0.017533,0.445329,28.682127,1.461137,4.453292,-218.134583,0.444540,0.000000
298.100006,4.155678,-218.134583,0.020544,0.017486,0.444149,18.485378,0.941690,4.441495,-218.134583,0.443256,0.000000
298.870026,2.611450,-218.179062,0.020523,0.017444,0.443074,11.616311,0.591763,4.430742,-218.179062,0.441973,0.000000
299.640015,1.548698,-218.134583,0.020462,0.017388,0.441661,6.888955,0.350940,4.416605,-218.134583,0.440689,0.000000
300.410004,1.093285,-218.223541,0.020406,0.017329,0.440161,4.863173,0.247742,4.401606,-218.223541,0.439406,0.000000
301.180023,1.065361,-218.268021,0.020359,0.017279,0.438877,4.738963,0.241414,4.388767,-218.268021,0.438122,0.000000
301.950012,1.018814,-218.268021,0.020324,0.017237,0.437810,4.531911,0.230867,4.378101,-218.268021,0.436839,0.000000
302.720001,0.954018,-218.179062,0.020273,0.017187,0.436544,4.243682,0.216183,4.365441,-218.179062,0.435555,0.000000
303.490021,0.843422,-218.356995,0.020217,0.017134,0.435208,3.751728,0.191122,4.352084,-218.356995,0.434272,0.000000
304.260010,0.720169,-218.356995,0.020156,0.017075,0.433708,3.203472,0.163193,4.337081,-218.356995,0.432989,0.000000
305.030029,0.658356,-218.401474,0.020100,0.017026,0.432451,2.928513,0.149186,4.324507,-218.401474,0.431705,0.000000
305.800018,0.595421,-218.356995,0.020061,0.016983,0.431367,2.648564,0.134924,4.313667,-218.356995,0.430421,0.000000
306.570007,0.542549,-218.356995,0.020010,0.016927,0.429953,2.413379,0.122943,4.299531,-218.356995,0.429138,0.000000
307.340027,0.502701,-218.445953,0.019945,0.016877,0.428670,2.236125,0.113914,4.286696,-218.445953,0.427854,0.000000
308.110016,0.433067,-218.490433,0.019915,0.016823,0.427308,1.926380,0.098134,4.273082,-218.490433,0.426571,0.000000
308.880005,0.408493,-218.534912,0.019863,0.016774,0.426059,1.817068,0.092566,4.260592,-218.534912,0.425287,0.000000
309.650024,0.399185,-218.490433,0.019824,0.016729,0.424923,1.775664,0.090457,4.249233,-218.490433,0.424004,0.000000
310.420013,0.380196,-218.534912,0.019764,0.016674,0.423527,1.691195,0.086154,4.235271,-218.534912,0.422721,0.000000
311.190002,0.354500,-218.668350,0.019704,0.016623,0.422218,1.576894,0.080331,4.222175,-218.668350,0.421437,0.000000
311.960022,0.341835,-218.623871,0.019665,0.016570,0.420882,1.520558,0.077461,4.208818,-218.623871,0.420154,0.000000
312.730011,0.348541,-218.623871,0.019613,0.016531,0.419876,1.550389,0.078981,4.198762,-218.623871,0.418870,0.000000
313.500000,0.313911,-218.623871,0.019557,0.016472,0.418393,1.396348,0.071133,4.183929,-218.623871,0.417587,0.000000
314.270020,0.316513,-218.668350,0.019505,0.016424,0.417162,1.407920,0.071723,4.171617,-218.668350,0.416303,0.000000
315.040009,0.313538,-218.757324,0.019449,0.016376,0.415947,1.394685,0.071049,4.159475,-218.757324,0.415019,0.000000
315.810028,0.320610,-218.712830,0.019410,0.016325,0.414664,1.426145,0.072651,4.146640,-218.712830,0.413736,0.000000
316.580017,0.312424,-218.757324,0.019354,0.016272,0.413303,1.389730,0.070796,4.133026,-218.757324,0.412452,0.000000
317.350006,0.294922,-218.757324,0.019320,0.016224,0.412080,1.311878,0.066830,4.120797,-218.757324,0.411169,0.000000
318.120026,0.316147,-218.801804,0.019255,0.016173,0.410796,1.406291,0.071640,4.107962,-218.801804,0.409886,0.000000
318.890015,0.276299,-218.890762,0.019195,0.016119,0.409417,1.229037,0.062610,4.094174,-218.890762,0.408602,0.000000
319.660004,0.286728,-218.890762,0.019152,0.016066,0.408064,1.275429,0.064973,4.080643,-218.890762,0.407319,0.000000
320.430023,0.304604,-218.890762,0.019109,0.016024,0.406998,1.354944,0.069024,4.069977,-218.890762,0.406035,0.000000
321.200012,0.261406,-218.890762,0.019040,0.015971,0.405671,1.162792,0.059235,4.056707,-218.890762,0.404752,0.000000
321.970001,0.293427,-218.979721,0.019009,0.015920,0.404362,1.305226,0.066491,4.043615,-218.979721,0.403468,0.000000
322.740021,0.259544,-219.068680,0.018940,0.015867,0.403017,1.154511,0.058814,4.030171,-219.068680,0.402184,0.000000
323.510010,0.266991,-219.024200,0.018880,0.015810,0.401577,1.187634,0.060501,4.015774,-219.024200,0.400901,0.000000
324.280029,0.245018,-218.979721,0.018867,0.015775,0.400676,1.089895,0.055522,4.006758,-218.979721,0.399618,0.000000
325.050018,0.239067,-219.068680,0.018798,0.015722,0.399340,1.063424,0.054173,3.993401,-219.068680,0.398334,0.000000
325.820007,0.263268,-219.157639,0.018751,0.015666,0.397909,1.171072,0.059657,3.979090,-219.157639,0.397051,0.000000
326.590027,0.278160,-219.202133,0.018690,0.015615,0.396617,1.237318,0.063032,3.966169,-219.202133,0.395767,0.000000
326.800018,0.260658,-219.157639,0.018677,0.015606,0.396392,1.159466,0.059066,3.963917,-219.157639,0.396313,0.000000