File: Data/PDMS compression/PDMS 0010 Punched_3_07152024_151548.csv
Time (sec),S:Load (lbs),S:HL1 (DIM),S:LVDT (in),S:Position (in),Ch:Position (mm),Ch:Load (N),Ch:Stress (MPa),Ch:Strain (mm/mm),Ch:HL1 (DIM),Set Point (),Cycles ()
0.110000,0.006332,-134.599365,-0.000009,-0.000000,-0.000000,0.028168,0.001435,-0.000000,-134.599365,0.000208,0.000000
0.370000,-0.012657,-134.643845,0.000013,-0.000000,-0.000000,-0.056302,-0.002868,-0.000000,-134.643845,0.000208,0.000000
0.630000,0.010803,-134.643845,0.000004,0.000070,0.001778,0.048055,0.002448,0.017778,-134.643845,0.002315,0.000000
0.890000,0.005592,-134.643845,0.000000,0.000144,0.003668,0.024876,0.001267,0.036684,-134.643845,0.004484,0.000000
1.150000,-0.013031,-134.688324,0.000034,0.000220,0.005585,-0.057965,-0.002953,0.055849,-134.688324,0.006652,0.000000
1.410000,0.020485,-134.777283,0.000078,0.000303,0.007701,0.091121,0.004642,0.077010,-134.777283,0.008811,0.000000
1.670000,0.021599,-134.821762,0.000203,0.000390,0.009895,0.096076,0.004894,0.098950,-134.821762,0.010979,0.000000
1.930000,-0.026436,-134.866241,0.000276,0.000476,0.012098,-0.117593,-0.005990,0.120978,-134.866241,0.013147,0.000000
2.190000,0.004845,-134.732803,0.000371,0.000565,0.014353,0.021550,0.001098,0.143526,-134.732803,0.015315,0.000000
2.450000,0.005219,-134.821762,0.000453,0.000645,0.016391,0.023213,0.001183,0.163906,-134.821762,0.017475,0.000000
2.710000,-0.035370,-134.821762,0.000535,0.000731,0.018567,-0.157333,-0.008015,0.185673,-134.821762,0.019643,0.000000
2.970000,0.014153,-134.866241,0.000625,0.000816,0.020727,0.062954,0.003207,0.207267,-134.866241,0.021811,0.000000
3.230000,0.026817,-134.910721,0.000707,0.000908,0.023068,0.119289,0.006077,0.230682,-134.910721,0.023979,0.000000
3.490000,0.026443,-134.910721,0.000819,0.000987,0.025071,0.117626,0.005992,0.250715,-134.910721,0.026138,0.000000
3.750000,0.074478,-134.955200,0.000884,0.001069,0.027153,0.331295,0.016877,0.271528,-134.955200,0.028306,0.000000
4.010000,0.108360,-134.955200,0.000983,0.001160,0.029468,0.482011,0.024555,0.294683,-134.955200,0.030474,0.000000
4.270000,0.201080,-134.999680,0.001069,0.001244,0.031593,0.894450,0.045565,0.315930,-134.999680,0.032642,0.000000
4.530000,0.427116,-134.999680,0.001138,-0.000004,-0.000104,1.899909,0.096786,-0.001041,-134.999680,0.001353,0.000000
4.790000,0.400673,-135.044174,0.001155,-0.000005,-0.000121,1.782282,0.090794,-0.001214,-135.044174,0.000087,0.000000
5.050000,0.392853,-135.133133,0.001130,-0.000005,-0.000121,1.747496,0.089022,-0.001214,-135.133133,0.000087,0.000000
5.310000,0.418175,-135.133133,0.001143,-0.000005,-0.000121,1.860134,0.094760,-0.001214,-135.133133,0.000512,0.000000
5.570000,0.396576,-135.133133,0.001151,-0.000005,-0.000121,1.764058,0.089865,-0.001214,-135.133133,0.000945,0.000000
5.830000,0.397697,-135.133133,0.001130,-0.000005,-0.000121,1.769047,0.090120,-0.001214,-135.133133,0.001379,0.000000
6.090000,0.553345,-135.177612,0.001177,0.000034,0.000859,2.461400,0.125390,0.008586,-135.177612,0.001804,0.000000
6.350000,0.660965,-135.266571,0.001173,0.000050,0.001275,2.940119,0.149777,0.012748,-135.266571,0.002237,0.000000
6.610000,0.713470,-135.177612,0.001207,0.000068,0.001734,3.173675,0.161675,0.017345,-135.177612,0.002671,0.000000
6.870000,0.815872,-135.311050,0.001216,0.000085,0.002159,3.629181,0.184879,0.021594,-135.311050,0.003105,0.000000
7.130000,0.940987,-135.311050,0.001233,0.000107,0.002706,4.185718,0.213231,0.027057,-135.311050,0.003538,0.000000
7.390000,1.034081,-135.311050,0.001263,0.000118,0.003009,4.599820,0.234326,0.030093,-135.311050,0.003972,0.000000
7.650001,1.097382,-135.355530,0.001272,0.000130,0.003304,4.881397,0.248670,0.033041,-135.355530,0.004406,0.000000
7.910000,1.273148,-135.311050,0.001285,0.000150,0.003798,5.663243,0.288499,0.037984,-135.311050,0.004839,0.000000
8.170000,1.411293,-135.400009,0.001298,0.000173,0.004388,6.277745,0.319804,0.043882,-135.400009,0.005273,0.000000
8.430000,1.457100,-135.488983,0.001311,0.000186,0.004726,6.481504,0.330184,0.047264,-135.488983,0.005706,0.000000
8.690001,1.620193,-135.444489,0.001350,0.000205,0.005212,7.206981,0.367141,0.052120,-135.444489,0.006140,0.000000
8.950001,1.784782,-135.444489,0.001362,0.000225,0.005724,7.939109,0.404437,0.057237,-135.444489,0.006574,0.000000
9.210000,1.915863,-135.488983,0.001367,0.000243,0.006175,8.522184,0.434141,0.061746,-135.488983,0.007007,0.000000
9.470000,1.981400,-135.577942,0.001388,0.000255,0.006478,8.813705,0.448992,0.064782,-135.577942,0.007441,0.000000
9.730000,2.220459,-135.577942,0.001427,0.000277,0.007033,9.877095,0.503163,0.070332,-135.577942,0.007874,0.000000
9.990001,2.239822,-135.577942,0.001436,0.000294,0.007475,9.963227,0.507551,0.074755,-135.577942,0.008308,0.000000
10.250001,2.242058,-135.622421,0.001431,0.000304,0.007718,9.973171,0.508058,0.077183,-135.622421,0.008742,0.000000
10.510000,2.438301,-135.577942,0.001457,0.000324,0.008221,10.846105,0.552527,0.082213,-135.577942,0.009175,0.000000
10.770000,2.437553,-135.755859,0.001462,0.000337,0.008560,10.842779,0.552357,0.085595,-135.755859,0.009609,0.000000
11.030001,2.685928,-135.711380,0.001466,0.000359,0.009123,11.947606,0.608640,0.091232,-135.711380,0.010042,0.000000
11.290001,2.687790,-135.711380,0.001492,0.000370,0.009409,11.955887,0.609062,0.094094,-135.711380,0.010476,0.000000
11.550000,2.832268,-135.755859,0.001513,0.000386,0.009808,12.598557,0.641801,0.098083,-135.755859,0.010910,0.000000
11.810000,2.878815,-135.755859,0.001548,0.000402,0.010199,12.805608,0.652349,0.101986,-135.755859,0.011343,0.000000
12.070001,3.094048,-135.800339,0.001569,0.000430,0.010910,13.763011,0.701121,0.109097,-135.800339,0.011777,0.000000
12.330001,3.151764,-135.844818,0.001587,0.000445,0.011291,14.019746,0.714200,0.112913,-135.844818,0.012211,0.000000
12.590000,3.200172,-135.844818,0.001578,0.000459,0.011664,14.235078,0.725169,0.116642,-135.844818,0.012644,0.000000
12.850000,3.275017,-135.933792,0.001600,0.000472,0.011985,14.568003,0.742129,0.119851,-135.933792,0.013078,0.000000
13.110001,3.435883,-135.844818,0.001617,0.000492,0.012505,15.283569,0.778582,0.125054,-135.844818,0.013511,0.000000
13.370001,3.299225,-135.889313,0.001638,0.000496,0.012601,14.675685,0.747615,0.126008,-135.889313,0.013945,0.000000
13.630001,3.771393,-135.889313,0.001625,0.000529,0.013433,16.775993,0.854610,0.134333,-135.889313,0.014379,0.000000
13.890000,3.796715,-135.933792,0.001690,0.000551,0.014006,16.888630,0.860348,0.140057,-135.933792,0.014812,0.000000
14.150001,3.836929,-136.111710,0.001686,0.000565,0.014353,17.067514,0.869461,0.143526,-136.111710,0.015246,0.000000
14.410001,3.806396,-135.978271,0.001690,0.000579,0.014708,16.931698,0.862542,0.147081,-135.978271,0.015679,0.000000
14.670001,3.978432,-136.111710,0.001707,0.000595,0.015107,17.696949,0.901525,0.151071,-136.111710,0.016113,0.000000
14.930000,4.186958,-136.022751,0.001712,0.000617,0.015662,18.624521,0.948778,0.156621,-136.022751,0.016547,0.000000
15.190001,4.154190,-136.067230,0.001768,0.000634,0.016104,18.478760,0.941353,0.161044,-136.067230,0.016972,0.000000
15.450001,4.373146,-136.156189,0.001768,0.000651,0.016547,19.452724,0.990969,0.165467,-136.156189,0.017405,0.000000
15.710001,4.471077,-136.111710,0.001789,0.000672,0.017076,19.888344,1.013161,0.170757,-136.111710,0.017839,0.000000
15.970001,4.436073,-136.200668,0.001837,0.000685,0.017397,19.732639,1.005229,0.173965,-136.200668,0.018272,0.000000
16.230001,4.530289,-136.200668,0.001828,0.000700,0.017769,20.151731,1.026578,0.177695,-136.200668,0.018706,0.000000
16.490002,4.621521,-136.289627,0.001837,0.000714,0.018142,20.557552,1.047252,0.181424,-136.289627,0.019140,0.000000
16.750000,4.739563,-136.334122,0.001841,0.000731,0.018576,21.082628,1.074000,0.185760,-136.334122,0.019573,0.000000
17.010000,4.898193,-136.245148,0.001867,0.000751,0.019088,21.788252,1.109946,0.190876,-136.245148,0.020007,0.000000
17.270000,4.747383,-136.334122,0.001876,0.000759,0.019287,21.117414,1.075772,0.192871,-136.334122,0.020441,0.000000
17.530001,5.267212,-136.378601,0.001897,0.000790,0.020059,23.429729,1.193567,0.200589,-136.378601,0.020874,0.000000
17.790001,5.157738,-136.423080,0.001927,0.000807,0.020493,22.942762,1.168760,0.204925,-136.423080,0.021308,0.000000
18.050001,5.164810,-136.378601,0.001932,0.000820,0.020831,22.974222,1.170363,0.208308,-136.378601,0.021741,0.000000
18.310001,5.191246,-136.378601,0.001949,0.000835,0.021221,23.091816,1.176353,0.212210,-136.378601,0.022175,0.000000
18.570002,5.240402,-136.512039,0.001970,0.000849,0.021568,23.310472,1.187492,0.215679,-136.512039,0.022609,0.000000
18.830002,5.467918,-136.467560,0.001975,0.000867,0.022019,24.322515,1.239048,0.220189,-136.467560,0.023042,0.000000
19.090000,5.497711,-136.467560,0.001988,0.000883,0.022426,24.455040,1.245799,0.224265,-136.467560,0.023476,0.000000
19.350000,5.567345,-136.512039,0.002022,0.000897,0.022782,24.764786,1.261578,0.227820,-136.512039,0.023909,0.000000
19.610001,5.927429,-136.600998,0.002048,0.000929,0.023606,26.366522,1.343175,0.236059,-136.600998,0.024343,0.000000
19.870001,5.811249,-136.600998,0.002048,0.000942,0.023918,25.849726,1.316848,0.239181,-136.600998,0.024777,0.000000
20.130001,5.799332,-136.600998,0.002039,0.000953,0.024204,25.796715,1.314147,0.242043,-136.600998,0.025210,0.000000
20.390001,6.061852,-136.600998,0.002095,0.000971,0.024673,26.964462,1.373635,0.246726,-136.600998,0.025644,0.000000
20.650002,6.264427,-136.689957,0.002082,0.000993,0.025210,27.865564,1.419540,0.252103,-136.689957,0.026077,0.000000
20.910002,6.226440,-136.645477,0.002113,0.001009,0.025627,27.696590,1.410932,0.256265,-136.645477,0.026511,0.000000
21.170000,6.241341,-136.778931,0.002126,0.001022,0.025956,27.762869,1.414308,0.259561,-136.778931,0.026945,0.000000
21.430000,6.496414,-136.734436,0.002151,0.001043,0.026502,28.897493,1.472109,0.265024,-136.734436,0.027378,0.000000
21.690001,6.496788,-136.778931,0.002156,0.001058,0.026867,28.899157,1.472193,0.268667,-136.778931,0.027812,0.000000
21.950001,6.463272,-136.823410,0.002190,0.001071,0.027214,28.750071,1.464598,0.272135,-136.823410,0.028246,0.000000
22.210001,6.612968,-136.867889,0.002199,0.001089,0.027656,29.415953,1.498520,0.276558,-136.867889,0.028679,0.000000
22.470001,6.730637,-136.867889,0.002212,0.001108,0.028141,29.939367,1.525184,0.281415,-136.867889,0.029113,0.000000
22.730001,6.865807,-136.867889,0.002207,0.001130,0.028714,30.540632,1.555814,0.287138,-136.867889,0.029546,0.000000
22.990002,6.768616,-136.912369,0.002255,0.001141,0.028983,30.108307,1.533790,0.289827,-136.912369,0.029980,0.000000
23.250002,6.884056,-136.956848,0.002272,0.001157,0.029399,30.621811,1.559949,0.293990,-136.956848,0.030414,0.000000
23.510000,6.962624,-136.956848,0.002281,0.001173,0.029807,30.971296,1.577753,0.298065,-136.956848,0.030847,0.000000
23.770000,7.151787,-137.001328,0.002324,0.001195,0.030344,31.812737,1.620618,0.303442,-137.001328,0.031281,0.000000
24.030001,7.146202,-137.001328,0.002315,0.001209,0.030717,31.787895,1.619352,0.307171,-137.001328,0.031714,0.000000
24.290001,7.279510,-137.090286,0.002341,0.001228,0.031185,32.380878,1.649561,0.311854,-137.090286,0.032139,0.000000
24.550001,7.454529,-137.090286,0.002354,0.001247,0.031680,33.159401,1.689220,0.316798,-137.090286,0.032573,0.000000
24.810001,7.319359,-137.090286,0.002371,0.001261,0.032018,32.558136,1.658590,0.320180,-137.090286,0.033007,0.000000
25.070002,7.236687,-137.134766,0.002376,0.001269,0.032235,32.190392,1.639857,0.322348,-137.134766,0.033440,0.000000
25.330002,7.766945,-137.134766,0.002393,0.001297,0.032937,34.549095,1.760015,0.329372,-137.134766,0.033874,0.000000
25.590002,7.716675,-137.223740,0.002419,0.001317,0.033458,34.325485,1.748624,0.334576,-137.223740,0.034307,0.000000
25.850000,7.698059,-137.179260,0.002453,0.001334,0.033874,34.242676,1.744405,0.338738,-137.179260,0.034741,0.000000
26.110001,7.636246,-137.223740,0.002462,0.001347,0.034212,33.967716,1.730398,0.342121,-137.223740,0.035175,0.000000
26.370001,7.838074,-137.268219,0.002471,0.001366,0.034689,34.865494,1.776133,0.346890,-137.268219,0.035608,0.000000
26.630001,7.950897,-137.268219,0.002488,0.001382,0.035114,35.367355,1.801699,0.351140,-137.268219,0.036042,0.000000
26.890001,7.838074,-137.357178,0.002514,0.001393,0.035391,34.865494,1.776133,0.353915,-137.357178,0.036476,0.000000
27.150002,8.019043,-137.312698,0.002535,0.001412,0.035860,35.670486,1.817141,0.358598,-137.312698,0.036909,0.000000
27.410002,8.398117,-137.357178,0.002539,0.001436,0.036484,37.356689,1.903041,0.364842,-137.357178,0.037343,0.000000
27.670002,8.147888,-137.446136,0.002548,0.001450,0.036822,36.243618,1.846338,0.368224,-137.446136,0.037776,0.000000
27.930002,8.219009,-137.401657,0.002574,0.001467,0.037273,36.559978,1.862454,0.372734,-137.401657,0.038210,0.000000
28.190001,8.270020,-137.490616,0.002578,0.001484,0.037681,36.786884,1.874013,0.376810,-137.490616,0.038644,0.000000
28.450001,8.533287,-137.490616,0.002600,0.001506,0.038245,37.957958,1.933670,0.382447,-137.490616,0.039077,0.000000
28.710001,8.367584,-137.490616,0.002643,0.001517,0.038531,37.220875,1.896122,0.385308,-137.490616,0.039511,0.000000
28.970001,8.336304,-137.535095,0.002639,0.001529,0.038826,37.081730,1.889033,0.388257,-137.535095,0.039944,0.000000
29.230001,8.599945,-137.535095,0.002643,0.001549,0.039337,38.254467,1.948775,0.393374,-137.535095,0.040378,0.000000
29.490002,8.712029,-137.579575,0.002695,0.001573,0.039944,38.753036,1.974174,0.399444,-137.579575,0.040812,0.000000
29.750002,8.641647,-137.579575,0.002686,0.001587,0.040309,38.439968,1.958225,0.403087,-137.579575,0.041245,0.000000
30.010002,8.722084,-137.624069,0.002712,0.001603,0.040725,38.797768,1.976452,0.407249,-137.624069,0.041679,0.000000
30.270002,8.925400,-137.668549,0.002733,0.001623,0.041228,39.702160,2.022524,0.412279,-137.668549,0.042112,0.000000
30.530001,9.007324,-137.624069,0.002759,0.001642,0.041696,40.066578,2.041089,0.416962,-137.624069,0.042546,0.000000
30.790001,8.949234,-137.713028,0.002768,0.001654,0.042008,39.808182,2.027925,0.420084,-137.713028,0.042980,0.000000
31.050001,9.284363,-137.757507,0.002790,0.001676,0.042572,41.298908,2.103867,0.425721,-137.757507,0.043413,0.000000
31.310001,9.088127,-137.757507,0.002802,0.001693,0.043006,40.426010,2.059399,0.430057,-137.757507,0.043847,0.000000
31.570002,8.937683,-137.757507,0.002811,0.001704,0.043275,39.756802,2.025308,0.432746,-137.757507,0.044281,0.000000
31.830002,9.176750,-137.713028,0.002833,0.001723,0.043760,40.820225,2.079481,0.437602,-137.713028,0.044714,0.000000
32.090000,9.123871,-137.935425,0.002863,0.001739,0.044176,40.585003,2.067499,0.441765,-137.935425,0.045148,0.000000
32.350002,9.429222,-137.890945,0.002850,0.001758,0.044645,41.943275,2.136692,0.446448,-137.890945,0.045581,0.000000
32.610001,9.250107,-137.846466,0.002902,0.001770,0.044948,41.146530,2.096104,0.449483,-137.846466,0.046015,0.000000
32.870003,9.369637,-137.935425,0.002889,0.001786,0.045356,41.678226,2.123190,0.453559,-137.935425,0.046449,0.000000
33.130001,9.265373,-137.890945,0.002915,0.001797,0.045633,41.214439,2.099564,0.456334,-137.890945,0.046874,0.000000
33.390003,9.692482,-137.979904,0.002949,0.001829,0.046449,43.114315,2.196348,0.464486,-137.979904,0.047307,0.000000
33.650002,9.600136,-137.979904,0.002940,0.001843,0.046822,42.703537,2.175422,0.468215,-137.979904,0.047741,0.000000
33.910000,9.590828,-137.979904,0.002953,0.001858,0.047194,42.662132,2.173313,0.471944,-137.979904,0.048174,0.000000
34.170002,9.716690,-138.024384,0.002992,0.001875,0.047619,43.221996,2.201833,0.476194,-138.024384,0.048608,0.000000
34.430000,9.813507,-137.979904,0.003009,0.001892,0.048044,43.652660,2.223773,0.480443,-137.979904,0.049042,0.000000
34.690002,9.716690,-138.157837,0.003027,0.001905,0.048383,43.221996,2.201833,0.483825,-138.157837,0.049475,0.000000
34.950001,10.216415,-138.113358,0.003044,0.001929,0.048990,45.444885,2.315073,0.489896,-138.113358,0.049909,0.000000
35.210003,10.109169,-138.157837,0.003065,0.001950,0.049536,44.967831,2.290771,0.495359,-138.157837,0.050342,0.000000
35.470001,10.010864,-138.202316,0.003083,0.001965,0.049918,44.530548,2.268494,0.499175,-138.202316,0.050776,0.000000
35.730003,9.912560,-138.157837,0.003096,0.001977,0.050212,44.093266,2.246218,0.502124,-138.157837,0.051210,0.000000
35.990002,10.016823,-138.335754,0.003117,0.001993,0.050620,44.557053,2.269845,0.506200,-138.335754,0.051643,0.000000
36.250000,10.282700,-138.291275,0.003143,0.002015,0.051192,45.739731,2.330093,0.511923,-138.291275,0.052077,0.000000
36.510002,10.259239,-138.291275,0.003156,0.002034,0.051669,45.635376,2.324777,0.516693,-138.291275,0.052511,0.000000
36.770000,10.359406,-138.291275,0.003178,0.002050,0.052077,46.080936,2.347475,0.520769,-138.291275,0.052944,0.000000
37.030003,10.457710,-138.291275,0.003195,0.002071,0.052615,46.518219,2.369751,0.526146,-138.291275,0.053378,0.000000
37.290001,10.334457,-138.424713,0.003203,0.002085,0.052953,45.969963,2.341822,0.529528,-138.424713,0.053811,0.000000
37.550003,10.353447,-138.335754,0.003212,0.002100,0.053343,46.054432,2.346125,0.533431,-138.335754,0.054245,0.000000
37.810001,10.367966,-138.424713,0.003242,0.002112,0.053655,46.119015,2.349415,0.536552,-138.424713,0.054679,0.000000
38.070004,10.474098,-138.424713,0.003264,0.002131,0.054115,46.591114,2.373465,0.541149,-138.424713,0.055112,0.000000
38.330002,10.696777,-138.469208,0.003285,0.002150,0.054618,47.581642,2.423924,0.546179,-138.469208,0.055546,0.000000
38.590000,10.389565,-138.513687,0.003281,0.002159,0.054835,46.215092,2.354309,0.548347,-138.513687,0.055979,0.000000
38.850002,11.085159,-138.469208,0.003316,0.002190,0.055624,49.309250,2.511933,0.556239,-138.469208,0.056413,0.000000
39.110001,10.795822,-138.513687,0.003337,0.002206,0.056031,48.022217,2.446368,0.560315,-138.513687,0.056847,0.000000
39.370003,10.718369,-138.558167,0.003359,0.002219,0.056352,47.677685,2.428817,0.563523,-138.558167,0.057280,0.000000
39.630001,10.699753,-138.558167,0.003367,0.002234,0.056734,47.594879,2.424599,0.567339,-138.558167,0.057714,0.000000
39.890003,10.678154,-138.647125,0.003397,0.002246,0.057046,47.498802,2.419704,0.570461,-138.647125,0.058147,0.000000
40.150002,10.979034,-138.602646,0.003389,0.002266,0.057558,48.837185,2.487885,0.575578,-138.602646,0.058581,0.000000
40.410004,10.938072,-138.736084,0.003410,0.002282,0.057965,48.654976,2.478603,0.579654,-138.736084,0.059015,0.000000
40.670002,10.994301,-138.691605,0.003428,0.002296,0.058312,48.905094,2.491344,0.583123,-138.691605,0.059448,0.000000
40.930000,11.427368,-138.736084,0.003454,0.002328,0.059136,50.831470,2.589479,0.591361,-138.736084,0.059882,0.000000
41.190002,11.183838,-138.780563,0.003492,0.002341,0.059466,49.748196,2.534294,0.594657,-138.780563,0.060316,0.000000
41.450001,11.037498,-138.736084,0.003501,0.002351,0.059717,49.097244,2.501133,0.597172,-138.736084,0.060749,0.000000
41.710003,11.284004,-138.825043,0.003518,0.002370,0.060185,50.193756,2.556992,0.601855,-138.825043,0.061183,0.000000
41.970001,11.609833,-138.825043,0.003518,0.002391,0.060732,51.643116,2.630826,0.607318,-138.825043,0.061616,0.000000
42.230003,11.503334,-138.869522,0.003557,0.002408,0.061174,51.169384,2.606693,0.611741,-138.869522,0.062041,0.000000
42.490002,11.458275,-138.914017,0.003570,0.002422,0.061530,50.968952,2.596482,0.615297,-138.914017,0.062475,0.000000
42.750004,11.657867,-138.869522,0.003596,0.002444,0.062076,51.856785,2.641710,0.620760,-138.869522,0.062909,0.000000
43.010002,11.663826,-138.914017,0.003583,0.002458,0.062432,51.883289,2.643061,0.624316,-138.914017,0.063342,0.000000
43.270000,11.482109,-139.002975,0.003613,0.002469,0.062700,51.074970,2.601883,0.627004,-139.002975,0.063776,0.000000
43.530003,11.690636,-139.002975,0.003622,0.002486,0.063151,52.002544,2.649136,0.631514,-139.002975,0.064209,0.000000
43.790001,11.688026,-139.047455,0.003639,0.002501,0.063533,51.990936,2.648545,0.635329,-139.047455,0.064643,0.000000
44.050003,12.055565,-139.002975,0.003665,0.002528,0.064209,53.625832,2.731830,0.642094,-139.002975,0.065077,0.000000
44.310001,11.798248,-139.047455,0.003695,0.002540,0.064504,52.481228,2.673521,0.645042,-139.047455,0.065510,0.000000
44.570004,11.843307,-139.002975,0.003699,0.002556,0.064912,52.681664,2.683732,0.649118,-139.002975,0.065944,0.000000
44.830002,12.002686,-139.136414,0.003725,0.002572,0.065328,53.390614,2.719847,0.653281,-139.136414,0.066377,0.000000
45.090004,12.099876,-139.180893,0.003738,0.002593,0.065866,53.822937,2.741871,0.658658,-139.180893,0.066811,0.000000
45.350002,12.088699,-139.136414,0.003755,0.002608,0.066239,53.773220,2.739338,0.662387,-139.136414,0.067245,0.000000
45.610001,12.117378,-139.180893,0.003781,0.002625,0.066681,53.900791,2.745837,0.666810,-139.180893,0.067678,0.000000
45.870003,12.444687,-139.225372,0.003794,0.002646,0.067201,55.356731,2.820006,0.672013,-139.225372,0.068112,0.000000
46.130001,12.203392,-139.269852,0.003829,0.002659,0.067531,54.283398,2.765328,0.675309,-139.269852,0.068546,0.000000
46.390003,12.025398,-139.314346,0.003811,0.002667,0.067748,53.491642,2.724994,0.677477,-139.314346,0.068979,0.000000
46.650002,12.701630,-139.269852,0.003837,0.002697,0.068493,56.499672,2.878231,0.684935,-139.269852,0.069413,0.000000
46.910004,12.582466,-139.358826,0.003889,0.002716,0.068979,55.969604,2.851228,0.689791,-139.358826,0.069846,0.000000
47.170002,12.461075,-139.358826,0.003876,0.002732,0.069404,55.429630,2.823720,0.694041,-139.358826,0.070280,0.000000
47.430004,12.434639,-139.358826,0.003893,0.002747,0.069786,55.312038,2.817729,0.697856,-139.358826,0.070714,0.000000
47.690002,12.601830,-139.358826,0.003928,0.002765,0.070228,56.055737,2.855615,0.702279,-139.358826,0.071147,0.000000
47.950001,12.637207,-139.403305,0.003945,0.002781,0.070636,56.213104,2.863632,0.706355,-139.403305,0.071581,0.000000
48.210003,12.495705,-139.492264,0.003941,0.002792,0.070922,55.583672,2.831567,0.709217,-139.492264,0.072014,0.000000
48.470001,12.696045,-139.403305,0.003949,0.002811,0.071390,56.474827,2.876965,0.713900,-139.403305,0.072448,0.000000
48.730003,13.227043,-139.536743,0.003967,0.002836,0.072023,58.836826,2.997291,0.720231,-139.536743,0.072882,0.000000
48.990002,12.819298,-139.581223,0.003992,0.002848,0.072344,57.023083,2.904895,0.723440,-139.581223,0.073315,0.000000
49.250004,12.880363,-139.536743,0.004014,0.002866,0.072795,57.294720,2.918732,0.727949,-139.536743,0.073749,0.000000
49.510002,12.914993,-139.670181,0.004036,0.002882,0.073203,57.448761,2.926579,0.732025,-139.670181,0.074182,0.000000
49.770000,13.234863,-139.581223,0.004040,0.002906,0.073810,58.871613,2.999063,0.738096,-139.581223,0.074616,0.000000
50.030003,12.950745,-139.625702,0.004083,0.002915,0.074052,57.607788,2.934681,0.740524,-139.625702,0.075050,0.000000
50.290001,12.656570,-139.714661,0.004105,0.002921,0.074182,56.299236,2.868020,0.741825,-139.714661,0.075483,0.000000
50.550003,13.237099,-139.670181,0.004109,0.002947,0.074859,58.881557,2.999569,0.748589,-139.670181,0.075917,0.000000
50.810001,13.355141,-139.803635,0.004113,0.002971,0.075457,59.406631,3.026318,0.754573,-139.803635,0.076351,0.000000
51.070004,13.181244,-139.759155,0.004152,0.002984,0.075804,58.633102,2.986912,0.758042,-139.759155,0.076784,0.000000
51.330002,13.361099,-139.803635,0.004165,0.003003,0.076272,59.433136,3.027668,0.762725,-139.803635,0.077209,0.000000
51.590004,13.503349,-139.848114,0.004169,0.003023,0.076775,60.065899,3.059903,0.767755,-139.848114,0.077643,0.000000
51.850002,13.583031,-139.803635,0.004208,0.003040,0.077218,60.420338,3.077959,0.772178,-139.803635,0.078076,0.000000
52.110001,13.444885,-139.848114,0.004204,0.003052,0.077521,59.805836,3.046654,0.775213,-139.848114,0.078510,0.000000
52.370003,13.812042,-139.848114,0.004238,0.003073,0.078059,61.439034,3.129853,0.780590,-139.848114,0.078944,0.000000
52.630001,13.676125,-139.937073,0.004255,0.003092,0.078545,60.834442,3.099054,0.785446,-139.937073,0.079377,0.000000
52.890003,13.527550,-139.937073,0.004273,0.003105,0.078874,60.173546,3.065387,0.788742,-139.937073,0.079811,0.000000
53.150002,13.702934,-139.937073,0.004294,0.003122,0.079299,60.953697,3.105129,0.792991,-139.937073,0.080244,0.000000
53.410004,13.867157,-140.070511,0.004312,0.003140,0.079759,61.684196,3.142343,0.797588,-140.070511,0.080678,0.000000
53.670002,13.964340,-139.937073,0.004316,0.003156,0.080166,62.116489,3.164365,0.801663,-139.937073,0.081112,0.000000
53.930004,13.708153,-140.070511,0.004320,0.003168,0.080479,60.976910,3.106312,0.804785,-140.070511,0.081545,0.000000
54.190002,13.867897,-140.026031,0.004337,0.003184,0.080886,61.687489,3.142510,0.808861,-140.026031,0.081979,0.000000
54.450001,13.683205,-140.026031,0.004363,0.003198,0.081233,60.865932,3.100659,0.812330,-140.026031,0.082412,0.000000
54.710003,14.203033,-140.070511,0.004385,0.003226,0.081953,63.178249,3.218453,0.819528,-140.070511,0.082846,0.000000
54.970001,14.100258,-140.114990,0.004411,0.003242,0.082343,62.721081,3.195164,0.823431,-140.114990,0.083280,0.000000
55.230003,14.101006,-140.203964,0.004432,0.003256,0.082707,62.724407,3.195333,0.827073,-140.203964,0.083713,0.000000
55.490002,14.049240,-140.203964,0.004432,0.003268,0.083011,62.494141,3.183603,0.830108,-140.203964,0.084147,0.000000
55.750004,14.347145,-140.248444,0.004462,0.003290,0.083566,63.819290,3.251109,0.835659,-140.248444,0.084581,0.000000
56.010002,14.143456,-140.292923,0.004471,0.003303,0.083887,62.913231,3.204953,0.838867,-140.292923,0.085014,0.000000
56.270004,14.747818,-140.337402,0.004493,0.003328,0.084528,65.601570,3.341903,0.845285,-140.337402,0.085448,0.000000
56.530003,14.667381,-140.337402,0.004488,0.003348,0.085049,65.243767,3.323676,0.850488,-140.337402,0.085881,0.000000
56.790001,14.541893,-140.337402,0.004523,0.003364,0.085439,64.685570,3.295240,0.854391,-140.337402,0.086315,0.000000
57.050003,14.407097,-140.337402,0.004553,0.003377,0.085769,64.085968,3.264695,0.857686,-140.337402,0.086749,0.000000
57.310001,14.489761,-140.426361,0.004562,0.003392,0.086150,64.453674,3.283427,0.861502,-140.426361,0.087182,0.000000
57.570004,14.809998,-140.426361,0.004587,0.003414,0.086714,65.878159,3.355993,0.867139,-140.426361,0.087616,0.000000
57.830002,14.771645,-140.470840,0.004609,0.003432,0.087182,65.707558,3.347303,0.871822,-140.470840,0.088049,0.000000
58.090004,14.898994,-140.470840,0.004600,0.003449,0.087598,66.274040,3.376160,0.875985,-140.470840,0.088483,0.000000
58.350002,15.031937,-140.470840,0.004639,0.003470,0.088136,66.865395,3.406286,0.881361,-140.470840,0.088917,0.000000
58.610004,14.853195,-140.559799,0.004665,0.003484,0.088483,66.070312,3.365782,0.884830,-140.559799,0.089350,0.000000
58.870003,14.877029,-140.559799,0.004682,0.003499,0.088882,66.176331,3.371183,0.888820,-140.559799,0.089784,0.000000
59.130001,14.834206,-140.604294,0.004687,0.003511,0.089177,65.985840,3.361479,0.891768,-140.604294,0.090217,0.000000
59.390003,15.014809,-140.648773,0.004704,0.003530,0.089654,66.789207,3.402404,0.896538,-140.648773,0.090651,0.000000
59.650002,15.151466,-140.604294,0.004730,0.003549,0.090139,67.397087,3.433371,0.901394,-140.604294,0.091085,0.000000
59.910004,14.822289,-140.648773,0.004704,0.003557,0.090356,65.932831,3.358778,0.903562,-140.648773,0.091518,0.000000
60.170002,15.758804,-140.693253,0.004764,0.003589,0.091171,70.098663,3.570996,0.911714,-140.693253,0.091943,0.000000
60.430004,15.369675,-140.737732,0.004790,0.003605,0.091579,68.367729,3.482818,0.915790,-140.737732,0.092377,0.000000
60.690002,15.231895,-140.693253,0.004790,0.003617,0.091874,67.754852,3.451597,0.918739,-140.693253,0.092810,0.000000
60.950005,15.247536,-140.782211,0.004794,0.003633,0.092290,67.824425,3.455141,0.922902,-140.782211,0.093244,0.000000
61.210003,15.180511,-140.826691,0.004825,0.003645,0.092576,67.526291,3.439953,0.925763,-140.826691,0.093678,0.000000
61.470001,15.437820,-140.782211,0.004859,0.003665,0.093097,68.670853,3.498260,0.930967,-140.782211,0.094111,0.000000
61.730003,15.446014,-140.826691,0.004855,0.003679,0.093444,68.707306,3.500117,0.934436,-140.826691,0.094545,0.000000
61.990002,15.508568,-140.782211,0.004881,0.003694,0.093834,68.985558,3.514292,0.938338,-140.782211,0.094979,0.000000
62.250004,16.064522,-140.871170,0.004902,0.003726,0.094640,71.458565,3.640273,0.946403,-140.871170,0.095412,0.000000
62.510002,15.753220,-140.960129,0.004911,0.003739,0.094979,70.073822,3.569731,0.949786,-140.960129,0.095846,0.000000
62.770004,15.575974,-140.960129,0.004919,0.003750,0.095239,69.285393,3.529566,0.952387,-140.960129,0.096279,0.000000
63.030003,15.775932,-141.049103,0.004941,0.003767,0.095681,70.174850,3.574877,0.956810,-141.049103,0.096713,0.000000
63.290005,16.183311,-140.960129,0.004963,0.003790,0.096253,71.986961,3.667191,0.962534,-140.960129,0.097147,0.000000
63.550003,16.115540,-141.049103,0.004984,0.003807,0.096687,71.685501,3.651834,0.966870,-141.049103,0.097580,0.000000
63.810001,16.089470,-141.093582,0.004984,0.003821,0.097060,71.569534,3.645926,0.970599,-141.093582,0.098014,0.000000
64.070000,16.116280,-141.049103,0.005019,0.003840,0.097528,71.688789,3.652001,0.975282,-141.049103,0.098447,0.000000
64.330002,16.314758,-141.138062,0.005023,0.003856,0.097953,72.571671,3.696977,0.979531,-141.138062,0.098881,0.000000
64.590004,16.094688,-141.138062,0.005036,0.003867,0.098213,71.592751,3.647109,0.982133,-141.138062,0.099315,0.000000
64.850006,16.351250,-141.138062,0.005062,0.003885,0.098682,72.733994,3.705246,0.986816,-141.138062,0.099748,0.000000
65.110001,16.320717,-141.182541,0.005092,0.003900,0.099055,72.598175,3.698327,0.990545,-141.182541,0.100182,0.000000
65.370003,16.824165,-141.182541,0.005113,0.003927,0.099757,74.837624,3.812410,0.997570,-141.182541,0.100616,0.000000
65.630005,16.433548,-141.271500,0.005126,0.003938,0.100026,73.100075,3.723895,1.000258,-141.271500,0.101049,0.000000
65.889999,16.493500,-141.271500,0.005135,0.003953,0.100399,73.366753,3.737480,1.003987,-141.271500,0.101483,0.000000
66.150002,16.741127,-141.315979,0.005161,0.003970,0.100850,74.468254,3.793594,1.008497,-141.315979,0.101916,0.000000
66.410004,16.894539,-141.315979,0.005178,0.003993,0.101422,75.150665,3.828357,1.014220,-141.315979,0.102350,0.000000
66.670006,16.846130,-141.360458,0.005204,0.004006,0.101760,74.935333,3.817388,1.017603,-141.360458,0.102784,0.000000
66.930000,16.878159,-141.360458,0.005208,0.004024,0.102211,75.077797,3.824646,1.022112,-141.360458,0.103217,0.000000
67.190002,17.235260,-141.360458,0.005217,0.004044,0.102723,76.666267,3.905566,1.027229,-141.360458,0.103651,0.000000
67.450005,16.988007,-141.449417,0.005256,0.004058,0.103061,75.566429,3.849537,1.030611,-141.449417,0.104084,0.000000
67.710007,16.780968,-141.449417,0.005256,0.004066,0.103269,74.645470,3.802622,1.032692,-141.449417,0.104518,0.000000
67.970001,17.629608,-141.449417,0.005269,0.004096,0.104041,78.420410,3.994926,1.040411,-141.449417,0.104952,0.000000
68.230003,17.543587,-141.493912,0.005290,0.004115,0.104518,78.037773,3.975434,1.045180,-141.493912,0.105385,0.000000
68.490005,17.430382,-141.449417,0.005320,0.004131,0.104926,77.534210,3.949781,1.049256,-141.449417,0.105819,0.000000
68.750000,17.421448,-141.627350,0.005329,0.004147,0.105325,77.494469,3.947757,1.053246,-141.627350,0.106252,0.000000
69.010002,17.611732,-141.582870,0.005346,0.004164,0.105758,78.340897,3.990876,1.057582,-141.582870,0.106686,0.000000
69.270004,17.609123,-141.627350,0.005381,0.004179,0.106148,78.329292,3.990284,1.061484,-141.627350,0.107111,0.000000
69.530006,17.474327,-141.627350,0.005376,0.004191,0.106452,77.729691,3.959739,1.064520,-141.627350,0.107545,0.000000
69.790001,17.751740,-141.627350,0.005407,0.004210,0.106929,78.963684,4.022602,1.069289,-141.627350,0.107978,0.000000
70.050003,18.309181,-141.671829,0.005424,0.004233,0.107527,81.443306,4.148920,1.075273,-141.671829,0.108412,0.000000
70.310005,17.967720,-141.716309,0.005424,0.004246,0.107857,79.924408,4.071544,1.078569,-141.716309,0.108845,0.000000
70.570000,18.048897,-141.716309,0.005463,0.004264,0.108316,80.285500,4.089939,1.083165,-141.716309,0.109279,0.000000
70.830002,18.104004,-141.760788,0.005476,0.004280,0.108724,80.530632,4.102426,1.087241,-141.760788,0.109713,0.000000
71.090004,18.534843,-141.760788,0.005493,0.004304,0.109331,82.447098,4.200056,1.093311,-141.760788,0.110146,0.000000
71.350006,18.132683,-141.849747,0.005523,0.004314,0.109574,80.658203,4.108925,1.095740,-141.849747,0.110580,0.000000
71.610001,18.111458,-141.849747,0.005523,0.004326,0.109886,80.563789,4.104115,1.098862,-141.849747,0.111014,0.000000
71.870003,18.433556,-141.894241,0.005562,0.004346,0.110380,81.996552,4.177104,1.103805,-141.894241,0.111447,0.000000
72.130005,18.696449,-141.894241,0.005549,0.004369,0.110979,83.165962,4.236676,1.109789,-141.894241,0.111881,0.000000
72.390007,18.500587,-141.894241,0.005566,0.004383,0.111317,82.294724,4.192293,1.113171,-141.894241,0.112314,0.000000
72.650002,18.764595,-141.983200,0.005592,0.004401,0.111794,83.469086,4.252118,1.117941,-141.983200,0.112748,0.000000
72.910004,18.993233,-141.894241,0.005614,0.004422,0.112314,84.486122,4.303928,1.123144,-141.894241,0.113182,0.000000
73.170006,19.085953,-141.983200,0.005635,0.004439,0.112739,84.898560,4.324939,1.127393,-141.983200,0.113615,0.000000
73.430000,18.925461,-141.983200,0.005657,0.004451,0.113060,84.184654,4.288571,1.130602,-141.983200,0.114049,0.000000
73.690002,19.449387,-141.983200,0.005670,0.004472,0.113598,86.515190,4.407294,1.135979,-141.983200,0.114482,0.000000
73.950005,19.267296,-142.072159,0.005696,0.004489,0.114032,85.705215,4.366032,1.140315,-142.072159,0.114916,0.000000
74.210007,18.982803,-142.161118,0.005704,0.004500,0.114300,84.439728,4.301565,1.143003,-142.161118,0.115350,0.000000
74.470001,19.359650,-142.116638,0.005734,0.004520,0.114812,86.116020,4.386960,1.148120,-142.116638,0.115783,0.000000
74.730003,19.546204,-142.161118,0.005730,0.004539,0.115280,86.945854,4.429233,1.152803,-142.161118,0.116217,0.000000
74.990005,19.700737,-142.116638,0.005773,0.004555,0.115688,87.633255,4.464251,1.156879,-142.116638,0.116651,0.000000
75.250000,19.452370,-142.205597,0.005769,0.004567,0.116000,86.528465,4.407970,1.160001,-142.205597,0.117084,0.000000
75.510002,19.649727,-142.205597,0.005803,0.004583,0.116408,87.406349,4.452692,1.164077,-142.205597,0.117518,0.000000
75.770004,19.673187,-142.205597,0.005812,0.004601,0.116876,87.510704,4.458008,1.168760,-142.205597,0.117951,0.000000
76.030006,20.165833,-142.250076,0.005829,0.004625,0.117483,89.702103,4.569643,1.174831,-142.250076,0.118385,0.000000
76.290001,20.062683,-142.339050,0.005838,0.004641,0.117882,89.243271,4.546269,1.178820,-142.339050,0.118819,0.000000
76.550003,20.066040,-142.383530,0.005859,0.004655,0.118238,89.258202,4.547029,1.182376,-142.383530,0.119252,0.000000
76.810005,20.161362,-142.339050,0.005890,0.004672,0.118680,89.682213,4.568630,1.186798,-142.339050,0.119686,0.000000
77.070007,20.323723,-142.383530,0.005898,0.004688,0.119079,90.404434,4.605422,1.190788,-142.383530,0.120119,0.000000
77.330002,20.317390,-142.383530,0.005902,0.004704,0.119486,90.376266,4.603987,1.194864,-142.383530,0.120553,0.000000
77.590004,20.906853,-142.428009,0.005920,0.004726,0.120041,92.998329,4.737560,1.200414,-142.428009,0.120987,0.000000
77.850006,21.004791,-142.472488,0.005954,0.004748,0.120588,93.433975,4.759754,1.205877,-142.472488,0.121420,0.000000
78.110001,20.786949,-142.516968,0.005954,0.004762,0.120961,92.464966,4.710390,1.209606,-142.516968,0.121854,0.000000
78.370003,20.639862,-142.516968,0.005997,0.004775,0.121282,91.810692,4.677060,1.212815,-142.516968,0.122279,0.000000
78.630005,20.754929,-142.516968,0.005984,0.004787,0.121602,92.322533,4.703134,1.216024,-142.516968,0.122712,0.000000
78.890007,21.256882,-142.561447,0.006006,0.004811,0.122209,94.555336,4.816878,1.222094,-142.561447,0.123146,0.000000
79.150002,21.329124,-142.650406,0.006028,0.004831,0.122712,94.876686,4.833249,1.227124,-142.650406,0.123580,0.000000
79.410004,21.462059,-142.605927,0.006036,0.004847,0.123120,95.468010,4.863372,1.231200,-142.605927,0.124013,0.000000
79.670006,21.687347,-142.605927,0.006079,0.004868,0.123658,96.470139,4.914423,1.236577,-142.605927,0.124447,0.000000
79.930000,21.502281,-142.650406,0.006092,0.004881,0.123987,95.646927,4.872487,1.239873,-142.650406,0.124881,0.000000
80.190002,21.487015,-142.650406,0.006114,0.004895,0.124334,95.579018,4.869027,1.243342,-142.650406,0.125314,0.000000
80.450005,21.656441,-142.783859,0.006101,0.004910,0.124707,96.332657,4.907420,1.247071,-142.783859,0.125748,0.000000
80.710007,21.933113,-142.694885,0.006165,0.004928,0.125175,97.563362,4.970114,1.251754,-142.694885,0.126181,0.000000
80.970001,22.152817,-142.828339,0.006148,0.004947,0.125661,98.540649,5.019900,1.256610,-142.828339,0.126615,0.000000
81.230003,21.681015,-142.783859,0.006178,0.004955,0.125869,96.441971,4.912988,1.258691,-142.783859,0.127049,0.000000
81.490005,22.802605,-142.828339,0.006204,0.004987,0.126658,101.431053,5.167144,1.266583,-142.828339,0.127482,0.000000
81.750008,22.595566,-142.828339,0.006222,0.005004,0.127092,100.510094,5.120228,1.270919,-142.828339,0.127916,0.000000
82.010002,22.416451,-142.783859,0.006243,0.005016,0.127395,99.713348,5.079640,1.273955,-142.783859,0.128349,0.000000
82.270004,22.579178,-142.917297,0.006239,0.005033,0.127838,100.437202,5.116515,1.278377,-142.917297,0.128783,0.000000
82.530006,22.439911,-142.917297,0.006256,0.005043,0.128098,99.817711,5.084956,1.280979,-142.917297,0.129217,0.000000
82.790001,22.857346,-142.961777,0.006295,0.005064,0.128627,101.674553,5.179548,1.286269,-142.961777,0.129650,0.000000
83.050003,22.879684,-143.050735,0.006299,0.005079,0.129017,101.773918,5.184610,1.290172,-143.050735,0.130084,0.000000
83.310005,22.925858,-143.006256,0.006299,0.005093,0.129364,101.979309,5.195074,1.293641,-143.006256,0.130517,0.000000
83.570007,23.775986,-143.095215,0.006342,0.005124,0.130145,105.760864,5.387715,1.301446,-143.095215,0.130951,0.000000
83.830002,23.522400,-143.050735,0.006347,0.005138,0.130509,104.632858,5.330252,1.305088,-143.050735,0.131385,0.000000
84.090004,23.278496,-143.139694,0.006364,0.005148,0.130760,103.547920,5.274982,1.307603,-143.139694,0.131818,0.000000
84.350006,23.443085,-143.139694,0.006390,0.005163,0.131151,104.280052,5.312279,1.311505,-143.139694,0.132252,0.000000
84.610001,24.148727,-143.095215,0.006381,0.005189,0.131792,107.418907,5.472180,1.317923,-143.095215,0.132686,0.000000
84.870003,24.101067,-143.139694,0.006428,0.005204,0.132191,107.206902,5.461380,1.321912,-143.139694,0.133119,0.000000
85.130005,24.054893,-143.228668,0.006433,0.005218,0.132538,107.001511,5.450917,1.325381,-143.228668,0.133553,0.000000
85.390007,24.438805,-143.273148,0.006437,0.005239,0.133067,108.709229,5.537912,1.330671,-143.273148,0.133986,0.000000
85.650002,24.508438,-143.228668,0.006454,0.005255,0.133466,109.018974,5.553691,1.334660,-143.228668,0.134420,0.000000
85.910004,24.244431,-143.273148,0.006467,0.005265,0.133735,107.844612,5.493866,1.337349,-143.273148,0.134854,0.000000
86.170006,24.632439,-143.273148,0.006502,0.005284,0.134212,109.570557,5.581790,1.342119,-143.273148,0.135287,0.000000
86.430000,24.581055,-143.273148,0.006502,0.005298,0.134559,109.341995,5.570147,1.345587,-143.273148,0.135721,0.000000
86.690002,25.419266,-143.362106,0.006523,0.005326,0.135270,113.070541,5.760088,1.352699,-143.362106,0.136154,0.000000
86.950005,25.065880,-143.362106,0.006536,0.005336,0.135539,111.498604,5.680009,1.355387,-143.362106,0.136588,0.000000
87.210007,25.138496,-143.362106,0.006549,0.005350,0.135886,111.821617,5.696465,1.358856,-143.362106,0.137013,0.000000
87.470001,25.539543,-143.495544,0.006558,0.005369,0.136371,113.605560,5.787343,1.363712,-143.495544,0.137447,0.000000
87.730003,25.840790,-143.362106,0.006592,0.005390,0.136909,114.945572,5.855607,1.369089,-143.362106,0.137880,0.000000
87.990005,25.810997,-143.495544,0.006605,0.005405,0.137282,114.813049,5.848855,1.372818,-143.495544,0.138314,0.000000
88.250008,25.867226,-143.540024,0.006618,0.005420,0.137663,115.063164,5.861598,1.376634,-143.540024,0.138747,0.000000
88.510002,26.473824,-143.540024,0.006635,0.005442,0.138236,117.761452,5.999054,1.382358,-143.540024,0.139181,0.000000
88.770004,26.305511,-143.584503,0.006670,0.005456,0.138583,117.012756,5.960914,1.385827,-143.584503,0.139615,0.000000
89.030006,26.081718,-143.540024,0.006661,0.005464,0.138791,116.017281,5.910202,1.387908,-143.540024,0.140048,0.000000
89.290001,27.224152,-143.628998,0.006679,0.005495,0.139571,121.099075,6.169081,1.395713,-143.628998,0.140482,0.000000
89.550003,27.299004,-143.584503,0.006704,0.005513,0.140031,121.432030,6.186042,1.400309,-143.584503,0.140915,0.000000
89.810005,27.245003,-143.628998,0.006748,0.005529,0.140447,121.191826,6.173806,1.404472,-143.628998,0.141349,0.000000
90.070007,27.171646,-143.717957,0.006739,0.005545,0.140837,120.865517,6.157183,1.408375,-143.717957,0.141783,0.000000
90.330002,27.595779,-143.628998,0.006748,0.005562,0.141280,122.752159,6.253293,1.412797,-143.628998,0.142216,0.000000
90.590004,27.748085,-143.762436,0.006760,0.005578,0.141679,123.429649,6.287806,1.416787,-143.762436,0.142650,0.000000
90.850006,27.678452,-143.673477,0.006778,0.005589,0.141965,123.119904,6.272027,1.419649,-143.673477,0.143084,0.000000
91.110001,28.131256,-143.806915,0.006804,0.005609,0.142468,125.134079,6.374634,1.424678,-143.806915,0.143517,0.000000
91.370003,28.315208,-143.851395,0.006812,0.005629,0.142988,125.952339,6.416318,1.429882,-143.851395,0.143951,0.000000
91.630005,28.735985,-143.762436,0.006842,0.005645,0.143387,127.824043,6.511667,1.433871,-143.762436,0.144384,0.000000
91.890007,28.844719,-143.851395,0.006842,0.005663,0.143838,128.307724,6.536307,1.438380,-143.851395,0.144818,0.000000
92.150002,29.039841,-143.851395,0.006881,0.005679,0.144246,129.175659,6.580522,1.442457,-143.851395,0.145252,0.000000
92.410004,29.610687,-143.851395,0.006877,0.005703,0.144853,131.714920,6.709878,1.448527,-143.851395,0.145685,0.000000
92.670006,29.343323,-143.940353,0.006898,0.005712,0.145096,130.525620,6.649292,1.450955,-143.940353,0.146119,0.000000
92.930008,28.952705,-143.851395,0.006920,0.005718,0.145226,128.788071,6.560777,1.452256,-143.851395,0.146552,0.000000
93.190002,29.991257,-144.029312,0.006933,0.005745,0.145928,133.407776,6.796116,1.459281,-144.029312,0.146986,0.000000
93.450005,30.507736,-143.984833,0.006954,0.005769,0.146526,135.705185,6.913152,1.465265,-143.984833,0.147420,0.000000
93.710007,30.447037,-144.029312,0.006985,0.005784,0.146925,135.435181,6.899397,1.469254,-144.029312,0.147853,0.000000
93.970001,30.675674,-143.984833,0.006972,0.005800,0.147324,136.452209,6.951207,1.473243,-143.984833,0.148287,0.000000
94.230003,31.002243,-144.029312,0.007006,0.005820,0.147827,137.904861,7.025209,1.478273,-144.029312,0.148721,0.000000
94.490005,31.377968,-144.118286,0.007002,0.005837,0.148270,139.576172,7.110349,1.482696,-144.118286,0.149154,0.000000
94.750008,31.268120,-144.118286,0.007015,0.005849,0.148564,139.087540,7.085457,1.485644,-144.118286,0.149588,0.000000
95.010002,31.887375,-144.162766,0.007045,0.005870,0.149102,141.842133,7.225782,1.491021,-144.162766,0.150021,0.000000
95.270004,32.051964,-144.118286,0.007080,0.005888,0.149553,142.574249,7.263079,1.495531,-144.118286,0.150455,0.000000
95.530006,31.866150,-144.207245,0.007084,0.005900,0.149865,141.747711,7.220973,1.498653,-144.207245,0.150889,0.000000
95.790001,32.383003,-144.296204,0.007092,0.005919,0.150342,144.046799,7.338093,1.503422,-144.296204,0.151322,0.000000
96.050003,32.787773,-144.251724,0.007110,0.005938,0.150819,145.847305,7.429816,1.508192,-144.251724,0.151756,0.000000
96.310005,33.048058,-144.385162,0.007131,0.005953,0.151209,147.005096,7.488797,1.512095,-144.385162,0.152181,0.000000
96.570007,33.068542,-144.296204,0.007157,0.005967,0.151565,147.096222,7.493439,1.515650,-144.296204,0.152614,0.000000
96.830002,33.237221,-144.296204,0.007166,0.005982,0.151947,147.846542,7.531662,1.519466,-144.296204,0.153048,0.000000
97.090004,33.449104,-144.429642,0.007174,0.006000,0.152389,148.789047,7.579676,1.523889,-144.429642,0.153482,0.000000
97.350006,33.055138,-144.340683,0.007192,0.005998,0.152354,147.036591,7.490401,1.523542,-144.340683,0.152554,0.000000
97.610008,32.414284,-144.429642,0.007205,0.005998,0.152346,144.185928,7.345182,1.523456,-144.429642,0.152346,0.000000
97.870003,31.881042,-144.429642,0.007213,0.005989,0.152129,141.813965,7.224347,1.521287,-144.429642,0.151912,0.000000
98.130005,31.539948,-144.429642,0.007213,0.005973,0.151704,140.296692,7.147054,1.517038,-144.429642,0.151478,0.000000
98.390007,31.326584,-144.518616,0.007205,0.005961,0.151409,139.347610,7.098705,1.514089,-144.518616,0.151045,0.000000
98.650002,31.063683,-144.474136,0.007222,0.005948,0.151079,138.178162,7.039131,1.510794,-144.474136,0.150611,0.000000
98.910004,30.848824,-144.518616,0.007209,0.005934,0.150715,137.222427,6.990443,1.507152,-144.518616,0.150177,0.000000
99.170006,30.736740,-144.563095,0.007196,0.005921,0.150403,136.723846,6.965045,1.504030,-144.563095,0.149744,0.000000
99.430008,30.555771,-144.607574,0.007213,0.005900,0.149865,135.918854,6.924037,1.498653,-144.607574,0.149310,0.000000
99.690002,30.405701,-144.652054,0.007222,0.005883,0.149423,135.251312,6.890030,1.494230,-144.652054,0.148877,0.000000
99.950005,30.291756,-144.652054,0.007217,0.005864,0.148937,134.744461,6.864210,1.489373,-144.652054,0.148443,0.000000
100.210007,30.182655,-144.652054,0.007209,0.005845,0.148460,134.259155,6.839488,1.484604,-144.652054,0.148009,0.000000
100.470001,30.075783,-144.652054,0.007209,0.005832,0.148131,133.783768,6.815270,1.481308,-144.652054,0.147576,0.000000
100.730003,29.984550,-144.785492,0.007235,0.005819,0.147793,133.377945,6.794596,1.477926,-144.785492,0.147142,0.000000
100.990005,29.887733,-144.785492,0.007192,0.005805,0.147454,132.947281,6.772657,1.474544,-144.785492,0.146709,0.000000
101.250008,29.788307,-144.741013,0.007239,0.005795,0.147203,132.505005,6.750127,1.472029,-144.741013,0.146275,0.000000
101.510002,29.580902,-144.785492,0.007235,0.005768,0.146500,131.582428,6.703128,1.465004,-144.785492,0.145841,0.000000
101.770004,29.391365,-144.829971,0.007226,0.005749,0.146023,130.739319,6.660178,1.460235,-144.829971,0.145408,0.000000
102.030006,28.907646,-144.874451,0.007222,0.005732,0.145599,128.587631,6.550566,1.455985,-144.874451,0.144974,0.000000
102.290009,28.558365,-144.874451,0.007230,0.005722,0.145330,127.033951,6.471418,1.453297,-144.874451,0.144541,0.000000
102.550003,28.136467,-144.874451,0.007239,0.005709,0.145000,125.157257,6.375814,1.450001,-144.874451,0.144116,0.000000
102.810005,27.891441,-144.963425,0.007235,0.005705,0.144913,124.067329,6.320291,1.449134,-144.963425,0.143682,0.000000
103.070007,26.638039,-144.918945,0.007230,0.005676,0.144168,118.491913,6.036266,1.441676,-144.918945,0.143248,0.000000
103.330002,26.112991,-145.007904,0.007239,0.005671,0.144055,116.156387,5.917288,1.440549,-145.007904,0.142815,0.000000
103.590004,24.570625,-145.052383,0.007226,0.005642,0.143300,109.295601,5.567783,1.433004,-145.052383,0.142381,0.000000
103.850006,23.396912,-145.052383,0.007248,0.005624,0.142841,104.074661,5.301816,1.428408,-145.052383,0.141947,0.000000
104.110008,22.314049,-145.141342,0.007239,0.005608,0.142433,99.257843,5.056436,1.424331,-145.141342,0.141514,0.000000
104.370003,21.349236,-145.096863,0.007256,0.005593,0.142060,94.966141,4.837806,1.420602,-145.096863,0.141080,0.000000
104.630005,20.373993,-145.185822,0.007243,0.005580,0.141731,90.628044,4.616813,1.417307,-145.185822,0.140647,0.000000
104.890007,19.458328,-145.141342,0.007235,0.005569,0.141445,86.554970,4.409320,1.414445,-145.141342,0.140213,0.000000
105.150002,17.818771,-145.141342,0.007239,0.005546,0.140863,79.261856,4.037791,1.408635,-145.141342,0.139779,0.000000
105.410004,16.023933,-145.230301,0.007226,0.005525,0.140326,71.278015,3.631075,1.403258,-145.230301,0.139346,0.000000
105.670006,15.149231,-145.230301,0.007222,0.005515,0.140092,67.387146,3.432865,1.400916,-145.230301,0.138912,0.000000
105.930008,13.367058,-145.274780,0.007239,0.005492,0.139485,59.459644,3.029019,1.394846,-145.274780,0.138479,0.000000
106.190002,11.705902,-145.230301,0.007222,0.005469,0.138921,52.070454,2.652596,1.389209,-145.230301,0.138045,0.000000
106.450005,10.618202,-145.319260,0.007222,0.005458,0.138643,47.232121,2.406119,1.386434,-145.319260,0.137611,0.000000
106.710007,10.036560,-145.363754,0.007222,0.005450,0.138435,44.644848,2.274317,1.384352,-145.363754,0.137178,0.000000
106.970009,8.709053,-145.274780,0.007205,0.005433,0.137993,38.739803,1.973500,1.379930,-145.274780,0.136744,0.000000
107.230003,6.991669,-145.452713,0.007205,0.005408,0.137369,31.100496,1.584335,1.373685,-145.452713,0.136311,0.000000
107.490005,5.629532,-145.408234,0.007187,0.005391,0.136944,25.041409,1.275670,1.369436,-145.408234,0.135877,0.000000
107.750008,4.227547,-145.452713,0.007187,0.005370,0.136397,18.805067,0.957976,1.363973,-145.452713,0.135443,0.000000
108.010002,3.324173,-145.408234,0.007183,0.005357,0.136059,14.786660,0.753268,1.360590,-145.408234,0.135010,0.000000
108.270004,2.099442,-145.452713,0.007157,0.005336,0.135530,9.338782,0.475740,1.355300,-145.452713,0.134576,0.000000
108.530006,1.589661,-145.586151,0.007140,0.005326,0.135270,7.071164,0.360222,1.352699,-145.586151,0.134142,0.000000
108.790009,1.173347,-145.541672,0.007144,0.005313,0.134940,5.219310,0.265884,1.349403,-145.541672,0.133709,0.000000
109.050003,0.322105,-145.586151,0.007118,0.005289,0.134342,1.432796,0.072990,1.343419,-145.586151,0.133275,0.000000
109.200005,0.429718,-145.586151,0.007131,0.005290,0.134368,1.911481,0.097375,1.343680,-145.586151,0.134212,0.000000