File: Data/compression 8/AutoHeating-17-8-1-4-240328_03282024_154142.csv
Time (sec),S:Load (lbs),S:HL1 (DIM),S:LVDT (in),S:Position (in),Ch:Position (mm),Ch:Load (N),Ch:Stress (MPa),Ch:Strain (mm/mm),Ch:HL1 (DIM),Set Point (),Cycles ()
0.110000,-0.008934,-162.577881,0.000017,-0.000000,-0.000000,-0.039741,-0.002024,-0.000000,-162.577881,-0.000260,0.000000
0.330000,-0.012283,-162.622360,0.000000,-0.000000,-0.000000,-0.054639,-0.002783,-0.000000,-162.622360,-0.000260,0.000000
0.550000,0.008568,-162.622360,0.000004,0.000074,0.001891,0.038112,0.001941,0.018906,-162.622360,0.002515,0.000000
0.770000,0.008568,-162.622360,0.000069,0.000210,0.005325,0.038112,0.001941,0.053250,-162.622360,0.006175,0.000000
0.990000,-0.038353,-162.577881,0.000220,0.000349,0.008872,-0.170603,-0.008691,0.088718,-162.577881,0.009834,0.000000
1.210000,-0.055107,-162.622360,0.000358,0.000490,0.012445,-0.245129,-0.012487,0.124447,-162.622360,0.013494,0.000000
1.430000,-0.004463,-162.666840,0.000504,0.000639,0.016243,-0.019853,-0.001011,0.162433,-162.666840,0.017171,0.000000
1.650000,0.011917,-162.622360,0.000642,0.000783,0.019894,0.053010,0.002700,0.198942,-162.622360,0.020831,0.000000
1.870000,0.018623,-162.666840,0.000798,0.000923,0.023441,0.082841,0.004220,0.234410,-162.666840,0.024491,0.000000
2.090000,0.017136,-162.622360,0.000936,0.001059,0.026910,0.076223,0.003883,0.269102,-162.622360,0.028168,0.000000
2.310000,0.010429,-162.622360,0.001078,0.001208,0.030691,0.046392,0.002363,0.306910,-162.622360,0.031827,0.000000
2.530000,-0.011543,-162.666840,0.001237,0.001359,0.034524,-0.051347,-0.002616,0.345243,-162.666840,0.035487,0.000000
2.750000,-0.043190,-162.711319,0.001375,0.001499,0.038071,-0.192119,-0.009787,0.380711,-162.711319,0.039164,0.000000
2.970000,-0.039841,-162.711319,0.001518,0.001640,0.041653,-0.177220,-0.009028,0.416528,-162.711319,0.042824,0.000000
3.190000,-0.027550,-162.666840,0.001699,0.001793,0.045538,-0.122547,-0.006243,0.455380,-162.666840,0.046483,0.000000
3.410000,0.016388,-162.666840,0.001828,0.001933,0.049102,0.072897,0.003714,0.491022,-162.666840,0.050160,0.000000
3.630000,0.039848,-162.666840,0.001957,0.002070,0.052571,0.177254,0.009030,0.525711,-162.666840,0.053820,0.000000
3.850000,0.029793,-162.711319,0.002108,0.002219,0.056370,0.132525,0.006751,0.563696,-162.711319,0.057480,0.000000
4.070000,0.038727,-162.666840,0.002272,0.002371,0.060220,0.172265,0.008776,0.602203,-162.666840,0.061157,0.000000
4.290000,0.014153,-162.711319,0.002410,0.002511,0.063767,0.062954,0.003207,0.637672,-162.711319,0.064816,0.000000
4.510000,-0.008560,-162.711319,0.002544,0.002653,0.067392,-0.038078,-0.001940,0.673919,-162.711319,0.068476,0.000000
4.730000,-0.017502,-162.711319,0.002695,0.002796,0.071008,-0.077852,-0.003966,0.710084,-162.711319,0.072136,0.000000
4.950000,0.009315,-162.800278,0.002837,0.002942,0.074720,0.041437,0.002111,0.747203,-162.800278,0.075813,0.000000
5.170000,0.012291,-162.800278,0.002988,0.003084,0.078328,0.054673,0.002785,0.783280,-162.800278,0.079473,0.000000
5.390000,0.013405,-162.800278,0.003134,0.003230,0.082048,0.059628,0.003038,0.820482,-162.800278,0.083132,0.000000
5.610000,0.029419,-162.711319,0.003290,0.003376,0.085751,0.130862,0.006666,0.857513,-162.711319,0.086809,0.000000
5.830000,0.019363,-162.711319,0.003432,0.003523,0.089489,0.086133,0.004388,0.894889,-162.711319,0.090469,0.000000
6.050000,-0.010048,-162.755798,0.003574,0.003664,0.093071,-0.044695,-0.002277,0.930706,-162.755798,0.094129,0.000000
6.270000,0.005592,-162.800278,0.003729,0.003809,0.096739,0.024876,0.001267,0.967389,-162.800278,0.097806,0.000000
6.490000,0.026817,-162.755798,0.003872,0.003953,0.100408,0.119289,0.006077,1.004076,-162.755798,0.101465,0.000000
6.710001,0.009682,-162.800278,0.004014,0.004094,0.103989,0.043066,0.002194,1.039892,-162.800278,0.105125,0.000000
6.930000,0.041336,-162.800278,0.004139,0.004234,0.107553,0.183872,0.009367,1.075535,-162.800278,0.108802,0.000000
7.150001,0.008942,-162.844757,0.004299,0.004388,0.111456,0.039774,0.002026,1.114557,-162.844757,0.112462,0.000000
7.370000,0.039101,-162.800278,0.004458,0.004536,0.115211,0.173928,0.008860,1.152111,-162.800278,0.116122,0.000000
7.590000,0.428230,-162.800278,0.004592,0.004676,0.118767,1.904863,0.097038,1.187666,-162.800278,0.119799,0.000000
7.810000,0.668037,-162.844757,0.004626,-0.000000,-0.000000,2.971579,0.151379,-0.000000,-162.844757,0.000234,0.000000
8.030001,0.630058,-162.844757,0.004626,-0.000000,-0.000000,2.802639,0.142773,-0.000000,-162.844757,0.000234,0.000000
8.250000,0.649048,-162.800278,0.004635,-0.000000,-0.000000,2.887109,0.147076,-0.000000,-162.800278,0.000364,0.000000
8.470000,0.638618,-162.844757,0.004626,0.000000,0.000009,2.840717,0.144713,0.000087,-162.844757,0.000737,0.000000
8.690001,0.618141,-162.755798,0.004639,0.000000,0.000009,2.749629,0.140073,0.000087,-162.755798,0.001101,0.000000
8.910001,0.645325,-162.844757,0.004631,0.000011,0.000277,2.870548,0.146233,0.002774,-162.844757,0.001466,0.000000
9.130000,1.045624,-162.844757,0.004652,0.000035,0.000885,4.651167,0.236942,0.008845,-162.844757,0.001830,0.000000
9.350000,1.250801,-162.889236,0.004656,0.000050,0.001257,5.563841,0.283436,0.012573,-162.889236,0.002203,0.000000
9.570001,1.507736,-162.889236,0.004687,0.000071,0.001804,6.706746,0.341658,0.018039,-162.889236,0.002567,0.000000
9.790001,1.684990,-162.844757,0.004704,0.000083,0.002107,7.495210,0.381824,0.021074,-162.844757,0.002931,0.000000
10.010000,1.785530,-162.933731,0.004700,0.000094,0.002385,7.942434,0.404607,0.023849,-162.933731,0.003304,0.000000
10.230000,2.020866,-162.889236,0.004717,0.000108,0.002740,8.989263,0.457935,0.027403,-162.889236,0.003668,0.000000
10.450001,2.337013,-162.933731,0.004730,0.000128,0.003243,10.395555,0.529575,0.032433,-162.933731,0.004032,0.000000
10.670000,2.597672,-162.889236,0.004747,0.000143,0.003633,11.555020,0.588641,0.036335,-162.889236,0.004397,0.000000
10.890000,2.779022,-162.933731,0.004756,0.000154,0.003920,12.361709,0.629735,0.039196,-162.933731,0.004770,0.000000
11.110001,2.893333,-162.889236,0.004764,0.000163,0.004137,12.870190,0.655639,0.041365,-162.889236,0.005134,0.000000
11.330001,3.146553,-162.933731,0.004764,0.000175,0.004449,13.996567,0.713019,0.044488,-162.933731,0.005498,0.000000
11.550000,3.677925,-162.889236,0.004786,0.000201,0.005116,16.360228,0.833430,0.051164,-162.889236,0.005871,0.000000
11.770000,3.762085,-162.978210,0.004803,0.000211,0.005351,16.734591,0.852501,0.053507,-162.978210,0.006235,0.000000
11.990001,4.047318,-162.933731,0.004812,0.000228,0.005784,18.003366,0.917135,0.057845,-162.933731,0.006599,0.000000
12.210001,4.234993,-162.889236,0.004825,0.000239,0.006071,18.838190,0.959663,0.060706,-162.889236,0.006964,0.000000
12.430000,4.522842,-162.978210,0.004846,0.000255,0.006487,20.118608,1.024891,0.064869,-162.978210,0.007337,0.000000
12.650001,4.874733,-162.978210,0.004846,0.000273,0.006929,21.683895,1.104630,0.069290,-162.978210,0.007701,0.000000
12.870001,5.040810,-162.933731,0.004863,0.000283,0.007181,22.422642,1.142264,0.071807,-162.933731,0.008065,0.000000
13.090000,5.175980,-162.978210,0.004881,0.000293,0.007449,23.023907,1.172894,0.074494,-162.978210,0.008438,0.000000
13.310000,5.739754,-162.978210,0.004902,0.000317,0.008048,25.531700,1.300647,0.080478,-162.978210,0.008802,0.000000
13.530001,5.946419,-162.978210,0.004907,0.000333,0.008447,26.450993,1.347478,0.084468,-162.978210,0.009167,0.000000
13.750001,6.080475,-163.022690,0.004919,0.000345,0.008768,27.047302,1.377855,0.087677,-163.022690,0.009531,0.000000
13.970000,6.210060,-163.022690,0.004945,0.000357,0.009071,27.623728,1.407220,0.090713,-163.022690,0.009904,0.000000
14.190001,6.430878,-162.978210,0.004958,0.000374,0.009496,28.605972,1.457258,0.094959,-162.978210,0.010268,0.000000
14.410001,6.764153,-163.022690,0.004958,0.000390,0.009904,30.088453,1.532779,0.099036,-163.022690,0.010632,0.000000
14.630001,6.900436,-162.978210,0.004984,0.000402,0.010216,30.694674,1.563661,0.102158,-162.978210,0.011005,0.000000
14.850000,7.022575,-163.022690,0.004984,0.000413,0.010485,31.237976,1.591338,0.104845,-163.022690,0.011369,0.000000
15.070001,6.902672,-163.022690,0.004997,0.000422,0.010719,30.704618,1.564168,0.107188,-163.022690,0.011734,0.000000
15.290001,7.693588,-163.022690,0.005014,0.000449,0.011395,34.222790,1.743392,0.113952,-163.022690,0.012098,0.000000
15.510001,7.793015,-163.022690,0.005023,0.000461,0.011707,34.665058,1.765922,0.117074,-163.022690,0.012470,0.000000
15.730000,7.805672,-163.067169,0.005040,0.000475,0.012055,34.721363,1.768790,0.120545,-163.067169,0.012835,0.000000
15.950001,7.963562,-163.067169,0.005053,0.000488,0.012393,35.423695,1.804569,0.123925,-163.067169,0.013199,0.000000
16.170000,8.142296,-163.111649,0.005075,0.000502,0.012748,36.218742,1.845071,0.127483,-163.111649,0.013563,0.000000
16.390001,8.255501,-163.067169,0.005092,0.000513,0.013034,36.722301,1.870723,0.130344,-163.067169,0.013936,0.000000
16.610001,8.436470,-162.978210,0.005101,0.000529,0.013433,37.527294,1.911731,0.134333,-162.978210,0.014300,0.000000
16.830000,8.489723,-163.111649,0.005096,0.000540,0.013711,37.764175,1.923799,0.137108,-163.111649,0.014665,0.000000
17.050001,8.520630,-163.111649,0.005105,0.000550,0.013971,37.901653,1.930802,0.139708,-163.111649,0.015038,0.000000
17.270000,8.914597,-163.156128,0.005135,0.000574,0.014587,39.654106,2.020077,0.145866,-163.156128,0.015402,0.000000
17.490002,9.093712,-163.111649,0.005157,0.000588,0.014942,40.450851,2.060664,0.149420,-163.111649,0.015766,0.000000
17.710001,9.107864,-163.067169,0.005165,0.000601,0.015272,40.513805,2.063872,0.152717,-163.067169,0.016130,0.000000
17.930000,9.155151,-163.111649,0.005174,0.000614,0.015593,40.724148,2.074587,0.155926,-163.111649,0.016503,0.000000
18.150002,9.231491,-163.200607,0.005178,0.000629,0.015974,41.063725,2.091886,0.159741,-163.200607,0.016867,0.000000
18.370001,9.407249,-163.156128,0.005204,0.000644,0.016347,41.845535,2.131713,0.163470,-163.156128,0.017231,0.000000
18.590000,9.609818,-163.156128,0.005226,0.000660,0.016772,42.746605,2.177616,0.167720,-163.156128,0.017605,0.000000
18.810001,9.466080,-163.067169,0.005238,0.000668,0.016971,42.107227,2.145044,0.169715,-163.067169,0.017969,0.000000
19.030001,9.525665,-163.111649,0.005238,0.000681,0.017292,42.372276,2.158547,0.172924,-163.111649,0.018333,0.000000
19.250000,9.868988,-163.111649,0.005251,0.000699,0.017761,43.899452,2.236345,0.177606,-163.111649,0.018697,0.000000
19.470001,10.095764,-163.156128,0.005282,0.000719,0.018264,44.908203,2.287733,0.182636,-163.156128,0.019070,0.000000
19.690001,10.064117,-163.200607,0.005290,0.000733,0.018611,44.767429,2.280561,0.186107,-163.200607,0.019434,0.000000
19.910002,10.099861,-163.156128,0.005307,0.000745,0.018931,44.926426,2.288661,0.189313,-163.156128,0.019799,0.000000
20.130001,10.019058,-163.156128,0.005307,0.000758,0.019252,44.566998,2.270351,0.192522,-163.156128,0.020172,0.000000
20.350000,10.357544,-163.156128,0.005316,0.000774,0.019669,46.072655,2.347053,0.196686,-163.156128,0.020536,0.000000
20.570002,10.384354,-163.245087,0.005346,0.000789,0.020041,46.191914,2.353128,0.200414,-163.245087,0.020900,0.000000
20.790001,10.301315,-163.245087,0.005351,0.000795,0.020198,45.822540,2.334311,0.201977,-163.245087,0.021264,0.000000
21.010000,10.465530,-163.111649,0.005381,0.000813,0.020648,46.553005,2.371523,0.206485,-163.111649,0.021637,0.000000
21.230001,10.814819,-163.245087,0.005389,0.000833,0.021152,48.106720,2.450673,0.211515,-163.245087,0.022002,0.000000
21.450001,10.918335,-163.200607,0.005402,0.000850,0.021594,48.567181,2.474130,0.215940,-163.200607,0.022366,0.000000
21.670000,10.884819,-163.289566,0.005428,0.000863,0.021915,48.418095,2.466535,0.219145,-163.289566,0.022739,0.000000
21.890001,10.879608,-163.289566,0.005428,0.000873,0.022175,48.394913,2.465354,0.221749,-163.289566,0.023103,0.000000
22.110001,10.927277,-163.289566,0.005450,0.000888,0.022548,48.606953,2.476156,0.225478,-163.289566,0.023467,0.000000
22.330002,11.218468,-163.289566,0.005458,0.000905,0.022982,49.902237,2.542141,0.229815,-163.289566,0.023831,0.000000
22.550001,11.312309,-163.200607,0.005476,0.000919,0.023354,50.319664,2.563406,0.233543,-163.200607,0.024204,0.000000
22.770000,11.118301,-163.245087,0.005480,0.000926,0.023510,49.456676,2.519443,0.235103,-163.245087,0.024569,0.000000
22.990002,11.313049,-163.289566,0.005493,0.000946,0.024022,50.322956,2.563574,0.240220,-163.289566,0.024933,0.000000
23.210001,11.804955,-163.289566,0.005514,0.000968,0.024594,52.511059,2.675041,0.245942,-163.289566,0.025305,0.000000
23.430000,11.641113,-163.245087,0.005536,0.000978,0.024829,51.782257,2.637914,0.248285,-163.245087,0.025670,0.000000
23.650002,11.624352,-163.289566,0.005549,0.000991,0.025167,51.707699,2.634116,0.251669,-163.289566,0.026034,0.000000
23.870001,11.663826,-163.289566,0.005549,0.001003,0.025479,51.883289,2.643061,0.254792,-163.289566,0.026398,0.000000
24.090002,11.756546,-163.289566,0.005570,0.001017,0.025843,52.295727,2.664072,0.258433,-163.289566,0.026771,0.000000
24.310001,12.013107,-163.289566,0.005583,0.001032,0.026216,53.436970,2.722209,0.262161,-163.289566,0.027135,0.000000
24.530001,12.039551,-163.289566,0.005601,0.001046,0.026580,53.554596,2.728201,0.265802,-163.289566,0.027500,0.000000
24.750002,11.960609,-163.289566,0.005609,0.001058,0.026875,53.203449,2.710313,0.268754,-163.289566,0.027872,0.000000
24.970001,12.580978,-163.334045,0.005627,0.001083,0.027517,55.962986,2.850890,0.275169,-163.334045,0.028237,0.000000
25.190001,12.643913,-163.334045,0.005652,0.001099,0.027907,56.242935,2.865152,0.279072,-163.334045,0.028601,0.000000
25.410002,12.461075,-163.289566,0.005661,0.001108,0.028150,55.429630,2.823720,0.281502,-163.289566,0.028965,0.000000
25.630001,12.468895,-163.289566,0.005670,0.001122,0.028506,55.464417,2.825492,0.285056,-163.289566,0.029338,0.000000
25.850000,12.448418,-163.334045,0.005687,0.001132,0.028757,55.373329,2.820852,0.287573,-163.334045,0.029702,0.000000
26.070002,12.586189,-163.334045,0.005700,0.001148,0.029147,55.986168,2.852071,0.291475,-163.334045,0.030066,0.000000
26.290001,12.967499,-163.378540,0.005713,0.001165,0.029590,57.682316,2.938477,0.295896,-163.378540,0.030440,0.000000
26.510002,12.900848,-163.378540,0.005730,0.001176,0.029859,57.385841,2.923374,0.298587,-163.378540,0.030804,0.000000
26.730001,13.006599,-163.334045,0.005726,0.001189,0.030188,57.856243,2.947337,0.301879,-163.334045,0.031168,0.000000
26.950001,13.265770,-163.334045,0.005747,0.001207,0.030665,59.009090,3.006066,0.306648,-163.334045,0.031532,0.000000
27.170002,13.595322,-163.378540,0.005764,0.001227,0.031177,60.475010,3.080744,0.311766,-163.378540,0.031905,0.000000
27.390001,13.441902,-163.378540,0.005790,0.001237,0.031420,59.792568,3.045979,0.314195,-163.378540,0.032269,0.000000
27.610001,13.380836,-163.378540,0.005808,0.001250,0.031741,59.520935,3.032141,0.317405,-163.378540,0.032634,0.000000
27.830002,13.572983,-163.334045,0.005816,0.001267,0.032174,60.375645,3.075682,0.321739,-163.334045,0.033007,0.000000
28.050001,13.834381,-163.334045,0.005829,0.001284,0.032608,61.538399,3.134916,0.326076,-163.334045,0.033371,0.000000
28.270000,13.828430,-163.378540,0.005833,0.001295,0.032902,61.511929,3.133567,0.329025,-163.378540,0.033735,0.000000
28.490002,13.807205,-163.423019,0.005851,0.001306,0.033171,61.417515,3.128757,0.331712,-163.423019,0.034099,0.000000
28.710001,13.780762,-163.467499,0.005868,0.001320,0.033527,61.299889,3.122765,0.335270,-163.467499,0.034472,0.000000
28.930002,14.160583,-163.423019,0.005881,0.001339,0.034013,62.989422,3.208834,0.340126,-163.423019,0.034836,0.000000
29.150002,14.437630,-163.423019,0.005898,0.001356,0.034455,64.221786,3.271614,0.344547,-163.423019,0.035201,0.000000
29.370001,14.319962,-163.423019,0.005902,0.001368,0.034741,63.698372,3.244950,0.347408,-163.423019,0.035565,0.000000
29.590002,14.306557,-163.467499,0.005920,0.001379,0.035019,63.638744,3.241912,0.350186,-163.467499,0.035938,0.000000
29.810001,14.398155,-163.467499,0.005941,0.001393,0.035383,64.046196,3.262669,0.353827,-163.467499,0.036302,0.000000
30.030001,14.683022,-163.467499,0.005963,0.001410,0.035825,65.313339,3.327220,0.358252,-163.467499,0.036666,0.000000
30.250002,14.837181,-163.467499,0.005967,0.001424,0.036181,65.999077,3.362153,0.361806,-163.467499,0.037039,0.000000
30.470001,14.675949,-163.511978,0.005971,0.001433,0.036389,65.281883,3.325618,0.363887,-163.511978,0.037403,0.000000
30.690001,14.904587,-163.467499,0.005976,0.001449,0.036796,66.298912,3.377428,0.367964,-163.467499,0.037768,0.000000
30.910002,15.291107,-163.467499,0.005997,0.001470,0.037343,68.018242,3.465014,0.373425,-163.467499,0.038132,0.000000
31.130001,15.362976,-163.467499,0.006023,0.001481,0.037629,68.337929,3.481300,0.376287,-163.467499,0.038505,0.000000
31.350002,15.396118,-163.467499,0.006040,0.001495,0.037967,68.485352,3.488810,0.379670,-163.467499,0.038869,0.000000
31.570002,15.365578,-163.556458,0.006045,0.001507,0.038279,68.349503,3.481889,0.382793,-163.556458,0.039233,0.000000
31.790001,15.698112,-163.511978,0.006058,0.001524,0.038721,69.828690,3.557243,0.387214,-163.511978,0.039606,0.000000
32.010002,15.926743,-163.511978,0.006075,0.001542,0.039155,70.845688,3.609051,0.391551,-163.511978,0.039970,0.000000
32.230003,15.923019,-163.511978,0.006079,0.001554,0.039476,70.829124,3.608208,0.394761,-163.511978,0.040334,0.000000
32.450001,15.744286,-163.511978,0.006088,0.001562,0.039667,70.034081,3.567706,0.396668,-163.511978,0.040699,0.000000
32.670002,15.806839,-163.556458,0.006101,0.001574,0.039988,70.312332,3.581881,0.399878,-163.556458,0.041072,0.000000
32.890003,16.614143,-163.556458,0.006118,0.001601,0.040673,73.903404,3.764819,0.406729,-163.556458,0.041436,0.000000
33.110001,16.398544,-163.511978,0.006153,0.001611,0.040915,72.944366,3.715963,0.409155,-163.511978,0.041800,0.000000
33.330002,16.610794,-163.600937,0.006153,0.001627,0.041314,73.888504,3.764060,0.413144,-163.600937,0.042173,0.000000
33.550003,16.579887,-163.467499,0.006170,0.001640,0.041653,73.751022,3.757056,0.416528,-163.467499,0.042537,0.000000
33.770000,16.797356,-163.556458,0.006183,0.001657,0.042078,74.718369,3.806335,0.420778,-163.556458,0.042901,0.000000
33.990002,17.092270,-163.645416,0.006187,0.001672,0.042468,76.030212,3.873164,0.424680,-163.645416,0.043266,0.000000
34.210003,16.954865,-163.689896,0.006213,0.001681,0.042702,75.419006,3.842027,0.427019,-163.689896,0.043639,0.000000
34.430000,16.942581,-163.600937,0.006230,0.001693,0.042997,75.364365,3.839244,0.429968,-163.600937,0.044003,0.000000
34.650002,17.590881,-163.600937,0.006243,0.001717,0.043604,78.248146,3.986151,0.436039,-163.600937,0.044367,0.000000
34.870003,17.710411,-163.600937,0.006239,0.001732,0.043994,78.779846,4.013237,0.439941,-163.600937,0.044740,0.000000
35.090000,17.712273,-163.645416,0.006256,0.001745,0.044315,78.788124,4.013659,0.443151,-163.645416,0.045104,0.000000
35.310001,17.650833,-163.645416,0.006286,0.001756,0.044601,78.514824,3.999736,0.446012,-163.645416,0.045469,0.000000
35.530003,17.931969,-163.600937,0.006299,0.001774,0.045061,79.765381,4.063442,0.450611,-163.600937,0.045833,0.000000
35.750000,18.130821,-163.645416,0.006308,0.001789,0.045434,80.649918,4.108503,0.454339,-163.645416,0.046206,0.000000
35.970001,18.207901,-163.600937,0.006316,0.001802,0.045781,80.992790,4.125969,0.457806,-163.600937,0.046570,0.000000
36.190002,18.137520,-163.600937,0.006321,0.001812,0.046015,80.679718,4.110021,0.460149,-163.600937,0.046934,0.000000
36.410000,18.246254,-163.645416,0.006347,0.001825,0.046345,81.163391,4.134660,0.463445,-163.645416,0.047307,0.000000
36.630001,19.079254,-163.645416,0.006364,0.001849,0.046969,84.868759,4.323421,0.469687,-163.645416,0.047671,0.000000
36.850002,18.973122,-163.689896,0.006368,0.001860,0.047246,84.396660,4.299371,0.472465,-163.689896,0.048036,0.000000
37.070004,19.006638,-163.645416,0.006390,0.001874,0.047602,84.545746,4.306965,0.476019,-163.645416,0.048400,0.000000
37.290001,19.058769,-163.645416,0.006407,0.001887,0.047923,84.777641,4.318779,0.479228,-163.645416,0.048773,0.000000
37.510002,19.229691,-163.734375,0.006411,0.001901,0.048287,85.537933,4.357511,0.482869,-163.734375,0.049137,0.000000
37.730003,19.196175,-163.689896,0.006433,0.001912,0.048573,85.388847,4.349916,0.485731,-163.689896,0.049501,0.000000
37.950001,19.463165,-163.734375,0.006428,0.001928,0.048981,86.576485,4.410416,0.489807,-163.734375,0.049874,0.000000
38.170002,19.464653,-163.645416,0.006441,0.001939,0.049250,86.583099,4.410754,0.492498,-163.645416,0.050238,0.000000
38.390003,19.463165,-163.823349,0.006450,0.001949,0.049510,86.576485,4.410416,0.495098,-163.823349,0.050603,0.000000
38.610001,20.611938,-163.734375,0.006476,0.001977,0.050212,91.686485,4.670732,0.502123,-163.734375,0.050967,0.000000
38.830002,20.486450,-163.734375,0.006506,0.001988,0.050490,91.128281,4.642296,0.504897,-163.734375,0.051340,0.000000
39.050003,20.489052,-163.689896,0.006497,0.002000,0.050811,91.139854,4.642885,0.508107,-163.689896,0.051704,0.000000
39.270000,20.578049,-163.734375,0.006515,0.002015,0.051175,91.535736,4.663053,0.511748,-163.734375,0.052068,0.000000
39.490002,20.675987,-163.778854,0.006528,0.002028,0.051522,91.971382,4.685246,0.515219,-163.778854,0.052441,0.000000
39.710003,21.184273,-163.778854,0.006545,0.002045,0.051938,94.232353,4.800425,0.519382,-163.778854,0.052805,0.000000
39.930000,21.393921,-163.778854,0.006554,0.002059,0.052302,95.164909,4.847931,0.523023,-163.778854,0.053169,0.000000
40.150002,21.158203,-163.734375,0.006566,0.002071,0.052597,94.116386,4.794518,0.525972,-163.734375,0.053534,0.000000
40.370003,21.255768,-163.689896,0.006575,0.002080,0.052840,94.550377,4.816626,0.528398,-163.689896,0.053907,0.000000
40.590000,21.823639,-163.778854,0.006592,0.002101,0.053360,97.076393,4.945307,0.533602,-163.778854,0.054271,0.000000
40.810001,22.360970,-163.823349,0.006610,0.002118,0.053794,99.466560,5.067068,0.537940,-163.823349,0.054635,0.000000
41.030003,22.438423,-163.867828,0.006622,0.002134,0.054193,99.811089,5.084620,0.541929,-163.867828,0.055008,0.000000
41.250004,22.523697,-163.778854,0.006640,0.002144,0.054462,100.190407,5.103943,0.544616,-163.778854,0.055372,0.000000
41.470001,22.381821,-163.778854,0.006644,0.002157,0.054791,99.559311,5.071793,0.547913,-163.778854,0.055736,0.000000
41.690002,23.089333,-163.823349,0.006661,0.002174,0.055216,102.706482,5.232117,0.552163,-163.823349,0.056101,0.000000
41.910004,23.319832,-163.823349,0.006679,0.002189,0.055589,103.731796,5.284349,0.555891,-163.823349,0.056474,0.000000
42.130001,23.014114,-163.867828,0.006696,0.002195,0.055762,102.371895,5.215073,0.557625,-163.867828,0.056838,0.000000
42.350002,24.012070,-163.823349,0.006704,0.002219,0.056370,106.811020,5.441213,0.563696,-163.823349,0.057202,0.000000
42.570004,24.074997,-163.823349,0.006709,0.002232,0.056682,107.090935,5.455472,0.566818,-163.823349,0.057566,0.000000
42.790001,24.575096,-163.823349,0.006735,0.002251,0.057167,109.315491,5.568796,0.571674,-163.823349,0.057939,0.000000
43.010002,24.648453,-163.867828,0.006722,0.002262,0.057454,109.641792,5.585419,0.574536,-163.867828,0.058304,0.000000
43.230003,24.518494,-163.867828,0.006760,0.002272,0.057697,109.063705,5.555970,0.576966,-163.867828,0.058668,0.000000
43.450001,24.853630,-163.867828,0.006773,0.002287,0.058095,110.554466,5.631913,0.580955,-163.867828,0.059041,0.000000
43.670002,25.362289,-163.823349,0.006773,0.002305,0.058538,112.817101,5.747177,0.585376,-163.823349,0.059405,0.000000
43.890003,25.655350,-163.867828,0.006786,0.002319,0.058902,114.120697,5.813585,0.589020,-163.867828,0.059769,0.000000
44.110001,25.339203,-163.912308,0.006799,0.002325,0.059049,112.714401,5.741946,0.590493,-163.912308,0.060133,0.000000
44.330002,26.113365,-163.912308,0.006821,0.002348,0.059630,116.158051,5.917373,0.596303,-163.912308,0.060506,0.000000
44.550003,27.021210,-163.956787,0.006821,0.002367,0.060133,120.196342,6.123094,0.601333,-163.956787,0.060871,0.000000
44.770000,26.817154,-163.912308,0.006834,0.002376,0.060350,119.288658,6.076854,0.603501,-163.912308,0.061235,0.000000
44.990002,26.984344,-163.867828,0.006847,0.002390,0.060706,120.032356,6.114740,0.607056,-163.867828,0.061607,0.000000
45.210003,27.085258,-163.956787,0.006873,0.002402,0.061009,120.481247,6.137607,0.610091,-163.956787,0.061972,0.000000
45.430000,27.419647,-163.912308,0.006877,0.002417,0.061391,121.968681,6.213381,0.613906,-163.912308,0.062336,0.000000
45.650002,27.885117,-163.867828,0.006890,0.002431,0.061755,124.039192,6.318858,0.617551,-163.867828,0.062700,0.000000
45.870003,28.045235,-163.912308,0.006898,0.002446,0.062119,124.751434,6.355141,0.621192,-163.912308,0.063073,0.000000
46.090004,27.843040,-163.912308,0.006920,0.002455,0.062345,123.852028,6.309323,0.623448,-163.912308,0.063437,0.000000
46.310001,29.553345,-164.001266,0.006911,0.002483,0.063073,131.459839,6.696884,0.630734,-164.001266,0.063802,0.000000
46.530003,29.930183,-164.001266,0.006937,0.002498,0.063446,133.136108,6.782276,0.634462,-164.001266,0.064175,0.000000
46.750004,29.783470,-163.956787,0.006946,0.002508,0.063698,132.483490,6.749031,0.636975,-163.956787,0.064539,0.000000
46.970001,29.996468,-163.956787,0.006967,0.002521,0.064036,133.430954,6.797297,0.640359,-163.956787,0.064903,0.000000
47.190002,29.967049,-163.956787,0.006976,0.002531,0.064296,133.300095,6.790630,0.642959,-163.956787,0.065267,0.000000
47.410004,30.529701,-164.045746,0.006985,0.002548,0.064712,135.802887,6.918129,0.647122,-164.045746,0.065640,0.000000
47.630001,31.122520,-164.045746,0.007006,0.002563,0.065102,138.439880,7.052464,0.651025,-164.045746,0.066004,0.000000
47.850002,31.201462,-163.956787,0.007015,0.002574,0.065380,138.791031,7.070353,0.653799,-163.956787,0.066369,0.000000
48.070004,31.376106,-163.956787,0.007023,0.002587,0.065701,139.567886,7.109927,0.657009,-163.956787,0.066742,0.000000
48.290001,32.034462,-164.045746,0.007028,0.002604,0.066135,142.496399,7.259113,0.661346,-164.045746,0.067106,0.000000
48.510002,33.220840,-164.001266,0.007041,0.002627,0.066716,147.773682,7.527950,0.667156,-164.001266,0.067470,0.000000
48.730003,33.185837,-164.045746,0.007058,0.002635,0.066941,147.617981,7.520018,0.669412,-164.045746,0.067834,0.000000
48.950001,33.278557,-164.045746,0.007067,0.002648,0.067253,148.030411,7.541028,0.672534,-164.045746,0.068207,0.000000
49.170002,33.678856,-164.045746,0.007080,0.002664,0.067678,149.811035,7.631738,0.676781,-164.045746,0.068571,0.000000
49.390003,34.522652,-164.090225,0.007075,0.002682,0.068112,153.564423,7.822945,0.681118,-164.090225,0.068936,0.000000
49.610001,34.868591,-164.045746,0.007101,0.002694,0.068433,155.103241,7.901336,0.684328,-164.045746,0.069309,0.000000
49.830002,35.019028,-164.090225,0.007097,0.002704,0.068693,155.772415,7.935425,0.686928,-164.090225,0.069673,0.000000
50.050003,35.163506,-164.045746,0.007123,0.002720,0.069100,156.415085,7.968164,0.691005,-164.045746,0.070037,0.000000
50.270004,36.073212,-164.001266,0.007127,0.002738,0.069551,160.461655,8.174307,0.695512,-164.001266,0.070401,0.000000
50.490002,37.045853,-164.045746,0.007153,0.002756,0.070002,164.788177,8.394710,0.700024,-164.045746,0.070774,0.000000
50.710003,37.070427,-164.090225,0.007148,0.002767,0.070271,164.897491,8.400279,0.702711,-164.090225,0.071138,0.000000
50.930004,37.260338,-164.090225,0.007170,0.002778,0.070549,165.742264,8.443313,0.705486,-164.090225,0.071503,0.000000
51.150002,37.500893,-164.090225,0.007179,0.002790,0.070878,166.812302,8.497824,0.708782,-164.090225,0.071876,0.000000
51.370003,38.187920,-164.090225,0.007196,0.002808,0.071312,169.868347,8.653506,0.713120,-164.090225,0.072240,0.000000
51.590004,38.855583,-164.090225,0.007205,0.002822,0.071685,172.838272,8.804801,0.716848,-164.090225,0.072604,0.000000
51.810001,38.913673,-164.223679,0.007213,0.002831,0.071902,173.096664,8.817965,0.719016,-164.223679,0.072968,0.000000
52.030003,39.596603,-164.134705,0.007235,0.002846,0.072301,176.134491,8.972719,0.723006,-164.134705,0.073341,0.000000
52.250004,40.060577,-164.134705,0.007235,0.002866,0.072795,178.198349,9.077857,0.727949,-164.134705,0.073706,0.000000
52.470001,41.152374,-164.090225,0.007248,0.002881,0.073176,183.054901,9.325262,0.731764,-164.090225,0.074070,0.000000
52.690002,41.436119,-164.134705,0.007252,0.002894,0.073497,184.317062,9.389559,0.734974,-164.134705,0.074442,0.000000
52.910004,41.584328,-164.179184,0.007261,0.002905,0.073775,184.976334,9.423143,0.737748,-164.179184,0.074807,0.000000
53.130001,42.582283,-164.179184,0.007278,0.002923,0.074243,189.415451,9.649283,0.742430,-164.179184,0.075171,0.000000
53.350002,43.431664,-164.090225,0.007282,0.002940,0.074668,193.193695,9.841755,0.746680,-164.090225,0.075535,0.000000
53.570004,43.719513,-164.134705,0.007304,0.002952,0.074972,194.474106,9.906983,0.749716,-164.134705,0.075908,0.000000
53.790001,43.797707,-164.134705,0.007299,0.002960,0.075188,194.821930,9.924702,0.751885,-164.134705,0.076272,0.000000
54.010002,44.342491,-164.179184,0.007312,0.002977,0.075613,197.245255,10.048152,0.756131,-164.179184,0.076637,0.000000
54.230003,45.881874,-164.223679,0.007312,0.002999,0.076168,204.092773,10.396981,0.761684,-164.223679,0.077009,0.000000
54.450001,46.106041,-164.223679,0.007338,0.003011,0.076481,205.089920,10.447779,0.764806,-164.223679,0.077374,0.000000
54.670002,46.895103,-164.179184,0.007347,0.003026,0.076853,208.599838,10.626582,0.768534,-164.179184,0.077738,0.000000
54.890003,47.215340,-164.223679,0.007351,0.003039,0.077183,210.024323,10.699149,0.771831,-164.223679,0.078102,0.000000
55.110004,47.742622,-164.268158,0.007364,0.003055,0.077599,212.369797,10.818632,0.775994,-164.268158,0.078475,0.000000
55.330002,48.797554,-164.223679,0.007373,0.003070,0.077990,217.062363,11.057683,0.779897,-164.223679,0.078839,0.000000
55.550003,49.110344,-164.223679,0.007386,0.003080,0.078232,218.453720,11.128563,0.782323,-164.223679,0.079203,0.000000
55.770004,49.396324,-164.223679,0.007399,0.003091,0.078518,219.725830,11.193367,0.785184,-164.223679,0.079568,0.000000
55.990002,50.973328,-164.223679,0.007403,0.003116,0.079143,226.740692,11.550721,0.791429,-164.223679,0.079941,0.000000
56.210003,51.706154,-164.223679,0.007420,0.003131,0.079516,230.000458,11.716782,0.795157,-164.223679,0.080305,0.000000
56.430004,52.224869,-164.268158,0.007424,0.003144,0.079845,232.307816,11.834324,0.798454,-164.268158,0.080669,0.000000
56.650002,52.555908,-164.268158,0.007437,0.003154,0.080114,233.780350,11.909339,0.801141,-164.268158,0.081042,0.000000
56.870003,53.302513,-164.223679,0.007442,0.003173,0.080600,237.101425,12.078522,0.805997,-164.223679,0.081406,0.000000
57.090004,54.230843,-164.268158,0.007450,0.003188,0.080964,241.230835,12.288885,0.809642,-164.268158,0.081771,0.000000
57.310001,54.810249,-164.268158,0.007450,0.003201,0.081293,243.808167,12.420179,0.812935,-164.268158,0.082135,0.000000
57.530003,55.146873,-164.268158,0.007472,0.003210,0.081528,245.305542,12.496460,0.815278,-164.268158,0.082508,0.000000
57.750004,55.722191,-164.357117,0.007468,0.003223,0.081866,247.864685,12.626829,0.818661,-164.357117,0.082872,0.000000
57.970001,57.380363,-164.223679,0.007485,0.003247,0.082482,255.240601,13.002576,0.824816,-164.223679,0.083236,0.000000
58.190002,57.948235,-164.223679,0.007489,0.003258,0.082759,257.766632,13.131257,0.827594,-164.223679,0.083609,0.000000
58.410004,58.295288,-164.312637,0.007511,0.003272,0.083115,259.310394,13.209901,0.831148,-164.312637,0.083973,0.000000
58.630001,59.140572,-164.357117,0.007502,0.003285,0.083444,263.070404,13.401445,0.834444,-164.357117,0.084338,0.000000
58.850002,59.914360,-164.357117,0.007524,0.003300,0.083809,266.512390,13.576789,0.838086,-164.357117,0.084702,0.000000
59.070004,60.447594,-164.312637,0.007524,0.003311,0.084095,268.884338,13.697620,0.840947,-164.312637,0.085075,0.000000
59.290001,61.287666,-164.312637,0.007524,0.003326,0.084485,272.621155,13.887984,0.844849,-164.312637,0.085439,0.000000
59.510002,61.873787,-164.312637,0.007537,0.003338,0.084797,275.228363,14.020801,0.847972,-164.312637,0.085803,0.000000
59.730003,62.255836,-164.357117,0.007545,0.003348,0.085031,276.927795,14.107374,0.850314,-164.357117,0.086176,0.000000
59.950005,64.317291,-164.357117,0.007549,0.003375,0.085734,286.097595,14.574507,0.857339,-164.357117,0.086540,0.000000
60.170002,64.888504,-164.312637,0.007571,0.003386,0.086011,288.638489,14.703945,0.860114,-164.312637,0.086905,0.000000
60.390003,65.475739,-164.268158,0.007571,0.003399,0.086324,291.250641,14.837015,0.863236,-164.268158,0.087269,0.000000
60.610004,66.265167,-164.312637,0.007580,0.003414,0.086705,294.762177,15.015902,0.867051,-164.312637,0.087642,0.000000
60.830002,66.851654,-164.401596,0.007588,0.003425,0.086991,297.371002,15.148801,0.869913,-164.401596,0.088006,0.000000
61.050003,67.623581,-164.401596,0.007593,0.003431,0.087139,300.804718,15.323722,0.871389,-164.401596,0.087364,0.000000
61.270004,66.906403,-164.401596,0.007606,0.003431,0.087139,297.614532,15.161207,0.871389,-164.401596,0.087364,0.000000
61.490002,66.283798,-164.312637,0.007614,0.003428,0.087069,294.845062,15.020123,0.870692,-164.312637,0.087139,0.000000
61.710003,65.686508,-164.357117,0.007614,0.003427,0.087044,292.188171,14.884775,0.870435,-164.357117,0.087139,0.000000
61.930004,65.129807,-164.401596,0.007627,0.003426,0.087026,289.711853,14.758625,0.870261,-164.401596,0.087139,0.000000
62.150002,64.610352,-164.490555,0.007627,0.003426,0.087017,287.401184,14.640915,0.870174,-164.490555,0.087139,0.000000
62.370003,64.152328,-164.401596,0.007618,0.003426,0.087009,285.363800,14.537126,0.870087,-164.401596,0.087139,0.000000
62.590004,63.718887,-164.401596,0.007631,0.003426,0.087009,283.435760,14.438907,0.870087,-164.401596,0.087139,0.000000
62.810001,63.336456,-164.446075,0.007640,0.003426,0.087009,281.734619,14.352245,0.870087,-164.446075,0.087139,0.000000
63.030003,62.950310,-164.490555,0.007640,0.003425,0.087000,280.016968,14.264745,0.870000,-164.490555,0.087139,0.000000
63.250004,62.586136,-164.446075,0.007649,0.003425,0.087000,278.397034,14.182221,0.870000,-164.446075,0.087139,0.000000
63.470001,62.272224,-164.401596,0.007644,0.003425,0.087000,277.000702,14.111088,0.870000,-164.401596,0.087139,0.000000
63.690002,61.923309,-164.446075,0.007653,0.003425,0.087000,275.448639,14.032022,0.870000,-164.446075,0.087139,0.000000
63.910004,61.639931,-164.446075,0.007649,0.003425,0.087000,274.188110,13.967808,0.870000,-164.446075,0.087139,0.000000
64.130005,61.378525,-164.535034,0.007653,0.003425,0.087000,273.025299,13.908573,0.870000,-164.535034,0.087139,0.000000
64.350006,61.107445,-164.490555,0.007649,0.003425,0.087000,271.819489,13.847144,0.870000,-164.490555,0.087139,0.000000
64.570000,60.864655,-164.446075,0.007662,0.003425,0.087000,270.739502,13.792128,0.870000,-164.446075,0.087139,0.000000
64.790001,60.625221,-164.446075,0.007657,0.003425,0.087000,269.674438,13.737871,0.870000,-164.446075,0.087139,0.000000
65.010002,60.410736,-164.490555,0.007644,0.003425,0.087000,268.720367,13.689268,0.870000,-164.490555,0.087139,0.000000
65.230003,60.201462,-164.535034,0.007649,0.003425,0.086991,267.789490,13.641846,0.869913,-164.535034,0.087139,0.000000
65.450005,59.993675,-164.490555,0.007666,0.003425,0.086991,266.865204,13.594761,0.869913,-164.490555,0.087139,0.000000
65.670006,59.801155,-164.490555,0.007666,0.003425,0.086991,266.008820,13.551136,0.869913,-164.490555,0.087139,0.000000
65.889999,59.619438,-164.535034,0.007662,0.003425,0.086991,265.200500,13.509958,0.869913,-164.535034,0.087139,0.000000
66.110001,59.438469,-164.579514,0.007670,0.003425,0.086991,264.395508,13.468949,0.869913,-164.579514,0.087139,0.000000
66.330002,59.270531,-164.579514,0.007657,0.003425,0.086991,263.648499,13.430894,0.869913,-164.579514,0.087139,0.000000
66.550003,59.097374,-164.490555,0.007675,0.003425,0.086991,262.878235,13.391656,0.869913,-164.490555,0.087139,0.000000
66.770004,58.941727,-164.490555,0.007666,0.003425,0.086991,262.185883,13.356386,0.869913,-164.490555,0.087139,0.000000
66.990005,58.799850,-164.579514,0.007666,0.003425,0.086991,261.554810,13.324236,0.869913,-164.579514,0.087139,0.000000
67.210007,58.659096,-164.490555,0.007666,0.003425,0.086991,260.928680,13.292341,0.869913,-164.490555,0.087139,0.000000
67.430000,58.505676,-164.623993,0.007670,0.003425,0.086991,260.246246,13.257576,0.869913,-164.623993,0.087139,0.000000
67.650002,58.370506,-164.623993,0.007675,0.003425,0.086991,259.644989,13.226946,0.869913,-164.623993,0.087139,0.000000
67.870003,58.242783,-164.535034,0.007675,0.003425,0.086991,259.076843,13.198004,0.869913,-164.535034,0.087139,0.000000
68.090004,58.112823,-164.623993,0.007670,0.003425,0.086991,258.498749,13.168554,0.869913,-164.623993,0.087139,0.000000
68.310005,57.989563,-164.579514,0.007670,0.003425,0.086991,257.950470,13.140622,0.869913,-164.579514,0.087139,0.000000
68.530006,57.870407,-164.623993,0.007679,0.003425,0.086991,257.420441,13.113622,0.869913,-164.623993,0.087139,0.000000
68.750000,57.751251,-164.623993,0.007679,0.003425,0.086991,256.890381,13.086620,0.869913,-164.623993,0.087139,0.000000
68.970001,57.635811,-164.623993,0.007679,0.003425,0.086991,256.376892,13.060461,0.869913,-164.623993,0.087139,0.000000
69.190002,57.523354,-164.668488,0.007679,0.003425,0.086991,255.876663,13.034978,0.869913,-164.668488,0.087139,0.000000
69.410004,57.412392,-164.623993,0.007679,0.003425,0.086991,255.383072,13.009834,0.869913,-164.623993,0.087139,0.000000
69.630005,57.316689,-164.668488,0.007679,0.003425,0.086991,254.957367,12.988147,0.869913,-164.668488,0.087139,0.000000
69.850006,57.198273,-164.668488,0.007675,0.003425,0.086991,254.430618,12.961314,0.869913,-164.668488,0.087139,0.000000
70.070000,57.127151,-164.623993,0.007683,0.003425,0.086991,254.114258,12.945198,0.869913,-164.623993,0.087139,0.000000
70.290001,57.018417,-164.668488,0.007679,0.003425,0.086991,253.630585,12.920558,0.869913,-164.668488,0.087139,0.000000
70.510002,56.925323,-164.623993,0.007670,0.003425,0.086991,253.216492,12.899463,0.869913,-164.623993,0.087139,0.000000
70.730003,56.843033,-164.668488,0.007692,0.003425,0.086991,252.850433,12.880816,0.869913,-164.668488,0.087139,0.000000
70.950005,56.748077,-164.712967,0.007687,0.003425,0.086991,252.428055,12.859298,0.869913,-164.712967,0.087139,0.000000
71.170006,56.662804,-164.712967,0.007687,0.003425,0.086991,252.048737,12.839974,0.869913,-164.712967,0.087139,0.000000
71.390007,56.595779,-164.623993,0.007683,0.003425,0.086991,251.750595,12.824787,0.869913,-164.623993,0.087139,0.000000
71.610001,56.498215,-164.712967,0.007683,0.003425,0.086991,251.316605,12.802679,0.869913,-164.712967,0.087139,0.000000
71.830002,56.420761,-164.712967,0.007683,0.003425,0.086991,250.972076,12.785128,0.869913,-164.712967,0.087139,0.000000
72.050003,56.358200,-164.757446,0.007692,0.003425,0.086991,250.693802,12.770950,0.869913,-164.757446,0.087139,0.000000
72.270004,56.275909,-164.668488,0.007687,0.003425,0.086991,250.327744,12.752303,0.869913,-164.668488,0.087139,0.000000
72.490005,56.216698,-164.757446,0.007692,0.003425,0.086991,250.064362,12.738886,0.869913,-164.757446,0.087139,0.000000
72.710007,56.123611,-164.757446,0.007683,0.003425,0.086991,249.650299,12.717792,0.869913,-164.757446,0.087139,0.000000
72.930000,56.049881,-164.801926,0.007679,0.003425,0.086991,249.322327,12.701085,0.869913,-164.801926,0.087139,0.000000
73.150002,55.992531,-164.757446,0.007683,0.003425,0.086991,249.067215,12.688089,0.869913,-164.757446,0.087139,0.000000
73.370003,55.898697,-164.757446,0.007692,0.003425,0.086991,248.649826,12.666825,0.869913,-164.757446,0.087139,0.000000
73.590004,55.848427,-164.712967,0.007692,0.003425,0.086991,248.426208,12.655434,0.869913,-164.712967,0.087139,0.000000
73.810005,55.787727,-164.801926,0.007679,0.003425,0.086991,248.156204,12.641680,0.869913,-164.801926,0.087139,0.000000
74.030006,55.709160,-164.801926,0.007696,0.003425,0.086991,247.806717,12.623876,0.869913,-164.801926,0.087139,0.000000
74.250000,55.659256,-164.801926,0.007692,0.003425,0.086991,247.584732,12.612568,0.869913,-164.801926,0.087139,0.000000
74.470001,55.595955,-164.757446,0.007696,0.003425,0.086991,247.303162,12.598224,0.869913,-164.757446,0.087139,0.000000
74.690002,55.533768,-164.801926,0.007692,0.003425,0.086991,247.026535,12.584131,0.869913,-164.801926,0.087139,0.000000
74.910004,55.472702,-164.801926,0.007679,0.003425,0.086991,246.754898,12.570294,0.869913,-164.801926,0.087139,0.000000
75.130005,55.417961,-164.801926,0.007687,0.003425,0.086991,246.511398,12.557889,0.869913,-164.801926,0.087139,0.000000
75.350006,55.374397,-164.801926,0.007696,0.003425,0.086991,246.317627,12.548018,0.869913,-164.801926,0.087139,0.000000
75.570007,55.309227,-164.712967,0.007687,0.003425,0.086991,246.027725,12.533250,0.869913,-164.712967,0.087139,0.000000
75.790001,55.250771,-164.801926,0.007696,0.003425,0.086991,245.767700,12.520003,0.869913,-164.801926,0.087139,0.000000
76.010002,55.198631,-164.757446,0.007687,0.003425,0.086991,245.535782,12.508188,0.869913,-164.757446,0.087139,0.000000
76.230003,55.136818,-164.801926,0.007696,0.003425,0.086991,245.260818,12.494182,0.869913,-164.801926,0.087139,0.000000
76.450005,55.095116,-164.801926,0.007700,0.003425,0.086991,245.075317,12.484732,0.869913,-164.801926,0.087139,0.000000
76.670006,55.061974,-164.801926,0.007692,0.003425,0.086991,244.927887,12.477221,0.869913,-164.801926,0.087139,0.000000
76.890007,54.993828,-164.846405,0.007700,0.003425,0.086991,244.624771,12.461780,0.869913,-164.846405,0.087139,0.000000
77.110001,54.936485,-164.846405,0.007683,0.003425,0.086991,244.369690,12.448786,0.869913,-164.846405,0.087139,0.000000
77.330002,54.886589,-164.846405,0.007692,0.003425,0.086991,244.147736,12.437479,0.869913,-164.846405,0.087139,0.000000
77.550003,54.832596,-164.846405,0.007692,0.003425,0.086991,243.907562,12.425243,0.869913,-164.846405,0.087139,0.000000
77.770004,54.795731,-164.846405,0.007709,0.003425,0.086991,243.743576,12.416889,0.869913,-164.846405,0.087139,0.000000
77.990005,54.752159,-164.846405,0.007700,0.003425,0.086991,243.549774,12.407017,0.869913,-164.846405,0.087139,0.000000
78.210007,54.714554,-164.890884,0.007700,0.003425,0.086991,243.382492,12.398495,0.869913,-164.890884,0.087139,0.000000
78.430000,54.654968,-164.890884,0.007692,0.003425,0.086991,243.117447,12.384993,0.869913,-164.890884,0.087139,0.000000
78.650002,54.608421,-164.935364,0.007700,0.003425,0.086991,242.910385,12.374446,0.869913,-164.935364,0.087139,0.000000
78.870003,54.564857,-164.935364,0.007709,0.003425,0.086991,242.716614,12.364573,0.869913,-164.935364,0.087139,0.000000
79.090004,54.508255,-164.801926,0.007705,0.003425,0.086991,242.464828,12.351748,0.869913,-164.801926,0.087139,0.000000
79.310005,54.483681,-164.890884,0.007700,0.003425,0.086991,242.355515,12.346179,0.869913,-164.890884,0.087139,0.000000
79.530006,54.437134,-164.935364,0.007700,0.003425,0.086991,242.148468,12.335630,0.869913,-164.935364,0.087139,0.000000
79.750000,54.392822,-164.935364,0.007700,0.003425,0.086991,241.951355,12.325590,0.869913,-164.935364,0.087139,0.000000
79.970001,54.352234,-164.935364,0.007696,0.003425,0.086991,241.770813,12.316393,0.869913,-164.935364,0.087139,0.000000
80.190002,54.293770,-164.935364,0.007713,0.003425,0.086991,241.510757,12.303144,0.869913,-164.935364,0.087139,0.000000
80.410004,54.266212,-164.890884,0.007709,0.003425,0.086991,241.388168,12.296900,0.869913,-164.890884,0.087139,0.000000
80.630005,54.218925,-164.979843,0.007700,0.003425,0.086991,241.177826,12.286184,0.869913,-164.979843,0.087139,0.000000
80.850006,54.176842,-164.979843,0.007700,0.003425,0.086991,240.990631,12.276649,0.869913,-164.979843,0.087139,0.000000
81.070007,54.143707,-164.935364,0.007700,0.003425,0.086991,240.843231,12.269139,0.869913,-164.935364,0.087139,0.000000
81.290001,54.108704,-164.935364,0.007700,0.003425,0.086991,240.687531,12.261208,0.869913,-164.935364,0.087139,0.000000
81.510002,54.067741,-164.979843,0.007705,0.003425,0.086991,240.505325,12.251925,0.869913,-164.979843,0.087139,0.000000
81.730003,54.023430,-164.979843,0.007705,0.003425,0.086991,240.308212,12.241884,0.869913,-164.979843,0.087139,0.000000
81.950005,54.004066,-164.979843,0.007705,0.003425,0.086991,240.222092,12.237496,0.869913,-164.979843,0.087139,0.000000
82.170006,53.957520,-165.024323,0.007718,0.003425,0.086991,240.015030,12.226949,0.869913,-165.024323,0.087139,0.000000
82.390007,53.939644,-164.935364,0.007696,0.003425,0.086991,239.935516,12.222898,0.869913,-164.935364,0.087139,0.000000
82.610001,53.893471,-164.979843,0.007696,0.003425,0.086991,239.730133,12.212435,0.869913,-164.979843,0.087139,0.000000
82.830002,53.859955,-165.024323,0.007696,0.003425,0.086991,239.581039,12.204840,0.869913,-165.024323,0.087139,0.000000
83.050003,53.833519,-165.024323,0.007705,0.003425,0.086991,239.463455,12.198850,0.869913,-165.024323,0.087139,0.000000
83.270004,53.782501,-164.979843,0.007713,0.003425,0.086991,239.236511,12.187289,0.869913,-164.979843,0.087139,0.000000
83.490005,53.777290,-164.979843,0.007705,0.003425,0.086991,239.213333,12.186109,0.869913,-164.979843,0.087139,0.000000
83.710007,53.721809,-165.024323,0.007696,0.003425,0.086991,238.966537,12.173536,0.869913,-165.024323,0.087139,0.000000
83.930000,53.703560,-165.068802,0.007705,0.003425,0.086991,238.885361,12.169400,0.869913,-165.068802,0.087139,0.000000
84.150002,53.658127,-165.068802,0.007705,0.003425,0.086991,238.683273,12.159105,0.869913,-165.068802,0.087139,0.000000
84.370003,53.638763,-165.024323,0.007718,0.003425,0.086991,238.597137,12.154717,0.869913,-165.024323,0.087139,0.000000
84.590004,53.629456,-165.024323,0.007705,0.003425,0.086991,238.555725,12.152608,0.869913,-165.024323,0.087139,0.000000
84.810005,53.571739,-165.068802,0.007700,0.003425,0.086991,238.298996,12.139529,0.869913,-165.068802,0.087139,0.000000
85.030006,53.541580,-165.157776,0.007700,0.003425,0.086991,238.164841,12.132695,0.869913,-165.157776,0.087139,0.000000
85.250008,53.517746,-165.068802,0.007709,0.003425,0.086991,238.058823,12.127295,0.869913,-165.068802,0.087139,0.000000
85.470001,53.501358,-165.113297,0.007705,0.003425,0.086991,237.985931,12.123581,0.869913,-165.113297,0.087139,0.000000
85.690002,53.450348,-165.068802,0.007709,0.003425,0.086991,237.759018,12.112022,0.869913,-165.068802,0.087139,0.000000
85.910004,53.434334,-165.068802,0.007713,0.003425,0.086991,237.687790,12.108394,0.869913,-165.068802,0.087139,0.000000
86.130005,53.400078,-165.068802,0.007718,0.003425,0.086991,237.535416,12.100631,0.869913,-165.068802,0.087139,0.000000
86.350006,53.371773,-165.068802,0.007709,0.003425,0.086991,237.409500,12.094216,0.869913,-165.068802,0.087139,0.000000
86.570007,53.351669,-165.113297,0.007709,0.003425,0.086991,237.320084,12.089661,0.869913,-165.113297,0.087139,0.000000
86.790001,53.317406,-165.024323,0.007709,0.003425,0.086991,237.167664,12.081897,0.869913,-165.024323,0.087139,0.000000
87.010002,53.285385,-165.157776,0.007709,0.003425,0.086991,237.025238,12.074641,0.869913,-165.157776,0.087139,0.000000
87.230003,53.267883,-165.202255,0.007709,0.003425,0.086991,236.947372,12.070674,0.869913,-165.202255,0.087139,0.000000
87.450005,53.246658,-165.113297,0.007713,0.003425,0.086991,236.852966,12.065866,0.869913,-165.113297,0.087139,0.000000
87.670006,53.198250,-165.157776,0.007713,0.003425,0.086991,236.637634,12.054896,0.869913,-165.157776,0.087139,0.000000
87.890007,53.193413,-165.157776,0.007696,0.003425,0.086991,236.616119,12.053800,0.869913,-165.157776,0.087139,0.000000
88.110001,53.163246,-165.202255,0.007718,0.003425,0.086991,236.481934,12.046964,0.869913,-165.202255,0.087139,0.000000
88.330002,53.127129,-165.202255,0.007709,0.003425,0.086991,236.321274,12.038779,0.869913,-165.202255,0.087139,0.000000
88.550003,53.095100,-165.113297,0.007700,0.003425,0.086991,236.178802,12.031522,0.869913,-165.113297,0.087139,0.000000
88.770004,53.079094,-165.157776,0.007709,0.003425,0.086991,236.107605,12.027894,0.869913,-165.157776,0.087139,0.000000
88.990005,53.056007,-165.113297,0.007705,0.003425,0.086991,236.004913,12.022663,0.869913,-165.113297,0.087139,0.000000
89.210007,53.027702,-165.202255,0.007705,0.003425,0.086991,235.878998,12.016250,0.869913,-165.202255,0.087139,0.000000
89.430008,53.006477,-165.202255,0.007718,0.003425,0.086991,235.784592,12.011439,0.869913,-165.202255,0.087139,0.000000
89.650002,52.980042,-165.202255,0.007705,0.003425,0.086991,235.666992,12.005448,0.869913,-165.202255,0.087139,0.000000
89.870003,52.974457,-165.202255,0.007718,0.003425,0.086991,235.642151,12.004183,0.869913,-165.202255,0.087139,0.000000
90.090004,52.929771,-165.157776,0.007705,0.003425,0.086991,235.443375,11.994058,0.869913,-165.157776,0.087139,0.000000
90.310005,52.902962,-165.202255,0.007705,0.003425,0.086991,235.324127,11.987983,0.869913,-165.202255,0.087139,0.000000
90.530006,52.881363,-165.291214,0.007713,0.003425,0.086991,235.228058,11.983088,0.869913,-165.291214,0.087139,0.000000
90.750008,52.860878,-165.202255,0.007709,0.003425,0.086991,235.136932,11.978446,0.869913,-165.202255,0.087139,0.000000
90.970001,52.847847,-165.291214,0.007718,0.003425,0.086991,235.078964,11.975493,0.869913,-165.291214,0.087139,0.000000
91.190002,52.807632,-165.246735,0.007709,0.003425,0.086991,234.900085,11.966381,0.869913,-165.246735,0.087139,0.000000
91.410004,52.794228,-165.246735,0.007700,0.003425,0.086991,234.840454,11.963343,0.869913,-165.246735,0.087139,0.000000
91.500008,52.780823,-165.246735,0.007709,0.003425,0.086991,234.780823,11.960305,0.869913,-165.246735,0.087139,0.000000