File: Data/compression 8/AutoHeating-12-8-1-1-240328_03282024_152144.csv
Time (sec),S:Load (lbs),S:HL1 (DIM),S:LVDT (in),S:Position (in),Ch:Position (mm),Ch:Load (N),Ch:Stress (MPa),Ch:Strain (mm/mm),Ch:HL1 (DIM),Set Point (),Cycles ()
0.110000,0.000374,-127.971695,0.000009,-0.000000,-0.000000,0.001663,0.000085,-0.000000,-127.971695,0.000216,0.000000
0.350000,-0.006332,-127.971695,-0.000004,-0.000000,-0.000000,-0.028168,-0.001435,-0.000000,-127.971695,0.000216,0.000000
0.590000,-0.019363,-127.971695,0.000000,0.000102,0.002584,-0.086133,-0.004388,0.025843,-127.971695,0.003425,0.000000
0.830000,-0.006332,-127.971695,0.000099,0.000249,0.006322,-0.028168,-0.001435,0.063219,-127.971695,0.007432,0.000000
1.070000,0.002975,-127.927216,0.000241,0.000395,0.010042,0.013236,0.000674,0.100425,-127.927216,0.011421,0.000000
1.310000,-0.002609,-127.971695,0.000414,0.000566,0.014370,-0.011607,-0.000591,0.143697,-127.971695,0.015428,0.000000
1.550000,-0.029793,-127.971695,0.000573,0.000718,0.018238,-0.132525,-0.006751,0.182375,-127.971695,0.019417,0.000000
1.790000,-0.004097,-128.016174,0.000742,0.000878,0.022296,-0.018224,-0.000928,0.222961,-128.016174,0.023424,0.000000
2.030000,-0.004471,-127.971695,0.000892,0.001030,0.026156,-0.019887,-0.001013,0.261555,-127.971695,0.027413,0.000000
2.270000,-0.027557,-128.016174,0.001061,0.001200,0.030474,-0.122581,-0.006245,0.304741,-128.016174,0.031420,0.000000
2.510000,-0.029045,-127.971695,0.001207,0.001341,0.034073,-0.129199,-0.006582,0.340731,-127.971695,0.035409,0.000000
2.750000,0.006332,-128.016174,0.001375,0.001509,0.038331,0.028168,0.001435,0.383311,-128.016174,0.039415,0.000000
2.990000,0.006332,-128.105133,0.001539,0.001654,0.042017,0.028168,0.001435,0.420169,-128.105133,0.043422,0.000000
3.230000,0.008560,-128.016174,0.001699,0.001818,0.046188,0.038078,0.001940,0.461882,-128.016174,0.047411,0.000000
3.470000,-0.031281,-128.060654,0.001850,0.001980,0.050282,-0.139143,-0.007088,0.502816,-128.060654,0.051418,0.000000
3.710000,-0.011917,-128.105133,0.002018,0.002135,0.054227,-0.053010,-0.002700,0.542273,-128.105133,0.055407,0.000000
3.950000,0.008194,-127.971695,0.002156,0.002290,0.058156,0.036449,0.001857,0.581560,-127.971695,0.059413,0.000000
4.190000,-0.023460,-128.105133,0.002324,0.002453,0.062319,-0.104357,-0.005316,0.623187,-128.105133,0.063403,0.000000
4.430000,-0.067032,-128.060654,0.002475,0.002610,0.066299,-0.298173,-0.015190,0.662992,-128.060654,0.067409,0.000000
4.670000,-0.017128,-128.105133,0.002639,0.002762,0.070150,-0.076189,-0.003881,0.701496,-128.105133,0.071399,0.000000
4.910000,0.009308,-128.105133,0.002820,0.002921,0.074200,0.041403,0.002109,0.741998,-128.105133,0.075405,0.000000
5.150000,0.027557,-128.105133,0.002962,0.003081,0.078258,0.122581,0.006245,0.782584,-128.105133,0.079394,0.000000
5.390000,0.018990,-128.105133,0.003104,0.003239,0.082265,0.084470,0.004303,0.822647,-128.105133,0.083401,0.000000
5.630000,-0.017502,-128.016174,0.003268,0.003392,0.086159,-0.077852,-0.003966,0.861586,-128.016174,0.087390,0.000000
5.870000,0.002235,-128.149612,0.003441,0.003552,0.090209,0.009944,0.000507,0.902088,-128.149612,0.091397,0.000000
6.110000,-0.008942,-128.060654,0.003604,0.003706,0.094120,-0.039774,-0.002026,0.941197,-128.060654,0.095386,0.000000
6.350000,-0.003349,-128.105133,0.003755,0.003875,0.098413,-0.014898,-0.000759,0.984126,-128.105133,0.099392,0.000000
6.590000,0.048409,-128.194107,0.003902,0.004024,0.102220,0.215332,0.010970,1.022198,-128.194107,0.103382,0.000000
6.830000,0.538818,-128.149612,0.004079,0.004184,0.106261,2.396784,0.122098,1.062609,-128.149612,0.107388,0.000000
7.070000,0.637497,-128.194107,0.004130,-0.000007,-0.000174,2.835728,0.144459,-0.001737,-128.194107,0.000017,0.000000
7.310000,0.593559,-128.149612,0.004135,-0.000007,-0.000182,2.640284,0.134502,-0.001824,-128.149612,0.000017,0.000000
7.550000,0.579407,-128.149612,0.004122,-0.000007,-0.000182,2.577330,0.131295,-0.001824,-128.149612,0.000216,0.000000
7.790000,0.571220,-128.194107,0.004109,-0.000007,-0.000174,2.540915,0.129440,-0.001737,-128.194107,0.000615,0.000000
8.030001,0.619255,-128.149612,0.004135,0.000006,0.000165,2.754584,0.140325,0.001646,-128.149612,0.001014,0.000000
8.270000,0.740646,-128.194107,0.004126,0.000020,0.000503,3.294559,0.167833,0.005030,-128.194107,0.001413,0.000000
8.510000,0.827034,-128.238586,0.004148,0.000038,0.000962,3.678831,0.187409,0.009625,-128.238586,0.001812,0.000000
8.750000,0.898163,-128.238586,0.004165,0.000050,0.001266,3.995228,0.203527,0.012660,-128.238586,0.002220,0.000000
8.990001,1.015831,-128.194107,0.004165,0.000066,0.001674,4.518642,0.230191,0.016737,-128.194107,0.002619,0.000000
9.230000,1.137222,-128.194107,0.004195,0.000085,0.002159,5.058618,0.257698,0.021593,-128.194107,0.003018,0.000000
9.470000,1.191963,-128.238586,0.004204,0.000096,0.002428,5.302117,0.270103,0.024280,-128.238586,0.003417,0.000000
9.710000,1.333466,-128.238586,0.004221,0.000110,0.002801,5.931551,0.302168,0.028008,-128.238586,0.003816,0.000000
9.950001,1.508476,-128.238586,0.004221,0.000131,0.003321,6.710038,0.341826,0.033212,-128.238586,0.004214,0.000000
10.190001,1.607903,-128.238586,0.004260,0.000151,0.003842,7.152308,0.364356,0.038417,-128.238586,0.004613,0.000000
10.430000,1.638435,-128.238586,0.004268,0.000165,0.004180,7.288125,0.371275,0.041800,-128.238586,0.005012,0.000000
10.670000,1.722221,-128.238586,0.004268,0.000178,0.004509,7.660823,0.390261,0.045093,-128.238586,0.005420,0.000000
10.910001,1.889420,-128.238586,0.004303,0.000197,0.005004,8.404558,0.428149,0.050036,-128.238586,0.005819,0.000000
11.150001,2.005226,-128.194107,0.004312,0.000212,0.005394,8.919691,0.454391,0.053939,-128.194107,0.006218,0.000000
11.390000,2.100182,-128.283066,0.004333,0.000225,0.005724,9.342074,0.475908,0.057235,-128.283066,0.006617,0.000000
11.630000,2.058472,-128.194107,0.004337,0.000229,0.005828,9.156539,0.466456,0.058276,-128.194107,0.007016,0.000000
11.870001,2.329559,-128.327545,0.004346,0.000255,0.006487,10.362397,0.527886,0.064866,-128.327545,0.007415,0.000000
12.110001,2.490051,-128.238586,0.004376,0.000276,0.007007,11.076302,0.564254,0.070070,-128.238586,0.007814,0.000000
12.350000,2.567131,-128.283066,0.004385,0.000289,0.007345,11.419169,0.581720,0.073453,-128.283066,0.008212,0.000000
12.590000,2.647568,-128.327545,0.004398,0.000304,0.007727,11.776970,0.599947,0.077269,-128.327545,0.008620,0.000000
12.830001,2.757790,-128.283066,0.004419,0.000319,0.008100,12.267261,0.624924,0.080997,-128.283066,0.009019,0.000000
13.070001,2.869125,-128.327545,0.004428,0.000337,0.008551,12.762507,0.650153,0.085508,-128.327545,0.009418,0.000000
13.310000,3.017334,-128.327545,0.004458,0.000353,0.008975,13.421772,0.683738,0.089755,-128.327545,0.009817,0.000000
13.550000,2.934669,-128.327545,0.004467,0.000358,0.009097,13.054062,0.665006,0.090970,-128.327545,0.010216,0.000000
13.790001,3.111542,-128.327545,0.004480,0.000377,0.009565,13.840829,0.705085,0.095652,-128.327545,0.010615,0.000000
14.030001,3.365875,-128.372025,0.004501,0.000397,0.010094,14.972161,0.762718,0.100943,-128.372025,0.011014,0.000000
14.270000,3.431038,-128.372025,0.004523,0.000412,0.010476,15.262019,0.777484,0.104758,-128.372025,0.011413,0.000000
14.510000,3.528229,-128.416504,0.004544,0.000430,0.010927,15.694345,0.799508,0.109270,-128.416504,0.011820,0.000000
14.750001,3.563972,-128.327545,0.004531,0.000444,0.011282,15.853341,0.807608,0.112824,-128.327545,0.012219,0.000000
14.990001,3.734520,-128.416504,0.004553,0.000461,0.011716,16.611975,0.846254,0.117161,-128.416504,0.012618,0.000000
15.230000,3.844002,-128.372025,0.004579,0.000478,0.012150,17.098974,0.871063,0.121495,-128.372025,0.013017,0.000000
15.470000,3.797829,-128.372025,0.004587,0.000486,0.012349,16.893585,0.860600,0.123490,-128.372025,0.013416,0.000000
15.710001,3.845863,-128.416504,0.004600,0.000498,0.012661,17.107254,0.871485,0.126612,-128.416504,0.013815,0.000000
15.950001,4.193657,-128.416504,0.004622,0.000527,0.013390,18.654318,0.950296,0.133898,-128.416504,0.014214,0.000000
16.190001,4.166100,-128.416504,0.004631,0.000538,0.013676,18.531736,0.944052,0.136760,-128.416504,0.014613,0.000000
16.430000,4.288986,-128.372025,0.004661,0.000556,0.014118,19.078363,0.971898,0.141184,-128.372025,0.015020,0.000000
16.670000,4.315422,-128.460983,0.004669,0.000568,0.014439,19.195955,0.977889,0.144390,-128.460983,0.015419,0.000000
16.910002,4.304993,-128.460983,0.004691,0.000580,0.014734,19.149565,0.975525,0.147342,-128.460983,0.015818,0.000000
17.150002,4.515388,-128.416504,0.004700,0.000599,0.015202,20.085451,1.023202,0.152024,-128.416504,0.016217,0.000000
17.390001,4.546295,-128.460983,0.004712,0.000612,0.015540,20.222931,1.030205,0.155404,-128.460983,0.016616,0.000000
17.630001,4.646461,-128.460983,0.004730,0.000622,0.015810,20.668493,1.052903,0.158095,-128.460983,0.017015,0.000000
17.870001,4.977127,-128.460983,0.004751,0.000650,0.016521,22.139366,1.127833,0.165207,-128.460983,0.017414,0.000000
18.110001,4.966705,-128.460983,0.004777,0.000665,0.016902,22.093008,1.125472,0.169022,-128.460983,0.017813,0.000000
18.350000,5.056442,-128.460983,0.004777,0.000681,0.017301,22.492178,1.145806,0.173011,-128.460983,0.018220,0.000000
18.590000,5.030006,-128.549942,0.004799,0.000693,0.017613,22.374586,1.139816,0.176134,-128.549942,0.018619,0.000000
18.830002,5.092567,-128.460983,0.004812,0.000707,0.017960,22.652872,1.153992,0.179601,-128.460983,0.019018,0.000000
19.070002,5.253799,-128.416504,0.004833,0.000727,0.018472,23.370068,1.190528,0.184718,-128.416504,0.019417,0.000000
19.310001,5.375198,-128.460983,0.004850,0.000740,0.018801,23.910076,1.218037,0.188015,-128.460983,0.019816,0.000000
19.550001,5.493607,-128.505463,0.004863,0.000759,0.019270,24.436783,1.244869,0.192697,-128.505463,0.020215,0.000000
19.790001,5.705116,-128.594437,0.004889,0.000778,0.019755,25.377625,1.292798,0.197553,-128.594437,0.020614,0.000000
20.030001,5.639580,-128.505463,0.004907,0.000789,0.020033,25.086103,1.277947,0.200327,-128.505463,0.021021,0.000000
20.270000,5.750549,-128.594437,0.004924,0.000807,0.020493,25.579721,1.303093,0.204926,-128.594437,0.021420,0.000000
20.510000,5.775124,-128.549942,0.004937,0.000821,0.020865,25.689034,1.308662,0.208654,-128.549942,0.021819,0.000000
20.750002,5.784058,-128.505463,0.004950,0.000834,0.021186,25.728773,1.310686,0.211863,-128.505463,0.022218,0.000000
20.990002,6.073021,-128.594437,0.004975,0.000856,0.021750,27.014147,1.376166,0.217499,-128.594437,0.022617,0.000000
21.230001,6.021637,-128.505463,0.004988,0.000866,0.021993,26.785580,1.364522,0.219929,-128.505463,0.023016,0.000000
21.470001,6.024612,-128.594437,0.004988,0.000878,0.022296,26.798815,1.365197,0.222961,-128.594437,0.023415,0.000000
21.710001,6.360489,-128.549942,0.005027,0.000903,0.022947,28.292868,1.441307,0.229467,-128.549942,0.023814,0.000000
21.950001,6.344109,-128.549942,0.005040,0.000916,0.023259,28.220005,1.437596,0.232589,-128.549942,0.024221,0.000000
22.190001,6.419327,-128.638916,0.005057,0.000934,0.023736,28.554592,1.454640,0.237358,-128.638916,0.024620,0.000000
22.430000,6.419701,-128.594437,0.005075,0.000946,0.024031,28.556255,1.454725,0.240307,-128.594437,0.025019,0.000000
22.670002,6.520241,-128.638916,0.005083,0.000962,0.024438,29.003479,1.477508,0.244383,-128.638916,0.025418,0.000000
22.910002,6.753342,-128.594437,0.005109,0.000980,0.024880,30.040363,1.530329,0.248804,-128.594437,0.025817,0.000000
23.150002,6.733978,-128.638916,0.005126,0.000992,0.025201,29.954231,1.525941,0.252013,-128.638916,0.026216,0.000000
23.390001,6.904160,-128.638916,0.005139,0.001012,0.025696,30.711235,1.564505,0.256957,-128.638916,0.026615,0.000000
23.630001,6.993156,-128.638916,0.005161,0.001030,0.026164,31.107113,1.584672,0.261642,-128.638916,0.027014,0.000000
23.870001,7.187531,-128.683395,0.005178,0.001051,0.026684,31.971733,1.628718,0.266843,-128.683395,0.027422,0.000000
24.110001,6.897827,-128.638916,0.005204,0.001058,0.026875,30.683067,1.563070,0.268750,-128.638916,0.027820,0.000000
24.350000,6.996880,-128.683395,0.005213,0.001074,0.027274,31.123674,1.585515,0.272740,-128.683395,0.028219,0.000000
24.590002,7.148064,-128.727875,0.005234,0.001089,0.027664,31.796175,1.619774,0.276642,-128.727875,0.028618,0.000000
24.830002,7.305573,-128.683395,0.005251,0.001106,0.028089,32.496811,1.655466,0.280892,-128.683395,0.029017,0.000000
25.070002,7.362923,-128.683395,0.005260,0.001121,0.028462,32.751915,1.668462,0.284620,-128.683395,0.029416,0.000000
25.310001,7.603470,-128.727875,0.005295,0.001140,0.028965,33.821922,1.722971,0.289650,-128.727875,0.029815,0.000000
25.550001,7.636612,-128.727875,0.005312,0.001157,0.029390,33.969345,1.730481,0.293901,-128.727875,0.030214,0.000000
25.790001,7.797852,-128.727875,0.005342,0.001177,0.029902,34.686577,1.767018,0.299018,-128.727875,0.030622,0.000000
26.030001,7.588951,-128.638916,0.005351,0.001188,0.030171,33.757339,1.719681,0.301705,-128.638916,0.031021,0.000000
26.270000,7.508141,-128.727875,0.005359,0.001201,0.030500,33.397877,1.701369,0.305002,-128.727875,0.031420,0.000000
26.510002,7.737900,-128.727875,0.005389,0.001216,0.030882,34.419899,1.753433,0.308817,-128.727875,0.031818,0.000000
26.750002,7.866737,-128.638916,0.005394,0.001232,0.031289,34.992996,1.782628,0.312893,-128.638916,0.032217,0.000000
26.990002,7.780350,-128.816833,0.005415,0.001241,0.031532,34.608723,1.763052,0.315323,-128.816833,0.032616,0.000000
27.230001,8.080109,-128.727875,0.005437,0.001262,0.032044,35.942120,1.830979,0.320437,-128.727875,0.033015,0.000000
27.470001,8.059631,-128.727875,0.005445,0.001276,0.032399,35.851032,1.826339,0.323995,-128.727875,0.033414,0.000000
27.710001,8.327736,-128.816833,0.005467,0.001296,0.032920,37.043621,1.887092,0.329199,-128.816833,0.033822,0.000000
27.950001,8.231293,-128.727875,0.005476,0.001309,0.033249,36.614620,1.865238,0.332492,-128.727875,0.034221,0.000000
28.190001,8.174316,-128.772354,0.005493,0.001321,0.033544,36.361176,1.852327,0.335440,-128.772354,0.034620,0.000000
28.430002,8.394760,-128.816833,0.005519,0.001339,0.034013,37.341759,1.902280,0.340126,-128.816833,0.035019,0.000000
28.670002,8.689682,-128.816833,0.005540,0.001362,0.034594,38.653637,1.969110,0.345936,-128.816833,0.035418,0.000000
28.910002,8.291618,-128.772354,0.005558,0.001367,0.034715,36.882961,1.878908,0.347151,-128.772354,0.035816,0.000000
29.150002,8.601059,-128.816833,0.005579,0.001388,0.035244,38.259422,1.949028,0.352438,-128.816833,0.036215,0.000000
29.390001,8.936195,-128.861313,0.005592,0.001409,0.035790,39.750183,2.024971,0.357903,-128.861313,0.036614,0.000000
29.630001,8.722824,-128.772354,0.005605,0.001421,0.036085,38.801060,1.976620,0.360852,-128.772354,0.037022,0.000000
29.870001,8.879967,-128.816833,0.005627,0.001440,0.036571,39.500065,2.012229,0.365708,-128.816833,0.037421,0.000000
30.110001,8.675529,-128.816833,0.005648,0.001450,0.036822,38.590683,1.965903,0.368221,-128.816833,0.037819,0.000000
30.350002,8.844963,-128.861313,0.005670,0.001468,0.037291,39.344360,2.004297,0.372907,-128.861313,0.038218,0.000000
30.590002,9.050140,-128.861313,0.005696,0.001487,0.037776,40.257034,2.050791,0.377763,-128.861313,0.038617,0.000000
30.830002,8.890388,-128.816833,0.005713,0.001498,0.038045,39.546425,2.014591,0.380450,-128.816833,0.039016,0.000000
31.070002,9.049393,-128.861313,0.005734,0.001515,0.038470,40.253708,2.050622,0.384701,-128.861313,0.039415,0.000000
31.310001,9.213608,-128.861313,0.005747,0.001533,0.038930,40.984173,2.087833,0.389295,-128.861313,0.039814,0.000000
31.550001,9.311172,-128.861313,0.005769,0.001551,0.039389,41.418163,2.109942,0.393894,-128.861313,0.040222,0.000000
31.790001,9.242279,-128.905792,0.005795,0.001566,0.039788,41.111710,2.094330,0.397883,-128.905792,0.040621,0.000000
32.030003,9.194992,-128.816833,0.005816,0.001580,0.040135,40.901367,2.083615,0.401350,-128.816833,0.041020,0.000000
32.270000,9.320480,-128.950272,0.005829,0.001596,0.040543,41.459568,2.112051,0.405427,-128.950272,0.041418,0.000000
32.510002,9.394958,-128.816833,0.005851,0.001614,0.040993,41.790863,2.128928,0.409934,-128.816833,0.041817,0.000000
32.750000,9.343941,-128.905792,0.005868,0.001626,0.041306,41.563923,2.117367,0.413057,-128.905792,0.042216,0.000000
32.990002,9.144348,-128.994751,0.005872,0.001637,0.041592,40.676090,2.072139,0.415918,-128.994751,0.042615,0.000000
33.230003,9.827278,-128.950272,0.005902,0.001662,0.042216,43.713917,2.226893,0.422163,-128.950272,0.043023,0.000000
33.470001,9.756905,-128.994751,0.005928,0.001677,0.042598,43.400879,2.210946,0.425979,-128.994751,0.043422,0.000000
33.710003,9.648911,-128.950272,0.005954,0.001692,0.042980,42.920498,2.186475,0.429798,-128.950272,0.043821,0.000000
33.950001,9.602737,-128.950272,0.005963,0.001707,0.043353,42.715111,2.176011,0.433526,-128.950272,0.044220,0.000000
34.190002,9.550980,-128.994751,0.005984,0.001718,0.043630,42.484879,2.164283,0.436300,-128.994751,0.044619,0.000000
34.430000,9.822067,-128.994751,0.005993,0.001739,0.044159,43.690739,2.225712,0.441591,-128.994751,0.045018,0.000000
34.670002,9.867867,-128.994751,0.006006,0.001752,0.044506,43.894463,2.236090,0.445058,-128.994751,0.045416,0.000000
34.910000,9.478737,-128.950272,0.006036,0.001757,0.044619,42.163528,2.147913,0.446186,-128.950272,0.045815,0.000000
35.150002,10.031342,-128.994751,0.006049,0.001780,0.045208,44.621635,2.273134,0.452083,-128.994751,0.046223,0.000000
35.390003,10.197044,-129.039246,0.006075,0.001799,0.045685,45.358719,2.310683,0.456852,-129.039246,0.046622,0.000000
35.630001,10.217529,-128.994751,0.006088,0.001816,0.046128,45.449841,2.315325,0.461277,-128.994751,0.047021,0.000000
35.870003,10.175079,-129.039246,0.006118,0.001831,0.046518,45.261013,2.305706,0.465179,-129.039246,0.047420,0.000000
36.110001,10.177307,-128.950272,0.006144,0.001847,0.046926,45.270924,2.306211,0.469255,-128.950272,0.047819,0.000000
36.350002,10.155716,-128.994751,0.006161,0.001860,0.047238,45.174881,2.301318,0.472378,-128.994751,0.048218,0.000000
36.590000,10.342644,-129.039246,0.006187,0.001879,0.047723,46.006378,2.343677,0.477234,-129.039246,0.048617,0.000000
36.830002,10.308754,-128.994751,0.006183,0.001892,0.048061,45.855629,2.335997,0.480614,-128.994751,0.049016,0.000000
37.070004,9.919632,-129.083725,0.006204,0.001900,0.048252,44.124725,2.247821,0.482525,-129.083725,0.049423,0.000000
37.310001,10.769379,-129.039246,0.006230,0.001928,0.048972,47.904591,2.440376,0.489720,-129.039246,0.049822,0.000000
37.550003,10.670334,-129.083725,0.006252,0.001944,0.049388,47.464016,2.417932,0.493883,-129.083725,0.050221,0.000000
37.790001,10.485260,-129.083725,0.006269,0.001957,0.049709,46.640766,2.375994,0.497093,-129.083725,0.050620,0.000000
38.030003,10.320671,-129.039246,0.006303,0.001970,0.050039,45.908638,2.338697,0.500390,-129.039246,0.051019,0.000000
38.270000,10.652832,-129.172684,0.006308,0.001987,0.050464,47.386162,2.413966,0.504636,-129.172684,0.051418,0.000000
38.510002,10.525108,-129.039246,0.006329,0.002000,0.050802,46.818020,2.385024,0.508020,-129.039246,0.051817,0.000000
38.750000,10.470741,-129.083725,0.006338,0.002011,0.051079,46.576183,2.372704,0.510794,-129.083725,0.052216,0.000000
38.990002,10.528831,-129.128204,0.006368,0.002030,0.051556,46.834583,2.385867,0.515563,-129.128204,0.052623,0.000000
39.230003,10.997650,-129.128204,0.006390,0.002050,0.052077,48.919991,2.492103,0.520768,-129.128204,0.053022,0.000000
39.470001,11.160744,-129.172684,0.006411,0.002069,0.052562,49.645466,2.529061,0.525624,-129.172684,0.053421,0.000000
39.710003,10.886307,-129.128204,0.006433,0.002083,0.052901,48.424709,2.466872,0.529007,-129.128204,0.053820,0.000000
39.950001,10.795448,-129.128204,0.006433,0.002096,0.053239,48.020554,2.446284,0.532387,-129.128204,0.054219,0.000000
40.190002,10.801407,-129.083725,0.006467,0.002112,0.053646,48.047058,2.447634,0.536463,-129.083725,0.054618,0.000000
40.430000,11.114197,-129.083725,0.006472,0.002129,0.054080,49.438416,2.518513,0.540801,-129.083725,0.055016,0.000000
40.670002,10.985733,-129.172684,0.006489,0.002141,0.054375,48.866982,2.489403,0.543749,-129.172684,0.055415,0.000000
40.910004,11.314163,-129.128204,0.006528,0.002161,0.054878,50.327911,2.563826,0.548779,-129.128204,0.055823,0.000000
41.150002,11.476891,-129.172684,0.006536,0.002179,0.055355,51.051758,2.600701,0.553548,-129.172684,0.056222,0.000000
41.390003,11.146225,-129.128204,0.006562,0.002190,0.055615,49.580887,2.525771,0.556149,-129.128204,0.056621,0.000000
41.630001,11.448593,-129.172684,0.006579,0.002209,0.056118,50.925884,2.594288,0.561179,-129.172684,0.057020,0.000000
41.870003,11.477638,-129.128204,0.006601,0.002225,0.056517,51.055084,2.600870,0.565168,-129.128204,0.057419,0.000000
42.110001,11.134682,-129.217163,0.006610,0.002234,0.056742,49.529537,2.523155,0.567424,-129.217163,0.057818,0.000000
42.350002,11.689140,-129.217163,0.006631,0.002256,0.057298,51.995892,2.648797,0.572976,-129.217163,0.058217,0.000000
42.590000,11.400551,-129.217163,0.006661,0.002265,0.057540,50.712181,2.583402,0.575402,-129.217163,0.058616,0.000000
42.830002,11.769203,-129.128204,0.006679,0.002287,0.058095,52.352032,2.666939,0.580955,-129.128204,0.059023,0.000000
43.070004,11.920761,-129.261642,0.006704,0.002303,0.058494,53.026196,2.701283,0.584944,-129.261642,0.059422,0.000000
43.310001,11.779259,-129.172684,0.006709,0.002318,0.058867,52.396759,2.669218,0.588672,-129.172684,0.059821,0.000000
43.550003,11.978104,-129.261642,0.006735,0.002336,0.059327,53.281265,2.714277,0.593267,-129.261642,0.060220,0.000000
43.790001,11.786331,-129.217163,0.006765,0.002346,0.059587,52.428219,2.670821,0.595871,-129.217163,0.060619,0.000000
44.030003,12.024277,-129.261642,0.006778,0.002365,0.060064,53.486652,2.724740,0.600640,-129.261642,0.061018,0.000000
44.270000,12.204506,-129.261642,0.006795,0.002380,0.060446,54.288353,2.765581,0.604455,-129.261642,0.061417,0.000000
44.510002,12.074173,-129.261642,0.006808,0.002391,0.060740,53.708603,2.736047,0.607404,-129.261642,0.061816,0.000000
44.750004,12.474846,-129.261642,0.006821,0.002414,0.061304,55.490887,2.826840,0.613039,-129.261642,0.062223,0.000000
44.990002,12.746681,-129.217163,0.006842,0.002434,0.061816,56.700069,2.888439,0.618157,-129.217163,0.062622,0.000000
45.230003,12.802910,-129.217163,0.006873,0.002450,0.062223,56.950188,2.901181,0.622233,-129.217163,0.063021,0.000000
45.470001,12.260735,-129.261642,0.006894,0.002459,0.062458,54.538471,2.778322,0.624576,-129.261642,0.063420,0.000000
45.710003,12.542992,-129.306122,0.006903,0.002475,0.062857,55.794014,2.842283,0.628565,-129.306122,0.063819,0.000000
45.950001,12.639061,-129.350601,0.006929,0.002490,0.063247,56.221352,2.864052,0.632467,-129.350601,0.064218,0.000000
46.190002,12.826736,-129.306122,0.006942,0.002506,0.063646,57.056171,2.906580,0.636457,-129.306122,0.064617,0.000000
46.430000,12.949623,-129.306122,0.006954,0.002519,0.063992,57.602802,2.934427,0.639924,-129.306122,0.065024,0.000000
46.670002,13.434082,-129.306122,0.006985,0.002541,0.064548,59.757782,3.044206,0.645476,-129.306122,0.065423,0.000000
46.910004,13.555473,-129.306122,0.006993,0.002560,0.065024,60.297756,3.071714,0.650245,-129.306122,0.065822,0.000000
47.150002,13.601646,-129.395081,0.007019,0.002577,0.065458,60.503143,3.082177,0.654582,-129.395081,0.066221,0.000000
47.390003,13.326836,-129.306122,0.007032,0.002588,0.065736,59.280727,3.019904,0.657357,-129.306122,0.066620,0.000000
47.630001,13.269867,-129.350601,0.007058,0.002601,0.066074,59.027317,3.006995,0.660737,-129.350601,0.067019,0.000000
47.870003,13.398331,-129.350601,0.007075,0.002616,0.066438,59.598751,3.036105,0.664382,-129.350601,0.067418,0.000000
48.110001,13.676865,-129.395081,0.007097,0.002632,0.066854,60.837730,3.099222,0.668541,-129.395081,0.067817,0.000000
48.350002,13.454185,-129.439575,0.007097,0.002640,0.067062,59.847206,3.048762,0.670623,-129.439575,0.068225,0.000000
48.590004,14.045143,-129.306122,0.007118,0.002661,0.067591,62.475918,3.182675,0.675914,-129.306122,0.068624,0.000000
48.830002,14.136002,-129.350601,0.007140,0.002678,0.068016,62.880077,3.203264,0.680165,-129.350601,0.069022,0.000000
49.070004,14.551567,-129.350601,0.007166,0.002697,0.068493,64.728600,3.297432,0.684934,-129.350601,0.069421,0.000000
49.310001,14.324425,-129.439575,0.007174,0.002709,0.068797,63.718224,3.245961,0.687969,-129.439575,0.069820,0.000000
49.550003,14.266335,-129.439575,0.007196,0.002721,0.069118,63.459824,3.232798,0.691179,-129.439575,0.070219,0.000000
49.790001,14.671844,-129.395081,0.007209,0.002742,0.069638,65.263626,3.324687,0.696379,-129.395081,0.070618,0.000000
50.030003,15.215881,-129.484055,0.007243,0.002761,0.070141,67.683624,3.447968,0.701409,-129.484055,0.071017,0.000000
50.270004,14.535561,-129.439575,0.007248,0.002766,0.070254,64.657402,3.293805,0.702537,-129.439575,0.071425,0.000000
50.510002,15.156677,-129.439575,0.007261,0.002787,0.070800,67.420265,3.434552,0.708002,-129.439575,0.071824,0.000000
50.750004,15.612457,-129.484055,0.007286,0.002808,0.071321,69.447678,3.537833,0.713207,-129.484055,0.072223,0.000000
50.990002,15.472450,-129.484055,0.007304,0.002822,0.071667,68.824898,3.506107,0.716674,-129.484055,0.072621,0.000000
51.230003,16.021324,-129.528534,0.007321,0.002841,0.072170,71.266411,3.630484,0.721704,-129.528534,0.073020,0.000000
51.470001,15.701454,-129.484055,0.007334,0.002853,0.072474,69.843559,3.558000,0.724739,-129.484055,0.073419,0.000000
51.710003,16.226501,-129.439575,0.007355,0.002872,0.072960,72.179085,3.676978,0.729595,-129.439575,0.073818,0.000000
51.950001,16.328903,-129.484055,0.007373,0.002886,0.073298,72.634590,3.700182,0.732979,-129.484055,0.074217,0.000000
52.190002,16.129684,-129.439575,0.007386,0.002896,0.073567,71.748421,3.655039,0.735666,-129.439575,0.074625,0.000000
52.430004,16.574669,-129.573013,0.007403,0.002913,0.074000,73.727806,3.755874,0.740004,-129.573013,0.075023,0.000000
52.670002,17.123917,-129.484055,0.007433,0.002936,0.074564,76.170982,3.880335,0.745639,-129.484055,0.075422,0.000000
52.910004,17.332817,-129.528534,0.007442,0.002951,0.074963,77.100220,3.927672,0.749629,-129.528534,0.075821,0.000000
53.150002,17.460541,-129.528534,0.007459,0.002967,0.075371,77.668365,3.956615,0.753705,-129.528534,0.076220,0.000000
53.390003,17.605392,-129.484055,0.007463,0.002982,0.075752,78.312698,3.989439,0.757520,-129.484055,0.076619,0.000000
53.630001,18.036972,-129.573013,0.007493,0.003000,0.076203,80.232460,4.087236,0.762028,-129.573013,0.077018,0.000000
53.870003,18.314018,-129.484055,0.007506,0.003016,0.076602,81.464821,4.150016,0.766017,-129.484055,0.077417,0.000000
54.110004,18.201935,-129.528534,0.007515,0.003025,0.076836,80.966248,4.124618,0.768360,-129.528534,0.077825,0.000000
54.350002,18.544144,-129.573013,0.007532,0.003040,0.077218,82.488472,4.202163,0.772175,-129.573013,0.078224,0.000000
54.590004,19.605034,-129.617493,0.007537,0.003064,0.077833,87.207542,4.442564,0.778333,-129.617493,0.078622,0.000000
54.830002,19.618813,-129.573013,0.007567,0.003078,0.078189,87.268837,4.445686,0.781891,-129.573013,0.079021,0.000000
55.070004,19.886925,-129.528534,0.007575,0.003093,0.078571,88.461456,4.506442,0.785706,-129.528534,0.079420,0.000000
55.310001,20.062309,-129.573013,0.007588,0.003107,0.078917,89.241608,4.546185,0.789173,-129.573013,0.079819,0.000000
55.550003,20.158752,-129.617493,0.007610,0.003122,0.079290,89.670609,4.568038,0.792901,-129.617493,0.080218,0.000000
55.790001,20.941483,-129.573013,0.007614,0.003139,0.079724,93.152367,4.745408,0.797239,-129.573013,0.080617,0.000000
56.030003,21.159317,-129.661972,0.007631,0.003151,0.080045,94.121346,4.794770,0.800449,-129.661972,0.081025,0.000000
56.270004,20.683800,-129.617493,0.007649,0.003157,0.080192,92.006134,4.687016,0.801921,-129.617493,0.081424,0.000000
56.510002,21.892517,-129.661972,0.007644,0.003181,0.080790,97.382782,4.960916,0.807905,-129.661972,0.081823,0.000000
56.750004,22.472305,-129.661972,0.007670,0.003198,0.081233,99.961807,5.092297,0.812329,-129.661972,0.082222,0.000000
56.990002,23.183907,-129.661972,0.007687,0.003219,0.081771,103.127167,5.253549,0.817708,-129.661972,0.082620,0.000000
57.230003,23.466911,-129.617493,0.007700,0.003233,0.082126,104.386032,5.317678,0.821262,-129.617493,0.083019,0.000000
57.470001,23.878754,-129.617493,0.007726,0.003247,0.082482,106.218002,5.411003,0.824816,-129.617493,0.083418,0.000000
57.710003,24.254478,-129.661972,0.007718,0.003265,0.082941,107.889305,5.496144,0.829414,-129.661972,0.083817,0.000000
57.950005,24.740425,-129.706451,0.007739,0.003278,0.083271,110.050911,5.606261,0.832707,-129.706451,0.084225,0.000000
58.190002,24.984703,-129.706451,0.007752,0.003291,0.083583,111.137512,5.661615,0.835830,-129.706451,0.084624,0.000000
58.430004,24.897568,-129.661972,0.007761,0.003307,0.083991,110.749916,5.641869,0.839906,-129.661972,0.085023,0.000000
58.670002,26.661865,-129.661972,0.007787,0.003329,0.084546,118.597900,6.041665,0.845459,-129.661972,0.085422,0.000000
58.910004,27.095306,-129.661972,0.007778,0.003344,0.084936,120.525940,6.139884,0.849361,-129.661972,0.085821,0.000000
59.150002,27.356339,-129.706451,0.007804,0.003357,0.085265,121.687073,6.199035,0.852654,-129.706451,0.086220,0.000000
59.390003,27.649773,-129.706451,0.007808,0.003370,0.085604,122.992332,6.265528,0.856037,-129.706451,0.086618,0.000000
59.630001,28.530060,-129.661972,0.007825,0.003387,0.086029,126.908043,6.465004,0.860288,-129.661972,0.087026,0.000000
59.870003,28.857376,-129.706451,0.007838,0.003400,0.086349,128.364014,6.539175,0.863494,-129.706451,0.087425,0.000000
60.110004,29.194000,-129.750931,0.007843,0.003411,0.086636,129.861404,6.615455,0.866359,-129.750931,0.087824,0.000000
60.350002,30.186371,-129.661972,0.007856,0.003435,0.087251,134.275681,6.840329,0.872513,-129.661972,0.088223,0.000000
60.590004,31.311684,-129.706451,0.007864,0.003451,0.087650,139.281326,7.095329,0.876502,-129.706451,0.088622,0.000000
60.830002,32.191597,-129.706451,0.007869,0.003469,0.088110,143.195374,7.294720,0.881101,-129.706451,0.089021,0.000000
61.070004,32.626526,-129.706451,0.007899,0.003484,0.088492,145.130035,7.393276,0.884916,-129.706451,0.089420,0.000000
61.310001,32.944908,-129.750931,0.007894,0.003496,0.088804,146.546265,7.465423,0.888039,-129.750931,0.089819,0.000000
61.550003,33.878075,-129.750931,0.007920,0.003514,0.089255,150.697205,7.676881,0.892546,-129.750931,0.090226,0.000000
61.790005,34.696548,-129.795410,0.007907,0.003530,0.089662,154.337952,7.862350,0.896623,-129.795410,0.090625,0.000000
62.030003,35.096848,-129.706451,0.007933,0.003542,0.089975,156.118576,7.953059,0.899745,-129.706451,0.091024,0.000000
62.270004,36.238541,-129.706451,0.007938,0.003561,0.090451,161.197083,8.211771,0.904514,-129.706451,0.091423,0.000000
62.510002,37.205223,-129.884384,0.007938,0.003579,0.090911,165.497101,8.430824,0.909113,-129.884384,0.091822,0.000000
62.750004,37.659889,-129.839890,0.007963,0.003591,0.091206,167.519547,8.533853,0.912061,-129.839890,0.092220,0.000000
62.990002,38.657845,-129.839890,0.007963,0.003609,0.091657,171.958679,8.759993,0.916569,-129.839890,0.092619,0.000000
63.230003,39.437592,-129.795410,0.007976,0.003625,0.092073,175.427170,8.936686,0.920732,-129.795410,0.093018,0.000000
63.470001,40.100044,-129.750931,0.007981,0.003641,0.092481,178.373901,9.086800,0.924809,-129.750931,0.093426,0.000000
63.710003,41.122948,-129.795410,0.007998,0.003656,0.092862,182.924011,9.318593,0.928624,-129.795410,0.093825,0.000000
63.950005,41.404465,-129.839890,0.008015,0.003664,0.093062,184.176254,9.382386,0.930619,-129.839890,0.094224,0.000000
64.190002,42.995613,-129.795410,0.008011,0.003690,0.093738,191.254044,9.742945,0.937382,-129.795410,0.094623,0.000000
64.430000,43.873291,-129.884384,0.008019,0.003705,0.094103,195.158142,9.941830,0.941027,-129.884384,0.095022,0.000000
64.670006,44.585640,-129.795410,0.008032,0.003717,0.094423,198.326828,10.103250,0.944233,-129.795410,0.095421,0.000000
64.910004,45.743721,-129.839890,0.008041,0.003736,0.094883,203.478241,10.365675,0.948832,-129.839890,0.095820,0.000000
65.150002,46.106041,-129.839890,0.008041,0.003745,0.095117,205.089920,10.447779,0.951171,-129.839890,0.096218,0.000000
65.389999,47.328537,-129.884384,0.008058,0.003765,0.095620,210.527847,10.724800,0.956201,-129.884384,0.096626,0.000000
65.630005,48.496674,-129.973343,0.008067,0.003783,0.096089,215.723984,10.989504,0.960886,-129.973343,0.097025,0.000000
65.870003,48.933838,-129.839890,0.008080,0.003794,0.096357,217.668579,11.088567,0.963574,-129.839890,0.097424,0.000000
66.110001,50.667976,-129.973343,0.008071,0.003815,0.096904,225.382416,11.481527,0.969035,-129.973343,0.097823,0.000000
66.350006,52.166771,-129.928864,0.008093,0.003836,0.097433,232.049393,11.821159,0.974327,-129.928864,0.098222,0.000000
66.590004,53.126747,-129.928864,0.008101,0.003849,0.097771,236.319580,12.038693,0.977710,-129.928864,0.098621,0.000000
66.830002,53.329697,-129.928864,0.008093,0.003859,0.098031,237.222336,12.084682,0.980310,-129.928864,0.099020,0.000000
67.070000,54.432289,-129.884384,0.008114,0.003874,0.098404,242.126907,12.334533,0.984039,-129.884384,0.099419,0.000000
67.310005,55.457054,-129.928864,0.008110,0.003891,0.098838,246.685303,12.566748,0.988376,-129.928864,0.099826,0.000000
67.550003,56.612526,-129.884384,0.008136,0.003905,0.099193,251.825089,12.828582,0.991930,-129.884384,0.100225,0.000000
67.790001,57.608994,-129.884384,0.008123,0.003919,0.099531,256.257599,13.054384,0.995314,-129.884384,0.100624,0.000000
68.030006,59.392662,-129.973343,0.008140,0.003941,0.100095,264.191742,13.458570,1.000950,-129.973343,0.101023,0.000000
68.270004,60.799484,-129.973343,0.008149,0.003960,0.100572,270.449615,13.777360,1.005718,-129.973343,0.101422,0.000000
68.510002,62.110237,-130.062302,0.008149,0.003976,0.100988,276.280121,14.074381,1.009882,-130.062302,0.101821,0.000000
68.750000,62.721298,-129.928864,0.008170,0.003987,0.101274,278.998260,14.212850,1.012743,-129.928864,0.102220,0.000000
68.990005,63.423965,-129.973343,0.008166,0.003998,0.101543,282.123901,14.372076,1.015434,-129.973343,0.102619,0.000000
69.230003,64.605133,-129.973343,0.008162,0.004015,0.101977,287.377991,14.639732,1.019768,-129.973343,0.103026,0.000000
69.470001,65.956848,-129.973343,0.008179,0.004031,0.102393,293.390717,14.946035,1.023931,-129.973343,0.103425,0.000000
69.710007,66.539978,-130.017822,0.008183,0.004039,0.102593,295.984619,15.078175,1.025926,-130.017822,0.103824,0.000000
69.950005,67.465317,-130.017822,0.008188,0.004044,0.102705,300.100708,15.287860,1.027054,-130.017822,0.102965,0.000000
70.190002,66.960754,-130.017822,0.008201,0.004044,0.102705,297.856323,15.173524,1.027054,-130.017822,0.102965,0.000000
70.430000,66.463638,-130.106781,0.008196,0.004039,0.102593,295.645020,15.060876,1.025926,-130.106781,0.102705,0.000000
70.670006,66.083084,-130.017822,0.008209,0.004038,0.102566,293.952240,14.974641,1.025665,-130.017822,0.102705,0.000000
70.910004,65.715546,-130.062302,0.008205,0.004038,0.102558,292.317352,14.891356,1.025582,-130.062302,0.102705,0.000000
71.150002,65.410202,-130.017822,0.008209,0.004037,0.102549,290.959106,14.822164,1.025495,-130.017822,0.102705,0.000000
71.390007,65.133896,-130.017822,0.008205,0.004037,0.102549,289.730042,14.759551,1.025495,-130.017822,0.102705,0.000000
71.630005,64.879944,-130.062302,0.008213,0.004037,0.102541,288.600403,14.702005,1.025408,-130.062302,0.102705,0.000000
71.870003,64.641251,-130.017822,0.008213,0.004037,0.102541,287.538635,14.647917,1.025408,-130.017822,0.102705,0.000000
72.110001,64.433472,-130.106781,0.008209,0.004037,0.102541,286.614410,14.600834,1.025408,-130.106781,0.102705,0.000000
72.350006,64.238342,-130.106781,0.008209,0.004037,0.102541,285.746429,14.556616,1.025408,-130.106781,0.102705,0.000000
72.590004,64.057739,-130.062302,0.008209,0.004037,0.102541,284.943054,14.515691,1.025408,-130.062302,0.102705,0.000000
72.830002,63.898743,-130.106781,0.008205,0.004037,0.102541,284.235809,14.479662,1.025408,-130.106781,0.102705,0.000000
73.070000,63.737503,-130.106781,0.008226,0.004037,0.102541,283.518585,14.443124,1.025408,-130.106781,0.102705,0.000000
73.310005,63.594513,-130.106781,0.008209,0.004037,0.102532,282.882507,14.410723,1.025321,-130.106781,0.102705,0.000000
73.550003,63.447800,-130.106781,0.008213,0.004037,0.102532,282.229919,14.377478,1.025321,-130.106781,0.102705,0.000000
73.790001,63.331619,-130.151260,0.008205,0.004037,0.102532,281.713104,14.351150,1.025321,-130.151260,0.102705,0.000000
74.030006,63.201660,-130.151260,0.008213,0.004037,0.102532,281.135040,14.321700,1.025321,-130.151260,0.102705,0.000000
74.270004,63.079147,-130.106781,0.008222,0.004037,0.102532,280.590057,14.293939,1.025321,-130.106781,0.102705,0.000000
74.510002,62.971909,-130.195740,0.008226,0.004037,0.102532,280.113037,14.269638,1.025321,-130.195740,0.102705,0.000000
74.750000,62.856094,-130.151260,0.008218,0.004037,0.102532,279.597870,14.243395,1.025321,-130.151260,0.102705,0.000000
74.990005,62.769707,-130.151260,0.008222,0.004037,0.102532,279.213593,14.223819,1.025321,-130.151260,0.102705,0.000000
75.230003,62.663208,-130.195740,0.008222,0.004037,0.102532,278.739868,14.199686,1.025321,-130.195740,0.102705,0.000000
75.470001,62.589104,-130.062302,0.008222,0.004037,0.102532,278.410248,14.182894,1.025321,-130.062302,0.102705,0.000000
75.710007,62.476280,-130.151260,0.008218,0.004037,0.102532,277.908386,14.157328,1.025321,-130.151260,0.102705,0.000000
75.950005,62.397331,-130.151260,0.008222,0.004037,0.102532,277.557190,14.139438,1.025321,-130.151260,0.102705,0.000000
76.190002,62.324348,-130.151260,0.008231,0.004037,0.102532,277.232544,14.122900,1.025321,-130.151260,0.102705,0.000000
76.430000,62.245407,-130.284698,0.008218,0.004037,0.102532,276.881409,14.105011,1.025321,-130.284698,0.102705,0.000000
76.670006,62.169815,-130.195740,0.008222,0.004037,0.102532,276.545135,14.087881,1.025321,-130.195740,0.102705,0.000000
76.910004,62.108376,-130.195740,0.008222,0.004037,0.102532,276.271851,14.073958,1.025321,-130.195740,0.102705,0.000000
77.150002,62.033897,-130.240219,0.008226,0.004037,0.102532,275.940552,14.057082,1.025321,-130.240219,0.102705,0.000000
77.390007,61.963890,-130.195740,0.008231,0.004037,0.102532,275.629150,14.041219,1.025321,-130.195740,0.102705,0.000000
77.630005,61.897614,-130.240219,0.008226,0.004037,0.102532,275.334351,14.026200,1.025321,-130.240219,0.102705,0.000000
77.870003,61.835800,-130.240219,0.008235,0.004037,0.102532,275.059387,14.012193,1.025321,-130.240219,0.102705,0.000000
78.110001,61.773239,-130.284698,0.008239,0.004037,0.102532,274.781097,13.998016,1.025321,-130.284698,0.102705,0.000000
78.350006,61.712166,-130.240219,0.008231,0.004037,0.102532,274.509430,13.984177,1.025321,-130.240219,0.102705,0.000000
78.590004,61.651474,-130.284698,0.008231,0.004037,0.102532,274.239441,13.970424,1.025321,-130.284698,0.102705,0.000000
78.830002,61.597107,-130.284698,0.008222,0.004037,0.102532,273.997620,13.958104,1.025321,-130.284698,0.102705,0.000000
79.070007,61.546837,-130.329193,0.008222,0.004037,0.102532,273.774017,13.946713,1.025321,-130.329193,0.102705,0.000000
79.310005,61.489861,-130.284698,0.008235,0.004037,0.102532,273.520569,13.933802,1.025321,-130.284698,0.102705,0.000000
79.550003,61.444809,-130.284698,0.008239,0.004037,0.102532,273.320160,13.923593,1.025321,-130.284698,0.102705,0.000000
79.790001,61.400124,-130.284698,0.008235,0.004037,0.102532,273.121399,13.913466,1.025321,-130.284698,0.102705,0.000000
80.030006,61.336449,-130.284698,0.008239,0.004037,0.102532,272.838165,13.899037,1.025321,-130.284698,0.102705,0.000000
80.270004,61.293251,-130.373672,0.008244,0.004037,0.102532,272.645996,13.889250,1.025321,-130.373672,0.102705,0.000000
80.510002,61.251175,-130.284698,0.008222,0.004037,0.102532,272.458832,13.879714,1.025321,-130.284698,0.102705,0.000000
80.750008,61.200157,-130.329193,0.008235,0.004037,0.102532,272.231903,13.868154,1.025321,-130.329193,0.102705,0.000000
80.990005,61.165527,-130.329193,0.008231,0.004037,0.102532,272.077850,13.860307,1.025321,-130.329193,0.102705,0.000000
81.230003,61.120842,-130.373672,0.008231,0.004037,0.102532,271.879089,13.850181,1.025321,-130.373672,0.102705,0.000000
81.470001,61.089935,-130.329193,0.008231,0.004037,0.102532,271.741608,13.843178,1.025321,-130.329193,0.102705,0.000000
81.710007,61.035942,-130.373672,0.008235,0.004037,0.102532,271.501434,13.830942,1.025321,-130.373672,0.102705,0.000000
81.950005,61.001686,-130.373672,0.008239,0.004036,0.102523,271.349060,13.823179,1.025233,-130.373672,0.102705,0.000000
82.190002,60.967422,-130.373672,0.008244,0.004036,0.102523,271.196625,13.815415,1.025233,-130.373672,0.102705,0.000000
82.430000,60.921997,-130.373672,0.008248,0.004036,0.102523,270.994568,13.805121,1.025233,-130.373672,0.102705,0.000000
82.670006,60.894814,-130.284698,0.008244,0.004036,0.102523,270.873657,13.798962,1.025233,-130.284698,0.102705,0.000000
82.910004,60.840820,-130.373672,0.008239,0.004036,0.102523,270.633484,13.786727,1.025233,-130.373672,0.102705,0.000000
83.150002,60.825180,-130.418152,0.008231,0.004036,0.102523,270.563904,13.783182,1.025233,-130.418152,0.102705,0.000000
83.390007,60.781982,-130.373672,0.008235,0.004036,0.102523,270.371765,13.773395,1.025233,-130.373672,0.102705,0.000000
83.630005,60.745865,-130.418152,0.008244,0.004036,0.102523,270.211090,13.765210,1.025233,-130.418152,0.102705,0.000000
83.870003,60.715332,-130.418152,0.008235,0.004036,0.102523,270.075287,13.758290,1.025233,-130.418152,0.102705,0.000000
84.110001,60.689636,-130.462631,0.008231,0.004036,0.102523,269.960999,13.752468,1.025233,-130.462631,0.102705,0.000000
84.350006,60.649422,-130.418152,0.008248,0.004036,0.102523,269.782104,13.743356,1.025233,-130.418152,0.102705,0.000000
84.590004,60.614044,-130.418152,0.008231,0.004036,0.102523,269.624725,13.735338,1.025233,-130.418152,0.102705,0.000000
84.830002,60.577927,-130.462631,0.008244,0.004036,0.102523,269.464081,13.727155,1.025233,-130.462631,0.102705,0.000000
85.070007,60.570473,-130.462631,0.008244,0.004036,0.102523,269.430908,13.725465,1.025233,-130.462631,0.102705,0.000000
85.310005,60.523560,-130.462631,0.008239,0.004036,0.102523,269.222229,13.714835,1.025233,-130.462631,0.102705,0.000000
85.550003,60.504196,-130.462631,0.008231,0.004036,0.102523,269.136108,13.710447,1.025233,-130.462631,0.102705,0.000000
85.790001,60.478874,-130.462631,0.008226,0.004036,0.102523,269.023468,13.704709,1.025233,-130.462631,0.102705,0.000000
86.030006,60.448334,-130.462631,0.008235,0.004036,0.102523,268.887604,13.697788,1.025233,-130.462631,0.102705,0.000000
86.270004,60.418922,-130.462631,0.008244,0.004036,0.102523,268.756775,13.691124,1.025233,-130.462631,0.102705,0.000000
86.510002,60.392853,-130.507111,0.008235,0.004036,0.102523,268.640839,13.685216,1.025233,-130.507111,0.102705,0.000000
86.750008,60.365295,-130.462631,0.008239,0.004036,0.102523,268.518250,13.678971,1.025233,-130.462631,0.102705,0.000000
86.990005,60.325081,-130.462631,0.008235,0.004036,0.102523,268.339355,13.669859,1.025233,-130.462631,0.102705,0.000000
87.230003,60.319870,-130.551590,0.008235,0.004036,0.102523,268.316193,13.668677,1.025233,-130.551590,0.102705,0.000000
87.470001,60.287842,-130.507111,0.008239,0.004036,0.102523,268.173706,13.661420,1.025233,-130.507111,0.102705,0.000000
87.710007,60.268112,-130.507111,0.008235,0.004036,0.102523,268.085937,13.656949,1.025233,-130.507111,0.102705,0.000000
87.950005,60.237946,-130.462631,0.008244,0.004036,0.102523,267.951752,13.650113,1.025233,-130.462631,0.102705,0.000000
88.190002,60.205925,-130.462631,0.008239,0.004036,0.102523,267.809326,13.642858,1.025233,-130.462631,0.102705,0.000000
88.430008,60.181717,-130.551590,0.008244,0.004036,0.102523,267.701660,13.637372,1.025233,-130.551590,0.102705,0.000000
88.670006,60.170921,-130.507111,0.008252,0.004036,0.102523,267.653625,13.634926,1.025233,-130.507111,0.102705,0.000000
88.910004,60.156395,-130.551590,0.008235,0.004036,0.102523,267.589020,13.631634,1.025233,-130.551590,0.102705,0.000000
89.150002,60.139267,-130.596069,0.008244,0.004036,0.102523,267.512817,13.627753,1.025233,-130.596069,0.102705,0.000000
89.390007,60.098679,-130.462631,0.008235,0.004036,0.102523,267.332275,13.618556,1.025233,-130.462631,0.102705,0.000000
89.630005,60.094582,-130.640549,0.008235,0.004036,0.102523,267.314056,13.617627,1.025233,-130.640549,0.102705,0.000000
89.870003,60.053993,-130.596069,0.008248,0.004036,0.102523,267.133514,13.608430,1.025233,-130.596069,0.102705,0.000000
90.110001,60.048409,-130.596069,0.008235,0.004036,0.102523,267.108673,13.607164,1.025233,-130.596069,0.102705,0.000000
90.350006,60.020851,-130.596069,0.008244,0.004036,0.102523,266.986084,13.600919,1.025233,-130.596069,0.102705,0.000000
90.590004,59.990318,-130.551590,0.008235,0.004036,0.102523,266.850250,13.594001,1.025233,-130.551590,0.102705,0.000000
90.830002,59.976166,-130.640549,0.008244,0.004036,0.102523,266.787323,13.590793,1.025233,-130.640549,0.102705,0.000000
91.070007,59.949356,-130.640549,0.008231,0.004036,0.102523,266.668060,13.584719,1.025233,-130.640549,0.102705,0.000000
91.310005,59.953079,-130.596069,0.008239,0.004036,0.102523,266.684601,13.585562,1.025233,-130.596069,0.102705,0.000000
91.550003,59.910629,-130.640549,0.008244,0.004036,0.102523,266.495789,13.575942,1.025233,-130.640549,0.102705,0.000000
91.790001,59.882332,-130.685028,0.008239,0.004036,0.102523,266.369904,13.569530,1.025233,-130.685028,0.102705,0.000000
92.030006,59.871162,-130.640549,0.008244,0.004036,0.102523,266.320221,13.566999,1.025233,-130.640549,0.102705,0.000000
92.270004,59.848442,-130.640549,0.008239,0.004036,0.102523,266.219177,13.561852,1.025233,-130.640549,0.102705,0.000000
92.510002,59.823494,-130.685028,0.008235,0.004036,0.102523,266.108185,13.556198,1.025233,-130.685028,0.102705,0.000000
92.750008,59.814186,-130.640549,0.008239,0.004036,0.102523,266.066803,13.554088,1.025233,-130.640549,0.102705,0.000000
92.990005,59.785889,-130.640549,0.008239,0.004036,0.102523,265.940918,13.547676,1.025233,-130.640549,0.102705,0.000000
93.230003,59.769127,-130.685028,0.008244,0.004036,0.102523,265.866364,13.543878,1.025233,-130.685028,0.102705,0.000000
93.470001,59.753120,-130.685028,0.008239,0.004036,0.102523,265.795166,13.540251,1.025233,-130.685028,0.102705,0.000000
93.710007,59.737106,-130.685028,0.008226,0.004036,0.102523,265.723907,13.536622,1.025233,-130.685028,0.102705,0.000000
93.950005,59.723328,-130.729523,0.008239,0.004036,0.102523,265.662628,13.533499,1.025233,-130.729523,0.102705,0.000000
94.190002,59.711784,-130.685028,0.008244,0.004036,0.102523,265.611298,13.530884,1.025233,-130.685028,0.102705,0.000000
94.430008,59.704712,-130.729523,0.008244,0.004036,0.102523,265.579834,13.529282,1.025233,-130.729523,0.102705,0.000000
94.670006,59.676407,-130.685028,0.008239,0.004036,0.102523,265.453918,13.522867,1.025233,-130.685028,0.102705,0.000000
94.910004,59.654442,-130.729523,0.008231,0.004036,0.102523,265.356201,13.517890,1.025233,-130.729523,0.102705,0.000000
95.150002,59.632095,-130.729523,0.008244,0.004036,0.102523,265.256805,13.512826,1.025233,-130.729523,0.102705,0.000000
95.390007,59.635078,-130.729523,0.008239,0.004036,0.102523,265.270081,13.513502,1.025233,-130.729523,0.102705,0.000000
95.630005,59.611244,-130.774002,0.008252,0.004036,0.102523,265.164062,13.508101,1.025233,-130.774002,0.102705,0.000000
95.870003,59.592628,-130.729523,0.008244,0.004036,0.102523,265.081238,13.503882,1.025233,-130.729523,0.102705,0.000000
96.110008,59.579224,-130.774002,0.008226,0.004036,0.102523,265.021637,13.500845,1.025233,-130.774002,0.102705,0.000000
96.350006,59.553902,-130.729523,0.008244,0.004036,0.102523,264.908997,13.495108,1.025233,-130.729523,0.102705,0.000000
96.590004,59.541985,-130.774002,0.008252,0.004036,0.102523,264.855988,13.492407,1.025233,-130.774002,0.102705,0.000000
96.830002,59.523735,-130.818481,0.008235,0.004036,0.102523,264.774811,13.488272,1.025233,-130.818481,0.102705,0.000000
97.070007,59.506233,-130.774002,0.008248,0.004036,0.102523,264.696960,13.484305,1.025233,-130.774002,0.102705,0.000000
97.310005,59.492828,-130.818481,0.008235,0.004036,0.102523,264.637329,13.481267,1.025233,-130.818481,0.102705,0.000000
97.550003,59.464905,-130.818481,0.008257,0.004036,0.102523,264.513092,13.474939,1.025233,-130.818481,0.102705,0.000000
97.790001,59.470490,-130.818481,0.008239,0.004036,0.102523,264.537964,13.476205,1.025233,-130.818481,0.102705,0.000000
98.030006,59.445168,-130.862961,0.008239,0.004036,0.102523,264.425323,13.470468,1.025233,-130.862961,0.102705,0.000000
98.270004,59.433250,-130.818481,0.008248,0.004036,0.102523,264.372314,13.467767,1.025233,-130.818481,0.102705,0.000000
98.510002,59.418724,-130.862961,0.008244,0.004036,0.102523,264.307678,13.464475,1.025233,-130.862961,0.102705,0.000000
98.750008,59.406067,-130.818481,0.008244,0.004036,0.102523,264.251373,13.461607,1.025233,-130.818481,0.102705,0.000000
98.990005,59.388565,-130.862961,0.008235,0.004036,0.102523,264.173523,13.457641,1.025233,-130.862961,0.102705,0.000000
99.230003,59.370689,-130.907440,0.008244,0.004036,0.102523,264.094025,13.453591,1.025233,-130.907440,0.102705,0.000000
99.470001,59.365852,-130.907440,0.008239,0.004036,0.102523,264.072510,13.452495,1.025233,-130.907440,0.102705,0.000000
99.710007,59.351326,-130.862961,0.008239,0.004036,0.102523,264.007874,13.449203,1.025233,-130.862961,0.102705,0.000000
99.950005,59.332336,-130.862961,0.008244,0.004036,0.102523,263.923401,13.444900,1.025233,-130.862961,0.102705,0.000000
100.190002,59.330101,-130.862961,0.008244,0.004036,0.102523,263.913483,13.444392,1.025233,-130.862961,0.102705,0.000000
100.300003,59.315582,-130.862961,0.008248,0.004036,0.102523,263.848877,13.441104,1.025233,-130.862961,0.102705,0.000000