File: Data/compression 8/AutoHeating-17-8-1-2-240328_03282024_153634.csv
Time (sec),S:Load (lbs),S:HL1 (DIM),S:LVDT (in),S:Position (in),Ch:Position (mm),Ch:Load (N),Ch:Stress (MPa),Ch:Strain (mm/mm),Ch:HL1 (DIM),Set Point (),Cycles ()
0.110000,0.010048,-153.726166,0.000004,-0.000000,-0.000000,0.044695,0.002277,-0.000000,-153.726166,0.000199,0.000000
0.330000,0.001862,-153.681686,-0.000004,-0.000000,-0.000000,0.008281,0.000422,-0.000000,-153.681686,0.000199,0.000000
0.550000,0.027184,-153.770645,-0.000013,0.000095,0.002402,0.120918,0.006160,0.024019,-153.770645,0.002975,0.000000
0.770000,0.017868,-153.726166,0.000047,0.000223,0.005663,0.079481,0.004049,0.056630,-153.726166,0.006634,0.000000
0.990000,-0.000748,-153.770645,0.000185,0.000369,0.009366,-0.003326,-0.000169,0.093657,-153.770645,0.010311,0.000000
1.210000,-0.043198,-153.770645,0.000332,0.000507,0.012878,-0.192153,-0.009789,0.128781,-153.770645,0.013971,0.000000
1.430000,-0.040962,-153.815125,0.000474,0.000647,0.016434,-0.182209,-0.009282,0.164336,-153.815125,0.017630,0.000000
1.650000,-0.035378,-153.770645,0.000629,0.000800,0.020319,-0.157367,-0.008017,0.203188,-153.770645,0.021290,0.000000
1.870000,0.004463,-153.770645,0.000772,0.000941,0.023892,0.019853,0.001011,0.238918,-153.770645,0.024967,0.000000
2.090000,0.023453,-153.815125,0.000914,0.001079,0.027413,0.104323,0.005314,0.274129,-153.815125,0.028627,0.000000
2.310000,0.025322,-153.859604,0.001069,0.001229,0.031211,0.112638,0.005738,0.312114,-153.859604,0.032287,0.000000
2.530000,0.025322,-153.815125,0.001216,0.001378,0.035010,0.112638,0.005738,0.350099,-153.815125,0.035964,0.000000
2.750000,0.001488,-153.770645,0.001362,0.001519,0.038592,0.006618,0.000337,0.385915,-153.770645,0.039623,0.000000
2.970000,-0.026070,-153.815125,0.001505,0.001664,0.042260,-0.115964,-0.005907,0.422599,-153.815125,0.043283,0.000000
3.190000,-0.005959,-153.815125,0.001647,0.001808,0.045919,-0.026505,-0.001350,0.459195,-153.815125,0.046960,0.000000
3.410000,-0.003723,-153.859604,0.001794,0.001952,0.049570,-0.016561,-0.000844,0.495704,-153.859604,0.050620,0.000000
3.630000,0.015640,-153.770645,0.001940,0.002091,0.053117,0.069571,0.003544,0.531172,-153.770645,0.054280,0.000000
3.850000,-0.016388,-153.859604,0.002082,0.002240,0.056890,-0.072897,-0.003714,0.568900,-153.859604,0.057957,0.000000
4.070000,0.020477,-153.815125,0.002233,0.002384,0.060541,0.091088,0.004640,0.605409,-153.815125,0.061616,0.000000
4.290000,-0.000000,-153.904083,0.002384,0.002532,0.064305,-0.000000,-0.000000,0.643046,-153.904083,0.065276,0.000000
4.510000,-0.017136,-153.859604,0.002531,0.002672,0.067878,-0.076223,-0.003883,0.678775,-153.859604,0.068953,0.000000
4.730000,0.000740,-153.859604,0.002686,0.002816,0.071528,0.003292,0.000168,0.715285,-153.859604,0.072612,0.000000
4.950000,0.013405,-153.859604,0.002833,0.002964,0.075284,0.059628,0.003038,0.752838,-153.859604,0.076272,0.000000
5.170000,0.007446,-153.859604,0.002984,0.003104,0.078831,0.033123,0.001687,0.788307,-153.859604,0.079949,0.000000
5.390000,0.016380,-153.904083,0.003126,0.003244,0.082395,0.072863,0.003712,0.823949,-153.904083,0.083609,0.000000
5.610000,-0.012291,-153.904083,0.003268,0.003395,0.086228,-0.054673,-0.002785,0.862282,-153.904083,0.087269,0.000000
5.830000,-0.008942,-153.904083,0.003410,0.003542,0.089975,-0.039774,-0.002026,0.899745,-153.904083,0.090928,0.000000
6.050000,-0.051392,-153.904083,0.003553,0.003684,0.093574,-0.228601,-0.011646,0.935736,-153.904083,0.094605,0.000000
6.270000,-0.008568,-153.904083,0.003686,0.003822,0.097069,-0.038112,-0.001941,0.970686,-153.904083,0.098265,0.000000
6.490000,-0.001862,-153.904083,0.003859,0.003974,0.100936,-0.008281,-0.000422,1.009363,-153.904083,0.101925,0.000000
6.710001,0.011909,-153.948578,0.004001,0.004116,0.104552,0.052976,0.002699,1.045524,-153.948578,0.105602,0.000000
6.930000,0.025688,-153.948578,0.004139,0.004254,0.108056,0.114267,0.005821,1.080561,-153.948578,0.109262,0.000000
7.150001,0.022713,-153.993057,0.004277,0.004401,0.111794,0.101031,0.005147,1.117941,-153.993057,0.112921,0.000000
7.370000,-0.000000,-153.948578,0.004428,0.004551,0.115584,-0.000000,-0.000000,1.155835,-153.948578,0.116598,0.000000
7.590000,-0.024956,-153.993057,0.004583,0.004694,0.119226,-0.111009,-0.005655,1.192261,-153.993057,0.120258,0.000000
7.810000,-0.049904,-153.993057,0.004725,0.004836,0.122825,-0.221983,-0.011308,1.228251,-153.993057,0.123918,0.000000
8.030001,-0.032028,-153.948578,0.004885,0.004981,0.126519,-0.142469,-0.007258,1.265192,-153.948578,0.127595,0.000000
8.250000,0.011169,-153.904083,0.005019,0.005128,0.130240,0.049684,0.002531,1.302397,-153.904083,0.131254,0.000000
8.470000,0.028671,-153.993057,0.005165,0.005266,0.133752,0.127536,0.006497,1.337521,-153.993057,0.134914,0.000000
8.690001,0.045052,-154.037537,0.005303,0.005413,0.137490,0.200399,0.010209,1.374897,-154.037537,0.138591,0.000000
8.910001,0.035370,-153.993057,0.005463,0.005561,0.141253,0.157333,0.008015,1.412534,-153.993057,0.142251,0.000000
9.130000,0.035370,-154.037537,0.005605,0.005704,0.144870,0.157333,0.008015,1.448699,-154.037537,0.145911,0.000000
9.350000,-0.006706,-153.993057,0.005756,0.005847,0.148521,-0.029831,-0.001520,1.485208,-153.993057,0.149588,0.000000
9.570001,0.010422,-153.993057,0.005898,0.005988,0.152102,0.046358,0.002362,1.521024,-153.993057,0.153247,0.000000
9.790001,0.005959,-153.993057,0.006028,0.006133,0.155779,0.026505,0.001350,1.557795,-153.993057,0.156907,0.000000
10.010000,0.017502,-154.037537,0.006187,0.006280,0.159517,0.077852,0.003966,1.595174,-154.037537,0.160567,0.000000
10.230000,0.041702,-153.993057,0.006334,0.006420,0.163056,0.185501,0.009450,1.630556,-153.993057,0.164244,0.000000
10.450001,0.072983,-154.037537,0.006467,0.006563,0.166698,0.324644,0.016538,1.666981,-154.037537,0.167903,0.000000
10.670000,0.645691,-154.037537,0.006618,0.006714,0.170531,2.872177,0.146316,1.705311,-154.037537,0.171563,0.000000
10.890000,0.672501,-154.082016,0.006622,-0.000002,-0.000061,2.991432,0.152391,-0.000606,-154.082016,0.000104,0.000000
11.110001,0.660210,-154.082016,0.006631,-0.000003,-0.000069,2.936759,0.149606,-0.000693,-154.082016,0.000104,0.000000
11.330001,0.650162,-154.037537,0.006631,-0.000003,-0.000069,2.892064,0.147329,-0.000693,-154.037537,0.000330,0.000000
11.550000,0.635635,-154.126495,0.006618,-0.000003,-0.000069,2.827447,0.144037,-0.000693,-154.126495,0.000702,0.000000
11.770000,0.640846,-154.082016,0.006622,-0.000003,-0.000069,2.850626,0.145218,-0.000693,-154.082016,0.001067,0.000000
11.990001,0.687393,-154.170975,0.006640,0.000020,0.000520,3.057678,0.155766,0.005204,-154.170975,0.001431,0.000000
12.210001,1.057159,-154.082016,0.006661,0.000037,0.000928,4.702480,0.239556,0.009281,-154.082016,0.001804,0.000000
12.430000,1.315964,-154.126495,0.006679,0.000055,0.001396,5.853699,0.298202,0.013962,-154.126495,0.002168,0.000000
12.650001,1.482040,-154.082016,0.006674,0.000066,0.001682,6.592445,0.335835,0.016824,-154.082016,0.002532,0.000000
12.870001,1.671951,-154.082016,0.006691,0.000078,0.001969,7.437211,0.378870,0.019685,-154.082016,0.002897,0.000000
13.090000,2.016769,-154.126495,0.006717,0.000097,0.002472,8.971039,0.457006,0.024715,-154.126495,0.003269,0.000000
13.310000,2.239815,-154.170975,0.006713,0.000114,0.002888,9.963194,0.507549,0.028879,-154.170975,0.003634,0.000000
13.530001,2.489304,-154.082016,0.006735,0.000129,0.003269,11.072975,0.564084,0.032694,-154.082016,0.003998,0.000000
13.750001,2.626709,-154.082016,0.006739,0.000141,0.003573,11.684185,0.595221,0.035729,-154.082016,0.004371,0.000000
13.970000,2.808060,-154.082016,0.006760,0.000152,0.003850,12.490873,0.636315,0.038504,-154.082016,0.004735,0.000000
14.190001,3.132767,-154.170975,0.006769,0.000170,0.004319,13.935243,0.709895,0.043189,-154.170975,0.005099,0.000000
14.410001,3.377785,-154.215454,0.006791,0.000183,0.004657,15.025137,0.765417,0.046569,-154.215454,0.005463,0.000000
14.630001,3.619461,-154.126495,0.006804,0.000197,0.005004,16.100166,0.820182,0.050040,-154.126495,0.005836,0.000000
14.850000,3.617592,-154.170975,0.006808,0.000201,0.005117,16.091852,0.819758,0.051168,-154.170975,0.006201,0.000000
15.070001,4.094604,-154.215454,0.006799,0.000222,0.005637,18.213711,0.927851,0.056368,-154.215454,0.006565,0.000000
15.290001,4.474800,-154.170975,0.006834,0.000242,0.006157,19.904905,1.014004,0.061573,-154.170975,0.006938,0.000000
15.510001,4.671783,-154.170975,0.006855,0.000256,0.006496,20.781130,1.058641,0.064956,-154.170975,0.007302,0.000000
15.730000,4.846054,-154.215454,0.006851,0.000270,0.006851,21.556326,1.098132,0.068510,-154.215454,0.007666,0.000000
15.950001,5.094055,-154.170975,0.006864,0.000283,0.007189,22.659489,1.154329,0.071894,-154.170975,0.008030,0.000000
16.170000,5.150650,-154.259933,0.006885,0.000294,0.007467,22.911236,1.167154,0.074668,-154.259933,0.008404,0.000000
16.390001,5.521912,-154.215454,0.006903,0.000311,0.007892,24.562689,1.251283,0.078919,-154.215454,0.008768,0.000000
16.610001,5.827629,-154.259933,0.006903,0.000325,0.008265,25.922588,1.320560,0.082647,-154.259933,0.009132,0.000000
16.830000,5.755013,-154.170975,0.006920,0.000331,0.008395,25.599575,1.304104,0.083949,-154.170975,0.009505,0.000000
17.050001,6.041367,-154.215454,0.006929,0.000349,0.008872,26.873341,1.368993,0.088718,-154.215454,0.009869,0.000000
17.270000,6.532158,-154.259933,0.006942,0.000367,0.009331,29.056490,1.480208,0.093313,-154.259933,0.010233,0.000000
17.490002,6.714615,-154.259933,0.006959,0.000384,0.009756,29.868099,1.521554,0.097563,-154.259933,0.010598,0.000000
17.710001,6.855377,-154.215454,0.006972,0.000399,0.010129,30.494242,1.553451,0.101291,-154.215454,0.010971,0.000000
17.930000,6.987564,-154.215454,0.006998,0.000411,0.010441,31.082237,1.583405,0.104414,-154.215454,0.011335,0.000000
18.150002,7.087738,-154.259933,0.007006,0.000422,0.010719,31.527834,1.606104,0.107188,-154.259933,0.011699,0.000000
18.370001,7.450050,-154.304413,0.007011,0.000444,0.011265,33.139481,1.688206,0.112654,-154.304413,0.012072,0.000000
18.590000,7.497345,-154.304413,0.007028,0.000453,0.011517,33.349857,1.698923,0.115167,-154.304413,0.012436,0.000000
18.810001,7.548363,-154.304413,0.007036,0.000464,0.011786,33.576794,1.710483,0.117858,-154.304413,0.012800,0.000000
19.030001,7.871582,-154.259933,0.007054,0.000483,0.012263,35.014545,1.783726,0.122627,-154.259933,0.013165,0.000000
19.250000,8.081223,-154.259933,0.007080,0.000499,0.012679,35.947075,1.831231,0.126790,-154.259933,0.013537,0.000000
19.470001,8.161285,-154.304413,0.007084,0.000515,0.013069,36.303211,1.849374,0.130692,-154.304413,0.013902,0.000000
19.690001,8.248047,-154.348907,0.007092,0.000527,0.013390,36.689144,1.869034,0.133902,-154.348907,0.014266,0.000000
19.910002,8.296829,-154.304413,0.007114,0.000540,0.013711,36.906139,1.880088,0.137108,-154.304413,0.014639,0.000000
20.130001,8.369812,-154.259933,0.007136,0.000554,0.014084,37.230782,1.896626,0.140840,-154.259933,0.015003,0.000000
20.350000,8.621536,-154.304413,0.007131,0.000569,0.014457,38.350510,1.953668,0.144568,-154.304413,0.015367,0.000000
20.570002,8.746651,-154.393387,0.007144,0.000583,0.014803,38.907047,1.982019,0.148035,-154.393387,0.015732,0.000000
20.790001,8.743675,-154.348907,0.007157,0.000593,0.015073,38.893810,1.981345,0.150726,-154.348907,0.016104,0.000000
21.010000,9.088120,-154.393387,0.007187,0.000617,0.015662,40.425976,2.059397,0.156623,-154.393387,0.016469,0.000000
21.230001,9.111954,-154.348907,0.007209,0.000628,0.015948,40.531994,2.064798,0.159484,-154.348907,0.016833,0.000000
21.450001,9.278770,-154.304413,0.007200,0.000646,0.016399,41.274033,2.102599,0.163992,-154.304413,0.017206,0.000000
21.670000,9.200577,-154.393387,0.007217,0.000656,0.016660,40.926208,2.084881,0.166596,-154.393387,0.017570,0.000000
21.890001,9.229248,-154.348907,0.007235,0.000670,0.017006,41.053745,2.091377,0.170063,-154.348907,0.017934,0.000000
22.110001,9.459373,-154.437866,0.007256,0.000686,0.017414,42.077396,2.143525,0.174139,-154.437866,0.018298,0.000000
22.330002,9.632530,-154.348907,0.007261,0.000701,0.017813,42.847633,2.182762,0.178129,-154.348907,0.018671,0.000000
22.550001,9.615028,-154.393387,0.007274,0.000711,0.018056,42.769783,2.178797,0.180558,-154.393387,0.019036,0.000000
22.770000,9.533852,-154.393387,0.007286,0.000720,0.018281,42.408691,2.160402,0.182810,-154.393387,0.019400,0.000000
22.990002,10.029846,-154.482346,0.007299,0.000747,0.018975,44.614983,2.272796,0.189748,-154.482346,0.019764,0.000000
23.210001,10.086075,-154.437866,0.007321,0.000761,0.019331,44.865101,2.285537,0.193306,-154.437866,0.020137,0.000000
23.430000,10.084961,-154.393387,0.007330,0.000776,0.019703,44.860146,2.285285,0.197034,-154.393387,0.020501,0.000000
23.650002,10.024261,-154.348907,0.007338,0.000787,0.019981,44.590141,2.271530,0.199808,-154.348907,0.020865,0.000000
23.870001,9.953514,-154.437866,0.007355,0.000795,0.020189,44.275440,2.255498,0.201890,-154.437866,0.021239,0.000000
24.090002,10.344131,-154.482346,0.007368,0.000815,0.020701,46.012997,2.344014,0.207007,-154.482346,0.021603,0.000000
24.310001,10.492706,-154.437866,0.007381,0.000831,0.021117,46.673889,2.377681,0.211171,-154.437866,0.021967,0.000000
24.530001,10.317696,-154.393387,0.007403,0.000838,0.021273,45.895401,2.338023,0.212730,-154.393387,0.022331,0.000000
24.750002,10.354927,-154.437866,0.007403,0.000853,0.021672,46.061016,2.346460,0.216719,-154.437866,0.022704,0.000000
24.970001,10.903061,-154.393387,0.007429,0.000878,0.022305,48.499237,2.470669,0.223051,-154.393387,0.023068,0.000000
25.190001,10.817047,-154.526825,0.007437,0.000890,0.022600,48.116631,2.451178,0.226000,-154.526825,0.023433,0.000000
25.410002,10.770126,-154.526825,0.007459,0.000902,0.022921,47.907913,2.440546,0.229209,-154.526825,0.023805,0.000000
25.630001,10.790237,-154.437866,0.007476,0.000914,0.023207,47.997372,2.445103,0.232071,-154.437866,0.024170,0.000000
25.850000,10.833054,-154.348907,0.007476,0.000927,0.023537,48.187828,2.454805,0.235367,-154.348907,0.024534,0.000000
26.070002,11.305969,-154.526825,0.007498,0.000949,0.024109,50.291462,2.561969,0.241090,-154.526825,0.024898,0.000000
26.290001,11.231865,-154.526825,0.007502,0.000958,0.024334,49.961830,2.545177,0.243342,-154.526825,0.025271,0.000000
26.510002,11.225906,-154.482346,0.007528,0.000971,0.024673,49.935326,2.543827,0.246726,-154.482346,0.025635,0.000000
26.730001,11.463486,-154.482346,0.007541,0.000989,0.025124,50.992130,2.597663,0.251238,-154.482346,0.026000,0.000000
26.950001,11.692863,-154.526825,0.007549,0.001007,0.025566,52.012455,2.649641,0.255658,-154.526825,0.026372,0.000000
27.170002,11.718559,-154.482346,0.007554,0.001022,0.025947,52.126755,2.655463,0.259473,-154.482346,0.026736,0.000000
27.390001,11.628075,-154.526825,0.007584,0.001032,0.026225,51.724258,2.634959,0.262248,-154.526825,0.027101,0.000000
27.610001,11.769203,-154.526825,0.007588,0.001048,0.026615,52.352032,2.666939,0.266154,-154.526825,0.027465,0.000000
27.830002,11.804947,-154.571304,0.007614,0.001060,0.026936,52.511028,2.675039,0.269360,-154.571304,0.027838,0.000000
28.050001,12.074173,-154.526825,0.007606,0.001078,0.027387,53.708603,2.736047,0.273871,-154.526825,0.028202,0.000000
28.270000,12.020180,-154.526825,0.007627,0.001089,0.027665,53.468430,2.723812,0.276646,-154.526825,0.028566,0.000000
28.490002,12.005287,-154.615784,0.007636,0.001100,0.027951,53.402184,2.720437,0.279507,-154.615784,0.028939,0.000000
28.710001,12.362762,-154.571304,0.007662,0.001120,0.028445,54.992313,2.801442,0.284450,-154.571304,0.029304,0.000000
28.930002,12.612625,-154.571304,0.007683,0.001138,0.028905,56.103760,2.858062,0.289049,-154.571304,0.029668,0.000000
29.150002,12.594009,-154.526825,0.007687,0.001151,0.029234,56.020950,2.853843,0.292342,-154.526825,0.030032,0.000000
29.370001,12.573524,-154.615784,0.007700,0.001164,0.029573,55.929829,2.849201,0.295725,-154.615784,0.030405,0.000000
29.590002,12.578369,-154.615784,0.007713,0.001175,0.029850,55.951382,2.850299,0.298500,-154.615784,0.030769,0.000000
29.810001,12.718376,-154.615784,0.007726,0.001191,0.030249,56.574162,2.882025,0.302489,-154.615784,0.031133,0.000000
30.030001,12.978294,-154.526825,0.007743,0.001206,0.030639,57.730335,2.940924,0.306391,-154.526825,0.031506,0.000000
30.250002,12.758965,-154.615784,0.007743,0.001213,0.030821,56.754707,2.891223,0.308212,-154.615784,0.031871,0.000000
30.470001,13.140274,-154.615784,0.007761,0.001233,0.031307,58.450859,2.977629,0.313068,-154.615784,0.032235,0.000000
30.690001,13.092613,-154.660263,0.007787,0.001245,0.031619,58.238853,2.966829,0.316190,-154.660263,0.032599,0.000000
30.910002,13.406525,-154.615784,0.007800,0.001262,0.032053,59.635201,3.037962,0.320528,-154.615784,0.032972,0.000000
31.130001,13.372261,-154.615784,0.007804,0.001273,0.032339,59.482788,3.030198,0.323389,-154.615784,0.033336,0.000000
31.350002,13.400940,-154.615784,0.007825,0.001287,0.032686,59.610359,3.036696,0.326860,-154.615784,0.033700,0.000000
31.570002,13.612816,-154.571304,0.007830,0.001304,0.033111,60.552830,3.084708,0.331106,-154.571304,0.034074,0.000000
31.790001,14.008278,-154.660263,0.007851,0.001323,0.033605,62.311932,3.174321,0.336049,-154.660263,0.034438,0.000000
32.010002,14.049980,-154.660263,0.007873,0.001336,0.033935,62.497433,3.183771,0.339346,-154.660263,0.034802,0.000000
32.230003,13.895821,-154.660263,0.007886,0.001345,0.034151,61.811699,3.148838,0.341515,-154.660263,0.035166,0.000000
32.450001,14.157600,-154.660263,0.007881,0.001363,0.034620,62.976151,3.208158,0.346197,-154.660263,0.035539,0.000000
32.670002,14.517685,-154.704742,0.007903,0.001382,0.035114,64.577888,3.289754,0.351140,-154.704742,0.035903,0.000000
32.890003,14.323303,-154.704742,0.007912,0.001391,0.035331,63.713234,3.245707,0.353309,-154.704742,0.036268,0.000000
33.110001,14.599602,-154.660263,0.007933,0.001410,0.035825,64.942268,3.308317,0.358252,-154.660263,0.036640,0.000000
33.330002,14.392189,-154.704742,0.007946,0.001420,0.036076,64.019653,3.261317,0.360765,-154.704742,0.037005,0.000000
33.550003,14.668495,-154.704742,0.007955,0.001436,0.036467,65.248726,3.323928,0.364671,-154.704742,0.037369,0.000000
33.770000,15.007721,-154.749222,0.007972,0.001454,0.036944,66.757675,3.400798,0.369440,-154.749222,0.037733,0.000000
33.990002,14.954849,-154.793716,0.007989,0.001466,0.037230,66.522491,3.388817,0.372301,-154.793716,0.038106,0.000000
34.210003,14.930267,-154.660263,0.007998,0.001477,0.037516,66.413147,3.383247,0.375163,-154.660263,0.038470,0.000000
34.430000,15.383446,-154.704742,0.008024,0.001496,0.037993,68.428986,3.485939,0.379932,-154.704742,0.038835,0.000000
34.650002,15.551758,-154.704742,0.008028,0.001513,0.038427,69.177673,3.524079,0.384269,-154.704742,0.039207,0.000000
34.870003,15.634056,-154.749222,0.008037,0.001527,0.038782,69.543755,3.542728,0.387823,-154.749222,0.039571,0.000000
35.090000,15.610222,-154.749222,0.008058,0.001541,0.039129,69.437737,3.537327,0.391294,-154.749222,0.039936,0.000000
35.310001,15.558090,-154.793716,0.008067,0.001550,0.039381,69.205841,3.525514,0.393807,-154.793716,0.040300,0.000000
35.530003,15.904396,-154.704742,0.008084,0.001570,0.039866,70.746284,3.603988,0.398663,-154.704742,0.040673,0.000000
35.750000,16.015366,-154.749222,0.008097,0.001582,0.040179,71.239906,3.629134,0.401786,-154.749222,0.041037,0.000000
35.970001,16.096542,-154.749222,0.008101,0.001596,0.040543,71.600998,3.647529,0.405430,-154.749222,0.041401,0.000000
36.190002,15.762894,-154.793716,0.008119,0.001602,0.040690,70.116852,3.571923,0.406903,-154.793716,0.041766,0.000000
36.410000,16.337837,-154.838196,0.008149,0.001622,0.041202,72.674332,3.702207,0.412020,-154.838196,0.042138,0.000000
36.630001,16.811867,-154.793716,0.008157,0.001642,0.041705,74.782921,3.809623,0.417050,-154.793716,0.042503,0.000000
36.850002,16.827507,-154.749222,0.008162,0.001655,0.042026,74.852493,3.813168,0.420260,-154.749222,0.042867,0.000000
37.070004,16.865860,-154.793716,0.008179,0.001670,0.042416,75.023094,3.821859,0.424162,-154.793716,0.043240,0.000000
37.290001,16.943314,-154.838196,0.008196,0.001683,0.042737,75.367622,3.839410,0.427368,-154.838196,0.043604,0.000000
37.510002,16.956718,-154.793716,0.008205,0.001697,0.043101,75.427254,3.842447,0.431012,-154.793716,0.043968,0.000000
37.730003,17.326859,-154.793716,0.008222,0.001711,0.043457,77.073715,3.926322,0.434566,-154.793716,0.044332,0.000000
37.950001,17.425911,-154.793716,0.008222,0.001724,0.043795,77.514320,3.948768,0.437950,-154.793716,0.044706,0.000000
38.170002,17.103065,-154.793716,0.008244,0.001731,0.043977,76.078232,3.875610,0.439771,-154.793716,0.045070,0.000000
38.390003,17.689926,-154.927155,0.008252,0.001752,0.044489,78.688721,4.008595,0.444888,-154.927155,0.045434,0.000000
38.610001,18.071236,-154.793716,0.008261,0.001767,0.044888,80.384872,4.095001,0.448877,-154.793716,0.045807,0.000000
38.830002,18.309547,-154.838196,0.008278,0.001783,0.045295,81.444931,4.149003,0.452954,-154.838196,0.046171,0.000000
39.050003,18.425728,-154.793716,0.008287,0.001798,0.045659,81.961731,4.175330,0.456595,-154.793716,0.046535,0.000000
39.270000,18.420517,-154.838196,0.008300,0.001810,0.045980,81.938553,4.174149,0.459804,-154.838196,0.046900,0.000000
39.490002,18.629791,-154.927155,0.008321,0.001828,0.046431,82.869453,4.221571,0.464312,-154.927155,0.047273,0.000000
39.710003,18.984665,-154.927155,0.008343,0.001843,0.046813,84.448006,4.301986,0.468127,-154.927155,0.047637,0.000000
39.930000,18.803314,-154.882675,0.008347,0.001852,0.047047,83.641319,4.260892,0.470470,-154.882675,0.048001,0.000000
40.150002,18.824913,-154.882675,0.008364,0.001863,0.047324,83.737396,4.265786,0.473244,-154.882675,0.048374,0.000000
40.370003,19.377518,-154.927155,0.008369,0.001882,0.047802,86.195503,4.391008,0.478017,-154.927155,0.048738,0.000000
40.590000,19.758453,-154.927155,0.008386,0.001901,0.048279,87.889992,4.477330,0.482786,-154.927155,0.049102,0.000000
40.810001,19.859367,-154.927155,0.008403,0.001915,0.048643,88.338875,4.500197,0.486427,-154.927155,0.049467,0.000000
41.030003,19.949104,-154.882675,0.008429,0.001928,0.048964,88.738045,4.520532,0.489637,-154.882675,0.049839,0.000000
41.250004,19.930489,-154.882675,0.008429,0.001939,0.049241,88.655243,4.516313,0.492411,-154.882675,0.050204,0.000000
41.470001,20.215355,-154.971634,0.008438,0.001956,0.049675,89.922386,4.580865,0.496749,-154.971634,0.050568,0.000000
41.690002,20.480110,-154.927155,0.008451,0.001968,0.049995,91.100082,4.640859,0.499954,-154.927155,0.050941,0.000000
41.910004,20.664436,-154.971634,0.008476,0.001981,0.050325,91.920006,4.682628,0.503251,-154.971634,0.051305,0.000000
42.130001,20.630547,-154.882675,0.008481,0.001993,0.050611,91.769257,4.674949,0.506112,-154.882675,0.051669,0.000000
42.350002,21.436363,-154.927155,0.008485,0.002016,0.051210,95.353706,4.857550,0.512096,-154.927155,0.052034,0.000000
42.570004,21.440460,-154.971634,0.008507,0.002027,0.051487,95.371933,4.858478,0.514871,-154.971634,0.052406,0.000000
42.790001,21.837410,-155.016113,0.008511,0.002045,0.051947,97.137650,4.948428,0.519469,-155.016113,0.052771,0.000000
43.010002,21.732025,-155.016113,0.008532,0.002055,0.052207,96.668877,4.924547,0.522070,-155.016113,0.053135,0.000000
43.230003,21.890282,-154.927155,0.008545,0.002069,0.052545,97.372833,4.960409,0.525453,-154.927155,0.053508,0.000000
43.450001,22.349045,-154.971634,0.008558,0.002086,0.052996,99.413513,5.064366,0.529961,-154.971634,0.053872,0.000000
43.670002,22.636147,-155.016113,0.008576,0.002101,0.053361,100.690605,5.129424,0.533606,-155.016113,0.054236,0.000000
43.890003,22.580292,-155.060593,0.008593,0.002110,0.053594,100.442154,5.116767,0.535945,-155.060593,0.054601,0.000000
44.110001,22.464851,-155.016113,0.008593,0.002121,0.053881,99.928650,5.090608,0.538806,-155.016113,0.054973,0.000000
44.330002,23.532822,-155.016113,0.008610,0.002146,0.054514,104.679222,5.332613,0.545138,-155.016113,0.055338,0.000000
44.550003,23.800186,-154.971634,0.008623,0.002159,0.054844,105.868515,5.393199,0.548435,-154.971634,0.055702,0.000000
44.770000,24.041481,-154.971634,0.008632,0.002175,0.055234,106.941849,5.447877,0.552337,-154.971634,0.056075,0.000000
44.990002,24.037758,-155.060593,0.008636,0.002188,0.055563,106.925285,5.447034,0.555634,-155.060593,0.056439,0.000000
45.210003,23.813957,-155.060593,0.008666,0.002198,0.055823,105.929771,5.396320,0.558234,-155.060593,0.056803,0.000000
45.430000,24.647705,-155.016113,0.008675,0.002217,0.056300,109.638466,5.585250,0.563003,-155.016113,0.057167,0.000000
45.650002,24.986565,-155.060593,0.008692,0.002230,0.056639,111.145790,5.662036,0.566387,-155.060593,0.057541,0.000000
45.870003,24.712120,-155.016113,0.008701,0.002236,0.056803,109.925003,5.599846,0.568033,-155.016113,0.057905,0.000000
46.090004,25.438995,-155.060593,0.008701,0.002260,0.057393,113.158302,5.764559,0.573930,-155.060593,0.058269,0.000000
46.310001,26.272362,-155.105072,0.008727,0.002278,0.057861,116.865303,5.953403,0.578612,-155.105072,0.058642,0.000000
46.530003,26.271248,-155.060593,0.008744,0.002289,0.058130,116.860344,5.953150,0.581303,-155.060593,0.059006,0.000000
46.750004,26.383331,-155.060593,0.008752,0.002303,0.058494,117.358917,5.978548,0.584944,-155.060593,0.059370,0.000000
46.970001,26.415352,-155.105072,0.008748,0.002312,0.058737,117.501350,5.985804,0.587374,-155.105072,0.059735,0.000000
47.190002,26.614944,-155.105072,0.008770,0.002326,0.059093,118.389183,6.031033,0.590928,-155.105072,0.060108,0.000000
47.410004,27.651260,-155.149551,0.008774,0.002348,0.059639,122.998947,6.265865,0.596393,-155.149551,0.060472,0.000000
47.630001,27.610298,-155.105072,0.008795,0.002356,0.059847,122.816742,6.256583,0.598471,-155.105072,0.060836,0.000000
47.850002,27.657219,-155.149551,0.008804,0.002369,0.060177,123.025452,6.267215,0.601768,-155.149551,0.061209,0.000000
48.070004,28.426910,-155.149551,0.008826,0.002388,0.060645,126.449211,6.441630,0.606450,-155.149551,0.061573,0.000000
48.290001,29.168304,-155.149551,0.008826,0.002407,0.061148,129.747101,6.609632,0.611480,-155.149551,0.061937,0.000000
48.510002,29.388748,-155.238525,0.008847,0.002420,0.061460,130.727676,6.659586,0.614603,-155.238525,0.062302,0.000000
48.730003,29.405876,-155.194031,0.008856,0.002431,0.061746,130.803864,6.663467,0.617464,-155.194031,0.062674,0.000000
48.950001,29.873947,-155.149551,0.008869,0.002446,0.062128,132.885956,6.769533,0.621279,-155.149551,0.063039,0.000000
49.170002,29.927574,-155.194031,0.008869,0.002456,0.062388,133.124496,6.781685,0.623883,-155.194031,0.063403,0.000000
49.390003,30.780304,-155.149551,0.008895,0.002475,0.062865,136.917633,6.974916,0.628652,-155.149551,0.063767,0.000000
49.610001,30.975800,-155.238525,0.008899,0.002488,0.063186,137.787231,7.019217,0.631862,-155.238525,0.064140,0.000000
49.830002,31.037613,-155.194031,0.008912,0.002499,0.063481,138.062195,7.033224,0.634810,-155.194031,0.064504,0.000000
50.050003,31.949181,-155.105072,0.008925,0.002518,0.063958,142.117050,7.239788,0.639579,-155.105072,0.064869,0.000000
50.270004,32.789627,-155.149551,0.008938,0.002537,0.064452,145.855545,7.430236,0.644522,-155.149551,0.065241,0.000000
50.490002,32.992195,-155.238525,0.008938,0.002549,0.064756,146.756607,7.476138,0.647558,-155.238525,0.065606,0.000000
50.710003,33.204453,-155.283005,0.008959,0.002563,0.065103,147.700775,7.524236,0.651028,-155.283005,0.065970,0.000000
50.930004,33.306854,-155.238525,0.008977,0.002574,0.065372,148.156281,7.547441,0.653716,-155.238525,0.066334,0.000000
51.150002,33.674011,-155.149551,0.008981,0.002588,0.065727,149.789490,7.630640,0.657270,-155.149551,0.066707,0.000000
51.370003,34.479828,-155.194031,0.008985,0.002604,0.066143,153.373932,7.813241,0.661433,-155.194031,0.067071,0.000000
51.590004,34.320450,-155.283005,0.008998,0.002612,0.066334,152.664978,7.777125,0.663341,-155.283005,0.067435,0.000000
51.810001,35.257713,-155.238525,0.009011,0.002631,0.066828,156.834137,7.989512,0.668284,-155.238525,0.067808,0.000000
52.030003,35.420067,-155.238525,0.009020,0.002643,0.067141,157.556320,8.026302,0.671406,-155.238525,0.068173,0.000000
52.250004,36.405739,-155.238525,0.009041,0.002662,0.067626,161.940811,8.249659,0.676262,-155.238525,0.068537,0.000000
52.470001,36.530479,-155.194031,0.009050,0.002673,0.067887,162.495682,8.277925,0.678866,-155.194031,0.068901,0.000000
52.690002,36.862267,-155.283005,0.009050,0.002685,0.068207,163.971558,8.353109,0.682072,-155.283005,0.069274,0.000000
52.910004,37.312462,-155.283005,0.009058,0.002700,0.068589,165.974121,8.455125,0.685891,-155.283005,0.069638,0.000000
53.130001,38.537193,-155.283005,0.009080,0.002722,0.069135,171.421997,8.732653,0.691353,-155.283005,0.070002,0.000000
53.350002,39.000053,-155.238525,0.009089,0.002734,0.069448,173.480896,8.837539,0.694475,-155.238525,0.070376,0.000000
53.570004,39.010857,-155.238525,0.009093,0.002743,0.069673,173.528961,8.839986,0.696731,-155.238525,0.070740,0.000000
53.790001,39.735489,-155.327484,0.009106,0.002761,0.070124,176.752289,9.004190,0.701239,-155.327484,0.071104,0.000000
54.010002,40.726746,-155.371964,0.009119,0.002781,0.070627,181.161606,9.228813,0.706269,-155.371964,0.071468,0.000000
54.230003,40.854843,-155.283005,0.009140,0.002789,0.070852,181.731415,9.257840,0.708525,-155.283005,0.071841,0.000000
54.450001,41.891151,-155.283005,0.009149,0.002810,0.071373,186.341141,9.492670,0.713729,-155.283005,0.072205,0.000000
54.670002,41.846100,-155.327484,0.009149,0.002821,0.071650,186.140747,9.482462,0.716503,-155.327484,0.072570,0.000000
54.890003,42.521210,-155.371964,0.009166,0.002834,0.071980,189.143784,9.635444,0.719796,-155.371964,0.072942,0.000000
55.110004,43.506882,-155.371964,0.009184,0.002853,0.072457,193.528275,9.858800,0.724569,-155.371964,0.073307,0.000000
55.330002,43.867332,-155.371964,0.009196,0.002865,0.072760,195.131638,9.940479,0.727604,-155.371964,0.073671,0.000000
55.550003,44.127251,-155.327484,0.009196,0.002875,0.073029,196.287811,9.999377,0.730292,-155.327484,0.074035,0.000000
55.770004,45.293152,-155.327484,0.009205,0.002894,0.073515,201.473999,10.263575,0.735148,-155.327484,0.074408,0.000000
55.990002,45.954483,-155.371964,0.009205,0.002911,0.073949,204.415756,10.413435,0.739485,-155.371964,0.074772,0.000000
56.210003,46.680237,-155.371964,0.009227,0.002926,0.074313,207.644058,10.577893,0.743126,-155.371964,0.075137,0.000000
56.430004,46.960632,-155.416443,0.009240,0.002939,0.074642,208.891327,10.641431,0.746423,-155.416443,0.075509,0.000000
56.650002,47.248474,-155.371964,0.009253,0.002949,0.074894,210.171707,10.706657,0.748936,-155.371964,0.075874,0.000000
56.870003,48.500023,-155.327484,0.009253,0.002969,0.075414,215.738876,10.990263,0.754140,-155.327484,0.076238,0.000000
57.090004,48.904045,-155.416443,0.009265,0.002980,0.075700,217.536057,11.081815,0.757002,-155.416443,0.076602,0.000000
57.310001,49.534470,-155.416443,0.009261,0.002995,0.076064,220.340332,11.224671,0.760643,-155.416443,0.076975,0.000000
57.530003,49.616768,-155.416443,0.009278,0.003007,0.076377,220.706406,11.243320,0.763765,-155.416443,0.077339,0.000000
57.750004,50.813202,-155.416443,0.009291,0.003023,0.076784,226.028412,11.514437,0.767842,-155.416443,0.077704,0.000000
57.970001,51.966805,-155.371964,0.009304,0.003040,0.077227,231.159897,11.775846,0.772266,-155.371964,0.078076,0.000000
58.190002,52.473976,-155.416443,0.009309,0.003053,0.077539,233.415909,11.890773,0.775389,-155.416443,0.078440,0.000000
58.410004,53.120049,-155.460922,0.009322,0.003068,0.077929,236.289780,12.037175,0.779291,-155.460922,0.078805,0.000000
58.630001,53.717331,-155.505402,0.009330,0.003080,0.078224,238.946625,12.172522,0.782239,-155.505402,0.079169,0.000000
58.850002,54.288177,-155.416443,0.009343,0.003094,0.078597,241.485870,12.301877,0.785968,-155.416443,0.079542,0.000000
59.070004,54.875778,-155.460922,0.009334,0.003109,0.078978,244.099655,12.435029,0.789783,-155.460922,0.079906,0.000000
59.290001,55.897575,-155.505402,0.009347,0.003123,0.079317,248.644836,12.666572,0.793166,-155.505402,0.080270,0.000000
59.510002,55.851028,-155.460922,0.009369,0.003132,0.079551,248.437790,12.656024,0.795505,-155.460922,0.080643,0.000000
59.730003,56.908936,-155.460922,0.009373,0.003151,0.080028,253.143585,12.895749,0.800278,-155.460922,0.081008,0.000000
59.950005,58.160110,-155.460922,0.009382,0.003164,0.080375,258.709106,13.179270,0.803745,-155.460922,0.081372,0.000000
60.170002,59.161415,-155.549881,0.009390,0.003182,0.080817,263.163116,13.406168,0.808170,-155.549881,0.081736,0.000000
60.390003,59.986595,-155.549881,0.009395,0.003196,0.081181,266.833710,13.593157,0.811811,-155.549881,0.082109,0.000000
60.610004,60.531746,-155.549881,0.009399,0.003209,0.081502,269.258667,13.716690,0.815020,-155.549881,0.082473,0.000000
60.830002,61.377777,-155.549881,0.009412,0.003227,0.081970,273.022003,13.908403,0.819702,-155.549881,0.082837,0.000000
61.050003,62.550377,-155.549881,0.009408,0.003242,0.082334,278.237976,14.174118,0.823343,-155.549881,0.083211,0.000000
61.270004,62.892586,-155.505402,0.009425,0.003250,0.082560,279.760193,14.251663,0.825599,-155.505402,0.083575,0.000000
61.490002,63.398643,-155.594360,0.009421,0.003261,0.082829,282.011261,14.366338,0.828286,-155.594360,0.083939,0.000000
61.710003,64.573112,-155.549881,0.009442,0.003280,0.083314,287.235565,14.632476,0.833142,-155.549881,0.084303,0.000000
61.930004,65.954613,-155.549881,0.009447,0.003300,0.083809,293.380768,14.945529,0.838089,-155.549881,0.084676,0.000000
62.150002,66.614830,-155.505402,0.009464,0.003312,0.084130,296.317566,15.095137,0.841295,-155.505402,0.085040,0.000000
62.370003,67.398674,-155.505402,0.009472,0.003315,0.084208,299.804260,15.272758,0.842079,-155.505402,0.084416,0.000000
62.590004,66.663231,-155.549881,0.009477,0.003315,0.084199,296.532867,15.106105,0.841992,-155.549881,0.084416,0.000000
62.810001,66.002647,-155.594360,0.009468,0.003314,0.084182,293.594452,14.956414,0.841817,-155.594360,0.084199,0.000000
63.030003,65.378548,-155.638855,0.009481,0.003314,0.084164,290.818298,14.814991,0.841643,-155.638855,0.084199,0.000000
63.250004,64.839348,-155.594360,0.009503,0.003313,0.084156,288.419830,14.692806,0.841556,-155.594360,0.084199,0.000000
63.470001,64.334038,-155.594360,0.009494,0.003313,0.084156,286.172089,14.578301,0.841556,-155.594360,0.084199,0.000000
63.690002,63.864479,-155.549881,0.009498,0.003313,0.084147,284.083405,14.471897,0.841469,-155.549881,0.084199,0.000000
63.910004,63.444069,-155.594360,0.009498,0.003313,0.084147,282.213318,14.376632,0.841469,-155.594360,0.084199,0.000000
64.130005,63.043022,-155.638855,0.009503,0.003313,0.084147,280.429382,14.285753,0.841469,-155.638855,0.084199,0.000000
64.350006,62.657249,-155.594360,0.009507,0.003313,0.084147,278.713379,14.198336,0.841469,-155.594360,0.084199,0.000000
64.570000,62.313919,-155.594360,0.009511,0.003313,0.084147,277.186157,14.120536,0.841469,-155.594360,0.084199,0.000000
64.790001,61.977669,-155.594360,0.009511,0.003313,0.084138,275.690430,14.044340,0.841382,-155.594360,0.084199,0.000000
65.010002,61.671204,-155.594360,0.009511,0.003313,0.084138,274.327209,13.974895,0.841382,-155.594360,0.084199,0.000000
65.230003,61.388206,-155.683334,0.009520,0.003313,0.084138,273.068390,13.910766,0.841382,-155.683334,0.084199,0.000000
65.450005,61.130524,-155.594360,0.009516,0.003313,0.084138,271.922150,13.852375,0.841382,-155.594360,0.084199,0.000000
65.670006,60.877312,-155.638855,0.009524,0.003313,0.084138,270.795807,13.794996,0.841382,-155.638855,0.084199,0.000000
65.889999,60.629311,-155.683334,0.009507,0.003313,0.084138,269.692657,13.738798,0.841382,-155.683334,0.084199,0.000000
66.110001,60.401047,-155.727814,0.009524,0.003313,0.084138,268.677277,13.687073,0.841382,-155.727814,0.084199,0.000000
66.330002,60.178368,-155.683334,0.009520,0.003313,0.084138,267.686737,13.636613,0.841382,-155.683334,0.084199,0.000000
66.550003,59.961273,-155.638855,0.009528,0.003313,0.084138,266.721069,13.587419,0.841382,-155.638855,0.084199,0.000000
66.770004,59.781418,-155.683334,0.009524,0.003313,0.084138,265.921021,13.546662,0.841382,-155.683334,0.084199,0.000000
66.990005,59.594856,-155.683334,0.009528,0.003313,0.084138,265.091156,13.504388,0.841382,-155.683334,0.084199,0.000000
67.210007,59.399361,-155.727814,0.009533,0.003313,0.084138,264.221558,13.460088,0.841382,-155.727814,0.084199,0.000000
67.430000,59.226212,-155.683334,0.009524,0.003313,0.084138,263.451355,13.420852,0.841382,-155.683334,0.084199,0.000000
67.650002,59.065720,-155.772293,0.009537,0.003313,0.084138,262.737457,13.384483,0.841382,-155.772293,0.084199,0.000000
67.870003,58.917137,-155.727814,0.009528,0.003313,0.084138,262.076508,13.350814,0.841382,-155.727814,0.084199,0.000000
68.090004,58.767075,-155.683334,0.009524,0.003313,0.084138,261.408997,13.316810,0.841382,-155.683334,0.084199,0.000000
68.310005,58.621101,-155.772293,0.009537,0.003313,0.084138,260.759674,13.283731,0.841382,-155.772293,0.084199,0.000000
68.530006,58.468430,-155.772293,0.009524,0.003313,0.084138,260.080566,13.249135,0.841382,-155.772293,0.084199,0.000000
68.750000,58.341827,-155.772293,0.009550,0.003313,0.084138,259.517395,13.220448,0.841382,-155.772293,0.084199,0.000000
68.970001,58.217079,-155.683334,0.009541,0.003313,0.084138,258.962494,13.192179,0.841382,-155.683334,0.084199,0.000000
69.190002,58.080048,-155.727814,0.009537,0.003313,0.084138,258.352966,13.161127,0.841382,-155.727814,0.084199,0.000000
69.410004,57.956421,-155.772293,0.009537,0.003313,0.084138,257.803040,13.133113,0.841382,-155.772293,0.084199,0.000000
69.630005,57.826462,-155.816772,0.009537,0.003313,0.084138,257.224945,13.103663,0.841382,-155.816772,0.084199,0.000000
69.850006,57.725922,-155.727814,0.009541,0.003313,0.084138,256.777710,13.080881,0.841382,-155.727814,0.084199,0.000000
70.070000,57.607132,-155.727814,0.009546,0.003313,0.084138,256.249329,13.053963,0.841382,-155.727814,0.084199,0.000000
70.290001,57.504730,-155.772293,0.009533,0.003313,0.084138,255.793808,13.030759,0.841382,-155.772293,0.084199,0.000000
70.510002,57.409775,-155.861252,0.009537,0.003313,0.084138,255.371429,13.009241,0.841382,-155.861252,0.084199,0.000000
70.730003,57.305885,-155.816772,0.009546,0.003312,0.084130,254.909302,12.985700,0.841295,-155.816772,0.084199,0.000000
70.950005,57.204597,-155.816772,0.009554,0.003312,0.084130,254.458755,12.962748,0.841295,-155.816772,0.084199,0.000000
71.170006,57.109642,-155.727814,0.009554,0.003312,0.084130,254.036377,12.941230,0.841295,-155.727814,0.084199,0.000000
71.390007,57.014687,-155.816772,0.009554,0.003312,0.084130,253.613998,12.919712,0.841295,-155.816772,0.084199,0.000000
71.610001,56.927551,-155.772293,0.009537,0.003312,0.084130,253.226395,12.899967,0.841295,-155.772293,0.084199,0.000000
71.830002,56.825897,-155.861252,0.009550,0.003312,0.084130,252.774216,12.876932,0.841295,-155.861252,0.084199,0.000000
72.050003,56.745094,-155.816772,0.009554,0.003312,0.084130,252.414780,12.858623,0.841295,-155.816772,0.084199,0.000000
72.270004,56.655724,-155.816772,0.009546,0.003312,0.084130,252.017242,12.838370,0.841295,-155.816772,0.084199,0.000000
72.490005,56.577896,-155.816772,0.009554,0.003312,0.084130,251.671051,12.820735,0.841295,-155.816772,0.084199,0.000000
72.710007,56.495972,-155.861252,0.009541,0.003312,0.084130,251.306641,12.802171,0.841295,-155.861252,0.084199,0.000000
72.930000,56.425972,-155.905731,0.009546,0.003312,0.084130,250.995255,12.786307,0.841295,-155.905731,0.084199,0.000000
73.150002,56.342186,-155.861252,0.009541,0.003312,0.084130,250.622559,12.767322,0.841295,-155.861252,0.084199,0.000000
73.370003,56.273293,-155.905731,0.009546,0.003312,0.084130,250.316101,12.751711,0.841295,-155.905731,0.084199,0.000000
73.590004,56.191376,-155.905731,0.009550,0.003312,0.084130,249.951721,12.733148,0.841295,-155.905731,0.084199,0.000000
73.810005,56.120995,-155.861252,0.009550,0.003312,0.084130,249.638657,12.717199,0.841295,-155.861252,0.084199,0.000000
74.030006,56.058434,-155.861252,0.009537,0.003312,0.084130,249.360367,12.703022,0.841295,-155.861252,0.084199,0.000000
74.250000,55.991035,-155.905731,0.009546,0.003312,0.084130,249.060562,12.687750,0.841295,-155.905731,0.084199,0.000000
74.470001,55.915077,-155.905731,0.009563,0.003312,0.084130,248.722687,12.670538,0.841295,-155.905731,0.084199,0.000000
74.690002,55.857353,-155.950211,0.009554,0.003312,0.084130,248.465912,12.657456,0.841295,-155.950211,0.084199,0.000000
74.910004,55.792564,-155.905731,0.009550,0.003312,0.084130,248.177719,12.642776,0.841295,-155.905731,0.084199,0.000000
75.130005,55.722183,-155.950211,0.009546,0.003312,0.084130,247.864655,12.626827,0.841295,-155.950211,0.084199,0.000000
75.350006,55.665955,-155.994690,0.009541,0.003312,0.084130,247.614532,12.614085,0.841295,-155.994690,0.084199,0.000000
75.570007,55.604889,-155.905731,0.009563,0.003312,0.084130,247.342896,12.600248,0.841295,-155.905731,0.084199,0.000000
75.790001,55.546799,-155.861252,0.009554,0.003312,0.084130,247.084503,12.587085,0.841295,-155.861252,0.084199,0.000000
76.010002,55.489822,-155.905731,0.009550,0.003312,0.084130,246.831055,12.574173,0.841295,-155.905731,0.084199,0.000000
76.230003,55.427269,-155.950211,0.009550,0.003312,0.084130,246.552811,12.559999,0.841295,-155.950211,0.084199,0.000000
76.450005,55.366196,-155.950211,0.009559,0.003312,0.084130,246.281143,12.546159,0.841295,-155.950211,0.084199,0.000000
76.670006,55.326721,-155.994690,0.009563,0.003312,0.084130,246.105545,12.537214,0.841295,-155.994690,0.084199,0.000000
76.890007,55.264908,-155.950211,0.009563,0.003312,0.084130,245.830582,12.523207,0.841295,-155.950211,0.084199,0.000000
77.110001,55.194160,-155.994690,0.009554,0.003312,0.084130,245.515884,12.507175,0.841295,-155.994690,0.084199,0.000000
77.330002,55.146866,-155.994690,0.009563,0.003312,0.084130,245.305511,12.496458,0.841295,-155.994690,0.084199,0.000000
77.550003,55.089897,-155.950211,0.009559,0.003312,0.084130,245.052109,12.483549,0.841295,-155.950211,0.084199,0.000000
77.770004,55.039253,-155.950211,0.009563,0.003312,0.084130,244.826828,12.472073,0.841295,-155.950211,0.084199,0.000000
77.990005,55.003136,-155.994690,0.009563,0.003312,0.084130,244.666168,12.463889,0.841295,-155.994690,0.084199,0.000000
78.210007,54.937965,-155.950211,0.009559,0.003312,0.084130,244.376282,12.449121,0.841295,-155.950211,0.084199,0.000000
78.430000,54.897377,-156.083664,0.009550,0.003312,0.084130,244.195724,12.439923,0.841295,-156.083664,0.084199,0.000000
78.650002,54.843758,-156.083664,0.009563,0.003312,0.084130,243.957214,12.427773,0.841295,-156.083664,0.084199,0.000000
78.870003,54.800934,-156.039169,0.009563,0.003312,0.084130,243.766724,12.418069,0.841295,-156.039169,0.084199,0.000000
79.090004,54.746567,-155.994690,0.009563,0.003312,0.084130,243.524887,12.405749,0.841295,-155.994690,0.084199,0.000000
79.310005,54.693695,-156.039169,0.009554,0.003312,0.084130,243.289703,12.393769,0.841295,-156.039169,0.084199,0.000000
79.530006,54.659058,-156.172623,0.009567,0.003312,0.084130,243.135635,12.385920,0.841295,-156.172623,0.084199,0.000000
79.750000,54.611023,-156.083664,0.009559,0.003312,0.084130,242.921967,12.375034,0.841295,-156.083664,0.084199,0.000000
79.970001,54.584213,-156.039169,0.009559,0.003312,0.084130,242.802704,12.368959,0.841295,-156.039169,0.084199,0.000000
80.190002,54.539154,-156.083664,0.009567,0.003312,0.084130,242.602280,12.358749,0.841295,-156.083664,0.084199,0.000000
80.410004,54.494476,-156.083664,0.009563,0.003312,0.084130,242.403534,12.348624,0.841295,-156.083664,0.084199,0.000000
80.630005,54.438988,-156.083664,0.009563,0.003312,0.084130,242.156708,12.336051,0.841295,-156.083664,0.084199,0.000000
80.850006,54.405846,-156.039169,0.009550,0.003312,0.084130,242.009293,12.328541,0.841295,-156.039169,0.084199,0.000000
81.070007,54.364143,-156.128143,0.009563,0.003312,0.084130,241.823792,12.319091,0.841295,-156.128143,0.084199,0.000000
81.290001,54.325417,-156.039169,0.009554,0.003312,0.084130,241.651520,12.310315,0.841295,-156.039169,0.084199,0.000000
81.510002,54.291901,-156.083664,0.009554,0.003312,0.084130,241.502441,12.302721,0.841295,-156.083664,0.084199,0.000000
81.730003,54.243118,-156.128143,0.009567,0.003312,0.084130,241.285446,12.291667,0.841295,-156.128143,0.084199,0.000000
81.950005,54.214073,-156.128143,0.009567,0.003312,0.084130,241.156235,12.285085,0.841295,-156.128143,0.084199,0.000000
82.170006,54.162689,-156.128143,0.009567,0.003312,0.084130,240.927673,12.273441,0.841295,-156.128143,0.084199,0.000000
82.390007,54.140717,-156.083664,0.009567,0.003312,0.084130,240.829941,12.268461,0.841295,-156.083664,0.084199,0.000000
82.610001,54.097893,-156.083664,0.009567,0.003312,0.084130,240.639450,12.258758,0.841295,-156.083664,0.084199,0.000000
82.830002,54.058800,-156.128143,0.009554,0.003312,0.084130,240.465546,12.249899,0.841295,-156.128143,0.084199,0.000000
83.050003,54.016716,-156.128143,0.009572,0.003312,0.084130,240.278351,12.240363,0.841295,-156.128143,0.084199,0.000000
83.270004,53.995125,-156.128143,0.009572,0.003312,0.084130,240.182312,12.235471,0.841295,-156.128143,0.084199,0.000000
83.490005,53.975761,-156.172623,0.009563,0.003312,0.084130,240.096176,12.231083,0.841295,-156.172623,0.084199,0.000000
83.710007,53.935165,-156.128143,0.009563,0.003312,0.084130,239.915604,12.221883,0.841295,-156.128143,0.084199,0.000000
83.930000,53.899422,-156.128143,0.009554,0.003312,0.084130,239.756607,12.213784,0.841295,-156.128143,0.084199,0.000000
84.150002,53.853622,-156.172623,0.009576,0.003312,0.084130,239.552872,12.203405,0.841295,-156.172623,0.084199,0.000000
84.370003,53.828300,-156.128143,0.009572,0.003312,0.084130,239.440247,12.197667,0.841295,-156.128143,0.084199,0.000000
84.590004,53.804092,-156.128143,0.009580,0.003312,0.084130,239.332550,12.192182,0.841295,-156.128143,0.084199,0.000000
84.810005,53.781754,-156.172623,0.009567,0.003312,0.084130,239.233185,12.187119,0.841295,-156.172623,0.084199,0.000000
85.030006,53.753082,-156.261581,0.009563,0.003312,0.084130,239.105652,12.180622,0.841295,-156.261581,0.084199,0.000000
85.250008,53.700943,-156.217102,0.009567,0.003312,0.084130,238.873718,12.168808,0.841295,-156.217102,0.084199,0.000000
85.470001,53.682327,-156.217102,0.009576,0.003312,0.084130,238.790924,12.164589,0.841295,-156.217102,0.084199,0.000000
85.690002,53.652908,-156.217102,0.009567,0.003312,0.084130,238.660049,12.157923,0.841295,-156.217102,0.084199,0.000000
85.910004,53.613068,-156.217102,0.009572,0.003312,0.084130,238.482834,12.148895,0.841295,-156.217102,0.084199,0.000000
86.130005,53.600037,-156.217102,0.009559,0.003312,0.084130,238.424866,12.145942,0.841295,-156.217102,0.084199,0.000000
86.350006,53.560562,-156.261581,0.009563,0.003312,0.084130,238.249283,12.136997,0.841295,-156.261581,0.084199,0.000000
86.570007,53.535240,-156.261581,0.009572,0.003312,0.084130,238.136642,12.131258,0.841295,-156.261581,0.084199,0.000000
86.790001,53.507683,-156.261581,0.009567,0.003312,0.084130,238.014053,12.125014,0.841295,-156.261581,0.084199,0.000000
87.010002,53.475288,-156.261581,0.009567,0.003312,0.084130,237.869965,12.117674,0.841295,-156.261581,0.084199,0.000000
87.230003,53.454811,-156.306061,0.009567,0.003312,0.084130,237.778870,12.113033,0.841295,-156.306061,0.084199,0.000000
87.450005,53.423157,-156.217102,0.009572,0.003312,0.084130,237.638077,12.105861,0.841295,-156.217102,0.084199,0.000000
87.670006,53.404541,-156.261581,0.009563,0.003312,0.084130,237.555267,12.101642,0.841295,-156.261581,0.084199,0.000000
87.890007,53.373634,-156.217102,0.009563,0.003312,0.084130,237.417786,12.094639,0.841295,-156.217102,0.084199,0.000000
88.110001,53.341980,-156.261581,0.009567,0.003312,0.084130,237.276978,12.087465,0.841295,-156.261581,0.084199,0.000000
88.330002,53.319267,-156.306061,0.009567,0.003312,0.084130,237.175949,12.082318,0.841295,-156.306061,0.084199,0.000000
88.550003,53.295059,-156.306061,0.009572,0.003312,0.084130,237.068268,12.076834,0.841295,-156.306061,0.084199,0.000000
88.770004,53.274956,-156.395020,0.009576,0.003312,0.084130,236.978836,12.072278,0.841295,-156.395020,0.084199,0.000000
88.990005,53.246277,-156.306061,0.009572,0.003312,0.084130,236.851273,12.065779,0.841295,-156.306061,0.084199,0.000000
89.210007,53.229897,-156.306061,0.009559,0.003312,0.084130,236.778412,12.062067,0.841295,-156.306061,0.084199,0.000000
89.430008,53.191170,-156.350540,0.009567,0.003312,0.084130,236.606140,12.053291,0.841295,-156.350540,0.084199,0.000000
89.650002,53.165100,-156.306061,0.009563,0.003312,0.084130,236.490173,12.047384,0.841295,-156.306061,0.084199,0.000000
89.870003,53.131218,-156.306061,0.009567,0.003312,0.084130,236.339462,12.039706,0.841295,-156.306061,0.084199,0.000000
90.090004,53.101799,-156.306061,0.009572,0.003312,0.084130,236.208603,12.033040,0.841295,-156.306061,0.084199,0.000000
90.310005,53.090256,-156.350540,0.009572,0.003312,0.084130,236.157257,12.030423,0.841295,-156.350540,0.084199,0.000000
90.530006,53.073502,-156.395020,0.009559,0.003312,0.084130,236.082733,12.026627,0.841295,-156.395020,0.084199,0.000000
90.750008,53.036636,-156.439499,0.009572,0.003312,0.084130,235.918747,12.018274,0.841295,-156.439499,0.084199,0.000000
90.970001,53.011688,-156.350540,0.009572,0.003312,0.084130,235.807770,12.012620,0.841295,-156.350540,0.084199,0.000000
91.190002,52.995674,-156.395020,0.009576,0.003312,0.084130,235.736526,12.008991,0.841295,-156.395020,0.084199,0.000000
91.410004,52.966629,-156.350540,0.009576,0.003312,0.084130,235.607330,12.002409,0.841295,-156.350540,0.084199,0.000000
91.630005,52.937584,-156.395020,0.009567,0.003312,0.084130,235.478134,11.995828,0.841295,-156.395020,0.084199,0.000000
91.850006,52.926041,-156.439499,0.009572,0.003312,0.084130,235.426788,11.993212,0.841295,-156.439499,0.084199,0.000000
92.070007,52.905190,-156.395020,0.009576,0.003312,0.084130,235.334030,11.988487,0.841295,-156.395020,0.084199,0.000000
92.290001,52.871674,-156.439499,0.009576,0.003312,0.084130,235.184952,11.980893,0.841295,-156.439499,0.084199,0.000000
92.510002,52.856033,-156.306061,0.009576,0.003312,0.084130,235.115372,11.977348,0.841295,-156.306061,0.084199,0.000000
92.730003,52.834061,-156.350540,0.009585,0.003312,0.084130,235.017639,11.972369,0.841295,-156.350540,0.084199,0.000000
92.800003,52.826988,-156.483978,0.009559,0.003312,0.084130,234.986176,11.970767,0.841295,-156.483978,0.084199,0.000000