File: Data/compression 8/AutoHeating-12-8-1-2-240328_03282024_152416.csv
Time (sec),S:Load (lbs),S:HL1 (DIM),S:LVDT (in),S:Position (in),Ch:Position (mm),Ch:Load (N),Ch:Stress (MPa),Ch:Strain (mm/mm),Ch:HL1 (DIM),Set Point (),Cycles ()
0.110000,0.006332,-132.419785,-0.000013,-0.000000,-0.000000,0.028168,0.001435,-0.000000,-132.419785,0.000199,0.000000
0.340000,-0.003349,-132.419785,-0.000009,-0.000000,-0.000000,-0.014898,-0.000759,-0.000000,-132.419785,0.000199,0.000000
0.570000,0.006706,-132.464279,-0.000013,0.000090,0.002298,0.029831,0.001520,0.022982,-132.464279,0.003235,0.000000
0.800000,0.007820,-132.464279,0.000052,0.000231,0.005862,0.034786,0.001772,0.058624,-132.464279,0.007068,0.000000
1.030000,-0.003349,-132.508759,0.000224,0.000391,0.009930,-0.014898,-0.000759,0.099297,-132.508759,0.010901,0.000000
1.260000,-0.025314,-132.464279,0.000375,0.000538,0.013668,-0.112604,-0.005736,0.136676,-132.464279,0.014734,0.000000
1.490000,-0.023453,-132.375305,0.000543,0.000690,0.017518,-0.104323,-0.005314,0.175180,-132.375305,0.018550,0.000000
1.720000,-0.008186,-132.464279,0.000677,0.000843,0.021412,-0.036415,-0.001855,0.214119,-132.464279,0.022383,0.000000
1.950000,0.033142,-132.464279,0.000832,0.000985,0.025011,0.147423,0.007510,0.250106,-132.464279,0.026216,0.000000
2.180000,0.022346,-132.464279,0.000992,0.001142,0.029009,0.099402,0.005064,0.290086,-132.464279,0.030049,0.000000
2.410000,-0.017502,-132.508759,0.001138,0.001293,0.032842,-0.077852,-0.003966,0.328419,-132.508759,0.033882,0.000000
2.640000,-0.003349,-132.464279,0.001298,0.001442,0.036623,-0.014898,-0.000759,0.366230,-132.464279,0.037716,0.000000
2.870000,0.022346,-132.508759,0.001440,0.001597,0.040560,0.099402,0.005064,0.405601,-132.508759,0.041549,0.000000
3.100000,0.026443,-132.464279,0.001600,0.001739,0.044159,0.117626,0.005992,0.441591,-132.464279,0.045382,0.000000
3.330000,-0.002602,-132.553238,0.001742,0.001894,0.048114,-0.011573,-0.000590,0.481136,-132.553238,0.049215,0.000000
3.560000,-0.026810,-132.464279,0.001910,0.002050,0.052060,-0.119255,-0.006075,0.520597,-132.464279,0.053048,0.000000
3.790000,-0.049896,-132.508759,0.002052,0.002195,0.055754,-0.221950,-0.011307,0.557538,-132.508759,0.056881,0.000000
4.020000,-0.008560,-132.597717,0.002195,0.002348,0.059648,-0.038078,-0.001940,0.596477,-132.597717,0.060715,0.000000
4.250000,0.021225,-132.553238,0.002354,0.002495,0.063377,0.094413,0.004810,0.633769,-132.553238,0.064548,0.000000
4.480000,0.036125,-132.553238,0.002509,0.002649,0.067297,0.160693,0.008186,0.672966,-132.553238,0.068364,0.000000
4.710000,0.041336,-132.508759,0.002669,0.002803,0.071199,0.183872,0.009367,0.711992,-132.508759,0.072196,0.000000
4.940000,0.018623,-132.597717,0.002820,0.002951,0.074945,0.082841,0.004220,0.749455,-132.597717,0.076030,0.000000
5.170000,-0.001862,-132.553238,0.002966,0.003097,0.078657,-0.008281,-0.000422,0.786573,-132.553238,0.079863,0.000000
5.400000,0.011917,-132.597717,0.003113,0.003252,0.082603,0.053010,0.002700,0.826031,-132.597717,0.083696,0.000000
5.630000,0.033516,-132.597717,0.003272,0.003399,0.086324,0.149086,0.007595,0.863236,-132.597717,0.087529,0.000000
5.860000,-0.003349,-132.553238,0.003423,0.003560,0.090434,-0.014898,-0.000759,0.904344,-132.553238,0.091362,0.000000
6.090000,0.001122,-132.597717,0.003591,0.003708,0.094181,0.004989,0.000254,0.941807,-132.597717,0.095195,0.000000
6.320000,0.089745,-132.553238,0.003725,0.003851,0.097823,0.399204,0.020336,0.978229,-132.553238,0.099028,0.000000
6.550000,0.462486,-132.642197,0.003876,0.004009,0.101838,2.057242,0.104801,1.018383,-132.642197,0.102862,0.000000
6.780000,0.618889,-132.642197,0.003923,-0.000000,-0.000000,2.752955,0.140242,-0.000000,-132.642197,0.000156,0.000000
7.010000,0.584625,-132.553238,0.003932,-0.000000,-0.000009,2.600543,0.132478,-0.000087,-132.553238,0.000156,0.000000
7.240000,0.602127,-132.597717,0.003923,-0.000000,-0.000009,2.678395,0.136444,-0.000087,-132.597717,0.000260,0.000000
7.470000,0.575317,-132.642197,0.003941,-0.000000,-0.000009,2.559139,0.130369,-0.000087,-132.642197,0.000642,0.000000
7.700000,0.543671,-132.642197,0.003932,-0.000000,-0.000000,2.418368,0.123198,-0.000000,-132.642197,0.001032,0.000000
7.930000,0.561913,-132.686676,0.003928,-0.000000,-0.000000,2.499512,0.127331,-0.000000,-132.686676,0.001414,0.000000
8.160001,0.809166,-132.686676,0.003954,0.000040,0.001015,3.599350,0.183360,0.010147,-132.686676,0.001795,0.000000
8.390000,0.848640,-132.642197,0.003984,0.000053,0.001344,3.774941,0.192305,0.013444,-132.642197,0.002177,0.000000
8.620001,0.976738,-132.642197,0.003988,0.000072,0.001821,4.344748,0.221332,0.018213,-132.642197,0.002559,0.000000
8.850000,1.069832,-132.686676,0.004010,0.000086,0.002177,4.758850,0.242427,0.021767,-132.686676,0.002949,0.000000
9.080001,1.118980,-132.686676,0.004010,0.000094,0.002385,4.977473,0.253565,0.023849,-132.686676,0.003330,0.000000
9.310000,1.246330,-132.686676,0.004010,0.000108,0.002732,5.543954,0.282422,0.027319,-132.686676,0.003712,0.000000
9.540001,1.448532,-132.686676,0.004049,0.000132,0.003365,6.443393,0.328242,0.033648,-132.686676,0.004093,0.000000
9.770000,1.475716,-132.686676,0.004061,0.000145,0.003694,6.564311,0.334402,0.036944,-132.686676,0.004475,0.000000
10.000000,1.527473,-132.642197,0.004079,0.000160,0.004076,6.794541,0.346130,0.040760,-132.642197,0.004865,0.000000
10.230000,1.628387,-132.731155,0.004083,0.000174,0.004414,7.243429,0.368998,0.044143,-132.731155,0.005247,0.000000
10.460000,1.739731,-132.775635,0.004096,0.000186,0.004718,7.738709,0.394229,0.047179,-132.775635,0.005629,0.000000
10.690001,1.882347,-132.642197,0.004113,0.000203,0.005151,8.373098,0.426546,0.051512,-132.642197,0.006010,0.000000
10.920000,2.007835,-132.731155,0.004122,0.000219,0.005559,8.931298,0.454982,0.055589,-132.731155,0.006392,0.000000
11.150001,1.994804,-132.775635,0.004130,0.000223,0.005663,8.873333,0.452029,0.056630,-132.775635,0.006782,0.000000
11.380000,2.122902,-132.731155,0.004143,0.000235,0.005967,9.443139,0.481056,0.059665,-132.731155,0.007163,0.000000
11.610001,2.372391,-132.731155,0.004174,0.000262,0.006643,10.552921,0.537591,0.066429,-132.731155,0.007545,0.000000
11.840000,2.487450,-132.775635,0.004169,0.000277,0.007042,11.064729,0.563664,0.070418,-132.775635,0.007927,0.000000
12.070001,2.598793,-132.731155,0.004199,0.000293,0.007449,11.560009,0.588895,0.074494,-132.731155,0.008317,0.000000
12.300000,2.669914,-132.775635,0.004208,0.000307,0.007805,11.876371,0.605011,0.078052,-132.775635,0.008698,0.000000
12.530001,2.838600,-132.820114,0.004234,0.000326,0.008291,12.626724,0.643236,0.082908,-132.820114,0.009080,0.000000
12.760000,2.915306,-132.775635,0.004238,0.000340,0.008646,12.967929,0.660618,0.086462,-132.775635,0.009461,0.000000
12.990001,2.974518,-132.775635,0.004255,0.000351,0.008915,13.231317,0.674035,0.089153,-132.775635,0.009843,0.000000
13.220000,2.998718,-132.775635,0.004273,0.000362,0.009193,13.338965,0.679519,0.091928,-132.775635,0.010233,0.000000
13.450001,3.242622,-132.775635,0.004286,0.000382,0.009696,14.423904,0.734789,0.096958,-132.775635,0.010615,0.000000
13.680000,3.345398,-132.820114,0.004294,0.000399,0.010129,14.881073,0.758078,0.101291,-132.820114,0.010997,0.000000
13.910001,3.413918,-132.775635,0.004312,0.000416,0.010563,15.185863,0.773605,0.105629,-132.775635,0.011378,0.000000
14.140000,3.479820,-132.775635,0.004320,0.000428,0.010875,15.479013,0.788539,0.108751,-132.775635,0.011760,0.000000
14.370001,3.537544,-132.775635,0.004342,0.000440,0.011170,15.735783,0.801619,0.111700,-132.775635,0.012150,0.000000
14.600000,3.692818,-132.820114,0.004359,0.000455,0.011569,16.426474,0.836804,0.115689,-132.820114,0.012531,0.000000
14.830001,3.767670,-132.864594,0.004368,0.000470,0.011950,16.759432,0.853766,0.119504,-132.864594,0.012913,0.000000
15.060000,3.804909,-132.864594,0.004381,0.000481,0.012211,16.925079,0.862205,0.122108,-132.864594,0.013295,0.000000
15.290001,4.078224,-132.820114,0.004393,0.000504,0.012801,18.140846,0.924139,0.128005,-132.820114,0.013676,0.000000
15.520000,4.144882,-132.775635,0.004415,0.000518,0.013156,18.437357,0.939244,0.131559,-132.775635,0.014067,0.000000
15.750001,4.274094,-132.909088,0.004441,0.000537,0.013642,19.012117,0.968523,0.136415,-132.909088,0.014448,0.000000
15.980000,4.238716,-132.909088,0.004437,0.000548,0.013928,18.854752,0.960507,0.139277,-132.909088,0.014830,0.000000
16.210001,4.297180,-132.864594,0.004449,0.000562,0.014283,19.114813,0.973755,0.142834,-132.864594,0.015211,0.000000
16.440001,4.438683,-132.864594,0.004475,0.000578,0.014691,19.744246,1.005820,0.146911,-132.864594,0.015593,0.000000
16.670000,4.588005,-132.953568,0.004480,0.000593,0.015073,20.408466,1.039657,0.150726,-132.953568,0.015983,0.000000
16.900002,4.631569,-132.909088,0.004506,0.000606,0.015385,20.602247,1.049528,0.153848,-132.909088,0.016365,0.000000
17.130001,4.681839,-132.953568,0.004518,0.000622,0.015810,20.825859,1.060920,0.158095,-132.953568,0.016746,0.000000
17.360001,5.013626,-132.909088,0.004536,0.000645,0.016373,22.301723,1.136104,0.163735,-132.909088,0.017128,0.000000
17.590000,4.947716,-132.864594,0.004549,0.000655,0.016625,22.008539,1.121168,0.166248,-132.864594,0.017509,0.000000
17.820002,5.011765,-132.864594,0.004557,0.000671,0.017041,22.293442,1.135682,0.170411,-132.864594,0.017900,0.000000
18.050001,5.074692,-132.953568,0.004570,0.000684,0.017371,22.573357,1.149942,0.173708,-132.953568,0.018281,0.000000
18.280001,5.126831,-132.998047,0.004587,0.000697,0.017700,22.805283,1.161757,0.177001,-132.998047,0.018663,0.000000
18.510000,5.345413,-132.953568,0.004600,0.000716,0.018177,23.777586,1.211288,0.181773,-132.953568,0.019044,0.000000
18.740002,5.380409,-132.909088,0.004626,0.000729,0.018507,23.933256,1.219218,0.185066,-132.909088,0.019426,0.000000
18.970001,5.427330,-132.998047,0.004626,0.000741,0.018810,24.141970,1.229851,0.188102,-132.998047,0.019816,0.000000
19.200001,5.711449,-132.998047,0.004652,0.000764,0.019417,25.405792,1.294233,0.194173,-132.998047,0.020198,0.000000
19.430000,5.699539,-132.998047,0.004669,0.000778,0.019764,25.352816,1.291534,0.197643,-132.998047,0.020579,0.000000
19.660002,5.744225,-132.953568,0.004674,0.000792,0.020111,25.551586,1.301660,0.201110,-132.953568,0.020961,0.000000
19.890001,5.754272,-132.953568,0.004695,0.000805,0.020441,25.596283,1.303937,0.204407,-132.953568,0.021343,0.000000
20.120001,5.747574,-132.998047,0.004708,0.000816,0.020736,25.566484,1.302419,0.207355,-132.998047,0.021733,0.000000
20.350000,5.997810,-133.042526,0.004717,0.000834,0.021178,26.679592,1.359123,0.211776,-133.042526,0.022114,0.000000
20.580002,6.183250,-133.042526,0.004738,0.000852,0.021629,27.504471,1.401145,0.216288,-133.042526,0.022496,0.000000
20.810001,6.042488,-133.087006,0.004743,0.000862,0.021889,26.878330,1.369247,0.218888,-133.087006,0.022877,0.000000
21.040001,6.335922,-132.953568,0.004756,0.000883,0.022418,28.183590,1.435740,0.224179,-132.953568,0.023268,0.000000
21.270000,6.589134,-132.998047,0.004786,0.000903,0.022947,29.309933,1.493119,0.229471,-132.998047,0.023650,0.000000
21.500002,6.535141,-132.998047,0.004803,0.000917,0.023294,29.069759,1.480884,0.232938,-132.998047,0.024031,0.000000
21.730001,6.380981,-133.042526,0.004816,0.000927,0.023537,28.384024,1.445951,0.235367,-133.042526,0.024413,0.000000
21.960001,6.489342,-133.087006,0.004825,0.000940,0.023883,28.866034,1.470506,0.238834,-133.087006,0.024794,0.000000
22.190001,6.629723,-133.087006,0.004846,0.000957,0.024300,29.490479,1.502317,0.242998,-133.087006,0.025184,0.000000
22.420002,6.760056,-133.042526,0.004859,0.000971,0.024673,30.070229,1.531850,0.246726,-133.042526,0.025566,0.000000
22.650002,6.752609,-133.042526,0.004872,0.000984,0.025002,30.037106,1.530163,0.250023,-133.042526,0.025947,0.000000
22.880001,6.879959,-133.175964,0.004881,0.001000,0.025401,30.603586,1.559021,0.254012,-133.175964,0.026329,0.000000
23.110001,7.179344,-132.998047,0.004898,0.001022,0.025965,31.935318,1.626863,0.259648,-132.998047,0.026711,0.000000
23.340002,7.255684,-133.042526,0.004915,0.001039,0.026399,32.274895,1.644161,0.263985,-133.042526,0.027101,0.000000
23.570002,7.148064,-132.998047,0.004937,0.001051,0.026693,31.796175,1.619774,0.266934,-132.998047,0.027483,0.000000
23.800001,7.096680,-133.087006,0.004954,0.001062,0.026979,31.567608,1.608131,0.269795,-133.087006,0.027864,0.000000
24.030001,7.220306,-133.087006,0.004958,0.001077,0.027344,32.117527,1.636145,0.273436,-133.087006,0.028246,0.000000
24.260000,7.393456,-133.131485,0.004967,0.001094,0.027777,32.887733,1.675381,0.277773,-133.131485,0.028627,0.000000
24.490002,7.437027,-133.087006,0.004984,0.001106,0.028098,33.081547,1.685254,0.280983,-133.087006,0.029018,0.000000
24.720001,7.467560,-133.087006,0.004997,0.001119,0.028419,33.217365,1.692173,0.284193,-133.087006,0.029399,0.000000
24.950001,7.718536,-133.175964,0.005006,0.001137,0.028879,34.333763,1.749045,0.288787,-133.175964,0.029781,0.000000
25.180000,7.807907,-133.175964,0.005032,0.001153,0.029295,34.731304,1.769297,0.292951,-133.175964,0.030162,0.000000
25.410002,7.838814,-133.087006,0.005032,0.001166,0.029624,34.868786,1.776301,0.296244,-133.087006,0.030544,0.000000
25.640001,7.885735,-133.131485,0.005053,0.001181,0.029998,35.077499,1.786933,0.299976,-133.131485,0.030934,0.000000
25.870001,7.917389,-133.131485,0.005070,0.001196,0.030370,35.218304,1.794106,0.303704,-133.131485,0.031315,0.000000
26.100000,8.118843,-133.175964,0.005088,0.001214,0.030830,36.114418,1.839756,0.308299,-133.175964,0.031697,0.000000
26.330002,8.220871,-133.175964,0.005096,0.001230,0.031246,36.568260,1.862876,0.312462,-133.175964,0.032079,0.000000
26.560001,8.122566,-133.131485,0.005118,0.001241,0.031524,36.130978,1.840600,0.315236,-133.131485,0.032460,0.000000
26.790001,8.248428,-133.220444,0.005131,0.001255,0.031888,36.690842,1.869120,0.318881,-133.220444,0.032851,0.000000
27.020000,8.378754,-133.087006,0.005144,0.001274,0.032356,37.270557,1.898653,0.323563,-133.087006,0.033232,0.000000
27.250002,8.367210,-133.175964,0.005161,0.001287,0.032686,37.219212,1.896037,0.326860,-133.175964,0.033614,0.000000
27.480001,8.596596,-133.264923,0.005174,0.001306,0.033163,38.239567,1.948017,0.331629,-133.264923,0.033995,0.000000
27.710001,8.483017,-133.220444,0.005182,0.001317,0.033449,37.734344,1.922279,0.334490,-133.220444,0.034377,0.000000
27.940001,8.661758,-133.220444,0.005200,0.001335,0.033900,38.529427,1.962783,0.338998,-133.220444,0.034767,0.000000
28.170002,8.795441,-133.220444,0.005221,0.001353,0.034360,39.124073,1.993075,0.343597,-133.220444,0.035149,0.000000
28.400002,8.701233,-133.220444,0.005234,0.001363,0.034628,38.705017,1.971728,0.346284,-133.220444,0.035530,0.000000
28.630001,8.896355,-133.264923,0.005247,0.001380,0.035045,39.572964,2.015943,0.350447,-133.264923,0.035912,0.000000
28.860001,8.977905,-133.264923,0.005260,0.001396,0.035470,39.935719,2.034422,0.354698,-133.264923,0.036293,0.000000
29.090002,9.152916,-133.220444,0.005295,0.001414,0.035921,40.714203,2.074080,0.359205,-133.220444,0.036684,0.000000
29.320002,9.062805,-133.264923,0.005299,0.001428,0.036276,40.313370,2.053661,0.362763,-133.264923,0.037065,0.000000
29.550001,9.000992,-133.264923,0.005307,0.001439,0.036562,40.038410,2.039654,0.365625,-133.264923,0.037447,0.000000
29.780001,9.217339,-133.309418,0.005333,0.001458,0.037039,41.000771,2.088679,0.370394,-133.309418,0.037829,0.000000
30.010002,9.335007,-133.264923,0.005338,0.001474,0.037447,41.524185,2.115343,0.374470,-133.264923,0.038219,0.000000
30.240002,9.324585,-133.264923,0.005364,0.001488,0.037785,41.477825,2.112981,0.377850,-133.264923,0.038600,0.000000
30.470001,9.032272,-133.264923,0.005368,0.001493,0.037933,40.177555,2.046742,0.379326,-133.264923,0.038982,0.000000
30.700001,9.164459,-133.264923,0.005389,0.001508,0.038297,40.765553,2.076696,0.382967,-133.264923,0.039364,0.000000
30.930002,9.823936,-133.353897,0.005402,0.001536,0.039008,43.699051,2.226136,0.390079,-133.353897,0.039745,0.000000
31.160002,9.672752,-133.309418,0.005415,0.001549,0.039346,43.026550,2.191877,0.393463,-133.309418,0.040135,0.000000
31.390001,9.628807,-133.264923,0.005437,0.001563,0.039702,42.831074,2.181919,0.397017,-133.264923,0.040517,0.000000
31.620001,9.587852,-133.309418,0.005445,0.001576,0.040040,42.648899,2.172638,0.400400,-133.309418,0.040898,0.000000
31.850002,9.725624,-133.309418,0.005467,0.001591,0.040404,43.261738,2.203858,0.404041,-133.309418,0.041280,0.000000
32.080002,9.849625,-133.398376,0.005467,0.001607,0.040820,43.813320,2.231957,0.408205,-133.398376,0.041661,0.000000
32.310001,9.783348,-133.398376,0.005480,0.001618,0.041107,43.518505,2.216938,0.411066,-133.398376,0.042052,0.000000
32.540001,9.429588,-133.309418,0.005493,0.001622,0.041202,41.944904,2.136775,0.412020,-133.309418,0.042434,0.000000
32.770000,10.164658,-133.309418,0.005493,0.001648,0.041870,45.214657,2.303344,0.418696,-133.309418,0.042815,0.000000
33.000000,10.263702,-133.353897,0.005527,0.001664,0.042277,45.655228,2.325788,0.422773,-133.353897,0.043197,0.000000
33.230003,10.388451,-133.353897,0.005536,0.001683,0.042754,46.210136,2.354057,0.427542,-133.353897,0.043578,0.000000
33.460003,10.264824,-133.398376,0.005553,0.001695,0.043058,45.660217,2.326042,0.430577,-133.398376,0.043968,0.000000
33.690002,10.334831,-133.353897,0.005566,0.001712,0.043483,45.971626,2.341906,0.434828,-133.353897,0.044350,0.000000
33.920002,10.383240,-133.353897,0.005588,0.001726,0.043847,46.186958,2.352876,0.438469,-133.353897,0.044732,0.000000
34.150002,10.404831,-133.353897,0.005596,0.001742,0.044246,46.283001,2.357768,0.442458,-133.353897,0.045113,0.000000
34.380001,10.391060,-133.398376,0.005618,0.001756,0.044593,46.221745,2.354648,0.445929,-133.398376,0.045495,0.000000
34.610001,10.174706,-133.442856,0.005622,0.001764,0.044810,45.259350,2.305621,0.448097,-133.442856,0.045885,0.000000
34.840000,10.877747,-133.398376,0.005652,0.001790,0.045469,48.386635,2.464933,0.454687,-133.398376,0.046267,0.000000
35.070004,10.712784,-133.442856,0.005661,0.001802,0.045781,47.652843,2.427552,0.457810,-133.442856,0.046648,0.000000
35.300003,10.780930,-133.398376,0.005678,0.001818,0.046180,47.955971,2.442993,0.461799,-133.398376,0.047030,0.000000
35.530003,10.815559,-133.442856,0.005687,0.001832,0.046527,48.110012,2.450841,0.465270,-133.442856,0.047411,0.000000
35.760002,10.656555,-133.487335,0.005687,0.001843,0.046804,47.402725,2.414810,0.468044,-133.487335,0.047802,0.000000
35.990002,11.012543,-133.398376,0.005713,0.001860,0.047255,48.986237,2.495478,0.472552,-133.398376,0.048183,0.000000
36.220001,10.881844,-133.442856,0.005730,0.001871,0.047524,48.404858,2.465861,0.475239,-133.442856,0.048565,0.000000
36.450001,11.051270,-133.398376,0.005743,0.001885,0.047880,49.158501,2.504254,0.478797,-133.398376,0.048946,0.000000
36.680000,11.457535,-133.487335,0.005764,0.001907,0.048426,50.965660,2.596314,0.484258,-133.487335,0.049328,0.000000
36.910000,11.453064,-133.487335,0.005773,0.001923,0.048833,50.945774,2.595301,0.488335,-133.487335,0.049718,0.000000
37.140003,11.677231,-133.531815,0.005795,0.001940,0.049285,51.942917,2.646098,0.492846,-133.531815,0.050100,0.000000
37.370003,11.492165,-133.487335,0.005816,0.001952,0.049588,51.119701,2.604162,0.495882,-133.487335,0.050481,0.000000
37.600002,11.451942,-133.531815,0.005825,0.001967,0.049961,50.940784,2.595047,0.499610,-133.531815,0.050863,0.000000
37.830002,11.743141,-133.576294,0.005825,0.001984,0.050386,52.236099,2.661034,0.503860,-133.576294,0.051244,0.000000
38.060001,11.528656,-133.531815,0.005846,0.001992,0.050594,51.282024,2.612431,0.505942,-133.531815,0.051635,0.000000
38.290001,11.677605,-133.531815,0.005855,0.002010,0.051045,51.944580,2.646183,0.510450,-133.531815,0.052016,0.000000
38.520000,11.968056,-133.531815,0.005881,0.002026,0.051470,53.236572,2.712000,0.514700,-133.531815,0.052398,0.000000
38.750000,12.391441,-133.487335,0.005890,0.002047,0.051999,55.119884,2.807941,0.519988,-133.487335,0.052780,0.000000
38.980003,12.215309,-133.487335,0.005920,0.002061,0.052346,54.336411,2.768028,0.523459,-133.487335,0.053170,0.000000
39.210003,12.261856,-133.531815,0.005915,0.002075,0.052701,54.543461,2.778576,0.527013,-133.531815,0.053551,0.000000
39.440002,12.051842,-133.576294,0.005941,0.002085,0.052962,53.609268,2.730986,0.529617,-133.576294,0.053933,0.000000
39.670002,12.412666,-133.487335,0.005941,0.002104,0.053439,55.214298,2.812750,0.534386,-133.487335,0.054314,0.000000
39.900002,12.672211,-133.531815,0.005959,0.002121,0.053881,56.368809,2.871564,0.538810,-133.531815,0.054696,0.000000
40.130001,12.486771,-133.531815,0.005989,0.002131,0.054124,55.543930,2.829543,0.541236,-133.531815,0.055086,0.000000
40.360001,12.443199,-133.576294,0.005984,0.002144,0.054453,55.350113,2.819669,0.544533,-133.576294,0.055468,0.000000
40.590000,13.065063,-133.620773,0.006002,0.002166,0.055017,58.116306,2.960586,0.550169,-133.620773,0.055850,0.000000
40.820004,13.042351,-133.576294,0.006010,0.002180,0.055373,58.015274,2.955439,0.553726,-133.576294,0.056231,0.000000
41.050003,13.075119,-133.576294,0.006036,0.002195,0.055754,58.161034,2.962864,0.557542,-133.576294,0.056613,0.000000
41.280003,13.002502,-133.665253,0.006058,0.002207,0.056049,57.838020,2.946409,0.560490,-133.665253,0.057003,0.000000
41.510002,12.966385,-133.620773,0.006058,0.002219,0.056361,57.677361,2.938225,0.563613,-133.620773,0.057384,0.000000
41.740002,13.604630,-133.620773,0.006066,0.002241,0.056934,60.516415,3.082853,0.569335,-133.620773,0.057766,0.000000
41.970001,13.443024,-133.620773,0.006092,0.002251,0.057168,59.797554,3.046233,0.571678,-133.620773,0.058148,0.000000
42.200001,13.580803,-133.576294,0.006088,0.002266,0.057558,60.410427,3.077454,0.575580,-133.576294,0.058529,0.000000
42.430000,13.939392,-133.620773,0.006114,0.002283,0.058000,62.005512,3.158711,0.580001,-133.620773,0.058919,0.000000
42.660004,14.501305,-133.620773,0.006135,0.002306,0.058581,64.505028,3.286042,0.585811,-133.620773,0.059301,0.000000
42.890003,14.214577,-133.665253,0.006148,0.002317,0.058859,63.229595,3.221069,0.588589,-133.665253,0.059682,0.000000
43.120003,14.028763,-133.665253,0.006148,0.002329,0.059154,62.403053,3.178963,0.591537,-133.665253,0.060064,0.000000
43.350002,14.072334,-133.620773,0.006161,0.002342,0.059474,62.596870,3.188837,0.594743,-133.620773,0.060446,0.000000
43.580002,14.397041,-133.620773,0.006187,0.002360,0.059943,64.041237,3.262416,0.599429,-133.620773,0.060836,0.000000
43.810001,14.564232,-133.665253,0.006200,0.002373,0.060263,64.784943,3.300302,0.602635,-133.665253,0.061218,0.000000
44.040001,14.685257,-133.709732,0.006196,0.002386,0.060602,65.323288,3.327727,0.606018,-133.709732,0.061599,0.000000
44.270000,15.249771,-133.665253,0.006222,0.002407,0.061131,67.834373,3.455647,0.611310,-133.665253,0.061981,0.000000
44.500004,15.530914,-133.665253,0.006234,0.002426,0.061608,69.084961,3.519356,0.616079,-133.665253,0.062362,0.000000
44.730003,15.634430,-133.620773,0.006260,0.002441,0.062007,69.545418,3.542813,0.620068,-133.620773,0.062752,0.000000
44.960003,15.326485,-133.709732,0.006260,0.002454,0.062328,68.175606,3.473031,0.623278,-133.709732,0.063134,0.000000
45.190002,15.282166,-133.754227,0.006269,0.002464,0.062579,67.978470,3.462988,0.625791,-133.754227,0.063516,0.000000
45.420002,15.556610,-133.709732,0.006282,0.002479,0.062978,69.199257,3.525178,0.629780,-133.709732,0.063897,0.000000
45.650002,15.885414,-133.709732,0.006303,0.002496,0.063394,70.661850,3.599686,0.633943,-133.709732,0.064279,0.000000
45.880001,15.672417,-133.665253,0.006329,0.002505,0.063629,69.714394,3.551420,0.636286,-133.665253,0.064669,0.000000
46.110001,16.224648,-133.754227,0.006325,0.002522,0.064071,72.170837,3.676558,0.640707,-133.754227,0.065051,0.000000
46.340004,16.499084,-133.754227,0.006351,0.002540,0.064513,73.391594,3.738746,0.645132,-133.754227,0.065432,0.000000
46.570004,16.647659,-133.709732,0.006359,0.002555,0.064886,74.052490,3.772413,0.648860,-133.709732,0.065814,0.000000
46.800003,16.621964,-133.665253,0.006377,0.002568,0.065224,73.938187,3.766591,0.652243,-133.665253,0.066204,0.000000
47.030003,16.665535,-133.754227,0.006398,0.002581,0.065545,74.132004,3.776464,0.655449,-133.754227,0.066586,0.000000
47.260002,16.988007,-133.798706,0.006403,0.002598,0.065987,75.566429,3.849537,0.659874,-133.798706,0.066967,0.000000
47.490002,17.650833,-133.754227,0.006420,0.002619,0.066525,78.514824,3.999736,0.665248,-133.754227,0.067349,0.000000
47.720001,17.653061,-133.709732,0.006433,0.002632,0.066846,78.524734,4.000241,0.668458,-133.709732,0.067730,0.000000
47.950001,17.452728,-133.798706,0.006446,0.002642,0.067097,77.633614,3.954845,0.670975,-133.798706,0.068121,0.000000
48.180004,17.833664,-133.798706,0.006454,0.002659,0.067540,79.328102,4.041166,0.675396,-133.798706,0.068502,0.000000
48.410004,18.290192,-133.798706,0.006463,0.002677,0.068008,81.358833,4.144617,0.680081,-133.798706,0.068884,0.000000
48.640003,18.360947,-133.798706,0.006480,0.002692,0.068381,81.673569,4.160650,0.683809,-133.798706,0.069265,0.000000
48.870003,18.587349,-133.754227,0.006502,0.002708,0.068771,82.680656,4.211954,0.687712,-133.754227,0.069647,0.000000
49.100002,18.662941,-133.798706,0.006519,0.002722,0.069135,83.016907,4.229083,0.691353,-133.798706,0.070037,0.000000
49.330002,19.154472,-133.754227,0.006528,0.002741,0.069612,85.203346,4.340466,0.696122,-133.754227,0.070419,0.000000
49.560001,19.174210,-133.843185,0.006528,0.002752,0.069890,85.291145,4.344938,0.698900,-133.843185,0.070800,0.000000
49.790001,19.276978,-133.843185,0.006536,0.002767,0.070271,85.748276,4.368226,0.702715,-133.843185,0.071182,0.000000
50.020004,19.445663,-133.843185,0.006554,0.002781,0.070627,86.498634,4.406450,0.706269,-133.843185,0.071564,0.000000
50.250004,19.999382,-133.843185,0.006575,0.002800,0.071112,88.961693,4.531925,0.711125,-133.843185,0.071954,0.000000
50.480003,20.342339,-133.887665,0.006592,0.002816,0.071520,90.487244,4.609640,0.715201,-133.887665,0.072335,0.000000
50.710003,20.324089,-133.843185,0.006592,0.002828,0.071841,90.406067,4.605505,0.718411,-133.843185,0.072717,0.000000
50.940002,20.253716,-133.976624,0.006622,0.002841,0.072153,90.093025,4.589558,0.721533,-133.976624,0.073098,0.000000
51.170002,21.070702,-133.887665,0.006622,0.002862,0.072691,93.727165,4.774689,0.726908,-133.887665,0.073480,0.000000
51.400002,21.224487,-133.887665,0.006640,0.002875,0.073029,94.411232,4.809538,0.730292,-133.887665,0.073871,0.000000
51.630001,21.365242,-133.798706,0.006657,0.002889,0.073385,95.037346,4.841433,0.733846,-133.798706,0.074252,0.000000
51.860001,20.780251,-133.976624,0.006666,0.002893,0.073480,92.435173,4.708872,0.734803,-133.976624,0.074634,0.000000
52.090004,21.897736,-133.932144,0.006679,0.002919,0.074148,97.405991,4.962098,0.741480,-133.932144,0.075015,0.000000
52.320004,22.714348,-133.976624,0.006687,0.002937,0.074607,101.038467,5.147145,0.746075,-133.976624,0.075397,0.000000
52.550003,22.668175,-133.887665,0.006704,0.002950,0.074920,100.833076,5.136682,0.749197,-133.887665,0.075787,0.000000
52.780003,22.995117,-133.887665,0.006717,0.002966,0.075327,102.287392,5.210768,0.753274,-133.887665,0.076168,0.000000
53.010002,23.168274,-133.976624,0.006717,0.002979,0.075674,103.057632,5.250006,0.756741,-133.976624,0.076550,0.000000
53.240002,23.309402,-133.932144,0.006743,0.002991,0.075978,103.685402,5.281986,0.759776,-133.932144,0.076932,0.000000
53.470001,23.755501,-133.976624,0.006752,0.003007,0.076385,105.669746,5.383073,0.763852,-133.976624,0.077313,0.000000
53.700001,23.842636,-133.887665,0.006760,0.003018,0.076663,106.057343,5.402818,0.766630,-133.887665,0.077704,0.000000
53.930004,23.643417,-133.976624,0.006760,0.003031,0.076984,105.171173,5.357675,0.769836,-133.976624,0.078085,0.000000
54.160004,25.114288,-133.976624,0.006782,0.003052,0.077513,111.713936,5.690979,0.775128,-133.976624,0.078467,0.000000
54.390003,25.378304,-134.021103,0.006791,0.003067,0.077894,112.888329,5.750806,0.778943,-134.021103,0.078848,0.000000
54.620003,26.021019,-133.976624,0.006804,0.003086,0.078389,115.747276,5.896447,0.783886,-133.976624,0.079230,0.000000
54.850002,26.223587,-133.932144,0.006825,0.003100,0.078736,116.648338,5.942350,0.787357,-133.932144,0.079620,0.000000
55.080002,26.572876,-134.021103,0.006829,0.003115,0.079108,118.202057,6.021500,0.791085,-134.021103,0.080002,0.000000
55.310001,27.140373,-134.021103,0.006847,0.003131,0.079534,120.726410,6.150096,0.795335,-134.021103,0.080383,0.000000
55.540001,27.312035,-134.065582,0.006847,0.003144,0.079854,121.489998,6.188996,0.798541,-134.065582,0.080765,0.000000
55.770004,27.504921,-134.021103,0.006873,0.003155,0.080149,122.348000,6.232704,0.801489,-134.021103,0.081155,0.000000
56.000004,27.348152,-134.021103,0.006864,0.003170,0.080513,121.650658,6.197180,0.805134,-134.021103,0.081537,0.000000
56.230003,29.061813,-134.021103,0.006885,0.003193,0.081094,129.273407,6.585501,0.810944,-134.021103,0.081918,0.000000
56.460003,29.316513,-134.065582,0.006898,0.003207,0.081467,130.406357,6.643217,0.814672,-134.065582,0.082300,0.000000
56.690002,29.540680,-134.065582,0.006894,0.003219,0.081753,131.403503,6.694014,0.817534,-134.065582,0.082681,0.000000
56.920002,29.761131,-134.110062,0.006916,0.003231,0.082057,132.384125,6.743969,0.820569,-134.110062,0.083072,0.000000
57.150002,30.584442,-134.065582,0.006929,0.003250,0.082551,136.046387,6.930533,0.825512,-134.065582,0.083453,0.000000
57.380001,30.908409,-134.021103,0.006946,0.003262,0.082855,137.487473,7.003946,0.828548,-134.021103,0.083835,0.000000
57.610004,31.304237,-134.065582,0.006946,0.003275,0.083176,139.248199,7.093642,0.831757,-134.065582,0.084217,0.000000
57.840004,31.452812,-134.065582,0.006954,0.003285,0.083436,139.909103,7.127309,0.834357,-134.065582,0.084598,0.000000
58.070004,32.812347,-134.065582,0.006950,0.003310,0.084078,145.956604,7.435384,0.840777,-134.065582,0.084988,0.000000
58.300003,33.633057,-134.065582,0.006972,0.003326,0.084468,149.607315,7.621359,0.844679,-134.065582,0.085370,0.000000
58.530003,34.219543,-134.110062,0.006998,0.003343,0.084902,152.216125,7.754259,0.849016,-134.110062,0.085751,0.000000
58.760002,34.346519,-134.110062,0.006998,0.003353,0.085170,152.780945,7.783032,0.851704,-134.110062,0.086133,0.000000
58.990002,34.973969,-134.154541,0.007011,0.003368,0.085543,155.571976,7.925214,0.855432,-134.154541,0.086514,0.000000
59.220001,35.818512,-134.110062,0.007011,0.003384,0.085951,159.328705,8.116590,0.859508,-134.110062,0.086905,0.000000
59.450005,36.292168,-134.065582,0.007023,0.003397,0.086289,161.435623,8.223924,0.862892,-134.065582,0.087286,0.000000
59.680004,36.820938,-134.110062,0.007041,0.003411,0.086645,163.787720,8.343743,0.866446,-134.110062,0.087668,0.000000
59.910004,37.628983,-134.154541,0.007049,0.003427,0.087052,167.382080,8.526849,0.870522,-134.154541,0.088050,0.000000
60.140003,38.848129,-134.199036,0.007058,0.003448,0.087573,172.805115,8.803112,0.875726,-134.199036,0.088431,0.000000
60.370003,39.192207,-134.154541,0.007067,0.003462,0.087937,174.335648,8.881082,0.879367,-134.154541,0.088821,0.000000
60.600002,39.820023,-134.110062,0.007075,0.003476,0.088293,177.128311,9.023347,0.882925,-134.110062,0.089203,0.000000
60.830002,40.111961,-134.154541,0.007084,0.003487,0.088561,178.426910,9.089499,0.885612,-134.154541,0.089585,0.000000
61.060001,41.315102,-134.199036,0.007092,0.003505,0.089029,183.778748,9.362136,0.890294,-134.199036,0.089966,0.000000
61.290005,42.247894,-134.154541,0.007105,0.003522,0.089454,187.928024,9.573510,0.894545,-134.154541,0.090348,0.000000
61.520004,42.362953,-134.243515,0.007105,0.003530,0.089671,188.439835,9.599583,0.896714,-134.243515,0.090738,0.000000
61.750004,43.389587,-134.154541,0.007105,0.003551,0.090183,193.006531,9.832221,0.901831,-134.154541,0.091119,0.000000
61.980003,44.832901,-134.199036,0.007123,0.003569,0.090651,199.426697,10.159281,0.906513,-134.199036,0.091501,0.000000
62.210003,45.192986,-134.199036,0.007136,0.003581,0.090946,201.028442,10.240877,0.909461,-134.199036,0.091882,0.000000
62.440002,46.011833,-134.199036,0.007131,0.003597,0.091362,204.670853,10.426431,0.913624,-134.199036,0.092264,0.000000
62.670002,46.697746,-134.243515,0.007144,0.003609,0.091666,207.721954,10.581861,0.916660,-134.243515,0.092655,0.000000
62.900002,47.107353,-134.199036,0.007153,0.003623,0.092021,209.543976,10.674679,0.920214,-134.199036,0.093036,0.000000
63.130005,48.735367,-134.154541,0.007157,0.003643,0.092524,216.785736,11.043591,0.925244,-134.154541,0.093418,0.000000
63.360004,49.050392,-134.243515,0.007170,0.003650,0.092715,218.187042,11.114978,0.927152,-134.243515,0.093799,0.000000
63.590004,50.127296,-134.287994,0.007183,0.003668,0.093166,222.977356,11.359008,0.931663,-134.287994,0.094181,0.000000
63.820004,51.448845,-134.287994,0.007174,0.003687,0.093652,228.855896,11.658475,0.936519,-134.287994,0.094571,0.000000
64.050003,53.004242,-134.243515,0.007179,0.003708,0.094172,235.774643,12.010933,0.941720,-134.243515,0.094953,0.000000
64.280006,53.410873,-134.287994,0.007192,0.003716,0.094389,237.583435,12.103077,0.943888,-134.287994,0.095334,0.000000
64.510002,53.913574,-134.332474,0.007200,0.003728,0.094701,239.819550,12.216990,0.947011,-134.332474,0.095716,0.000000
64.740005,54.875786,-134.376953,0.007213,0.003744,0.095100,244.099686,12.435031,0.951000,-134.376953,0.096106,0.000000
64.970001,56.275162,-134.243515,0.007200,0.003763,0.095577,250.324417,12.752133,0.955769,-134.243515,0.096488,0.000000
65.200005,57.003151,-134.243515,0.007222,0.003773,0.095846,253.562683,12.917098,0.958460,-134.243515,0.096869,0.000000
65.430000,58.057335,-134.243515,0.007235,0.003790,0.096254,258.251923,13.155980,0.962537,-134.243515,0.097251,0.000000
65.660004,59.446663,-134.287994,0.007226,0.003807,0.096696,264.431976,13.470806,0.966957,-134.287994,0.097632,0.000000
65.889999,60.942108,-134.421432,0.007235,0.003826,0.097190,271.084045,13.809679,0.971900,-134.421432,0.098023,0.000000
66.120003,62.027946,-134.332474,0.007239,0.003840,0.097546,275.914093,14.055734,0.975458,-134.332474,0.098404,0.000000
66.350006,62.821472,-134.332474,0.007256,0.003854,0.097884,279.443878,14.235549,0.978838,-134.332474,0.098786,0.000000
66.580002,63.342415,-134.332474,0.007256,0.003863,0.098127,281.761139,14.353597,0.981268,-134.332474,0.099167,0.000000
66.810005,64.598808,-134.287994,0.007269,0.003880,0.098543,287.349854,14.638299,0.985431,-134.287994,0.099549,0.000000
67.040001,65.975838,-134.376953,0.007261,0.003896,0.098968,293.475189,14.950338,0.989678,-134.376953,0.099939,0.000000
67.270004,66.519875,-134.421432,0.007278,0.003905,0.099176,295.895172,15.073619,0.991760,-134.421432,0.100321,0.000000
67.500000,67.388252,-134.376953,0.007274,0.003909,0.099297,299.757904,15.270396,0.992975,-134.376953,0.099540,0.000000
67.730003,66.852776,-134.421432,0.007291,0.003909,0.099297,297.376007,15.149055,0.992975,-134.421432,0.099540,0.000000
67.960007,66.449501,-134.376953,0.007299,0.003906,0.099211,295.582153,15.057672,0.992108,-134.376953,0.099297,0.000000
68.190002,66.018288,-134.421432,0.007299,0.003905,0.099185,293.664001,14.959958,0.991847,-134.421432,0.099297,0.000000
68.420006,65.637718,-134.376953,0.007291,0.003904,0.099167,291.971161,14.873720,0.991673,-134.376953,0.099297,0.000000
68.650002,65.317482,-134.376953,0.007299,0.003904,0.099167,290.546661,14.801153,0.991673,-134.376953,0.099297,0.000000
68.880005,65.030388,-134.376953,0.007299,0.003904,0.099159,289.269623,14.736096,0.991586,-134.376953,0.099297,0.000000
69.110001,64.748878,-134.421432,0.007308,0.003904,0.099159,288.017395,14.672306,0.991586,-134.421432,0.099297,0.000000
69.340004,64.498634,-134.465912,0.007299,0.003904,0.099150,286.904266,14.615600,0.991499,-134.465912,0.099297,0.000000
69.570000,64.268517,-134.465912,0.007312,0.003904,0.099150,285.880646,14.563454,0.991499,-134.465912,0.099297,0.000000
69.800003,64.061470,-134.376953,0.007304,0.003904,0.099150,284.959656,14.516537,0.991499,-134.376953,0.099297,0.000000
70.030006,63.873802,-134.465912,0.007317,0.003904,0.099150,284.124847,14.474010,0.991499,-134.465912,0.099297,0.000000
70.260002,63.683510,-134.465912,0.007321,0.003904,0.099150,283.278412,14.430889,0.991499,-134.465912,0.099297,0.000000
70.490005,63.513344,-134.421432,0.007317,0.003904,0.099150,282.521454,14.392329,0.991499,-134.421432,0.099297,0.000000
70.720001,63.364769,-134.465912,0.007304,0.003904,0.099150,281.860565,14.358663,0.991499,-134.465912,0.099297,0.000000
70.950005,63.217308,-134.465912,0.007308,0.003904,0.099150,281.204620,14.325246,0.991499,-134.465912,0.099297,0.000000
71.180000,63.073570,-134.421432,0.007317,0.003904,0.099150,280.565247,14.292676,0.991499,-134.421432,0.099297,0.000000
71.410004,62.946960,-134.510391,0.007321,0.003903,0.099142,280.002075,14.263986,0.991415,-134.510391,0.099297,0.000000
71.640007,62.833763,-134.465912,0.007325,0.003903,0.099142,279.498535,14.238334,0.991415,-134.465912,0.099297,0.000000
71.870003,62.700081,-134.510391,0.007325,0.003903,0.099142,278.903900,14.208041,0.991415,-134.510391,0.099297,0.000000
72.100006,62.578682,-134.554871,0.007312,0.003903,0.099142,278.363892,14.180532,0.991415,-134.554871,0.099297,0.000000
72.330002,62.498253,-134.465912,0.007325,0.003903,0.099142,278.006104,14.162306,0.991415,-134.465912,0.099297,0.000000
72.560005,62.389893,-134.510391,0.007330,0.003903,0.099142,277.524109,14.137752,0.991415,-134.510391,0.099297,0.000000
72.790001,62.269989,-134.554871,0.007330,0.003903,0.099142,276.990753,14.110581,0.991415,-134.554871,0.099297,0.000000
73.020004,62.180244,-134.554871,0.007325,0.003903,0.099142,276.591553,14.090244,0.991415,-134.554871,0.099297,0.000000
73.250000,62.108009,-134.510391,0.007321,0.003903,0.099142,276.270233,14.073876,0.991415,-134.510391,0.099297,0.000000
73.480003,62.020126,-134.510391,0.007330,0.003903,0.099142,275.879303,14.053962,0.991415,-134.510391,0.099297,0.000000
73.710007,61.934105,-134.510391,0.007321,0.003903,0.099142,275.496643,14.034469,0.991415,-134.510391,0.099297,0.000000
73.940002,61.860008,-134.554871,0.007321,0.003903,0.099142,275.167053,14.017678,0.991415,-134.554871,0.099297,0.000000
74.170006,61.793724,-134.599365,0.007321,0.003903,0.099142,274.872223,14.002658,0.991415,-134.599365,0.099297,0.000000
74.400002,61.704353,-134.554871,0.007325,0.003903,0.099142,274.474670,13.982407,0.991415,-134.554871,0.099297,0.000000
74.630005,61.638069,-134.554871,0.007330,0.003903,0.099142,274.179840,13.967386,0.991415,-134.554871,0.099297,0.000000
74.860001,61.582962,-134.510391,0.007330,0.003903,0.099142,273.934692,13.954899,0.991415,-134.510391,0.099297,0.000000
75.090004,61.514442,-134.643845,0.007325,0.003903,0.099142,273.629913,13.939372,0.991415,-134.643845,0.099297,0.000000
75.320007,61.437737,-134.599365,0.007325,0.003903,0.099142,273.288696,13.921989,0.991415,-134.599365,0.099297,0.000000
75.550003,61.378159,-134.554871,0.007330,0.003903,0.099142,273.023682,13.908489,0.991415,-134.554871,0.099297,0.000000
75.780006,61.332352,-134.554871,0.007330,0.003903,0.099142,272.819916,13.898109,0.991415,-134.554871,0.099297,0.000000
76.010002,61.280220,-134.599365,0.007325,0.003903,0.099142,272.588043,13.886296,0.991415,-134.599365,0.099297,0.000000
76.240005,61.206123,-134.643845,0.007334,0.003903,0.099142,272.258423,13.869506,0.991415,-134.643845,0.099297,0.000000
76.470001,61.152122,-134.688324,0.007330,0.003903,0.099142,272.018219,13.857269,0.991415,-134.688324,0.099297,0.000000
76.700005,61.107445,-134.688324,0.007338,0.003903,0.099142,271.819489,13.847144,0.991415,-134.688324,0.099297,0.000000
76.930000,61.066483,-134.599365,0.007321,0.003903,0.099142,271.637268,13.837863,0.991415,-134.599365,0.099297,0.000000
77.160004,60.992752,-134.599365,0.007334,0.003903,0.099142,271.309326,13.821155,0.991415,-134.599365,0.099297,0.000000
77.390007,60.945084,-134.599365,0.007330,0.003903,0.099133,271.097260,13.810353,0.991328,-134.599365,0.099297,0.000000
77.620003,60.897049,-134.732803,0.007330,0.003903,0.099133,270.883606,13.799468,0.991328,-134.732803,0.099297,0.000000
77.850006,60.860558,-134.688324,0.007321,0.003903,0.099133,270.721283,13.791200,0.991328,-134.688324,0.099297,0.000000
78.080002,60.806564,-134.643845,0.007334,0.003903,0.099133,270.481110,13.778965,0.991328,-134.643845,0.099297,0.000000
78.310005,60.764488,-134.688324,0.007334,0.003903,0.099133,270.293945,13.769429,0.991328,-134.688324,0.099297,0.000000
78.540001,60.720177,-134.732803,0.007334,0.003903,0.099133,270.096832,13.759389,0.991328,-134.732803,0.099297,0.000000
78.770004,60.676231,-134.688324,0.007330,0.003903,0.099133,269.901367,13.749431,0.991328,-134.688324,0.099297,0.000000
79.000000,60.639366,-134.688324,0.007325,0.003903,0.099133,269.737366,13.741077,0.991328,-134.688324,0.099297,0.000000
79.230003,60.601013,-134.732803,0.007338,0.003903,0.099133,269.566772,13.732387,0.991328,-134.732803,0.099297,0.000000
79.460007,60.573830,-134.732803,0.007334,0.003903,0.099133,269.445862,13.726226,0.991328,-134.732803,0.099297,0.000000
79.690002,60.517601,-134.732803,0.007343,0.003903,0.099133,269.195740,13.713484,0.991328,-134.732803,0.099297,0.000000
79.920006,60.477013,-134.777283,0.007330,0.003903,0.099133,269.015198,13.704287,0.991328,-134.777283,0.099297,0.000000
80.150002,60.457649,-134.688324,0.007330,0.003903,0.099133,268.929047,13.699899,0.991328,-134.688324,0.099297,0.000000
80.380005,60.423393,-134.688324,0.007334,0.003903,0.099133,268.776672,13.692137,0.991328,-134.688324,0.099297,0.000000
80.610001,60.372375,-134.777283,0.007343,0.003903,0.099133,268.549744,13.680575,0.991328,-134.777283,0.099297,0.000000
80.840004,60.340729,-134.777283,0.007330,0.003903,0.099133,268.408966,13.673405,0.991328,-134.777283,0.099297,0.000000
81.070007,60.315407,-134.777283,0.007334,0.003903,0.099133,268.296326,13.667666,0.991328,-134.777283,0.099297,0.000000
81.300003,60.289711,-134.777283,0.007330,0.003903,0.099133,268.182037,13.661844,0.991328,-134.777283,0.099297,0.000000
81.530006,60.236832,-134.732803,0.007338,0.003903,0.099133,267.946808,13.649861,0.991328,-134.732803,0.099297,0.000000
81.760002,60.217102,-134.777283,0.007325,0.003903,0.099133,267.859039,13.645391,0.991328,-134.777283,0.099297,0.000000
81.990005,60.191406,-134.777283,0.007338,0.003903,0.099133,267.744751,13.639567,0.991328,-134.777283,0.099297,0.000000
82.220001,60.153793,-134.821762,0.007343,0.003903,0.099133,267.577423,13.631044,0.991328,-134.821762,0.099297,0.000000
82.450005,60.123634,-134.777283,0.007321,0.003903,0.099133,267.443268,13.624210,0.991328,-134.777283,0.099297,0.000000
82.680000,60.091606,-134.777283,0.007343,0.003903,0.099133,267.300812,13.616952,0.991328,-134.777283,0.099297,0.000000
82.910004,60.067032,-134.821762,0.007343,0.003903,0.099133,267.191498,13.611383,0.991328,-134.821762,0.099297,0.000000
83.140007,60.026070,-134.866241,0.007343,0.003903,0.099133,267.009308,13.602102,0.991328,-134.866241,0.099297,0.000000
83.370003,60.002243,-134.866241,0.007338,0.003903,0.099133,266.903320,13.596703,0.991328,-134.866241,0.099297,0.000000
83.600006,59.958672,-134.866241,0.007330,0.003903,0.099133,266.709503,13.586829,0.991328,-134.866241,0.099297,0.000000
83.830002,59.951973,-134.866241,0.007330,0.003903,0.099133,266.679687,13.585311,0.991328,-134.866241,0.099297,0.000000
84.060005,59.923294,-134.821762,0.007338,0.003903,0.099133,266.552124,13.578812,0.991328,-134.821762,0.099297,0.000000
84.290001,59.887177,-134.866241,0.007343,0.003903,0.099133,266.391479,13.570628,0.991328,-134.866241,0.099297,0.000000
84.520004,59.871910,-134.866241,0.007334,0.003903,0.099133,266.323547,13.567169,0.991328,-134.866241,0.099297,0.000000
84.750008,59.844727,-134.910721,0.007338,0.003903,0.099133,266.202637,13.561009,0.991328,-134.910721,0.099297,0.000000
84.980003,59.807114,-134.866241,0.007338,0.003903,0.099133,266.035339,13.552485,0.991328,-134.866241,0.099297,0.000000
85.210007,59.795944,-134.821762,0.007338,0.003903,0.099133,265.985657,13.549954,0.991328,-134.821762,0.099297,0.000000
85.440002,59.762062,-134.866241,0.007343,0.003903,0.099133,265.834930,13.542277,0.991328,-134.866241,0.099297,0.000000
85.670006,59.746422,-134.955200,0.007330,0.003903,0.099133,265.765350,13.538733,0.991328,-134.955200,0.099297,0.000000
85.900002,59.706947,-134.910721,0.007338,0.003903,0.099133,265.589752,13.529788,0.991328,-134.910721,0.099297,0.000000
86.130005,59.687210,-134.910721,0.007325,0.003903,0.099133,265.501984,13.525315,0.991328,-134.910721,0.099297,0.000000
86.360001,59.664124,-134.910721,0.007351,0.003903,0.099133,265.399261,13.520083,0.991328,-134.910721,0.099297,0.000000
86.590004,59.627258,-134.910721,0.007338,0.003903,0.099133,265.235291,13.511730,0.991328,-134.910721,0.099297,0.000000
86.820007,59.609016,-135.044174,0.007338,0.003903,0.099133,265.154144,13.507596,0.991328,-135.044174,0.099297,0.000000
87.050003,59.586304,-134.955200,0.007330,0.003903,0.099133,265.053131,13.502450,0.991328,-134.955200,0.099297,0.000000
87.280006,59.555763,-134.999680,0.007338,0.003903,0.099133,264.917267,13.495528,0.991328,-134.999680,0.099297,0.000000
87.510002,59.527466,-134.910721,0.007338,0.003903,0.099133,264.791382,13.489117,0.991328,-134.910721,0.099297,0.000000
87.740005,59.513687,-134.955200,0.007334,0.003903,0.099133,264.730103,13.485994,0.991328,-134.955200,0.099297,0.000000
87.970001,59.501770,-134.955200,0.007334,0.003903,0.099133,264.677094,13.483294,0.991328,-134.955200,0.099297,0.000000
88.200005,59.461929,-134.955200,0.007338,0.003903,0.099133,264.499878,13.474266,0.991328,-134.955200,0.099297,0.000000
88.430008,59.447403,-134.910721,0.007334,0.003903,0.099133,264.435242,13.470974,0.991328,-134.910721,0.099297,0.000000
88.660004,59.435486,-134.955200,0.007338,0.003903,0.099133,264.382233,13.468273,0.991328,-134.955200,0.099297,0.000000
88.890007,59.397881,-134.999680,0.007347,0.003903,0.099133,264.214966,13.459752,0.991328,-134.999680,0.099297,0.000000
89.120003,59.368835,-134.999680,0.007343,0.003903,0.099133,264.085754,13.453171,0.991328,-134.999680,0.099297,0.000000
89.350006,59.350960,-135.044174,0.007343,0.003903,0.099133,264.006256,13.449120,0.991328,-135.044174,0.099297,0.000000
89.580002,59.333832,-134.955200,0.007347,0.003903,0.099133,263.930054,13.445239,0.991328,-134.955200,0.099297,0.000000
89.810005,59.316330,-135.044174,0.007343,0.003903,0.099133,263.852203,13.441273,0.991328,-135.044174,0.099297,0.000000
90.040001,59.284309,-134.999680,0.007351,0.003903,0.099133,263.709778,13.434017,0.991328,-134.999680,0.099297,0.000000
90.270004,59.270531,-135.088654,0.007347,0.003903,0.099133,263.648499,13.430894,0.991328,-135.088654,0.099297,0.000000
90.500008,59.242973,-135.088654,0.007330,0.003903,0.099133,263.525909,13.424650,0.991328,-135.088654,0.099297,0.000000
90.730003,59.237389,-135.088654,0.007343,0.003903,0.099133,263.501068,13.423384,0.991328,-135.088654,0.099297,0.000000
90.960007,59.211693,-135.044174,0.007351,0.003903,0.099133,263.386749,13.417562,0.991328,-135.044174,0.099297,0.000000
91.190002,59.196426,-135.044174,0.007330,0.003903,0.099133,263.318848,13.414102,0.991328,-135.044174,0.099297,0.000000
91.420006,59.176689,-135.133133,0.007343,0.003903,0.099133,263.231049,13.409630,0.991328,-135.133133,0.099297,0.000000
91.650002,59.145782,-135.088654,0.007338,0.003903,0.099133,263.093567,13.402625,0.991328,-135.088654,0.099297,0.000000
91.880005,59.136475,-135.088654,0.007343,0.003903,0.099133,263.052185,13.400517,0.991328,-135.088654,0.099297,0.000000
92.110001,59.107803,-135.044174,0.007330,0.003903,0.099133,262.924652,13.394020,0.991328,-135.044174,0.099297,0.000000
92.340004,59.105568,-135.044174,0.007343,0.003903,0.099133,262.914703,13.393514,0.991328,-135.044174,0.099297,0.000000
92.570007,59.088066,-135.088654,0.007343,0.003903,0.099133,262.836853,13.389547,0.991328,-135.088654,0.099297,0.000000
92.800003,59.071312,-135.177612,0.007334,0.003903,0.099133,262.762329,13.385751,0.991328,-135.177612,0.099297,0.000000
93.030006,59.037796,-135.088654,0.007343,0.003903,0.099133,262.613220,13.378156,0.991328,-135.088654,0.099297,0.000000
93.260002,59.027740,-135.044174,0.007334,0.003903,0.099133,262.568512,13.375876,0.991328,-135.044174,0.099297,0.000000
93.490005,59.010612,-135.044174,0.007351,0.003903,0.099133,262.492310,13.371996,0.991328,-135.044174,0.099297,0.000000
93.720001,59.000931,-135.133133,0.007351,0.003903,0.099133,262.449249,13.369802,0.991328,-135.133133,0.099297,0.000000
93.950005,58.983055,-135.177612,0.007338,0.003903,0.099133,262.369720,13.365752,0.991328,-135.177612,0.099297,0.000000
94.180008,58.956993,-135.177612,0.007338,0.003903,0.099133,262.253815,13.359845,0.991328,-135.177612,0.099297,0.000000
94.410004,58.954010,-135.133133,0.007343,0.003903,0.099133,262.240540,13.359170,0.991328,-135.133133,0.099297,0.000000
94.640007,58.929436,-135.088654,0.007343,0.003903,0.099133,262.131226,13.353601,0.991328,-135.088654,0.099297,0.000000
94.870003,58.924225,-135.222092,0.007343,0.003903,0.099133,262.108032,13.352420,0.991328,-135.222092,0.099297,0.000000
95.100006,58.905602,-135.133133,0.007343,0.003903,0.099133,262.025208,13.348201,0.991328,-135.133133,0.099297,0.000000
95.330002,58.896294,-135.177612,0.007338,0.003903,0.099133,261.983795,13.346090,0.991328,-135.177612,0.099297,0.000000
95.560005,58.881027,-135.133133,0.007343,0.003903,0.099133,261.915894,13.342631,0.991328,-135.133133,0.099297,0.000000
95.790001,58.862038,-135.177612,0.007343,0.003903,0.099133,261.831421,13.338328,0.991328,-135.177612,0.099297,0.000000
96.020004,58.846024,-135.222092,0.007351,0.003903,0.099133,261.760193,13.334700,0.991328,-135.222092,0.099297,0.000000
96.250008,58.832993,-135.266571,0.007343,0.003903,0.099133,261.702209,13.331747,0.991328,-135.266571,0.099297,0.000000
96.480003,58.813255,-135.177612,0.007343,0.003903,0.099133,261.614410,13.327273,0.991328,-135.177612,0.099297,0.000000
96.710007,58.798363,-135.177612,0.007343,0.003903,0.099133,261.548187,13.323899,0.991328,-135.177612,0.099297,0.000000
96.940002,58.796867,-135.222092,0.007351,0.003903,0.099133,261.541534,13.323561,0.991328,-135.222092,0.099297,0.000000
97.170006,58.781227,-135.222092,0.007343,0.003903,0.099133,261.471954,13.320017,0.991328,-135.222092,0.099297,0.000000
97.400002,58.754791,-135.266571,0.007338,0.003903,0.099133,261.354370,13.314026,0.991328,-135.266571,0.099297,0.000000
97.630005,58.742500,-135.266571,0.007347,0.003903,0.099133,261.299683,13.311240,0.991328,-135.266571,0.099297,0.000000
97.860008,58.738777,-135.266571,0.007334,0.003903,0.099133,261.283142,13.310397,0.991328,-135.266571,0.099297,0.000000
97.900002,58.736176,-135.311050,0.007338,0.003903,0.099133,261.271545,13.309808,0.991328,-135.311050,0.099297,0.000000