File: Data/compression 8/AutoHeating-12-8-1-3-240328_03282024_152657.csv
Time (sec),S:Load (lbs),S:HL1 (DIM),S:LVDT (in),S:Position (in),Ch:Position (mm),Ch:Load (N),Ch:Stress (MPa),Ch:Strain (mm/mm),Ch:HL1 (DIM),Set Point (),Cycles ()
0.110000,-0.016014,-137.045807,0.000017,-0.000000,-0.000000,-0.071234,-0.003629,-0.000000,-137.045807,0.000191,0.000000
0.370000,-0.010803,-137.090286,-0.000004,-0.000000,-0.000000,-0.048055,-0.002448,-0.000000,-137.090286,0.000191,0.000000
0.630000,-0.007820,-137.045807,0.000004,0.000132,0.003356,-0.034786,-0.001772,0.033564,-137.045807,0.004267,0.000000
0.890000,-0.014900,-137.090286,0.000155,0.000297,0.007536,-0.066279,-0.003376,0.075365,-137.090286,0.008586,0.000000
1.150000,0.011169,-137.134766,0.000323,0.000462,0.011725,0.049684,0.002531,0.117252,-137.134766,0.012922,0.000000
1.410000,-0.017876,-137.090286,0.000513,0.000640,0.016261,-0.079515,-0.004051,0.162607,-137.090286,0.017258,0.000000
1.670000,-0.026810,-137.134766,0.000668,0.000804,0.020423,-0.119255,-0.006075,0.204233,-137.134766,0.021594,0.000000
1.930000,0.010422,-137.045807,0.000836,0.000975,0.024760,0.046358,0.002362,0.247596,-137.045807,0.025913,0.000000
2.190000,-0.042076,-137.090286,0.001039,0.001151,0.029226,-0.187164,-0.009535,0.292258,-137.090286,0.030249,0.000000
2.450000,-0.015640,-137.090286,0.001190,0.001322,0.033579,-0.069571,-0.003544,0.335792,-137.090286,0.034585,0.000000
2.710000,0.023460,-137.090286,0.001354,0.001482,0.037655,0.104357,0.005316,0.376552,-137.090286,0.038921,0.000000
2.970000,-0.009308,-137.134766,0.001531,0.001662,0.042208,-0.041403,-0.002109,0.422080,-137.134766,0.043240,0.000000
3.230000,0.004097,-137.134766,0.001707,0.001832,0.046527,0.018224,0.000928,0.465270,-137.134766,0.047576,0.000000
3.490000,0.007820,-137.179260,0.001871,0.001998,0.050750,0.034786,0.001772,0.507501,-137.179260,0.051912,0.000000
3.750000,-0.038727,-137.134766,0.002057,0.002173,0.055191,-0.172265,-0.008776,0.551906,-137.134766,0.056248,0.000000
4.010000,-0.007446,-137.179260,0.002220,0.002342,0.059475,-0.033123,-0.001687,0.594747,-137.179260,0.060567,0.000000
4.270000,-0.011917,-137.223740,0.002397,0.002515,0.063871,-0.053010,-0.002700,0.638712,-137.223740,0.064903,0.000000
4.530000,-0.008568,-137.223740,0.002574,0.002677,0.067991,-0.038112,-0.001941,0.679907,-137.223740,0.069239,0.000000
4.790000,-0.001122,-137.179260,0.002755,0.002856,0.072544,-0.004989,-0.000254,0.725436,-137.179260,0.073576,0.000000
5.050000,0.028297,-137.223740,0.002923,0.003024,0.076802,0.125873,0.006412,0.768016,-137.223740,0.077894,0.000000
5.310000,-0.007820,-137.223740,0.003113,0.003195,0.081164,-0.034786,-0.001772,0.811637,-137.223740,0.082231,0.000000
5.570000,0.004837,-137.223740,0.003268,0.003362,0.085387,0.021516,0.001096,0.853872,-137.223740,0.086567,0.000000
5.830000,-0.002609,-137.179260,0.003432,0.003534,0.089767,-0.011607,-0.000591,0.897667,-137.179260,0.090886,0.000000
6.090000,-0.056229,-137.223740,0.003622,0.003706,0.094129,-0.250117,-0.012742,0.941288,-137.223740,0.095222,0.000000
6.350000,-0.009682,-137.223740,0.003781,0.003879,0.098526,-0.043066,-0.002194,0.985257,-137.223740,0.099558,0.000000
6.610000,0.013031,-137.223740,0.003954,0.004045,0.102749,0.057965,0.002953,1.027489,-137.223740,0.103894,0.000000
6.870000,-0.005959,-137.268219,0.004135,0.004218,0.107128,-0.026505,-0.001350,1.071284,-137.268219,0.108213,0.000000
7.130000,0.015266,-137.223740,0.004290,0.004389,0.111473,0.067908,0.003459,1.114735,-137.223740,0.112549,0.000000
7.390000,0.007820,-137.312698,0.004475,0.004556,0.115723,0.034786,0.001772,1.157228,-137.312698,0.116885,0.000000
7.650001,-0.025696,-137.312698,0.004639,0.004727,0.120076,-0.114301,-0.005823,1.200762,-137.312698,0.121221,0.000000
7.910000,0.011917,-137.312698,0.004816,0.004899,0.124438,0.053010,0.002700,1.244383,-137.312698,0.125540,0.000000
8.170000,-0.013779,-137.268219,0.004997,0.005078,0.128974,-0.061291,-0.003122,1.289741,-137.268219,0.129876,0.000000
8.430000,-0.046921,-137.268219,0.005165,0.005239,0.133076,-0.208714,-0.010632,1.330762,-137.268219,0.134212,0.000000
8.690001,0.030533,-137.312698,0.005333,0.005409,0.137386,0.135817,0.006919,1.373860,-137.312698,0.138548,0.000000
8.950001,0.023087,-137.312698,0.005510,0.005584,0.141835,0.102694,0.005231,1.418348,-137.312698,0.142867,0.000000
9.210000,-0.009682,-137.268219,0.005700,0.005754,0.146162,-0.043066,-0.002194,1.461624,-137.268219,0.147203,0.000000
9.470000,0.019737,-137.357178,0.005859,0.005921,0.150386,0.087796,0.004473,1.503856,-137.357178,0.151539,0.000000
9.730000,0.021225,-137.312698,0.006040,0.006095,0.154817,0.094413,0.004810,1.548173,-137.312698,0.155858,0.000000
9.990001,0.005959,-137.357178,0.006200,0.006263,0.159075,0.026505,0.001350,1.590754,-137.357178,0.160194,0.000000
10.250001,0.065163,-137.401657,0.006368,0.006431,0.163359,0.289858,0.014766,1.633595,-137.401657,0.164530,0.000000
10.510000,0.399551,-137.357178,0.006545,0.006611,0.167912,1.777293,0.090540,1.679123,-137.357178,0.168866,0.000000
10.770000,0.623726,-137.401657,0.006618,-0.000006,-0.000148,2.774471,0.141338,-0.001476,-137.401657,0.000052,0.000000
11.030001,0.587975,-137.357178,0.006622,-0.000006,-0.000156,2.615441,0.133237,-0.001563,-137.357178,0.000052,0.000000
11.290001,0.590950,-137.446136,0.006614,-0.000006,-0.000156,2.628677,0.133911,-0.001563,-137.446136,0.000286,0.000000
11.550000,0.552971,-137.357178,0.006627,-0.000006,-0.000156,2.459737,0.125305,-0.001563,-137.357178,0.000720,0.000000
11.810000,0.671013,-137.401657,0.006627,0.000010,0.000243,2.984814,0.152054,0.002426,-137.401657,0.001153,0.000000
12.070001,0.769318,-137.401657,0.006627,0.000029,0.000728,3.422096,0.174330,0.007282,-137.401657,0.001587,0.000000
12.330001,0.907097,-137.357178,0.006666,0.000050,0.001266,4.034968,0.205551,0.012660,-137.357178,0.002020,0.000000
12.590000,0.982315,-137.401657,0.006674,0.000064,0.001630,4.369555,0.222596,0.016302,-137.401657,0.002454,0.000000
12.850000,1.029236,-137.357178,0.006691,0.000081,0.002064,4.578269,0.233228,0.020639,-137.357178,0.002888,0.000000
13.110001,1.154350,-137.446136,0.006700,0.000096,0.002445,5.134807,0.261580,0.024454,-137.446136,0.003321,0.000000
13.370001,1.296600,-137.446136,0.006726,0.000115,0.002914,5.767566,0.293814,0.029140,-137.446136,0.003755,0.000000
13.630001,1.412407,-137.446136,0.006730,0.000128,0.003252,6.282700,0.320056,0.032520,-137.446136,0.004189,0.000000
13.890000,1.547951,-137.446136,0.006748,0.000144,0.003668,6.885629,0.350771,0.036683,-137.446136,0.004622,0.000000
14.150001,1.660408,-137.401657,0.006773,0.000161,0.004102,7.385864,0.376254,0.041021,-137.401657,0.005056,0.000000
14.410001,1.806007,-137.490616,0.006791,0.000181,0.004605,8.033522,0.409247,0.046047,-137.490616,0.005490,0.000000
14.670001,1.883087,-137.490616,0.006795,0.000197,0.005004,8.376390,0.426714,0.050036,-137.490616,0.005914,0.000000
14.930000,1.948997,-137.446136,0.006812,0.000211,0.005368,8.669574,0.441649,0.053681,-137.446136,0.006348,0.000000
15.190001,2.185455,-137.535095,0.006821,0.000235,0.005958,9.721391,0.495231,0.059578,-137.535095,0.006782,0.000000
15.450001,2.296043,-137.446136,0.006851,0.000251,0.006374,10.213311,0.520291,0.063741,-137.446136,0.007215,0.000000
15.710001,2.350784,-137.490616,0.006860,0.000263,0.006678,10.456811,0.532695,0.066777,-137.490616,0.007649,0.000000
15.970001,2.547401,-137.535095,0.006873,0.000282,0.007155,11.331408,0.577249,0.071546,-137.535095,0.008083,0.000000
16.230001,2.722412,-137.446136,0.006898,0.000303,0.007692,12.109894,0.616907,0.076920,-137.446136,0.008516,0.000000
16.490002,2.792419,-137.579575,0.006903,0.000317,0.008039,12.421302,0.632771,0.080391,-137.579575,0.008950,0.000000
16.750000,2.880302,-137.490616,0.006929,0.000333,0.008447,12.812225,0.652686,0.084468,-137.490616,0.009383,0.000000
17.010000,3.009514,-137.535095,0.006937,0.000350,0.008889,13.386986,0.681966,0.088888,-137.535095,0.009817,0.000000
17.270000,3.227348,-137.535095,0.006950,0.000372,0.009444,14.355963,0.731328,0.094441,-137.535095,0.010251,0.000000
17.530001,3.297356,-137.535095,0.006976,0.000386,0.009808,14.667371,0.747191,0.098082,-137.535095,0.010684,0.000000
17.790001,3.461945,-137.579575,0.006993,0.000403,0.010242,15.399499,0.784488,0.102419,-137.579575,0.011118,0.000000
18.050001,3.582596,-137.579575,0.007011,0.000422,0.010710,15.936182,0.811828,0.107101,-137.579575,0.011551,0.000000
18.310001,3.738243,-137.624069,0.007032,0.000442,0.011222,16.628536,0.847098,0.112218,-137.624069,0.011985,0.000000
18.570002,3.742714,-137.579575,0.007045,0.000457,0.011612,16.648422,0.848111,0.116121,-137.579575,0.012419,0.000000
18.830002,3.895012,-137.579575,0.007062,0.000475,0.012072,17.325878,0.882622,0.120715,-137.579575,0.012852,0.000000
19.090000,4.081200,-137.579575,0.007062,0.000493,0.012523,18.154083,0.924813,0.125227,-137.579575,0.013286,0.000000
19.350000,4.186951,-137.535095,0.007080,0.000509,0.012939,18.624487,0.948777,0.129390,-137.535095,0.013719,0.000000
19.610001,4.093864,-137.624069,0.007101,0.000516,0.013104,18.210419,0.927683,0.131037,-137.624069,0.014153,0.000000
19.870001,4.302391,-137.624069,0.007118,0.000535,0.013589,19.137991,0.974936,0.135893,-137.624069,0.014587,0.000000
20.130001,4.602150,-137.624069,0.007136,0.000560,0.014222,20.471386,1.042862,0.142225,-137.624069,0.015020,0.000000
20.390001,4.646461,-137.624069,0.007144,0.000575,0.014613,20.668493,1.052903,0.146127,-137.624069,0.015454,0.000000
20.650002,4.716843,-137.624069,0.007166,0.000591,0.015012,20.981564,1.068852,0.150117,-137.624069,0.015887,0.000000
20.910002,4.793175,-137.668549,0.007174,0.000606,0.015384,21.321106,1.086149,0.153845,-137.668549,0.016321,0.000000
21.170000,4.968567,-137.579575,0.007192,0.000624,0.015844,22.101290,1.125893,0.158439,-137.579575,0.016755,0.000000
21.430000,5.099640,-137.668549,0.007217,0.000641,0.016278,22.684332,1.155595,0.162777,-137.668549,0.017188,0.000000
21.690001,5.067612,-137.668549,0.007226,0.000653,0.016590,22.541862,1.148337,0.165900,-137.668549,0.017622,0.000000
21.950001,5.467171,-137.668549,0.007248,0.000676,0.017171,24.319189,1.238879,0.171709,-137.668549,0.018055,0.000000
22.210001,5.474617,-137.713028,0.007265,0.000692,0.017579,24.352312,1.240566,0.175786,-137.713028,0.018489,0.000000
22.470001,5.633247,-137.713028,0.007274,0.000711,0.018064,25.057936,1.276512,0.180642,-137.713028,0.018923,0.000000
22.730001,5.646652,-137.713028,0.007304,0.000726,0.018437,25.117563,1.279550,0.184370,-137.713028,0.019356,0.000000
22.990002,5.851456,-137.713028,0.007308,0.000746,0.018949,26.028574,1.325959,0.189487,-137.713028,0.019790,0.000000
23.250002,5.951630,-137.713028,0.007317,0.000763,0.019391,26.474171,1.348659,0.193912,-137.713028,0.020223,0.000000
23.510000,5.924446,-137.801987,0.007343,0.000778,0.019764,26.353252,1.342499,0.197640,-137.801987,0.020648,0.000000
23.770000,5.954605,-137.713028,0.007338,0.000790,0.020076,26.487406,1.349333,0.200762,-137.713028,0.021082,0.000000
24.030001,6.375015,-137.668549,0.007373,0.000816,0.020735,28.357485,1.444599,0.207352,-137.668549,0.021516,0.000000
24.290001,6.374641,-137.757507,0.007386,0.000831,0.021100,28.355822,1.444514,0.210997,-137.757507,0.021949,0.000000
24.550001,6.387306,-137.757507,0.007407,0.000846,0.021499,28.412157,1.447384,0.214986,-137.757507,0.022383,0.000000
24.810001,6.349319,-137.713028,0.007407,0.000861,0.021863,28.243183,1.438776,0.218627,-137.713028,0.022816,0.000000
25.070002,6.610352,-137.713028,0.007433,0.000878,0.022296,29.404312,1.497927,0.222964,-137.713028,0.023250,0.000000
25.330002,6.711639,-137.846466,0.007450,0.000893,0.022687,29.854862,1.520879,0.226867,-137.846466,0.023684,0.000000
25.590002,6.806595,-137.757507,0.007455,0.000908,0.023068,30.277246,1.542396,0.230682,-137.757507,0.024117,0.000000
25.850000,7.072838,-137.757507,0.007472,0.000932,0.023675,31.461554,1.602728,0.236753,-137.757507,0.024551,0.000000
26.110001,7.162582,-137.846466,0.007480,0.000951,0.024152,31.860758,1.623064,0.241522,-137.846466,0.024985,0.000000
26.370001,7.202423,-137.757507,0.007511,0.000967,0.024551,32.037979,1.632092,0.245511,-137.757507,0.025418,0.000000
26.630001,7.155876,-137.846466,0.007524,0.000980,0.024881,31.830927,1.621545,0.248808,-137.846466,0.025852,0.000000
26.890001,7.325310,-137.801987,0.007532,0.000999,0.025366,32.584606,1.659939,0.253664,-137.801987,0.026286,0.000000
27.150002,7.505539,-137.801987,0.007562,0.001017,0.025835,33.386303,1.700779,0.258346,-137.801987,0.026719,0.000000
27.410002,7.515221,-137.890945,0.007558,0.001032,0.026207,33.429371,1.702973,0.262074,-137.890945,0.027153,0.000000
27.670002,7.746094,-137.757507,0.007571,0.001051,0.026693,34.456345,1.755290,0.266930,-137.757507,0.027586,0.000000
27.930002,7.949776,-137.890945,0.007597,0.001073,0.027266,35.362370,1.801445,0.272656,-137.890945,0.028020,0.000000
28.190001,7.841415,-137.801987,0.007614,0.001088,0.027630,34.880360,1.776890,0.276297,-137.801987,0.028454,0.000000
28.450001,7.866364,-137.890945,0.007627,0.001102,0.027985,34.991333,1.782543,0.279851,-137.890945,0.028887,0.000000
28.710001,7.870461,-137.846466,0.007636,0.001116,0.028341,35.009556,1.783472,0.283409,-137.846466,0.029321,0.000000
28.970001,8.220863,-137.801987,0.007657,0.001136,0.028861,36.568226,1.862874,0.288613,-137.801987,0.029755,0.000000
29.230001,8.230545,-137.846466,0.007662,0.001152,0.029269,36.611294,1.865068,0.292690,-137.846466,0.030188,0.000000
29.490002,8.225708,-137.846466,0.007679,0.001167,0.029633,36.589775,1.863972,0.296331,-137.846466,0.030622,0.000000
29.750002,8.755592,-137.846466,0.007696,0.001196,0.030379,38.946819,1.984046,0.303787,-137.846466,0.031055,0.000000
30.010002,8.465889,-137.979904,0.007713,0.001206,0.030630,37.658154,1.918398,0.306304,-137.979904,0.031489,0.000000
30.270002,8.537758,-137.890945,0.007718,0.001223,0.031064,37.977844,1.934684,0.310638,-137.890945,0.031923,0.000000
30.530001,8.508339,-137.935425,0.007748,0.001236,0.031393,37.846981,1.928017,0.313934,-137.935425,0.032356,0.000000
30.790001,8.813309,-137.890945,0.007743,0.001256,0.031905,39.203556,1.997124,0.319052,-137.890945,0.032790,0.000000
31.050001,8.930237,-137.935425,0.007769,0.001273,0.032330,39.723679,2.023621,0.323302,-137.935425,0.033223,0.000000
31.310001,8.972687,-137.979904,0.007778,0.001288,0.032720,39.912502,2.033240,0.327204,-137.979904,0.033657,0.000000
31.570002,9.091469,-137.935425,0.007787,0.001306,0.033171,40.440872,2.060156,0.331712,-137.935425,0.034091,0.000000
31.830002,9.390114,-137.979904,0.007808,0.001330,0.033787,41.769314,2.127830,0.337870,-137.979904,0.034524,0.000000
32.090000,9.164459,-137.935425,0.007821,0.001340,0.034039,40.765553,2.076696,0.340387,-137.935425,0.034958,0.000000
32.350002,9.161102,-138.024384,0.007838,0.001356,0.034438,40.750618,2.075935,0.344376,-138.024384,0.035391,0.000000
32.610001,9.349899,-137.979904,0.007834,0.001376,0.034940,41.590427,2.118717,0.349403,-137.979904,0.035816,0.000000
32.870003,9.557312,-137.979904,0.007869,0.001394,0.035418,42.513046,2.165718,0.354175,-137.979904,0.036250,0.000000
33.130001,9.556564,-138.024384,0.007873,0.001408,0.035764,42.509720,2.165548,0.357642,-138.024384,0.036684,0.000000
33.390003,9.651894,-137.979904,0.007877,0.001426,0.036233,42.933765,2.187150,0.362328,-137.979904,0.037117,0.000000
33.650002,9.937500,-137.979904,0.007912,0.001448,0.036788,44.204208,2.251870,0.367877,-137.979904,0.037551,0.000000
33.910000,9.862282,-138.024384,0.007912,0.001463,0.037160,43.869621,2.234825,0.371605,-138.024384,0.037984,0.000000
34.170002,9.846642,-138.024384,0.007929,0.001480,0.037586,43.800049,2.231281,0.375855,-138.024384,0.038418,0.000000
34.430000,9.776634,-138.113358,0.007938,0.001491,0.037880,43.488640,2.215417,0.378804,-138.113358,0.038852,0.000000
34.690002,10.077515,-138.024384,0.007942,0.001513,0.038435,44.827023,2.283597,0.384352,-138.024384,0.039285,0.000000
34.950001,10.020538,-138.068878,0.007946,0.001527,0.038774,44.573582,2.270686,0.387736,-138.068878,0.039719,0.000000
35.210003,10.203377,-138.068878,0.007959,0.001544,0.039216,45.386887,2.312118,0.392161,-138.068878,0.040152,0.000000
35.470001,10.184761,-138.024384,0.007989,0.001559,0.039598,45.304081,2.307900,0.395976,-138.024384,0.040586,0.000000
35.730003,10.431641,-138.113358,0.008002,0.001579,0.040109,46.402256,2.363844,0.401093,-138.113358,0.041020,0.000000
35.990002,10.373924,-138.068878,0.008006,0.001594,0.040482,46.145519,2.350765,0.404821,-138.068878,0.041453,0.000000
36.250000,10.325516,-138.068878,0.008028,0.001607,0.040829,45.930187,2.339795,0.408288,-138.068878,0.041887,0.000000
36.510002,10.734383,-138.113358,0.008028,0.001631,0.041427,47.748920,2.432446,0.414272,-138.113358,0.042320,0.000000
36.770000,10.817421,-138.113358,0.008067,0.001650,0.041921,48.118290,2.451262,0.419215,-138.113358,0.042754,0.000000
37.030003,10.631233,-138.157837,0.008058,0.001663,0.042242,47.290089,2.409072,0.422425,-138.157837,0.043188,0.000000
37.290001,10.771614,-138.068878,0.008075,0.001682,0.042711,47.914532,2.440883,0.427106,-138.068878,0.043621,0.000000
37.550003,10.988708,-138.113358,0.008088,0.001702,0.043231,48.880219,2.490077,0.432311,-138.113358,0.044055,0.000000
37.810001,10.829704,-138.157837,0.008093,0.001715,0.043552,48.172932,2.454046,0.435520,-138.157837,0.044489,0.000000
38.070004,10.838646,-138.157837,0.008110,0.001731,0.043977,48.212704,2.456072,0.439771,-138.157837,0.044922,0.000000
38.330002,10.969345,-138.157837,0.008127,0.001751,0.044471,48.794083,2.485689,0.444714,-138.157837,0.045356,0.000000
38.590000,11.238197,-138.113358,0.008136,0.001772,0.045000,49.989998,2.546612,0.450001,-138.113358,0.045789,0.000000
38.850002,11.086273,-138.202316,0.008144,0.001785,0.045330,49.314205,2.512185,0.453298,-138.202316,0.046223,0.000000
39.110001,11.238571,-138.202316,0.008162,0.001803,0.045807,49.991661,2.546697,0.458067,-138.202316,0.046657,0.000000
39.370003,11.282143,-138.157837,0.008183,0.001820,0.046232,50.185478,2.556570,0.462317,-138.157837,0.047090,0.000000
39.630001,11.387894,-138.202316,0.008183,0.001840,0.046726,50.655880,2.580534,0.467260,-138.202316,0.047524,0.000000
39.890003,11.333900,-138.157837,0.008205,0.001856,0.047142,50.415707,2.568299,0.471424,-138.157837,0.047958,0.000000
40.150002,11.268730,-138.246796,0.008209,0.001872,0.047550,50.125816,2.553531,0.475500,-138.246796,0.048391,0.000000
40.410004,11.565887,-138.246796,0.008226,0.001892,0.048053,51.447636,2.620867,0.480530,-138.246796,0.048825,0.000000
40.670002,11.568123,-138.246796,0.008235,0.001908,0.048461,51.457581,2.621374,0.484607,-138.246796,0.049259,0.000000
40.930000,11.139145,-138.246796,0.008248,0.001915,0.048634,49.549393,2.524166,0.486340,-138.246796,0.049692,0.000000
41.190002,11.371880,-138.157837,0.008257,0.001936,0.049180,50.584648,2.576905,0.491802,-138.157837,0.050126,0.000000
41.450001,11.866020,-138.246796,0.008269,0.001960,0.049779,52.782696,2.688879,0.497786,-138.246796,0.050559,0.000000
41.710003,11.703667,-138.202316,0.008274,0.001974,0.050152,52.060509,2.652089,0.501518,-138.202316,0.050984,0.000000
41.970001,11.608711,-138.246796,0.008304,0.001992,0.050585,51.638126,2.630571,0.505851,-138.246796,0.051418,0.000000
42.230003,11.538330,-138.291275,0.008300,0.002005,0.050923,51.325054,2.614623,0.509235,-138.291275,0.051851,0.000000
42.490002,11.924484,-138.246796,0.008317,0.002027,0.051478,53.042755,2.702127,0.514784,-138.246796,0.052285,0.000000
42.750004,11.765106,-138.291275,0.008326,0.002039,0.051799,52.333805,2.666011,0.517993,-138.291275,0.052719,0.000000
43.010002,11.561790,-138.291275,0.008330,0.002052,0.052129,51.429413,2.619939,0.521290,-138.291275,0.053152,0.000000
43.270000,12.201530,-138.335754,0.008347,0.002074,0.052675,54.275120,2.764906,0.526751,-138.335754,0.053586,0.000000
43.530003,12.169502,-138.335754,0.008360,0.002091,0.053118,54.132648,2.757649,0.531176,-138.335754,0.054020,0.000000
43.790001,12.233925,-138.246796,0.008369,0.002110,0.053586,54.419216,2.772247,0.535858,-138.246796,0.054453,0.000000
44.050003,12.063004,-138.335754,0.008382,0.002124,0.053959,53.658920,2.733516,0.539586,-138.335754,0.054887,0.000000
44.310001,12.315842,-138.291275,0.008382,0.002145,0.054470,54.783600,2.790810,0.544703,-138.291275,0.055320,0.000000
44.570004,12.325897,-138.335754,0.008407,0.002162,0.054913,54.828331,2.793088,0.549128,-138.335754,0.055754,0.000000
44.830002,12.217911,-138.335754,0.008403,0.002176,0.055277,54.347980,2.768618,0.552769,-138.335754,0.056188,0.000000
45.090004,11.768829,-138.380234,0.008420,0.002183,0.055459,52.350368,2.666855,0.554589,-138.380234,0.056621,0.000000
45.350002,12.683746,-138.424713,0.008425,0.002215,0.056257,56.420120,2.874178,0.562568,-138.424713,0.057055,0.000000
45.610001,12.472984,-138.335754,0.008442,0.002230,0.056630,55.482605,2.826419,0.566296,-138.335754,0.057488,0.000000
45.870003,12.357552,-138.335754,0.008459,0.002245,0.057029,54.969135,2.800261,0.570285,-138.335754,0.057922,0.000000
46.130001,12.294617,-138.380234,0.008464,0.002260,0.057393,54.689186,2.786000,0.573930,-138.380234,0.058356,0.000000
46.390003,12.426811,-138.380234,0.008481,0.002277,0.057844,55.277218,2.815956,0.578438,-138.380234,0.058789,0.000000
46.650002,12.495331,-138.469208,0.008476,0.002292,0.058208,55.582008,2.831482,0.582083,-138.469208,0.059223,0.000000
46.910004,12.554161,-138.380234,0.008494,0.002306,0.058581,55.843697,2.844813,0.585811,-138.380234,0.059656,0.000000
47.170002,12.982765,-138.469208,0.008511,0.002331,0.059206,57.750225,2.941937,0.592056,-138.469208,0.060090,0.000000
47.430004,12.843124,-138.424713,0.008515,0.002349,0.059656,57.129070,2.910294,0.596564,-138.424713,0.060523,0.000000
47.690002,12.929146,-138.380234,0.008537,0.002365,0.060081,57.511711,2.929786,0.600814,-138.380234,0.060957,0.000000
47.950001,12.701996,-138.469208,0.008537,0.002378,0.060402,56.501301,2.878313,0.604024,-138.469208,0.061391,0.000000
48.210003,12.826736,-138.380234,0.008550,0.002398,0.060905,57.056171,2.906580,0.609050,-138.380234,0.061824,0.000000
48.470001,12.961166,-138.424713,0.008558,0.002413,0.061296,57.654148,2.937042,0.612956,-138.424713,0.062258,0.000000
48.730003,12.884087,-138.469208,0.008563,0.002430,0.061720,57.311279,2.919576,0.617203,-138.469208,0.062691,0.000000
48.990002,13.301514,-138.469208,0.008576,0.002449,0.062215,59.168087,3.014166,0.622146,-138.469208,0.063125,0.000000
49.250004,13.652664,-138.513687,0.008589,0.002472,0.062787,60.730083,3.093738,0.627872,-138.513687,0.063559,0.000000
49.510002,13.454185,-138.469208,0.008597,0.002488,0.063186,59.847206,3.048762,0.631862,-138.469208,0.063992,0.000000
49.770000,13.262413,-138.469208,0.008610,0.002502,0.063559,58.994160,3.005306,0.635590,-138.469208,0.064426,0.000000
50.030003,13.109001,-138.558167,0.008614,0.002516,0.063906,58.311749,2.970542,0.639057,-138.558167,0.064860,0.000000
50.290001,13.561432,-138.469208,0.008627,0.002535,0.064400,60.324261,3.073064,0.644000,-138.469208,0.065293,0.000000
50.550003,13.561432,-138.513687,0.008640,0.002551,0.064790,60.324261,3.073064,0.647902,-138.513687,0.065718,0.000000
50.810001,13.328697,-138.513687,0.008636,0.002562,0.065085,59.289005,3.020326,0.650851,-138.513687,0.066152,0.000000
51.070004,14.246597,-138.513687,0.008662,0.002593,0.065866,63.372028,3.228325,0.658659,-138.513687,0.066585,0.000000
51.330002,13.874222,-138.602646,0.008653,0.002605,0.066169,61.715622,3.143944,0.661694,-138.602646,0.067019,0.000000
51.590004,13.815758,-138.513687,0.008679,0.002622,0.066603,61.455559,3.130695,0.666028,-138.513687,0.067453,0.000000
51.850002,13.661972,-138.602646,0.008679,0.002634,0.066915,60.771488,3.095847,0.669151,-138.602646,0.067886,0.000000
52.110001,14.013489,-138.513687,0.008696,0.002653,0.067392,62.335110,3.175502,0.673919,-138.513687,0.068320,0.000000
52.370003,14.154251,-138.558167,0.008718,0.002671,0.067843,62.961254,3.207399,0.678431,-138.558167,0.068754,0.000000
52.630001,14.232445,-138.602646,0.008701,0.002687,0.068242,63.309074,3.225118,0.682420,-138.602646,0.069187,0.000000
52.890003,14.417885,-138.513687,0.008727,0.002705,0.068702,64.133957,3.267139,0.687015,-138.513687,0.069621,0.000000
53.150002,14.867714,-138.647125,0.008727,0.002728,0.069291,66.134895,3.369072,0.692912,-138.647125,0.070054,0.000000
53.410004,14.402992,-138.647125,0.008752,0.002739,0.069560,64.067711,3.263765,0.695599,-138.647125,0.070488,0.000000
53.670002,14.335968,-138.602646,0.008757,0.002754,0.069942,63.769569,3.248577,0.699418,-138.602646,0.070922,0.000000
53.930004,14.576515,-138.602646,0.008748,0.002771,0.070393,64.839577,3.303086,0.703926,-138.602646,0.071355,0.000000
54.190002,14.905327,-138.691605,0.008765,0.002790,0.070878,66.302208,3.377595,0.708782,-138.691605,0.071789,0.000000
54.450001,14.925430,-138.691605,0.008774,0.002807,0.071286,66.391632,3.382151,0.712858,-138.691605,0.072223,0.000000
54.710003,14.900108,-138.647125,0.008770,0.002824,0.071737,66.278992,3.376413,0.717370,-138.647125,0.072656,0.000000
54.970001,15.501122,-138.647125,0.008800,0.002847,0.072309,68.952431,3.512604,0.723093,-138.647125,0.073090,0.000000
55.230003,15.358498,-138.602646,0.008804,0.002862,0.072691,68.318008,3.480285,0.726908,-138.602646,0.073523,0.000000
55.490002,15.218117,-138.647125,0.008826,0.002877,0.073072,67.693565,3.448474,0.730723,-138.647125,0.073957,0.000000
55.750004,15.117577,-138.691605,0.008817,0.002890,0.073411,67.246338,3.425692,0.734107,-138.691605,0.074391,0.000000
56.010002,15.500000,-138.647125,0.008830,0.002910,0.073914,68.947441,3.512350,0.739137,-138.647125,0.074824,0.000000
56.270004,15.527931,-138.736084,0.008847,0.002925,0.074287,69.071686,3.518679,0.742865,-138.736084,0.075258,0.000000
56.530003,15.796783,-138.691605,0.008839,0.002942,0.074720,70.267601,3.579602,0.747203,-138.691605,0.075691,0.000000
56.790001,15.784492,-138.647125,0.008856,0.002956,0.075093,70.212929,3.576817,0.750931,-138.647125,0.076125,0.000000
57.050003,16.213837,-138.736084,0.008877,0.002977,0.075613,72.122749,3.674108,0.756135,-138.736084,0.076559,0.000000
57.310001,16.019836,-138.736084,0.008873,0.002990,0.075934,71.259789,3.630147,0.759341,-138.736084,0.076992,0.000000
57.570004,16.014618,-138.736084,0.008890,0.003005,0.076316,71.236580,3.628964,0.763160,-138.736084,0.077426,0.000000
57.830002,16.675209,-138.691605,0.008895,0.003029,0.076931,74.175034,3.778656,0.769314,-138.691605,0.077859,0.000000
58.090004,17.052048,-138.691605,0.008912,0.003048,0.077426,75.851295,3.864049,0.774257,-138.691605,0.078293,0.000000
58.350002,16.834587,-138.780563,0.008916,0.003061,0.077755,74.883980,3.814772,0.777554,-138.780563,0.078727,0.000000
58.610004,17.134720,-138.691605,0.008921,0.003080,0.078241,76.219040,3.882783,0.782410,-138.691605,0.079160,0.000000
58.870003,17.496666,-138.825043,0.008933,0.003099,0.078709,77.829056,3.964801,0.787092,-138.825043,0.079594,0.000000
59.130001,17.453468,-138.825043,0.008942,0.003113,0.079065,77.636902,3.955013,0.790649,-138.825043,0.080027,0.000000
59.390003,17.634811,-138.780563,0.008955,0.003130,0.079507,78.443558,3.996105,0.795070,-138.780563,0.080461,0.000000
59.650002,17.882812,-138.780563,0.008964,0.003149,0.079984,79.546722,4.052303,0.799843,-138.780563,0.080886,0.000000
59.910004,18.391472,-138.780563,0.008977,0.003168,0.080461,81.809349,4.167567,0.804612,-138.780563,0.081320,0.000000
60.170002,18.461105,-138.825043,0.008981,0.003183,0.080843,82.119095,4.183346,0.808427,-138.825043,0.081753,0.000000
60.430004,18.870346,-138.869522,0.008981,0.003202,0.081328,83.939491,4.276082,0.813283,-138.869522,0.082187,0.000000
60.690002,19.107544,-138.780563,0.009002,0.003219,0.081762,84.994598,4.329831,0.817621,-138.780563,0.082620,0.000000
60.950005,19.532799,-138.825043,0.009015,0.003238,0.082248,86.886230,4.426196,0.822477,-138.825043,0.083054,0.000000
61.210003,19.640411,-138.825043,0.009033,0.003254,0.082664,87.364914,4.450581,0.826640,-138.825043,0.083488,0.000000
61.470001,20.080559,-138.825043,0.009033,0.003274,0.083150,89.322784,4.550320,0.831496,-138.825043,0.083921,0.000000
61.730003,20.500961,-138.914017,0.009028,0.003290,0.083575,91.192833,4.645585,0.835746,-138.914017,0.084355,0.000000
61.990002,20.708374,-138.869522,0.009054,0.003306,0.083974,92.115448,4.692585,0.839736,-138.869522,0.084788,0.000000
62.250004,20.418671,-138.914017,0.009067,0.003314,0.084164,90.826782,4.626937,0.841643,-138.914017,0.085222,0.000000
62.510002,21.332474,-138.869522,0.009071,0.003337,0.084763,94.891586,4.834008,0.847627,-138.869522,0.085656,0.000000
62.770004,22.057480,-138.869522,0.009084,0.003358,0.085291,98.116570,4.998296,0.852915,-138.869522,0.086089,0.000000
63.030003,22.116318,-138.869522,0.009093,0.003372,0.085656,98.378296,5.011629,0.856560,-138.869522,0.086523,0.000000
63.290005,22.543800,-138.825043,0.009115,0.003388,0.086055,100.279831,5.108498,0.860549,-138.825043,0.086957,0.000000
63.550003,22.780258,-138.869522,0.009123,0.003403,0.086428,101.331650,5.162080,0.864277,-138.869522,0.087390,0.000000
63.810001,23.536545,-138.825043,0.009132,0.003425,0.087000,104.695778,5.333457,0.870000,-138.825043,0.087824,0.000000
64.070000,23.910782,-138.869522,0.009136,0.003438,0.087321,106.360466,5.418261,0.873209,-138.869522,0.088257,0.000000
64.330002,24.018394,-138.914017,0.009149,0.003451,0.087659,106.839157,5.442646,0.876589,-138.914017,0.088691,0.000000
64.590004,24.927727,-138.914017,0.009149,0.003473,0.088205,110.884064,5.648704,0.882055,-138.914017,0.089125,0.000000
64.850006,25.422241,-138.914017,0.009162,0.003489,0.088622,113.083778,5.760762,0.886218,-138.914017,0.089558,0.000000
65.110001,26.208687,-138.914017,0.009175,0.003509,0.089116,116.582062,5.938973,0.891161,-138.914017,0.089992,0.000000
65.370003,26.458549,-138.958496,0.009188,0.003523,0.089480,117.693504,5.995593,0.894802,-138.958496,0.090426,0.000000
65.630005,27.301971,-138.958496,0.009192,0.003543,0.089992,121.445236,6.186715,0.899919,-138.958496,0.090859,0.000000
65.889999,27.851967,-138.958496,0.009218,0.003560,0.090434,123.891739,6.311346,0.904344,-138.958496,0.091293,0.000000
66.150002,28.029221,-139.047455,0.009227,0.003575,0.090807,124.680199,6.351512,0.908072,-139.047455,0.091727,0.000000
66.410004,28.003151,-138.958496,0.009235,0.003583,0.091015,124.564240,6.345605,0.910154,-138.958496,0.092160,0.000000
66.670006,29.806923,-138.958496,0.009248,0.003613,0.091778,132.587814,6.754345,0.917784,-138.958496,0.092594,0.000000
66.930000,29.851982,-138.958496,0.009253,0.003624,0.092056,132.788254,6.764556,0.920558,-138.958496,0.093027,0.000000
67.190002,30.560234,-139.002975,0.009261,0.003642,0.092507,135.938705,6.925048,0.925070,-139.002975,0.093461,0.000000
67.450005,30.760941,-139.047455,0.009270,0.003656,0.092871,136.831497,6.970529,0.928711,-139.047455,0.093895,0.000000
67.710007,31.711609,-139.002975,0.009283,0.003672,0.093270,141.060287,7.185954,0.932700,-139.002975,0.094328,0.000000
67.970001,32.362144,-139.047455,0.009296,0.003690,0.093721,143.954010,7.333367,0.937212,-139.047455,0.094762,0.000000
68.230003,33.100189,-139.002975,0.009300,0.003705,0.094103,147.237000,7.500610,0.941027,-139.002975,0.095195,0.000000
68.490005,34.444077,-139.002975,0.009313,0.003728,0.094692,153.214905,7.805140,0.946924,-139.002975,0.095629,0.000000
68.750000,35.029076,-139.047455,0.009313,0.003744,0.095109,155.817108,7.937702,0.951087,-139.047455,0.096054,0.000000
69.010002,36.161087,-139.047455,0.009334,0.003764,0.095594,160.852554,8.194220,0.955943,-139.047455,0.096488,0.000000
69.270004,36.504791,-139.047455,0.009347,0.003777,0.095924,162.381424,8.272104,0.959236,-139.047455,0.096921,0.000000
69.530006,37.153458,-139.091934,0.009343,0.003793,0.096349,165.266830,8.419094,0.963487,-139.091934,0.097355,0.000000
69.790001,38.344681,-139.047455,0.009369,0.003813,0.096860,170.565659,8.689029,0.968604,-139.047455,0.097788,0.000000
70.050003,38.913292,-139.180893,0.009369,0.003829,0.097251,173.094971,8.817879,0.972506,-139.180893,0.098222,0.000000
70.310005,40.068024,-139.002975,0.009382,0.003848,0.097736,178.231476,9.079544,0.977362,-139.002975,0.098656,0.000000
70.570000,41.585442,-139.136414,0.009390,0.003870,0.098300,184.981277,9.423396,0.982998,-139.136414,0.099089,0.000000
70.830002,41.857269,-139.180893,0.009395,0.003885,0.098673,186.190430,9.484993,0.986730,-139.180893,0.099523,0.000000
71.090004,42.662338,-139.047455,0.009403,0.003899,0.099037,189.771561,9.667424,0.990371,-139.047455,0.099956,0.000000
71.350006,43.170624,-139.180893,0.009412,0.003911,0.099332,192.032532,9.782603,0.993319,-139.180893,0.100390,0.000000
71.610001,44.685066,-139.136414,0.009421,0.003933,0.099887,198.769104,10.125781,0.998872,-139.136414,0.100824,0.000000
71.870003,45.448799,-139.136414,0.009442,0.003949,0.100303,202.166351,10.298845,1.003031,-139.136414,0.101257,0.000000
72.130005,45.969749,-139.180893,0.009438,0.003961,0.100598,204.483658,10.416894,1.005980,-139.180893,0.101691,0.000000
72.390007,47.822678,-139.136414,0.009447,0.003988,0.101292,212.725891,10.836774,1.012917,-139.136414,0.102124,0.000000
72.650002,48.800529,-139.180893,0.009455,0.004003,0.101665,217.075592,11.058358,1.016649,-139.180893,0.102558,0.000000
72.910004,49.472290,-139.180893,0.009464,0.004019,0.102073,220.063736,11.210581,1.020726,-139.180893,0.102992,0.000000
73.170006,50.320175,-139.225372,0.009468,0.004033,0.102428,223.835312,11.402715,1.024280,-139.225372,0.103425,0.000000
73.430000,51.528900,-139.225372,0.009477,0.004051,0.102896,229.211990,11.676616,1.028962,-139.225372,0.103859,0.000000
73.690002,52.838531,-139.180893,0.009494,0.004069,0.103365,235.037521,11.973382,1.033647,-139.180893,0.104292,0.000000
73.950005,53.643600,-139.225372,0.009494,0.004085,0.103755,238.618652,12.155814,1.037549,-139.225372,0.104726,0.000000
74.210007,54.982651,-139.136414,0.009503,0.004103,0.104206,244.575043,12.459247,1.042057,-139.136414,0.105160,0.000000
74.470001,56.811745,-139.225372,0.009498,0.004126,0.104795,252.711258,12.873726,1.047954,-139.225372,0.105593,0.000000
74.730003,57.400841,-139.225372,0.009520,0.004137,0.105073,255.331696,13.007216,1.050728,-139.225372,0.106027,0.000000
74.990005,58.106117,-139.269852,0.009524,0.004152,0.105455,258.468933,13.167034,1.054547,-139.269852,0.106460,0.000000
75.250000,59.466019,-139.269852,0.009528,0.004170,0.105923,264.518066,13.475192,1.059229,-139.269852,0.106894,0.000000
75.510002,60.920876,-139.225372,0.009546,0.004188,0.106374,270.989594,13.804868,1.063737,-139.225372,0.107328,0.000000
75.770004,61.803772,-139.269852,0.009541,0.004203,0.106755,274.916901,14.004934,1.067552,-139.269852,0.107761,0.000000
76.030006,62.812531,-139.269852,0.009546,0.004218,0.107128,279.404083,14.233522,1.071284,-139.269852,0.108195,0.000000
76.290001,64.937286,-139.225372,0.009559,0.004242,0.107753,288.855469,14.714999,1.077525,-139.225372,0.108629,0.000000
76.550003,66.340012,-139.314346,0.009559,0.004259,0.108178,295.095123,15.032862,1.081776,-139.314346,0.109062,0.000000
76.810005,67.201691,-139.269852,0.009572,0.004274,0.108550,298.928040,15.228121,1.085504,-139.269852,0.109496,0.000000
77.070007,67.118271,-139.358826,0.009585,0.004269,0.108421,298.556976,15.209218,1.084206,-139.358826,0.108637,0.000000
77.330002,66.554504,-139.358826,0.009589,0.004268,0.108403,296.049225,15.081467,1.084032,-139.358826,0.108421,0.000000
77.590004,66.072647,-139.358826,0.009593,0.004267,0.108386,293.905823,14.972276,1.083858,-139.358826,0.108421,0.000000
77.850006,65.642181,-139.314346,0.009602,0.004267,0.108377,291.990997,14.874731,1.083771,-139.314346,0.108421,0.000000
78.110001,65.276886,-139.314346,0.009593,0.004266,0.108368,290.366089,14.791954,1.083684,-139.314346,0.108421,0.000000
78.370003,64.937653,-139.314346,0.009610,0.004266,0.108368,288.857117,14.715083,1.083684,-139.314346,0.108421,0.000000
78.630005,64.646088,-139.403305,0.009597,0.004266,0.108368,287.560150,14.649013,1.083684,-139.403305,0.108421,0.000000
78.890007,64.376862,-139.403305,0.009610,0.004266,0.108368,286.362579,14.588006,1.083684,-139.403305,0.108421,0.000000
79.150002,64.128860,-139.403305,0.009602,0.004266,0.108368,285.259430,14.531808,1.083684,-139.403305,0.108421,0.000000
79.410004,63.897629,-139.358826,0.009602,0.004266,0.108360,284.230835,14.479409,1.083596,-139.358826,0.108421,0.000000
79.670006,63.691696,-139.314346,0.009602,0.004266,0.108360,283.314819,14.432745,1.083596,-139.314346,0.108421,0.000000
79.930000,63.497696,-139.447784,0.009610,0.004266,0.108360,282.451843,14.388783,1.083596,-139.447784,0.108421,0.000000
80.190002,63.317841,-139.358826,0.009615,0.004266,0.108360,281.651825,14.348028,1.083596,-139.358826,0.108421,0.000000
80.450005,63.159210,-139.403305,0.009610,0.004266,0.108360,280.946198,14.312082,1.083596,-139.403305,0.108421,0.000000
80.710007,62.996109,-139.403305,0.009602,0.004266,0.108360,280.220703,14.275123,1.083596,-139.403305,0.108421,0.000000
80.970001,62.856094,-139.403305,0.009623,0.004266,0.108360,279.597870,14.243395,1.083596,-139.403305,0.108421,0.000000
81.230003,62.714966,-139.447784,0.009615,0.004266,0.108360,278.970093,14.211414,1.083596,-139.447784,0.108421,0.000000
81.490005,62.583519,-139.358826,0.009623,0.004266,0.108360,278.385406,14.181628,1.083596,-139.358826,0.108421,0.000000
81.750008,62.456543,-139.447784,0.009619,0.004266,0.108360,277.820587,14.152855,1.083596,-139.447784,0.108421,0.000000
82.010002,62.348557,-139.403305,0.009606,0.004266,0.108360,277.340240,14.128385,1.083596,-139.403305,0.108421,0.000000
82.270004,62.242798,-139.447784,0.009619,0.004266,0.108360,276.869781,14.104420,1.083596,-139.447784,0.108421,0.000000
82.530006,62.134438,-139.492264,0.009610,0.004266,0.108360,276.387787,14.079865,1.083596,-139.492264,0.108421,0.000000
82.790001,62.032784,-139.447784,0.009619,0.004266,0.108360,275.935608,14.056829,1.083596,-139.447784,0.108421,0.000000
83.050003,61.946022,-139.492264,0.009615,0.004266,0.108360,275.549683,14.037169,1.083596,-139.492264,0.108421,0.000000
83.310005,61.835800,-139.492264,0.009615,0.004266,0.108360,275.059387,14.012193,1.083596,-139.492264,0.108421,0.000000
83.570007,61.759087,-139.492264,0.009632,0.004266,0.108360,274.718140,13.994808,1.083596,-139.492264,0.108421,0.000000
83.830002,61.687965,-139.581223,0.009623,0.004266,0.108360,274.401764,13.978693,1.083596,-139.581223,0.108421,0.000000
84.090004,61.593384,-139.492264,0.009628,0.004266,0.108360,273.981049,13.957260,1.083596,-139.492264,0.108421,0.000000
84.350006,61.514442,-139.536743,0.009628,0.004266,0.108360,273.629913,13.939372,1.083596,-139.536743,0.108421,0.000000
84.610001,61.454117,-139.536743,0.009628,0.004266,0.108360,273.361572,13.925702,1.083596,-139.536743,0.108421,0.000000
84.870003,61.375916,-139.492264,0.009636,0.004266,0.108360,273.013702,13.907981,1.083596,-139.492264,0.108421,0.000000
85.130005,61.299583,-139.536743,0.009628,0.004266,0.108360,272.674164,13.890684,1.083596,-139.536743,0.108421,0.000000
85.390007,61.243729,-139.581223,0.009632,0.004266,0.108360,272.425720,13.878028,1.083596,-139.581223,0.108421,0.000000
85.650002,61.187866,-139.581223,0.009628,0.004266,0.108360,272.177216,13.865369,1.083596,-139.581223,0.108421,0.000000
85.910004,61.105576,-139.536743,0.009628,0.004266,0.108360,271.811188,13.846722,1.083596,-139.536743,0.108421,0.000000
86.170006,61.058281,-139.536743,0.009632,0.004266,0.108360,271.600800,13.836004,1.083596,-139.536743,0.108421,0.000000
86.430000,60.993492,-139.625702,0.009615,0.004266,0.108360,271.312592,13.821322,1.083596,-139.625702,0.108421,0.000000
86.690002,60.930931,-139.581223,0.009623,0.004266,0.108360,271.034332,13.807146,1.083596,-139.581223,0.108421,0.000000
86.950005,60.893692,-139.625702,0.009645,0.004266,0.108360,270.868683,13.798708,1.083596,-139.625702,0.108421,0.000000
87.210007,60.821823,-139.581223,0.009619,0.004266,0.108360,270.548981,13.782422,1.083596,-139.581223,0.108421,0.000000
87.470001,60.778259,-139.581223,0.009628,0.004266,0.108360,270.355194,13.772550,1.083596,-139.581223,0.108421,0.000000
87.730003,60.717934,-139.625702,0.009636,0.004266,0.108360,270.086853,13.758881,1.083596,-139.625702,0.108421,0.000000
87.990005,60.675484,-139.581223,0.009619,0.004266,0.108360,269.898041,13.749261,1.083596,-139.581223,0.108421,0.000000
88.250008,60.629311,-139.581223,0.009641,0.004266,0.108360,269.692657,13.738798,1.083596,-139.581223,0.108421,0.000000
88.510002,60.577179,-139.670181,0.009636,0.004266,0.108360,269.460754,13.726985,1.083596,-139.670181,0.108421,0.000000
88.770004,60.529884,-139.625702,0.009632,0.004266,0.108360,269.250366,13.716268,1.083596,-139.625702,0.108421,0.000000
89.030006,60.494881,-139.670181,0.009636,0.004266,0.108360,269.094666,13.708336,1.083596,-139.670181,0.108421,0.000000
89.290001,60.452431,-139.670181,0.009623,0.004266,0.108360,268.905853,13.698716,1.083596,-139.670181,0.108421,0.000000
89.550003,60.397324,-139.714661,0.009623,0.004266,0.108360,268.660706,13.686229,1.083596,-139.714661,0.108421,0.000000
89.810005,60.366791,-139.670181,0.009623,0.004266,0.108360,268.524902,13.679310,1.083596,-139.670181,0.108421,0.000000
90.070007,60.323219,-139.625702,0.009636,0.004266,0.108360,268.331085,13.669436,1.083596,-139.625702,0.108421,0.000000
90.330002,60.275932,-139.759155,0.009628,0.004266,0.108360,268.120728,13.658721,1.083596,-139.759155,0.108421,0.000000
90.590004,60.249115,-139.670181,0.009636,0.004266,0.108360,268.001434,13.652644,1.083596,-139.670181,0.108421,0.000000
90.850006,60.208160,-139.714661,0.009636,0.004266,0.108360,267.819275,13.643364,1.083596,-139.714661,0.108421,0.000000
91.110001,60.161613,-139.670181,0.009632,0.004266,0.108360,267.612213,13.632817,1.083596,-139.670181,0.108421,0.000000
91.370003,60.131447,-139.714661,0.009649,0.004266,0.108360,267.478027,13.625981,1.083596,-139.714661,0.108421,0.000000
91.630005,60.083786,-139.759155,0.009641,0.004266,0.108360,267.266022,13.615180,1.083596,-139.759155,0.108421,0.000000
91.890007,60.064423,-139.714661,0.009632,0.004266,0.108360,267.179901,13.610793,1.083596,-139.714661,0.108421,0.000000
92.150002,60.018616,-139.803635,0.009641,0.004266,0.108360,266.976135,13.600412,1.083596,-139.803635,0.108421,0.000000
92.410004,59.983246,-139.714661,0.009632,0.004266,0.108360,266.818817,13.592398,1.083596,-139.714661,0.108421,0.000000
92.670006,59.951218,-139.759155,0.009632,0.004266,0.108360,266.676331,13.585140,1.083596,-139.759155,0.108421,0.000000
92.930008,59.918823,-139.848114,0.009641,0.004266,0.108360,266.532227,13.577799,1.083596,-139.848114,0.108421,0.000000
93.190002,59.877487,-139.803635,0.009641,0.004266,0.108360,266.348358,13.568433,1.083596,-139.803635,0.108421,0.000000
93.450005,59.845467,-139.848114,0.009636,0.004266,0.108360,266.205933,13.561176,1.083596,-139.848114,0.108421,0.000000
93.710007,59.815308,-139.803635,0.009636,0.004266,0.108360,266.071777,13.554342,1.083596,-139.803635,0.108421,0.000000
93.970001,59.793709,-139.759155,0.009623,0.004266,0.108360,265.975708,13.549448,1.083596,-139.759155,0.108421,0.000000
94.230003,59.758705,-139.937073,0.009619,0.004266,0.108360,265.820007,13.541516,1.083596,-139.937073,0.108421,0.000000
94.490005,59.723701,-139.803635,0.009636,0.004266,0.108360,265.664307,13.533585,1.083596,-139.803635,0.108421,0.000000
94.750008,59.699127,-139.803635,0.009641,0.004266,0.108360,265.554993,13.528016,1.083596,-139.803635,0.108421,0.000000
95.010002,59.668221,-139.848114,0.009636,0.004266,0.108360,265.417511,13.521011,1.083596,-139.848114,0.108421,0.000000
95.270004,59.639915,-139.759155,0.009641,0.004266,0.108360,265.291595,13.514598,1.083596,-139.759155,0.108421,0.000000
95.530006,59.600449,-139.848114,0.009649,0.004266,0.108360,265.116028,13.505654,1.083596,-139.848114,0.108421,0.000000
95.790001,59.576241,-139.892593,0.009628,0.004266,0.108360,265.008362,13.500170,1.083596,-139.892593,0.108421,0.000000
96.050003,59.555763,-139.848114,0.009641,0.004266,0.108360,264.917267,13.495528,1.083596,-139.848114,0.108421,0.000000
96.310005,59.517036,-139.892593,0.009645,0.004266,0.108360,264.744995,13.486753,1.083596,-139.892593,0.108421,0.000000
96.570007,59.495811,-139.848114,0.009636,0.004266,0.108360,264.650574,13.481944,1.083596,-139.848114,0.108421,0.000000
96.830002,59.478310,-139.937073,0.009645,0.004266,0.108360,264.572723,13.477977,1.083596,-139.937073,0.108421,0.000000
97.090004,59.442932,-139.892593,0.009636,0.004266,0.108360,264.415375,13.469961,1.083596,-139.892593,0.108421,0.000000
97.350006,59.429153,-139.892593,0.009653,0.004266,0.108360,264.354065,13.466839,1.083596,-139.892593,0.108421,0.000000
97.610008,59.404579,-139.892593,0.009632,0.004266,0.108360,264.244751,13.461270,1.083596,-139.892593,0.108421,0.000000
97.870003,59.378136,-139.892593,0.009636,0.004266,0.108360,264.127136,13.455277,1.083596,-139.892593,0.108421,0.000000
98.130005,59.349091,-139.937073,0.009653,0.004266,0.108360,263.997925,13.448696,1.083596,-139.937073,0.108421,0.000000
98.390007,59.321541,-139.937073,0.009632,0.004266,0.108360,263.875397,13.442453,1.083596,-139.937073,0.108421,0.000000
98.650002,59.318184,-139.892593,0.009636,0.004266,0.108360,263.860474,13.441692,1.083596,-139.892593,0.108421,0.000000
98.910004,59.285789,-139.937073,0.009641,0.004266,0.108360,263.716370,13.434352,1.083596,-139.937073,0.108421,0.000000
99.170006,59.261955,-139.892593,0.009632,0.004266,0.108360,263.610352,13.428951,1.083596,-139.892593,0.108421,0.000000
99.430008,59.249298,-139.937073,0.009636,0.004266,0.108360,263.554047,13.426084,1.083596,-139.937073,0.108421,0.000000
99.690002,59.220627,-139.981552,0.009632,0.004266,0.108360,263.426514,13.419586,1.083596,-139.981552,0.108421,0.000000
99.950005,59.204613,-139.981552,0.009636,0.004266,0.108360,263.355255,13.415957,1.083596,-139.981552,0.108421,0.000000
100.210007,59.175568,-140.026031,0.009641,0.004266,0.108360,263.226074,13.409375,1.083596,-140.026031,0.108421,0.000000
100.470001,59.159187,-140.026031,0.009649,0.004266,0.108360,263.153198,13.405663,1.083596,-140.026031,0.108421,0.000000
100.730003,59.144287,-140.026031,0.009645,0.004266,0.108360,263.086914,13.402287,1.083596,-140.026031,0.108421,0.000000
100.990005,59.108917,-140.026031,0.009645,0.004266,0.108360,262.929596,13.394273,1.083596,-140.026031,0.108421,0.000000
101.250008,59.095879,-139.981552,0.009645,0.004266,0.108360,262.871582,13.391317,1.083596,-139.981552,0.108421,0.000000
101.510002,59.064972,-140.070511,0.009641,0.004266,0.108360,262.734131,13.384314,1.083596,-140.070511,0.108421,0.000000
101.770004,59.064598,-140.026031,0.009645,0.004266,0.108360,262.732452,13.384229,1.083596,-140.026031,0.108421,0.000000
102.030006,59.031090,-140.070511,0.009636,0.004266,0.108360,262.583405,13.376636,1.083596,-140.070511,0.108421,0.000000
102.290009,59.015450,-140.114990,0.009632,0.004266,0.108360,262.513824,13.373092,1.083596,-140.114990,0.108421,0.000000
102.550003,59.001671,-140.026031,0.009645,0.004266,0.108360,262.452545,13.369969,1.083596,-140.026031,0.108421,0.000000
102.810005,58.971878,-140.070511,0.009641,0.004266,0.108360,262.320007,13.363219,1.083596,-140.070511,0.108421,0.000000
103.070007,58.956612,-140.026031,0.009632,0.004266,0.108360,262.252106,13.359759,1.083596,-140.026031,0.108421,0.000000
103.330002,58.932785,-140.070511,0.009645,0.004266,0.108360,262.146118,13.354361,1.083596,-140.070511,0.108421,0.000000
103.590004,58.912674,-140.114990,0.009632,0.004266,0.108360,262.056671,13.349803,1.083596,-140.114990,0.108421,0.000000
103.850006,58.905602,-140.070511,0.009645,0.004266,0.108360,262.025208,13.348201,1.083596,-140.070511,0.108421,0.000000
104.110008,58.873947,-140.070511,0.009649,0.004266,0.108360,261.884399,13.341026,1.083596,-140.070511,0.108421,0.000000
104.370003,58.867241,-140.114990,0.009641,0.004266,0.108360,261.854553,13.339507,1.083596,-140.114990,0.108421,0.000000
104.630005,58.848999,-140.159470,0.009641,0.004266,0.108360,261.773407,13.335374,1.083596,-140.159470,0.108421,0.000000
104.890007,58.831123,-140.159470,0.009641,0.004266,0.108360,261.693909,13.331323,1.083596,-140.159470,0.108421,0.000000
105.150002,58.824425,-140.159470,0.009641,0.004266,0.108360,261.664124,13.329804,1.083596,-140.159470,0.108421,0.000000
105.410004,58.786812,-140.203964,0.009649,0.004266,0.108360,261.496796,13.321282,1.083596,-140.203964,0.108421,0.000000
105.670006,58.781227,-140.159470,0.009641,0.004266,0.108360,261.471954,13.320017,1.083596,-140.159470,0.108421,0.000000
105.930008,58.755531,-140.159470,0.009653,0.004266,0.108360,261.357666,13.314194,1.083596,-140.159470,0.108421,0.000000
106.190002,58.740265,-140.159470,0.009632,0.004266,0.108360,261.289734,13.310734,1.083596,-140.159470,0.108421,0.000000
106.450005,58.726486,-140.203964,0.009632,0.004266,0.108360,261.228455,13.307611,1.083596,-140.203964,0.108421,0.000000
106.710007,58.697441,-140.203964,0.009641,0.004266,0.108360,261.099243,13.301030,1.083596,-140.203964,0.108421,0.000000
106.970009,58.682922,-140.203964,0.009641,0.004266,0.108360,261.034668,13.297740,1.083596,-140.203964,0.108421,0.000000
107.230003,58.684410,-140.159470,0.009653,0.004266,0.108360,261.041290,13.298078,1.083596,-140.159470,0.108421,0.000000
107.400002,58.660202,-140.203964,0.009632,0.004266,0.108360,260.933624,13.292592,1.083596,-140.203964,0.108421,0.000000