File: Data/compression 8/AutoHeating-12-8-1-4-240328_03282024_152944.csv
Time (sec),S:Load (lbs),S:HL1 (DIM),S:LVDT (in),S:Position (in),Ch:Position (mm),Ch:Load (N),Ch:Stress (MPa),Ch:Strain (mm/mm),Ch:HL1 (DIM),Set Point (),Cycles ()
0.110000,0.008560,-141.894241,0.000000,-0.000000,-0.000000,0.038078,0.001940,-0.000000,-141.894241,0.000208,0.000000
0.380000,0.005959,-141.938721,-0.000013,-0.000000,-0.000000,0.026505,0.001350,-0.000000,-141.938721,0.000208,0.000000
0.650000,-0.023087,-142.027679,0.000004,0.000144,0.003668,-0.102694,-0.005231,0.036683,-142.027679,0.004666,0.000000
0.920000,-0.055489,-141.894241,0.000185,0.000318,0.008065,-0.246826,-0.012574,0.080652,-141.894241,0.009158,0.000000
1.190000,0.007446,-141.938721,0.000349,0.000497,0.012618,0.033123,0.001687,0.126181,-141.938721,0.013650,0.000000
1.460000,0.033882,-141.894241,0.000530,0.000678,0.017223,0.150715,0.007678,0.172232,-141.894241,0.018160,0.000000
1.730000,-0.003349,-141.983200,0.000711,0.000849,0.021568,-0.014898,-0.000759,0.215678,-141.983200,0.022652,0.000000
2.000000,0.030159,-141.938721,0.000897,0.001023,0.025973,0.134154,0.006834,0.259735,-141.938721,0.027144,0.000000
2.270000,0.001488,-141.894241,0.001082,0.001208,0.030674,0.006618,0.000337,0.306739,-141.894241,0.031654,0.000000
2.540000,-0.001862,-141.938721,0.001242,0.001381,0.035088,-0.008281,-0.000422,0.350882,-141.938721,0.036146,0.000000
2.810000,-0.004845,-141.983200,0.001418,0.001558,0.039580,-0.021550,-0.001098,0.395802,-141.983200,0.040638,0.000000
3.080000,-0.040215,-142.027679,0.001604,0.001736,0.044090,-0.178883,-0.009113,0.440899,-142.027679,0.045148,0.000000
3.350000,0.040588,-142.027679,0.001768,0.001909,0.048478,0.180546,0.009197,0.484781,-142.027679,0.049640,0.000000
3.620000,0.008560,-141.938721,0.001970,0.002093,0.053170,0.038078,0.001940,0.531698,-141.938721,0.054132,0.000000
3.890000,0.015640,-141.983200,0.002143,0.002269,0.057627,0.069571,0.003544,0.576273,-141.983200,0.058642,0.000000
4.160000,0.010422,-142.072159,0.002320,0.002441,0.062007,0.046358,0.002362,0.620068,-142.072159,0.063134,0.000000
4.430000,-0.016388,-142.072159,0.002505,0.002621,0.066568,-0.072897,-0.003714,0.665684,-142.072159,0.067626,0.000000
4.700000,0.013031,-142.027679,0.002682,0.002795,0.071000,0.057965,0.002953,0.709997,-142.027679,0.072136,0.000000
4.970000,-0.010056,-141.983200,0.002863,0.002978,0.075648,-0.044729,-0.002279,0.756483,-141.983200,0.076628,0.000000
5.240000,-0.002983,-142.027679,0.003044,0.003153,0.080097,-0.013269,-0.000676,0.800971,-142.027679,0.081138,0.000000
5.510000,0.029785,-142.116638,0.003216,0.003329,0.084546,0.132491,0.006749,0.845459,-142.116638,0.085630,0.000000
5.780000,-0.011169,-142.116638,0.003415,0.003509,0.089125,-0.049684,-0.002531,0.891248,-142.116638,0.090122,0.000000
6.050000,0.016380,-142.072159,0.003587,0.003681,0.093487,0.072863,0.003712,0.934869,-142.072159,0.094632,0.000000
6.320000,0.027557,-142.027679,0.003777,0.003863,0.098127,0.122581,0.006245,0.981268,-142.027679,0.099124,0.000000
6.590000,0.007820,-142.072159,0.003941,0.004037,0.102549,0.034786,0.001772,1.025495,-142.072159,0.103616,0.000000
6.860000,0.008934,-142.116638,0.004122,0.004214,0.107024,0.039741,0.002024,1.070243,-142.116638,0.108126,0.000000
7.130000,-0.049896,-142.161118,0.004307,0.004390,0.111508,-0.221950,-0.011307,1.115079,-142.161118,0.112618,0.000000
7.400001,0.027557,-142.161118,0.004488,0.004564,0.115931,0.122581,0.006245,1.159310,-142.161118,0.117110,0.000000
7.670001,0.021965,-142.072159,0.004674,0.004748,0.120605,0.097705,0.004977,1.206053,-142.072159,0.121620,0.000000
7.940001,0.011917,-142.072159,0.004846,0.004927,0.125141,0.053010,0.002700,1.251407,-142.072159,0.126112,0.000000
8.210000,0.028297,-142.161118,0.005006,0.005091,0.129303,0.125873,0.006412,1.293034,-142.161118,0.130604,0.000000
8.480000,-0.001122,-142.116638,0.005217,0.005277,0.134047,-0.004989,-0.000254,1.340474,-142.116638,0.135114,0.000000
8.750000,0.020103,-142.072159,0.005389,0.005454,0.138522,0.089425,0.004556,1.385222,-142.072159,0.139606,0.000000
9.020000,0.004471,-142.161118,0.005566,0.005636,0.143162,0.019887,0.001013,1.431618,-142.161118,0.144099,0.000000
9.290001,-0.040215,-142.161118,0.005726,0.005806,0.147472,-0.178883,-0.009113,1.474720,-142.161118,0.148608,0.000000
9.560000,0.050270,-142.205597,0.005898,0.005981,0.151929,0.223612,0.011391,1.519295,-142.205597,0.153100,0.000000
9.830001,-0.002609,-142.205597,0.006088,0.006164,0.156578,-0.011607,-0.000591,1.565777,-142.205597,0.157592,0.000000
10.100000,0.027557,-142.161118,0.006286,0.006341,0.161070,0.122581,0.006245,1.610700,-142.161118,0.162102,0.000000
10.370001,0.040588,-142.161118,0.006459,0.006515,0.165493,0.180546,0.009197,1.654926,-142.161118,0.166594,0.000000
10.640000,0.018616,-142.161118,0.006631,0.006691,0.169959,0.082807,0.004218,1.699592,-142.161118,0.171086,0.000000
10.910001,0.333641,-142.250076,0.006808,0.006866,0.174399,1.484110,0.075604,1.743993,-142.250076,0.175596,0.000000
11.180000,0.718681,-142.205597,0.006890,-0.000000,-0.000000,3.196854,0.162856,-0.000000,-142.205597,0.000260,0.000000
11.450001,0.684792,-142.205597,0.006881,-0.000000,-0.000000,3.046105,0.155176,-0.000000,-142.205597,0.000260,0.000000
11.720000,0.583878,-142.205597,0.006894,-0.000000,-0.000000,2.597217,0.132309,-0.000000,-142.205597,0.000512,0.000000
11.990001,0.583138,-142.294556,0.006873,0.000000,0.000009,2.593925,0.132141,0.000087,-142.294556,0.000962,0.000000
12.260000,0.614784,-142.250076,0.006890,0.000019,0.000486,2.734697,0.139312,0.004856,-142.250076,0.001414,0.000000
12.530001,0.891830,-142.339050,0.006911,0.000042,0.001067,3.967060,0.202092,0.010666,-142.339050,0.001864,0.000000
12.800000,0.940987,-142.250076,0.006907,0.000051,0.001283,4.185718,0.213231,0.012835,-142.250076,0.002307,0.000000
13.070001,1.135735,-142.205597,0.006937,0.000077,0.001951,5.052000,0.257361,0.019515,-142.205597,0.002758,0.000000
13.340001,1.263832,-142.250076,0.006967,0.000096,0.002446,5.621806,0.286388,0.024458,-142.250076,0.003209,0.000000
13.610001,1.330482,-142.383530,0.006980,0.000112,0.002836,5.918282,0.301492,0.028360,-142.383530,0.003660,0.000000
13.880001,1.436241,-142.250076,0.006998,0.000126,0.003191,6.388720,0.325457,0.031914,-142.250076,0.004111,0.000000
14.150001,1.543114,-142.250076,0.007011,0.000141,0.003590,6.864112,0.349675,0.035904,-142.250076,0.004562,0.000000
14.420001,1.781059,-142.294556,0.007023,0.000165,0.004180,7.922547,0.403594,0.041800,-142.294556,0.005013,0.000000
14.690001,1.849945,-142.339050,0.007036,0.000176,0.004466,8.228967,0.419204,0.044662,-142.339050,0.005463,0.000000
14.960001,1.997780,-142.339050,0.007058,0.000195,0.004960,8.886569,0.452703,0.049605,-142.339050,0.005915,0.000000
15.230000,2.222321,-142.339050,0.007084,0.000220,0.005585,9.885376,0.503585,0.055850,-142.339050,0.006365,0.000000
15.500001,2.285995,-142.339050,0.007084,0.000235,0.005975,10.168615,0.518014,0.059752,-142.339050,0.006808,0.000000
15.770000,2.329933,-142.339050,0.007110,0.000249,0.006322,10.364060,0.527970,0.063223,-142.339050,0.007259,0.000000
16.040001,2.477394,-142.383530,0.007123,0.000267,0.006790,11.020000,0.561386,0.067905,-142.383530,0.007710,0.000000
16.310001,2.680710,-142.339050,0.007131,0.000287,0.007302,11.924393,0.607458,0.073022,-142.339050,0.008161,0.000000
16.580000,2.796890,-142.339050,0.007148,0.000304,0.007710,12.441189,0.633784,0.077098,-142.339050,0.008612,0.000000
16.850000,2.931313,-142.383530,0.007170,0.000324,0.008221,13.039129,0.664245,0.082212,-142.383530,0.009063,0.000000
17.120001,3.076164,-142.428009,0.007187,0.000344,0.008742,13.683462,0.697069,0.087416,-142.428009,0.009513,0.000000
17.390001,3.135376,-142.472488,0.007205,0.000360,0.009141,13.946849,0.710486,0.091405,-142.472488,0.009964,0.000000
17.660002,3.188995,-142.383530,0.007235,0.000375,0.009531,14.185360,0.722637,0.095307,-142.383530,0.010415,0.000000
17.930000,3.282837,-142.428009,0.007239,0.000390,0.009904,14.602788,0.743901,0.099039,-142.428009,0.010858,0.000000
18.200001,3.498810,-142.383530,0.007248,0.000411,0.010441,15.563483,0.792842,0.104414,-142.383530,0.011309,0.000000
18.470001,3.502907,-142.428009,0.007261,0.000422,0.010728,15.581708,0.793770,0.107275,-142.428009,0.011760,0.000000
18.740002,3.777718,-142.472488,0.007278,0.000444,0.011283,16.804127,0.856043,0.112828,-142.472488,0.012210,0.000000
19.010000,3.887192,-142.428009,0.007304,0.000462,0.011734,17.291092,0.880850,0.117336,-142.428009,0.012662,0.000000
19.280001,3.985870,-142.383530,0.007321,0.000481,0.012210,17.730038,0.903211,0.122104,-142.383530,0.013112,0.000000
19.550001,4.008217,-142.339050,0.007334,0.000495,0.012566,17.829439,0.908275,0.125662,-142.339050,0.013564,0.000000
19.820002,4.186584,-142.472488,0.007347,0.000515,0.013069,18.622858,0.948694,0.130692,-142.472488,0.014014,0.000000
20.090000,4.356384,-142.516968,0.007377,0.000538,0.013659,19.378164,0.987171,0.136589,-142.516968,0.014465,0.000000
20.360001,4.366814,-142.472488,0.007386,0.000551,0.014006,19.424557,0.989534,0.140056,-142.472488,0.014908,0.000000
20.630001,4.564537,-142.472488,0.007394,0.000571,0.014509,20.304075,1.034339,0.145086,-142.472488,0.015359,0.000000
20.900002,4.666946,-142.472488,0.007416,0.000588,0.014934,20.759615,1.057545,0.149337,-142.472488,0.015810,0.000000
21.170000,4.765251,-142.561447,0.007424,0.000608,0.015437,21.196896,1.079821,0.154367,-142.561447,0.016261,0.000000
21.440001,4.872490,-142.516968,0.007446,0.000626,0.015896,21.673918,1.104122,0.158962,-142.516968,0.016711,0.000000
21.710001,4.944359,-142.516968,0.007476,0.000642,0.016295,21.993607,1.120408,0.162951,-142.516968,0.017163,0.000000
21.980001,5.180443,-142.472488,0.007493,0.000664,0.016868,23.043760,1.173905,0.168678,-142.472488,0.017613,0.000000
22.250002,5.158104,-142.561447,0.007489,0.000678,0.017214,22.944393,1.168843,0.172145,-142.561447,0.018065,0.000000
22.520000,5.317108,-142.516968,0.007498,0.000697,0.017700,23.651678,1.204874,0.177001,-142.516968,0.018515,0.000000
22.790001,5.455254,-142.516968,0.007537,0.000715,0.018151,24.266180,1.236178,0.181512,-142.516968,0.018966,0.000000
23.060001,5.591545,-142.516968,0.007549,0.000734,0.018654,24.872435,1.267062,0.186542,-142.516968,0.019409,0.000000
23.330002,5.565849,-142.516968,0.007562,0.000751,0.019079,24.758135,1.261240,0.190789,-142.516968,0.019859,0.000000
23.600000,5.730812,-142.561447,0.007575,0.000771,0.019573,25.491926,1.298621,0.195732,-142.561447,0.020311,0.000000
23.870001,5.818321,-142.650406,0.007593,0.000788,0.020016,25.881186,1.318450,0.200157,-142.650406,0.020761,0.000000
24.140001,5.902847,-142.650406,0.007606,0.000804,0.020432,26.257175,1.337604,0.204320,-142.650406,0.021212,0.000000
24.410002,5.764328,-142.605927,0.007623,0.000811,0.020605,25.641012,1.306215,0.206053,-142.605927,0.021663,0.000000
24.680000,6.150475,-142.561447,0.007631,0.000838,0.021273,27.358677,1.393717,0.212730,-142.561447,0.022114,0.000000
24.950001,6.245804,-142.650406,0.007640,0.000858,0.021785,27.782722,1.415319,0.217847,-142.650406,0.022565,0.000000
25.220001,6.262184,-142.694885,0.007666,0.000876,0.022244,27.855587,1.419031,0.222442,-142.694885,0.023016,0.000000
25.490002,6.297188,-142.605927,0.007683,0.000892,0.022652,28.011290,1.426963,0.226518,-142.605927,0.023458,0.000000
25.760002,6.393265,-142.650406,0.007692,0.000909,0.023077,28.438662,1.448735,0.230769,-142.650406,0.023910,0.000000
26.030001,6.513908,-142.650406,0.007709,0.000924,0.023467,28.975311,1.476073,0.234671,-142.650406,0.024360,0.000000
26.300001,6.453217,-142.739365,0.007713,0.000937,0.023788,28.705341,1.462320,0.237881,-142.739365,0.024812,0.000000
26.570002,6.534760,-142.694885,0.007722,0.000951,0.024152,29.068062,1.480798,0.241522,-142.694885,0.025262,0.000000
26.840002,6.859100,-142.605927,0.007756,0.000978,0.024829,30.510801,1.554294,0.248285,-142.605927,0.025713,0.000000
27.110001,6.905647,-142.650406,0.007769,0.000996,0.025288,30.717854,1.564842,0.252884,-142.650406,0.026164,0.000000
27.380001,6.913094,-142.694885,0.007774,0.001013,0.025730,30.750977,1.566529,0.257305,-142.694885,0.026615,0.000000
27.650002,7.000603,-142.694885,0.007787,0.001031,0.026190,31.140236,1.586359,0.261903,-142.694885,0.027066,0.000000
27.920002,7.074333,-142.739365,0.007804,0.001051,0.026702,31.468206,1.603067,0.267021,-142.739365,0.027509,0.000000
28.190001,7.049385,-142.694885,0.007812,0.001066,0.027066,31.357231,1.597414,0.270662,-142.694885,0.027959,0.000000
28.460001,7.034859,-142.694885,0.007834,0.001078,0.027387,31.292614,1.594122,0.273871,-142.694885,0.028410,0.000000
28.730001,7.298500,-142.650406,0.007838,0.001102,0.027986,32.465351,1.653864,0.279855,-142.650406,0.028861,0.000000
29.000002,7.284721,-142.783859,0.007847,0.001117,0.028384,32.404060,1.650741,0.283844,-142.783859,0.029312,0.000000
29.270000,7.398293,-142.828339,0.007864,0.001137,0.028887,32.909248,1.676477,0.288875,-142.828339,0.029763,0.000000
29.540001,7.352119,-142.783859,0.007886,0.001152,0.029269,32.703861,1.666014,0.292690,-142.783859,0.030214,0.000000
29.810001,7.461967,-142.739365,0.007899,0.001170,0.029720,33.192490,1.690906,0.297198,-142.739365,0.030665,0.000000
30.080002,7.496971,-142.783859,0.007907,0.001186,0.030127,33.348194,1.698838,0.301274,-142.783859,0.031116,0.000000
30.350002,7.428459,-142.783859,0.007907,0.001198,0.030422,33.043438,1.683313,0.304222,-142.783859,0.031567,0.000000
30.620001,7.868973,-142.783859,0.007933,0.001226,0.031151,35.002937,1.783135,0.311508,-142.783859,0.032009,0.000000
30.890001,7.869720,-142.783859,0.007950,0.001246,0.031636,35.006264,1.783304,0.316364,-142.783859,0.032460,0.000000
31.160002,7.841049,-142.739365,0.007946,0.001262,0.032044,34.878727,1.776807,0.320441,-142.739365,0.032911,0.000000
31.430002,7.730820,-142.783859,0.007959,0.001275,0.032382,34.388405,1.751829,0.323824,-142.783859,0.033362,0.000000
31.700001,7.909187,-142.828339,0.007972,0.001297,0.032946,35.181824,1.792247,0.329460,-142.828339,0.033813,0.000000
31.970001,7.994461,-142.872818,0.007998,0.001314,0.033388,35.561138,1.811571,0.333881,-142.872818,0.034264,0.000000
32.240002,7.936745,-142.783859,0.008006,0.001330,0.033770,35.304405,1.798492,0.337700,-142.783859,0.034715,0.000000
32.510002,8.143036,-142.828339,0.008024,0.001350,0.034290,36.222034,1.845238,0.342900,-142.828339,0.035166,0.000000
32.780003,8.201874,-142.828339,0.008028,0.001370,0.034793,36.483757,1.858571,0.347930,-142.828339,0.035617,0.000000
33.050003,8.175438,-142.917297,0.008058,0.001387,0.035227,36.366165,1.852581,0.352268,-142.917297,0.036059,0.000000
33.320000,8.118462,-142.872818,0.008058,0.001400,0.035565,36.112720,1.839670,0.355651,-142.872818,0.036510,0.000000
33.590000,8.189217,-142.783859,0.008075,0.001418,0.036025,36.427456,1.855703,0.360246,-142.783859,0.036961,0.000000
33.860001,8.467003,-142.917297,0.008084,0.001440,0.036588,37.663109,1.918650,0.365882,-142.917297,0.037412,0.000000
34.130001,8.231293,-142.872818,0.008084,0.001451,0.036849,36.614620,1.865238,0.368486,-142.872818,0.037863,0.000000
34.400002,8.655800,-142.917297,0.008106,0.001478,0.037534,38.502922,1.961432,0.375337,-142.917297,0.038314,0.000000
34.670002,8.664360,-142.872818,0.008127,0.001496,0.038002,38.540997,1.963372,0.380019,-142.872818,0.038765,0.000000
34.940002,8.462166,-142.872818,0.008136,0.001510,0.038357,37.641594,1.917554,0.383573,-142.872818,0.039216,0.000000
35.210003,8.442802,-142.917297,0.008140,0.001524,0.038722,37.555462,1.913166,0.387217,-142.917297,0.039667,0.000000
35.480003,8.364227,-142.917297,0.008144,0.001536,0.039008,37.205940,1.895361,0.390079,-142.917297,0.040109,0.000000
35.750000,8.809212,-142.961777,0.008170,0.001563,0.039702,39.185329,1.996196,0.397017,-142.961777,0.040560,0.000000
36.020000,8.649841,-142.961777,0.008179,0.001575,0.039996,38.476418,1.960082,0.399965,-142.961777,0.041011,0.000000
36.290001,8.755592,-142.961777,0.008188,0.001595,0.040508,38.946819,1.984046,0.405082,-142.961777,0.041462,0.000000
36.560001,9.127220,-142.917297,0.008201,0.001621,0.041167,40.599903,2.068258,0.411672,-142.917297,0.041913,0.000000
36.830002,8.919067,-143.006256,0.008213,0.001634,0.041514,39.673992,2.021090,0.415142,-143.006256,0.042364,0.000000
37.100002,8.755592,-143.006256,0.008226,0.001648,0.041870,38.946819,1.984046,0.418696,-143.006256,0.042815,0.000000
37.370003,8.891884,-143.006256,0.008239,0.001667,0.042338,39.553074,2.014930,0.423378,-143.006256,0.043266,0.000000
37.640003,9.036362,-142.961777,0.008244,0.001686,0.042824,40.195744,2.047669,0.428238,-142.961777,0.043717,0.000000
37.910004,9.073227,-143.006256,0.008261,0.001703,0.043248,40.359730,2.056023,0.432485,-143.006256,0.044168,0.000000
38.180000,9.209511,-143.095215,0.008265,0.001722,0.043751,40.965950,2.086905,0.437515,-143.095215,0.044610,0.000000
38.450001,9.310799,-143.050735,0.008278,0.001743,0.044281,41.416500,2.109857,0.442806,-143.050735,0.045061,0.000000
38.720001,9.219193,-143.006256,0.008295,0.001758,0.044645,41.009018,2.089099,0.446447,-143.006256,0.045512,0.000000
38.990002,9.237816,-143.006256,0.008300,0.001776,0.045105,41.091858,2.093319,0.451046,-143.006256,0.045963,0.000000
39.260002,9.167061,-143.050735,0.008321,0.001790,0.045460,40.777122,2.077286,0.454600,-143.050735,0.046414,0.000000
39.530003,9.342827,-143.050735,0.008326,0.001810,0.045980,41.558968,2.117115,0.459804,-143.050735,0.046865,0.000000
39.800003,9.206909,-143.050735,0.008338,0.001823,0.046293,40.954376,2.086315,0.462927,-143.050735,0.047316,0.000000
40.070004,9.507416,-143.095215,0.008356,0.001844,0.046839,42.291096,2.154411,0.468388,-143.095215,0.047767,0.000000
40.340000,9.530502,-143.050735,0.008377,0.001862,0.047307,42.393791,2.159643,0.473070,-143.050735,0.048218,0.000000
40.610001,9.627319,-143.095215,0.008382,0.001882,0.047793,42.824455,2.181582,0.477930,-143.095215,0.048660,0.000000
40.880001,9.466080,-143.139694,0.008382,0.001895,0.048140,42.107227,2.145044,0.481397,-143.139694,0.049111,0.000000
41.150002,9.518585,-143.095215,0.008399,0.001914,0.048608,42.340782,2.156942,0.486079,-143.095215,0.049562,0.000000
41.420002,9.817596,-143.095215,0.008412,0.001937,0.049189,43.670849,2.224699,0.491893,-143.095215,0.050013,0.000000
41.690002,9.652267,-143.095215,0.008420,0.001951,0.049562,42.935429,2.187235,0.495621,-143.095215,0.050464,0.000000
41.960003,9.822441,-143.095215,0.008416,0.001971,0.050065,43.692402,2.225797,0.500651,-143.095215,0.050915,0.000000
42.230003,9.746475,-143.139694,0.008451,0.001987,0.050481,43.354488,2.208583,0.504814,-143.139694,0.051366,0.000000
42.500004,9.857445,-143.184189,0.008464,0.002008,0.050993,43.848103,2.233729,0.509928,-143.184189,0.051817,0.000000
42.770000,9.833237,-143.184189,0.008472,0.002024,0.051418,43.740421,2.228243,0.514178,-143.184189,0.052268,0.000000
43.040001,9.818718,-143.095215,0.008472,0.002041,0.051852,43.675838,2.224953,0.518515,-143.095215,0.052719,0.000000
43.310001,10.099487,-143.184189,0.008476,0.002064,0.052415,44.924763,2.288577,0.524151,-143.184189,0.053161,0.000000
43.580002,9.910316,-143.228668,0.008502,0.002079,0.052797,44.083290,2.245710,0.527966,-143.228668,0.053612,0.000000
43.850002,10.011978,-143.139694,0.008511,0.002096,0.053248,44.535503,2.268747,0.532478,-143.139694,0.054063,0.000000
44.120003,10.006393,-143.184189,0.008520,0.002113,0.053681,44.510662,2.267481,0.536812,-143.184189,0.054514,0.000000
44.390003,10.084961,-143.184189,0.008520,0.002133,0.054167,44.860146,2.285285,0.541671,-143.184189,0.054965,0.000000
44.660004,10.077888,-143.228668,0.008532,0.002152,0.054653,44.828686,2.283682,0.546528,-143.228668,0.055416,0.000000
44.930000,10.136719,-143.228668,0.008550,0.002169,0.055104,45.090378,2.297013,0.551035,-143.228668,0.055867,0.000000
45.200001,10.175079,-143.184189,0.008554,0.002188,0.055563,45.261013,2.305706,0.555630,-143.184189,0.056318,0.000000
45.470001,10.143425,-143.228668,0.008576,0.002204,0.055971,45.120209,2.298533,0.559707,-143.228668,0.056769,0.000000
45.740002,9.764725,-143.228668,0.008571,0.002210,0.056144,43.435665,2.212718,0.561444,-143.228668,0.057211,0.000000
46.010002,10.305405,-143.273148,0.008571,0.002238,0.056847,45.840729,2.335238,0.568469,-143.273148,0.057662,0.000000
46.280003,10.329239,-143.273148,0.008580,0.002257,0.057332,45.946751,2.340639,0.573325,-143.273148,0.058113,0.000000
46.550003,10.332962,-143.273148,0.008610,0.002276,0.057818,45.963310,2.341483,0.578181,-143.273148,0.058564,0.000000
46.820004,10.255882,-143.228668,0.008610,0.002291,0.058191,45.620441,2.324016,0.581909,-143.228668,0.059015,0.000000
47.090004,10.287529,-143.273148,0.008614,0.002308,0.058616,45.761215,2.331187,0.586159,-143.273148,0.059466,0.000000
47.360001,10.309875,-143.317627,0.008632,0.002323,0.059015,45.860615,2.336251,0.590148,-143.317627,0.059917,0.000000
47.630001,10.102837,-143.317627,0.008640,0.002335,0.059310,44.939663,2.289335,0.593097,-143.317627,0.060368,0.000000
47.900002,10.154221,-143.228668,0.008658,0.002350,0.059682,45.168228,2.300979,0.596825,-143.228668,0.060819,0.000000
48.170002,10.621925,-143.273148,0.008670,0.002377,0.060368,47.248684,2.406963,0.603676,-143.273148,0.061261,0.000000
48.440002,10.652458,-143.273148,0.008670,0.002395,0.060844,47.384502,2.413882,0.608445,-143.273148,0.061712,0.000000
48.710003,10.526222,-143.362106,0.008679,0.002411,0.061252,46.822975,2.385276,0.612521,-143.362106,0.062163,0.000000
48.980003,10.605537,-143.317627,0.008696,0.002432,0.061764,47.175785,2.403249,0.617638,-143.317627,0.062614,0.000000
49.250004,10.602188,-143.317627,0.008705,0.002448,0.062189,47.160889,2.402490,0.621889,-143.317627,0.063065,0.000000
49.520000,10.494942,-143.362106,0.008718,0.002464,0.062596,46.683834,2.378188,0.625965,-143.362106,0.063516,0.000000
49.790001,10.413765,-143.362106,0.008714,0.002477,0.062909,46.322739,2.359793,0.629087,-143.362106,0.063967,0.000000
50.060001,10.971207,-143.406586,0.008718,0.002505,0.063620,48.802364,2.486111,0.636195,-143.406586,0.064417,0.000000
50.330002,10.724701,-143.362106,0.008748,0.002517,0.063932,47.705853,2.430252,0.639318,-143.362106,0.064869,0.000000
50.600002,10.818909,-143.317627,0.008752,0.002536,0.064417,48.124908,2.451600,0.644174,-143.317627,0.065319,0.000000
50.870003,10.646873,-143.406586,0.008761,0.002550,0.064782,47.359657,2.412616,0.647819,-143.406586,0.065762,0.000000
51.140003,10.874763,-143.406586,0.008765,0.002570,0.065276,48.373363,2.464257,0.652762,-143.406586,0.066213,0.000000
51.410004,10.883698,-143.451065,0.008770,0.002585,0.065649,48.413105,2.466281,0.656490,-143.451065,0.066664,0.000000
51.680004,10.890030,-143.362106,0.008795,0.002602,0.066091,48.441273,2.467716,0.660915,-143.362106,0.067115,0.000000
51.950001,11.379700,-143.362106,0.008787,0.002627,0.066724,50.619431,2.578677,0.667243,-143.362106,0.067566,0.000000
52.220001,11.245644,-143.451065,0.008813,0.002644,0.067158,50.023121,2.548299,0.671580,-143.451065,0.068016,0.000000
52.490002,11.206177,-143.495544,0.008813,0.002661,0.067583,49.847565,2.539356,0.675831,-143.495544,0.068468,0.000000
52.760002,11.038605,-143.406586,0.008821,0.002677,0.067991,49.102165,2.501384,0.679907,-143.406586,0.068918,0.000000
53.030003,11.349541,-143.406586,0.008839,0.002697,0.068502,50.485279,2.571843,0.685021,-143.406586,0.069370,0.000000
53.300003,11.391617,-143.451065,0.008839,0.002714,0.068927,50.672443,2.581377,0.689271,-143.451065,0.069812,0.000000
53.570004,11.310066,-143.451065,0.008856,0.002729,0.069309,50.309689,2.562898,0.693086,-143.451065,0.070263,0.000000
53.840004,11.537590,-143.540024,0.008860,0.002747,0.069786,51.321762,2.614455,0.697855,-143.540024,0.070714,0.000000
54.110004,11.725632,-143.540024,0.008869,0.002768,0.070306,52.158215,2.657066,0.703059,-143.540024,0.071165,0.000000
54.380001,11.712227,-143.495544,0.008886,0.002786,0.070766,52.098587,2.654029,0.707658,-143.495544,0.071616,0.000000
54.650002,11.523811,-143.451065,0.008895,0.002799,0.071095,51.260471,2.611333,0.710951,-143.451065,0.072067,0.000000
54.920002,11.613548,-143.540024,0.008899,0.002817,0.071564,51.659641,2.631668,0.715637,-143.540024,0.072517,0.000000
55.190002,12.051834,-143.540024,0.008908,0.002839,0.072119,53.609234,2.730985,0.721185,-143.540024,0.072968,0.000000
55.460003,11.679832,-143.584503,0.008912,0.002849,0.072370,51.954491,2.646688,0.723702,-143.584503,0.073419,0.000000
55.730003,12.564590,-143.495544,0.008938,0.002878,0.073098,55.890091,2.847177,0.730984,-143.495544,0.073862,0.000000
56.000004,12.443573,-143.540024,0.008938,0.002895,0.073532,55.351776,2.819754,0.735322,-143.540024,0.074313,0.000000
56.270004,12.242485,-143.584503,0.008938,0.002910,0.073914,54.457294,2.774187,0.739137,-143.584503,0.074763,0.000000
56.540001,12.153122,-143.584503,0.008955,0.002924,0.074261,54.059788,2.753937,0.742608,-143.584503,0.075215,0.000000
56.810001,12.094658,-143.584503,0.008968,0.002939,0.074659,53.799725,2.740689,0.746593,-143.584503,0.075665,0.000000
57.080002,12.801422,-143.495544,0.008972,0.002962,0.075241,56.943569,2.900844,0.752407,-143.495544,0.076117,0.000000
57.350002,12.595497,-143.540024,0.008981,0.002976,0.075579,56.027569,2.854181,0.755787,-143.540024,0.076567,0.000000
57.620003,12.845734,-143.584503,0.008985,0.002993,0.076030,57.140678,2.910885,0.760298,-143.584503,0.077018,0.000000
57.890003,13.542442,-143.673477,0.009002,0.003020,0.076715,60.239792,3.068761,0.767149,-143.673477,0.077469,0.000000
58.160004,13.216240,-143.584503,0.009020,0.003033,0.077036,58.788773,2.994843,0.770359,-143.584503,0.077920,0.000000
58.430004,13.048302,-143.584503,0.009028,0.003047,0.077383,58.041744,2.956787,0.773826,-143.584503,0.078362,0.000000
58.700005,13.320877,-143.584503,0.009024,0.003065,0.077842,59.254219,3.018554,0.778420,-143.584503,0.078814,0.000000
58.970001,13.583405,-143.584503,0.009050,0.003082,0.078293,60.422001,3.078043,0.782932,-143.584503,0.079264,0.000000
59.240002,13.863426,-143.673477,0.009054,0.003101,0.078770,61.667599,3.141497,0.787701,-143.673477,0.079716,0.000000
59.510002,14.230583,-143.673477,0.009067,0.003121,0.079282,63.300797,3.224696,0.792818,-143.673477,0.080166,0.000000
59.780003,14.554924,-143.673477,0.009080,0.003142,0.079811,64.743538,3.298193,0.798109,-143.673477,0.080618,0.000000
60.050003,14.452148,-143.584503,0.009084,0.003156,0.080175,64.286369,3.274904,0.801751,-143.584503,0.081068,0.000000
60.320004,14.593277,-143.628998,0.009106,0.003174,0.080626,64.914139,3.306884,0.806262,-143.628998,0.081519,0.000000
60.590004,14.502792,-143.673477,0.009115,0.003188,0.080982,64.511642,3.286380,0.809816,-143.673477,0.081970,0.000000
60.860004,14.899368,-143.717957,0.009123,0.003207,0.081450,66.275703,3.376245,0.814498,-143.717957,0.082413,0.000000
61.130001,15.023369,-143.673477,0.009132,0.003221,0.081823,66.827286,3.404344,0.818226,-143.673477,0.082863,0.000000
61.400002,15.666824,-143.717957,0.009140,0.003243,0.082378,69.689514,3.550153,0.823779,-143.717957,0.083314,0.000000
61.670002,15.748001,-143.717957,0.009166,0.003259,0.082777,70.050606,3.568548,0.827768,-143.717957,0.083765,0.000000
61.940002,16.221291,-143.762436,0.009175,0.003280,0.083314,72.155907,3.675797,0.833142,-143.762436,0.084216,0.000000
62.210003,16.139740,-143.762436,0.009184,0.003295,0.083687,71.793152,3.657317,0.836874,-143.762436,0.084667,0.000000
62.480003,16.779846,-143.717957,0.009188,0.003317,0.084242,74.640480,3.802368,0.842423,-143.717957,0.085118,0.000000
62.750004,17.197647,-143.717957,0.009201,0.003337,0.084763,76.498955,3.897043,0.847627,-143.717957,0.085569,0.000000
63.020004,17.125038,-143.762436,0.009214,0.003350,0.085101,76.175972,3.880589,0.851011,-143.762436,0.086020,0.000000
63.290005,17.664230,-143.762436,0.009218,0.003371,0.085612,78.574417,4.002772,0.856124,-143.762436,0.086463,0.000000
63.560001,17.783760,-143.717957,0.009240,0.003387,0.086037,79.106117,4.029858,0.860375,-143.717957,0.086913,0.000000
63.830002,18.227631,-143.762436,0.009261,0.003406,0.086523,81.080551,4.130440,0.865231,-143.762436,0.087364,0.000000
64.100006,18.527016,-143.762436,0.009261,0.003423,0.086957,82.412285,4.198282,0.869568,-143.762436,0.087815,0.000000
64.370003,18.835716,-143.806915,0.009287,0.003441,0.087399,83.785454,4.268234,0.873989,-143.806915,0.088266,0.000000
64.639999,19.495560,-143.806915,0.009296,0.003461,0.087919,86.720581,4.417757,0.879193,-143.806915,0.088717,0.000000
64.910004,19.616577,-143.806915,0.009300,0.003476,0.088301,87.258896,4.445180,0.883008,-143.806915,0.089168,0.000000
65.180000,20.197105,-143.806915,0.009321,0.003496,0.088795,89.841209,4.576730,0.887951,-143.806915,0.089619,0.000000
65.450005,20.513626,-143.851395,0.009330,0.003513,0.089220,91.249168,4.648454,0.892202,-143.851395,0.090070,0.000000
65.720001,21.029732,-143.851395,0.009334,0.003532,0.089714,93.544922,4.765405,0.897145,-143.851395,0.090521,0.000000
65.990005,21.288536,-143.851395,0.009356,0.003549,0.090157,94.696136,4.824051,0.901570,-143.851395,0.090964,0.000000
66.260002,21.853424,-143.851395,0.009373,0.003569,0.090643,97.208885,4.952056,0.906426,-143.851395,0.091414,0.000000
66.530006,22.424644,-143.851395,0.009386,0.003587,0.091102,99.749802,5.081497,0.911020,-143.851395,0.091865,0.000000
66.800003,22.662216,-143.851395,0.009390,0.003602,0.091484,100.806572,5.135332,0.914836,-143.851395,0.092316,0.000000
67.070000,22.410866,-143.940353,0.009408,0.003609,0.091666,99.688507,5.078375,0.916660,-143.940353,0.092767,0.000000
67.340004,23.956955,-143.895874,0.009416,0.003639,0.092438,106.565857,5.428724,0.924377,-143.895874,0.093218,0.000000
67.610001,24.394493,-143.895874,0.009425,0.003656,0.092854,108.512123,5.527871,0.928541,-143.895874,0.093669,0.000000
67.880005,24.792183,-143.895874,0.009442,0.003674,0.093331,110.281136,5.617989,0.933310,-143.895874,0.094120,0.000000
68.150002,25.294144,-143.940353,0.009451,0.003689,0.093712,112.513969,5.731735,0.937125,-143.940353,0.094571,0.000000
68.420006,25.821419,-143.895874,0.009451,0.003706,0.094138,114.859406,5.851217,0.941375,-143.895874,0.095013,0.000000
68.690002,26.275719,-143.895874,0.009468,0.003722,0.094528,116.880234,5.954163,0.945278,-143.895874,0.095464,0.000000
68.960007,26.509567,-143.895874,0.009490,0.003735,0.094857,117.920448,6.007154,0.948570,-143.895874,0.095915,0.000000
69.230003,26.935188,-143.895874,0.009485,0.003749,0.095230,119.813698,6.103601,0.952302,-143.895874,0.096366,0.000000
69.500000,28.390793,-143.984833,0.009490,0.003776,0.095898,126.288551,6.433445,0.958979,-143.984833,0.096817,0.000000
69.770004,29.017868,-143.940353,0.009516,0.003794,0.096366,129.077927,6.575543,0.963661,-143.940353,0.097268,0.000000
70.040001,29.662071,-143.940353,0.009516,0.003811,0.096809,131.943481,6.721521,0.968085,-143.940353,0.097719,0.000000
70.310005,30.416122,-143.984833,0.009541,0.003832,0.097320,135.297668,6.892392,0.973202,-143.984833,0.098170,0.000000
70.580002,31.067032,-143.984833,0.009537,0.003847,0.097702,138.193054,7.039890,0.977018,-143.984833,0.098621,0.000000
70.850006,31.592079,-144.029312,0.009559,0.003863,0.098127,140.528580,7.158867,0.981268,-144.029312,0.099063,0.000000
71.120003,31.878059,-143.984833,0.009576,0.003876,0.098439,141.800690,7.223671,0.984387,-143.984833,0.099514,0.000000
71.390007,33.102051,-143.984833,0.009580,0.003902,0.099115,147.245270,7.501032,0.991154,-143.984833,0.099965,0.000000
71.660004,33.779770,-143.940353,0.009593,0.003916,0.099462,150.259918,7.654605,0.994621,-143.940353,0.100416,0.000000
71.930000,34.675323,-143.895874,0.009597,0.003934,0.099930,154.243546,7.857541,0.999303,-143.895874,0.100867,0.000000
72.200005,34.985512,-144.029312,0.009606,0.003947,0.100251,155.623322,7.927830,1.002513,-144.029312,0.101318,0.000000
72.470001,36.149544,-144.029312,0.009623,0.003968,0.100798,160.801208,8.191604,1.007978,-144.029312,0.101769,0.000000
72.740005,36.777367,-144.073807,0.009623,0.003984,0.101197,163.593903,8.333870,1.011967,-144.073807,0.102220,0.000000
73.010002,37.094254,-144.029312,0.009641,0.003998,0.101552,165.003479,8.405678,1.015521,-144.029312,0.102671,0.000000
73.280006,38.994843,-144.073807,0.009653,0.004023,0.102194,173.457718,8.836357,1.021941,-144.073807,0.103122,0.000000
73.550003,39.892632,-144.118286,0.009653,0.004043,0.102680,177.451294,9.039800,1.026797,-144.118286,0.103564,0.000000
73.820000,40.826912,-144.118286,0.009675,0.004059,0.103105,181.607178,9.251511,1.031047,-144.118286,0.104015,0.000000
74.090004,41.220512,-144.029312,0.009692,0.004073,0.103451,183.358002,9.340701,1.034514,-144.029312,0.104466,0.000000
74.360001,42.564407,-144.029312,0.009688,0.004096,0.104032,189.335937,9.645232,1.040324,-144.029312,0.104917,0.000000
74.630005,43.333351,-144.029312,0.009697,0.004111,0.104423,192.756378,9.819478,1.044226,-144.029312,0.105368,0.000000
74.900002,43.982773,-144.162766,0.009710,0.004127,0.104830,195.645142,9.966639,1.048302,-144.162766,0.105819,0.000000
75.170006,45.354965,-144.118286,0.009718,0.004146,0.105316,201.748962,10.277582,1.053158,-144.118286,0.106270,0.000000
75.440002,46.655663,-144.162766,0.009731,0.004166,0.105828,207.534760,10.572324,1.058276,-144.162766,0.106721,0.000000
75.710007,47.560158,-144.073807,0.009744,0.004184,0.106279,211.558151,10.777286,1.062787,-144.073807,0.107172,0.000000
75.980003,48.143288,-144.118286,0.009753,0.004198,0.106617,214.152039,10.909425,1.066167,-144.118286,0.107614,0.000000
76.250000,48.974800,-144.207245,0.009757,0.004215,0.107068,217.850784,11.097848,1.070679,-144.207245,0.108065,0.000000
76.520004,50.705582,-144.162766,0.009770,0.004238,0.107640,225.549698,11.490049,1.076401,-144.162766,0.108516,0.000000
76.790001,50.934593,-144.162766,0.009787,0.004247,0.107874,226.568390,11.541945,1.078744,-144.162766,0.108967,0.000000
77.060005,52.866837,-144.118286,0.009779,0.004275,0.108577,235.163437,11.979796,1.085765,-144.118286,0.109418,0.000000
77.330002,54.107582,-144.162766,0.009796,0.004292,0.109019,240.682541,12.260954,1.090190,-144.162766,0.109869,0.000000
77.600006,54.991592,-144.340683,0.009796,0.004308,0.109427,244.614822,12.461273,1.094266,-144.340683,0.110320,0.000000
77.870003,55.802246,-144.251724,0.009809,0.004323,0.109808,248.220795,12.644969,1.098081,-144.251724,0.110771,0.000000
78.140007,56.848244,-144.162766,0.009817,0.004340,0.110233,252.873611,12.881996,1.102332,-144.162766,0.111222,0.000000
78.410004,58.393585,-144.207245,0.009826,0.004360,0.110754,259.747650,13.232176,1.107536,-144.207245,0.111673,0.000000
78.680000,58.945068,-144.207245,0.009826,0.004372,0.111040,262.200745,13.357143,1.110397,-144.207245,0.112115,0.000000
78.950005,60.441261,-144.207245,0.009830,0.004392,0.111551,268.856171,13.696185,1.115515,-144.207245,0.112566,0.000000
79.220001,62.344086,-144.251724,0.009848,0.004417,0.112193,277.320343,14.127372,1.121930,-144.251724,0.113017,0.000000
79.490005,63.425079,-144.296204,0.009856,0.004431,0.112549,282.128845,14.372328,1.125488,-144.296204,0.113468,0.000000
79.760002,64.123657,-144.207245,0.009860,0.004444,0.112887,285.236267,14.530628,1.128868,-144.207245,0.113919,0.000000
80.030006,65.444824,-144.207245,0.009873,0.004462,0.113347,291.113129,14.830009,1.133466,-144.207245,0.114370,0.000000
80.300003,66.837128,-144.340683,0.009878,0.004480,0.113797,297.306396,15.145510,1.137974,-144.340683,0.114821,0.000000
80.570007,67.204285,-144.207245,0.009891,0.004481,0.113824,298.939575,15.228708,1.138235,-144.207245,0.114049,0.000000
80.840004,66.598068,-144.251724,0.009895,0.004481,0.113824,296.243011,15.091338,1.138235,-144.251724,0.114049,0.000000
81.110001,66.169464,-144.251724,0.009895,0.004480,0.113780,294.336487,14.994215,1.137800,-144.251724,0.113824,0.000000
81.380005,65.720764,-144.385162,0.009886,0.004479,0.113771,292.340546,14.892538,1.137713,-144.385162,0.113824,0.000000
81.650002,65.300720,-144.340683,0.009904,0.004479,0.113763,290.472107,14.797355,1.137626,-144.340683,0.113824,0.000000
81.920006,64.935425,-144.251724,0.009904,0.004479,0.113763,288.847198,14.714578,1.137626,-144.251724,0.113824,0.000000
82.190002,64.608856,-144.296204,0.009904,0.004479,0.113763,287.394531,14.640576,1.137626,-144.296204,0.113824,0.000000
82.460007,64.323624,-144.340683,0.009895,0.004478,0.113754,286.125763,14.575941,1.137539,-144.340683,0.113824,0.000000
82.730003,64.059982,-144.340683,0.009908,0.004478,0.113754,284.953033,14.516200,1.137539,-144.340683,0.113824,0.000000
83.000008,63.810486,-144.385162,0.009899,0.004478,0.113754,283.843231,14.459662,1.137539,-144.385162,0.113824,0.000000
83.270004,63.603455,-144.296204,0.009912,0.004478,0.113754,282.922302,14.412748,1.137539,-144.296204,0.113824,0.000000
83.540001,63.395660,-144.340683,0.009921,0.004478,0.113754,281.997986,14.365662,1.137539,-144.340683,0.113824,0.000000
83.810005,63.190491,-144.296204,0.009925,0.004478,0.113754,281.085327,14.319170,1.137539,-144.296204,0.113824,0.000000
84.080002,63.011375,-144.385162,0.009916,0.004478,0.113754,280.288605,14.278582,1.137539,-144.385162,0.113824,0.000000
84.350006,62.836365,-144.429642,0.009925,0.004478,0.113754,279.510101,14.238923,1.137539,-144.429642,0.113824,0.000000
84.620003,62.694489,-144.340683,0.009916,0.004478,0.113754,278.879028,14.206774,1.137539,-144.340683,0.113824,0.000000
84.890007,62.549263,-144.385162,0.009916,0.004478,0.113746,278.233032,14.173865,1.137456,-144.385162,0.113824,0.000000
85.160004,62.401428,-144.385162,0.009925,0.004478,0.113746,277.575409,14.140366,1.137456,-144.385162,0.113824,0.000000
85.430000,62.273338,-144.429642,0.009916,0.004478,0.113746,277.005646,14.111340,1.137456,-144.429642,0.113824,0.000000
85.700005,62.140770,-144.474136,0.009921,0.004478,0.113746,276.415955,14.081300,1.137456,-144.474136,0.113824,0.000000
85.970001,62.033897,-144.429642,0.009925,0.004478,0.113746,275.940552,14.057082,1.137456,-144.429642,0.113824,0.000000
86.240005,61.927399,-144.385162,0.009929,0.004478,0.113746,275.466827,14.032948,1.137456,-144.385162,0.113824,0.000000
86.510002,61.809731,-144.474136,0.009916,0.004478,0.113746,274.943420,14.006286,1.137456,-144.474136,0.113824,0.000000
86.780006,61.725204,-144.474136,0.009938,0.004478,0.113746,274.567413,13.987131,1.137456,-144.474136,0.113824,0.000000
87.050003,61.618332,-144.429642,0.009925,0.004478,0.113746,274.092041,13.962914,1.137456,-144.429642,0.113824,0.000000
87.320007,61.516678,-144.474136,0.009934,0.004478,0.113746,273.639862,13.939878,1.137456,-144.474136,0.113824,0.000000
87.590004,61.434006,-144.429642,0.009934,0.004478,0.113746,273.272095,13.921144,1.137456,-144.429642,0.113824,0.000000
87.860001,61.328995,-144.474136,0.009916,0.004478,0.113746,272.804993,13.897349,1.137456,-144.474136,0.113824,0.000000
88.130005,61.244843,-144.518616,0.009938,0.004478,0.113746,272.430664,13.878280,1.137456,-144.518616,0.113824,0.000000
88.400002,61.173721,-144.563095,0.009929,0.004478,0.113746,272.114288,13.862163,1.137456,-144.563095,0.113824,0.000000
88.670006,61.087700,-144.474136,0.009934,0.004478,0.113746,271.731659,13.842670,1.137456,-144.474136,0.113824,0.000000
88.940002,61.020676,-144.474136,0.009925,0.004478,0.113746,271.433533,13.827482,1.137456,-144.474136,0.113824,0.000000
89.210007,60.954018,-144.518616,0.009921,0.004478,0.113746,271.137024,13.812378,1.137456,-144.518616,0.113824,0.000000
89.480003,60.872101,-144.563095,0.009938,0.004478,0.113746,270.772614,13.793816,1.137456,-144.563095,0.113824,0.000000
89.750008,60.800972,-144.518616,0.009921,0.004478,0.113746,270.456238,13.777698,1.137456,-144.518616,0.113824,0.000000
90.020004,60.739159,-144.474136,0.009925,0.004478,0.113746,270.181274,13.763690,1.137456,-144.474136,0.113824,0.000000
90.290001,60.669151,-144.563095,0.009934,0.004478,0.113746,269.869873,13.747826,1.137456,-144.563095,0.113824,0.000000
90.560005,60.618141,-144.607574,0.009938,0.004478,0.113746,269.642944,13.736267,1.137456,-144.607574,0.113824,0.000000
90.830002,60.558189,-144.563095,0.009929,0.004478,0.113746,269.376282,13.722682,1.137456,-144.563095,0.113824,0.000000
91.100006,60.480362,-144.563095,0.009938,0.004478,0.113746,269.030090,13.705046,1.137456,-144.563095,0.113824,0.000000
91.370003,60.433815,-144.563095,0.009934,0.004478,0.113746,268.823029,13.694498,1.137456,-144.563095,0.113824,0.000000
91.640007,60.388382,-144.563095,0.009934,0.004478,0.113746,268.620941,13.684202,1.137456,-144.563095,0.113824,0.000000
91.910004,60.331413,-144.607574,0.009938,0.004478,0.113746,268.367523,13.671294,1.137456,-144.607574,0.113824,0.000000
92.180008,60.286354,-144.563095,0.009938,0.004478,0.113746,268.167084,13.661083,1.137456,-144.563095,0.113824,0.000000
92.450005,60.232735,-144.607574,0.009929,0.004478,0.113746,267.928589,13.648932,1.137456,-144.607574,0.113824,0.000000
92.720001,60.175018,-144.652054,0.009942,0.004478,0.113746,267.671844,13.635855,1.137456,-144.652054,0.113824,0.000000
92.990005,60.130333,-144.696533,0.009942,0.004478,0.113746,267.473083,13.625729,1.137456,-144.696533,0.113824,0.000000
93.260002,60.088997,-144.652054,0.009947,0.004478,0.113746,267.289215,13.616362,1.137456,-144.652054,0.113824,0.000000
93.530006,60.051018,-144.696533,0.009934,0.004478,0.113746,267.120270,13.607755,1.137456,-144.696533,0.113824,0.000000
93.800003,60.002235,-144.652054,0.009947,0.004478,0.113746,266.903259,13.596702,1.137456,-144.652054,0.113824,0.000000
94.070007,59.959038,-144.652054,0.009942,0.004478,0.113746,266.711121,13.586912,1.137456,-144.652054,0.113824,0.000000
94.340004,59.905792,-144.696533,0.009934,0.004478,0.113746,266.474274,13.574846,1.137456,-144.696533,0.113824,0.000000
94.610008,59.868927,-144.741013,0.009938,0.004478,0.113746,266.310303,13.566493,1.137456,-144.741013,0.113824,0.000000
94.880005,59.837646,-144.652054,0.009947,0.004478,0.113746,266.171143,13.559404,1.137456,-144.652054,0.113824,0.000000
95.150002,59.790726,-144.652054,0.009942,0.004478,0.113746,265.962433,13.548772,1.137456,-144.652054,0.113824,0.000000
95.420006,59.747162,-144.741013,0.009934,0.004478,0.113746,265.768646,13.538900,1.137456,-144.741013,0.113824,0.000000
95.690002,59.708061,-144.741013,0.009947,0.004478,0.113746,265.594727,13.530040,1.137456,-144.741013,0.113824,0.000000
95.960007,59.664864,-144.785492,0.009942,0.004478,0.113746,265.402557,13.520251,1.137456,-144.785492,0.113824,0.000000
96.230003,59.635078,-144.652054,0.009942,0.004478,0.113746,265.270081,13.513502,1.137456,-144.652054,0.113824,0.000000
96.500008,59.623901,-144.652054,0.009942,0.004478,0.113746,265.220367,13.510969,1.137456,-144.652054,0.113824,0.000000
96.770004,59.577362,-144.741013,0.009951,0.004478,0.113746,265.013336,13.500423,1.137456,-144.741013,0.113824,0.000000
97.040001,59.536026,-144.785492,0.009947,0.004478,0.113746,264.829468,13.491056,1.137456,-144.785492,0.113824,0.000000
97.310005,59.499161,-144.741013,0.009942,0.004478,0.113746,264.665497,13.482702,1.137456,-144.741013,0.113824,0.000000
97.580002,59.456337,-144.741013,0.009938,0.004478,0.113746,264.475006,13.472999,1.137456,-144.741013,0.113824,0.000000
97.850006,59.426178,-144.696533,0.009938,0.004478,0.113746,264.340851,13.466165,1.137456,-144.696533,0.113824,0.000000
98.120003,59.403091,-144.785492,0.009938,0.004478,0.113746,264.238159,13.460933,1.137456,-144.785492,0.113824,0.000000
98.390007,59.377022,-144.829971,0.009934,0.004478,0.113746,264.122192,13.455026,1.137456,-144.829971,0.113824,0.000000
98.660004,59.330475,-144.829971,0.009942,0.004478,0.113746,263.915131,13.444478,1.137456,-144.829971,0.113824,0.000000
98.930008,59.303665,-144.785492,0.009951,0.004478,0.113746,263.795868,13.438403,1.137456,-144.785492,0.113824,0.000000
99.200005,59.266052,-144.829971,0.009938,0.004478,0.113746,263.628571,13.429879,1.137456,-144.829971,0.113824,0.000000
99.470001,59.241104,-144.829971,0.009929,0.004478,0.113746,263.517578,13.424226,1.137456,-144.829971,0.113824,0.000000
99.740005,59.218765,-144.874451,0.009934,0.004478,0.113746,263.418213,13.419164,1.137456,-144.874451,0.113824,0.000000
100.010002,59.182640,-144.829971,0.009942,0.004478,0.113746,263.257538,13.410977,1.137456,-144.829971,0.113824,0.000000
100.280006,59.150993,-144.829971,0.009934,0.004478,0.113746,263.116760,13.403807,1.137456,-144.829971,0.113824,0.000000
100.550003,59.123436,-144.785492,0.009942,0.004478,0.113746,262.994171,13.397562,1.137456,-144.785492,0.113824,0.000000
100.820007,59.101837,-144.829971,0.009934,0.004478,0.113746,262.898102,13.392668,1.137456,-144.829971,0.113824,0.000000
101.090004,59.070190,-144.829971,0.009934,0.004478,0.113746,262.757324,13.385496,1.137456,-144.829971,0.113824,0.000000
101.360008,59.041885,-144.918945,0.009942,0.004478,0.113746,262.631409,13.379083,1.137456,-144.918945,0.113824,0.000000
101.630005,59.019920,-144.874451,0.009942,0.004478,0.113746,262.533722,13.374104,1.137456,-144.874451,0.113824,0.000000
101.900002,58.978210,-144.829971,0.009938,0.004478,0.113746,262.348175,13.364654,1.137456,-144.829971,0.113824,0.000000
102.170006,58.948418,-144.918945,0.009947,0.004478,0.113746,262.215668,13.357903,1.137456,-144.918945,0.113824,0.000000
102.440002,58.935387,-144.874451,0.009942,0.004478,0.113746,262.157684,13.354949,1.137456,-144.874451,0.113824,0.000000
102.710007,58.896286,-144.874451,0.009947,0.004478,0.113746,261.983765,13.346089,1.137456,-144.874451,0.113824,0.000000
102.980003,58.884003,-144.874451,0.009947,0.004478,0.113746,261.929138,13.343306,1.137456,-144.874451,0.113824,0.000000
103.250008,58.854584,-144.918945,0.009934,0.004478,0.113746,261.798279,13.336639,1.137456,-144.918945,0.113824,0.000000
103.520004,58.830376,-144.963425,0.009934,0.004478,0.113746,261.690582,13.331154,1.137456,-144.963425,0.113824,0.000000
103.790009,58.810646,-144.874451,0.009938,0.004478,0.113746,261.602814,13.326683,1.137456,-144.874451,0.113824,0.000000
104.060005,58.773407,-144.918945,0.009951,0.004478,0.113746,261.437164,13.318245,1.137456,-144.918945,0.113824,0.000000
104.330002,58.757393,-144.918945,0.009942,0.004478,0.113746,261.365936,13.314616,1.137456,-144.918945,0.113824,0.000000
104.600006,58.734306,-144.963425,0.009934,0.004478,0.113746,261.263245,13.309384,1.137456,-144.963425,0.113824,0.000000
104.870003,58.720528,-145.052383,0.009947,0.004478,0.113746,261.201965,13.306262,1.137456,-145.052383,0.113824,0.000000
105.140007,58.682922,-145.007904,0.009955,0.004478,0.113746,261.034668,13.297740,1.137456,-145.007904,0.113824,0.000000
105.410004,58.653877,-144.918945,0.009947,0.004478,0.113746,260.905487,13.291159,1.137456,-144.918945,0.113824,0.000000
105.680008,58.642700,-144.963425,0.009942,0.004478,0.113746,260.855743,13.288627,1.137456,-144.963425,0.113824,0.000000
105.950005,58.610306,-145.007904,0.009942,0.004478,0.113746,260.711670,13.281285,1.137456,-145.007904,0.113824,0.000000
106.220009,58.607704,-145.007904,0.009951,0.004478,0.113746,260.700073,13.280695,1.137456,-145.007904,0.113824,0.000000
106.490005,58.587967,-144.963425,0.009942,0.004478,0.113746,260.612305,13.276223,1.137456,-144.963425,0.113824,0.000000
106.760002,58.560036,-145.007904,0.009951,0.004478,0.113746,260.488037,13.269894,1.137456,-145.007904,0.113824,0.000000
107.030006,58.542908,-145.007904,0.009942,0.004478,0.113746,260.411865,13.266013,1.137456,-145.007904,0.113824,0.000000
107.300003,58.530251,-145.007904,0.009942,0.004478,0.113746,260.355560,13.263144,1.137456,-145.007904,0.113824,0.000000
107.570007,58.505669,-145.052383,0.009942,0.004478,0.113746,260.246216,13.257574,1.137456,-145.052383,0.113824,0.000000
107.840004,58.492638,-145.007904,0.009942,0.004478,0.113746,260.188232,13.254622,1.137456,-145.007904,0.113824,0.000000
108.110008,58.463593,-145.096863,0.009951,0.004478,0.113746,260.059052,13.248039,1.137456,-145.096863,0.113824,0.000000
108.380005,58.455399,-145.096863,0.009938,0.004478,0.113746,260.022614,13.246182,1.137456,-145.096863,0.113824,0.000000
108.650002,58.425980,-145.096863,0.009934,0.004478,0.113746,259.891724,13.239516,1.137456,-145.096863,0.113824,0.000000
108.920006,58.437157,-145.052383,0.009955,0.004478,0.113746,259.941467,13.242049,1.137456,-145.052383,0.113824,0.000000
109.190002,58.411461,-145.141342,0.009951,0.004478,0.113746,259.827148,13.236226,1.137456,-145.141342,0.113824,0.000000
109.460007,58.384651,-145.096863,0.009947,0.004478,0.113746,259.707886,13.230151,1.137456,-145.096863,0.113824,0.000000
109.730003,58.371246,-145.096863,0.009942,0.004478,0.113746,259.648285,13.227114,1.137456,-145.096863,0.113824,0.000000
110.000008,58.342941,-145.052383,0.009951,0.004478,0.113746,259.522369,13.220699,1.137456,-145.052383,0.113824,0.000000
110.270004,58.337730,-145.096863,0.009947,0.004478,0.113746,259.499176,13.219519,1.137456,-145.096863,0.113824,0.000000
110.540009,58.323578,-145.096863,0.009955,0.004478,0.113746,259.436218,13.216312,1.137456,-145.096863,0.113824,0.000000
110.810005,58.310547,-145.052383,0.009938,0.004478,0.113746,259.378265,13.213359,1.137456,-145.052383,0.113824,0.000000
111.000008,58.294533,-145.185822,0.009938,0.004478,0.113746,259.307037,13.209730,1.137456,-145.185822,0.113824,0.000000