File: Data/compression 8/AutoHeating-17-8-1-1-240328_03282024_153404.csv
Time (sec),S:Load (lbs),S:HL1 (DIM),S:LVDT (in),S:Position (in),Ch:Position (mm),Ch:Load (N),Ch:Stress (MPa),Ch:Strain (mm/mm),Ch:HL1 (DIM),Set Point (),Cycles ()
0.110000,0.008934,-149.322556,-0.000017,-0.000000,-0.000000,0.039741,0.002024,-0.000000,-149.322556,0.000182,0.000000
0.330000,-0.014526,-149.322556,0.000004,-0.000000,-0.000000,-0.064617,-0.003292,-0.000000,-149.322556,0.000182,0.000000
0.550000,0.002975,-149.367035,-0.000013,0.000094,0.002377,0.013236,0.000674,0.023765,-149.367035,0.003096,0.000000
0.770000,0.013031,-149.322556,0.000078,0.000220,0.005576,0.057965,0.002953,0.055763,-149.322556,0.006756,0.000000
0.990000,0.020851,-149.322556,0.000233,0.000373,0.009479,0.092750,0.004725,0.094789,-149.322556,0.010416,0.000000
1.210000,-0.014526,-149.411514,0.000371,0.000515,0.013078,-0.064617,-0.003292,0.130779,-149.411514,0.014093,0.000000
1.430000,-0.021973,-149.411514,0.000526,0.000657,0.016686,-0.097739,-0.004979,0.166857,-149.411514,0.017752,0.000000
1.650000,0.006699,-149.455994,0.000673,0.000801,0.020354,0.029797,0.001518,0.203540,-149.455994,0.021412,0.000000
1.870000,-0.012665,-149.411514,0.000823,0.000944,0.023988,-0.056336,-0.002870,0.239875,-149.411514,0.025089,0.000000
2.090000,0.020103,-149.367035,0.000957,0.001085,0.027552,0.089425,0.004556,0.275518,-149.367035,0.028749,0.000000
2.310000,-0.016388,-149.367035,0.001095,0.001231,0.031255,-0.072897,-0.003714,0.312549,-149.367035,0.032409,0.000000
2.530000,-0.024582,-149.411514,0.001246,0.001375,0.034915,-0.109346,-0.005570,0.349145,-149.411514,0.036086,0.000000
2.750000,-0.029045,-149.455994,0.001397,0.001524,0.038713,-0.129199,-0.006582,0.387130,-149.455994,0.039745,0.000000
2.970000,0.001488,-149.411514,0.001548,0.001663,0.042234,0.006618,0.000337,0.422341,-149.411514,0.043405,0.000000
3.190000,-0.006706,-149.411514,0.001699,0.001809,0.045937,-0.029831,-0.001520,0.459373,-149.411514,0.047082,0.000000
3.410000,0.022339,-149.455994,0.001832,0.001959,0.049753,0.099368,0.005062,0.497528,-149.455994,0.050741,0.000000
3.630000,0.004097,-149.500473,0.001975,0.002096,0.053248,0.018224,0.000928,0.532478,-149.500473,0.054401,0.000000
3.850000,0.016380,-149.455994,0.002121,0.002237,0.056812,0.072863,0.003712,0.568120,-149.455994,0.058061,0.000000
4.070000,0.001488,-149.455994,0.002281,0.002386,0.060611,0.006618,0.000337,0.606106,-149.455994,0.061738,0.000000
4.290000,0.007446,-149.455994,0.002414,0.002536,0.064426,0.033123,0.001687,0.644265,-149.455994,0.065398,0.000000
4.510000,-0.068893,-149.455994,0.002565,0.002678,0.068017,-0.306453,-0.015611,0.680168,-149.455994,0.069057,0.000000
4.730000,-0.052132,-149.544952,0.002712,0.002816,0.071529,-0.231893,-0.011813,0.715288,-149.544952,0.072734,0.000000
4.950000,-0.023087,-149.455994,0.002846,0.002964,0.075276,-0.102694,-0.005231,0.752755,-149.455994,0.076394,0.000000
5.170000,0.013031,-149.500473,0.003014,0.003110,0.078996,0.057965,0.002953,0.789957,-149.500473,0.080054,0.000000
5.390000,0.055481,-149.455994,0.003147,0.003250,0.082560,0.246792,0.012572,0.825599,-149.455994,0.083731,0.000000
5.610000,0.042076,-149.411514,0.003290,0.003397,0.086289,0.187164,0.009535,0.862892,-149.411514,0.087391,0.000000
5.830000,0.032021,-149.589432,0.003449,0.003544,0.090027,0.142435,0.007256,0.900268,-149.589432,0.091050,0.000000
6.050000,-0.004845,-149.544952,0.003600,0.003689,0.093712,-0.021550,-0.001098,0.937125,-149.544952,0.094727,0.000000
6.270000,-0.014900,-149.500473,0.003738,0.003829,0.097268,-0.066279,-0.003376,0.972680,-149.500473,0.098387,0.000000
6.490000,-0.008568,-149.500473,0.003885,0.003971,0.100876,-0.038112,-0.001941,1.008758,-149.500473,0.102046,0.000000
6.710001,0.017502,-149.544952,0.004027,0.004121,0.104683,0.077852,0.003966,1.046830,-149.544952,0.105723,0.000000
6.930000,-0.000748,-149.589432,0.004174,0.004262,0.108256,-0.003326,-0.000169,1.082559,-149.589432,0.109383,0.000000
7.150001,0.045052,-149.500473,0.004312,0.004402,0.111820,0.200399,0.010209,1.118202,-149.500473,0.113043,0.000000
7.370000,0.023827,-149.544952,0.004471,0.004553,0.115636,0.105986,0.005399,1.156361,-149.544952,0.116703,0.000000
7.590000,0.045052,-149.544952,0.004613,0.004700,0.119391,0.200399,0.010209,1.193911,-149.544952,0.120380,0.000000
7.810000,-0.002609,-149.589432,0.004764,0.004841,0.122955,-0.011607,-0.000591,1.229553,-149.589432,0.124039,0.000000
8.030001,0.027550,-149.589432,0.004902,0.004983,0.126563,0.122547,0.006243,1.265631,-149.589432,0.127699,0.000000
8.250000,0.013779,-149.589432,0.005053,0.005127,0.130223,0.061291,0.003122,1.302227,-149.589432,0.131376,0.000000
8.470000,0.022713,-149.589432,0.005208,0.005273,0.133943,0.101031,0.005147,1.339433,-149.589432,0.135036,0.000000
8.690001,0.014519,-149.589432,0.005346,0.005413,0.137490,0.064583,0.003290,1.374901,-149.589432,0.138696,0.000000
8.910001,-0.000000,-149.589432,0.005484,0.005557,0.141158,-0.000000,-0.000000,1.411584,-149.589432,0.142373,0.000000
9.130000,0.013405,-149.589432,0.005639,0.005707,0.144966,0.059628,0.003038,1.449656,-149.589432,0.146032,0.000000
9.350000,0.084900,-149.633926,0.005773,0.005848,0.148547,0.377654,0.019239,1.485473,-149.633926,0.149692,0.000000
9.570001,0.752563,-149.633926,0.005902,0.005966,0.151531,3.347569,0.170533,1.515305,-149.633926,0.152779,0.000000
9.790001,0.673248,-149.589432,0.005911,-0.000000,-0.000000,2.994758,0.152560,-0.000000,-149.589432,0.000208,0.000000
10.010000,0.649040,-149.678406,0.005902,-0.000000,-0.000000,2.887075,0.147075,-0.000000,-149.678406,0.000208,0.000000
10.230000,0.675850,-149.678406,0.005907,-0.000000,-0.000000,3.006330,0.153150,-0.000000,-149.678406,0.000434,0.000000
10.450001,0.619621,-149.678406,0.005911,-0.000000,-0.000000,2.756213,0.140408,-0.000000,-149.678406,0.000807,0.000000
10.670000,0.647552,-149.589432,0.005907,-0.000000,-0.000000,2.880457,0.146737,-0.000000,-149.589432,0.001171,0.000000
10.890000,0.632660,-149.633926,0.005907,-0.000000,-0.000000,2.814212,0.143363,-0.000000,-149.633926,0.001535,0.000000
11.110001,1.131264,-149.633926,0.005937,0.000045,0.001154,5.032113,0.256348,0.011536,-149.633926,0.001908,0.000000
11.330001,1.283562,-149.722885,0.005941,0.000056,0.001422,5.709568,0.290859,0.014224,-149.722885,0.002272,0.000000
11.550000,1.417244,-149.678406,0.005963,0.000067,0.001709,6.304216,0.321152,0.017085,-149.678406,0.002637,0.000000
11.770000,1.706955,-149.678406,0.005971,0.000085,0.002159,7.592915,0.386802,0.021593,-149.678406,0.003001,0.000000
11.990001,1.913994,-149.678406,0.005989,0.000100,0.002532,8.513870,0.433717,0.025325,-149.678406,0.003373,0.000000
12.210001,2.208168,-149.722885,0.006006,0.000118,0.003009,9.822422,0.500378,0.030094,-149.722885,0.003738,0.000000
12.430000,2.346687,-149.722885,0.006015,0.000132,0.003348,10.438586,0.531767,0.033477,-149.722885,0.004102,0.000000
12.650001,2.500847,-149.722885,0.006023,0.000141,0.003590,11.124323,0.566700,0.035904,-149.722885,0.004475,0.000000
12.870001,2.841202,-149.722885,0.006040,0.000159,0.004042,12.638297,0.643826,0.040415,-149.722885,0.004839,0.000000
13.090000,3.079887,-149.678406,0.006045,0.000174,0.004423,13.700024,0.697912,0.044230,-149.678406,0.005203,0.000000
13.310000,3.293633,-149.722885,0.006066,0.000188,0.004770,14.650809,0.746348,0.047697,-149.722885,0.005568,0.000000
13.530001,3.448540,-149.767365,0.006066,0.000196,0.004969,15.339870,0.781450,0.049692,-149.767365,0.005940,0.000000
13.750001,3.791862,-149.767365,0.006088,0.000213,0.005403,16.867046,0.859248,0.054029,-149.767365,0.006305,0.000000
13.970000,4.161629,-149.722885,0.006109,0.000234,0.005949,18.511848,0.943039,0.059491,-149.722885,0.006669,0.000000
14.190001,4.341484,-149.722885,0.006109,0.000246,0.006253,19.311886,0.983794,0.062526,-149.722885,0.007033,0.000000
14.410001,4.490440,-149.767365,0.006114,0.000259,0.006574,19.974476,1.017548,0.065736,-149.767365,0.007406,0.000000
14.630001,4.716469,-149.811844,0.006140,0.000271,0.006886,20.979900,1.068767,0.068859,-149.811844,0.007770,0.000000
14.850000,4.959625,-149.811844,0.006153,0.000286,0.007259,22.061516,1.123867,0.072587,-149.811844,0.008134,0.000000
15.070001,5.104851,-149.767365,0.006161,0.000297,0.007554,22.707510,1.156776,0.075535,-149.767365,0.008508,0.000000
15.290001,5.345779,-149.722885,0.006170,0.000312,0.007918,23.779215,1.211371,0.079180,-149.722885,0.008872,0.000000
15.510001,5.528236,-149.811844,0.006165,0.000323,0.008195,24.590824,1.252716,0.081954,-149.811844,0.009236,0.000000
15.730000,5.729317,-149.811844,0.006196,0.000335,0.008516,25.485273,1.298282,0.085164,-149.811844,0.009600,0.000000
15.950001,6.272614,-149.811844,0.006222,0.000360,0.009132,27.901978,1.421395,0.091318,-149.811844,0.009973,0.000000
16.170000,6.354164,-149.811844,0.006230,0.000372,0.009461,28.264734,1.439874,0.094615,-149.811844,0.010337,0.000000
16.390001,6.525826,-149.811844,0.006234,0.000388,0.009852,29.028322,1.478773,0.098517,-149.811844,0.010702,0.000000
16.610001,6.667328,-149.856323,0.006243,0.000401,0.010181,29.657755,1.510838,0.101814,-149.856323,0.011075,0.000000
16.830000,6.880325,-149.856323,0.006265,0.000417,0.010598,30.605215,1.559104,0.105977,-149.856323,0.011439,0.000000
17.050001,7.084007,-149.856323,0.006286,0.000430,0.010927,31.511238,1.605259,0.109270,-149.856323,0.011803,0.000000
17.270000,7.255676,-149.856323,0.006291,0.000447,0.011361,32.274860,1.644160,0.113607,-149.856323,0.012167,0.000000
17.490002,7.270569,-149.856323,0.006299,0.000456,0.011595,32.341106,1.647534,0.115950,-149.856323,0.012540,0.000000
17.710001,7.279503,-149.856323,0.006303,0.000464,0.011777,32.380844,1.649559,0.117771,-149.856323,0.012904,0.000000
17.930000,7.776993,-149.900803,0.006334,0.000489,0.012419,34.593792,1.762292,0.124186,-149.900803,0.013269,0.000000
18.150002,7.915520,-149.856323,0.006347,0.000503,0.012783,35.209991,1.793682,0.127831,-149.856323,0.013642,0.000000
18.370001,7.988129,-149.856323,0.006359,0.000518,0.013147,35.532970,1.810136,0.131472,-149.856323,0.014006,0.000000
18.590000,8.033188,-149.900803,0.006368,0.000530,0.013451,35.733406,1.820346,0.134508,-149.900803,0.014370,0.000000
18.810001,8.132614,-149.900803,0.006385,0.000543,0.013780,36.175674,1.842877,0.137804,-149.900803,0.014734,0.000000
19.030001,8.307251,-149.945282,0.006390,0.000557,0.014153,36.952499,1.882450,0.141532,-149.945282,0.015107,0.000000
19.250000,8.391037,-149.900803,0.006411,0.000572,0.014517,37.325195,1.901436,0.145173,-149.900803,0.015472,0.000000
19.470001,8.387688,-149.856323,0.006416,0.000579,0.014717,37.310299,1.900677,0.147168,-149.856323,0.015836,0.000000
19.690001,8.486740,-149.945282,0.006420,0.000597,0.015168,37.750904,1.923123,0.151680,-149.945282,0.016208,0.000000
19.910002,8.937683,-149.945282,0.006433,0.000618,0.015697,39.756802,2.025308,0.156967,-149.945282,0.016573,0.000000
20.130001,9.068008,-149.945282,0.006467,0.000635,0.016130,40.336517,2.054840,0.161305,-149.945282,0.016937,0.000000
20.350000,9.013275,-149.945282,0.006485,0.000647,0.016425,40.093052,2.042437,0.164253,-149.945282,0.017301,0.000000
20.570002,8.948853,-149.900803,0.006502,0.000659,0.016746,39.806484,2.027839,0.167463,-149.900803,0.017674,0.000000
20.790001,9.131683,-149.945282,0.006510,0.000675,0.017136,40.619755,2.069269,0.171365,-149.945282,0.018038,0.000000
21.010000,9.329048,-149.900803,0.006523,0.000689,0.017509,41.497677,2.113992,0.175093,-149.900803,0.018403,0.000000
21.230001,9.368515,-150.034241,0.006523,0.000703,0.017865,41.673237,2.122936,0.178651,-150.034241,0.018775,0.000000
21.450001,9.260529,-149.989761,0.006536,0.000713,0.018108,41.192890,2.098466,0.181077,-149.989761,0.019140,0.000000
21.670000,9.683174,-149.945282,0.006566,0.000734,0.018646,43.072910,2.194239,0.186455,-149.945282,0.019504,0.000000
21.890001,9.820946,-149.945282,0.006562,0.000751,0.019088,43.685749,2.225458,0.190876,-149.945282,0.019868,0.000000
22.110001,9.747215,-150.034241,0.006584,0.000761,0.019339,43.357780,2.208751,0.193393,-150.034241,0.020241,0.000000
22.330002,9.743866,-150.078735,0.006597,0.000775,0.019686,43.342880,2.207992,0.196860,-150.078735,0.020605,0.000000
22.550001,9.752808,-150.034241,0.006618,0.000788,0.020007,43.382656,2.210018,0.200070,-150.034241,0.020969,0.000000
22.770000,9.896172,-149.989761,0.006635,0.000801,0.020345,44.020370,2.242505,0.203453,-149.989761,0.021343,0.000000
22.990002,10.140442,-149.945282,0.006640,0.000819,0.020814,45.106937,2.297857,0.208135,-149.945282,0.021707,0.000000
23.210001,10.189598,-150.034241,0.006648,0.000833,0.021169,45.325596,2.308996,0.211689,-150.034241,0.022071,0.000000
23.430000,10.053680,-150.078735,0.006661,0.000841,0.021351,44.721004,2.278197,0.213513,-150.078735,0.022435,0.000000
23.650002,10.621552,-149.989761,0.006696,0.000868,0.022045,47.247021,2.406878,0.220451,-149.989761,0.022808,0.000000
23.870001,10.561226,-150.034241,0.006704,0.000881,0.022366,46.978680,2.393208,0.223657,-150.034241,0.023172,0.000000
24.090002,10.532555,-150.034241,0.006713,0.000892,0.022669,46.851143,2.386711,0.226692,-150.034241,0.023537,0.000000
24.310001,10.558617,-150.034241,0.006722,0.000905,0.022999,46.967072,2.392617,0.229989,-150.034241,0.023910,0.000000
24.530001,10.430153,-150.078735,0.006730,0.000915,0.023242,46.395638,2.363506,0.232419,-150.078735,0.024274,0.000000
24.750002,10.734749,-150.123215,0.006756,0.000934,0.023719,47.750549,2.432529,0.237188,-150.123215,0.024638,0.000000
24.970001,11.030411,-150.078735,0.006769,0.000952,0.024187,49.065716,2.499527,0.241870,-150.078735,0.025002,0.000000
25.190001,10.867691,-150.078735,0.006769,0.000960,0.024378,48.341904,2.462654,0.243778,-150.078735,0.025375,0.000000
25.410002,10.988335,-150.034241,0.006786,0.000975,0.024759,48.878555,2.489992,0.247593,-150.034241,0.025739,0.000000
25.630001,11.168938,-150.078735,0.006795,0.000991,0.025176,49.681915,2.530918,0.251756,-150.078735,0.026104,0.000000
25.850000,11.509659,-150.123215,0.006821,0.001012,0.025696,51.197521,2.608126,0.256960,-150.123215,0.026476,0.000000
26.070002,11.333153,-150.078735,0.006829,0.001020,0.025913,50.412380,2.568129,0.259129,-150.078735,0.026841,0.000000
26.290001,11.320496,-150.034241,0.006838,0.001034,0.026268,50.356079,2.565261,0.262683,-150.034241,0.027205,0.000000
26.510002,11.447098,-150.167694,0.006851,0.001049,0.026650,50.919235,2.593950,0.266498,-150.167694,0.027569,0.000000
26.730001,11.618019,-150.167694,0.006873,0.001064,0.027031,51.679531,2.632681,0.270313,-150.167694,0.027942,0.000000
26.950001,11.767715,-150.078735,0.006894,0.001080,0.027422,52.345413,2.666603,0.274216,-150.078735,0.028306,0.000000
27.170002,11.728241,-150.123215,0.006894,0.001092,0.027734,52.169823,2.657657,0.277338,-150.123215,0.028671,0.000000
27.390001,11.887985,-150.123215,0.006907,0.001106,0.028090,52.880398,2.693856,0.280896,-150.123215,0.029035,0.000000
27.610001,12.002678,-150.123215,0.006924,0.001122,0.028506,53.390579,2.719846,0.285059,-150.123215,0.029408,0.000000
27.830002,12.240623,-150.212173,0.006942,0.001139,0.028939,54.449013,2.773765,0.289393,-150.212173,0.029772,0.000000
28.050001,12.262596,-150.167694,0.006967,0.001153,0.029286,54.546753,2.778744,0.292864,-150.167694,0.030136,0.000000
28.270000,12.125565,-150.078735,0.006959,0.001163,0.029529,53.937206,2.747692,0.295290,-150.078735,0.030509,0.000000
28.490002,12.222748,-150.167694,0.006980,0.001177,0.029885,54.369499,2.769714,0.298848,-150.167694,0.030873,0.000000
28.710001,12.570175,-150.167694,0.007002,0.001196,0.030370,55.914932,2.848443,0.303704,-150.167694,0.031237,0.000000
28.930002,12.499794,-150.212173,0.007006,0.001205,0.030604,55.601860,2.832494,0.306043,-150.212173,0.031602,0.000000
29.150002,12.567566,-150.167694,0.007028,0.001220,0.030986,55.903324,2.847851,0.309862,-150.167694,0.031975,0.000000
29.370001,12.835678,-150.212173,0.007019,0.001236,0.031385,57.095947,2.908606,0.313851,-150.212173,0.032339,0.000000
29.590002,12.985001,-150.212173,0.007045,0.001251,0.031775,57.760166,2.942443,0.317753,-150.212173,0.032703,0.000000
29.810001,13.160759,-150.256653,0.007049,0.001266,0.032157,58.541981,2.982270,0.321568,-150.256653,0.033076,0.000000
30.030001,13.126495,-150.256653,0.007084,0.001277,0.032443,58.389568,2.974506,0.324430,-150.256653,0.033440,0.000000
30.250002,13.090378,-150.212173,0.007088,0.001290,0.032764,58.228909,2.966322,0.327639,-150.212173,0.033804,0.000000
30.470001,13.348808,-150.256653,0.007097,0.001306,0.033163,59.378464,3.024883,0.331629,-150.256653,0.034169,0.000000
30.690001,13.737564,-150.167694,0.007114,0.001326,0.033692,61.107738,3.112977,0.336916,-150.167694,0.034542,0.000000
30.910002,13.630318,-150.256653,0.007123,0.001338,0.033995,60.630680,3.088674,0.339952,-150.256653,0.034906,0.000000
31.130001,13.545792,-150.256653,0.007136,0.001350,0.034290,60.254692,3.069520,0.342900,-150.256653,0.035270,0.000000
31.350002,13.782990,-150.256653,0.007157,0.001365,0.034681,61.309799,3.123270,0.346806,-150.256653,0.035643,0.000000
31.570002,14.205635,-150.301132,0.007183,0.001385,0.035183,63.189819,3.219043,0.351832,-150.301132,0.036007,0.000000
31.790001,14.078285,-150.256653,0.007183,0.001395,0.035444,62.623341,3.190185,0.354436,-150.256653,0.036372,0.000000
32.010002,14.239151,-150.256653,0.007200,0.001411,0.035834,63.338905,3.226638,0.358339,-150.256653,0.036736,0.000000
32.230003,14.275269,-150.301132,0.007217,0.001425,0.036189,63.499565,3.234822,0.361893,-150.301132,0.037109,0.000000
32.450001,14.435387,-150.256653,0.007226,0.001441,0.036597,64.211807,3.271105,0.365969,-150.256653,0.037473,0.000000
32.670002,14.621948,-150.345612,0.007248,0.001454,0.036944,65.041672,3.313381,0.369440,-150.345612,0.037837,0.000000
32.890003,14.585823,-150.301132,0.007265,0.001467,0.037256,64.880981,3.305195,0.372562,-150.301132,0.038210,0.000000
33.110001,14.880745,-150.256653,0.007256,0.001485,0.037716,66.192856,3.372025,0.377157,-150.256653,0.038574,0.000000
33.330002,14.953728,-150.345612,0.007274,0.001499,0.038062,66.517502,3.388563,0.380624,-150.345612,0.038939,0.000000
33.550003,15.316048,-150.345612,0.007286,0.001517,0.038531,68.129181,3.470666,0.385310,-150.345612,0.039303,0.000000
33.770000,15.240829,-150.301132,0.007312,0.001531,0.038878,67.794594,3.453621,0.388777,-150.301132,0.039676,0.000000
33.990002,15.165611,-150.301132,0.007325,0.001541,0.039129,67.460007,3.436577,0.391294,-150.301132,0.040040,0.000000
34.210003,15.478401,-150.390091,0.007334,0.001558,0.039580,68.851364,3.507456,0.395802,-150.390091,0.040404,0.000000
34.430000,15.636665,-150.345612,0.007347,0.001573,0.039953,69.555359,3.543319,0.399530,-150.345612,0.040777,0.000000
34.650002,15.803116,-150.390091,0.007364,0.001588,0.040326,70.295769,3.581037,0.403262,-150.390091,0.041141,0.000000
34.870003,15.603523,-150.345612,0.007373,0.001596,0.040543,69.407936,3.535809,0.405430,-150.345612,0.041506,0.000000
35.090000,15.780396,-150.345612,0.007381,0.001609,0.040881,70.194702,3.575889,0.408810,-150.345612,0.041870,0.000000
35.310001,16.540413,-150.390091,0.007394,0.001634,0.041514,73.575432,3.748111,0.415142,-150.390091,0.042242,0.000000
35.530003,16.443222,-150.390091,0.007411,0.001646,0.041809,73.143105,3.726087,0.418091,-150.390091,0.042607,0.000000
35.750000,16.484550,-150.390091,0.007429,0.001660,0.042173,73.326942,3.735452,0.421732,-150.390091,0.042971,0.000000
35.970001,16.439873,-150.345612,0.007446,0.001670,0.042425,73.128204,3.725328,0.424249,-150.345612,0.043344,0.000000
36.190002,16.581741,-150.345612,0.007463,0.001684,0.042780,73.759270,3.757476,0.427803,-150.345612,0.043708,0.000000
36.410000,16.714310,-150.345612,0.007468,0.001701,0.043205,74.348961,3.787517,0.432053,-150.345612,0.044072,0.000000
36.630001,16.728088,-150.434570,0.007468,0.001712,0.043483,74.410255,3.790639,0.434828,-150.434570,0.044437,0.000000
36.850002,16.810753,-150.479065,0.007489,0.001721,0.043726,74.777962,3.809371,0.437258,-150.479065,0.044810,0.000000
37.070004,16.955978,-150.434570,0.007502,0.001734,0.044055,75.423958,3.842280,0.440550,-150.434570,0.045174,0.000000
37.290001,17.889885,-150.434570,0.007511,0.001760,0.044706,79.578186,4.053906,0.447057,-150.434570,0.045538,0.000000
37.510002,17.809830,-150.390091,0.007524,0.001771,0.044992,79.222076,4.035765,0.449918,-150.390091,0.045911,0.000000
37.730003,17.993408,-150.479065,0.007549,0.001789,0.045434,80.038673,4.077364,0.454339,-150.479065,0.046275,0.000000
37.950001,18.008301,-150.479065,0.007545,0.001801,0.045755,80.104919,4.080739,0.457548,-150.479065,0.046639,0.000000
38.170002,18.239174,-150.523544,0.007571,0.001816,0.046119,81.131897,4.133056,0.461189,-150.523544,0.047004,0.000000
38.390003,18.529251,-150.434570,0.007593,0.001833,0.046561,82.422226,4.198789,0.465614,-150.434570,0.047377,0.000000
38.610001,18.522919,-150.434570,0.007593,0.001845,0.046856,82.394058,4.197353,0.468562,-150.434570,0.047741,0.000000
38.830002,18.394081,-150.479065,0.007606,0.001855,0.047125,81.820961,4.168159,0.471250,-150.479065,0.048105,0.000000
39.050003,18.342323,-150.523544,0.007618,0.001862,0.047307,81.590729,4.156430,0.473074,-150.523544,0.048469,0.000000
39.270000,19.416985,-150.479065,0.007640,0.001892,0.048044,86.371063,4.399951,0.480443,-150.479065,0.048842,0.000000
39.490002,19.475822,-150.434570,0.007657,0.001903,0.048339,86.632782,4.413285,0.483392,-150.434570,0.049206,0.000000
39.710003,19.611366,-150.479065,0.007657,0.001918,0.048729,87.235718,4.443999,0.487294,-150.479065,0.049571,0.000000
39.930000,19.556625,-150.523544,0.007666,0.001929,0.048990,86.992218,4.431594,0.489898,-150.523544,0.049944,0.000000
40.150002,19.607269,-150.568024,0.007675,0.001942,0.049319,87.217491,4.443071,0.493191,-150.568024,0.050308,0.000000
40.370003,19.936447,-150.479065,0.007700,0.001955,0.049666,88.681747,4.517663,0.496661,-150.479065,0.050672,0.000000
40.590000,20.104385,-150.434570,0.007718,0.001971,0.050056,89.428772,4.555719,0.500564,-150.434570,0.051036,0.000000
40.810001,20.056725,-150.523544,0.007713,0.001980,0.050291,89.216766,4.544919,0.502907,-150.523544,0.051409,0.000000
41.030003,21.081116,-150.523544,0.007735,0.002006,0.050941,93.773483,4.777049,0.509409,-150.523544,0.051774,0.000000
41.250004,21.135857,-150.568024,0.007752,0.002018,0.051253,94.016983,4.789454,0.512532,-150.568024,0.052138,0.000000
41.470001,21.536530,-150.523544,0.007765,0.002035,0.051695,95.799271,4.880247,0.516952,-150.523544,0.052510,0.000000
41.690002,21.479927,-150.479065,0.007787,0.002047,0.051999,95.547485,4.867421,0.519988,-150.479065,0.052875,0.000000
41.910004,21.488121,-150.523544,0.007795,0.002058,0.052285,95.583939,4.869278,0.522853,-150.523544,0.053239,0.000000
42.130001,21.768150,-150.612503,0.007791,0.002073,0.052658,96.829567,4.932733,0.526581,-150.612503,0.053603,0.000000
42.350002,22.092110,-150.568024,0.007817,0.002087,0.053022,98.270615,5.006144,0.530222,-150.568024,0.053976,0.000000
42.570004,22.318512,-150.612503,0.007834,0.002102,0.053395,99.277702,5.057447,0.533950,-150.612503,0.054340,0.000000
42.790001,22.228401,-150.568024,0.007838,0.002113,0.053664,98.876869,5.037028,0.536641,-150.568024,0.054705,0.000000
43.010002,23.024902,-150.568024,0.007847,0.002133,0.054175,102.419884,5.217517,0.541755,-150.568024,0.055077,0.000000
43.230003,23.481804,-150.612503,0.007873,0.002151,0.054627,104.452278,5.321053,0.546266,-150.612503,0.055442,0.000000
43.450001,23.406960,-150.656982,0.007881,0.002163,0.054930,104.119354,5.304093,0.549302,-150.656982,0.055806,0.000000
43.670002,23.619957,-150.612503,0.007890,0.002177,0.055294,105.066818,5.352359,0.552943,-150.612503,0.056170,0.000000
43.890003,23.644157,-150.612503,0.007912,0.002187,0.055555,105.174461,5.357842,0.555547,-150.612503,0.056543,0.000000
44.110001,23.829971,-150.612503,0.007916,0.002201,0.055910,106.001007,5.399949,0.559101,-150.612503,0.056907,0.000000
44.330002,24.367676,-150.612503,0.007912,0.002218,0.056344,108.392838,5.521794,0.563438,-150.612503,0.057272,0.000000
44.550003,24.720314,-150.701462,0.007942,0.002232,0.056699,109.961449,5.601703,0.566992,-150.701462,0.057645,0.000000
44.770000,24.486465,-150.701462,0.007946,0.002240,0.056907,108.921242,5.548713,0.569074,-150.701462,0.058009,0.000000
44.990002,25.866478,-150.656982,0.007972,0.002267,0.057575,115.059837,5.861428,0.575751,-150.656982,0.058373,0.000000
45.210003,25.959572,-150.656982,0.007981,0.002280,0.057913,115.473946,5.882523,0.579134,-150.656982,0.058737,0.000000
45.430000,25.960320,-150.701462,0.007985,0.002293,0.058243,115.477272,5.882692,0.582431,-150.701462,0.059110,0.000000
45.650002,26.153946,-150.745941,0.007989,0.002305,0.058555,116.338562,5.926569,0.585550,-150.745941,0.059474,0.000000
45.870003,26.192673,-150.656982,0.008019,0.002317,0.058841,116.510826,5.935345,0.588415,-150.656982,0.059839,0.000000
46.090004,26.741554,-150.701462,0.008032,0.002334,0.059284,118.952377,6.059723,0.592836,-150.701462,0.060212,0.000000
46.310001,27.395439,-150.701462,0.008032,0.002351,0.059709,121.861000,6.207895,0.597086,-150.701462,0.060576,0.000000
46.530003,27.169785,-150.612503,0.008050,0.002357,0.059873,120.857239,6.156761,0.598733,-150.612503,0.060940,0.000000
46.750004,27.666901,-150.745941,0.008058,0.002375,0.060316,123.068520,6.269409,0.603157,-150.745941,0.061304,0.000000
46.970001,27.929794,-150.701462,0.008080,0.002386,0.060611,124.237930,6.328982,0.606106,-150.701462,0.061677,0.000000
47.190002,29.070740,-150.701462,0.008093,0.002410,0.061218,129.313110,6.587523,0.612176,-150.701462,0.062041,0.000000
47.410004,28.974670,-150.656982,0.008088,0.002419,0.061435,128.885773,6.565754,0.614345,-150.656982,0.062406,0.000000
47.630001,29.138145,-150.745941,0.008106,0.002433,0.061790,129.612946,6.602798,0.617899,-150.745941,0.062779,0.000000
47.850002,29.462479,-150.745941,0.008119,0.002446,0.062137,131.055649,6.676293,0.621366,-150.745941,0.063143,0.000000
48.070004,29.953636,-150.745941,0.008132,0.002462,0.062536,133.240433,6.787591,0.625355,-150.745941,0.063507,0.000000
48.290001,30.489853,-150.745941,0.008144,0.002477,0.062917,135.625641,6.909100,0.629174,-150.745941,0.063871,0.000000
48.510002,30.628006,-150.790421,0.008157,0.002487,0.063177,136.240173,6.940405,0.631775,-150.790421,0.064244,0.000000
48.730003,31.164597,-150.745941,0.008162,0.002504,0.063603,138.627045,7.061998,0.636025,-150.745941,0.064609,0.000000
48.950001,31.337372,-150.834900,0.008170,0.002517,0.063923,139.395599,7.101150,0.639231,-150.834900,0.064973,0.000000
49.170002,32.470131,-150.834900,0.008196,0.002539,0.064487,144.434357,7.357837,0.644870,-150.834900,0.065345,0.000000
49.390003,32.756859,-150.745941,0.008205,0.002551,0.064808,145.709778,7.422810,0.648080,-150.745941,0.065710,0.000000
49.610001,32.645515,-150.745941,0.008209,0.002560,0.065033,145.214508,7.397580,0.650332,-150.745941,0.066074,0.000000
49.830002,32.976189,-150.790421,0.008218,0.002575,0.065406,146.685410,7.472511,0.654064,-150.790421,0.066438,0.000000
50.050003,33.732101,-150.834900,0.008239,0.002593,0.065857,150.047882,7.643804,0.658572,-150.834900,0.066811,0.000000
50.270004,33.987549,-150.834900,0.008235,0.002603,0.066117,151.184174,7.701688,0.661172,-150.834900,0.067175,0.000000
50.490002,34.212837,-150.879379,0.008265,0.002616,0.066456,152.186295,7.752739,0.664556,-150.879379,0.067540,0.000000
50.710003,34.882729,-150.790421,0.008274,0.002634,0.066898,155.166122,7.904540,0.668980,-150.790421,0.067912,0.000000
50.930004,35.628967,-150.879379,0.008274,0.002650,0.067314,158.485565,8.073640,0.673140,-150.879379,0.068277,0.000000
51.150002,36.109703,-150.879379,0.008282,0.002664,0.067661,160.623978,8.182576,0.676611,-150.879379,0.068641,0.000000
51.370003,36.355469,-150.879379,0.008304,0.002676,0.067965,161.717209,8.238267,0.679646,-150.879379,0.069005,0.000000
51.590004,36.581871,-150.834900,0.008313,0.002688,0.068286,162.724289,8.289570,0.682856,-150.834900,0.069378,0.000000
51.810001,37.360497,-150.923874,0.008321,0.002704,0.068684,166.187790,8.466009,0.686845,-150.923874,0.069742,0.000000
52.030003,38.431442,-150.834900,0.008326,0.002724,0.069196,170.951599,8.708690,0.691958,-150.834900,0.070106,0.000000
52.250004,38.561028,-150.879379,0.008338,0.002737,0.069508,171.528015,8.738053,0.695081,-150.879379,0.070471,0.000000
52.470001,38.718910,-150.879379,0.008351,0.002748,0.069794,172.230316,8.773830,0.697942,-150.879379,0.070844,0.000000
52.690002,39.505363,-150.879379,0.008360,0.002764,0.070211,175.728638,8.952044,0.702106,-150.879379,0.071208,0.000000
52.910004,40.492523,-150.879379,0.008369,0.002783,0.070687,180.119736,9.175736,0.706875,-150.879379,0.071572,0.000000
53.130001,40.794144,-150.923874,0.008377,0.002794,0.070974,181.461411,9.244085,0.709740,-150.923874,0.071945,0.000000
53.350002,41.423828,-150.968353,0.008395,0.002809,0.071355,184.262390,9.386773,0.713555,-150.968353,0.072309,0.000000
53.570004,41.809975,-150.879379,0.008403,0.002824,0.071737,185.980057,9.474276,0.717370,-150.879379,0.072674,0.000000
53.790001,42.502960,-150.923874,0.008416,0.002841,0.072162,189.062607,9.631309,0.721621,-150.923874,0.073038,0.000000
54.010002,43.080513,-150.923874,0.008433,0.002853,0.072466,191.631699,9.762184,0.724656,-150.923874,0.073411,0.000000
54.230003,43.389580,-150.968353,0.008429,0.002865,0.072777,193.006485,9.832219,0.727775,-150.968353,0.073775,0.000000
54.450001,44.212898,-150.923874,0.008438,0.002881,0.073185,196.668793,10.018786,0.731851,-150.923874,0.074139,0.000000
54.670002,44.880936,-151.012833,0.008451,0.002897,0.073593,199.640366,10.170165,0.735927,-151.012833,0.074512,0.000000
54.890003,45.944427,-151.012833,0.008476,0.002915,0.074053,204.371017,10.411157,0.740526,-151.012833,0.074876,0.000000
55.110004,46.253494,-150.968353,0.008481,0.002929,0.074391,205.745819,10.481192,0.743906,-150.968353,0.075241,0.000000
55.330002,46.502991,-150.923874,0.008494,0.002939,0.074642,206.855637,10.537728,0.746423,-150.923874,0.075605,0.000000
55.550003,47.562386,-150.968353,0.008502,0.002958,0.075128,211.568054,10.777791,0.751279,-150.968353,0.075978,0.000000
55.770004,48.176804,-151.012833,0.008498,0.002971,0.075475,214.301132,10.917020,0.754746,-151.012833,0.076342,0.000000
55.990002,48.787117,-151.012833,0.008524,0.002986,0.075839,217.015930,11.055319,0.758391,-151.012833,0.076706,0.000000
56.210003,48.873138,-150.968353,0.008528,0.002994,0.076047,217.398575,11.074812,0.760472,-150.968353,0.077079,0.000000
56.430004,49.558304,-151.012833,0.008537,0.003008,0.076403,220.446350,11.230073,0.764026,-151.012833,0.077443,0.000000
56.650002,51.283875,-151.012833,0.008537,0.003032,0.077018,228.122070,11.621093,0.770185,-151.012833,0.077808,0.000000
56.870003,51.707268,-151.057312,0.008554,0.003043,0.077305,230.005417,11.717034,0.773046,-151.057312,0.078172,0.000000
57.090004,52.245712,-151.012833,0.008567,0.003059,0.077686,232.400528,11.839048,0.776861,-151.012833,0.078545,0.000000
57.310001,52.756981,-151.012833,0.008576,0.003069,0.077947,234.674774,11.954903,0.779465,-151.012833,0.078909,0.000000
57.530003,53.441032,-151.012833,0.008580,0.003083,0.078302,237.717590,12.109911,0.783019,-151.012833,0.079273,0.000000
57.750004,53.678230,-151.057312,0.008593,0.003092,0.078527,238.772690,12.163661,0.785275,-151.057312,0.079646,0.000000
57.970001,54.710075,-151.101791,0.008593,0.003111,0.079022,243.362564,12.397480,0.790218,-151.101791,0.080010,0.000000
58.190002,55.126762,-151.146271,0.008606,0.003120,0.079247,245.216080,12.491903,0.792470,-151.146271,0.080375,0.000000
58.410004,55.494667,-151.057312,0.008614,0.003133,0.079568,246.852615,12.575272,0.795680,-151.057312,0.080739,0.000000
58.630001,57.577713,-151.101791,0.008614,0.003158,0.080201,256.118469,13.047297,0.802012,-151.101791,0.081112,0.000000
58.850002,58.103508,-151.146271,0.008619,0.003171,0.080531,258.457306,13.166444,0.805308,-151.146271,0.081476,0.000000
59.070004,59.083961,-151.101791,0.008640,0.003188,0.080964,262.818573,13.388617,0.809642,-151.101791,0.081840,0.000000
59.290001,59.662628,-151.146271,0.008649,0.003200,0.081276,265.392639,13.519745,0.812765,-151.146271,0.082213,0.000000
59.510002,60.548134,-151.012833,0.008662,0.003215,0.081649,269.331543,13.720404,0.816493,-151.012833,0.082577,0.000000
59.730003,61.676796,-151.057312,0.008658,0.003232,0.082083,274.352081,13.976162,0.820830,-151.057312,0.082941,0.000000
59.950005,62.219337,-151.101791,0.008675,0.003245,0.082421,276.765442,14.099103,0.824214,-151.101791,0.083306,0.000000
60.170002,62.584267,-151.101791,0.008683,0.003255,0.082673,278.388733,14.181798,0.826727,-151.101791,0.083679,0.000000
60.390003,62.735077,-151.101791,0.008688,0.003261,0.082829,279.059570,14.215971,0.828286,-151.101791,0.084043,0.000000
60.610004,64.593956,-151.190750,0.008683,0.003289,0.083531,287.328278,14.637200,0.835311,-151.190750,0.084407,0.000000
60.830002,65.691719,-151.057312,0.008696,0.003301,0.083835,292.211365,14.885957,0.838347,-151.057312,0.084780,0.000000
61.050003,66.371666,-151.190750,0.008701,0.003315,0.084208,295.235901,15.040034,0.842079,-151.190750,0.085144,0.000000
61.270004,67.025185,-151.235229,0.008714,0.003327,0.084494,298.142914,15.188124,0.844940,-151.235229,0.085508,0.000000
61.490002,67.534950,-151.190750,0.008722,0.003327,0.084511,300.410461,15.303639,0.845110,-151.190750,0.084780,0.000000
61.710003,66.842339,-151.146271,0.008735,0.003327,0.084511,297.329559,15.146690,0.845110,-151.146271,0.084780,0.000000
61.930004,66.166862,-151.101791,0.008739,0.003325,0.084459,294.324890,14.993626,0.844592,-151.101791,0.084511,0.000000
62.150002,65.590431,-151.190750,0.008735,0.003324,0.084433,291.760803,14.863005,0.844331,-151.190750,0.084511,0.000000
62.370003,65.048622,-151.235229,0.008739,0.003324,0.084424,289.350708,14.740228,0.844244,-151.235229,0.084511,0.000000
62.590004,64.558586,-151.190750,0.008761,0.003323,0.084416,287.170929,14.629185,0.844157,-151.190750,0.084511,0.000000
62.810001,64.103539,-151.190750,0.008752,0.003323,0.084416,285.146790,14.526070,0.844157,-151.190750,0.084511,0.000000
63.030003,63.687599,-151.235229,0.008752,0.003323,0.084416,283.296600,14.431816,0.844157,-151.235229,0.084511,0.000000
63.250004,63.290276,-151.190750,0.008752,0.003323,0.084407,281.529205,14.341781,0.844073,-151.190750,0.084511,0.000000
63.470001,62.930946,-151.235229,0.008757,0.003323,0.084407,279.930817,14.260357,0.844073,-151.235229,0.084511,0.000000
63.690002,62.577187,-151.279709,0.008765,0.003323,0.084407,278.357239,14.180194,0.844073,-151.279709,0.084511,0.000000
63.910004,62.262535,-151.235229,0.008774,0.003323,0.084407,276.957581,14.108892,0.844073,-151.235229,0.084511,0.000000
64.130005,61.962402,-151.190750,0.008765,0.003323,0.084407,275.622528,14.040880,0.844073,-151.190750,0.084511,0.000000
64.350006,61.673073,-151.190750,0.008770,0.003323,0.084407,274.335541,13.975318,0.844073,-151.190750,0.084511,0.000000
64.570000,61.386711,-151.279709,0.008765,0.003323,0.084407,273.061737,13.910428,0.844073,-151.279709,0.084511,0.000000
64.790001,61.137970,-151.279709,0.008765,0.003323,0.084407,271.955261,13.854062,0.844073,-151.279709,0.084511,0.000000
65.010002,60.901886,-151.235229,0.008774,0.003323,0.084399,270.905121,13.800564,0.843986,-151.235229,0.084511,0.000000
65.230003,60.672874,-151.279709,0.008774,0.003323,0.084399,269.886414,13.748671,0.843986,-151.279709,0.084511,0.000000
65.450005,60.442375,-151.235229,0.008774,0.003323,0.084399,268.861115,13.696438,0.843986,-151.235229,0.084511,0.000000
65.670006,60.247253,-151.279709,0.008774,0.003323,0.084399,267.993164,13.652223,0.843986,-151.279709,0.084511,0.000000
65.889999,60.038727,-151.324188,0.008791,0.003323,0.084399,267.065582,13.604970,0.843986,-151.324188,0.084511,0.000000
66.110001,59.842117,-151.190750,0.008787,0.003323,0.084399,266.191040,13.560417,0.843986,-151.190750,0.084511,0.000000
66.330002,59.673431,-151.279709,0.008783,0.003323,0.084399,265.440674,13.522193,0.843986,-151.279709,0.084511,0.000000
66.550003,59.493942,-151.279709,0.008783,0.003323,0.084399,264.642273,13.481520,0.843986,-151.279709,0.084511,0.000000
66.770004,59.329727,-151.324188,0.008795,0.003323,0.084399,263.911804,13.444308,0.843986,-151.324188,0.084511,0.000000
66.990005,59.167374,-151.324188,0.008783,0.003323,0.084399,263.189636,13.407519,0.843986,-151.324188,0.084511,0.000000
67.210007,59.006134,-151.324188,0.008787,0.003323,0.084399,262.472382,13.370981,0.843986,-151.324188,0.084511,0.000000
67.430000,58.863144,-151.279709,0.008791,0.003323,0.084399,261.836334,13.338579,0.843986,-151.279709,0.084511,0.000000
67.650002,58.726860,-151.368683,0.008787,0.003323,0.084399,261.230133,13.307696,0.843986,-151.368683,0.084511,0.000000
67.870003,58.589081,-151.368683,0.008791,0.003323,0.084399,260.617249,13.276476,0.843986,-151.368683,0.084511,0.000000
68.090004,58.459869,-151.368683,0.008787,0.003323,0.084399,260.042480,13.247196,0.843986,-151.368683,0.084511,0.000000
68.310005,58.335121,-151.413162,0.008795,0.003323,0.084399,259.487579,13.218927,0.843986,-151.413162,0.084511,0.000000
68.530006,58.202927,-151.324188,0.008800,0.003323,0.084399,258.899536,13.188972,0.843986,-151.324188,0.084511,0.000000
68.750000,58.072227,-151.324188,0.008778,0.003323,0.084399,258.318176,13.159355,0.843986,-151.324188,0.084511,0.000000
68.970001,57.960892,-151.368683,0.008791,0.003323,0.084399,257.822937,13.134126,0.843986,-151.368683,0.084511,0.000000
69.190002,57.844711,-151.413162,0.008800,0.003323,0.084399,257.306122,13.107799,0.843986,-151.413162,0.084511,0.000000
69.410004,57.733368,-151.324188,0.008804,0.003323,0.084399,256.810852,13.082568,0.843986,-151.324188,0.084511,0.000000
69.630005,57.623520,-151.368683,0.008800,0.003323,0.084399,256.322205,13.057676,0.843986,-151.368683,0.084511,0.000000
69.850006,57.517761,-151.413162,0.008804,0.003323,0.084399,255.851776,13.033710,0.843986,-151.413162,0.084511,0.000000
70.070000,57.407173,-151.457642,0.008800,0.003323,0.084399,255.359863,13.008652,0.843986,-151.457642,0.084511,0.000000
70.290001,57.325249,-151.457642,0.008800,0.003323,0.084399,254.995438,12.990088,0.843986,-151.457642,0.084511,0.000000
70.510002,57.226570,-151.413162,0.008804,0.003323,0.084399,254.556503,12.967726,0.843986,-151.413162,0.084511,0.000000
70.730003,57.141670,-151.413162,0.008795,0.003323,0.084399,254.178848,12.948488,0.843986,-151.413162,0.084511,0.000000
70.950005,57.035172,-151.413162,0.008800,0.003323,0.084399,253.705109,12.924355,0.843986,-151.413162,0.084511,0.000000
71.170006,56.957718,-151.457642,0.008791,0.003323,0.084399,253.360580,12.906803,0.843986,-151.457642,0.084511,0.000000
71.390007,56.854195,-151.457642,0.008804,0.003323,0.084399,252.900085,12.883345,0.843986,-151.457642,0.084511,0.000000
71.610001,56.781960,-151.457642,0.008813,0.003323,0.084399,252.578766,12.866976,0.843986,-151.457642,0.084511,0.000000
71.830002,56.697060,-151.413162,0.008804,0.003323,0.084399,252.201111,12.847737,0.843986,-151.413162,0.084511,0.000000
72.050003,56.621094,-151.457642,0.008804,0.003323,0.084399,251.863205,12.830523,0.843986,-151.457642,0.084511,0.000000
72.270004,56.550339,-151.457642,0.008804,0.003323,0.084399,251.548477,12.814489,0.843986,-151.457642,0.084511,0.000000
72.490005,56.467300,-151.502121,0.008804,0.003323,0.084399,251.179092,12.795673,0.843986,-151.502121,0.084511,0.000000
72.710007,56.379051,-151.457642,0.008804,0.003323,0.084399,250.786545,12.775676,0.843986,-151.457642,0.084511,0.000000
72.930000,56.309418,-151.502121,0.008804,0.003323,0.084399,250.476807,12.759896,0.843986,-151.502121,0.084511,0.000000
73.150002,56.237923,-151.457642,0.008804,0.003323,0.084399,250.158768,12.743695,0.843986,-151.457642,0.084511,0.000000
73.370003,56.167542,-151.546600,0.008795,0.003323,0.084399,249.845703,12.727746,0.843986,-151.546600,0.084511,0.000000
73.590004,56.101257,-151.502121,0.008804,0.003323,0.084399,249.550858,12.712727,0.843986,-151.502121,0.084511,0.000000
73.810005,56.037582,-151.546600,0.008813,0.003323,0.084399,249.267609,12.698298,0.843986,-151.546600,0.084511,0.000000
74.030006,55.972420,-151.502121,0.008804,0.003323,0.084399,248.977753,12.683532,0.843986,-151.502121,0.084511,0.000000
74.250000,55.901299,-151.457642,0.008808,0.003323,0.084399,248.661392,12.667415,0.843986,-151.457642,0.084511,0.000000
74.470001,55.842461,-151.591080,0.008817,0.003323,0.084399,248.399673,12.654082,0.843986,-151.591080,0.084511,0.000000
74.690002,55.769478,-151.546600,0.008808,0.003323,0.084399,248.075027,12.637545,0.843986,-151.546600,0.084511,0.000000
74.910004,55.707291,-151.591080,0.008808,0.003323,0.084399,247.798401,12.623453,0.843986,-151.591080,0.084511,0.000000
75.130005,55.648827,-151.591080,0.008817,0.003323,0.084399,247.538345,12.610205,0.843986,-151.591080,0.084511,0.000000
75.350006,55.607864,-151.546600,0.008817,0.003323,0.084399,247.356140,12.600922,0.843986,-151.546600,0.084511,0.000000
75.570007,55.547539,-151.546600,0.008813,0.003323,0.084399,247.087799,12.587253,0.843986,-151.546600,0.084511,0.000000
75.790001,55.484238,-151.591080,0.008813,0.003323,0.084399,246.806213,12.572907,0.843986,-151.591080,0.084511,0.000000
76.010002,55.433968,-151.546600,0.008813,0.003323,0.084399,246.582596,12.561516,0.843986,-151.546600,0.084511,0.000000
76.230003,55.378487,-151.591080,0.008813,0.003323,0.084399,246.335815,12.548944,0.843986,-151.591080,0.084511,0.000000
76.450005,55.329704,-151.546600,0.008804,0.003323,0.084399,246.118820,12.537890,0.843986,-151.546600,0.084511,0.000000
76.670006,55.273849,-151.591080,0.008813,0.003323,0.084399,245.870361,12.525233,0.843986,-151.591080,0.084511,0.000000
76.890007,55.216499,-151.635559,0.008817,0.003323,0.084399,245.615250,12.512238,0.843986,-151.635559,0.084511,0.000000
77.110001,55.167351,-151.591080,0.008808,0.003323,0.084399,245.396637,12.501101,0.843986,-151.591080,0.084511,0.000000
77.330002,55.126762,-151.680038,0.008808,0.003323,0.084399,245.216080,12.491903,0.843986,-151.680038,0.084511,0.000000
77.550003,55.076118,-151.591080,0.008817,0.003323,0.084399,244.990814,12.480427,0.843986,-151.591080,0.084511,0.000000
77.770004,55.020638,-151.635559,0.008821,0.003323,0.084399,244.744019,12.467855,0.843986,-151.635559,0.084511,0.000000
77.990005,54.980415,-151.680038,0.008817,0.003323,0.084399,244.565109,12.458740,0.843986,-151.680038,0.084511,0.000000
78.210007,54.931267,-151.680038,0.008826,0.003323,0.084399,244.346481,12.447603,0.843986,-151.680038,0.084511,0.000000
78.430000,54.872803,-151.591080,0.008826,0.003323,0.084399,244.086411,12.434355,0.843986,-151.591080,0.084511,0.000000
78.650002,54.824394,-151.680038,0.008817,0.003323,0.084399,243.871078,12.423386,0.843986,-151.680038,0.084511,0.000000
78.870003,54.807640,-151.635559,0.008813,0.003323,0.084399,243.796555,12.419589,0.843986,-151.635559,0.084511,0.000000
79.090004,54.756622,-151.680038,0.008826,0.003323,0.084399,243.569626,12.408029,0.843986,-151.680038,0.084511,0.000000
79.310005,54.720879,-151.635559,0.008821,0.003323,0.084399,243.410629,12.399928,0.843986,-151.635559,0.084511,0.000000
79.530006,54.674332,-151.680038,0.008826,0.003323,0.084399,243.203568,12.389380,0.843986,-151.680038,0.084511,0.000000
79.750000,54.631882,-151.635559,0.008804,0.003323,0.084399,243.014740,12.379762,0.843986,-151.635559,0.084511,0.000000
79.970001,54.568199,-151.635559,0.008821,0.003323,0.084399,242.731476,12.365331,0.843986,-151.635559,0.084511,0.000000
80.190002,54.544746,-151.680038,0.008821,0.003323,0.084399,242.627151,12.360016,0.843986,-151.680038,0.084511,0.000000
80.410004,54.491493,-151.680038,0.008813,0.003323,0.084399,242.390274,12.347949,0.843986,-151.680038,0.084511,0.000000
80.630005,54.452393,-151.724518,0.008826,0.003323,0.084399,242.216339,12.339088,0.843986,-151.724518,0.084511,0.000000
80.850006,54.419624,-151.680038,0.008808,0.003323,0.084399,242.070572,12.331663,0.843986,-151.680038,0.084511,0.000000
81.070007,54.378296,-151.680038,0.008821,0.003323,0.084399,241.886734,12.322298,0.843986,-151.680038,0.084511,0.000000
81.290001,54.337708,-151.769012,0.008826,0.003323,0.084399,241.706192,12.313101,0.843986,-151.769012,0.084511,0.000000
81.510002,54.287437,-151.724518,0.008813,0.003323,0.084399,241.482590,12.301709,0.843986,-151.724518,0.084511,0.000000
81.730003,54.257271,-151.769012,0.008821,0.003323,0.084399,241.348389,12.294873,0.843986,-151.769012,0.084511,0.000000
81.950005,54.218918,-151.724518,0.008813,0.003323,0.084399,241.177795,12.286182,0.843986,-151.724518,0.084511,0.000000
82.170006,54.180191,-151.769012,0.008834,0.003323,0.084399,241.005524,12.277408,0.843986,-151.769012,0.084511,0.000000
82.390007,54.142952,-151.769012,0.008830,0.003323,0.084399,240.839874,12.268968,0.843986,-151.769012,0.084511,0.000000
82.610001,54.113533,-151.769012,0.008821,0.003323,0.084399,240.709015,12.262301,0.843986,-151.769012,0.084511,0.000000
82.830002,54.071083,-151.769012,0.008817,0.003323,0.084399,240.520187,12.252682,0.843986,-151.769012,0.084511,0.000000
83.050003,54.033104,-151.769012,0.008826,0.003323,0.084399,240.351257,12.244077,0.843986,-151.769012,0.084511,0.000000
83.270004,54.002197,-151.813492,0.008813,0.003323,0.084399,240.213776,12.237073,0.843986,-151.813492,0.084511,0.000000
83.490005,53.971664,-151.857971,0.008826,0.003323,0.084399,240.077957,12.230154,0.843986,-151.857971,0.084511,0.000000
83.710007,53.943733,-151.724518,0.008834,0.003323,0.084399,239.953705,12.223825,0.843986,-151.724518,0.084511,0.000000
83.930000,53.913940,-151.813492,0.008821,0.003323,0.084399,239.821182,12.217074,0.843986,-151.813492,0.084511,0.000000
84.150002,53.889740,-151.769012,0.008830,0.003323,0.084399,239.713531,12.211590,0.843986,-151.769012,0.084511,0.000000
84.370003,53.839470,-151.813492,0.008821,0.003323,0.084399,239.489929,12.200198,0.843986,-151.813492,0.084511,0.000000
84.590004,53.809311,-151.902451,0.008826,0.003323,0.084399,239.355774,12.193364,0.843986,-151.902451,0.084511,0.000000
84.810005,53.781754,-151.857971,0.008834,0.003323,0.084399,239.233185,12.187119,0.843986,-151.857971,0.084511,0.000000
85.030006,53.730362,-151.813492,0.008821,0.003323,0.084399,239.004593,12.175474,0.843986,-151.813492,0.084511,0.000000
85.250008,53.725151,-151.813492,0.008826,0.003323,0.084399,238.981415,12.174293,0.843986,-151.813492,0.084511,0.000000
85.470001,53.680466,-151.857971,0.008826,0.003323,0.084399,238.782639,12.164167,0.843986,-151.857971,0.084511,0.000000
85.690002,53.656265,-151.857971,0.008817,0.003323,0.084399,238.674988,12.158684,0.843986,-151.857971,0.084511,0.000000
85.910004,53.619026,-151.857971,0.008817,0.003323,0.084399,238.509338,12.150245,0.843986,-151.857971,0.084511,0.000000
86.130005,53.575455,-151.813492,0.008826,0.003323,0.084399,238.315521,12.140371,0.843986,-151.813492,0.084511,0.000000
86.350006,53.560562,-151.857971,0.008830,0.003323,0.084399,238.249283,12.136997,0.843986,-151.857971,0.084511,0.000000
86.570007,53.530403,-151.813492,0.008826,0.003323,0.084399,238.115128,12.130162,0.843986,-151.813492,0.084511,0.000000
86.790001,53.519226,-151.902451,0.008830,0.003323,0.084399,238.065414,12.127630,0.843986,-151.902451,0.084511,0.000000
87.010002,53.467094,-151.857971,0.008817,0.003323,0.084399,237.833511,12.115817,0.843986,-151.857971,0.084511,0.000000
87.230003,53.439911,-151.902451,0.008830,0.003323,0.084399,237.712601,12.109657,0.843986,-151.902451,0.084511,0.000000
87.450005,53.412727,-151.902451,0.008826,0.003323,0.084399,237.591675,12.103497,0.843986,-151.902451,0.084511,0.000000
87.670006,53.392250,-151.857971,0.008821,0.003323,0.084399,237.500595,12.098857,0.843986,-151.857971,0.084511,0.000000
87.890007,53.370277,-151.946930,0.008834,0.003323,0.084399,237.402847,12.093878,0.843986,-151.946930,0.084511,0.000000
88.110001,53.330811,-151.946930,0.008830,0.003323,0.084399,237.227295,12.084935,0.843986,-151.946930,0.084511,0.000000
88.330002,53.320755,-151.946930,0.008843,0.003323,0.084399,237.182571,12.082656,0.843986,-151.946930,0.084511,0.000000
88.550003,53.289474,-151.946930,0.008834,0.003323,0.084399,237.043427,12.075568,0.843986,-151.946930,0.084511,0.000000
88.770004,53.240326,-151.946930,0.008834,0.003323,0.084399,236.824799,12.064430,0.843986,-151.946930,0.084511,0.000000
88.990005,53.231758,-151.991409,0.008826,0.003323,0.084399,236.786682,12.062489,0.843986,-151.991409,0.084511,0.000000
89.210007,53.181488,-151.991409,0.008834,0.003323,0.084399,236.563080,12.051098,0.843986,-151.991409,0.084511,0.000000
89.430008,53.163239,-151.991409,0.008826,0.003323,0.084399,236.481903,12.046962,0.843986,-151.991409,0.084511,0.000000
89.650002,53.135689,-151.991409,0.008826,0.003323,0.084399,236.359344,12.040719,0.843986,-151.991409,0.084511,0.000000
89.870003,53.103661,-151.946930,0.008834,0.003323,0.084399,236.216873,12.033462,0.843986,-151.946930,0.084511,0.000000
90.090004,53.067169,-151.991409,0.008817,0.003323,0.084399,236.054565,12.025192,0.843986,-151.991409,0.084511,0.000000
90.310005,53.046318,-151.991409,0.008834,0.003323,0.084399,235.961807,12.020467,0.843986,-151.991409,0.084511,0.000000
90.530006,53.034401,-151.946930,0.008843,0.003323,0.084399,235.908798,12.017767,0.843986,-151.946930,0.084511,0.000000
90.750008,53.011688,-151.946930,0.008821,0.003323,0.084399,235.807770,12.012620,0.843986,-151.946930,0.084511,0.000000
90.970001,52.983009,-151.991409,0.008839,0.003323,0.084399,235.680191,12.006122,0.843986,-151.991409,0.084511,0.000000
91.190002,52.956573,-152.080368,0.008817,0.003323,0.084399,235.562607,12.000131,0.843986,-152.080368,0.084511,0.000000
91.410004,52.940193,-152.035889,0.008834,0.003323,0.084399,235.489746,11.996419,0.843986,-152.035889,0.084511,0.000000
91.630005,52.913010,-151.991409,0.008830,0.003323,0.084399,235.368820,11.990260,0.843986,-151.991409,0.084511,0.000000
91.850006,52.889175,-152.035889,0.008839,0.003323,0.084399,235.262802,11.984859,0.843986,-152.035889,0.084511,0.000000
91.900002,52.893646,-151.991409,0.008830,0.003323,0.084399,235.282684,11.985871,0.843986,-151.991409,0.084511,0.000000