File: Data/compression 8/AutoHeating-17-8-1-3-240328_03282024_153853.csv
Time (sec),S:Load (lbs),S:HL1 (DIM),S:LVDT (in),S:Position (in),Ch:Position (mm),Ch:Load (N),Ch:Stress (MPa),Ch:Strain (mm/mm),Ch:HL1 (DIM),Set Point (),Cycles ()
0.110000,-0.008194,-157.773926,0.000000,-0.000000,-0.000000,-0.036449,-0.001857,-0.000000,-157.773926,0.000173,0.000000
0.320000,0.000748,-157.773926,-0.000013,-0.000000,-0.000000,0.003326,0.000169,-0.000000,-157.773926,0.000173,0.000000
0.530000,0.011543,-157.684967,-0.000004,0.000074,0.001882,0.051347,0.002616,0.018818,-157.684967,0.002619,0.000000
0.740000,-0.013405,-157.773926,0.000069,0.000201,0.005108,-0.059628,-0.003038,0.051077,-157.773926,0.006122,0.000000
0.950000,-0.015266,-157.729446,0.000203,0.000334,0.008481,-0.067908,-0.003459,0.084812,-157.729446,0.009609,0.000000
1.160000,0.003723,-157.729446,0.000332,0.000473,0.012011,0.016561,0.000844,0.120110,-157.729446,0.013112,0.000000
1.370000,0.002975,-157.773926,0.000474,0.000608,0.015445,0.013236,0.000674,0.154450,-157.773926,0.016616,0.000000
1.580000,0.014153,-157.773926,0.000612,0.000744,0.018888,0.062954,0.003207,0.188881,-157.773926,0.020102,0.000000
1.790000,0.046173,-157.773926,0.000755,0.000882,0.022392,0.205388,0.010463,0.223918,-157.773926,0.023606,0.000000
2.000000,0.651276,-157.773926,0.000875,0.001019,0.025895,2.897019,0.147581,0.258951,-157.773926,0.027109,0.000000
2.210000,0.716446,-157.729446,0.000910,-0.000000,-0.000000,3.186911,0.162349,-0.000000,-157.729446,0.000104,0.000000
2.420000,0.688141,-157.862900,0.000897,-0.000000,-0.000009,3.061003,0.155935,-0.000087,-157.862900,0.000104,0.000000
2.630000,0.666550,-157.818420,0.000905,-0.000000,-0.000009,2.964961,0.151042,-0.000087,-157.818420,0.000199,0.000000
2.840000,0.656494,-157.862900,0.000901,-0.000000,-0.000009,2.920232,0.148764,-0.000087,-157.862900,0.000546,0.000000
3.050000,0.654259,-157.818420,0.000892,-0.000000,-0.000000,2.910288,0.148257,-0.000000,-157.818420,0.000893,0.000000
3.260000,0.807678,-157.862900,0.000892,0.000015,0.000373,3.592732,0.183022,0.003728,-157.862900,0.001249,0.000000
3.470000,0.881409,-157.862900,0.000914,0.000021,0.000537,3.920702,0.199730,0.005375,-157.862900,0.001596,0.000000
3.680000,1.111900,-157.818420,0.000923,0.000039,0.000997,4.945980,0.251960,0.009973,-157.818420,0.001942,0.000000
3.890000,1.334213,-157.907379,0.000936,0.000057,0.001448,5.934877,0.302337,0.014481,-157.907379,0.002298,0.000000
4.100000,1.561729,-157.907379,0.000953,0.000073,0.001864,6.946919,0.353893,0.018644,-157.907379,0.002645,0.000000
4.310000,1.757225,-157.773926,0.000970,0.000086,0.002185,7.816527,0.398193,0.021854,-157.773926,0.003000,0.000000
4.520000,1.854416,-157.862900,0.000970,0.000093,0.002350,8.248854,0.420217,0.023500,-157.862900,0.003347,0.000000
4.730000,2.128105,-157.907379,0.000983,0.000109,0.002758,9.466285,0.482236,0.027577,-157.907379,0.003694,0.000000
4.940000,2.302750,-157.862900,0.000996,0.000122,0.003087,10.243142,0.521811,0.030873,-157.862900,0.004050,0.000000
5.150000,2.630440,-157.907379,0.001013,0.000139,0.003521,11.700781,0.596066,0.035207,-157.907379,0.004397,0.000000
5.360000,2.900406,-157.862900,0.001035,0.000156,0.003972,12.901649,0.657241,0.039719,-157.862900,0.004744,0.000000
5.570000,3.012489,-157.907379,0.001035,0.000164,0.004171,13.400222,0.682640,0.041713,-157.907379,0.005099,0.000000
5.780000,3.309273,-157.907379,0.001043,0.000180,0.004562,14.720381,0.749892,0.045616,-157.907379,0.005446,0.000000
5.990000,3.662285,-157.951859,0.001065,0.000198,0.005021,16.290657,0.829886,0.050210,-157.951859,0.005793,0.000000
6.200000,3.814209,-157.951859,0.001065,0.000211,0.005351,16.966450,0.864312,0.053507,-157.951859,0.006149,0.000000
6.410000,4.005608,-157.907379,0.001087,0.000220,0.005593,17.817833,0.907684,0.055933,-157.907379,0.006495,0.000000
6.620000,4.181740,-157.951859,0.001099,0.000229,0.005828,18.601307,0.947596,0.058276,-157.951859,0.006851,0.000000
6.830000,4.589119,-157.907379,0.001112,0.000250,0.006339,20.413420,1.039909,0.063393,-157.907379,0.007198,0.000000
7.040000,4.939896,-157.907379,0.001134,0.000268,0.006816,21.973753,1.119396,0.068162,-157.907379,0.007545,0.000000
7.250000,5.052353,-157.951859,0.001134,0.000281,0.007146,22.473988,1.144880,0.071459,-157.951859,0.007900,0.000000
7.460001,5.173744,-157.951859,0.001143,0.000290,0.007371,23.013964,1.172387,0.073715,-157.951859,0.008247,0.000000
7.670001,5.505898,-158.040817,0.001164,0.000308,0.007822,24.491455,1.247654,0.078222,-158.040817,0.008594,0.000000
7.880001,5.701019,-157.951859,0.001168,0.000321,0.008161,25.359400,1.291869,0.081606,-157.951859,0.008950,0.000000
8.090000,5.985512,-157.951859,0.001186,0.000336,0.008533,26.624886,1.356336,0.085334,-157.951859,0.009296,0.000000
8.300000,6.105789,-158.040817,0.001194,0.000346,0.008785,27.159906,1.383592,0.087847,-158.040817,0.009644,0.000000
8.510000,6.307617,-157.907379,0.001207,0.000357,0.009080,28.057682,1.429327,0.090796,-157.907379,0.009999,0.000000
8.720000,6.497154,-158.040817,0.001220,0.000373,0.009479,28.900785,1.472276,0.094785,-158.040817,0.010346,0.000000
8.930000,6.897453,-157.951859,0.001229,0.000392,0.009964,30.681404,1.562985,0.099641,-157.951859,0.010693,0.000000
9.140000,6.964111,-158.085297,0.001246,0.000402,0.010216,30.977915,1.578090,0.102158,-158.085297,0.011048,0.000000
9.350000,7.110077,-157.996338,0.001259,0.000416,0.010571,31.627201,1.611166,0.105712,-157.996338,0.011395,0.000000
9.560000,7.293289,-158.040817,0.001259,0.000430,0.010927,32.442169,1.652683,0.109270,-158.040817,0.011751,0.000000
9.770000,7.364037,-157.996338,0.001293,0.000439,0.011153,32.756870,1.668715,0.111526,-157.996338,0.012098,0.000000
9.980000,7.593788,-157.996338,0.001293,0.000455,0.011551,33.778858,1.720777,0.115511,-157.996338,0.012445,0.000000
10.190001,7.800827,-157.996338,0.001306,0.000471,0.011959,34.699810,1.767693,0.119588,-157.996338,0.012800,0.000000
10.400001,7.798599,-158.129776,0.001315,0.000480,0.012184,34.689903,1.767188,0.121843,-158.129776,0.013147,0.000000
10.610001,7.807533,-158.040817,0.001319,0.000487,0.012358,34.729641,1.769212,0.123577,-158.040817,0.013494,0.000000
10.820001,8.417107,-158.129776,0.001337,0.000514,0.013051,37.441162,1.907344,0.130515,-158.129776,0.013849,0.000000
11.030001,8.389549,-158.040817,0.001345,0.000525,0.013338,37.318581,1.901099,0.133380,-158.040817,0.014196,0.000000
11.240001,8.458443,-158.040817,0.001367,0.000538,0.013659,37.625031,1.916710,0.136586,-158.040817,0.014543,0.000000
11.450001,8.565308,-158.085297,0.001375,0.000552,0.014014,38.100391,1.940926,0.140143,-158.085297,0.014899,0.000000
11.660001,8.551163,-158.085297,0.001397,0.000564,0.014327,38.037472,1.937721,0.143266,-158.085297,0.015246,0.000000
11.870001,8.856133,-158.085297,0.001414,0.000580,0.014726,39.394043,2.006828,0.147255,-158.085297,0.015601,0.000000
12.080001,8.986839,-158.129776,0.001423,0.000594,0.015081,39.975456,2.036447,0.150809,-158.129776,0.015948,0.000000
12.290001,9.034500,-158.040817,0.001436,0.000607,0.015428,40.187462,2.047247,0.154280,-158.040817,0.016295,0.000000
12.500001,8.888901,-158.129776,0.001444,0.000612,0.015540,39.539806,2.014254,0.155404,-158.129776,0.016651,0.000000
12.710001,9.236328,-158.085297,0.001457,0.000631,0.016035,41.085239,2.092982,0.160347,-158.085297,0.016998,0.000000
12.920001,9.549118,-158.085297,0.001483,0.000651,0.016538,42.476597,2.163861,0.165377,-158.085297,0.017344,0.000000
13.130001,9.465332,-158.040817,0.001492,0.000662,0.016807,42.103901,2.144875,0.168068,-158.040817,0.017700,0.000000
13.340001,9.507782,-158.129776,0.001513,0.000676,0.017162,42.292725,2.154494,0.171622,-158.129776,0.018047,0.000000
13.550000,9.501457,-158.129776,0.001518,0.000686,0.017414,42.264591,2.153061,0.174139,-158.129776,0.018394,0.000000
13.760000,9.553963,-158.174255,0.001531,0.000699,0.017743,42.498150,2.164959,0.177432,-158.174255,0.018749,0.000000
13.970000,9.804939,-158.218750,0.001548,0.000716,0.018194,43.614548,2.221831,0.181944,-158.218750,0.019096,0.000000
14.180000,9.819458,-158.129776,0.001552,0.000727,0.018463,43.679131,2.225121,0.184631,-158.129776,0.019452,0.000000
14.390000,9.635506,-158.174255,0.001561,0.000731,0.018576,42.860870,2.183437,0.185759,-158.174255,0.019799,0.000000
14.600000,10.289398,-158.218750,0.001582,0.000759,0.019270,45.769527,2.331611,0.192697,-158.218750,0.020145,0.000000
14.810000,10.356422,-158.174255,0.001604,0.000774,0.019669,46.067669,2.346799,0.196686,-158.174255,0.020501,0.000000
15.020000,10.389191,-158.174255,0.001617,0.000789,0.020041,46.213428,2.354224,0.200414,-158.174255,0.020848,0.000000
15.230000,10.305405,-158.174255,0.001625,0.000799,0.020293,45.840729,2.335238,0.202931,-158.174255,0.021195,0.000000
15.440001,10.260353,-158.174255,0.001643,0.000811,0.020597,45.640331,2.325029,0.205966,-158.174255,0.021550,0.000000
15.650001,10.529945,-158.218750,0.001647,0.000825,0.020961,46.839535,2.386120,0.209607,-158.218750,0.021897,0.000000
15.860001,10.659531,-158.263229,0.001664,0.000840,0.021342,47.415962,2.415484,0.213423,-158.263229,0.022244,0.000000
16.070002,10.720604,-158.263229,0.001681,0.000854,0.021689,47.687630,2.429323,0.216893,-158.263229,0.022600,0.000000
16.280001,10.725815,-158.218750,0.001681,0.000866,0.021984,47.710808,2.430504,0.219842,-158.218750,0.022947,0.000000
16.490002,10.909019,-158.174255,0.001699,0.000882,0.022409,48.525742,2.472019,0.224088,-158.174255,0.023293,0.000000
16.700001,11.223679,-158.218750,0.001725,0.000902,0.022903,49.925415,2.543322,0.229032,-158.218750,0.023649,0.000000
16.910002,11.011429,-158.174255,0.001733,0.000908,0.023068,48.981281,2.495225,0.230682,-158.174255,0.023996,0.000000
17.120001,11.129471,-158.218750,0.001746,0.000924,0.023467,49.506359,2.521974,0.234671,-158.218750,0.024352,0.000000
17.330000,11.172661,-158.174255,0.001750,0.000936,0.023771,49.698479,2.531761,0.237707,-158.174255,0.024698,0.000000
17.540001,11.288841,-158.218750,0.001772,0.000951,0.024152,50.215275,2.558088,0.241522,-158.218750,0.025045,0.000000
17.750000,11.475777,-158.307709,0.001789,0.000965,0.024516,51.046803,2.600448,0.245163,-158.307709,0.025401,0.000000
17.960001,11.532745,-158.218750,0.001802,0.000979,0.024855,51.300213,2.613358,0.248546,-158.218750,0.025748,0.000000
18.170000,11.316025,-158.263229,0.001807,0.000985,0.025028,50.336193,2.564248,0.250280,-158.263229,0.026095,0.000000
18.380001,11.618393,-158.307709,0.001815,0.001006,0.025540,51.681194,2.632766,0.255397,-158.307709,0.026450,0.000000
18.590000,12.009758,-158.218750,0.001841,0.001026,0.026060,53.422073,2.721450,0.260601,-158.218750,0.026797,0.000000
18.800001,11.936768,-158.263229,0.001845,0.001036,0.026320,53.097393,2.704910,0.263202,-158.263229,0.027144,0.000000
19.010000,11.897675,-158.263229,0.001871,0.001049,0.026632,52.923500,2.696052,0.266324,-158.263229,0.027500,0.000000
19.220001,11.948685,-158.352188,0.001884,0.001061,0.026962,53.150406,2.707611,0.269621,-158.352188,0.027847,0.000000
19.430000,11.834366,-158.307709,0.001880,0.001068,0.027127,52.641888,2.681706,0.271267,-158.307709,0.028202,0.000000
19.640001,12.222755,-158.218750,0.001901,0.001086,0.027595,54.369530,2.769716,0.275949,-158.218750,0.028549,0.000000
19.850000,12.423836,-158.307709,0.001906,0.001102,0.028003,55.263981,2.815282,0.280025,-158.307709,0.028896,0.000000
20.060001,12.270790,-158.263229,0.001919,0.001112,0.028246,54.583199,2.780601,0.282455,-158.263229,0.029252,0.000000
20.270000,12.383987,-158.307709,0.001940,0.001124,0.028549,55.086727,2.806252,0.285491,-158.307709,0.029598,0.000000
20.480001,12.493469,-158.307709,0.001932,0.001138,0.028913,55.573727,2.831061,0.289132,-158.307709,0.029945,0.000000
20.690001,13.117935,-158.307709,0.001962,0.001162,0.029520,58.351490,2.972567,0.295203,-158.307709,0.030301,0.000000
20.900002,12.892281,-158.396667,0.001983,0.001171,0.029746,57.347729,2.921432,0.297459,-158.396667,0.030647,0.000000
21.110001,12.863609,-158.352188,0.001983,0.001183,0.030058,57.220192,2.914935,0.300577,-158.352188,0.030995,0.000000
21.320002,12.898979,-158.352188,0.002005,0.001198,0.030422,57.377525,2.922951,0.304222,-158.352188,0.031350,0.000000
21.530001,13.259064,-158.396667,0.002018,0.001216,0.030882,58.979259,3.004547,0.308817,-158.396667,0.031697,0.000000
21.740002,13.313057,-158.352188,0.002039,0.001228,0.031203,59.219437,3.016782,0.312027,-158.352188,0.032052,0.000000
21.950001,13.253105,-158.396667,0.002048,0.001239,0.031463,58.952755,3.003196,0.314627,-158.396667,0.032399,0.000000
22.160002,13.276192,-158.396667,0.002052,0.001251,0.031775,59.055450,3.008428,0.317750,-158.396667,0.032746,0.000000
22.370001,13.540207,-158.396667,0.002070,0.001268,0.032200,60.229847,3.068255,0.322000,-158.396667,0.033102,0.000000
22.580002,13.801239,-158.307709,0.002082,0.001285,0.032642,61.390976,3.127406,0.326421,-158.307709,0.033449,0.000000
22.790001,13.706284,-158.352188,0.002100,0.001295,0.032894,60.968594,3.105888,0.328938,-158.352188,0.033796,0.000000
23.000002,13.753952,-158.396667,0.002117,0.001310,0.033267,61.180634,3.116690,0.332666,-158.396667,0.034151,0.000000
23.210001,13.765121,-158.396667,0.002113,0.001322,0.033588,61.230320,3.119221,0.335875,-158.396667,0.034498,0.000000
23.420002,13.912209,-158.441147,0.002134,0.001336,0.033926,61.884594,3.152552,0.339259,-158.441147,0.034845,0.000000
23.630001,14.206383,-158.441147,0.002147,0.001352,0.034342,63.193146,3.219212,0.343419,-158.441147,0.035201,0.000000
23.840002,14.022057,-158.396667,0.002173,0.001359,0.034516,62.373222,3.177444,0.345156,-158.396667,0.035547,0.000000
24.050001,14.356071,-158.485626,0.002182,0.001376,0.034949,63.858994,3.253132,0.349490,-158.485626,0.035894,0.000000
24.260000,14.358307,-158.485626,0.002186,0.001388,0.035253,63.868938,3.253639,0.352525,-158.485626,0.036250,0.000000
24.470001,14.758980,-158.441147,0.002207,0.001407,0.035747,65.651222,3.344433,0.357468,-158.441147,0.036597,0.000000
24.680000,14.586945,-158.485626,0.002212,0.001416,0.035964,64.885971,3.305449,0.359637,-158.485626,0.036952,0.000000
24.890001,14.773506,-158.485626,0.002225,0.001432,0.036363,65.715836,3.347724,0.363626,-158.485626,0.037299,0.000000
25.100000,15.106033,-158.441147,0.002246,0.001448,0.036779,67.194992,3.423076,0.367790,-158.441147,0.037646,0.000000
25.310001,15.186096,-158.441147,0.002242,0.001463,0.037152,67.551132,3.441219,0.371518,-158.441147,0.038002,0.000000
25.520000,15.388290,-158.441147,0.002268,0.001479,0.037568,68.450531,3.487036,0.375681,-158.441147,0.038349,0.000000
25.730001,15.297058,-158.530106,0.002276,0.001489,0.037828,68.044716,3.466363,0.378281,-158.530106,0.038696,0.000000
25.940001,15.113106,-158.441147,0.002294,0.001499,0.038071,67.226456,3.424679,0.380711,-158.441147,0.039051,0.000000
26.150002,15.424042,-158.485626,0.002307,0.001514,0.038461,68.609566,3.495138,0.384613,-158.485626,0.039398,0.000000
26.360001,15.877960,-158.485626,0.002320,0.001534,0.038973,70.628693,3.597997,0.389731,-158.485626,0.039745,0.000000
26.570002,15.712997,-158.485626,0.002337,0.001544,0.039224,69.894905,3.560616,0.392244,-158.485626,0.040100,0.000000
26.780001,15.923759,-158.574585,0.002358,0.001560,0.039623,70.832420,3.608376,0.396233,-158.574585,0.040447,0.000000
26.990002,15.874237,-158.485626,0.002354,0.001571,0.039901,70.612137,3.597153,0.399007,-158.485626,0.040803,0.000000
27.200001,15.997124,-158.619064,0.002376,0.001585,0.040265,71.158760,3.625000,0.402652,-158.619064,0.041150,0.000000
27.410002,16.328903,-158.530106,0.002393,0.001601,0.040673,72.634590,3.700182,0.406729,-158.530106,0.041496,0.000000
27.620001,16.425720,-158.530106,0.002402,0.001615,0.041028,73.065254,3.722121,0.410283,-158.530106,0.041852,0.000000
27.830002,16.279007,-158.530106,0.002406,0.001624,0.041245,72.412636,3.688876,0.412451,-158.530106,0.042199,0.000000
28.040001,16.760857,-158.530106,0.002423,0.001644,0.041748,74.556015,3.798064,0.417481,-158.530106,0.042546,0.000000
28.250002,16.996193,-158.574585,0.002453,0.001660,0.042164,75.602844,3.851393,0.421645,-158.574585,0.042901,0.000000
28.460001,16.971245,-158.574585,0.002458,0.001672,0.042459,75.491867,3.845739,0.424593,-158.574585,0.043248,0.000000
28.670002,16.974602,-158.530106,0.002470,0.001685,0.042797,75.506798,3.846500,0.427973,-158.530106,0.043595,0.000000
28.880001,17.004387,-158.619064,0.002470,0.001696,0.043066,75.639290,3.853249,0.430664,-158.619064,0.043951,0.000000
29.090002,17.287392,-158.619064,0.002488,0.001713,0.043509,76.898155,3.917379,0.435085,-158.619064,0.044298,0.000000
29.300001,17.412880,-158.619064,0.002501,0.001726,0.043847,77.456360,3.945815,0.438469,-158.619064,0.044653,0.000000
29.510002,17.575607,-158.574585,0.002505,0.001740,0.044185,78.180206,3.982690,0.441849,-158.574585,0.045000,0.000000
29.720001,17.516769,-158.619064,0.002531,0.001752,0.044497,77.918480,3.969357,0.444971,-158.619064,0.045347,0.000000
29.930002,17.357399,-158.619064,0.002539,0.001757,0.044636,77.209564,3.933243,0.446360,-158.619064,0.045703,0.000000
30.140001,18.378067,-158.530106,0.002552,0.001785,0.045339,81.749725,4.164529,0.453385,-158.530106,0.046050,0.000000
30.350002,18.122993,-158.619064,0.002570,0.001792,0.045529,80.615105,4.106729,0.455293,-158.619064,0.046396,0.000000
30.560001,18.253326,-158.619064,0.002578,0.001808,0.045928,81.194855,4.136263,0.459282,-158.619064,0.046752,0.000000
30.770002,18.330406,-158.619064,0.002596,0.001820,0.046232,81.537720,4.153729,0.462317,-158.619064,0.047099,0.000000
30.980001,18.550110,-158.663559,0.002608,0.001836,0.046631,82.515007,4.203515,0.466307,-158.663559,0.047446,0.000000
31.190001,18.512871,-158.574585,0.002626,0.001846,0.046882,82.349365,4.195076,0.468820,-158.574585,0.047801,0.000000
31.400002,18.745972,-158.619064,0.002630,0.001860,0.047255,83.386246,4.247898,0.472552,-158.619064,0.048148,0.000000
31.610001,18.783958,-158.663559,0.002630,0.001871,0.047533,83.555222,4.256506,0.475326,-158.663559,0.048504,0.000000
31.820002,18.770180,-158.708038,0.002656,0.001882,0.047793,83.493927,4.253383,0.477926,-158.708038,0.048851,0.000000
32.030003,19.396881,-158.663559,0.002665,0.001901,0.048287,86.281639,4.395396,0.482869,-158.663559,0.049198,0.000000
32.240002,19.644508,-158.619064,0.002677,0.001915,0.048643,87.383141,4.451509,0.486427,-158.619064,0.049553,0.000000
32.450001,19.659035,-158.708038,0.002690,0.001928,0.048963,87.447754,4.454801,0.489633,-158.708038,0.049900,0.000000
32.660000,20.029915,-158.708038,0.002703,0.001944,0.049388,89.097511,4.538844,0.493883,-158.708038,0.050247,0.000000
32.870003,19.987091,-158.619064,0.002721,0.001955,0.049657,88.907021,4.529140,0.496571,-158.619064,0.050603,0.000000
33.080002,20.372498,-158.752518,0.002725,0.001974,0.050134,90.621391,4.616474,0.501343,-158.752518,0.050949,0.000000
33.290001,20.589218,-158.619064,0.002742,0.001988,0.050490,91.585419,4.665584,0.504897,-158.619064,0.051296,0.000000
33.500000,20.567245,-158.752518,0.002759,0.001997,0.050724,91.487679,4.660604,0.507240,-158.752518,0.051652,0.000000
33.710003,20.601509,-158.796997,0.002768,0.002009,0.051019,91.640091,4.668369,0.510189,-158.796997,0.051999,0.000000
33.920002,20.648796,-158.708038,0.002772,0.002024,0.051400,91.850433,4.679084,0.514004,-158.708038,0.052345,0.000000
34.130001,21.518661,-158.796997,0.002790,0.002043,0.051886,95.719788,4.876198,0.518860,-158.796997,0.052701,0.000000
34.340000,21.462433,-158.708038,0.002807,0.002053,0.052155,95.469673,4.863457,0.521547,-158.708038,0.053048,0.000000
34.550003,21.622925,-158.752518,0.002820,0.002068,0.052536,96.183571,4.899825,0.525362,-158.752518,0.053404,0.000000
34.760002,21.646011,-158.708038,0.002828,0.002079,0.052814,96.286270,4.905056,0.528140,-158.708038,0.053750,0.000000
34.970001,21.703354,-158.708038,0.002833,0.002091,0.053100,96.541336,4.918050,0.531002,-158.708038,0.054098,0.000000
35.180000,22.228401,-158.752518,0.002854,0.002108,0.053551,98.876869,5.037028,0.535510,-158.752518,0.054453,0.000000
35.390003,22.251488,-158.752518,0.002854,0.002120,0.053846,98.979561,5.042259,0.538458,-158.752518,0.054800,0.000000
35.600002,22.212761,-158.752518,0.002876,0.002128,0.054063,98.807297,5.033484,0.540627,-158.752518,0.055147,0.000000
35.810001,23.144066,-158.708038,0.002897,0.002152,0.054661,102.949944,5.244520,0.546611,-158.708038,0.055502,0.000000
36.020000,23.287804,-158.708038,0.002897,0.002164,0.054956,103.589325,5.277092,0.549559,-158.708038,0.055849,0.000000
36.230003,23.545486,-158.841476,0.002919,0.002180,0.055364,104.735558,5.335483,0.553636,-158.841476,0.056196,0.000000
36.440002,23.771889,-158.796997,0.002928,0.002195,0.055754,105.742645,5.386787,0.557538,-158.796997,0.056552,0.000000
36.650002,23.650490,-158.796997,0.002953,0.002204,0.055988,105.202629,5.359277,0.559881,-158.796997,0.056899,0.000000
36.860001,23.783432,-158.841476,0.002940,0.002215,0.056265,105.793991,5.389403,0.562655,-158.841476,0.057254,0.000000
37.070004,24.161011,-158.796997,0.002953,0.002232,0.056699,107.473541,5.474963,0.566992,-158.796997,0.057601,0.000000
37.280003,24.638397,-158.885956,0.002971,0.002247,0.057072,109.597061,5.583140,0.570721,-158.885956,0.057948,0.000000
37.490002,24.631317,-158.752518,0.002984,0.002257,0.057323,109.565567,5.581536,0.573234,-158.752518,0.058303,0.000000
37.700001,24.639885,-158.841476,0.002992,0.002268,0.057618,109.603683,5.583478,0.576182,-158.841476,0.058650,0.000000
37.910004,25.260628,-158.930435,0.003005,0.002287,0.058087,112.364883,5.724140,0.580868,-158.930435,0.058997,0.000000
38.120003,25.853073,-158.796997,0.003027,0.002303,0.058503,115.000214,5.858390,0.585027,-158.796997,0.059353,0.000000
38.330002,25.966278,-158.841476,0.003040,0.002318,0.058867,115.503777,5.884043,0.588672,-158.841476,0.059700,0.000000
38.540001,26.155067,-158.796997,0.003040,0.002329,0.059153,116.343552,5.926823,0.591534,-158.796997,0.060047,0.000000
38.750000,26.197144,-158.885956,0.003057,0.002340,0.059440,116.530716,5.936357,0.594395,-158.885956,0.060402,0.000000
38.960003,26.311462,-158.841476,0.003070,0.002350,0.059700,117.039230,5.962263,0.596995,-158.841476,0.060749,0.000000
39.170002,27.264740,-158.885956,0.003078,0.002373,0.060272,121.279617,6.178278,0.602722,-158.885956,0.061104,0.000000
39.380001,27.196594,-158.930435,0.003100,0.002381,0.060489,120.976494,6.162836,0.604887,-158.930435,0.061452,0.000000
39.590000,27.245750,-158.885956,0.003100,0.002392,0.060766,121.195152,6.173975,0.607665,-158.885956,0.061798,0.000000
39.800003,28.295837,-158.885956,0.003122,0.002415,0.061339,125.866173,6.411929,0.613388,-158.885956,0.062154,0.000000
40.010002,28.840988,-158.885956,0.003130,0.002431,0.061738,128.291122,6.535461,0.617377,-158.885956,0.062501,0.000000
40.220001,28.657784,-158.841476,0.003130,0.002441,0.061998,127.476189,6.493947,0.619977,-158.841476,0.062848,0.000000
40.430000,28.922539,-158.885956,0.003152,0.002454,0.062336,128.653885,6.553941,0.623361,-158.885956,0.063203,0.000000
40.640003,28.919937,-158.930435,0.003156,0.002463,0.062570,128.642303,6.553351,0.625704,-158.930435,0.063550,0.000000
40.850002,29.045799,-158.885956,0.003165,0.002473,0.062822,129.202164,6.581872,0.628217,-158.885956,0.063897,0.000000
41.060001,30.184883,-158.974915,0.003191,0.002496,0.063403,134.269073,6.839993,0.634027,-158.974915,0.064253,0.000000
41.270000,30.050461,-158.930435,0.003203,0.002505,0.063637,133.671127,6.809532,0.636370,-158.930435,0.064599,0.000000
41.480003,30.056046,-158.930435,0.003216,0.002515,0.063888,133.695969,6.810798,0.638883,-158.930435,0.064947,0.000000
41.690002,30.549065,-158.930435,0.003225,0.002530,0.064253,135.889023,6.922517,0.642528,-158.930435,0.065302,0.000000
41.900002,30.538261,-158.930435,0.003234,0.002537,0.064435,135.840973,6.920069,0.644348,-158.930435,0.065649,0.000000
42.110001,32.151009,-159.019394,0.003242,0.002564,0.065137,143.014832,7.285523,0.651373,-159.019394,0.066004,0.000000
42.320004,31.935036,-158.930435,0.003260,0.002574,0.065389,142.054138,7.236582,0.653886,-158.930435,0.066351,0.000000
42.530003,32.319695,-159.019394,0.003268,0.002588,0.065727,143.765182,7.323747,0.657270,-159.019394,0.066698,0.000000
42.740002,32.775848,-158.930435,0.003277,0.002602,0.066082,145.794250,7.427114,0.660824,-158.930435,0.067054,0.000000
42.950001,33.484848,-158.974915,0.003298,0.002618,0.066499,148.948044,7.587775,0.664987,-158.974915,0.067401,0.000000
43.160004,33.636032,-159.019394,0.003294,0.002629,0.066785,149.620544,7.622034,0.667849,-159.019394,0.067747,0.000000
43.370003,33.726891,-159.019394,0.003316,0.002641,0.067071,150.024704,7.642622,0.670710,-159.019394,0.068103,0.000000
43.580002,34.294762,-158.974915,0.003316,0.002655,0.067435,152.550720,7.771304,0.674355,-158.974915,0.068450,0.000000
43.790001,35.078606,-159.063889,0.003328,0.002674,0.067921,156.037430,7.948926,0.679211,-159.063889,0.068797,0.000000
44.000004,35.607742,-158.930435,0.003341,0.002688,0.068285,158.391144,8.068830,0.682852,-158.930435,0.069152,0.000000
44.210003,36.006927,-159.063889,0.003359,0.002702,0.068624,160.166809,8.159286,0.686236,-159.063889,0.069499,0.000000
44.420002,36.043419,-158.974915,0.003350,0.002712,0.068875,160.329132,8.167556,0.688749,-158.974915,0.069855,0.000000
44.630001,36.403877,-159.108368,0.003380,0.002725,0.069205,161.932541,8.249236,0.692045,-159.108368,0.070202,0.000000
44.840004,37.001160,-159.108368,0.003380,0.002740,0.069595,164.589386,8.384583,0.695948,-159.108368,0.070549,0.000000
45.050003,37.513916,-159.019394,0.003393,0.002754,0.069941,166.870239,8.500775,0.699415,-159.019394,0.070904,0.000000
45.260002,37.283791,-159.019394,0.003410,0.002760,0.070098,165.846588,8.448627,0.700978,-159.019394,0.071251,0.000000
45.470001,38.396812,-159.063889,0.003415,0.002779,0.070592,170.797546,8.700842,0.705921,-159.063889,0.071598,0.000000
45.680000,38.857811,-159.063889,0.003436,0.002796,0.071008,172.848175,8.805305,0.710084,-159.063889,0.071953,0.000000
45.890003,39.483772,-159.063889,0.003436,0.002808,0.071329,175.632584,8.947150,0.713290,-159.063889,0.072301,0.000000
46.100002,39.469994,-159.063889,0.003436,0.002817,0.071546,175.571304,8.944028,0.715459,-159.063889,0.072647,0.000000
46.310001,40.257187,-159.063889,0.003462,0.002835,0.071997,179.072906,9.122409,0.719970,-159.063889,0.073003,0.000000
46.520000,40.960594,-159.063889,0.003458,0.002850,0.072396,182.201828,9.281803,0.723960,-159.063889,0.073350,0.000000
46.730003,41.654701,-159.108368,0.003484,0.002866,0.072795,185.289368,9.439091,0.727949,-159.108368,0.073706,0.000000
46.940002,42.198738,-159.152847,0.003479,0.002880,0.073142,187.709366,9.562371,0.731416,-159.152847,0.074052,0.000000
47.150002,42.431839,-159.152847,0.003497,0.002889,0.073393,188.746246,9.615191,0.733933,-159.152847,0.074399,0.000000
47.360001,42.967682,-159.152847,0.003497,0.002904,0.073766,191.129791,9.736615,0.737661,-159.152847,0.074755,0.000000
47.570004,43.502037,-159.108368,0.003510,0.002919,0.074130,193.506729,9.857702,0.741302,-159.108368,0.075102,0.000000
47.780003,44.443398,-159.108368,0.003535,0.002935,0.074538,197.694107,10.071018,0.745378,-159.108368,0.075448,0.000000
47.990002,45.072708,-159.197327,0.003527,0.002951,0.074963,200.493423,10.213622,0.749629,-159.197327,0.075804,0.000000
48.200001,45.278999,-159.152847,0.003544,0.002960,0.075180,201.411041,10.260368,0.751797,-159.152847,0.076151,0.000000
48.410004,45.788780,-159.152847,0.003548,0.002976,0.075579,203.678665,10.375886,0.755787,-159.152847,0.076498,0.000000
48.620003,46.815041,-159.108368,0.003557,0.002993,0.076021,208.243698,10.608440,0.760208,-159.108368,0.076853,0.000000
48.830002,47.203049,-159.108368,0.003583,0.003004,0.076290,209.969650,10.696363,0.762899,-159.108368,0.077200,0.000000
49.040001,47.663300,-159.286285,0.003596,0.003016,0.076602,212.016953,10.800658,0.766017,-159.286285,0.077547,0.000000
49.250004,48.189095,-159.197327,0.003596,0.003029,0.076949,214.355804,10.919805,0.769488,-159.197327,0.077903,0.000000
49.460003,49.184441,-159.152847,0.003600,0.003047,0.077383,218.783325,11.145353,0.773826,-159.152847,0.078250,0.000000
49.670002,49.978340,-159.197327,0.003617,0.003063,0.077807,222.314758,11.325253,0.778072,-159.197327,0.078605,0.000000
49.880001,50.419228,-159.197327,0.003626,0.003074,0.078076,224.275925,11.425160,0.780763,-159.197327,0.078952,0.000000
50.090004,50.892517,-159.197327,0.003626,0.003087,0.078406,226.381226,11.532409,0.784056,-159.197327,0.079299,0.000000
50.300003,51.388519,-159.152847,0.003639,0.003102,0.078796,228.587555,11.644805,0.787958,-159.152847,0.079655,0.000000
50.510002,52.225609,-159.241806,0.003643,0.003116,0.079143,232.311111,11.834493,0.791429,-159.241806,0.080001,0.000000
50.720001,52.889175,-159.197327,0.003660,0.003129,0.079473,235.262802,11.984859,0.794726,-159.197327,0.080348,0.000000
50.930004,53.553490,-159.241806,0.003660,0.003142,0.079802,238.217819,12.135394,0.798019,-159.241806,0.080704,0.000000
51.140003,54.144821,-159.197327,0.003678,0.003154,0.080123,240.848190,12.269392,0.801228,-159.197327,0.081051,0.000000
51.350002,54.850838,-159.241806,0.003682,0.003170,0.080513,243.988708,12.429377,0.805130,-159.241806,0.081398,0.000000
51.560001,56.014496,-159.241806,0.003695,0.003187,0.080938,249.164917,12.693066,0.809381,-159.241806,0.081753,0.000000
51.770004,56.244995,-159.241806,0.003699,0.003198,0.081224,250.190231,12.745297,0.812242,-159.241806,0.082100,0.000000
51.980003,57.006500,-159.197327,0.003712,0.003211,0.081554,253.577576,12.917857,0.815539,-159.197327,0.082456,0.000000
52.190002,57.447762,-159.286285,0.003708,0.003224,0.081901,255.540405,13.017849,0.819006,-159.286285,0.082803,0.000000
52.400002,58.326935,-159.197327,0.003738,0.003236,0.082195,259.451172,13.217072,0.821954,-159.197327,0.083150,0.000000
52.610001,59.044868,-159.286285,0.003729,0.003252,0.082594,262.644684,13.379759,0.825944,-159.286285,0.083505,0.000000
52.820004,59.632469,-159.286285,0.003729,0.003263,0.082889,265.258484,13.512911,0.828892,-159.286285,0.083852,0.000000
53.030003,60.042824,-159.330765,0.003755,0.003272,0.083115,267.083832,13.605899,0.831148,-159.330765,0.084199,0.000000
53.240002,60.566750,-159.330765,0.003751,0.003284,0.083401,269.414368,13.724622,0.834009,-159.330765,0.084555,0.000000
53.450001,62.380951,-159.241806,0.003764,0.003311,0.084095,277.484314,14.135726,0.840947,-159.241806,0.084901,0.000000
53.660004,63.039299,-159.330765,0.003760,0.003319,0.084312,280.412811,14.284909,0.843116,-159.330765,0.085248,0.000000
53.870003,63.588921,-159.286285,0.003777,0.003332,0.084641,282.857635,14.409455,0.846412,-159.286285,0.085604,0.000000
54.080002,64.397728,-159.241806,0.003786,0.003346,0.084988,286.455414,14.592733,0.849879,-159.241806,0.085950,0.000000
54.290001,65.069115,-159.375244,0.003777,0.003358,0.085300,289.441864,14.744872,0.853002,-159.375244,0.086306,0.000000
54.500004,66.361610,-159.375244,0.003803,0.003376,0.085751,295.191193,15.037756,0.857510,-159.375244,0.086653,0.000000
54.710003,67.197960,-159.330765,0.003807,0.003391,0.086124,298.911469,15.227276,0.861242,-159.330765,0.087000,0.000000
54.920002,67.103752,-159.375244,0.003820,0.003386,0.086011,298.492401,15.205928,0.860114,-159.375244,0.086237,0.000000
55.130001,66.423805,-159.330765,0.003824,0.003386,0.086011,295.467834,15.051850,0.860114,-159.330765,0.086237,0.000000
55.340004,65.800453,-159.375244,0.003820,0.003386,0.085994,292.695038,14.910596,0.859940,-159.375244,0.086011,0.000000
55.550003,65.240028,-159.375244,0.003829,0.003385,0.085985,290.202148,14.783602,0.859852,-159.375244,0.086011,0.000000
55.760002,64.717964,-159.375244,0.003837,0.003385,0.085977,287.879883,14.665300,0.859765,-159.375244,0.086011,0.000000
55.970001,64.225685,-159.375244,0.003842,0.003385,0.085977,285.690125,14.553748,0.859765,-159.375244,0.086011,0.000000
56.180004,63.777351,-159.375244,0.003837,0.003385,0.085968,283.695831,14.452154,0.859678,-159.375244,0.086011,0.000000
56.390003,63.364021,-159.419724,0.003837,0.003385,0.085968,281.857239,14.358493,0.859678,-159.419724,0.086011,0.000000
56.600002,62.985687,-159.419724,0.003859,0.003385,0.085968,280.174316,14.272760,0.859678,-159.419724,0.086011,0.000000
56.810001,62.623741,-159.375244,0.003854,0.003385,0.085968,278.564301,14.190742,0.859678,-159.375244,0.086011,0.000000
57.020004,62.291954,-159.464203,0.003850,0.003385,0.085968,277.088440,14.115559,0.859678,-159.464203,0.086011,0.000000
57.230003,61.958305,-159.375244,0.003863,0.003384,0.085959,275.604309,14.039953,0.859591,-159.375244,0.086011,0.000000
57.440002,61.655571,-159.464203,0.003867,0.003384,0.085959,274.257690,13.971352,0.859591,-159.464203,0.086011,0.000000
57.650002,61.378151,-159.419724,0.003859,0.003384,0.085959,273.023651,13.908487,0.859591,-159.419724,0.086011,0.000000
57.860004,61.111160,-159.419724,0.003854,0.003384,0.085959,271.836029,13.847987,0.859591,-159.419724,0.086011,0.000000
58.070004,60.870979,-159.419724,0.003867,0.003384,0.085959,270.767639,13.793561,0.859591,-159.419724,0.086011,0.000000
58.280003,60.619629,-159.464203,0.003872,0.003384,0.085959,269.649567,13.736604,0.859591,-159.464203,0.086011,0.000000
58.490002,60.398071,-159.464203,0.003863,0.003384,0.085959,268.664032,13.686399,0.859591,-159.464203,0.086011,0.000000
58.700005,60.180977,-159.375244,0.003867,0.003384,0.085959,267.698364,13.637204,0.859591,-159.375244,0.086011,0.000000
58.910004,59.960159,-159.464203,0.003880,0.003384,0.085959,266.716095,13.587166,0.859591,-159.464203,0.086011,0.000000
59.120003,59.780304,-159.553177,0.003867,0.003384,0.085959,265.916077,13.546411,0.859591,-159.553177,0.086011,0.000000
59.330002,59.589645,-159.419724,0.003880,0.003384,0.085959,265.067993,13.503206,0.859591,-159.419724,0.086011,0.000000
59.540005,59.413139,-159.508698,0.003867,0.003384,0.085959,264.282837,13.463209,0.859591,-159.508698,0.086011,0.000000
59.750004,59.223236,-159.508698,0.003859,0.003384,0.085959,263.438110,13.420177,0.859591,-159.508698,0.086011,0.000000
59.960003,59.070930,-159.508698,0.003876,0.003384,0.085959,262.760620,13.385664,0.859591,-159.508698,0.086011,0.000000
60.170002,58.915283,-159.508698,0.003876,0.003384,0.085959,262.068268,13.350394,0.859591,-159.508698,0.086011,0.000000
60.380001,58.746223,-159.508698,0.003880,0.003384,0.085959,261.316254,13.312085,0.859591,-159.508698,0.086011,0.000000
60.590004,58.598389,-159.553177,0.003880,0.003384,0.085959,260.658661,13.278584,0.859591,-159.553177,0.086011,0.000000
60.800003,58.462479,-159.508698,0.003872,0.003384,0.085959,260.054108,13.247787,0.859591,-159.508698,0.086011,0.000000
61.010002,58.320229,-159.553177,0.003889,0.003384,0.085959,259.421326,13.215553,0.859591,-159.553177,0.086011,0.000000
61.220001,58.199211,-159.508698,0.003880,0.003384,0.085959,258.883026,13.188129,0.859591,-159.508698,0.086011,0.000000
61.430004,58.064781,-159.464203,0.003872,0.003384,0.085959,258.285034,13.157667,0.859591,-159.464203,0.086011,0.000000
61.640003,57.956047,-159.642136,0.003876,0.003384,0.085959,257.801361,13.133028,0.859591,-159.642136,0.086011,0.000000
61.850002,57.827957,-159.553177,0.003889,0.003384,0.085959,257.231598,13.104002,0.859591,-159.553177,0.086011,0.000000
62.060001,57.706932,-159.597656,0.003889,0.003384,0.085959,256.693268,13.076578,0.859591,-159.597656,0.086011,0.000000
62.270004,57.595963,-159.642136,0.003880,0.003384,0.085950,256.199646,13.051432,0.859504,-159.642136,0.086011,0.000000
62.480003,57.487976,-159.597656,0.003885,0.003384,0.085950,255.719284,13.026962,0.859504,-159.597656,0.086011,0.000000
62.690002,57.375519,-159.597656,0.003885,0.003384,0.085950,255.219055,13.001479,0.859504,-159.597656,0.086011,0.000000
62.900002,57.269768,-159.597656,0.003889,0.003384,0.085950,254.748657,12.977515,0.859504,-159.597656,0.086011,0.000000
63.110004,57.175926,-159.553177,0.003898,0.003384,0.085950,254.331223,12.956250,0.859504,-159.553177,0.086011,0.000000
63.320004,57.079857,-159.642136,0.003876,0.003384,0.085950,253.903885,12.934480,0.859504,-159.642136,0.086011,0.000000
63.530003,56.981178,-159.553177,0.003893,0.003384,0.085950,253.464935,12.912120,0.859504,-159.553177,0.086011,0.000000
63.740002,56.898140,-159.642136,0.003893,0.003384,0.085950,253.095566,12.893303,0.859504,-159.642136,0.086011,0.000000
63.950005,56.802437,-159.553177,0.003893,0.003384,0.085950,252.669861,12.871616,0.859504,-159.553177,0.086011,0.000000
64.160004,56.724617,-159.642136,0.003880,0.003384,0.085950,252.323700,12.853982,0.859504,-159.642136,0.086011,0.000000
64.370003,56.636360,-159.686615,0.003893,0.003384,0.085950,251.931107,12.833982,0.859504,-159.686615,0.086011,0.000000
64.580002,56.539543,-159.553177,0.003898,0.003384,0.085950,251.500443,12.812044,0.859504,-159.553177,0.086011,0.000000
64.790001,56.475868,-159.686615,0.003898,0.003384,0.085950,251.217209,12.797615,0.859504,-159.686615,0.086011,0.000000
65.000000,56.384636,-159.642136,0.003898,0.003384,0.085950,250.811386,12.776941,0.859504,-159.642136,0.086011,0.000000
65.210007,56.306808,-159.642136,0.003906,0.003384,0.085950,250.465195,12.759305,0.859504,-159.642136,0.086011,0.000000
65.420006,56.238297,-159.686615,0.003898,0.003384,0.085950,250.160431,12.743780,0.859504,-159.686615,0.086011,0.000000
65.630005,56.161217,-159.642136,0.003898,0.003384,0.085950,249.817566,12.726314,0.859504,-159.642136,0.086011,0.000000
65.840004,56.075943,-159.731094,0.003893,0.003384,0.085950,249.438248,12.706990,0.859504,-159.731094,0.086011,0.000000
66.050003,56.012634,-159.642136,0.003906,0.003384,0.085950,249.156647,12.692645,0.859504,-159.642136,0.086011,0.000000
66.260002,55.943001,-159.686615,0.003906,0.003384,0.085950,248.846893,12.676866,0.859504,-159.686615,0.086011,0.000000
66.470001,55.864433,-159.686615,0.003898,0.003384,0.085950,248.497406,12.659061,0.859504,-159.686615,0.086011,0.000000
66.680000,55.808205,-159.686615,0.003885,0.003384,0.085950,248.247299,12.646320,0.859504,-159.686615,0.086011,0.000000
66.889999,55.735596,-159.731094,0.003902,0.003384,0.085950,247.924316,12.629867,0.859504,-159.731094,0.086011,0.000000
67.100006,55.667076,-159.686615,0.003898,0.003384,0.085950,247.619522,12.614340,0.859504,-159.686615,0.086011,0.000000
67.310005,55.613457,-159.731094,0.003898,0.003384,0.085950,247.381012,12.602189,0.859504,-159.731094,0.086011,0.000000
67.520004,55.555740,-159.731094,0.003898,0.003384,0.085950,247.124283,12.589110,0.859504,-159.731094,0.086011,0.000000
67.730003,55.489830,-159.686615,0.003902,0.003384,0.085950,246.831085,12.574175,0.859504,-159.686615,0.086011,0.000000
67.940002,55.418701,-159.731094,0.003906,0.003384,0.085950,246.514694,12.558057,0.859504,-159.731094,0.086011,0.000000
68.150002,55.369179,-159.731094,0.003902,0.003384,0.085950,246.294403,12.546835,0.859504,-159.731094,0.086011,0.000000
68.360001,55.314812,-159.731094,0.003902,0.003384,0.085950,246.052567,12.534515,0.859504,-159.731094,0.086011,0.000000
68.570000,55.248528,-159.820053,0.003906,0.003384,0.085950,245.757721,12.519495,0.859504,-159.820053,0.086011,0.000000
68.780006,55.199005,-159.731094,0.003893,0.003384,0.085950,245.537445,12.508273,0.859504,-159.731094,0.086011,0.000000
68.990005,55.139427,-159.775574,0.003893,0.003384,0.085950,245.272415,12.494773,0.859504,-159.775574,0.086011,0.000000
69.200005,55.082451,-159.820053,0.003906,0.003384,0.085950,245.018982,12.481862,0.859504,-159.820053,0.086011,0.000000
69.410004,55.033669,-159.820053,0.003898,0.003384,0.085950,244.801987,12.470807,0.859504,-159.820053,0.086011,0.000000
69.620003,54.987122,-159.820053,0.003893,0.003384,0.085950,244.594940,12.460260,0.859504,-159.820053,0.086011,0.000000
69.830002,54.923073,-159.775574,0.003906,0.003384,0.085950,244.310028,12.445746,0.859504,-159.775574,0.086011,0.000000
70.040001,54.869827,-159.775574,0.003906,0.003384,0.085950,244.073181,12.433681,0.859504,-159.775574,0.086011,0.000000
70.250000,54.831474,-159.775574,0.003902,0.003384,0.085950,243.902573,12.424990,0.859504,-159.775574,0.086011,0.000000
70.460007,54.781578,-159.731094,0.003906,0.003384,0.085950,243.680634,12.413683,0.859504,-159.731094,0.086011,0.000000
70.670006,54.728325,-159.820053,0.003906,0.003384,0.085950,243.443741,12.401615,0.859504,-159.820053,0.086011,0.000000
70.880005,54.686623,-159.775574,0.003889,0.003384,0.085950,243.258240,12.392165,0.859504,-159.775574,0.086011,0.000000
71.090004,54.649384,-159.864532,0.003906,0.003384,0.085950,243.092606,12.383727,0.859504,-159.864532,0.086011,0.000000
71.300003,54.600601,-159.775574,0.003911,0.003384,0.085950,242.875610,12.372673,0.859504,-159.775574,0.086011,0.000000
71.510002,54.559265,-159.775574,0.003915,0.003384,0.085950,242.691727,12.363306,0.859504,-159.775574,0.086011,0.000000
71.720001,54.516815,-159.864532,0.003902,0.003384,0.085950,242.502899,12.353686,0.859504,-159.864532,0.086011,0.000000
71.930000,54.477722,-159.820053,0.003915,0.003384,0.085950,242.329010,12.344828,0.859504,-159.820053,0.086011,0.000000
72.140007,54.426331,-159.909012,0.003906,0.003384,0.085950,242.100403,12.333183,0.859504,-159.909012,0.086011,0.000000
72.350006,54.381271,-159.820053,0.003906,0.003384,0.085950,241.899979,12.322971,0.859504,-159.820053,0.086011,0.000000
72.560005,54.341431,-159.820053,0.003906,0.003384,0.085950,241.722763,12.313944,0.859504,-159.820053,0.086011,0.000000
72.770004,54.298981,-159.864532,0.003902,0.003384,0.085950,241.533936,12.304325,0.859504,-159.864532,0.086011,0.000000
72.980003,54.263229,-159.864532,0.003902,0.003384,0.085950,241.374893,12.296223,0.859504,-159.864532,0.086011,0.000000
73.190002,54.218918,-159.864532,0.003915,0.003384,0.085950,241.177795,12.286182,0.859504,-159.864532,0.086011,0.000000
73.400002,54.186523,-159.864532,0.003911,0.003384,0.085950,241.033691,12.278842,0.859504,-159.864532,0.086011,0.000000
73.610001,54.156364,-159.864532,0.003919,0.003384,0.085950,240.899536,12.272007,0.859504,-159.864532,0.086011,0.000000
73.820000,54.116890,-159.909012,0.003915,0.003384,0.085950,240.723953,12.263062,0.859504,-159.909012,0.086011,0.000000
74.030006,54.083374,-159.953506,0.003915,0.003384,0.085950,240.574860,12.255467,0.859504,-159.953506,0.086011,0.000000
74.240005,54.050232,-159.997986,0.003911,0.003384,0.085950,240.427444,12.247958,0.859504,-159.997986,0.086011,0.000000
74.450005,54.014114,-159.864532,0.003915,0.003384,0.085950,240.266785,12.239774,0.859504,-159.864532,0.086011,0.000000
74.660004,53.976135,-159.909012,0.003919,0.003384,0.085950,240.097839,12.231167,0.859504,-159.909012,0.086011,0.000000
74.870003,53.931450,-159.997986,0.003906,0.003384,0.085950,239.899063,12.221041,0.859504,-159.997986,0.086011,0.000000
75.080002,53.894958,-159.909012,0.003915,0.003384,0.085950,239.736755,12.212772,0.859504,-159.909012,0.086011,0.000000
75.290001,53.876335,-160.042465,0.003928,0.003384,0.085950,239.653915,12.208552,0.859504,-160.042465,0.086011,0.000000
75.500000,53.834259,-159.953506,0.003919,0.003384,0.085950,239.466751,12.199018,0.859504,-159.953506,0.086011,0.000000
75.710007,53.800369,-159.953506,0.003911,0.003384,0.085950,239.315994,12.191338,0.859504,-159.953506,0.086011,0.000000
75.920006,53.766487,-159.997986,0.003919,0.003384,0.085950,239.165283,12.183660,0.859504,-159.997986,0.086011,0.000000
76.130005,53.736328,-159.953506,0.003915,0.003384,0.085950,239.031128,12.176826,0.859504,-159.953506,0.086011,0.000000
76.340004,53.693130,-159.997986,0.003911,0.003384,0.085950,238.838974,12.167037,0.859504,-159.997986,0.086011,0.000000
76.550003,53.666695,-159.997986,0.003915,0.003384,0.085950,238.721375,12.161046,0.859504,-159.997986,0.086011,0.000000
76.760002,53.633553,-159.953506,0.003923,0.003384,0.085950,238.573959,12.153537,0.859504,-159.953506,0.086011,0.000000
76.970001,53.591843,-160.042465,0.003915,0.003384,0.085950,238.388428,12.144085,0.859504,-160.042465,0.086011,0.000000
77.180000,53.564659,-159.953506,0.003915,0.003384,0.085950,238.267502,12.137925,0.859504,-159.953506,0.086011,0.000000
77.390007,53.538597,-160.042465,0.003919,0.003384,0.085950,238.151581,12.132019,0.859504,-160.042465,0.086011,0.000000
77.600006,53.514763,-159.997986,0.003919,0.003384,0.085950,238.045547,12.126618,0.859504,-159.997986,0.086011,0.000000
77.810005,53.476784,-159.997986,0.003915,0.003384,0.085950,237.876617,12.118012,0.859504,-159.997986,0.086011,0.000000
78.020004,53.438057,-160.042465,0.003915,0.003384,0.085950,237.704346,12.109237,0.859504,-160.042465,0.086011,0.000000
78.230003,53.420929,-159.997986,0.003919,0.003384,0.085950,237.628159,12.105356,0.859504,-159.997986,0.086011,0.000000
78.440002,53.397469,-160.042465,0.003923,0.003384,0.085950,237.523804,12.100039,0.859504,-160.042465,0.086011,0.000000
78.650002,53.365067,-160.042465,0.003919,0.003384,0.085950,237.379669,12.092697,0.859504,-160.042465,0.086011,0.000000
78.860001,53.333046,-159.997986,0.003928,0.003384,0.085950,237.237244,12.085441,0.859504,-159.997986,0.086011,0.000000
79.070007,53.302513,-160.042465,0.003915,0.003384,0.085950,237.101425,12.078522,0.859504,-160.042465,0.086011,0.000000
79.280006,53.275330,-159.997986,0.003911,0.003384,0.085950,236.980499,12.072362,0.859504,-159.997986,0.086011,0.000000
79.490005,53.245163,-160.042465,0.003919,0.003384,0.085950,236.846313,12.065526,0.859504,-160.042465,0.086011,0.000000
79.700005,53.218353,-160.042465,0.003915,0.003384,0.085950,236.727051,12.059451,0.859504,-160.042465,0.086011,0.000000
79.910004,53.198616,-160.042465,0.003919,0.003384,0.085950,236.639267,12.054979,0.859504,-160.042465,0.086011,0.000000
80.120003,53.163246,-160.131424,0.003919,0.003384,0.085950,236.481934,12.046964,0.859504,-160.131424,0.086011,0.000000
80.330002,53.128242,-160.042465,0.003923,0.003384,0.085950,236.326233,12.039032,0.859504,-160.042465,0.086011,0.000000
80.540001,53.108131,-160.131424,0.003915,0.003384,0.085950,236.236771,12.034474,0.859504,-160.131424,0.086011,0.000000
80.750008,53.080208,-160.042465,0.003919,0.003384,0.085950,236.112564,12.028147,0.859504,-160.042465,0.086011,0.000000
80.960007,53.053024,-160.086945,0.003923,0.003384,0.085950,235.991638,12.021987,0.859504,-160.086945,0.086011,0.000000
81.170006,53.039246,-160.131424,0.003919,0.003384,0.085950,235.930344,12.018865,0.859504,-160.131424,0.086011,0.000000
81.380005,53.014297,-160.042465,0.003919,0.003384,0.085950,235.819366,12.013211,0.859504,-160.042465,0.086011,0.000000
81.590004,52.988228,-160.042465,0.003923,0.003384,0.085950,235.703415,12.007304,0.859504,-160.042465,0.086011,0.000000
81.800003,52.961792,-160.131424,0.003919,0.003384,0.085950,235.585815,12.001313,0.859504,-160.131424,0.086011,0.000000
82.010002,52.937210,-160.086945,0.003923,0.003384,0.085950,235.476471,11.995743,0.859504,-160.086945,0.086011,0.000000
82.220001,52.896996,-160.175903,0.003919,0.003384,0.085950,235.297592,11.986630,0.859504,-160.175903,0.086011,0.000000
82.430000,52.871307,-160.175903,0.003915,0.003384,0.085950,235.183319,11.980810,0.859504,-160.175903,0.086011,0.000000
82.640007,52.844864,-160.131424,0.003915,0.003384,0.085950,235.065689,11.974817,0.859504,-160.131424,0.086011,0.000000
82.850006,52.832581,-160.175903,0.003915,0.003384,0.085950,235.011063,11.972034,0.859504,-160.175903,0.086011,0.000000
83.060005,52.793854,-160.175903,0.003919,0.003384,0.085950,234.838791,11.963259,0.859504,-160.175903,0.086011,0.000000
83.270004,52.777840,-160.175903,0.003915,0.003384,0.085950,234.767563,11.959629,0.859504,-160.175903,0.086011,0.000000
83.480003,52.761078,-160.131424,0.003923,0.003384,0.085950,234.692993,11.955831,0.859504,-160.131424,0.086011,0.000000
83.690002,52.737625,-160.220383,0.003915,0.003384,0.085950,234.588669,11.950517,0.859504,-160.220383,0.086011,0.000000
83.900002,52.707832,-160.131424,0.003923,0.003384,0.085950,234.456146,11.943766,0.859504,-160.131424,0.086011,0.000000
84.110001,52.687721,-160.131424,0.003923,0.003384,0.085950,234.366684,11.939208,0.859504,-160.131424,0.086011,0.000000
84.320007,52.664261,-160.220383,0.003928,0.003384,0.085950,234.262329,11.933892,0.859504,-160.220383,0.086011,0.000000
84.530006,52.652351,-160.175903,0.003928,0.003384,0.085950,234.209351,11.931193,0.859504,-160.175903,0.086011,0.000000
84.740005,52.622559,-160.264862,0.003923,0.003384,0.085950,234.076828,11.924442,0.859504,-160.264862,0.086011,0.000000
84.950005,52.605431,-160.220383,0.003919,0.003384,0.085950,234.000641,11.920561,0.859504,-160.220383,0.086011,0.000000
85.160004,52.590904,-160.175903,0.003928,0.003384,0.085950,233.936020,11.917270,0.859504,-160.175903,0.086011,0.000000
85.370003,52.564468,-160.264862,0.003932,0.003384,0.085950,233.818436,11.911279,0.859504,-160.264862,0.086011,0.000000
85.400002,52.567444,-160.175903,0.003911,0.003384,0.085950,233.831665,11.911953,0.859504,-160.175903,0.086011,0.000000