File: Data/compression 27/AutoNoHeating-17-27-reverse-1-2_10162024_171305.csv
Time (sec),S:Load (lbs),S:HL1 (DIM),S:LVDT (in),S:Position (in),Ch:Position (mm),Ch:Load (N),Ch:Stress (MPa),Ch:Strain (mm/mm),Ch:HL1 (DIM),Set Point (),Cycles ()
0.110000,-0.014153,-170.406525,-0.013849,-0.009150,-0.232417,-0.062954,-0.003207,-2.324168,-170.406525,-0.232226,0.000000
0.490000,-0.024948,-170.539963,-0.013840,-0.009074,-0.230474,-0.110975,-0.005653,-2.304744,-170.539963,-0.229779,0.000000
0.870000,-0.028671,-170.539963,-0.013693,-0.008842,-0.224578,-0.127536,-0.006497,-2.245775,-170.539963,-0.223450,0.000000
1.250000,-0.046921,-170.539963,-0.013430,-0.008596,-0.218341,-0.208714,-0.010632,-2.183415,-170.539963,-0.217118,0.000000
1.630000,0.000374,-170.539963,-0.013189,-0.008351,-0.212115,0.001663,0.000085,-2.121146,-170.539963,-0.210788,0.000000
2.010000,0.022339,-170.628922,-0.012926,-0.008104,-0.205853,0.099368,0.005062,-2.058529,-170.628922,-0.204457,0.000000
2.390000,0.005959,-170.717896,-0.012676,-0.007852,-0.199453,0.026505,0.001350,-1.994534,-170.717896,-0.198126,0.000000
2.770000,0.012657,-170.762375,-0.012430,-0.007600,-0.193052,0.056302,0.002868,-1.930524,-170.762375,-0.191796,0.000000
3.150000,-0.004097,-170.673416,-0.012184,-0.007353,-0.186757,-0.018224,-0.000928,-1.867573,-170.673416,-0.185464,0.000000
3.530000,0.016006,-170.762375,-0.011887,-0.007100,-0.180331,0.071200,0.003627,-1.803306,-170.762375,-0.179135,0.000000
3.910000,0.017502,-170.895813,-0.011637,-0.006849,-0.173966,0.077852,0.003966,-1.739659,-170.895813,-0.172803,0.000000
4.290000,0.018242,-170.895813,-0.011391,-0.006599,-0.167609,0.081144,0.004134,-1.676088,-170.895813,-0.166473,0.000000
4.670000,0.016754,-170.895813,-0.011137,-0.006347,-0.161226,0.074526,0.003797,-1.612259,-170.895813,-0.160142,0.000000
5.050000,0.002602,-170.940292,-0.010895,-0.006102,-0.154982,0.011573,0.000590,-1.549824,-170.940292,-0.153811,0.000000
5.430000,-0.008568,-170.984772,-0.010606,-0.005851,-0.148616,-0.038112,-0.001941,-1.486162,-170.984772,-0.147481,0.000000
5.810000,-0.018250,-171.029251,-0.010369,-0.005601,-0.142268,-0.081178,-0.004135,-1.422681,-171.029251,-0.141149,0.000000
6.190000,0.003723,-171.118225,-0.010111,-0.005352,-0.135946,0.016561,0.000844,-1.359459,-171.118225,-0.134819,0.000000
6.570000,0.005585,-171.118225,-0.009856,-0.005107,-0.129711,0.024842,0.001266,-1.297114,-171.118225,-0.128488,0.000000
6.950000,-0.008194,-171.118225,-0.009602,-0.004857,-0.123371,-0.036449,-0.001857,-1.233709,-171.118225,-0.122157,0.000000
7.330000,-0.039474,-171.118225,-0.009339,-0.004608,-0.117041,-0.175591,-0.008945,-1.170411,-171.118225,-0.115827,0.000000
7.710001,-0.064423,-171.207184,-0.009071,-0.004356,-0.110640,-0.286566,-0.014598,-1.106400,-171.207184,-0.109495,0.000000
8.090000,0.003723,-171.340622,-0.008821,-0.004105,-0.104275,0.016561,0.000844,-1.042754,-171.340622,-0.103166,0.000000
8.470000,-0.006706,-171.251663,-0.008580,-0.003856,-0.097944,-0.029831,-0.001520,-0.979440,-171.251663,-0.096834,0.000000
8.850000,0.035744,-171.385101,-0.008317,-0.003608,-0.091649,0.158996,0.008100,-0.916490,-171.385101,-0.090504,0.000000
9.230000,0.005959,-171.429581,-0.008054,-0.003356,-0.085231,0.026505,0.001350,-0.852313,-171.429581,-0.084173,0.000000
9.610001,0.007446,-171.429581,-0.007787,-0.003107,-0.078909,0.033123,0.001687,-0.789090,-171.429581,-0.077842,0.000000
9.990001,0.001862,-171.429581,-0.007528,-0.002855,-0.072517,0.008281,0.000422,-0.725171,-171.429581,-0.071512,0.000000
10.370001,0.044685,-171.518555,-0.007286,-0.002610,-0.066290,0.198770,0.010126,-0.662902,-171.518555,-0.065180,0.000000
10.750001,0.070747,-171.563034,-0.007049,-0.002365,-0.060081,0.314700,0.016032,-0.600814,-171.563034,-0.058851,0.000000
11.130000,0.047661,-171.518555,-0.006769,-0.002124,-0.053941,0.212006,0.010800,-0.539408,-171.518555,-0.052519,0.000000
11.510000,0.013031,-171.651993,-0.006523,-0.001868,-0.047455,0.057965,0.002953,-0.474550,-171.651993,-0.046188,0.000000
11.890000,0.024200,-171.696472,-0.006278,-0.001619,-0.041115,0.107649,0.005484,-0.411146,-171.696472,-0.039858,0.000000
12.270000,0.058464,-171.740952,-0.006015,-0.001370,-0.034810,0.260061,0.013248,-0.348104,-171.740952,-0.033527,0.000000
12.650001,0.072983,-171.740952,-0.005752,-0.001117,-0.028376,0.324644,0.016538,-0.283761,-171.740952,-0.027197,0.000000
13.030001,0.067024,-171.785431,-0.005506,-0.000869,-0.022063,0.298139,0.015188,-0.220629,-171.785431,-0.020865,0.000000
13.410001,0.026810,-171.918869,-0.005243,-0.000621,-0.015783,0.119255,0.006075,-0.157830,-171.918869,-0.014534,0.000000
13.790001,0.044312,-171.874390,-0.004988,-0.000369,-0.009384,0.197107,0.010041,-0.093835,-171.874390,-0.008204,0.000000
14.170001,0.046547,-171.918869,-0.004751,-0.000118,-0.002992,0.207051,0.010548,-0.029916,-171.918869,-0.001873,0.000000
14.550001,0.089371,-171.918869,-0.004579,-0.000000,-0.000009,0.397541,0.020252,-0.000091,-171.918869,0.000207,0.000000
14.930000,0.053993,-171.963364,-0.004587,-0.000000,-0.000009,0.240174,0.012235,-0.000091,-171.963364,0.000251,0.000000
15.310000,0.094955,-172.052322,-0.004583,0.000002,0.000051,0.422383,0.021517,0.000515,-172.052322,0.000884,0.000000
15.690001,0.124741,-172.096802,-0.004596,0.000017,0.000424,0.554874,0.028267,0.004239,-172.096802,0.001517,0.000000
16.070002,0.184326,-172.096802,-0.004570,0.000047,0.001187,0.819924,0.041769,0.011869,-172.096802,0.002150,0.000000
16.450001,0.228264,-172.096802,-0.004557,0.000070,0.001786,1.015368,0.051725,0.017865,-172.096802,0.002783,0.000000
16.830000,0.360451,-172.096802,-0.004518,0.000094,0.002384,1.603365,0.081679,0.023845,-172.096802,0.003415,0.000000
17.210001,0.541054,-172.230240,-0.004506,0.000118,0.003008,2.406727,0.122605,0.030082,-172.230240,0.004050,0.000000
17.590000,0.779747,-172.319199,-0.004488,0.000137,0.003485,3.468488,0.176693,0.034851,-172.319199,0.004683,0.000000
17.970001,1.317825,-172.319199,-0.004458,0.000178,0.004527,5.861980,0.298624,0.045267,-172.319199,0.005316,0.000000
18.350000,1.505875,-172.319199,-0.004449,0.000195,0.004960,6.698465,0.341236,0.049597,-172.319199,0.005948,0.000000
18.730001,1.860374,-172.363678,-0.004419,0.000219,0.005550,8.275359,0.421567,0.055502,-172.363678,0.006590,0.000000
19.110001,2.378716,-172.497131,-0.004385,0.000249,0.006321,10.581055,0.539025,0.063208,-172.497131,0.007223,0.000000
19.490002,2.593575,-172.452652,-0.004381,0.000265,0.006737,11.536796,0.587712,0.067371,-172.452652,0.007856,0.000000
19.870001,3.334221,-172.541611,-0.004372,0.000300,0.007614,14.831355,0.755545,0.076137,-172.541611,0.008489,0.000000
20.250002,3.599724,-172.497131,-0.004337,0.000322,0.008177,16.012371,0.815709,0.081769,-172.497131,0.009123,0.000000
20.630001,3.986992,-172.541611,-0.004290,0.000345,0.008767,17.735025,0.903465,0.087673,-172.541611,0.009756,0.000000
21.010000,4.303131,-172.675049,-0.004290,0.000367,0.009321,19.141283,0.975103,0.093214,-172.675049,0.010389,0.000000
21.390001,4.694496,-172.630569,-0.004264,0.000390,0.009894,20.882162,1.063788,0.098937,-172.630569,0.011022,0.000000
21.770000,5.006920,-172.675049,-0.004264,0.000413,0.010484,22.271893,1.134584,0.104842,-172.675049,0.011654,0.000000
22.150002,5.568459,-172.719528,-0.004225,0.000443,0.011264,24.769741,1.261831,0.112638,-172.719528,0.012287,0.000000
22.530001,5.967270,-172.764008,-0.004195,0.000469,0.011924,26.543743,1.352203,0.119239,-172.764008,0.012922,0.000000
22.910002,6.391769,-172.808502,-0.004174,0.000497,0.012635,28.432011,1.448396,0.126355,-172.808502,0.013554,0.000000
23.290001,6.481514,-172.897461,-0.004148,0.000515,0.013068,28.831215,1.468732,0.130685,-172.897461,0.014187,0.000000
23.670002,6.783134,-172.897461,-0.004135,0.000537,0.013632,30.172890,1.537080,0.136317,-172.897461,0.014820,0.000000
24.050001,7.150291,-172.852982,-0.004105,0.000564,0.014334,31.806086,1.620279,0.143342,-172.852982,0.015453,0.000000
24.430000,7.408722,-172.941940,-0.004070,0.000591,0.015002,32.955643,1.678840,0.150018,-172.941940,0.016086,0.000000
24.810001,7.651138,-173.030899,-0.004066,0.000615,0.015618,34.033962,1.733773,0.156180,-173.030899,0.016720,0.000000
25.190001,7.909935,-173.030899,-0.004040,0.000642,0.016304,35.185146,1.792417,0.163038,-173.030899,0.017353,0.000000
25.570002,7.939354,-173.075378,-0.004023,0.000659,0.016746,35.316010,1.799083,0.167459,-173.075378,0.017986,0.000000
25.950001,8.401840,-173.119858,-0.003988,0.000690,0.017535,37.373253,1.903884,0.175347,-173.119858,0.018619,0.000000
26.330002,8.546692,-173.164337,-0.003971,0.000718,0.018246,38.017586,1.936708,0.182462,-173.164337,0.019251,0.000000
26.710001,8.712395,-173.208817,-0.003949,0.000743,0.018870,38.754665,1.974257,0.188700,-173.208817,0.019884,0.000000
27.090002,8.917946,-173.253311,-0.003911,0.000766,0.019460,39.669003,2.020835,0.194604,-173.253311,0.020517,0.000000
27.470001,8.925766,-173.253311,-0.003898,0.000786,0.019954,39.703789,2.022608,0.199540,-173.253311,0.021152,0.000000
27.850000,9.517090,-173.297791,-0.003872,0.000820,0.020838,42.334129,2.156603,0.208381,-173.297791,0.021784,0.000000
28.230001,9.221428,-173.386749,-0.003842,0.000842,0.021385,41.018959,2.089606,0.213847,-173.386749,0.022417,0.000000
28.610001,9.425117,-173.431229,-0.003816,0.000863,0.021915,41.925018,2.135762,0.219145,-173.431229,0.023050,0.000000
28.990002,9.813873,-173.386749,-0.003798,0.000893,0.022678,43.654289,2.223855,0.226776,-173.386749,0.023683,0.000000
29.370001,9.798607,-173.475708,-0.003777,0.000914,0.023206,43.586380,2.220396,0.232059,-173.475708,0.024316,0.000000
29.750002,10.071930,-173.520187,-0.003738,0.000941,0.023908,44.802181,2.282332,0.239084,-173.520187,0.024958,0.000000
30.130001,10.109169,-173.609146,-0.003712,0.000968,0.024585,44.967831,2.290771,0.245852,-173.609146,0.025590,0.000000
30.510002,10.185501,-173.609146,-0.003699,0.000989,0.025123,45.307373,2.308068,0.251226,-173.609146,0.026225,0.000000
30.890001,10.348976,-173.653625,-0.003678,0.001014,0.025765,46.034546,2.345111,0.257645,-173.653625,0.026858,0.000000
31.270002,10.488983,-173.653625,-0.003665,0.001038,0.026372,46.657326,2.376838,0.263716,-173.653625,0.027490,0.000000
31.650002,10.864708,-173.742599,-0.003626,0.001070,0.027169,48.328636,2.461978,0.271695,-173.742599,0.028123,0.000000
32.030003,10.783531,-173.787079,-0.003604,0.001094,0.027777,47.967541,2.443583,0.277766,-173.787079,0.028756,0.000000
32.410000,10.840134,-173.787079,-0.003596,0.001116,0.028349,48.219322,2.456409,0.283489,-173.787079,0.029389,0.000000
32.790001,11.131325,-173.831558,-0.003553,0.001142,0.029017,49.514606,2.522394,0.290165,-173.831558,0.030023,0.000000
33.170002,11.307457,-173.876038,-0.003535,0.001167,0.029642,50.298080,2.562306,0.296418,-173.876038,0.030656,0.000000
33.550003,11.652649,-173.920517,-0.003514,0.001196,0.030378,51.833572,2.640528,0.303776,-173.920517,0.031289,0.000000
33.930000,11.584503,-173.964996,-0.003488,0.001220,0.030977,51.530445,2.625086,0.309771,-173.964996,0.031922,0.000000
34.310001,11.508545,-173.920517,-0.003471,0.001239,0.031471,51.192566,2.607874,0.314706,-173.920517,0.032555,0.000000
34.690002,12.013107,-174.009476,-0.003436,0.001269,0.032243,53.436970,2.722209,0.322428,-174.009476,0.033187,0.000000
35.070004,11.974007,-174.053955,-0.003432,0.001291,0.032798,53.263042,2.713349,0.327984,-174.053955,0.033822,0.000000
35.450001,12.543739,-174.142929,-0.003393,0.001325,0.033657,55.797340,2.842452,0.336568,-174.142929,0.034455,0.000000
35.830002,12.340424,-174.142929,-0.003363,0.001346,0.034176,54.892944,2.796380,0.341761,-174.142929,0.035087,0.000000
36.210003,12.366486,-174.187408,-0.003354,0.001365,0.034671,55.008877,2.802286,0.346712,-174.187408,0.035720,0.000000
36.590000,12.839027,-174.187408,-0.003320,0.001396,0.035469,57.110847,2.909365,0.354690,-174.187408,0.036353,0.000000
36.970001,12.770508,-174.142929,-0.003298,0.001415,0.035937,56.806057,2.893838,0.359368,-174.142929,0.036986,0.000000
37.350002,13.286621,-174.320847,-0.003277,0.001444,0.036665,59.101841,3.010791,0.366650,-174.320847,0.037620,0.000000
37.730003,13.186455,-174.409805,-0.003260,0.001468,0.037281,58.656281,2.988093,0.372812,-174.409805,0.038253,0.000000
38.110001,13.377480,-174.409805,-0.003234,0.001492,0.037897,59.506001,3.031380,0.378974,-174.409805,0.038886,0.000000
38.490002,13.559570,-174.409805,-0.003208,0.001514,0.038461,60.315983,3.072643,0.384606,-174.409805,0.039519,0.000000
38.870003,13.636276,-174.365326,-0.003186,0.001538,0.039077,60.657185,3.090024,0.390768,-174.365326,0.040152,0.000000
39.250000,14.510239,-174.454285,-0.003165,0.001574,0.039979,64.544762,3.288067,0.399791,-174.454285,0.040785,0.000000
39.630001,14.250694,-174.543259,-0.003139,0.001593,0.040464,63.390255,3.229254,0.404636,-174.543259,0.041417,0.000000
40.010002,14.297241,-174.543259,-0.003126,0.001616,0.041036,63.597305,3.239801,0.410358,-174.543259,0.042052,0.000000
40.390003,14.444695,-174.543259,-0.003100,0.001641,0.041678,64.253212,3.273214,0.416777,-174.543259,0.042692,0.000000
40.770000,14.634239,-174.632217,-0.003057,0.001662,0.042215,65.096344,3.316166,0.422152,-174.632217,0.043326,0.000000
41.150002,15.159653,-174.721176,-0.003040,0.001697,0.043092,67.433502,3.435226,0.430918,-174.721176,0.043959,0.000000
41.530003,15.113106,-174.765656,-0.003022,0.001717,0.043620,67.226456,3.424679,0.436202,-174.765656,0.044592,0.000000
41.910004,15.504845,-174.721176,-0.002984,0.001743,0.044280,68.968994,3.513448,0.442802,-174.721176,0.045225,0.000000
42.290001,15.651558,-174.810135,-0.002953,0.001765,0.044827,69.621605,3.546694,0.448268,-174.810135,0.045858,0.000000
42.670002,15.814659,-174.854614,-0.002949,0.001788,0.045407,70.347115,3.583653,0.454066,-174.854614,0.046491,0.000000
43.050003,15.799019,-174.854614,-0.002928,0.001808,0.045918,70.277542,3.580109,0.459183,-174.854614,0.047125,0.000000
43.430000,16.298744,-174.943573,-0.002915,0.001839,0.046709,72.500435,3.693348,0.467086,-174.943573,0.047758,0.000000
43.810001,16.731438,-174.943573,-0.002876,0.001868,0.047446,74.425156,3.791398,0.474459,-174.943573,0.048391,0.000000
44.190002,17.126152,-174.943573,-0.002863,0.001895,0.048130,76.180931,3.880842,0.481302,-174.943573,0.049023,0.000000
44.570004,16.987633,-175.077026,-0.002828,0.001913,0.048590,75.564766,3.849452,0.485905,-175.077026,0.049656,0.000000
44.950001,17.158173,-175.121506,-0.002798,0.001935,0.049145,76.323364,3.888097,0.491446,-175.121506,0.050289,0.000000
45.330002,17.766632,-175.121506,-0.002790,0.001966,0.049942,79.029930,4.025976,0.499424,-175.121506,0.050923,0.000000
45.710003,17.941277,-175.210464,-0.002772,0.001988,0.050507,79.806786,4.065551,0.505072,-175.210464,0.051556,0.000000
46.090004,18.257790,-175.121506,-0.002742,0.002013,0.051140,81.214706,4.137274,0.511400,-175.121506,0.052189,0.000000
46.470001,18.629791,-175.254944,-0.002708,0.002040,0.051817,82.869453,4.221571,0.518167,-175.254944,0.052822,0.000000
46.850002,18.549736,-175.299423,-0.002703,0.002058,0.052266,82.513344,4.203430,0.522664,-175.299423,0.053455,0.000000
47.230003,19.302666,-175.388397,-0.002690,0.002089,0.053057,85.862549,4.374046,0.530567,-175.388397,0.054088,0.000000
47.610001,19.579712,-175.388397,-0.002656,0.002115,0.053715,87.094910,4.436826,0.537152,-175.388397,0.054722,0.000000
47.990002,19.780792,-175.388397,-0.002634,0.002139,0.054331,87.989357,4.482392,0.543314,-175.388397,0.055355,0.000000
48.370003,20.204552,-175.521835,-0.002604,0.002164,0.054964,89.874336,4.578417,0.549642,-175.521835,0.055988,0.000000
48.750004,20.229874,-175.521835,-0.002583,0.002182,0.055432,89.986969,4.584155,0.554321,-175.521835,0.056621,0.000000
49.130001,20.303604,-175.521835,-0.002570,0.002202,0.055935,90.314941,4.600863,0.559347,-175.521835,0.057253,0.000000
49.510002,20.739655,-175.610794,-0.002531,0.002229,0.056621,92.254593,4.699673,0.566205,-175.610794,0.057886,0.000000
49.890003,21.460937,-175.566315,-0.002514,0.002262,0.057462,95.463020,4.863118,0.574623,-175.566315,0.058519,0.000000
50.270004,22.106262,-175.655273,-0.002488,0.002291,0.058190,98.333565,5.009350,0.581905,-175.655273,0.059153,0.000000
50.650002,22.229141,-175.699753,-0.002475,0.002311,0.058702,98.880157,5.037195,0.587022,-175.699753,0.059786,0.000000
51.030003,22.965324,-175.744232,-0.002453,0.002340,0.059440,102.154861,5.204017,0.594395,-175.744232,0.060419,0.000000
51.410004,22.962715,-175.788712,-0.002423,0.002364,0.060038,102.143257,5.203426,0.600375,-175.788712,0.061061,0.000000
51.790001,23.349617,-175.788712,-0.002402,0.002387,0.060626,103.864281,5.291099,0.606264,-175.788712,0.061694,0.000000
52.170002,23.854919,-175.877686,-0.002380,0.002412,0.061277,106.111984,5.405602,0.612774,-175.877686,0.062327,0.000000
52.550003,24.020256,-175.877686,-0.002363,0.002433,0.061806,106.847435,5.443068,0.618058,-175.877686,0.062959,0.000000
52.930004,25.151894,-176.011124,-0.002358,0.002467,0.062673,111.881210,5.699501,0.626733,-176.011124,0.063592,0.000000
53.310001,25.293396,-175.966644,-0.002333,0.002489,0.063229,112.510643,5.731565,0.632289,-175.966644,0.064227,0.000000
53.690002,25.593155,-176.011124,-0.002289,0.002513,0.063818,113.844040,5.799492,0.638179,-176.011124,0.064859,0.000000
54.070004,26.220230,-176.100082,-0.002268,0.002539,0.064495,116.633408,5.941589,0.644946,-176.100082,0.065492,0.000000
54.450001,26.579201,-176.100082,-0.002264,0.002561,0.065050,118.230186,6.022933,0.650502,-176.100082,0.066125,0.000000
54.830002,27.731689,-176.144562,-0.002238,0.002592,0.065830,123.356712,6.284091,0.658299,-176.144562,0.066758,0.000000
55.210003,27.712326,-176.144562,-0.002207,0.002613,0.066367,123.270584,6.279703,0.663674,-176.144562,0.067391,0.000000
55.590004,28.156570,-176.233521,-0.002190,0.002636,0.066967,125.246681,6.380370,0.669669,-176.233521,0.068025,0.000000
55.970001,28.469734,-176.233521,-0.002173,0.002660,0.067556,126.639702,6.451334,0.675558,-176.233521,0.068658,0.000000
56.350002,29.252464,-176.278015,-0.002160,0.002685,0.068207,130.121460,6.628703,0.682068,-176.278015,0.069291,0.000000
56.730003,30.836159,-176.322495,-0.002147,0.002720,0.069091,137.166092,6.987573,0.690910,-176.322495,0.069924,0.000000
57.110004,30.951225,-176.366974,-0.002117,0.002740,0.069603,137.677933,7.013648,0.696027,-176.366974,0.070556,0.000000
57.490002,31.041710,-176.366974,-0.002100,0.002763,0.070184,138.080429,7.034152,0.701841,-176.366974,0.071189,0.000000
57.870003,32.454117,-176.455933,-0.002070,0.002793,0.070930,144.363129,7.354208,0.709304,-176.455933,0.071824,0.000000
58.250004,32.235168,-176.500412,-0.002057,0.002806,0.071277,143.389191,7.304594,0.712771,-176.500412,0.072457,0.000000
58.630001,33.237221,-176.544891,-0.002022,0.002841,0.072152,147.846542,7.531662,0.721522,-176.544891,0.073089,0.000000
59.010002,34.005798,-176.500412,-0.002009,0.002859,0.072612,151.265350,7.705824,0.726125,-176.500412,0.073722,0.000000
59.390003,34.951248,-176.589371,-0.001992,0.002887,0.073324,155.470917,7.920066,0.733240,-176.589371,0.074355,0.000000
59.770004,35.832283,-176.678345,-0.001979,0.002912,0.073973,159.389954,8.119712,0.739735,-176.678345,0.074988,0.000000
60.150002,36.138000,-176.722824,-0.001953,0.002934,0.074520,160.749847,8.188988,0.745200,-176.722824,0.075621,0.000000
60.530003,36.603470,-176.767303,-0.001940,0.002960,0.075188,162.820358,8.294465,0.751877,-176.767303,0.076255,0.000000
60.910004,38.212860,-176.722824,-0.001932,0.002990,0.075934,169.979294,8.659158,0.759341,-176.722824,0.076888,0.000000
61.290005,38.758759,-176.767303,-0.001901,0.003011,0.076488,172.407562,8.782860,0.764882,-176.767303,0.077521,0.000000
61.670002,39.811455,-176.900742,-0.001871,0.003038,0.077156,177.090195,9.021404,0.771558,-176.900742,0.078154,0.000000
62.050003,40.319000,-176.945221,-0.001871,0.003058,0.077668,179.347870,9.136416,0.776676,-176.945221,0.078786,0.000000
62.430004,40.635513,-176.945221,-0.001850,0.003078,0.078172,180.755798,9.208138,0.781717,-176.945221,0.079428,0.000000
62.810001,42.375610,-176.945221,-0.001819,0.003109,0.078970,188.496124,9.602450,0.789696,-176.945221,0.080061,0.000000
63.190002,43.512840,-176.945221,-0.001807,0.003140,0.079749,193.554779,9.860151,0.797493,-176.945221,0.080694,0.000000
63.570004,44.432228,-177.034180,-0.001781,0.003163,0.080347,197.644424,10.068487,0.803473,-177.034180,0.081328,0.000000
63.950005,45.220909,-177.078659,-0.001772,0.003185,0.080894,201.152649,10.247205,0.808938,-177.078659,0.081961,0.000000
64.330002,45.723244,-177.078659,-0.001768,0.003203,0.081345,203.387146,10.361035,0.813450,-177.078659,0.082594,0.000000
64.710007,47.586594,-177.123154,-0.001742,0.003236,0.082187,211.675735,10.783277,0.821867,-177.123154,0.083227,0.000000
65.090004,48.562584,-177.212112,-0.001703,0.003261,0.082820,216.017166,11.004438,0.828196,-177.212112,0.083860,0.000000
65.470001,49.818962,-177.212112,-0.001703,0.003290,0.083557,221.605804,11.289139,0.835569,-177.212112,0.084492,0.000000
65.850006,50.870171,-177.345551,-0.001686,0.003311,0.084111,226.281815,11.527345,0.841110,-177.345551,0.085127,0.000000
66.230003,51.366920,-177.301071,-0.001673,0.003332,0.084623,228.491470,11.639910,0.846227,-177.301071,0.085760,0.000000
66.610001,53.142761,-177.301071,-0.001647,0.003361,0.085360,236.390808,12.042322,0.853600,-177.301071,0.086392,0.000000
66.990005,54.056564,-177.390030,-0.001638,0.003384,0.085958,240.455612,12.249393,0.859580,-177.390030,0.087025,0.000000
67.370003,55.559830,-177.478989,-0.001634,0.003411,0.086644,247.142471,12.590038,0.866438,-177.478989,0.087658,0.000000
67.750000,56.918617,-177.478989,-0.001621,0.003437,0.087302,253.186661,12.897943,0.873024,-177.478989,0.088291,0.000000
68.130005,57.481270,-177.523483,-0.001595,0.003455,0.087746,255.689453,13.025442,0.877460,-177.523483,0.088925,0.000000
68.510002,59.326752,-177.523483,-0.001574,0.003486,0.088535,263.898560,13.443634,0.885347,-177.523483,0.089558,0.000000
68.890007,60.584999,-177.567963,-0.001578,0.003510,0.089158,269.495544,13.728757,0.891585,-177.567963,0.090191,0.000000
69.270004,61.342400,-177.656921,-0.001556,0.003530,0.089661,272.864624,13.900387,0.896611,-177.656921,0.090824,0.000000
69.650002,62.474419,-177.745880,-0.001548,0.003549,0.090138,277.900085,14.156905,0.901380,-177.745880,0.091457,0.000000
70.030006,64.518745,-177.745880,-0.001531,0.003581,0.090945,286.993713,14.620157,0.909450,-177.745880,0.092090,0.000000
70.410004,65.900993,-177.701401,-0.001509,0.003610,0.091682,293.142273,14.933378,0.916823,-177.701401,0.092722,0.000000
70.790001,65.378548,-177.790359,-0.001492,0.003605,0.091561,290.818298,14.814991,0.915612,-177.790359,291.061768,0.000000
71.170006,65.568092,-177.879318,-0.001487,0.003620,0.091943,291.661438,14.857943,0.919427,-177.879318,294.500488,0.000000
71.550003,64.713860,-177.923798,-0.001470,0.003620,0.091943,287.861633,14.664370,0.919427,-177.923798,294.500488,0.000000
71.930000,66.353050,-177.834839,-0.001453,0.003563,0.090503,295.153107,15.035816,0.905029,-177.834839,294.500488,0.000000
72.310005,65.496956,-177.968292,-0.001440,0.003569,0.090642,291.345001,14.841822,0.906422,-177.968292,294.500488,0.000000
72.690002,65.122353,-178.012772,-0.001440,0.003640,0.092445,289.678680,14.756936,0.924453,-178.012772,294.500488,0.000000
73.070000,65.007286,-178.012772,-0.001449,0.003644,0.092550,289.166840,14.730862,0.925498,-178.012772,294.500488,0.000000
73.450005,65.004311,-178.057251,-0.001436,0.003650,0.092722,289.153625,14.730187,0.927224,-178.057251,294.500488,0.000000
73.830002,64.962242,-178.101730,-0.001449,0.003655,0.092836,288.966492,14.720654,0.928359,-178.101730,294.500488,0.000000
74.210007,65.077293,-178.190689,-0.001431,0.003661,0.092992,289.478271,14.746725,0.929918,-178.190689,294.500488,0.000000
74.590004,64.999107,-178.279648,-0.001436,0.003666,0.093105,289.130463,14.729008,0.931054,-178.279648,294.500488,0.000000
74.970001,65.488396,-178.235168,-0.001440,0.003674,0.093322,291.306946,14.839883,0.933219,-178.235168,294.500488,0.000000
75.350006,65.189018,-178.190689,-0.001436,0.003675,0.093339,289.975250,14.772042,0.933385,-178.190689,294.500488,0.000000
75.730003,65.301460,-178.235168,-0.001418,0.003680,0.093469,290.475403,14.797522,0.934687,-178.235168,294.500488,0.000000
76.110001,65.213219,-178.279648,-0.001423,0.003683,0.093555,290.082886,14.777527,0.935550,-178.279648,294.500488,0.000000
76.490005,65.358070,-178.368607,-0.001406,0.003688,0.093678,290.727203,14.810350,0.936777,-178.368607,294.500488,0.000000
76.870003,65.210976,-178.413101,-0.001414,0.003689,0.093703,290.072906,14.777019,0.937034,-178.413101,294.500488,0.000000
77.250000,65.143211,-178.413101,-0.001410,0.003692,0.093781,289.771484,14.761663,0.937806,-178.413101,294.500488,0.000000
77.630005,65.029259,-178.457581,-0.001406,0.003693,0.093808,289.264587,14.735841,0.938079,-178.457581,294.500488,0.000000
78.010002,65.577400,-178.502060,-0.001410,0.003701,0.094015,291.702850,14.860051,0.940153,-178.502060,294.500488,0.000000
78.390007,65.393440,-178.502060,-0.001401,0.003701,0.094015,290.884552,14.818365,0.940153,-178.502060,294.500488,0.000000
78.770004,65.180824,-178.635498,-0.001393,0.003701,0.094015,289.938782,14.770185,0.940153,-178.635498,294.500488,0.000000
79.150002,64.974892,-178.591019,-0.001388,0.003701,0.094015,289.022766,14.723521,0.940153,-178.591019,294.500488,0.000000
79.530006,65.517067,-178.679977,-0.001388,0.003710,0.094232,291.434479,14.846379,0.942318,-178.679977,294.500488,0.000000
79.910004,65.337212,-178.724457,-0.001397,0.003710,0.094232,290.634430,14.805623,0.942318,-178.724457,294.500488,0.000000
80.290001,65.176353,-178.768936,-0.001397,0.003710,0.094241,289.918915,14.769173,0.942409,-178.768936,294.500488,0.000000
80.670006,65.008781,-178.813431,-0.001384,0.003710,0.094241,289.173492,14.731200,0.942409,-178.813431,294.500488,0.000000
81.050003,64.821480,-178.813431,-0.001393,0.003710,0.094241,288.340332,14.688757,0.942409,-178.813431,294.500488,0.000000
81.430000,64.655403,-178.813431,-0.001375,0.003710,0.094241,287.601593,14.651123,0.942409,-178.813431,294.500488,0.000000
81.810005,64.480385,-178.902390,-0.001397,0.003710,0.094241,286.823090,14.611465,0.942409,-178.902390,294.500488,0.000000
82.190002,66.747765,-178.946869,-0.001393,0.003682,0.093520,296.908875,15.125259,0.935202,-178.946869,294.500488,0.000000
82.570007,66.414482,-179.035828,-0.001362,0.003674,0.093313,295.426361,15.049737,0.933128,-179.035828,294.500488,0.000000
82.950005,66.205208,-179.035828,-0.001358,0.003674,0.093313,294.495483,15.002315,0.933128,-179.035828,294.500488,0.000000
83.330002,66.019768,-179.035828,-0.001362,0.003674,0.093313,293.670593,14.960294,0.933128,-179.035828,294.500488,0.000000
83.710007,65.862267,-179.035828,-0.001345,0.003675,0.093339,292.970001,14.924603,0.933385,-179.035828,294.500488,0.000000
84.090004,65.651497,-179.169266,-0.001345,0.003675,0.093339,292.032440,14.876842,0.933385,-179.169266,294.500488,0.000000
84.470001,65.529366,-179.169266,-0.001354,0.003675,0.093348,291.489166,14.849166,0.933476,-179.169266,294.500488,0.000000
84.850006,65.375191,-179.169266,-0.001341,0.003693,0.093808,290.803375,14.814230,0.938079,-179.169266,294.500488,0.000000
85.230003,65.277260,-179.213745,-0.001337,0.003708,0.094180,290.367767,14.792039,0.941803,-179.213745,294.500488,0.000000
85.610001,65.133522,-179.302719,-0.001350,0.003709,0.094206,289.728363,14.759467,0.942060,-179.302719,294.500488,0.000000
85.990005,65.021812,-179.347198,-0.001345,0.003718,0.094448,289.231476,14.734154,0.944483,-179.347198,294.500488,0.000000
86.370003,64.909355,-179.391678,-0.001354,0.003718,0.094448,288.731232,14.708670,0.944483,-179.391678,294.500488,0.000000
86.750008,65.838432,-179.391678,-0.001337,0.003739,0.094969,292.863983,14.919202,0.949691,-179.391678,294.500488,0.000000
87.130005,65.765450,-179.391678,-0.001354,0.003739,0.094969,292.539337,14.902664,0.949691,-179.391678,294.500488,0.000000
87.510002,65.657082,-179.436157,-0.001354,0.003739,0.094969,292.057281,14.878107,0.949691,-179.436157,294.500488,0.000000
87.890007,65.571434,-179.569595,-0.001358,0.003739,0.094969,291.676300,14.858700,0.949691,-179.569595,294.500488,0.000000
88.270004,65.471642,-179.614075,-0.001354,0.003739,0.094969,291.232422,14.836086,0.949691,-179.614075,294.500488,0.000000
88.650002,65.369606,-179.569595,-0.001350,0.003739,0.094969,290.778534,14.812964,0.949691,-179.569595,294.500488,0.000000
89.030006,65.272423,-179.614075,-0.001350,0.003739,0.094969,290.346252,14.790943,0.949691,-179.614075,294.500488,0.000000
89.410004,65.177101,-179.658554,-0.001354,0.003739,0.094969,289.922211,14.769342,0.949691,-179.658554,294.500488,0.000000
89.790001,65.076927,-179.747528,-0.001358,0.003739,0.094969,289.476624,14.746643,0.949691,-179.747528,294.500488,0.000000
90.170006,64.984581,-179.792007,-0.001354,0.003739,0.094969,289.065857,14.725716,0.949691,-179.792007,294.500488,0.000000
90.550003,65.293648,-179.792007,-0.001358,0.003746,0.095160,290.440643,14.795753,0.951598,-179.792007,294.500488,0.000000
90.930008,65.308174,-179.792007,-0.001350,0.003746,0.095160,290.505280,14.799045,0.951598,-179.792007,294.500488,0.000000
91.310005,65.272057,-179.880966,-0.001350,0.003746,0.095160,290.344604,14.790859,0.951598,-179.880966,294.500488,0.000000
91.690002,65.208382,-179.925446,-0.001350,0.003746,0.095160,290.061371,14.776431,0.951598,-179.925446,294.500488,0.000000
92.070007,65.113426,-179.969925,-0.001350,0.003746,0.095160,289.638977,14.754913,0.951598,-179.969925,294.500488,0.000000
92.450005,65.041176,-180.014404,-0.001345,0.003746,0.095160,289.317596,14.738542,0.951598,-180.014404,294.500488,0.000000
92.830002,65.544624,-179.969925,-0.001354,0.003754,0.095360,291.557037,14.852624,0.953597,-179.969925,294.500488,0.000000
93.210007,65.530098,-180.058884,-0.001337,0.003754,0.095351,291.492432,14.849333,0.953506,-180.058884,294.500488,0.000000
93.590004,65.478722,-180.058884,-0.001345,0.003753,0.095334,291.263885,14.837690,0.953339,-180.058884,294.500488,0.000000
93.970001,65.394188,-180.147858,-0.001350,0.003753,0.095334,290.887878,14.818535,0.953339,-180.147858,294.500488,0.000000
94.350006,65.322685,-180.103378,-0.001358,0.003753,0.095334,290.569824,14.802332,0.953339,-180.103378,294.500488,0.000000
94.730003,65.281364,-180.192337,-0.001354,0.003753,0.095334,290.386017,14.792969,0.953339,-180.192337,294.500488,0.000000
95.110008,65.193474,-180.236816,-0.001350,0.003753,0.095334,289.995056,14.773052,0.953339,-180.236816,294.500488,0.000000
95.490005,65.113426,-180.325775,-0.001341,0.003753,0.095334,289.638977,14.754913,0.953339,-180.325775,294.500488,0.000000
95.870003,65.047874,-180.414734,-0.001341,0.003753,0.095334,289.347382,14.740059,0.953339,-180.414734,294.500488,0.000000
96.250008,64.989418,-180.414734,-0.001337,0.003753,0.095334,289.087372,14.726813,0.953339,-180.414734,294.500488,0.000000
96.630005,64.926857,-180.414734,-0.001337,0.003754,0.095342,288.809082,14.712636,0.953415,-180.414734,294.500488,0.000000
97.010002,65.270195,-180.459213,-0.001341,0.003761,0.095532,290.336334,14.790438,0.955323,-180.459213,294.500488,0.000000
97.390007,65.316734,-180.503693,-0.001354,0.003761,0.095532,290.543335,14.800983,0.955323,-180.503693,294.500488,0.000000
97.770004,65.304817,-180.503693,-0.001337,0.003761,0.095532,290.490326,14.798283,0.955323,-180.503693,294.500488,0.000000
98.150002,65.262733,-180.548187,-0.001350,0.003761,0.095532,290.303131,14.788747,0.955323,-180.548187,294.500488,0.000000
98.530006,65.238533,-180.592667,-0.001345,0.003761,0.095532,290.195496,14.783262,0.955323,-180.592667,294.500488,0.000000
98.910004,65.172630,-180.681625,-0.001341,0.003761,0.095532,289.902344,14.768330,0.955323,-180.681625,294.500488,0.000000
99.290001,65.120872,-180.726105,-0.001350,0.003761,0.095541,289.672119,14.756600,0.955413,-180.726105,294.500488,0.000000
99.670006,65.089211,-180.726105,-0.001345,0.003762,0.095560,289.531281,14.749426,0.955595,-180.726105,294.500488,0.000000
100.050003,65.267952,-180.681625,-0.001345,0.003765,0.095628,290.326355,14.789929,0.956276,-180.681625,294.500488,0.000000
100.430008,65.244118,-180.770584,-0.001332,0.003765,0.095628,290.220337,14.784528,0.956276,-180.770584,294.500488,0.000000
100.810005,65.215080,-180.815063,-0.001354,0.003765,0.095628,290.091156,14.777948,0.956276,-180.815063,294.500488,0.000000
101.190002,65.178581,-180.859543,-0.001341,0.003765,0.095637,289.928802,14.769677,0.956367,-180.859543,294.500488,0.000000
101.570007,65.139854,-180.904022,-0.001350,0.003766,0.095646,289.756531,14.760902,0.956458,-180.904022,294.500488,0.000000
101.950005,65.124596,-180.948502,-0.001337,0.003766,0.095662,289.688660,14.757444,0.956625,-180.948502,294.500488,0.000000
102.330002,65.103737,-181.037476,-0.001337,0.003767,0.095681,289.595886,14.752718,0.956806,-181.037476,294.500488,0.000000
102.710007,65.219170,-180.992996,-0.001328,0.003769,0.095723,290.109344,14.778874,0.957230,-180.992996,294.500488,0.000000
103.090004,65.204277,-181.126434,-0.001341,0.003769,0.095723,290.043121,14.775500,0.957230,-181.126434,294.500488,0.000000
103.470001,65.166664,-181.037476,-0.001337,0.003769,0.095723,289.875793,14.766976,0.957230,-181.037476,294.500488,0.000000
103.850006,65.128685,-181.037476,-0.001345,0.003769,0.095732,289.706848,14.758371,0.957321,-181.037476,294.500488,0.000000
104.230003,65.116402,-181.170914,-0.001337,0.003770,0.095750,289.652222,14.755588,0.957503,-181.170914,294.500488,0.000000
104.610008,65.122353,-181.215393,-0.001341,0.003770,0.095767,289.678680,14.756936,0.957669,-181.215393,294.500488,0.000000
104.990005,65.099266,-181.215393,-0.001337,0.003771,0.095776,289.575989,14.751705,0.957760,-181.215393,294.500488,0.000000
105.370003,65.104103,-181.259872,-0.001345,0.003771,0.095793,289.597504,14.752801,0.957927,-181.259872,294.500488,0.000000
105.750008,65.091072,-181.304352,-0.001332,0.003771,0.095793,289.539551,14.749847,0.957927,-181.304352,294.500488,0.000000
106.130005,65.075813,-181.304352,-0.001337,0.003772,0.095802,289.471680,14.746390,0.958017,-181.304352,294.500488,0.000000
106.510002,65.062401,-181.437805,-0.001337,0.003772,0.095818,289.412018,14.743351,0.958184,-181.437805,294.500488,0.000000
106.890007,65.080650,-181.482285,-0.001350,0.003773,0.095837,289.493195,14.747486,0.958366,-181.482285,294.500488,0.000000
107.270004,65.093315,-181.437805,-0.001328,0.003774,0.095853,289.549530,14.750356,0.958532,-181.437805,294.500488,0.000000
107.650002,65.082512,-181.393326,-0.001324,0.003774,0.095853,289.501465,14.747909,0.958532,-181.393326,294.500488,0.000000
108.030006,65.050117,-181.526764,-0.001319,0.003774,0.095853,289.357361,14.740567,0.958532,-181.526764,294.500488,0.000000
108.410004,65.105965,-181.615723,-0.001324,0.003776,0.095914,289.605804,14.753222,0.959138,-181.615723,294.500488,0.000000
108.790009,65.165184,-181.660202,-0.001332,0.003776,0.095914,289.869202,14.766642,0.959138,-181.660202,294.500488,0.000000
109.170006,65.153633,-181.615723,-0.001345,0.003776,0.095914,289.817841,14.764025,0.959138,-181.615723,294.500488,0.000000
109.550003,65.133522,-181.704681,-0.001332,0.003776,0.095914,289.728363,14.759467,0.959138,-181.704681,294.500488,0.000000
109.930008,65.098900,-181.749161,-0.001337,0.003776,0.095914,289.574371,14.751621,0.959138,-181.749161,294.500488,0.000000
110.310005,65.090706,-181.793640,-0.001328,0.003776,0.095923,289.537933,14.749764,0.959229,-181.793640,294.500488,0.000000
110.690002,65.110817,-181.838135,-0.001341,0.003779,0.095983,289.627380,14.754322,0.959834,-181.838135,294.500488,0.000000
111.070007,65.171135,-181.793640,-0.001332,0.003779,0.095983,289.895691,14.767991,0.959834,-181.793640,294.500488,0.000000
111.450005,65.172997,-181.882614,-0.001328,0.003779,0.095983,289.903961,14.768412,0.959834,-181.882614,294.500488,0.000000
111.830002,65.161461,-181.927094,-0.001324,0.003779,0.095993,289.852661,14.765799,0.959925,-181.927094,294.500488,0.000000
112.210007,65.135765,-181.971573,-0.001319,0.003780,0.096002,289.738342,14.759975,0.960016,-181.971573,294.500488,0.000000
112.590004,65.134651,-182.016052,-0.001324,0.003780,0.096009,289.733398,14.759723,0.960092,-182.016052,294.500488,0.000000
112.970009,65.184914,-181.971573,-0.001341,0.003783,0.096079,289.956970,14.771112,0.960788,-181.971573,294.500488,0.000000
113.350006,65.298119,-182.060532,-0.001319,0.003783,0.096079,290.460541,14.796765,0.960788,-182.060532,294.500488,0.000000
113.730003,65.285088,-182.105011,-0.001341,0.003783,0.096079,290.402588,14.793813,0.960788,-182.105011,294.500488,0.000000
114.110008,65.278374,-182.193970,-0.001332,0.003783,0.096079,290.372711,14.792291,0.960788,-182.193970,294.500488,0.000000
114.490005,65.270927,-182.238449,-0.001332,0.003783,0.096079,290.339600,14.790604,0.960788,-182.238449,294.500488,0.000000
114.870003,65.243370,-182.238449,-0.001332,0.003783,0.096079,290.217010,14.784359,0.960788,-182.238449,294.500488,0.000000
115.250008,65.212105,-182.238449,-0.001319,0.003783,0.096079,290.077942,14.777274,0.960788,-182.238449,294.500488,0.000000
115.630005,65.187141,-182.282944,-0.001324,0.003783,0.096079,289.966888,14.771618,0.960788,-182.282944,294.500488,0.000000
116.010002,65.158852,-182.416382,-0.001328,0.003783,0.096079,289.841034,14.765207,0.960788,-182.416382,294.500488,0.000000
116.390007,65.127190,-182.416382,-0.001341,0.003783,0.096079,289.700195,14.758032,0.960788,-182.416382,294.500488,0.000000
116.770004,65.167778,-182.371902,-0.001332,0.003785,0.096139,289.880768,14.767229,0.961394,-182.371902,294.500488,0.000000
117.150009,65.205772,-182.416382,-0.001332,0.003785,0.096139,290.049774,14.775839,0.961394,-182.416382,294.500488,0.000000
117.530006,65.206139,-182.549820,-0.001324,0.003785,0.096139,290.051392,14.775923,0.961394,-182.549820,294.500488,0.000000
117.910004,65.178963,-182.549820,-0.001324,0.003785,0.096139,289.930511,14.769765,0.961394,-182.549820,294.500488,0.000000
118.290009,65.162193,-182.549820,-0.001332,0.003785,0.096139,289.855927,14.765965,0.961394,-182.549820,294.500488,0.000000
118.670006,65.133156,-182.594299,-0.001324,0.003785,0.096139,289.726746,14.759384,0.961394,-182.594299,294.500488,0.000000
119.050003,65.098900,-182.594299,-0.001315,0.003785,0.096148,289.574371,14.751621,0.961484,-182.594299,294.500488,0.000000
119.430008,65.080650,-182.727753,-0.001328,0.003785,0.096148,289.493195,14.747486,0.961484,-182.727753,294.500488,0.000000
119.810005,65.383385,-182.727753,-0.001319,0.003791,0.096288,290.839813,14.816087,0.962877,-182.727753,294.500488,0.000000
120.190002,65.467552,-182.816711,-0.001328,0.003791,0.096288,291.214203,14.835159,0.962877,-182.816711,294.500488,0.000000
120.570007,65.472008,-182.816711,-0.001324,0.003791,0.096288,291.234039,14.836168,0.962877,-182.816711,294.500488,0.000000
120.950005,65.475731,-182.816711,-0.001311,0.003791,0.096288,291.250610,14.837013,0.962877,-182.816711,294.500488,0.000000
121.330009,65.451164,-182.905670,-0.001337,0.003791,0.096288,291.141327,14.831446,0.962877,-182.905670,294.500488,0.000000
121.710007,65.434029,-182.905670,-0.001328,0.003791,0.096288,291.065094,14.827562,0.962877,-182.905670,294.500488,0.000000
122.090004,65.407219,-182.905670,-0.001332,0.003791,0.096288,290.945831,14.821488,0.962877,-182.905670,294.500488,0.000000
122.470009,65.381523,-182.905670,-0.001337,0.003791,0.096288,290.831543,14.815665,0.962877,-182.905670,294.500488,0.000000
122.850006,65.344658,-182.994629,-0.001324,0.003791,0.096288,290.667542,14.807311,0.962877,-182.994629,294.500488,0.000000
123.230003,65.337212,-183.083588,-0.001315,0.003791,0.096288,290.634430,14.805623,0.962877,-183.083588,294.500488,0.000000
123.610008,65.314873,-183.083588,-0.001324,0.003791,0.096288,290.535065,14.800561,0.962877,-183.083588,294.500488,0.000000
123.990005,65.314507,-183.128082,-0.001324,0.003791,0.096288,290.533447,14.800479,0.962877,-183.128082,294.500488,0.000000
124.370003,65.269814,-183.083588,-0.001324,0.003791,0.096288,290.334625,14.790351,0.962877,-183.083588,294.500488,0.000000
124.750008,65.265724,-183.172562,-0.001319,0.003791,0.096288,290.316437,14.789425,0.962877,-183.172562,294.500488,0.000000
125.130005,65.235924,-183.217041,-0.001319,0.003791,0.096297,290.183868,14.782672,0.962968,-183.217041,294.500488,0.000000
125.510010,65.213966,-183.306000,-0.001315,0.003791,0.096297,290.086212,14.777697,0.962968,-183.306000,294.500488,0.000000
125.890007,65.195717,-183.261520,-0.001328,0.003791,0.096297,290.005035,14.773561,0.962968,-183.261520,294.500488,0.000000
126.270004,65.165916,-183.306000,-0.001319,0.003791,0.096297,289.872467,14.766808,0.962968,-183.306000,294.500488,0.000000
126.650009,65.206139,-183.350479,-0.001315,0.003793,0.096348,290.051392,14.775923,0.963483,-183.350479,294.500488,0.000000
127.030006,65.208748,-183.483917,-0.001315,0.003793,0.096348,290.062988,14.776513,0.963483,-183.483917,294.500488,0.000000
127.410004,65.225502,-183.483917,-0.001319,0.003793,0.096348,290.137512,14.780310,0.963483,-183.483917,294.500488,0.000000
127.790009,65.199440,-183.528397,-0.001319,0.003793,0.096348,290.021606,14.774405,0.963483,-183.528397,294.500488,0.000000
128.170013,65.170769,-183.483917,-0.001328,0.003793,0.096348,289.894043,14.767907,0.963483,-183.483917,294.500488,0.000000
128.550003,65.166298,-183.528397,-0.001324,0.003794,0.096365,289.874176,14.766894,0.963649,-183.528397,294.500488,0.000000
128.930008,65.175240,-183.661850,-0.001324,0.003794,0.096374,289.913940,14.768920,0.963740,-183.661850,294.500488,0.000000
129.310013,65.183418,-183.661850,-0.001328,0.003794,0.096374,289.950317,14.770773,0.963740,-183.661850,294.500488,0.000000
129.690002,65.163689,-183.750809,-0.001311,0.003794,0.096374,289.862549,14.766303,0.963740,-183.750809,294.500488,0.000000
130.070007,65.142830,-183.706329,-0.001315,0.003795,0.096383,289.769775,14.761576,0.963831,-183.706329,294.500488,0.000000
130.450012,65.121986,-183.750809,-0.001311,0.003795,0.096383,289.677063,14.756853,0.963831,-183.750809,294.500488,0.000000
130.830002,65.113426,-183.795288,-0.001328,0.003795,0.096400,289.638977,14.754913,0.963998,-183.795288,294.500488,0.000000
131.210007,65.158852,-183.795288,-0.001324,0.003787,0.096201,289.841034,14.765207,0.962014,-183.795288,0.096400,0.000000
131.590012,65.057564,-183.884247,-0.001319,0.003780,0.096002,289.390503,14.742254,0.960016,-183.884247,0.095802,0.000000
131.970001,65.060539,-183.973221,-0.001315,0.003761,0.095532,289.403748,14.742929,0.955323,-183.973221,0.095169,0.000000
132.350006,65.057930,-183.928726,-0.001319,0.003738,0.094934,289.392120,14.742338,0.949342,-183.928726,0.094536,0.000000
132.730011,64.947716,-184.017700,-0.001289,0.003715,0.094353,288.901855,14.717363,0.943529,-184.017700,0.093903,0.000000
133.110001,64.891853,-184.106659,-0.001306,0.003690,0.093729,288.653381,14.704704,0.937291,-184.106659,0.093269,0.000000
133.490005,64.880318,-184.062180,-0.001285,0.003673,0.093296,288.602081,14.702090,0.932961,-184.062180,0.092636,0.000000
133.870010,64.833763,-184.062180,-0.001285,0.003643,0.092541,288.394989,14.691541,0.925407,-184.062180,0.092003,0.000000
134.250000,64.804344,-184.195618,-0.001293,0.003616,0.091847,288.264130,14.684875,0.918473,-184.195618,0.091370,0.000000
134.630005,64.744392,-184.240097,-0.001285,0.003591,0.091214,287.997437,14.671289,0.912145,-184.240097,0.090738,0.000000
135.010010,64.731361,-184.195618,-0.001298,0.003570,0.090668,287.939484,14.668336,0.906679,-184.195618,0.090105,0.000000
135.389999,64.669930,-184.195618,-0.001293,0.003547,0.090105,287.666199,14.654415,0.901047,-184.195618,0.089470,0.000000
135.770004,64.401436,-184.240097,-0.001293,0.003522,0.089454,286.471893,14.593574,0.894537,-184.240097,0.088838,0.000000
136.150009,63.859276,-184.373535,-0.001293,0.003505,0.089037,284.060242,14.470719,0.890374,-184.373535,0.088205,0.000000
136.530014,62.528412,-184.373535,-0.001272,0.003478,0.088344,278.140259,14.169141,0.883440,-184.373535,0.087572,0.000000
136.910004,61.361763,-184.418030,-0.001263,0.003458,0.087841,272.950745,13.904775,0.878414,-184.418030,0.086939,0.000000
137.290009,59.940422,-184.462509,-0.001255,0.003439,0.087355,266.628326,13.582694,0.873554,-184.462509,0.086306,0.000000
137.670013,58.143723,-184.462509,-0.001255,0.003408,0.086574,258.636200,13.175555,0.865742,-184.462509,0.085672,0.000000
138.050003,55.425774,-184.551468,-0.001242,0.003385,0.085985,246.546158,12.559660,0.859852,-184.551468,0.085039,0.000000
138.430008,52.977798,-184.595947,-0.001250,0.003358,0.085299,235.657013,12.004940,0.852994,-184.595947,0.084406,0.000000
138.810013,50.328369,-184.640427,-0.001250,0.003335,0.084718,223.871765,11.404572,0.847181,-184.640427,0.083773,0.000000
139.190002,47.365776,-184.595947,-0.001259,0.003308,0.084016,210.693497,10.733238,0.840156,-184.595947,0.083141,0.000000
139.570007,46.333557,-184.640427,-0.001250,0.003302,0.083878,206.101959,10.499334,0.838778,-184.640427,0.082499,0.000000
139.950012,42.152931,-184.729385,-0.001242,0.003263,0.082871,187.505600,9.551991,0.828710,-184.729385,0.081866,0.000000
140.330002,39.622665,-184.773865,-0.001255,0.003239,0.082273,176.250412,8.978624,0.822730,-184.773865,0.081233,0.000000
140.710007,36.646660,-184.773865,-0.001250,0.003212,0.081580,163.012482,8.304252,0.815796,-184.773865,0.080599,0.000000
141.090012,34.376305,-184.773865,-0.001250,0.003192,0.081085,152.913437,7.789782,0.810846,-184.773865,0.079966,0.000000
141.470001,32.477203,-184.818344,-0.001242,0.003176,0.080661,144.465820,7.359440,0.806607,-184.818344,0.079333,0.000000
141.850006,29.786819,-184.951797,-0.001242,0.003151,0.080035,132.498398,6.749790,0.800354,-184.951797,0.078700,0.000000
142.230011,26.404556,-184.996277,-0.001242,0.003116,0.079151,117.453331,5.983358,0.791512,-184.996277,0.078067,0.000000
142.610001,23.498192,-184.996277,-0.001259,0.003088,0.078440,104.525177,5.324766,0.784397,-184.996277,0.077434,0.000000
142.990005,20.211632,-184.951797,-0.001242,0.003061,0.077746,89.905830,4.580021,0.777463,-184.951797,0.076802,0.000000
143.370010,18.560158,-185.040756,-0.001250,0.003046,0.077365,82.559708,4.205792,0.773648,-185.040756,0.076167,0.000000
143.750000,15.610970,-185.129715,-0.001237,0.003018,0.076653,69.441063,3.537496,0.766532,-185.129715,0.075534,0.000000
144.130005,12.810730,-185.129715,-0.001250,0.002992,0.076004,56.984974,2.902953,0.760037,-185.129715,0.074902,0.000000
144.510010,10.568672,-185.174194,-0.001255,0.002970,0.075430,47.011803,2.394895,0.754299,-185.174194,0.074269,0.000000
144.889999,7.711830,-185.129715,-0.001242,0.002940,0.074667,34.303932,1.747526,0.746669,-185.129715,0.073636,0.000000
145.270004,5.373703,-185.263168,-0.001237,0.002922,0.074217,23.903425,1.217699,0.742172,-185.263168,0.073003,0.000000
145.650009,2.069275,-185.263168,-0.001242,0.002890,0.073401,9.204595,0.468904,0.734012,-185.263168,0.072369,0.000000
146.030014,-0.477753,-185.352127,-0.001263,0.002866,0.072785,-2.125150,-0.108260,0.727850,-185.352127,0.071736,0.000000
146.410004,-2.792797,-185.307648,-0.001259,0.002839,0.072101,-12.422982,-0.632857,0.721007,-185.307648,0.071103,0.000000
146.790009,-0.341469,-185.307648,-0.001250,0.002817,0.071554,-1.518929,-0.077378,0.715542,-185.307648,0.070470,0.000000
147.170013,-0.197357,-185.441086,-0.001246,0.002789,0.070835,-0.877889,-0.044722,0.708351,-185.441086,0.069837,0.000000
147.550003,-0.200714,-185.485565,-0.001259,0.002761,0.070140,-0.892821,-0.045482,0.701402,-185.485565,0.069205,0.000000
147.930008,-0.042084,-185.530045,-0.001259,0.002750,0.069854,-0.187198,-0.009536,0.698540,-185.530045,0.068570,0.000000
148.310013,-0.075218,-185.441086,-0.001259,0.002712,0.068874,-0.334587,-0.017045,0.688745,-185.441086,0.067937,0.000000
148.690002,-0.035751,-185.574524,-0.001250,0.002691,0.068354,-0.159030,-0.008101,0.683537,-185.574524,0.067305,0.000000
149.070007,-0.016014,-185.574524,-0.001263,0.002672,0.067860,-0.071234,-0.003629,0.678601,-185.574524,0.066672,0.000000
149.450012,-0.062187,-185.707977,-0.001259,0.002640,0.067044,-0.276622,-0.014092,0.670441,-185.707977,0.066039,0.000000
149.830002,-0.064049,-185.663483,-0.001281,0.002613,0.066360,-0.284903,-0.014514,0.663598,-185.663483,0.065406,0.000000
150.210007,-0.081177,-185.707977,-0.001268,0.002586,0.065683,-0.361092,-0.018395,0.656831,-185.707977,0.064773,0.000000
150.590012,-0.048035,-185.707977,-0.001272,0.002565,0.065162,-0.213669,-0.010885,0.651623,-185.707977,0.064131,0.000000
150.970001,-0.036865,-185.796936,-0.001281,0.002543,0.064581,-0.163985,-0.008354,0.645809,-185.796936,0.063497,0.000000
151.350006,-0.033516,-185.885895,-0.001289,0.002522,0.064062,-0.149086,-0.007595,0.640616,-185.885895,0.062864,0.000000
151.730011,-0.052879,-185.885895,-0.001315,0.002494,0.063341,-0.235219,-0.011983,0.633410,-185.885895,0.062231,0.000000
152.110001,-0.105759,-185.885895,-0.001337,0.002465,0.062622,-0.470438,-0.023965,0.626218,-185.885895,0.061598,0.000000
152.490005,-0.086021,-185.930374,-0.001362,0.002443,0.062050,-0.382642,-0.019493,0.620496,-185.930374,0.060966,0.000000
152.870010,-0.090858,-186.019333,-0.001384,0.002417,0.061382,-0.404159,-0.020589,0.613819,-186.019333,0.060333,0.000000
153.250000,-0.042450,-185.974854,-0.001414,0.002398,0.060913,-0.188827,-0.009619,0.609126,-185.974854,0.059700,0.000000
153.630005,-0.069633,-186.019333,-0.001457,0.002373,0.060272,-0.309745,-0.015779,0.602722,-186.019333,0.059066,0.000000
154.010010,-0.084900,-186.019333,-0.001483,0.002340,0.059440,-0.377654,-0.019239,0.594395,-186.019333,0.058433,0.000000
154.390015,-0.091232,-186.152786,-0.001496,0.002316,0.058832,-0.405822,-0.020674,0.588324,-186.152786,0.057800,0.000000
154.770004,-0.066658,-186.241745,-0.001535,0.002295,0.058286,-0.296510,-0.015105,0.582859,-186.241745,0.058190,0.000000
154.800003,-0.063309,-186.197266,-0.001544,0.002295,0.058286,-0.281611,-0.014346,0.582859,-186.197266,0.058190,0.000000