File: Data/compression 27/AutoNoHeating-17-27-reverse-1-3_10162024_170940.csv
Time (sec),S:Load (lbs),S:HL1 (DIM),S:LVDT (in),S:Position (in),Ch:Position (mm),Ch:Load (N),Ch:Stress (MPa),Ch:Strain (mm/mm),Ch:HL1 (DIM),Set Point (),Cycles ()
0.110000,-0.052132,-147.187469,-0.009089,-0.004303,-0.109297,-0.231893,-0.011813,-1.092972,-147.187469,-0.109072,0.000000
0.500000,-0.021599,-147.231949,-0.009093,-0.004221,-0.107206,-0.096076,-0.004894,-1.072064,-147.231949,-0.106452,0.000000
0.890000,-0.053993,-147.320908,-0.008921,-0.003977,-0.101023,-0.240174,-0.012235,-1.010234,-147.320908,-0.099948,0.000000
1.280000,0.011169,-147.365387,-0.008658,-0.003725,-0.094615,0.049684,0.002531,-0.946148,-147.365387,-0.093461,0.000000
1.670000,0.014893,-147.365387,-0.008399,-0.003468,-0.088084,0.066245,0.003375,-0.880836,-147.365387,-0.086957,0.000000
2.060000,0.013405,-147.409866,-0.008153,-0.003215,-0.081658,0.059628,0.003038,-0.816584,-147.409866,-0.080470,0.000000
2.450000,-0.023087,-147.454346,-0.007886,-0.002961,-0.075206,-0.102694,-0.005231,-0.752059,-147.454346,-0.073966,0.000000
2.840000,-0.048409,-147.543320,-0.007618,-0.002702,-0.068641,-0.215332,-0.010970,-0.686413,-147.543320,-0.067462,0.000000
3.230000,0.017128,-147.587799,-0.007351,-0.002446,-0.062137,0.076189,0.003881,-0.621374,-147.587799,-0.060975,0.000000
3.620000,0.010796,-147.676758,-0.007105,-0.002190,-0.055633,0.048021,0.002446,-0.556334,-147.676758,-0.054471,0.000000
4.010000,0.041702,-147.632278,-0.006821,-0.001934,-0.049128,0.185501,0.009450,-0.491279,-147.632278,-0.047983,0.000000
4.400000,0.000374,-147.721237,-0.006579,-0.001687,-0.042840,0.001663,0.000085,-0.428405,-147.721237,-0.041479,0.000000
4.790000,-0.022720,-147.721237,-0.006325,-0.001421,-0.036103,-0.101065,-0.005149,-0.361034,-147.721237,-0.034975,0.000000
5.180000,-0.020111,-147.765717,-0.006062,-0.001168,-0.029668,-0.089459,-0.004557,-0.296675,-147.765717,-0.028488,0.000000
5.570000,0.024574,-147.765717,-0.005799,-0.000913,-0.023198,0.109312,0.005569,-0.231984,-147.765717,-0.021984,0.000000
5.960001,0.050644,-147.899155,-0.005540,-0.000658,-0.016711,0.225275,0.011476,-0.167111,-147.899155,-0.015497,0.000000
6.350000,0.013405,-147.943649,-0.005286,-0.000406,-0.010312,0.059628,0.003038,-0.103116,-147.943649,-0.008993,0.000000
6.740000,-0.001122,-147.988129,-0.005006,-0.000147,-0.003729,-0.004989,-0.000254,-0.037289,-147.988129,-0.002489,0.000000
7.130000,0.002235,-147.988129,-0.004764,0.000110,0.002792,0.009944,0.000507,0.027917,-147.988129,0.003998,0.000000
7.520000,0.092720,-148.121567,-0.004579,-0.000001,-0.000017,0.412439,0.021011,-0.000167,-148.121567,0.000191,0.000000
7.910000,0.072609,-148.121567,-0.004562,-0.000001,-0.000017,0.322981,0.016453,-0.000167,-148.121567,0.000207,0.000000
8.300000,0.070007,-148.166046,-0.004557,0.000001,0.000035,0.311408,0.015864,0.000348,-148.166046,0.000858,0.000000
8.690001,0.126236,-148.210526,-0.004575,0.000015,0.000382,0.561526,0.028605,0.003815,-148.210526,0.001509,0.000000
9.080001,0.161606,-148.299484,-0.004544,0.000050,0.001266,0.718859,0.036620,0.012657,-148.299484,0.002159,0.000000
9.470000,0.197357,-148.343979,-0.004518,0.000074,0.001882,0.877889,0.044722,0.018818,-148.343979,0.002810,0.000000
9.860001,0.270714,-148.299484,-0.004497,0.000097,0.002463,1.204195,0.061345,0.024632,-148.299484,0.003461,0.000000
10.250001,0.466209,-148.388458,-0.004475,0.000126,0.003208,2.073803,0.105645,0.032081,-148.388458,0.004110,0.000000
10.640000,0.644951,-148.477417,-0.004441,0.000144,0.003659,2.868885,0.146148,0.036592,-148.477417,0.004761,0.000000
11.030001,1.032585,-148.477417,-0.004424,0.000182,0.004613,4.593168,0.233987,0.046130,-148.477417,0.005411,0.000000
11.420000,1.247444,-148.521896,-0.004402,0.000201,0.005099,5.548909,0.282675,0.050990,-148.521896,0.006062,0.000000
11.810000,1.600456,-148.521896,-0.004393,0.000227,0.005767,7.119185,0.362669,0.057667,-148.521896,0.006713,0.000000
12.200001,2.040596,-148.655334,-0.004355,0.000252,0.006392,9.077024,0.462406,0.063919,-148.655334,0.007362,0.000000
12.590000,2.402916,-148.610855,-0.004333,0.000274,0.006972,10.688704,0.544509,0.069718,-148.610855,0.008013,0.000000
12.980000,2.997223,-148.744293,-0.004320,0.000309,0.007839,13.332314,0.679180,0.078393,-148.744293,0.008663,0.000000
13.370001,3.216553,-148.788788,-0.004290,0.000329,0.008360,14.307941,0.728881,0.083601,-148.788788,0.009305,0.000000
13.760000,3.611267,-148.833267,-0.004286,0.000353,0.008976,16.063719,0.818325,0.089763,-148.833267,0.009956,0.000000
14.150001,4.169083,-148.877747,-0.004260,0.000383,0.009721,18.545006,0.944728,0.097211,-148.877747,0.010607,0.000000
14.540001,4.507195,-148.922226,-0.004238,0.000404,0.010259,20.049002,1.021345,0.102586,-148.922226,0.011256,0.000000
14.930000,5.132782,-148.922226,-0.004208,0.000435,0.011049,22.831755,1.163105,0.110489,-148.922226,0.011907,0.000000
15.320001,5.278008,-149.011185,-0.004191,0.000457,0.011603,23.477751,1.196014,0.116030,-149.011185,0.012557,0.000000
15.710001,5.569572,-149.055664,-0.004169,0.000479,0.012168,24.774696,1.262083,0.121677,-149.055664,0.013208,0.000000
16.100000,6.135582,-149.055664,-0.004148,0.000510,0.012947,27.292431,1.390343,0.129474,-149.055664,0.013859,0.000000
16.490002,6.302399,-149.144623,-0.004122,0.000530,0.013468,28.034470,1.428144,0.134682,-149.144623,0.014508,0.000000
16.880001,6.937668,-149.189117,-0.004100,0.000561,0.014248,30.860289,1.572098,0.142479,-149.189117,0.015159,0.000000
17.270000,7.005066,-149.233597,-0.004079,0.000583,0.014813,31.160089,1.587371,0.148126,-149.233597,0.015810,0.000000
17.660002,7.231468,-149.278076,-0.004057,0.000606,0.015385,32.167175,1.638674,0.153848,-149.278076,0.016460,0.000000
18.050001,7.708107,-149.322556,-0.004010,0.000639,0.016243,34.287373,1.746682,0.162433,-149.322556,0.017111,0.000000
18.440001,7.767319,-149.322556,-0.003992,0.000658,0.016711,34.550758,1.760100,0.167111,-149.322556,0.017760,0.000000
18.830002,8.197037,-149.411514,-0.003975,0.000687,0.017448,36.462242,1.857475,0.174484,-149.411514,0.018411,0.000000
19.220001,8.232407,-149.500473,-0.003945,0.000712,0.018081,36.619572,1.865490,0.180812,-149.500473,0.019062,0.000000
19.610001,8.247673,-149.500473,-0.003919,0.000731,0.018567,36.687481,1.868950,0.185672,-149.500473,0.019712,0.000000
20.000000,8.518021,-149.633926,-0.003911,0.000760,0.019295,37.890049,1.930211,0.192954,-149.633926,0.020363,0.000000
20.390001,8.843842,-149.544952,-0.003872,0.000786,0.019972,39.339371,2.004043,0.199721,-149.544952,0.021012,0.000000
20.780001,9.222916,-149.633926,-0.003850,0.000818,0.020788,41.025578,2.089942,0.207882,-149.633926,0.021663,0.000000
21.170000,9.078438,-149.722885,-0.003803,0.000838,0.021282,40.382908,2.057204,0.212817,-149.722885,0.022314,0.000000
21.560001,9.073601,-149.722885,-0.003807,0.000859,0.021828,40.361393,2.056108,0.218282,-149.722885,0.022964,0.000000
21.950001,9.530869,-149.811844,-0.003764,0.000889,0.022591,42.395420,2.159726,0.225913,-149.811844,0.023615,0.000000
22.340000,9.664177,-149.856323,-0.003742,0.000914,0.023215,42.988407,2.189934,0.232150,-149.856323,0.024266,0.000000
22.730001,9.964310,-149.900803,-0.003742,0.000944,0.023970,44.323463,2.257945,0.239705,-149.900803,0.024906,0.000000
23.120001,9.879410,-149.989761,-0.003699,0.000967,0.024559,43.945808,2.238706,0.245594,-149.989761,0.025557,0.000000
23.510000,10.023521,-149.989761,-0.003665,0.000992,0.025192,44.586849,2.271363,0.251923,-149.989761,0.026208,0.000000
23.900002,10.205612,-150.078735,-0.003639,0.001018,0.025869,45.396832,2.312625,0.258690,-150.078735,0.026858,0.000000
24.290001,10.294235,-150.078735,-0.003613,0.001041,0.026434,45.791046,2.332707,0.264337,-150.078735,0.027509,0.000000
24.680000,10.694160,-150.123215,-0.003574,0.001073,0.027248,47.570000,2.423331,0.272482,-150.123215,0.028158,0.000000
25.070002,10.622665,-150.167694,-0.003570,0.001097,0.027872,47.251976,2.407130,0.278720,-150.167694,0.028809,0.000000
25.460001,10.790604,-150.123215,-0.003557,0.001123,0.028514,47.999001,2.445186,0.285139,-150.123215,0.029460,0.000000
25.850000,10.955940,-150.301132,-0.003523,0.001148,0.029156,48.734455,2.482651,0.291558,-150.301132,0.030110,0.000000
26.240002,11.055733,-150.256653,-0.003505,0.001171,0.029754,49.178356,2.505265,0.297538,-150.256653,0.030761,0.000000
26.630001,11.409866,-150.390091,-0.003471,0.001199,0.030465,50.753620,2.585513,0.304654,-150.390091,0.031412,0.000000
27.020000,11.378212,-150.434570,-0.003441,0.001225,0.031125,50.612816,2.578340,0.311255,-150.434570,0.032061,0.000000
27.410002,11.352890,-150.390091,-0.003428,0.001245,0.031619,50.500175,2.572602,0.316190,-150.390091,0.032712,0.000000
27.800001,11.671265,-150.479065,-0.003389,0.001274,0.032347,51.916378,2.644746,0.323472,-150.479065,0.033362,0.000000
28.190001,11.807182,-150.568024,-0.003372,0.001298,0.032963,52.520969,2.675546,0.329634,-150.568024,0.034013,0.000000
28.580002,12.265945,-150.568024,-0.003337,0.001332,0.033838,54.561649,2.779503,0.338385,-150.568024,0.034664,0.000000
28.970001,12.119980,-150.701462,-0.003303,0.001353,0.034377,53.912361,2.746427,0.343774,-150.701462,0.035313,0.000000
29.360001,12.291267,-150.701462,-0.003298,0.001378,0.034992,54.674290,2.785241,0.349921,-150.701462,0.035964,0.000000
29.750002,12.622307,-150.790421,-0.003268,0.001404,0.035660,56.146824,2.860255,0.356598,-150.790421,0.036614,0.000000
30.140001,12.539268,-150.790421,-0.003242,0.001423,0.036155,55.777451,2.841439,0.361548,-150.790421,0.037265,0.000000
30.530001,12.886688,-150.790421,-0.003225,0.001455,0.036969,57.322853,2.920165,0.369693,-150.790421,0.037916,0.000000
30.920002,13.174538,-150.879379,-0.003191,0.001480,0.037586,58.603271,2.985393,0.375855,-150.879379,0.038565,0.000000
31.310001,13.194275,-150.879379,-0.003182,0.001502,0.038149,58.691067,2.989866,0.381487,-150.879379,0.039216,0.000000
31.700001,13.645218,-151.012833,-0.003156,0.001533,0.038930,60.696960,3.092051,0.389299,-151.012833,0.039858,0.000000
32.090000,13.571487,-150.968353,-0.003143,0.001551,0.039407,60.368992,3.075343,0.394068,-150.968353,0.040507,0.000000
32.480003,14.133392,-151.101791,-0.003096,0.001585,0.040265,62.868469,3.202672,0.402652,-151.101791,0.041158,0.000000
32.870003,13.998596,-151.057312,-0.003078,0.001607,0.040821,62.268867,3.172127,0.408208,-151.057312,0.041809,0.000000
33.260002,14.503906,-151.101791,-0.003061,0.001639,0.041626,64.516594,3.286632,0.416263,-151.101791,0.042459,0.000000
33.650002,14.467041,-151.235229,-0.003018,0.001659,0.042138,64.352615,3.278278,0.421380,-151.235229,0.043110,0.000000
34.040001,14.546730,-151.235229,-0.003009,0.001679,0.042659,64.707085,3.296336,0.426588,-151.235229,0.043761,0.000000
34.430000,15.132095,-151.324188,-0.002984,0.001712,0.043491,67.310921,3.428982,0.434915,-151.324188,0.044410,0.000000
34.820004,15.081825,-151.324188,-0.002966,0.001735,0.044073,67.087311,3.417590,0.440728,-151.324188,0.045061,0.000000
35.210003,15.306740,-151.368683,-0.002932,0.001760,0.044697,68.087776,3.468557,0.446966,-151.368683,0.045711,0.000000
35.600002,15.702942,-151.413162,-0.002915,0.001788,0.045417,69.850174,3.558337,0.454172,-151.413162,0.046362,0.000000
35.990002,15.621765,-151.502121,-0.002893,0.001807,0.045894,69.489082,3.539943,0.458941,-151.502121,0.047013,0.000000
36.380001,16.314011,-151.546600,-0.002871,0.001840,0.046743,72.568344,3.696808,0.467435,-151.546600,0.047662,0.000000
36.770000,16.385132,-151.546600,-0.002837,0.001865,0.047360,72.884705,3.712924,0.473596,-151.546600,0.048313,0.000000
37.160004,16.729576,-151.591080,-0.002837,0.001891,0.048036,74.416870,3.790976,0.480364,-151.591080,0.048963,0.000000
37.550003,16.884857,-151.680038,-0.002807,0.001916,0.048660,75.107597,3.826164,0.486601,-151.680038,0.049614,0.000000
37.940002,16.836075,-151.724518,-0.002772,0.001935,0.049146,74.890602,3.815109,0.491461,-151.724518,0.050265,0.000000
38.330002,17.556244,-151.769012,-0.002755,0.001965,0.049918,78.094070,3.978302,0.499182,-151.769012,0.050914,0.000000
38.720001,17.704445,-151.813492,-0.002734,0.001991,0.050568,78.753304,4.011885,0.505677,-151.813492,0.051565,0.000000
39.110001,18.074211,-151.857971,-0.002699,0.002016,0.051210,80.398109,4.095675,0.512096,-151.857971,0.052216,0.000000
39.500000,18.291679,-151.902451,-0.002686,0.002043,0.051895,81.365456,4.144954,0.518955,-151.902451,0.052866,0.000000
39.890003,18.260399,-151.946930,-0.002660,0.002061,0.052345,81.226311,4.137866,0.523451,-151.946930,0.053517,0.000000
40.280003,19.020409,-152.035889,-0.002647,0.002092,0.053126,84.607002,4.310086,0.531263,-152.035889,0.054166,0.000000
40.670002,19.209946,-152.035889,-0.002613,0.002118,0.053803,85.450104,4.353036,0.538030,-152.035889,0.054808,0.000000
41.060001,19.458694,-152.080368,-0.002596,0.002142,0.054401,86.556595,4.409403,0.544011,-152.080368,0.055459,0.000000
41.450001,19.862717,-152.169327,-0.002561,0.002168,0.055060,88.353775,4.500956,0.550596,-152.169327,0.056109,0.000000
41.840000,19.810211,-152.169327,-0.002539,0.002186,0.055529,88.120224,4.489058,0.555290,-152.169327,0.056760,0.000000
42.230003,20.876686,-152.302780,-0.002518,0.002222,0.056448,92.864136,4.730724,0.564479,-152.302780,0.057411,0.000000
42.620003,20.784714,-152.302780,-0.002483,0.002245,0.057029,92.455025,4.709884,0.570293,-152.302780,0.058060,0.000000
43.010002,21.104950,-152.347260,-0.002475,0.002269,0.057644,93.879509,4.782450,0.576439,-152.347260,0.058711,0.000000
43.400002,21.629997,-152.436218,-0.002432,0.002297,0.058346,96.215034,4.901427,0.583464,-152.436218,0.059362,0.000000
43.790001,21.681015,-152.391739,-0.002423,0.002317,0.058858,96.441971,4.912988,0.588581,-152.391739,0.060012,0.000000
44.180000,22.756050,-152.480698,-0.002397,0.002350,0.059691,101.223969,5.156595,0.596908,-152.480698,0.060663,0.000000
44.570004,22.794403,-152.525177,-0.002367,0.002374,0.060289,101.394569,5.165286,0.602888,-152.525177,0.061312,0.000000
44.960003,23.391693,-152.614136,-0.002350,0.002402,0.061019,104.051445,5.300633,0.610186,-152.614136,0.061963,0.000000
45.350002,23.504150,-152.614136,-0.002315,0.002424,0.061565,104.551682,5.326117,0.615651,-152.614136,0.062614,0.000000
45.740002,23.868698,-152.658630,-0.002311,0.002445,0.062110,106.173271,5.408724,0.621101,-152.658630,0.063264,0.000000
46.130001,24.686432,-152.703110,-0.002276,0.002476,0.062900,109.810730,5.594026,0.629004,-152.703110,0.063915,0.000000
46.520000,25.112801,-152.747589,-0.002268,0.002503,0.063568,111.707314,5.690642,0.635681,-152.747589,0.064564,0.000000
46.910004,25.713432,-152.836548,-0.002238,0.002531,0.064278,114.379059,5.826747,0.642781,-152.836548,0.065215,0.000000
47.300003,25.773758,-152.925507,-0.002220,0.002548,0.064722,114.647400,5.840417,0.647217,-152.925507,0.065866,0.000000
47.690002,26.255608,-152.881027,-0.002195,0.002575,0.065406,116.790779,5.949606,0.654060,-152.881027,0.066516,0.000000
48.080002,27.521301,-153.014465,-0.002177,0.002608,0.066248,122.420860,6.236416,0.662478,-153.014465,0.067167,0.000000
48.470001,27.689240,-153.058960,-0.002151,0.002631,0.066820,123.167892,6.274471,0.668200,-153.058960,0.067818,0.000000
48.860001,28.258224,-153.058960,-0.002130,0.002654,0.067409,125.698860,6.403405,0.674090,-153.058960,0.068467,0.000000
49.250004,28.409409,-153.058960,-0.002095,0.002678,0.068009,126.371361,6.437664,0.680085,-153.058960,0.069118,0.000000
49.640003,29.818092,-153.103439,-0.002087,0.002710,0.068840,132.637497,6.756876,0.688397,-153.103439,0.069760,0.000000
50.030003,30.483154,-153.236877,-0.002057,0.002735,0.069474,135.595840,6.907582,0.694740,-153.236877,0.070410,0.000000
50.420002,30.681625,-153.192398,-0.002044,0.002757,0.070037,136.478683,6.952556,0.700372,-153.192398,0.071061,0.000000
50.810001,31.410736,-153.281357,-0.002022,0.002785,0.070731,139.721939,7.117774,0.707306,-153.281357,0.071712,0.000000
51.200001,32.081375,-153.236877,-0.002001,0.002809,0.071347,142.705078,7.269743,0.713468,-153.236877,0.072361,0.000000
51.590004,32.603439,-153.370316,-0.001983,0.002834,0.071989,145.027344,7.388045,0.719887,-153.370316,0.073012,0.000000
51.980003,33.847168,-153.459274,-0.001962,0.002861,0.072673,150.559723,7.669878,0.726730,-153.459274,0.073662,0.000000
52.370003,34.277252,-153.414795,-0.001932,0.002885,0.073280,152.472839,7.767336,0.732801,-153.414795,0.074313,0.000000
52.760002,35.425278,-153.503769,-0.001923,0.002914,0.074017,157.579498,8.027483,0.740174,-153.503769,0.074964,0.000000
53.150002,35.708656,-153.548248,-0.001901,0.002933,0.074494,158.840042,8.091698,0.744943,-153.548248,0.075613,0.000000
53.540001,36.177475,-153.592728,-0.001884,0.002955,0.075059,160.925446,8.197933,0.750590,-153.592728,0.076264,0.000000
53.930004,37.491943,-153.681686,-0.001854,0.002989,0.075917,166.772491,8.495795,0.759174,-153.681686,0.076914,0.000000
54.320004,38.422134,-153.726166,-0.001832,0.003014,0.076559,170.910187,8.706580,0.765593,-153.726166,0.077565,0.000000
54.710003,39.340034,-153.770645,-0.001832,0.003039,0.077183,174.993210,8.914578,0.771831,-153.770645,0.078216,0.000000
55.100002,40.039719,-153.770645,-0.001802,0.003063,0.077790,178.105560,9.073130,0.777902,-153.770645,0.078865,0.000000
55.490002,40.263512,-153.815125,-0.001781,0.003082,0.078293,179.101044,9.123842,0.782928,-153.815125,0.079516,0.000000
55.880001,41.933609,-153.904083,-0.001763,0.003114,0.079091,186.530014,9.502292,0.790907,-153.904083,0.080167,0.000000
56.270004,43.059662,-153.948578,-0.001729,0.003143,0.079837,191.538940,9.757459,0.798371,-153.948578,0.080817,0.000000
56.660004,43.990593,-153.993057,-0.001733,0.003169,0.080496,195.679932,9.968411,0.804956,-153.993057,0.081468,0.000000
57.050003,44.855614,-154.037537,-0.001699,0.003190,0.081016,199.527740,10.164428,0.810164,-154.037537,0.082117,0.000000
57.440002,45.154999,-154.037537,-0.001681,0.003209,0.081502,200.859467,10.232268,0.815024,-154.037537,0.082768,0.000000
57.830002,47.351250,-154.082016,-0.001677,0.003243,0.082377,210.628876,10.729946,0.823775,-154.082016,0.083419,0.000000
58.220001,48.367088,-154.126495,-0.001647,0.003269,0.083028,215.147552,10.960138,0.830285,-154.126495,0.084069,0.000000
58.610004,49.773163,-154.259933,-0.001643,0.003298,0.083757,221.402084,11.278760,0.837567,-154.259933,0.084710,0.000000
59.000004,50.307518,-154.259933,-0.001600,0.003316,0.084225,223.779022,11.399846,0.842245,-154.259933,0.085361,0.000000
59.390003,50.984489,-154.259933,-0.001595,0.003336,0.084736,226.790329,11.553250,0.847362,-154.259933,0.086011,0.000000
59.780003,52.914497,-154.393387,-0.001604,0.003370,0.085595,235.375443,11.990597,0.855946,-154.393387,0.086662,0.000000
60.170002,54.148537,-154.348907,-0.001587,0.003398,0.086306,240.864716,12.270233,0.863062,-154.348907,0.087313,0.000000
60.560001,55.658134,-154.437866,-0.001565,0.003426,0.087009,247.579742,12.612313,0.870087,-154.437866,0.087962,0.000000
60.950005,56.502678,-154.482346,-0.001544,0.003444,0.087469,251.336472,12.803690,0.874689,-154.482346,0.088613,0.000000
61.340004,56.897766,-154.526825,-0.001539,0.003460,0.087876,253.093903,12.893218,0.878762,-154.526825,0.089263,0.000000
61.730003,59.201263,-154.615784,-0.001522,0.003499,0.088865,263.340363,13.415198,0.888648,-154.615784,0.089914,0.000000
62.120003,60.430466,-154.571304,-0.001500,0.003521,0.089437,268.808136,13.693739,0.894371,-154.571304,0.090565,0.000000
62.510002,61.809357,-154.660263,-0.001483,0.003548,0.090130,274.941742,14.006200,0.901305,-154.660263,0.091214,0.000000
62.900002,63.250435,-154.704742,-0.001462,0.003570,0.090677,281.351990,14.332753,0.906770,-154.704742,0.091865,0.000000
63.290005,64.642372,-154.749222,-0.001466,0.003600,0.091431,287.543640,14.648171,0.914310,-154.749222,0.092515,0.000000
63.680004,65.512230,-154.838196,-0.001440,0.003608,0.091640,291.412964,14.845284,0.916399,-154.838196,0.016085,0.000000
64.070000,65.546486,-154.838196,-0.001444,0.003619,0.091926,291.565338,14.853046,0.919260,-154.838196,294.500488,0.000000
64.460007,65.271309,-154.927155,-0.001436,0.003631,0.092229,290.341278,14.790690,0.922288,-154.927155,294.500488,0.000000
64.850006,65.197197,-154.927155,-0.001410,0.003640,0.092447,290.011627,14.773896,0.924468,-154.927155,294.500488,0.000000
65.240005,65.073570,-154.971634,-0.001410,0.003647,0.092645,289.461700,14.745882,0.926451,-154.971634,294.500488,0.000000
65.630005,65.141716,-155.105072,-0.001414,0.003654,0.092819,289.764832,14.761324,0.928192,-155.105072,294.500488,0.000000
66.020004,65.083260,-155.016113,-0.001384,0.003664,0.093061,289.504791,14.748077,0.930615,-155.016113,294.500488,0.000000
66.410004,64.934685,-155.149551,-0.001397,0.003664,0.093061,288.843903,14.714410,0.930615,-155.149551,294.500488,0.000000
66.800003,65.502556,-155.194031,-0.001380,0.003675,0.093348,291.369934,14.843092,0.933476,-155.194031,294.500488,0.000000
67.190002,65.275032,-155.194031,-0.001371,0.003679,0.093443,290.357849,14.791533,0.934430,-155.194031,294.500488,0.000000
67.580002,65.360680,-155.283005,-0.001380,0.003684,0.093582,290.738831,14.810942,0.935823,-155.283005,294.500488,0.000000
67.970001,65.126823,-155.283005,-0.001375,0.003686,0.093626,289.698578,14.757949,0.936262,-155.283005,294.500488,0.000000
68.360001,65.243004,-155.416443,-0.001362,0.003691,0.093756,290.215363,14.784276,0.937564,-155.416443,294.500488,0.000000
68.750000,65.165184,-155.416443,-0.001358,0.003696,0.093878,289.869202,14.766642,0.938775,-155.416443,294.500488,0.000000
69.140007,65.023674,-155.460922,-0.001350,0.003697,0.093903,289.239746,14.734575,0.939032,-155.460922,294.500488,0.000000
69.530006,65.302589,-155.549881,-0.001358,0.003702,0.094033,290.480438,14.797779,0.940334,-155.549881,294.500488,0.000000
69.920006,64.993523,-155.505402,-0.001341,0.003702,0.094033,289.105621,14.727742,0.940334,-155.505402,294.500488,0.000000
70.310005,65.330513,-155.594360,-0.001354,0.003718,0.094432,290.604645,14.804106,0.944316,-155.594360,294.500488,0.000000
70.700005,65.651131,-155.638855,-0.001345,0.003715,0.094354,292.030823,14.876760,0.943544,-155.638855,294.500488,0.000000
71.090004,65.423973,-155.683334,-0.001345,0.003715,0.094354,291.020355,14.825285,0.943544,-155.683334,294.500488,0.000000
71.480003,65.172630,-155.772293,-0.001341,0.003715,0.094354,289.902344,14.768330,0.943544,-155.772293,294.500488,0.000000
71.870003,64.961494,-155.727814,-0.001341,0.003715,0.094363,288.963165,14.720485,0.943635,-155.727814,294.500488,0.000000
72.260002,65.003197,-155.816772,-0.001332,0.003719,0.094466,289.148651,14.729935,0.944664,-155.816772,294.500488,0.000000
72.650002,64.933937,-155.816772,-0.001332,0.003721,0.094510,288.840576,14.714240,0.945103,-155.816772,294.500488,0.000000
73.040001,66.022377,-155.861252,-0.001332,0.003728,0.094684,293.682190,14.960884,0.946844,-155.861252,294.500488,0.000000
73.430000,65.769173,-155.950211,-0.001332,0.003727,0.094675,292.555878,14.903507,0.946754,-155.950211,294.500488,0.000000
73.820000,65.530098,-155.950211,-0.001324,0.003728,0.094684,291.492432,14.849333,0.946844,-155.950211,294.500488,0.000000
74.210007,65.280983,-156.083664,-0.001328,0.003728,0.094701,290.384308,14.792882,0.947011,-156.083664,294.500488,0.000000
74.600006,65.063515,-156.128143,-0.001324,0.003729,0.094710,289.416962,14.743604,0.947102,-156.128143,294.500488,0.000000
74.990005,65.739372,-156.128143,-0.001319,0.003740,0.094996,292.423340,14.896754,0.949963,-156.128143,294.500488,0.000000
75.380005,65.601234,-156.172623,-0.001324,0.003740,0.094996,291.808868,14.865452,0.949963,-156.172623,294.500488,0.000000
75.770004,65.482445,-156.217102,-0.001328,0.003740,0.094996,291.280457,14.838534,0.949963,-156.217102,294.500488,0.000000
76.160004,65.301842,-156.261581,-0.001315,0.003740,0.094996,290.477112,14.797609,0.949963,-156.261581,294.500488,0.000000
76.550003,65.177834,-156.306061,-0.001306,0.003740,0.094996,289.925476,14.769507,0.949963,-156.306061,294.500488,0.000000
76.940002,65.012138,-156.350540,-0.001311,0.003740,0.094996,289.188446,14.731961,0.949963,-156.350540,294.500488,0.000000
77.330002,64.868401,-156.439499,-0.001324,0.003742,0.095057,288.549042,14.699389,0.950569,-156.439499,294.500488,0.000000
77.720001,65.830986,-156.439499,-0.001311,0.003752,0.095308,292.830841,14.917515,0.953082,-156.439499,294.500488,0.000000
78.110001,65.742729,-156.528473,-0.001315,0.003752,0.095308,292.438263,14.897515,0.953082,-156.528473,294.500488,0.000000
78.500000,65.592293,-156.528473,-0.001302,0.003752,0.095308,291.769104,14.863425,0.953082,-156.528473,294.500488,0.000000
78.890007,65.507759,-156.617432,-0.001298,0.003752,0.095308,291.393066,14.844271,0.953082,-156.617432,294.500488,0.000000
79.280006,65.367744,-156.661911,-0.001302,0.003752,0.095308,290.770264,14.812542,0.953082,-156.661911,294.500488,0.000000
79.670006,65.260139,-156.706390,-0.001311,0.003752,0.095308,290.291595,14.788159,0.953082,-156.706390,294.500488,0.000000
80.060005,65.134651,-156.706390,-0.001306,0.003752,0.095308,289.733398,14.759723,0.953082,-156.706390,294.500488,0.000000
80.450005,65.019951,-156.795349,-0.001293,0.003752,0.095308,289.223175,14.733731,0.953082,-156.795349,294.500488,0.000000
80.840004,64.924248,-156.795349,-0.001315,0.003752,0.095308,288.797485,14.712045,0.953082,-156.795349,294.500488,0.000000
81.230003,64.797646,-156.884308,-0.001315,0.003752,0.095308,288.234314,14.683356,0.953082,-156.884308,294.500488,0.000000
81.620003,64.701576,-156.928802,-0.001306,0.003752,0.095308,287.806976,14.661587,0.953082,-156.928802,294.500488,0.000000
82.010002,66.389915,-157.017761,-0.001293,0.003739,0.094971,295.317108,15.044169,0.949706,-157.017761,294.500488,0.000000
82.400002,66.249153,-156.973282,-0.001281,0.003739,0.094971,294.690948,15.012273,0.949706,-156.973282,294.500488,0.000000
82.790001,66.109886,-157.062241,-0.001289,0.003739,0.094971,294.071472,14.980714,0.949706,-157.062241,294.500488,0.000000
83.180000,65.997063,-157.151199,-0.001281,0.003739,0.094971,293.569611,14.955149,0.949706,-157.151199,294.500488,0.000000
83.570007,65.845131,-157.151199,-0.001293,0.003739,0.094971,292.893768,14.920719,0.949706,-157.151199,294.500488,0.000000
83.960007,65.765068,-157.151199,-0.001289,0.003739,0.094971,292.537628,14.902577,0.949706,-157.151199,294.500488,0.000000
84.350006,65.648888,-157.284637,-0.001276,0.003739,0.094978,292.020844,14.876251,0.949782,-157.284637,294.500488,0.000000
84.740005,65.555428,-157.240158,-0.001272,0.003740,0.095004,291.605103,14.855073,0.950039,-157.240158,294.500488,0.000000
85.130005,65.443718,-157.284637,-0.001276,0.003740,0.095004,291.108185,14.829759,0.950039,-157.284637,294.500488,0.000000
85.520004,65.367012,-157.329117,-0.001281,0.003750,0.095257,290.766998,14.812377,0.952567,-157.329117,294.500488,0.000000
85.910004,65.309654,-157.373611,-0.001281,0.003758,0.095447,290.511841,14.799379,0.954475,-157.373611,294.500488,0.000000
86.300003,65.224388,-157.462570,-0.001285,0.003761,0.095534,290.132568,14.780058,0.955338,-157.462570,294.500488,0.000000
86.690002,65.198326,-157.462570,-0.001276,0.003764,0.095594,290.016632,14.774152,0.955943,-157.462570,294.500488,0.000000
87.080002,65.203529,-157.507050,-0.001293,0.003765,0.095620,290.039795,14.775331,0.956201,-157.507050,294.500488,0.000000
87.470001,65.306679,-157.596008,-0.001268,0.003767,0.095690,290.498627,14.798705,0.956897,-157.596008,294.500488,0.000000
87.860001,65.285088,-157.596008,-0.001272,0.003768,0.095706,290.402588,14.793813,0.957064,-157.596008,294.500488,0.000000
88.250008,65.295143,-157.684967,-0.001293,0.003769,0.095725,290.447296,14.796091,0.957245,-157.684967,294.500488,0.000000
88.640007,65.255287,-157.729446,-0.001281,0.003769,0.095734,290.270020,14.787059,0.957336,-157.729446,294.500488,0.000000
89.030006,65.213219,-157.773926,-0.001281,0.003770,0.095759,290.082886,14.777527,0.957594,-157.773926,294.500488,0.000000
89.420006,65.190498,-157.773926,-0.001289,0.003770,0.095759,289.981812,14.772378,0.957594,-157.773926,294.500488,0.000000
89.810005,65.194221,-157.773926,-0.001268,0.003773,0.095846,289.998383,14.773222,0.958457,-157.773926,294.500488,0.000000
90.200005,65.282845,-157.862900,-0.001289,0.003773,0.095846,290.392609,14.793304,0.958457,-157.862900,294.500488,0.000000
90.590004,65.249702,-157.907379,-0.001276,0.003773,0.095846,290.245178,14.785793,0.958457,-157.907379,294.500488,0.000000
90.980003,65.219917,-157.907379,-0.001285,0.003773,0.095846,290.112671,14.779044,0.958457,-157.907379,294.500488,0.000000
91.370003,65.178581,-158.040817,-0.001276,0.003774,0.095864,289.928802,14.769677,0.958638,-158.040817,294.500488,0.000000
91.760002,65.166298,-158.085297,-0.001281,0.003776,0.095906,289.874176,14.766894,0.959062,-158.085297,294.500488,0.000000
92.150002,65.188637,-158.129776,-0.001285,0.003776,0.095915,289.973541,14.771956,0.959153,-158.129776,294.500488,0.000000
92.540001,65.275398,-158.129776,-0.001285,0.003778,0.095967,290.359467,14.791616,0.959668,-158.129776,294.500488,0.000000
92.930008,65.278755,-158.218750,-0.001272,0.003778,0.095967,290.374420,14.792377,0.959668,-158.218750,294.500488,0.000000
93.320007,65.240395,-158.307709,-0.001272,0.003778,0.095967,290.203766,14.783685,0.959668,-158.307709,294.500488,0.000000
93.710007,65.219551,-158.174255,-0.001272,0.003779,0.095976,290.111053,14.778962,0.959759,-158.174255,294.500488,0.000000
94.100006,65.183800,-158.307709,-0.001276,0.003779,0.095993,289.952026,14.770861,0.959925,-158.307709,294.500488,0.000000
94.490005,65.174858,-158.352188,-0.001281,0.003780,0.096011,289.912262,14.768834,0.960107,-158.352188,294.500488,0.000000
94.880005,65.167778,-158.352188,-0.001289,0.003780,0.096020,289.880768,14.767229,0.960198,-158.352188,294.500488,0.000000
95.270004,65.165916,-158.530106,-0.001285,0.003782,0.096055,289.872467,14.766808,0.960546,-158.530106,294.500488,0.000000
95.660004,65.186775,-158.441147,-0.001272,0.003782,0.096062,289.965271,14.771534,0.960621,-158.441147,294.500488,0.000000
96.050003,65.173378,-158.530106,-0.001285,0.003782,0.096071,289.905670,14.768499,0.960712,-158.530106,294.500488,0.000000
96.440002,65.174110,-158.619064,-0.001272,0.003783,0.096080,289.908936,14.768664,0.960803,-158.619064,294.500488,0.000000
96.830002,65.238533,-158.619064,-0.001268,0.003785,0.096132,290.195496,14.783262,0.961318,-158.619064,294.500488,0.000000
97.220001,65.232201,-158.708038,-0.001281,0.003785,0.096132,290.167328,14.781828,0.961318,-158.708038,294.500488,0.000000
97.610008,65.211723,-158.752518,-0.001263,0.003785,0.096132,290.076233,14.777188,0.961318,-158.752518,294.500488,0.000000
98.000008,65.197945,-158.796997,-0.001268,0.003785,0.096150,290.014954,14.774065,0.961500,-158.796997,294.500488,0.000000
98.390007,65.171516,-158.796997,-0.001281,0.003786,0.096158,289.897369,14.768077,0.961575,-158.796997,294.500488,0.000000
98.780006,65.153633,-158.752518,-0.001263,0.003786,0.096158,289.817841,14.764025,0.961575,-158.752518,294.500488,0.000000
99.170006,65.162575,-158.974915,-0.001281,0.003787,0.096183,289.857605,14.766050,0.961833,-158.974915,294.500488,0.000000
99.560005,65.149910,-158.930435,-0.001276,0.003787,0.096192,289.801270,14.763181,0.961923,-158.930435,294.500488,0.000000
99.950005,65.190880,-158.974915,-0.001268,0.003788,0.096227,289.983521,14.772465,0.962272,-158.974915,294.500488,0.000000
100.340004,65.185661,-159.063889,-0.001276,0.003788,0.096227,289.960297,14.771281,0.962272,-159.063889,294.500488,0.000000
100.730003,65.162193,-158.974915,-0.001276,0.003788,0.096227,289.855927,14.765965,0.962272,-158.974915,294.500488,0.000000
101.120003,65.122353,-159.197327,-0.001281,0.003788,0.096227,289.678680,14.756936,0.962272,-159.197327,294.500488,0.000000
101.510002,65.090706,-159.152847,-0.001272,0.003788,0.096227,289.537933,14.749764,0.962272,-159.152847,294.500488,0.000000
101.900002,65.517067,-159.241806,-0.001272,0.003796,0.096427,291.434479,14.846379,0.964270,-159.241806,294.500488,0.000000
102.290009,65.637718,-159.241806,-0.001281,0.003796,0.096427,291.971161,14.873720,0.964270,-159.241806,294.500488,0.000000
102.680008,65.642189,-159.241806,-0.001263,0.003796,0.096427,291.991028,14.874733,0.964270,-159.241806,294.500488,0.000000
103.070007,65.619102,-159.375244,-0.001272,0.003796,0.096427,291.888336,14.869501,0.964270,-159.375244,294.500488,0.000000
103.460007,65.595268,-159.330765,-0.001268,0.003796,0.096427,291.782318,14.864100,0.964270,-159.330765,294.500488,0.000000
103.850006,65.588188,-159.419724,-0.001276,0.003796,0.096427,291.750824,14.862496,0.964270,-159.419724,294.500488,0.000000
104.240005,65.559898,-159.464203,-0.001268,0.003796,0.096427,291.625000,14.856086,0.964270,-159.464203,294.500488,0.000000
104.630005,65.532707,-159.508698,-0.001268,0.003796,0.096427,291.504028,14.849923,0.964270,-159.508698,294.500488,0.000000
105.020004,65.493614,-159.597656,-0.001276,0.003796,0.096427,291.330139,14.841065,0.964270,-159.597656,294.500488,0.000000
105.410004,65.477226,-159.642136,-0.001268,0.003796,0.096427,291.257263,14.837352,0.964270,-159.642136,294.500488,0.000000
105.800003,65.428825,-159.597656,-0.001259,0.003796,0.096427,291.041962,14.826384,0.964270,-159.597656,294.500488,0.000000
106.190002,65.384132,-159.775574,-0.001272,0.003796,0.096427,290.843140,14.816257,0.964270,-159.775574,294.500488,0.000000
106.580002,65.361046,-159.731094,-0.001268,0.003796,0.096427,290.740448,14.811025,0.964270,-159.731094,294.500488,0.000000
106.970009,65.326424,-159.775574,-0.001272,0.003796,0.096427,290.586456,14.803180,0.964270,-159.775574,294.500488,0.000000
107.360008,65.295143,-159.909012,-0.001268,0.003797,0.096444,290.447296,14.796091,0.964437,-159.909012,294.500488,0.000000
107.750008,65.291420,-159.820053,-0.001272,0.003797,0.096453,290.430756,14.795248,0.964527,-159.820053,294.500488,0.000000
108.140007,65.272423,-159.953506,-0.001285,0.003798,0.096471,290.346252,14.790943,0.964709,-159.953506,294.500488,0.000000
108.530006,65.271309,-159.953506,-0.001255,0.003799,0.096488,290.341278,14.790690,0.964876,-159.953506,294.500488,0.000000
108.920006,65.264977,-159.997986,-0.001263,0.003799,0.096488,290.313110,14.789255,0.964876,-159.997986,294.500488,0.000000
109.310005,65.253807,-160.086945,-0.001276,0.003799,0.096504,290.263428,14.786724,0.965042,-160.086945,294.500488,0.000000
109.700005,65.257149,-160.042465,-0.001259,0.003799,0.096504,290.278290,14.787481,0.965042,-160.042465,294.500488,0.000000
110.090004,65.266090,-160.175903,-0.001263,0.003800,0.096531,290.318085,14.789508,0.965315,-160.175903,294.500488,0.000000
110.480003,65.306679,-160.175903,-0.001276,0.003801,0.096539,290.498627,14.798705,0.965390,-160.175903,294.500488,0.000000
110.870003,65.301460,-160.220383,-0.001276,0.003801,0.096548,290.475403,14.797522,0.965481,-160.220383,294.500488,0.000000
111.260002,65.301094,-160.264862,-0.001272,0.003801,0.096548,290.473785,14.797440,0.965481,-160.264862,294.500488,0.000000
111.650002,65.293282,-160.264862,-0.001268,0.003802,0.096566,290.439026,14.795669,0.965663,-160.264862,294.500488,0.000000
112.040009,65.280983,-160.398315,-0.001268,0.003802,0.096566,290.384308,14.792882,0.965663,-160.398315,294.500488,0.000000
112.430008,65.296257,-160.398315,-0.001268,0.003803,0.096592,290.452271,14.796344,0.965920,-160.398315,294.500488,0.000000
112.820007,65.294395,-160.442795,-0.001272,0.003803,0.096592,290.443970,14.795921,0.965920,-160.442795,294.500488,0.000000
113.210007,65.287315,-160.487274,-0.001259,0.003803,0.096600,290.412476,14.794317,0.965996,-160.487274,294.500488,0.000000
113.600006,65.278755,-160.487274,-0.001268,0.003803,0.096600,290.374420,14.792377,0.965996,-160.487274,294.500488,0.000000
113.990005,65.266457,-160.576233,-0.001272,0.003804,0.096618,290.319702,14.789590,0.966178,-160.576233,294.500488,0.000000
114.380005,65.275032,-160.576233,-0.001250,0.003804,0.096618,290.357849,14.791533,0.966178,-160.576233,294.500488,0.000000
114.770004,65.276894,-160.620712,-0.001272,0.003805,0.096634,290.366119,14.791956,0.966344,-160.620712,294.500488,0.000000
115.160004,65.278755,-160.754150,-0.001263,0.003805,0.096634,290.374420,14.792377,0.966344,-160.754150,294.500488,0.000000
115.550003,65.263481,-160.754150,-0.001259,0.003805,0.096644,290.306458,14.788917,0.966435,-160.754150,294.500488,0.000000
115.940002,65.278008,-160.709671,-0.001259,0.003805,0.096653,290.371094,14.792209,0.966526,-160.709671,294.500488,0.000000
116.330002,65.267204,-160.843124,-0.001255,0.003805,0.096653,290.323029,14.789760,0.966526,-160.843124,294.500488,0.000000
116.720009,65.250832,-160.843124,-0.001263,0.003806,0.096669,290.250183,14.786049,0.966692,-160.843124,294.500488,0.000000
117.110008,65.267952,-160.976562,-0.001276,0.003807,0.096687,290.326355,14.789929,0.966874,-160.976562,294.500488,0.000000
117.500008,65.281731,-160.932083,-0.001263,0.003807,0.096687,290.387634,14.793052,0.966874,-160.932083,294.500488,0.000000
117.890007,65.262733,-160.976562,-0.001268,0.003807,0.096687,290.303131,14.788747,0.966874,-160.976562,294.500488,0.000000
118.280006,65.263115,-161.065521,-0.001268,0.003807,0.096695,290.304840,14.788833,0.966950,-161.065521,294.500488,0.000000
118.670006,65.254173,-161.065521,-0.001259,0.003807,0.096695,290.265045,14.786807,0.966950,-161.065521,294.500488,0.000000
119.060005,65.279869,-161.110001,-0.001263,0.003807,0.096695,290.379364,14.792629,0.966950,-161.110001,294.500488,0.000000
119.450005,65.250084,-161.243454,-0.001242,0.003807,0.096695,290.246857,14.785880,0.966950,-161.243454,294.500488,0.000000
119.840004,65.242638,-161.243454,-0.001259,0.003808,0.096730,290.213745,14.784193,0.967298,-161.243454,294.500488,0.000000
120.230003,65.342049,-161.287933,-0.001250,0.003809,0.096757,290.655945,14.806720,0.967571,-161.287933,294.500488,0.000000
120.620003,65.342430,-161.287933,-0.001250,0.003809,0.096757,290.657654,14.806807,0.967571,-161.287933,294.500488,0.000000
121.010002,65.323814,-161.287933,-0.001259,0.003809,0.096757,290.574829,14.802588,0.967571,-161.287933,294.500488,0.000000
121.400009,65.326042,-161.376892,-0.001250,0.003809,0.096757,290.584747,14.803092,0.967571,-161.376892,294.500488,0.000000
121.790009,65.298119,-161.421371,-0.001268,0.003809,0.096757,290.460541,14.796765,0.967571,-161.421371,294.500488,0.000000
122.180008,65.288811,-161.510330,-0.001263,0.003809,0.096757,290.419128,14.794656,0.967571,-161.510330,294.500488,0.000000
122.570007,65.282845,-161.510330,-0.001259,0.003810,0.096765,290.392609,14.793304,0.967646,-161.510330,294.500488,0.000000
122.960007,65.255669,-161.554810,-0.001268,0.003810,0.096765,290.271698,14.787147,0.967646,-161.554810,294.500488,0.000000
123.350006,65.244499,-161.599289,-0.001246,0.003810,0.096765,290.222015,14.784615,0.967646,-161.599289,294.500488,0.000000
123.740005,65.286568,-161.643784,-0.001272,0.003812,0.096825,290.409149,14.794147,0.968252,-161.643784,294.500488,0.000000
124.130005,65.336098,-161.777222,-0.001255,0.003812,0.096834,290.629486,14.805371,0.968343,-161.777222,1681.640991,0.000000
124.520004,65.237419,-161.732742,-0.001242,0.003801,0.096557,290.190521,14.783010,0.965572,-161.732742,0.096357,0.000000
124.910004,65.181557,-161.821701,-0.001255,0.003780,0.096002,289.942047,14.770352,0.960016,-161.821701,0.095706,0.000000
125.300003,65.173378,-161.866180,-0.001237,0.003760,0.095516,289.905670,14.768499,0.955156,-161.866180,0.095057,0.000000
125.690002,65.148796,-161.866180,-0.001242,0.003734,0.094840,289.796326,14.762929,0.948404,-161.866180,0.094406,0.000000
126.080009,65.069847,-161.955139,-0.001237,0.003711,0.094259,289.445129,14.745038,0.942590,-161.955139,0.093756,0.000000
126.470009,65.070229,-161.955139,-0.001237,0.003687,0.093661,289.446838,14.745125,0.936610,-161.955139,0.093105,0.000000
126.860008,64.989418,-162.044098,-0.001237,0.003661,0.093001,289.087372,14.726813,0.930009,-162.044098,0.092454,0.000000
127.250008,64.952187,-162.088593,-0.001237,0.003633,0.092282,288.921753,14.718376,0.922818,-162.088593,0.091805,0.000000
127.640007,64.949196,-162.088593,-0.001233,0.003608,0.091649,288.908447,14.717698,0.916490,-162.088593,0.091154,0.000000
128.029999,64.888878,-162.177551,-0.001242,0.003582,0.090989,288.640137,14.704030,0.909889,-162.177551,0.090504,0.000000
128.420013,64.791313,-162.133072,-0.001229,0.003557,0.090339,288.206146,14.681921,0.903394,-162.133072,0.089862,0.000000
128.810013,64.573845,-162.266510,-0.001233,0.003537,0.089835,287.238800,14.632643,0.898352,-162.266510,0.089211,0.000000
129.200012,63.568077,-162.266510,-0.001224,0.003510,0.089151,282.764923,14.404733,0.891509,-162.266510,0.088560,0.000000
129.590012,62.406273,-162.310989,-0.001224,0.003490,0.088648,277.596954,14.141464,0.886483,-162.310989,0.087911,0.000000
129.980011,61.123077,-162.399948,-0.001216,0.003468,0.088076,271.889038,13.850687,0.880760,-162.399948,0.087260,0.000000
130.370010,58.740265,-162.444427,-0.001207,0.003436,0.087269,261.289734,13.310734,0.872691,-162.444427,0.086611,0.000000
130.760010,57.601547,-162.444427,-0.001199,0.003424,0.086957,256.224487,13.052697,0.869572,-162.444427,0.085960,0.000000
131.150009,55.338638,-162.488907,-0.001194,0.003400,0.086358,246.158554,12.539915,0.863577,-162.488907,0.085308,0.000000
131.540009,52.573402,-162.488907,-0.001199,0.003371,0.085629,233.858170,11.913303,0.856295,-162.488907,0.084659,0.000000
131.930008,49.797737,-162.622360,-0.001207,0.003345,0.084962,221.511398,11.284328,0.849618,-162.622360,0.084008,0.000000
132.320007,46.244186,-162.622360,-0.001199,0.003313,0.084138,205.704422,10.479083,0.841382,-162.622360,0.083357,0.000000
132.710007,44.294449,-162.622360,-0.001199,0.003298,0.083757,197.031555,10.037266,0.837567,-162.622360,0.082708,0.000000
133.100006,41.206734,-162.666840,-0.001194,0.003266,0.082959,183.296707,9.337580,0.829588,-162.666840,0.082057,0.000000
133.490005,38.644066,-162.755798,-0.001190,0.003245,0.082421,171.897385,8.756870,0.824214,-162.755798,0.081407,0.000000
133.880005,35.652054,-162.844757,-0.001212,0.003218,0.081728,158.588257,8.078871,0.817280,-162.844757,0.080756,0.000000
134.270004,32.268303,-162.800278,-0.001186,0.003185,0.080903,143.536575,7.312102,0.809029,-162.800278,0.080105,0.000000
134.660004,30.254890,-162.844757,-0.001194,0.003169,0.080496,134.580475,6.855856,0.804956,-162.844757,0.079456,0.000000
135.050003,29.051010,-162.978210,-0.001199,0.003159,0.080235,129.225342,6.583053,0.802352,-162.978210,0.078805,0.000000
135.440002,24.997360,-162.978210,-0.001194,0.003121,0.079274,111.193810,5.664483,0.792739,-162.978210,0.078155,0.000000
135.830002,22.029556,-163.022690,-0.001199,0.003091,0.078518,97.992363,4.991969,0.785184,-163.022690,0.077504,0.000000
136.220001,18.615273,-163.067169,-0.001181,0.003060,0.077730,82.804871,4.218281,0.777296,-163.067169,0.076853,0.000000
136.610001,17.260582,-163.111649,-0.001199,0.003047,0.077390,76.778900,3.911304,0.773905,-163.111649,0.076204,0.000000
137.000000,14.240265,-163.156128,-0.001207,0.003021,0.076732,63.343861,3.226890,0.767319,-163.156128,0.075553,0.000000
137.389999,11.407631,-163.200607,-0.001186,0.002994,0.076055,50.743675,2.585006,0.760552,-163.200607,0.074911,0.000000
137.780014,8.523232,-163.245087,-0.001203,0.002965,0.075301,37.913227,1.931392,0.753012,-163.245087,0.074261,0.000000
138.170013,5.617233,-163.334045,-0.001190,0.002938,0.074625,24.986702,1.272883,0.746245,-163.334045,0.073610,0.000000
138.560013,3.015846,-163.289566,-0.001190,0.002913,0.073983,13.415154,0.683401,0.739826,-163.289566,0.072959,0.000000
138.950012,0.099052,-163.378540,-0.001199,0.002884,0.073245,0.440607,0.022446,0.732453,-163.378540,0.072310,0.000000
139.340012,-2.100555,-163.378540,-0.001207,0.002864,0.072752,-9.343738,-0.475993,0.727517,-163.378540,0.071659,0.000000
139.730011,-4.664341,-163.423019,-0.001199,0.002835,0.072014,-20.748024,-1.056955,0.720144,-163.423019,0.071009,0.000000
140.120010,-0.211884,-163.511978,-0.001199,0.002802,0.071173,-0.942505,-0.048013,0.711727,-163.511978,0.070358,0.000000
140.510010,-0.069260,-163.556458,-0.001203,0.002784,0.070705,-0.308082,-0.015694,0.707049,-163.556458,0.069707,0.000000
140.900009,-0.053993,-163.600937,-0.001190,0.002759,0.070072,-0.240174,-0.012235,0.700720,-163.600937,0.069058,0.000000
141.290009,-0.023834,-163.645416,-0.001207,0.002738,0.069551,-0.106020,-0.005401,0.695512,-163.645416,0.068407,0.000000
141.680008,-0.059578,-163.645416,-0.001212,0.002707,0.068762,-0.265016,-0.013501,0.687625,-163.645416,0.067756,0.000000
142.070007,-0.037987,-163.689896,-0.001203,0.002682,0.068130,-0.168974,-0.008608,0.681296,-163.689896,0.067106,0.000000
142.460007,-0.019737,-163.734375,-0.001203,0.002663,0.067635,-0.087796,-0.004473,0.676346,-163.734375,0.066455,0.000000
142.850006,-0.037613,-163.867828,-0.001207,0.002632,0.066846,-0.167311,-0.008523,0.668458,-163.867828,0.065806,0.000000
143.240005,-0.075966,-163.823349,-0.001216,0.002604,0.066134,-0.337913,-0.017214,0.661342,-163.823349,0.065155,0.000000
143.630005,-0.075218,-163.956787,-0.001220,0.002577,0.065457,-0.334587,-0.017045,0.654575,-163.956787,0.064504,0.000000
144.020004,-0.037613,-163.956787,-0.001229,0.002555,0.064885,-0.167311,-0.008523,0.648852,-163.956787,0.063854,0.000000
144.410004,-0.012665,-164.001266,-0.001233,0.002535,0.064401,-0.056336,-0.002870,0.644007,-164.001266,0.063203,0.000000
144.800003,-0.040215,-164.090225,-0.001263,0.002511,0.063785,-0.178883,-0.009113,0.637846,-164.090225,0.062554,0.000000
145.190002,-0.050644,-164.045746,-0.001276,0.002485,0.063117,-0.225275,-0.011476,0.631169,-164.045746,0.061903,0.000000
145.580002,-0.098305,-164.090225,-0.001341,0.002452,0.062293,-0.437281,-0.022276,0.622933,-164.090225,0.061252,0.000000
145.970001,-0.055115,-164.179184,-0.001367,0.002425,0.061591,-0.245163,-0.012489,0.615908,-164.179184,0.060602,0.000000
146.360001,-0.051392,-164.179184,-0.001393,0.002402,0.061000,-0.228601,-0.011646,0.610004,-164.179184,0.059951,0.000000
146.750000,-0.042084,-164.223679,-0.001423,0.002380,0.060454,-0.187198,-0.009536,0.604539,-164.223679,0.059309,0.000000
147.139999,-0.077080,-164.268158,-0.001444,0.002350,0.059691,-0.342868,-0.017467,0.596908,-164.268158,0.058660,0.000000
147.530014,-0.060699,-164.312637,-0.001470,0.002321,0.058963,-0.270005,-0.013755,0.589626,-164.312637,0.058009,0.000000
147.920013,-0.089371,-164.357117,-0.001500,0.002298,0.058374,-0.397541,-0.020252,0.583737,-164.357117,0.057358,0.000000
148.310013,-0.068893,-164.401596,-0.001518,0.002280,0.057923,-0.306453,-0.015611,0.579225,-164.401596,0.056708,0.000000
148.700012,-0.077454,-164.535034,-0.001552,0.002245,0.057020,-0.344531,-0.017551,0.570202,-164.535034,0.056057,0.000000
149.090012,-0.058838,-164.401596,-0.001587,0.002218,0.056327,-0.261724,-0.013333,0.563268,-164.401596,0.055406,0.000000
149.480011,-0.062561,-164.535034,-0.001621,0.002193,0.055711,-0.278285,-0.014177,0.557106,-164.535034,0.054757,0.000000
149.870010,-0.045059,-164.623993,-0.001656,0.002167,0.055052,-0.200433,-0.010211,0.550521,-164.623993,0.054106,0.000000
150.260010,-0.045433,-164.579514,-0.001664,0.002150,0.054601,-0.202096,-0.010295,0.546009,-164.579514,0.053456,0.000000
150.650009,-0.047668,-164.668488,-0.001703,0.002116,0.053742,-0.212040,-0.010802,0.537425,-164.668488,0.052805,0.000000
151.040009,-0.088997,-164.668488,-0.001720,0.002090,0.053082,-0.395878,-0.020167,0.530824,-164.668488,0.052154,0.000000
151.430008,-0.104637,-164.757446,-0.001755,0.002066,0.052484,-0.465449,-0.023711,0.524844,-164.757446,0.051505,0.000000
151.820007,-0.098679,-164.757446,-0.001785,0.002034,0.051670,-0.438944,-0.022361,0.516699,-164.757446,0.050854,0.000000
152.210007,-0.068520,-164.846405,-0.001802,0.002023,0.051391,-0.304790,-0.015527,0.513913,-164.846405,0.050204,0.000000
152.600006,-0.070755,-164.935364,-0.001832,0.001988,0.050498,-0.314734,-0.016033,0.504981,-164.935364,0.049553,0.000000
152.990005,-0.094955,-164.890884,-0.001850,0.001961,0.049814,-0.422383,-0.021517,0.498138,-164.890884,0.048902,0.000000
153.380005,-0.089371,-165.024323,-0.001888,0.001938,0.049216,-0.397541,-0.020252,0.492157,-165.024323,0.048253,0.000000
153.770004,-0.072990,-164.979843,-0.001910,0.001909,0.048495,-0.324678,-0.016540,0.484951,-164.979843,0.047602,0.000000
154.160004,-0.075592,-165.024323,-0.001936,0.001886,0.047914,-0.336250,-0.017129,0.479137,-165.024323,0.046951,0.000000
154.550003,-0.078201,-165.113297,-0.001962,0.001862,0.047290,-0.347857,-0.017721,0.472900,-165.113297,0.046301,0.000000
154.940002,-0.114693,-165.113297,-0.001983,0.001838,0.046692,-0.510179,-0.025990,0.466920,-165.113297,0.045650,0.000000
155.330002,-0.129585,-165.202255,-0.002018,0.001812,0.046032,-0.576424,-0.029364,0.460319,-165.202255,0.045001,0.000000
155.720001,-0.086395,-165.202255,-0.002039,0.001779,0.045199,-0.384305,-0.019577,0.451992,-165.202255,0.044359,0.000000
156.110001,-0.099800,-165.202255,-0.002070,0.001772,0.045018,-0.443933,-0.022615,0.450175,-165.202255,0.043708,0.000000
156.500000,-0.081924,-165.380173,-0.002091,0.001731,0.043977,-0.364418,-0.018564,0.439775,-165.380173,0.043058,0.000000
156.890015,-0.108734,-165.380173,-0.002108,0.001711,0.043466,-0.483674,-0.024640,0.434657,-165.380173,0.042407,0.000000
157.280014,-0.091232,-165.469131,-0.002156,0.001687,0.042850,-0.405822,-0.020674,0.428496,-165.469131,0.041756,0.000000
157.670013,-0.067398,-165.469131,-0.002195,0.001656,0.042052,-0.299802,-0.015273,0.420517,-165.469131,0.041107,0.000000
158.060013,-0.068520,-165.513626,-0.002203,0.001638,0.041610,-0.304790,-0.015527,0.416096,-165.513626,0.040456,0.000000
158.450012,-0.070007,-165.647064,-0.002242,0.001603,0.040707,-0.311408,-0.015864,0.407073,-165.647064,0.039805,0.000000
158.700012,-0.052132,-165.602585,-0.002233,0.001600,0.040638,-0.231893,-0.011813,0.406377,-165.602585,0.040542,0.000000