File: Data/compression 27/AutoNoHeating-17-27-reverse-1-4_10162024_170625.csv
Time (sec),S:Load (lbs),S:HL1 (DIM),S:LVDT (in),S:Position (in),Ch:Position (mm),Ch:Load (N),Ch:Stress (MPa),Ch:Strain (mm/mm),Ch:HL1 (DIM),Set Point (),Cycles ()
0.110000,0.040588,-120.943703,-0.005338,-0.005490,-0.139458,0.180546,0.009197,-1.394582,-120.943703,-0.139260,0.000000
0.460000,0.061813,-120.899223,-0.005338,-0.005428,-0.137863,0.274960,0.014007,-1.378625,-120.899223,-0.137195,0.000000
0.810000,0.032768,-121.032669,-0.005230,-0.005217,-0.132521,0.145760,0.007425,-1.325213,-121.032669,-0.131368,0.000000
1.160000,0.061066,-121.032669,-0.005006,-0.004991,-0.126771,0.271634,0.013838,-1.267713,-121.032669,-0.125540,0.000000
1.510000,0.101280,-121.121628,-0.004777,-0.000000,-0.000009,0.450517,0.022950,-0.000091,-121.121628,0.001440,0.000000
1.860000,0.046913,-121.121628,-0.004773,-0.000001,-0.000018,0.208680,0.010631,-0.000182,-121.121628,0.000207,0.000000
2.210000,0.086388,-121.210594,-0.004769,-0.000001,-0.000018,0.384271,0.019576,-0.000182,-121.210594,0.000521,0.000000
2.560000,0.096817,-121.299553,-0.004777,-0.000000,-0.000009,0.430664,0.021939,-0.000091,-121.299553,0.001101,0.000000
2.910000,0.151184,-121.299553,-0.004773,0.000029,0.000737,0.672500,0.034259,0.007373,-121.299553,0.001682,0.000000
3.260000,0.196236,-121.388512,-0.004764,0.000055,0.001387,0.872900,0.044468,0.013868,-121.388512,0.002263,0.000000
3.610000,0.196236,-121.521957,-0.004734,0.000075,0.001908,0.872900,0.044468,0.019076,-121.521957,0.002852,0.000000
3.960000,0.259911,-121.521957,-0.004708,0.000094,0.002394,1.156140,0.058897,0.023936,-121.521957,0.003434,0.000000
4.310000,0.421898,-121.566437,-0.004691,0.000122,0.003105,1.876696,0.095603,0.031051,-121.566437,0.004015,0.000000
4.660000,0.541801,-121.566437,-0.004674,0.000138,0.003512,2.410053,0.122774,0.035124,-121.566437,0.004596,0.000000
5.010000,0.671387,-121.610924,-0.004648,0.000157,0.003998,2.986477,0.152138,0.039984,-121.610924,0.005185,0.000000
5.360000,0.931671,-121.699883,-0.004618,0.000192,0.004883,4.144280,0.211120,0.048825,-121.699883,0.005767,0.000000
5.710000,1.105202,-121.744362,-0.004596,0.000214,0.005437,4.916183,0.250442,0.054366,-121.744362,0.006348,0.000000
6.060000,1.308144,-121.744362,-0.004579,0.000233,0.005923,5.818913,0.296430,0.059226,-121.744362,0.006929,0.000000
6.410000,1.756104,-121.788841,-0.004553,0.000261,0.006634,7.811539,0.397939,0.066342,-121.788841,0.007518,0.000000
6.760000,1.924416,-121.922287,-0.004540,0.000276,0.006999,8.560228,0.436079,0.069990,-121.922287,0.008100,0.000000
7.110000,2.403290,-122.011246,-0.004518,0.000304,0.007727,10.690367,0.544593,0.077272,-122.011246,0.008681,0.000000
7.460001,2.720924,-122.055733,-0.004506,0.000329,0.008369,12.103276,0.616570,0.083692,-122.055733,0.009270,0.000000
7.810000,2.939880,-122.011246,-0.004467,0.000348,0.008837,13.077241,0.666186,0.088370,-122.011246,0.009851,0.000000
8.160001,3.401619,-122.100212,-0.004449,0.000374,0.009505,15.131157,0.770818,0.095046,-122.100212,0.010433,0.000000
8.510000,3.582596,-122.233650,-0.004437,0.000394,0.009998,15.936182,0.811828,0.099982,-122.233650,0.011014,0.000000
8.860001,3.876770,-122.144691,-0.004428,0.000411,0.010433,17.244734,0.878489,0.104327,-122.144691,0.011603,0.000000
9.210000,4.444260,-122.278137,-0.004398,0.000443,0.011240,19.769054,1.007084,0.112396,-122.278137,0.012184,0.000000
9.560000,4.582787,-122.322617,-0.004381,0.000461,0.011717,20.385252,1.038474,0.117165,-122.322617,0.012766,0.000000
9.910001,5.018089,-122.367096,-0.004337,0.000487,0.012375,22.321575,1.137115,0.123751,-122.367096,0.013347,0.000000
10.260000,5.396049,-122.411575,-0.004342,0.000513,0.013026,24.002827,1.222762,0.130261,-122.411575,0.013936,0.000000
10.610001,5.598991,-122.411575,-0.004316,0.000531,0.013485,24.905558,1.268750,0.134848,-122.411575,0.014517,0.000000
10.960001,6.103554,-122.545021,-0.004294,0.000559,0.014205,27.149963,1.383085,0.142055,-122.545021,0.015099,0.000000
11.310000,6.244682,-122.633980,-0.004277,0.000580,0.014734,27.777735,1.415065,0.147338,-122.633980,0.015688,0.000000
11.660001,6.398476,-122.633980,-0.004255,0.000602,0.015297,28.461842,1.449915,0.152970,-122.633980,0.016269,0.000000
12.010000,6.579445,-122.678467,-0.004238,0.000624,0.015844,29.266832,1.490924,0.158436,-122.678467,0.016850,0.000000
12.360001,6.884048,-122.722946,-0.004204,0.000647,0.016434,30.621777,1.559948,0.164340,-122.722946,0.017432,0.000000
12.710001,6.974533,-122.722946,-0.004195,0.000664,0.016876,31.024273,1.580452,0.168761,-122.722946,0.018021,0.000000
13.060000,7.427711,-122.856384,-0.004174,0.000694,0.017639,33.040112,1.683143,0.176391,-122.856384,0.018602,0.000000
13.410001,7.567352,-122.900871,-0.004143,0.000717,0.018220,33.661263,1.714787,0.182205,-122.900871,0.019183,0.000000
13.760000,7.594536,-122.900871,-0.004126,0.000739,0.018775,33.782181,1.720946,0.187746,-122.900871,0.019763,0.000000
14.110001,7.810135,-122.989830,-0.004100,0.000759,0.019279,34.741215,1.769802,0.192787,-122.989830,0.020354,0.000000
14.460001,7.848495,-123.034309,-0.004070,0.000781,0.019833,34.911850,1.778494,0.198328,-123.034309,0.020935,0.000000
14.810000,7.911797,-123.078789,-0.004061,0.000796,0.020207,35.193428,1.792839,0.202068,-123.078789,0.021516,0.000000
15.160001,8.386200,-123.167755,-0.004018,0.000832,0.021126,37.303680,1.900340,0.211258,-123.167755,0.022096,0.000000
15.510001,8.394394,-123.167755,-0.004023,0.000850,0.021603,37.340130,1.902197,0.216027,-123.167755,0.022687,0.000000
15.860001,8.592491,-123.256714,-0.003975,0.000874,0.022201,38.221310,1.947086,0.222007,-123.256714,0.023268,0.000000
16.210001,8.672928,-123.301193,-0.003954,0.000896,0.022756,38.579109,1.965314,0.227563,-123.301193,0.023848,0.000000
16.560001,8.706810,-123.345680,-0.003949,0.000914,0.023224,38.729824,1.972991,0.232241,-123.345680,0.024438,0.000000
16.910002,9.264252,-123.390160,-0.003902,0.000949,0.024101,41.209450,2.099309,0.241007,-123.390160,0.025020,0.000000
17.260000,9.147331,-123.390160,-0.003902,0.000970,0.024638,40.689362,2.072815,0.246382,-123.390160,0.025601,0.000000
17.610001,9.066521,-123.479118,-0.003867,0.000986,0.025036,40.329899,2.054503,0.250363,-123.479118,0.026181,0.000000
17.960001,9.354736,-123.479118,-0.003854,0.001012,0.025704,41.611946,2.119813,0.257040,-123.479118,0.026771,0.000000
18.310001,9.327187,-123.612564,-0.003829,0.001029,0.026129,41.489399,2.113571,0.261294,-123.612564,0.027353,0.000000
18.660002,9.363678,-123.657043,-0.003824,0.001048,0.026623,41.651718,2.121840,0.266230,-123.657043,0.027933,0.000000
19.010000,9.982933,-123.701523,-0.003773,0.001085,0.027560,44.406303,2.262165,0.275601,-123.701523,0.028514,0.000000
19.360001,9.831001,-123.790489,-0.003760,0.001105,0.028055,43.730476,2.227737,0.280552,-123.790489,0.029104,0.000000
19.710001,9.930428,-123.790489,-0.003742,0.001123,0.028523,44.172749,2.250267,0.285230,-123.790489,0.029684,0.000000
20.060001,10.279343,-123.879448,-0.003704,0.001153,0.029277,45.724800,2.329332,0.292769,-123.879448,0.030266,0.000000
20.410002,10.221992,-123.879448,-0.003686,0.001172,0.029763,45.469692,2.316337,0.297629,-123.879448,0.030856,0.000000
20.760000,10.661018,-123.923927,-0.003669,0.001202,0.030526,47.422577,2.415821,0.305259,-123.923927,0.031437,0.000000
21.110001,10.493454,-123.968414,-0.003635,0.001221,0.031003,46.677216,2.377851,0.310028,-123.968414,0.032017,0.000000
21.460001,10.451752,-124.057373,-0.003626,0.001242,0.031558,46.491714,2.368401,0.315585,-124.057373,0.032599,0.000000
21.810001,10.767891,-124.057373,-0.003600,0.001268,0.032200,47.897972,2.440039,0.322004,-124.057373,0.033189,0.000000
22.160002,10.758957,-124.146332,-0.003591,0.001287,0.032677,47.858231,2.438015,0.326773,-124.146332,0.033769,0.000000
22.510000,10.796196,-124.235298,-0.003544,0.001309,0.033240,48.023880,2.446453,0.332405,-124.235298,0.034350,0.000000
22.860001,11.231865,-124.279778,-0.003527,0.001337,0.033960,49.961830,2.545177,0.339596,-124.279778,0.034932,0.000000
23.210001,11.213249,-124.324257,-0.003492,0.001358,0.034499,49.879025,2.540958,0.344986,-124.324257,0.035522,0.000000
23.560001,11.303368,-124.368736,-0.003497,0.001381,0.035087,50.279892,2.561380,0.350875,-124.368736,0.036102,0.000000
23.910002,11.580406,-124.457703,-0.003471,0.001404,0.035669,51.512218,2.624158,0.356688,-124.457703,0.036683,0.000000
24.260000,11.671265,-124.457703,-0.003441,0.001424,0.036181,51.916378,2.644746,0.361806,-124.457703,0.037265,0.000000
24.610001,12.160934,-124.502182,-0.003419,0.001455,0.036953,54.094540,2.755707,0.369527,-124.502182,0.037853,0.000000
24.960001,12.069710,-124.546661,-0.003397,0.001477,0.037507,53.688751,2.735035,0.375068,-124.546661,0.038435,0.000000
25.310001,11.980339,-124.591141,-0.003367,0.001495,0.037967,53.291210,2.714784,0.379670,-124.591141,0.039016,0.000000
25.660002,12.475967,-124.635628,-0.003341,0.001524,0.038721,55.495876,2.827095,0.387210,-124.635628,0.039607,0.000000
26.010002,12.223869,-124.680107,-0.003316,0.001537,0.039033,54.374485,2.769969,0.390329,-124.680107,0.040186,0.000000
26.360001,12.680771,-124.724586,-0.003303,0.001569,0.039849,56.406887,2.873504,0.398489,-124.724586,0.040768,0.000000
26.710001,12.917595,-124.769066,-0.003268,0.001592,0.040438,57.460331,2.927169,0.404378,-124.769066,0.041349,0.000000
27.060001,12.862488,-124.902512,-0.003260,0.001614,0.041003,57.215202,2.914681,0.410025,-124.902512,0.041938,0.000000
27.410002,12.874031,-124.902512,-0.003251,0.001634,0.041496,57.266552,2.917297,0.414961,-124.902512,0.042520,0.000000
27.760002,13.311569,-124.902512,-0.003208,0.001659,0.042147,59.212818,3.016445,0.421471,-124.902512,0.043101,0.000000
28.110001,13.164482,-124.946991,-0.003203,0.001674,0.042529,58.558540,2.983114,0.425286,-124.946991,0.043682,0.000000
28.460001,13.707031,-125.035950,-0.003173,0.001705,0.043308,60.971920,3.106058,0.433083,-125.035950,0.044271,0.000000
28.810001,13.963593,-125.080437,-0.003152,0.001729,0.043915,62.113163,3.164195,0.439154,-125.080437,0.044853,0.000000
29.160002,13.855606,-125.169395,-0.003122,0.001748,0.044410,61.632812,3.139725,0.444104,-125.169395,0.045434,0.000000
29.510002,14.224998,-125.213875,-0.003122,0.001773,0.045034,63.275955,3.223431,0.450342,-125.213875,0.046023,0.000000
29.860001,14.118126,-125.213875,-0.003096,0.001790,0.045478,62.800560,3.199213,0.454778,-125.213875,0.046604,0.000000
30.210001,14.238029,-125.347321,-0.003074,0.001812,0.046015,63.333920,3.226384,0.460152,-125.347321,0.047186,0.000000
30.560001,14.756744,-125.302841,-0.003035,0.001842,0.046778,65.641281,3.343926,0.467783,-125.302841,0.047767,0.000000
30.910002,14.715782,-125.391800,-0.003027,0.001863,0.047332,65.459068,3.334644,0.473324,-125.391800,0.048356,0.000000
31.260002,15.025970,-125.436279,-0.003005,0.001886,0.047897,66.838852,3.404933,0.478971,-125.436279,0.048937,0.000000
31.610001,15.336533,-125.480766,-0.002975,0.001914,0.048607,68.220306,3.475308,0.486071,-125.480766,0.049519,0.000000
31.960001,15.371536,-125.569725,-0.002958,0.001931,0.049051,68.376007,3.483240,0.490507,-125.569725,0.050100,0.000000
32.310001,16.001587,-125.614204,-0.002940,0.001960,0.049796,71.178612,3.626012,0.497956,-125.614204,0.050689,0.000000
32.660000,15.949829,-125.703171,-0.002910,0.001982,0.050351,70.948380,3.614283,0.503512,-125.703171,0.051270,0.000000
33.010002,16.099518,-125.658684,-0.002876,0.002002,0.050863,71.614235,3.648203,0.508629,-125.658684,0.051852,0.000000
33.360001,16.259644,-125.703171,-0.002876,0.002024,0.051417,72.326508,3.684488,0.514170,-125.703171,0.052433,0.000000
33.710003,16.542648,-125.881088,-0.002846,0.002047,0.051989,73.585373,3.748618,0.519893,-125.881088,0.053022,0.000000
34.060001,16.464821,-125.836609,-0.002824,0.002063,0.052398,73.239182,3.730982,0.523981,-125.836609,0.053603,0.000000
34.410000,17.257973,-125.925575,-0.002807,0.002097,0.053257,76.767296,3.910712,0.532565,-125.925575,0.054185,0.000000
34.760002,17.270630,-125.970055,-0.002781,0.002120,0.053838,76.823601,3.913581,0.538379,-125.970055,0.054773,0.000000
35.110001,17.437080,-126.014534,-0.002764,0.002140,0.054366,77.564011,3.951299,0.543662,-126.014534,0.055355,0.000000
35.460003,17.492195,-126.103493,-0.002751,0.002161,0.054878,77.809174,3.963788,0.548779,-126.103493,0.055936,0.000000
35.810001,17.462029,-126.103493,-0.002716,0.002178,0.055320,77.674980,3.956952,0.553200,-126.103493,0.056518,0.000000
36.160000,17.771843,-126.192459,-0.002716,0.002205,0.056006,79.053108,4.027157,0.560058,-126.192459,0.057106,0.000000
36.510002,18.577286,-126.236938,-0.002686,0.002231,0.056655,82.635895,4.209673,0.566553,-126.236938,0.057688,0.000000
36.860001,18.681183,-126.370384,-0.002656,0.002255,0.057272,83.098053,4.233216,0.572715,-126.370384,0.058269,0.000000
37.210003,18.976471,-126.325897,-0.002634,0.002273,0.057723,84.411560,4.300130,0.577227,-126.325897,0.058849,0.000000
37.560001,19.457947,-126.370384,-0.002617,0.002300,0.058425,86.553268,4.409234,0.584252,-126.370384,0.059440,0.000000
37.910004,19.426666,-126.459343,-0.002604,0.002317,0.058849,86.414131,4.402145,0.588491,-126.459343,0.060021,0.000000
38.260002,20.442505,-126.459343,-0.002578,0.002349,0.059656,90.932800,4.632338,0.596560,-126.459343,0.060602,0.000000
38.610001,20.480858,-126.548309,-0.002552,0.002372,0.060237,91.103409,4.641029,0.602374,-126.548309,0.061182,0.000000
38.960003,20.218704,-126.592789,-0.002535,0.002386,0.060610,89.937286,4.581624,0.606098,-126.592789,0.061773,0.000000
39.310001,20.918396,-126.592789,-0.002505,0.002414,0.061305,93.049675,4.740176,0.613047,-126.592789,0.062354,0.000000
39.660004,20.764977,-126.681747,-0.002501,0.002429,0.061703,92.367226,4.705411,0.617029,-126.681747,0.062934,0.000000
40.010002,21.485146,-126.770714,-0.002479,0.002459,0.062466,95.570702,4.868604,0.624659,-126.770714,0.063524,0.000000
40.360001,22.155045,-126.815193,-0.002458,0.002484,0.063099,98.550560,5.020405,0.630987,-126.815193,0.064106,0.000000
40.710003,22.138283,-126.859673,-0.002436,0.002504,0.063610,98.475998,5.016606,0.636105,-126.859673,0.064687,0.000000
41.060001,22.388519,-126.859673,-0.002414,0.002524,0.064113,99.589111,5.073311,0.641131,-126.859673,0.065267,0.000000
41.410004,23.090439,-126.904152,-0.002384,0.002551,0.064799,102.711403,5.232368,0.647989,-126.904152,0.065857,0.000000
41.760002,23.258385,-126.993118,-0.002371,0.002571,0.065311,103.458466,5.270425,0.653106,-126.993118,0.066439,0.000000
42.110001,24.230270,-126.993118,-0.002345,0.002603,0.066118,107.781624,5.490657,0.661176,-126.993118,0.067018,0.000000
42.460003,24.112228,-127.126556,-0.002328,0.002622,0.066602,107.256546,5.463909,0.666020,-127.126556,0.067600,0.000000
42.810001,24.393745,-127.171036,-0.002311,0.002644,0.067149,108.508797,5.527701,0.671486,-127.171036,0.068190,0.000000
43.160004,24.990288,-127.215523,-0.002298,0.002670,0.067809,111.162354,5.662880,0.678087,-127.215523,0.068770,0.000000
43.510002,25.138863,-127.260002,-0.002264,0.002688,0.068286,111.823242,5.696548,0.682856,-127.260002,0.069351,0.000000
43.860001,25.625923,-127.304482,-0.002255,0.002713,0.068918,113.989799,5.806917,0.689184,-127.304482,0.069942,0.000000
44.210003,26.425041,-127.393440,-0.002225,0.002739,0.069577,117.544456,5.988000,0.695770,-127.393440,0.070523,0.000000
44.560001,26.680489,-127.348961,-0.002216,0.002760,0.070098,118.680740,6.045885,0.700978,-127.348961,0.071103,0.000000
44.910004,27.180206,-127.437927,-0.002190,0.002783,0.070687,120.903595,6.159123,0.706867,-127.437927,0.071684,0.000000
45.260002,27.643066,-127.526886,-0.002164,0.002803,0.071208,122.962502,6.264009,0.712075,-127.526886,0.072275,0.000000
45.610001,28.035545,-127.526886,-0.002151,0.002825,0.071754,124.708336,6.352946,0.717540,-127.526886,0.072855,0.000000
45.960003,29.192513,-127.571365,-0.002139,0.002853,0.072473,129.854782,6.615118,0.724732,-127.571365,0.073436,0.000000
46.310001,29.427101,-127.660332,-0.002113,0.002875,0.073029,130.898285,6.668276,0.730288,-127.660332,0.074017,0.000000
46.660004,29.571213,-127.660332,-0.002104,0.002895,0.073531,131.539322,6.700933,0.735314,-127.660332,0.074608,0.000000
47.010002,30.692795,-127.749290,-0.002078,0.002923,0.074243,136.528366,6.955087,0.742430,-127.749290,0.075188,0.000000
47.360001,30.655563,-127.749290,-0.002039,0.002939,0.074641,136.362762,6.946650,0.746412,-127.749290,0.075769,0.000000
47.710003,31.918648,-127.838257,-0.002035,0.002971,0.075474,141.981232,7.232869,0.754738,-127.838257,0.076350,0.000000
48.060001,32.455238,-127.882736,-0.002013,0.002991,0.075969,144.368103,7.354462,0.759689,-127.882736,0.076939,0.000000
48.410004,32.782555,-127.971695,-0.002001,0.003013,0.076541,145.824081,7.428633,0.765412,-127.971695,0.077521,0.000000
48.760002,33.119919,-127.971695,-0.001970,0.003033,0.077035,147.324753,7.505081,0.770347,-127.971695,0.078102,0.000000
49.110001,34.206879,-128.016174,-0.001957,0.003059,0.077695,152.159790,7.751390,0.776948,-128.016174,0.078693,0.000000
49.460003,34.143944,-128.105133,-0.001944,0.003075,0.078102,151.879852,7.737128,0.781021,-128.105133,0.079272,0.000000
49.810001,35.562683,-128.149612,-0.001936,0.003103,0.078821,158.190720,8.058619,0.788212,-128.149612,0.079854,0.000000
50.160004,36.407600,-128.194107,-0.001893,0.003128,0.079463,161.949097,8.250080,0.794631,-128.194107,0.080435,0.000000
50.510002,36.718903,-128.238586,-0.001884,0.003149,0.079984,163.333832,8.320621,0.799839,-128.238586,0.081024,0.000000
50.860001,37.681114,-128.283066,-0.001867,0.003172,0.080556,167.613968,8.538663,0.805562,-128.283066,0.081605,0.000000
51.210003,38.142853,-128.416504,-0.001841,0.003192,0.081068,169.667877,8.643294,0.810679,-128.416504,0.082187,0.000000
51.560001,38.592308,-128.416504,-0.001828,0.003211,0.081571,171.667160,8.745142,0.815705,-128.416504,0.082768,0.000000
51.910004,40.008438,-128.416504,-0.001798,0.003240,0.082299,177.966415,9.066041,0.822988,-128.416504,0.083357,0.000000
52.260002,40.593437,-128.505463,-0.001794,0.003263,0.082889,180.568634,9.198605,0.828892,-128.505463,0.083938,0.000000
52.610001,41.381004,-128.549942,-0.001763,0.003285,0.083427,184.071899,9.377069,0.834267,-128.549942,0.084520,0.000000
52.960003,42.599777,-128.594437,-0.001763,0.003312,0.084129,189.493271,9.653248,0.841291,-128.594437,0.085109,0.000000
53.310001,43.082375,-128.638916,-0.001738,0.003330,0.084571,191.639969,9.762606,0.845712,-128.638916,0.085690,0.000000
53.660004,44.644852,-128.683395,-0.001716,0.003360,0.085343,198.590225,10.116668,0.853433,-128.683395,0.086271,0.000000
54.010002,45.169151,-128.727875,-0.001703,0.003381,0.085890,200.922424,10.235476,0.858899,-128.727875,0.086853,0.000000
54.360004,46.018906,-128.816833,-0.001690,0.003401,0.086392,204.702316,10.428033,0.863925,-128.816833,0.087442,0.000000
54.710003,46.737579,-128.816833,-0.001673,0.003423,0.086948,207.899139,10.590887,0.869481,-128.816833,0.088023,0.000000
55.060001,47.815971,-128.905792,-0.001647,0.003445,0.087511,212.696060,10.835255,0.875113,-128.905792,0.088604,0.000000
55.410004,48.205101,-128.950272,-0.001647,0.003461,0.087919,214.427002,10.923432,0.879186,-128.950272,0.089186,0.000000
55.760002,50.147026,-128.994751,-0.001617,0.003496,0.088795,223.065109,11.363479,0.887951,-128.994751,0.089775,0.000000
56.110004,51.100296,-128.994751,-0.001613,0.003518,0.089367,227.305466,11.579493,0.893674,-128.994751,0.090356,0.000000
56.460003,52.023781,-129.128204,-0.001591,0.003539,0.089888,231.413330,11.788757,0.898882,-129.128204,0.090937,0.000000
56.810001,53.025467,-129.128204,-0.001587,0.003563,0.090495,235.869064,12.015743,0.904953,-129.128204,0.091519,0.000000
57.160004,53.956024,-129.128204,-0.001569,0.003583,0.091015,240.008377,12.226610,0.910146,-129.128204,0.092108,0.000000
57.510002,55.187828,-129.261642,-0.001544,0.003609,0.091657,245.487717,12.505740,0.916565,-129.261642,0.092689,0.000000
57.860004,56.337715,-129.261642,-0.001522,0.003629,0.092186,250.602676,12.766309,0.921864,-129.261642,0.093270,0.000000
58.210003,57.607880,-129.395081,-0.001513,0.003655,0.092828,256.252655,13.054132,0.928283,-129.395081,0.093859,0.000000
58.560001,58.458382,-129.439575,-0.001513,0.003671,0.093243,260.035858,13.246860,0.932432,-129.439575,0.094441,0.000000
58.910004,60.074478,-129.439575,-0.001496,0.003699,0.093964,267.224640,13.613071,0.939638,-129.439575,0.095022,0.000000
59.260002,60.642342,-129.484055,-0.001470,0.003716,0.094380,269.750610,13.741751,0.943801,-129.484055,0.095603,0.000000
59.610004,62.674377,-129.573013,-0.001462,0.003747,0.095178,278.789551,14.202217,0.951780,-129.573013,0.096192,0.000000
59.960003,63.760963,-129.617493,-0.001470,0.003770,0.095750,283.622925,14.448441,0.957503,-129.617493,0.096774,0.000000
60.310001,64.267769,-129.617493,-0.001427,0.003784,0.096106,285.877319,14.563284,0.961061,-129.617493,0.097355,0.000000
60.660004,66.157173,-129.706451,-0.001431,0.003812,0.096818,294.281799,14.991429,0.968176,-129.706451,0.097935,0.000000
61.010002,65.276894,-129.750931,-0.001418,0.003805,0.096634,290.366119,14.791956,0.966344,-129.750931,0.016972,0.000000
61.360004,66.866920,-129.839890,-0.001393,0.003842,0.097581,297.438904,15.152261,0.975806,-129.839890,294.500488,0.000000
61.710003,66.050301,-129.839890,-0.001375,0.003722,0.094545,293.806396,14.967212,0.945452,-129.839890,294.500488,0.000000
62.060001,65.188637,-129.839890,-0.001375,0.003798,0.096478,289.973541,14.771956,0.964785,-129.839890,294.500488,0.000000
62.410004,65.606071,-129.928864,-0.001375,0.003843,0.097606,291.830383,14.866549,0.976064,-129.928864,294.500488,0.000000
62.760002,65.105232,-129.973343,-0.001367,0.003843,0.097606,289.602539,14.753057,0.976064,-129.973343,294.500488,0.000000
63.110004,65.781456,-130.017822,-0.001358,0.003857,0.097979,292.610535,14.906291,0.979788,-130.017822,294.500488,0.000000
63.460003,65.298485,-130.106781,-0.001358,0.003857,0.097979,290.462158,14.796848,0.979788,-130.106781,294.500488,0.000000
63.810001,64.811790,-130.151260,-0.001354,0.003858,0.097988,288.297241,14.686562,0.979879,-130.151260,294.500488,0.000000
64.160004,66.719841,-130.195740,-0.001337,0.003779,0.095993,296.784668,15.118932,0.959925,-130.195740,294.500488,0.000000
64.510002,66.131111,-130.284698,-0.001324,0.003774,0.095855,294.165863,14.985524,0.958547,-130.284698,294.500488,0.000000
64.860001,65.591911,-130.240219,-0.001324,0.003785,0.096148,291.767395,14.863339,0.961484,-130.240219,294.500488,0.000000
65.210007,65.219170,-130.284698,-0.001328,0.003841,0.097562,290.109344,14.778874,0.975625,-130.284698,294.500488,0.000000
65.560005,65.511116,-130.373672,-0.001324,0.003883,0.098630,291.407990,14.845031,0.986298,-130.373672,294.500488,0.000000
65.910004,65.195717,-130.373672,-0.001315,0.003883,0.098637,290.005035,14.773561,0.986374,-130.373672,294.500488,0.000000
66.260002,65.267586,-130.462631,-0.001324,0.003891,0.098828,290.324707,14.789846,0.988281,-130.462631,294.500488,0.000000
66.610001,65.216194,-130.462631,-0.001319,0.003894,0.098907,290.096130,14.778201,0.989069,-130.462631,294.500488,0.000000
66.960007,65.152885,-130.551590,-0.001324,0.003896,0.098967,289.814514,14.763855,0.989674,-130.551590,294.500488,0.000000
67.310005,65.179329,-130.640549,-0.001324,0.003899,0.099046,289.932129,14.769847,0.990462,-130.640549,294.500488,0.000000
67.660004,65.151772,-130.640549,-0.001311,0.003902,0.099107,289.809540,14.763602,0.991067,-130.640549,294.500488,0.000000
68.010002,65.071342,-130.774002,-0.001315,0.003905,0.099176,289.451782,14.745378,0.991764,-130.774002,294.500488,0.000000
68.360001,64.995003,-130.818481,-0.001306,0.003905,0.099193,289.112213,14.728079,0.991930,-130.818481,294.500488,0.000000
68.710007,64.986809,-130.818481,-0.001302,0.003909,0.099288,289.075775,14.726221,0.992884,-130.818481,294.500488,0.000000
69.060005,64.871010,-130.862961,-0.001319,0.003909,0.099288,288.560669,14.699981,0.992884,-130.862961,294.500488,0.000000
69.410004,65.394936,-130.862961,-0.001306,0.003918,0.099523,290.891205,14.818705,0.995231,-130.862961,294.500488,0.000000
69.760002,65.331627,-130.951920,-0.001302,0.003918,0.099523,290.609589,14.804358,0.995231,-130.951920,294.500488,0.000000
70.110001,65.180443,-130.996399,-0.001311,0.003918,0.099523,289.937103,14.770100,0.995231,-130.996399,294.500488,0.000000
70.460007,65.006920,-130.996399,-0.001306,0.003918,0.099523,289.165222,14.730779,0.995231,-130.996399,294.500488,0.000000
70.810005,64.884789,-131.174332,-0.001306,0.003920,0.099565,288.621948,14.703104,0.995654,-131.174332,294.500488,0.000000
71.160004,65.702141,-131.129837,-0.001302,0.003931,0.099844,292.257721,14.888318,0.998440,-131.129837,294.500488,0.000000
71.510002,65.570320,-131.174332,-0.001298,0.003930,0.099817,291.671356,14.858447,0.998168,-131.174332,294.500488,0.000000
71.860001,65.419136,-131.263290,-0.001298,0.003930,0.099817,290.998840,14.824188,0.998168,-131.263290,294.500488,0.000000
72.210007,65.271675,-131.307770,-0.001285,0.003930,0.099817,290.342926,14.790773,0.998168,-131.307770,294.500488,0.000000
72.560005,65.113045,-131.307770,-0.001285,0.003930,0.099817,289.637299,14.754827,0.998168,-131.307770,294.500488,0.000000
72.910004,64.959251,-131.352249,-0.001298,0.003930,0.099817,288.953186,14.719976,0.998168,-131.352249,294.500488,0.000000
73.260002,66.122551,-131.441208,-0.001302,0.003934,0.099930,294.127808,14.983583,0.999303,-131.441208,294.500488,0.000000
73.610001,65.852577,-131.441208,-0.001281,0.003934,0.099912,292.926880,14.922407,0.999121,-131.441208,294.500488,0.000000
73.960007,65.752785,-131.530167,-0.001285,0.003934,0.099912,292.483002,14.899794,0.999121,-131.530167,294.500488,0.000000
74.310005,65.552452,-131.574646,-0.001285,0.003934,0.099912,291.591858,14.854398,0.999121,-131.574646,294.500488,0.000000
74.660004,65.378914,-131.574646,-0.001293,0.003934,0.099921,290.819946,14.815073,0.999212,-131.574646,294.500488,0.000000
75.010002,65.238914,-131.708099,-0.001298,0.003934,0.099921,290.197174,14.783349,0.999212,-131.708099,294.500488,0.000000
75.360001,65.517815,-131.663620,-0.001276,0.003946,0.100233,291.437805,14.846549,1.002331,-131.663620,294.500488,0.000000
75.710007,65.508507,-131.752579,-0.001281,0.003946,0.100233,291.396393,14.844440,1.002331,-131.752579,294.500488,0.000000
76.060005,65.398659,-131.797058,-0.001281,0.003946,0.100233,290.907776,14.819548,1.002331,-131.797058,294.500488,0.000000
76.410004,65.318962,-131.841537,-0.001285,0.003947,0.100242,290.553253,14.801488,1.002422,-131.841537,294.500488,0.000000
76.760002,65.271309,-131.930496,-0.001276,0.003948,0.100286,290.341278,14.790690,1.002861,-131.930496,294.500488,0.000000
77.110001,65.193855,-131.930496,-0.001281,0.003949,0.100295,289.996765,14.773139,1.002952,-131.930496,294.500488,0.000000
77.460007,65.175240,-131.974976,-0.001276,0.003950,0.100338,289.913940,14.768920,1.003376,-131.974976,294.500488,0.000000
77.810005,65.175240,-132.019470,-0.001281,0.003951,0.100356,289.913940,14.768920,1.003557,-132.019470,294.500488,0.000000
78.160004,65.102623,-132.019470,-0.001289,0.003951,0.100363,289.590942,14.752465,1.003633,-132.019470,294.500488,0.000000
78.510002,65.044899,-132.108429,-0.001272,0.003951,0.100363,289.334167,14.739385,1.003633,-132.108429,294.500488,0.000000
78.860001,64.995384,-132.197388,-0.001276,0.003952,0.100391,289.113922,14.728165,1.003906,-132.197388,294.500488,0.000000
79.210007,64.940269,-132.241867,-0.001276,0.003952,0.100391,288.868744,14.715675,1.003906,-132.241867,294.500488,0.000000
79.560005,65.057930,-132.330826,-0.001276,0.003964,0.100684,289.392120,14.742338,1.006843,-132.330826,294.500488,0.000000
79.910004,65.737892,-132.286346,-0.001281,0.003962,0.100642,292.416748,14.896420,1.006419,-132.286346,294.500488,0.000000
80.260002,65.637352,-132.330826,-0.001272,0.003962,0.100642,291.969513,14.873637,1.006419,-132.330826,294.500488,0.000000
80.610001,65.581123,-132.375305,-0.001268,0.003962,0.100642,291.719421,14.860894,1.006419,-132.375305,294.500488,0.000000
80.960007,65.527122,-132.464279,-0.001276,0.003962,0.100642,291.479187,14.848658,1.006419,-132.464279,294.500488,0.000000
81.310005,65.425835,-132.553238,-0.001263,0.003962,0.100642,291.028656,14.825706,1.006419,-132.553238,294.500488,0.000000
81.660004,65.338707,-132.553238,-0.001268,0.003962,0.100642,290.641083,14.805963,1.006419,-132.553238,294.500488,0.000000
82.010002,65.267204,-132.553238,-0.001263,0.003962,0.100642,290.323029,14.789760,1.006419,-132.553238,294.500488,0.000000
82.360001,65.188271,-132.686676,-0.001263,0.003962,0.100642,289.971924,14.771873,1.006419,-132.686676,294.500488,0.000000
82.710007,65.106346,-132.686676,-0.001263,0.003963,0.100649,289.607483,14.753309,1.006494,-132.686676,294.500488,0.000000
83.060005,65.030754,-132.775635,-0.001268,0.003963,0.100649,289.271240,14.736180,1.006494,-132.775635,294.500488,0.000000
83.410004,65.198692,-132.775635,-0.001268,0.003967,0.100763,290.018280,14.774235,1.007630,-132.775635,294.500488,0.000000
83.760002,65.211723,-132.775635,-0.001263,0.003967,0.100763,290.076233,14.777188,1.007630,-132.775635,294.500488,0.000000
84.110001,65.171883,-132.820114,-0.001263,0.003967,0.100763,289.899017,14.768160,1.007630,-132.820114,294.500488,0.000000
84.460007,65.101509,-132.953568,-0.001259,0.003967,0.100763,289.585968,14.752213,1.007630,-132.953568,294.500488,0.000000
84.810005,65.059425,-132.953568,-0.001263,0.003967,0.100763,289.398773,14.742677,1.007630,-132.953568,294.500488,0.000000
85.160004,65.012505,-132.998047,-0.001259,0.003969,0.100814,289.190063,14.732044,1.008145,-132.998047,294.500488,0.000000
85.510002,65.060539,-133.087006,-0.001255,0.003970,0.100833,289.403748,14.742929,1.008326,-133.087006,294.500488,0.000000
85.860001,65.045280,-133.087006,-0.001255,0.003970,0.100833,289.335846,14.739471,1.008326,-133.087006,294.500488,0.000000
86.210007,64.986809,-133.175964,-0.001263,0.003970,0.100833,289.075775,14.726221,1.008326,-133.175964,294.500488,0.000000
86.560005,65.289558,-133.175964,-0.001250,0.003975,0.100963,290.422455,14.794826,1.009628,-133.175964,294.500488,0.000000
86.910004,65.305565,-133.220444,-0.001263,0.003975,0.100963,290.493652,14.798452,1.009628,-133.220444,294.500488,0.000000
87.260002,65.269447,-133.264923,-0.001263,0.003975,0.100963,290.333008,14.790268,1.009628,-133.264923,294.500488,0.000000
87.610001,65.228477,-133.309418,-0.001255,0.003975,0.100963,290.150757,14.780985,1.009628,-133.309418,294.500488,0.000000
87.960007,65.184166,-133.353897,-0.001250,0.003975,0.100963,289.953644,14.770943,1.009628,-133.353897,294.500488,0.000000
88.310005,65.117516,-133.442856,-0.001250,0.003975,0.100963,289.657166,14.755840,1.009628,-133.442856,294.500488,0.000000
88.660004,65.082512,-133.442856,-0.001268,0.003975,0.100970,289.501465,14.747909,1.009704,-133.442856,294.500488,0.000000
89.010002,65.043419,-133.487335,-0.001242,0.003976,0.100979,289.327576,14.739050,1.009795,-133.487335,294.500488,0.000000
89.360001,64.984947,-133.576294,-0.001250,0.003976,0.100979,289.067474,14.725800,1.009795,-133.576294,294.500488,0.000000
89.710007,64.951805,-133.620773,-0.001255,0.003976,0.100996,288.920044,14.718289,1.009961,-133.620773,294.500488,0.000000
90.060005,64.954414,-133.620773,-0.001246,0.003977,0.101014,288.931671,14.718881,1.010143,-133.620773,294.500488,0.000000
90.410004,64.918297,-133.665253,-0.001246,0.003977,0.101014,288.770996,14.710696,1.010143,-133.665253,294.500488,0.000000
90.760002,64.869148,-133.709732,-0.001242,0.003977,0.101014,288.552368,14.699559,1.010143,-133.709732,294.500488,0.000000
91.110001,64.887764,-133.798706,-0.001246,0.003978,0.101049,288.635193,14.703777,1.010491,-133.798706,294.500488,0.000000
91.460007,64.847176,-133.887665,-0.001255,0.003979,0.101058,288.454651,14.694580,1.010582,-133.887665,294.500488,0.000000
91.810005,65.943062,-133.887665,-0.001250,0.003988,0.101291,293.329376,14.942912,1.012914,-133.887665,294.500488,0.000000
92.160004,65.866356,-133.932144,-0.001246,0.003988,0.101291,292.988190,14.925529,1.012914,-133.932144,294.500488,0.000000
92.510002,65.844765,-133.976624,-0.001250,0.003988,0.101291,292.892151,14.920637,1.012914,-133.976624,294.500488,0.000000
92.860001,65.773262,-134.021103,-0.001246,0.003988,0.101291,292.574097,14.904434,1.012914,-134.021103,294.500488,0.000000
93.210007,65.754646,-134.110062,-0.001250,0.003988,0.101291,292.491272,14.900216,1.012914,-134.110062,294.500488,0.000000
93.560005,65.673836,-134.110062,-0.001237,0.003988,0.101291,292.131805,14.881904,1.012914,-134.110062,294.500488,0.000000
93.910004,65.630272,-134.243515,-0.001246,0.003988,0.101291,291.938019,14.872032,1.012914,-134.243515,294.500488,0.000000
94.260002,65.591911,-134.199036,-0.001250,0.003988,0.101291,291.767395,14.863339,1.012914,-134.199036,294.500488,0.000000
94.610008,65.560646,-134.243515,-0.001237,0.003988,0.101291,291.628326,14.856255,1.012914,-134.243515,294.500488,0.000000
94.960007,65.514091,-134.332474,-0.001242,0.003988,0.101291,291.421234,14.845706,1.012914,-134.332474,294.500488,0.000000
95.310005,65.480202,-134.376953,-0.001242,0.003988,0.101300,291.270477,14.838026,1.013004,-134.376953,294.500488,0.000000
95.660004,65.406105,-134.332474,-0.001250,0.003988,0.101300,290.940887,14.821236,1.013004,-134.332474,294.500488,0.000000
96.010002,65.371101,-134.510391,-0.001237,0.003988,0.101300,290.785187,14.813304,1.013004,-134.510391,294.500488,0.000000
96.360008,65.327904,-134.421432,-0.001224,0.003988,0.101300,290.593018,14.803514,1.013004,-134.421432,294.500488,0.000000
96.710007,65.285454,-134.510391,-0.001237,0.003988,0.101300,290.404205,14.793895,1.013004,-134.510391,294.500488,0.000000
97.060005,65.244118,-134.554871,-0.001229,0.003988,0.101300,290.220337,14.784528,1.013004,-134.554871,294.500488,0.000000
97.410004,65.208000,-134.643845,-0.001229,0.003988,0.101300,290.059662,14.776343,1.013004,-134.643845,294.500488,0.000000
97.760002,65.137993,-134.643845,-0.001237,0.003988,0.101300,289.748260,14.760480,1.013004,-134.643845,294.500488,0.000000
98.110008,65.097786,-134.732803,-0.001237,0.003988,0.101300,289.569427,14.751369,1.013004,-134.732803,294.500488,0.000000
98.460007,65.059059,-134.777283,-0.001242,0.003988,0.101300,289.397156,14.742594,1.013004,-134.777283,294.500488,0.000000
98.810005,65.025917,-134.821762,-0.001233,0.003989,0.101326,289.249725,14.735084,1.013262,-134.821762,294.500488,0.000000
99.160004,64.989052,-134.866241,-0.001242,0.003989,0.101326,289.085754,14.726729,1.013262,-134.866241,294.500488,0.000000
99.510002,64.955528,-134.910721,-0.001229,0.003989,0.101326,288.936615,14.719133,1.013262,-134.910721,294.500488,0.000000
99.860008,64.906746,-134.955200,-0.001242,0.003989,0.101326,288.719635,14.708078,1.013262,-134.955200,294.500488,0.000000
100.210007,64.870262,-134.955200,-0.001246,0.003989,0.101326,288.557343,14.699812,1.013262,-134.955200,294.500488,0.000000
100.560005,64.842339,-135.044174,-0.001233,0.003989,0.101326,288.433136,14.693484,1.013262,-135.044174,294.500488,0.000000
100.910004,64.792427,-135.088654,-0.001233,0.003990,0.101335,288.211121,14.682174,1.013353,-135.088654,294.500488,0.000000
101.260002,64.758553,-135.133133,-0.001237,0.003990,0.101335,288.060425,14.674498,1.013353,-135.133133,294.500488,0.000000
101.610008,64.734337,-135.133133,-0.001220,0.003990,0.101335,287.952698,14.669011,1.013353,-135.133133,294.500488,0.000000
101.960007,64.703072,-135.266571,-0.001237,0.003990,0.101335,287.813629,14.661925,1.013353,-135.266571,294.500488,0.000000
102.310005,64.655022,-135.311050,-0.001224,0.003990,0.101335,287.599915,14.651037,1.013353,-135.311050,294.500488,0.000000
102.660004,64.607735,-135.355530,-0.001220,0.003990,0.101335,287.389557,14.640322,1.013353,-135.355530,294.500488,0.000000
103.010002,66.503120,-135.400009,-0.001237,0.003971,0.100867,295.820648,15.069822,1.008675,-135.400009,294.500488,0.000000
103.360008,66.419334,-135.355530,-0.001229,0.003971,0.100867,295.447968,15.050837,1.008675,-135.355530,294.500488,0.000000
103.710007,66.374641,-135.444489,-0.001229,0.003971,0.100867,295.249146,15.040709,1.008675,-135.444489,294.500488,0.000000
104.060005,66.325127,-135.577942,-0.001229,0.003971,0.100867,295.028900,15.029489,1.008675,-135.577942,294.500488,0.000000
104.410004,66.274849,-135.577942,-0.001229,0.003971,0.100867,294.805237,15.018096,1.008675,-135.577942,294.500488,0.000000
104.760002,66.216759,-135.622421,-0.001216,0.003971,0.100867,294.546844,15.004931,1.008675,-135.622421,294.500488,0.000000
105.110008,66.189201,-135.622421,-0.001212,0.003971,0.100867,294.424286,14.998688,1.008675,-135.622421,294.500488,0.000000
105.460007,66.144142,-135.711380,-0.001212,0.003971,0.100867,294.223846,14.988478,1.008675,-135.711380,294.500488,0.000000
105.810005,66.086800,-135.755859,-0.001216,0.003971,0.100867,293.968781,14.975483,1.008675,-135.755859,294.500488,0.000000
106.160004,66.058495,-135.755859,-0.001216,0.003971,0.100867,293.842865,14.969069,1.008675,-135.755859,294.500488,0.000000
106.510002,66.021629,-135.889313,-0.001207,0.003971,0.100867,293.678864,14.960714,1.008675,-135.889313,294.500488,0.000000
106.860008,65.963173,-135.889313,-0.001212,0.003971,0.100867,293.418854,14.947468,1.008675,-135.889313,294.500488,0.000000
107.210007,65.873436,-135.933792,-0.001224,0.003971,0.100867,293.019684,14.927135,1.008675,-135.933792,294.500488,0.000000
107.560005,65.843269,-135.978271,-0.001224,0.003971,0.100867,292.885498,14.920299,1.008675,-135.978271,294.500488,0.000000
107.910004,65.864861,-136.067230,-0.001212,0.003971,0.100875,292.981537,14.925191,1.008750,-136.067230,294.500488,0.000000
108.260002,65.837318,-136.111710,-0.001207,0.003971,0.100875,292.859009,14.918950,1.008750,-136.111710,294.500488,0.000000
108.610008,65.769905,-136.156189,-0.001207,0.003971,0.100875,292.559143,14.903673,1.008750,-136.156189,294.500488,0.000000
108.960007,65.746452,-136.200668,-0.001212,0.003971,0.100875,292.454834,14.898359,1.008750,-136.200668,294.500488,0.000000
109.310005,65.682030,-136.156189,-0.001207,0.003972,0.100884,292.168274,14.883760,1.008841,-136.156189,294.500488,0.000000
109.660004,65.648888,-136.289627,-0.001216,0.003972,0.100884,292.020844,14.876251,1.008841,-136.289627,294.500488,0.000000
110.010002,65.603462,-136.289627,-0.001224,0.003972,0.100893,291.818787,14.865956,1.008932,-136.289627,294.500488,0.000000
110.360008,65.572548,-136.334122,-0.001203,0.003972,0.100901,291.681274,14.858952,1.009008,-136.334122,294.500488,0.000000
110.710007,65.559517,-136.423080,-0.001216,0.003972,0.100901,291.623291,14.855999,1.009008,-136.423080,294.500488,0.000000
111.060005,65.540154,-136.512039,-0.001216,0.003972,0.100901,291.537170,14.851611,1.009008,-136.512039,294.500488,0.000000
111.410004,65.480202,-136.556519,-0.001224,0.003973,0.100910,291.270477,14.838026,1.009098,-136.556519,294.500488,0.000000
111.760002,65.460472,-136.556519,-0.001212,0.003974,0.100936,291.182709,14.833555,1.009356,-136.556519,294.500488,0.000000
112.110008,65.406853,-136.600998,-0.001216,0.003976,0.100989,290.944214,14.821404,1.009886,-136.600998,294.500488,0.000000
112.460007,65.352486,-136.645477,-0.001216,0.003976,0.100996,290.702362,14.809085,1.009961,-136.645477,294.500488,0.000000
112.810005,65.334236,-136.645477,-0.001207,0.003976,0.100996,290.621185,14.804950,1.009961,-136.645477,294.500488,0.000000
113.160004,65.299232,-136.778931,-0.001212,0.003976,0.100996,290.465485,14.797018,1.009961,-136.778931,294.500488,0.000000
113.510002,65.278755,-136.867889,-0.001212,0.003978,0.101049,290.374420,14.792377,1.010491,-136.867889,294.500488,0.000000
113.860008,65.251198,-136.823410,-0.001212,0.003978,0.101049,290.251831,14.786133,1.010491,-136.823410,294.500488,0.000000
114.210007,65.221413,-136.956848,-0.001216,0.003978,0.101049,290.119324,14.779383,1.010491,-136.956848,294.500488,0.000000
114.560005,65.328285,-136.956848,-0.001212,0.004002,0.101656,290.594727,14.803600,1.016562,-136.956848,294.500488,0.000000
114.910004,65.343544,-136.956848,-0.001216,0.004002,0.101656,290.662598,14.807058,1.016562,-136.956848,294.500488,0.000000
115.260002,65.371101,-137.045807,-0.001216,0.004004,0.101691,290.785187,14.813304,1.016910,-137.045807,294.500488,0.000000
115.610008,65.357323,-137.045807,-0.001212,0.004004,0.101691,290.723877,14.810181,1.016910,-137.045807,294.500488,0.000000
115.960007,65.334236,-137.179260,-0.001212,0.004004,0.101691,290.621185,14.804950,1.016910,-137.179260,294.500488,0.000000
116.310005,65.339455,-137.179260,-0.001216,0.004004,0.101708,290.644409,14.806131,1.017077,-137.179260,294.500488,0.000000
116.660004,65.328651,-137.268219,-0.001212,0.004004,0.101708,290.596344,14.803684,1.017077,-137.268219,294.500488,0.000000
117.010002,65.301460,-137.268219,-0.001207,0.004005,0.101717,290.475403,14.797522,1.017168,-137.268219,294.500488,0.000000
117.360008,65.294014,-137.312698,-0.001212,0.004005,0.101717,290.442291,14.795835,1.017168,-137.312698,294.500488,0.000000
117.710007,65.274651,-137.357178,-0.001216,0.004005,0.101717,290.356140,14.791448,1.017168,-137.357178,294.500488,0.000000
118.060005,65.253807,-137.357178,-0.001224,0.004005,0.101717,290.263428,14.786724,1.017168,-137.357178,294.500488,0.000000
118.410004,65.255287,-137.401657,-0.001212,0.004005,0.101733,290.270020,14.787059,1.017334,-137.401657,294.500488,0.000000
118.760002,65.238914,-137.535095,-0.001220,0.004005,0.101733,290.197174,14.783349,1.017334,-137.535095,294.500488,0.000000
119.110008,65.224388,-137.446136,-0.001212,0.004006,0.101743,290.132568,14.780058,1.017425,-137.446136,294.500488,0.000000
119.460007,65.295876,-137.579575,-0.001212,0.004008,0.101803,290.450562,14.796256,1.018031,-137.579575,294.500488,0.000000
119.810005,65.313377,-137.713028,-0.001212,0.004008,0.101803,290.528412,14.800222,1.018031,-137.713028,294.500488,0.000000
120.160004,65.299599,-137.713028,-0.001216,0.004008,0.101803,290.467133,14.797101,1.018031,-137.713028,294.500488,0.000000
120.510002,65.286568,-137.713028,-0.001203,0.004008,0.101803,290.409149,14.794147,1.018031,-137.713028,294.500488,0.000000
120.860008,65.285820,-137.757507,-0.001199,0.004008,0.101803,290.405823,14.793979,1.018031,-137.757507,294.500488,0.000000
121.210007,65.259758,-137.801987,-0.001220,0.004008,0.101803,290.289886,14.788073,1.018031,-137.801987,1681.640991,0.000000
121.560005,65.218056,-137.846466,-0.001207,0.004001,0.101638,290.104401,14.778623,1.016381,-137.846466,0.101612,0.000000
121.910004,65.047508,-137.890945,-0.001212,0.003988,0.101300,289.345764,14.739976,1.013004,-137.890945,0.101031,0.000000
122.260002,65.143211,-137.935425,-0.001203,0.003972,0.100893,289.771484,14.761663,1.008932,-137.935425,0.100442,0.000000
122.610008,65.037086,-138.024384,-0.001203,0.003951,0.100363,289.299408,14.737615,1.003633,-138.024384,0.099861,0.000000
122.960007,65.018471,-138.024384,-0.001216,0.003935,0.099939,289.216614,14.733397,0.999394,-138.024384,0.099279,0.000000
123.310005,64.952187,-138.113358,-0.001216,0.003907,0.099244,288.921753,14.718376,0.992445,-138.113358,0.098699,0.000000
123.660004,64.948082,-138.113358,-0.001212,0.003887,0.098742,288.903503,14.717445,0.987419,-138.113358,0.098109,0.000000
124.010002,64.906380,-138.157837,-0.001212,0.003859,0.098030,288.717987,14.707996,0.980303,-138.157837,0.097528,0.000000
124.360008,64.871010,-138.246796,-0.001212,0.003838,0.097485,288.560669,14.699981,0.974853,-138.246796,0.096946,0.000000
124.710007,64.836006,-138.246796,-0.001207,0.003816,0.096921,288.404968,14.692049,0.969206,-138.246796,0.096366,0.000000
125.060005,64.776787,-138.335754,-0.001212,0.003792,0.096313,288.141541,14.678629,0.963135,-138.335754,0.095776,0.000000
125.410004,64.732475,-138.335754,-0.001212,0.003772,0.095820,287.944427,14.668589,0.958199,-138.335754,0.095195,0.000000
125.760010,64.466240,-138.380234,-0.001199,0.003749,0.095213,286.760162,14.608258,0.952128,-138.380234,0.094615,0.000000
126.110008,64.002998,-138.469208,-0.001199,0.003732,0.094796,284.699554,14.503287,0.947965,-138.469208,0.094024,0.000000
126.460007,63.213203,-138.513687,-0.001203,0.003708,0.094171,281.186371,14.324317,0.941712,-138.513687,0.093443,0.000000
126.810005,61.693176,-138.602646,-0.001164,0.003684,0.093573,274.424957,13.979874,0.935732,-138.602646,0.092862,0.000000
127.160004,60.971519,-138.602646,-0.001173,0.003667,0.093148,271.214874,13.816343,0.931478,-138.602646,0.092282,0.000000
127.510010,58.825912,-138.647125,-0.001168,0.003643,0.092524,261.670715,13.330143,0.925240,-138.647125,0.091691,0.000000
127.860008,57.017670,-138.736084,-0.001155,0.003622,0.091987,253.627258,12.920388,0.919866,-138.736084,0.091110,0.000000
128.210007,55.156555,-138.691605,-0.001160,0.003603,0.091510,245.348618,12.498654,0.915097,-138.691605,0.090530,0.000000
128.560013,53.168831,-138.825043,-0.001160,0.003583,0.091007,236.506775,12.048229,0.910070,-138.825043,0.089949,0.000000
128.910004,50.490349,-138.825043,-0.001155,0.003557,0.090347,224.592285,11.441277,0.903470,-138.825043,0.089358,0.000000
129.260010,48.446030,-138.780563,-0.001164,0.003537,0.089835,215.498703,10.978027,0.898352,-138.780563,0.088777,0.000000
129.610001,45.756378,-138.958496,-0.001151,0.003515,0.089289,203.534531,10.368543,0.892887,-138.958496,0.088197,0.000000
129.960007,43.133018,-138.958496,-0.001164,0.003491,0.088682,191.865250,9.774081,0.886816,-138.958496,0.087616,0.000000
130.310013,40.547638,-139.002975,-0.001155,0.003469,0.088109,180.364899,9.188226,0.881093,-139.002975,0.087025,0.000000
130.660004,37.818146,-139.047455,-0.001155,0.003443,0.087451,168.223511,8.569715,0.874508,-139.047455,0.086445,0.000000
131.010010,35.495285,-139.002975,-0.001168,0.003422,0.086913,157.890915,8.043346,0.869133,-139.002975,0.085864,0.000000
131.360001,33.981964,-139.091934,-0.001160,0.003411,0.086627,151.159332,7.700423,0.866272,-139.091934,0.085274,0.000000
131.710007,30.456345,-139.180893,-0.001168,0.003376,0.085751,135.476593,6.901506,0.857506,-139.180893,0.084692,0.000000
132.060013,28.058632,-139.225372,-0.001155,0.003353,0.085162,124.811028,6.358177,0.851617,-139.225372,0.084112,0.000000
132.410004,26.153206,-139.225372,-0.001160,0.003337,0.084762,116.335266,5.926401,0.847620,-139.225372,0.083531,0.000000
132.760010,23.401375,-139.269852,-0.001164,0.003311,0.084087,104.094513,5.302827,0.840867,-139.269852,0.082941,0.000000
133.110001,21.254272,-139.314346,-0.001151,0.003293,0.083636,94.543724,4.816287,0.836356,-139.314346,0.082361,0.000000
133.460007,17.753601,-139.403305,-0.001155,0.003255,0.082689,78.971962,4.023024,0.826894,-139.403305,0.081779,0.000000
133.810013,16.218307,-139.492264,-0.001164,0.003243,0.082368,72.142632,3.675121,0.823684,-139.492264,0.081198,0.000000
134.160004,13.378967,-139.536743,-0.001164,0.003220,0.081779,59.512619,3.031717,0.817795,-139.536743,0.080608,0.000000
134.510010,10.585426,-139.536743,-0.001160,0.003191,0.081059,47.086327,2.398692,0.810588,-139.536743,0.080028,0.000000
134.860001,8.349335,-139.581223,-0.001177,0.003172,0.080565,37.139694,1.891986,0.805653,-139.581223,0.079446,0.000000
135.210007,6.318787,-139.625702,-0.001168,0.003152,0.080070,28.107367,1.431858,0.800702,-139.625702,0.078856,0.000000
135.560013,3.191978,-139.670181,-0.001143,0.003124,0.079351,14.198629,0.723313,0.793511,-139.670181,0.078276,0.000000
135.910004,1.046364,-139.714661,-0.001173,0.003101,0.078753,4.654459,0.237109,0.787531,-139.714661,0.077695,0.000000
136.260010,-0.876938,-139.803635,-0.001155,0.003082,0.078284,-3.900815,-0.198717,0.782837,-139.803635,0.077113,0.000000
136.610001,-3.994812,-139.803635,-0.001164,0.003051,0.077504,-17.769812,-0.905237,0.775041,-139.803635,0.076525,0.000000
136.960007,-4.912712,-139.848114,-0.001160,0.003040,0.077209,-21.852835,-1.113236,0.772088,-139.848114,0.075943,0.000000
137.310013,-0.302368,-139.892593,-0.001164,0.003007,0.076376,-1.345001,-0.068518,0.763762,-139.892593,0.075362,0.000000
137.660004,-0.264389,-139.937073,-0.001155,0.002989,0.075908,-1.176061,-0.059911,0.759083,-139.937073,0.074780,0.000000
138.010010,-0.209274,-139.981552,-0.001164,0.002963,0.075248,-0.930899,-0.047422,0.752483,-139.981552,0.074192,0.000000
138.360001,-0.097939,-140.070511,-0.001160,0.002949,0.074911,-0.435652,-0.022193,0.749106,-140.070511,0.073610,0.000000
138.710007,-0.077454,-140.114990,-0.001168,0.002924,0.074278,-0.344531,-0.017551,0.742778,-140.114990,0.073029,0.000000
139.060013,-0.055489,-140.159470,-0.001173,0.002894,0.073515,-0.246826,-0.012574,0.735148,-140.159470,0.072447,0.000000
139.410004,-0.030167,-140.203964,-0.001173,0.002876,0.073055,-0.134188,-0.006836,0.730545,-140.203964,0.071859,0.000000
139.760010,-0.074104,-140.248444,-0.001177,0.002845,0.072257,-0.329632,-0.016792,0.722567,-140.248444,0.071277,0.000000
140.110001,-0.045807,-140.292923,-0.001181,0.002828,0.071833,-0.203759,-0.010380,0.718328,-140.292923,0.070696,0.000000
140.460007,-0.007820,-140.337402,-0.001190,0.002807,0.071286,-0.034786,-0.001772,0.712862,-140.337402,0.070107,0.000000
140.810013,-0.038353,-140.381882,-0.001203,0.002790,0.070877,-0.170603,-0.008691,0.708775,-140.381882,0.069525,0.000000
141.160004,-0.020111,-140.426361,-0.001229,0.002765,0.070228,-0.089459,-0.004557,0.702280,-140.426361,0.068944,0.000000
141.510010,-0.044312,-140.470840,-0.001233,0.002739,0.069568,-0.197107,-0.010041,0.695679,-140.470840,0.068363,0.000000
141.860001,-0.076340,-140.470840,-0.001285,0.002711,0.068867,-0.339576,-0.017299,0.688669,-140.470840,0.067774,0.000000
142.210007,-0.043198,-140.470840,-0.001302,0.002689,0.068302,-0.192153,-0.009789,0.683022,-140.470840,0.067192,0.000000
142.560013,-0.021599,-140.648773,-0.001328,0.002668,0.067774,-0.096076,-0.004894,0.677738,-140.648773,0.066611,0.000000
142.910004,-0.052879,-140.604294,-0.001350,0.002639,0.067037,-0.235219,-0.011983,0.670365,-140.604294,0.066030,0.000000
143.260010,-0.055115,-140.648773,-0.001367,0.002617,0.066481,-0.245163,-0.012489,0.664809,-140.648773,0.065441,0.000000
143.610001,-0.048035,-140.693253,-0.001414,0.002591,0.065822,-0.213669,-0.010885,0.658224,-140.693253,0.064859,0.000000
143.960007,-0.062935,-140.737732,-0.001440,0.002574,0.065371,-0.279948,-0.014261,0.653712,-140.737732,0.064278,0.000000
144.310013,-0.054741,-140.826691,-0.001462,0.002550,0.064764,-0.243500,-0.012404,0.647641,-140.826691,0.063689,0.000000
144.660004,-0.047668,-140.871170,-0.001479,0.002520,0.064001,-0.212040,-0.010802,0.640011,-140.871170,0.063108,0.000000
145.010010,-0.044685,-140.915649,-0.001531,0.002503,0.063576,-0.198770,-0.010126,0.635756,-140.915649,0.063489,0.000000
145.100006,-0.047668,-140.915649,-0.001518,0.002503,0.063585,-0.212040,-0.010802,0.635847,-140.915649,0.063489,0.000000