File: Data/compression 17/ManualNoHeating-10-17-reverse-hand-2-4_09062024_171852.csv
Time (sec),S:Load (lbs),S:HL1 (DIM),S:LVDT (in),S:Position (in),Ch:Position (mm),Ch:Load (N),Ch:Stress (MPa),Ch:Strain (mm/mm),Ch:HL1 (DIM),Set Point (),Cycles ()
0.110000,0.018616,-382.313782,-0.008494,-0.003686,-0.093634,0.082807,0.004218,-0.936343,-382.313782,-0.093392,0.000000
0.500000,0.035744,-382.402740,-0.008515,-0.003647,-0.092646,0.158996,0.008100,-0.926457,-382.402740,-0.091900,0.000000
0.890000,0.036491,-382.313782,-0.008360,-0.003410,-0.086610,0.162322,0.008269,-0.866098,-382.313782,-0.085396,0.000000
1.280000,0.005211,-382.447205,-0.008127,-0.003164,-0.080357,0.023179,0.001181,-0.803571,-382.447205,-0.078891,0.000000
1.670000,-0.001862,-382.491699,-0.007838,-0.002896,-0.073549,-0.008281,-0.000422,-0.735494,-382.491699,-0.072405,0.000000
2.060000,0.016754,-382.447205,-0.007580,-0.002646,-0.067201,0.074526,0.003797,-0.672012,-382.447205,-0.065901,0.000000
2.450000,0.039841,-382.491699,-0.007299,-0.002387,-0.060628,0.177220,0.009028,-0.606278,-382.491699,-0.059414,0.000000
2.840000,0.040588,-382.447205,-0.007036,-0.002125,-0.053985,0.180546,0.009197,-0.539847,-382.447205,-0.052909,0.000000
3.230000,0.054367,-382.536194,-0.006786,-0.001873,-0.047585,0.241837,0.012320,-0.475846,-382.536194,-0.046405,0.000000
3.620000,0.033882,-382.536194,-0.006532,-0.001626,-0.041306,0.150715,0.007678,-0.413059,-382.536194,-0.039918,0.000000
4.010000,0.029045,-382.491699,-0.006265,-0.001365,-0.034680,0.129199,0.006582,-0.346802,-382.491699,-0.033414,0.000000
4.400000,0.042450,-382.580658,-0.005997,-0.001109,-0.028167,0.188827,0.009619,-0.281674,-382.580658,-0.026927,0.000000
4.790000,0.043564,-382.536194,-0.005734,-0.000855,-0.021724,0.193782,0.009872,-0.217240,-382.536194,-0.020423,0.000000
5.180000,0.042076,-382.580658,-0.005471,-0.000599,-0.015220,0.187164,0.009535,-0.152198,-382.580658,-0.013919,0.000000
5.570000,0.036865,-382.536194,-0.005226,-0.000346,-0.008776,0.163985,0.008354,-0.087762,-382.536194,-0.007432,0.000000
5.960001,0.061066,-382.625153,-0.004958,-0.000083,-0.002099,0.271634,0.013838,-0.020987,-382.625153,-0.000928,0.000000
6.350000,0.132187,-382.714111,-0.004799,-0.000002,-0.000061,0.587997,0.029954,-0.000607,-382.714111,0.000139,0.000000
6.740000,0.072235,-382.669617,-0.004794,-0.000003,-0.000069,0.321318,0.016369,-0.000693,-382.669617,0.000234,0.000000
7.130000,0.127724,-382.714111,-0.004794,-0.000002,-0.000052,0.568143,0.028943,-0.000520,-382.714111,0.000885,0.000000
7.520000,0.149689,-382.669617,-0.004777,0.000022,0.000546,0.665849,0.033920,0.005463,-382.669617,0.001535,0.000000
7.910000,0.205177,-382.758575,-0.004773,0.000045,0.001153,0.912674,0.046494,0.011534,-382.758575,0.002185,0.000000
8.300000,0.265503,-382.803070,-0.004756,0.000069,0.001761,1.181016,0.060164,0.017605,-382.803070,0.002836,0.000000
8.690001,0.448334,-382.803070,-0.004708,0.000094,0.002385,1.994288,0.101594,0.023849,-382.803070,0.003486,0.000000
9.080001,0.604729,-382.803070,-0.004717,0.000121,0.003061,2.689968,0.137033,0.030614,-382.803070,0.004137,0.000000
9.470000,0.767456,-382.803070,-0.004678,0.000150,0.003816,3.413815,0.173908,0.038157,-382.803070,0.004787,0.000000
9.860001,0.950294,-382.803070,-0.004648,0.000175,0.004458,4.227121,0.215340,0.044577,-382.803070,0.005438,0.000000
10.250001,1.067215,-382.936493,-0.004605,0.000198,0.005039,4.747209,0.241834,0.050386,-382.936493,0.006088,0.000000
10.640000,1.374428,-382.847534,-0.004587,0.000227,0.005776,6.113760,0.311450,0.057757,-382.847534,0.006738,0.000000
11.030001,1.472733,-382.936493,-0.004583,0.000241,0.006123,6.551042,0.333726,0.061226,-382.936493,0.007389,0.000000
11.420000,1.750893,-382.936493,-0.004540,0.000272,0.006912,7.788360,0.396758,0.069118,-382.936493,0.008039,0.000000
11.810000,2.013046,-383.025482,-0.004527,0.000302,0.007675,8.954477,0.456163,0.076750,-383.025482,0.008690,0.000000
12.200001,2.162369,-382.980988,-0.004506,0.000326,0.008282,9.618697,0.490000,0.082821,-382.980988,0.009340,0.000000
12.590000,2.481117,-382.980988,-0.004467,0.000355,0.009028,11.036561,0.562229,0.090279,-382.980988,0.009990,0.000000
12.980000,2.675125,-383.025482,-0.004445,0.000377,0.009583,11.899550,0.606192,0.095830,-383.025482,0.010641,0.000000
13.370001,3.030739,-382.980988,-0.004406,0.000409,0.010381,13.481400,0.686775,0.103806,-382.980988,0.011291,0.000000
13.760000,3.180428,-383.025482,-0.004398,0.000435,0.011040,14.147248,0.720695,0.110398,-383.025482,0.011942,0.000000
14.150001,3.361778,-383.203400,-0.004363,0.000458,0.011621,14.953937,0.761790,0.116210,-383.203400,0.012592,0.000000
14.540001,3.577011,-383.069946,-0.004329,0.000481,0.012219,15.911340,0.810562,0.122193,-383.069946,0.013243,0.000000
14.930000,3.842880,-383.158905,-0.004320,0.000505,0.012826,17.093985,0.870809,0.128263,-383.158905,0.013893,0.000000
15.320001,4.169823,-383.114441,-0.004277,0.000538,0.013659,18.548298,0.944895,0.136589,-383.114441,0.014535,0.000000
15.710001,4.287491,-383.158905,-0.004247,0.000563,0.014309,19.071712,0.971559,0.143092,-383.158905,0.015185,0.000000
16.100000,4.458038,-383.203400,-0.004221,0.000589,0.014960,19.830345,1.010206,0.149596,-383.203400,0.015836,0.000000
16.490002,4.734344,-383.247864,-0.004178,0.000615,0.015610,21.059416,1.072818,0.156100,-383.247864,0.016486,0.000000
16.880001,4.693008,-383.292358,-0.004195,0.000627,0.015931,20.875544,1.063451,0.159310,-383.292358,0.017136,0.000000
17.270000,5.254173,-383.247864,-0.004143,0.000665,0.016885,23.371731,1.190613,0.168850,-383.247864,0.017787,0.000000
17.660002,5.188263,-383.247864,-0.004126,0.000688,0.017466,23.078547,1.175677,0.174660,-383.247864,0.018437,0.000000
18.050001,5.331627,-383.292358,-0.004087,0.000712,0.018082,23.716261,1.208164,0.180818,-383.292358,0.019088,0.000000
18.440001,5.581863,-383.336823,-0.004057,0.000740,0.018801,24.829369,1.264868,0.188015,-383.336823,0.019738,0.000000
18.830002,5.698418,-383.381317,-0.004031,0.000760,0.019313,25.347828,1.291280,0.193132,-383.381317,0.020388,0.000000
19.220001,5.988121,-383.336823,-0.004001,0.000790,0.020068,26.636492,1.356928,0.200677,-383.336823,0.021039,0.000000
19.610001,5.965408,-383.381317,-0.003980,0.000809,0.020553,26.535461,1.351781,0.205533,-383.381317,0.021689,0.000000
20.000000,6.122917,-383.470276,-0.003923,0.000836,0.021238,27.236095,1.387473,0.212384,-383.470276,0.022340,0.000000
20.390001,6.299423,-383.425812,-0.003889,0.000866,0.022002,28.021235,1.427470,0.220016,-383.425812,0.022990,0.000000
20.780001,6.303146,-383.514771,-0.003872,0.000890,0.022609,28.037796,1.428313,0.226087,-383.514771,0.023641,0.000000
21.170000,6.338150,-383.470276,-0.003837,0.000916,0.023276,28.193499,1.436245,0.232763,-383.470276,0.024291,0.000000
21.560001,6.466988,-383.514771,-0.003798,0.000945,0.024005,28.766598,1.465440,0.240049,-383.514771,0.024942,0.000000
21.950001,6.344856,-383.603729,-0.003768,0.000961,0.024421,28.223330,1.437765,0.244211,-383.603729,0.025592,0.000000
22.340000,6.681107,-383.514771,-0.003729,0.000989,0.025132,29.719046,1.513960,0.251323,-383.514771,0.026242,0.000000
22.730001,6.858353,-383.559235,-0.003699,0.001017,0.025843,30.507477,1.554125,0.258435,-383.559235,0.026893,0.000000
23.120001,6.838615,-383.603729,-0.003665,0.001044,0.026529,30.419682,1.549652,0.265285,-383.603729,0.027543,0.000000
23.510000,7.023689,-383.559235,-0.003639,0.001073,0.027257,31.242929,1.591591,0.272569,-383.559235,0.028193,0.000000
23.900002,6.853516,-383.603729,-0.003587,0.001093,0.027769,30.485960,1.553029,0.277686,-383.603729,0.028844,0.000000
24.290001,6.990547,-383.692688,-0.003570,0.001115,0.028324,31.095507,1.584081,0.283237,-383.692688,0.029486,0.000000
24.680000,7.444839,-383.781647,-0.003540,0.001147,0.029139,33.116299,1.687025,0.291388,-383.781647,0.030136,0.000000
25.070002,7.400154,-383.692688,-0.003471,0.001174,0.029824,32.917530,1.676899,0.298240,-383.692688,0.030787,0.000000
25.460001,7.416916,-383.737152,-0.003475,0.001198,0.030440,32.992088,1.680697,0.304396,-383.737152,0.031437,0.000000
25.850000,7.446327,-383.781647,-0.003428,0.001218,0.030943,33.122917,1.687362,0.309427,-383.781647,0.032087,0.000000
26.240002,7.830620,-383.781647,-0.003393,0.001253,0.031836,34.832336,1.774444,0.318359,-383.781647,0.032738,0.000000
26.630001,7.733055,-383.826141,-0.003363,0.001272,0.032304,34.398346,1.752335,0.323043,-383.826141,0.033388,0.000000
27.020000,8.049202,-383.870605,-0.003320,0.001307,0.033189,35.804638,1.823975,0.331888,-383.870605,0.034039,0.000000
27.410002,8.029839,-383.826141,-0.003303,0.001329,0.033761,35.718506,1.819587,0.337611,-383.826141,0.034689,0.000000
27.800001,8.050690,-383.870605,-0.003264,0.001350,0.034290,35.811256,1.824312,0.342902,-383.870605,0.035340,0.000000
28.190001,8.306885,-383.870605,-0.003225,0.001376,0.034958,36.950871,1.882367,0.349579,-383.870605,0.035990,0.000000
28.580002,8.557114,-383.915100,-0.003199,0.001402,0.035608,38.063942,1.939070,0.356083,-383.915100,0.036640,0.000000
28.970001,8.696388,-383.870605,-0.003156,0.001427,0.036250,38.683468,1.970630,0.362500,-383.870605,0.037291,0.000000
29.360001,8.767509,-383.959564,-0.003143,0.001453,0.036918,38.999828,1.986746,0.369179,-383.959564,0.037941,0.000000
29.750002,8.626755,-384.048523,-0.003109,0.001474,0.037430,38.373722,1.954851,0.374296,-384.048523,0.038592,0.000000
30.140001,8.968590,-384.048523,-0.003074,0.001503,0.038175,39.894279,2.032311,0.381754,-384.048523,0.039242,0.000000
30.530001,9.176376,-383.959564,-0.003057,0.001529,0.038826,40.818562,2.079396,0.388256,-383.959564,0.039892,0.000000
30.920002,9.433685,-384.004059,-0.003005,0.001558,0.039580,41.963127,2.137704,0.395802,-384.004059,0.040543,0.000000
31.310001,9.417297,-384.048523,-0.002992,0.001583,0.040196,41.890232,2.133990,0.401960,-384.048523,0.041193,0.000000
31.700001,9.597900,-384.093018,-0.002966,0.001609,0.040864,42.693592,2.174915,0.408638,-384.093018,0.041844,0.000000
32.090000,9.682053,-384.093018,-0.002923,0.001632,0.041445,43.067921,2.193985,0.414448,-384.093018,0.042494,0.000000
32.480003,9.956123,-384.181976,-0.002906,0.001657,0.042095,44.287048,2.256090,0.420952,-384.181976,0.043145,0.000000
32.870003,10.141563,-384.093018,-0.002859,0.001684,0.042780,45.111927,2.298111,0.427803,-384.093018,0.043795,0.000000
33.260002,10.323280,-384.137482,-0.002820,0.001712,0.043483,45.920246,2.339289,0.434828,-384.137482,0.044437,0.000000
33.650002,10.308014,-384.137482,-0.002790,0.001734,0.044055,45.852337,2.335829,0.440550,-384.137482,0.045087,0.000000
34.040001,10.480797,-384.181976,-0.002764,0.001760,0.044714,46.620914,2.374983,0.447142,-384.181976,0.045738,0.000000
34.430000,10.563461,-384.270935,-0.002738,0.001785,0.045339,46.988621,2.393715,0.453387,-384.270935,0.046388,0.000000
34.820004,10.869179,-384.226440,-0.002703,0.001816,0.046119,48.348522,2.462991,0.461191,-384.226440,0.047038,0.000000
35.210003,10.837524,-384.315430,-0.002673,0.001841,0.046752,48.207718,2.455818,0.467523,-384.315430,0.047689,0.000000
35.600002,11.043449,-384.315430,-0.002639,0.001867,0.047420,49.123718,2.502481,0.474200,-384.315430,0.048339,0.000000
35.990002,11.061691,-384.315430,-0.002613,0.001888,0.047957,49.204861,2.506615,0.479575,-384.315430,0.048990,0.000000
36.380001,11.511147,-384.315430,-0.002570,0.001917,0.048695,51.204136,2.608463,0.486948,-384.315430,0.049640,0.000000
36.770000,11.651535,-384.404388,-0.002535,0.001945,0.049415,51.828617,2.640275,0.494146,-384.404388,0.050290,0.000000
37.160004,11.603127,-384.359894,-0.002496,0.001969,0.050022,51.613285,2.629306,0.500217,-384.359894,0.050941,0.000000
37.550003,11.629936,-384.404388,-0.002479,0.001993,0.050620,51.732540,2.635381,0.506201,-384.404388,0.051591,0.000000
37.940002,11.868622,-384.404388,-0.002432,0.002021,0.051323,52.794266,2.689468,0.513226,-384.404388,0.052242,0.000000
38.330002,11.808670,-384.493347,-0.002423,0.002038,0.051765,52.527588,2.675883,0.517647,-384.493347,0.052892,0.000000
38.720001,12.195198,-384.448853,-0.002389,0.002068,0.052528,54.246952,2.763472,0.525277,-384.448853,0.053542,0.000000
39.110001,12.287918,-384.493347,-0.002363,0.002097,0.053256,54.659389,2.784482,0.532563,-384.493347,0.054193,0.000000
39.500000,12.356430,-384.493347,-0.002337,0.002120,0.053846,54.964146,2.800007,0.538460,-384.493347,0.054843,0.000000
39.890003,12.240250,-384.493347,-0.002285,0.002141,0.054384,54.447350,2.773680,0.543838,-384.493347,0.055494,0.000000
40.280003,12.444313,-384.671265,-0.002272,0.002167,0.055051,55.355068,2.819921,0.550515,-384.671265,0.056144,0.000000
40.670002,12.767532,-384.582306,-0.002246,0.002192,0.055685,56.792820,2.893164,0.556847,-384.582306,0.056795,0.000000
41.060001,11.839951,-384.671265,-0.002233,0.002192,0.055676,52.666729,2.682971,0.556760,-384.671265,0.057445,0.000000
41.450001,12.791367,-384.715759,-0.002186,0.002236,0.056803,56.898842,2.898565,0.568031,-384.715759,0.058096,0.000000
41.840000,13.036758,-384.671265,-0.002147,0.002273,0.057740,57.990398,2.954172,0.577399,-384.671265,0.058746,0.000000
42.230003,12.934731,-384.760223,-0.002113,0.002296,0.058312,57.536556,2.931052,0.583122,-384.760223,0.059388,0.000000
42.620003,13.044952,-384.715759,-0.002065,0.002324,0.059032,58.026848,2.956028,0.590321,-384.715759,0.060038,0.000000
43.010002,13.198364,-384.760223,-0.002057,0.002352,0.059743,58.709255,2.990792,0.597432,-384.760223,0.060688,0.000000
43.400002,12.743698,-384.715759,-0.002026,0.002364,0.060047,56.686802,2.887763,0.600468,-384.715759,0.061339,0.000000
43.790001,13.456795,-384.715759,-0.001996,0.002395,0.060836,59.858814,3.049353,0.608359,-384.715759,0.061989,0.000000
44.180000,13.354019,-384.849182,-0.001970,0.002419,0.061443,59.401646,3.026064,0.614430,-384.849182,0.062640,0.000000
44.570004,13.799004,-384.760223,-0.001932,0.002453,0.062301,61.381035,3.126899,0.623015,-384.760223,0.063290,0.000000
44.960003,13.743896,-384.893677,-0.001901,0.002481,0.063013,61.135906,3.114412,0.630126,-384.893677,0.063941,0.000000
45.350002,13.485092,-384.893677,-0.001871,0.002501,0.063533,59.984684,3.055766,0.635331,-384.893677,0.064591,0.000000
45.740002,13.294815,-384.849182,-0.001845,0.002517,0.063923,59.138290,3.012648,0.639233,-384.849182,0.065242,0.000000
46.130001,14.082008,-384.938141,-0.001815,0.002555,0.064886,62.639900,3.191029,0.648858,-384.938141,0.065892,0.000000
46.520000,13.720436,-384.849182,-0.001776,0.002579,0.065519,61.031548,3.109095,0.655190,-384.849182,0.066542,0.000000
46.910004,13.817993,-384.938141,-0.001746,0.002606,0.066187,61.465504,3.131202,0.661866,-384.938141,0.067193,0.000000
47.300003,13.433334,-384.893677,-0.001720,0.002625,0.066681,59.754456,3.044037,0.666810,-384.893677,0.067843,0.000000
47.690002,14.095039,-384.938141,-0.001677,0.002657,0.067496,62.697868,3.193982,0.674962,-384.938141,0.068494,0.000000
48.080002,14.244362,-385.027100,-0.001669,0.002685,0.068199,63.362087,3.227818,0.681987,-385.027100,0.069144,0.000000
48.470001,14.245476,-384.938141,-0.001617,0.002711,0.068858,63.367043,3.228071,0.688576,-384.938141,0.069794,0.000000
48.860001,14.277130,-385.027100,-0.001600,0.002736,0.069500,63.507847,3.235244,0.694996,-385.027100,0.070445,0.000000
49.250004,14.478210,-385.071594,-0.001548,0.002759,0.070089,64.402298,3.280809,0.700893,-385.071594,0.071095,0.000000
49.640003,14.482307,-385.116089,-0.001531,0.002782,0.070670,64.420525,3.281738,0.706702,-385.116089,0.071746,0.000000
50.030003,14.519173,-385.116089,-0.001505,0.002805,0.071251,64.584503,3.290092,0.712512,-385.116089,0.072396,0.000000
50.420002,14.887077,-385.071594,-0.001483,0.002834,0.071989,66.221024,3.373460,0.719885,-385.071594,0.073046,0.000000
50.810001,14.887077,-385.160553,-0.001449,0.002862,0.072682,66.221024,3.373460,0.726823,-385.160553,0.073697,0.000000
51.200001,15.118690,-385.116089,-0.001431,0.002886,0.073315,67.251297,3.425944,0.733151,-385.116089,0.074339,0.000000
51.590004,14.425339,-385.205048,-0.001401,0.002895,0.073541,64.167114,3.268829,0.735407,-385.205048,0.074989,0.000000
51.980003,15.418449,-385.294006,-0.001358,0.002935,0.074555,68.584686,3.493870,0.745554,-385.294006,0.075639,0.000000
52.370003,15.342857,-385.205048,-0.001328,0.002963,0.075267,68.248436,3.476741,0.752666,-385.205048,0.076290,0.000000
52.760002,15.381584,-385.294006,-0.001293,0.002991,0.075978,68.420700,3.485517,0.759778,-385.294006,0.076940,0.000000
53.150002,15.621399,-385.249512,-0.001263,0.003015,0.076594,69.487450,3.539860,0.765936,-385.249512,0.077591,0.000000
53.540001,15.400948,-385.294006,-0.001224,0.003038,0.077157,68.506836,3.489905,0.771572,-385.294006,0.078241,0.000000
53.930004,15.841469,-385.294006,-0.001203,0.003062,0.077782,70.466370,3.589728,0.777817,-385.294006,0.078891,0.000000
54.320004,15.699966,-385.338470,-0.001164,0.003084,0.078328,69.836937,3.557663,0.783278,-385.338470,0.079542,0.000000
54.710003,16.074203,-385.338470,-0.001147,0.003116,0.079152,71.501625,3.642467,0.791518,-385.338470,0.080192,0.000000
55.100002,15.971428,-385.338470,-0.001104,0.003137,0.079689,71.044456,3.619177,0.796893,-385.338470,0.080843,0.000000
55.490002,16.153885,-385.382965,-0.001087,0.003163,0.080340,71.856071,3.660523,0.803399,-385.382965,0.081493,0.000000
55.880001,16.728462,-385.427429,-0.001043,0.003196,0.081181,74.411919,3.790724,0.811809,-385.427429,0.082144,0.000000
56.270004,16.831978,-385.338470,-0.001000,0.003224,0.081892,74.872375,3.814181,0.818921,-385.338470,0.082794,0.000000
56.660004,16.793999,-385.427429,-0.000979,0.003248,0.082490,74.703438,3.805574,0.824905,-385.427429,0.083445,0.000000
57.050003,16.882996,-385.427429,-0.000931,0.003272,0.083106,75.099312,3.825742,0.831063,-385.427429,0.084095,0.000000
57.440002,16.916138,-385.516388,-0.000918,0.003293,0.083644,75.246742,3.833252,0.836441,-385.516388,0.084745,0.000000
57.830002,18.053360,-385.605377,-0.000880,0.003324,0.084433,80.305359,4.090950,0.844332,-385.605377,0.085396,0.000000
58.220001,17.781158,-385.560883,-0.000841,0.003350,0.085083,79.094543,4.029268,0.850835,-385.560883,0.086046,0.000000
58.610004,18.004578,-385.605377,-0.000823,0.003378,0.085803,80.088364,4.079895,0.858034,-385.605377,0.086697,0.000000
59.000004,18.238800,-385.516388,-0.000785,0.003403,0.086437,81.130234,4.132971,0.864366,-385.516388,0.087347,0.000000
59.390003,18.088737,-385.605377,-0.000742,0.003420,0.086879,80.462723,4.098967,0.868787,-385.605377,0.087997,0.000000
59.780003,18.412697,-385.649841,-0.000724,0.003440,0.087382,81.903763,4.172377,0.873817,-385.649841,0.088648,0.000000
60.170002,19.522743,-385.649841,-0.000690,0.003475,0.088266,86.841499,4.423917,0.882662,-385.649841,0.089290,0.000000
60.560001,19.839256,-385.738800,-0.000664,0.003502,0.088960,88.249420,4.495640,0.889600,-385.738800,0.089940,0.000000
60.950005,20.353874,-385.738800,-0.000634,0.003527,0.089593,90.538551,4.612254,0.895932,-385.738800,0.090591,0.000000
61.340004,20.359093,-385.738800,-0.000604,0.003548,0.090122,90.561768,4.613436,0.901223,-385.738800,0.091241,0.000000
61.730003,20.894188,-385.827759,-0.000586,0.003572,0.090720,92.941986,4.734691,0.907203,-385.827759,0.091891,0.000000
62.120003,21.605423,-385.783295,-0.000578,0.003597,0.091354,96.105721,4.895859,0.913535,-385.783295,0.092542,0.000000
62.510002,22.348305,-385.872253,-0.000548,0.003626,0.092100,99.410225,5.064198,0.920996,-385.872253,0.093192,0.000000
62.900002,23.384613,-385.783295,-0.000517,0.003655,0.092836,104.019951,5.299029,0.928365,-385.783295,0.093842,0.000000
63.290005,23.480690,-385.827759,-0.000492,0.003673,0.093296,104.447327,5.320800,0.932963,-385.827759,0.094493,0.000000
63.680004,25.192116,-385.827759,-0.000457,0.003712,0.094276,112.060127,5.708615,0.942762,-385.827759,0.095143,0.000000
64.070000,25.333244,-385.872253,-0.000448,0.003732,0.094797,112.687897,5.740595,0.947967,-385.872253,0.095794,0.000000
64.460007,25.667633,-385.916718,-0.000418,0.003753,0.095325,114.175331,5.816369,0.953254,-385.916718,0.096444,0.000000
64.850006,26.299919,-385.916718,-0.000401,0.003776,0.095906,116.987885,5.959647,0.959064,-385.916718,0.097094,0.000000
65.240005,27.680305,-385.961212,-0.000388,0.003806,0.096679,123.128151,6.272447,0.966785,-385.961212,0.097745,0.000000
65.630005,28.890518,-385.961212,-0.000358,0.003835,0.097398,128.511444,6.546685,0.973980,-385.961212,0.098395,0.000000
66.020004,29.723885,-385.961212,-0.000332,0.003858,0.097988,132.218445,6.735528,0.979877,-385.961212,0.099046,0.000000
66.410004,30.856270,-386.050171,-0.000332,0.003885,0.098690,137.255539,6.992131,0.986902,-386.050171,0.099696,0.000000
66.800003,31.340729,-386.005707,-0.000293,0.003906,0.099219,139.410522,7.101911,0.992193,-386.005707,0.100347,0.000000
67.190002,31.343330,-386.050171,-0.000280,0.003924,0.099670,139.422104,7.102500,0.996705,-386.050171,0.100997,0.000000
67.580002,34.361412,-386.094666,-0.000254,0.003963,0.100650,152.847198,7.786407,1.006504,-386.094666,0.101648,0.000000
67.970001,34.948273,-386.094666,-0.000250,0.003987,0.101266,155.457687,7.919392,1.012658,-386.094666,0.102298,0.000000
68.360001,36.145447,-386.094666,-0.000233,0.004011,0.101890,160.782974,8.190675,1.018903,-386.094666,0.102949,0.000000
68.750000,37.631958,-386.094666,-0.000211,0.004038,0.102558,167.395309,8.527524,1.025580,-386.094666,0.103599,0.000000
69.140007,38.739395,-386.183624,-0.000207,0.004064,0.103217,172.321442,8.778473,1.032173,-386.183624,0.104241,0.000000
69.530006,40.556946,-386.228088,-0.000185,0.004093,0.103963,180.406311,9.190335,1.039629,-386.228088,0.104891,0.000000
69.920006,41.659538,-386.183624,-0.000181,0.004117,0.104570,185.310883,9.440187,1.045700,-386.183624,0.105541,0.000000
70.310005,42.945343,-386.228088,-0.000155,0.004140,0.105168,191.030426,9.731553,1.051684,-386.228088,0.106192,0.000000
70.700005,44.498878,-386.228088,-0.000138,0.004167,0.105853,197.940903,10.083590,1.058535,-386.228088,0.106842,0.000000
71.090004,45.892296,-386.272583,-0.000129,0.004191,0.106461,204.139130,10.399343,1.064606,-386.272583,0.107493,0.000000
71.480003,47.436523,-386.272583,-0.000125,0.004217,0.107120,211.008194,10.749269,1.071199,-386.272583,0.108143,0.000000
71.870003,48.873512,-386.317047,-0.000103,0.004240,0.107683,217.400238,11.074896,1.076835,-386.317047,0.108794,0.000000
72.260002,50.461678,-386.317047,-0.000099,0.004265,0.108325,224.464752,11.434780,1.083250,-386.317047,0.109444,0.000000
72.650002,52.301201,-386.317047,-0.000091,0.004289,0.108950,232.647354,11.851622,1.089495,-386.317047,0.110094,0.000000
73.040001,52.815445,-386.317047,-0.000082,0.004311,0.109496,234.934830,11.968151,1.094961,-386.317047,0.110745,0.000000
73.430000,55.986946,-386.450500,-0.000060,0.004343,0.110320,249.042374,12.686824,1.103197,-386.450500,0.111395,0.000000
73.820000,57.907639,-386.361542,-0.000056,0.004369,0.110979,257.586029,13.122058,1.109790,-386.361542,0.112046,0.000000
74.210007,59.450005,-386.450500,-0.000052,0.004392,0.111560,264.446838,13.471563,1.115600,-386.450500,0.112696,0.000000
74.600006,61.586304,-386.494995,-0.000043,0.004420,0.112280,273.949554,13.955656,1.122799,-386.494995,0.113346,0.000000
74.990005,62.642731,-386.494995,-0.000043,0.004437,0.112687,278.648773,14.195045,1.126875,-386.494995,0.113997,0.000000
75.380005,65.167419,-386.539459,-0.000017,0.004471,0.113572,289.879150,14.767148,1.135720,-386.539459,0.114647,0.000000
75.770004,65.809006,-386.494995,-0.000009,0.004474,0.113633,292.733063,14.912534,1.136326,-386.494995,0.019938,0.000000
76.160004,65.064636,-386.583954,-0.000022,0.004474,0.113633,289.421967,14.743857,1.136326,-386.583954,294.500458,0.000000
76.550003,66.150482,-386.583954,0.000000,0.004485,0.113927,294.252045,14.989913,1.139274,-386.583954,294.500458,0.000000
76.940002,65.622086,-386.494995,-0.000004,0.004485,0.113927,291.901611,14.870177,1.139274,-386.494995,294.500458,0.000000
77.330002,65.222153,-386.628418,0.000013,0.004485,0.113927,290.122620,14.779552,1.139274,-386.628418,294.500458,0.000000
77.720001,64.872498,-386.628418,0.000009,0.004485,0.113927,288.567291,14.700318,1.139274,-386.628418,294.500458,0.000000
78.110001,64.579071,-386.672913,0.000013,0.004485,0.113927,287.262054,14.633827,1.139274,-386.672913,294.500458,0.000000
78.500000,64.342239,-386.672913,0.000017,0.004485,0.113927,286.208588,14.580160,1.139274,-386.672913,294.500458,0.000000
78.890007,66.326233,-386.717377,0.000034,0.004310,0.109470,295.033813,15.029739,1.094700,-386.717377,294.500458,0.000000
79.280006,66.078979,-386.717377,0.000043,0.004310,0.109470,293.933990,14.973711,1.094700,-386.717377,294.500458,0.000000
79.670006,65.820557,-386.672913,0.000039,0.004311,0.109496,292.784454,14.915152,1.094961,-386.672913,294.500458,0.000000
80.060005,65.666397,-386.806335,0.000047,0.004330,0.109990,292.098724,14.880218,1.099904,-386.806335,294.500458,0.000000
80.450005,65.520798,-386.717377,0.000056,0.004433,0.112609,291.451050,14.847225,1.126091,-386.717377,294.500458,0.000000
80.840004,65.392700,-386.806335,0.000039,0.004462,0.113329,290.881256,14.818198,1.133290,-386.806335,294.500458,0.000000
81.230003,65.263489,-386.850830,0.000052,0.004466,0.113433,290.306488,14.788918,1.134331,-386.850830,294.500458,0.000000
81.620003,65.237793,-386.850830,0.000034,0.004482,0.113849,290.192200,14.783095,1.138494,-386.850830,294.500458,0.000000
82.010002,65.101883,-386.895325,0.000039,0.004489,0.114014,289.587646,14.752297,1.140141,-386.895325,294.500458,0.000000
82.400002,65.218796,-386.895325,0.000039,0.004498,0.114257,290.107697,14.778790,1.142571,-386.895325,294.500458,0.000000
82.790001,65.279877,-386.895325,0.000034,0.004503,0.114379,290.379395,14.792631,1.143786,-386.895325,294.500458,0.000000
83.180000,65.290298,-386.939789,0.000052,0.004504,0.114404,290.425751,14.794993,1.144043,-386.939789,294.500458,0.000000
83.570007,65.254913,-386.984283,0.000056,0.004505,0.114430,290.268341,14.786975,1.144304,-386.984283,294.500458,0.000000
83.960007,65.294769,-387.028748,0.000039,0.004508,0.114491,290.445648,14.796006,1.144910,-387.028748,294.500458,0.000000
84.350006,65.246735,-386.984283,0.000060,0.004508,0.114500,290.231964,14.785122,1.144997,-386.984283,294.500458,0.000000
84.740005,65.238159,-386.984283,0.000043,0.004509,0.114517,290.193817,14.783178,1.145171,-386.984283,294.500458,0.000000
85.130005,65.180069,-387.028748,0.000052,0.004509,0.114517,289.935425,14.770015,1.145171,-387.028748,294.500458,0.000000
85.520004,65.127197,-387.028748,0.000039,0.004510,0.114543,289.700256,14.758034,1.145432,-387.028748,294.500458,0.000000
85.910004,65.144699,-387.117706,0.000039,0.004511,0.114569,289.778107,14.762000,1.145693,-387.117706,294.500458,0.000000
86.300003,65.106339,-387.117706,0.000052,0.004511,0.114569,289.607452,14.753307,1.145693,-387.117706,294.500458,0.000000
86.690002,65.059418,-387.251160,0.000047,0.004511,0.114569,289.398743,14.742675,1.145693,-387.251160,294.500458,0.000000
87.080002,65.169281,-387.162201,0.000052,0.004513,0.114639,289.887451,14.767570,1.146386,-387.162201,294.500458,0.000000
87.470001,65.158478,-387.117706,0.000060,0.004513,0.114639,289.839386,14.765121,1.146386,-387.117706,294.500458,0.000000
87.860001,65.116776,-387.251160,0.000043,0.004514,0.114647,289.653870,14.755672,1.146473,-387.251160,294.500458,0.000000
88.250008,65.086975,-387.206665,0.000043,0.004514,0.114647,289.521332,14.748919,1.146473,-387.206665,294.500458,0.000000
88.640007,65.037079,-387.206665,0.000052,0.004514,0.114647,289.299377,14.737613,1.146473,-387.206665,294.500458,0.000000
89.030006,65.295883,-387.251160,0.000056,0.004519,0.114778,290.450592,14.796259,1.147775,-387.251160,294.500458,0.000000
89.420006,65.351364,-387.251160,0.000056,0.004519,0.114778,290.697388,14.808831,1.147775,-387.251160,294.500458,0.000000
89.810005,65.341690,-387.340118,0.000043,0.004519,0.114778,290.654358,14.806639,1.147775,-387.340118,294.500458,0.000000
90.200005,65.341309,-387.340118,0.000052,0.004519,0.114778,290.652649,14.806552,1.147775,-387.340118,294.500458,0.000000
90.590004,65.315613,-387.384613,0.000047,0.004519,0.114778,290.538361,14.800730,1.147775,-387.384613,294.500458,0.000000
90.980003,65.288803,-387.429077,0.000047,0.004519,0.114778,290.419098,14.794654,1.147775,-387.429077,294.500458,0.000000
91.370003,65.276154,-387.384613,0.000043,0.004519,0.114778,290.362823,14.791788,1.147775,-387.384613,294.500458,0.000000
91.760002,65.239288,-387.384613,0.000047,0.004519,0.114778,290.198853,14.783434,1.147775,-387.384613,294.500458,0.000000
92.150002,65.195709,-387.429077,0.000047,0.004519,0.114778,290.005005,14.773559,1.147775,-387.429077,294.500458,0.000000
92.540001,65.170761,-387.473572,0.000052,0.004519,0.114778,289.894012,14.767905,1.147775,-387.473572,294.500458,0.000000
92.930008,65.130173,-387.473572,0.000052,0.004519,0.114778,289.713470,14.758708,1.147775,-387.473572,294.500458,0.000000
93.320007,65.098892,-387.473572,0.000039,0.004519,0.114778,289.574341,14.751619,1.147775,-387.473572,294.500458,0.000000
93.710007,65.060547,-387.606995,0.000030,0.004519,0.114778,289.403778,14.742930,1.147775,-387.606995,294.500458,0.000000
94.100006,65.462708,-387.473572,0.000043,0.004525,0.114942,291.192657,14.834062,1.149421,-387.473572,294.500458,0.000000
94.490005,65.530472,-387.518036,0.000030,0.004525,0.114933,291.494110,14.849417,1.149334,-387.518036,294.500458,0.000000
94.880005,65.539780,-387.562531,0.000052,0.004525,0.114933,291.535492,14.851526,1.149334,-387.562531,294.500458,0.000000
95.270004,65.531601,-387.562531,0.000052,0.004525,0.114933,291.499115,14.849672,1.149334,-387.562531,294.500458,0.000000
95.660004,65.521912,-387.606995,0.000043,0.004525,0.114933,291.456024,14.847478,1.149334,-387.606995,294.500458,0.000000
96.050003,65.507019,-387.606995,0.000043,0.004525,0.114933,291.389771,14.844102,1.149334,-387.606995,294.500458,0.000000
96.440002,65.481689,-387.651489,0.000039,0.004525,0.114933,291.277100,14.838363,1.149334,-387.651489,294.500458,0.000000
96.830002,65.449677,-387.740448,0.000043,0.004525,0.114933,291.134705,14.831108,1.149334,-387.740448,294.500458,0.000000
97.220001,65.421005,-387.695984,0.000047,0.004525,0.114933,291.007172,14.824612,1.149334,-387.695984,294.500458,0.000000
97.610008,65.389343,-387.740448,0.000034,0.004525,0.114933,290.866333,14.817437,1.149334,-387.740448,294.500458,0.000000
98.000008,65.368118,-387.740448,0.000043,0.004525,0.114933,290.771912,14.812628,1.149334,-387.740448,294.500458,0.000000
98.390007,65.341309,-387.740448,0.000043,0.004525,0.114942,290.652649,14.806552,1.149421,-387.740448,294.500458,0.000000
98.780006,65.320084,-387.873901,0.000052,0.004525,0.114942,290.558258,14.801743,1.149421,-387.873901,294.500458,0.000000
99.170006,65.319717,-387.784943,0.000056,0.004525,0.114942,290.556610,14.801660,1.149421,-387.784943,294.500458,0.000000
99.560005,65.295883,-387.829407,0.000047,0.004525,0.114942,290.450592,14.796259,1.149421,-387.829407,294.500458,0.000000
99.950005,65.279495,-387.784943,0.000052,0.004525,0.114942,290.377686,14.792545,1.149421,-387.784943,294.500458,0.000000
100.340004,65.264603,-387.873901,0.000034,0.004525,0.114942,290.311462,14.789170,1.149421,-387.873901,294.500458,0.000000
100.730003,65.253433,-387.962860,0.000060,0.004526,0.114951,290.261780,14.786639,1.149509,-387.962860,294.500458,0.000000
101.120003,65.231461,-387.918365,0.000039,0.004526,0.114951,290.164032,14.781660,1.149509,-387.918365,294.500458,0.000000
101.510002,65.215820,-387.962860,0.000034,0.004526,0.114951,290.094452,14.778116,1.149509,-387.962860,294.500458,0.000000
101.900002,65.203903,-387.962860,0.000030,0.004526,0.114951,290.041443,14.775416,1.149509,-387.962860,294.500458,0.000000
102.290009,65.183060,-387.962860,0.000047,0.004526,0.114951,289.948730,14.770692,1.149509,-387.962860,294.500458,0.000000
102.680008,65.142471,-388.007324,0.000052,0.004526,0.114951,289.768188,14.761495,1.149509,-388.007324,294.500458,0.000000
103.070007,65.108582,-387.962860,0.000034,0.004526,0.114960,289.617432,14.753816,1.149596,-387.962860,294.500458,0.000000
103.460007,65.292160,-388.096283,0.000039,0.004529,0.115046,290.434021,14.795415,1.150462,-388.096283,294.500458,0.000000
103.850006,65.325668,-388.096283,0.000056,0.004529,0.115046,290.583099,14.803008,1.150462,-388.096283,294.500458,0.000000
104.240005,65.341690,-388.140778,0.000043,0.004529,0.115046,290.654358,14.806639,1.150462,-388.140778,294.500458,0.000000
104.630005,65.338699,-388.096283,0.000052,0.004529,0.115046,290.641052,14.805962,1.150462,-388.096283,294.500458,0.000000
105.020004,65.330887,-388.096283,0.000043,0.004529,0.115046,290.606293,14.804191,1.150462,-388.096283,294.500458,0.000000
105.410004,65.322693,-388.229736,0.000039,0.004529,0.115046,290.569855,14.802334,1.150462,-388.229736,294.500458,0.000000
105.800003,65.312271,-388.096283,0.000043,0.004529,0.115046,290.523499,14.799972,1.150462,-388.096283,294.500458,0.000000
106.190002,65.314133,-388.185272,0.000047,0.004529,0.115046,290.531769,14.800394,1.150462,-388.185272,294.500458,0.000000
106.580002,65.294022,-388.185272,0.000056,0.004529,0.115046,290.442322,14.795836,1.150462,-388.185272,294.500458,0.000000
106.970009,65.310410,-388.185272,0.000056,0.004529,0.115046,290.515198,14.799551,1.150462,-388.185272,294.500458,0.000000
107.360008,65.275772,-388.318695,0.000043,0.004529,0.115046,290.361145,14.791701,1.150462,-388.318695,294.500458,0.000000
107.750008,65.279877,-388.185272,0.000065,0.004529,0.115046,290.379395,14.792631,1.150462,-388.185272,294.500458,0.000000
108.140007,65.251572,-388.274231,0.000043,0.004529,0.115046,290.253479,14.786218,1.150462,-388.274231,294.500458,0.000000
108.530006,65.251938,-388.318695,0.000060,0.004529,0.115046,290.255127,14.786300,1.150462,-388.318695,294.500458,0.000000
108.920006,65.230347,-388.363190,0.000039,0.004529,0.115046,290.159088,14.781407,1.150462,-388.363190,294.500458,0.000000
109.310005,65.211731,-388.363190,0.000043,0.004529,0.115046,290.076263,14.777190,1.150462,-388.363190,294.500458,0.000000
109.700005,65.189377,-388.407654,0.000052,0.004529,0.115046,289.976837,14.772124,1.150462,-388.407654,294.500458,0.000000
110.090004,65.173737,-388.407654,0.000043,0.004529,0.115046,289.907257,14.768580,1.150462,-388.407654,294.500458,0.000000
110.480003,65.165924,-388.452148,0.000047,0.004529,0.115046,289.872498,14.766809,1.150462,-388.452148,294.500458,0.000000
110.870003,65.145065,-388.363190,0.000052,0.004529,0.115046,289.779724,14.762082,1.150462,-388.363190,294.500458,0.000000
111.260002,65.125336,-388.496613,0.000039,0.004529,0.115046,289.691956,14.757612,1.150462,-388.496613,294.500458,0.000000
111.650002,65.102615,-388.496613,0.000047,0.004529,0.115046,289.590881,14.752463,1.150462,-388.496613,294.500458,0.000000
112.040009,65.096283,-388.541107,0.000043,0.004529,0.115046,289.562714,14.751029,1.150462,-388.541107,294.500458,0.000000
112.430008,65.082520,-388.496613,0.000047,0.004529,0.115046,289.501495,14.747910,1.150462,-388.496613,294.500458,0.000000
112.820007,65.060165,-388.541107,0.000047,0.004529,0.115046,289.402069,14.742845,1.150462,-388.541107,294.500458,0.000000
113.210007,65.047882,-388.630066,0.000039,0.004529,0.115046,289.347443,14.740061,1.150462,-388.630066,294.500458,0.000000
113.600006,65.036713,-388.630066,0.000039,0.004530,0.115055,289.297760,14.737530,1.150549,-388.630066,294.500458,0.000000
113.990005,65.038574,-388.630066,0.000047,0.004530,0.115055,289.306030,14.737952,1.150549,-388.630066,294.500458,0.000000
114.380005,65.018097,-388.630066,0.000060,0.004530,0.115055,289.214935,14.733311,1.150549,-388.630066,294.500458,0.000000
114.770004,65.024048,-388.630066,0.000047,0.004530,0.115055,289.241425,14.734660,1.150549,-388.630066,294.500458,0.000000
115.160004,65.049377,-388.674561,0.000052,0.004532,0.115107,289.354095,14.740399,1.151068,-388.674561,294.500458,0.000000
115.550003,65.075439,-388.674561,0.000047,0.004532,0.115107,289.470001,14.746305,1.151068,-388.674561,294.500458,0.000000
115.940002,65.063889,-388.719025,0.000052,0.004532,0.115107,289.418640,14.743688,1.151068,-388.719025,294.500458,0.000000
116.330002,65.080276,-388.674561,0.000060,0.004532,0.115107,289.491516,14.747402,1.151068,-388.674561,294.500458,0.000000
116.720009,65.059418,-388.763519,0.000039,0.004532,0.115107,289.398743,14.742675,1.151068,-388.763519,294.500458,0.000000
117.110008,65.057556,-388.807983,0.000043,0.004532,0.115107,289.390472,14.742252,1.151068,-388.807983,294.500458,0.000000
117.500008,65.043045,-388.763519,0.000047,0.004532,0.115107,289.325928,14.738965,1.151068,-388.763519,294.500458,0.000000
117.890007,65.043793,-388.763519,0.000043,0.004532,0.115107,289.329254,14.739134,1.151068,-388.763519,294.500458,0.000000
118.280006,65.034851,-388.852478,0.000052,0.004532,0.115107,289.289459,14.737107,1.151068,-388.852478,294.500458,0.000000
118.670006,65.025162,-388.807983,0.000039,0.004532,0.115107,289.246368,14.734913,1.151068,-388.807983,294.500458,0.000000
119.060005,65.029633,-388.941437,0.000060,0.004532,0.115107,289.266266,14.735926,1.151068,-388.941437,294.500458,0.000000
119.450005,65.009521,-388.852478,0.000039,0.004532,0.115107,289.176788,14.731368,1.151068,-388.852478,294.500458,0.000000
119.840004,65.006927,-388.985931,0.000043,0.004532,0.115107,289.165253,14.730780,1.151068,-388.985931,294.500458,0.000000
120.230003,64.992767,-388.941437,0.000039,0.004532,0.115107,289.102264,14.727571,1.151068,-388.941437,294.500458,0.000000
120.620003,64.980103,-388.985931,0.000052,0.004532,0.115107,289.045929,14.724701,1.151068,-388.985931,294.500458,0.000000
121.010002,64.971924,-389.030396,0.000047,0.004532,0.115107,289.009552,14.722848,1.151068,-389.030396,294.500458,0.000000
121.400009,64.961868,-388.941437,0.000047,0.004532,0.115107,288.964813,14.720570,1.151068,-388.941437,294.500458,0.000000
121.790009,64.955154,-389.030396,0.000047,0.004532,0.115107,288.934967,14.719049,1.151068,-389.030396,294.500458,0.000000
122.180008,64.946228,-388.985931,0.000043,0.004532,0.115107,288.895264,14.717026,1.151068,-388.985931,294.500458,0.000000
122.570007,64.939514,-389.030396,0.000047,0.004532,0.115107,288.865387,14.715504,1.151068,-389.030396,294.500458,0.000000
122.960007,64.925751,-389.119354,0.000043,0.004532,0.115107,288.804169,14.712385,1.151068,-389.119354,294.500458,0.000000
123.350006,64.908615,-389.074890,0.000047,0.004532,0.115107,288.727936,14.708503,1.151068,-389.074890,294.500458,0.000000
123.740005,64.906754,-389.163849,0.000052,0.004532,0.115107,288.719666,14.708080,1.151068,-389.163849,294.500458,0.000000
124.130005,64.882553,-389.119354,0.000047,0.004532,0.115107,288.612000,14.702597,1.151068,-389.119354,294.500458,0.000000
124.520004,65.536057,-389.163849,0.000043,0.004540,0.115306,291.518951,14.850682,1.153063,-389.163849,294.500458,0.000000
124.910004,65.559143,-389.163849,0.000047,0.004540,0.115306,291.621643,14.855914,1.153063,-389.163849,294.500458,0.000000
125.300003,65.586334,-389.208313,0.000052,0.004540,0.115306,291.742584,14.862076,1.153063,-389.208313,294.500458,0.000000
125.690002,65.591553,-389.208313,0.000030,0.004540,0.115306,291.765808,14.863258,1.153063,-389.208313,294.500458,0.000000
126.080009,65.582977,-389.252808,0.000060,0.004540,0.115306,291.727661,14.861315,1.153063,-389.252808,294.500458,0.000000
126.470009,65.585587,-389.252808,0.000039,0.004540,0.115306,291.739258,14.861906,1.153063,-389.252808,294.500458,0.000000
126.860008,65.582977,-389.341766,0.000056,0.004540,0.115306,291.727661,14.861315,1.153063,-389.341766,294.500458,0.000000
127.250008,65.588943,-389.297272,0.000043,0.004540,0.115306,291.754181,14.862667,1.153063,-389.297272,294.500458,0.000000
127.640007,65.584839,-389.341766,0.000052,0.004540,0.115306,291.735931,14.861737,1.153063,-389.341766,294.500458,0.000000
128.029999,65.575531,-389.386230,0.000052,0.004540,0.115306,291.694519,14.859628,1.153063,-389.386230,294.500458,0.000000
128.420013,65.596008,-389.386230,0.000047,0.004540,0.115306,291.785614,14.864268,1.153063,-389.386230,294.500458,0.000000
128.810013,65.582977,-389.475220,0.000043,0.004540,0.115306,291.727661,14.861315,1.153063,-389.475220,294.500458,0.000000
129.200012,65.586334,-389.475220,0.000039,0.004540,0.115306,291.742584,14.862076,1.153063,-389.475220,294.500458,0.000000
129.590012,65.573669,-389.475220,0.000047,0.004540,0.115306,291.686249,14.859206,1.153063,-389.475220,294.500458,0.000000
129.980011,65.571060,-389.475220,0.000069,0.004540,0.115306,291.674652,14.858614,1.153063,-389.475220,294.500458,0.000000
130.370010,65.567719,-389.475220,0.000043,0.004540,0.115306,291.659790,14.857858,1.153063,-389.475220,294.500458,0.000000
130.760010,65.565109,-389.608643,0.000056,0.004540,0.115306,291.648163,14.857265,1.153063,-389.608643,294.500458,0.000000
131.150009,65.562500,-389.519684,0.000047,0.004540,0.115306,291.636566,14.856675,1.153063,-389.519684,294.500458,0.000000
131.540009,65.552826,-389.564178,0.000039,0.004540,0.115306,291.593536,14.854483,1.153063,-389.564178,294.500458,0.000000
131.930008,65.562866,-389.564178,0.000039,0.004540,0.115306,291.638184,14.856758,1.153063,-389.564178,294.500458,0.000000
132.320007,65.547974,-389.608643,0.000034,0.004540,0.115306,291.571960,14.853383,1.153063,-389.608643,294.500458,0.000000
132.710007,65.555801,-389.608643,0.000047,0.004540,0.115306,291.606781,14.855157,1.153063,-389.608643,294.500458,0.000000
133.100006,65.541275,-389.653137,0.000047,0.004540,0.115306,291.542145,14.851865,1.153063,-389.653137,294.500458,0.000000
133.490005,65.530106,-389.697601,0.000047,0.004540,0.115306,291.492462,14.849334,1.153063,-389.697601,294.500458,0.000000
133.880005,65.508881,-389.697601,0.000047,0.004540,0.115306,291.398041,14.844524,1.153063,-389.697601,294.500458,0.000000
134.270004,65.513351,-389.742096,0.000056,0.004540,0.115306,291.417938,14.845537,1.153063,-389.742096,294.500458,0.000000
134.660004,65.507019,-389.831055,0.000052,0.004540,0.115306,291.389771,14.844102,1.153063,-389.831055,294.500458,0.000000
135.050003,65.504044,-389.742096,0.000056,0.004540,0.115306,291.376526,14.843429,1.153063,-389.742096,294.500458,0.000000
135.440002,65.498077,-389.786560,0.000052,0.004540,0.115306,291.350006,14.842077,1.153063,-389.786560,294.500458,0.000000
135.830002,65.481689,-389.875549,0.000052,0.004540,0.115306,291.277100,14.838363,1.153063,-389.875549,294.500458,0.000000
136.220001,65.485046,-389.875549,0.000047,0.004540,0.115306,291.292023,14.839124,1.153063,-389.875549,1681.640747,0.000000
136.610001,65.368866,-389.920013,0.000039,0.004527,0.114994,290.775238,14.812798,1.149940,-389.920013,0.114786,0.000000
137.000000,65.365509,-389.831055,0.000052,0.004510,0.114543,290.760315,14.812036,1.145432,-389.831055,0.114136,0.000000
137.389999,65.322693,-389.920013,0.000043,0.004481,0.113815,290.569855,14.802334,1.138146,-389.920013,0.113485,0.000000
137.780014,65.248596,-389.920013,0.000052,0.004462,0.113329,290.240265,14.785542,1.133290,-389.920013,0.112835,0.000000
138.170013,65.279877,-389.920013,0.000056,0.004443,0.112843,290.379395,14.792631,1.128434,-389.920013,0.112184,0.000000
138.560013,65.232574,-389.920013,0.000039,0.004413,0.112089,290.168976,14.781913,1.120891,-389.920013,0.111534,0.000000
138.950012,65.181564,-389.920013,0.000052,0.004393,0.111577,289.942078,14.770354,1.115774,-389.920013,0.110884,0.000000
139.340012,65.205017,-390.008972,0.000056,0.004367,0.110918,290.046417,14.775668,1.109180,-390.008972,0.110233,0.000000
139.730011,65.178589,-390.053467,0.000052,0.004340,0.110242,289.928833,14.769679,1.102417,-390.053467,0.109591,0.000000
140.120010,64.955902,-390.008972,0.000056,0.004315,0.109591,288.938293,14.719218,1.095914,-390.008972,0.108941,0.000000
140.510010,64.090134,-390.097931,0.000039,0.004292,0.109019,285.087158,14.523031,1.090192,-390.097931,0.108291,0.000000
140.900009,63.077660,-390.097931,0.000056,0.004266,0.108351,280.583435,14.293602,1.083511,-390.097931,0.107640,0.000000
141.290009,62.199608,-390.097931,0.000086,0.004250,0.107952,276.677673,14.094633,1.079522,-390.097931,0.106990,0.000000
141.680008,60.321732,-390.142426,0.000078,0.004217,0.107111,268.324463,13.669100,1.071112,-390.142426,0.106339,0.000000
142.070007,58.956612,-390.142426,0.000086,0.004198,0.106634,262.252106,13.359759,1.066339,-390.142426,0.105689,0.000000
142.460007,56.886971,-390.186890,0.000095,0.004172,0.105966,253.045883,12.890772,1.059663,-390.186890,0.105039,0.000000
142.850006,54.951004,-390.142426,0.000086,0.004151,0.105429,244.434280,12.452076,1.054288,-390.142426,0.104388,0.000000
143.240005,52.446426,-390.231384,0.000095,0.004124,0.104743,233.293350,11.884530,1.047434,-390.231384,0.103738,0.000000
143.630005,49.831253,-390.231384,0.000091,0.004097,0.104058,221.660477,11.291924,1.040583,-390.231384,0.103087,0.000000
144.020004,47.306198,-390.231384,0.000091,0.004074,0.103469,210.428482,10.719738,1.034686,-390.231384,0.102437,0.000000
144.410004,45.349007,-390.320343,0.000091,0.004059,0.103087,201.722458,10.276232,1.030871,-390.320343,0.101786,0.000000
144.800003,42.187561,-390.231384,0.000082,0.004029,0.102341,187.659637,9.559838,1.023415,-390.231384,0.101136,0.000000
145.190002,39.267418,-390.275879,0.000091,0.004003,0.101665,174.670197,8.898125,1.016647,-390.275879,0.100485,0.000000
145.580002,35.813667,-390.364838,0.000099,0.003968,0.100798,159.307144,8.115493,1.007976,-390.364838,0.099835,0.000000
145.970001,33.664330,-390.364838,0.000099,0.003949,0.100312,149.746414,7.628446,1.003120,-390.364838,0.099184,0.000000
146.360001,30.520760,-390.409302,0.000086,0.003920,0.099575,135.763123,6.916103,0.995747,-390.409302,0.098534,0.000000
146.750000,29.082291,-390.320343,0.000095,0.003911,0.099332,129.364487,6.590141,0.993321,-390.320343,0.097884,0.000000
147.139999,28.812691,-390.364838,0.000082,0.003890,0.098812,128.165253,6.529049,0.988117,-390.364838,0.097233,0.000000
147.530014,22.149460,-390.453796,0.000086,0.003843,0.097624,98.525719,5.019139,0.976236,-390.453796,0.096583,0.000000
147.920013,19.252769,-390.453796,0.000099,0.003821,0.097051,85.640594,4.362740,0.970513,-390.453796,0.095933,0.000000
148.310013,16.995079,-390.498260,0.000095,0.003801,0.096548,75.597885,3.851140,0.965483,-390.498260,0.095282,0.000000
148.700012,13.084419,-390.453796,0.000091,0.003764,0.095594,58.202404,2.964972,0.955941,-390.453796,0.094640,0.000000
149.090012,11.462364,-390.409302,0.000095,0.003745,0.095126,50.987141,2.597409,0.951260,-390.409302,0.093990,0.000000
149.480011,8.145645,-390.542755,0.000073,0.003720,0.094476,36.233639,1.845830,0.944757,-390.542755,0.093339,0.000000
149.870010,5.103363,-390.453796,0.000091,0.003690,0.093730,22.700893,1.156439,0.937297,-390.453796,0.092689,0.000000
150.260010,2.922752,-390.542755,0.000099,0.003670,0.093227,13.001052,0.662305,0.932267,-390.542755,0.092039,0.000000
150.650009,0.336250,-390.587219,0.000108,0.003644,0.092559,1.495716,0.076195,0.925590,-390.587219,0.091388,0.000000
151.040009,-0.202576,-390.587219,0.000103,0.003620,0.091943,-0.901102,-0.045904,0.919432,-390.587219,0.090738,0.000000
151.430008,-0.027557,-390.587219,0.000099,0.003587,0.091111,-0.122581,-0.006245,0.911109,-390.587219,0.090088,0.000000
151.820007,0.131447,-390.587219,0.000099,0.003563,0.090513,0.584705,0.029786,0.905125,-390.587219,0.089437,0.000000
152.210007,0.116180,-390.631714,0.000082,0.003533,0.089732,0.516796,0.026327,0.897317,-390.631714,0.088787,0.000000
152.600006,0.113945,-390.720673,0.000047,0.003505,0.089021,0.506853,0.025820,0.890209,-390.720673,0.088136,0.000000
152.990005,0.140381,-390.631714,-0.000017,0.003484,0.088492,0.624445,0.031811,0.884918,-390.631714,0.087486,0.000000
153.380005,0.129585,-390.720673,-0.000099,0.003452,0.087685,0.576424,0.029364,0.876852,-390.720673,0.086836,0.000000
153.770004,0.140381,-390.676178,-0.000134,0.003429,0.087104,0.624445,0.031811,0.871042,-390.676178,0.086185,0.000000
154.160004,0.186928,-390.720673,-0.000229,0.003404,0.086454,0.831496,0.042358,0.864536,-390.720673,0.085535,0.000000
154.550003,0.151550,-390.765167,-0.000276,0.003381,0.085890,0.674129,0.034342,0.858901,-390.765167,0.084884,0.000000
154.940002,0.171288,-390.765167,-0.000336,0.003368,0.085535,0.761925,0.038814,0.855347,-390.765167,0.084234,0.000000
155.330002,0.116554,-390.854126,-0.000431,0.003333,0.084650,0.518459,0.026412,0.846501,-390.854126,0.083583,0.000000
155.720001,0.112083,-390.854126,-0.000504,0.003303,0.083895,0.498572,0.025398,0.838954,-390.854126,0.082933,0.000000
156.110001,0.131447,-390.854126,-0.000569,0.003289,0.083540,0.584705,0.029786,0.835400,-390.854126,0.082282,0.000000
156.500000,0.081177,-390.943085,-0.000617,0.003255,0.082673,0.361092,0.018395,0.826725,-390.943085,0.081632,0.000000
156.890015,0.091599,-390.898590,-0.000677,0.003245,0.082430,0.407451,0.020757,0.824299,-390.898590,0.080981,0.000000
157.280014,0.058830,-390.943085,-0.000742,0.003205,0.081398,0.261690,0.013331,0.813978,-390.943085,0.080331,0.000000
157.670013,0.053619,-390.898590,-0.000785,0.003182,0.080825,0.238511,0.012150,0.808255,-390.898590,0.079689,0.000000
158.060013,0.076706,-390.943085,-0.000841,0.003159,0.080227,0.341205,0.017382,0.802271,-390.943085,0.079039,0.000000
158.450012,0.014893,-391.032043,-0.000931,0.003128,0.079447,0.066245,0.003375,0.794466,-391.032043,0.078388,0.000000
158.840012,0.007072,-390.987549,-0.000974,0.003110,0.079004,0.031460,0.001603,0.790042,-390.987549,0.077738,0.000000
159.230011,0.033882,-390.987549,-0.001013,0.003070,0.077989,0.150715,0.007678,0.779895,-390.987549,0.077088,0.000000
159.620010,0.017128,-391.076508,-0.001030,0.003050,0.077461,0.076189,0.003881,0.774607,-391.076508,0.076437,0.000000
160.010010,0.019737,-390.987549,-0.001065,0.003033,0.077044,0.087796,0.004473,0.770444,-390.987549,0.075787,0.000000
160.400009,0.032021,-391.121002,-0.001121,0.003006,0.076342,0.142435,0.007256,0.763419,-391.121002,0.075136,0.000000
160.790009,0.043564,-391.121002,-0.001143,0.002992,0.076004,0.193782,0.009872,0.760035,-391.121002,0.075917,0.000000
160.800003,0.040215,-391.165497,-0.001130,0.002992,0.076004,0.178883,0.009113,0.760035,-391.165497,0.075917,0.000000