File: Data/compression 17/ManualNoHeating-10-17-reverse-hand-1-2_09062024_165354.csv
Time (sec),S:Load (lbs),S:HL1 (DIM),S:LVDT (in),S:Position (in),Ch:Position (mm),Ch:Load (N),Ch:Stress (MPa),Ch:Strain (mm/mm),Ch:HL1 (DIM),Set Point (),Cycles ()
0.010000,0.069633,-289.615479,-0.010425,-0.004822,-0.122478,0.309745,0.015779,-1.224783,-289.615479,-0.122218,0.000000
0.460000,-0.018250,-289.570984,-0.010408,-0.004738,-0.120354,-0.081178,-0.004135,-1.203536,-289.570984,-0.119790,0.000000
0.910000,0.046921,-289.570984,-0.010231,-0.004466,-0.113433,0.208714,0.010632,-1.134331,-289.570984,-0.112297,0.000000
1.360000,0.083412,-289.659943,-0.009929,-0.004174,-0.106027,0.371036,0.018901,-1.060270,-289.659943,-0.104787,0.000000
1.810000,0.068886,-289.704437,-0.009606,-0.003873,-0.098387,0.306419,0.015610,-0.983866,-289.704437,-0.097294,0.000000
2.260000,0.002975,-289.704437,-0.009321,-0.003585,-0.091067,0.013236,0.000674,-0.910672,-289.704437,-0.089801,0.000000
2.710000,0.063675,-289.793396,-0.009011,-0.003289,-0.083531,0.283240,0.014429,-0.835311,-289.793396,-0.082308,0.000000
3.160000,0.064789,-289.793396,-0.008705,-0.002990,-0.075934,0.288195,0.014681,-0.759343,-289.793396,-0.074815,0.000000
3.610000,0.066650,-289.837891,-0.008395,-0.002697,-0.068502,0.296476,0.015103,-0.685021,-289.837891,-0.067305,0.000000
4.060000,0.037605,-289.926849,-0.008110,-0.002403,-0.061044,0.167277,0.008521,-0.610439,-289.926849,-0.059813,0.000000
4.510000,0.024574,-289.882355,-0.007804,-0.002106,-0.053499,0.109312,0.005569,-0.534991,-289.882355,-0.052320,0.000000
4.960000,0.014519,-289.971313,-0.007485,-0.001810,-0.045972,0.064583,0.003290,-0.459715,-289.971313,-0.044827,0.000000
5.410000,0.077454,-289.971313,-0.007187,-0.001514,-0.038461,0.344531,0.017551,-0.384613,-289.971313,-0.037317,0.000000
5.860000,0.078194,-289.971313,-0.006881,-0.001220,-0.030995,0.347823,0.017719,-0.309945,-289.971313,-0.029824,0.000000
6.310000,0.048782,-290.015808,-0.006597,-0.000926,-0.023510,0.216995,0.011054,-0.235104,-290.015808,-0.022331,0.000000
6.760000,0.054733,-290.060272,-0.006299,-0.000631,-0.016018,0.243466,0.012403,-0.160177,-290.060272,-0.014838,0.000000
7.210001,0.081917,-290.015808,-0.005989,-0.000337,-0.008568,0.364384,0.018563,-0.085681,-290.015808,-0.007328,0.000000
7.660000,0.064415,-290.104767,-0.005678,-0.000039,-0.000980,0.286532,0.014597,-0.009799,-290.104767,0.000165,0.000000
8.110001,0.095695,-290.193726,-0.005553,0.000010,0.000252,0.425675,0.021685,0.002515,-290.193726,0.000442,0.000000
8.560000,0.079315,-290.149231,-0.005562,0.000010,0.000252,0.352812,0.017973,0.002515,-290.149231,0.000780,0.000000
9.010000,0.068146,-290.238220,-0.005549,0.000021,0.000529,0.303127,0.015442,0.005289,-290.238220,0.001535,0.000000
9.460000,0.064415,-290.238220,-0.005553,0.000047,0.001205,0.286532,0.014597,0.012055,-290.238220,0.002281,0.000000
9.910001,0.055107,-290.238220,-0.005506,0.000080,0.002021,0.245129,0.012487,0.020206,-290.238220,0.003035,0.000000
10.360001,0.094582,-290.282684,-0.005480,0.000108,0.002749,0.420720,0.021432,0.027492,-290.282684,0.003781,0.000000
10.810000,0.082291,-290.327179,-0.005445,0.000139,0.003530,0.366047,0.018647,0.035296,-290.327179,0.004536,0.000000
11.260000,0.087875,-290.371643,-0.005415,0.000172,0.004371,0.390889,0.019913,0.043708,-290.371643,0.005281,0.000000
11.710001,0.091972,-290.371643,-0.005389,0.000202,0.005143,0.409113,0.020841,0.051427,-290.371643,0.006036,0.000000
12.160001,0.102402,-290.416138,-0.005355,0.000226,0.005750,0.455506,0.023205,0.057496,-290.416138,0.006782,0.000000
12.610001,0.124741,-290.416138,-0.005333,0.000259,0.006582,0.554874,0.028267,0.065823,-290.416138,0.007536,0.000000
13.060000,0.126602,-290.505096,-0.005290,0.000289,0.007328,0.563155,0.028688,0.073281,-290.505096,0.008282,0.000000
13.510000,0.180229,-290.505096,-0.005264,0.000316,0.008031,0.801699,0.040841,0.080306,-290.505096,0.009036,0.000000
13.960001,0.253212,-290.505096,-0.005234,0.000340,0.008629,1.126343,0.057379,0.086290,-290.505096,0.009782,0.000000
14.410001,0.336250,-290.594055,-0.005208,0.000372,0.009461,1.495716,0.076195,0.094615,-290.594055,0.010537,0.000000
14.860001,0.421150,-290.594055,-0.005187,0.000405,0.010285,1.873370,0.095434,0.102853,-290.594055,0.011283,0.000000
15.310000,0.522812,-290.638519,-0.005161,0.000429,0.010892,2.325583,0.118471,0.108924,-290.638519,0.012037,0.000000
15.760001,0.686653,-290.638519,-0.005118,0.000462,0.011725,3.054386,0.155598,0.117248,-290.638519,0.012783,0.000000
16.210001,0.806183,-290.727509,-0.005113,0.000491,0.012479,3.586081,0.182684,0.124794,-290.727509,0.013537,0.000000
16.660000,0.959976,-290.727509,-0.005057,0.000521,0.013243,4.270187,0.217534,0.132426,-290.727509,0.014283,0.000000
17.110001,1.082481,-290.771973,-0.005044,0.000548,0.013910,4.815118,0.245294,0.139102,-290.771973,0.015029,0.000000
17.560001,1.258987,-290.816467,-0.005014,0.000573,0.014552,5.600256,0.285291,0.145520,-290.816467,0.015784,0.000000
18.010000,1.633972,-290.860931,-0.004980,0.000610,0.015497,7.268271,0.370263,0.154973,-290.860931,0.016529,0.000000
18.460001,1.823135,-290.860931,-0.004963,0.000645,0.016382,8.109712,0.413128,0.163820,-290.860931,0.017284,0.000000
18.910002,1.937080,-290.905426,-0.004919,0.000671,0.017032,8.616564,0.438949,0.170324,-290.905426,0.018030,0.000000
19.360001,2.274078,-290.949890,-0.004889,0.000701,0.017813,10.115605,0.515314,0.178129,-290.949890,0.018784,0.000000
19.810001,2.551125,-290.994385,-0.004876,0.000731,0.018567,11.347969,0.578093,0.185674,-290.994385,0.019530,0.000000
20.260000,2.665810,-290.994385,-0.004833,0.000756,0.019200,11.858113,0.604081,0.192004,-290.994385,0.020284,0.000000
20.710001,2.915672,-291.038849,-0.004807,0.000789,0.020050,12.969558,0.660701,0.200503,-291.038849,0.021030,0.000000
21.160002,3.085846,-290.994385,-0.004790,0.000814,0.020666,13.726528,0.699263,0.206659,-290.994385,0.021785,0.000000
21.610001,3.254532,-291.127838,-0.004769,0.000844,0.021447,14.476881,0.737487,0.214465,-291.127838,0.022531,0.000000
22.060001,3.582596,-291.083344,-0.004725,0.000869,0.022062,15.936182,0.811828,0.220622,-291.083344,0.023285,0.000000
22.510000,3.972466,-291.216797,-0.004704,0.000910,0.023103,17.670408,0.900174,0.231028,-291.216797,0.024031,0.000000
22.960001,4.099075,-291.172302,-0.004665,0.000937,0.023797,18.233597,0.928864,0.237968,-291.172302,0.024785,0.000000
23.410002,4.345215,-291.216797,-0.004648,0.000961,0.024421,19.328482,0.984640,0.244211,-291.216797,0.025531,0.000000
23.860001,4.640503,-291.305756,-0.004622,0.000991,0.025176,20.641989,1.051553,0.251756,-291.305756,0.026286,0.000000
24.310001,4.862434,-291.305756,-0.004592,0.001026,0.026051,21.629189,1.101843,0.260514,-291.305756,0.027031,0.000000
24.760000,5.169273,-291.305756,-0.004544,0.001058,0.026867,22.994076,1.171374,0.268667,-291.305756,0.027786,0.000000
25.210001,5.387108,-291.394714,-0.004531,0.001089,0.027665,23.963053,1.220736,0.276646,-291.394714,0.028532,0.000000
25.660002,5.383385,-291.394714,-0.004510,0.001109,0.028159,23.946491,1.219893,0.281589,-291.394714,0.029286,0.000000
26.110001,5.848854,-291.439178,-0.004454,0.001144,0.029069,26.017002,1.325369,0.290693,-291.439178,0.030032,0.000000
26.560001,5.926308,-291.439178,-0.004445,0.001173,0.029807,26.361532,1.342921,0.298066,-291.439178,0.030787,0.000000
27.010002,6.141167,-291.483673,-0.004415,0.001202,0.030526,27.317274,1.391608,0.305263,-291.483673,0.031532,0.000000
27.460001,6.257721,-291.572632,-0.004376,0.001227,0.031168,27.835733,1.418020,0.311680,-291.572632,0.032287,0.000000
27.910002,6.665466,-291.572632,-0.004359,0.001262,0.032061,29.649475,1.510416,0.320613,-291.572632,0.033033,0.000000
28.360001,6.753716,-291.572632,-0.004320,0.001293,0.032833,30.042027,1.530414,0.328332,-291.572632,0.033787,0.000000
28.810001,6.866173,-291.661591,-0.004290,0.001319,0.033492,30.542261,1.555897,0.334923,-291.661591,0.034533,0.000000
29.260002,7.280998,-291.617126,-0.004260,0.001354,0.034394,32.387497,1.649898,0.343941,-291.617126,0.035287,0.000000
29.710001,7.213226,-291.661591,-0.004251,0.001371,0.034819,32.086033,1.634540,0.348191,-291.661591,0.036033,0.000000
30.160002,7.612778,-291.750549,-0.004208,0.001405,0.035678,33.863327,1.725080,0.356777,-291.750549,0.036788,0.000000
30.610001,7.829498,-291.750549,-0.004178,0.001437,0.036510,34.827347,1.774190,0.365102,-291.750549,0.037533,0.000000
31.060001,8.000793,-291.795044,-0.004156,0.001467,0.037256,35.589306,1.813006,0.372560,-291.795044,0.038288,0.000000
31.510002,8.178787,-291.795044,-0.004130,0.001496,0.037993,36.381062,1.853340,0.379932,-291.795044,0.039034,0.000000
31.960001,8.305763,-291.884003,-0.004087,0.001522,0.038661,36.945881,1.882113,0.386610,-291.884003,0.039788,0.000000
32.410000,8.566795,-291.928467,-0.004070,0.001554,0.039476,38.107010,1.941264,0.394761,-291.928467,0.040534,0.000000
32.860001,8.692657,-291.839508,-0.004049,0.001584,0.040231,38.666870,1.969784,0.402306,-291.839508,0.041289,0.000000
33.310001,8.879967,-291.884003,-0.004010,0.001611,0.040924,39.500065,2.012229,0.409244,-291.884003,0.042034,0.000000
33.760002,9.284737,-291.928467,-0.003984,0.001647,0.041844,41.300571,2.103951,0.418437,-291.928467,0.042789,0.000000
34.210003,9.163712,-291.972961,-0.003962,0.001672,0.042459,40.762226,2.076527,0.424593,-291.972961,0.043535,0.000000
34.660000,9.234467,-291.972961,-0.003932,0.001700,0.043171,41.076958,2.092560,0.431705,-291.972961,0.044289,0.000000
35.110001,9.471291,-291.972961,-0.003906,0.001728,0.043882,42.130405,2.146225,0.438817,-291.972961,0.045035,0.000000
35.560001,9.855209,-292.061920,-0.003889,0.001763,0.044783,43.838161,2.233222,0.447834,-292.061920,0.045789,0.000000
36.010002,9.965431,-292.106415,-0.003854,0.001792,0.045512,44.328453,2.258199,0.455120,-292.106415,0.046535,0.000000
36.460003,10.059639,-292.150879,-0.003811,0.001820,0.046240,44.747509,2.279547,0.462404,-292.150879,0.047290,0.000000
36.910000,10.204491,-292.150879,-0.003803,0.001846,0.046882,45.391842,2.312371,0.468822,-292.150879,0.048036,0.000000
37.360001,10.678154,-292.106415,-0.003768,0.001880,0.047758,47.498802,2.419704,0.477582,-292.106415,0.048781,0.000000
37.810001,10.560852,-292.195374,-0.003747,0.001906,0.048417,46.977016,2.393123,0.484171,-292.195374,0.049536,0.000000
38.260002,10.869553,-292.284332,-0.003721,0.001938,0.049232,48.350185,2.463076,0.492324,-292.284332,0.050282,0.000000
38.710003,10.898224,-292.284332,-0.003691,0.001964,0.049883,48.477722,2.469573,0.498828,-292.284332,0.051036,0.000000
39.160004,10.536652,-292.284332,-0.003682,0.001975,0.050178,46.869366,2.387640,0.501777,-292.284332,0.051782,0.000000
39.610001,11.284744,-292.284332,-0.003652,0.002023,0.051383,50.197048,2.557160,0.513832,-292.284332,0.052537,0.000000
40.060001,11.565514,-292.373291,-0.003622,0.002057,0.052250,51.445972,2.620783,0.522503,-292.373291,0.053282,0.000000
40.510002,11.439651,-292.373291,-0.003604,0.002081,0.052849,50.886112,2.592262,0.528487,-292.373291,0.054037,0.000000
40.960003,11.683556,-292.373291,-0.003570,0.002109,0.053569,51.971050,2.647532,0.535686,-292.373291,0.054783,0.000000
41.410004,11.641106,-292.417786,-0.003544,0.002141,0.054384,51.782223,2.637912,0.543836,-292.417786,0.055537,0.000000
41.860001,11.862671,-292.462250,-0.003510,0.002162,0.054921,52.767796,2.688120,0.549215,-292.462250,0.056283,0.000000
42.310001,12.387337,-292.551208,-0.003484,0.002202,0.055936,55.101627,2.807011,0.559360,-292.551208,0.057037,0.000000
42.760002,12.570923,-292.506744,-0.003466,0.002231,0.056673,55.918259,2.848612,0.566731,-292.506744,0.057783,0.000000
43.210003,12.781685,-292.595703,-0.003449,0.002262,0.057454,56.855774,2.896371,0.574538,-292.595703,0.058538,0.000000
43.660004,12.922066,-292.595703,-0.003415,0.002290,0.058165,57.480221,2.928182,0.581648,-292.595703,0.059284,0.000000
44.110001,13.007339,-292.640167,-0.003406,0.002322,0.058980,57.859535,2.947505,0.589800,-292.640167,0.060038,0.000000
44.560001,13.340988,-292.595703,-0.003376,0.002354,0.059804,59.343678,3.023111,0.598038,-292.595703,0.060784,0.000000
45.010002,13.163734,-292.684662,-0.003341,0.002375,0.060333,58.555214,2.982945,0.603329,-292.684662,0.061538,0.000000
45.460003,13.322739,-292.729126,-0.003333,0.002403,0.061044,59.262501,3.018976,0.610441,-292.729126,0.062284,0.000000
45.910004,13.892471,-292.773621,-0.003303,0.002440,0.061972,61.796799,3.148079,0.619720,-292.773621,0.063039,0.000000
46.360001,13.855232,-292.773621,-0.003277,0.002465,0.062614,61.631149,3.139641,0.626137,-292.773621,0.063784,0.000000
46.810001,14.267075,-292.773621,-0.003238,0.002500,0.063507,63.463116,3.232965,0.635069,-292.773621,0.064539,0.000000
47.260002,14.254791,-292.818115,-0.003229,0.002530,0.064253,63.408478,3.230182,0.642528,-292.818115,0.065285,0.000000
47.710003,14.586571,-292.907074,-0.003203,0.002562,0.065068,64.884308,3.305364,0.650678,-292.907074,0.066039,0.000000
48.160004,14.563484,-292.996033,-0.003169,0.002588,0.065727,64.781616,3.300133,0.657272,-292.996033,0.066785,0.000000
48.610001,14.667007,-292.907074,-0.003156,0.002614,0.066386,65.242111,3.323591,0.663861,-292.907074,0.067539,0.000000
49.060001,15.128746,-292.996033,-0.003126,0.002646,0.067210,67.296021,3.428223,0.672101,-292.996033,0.068285,0.000000
49.510002,15.444519,-292.996033,-0.003100,0.002682,0.068112,68.700653,3.499778,0.681120,-292.996033,0.069040,0.000000
49.960003,15.261314,-293.084991,-0.003074,0.002708,0.068788,67.885719,3.458263,0.687884,-293.084991,0.069786,0.000000
50.410004,15.421432,-293.129456,-0.003053,0.002737,0.069517,68.597961,3.494546,0.695170,-293.129456,0.070540,0.000000
50.860001,15.446754,-293.129456,-0.003031,0.002765,0.070228,68.710594,3.500284,0.702278,-293.129456,0.071286,0.000000
51.310001,15.822105,-293.084991,-0.003022,0.002795,0.070991,70.380241,3.585340,0.709912,-293.084991,0.072040,0.000000
51.760002,16.006798,-293.218414,-0.002984,0.002827,0.071815,71.201790,3.627192,0.718148,-293.218414,0.072786,0.000000
52.210003,15.832527,-293.218414,-0.002962,0.002854,0.072483,70.426598,3.587702,0.724828,-293.218414,0.073541,0.000000
52.660004,15.998238,-293.173950,-0.002945,0.002882,0.073203,71.163712,3.625252,0.732027,-293.173950,0.074287,0.000000
53.110004,16.308426,-293.307404,-0.002910,0.002914,0.074018,72.543503,3.695542,0.740176,-293.307404,0.075041,0.000000
53.560001,16.408218,-293.351868,-0.002897,0.002942,0.074729,72.987404,3.718155,0.747288,-293.351868,0.075787,0.000000
54.010002,16.414925,-293.396362,-0.002867,0.002970,0.075431,73.017235,3.719675,0.754313,-293.396362,0.076541,0.000000
54.460003,16.455139,-293.440826,-0.002846,0.003000,0.076203,73.196114,3.728788,0.762030,-293.440826,0.077287,0.000000
54.910004,16.721382,-293.440826,-0.002828,0.003034,0.077053,74.380424,3.789119,0.770531,-293.440826,0.078042,0.000000
55.360004,16.549347,-293.485321,-0.002790,0.003063,0.077790,73.615173,3.750136,0.777900,-293.485321,0.078787,0.000000
55.810001,16.377312,-293.440826,-0.002777,0.003089,0.078467,72.849922,3.711152,0.784667,-293.440826,0.079542,0.000000
56.260002,16.441734,-293.574280,-0.002738,0.003116,0.079143,73.136490,3.725750,0.791431,-293.574280,0.080288,0.000000
56.710003,16.855438,-293.529785,-0.002721,0.003150,0.080010,74.976730,3.819497,0.800102,-293.529785,0.081034,0.000000
57.160004,16.934380,-293.618744,-0.002673,0.003184,0.080877,75.327881,3.837385,0.808773,-293.618744,0.081788,0.000000
57.610004,16.432419,-293.574280,-0.002673,0.003210,0.081537,73.095047,3.723639,0.815367,-293.574280,0.082534,0.000000
58.060001,16.112556,-293.618744,-0.002626,0.003233,0.082109,71.672234,3.651158,0.821089,-293.618744,0.083288,0.000000
58.510002,16.373962,-293.663239,-0.002604,0.003261,0.082838,72.835022,3.710393,0.828375,-293.663239,0.084034,0.000000
58.960003,16.476364,-293.707733,-0.002591,0.003298,0.083765,73.290527,3.733598,0.837652,-293.707733,0.084789,0.000000
59.410004,16.064522,-293.796692,-0.002570,0.003320,0.084329,71.458565,3.640273,0.843292,-293.796692,0.085535,0.000000
59.860004,16.158730,-293.752197,-0.002527,0.003352,0.085153,71.877617,3.661620,0.851528,-293.752197,0.086289,0.000000
60.310001,16.473381,-293.841156,-0.002509,0.003384,0.085951,73.277260,3.732921,0.859506,-293.841156,0.087035,0.000000
60.760002,16.206390,-293.841156,-0.002471,0.003413,0.086688,72.089622,3.672421,0.866879,-293.841156,0.087789,0.000000
61.210003,16.499825,-293.885651,-0.002453,0.003445,0.087494,73.394882,3.738914,0.874945,-293.885651,0.088535,0.000000
61.660004,16.297623,-293.885651,-0.002423,0.003470,0.088136,72.495445,3.693094,0.881360,-293.885651,0.089290,0.000000
62.110004,16.342682,-293.930115,-0.002410,0.003498,0.088856,72.695877,3.703305,0.888559,-293.930115,0.090035,0.000000
62.560001,17.018166,-294.019073,-0.002367,0.003529,0.089636,75.700584,3.856371,0.896363,-294.019073,0.090790,0.000000
63.010002,16.606323,-294.019073,-0.002350,0.003552,0.090226,73.868614,3.763047,0.902260,-294.019073,0.091536,0.000000
63.460003,17.505226,-294.108063,-0.002350,0.003588,0.091137,77.867134,3.966741,0.911367,-294.108063,0.092290,0.000000
63.910004,17.519005,-294.108063,-0.002311,0.003620,0.091952,77.928429,3.969863,0.919519,-294.108063,0.093036,0.000000
64.360001,17.693649,-294.063568,-0.002272,0.003648,0.092654,78.705284,4.009439,0.926544,-294.063568,0.093791,0.000000
64.810005,17.970695,-294.152527,-0.002255,0.003680,0.093470,79.937645,4.072218,0.934697,-294.152527,0.094536,0.000000
65.260002,17.961388,-294.197021,-0.002225,0.003710,0.094241,79.896240,4.070108,0.942414,-294.197021,0.095291,0.000000
65.710007,18.018730,-294.152527,-0.002216,0.003740,0.095004,80.151314,4.083103,0.950045,-294.152527,0.096037,0.000000
66.160004,18.289444,-294.285980,-0.002186,0.003768,0.095716,81.355507,4.144447,0.957156,-294.285980,0.096791,0.000000
66.610001,18.479355,-294.241486,-0.002173,0.003796,0.096427,82.200279,4.187482,0.964268,-294.241486,0.097537,0.000000
67.060005,18.880402,-294.330444,-0.002143,0.003827,0.097199,83.984222,4.278360,0.971986,-294.330444,0.098291,0.000000
67.510002,19.145531,-294.374939,-0.002126,0.003857,0.097962,85.163574,4.338439,0.979620,-294.374939,0.099037,0.000000
67.960007,19.297455,-294.374939,-0.002113,0.003889,0.098777,85.839363,4.372866,0.987769,-294.374939,0.099792,0.000000
68.410004,19.408051,-294.374939,-0.002087,0.003914,0.099419,86.331322,4.397927,0.994188,-294.374939,0.100538,0.000000
68.860001,19.789360,-294.419403,-0.002065,0.003946,0.100217,88.027473,4.484333,1.002166,-294.419403,0.101292,0.000000
69.310005,20.251099,-294.463898,-0.002052,0.003979,0.101075,90.081383,4.588964,1.010751,-294.463898,0.102038,0.000000
69.760002,20.255943,-294.508362,-0.002026,0.004004,0.101700,90.102936,4.590062,1.016996,-294.508362,0.102792,0.000000
70.210007,20.558685,-294.508362,-0.002026,0.004031,0.102376,91.449600,4.658665,1.023759,-294.508362,0.103538,0.000000
70.660004,21.302681,-294.552856,-0.002001,0.004067,0.103304,94.759056,4.827257,1.033040,-294.552856,0.104293,0.000000
71.110001,21.600578,-294.597351,-0.001983,0.004097,0.104076,96.084167,4.894761,1.040757,-294.597351,0.105038,0.000000
71.560005,21.999016,-294.597351,-0.001957,0.004127,0.104822,97.856506,4.985048,1.048217,-294.597351,0.105793,0.000000
72.010002,22.260796,-294.641815,-0.001944,0.004154,0.105524,99.020966,5.044368,1.055242,-294.641815,0.106539,0.000000
72.460007,22.940376,-294.686310,-0.001923,0.004183,0.106252,102.043892,5.198363,1.062524,-294.686310,0.107293,0.000000
72.910004,23.454994,-294.775269,-0.001906,0.004212,0.106981,104.333023,5.314978,1.069810,-294.775269,0.108039,0.000000
73.360001,23.791618,-294.775269,-0.001888,0.004240,0.107692,105.830406,5.391258,1.076922,-294.775269,0.108794,0.000000
73.810005,24.489449,-294.730774,-0.001867,0.004272,0.108516,108.934509,5.549388,1.085158,-294.730774,0.109539,0.000000
74.260002,25.368614,-294.864227,-0.001854,0.004302,0.109262,112.845230,5.748610,1.092618,-294.864227,0.110294,0.000000
74.710007,25.850098,-294.864227,-0.001824,0.004328,0.109929,114.986977,5.857716,1.099294,-294.864227,0.111040,0.000000
75.160004,26.693893,-294.908691,-0.001811,0.004360,0.110753,118.740372,6.048923,1.107534,-294.908691,0.111794,0.000000
75.610001,27.515343,-294.908691,-0.001789,0.004389,0.111473,122.394356,6.235066,1.114733,-294.908691,0.112540,0.000000
76.060005,28.249290,-294.997681,-0.001772,0.004418,0.112228,125.659119,6.401381,1.122276,-294.997681,0.113286,0.000000
76.510002,29.431198,-295.042145,-0.001763,0.004453,0.113095,130.916504,6.669205,1.130947,-295.042145,0.114040,0.000000
76.960007,30.222862,-295.042145,-0.001738,0.004482,0.113832,134.438004,6.848598,1.138320,-295.042145,0.114786,0.000000
77.410004,30.508476,-295.086639,-0.001716,0.004504,0.114396,135.708481,6.913320,1.143956,-295.086639,0.115541,0.000000
77.860001,31.751450,-295.131104,-0.001712,0.004533,0.115133,141.237503,7.194982,1.151329,-295.131104,0.116286,0.000000
78.310005,33.552994,-295.131104,-0.001677,0.004569,0.116044,149.251175,7.603217,1.160436,-295.131104,0.117041,0.000000
78.760002,34.334976,-295.175598,-0.001669,0.004595,0.116720,152.729599,7.780417,1.167199,-295.175598,0.117786,0.000000
79.210007,35.281174,-295.220062,-0.001651,0.004622,0.117405,156.938492,7.994828,1.174050,-295.220062,0.118541,0.000000
79.660004,36.354347,-295.220062,-0.001634,0.004649,0.118081,161.712219,8.238013,1.180813,-295.220062,0.119287,0.000000
80.110001,38.520439,-295.264557,-0.001625,0.004686,0.119027,171.347473,8.728856,1.190268,-295.264557,0.120042,0.000000
80.560005,39.317314,-295.264557,-0.001608,0.004710,0.119643,174.892151,8.909431,1.196426,-295.264557,0.120787,0.000000
81.010002,40.951286,-295.353516,-0.001600,0.004741,0.120432,182.160416,9.279695,1.204318,-295.353516,0.121542,0.000000
81.460007,42.104897,-295.398010,-0.001574,0.004768,0.121099,187.291931,9.541105,1.210994,-295.398010,0.122287,0.000000
81.910004,44.020012,-295.398010,-0.001561,0.004800,0.121923,195.810791,9.975078,1.219234,-295.398010,0.123042,0.000000
82.360001,45.700523,-295.442474,-0.001561,0.004833,0.122764,203.286087,10.355886,1.227644,-295.442474,0.123788,0.000000
82.810005,47.162460,-295.486969,-0.001544,0.004862,0.123493,209.789108,10.687166,1.234930,-295.486969,0.124542,0.000000
83.260002,48.800529,-295.531433,-0.001526,0.004890,0.124213,217.075592,11.058358,1.242129,-295.531433,0.125288,0.000000
83.710007,50.340286,-295.486969,-0.001505,0.004918,0.124915,223.924774,11.407272,1.249153,-295.486969,0.126042,0.000000
84.160004,52.295616,-295.575928,-0.001479,0.004947,0.125644,232.622513,11.850356,1.256436,-295.575928,0.126788,0.000000
84.610001,54.049492,-295.575928,-0.001492,0.004974,0.126346,240.424149,12.247789,1.263460,-295.575928,0.127543,0.000000
85.060005,55.877464,-295.664886,-0.001483,0.005003,0.127075,248.555374,12.662014,1.270746,-295.664886,0.128289,0.000000
85.510002,58.026428,-295.620392,-0.001462,0.005036,0.127924,258.114441,13.148976,1.279243,-295.620392,0.129043,0.000000
85.960007,59.568047,-295.664886,-0.001436,0.005058,0.128471,264.971893,13.498312,1.284709,-295.664886,0.129789,0.000000
86.410004,62.334030,-295.709351,-0.001436,0.005096,0.129451,277.275604,14.125093,1.294508,-295.709351,0.130543,0.000000
86.860001,64.495651,-295.709351,-0.001414,0.005127,0.130223,286.890991,14.614923,1.302225,-295.709351,0.131289,0.000000
87.310005,66.060364,-295.753845,-0.001401,0.005140,0.130561,293.851166,14.969492,1.305609,-295.753845,0.022913,0.000000
87.760002,65.094803,-295.798309,-0.001393,0.005139,0.130535,289.556152,14.750693,1.305348,-295.798309,294.500458,0.000000
88.210007,66.375397,-295.842804,-0.001384,0.005128,0.130249,295.252502,15.040879,1.302486,-295.842804,294.500458,0.000000
88.660004,65.768051,-295.931763,-0.001384,0.005128,0.130249,292.550903,14.903254,1.302486,-295.931763,294.500458,0.000000
89.110001,65.213593,-295.887299,-0.001375,0.005145,0.130682,290.084534,14.777611,1.306824,-295.887299,294.500458,0.000000
89.560005,65.397919,-295.931763,-0.001367,0.005165,0.131194,290.904480,14.819380,1.311937,-295.931763,294.500458,0.000000
90.010002,65.264236,-295.976257,-0.001367,0.005165,0.131194,290.309814,14.789087,1.311937,-295.976257,294.500458,0.000000
90.460007,65.121246,-296.065216,-0.001367,0.005168,0.131263,289.673767,14.756685,1.312634,-296.065216,294.500458,0.000000
90.910004,64.968567,-295.976257,-0.001371,0.005171,0.131333,288.994629,14.722088,1.313326,-295.976257,294.500458,0.000000
91.360001,65.100388,-296.065216,-0.001367,0.005172,0.131376,289.580994,14.751959,1.313762,-296.065216,294.500458,0.000000
91.810005,65.244125,-296.109680,-0.001367,0.005178,0.131515,290.220367,14.784530,1.315147,-296.109680,294.500458,0.000000
92.260002,65.274277,-296.154175,-0.001371,0.005178,0.131515,290.354492,14.791362,1.315147,-296.154175,294.500458,0.000000
92.710007,65.158096,-296.198639,-0.001362,0.005178,0.131515,289.837677,14.765036,1.315147,-296.198639,294.500458,0.000000
93.160004,65.070221,-296.198639,-0.001367,0.005179,0.131541,289.446808,14.745123,1.315408,-296.198639,294.500458,0.000000
93.610008,65.275772,-296.198639,-0.001358,0.005183,0.131636,290.361145,14.791701,1.316362,-296.198639,294.500458,0.000000
94.060005,65.197571,-296.243134,-0.001371,0.005183,0.131636,290.013275,14.773981,1.316362,-296.243134,294.500458,0.000000
94.510002,65.143951,-296.243134,-0.001362,0.005184,0.131671,289.774780,14.761830,1.316710,-296.243134,294.500458,0.000000
94.960007,65.114532,-296.332092,-0.001358,0.005186,0.131723,289.643921,14.755164,1.317229,-296.332092,294.500458,0.000000
95.410004,65.129425,-296.287628,-0.001358,0.005186,0.131723,289.710144,14.758538,1.317229,-296.287628,294.500458,0.000000
95.860008,65.065750,-296.376587,-0.001358,0.005186,0.131723,289.426910,14.744110,1.317229,-296.376587,294.500458,0.000000
96.310005,65.000595,-296.421051,-0.001358,0.005187,0.131740,289.137085,14.729345,1.317403,-296.421051,294.500458,0.000000
96.760002,65.341690,-296.421051,-0.001341,0.005191,0.131862,290.654358,14.806639,1.318618,-296.421051,294.500458,0.000000
97.210007,65.314133,-296.465546,-0.001358,0.005191,0.131862,290.531769,14.800394,1.318618,-296.465546,294.500458,0.000000
97.660004,65.267960,-296.510010,-0.001345,0.005191,0.131862,290.326385,14.789931,1.318618,-296.510010,294.500458,0.000000
98.110008,65.200562,-296.510010,-0.001350,0.005191,0.131862,290.026581,14.774658,1.318618,-296.510010,294.500458,0.000000
98.560005,65.132416,-296.598969,-0.001354,0.005191,0.131862,289.723450,14.759216,1.318618,-296.598969,294.500458,0.000000
99.010002,65.067245,-296.510010,-0.001354,0.005192,0.131870,289.433563,14.744449,1.318705,-296.510010,294.500458,0.000000
99.460007,65.044907,-296.598969,-0.001354,0.005193,0.131896,289.334198,14.739387,1.318962,-296.598969,294.500458,0.000000
99.910004,65.067993,-296.687958,-0.001350,0.005194,0.131931,289.436890,14.744618,1.319310,-296.687958,294.500458,0.000000
100.360008,65.041550,-296.687958,-0.001350,0.005194,0.131931,289.319275,14.738626,1.319310,-296.687958,294.500458,0.000000
100.810005,65.008408,-296.732422,-0.001354,0.005194,0.131931,289.171844,14.731116,1.319310,-296.732422,294.500458,0.000000
101.260002,65.018097,-296.776917,-0.001350,0.005196,0.131975,289.214935,14.733311,1.319746,-296.776917,294.500458,0.000000
101.710007,65.020691,-296.776917,-0.001350,0.005196,0.131975,289.226471,14.733899,1.319746,-296.776917,294.500458,0.000000
102.160004,64.994263,-296.732422,-0.001332,0.005196,0.131975,289.108917,14.727910,1.319746,-296.732422,294.500458,0.000000
102.610008,64.966705,-296.821381,-0.001341,0.005196,0.131975,288.986328,14.721666,1.319746,-296.821381,294.500458,0.000000
103.060005,64.955536,-296.865875,-0.001345,0.005197,0.131992,288.936646,14.719135,1.319916,-296.865875,294.500458,0.000000
103.510002,64.919037,-296.865875,-0.001350,0.005197,0.131992,288.774292,14.710864,1.319916,-296.865875,294.500458,0.000000
103.960007,64.864304,-296.954834,-0.001341,0.005197,0.131992,288.530823,14.698461,1.319916,-296.954834,294.500458,0.000000
104.410004,64.838242,-296.910339,-0.001345,0.005197,0.131992,288.414917,14.692555,1.319916,-296.910339,294.500458,0.000000
104.860008,64.789825,-296.999298,-0.001341,0.005197,0.131992,288.199524,14.681584,1.319916,-296.999298,294.500458,0.000000
105.310005,64.753708,-297.043793,-0.001337,0.005197,0.131992,288.038879,14.673400,1.319916,-297.043793,294.500458,0.000000
105.760002,64.721313,-296.999298,-0.001350,0.005197,0.131992,287.894775,14.666059,1.319916,-296.999298,294.500458,0.000000
106.210007,64.688538,-297.043793,-0.001350,0.005197,0.131992,287.748993,14.658632,1.319916,-297.043793,294.500458,0.000000
106.660004,65.910294,-297.088287,-0.001341,0.005204,0.132191,293.183624,14.935486,1.321911,-297.088287,294.500458,0.000000
107.110008,65.901733,-297.177246,-0.001337,0.005204,0.132191,293.145538,14.933546,1.321911,-297.177246,294.500458,0.000000
107.560005,65.837677,-297.177246,-0.001350,0.005204,0.132191,292.860626,14.919031,1.321911,-297.177246,294.500458,0.000000
108.010002,65.834702,-297.177246,-0.001341,0.005204,0.132191,292.847382,14.918357,1.321911,-297.177246,294.500458,0.000000
108.460007,65.776993,-297.221710,-0.001341,0.005204,0.132191,292.590668,14.905280,1.321911,-297.221710,294.500458,0.000000
108.910004,65.764328,-297.310669,-0.001354,0.005204,0.132191,292.534332,14.902411,1.321911,-297.310669,294.500458,0.000000
109.360008,65.678680,-297.266205,-0.001345,0.005204,0.132191,292.153351,14.883001,1.321911,-297.266205,294.500458,0.000000
109.810005,65.648148,-297.310669,-0.001337,0.005204,0.132191,292.017548,14.876082,1.321911,-297.310669,294.500458,0.000000
110.260002,65.600113,-297.310669,-0.001328,0.005204,0.132191,291.803864,14.865198,1.321911,-297.310669,294.500458,0.000000
110.710007,65.570694,-297.399628,-0.001328,0.005204,0.132191,291.673004,14.858532,1.321911,-297.399628,294.500458,0.000000
111.160004,65.550964,-297.355164,-0.001345,0.005204,0.132191,291.585266,14.854061,1.321911,-297.355164,294.500458,0.000000
111.610008,65.515213,-297.488586,-0.001337,0.005204,0.132191,291.426208,14.845960,1.321911,-297.488586,294.500458,0.000000
112.060005,65.478714,-297.399628,-0.001332,0.005204,0.132191,291.263855,14.837688,1.321911,-297.399628,294.500458,0.000000
112.510002,65.437759,-297.488586,-0.001328,0.005204,0.132191,291.081696,14.828408,1.321911,-297.488586,294.500458,0.000000
112.960007,65.385254,-297.577576,-0.001345,0.005205,0.132200,290.848145,14.816510,1.321998,-297.577576,294.500458,0.000000
113.410004,65.359558,-297.533081,-0.001350,0.005205,0.132200,290.733826,14.810687,1.321998,-297.533081,294.500458,0.000000
113.860008,65.311890,-297.533081,-0.001324,0.005205,0.132200,290.521790,14.799886,1.321998,-297.533081,294.500458,0.000000
114.310005,65.299240,-297.577576,-0.001341,0.005205,0.132200,290.465515,14.797020,1.321998,-297.577576,294.500458,0.000000
114.760002,65.264969,-297.710999,-0.001324,0.005205,0.132200,290.313080,14.789253,1.321998,-297.710999,294.500458,0.000000
115.210007,65.230713,-297.666534,-0.001328,0.005205,0.132200,290.160706,14.781491,1.321998,-297.666534,294.500458,0.000000
115.660004,65.215820,-297.710999,-0.001324,0.005205,0.132200,290.094452,14.778116,1.321998,-297.710999,294.500458,0.000000
116.110008,65.164062,-297.710999,-0.001341,0.005205,0.132200,289.864227,14.766387,1.321998,-297.710999,294.500458,0.000000
116.560005,65.128311,-297.710999,-0.001332,0.005205,0.132200,289.705200,14.758286,1.321998,-297.710999,294.500458,0.000000
117.010002,65.093689,-297.799957,-0.001328,0.005205,0.132200,289.551178,14.750442,1.321998,-297.799957,294.500458,0.000000
117.460007,65.069855,-297.844452,-0.001324,0.005205,0.132200,289.445160,14.745040,1.321998,-297.844452,294.500458,0.000000
117.910004,65.039688,-297.799957,-0.001332,0.005205,0.132200,289.310974,14.738203,1.321998,-297.799957,294.500458,0.000000
118.360008,65.024796,-297.933411,-0.001337,0.005205,0.132200,289.244751,14.734829,1.321998,-297.933411,294.500458,0.000000
118.810005,64.994629,-297.888916,-0.001328,0.005205,0.132200,289.110535,14.727993,1.321998,-297.888916,294.500458,0.000000
119.260002,64.970428,-297.977905,-0.001341,0.005205,0.132200,289.002899,14.722509,1.321998,-297.977905,294.500458,0.000000
119.710007,64.952179,-297.933411,-0.001341,0.005205,0.132200,288.921722,14.718374,1.321998,-297.933411,294.500458,0.000000
120.160004,64.908615,-297.977905,-0.001345,0.005205,0.132208,288.727936,14.708503,1.322085,-297.977905,294.500458,0.000000
120.610008,64.881058,-298.066864,-0.001341,0.005205,0.132208,288.605347,14.702257,1.322085,-298.066864,294.500458,0.000000
121.060005,65.431046,-298.155823,-0.001332,0.005219,0.132564,291.051819,14.826887,1.325642,-298.155823,294.500458,0.000000
121.510002,65.692825,-298.066864,-0.001350,0.005217,0.132503,292.216278,14.886208,1.325033,-298.066864,294.500458,0.000000
121.960007,65.704376,-298.066864,-0.001332,0.005217,0.132503,292.267670,14.888824,1.325033,-298.066864,294.500458,0.000000
122.410004,65.751297,-298.200287,-0.001328,0.005217,0.132503,292.476379,14.899457,1.325033,-298.200287,294.500458,0.000000
122.860008,65.753906,-298.244781,-0.001332,0.005217,0.132503,292.487976,14.900048,1.325033,-298.244781,294.500458,0.000000
123.310005,65.750183,-298.155823,-0.001341,0.005217,0.132503,292.471436,14.899204,1.325033,-298.155823,294.500458,0.000000
123.760002,65.738266,-298.289246,-0.001324,0.005217,0.132503,292.418427,14.896503,1.325033,-298.289246,294.500458,0.000000
124.210007,65.683517,-298.289246,-0.001341,0.005217,0.132503,292.174866,14.884098,1.325033,-298.289246,294.500458,0.000000
124.660004,65.667130,-298.289246,-0.001337,0.005217,0.132503,292.101990,14.880384,1.325033,-298.289246,294.500458,0.000000
125.110008,65.661545,-298.333740,-0.001345,0.005217,0.132503,292.077148,14.879119,1.325033,-298.333740,294.500458,0.000000
125.560005,65.640701,-298.378235,-0.001328,0.005217,0.132503,291.984436,14.874395,1.325033,-298.378235,294.500458,0.000000
126.010010,65.611649,-298.378235,-0.001337,0.005217,0.132503,291.855194,14.867812,1.325033,-298.378235,294.500458,0.000000
126.460007,65.604584,-298.467194,-0.001341,0.005217,0.132503,291.823761,14.866211,1.325033,-298.467194,294.500458,0.000000
126.910004,65.600861,-298.378235,-0.001332,0.005217,0.132503,291.807190,14.865368,1.325033,-298.378235,294.500458,0.000000
127.360008,65.586334,-298.511658,-0.001328,0.005217,0.132503,291.742584,14.862076,1.325033,-298.511658,294.500458,0.000000
127.810005,65.569946,-298.556152,-0.001324,0.005217,0.132503,291.669678,14.858362,1.325033,-298.556152,294.500458,0.000000
128.260010,65.555054,-298.600616,-0.001319,0.005217,0.132503,291.603455,14.854987,1.325033,-298.600616,294.500458,0.000000
128.710007,65.556168,-298.600616,-0.001324,0.005217,0.132503,291.608398,14.855240,1.325033,-298.600616,294.500458,0.000000
129.160004,65.522278,-298.645111,-0.001328,0.005217,0.132503,291.457642,14.847560,1.325033,-298.645111,294.500458,0.000000
129.610001,65.513351,-298.689575,-0.001332,0.005217,0.132503,291.417938,14.845537,1.325033,-298.689575,294.500458,0.000000
130.060013,65.478348,-298.645111,-0.001328,0.005217,0.132503,291.262238,14.837605,1.325033,-298.645111,294.500458,0.000000
130.510010,65.481323,-298.734070,-0.001324,0.005217,0.132503,291.275482,14.838281,1.325033,-298.734070,294.500458,0.000000
130.960007,65.470520,-298.778534,-0.001324,0.005217,0.132503,291.227417,14.835832,1.325033,-298.778534,294.500458,0.000000
131.410004,65.435150,-298.823029,-0.001337,0.005217,0.132503,291.070099,14.827816,1.325033,-298.823029,294.500458,0.000000
131.860001,65.415421,-298.867523,-0.001345,0.005217,0.132503,290.982330,14.823346,1.325033,-298.867523,294.500458,0.000000
132.310013,65.390839,-298.823029,-0.001324,0.005217,0.132503,290.872986,14.817776,1.325033,-298.823029,294.500458,0.000000
132.760010,65.374832,-298.823029,-0.001337,0.005217,0.132503,290.801788,14.814149,1.325033,-298.823029,294.500458,0.000000
133.210007,65.358063,-298.911987,-0.001341,0.005217,0.132503,290.727173,14.810349,1.325033,-298.911987,294.500458,0.000000
133.660004,65.347275,-298.956482,-0.001324,0.005217,0.132503,290.679199,14.807904,1.325033,-298.956482,294.500458,0.000000
134.110001,65.335724,-298.956482,-0.001332,0.005217,0.132503,290.627808,14.805286,1.325033,-298.956482,294.500458,0.000000
134.560013,65.324554,-299.000946,-0.001337,0.005217,0.132503,290.578125,14.802755,1.325033,-299.000946,294.500458,0.000000
135.010010,65.289917,-299.000946,-0.001324,0.005217,0.132503,290.424042,14.794907,1.325033,-299.000946,294.500458,0.000000
135.460007,65.286942,-299.089905,-0.001332,0.005217,0.132503,290.410828,14.794232,1.325033,-299.089905,294.500458,0.000000
135.910004,65.265717,-299.134399,-0.001332,0.005217,0.132503,290.316406,14.789423,1.325033,-299.134399,294.500458,0.000000
136.360001,65.259018,-299.134399,-0.001332,0.005217,0.132503,290.286621,14.787905,1.325033,-299.134399,294.500458,0.000000
136.810013,65.263107,-299.178864,-0.001337,0.005217,0.132503,290.304810,14.788831,1.325033,-299.178864,294.500458,0.000000
137.260010,65.239288,-299.223358,-0.001324,0.005217,0.132503,290.198853,14.783434,1.325033,-299.223358,294.500458,0.000000
137.710007,65.222519,-299.223358,-0.001324,0.005217,0.132503,290.124268,14.779634,1.325033,-299.223358,294.500458,0.000000
138.160004,65.196091,-299.267853,-0.001345,0.005217,0.132503,290.006683,14.773645,1.325033,-299.267853,294.500458,0.000000
138.610001,65.189377,-299.312317,-0.001328,0.005217,0.132503,289.976837,14.772124,1.325033,-299.312317,294.500458,0.000000
139.060013,65.167419,-299.312317,-0.001345,0.005217,0.132503,289.879150,14.767148,1.325033,-299.312317,294.500458,0.000000
139.510010,65.167786,-299.356812,-0.001341,0.005217,0.132503,289.880798,14.767232,1.325033,-299.356812,294.500458,0.000000
139.960007,65.127563,-299.312317,-0.001328,0.005217,0.132503,289.701874,14.758117,1.325033,-299.312317,294.500458,0.000000
140.410004,65.124969,-299.445770,-0.001341,0.005217,0.132503,289.690338,14.757528,1.325033,-299.445770,294.500458,0.000000
140.860001,65.091827,-299.445770,-0.001332,0.005217,0.132503,289.542908,14.750019,1.325033,-299.445770,294.500458,0.000000
141.310013,65.099640,-299.445770,-0.001337,0.005217,0.132503,289.577667,14.751789,1.325033,-299.445770,294.500458,0.000000
141.760010,65.080658,-299.490234,-0.001319,0.005217,0.132503,289.493225,14.747488,1.325033,-299.490234,294.500458,0.000000
142.210007,65.063889,-299.534729,-0.001337,0.005217,0.132503,289.418640,14.743688,1.325033,-299.534729,294.500458,0.000000
142.660004,65.062027,-299.534729,-0.001337,0.005217,0.132503,289.410339,14.743266,1.325033,-299.534729,294.500458,0.000000
143.110001,65.044907,-299.623688,-0.001341,0.005217,0.132503,289.334198,14.739387,1.325033,-299.623688,294.500458,0.000000
143.560013,65.034470,-299.579193,-0.001328,0.005217,0.132503,289.287781,14.737021,1.325033,-299.579193,294.500458,0.000000
144.010010,65.015488,-299.668182,-0.001332,0.005217,0.132503,289.203339,14.732720,1.325033,-299.668182,294.500458,0.000000
144.460007,65.021072,-299.712646,-0.001328,0.005217,0.132503,289.228180,14.733986,1.325033,-299.712646,294.500458,0.000000
144.910004,65.000214,-299.712646,-0.001324,0.005217,0.132512,289.135376,14.729259,1.325120,-299.712646,294.500458,0.000000
145.360001,64.993149,-299.846100,-0.001337,0.005217,0.132512,289.103973,14.727658,1.325120,-299.846100,294.500458,0.000000
145.810013,64.986435,-299.801605,-0.001332,0.005217,0.132512,289.074097,14.726136,1.325120,-299.801605,294.500458,0.000000
146.260010,64.973038,-299.801605,-0.001324,0.005217,0.132512,289.014496,14.723101,1.325120,-299.801605,294.500458,0.000000
146.710007,64.954422,-299.890564,-0.001337,0.005217,0.132512,288.931702,14.718883,1.325120,-299.890564,294.500458,0.000000
147.160004,64.954422,-299.890564,-0.001328,0.005217,0.132512,288.931702,14.718883,1.325120,-299.890564,294.500458,0.000000
147.610001,64.936172,-299.935059,-0.001324,0.005217,0.132512,288.850525,14.714746,1.325120,-299.935059,294.500458,0.000000
148.060013,64.895584,-299.979523,-0.001332,0.005214,0.132425,288.669983,14.705549,1.324253,-299.979523,0.132382,0.000000
148.510010,64.755203,-299.979523,-0.001345,0.005193,0.131905,288.045532,14.673738,1.319049,-299.979523,0.131627,0.000000
148.960007,64.786484,-300.024017,-0.001324,0.005174,0.131411,288.184662,14.680827,1.314106,-300.024017,0.130882,0.000000
149.410004,64.748871,-300.068481,-0.001315,0.005148,0.130752,288.017365,14.672304,1.307517,-300.068481,0.130127,0.000000
149.860001,64.702698,-300.024017,-0.001328,0.005117,0.129963,287.811981,14.661841,1.299625,-300.024017,0.129382,0.000000
150.310013,64.692642,-300.068481,-0.001315,0.005084,0.129130,287.767242,14.659563,1.291298,-300.068481,0.128627,0.000000
150.760010,64.658005,-300.201935,-0.001319,0.005056,0.128419,287.613159,14.651713,1.284186,-300.201935,0.127881,0.000000
151.210007,64.631577,-300.201935,-0.001328,0.005029,0.127742,287.495605,14.645724,1.277423,-300.201935,0.127126,0.000000
151.660004,64.579803,-300.201935,-0.001315,0.005001,0.127022,287.265320,14.633992,1.270224,-300.201935,0.126381,0.000000
152.110001,63.969864,-300.246429,-0.001298,0.004970,0.126242,284.552155,14.495778,1.262420,-300.246429,0.125626,0.000000
152.560013,63.112289,-300.290894,-0.001311,0.004944,0.125566,280.737488,14.301449,1.255656,-300.290894,0.124881,0.000000
153.010010,61.767654,-300.379852,-0.001311,0.004917,0.124889,274.756256,13.996751,1.248892,-300.379852,0.124126,0.000000
153.460007,60.202942,-300.379852,-0.001281,0.004891,0.124222,267.796051,13.642181,1.242216,-300.379852,0.123380,0.000000
153.910004,58.142235,-300.335388,-0.001289,0.004862,0.123502,258.629578,13.175219,1.235017,-300.335388,0.122626,0.000000
154.360001,55.964600,-300.424347,-0.001285,0.004834,0.122773,248.942978,12.681760,1.227731,-300.424347,0.121880,0.000000
154.810013,53.655518,-300.424347,-0.001311,0.004808,0.122123,238.671661,12.158515,1.221228,-300.424347,0.121126,0.000000
155.260010,51.425011,-300.468811,-0.001293,0.004786,0.121576,228.749878,11.653074,1.215763,-300.468811,0.120380,0.000000
155.710007,51.254463,-300.513306,-0.001302,0.004786,0.121576,227.991241,11.614427,1.215763,-300.513306,0.119625,0.000000
156.160004,44.753952,-300.557800,-0.001289,0.004720,0.119885,199.075516,10.141390,1.198852,-300.557800,0.118879,0.000000
156.610001,41.692680,-300.602264,-0.001293,0.004691,0.119140,185.458298,9.447696,1.191396,-300.602264,0.118125,0.000000
157.060013,38.163704,-300.646759,-0.001293,0.004660,0.118376,169.760635,8.648019,1.183762,-300.646759,0.117379,0.000000
157.510010,37.706436,-300.646759,-0.001298,0.004659,0.118350,167.726608,8.544400,1.183504,-300.646759,0.116625,0.000000
157.960007,31.790550,-300.735718,-0.001285,0.004603,0.116928,141.411423,7.203842,1.169281,-300.735718,0.115879,0.000000
158.410004,27.892181,-300.691223,-0.001285,0.004568,0.116026,124.070618,6.320458,1.160261,-300.691223,0.115124,0.000000
158.860001,25.212593,-300.780182,-0.001281,0.004542,0.115376,112.151215,5.713255,1.153755,-300.780182,0.114379,0.000000
159.310013,21.925285,-300.735718,-0.001306,0.004513,0.114621,97.528542,4.968340,1.146212,-300.735718,0.113624,0.000000
159.760010,18.786560,-300.780182,-0.001298,0.004489,0.114014,83.566795,4.257095,1.140141,-300.780182,0.112878,0.000000
160.210007,15.120552,-300.824677,-0.001298,0.004454,0.113130,67.259575,3.426366,1.131296,-300.824677,0.112124,0.000000
160.660004,12.422714,-300.869141,-0.001302,0.004430,0.112522,55.258991,2.815027,1.125225,-300.869141,0.111378,0.000000
161.110001,9.755409,-300.913635,-0.001302,0.004406,0.111924,43.394226,2.210607,1.119241,-300.913635,0.110623,0.000000
161.560013,5.664154,-300.958130,-0.001293,0.004367,0.110927,25.195415,1.283516,1.109268,-300.958130,0.109878,0.000000
162.010010,2.963707,-300.913635,-0.001289,0.004337,0.110155,13.183227,0.671586,1.101550,-300.913635,0.109123,0.000000
162.460007,-0.090118,-301.047089,-0.001293,0.004308,0.109426,-0.400867,-0.020421,1.094264,-301.047089,0.108377,0.000000
162.910004,-0.653145,-301.002594,-0.001302,0.004278,0.108663,-2.905333,-0.148005,1.086634,-301.002594,0.107623,0.000000
163.360001,0.003723,-301.047089,-0.001302,0.004249,0.107935,0.016561,0.000844,1.079348,-301.047089,0.106877,0.000000
163.810013,0.024200,-301.091553,-0.001328,0.004222,0.107232,0.107649,0.005484,1.072323,-301.091553,0.106123,0.000000
164.260010,-0.001862,-301.091553,-0.001341,0.004186,0.106330,-0.008281,-0.000422,1.063304,-301.091553,0.105377,0.000000
164.710007,0.026062,-301.180511,-0.001358,0.004162,0.105724,0.115930,0.005906,1.057237,-301.180511,0.104622,0.000000
165.160004,0.054733,-301.180511,-0.001362,0.004149,0.105385,0.243466,0.012403,1.053853,-301.180511,0.103876,0.000000
165.610001,0.023460,-301.180511,-0.001384,0.004107,0.104319,0.104357,0.005316,1.043187,-301.180511,0.103122,0.000000
166.060013,0.040215,-301.269470,-0.001388,0.004075,0.103503,0.178883,0.009113,1.035034,-301.269470,0.102376,0.000000
166.510010,0.026062,-301.269470,-0.001401,0.004047,0.102784,0.115930,0.005906,1.027835,-301.269470,0.101630,0.000000
166.960007,0.057716,-301.269470,-0.001423,0.004019,0.102090,0.256735,0.013079,1.020898,-301.269470,0.100876,0.000000
167.410004,0.060326,-301.313965,-0.001423,0.004019,0.102090,0.268342,0.013670,1.020898,-301.313965,0.100130,0.000000
167.860001,0.015266,-301.313965,-0.001449,0.003953,0.100399,0.067908,0.003459,1.003987,-301.313965,0.099375,0.000000
168.310013,0.022713,-301.358429,-0.001470,0.003924,0.099661,0.101031,0.005147,0.996614,-301.358429,0.098630,0.000000
168.760010,0.033882,-301.358429,-0.001483,0.003894,0.098907,0.150715,0.007678,0.989071,-301.358429,0.097875,0.000000
169.210007,0.003349,-301.447418,-0.001518,0.003864,0.098153,0.014898,0.000759,0.981527,-301.447418,0.097129,0.000000
169.660004,0.021965,-301.447418,-0.001526,0.003832,0.097337,0.097705,0.004977,0.973375,-301.447418,0.096375,0.000000
170.110001,0.027184,-301.447418,-0.001552,0.003802,0.096574,0.120918,0.006160,0.965744,-301.447418,0.095629,0.000000
170.560013,0.049896,-301.580841,-0.001556,0.003779,0.095976,0.221950,0.011307,0.959760,-301.580841,0.094875,0.000000
171.010010,0.028671,-301.536377,-0.001595,0.003743,0.095065,0.127536,0.006497,0.950654,-301.536377,0.094129,0.000000
171.460007,0.025322,-301.625336,-0.001604,0.003720,0.094493,0.112638,0.005738,0.944927,-301.625336,0.093374,0.000000
171.910004,0.041328,-301.625336,-0.001634,0.003685,0.093600,0.183838,0.009365,0.935995,-301.625336,0.092628,0.000000
172.360001,0.057343,-301.714294,-0.001651,0.003658,0.092914,0.255072,0.012994,0.929144,-301.714294,0.091874,0.000000
172.810013,0.057343,-301.714294,-0.001673,0.003629,0.092186,0.255072,0.012994,0.921862,-301.714294,0.091128,0.000000
173.260010,0.080055,-301.758759,-0.001690,0.003603,0.091509,0.356103,0.018141,0.915095,-301.758759,0.090374,0.000000
173.710007,0.039841,-301.758759,-0.001725,0.003566,0.090582,0.177220,0.009028,0.905818,-301.758759,0.089628,0.000000
174.160004,0.061440,-301.714294,-0.001750,0.003538,0.089871,0.273297,0.013922,0.898706,-301.714294,0.088873,0.000000
174.610016,0.072609,-301.803253,-0.001776,0.003507,0.089090,0.322981,0.016453,0.890902,-301.803253,0.088127,0.000000
175.060013,0.065536,-301.803253,-0.001794,0.003482,0.088448,0.291521,0.014851,0.884483,-301.803253,0.087373,0.000000
175.510010,0.072609,-301.847748,-0.001819,0.003444,0.087486,0.322981,0.016453,0.874858,-301.847748,0.086627,0.000000
175.960007,0.056229,-301.892212,-0.001850,0.003416,0.086766,0.250117,0.012742,0.867659,-301.892212,0.085873,0.000000
176.410004,0.077080,-301.936707,-0.001871,0.003396,0.086254,0.342868,0.017467,0.862542,-301.936707,0.085127,0.000000
176.860016,0.046921,-301.892212,-0.001893,0.003358,0.085292,0.208714,0.010632,0.852917,-301.892212,0.084372,0.000000
177.310013,0.026810,-301.981171,-0.001923,0.003332,0.084641,0.119255,0.006075,0.846414,-301.981171,0.083627,0.000000
177.760010,0.049149,-302.025665,-0.001927,0.003300,0.083826,0.218624,0.011137,0.838261,-302.025665,0.082872,0.000000
178.210007,0.026436,-302.070129,-0.001966,0.003272,0.083098,0.117593,0.005990,0.830976,-302.070129,0.082126,0.000000
178.660004,0.031281,-302.025665,-0.001979,0.003254,0.082664,0.139143,0.007088,0.826638,-302.025665,0.081372,0.000000
179.110016,0.031281,-302.114624,-0.002005,0.003212,0.081597,0.139143,0.007088,0.815972,-302.114624,0.080626,0.000000
179.560013,0.055107,-302.203583,-0.002044,0.003180,0.080782,0.245129,0.012487,0.807820,-302.203583,0.079871,0.000000
180.010010,0.044312,-302.159088,-0.002057,0.003158,0.080218,0.197107,0.010041,0.802184,-302.159088,0.079126,0.000000
180.460007,0.039101,-302.159088,-0.002082,0.003124,0.079343,0.173928,0.008860,0.793426,-302.159088,0.078371,0.000000
180.910004,0.046173,-302.203583,-0.002108,0.003091,0.078519,0.205388,0.010463,0.785186,-302.203583,0.077625,0.000000
181.360016,0.029419,-302.248077,-0.002139,0.003063,0.077799,0.130862,0.006666,0.777987,-302.248077,0.076871,0.000000
181.810013,0.014145,-302.292542,-0.002151,0.003037,0.077148,0.062920,0.003205,0.771485,-302.292542,0.076125,0.000000
182.260010,0.011543,-302.292542,-0.002190,0.003010,0.076446,0.051347,0.002616,0.764460,-302.292542,0.075371,0.000000
182.710007,0.027557,-302.337036,-0.002216,0.002974,0.075544,0.122581,0.006245,0.755440,-302.337036,0.074625,0.000000
183.160004,0.045425,-302.381500,-0.002238,0.002953,0.075015,0.202062,0.010294,0.750149,-302.381500,0.073870,0.000000
183.610016,-0.001862,-302.381500,-0.002281,0.002917,0.074096,-0.008281,-0.000422,0.740959,-302.381500,0.073124,0.000000
184.060013,0.004097,-302.425995,-0.002294,0.002893,0.073480,0.018224,0.000928,0.734801,-302.425995,0.072370,0.000000
184.510010,-0.004471,-302.381500,-0.002324,0.002862,0.072682,-0.019887,-0.001013,0.726823,-302.381500,0.071624,0.000000
184.960007,0.015266,-302.514954,-0.002367,0.002830,0.071884,0.067908,0.003459,0.718844,-302.514954,0.070870,0.000000
185.100006,0.038727,-302.514954,-0.002380,0.002823,0.071702,0.172265,0.008776,0.717024,-302.514954,0.071546,0.000000