File: Data/compression 17/ManualNoHeating-10-17-reverse-hand-2-3_09062024_171521.csv
Time (sec),S:Load (lbs),S:HL1 (DIM),S:LVDT (in),S:Position (in),Ch:Position (mm),Ch:Load (N),Ch:Stress (MPa),Ch:Strain (mm/mm),Ch:HL1 (DIM),Set Point (),Cycles ()
0.110000,-0.053253,-370.437347,-0.013547,-0.005457,-0.138600,-0.236882,-0.012067,-1.386000,-370.437347,-0.138886,0.000000
0.510000,-0.005585,-370.437347,-0.013555,-0.005434,-0.138019,-0.024842,-0.001266,-1.380190,-370.437347,-0.137238,0.000000
0.910000,-0.009308,-370.437347,-0.013469,-0.005191,-0.131862,-0.041403,-0.002109,-1.318616,-370.437347,-0.130578,0.000000
1.310000,0.027557,-370.526337,-0.013206,-0.004929,-0.125201,0.122581,0.006245,-1.252013,-370.526337,-0.123918,0.000000
1.710000,0.050644,-370.526337,-0.012922,-0.004659,-0.118342,0.225275,0.011476,-1.183416,-370.526337,-0.117240,0.000000
2.110000,0.024200,-370.526337,-0.012654,-0.004405,-0.111881,0.107649,0.005484,-1.118807,-370.526337,-0.110580,0.000000
2.510000,0.009308,-370.526337,-0.012391,-0.004141,-0.105177,0.041403,0.002109,-1.051771,-370.526337,-0.103920,0.000000
2.910000,-0.046547,-370.615295,-0.012107,-0.003879,-0.098534,-0.207051,-0.010548,-0.985343,-370.615295,-0.097259,0.000000
3.310000,-0.026070,-370.570801,-0.011839,-0.003614,-0.091805,-0.115964,-0.005907,-0.918045,-370.570801,-0.090599,0.000000
3.710000,0.016380,-370.615295,-0.011568,-0.003350,-0.085083,0.072863,0.003712,-0.850835,-370.615295,-0.083921,0.000000
4.110000,0.014145,-370.659760,-0.011313,-0.003094,-0.078597,0.062920,0.003205,-0.785968,-370.659760,-0.077261,0.000000
4.510000,-0.001488,-370.659760,-0.011050,-0.002837,-0.072066,-0.006618,-0.000337,-0.720665,-370.659760,-0.070601,0.000000
4.910000,0.002975,-370.659760,-0.010762,-0.002564,-0.065129,0.013236,0.000674,-0.651286,-370.659760,-0.063941,0.000000
5.310000,0.008194,-370.704254,-0.010481,-0.002306,-0.058572,0.036449,0.001857,-0.585724,-370.704254,-0.057280,0.000000
5.710000,0.032394,-370.748718,-0.010227,-0.002041,-0.051843,0.144098,0.007341,-0.518428,-370.748718,-0.050603,0.000000
6.110000,0.059578,-370.748718,-0.009947,-0.001781,-0.045234,0.265016,0.013501,-0.452344,-370.748718,-0.043942,0.000000
6.510000,0.040962,-370.748718,-0.009679,-0.001519,-0.038583,0.182209,0.009282,-0.385828,-370.748718,-0.037282,0.000000
6.910000,0.025322,-370.837677,-0.009416,-0.001256,-0.031905,0.112638,0.005738,-0.319052,-370.837677,-0.030622,0.000000
7.310000,0.001114,-370.837677,-0.009140,-0.000995,-0.025271,0.004955,0.000252,-0.252710,-370.837677,-0.023944,0.000000
7.710001,0.039101,-370.882172,-0.008869,-0.000735,-0.018663,0.173928,0.008860,-0.186627,-370.882172,-0.017284,0.000000
8.110001,0.042450,-370.882172,-0.008593,-0.000460,-0.011682,0.188827,0.009619,-0.116815,-370.882172,-0.010623,0.000000
8.510000,0.040588,-370.926636,-0.008317,-0.000206,-0.005221,0.180546,0.009197,-0.052207,-370.926636,-0.003963,0.000000
8.910001,0.021225,-370.926636,-0.008041,0.000059,0.001492,0.094413,0.004810,0.014916,-370.926636,0.002697,0.000000
9.310000,-0.042824,-370.971130,-0.007778,0.000319,0.008109,-0.190490,-0.009704,0.081086,-370.971130,0.009375,0.000000
9.710000,-0.018623,-370.971130,-0.007498,0.000583,0.014812,-0.082841,-0.004220,0.148122,-370.971130,0.016035,0.000000
10.110001,0.011917,-370.971130,-0.007222,0.000847,0.021516,0.053010,0.002700,0.215158,-370.971130,0.022695,0.000000
10.510000,0.030159,-371.015625,-0.006967,0.001107,0.028116,0.134154,0.006834,0.281155,-371.015625,0.029356,0.000000
10.910001,0.008194,-371.104584,-0.006696,0.001360,0.034550,0.036449,0.001857,0.345502,-371.104584,0.036016,0.000000
11.310000,-0.004471,-371.060089,-0.006416,0.001633,0.041479,-0.019887,-0.001013,0.414794,-371.060089,0.042694,0.000000
11.710001,0.012657,-371.060089,-0.006148,0.001893,0.048088,0.056302,0.002868,0.480877,-371.060089,0.049354,0.000000
12.110001,0.046547,-371.104584,-0.005872,0.002157,0.054791,0.207051,0.010548,0.547913,-371.104584,0.056014,0.000000
12.510000,0.077454,-371.193542,-0.005605,0.002417,0.061382,0.344531,0.017551,0.613823,-371.193542,0.062674,0.000000
12.910001,0.054367,-371.193542,-0.005333,0.002679,0.068043,0.241837,0.012320,0.680426,-371.193542,0.069335,0.000000
13.310000,0.045425,-371.238007,-0.005079,0.002943,0.074746,0.202062,0.010294,0.747462,-371.238007,0.076012,0.000000
13.710001,0.152298,-371.193542,-0.004850,0.000015,0.000382,0.677455,0.034511,0.003817,-371.193542,0.000581,0.000000
14.110001,0.120644,-371.238007,-0.004850,0.000015,0.000373,0.536650,0.027338,0.003730,-371.238007,0.000581,0.000000
14.510000,0.097931,-371.282501,-0.004842,0.000015,0.000373,0.435618,0.022191,0.003730,-371.282501,0.001153,0.000000
14.910001,0.101654,-371.282501,-0.004846,0.000015,0.000382,0.452180,0.023035,0.003817,-371.282501,0.001821,0.000000
15.310000,0.191772,-371.326965,-0.004816,0.000054,0.001379,0.853047,0.043456,0.013790,-371.326965,0.002489,0.000000
15.710001,0.310928,-371.371460,-0.004799,0.000084,0.002142,1.383078,0.070457,0.021421,-371.371460,0.003157,0.000000
16.110001,0.374603,-371.326965,-0.004769,0.000111,0.002827,1.666319,0.084886,0.028271,-371.326965,0.003824,0.000000
16.510000,0.540314,-371.371460,-0.004743,0.000133,0.003391,2.403435,0.122437,0.033909,-371.371460,0.004492,0.000000
16.910002,0.605103,-371.415955,-0.004721,0.000156,0.003955,2.691631,0.137118,0.039546,-371.415955,0.005160,0.000000
17.310001,0.877678,-371.415955,-0.004682,0.000189,0.004805,3.904106,0.198885,0.048045,-371.415955,0.005819,0.000000
17.710001,1.149887,-371.504913,-0.004674,0.000218,0.005542,5.114953,0.260568,0.055417,-371.504913,0.006487,0.000000
18.110001,1.290642,-371.504913,-0.004644,0.000243,0.006166,5.741061,0.292464,0.061660,-371.504913,0.007155,0.000000
18.510000,1.566566,-371.504913,-0.004609,0.000271,0.006895,6.968436,0.354989,0.068946,-371.504913,0.007822,0.000000
18.910002,1.700249,-371.504913,-0.004587,0.000288,0.007319,7.563084,0.385282,0.073194,-371.504913,0.008490,0.000000
19.310001,1.916969,-371.504913,-0.004566,0.000313,0.007952,8.527105,0.434391,0.079524,-371.504913,0.009158,0.000000
19.710001,2.248009,-371.549377,-0.004549,0.000347,0.008802,9.999642,0.509406,0.088023,-371.549377,0.009826,0.000000
20.110001,2.413345,-371.638336,-0.004501,0.000372,0.009461,10.735096,0.546872,0.094615,-371.638336,0.010493,0.000000
20.510000,2.730606,-371.549377,-0.004480,0.000402,0.010207,12.146342,0.618764,0.102073,-371.549377,0.011161,0.000000
20.910002,2.933922,-371.638336,-0.004471,0.000424,0.010771,13.050736,0.664836,0.107711,-371.638336,0.011820,0.000000
21.310001,3.312622,-371.682831,-0.004445,0.000455,0.011569,14.735279,0.750651,0.115689,-371.682831,0.012488,0.000000
21.710001,3.448540,-371.727295,-0.004402,0.000482,0.012237,15.339870,0.781450,0.122366,-371.727295,0.013156,0.000000
22.110001,3.610893,-371.682831,-0.004381,0.000506,0.012844,16.062056,0.818240,0.128437,-371.682831,0.013824,0.000000
22.510000,3.766174,-371.771790,-0.004372,0.000525,0.013338,16.752781,0.853427,0.133380,-371.771790,0.014491,0.000000
22.910002,4.128860,-371.727295,-0.004320,0.000553,0.014049,18.366089,0.935613,0.140492,-371.727295,0.015159,0.000000
23.310001,4.451340,-371.816284,-0.004299,0.000586,0.014882,19.800549,1.008688,0.148816,-371.816284,0.015827,0.000000
23.710001,4.619652,-371.771790,-0.004268,0.000614,0.015593,20.549238,1.046828,0.155928,-371.771790,0.016495,0.000000
24.110001,4.881798,-371.860748,-0.004247,0.000640,0.016260,21.715321,1.106231,0.162605,-371.860748,0.017154,0.000000
24.510000,5.090332,-371.816284,-0.004221,0.000666,0.016911,22.642927,1.153486,0.169109,-371.816284,0.017822,0.000000
24.910002,5.142464,-371.860748,-0.004199,0.000685,0.017397,22.874821,1.165299,0.173965,-371.860748,0.018489,0.000000
25.310001,5.584839,-371.994202,-0.004165,0.000715,0.018151,24.842604,1.265543,0.181510,-371.994202,0.019157,0.000000
25.710001,5.726715,-371.905243,-0.004135,0.000742,0.018836,25.473701,1.297692,0.188363,-371.905243,0.019825,0.000000
26.110001,5.816460,-371.949707,-0.004122,0.000763,0.019374,25.872904,1.318029,0.193739,-371.949707,0.020493,0.000000
26.510002,6.003387,-371.949707,-0.004083,0.000790,0.020059,26.704401,1.360387,0.200590,-371.949707,0.021160,0.000000
26.910002,6.281174,-372.038666,-0.004053,0.000816,0.020735,27.940056,1.423334,0.207354,-372.038666,0.021828,0.000000
27.310001,6.439804,-371.994202,-0.004031,0.000842,0.021377,28.645679,1.459280,0.213771,-371.994202,0.022487,0.000000
27.710001,6.571625,-372.038666,-0.003992,0.000866,0.021993,29.232046,1.489151,0.219929,-372.038666,0.023155,0.000000
28.110001,6.527313,-372.083160,-0.003980,0.000887,0.022531,29.034939,1.479110,0.225305,-372.083160,0.023823,0.000000
28.510002,6.983841,-372.127625,-0.003941,0.000923,0.023432,31.065676,1.582561,0.234325,-372.127625,0.024491,0.000000
28.910002,7.413193,-372.127625,-0.003893,0.000958,0.024326,32.975529,1.679854,0.243257,-372.127625,0.025158,0.000000
29.310001,7.294403,-372.127625,-0.003850,0.000982,0.024933,32.447124,1.652935,0.249328,-372.127625,0.025826,0.000000
29.710001,7.258652,-372.127625,-0.003842,0.001002,0.025445,32.288097,1.644834,0.254445,-372.127625,0.026494,0.000000
30.110001,7.435532,-372.172119,-0.003807,0.001023,0.025973,33.074898,1.684916,0.259735,-372.172119,0.027162,0.000000
30.510002,7.639595,-372.172119,-0.003786,0.001049,0.026641,33.982616,1.731157,0.266413,-372.172119,0.027821,0.000000
30.910002,7.941216,-372.216583,-0.003734,0.001084,0.027526,35.324291,1.799505,0.275258,-372.216583,0.028488,0.000000
31.310001,7.908813,-372.216583,-0.003708,0.001108,0.028141,35.180161,1.792163,0.281415,-372.216583,0.029156,0.000000
31.710001,7.863388,-372.216583,-0.003678,0.001131,0.028740,34.978096,1.781869,0.287398,-372.216583,0.029824,0.000000
32.110001,8.039894,-372.305573,-0.003635,0.001158,0.029416,35.763237,1.821866,0.294164,-372.305573,0.030492,0.000000
32.510002,8.203362,-372.305573,-0.003617,0.001183,0.030058,36.490376,1.858908,0.300581,-372.305573,0.031160,0.000000
32.910000,8.353432,-372.350037,-0.003566,0.001214,0.030830,37.157921,1.892915,0.308299,-372.350037,0.031827,0.000000
33.310001,8.339653,-372.305573,-0.003540,0.001241,0.031515,37.096630,1.889792,0.315151,-372.305573,0.032495,0.000000
33.710003,8.419708,-372.350037,-0.003510,0.001265,0.032139,37.452732,1.907933,0.321394,-372.350037,0.033154,0.000000
34.110001,8.823738,-372.394531,-0.003471,0.001297,0.032946,39.249947,1.999488,0.329460,-372.394531,0.033822,0.000000
34.510002,8.726173,-372.438995,-0.003445,0.001318,0.033475,38.815956,1.977379,0.334749,-372.438995,0.034490,0.000000
34.910000,8.922791,-372.527954,-0.003410,0.001349,0.034255,39.690556,2.021933,0.342554,-372.527954,0.035157,0.000000
35.310001,8.800278,-372.483490,-0.003385,0.001368,0.034758,39.145592,1.994172,0.347584,-372.483490,0.035825,0.000000
35.710003,9.019974,-372.438995,-0.003341,0.001396,0.035461,40.122849,2.043955,0.354609,-372.438995,0.036493,0.000000
36.110001,9.239304,-372.438995,-0.003307,0.001420,0.036059,41.098476,2.093656,0.360593,-372.438995,0.037161,0.000000
36.510002,9.408730,-372.483490,-0.003298,0.001449,0.036805,41.852119,2.132049,0.368051,-372.483490,0.037829,0.000000
36.910000,9.651520,-372.527954,-0.003251,0.001474,0.037430,42.932106,2.187066,0.374296,-372.527954,0.038496,0.000000
37.310001,9.714455,-372.572449,-0.003225,0.001501,0.038115,43.212051,2.201327,0.381146,-372.572449,0.039155,0.000000
37.710003,9.800095,-372.572449,-0.003195,0.001526,0.038765,43.592999,2.220733,0.387651,-372.572449,0.039823,0.000000
38.110001,9.994102,-372.616913,-0.003160,0.001552,0.039424,44.455990,2.264696,0.394242,-372.616913,0.040491,0.000000
38.510002,10.257744,-372.616913,-0.003134,0.001579,0.040101,45.628723,2.324438,0.401006,-372.616913,0.041159,0.000000
38.910004,10.566811,-372.750366,-0.003078,0.001610,0.040898,47.003521,2.394474,0.408984,-372.750366,0.041826,0.000000
39.310001,10.543350,-372.750366,-0.003048,0.001634,0.041514,46.899162,2.389157,0.415141,-372.750366,0.042494,0.000000
39.710003,10.850189,-372.750366,-0.003018,0.001663,0.042251,48.264053,2.458688,0.422514,-372.750366,0.043162,0.000000
40.110001,10.677406,-372.750366,-0.003005,0.001682,0.042720,47.495476,2.419535,0.427195,-372.750366,0.043830,0.000000
40.510002,11.083290,-372.794861,-0.002984,0.001707,0.043370,49.300938,2.511509,0.433700,-372.794861,0.044489,0.000000
40.910004,11.250114,-372.794861,-0.002945,0.001732,0.044003,50.043007,2.549312,0.440030,-372.794861,0.045156,0.000000
41.310001,11.489182,-372.839325,-0.002910,0.001766,0.044844,51.106430,2.603486,0.448444,-372.839325,0.045824,0.000000
41.710003,11.494392,-372.839325,-0.002893,0.001790,0.045460,51.129612,2.604666,0.454600,-372.839325,0.046492,0.000000
42.110001,11.787445,-372.928284,-0.002863,0.001817,0.046145,52.433174,2.671073,0.461451,-372.928284,0.047160,0.000000
42.510002,11.999329,-372.883820,-0.002820,0.001844,0.046848,53.375679,2.719087,0.468475,-372.883820,0.047828,0.000000
42.910004,12.203018,-372.883820,-0.002790,0.001873,0.047576,54.281734,2.765243,0.475759,-372.883820,0.048495,0.000000
43.310001,12.165779,-372.928284,-0.002764,0.001897,0.048192,54.116089,2.756805,0.481917,-372.928284,0.049163,0.000000
43.710003,12.287170,-372.972778,-0.002729,0.001921,0.048799,54.656063,2.784313,0.487988,-372.972778,0.049822,0.000000
44.110001,12.122208,-372.972778,-0.002712,0.001937,0.049198,53.922272,2.746932,0.491978,-372.972778,0.050490,0.000000
44.510002,13.110863,-373.061737,-0.002673,0.001980,0.050282,58.320030,2.970964,0.502818,-373.061737,0.051158,0.000000
44.910004,13.031914,-373.106232,-0.002647,0.002005,0.050932,57.968849,2.953074,0.509324,-373.106232,0.051826,0.000000
45.310001,12.933235,-373.017242,-0.002630,0.002028,0.051505,57.529903,2.930713,0.515047,-373.017242,0.052493,0.000000
45.710003,13.371147,-373.150696,-0.002587,0.002058,0.052285,59.477833,3.029945,0.522851,-373.150696,0.053161,0.000000
46.110001,12.990585,-373.150696,-0.002565,0.002073,0.052649,57.785011,2.943709,0.526492,-373.150696,0.053829,0.000000
46.510002,13.832146,-373.150696,-0.002535,0.002109,0.053560,61.528458,3.134409,0.535599,-373.150696,0.054497,0.000000
46.910004,13.574837,-373.195190,-0.002522,0.002128,0.054054,60.383888,3.076102,0.540542,-373.195190,0.055156,0.000000
47.310001,13.766983,-373.195190,-0.002479,0.002156,0.054774,61.238598,3.119643,0.547741,-373.195190,0.055823,0.000000
47.710003,13.974388,-373.239655,-0.002445,0.002185,0.055494,62.161182,3.166642,0.554939,-373.239655,0.056491,0.000000
48.110001,14.190369,-373.239655,-0.002427,0.002209,0.056101,63.121914,3.215584,0.561010,-373.239655,0.057159,0.000000
48.510002,14.557899,-373.284149,-0.002402,0.002236,0.056804,64.756767,3.298867,0.568035,-373.284149,0.057827,0.000000
48.910004,14.486778,-373.328613,-0.002380,0.002259,0.057376,64.440407,3.282751,0.573758,-373.328613,0.058495,0.000000
49.310001,14.530716,-373.328613,-0.002350,0.002281,0.057948,64.635849,3.292707,0.579481,-373.328613,0.059162,0.000000
49.710003,14.948143,-373.328613,-0.002307,0.002312,0.058729,66.492661,3.387298,0.587285,-373.328613,0.059830,0.000000
50.110001,14.988731,-373.462067,-0.002307,0.002339,0.059414,66.673210,3.396495,0.594136,-373.462067,0.060498,0.000000
50.510002,15.228546,-373.373108,-0.002255,0.002371,0.060229,67.739960,3.450838,0.602288,-373.373108,0.061157,0.000000
50.910004,15.148857,-373.417572,-0.002225,0.002396,0.060871,67.385483,3.432780,0.608708,-373.417572,0.061825,0.000000
51.310001,14.688972,-373.417572,-0.002199,0.002411,0.061244,65.339813,3.328569,0.612436,-373.417572,0.062492,0.000000
51.710003,15.510803,-373.506561,-0.002190,0.002442,0.062033,68.995499,3.514798,0.620327,-373.506561,0.063160,0.000000
52.110001,15.468719,-373.506561,-0.002160,0.002466,0.062640,68.808304,3.505262,0.626398,-373.506561,0.063828,0.000000
52.510002,15.837746,-373.506561,-0.002117,0.002500,0.063490,70.449814,3.588884,0.634895,-373.506561,0.064496,0.000000
52.910004,15.857109,-373.506561,-0.002100,0.002529,0.064227,70.535942,3.593272,0.642268,-373.506561,0.065163,0.000000
53.310001,15.619164,-373.595520,-0.002082,0.002548,0.064712,69.477509,3.539353,0.647124,-373.595520,0.065831,0.000000
53.710003,15.074005,-373.639984,-0.002044,0.002563,0.065103,67.052521,3.415818,0.651027,-373.639984,0.066490,0.000000
54.110004,16.069359,-373.684479,-0.002009,0.002603,0.066109,71.480080,3.641369,0.661087,-373.684479,0.067158,0.000000
54.510002,16.096169,-373.595520,-0.001983,0.002631,0.066837,71.599335,3.647444,0.668373,-373.595520,0.067826,0.000000
54.910004,15.967705,-373.639984,-0.001970,0.002656,0.067470,71.027901,3.618334,0.674701,-373.639984,0.068494,0.000000
55.310001,16.362785,-373.639984,-0.001944,0.002685,0.068199,72.785301,3.707860,0.681987,-373.639984,0.069161,0.000000
55.710003,16.140854,-373.684479,-0.001919,0.002710,0.068832,71.798103,3.657570,0.688319,-373.684479,0.069829,0.000000
56.110004,16.526260,-373.684479,-0.001893,0.002739,0.069569,73.512474,3.744904,0.695688,-373.684479,0.070497,0.000000
56.510002,16.178841,-373.684479,-0.001863,0.002762,0.070167,71.967079,3.666178,0.701672,-373.684479,0.071165,0.000000
56.910004,16.346031,-373.684479,-0.001858,0.002789,0.070844,72.710777,3.704064,0.708436,-373.684479,0.071824,0.000000
57.310001,16.393692,-373.773437,-0.001819,0.002814,0.071468,72.922783,3.714864,0.714681,-373.773437,0.072492,0.000000
57.710003,16.668137,-373.773437,-0.001798,0.002839,0.072110,74.143578,3.777054,0.721100,-373.773437,0.073159,0.000000
58.110004,16.881874,-373.817902,-0.001776,0.002866,0.072804,75.094330,3.825487,0.728038,-373.817902,0.073827,0.000000
58.510002,17.092636,-373.817902,-0.001750,0.002892,0.073454,76.031845,3.873247,0.734540,-373.817902,0.074495,0.000000
58.910004,16.808144,-373.862396,-0.001703,0.002915,0.074044,74.766357,3.808780,0.740437,-373.862396,0.075163,0.000000
59.310001,17.052048,-373.862396,-0.001699,0.002941,0.074694,75.851295,3.864049,0.746943,-373.862396,0.075830,0.000000
59.710003,17.294090,-373.906860,-0.001677,0.002969,0.075406,76.927956,3.918897,0.754055,-373.906860,0.076498,0.000000
60.110004,17.755089,-373.951355,-0.001656,0.003000,0.076203,78.978577,4.023361,0.762030,-373.951355,0.077157,0.000000
60.510002,17.491447,-373.906860,-0.001621,0.003023,0.076793,77.805847,3.963619,0.767931,-373.906860,0.077825,0.000000
60.910004,17.742798,-373.951355,-0.001591,0.003051,0.077504,78.923904,4.020576,0.775039,-373.951355,0.078492,0.000000
61.310001,18.090225,-373.995850,-0.001569,0.003077,0.078163,80.469337,4.099304,0.781632,-373.995850,0.079161,0.000000
61.710003,18.010536,-373.995850,-0.001544,0.003099,0.078718,80.114868,4.081246,0.787181,-373.995850,0.079828,0.000000
62.110004,18.796616,-374.040314,-0.001531,0.003130,0.079498,83.611519,4.259374,0.794985,-374.040314,0.080496,0.000000
62.510002,18.909073,-374.040314,-0.001496,0.003158,0.080201,84.111755,4.284857,0.802010,-374.040314,0.081164,0.000000
62.910004,18.725121,-374.084808,-0.001470,0.003179,0.080756,83.293495,4.243173,0.807562,-374.084808,0.081832,0.000000
63.310001,18.926575,-374.084808,-0.001440,0.003208,0.081476,84.189606,4.288823,0.814757,-374.084808,0.082499,0.000000
63.710003,19.014084,-374.129272,-0.001418,0.003231,0.082074,84.578873,4.308653,0.820741,-374.129272,0.083158,0.000000
64.110001,19.591255,-374.129272,-0.001393,0.003264,0.082898,87.146255,4.439442,0.828981,-374.129272,0.083826,0.000000
64.510002,19.664986,-374.173767,-0.001367,0.003291,0.083601,87.474228,4.456149,0.836006,-374.173767,0.084494,0.000000
64.910004,19.713020,-374.173767,-0.001324,0.003316,0.084216,87.687897,4.467034,0.842164,-374.173767,0.085161,0.000000
65.310005,19.619186,-374.218231,-0.001298,0.003335,0.084719,87.270500,4.445771,0.847194,-374.218231,0.085829,0.000000
65.710007,20.324089,-374.218231,-0.001281,0.003363,0.085431,90.406067,4.605505,0.854306,-374.218231,0.086497,0.000000
66.110001,20.619003,-374.307190,-0.001229,0.003394,0.086220,91.717911,4.672333,0.862197,-374.307190,0.087165,0.000000
66.510002,20.576553,-374.262726,-0.001212,0.003422,0.086922,91.529083,4.662714,0.869222,-374.262726,0.087833,0.000000
66.910004,20.942596,-374.262726,-0.001181,0.003450,0.087625,93.157318,4.745660,0.876247,-374.262726,0.088492,0.000000
67.310005,20.616402,-374.262726,-0.001147,0.003466,0.088041,91.706337,4.671743,0.880406,-374.262726,0.089159,0.000000
67.710007,21.206238,-374.307190,-0.001121,0.003493,0.088726,94.330055,4.805402,0.887261,-374.307190,0.089827,0.000000
68.110001,21.786766,-374.351685,-0.001099,0.003521,0.089429,96.912376,4.936952,0.894286,-374.351685,0.090495,0.000000
68.510002,22.243294,-374.396179,-0.001065,0.003549,0.090157,98.943115,5.040402,0.901568,-374.396179,0.091163,0.000000
68.910004,22.550499,-374.351685,-0.001030,0.003576,0.090833,100.309631,5.110016,0.908331,-374.351685,0.091830,0.000000
69.310005,22.725143,-374.440643,-0.001013,0.003600,0.091449,101.086487,5.149591,0.914489,-374.440643,0.092498,0.000000
69.710007,23.072197,-374.440643,-0.000974,0.003624,0.092039,102.630257,5.228235,0.920386,-374.440643,0.093166,0.000000
70.110001,23.733902,-374.440643,-0.000944,0.003651,0.092741,105.573669,5.378179,0.927411,-374.440643,0.093825,0.000000
70.510002,24.344589,-374.529602,-0.000923,0.003677,0.093400,108.290138,5.516563,0.934004,-374.529602,0.094493,0.000000
70.910004,25.478470,-374.529602,-0.000901,0.003707,0.094155,113.333893,5.773504,0.941548,-374.529602,0.095161,0.000000
71.310005,24.968315,-374.529602,-0.000871,0.003722,0.094536,111.064613,5.657901,0.945363,-374.529602,0.095828,0.000000
71.710007,26.712135,-374.618561,-0.000841,0.003761,0.095534,118.821510,6.053057,0.955336,-374.618561,0.096496,0.000000
72.110001,27.103874,-374.574097,-0.000819,0.003787,0.096201,120.564056,6.141826,0.962012,-374.574097,0.097164,0.000000
72.510002,27.016365,-374.618561,-0.000776,0.003803,0.096609,120.174797,6.121996,0.966089,-374.618561,0.097832,0.000000
72.910004,28.333443,-374.618561,-0.000767,0.003832,0.097329,126.033447,6.420450,0.973288,-374.618561,0.098499,0.000000
73.310005,29.679573,-374.574097,-0.000750,0.003862,0.098083,132.021332,6.725487,0.980831,-374.574097,0.099159,0.000000
73.710007,30.616089,-374.707520,-0.000733,0.003890,0.098794,136.187164,6.937705,0.987943,-374.707520,0.099826,0.000000
74.110001,31.751083,-374.707520,-0.000707,0.003918,0.099523,141.235870,7.194898,0.995229,-374.707520,0.100494,0.000000
74.510002,31.904495,-374.663055,-0.000681,0.003937,0.099991,141.918289,7.229662,0.999911,-374.663055,0.101162,0.000000
74.910004,32.703613,-374.663055,-0.000655,0.003958,0.100529,145.472931,7.410745,1.005289,-374.663055,0.101830,0.000000
75.310005,34.733040,-374.752014,-0.000634,0.003996,0.101491,154.500275,7.870619,1.014914,-374.752014,0.102497,0.000000
75.710007,35.697487,-374.752014,-0.000617,0.004018,0.102064,158.790359,8.089167,1.020637,-374.752014,0.103165,0.000000
76.110001,36.855186,-374.752014,-0.000604,0.004047,0.102792,163.940063,8.351505,1.027923,-374.752014,0.103833,0.000000
76.510002,37.839371,-374.796509,-0.000586,0.004073,0.103443,168.317932,8.574524,1.034429,-374.796509,0.104501,0.000000
76.910004,39.525848,-374.840973,-0.000573,0.004101,0.104171,175.819748,8.956685,1.041711,-374.840973,0.105160,0.000000
77.310005,40.849632,-374.840973,-0.000543,0.004130,0.104891,181.708237,9.256659,1.048910,-374.840973,0.105828,0.000000
77.710007,42.249374,-374.885468,-0.000543,0.004154,0.105515,187.934601,9.573845,1.055155,-374.885468,0.106495,0.000000
78.110001,43.552681,-374.885468,-0.000522,0.004180,0.106183,193.731995,9.869179,1.061831,-374.885468,0.107163,0.000000
78.510002,44.824707,-374.885468,-0.000504,0.004204,0.106782,199.390259,10.157424,1.067815,-374.885468,0.107831,0.000000
78.910004,46.104179,-374.929932,-0.000492,0.004228,0.107389,205.081635,10.447356,1.073886,-374.929932,0.108499,0.000000
79.310005,47.400032,-374.974426,-0.000474,0.004250,0.107943,210.845871,10.741001,1.079435,-374.974426,0.109166,0.000000
79.710007,49.389992,-374.974426,-0.000470,0.004281,0.108750,219.697662,11.191933,1.087501,-374.974426,0.109834,0.000000
80.110001,51.092476,-374.974426,-0.000440,0.004309,0.109444,227.270691,11.577721,1.094438,-374.974426,0.110493,0.000000
80.510002,52.946518,-375.018890,-0.000457,0.004335,0.110120,235.517868,11.997852,1.101202,-375.018890,0.111161,0.000000
80.910004,54.229713,-375.063385,-0.000435,0.004359,0.110710,241.225815,12.288630,1.107103,-375.063385,0.111829,0.000000
81.310005,56.530975,-375.063385,-0.000414,0.004389,0.111473,251.462341,12.810102,1.114733,-375.063385,0.112497,0.000000
81.710007,58.495987,-375.107849,-0.000401,0.004415,0.112150,260.203156,13.255380,1.121497,-375.107849,0.113164,0.000000
82.110001,60.052505,-375.107849,-0.000405,0.004439,0.112739,267.126892,13.608092,1.127393,-375.107849,0.113832,0.000000
82.510002,62.172424,-375.107849,-0.000405,0.004468,0.113485,276.556763,14.088472,1.134853,-375.107849,0.114500,0.000000
82.910004,63.190117,-375.152344,-0.000388,0.004484,0.113884,281.083679,14.319085,1.138843,-375.152344,0.115168,0.000000
83.310005,65.296249,-375.152344,-0.000371,0.004512,0.114604,290.452209,14.796342,1.146038,-375.152344,0.115827,0.000000
83.710007,65.587448,-375.152344,-0.000362,0.004515,0.114682,291.747528,14.862329,1.146821,-375.152344,0.020125,0.000000
84.110001,64.953293,-375.241302,-0.000345,0.004515,0.114691,288.926666,14.718627,1.146908,-375.241302,294.500458,0.000000
84.510002,65.579254,-375.285797,-0.000345,0.004529,0.115046,291.711090,14.860472,1.150462,-375.285797,294.500458,0.000000
84.910004,65.161835,-375.241302,-0.000349,0.004529,0.115046,289.854309,14.765882,1.150462,-375.241302,294.500458,0.000000
85.310005,64.802856,-375.330261,-0.000341,0.004529,0.115046,288.257507,14.684538,1.150462,-375.330261,294.500458,0.000000
85.710007,64.487091,-375.330261,-0.000336,0.004529,0.115046,286.852905,14.612984,1.150462,-375.330261,294.500458,0.000000
86.110001,67.175613,-375.330261,-0.000336,0.004433,0.112592,298.812042,15.222212,1.125921,-375.330261,294.500458,0.000000
86.510002,66.593597,-375.330261,-0.000328,0.004375,0.111118,296.223114,15.090325,1.111175,-375.330261,294.500458,0.000000
86.910004,66.293091,-375.419220,-0.000328,0.004375,0.111126,294.886383,15.022229,1.111262,-375.419220,294.500458,0.000000
87.310005,66.029831,-375.330261,-0.000323,0.004375,0.111126,293.715363,14.962574,1.111262,-375.330261,294.500458,0.000000
87.710007,65.844757,-375.419220,-0.000332,0.004377,0.111178,292.892120,14.920635,1.111784,-375.419220,294.500458,0.000000
88.110001,65.594894,-375.463715,-0.000310,0.004455,0.113156,291.780670,14.864016,1.131557,-375.463715,294.500458,0.000000
88.510002,65.470154,-375.463715,-0.000302,0.004480,0.113789,291.225800,14.835750,1.137889,-375.463715,294.500458,0.000000
88.910004,65.313385,-375.463715,-0.000319,0.004505,0.114430,290.528442,14.800224,1.144304,-375.463715,294.500458,0.000000
89.310005,65.205017,-375.508179,-0.000306,0.004512,0.114604,290.046417,14.775668,1.146038,-375.508179,294.500458,0.000000
89.710007,65.163315,-375.552673,-0.000306,0.004529,0.115046,289.860901,14.766218,1.150462,-375.552673,294.500458,0.000000
90.110001,65.168900,-375.552673,-0.000306,0.004542,0.115367,289.885742,14.767485,1.153672,-375.552673,294.500458,0.000000
90.510002,65.220657,-375.597137,-0.000315,0.004546,0.115480,290.115967,14.779213,1.154800,-375.597137,294.500458,0.000000
90.910004,65.257156,-375.552673,-0.000323,0.004549,0.115541,290.278320,14.787483,1.155405,-375.552673,294.500458,0.000000
91.310005,65.318604,-375.641632,-0.000310,0.004551,0.115592,290.551666,14.801407,1.155924,-375.641632,294.500458,0.000000
91.710007,65.290665,-375.597137,-0.000310,0.004551,0.115601,290.427368,14.795076,1.156011,-375.597137,294.500458,0.000000
92.110001,65.282852,-375.641632,-0.000328,0.004552,0.115619,290.392639,14.793305,1.156185,-375.641632,294.500458,0.000000
92.510002,65.255661,-375.686127,-0.000302,0.004553,0.115636,290.271667,14.787145,1.156359,-375.686127,294.500458,0.000000
92.910004,65.278381,-375.730591,-0.000319,0.004554,0.115679,290.372742,14.792293,1.156794,-375.730591,294.500458,0.000000
93.310005,65.297745,-375.730591,-0.000315,0.004555,0.115688,290.458862,14.796680,1.156878,-375.730591,294.500458,0.000000
93.710007,65.278015,-375.730591,-0.000306,0.004555,0.115688,290.371124,14.792210,1.156878,-375.730591,294.500458,0.000000
94.110008,65.278381,-375.819550,-0.000315,0.004556,0.115714,290.372742,14.792293,1.157139,-375.819550,294.500458,0.000000
94.510002,65.269440,-375.819550,-0.000319,0.004556,0.115723,290.332977,14.790266,1.157226,-375.819550,294.500458,0.000000
94.910004,65.236679,-375.864044,-0.000302,0.004556,0.115731,290.187256,14.782843,1.157313,-375.864044,294.500458,0.000000
95.310005,65.209869,-375.864044,-0.000323,0.004556,0.115731,290.067993,14.776768,1.157313,-375.864044,294.500458,0.000000
95.710007,65.218430,-375.908508,-0.000319,0.004557,0.115757,290.106049,14.778708,1.157574,-375.908508,294.500458,0.000000
96.110008,65.190872,-375.864044,-0.000310,0.004558,0.115775,289.983490,14.772463,1.157748,-375.864044,294.500458,0.000000
96.510002,65.207626,-375.908508,-0.000315,0.004558,0.115784,290.058014,14.776259,1.157835,-375.908508,294.500458,0.000000
96.910004,65.206879,-375.908508,-0.000319,0.004559,0.115792,290.054687,14.776090,1.157919,-375.908508,294.500458,0.000000
97.310005,65.159973,-376.041962,-0.000319,0.004560,0.115827,289.846039,14.765461,1.158267,-376.041962,294.500458,0.000000
97.710007,65.236298,-376.041962,-0.000306,0.004561,0.115844,290.185547,14.782756,1.158441,-376.041962,294.500458,0.000000
98.110008,65.222519,-375.997467,-0.000315,0.004561,0.115844,290.124268,14.779634,1.158441,-375.997467,294.500458,0.000000
98.510002,65.205017,-376.041962,-0.000315,0.004561,0.115844,290.046417,14.775668,1.158441,-376.041962,294.500458,0.000000
98.910004,65.363281,-376.130920,-0.000310,0.004564,0.115931,290.750397,14.811532,1.159308,-376.130920,294.500458,0.000000
99.310005,65.403503,-376.086456,-0.000310,0.004564,0.115931,290.929321,14.820645,1.159308,-376.086456,294.500458,0.000000
99.710007,65.407227,-376.130920,-0.000315,0.004564,0.115931,290.945862,14.821489,1.159308,-376.130920,294.500458,0.000000
100.110008,65.375565,-376.041962,-0.000306,0.004564,0.115931,290.805023,14.814314,1.159308,-376.041962,294.500458,0.000000
100.510002,65.352478,-376.175415,-0.000306,0.004564,0.115931,290.702332,14.809083,1.159308,-376.175415,294.500458,0.000000
100.910004,65.341690,-376.130920,-0.000310,0.004564,0.115931,290.654358,14.806639,1.159308,-376.130920,294.500458,0.000000
101.310005,65.301102,-376.219879,-0.000310,0.004564,0.115931,290.473816,14.797441,1.159308,-376.219879,294.500458,0.000000
101.710007,65.283966,-376.219879,-0.000306,0.004564,0.115931,290.397583,14.793558,1.159308,-376.219879,294.500458,0.000000
102.110008,65.254913,-376.264374,-0.000302,0.004564,0.115931,290.268341,14.786975,1.159308,-376.264374,294.500458,0.000000
102.510002,65.212097,-376.264374,-0.000315,0.004564,0.115931,290.077881,14.777272,1.159308,-376.264374,294.500458,0.000000
102.910004,65.204285,-376.308838,-0.000319,0.004565,0.115957,290.043152,14.775502,1.159569,-376.308838,294.500458,0.000000
103.310005,65.191620,-376.353333,-0.000297,0.004565,0.115957,289.986816,14.772633,1.159569,-376.353333,294.500458,0.000000
103.710007,65.186401,-376.353333,-0.000306,0.004566,0.115966,289.963593,14.771450,1.159656,-376.353333,294.500458,0.000000
104.110008,65.159973,-376.353333,-0.000306,0.004566,0.115974,289.846039,14.765461,1.159743,-376.353333,294.500458,0.000000
104.510002,65.206879,-376.397797,-0.000306,0.004567,0.116009,290.054687,14.776090,1.160087,-376.397797,294.500458,0.000000
104.910004,65.203537,-376.442291,-0.000306,0.004567,0.116009,290.039825,14.775332,1.160087,-376.442291,294.500458,0.000000
105.310005,65.212097,-376.397797,-0.000323,0.004567,0.116009,290.077881,14.777272,1.160087,-376.397797,294.500458,0.000000
105.710007,65.197205,-376.486755,-0.000306,0.004568,0.116017,290.011658,14.773898,1.160174,-376.486755,294.500458,0.000000
106.110008,65.186035,-376.486755,-0.000302,0.004568,0.116017,289.961975,14.771367,1.160174,-376.486755,294.500458,0.000000
106.510002,65.186035,-376.531250,-0.000306,0.004568,0.116026,289.961975,14.771367,1.160261,-376.531250,294.500458,0.000000
106.910004,65.176727,-376.531250,-0.000306,0.004568,0.116026,289.920563,14.769257,1.160261,-376.531250,294.500458,0.000000
107.310005,65.170761,-376.486755,-0.000315,0.004569,0.116044,289.894012,14.767905,1.160436,-376.486755,294.500458,0.000000
107.710007,65.165558,-376.575745,-0.000306,0.004569,0.116061,289.870880,14.766726,1.160610,-376.575745,294.500458,0.000000
108.110008,65.270187,-376.620209,-0.000315,0.004571,0.116104,290.336304,14.790436,1.161041,-376.620209,294.500458,0.000000
108.510002,65.310410,-376.664703,-0.000310,0.004571,0.116104,290.515198,14.799551,1.161041,-376.664703,294.500458,0.000000
108.910004,65.333862,-376.575745,-0.000297,0.004571,0.116104,290.619537,14.804865,1.161041,-376.575745,294.500458,0.000000
109.310005,65.318970,-376.709167,-0.000297,0.004571,0.116104,290.553284,14.801490,1.161041,-376.709167,294.500458,0.000000
109.710007,65.308548,-376.709167,-0.000310,0.004571,0.116104,290.506927,14.799129,1.161041,-376.709167,294.500458,0.000000
110.110008,65.310410,-376.753662,-0.000297,0.004571,0.116104,290.515198,14.799551,1.161041,-376.753662,294.500458,0.000000
110.510002,65.290665,-376.753662,-0.000315,0.004571,0.116104,290.427368,14.795076,1.161041,-376.753662,294.500458,0.000000
110.910004,65.264969,-376.753662,-0.000297,0.004571,0.116104,290.313080,14.789253,1.161041,-376.753662,294.500458,0.000000
111.310005,65.263107,-376.798126,-0.000310,0.004571,0.116113,290.304810,14.788831,1.161128,-376.798126,294.500458,0.000000
111.710007,65.264603,-376.798126,-0.000293,0.004572,0.116130,290.311462,14.789170,1.161302,-376.798126,294.500458,0.000000
112.110008,65.257156,-376.842621,-0.000302,0.004572,0.116130,290.278320,14.787483,1.161302,-376.842621,294.500458,0.000000
112.510002,65.258270,-376.842621,-0.000302,0.004572,0.116130,290.283295,14.787735,1.161302,-376.842621,294.500458,0.000000
112.910004,65.236298,-376.931580,-0.000302,0.004572,0.116130,290.185547,14.782756,1.161302,-376.931580,294.500458,0.000000
113.310005,65.233688,-376.976074,-0.000297,0.004572,0.116130,290.173950,14.782165,1.161302,-376.976074,294.500458,0.000000
113.710007,65.236679,-376.931580,-0.000310,0.004572,0.116130,290.187256,14.782843,1.161302,-376.931580,294.500458,0.000000
114.110008,65.203537,-376.931580,-0.000293,0.004573,0.116148,290.039825,14.775332,1.161476,-376.931580,294.500458,0.000000
114.510002,65.223648,-376.976074,-0.000302,0.004573,0.116148,290.129272,14.779890,1.161476,-376.976074,294.500458,0.000000
114.910004,65.214325,-376.931580,-0.000315,0.004573,0.116148,290.087799,14.777778,1.161476,-376.931580,294.500458,0.000000
115.310005,65.207260,-377.020538,-0.000297,0.004573,0.116148,290.056366,14.776176,1.161476,-377.020538,294.500458,0.000000
115.710007,65.190506,-377.020538,-0.000297,0.004573,0.116148,289.981842,14.772380,1.161476,-377.020538,294.500458,0.000000
116.110008,65.164810,-377.109497,-0.000297,0.004573,0.116148,289.867554,14.766557,1.161476,-377.109497,294.500458,0.000000
116.510002,65.151031,-377.109497,-0.000302,0.004573,0.116156,289.806274,14.763435,1.161563,-377.109497,294.500458,0.000000
116.910004,65.301468,-377.198456,-0.000302,0.004576,0.116234,290.475433,14.797524,1.162343,-377.198456,294.500458,0.000000
117.310005,65.318604,-377.109497,-0.000302,0.004576,0.116234,290.551666,14.801407,1.162343,-377.109497,294.500458,0.000000
117.710007,65.342056,-377.198456,-0.000289,0.004576,0.116234,290.655975,14.806722,1.162343,-377.198456,294.500458,0.000000
118.110008,65.329391,-377.153992,-0.000289,0.004576,0.116234,290.599640,14.803851,1.162343,-377.153992,294.500458,0.000000
118.510002,65.331253,-377.242950,-0.000306,0.004576,0.116234,290.607941,14.804274,1.162343,-377.242950,294.500458,0.000000
118.910004,65.340561,-377.198456,-0.000302,0.004576,0.116234,290.649323,14.806382,1.162343,-377.198456,294.500458,0.000000
119.310005,65.320465,-377.242950,-0.000302,0.004576,0.116234,290.559937,14.801828,1.162343,-377.242950,294.500458,0.000000
119.710007,65.320465,-377.287415,-0.000297,0.004576,0.116234,290.559937,14.801828,1.162343,-377.287415,294.500458,0.000000
120.110008,65.307053,-377.287415,-0.000302,0.004576,0.116234,290.500275,14.798789,1.162343,-377.287415,294.500458,0.000000
120.510002,65.306686,-377.331909,-0.000310,0.004576,0.116234,290.498657,14.798706,1.162343,-377.331909,294.500458,0.000000
120.910004,65.297745,-377.376404,-0.000297,0.004576,0.116234,290.458862,14.796680,1.162343,-377.376404,294.500458,0.000000
121.310005,65.283966,-377.420868,-0.000310,0.004576,0.116234,290.397583,14.793558,1.162343,-377.420868,294.500458,0.000000
121.710007,65.274658,-377.465363,-0.000297,0.004576,0.116234,290.356171,14.791450,1.162343,-377.465363,294.500458,0.000000
122.110008,65.271683,-377.465363,-0.000293,0.004576,0.116234,290.342957,14.790774,1.162343,-377.465363,294.500458,0.000000
122.510002,65.262741,-377.509827,-0.000306,0.004576,0.116234,290.303162,14.788749,1.162343,-377.509827,294.500458,0.000000
122.910004,65.256790,-377.420868,-0.000297,0.004576,0.116234,290.276703,14.787400,1.162343,-377.420868,294.500458,0.000000
123.310005,65.236298,-377.554321,-0.000306,0.004576,0.116234,290.185547,14.782756,1.162343,-377.554321,294.500458,0.000000
123.710007,65.228851,-377.509827,-0.000293,0.004576,0.116234,290.152435,14.781069,1.162343,-377.509827,294.500458,0.000000
124.110008,65.218430,-377.598785,-0.000302,0.004576,0.116243,290.106049,14.778708,1.162430,-377.598785,294.500458,0.000000
124.510002,65.222153,-377.554321,-0.000297,0.004576,0.116243,290.122620,14.779552,1.162430,-377.554321,294.500458,0.000000
124.910004,65.208740,-377.554321,-0.000302,0.004576,0.116243,290.062958,14.776512,1.162430,-377.554321,294.500458,0.000000
125.310005,65.199066,-377.598785,-0.000302,0.004576,0.116243,290.019928,14.774320,1.162430,-377.598785,294.500458,0.000000
125.710007,65.184174,-377.643280,-0.000315,0.004576,0.116243,289.953674,14.770945,1.162430,-377.643280,294.500458,0.000000
126.110008,65.168533,-377.598785,-0.000297,0.004576,0.116243,289.884125,14.767401,1.162430,-377.598785,294.500458,0.000000
126.510010,65.166672,-377.687744,-0.000310,0.004576,0.116243,289.875824,14.766979,1.162430,-377.687744,294.500458,0.000000
126.910004,65.134644,-377.732239,-0.000302,0.004576,0.116243,289.733368,14.759721,1.162430,-377.732239,294.500458,0.000000
127.310005,65.135391,-377.776703,-0.000302,0.004576,0.116243,289.736694,14.759891,1.162430,-377.776703,294.500458,0.000000
127.710007,65.111557,-377.732239,-0.000315,0.004576,0.116243,289.630676,14.754489,1.162430,-377.732239,294.500458,0.000000
128.110001,65.106720,-377.776703,-0.000306,0.004576,0.116243,289.609161,14.753393,1.162430,-377.776703,294.500458,0.000000
128.510010,65.081772,-377.776703,-0.000302,0.004576,0.116243,289.498169,14.747741,1.162430,-377.776703,294.500458,0.000000
128.910004,65.117142,-377.821198,-0.000315,0.004578,0.116278,289.655518,14.755754,1.162778,-377.821198,294.500458,0.000000
129.310013,65.110062,-377.865692,-0.000302,0.004578,0.116278,289.624023,14.754150,1.162778,-377.865692,294.500458,0.000000
129.710007,65.110062,-377.865692,-0.000293,0.004578,0.116278,289.624023,14.754150,1.162778,-377.865692,294.500458,0.000000
130.110001,65.112305,-377.954651,-0.000297,0.004578,0.116278,289.634003,14.754659,1.162778,-377.954651,294.500458,0.000000
130.510010,65.105972,-377.910156,-0.000297,0.004578,0.116278,289.605835,14.753223,1.162778,-377.910156,294.500458,0.000000
130.910004,65.107834,-377.910156,-0.000310,0.004578,0.116278,289.614105,14.753646,1.162778,-377.910156,294.500458,0.000000
131.310013,65.094055,-377.999115,-0.000293,0.004578,0.116278,289.552826,14.750524,1.162778,-377.999115,294.500458,0.000000
131.710007,65.090698,-377.999115,-0.000319,0.004578,0.116278,289.537872,14.749763,1.162778,-377.999115,294.500458,0.000000
132.110001,65.072083,-377.999115,-0.000306,0.004578,0.116278,289.455078,14.745544,1.162778,-377.999115,294.500458,0.000000
132.510010,65.059052,-378.043610,-0.000310,0.004578,0.116278,289.397125,14.742592,1.162778,-378.043610,294.500458,0.000000
132.910004,65.054581,-378.088074,-0.000293,0.004578,0.116278,289.377228,14.741579,1.162778,-378.088074,294.500458,0.000000
133.310013,65.059418,-378.043610,-0.000302,0.004579,0.116304,289.398743,14.742675,1.163036,-378.043610,294.500458,0.000000
133.710007,65.056824,-378.132568,-0.000302,0.004579,0.116304,289.387207,14.742087,1.163036,-378.132568,294.500458,0.000000
134.110001,65.047134,-378.177032,-0.000302,0.004579,0.116304,289.344116,14.739891,1.163036,-378.177032,294.500458,0.000000
134.510010,65.056442,-378.177032,-0.000293,0.004579,0.116304,289.385498,14.742001,1.163036,-378.177032,294.500458,0.000000
134.910004,65.040802,-378.132568,-0.000302,0.004579,0.116304,289.315948,14.738456,1.163036,-378.132568,294.500458,0.000000
135.310013,65.039688,-378.221527,-0.000315,0.004579,0.116304,289.310974,14.738203,1.163036,-378.221527,294.500458,0.000000
135.710007,65.042664,-378.177032,-0.000297,0.004579,0.116304,289.324219,14.738878,1.163036,-378.177032,294.500458,0.000000
136.110001,65.028152,-378.266022,-0.000302,0.004579,0.116304,289.259674,14.735590,1.163036,-378.266022,294.500458,0.000000
136.510010,65.021439,-378.221527,-0.000293,0.004579,0.116304,289.229797,14.734068,1.163036,-378.221527,294.500458,0.000000
136.910004,65.006927,-378.266022,-0.000302,0.004579,0.116304,289.165253,14.730780,1.163036,-378.266022,294.500458,0.000000
137.310013,65.010269,-378.266022,-0.000302,0.004579,0.116304,289.180115,14.731537,1.163036,-378.266022,294.500458,0.000000
137.710007,65.268326,-378.354980,-0.000289,0.004583,0.116416,290.328003,14.790014,1.164164,-378.354980,294.500458,0.000000
138.110001,65.317474,-378.399445,-0.000302,0.004583,0.116416,290.546631,14.801151,1.164164,-378.399445,294.500458,0.000000
138.510010,65.331253,-378.354980,-0.000293,0.004583,0.116416,290.607941,14.804274,1.164164,-378.354980,294.500458,0.000000
138.910004,65.343918,-378.399445,-0.000306,0.004583,0.116416,290.664276,14.807143,1.164164,-378.399445,294.500458,0.000000
139.310013,65.349869,-378.443939,-0.000297,0.004583,0.116416,290.690735,14.808493,1.164164,-378.443939,294.500458,0.000000
139.710007,65.349869,-378.443939,-0.000302,0.004583,0.116416,290.690735,14.808493,1.164164,-378.443939,294.500458,0.000000
140.110001,65.357697,-378.532898,-0.000289,0.004583,0.116416,290.725555,14.810266,1.164164,-378.532898,294.500458,0.000000
140.510010,65.362534,-378.488403,-0.000302,0.004583,0.116416,290.747070,14.811362,1.164164,-378.488403,294.500458,0.000000
140.910004,65.364395,-378.488403,-0.000302,0.004583,0.116416,290.755341,14.811783,1.164164,-378.488403,294.500458,0.000000
141.310013,65.365891,-378.577362,-0.000297,0.004583,0.116416,290.761993,14.812122,1.164164,-378.577362,294.500458,0.000000
141.710007,65.349869,-378.577362,-0.000297,0.004583,0.116416,290.690735,14.808493,1.164164,-378.577362,294.500458,0.000000
142.110001,65.352859,-378.532898,-0.000302,0.004583,0.116416,290.704041,14.809170,1.164164,-378.532898,294.500458,0.000000
142.510010,65.348007,-378.621857,-0.000302,0.004583,0.116416,290.682465,14.808070,1.164164,-378.621857,294.500458,0.000000
142.910004,65.361786,-378.621857,-0.000297,0.004583,0.116416,290.743744,14.811193,1.164164,-378.621857,294.500458,0.000000
143.310013,65.348007,-378.621857,-0.000302,0.004583,0.116416,290.682465,14.808070,1.164164,-378.621857,294.500458,0.000000
143.710007,65.329025,-378.666351,-0.000297,0.004583,0.116416,290.598022,14.803769,1.164164,-378.666351,294.500458,0.000000
144.110001,65.340195,-378.666351,-0.000306,0.004580,0.116338,290.647705,14.806300,1.163384,-378.666351,0.116416,0.000000
144.510010,65.256409,-378.666351,-0.000306,0.004568,0.116026,290.274994,14.787313,1.160261,-378.666351,0.115809,0.000000
144.910004,65.152893,-378.755310,-0.000302,0.004544,0.115428,289.814545,14.763856,1.154278,-378.755310,0.115142,0.000000
145.310013,65.151031,-378.710815,-0.000315,0.004522,0.114847,289.806274,14.763435,1.148468,-378.710815,0.114483,0.000000
145.710007,65.134277,-378.710815,-0.000297,0.004499,0.114266,289.731750,14.759639,1.142658,-378.710815,0.113815,0.000000
146.110001,65.124588,-378.755310,-0.000310,0.004474,0.113633,289.688629,14.757442,1.136326,-378.755310,0.113147,0.000000
146.510010,65.115646,-378.799774,-0.000310,0.004445,0.112896,289.648865,14.755416,1.128957,-378.799774,0.112479,0.000000
146.910004,65.089584,-378.799774,-0.000293,0.004421,0.112306,289.532928,14.749511,1.123056,-378.799774,0.111811,0.000000
147.310013,65.069107,-378.888733,-0.000289,0.004408,0.111968,289.441833,14.744871,1.119676,-378.888733,0.111144,0.000000
147.710007,65.003937,-378.888733,-0.000306,0.004378,0.111213,289.151947,14.730103,1.112129,-378.888733,0.110476,0.000000
148.110001,64.634918,-378.888733,-0.000285,0.004347,0.110407,287.510468,14.646482,1.104067,-378.888733,0.109808,0.000000
148.510010,63.803040,-378.977692,-0.000289,0.004326,0.109869,283.810089,14.457975,1.098689,-378.977692,0.109149,0.000000
148.910004,62.579422,-378.933228,-0.000267,0.004301,0.109236,278.367157,14.180700,1.092357,-378.933228,0.108481,0.000000
149.310013,61.259361,-378.933228,-0.000259,0.004273,0.108542,272.495239,13.881570,1.085419,-378.933228,0.107814,0.000000
149.710007,59.690186,-378.977692,-0.000259,0.004251,0.107987,265.515198,13.525990,1.079870,-378.977692,0.107146,0.000000
150.110001,57.985092,-378.977692,-0.000259,0.004230,0.107432,257.930573,13.139609,1.074322,-378.977692,0.106478,0.000000
150.510010,55.772827,-378.977692,-0.000246,0.004202,0.106721,248.089920,12.638303,1.067210,-378.977692,0.105810,0.000000
150.910004,53.223938,-379.022186,-0.000246,0.004173,0.106001,236.751907,12.060717,1.060011,-379.022186,0.105143,0.000000
151.310013,51.068275,-379.111145,-0.000246,0.004151,0.105446,227.163040,11.572237,1.054458,-379.111145,0.104475,0.000000
151.710007,48.144035,-379.111145,-0.000246,0.004124,0.104761,214.155365,10.909595,1.047608,-379.111145,0.103816,0.000000
152.110001,45.706108,-379.066650,-0.000259,0.004104,0.104241,203.310928,10.357152,1.042407,-379.066650,0.103148,0.000000
152.510010,42.602760,-379.155640,-0.000250,0.004074,0.103469,189.506546,9.653924,1.034686,-379.155640,0.102480,0.000000
152.910004,39.486000,-379.111145,-0.000259,0.004047,0.102784,175.642502,8.947656,1.027835,-379.111145,0.101812,0.000000
153.310013,36.723373,-379.111145,-0.000246,0.004019,0.102072,163.353729,8.321635,1.020724,-379.111145,0.101145,0.000000
153.710007,34.198685,-379.155640,-0.000246,0.003997,0.101535,152.123352,7.749533,1.015349,-379.155640,0.100477,0.000000
154.110001,31.303116,-379.200104,-0.000254,0.003970,0.100832,139.243210,7.093387,1.008324,-379.200104,0.099809,0.000000
154.510010,28.980629,-379.244598,-0.000250,0.003952,0.100373,128.912277,6.567104,1.003726,-379.244598,0.099141,0.000000
154.910004,26.158791,-379.289062,-0.000237,0.003927,0.099740,116.360115,5.927667,0.997397,-379.289062,0.098482,0.000000
155.310013,22.437302,-379.289062,-0.000246,0.003889,0.098777,99.806099,5.084365,0.987772,-379.289062,0.097814,0.000000
155.710007,19.748772,-379.333557,-0.000259,0.003866,0.098187,87.846924,4.475136,0.981872,-379.333557,0.097147,0.000000
156.110001,16.968636,-379.378021,-0.000250,0.003843,0.097615,75.480263,3.845148,0.976149,-379.378021,0.096479,0.000000
156.510010,13.828049,-379.333557,-0.000237,0.003814,0.096878,61.510231,3.133481,0.968780,-379.333557,0.095811,0.000000
156.910004,11.127602,-379.378021,-0.000241,0.003785,0.096141,49.498043,2.521550,0.961407,-379.378021,0.095143,0.000000
157.310013,8.449875,-379.466980,-0.000254,0.003764,0.095595,37.586922,1.914769,0.955945,-379.466980,0.094476,0.000000
157.710007,5.494728,-379.378021,-0.000246,0.003737,0.094918,24.441771,1.245123,0.949178,-379.378021,0.093808,0.000000
158.110001,2.879555,-379.466980,-0.000241,0.003712,0.094294,12.808899,0.652516,0.942937,-379.466980,0.093140,0.000000
158.510010,0.344818,-379.422516,-0.000250,0.003687,0.093643,1.533828,0.078137,0.936430,-379.422516,0.092481,0.000000
158.910004,-1.425072,-379.422516,-0.000259,0.003658,0.092906,-6.339036,-0.322926,0.929061,-379.422516,0.091813,0.000000
159.310013,0.071869,-379.422516,-0.000250,0.003627,0.092134,0.319689,0.016286,0.921340,-379.422516,0.091145,0.000000
159.710007,0.141869,-379.511475,-0.000259,0.003603,0.091510,0.631063,0.032148,0.915099,-379.511475,0.090478,0.000000
160.110001,0.143730,-379.511475,-0.000250,0.003579,0.090894,0.639344,0.032570,0.908941,-379.511475,0.089810,0.000000
160.510010,0.133308,-379.555969,-0.000259,0.003550,0.090174,0.592985,0.030208,0.901742,-379.555969,0.089142,0.000000
160.910004,0.125488,-379.600433,-0.000310,0.003523,0.089480,0.558200,0.028436,0.894804,-379.600433,0.088474,0.000000
161.310013,0.124367,-379.644928,-0.000379,0.003492,0.088709,0.553211,0.028182,0.887087,-379.644928,0.087807,0.000000
161.710007,0.124741,-379.689392,-0.000431,0.003469,0.088110,0.554874,0.028267,0.881103,-379.689392,0.087147,0.000000
162.110001,0.116180,-379.600433,-0.000483,0.003443,0.087460,0.516796,0.026327,0.874596,-379.600433,0.086480,0.000000
162.510010,0.100914,-379.689392,-0.000530,0.003421,0.086887,0.448888,0.022867,0.868874,-379.689392,0.085812,0.000000
162.910004,0.106125,-379.733887,-0.000578,0.003391,0.086133,0.472067,0.024048,0.861330,-379.733887,0.085144,0.000000
163.310013,0.084526,-379.644928,-0.000651,0.003364,0.085439,0.375991,0.019154,0.854393,-379.644928,0.084476,0.000000
163.710007,0.092720,-379.689392,-0.000711,0.003338,0.084780,0.412439,0.021011,0.847799,-379.689392,0.083809,0.000000
164.110001,0.054367,-379.733887,-0.000755,0.003313,0.084147,0.241837,0.012320,0.841471,-379.733887,0.083141,0.000000
164.510010,0.075966,-379.822845,-0.000789,0.003292,0.083627,0.337913,0.017214,0.836267,-379.822845,0.082473,0.000000
164.910004,0.058090,-379.822845,-0.000858,0.003261,0.082829,0.258398,0.013163,0.828288,-379.822845,0.081814,0.000000
165.310013,0.063675,-379.822845,-0.000905,0.003237,0.082222,0.283240,0.014429,0.822217,-379.822845,0.081146,0.000000
165.710007,0.034630,-379.867310,-0.000957,0.003206,0.081441,0.154041,0.007847,0.814413,-379.867310,0.080478,0.000000
166.110001,0.005585,-379.911804,-0.001005,0.003181,0.080808,0.024842,0.001266,0.808081,-379.911804,0.079811,0.000000
166.510010,0.013405,-379.867310,-0.001043,0.003151,0.080045,0.059628,0.003038,0.800450,-379.867310,0.079143,0.000000
166.900009,0.052132,-379.956299,-0.001099,0.003132,0.079551,0.231893,0.011813,0.795507,-379.956299,0.079421,0.000000