File: Data/compression 17/ManualNoHeating-10-17-reverse-hand-1-3_09062024_165746.csv
Time (sec),S:Load (lbs),S:HL1 (DIM),S:LVDT (in),S:Position (in),Ch:Position (mm),Ch:Load (N),Ch:Stress (MPa),Ch:Strain (mm/mm),Ch:HL1 (DIM),Set Point (),Cycles ()
0.110000,-0.021225,-305.584137,-0.010649,-0.005064,-0.128627,-0.094413,-0.004810,-1.286270,-305.584137,-0.128410,0.000000
0.520000,0.032394,-305.762054,-0.010662,-0.005017,-0.127439,0.144098,0.007341,-1.274387,-305.762054,-0.126572,0.000000
0.930000,-0.010056,-305.673096,-0.010529,-0.004764,-0.121013,-0.044729,-0.002279,-1.210127,-305.673096,-0.119738,0.000000
1.340000,0.051758,-305.717590,-0.010223,-0.004491,-0.114075,0.230230,0.011728,-1.140748,-305.717590,-0.112904,0.000000
1.750000,0.068886,-305.673096,-0.009960,-0.004229,-0.107406,0.306419,0.015610,-1.074059,-305.673096,-0.106088,0.000000
2.160000,0.049896,-305.762054,-0.009671,-0.003960,-0.100572,0.221950,0.011307,-1.005722,-305.762054,-0.099254,0.000000
2.570000,0.032768,-305.806549,-0.009395,-0.003685,-0.093608,0.145760,0.007425,-0.936084,-305.806549,-0.092420,0.000000
2.980000,0.022713,-305.851013,-0.009140,-0.003420,-0.086879,0.101031,0.005147,-0.868787,-305.851013,-0.085587,0.000000
3.390000,0.040215,-305.851013,-0.008839,-0.003151,-0.080045,0.178883,0.009113,-0.800449,-305.851013,-0.078753,0.000000
3.800000,0.047287,-305.895508,-0.008567,-0.002881,-0.073168,0.210343,0.010715,-0.731679,-305.895508,-0.071936,0.000000
4.210000,0.058090,-305.895508,-0.008295,-0.002611,-0.066317,0.258398,0.013163,-0.663167,-305.895508,-0.065103,0.000000
4.620000,0.042076,-305.939972,-0.008024,-0.002346,-0.059596,0.187164,0.009535,-0.595958,-305.939972,-0.058269,0.000000
5.030000,0.037605,-305.939972,-0.007743,-0.002074,-0.052675,0.167277,0.008521,-0.526753,-305.939972,-0.051435,0.000000
5.440000,0.081177,-305.939972,-0.007455,-0.001806,-0.045876,0.361092,0.018395,-0.458761,-305.939972,-0.044601,0.000000
5.850000,0.077080,-305.984467,-0.007187,-0.001541,-0.039129,0.342868,0.017467,-0.391292,-305.984467,-0.037768,0.000000
6.260000,0.078568,-306.073425,-0.006885,-0.001265,-0.032131,0.349486,0.017804,-0.321307,-306.073425,-0.030951,0.000000
6.670001,0.050644,-305.984467,-0.006622,-0.000994,-0.025236,0.225275,0.011476,-0.252364,-305.984467,-0.024118,0.000000
7.080000,-0.004845,-306.073425,-0.006355,-0.000731,-0.018559,-0.021550,-0.001098,-0.185587,-306.073425,-0.017284,0.000000
7.490000,0.005959,-306.162384,-0.006079,-0.000460,-0.011682,0.026505,0.001350,-0.116815,-306.162384,-0.010450,0.000000
7.900001,0.054733,-306.162384,-0.005803,-0.000191,-0.004839,0.243466,0.012403,-0.048392,-306.162384,-0.003616,0.000000
8.310000,0.072609,-306.206879,-0.005536,0.000079,0.002012,0.322981,0.016453,0.020121,-306.206879,0.003200,0.000000
8.720000,0.070747,-306.162384,-0.005247,0.000345,0.008759,0.314700,0.016032,0.087590,-306.162384,0.010034,0.000000
9.130000,0.126976,-306.251343,-0.005191,-0.000001,-0.000035,0.564817,0.028773,-0.000346,-306.251343,0.000104,0.000000
9.540001,0.095695,-306.295837,-0.005208,-0.000001,-0.000035,0.425675,0.021685,-0.000346,-306.295837,0.000529,0.000000
9.950001,0.115433,-306.295837,-0.005204,-0.000001,-0.000026,0.513470,0.026157,-0.000261,-306.295837,0.001214,0.000000
10.360001,0.114685,-306.429260,-0.005187,0.000035,0.000885,0.510145,0.025988,0.008845,-306.429260,0.001899,0.000000
10.770000,0.171661,-306.384796,-0.005170,0.000057,0.001440,0.763588,0.038899,0.014396,-306.384796,0.002576,0.000000
11.180000,0.202942,-306.384796,-0.005144,0.000078,0.001969,0.902731,0.045987,0.019685,-306.384796,0.003261,0.000000
11.590000,0.310181,-306.429260,-0.005096,0.000117,0.002975,1.379753,0.070288,0.029745,-306.429260,0.003946,0.000000
12.000001,0.345932,-306.384796,-0.005075,0.000141,0.003582,1.538782,0.078389,0.035816,-306.384796,0.004631,0.000000
12.410001,0.428596,-306.518219,-0.005053,0.000168,0.004258,1.906492,0.097121,0.042580,-306.518219,0.005316,0.000000
12.820001,0.599518,-306.473755,-0.005027,0.000192,0.004883,2.666789,0.135853,0.048825,-306.473755,0.005992,0.000000
13.230000,0.775650,-306.562714,-0.004988,0.000222,0.005628,3.450264,0.175765,0.056283,-306.562714,0.006678,0.000000
13.640000,0.969658,-306.518219,-0.004967,0.000252,0.006391,4.313254,0.219728,0.063914,-306.518219,0.007363,0.000000
14.050000,1.089561,-306.562714,-0.004941,0.000273,0.006946,4.846611,0.246898,0.069464,-306.562714,0.008048,0.000000
14.460001,1.344261,-306.651672,-0.004911,0.000305,0.007753,5.979572,0.304614,0.077530,-306.651672,0.008733,0.000000
14.870001,1.571785,-306.607208,-0.004885,0.000329,0.008369,6.991649,0.356172,0.083688,-306.607208,0.009409,0.000000
15.280001,1.838028,-306.696167,-0.004859,0.000359,0.009115,8.175957,0.416503,0.091146,-306.696167,0.010095,0.000000
15.690001,1.798927,-306.651672,-0.004868,0.000366,0.009305,8.002028,0.407643,0.093054,-306.651672,0.010780,0.000000
16.100000,2.243912,-306.696167,-0.004816,0.000410,0.010424,9.981418,0.508478,0.104240,-306.696167,0.011465,0.000000
16.510000,2.423027,-306.785126,-0.004803,0.000433,0.011005,10.778163,0.549066,0.110051,-306.785126,0.012150,0.000000
16.920000,2.626343,-306.740631,-0.004773,0.000454,0.011543,11.682556,0.595138,0.115428,-306.740631,0.012826,0.000000
17.330000,2.991264,-306.874084,-0.004747,0.000487,0.012358,13.305808,0.677830,0.123579,-306.874084,0.013511,0.000000
17.740002,3.282089,-306.829590,-0.004725,0.000521,0.013243,14.599463,0.743732,0.132426,-306.829590,0.014196,0.000000
18.150002,3.430290,-306.874084,-0.004678,0.000547,0.013893,15.258693,0.777315,0.138930,-306.874084,0.014882,0.000000
18.560001,3.747185,-306.829590,-0.004665,0.000576,0.014639,16.668310,0.849124,0.146388,-306.829590,0.015567,0.000000
18.970001,3.856659,-306.829590,-0.004639,0.000597,0.015159,17.155275,0.873931,0.151591,-306.829590,0.016243,0.000000
19.380001,4.123276,-306.918549,-0.004618,0.000621,0.015775,18.341246,0.934348,0.157749,-306.918549,0.016928,0.000000
19.790001,4.339630,-306.963043,-0.004575,0.000650,0.016503,19.303638,0.983374,0.165033,-306.963043,0.017613,0.000000
20.200001,4.570869,-307.007538,-0.004557,0.000679,0.017249,20.332243,1.035774,0.172491,-307.007538,0.018298,0.000000
20.610001,4.918297,-307.007538,-0.004536,0.000711,0.018064,21.877676,1.114502,0.180644,-307.007538,0.018984,0.000000
21.020000,4.911591,-307.052002,-0.004506,0.000733,0.018611,21.847847,1.112982,0.186107,-307.052002,0.019660,0.000000
21.430000,5.238907,-307.096497,-0.004467,0.000760,0.019313,23.303822,1.187153,0.193132,-307.096497,0.020345,0.000000
21.840000,5.381149,-307.096497,-0.004454,0.000789,0.020042,23.936548,1.219386,0.200416,-307.096497,0.021030,0.000000
22.250002,5.522285,-307.140961,-0.004415,0.000814,0.020683,24.564352,1.251368,0.206833,-307.140961,0.021715,0.000000
22.660002,5.683517,-307.185455,-0.004393,0.000839,0.021299,25.281548,1.287903,0.212991,-307.185455,0.022400,0.000000
23.070002,6.074509,-307.185455,-0.004368,0.000867,0.022010,27.020763,1.376503,0.220101,-307.185455,0.023077,0.000000
23.480001,6.348579,-307.229919,-0.004337,0.000899,0.022843,28.239891,1.438609,0.228428,-307.229919,0.023762,0.000000
23.890001,6.339264,-307.229919,-0.004290,0.000924,0.023467,28.198454,1.436498,0.234671,-307.229919,0.024447,0.000000
24.300001,6.555244,-307.274414,-0.004273,0.000951,0.024161,29.159184,1.485440,0.241609,-307.274414,0.025132,0.000000
24.710001,6.747391,-307.318878,-0.004260,0.000978,0.024829,30.013893,1.528981,0.248287,-307.318878,0.025817,0.000000
25.120001,7.035233,-307.363373,-0.004234,0.001006,0.025540,31.294277,1.594206,0.255397,-307.363373,0.026494,0.000000
25.530001,7.156998,-307.318878,-0.004195,0.001032,0.026208,31.835917,1.621799,0.262076,-307.318878,0.027179,0.000000
25.940001,7.289932,-307.363373,-0.004182,0.001059,0.026901,32.427238,1.651922,0.269013,-307.363373,0.027864,0.000000
26.350000,7.514473,-307.407867,-0.004139,0.001086,0.027578,33.426044,1.702804,0.275777,-307.407867,0.028549,0.000000
26.760002,7.425850,-307.407867,-0.004126,0.001103,0.028011,33.031830,1.682722,0.280114,-307.407867,0.029234,0.000000
27.170002,7.854080,-307.452332,-0.004100,0.001137,0.028879,34.936695,1.779760,0.288786,-307.452332,0.029911,0.000000
27.580002,8.005264,-307.496826,-0.004066,0.001165,0.029590,35.609196,1.814019,0.295897,-307.496826,0.030596,0.000000
27.990002,8.159050,-307.585785,-0.004031,0.001192,0.030275,36.293266,1.848867,0.302748,-307.585785,0.031281,0.000000
28.400002,8.390663,-307.585785,-0.004023,0.001221,0.031003,37.323532,1.901351,0.310032,-307.585785,0.031966,0.000000
28.810001,8.500893,-307.541290,-0.003984,0.001244,0.031593,37.813858,1.926330,0.315931,-307.541290,0.032651,0.000000
29.220001,8.799156,-307.674744,-0.003958,0.001277,0.032426,39.140602,1.993917,0.324256,-307.674744,0.033328,0.000000
29.630001,8.868050,-307.630249,-0.003928,0.001303,0.033093,39.447056,2.009529,0.330932,-307.630249,0.034013,0.000000
30.040001,8.821877,-307.674744,-0.003906,0.001323,0.033596,39.241665,1.999066,0.335962,-307.674744,0.034698,0.000000
30.450001,9.163712,-307.674744,-0.003885,0.001350,0.034299,40.762226,2.076527,0.342987,-307.674744,0.035383,0.000000
30.860001,9.515602,-307.719208,-0.003854,0.001383,0.035131,42.327511,2.156266,0.351312,-307.719208,0.036068,0.000000
31.270002,9.679451,-307.808167,-0.003824,0.001411,0.035834,43.056347,2.193395,0.358337,-307.808167,0.036744,0.000000
31.680002,9.657478,-307.719208,-0.003794,0.001434,0.036432,42.958611,2.188416,0.364321,-307.719208,0.037429,0.000000
32.090000,9.716682,-307.852661,-0.003768,0.001458,0.037022,43.221962,2.201832,0.370218,-307.852661,0.038115,0.000000
32.500000,9.708862,-307.808167,-0.003751,0.001474,0.037447,43.187176,2.200060,0.374468,-307.808167,0.038800,0.000000
32.910000,10.443184,-307.852661,-0.003704,0.001517,0.038540,46.453602,2.366459,0.385395,-307.852661,0.039485,0.000000
33.320000,10.239120,-307.897156,-0.003699,0.001540,0.039112,45.545883,2.320218,0.391118,-307.897156,0.040161,0.000000
33.730003,10.472977,-307.852661,-0.003652,0.001566,0.039788,46.586128,2.373210,0.397883,-307.852661,0.040846,0.000000
34.140003,10.638680,-307.941620,-0.003630,0.001592,0.040439,47.323212,2.410759,0.404388,-307.941620,0.041531,0.000000
34.550003,10.937325,-307.986115,-0.003609,0.001620,0.041158,48.651649,2.478433,0.411585,-307.986115,0.042217,0.000000
34.960003,11.217720,-307.986115,-0.003583,0.001651,0.041939,49.898911,2.541972,0.419391,-307.986115,0.042902,0.000000
35.370003,11.021851,-308.030579,-0.003566,0.001671,0.042451,49.027641,2.497587,0.424506,-308.030579,0.043578,0.000000
35.780003,11.446358,-308.075073,-0.003527,0.001703,0.043266,50.915943,2.593782,0.432659,-308.075073,0.044263,0.000000
36.190002,11.526787,-308.030579,-0.003479,0.001728,0.043890,51.273708,2.612007,0.438902,-308.030579,0.044948,0.000000
36.600002,11.773674,-308.075073,-0.003488,0.001758,0.044645,52.371918,2.667953,0.446447,-308.075073,0.045633,0.000000
37.010002,11.168190,-308.119537,-0.003462,0.001766,0.044862,49.678589,2.530748,0.448616,-308.119537,0.046319,0.000000
37.420002,12.146790,-308.164032,-0.003441,0.001809,0.045946,54.031620,2.752502,0.459456,-308.164032,0.046995,0.000000
37.830002,12.149765,-308.208496,-0.003402,0.001837,0.046648,54.044853,2.753176,0.466481,-308.208496,0.047680,0.000000
38.240002,12.382126,-308.252991,-0.003376,0.001863,0.047316,55.078445,2.805830,0.473157,-308.252991,0.048365,0.000000
38.650002,12.294250,-308.164032,-0.003350,0.001881,0.047775,54.687557,2.785917,0.477754,-308.164032,0.049050,0.000000
39.060001,12.935471,-308.297485,-0.003324,0.001920,0.048773,57.539848,2.931220,0.487727,-308.297485,0.049735,0.000000
39.470001,12.920952,-308.297485,-0.003290,0.001948,0.049475,57.475266,2.927930,0.494752,-308.297485,0.050412,0.000000
39.880001,13.272095,-308.297485,-0.003277,0.001975,0.050160,59.037228,3.007500,0.501603,-308.297485,0.051097,0.000000
40.290001,13.106018,-308.386444,-0.003247,0.001996,0.050689,58.298481,2.969866,0.506894,-308.386444,0.051782,0.000000
40.700001,13.282150,-308.386444,-0.003203,0.002020,0.051296,59.081955,3.009778,0.512963,-308.386444,0.052467,0.000000
41.110001,13.658623,-308.386444,-0.003199,0.002050,0.052068,60.756588,3.095088,0.520682,-308.386444,0.053152,0.000000
41.520000,13.937897,-308.430908,-0.003169,0.002078,0.052779,61.998859,3.158372,0.527794,-308.430908,0.053829,0.000000
41.930000,14.355698,-308.430908,-0.003139,0.002110,0.053586,63.857334,3.253048,0.535858,-308.430908,0.054514,0.000000
42.340000,14.171753,-308.564362,-0.003122,0.002132,0.054141,63.039104,3.211365,0.541408,-308.564362,0.055199,0.000000
42.750004,14.453636,-308.430908,-0.003078,0.002159,0.054843,64.292984,3.275241,0.548433,-308.430908,0.055884,0.000000
43.160004,14.613380,-308.564362,-0.003074,0.002188,0.055581,65.003563,3.311439,0.555806,-308.564362,0.056569,0.000000
43.570004,14.722488,-308.519867,-0.003018,0.002213,0.056222,65.488899,3.336164,0.562222,-308.519867,0.057246,0.000000
43.980003,14.754509,-308.653320,-0.003005,0.002238,0.056838,65.631332,3.343420,0.568380,-308.653320,0.057931,0.000000
44.390003,15.300407,-308.653320,-0.002984,0.002265,0.057540,68.059608,3.467122,0.575404,-308.653320,0.058616,0.000000
44.800003,15.714119,-308.608826,-0.002953,0.002297,0.058356,69.899895,3.560870,0.583557,-308.608826,0.059301,0.000000
45.210003,15.555115,-308.697815,-0.002932,0.002323,0.058997,69.192604,3.524839,0.589972,-308.697815,0.059986,0.000000
45.620003,15.764755,-308.697815,-0.002893,0.002351,0.059726,70.125137,3.572345,0.597258,-308.697815,0.060671,0.000000
46.030003,15.749489,-308.742279,-0.002867,0.002376,0.060359,70.057228,3.568885,0.603590,-308.742279,0.061348,0.000000
46.440002,16.129311,-308.831238,-0.002846,0.002404,0.061070,71.746758,3.654954,0.610698,-308.831238,0.062033,0.000000
46.850002,16.243629,-308.786774,-0.002794,0.002432,0.061781,72.255272,3.680859,0.617810,-308.786774,0.062718,0.000000
47.260002,16.264481,-308.875732,-0.002768,0.002459,0.062449,72.348022,3.685584,0.624491,-308.875732,0.063403,0.000000
47.670002,16.475616,-308.875732,-0.002759,0.002485,0.063117,73.287201,3.733428,0.631167,-308.875732,0.064088,0.000000
48.080002,16.334862,-308.875732,-0.002734,0.002506,0.063646,72.661095,3.701533,0.636458,-308.875732,0.064764,0.000000
48.490002,16.769051,-308.875732,-0.002699,0.002535,0.064400,74.592461,3.799921,0.644002,-308.875732,0.065449,0.000000
48.900002,16.897514,-308.920197,-0.002665,0.002564,0.065120,75.163895,3.829032,0.651201,-308.920197,0.066135,0.000000
49.310001,16.964912,-309.009155,-0.002647,0.002590,0.065779,75.463699,3.844304,0.657790,-309.009155,0.066820,0.000000
49.720001,17.217758,-309.009155,-0.002604,0.002619,0.066525,76.588417,3.901600,0.665250,-309.009155,0.067505,0.000000
50.130001,17.205841,-309.053650,-0.002591,0.002644,0.067149,76.535400,3.898899,0.671491,-309.053650,0.068181,0.000000
50.540001,17.462036,-309.053650,-0.002535,0.002675,0.067956,77.675018,3.956954,0.679557,-309.053650,0.068866,0.000000
50.950001,17.320534,-309.142609,-0.002514,0.002702,0.068632,77.045586,3.924889,0.686321,-309.142609,0.069551,0.000000
51.360001,16.886719,-309.142609,-0.002488,0.002720,0.069101,75.115875,3.826585,0.691006,-309.142609,0.070236,0.000000
51.770004,17.218872,-309.142609,-0.002432,0.002749,0.069820,76.593369,3.901852,0.698201,-309.142609,0.070922,0.000000
52.180004,17.498894,-309.187103,-0.002406,0.002782,0.070662,77.838966,3.965306,0.706615,-309.187103,0.071598,0.000000
52.590004,17.382347,-309.142609,-0.002367,0.002810,0.071373,77.320541,3.938896,0.713727,-309.142609,0.072283,0.000000
53.000004,16.893417,-309.231567,-0.002333,0.002834,0.071980,75.145676,3.828103,0.719798,-309.231567,0.072968,0.000000
53.410004,16.796600,-309.231567,-0.002302,0.002859,0.072630,74.715012,3.806164,0.726301,-309.231567,0.073653,0.000000
53.820004,16.354225,-309.231567,-0.002285,0.002879,0.073124,72.747231,3.705920,0.731244,-309.231567,0.074339,0.000000
54.230003,17.125778,-309.276062,-0.002233,0.002916,0.074061,76.179268,3.880757,0.740611,-309.276062,0.075015,0.000000
54.640003,16.658081,-309.365021,-0.002207,0.002938,0.074625,74.098846,3.774775,0.746247,-309.365021,0.075700,0.000000
55.050003,16.728462,-309.365021,-0.002177,0.002966,0.075345,74.411919,3.790724,0.753446,-309.365021,0.076385,0.000000
55.460003,16.789154,-309.365021,-0.002147,0.002993,0.076012,74.681885,3.804477,0.760122,-309.365021,0.077070,0.000000
55.870003,17.015556,-309.453979,-0.002113,0.003019,0.076689,75.688972,3.855780,0.766886,-309.453979,0.077756,0.000000
56.280003,17.361122,-309.453979,-0.002070,0.003050,0.077461,77.226128,3.934087,0.774607,-309.453979,0.078432,0.000000
56.690002,16.920601,-309.498444,-0.002044,0.003074,0.078068,75.266594,3.834263,0.780678,-309.498444,0.079117,0.000000
57.100002,17.423309,-309.587433,-0.002022,0.003102,0.078796,77.502754,3.948178,0.787960,-309.587433,0.079802,0.000000
57.510002,17.464638,-309.498444,-0.002013,0.003126,0.079412,77.686592,3.957544,0.794118,-309.498444,0.080487,0.000000
57.920002,17.823235,-309.587433,-0.001957,0.003156,0.080166,79.281708,4.038803,0.801662,-309.587433,0.081172,0.000000
58.330002,18.218697,-309.631897,-0.001940,0.003182,0.080817,81.040810,4.128416,0.808168,-309.631897,0.081849,0.000000
58.740002,18.236565,-309.587433,-0.001906,0.003207,0.081467,81.120293,4.132465,0.814670,-309.587433,0.082534,0.000000
59.150002,18.094696,-309.631897,-0.001880,0.003233,0.082126,80.489227,4.100317,0.821264,-309.631897,0.083219,0.000000
59.560001,18.493134,-309.631897,-0.001841,0.003261,0.082838,82.261566,4.190604,0.828375,-309.631897,0.083904,0.000000
59.970001,18.606331,-309.676392,-0.001828,0.003284,0.083401,82.765091,4.216255,0.834011,-309.676392,0.084589,0.000000
60.380001,19.186119,-309.720856,-0.001794,0.003319,0.084294,85.344124,4.347637,0.842943,-309.720856,0.085266,0.000000
60.790005,19.122444,-309.720856,-0.001763,0.003346,0.084997,85.060883,4.333208,0.849968,-309.720856,0.085951,0.000000
61.200005,19.468750,-309.854309,-0.001738,0.003372,0.085656,86.601326,4.411682,0.856558,-309.854309,0.086636,0.000000
61.610004,19.314217,-309.765350,-0.001703,0.003394,0.086211,85.913925,4.376664,0.862110,-309.765350,0.087321,0.000000
62.020004,19.467255,-309.854309,-0.001669,0.003418,0.086818,86.594673,4.411343,0.868181,-309.854309,0.088006,0.000000
62.430004,19.539497,-309.898773,-0.001656,0.003440,0.087364,86.916023,4.427713,0.873643,-309.898773,0.088683,0.000000
62.840004,20.337494,-309.898773,-0.001617,0.003477,0.088318,90.465691,4.608542,0.883181,-309.898773,0.089368,0.000000
63.250004,20.845039,-309.987762,-0.001595,0.003508,0.089108,92.723366,4.723553,0.891076,-309.987762,0.090053,0.000000
63.660004,20.515114,-309.898773,-0.001548,0.003530,0.089654,91.255783,4.648791,0.896538,-309.898773,0.090738,0.000000
64.070000,20.869987,-309.943268,-0.001526,0.003559,0.090400,92.834343,4.729207,0.903998,-309.943268,0.091423,0.000000
64.480003,21.158203,-310.032227,-0.001492,0.003588,0.091128,94.116386,4.794518,0.911280,-310.032227,0.092099,0.000000
64.889999,21.119476,-310.032227,-0.001466,0.003611,0.091709,93.944122,4.785742,0.917090,-310.032227,0.092785,0.000000
65.300003,21.225601,-310.032227,-0.001444,0.003634,0.092316,94.416191,4.809790,0.923160,-310.032227,0.093470,0.000000
65.710007,22.015030,-310.076721,-0.001423,0.003664,0.093062,97.927742,4.988677,0.930620,-310.076721,0.094155,0.000000
66.120003,22.734825,-310.165680,-0.001393,0.003697,0.093903,101.129555,5.151785,0.939031,-310.165680,0.094840,0.000000
66.530006,22.554970,-310.165680,-0.001358,0.003721,0.094519,100.329514,5.111029,0.945189,-310.165680,0.095516,0.000000
66.940002,22.942612,-310.165680,-0.001328,0.003750,0.095247,102.053833,5.198870,0.952474,-310.165680,0.096201,0.000000
67.350006,23.133636,-310.210144,-0.001293,0.003774,0.095872,102.903557,5.242157,0.958720,-310.210144,0.096886,0.000000
67.760002,23.104591,-310.210144,-0.001285,0.003798,0.096479,102.774353,5.235576,0.964787,-310.210144,0.097571,0.000000
68.170006,24.247772,-310.254639,-0.001242,0.003830,0.097294,107.859474,5.494624,0.972939,-310.254639,0.098257,0.000000
68.580002,24.562431,-310.343597,-0.001216,0.003857,0.097979,109.259148,5.565927,0.979790,-310.343597,0.098933,0.000000
68.990005,25.080399,-310.388062,-0.001186,0.003883,0.098638,111.563187,5.683300,0.986383,-310.388062,0.099618,0.000000
69.400002,25.157112,-310.388062,-0.001173,0.003906,0.099219,111.904427,5.700683,0.992193,-310.388062,0.100303,0.000000
69.810005,26.091019,-310.299103,-0.001147,0.003936,0.099965,116.058647,5.912309,0.999649,-310.299103,0.100988,0.000000
70.220001,26.688301,-310.388062,-0.001117,0.003963,0.100650,118.715492,6.047656,1.006504,-310.388062,0.101673,0.000000
70.630005,27.243515,-310.388062,-0.001082,0.003989,0.101318,121.185204,6.173469,1.013180,-310.388062,0.102350,0.000000
71.040001,28.121567,-310.432556,-0.001048,0.004019,0.102072,125.090973,6.372438,1.020724,-310.432556,0.103035,0.000000
71.450005,28.533783,-310.477051,-0.001035,0.004042,0.102662,126.924606,6.465848,1.026621,-310.477051,0.103720,0.000000
71.860001,29.743622,-310.477051,-0.001018,0.004075,0.103495,132.306244,6.740001,1.034947,-310.477051,0.104405,0.000000
72.270004,30.298080,-310.521515,-0.000974,0.004100,0.104145,134.772598,6.865643,1.041450,-310.521515,0.105090,0.000000
72.680000,30.461929,-310.521515,-0.000961,0.004119,0.104614,135.501434,6.902772,1.046136,-310.521515,0.105767,0.000000
73.090004,31.776772,-310.610474,-0.000936,0.004149,0.105377,141.350143,7.200719,1.053766,-310.610474,0.106452,0.000000
73.500000,33.049171,-310.610474,-0.000936,0.004180,0.106174,147.010056,7.489049,1.061744,-310.610474,0.107137,0.000000
73.910004,34.280235,-310.610474,-0.000897,0.004208,0.106894,152.486099,7.768012,1.068943,-310.610474,0.107822,0.000000
74.320007,34.761337,-310.699432,-0.000888,0.004231,0.107467,154.626144,7.877032,1.074666,-310.699432,0.108507,0.000000
74.730003,35.545555,-310.654968,-0.000867,0.004256,0.108100,158.114532,8.054738,1.080998,-310.654968,0.109184,0.000000
75.140007,35.944366,-310.699432,-0.000854,0.004275,0.108594,159.888535,8.145110,1.085941,-310.699432,0.109869,0.000000
75.550003,38.540550,-310.654968,-0.000815,0.004313,0.109557,171.436935,8.733414,1.095566,-310.654968,0.110554,0.000000
75.960007,39.232414,-310.654968,-0.000815,0.004336,0.110146,174.514496,8.890193,1.101463,-310.654968,0.111239,0.000000
76.370003,40.503693,-310.788391,-0.000785,0.004363,0.110831,180.169418,9.178267,1.108314,-310.788391,0.111924,0.000000
76.780006,41.617088,-310.743927,-0.000763,0.004388,0.111465,185.122055,9.430567,1.114646,-310.743927,0.112600,0.000000
77.190002,43.222015,-310.832886,-0.000755,0.004417,0.112202,192.261124,9.794249,1.122015,-310.832886,0.113285,0.000000
77.600006,44.931580,-310.788391,-0.000733,0.004447,0.112965,199.865646,10.181641,1.129649,-310.788391,0.113971,0.000000
78.010002,45.805908,-310.877380,-0.000716,0.004472,0.113598,203.754852,10.379767,1.135978,-310.877380,0.114656,0.000000
78.420006,47.515472,-310.921844,-0.000707,0.004500,0.114309,211.359375,10.767159,1.143089,-310.921844,0.115341,0.000000
78.830002,48.987831,-310.921844,-0.000681,0.004525,0.114942,217.908752,11.100801,1.149421,-310.921844,0.116017,0.000000
79.240005,50.572647,-310.966339,-0.000673,0.004554,0.115679,224.958374,11.459926,1.156791,-310.966339,0.116703,0.000000
79.650002,52.224121,-310.966339,-0.000660,0.004580,0.116330,232.304489,11.834154,1.163297,-310.966339,0.117388,0.000000
80.060005,53.808189,-311.055298,-0.000642,0.004606,0.116997,239.350784,12.193110,1.169973,-311.055298,0.118073,0.000000
80.470001,55.133469,-311.010803,-0.000638,0.004628,0.117561,245.245911,12.493423,1.175609,-311.010803,0.118758,0.000000
80.880005,57.192688,-311.055298,-0.000604,0.004659,0.118342,254.405777,12.960049,1.183417,-311.055298,0.119434,0.000000
81.290001,58.705261,-311.099762,-0.000599,0.004681,0.118905,261.134033,13.302802,1.189053,-311.099762,0.120120,0.000000
81.700005,61.365494,-311.055298,-0.000582,0.004717,0.119807,272.967346,13.905620,1.198073,-311.055298,0.120805,0.000000
82.110001,62.964828,-311.144257,-0.000586,0.004742,0.120440,280.081543,14.268034,1.204405,-311.144257,0.121490,0.000000
82.520004,64.881805,-311.099762,-0.000552,0.004770,0.121151,288.608673,14.702427,1.211513,-311.099762,0.122175,0.000000
82.930000,65.851456,-311.277710,-0.000535,0.004775,0.121273,292.921906,14.922153,1.212728,-311.277710,0.021284,0.000000
83.340004,64.908249,-311.233215,-0.000530,0.004774,0.121255,288.726318,14.708420,1.212554,-311.233215,294.500458,0.000000
83.750008,66.434601,-311.277710,-0.000509,0.004751,0.120683,295.515869,15.054296,1.206831,-311.277710,294.500458,0.000000
84.160004,65.794113,-311.366669,-0.000513,0.004751,0.120683,292.666840,14.909159,1.206831,-311.366669,294.500458,0.000000
84.570007,65.330887,-311.322174,-0.000517,0.004770,0.121151,290.606293,14.804191,1.211513,-311.322174,294.500458,0.000000
84.980003,65.120499,-311.366669,-0.000513,0.004791,0.121698,289.670441,14.756516,1.216978,-311.366669,294.500458,0.000000
85.390007,65.220291,-311.366669,-0.000522,0.004797,0.121845,290.114349,14.779129,1.218450,-311.366669,294.500458,0.000000
85.800003,65.112671,-311.366669,-0.000504,0.004799,0.121889,289.635620,14.754742,1.218886,-311.366669,294.500458,0.000000
86.210007,65.191986,-311.455627,-0.000504,0.004802,0.121975,289.988434,14.772716,1.219752,-311.455627,294.500458,0.000000
86.620003,65.145065,-311.455627,-0.000513,0.004805,0.122036,289.779724,14.762082,1.220358,-311.455627,294.500458,0.000000
87.030006,65.071716,-311.500092,-0.000513,0.004807,0.122088,289.453461,14.745461,1.220880,-311.500092,294.500458,0.000000
87.440002,65.176346,-311.500092,-0.000500,0.004810,0.122183,289.918854,14.769171,1.221834,-311.500092,294.500458,0.000000
87.850006,65.192734,-311.589050,-0.000509,0.004810,0.122183,289.991760,14.772885,1.221834,-311.589050,294.500458,0.000000
88.260002,65.069855,-311.589050,-0.000500,0.004811,0.122192,289.445160,14.745040,1.221921,-311.589050,294.500458,0.000000
88.670006,65.074326,-311.589050,-0.000496,0.004813,0.122244,289.465057,14.746053,1.222440,-311.589050,294.500458,0.000000
89.080002,65.034470,-311.633545,-0.000483,0.004814,0.122279,289.287781,14.737021,1.222788,-311.633545,294.500458,0.000000
89.490005,65.051605,-311.633545,-0.000513,0.004815,0.122314,289.363983,14.740905,1.223136,-311.633545,294.500458,0.000000
89.900002,65.036713,-311.678009,-0.000504,0.004816,0.122322,289.297760,14.737530,1.223223,-311.678009,294.500458,0.000000
90.310005,64.987183,-311.678009,-0.000509,0.004817,0.122339,289.077423,14.726306,1.223393,-311.678009,294.500458,0.000000
90.720001,64.918289,-311.722504,-0.000500,0.004817,0.122339,288.770966,14.710694,1.223393,-311.722504,294.500458,0.000000
91.130005,65.029633,-311.766998,-0.000487,0.004826,0.122591,289.266266,14.735926,1.225910,-311.766998,294.500458,0.000000
91.540001,65.746460,-311.766998,-0.000487,0.004826,0.122582,292.454865,14.898361,1.225823,-311.766998,294.500458,0.000000
91.950005,65.651871,-311.900421,-0.000483,0.004826,0.122591,292.034119,14.876926,1.225910,-311.900421,294.500458,0.000000
92.360001,65.584473,-311.855957,-0.000492,0.004826,0.122591,291.734314,14.861653,1.225910,-311.855957,294.500458,0.000000
92.770004,65.546860,-311.855957,-0.000492,0.004826,0.122591,291.566986,14.853130,1.225910,-311.855957,294.500458,0.000000
93.180008,65.467911,-311.944916,-0.000492,0.004826,0.122591,291.215820,14.835241,1.225910,-311.944916,294.500458,0.000000
93.590004,65.387115,-311.900421,-0.000483,0.004826,0.122591,290.856415,14.816933,1.225910,-311.900421,294.500458,0.000000
94.000008,65.317108,-311.900421,-0.000479,0.004826,0.122591,290.545013,14.801068,1.225910,-311.900421,294.500458,0.000000
94.410004,65.263489,-311.944916,-0.000492,0.004826,0.122591,290.306488,14.788918,1.225910,-311.944916,294.500458,0.000000
94.820007,65.203156,-311.989380,-0.000479,0.004826,0.122591,290.038116,14.775247,1.225910,-311.989380,294.500458,0.000000
95.230003,65.134644,-312.122833,-0.000479,0.004826,0.122591,289.733368,14.759721,1.225910,-312.122833,294.500458,0.000000
95.640007,65.057190,-312.078339,-0.000474,0.004826,0.122591,289.388824,14.742170,1.225910,-312.078339,294.500458,0.000000
96.050003,65.015854,-312.167328,-0.000487,0.004826,0.122591,289.204956,14.732802,1.225910,-312.167328,294.500458,0.000000
96.460007,64.967453,-312.167328,-0.000483,0.004826,0.122591,288.989655,14.721835,1.225910,-312.167328,294.500458,0.000000
96.870003,64.898193,-312.122833,-0.000496,0.004826,0.122591,288.681580,14.706141,1.225910,-312.122833,294.500458,0.000000
97.280006,64.842697,-312.167328,-0.000474,0.004827,0.122600,288.434723,14.693565,1.225997,-312.167328,294.500458,0.000000
97.690002,64.798767,-312.211792,-0.000487,0.004827,0.122600,288.239319,14.683610,1.225997,-312.211792,294.500458,0.000000
98.100006,64.747375,-312.256287,-0.000483,0.004827,0.122600,288.010712,14.671965,1.225997,-312.256287,294.500458,0.000000
98.510002,64.706039,-312.300751,-0.000496,0.004827,0.122600,287.826843,14.662599,1.225997,-312.300751,294.500458,0.000000
98.920006,64.674759,-312.345245,-0.000483,0.004827,0.122600,287.687683,14.655510,1.225997,-312.345245,294.500458,0.000000
99.330002,66.146378,-312.345245,-0.000487,0.004836,0.122825,294.233795,14.988984,1.228253,-312.345245,294.500458,0.000000
99.740005,66.095367,-312.300751,-0.000479,0.004835,0.122817,294.006866,14.977425,1.228166,-312.300751,294.500458,0.000000
100.150002,66.051056,-312.434204,-0.000479,0.004835,0.122817,293.809784,14.967383,1.228166,-312.434204,294.500458,0.000000
100.560005,65.986267,-312.389709,-0.000470,0.004835,0.122817,293.521576,14.952702,1.228166,-312.389709,294.500458,0.000000
100.970001,65.930038,-312.434204,-0.000466,0.004835,0.122817,293.271454,14.939960,1.228166,-312.434204,294.500458,0.000000
101.380005,65.883484,-312.523163,-0.000470,0.004835,0.122817,293.064362,14.929411,1.228166,-312.523163,294.500458,0.000000
101.790009,65.814224,-312.523163,-0.000479,0.004835,0.122817,292.756287,14.913716,1.228166,-312.523163,294.500458,0.000000
102.200005,65.845505,-312.523163,-0.000470,0.004835,0.122817,292.895447,14.920805,1.228166,-312.523163,294.500458,0.000000
102.610008,65.781830,-312.523163,-0.000479,0.004835,0.122817,292.612183,14.906376,1.228166,-312.523163,294.500458,0.000000
103.020004,65.749435,-312.612122,-0.000479,0.004835,0.122817,292.468109,14.899035,1.228166,-312.612122,294.500458,0.000000
103.430008,65.674210,-312.612122,-0.000479,0.004835,0.122817,292.133484,14.881989,1.228166,-312.612122,294.500458,0.000000
103.840004,65.629150,-312.612122,-0.000474,0.004835,0.122817,291.933044,14.871778,1.228166,-312.612122,294.500458,0.000000
104.250008,65.588562,-312.701080,-0.000479,0.004835,0.122817,291.752502,14.862580,1.228166,-312.701080,294.500458,0.000000
104.660004,65.566589,-312.701080,-0.000474,0.004835,0.122817,291.654755,14.857601,1.228166,-312.701080,294.500458,0.000000
105.070007,65.533829,-312.745575,-0.000474,0.004835,0.122817,291.509033,14.850178,1.228166,-312.745575,294.500458,0.000000
105.480003,65.509628,-312.745575,-0.000474,0.004835,0.122817,291.401367,14.844694,1.228166,-312.745575,294.500458,0.000000
105.890007,65.459732,-312.745575,-0.000466,0.004835,0.122817,291.179443,14.833387,1.228166,-312.745575,294.500458,0.000000
106.300003,65.421371,-312.790039,-0.000479,0.004835,0.122817,291.008789,14.824695,1.228166,-312.790039,294.500458,0.000000
106.710007,65.366638,-312.834534,-0.000474,0.004835,0.122817,290.765320,14.812292,1.228166,-312.834534,294.500458,0.000000
107.120003,65.333862,-312.878998,-0.000479,0.004835,0.122817,290.619537,14.804865,1.228166,-312.878998,294.500458,0.000000
107.530006,65.317108,-312.834534,-0.000479,0.004835,0.122817,290.545013,14.801068,1.228166,-312.834534,294.500458,0.000000
107.940002,65.279129,-312.878998,-0.000474,0.004836,0.122825,290.376068,14.792462,1.228253,-312.878998,294.500458,0.000000
108.350006,65.263489,-312.923492,-0.000470,0.004836,0.122825,290.306488,14.788918,1.228253,-312.923492,294.500458,0.000000
108.760002,65.215073,-312.923492,-0.000466,0.004836,0.122825,290.091125,14.777947,1.228253,-312.923492,294.500458,0.000000
109.170006,65.194229,-312.967957,-0.000470,0.004836,0.122825,289.998413,14.773223,1.228253,-312.967957,294.500458,0.000000
109.580002,65.162949,-312.967957,-0.000474,0.004836,0.122825,289.859283,14.766135,1.228253,-312.967957,294.500458,0.000000
109.990005,65.110809,-313.056946,-0.000461,0.004836,0.122825,289.627350,14.754320,1.228253,-313.056946,294.500458,0.000000
110.400002,65.098145,-312.967957,-0.000470,0.004836,0.122825,289.571014,14.751450,1.228253,-312.967957,294.500458,0.000000
110.810005,65.070969,-313.012451,-0.000466,0.004836,0.122825,289.450134,14.745292,1.228253,-313.012451,294.500458,0.000000
111.220009,65.040802,-313.145905,-0.000483,0.004836,0.122825,289.315948,14.738456,1.228253,-313.145905,294.500458,0.000000
111.630005,65.030746,-313.101410,-0.000470,0.004836,0.122825,289.271210,14.736178,1.228253,-313.101410,294.500458,0.000000
112.040009,64.997238,-313.190369,-0.000479,0.004836,0.122825,289.122162,14.728585,1.228253,-313.190369,294.500458,0.000000
112.450005,64.980103,-313.145905,-0.000474,0.004836,0.122825,289.045929,14.724701,1.228253,-313.145905,294.500458,0.000000
112.860008,64.948837,-313.234863,-0.000466,0.004836,0.122825,288.906860,14.717617,1.228253,-313.234863,294.500458,0.000000
113.270004,64.929092,-313.279327,-0.000470,0.004836,0.122825,288.819031,14.713142,1.228253,-313.279327,294.500458,0.000000
113.680008,64.908615,-313.190369,-0.000457,0.004836,0.122825,288.727936,14.708503,1.228253,-313.190369,294.500458,0.000000
114.090004,64.866913,-313.368286,-0.000466,0.004836,0.122825,288.542450,14.699053,1.228253,-313.368286,294.500458,0.000000
114.500008,64.844193,-313.323822,-0.000474,0.004836,0.122825,288.441376,14.693904,1.228253,-313.323822,294.500458,0.000000
114.910004,64.814774,-313.323822,-0.000474,0.004836,0.122825,288.310516,14.687238,1.228253,-313.323822,294.500458,0.000000
115.320007,64.775681,-313.368286,-0.000479,0.004836,0.122825,288.136627,14.678379,1.228253,-313.368286,294.500458,0.000000
115.730003,64.777542,-313.412781,-0.000466,0.004836,0.122825,288.144897,14.678801,1.228253,-313.412781,294.500458,0.000000
116.140007,64.748489,-313.457275,-0.000470,0.004836,0.122825,288.015656,14.672217,1.228253,-313.457275,294.500458,0.000000
116.550003,64.739182,-313.412781,-0.000466,0.004836,0.122825,287.974274,14.670108,1.228253,-313.412781,294.500458,0.000000
116.960007,64.711258,-313.501740,-0.000466,0.004836,0.122825,287.850037,14.663780,1.228253,-313.501740,294.500458,0.000000
117.370003,64.691895,-313.546234,-0.000466,0.004836,0.122825,287.763916,14.659393,1.228253,-313.546234,294.500458,0.000000
117.780006,64.669556,-313.501740,-0.000457,0.004836,0.122825,287.664551,14.654330,1.228253,-313.501740,294.500458,0.000000
118.190002,64.642746,-313.590698,-0.000461,0.004836,0.122825,287.545288,14.648255,1.228253,-313.590698,294.500458,0.000000
118.600006,64.615189,-313.590698,-0.000466,0.004836,0.122834,287.422699,14.642012,1.228337,-313.590698,294.500458,0.000000
119.010002,66.389542,-313.635193,-0.000461,0.004847,0.123120,295.315430,15.044086,1.231202,-313.635193,294.500458,0.000000
119.420006,66.347092,-313.590698,-0.000479,0.004847,0.123120,295.126617,15.034466,1.231202,-313.590698,294.500458,0.000000
119.830009,66.322510,-313.635193,-0.000461,0.004847,0.123120,295.017242,15.028895,1.231202,-313.635193,294.500458,0.000000
120.240005,66.290482,-313.679657,-0.000453,0.004847,0.123120,294.874786,15.021638,1.231202,-313.679657,294.500458,0.000000
120.650009,66.279694,-313.679657,-0.000453,0.004847,0.123120,294.826813,15.019193,1.231202,-313.679657,294.500458,0.000000
121.060005,66.254745,-313.768616,-0.000461,0.004847,0.123120,294.715820,15.013540,1.231202,-313.768616,294.500458,0.000000
121.470009,66.232025,-313.768616,-0.000457,0.004847,0.123120,294.614777,15.008391,1.231202,-313.768616,294.500458,0.000000
121.880005,66.218994,-313.813110,-0.000461,0.004847,0.123120,294.556793,15.005439,1.231202,-313.813110,294.500458,0.000000
122.290009,66.191071,-313.857605,-0.000461,0.004847,0.123120,294.432587,14.999110,1.231202,-313.857605,294.500458,0.000000
122.700005,66.163132,-313.813110,-0.000453,0.004847,0.123120,294.308319,14.992780,1.231202,-313.813110,294.500458,0.000000
123.110008,66.138931,-313.902069,-0.000457,0.004847,0.123120,294.200653,14.987296,1.231202,-313.902069,294.500458,0.000000
123.520004,66.131851,-313.857605,-0.000461,0.004847,0.123120,294.169159,14.985692,1.231202,-313.857605,294.500458,0.000000
123.930008,66.102814,-313.946564,-0.000466,0.004847,0.123120,294.040009,14.979112,1.231202,-313.946564,294.500458,0.000000
124.340004,66.083450,-313.902069,-0.000453,0.004847,0.123120,293.953857,14.974725,1.231202,-313.902069,294.500458,0.000000
124.750008,66.069305,-313.902069,-0.000457,0.004847,0.123120,293.890961,14.971519,1.231202,-313.902069,294.500458,0.000000
125.160004,66.035782,-314.035522,-0.000461,0.004847,0.123120,293.741821,14.963922,1.231202,-314.035522,294.500458,0.000000
125.570007,66.039886,-313.946564,-0.000461,0.004847,0.123120,293.760101,14.964852,1.231202,-313.946564,294.500458,0.000000
125.980003,66.008972,-314.079987,-0.000466,0.004847,0.123120,293.622559,14.957847,1.231202,-314.079987,294.500458,0.000000
126.390007,65.984406,-314.035522,-0.000466,0.004847,0.123120,293.513306,14.952280,1.231202,-314.035522,294.500458,0.000000
126.800003,65.970245,-313.991028,-0.000453,0.004847,0.123120,293.450317,14.949072,1.231202,-313.991028,294.500458,0.000000
127.210007,65.921463,-314.079987,-0.000466,0.004847,0.123120,293.233307,14.938017,1.231202,-314.079987,294.500458,0.000000
127.620003,65.938965,-314.035522,-0.000461,0.004847,0.123120,293.311157,14.941983,1.231202,-314.035522,294.500458,0.000000
128.029999,65.930038,-314.213440,-0.000453,0.004847,0.123120,293.271454,14.939960,1.231202,-314.213440,294.500458,0.000000
128.440002,65.873062,-314.168945,-0.000461,0.004847,0.123120,293.018005,14.927049,1.231202,-314.168945,294.500458,0.000000
128.850006,65.871201,-314.168945,-0.000461,0.004847,0.123120,293.009735,14.926628,1.231202,-314.168945,294.500458,0.000000
129.260010,65.852951,-314.257904,-0.000453,0.004847,0.123120,292.928558,14.922492,1.231202,-314.257904,294.500458,0.000000
129.670013,65.877899,-314.213440,-0.000461,0.004847,0.123120,293.039520,14.928145,1.231202,-314.213440,294.500458,0.000000
130.080002,65.851456,-314.257904,-0.000461,0.004847,0.123120,292.921906,14.922153,1.231202,-314.257904,294.500458,0.000000
130.490005,65.831360,-314.257904,-0.000466,0.004847,0.123120,292.832520,14.917599,1.231202,-314.257904,294.500458,0.000000
130.900009,65.832840,-314.346893,-0.000466,0.004847,0.123120,292.839111,14.917934,1.231202,-314.346893,294.500458,0.000000
131.310013,65.829498,-314.391357,-0.000466,0.004847,0.123120,292.824219,14.917178,1.231202,-314.391357,294.500458,0.000000
131.720001,65.788162,-314.391357,-0.000461,0.004847,0.123120,292.640350,14.907811,1.231202,-314.391357,294.500458,0.000000
132.130005,65.772888,-314.524811,-0.000448,0.004847,0.123120,292.572418,14.904349,1.231202,-314.524811,294.500458,0.000000
132.540009,65.763947,-314.435852,-0.000461,0.004847,0.123120,292.532654,14.902323,1.231202,-314.435852,294.500458,0.000000
132.950012,65.759491,-314.524811,-0.000453,0.004847,0.123120,292.512817,14.901314,1.231202,-314.524811,294.500458,0.000000
133.360001,65.735275,-314.613770,-0.000457,0.004847,0.123120,292.405121,14.895826,1.231202,-314.613770,294.500458,0.000000
133.770004,65.701767,-314.480316,-0.000453,0.004847,0.123120,292.256042,14.888233,1.231202,-314.480316,294.500458,0.000000
134.180008,65.669373,-314.569275,-0.000479,0.004847,0.123120,292.111969,14.880893,1.231202,-314.569275,294.500458,0.000000
134.590012,65.659683,-314.613770,-0.000466,0.004847,0.123120,292.068848,14.878696,1.231202,-314.613770,294.500458,0.000000
135.000000,65.647400,-314.613770,-0.000457,0.004847,0.123120,292.014221,14.875913,1.231202,-314.613770,294.500458,0.000000
135.410004,65.630646,-314.702728,-0.000457,0.004847,0.123120,291.939697,14.872117,1.231202,-314.702728,294.500458,0.000000
135.820007,65.619095,-314.658234,-0.000461,0.004847,0.123120,291.888306,14.869499,1.231202,-314.658234,294.500458,0.000000
136.230011,65.603836,-314.658234,-0.000457,0.004847,0.123120,291.820435,14.866042,1.231202,-314.658234,294.500458,0.000000
136.639999,65.591553,-314.702728,-0.000470,0.004847,0.123120,291.765808,14.863258,1.231202,-314.702728,294.500458,0.000000
137.050003,65.590424,-314.747223,-0.000453,0.004847,0.123120,291.760773,14.863003,1.231202,-314.747223,294.500458,0.000000
137.460007,65.566589,-314.791687,-0.000448,0.004847,0.123120,291.654755,14.857601,1.231202,-314.791687,294.500458,0.000000
137.870010,65.561386,-314.791687,-0.000457,0.004847,0.123120,291.631622,14.856422,1.231202,-314.791687,294.500458,0.000000
138.280014,65.565857,-314.836182,-0.000457,0.004847,0.123120,291.651489,14.857435,1.231202,-314.836182,294.500458,0.000000
138.690002,65.542023,-314.791687,-0.000466,0.004847,0.123120,291.545471,14.852035,1.231202,-314.791687,294.500458,0.000000
139.100006,65.524887,-314.836182,-0.000448,0.004847,0.123120,291.469269,14.848151,1.231202,-314.836182,294.500458,0.000000
139.510010,65.509995,-314.880646,-0.000448,0.004847,0.123120,291.403015,14.844777,1.231202,-314.880646,294.500458,0.000000
139.920013,65.490631,-314.925140,-0.000457,0.004847,0.123120,291.316864,14.840389,1.231202,-314.925140,294.500458,0.000000
140.330002,65.496964,-314.969604,-0.000457,0.004847,0.123120,291.345032,14.841825,1.231202,-314.969604,294.500458,0.000000
140.740005,65.461960,-314.969604,-0.000453,0.004847,0.123120,291.189331,14.833892,1.231202,-314.969604,294.500458,0.000000
141.150009,65.457123,-314.969604,-0.000453,0.004847,0.123120,291.167816,14.832796,1.231202,-314.969604,294.500458,0.000000
141.560013,65.440735,-314.969604,-0.000470,0.004847,0.123120,291.094940,14.829082,1.231202,-314.969604,294.500458,0.000000
141.970001,65.428070,-315.014099,-0.000457,0.004847,0.123120,291.038605,14.826213,1.231202,-315.014099,294.500458,0.000000
142.380005,65.413925,-315.103058,-0.000444,0.004847,0.123120,290.975677,14.823008,1.231202,-315.103058,294.500458,0.000000
142.790009,65.391953,-315.103058,-0.000461,0.004848,0.123129,290.877930,14.818028,1.231289,-315.103058,294.500458,0.000000
143.200012,65.378555,-315.103058,-0.000457,0.004848,0.123129,290.818329,14.814992,1.231289,-315.103058,294.500458,0.000000
143.610001,65.375198,-315.147552,-0.000466,0.004847,0.123111,290.803406,14.814232,1.231115,-315.147552,0.123007,0.000000
144.020004,65.366257,-315.058563,-0.000448,0.004828,0.122643,290.763641,14.812205,1.226429,-315.058563,0.122322,0.000000
144.430008,65.264969,-315.192017,-0.000444,0.004805,0.122045,290.313080,14.789253,1.220445,-315.192017,0.121637,0.000000
144.840012,65.224014,-315.192017,-0.000448,0.004786,0.121576,290.130920,14.779973,1.215763,-315.192017,0.120961,0.000000
145.250000,65.164429,-315.236511,-0.000461,0.004759,0.120891,289.865845,14.766471,1.208912,-315.236511,0.120275,0.000000
145.660004,65.170395,-315.325470,-0.000440,0.004735,0.120267,289.892395,14.767822,1.202667,-315.325470,0.119590,0.000000
146.070007,65.152512,-315.280975,-0.000444,0.004707,0.119547,289.812836,14.763770,1.195472,-315.280975,0.118905,0.000000
146.480011,65.137619,-315.325470,-0.000453,0.004680,0.118879,289.746613,14.760396,1.188792,-315.325470,0.118220,0.000000
146.889999,65.084747,-315.369934,-0.000440,0.004651,0.118134,289.511414,14.748415,1.181336,-315.369934,0.117544,0.000000
147.300003,64.816269,-315.369934,-0.000444,0.004627,0.117518,288.317169,14.687577,1.175178,-315.369934,0.116859,0.000000
147.710007,64.258453,-315.458893,-0.000453,0.004607,0.117006,285.835876,14.561173,1.170061,-315.458893,0.116173,0.000000
148.120010,63.041908,-315.414429,-0.000435,0.004574,0.116191,280.424408,14.285501,1.161908,-315.414429,0.115488,0.000000
148.530014,61.916229,-315.414429,-0.000427,0.004552,0.115627,275.417145,14.030417,1.156272,-315.414429,0.114803,0.000000
148.940002,60.796509,-315.458893,-0.000444,0.004530,0.115064,270.436371,13.776686,1.150636,-315.458893,0.114127,0.000000
149.350006,58.778992,-315.503387,-0.000431,0.004506,0.114448,261.462006,13.319510,1.144478,-315.503387,0.113442,0.000000
149.760010,56.685143,-315.503387,-0.000448,0.004480,0.113789,252.148102,12.845037,1.137885,-315.503387,0.112757,0.000000
150.170013,54.346642,-315.547852,-0.000440,0.004451,0.113060,241.745941,12.315125,1.130603,-315.547852,0.112072,0.000000
150.580002,51.998085,-315.636841,-0.000440,0.004427,0.112444,231.299026,11.782934,1.124445,-315.636841,0.111387,0.000000
150.990005,49.270836,-315.592346,-0.000448,0.004401,0.111777,219.167618,11.164931,1.117768,-315.592346,0.110710,0.000000
151.400009,46.728271,-315.547852,-0.000440,0.004372,0.111040,207.857727,10.588778,1.110395,-315.547852,0.110025,0.000000
151.810013,43.211960,-315.725800,-0.000448,0.004341,0.110268,192.216400,9.791970,1.102678,-315.725800,0.109340,0.000000
152.220001,40.175636,-315.636841,-0.000444,0.004316,0.109626,178.710159,9.103930,1.096259,-315.636841,0.108655,0.000000
152.630005,37.612595,-315.725800,-0.000440,0.004290,0.108958,167.309174,8.523136,1.089582,-315.725800,0.107970,0.000000
153.040009,34.815331,-315.770264,-0.000457,0.004267,0.108386,154.866318,7.889266,1.083860,-315.770264,0.107293,0.000000
153.450012,33.118431,-315.770264,-0.000448,0.004240,0.107692,147.318146,7.504744,1.076922,-315.770264,0.106608,0.000000
153.860001,28.698372,-315.814758,-0.000457,0.004211,0.106964,127.656731,6.503144,1.069636,-315.814758,0.105923,0.000000
154.270004,25.158974,-315.814758,-0.000444,0.004181,0.106192,111.912704,5.701105,1.061918,-315.814758,0.105238,0.000000
154.680008,22.285004,-315.859222,-0.000448,0.004157,0.105593,99.128647,5.049854,1.055935,-315.859222,0.104553,0.000000
155.090012,19.535400,-315.859222,-0.000470,0.004128,0.104847,86.897804,4.426785,1.048475,-315.859222,0.103876,0.000000
155.500000,16.725105,-315.859222,-0.000466,0.004104,0.104232,74.396980,3.789963,1.042317,-315.859222,0.103191,0.000000
155.910004,13.352158,-315.948181,-0.000474,0.004076,0.103521,59.393364,3.025642,1.035208,-315.948181,0.102506,0.000000
156.320007,10.415627,-315.948181,-0.000483,0.004050,0.102862,46.331020,2.360215,1.028615,-315.948181,0.101821,0.000000
156.730011,7.960205,-315.992676,-0.000474,0.004025,0.102237,35.408760,1.803808,1.022374,-315.992676,0.101136,0.000000
157.140015,5.151024,-316.037170,-0.000487,0.003997,0.101526,22.912899,1.167239,1.015262,-316.037170,0.100459,0.000000
157.550003,2.388397,-315.992676,-0.000496,0.003974,0.100937,10.624122,0.541219,1.009365,-315.992676,0.099774,0.000000
157.960007,-0.659103,-316.081635,-0.000500,0.003942,0.100121,-2.931838,-0.149355,1.001213,-316.081635,0.099089,0.000000
158.370010,-0.073730,-316.126129,-0.000543,0.003917,0.099488,-0.327969,-0.016708,0.994880,-316.126129,0.098404,0.000000
158.780014,0.029785,-316.126129,-0.000565,0.003887,0.098734,0.132491,0.006749,0.987337,-316.126129,0.097719,0.000000
159.190002,0.055481,-316.126129,-0.000617,0.003860,0.098040,0.246792,0.012572,0.980399,-316.126129,0.097043,0.000000
159.600006,0.050644,-316.215088,-0.000655,0.003844,0.097632,0.225275,0.011476,0.976323,-316.215088,0.096358,0.000000
160.010010,0.029785,-316.215088,-0.000703,0.003803,0.096609,0.132491,0.006749,0.966089,-316.215088,0.095672,0.000000
160.420013,0.037605,-316.170593,-0.000729,0.003783,0.096080,0.167277,0.008521,0.960797,-316.170593,0.094987,0.000000
160.830002,0.052505,-316.259552,-0.000767,0.003755,0.095378,0.233556,0.011898,0.953776,-316.259552,0.094302,0.000000
161.240005,0.021965,-316.259552,-0.000815,0.003729,0.094710,0.097705,0.004977,0.947096,-316.259552,0.093626,0.000000
161.650009,0.020103,-316.304047,-0.000828,0.003701,0.094007,0.089425,0.004556,0.940071,-316.304047,0.092941,0.000000
162.060013,-0.002235,-316.393005,-0.000871,0.003674,0.093322,-0.009944,-0.000507,0.933221,-316.393005,0.092255,0.000000
162.470001,0.020103,-316.348511,-0.000914,0.003646,0.092602,0.089425,0.004556,0.926022,-316.348511,0.091570,0.000000
162.880005,0.012283,-316.348511,-0.000940,0.003618,0.091908,0.054639,0.002783,0.919084,-316.348511,0.090885,0.000000
163.290009,0.018242,-316.393005,-0.000979,0.003595,0.091319,0.081144,0.004134,0.913187,-316.393005,0.090209,0.000000
163.700012,0.040588,-316.393005,-0.001022,0.003569,0.090642,0.180546,0.009197,0.906424,-316.393005,0.089524,0.000000
164.110001,0.022339,-316.437500,-0.001043,0.003541,0.089931,0.099368,0.005062,0.899312,-316.437500,0.088838,0.000000
164.520004,0.023827,-316.481964,-0.001091,0.003514,0.089255,0.105986,0.005399,0.892548,-316.481964,0.088153,0.000000
164.930008,0.002975,-316.526459,-0.001125,0.003486,0.088544,0.013236,0.000674,0.885436,-316.526459,0.087468,0.000000
165.340012,0.012657,-316.615417,-0.001186,0.003466,0.088041,0.056302,0.002868,0.880406,-316.615417,0.086792,0.000000
165.750015,0.024200,-316.570923,-0.001216,0.003426,0.087009,0.107649,0.005484,0.870089,-316.570923,0.086107,0.000000
166.160004,0.011543,-316.659882,-0.001237,0.003404,0.086471,0.051347,0.002616,0.864710,-316.659882,0.085422,0.000000
166.570007,0.004837,-316.570923,-0.001268,0.003375,0.085725,0.021516,0.001096,0.857254,-316.570923,0.084737,0.000000
166.980011,0.021965,-316.659882,-0.001293,0.003352,0.085144,0.097705,0.004977,0.851440,-316.659882,0.084051,0.000000
167.300003,0.038727,-316.748840,-0.001306,0.003345,0.084971,0.172265,0.008776,0.849707,-316.748840,0.084867,0.000000