File: Data/compression 17/ManualNoHeating-10-17-reverse-hand-2-2_09062024_171051.csv
Time (sec),S:Load (lbs),S:HL1 (DIM),S:LVDT (in),S:Position (in),Ch:Position (mm),Ch:Load (N),Ch:Stress (MPa),Ch:Strain (mm/mm),Ch:HL1 (DIM),Set Point (),Cycles ()
0.010000,-0.032028,-354.869019,-0.008050,-0.003186,-0.080912,-0.142469,-0.007258,-0.809122,-354.869019,-0.081120,0.000000
0.510000,0.012657,-355.002472,-0.008045,-0.003100,-0.078744,0.056302,0.002868,-0.787442,-355.002472,-0.077964,0.000000
1.010000,0.026062,-354.957977,-0.008011,-0.000000,-0.000000,0.115930,0.005906,-0.000000,-354.957977,0.000147,0.000000
1.510000,0.041328,-355.046967,-0.008019,0.000000,0.000009,0.183838,0.009365,0.000087,-355.046967,0.000668,0.000000
2.010000,0.033508,-355.046967,-0.008028,0.000024,0.000607,0.149052,0.007593,0.006071,-355.046967,0.001500,0.000000
2.510000,0.005959,-355.091431,-0.008011,0.000055,0.001388,0.026505,0.001350,0.013875,-355.091431,0.002333,0.000000
3.010000,0.020103,-355.135925,-0.007985,0.000080,0.002021,0.089425,0.004556,0.020206,-355.135925,0.003174,0.000000
3.510000,0.026810,-355.180389,-0.007972,0.000111,0.002810,0.119255,0.006075,0.028099,-355.180389,0.004007,0.000000
4.010000,0.019363,-355.180389,-0.007933,0.000148,0.003755,0.086133,0.004388,0.037550,-355.180389,0.004839,0.000000
4.510000,-0.021973,-355.224884,-0.007890,0.000183,0.004640,-0.097739,-0.004979,0.046397,-355.224884,0.005672,0.000000
5.010000,-0.001862,-355.224884,-0.007869,0.000212,0.005394,-0.008281,-0.000422,0.053942,-355.224884,0.006504,0.000000
5.510000,0.032394,-355.269348,-0.007838,0.000249,0.006331,0.144098,0.007341,0.063308,-355.269348,0.007337,0.000000
6.010000,0.004463,-355.313843,-0.007787,0.000287,0.007302,0.019853,0.001011,0.073020,-355.313843,0.008169,0.000000
6.510000,-0.025696,-355.313843,-0.007765,0.000320,0.008117,-0.114301,-0.005823,0.081173,-355.313843,0.009002,0.000000
7.010000,0.021225,-355.269348,-0.007726,0.000352,0.008932,0.094413,0.004810,0.089324,-355.269348,0.009834,0.000000
7.510000,0.040962,-355.358307,-0.007692,0.000381,0.009670,0.182209,0.009282,0.096696,-355.358307,0.010667,0.000000
8.010000,0.023827,-355.358307,-0.007657,0.000412,0.010468,0.105986,0.005399,0.104675,-355.358307,0.011508,0.000000
8.510000,-0.042824,-355.447266,-0.007623,0.000444,0.011274,-0.190490,-0.009704,0.112739,-355.447266,0.012341,0.000000
9.010000,0.014145,-355.402802,-0.007597,0.000477,0.012115,0.062920,0.003205,0.121151,-355.402802,0.013173,0.000000
9.510000,0.040215,-355.402802,-0.007554,0.000509,0.012939,0.178883,0.009113,0.129390,-355.402802,0.014006,0.000000
10.010000,0.020477,-355.447266,-0.007506,0.000550,0.013962,0.091088,0.004640,0.139623,-355.447266,0.014838,0.000000
10.510000,-0.021225,-355.580719,-0.007485,0.000580,0.014734,-0.094413,-0.004810,0.147342,-355.580719,0.015671,0.000000
11.010000,0.032021,-355.536255,-0.007455,0.000616,0.015636,0.142435,0.007256,0.156362,-355.536255,0.016503,0.000000
11.510000,0.062927,-355.625214,-0.007433,0.000639,0.016243,0.279914,0.014260,0.162431,-355.625214,0.017336,0.000000
12.010000,0.052132,-355.536255,-0.007390,0.000678,0.017232,0.231893,0.011813,0.172319,-355.536255,0.018168,0.000000
12.510000,0.015266,-355.625214,-0.007360,0.000709,0.018004,0.067908,0.003459,0.180036,-355.625214,0.019001,0.000000
13.010000,0.042450,-355.714172,-0.007325,0.000744,0.018897,0.188827,0.009619,0.188968,-355.714172,0.019842,0.000000
13.510000,0.042824,-355.669678,-0.007299,0.000772,0.019617,0.190490,0.009704,0.196167,-355.669678,0.020675,0.000000
14.010000,0.055107,-355.758636,-0.007248,0.000813,0.020640,0.245129,0.012487,0.206400,-355.758636,0.021507,0.000000
14.510000,0.035004,-355.758636,-0.007209,0.000842,0.021386,0.155704,0.007932,0.213858,-355.758636,0.022340,0.000000
15.010001,0.036118,-355.758636,-0.007192,0.000870,0.022097,0.160659,0.008184,0.220970,-355.758636,0.023172,0.000000
15.510001,0.064789,-355.803131,-0.007153,0.000906,0.023007,0.288195,0.014681,0.230074,-355.803131,0.024005,0.000000
16.010000,0.023460,-355.803131,-0.007110,0.000945,0.024005,0.104357,0.005316,0.240047,-355.803131,0.024837,0.000000
16.510000,0.032768,-355.847595,-0.007088,0.000977,0.024811,0.145760,0.007425,0.248113,-355.847595,0.025670,0.000000
17.010000,0.066284,-355.847595,-0.007049,0.001008,0.025600,0.294847,0.015020,0.256005,-355.847595,0.026502,0.000000
17.510000,0.064789,-355.936584,-0.007032,0.001035,0.026286,0.288195,0.014681,0.262855,-355.936584,0.027335,0.000000
18.010000,0.062187,-355.936584,-0.006985,0.001068,0.027135,0.276622,0.014092,0.271354,-355.936584,0.028176,0.000000
18.510000,0.016754,-355.981049,-0.006946,0.001102,0.027985,0.074526,0.003797,0.279853,-355.981049,0.029009,0.000000
19.010000,0.037605,-355.936584,-0.006924,0.001133,0.028783,0.167277,0.008521,0.287832,-355.936584,0.029841,0.000000
19.510000,0.044685,-356.070007,-0.006890,0.001166,0.029624,0.198770,0.010126,0.296244,-356.070007,0.030674,0.000000
20.010000,0.049149,-356.025543,-0.006864,0.001196,0.030370,0.218624,0.011137,0.303702,-356.025543,0.031506,0.000000
20.510000,0.044685,-356.070007,-0.006821,0.001229,0.031211,0.198770,0.010126,0.312114,-356.070007,0.032339,0.000000
21.010000,0.026436,-356.158966,-0.006791,0.001264,0.032096,0.117593,0.005990,0.320961,-356.158966,0.033171,0.000000
21.510000,0.062187,-356.114502,-0.006752,0.001302,0.033067,0.276622,0.014092,0.330673,-356.114502,0.034004,0.000000
22.010000,0.017502,-356.114502,-0.006717,0.001333,0.033865,0.077852,0.003966,0.338652,-356.114502,0.034837,0.000000
22.510000,0.040215,-356.158966,-0.006696,0.001361,0.034559,0.178883,0.009113,0.345589,-356.158966,0.035669,0.000000
23.010000,0.042450,-356.203461,-0.006640,0.001394,0.035418,0.188827,0.009619,0.354175,-356.203461,0.036510,0.000000
23.510000,0.038353,-356.247925,-0.006627,0.001432,0.036363,0.170603,0.008691,0.363628,-356.247925,0.037343,0.000000
24.010000,0.013031,-356.292419,-0.006575,0.001464,0.037178,0.057965,0.002953,0.371779,-356.292419,0.038175,0.000000
24.510000,0.023460,-356.292419,-0.006554,0.001495,0.037976,0.104357,0.005316,0.379757,-356.292419,0.039008,0.000000
25.010002,0.053993,-356.381378,-0.006519,0.001529,0.038826,0.240174,0.012235,0.388256,-356.381378,0.039840,0.000000
25.510002,0.029045,-356.381378,-0.006485,0.001561,0.039658,0.129199,0.006582,0.396583,-356.381378,0.040673,0.000000
26.010002,-0.013779,-356.425873,-0.006454,0.001593,0.040473,-0.061291,-0.003122,0.404734,-356.425873,0.041505,0.000000
26.510002,0.023460,-356.381378,-0.006403,0.001626,0.041289,0.104357,0.005316,0.412887,-356.381378,0.042338,0.000000
27.010002,0.043190,-356.425873,-0.006381,0.001658,0.042104,0.192119,0.009787,0.421037,-356.425873,0.043171,0.000000
27.510002,0.028297,-356.425873,-0.006338,0.001696,0.043075,0.125873,0.006412,0.430751,-356.425873,0.044003,0.000000
28.010002,-0.021599,-356.514832,-0.006316,0.001726,0.043838,-0.096076,-0.004894,0.438382,-356.514832,0.044844,0.000000
28.510002,0.020477,-356.470337,-0.006286,0.001759,0.044671,0.091088,0.004640,0.446708,-356.470337,0.045677,0.000000
29.010002,0.034256,-356.514832,-0.006252,0.001782,0.045261,0.152378,0.007763,0.452605,-356.514832,0.046509,0.000000
29.510002,-0.001122,-356.603790,-0.006222,0.001821,0.046249,-0.004989,-0.000254,0.462491,-356.603790,0.047342,0.000000
30.010002,-0.045807,-356.603790,-0.006183,0.001854,0.047090,-0.203759,-0.010380,0.470903,-356.603790,0.048174,0.000000
30.510002,0.027924,-356.648254,-0.006140,0.001883,0.047836,0.124210,0.006328,0.478362,-356.648254,0.049007,0.000000
31.010002,0.023827,-356.692749,-0.006109,0.001916,0.048669,0.105986,0.005399,0.486686,-356.692749,0.049839,0.000000
31.510002,0.010422,-356.737213,-0.006062,0.001956,0.049692,0.046358,0.002362,0.496921,-356.737213,0.050672,0.000000
32.010002,-0.010429,-356.692749,-0.006032,0.001985,0.050420,-0.046392,-0.002363,0.504205,-356.692749,0.051504,0.000000
32.510002,0.042076,-356.781708,-0.006010,0.002018,0.051253,0.187164,0.009535,0.512530,-356.781708,0.052337,0.000000
33.010002,0.057716,-356.826202,-0.005971,0.002048,0.052016,0.256735,0.013079,0.520162,-356.826202,0.053170,0.000000
33.510002,0.046547,-356.826202,-0.005941,0.002086,0.052988,0.207051,0.010548,0.529876,-356.826202,0.054011,0.000000
34.010002,0.035744,-356.870667,-0.005920,0.002117,0.053768,0.158996,0.008100,0.537680,-356.870667,0.054843,0.000000
34.510002,0.037605,-356.870667,-0.005872,0.002152,0.054670,0.167277,0.008521,0.546700,-356.870667,0.055676,0.000000
35.010002,0.062553,-356.915161,-0.005829,0.002189,0.055598,0.278251,0.014175,0.555978,-356.915161,0.056508,0.000000
35.510002,0.039841,-356.915161,-0.005799,0.002222,0.056439,0.177220,0.009028,0.564390,-356.915161,0.057341,0.000000
36.010002,0.027924,-357.004120,-0.005777,0.002252,0.057202,0.124210,0.006328,0.572023,-357.004120,0.058173,0.000000
36.510002,0.065536,-357.048584,-0.005743,0.002281,0.057939,0.291521,0.014851,0.579394,-357.048584,0.059006,0.000000
37.010002,0.069633,-357.048584,-0.005700,0.002321,0.058954,0.309745,0.015779,0.589541,-357.048584,0.059839,0.000000
37.510002,0.030159,-357.048584,-0.005670,0.002354,0.059787,0.134154,0.006834,0.597866,-357.048584,0.060671,0.000000
38.010002,0.027924,-357.093079,-0.005622,0.002387,0.060628,0.124210,0.006328,0.606278,-357.093079,0.061504,0.000000
38.510002,0.065536,-357.093079,-0.005596,0.002407,0.061139,0.291521,0.014851,0.611395,-357.093079,0.062345,0.000000
39.010002,0.077827,-357.182037,-0.005562,0.002451,0.062249,0.346194,0.017636,0.622494,-357.182037,0.063177,0.000000
39.510002,0.021965,-357.182037,-0.005532,0.002480,0.062995,0.097705,0.004977,0.629952,-357.182037,0.064010,0.000000
40.010002,0.043938,-357.182037,-0.005501,0.002515,0.063888,0.195445,0.009956,0.638885,-357.182037,0.064842,0.000000
40.510002,0.056602,-357.315491,-0.005484,0.002545,0.064634,0.251780,0.012826,0.646343,-357.315491,0.065675,0.000000
41.010002,0.052872,-357.270996,-0.005428,0.002579,0.065510,0.235185,0.011981,0.655103,-357.270996,0.066508,0.000000
41.510002,0.045052,-357.315491,-0.005411,0.002606,0.066195,0.200399,0.010209,0.661954,-357.315491,0.067340,0.000000
42.010002,0.052505,-357.359955,-0.005359,0.002647,0.067227,0.233556,0.011898,0.672273,-357.359955,0.068173,0.000000
42.510002,0.057343,-357.359955,-0.005333,0.002676,0.067982,0.255072,0.012994,0.679818,-357.359955,0.069005,0.000000
43.010002,0.064415,-357.404449,-0.005299,0.002713,0.068901,0.286532,0.014597,0.689012,-357.404449,0.069838,0.000000
43.510002,0.004837,-357.493408,-0.005260,0.002739,0.069578,0.021516,0.001096,0.695775,-357.493408,0.070679,0.000000
44.010002,0.024200,-357.448914,-0.005243,0.002773,0.070445,0.107649,0.005484,0.704447,-357.448914,0.071511,0.000000
44.510002,0.040215,-357.493408,-0.005213,0.002805,0.071243,0.178883,0.009113,0.712425,-357.493408,0.072344,0.000000
45.010002,0.035004,-357.493408,-0.005157,0.002839,0.072119,0.155704,0.007932,0.721185,-357.493408,0.073177,0.000000
45.510002,0.023087,-357.493408,-0.005135,0.002873,0.072986,0.102694,0.005231,0.729856,-357.493408,0.074009,0.000000
46.010002,0.037605,-357.582367,-0.005105,0.002903,0.073731,0.167277,0.008521,0.737315,-357.582367,0.074842,0.000000
46.510002,0.026810,-357.671326,-0.005083,0.002938,0.074625,0.119255,0.006075,0.746247,-357.671326,0.075674,0.000000
47.010002,0.040215,-357.671326,-0.005032,0.002971,0.075457,0.178883,0.009113,0.754574,-357.671326,0.076507,0.000000
47.510002,0.012657,-357.715820,-0.005014,0.003002,0.076255,0.056302,0.002868,0.762552,-357.715820,0.077339,0.000000
48.010002,0.059204,-357.715820,-0.004975,0.003040,0.077218,0.263353,0.013416,0.772177,-357.715820,0.078172,0.000000
48.510002,0.106125,-357.760284,-0.004924,0.003075,0.078102,0.472067,0.024048,0.781023,-357.760284,0.079013,0.000000
49.010002,0.138145,-357.760284,-0.004894,0.003106,0.078883,0.614502,0.031304,0.788829,-357.760284,0.079845,0.000000
49.510002,0.272949,-357.804779,-0.004859,0.003139,0.079724,1.214139,0.061851,0.797241,-357.804779,0.080678,0.000000
50.010002,0.433815,-357.804779,-0.004838,0.003167,0.080452,1.929706,0.098304,0.804525,-357.804779,0.081511,0.000000
50.510002,0.561165,-357.849243,-0.004794,0.003193,0.081112,2.496186,0.127162,0.811116,-357.849243,0.082343,0.000000
51.010002,0.780487,-357.849243,-0.004760,0.003232,0.082100,3.471780,0.176861,0.821002,-357.849243,0.083176,0.000000
51.510002,1.072060,-357.893738,-0.004734,0.003267,0.082993,4.768759,0.242932,0.829935,-357.893738,0.084008,0.000000
52.010002,1.339050,-357.938202,-0.004700,0.003297,0.083748,5.956393,0.303433,0.837480,-357.938202,0.084841,0.000000
52.510002,1.703972,-357.982697,-0.004669,0.003338,0.084797,7.579646,0.386126,0.847974,-357.982697,0.085673,0.000000
53.010002,1.891281,-357.982697,-0.004648,0.003367,0.085517,8.412839,0.428570,0.855171,-357.982697,0.086506,0.000000
53.510002,2.303123,-357.982697,-0.004605,0.003405,0.086497,10.244805,0.521895,0.864972,-357.982697,0.087347,0.000000
54.010002,2.402176,-358.071655,-0.004570,0.003423,0.086948,10.685412,0.544341,0.869481,-358.071655,0.088180,0.000000
54.510002,2.891846,-358.071655,-0.004527,0.003465,0.088006,12.863572,0.655302,0.880060,-358.071655,0.089012,0.000000
55.010002,3.113403,-358.071655,-0.004514,0.003497,0.088830,13.849110,0.705507,0.888300,-358.071655,0.089845,0.000000
55.510002,3.379654,-358.116150,-0.004493,0.003530,0.089671,15.033451,0.765841,0.896712,-358.116150,0.090677,0.000000
56.010002,3.686111,-358.160614,-0.004454,0.003561,0.090443,16.396643,0.835285,0.904429,-358.160614,0.091510,0.000000
56.510002,4.053642,-358.205109,-0.004419,0.003597,0.091362,18.031502,0.918568,0.913623,-358.205109,0.092342,0.000000
57.010002,4.351540,-358.294067,-0.004389,0.003633,0.092273,19.356615,0.986073,0.922729,-358.294067,0.093175,0.000000
57.510002,4.563049,-358.160614,-0.004342,0.003661,0.092984,20.297457,1.034002,0.929839,-358.160614,0.094007,0.000000
58.010002,4.895576,-358.294067,-0.004316,0.003692,0.093782,21.776611,1.109353,0.937818,-358.294067,0.094840,0.000000
58.510002,5.309288,-358.294067,-0.004277,0.003733,0.094822,23.616892,1.203102,0.948224,-358.294067,0.095681,0.000000
59.010002,5.474617,-358.294067,-0.004255,0.003765,0.095620,24.352312,1.240566,0.956203,-358.294067,0.096513,0.000000
59.510002,5.810501,-358.427490,-0.004221,0.003799,0.096505,25.846399,1.316678,0.965048,-358.427490,0.097346,0.000000
60.010002,5.934868,-358.471985,-0.004191,0.003821,0.097043,26.399611,1.344860,0.970426,-358.471985,0.098179,0.000000
60.510002,6.365334,-358.427490,-0.004156,0.003861,0.098066,28.314417,1.442405,0.980659,-358.427490,0.099011,0.000000
61.010002,6.485611,-358.383026,-0.004126,0.003890,0.098803,28.849438,1.469660,0.988030,-358.383026,0.099844,0.000000
61.510002,6.806969,-358.516479,-0.004087,0.003925,0.099705,30.278910,1.542481,0.997049,-358.516479,0.100676,0.000000
62.010002,7.032623,-358.516479,-0.004057,0.003955,0.100459,31.282671,1.593615,1.004594,-358.516479,0.101509,0.000000
62.510002,7.279877,-358.516479,-0.004010,0.003990,0.101344,32.382507,1.649644,1.013440,-358.516479,0.102341,0.000000
63.010002,7.469414,-358.560944,-0.003975,0.004019,0.102090,33.225613,1.692593,1.020898,-358.560944,0.103174,0.000000
63.510002,7.676826,-358.605438,-0.003945,0.004053,0.102948,34.148232,1.739594,1.029484,-358.605438,0.104015,0.000000
64.010002,8.231293,-358.605438,-0.003919,0.004094,0.103998,36.614620,1.865238,1.039977,-358.605438,0.104848,0.000000
64.510002,8.041008,-358.605438,-0.003859,0.004120,0.104639,35.768188,1.822118,1.046395,-358.605438,0.105680,0.000000
65.010002,8.112503,-358.738861,-0.003846,0.004148,0.105351,36.086216,1.838319,1.053507,-358.738861,0.106513,0.000000
65.510002,8.504982,-358.694397,-0.003798,0.004180,0.106166,37.832050,1.927256,1.061657,-358.694397,0.107345,0.000000
66.010002,8.883690,-358.783356,-0.003755,0.004221,0.107215,39.516624,2.013073,1.072151,-358.783356,0.108178,0.000000
66.510002,8.886665,-358.783356,-0.003721,0.004251,0.107987,39.529861,2.013747,1.079870,-358.783356,0.109010,0.000000
67.010002,8.990562,-358.694397,-0.003682,0.004281,0.108750,39.992020,2.037291,1.087501,-358.694397,0.109843,0.000000
67.510002,8.881454,-358.783356,-0.003656,0.004301,0.109236,39.506683,2.012566,1.092357,-358.783356,0.110675,0.000000
68.010002,9.461609,-358.827820,-0.003609,0.004350,0.110502,42.087337,2.144031,1.105019,-358.827820,0.111508,0.000000
68.510002,9.492142,-358.827820,-0.003583,0.004384,0.111343,42.223156,2.150950,1.113431,-358.827820,0.112340,0.000000
69.010002,9.743126,-358.916809,-0.003527,0.004416,0.112167,43.339588,2.207824,1.121671,-358.916809,0.113182,0.000000
69.510002,9.800095,-358.872314,-0.003505,0.004448,0.112982,43.592999,2.220733,1.129821,-358.872314,0.114014,0.000000
70.010002,10.109535,-358.961273,-0.003462,0.004486,0.113945,44.969460,2.290854,1.139448,-358.961273,0.114847,0.000000
70.510002,10.103210,-359.005768,-0.003397,0.004517,0.114734,44.941326,2.289420,1.147340,-359.005768,0.115679,0.000000
71.010002,10.339661,-359.005768,-0.003393,0.004548,0.115514,45.993107,2.343001,1.155144,-359.005768,0.116512,0.000000
71.510002,10.504623,-359.050232,-0.003367,0.004576,0.116234,46.726898,2.380382,1.162343,-359.050232,0.117344,0.000000
72.010002,10.940674,-359.005768,-0.003298,0.004614,0.117188,48.666546,2.479192,1.171883,-359.005768,0.118177,0.000000
72.510002,10.984985,-359.183685,-0.003264,0.004647,0.118038,48.863655,2.489233,1.180380,-359.183685,0.119009,0.000000
73.010002,11.041962,-359.183685,-0.003229,0.004676,0.118758,49.117100,2.502144,1.187579,-359.183685,0.119842,0.000000
73.510002,11.339111,-359.139191,-0.003199,0.004708,0.119590,50.438885,2.569479,1.195904,-359.139191,0.120674,0.000000
74.010002,11.674995,-359.183685,-0.003169,0.004747,0.120562,51.932972,2.645592,1.205618,-359.183685,0.121516,0.000000
74.510002,11.727867,-359.183685,-0.003122,0.004778,0.121360,52.168159,2.657573,1.213596,-359.183685,0.122348,0.000000
75.010002,12.037308,-359.272644,-0.003083,0.004813,0.122253,53.544621,2.727693,1.222529,-359.272644,0.123181,0.000000
75.510002,12.117744,-359.317108,-0.003057,0.004841,0.122955,53.902420,2.745920,1.229553,-359.317108,0.124013,0.000000
76.010002,12.530334,-359.317108,-0.003014,0.004876,0.123840,55.737713,2.839414,1.238399,-359.317108,0.124846,0.000000
76.510002,12.587677,-359.361603,-0.002992,0.004906,0.124620,55.992783,2.852408,1.246203,-359.361603,0.125678,0.000000
77.010002,13.117935,-359.361603,-0.002953,0.004944,0.125566,58.351490,2.972567,1.255656,-359.361603,0.126511,0.000000
77.510002,12.963402,-359.406097,-0.002932,0.004970,0.126251,57.664093,2.937549,1.262507,-359.406097,0.127343,0.000000
78.010002,13.504456,-359.406097,-0.002893,0.005011,0.127283,60.070820,3.060153,1.272828,-359.406097,0.128176,0.000000
78.510002,13.439667,-359.495056,-0.002854,0.005041,0.128046,59.782623,3.045472,1.280458,-359.495056,0.129008,0.000000
79.010002,13.616173,-359.406097,-0.002824,0.005071,0.128792,60.567760,3.085469,1.287918,-359.406097,0.129850,0.000000
79.510002,14.110680,-359.539520,-0.002794,0.005107,0.129728,62.767437,3.197526,1.297282,-359.539520,0.130682,0.000000
80.010002,14.337082,-359.495056,-0.002764,0.005144,0.130656,63.774525,3.248829,1.306563,-359.495056,0.131515,0.000000
80.510002,14.417885,-359.539520,-0.002734,0.005175,0.131437,64.133957,3.267139,1.314367,-359.539520,0.132347,0.000000
81.010002,14.421242,-359.628479,-0.002695,0.005204,0.132174,64.148888,3.267900,1.321740,-359.628479,0.133180,0.000000
81.510002,14.902344,-359.672974,-0.002677,0.005236,0.133006,66.288933,3.376919,1.330063,-359.672974,0.134012,0.000000
82.010002,15.005867,-359.672974,-0.002643,0.005270,0.133856,66.749428,3.400378,1.338564,-359.672974,0.134845,0.000000
82.510002,15.156303,-359.672974,-0.002613,0.005304,0.134715,67.418602,3.434467,1.347148,-359.672974,0.135677,0.000000
83.010002,15.002510,-359.717438,-0.002587,0.005331,0.135400,66.734497,3.399617,1.353999,-359.717438,0.136510,0.000000
83.510002,15.814659,-359.761932,-0.002557,0.005369,0.136371,70.347115,3.583653,1.363711,-359.761932,0.137343,0.000000
84.010002,15.772575,-359.806427,-0.002522,0.005399,0.137143,70.159920,3.574117,1.371432,-359.806427,0.138184,0.000000
84.510002,16.047386,-359.850891,-0.002501,0.005432,0.137984,71.382339,3.636390,1.379842,-359.850891,0.139016,0.000000
85.010002,16.005684,-359.850891,-0.002475,0.005464,0.138791,71.196838,3.626940,1.387908,-359.850891,0.139849,0.000000
85.510002,16.442848,-359.939850,-0.002445,0.005503,0.139779,73.141441,3.726003,1.397794,-359.939850,0.140681,0.000000
86.010002,16.278259,-359.895386,-0.002419,0.005534,0.140560,72.409317,3.688706,1.405598,-359.895386,0.141514,0.000000
86.510002,16.093567,-359.984344,-0.002406,0.005557,0.141150,71.587761,3.646854,1.411495,-359.984344,0.142346,0.000000
87.010002,16.786552,-359.939850,-0.002380,0.005597,0.142173,74.670311,3.803887,1.421730,-359.939850,0.143179,0.000000
87.510002,16.608925,-360.028809,-0.002345,0.005631,0.143023,73.880188,3.763636,1.430230,-360.028809,0.144012,0.000000
88.010002,16.517326,-360.028809,-0.002328,0.005664,0.143855,73.472740,3.742880,1.438553,-360.028809,0.144844,0.000000
88.510002,16.034355,-360.073303,-0.002311,0.005686,0.144419,71.324371,3.633437,1.444189,-360.073303,0.145677,0.000000
89.010002,16.766815,-360.073303,-0.002285,0.005729,0.145512,74.582520,3.799415,1.455120,-360.073303,0.146518,0.000000
89.510002,16.597008,-360.162262,-0.002272,0.005763,0.146370,73.827179,3.760936,1.463704,-360.162262,0.147350,0.000000
90.010002,16.165062,-360.117767,-0.002242,0.005791,0.147090,71.905785,3.663055,1.470903,-360.117767,0.148183,0.000000
90.510002,16.212723,-360.251221,-0.002212,0.005822,0.147879,72.117790,3.673855,1.478794,-360.251221,0.149015,0.000000
91.010002,16.445084,-360.251221,-0.002186,0.005862,0.148894,73.151382,3.726509,1.488938,-360.251221,0.149848,0.000000
91.510002,16.443222,-360.295715,-0.002169,0.005894,0.149709,73.143105,3.726087,1.497091,-360.295715,0.150681,0.000000
92.010002,16.552330,-360.295715,-0.002156,0.005925,0.150498,73.628441,3.750812,1.504982,-360.295715,0.151513,0.000000
92.510002,16.718781,-360.251221,-0.002139,0.005956,0.151279,74.368851,3.788530,1.512790,-360.251221,0.152346,0.000000
93.010002,17.179405,-360.384674,-0.002113,0.005987,0.152077,76.417809,3.892909,1.520765,-360.384674,0.153178,0.000000
93.510002,17.610611,-360.429138,-0.002082,0.006023,0.152987,78.335907,3.990621,1.529872,-360.429138,0.154011,0.000000
94.010002,17.422562,-360.384674,-0.002065,0.006051,0.153690,77.499428,3.948009,1.536896,-360.384674,0.154852,0.000000
94.510002,17.473206,-360.473633,-0.002044,0.006084,0.154522,77.724701,3.959485,1.545223,-360.473633,0.155684,0.000000
95.010002,18.234703,-360.473633,-0.002026,0.006121,0.155476,81.112007,4.132043,1.554761,-360.473633,0.156517,0.000000
95.510002,18.449936,-360.562592,-0.001996,0.006154,0.156309,82.069412,4.180815,1.563088,-360.562592,0.157349,0.000000
96.010002,18.724747,-360.607056,-0.001970,0.006189,0.157193,83.291832,4.243088,1.571933,-360.607056,0.158182,0.000000
96.510002,18.529999,-360.518097,-0.001957,0.006213,0.157818,82.425552,4.198958,1.578178,-360.518097,0.159015,0.000000
97.010002,19.068451,-360.562592,-0.001927,0.006251,0.158772,84.820709,4.320972,1.587716,-360.562592,0.159847,0.000000
97.510002,19.567802,-360.607056,-0.001884,0.006286,0.159656,87.041931,4.434127,1.596561,-360.607056,0.160680,0.000000
98.010002,19.626259,-360.696045,-0.001871,0.006315,0.160411,87.301956,4.447373,1.604108,-360.696045,0.161512,0.000000
98.510002,20.010925,-360.740509,-0.001832,0.006351,0.161321,89.013039,4.534540,1.613215,-360.740509,0.162345,0.000000
99.010002,20.534851,-360.696045,-0.001824,0.006388,0.162258,91.343582,4.653264,1.622579,-360.696045,0.163177,0.000000
99.510002,20.516602,-360.785004,-0.001794,0.006421,0.163099,91.262405,4.649128,1.630993,-360.785004,0.164018,0.000000
100.010002,20.350525,-360.740509,-0.001772,0.006452,0.163880,90.523659,4.611495,1.638797,-360.740509,0.164851,0.000000
100.510002,20.619003,-360.829468,-0.001750,0.006481,0.164608,91.717911,4.672333,1.646083,-360.829468,0.165684,0.000000
101.010002,21.440460,-360.785004,-0.001720,0.006519,0.165579,95.371933,4.858478,1.655795,-360.785004,0.166516,0.000000
101.510002,21.226715,-360.785004,-0.001694,0.006553,0.166455,94.421143,4.810042,1.664553,-360.785004,0.167349,0.000000
102.010002,21.464661,-360.918427,-0.001660,0.006587,0.167305,95.479576,4.863962,1.673050,-360.918427,0.168181,0.000000
102.510002,21.164536,-360.918427,-0.001634,0.006607,0.167825,94.144554,4.795952,1.678255,-360.918427,0.169014,0.000000
103.010002,22.551247,-360.962921,-0.001625,0.006649,0.168884,100.312958,5.110185,1.688837,-360.962921,0.169846,0.000000
103.510002,22.831642,-361.007385,-0.001608,0.006681,0.169699,101.560219,5.173724,1.696986,-361.007385,0.170679,0.000000
104.010002,23.369720,-360.962921,-0.001582,0.006715,0.170557,103.953705,5.295655,1.705574,-360.962921,0.171511,0.000000
104.510002,23.763695,-361.007385,-0.001552,0.006743,0.171277,105.706192,5.384930,1.712769,-361.007385,0.172353,0.000000
105.010002,24.363953,-361.051880,-0.001531,0.006775,0.172075,108.376274,5.520950,1.720748,-361.051880,0.173185,0.000000
105.510002,25.044281,-361.096375,-0.001513,0.006810,0.172977,111.402527,5.675116,1.729767,-361.096375,0.174018,0.000000
106.010002,26.104050,-361.096375,-0.001483,0.006844,0.173827,116.116615,5.915262,1.738268,-361.096375,0.174850,0.000000
106.510002,26.569893,-361.096375,-0.001475,0.006873,0.174581,118.188789,6.020823,1.745811,-361.096375,0.175683,0.000000
107.010002,27.891068,-361.096375,-0.001440,0.006914,0.175622,124.065666,6.320206,1.756220,-361.096375,0.176515,0.000000
107.510002,27.960701,-361.185333,-0.001418,0.006938,0.176220,124.375412,6.335985,1.762204,-361.185333,0.177347,0.000000
108.010002,29.377579,-361.185333,-0.001393,0.006971,0.177070,130.677994,6.657054,1.770701,-361.185333,0.178180,0.000000
108.510002,30.505119,-361.274292,-0.001384,0.007005,0.177920,135.693542,6.912559,1.779202,-361.274292,0.179013,0.000000
109.010002,31.979721,-361.274292,-0.001354,0.007039,0.178796,142.252899,7.246708,1.787960,-361.274292,0.179845,0.000000
109.510002,32.886444,-361.274292,-0.001350,0.007069,0.179559,146.286209,7.452175,1.795590,-361.274292,0.180687,0.000000
110.010002,33.907494,-361.318756,-0.001324,0.007098,0.180288,150.828064,7.683548,1.802876,-361.318756,0.181519,0.000000
110.510002,36.047142,-361.318756,-0.001298,0.007138,0.181294,160.345703,8.168399,1.812936,-361.318756,0.182351,0.000000
111.010002,37.166122,-361.318756,-0.001276,0.007170,0.182117,165.323166,8.421964,1.821172,-361.318756,0.183184,0.000000
111.510002,38.374474,-361.318756,-0.001268,0.007198,0.182820,170.698181,8.695780,1.828197,-361.318756,0.184016,0.000000
112.010002,40.562904,-361.407715,-0.001242,0.007237,0.183817,180.432816,9.191686,1.838170,-361.407715,0.184849,0.000000
112.510002,42.463493,-361.407715,-0.001220,0.007273,0.184736,188.887054,9.622366,1.847364,-361.407715,0.185682,0.000000
113.010002,43.770889,-361.452209,-0.001212,0.007304,0.185534,194.702637,9.918625,1.855342,-361.452209,0.186514,0.000000
113.510002,45.564240,-361.496704,-0.001190,0.007336,0.186341,202.679855,10.325005,1.863408,-361.496704,0.187347,0.000000
114.010002,46.469849,-361.496704,-0.001160,0.007364,0.187052,206.708206,10.530219,1.870520,-361.496704,0.188179,0.000000
114.510002,48.830688,-361.585663,-0.001164,0.007398,0.187910,217.209747,11.065192,1.879104,-361.585663,0.189020,0.000000
115.010002,51.322235,-361.541168,-0.001151,0.007433,0.188795,228.292709,11.629785,1.887949,-361.541168,0.189853,0.000000
115.510002,53.674141,-361.585663,-0.001121,0.007466,0.189645,238.754501,12.162734,1.896450,-361.585663,0.190685,0.000000
116.010002,55.054146,-361.585663,-0.001112,0.007490,0.190235,244.893066,12.475448,1.902347,-361.585663,0.191518,0.000000
116.510002,58.483704,-361.674622,-0.001087,0.007535,0.191388,260.148499,13.252597,1.913879,-361.674622,0.192351,0.000000
117.010002,60.250977,-361.719086,-0.001091,0.007564,0.192117,268.009735,13.653067,1.921165,-361.719086,0.193183,0.000000
117.510002,63.207245,-361.719086,-0.001074,0.007602,0.193088,281.159882,14.322966,1.930877,-361.719086,0.194016,0.000000
118.010002,64.946594,-361.719086,-0.001052,0.007629,0.193764,288.896881,14.717109,1.937641,-361.719086,0.194848,0.000000
118.510002,65.961304,-361.763580,-0.001039,0.007638,0.193998,293.410522,14.947045,1.939984,-361.763580,0.034014,0.000000
119.010002,65.054214,-361.763580,-0.001035,0.007640,0.194059,289.375610,14.741495,1.940589,-361.763580,294.500458,0.000000
119.510002,65.265717,-361.808044,-0.001030,0.007653,0.194380,290.316406,14.789423,1.943799,-361.808044,294.500458,0.000000
120.010002,65.194229,-361.897003,-0.001022,0.007654,0.194423,289.998413,14.773223,1.944234,-361.897003,294.500458,0.000000
120.510002,65.091827,-361.897003,-0.001009,0.007658,0.194501,289.542908,14.750019,1.945014,-361.897003,294.500458,0.000000
121.010002,65.237793,-361.897003,-0.001013,0.007663,0.194640,290.192200,14.783095,1.946403,-361.897003,294.500458,0.000000
121.510002,65.120499,-361.897003,-0.001018,0.007664,0.194675,289.670441,14.756516,1.946747,-361.897003,294.500458,0.000000
122.010002,65.394562,-361.985992,-0.001022,0.007670,0.194814,290.889526,14.818619,1.948137,-361.985992,294.500458,0.000000
122.510002,65.286575,-361.985992,-0.001005,0.007670,0.194814,290.409180,14.794149,1.948137,-361.985992,294.500458,0.000000
123.010002,65.096664,-362.030457,-0.001013,0.007670,0.194814,289.564423,14.751115,1.948137,-362.030457,294.500458,0.000000
123.510002,65.379288,-362.074951,-0.001009,0.007676,0.194961,290.821594,14.815159,1.949609,-362.074951,294.500458,0.000000
124.010002,65.305939,-362.119415,-0.001005,0.007676,0.194961,290.495331,14.798536,1.949609,-362.119415,294.500458,0.000000
124.510002,65.183426,-362.163910,-0.001005,0.007676,0.194961,289.950348,14.770775,1.949609,-362.163910,294.500458,0.000000
125.010002,65.079910,-362.119415,-0.001009,0.007678,0.195031,289.489899,14.747318,1.950305,-362.119415,294.500458,0.000000
125.510010,65.303696,-362.208374,-0.001000,0.007680,0.195065,290.485352,14.798029,1.950650,-362.208374,294.500458,0.000000
126.010010,65.256409,-362.163910,-0.000992,0.007680,0.195074,290.274994,14.787313,1.950737,-362.163910,294.500458,0.000000
126.510010,65.144333,-362.208374,-0.001000,0.007680,0.195074,289.776459,14.761917,1.950737,-362.208374,294.500458,0.000000
127.010010,65.225128,-362.252869,-0.001000,0.007682,0.195135,290.135864,14.780226,1.951346,-362.252869,294.500458,0.000000
127.510010,65.211349,-362.297333,-0.001000,0.007683,0.195160,290.074585,14.777102,1.951604,-362.297333,294.500458,0.000000
128.010010,65.198700,-362.430786,-0.000992,0.007684,0.195178,290.018311,14.774237,1.951778,-362.430786,294.500458,0.000000
128.510010,65.219925,-362.386322,-0.000996,0.007685,0.195204,290.112701,14.779046,1.952039,-362.386322,294.500458,0.000000
129.010010,65.238159,-362.430786,-0.000983,0.007687,0.195247,290.193817,14.783178,1.952470,-362.430786,294.500458,0.000000
129.510010,65.254181,-362.430786,-0.000992,0.007687,0.195247,290.265106,14.786808,1.952470,-362.430786,294.500458,0.000000
130.010010,65.212463,-362.475281,-0.000992,0.007687,0.195256,290.079529,14.777355,1.952557,-362.475281,294.500458,0.000000
130.510010,65.199814,-362.475281,-0.000992,0.007688,0.195273,290.023254,14.774489,1.952731,-362.475281,294.500458,0.000000
131.010010,65.190872,-362.564240,-0.000992,0.007689,0.195299,289.983490,14.772463,1.952993,-362.564240,294.500458,0.000000
131.510010,65.248215,-362.608704,-0.000987,0.007690,0.195325,290.238556,14.785457,1.953254,-362.608704,294.500458,0.000000
132.010010,65.231827,-362.608704,-0.000996,0.007690,0.195334,290.165649,14.781743,1.953341,-362.608704,294.500458,0.000000
132.510010,65.217316,-362.608704,-0.000987,0.007690,0.195334,290.101105,14.778456,1.953341,-362.608704,294.500458,0.000000
133.010010,65.189377,-362.653198,-0.001000,0.007691,0.195342,289.976837,14.772124,1.953424,-362.653198,294.500458,0.000000
133.510010,65.205399,-362.697662,-0.000992,0.007692,0.195377,290.048096,14.775755,1.953772,-362.697662,294.500458,0.000000
134.010010,65.216568,-362.697662,-0.000983,0.007692,0.195377,290.097778,14.778286,1.953772,-362.697662,294.500458,0.000000
134.510010,65.172256,-362.742157,-0.000996,0.007692,0.195386,289.900665,14.768245,1.953859,-362.742157,294.500458,0.000000
135.010010,65.140228,-362.742157,-0.000983,0.007692,0.195386,289.758209,14.760986,1.953859,-362.742157,294.500458,0.000000
135.510010,65.109695,-362.786652,-0.000987,0.007692,0.195386,289.622375,14.754068,1.953859,-362.786652,294.500458,0.000000
136.010010,65.136871,-362.786652,-0.000983,0.007694,0.195438,289.743286,14.760226,1.954382,-362.786652,294.500458,0.000000
136.510010,65.164810,-362.831116,-0.000979,0.007694,0.195438,289.867554,14.766557,1.954382,-362.831116,294.500458,0.000000
137.010010,65.152512,-362.920074,-0.000987,0.007694,0.195438,289.812836,14.763770,1.954382,-362.920074,294.500458,0.000000
137.510010,65.138000,-362.920074,-0.000987,0.007695,0.195446,289.748291,14.760482,1.954465,-362.920074,294.500458,0.000000
138.010010,65.108948,-362.920074,-0.000970,0.007695,0.195464,289.619049,14.753899,1.954639,-362.920074,294.500458,0.000000
138.510010,65.084000,-362.964569,-0.000979,0.007695,0.195464,289.508087,14.748245,1.954639,-362.964569,294.500458,0.000000
139.010010,65.167786,-363.053528,-0.000979,0.007696,0.195490,289.880798,14.767232,1.954900,-363.053528,294.500458,0.000000
139.510010,65.159592,-363.053528,-0.000992,0.007696,0.195490,289.844330,14.765374,1.954900,-363.053528,294.500458,0.000000
140.010010,65.147675,-363.097992,-0.000987,0.007696,0.195490,289.791321,14.762674,1.954900,-363.097992,294.500458,0.000000
140.510010,65.111191,-363.097992,-0.000979,0.007696,0.195490,289.629028,14.754407,1.954900,-363.097992,294.500458,0.000000
141.010010,65.264969,-363.142487,-0.000992,0.007701,0.195594,290.313080,14.789253,1.955941,-363.142487,294.500458,0.000000
141.510010,65.369980,-363.186951,-0.000974,0.007701,0.195594,290.780182,14.813048,1.955941,-363.186951,294.500458,0.000000
142.010010,65.388596,-363.142487,-0.000974,0.007701,0.195594,290.863007,14.817267,1.955941,-363.142487,294.500458,0.000000
142.510010,65.378555,-363.231445,-0.000979,0.007701,0.195594,290.818329,14.814992,1.955941,-363.231445,294.500458,0.000000
143.010010,65.362534,-363.275940,-0.000987,0.007701,0.195594,290.747070,14.811362,1.955941,-363.275940,294.500458,0.000000
143.510010,65.337967,-363.320404,-0.000979,0.007701,0.195594,290.637787,14.805795,1.955941,-363.320404,294.500458,0.000000
144.010010,65.324921,-363.275940,-0.000983,0.007701,0.195594,290.579773,14.802838,1.955941,-363.275940,294.500458,0.000000
144.510010,65.303696,-363.364899,-0.000983,0.007701,0.195594,290.485352,14.798029,1.955941,-363.364899,294.500458,0.000000
145.010010,65.278381,-363.320404,-0.000992,0.007701,0.195594,290.372742,14.792293,1.955941,-363.320404,294.500458,0.000000
145.510010,65.274658,-363.409363,-0.000992,0.007701,0.195594,290.356171,14.791450,1.955941,-363.409363,294.500458,0.000000
146.010010,65.218063,-363.409363,-0.000979,0.007701,0.195603,290.104431,14.778625,1.956028,-363.409363,294.500458,0.000000
146.510010,65.221786,-363.498322,-0.000979,0.007701,0.195603,290.121002,14.779469,1.956028,-363.498322,294.500458,0.000000
147.010010,65.191620,-363.453857,-0.000987,0.007701,0.195612,289.986816,14.772633,1.956115,-363.453857,294.500458,0.000000
147.510010,65.196457,-363.542816,-0.000987,0.007701,0.195612,290.008331,14.773728,1.956115,-363.542816,294.500458,0.000000
148.010010,65.155502,-363.542816,-0.000979,0.007702,0.195620,289.826141,14.764448,1.956202,-363.542816,294.500458,0.000000
148.510010,65.149918,-363.587280,-0.000992,0.007702,0.195620,289.801300,14.763183,1.956202,-363.587280,294.500458,0.000000
149.010010,65.115280,-363.587280,-0.000987,0.007702,0.195629,289.647247,14.755334,1.956289,-363.587280,294.500458,0.000000
149.510010,65.165558,-363.676270,-0.000970,0.007703,0.195663,289.870880,14.766726,1.956634,-363.676270,294.500458,0.000000
150.010010,65.183426,-363.676270,-0.000987,0.007703,0.195663,289.950348,14.770775,1.956634,-363.676270,294.500458,0.000000
150.510010,65.186035,-363.676270,-0.000979,0.007703,0.195663,289.961975,14.771367,1.956634,-363.676270,294.500458,0.000000
151.010010,65.179703,-363.720734,-0.000970,0.007703,0.195663,289.933807,14.769932,1.956634,-363.720734,294.500458,0.000000
151.510010,65.156982,-363.720734,-0.000987,0.007704,0.195672,289.832733,14.764783,1.956721,-363.720734,294.500458,0.000000
152.010010,65.165558,-363.765228,-0.000979,0.007704,0.195681,289.870880,14.766726,1.956808,-363.765228,294.500458,0.000000
152.510010,65.158478,-363.809692,-0.000983,0.007704,0.195681,289.839386,14.765121,1.956808,-363.809692,294.500458,0.000000
153.010010,65.154373,-363.809692,-0.000987,0.007705,0.195698,289.821136,14.764193,1.956982,-363.809692,294.500458,0.000000
153.510010,65.161087,-363.809692,-0.000974,0.007705,0.195698,289.850983,14.765714,1.956982,-363.809692,294.500458,0.000000
154.010010,65.157730,-363.898651,-0.000983,0.007705,0.195698,289.836060,14.764953,1.956982,-363.898651,294.500458,0.000000
154.510010,65.138748,-363.898651,-0.000983,0.007705,0.195698,289.751617,14.760652,1.956982,-363.898651,294.500458,0.000000
155.010010,65.271301,-363.943146,-0.000979,0.007707,0.195767,290.341248,14.790689,1.957675,-363.943146,294.500458,0.000000
155.510010,65.310776,-363.943146,-0.000987,0.007707,0.195767,290.516846,14.799634,1.957675,-363.943146,294.500458,0.000000
156.010010,65.324554,-364.032104,-0.000979,0.007707,0.195767,290.578125,14.802755,1.957675,-364.032104,294.500458,0.000000
156.510010,65.305557,-363.987610,-0.000966,0.007707,0.195767,290.493622,14.798450,1.957675,-363.987610,294.500458,0.000000
157.010010,65.312271,-364.032104,-0.000970,0.007707,0.195767,290.523499,14.799972,1.957675,-364.032104,294.500458,0.000000
157.510010,65.302582,-364.076599,-0.000987,0.007707,0.195767,290.480377,14.797776,1.957675,-364.076599,294.500458,0.000000
158.010010,65.290665,-364.121063,-0.000974,0.007707,0.195767,290.427368,14.795076,1.957675,-364.121063,294.500458,0.000000
158.510010,65.280991,-364.210022,-0.000987,0.007707,0.195767,290.384338,14.792884,1.957675,-364.210022,294.500458,0.000000
159.010010,65.272415,-364.121063,-0.000979,0.007707,0.195767,290.346191,14.790941,1.957675,-364.121063,294.500458,0.000000
159.510010,65.262741,-364.165558,-0.000979,0.007707,0.195767,290.303162,14.788749,1.957675,-364.165558,294.500458,0.000000
160.010010,65.253433,-364.254517,-0.000966,0.007707,0.195767,290.261780,14.786639,1.957675,-364.254517,294.500458,0.000000
160.510010,65.231461,-364.298981,-0.000974,0.007707,0.195767,290.164032,14.781660,1.957675,-364.298981,294.500458,0.000000
161.010010,65.230713,-364.298981,-0.000983,0.007707,0.195767,290.160706,14.781491,1.957675,-364.298981,294.500458,0.000000
161.510010,65.212845,-364.298981,-0.000983,0.007707,0.195767,290.081207,14.777442,1.957675,-364.298981,294.500458,0.000000
162.010010,65.182678,-364.343475,-0.000979,0.007708,0.195785,289.947021,14.770606,1.957849,-364.343475,294.500458,0.000000
162.510010,65.199814,-364.432434,-0.000970,0.007708,0.195785,290.023254,14.774489,1.957849,-364.432434,294.500458,0.000000
163.010010,65.214325,-364.432434,-0.000974,0.007708,0.195785,290.087799,14.777778,1.957849,-364.432434,294.500458,0.000000
163.510010,65.197952,-364.476898,-0.000983,0.007708,0.195785,290.014984,14.774067,1.957849,-364.476898,294.500458,0.000000
164.010010,65.183792,-364.432434,-0.000970,0.007708,0.195785,289.951996,14.770859,1.957849,-364.432434,294.500458,0.000000
164.510010,65.156982,-364.476898,-0.000970,0.007708,0.195785,289.832733,14.764783,1.957849,-364.476898,294.500458,0.000000
165.010010,65.149918,-364.521393,-0.000983,0.007708,0.195794,289.801300,14.763183,1.957936,-364.521393,294.500458,0.000000
165.510010,65.143204,-364.521393,-0.000979,0.007709,0.195802,289.771454,14.761662,1.958023,-364.521393,294.500458,0.000000
166.010010,65.131287,-364.610352,-0.000979,0.007709,0.195802,289.718445,14.758961,1.958023,-364.610352,294.500458,0.000000
166.510010,65.119751,-364.565887,-0.000970,0.007709,0.195802,289.667114,14.756347,1.958023,-364.565887,294.500458,0.000000
167.010010,65.120117,-364.654846,-0.000983,0.007709,0.195802,289.668762,14.756430,1.958023,-364.654846,294.500458,0.000000
167.510010,65.101135,-364.654846,-0.000974,0.007709,0.195802,289.584320,14.752128,1.958023,-364.654846,294.500458,0.000000
168.010010,65.093307,-364.699310,-0.000974,0.007709,0.195802,289.549500,14.750354,1.958023,-364.699310,294.500458,0.000000
168.510010,65.073944,-364.743805,-0.000974,0.007709,0.195811,289.463348,14.745967,1.958110,-364.743805,294.500458,0.000000
169.010010,65.064636,-364.743805,-0.000974,0.007709,0.195811,289.421967,14.743857,1.958110,-364.743805,294.500458,0.000000
169.510010,65.051971,-364.832764,-0.000970,0.007709,0.195811,289.365631,14.740987,1.958110,-364.832764,294.500458,0.000000
170.010010,65.041550,-364.877228,-0.000961,0.007709,0.195811,289.319275,14.738626,1.958110,-364.877228,294.500458,0.000000
170.510010,65.043045,-364.832764,-0.000979,0.007709,0.195811,289.325928,14.738965,1.958110,-364.832764,294.500458,0.000000
171.010010,65.024048,-364.832764,-0.000970,0.007709,0.195811,289.241425,14.734660,1.958110,-364.832764,294.500458,0.000000
171.510010,65.015854,-365.010681,-0.000987,0.007709,0.195811,289.204956,14.732802,1.958110,-365.010681,294.500458,0.000000
172.010010,65.006546,-364.966217,-0.000983,0.007709,0.195811,289.163544,14.730694,1.958110,-364.966217,294.500458,0.000000
172.510010,65.088837,-364.921722,-0.000970,0.007711,0.195872,289.529602,14.749341,1.958715,-364.921722,294.500458,0.000000
173.010010,65.152145,-364.966217,-0.000983,0.007712,0.195889,289.811218,14.763687,1.958889,-364.966217,294.500458,0.000000
173.510010,65.172256,-365.010681,-0.000970,0.007712,0.195889,289.900665,14.768245,1.958889,-365.010681,294.500458,0.000000
174.010010,65.190506,-365.010681,-0.000961,0.007712,0.195889,289.981842,14.772380,1.958889,-365.010681,294.500458,0.000000
174.510010,65.181564,-365.055176,-0.000979,0.007712,0.195889,289.942078,14.770354,1.958889,-365.055176,294.500458,0.000000
175.010010,65.178207,-365.144135,-0.000974,0.007712,0.195889,289.927155,14.769593,1.958889,-365.144135,294.500458,0.000000
175.510010,65.173004,-365.099640,-0.000983,0.007712,0.195889,289.903992,14.768414,1.958889,-365.099640,294.500458,0.000000
176.010010,65.168533,-365.144135,-0.000966,0.007712,0.195889,289.884125,14.767401,1.958889,-365.144135,294.500458,0.000000
176.510010,65.166290,-365.144135,-0.000979,0.007712,0.195889,289.874146,14.766892,1.958889,-365.144135,294.500458,0.000000
177.010010,65.161453,-365.233093,-0.000966,0.007712,0.195889,289.852631,14.765797,1.958889,-365.233093,294.500458,0.000000
177.510010,65.152893,-365.188599,-0.000966,0.007712,0.195889,289.814545,14.763856,1.958889,-365.188599,294.500458,0.000000
178.010010,65.136505,-365.322052,-0.000961,0.007712,0.195889,289.741638,14.760143,1.958889,-365.322052,294.500458,0.000000
178.510010,65.129425,-365.322052,-0.000970,0.007712,0.195889,289.710144,14.758538,1.958889,-365.322052,294.500458,0.000000
179.010010,65.125702,-365.366547,-0.000974,0.007712,0.195889,289.693604,14.757695,1.958889,-365.366547,1681.640747,0.000000
179.510010,65.070221,-365.366547,-0.000966,0.007694,0.195438,289.446808,14.745123,1.954382,-365.366547,0.195169,0.000000
180.010010,65.012131,-365.455505,-0.000979,0.007664,0.194657,289.188416,14.731959,1.946573,-365.455505,0.194337,0.000000
180.510010,64.971176,-365.322052,-0.000974,0.007634,0.193912,289.006226,14.722679,1.939117,-365.322052,0.193504,0.000000
181.010010,64.917923,-365.411011,-0.000974,0.007607,0.193227,288.769348,14.710611,1.932266,-365.411011,0.192671,0.000000
181.510010,64.881058,-365.455505,-0.000966,0.007575,0.192403,288.605347,14.702257,1.924027,-365.455505,0.191839,0.000000
182.010010,64.907120,-365.499969,-0.000970,0.007545,0.191631,288.721283,14.708163,1.916309,-365.499969,0.191006,0.000000
182.510010,64.807709,-365.544464,-0.000970,0.007511,0.190781,288.279083,14.685637,1.907808,-365.544464,0.190174,0.000000
183.010010,64.708649,-365.544464,-0.000979,0.007487,0.190174,287.838440,14.663190,1.901737,-365.544464,0.189341,0.000000
183.510010,63.605316,-365.544464,-0.000953,0.007451,0.189246,282.930573,14.413171,1.892461,-365.544464,0.188509,0.000000
184.010010,61.967987,-365.633423,-0.000949,0.007417,0.188387,275.647369,14.042147,1.883873,-365.633423,0.187668,0.000000
184.510010,60.112831,-365.677887,-0.000931,0.007385,0.187589,267.395233,13.621762,1.875894,-365.677887,0.186835,0.000000
185.010010,58.312408,-365.722382,-0.000940,0.007356,0.186852,259.386536,13.213781,1.868525,-365.722382,0.186002,0.000000
185.510010,56.018967,-365.722382,-0.000931,0.007332,0.186228,249.184814,12.694079,1.862280,-365.722382,0.185170,0.000000
186.010010,52.644524,-365.722382,-0.000918,0.007295,0.185300,234.174530,11.929420,1.852999,-365.722382,0.184337,0.000000
186.510010,49.284981,-365.766846,-0.000936,0.007262,0.184450,219.230545,11.168136,1.844502,-365.766846,0.183505,0.000000
187.010010,45.878151,-365.811340,-0.000949,0.007231,0.183670,204.076202,10.396137,1.836698,-365.811340,0.182672,0.000000
187.510010,44.903275,-365.855835,-0.000936,0.007226,0.183531,199.739746,10.175227,1.835309,-365.855835,0.181840,0.000000
188.010010,38.515602,-365.855835,-0.000931,0.007162,0.181918,171.325958,8.727760,1.819178,-365.855835,0.181007,0.000000
188.510010,35.301651,-365.900299,-0.000923,0.007133,0.181181,157.029587,7.999469,1.811808,-365.900299,0.180175,0.000000
189.010010,31.876945,-365.900299,-0.000936,0.007104,0.180435,141.795731,7.223419,1.804348,-365.900299,0.179333,0.000000
189.510010,28.115982,-365.944794,-0.000927,0.007066,0.179472,125.066132,6.371173,1.794723,-365.944794,0.178501,0.000000
190.010010,24.978745,-365.944794,-0.000931,0.007041,0.178831,111.111008,5.660264,1.788308,-365.944794,0.177668,0.000000
190.510010,20.777634,-365.989258,-0.000923,0.007003,0.177868,92.423531,4.708279,1.778679,-365.989258,0.176836,0.000000
191.010010,17.226318,-366.033752,-0.000936,0.006971,0.177070,76.626488,3.903539,1.770701,-366.033752,0.176003,0.000000
191.510010,13.421043,-366.033752,-0.000923,0.006937,0.176203,59.699783,3.041252,1.762029,-366.033752,0.175171,0.000000
192.010010,10.121452,-366.033752,-0.000931,0.006905,0.175388,45.022469,2.293554,1.753877,-366.033752,0.174339,0.000000
192.510010,6.506462,-366.078217,-0.000923,0.006873,0.174581,28.942188,1.474385,1.745811,-366.078217,0.173506,0.000000
193.010010,3.072441,-366.122711,-0.000940,0.006840,0.173740,13.666901,0.696225,1.737401,-366.122711,0.172673,0.000000
193.510010,0.356361,-366.078217,-0.000940,0.006814,0.173072,1.585175,0.080753,1.730721,-366.078217,0.171841,0.000000
194.010010,0.049149,-366.122711,-0.000931,0.006775,0.172092,0.218624,0.011137,1.720922,-366.122711,0.170999,0.000000
194.510010,0.180229,-366.211670,-0.000927,0.006741,0.171234,0.801699,0.040841,1.712338,-366.211670,0.170167,0.000000
195.010010,0.147461,-366.256165,-0.000905,0.006706,0.170323,0.655939,0.033415,1.703231,-366.256165,0.169335,0.000000
195.510010,0.141129,-366.211670,-0.000880,0.006679,0.169647,0.627771,0.031980,1.696468,-366.211670,0.168502,0.000000
196.010010,0.069260,-366.300629,-0.000910,0.006636,0.168545,0.308082,0.015694,1.685453,-366.300629,0.167670,0.000000
196.510010,0.047661,-366.300629,-0.000949,0.006603,0.167704,0.212006,0.010800,1.677040,-366.300629,0.166837,0.000000
197.010010,0.042076,-366.345123,-0.000979,0.006575,0.166993,0.187164,0.009535,1.669932,-366.345123,0.166004,0.000000
197.510010,0.035370,-366.345123,-0.000987,0.006551,0.166395,0.157333,0.008015,1.663948,-366.345123,0.165172,0.000000
198.010010,0.006325,-366.434082,-0.001039,0.006508,0.165293,0.028134,0.001433,1.652934,-366.434082,0.164339,0.000000
198.510010,0.029419,-366.434082,-0.001069,0.006475,0.164461,0.130862,0.006666,1.644607,-366.434082,0.163507,0.000000
199.010010,0.011917,-366.478546,-0.001104,0.006447,0.163750,0.053010,0.002700,1.637495,-366.478546,0.162674,0.000000
199.510010,0.015266,-366.567505,-0.001134,0.006416,0.162978,0.067908,0.003459,1.629778,-366.567505,0.161833,0.000000
200.010010,0.001114,-366.523041,-0.001168,0.006379,0.162015,0.004955,0.000252,1.620153,-366.523041,0.161001,0.000000
200.510010,0.020103,-366.523041,-0.001203,0.006353,0.161373,0.089425,0.004556,1.613734,-366.523041,0.160168,0.000000
201.010010,-0.010429,-366.567505,-0.001246,0.006312,0.160324,-0.046392,-0.002363,1.603242,-366.567505,0.159336,0.000000
201.510010,0.017128,-366.612000,-0.001276,0.006275,0.159379,0.076189,0.003881,1.593787,-366.612000,0.158503,0.000000
202.010010,0.015640,-366.656494,-0.001319,0.006242,0.158546,0.069571,0.003544,1.585460,-366.656494,0.157670,0.000000
202.510010,0.026810,-366.700958,-0.001354,0.006212,0.157774,0.119255,0.006075,1.577743,-366.700958,0.156838,0.000000
203.010010,0.006325,-366.700958,-0.001367,0.006189,0.157202,0.028134,0.001433,1.572020,-366.700958,0.156005,0.000000
203.510010,0.022713,-366.656494,-0.001410,0.006160,0.156465,0.101031,0.005147,1.564647,-366.656494,0.155173,0.000000
204.010010,0.016754,-366.745453,-0.001444,0.006116,0.155346,0.074526,0.003797,1.553463,-366.745453,0.154340,0.000000
204.510010,0.060692,-366.745453,-0.001475,0.006084,0.154540,0.269971,0.013753,1.545397,-366.745453,0.153499,0.000000
205.010010,0.033508,-366.789917,-0.001513,0.006050,0.153672,0.149052,0.007593,1.536722,-366.789917,0.152667,0.000000
205.510010,0.027924,-366.834412,-0.001552,0.006016,0.152814,0.124210,0.006328,1.528138,-366.834412,0.151834,0.000000
206.010010,0.065163,-366.923370,-0.001591,0.005983,0.151973,0.289858,0.014766,1.519728,-366.923370,0.151001,0.000000
206.510010,0.060692,-366.878876,-0.001600,0.005953,0.151209,0.269971,0.013753,1.512094,-366.878876,0.150169,0.000000
207.010010,0.057716,-366.878876,-0.001660,0.005916,0.150264,0.256735,0.013079,1.502643,-366.878876,0.149336,0.000000
207.510010,0.035744,-366.923370,-0.001677,0.005884,0.149449,0.158996,0.008100,1.494490,-366.923370,0.148504,0.000000
208.010010,0.042824,-366.967834,-0.001729,0.005855,0.148729,0.190490,0.009704,1.487291,-366.967834,0.147671,0.000000
208.510010,0.038727,-367.012329,-0.001733,0.005826,0.147992,0.172265,0.008776,1.479922,-367.012329,0.146839,0.000000
208.800003,0.038353,-366.967834,-0.001768,0.005808,0.147515,0.170603,0.008691,1.475150,-366.967834,0.147420,0.000000