File: Data/compression 17/ManualNoHeating-10-17-reverse-hand-2-1_09062024_170642.csv
Time (sec),S:Load (lbs),S:HL1 (DIM),S:LVDT (in),S:Position (in),Ch:Position (mm),Ch:Load (N),Ch:Stress (MPa),Ch:Strain (mm/mm),Ch:HL1 (DIM),Set Point (),Cycles ()
0.110000,0.026062,-340.056885,-0.009848,-0.004875,-0.123814,0.115930,0.005906,-1.238139,-340.056885,-0.123606,0.000000
0.580000,0.039467,-340.056885,-0.009826,-0.004786,-0.121559,0.175557,0.008943,-1.215591,-340.056885,-0.120813,0.000000
1.050000,0.049522,-340.101349,-0.009636,-0.004493,-0.114118,0.220287,0.011222,-1.141184,-340.101349,-0.112974,0.000000
1.520000,-0.002235,-340.056885,-0.009321,-0.004199,-0.106660,-0.009944,-0.000507,-1.066602,-340.056885,-0.105151,0.000000
1.990000,0.016754,-340.101349,-0.008994,-0.003883,-0.098638,0.074526,0.003797,-0.986383,-340.101349,-0.097312,0.000000
2.460000,0.024574,-340.190308,-0.008683,-0.003571,-0.090712,0.109312,0.005569,-0.907118,-340.190308,-0.089489,0.000000
2.930000,0.042824,-340.190308,-0.008364,-0.003265,-0.082933,0.190490,0.009704,-0.829329,-340.190308,-0.081649,0.000000
3.400000,0.016380,-340.190308,-0.008050,-0.002957,-0.075119,0.072863,0.003712,-0.751192,-340.190308,-0.073827,0.000000
3.870000,0.036865,-340.279266,-0.007731,-0.002646,-0.067201,0.163985,0.008354,-0.672014,-340.279266,-0.066005,0.000000
4.340000,0.045052,-340.323761,-0.007407,-0.002337,-0.059362,0.200399,0.010209,-0.593617,-340.323761,-0.058165,0.000000
4.810000,0.028671,-340.323761,-0.007084,-0.002026,-0.051470,0.127536,0.006497,-0.514698,-340.323761,-0.050343,0.000000
5.280000,0.039841,-340.323761,-0.006778,-0.001719,-0.043665,0.177220,0.009028,-0.436648,-340.323761,-0.042503,0.000000
5.750000,0.002235,-340.323761,-0.006459,-0.001417,-0.035990,0.009944,0.000507,-0.359900,-340.323761,-0.034680,0.000000
6.220000,0.052872,-340.368225,-0.006170,-0.001109,-0.028176,0.235185,0.011981,-0.281763,-340.368225,-0.026841,0.000000
6.690001,0.045799,-340.457214,-0.005838,-0.000793,-0.020154,0.203725,0.010378,-0.201544,-340.457214,-0.019018,0.000000
7.160000,0.055855,-340.546173,-0.005523,-0.000488,-0.012384,0.248455,0.012657,-0.123840,-340.546173,-0.011179,0.000000
7.630001,0.047287,-340.457214,-0.005195,-0.000178,-0.004527,0.210343,0.010715,-0.045269,-340.457214,-0.003356,0.000000
8.100000,0.078568,-340.501678,-0.004984,-0.000000,-0.000000,0.349486,0.017804,-0.000000,-340.501678,0.000243,0.000000
8.570001,0.151550,-340.457214,-0.004993,-0.000000,-0.000000,0.674129,0.034342,-0.000000,-340.457214,0.000373,0.000000
9.040000,0.141502,-340.590637,-0.004997,0.000000,0.000009,0.629434,0.032065,0.000087,-340.590637,0.001153,0.000000
9.510000,0.210014,-340.590637,-0.004963,0.000043,0.001084,0.934190,0.047590,0.010840,-340.590637,0.001934,0.000000
9.980000,0.297150,-340.590637,-0.004937,0.000069,0.001743,1.321788,0.067335,0.017431,-340.590637,0.002723,0.000000
10.450001,0.401413,-340.635132,-0.004907,0.000099,0.002524,1.785574,0.090961,0.025236,-340.635132,0.003503,0.000000
10.920000,0.602127,-340.590637,-0.004876,0.000128,0.003261,2.678395,0.136444,0.032607,-340.590637,0.004284,0.000000
11.390000,0.831505,-340.768555,-0.004846,0.000160,0.004067,3.698718,0.188422,0.040672,-340.768555,0.005073,0.000000
11.860001,1.059395,-340.813049,-0.004816,0.000193,0.004891,4.712424,0.240062,0.048910,-340.813049,0.005854,0.000000
12.330001,1.230316,-340.768555,-0.004799,0.000222,0.005628,5.472720,0.278794,0.056283,-340.768555,0.006634,0.000000
12.800000,1.514809,-340.724091,-0.004773,0.000251,0.006365,6.738205,0.343261,0.063654,-340.724091,0.007424,0.000000
13.270000,1.805260,-340.813049,-0.004747,0.000280,0.007111,8.030196,0.409078,0.071112,-340.813049,0.008204,0.000000
13.740001,2.072624,-340.857513,-0.004708,0.000316,0.008022,9.219493,0.469663,0.080219,-340.857513,0.008984,0.000000
14.210001,2.358604,-340.857513,-0.004682,0.000347,0.008802,10.491596,0.534467,0.088023,-340.857513,0.009774,0.000000
14.680000,2.713104,-340.813049,-0.004648,0.000380,0.009661,12.068490,0.614798,0.096609,-340.813049,0.010554,0.000000
15.150001,2.913437,-340.902008,-0.004631,0.000405,0.010277,12.959615,0.660194,0.102766,-340.902008,0.011335,0.000000
15.620001,3.250435,-340.902008,-0.004605,0.000438,0.011126,14.458656,0.736559,0.111265,-340.902008,0.012124,0.000000
16.090000,3.439606,-341.035461,-0.004570,0.000468,0.011890,15.300130,0.779426,0.118897,-341.035461,0.012904,0.000000
16.560001,3.751282,-341.035461,-0.004536,0.000499,0.012670,16.686535,0.850053,0.126701,-341.035461,0.013685,0.000000
17.030001,3.915497,-341.035461,-0.004510,0.000525,0.013346,17.417000,0.887264,0.133465,-341.035461,0.014474,0.000000
17.500000,4.371277,-341.035461,-0.004480,0.000563,0.014292,19.444410,0.990545,0.142918,-341.035461,0.015254,0.000000
17.970001,4.602524,-341.079926,-0.004449,0.000595,0.015107,20.473049,1.042947,0.151070,-341.079926,0.016035,0.000000
18.440001,4.765251,-341.168884,-0.004415,0.000621,0.015775,21.196896,1.079821,0.157749,-341.168884,0.016824,0.000000
18.910002,5.159218,-341.124420,-0.004376,0.000652,0.016555,22.949347,1.169095,0.165553,-341.124420,0.017605,0.000000
19.380001,5.621704,-341.124420,-0.004355,0.000689,0.017509,25.006588,1.273896,0.175093,-341.124420,0.018385,0.000000
19.850000,5.727829,-341.213379,-0.004324,0.000719,0.018255,25.478655,1.297945,0.182551,-341.213379,0.019174,0.000000
20.320002,5.914391,-341.257843,-0.004299,0.000748,0.019001,26.308523,1.340220,0.190009,-341.257843,0.019955,0.000000
20.790001,6.080093,-341.302338,-0.004277,0.000775,0.019677,27.045607,1.377769,0.196773,-341.302338,0.020735,0.000000
21.260000,6.477791,-341.346832,-0.004234,0.000806,0.020475,28.814653,1.467888,0.204751,-341.346832,0.021525,0.000000
21.730001,6.676262,-341.346832,-0.004221,0.000834,0.021178,29.697496,1.512863,0.211776,-341.346832,0.022305,0.000000
22.200001,6.835266,-341.257843,-0.004186,0.000862,0.021906,30.404781,1.548893,0.219060,-341.257843,0.023086,0.000000
22.670002,7.145454,-341.480255,-0.004143,0.000896,0.022747,31.784569,1.619183,0.227472,-341.480255,0.023875,0.000000
23.140001,7.382652,-341.435791,-0.004118,0.000927,0.023537,32.839676,1.672933,0.235366,-341.435791,0.024655,0.000000
23.610001,7.680550,-341.391296,-0.004092,0.000960,0.024395,34.164791,1.740437,0.243950,-341.391296,0.025436,0.000000
24.080002,7.852585,-341.480255,-0.004057,0.000988,0.025089,34.930042,1.779421,0.250887,-341.480255,0.026225,0.000000
24.550001,8.081970,-341.480255,-0.004031,0.001021,0.025939,35.950397,1.831401,0.259386,-341.480255,0.027005,0.000000
25.020000,8.477798,-341.569214,-0.004001,0.001059,0.026893,37.711132,1.921097,0.268926,-341.569214,0.027786,0.000000
25.490002,8.654678,-341.569214,-0.003958,0.001086,0.027595,38.497932,1.961178,0.275951,-341.569214,0.028575,0.000000
25.960001,8.600685,-341.613708,-0.003945,0.001111,0.028211,38.257759,1.948943,0.282109,-341.613708,0.029356,0.000000
26.430000,9.030777,-341.613708,-0.003915,0.001142,0.029017,40.170902,2.046403,0.290173,-341.613708,0.030136,0.000000
26.900002,9.272820,-341.702667,-0.003885,0.001173,0.029789,41.247562,2.101251,0.297892,-341.702667,0.030925,0.000000
27.370001,9.546509,-341.658173,-0.003846,0.001209,0.030708,42.464993,2.163270,0.307084,-341.658173,0.031706,0.000000
27.840002,9.553589,-341.747162,-0.003824,0.001235,0.031359,42.496487,2.164874,0.313588,-341.747162,0.032486,0.000000
28.310001,9.831749,-341.747162,-0.003794,0.001265,0.032122,43.733803,2.227906,0.321220,-341.747162,0.033275,0.000000
28.780001,10.531433,-341.791626,-0.003764,0.001304,0.033111,46.846153,2.386457,0.331106,-341.791626,0.034056,0.000000
29.250002,10.221252,-341.791626,-0.003729,0.001330,0.033770,45.466400,2.316169,0.337698,-341.791626,0.034836,0.000000
29.720001,10.479301,-341.836121,-0.003695,0.001360,0.034550,46.614262,2.374644,0.345502,-341.836121,0.035626,0.000000
30.190001,10.727676,-341.836121,-0.003669,0.001391,0.035339,47.719090,2.430926,0.353394,-341.836121,0.036406,0.000000
30.660002,10.893379,-341.836121,-0.003639,0.001423,0.036155,48.456169,2.468475,0.361546,-341.836121,0.037187,0.000000
31.130001,11.094093,-341.880585,-0.003600,0.001459,0.037057,49.348991,2.513958,0.370566,-341.880585,0.037976,0.000000
31.600002,11.155907,-341.969543,-0.003579,0.001488,0.037802,49.623951,2.527965,0.378024,-341.969543,0.038756,0.000000
32.070000,11.404648,-342.014038,-0.003548,0.001519,0.038574,50.730408,2.584330,0.385741,-342.014038,0.039537,0.000000
32.540001,11.504814,-342.014038,-0.003514,0.001547,0.039303,51.175968,2.607028,0.393027,-342.014038,0.040326,0.000000
33.010002,11.775162,-341.969543,-0.003484,0.001579,0.040118,52.378536,2.668290,0.401178,-341.969543,0.041106,0.000000
33.480003,11.915543,-342.058502,-0.003462,0.001612,0.040933,53.002979,2.700101,0.409331,-342.058502,0.041887,0.000000
33.950001,12.187752,-342.014038,-0.003436,0.001642,0.041714,54.213829,2.761784,0.417135,-342.014038,0.042676,0.000000
34.420002,12.081619,-342.147461,-0.003410,0.001668,0.042355,53.741726,2.737734,0.423552,-342.147461,0.043457,0.000000
34.890003,12.560120,-342.191956,-0.003389,0.001705,0.043301,55.870201,2.846164,0.433005,-342.191956,0.044237,0.000000
35.360001,12.467773,-342.147461,-0.003350,0.001733,0.044029,55.459427,2.825238,0.440289,-342.147461,0.045026,0.000000
35.830002,12.546341,-342.147461,-0.003337,0.001765,0.044835,55.808910,2.843042,0.448355,-342.147461,0.045807,0.000000
36.300003,12.582832,-342.147461,-0.003303,0.001790,0.045469,55.971233,2.851311,0.454687,-342.147461,0.046587,0.000000
36.770000,12.812592,-342.280914,-0.003268,0.001821,0.046258,56.993252,2.903375,0.462579,-342.280914,0.047376,0.000000
37.240002,13.343590,-342.236450,-0.003251,0.001857,0.047168,59.355251,3.023701,0.471683,-342.236450,0.048157,0.000000
37.710003,13.250504,-342.280914,-0.003208,0.001884,0.047854,58.941185,3.002607,0.478536,-342.280914,0.048938,0.000000
38.180000,13.522705,-342.280914,-0.003191,0.001917,0.048695,60.151997,3.064289,0.486948,-342.280914,0.049727,0.000000
38.650002,13.827675,-342.369873,-0.003156,0.001950,0.049519,61.508572,3.133396,0.495185,-342.369873,0.050507,0.000000
39.120003,14.070839,-342.414368,-0.003122,0.001983,0.050368,62.590218,3.188498,0.503684,-342.414368,0.051288,0.000000
39.590000,13.981094,-342.414368,-0.003109,0.002010,0.051054,62.191013,3.168161,0.510535,-342.414368,0.052077,0.000000
40.060001,14.223511,-342.369873,-0.003091,0.002040,0.051825,63.269337,3.223094,0.518252,-342.369873,0.052857,0.000000
40.530003,14.528107,-342.458832,-0.003070,0.002070,0.052580,64.624245,3.292116,0.525800,-342.458832,0.053638,0.000000
41.000004,14.709457,-342.503326,-0.003035,0.002105,0.053456,65.430931,3.333211,0.534558,-342.503326,0.054427,0.000000
41.470001,14.596252,-342.503326,-0.003001,0.002133,0.054184,64.927376,3.307558,0.541844,-342.503326,0.055207,0.000000
41.940002,15.050545,-342.547791,-0.002992,0.002169,0.055086,66.948166,3.410502,0.550863,-342.547791,0.055988,0.000000
42.410004,14.774994,-342.503326,-0.002958,0.002190,0.055632,65.722458,3.348062,0.556325,-342.503326,0.056777,0.000000
42.880001,15.244553,-342.547791,-0.002940,0.002227,0.056561,67.811157,3.454465,0.565605,-342.547791,0.057558,0.000000
43.350002,15.193169,-342.681244,-0.002932,0.002253,0.057219,67.582588,3.442821,0.572195,-342.681244,0.058338,0.000000
43.820004,15.549896,-342.681244,-0.002897,0.002287,0.058087,69.169395,3.523657,0.580866,-342.681244,0.059127,0.000000
44.290001,15.383080,-342.681244,-0.002884,0.002314,0.058780,68.427353,3.485856,0.587804,-342.681244,0.059908,0.000000
44.760002,15.581177,-342.725739,-0.002867,0.002349,0.059657,69.308533,3.530745,0.596566,-342.725739,0.060688,0.000000
45.230003,15.500748,-342.681244,-0.002854,0.002379,0.060428,68.950768,3.512520,0.604283,-342.681244,0.061477,0.000000
45.700001,15.787849,-342.770203,-0.002833,0.002413,0.061278,70.227859,3.577578,0.612780,-342.770203,0.062258,0.000000
46.170002,15.544312,-342.770203,-0.002815,0.002442,0.062033,69.144554,3.522392,0.620327,-342.770203,0.063039,0.000000
46.640003,15.372650,-342.814697,-0.002798,0.002476,0.062882,68.380966,3.483492,0.628824,-342.814697,0.063828,0.000000
47.110001,15.171196,-342.859161,-0.002772,0.002504,0.063594,67.484848,3.437842,0.635936,-342.859161,0.064608,0.000000
47.580002,15.013687,-342.903656,-0.002772,0.002529,0.064236,66.784218,3.402150,0.642355,-342.903656,0.065389,0.000000
48.050003,14.771271,-342.859161,-0.002751,0.002554,0.064860,65.705894,3.347218,0.648597,-342.859161,0.066178,0.000000
48.520000,15.301155,-342.903656,-0.002742,0.002596,0.065927,68.062935,3.467291,0.659266,-342.903656,0.066958,0.000000
48.990002,15.027832,-342.903656,-0.002734,0.002626,0.066707,66.847137,3.405355,0.667071,-342.903656,0.067739,0.000000
49.460003,14.808510,-342.992615,-0.002721,0.002651,0.067331,65.871544,3.355656,0.673312,-342.992615,0.068528,0.000000
49.930004,14.373947,-343.126068,-0.002712,0.002669,0.067782,63.938511,3.257183,0.677824,-343.126068,0.069309,0.000000
50.400002,15.285141,-343.037109,-0.002682,0.002716,0.068988,67.991699,3.463662,0.689878,-343.037109,0.070089,0.000000
50.870003,15.161888,-343.126068,-0.002660,0.002744,0.069690,67.443443,3.435733,0.696903,-343.126068,0.070878,0.000000
51.340004,15.550270,-343.081573,-0.002656,0.002780,0.070609,69.171059,3.523742,0.706093,-343.081573,0.071659,0.000000
51.810001,15.784492,-343.170532,-0.002634,0.002812,0.071433,70.212929,3.576817,0.714333,-343.170532,0.072439,0.000000
52.280003,16.135643,-343.215027,-0.002613,0.002846,0.072300,71.774925,3.656389,0.723004,-343.215027,0.073228,0.000000
52.750004,16.166924,-343.215027,-0.002591,0.002877,0.073081,71.914070,3.663477,0.730812,-343.215027,0.074009,0.000000
53.220001,16.147560,-343.215027,-0.002583,0.002906,0.073801,71.827934,3.659089,0.738007,-343.215027,0.074789,0.000000
53.690002,16.478966,-343.215027,-0.002544,0.002934,0.074521,73.302101,3.734187,0.745206,-343.215027,0.075579,0.000000
54.160004,16.985771,-343.303986,-0.002539,0.002968,0.075379,75.556480,3.849031,0.753794,-343.303986,0.076359,0.000000
54.630001,16.648026,-343.348450,-0.002518,0.002992,0.076004,74.054115,3.772496,0.760035,-343.348450,0.077140,0.000000
55.100002,16.608185,-343.348450,-0.002496,0.003021,0.076723,73.876892,3.763468,0.767234,-343.348450,0.077929,0.000000
55.570004,17.062477,-343.348450,-0.002479,0.003057,0.077660,75.897690,3.866413,0.776602,-343.348450,0.078709,0.000000
56.040001,17.233025,-343.392944,-0.002462,0.003087,0.078415,76.656319,3.905059,0.784145,-343.392944,0.079490,0.000000
56.510002,17.564438,-343.481903,-0.002458,0.003122,0.079308,78.130524,3.980159,0.793077,-343.481903,0.080279,0.000000
56.980003,17.149239,-343.481903,-0.002419,0.003149,0.079984,76.283623,3.886073,0.799841,-343.481903,0.081059,0.000000
57.450005,17.541351,-343.526398,-0.002384,0.003183,0.080860,78.027824,3.974927,0.808599,-343.526398,0.081840,0.000000
57.920002,17.088539,-343.526398,-0.002380,0.003204,0.081380,76.013618,3.872319,0.813803,-343.526398,0.082629,0.000000
58.390003,17.363350,-343.526398,-0.002358,0.003242,0.082343,77.236038,3.934591,0.823432,-343.526398,0.083410,0.000000
58.860004,17.564804,-343.526398,-0.002341,0.003272,0.083106,78.132149,3.980242,0.831063,-343.526398,0.084190,0.000000
59.330002,17.921539,-343.615356,-0.002302,0.003307,0.083999,79.718987,4.061079,0.839995,-343.615356,0.084979,0.000000
59.800003,17.428146,-343.615356,-0.002289,0.003333,0.084667,77.524269,3.949275,0.846672,-343.615356,0.085760,0.000000
60.270004,18.080544,-343.615356,-0.002264,0.003370,0.085604,80.426277,4.097110,0.856039,-343.615356,0.086540,0.000000
60.740002,17.958031,-343.704315,-0.002255,0.003400,0.086350,79.881310,4.069348,0.863495,-343.704315,0.087329,0.000000
61.210003,17.966972,-343.704315,-0.002238,0.003426,0.087018,79.921082,4.071374,0.870176,-343.704315,0.088110,0.000000
61.680004,18.168793,-343.793274,-0.002199,0.003455,0.087746,80.818825,4.117107,0.877458,-343.793274,0.088891,0.000000
62.150002,19.012589,-343.704315,-0.002177,0.003494,0.088743,84.572220,4.308314,0.887431,-343.704315,0.089680,0.000000
62.620003,19.187981,-343.793274,-0.002164,0.003524,0.089498,85.352402,4.348058,0.894978,-343.793274,0.090460,0.000000
63.090004,19.538757,-343.882233,-0.002143,0.003556,0.090313,86.912735,4.427546,0.903127,-343.882233,0.091241,0.000000
63.560001,19.841866,-343.926727,-0.002121,0.003582,0.090981,88.261024,4.496231,0.909807,-343.926727,0.092030,0.000000
64.030006,20.689011,-343.837738,-0.002113,0.003612,0.091735,92.029312,4.688197,0.917351,-343.837738,0.092810,0.000000
64.500000,21.211075,-343.882233,-0.002082,0.003644,0.092559,94.351570,4.806499,0.925590,-343.882233,0.093591,0.000000
64.970001,22.150948,-343.926727,-0.002061,0.003679,0.093444,98.532333,5.019476,0.934436,-343.926727,0.094380,0.000000
65.440002,22.409370,-343.971191,-0.002035,0.003706,0.094129,99.681862,5.078036,0.941286,-343.971191,0.095161,0.000000
65.910004,23.414032,-343.971191,-0.002013,0.003740,0.095004,104.150818,5.305696,0.950045,-343.971191,0.095941,0.000000
66.380005,23.371582,-344.015686,-0.001992,0.003766,0.095655,103.961990,5.296076,0.956551,-344.015686,0.096730,0.000000
66.850006,23.991959,-344.015686,-0.001983,0.003796,0.096409,106.721565,5.436656,0.964094,-344.015686,0.097511,0.000000
67.320000,25.090828,-344.104645,-0.001944,0.003827,0.097199,111.609573,5.685663,0.971986,-344.104645,0.098291,0.000000
67.790001,26.480522,-344.104645,-0.001927,0.003864,0.098144,117.791245,6.000572,0.981440,-344.104645,0.099080,0.000000
68.260002,26.926254,-344.149109,-0.001897,0.003893,0.098890,119.773964,6.101576,0.988897,-344.149109,0.099861,0.000000
68.730003,27.122864,-344.149109,-0.001880,0.003914,0.099419,120.648521,6.146129,0.994188,-344.149109,0.100642,0.000000
69.200005,28.812691,-344.238068,-0.001863,0.003949,0.100295,128.165253,6.529049,1.002946,-344.238068,0.101431,0.000000
69.670006,30.022530,-344.327057,-0.001828,0.003982,0.101144,133.546875,6.803203,1.011443,-344.327057,0.102211,0.000000
70.140007,31.110229,-344.282562,-0.001819,0.004013,0.101925,138.385208,7.049679,1.019251,-344.282562,0.102992,0.000000
70.610001,32.012115,-344.282562,-0.001798,0.004039,0.102584,142.397003,7.254049,1.025841,-344.282562,0.103781,0.000000
71.080002,33.152687,-344.282562,-0.001763,0.004066,0.103278,147.470520,7.512506,1.032779,-344.282562,0.104561,0.000000
71.550003,35.679985,-344.371521,-0.001763,0.004109,0.104362,158.712494,8.085200,1.043619,-344.371521,0.105342,0.000000
72.020004,36.365517,-344.371521,-0.001738,0.004133,0.104978,161.761902,8.240544,1.049777,-344.371521,0.106131,0.000000
72.490005,37.945122,-344.416016,-0.001720,0.004166,0.105827,168.788330,8.598488,1.058274,-344.416016,0.106912,0.000000
72.960007,39.609261,-344.416016,-0.001703,0.004199,0.106651,176.190796,8.975587,1.066513,-344.416016,0.107692,0.000000
73.430000,41.433136,-344.416016,-0.001694,0.004233,0.107510,184.303787,9.388883,1.075098,-344.416016,0.108481,0.000000
73.900002,42.810173,-344.460480,-0.001677,0.004263,0.108282,190.429153,9.700924,1.082819,-344.460480,0.109262,0.000000
74.370003,44.359612,-344.504974,-0.001656,0.004292,0.109027,197.321411,10.052032,1.090275,-344.504974,0.110042,0.000000
74.840004,46.037895,-344.549438,-0.001638,0.004321,0.109765,204.786789,10.432336,1.097648,-344.549438,0.110831,0.000000
75.310005,47.956360,-344.593933,-0.001617,0.004354,0.110597,213.320541,10.867066,1.105971,-344.593933,0.111612,0.000000
75.780006,49.970520,-344.593933,-0.001595,0.004385,0.111387,222.279968,11.323483,1.113866,-344.593933,0.112392,0.000000
76.250000,51.733704,-344.682892,-0.001595,0.004413,0.112097,230.123001,11.723025,1.120974,-344.682892,0.113181,0.000000
76.720001,53.895699,-344.727356,-0.001569,0.004445,0.112895,239.740036,12.212939,1.128953,-344.727356,0.113962,0.000000
77.190002,55.607864,-344.771851,-0.001565,0.004474,0.113633,247.356140,12.600922,1.136326,-344.771851,0.114743,0.000000
77.660004,58.357468,-344.771851,-0.001548,0.004508,0.114508,259.586975,13.223991,1.145084,-344.771851,0.115532,0.000000
78.130005,60.255447,-344.727356,-0.001544,0.004538,0.115254,268.029602,13.654079,1.152544,-344.727356,0.116312,0.000000
78.600006,62.786835,-344.816345,-0.001535,0.004571,0.116095,279.289795,14.227700,1.160954,-344.816345,0.117093,0.000000
79.070007,64.671783,-344.860809,-0.001522,0.004597,0.116763,287.674469,14.654836,1.167631,-344.860809,0.117882,0.000000
79.540001,66.665833,-344.860809,-0.001500,0.004616,0.117257,296.544434,15.106693,1.172574,-344.860809,0.117474,0.000000
80.010002,65.752777,-344.905304,-0.001483,0.004616,0.117249,292.482971,14.899792,1.172490,-344.905304,294.500458,0.000000
80.480003,65.026657,-344.860809,-0.001479,0.004617,0.117266,289.253021,14.735251,1.172661,-344.860809,294.500458,0.000000
80.950005,65.445572,-344.949768,-0.001487,0.004628,0.117544,291.116455,14.830179,1.175439,-344.949768,294.500458,0.000000
81.420006,65.062027,-344.994263,-0.001483,0.004628,0.117544,289.410339,14.743266,1.175439,-344.994263,294.500458,0.000000
81.890007,64.748123,-344.994263,-0.001466,0.004628,0.117544,288.014038,14.672134,1.175439,-344.994263,294.500458,0.000000
82.360001,64.440918,-344.994263,-0.001479,0.004628,0.117553,286.647522,14.602521,1.175526,-344.994263,294.500458,0.000000
82.830002,66.571259,-345.038727,-0.001462,0.004566,0.115974,296.123749,15.085263,1.159739,-345.038727,294.500458,0.000000
83.300003,66.274841,-345.083221,-0.001462,0.004566,0.115974,294.805206,15.018094,1.159739,-345.083221,294.500458,0.000000
83.770004,66.019028,-345.172180,-0.001444,0.004566,0.115974,293.667297,14.960125,1.159739,-345.172180,294.500458,0.000000
84.240005,65.832474,-345.083221,-0.001453,0.004566,0.115983,292.837463,14.917851,1.159826,-345.083221,294.500458,0.000000
84.710007,65.596756,-345.172180,-0.001457,0.004598,0.116798,291.788940,14.864437,1.167979,-345.172180,294.500458,0.000000
85.180000,65.452652,-345.172180,-0.001444,0.004602,0.116893,291.147949,14.831783,1.168933,-345.172180,294.500458,0.000000
85.650002,65.309662,-345.261139,-0.001444,0.004612,0.117154,290.511871,14.799381,1.171537,-345.261139,294.500458,0.000000
86.120003,65.189377,-345.261139,-0.001457,0.004617,0.117266,289.976837,14.772124,1.172661,-345.261139,294.500458,0.000000
86.590004,65.235184,-345.261139,-0.001440,0.004639,0.117830,290.180603,14.782503,1.178300,-345.261139,294.500458,0.000000
87.060005,65.163696,-345.261139,-0.001440,0.004641,0.117891,289.862610,14.766305,1.178906,-345.261139,294.500458,0.000000
87.530006,65.190872,-345.350098,-0.001440,0.004643,0.117925,289.983490,14.772463,1.179254,-345.350098,294.500458,0.000000
88.000008,65.117508,-345.350098,-0.001444,0.004643,0.117934,289.657135,14.755838,1.179341,-345.350098,294.500458,0.000000
88.470001,65.162949,-345.439056,-0.001444,0.004645,0.117977,289.859283,14.766135,1.179773,-345.439056,294.500458,0.000000
88.940002,65.233688,-345.439056,-0.001440,0.004647,0.118029,290.173950,14.782165,1.180295,-345.439056,294.500458,0.000000
89.410004,65.168152,-345.439056,-0.001453,0.004647,0.118029,289.882416,14.767315,1.180295,-345.439056,294.500458,0.000000
89.880005,65.101501,-345.483551,-0.001449,0.004647,0.118029,289.585937,14.752212,1.180295,-345.483551,294.500458,0.000000
90.350006,65.352478,-345.572510,-0.001444,0.004651,0.118142,290.702332,14.809083,1.181423,-345.572510,294.500458,0.000000
90.820007,65.332001,-345.572510,-0.001431,0.004651,0.118142,290.611267,14.804443,1.181423,-345.572510,294.500458,0.000000
91.290001,65.289551,-345.572510,-0.001444,0.004651,0.118142,290.422424,14.794824,1.181423,-345.572510,294.500458,0.000000
91.760002,65.235931,-345.528015,-0.001427,0.004652,0.118151,290.183929,14.782673,1.181506,-345.528015,294.500458,0.000000
92.230003,65.243011,-345.661469,-0.001436,0.004653,0.118177,290.215424,14.784278,1.181767,-345.661469,294.500458,0.000000
92.700005,65.234436,-345.661469,-0.001440,0.004653,0.118194,290.177277,14.782334,1.181941,-345.661469,294.500458,0.000000
93.170006,65.242264,-345.661469,-0.001436,0.004654,0.118212,290.212097,14.784108,1.182115,-345.661469,294.500458,0.000000
93.640007,65.218063,-345.617004,-0.001444,0.004655,0.118229,290.104431,14.778625,1.182289,-345.617004,294.500458,0.000000
94.110008,65.237427,-345.750427,-0.001436,0.004655,0.118238,290.190582,14.783012,1.182377,-345.750427,294.500458,0.000000
94.580002,65.249329,-345.794922,-0.001444,0.004656,0.118255,290.243500,14.785709,1.182547,-345.794922,294.500458,0.000000
95.050003,65.220657,-345.794922,-0.001440,0.004656,0.118263,290.115967,14.779213,1.182634,-345.794922,294.500458,0.000000
95.520004,65.231094,-345.794922,-0.001444,0.004656,0.118272,290.162415,14.781577,1.182721,-345.794922,294.500458,0.000000
95.990005,65.226990,-345.794922,-0.001444,0.004657,0.118281,290.144135,14.780647,1.182808,-345.794922,294.500458,0.000000
96.460007,65.223648,-345.883881,-0.001444,0.004658,0.118307,290.129272,14.779890,1.183069,-345.883881,294.500458,0.000000
96.930008,65.222900,-345.928345,-0.001436,0.004658,0.118307,290.125946,14.779721,1.183069,-345.928345,294.500458,0.000000
97.400002,65.226242,-345.883881,-0.001440,0.004658,0.118324,290.140808,14.780478,1.183243,-345.883881,294.500458,0.000000
97.870003,65.211731,-345.928345,-0.001423,0.004658,0.118324,290.076263,14.777190,1.183243,-345.928345,294.500458,0.000000
98.340004,65.184921,-345.928345,-0.001436,0.004658,0.118324,289.957001,14.771114,1.183243,-345.928345,294.500458,0.000000
98.810005,65.192368,-346.017303,-0.001444,0.004659,0.118350,289.990143,14.772801,1.183501,-346.017303,294.500458,0.000000
99.280006,65.198318,-346.017303,-0.001444,0.004660,0.118359,290.016602,14.774151,1.183588,-346.017303,294.500458,0.000000
99.750008,65.166672,-346.061798,-0.001427,0.004660,0.118359,289.875824,14.766979,1.183588,-346.061798,294.500458,0.000000
100.220001,65.162567,-346.061798,-0.001440,0.004660,0.118359,289.857574,14.766049,1.183588,-346.061798,294.500458,0.000000
100.690002,65.186783,-346.106293,-0.001423,0.004661,0.118394,289.965302,14.771536,1.183936,-346.106293,294.500458,0.000000
101.160004,65.187897,-346.150757,-0.001431,0.004661,0.118394,289.970245,14.771788,1.183936,-346.150757,294.500458,0.000000
101.630005,65.178207,-346.150757,-0.001444,0.004661,0.118394,289.927155,14.769593,1.183936,-346.150757,294.500458,0.000000
102.100006,65.159973,-346.106293,-0.001427,0.004661,0.118394,289.846039,14.765461,1.183936,-346.106293,294.500458,0.000000
102.570007,65.127197,-346.195251,-0.001423,0.004662,0.118411,289.700256,14.758034,1.184110,-346.195251,294.500458,0.000000
103.040009,65.263489,-346.150757,-0.001423,0.004664,0.118463,290.306488,14.788918,1.184629,-346.150757,294.500458,0.000000
103.510002,65.278748,-346.284210,-0.001444,0.004664,0.118463,290.374359,14.792376,1.184629,-346.284210,294.500458,0.000000
103.980003,65.276154,-346.328674,-0.001427,0.004664,0.118463,290.362823,14.791788,1.184629,-346.328674,294.500458,0.000000
104.450005,65.268326,-346.284210,-0.001423,0.004664,0.118463,290.328003,14.790014,1.184629,-346.284210,294.500458,0.000000
104.920006,65.249710,-346.328674,-0.001436,0.004664,0.118463,290.245209,14.785795,1.184629,-346.328674,294.500458,0.000000
105.390007,65.231094,-346.373169,-0.001444,0.004664,0.118463,290.162415,14.781577,1.184629,-346.373169,294.500458,0.000000
105.860008,65.214706,-346.417633,-0.001423,0.004664,0.118463,290.089508,14.777864,1.184629,-346.417633,294.500458,0.000000
106.330002,65.222519,-346.462128,-0.001427,0.004665,0.118498,290.124268,14.779634,1.184977,-346.462128,294.500458,0.000000
106.800003,65.234070,-346.462128,-0.001418,0.004665,0.118498,290.175629,14.782252,1.184977,-346.462128,294.500458,0.000000
107.270004,65.237045,-346.462128,-0.001431,0.004666,0.118515,290.188873,14.782926,1.185151,-346.462128,294.500458,0.000000
107.740005,65.252686,-346.506622,-0.001436,0.004666,0.118515,290.258453,14.786469,1.185151,-346.506622,294.500458,0.000000
108.210007,65.245239,-346.551086,-0.001427,0.004666,0.118515,290.225311,14.784782,1.185151,-346.551086,294.500458,0.000000
108.680008,65.251190,-346.551086,-0.001431,0.004666,0.118524,290.251801,14.786131,1.185238,-346.551086,294.500458,0.000000
109.150002,65.252686,-346.595581,-0.001418,0.004666,0.118524,290.258453,14.786469,1.185238,-346.595581,294.500458,0.000000
109.620003,65.233688,-346.595581,-0.001431,0.004666,0.118524,290.173950,14.782165,1.185238,-346.595581,294.500458,0.000000
110.090004,65.206512,-346.640045,-0.001427,0.004666,0.118524,290.053040,14.776007,1.185238,-346.640045,294.500458,0.000000
110.560005,65.199432,-346.773499,-0.001436,0.004666,0.118524,290.021545,14.774403,1.185238,-346.773499,294.500458,0.000000
111.030006,65.174118,-346.729004,-0.001418,0.004666,0.118524,289.908966,14.768666,1.185238,-346.729004,294.500458,0.000000
111.500008,65.151779,-346.684540,-0.001436,0.004666,0.118524,289.809601,14.763604,1.185238,-346.684540,294.500458,0.000000
111.970009,65.269821,-346.773499,-0.001418,0.004669,0.118593,290.334656,14.790353,1.185931,-346.773499,294.500458,0.000000
112.440002,65.302963,-346.773499,-0.001431,0.004669,0.118593,290.482086,14.797863,1.185931,-346.773499,294.500458,0.000000
112.910004,65.296997,-346.817963,-0.001418,0.004669,0.118593,290.455536,14.796512,1.185931,-346.817963,294.500458,0.000000
113.380005,65.281357,-346.817963,-0.001427,0.004669,0.118593,290.385986,14.792967,1.185931,-346.817963,294.500458,0.000000
113.850006,65.289185,-346.862457,-0.001414,0.004669,0.118593,290.420807,14.794741,1.185931,-346.862457,294.500458,0.000000
114.320007,65.288437,-346.817963,-0.001436,0.004669,0.118593,290.417480,14.794571,1.185931,-346.817963,294.500458,0.000000
114.790009,65.270935,-346.951416,-0.001427,0.004669,0.118593,290.339630,14.790605,1.185931,-346.951416,294.500458,0.000000
115.260002,65.244873,-346.995911,-0.001431,0.004669,0.118593,290.223694,14.784699,1.185931,-346.995911,294.500458,0.000000
115.730003,65.243011,-346.951416,-0.001414,0.004669,0.118593,290.215424,14.784278,1.185931,-346.951416,294.500458,0.000000
116.200005,65.241882,-346.995911,-0.001431,0.004669,0.118593,290.210388,14.784021,1.185931,-346.995911,294.500458,0.000000
116.670006,65.219543,-347.040375,-0.001427,0.004669,0.118593,290.111023,14.778960,1.185931,-347.040375,294.500458,0.000000
117.140007,65.207260,-347.129333,-0.001423,0.004669,0.118593,290.056366,14.776176,1.185931,-347.129333,294.500458,0.000000
117.610008,65.189758,-347.084869,-0.001440,0.004669,0.118593,289.978516,14.772210,1.185931,-347.084869,294.500458,0.000000
118.080002,65.153259,-347.084869,-0.001431,0.004669,0.118593,289.816162,14.763940,1.185931,-347.084869,294.500458,0.000000
118.550003,65.136139,-347.173828,-0.001414,0.004669,0.118602,289.740021,14.760059,1.186018,-347.173828,294.500458,0.000000
119.020004,65.133148,-347.218292,-0.001431,0.004670,0.118619,289.726715,14.759382,1.186192,-347.218292,294.500458,0.000000
119.490005,65.141724,-347.218292,-0.001427,0.004670,0.118619,289.764862,14.761325,1.186192,-347.218292,294.500458,0.000000
119.960007,65.140228,-347.307251,-0.001410,0.004670,0.118628,289.758209,14.760986,1.186279,-347.307251,294.500458,0.000000
120.430008,65.127563,-347.262787,-0.001414,0.004670,0.118628,289.701874,14.758117,1.186279,-347.262787,294.500458,0.000000
120.900009,65.115280,-347.307251,-0.001423,0.004670,0.118628,289.647247,14.755334,1.186279,-347.307251,294.500458,0.000000
121.370003,65.116028,-347.307251,-0.001427,0.004671,0.118637,289.650543,14.755503,1.186366,-347.307251,294.500458,0.000000
121.840004,65.108582,-347.396240,-0.001423,0.004671,0.118637,289.617432,14.753816,1.186366,-347.396240,294.500458,0.000000
122.310005,65.116028,-347.396240,-0.001414,0.004672,0.118662,289.650543,14.755503,1.186623,-347.396240,294.500458,0.000000
122.780006,65.134644,-347.396240,-0.001414,0.004672,0.118662,289.733368,14.759721,1.186623,-347.396240,294.500458,0.000000
123.250008,65.144699,-347.440704,-0.001418,0.004672,0.118662,289.778107,14.762000,1.186623,-347.440704,294.500458,0.000000
123.720009,65.143204,-347.485199,-0.001423,0.004672,0.118671,289.771454,14.761662,1.186710,-347.485199,294.500458,0.000000
124.190002,65.135391,-347.529663,-0.001427,0.004672,0.118671,289.736694,14.759891,1.186710,-347.529663,294.500458,0.000000
124.660004,65.129807,-347.574158,-0.001418,0.004672,0.118671,289.711853,14.758625,1.186710,-347.574158,294.500458,0.000000
125.130005,65.114532,-347.529663,-0.001427,0.004672,0.118680,289.643921,14.755164,1.186797,-347.529663,294.500458,0.000000
125.600006,65.108200,-347.618622,-0.001431,0.004672,0.118680,289.615753,14.753729,1.186797,-347.618622,294.500458,0.000000
126.070007,65.094803,-347.618622,-0.001436,0.004672,0.118680,289.556152,14.750693,1.186797,-347.618622,294.500458,0.000000
126.540009,65.087357,-347.663116,-0.001414,0.004673,0.118688,289.523010,14.749006,1.186884,-347.663116,294.500458,0.000000
127.010010,65.104858,-347.707581,-0.001414,0.004673,0.118688,289.600861,14.752973,1.186884,-347.707581,294.500458,0.000000
127.480003,65.095169,-347.663116,-0.001418,0.004673,0.118688,289.557770,14.750776,1.186884,-347.663116,294.500458,0.000000
127.950005,65.098526,-347.796570,-0.001423,0.004673,0.118688,289.572693,14.751537,1.186884,-347.796570,294.500458,0.000000
128.420013,65.092194,-347.796570,-0.001418,0.004673,0.118688,289.544525,14.750102,1.186884,-347.796570,294.500458,0.000000
128.889999,65.101883,-347.796570,-0.001414,0.004673,0.118688,289.587646,14.752297,1.186884,-347.796570,294.500458,0.000000
129.360001,65.096283,-347.841034,-0.001414,0.004673,0.118697,289.562714,14.751029,1.186971,-347.841034,294.500458,0.000000
129.830002,65.070969,-347.841034,-0.001423,0.004674,0.118715,289.450134,14.745292,1.187146,-347.841034,294.500458,0.000000
130.300003,65.237427,-347.885529,-0.001427,0.004676,0.118775,290.190582,14.783012,1.187751,-347.885529,294.500458,0.000000
130.770004,65.272797,-347.929993,-0.001418,0.004676,0.118775,290.347900,14.791027,1.187751,-347.929993,294.500458,0.000000
131.240005,65.278748,-347.974487,-0.001427,0.004676,0.118775,290.374359,14.792376,1.187751,-347.974487,294.500458,0.000000
131.710007,65.288803,-347.929993,-0.001410,0.004676,0.118775,290.419098,14.794654,1.187751,-347.929993,294.500458,0.000000
132.180008,65.290298,-347.974487,-0.001427,0.004676,0.118775,290.425751,14.794993,1.187751,-347.974487,294.500458,0.000000
132.650009,65.288437,-348.018951,-0.001436,0.004676,0.118775,290.417480,14.794571,1.187751,-348.018951,294.500458,0.000000
133.120010,65.278748,-348.152405,-0.001436,0.004676,0.118775,290.374359,14.792376,1.187751,-348.152405,294.500458,0.000000
133.590012,65.273911,-348.063446,-0.001406,0.004676,0.118775,290.352844,14.791280,1.187751,-348.063446,294.500458,0.000000
134.060013,65.260880,-348.063446,-0.001406,0.004676,0.118775,290.294891,14.788326,1.187751,-348.063446,294.500458,0.000000
134.529999,65.275772,-348.063446,-0.001423,0.004676,0.118775,290.361145,14.791701,1.187751,-348.063446,294.500458,0.000000
135.000000,65.265717,-348.196899,-0.001427,0.004676,0.118775,290.316406,14.789423,1.187751,-348.196899,294.500458,0.000000
135.470001,65.258652,-348.152405,-0.001414,0.004676,0.118775,290.284973,14.787822,1.187751,-348.152405,294.500458,0.000000
135.940002,65.248962,-348.241364,-0.001423,0.004676,0.118775,290.241882,14.785626,1.187751,-348.241364,294.500458,0.000000
136.410004,65.239655,-348.196899,-0.001431,0.004676,0.118775,290.200470,14.783518,1.187751,-348.196899,294.500458,0.000000
136.880005,65.245239,-348.241364,-0.001418,0.004676,0.118775,290.225311,14.784782,1.187751,-348.241364,294.500458,0.000000
137.350006,65.238159,-348.330322,-0.001427,0.004676,0.118775,290.193817,14.783178,1.187751,-348.330322,294.500458,0.000000
137.820007,65.224014,-348.330322,-0.001414,0.004676,0.118775,290.130920,14.779973,1.187751,-348.330322,294.500458,0.000000
138.290009,65.209122,-348.330322,-0.001418,0.004676,0.118775,290.064667,14.776598,1.187751,-348.330322,294.500458,0.000000
138.760010,65.191620,-348.374817,-0.001406,0.004676,0.118775,289.986816,14.772633,1.187751,-348.374817,294.500458,0.000000
139.230011,65.175980,-348.508240,-0.001423,0.004676,0.118775,289.917236,14.769088,1.187751,-348.508240,294.500458,0.000000
139.700012,65.170395,-348.508240,-0.001427,0.004676,0.118775,289.892395,14.767822,1.187751,-348.508240,294.500458,0.000000
140.170013,65.156616,-348.463776,-0.001401,0.004676,0.118775,289.831116,14.764701,1.187751,-348.463776,1681.640747,0.000000
140.639999,65.098526,-348.463776,-0.001414,0.004660,0.118359,289.572693,14.751537,1.183588,-348.463776,0.118099,0.000000
141.110001,65.050110,-348.552734,-0.001427,0.004631,0.117631,289.357330,14.740566,1.176306,-348.552734,0.117310,0.000000
141.580002,64.997604,-348.597198,-0.001423,0.004604,0.116937,289.123779,14.728667,1.169368,-348.597198,0.116529,0.000000
142.050003,64.953293,-348.597198,-0.001410,0.004585,0.116468,288.926666,14.718627,1.164682,-348.597198,0.115749,0.000000
142.520004,64.942505,-348.641693,-0.001410,0.004550,0.115558,288.878693,14.716182,1.155580,-348.641693,0.114960,0.000000
142.990005,64.891479,-348.641693,-0.001414,0.004517,0.114734,288.651703,14.704619,1.147340,-348.641693,0.114179,0.000000
143.460007,64.825577,-348.641693,-0.001423,0.004486,0.113936,288.358582,14.689686,1.139361,-348.641693,0.113398,0.000000
143.930008,64.749619,-348.730652,-0.001427,0.004458,0.113225,288.020691,14.672473,1.132249,-348.730652,0.112609,0.000000
144.400009,64.105774,-348.730652,-0.001414,0.004432,0.112566,285.156738,14.526576,1.125660,-348.730652,0.111829,0.000000
144.870010,63.067604,-348.686188,-0.001410,0.004406,0.111907,280.538727,14.291324,1.119067,-348.686188,0.111048,0.000000
145.340012,61.275749,-348.730652,-0.001410,0.004369,0.110979,272.568146,13.885283,1.109790,-348.730652,0.110259,0.000000
145.810013,59.303291,-348.864105,-0.001388,0.004338,0.110190,263.794220,13.438318,1.101898,-348.864105,0.109479,0.000000
146.280014,57.707306,-348.819611,-0.001384,0.004320,0.109730,256.694916,13.076662,1.097300,-348.819611,0.108698,0.000000
146.750000,55.214645,-348.953064,-0.001375,0.004291,0.108984,245.607010,12.511817,1.089844,-348.953064,0.107909,0.000000
147.220001,52.212578,-348.908569,-0.001393,0.004257,0.108117,232.253143,11.831539,1.081169,-348.908569,0.107128,0.000000
147.690002,49.079063,-348.908569,-0.001380,0.004227,0.107354,218.314575,11.121474,1.073538,-348.908569,0.106348,0.000000
148.160004,46.933075,-348.997528,-0.001388,0.004201,0.106695,208.768738,10.635187,1.066949,-348.997528,0.105559,0.000000
148.630005,42.033028,-349.042023,-0.001375,0.004162,0.105715,186.972244,9.524819,1.057150,-349.042023,0.104778,0.000000
149.100006,38.844406,-348.997528,-0.001380,0.004132,0.104952,172.788544,8.802268,1.049515,-348.997528,0.103998,0.000000
149.570007,35.628593,-349.042023,-0.001380,0.004104,0.104240,158.483902,8.073555,1.042404,-349.042023,0.103209,0.000000
150.040009,32.061638,-349.086517,-0.001384,0.004070,0.103391,142.617294,7.265271,1.033906,-349.086517,0.102428,0.000000
150.510010,29.990135,-349.130981,-0.001406,0.004055,0.103009,133.402786,6.795862,1.030091,-349.130981,0.101647,0.000000
150.980011,26.157677,-349.175476,-0.001380,0.004020,0.102098,116.355156,5.927414,1.020985,-349.175476,0.100858,0.000000
151.450012,21.733887,-349.130981,-0.001380,0.003978,0.101032,96.677155,4.924969,1.010319,-349.130981,0.100078,0.000000
151.920013,18.751930,-349.219940,-0.001397,0.003953,0.100416,83.412750,4.249248,1.004161,-349.219940,0.099297,0.000000
152.390015,15.150345,-349.175476,-0.001393,0.003919,0.099540,67.392097,3.433117,0.995403,-349.175476,0.098508,0.000000
152.860001,12.141571,-349.264435,-0.001401,0.003887,0.098725,54.008404,2.751319,0.987250,-349.264435,0.097728,0.000000
153.330002,8.621910,-349.353394,-0.001380,0.003858,0.097996,38.352173,1.953753,0.979964,-349.353394,0.096947,0.000000
153.800003,5.056442,-349.264435,-0.001393,0.003828,0.097225,22.492178,1.145806,0.972247,-349.264435,0.096158,0.000000
154.270004,2.002243,-349.353394,-0.001393,0.003798,0.096470,8.906422,0.453715,0.964700,-349.353394,0.095377,0.000000
154.740005,-0.531380,-349.353394,-0.001384,0.003771,0.095776,-2.363695,-0.120412,0.957762,-349.353394,0.094597,0.000000
155.210007,0.072235,-349.442352,-0.001388,0.003736,0.094892,0.321318,0.016369,0.948917,-349.442352,0.093808,0.000000
155.680008,0.160492,-349.397858,-0.001384,0.003703,0.094051,0.713904,0.036368,0.940507,-349.397858,0.093027,0.000000
156.150009,0.106499,-349.442352,-0.001358,0.003668,0.093175,0.473730,0.024133,0.931748,-349.442352,0.092247,0.000000
156.620010,0.123253,-349.442352,-0.001345,0.003647,0.092646,0.548256,0.027929,0.926457,-349.442352,0.091458,0.000000
157.090012,0.064049,-349.531311,-0.001302,0.003604,0.091553,0.284903,0.014514,0.915530,-349.531311,0.090677,0.000000
157.560013,0.049522,-349.575806,-0.001302,0.003576,0.090824,0.220287,0.011222,0.908244,-349.575806,0.089897,0.000000
158.030014,0.096817,-349.531311,-0.001293,0.003565,0.090547,0.430664,0.021939,0.905470,-349.531311,0.089108,0.000000
158.500000,0.019737,-349.620270,-0.001311,0.003524,0.089506,0.087796,0.004473,0.895061,-349.620270,0.088327,0.000000
158.970001,0.038727,-349.664764,-0.001311,0.003494,0.088743,0.172265,0.008776,0.887431,-349.664764,0.087546,0.000000
159.440002,0.026810,-349.664764,-0.001328,0.003457,0.087815,0.119255,0.006075,0.878151,-349.664764,0.086757,0.000000
159.910004,0.020103,-349.709229,-0.001337,0.003426,0.087009,0.089425,0.004556,0.870089,-349.709229,0.085977,0.000000
160.380005,0.024948,-349.709229,-0.001337,0.003403,0.086445,0.110975,0.005653,0.864449,-349.709229,0.085196,0.000000
160.850006,0.014893,-349.709229,-0.001362,0.003366,0.085500,0.066245,0.003375,0.854998,-349.709229,0.084407,0.000000
161.320007,0.032021,-349.798187,-0.001380,0.003338,0.084789,0.142435,0.007256,0.847887,-349.798187,0.083627,0.000000
161.790009,0.044312,-349.842682,-0.001388,0.003310,0.084086,0.197107,0.010041,0.840862,-349.842682,0.082846,0.000000
162.260010,-0.009682,-349.798187,-0.001410,0.003281,0.083332,-0.043066,-0.002194,0.833318,-349.798187,0.082057,0.000000
162.730011,0.017128,-349.842682,-0.001431,0.003233,0.082126,0.076189,0.003881,0.821264,-349.842682,0.081276,0.000000
163.200012,0.013031,-349.842682,-0.001453,0.003209,0.081511,0.057965,0.002953,0.815105,-349.842682,0.080496,0.000000
163.670013,0.033882,-349.887146,-0.001492,0.003179,0.080756,0.150715,0.007678,0.807558,-349.887146,0.079707,0.000000
164.140015,0.017128,-349.931641,-0.001483,0.003168,0.080470,0.076189,0.003881,0.804697,-349.931641,0.078926,0.000000
164.610001,0.013779,-349.976135,-0.001513,0.003126,0.079403,0.061291,0.003122,0.794031,-349.976135,0.078146,0.000000
165.080002,0.017128,-349.931641,-0.001544,0.003085,0.078363,0.076189,0.003881,0.783627,-349.931641,0.077357,0.000000
165.550003,0.055107,-350.020599,-0.001578,0.003056,0.077634,0.245129,0.012487,0.776341,-350.020599,0.076576,0.000000
166.020004,0.048782,-350.109558,-0.001600,0.003024,0.076801,0.216995,0.011054,0.768014,-350.109558,0.075795,0.000000
166.490005,0.021225,-350.065094,-0.001625,0.003004,0.076307,0.094413,0.004810,0.763071,-350.065094,0.075006,0.000000
166.960007,0.032394,-350.065094,-0.001647,0.002960,0.075180,0.144098,0.007341,0.751799,-350.065094,0.074226,0.000000
167.430008,0.062927,-350.154053,-0.001686,0.002931,0.074451,0.279914,0.014260,0.744513,-350.154053,0.073445,0.000000
167.900009,0.062927,-350.109558,-0.001703,0.002904,0.073766,0.279914,0.014260,0.737663,-350.109558,0.072656,0.000000
168.370010,0.053246,-350.198517,-0.001746,0.002869,0.072864,0.236848,0.012066,0.728643,-350.198517,0.071876,0.000000
168.840012,0.030533,-350.243011,-0.001772,0.002838,0.072075,0.135817,0.006919,0.720752,-350.243011,0.071095,0.000000
169.310013,0.035744,-350.154053,-0.001802,0.002812,0.071416,0.158996,0.008100,0.714159,-350.154053,0.070306,0.000000
169.780014,0.045052,-350.198517,-0.001815,0.002778,0.070549,0.200399,0.010209,0.705487,-350.198517,0.069525,0.000000
170.250015,0.050644,-350.287476,-0.001854,0.002754,0.069950,0.225275,0.011476,0.699503,-350.287476,0.068745,0.000000
170.720001,0.026062,-350.376465,-0.001888,0.002714,0.068944,0.115930,0.005906,0.689443,-350.376465,0.067956,0.000000
171.190002,0.030907,-350.376465,-0.001919,0.002691,0.068346,0.137480,0.007004,0.683459,-350.376465,0.067175,0.000000
171.660004,0.024200,-350.376465,-0.001940,0.002657,0.067496,0.107649,0.005484,0.674962,-350.376465,0.066395,0.000000
172.130005,0.010422,-350.376465,-0.001979,0.002633,0.066880,0.046358,0.002362,0.668804,-350.376465,0.065606,0.000000
172.600006,0.049522,-350.420929,-0.002009,0.002587,0.065718,0.220287,0.011222,0.657185,-350.420929,0.064825,0.000000
173.070007,0.033142,-350.509888,-0.002035,0.002559,0.064990,0.147423,0.007510,0.649899,-350.509888,0.064044,0.000000
173.540009,0.045052,-350.509888,-0.002044,0.002546,0.064669,0.200399,0.010209,0.646689,-350.509888,0.063255,0.000000
174.010010,0.046547,-350.509888,-0.002113,0.002507,0.063672,0.207051,0.010548,0.636716,-350.509888,0.062475,0.000000
174.480011,-0.005219,-350.554382,-0.002139,0.002469,0.062709,-0.023213,-0.001183,0.627091,-350.554382,0.061694,0.000000
174.950012,-0.012291,-350.598846,-0.002143,0.002435,0.061859,-0.054673,-0.002785,0.618590,-350.598846,0.060905,0.000000
175.420013,-0.004097,-350.598846,-0.002186,0.002406,0.061113,-0.018224,-0.000928,0.611134,-350.598846,0.060125,0.000000
175.890015,0.010796,-350.643341,-0.002220,0.002381,0.060489,0.048021,0.002446,0.604889,-350.643341,0.059344,0.000000
176.360016,-0.017128,-350.598846,-0.002255,0.002344,0.059544,-0.076189,-0.003881,0.595438,-350.598846,0.058555,0.000000
176.830002,-0.025696,-350.687805,-0.002281,0.002313,0.058746,-0.114301,-0.005823,0.587459,-350.687805,0.057775,0.000000
177.300003,0.001488,-350.732300,-0.002315,0.002282,0.057957,0.006618,0.000337,0.579568,-350.732300,0.056994,0.000000
177.770004,0.015266,-350.732300,-0.002333,0.002249,0.057133,0.067908,0.003459,0.571328,-350.732300,0.056205,0.000000
178.240005,-0.003357,-350.776794,-0.002363,0.002216,0.056274,-0.014932,-0.000761,0.562744,-350.776794,0.055424,0.000000
178.710007,-0.013039,-350.821259,-0.002410,0.002192,0.055667,-0.057999,-0.002955,0.556673,-350.821259,0.054644,0.000000
179.180008,-0.001122,-350.776794,-0.002440,0.002156,0.054757,-0.004989,-0.000254,0.547566,-350.776794,0.053855,0.000000
179.650009,0.013779,-350.954712,-0.002466,0.002135,0.054219,0.061291,0.003122,0.542188,-350.954712,0.053074,0.000000
180.120010,0.004837,-350.865753,-0.002479,0.002101,0.053378,0.021516,0.001096,0.533778,-350.865753,0.052294,0.000000
180.590012,-0.000000,-350.910217,-0.002527,0.002066,0.052485,-0.000000,-0.000000,0.524846,-350.910217,0.051505,0.000000
181.060013,0.005585,-350.910217,-0.002565,0.002036,0.051721,0.024842,0.001266,0.517212,-350.910217,0.050724,0.000000
181.530014,-0.007446,-351.043671,-0.002600,0.002007,0.050967,-0.033123,-0.001687,0.509668,-351.043671,0.049944,0.000000
182.000015,0.013405,-350.999176,-0.002608,0.001983,0.050360,0.059628,0.003038,0.503597,-350.999176,0.049154,0.000000
182.470001,0.003723,-350.999176,-0.002652,0.001944,0.049380,0.016561,0.000844,0.493798,-350.999176,0.048374,0.000000
182.940002,0.002602,-351.043671,-0.002682,0.001912,0.048556,0.011573,0.000590,0.485559,-351.043671,0.047593,0.000000
183.410004,-0.010429,-351.043671,-0.002703,0.001884,0.047845,-0.046392,-0.002363,0.478449,-351.043671,0.046804,0.000000
183.880005,0.010056,-351.177094,-0.002751,0.001846,0.046891,0.044729,0.002279,0.468909,-351.177094,0.046024,0.000000
184.350006,0.005585,-351.221588,-0.002768,0.001818,0.046180,0.024842,0.001266,0.461797,-351.221588,0.045243,0.000000
184.820007,0.039467,-351.177094,-0.002802,0.001798,0.045668,0.175557,0.008943,0.456682,-351.177094,0.044454,0.000000
185.290009,0.026062,-351.132629,-0.002833,0.001765,0.044835,0.115930,0.005906,0.448355,-351.132629,0.043674,0.000000
185.760010,0.003349,-351.266083,-0.002863,0.001739,0.044168,0.014898,0.000759,0.441678,-351.266083,0.042893,0.000000
186.230011,0.008194,-351.266083,-0.002897,0.001698,0.043118,0.036449,0.001857,0.431185,-351.266083,0.042104,0.000000
186.700012,0.043938,-351.266083,-0.002932,0.001667,0.042338,0.195445,0.009956,0.423378,-351.266083,0.041323,0.000000
187.170013,0.050270,-351.310547,-0.002940,0.001647,0.041835,0.223612,0.011391,0.418350,-351.310547,0.040543,0.000000
187.640015,0.057716,-351.310547,-0.002979,0.001613,0.040976,0.256735,0.013079,0.409764,-351.310547,0.039754,0.000000
188.110016,0.036491,-351.355042,-0.003031,0.001571,0.039892,0.162322,0.008269,0.398924,-351.355042,0.038973,0.000000
188.580002,0.086761,-351.444000,-0.003053,0.001537,0.039051,0.385934,0.019660,0.390512,-351.444000,0.038193,0.000000
189.050003,0.060326,-351.444000,-0.003083,0.001514,0.038444,0.268342,0.013670,0.384441,-351.444000,0.037403,0.000000
189.520004,0.059204,-351.488464,-0.003126,0.001481,0.037620,0.263353,0.013416,0.376202,-351.488464,0.036623,0.000000
189.990005,0.010056,-351.444000,-0.003152,0.001451,0.036857,0.044729,0.002279,0.368571,-351.444000,0.035842,0.000000
190.460007,0.029419,-351.444000,-0.003173,0.001420,0.036059,0.130862,0.006666,0.360593,-351.444000,0.035053,0.000000
190.930008,0.048409,-351.577423,-0.003208,0.001397,0.035487,0.215332,0.010970,0.354868,-351.577423,0.034273,0.000000
191.400009,0.033142,-351.532959,-0.003251,0.001354,0.034403,0.147423,0.007510,0.344028,-351.532959,0.033492,0.000000
191.870010,0.033882,-351.577423,-0.003264,0.001326,0.033674,0.150715,0.007678,0.336744,-351.577423,0.032703,0.000000
192.340012,0.006699,-351.621918,-0.003294,0.001301,0.033050,0.029797,0.001518,0.330499,-351.621918,0.031923,0.000000
192.810013,0.013031,-351.666412,-0.003341,0.001267,0.032183,0.057965,0.002953,0.321828,-351.666412,0.031142,0.000000
193.280014,0.010422,-351.710876,-0.003380,0.001235,0.031368,0.046358,0.002362,0.313675,-351.710876,0.030353,0.000000
193.750015,0.010056,-351.666412,-0.003406,0.001206,0.030639,0.044729,0.002279,0.306391,-351.666412,0.029572,0.000000
194.220016,0.029419,-351.755371,-0.003419,0.001173,0.029789,0.130862,0.006666,0.297892,-351.755371,0.028792,0.000000
194.690002,0.030533,-351.799835,-0.003492,0.001143,0.029035,0.135817,0.006919,0.290347,-351.799835,0.028003,0.000000
195.160004,0.037239,-351.799835,-0.003497,0.001109,0.028176,0.165648,0.008438,0.281761,-351.799835,0.027222,0.000000
195.630005,0.033142,-351.888794,-0.003518,0.001080,0.027439,0.147423,0.007510,0.274390,-351.888794,0.026442,0.000000
196.100006,-0.019737,-351.888794,-0.003557,0.001051,0.026684,-0.087796,-0.004473,0.266845,-351.888794,0.025653,0.000000
196.300003,0.032394,-351.844330,-0.003553,0.001051,0.026702,0.144098,0.007341,0.267019,-351.844330,0.026537,0.000000