File: Data/compression 17/ManualNoHeating-10-17-reverse-hand-1-1_09062024_164958.csv
Time (sec),S:Load (lbs),S:HL1 (DIM),S:LVDT (in),S:Position (in),Ch:Position (mm),Ch:Load (N),Ch:Stress (MPa),Ch:Strain (mm/mm),Ch:HL1 (DIM),Set Point (),Cycles ()
0.110000,0.070374,-272.223419,-0.005497,-0.005458,-0.138626,0.313037,0.015947,-1.386261,-272.223419,-0.138435,0.000000
0.520000,0.091599,-272.223419,-0.005501,-0.005405,-0.137282,0.407451,0.020757,-1.372819,-272.223419,-0.136649,0.000000
0.930000,0.062553,-272.312378,-0.005523,-0.000000,-0.000000,0.278251,0.014175,-0.000000,-272.312378,-0.000052,0.000000
1.340000,0.112823,-272.356873,-0.005501,0.000001,0.000017,0.501864,0.025566,0.000174,-272.356873,0.000382,0.000000
1.750000,0.099052,-272.356873,-0.005514,0.000017,0.000442,0.440607,0.022446,0.004423,-272.356873,0.001067,0.000000
2.160000,0.100914,-272.356873,-0.005514,0.000038,0.000963,0.448888,0.022867,0.009627,-272.356873,0.001752,0.000000
2.570000,0.102776,-272.445831,-0.005501,0.000062,0.001587,0.457169,0.023289,0.015870,-272.445831,0.002428,0.000000
2.980000,0.080803,-272.490295,-0.005510,0.000087,0.002203,0.359429,0.018310,0.022028,-272.490295,0.003113,0.000000
3.390000,0.081917,-272.490295,-0.005489,0.000108,0.002749,0.364384,0.018563,0.027492,-272.490295,0.003799,0.000000
3.800000,0.068146,-272.534790,-0.005463,0.000135,0.003434,0.303127,0.015442,0.034342,-272.534790,0.004484,0.000000
4.210000,0.105377,-272.534790,-0.005458,0.000157,0.003981,0.468741,0.023879,0.039806,-272.534790,0.005169,0.000000
4.620000,0.087509,-272.579254,-0.005411,0.000191,0.004839,0.389260,0.019830,0.048392,-272.579254,0.005845,0.000000
5.030000,0.090858,-272.623749,-0.005394,0.000222,0.005637,0.404159,0.020589,0.056370,-272.623749,0.006530,0.000000
5.440000,0.082664,-272.668243,-0.005346,0.000252,0.006409,0.367710,0.018732,0.064088,-272.668243,0.007215,0.000000
5.850000,0.112823,-272.712708,-0.005355,0.000264,0.006704,0.501864,0.025566,0.067038,-272.712708,0.007900,0.000000
6.260000,0.115807,-272.668243,-0.005316,0.000301,0.007649,0.515133,0.026242,0.076489,-272.668243,0.008586,0.000000
6.670001,0.128464,-272.712708,-0.005286,0.000324,0.008230,0.571435,0.029110,0.082301,-272.712708,0.009262,0.000000
7.080000,0.135170,-272.801666,-0.005256,0.000349,0.008863,0.601266,0.030630,0.088631,-272.801666,0.009947,0.000000
7.490000,0.212250,-272.757202,-0.005230,0.000378,0.009609,0.944134,0.048096,0.096089,-272.757202,0.010632,0.000000
7.900001,0.308319,-272.890625,-0.005200,0.000405,0.010277,1.371472,0.069866,0.102767,-272.890625,0.011317,0.000000
8.310000,0.455780,-272.890625,-0.005182,0.000439,0.011144,2.027411,0.103281,0.111439,-272.890625,0.012002,0.000000
8.720000,0.531372,-272.890625,-0.005144,0.000458,0.011638,2.363661,0.120411,0.116382,-272.890625,0.012679,0.000000
9.130000,0.665054,-272.935120,-0.005135,0.000479,0.012159,2.958309,0.150703,0.121586,-272.935120,0.013364,0.000000
9.540001,0.915665,-272.979584,-0.005101,0.000511,0.012982,4.073080,0.207493,0.129824,-272.979584,0.014049,0.000000
9.950001,1.121582,-273.024078,-0.005079,0.000536,0.013607,4.989046,0.254154,0.136069,-273.024078,0.014734,0.000000
10.360001,1.369583,-273.024078,-0.005062,0.000567,0.014413,6.092210,0.310352,0.144133,-273.024078,0.015419,0.000000
10.770000,1.507362,-273.024078,-0.005019,0.000591,0.015003,6.705083,0.341573,0.150031,-273.024078,0.016096,0.000000
11.180000,1.763557,-273.068573,-0.005001,0.000616,0.015654,7.844695,0.399628,0.156536,-273.068573,0.016781,0.000000
11.590000,1.804886,-273.113037,-0.004997,0.000627,0.015914,8.028533,0.408993,0.159136,-273.113037,0.017466,0.000000
12.000001,2.132576,-273.113037,-0.004975,0.000663,0.016833,9.486172,0.483249,0.168329,-273.113037,0.018151,0.000000
12.410001,2.302002,-273.113037,-0.004945,0.000681,0.017301,10.239816,0.521641,0.173011,-273.113037,0.018836,0.000000
12.820001,2.687782,-273.246490,-0.004915,0.000720,0.018298,11.955853,0.609060,0.182985,-273.246490,0.019513,0.000000
13.230000,2.998711,-273.246490,-0.004885,0.000754,0.019148,13.338931,0.679518,0.191484,-273.246490,0.020198,0.000000
13.640000,3.269058,-273.246490,-0.004859,0.000781,0.019833,14.541497,0.740779,0.198334,-273.246490,0.020883,0.000000
14.050000,3.413536,-273.335449,-0.004820,0.000804,0.020432,15.184167,0.773518,0.204318,-273.335449,0.021568,0.000000
14.460001,3.605309,-273.335449,-0.004794,0.000835,0.021221,16.037212,0.816975,0.212211,-273.335449,0.022253,0.000000
14.870001,3.762451,-273.335449,-0.004769,0.000857,0.021767,16.736219,0.852584,0.217675,-273.335449,0.022929,0.000000
15.280001,4.088272,-273.379913,-0.004769,0.000884,0.022444,18.185543,0.926416,0.224439,-273.379913,0.023615,0.000000
15.690001,4.360855,-273.379913,-0.004717,0.000913,0.023190,19.398052,0.988184,0.231897,-273.379913,0.024300,0.000000
16.100000,4.683327,-273.424408,-0.004687,0.000946,0.024040,20.832478,1.061257,0.240396,-273.424408,0.024985,0.000000
16.510000,4.671036,-273.468872,-0.004674,0.000971,0.024673,20.777805,1.058472,0.246726,-273.468872,0.025670,0.000000
16.920000,4.917175,-273.468872,-0.004631,0.000995,0.025262,21.872688,1.114248,0.252623,-273.468872,0.026346,0.000000
17.330000,5.155121,-273.557861,-0.004631,0.001022,0.025956,22.931124,1.168167,0.259561,-273.557861,0.027032,0.000000
17.740002,5.384880,-273.513367,-0.004596,0.001046,0.026563,23.953142,1.220231,0.265631,-273.513367,0.027717,0.000000
18.150002,5.631760,-273.646820,-0.004562,0.001078,0.027370,25.051317,1.276175,0.273697,-273.646820,0.028402,0.000000
18.560001,5.832092,-273.691284,-0.004544,0.001106,0.028098,25.942442,1.321571,0.280981,-273.691284,0.029087,0.000000
18.970001,5.991470,-273.646820,-0.004510,0.001133,0.028775,26.651392,1.357687,0.287747,-273.646820,0.029763,0.000000
19.380001,6.128128,-273.735779,-0.004493,0.001156,0.029373,27.259275,1.388654,0.293731,-273.735779,0.030448,0.000000
19.790001,6.178032,-273.691284,-0.004480,0.001175,0.029850,27.481258,1.399962,0.298500,-273.691284,0.031133,0.000000
20.200001,6.475929,-273.824738,-0.004454,0.001208,0.030674,28.806372,1.467467,0.306739,-273.824738,0.031818,0.000000
20.610001,6.685204,-273.780243,-0.004419,0.001237,0.031420,29.737270,1.514889,0.314197,-273.780243,0.032504,0.000000
21.020000,7.021828,-273.824738,-0.004389,0.001270,0.032269,31.234650,1.591169,0.322694,-273.824738,0.033180,0.000000
21.430000,6.702705,-273.913696,-0.004389,0.001285,0.032634,29.815123,1.518855,0.326337,-273.913696,0.033865,0.000000
21.840000,7.571449,-273.869202,-0.004350,0.001324,0.033640,33.679489,1.715715,0.336398,-273.869202,0.034550,0.000000
22.250002,7.403511,-273.913696,-0.004316,0.001348,0.034247,32.932461,1.677660,0.342469,-273.913696,0.035235,0.000000
22.660002,7.631027,-273.958191,-0.004303,0.001378,0.035001,33.944504,1.729216,0.350012,-273.958191,0.035921,0.000000
23.070002,7.807159,-273.958191,-0.004268,0.001405,0.035678,34.727978,1.769128,0.356777,-273.958191,0.036597,0.000000
23.480001,7.574799,-274.002655,-0.004260,0.001416,0.035964,33.694386,1.716474,0.359639,-274.002655,0.037282,0.000000
23.890001,8.197037,-274.002655,-0.004243,0.001456,0.036970,36.462242,1.857475,0.369699,-274.002655,0.037967,0.000000
24.300001,8.259590,-274.136108,-0.004195,0.001484,0.037698,36.740494,1.871650,0.376983,-274.136108,0.038652,0.000000
24.710001,8.512436,-274.091614,-0.004178,0.001513,0.038427,37.865208,1.928946,0.384269,-274.091614,0.039337,0.000000
25.120001,8.443542,-274.091614,-0.004148,0.001534,0.038956,37.558754,1.913334,0.389558,-274.091614,0.040014,0.000000
25.530001,8.577972,-274.180573,-0.004130,0.001558,0.039563,38.156727,1.943796,0.395629,-274.180573,0.040699,0.000000
25.940001,8.827461,-274.225067,-0.004113,0.001589,0.040361,39.266510,2.000331,0.403608,-274.225067,0.041384,0.000000
26.350000,9.081787,-274.180573,-0.004092,0.001620,0.041159,40.397808,2.057962,0.411587,-274.180573,0.042069,0.000000
26.760002,9.317505,-274.225067,-0.004057,0.001651,0.041930,41.446331,2.111377,0.419304,-274.225067,0.042754,0.000000
27.170002,8.906029,-274.269531,-0.004027,0.001663,0.042251,39.615993,2.018135,0.422514,-274.269531,0.043431,0.000000
27.580002,9.572578,-274.402985,-0.004018,0.001700,0.043179,42.580956,2.169177,0.431792,-274.402985,0.044116,0.000000
27.990002,9.484322,-274.358521,-0.004001,0.001723,0.043760,42.188370,2.149178,0.437602,-274.358521,0.044801,0.000000
28.400002,9.520821,-274.402985,-0.003962,0.001748,0.044393,42.350727,2.157449,0.443934,-274.402985,0.045486,0.000000
28.810001,9.826538,-274.358521,-0.003962,0.001778,0.045165,43.710625,2.226725,0.451652,-274.358521,0.046171,0.000000
29.220001,9.966919,-274.358521,-0.003923,0.001803,0.045790,44.335072,2.258536,0.457897,-274.358521,0.046848,0.000000
29.630001,10.339294,-274.402985,-0.003923,0.001836,0.046622,45.991478,2.342918,0.466221,-274.402985,0.047533,0.000000
30.040001,10.204865,-274.491943,-0.003889,0.001859,0.047212,45.393505,2.312455,0.472118,-274.491943,0.048218,0.000000
30.450001,10.087570,-274.491943,-0.003863,0.001878,0.047697,44.871754,2.285876,0.476974,-274.491943,0.048903,0.000000
30.860001,10.559364,-274.580902,-0.003837,0.001911,0.048530,46.970398,2.392786,0.485299,-274.580902,0.049588,0.000000
31.270002,10.026871,-274.536438,-0.003837,0.001928,0.048972,44.601749,2.272121,0.489724,-274.536438,0.050265,0.000000
31.680002,10.971207,-274.669861,-0.003790,0.001967,0.049961,48.802364,2.486111,0.499610,-274.669861,0.050950,0.000000
32.090000,10.769012,-274.625397,-0.003786,0.001991,0.050559,47.902962,2.440293,0.505594,-274.625397,0.051635,0.000000
32.500000,10.929131,-274.669861,-0.003755,0.002015,0.051192,48.615200,2.476576,0.511924,-274.669861,0.052320,0.000000
32.910000,10.473343,-274.714355,-0.003747,0.002025,0.051435,46.587757,2.373293,0.514352,-274.714355,0.053005,0.000000
33.320000,11.313416,-274.714355,-0.003712,0.002068,0.052537,50.324585,2.563657,0.525366,-274.714355,0.053681,0.000000
33.730003,11.262405,-274.758820,-0.003695,0.002096,0.053230,50.097683,2.552097,0.532304,-274.758820,0.054366,0.000000
34.140003,11.380074,-274.758820,-0.003669,0.002123,0.053924,50.621094,2.578761,0.539242,-274.758820,0.055051,0.000000
34.550003,11.658981,-274.847809,-0.003639,0.002153,0.054679,51.861740,2.641963,0.546787,-274.847809,0.055737,0.000000
34.960003,11.731964,-274.847809,-0.003626,0.002179,0.055355,52.186382,2.658501,0.553550,-274.847809,0.056422,0.000000
35.370003,11.801598,-274.847809,-0.003626,0.002205,0.055997,52.496128,2.674280,0.559968,-274.847809,0.057098,0.000000
35.780003,12.028748,-274.847809,-0.003587,0.002235,0.056769,53.506542,2.725753,0.567687,-274.847809,0.057783,0.000000
36.190002,11.883896,-274.892273,-0.003579,0.002260,0.057393,52.862209,2.692929,0.573930,-274.892273,0.058468,0.000000
36.600002,12.277863,-274.981232,-0.003566,0.002292,0.058225,54.614662,2.782203,0.582255,-274.981232,0.059154,0.000000
37.010002,12.264832,-275.025726,-0.003535,0.002311,0.058711,54.556694,2.779250,0.587113,-275.025726,0.059839,0.000000
37.420002,12.751892,-274.981232,-0.003527,0.002347,0.059613,56.723248,2.889620,0.596132,-274.981232,0.060515,0.000000
37.830002,12.544853,-275.070190,-0.003492,0.002372,0.060238,55.802296,2.842704,0.602376,-275.070190,0.061200,0.000000
38.240002,12.548950,-275.070190,-0.003484,0.002393,0.060784,55.820518,2.843633,0.607839,-275.070190,0.061885,0.000000
38.650002,12.738861,-275.159149,-0.003458,0.002423,0.061547,56.665283,2.886667,0.615471,-275.159149,0.062570,0.000000
39.060001,12.566078,-275.203644,-0.003462,0.002439,0.061955,55.896706,2.847514,0.619546,-275.203644,0.063255,0.000000
39.470001,13.242310,-275.203644,-0.003423,0.002479,0.062969,58.904736,3.000750,0.629693,-275.203644,0.063932,0.000000
39.880001,13.301888,-275.292603,-0.003406,0.002505,0.063637,59.169750,3.014251,0.636371,-275.292603,0.064617,0.000000
40.290001,13.510040,-275.248138,-0.003389,0.002534,0.064357,60.095661,3.061419,0.643568,-275.248138,0.065302,0.000000
40.700001,13.352531,-275.248138,-0.003385,0.002555,0.064894,59.395027,3.025727,0.648945,-275.248138,0.065987,0.000000
41.110001,13.641121,-275.337097,-0.003363,0.002584,0.065640,60.678738,3.091122,0.656403,-275.337097,0.066672,0.000000
41.520000,13.603134,-275.337097,-0.003337,0.002609,0.066274,60.509762,3.082514,0.662735,-275.337097,0.067349,0.000000
41.930000,13.783363,-275.381561,-0.003320,0.002637,0.066976,61.311462,3.123355,0.669760,-275.381561,0.068034,0.000000
42.340000,14.216431,-275.426056,-0.003303,0.002671,0.067834,63.237843,3.221489,0.678344,-275.426056,0.068719,0.000000
42.750004,13.774429,-275.426056,-0.003277,0.002686,0.068225,61.271721,3.121330,0.682246,-275.426056,0.069404,0.000000
43.160004,14.594765,-275.515015,-0.003260,0.002722,0.069144,64.920753,3.307221,0.691440,-275.515015,0.070089,0.000000
43.570004,14.385864,-275.470520,-0.003247,0.002749,0.069820,63.991520,3.259883,0.698203,-275.470520,0.070766,0.000000
43.980003,14.383255,-275.603973,-0.003234,0.002775,0.070480,63.979912,3.259292,0.704797,-275.603973,0.071451,0.000000
44.390003,14.629395,-275.515015,-0.003199,0.002805,0.071251,65.074799,3.315068,0.712514,-275.515015,0.072136,0.000000
44.800003,14.129669,-275.559479,-0.003191,0.002820,0.071624,62.851906,3.201829,0.716242,-275.559479,0.072821,0.000000
45.210003,14.795471,-275.648468,-0.003186,0.002855,0.072509,65.813545,3.352702,0.725087,-275.648468,0.073506,0.000000
45.620003,14.878883,-275.648468,-0.003169,0.002884,0.073246,66.184578,3.371603,0.732460,-275.648468,0.074182,0.000000
46.030003,15.020386,-275.692932,-0.003126,0.002913,0.073983,66.814011,3.403668,0.739830,-275.692932,0.074867,0.000000
46.440002,14.736267,-275.737427,-0.003113,0.002932,0.074477,65.550186,3.339286,0.744773,-275.737427,0.075553,0.000000
46.850002,14.836433,-275.692932,-0.003091,0.002958,0.075137,65.995750,3.361984,0.751366,-275.692932,0.076238,0.000000
47.260002,15.085548,-275.826385,-0.003074,0.002989,0.075917,67.103874,3.418434,0.759170,-275.826385,0.076923,0.000000
47.670002,15.308228,-275.826385,-0.003057,0.003019,0.076680,68.094398,3.468894,0.766801,-275.826385,0.077599,0.000000
48.080002,15.494789,-275.870850,-0.003031,0.003049,0.077452,68.924263,3.511169,0.774518,-275.870850,0.078284,0.000000
48.490002,14.734032,-275.915344,-0.003027,0.003066,0.077868,65.540245,3.338779,0.778682,-275.915344,0.078970,0.000000
48.900002,15.434464,-275.826385,-0.003001,0.003099,0.078710,68.655922,3.497499,0.787095,-275.826385,0.079655,0.000000
49.310001,15.181625,-276.004303,-0.002988,0.003125,0.079377,67.531242,3.440205,0.793772,-276.004303,0.080340,0.000000
49.720001,14.961182,-275.959808,-0.002962,0.003148,0.079958,66.550659,3.390252,0.799582,-275.959808,0.081016,0.000000
50.130001,15.313072,-276.048767,-0.002953,0.003179,0.080739,68.115944,3.469992,0.807386,-276.048767,0.081701,0.000000
50.540001,15.141037,-276.093262,-0.002940,0.003203,0.081346,67.350693,3.431008,0.813457,-276.093262,0.082387,0.000000
50.950001,15.436699,-276.093262,-0.002910,0.003234,0.082144,68.665863,3.498006,0.821436,-276.093262,0.083072,0.000000
51.360001,15.094116,-276.093262,-0.002889,0.003258,0.082759,67.141983,3.420376,0.827594,-276.093262,0.083757,0.000000
51.770004,14.654343,-276.137756,-0.002876,0.003276,0.083219,65.185768,3.320722,0.832189,-276.137756,0.084433,0.000000
52.180004,15.113106,-276.182220,-0.002863,0.003309,0.084043,67.226456,3.424679,0.840428,-276.182220,0.085118,0.000000
52.590004,14.674080,-276.226715,-0.002850,0.003327,0.084503,65.273567,3.325194,0.845027,-276.226715,0.085803,0.000000
53.000004,15.324242,-276.182220,-0.002811,0.003366,0.085491,68.165634,3.472523,0.854913,-276.182220,0.086489,0.000000
53.410004,14.974960,-276.315674,-0.002794,0.003391,0.086124,66.611954,3.393375,0.861242,-276.315674,0.087174,0.000000
53.820004,14.888565,-276.226715,-0.002781,0.003414,0.086723,66.227646,3.373797,0.867225,-276.226715,0.087850,0.000000
54.230003,14.115150,-276.360138,-0.002768,0.003423,0.086957,62.787327,3.198539,0.869568,-276.360138,0.088535,0.000000
54.640003,15.259453,-276.404633,-0.002751,0.003470,0.088127,67.877434,3.457842,0.881275,-276.404633,0.089220,0.000000
55.050003,14.826378,-276.404633,-0.002716,0.003493,0.088735,65.951019,3.359705,0.887346,-276.404633,0.089905,0.000000
55.460003,15.049431,-276.493591,-0.002699,0.003526,0.089550,66.943214,3.410250,0.895499,-276.493591,0.090590,0.000000
55.870003,15.108269,-276.449097,-0.002669,0.003551,0.090200,67.204933,3.423583,0.902001,-276.449097,0.091267,0.000000
56.280003,14.604073,-276.493591,-0.002660,0.003568,0.090616,64.962158,3.309330,0.906164,-276.493591,0.091952,0.000000
56.690002,15.416962,-276.538086,-0.002665,0.003604,0.091553,68.578072,3.493533,0.915532,-276.538086,0.092637,0.000000
57.100002,15.456062,-276.538086,-0.002626,0.003632,0.092264,68.751999,3.502394,0.922644,-276.538086,0.093322,0.000000
57.510002,15.263176,-276.627045,-0.002613,0.003658,0.092915,67.893997,3.458685,0.929146,-276.627045,0.094007,0.000000
57.920002,15.600166,-276.671509,-0.002596,0.003689,0.093712,69.393005,3.535048,0.937125,-276.671509,0.094684,0.000000
58.330002,14.904205,-276.671509,-0.002574,0.003699,0.093964,66.297218,3.377341,0.939638,-276.671509,0.095369,0.000000
58.740002,16.245865,-276.671509,-0.002544,0.003746,0.095152,72.265213,3.681365,0.951519,-276.671509,0.096054,0.000000
59.150002,15.832527,-276.716003,-0.002539,0.003771,0.095776,70.426598,3.587702,0.957764,-276.716003,0.096739,0.000000
59.560001,15.792686,-276.760468,-0.002527,0.003792,0.096306,70.249374,3.578674,0.963055,-276.760468,0.097424,0.000000
59.970001,16.059677,-276.760468,-0.002496,0.003822,0.097069,71.437012,3.639175,0.970686,-276.760468,0.098101,0.000000
60.380001,15.903282,-276.760468,-0.002471,0.003838,0.097476,70.741333,3.603735,0.974762,-276.760468,0.098786,0.000000
60.790005,16.185165,-276.849426,-0.002466,0.003869,0.098274,71.995209,3.667611,0.982740,-276.849426,0.099471,0.000000
61.200005,17.181267,-276.893921,-0.002462,0.003905,0.099176,76.426094,3.893331,0.991760,-276.893921,0.100156,0.000000
61.610004,17.427032,-276.938416,-0.002445,0.003933,0.099887,77.519310,3.949022,0.998872,-276.938416,0.100841,0.000000
62.020004,17.317177,-276.982880,-0.002423,0.003953,0.100416,77.030647,3.924129,1.004163,-276.982880,0.101517,0.000000
62.430004,17.873131,-276.982880,-0.002384,0.003984,0.101197,79.503654,4.050109,1.011967,-276.982880,0.102203,0.000000
62.840004,18.028786,-276.982880,-0.002376,0.004008,0.101813,80.196045,4.085382,1.018125,-276.982880,0.102888,0.000000
63.250004,18.445099,-277.027374,-0.002363,0.004037,0.102532,82.047897,4.179719,1.025321,-277.027374,0.103573,0.000000
63.660004,19.117973,-277.071838,-0.002337,0.004068,0.103339,85.040993,4.332195,1.033386,-277.071838,0.104258,0.000000
64.070000,19.089302,-277.071838,-0.002324,0.004087,0.103807,84.913460,4.325698,1.038068,-277.071838,0.104934,0.000000
64.480003,20.417183,-277.160797,-0.002307,0.004122,0.104692,90.820168,4.626600,1.046917,-277.160797,0.105619,0.000000
64.889999,20.423141,-277.160797,-0.002294,0.004148,0.105359,90.846672,4.627950,1.053594,-277.160797,0.106304,0.000000
65.300003,20.856949,-277.160797,-0.002281,0.004175,0.106044,92.776344,4.726252,1.060444,-277.160797,0.106990,0.000000
65.710007,21.475464,-277.205292,-0.002251,0.004204,0.106773,95.527634,4.866409,1.067730,-277.205292,0.107675,0.000000
66.120003,21.206238,-277.205292,-0.002242,0.004218,0.107146,94.330055,4.805402,1.071458,-277.205292,0.108351,0.000000
66.530006,22.533371,-277.294250,-0.002207,0.004254,0.108048,100.233437,5.106135,1.080478,-277.294250,0.109036,0.000000
66.940002,23.238647,-277.294250,-0.002186,0.004282,0.108768,103.370667,5.265953,1.087677,-277.294250,0.109721,0.000000
67.350006,23.941315,-277.294250,-0.002186,0.004312,0.109522,106.496284,5.425179,1.095220,-277.294250,0.110407,0.000000
67.760002,23.904076,-277.383209,-0.002169,0.004329,0.109947,106.330643,5.416741,1.099470,-277.383209,0.111092,0.000000
68.170006,24.705421,-277.383209,-0.002156,0.004358,0.110693,109.895203,5.598329,1.106927,-277.383209,0.111768,0.000000
68.580002,25.719391,-277.383209,-0.002126,0.004388,0.111456,114.405563,5.828097,1.114561,-277.383209,0.112453,0.000000
68.990005,26.769112,-277.516663,-0.002108,0.004418,0.112210,119.074959,6.065968,1.122104,-277.516663,0.113138,0.000000
69.400002,27.780098,-277.516663,-0.002100,0.004448,0.112991,123.572044,6.295060,1.129908,-277.516663,0.113824,0.000000
69.810005,27.622963,-277.605621,-0.002074,0.004467,0.113459,122.873077,6.259453,1.134590,-277.605621,0.114509,0.000000
70.220001,29.303474,-277.516663,-0.002065,0.004498,0.114248,130.348358,6.640262,1.142482,-277.516663,0.115185,0.000000
70.630005,29.781227,-277.561127,-0.002044,0.004523,0.114881,132.473511,6.748522,1.148814,-277.561127,0.115870,0.000000
71.040001,30.544594,-277.605621,-0.002048,0.004545,0.115454,135.869141,6.921504,1.154537,-277.605621,0.116555,0.000000
71.450005,31.949181,-277.605621,-0.002013,0.004576,0.116226,142.117050,7.239788,1.162258,-277.605621,0.117240,0.000000
71.860001,33.002251,-277.694580,-0.002001,0.004600,0.116841,146.801346,7.478417,1.168412,-277.694580,0.117926,0.000000
72.270004,34.381149,-277.694580,-0.001979,0.004632,0.117656,152.934998,7.790880,1.176565,-277.694580,0.118611,0.000000
72.680000,35.241325,-277.739044,-0.001979,0.004656,0.118264,156.761246,7.985798,1.182636,-277.739044,0.119287,0.000000
73.090004,35.765625,-277.783539,-0.001957,0.004674,0.118723,159.093445,8.104607,1.187231,-277.783539,0.119972,0.000000
73.500000,37.617805,-277.828033,-0.001949,0.004707,0.119547,167.332352,8.524316,1.195470,-277.828033,0.120657,0.000000
73.910004,38.495491,-277.828033,-0.001936,0.004729,0.120111,171.236496,8.723204,1.201110,-277.828033,0.121342,0.000000
74.320007,40.497368,-277.872498,-0.001927,0.004764,0.121004,180.141296,9.176835,1.210042,-277.872498,0.122027,0.000000
74.730003,41.556023,-277.828033,-0.001893,0.004789,0.121646,184.850418,9.416730,1.216458,-277.828033,0.122704,0.000000
75.140007,42.750221,-277.961456,-0.001884,0.004812,0.122235,190.162476,9.687339,1.222355,-277.961456,0.123389,0.000000
75.550003,42.613556,-278.005951,-0.001876,0.004822,0.122478,189.554565,9.656370,1.224784,-278.005951,0.124074,0.000000
75.960007,45.779099,-278.050415,-0.001850,0.004868,0.123649,203.635605,10.373693,1.236491,-278.050415,0.124759,0.000000
76.370003,47.259651,-278.005951,-0.001854,0.004892,0.124256,210.221420,10.709190,1.242562,-278.005951,0.125444,0.000000
76.780006,48.834038,-278.005951,-0.001828,0.004921,0.125002,217.224655,11.065951,1.250018,-278.005951,0.126121,0.000000
77.190002,50.643768,-278.139374,-0.001824,0.004950,0.125722,225.274734,11.476042,1.257217,-278.139374,0.126806,0.000000
77.600006,51.262650,-278.183868,-0.001828,0.004969,0.126216,228.027649,11.616282,1.262160,-278.183868,0.127491,0.000000
78.010002,53.623123,-278.139374,-0.001802,0.005004,0.127092,238.527557,12.151174,1.270918,-278.139374,0.128176,0.000000
78.420006,55.654411,-278.183868,-0.001798,0.005032,0.127812,247.563187,12.611470,1.278117,-278.183868,0.128861,0.000000
78.830002,57.099594,-278.139374,-0.001768,0.005057,0.128436,253.991684,12.938952,1.284362,-278.139374,0.129538,0.000000
79.240005,59.409042,-278.228363,-0.001759,0.005086,0.129182,264.264618,13.462282,1.291819,-278.228363,0.130223,0.000000
79.650002,60.793526,-278.228363,-0.001755,0.005108,0.129755,270.423096,13.776010,1.297545,-278.228363,0.130908,0.000000
80.060005,63.215805,-278.317322,-0.001725,0.005142,0.130596,281.197937,14.324906,1.305955,-278.317322,0.131593,0.000000
80.470001,64.941010,-278.361786,-0.001729,0.005166,0.131211,288.872040,14.715843,1.312113,-278.361786,0.132278,0.000000
80.880005,66.093124,-278.406281,-0.001716,0.005173,0.131385,293.996887,14.976916,1.313847,-278.406281,0.023055,0.000000
81.290001,65.090698,-278.450745,-0.001703,0.005173,0.131393,289.537872,14.749763,1.313934,-278.450745,294.500458,0.000000
81.700005,64.811050,-278.361786,-0.001712,0.005183,0.131645,288.293945,14.686394,1.316451,-278.361786,294.500458,0.000000
82.110001,65.508499,-278.406281,-0.001690,0.005192,0.131879,291.396362,14.844439,1.318790,-278.406281,294.500458,0.000000
82.520004,65.029266,-278.495239,-0.001694,0.005192,0.131888,289.264618,14.735842,1.318877,-278.495239,294.500458,0.000000
82.930000,65.760605,-278.450745,-0.001694,0.005201,0.132105,292.517792,14.901566,1.321046,-278.450745,294.500458,0.000000
83.340004,65.344284,-278.539703,-0.001681,0.005201,0.132113,290.665894,14.807227,1.321133,-278.539703,294.500458,0.000000
83.750008,65.266830,-278.584198,-0.001699,0.005205,0.132217,290.321350,14.789676,1.322174,-278.584198,294.500458,0.000000
84.160004,65.151031,-278.539703,-0.001681,0.005205,0.132217,289.806274,14.763435,1.322174,-278.539703,294.500458,0.000000
84.570007,65.589310,-278.628693,-0.001686,0.005212,0.132391,291.755829,14.862750,1.323907,-278.628693,294.500458,0.000000
84.980003,65.458603,-278.628693,-0.001677,0.005212,0.132391,291.174408,14.833131,1.323907,-278.628693,294.500458,0.000000
85.390007,65.286194,-278.673157,-0.001677,0.005212,0.132391,290.407501,14.794064,1.323907,-278.673157,294.500458,0.000000
85.800003,65.146927,-278.717651,-0.001669,0.005212,0.132391,289.787994,14.762505,1.323907,-278.717651,294.500458,0.000000
86.210007,65.002457,-278.762115,-0.001681,0.005212,0.132391,289.145355,14.729767,1.323907,-278.762115,294.500458,0.000000
86.620003,64.856476,-278.806610,-0.001677,0.005212,0.132391,288.496002,14.696687,1.323907,-278.806610,294.500458,0.000000
87.030006,65.683517,-278.762115,-0.001677,0.005222,0.132634,292.174866,14.884098,1.326337,-278.762115,294.500458,0.000000
87.440002,65.579636,-278.851074,-0.001673,0.005222,0.132634,291.712799,14.860558,1.326337,-278.851074,294.500458,0.000000
87.850006,65.504776,-278.984528,-0.001656,0.005222,0.132634,291.379791,14.843594,1.326337,-278.984528,294.500458,0.000000
88.260002,65.385254,-278.940033,-0.001656,0.005222,0.132642,290.848145,14.816510,1.326424,-278.940033,294.500458,0.000000
88.670006,65.307800,-278.984528,-0.001673,0.005223,0.132659,290.503601,14.798959,1.326594,-278.984528,294.500458,0.000000
89.080002,65.258270,-278.984528,-0.001677,0.005223,0.132659,290.283295,14.787735,1.326594,-278.984528,294.500458,0.000000
89.490005,65.194962,-278.940033,-0.001656,0.005223,0.132668,290.001678,14.773390,1.326681,-278.940033,294.500458,0.000000
89.900002,65.119003,-279.073486,-0.001673,0.005223,0.132668,289.663788,14.756177,1.326681,-279.073486,294.500458,0.000000
90.310005,65.126831,-279.028992,-0.001669,0.005225,0.132720,289.698608,14.757951,1.327204,-279.028992,294.500458,0.000000
90.720001,65.103363,-279.117981,-0.001660,0.005226,0.132729,289.594208,14.752633,1.327291,-279.117981,294.500458,0.000000
91.130005,65.076920,-279.117981,-0.001664,0.005226,0.132738,289.476593,14.746641,1.327378,-279.117981,294.500458,0.000000
91.540001,65.017349,-279.162445,-0.001664,0.005226,0.132738,289.211609,14.733142,1.327378,-279.162445,294.500458,0.000000
91.950005,64.980103,-279.206940,-0.001669,0.005226,0.132738,289.045929,14.724701,1.327378,-279.206940,294.500458,0.000000
92.360001,65.081772,-279.206940,-0.001669,0.005228,0.132798,289.498169,14.747741,1.327983,-279.206940,294.500458,0.000000
92.770004,65.052719,-279.251404,-0.001664,0.005228,0.132798,289.368958,14.741157,1.327983,-279.251404,294.500458,0.000000
93.180008,65.255295,-279.251404,-0.001656,0.005232,0.132885,290.270050,14.787061,1.328850,-279.251404,294.500458,0.000000
93.590004,65.253799,-279.251404,-0.001660,0.005232,0.132885,290.263397,14.786722,1.328850,-279.251404,294.500458,0.000000
94.000008,65.236298,-279.384857,-0.001660,0.005232,0.132885,290.185547,14.782756,1.328850,-279.384857,294.500458,0.000000
94.410004,65.200562,-279.295898,-0.001669,0.005232,0.132885,290.026581,14.774658,1.328850,-279.295898,294.500458,0.000000
94.820007,65.142090,-279.384857,-0.001651,0.005232,0.132885,289.766479,14.761409,1.328850,-279.384857,294.500458,0.000000
95.230003,65.102997,-279.384857,-0.001669,0.005232,0.132894,289.592590,14.752550,1.328937,-279.384857,294.500458,0.000000
95.640007,65.121613,-279.429321,-0.001664,0.005234,0.132937,289.675415,14.756768,1.329372,-279.429321,294.500458,0.000000
96.050003,65.144699,-279.473816,-0.001660,0.005234,0.132937,289.778107,14.762000,1.329372,-279.473816,294.500458,0.000000
96.460007,65.120865,-279.518311,-0.001664,0.005234,0.132937,289.672089,14.756599,1.329372,-279.518311,294.500458,0.000000
96.870003,65.098892,-279.518311,-0.001664,0.005234,0.132937,289.574341,14.751619,1.329372,-279.518311,294.500458,0.000000
97.280006,65.119003,-279.562775,-0.001660,0.005235,0.132980,289.663788,14.756177,1.329804,-279.562775,294.500458,0.000000
97.690002,65.128693,-279.607269,-0.001660,0.005235,0.132980,289.706879,14.758373,1.329804,-279.607269,294.500458,0.000000
98.100006,65.114166,-279.607269,-0.001651,0.005235,0.132980,289.642273,14.755081,1.329804,-279.607269,294.500458,0.000000
98.510002,65.082886,-279.696228,-0.001660,0.005235,0.132980,289.503143,14.747993,1.329804,-279.696228,294.500458,0.000000
98.920006,65.060547,-279.696228,-0.001673,0.005236,0.132989,289.403778,14.742930,1.329891,-279.696228,294.500458,0.000000
99.330002,65.044159,-279.740692,-0.001660,0.005236,0.132998,289.330872,14.739217,1.329978,-279.740692,294.500458,0.000000
99.740005,65.033737,-279.696228,-0.001656,0.005236,0.132998,289.284515,14.736856,1.329978,-279.696228,294.500458,0.000000
100.150002,65.014374,-279.785187,-0.001660,0.005236,0.132998,289.198364,14.732468,1.329978,-279.785187,294.500458,0.000000
100.560005,64.988678,-279.829651,-0.001651,0.005236,0.132998,289.084076,14.726645,1.329978,-279.829651,294.500458,0.000000
100.970001,64.973404,-279.785187,-0.001651,0.005236,0.132998,289.016144,14.723184,1.329978,-279.785187,294.500458,0.000000
101.380005,64.938400,-279.918640,-0.001638,0.005236,0.132998,288.860443,14.715252,1.329978,-279.918640,294.500458,0.000000
101.790009,64.914566,-279.874146,-0.001660,0.005236,0.132998,288.754425,14.709851,1.329978,-279.874146,294.500458,0.000000
102.200005,64.875839,-279.918640,-0.001643,0.005236,0.132998,288.582153,14.701076,1.329978,-279.918640,294.500458,0.000000
102.610008,64.844559,-280.007599,-0.001643,0.005236,0.132998,288.442993,14.693987,1.329978,-280.007599,294.500458,0.000000
103.020004,64.819992,-280.007599,-0.001643,0.005236,0.132998,288.333740,14.688420,1.329978,-280.007599,294.500458,0.000000
103.430008,64.783493,-280.096558,-0.001651,0.005236,0.132998,288.171356,14.680149,1.329978,-280.096558,294.500458,0.000000
103.840004,65.585220,-280.052063,-0.001660,0.005247,0.133267,291.737640,14.861823,1.332665,-280.052063,294.500458,0.000000
104.250008,65.626541,-280.096558,-0.001647,0.005246,0.133241,291.921448,14.871187,1.332408,-280.096558,294.500458,0.000000
104.660004,65.615372,-280.141022,-0.001660,0.005246,0.133241,291.871765,14.868656,1.332408,-280.141022,294.500458,0.000000
105.070007,65.618729,-280.141022,-0.001656,0.005246,0.133241,291.886688,14.869416,1.332408,-280.141022,294.500458,0.000000
105.480003,65.589310,-280.185516,-0.001664,0.005246,0.133241,291.755829,14.862750,1.332408,-280.185516,294.500458,0.000000
105.890007,65.581116,-280.185516,-0.001664,0.005246,0.133241,291.719360,14.860893,1.332408,-280.185516,294.500458,0.000000
106.300003,65.575531,-280.229980,-0.001634,0.005246,0.133241,291.694519,14.859628,1.332408,-280.229980,294.500458,0.000000
106.710007,65.569199,-280.274475,-0.001660,0.005246,0.133241,291.666351,14.858193,1.332408,-280.274475,294.500458,0.000000
107.120003,65.551331,-280.363434,-0.001660,0.005246,0.133241,291.586884,14.854144,1.332408,-280.363434,294.500458,0.000000
107.530006,65.537552,-280.363434,-0.001656,0.005246,0.133241,291.525604,14.851022,1.332408,-280.363434,294.500458,0.000000
107.940002,65.514099,-280.363434,-0.001651,0.005246,0.133241,291.421265,14.845707,1.332408,-280.363434,294.500458,0.000000
108.350006,65.487274,-280.407928,-0.001647,0.005246,0.133241,291.301941,14.839628,1.332408,-280.407928,294.500458,0.000000
108.760002,65.477966,-280.407928,-0.001651,0.005246,0.133241,291.260529,14.837520,1.332408,-280.407928,294.500458,0.000000
109.170006,65.435516,-280.452393,-0.001660,0.005246,0.133249,291.071716,14.827900,1.332491,-280.452393,294.500458,0.000000
109.580002,65.415421,-280.496887,-0.001651,0.005246,0.133249,290.982330,14.823346,1.332491,-280.496887,294.500458,0.000000
109.990005,65.389343,-280.496887,-0.001643,0.005246,0.133249,290.866333,14.817437,1.332491,-280.496887,294.500458,0.000000
110.400002,65.360306,-280.541351,-0.001647,0.005246,0.133249,290.737152,14.810857,1.332491,-280.541351,294.500458,0.000000
110.810005,65.336838,-280.630310,-0.001651,0.005246,0.133249,290.632782,14.805539,1.332491,-280.630310,294.500458,0.000000
111.220009,65.333115,-280.585846,-0.001647,0.005246,0.133249,290.616211,14.804696,1.332491,-280.585846,294.500458,0.000000
111.630005,65.313004,-280.630310,-0.001643,0.005246,0.133249,290.526764,14.800138,1.332491,-280.630310,294.500458,0.000000
112.040009,65.292160,-280.674805,-0.001647,0.005246,0.133249,290.434021,14.795415,1.332491,-280.674805,294.500458,0.000000
112.450005,65.266098,-280.674805,-0.001643,0.005246,0.133249,290.318115,14.789509,1.332491,-280.674805,294.500458,0.000000
112.860008,65.250076,-280.808258,-0.001643,0.005246,0.133249,290.246826,14.785879,1.332491,-280.808258,294.500458,0.000000
113.270004,65.239288,-280.763763,-0.001643,0.005246,0.133249,290.198853,14.783434,1.332491,-280.763763,294.500458,0.000000
113.680008,65.212097,-280.808258,-0.001651,0.005246,0.133249,290.077881,14.777272,1.332491,-280.808258,294.500458,0.000000
114.090004,65.193848,-280.852722,-0.001643,0.005246,0.133249,289.996704,14.773137,1.332491,-280.852722,294.500458,0.000000
114.500008,65.162201,-280.852722,-0.001656,0.005246,0.133249,289.855957,14.765966,1.332491,-280.852722,294.500458,0.000000
114.910004,65.131287,-280.941681,-0.001643,0.005246,0.133249,289.718445,14.758961,1.332491,-280.941681,294.500458,0.000000
115.320007,65.115280,-280.897217,-0.001647,0.005246,0.133249,289.647247,14.755334,1.332491,-280.897217,294.500458,0.000000
115.730003,65.087723,-280.941681,-0.001651,0.005246,0.133249,289.524658,14.749088,1.332491,-280.941681,294.500458,0.000000
116.140007,65.082138,-281.075134,-0.001656,0.005246,0.133249,289.499817,14.747823,1.332491,-281.075134,294.500458,0.000000
116.550003,65.041183,-280.986176,-0.001643,0.005246,0.133249,289.317627,14.738543,1.332491,-280.986176,294.500458,0.000000
116.960007,65.041931,-281.030640,-0.001647,0.005246,0.133258,289.320953,14.738712,1.332578,-281.030640,294.500458,0.000000
117.370003,65.019958,-281.030640,-0.001647,0.005246,0.133258,289.223206,14.733733,1.332578,-281.030640,294.500458,0.000000
117.780006,65.004684,-281.119598,-0.001660,0.005246,0.133258,289.155273,14.730271,1.332578,-281.119598,294.500458,0.000000
118.190002,64.989792,-281.164093,-0.001651,0.005246,0.133258,289.089020,14.726897,1.332578,-281.164093,294.500458,0.000000
118.600006,64.981232,-281.119598,-0.001638,0.005247,0.133267,289.050964,14.724958,1.332665,-281.119598,294.500458,0.000000
119.010002,64.967072,-281.253052,-0.001647,0.005247,0.133267,288.987976,14.721749,1.332665,-281.253052,294.500458,0.000000
119.420006,64.942123,-281.164093,-0.001656,0.005247,0.133267,288.876984,14.716096,1.332665,-281.164093,294.500458,0.000000
119.830009,64.926117,-281.253052,-0.001647,0.005247,0.133267,288.805786,14.712468,1.332665,-281.253052,294.500458,0.000000
120.240005,64.914948,-281.342010,-0.001651,0.005247,0.133267,288.756104,14.709937,1.332665,-281.342010,294.500458,0.000000
120.650009,64.899673,-281.297546,-0.001651,0.005247,0.133267,288.688171,14.706476,1.332665,-281.297546,294.500458,0.000000
121.060005,64.871384,-281.342010,-0.001638,0.005247,0.133267,288.562317,14.700066,1.332665,-281.342010,294.500458,0.000000
121.470009,64.863556,-281.342010,-0.001651,0.005247,0.133267,288.527496,14.698292,1.332665,-281.342010,294.500458,0.000000
121.880005,64.852753,-281.342010,-0.001634,0.005247,0.133267,288.479462,14.695844,1.332665,-281.342010,294.500458,0.000000
122.290009,66.007858,-281.475464,-0.001651,0.005254,0.133457,293.617615,14.957594,1.334573,-281.475464,294.500458,0.000000
122.700005,65.931152,-281.430969,-0.001638,0.005254,0.133440,293.276398,14.940212,1.334403,-281.430969,294.500458,0.000000
123.110008,65.925934,-281.475464,-0.001651,0.005254,0.133440,293.253204,14.939030,1.334403,-281.475464,294.500458,0.000000
123.520004,65.916626,-281.475464,-0.001647,0.005254,0.133440,293.211792,14.936921,1.334403,-281.475464,294.500458,0.000000
123.930008,65.868958,-281.519928,-0.001638,0.005254,0.133440,292.999756,14.926120,1.334403,-281.519928,294.500458,0.000000
124.340004,65.901733,-281.653381,-0.001647,0.005254,0.133440,293.145538,14.933546,1.334403,-281.653381,294.500458,0.000000
124.750008,65.846619,-281.519928,-0.001651,0.005254,0.133440,292.900391,14.921058,1.334403,-281.519928,294.500458,0.000000
125.160004,65.841034,-281.608887,-0.001647,0.005254,0.133440,292.875549,14.919792,1.334403,-281.608887,294.500458,0.000000
125.570007,65.857422,-281.653381,-0.001634,0.005254,0.133440,292.948456,14.923505,1.334403,-281.653381,294.500458,0.000000
125.980003,65.836563,-281.697876,-0.001634,0.005254,0.133440,292.855652,14.918778,1.334403,-281.697876,294.500458,0.000000
126.390007,65.846252,-281.742340,-0.001647,0.005254,0.133440,292.898773,14.920974,1.334403,-281.742340,294.500458,0.000000
126.800003,65.788162,-281.653381,-0.001638,0.005254,0.133440,292.640350,14.907811,1.334403,-281.653381,294.500458,0.000000
127.210007,65.768799,-281.742340,-0.001643,0.005254,0.133440,292.554230,14.903423,1.334403,-281.742340,294.500458,0.000000
127.620003,65.778473,-281.786835,-0.001638,0.005254,0.133440,292.597260,14.905615,1.334403,-281.786835,294.500458,0.000000
128.029999,65.777359,-281.831299,-0.001630,0.005254,0.133440,292.592316,14.905362,1.334403,-281.831299,294.500458,0.000000
128.440002,65.766556,-281.875793,-0.001643,0.005254,0.133440,292.544250,14.902914,1.334403,-281.875793,294.500458,0.000000
128.850006,65.750183,-281.875793,-0.001643,0.005254,0.133440,292.471436,14.899204,1.334403,-281.875793,294.500458,0.000000
129.260010,65.675705,-281.964752,-0.001630,0.005254,0.133440,292.140137,14.882328,1.334403,-281.964752,294.500458,0.000000
129.670013,65.674957,-281.964752,-0.001638,0.005254,0.133440,292.136810,14.882158,1.334403,-281.964752,294.500458,0.000000
130.080002,65.661926,-281.964752,-0.001634,0.005254,0.133440,292.078827,14.879205,1.334403,-281.964752,294.500458,0.000000
130.490005,65.646652,-282.053711,-0.001647,0.005254,0.133440,292.010895,14.875744,1.334403,-282.053711,294.500458,0.000000
130.900009,65.642563,-282.009216,-0.001634,0.005254,0.133440,291.992706,14.874817,1.334403,-282.009216,294.500458,0.000000
131.310013,65.613892,-282.053711,-0.001638,0.005254,0.133440,291.865173,14.868320,1.334403,-282.053711,294.500458,0.000000
131.720001,65.594894,-282.142670,-0.001647,0.005254,0.133440,291.780670,14.864016,1.334403,-282.142670,294.500458,0.000000
132.130005,65.593033,-282.098206,-0.001634,0.005254,0.133440,291.772369,14.863594,1.334403,-282.098206,294.500458,0.000000
132.540009,65.575531,-282.187164,-0.001634,0.005254,0.133440,291.694519,14.859628,1.334403,-282.187164,294.500458,0.000000
132.950012,65.567337,-282.187164,-0.001638,0.005254,0.133440,291.658081,14.857771,1.334403,-282.187164,294.500458,0.000000
133.360001,65.555420,-282.187164,-0.001638,0.005254,0.133440,291.605072,14.855071,1.334403,-282.187164,294.500458,0.000000
133.770004,65.539047,-282.231628,-0.001638,0.005254,0.133440,291.532257,14.851360,1.334403,-282.231628,294.500458,0.000000
134.180008,65.532715,-282.231628,-0.001638,0.005254,0.133440,291.504089,14.849925,1.334403,-282.231628,294.500458,0.000000
134.590012,65.509247,-282.365082,-0.001634,0.005254,0.133440,291.399689,14.844607,1.334403,-282.365082,294.500458,0.000000
135.000000,65.517075,-282.320587,-0.001651,0.005254,0.133440,291.434509,14.846381,1.334403,-282.320587,294.500458,0.000000
135.410004,65.498459,-282.365082,-0.001638,0.005254,0.133440,291.351685,14.842163,1.334403,-282.365082,294.500458,0.000000
135.820007,65.491745,-282.409546,-0.001638,0.005254,0.133440,291.321838,14.840642,1.334403,-282.409546,294.500458,0.000000
136.230011,65.464569,-282.365082,-0.001647,0.005254,0.133440,291.200958,14.834484,1.334403,-282.365082,294.500458,0.000000
136.639999,65.442963,-282.498535,-0.001634,0.005254,0.133449,291.104828,14.829587,1.334486,-282.498535,294.500458,0.000000
137.050003,65.426590,-282.498535,-0.001634,0.005254,0.133449,291.032013,14.825877,1.334486,-282.498535,294.500458,0.000000
137.460007,65.407227,-282.587494,-0.001643,0.005254,0.133457,290.945862,14.821489,1.334573,-282.587494,294.500458,0.000000
137.870010,65.403503,-282.587494,-0.001638,0.005254,0.133457,290.929321,14.820645,1.334573,-282.587494,294.500458,0.000000
138.280014,65.386368,-282.542999,-0.001625,0.005254,0.133457,290.853088,14.816763,1.334573,-282.542999,294.500458,0.000000
138.690002,65.372223,-282.631958,-0.001634,0.005254,0.133457,290.790161,14.813558,1.334573,-282.631958,294.500458,0.000000
139.100006,65.365509,-282.676453,-0.001638,0.005254,0.133457,290.760315,14.812036,1.334573,-282.676453,294.500458,0.000000
139.510010,65.348389,-282.631958,-0.001643,0.005254,0.133457,290.684143,14.808156,1.334573,-282.631958,294.500458,0.000000
139.920013,65.339447,-282.720917,-0.001634,0.005254,0.133457,290.644379,14.806130,1.334573,-282.720917,294.500458,0.000000
140.330002,65.318604,-282.676453,-0.001643,0.005254,0.133457,290.551666,14.801407,1.334573,-282.676453,294.500458,0.000000
140.740005,65.308914,-282.809875,-0.001647,0.005254,0.133457,290.508545,14.799212,1.334573,-282.809875,294.500458,0.000000
141.150009,65.305191,-282.809875,-0.001643,0.005254,0.133457,290.492004,14.798368,1.334573,-282.809875,294.500458,0.000000
141.560013,65.275772,-282.854370,-0.001634,0.005253,0.133423,290.361145,14.791701,1.334229,-282.854370,0.133388,0.000000
141.970001,65.229965,-282.898834,-0.001634,0.005237,0.133015,290.157379,14.781322,1.330152,-282.898834,0.132703,0.000000
142.380005,65.159592,-282.854370,-0.001647,0.005219,0.132564,289.844330,14.765374,1.325641,-282.854370,0.132027,0.000000
142.790009,65.113419,-282.943329,-0.001617,0.005195,0.131957,289.638947,14.754911,1.319570,-282.943329,0.131342,0.000000
143.200012,65.088104,-282.987823,-0.001625,0.005166,0.131229,289.526337,14.749176,1.312287,-282.987823,0.130656,0.000000
143.610001,65.077667,-282.898834,-0.001621,0.005147,0.130726,289.479919,14.746810,1.307257,-282.898834,0.129971,0.000000
144.020004,65.051605,-283.032288,-0.001625,0.005112,0.129841,289.363983,14.740905,1.298412,-283.032288,0.129286,0.000000
144.430008,65.072464,-282.987823,-0.001625,0.005091,0.129321,289.456787,14.745631,1.293208,-282.987823,0.128610,0.000000
144.840012,65.013626,-283.076782,-0.001617,0.005063,0.128592,289.195038,14.732298,1.285922,-283.076782,0.127925,0.000000
145.250000,64.937653,-283.121246,-0.001621,0.005039,0.128002,288.857117,14.715083,1.280025,-283.121246,0.127239,0.000000
145.660004,64.351547,-283.076782,-0.001630,0.005007,0.127170,286.249969,14.582269,1.271702,-283.076782,0.126554,0.000000
146.070007,63.604568,-283.165741,-0.001604,0.004985,0.126615,282.927246,14.413001,1.266150,-283.165741,0.125869,0.000000
146.480011,62.553734,-283.165741,-0.001621,0.004960,0.125990,278.252899,14.174879,1.259905,-283.165741,0.125193,0.000000
146.889999,60.979340,-283.210205,-0.001617,0.004936,0.125375,271.249664,13.818115,1.253750,-283.210205,0.124508,0.000000
147.300003,59.279091,-283.254700,-0.001604,0.004909,0.124690,263.686554,13.432834,1.246896,-283.254700,0.123822,0.000000
147.710007,57.115974,-283.254700,-0.001600,0.004884,0.124048,254.064545,12.942665,1.240480,-283.254700,0.123137,0.000000
148.120010,55.115593,-283.343658,-0.001608,0.004860,0.123432,245.166397,12.489371,1.234322,-283.343658,0.122452,0.000000
148.530014,53.496887,-283.254700,-0.001604,0.004844,0.123042,237.966034,12.122567,1.230420,-283.254700,0.121776,0.000000
148.940002,50.365608,-283.343658,-0.001600,0.004812,0.122227,224.037415,11.413010,1.222268,-283.343658,0.121091,0.000000
149.350006,48.091904,-283.388153,-0.001613,0.004791,0.121698,213.923477,10.897780,1.216980,-283.388153,0.120406,0.000000
149.760010,43.965645,-283.388153,-0.001595,0.004750,0.120640,195.568954,9.962758,1.206397,-283.388153,0.119720,0.000000
150.170013,41.645386,-283.477112,-0.001608,0.004732,0.120180,185.247925,9.436979,1.201803,-283.477112,0.119035,0.000000
150.580002,38.739021,-283.477112,-0.001600,0.004702,0.119443,172.319778,8.778387,1.194430,-283.477112,0.118359,0.000000
150.990005,35.410385,-283.521576,-0.001600,0.004675,0.118740,157.513260,8.024108,1.187405,-283.521576,0.117674,0.000000
151.400009,32.539391,-283.610535,-0.001608,0.004650,0.118099,144.742432,7.373531,1.180989,-283.610535,0.116989,0.000000
151.810013,28.943390,-283.521576,-0.001600,0.004615,0.117231,128.746628,6.558666,1.172314,-283.521576,0.116304,0.000000
152.220001,26.048569,-283.610535,-0.001595,0.004590,0.116599,115.869820,5.902690,1.165986,-283.610535,0.115619,0.000000
152.630005,23.659798,-283.566071,-0.001600,0.004570,0.116069,105.244034,5.361387,1.160695,-283.566071,0.114942,0.000000
153.040009,20.703163,-283.610535,-0.001600,0.004542,0.115358,92.092270,4.691404,1.153583,-283.610535,0.114257,0.000000
153.450012,17.528687,-283.655029,-0.001595,0.004512,0.114604,77.971489,3.972057,1.146040,-283.655029,0.113572,0.000000
153.860001,14.497948,-283.699493,-0.001595,0.004488,0.113988,64.490089,3.285282,1.139882,-283.699493,0.112887,0.000000
154.270004,11.220322,-283.788483,-0.001587,0.004457,0.113208,49.910484,2.542561,1.132077,-283.788483,0.112202,0.000000
154.680008,8.659149,-283.832947,-0.001613,0.004432,0.112575,38.517818,1.962191,1.125745,-283.832947,0.111525,0.000000
155.090012,6.480026,-283.743988,-0.001591,0.004412,0.112054,28.824596,1.468395,1.120545,-283.743988,0.110840,0.000000
155.500000,2.715340,-283.832947,-0.001595,0.004377,0.111178,12.078434,0.615305,1.111783,-283.832947,0.110155,0.000000
155.910004,0.116920,-283.832947,-0.001608,0.004351,0.110519,0.520088,0.026495,1.105193,-283.832947,0.109470,0.000000
156.320007,-0.300880,-283.877441,-0.001608,0.004322,0.109773,-1.338383,-0.068180,1.097733,-283.877441,0.108785,0.000000
156.730011,-0.021599,-283.921906,-0.001613,0.004297,0.109140,-0.096076,-0.004894,1.091405,-283.921906,0.108108,0.000000
157.140015,0.075592,-283.921906,-0.001600,0.004282,0.108750,0.336250,0.017129,1.087502,-283.921906,0.107423,0.000000
157.550003,0.015266,-283.966400,-0.001617,0.004241,0.107727,0.067908,0.003459,1.077268,-283.966400,0.106738,0.000000
157.960007,0.026810,-283.966400,-0.001621,0.004218,0.107128,0.119255,0.006075,1.071284,-283.966400,0.106053,0.000000
158.370010,0.080803,-284.010864,-0.001617,0.004193,0.106495,0.359429,0.018310,1.064952,-284.010864,0.105368,0.000000
158.780014,0.059952,-284.099823,-0.001630,0.004164,0.105767,0.266679,0.013585,1.057670,-284.099823,0.104692,0.000000
159.190002,0.060692,-284.055359,-0.001621,0.004140,0.105169,0.269971,0.013753,1.051686,-284.055359,0.104006,0.000000
159.600006,0.057343,-284.099823,-0.001625,0.004109,0.104379,0.255072,0.012994,1.043795,-284.099823,0.103321,0.000000
160.010010,0.068886,-284.099823,-0.001634,0.004088,0.103842,0.306419,0.015610,1.038416,-284.099823,0.102636,0.000000
160.420013,0.049896,-284.188782,-0.001643,0.004054,0.102983,0.221950,0.011307,1.029832,-284.188782,0.101951,0.000000
160.830002,0.074097,-284.233276,-0.001647,0.004035,0.102480,0.329598,0.016791,1.024802,-284.233276,0.101275,0.000000
161.240005,0.068512,-284.188782,-0.001643,0.004002,0.101656,0.304756,0.015525,1.016562,-284.188782,0.100590,0.000000
161.650009,0.074097,-284.322235,-0.001651,0.003974,0.100945,0.329598,0.016791,1.009450,-284.322235,0.099905,0.000000
162.060013,0.063675,-284.322235,-0.001664,0.003947,0.100260,0.283240,0.014429,1.002600,-284.322235,0.099220,0.000000
162.470001,0.058830,-284.277771,-0.001660,0.003924,0.099679,0.261690,0.013331,0.996790,-284.277771,0.098534,0.000000
162.880005,0.067398,-284.366730,-0.001673,0.003896,0.098950,0.299802,0.015273,0.989504,-284.366730,0.097858,0.000000
163.290009,0.077080,-284.322235,-0.001677,0.003860,0.098048,0.342868,0.017467,0.980485,-284.322235,0.097173,0.000000
163.700012,0.067772,-284.455688,-0.001699,0.003838,0.097485,0.301465,0.015357,0.974849,-284.455688,0.096488,0.000000
164.110001,0.080055,-284.455688,-0.001699,0.003812,0.096835,0.356103,0.018141,0.968346,-284.455688,0.095803,0.000000
164.520004,0.064789,-284.411194,-0.001699,0.003797,0.096453,0.288195,0.014681,0.964527,-284.411194,0.095117,0.000000
164.930008,0.061813,-284.500153,-0.001707,0.003762,0.095551,0.274960,0.014007,0.955508,-284.500153,0.094441,0.000000
165.340012,0.070374,-284.500153,-0.001716,0.003729,0.094719,0.313037,0.015947,0.947185,-284.500153,0.093756,0.000000
165.750015,0.092346,-284.544647,-0.001720,0.003704,0.094085,0.410776,0.020926,0.940853,-284.544647,0.093071,0.000000
166.160004,0.118782,-284.589111,-0.001738,0.003683,0.093557,0.528369,0.026916,0.935565,-284.589111,0.092386,0.000000
166.570007,0.076706,-284.544647,-0.001755,0.003652,0.092767,0.341205,0.017382,0.927670,-284.544647,0.091700,0.000000
166.980011,0.078568,-284.633606,-0.001746,0.003622,0.091995,0.349486,0.017804,0.919953,-284.633606,0.091024,0.000000
167.390015,0.063301,-284.633606,-0.001785,0.003594,0.091293,0.281577,0.014344,0.912928,-284.633606,0.090339,0.000000
167.800003,0.081177,-284.767059,-0.001785,0.003569,0.090660,0.361092,0.018395,0.906600,-284.767059,0.089654,0.000000
168.210007,0.091232,-284.767059,-0.001785,0.003546,0.090079,0.405822,0.020674,0.900786,-284.767059,0.088969,0.000000
168.620010,0.106873,-284.767059,-0.001815,0.003512,0.089203,0.475393,0.024218,0.892028,-284.767059,0.088284,0.000000
169.030014,0.062553,-284.811523,-0.001824,0.003486,0.088535,0.278251,0.014175,0.885351,-284.811523,0.087607,0.000000
169.440002,0.065536,-284.767059,-0.001841,0.003460,0.087885,0.291521,0.014851,0.878849,-284.767059,0.086922,0.000000
169.850006,0.072609,-284.856018,-0.001863,0.003437,0.087304,0.322981,0.016453,0.873035,-284.856018,0.086237,0.000000
170.260010,0.059952,-284.900482,-0.001867,0.003415,0.086749,0.266679,0.013585,0.867487,-284.900482,0.086653,0.000000
170.300003,0.051758,-284.900482,-0.001884,0.003415,0.086749,0.230230,0.011728,0.867487,-284.900482,0.086653,0.000000