File: Data/compression 17/ManualNoHeating-10-17-reverse-hand-1-4_09062024_170120.csv
Time (sec),S:Load (lbs),S:HL1 (DIM),S:LVDT (in),S:Position (in),Ch:Position (mm),Ch:Load (N),Ch:Stress (MPa),Ch:Strain (mm/mm),Ch:HL1 (DIM),Set Point (),Cycles ()
0.110000,-0.068520,-319.773560,-0.009934,-0.004771,-0.121186,-0.304790,-0.015527,-1.211861,-319.773560,-0.120891,0.000000
0.620000,0.022339,-319.729065,-0.009951,-0.004667,-0.118550,0.099368,0.005062,-1.185497,-319.729065,-0.117717,0.000000
1.130000,0.048409,-319.818024,-0.009692,-0.004352,-0.110545,0.215332,0.010970,-1.105452,-319.818024,-0.109218,0.000000
1.640000,-0.000374,-319.907013,-0.009326,-0.004016,-0.102003,-0.001663,-0.000085,-1.020031,-319.907013,-0.100720,0.000000
2.150000,0.010056,-319.862518,-0.008990,-0.003679,-0.093452,0.044729,0.002279,-0.934523,-319.862518,-0.092221,0.000000
2.660000,0.045799,-319.907013,-0.008636,-0.003346,-0.084979,0.203725,0.010378,-0.849794,-319.907013,-0.083739,0.000000
3.170000,0.061440,-319.995972,-0.008300,-0.003009,-0.076429,0.273297,0.013922,-0.764286,-319.995972,-0.075240,0.000000
3.680000,0.034630,-319.951477,-0.007968,-0.002675,-0.067938,0.154041,0.007847,-0.679385,-319.951477,-0.066742,0.000000
4.190000,0.006325,-320.040436,-0.007614,-0.002340,-0.059448,0.028134,0.001433,-0.594484,-320.040436,-0.058243,0.000000
4.700000,0.054733,-320.040436,-0.007282,-0.002006,-0.050941,0.243466,0.012403,-0.509409,-320.040436,-0.049744,0.000000
5.210000,0.061813,-320.084930,-0.006933,-0.001674,-0.042529,0.274960,0.014007,-0.425288,-320.084930,-0.041245,0.000000
5.720000,0.033508,-320.173889,-0.006584,-0.001340,-0.034047,0.149052,0.007593,-0.340472,-320.173889,-0.032747,0.000000
6.230000,0.019363,-320.173889,-0.006256,-0.001003,-0.025470,0.086133,0.004388,-0.254705,-320.173889,-0.024265,0.000000
6.740000,0.068886,-320.218353,-0.005907,-0.000666,-0.016928,0.306419,0.015610,-0.169283,-320.218353,-0.015766,0.000000
7.250000,0.052505,-320.307343,-0.005562,-0.000332,-0.008430,0.233556,0.011898,-0.084295,-320.307343,-0.007267,0.000000
7.760000,0.059204,-320.173889,-0.005217,0.000004,0.000104,0.263353,0.013416,0.001041,-320.173889,0.001231,0.000000
8.270000,0.061813,-320.307343,-0.004993,-0.000002,-0.000044,0.274960,0.014007,-0.000435,-320.307343,0.000182,0.000000
8.780001,0.130325,-320.262848,-0.004984,-0.000002,-0.000044,0.579716,0.029532,-0.000435,-320.262848,0.000477,0.000000
9.290001,0.110962,-320.351807,-0.004988,-0.000001,-0.000017,0.493583,0.025144,-0.000174,-320.351807,0.001327,0.000000
9.800000,0.268852,-320.440765,-0.004975,0.000048,0.001231,1.195915,0.060923,0.012314,-320.440765,0.002177,0.000000
10.310000,0.366043,-320.396301,-0.004937,0.000081,0.002046,1.628241,0.082947,0.020465,-320.396301,0.003027,0.000000
10.820001,0.492271,-320.529724,-0.004898,0.000113,0.002862,2.189733,0.111550,0.028618,-320.529724,0.003876,0.000000
11.330001,0.681068,-320.529724,-0.004872,0.000144,0.003651,3.029544,0.154332,0.036509,-320.529724,0.004726,0.000000
11.840000,0.918640,-320.529724,-0.004838,0.000180,0.004562,4.086316,0.208167,0.045616,-320.529724,0.005576,0.000000
12.350000,1.133499,-320.574219,-0.004807,0.000212,0.005394,5.042056,0.256855,0.053940,-320.574219,0.006426,0.000000
12.860001,1.373306,-320.485260,-0.004781,0.000245,0.006227,6.108771,0.311196,0.062265,-320.485260,0.007276,0.000000
13.370001,1.690567,-320.707672,-0.004751,0.000278,0.007051,7.520018,0.383088,0.070505,-320.707672,0.008126,0.000000
13.880001,2.069641,-320.707672,-0.004708,0.000318,0.008065,9.206223,0.468987,0.080650,-320.707672,0.008976,0.000000
14.390000,2.240936,-320.663177,-0.004678,0.000348,0.008846,9.968183,0.507803,0.088457,-320.663177,0.009826,0.000000
14.900001,2.641609,-320.796631,-0.004648,0.000384,0.009756,11.750464,0.598597,0.097561,-320.796631,0.010675,0.000000
15.410001,2.846039,-320.752136,-0.004605,0.000412,0.010476,12.659813,0.644922,0.104760,-320.752136,0.011525,0.000000
15.920001,3.191978,-320.841095,-0.004583,0.000449,0.011413,14.198629,0.723313,0.114126,-320.841095,0.012375,0.000000
16.430000,3.351723,-320.796631,-0.004549,0.000482,0.012245,14.909207,0.759511,0.122451,-320.796631,0.013225,0.000000
16.940001,3.744949,-320.841095,-0.004510,0.000519,0.013173,16.658367,0.848618,0.131731,-320.841095,0.014075,0.000000
17.450001,3.827240,-320.974548,-0.004467,0.000543,0.013780,17.024414,0.867265,0.137800,-320.974548,0.014925,0.000000
17.960001,4.178764,-320.930054,-0.004449,0.000583,0.014812,18.588072,0.946922,0.148122,-320.930054,0.015775,0.000000
18.470001,4.391388,-320.974548,-0.004398,0.000616,0.015653,19.533869,0.995103,0.156534,-320.974548,0.016625,0.000000
18.980001,4.644226,-321.063507,-0.004372,0.000648,0.016460,20.658550,1.052397,0.164599,-321.063507,0.017474,0.000000
19.490002,4.973404,-320.974548,-0.004337,0.000683,0.017344,22.122805,1.126989,0.173445,-320.974548,0.018324,0.000000
20.000000,5.169273,-321.107971,-0.004299,0.000718,0.018238,22.994076,1.171374,0.182377,-321.107971,0.019174,0.000000
20.510000,5.399399,-321.152466,-0.004277,0.000754,0.019148,24.017725,1.223521,0.191484,-321.152466,0.020024,0.000000
21.020000,5.649635,-321.107971,-0.004238,0.000785,0.019938,25.130833,1.280226,0.199375,-321.107971,0.020874,0.000000
21.530001,5.972107,-321.196960,-0.004195,0.000817,0.020753,26.565258,1.353299,0.207526,-321.196960,0.021724,0.000000
22.040001,6.213036,-321.196960,-0.004161,0.000853,0.021672,27.636963,1.407894,0.216719,-321.196960,0.022574,0.000000
22.550001,6.392143,-321.241425,-0.004118,0.000885,0.022470,28.433674,1.448480,0.224698,-321.241425,0.023424,0.000000
23.060001,6.417839,-321.285919,-0.004079,0.000910,0.023103,28.547974,1.454303,0.231028,-321.285919,0.024273,0.000000
23.570002,6.932457,-321.330383,-0.004061,0.000953,0.024213,30.837109,1.570917,0.242129,-321.330383,0.025123,0.000000
24.080002,7.054596,-321.374878,-0.004018,0.000983,0.024976,31.380409,1.598594,0.249760,-321.374878,0.025973,0.000000
24.590002,7.364410,-321.330383,-0.003988,0.001019,0.025887,32.758533,1.668799,0.258866,-321.330383,0.026823,0.000000
25.100000,7.332382,-321.419342,-0.003958,0.001046,0.026580,32.616066,1.661542,0.265804,-321.419342,0.027673,0.000000
25.610001,7.732681,-321.419342,-0.003923,0.001086,0.027586,34.396683,1.752251,0.275864,-321.419342,0.028523,0.000000
26.120001,7.869720,-321.463837,-0.003880,0.001117,0.028384,35.006264,1.783304,0.283843,-321.463837,0.029373,0.000000
26.630001,8.207458,-321.552795,-0.003842,0.001151,0.029234,36.508598,1.859837,0.292342,-321.552795,0.030223,0.000000
27.140001,8.452484,-321.508301,-0.003803,0.001183,0.030049,37.598526,1.915360,0.300492,-321.508301,0.031073,0.000000
27.650002,8.631218,-321.552795,-0.003768,0.001220,0.030995,38.393574,1.955862,0.309945,-321.552795,0.031931,0.000000
28.160002,8.696014,-321.597290,-0.003738,0.001251,0.031766,38.681805,1.970545,0.317664,-321.597290,0.032781,0.000000
28.670002,8.936562,-321.597290,-0.003695,0.001281,0.032529,39.751812,2.025054,0.325295,-321.597290,0.033631,0.000000
29.180002,9.477249,-321.641754,-0.003656,0.001320,0.033518,42.156910,2.147575,0.335183,-321.641754,0.034481,0.000000
29.690001,9.333885,-321.686249,-0.003622,0.001347,0.034221,41.519196,2.115089,0.342206,-321.686249,0.035331,0.000000
30.200001,9.517838,-321.641754,-0.003579,0.001381,0.035070,42.337456,2.156773,0.350705,-321.641754,0.036181,0.000000
30.710001,9.991493,-321.775208,-0.003553,0.001420,0.036068,44.444382,2.264105,0.360678,-321.775208,0.037030,0.000000
31.220001,10.247688,-321.775208,-0.003501,0.001456,0.036987,45.583996,2.322160,0.369871,-321.775208,0.037880,0.000000
31.730001,10.176567,-321.819672,-0.003466,0.001487,0.037759,45.267632,2.306043,0.377589,-321.819672,0.038730,0.000000
32.240002,10.338921,-321.819672,-0.003432,0.001519,0.038583,45.989815,2.342833,0.385828,-321.819672,0.039580,0.000000
32.750000,10.614105,-321.864166,-0.003393,0.001550,0.039381,47.213898,2.405190,0.393807,-321.864166,0.040430,0.000000
33.260002,10.823746,-321.908630,-0.003346,0.001583,0.040204,48.146427,2.452696,0.402045,-321.908630,0.041280,0.000000
33.770000,11.181595,-321.953125,-0.003316,0.001621,0.041167,49.738216,2.533786,0.411672,-321.953125,0.042130,0.000000
34.280003,11.430717,-321.908630,-0.003281,0.001655,0.042026,50.846371,2.590238,0.420258,-321.908630,0.042980,0.000000
34.790001,11.374115,-322.042084,-0.003260,0.001682,0.042728,50.594589,2.577411,0.427281,-322.042084,0.043829,0.000000
35.300003,11.977730,-321.997620,-0.003212,0.001724,0.043777,53.279602,2.714192,0.437774,-321.997620,0.044679,0.000000
35.810001,11.994858,-322.086578,-0.003169,0.001756,0.044610,53.355793,2.718074,0.446101,-322.086578,0.045529,0.000000
36.320004,12.275627,-322.042084,-0.003130,0.001791,0.045503,54.604717,2.781697,0.455033,-322.042084,0.046379,0.000000
36.830002,12.125938,-322.131042,-0.003087,0.001814,0.046084,53.938869,2.747777,0.460843,-322.131042,0.047229,0.000000
37.340000,12.668106,-322.175537,-0.003061,0.001853,0.047073,56.350552,2.870634,0.470729,-322.175537,0.048079,0.000000
37.850002,12.768646,-322.131042,-0.003018,0.001885,0.047888,56.797775,2.893417,0.478882,-322.131042,0.048929,0.000000
38.360001,13.196877,-322.264496,-0.002988,0.001923,0.048851,58.702637,2.990455,0.488507,-322.264496,0.049779,0.000000
38.870003,13.001755,-322.264496,-0.002940,0.001950,0.049519,57.834694,2.946240,0.495185,-322.264496,0.050628,0.000000
39.380001,13.343964,-322.308960,-0.002871,0.001988,0.050490,59.356915,3.023786,0.504899,-322.308960,0.051479,0.000000
39.890003,13.435196,-322.308960,-0.002850,0.002021,0.051331,59.762737,3.044459,0.513309,-322.308960,0.052328,0.000000
40.400002,13.667557,-322.308960,-0.002811,0.002053,0.052155,60.796329,3.097113,0.521549,-322.308960,0.053178,0.000000
40.910004,14.059662,-322.397919,-0.002759,0.002089,0.053048,62.540501,3.185965,0.530481,-322.397919,0.054028,0.000000
41.420002,14.210480,-322.442413,-0.002734,0.002125,0.053976,63.211372,3.220141,0.539762,-322.442413,0.054878,0.000000
41.930000,14.165794,-322.486908,-0.002682,0.002157,0.054791,63.012600,3.210015,0.547911,-322.486908,0.055728,0.000000
42.440002,14.045891,-322.575867,-0.002634,0.002184,0.055477,62.479244,3.182844,0.554765,-322.575867,0.056578,0.000000
42.950001,14.848351,-322.531372,-0.002600,0.002225,0.056526,66.048759,3.364684,0.565257,-322.531372,0.057428,0.000000
43.460003,14.805527,-322.620331,-0.002565,0.002259,0.057384,65.858269,3.354980,0.573841,-322.620331,0.058277,0.000000
43.970001,14.975700,-322.620331,-0.002539,0.002292,0.058217,66.615242,3.393542,0.582168,-322.620331,0.059127,0.000000
44.480003,14.877022,-322.664825,-0.002483,0.002320,0.058928,66.176300,3.371181,0.589280,-322.664825,0.059977,0.000000
44.990002,15.359619,-322.709290,-0.002445,0.002357,0.059873,68.322998,3.480539,0.598731,-322.709290,0.060827,0.000000
45.500004,15.359619,-322.709290,-0.002393,0.002390,0.060706,68.322998,3.480539,0.607057,-322.709290,0.061677,0.000000
46.010002,15.721565,-322.709290,-0.002354,0.002424,0.061582,69.933014,3.562558,0.615816,-322.709290,0.062527,0.000000
46.520000,15.819870,-322.798248,-0.002307,0.002458,0.062423,70.370293,3.584834,0.624229,-322.798248,0.063377,0.000000
47.030003,15.714485,-322.842743,-0.002264,0.002491,0.063273,69.901520,3.560953,0.632727,-322.842743,0.064227,0.000000
47.540001,15.583786,-322.887238,-0.002220,0.002520,0.064010,69.320145,3.531336,0.640100,-322.887238,0.065077,0.000000
48.050003,16.052231,-322.931702,-0.002182,0.002556,0.064921,71.403893,3.637487,0.649206,-322.931702,0.065926,0.000000
48.560001,15.991531,-322.931702,-0.002134,0.002587,0.065701,71.133881,3.623733,0.657010,-322.931702,0.066776,0.000000
49.070004,16.231712,-322.976196,-0.002091,0.002623,0.066620,72.202263,3.678159,0.666200,-322.976196,0.067626,0.000000
49.580002,16.043663,-322.976196,-0.002026,0.002653,0.067392,71.365776,3.635546,0.673921,-322.976196,0.068476,0.000000
50.090004,15.864555,-322.976196,-0.001979,0.002680,0.068068,70.569069,3.594960,0.680685,-322.976196,0.069326,0.000000
50.600002,16.617867,-323.020660,-0.001944,0.002725,0.069222,73.919960,3.765662,0.692218,-323.020660,0.070176,0.000000
51.110001,16.052231,-323.065155,-0.001897,0.002757,0.070037,71.403893,3.637487,0.700370,-323.065155,0.071026,0.000000
51.620003,15.804230,-323.154114,-0.001841,0.002786,0.070766,70.300728,3.581290,0.707656,-323.154114,0.071876,0.000000
52.130001,16.420509,-323.154114,-0.001815,0.002823,0.071711,73.042076,3.720941,0.717107,-323.154114,0.072725,0.000000
52.640003,16.353477,-323.198578,-0.001729,0.002861,0.072674,72.743904,3.705751,0.726736,-323.198578,0.073584,0.000000
53.150002,16.104736,-323.243073,-0.001677,0.002893,0.073488,71.637444,3.649385,0.734885,-323.243073,0.074434,0.000000
53.660004,16.016113,-323.243073,-0.001634,0.002924,0.074278,71.243233,3.629303,0.742776,-323.243073,0.075284,0.000000
54.170002,16.115906,-323.287567,-0.001591,0.002957,0.075102,71.687126,3.651917,0.751016,-323.287567,0.076134,0.000000
54.680004,16.396675,-323.287567,-0.001539,0.002992,0.075986,72.936050,3.715540,0.759861,-323.287567,0.076983,0.000000
55.190002,16.412315,-323.376526,-0.001500,0.003026,0.076854,73.005623,3.719084,0.768536,-323.376526,0.077834,0.000000
55.700001,16.439125,-323.465485,-0.001462,0.003057,0.077660,73.124878,3.725159,0.776598,-323.465485,0.078683,0.000000
56.210003,16.497963,-323.465485,-0.001423,0.003087,0.078406,73.386604,3.738492,0.784058,-323.465485,0.079533,0.000000
56.720001,16.855438,-323.465485,-0.001367,0.003127,0.079421,74.976730,3.819497,0.794205,-323.465485,0.080383,0.000000
57.230003,16.627174,-323.509949,-0.001324,0.003156,0.080175,73.961365,3.767771,0.801749,-323.509949,0.081233,0.000000
57.740002,17.199135,-323.554443,-0.001289,0.003195,0.081155,76.505569,3.897380,0.811548,-323.554443,0.082083,0.000000
58.250004,17.031570,-323.598907,-0.001250,0.003221,0.081823,75.760208,3.859409,0.818228,-323.598907,0.082933,0.000000
58.760002,17.236374,-323.643402,-0.001212,0.003256,0.082690,76.671219,3.905818,0.826899,-323.643402,0.083783,0.000000
59.270004,17.729027,-323.687866,-0.001155,0.003291,0.083592,78.862648,4.017455,0.835919,-323.687866,0.084632,0.000000
59.780003,17.879463,-323.643402,-0.001108,0.003324,0.084433,79.531822,4.051544,0.844329,-323.643402,0.085482,0.000000
60.290005,18.390358,-323.643402,-0.001078,0.003361,0.085378,81.804398,4.167315,0.853783,-323.643402,0.086332,0.000000
60.800003,18.581757,-323.776855,-0.001035,0.003396,0.086254,82.655785,4.210686,0.862542,-323.776855,0.087182,0.000000
61.310001,18.442863,-323.776855,-0.000996,0.003425,0.086991,82.037956,4.179213,0.869915,-323.776855,0.088032,0.000000
61.820004,18.893433,-323.776855,-0.000944,0.003457,0.087806,84.042183,4.281313,0.878063,-323.776855,0.088882,0.000000
62.330002,19.792336,-323.821320,-0.000910,0.003497,0.088812,88.040703,4.485007,0.888124,-323.821320,0.089732,0.000000
62.840004,19.849686,-323.821320,-0.000871,0.003530,0.089654,88.295815,4.498003,0.896538,-323.821320,0.090582,0.000000
63.350002,20.235466,-323.910278,-0.000811,0.003563,0.090503,90.011848,4.585422,0.905035,-323.910278,0.091432,0.000000
63.860004,19.769997,-323.865814,-0.000785,0.003585,0.091067,87.941338,4.479945,0.910674,-323.865814,0.092281,0.000000
64.370003,21.402481,-323.954773,-0.000750,0.003628,0.092143,95.202988,4.849871,0.921427,-323.954773,0.093131,0.000000
64.880005,21.906670,-323.999237,-0.000724,0.003662,0.093019,97.445732,4.964122,0.930185,-323.999237,0.093981,0.000000
65.389999,22.465599,-323.999237,-0.000677,0.003696,0.093877,99.931976,5.090777,0.938769,-323.999237,0.094831,0.000000
65.900002,22.974632,-324.043732,-0.000638,0.003728,0.094683,102.196266,5.206126,0.946835,-324.043732,0.095681,0.000000
66.410004,23.850082,-324.088196,-0.000612,0.003759,0.095490,106.090462,5.404506,0.954901,-324.088196,0.096531,0.000000
66.920006,24.718826,-324.043732,-0.000573,0.003795,0.096383,109.954834,5.601366,0.963833,-324.043732,0.097381,0.000000
67.430000,25.542885,-324.177185,-0.000539,0.003828,0.097225,113.620430,5.788100,0.972247,-324.177185,0.098231,0.000000
67.940002,26.833527,-324.177185,-0.000526,0.003866,0.098205,119.361488,6.080564,0.982046,-324.177185,0.099080,0.000000
68.450005,27.533966,-324.221649,-0.000483,0.003896,0.098959,122.477196,6.239286,0.989589,-324.221649,0.099930,0.000000
68.960007,27.975227,-324.310608,-0.000457,0.003923,0.099644,124.440025,6.339277,0.996440,-324.310608,0.100780,0.000000
69.470001,29.411835,-324.266144,-0.000427,0.003958,0.100529,130.830368,6.664817,1.005289,-324.266144,0.101630,0.000000
69.980003,31.180977,-324.310608,-0.000401,0.003998,0.101543,138.699905,7.065711,1.015432,-324.310608,0.102480,0.000000
70.490005,32.181915,-324.399567,-0.000388,0.004029,0.102332,143.152313,7.292526,1.023324,-324.399567,0.103330,0.000000
71.000000,33.079330,-324.355103,-0.000362,0.004059,0.103096,147.144211,7.495883,1.030958,-324.355103,0.104180,0.000000
71.510002,33.793175,-324.444061,-0.000328,0.004084,0.103729,150.319550,7.657643,1.037286,-324.444061,0.105030,0.000000
72.020004,36.498085,-324.399567,-0.000302,0.004129,0.104865,162.351593,8.270584,1.048649,-324.399567,0.105880,0.000000
72.530006,38.107849,-324.488525,-0.000285,0.004162,0.105723,169.512177,8.635363,1.057233,-324.488525,0.106729,0.000000
73.040001,39.343758,-324.488525,-0.000246,0.004193,0.106512,175.009781,8.915423,1.065124,-324.488525,0.107579,0.000000
73.550003,41.158699,-324.488525,-0.000241,0.004228,0.107380,183.083038,9.326694,1.073799,-324.488525,0.108429,0.000000
74.060005,43.313622,-324.533020,-0.000216,0.004266,0.108351,192.668610,9.815006,1.083511,-324.533020,0.109279,0.000000
74.570007,44.922638,-324.621979,-0.000194,0.004297,0.109140,199.825867,10.179615,1.091403,-324.621979,0.110129,0.000000
75.080002,46.665344,-324.621979,-0.000177,0.004328,0.109938,207.577820,10.574518,1.099381,-324.621979,0.110979,0.000000
75.590004,48.455711,-324.710937,-0.000155,0.004362,0.110805,215.541763,10.980221,1.108053,-324.710937,0.111829,0.000000
76.100006,50.428535,-324.666473,-0.000142,0.004391,0.111534,224.317322,11.427269,1.115339,-324.666473,0.112678,0.000000
76.610001,52.830338,-324.710937,-0.000121,0.004428,0.112470,235.001083,11.971525,1.124702,-324.710937,0.113528,0.000000
77.120003,54.770401,-324.755432,-0.000112,0.004457,0.113216,243.630905,12.411150,1.132162,-324.755432,0.114378,0.000000
77.630005,56.786797,-324.710937,-0.000082,0.004489,0.114032,252.600281,12.868073,1.140315,-324.710937,0.115237,0.000000
78.140007,60.020477,-324.799896,-0.000069,0.004532,0.115107,266.984406,13.600835,1.151068,-324.799896,0.116087,0.000000
78.650002,61.954208,-324.844391,-0.000078,0.004562,0.115887,275.586090,14.039024,1.158872,-324.844391,0.116937,0.000000
79.160004,64.608109,-324.888855,-0.000047,0.004596,0.116729,287.391205,14.640407,1.167286,-324.888855,0.117786,0.000000
79.670006,65.585587,-324.933350,-0.000034,0.004621,0.117379,291.739258,14.861906,1.173789,-324.933350,0.118636,0.000000
80.180000,65.526749,-324.933350,-0.000030,0.004614,0.117206,291.477539,14.848574,1.172055,-324.933350,294.500458,0.000000
80.690002,65.081390,-325.022308,-0.000017,0.004623,0.117431,289.496490,14.747654,1.174311,-325.022308,294.500458,0.000000
81.200005,65.302963,-325.066803,-0.000026,0.004630,0.117604,290.482086,14.797863,1.176044,-325.066803,294.500458,0.000000
81.710007,65.368866,-325.022308,-0.000009,0.004635,0.117726,290.775238,14.812798,1.177259,-325.022308,294.500458,0.000000
82.220001,65.302963,-325.111267,-0.000009,0.004638,0.117804,290.482086,14.797863,1.178039,-325.111267,294.500458,0.000000
82.730003,65.226242,-325.066803,-0.000017,0.004640,0.117856,290.140808,14.780478,1.178558,-325.066803,294.500458,0.000000
83.240005,65.374084,-325.155762,-0.000009,0.004644,0.117969,290.798462,14.813979,1.179685,-325.155762,294.500458,0.000000
83.750008,65.244125,-325.200226,-0.000009,0.004645,0.117977,290.220367,14.784530,1.179773,-325.200226,294.500458,0.000000
84.260002,65.212845,-325.200226,0.000000,0.004647,0.118029,290.081207,14.777442,1.180295,-325.200226,294.500458,0.000000
84.770004,65.272415,-325.333679,0.000004,0.004650,0.118099,290.346191,14.790941,1.180987,-325.333679,294.500458,0.000000
85.280006,65.202789,-325.289185,0.000000,0.004650,0.118099,290.036499,14.775164,1.180987,-325.289185,294.500458,0.000000
85.790001,65.076553,-325.289185,0.000009,0.004650,0.118116,289.474976,14.746557,1.181162,-325.289185,294.500458,0.000000
86.300003,64.964478,-325.378143,0.000004,0.004653,0.118177,288.976440,14.721162,1.181767,-325.378143,294.500458,0.000000
86.810005,65.324554,-325.422638,0.000009,0.004656,0.118255,290.578125,14.802755,1.182547,-325.422638,294.500458,0.000000
87.320007,65.262741,-325.467133,0.000009,0.004656,0.118255,290.303162,14.788749,1.182547,-325.467133,294.500458,0.000000
87.830002,65.172623,-325.467133,-0.000004,0.004656,0.118255,289.902313,14.768328,1.182547,-325.467133,294.500458,0.000000
88.340004,65.054962,-325.467133,0.000004,0.004656,0.118255,289.378937,14.741665,1.182547,-325.467133,294.500458,0.000000
88.850006,65.511856,-325.600555,0.000013,0.004662,0.118420,291.411285,14.845199,1.184197,-325.600555,294.500458,0.000000
89.360001,65.497330,-325.600555,0.000009,0.004662,0.118420,291.346680,14.841908,1.184197,-325.600555,294.500458,0.000000
89.870003,65.430313,-325.556091,0.000026,0.004662,0.118420,291.048584,14.826720,1.184197,-325.556091,294.500458,0.000000
90.380005,65.338333,-325.689514,0.000013,0.004662,0.118420,290.639435,14.805878,1.184197,-325.689514,294.500458,0.000000
90.890007,65.297745,-325.600555,0.000017,0.004662,0.118420,290.458862,14.796680,1.184197,-325.600555,294.500458,0.000000
91.400002,65.249329,-325.689514,0.000017,0.004662,0.118420,290.243500,14.785709,1.184197,-325.689514,294.500458,0.000000
91.910004,65.255295,-325.734009,0.000009,0.004664,0.118472,290.270050,14.787061,1.184716,-325.734009,294.500458,0.000000
92.420006,65.231094,-325.689514,0.000017,0.004665,0.118480,290.162415,14.781577,1.184803,-325.689514,294.500458,0.000000
92.930008,65.217682,-325.822968,0.000017,0.004665,0.118498,290.102753,14.778538,1.184977,-325.822968,294.500458,0.000000
93.440002,65.244125,-325.822968,0.000017,0.004666,0.118524,290.220367,14.784530,1.185238,-325.822968,294.500458,0.000000
93.950005,65.229599,-325.867462,0.000013,0.004666,0.118524,290.155762,14.781239,1.185238,-325.867462,294.500458,0.000000
94.460007,65.228485,-325.956421,0.000022,0.004667,0.118533,290.150787,14.780987,1.185325,-325.956421,294.500458,0.000000
94.970001,65.181931,-325.911926,0.000022,0.004667,0.118541,289.943695,14.770436,1.185408,-325.911926,294.500458,0.000000
95.480003,65.173370,-326.000885,0.000022,0.004668,0.118567,289.905640,14.768497,1.185669,-326.000885,294.500458,0.000000
95.990005,65.193848,-325.956421,0.000022,0.004668,0.118576,289.996704,14.773137,1.185756,-325.956421,294.500458,0.000000
96.500008,65.174118,-326.045380,0.000022,0.004669,0.118584,289.908966,14.768666,1.185844,-326.045380,294.500458,0.000000
97.010002,65.156616,-326.134338,0.000009,0.004669,0.118593,289.831116,14.764701,1.185931,-326.134338,294.500458,0.000000
97.520004,65.187897,-326.089844,0.000026,0.004670,0.118619,289.970245,14.771788,1.186192,-326.089844,294.500458,0.000000
98.030006,65.170761,-326.178802,0.000013,0.004670,0.118619,289.894012,14.767905,1.186192,-326.178802,294.500458,0.000000
98.540001,65.163315,-326.178802,0.000004,0.004670,0.118628,289.860901,14.766218,1.186279,-326.178802,294.500458,0.000000
99.050003,65.205017,-326.178802,0.000026,0.004672,0.118662,290.046417,14.775668,1.186623,-326.178802,294.500458,0.000000
99.560005,65.213593,-326.312256,0.000022,0.004672,0.118662,290.084534,14.777611,1.186623,-326.312256,294.500458,0.000000
100.070007,65.194229,-326.267761,0.000026,0.004672,0.118662,289.998413,14.773223,1.186623,-326.267761,294.500458,0.000000
100.580002,65.168533,-326.356750,0.000026,0.004672,0.118662,289.884125,14.767401,1.186623,-326.356750,294.500458,0.000000
101.090004,65.139481,-326.401215,0.000022,0.004672,0.118680,289.754883,14.760817,1.186797,-326.401215,294.500458,0.000000
101.600006,65.202423,-326.356750,0.000022,0.004674,0.118715,290.034851,14.775080,1.187146,-326.356750,294.500458,0.000000
102.110008,65.215454,-326.401215,0.000026,0.004674,0.118715,290.092834,14.778033,1.187146,-326.401215,294.500458,0.000000
102.620003,65.205399,-326.401215,0.000030,0.004674,0.118715,290.048096,14.775755,1.187146,-326.401215,294.500458,0.000000
103.130005,65.195709,-326.490173,0.000026,0.004674,0.118715,290.005005,14.773559,1.187146,-326.490173,294.500458,0.000000
103.640007,65.164429,-326.490173,0.000030,0.004674,0.118715,289.865845,14.766471,1.187146,-326.490173,294.500458,0.000000
104.150002,65.247101,-326.490173,0.000017,0.004677,0.118784,290.233612,14.785204,1.187838,-326.490173,294.500458,0.000000
104.660004,65.295135,-326.623627,0.000026,0.004677,0.118784,290.447266,14.796089,1.187838,-326.623627,294.500458,0.000000
105.170006,65.289917,-326.579132,0.000022,0.004677,0.118784,290.424042,14.794907,1.187838,-326.579132,294.500458,0.000000
105.680008,65.279877,-326.579132,0.000022,0.004677,0.118784,290.379395,14.792631,1.187838,-326.579132,294.500458,0.000000
106.190002,65.254547,-326.668091,0.000017,0.004677,0.118784,290.266724,14.786892,1.187838,-326.668091,294.500458,0.000000
106.700005,65.243011,-326.623627,0.000013,0.004677,0.118784,290.215424,14.784278,1.187838,-326.623627,294.500458,0.000000
107.210007,65.231461,-326.757080,0.000026,0.004677,0.118784,290.164032,14.781660,1.187838,-326.757080,294.500458,0.000000
107.720009,65.200180,-326.712585,0.000017,0.004677,0.118784,290.024872,14.774571,1.187838,-326.712585,294.500458,0.000000
108.230003,65.156616,-326.801544,0.000034,0.004677,0.118784,289.831116,14.764701,1.187838,-326.801544,294.500458,0.000000
108.740005,65.165176,-326.846039,0.000034,0.004678,0.118810,289.869171,14.766640,1.188099,-326.846039,294.500458,0.000000
109.250008,65.359192,-326.801544,0.000026,0.004680,0.118879,290.732208,14.810605,1.188792,-326.801544,294.500458,0.000000
109.760002,65.371094,-326.846039,0.000030,0.004680,0.118879,290.785156,14.813301,1.188792,-326.846039,294.500458,0.000000
110.270004,65.384506,-326.979462,0.000039,0.004680,0.118879,290.844818,14.816340,1.188792,-326.979462,294.500458,0.000000
110.780006,65.358063,-326.890503,0.000030,0.004680,0.118879,290.727173,14.810349,1.188792,-326.890503,294.500458,0.000000
111.290009,65.367004,-327.023956,0.000034,0.004680,0.118879,290.766968,14.812375,1.188792,-327.023956,294.500458,0.000000
111.800003,65.339828,-327.023956,0.000022,0.004680,0.118879,290.646088,14.806217,1.188792,-327.023956,294.500458,0.000000
112.310005,65.344284,-326.979462,0.000047,0.004680,0.118879,290.665894,14.807227,1.188792,-326.979462,294.500458,0.000000
112.820007,65.322327,-327.112915,0.000026,0.004680,0.118879,290.568207,14.802251,1.188792,-327.112915,294.500458,0.000000
113.330002,65.304077,-327.112915,0.000026,0.004680,0.118879,290.487030,14.798116,1.188792,-327.112915,294.500458,0.000000
113.840004,65.286942,-327.201874,0.000034,0.004680,0.118879,290.410828,14.794232,1.188792,-327.201874,294.500458,0.000000
114.350006,65.258652,-327.201874,0.000013,0.004680,0.118879,290.284973,14.787822,1.188792,-327.201874,294.500458,0.000000
114.860008,65.254547,-327.201874,0.000030,0.004680,0.118879,290.266724,14.786892,1.188792,-327.201874,294.500458,0.000000
115.370003,65.231461,-327.290833,0.000039,0.004680,0.118879,290.164032,14.781660,1.188792,-327.290833,294.500458,0.000000
115.880005,65.215073,-327.246368,0.000026,0.004681,0.118888,290.091125,14.777947,1.188879,-327.246368,294.500458,0.000000
116.390007,65.190506,-327.290833,0.000034,0.004681,0.118897,289.981842,14.772380,1.188966,-327.290833,294.500458,0.000000
116.900009,65.183792,-327.335327,0.000022,0.004681,0.118897,289.951996,14.770859,1.188966,-327.335327,294.500458,0.000000
117.410004,65.174484,-327.335327,0.000022,0.004681,0.118905,289.910583,14.768749,1.189053,-327.335327,294.500458,0.000000
117.920006,65.180817,-327.424286,0.000039,0.004682,0.118914,289.938751,14.770185,1.189140,-327.424286,294.500458,0.000000
118.430008,65.186401,-327.424286,0.000026,0.004682,0.118914,289.963593,14.771450,1.189140,-327.424286,294.500458,0.000000
118.940002,65.166672,-327.424286,0.000030,0.004682,0.118914,289.875824,14.766979,1.189140,-327.424286,294.500458,0.000000
119.450005,65.155502,-327.557709,0.000030,0.004682,0.118923,289.826141,14.764448,1.189227,-327.557709,294.500458,0.000000
119.960007,65.136505,-327.513245,0.000026,0.004683,0.118940,289.741638,14.760143,1.189398,-327.513245,294.500458,0.000000
120.470009,65.172256,-327.557709,0.000039,0.004683,0.118940,289.900665,14.768245,1.189398,-327.557709,294.500458,0.000000
120.980003,65.157364,-327.557709,0.000017,0.004683,0.118940,289.834442,14.764870,1.189398,-327.557709,294.500458,0.000000
121.490005,65.140610,-327.646698,0.000043,0.004683,0.118940,289.759918,14.761073,1.189398,-327.646698,294.500458,0.000000
122.000008,65.149170,-327.735657,0.000026,0.004683,0.118948,289.797974,14.763013,1.189485,-327.735657,294.500458,0.000000
122.510002,65.134644,-327.646698,0.000022,0.004683,0.118957,289.733368,14.759721,1.189572,-327.646698,294.500458,0.000000
123.020004,65.132782,-327.691162,0.000030,0.004683,0.118957,289.725098,14.759299,1.189572,-327.691162,294.500458,0.000000
123.530006,65.137253,-327.780121,0.000030,0.004684,0.118975,289.744965,14.760312,1.189746,-327.780121,294.500458,0.000000
124.040009,65.157364,-327.735657,0.000022,0.004684,0.118975,289.834442,14.764870,1.189746,-327.735657,294.500458,0.000000
124.550003,65.152145,-327.869080,0.000034,0.004684,0.118975,289.811218,14.763687,1.189746,-327.869080,294.500458,0.000000
125.060005,65.138748,-327.913574,0.000026,0.004684,0.118975,289.751617,14.760652,1.189746,-327.913574,294.500458,0.000000
125.570007,65.126831,-327.869080,0.000034,0.004684,0.118975,289.698608,14.757951,1.189746,-327.869080,294.500458,0.000000
126.080009,65.107468,-327.958038,0.000047,0.004684,0.118983,289.612488,14.753563,1.189833,-327.958038,294.500458,0.000000
126.590004,65.111557,-327.913574,0.000034,0.004685,0.118992,289.630676,14.754489,1.189920,-327.913574,294.500458,0.000000
127.100006,65.115280,-328.047028,0.000026,0.004685,0.119001,289.647247,14.755334,1.190007,-328.047028,294.500458,0.000000
127.610008,65.180817,-328.002533,0.000026,0.004686,0.119018,289.938751,14.770185,1.190181,-328.002533,294.500458,0.000000
128.120010,65.199432,-328.047028,0.000039,0.004686,0.119018,290.021545,14.774403,1.190181,-328.047028,294.500458,0.000000
128.630005,65.200180,-328.135986,0.000017,0.004686,0.119018,290.024872,14.774571,1.190181,-328.135986,294.500458,0.000000
129.139999,65.209488,-328.091492,0.000030,0.004686,0.119018,290.066284,14.776682,1.190181,-328.091492,294.500458,0.000000
129.650009,65.188644,-328.135986,0.000022,0.004686,0.119018,289.973572,14.771957,1.190181,-328.135986,294.500458,0.000000
130.160004,65.196091,-328.180450,0.000022,0.004686,0.119018,290.006683,14.773645,1.190181,-328.180450,294.500458,0.000000
130.670013,65.188263,-328.224945,0.000039,0.004686,0.119018,289.971863,14.771872,1.190181,-328.224945,294.500458,0.000000
131.180008,65.163696,-328.269409,0.000030,0.004686,0.119018,289.862610,14.766305,1.190181,-328.269409,294.500458,0.000000
131.690002,65.229233,-328.224945,0.000034,0.004687,0.119053,290.154114,14.781156,1.190525,-328.224945,294.500458,0.000000
132.200012,65.242630,-328.313904,0.000034,0.004687,0.119053,290.213715,14.784191,1.190525,-328.313904,294.500458,0.000000
132.710007,65.245987,-328.358368,0.000022,0.004687,0.119053,290.228638,14.784952,1.190525,-328.358368,294.500458,0.000000
133.220001,65.236679,-328.447357,0.000030,0.004687,0.119053,290.187256,14.782843,1.190525,-328.447357,294.500458,0.000000
133.730011,65.240768,-328.402863,0.000030,0.004687,0.119053,290.205444,14.783769,1.190525,-328.402863,294.500458,0.000000
134.240005,65.237045,-328.447357,0.000026,0.004687,0.119053,290.188873,14.782926,1.190525,-328.447357,294.500458,0.000000
134.750000,65.236679,-328.491821,0.000030,0.004687,0.119053,290.187256,14.782843,1.190525,-328.491821,294.500458,0.000000
135.260010,65.215454,-328.536316,0.000043,0.004687,0.119053,290.092834,14.778033,1.190525,-328.536316,294.500458,0.000000
135.770004,65.200180,-328.491821,0.000039,0.004687,0.119053,290.024872,14.774571,1.190525,-328.491821,294.500458,0.000000
136.280014,65.212845,-328.625275,0.000034,0.004687,0.119053,290.081207,14.777442,1.190525,-328.625275,294.500458,0.000000
136.790009,65.190125,-328.625275,0.000039,0.004687,0.119053,289.980164,14.772293,1.190525,-328.625275,294.500458,0.000000
137.300003,65.171509,-328.580780,0.000026,0.004687,0.119053,289.897339,14.768075,1.190525,-328.580780,294.500458,0.000000
137.810013,65.154007,-328.714233,0.000039,0.004687,0.119053,289.819489,14.764109,1.190525,-328.714233,294.500458,0.000000
138.320007,65.172256,-328.669739,0.000047,0.004689,0.119096,289.900665,14.768245,1.190961,-328.669739,294.500458,0.000000
138.830002,65.200928,-328.758698,0.000039,0.004689,0.119096,290.028198,14.774741,1.190961,-328.758698,294.500458,0.000000
139.340012,65.214325,-328.803192,0.000026,0.004689,0.119096,290.087799,14.777778,1.190961,-328.803192,294.500458,0.000000
139.850006,65.221405,-328.803192,0.000052,0.004689,0.119096,290.119293,14.779382,1.190961,-328.803192,294.500458,0.000000
140.360001,65.210602,-328.892151,0.000043,0.004689,0.119096,290.071259,14.776934,1.190961,-328.892151,1681.640747,0.000000
140.870010,65.119385,-328.847656,0.000039,0.004671,0.118654,289.665497,14.756263,1.186536,-328.847656,0.118376,0.000000
141.380005,65.074692,-328.892151,0.000043,0.004640,0.117864,289.466675,14.746137,1.178645,-328.892151,0.117526,0.000000
141.889999,65.005798,-328.981110,0.000039,0.004611,0.117128,289.160248,14.730524,1.171275,-328.981110,0.116676,0.000000
142.400009,64.957764,-328.981110,0.000030,0.004581,0.116347,288.946564,14.719640,1.163471,-328.981110,0.115827,0.000000
142.910004,64.968933,-329.070068,0.000039,0.004551,0.115584,288.996246,14.722170,1.155837,-329.070068,0.114977,0.000000
143.420013,64.920898,-328.981110,0.000034,0.004515,0.114682,288.782593,14.711287,1.146817,-328.981110,0.114127,0.000000
143.930008,64.902649,-329.025604,0.000060,0.004484,0.113901,288.701416,14.707150,1.139013,-329.025604,0.113277,0.000000
144.440002,64.701569,-329.114563,0.000052,0.004455,0.113164,287.806946,14.661586,1.131644,-329.114563,0.112427,0.000000
144.950012,63.560257,-329.070068,0.000052,0.004422,0.112323,282.730133,14.402961,1.123230,-329.070068,0.111577,0.000000
145.460007,62.103905,-329.114563,0.000060,0.004388,0.111447,276.251953,14.072946,1.114472,-329.114563,0.110727,0.000000
145.970001,60.386154,-329.203522,0.000043,0.004358,0.110701,268.611023,13.683698,1.107012,-329.203522,0.109878,0.000000
146.480011,58.345551,-329.203522,0.000069,0.004332,0.110025,259.533966,13.221291,1.100248,-329.203522,0.109027,0.000000
146.990005,56.116898,-329.292480,0.000065,0.004298,0.109166,249.620422,12.716270,1.091664,-329.292480,0.108178,0.000000
147.500000,52.668358,-329.247986,0.000060,0.004263,0.108291,234.280563,11.934820,1.082906,-329.247986,0.107328,0.000000
148.010010,49.609695,-329.292480,0.000073,0.004234,0.107553,220.674942,11.241717,1.075533,-329.292480,0.106478,0.000000
148.520004,47.039207,-329.381439,0.000065,0.004213,0.107015,209.240845,10.659236,1.070154,-329.381439,0.105628,0.000000
149.030014,42.029678,-329.381439,0.000056,0.004166,0.105810,186.957352,9.524061,1.058100,-329.381439,0.104778,0.000000
149.540009,38.518578,-329.425934,0.000060,0.004131,0.104917,171.339188,8.728435,1.049167,-329.425934,0.103928,0.000000
150.050003,34.765434,-329.425934,0.000056,0.004096,0.104050,154.644379,7.877960,1.040496,-329.425934,0.103078,0.000000
150.560013,31.328064,-329.470398,0.000056,0.004068,0.103330,139.354187,7.099041,1.033297,-329.470398,0.102228,0.000000
151.070007,27.978577,-329.470398,0.000034,0.004034,0.102463,124.454926,6.340036,1.024626,-329.470398,0.101379,0.000000
151.580002,23.380890,-329.514893,0.000043,0.003994,0.101457,104.003395,5.298185,1.014566,-329.514893,0.100529,0.000000
152.090012,19.848564,-329.559357,0.000043,0.003964,0.100694,88.290825,4.497749,1.006935,-329.559357,0.099679,0.000000
152.600006,16.180702,-329.559357,0.000030,0.003930,0.099818,71.975357,3.666600,0.998177,-329.559357,0.098829,0.000000
153.110001,12.292755,-329.603851,0.000043,0.003895,0.098942,54.680904,2.785578,0.989419,-329.603851,0.097979,0.000000
153.620010,8.862839,-329.692810,0.000034,0.003863,0.098109,39.423874,2.008348,0.981092,-329.692810,0.097129,0.000000
154.130005,5.814590,-329.692810,0.000030,0.003836,0.097433,25.864590,1.317605,0.974328,-329.692810,0.096279,0.000000
154.640015,3.123833,-329.692810,0.000030,0.003811,0.096791,13.895502,0.707871,0.967909,-329.692810,0.095430,0.000000
155.150009,-1.089191,-329.737305,0.000017,0.003764,0.095603,-4.844965,-0.246814,0.956029,-329.737305,0.094579,0.000000
155.660004,-0.058838,-329.737305,-0.000039,0.003729,0.094710,-0.261724,-0.013333,0.947096,-329.737305,0.093730,0.000000
156.170013,0.073730,-329.826263,-0.000082,0.003701,0.094007,0.327969,0.016708,0.940071,-329.826263,0.092880,0.000000
156.680008,0.014893,-329.826263,-0.000138,0.003661,0.092992,0.066245,0.003375,0.929924,-329.826263,0.092030,0.000000
157.190002,0.051384,-329.870728,-0.000203,0.003624,0.092056,0.228567,0.011644,0.920560,-329.870728,0.091180,0.000000
157.700012,0.051010,-329.959686,-0.000285,0.003596,0.091336,0.226904,0.011559,0.913361,-329.959686,0.090330,0.000000
158.210007,0.077080,-329.959686,-0.000341,0.003567,0.090608,0.342868,0.017467,0.906075,-329.959686,0.089480,0.000000
158.720001,0.072983,-330.004181,-0.000414,0.003533,0.089749,0.324644,0.016538,0.897491,-330.004181,0.088630,0.000000
159.230011,0.061066,-329.959686,-0.000483,0.003498,0.088856,0.271634,0.013838,0.888559,-329.959686,0.087781,0.000000
159.740005,0.080055,-330.093140,-0.000565,0.003468,0.088075,0.356103,0.018141,0.880755,-330.093140,0.086931,0.000000
160.250000,0.053246,-330.093140,-0.000647,0.003428,0.087069,0.236848,0.012066,0.870694,-330.093140,0.086081,0.000000
160.760010,0.065536,-330.048645,-0.000707,0.003400,0.086367,0.291521,0.014851,0.863670,-330.048645,0.085231,0.000000
161.270004,0.055481,-330.182098,-0.000802,0.003361,0.085378,0.246792,0.012572,0.853783,-330.182098,0.084381,0.000000
161.780014,0.047661,-330.182098,-0.000858,0.003326,0.084485,0.212006,0.010800,0.844851,-330.182098,0.083531,0.000000
162.290009,0.071121,-330.271057,-0.000888,0.003316,0.084233,0.316363,0.016116,0.842334,-330.271057,0.082681,0.000000
162.800003,0.036865,-330.271057,-0.000987,0.003256,0.082707,0.163985,0.008354,0.827073,-330.271057,0.081832,0.000000
163.310013,0.026436,-330.226593,-0.001030,0.003224,0.081901,0.117593,0.005990,0.819008,-330.226593,0.080981,0.000000
163.820007,0.046547,-330.315552,-0.001074,0.003195,0.081155,0.207051,0.010548,0.811548,-330.315552,0.080132,0.000000
164.330002,0.028297,-330.360016,-0.001112,0.003175,0.080652,0.125873,0.006412,0.806518,-330.360016,0.079282,0.000000
164.840012,0.024948,-330.404510,-0.001160,0.003140,0.079759,0.110975,0.005653,0.797585,-330.404510,0.078423,0.000000
165.350006,0.001862,-330.448975,-0.001229,0.003096,0.078631,0.008281,0.000422,0.786314,-330.448975,0.077573,0.000000
165.860001,0.050270,-330.404510,-0.001268,0.003063,0.077799,0.223612,0.011391,0.777987,-330.404510,0.076723,0.000000
166.370010,0.060326,-330.493469,-0.001306,0.003031,0.076983,0.268342,0.013670,0.769834,-330.493469,0.075873,0.000000
166.880005,0.026436,-330.493469,-0.001358,0.002991,0.075977,0.117593,0.005990,0.759774,-330.493469,0.075024,0.000000
167.390015,0.055107,-330.537933,-0.001397,0.002959,0.075171,0.245129,0.012487,0.751712,-330.537933,0.074174,0.000000
167.900009,0.084152,-330.626923,-0.001427,0.002932,0.074477,0.374328,0.019069,0.744771,-330.626923,0.073324,0.000000
168.410004,0.061066,-330.582428,-0.001479,0.002891,0.073428,0.271634,0.013838,0.734279,-330.582428,0.072474,0.000000
168.920013,0.031647,-330.671387,-0.001522,0.002858,0.072587,0.140772,0.007171,0.725865,-330.671387,0.071624,0.000000
169.430008,0.062553,-330.671387,-0.001552,0.002824,0.071719,0.278251,0.014175,0.717194,-330.671387,0.070774,0.000000
169.940002,0.031281,-330.715881,-0.001574,0.002794,0.070956,0.139143,0.007088,0.709564,-330.715881,0.069924,0.000000
170.450012,0.026810,-330.760345,-0.001630,0.002762,0.070159,0.119255,0.006075,0.701585,-330.760345,0.069075,0.000000
170.960007,0.039841,-330.715881,-0.001664,0.002723,0.069161,0.177220,0.009028,0.691612,-330.715881,0.068224,0.000000
171.470001,0.000374,-330.804840,-0.001690,0.002690,0.068337,0.001663,0.000085,0.683372,-330.804840,0.067375,0.000000
171.980011,0.001114,-330.804840,-0.001725,0.002658,0.067522,0.004955,0.000252,0.675220,-330.804840,0.066525,0.000000
172.490005,0.018616,-330.849304,-0.001759,0.002627,0.066716,0.082807,0.004218,0.667158,-330.849304,0.065675,0.000000
173.000015,0.054733,-330.893799,-0.001802,0.002589,0.065753,0.243466,0.012403,0.657529,-330.893799,0.064825,0.000000
173.510010,0.006325,-330.893799,-0.001828,0.002564,0.065120,0.028134,0.001433,0.651201,-330.893799,0.063975,0.000000
174.020004,0.024948,-330.938263,-0.001876,0.002524,0.064105,0.110975,0.005653,0.641053,-330.938263,0.063125,0.000000
174.530014,0.020477,-330.982758,-0.001927,0.002489,0.063221,0.091088,0.004640,0.632208,-330.982758,0.062275,0.000000
175.040009,-0.012291,-331.071716,-0.001957,0.002458,0.062440,-0.054673,-0.002785,0.624404,-331.071716,0.061426,0.000000
175.550003,0.014893,-331.071716,-0.001988,0.002430,0.061720,0.066245,0.003375,0.617205,-331.071716,0.060576,0.000000
176.060013,-0.001488,-331.071716,-0.002018,0.002397,0.060879,-0.006618,-0.000337,0.608791,-331.071716,0.059726,0.000000
176.570007,-0.018990,-331.160675,-0.002044,0.002357,0.059873,-0.084470,-0.004303,0.598731,-331.160675,0.058876,0.000000
177.080002,-0.026070,-331.116211,-0.002104,0.002324,0.059032,-0.115964,-0.005907,0.590321,-331.116211,0.058026,0.000000
177.590012,-0.017502,-331.160675,-0.002130,0.002293,0.058234,-0.077852,-0.003966,0.582342,-331.160675,0.057176,0.000000
178.100006,0.003723,-331.249634,-0.002173,0.002261,0.057419,0.016561,0.000844,0.574189,-331.249634,0.056326,0.000000
178.610016,-0.024948,-331.205170,-0.002207,0.002218,0.056326,-0.110975,-0.005653,0.563262,-331.205170,0.055477,0.000000
179.120010,-0.002235,-331.294128,-0.002238,0.002183,0.055459,-0.009944,-0.000507,0.554591,-331.294128,0.054626,0.000000
179.630005,0.001862,-331.294128,-0.002281,0.002161,0.054886,0.008281,0.000422,0.548865,-331.294128,0.053777,0.000000
180.140015,0.000740,-331.294128,-0.002302,0.002132,0.054141,0.003292,0.000168,0.541408,-331.294128,0.052927,0.000000
180.650009,-0.010056,-331.383087,-0.002354,0.002089,0.053066,-0.044729,-0.002279,0.530656,-331.383087,0.052077,0.000000
181.160004,0.020477,-331.383087,-0.002384,0.002055,0.052190,0.091088,0.004640,0.521897,-331.383087,0.051227,0.000000
181.670013,-0.011917,-331.427551,-0.002414,0.002024,0.051418,-0.053010,-0.002700,0.514176,-331.427551,0.050377,0.000000
182.180008,-0.005219,-331.427551,-0.002449,0.001994,0.050637,-0.023213,-0.001183,0.506372,-331.427551,0.049527,0.000000
182.690002,0.002235,-331.472046,-0.002483,0.001956,0.049692,0.009944,0.000507,0.496919,-331.472046,0.048677,0.000000
183.200012,0.007446,-331.516541,-0.002522,0.001923,0.048842,0.033123,0.001687,0.488420,-331.516541,0.047827,0.000000
183.710007,0.006699,-331.561005,-0.002552,0.001893,0.048088,0.029797,0.001518,0.480877,-331.561005,0.046978,0.000000
184.220001,0.020103,-331.649963,-0.002596,0.001849,0.046960,0.089425,0.004556,0.469601,-331.649963,0.046128,0.000000
184.730011,0.002975,-331.649963,-0.002621,0.001822,0.046284,0.013236,0.000674,0.462838,-331.649963,0.045278,0.000000
185.240005,0.023460,-331.649963,-0.002665,0.001789,0.045451,0.104357,0.005316,0.454513,-331.649963,0.044428,0.000000
185.750015,0.004837,-331.738922,-0.002708,0.001757,0.044627,0.021516,0.001096,0.446273,-331.738922,0.043578,0.000000
186.260010,0.023460,-331.694458,-0.002721,0.001725,0.043812,0.104357,0.005316,0.438122,-331.694458,0.042728,0.000000
186.770004,0.059952,-331.783417,-0.002751,0.001694,0.043023,0.266679,0.013585,0.430229,-331.783417,0.041878,0.000000
187.280014,0.048035,-331.827881,-0.002785,0.001657,0.042086,0.213669,0.010885,0.420863,-331.827881,0.041028,0.000000
187.790009,0.025688,-331.872375,-0.002841,0.001625,0.041271,0.114267,0.005821,0.412713,-331.872375,0.040179,0.000000
188.300003,0.036491,-331.872375,-0.002889,0.001583,0.040213,0.162322,0.008269,0.402132,-331.872375,0.039329,0.000000
188.810013,0.071121,-331.916870,-0.002915,0.001549,0.039337,0.316363,0.016116,0.393374,-331.916870,0.038479,0.000000
189.320007,0.050644,-332.005829,-0.002936,0.001525,0.038747,0.225275,0.011476,0.387475,-332.005829,0.037629,0.000000
189.830002,0.060692,-331.916870,-0.002971,0.001490,0.037854,0.269971,0.013753,0.378542,-331.916870,0.036770,0.000000
190.340012,0.023827,-332.005829,-0.003018,0.001452,0.036883,0.105986,0.005399,0.368830,-332.005829,0.035920,0.000000
190.850006,0.031647,-332.050293,-0.003048,0.001424,0.036181,0.140772,0.007171,0.361806,-332.050293,0.035070,0.000000
191.360016,0.024200,-331.961334,-0.003074,0.001386,0.035201,0.107649,0.005484,0.352007,-331.961334,0.034221,0.000000
191.870010,0.049149,-332.094788,-0.003100,0.001361,0.034559,0.218624,0.011137,0.345589,-332.094788,0.033371,0.000000
192.380005,0.022713,-332.139252,-0.003152,0.001319,0.033492,0.101031,0.005147,0.334922,-332.139252,0.032521,0.000000
192.890015,0.016754,-332.183746,-0.003182,0.001285,0.032634,0.074526,0.003797,0.326336,-332.183746,0.031671,0.000000
193.400009,0.023460,-332.228210,-0.003212,0.001260,0.032009,0.104357,0.005316,0.320092,-332.228210,0.030821,0.000000
193.910004,-0.000000,-332.228210,-0.003251,0.001221,0.031012,-0.000000,-0.000000,0.310119,-332.228210,0.029971,0.000000
194.420013,0.012283,-332.317200,-0.003268,0.001188,0.030171,0.054639,0.002783,0.301707,-332.317200,0.029121,0.000000
194.930008,0.005585,-332.228210,-0.003320,0.001152,0.029269,0.024842,0.001266,0.292688,-332.228210,0.028271,0.000000
195.440002,0.010796,-332.272705,-0.003337,0.001120,0.028436,0.048021,0.002446,0.284363,-332.272705,0.027422,0.000000
195.950012,-0.008942,-332.272705,-0.003380,0.001086,0.027586,-0.039774,-0.002026,0.275864,-332.272705,0.026572,0.000000
196.460007,-0.008194,-332.361664,-0.003423,0.001052,0.026728,-0.036449,-0.001857,0.267278,-332.361664,0.025722,0.000000
196.970016,0.010056,-332.361664,-0.003449,0.001023,0.025973,0.044729,0.002279,0.259733,-332.361664,0.024872,0.000000
197.480011,0.001114,-332.406158,-0.003492,0.000985,0.025011,0.004955,0.000252,0.250108,-332.406158,0.024022,0.000000
197.990005,-0.019363,-332.539581,-0.003523,0.000952,0.024187,-0.086133,-0.004388,0.241868,-332.539581,0.023172,0.000000
198.500015,-0.024208,-332.406158,-0.003570,0.000922,0.023415,-0.107683,-0.005486,0.234151,-332.406158,0.022322,0.000000
199.010010,-0.006332,-332.495117,-0.003600,0.000885,0.022487,-0.028168,-0.001435,0.224870,-332.495117,0.021472,0.000000
199.520004,-0.013039,-332.539581,-0.003617,0.000852,0.021629,-0.057999,-0.002955,0.216286,-332.539581,0.020623,0.000000
200.030014,-0.013039,-332.584076,-0.003665,0.000815,0.020692,-0.057999,-0.002955,0.206918,-332.584076,0.019773,0.000000
200.540009,-0.010429,-332.628540,-0.003691,0.000781,0.019842,-0.046392,-0.002363,0.198421,-332.628540,0.018923,0.000000
201.050003,-0.008942,-332.628540,-0.003734,0.000754,0.019148,-0.039774,-0.002026,0.191484,-332.628540,0.018073,0.000000
201.560013,-0.017876,-332.673035,-0.003760,0.000730,0.018533,-0.079515,-0.004051,0.185325,-332.673035,0.017223,0.000000
202.070007,-0.016014,-332.761993,-0.003798,0.000687,0.017457,-0.071234,-0.003629,0.174573,-332.761993,0.016373,0.000000
202.580017,-0.001862,-332.717499,-0.003837,0.000651,0.016538,-0.008281,-0.000422,0.165379,-332.717499,0.015523,0.000000
203.090012,0.004837,-332.806488,-0.003859,0.000625,0.015870,0.021516,0.001096,0.158701,-332.806488,0.014673,0.000000
203.600006,-0.009308,-332.761993,-0.003915,0.000584,0.014838,-0.041403,-0.002109,0.148381,-332.761993,0.013824,0.000000
204.110016,-0.004471,-332.806488,-0.003928,0.000554,0.014066,-0.019887,-0.001013,0.140664,-332.806488,0.012974,0.000000
204.620010,0.014893,-332.895447,-0.003962,0.000524,0.013321,0.066245,0.003375,0.133206,-332.895447,0.012124,0.000000
205.130005,-0.024948,-332.850952,-0.003997,0.000484,0.012306,-0.110975,-0.005653,0.123058,-332.850952,0.011274,0.000000
205.640015,-0.002983,-332.939911,-0.004049,0.000443,0.011256,-0.013269,-0.000676,0.112565,-332.939911,0.010424,0.000000
206.150009,-0.007080,-332.939911,-0.004079,0.000418,0.010623,-0.031494,-0.001604,0.106234,-332.939911,0.009574,0.000000
206.660004,0.005959,-332.984406,-0.004109,0.000383,0.009730,0.026505,0.001350,0.097302,-332.984406,0.008724,0.000000
207.170013,0.014893,-333.073364,-0.004130,0.000366,0.009297,0.066245,0.003375,0.092966,-333.073364,0.007874,0.000000
207.680008,0.004463,-332.984406,-0.004178,0.000319,0.008091,0.019853,0.001011,0.080912,-332.984406,0.007024,0.000000
208.190002,0.040588,-333.073364,-0.004208,0.000291,0.007389,0.180546,0.009197,0.073887,-333.073364,0.006174,0.000000
208.700012,0.027557,-333.028870,-0.004255,0.000249,0.006331,0.122581,0.006245,0.063306,-333.028870,0.005325,0.000000
209.210007,0.033142,-333.162323,-0.004273,0.000221,0.005611,0.147423,0.007510,0.056109,-333.162323,0.004475,0.000000
209.720016,0.024200,-333.162323,-0.004337,0.000180,0.004579,0.107649,0.005484,0.045788,-333.162323,0.003625,0.000000
210.230011,0.036491,-333.162323,-0.004376,0.000150,0.003807,0.162322,0.008269,0.038070,-333.162323,0.002775,0.000000
210.740005,0.033508,-333.251282,-0.004406,0.000119,0.003018,0.149052,0.007593,0.030179,-333.251282,0.001925,0.000000
211.250015,0.047287,-333.340240,-0.004432,0.000077,0.001960,0.210343,0.010715,0.019598,-333.340240,0.001075,0.000000
211.760010,0.013031,-333.295776,-0.004462,0.000047,0.001188,0.057965,0.002953,0.011881,-333.295776,0.000225,0.000000
212.270004,0.031647,-333.384735,-0.004493,0.000023,0.000590,0.140772,0.007171,0.005897,-333.384735,-0.000625,0.000000
212.500015,0.029045,-333.384735,-0.004506,0.000002,0.000043,0.129199,0.006582,0.000433,-333.384735,-0.000000,0.000000