File: Data/compression 10/AutoHeating-17-10-1-240424_04242024_224404.csv
Time (sec),S:Load (lbs),S:HL1 (DIM),S:LVDT (in),S:Position (in),Ch:Position (mm),Ch:Load (N),Ch:Stress (MPa),Ch:Strain (mm/mm),Ch:HL1 (DIM),Set Point (),Cycles ()
0.110000,-0.002975,-116.406647,-0.021545,-0.000000,-0.000000,-0.013236,-0.000674,-0.000000,-116.406647,-0.000173,0.000000
0.390000,-0.018616,-116.495613,-0.021592,-0.000000,-0.000000,-0.082807,-0.004218,-0.000000,-116.495613,0.000503,0.000000
0.670000,-0.006332,-116.540092,-0.021571,0.000170,0.004328,-0.028168,-0.001435,0.043276,-116.540092,0.005169,0.000000
0.950000,-0.013779,-116.584572,-0.021502,0.000347,0.008820,-0.061291,-0.003122,0.088203,-116.584572,0.009835,0.000000
1.230000,0.017876,-116.629051,-0.021299,0.000526,0.013364,0.079515,0.004051,0.133645,-116.629051,0.014501,0.000000
1.510000,0.039474,-116.629051,-0.021118,0.000712,0.018074,0.175591,0.008945,0.180736,-116.629051,0.019166,0.000000
1.790000,0.011169,-116.762497,-0.020924,0.000900,0.022852,0.049684,0.002531,0.228517,-116.762497,0.023832,0.000000
2.070000,0.045807,-116.851456,-0.020734,0.001077,0.027361,0.203759,0.010380,0.273610,-116.851456,0.028497,0.000000
2.350000,-0.013031,-116.895943,-0.020566,0.001264,0.032097,-0.057965,-0.002953,0.320967,-116.895943,0.033163,0.000000
2.630000,0.014893,-116.895943,-0.020385,0.001446,0.036719,0.066245,0.003375,0.367188,-116.895943,0.037829,0.000000
2.910000,-0.003723,-116.984901,-0.020152,0.001633,0.041471,-0.016561,-0.000844,0.414711,-116.984901,0.042495,0.000000
3.190000,0.005585,-117.029381,-0.019997,0.001812,0.046024,0.024842,0.001266,0.460243,-117.029381,0.047160,0.000000
3.470000,0.037239,-117.073860,-0.019777,0.002000,0.050802,0.165648,0.008438,0.508024,-117.073860,0.051826,0.000000
3.750000,0.013031,-117.118347,-0.019587,0.002187,0.055555,0.057965,0.002953,0.555547,-117.118347,0.056491,0.000000
4.030000,0.053993,-117.162827,-0.019415,0.002367,0.060125,0.240174,0.012235,0.601253,-117.162827,0.061157,0.000000
4.310000,-0.000740,-117.207306,-0.019216,0.002547,0.064704,-0.003292,-0.000168,0.647043,-117.207306,0.065823,0.000000
4.590000,0.031281,-117.296265,-0.019027,0.002736,0.069482,0.139143,0.007088,0.694823,-117.296265,0.070488,0.000000
4.870000,-0.048035,-117.340752,-0.018863,0.002916,0.074070,-0.213669,-0.010885,0.740704,-117.340752,0.075154,0.000000
5.150000,0.009682,-117.385231,-0.018665,0.003099,0.078710,0.043066,0.002194,0.787099,-117.385231,0.079820,0.000000
5.430000,0.032394,-117.429710,-0.018479,0.003286,0.083471,0.144098,0.007341,0.834706,-117.429710,0.084468,0.000000
5.710000,0.027931,-117.429710,-0.018289,0.003468,0.088076,0.124244,0.006329,0.880760,-117.429710,0.089134,0.000000
5.990000,0.057350,-117.607635,-0.018095,0.003655,0.092828,0.255106,0.012996,0.928283,-117.607635,0.093800,0.000000
6.270000,0.045807,-117.607635,-0.017927,0.003835,0.097398,0.203759,0.010380,0.973982,-117.607635,0.098465,0.000000
6.550000,0.032768,-117.652115,-0.017733,0.004020,0.102099,0.145760,0.007425,1.020991,-117.652115,0.103131,0.000000
6.830000,-0.013405,-117.696594,-0.017535,0.004199,0.106652,-0.059628,-0.003038,1.066515,-117.696594,0.107797,0.000000
7.110000,0.031281,-117.785561,-0.017345,0.004384,0.111343,0.139143,0.007088,1.113433,-117.785561,0.112462,0.000000
7.390000,-0.020103,-117.874519,-0.017168,0.004571,0.116113,-0.089425,-0.004556,1.161130,-117.874519,0.117128,0.000000
7.670001,0.049896,-117.918999,-0.017009,0.004747,0.120579,0.221950,0.011307,1.205792,-117.918999,0.121793,0.000000
7.950000,0.050644,-117.874519,-0.016806,0.004939,0.125453,0.225275,0.011476,1.254534,-117.874519,0.126459,0.000000
8.230000,0.033516,-117.963486,-0.016617,0.005122,0.130093,0.149086,0.007595,1.300929,-117.963486,0.131125,0.000000
8.510000,0.034630,-117.963486,-0.016427,0.005305,0.134750,0.154041,0.007847,1.347498,-117.963486,0.135791,0.000000
8.790000,0.026070,-118.096924,-0.016237,0.005486,0.139337,0.115964,0.005907,1.393371,-118.096924,0.140456,0.000000
9.070001,0.022713,-118.185890,-0.016065,0.005675,0.144133,0.101031,0.005147,1.441333,-118.185890,0.145122,0.000000
9.350000,-0.034256,-118.185890,-0.015918,0.005853,0.148660,-0.152378,-0.007763,1.486601,-118.185890,0.149787,0.000000
9.630000,0.077454,-118.230370,-0.015703,0.006030,0.153161,0.344531,0.017551,1.531611,-118.230370,0.154453,0.000000
9.910001,0.014153,-118.230370,-0.015534,0.006223,0.158069,0.062954,0.003207,1.580693,-118.230370,0.159119,0.000000
10.190001,0.056229,-118.274849,-0.015336,0.006406,0.162710,0.250117,0.012742,1.627096,-118.274849,0.163785,0.000000
10.470000,0.059578,-118.452774,-0.015155,0.006594,0.167488,0.265016,0.013501,1.674877,-118.452774,0.168451,0.000000
10.750001,0.046173,-118.408295,-0.014974,0.006778,0.172154,0.205388,0.010463,1.721537,-118.408295,0.173098,0.000000
11.030001,0.052505,-118.497253,-0.014789,0.006960,0.176784,0.233556,0.011898,1.767841,-118.497253,0.177764,0.000000
11.310000,0.027557,-118.541733,-0.014594,0.007138,0.181294,0.122581,0.006245,1.812942,-118.541733,0.182430,0.000000
11.590000,0.031281,-118.586212,-0.014422,0.007325,0.186055,0.139143,0.007088,1.860548,-118.586212,0.187096,0.000000
11.870001,0.031281,-118.630699,-0.014245,0.007504,0.190599,0.139143,0.007088,1.905990,-118.630699,0.191761,0.000000
12.150001,0.094215,-118.719658,-0.014051,0.007687,0.195239,0.419091,0.021350,1.952385,-118.719658,0.196427,0.000000
12.430000,0.036491,-118.675179,-0.013857,0.007877,0.200070,0.162322,0.008269,2.000695,-118.675179,0.201093,0.000000
12.710001,0.066658,-118.808617,-0.013672,0.008059,0.204700,0.296510,0.015105,2.047000,-118.808617,0.205758,0.000000
12.990001,0.036125,-118.853104,-0.013473,0.008245,0.209427,0.160693,0.008186,2.094266,-118.853104,0.210424,0.000000
13.270000,0.042824,-118.942062,-0.013323,0.008426,0.214015,0.190490,0.009704,2.140146,-118.942062,0.215090,0.000000
13.550000,0.026810,-118.942062,-0.013146,0.008613,0.218767,0.119255,0.006075,2.187669,-118.942062,0.219756,0.000000
13.830001,0.024948,-119.031029,-0.012965,0.008790,0.223268,0.110975,0.005653,2.232679,-119.031029,0.224421,0.000000
14.110001,0.077454,-119.031029,-0.012732,0.008974,0.227942,0.344531,0.017551,2.279423,-119.031029,0.229087,0.000000
14.390000,0.034256,-119.031029,-0.012564,0.009163,0.232729,0.152378,0.007763,2.327294,-119.031029,0.233752,0.000000
14.670001,0.071869,-119.208946,-0.012365,0.009345,0.237352,0.319689,0.016286,2.373515,-119.208946,0.238418,0.000000
14.950001,0.019737,-119.253433,-0.012184,0.009528,0.242008,0.087796,0.004473,2.420084,-119.253433,0.243083,0.000000
15.230000,0.067398,-119.297913,-0.011982,0.009714,0.246743,0.299802,0.015273,2.467434,-119.297913,0.247749,0.000000
15.510001,0.037613,-119.342392,-0.011814,0.009896,0.251357,0.167311,0.008523,2.513572,-119.342392,0.252415,0.000000
15.790001,0.029419,-119.342392,-0.011624,0.010077,0.255962,0.130862,0.006666,2.559618,-119.342392,0.257081,0.000000
16.070002,0.084160,-119.475838,-0.011438,0.010262,0.260663,0.374362,0.019071,2.606627,-119.475838,0.261729,0.000000
16.350000,0.055489,-119.564796,-0.011279,0.010446,0.265320,0.246826,0.012574,2.653196,-119.564796,0.266395,0.000000
16.630001,0.101662,-119.475838,-0.011068,0.010635,0.270124,0.452214,0.023037,2.701242,-119.475838,0.271061,0.000000
16.910002,0.073730,-119.520317,-0.010891,0.010815,0.274702,0.327969,0.016708,2.747024,-119.520317,0.275726,0.000000
17.190001,0.077080,-119.609276,-0.010697,0.010996,0.279299,0.342868,0.017467,2.792988,-119.609276,0.280392,0.000000
17.470001,0.016388,-119.698242,-0.010507,0.011181,0.284000,0.072897,0.003714,2.839996,-119.698242,0.285057,0.000000
17.750000,0.053993,-119.831680,-0.010343,0.011363,0.288630,0.240174,0.012235,2.886300,-119.831680,0.289723,0.000000
18.030001,0.050644,-119.742722,-0.010158,0.011552,0.293409,0.225275,0.011476,2.934088,-119.742722,0.294389,0.000000
18.310001,0.064796,-119.787201,-0.009977,0.011731,0.297979,0.288229,0.014683,2.979787,-119.787201,0.299054,0.000000
18.590000,0.098305,-119.831680,-0.009779,0.011921,0.302783,0.437281,0.022276,3.027833,-119.831680,0.303720,0.000000
18.870001,0.063675,-119.920647,-0.009597,0.012103,0.307414,0.283240,0.014429,3.074145,-119.920647,0.308386,0.000000
19.150002,0.090118,-119.965126,-0.009416,0.012285,0.312028,0.400867,0.020421,3.120283,-119.965126,0.313052,0.000000
19.430000,0.052132,-120.054085,-0.009231,0.012465,0.316616,0.231893,0.011813,3.166156,-120.054085,0.317717,0.000000
19.710001,0.073357,-120.098564,-0.009058,0.012650,0.321307,0.326307,0.016623,3.213073,-120.098564,0.322383,0.000000
19.990002,-0.013779,-120.143051,-0.008864,0.012834,0.325973,-0.061291,-0.003122,3.259733,-120.143051,0.327048,0.000000
20.270000,0.088997,-120.187531,-0.008679,0.013012,0.330500,0.395878,0.020167,3.305001,-120.187531,0.331714,0.000000
20.550001,0.074852,-120.276489,-0.008489,0.013203,0.335357,0.332958,0.016962,3.353568,-120.276489,0.336379,0.000000
20.830002,0.104263,-120.276489,-0.008313,0.013389,0.340074,0.463786,0.023626,3.400743,-120.276489,0.341046,0.000000
21.110001,0.110222,-120.320976,-0.008136,0.013575,0.344809,0.490291,0.024977,3.448092,-120.320976,0.345694,0.000000
21.390001,0.055489,-120.365456,-0.007959,0.013753,0.349328,0.246826,0.012574,3.493276,-120.365456,0.350359,0.000000
21.670000,0.081551,-120.498894,-0.007743,0.013939,0.354063,0.362755,0.018480,3.540625,-120.498894,0.355025,0.000000
21.950001,0.017502,-120.543381,-0.007593,0.014117,0.358572,0.077852,0.003966,3.585719,-120.543381,0.359691,0.000000
22.230001,0.105011,-120.587860,-0.007390,0.014299,0.363186,0.467112,0.023796,3.631856,-120.587860,0.364357,0.000000
22.510000,0.072617,-120.632339,-0.007187,0.014485,0.367921,0.323015,0.016455,3.679206,-120.632339,0.369022,0.000000
22.790001,0.102028,-120.632339,-0.007002,0.014669,0.372604,0.453843,0.023120,3.726040,-120.632339,0.373688,0.000000
23.070002,0.094955,-120.721298,-0.006812,0.014857,0.377374,0.422383,0.021517,3.773737,-120.721298,0.378353,0.000000
23.350000,0.099800,-120.810265,-0.006631,0.015041,0.382048,0.443933,0.022615,3.820481,-120.810265,0.383019,0.000000
23.630001,0.087135,-120.810265,-0.006441,0.015224,0.386688,0.387597,0.019745,3.866876,-120.810265,0.387685,0.000000
23.910002,0.070007,-120.854744,-0.006273,0.015402,0.391214,0.311408,0.015864,3.912143,-120.854744,0.392351,0.000000
24.190001,0.067032,-120.899223,-0.006092,0.015589,0.395949,0.298173,0.015190,3.959492,-120.899223,0.397017,0.000000
24.470001,0.029419,-120.988190,-0.005902,0.015770,0.400546,0.130862,0.006666,4.005456,-120.988190,0.401682,0.000000
24.750002,0.126236,-121.032669,-0.005730,0.015949,0.405099,0.561526,0.028605,4.050988,-121.032669,0.406348,0.000000
25.030001,0.070755,-121.121628,-0.005558,0.016140,0.409956,0.314734,0.016033,4.099556,-121.121628,0.411013,0.000000
25.310001,0.110222,-121.121628,-0.005372,0.016323,0.414613,0.490291,0.024977,4.146125,-121.121628,0.415679,0.000000
25.590002,0.107246,-121.121628,-0.005178,0.016508,0.419304,0.477056,0.024302,4.193043,-121.121628,0.420344,0.000000
25.870001,0.120277,-121.255074,-0.004988,0.016692,0.423979,0.535021,0.027255,4.239786,-121.255074,0.425010,0.000000
26.150002,0.571594,-121.255074,-0.004799,0.016876,0.428661,2.542578,0.129525,4.286613,-121.255074,0.429676,0.000000
26.430000,0.728737,-121.299553,-0.004756,-0.000006,-0.000156,3.241584,0.165134,-0.001559,-121.299553,0.000052,0.000000
26.710001,0.700806,-121.388512,-0.004773,-0.000006,-0.000156,3.117339,0.158805,-0.001559,-121.388512,0.000052,0.000000
26.990002,0.679207,-121.432999,-0.004773,-0.000006,-0.000156,3.021263,0.153910,-0.001559,-121.432999,0.000459,0.000000
27.270000,0.651649,-121.432999,-0.004751,-0.000006,-0.000156,2.898682,0.147666,-0.001559,-121.432999,0.000928,0.000000
27.550001,0.983063,-121.521957,-0.004764,0.000023,0.000572,4.372881,0.222765,0.005723,-121.521957,0.001397,0.000000
27.830002,1.263832,-121.566437,-0.004738,0.000043,0.001101,5.621806,0.286388,0.011014,-121.566437,0.001856,0.000000
28.110001,1.423210,-121.610924,-0.004730,0.000056,0.001431,6.330755,0.322504,0.014314,-121.610924,0.002325,0.000000
28.390001,1.691315,-121.655403,-0.004734,0.000076,0.001934,7.523344,0.383257,0.019341,-121.655403,0.002792,0.000000
28.670002,2.000015,-121.744362,-0.004712,0.000098,0.002481,8.896512,0.453210,0.024806,-121.744362,0.003261,0.000000
28.950001,2.363823,-121.788841,-0.004674,0.000117,0.002975,10.514810,0.535650,0.029749,-121.788841,0.003729,0.000000
29.230001,2.506065,-121.922287,-0.004674,0.000131,0.003322,11.147535,0.567883,0.033216,-121.922287,0.004189,0.000000
29.510002,2.900780,-121.922287,-0.004656,0.000150,0.003799,12.903313,0.657326,0.037985,-121.922287,0.004657,0.000000
29.790001,3.345024,-121.966766,-0.004635,0.000170,0.004328,14.879411,0.757993,0.043276,-121.966766,0.005126,0.000000
30.070002,3.678299,-122.011246,-0.004631,0.000186,0.004727,16.361891,0.833514,0.047266,-122.011246,0.005594,0.000000
30.350002,3.835808,-122.011246,-0.004605,0.000202,0.005143,17.062525,0.869206,0.051429,-122.011246,0.006062,0.000000
30.630001,4.463257,-122.100212,-0.004587,0.000227,0.005758,19.853558,1.011388,0.057583,-122.100212,0.006521,0.000000
30.910002,4.840096,-122.144691,-0.004570,0.000243,0.006184,21.529819,1.096781,0.061838,-122.144691,0.006990,0.000000
31.190001,5.120499,-122.233650,-0.004570,0.000261,0.006626,22.777115,1.160322,0.066258,-122.233650,0.007459,0.000000
31.470001,5.528618,-122.278137,-0.004553,0.000278,0.007068,24.592520,1.252803,0.070679,-122.278137,0.007926,0.000000
31.750002,5.925934,-122.278137,-0.004536,0.000294,0.007467,26.359871,1.342836,0.074668,-122.278137,0.008395,0.000000
32.030003,6.156059,-122.367096,-0.004518,0.000308,0.007814,27.383520,1.394983,0.078135,-122.367096,0.008863,0.000000
32.310001,6.639778,-122.411575,-0.004518,0.000327,0.008317,29.535208,1.504595,0.083169,-122.411575,0.009323,0.000000
32.590000,7.220673,-122.456055,-0.004497,0.000352,0.008950,32.119156,1.636228,0.089498,-122.456055,0.009792,0.000000
32.870003,7.517830,-122.500542,-0.004475,0.000371,0.009418,33.440979,1.703565,0.094183,-122.500542,0.010259,0.000000
33.150002,7.654114,-122.456055,-0.004454,0.000384,0.009757,34.047199,1.734447,0.097567,-122.456055,0.010728,0.000000
33.430000,8.198151,-122.633980,-0.004445,0.000404,0.010259,36.467194,1.857728,0.102593,-122.633980,0.011196,0.000000
33.710003,8.685593,-122.678467,-0.004428,0.000426,0.010814,38.635445,1.968183,0.108142,-122.678467,0.011656,0.000000
33.990002,8.779053,-122.767426,-0.004411,0.000437,0.011109,39.051178,1.989362,0.111094,-122.767426,0.012124,0.000000
34.270000,9.382301,-122.811905,-0.004411,0.000460,0.011690,41.734562,2.126060,0.116900,-122.811905,0.012592,0.000000
34.550003,9.750198,-122.811905,-0.004372,0.000481,0.012219,43.371048,2.209426,0.122192,-122.811905,0.013061,0.000000
34.830002,10.061508,-122.856384,-0.004359,0.000499,0.012679,44.755825,2.279970,0.126786,-122.856384,0.013529,0.000000
35.110001,10.201889,-122.945351,-0.004346,0.000514,0.013061,45.380268,2.311781,0.130609,-122.945351,0.013997,0.000000
35.390003,10.643524,-122.989830,-0.004337,0.000535,0.013581,47.344761,2.411857,0.135810,-122.989830,0.014457,0.000000
35.670002,10.990944,-122.989830,-0.004312,0.000553,0.014040,48.890160,2.490583,0.140404,-122.989830,0.014925,0.000000
35.950001,11.277672,-122.989830,-0.004307,0.000567,0.014396,50.165588,2.555557,0.143962,-122.989830,0.015393,0.000000
36.230003,11.950180,-123.078789,-0.004281,0.000593,0.015056,53.157055,2.707949,0.150556,-123.078789,0.015862,0.000000
36.510002,12.197807,-123.167755,-0.004247,0.000612,0.015550,54.258556,2.764063,0.155499,-123.167755,0.016330,0.000000
36.790001,12.354202,-123.256714,-0.004251,0.000629,0.015975,54.954235,2.799502,0.159745,-123.256714,0.016790,0.000000
37.070004,12.694176,-123.301193,-0.004238,0.000649,0.016486,56.466515,2.876541,0.164862,-123.301193,0.017258,0.000000
37.350002,13.082191,-123.345680,-0.004225,0.000667,0.016954,58.192493,2.964467,0.169541,-123.345680,0.017726,0.000000
37.630001,13.308220,-123.390160,-0.004195,0.000685,0.017388,59.197918,3.015686,0.173878,-123.390160,0.018195,0.000000
37.910004,13.330566,-123.390160,-0.004174,0.000695,0.017648,59.297321,3.020750,0.176482,-123.390160,0.018663,0.000000
38.190002,14.047379,-123.479118,-0.004165,0.000721,0.018325,62.485859,3.183182,0.183249,-123.479118,0.019131,0.000000
38.470001,14.337456,-123.523598,-0.004161,0.000739,0.018775,63.776188,3.248914,0.187753,-123.523598,0.019591,0.000000
38.750000,14.545990,-123.568085,-0.004139,0.000758,0.019244,64.703796,3.296168,0.192439,-123.568085,0.020059,0.000000
39.030003,14.803299,-123.612564,-0.004117,0.000775,0.019678,65.848366,3.354475,0.196777,-123.612564,0.020528,0.000000
39.310001,15.042358,-123.701523,-0.004100,0.000791,0.020085,66.911751,3.408647,0.200849,-123.701523,0.020996,0.000000
39.590000,15.306000,-123.746002,-0.004092,0.000808,0.020528,68.084488,3.468389,0.205278,-123.746002,0.021464,0.000000
39.870003,15.634430,-123.790489,-0.004083,0.000827,0.021005,69.545418,3.542813,0.210047,-123.790489,0.021924,0.000000
40.150002,16.009041,-123.834969,-0.004044,0.000847,0.021525,71.211769,3.627700,0.215247,-123.834969,0.022392,0.000000
40.430000,16.357948,-123.879448,-0.004031,0.000867,0.022027,72.763786,3.706764,0.220273,-123.879448,0.022860,0.000000
40.710003,16.481209,-123.923927,-0.004023,0.000885,0.022478,73.312080,3.734695,0.224785,-123.923927,0.023329,0.000000
40.990002,16.825653,-124.057373,-0.004018,0.000902,0.022921,74.844246,3.812747,0.229213,-124.057373,0.023797,0.000000
41.270000,17.112007,-124.057373,-0.003997,0.000921,0.023398,76.118011,3.877636,0.233982,-124.057373,0.024257,0.000000
41.550003,17.386444,-124.057373,-0.003975,0.000939,0.023858,77.338768,3.939824,0.238577,-124.057373,0.024724,0.000000
41.830002,17.427406,-124.101852,-0.003945,0.000952,0.024187,77.520973,3.949107,0.241870,-124.101852,0.025193,0.000000
42.110001,18.013145,-124.101852,-0.003923,0.000975,0.024768,80.126472,4.081837,0.247684,-124.101852,0.025662,0.000000
42.390003,18.235451,-124.235298,-0.003919,0.000994,0.025245,81.115334,4.132213,0.252452,-124.235298,0.026129,0.000000
42.670002,18.518829,-124.279778,-0.003902,0.001015,0.025783,82.375870,4.196427,0.257827,-124.279778,0.026598,0.000000
42.950001,18.573196,-124.368736,-0.003889,0.001030,0.026173,82.617706,4.208746,0.261733,-124.368736,0.027057,0.000000
43.230003,18.941475,-124.324257,-0.003867,0.001052,0.026711,84.255890,4.292199,0.267108,-124.324257,0.027526,0.000000
43.510002,19.160797,-124.457703,-0.003850,0.001069,0.027145,85.231483,4.341899,0.271445,-124.457703,0.027994,0.000000
43.790001,18.897530,-124.502182,-0.003829,0.001080,0.027422,84.060410,4.282241,0.274216,-124.502182,0.028462,0.000000
44.070004,19.645630,-124.591141,-0.003820,0.001105,0.028055,87.388123,4.451763,0.280552,-124.591141,0.028931,0.000000
44.350002,19.770744,-124.546661,-0.003786,0.001121,0.028480,87.944664,4.480115,0.284798,-124.546661,0.029390,0.000000
44.630001,20.068642,-124.591141,-0.003773,0.001143,0.029026,89.269775,4.547619,0.290264,-124.591141,0.029859,0.000000
44.910004,20.109978,-124.680107,-0.003751,0.001158,0.029408,89.453651,4.556986,0.294079,-124.680107,0.030327,0.000000
45.190002,20.218712,-124.724586,-0.003734,0.001176,0.029867,89.937325,4.581625,0.298674,-124.724586,0.030795,0.000000
45.470001,20.733330,-124.769066,-0.003712,0.001197,0.030405,92.226456,4.698239,0.304048,-124.769066,0.031264,0.000000
45.750004,20.747849,-124.813545,-0.003704,0.001213,0.030804,92.291039,4.701530,0.308037,-124.813545,0.031732,0.000000
46.030003,21.146660,-124.769066,-0.003682,0.001236,0.031403,94.065041,4.791902,0.314025,-124.769066,0.032191,0.000000
46.310001,21.227837,-124.902512,-0.003669,0.001251,0.031767,94.426132,4.810297,0.317666,-124.902512,0.032660,0.000000
46.590004,21.427803,-124.902512,-0.003648,0.001269,0.032226,95.315628,4.855610,0.322261,-124.902512,0.033128,0.000000
46.870003,21.497063,-125.035950,-0.003630,0.001284,0.032625,95.623711,4.871304,0.326250,-125.035950,0.033596,0.000000
47.150002,21.883583,-125.080437,-0.003622,0.001305,0.033146,97.343040,4.958891,0.331458,-125.080437,0.034065,0.000000
47.430004,22.185577,-125.124916,-0.003604,0.001324,0.033623,98.686378,5.027324,0.336227,-125.124916,0.034524,0.000000
47.710003,22.331924,-125.124916,-0.003566,0.001344,0.034125,99.337364,5.060486,0.341254,-125.124916,0.034993,0.000000
47.990002,22.738556,-125.169395,-0.003561,0.001364,0.034637,101.146149,5.152630,0.346371,-125.169395,0.035461,0.000000
48.270000,22.645462,-125.302841,-0.003527,0.001379,0.035028,100.732048,5.131535,0.350277,-125.302841,0.035929,0.000000
48.550003,22.819733,-125.391800,-0.003527,0.001398,0.035505,101.507240,5.171026,0.355046,-125.391800,0.036398,0.000000
48.830002,22.603386,-125.391800,-0.003492,0.001410,0.035816,100.544884,5.122000,0.358165,-125.391800,0.036857,0.000000
49.110001,23.398399,-125.391800,-0.003492,0.001434,0.036433,104.081276,5.302153,0.364326,-125.391800,0.037326,0.000000
49.390003,23.523140,-125.480766,-0.003462,0.001454,0.036927,104.636154,5.330420,0.369269,-125.480766,0.037794,0.000000
49.670002,23.392441,-125.569725,-0.003441,0.001467,0.037265,104.054771,5.300803,0.372646,-125.569725,0.038262,0.000000
49.950001,24.126755,-125.614204,-0.003423,0.001491,0.037881,107.321167,5.467201,0.378807,-125.614204,0.038731,0.000000
50.230003,24.263420,-125.658684,-0.003406,0.001512,0.038410,107.929085,5.498170,0.384099,-125.658684,0.039199,0.000000
50.510002,24.278313,-125.614204,-0.003397,0.001527,0.038782,107.995331,5.501544,0.387823,-125.614204,0.039658,0.000000
50.790001,24.377365,-125.703171,-0.003363,0.001543,0.039181,108.435936,5.523990,0.391812,-125.703171,0.040127,0.000000
51.070004,24.549400,-125.747650,-0.003354,0.001561,0.039641,109.201187,5.562974,0.396407,-125.747650,0.040595,0.000000
51.350002,24.867783,-125.792130,-0.003346,0.001581,0.040152,110.617424,5.635120,0.401524,-125.792130,0.041063,0.000000
51.630001,24.748993,-125.925575,-0.003316,0.001594,0.040482,110.089020,5.608202,0.404825,-125.925575,0.041532,0.000000
51.910004,25.542519,-125.836609,-0.003311,0.001620,0.041158,113.618797,5.788018,0.411585,-125.836609,0.041991,0.000000
52.190002,25.519432,-125.970055,-0.003277,0.001637,0.041584,113.516106,5.782786,0.415839,-125.970055,0.042460,0.000000
52.470001,25.713440,-125.970055,-0.003234,0.001657,0.042096,114.379097,5.826749,0.420956,-125.970055,0.042928,0.000000
52.750004,25.229729,-126.103493,-0.003251,0.001670,0.042407,112.227440,5.717138,0.424075,-126.103493,0.043396,0.000000
53.030003,25.936485,-126.014534,-0.003216,0.001691,0.042954,115.371246,5.877292,0.429540,-126.014534,0.043865,0.000000
53.310001,25.903717,-126.192459,-0.003203,0.001706,0.043326,115.225487,5.869866,0.433264,-126.192459,0.044332,0.000000
53.590004,26.164009,-126.192459,-0.003191,0.001722,0.043743,116.383324,5.928849,0.437428,-126.192459,0.044793,0.000000
53.870003,26.964607,-126.281418,-0.003165,0.001748,0.044394,119.944565,6.110267,0.443938,-126.281418,0.045261,0.000000
54.150002,26.953064,-126.281418,-0.003143,0.001764,0.044801,119.893219,6.107652,0.448010,-126.281418,0.045729,0.000000
54.430004,26.958649,-126.370384,-0.003130,0.001781,0.045235,119.918060,6.108917,0.452348,-126.370384,0.046197,0.000000
54.710003,27.304955,-126.414864,-0.003100,0.001802,0.045772,121.458504,6.187391,0.457722,-126.414864,0.046665,0.000000
54.990002,27.716431,-126.459343,-0.003087,0.001821,0.046258,123.288841,6.280633,0.462582,-126.459343,0.047125,0.000000
55.270004,27.657219,-126.503822,-0.003044,0.001836,0.046640,123.025452,6.267215,0.466397,-126.503822,0.047594,0.000000
55.550003,27.960335,-126.548309,-0.003044,0.001856,0.047142,124.373779,6.335903,0.471424,-126.548309,0.048062,0.000000
55.830002,28.426170,-126.592789,-0.003018,0.001877,0.047681,126.445923,6.441462,0.476806,-126.592789,0.048530,0.000000
56.110004,28.436966,-126.592789,-0.002992,0.001894,0.048114,126.493942,6.443909,0.481136,-126.592789,0.048998,0.000000
56.390003,28.467506,-126.637268,-0.002988,0.001911,0.048547,126.629791,6.450830,0.485473,-126.637268,0.049458,0.000000
56.670002,28.637680,-126.770714,-0.002975,0.001928,0.048973,127.386765,6.489391,0.489728,-126.770714,0.049927,0.000000
56.950005,29.021225,-126.859673,-0.002953,0.001948,0.049484,129.092850,6.576303,0.494837,-126.859673,0.050394,0.000000
57.230003,29.093834,-126.904152,-0.002936,0.001965,0.049900,129.415833,6.592757,0.499001,-126.904152,0.050863,0.000000
57.510002,29.775276,-126.948631,-0.002902,0.001988,0.050507,132.447037,6.747174,0.505072,-126.948631,0.051332,0.000000
57.790001,30.027000,-126.948631,-0.002889,0.002008,0.051001,133.566772,6.804215,0.510015,-126.948631,0.051799,0.000000
58.070004,29.870979,-127.037598,-0.002863,0.002024,0.051418,132.872757,6.768861,0.514178,-127.037598,0.052260,0.000000
58.350002,29.988274,-127.082077,-0.002841,0.002042,0.051869,133.394501,6.795440,0.518690,-127.082077,0.052727,0.000000
58.630001,30.505501,-127.126556,-0.002828,0.002063,0.052398,135.695251,6.912645,0.523981,-127.126556,0.053196,0.000000
58.910004,30.578484,-127.171036,-0.002815,0.002079,0.052814,136.019882,6.929183,0.528144,-127.171036,0.053664,0.000000
59.190002,30.344261,-127.215523,-0.002785,0.002092,0.053126,134.978012,6.876108,0.531263,-127.215523,0.054132,0.000000
59.470001,31.213379,-127.260002,-0.002772,0.002117,0.053759,138.844040,7.073053,0.537591,-127.260002,0.054592,0.000000
59.750004,31.548515,-127.304482,-0.002746,0.002136,0.054253,140.334808,7.148995,0.542534,-127.304482,0.055060,0.000000
60.030003,31.309074,-127.348961,-0.002729,0.002150,0.054601,139.269714,7.094738,0.546009,-127.348961,0.055529,0.000000
60.310001,31.727249,-127.393440,-0.002725,0.002170,0.055121,141.129852,7.189497,0.551209,-127.393440,0.055997,0.000000
60.590004,32.206871,-127.393440,-0.002695,0.002191,0.055658,143.263321,7.298181,0.556584,-127.393440,0.056465,0.000000
60.870003,32.130905,-127.482407,-0.002660,0.002206,0.056041,142.925400,7.280967,0.560407,-127.482407,0.056934,0.000000
61.150002,32.146545,-127.526886,-0.002656,0.002222,0.056440,142.994980,7.284511,0.564396,-127.526886,0.057393,0.000000
61.430004,32.841766,-127.571365,-0.002630,0.002243,0.056977,146.087479,7.442051,0.569771,-127.571365,0.057861,0.000000
61.710003,33.343346,-127.660332,-0.002608,0.002265,0.057540,148.318604,7.555710,0.575402,-127.660332,0.058330,0.000000
61.990002,33.112106,-127.660332,-0.002587,0.002280,0.057913,147.290009,7.503311,0.579134,-127.660332,0.058798,0.000000
62.270004,33.364571,-127.749290,-0.002561,0.002299,0.058390,148.413025,7.560520,0.583903,-127.749290,0.059266,0.000000
62.550003,33.458786,-127.793770,-0.002544,0.002314,0.058764,148.832108,7.581869,0.587635,-127.793770,0.059726,0.000000
62.830002,33.984947,-127.927216,-0.002535,0.002334,0.059275,151.172592,7.701099,0.592752,-127.927216,0.060194,0.000000
63.110004,33.883659,-127.838257,-0.002531,0.002348,0.059630,150.722046,7.678147,0.596303,-127.838257,0.060663,0.000000
63.390003,34.757248,-127.882736,-0.002496,0.002371,0.060220,154.607956,7.876105,0.602199,-127.882736,0.061131,0.000000
63.670002,35.199623,-127.971695,-0.002479,0.002391,0.060732,156.575745,7.976348,0.607317,-127.971695,0.061599,0.000000
63.950005,35.346344,-128.016174,-0.002458,0.002411,0.061235,157.228394,8.009596,0.612351,-128.016174,0.062059,0.000000
64.230003,35.354904,-128.060654,-0.002427,0.002425,0.061599,157.266464,8.011536,0.615992,-128.060654,0.062527,0.000000
64.510002,35.450233,-128.105133,-0.002423,0.002442,0.062016,157.690521,8.033138,0.620155,-128.105133,0.062996,0.000000
64.790001,36.175987,-128.149612,-0.002406,0.002464,0.062579,160.918823,8.197596,0.625795,-128.149612,0.063464,0.000000
65.070000,35.853882,-128.194107,-0.002363,0.002474,0.062848,159.486038,8.124605,0.628482,-128.194107,0.063932,0.000000
65.350006,36.855942,-128.283066,-0.002354,0.002501,0.063524,163.943420,8.351675,0.635242,-128.283066,0.064400,0.000000
65.630005,37.019409,-128.372025,-0.002328,0.002518,0.063967,164.670563,8.388719,0.639670,-128.372025,0.064860,0.000000
65.910004,37.353058,-128.327545,-0.002315,0.002539,0.064496,166.154694,8.464324,0.644961,-128.327545,0.065328,0.000000
66.190002,37.121437,-128.372025,-0.002302,0.002555,0.064886,165.124405,8.411839,0.648860,-128.372025,0.065797,0.000000
66.470001,37.511688,-128.372025,-0.002276,0.002570,0.065285,166.860321,8.500270,0.652849,-128.372025,0.066265,0.000000
66.750000,37.977150,-128.416504,-0.002242,0.002592,0.065849,168.930801,8.605745,0.658488,-128.416504,0.066733,0.000000
67.030006,38.100410,-128.638916,-0.002246,0.002609,0.066256,169.479095,8.633677,0.662561,-128.638916,0.067192,0.000000
67.310005,38.496613,-128.594437,-0.002216,0.002628,0.066750,171.241486,8.723457,0.667504,-128.594437,0.067661,0.000000
67.590004,38.971390,-128.683395,-0.002190,0.002649,0.067280,173.353394,8.831043,0.672795,-128.683395,0.068130,0.000000
67.870003,39.182892,-128.683395,-0.002169,0.002667,0.067739,174.294205,8.878971,0.677390,-128.683395,0.068597,0.000000
68.150002,38.908455,-128.772354,-0.002143,0.002682,0.068121,173.073456,8.816782,0.681205,-128.772354,0.069066,0.000000
68.430000,39.445045,-128.816833,-0.002126,0.002702,0.068624,175.460327,8.938375,0.686239,-128.816833,0.069535,0.000000
68.710007,39.769753,-128.905792,-0.002113,0.002718,0.069049,176.904694,9.011955,0.690486,-128.905792,0.069994,0.000000
68.990005,39.546700,-128.905792,-0.002091,0.002733,0.069413,175.912506,8.961410,0.694127,-128.905792,0.070463,0.000000
69.270004,40.637009,-128.950272,-0.002044,0.002760,0.070115,180.762436,9.208478,0.701152,-128.950272,0.070930,0.000000
69.550003,40.818352,-129.039246,-0.002048,0.002775,0.070479,181.569092,9.249571,0.704793,-129.039246,0.071399,0.000000
69.830002,41.069702,-129.128204,-0.002022,0.002795,0.070983,182.687164,9.306527,0.709827,-129.128204,0.071867,0.000000
70.110001,40.805321,-129.128204,-0.002013,0.002807,0.071295,181.511139,9.246618,0.712946,-129.128204,0.072327,0.000000
70.390007,41.084969,-129.172684,-0.001983,0.002827,0.071798,182.755066,9.309987,0.717979,-129.172684,0.072795,0.000000
70.670006,41.828224,-129.172684,-0.001936,0.002848,0.072327,186.061234,9.478411,0.723271,-129.172684,0.073263,0.000000
70.950005,41.569801,-129.261642,-0.001932,0.002861,0.072682,184.911713,9.419851,0.726821,-129.261642,0.073732,0.000000
71.230003,42.675003,-129.306122,-0.001910,0.002887,0.073341,189.827896,9.670294,0.733414,-129.306122,0.074200,0.000000
71.510002,42.731606,-129.350601,-0.001910,0.002905,0.073775,190.079681,9.683120,0.737752,-129.350601,0.074659,0.000000
71.790001,42.481743,-129.395081,-0.001867,0.002919,0.074148,188.968231,9.626501,0.741476,-129.395081,0.075128,0.000000
72.070000,42.762886,-129.395081,-0.001858,0.002940,0.074677,190.218811,9.690208,0.746767,-129.395081,0.075596,0.000000
72.350006,43.085732,-129.528534,-0.001824,0.002956,0.075093,191.654907,9.763366,0.750931,-129.528534,0.076064,0.000000
72.630005,43.548958,-129.528534,-0.001807,0.002975,0.075553,193.715439,9.868335,0.755526,-129.528534,0.076533,0.000000
72.910004,43.378784,-129.573013,-0.001789,0.002988,0.075891,192.958466,9.829773,0.758909,-129.573013,0.077001,0.000000
73.190002,44.201729,-129.661972,-0.001768,0.003014,0.076559,196.619110,10.016255,0.765586,-129.661972,0.077461,0.000000
73.470001,44.869766,-129.661972,-0.001738,0.003034,0.077053,199.590683,10.167634,0.770529,-129.661972,0.077929,0.000000
73.750000,45.100639,-129.706451,-0.001716,0.003051,0.077487,200.617661,10.219951,0.774866,-129.706451,0.078397,0.000000
74.030006,44.642616,-129.795410,-0.001703,0.003062,0.077773,198.580276,10.116161,0.777728,-129.795410,0.078866,0.000000
74.310005,45.477478,-129.839890,-0.001677,0.003086,0.078389,202.293930,10.305344,0.783890,-129.839890,0.079334,0.000000
74.590004,45.518440,-129.884384,-0.001677,0.003101,0.078770,202.476135,10.314627,0.787705,-129.884384,0.079794,0.000000
74.870003,45.625679,-129.928864,-0.001625,0.003118,0.079195,202.953156,10.338926,0.791951,-129.928864,0.080262,0.000000
75.150002,46.464638,-129.973343,-0.001617,0.003143,0.079820,206.685028,10.529037,0.798196,-129.973343,0.080730,0.000000
75.430000,47.173637,-130.062302,-0.001595,0.003161,0.080297,209.838821,10.689699,0.802965,-130.062302,0.081199,0.000000
75.710007,47.423866,-130.106781,-0.001582,0.003178,0.080721,210.951889,10.746402,0.807212,-130.106781,0.081667,0.000000
75.990005,47.435410,-130.062302,-0.001565,0.003195,0.081147,211.003235,10.749018,0.811466,-130.062302,0.082135,0.000000
76.270004,48.291122,-130.151260,-0.001544,0.003217,0.081719,214.809647,10.942925,0.817189,-130.151260,0.082595,0.000000
76.550003,48.379005,-130.284698,-0.001526,0.003234,0.082135,215.200562,10.962839,0.821352,-130.284698,0.083063,0.000000
76.830002,48.309746,-130.329193,-0.001509,0.003244,0.082404,214.892487,10.947145,0.824040,-130.329193,0.083531,0.000000
77.110001,49.591446,-130.373672,-0.001496,0.003273,0.083141,220.593765,11.237582,0.831413,-130.373672,0.084000,0.000000
77.390007,50.224113,-130.329193,-0.001483,0.003291,0.083592,223.408020,11.380946,0.835924,-130.329193,0.084468,0.000000
77.670006,50.420723,-130.418152,-0.001466,0.003307,0.083991,224.282578,11.425499,0.839906,-130.418152,0.084928,0.000000
77.950005,50.727554,-130.462631,-0.001431,0.003326,0.084468,225.647430,11.495028,0.844683,-130.462631,0.085396,0.000000
78.230003,51.585503,-130.551590,-0.001427,0.003345,0.084963,229.463776,11.689442,0.849626,-130.551590,0.085864,0.000000
78.510002,52.024529,-130.507111,-0.001406,0.003363,0.085413,231.416656,11.788927,0.854130,-130.507111,0.086333,0.000000
78.790001,52.169014,-130.596069,-0.001388,0.003381,0.085882,232.059357,11.821667,0.858815,-130.596069,0.086801,0.000000
79.070007,53.762024,-130.640549,-0.001375,0.003404,0.086454,239.145432,12.182649,0.864538,-130.640549,0.087269,0.000000
79.350006,54.138115,-130.685028,-0.001354,0.003419,0.086835,240.818359,12.267872,0.868353,-130.685028,0.087729,0.000000
79.630005,54.339569,-130.818481,-0.001332,0.003434,0.087234,241.714478,12.313522,0.872343,-130.818481,0.088197,0.000000
79.910004,55.533768,-130.818481,-0.001337,0.003459,0.087859,247.026535,12.584131,0.878588,-130.818481,0.088665,0.000000
80.190002,56.052483,-130.774002,-0.001302,0.003475,0.088275,249.333893,12.701674,0.882751,-130.774002,0.089134,0.000000
80.470001,56.365646,-130.907440,-0.001298,0.003490,0.088639,250.726913,12.772638,0.886392,-130.907440,0.089602,0.000000
80.750008,56.857178,-131.040878,-0.001285,0.003510,0.089151,252.913361,12.884021,0.891509,-131.040878,0.090062,0.000000
81.030006,58.630417,-131.040878,-0.001276,0.003533,0.089750,260.801117,13.285843,0.897497,-131.040878,0.090530,0.000000
81.310005,58.819954,-131.085358,-0.001259,0.003546,0.090079,261.644226,13.328792,0.900790,-131.085358,0.090998,0.000000
81.590004,59.569168,-131.129837,-0.001255,0.003565,0.090556,264.976898,13.498567,0.905559,-131.129837,0.091467,0.000000
81.870003,60.538452,-131.129837,-0.001246,0.003586,0.091085,269.288483,13.718209,0.910850,-131.129837,0.091935,0.000000
82.150002,61.528595,-131.129837,-0.001229,0.003604,0.091553,273.692871,13.942578,0.915528,-131.129837,0.092395,0.000000
82.430000,61.798187,-131.307770,-0.001207,0.003617,0.091874,274.892059,14.003669,0.918738,-131.307770,0.092862,0.000000
82.710007,63.047501,-131.307770,-0.001203,0.003640,0.092455,280.449280,14.286768,0.924551,-131.307770,0.093331,0.000000
82.990005,64.270737,-131.307770,-0.001194,0.003662,0.093019,285.890503,14.563957,0.930191,-131.307770,0.093800,0.000000
83.270004,64.658386,-131.396729,-0.001168,0.003675,0.093339,287.614868,14.651799,0.933393,-131.396729,0.094267,0.000000
83.550003,65.454895,-131.485687,-0.001147,0.003693,0.093808,291.157928,14.832291,0.938079,-131.485687,0.094736,0.000000
83.830002,66.103561,-131.485687,-0.001155,0.003711,0.094250,294.043335,14.979280,0.942499,-131.485687,0.095195,0.000000
84.110001,67.311539,-131.574646,-0.001151,0.003730,0.094753,299.416687,15.253013,0.947533,-131.574646,0.095664,0.000000
84.390007,66.513550,-131.574646,-0.001117,0.003723,0.094571,295.867035,15.072186,0.945709,-131.574646,0.094779,0.000000
84.670006,65.564362,-131.619141,-0.001117,0.003723,0.094553,291.644836,14.857098,0.945535,-131.619141,0.094563,0.000000
84.950005,64.702316,-131.663620,-0.001112,0.003722,0.094536,287.810272,14.661755,0.945361,-131.663620,0.094563,0.000000
85.230003,63.931885,-131.752579,-0.001099,0.003722,0.094528,284.383240,14.487172,0.945278,-131.752579,0.094563,0.000000
85.510002,63.251938,-131.841537,-0.001104,0.003722,0.094528,281.358673,14.333094,0.945278,-131.841537,0.094563,0.000000
85.790001,62.646454,-131.886017,-0.001104,0.003722,0.094528,278.665344,14.195889,0.945278,-131.886017,0.094563,0.000000
86.070007,62.076729,-131.841537,-0.001078,0.003721,0.094519,276.131073,14.066788,0.945194,-131.841537,0.094563,0.000000
86.350006,61.556145,-131.930496,-0.001082,0.003721,0.094519,273.815399,13.948822,0.945194,-131.930496,0.094563,0.000000
86.630005,61.095154,-131.974976,-0.001087,0.003721,0.094519,271.764832,13.844360,0.945194,-131.974976,0.094563,0.000000
86.910004,60.676979,-132.019470,-0.001074,0.003721,0.094519,269.904694,13.749599,0.945194,-132.019470,0.094563,0.000000
87.190002,60.275932,-132.108429,-0.001087,0.003721,0.094519,268.120728,13.658721,0.945194,-132.108429,0.094563,0.000000
87.470001,59.914734,-132.108429,-0.001061,0.003721,0.094519,266.514038,13.576873,0.945194,-132.108429,0.094563,0.000000
87.750008,59.569168,-132.152908,-0.001061,0.003721,0.094519,264.976898,13.498567,0.945194,-132.152908,0.094563,0.000000
88.030006,59.255257,-132.241867,-0.001052,0.003721,0.094519,263.580536,13.427433,0.945194,-132.241867,0.094563,0.000000
88.310005,58.951027,-132.286346,-0.001056,0.003721,0.094519,262.227264,13.358494,0.945194,-132.286346,0.094563,0.000000
88.590004,58.694839,-132.286346,-0.001056,0.003721,0.094519,261.087677,13.300441,0.945194,-132.286346,0.094563,0.000000
88.870003,58.436783,-132.286346,-0.001039,0.003721,0.094519,259.939789,13.241964,0.945194,-132.286346,0.094563,0.000000
89.150002,58.188782,-132.375305,-0.001061,0.003721,0.094519,258.836639,13.185767,0.945194,-132.375305,0.094563,0.000000
89.430008,57.950096,-132.464279,-0.001069,0.003721,0.094519,257.774902,13.131680,0.945194,-132.464279,0.094563,0.000000
89.710007,57.728531,-132.553238,-0.001043,0.003721,0.094519,256.789337,13.081472,0.945194,-132.553238,0.094563,0.000000
89.990005,57.534523,-132.553238,-0.001056,0.003721,0.094519,255.926346,13.037509,0.945194,-132.553238,0.094563,0.000000
90.270004,57.340889,-132.553238,-0.001043,0.003721,0.094519,255.065018,12.993631,0.945194,-132.553238,0.094563,0.000000
90.550003,57.156570,-132.642197,-0.001026,0.003721,0.094519,254.245117,12.951864,0.945194,-132.642197,0.094563,0.000000
90.830002,56.974854,-132.686676,-0.001030,0.003721,0.094519,253.436813,12.910686,0.945194,-132.686676,0.094563,0.000000
91.110001,56.814728,-132.686676,-0.001039,0.003721,0.094519,252.724533,12.874402,0.945194,-132.686676,0.094563,0.000000
91.390007,56.649773,-132.731155,-0.001039,0.003721,0.094519,251.990768,12.837022,0.945194,-132.731155,0.094563,0.000000
91.670006,56.504173,-132.775635,-0.001022,0.003721,0.094519,251.343109,12.804029,0.945194,-132.775635,0.094563,0.000000
91.950005,56.356339,-132.864594,-0.001030,0.003721,0.094519,250.685516,12.770530,0.945194,-132.864594,0.094563,0.000000
92.230003,56.217072,-132.953568,-0.001035,0.003721,0.094519,250.066025,12.738971,0.945194,-132.953568,0.094563,0.000000
92.510002,56.099030,-132.909088,-0.001043,0.003721,0.094519,249.540939,12.712221,0.945194,-132.909088,0.094563,0.000000
92.790001,55.959763,-132.998047,-0.001043,0.003721,0.094519,248.921463,12.680664,0.945194,-132.998047,0.094563,0.000000
93.070007,55.842094,-133.087006,-0.001035,0.003721,0.094519,248.398041,12.653999,0.945194,-133.087006,0.094563,0.000000
93.350006,55.717346,-133.087006,-0.001026,0.003721,0.094519,247.843140,12.625731,0.945194,-133.087006,0.094563,0.000000
93.630005,55.601913,-133.220444,-0.001043,0.003721,0.094510,247.329666,12.599574,0.945103,-133.220444,0.094563,0.000000
93.910004,55.488708,-133.220444,-0.001026,0.003721,0.094510,246.826096,12.573921,0.945103,-133.220444,0.094563,0.000000
94.190002,55.404182,-133.220444,-0.001035,0.003721,0.094510,246.450119,12.554768,0.945103,-133.220444,0.094563,0.000000
94.470001,55.290237,-133.220444,-0.001022,0.003721,0.094510,245.943253,12.528947,0.945103,-133.220444,0.094563,0.000000
94.750008,55.195282,-133.398376,-0.001018,0.003721,0.094510,245.520874,12.507430,0.945103,-133.398376,0.094563,0.000000
95.030006,55.102188,-133.442856,-0.001018,0.003721,0.094510,245.106781,12.486334,0.945103,-133.442856,0.094563,0.000000
95.310005,54.993454,-133.442856,-0.001043,0.003721,0.094510,244.623108,12.461695,0.945103,-133.442856,0.094563,0.000000
95.590004,54.913399,-133.442856,-0.001022,0.003721,0.094510,244.266998,12.443554,0.945103,-133.442856,0.094563,0.000000
95.870003,54.810249,-133.487335,-0.001018,0.003721,0.094510,243.808167,12.420179,0.945103,-133.487335,0.094563,0.000000
96.150002,54.733170,-133.576294,-0.001013,0.003721,0.094510,243.465302,12.402714,0.945103,-133.576294,0.094563,0.000000
96.430008,54.643425,-133.620773,-0.001013,0.003721,0.094510,243.066101,12.382378,0.945103,-133.620773,0.094563,0.000000
96.710007,54.570068,-133.709732,-0.001026,0.003721,0.094510,242.739792,12.365755,0.945103,-133.709732,0.094563,0.000000
96.990005,54.484795,-133.709732,-0.001026,0.003721,0.094510,242.360474,12.346432,0.945103,-133.709732,0.094563,0.000000
97.270004,54.407341,-133.709732,-0.001009,0.003721,0.094510,242.015945,12.328880,0.945103,-133.709732,0.094563,0.000000
97.550003,54.331009,-133.843185,-0.001013,0.003721,0.094510,241.676392,12.311583,0.945103,-133.843185,0.094563,0.000000
97.830002,54.247597,-133.887665,-0.001018,0.003721,0.094510,241.305359,12.292682,0.945103,-133.887665,0.094563,0.000000
98.110008,54.184288,-133.976624,-0.001018,0.003721,0.094510,241.023758,12.278335,0.945103,-133.976624,0.094563,0.000000
98.390007,54.115402,-133.887665,-0.001018,0.003721,0.094510,240.717331,12.262726,0.945103,-133.887665,0.094563,0.000000
98.670006,54.049866,-133.976624,-0.001013,0.003721,0.094510,240.425812,12.247875,0.945103,-133.976624,0.094563,0.000000
98.950005,53.978371,-134.021103,-0.001009,0.003721,0.094510,240.107788,12.231673,0.945103,-134.021103,0.094563,0.000000
99.230003,53.914696,-134.154541,-0.001030,0.003721,0.094510,239.824539,12.217244,0.945103,-134.154541,0.094563,0.000000
99.510002,53.860703,-134.154541,-0.001030,0.003721,0.094510,239.584366,12.205009,0.945103,-134.154541,0.094563,0.000000
99.790009,53.807823,-134.154541,-0.001009,0.003721,0.094510,239.349152,12.193027,0.945103,-134.154541,0.094563,0.000000
100.070007,53.734467,-134.199036,-0.001009,0.003721,0.094510,239.022842,12.176404,0.945103,-134.199036,0.094563,0.000000
100.350006,53.686058,-134.243515,-0.001009,0.003721,0.094510,238.807510,12.165435,0.945103,-134.243515,0.094563,0.000000
100.630005,53.626480,-134.332474,-0.001018,0.003721,0.094510,238.542496,12.151935,0.945103,-134.332474,0.094563,0.000000
100.910004,53.567642,-134.332474,-0.001022,0.003721,0.094510,238.280777,12.138601,0.945103,-134.332474,0.094563,0.000000
101.190002,53.521469,-134.421432,-0.001026,0.003721,0.094510,238.075378,12.128138,0.945103,-134.421432,0.094563,0.000000
101.470001,53.463379,-134.465912,-0.001018,0.003721,0.094510,237.816986,12.114975,0.945103,-134.465912,0.094563,0.000000
101.750008,53.417580,-134.510391,-0.001009,0.003721,0.094510,237.613266,12.104597,0.945103,-134.510391,0.094563,0.000000
102.030006,53.355759,-134.599365,-0.001013,0.003721,0.094510,237.338272,12.090588,0.945103,-134.599365,0.094563,0.000000
102.310005,53.317406,-134.554871,-0.001018,0.003721,0.094510,237.167664,12.081897,0.945103,-134.554871,0.094563,0.000000
102.590004,53.259315,-134.688324,-0.000996,0.003721,0.094510,236.909271,12.068733,0.945103,-134.688324,0.094563,0.000000
102.870003,53.209419,-134.732803,-0.001000,0.003721,0.094510,236.687317,12.057426,0.945103,-134.732803,0.094563,0.000000
103.150002,53.165855,-134.732803,-0.001009,0.003721,0.094510,236.493530,12.047555,0.945103,-134.732803,0.094563,0.000000
103.430008,53.113350,-134.777283,-0.000996,0.003721,0.094510,236.259979,12.035657,0.945103,-134.777283,0.094563,0.000000
103.710007,53.074623,-134.777283,-0.001026,0.003721,0.094510,236.087708,12.026881,0.945103,-134.777283,0.094563,0.000000
103.990005,53.020256,-134.866241,-0.000996,0.003721,0.094510,235.845871,12.014562,0.945103,-134.866241,0.094563,0.000000
104.270004,52.987862,-134.910721,-0.001009,0.003721,0.094510,235.701782,12.007221,0.945103,-134.910721,0.094563,0.000000
104.550003,52.925674,-134.999680,-0.001000,0.003721,0.094510,235.425156,11.993130,0.945103,-134.999680,0.094563,0.000000
104.830002,52.878754,-135.044174,-0.000996,0.003721,0.094510,235.216446,11.982496,0.945103,-135.044174,0.094563,0.000000
105.110008,52.840027,-135.044174,-0.001005,0.003721,0.094510,235.044174,11.973722,0.945103,-135.044174,0.094563,0.000000
105.390007,52.786407,-135.044174,-0.001005,0.003721,0.094510,234.805664,11.961571,0.945103,-135.044174,0.094563,0.000000
105.670006,52.760712,-135.133133,-0.000987,0.003721,0.094510,234.691360,11.955749,0.945103,-135.133133,0.094563,0.000000
105.950005,52.712677,-135.222092,-0.000996,0.003721,0.094510,234.477692,11.944863,0.945103,-135.222092,0.094563,0.000000
106.230003,52.685867,-135.311050,-0.001018,0.003721,0.094510,234.358444,11.938787,0.945103,-135.311050,0.094563,0.000000
106.510002,52.635223,-135.311050,-0.001000,0.003721,0.094510,234.133163,11.927312,0.945103,-135.311050,0.094563,0.000000
106.790009,52.589050,-135.355530,-0.001009,0.003721,0.094510,233.927780,11.916849,0.945103,-135.355530,0.094563,0.000000
107.070007,52.543617,-135.400009,-0.000992,0.003721,0.094510,233.725677,11.906554,0.945103,-135.400009,0.094563,0.000000
107.350006,52.494095,-135.488983,-0.001000,0.003721,0.094510,233.505402,11.895332,0.945103,-135.488983,0.094563,0.000000
107.630005,52.471375,-135.444489,-0.001005,0.003721,0.094510,233.404327,11.890182,0.945103,-135.444489,0.094563,0.000000
107.910004,52.434143,-135.488983,-0.001000,0.003721,0.094510,233.238724,11.881746,0.945103,-135.488983,0.094563,0.000000
108.190002,52.405098,-135.488983,-0.001005,0.003721,0.094510,233.109512,11.875165,0.945103,-135.488983,0.094563,0.000000
108.470009,52.367111,-135.622421,-0.001009,0.003721,0.094510,232.940552,11.866557,0.945103,-135.622421,0.094563,0.000000
108.750008,52.332481,-135.666901,-0.001009,0.003721,0.094510,232.786499,11.858710,0.945103,-135.666901,0.094563,0.000000
109.030006,52.290031,-135.755859,-0.000996,0.003721,0.094510,232.597672,11.849091,0.945103,-135.755859,0.094563,0.000000
109.310005,52.266945,-135.711380,-0.001009,0.003721,0.094510,232.494980,11.843860,0.945103,-135.711380,0.094563,0.000000
109.590004,52.230827,-135.800339,-0.001009,0.003721,0.094510,232.334320,11.835674,0.945103,-135.800339,0.094563,0.000000
109.870003,52.202522,-135.844818,-0.000996,0.003721,0.094510,232.208420,11.829261,0.945103,-135.844818,0.094563,0.000000
110.150002,52.164169,-135.889313,-0.000996,0.003721,0.094510,232.037811,11.820570,0.945103,-135.889313,0.094563,0.000000
110.430008,52.125816,-135.889313,-0.001000,0.003721,0.094510,231.867218,11.811879,0.945103,-135.889313,0.094563,0.000000
110.710007,52.099380,-135.978271,-0.000992,0.003721,0.094510,231.749619,11.805888,0.945103,-135.978271,0.094563,0.000000
110.990005,52.060654,-136.022751,-0.001005,0.003721,0.094510,231.577347,11.797112,0.945103,-136.022751,0.094563,0.000000
111.270004,52.036819,-136.067230,-0.000992,0.003721,0.094510,231.471329,11.791712,0.945103,-136.067230,0.094563,0.000000
111.550003,52.011497,-136.156189,-0.000992,0.003721,0.094510,231.358688,11.785974,0.945103,-136.156189,0.094563,0.000000
111.830002,51.974258,-136.156189,-0.001009,0.003721,0.094510,231.193054,11.777535,0.945103,-136.156189,0.094563,0.000000
112.110008,51.947075,-136.200668,-0.001005,0.003721,0.094510,231.072128,11.771376,0.945103,-136.200668,0.094563,0.000000
112.390007,51.926598,-136.200668,-0.001005,0.003721,0.094510,230.981049,11.766736,0.945103,-136.200668,0.094563,0.000000
112.670006,51.897926,-136.245148,-0.001005,0.003721,0.094510,230.853500,11.760238,0.945103,-136.245148,0.094563,0.000000
112.950005,51.862549,-136.334122,-0.000992,0.003721,0.094510,230.696136,11.752222,0.945103,-136.334122,0.094563,0.000000
113.230003,51.827545,-136.423080,-0.001018,0.003721,0.094510,230.540436,11.744289,0.945103,-136.423080,0.094563,0.000000
113.510002,51.795525,-136.423080,-0.000996,0.003721,0.094510,230.397995,11.737034,0.945103,-136.423080,0.094563,0.000000
113.790009,51.776901,-136.512039,-0.001013,0.003721,0.094510,230.315155,11.732813,0.945103,-136.512039,0.094563,0.000000
114.070007,51.756424,-136.600998,-0.000992,0.003721,0.094510,230.224075,11.728173,0.945103,-136.600998,0.094563,0.000000
114.350006,51.729614,-136.600998,-0.000996,0.003721,0.094510,230.104813,11.722097,0.945103,-136.600998,0.094563,0.000000
114.600006,51.700569,-136.645477,-0.001000,0.003721,0.094510,229.975616,11.715516,0.945103,-136.645477,0.094563,0.000000