File: Data/compression 10/AutoHeating-17-10-7-240424_04242024_232950.csv
Time (sec),S:Load (lbs),S:HL1 (DIM),S:LVDT (in),S:Position (in),Ch:Position (mm),Ch:Load (N),Ch:Stress (MPa),Ch:Strain (mm/mm),Ch:HL1 (DIM),Set Point (),Cycles ()
0.110000,0.015640,-124.946991,-0.009179,-0.000000,-0.000000,0.069571,0.003544,-0.000000,-124.946991,0.000165,0.000000
0.340000,0.000374,-124.991470,-0.009175,-0.000000,-0.000000,0.001663,0.000085,-0.000000,-124.991470,0.000165,0.000000
0.570000,-0.004097,-125.035950,-0.009175,0.000095,0.002411,-0.018224,-0.000928,0.024109,-125.035950,0.003183,0.000000
0.800000,-0.021599,-125.035950,-0.009102,0.000234,0.005940,-0.096076,-0.004894,0.059405,-125.035950,0.007016,0.000000
1.030000,-0.007446,-125.124916,-0.008942,0.000388,0.009860,-0.033123,-0.001687,0.098604,-125.124916,0.010849,0.000000
1.260000,0.001114,-125.080437,-0.008795,0.000532,0.013520,0.004955,0.000252,0.135200,-125.080437,0.014682,0.000000
1.490000,-0.000748,-125.124916,-0.008623,0.000686,0.017414,-0.003326,-0.000169,0.174139,-125.124916,0.018515,0.000000
1.720000,0.022713,-125.124916,-0.008481,0.000842,0.021377,0.101031,0.005147,0.213771,-125.124916,0.022348,0.000000
1.950000,-0.008568,-125.124916,-0.008334,0.000988,0.025089,-0.038112,-0.001941,0.250888,-125.124916,0.026182,0.000000
2.180000,0.003349,-125.169395,-0.008183,0.001139,0.028939,0.014898,0.000759,0.289393,-125.169395,0.030015,0.000000
2.410000,0.005585,-125.124916,-0.008006,0.001293,0.032851,0.024842,0.001266,0.328505,-125.124916,0.033848,0.000000
2.640000,0.030159,-125.213875,-0.007881,0.001435,0.036458,0.134154,0.006834,0.364582,-125.213875,0.037681,0.000000
2.870000,0.011169,-125.169395,-0.007709,0.001598,0.040577,0.049684,0.002531,0.405775,-125.169395,0.041514,0.000000
3.100000,-0.041336,-125.258362,-0.007567,0.001743,0.044281,-0.183872,-0.009367,0.442805,-125.258362,0.045347,0.000000
3.330000,-0.053627,-125.258362,-0.007433,0.001890,0.048018,-0.238545,-0.012152,0.480183,-125.258362,0.049163,0.000000
3.560000,-0.016388,-125.213875,-0.007265,0.002043,0.051886,-0.072897,-0.003714,0.518861,-125.213875,0.052996,0.000000
3.790000,0.048035,-125.302841,-0.007114,0.002190,0.055615,0.213669,0.010885,0.556152,-125.302841,0.056829,0.000000
4.020000,0.027924,-125.347321,-0.006967,0.002346,0.059578,0.124210,0.006328,0.595784,-125.347321,0.060662,0.000000
4.250000,0.019363,-125.391800,-0.006808,0.002502,0.063542,0.086133,0.004388,0.635416,-125.391800,0.064496,0.000000
4.480000,-0.010056,-125.302841,-0.006653,0.002651,0.067323,-0.044729,-0.002279,0.673227,-125.302841,0.068329,0.000000
4.710000,0.023827,-125.391800,-0.006502,0.002804,0.071217,0.105986,0.005399,0.712166,-125.391800,0.072162,0.000000
4.940000,0.019737,-125.436279,-0.006342,0.002948,0.074868,0.087796,0.004473,0.748676,-125.436279,0.075995,0.000000
5.170000,0.002235,-125.480766,-0.006191,0.003104,0.078848,0.009944,0.000507,0.788482,-125.480766,0.079828,0.000000
5.400000,-0.005219,-125.436279,-0.006036,0.003256,0.082699,-0.023213,-0.001183,0.826986,-125.436279,0.083661,0.000000
5.630000,-0.059952,-125.436279,-0.005894,0.003402,0.086402,-0.266679,-0.013585,0.864017,-125.436279,0.087494,0.000000
5.860000,-0.033516,-125.480766,-0.005739,0.003548,0.090131,-0.149086,-0.007595,0.901308,-125.480766,0.091328,0.000000
6.090000,0.020851,-125.436279,-0.005583,0.003703,0.094068,0.092750,0.004725,0.940680,-125.436279,0.095143,0.000000
6.320000,0.058830,-125.569725,-0.005450,0.003851,0.097823,0.261690,0.013331,0.978231,-125.569725,0.098976,0.000000
6.550000,0.051010,-125.480766,-0.005299,0.004005,0.101717,0.226904,0.011559,1.017169,-125.480766,0.102810,0.000000
6.780000,0.020851,-125.525246,-0.005135,0.004157,0.105576,0.092750,0.004725,1.055761,-125.525246,0.106643,0.000000
7.010000,0.029419,-125.614204,-0.004967,0.004308,0.109418,0.130862,0.006666,1.094179,-125.614204,0.110476,0.000000
7.240000,0.751816,-125.569725,-0.004833,0.004451,0.113043,3.344244,0.170364,1.130429,-125.569725,0.114136,0.000000
7.470000,0.706764,-125.658684,-0.004838,-0.000001,-0.000017,3.143844,0.160155,-0.000174,-125.658684,0.000173,0.000000
7.700000,0.691490,-125.658684,-0.004816,-0.000001,-0.000026,3.075902,0.156694,-0.000260,-125.658684,0.000173,0.000000
7.930000,0.661331,-125.658684,-0.004829,-0.000001,-0.000026,2.941748,0.149860,-0.000260,-125.658684,0.000425,0.000000
8.160001,0.632660,-125.658684,-0.004825,-0.000001,-0.000026,2.814212,0.143363,-0.000260,-125.658684,0.000807,0.000000
8.390000,0.644203,-125.703171,-0.004812,-0.000001,-0.000026,2.865559,0.145979,-0.000260,-125.703171,0.001197,0.000000
8.620001,0.988274,-125.703171,-0.004816,0.000026,0.000650,4.396060,0.223946,0.006504,-125.703171,0.001578,0.000000
8.850000,1.217659,-125.703171,-0.004812,0.000044,0.001110,5.416418,0.275925,0.011101,-125.703171,0.001960,0.000000
9.080001,1.504753,-125.747650,-0.004777,0.000064,0.001622,6.693476,0.340982,0.016217,-125.747650,0.002342,0.000000
9.310000,1.649239,-125.836609,-0.004769,0.000074,0.001882,7.336180,0.373723,0.018819,-125.836609,0.002723,0.000000
9.540001,1.891647,-125.836609,-0.004751,0.000091,0.002307,8.414468,0.428653,0.023068,-125.836609,0.003113,0.000000
9.770000,2.033524,-125.881088,-0.004751,0.000100,0.002541,9.045565,0.460803,0.025410,-125.881088,0.003495,0.000000
10.000000,2.365311,-125.836609,-0.004734,0.000116,0.002940,10.521427,0.535987,0.029399,-125.836609,0.003877,0.000000
10.230000,2.719063,-125.836609,-0.004721,0.000135,0.003426,12.094995,0.616148,0.034255,-125.836609,0.004258,0.000000
10.460000,2.946205,-125.836609,-0.004708,0.000146,0.003720,13.105375,0.667620,0.037204,-125.836609,0.004640,0.000000
10.690001,3.000572,-125.970055,-0.004721,0.000152,0.003868,13.347212,0.679939,0.038678,-125.970055,0.005030,0.000000
10.920000,3.740105,-126.014534,-0.004682,0.000184,0.004674,16.636816,0.847520,0.046743,-126.014534,0.005411,0.000000
11.150001,3.994438,-126.014534,-0.004669,0.000198,0.005030,17.768148,0.905153,0.050299,-126.014534,0.005793,0.000000
11.380000,4.322128,-125.925575,-0.004652,0.000213,0.005411,19.225786,0.979408,0.054115,-125.925575,0.006175,0.000000
11.610001,4.472565,-125.970055,-0.004635,0.000224,0.005698,19.894962,1.013498,0.056977,-125.970055,0.006556,0.000000
11.840000,4.759293,-126.059013,-0.004635,0.000237,0.006019,21.170391,1.078471,0.060185,-126.059013,0.006946,0.000000
12.070001,5.273163,-126.103493,-0.004618,0.000256,0.006504,23.456200,1.194916,0.065042,-126.103493,0.007328,0.000000
12.300000,5.578880,-126.059013,-0.004622,0.000271,0.006877,24.816099,1.264192,0.068771,-126.059013,0.007710,0.000000
12.530001,5.699905,-126.059013,-0.004613,0.000279,0.007085,25.354446,1.291617,0.070852,-126.059013,0.008091,0.000000
12.760000,6.196648,-126.059013,-0.004596,0.000298,0.007580,27.564066,1.404180,0.075795,-126.059013,0.008481,0.000000
12.990001,6.631210,-126.147980,-0.004575,0.000317,0.008057,29.497097,1.502654,0.080565,-126.147980,0.008863,0.000000
13.220000,6.952934,-126.147980,-0.004566,0.000332,0.008429,30.928196,1.575557,0.084294,-126.147980,0.009245,0.000000
13.450001,7.100769,-126.192459,-0.004549,0.000346,0.008785,31.585798,1.609057,0.087850,-126.192459,0.009626,0.000000
13.680000,7.311157,-126.147980,-0.004544,0.000355,0.009028,32.521652,1.656732,0.090278,-126.147980,0.010008,0.000000
13.910001,7.783325,-126.192459,-0.004518,0.000373,0.009479,34.621960,1.763727,0.094788,-126.192459,0.010398,0.000000
14.140000,8.230919,-126.236938,-0.004510,0.000390,0.009895,36.612957,1.865153,0.098950,-126.236938,0.010780,0.000000
14.370001,8.367950,-126.325897,-0.004501,0.000400,0.010155,37.222504,1.896205,0.101552,-126.325897,0.011161,0.000000
14.600000,8.516899,-126.236938,-0.004480,0.000409,0.010389,37.885059,1.929957,0.103894,-126.236938,0.011543,0.000000
14.830001,9.231483,-126.281418,-0.004480,0.000434,0.011022,41.063690,2.091884,0.110224,-126.281418,0.011924,0.000000
15.060000,9.531990,-126.281418,-0.004449,0.000452,0.011473,42.400410,2.159980,0.114734,-126.281418,0.012315,0.000000
15.290001,9.821693,-126.370384,-0.004445,0.000467,0.011864,43.689075,2.225628,0.118636,-126.370384,0.012696,0.000000
15.520000,10.020538,-126.370384,-0.004449,0.000481,0.012228,44.573582,2.270686,0.122279,-126.370384,0.013078,0.000000
15.750001,9.969528,-126.370384,-0.004432,0.000486,0.012349,44.346676,2.259127,0.123493,-126.370384,0.013459,0.000000
15.980000,10.501648,-126.370384,-0.004419,0.000508,0.012896,46.713665,2.379708,0.128956,-126.370384,0.013841,0.000000
16.210001,10.905670,-126.459343,-0.004415,0.000522,0.013260,48.510845,2.471260,0.132599,-126.459343,0.014231,0.000000
16.440001,11.119041,-126.503822,-0.004393,0.000533,0.013546,49.459965,2.519611,0.135461,-126.503822,0.014613,0.000000
16.670000,11.790802,-126.503822,-0.004376,0.000557,0.014136,52.448105,2.671834,0.141358,-126.503822,0.014994,0.000000
16.900002,12.000816,-126.459343,-0.004363,0.000573,0.014552,53.382298,2.719424,0.145520,-126.459343,0.015376,0.000000
17.130001,12.187752,-126.459343,-0.004350,0.000587,0.014916,54.213829,2.761784,0.149163,-126.459343,0.015757,0.000000
17.360001,12.497932,-126.503822,-0.004329,0.000603,0.015315,55.593578,2.832072,0.153152,-126.503822,0.016148,0.000000
17.590000,12.714287,-126.592789,-0.004324,0.000617,0.015662,56.555973,2.881099,0.156621,-126.592789,0.016529,0.000000
17.820002,12.897865,-126.592789,-0.004307,0.000630,0.015992,57.372570,2.922698,0.159916,-126.592789,0.016911,0.000000
18.050001,13.371895,-126.548309,-0.004303,0.000647,0.016443,59.481159,3.030115,0.164426,-126.548309,0.017292,0.000000
18.280001,13.382317,-126.548309,-0.004273,0.000658,0.016720,59.527515,3.032476,0.167201,-126.548309,0.017674,0.000000
18.510000,13.550629,-126.637268,-0.004277,0.000669,0.016989,60.276207,3.070616,0.169890,-126.637268,0.018064,0.000000
18.740002,14.122971,-126.681747,-0.004260,0.000689,0.017492,62.822109,3.200311,0.174919,-126.681747,0.018446,0.000000
18.970001,14.440605,-126.681747,-0.004255,0.000706,0.017934,64.235023,3.272288,0.179342,-126.681747,0.018827,0.000000
19.200001,14.830101,-126.637268,-0.004238,0.000724,0.018385,65.967583,3.360549,0.183852,-126.637268,0.019209,0.000000
19.430000,14.997299,-126.726227,-0.004225,0.000736,0.018706,66.711319,3.398437,0.187061,-126.726227,0.019591,0.000000
19.660002,15.112732,-126.726227,-0.004204,0.000750,0.019044,67.224792,3.424594,0.190443,-126.726227,0.019981,0.000000
19.890001,15.601288,-126.770714,-0.004191,0.000768,0.019504,69.397995,3.535302,0.195039,-126.770714,0.020362,0.000000
20.120001,15.702202,-126.859673,-0.004195,0.000781,0.019825,69.846886,3.558170,0.198248,-126.859673,0.020744,0.000000
20.350000,15.829552,-126.770714,-0.004174,0.000792,0.020120,70.413361,3.587028,0.201196,-126.770714,0.021126,0.000000
20.580002,16.518814,-126.770714,-0.004161,0.000814,0.020683,73.479355,3.743217,0.206833,-126.770714,0.021507,0.000000
20.810001,16.747818,-126.859673,-0.004139,0.000832,0.021134,74.498016,3.795110,0.211343,-126.859673,0.021897,0.000000
21.040001,16.795113,-126.904152,-0.004135,0.000846,0.021481,74.708389,3.805827,0.214812,-126.904152,0.022279,0.000000
21.270000,16.774635,-126.948631,-0.004122,0.000858,0.021802,74.617302,3.801187,0.218020,-126.948631,0.022661,0.000000
21.500002,17.138069,-126.948631,-0.004118,0.000873,0.022184,76.233940,3.883542,0.221836,-126.948631,0.023042,0.000000
21.730001,17.308990,-126.904152,-0.004100,0.000888,0.022548,76.994232,3.922273,0.225479,-126.904152,0.023432,0.000000
21.960001,17.720459,-126.948631,-0.004079,0.000904,0.022964,78.824539,4.015513,0.229641,-126.948631,0.023814,0.000000
22.190001,17.752480,-127.037598,-0.004070,0.000915,0.023233,78.966972,4.022769,0.232330,-127.037598,0.024196,0.000000
22.420002,17.703331,-126.993118,-0.004061,0.000924,0.023467,78.748352,4.011632,0.234671,-126.993118,0.024577,0.000000
22.650002,18.430573,-126.993118,-0.004049,0.000948,0.024074,81.983284,4.176427,0.240742,-126.993118,0.024959,0.000000
22.880001,18.757515,-126.993118,-0.004027,0.000964,0.024490,83.437592,4.250514,0.244904,-126.993118,0.025349,0.000000
23.110001,18.877045,-127.037598,-0.004027,0.000980,0.024898,83.969292,4.277600,0.248980,-127.037598,0.025731,0.000000
23.340002,18.916145,-127.082077,-0.004001,0.000994,0.025236,84.143219,4.286459,0.252363,-127.082077,0.026112,0.000000
23.570002,19.136589,-127.126556,-0.003997,0.001007,0.025566,85.123802,4.336413,0.255658,-127.126556,0.026494,0.000000
23.800001,19.308998,-127.126556,-0.003984,0.001023,0.025982,85.890717,4.375482,0.259821,-127.126556,0.026875,0.000000
24.030001,19.631104,-127.082077,-0.003967,0.001039,0.026398,87.323509,4.448472,0.263983,-127.082077,0.027266,0.000000
24.260000,19.298576,-127.082077,-0.003971,0.001043,0.026485,85.844353,4.373120,0.264851,-127.082077,0.027647,0.000000
24.490002,20.289459,-127.215523,-0.003945,0.001071,0.027214,90.252022,4.597657,0.272135,-127.215523,0.028029,0.000000
24.720001,20.347176,-127.215523,-0.003936,0.001087,0.027604,90.508759,4.610736,0.276038,-127.215523,0.028410,0.000000
24.950001,20.476387,-127.260002,-0.003919,0.001101,0.027977,91.083519,4.640016,0.279767,-127.260002,0.028792,0.000000
25.180000,20.432076,-127.171036,-0.003902,0.001114,0.028306,90.886414,4.629974,0.283062,-127.171036,0.029182,0.000000
25.410002,20.671135,-127.304482,-0.003893,0.001130,0.028705,91.949799,4.684146,0.287052,-127.304482,0.029564,0.000000
25.640001,20.948181,-127.260002,-0.003872,0.001148,0.029165,93.182167,4.746926,0.291648,-127.260002,0.029945,0.000000
25.870001,21.154480,-127.304482,-0.003876,0.001163,0.029538,94.099823,4.793674,0.295377,-127.304482,0.030327,0.000000
26.100000,20.941856,-127.304482,-0.003863,0.001171,0.029746,93.154030,4.745493,0.297458,-127.304482,0.030708,0.000000
26.330002,21.396889,-127.260002,-0.003842,0.001190,0.030231,95.178116,4.848604,0.302315,-127.260002,0.031099,0.000000
26.560001,21.594994,-127.393440,-0.003829,0.001206,0.030630,96.059326,4.893496,0.306304,-127.393440,0.031480,0.000000
26.790001,21.774109,-127.393440,-0.003833,0.001220,0.030986,96.856071,4.934083,0.309860,-127.393440,0.031862,0.000000
27.020000,22.003860,-127.393440,-0.003807,0.001237,0.031428,97.878059,4.986146,0.314283,-127.393440,0.032243,0.000000
27.250002,22.018013,-127.393440,-0.003794,0.001250,0.031749,97.941017,4.989353,0.317491,-127.393440,0.032625,0.000000
27.480001,22.097328,-127.393440,-0.003786,0.001264,0.032096,98.293823,5.007326,0.320960,-127.393440,0.033015,0.000000
27.710001,22.447723,-127.437927,-0.003755,0.001281,0.032547,99.852463,5.086727,0.325470,-127.437927,0.033397,0.000000
27.940001,22.551994,-127.571365,-0.003747,0.001294,0.032877,100.316284,5.110355,0.328765,-127.571365,0.033778,0.000000
28.170002,22.115196,-127.526886,-0.003760,0.001299,0.032998,98.373306,5.011375,0.329979,-127.526886,0.034160,0.000000
28.400002,23.162682,-127.571365,-0.003742,0.001327,0.033709,103.032753,5.248739,0.337091,-127.571365,0.034542,0.000000
28.630001,23.274025,-127.526886,-0.003721,0.001342,0.034082,103.528030,5.273969,0.340820,-127.526886,0.034932,0.000000
28.860001,23.440842,-127.615852,-0.003721,0.001359,0.034524,104.270073,5.311770,0.345243,-127.615852,0.035313,0.000000
29.090002,23.144440,-127.615852,-0.003704,0.001370,0.034793,102.951607,5.244605,0.347931,-127.615852,0.035695,0.000000
29.320002,23.190239,-127.615852,-0.003699,0.001381,0.035088,103.155334,5.254983,0.350880,-127.615852,0.036077,0.000000
29.550001,23.494835,-127.615852,-0.003682,0.001398,0.035504,104.510246,5.324006,0.355042,-127.615852,0.036458,0.000000
29.780001,23.792740,-127.571365,-0.003673,0.001415,0.035929,105.835396,5.391512,0.359292,-127.571365,0.036848,0.000000
30.010002,23.996048,-127.704811,-0.003652,0.001430,0.036311,106.739754,5.437582,0.363107,-127.704811,0.037230,0.000000
30.240002,24.242935,-127.749290,-0.003648,0.001446,0.036736,107.837959,5.493527,0.367357,-127.749290,0.037612,0.000000
30.470001,24.507690,-127.793770,-0.003613,0.001464,0.037195,109.015648,5.553522,0.371953,-127.793770,0.037993,0.000000
30.700001,24.426514,-127.749290,-0.003622,0.001477,0.037508,108.654556,5.535127,0.375075,-127.749290,0.038383,0.000000
30.930002,24.535622,-127.749290,-0.003600,0.001491,0.037872,109.139893,5.559851,0.378717,-127.749290,0.038765,0.000000
31.160002,24.487953,-127.749290,-0.003587,0.001503,0.038184,108.927856,5.549049,0.381839,-127.749290,0.039147,0.000000
31.390001,24.631691,-127.838257,-0.003579,0.001517,0.038531,109.567230,5.581621,0.385308,-127.838257,0.039528,0.000000
31.620001,25.122475,-127.838257,-0.003570,0.001537,0.039034,111.750351,5.692834,0.390338,-127.838257,0.039910,0.000000
31.850002,25.034973,-127.793770,-0.003557,0.001548,0.039320,111.361122,5.673006,0.393200,-127.793770,0.040300,0.000000
32.080002,25.096039,-127.838257,-0.003531,0.001562,0.039676,111.632759,5.686844,0.396756,-127.838257,0.040682,0.000000
32.310001,25.765564,-127.882736,-0.003531,0.001585,0.040248,114.610954,5.838561,0.402479,-127.882736,0.041063,0.000000
32.540001,25.921219,-127.927216,-0.003510,0.001600,0.040638,115.303337,5.873832,0.406382,-127.927216,0.041445,0.000000
32.770000,25.809875,-127.971695,-0.003497,0.001614,0.040985,114.808060,5.848601,0.409851,-127.971695,0.041826,0.000000
33.000000,25.633743,-127.927216,-0.003484,0.001624,0.041254,114.024582,5.808689,0.412539,-127.927216,0.042217,0.000000
33.230003,25.780830,-127.971695,-0.003475,0.001639,0.041627,114.678864,5.842020,0.416268,-127.971695,0.042598,0.000000
33.460003,26.280556,-127.927216,-0.003471,0.001657,0.042095,116.901749,5.955259,0.420951,-127.927216,0.042980,0.000000
33.690002,26.388916,-127.971695,-0.003449,0.001671,0.042442,117.383759,5.979814,0.424420,-127.971695,0.043361,0.000000
33.920002,26.051178,-128.016174,-0.003441,0.001678,0.042615,115.881424,5.903281,0.426155,-128.016174,0.043743,0.000000
34.150002,26.693520,-128.060654,-0.003445,0.001700,0.043170,118.738708,6.048838,0.431705,-128.060654,0.044133,0.000000
34.380001,27.104248,-128.105133,-0.003428,0.001718,0.043630,120.565720,6.141911,0.436301,-128.105133,0.044515,0.000000
34.610001,27.236809,-128.016174,-0.003415,0.001735,0.044081,121.155373,6.171949,0.440811,-128.016174,0.044896,0.000000
34.840000,27.244255,-128.149612,-0.003385,0.001746,0.044359,121.188499,6.173636,0.443586,-128.149612,0.045278,0.000000
35.070004,27.124352,-128.149612,-0.003393,0.001759,0.044688,120.655144,6.146466,0.446881,-128.149612,0.045659,0.000000
35.300003,27.351128,-128.105133,-0.003389,0.001773,0.045044,121.663895,6.197854,0.450437,-128.105133,0.046050,0.000000
35.530003,27.721642,-128.149612,-0.003372,0.001791,0.045495,123.312019,6.281814,0.454947,-128.149612,0.046431,0.000000
35.760002,27.609184,-128.194107,-0.003350,0.001802,0.045781,122.811783,6.256331,0.457808,-128.194107,0.046813,0.000000
35.990002,27.535828,-128.194107,-0.003350,0.001815,0.046093,122.485481,6.239708,0.460930,-128.194107,0.047194,0.000000
36.220001,28.553146,-128.238586,-0.003324,0.001840,0.046726,127.010742,6.470235,0.467261,-128.238586,0.047576,0.000000
36.450001,28.585167,-128.194107,-0.003320,0.001854,0.047082,127.153175,6.477491,0.470817,-128.194107,0.047966,0.000000
36.680000,28.764656,-128.238586,-0.003307,0.001870,0.047489,127.951584,6.518165,0.474893,-128.238586,0.048348,0.000000
36.910000,28.865196,-128.194107,-0.003294,0.001884,0.047854,128.398804,6.540947,0.478535,-128.194107,0.048729,0.000000
37.140003,28.522614,-128.327545,-0.003281,0.001895,0.048122,126.874924,6.463317,0.481223,-128.327545,0.049111,0.000000
37.370003,28.859238,-128.327545,-0.003268,0.001910,0.048521,128.372299,6.539597,0.485213,-128.327545,0.049493,0.000000
37.600002,29.081543,-128.372025,-0.003268,0.001925,0.048903,129.361160,6.589972,0.489029,-128.372025,0.049883,0.000000
37.830002,29.288582,-128.283066,-0.003251,0.001940,0.049267,130.282120,6.636888,0.492671,-128.283066,0.050264,0.000000
38.060001,29.737663,-128.416504,-0.003242,0.001959,0.049753,132.279739,6.738651,0.497527,-128.416504,0.050646,0.000000
38.290001,29.996086,-128.372025,-0.003225,0.001975,0.050169,133.429260,6.797210,0.501690,-128.372025,0.051028,0.000000
38.520000,30.054550,-128.416504,-0.003208,0.001990,0.050542,133.689316,6.810459,0.505419,-128.416504,0.051409,0.000000
38.750000,30.118973,-128.460983,-0.003208,0.002004,0.050897,133.975876,6.825057,0.508975,-128.460983,0.051799,0.000000
38.980003,30.154350,-128.460983,-0.003199,0.002017,0.051227,134.133255,6.833073,0.512270,-128.460983,0.052181,0.000000
39.210003,30.253769,-128.460983,-0.003182,0.002031,0.051591,134.575485,6.855602,0.515913,-128.460983,0.052563,0.000000
39.440002,30.654068,-128.549942,-0.003173,0.002047,0.051990,136.356110,6.946311,0.519902,-128.549942,0.052944,0.000000
39.670002,30.559486,-128.505463,-0.003156,0.002059,0.052294,135.935379,6.924879,0.522937,-128.505463,0.053334,0.000000
39.900002,31.022720,-128.594437,-0.003152,0.002078,0.052788,137.995956,7.029849,0.527880,-128.594437,0.053716,0.000000
40.130001,31.257690,-128.594437,-0.003143,0.002093,0.053152,139.041153,7.083094,0.531523,-128.594437,0.054098,0.000000
40.360001,31.528404,-128.549942,-0.003130,0.002108,0.053551,140.245346,7.144439,0.535512,-128.549942,0.054479,0.000000
40.590000,31.955139,-128.594437,-0.003109,0.002127,0.054019,142.143555,7.241138,0.540195,-128.594437,0.054861,0.000000
40.820004,31.725388,-128.683395,-0.003109,0.002135,0.054236,141.121567,7.189075,0.542363,-128.683395,0.055251,0.000000
41.050003,31.853485,-128.638916,-0.003096,0.002151,0.054635,141.691376,7.218103,0.546352,-128.638916,0.055633,0.000000
41.280003,32.314484,-128.683395,-0.003096,0.002167,0.055043,143.742004,7.322567,0.550428,-128.683395,0.056014,0.000000
41.510002,32.457474,-128.727875,-0.003083,0.002182,0.055433,144.378052,7.354969,0.554331,-128.727875,0.056396,0.000000
41.740002,32.422096,-128.683395,-0.003070,0.002194,0.055719,144.220688,7.346952,0.557193,-128.683395,0.056777,0.000000
41.970001,33.337387,-128.727875,-0.003048,0.002219,0.056352,148.292099,7.554360,0.563523,-128.727875,0.057168,0.000000
42.200001,33.798759,-128.816833,-0.003053,0.002236,0.056795,150.344391,7.658908,0.567946,-128.816833,0.057549,0.000000
42.430000,33.469208,-128.816833,-0.003040,0.002246,0.057055,148.878479,7.584231,0.570548,-128.816833,0.057931,0.000000
42.660004,33.739174,-128.772354,-0.003018,0.002262,0.057462,150.079346,7.645406,0.574624,-128.772354,0.058312,0.000000
42.890003,33.659119,-128.816833,-0.003005,0.002274,0.057766,149.723236,7.627265,0.577659,-128.816833,0.058694,0.000000
43.120003,34.037445,-128.905792,-0.002984,0.002292,0.058208,151.406113,7.712995,0.582082,-128.905792,0.059084,0.000000
43.350002,34.327522,-128.905792,-0.002988,0.002306,0.058572,152.696442,7.778728,0.585724,-128.905792,0.059466,0.000000
43.580002,34.065002,-128.905792,-0.002988,0.002314,0.058781,151.528702,7.719240,0.587806,-128.905792,0.059847,0.000000
43.810001,34.135757,-128.950272,-0.002966,0.002332,0.059232,151.843430,7.735273,0.592315,-128.950272,0.060229,0.000000
44.040001,35.262550,-128.994751,-0.002953,0.002352,0.059735,156.855652,7.990608,0.597345,-128.994751,0.060610,0.000000
44.270000,35.573860,-128.994751,-0.002940,0.002367,0.060125,158.240433,8.061152,0.601248,-128.994751,0.061001,0.000000
44.500004,35.751480,-129.039246,-0.002940,0.002383,0.060532,159.030533,8.101401,0.605323,-129.039246,0.061382,0.000000
44.730003,35.589127,-128.950272,-0.002936,0.002394,0.060801,158.308334,8.064611,0.608012,-128.950272,0.061764,0.000000
44.960003,35.855743,-128.950272,-0.002932,0.002410,0.061217,159.494308,8.125028,0.612175,-128.950272,0.062145,0.000000
45.190002,36.083260,-128.994751,-0.002897,0.002424,0.061573,160.506348,8.176583,0.615730,-128.994751,0.062527,0.000000
45.420002,36.549843,-129.039246,-0.002902,0.002440,0.061981,162.581818,8.282313,0.619806,-129.039246,0.062917,0.000000
45.650002,35.855743,-129.128204,-0.002893,0.002446,0.062137,159.494308,8.125028,0.621367,-129.128204,0.063299,0.000000
45.880001,37.409653,-129.128204,-0.002897,0.002473,0.062804,166.406448,8.477148,0.628045,-129.128204,0.063680,0.000000
46.110001,37.747025,-129.083725,-0.002871,0.002488,0.063203,167.907150,8.553597,0.632034,-129.083725,0.064062,0.000000
46.340004,37.818520,-129.217163,-0.002859,0.002501,0.063533,168.225174,8.569799,0.635329,-129.217163,0.064444,0.000000
46.570004,38.080292,-129.128204,-0.002850,0.002518,0.063949,169.389603,8.629117,0.639492,-129.128204,0.064834,0.000000
46.800003,37.887779,-129.217163,-0.002854,0.002528,0.064209,168.533264,8.585494,0.642094,-129.217163,0.065215,0.000000
47.030003,38.803444,-129.217163,-0.002863,0.002549,0.064747,172.606339,8.792986,0.647471,-129.217163,0.065597,0.000000
47.260002,38.962448,-129.217163,-0.002828,0.002563,0.065094,173.313629,8.829017,0.650940,-129.217163,0.065979,0.000000
47.490002,38.713326,-129.261642,-0.002820,0.002572,0.065319,172.205475,8.772566,0.653194,-129.261642,0.066369,0.000000
47.720001,39.563454,-129.306122,-0.002807,0.002593,0.065866,175.987030,8.965206,0.658658,-129.306122,0.066750,0.000000
47.950001,40.113449,-129.350601,-0.002802,0.002610,0.066291,178.433533,9.089838,0.662907,-129.350601,0.067132,0.000000
48.180004,40.077332,-129.350601,-0.002794,0.002622,0.066603,178.272873,9.081654,0.666029,-129.350601,0.067514,0.000000
48.410004,40.452682,-129.306122,-0.002781,0.002638,0.067011,179.942520,9.166709,0.670105,-129.306122,0.067895,0.000000
48.640003,40.515236,-129.306122,-0.002794,0.002651,0.067323,180.220764,9.180883,0.673227,-129.306122,0.068285,0.000000
48.870003,40.777016,-129.439575,-0.002772,0.002665,0.067687,181.385223,9.240204,0.676870,-129.439575,0.068667,0.000000
49.100002,41.534050,-129.439575,-0.002768,0.002684,0.068181,184.752686,9.411750,0.681813,-129.439575,0.069049,0.000000
49.330002,41.462555,-129.528534,-0.002751,0.002694,0.068433,184.434662,9.395550,0.684328,-129.528534,0.069430,0.000000
49.560001,40.840691,-129.439575,-0.002751,0.002700,0.068589,181.668472,9.254633,0.685889,-129.439575,0.069812,0.000000
49.790001,42.434448,-129.484055,-0.002738,0.002727,0.069274,188.757858,9.615784,0.692740,-129.484055,0.070202,0.000000
50.020004,42.758781,-129.528534,-0.002721,0.002742,0.069656,190.200562,9.689278,0.696556,-129.528534,0.070583,0.000000
50.250004,43.321068,-129.528534,-0.002721,0.002760,0.070115,192.701736,9.816694,0.701152,-129.528534,0.070965,0.000000
50.480003,43.178444,-129.528534,-0.002716,0.002771,0.070384,192.067307,9.784375,0.703840,-129.528534,0.071347,0.000000
50.710003,43.266327,-129.528534,-0.002712,0.002786,0.070774,192.458237,9.804290,0.707743,-129.528534,0.071728,0.000000
50.940002,43.757484,-129.573013,-0.002699,0.002800,0.071130,194.643005,9.915587,0.711299,-129.573013,0.072118,0.000000
51.170002,44.191299,-129.617493,-0.002686,0.002816,0.071537,196.572723,10.013891,0.715374,-129.617493,0.072500,0.000000
51.400002,44.489571,-129.617493,-0.002690,0.002830,0.071876,197.899490,10.081481,0.718757,-129.617493,0.072882,0.000000
51.630001,44.891357,-129.617493,-0.002677,0.002847,0.072309,199.686737,10.172527,0.723093,-129.617493,0.073263,0.000000
51.860001,45.677811,-129.617493,-0.002673,0.002866,0.072786,203.185043,10.350740,0.727862,-129.617493,0.073645,0.000000
52.090004,45.912033,-129.661972,-0.002665,0.002881,0.073185,204.226929,10.403815,0.731852,-129.661972,0.074035,0.000000
52.320004,45.844261,-129.706451,-0.002656,0.002891,0.073428,203.925461,10.388458,0.734280,-129.706451,0.074417,0.000000
52.550003,45.851334,-129.795410,-0.002639,0.002903,0.073740,203.956924,10.390060,0.737402,-129.795410,0.074798,0.000000
52.780003,46.202858,-129.706451,-0.002647,0.002920,0.074165,205.520584,10.469717,0.741651,-129.706451,0.075180,0.000000
53.010002,46.946114,-129.795410,-0.002634,0.002938,0.074625,208.826736,10.638142,0.746248,-129.795410,0.075561,0.000000
53.240002,46.863815,-129.750931,-0.002617,0.002947,0.074842,208.460663,10.619493,0.748416,-129.750931,0.075952,0.000000
53.470001,47.235817,-129.839890,-0.002604,0.002964,0.075275,210.115402,10.703789,0.752752,-129.839890,0.076333,0.000000
53.700001,48.709671,-129.928864,-0.002604,0.002987,0.075874,216.671432,11.037769,0.758736,-129.928864,0.076715,0.000000
53.930004,49.052254,-129.884384,-0.002600,0.003003,0.076281,218.195328,11.115399,0.762812,-129.884384,0.077096,0.000000
54.160004,49.125977,-129.795410,-0.002591,0.003015,0.076585,218.523254,11.132106,0.765847,-129.795410,0.077478,0.000000
54.390003,48.900322,-129.884384,-0.002578,0.003025,0.076845,217.519501,11.080972,0.768449,-129.884384,0.077868,0.000000
54.620003,49.334877,-129.884384,-0.002574,0.003041,0.077252,219.452499,11.179443,0.772525,-129.884384,0.078250,0.000000
54.850002,49.890091,-129.973343,-0.002583,0.003058,0.077669,221.922211,11.305256,0.776687,-129.973343,0.078631,0.000000
55.080002,50.244217,-129.973343,-0.002565,0.003071,0.078007,223.497437,11.385502,0.780070,-129.973343,0.079013,0.000000
55.310001,50.181656,-129.973343,-0.002570,0.003082,0.078293,223.219147,11.371325,0.782931,-129.973343,0.079394,0.000000
55.540001,51.125992,-129.928864,-0.002539,0.003102,0.078796,227.419769,11.585316,0.787961,-129.928864,0.079785,0.000000
55.770004,51.627205,-130.017822,-0.002544,0.003119,0.079221,229.649277,11.698892,0.792211,-130.017822,0.080166,0.000000
56.000004,52.346626,-130.062302,-0.002535,0.003136,0.079655,232.849426,11.861915,0.796547,-130.062302,0.080548,0.000000
56.230003,52.243484,-130.062302,-0.002531,0.003148,0.079950,232.390625,11.838543,0.799495,-130.062302,0.080929,0.000000
56.460003,52.463554,-130.062302,-0.002518,0.003160,0.080270,233.369553,11.888412,0.802704,-130.062302,0.081320,0.000000
56.690002,52.714905,-130.062302,-0.002522,0.003175,0.080643,234.487610,11.945368,0.806433,-130.062302,0.081701,0.000000
56.920002,53.235855,-130.106781,-0.002522,0.003190,0.081025,236.804916,12.063417,0.810249,-130.106781,0.082083,0.000000
57.150002,53.349800,-130.151260,-0.002501,0.003202,0.081328,237.311768,12.089237,0.813284,-130.151260,0.082464,0.000000
57.380001,53.570244,-130.195740,-0.002501,0.003220,0.081779,238.292343,12.139191,0.817794,-130.195740,0.082846,0.000000
57.610004,55.041862,-130.195740,-0.002509,0.003239,0.082265,244.838440,12.472664,0.822650,-130.195740,0.083236,0.000000
57.840004,55.362099,-130.195740,-0.002479,0.003255,0.082673,246.262909,12.545232,0.826726,-130.195740,0.083618,0.000000
58.070004,55.779900,-130.240219,-0.002483,0.003270,0.083046,248.121384,12.639906,0.830455,-130.240219,0.083999,0.000000
58.300003,56.060303,-130.240219,-0.002479,0.003282,0.083375,249.368683,12.703446,0.833751,-130.240219,0.084381,0.000000
58.530003,56.014496,-130.284698,-0.002466,0.003295,0.083687,249.164917,12.693066,0.836873,-130.284698,0.084763,0.000000
58.760002,56.429321,-130.373672,-0.002466,0.003311,0.084095,251.010162,12.787066,0.840949,-130.373672,0.085153,0.000000
58.990002,56.953247,-130.329193,-0.002458,0.003327,0.084502,253.340698,12.905790,0.845025,-130.329193,0.085534,0.000000
59.220001,57.579948,-130.284698,-0.002440,0.003345,0.084971,256.128387,13.047803,0.849708,-130.284698,0.085916,0.000000
59.450005,58.116539,-130.284698,-0.002445,0.003359,0.085326,258.515289,13.169395,0.853263,-130.284698,0.086298,0.000000
59.680004,58.616638,-130.373672,-0.002440,0.003375,0.085725,260.739838,13.282720,0.857253,-130.373672,0.086679,0.000000
59.910004,58.818832,-130.418152,-0.002432,0.003391,0.086124,261.639221,13.328538,0.861242,-130.418152,0.087069,0.000000
60.140003,59.248177,-130.418152,-0.002432,0.003406,0.086506,263.549042,13.425828,0.865057,-130.418152,0.087451,0.000000
60.370003,59.451492,-130.418152,-0.002406,0.003417,0.086801,264.453461,13.471900,0.868006,-130.418152,0.087833,0.000000
60.600002,60.008194,-130.462631,-0.002423,0.003435,0.087252,266.929779,13.598051,0.872516,-130.462631,0.088214,0.000000
60.830002,60.378700,-130.507111,-0.002414,0.003450,0.087642,268.577881,13.682010,0.876418,-130.507111,0.088596,0.000000
61.060001,60.262520,-130.507111,-0.002406,0.003460,0.087893,268.061066,13.655682,0.878933,-130.507111,0.088986,0.000000
61.290005,61.105576,-130.507111,-0.002402,0.003480,0.088388,271.811188,13.846722,0.883876,-130.507111,0.089368,0.000000
61.520004,61.459328,-130.551590,-0.002389,0.003496,0.088787,273.384735,13.926883,0.887866,-130.551590,0.089749,0.000000
61.750004,62.141144,-130.596069,-0.002376,0.003513,0.089220,276.417603,14.081385,0.892202,-130.596069,0.090131,0.000000
61.980003,62.644218,-130.640549,-0.002389,0.003527,0.089576,278.655396,14.195382,0.895757,-130.640549,0.090512,0.000000
62.210003,62.693367,-130.685028,-0.002371,0.003540,0.089923,278.874023,14.206520,0.899226,-130.685028,0.090903,0.000000
62.440002,63.053825,-130.596069,-0.002371,0.003556,0.090313,280.477417,14.288201,0.903129,-130.596069,0.091284,0.000000
62.670002,63.422844,-130.596069,-0.002363,0.003568,0.090616,282.118896,14.371821,0.906164,-130.596069,0.091666,0.000000
62.900002,63.759468,-130.640549,-0.002354,0.003583,0.090998,283.616272,14.448102,0.909980,-130.640549,0.092047,0.000000
63.130005,64.026085,-130.685028,-0.002341,0.003595,0.091310,284.802246,14.508518,0.913102,-130.685028,0.092429,0.000000
63.360004,65.546486,-130.729523,-0.002337,0.003621,0.091969,291.565338,14.853046,0.919693,-130.729523,0.092819,0.000000
63.590004,66.376137,-130.729523,-0.002328,0.003637,0.092386,295.255798,15.041047,0.923856,-130.729523,0.093201,0.000000
63.820004,66.391777,-130.729523,-0.002324,0.003648,0.092672,295.325378,15.044592,0.926717,-130.729523,0.093582,0.000000
64.050003,66.647972,-130.774002,-0.002311,0.003661,0.092993,296.464996,15.102646,0.929926,-130.774002,0.093964,0.000000
64.280006,66.805107,-130.774002,-0.002311,0.003674,0.093313,297.163971,15.138254,0.933135,-130.774002,0.094345,0.000000
64.510002,67.387505,-130.774002,-0.002294,0.003681,0.093504,299.754578,15.270226,0.935043,-130.774002,0.093738,0.000000
64.740005,66.204475,-130.818481,-0.002294,0.003681,0.093504,294.492218,15.002149,0.935043,-130.818481,0.093738,0.000000
64.970001,65.188637,-130.774002,-0.002298,0.003679,0.093444,289.973541,14.771956,0.934436,-130.774002,0.093504,0.000000
65.200005,64.211540,-130.818481,-0.002281,0.003678,0.093409,285.627197,14.550543,0.934089,-130.818481,0.093504,0.000000
65.430000,63.301460,-130.951920,-0.002272,0.003677,0.093392,281.578949,14.344316,0.933915,-130.951920,0.093504,0.000000
65.660004,62.486702,-130.951920,-0.002268,0.003676,0.093383,277.954742,14.159689,0.933829,-130.951920,0.093504,0.000000
65.889999,61.732277,-130.907440,-0.002272,0.003676,0.093374,274.598877,13.988734,0.933742,-130.907440,0.093504,0.000000
66.120003,61.055679,-130.907440,-0.002285,0.003676,0.093366,271.589233,13.835414,0.933655,-130.907440,0.093504,0.000000
66.350006,60.403282,-130.951920,-0.002264,0.003675,0.093357,268.687225,13.687580,0.933568,-130.951920,0.093504,0.000000
66.580002,59.812698,-130.996399,-0.002268,0.003675,0.093348,266.060181,13.553751,0.933482,-130.996399,0.093504,0.000000
66.810005,59.254509,-131.085358,-0.002272,0.003675,0.093348,263.577209,13.427263,0.933482,-131.085358,0.093504,0.000000
67.040001,58.767075,-131.040878,-0.002251,0.003675,0.093348,261.408997,13.316810,0.933482,-131.040878,0.093504,0.000000
67.270004,58.288948,-131.040878,-0.002251,0.003675,0.093339,259.282196,13.208465,0.933395,-131.040878,0.093504,0.000000
67.500000,57.826462,-131.040878,-0.002246,0.003675,0.093339,257.224945,13.103663,0.933395,-131.040878,0.093504,0.000000
67.730003,57.431000,-131.085358,-0.002251,0.003675,0.093339,255.465851,13.014050,0.933395,-131.085358,0.093504,0.000000
67.960007,57.052299,-131.174332,-0.002233,0.003675,0.093339,253.781296,12.928236,0.933395,-131.174332,0.093504,0.000000
68.190002,56.676201,-131.174332,-0.002233,0.003675,0.093339,252.108337,12.843011,0.933395,-131.174332,0.093504,0.000000
68.420006,56.332878,-131.174332,-0.002242,0.003675,0.093339,250.581161,12.765213,0.933395,-131.174332,0.093504,0.000000
68.650002,56.020081,-131.218811,-0.002238,0.003675,0.093339,249.189758,12.694331,0.933395,-131.218811,0.093504,0.000000
68.880005,55.716972,-131.174332,-0.002242,0.003675,0.093339,247.841476,12.625646,0.933395,-131.174332,0.093504,0.000000
69.110001,55.424286,-131.307770,-0.002233,0.003675,0.093339,246.539536,12.559322,0.933395,-131.307770,0.093504,0.000000
69.340004,55.145378,-131.263290,-0.002233,0.003675,0.093339,245.298889,12.496121,0.933395,-131.263290,0.093504,0.000000
69.570000,54.895889,-131.174332,-0.002238,0.003675,0.093339,244.189117,12.439587,0.933395,-131.174332,0.093504,0.000000
69.800003,54.651245,-131.218811,-0.002225,0.003675,0.093339,243.100876,12.384150,0.933395,-131.218811,0.093504,0.000000
70.030006,54.409203,-131.352249,-0.002233,0.003675,0.093339,242.024216,12.329301,0.933395,-131.352249,0.093504,0.000000
70.260002,54.192482,-131.352249,-0.002220,0.003675,0.093339,241.060196,12.280191,0.933395,-131.352249,0.093504,0.000000
70.490005,53.982834,-131.352249,-0.002225,0.003675,0.093339,240.127640,12.232685,0.933395,-131.352249,0.093504,0.000000
70.720001,53.772446,-131.352249,-0.002216,0.003675,0.093339,239.191788,12.185011,0.933395,-131.352249,0.093504,0.000000
70.950005,53.583275,-131.352249,-0.002216,0.003675,0.093339,238.350311,12.142143,0.933395,-131.352249,0.093504,0.000000
71.180000,53.398956,-131.352249,-0.002225,0.003675,0.093339,237.530426,12.100376,0.933395,-131.352249,0.093504,0.000000
71.410004,53.220963,-131.441208,-0.002220,0.003675,0.093339,236.738663,12.060042,0.933395,-131.441208,0.093504,0.000000
71.640007,53.049294,-131.441208,-0.002220,0.003675,0.093339,235.975037,12.021142,0.933395,-131.441208,0.093504,0.000000
71.870003,52.885078,-131.530167,-0.002225,0.003675,0.093339,235.244583,11.983931,0.933395,-131.530167,0.093504,0.000000
72.100006,52.729057,-131.485687,-0.002207,0.003675,0.093339,234.550568,11.948575,0.933395,-131.485687,0.093504,0.000000
72.330002,52.582710,-131.485687,-0.002207,0.003675,0.093339,233.899582,11.915413,0.933395,-131.485687,0.093504,0.000000
72.560005,52.427437,-131.574646,-0.002199,0.003675,0.093339,233.208893,11.880226,0.933395,-131.574646,0.093504,0.000000
72.790001,52.294868,-131.530167,-0.002212,0.003675,0.093339,232.619186,11.850186,0.933395,-131.530167,0.093504,0.000000
73.020004,52.150764,-131.619141,-0.002220,0.003675,0.093339,231.978180,11.817532,0.933395,-131.619141,0.093504,0.000000
73.250000,52.023041,-131.574646,-0.002203,0.003675,0.093339,231.410049,11.788589,0.933395,-131.574646,0.093504,0.000000
73.480003,51.910583,-131.574646,-0.002216,0.003675,0.093339,230.909805,11.763106,0.933395,-131.574646,0.093504,0.000000
73.710007,51.773178,-131.708099,-0.002203,0.003675,0.093339,230.298599,11.731970,0.933395,-131.708099,0.093504,0.000000
73.940002,51.666679,-131.619141,-0.002203,0.003675,0.093339,229.824875,11.707837,0.933395,-131.619141,0.093504,0.000000
74.170006,51.551613,-131.663620,-0.002207,0.003675,0.093339,229.313034,11.681763,0.933395,-131.663620,0.093504,0.000000
74.400002,51.439903,-131.663620,-0.002203,0.003675,0.093339,228.816116,11.656448,0.933395,-131.663620,0.093504,0.000000
74.630005,51.327820,-131.708099,-0.002199,0.003675,0.093339,228.317551,11.631050,0.933395,-131.708099,0.093504,0.000000
74.860001,51.225418,-131.797058,-0.002203,0.003675,0.093339,227.862045,11.607846,0.933395,-131.797058,0.093504,0.000000
75.090004,51.128601,-131.752579,-0.002207,0.003675,0.093339,227.431381,11.585906,0.933395,-131.752579,0.093504,0.000000
75.320007,51.021729,-131.752579,-0.002207,0.003675,0.093339,226.955978,11.561688,0.933395,-131.752579,0.093504,0.000000
75.550003,50.921188,-131.752579,-0.002195,0.003675,0.093339,226.508759,11.538906,0.933395,-131.752579,0.093504,0.000000
75.780006,50.840385,-131.797058,-0.002212,0.003675,0.093339,226.149323,11.520597,0.933395,-131.797058,0.093504,0.000000
76.010002,50.750267,-131.886017,-0.002199,0.003675,0.093339,225.748459,11.500175,0.933395,-131.886017,0.093504,0.000000
76.240005,50.661644,-131.841537,-0.002199,0.003675,0.093339,225.354248,11.480093,0.933395,-131.841537,0.093504,0.000000
76.470001,50.571899,-131.841537,-0.002203,0.003675,0.093339,224.955048,11.459757,0.933395,-131.841537,0.093504,0.000000
76.700005,50.493332,-131.930496,-0.002207,0.003675,0.093339,224.605560,11.441953,0.933395,-131.930496,0.093504,0.000000
76.930000,50.408432,-131.886017,-0.002199,0.003675,0.093339,224.227905,11.422713,0.933395,-131.886017,0.093504,0.000000
77.160004,50.316452,-131.930496,-0.002199,0.003675,0.093339,223.818756,11.401871,0.933395,-131.930496,0.093504,0.000000
77.390007,50.244583,-131.886017,-0.002203,0.003675,0.093339,223.499069,11.385585,0.933395,-131.886017,0.093504,0.000000
77.620003,50.176445,-132.019470,-0.002203,0.003675,0.093339,223.195969,11.370145,0.933395,-132.019470,0.093504,0.000000
77.850006,50.108299,-131.974976,-0.002199,0.003675,0.093339,222.892853,11.354703,0.933395,-131.974976,0.093504,0.000000
78.080002,50.021912,-132.019470,-0.002199,0.003675,0.093339,222.508575,11.335127,0.933395,-132.019470,0.093504,0.000000
78.310005,49.957489,-132.063950,-0.002190,0.003675,0.093339,222.222015,11.320529,0.933395,-132.063950,0.093504,0.000000
78.540001,49.906471,-132.063950,-0.002195,0.003675,0.093339,221.995071,11.308968,0.933395,-132.063950,0.093504,0.000000
78.770004,49.817474,-132.019470,-0.002207,0.003675,0.093339,221.599197,11.288801,0.933395,-132.019470,0.093504,0.000000
79.000000,49.750076,-132.019470,-0.002190,0.003675,0.093339,221.299393,11.273528,0.933395,-132.019470,0.093504,0.000000
79.230003,49.684540,-132.108429,-0.002199,0.003675,0.093339,221.007874,11.258677,0.933395,-132.108429,0.093504,0.000000
79.460007,49.633148,-132.152908,-0.002195,0.003675,0.093339,220.779266,11.247032,0.933395,-132.152908,0.093504,0.000000
79.690002,49.557930,-132.197388,-0.002190,0.003675,0.093339,220.444687,11.229987,0.933395,-132.197388,0.093504,0.000000
79.920006,49.513618,-132.197388,-0.002195,0.003675,0.093339,220.247574,11.219947,0.933395,-132.197388,0.093504,0.000000
80.150002,49.440636,-132.152908,-0.002186,0.003675,0.093339,219.922928,11.203408,0.933395,-132.152908,0.093504,0.000000
80.380005,49.389244,-132.197388,-0.002195,0.003675,0.093339,219.694336,11.191763,0.933395,-132.197388,0.093504,0.000000
80.610001,49.341583,-132.286346,-0.002195,0.003675,0.093339,219.482330,11.180963,0.933395,-132.286346,0.093504,0.000000
80.840004,49.276047,-132.286346,-0.002199,0.003675,0.093339,219.190796,11.166111,0.933395,-132.286346,0.093504,0.000000
81.070007,49.215347,-132.241867,-0.002199,0.003675,0.093339,218.920792,11.152357,0.933395,-132.241867,0.093504,0.000000
81.300003,49.168060,-132.286346,-0.002207,0.003675,0.093339,218.710449,11.141642,0.933395,-132.286346,0.093504,0.000000
81.530006,49.130821,-132.330826,-0.002190,0.003675,0.093339,218.544815,11.133204,0.933395,-132.330826,0.093504,0.000000
81.760002,49.051506,-132.330826,-0.002190,0.003675,0.093339,218.192001,11.115231,0.933395,-132.330826,0.093504,0.000000
81.990005,49.003845,-132.375305,-0.002195,0.003675,0.093339,217.979996,11.104430,0.933395,-132.375305,0.093504,0.000000
82.220001,48.962135,-132.330826,-0.002199,0.003675,0.093339,217.794449,11.094978,0.933395,-132.330826,0.093504,0.000000
82.450005,48.911118,-132.375305,-0.002182,0.003675,0.093339,217.567520,11.083418,0.933395,-132.375305,0.093504,0.000000
82.680000,48.858986,-132.464279,-0.002186,0.003675,0.093339,217.335617,11.071605,0.933395,-132.464279,0.093504,0.000000
82.910004,48.789352,-132.375305,-0.002190,0.003675,0.093339,217.025879,11.055825,0.933395,-132.375305,0.093504,0.000000
83.140007,48.764778,-132.419785,-0.002199,0.003675,0.093339,216.916565,11.050257,0.933395,-132.419785,0.093504,0.000000
83.370003,48.718231,-132.464279,-0.002186,0.003675,0.093339,216.709518,11.039709,0.933395,-132.464279,0.093504,0.000000
83.600006,48.661629,-132.464279,-0.002199,0.003675,0.093339,216.457733,11.026882,0.933395,-132.464279,0.093504,0.000000
83.830002,48.625137,-132.508759,-0.002177,0.003675,0.093339,216.295410,11.018614,0.933395,-132.508759,0.093504,0.000000
84.060005,48.580452,-132.553238,-0.002199,0.003675,0.093339,216.096649,11.008488,0.933395,-132.553238,0.093504,0.000000
84.290001,48.536514,-132.553238,-0.002190,0.003675,0.093339,215.901199,10.998531,0.933395,-132.553238,0.093504,0.000000
84.520004,48.488106,-132.642197,-0.002186,0.003675,0.093339,215.685867,10.987562,0.933395,-132.642197,0.093504,0.000000
84.750008,48.440445,-132.597717,-0.002195,0.003675,0.093339,215.473862,10.976762,0.933395,-132.597717,0.093504,0.000000
84.980003,48.415863,-132.642197,-0.002190,0.003675,0.093339,215.364517,10.971191,0.933395,-132.642197,0.093504,0.000000
85.210007,48.376022,-132.642197,-0.002177,0.003675,0.093339,215.187302,10.962163,0.933395,-132.642197,0.093504,0.000000
85.440002,48.310112,-132.731155,-0.002186,0.003675,0.093339,214.894104,10.947228,0.933395,-132.731155,0.093504,0.000000
85.670006,48.278458,-132.642197,-0.002177,0.003675,0.093339,214.753311,10.940055,0.933395,-132.642197,0.093504,0.000000
85.900002,48.252396,-132.642197,-0.002182,0.003675,0.093339,214.637375,10.934149,0.933395,-132.642197,0.093504,0.000000
86.130005,48.210320,-132.642197,-0.002173,0.003675,0.093339,214.450211,10.924615,0.933395,-132.642197,0.093504,0.000000
86.360001,48.170097,-132.775635,-0.002195,0.003675,0.093339,214.271301,10.915500,0.933395,-132.775635,0.093504,0.000000
86.590004,48.131744,-132.820114,-0.002173,0.003675,0.093339,214.100693,10.906810,0.933395,-132.820114,0.093504,0.000000
86.820007,48.097862,-132.775635,-0.002195,0.003675,0.093339,213.949982,10.899132,0.933395,-132.775635,0.093504,0.000000
87.050003,48.044983,-132.731155,-0.002186,0.003675,0.093339,213.714752,10.887149,0.933395,-132.731155,0.093504,0.000000
87.280006,48.019661,-132.775635,-0.002190,0.003675,0.093339,213.602127,10.881411,0.933395,-132.775635,0.093504,0.000000
87.510002,47.992477,-132.820114,-0.002190,0.003675,0.093339,213.481201,10.875251,0.933395,-132.820114,0.093504,0.000000
87.740005,47.950401,-132.953568,-0.002186,0.003675,0.093339,213.294037,10.865716,0.933395,-132.953568,0.093504,0.000000
87.970001,47.907578,-132.864594,-0.002207,0.003675,0.093339,213.103546,10.856012,0.933395,-132.864594,0.093504,0.000000
88.200005,47.881882,-132.864594,-0.002190,0.003675,0.093339,212.989243,10.850189,0.933395,-132.864594,0.093504,0.000000
88.430008,47.844643,-132.909088,-0.002177,0.003675,0.093339,212.823593,10.841751,0.933395,-132.909088,0.093504,0.000000
88.660004,47.821930,-132.998047,-0.002177,0.003675,0.093339,212.722565,10.836604,0.933395,-132.998047,0.093504,0.000000
88.890007,47.784691,-132.998047,-0.002182,0.003675,0.093339,212.556915,10.828166,0.933395,-132.998047,0.093504,0.000000
89.120003,47.749695,-132.998047,-0.002186,0.003675,0.093339,212.401245,10.820235,0.933395,-132.998047,0.093504,0.000000
89.350006,47.715805,-132.998047,-0.002186,0.003675,0.093339,212.250504,10.812556,0.933395,-132.998047,0.093504,0.000000
89.580002,47.680801,-132.998047,-0.002177,0.003675,0.093339,212.094803,10.804624,0.933395,-132.998047,0.093504,0.000000
89.810005,47.652130,-133.042526,-0.002177,0.003675,0.093339,211.967255,10.798127,0.933395,-133.042526,0.093504,0.000000
90.040001,47.621223,-133.087006,-0.002186,0.003675,0.093339,211.829788,10.791123,0.933395,-133.087006,0.093504,0.000000
90.270004,47.591431,-133.131485,-0.002199,0.003675,0.093339,211.697250,10.784372,0.933395,-133.131485,0.093504,0.000000
90.500008,47.571693,-133.087006,-0.002182,0.003675,0.093339,211.609467,10.779900,0.933395,-133.087006,0.093504,0.000000
90.730003,47.521797,-133.131485,-0.002195,0.003675,0.093339,211.387512,10.768593,0.933395,-133.131485,0.093504,0.000000
90.960007,47.493500,-133.175964,-0.002177,0.003675,0.093339,211.261642,10.762181,0.933395,-133.175964,0.093504,0.000000
91.190002,47.483444,-133.220444,-0.002190,0.003675,0.093339,211.216904,10.759902,0.933395,-133.220444,0.093504,0.000000
91.420006,47.435410,-133.131485,-0.002190,0.003675,0.093339,211.003235,10.749018,0.933395,-133.131485,0.093504,0.000000
91.650002,47.393700,-133.175964,-0.002190,0.003675,0.093339,210.817703,10.739566,0.933395,-133.175964,0.093504,0.000000
91.880005,47.381416,-133.220444,-0.002182,0.003675,0.093339,210.763062,10.736782,0.933395,-133.220444,0.093504,0.000000
92.110001,47.349762,-133.220444,-0.002195,0.003675,0.093339,210.622253,10.729609,0.933395,-133.220444,0.093504,0.000000
92.340004,47.318855,-133.353897,-0.002177,0.003675,0.093339,210.484787,10.722606,0.933395,-133.353897,0.093504,0.000000
92.570007,47.289436,-133.309418,-0.002182,0.003675,0.093339,210.353912,10.715940,0.933395,-133.309418,0.093504,0.000000
92.800003,47.274170,-133.309418,-0.002186,0.003675,0.093339,210.286011,10.712480,0.933395,-133.309418,0.093504,0.000000
93.030006,47.240288,-133.353897,-0.002195,0.003675,0.093339,210.135300,10.704802,0.933395,-133.353897,0.093504,0.000000
93.260002,47.212357,-133.398376,-0.002182,0.003675,0.093339,210.011047,10.698472,0.933395,-133.398376,0.093504,0.000000
93.490005,47.188522,-133.442856,-0.002173,0.003675,0.093339,209.905029,10.693071,0.933395,-133.442856,0.093504,0.000000
93.720001,47.149796,-133.398376,-0.002190,0.003675,0.093339,209.732773,10.684297,0.933395,-133.398376,0.093504,0.000000
93.950005,47.132668,-133.442856,-0.002186,0.003675,0.093339,209.656570,10.680415,0.933395,-133.442856,0.093504,0.000000
94.180008,47.095062,-133.398376,-0.002177,0.003675,0.093339,209.489304,10.671893,0.933395,-133.398376,0.093504,0.000000
94.410004,47.090218,-133.487335,-0.002190,0.003675,0.093339,209.467743,10.670796,0.933395,-133.487335,0.093504,0.000000
94.640007,47.060059,-133.487335,-0.002186,0.003675,0.093339,209.333603,10.663961,0.933395,-133.487335,0.093504,0.000000
94.870003,47.028778,-133.531815,-0.002177,0.003675,0.093339,209.194458,10.656874,0.933395,-133.531815,0.093504,0.000000
94.900002,47.016487,-133.487335,-0.002190,0.003675,0.093339,209.139786,10.654088,0.933395,-133.487335,0.093504,0.000000