File: Data/compression 10/AutoHeating-17-10-4-240424_04242024_225129.csv
Time (sec),S:Load (lbs),S:HL1 (DIM),S:LVDT (in),S:Position (in),Ch:Position (mm),Ch:Load (N),Ch:Stress (MPa),Ch:Strain (mm/mm),Ch:HL1 (DIM),Set Point (),Cycles ()
0.010000,-0.008934,-183.439438,-0.010106,-0.000000,-0.000000,-0.039741,-0.002024,-0.000000,-183.439438,-0.000009,0.000000
0.230000,0.009308,-183.528397,-0.010093,-0.000000,-0.000000,0.041403,0.002109,-0.000000,-183.528397,-0.000009,0.000000
0.450000,-0.001488,-183.572891,-0.010102,0.000052,0.001310,-0.006618,-0.000337,0.013096,-183.572891,0.001934,0.000000
0.670000,0.020859,-183.528397,-0.010093,0.000173,0.004397,0.092784,0.004727,0.043965,-183.528397,0.005593,0.000000
0.890000,0.013405,-183.572891,-0.009951,0.000324,0.008238,0.059628,0.003038,0.082382,-183.572891,0.009271,0.000000
1.110000,0.016762,-183.572891,-0.009787,0.000474,0.012046,0.074560,0.003798,0.120458,-183.572891,0.012930,0.000000
1.330000,-0.016380,-183.661850,-0.009658,0.000613,0.015567,-0.072863,-0.003712,0.155665,-183.661850,0.016590,0.000000
1.550000,-0.016754,-183.750809,-0.009494,0.000756,0.019209,-0.074526,-0.003797,0.192091,-183.750809,0.020267,0.000000
1.770000,0.012291,-183.661850,-0.009352,0.000905,0.022981,0.054673,0.002785,0.229811,-183.661850,0.023927,0.000000
1.990000,0.007080,-183.750809,-0.009218,0.001048,0.026624,0.031494,0.001604,0.266237,-183.750809,0.027587,0.000000
2.210000,0.021225,-183.750809,-0.009058,0.001184,0.030084,0.094413,0.004810,0.300839,-183.750809,0.031263,0.000000
2.430000,-0.002975,-183.795288,-0.008938,0.001331,0.033795,-0.013236,-0.000674,0.337953,-183.795288,0.034923,0.000000
2.650000,-0.014145,-183.795288,-0.008774,0.001475,0.037455,-0.062920,-0.003205,0.374553,-183.795288,0.038582,0.000000
2.870000,-0.029411,-183.795288,-0.008636,0.001622,0.041211,-0.130828,-0.006665,0.412107,-183.795288,0.042260,0.000000
3.090000,-0.014145,-183.884247,-0.008481,0.001764,0.044801,-0.062920,-0.003205,0.448010,-183.884247,0.045920,0.000000
3.310000,0.005585,-183.884247,-0.008364,0.001910,0.048521,0.024842,0.001266,0.485208,-183.884247,0.049579,0.000000
3.530000,0.032768,-183.884247,-0.008188,0.002061,0.052346,0.145760,0.007425,0.523459,-183.884247,0.053257,0.000000
3.750000,0.032028,-183.973221,-0.008054,0.002197,0.055797,0.142469,0.007258,0.557969,-183.973221,0.056916,0.000000
3.970000,0.032402,-184.017700,-0.007912,0.002343,0.059509,0.144131,0.007342,0.595091,-184.017700,0.060576,0.000000
4.190000,0.004097,-184.017700,-0.007761,0.002490,0.063238,0.018224,0.000928,0.632380,-184.017700,0.064235,0.000000
4.410000,-0.002975,-183.973221,-0.007614,0.002630,0.066794,-0.013236,-0.000674,0.667936,-183.973221,0.067912,0.000000
4.630000,-0.047661,-184.062180,-0.007489,0.002778,0.070549,-0.212006,-0.010800,0.705489,-184.062180,0.071572,0.000000
4.850000,-0.058090,-184.151138,-0.007330,0.002915,0.074052,-0.258398,-0.013163,0.740522,-184.151138,0.075232,0.000000
5.070000,-0.017128,-184.151138,-0.007183,0.003063,0.077808,-0.076189,-0.003881,0.778076,-184.151138,0.078909,0.000000
5.290000,0.026070,-184.106659,-0.007023,0.003207,0.081467,0.115964,0.005907,0.814668,-184.106659,0.082568,0.000000
5.510000,0.048782,-184.195618,-0.006881,0.003350,0.085101,0.216995,0.011054,0.851011,-184.195618,0.086228,0.000000
5.730000,0.047295,-184.195618,-0.006730,0.003502,0.088960,0.210377,0.010717,0.889602,-184.195618,0.089905,0.000000
5.950000,0.028305,-184.284576,-0.006584,0.003650,0.092706,0.125907,0.006414,0.927065,-184.284576,0.093565,0.000000
6.170000,-0.001488,-184.240097,-0.006441,0.003789,0.096236,-0.006618,-0.000337,0.962363,-184.240097,0.097225,0.000000
6.390000,-0.005959,-184.284576,-0.006303,0.003926,0.099730,-0.026505,-0.001350,0.997305,-184.284576,0.100902,0.000000
6.610000,-0.013405,-184.329056,-0.006153,0.004070,0.103390,-0.059628,-0.003038,1.033905,-184.329056,0.104562,0.000000
6.830000,0.002609,-184.329056,-0.006019,0.004220,0.107181,0.011607,0.000591,1.071807,-184.329056,0.108221,0.000000
7.050000,0.010803,-184.329056,-0.005872,0.004357,0.110658,0.048055,0.002448,1.106582,-184.329056,0.111898,0.000000
7.270000,0.052505,-184.373535,-0.005717,0.004502,0.114352,0.233556,0.011898,1.143523,-184.373535,0.115557,0.000000
7.490000,0.025322,-184.418030,-0.005588,0.004653,0.118194,0.112638,0.005738,1.181939,-184.418030,0.119217,0.000000
7.710001,0.016014,-184.418030,-0.005428,0.004799,0.121897,0.071234,0.003629,1.218971,-184.418030,0.122895,0.000000
7.930000,0.007080,-184.462509,-0.005312,0.004941,0.125513,0.031494,0.001604,1.255132,-184.462509,0.126554,0.000000
8.150001,0.035004,-184.506989,-0.005139,0.005087,0.129216,0.155704,0.007932,1.292163,-184.506989,0.130214,0.000000
8.370001,0.163849,-184.462509,-0.005006,0.005233,0.132919,0.728836,0.037129,1.329195,-184.462509,0.133873,0.000000
8.590000,0.593933,-184.506989,-0.004907,-0.000005,-0.000130,2.641946,0.134587,-0.001302,-184.506989,0.000104,0.000000
8.810000,0.564148,-184.551468,-0.004902,-0.000005,-0.000130,2.509455,0.127838,-0.001302,-184.551468,0.000104,0.000000
9.030001,0.524300,-184.551468,-0.004915,-0.000005,-0.000130,2.332201,0.118808,-0.001302,-184.551468,0.000104,0.000000
9.250000,0.581276,-184.640427,-0.004902,-0.000005,-0.000130,2.585644,0.131719,-0.001302,-184.640427,0.000425,0.000000
9.470000,0.631172,-184.640427,-0.004902,-0.000005,-0.000130,2.807594,0.143026,-0.001302,-184.640427,0.000789,0.000000
9.690001,0.585373,-184.684906,-0.004898,-0.000005,-0.000130,2.603869,0.132647,-0.001302,-184.684906,0.001153,0.000000
9.910001,0.591705,-184.684906,-0.004898,-0.000004,-0.000104,2.632037,0.134082,-0.001045,-184.684906,0.001518,0.000000
10.130000,1.102966,-184.773865,-0.004885,0.000039,0.000989,4.906239,0.249936,0.009886,-184.773865,0.001890,0.000000
10.350000,1.278732,-184.818344,-0.004855,0.000054,0.001370,5.688086,0.289765,0.013701,-184.818344,0.002254,0.000000
10.570001,1.382996,-184.818344,-0.004855,0.000063,0.001604,6.151872,0.313391,0.016040,-184.818344,0.002619,0.000000
10.790001,1.680145,-184.773865,-0.004833,0.000084,0.002133,7.473660,0.380726,0.021332,-184.773865,0.002992,0.000000
11.010000,1.897614,-184.818344,-0.004838,0.000098,0.002489,8.441007,0.430005,0.024889,-184.818344,0.003356,0.000000
11.230000,2.143753,-184.862839,-0.004812,0.000113,0.002861,9.535890,0.485781,0.028614,-184.862839,0.003720,0.000000
11.450001,2.304619,-184.907318,-0.004803,0.000124,0.003139,10.251456,0.522234,0.031392,-184.907318,0.004085,0.000000
11.670001,2.530273,-184.907318,-0.004803,0.000137,0.003468,11.255219,0.573368,0.034685,-184.907318,0.004457,0.000000
11.890000,3.004677,-184.951797,-0.004773,0.000157,0.003998,13.365470,0.680869,0.039976,-184.951797,0.004821,0.000000
12.110001,3.232941,-184.996277,-0.004773,0.000171,0.004336,14.380838,0.732595,0.043360,-184.996277,0.005186,0.000000
12.330001,3.382263,-184.996277,-0.004777,0.000179,0.004544,15.045058,0.766432,0.045441,-184.996277,0.005558,0.000000
12.550000,3.756126,-185.040756,-0.004743,0.000194,0.004917,16.708084,0.851150,0.049166,-185.040756,0.005923,0.000000
12.770000,4.242073,-184.996277,-0.004738,0.000216,0.005490,18.869684,0.961267,0.054896,-184.996277,0.006287,0.000000
12.990001,4.479271,-185.085236,-0.004717,0.000228,0.005801,19.924791,1.015017,0.058015,-185.085236,0.006652,0.000000
13.210001,4.788338,-185.085236,-0.004708,0.000245,0.006218,21.299589,1.085053,0.062178,-185.085236,0.007024,0.000000
13.430000,5.007294,-185.174194,-0.004704,0.000254,0.006461,22.273556,1.134669,0.064608,-185.174194,0.007389,0.000000
13.650001,5.390839,-185.174194,-0.004691,0.000270,0.006851,23.979649,1.221581,0.068507,-185.174194,0.007753,0.000000
13.870001,5.863380,-185.218674,-0.004674,0.000288,0.007310,26.081619,1.328661,0.073101,-185.218674,0.008117,0.000000
14.090001,6.081215,-185.174194,-0.004656,0.000299,0.007588,27.050594,1.378023,0.075880,-185.174194,0.008490,0.000000
14.310000,6.183250,-185.263168,-0.004661,0.000306,0.007779,27.504471,1.401145,0.077787,-185.263168,0.008854,0.000000
14.530001,6.577965,-185.263168,-0.004648,0.000321,0.008143,29.260248,1.490588,0.081428,-185.263168,0.009218,0.000000
14.750001,7.227379,-185.307648,-0.004639,0.000344,0.008733,32.148987,1.637748,0.087325,-185.307648,0.009591,0.000000
14.970000,7.483200,-185.307648,-0.004609,0.000360,0.009131,33.286938,1.695717,0.091314,-185.307648,0.009956,0.000000
15.190001,7.635872,-185.307648,-0.004613,0.000371,0.009435,33.966053,1.730313,0.094350,-185.307648,0.010320,0.000000
15.410001,7.833603,-185.441086,-0.004605,0.000382,0.009713,34.845608,1.775120,0.097128,-185.441086,0.010684,0.000000
15.630001,8.284546,-185.396606,-0.004579,0.000399,0.010129,36.851501,1.877305,0.101291,-185.396606,0.011057,0.000000
15.850000,8.634949,-185.441086,-0.004596,0.000412,0.010476,38.410172,1.956707,0.104758,-185.441086,0.011421,0.000000
16.070002,8.903427,-185.485565,-0.004553,0.000425,0.010797,39.604424,2.017545,0.107968,-185.485565,0.011785,0.000000
16.290001,8.955559,-185.441086,-0.004549,0.000436,0.011075,39.836315,2.029359,0.110746,-185.441086,0.012159,0.000000
16.510000,9.392349,-185.485565,-0.004549,0.000449,0.011412,41.779255,2.128337,0.114122,-185.485565,0.012523,0.000000
16.730001,9.965065,-185.530045,-0.004527,0.000471,0.011959,44.326824,2.258116,0.119588,-185.530045,0.012887,0.000000
16.950001,10.207108,-185.619003,-0.004510,0.000486,0.012340,45.403481,2.312963,0.123403,-185.619003,0.013251,0.000000
17.170000,10.474838,-185.619003,-0.004506,0.000500,0.012704,46.594406,2.373632,0.127044,-185.619003,0.013624,0.000000
17.390001,10.549690,-185.574524,-0.004501,0.000512,0.013017,46.927364,2.390594,0.130170,-185.574524,0.013988,0.000000
17.610001,10.458824,-185.574524,-0.004484,0.000520,0.013199,46.523174,2.370003,0.131987,-185.574524,0.014352,0.000000
17.830000,11.370392,-185.707977,-0.004458,0.000543,0.013780,50.578030,2.576568,0.137800,-185.707977,0.014726,0.000000
18.050001,11.400932,-185.707977,-0.004462,0.000553,0.014058,50.713879,2.583488,0.140579,-185.707977,0.015090,0.000000
18.270000,11.721542,-185.707977,-0.004441,0.000568,0.014430,52.140026,2.656139,0.144303,-185.707977,0.015454,0.000000
18.490002,12.212700,-185.752457,-0.004441,0.000586,0.014872,54.324802,2.767437,0.148724,-185.752457,0.015818,0.000000
18.710001,12.720993,-185.752457,-0.004424,0.000606,0.015401,56.585804,2.882618,0.154015,-185.752457,0.016191,0.000000
18.930000,12.817062,-185.796936,-0.004398,0.000620,0.015757,57.013142,2.904388,0.157573,-185.796936,0.016555,0.000000
19.150002,12.939949,-185.885895,-0.004393,0.000632,0.016043,57.559769,2.932234,0.160434,-185.885895,0.016919,0.000000
19.370001,13.120171,-185.930374,-0.004372,0.000647,0.016434,58.361435,2.973073,0.164340,-185.930374,0.017292,0.000000
19.590000,13.528297,-185.841415,-0.004368,0.000662,0.016824,60.176872,3.065556,0.168239,-185.841415,0.017657,0.000000
19.810001,13.790817,-185.841415,-0.004350,0.000676,0.017162,61.344620,3.125044,0.171622,-185.841415,0.018021,0.000000
20.030001,13.844437,-185.974854,-0.004337,0.000685,0.017388,61.583130,3.137194,0.173878,-185.974854,0.018385,0.000000
20.250002,14.127441,-186.019333,-0.004346,0.000699,0.017752,62.841999,3.201324,0.177519,-186.019333,0.018758,0.000000
20.470001,14.651741,-185.974854,-0.004320,0.000718,0.018237,65.174202,3.320132,0.182371,-185.974854,0.019122,0.000000
20.690001,14.916496,-186.019333,-0.004316,0.000734,0.018645,66.351891,3.380126,0.186451,-186.019333,0.019486,0.000000
20.910002,15.205833,-186.063812,-0.004303,0.000749,0.019035,67.638924,3.445691,0.190350,-186.063812,0.019859,0.000000
21.130001,15.290359,-186.063812,-0.004268,0.000761,0.019339,68.014915,3.464845,0.193385,-186.063812,0.020223,0.000000
21.350000,15.614700,-186.108292,-0.004264,0.000777,0.019737,69.457657,3.538342,0.197375,-186.108292,0.020588,0.000000
21.570002,16.011642,-186.197266,-0.004268,0.000795,0.020180,71.223343,3.628290,0.201803,-186.197266,0.020952,0.000000
21.790001,16.127823,-186.152786,-0.004238,0.000806,0.020484,71.740143,3.654617,0.204839,-186.152786,0.021325,0.000000
22.010000,16.247360,-186.197266,-0.004243,0.000816,0.020726,72.271866,3.681705,0.207261,-186.197266,0.021689,0.000000
22.230001,16.666275,-186.241745,-0.004238,0.000837,0.021264,74.135292,3.776632,0.212643,-186.241745,0.022053,0.000000
22.450001,17.118340,-186.330704,-0.004221,0.000853,0.021663,76.146179,3.879071,0.216632,-186.330704,0.022426,0.000000
22.670002,17.347343,-186.330704,-0.004204,0.000868,0.022045,77.164841,3.930964,0.220447,-186.330704,0.022790,0.000000
22.890001,17.324257,-186.330704,-0.004195,0.000879,0.022339,77.062141,3.925733,0.223392,-186.330704,0.023154,0.000000
23.110001,17.549545,-186.330704,-0.004174,0.000895,0.022721,78.064278,3.976784,0.227207,-186.330704,0.023519,0.000000
23.330002,17.959152,-186.330704,-0.004178,0.000911,0.023146,79.886299,4.069602,0.231461,-186.330704,0.023892,0.000000
23.550001,18.127464,-186.419662,-0.004148,0.000926,0.023510,80.634987,4.107742,0.235103,-186.419662,0.024256,0.000000
23.770000,18.285355,-186.419662,-0.004143,0.000938,0.023831,81.337318,4.143520,0.238312,-186.419662,0.024620,0.000000
23.990002,18.106987,-186.464142,-0.004135,0.000944,0.023979,80.543900,4.103102,0.239788,-186.464142,0.024993,0.000000
24.210001,18.902374,-186.464142,-0.004126,0.000968,0.024594,84.081963,4.283340,0.245942,-186.464142,0.025357,0.000000
24.430000,19.202881,-186.553116,-0.004109,0.000984,0.024993,85.418678,4.351435,0.249932,-186.553116,0.025721,0.000000
24.650002,19.274002,-186.553116,-0.004096,0.000997,0.025332,85.735046,4.367551,0.253315,-186.553116,0.026086,0.000000
24.870001,19.317566,-186.553116,-0.004087,0.001010,0.025653,85.928825,4.377423,0.256525,-186.553116,0.026459,0.000000
25.090002,19.513062,-186.553116,-0.004083,0.001025,0.026025,86.798431,4.421723,0.260249,-186.553116,0.026823,0.000000
25.310001,19.785271,-186.553116,-0.004074,0.001040,0.026406,88.009277,4.483407,0.264065,-186.553116,0.027188,0.000000
25.530001,20.004227,-186.642075,-0.004057,0.001054,0.026780,88.983246,4.533022,0.267796,-186.642075,0.027560,0.000000
25.750002,20.144234,-186.686554,-0.004036,0.001067,0.027109,89.606026,4.564749,0.271089,-186.686554,0.027924,0.000000
25.970001,19.831070,-186.731033,-0.004031,0.001071,0.027196,88.213005,4.493784,0.271960,-186.731033,0.028288,0.000000
26.190001,20.770569,-186.686554,-0.004018,0.001097,0.027855,92.392105,4.706678,0.278553,-186.686554,0.028653,0.000000
26.410002,20.942604,-186.686554,-0.003997,0.001112,0.028237,93.157356,4.745662,0.282368,-186.686554,0.029026,0.000000
26.630001,21.152992,-186.731033,-0.003997,0.001127,0.028618,94.093208,4.793336,0.286183,-186.731033,0.029390,0.000000
26.850000,21.017822,-186.819992,-0.003984,0.001138,0.028904,93.491943,4.762707,0.289045,-186.819992,0.029755,0.000000
27.070002,21.257256,-186.908951,-0.003958,0.001152,0.029269,94.556992,4.816963,0.292686,-186.908951,0.030119,0.000000
27.290001,21.387589,-186.864471,-0.003954,0.001166,0.029624,95.136742,4.846497,0.296244,-186.864471,0.030491,0.000000
27.510002,21.733894,-186.864471,-0.003945,0.001183,0.030049,96.677193,4.924971,0.300490,-186.864471,0.030856,0.000000
27.730001,21.913750,-186.908951,-0.003932,0.001197,0.030413,97.477226,4.965727,0.304131,-186.908951,0.031220,0.000000
27.950001,21.597977,-186.908951,-0.003928,0.001203,0.030552,96.072601,4.894172,0.305524,-186.908951,0.031593,0.000000
28.170002,22.288353,-186.953430,-0.003911,0.001225,0.031116,99.143547,5.050613,0.311156,-186.953430,0.031957,0.000000
28.390001,22.509544,-186.997925,-0.003906,0.001241,0.031515,100.127457,5.100736,0.315145,-186.997925,0.032321,0.000000
28.610001,22.686798,-187.042404,-0.003885,0.001256,0.031905,100.915916,5.140902,0.319052,-187.042404,0.032686,0.000000
28.830002,22.656631,-187.042404,-0.003880,0.001268,0.032200,100.781731,5.134066,0.321996,-187.042404,0.033058,0.000000
29.050001,22.725151,-187.131363,-0.003872,0.001281,0.032538,101.086517,5.149593,0.325380,-187.131363,0.033423,0.000000
29.270000,22.892342,-187.175842,-0.003867,0.001295,0.032902,101.830223,5.187479,0.329021,-187.175842,0.033787,0.000000
29.490002,23.251686,-187.131363,-0.003854,0.001313,0.033353,103.428665,5.268907,0.333533,-187.131363,0.034159,0.000000
29.710001,23.305679,-187.175842,-0.003850,0.001324,0.033639,103.668839,5.281143,0.336394,-187.175842,0.034524,0.000000
29.930002,22.970169,-187.220322,-0.003833,0.001331,0.033813,102.176414,5.205114,0.338127,-187.220322,0.034888,0.000000
30.150002,23.752899,-187.220322,-0.003820,0.001354,0.034394,105.658173,5.382484,0.343941,-187.220322,0.035253,0.000000
30.370001,23.976318,-187.264801,-0.003811,0.001370,0.034793,106.651993,5.433111,0.347930,-187.264801,0.035626,0.000000
30.590002,24.080956,-187.264801,-0.003786,0.001383,0.035131,107.117439,5.456823,0.351314,-187.264801,0.035990,0.000000
30.810001,23.965897,-187.309280,-0.003794,0.001394,0.035418,106.605629,5.430750,0.354175,-187.309280,0.036354,0.000000
31.030001,24.072021,-187.264801,-0.003777,0.001409,0.035782,107.077698,5.454798,0.357816,-187.264801,0.036727,0.000000
31.250002,24.311455,-187.353760,-0.003786,0.001423,0.036137,108.142754,5.509054,0.361374,-187.353760,0.037091,0.000000
31.470001,24.584778,-187.398254,-0.003764,0.001437,0.036510,109.358551,5.570991,0.365099,-187.398254,0.037455,0.000000
31.690002,24.708405,-187.398254,-0.003747,0.001452,0.036891,109.908470,5.599005,0.368914,-187.398254,0.037819,0.000000
31.910002,24.530411,-187.398254,-0.003738,0.001461,0.037100,109.116714,5.558671,0.370995,-187.398254,0.038193,0.000000
32.130001,25.149666,-187.487213,-0.003747,0.001483,0.037663,111.871300,5.698996,0.376635,-187.487213,0.038557,0.000000
32.350002,25.147804,-187.531693,-0.003729,0.001495,0.037967,111.863022,5.698574,0.379670,-187.531693,0.038921,0.000000
32.570000,25.289680,-187.576172,-0.003721,0.001511,0.038374,112.494118,5.730724,0.383743,-187.576172,0.039294,0.000000
32.790001,25.288185,-187.576172,-0.003712,0.001523,0.038678,112.487465,5.730385,0.386778,-187.576172,0.039658,0.000000
33.010002,25.371231,-187.531693,-0.003686,0.001535,0.038981,112.856873,5.749203,0.389814,-187.531693,0.040022,0.000000
33.230003,26.030701,-187.576172,-0.003695,0.001556,0.039520,115.790337,5.898641,0.395196,-187.576172,0.040386,0.000000
33.450001,26.051178,-187.665131,-0.003682,0.001569,0.039857,115.881424,5.903281,0.398572,-187.665131,0.040760,0.000000
33.670002,25.760727,-187.709610,-0.003656,0.001577,0.040057,114.589439,5.837464,0.400571,-187.709610,0.041124,0.000000
33.890003,25.991226,-187.665131,-0.003656,0.001592,0.040429,115.614746,5.889696,0.404295,-187.665131,0.041488,0.000000
34.110001,26.728149,-187.665131,-0.003635,0.001614,0.041003,118.892746,6.056685,0.410025,-187.665131,0.041861,0.000000
34.330002,26.662613,-187.754089,-0.003622,0.001627,0.041314,118.601227,6.041835,0.413144,-187.754089,0.042225,0.000000
34.550003,26.854012,-187.798569,-0.003622,0.001644,0.041748,119.452606,6.085206,0.417481,-187.798569,0.042589,0.000000
34.770000,26.666336,-187.843063,-0.003613,0.001655,0.042025,118.617790,6.042678,0.420252,-187.843063,0.042953,0.000000
34.990002,26.824600,-187.843063,-0.003596,0.001668,0.042355,119.321777,6.078541,0.423552,-187.843063,0.043326,0.000000
35.210003,27.202187,-187.932022,-0.003596,0.001685,0.042789,121.001366,6.164104,0.427890,-187.932022,0.043691,0.000000
35.430000,27.237556,-187.887543,-0.003591,0.001696,0.043083,121.158699,6.172119,0.430835,-187.887543,0.044055,0.000000
35.650002,26.943008,-187.932022,-0.003570,0.001704,0.043292,119.848488,6.105373,0.432916,-187.932022,0.044428,0.000000
35.870003,27.210373,-187.976501,-0.003566,0.001719,0.043665,121.037781,6.165959,0.436648,-187.976501,0.044792,0.000000
36.090000,28.012466,-187.976501,-0.003548,0.001741,0.044228,124.605675,6.347716,0.442280,-187.976501,0.045156,0.000000
36.310001,28.333450,-187.976501,-0.003540,0.001760,0.044697,126.033478,6.420452,0.446966,-187.976501,0.045520,0.000000
36.530003,28.109657,-187.976501,-0.003518,0.001769,0.044922,125.038002,6.369740,0.449222,-187.976501,0.045893,0.000000
36.750000,28.124924,-188.020981,-0.003527,0.001781,0.045243,125.105911,6.373199,0.452431,-188.020981,0.046257,0.000000
36.970001,28.251900,-188.154419,-0.003510,0.001796,0.045616,125.670723,6.401972,0.456156,-188.154419,0.046622,0.000000
37.190002,28.546074,-188.109940,-0.003492,0.001811,0.046006,126.979279,6.468633,0.460062,-188.109940,0.046995,0.000000
37.410004,28.590012,-188.154419,-0.003505,0.001824,0.046318,127.174721,6.478590,0.463180,-188.154419,0.047359,0.000000
37.630001,28.318184,-188.154419,-0.003484,0.001832,0.046526,125.965576,6.416992,0.465262,-188.154419,0.047723,0.000000
37.850002,28.730774,-188.198898,-0.003492,0.001848,0.046943,127.800865,6.510486,0.469425,-188.198898,0.048087,0.000000
38.070004,29.503815,-188.287872,-0.003471,0.001870,0.047497,131.239517,6.685660,0.474974,-188.287872,0.048460,0.000000
38.290001,29.711227,-188.287872,-0.003458,0.001885,0.047879,132.162140,6.732660,0.478789,-188.287872,0.048824,0.000000
38.510002,29.799850,-188.287872,-0.003445,0.001899,0.048235,132.556351,6.752742,0.482347,-188.287872,0.049188,0.000000
38.730003,29.799110,-188.287872,-0.003441,0.001912,0.048573,132.553070,6.752575,0.485731,-188.287872,0.049553,0.000000
38.950001,29.625580,-188.332352,-0.003441,0.001925,0.048885,131.781158,6.713252,0.488849,-188.332352,0.049926,0.000000
39.170002,30.180420,-188.332352,-0.003410,0.001941,0.049293,134.249207,6.838981,0.492930,-188.332352,0.050290,0.000000
39.390003,30.037796,-188.421310,-0.003410,0.001953,0.049597,133.614792,6.806662,0.495965,-188.421310,0.050655,0.000000
39.610001,30.407936,-188.421310,-0.003389,0.001968,0.049978,135.261261,6.890537,0.499780,-188.421310,0.051027,0.000000
39.830002,30.751640,-188.465790,-0.003402,0.001984,0.050403,136.790131,6.968421,0.504027,-188.465790,0.051391,0.000000
40.050003,31.449837,-188.465790,-0.003376,0.002006,0.050941,139.895859,7.126635,0.509409,-188.465790,0.051755,0.000000
40.270000,31.533989,-188.510269,-0.003367,0.002021,0.051322,140.270187,7.145704,0.513224,-188.510269,0.052120,0.000000
40.490002,31.302376,-188.510269,-0.003354,0.002030,0.051565,139.239929,7.093220,0.515647,-188.510269,0.052493,0.000000
40.710003,31.444252,-188.465790,-0.003354,0.002045,0.051947,139.871017,7.125370,0.519469,-188.465790,0.052857,0.000000
40.930000,31.727257,-188.554749,-0.003350,0.002061,0.052346,141.129883,7.189499,0.523459,-188.554749,0.053222,0.000000
41.150002,31.835243,-188.554749,-0.003324,0.002075,0.052693,141.610229,7.213969,0.526926,-188.554749,0.053594,0.000000
41.370003,31.929825,-188.643707,-0.003328,0.002087,0.053004,142.030960,7.235402,0.530044,-188.643707,0.053958,0.000000
41.590000,31.840454,-188.643707,-0.003311,0.002101,0.053360,141.633408,7.215150,0.533602,-188.643707,0.054323,0.000000
41.810001,32.491737,-188.688202,-0.003294,0.002118,0.053785,144.530472,7.362733,0.537849,-188.688202,0.054687,0.000000
42.030003,32.813095,-188.688202,-0.003294,0.002133,0.054175,145.959930,7.435554,0.541755,-188.688202,0.055060,0.000000
42.250004,33.032417,-188.732681,-0.003281,0.002148,0.054565,146.935532,7.485253,0.545653,-188.732681,0.055424,0.000000
42.470001,32.997040,-188.821640,-0.003272,0.002160,0.054869,146.778168,7.477236,0.548689,-188.821640,0.055789,0.000000
42.690002,33.302757,-188.777161,-0.003260,0.002175,0.055250,148.138062,7.546513,0.552504,-188.777161,0.056161,0.000000
42.910004,33.779022,-188.777161,-0.003260,0.002193,0.055693,150.256592,7.654436,0.556932,-188.777161,0.056526,0.000000
43.130001,33.837860,-188.777161,-0.003247,0.002205,0.056014,150.518326,7.667769,0.560142,-188.777161,0.056890,0.000000
43.350002,33.769341,-188.821640,-0.003242,0.002214,0.056248,150.213531,7.652242,0.562481,-188.821640,0.057254,0.000000
43.570004,34.661545,-188.910599,-0.003238,0.002238,0.056838,154.182251,7.854418,0.568378,-188.910599,0.057627,0.000000
43.790001,34.938965,-188.999557,-0.003229,0.002252,0.057211,155.416275,7.917283,0.572110,-188.999557,0.057991,0.000000
44.010002,35.175049,-188.866119,-0.003212,0.002267,0.057592,156.466431,7.970780,0.575925,-188.866119,0.058356,0.000000
44.230003,35.079720,-188.999557,-0.003216,0.002279,0.057879,156.042389,7.949178,0.578786,-188.999557,0.058728,0.000000
44.450001,35.200371,-188.999557,-0.003203,0.002293,0.058234,156.579071,7.976518,0.582336,-188.999557,0.059093,0.000000
44.670002,35.659882,-189.044037,-0.003191,0.002310,0.058667,158.623077,8.080645,0.586674,-189.044037,0.059457,0.000000
44.890003,35.802498,-189.088516,-0.003173,0.002323,0.058997,159.257462,8.112962,0.589974,-189.088516,0.059821,0.000000
45.110001,35.973419,-189.088516,-0.003173,0.002335,0.059318,160.017761,8.151693,0.593176,-189.088516,0.060194,0.000000
45.330002,35.595459,-189.088516,-0.003160,0.002342,0.059492,158.336502,8.066046,0.594917,-189.088516,0.060558,0.000000
45.550003,36.337227,-189.177490,-0.003160,0.002366,0.060090,161.636063,8.234134,0.600897,-189.177490,0.060922,0.000000
45.770000,37.211182,-189.221970,-0.003139,0.002382,0.060514,165.523605,8.432175,0.605144,-189.221970,0.061296,0.000000
45.990002,37.311722,-189.221970,-0.003139,0.002396,0.060870,165.970825,8.454957,0.608702,-189.221970,0.061660,0.000000
46.210003,37.382477,-189.221970,-0.003130,0.002410,0.061209,166.285568,8.470990,0.612086,-189.221970,0.062024,0.000000
46.430000,37.462158,-189.221970,-0.003117,0.002422,0.061530,166.639999,8.489046,0.615295,-189.221970,0.062388,0.000000
46.650002,37.760429,-189.310928,-0.003109,0.002438,0.061937,167.966782,8.556635,0.619368,-189.310928,0.062761,0.000000
46.870003,38.111580,-189.310928,-0.003109,0.002453,0.062310,169.528778,8.636208,0.623100,-189.310928,0.063125,0.000000
47.090004,38.309685,-189.310928,-0.003113,0.002465,0.062622,170.409988,8.681098,0.626218,-189.310928,0.063489,0.000000
47.310001,37.728409,-189.399887,-0.003091,0.002469,0.062709,167.824341,8.549379,0.627089,-189.399887,0.063863,0.000000
47.530003,39.109909,-189.399887,-0.003078,0.002495,0.063368,173.969559,8.862432,0.633682,-189.399887,0.064227,0.000000
47.750004,39.283432,-189.444366,-0.003061,0.002508,0.063715,174.741440,8.901752,0.637149,-189.444366,0.064591,0.000000
47.970001,39.968597,-189.488846,-0.003061,0.002526,0.064157,177.789200,9.057014,0.641570,-189.488846,0.064955,0.000000
48.190002,39.788376,-189.533325,-0.003057,0.002537,0.064443,176.987534,9.016174,0.644431,-189.533325,0.065328,0.000000
48.410004,40.089622,-189.488846,-0.003035,0.002550,0.064782,178.327545,9.084438,0.647815,-189.488846,0.065692,0.000000
48.630001,40.025200,-189.533325,-0.003048,0.002562,0.065077,178.040985,9.069839,0.650767,-189.533325,0.066056,0.000000
48.850002,40.819847,-189.533325,-0.003040,0.002579,0.065519,181.575745,9.249910,0.655188,-189.533325,0.066429,0.000000
49.070004,41.066353,-189.622299,-0.003044,0.002594,0.065891,182.672256,9.305769,0.658912,-189.622299,0.066794,0.000000
49.290001,40.823196,-189.622299,-0.003018,0.002602,0.066099,181.590652,9.250669,0.660994,-189.622299,0.067158,0.000000
49.510002,41.777588,-189.666779,-0.003018,0.002621,0.066585,185.835999,9.466937,0.665854,-189.666779,0.067522,0.000000
49.730003,42.270233,-189.577820,-0.003001,0.002639,0.067027,188.027390,9.578572,0.670275,-189.577820,0.067895,0.000000
49.950001,42.654892,-189.622299,-0.002988,0.002654,0.067401,189.738434,9.665737,0.674007,-189.622299,0.068259,0.000000
50.170002,42.928215,-189.755737,-0.002979,0.002667,0.067739,190.954239,9.727673,0.677390,-189.755737,0.068623,0.000000
50.390003,42.956146,-189.755737,-0.002979,0.002679,0.068043,191.078476,9.734002,0.680426,-189.755737,0.068996,0.000000
50.610001,43.129669,-189.711258,-0.002975,0.002691,0.068354,191.850357,9.773323,0.683544,-189.711258,0.069360,0.000000
50.830002,43.803291,-189.755737,-0.002971,0.002710,0.068840,194.846771,9.925967,0.688404,-189.755737,0.069725,0.000000
51.050003,44.241577,-189.844696,-0.002962,0.002723,0.069161,196.796371,10.025285,0.691614,-189.844696,0.070089,0.000000
51.270004,43.776108,-189.800217,-0.002945,0.002730,0.069352,194.725845,9.919807,0.693521,-189.800217,0.070462,0.000000
51.490002,45.009781,-189.978149,-0.002945,0.002753,0.069915,200.213501,10.199362,0.699153,-189.978149,0.070826,0.000000
51.710003,45.587326,-189.933655,-0.002923,0.002769,0.070341,202.782547,10.330235,0.703408,-189.933655,0.071190,0.000000
51.930004,45.896400,-189.844696,-0.002915,0.002784,0.070713,204.157379,10.400272,0.707132,-189.844696,0.071554,0.000000
52.150002,45.812614,-189.933655,-0.002906,0.002794,0.070956,203.784683,10.381288,0.709562,-189.933655,0.071927,0.000000
52.370003,46.079979,-189.933655,-0.002906,0.002808,0.071320,204.973984,10.441873,0.713203,-189.933655,0.072291,0.000000
52.590004,46.457939,-190.022629,-0.002902,0.002822,0.071676,206.655228,10.527519,0.716761,-190.022629,0.072656,0.000000
52.810001,46.998619,-190.022629,-0.002884,0.002836,0.072032,209.060303,10.650039,0.720318,-190.022629,0.073029,0.000000
53.030003,47.359077,-190.067108,-0.002876,0.002851,0.072422,210.663696,10.731720,0.724217,-190.067108,0.073393,0.000000
53.250004,47.212738,-190.022629,-0.002880,0.002860,0.072647,210.012741,10.698560,0.726473,-190.022629,0.073757,0.000000
53.470001,48.340279,-190.111588,-0.002884,0.002883,0.073220,215.028305,10.954063,0.732195,-190.111588,0.074122,0.000000
53.690002,48.503006,-190.111588,-0.002867,0.002894,0.073497,215.752151,10.990938,0.734974,-190.111588,0.074494,0.000000
53.910004,49.026558,-190.156067,-0.002859,0.002911,0.073931,218.081024,11.109576,0.739311,-190.156067,0.074858,0.000000
54.130001,49.240677,-190.067108,-0.002846,0.002923,0.074234,219.033463,11.158097,0.742339,-190.067108,0.075223,0.000000
54.350002,49.379570,-190.200546,-0.002833,0.002936,0.074564,219.651291,11.189571,0.745639,-190.200546,0.075596,0.000000
54.570004,50.257622,-190.245026,-0.002837,0.002953,0.075015,223.557068,11.388540,0.750151,-190.245026,0.075960,0.000000
54.790001,50.721970,-190.289505,-0.002824,0.002968,0.075379,225.622589,11.493762,0.753792,-190.289505,0.076324,0.000000
55.010002,50.433014,-190.289505,-0.002815,0.002975,0.075570,224.337250,11.428284,0.755700,-190.289505,0.076689,0.000000
55.230003,50.743568,-190.289505,-0.002807,0.002988,0.075891,225.718658,11.498657,0.758909,-190.289505,0.077061,0.000000
55.450001,52.202896,-190.333984,-0.002790,0.003012,0.076515,232.210083,11.829346,0.765154,-190.333984,0.077425,0.000000
55.670002,52.599472,-190.378464,-0.002777,0.003025,0.076836,233.974136,11.919211,0.768356,-190.378464,0.077790,0.000000
55.890003,53.093613,-190.422958,-0.002768,0.003042,0.077269,236.172180,12.031184,0.772694,-190.422958,0.078163,0.000000
56.110004,53.278313,-190.422958,-0.002768,0.003055,0.077590,236.993774,12.073038,0.775903,-190.422958,0.078527,0.000000
56.330002,53.582909,-190.422958,-0.002759,0.003066,0.077886,238.348679,12.142060,0.778856,-190.422958,0.078892,0.000000
56.550003,54.265839,-190.467438,-0.002759,0.003083,0.078310,241.386505,12.296815,0.783102,-190.467438,0.079256,0.000000
56.770004,54.635231,-190.511917,-0.002742,0.003095,0.078622,243.029648,12.380521,0.786221,-190.511917,0.079628,0.000000
56.990002,54.438995,-190.511917,-0.002746,0.003104,0.078830,242.156738,12.336053,0.788303,-190.511917,0.079993,0.000000
57.210003,54.878769,-190.600876,-0.002725,0.003118,0.079186,244.112961,12.435706,0.791861,-190.600876,0.080357,0.000000
57.430004,56.168663,-190.511917,-0.002725,0.003140,0.079767,249.850693,12.728001,0.797674,-190.511917,0.080730,0.000000
57.650002,56.735413,-190.600876,-0.002712,0.003155,0.080140,252.371719,12.856428,0.801399,-190.600876,0.081094,0.000000
57.870003,56.994957,-190.689835,-0.002708,0.003167,0.080443,253.526230,12.915242,0.804434,-190.689835,0.081459,0.000000
58.090004,57.303658,-190.689835,-0.002690,0.003180,0.080764,254.899399,12.985194,0.807644,-190.689835,0.081823,0.000000
58.310001,57.759064,-190.689835,-0.002690,0.003193,0.081111,256.925140,13.088391,0.811111,-190.689835,0.082195,0.000000
58.530003,58.259537,-190.734314,-0.002682,0.003209,0.081510,259.151367,13.201800,0.815100,-190.734314,0.082560,0.000000
58.750004,58.775642,-190.689835,-0.002677,0.003222,0.081840,261.447113,13.318751,0.818400,-190.689835,0.082924,0.000000
58.970001,58.797241,-190.778793,-0.002682,0.003234,0.082144,261.543182,13.323646,0.821436,-190.778793,0.083296,0.000000
59.190002,59.292496,-190.778793,-0.002656,0.003246,0.082447,263.746185,13.435872,0.824471,-190.778793,0.083661,0.000000
59.410004,60.504944,-190.867767,-0.002660,0.003267,0.082976,269.139435,13.710616,0.829763,-190.867767,0.084025,0.000000
59.630001,61.231438,-190.823273,-0.002643,0.003283,0.083384,272.371033,13.875242,0.833835,-190.823273,0.084390,0.000000
59.850002,61.845108,-190.823273,-0.002643,0.003297,0.083739,275.100769,14.014301,0.837393,-190.823273,0.084763,0.000000
60.070004,62.341110,-190.912247,-0.002639,0.003311,0.084094,277.307098,14.126698,0.840943,-190.912247,0.085127,0.000000
60.290005,62.482986,-190.912247,-0.002626,0.003324,0.084442,277.938202,14.158847,0.844418,-190.912247,0.085491,0.000000
60.510002,63.454498,-190.956726,-0.002617,0.003339,0.084814,282.259705,14.378995,0.848142,-190.956726,0.085864,0.000000
60.730003,63.324539,-190.956726,-0.002604,0.003348,0.085049,281.681610,14.349545,0.850489,-190.956726,0.086228,0.000000
60.950005,64.333679,-190.912247,-0.002596,0.003365,0.085482,286.170502,14.578220,0.854819,-190.912247,0.086592,0.000000
61.170002,65.149170,-191.045685,-0.002600,0.003383,0.085933,289.797974,14.763013,0.859330,-191.045685,0.086956,0.000000
61.390003,66.499771,-191.090164,-0.002574,0.003404,0.086470,295.805756,15.069063,0.864705,-191.090164,0.087330,0.000000
61.610004,67.036728,-191.134644,-0.002578,0.003419,0.086844,298.194244,15.190740,0.868437,-191.134644,0.087694,0.000000
61.830002,67.178223,-191.090164,-0.002583,0.003429,0.087104,298.823669,15.222803,0.871041,-191.090164,0.088058,0.000000
62.050003,67.595657,-191.134644,-0.002565,0.003434,0.087225,300.680511,15.317395,0.872252,-191.134644,0.087460,0.000000
62.270004,66.391403,-191.179123,-0.002561,0.003432,0.087182,295.323700,15.044507,0.871820,-191.179123,0.087460,0.000000
62.490002,65.462708,-191.223602,-0.002561,0.003431,0.087147,291.192657,14.834062,0.871472,-191.223602,0.087182,0.000000
62.710003,64.513153,-191.268097,-0.002535,0.003430,0.087130,286.968842,14.618890,0.871298,-191.268097,0.087182,0.000000
62.930004,63.649994,-191.223602,-0.002544,0.003430,0.087112,283.129303,14.423295,0.871124,-191.223602,0.087182,0.000000
63.150002,62.849396,-191.312576,-0.002552,0.003430,0.087112,279.568085,14.241877,0.871124,-191.312576,0.087182,0.000000
63.370003,62.100555,-191.312576,-0.002552,0.003429,0.087104,276.237061,14.072186,0.871041,-191.312576,0.087182,0.000000
63.590004,61.380020,-191.357056,-0.002539,0.003429,0.087104,273.031952,13.908912,0.871041,-191.357056,0.087182,0.000000
63.810001,60.714218,-191.357056,-0.002531,0.003429,0.087104,270.070343,13.758038,0.871041,-191.357056,0.087182,0.000000
64.030006,60.098312,-191.401535,-0.002535,0.003429,0.087095,267.330658,13.618472,0.870950,-191.401535,0.087182,0.000000
64.250000,59.508476,-191.401535,-0.002539,0.003429,0.087095,264.706909,13.484814,0.870950,-191.401535,0.087182,0.000000
64.470001,58.977844,-191.401535,-0.002531,0.003429,0.087095,262.346558,13.364571,0.870950,-191.401535,0.087182,0.000000
64.690002,58.465828,-191.490494,-0.002518,0.003429,0.087095,260.069000,13.248546,0.870950,-191.490494,0.087182,0.000000
64.910004,57.970947,-191.490494,-0.002527,0.003429,0.087095,257.867645,13.136405,0.870950,-191.490494,0.087182,0.000000
65.130005,57.517395,-191.579453,-0.002509,0.003429,0.087095,255.850159,13.033628,0.870950,-191.579453,0.087182,0.000000
65.350006,57.075020,-191.579453,-0.002509,0.003429,0.087095,253.882370,12.933384,0.870950,-191.579453,0.087182,0.000000
65.570000,56.666901,-191.534973,-0.002522,0.003429,0.087095,252.066956,12.840903,0.870950,-191.534973,0.087182,0.000000
65.790001,56.275536,-191.623932,-0.002518,0.003429,0.087095,250.326080,12.752219,0.870950,-191.623932,0.087182,0.000000
66.010002,55.918800,-191.668411,-0.002514,0.003429,0.087095,248.739243,12.671381,0.870950,-191.668411,0.087182,0.000000
66.230003,55.568771,-191.623932,-0.002505,0.003429,0.087087,247.182236,12.592063,0.870866,-191.623932,0.087182,0.000000
66.450005,55.224701,-191.712906,-0.002492,0.003429,0.087087,245.651733,12.514096,0.870866,-191.712906,0.087182,0.000000
66.670006,54.910789,-191.712906,-0.002501,0.003429,0.087087,244.255386,12.442963,0.870866,-191.712906,0.087182,0.000000
66.889999,54.611031,-191.846344,-0.002509,0.003429,0.087087,242.921997,12.375036,0.870866,-191.846344,0.087182,0.000000
67.110001,54.321327,-191.712906,-0.002501,0.003429,0.087087,241.633331,12.309388,0.870866,-191.712906,0.087182,0.000000
67.330002,54.037201,-191.757385,-0.002496,0.003429,0.087087,240.369476,12.245005,0.870866,-191.757385,0.087182,0.000000
67.550003,53.772446,-191.801865,-0.002505,0.003429,0.087087,239.191788,12.185011,0.870866,-191.801865,0.087182,0.000000
67.770004,53.519981,-191.890823,-0.002492,0.003429,0.087087,238.068771,12.127801,0.870866,-191.890823,0.087182,0.000000
67.990005,53.264908,-191.935303,-0.002509,0.003429,0.087087,236.934143,12.070001,0.870866,-191.935303,0.087182,0.000000
68.210007,53.035896,-191.935303,-0.002492,0.003429,0.087087,235.915451,12.018106,0.870866,-191.935303,0.087182,0.000000
68.430000,52.794594,-191.935303,-0.002492,0.003429,0.087087,234.842087,11.963426,0.870866,-191.935303,0.087182,0.000000
68.650002,52.602081,-191.935303,-0.002488,0.003429,0.087087,233.985748,11.919802,0.870866,-191.935303,0.087182,0.000000
68.870003,52.371956,-192.024261,-0.002496,0.003429,0.087087,232.962097,11.867655,0.870866,-192.024261,0.087182,0.000000
69.090004,52.185020,-192.068741,-0.002496,0.003429,0.087087,232.130569,11.825295,0.870866,-192.068741,0.087182,0.000000
69.310005,51.969048,-191.979782,-0.002492,0.003429,0.087087,231.169876,11.776354,0.870866,-191.979782,0.087182,0.000000
69.530006,51.800362,-192.024261,-0.002492,0.003429,0.087087,230.419510,11.738130,0.870866,-192.024261,0.087182,0.000000
69.750000,51.609337,-192.113220,-0.002496,0.003429,0.087087,229.569794,11.694842,0.870866,-192.113220,0.087182,0.000000
69.970001,51.436180,-192.113220,-0.002496,0.003429,0.087087,228.799561,11.655605,0.870866,-192.113220,0.087182,0.000000
70.190002,51.265633,-192.202194,-0.002496,0.003429,0.087087,228.040924,11.616958,0.870866,-192.202194,0.087182,0.000000
70.410004,51.087273,-192.202194,-0.002483,0.003429,0.087087,227.247543,11.576542,0.870866,-192.202194,0.087182,0.000000
70.630005,50.936462,-192.202194,-0.002492,0.003429,0.087087,226.576706,11.542367,0.870866,-192.202194,0.087182,0.000000
70.850006,50.790489,-192.202194,-0.002483,0.003429,0.087087,225.927383,11.509289,0.870866,-192.202194,0.087182,0.000000
71.070000,50.638191,-192.246674,-0.002479,0.003429,0.087087,225.249924,11.474778,0.870866,-192.246674,0.087182,0.000000
71.290001,50.487381,-192.291153,-0.002492,0.003429,0.087087,224.579086,11.440604,0.870866,-192.291153,0.087182,0.000000
71.510002,50.353325,-192.291153,-0.002475,0.003429,0.087087,223.982773,11.410226,0.870866,-192.291153,0.087182,0.000000
71.730003,50.203629,-192.380112,-0.002488,0.003429,0.087087,223.316895,11.376305,0.870866,-192.380112,0.087182,0.000000
71.950005,50.065483,-192.291153,-0.002488,0.003429,0.087087,222.702393,11.345000,0.870866,-192.291153,0.087182,0.000000
72.170006,49.929565,-192.380112,-0.002488,0.003429,0.087087,222.097794,11.314201,0.870866,-192.380112,0.087182,0.000000
72.390007,49.813759,-192.424591,-0.002466,0.003429,0.087087,221.582672,11.287959,0.870866,-192.424591,0.087182,0.000000
72.610001,49.681938,-192.424591,-0.002470,0.003429,0.087087,220.996292,11.258088,0.870866,-192.424591,0.087182,0.000000
72.830002,49.570969,-192.424591,-0.002475,0.003429,0.087087,220.502686,11.232943,0.870866,-192.424591,0.087182,0.000000
73.050003,49.453300,-192.513550,-0.002475,0.003429,0.087087,219.979263,11.206278,0.870866,-192.513550,0.087182,0.000000
73.270004,49.343079,-192.558044,-0.002483,0.003429,0.087087,219.488983,11.181301,0.870866,-192.558044,0.087182,0.000000
73.490005,49.220192,-192.558044,-0.002488,0.003429,0.087087,218.942352,11.153455,0.870866,-192.558044,0.087182,0.000000
73.710007,49.119278,-192.558044,-0.002466,0.003429,0.087087,218.493454,11.130588,0.870866,-192.558044,0.087182,0.000000
73.930000,49.008690,-192.602524,-0.002475,0.003429,0.087087,218.001541,11.105528,0.870866,-192.602524,0.087182,0.000000
74.150002,48.893623,-192.602524,-0.002475,0.003429,0.087087,217.489700,11.079453,0.870866,-192.602524,0.087182,0.000000
74.370003,48.810585,-192.735962,-0.002479,0.003429,0.087087,217.120331,11.060637,0.870866,-192.735962,0.087182,0.000000
74.590004,48.699615,-192.691483,-0.002479,0.003429,0.087087,216.626709,11.035490,0.870866,-192.691483,0.087182,0.000000
74.810005,48.609879,-192.691483,-0.002475,0.003429,0.087087,216.227539,11.015156,0.870866,-192.691483,0.087182,0.000000
75.030006,48.506355,-192.691483,-0.002475,0.003429,0.087087,215.767044,10.991697,0.870866,-192.691483,0.087182,0.000000
75.250000,48.412521,-192.735962,-0.002479,0.003429,0.087087,215.349655,10.970434,0.870866,-192.735962,0.087182,0.000000
75.470001,48.326126,-192.824921,-0.002462,0.003429,0.087087,214.965347,10.950857,0.870866,-192.824921,0.087182,0.000000
75.690002,48.224472,-192.824921,-0.002466,0.003429,0.087087,214.513168,10.927821,0.870866,-192.824921,0.087182,0.000000
75.910004,48.152977,-192.869400,-0.002470,0.003429,0.087087,214.195145,10.911621,0.870866,-192.869400,0.087182,0.000000
76.130005,48.046852,-192.869400,-0.002479,0.003429,0.087087,213.723068,10.887572,0.870866,-192.869400,0.087182,0.000000
76.350006,47.974236,-192.869400,-0.002479,0.003429,0.087087,213.400055,10.871118,0.870866,-192.869400,0.087182,0.000000
76.570007,47.883003,-192.913879,-0.002470,0.003429,0.087087,212.994232,10.850443,0.870866,-192.913879,0.087182,0.000000
76.790001,47.813744,-192.913879,-0.002479,0.003429,0.087087,212.686157,10.834749,0.870866,-192.913879,0.087182,0.000000
77.010002,47.719162,-192.958359,-0.002458,0.003429,0.087087,212.265427,10.813317,0.870866,-192.958359,0.087182,0.000000
77.230003,47.655113,-192.958359,-0.002470,0.003429,0.087087,211.980530,10.798803,0.870866,-192.958359,0.087182,0.000000
77.450005,47.578773,-193.002853,-0.002466,0.003429,0.087087,211.640961,10.781505,0.870866,-193.002853,0.087182,0.000000
77.670006,47.509140,-193.002853,-0.002470,0.003429,0.087087,211.331207,10.765725,0.870866,-193.002853,0.087182,0.000000
77.890007,47.423500,-193.091812,-0.002453,0.003429,0.087087,210.950256,10.746318,0.870866,-193.091812,0.087182,0.000000
78.110001,47.365776,-193.047333,-0.002475,0.003429,0.087087,210.693497,10.733238,0.870866,-193.047333,0.087182,0.000000
78.330002,47.297638,-193.091812,-0.002458,0.003429,0.087087,210.390396,10.717797,0.870866,-193.091812,0.087182,0.000000
78.550003,47.218323,-193.091812,-0.002466,0.003429,0.087087,210.037582,10.699825,0.870866,-193.091812,0.087182,0.000000
78.770004,47.130814,-193.136292,-0.002466,0.003429,0.087087,209.648331,10.679996,0.870866,-193.136292,0.087182,0.000000
78.990005,47.076820,-193.180771,-0.002462,0.003429,0.087087,209.408157,10.667760,0.870866,-193.180771,0.087182,0.000000
79.210007,47.003830,-193.180771,-0.002462,0.003429,0.087087,209.083481,10.651220,0.870866,-193.180771,0.087182,0.000000
79.430000,46.938293,-193.225250,-0.002466,0.003429,0.087087,208.791962,10.636370,0.870866,-193.225250,0.087182,0.000000
79.650002,46.892868,-193.269730,-0.002462,0.003429,0.087087,208.589890,10.626076,0.870866,-193.269730,0.087182,0.000000
79.870003,46.831795,-193.314209,-0.002462,0.003429,0.087087,208.318222,10.612237,0.870866,-193.314209,0.087182,0.000000
80.090004,46.750244,-193.358688,-0.002458,0.003429,0.087087,207.955475,10.593757,0.870866,-193.358688,0.087182,0.000000
80.310005,46.705566,-193.358688,-0.002462,0.003429,0.087087,207.756729,10.583632,0.870866,-193.358688,0.087182,0.000000
80.530006,46.640022,-193.358688,-0.002466,0.003429,0.087087,207.465179,10.568780,0.870866,-193.358688,0.087182,0.000000
80.750008,46.581566,-193.403168,-0.002462,0.003429,0.087087,207.205154,10.555533,0.870866,-193.403168,0.087182,0.000000
80.970001,46.515282,-193.447662,-0.002466,0.003429,0.087087,206.910309,10.540513,0.870866,-193.447662,0.087182,0.000000
81.190002,46.466125,-193.447662,-0.002470,0.003429,0.087087,206.691650,10.529374,0.870866,-193.447662,0.087182,0.000000
81.410004,46.411758,-193.492142,-0.002458,0.003429,0.087087,206.449814,10.517055,0.870866,-193.492142,0.087182,0.000000
81.630005,46.367447,-193.447662,-0.002462,0.003429,0.087087,206.252701,10.507013,0.870866,-193.447662,0.087182,0.000000
81.850006,46.310852,-193.492142,-0.002479,0.003429,0.087087,206.000961,10.494189,0.870866,-193.492142,0.087182,0.000000
82.070007,46.259087,-193.625580,-0.002475,0.003429,0.087087,205.770691,10.482459,0.870866,-193.625580,0.087182,0.000000
82.290001,46.203232,-193.625580,-0.002462,0.003429,0.087087,205.522232,10.469802,0.870866,-193.625580,0.087182,0.000000
82.510002,46.153709,-193.536621,-0.002453,0.003429,0.087087,205.301956,10.458580,0.870866,-193.536621,0.087182,0.000000
82.730003,46.103806,-193.670059,-0.002453,0.003429,0.087087,205.079971,10.447272,0.870866,-193.670059,0.087182,0.000000
82.950005,46.063217,-193.670059,-0.002458,0.003429,0.087087,204.899429,10.438074,0.870866,-193.670059,0.087182,0.000000
83.170006,45.996941,-193.670059,-0.002466,0.003429,0.087087,204.604614,10.423056,0.870866,-193.670059,0.087182,0.000000
83.390007,45.956352,-193.759018,-0.002453,0.003429,0.087087,204.424057,10.413858,0.870866,-193.759018,0.087182,0.000000
83.610001,45.906448,-193.714539,-0.002458,0.003429,0.087087,204.202087,10.402550,0.870866,-193.714539,0.087182,0.000000
83.830002,45.859535,-193.759018,-0.002462,0.003429,0.087087,203.993408,10.391919,0.870866,-193.759018,0.087182,0.000000
84.050003,45.814850,-193.759018,-0.002470,0.003429,0.087087,203.794632,10.381794,0.870866,-193.759018,0.087182,0.000000
84.270004,45.776863,-193.892471,-0.002453,0.003429,0.087087,203.625656,10.373186,0.870866,-193.892471,0.087182,0.000000
84.490005,45.729950,-193.847992,-0.002445,0.003429,0.087087,203.416977,10.362555,0.870866,-193.847992,0.087182,0.000000
84.710007,45.691223,-193.847992,-0.002458,0.003429,0.087087,203.244705,10.353780,0.870866,-193.847992,0.087182,0.000000
84.930000,45.640205,-193.892471,-0.002453,0.003429,0.087087,203.017776,10.342218,0.870866,-193.892471,0.087182,0.000000
85.150002,45.596642,-193.847992,-0.002475,0.003429,0.087087,202.823990,10.332346,0.870866,-193.847992,0.087182,0.000000
85.370003,45.541153,-193.981430,-0.002453,0.003429,0.087087,202.577164,10.319773,0.870866,-193.981430,0.087182,0.000000
85.590004,45.511734,-193.981430,-0.002453,0.003429,0.087087,202.446304,10.313107,0.870866,-193.981430,0.087182,0.000000
85.810005,45.463326,-193.981430,-0.002453,0.003429,0.087087,202.230972,10.302137,0.870866,-193.981430,0.087182,0.000000
86.030006,45.434654,-194.070389,-0.002453,0.003429,0.087087,202.103439,10.295640,0.870866,-194.070389,0.087182,0.000000
86.250008,45.384758,-194.070389,-0.002458,0.003429,0.087087,201.881485,10.284333,0.870866,-194.070389,0.087182,0.000000
86.470001,45.357201,-194.070389,-0.002458,0.003429,0.087087,201.758911,10.278089,0.870866,-194.070389,0.087182,0.000000
86.690002,45.310280,-194.070389,-0.002458,0.003429,0.087087,201.550186,10.267456,0.870866,-194.070389,0.087182,0.000000
86.910004,45.286453,-194.159348,-0.002458,0.003429,0.087087,201.444199,10.262056,0.870866,-194.159348,0.087182,0.000000
87.130005,45.239906,-194.159348,-0.002453,0.003429,0.087087,201.237152,10.251510,0.870866,-194.159348,0.087182,0.000000
87.350006,45.205276,-194.203827,-0.002462,0.003429,0.087087,201.083115,10.243662,0.870866,-194.203827,0.087182,0.000000
87.570007,45.180328,-194.248306,-0.002462,0.003429,0.087087,200.972137,10.238008,0.870866,-194.248306,0.087182,0.000000
87.790001,45.128563,-194.292801,-0.002462,0.003429,0.087087,200.741867,10.226279,0.870866,-194.292801,0.087182,0.000000
88.010002,45.087975,-194.203827,-0.002449,0.003429,0.087087,200.561325,10.217081,0.870866,-194.203827,0.087182,0.000000
88.230003,45.064514,-194.337280,-0.002453,0.003429,0.087087,200.456970,10.211765,0.870866,-194.337280,0.087182,0.000000
88.450005,45.033607,-194.248306,-0.002462,0.003429,0.087087,200.319489,10.204762,0.870866,-194.248306,0.087182,0.000000
88.670006,44.994881,-194.381760,-0.002458,0.003429,0.087087,200.147232,10.195986,0.870866,-194.381760,0.087182,0.000000
88.890007,44.960999,-194.337280,-0.002449,0.003429,0.087087,199.996506,10.188309,0.870866,-194.337280,0.087182,0.000000
89.110001,44.930840,-194.426239,-0.002458,0.003429,0.087087,199.862350,10.181474,0.870866,-194.426239,0.087182,0.000000
89.330002,44.895088,-194.426239,-0.002445,0.003429,0.087087,199.703323,10.173372,0.870866,-194.426239,0.087182,0.000000
89.550003,44.870140,-194.515198,-0.002458,0.003429,0.087087,199.592346,10.167719,0.870866,-194.515198,0.087182,0.000000
89.770004,44.826569,-194.515198,-0.002470,0.003429,0.087087,199.398529,10.157845,0.870866,-194.515198,0.087182,0.000000
89.990005,44.810188,-194.470718,-0.002462,0.003429,0.087087,199.325668,10.154134,0.870866,-194.470718,0.087182,0.000000
90.210007,44.766617,-194.559677,-0.002453,0.003429,0.087087,199.131851,10.144260,0.870866,-194.559677,0.087182,0.000000
90.430008,44.737572,-194.559677,-0.002462,0.003429,0.087087,199.002655,10.137679,0.870866,-194.559677,0.087182,0.000000
90.650002,44.706299,-194.648636,-0.002466,0.003429,0.087087,198.863556,10.130592,0.870866,-194.648636,0.087182,0.000000
90.870003,44.682465,-194.648636,-0.002453,0.003429,0.087087,198.757523,10.125192,0.870866,-194.648636,0.087182,0.000000
91.090004,44.651184,-194.693115,-0.002458,0.003429,0.087087,198.618393,10.118103,0.870866,-194.693115,0.087182,0.000000
91.310005,44.620277,-194.648636,-0.002462,0.003429,0.087087,198.480911,10.111099,0.870866,-194.648636,0.087182,0.000000
91.530006,44.580063,-194.693115,-0.002449,0.003429,0.087087,198.302017,10.101987,0.870866,-194.693115,0.087182,0.000000
91.750008,44.553619,-194.648636,-0.002458,0.003429,0.087087,198.184402,10.095995,0.870866,-194.648636,0.087182,0.000000
91.970001,44.534256,-194.693115,-0.002453,0.003429,0.087087,198.098267,10.091607,0.870866,-194.693115,0.087182,0.000000
92.190002,44.513031,-194.782089,-0.002449,0.003429,0.087087,198.003845,10.086797,0.870866,-194.782089,0.087182,0.000000
92.400002,44.479523,-194.782089,-0.002449,0.003429,0.087087,197.854797,10.079204,0.870866,-194.782089,0.087182,0.000000