File: Data/compression 10/AutoHeating-17-10-3-240424_04242024_224921.csv
Time (sec),S:Load (lbs),S:HL1 (DIM),S:LVDT (in),S:Position (in),Ch:Position (mm),Ch:Load (N),Ch:Stress (MPa),Ch:Strain (mm/mm),Ch:HL1 (DIM),Set Point (),Cycles ()
0.010000,-0.005211,-166.714600,-0.006226,-0.000000,-0.000000,-0.023179,-0.001181,-0.000000,-166.714600,0.000225,0.000000
0.220000,-0.005951,-166.892532,-0.006243,-0.000000,-0.000000,-0.026471,-0.001348,-0.000000,-166.892532,0.000225,0.000000
0.430000,0.014900,-166.803574,-0.006243,0.000050,0.001266,0.066279,0.003376,0.012657,-166.803574,0.001717,0.000000
0.640000,0.020859,-166.848053,-0.006226,0.000167,0.004241,0.092784,0.004727,0.042406,-166.848053,0.005220,0.000000
0.850000,0.005959,-166.892532,-0.006109,0.000303,0.007692,0.026505,0.001350,0.076917,-166.892532,0.008707,0.000000
1.060000,-0.031647,-166.937012,-0.005976,0.000440,0.011169,-0.140772,-0.007171,0.111692,-166.937012,0.012210,0.000000
1.270000,-0.048401,-166.981491,-0.005859,0.000577,0.014664,-0.215298,-0.010968,0.146642,-166.981491,0.015714,0.000000
1.480000,0.021233,-166.981491,-0.005704,0.000711,0.018064,0.094447,0.004811,0.180638,-166.981491,0.019200,0.000000
1.690000,-0.005211,-167.070450,-0.005583,0.000853,0.021663,-0.023179,-0.001181,0.216632,-167.070450,0.022703,0.000000
1.900000,0.021233,-167.025970,-0.005433,0.000995,0.025279,0.094447,0.004811,0.252793,-167.025970,0.026207,0.000000
2.110000,0.030167,-167.025970,-0.005286,0.001132,0.028757,0.134188,0.006836,0.287569,-167.025970,0.029711,0.000000
2.320000,0.041336,-167.114929,-0.005152,0.001269,0.032234,0.183872,0.009367,0.322344,-167.114929,0.033197,0.000000
2.530000,0.080811,-167.070450,-0.005019,0.001398,0.035513,0.359463,0.018312,0.355129,-167.070450,0.036701,0.000000
2.740000,0.767464,-167.114929,-0.004919,0.000002,0.000043,3.413849,0.173910,0.000431,-167.114929,0.000191,0.000000
2.950000,0.699318,-167.203888,-0.004885,-0.000001,-0.000017,3.110722,0.158468,-0.000174,-167.203888,0.000191,0.000000
3.160000,0.677719,-167.248383,-0.004885,-0.000001,-0.000026,3.014645,0.153573,-0.000257,-167.248383,0.000191,0.000000
3.370000,0.653893,-167.248383,-0.004889,-0.000001,-0.000026,2.908659,0.148174,-0.000257,-167.248383,0.000373,0.000000
3.580000,0.658356,-167.248383,-0.004894,-0.000001,-0.000017,2.928513,0.149186,-0.000174,-167.248383,0.000720,0.000000
3.790000,0.640114,-167.292862,-0.004911,-0.000001,-0.000017,2.847368,0.145052,-0.000174,-167.292862,0.001076,0.000000
4.000000,0.641228,-167.337341,-0.004898,-0.000000,-0.000008,2.852323,0.145304,-0.000083,-167.337341,0.001422,0.000000
4.210000,1.215431,-167.337341,-0.004885,0.000041,0.001041,5.406508,0.275421,0.010408,-167.337341,0.001769,0.000000
4.420000,1.339058,-167.470779,-0.004863,0.000051,0.001292,5.956427,0.303435,0.012922,-167.470779,0.002125,0.000000
4.630000,1.544975,-167.337341,-0.004850,0.000064,0.001631,6.872393,0.350096,0.016305,-167.337341,0.002472,0.000000
4.840000,1.754250,-167.426300,-0.004829,0.000076,0.001942,7.803292,0.397519,0.019424,-167.426300,0.002818,0.000000
5.050000,1.905434,-167.426300,-0.004859,0.000087,0.002212,8.475792,0.431777,0.022119,-167.426300,0.003174,0.000000
5.260000,2.411118,-167.470779,-0.004829,0.000108,0.002740,10.725186,0.546367,0.027403,-167.470779,0.003521,0.000000
5.470000,2.649063,-167.604218,-0.004812,0.000120,0.003053,11.783621,0.600286,0.030529,-167.604218,0.003868,0.000000
5.680000,2.785721,-167.515259,-0.004807,0.000128,0.003261,12.391505,0.631253,0.032611,-167.515259,0.004223,0.000000
5.890000,3.036697,-167.604218,-0.004812,0.000143,0.003625,13.507905,0.688125,0.036252,-167.604218,0.004571,0.000000
6.100000,3.506638,-167.648712,-0.004786,0.000160,0.004059,15.598303,0.794615,0.040589,-167.648712,0.004926,0.000000
6.310000,3.805275,-167.648712,-0.004769,0.000174,0.004431,16.926708,0.862288,0.044314,-167.648712,0.005273,0.000000
6.520000,4.182121,-167.693192,-0.004764,0.000191,0.004839,18.603004,0.947682,0.048394,-167.693192,0.005620,0.000000
6.730000,4.404053,-167.737671,-0.004756,0.000203,0.005151,19.590204,0.997973,0.051512,-167.737671,0.005976,0.000000
6.940001,4.493050,-167.648712,-0.004743,0.000212,0.005386,19.986082,1.018140,0.053859,-167.648712,0.006322,0.000000
7.150001,5.085495,-167.737671,-0.004730,0.000232,0.005889,22.621412,1.152390,0.058885,-167.737671,0.006669,0.000000
7.360000,5.389351,-167.693192,-0.004734,0.000244,0.006200,23.973030,1.221244,0.062004,-167.693192,0.007025,0.000000
7.570000,5.608681,-167.826630,-0.004704,0.000255,0.006487,24.948658,1.270945,0.064873,-167.826630,0.007371,0.000000
7.780000,5.788162,-167.871109,-0.004708,0.000265,0.006721,25.747032,1.311616,0.067212,-167.871109,0.007718,0.000000
7.990000,6.289375,-167.871109,-0.004687,0.000283,0.007198,27.976538,1.425193,0.071981,-167.871109,0.008074,0.000000
8.200001,6.645363,-167.915588,-0.004682,0.000299,0.007588,29.560051,1.505861,0.075880,-167.915588,0.008421,0.000000
8.410001,6.952568,-167.915588,-0.004669,0.000315,0.008013,30.926567,1.575475,0.080134,-167.915588,0.008776,0.000000
8.620001,7.161469,-167.960068,-0.004652,0.000326,0.008290,31.855803,1.622812,0.082904,-167.960068,0.009123,0.000000
8.830001,7.334251,-168.004547,-0.004648,0.000337,0.008551,32.624378,1.661965,0.085508,-168.004547,0.009471,0.000000
9.040000,7.675720,-168.004547,-0.004631,0.000353,0.008967,34.143311,1.739343,0.089672,-168.004547,0.009826,0.000000
9.250000,8.103203,-168.049026,-0.004613,0.000366,0.009306,36.044846,1.836212,0.093055,-168.049026,0.010173,0.000000
9.460000,8.209328,-167.960068,-0.004605,0.000377,0.009566,36.516914,1.860260,0.095659,-167.960068,0.010520,0.000000
9.670000,8.508339,-168.093521,-0.004605,0.000388,0.009843,37.846981,1.928017,0.098430,-168.093521,0.010875,0.000000
9.880000,9.056099,-168.093521,-0.004592,0.000409,0.010380,40.283539,2.052141,0.103805,-168.093521,0.011222,0.000000
10.090000,9.339104,-168.138000,-0.004566,0.000423,0.010745,41.542408,2.116271,0.107453,-168.138000,0.011569,0.000000
10.300000,9.562157,-168.182480,-0.004562,0.000438,0.011118,42.534595,2.166816,0.111178,-168.182480,0.011925,0.000000
10.510000,9.731956,-168.138000,-0.004562,0.000450,0.011439,43.289906,2.205293,0.114387,-168.138000,0.012271,0.000000
10.720000,9.981819,-168.226959,-0.004536,0.000463,0.011760,44.401348,2.261913,0.117597,-168.226959,0.012627,0.000000
10.930000,9.764725,-168.315918,-0.004523,0.000464,0.011777,43.435665,2.212718,0.117771,-168.315918,0.012974,0.000000
11.140000,10.648743,-168.226959,-0.004501,0.000491,0.012470,47.367973,2.413040,0.124705,-168.226959,0.013321,0.000000
11.350000,10.765663,-168.315918,-0.004514,0.000501,0.012731,47.888062,2.439534,0.127309,-168.315918,0.013676,0.000000
11.560000,10.987595,-168.315918,-0.004514,0.000513,0.013026,48.875263,2.489825,0.130261,-168.315918,0.014023,0.000000
11.770000,11.293686,-168.360397,-0.004493,0.000527,0.013381,50.236824,2.559186,0.133811,-168.360397,0.014370,0.000000
11.980000,11.964706,-168.404877,-0.004467,0.000551,0.013988,53.221672,2.711241,0.139882,-168.404877,0.014726,0.000000
12.190001,12.138977,-168.449356,-0.004445,0.000565,0.014344,53.996868,2.750732,0.143440,-168.449356,0.015072,0.000000
12.400001,12.130035,-168.449356,-0.004454,0.000574,0.014587,53.957092,2.748705,0.145870,-168.449356,0.015420,0.000000
12.610001,12.252548,-168.449356,-0.004449,0.000586,0.014891,54.502056,2.776467,0.148905,-168.449356,0.015775,0.000000
12.820001,12.586937,-168.449356,-0.004424,0.000601,0.015263,55.989491,2.852241,0.152630,-168.449356,0.016122,0.000000
13.030001,13.122780,-168.582809,-0.004432,0.000619,0.015714,58.373039,2.973664,0.157141,-168.582809,0.016477,0.000000
13.240001,13.220718,-168.493835,-0.004406,0.000630,0.016009,58.808693,2.995858,0.160093,-168.493835,0.016825,0.000000
13.450001,13.253860,-168.627289,-0.004393,0.000638,0.016200,58.956116,3.003368,0.162001,-168.627289,0.017171,0.000000
13.660001,13.324234,-168.582809,-0.004402,0.000647,0.016426,59.269154,3.019315,0.164257,-168.582809,0.017527,0.000000
13.870001,14.288307,-168.627289,-0.004372,0.000674,0.017119,63.557564,3.237777,0.171191,-168.627289,0.017874,0.000000
14.080001,14.431297,-168.760727,-0.004363,0.000688,0.017483,64.193619,3.270179,0.174832,-168.760727,0.018220,0.000000
14.290001,14.529976,-168.671768,-0.004350,0.000701,0.017796,64.632561,3.292540,0.177958,-168.671768,0.018576,0.000000
14.500001,14.586578,-168.849686,-0.004346,0.000712,0.018090,64.884338,3.305366,0.180903,-168.849686,0.018923,0.000000
14.710001,14.890808,-168.716248,-0.004324,0.000725,0.018403,66.237625,3.374305,0.184029,-168.716248,0.019270,0.000000
14.920001,15.390160,-168.805206,-0.004312,0.000743,0.018871,68.458847,3.487460,0.188707,-168.805206,0.019625,0.000000
15.130001,15.606506,-168.849686,-0.004312,0.000756,0.019201,69.421204,3.536485,0.192008,-168.849686,0.019972,0.000000
15.340001,15.701836,-168.849686,-0.004290,0.000765,0.019426,69.845253,3.558087,0.194256,-168.849686,0.020319,0.000000
15.550001,15.622147,-168.938660,-0.004281,0.000774,0.019651,69.490776,3.540029,0.196512,-168.938660,0.020675,0.000000
15.760001,16.401146,-168.894165,-0.004277,0.000798,0.020267,72.955940,3.716553,0.202674,-168.894165,0.021021,0.000000
15.970001,16.512115,-168.938660,-0.004264,0.000809,0.020553,73.449554,3.741699,0.205535,-168.938660,0.021377,0.000000
16.180000,16.784317,-169.027618,-0.004234,0.000825,0.020943,74.660370,3.803381,0.209433,-169.027618,0.021724,0.000000
16.390001,16.832726,-168.938660,-0.004238,0.000835,0.021213,74.875702,3.814350,0.212128,-168.938660,0.022071,0.000000
16.600000,17.174568,-169.072098,-0.004238,0.000852,0.021628,76.396294,3.891813,0.216284,-169.072098,0.022426,0.000000
16.810001,17.498901,-169.072098,-0.004217,0.000867,0.022010,77.839005,3.965308,0.220099,-169.072098,0.022774,0.000000
17.020000,17.763657,-169.027618,-0.004217,0.000882,0.022392,79.016693,4.025302,0.223922,-169.027618,0.023120,0.000000
17.230001,17.774460,-169.116577,-0.004195,0.000891,0.022626,79.064743,4.027750,0.226261,-169.116577,0.023476,0.000000
17.440001,17.702965,-169.072098,-0.004174,0.000899,0.022825,78.746719,4.011549,0.228252,-169.072098,0.023823,0.000000
17.650002,18.391106,-169.161057,-0.004165,0.000919,0.023346,81.807724,4.167484,0.233460,-169.161057,0.024170,0.000000
17.860001,18.633148,-169.116577,-0.004165,0.000933,0.023710,82.884384,4.222332,0.237101,-169.116577,0.024525,0.000000
18.070002,18.973122,-169.205536,-0.004165,0.000950,0.024126,84.396660,4.299371,0.241264,-169.205536,0.024872,0.000000
18.280001,18.970146,-169.294495,-0.004130,0.000962,0.024438,84.383423,4.298697,0.244383,-169.294495,0.025228,0.000000
18.490002,19.050575,-169.250015,-0.004139,0.000973,0.024707,84.741188,4.316922,0.247070,-169.250015,0.025575,0.000000
18.700001,19.261345,-169.338974,-0.004113,0.000988,0.025098,85.678741,4.364683,0.250976,-169.338974,0.025921,0.000000
18.910002,19.749153,-169.338974,-0.004113,0.001004,0.025514,87.848618,4.475222,0.255140,-169.338974,0.026277,0.000000
19.120001,19.812828,-169.338974,-0.004087,0.001016,0.025808,88.131859,4.489651,0.258084,-169.338974,0.026624,0.000000
19.330002,19.475456,-169.472427,-0.004092,0.001019,0.025887,86.631157,4.413201,0.258872,-169.472427,0.026971,0.000000
19.540001,20.373245,-169.383469,-0.004066,0.001044,0.026511,90.624718,4.616643,0.265109,-169.383469,0.027326,0.000000
19.750000,20.512138,-169.472427,-0.004061,0.001057,0.026849,91.242546,4.648117,0.268493,-169.472427,0.027674,0.000000
19.960001,20.906853,-169.472427,-0.004044,0.001075,0.027300,92.998329,4.737560,0.273004,-169.472427,0.028020,0.000000
20.170000,20.768333,-169.472427,-0.004036,0.001086,0.027578,92.382164,4.706172,0.275783,-169.472427,0.028375,0.000000
20.380001,20.885628,-169.561386,-0.004040,0.001098,0.027881,92.903915,4.732751,0.278811,-169.561386,0.028723,0.000000
20.590000,20.917282,-169.472427,-0.004027,0.001109,0.028168,93.044716,4.739924,0.281679,-169.472427,0.029078,0.000000
20.800001,21.296730,-169.605865,-0.004018,0.001127,0.028618,94.732590,4.825908,0.286183,-169.605865,0.029425,0.000000
21.010000,21.673943,-169.605865,-0.004001,0.001142,0.029009,96.410515,4.911386,0.290089,-169.605865,0.029772,0.000000
21.220001,21.522758,-169.561386,-0.003992,0.001150,0.029217,95.738014,4.877127,0.292171,-169.561386,0.030128,0.000000
21.430000,21.653465,-169.650345,-0.003992,0.001168,0.029668,96.319427,4.906745,0.296675,-169.650345,0.030474,0.000000
21.640001,22.120049,-169.694824,-0.003967,0.001182,0.030032,98.394890,5.012475,0.300324,-169.694824,0.030821,0.000000
21.850000,22.282402,-169.739304,-0.003958,0.001196,0.030370,99.117073,5.049264,0.303700,-169.739304,0.031177,0.000000
22.060001,22.397461,-169.739304,-0.003945,0.001210,0.030735,99.628883,5.075337,0.307349,-169.739304,0.031524,0.000000
22.270000,22.377724,-169.783783,-0.003923,0.001220,0.030977,99.541084,5.070865,0.309771,-169.783783,0.031870,0.000000
22.480001,22.347939,-169.828278,-0.003911,0.001232,0.031281,99.408592,5.064116,0.312806,-169.828278,0.032226,0.000000
22.690001,22.727386,-169.828278,-0.003919,0.001249,0.031732,101.096466,5.150099,0.317318,-169.828278,0.032573,0.000000
22.900002,23.225990,-169.961716,-0.003906,0.001265,0.032131,103.314362,5.263085,0.321307,-169.961716,0.032920,0.000000
23.110001,23.069595,-169.917236,-0.003889,0.001273,0.032331,102.618683,5.227645,0.323306,-169.917236,0.033275,0.000000
23.320002,22.803719,-169.872757,-0.003898,0.001281,0.032547,101.436005,5.167397,0.325471,-169.872757,0.033623,0.000000
23.530001,23.775612,-170.006195,-0.003850,0.001305,0.033146,105.759201,5.387630,0.331458,-170.006195,0.033978,0.000000
23.740002,23.919724,-169.917236,-0.003850,0.001320,0.033518,106.400246,5.420287,0.335183,-169.917236,0.034325,0.000000
23.950001,24.078728,-170.006195,-0.003829,0.001334,0.033882,107.107529,5.456318,0.338824,-170.006195,0.034672,0.000000
24.160002,23.959564,-170.095154,-0.003816,0.001346,0.034178,106.577461,5.429315,0.341776,-170.095154,0.035028,0.000000
24.370001,23.971107,-170.050674,-0.003820,0.001356,0.034446,106.628815,5.431931,0.344463,-170.050674,0.035374,0.000000
24.580002,24.250389,-170.139633,-0.003811,0.001371,0.034820,107.871117,5.495216,0.348195,-170.139633,0.035721,0.000000
24.790001,24.616806,-170.139633,-0.003803,0.001387,0.035218,109.501022,5.578248,0.352184,-170.139633,0.036077,0.000000
25.000002,24.750114,-170.184113,-0.003773,0.001400,0.035565,110.094009,5.608456,0.355651,-170.184113,0.036424,0.000000
25.210001,24.593346,-170.228607,-0.003777,0.001409,0.035791,109.396667,5.572932,0.357907,-170.228607,0.036770,0.000000
25.420002,25.155624,-170.184113,-0.003773,0.001430,0.036311,111.897804,5.700346,0.363108,-170.184113,0.037126,0.000000
25.630001,25.312767,-170.273087,-0.003747,0.001443,0.036657,112.596809,5.735955,0.366575,-170.273087,0.037473,0.000000
25.840002,25.278511,-170.273087,-0.003751,0.001454,0.036927,112.444435,5.728193,0.369269,-170.273087,0.037829,0.000000
26.050001,25.495598,-170.228607,-0.003721,0.001469,0.037308,113.410080,5.777385,0.373085,-170.228607,0.038175,0.000000
26.260002,25.492996,-170.362045,-0.003721,0.001480,0.037603,113.398514,5.776795,0.376029,-170.362045,0.038522,0.000000
26.470001,25.321335,-170.317566,-0.003704,0.001490,0.037837,112.634926,5.737896,0.378368,-170.317566,0.038878,0.000000
26.680002,26.225822,-170.362045,-0.003691,0.001513,0.038427,116.658287,5.942856,0.384265,-170.362045,0.039224,0.000000
26.890001,25.986015,-170.362045,-0.003695,0.001522,0.038652,115.591568,5.888515,0.386521,-170.362045,0.039572,0.000000
27.100000,26.116722,-170.406525,-0.003673,0.001534,0.038965,116.172981,5.918134,0.389647,-170.406525,0.039927,0.000000
27.310001,26.585907,-170.451004,-0.003660,0.001554,0.039467,118.260017,6.024453,0.394674,-170.451004,0.040274,0.000000
27.520000,26.689056,-170.406525,-0.003643,0.001566,0.039780,118.718849,6.047827,0.397800,-170.406525,0.040621,0.000000
27.730001,26.800026,-170.495483,-0.003643,0.001579,0.040118,119.212471,6.072973,0.401176,-170.495483,0.040977,0.000000
27.940001,26.857742,-170.539963,-0.003635,0.001593,0.040473,119.469208,6.086051,0.404734,-170.539963,0.041323,0.000000
28.150002,26.943382,-170.539963,-0.003609,0.001606,0.040786,119.850151,6.105457,0.407860,-170.539963,0.041679,0.000000
28.360001,26.904289,-170.628922,-0.003604,0.001616,0.041055,119.676254,6.096599,0.410548,-170.628922,0.042026,0.000000
28.570002,27.398056,-170.584442,-0.003600,0.001634,0.041505,121.872643,6.208488,0.415052,-170.584442,0.042373,0.000000
28.780001,27.482208,-170.673416,-0.003574,0.001646,0.041800,122.246971,6.227558,0.418004,-170.673416,0.042728,0.000000
28.990002,27.441620,-170.673416,-0.003561,0.001658,0.042104,122.066422,6.218360,0.421039,-170.673416,0.043075,0.000000
29.200001,27.488541,-170.717896,-0.003570,0.001669,0.042382,122.275139,6.228992,0.423817,-170.717896,0.043422,0.000000
29.410002,28.184502,-170.717896,-0.003557,0.001689,0.042910,125.370926,6.386700,0.429101,-170.717896,0.043778,0.000000
29.620001,28.341644,-170.717896,-0.003527,0.001703,0.043248,126.069931,6.422308,0.432485,-170.717896,0.044124,0.000000
29.830002,28.573257,-170.762375,-0.003510,0.001718,0.043630,127.100197,6.474793,0.436300,-170.762375,0.044472,0.000000
30.040001,28.511070,-170.851334,-0.003518,0.001729,0.043916,126.823578,6.460701,0.439161,-170.851334,0.044827,0.000000
30.250002,28.468254,-170.851334,-0.003523,0.001742,0.044255,126.633118,6.450999,0.442545,-170.851334,0.045174,0.000000
30.460001,28.897972,-170.895813,-0.003497,0.001757,0.044628,128.544601,6.548374,0.446277,-170.895813,0.045521,0.000000
30.670002,28.988831,-170.762375,-0.003488,0.001770,0.044949,128.948761,6.568963,0.449487,-170.762375,0.045877,0.000000
30.880001,28.955315,-170.940292,-0.003475,0.001781,0.045226,128.799667,6.561368,0.452257,-170.940292,0.046223,0.000000
31.090002,28.989197,-170.940292,-0.003471,0.001794,0.045573,128.950394,6.569046,0.455732,-170.940292,0.046578,0.000000
31.300001,29.527275,-170.984772,-0.003458,0.001809,0.045955,131.343872,6.690976,0.459547,-170.984772,0.046926,0.000000
31.510002,30.047485,-171.029251,-0.003445,0.001828,0.046432,133.657883,6.808857,0.464316,-171.029251,0.047273,0.000000
31.720001,30.289894,-171.029251,-0.003441,0.001843,0.046821,134.736176,6.863788,0.468214,-171.029251,0.047628,0.000000
31.930002,30.325272,-171.073730,-0.003419,0.001856,0.047151,134.893539,6.871805,0.471515,-171.073730,0.047975,0.000000
32.140003,29.898163,-171.118225,-0.003410,0.001862,0.047290,132.993668,6.775020,0.472900,-171.118225,0.048322,0.000000
32.350002,30.678658,-171.162704,-0.003402,0.001884,0.047854,136.465485,6.951883,0.478539,-171.162704,0.048678,0.000000
32.560001,30.749031,-171.118225,-0.003389,0.001896,0.048148,136.778519,6.967830,0.481484,-171.118225,0.049024,0.000000
32.770000,30.510338,-171.162704,-0.003380,0.001905,0.048391,135.716766,6.913741,0.483914,-171.162704,0.049371,0.000000
32.980003,30.740471,-171.207184,-0.003367,0.001918,0.048730,136.740448,6.965890,0.487298,-171.207184,0.049727,0.000000
33.190002,31.539948,-171.207184,-0.003359,0.001939,0.049250,140.296692,7.147054,0.492498,-171.207184,0.050073,0.000000
33.400002,31.934669,-171.207184,-0.003359,0.001955,0.049666,142.052505,7.236500,0.496661,-171.207184,0.050429,0.000000
33.610001,32.044891,-171.296143,-0.003324,0.001969,0.050022,142.542801,7.261476,0.500219,-171.296143,0.050776,0.000000
33.820004,31.832634,-171.296143,-0.003324,0.001979,0.050256,141.598633,7.213378,0.502558,-171.296143,0.051123,0.000000
34.030003,31.905991,-171.296143,-0.003307,0.001990,0.050551,141.924942,7.230001,0.505511,-171.296143,0.051478,0.000000
34.240002,32.138351,-171.385101,-0.003307,0.002005,0.050933,142.958527,7.282654,0.509326,-171.385101,0.051826,0.000000
34.450001,32.623184,-171.385101,-0.003303,0.002021,0.051340,145.115173,7.392519,0.513398,-171.385101,0.052173,0.000000
34.660000,32.569191,-171.429581,-0.003281,0.002032,0.051609,144.875000,7.380284,0.516086,-171.429581,0.052528,0.000000
34.870003,32.220276,-171.429581,-0.003272,0.002040,0.051808,143.322952,7.301219,0.518084,-171.429581,0.052875,0.000000
35.080002,33.466980,-171.429581,-0.003277,0.002065,0.052441,148.868561,7.583726,0.524412,-171.429581,0.053222,0.000000
35.290001,33.681091,-171.563034,-0.003251,0.002078,0.052780,149.820984,7.632245,0.527796,-171.563034,0.053577,0.000000
35.500000,33.772697,-171.518555,-0.003247,0.002091,0.053109,150.228455,7.653003,0.531089,-171.518555,0.053924,0.000000
35.710003,33.693008,-171.518555,-0.003221,0.002103,0.053422,149.873993,7.634945,0.534215,-171.518555,0.054280,0.000000
35.920002,33.722427,-171.607513,-0.003229,0.002114,0.053690,150.004852,7.641611,0.536902,-171.607513,0.054627,0.000000
36.130001,34.143578,-171.607513,-0.003208,0.002131,0.054124,151.878220,7.737045,0.541240,-171.607513,0.054973,0.000000
36.340000,34.647400,-171.651993,-0.003212,0.002146,0.054506,154.119339,7.851213,0.545055,-171.651993,0.055329,0.000000
36.550003,35.140419,-171.651993,-0.003191,0.002163,0.054939,156.312393,7.962933,0.549385,-171.651993,0.055676,0.000000
36.760002,34.385994,-171.740952,-0.003182,0.002167,0.055043,152.956543,7.791978,0.550430,-171.740952,0.056023,0.000000
36.970001,35.528809,-171.740952,-0.003173,0.002189,0.055598,158.040039,8.050943,0.555978,-171.740952,0.056378,0.000000
37.180000,35.767868,-171.740952,-0.003152,0.002202,0.055927,159.103424,8.105115,0.559271,-171.740952,0.056725,0.000000
37.390003,36.076569,-171.785431,-0.003152,0.002218,0.056326,160.476593,8.175067,0.563260,-171.785431,0.057072,0.000000
37.600002,35.955917,-171.829910,-0.003139,0.002227,0.056578,159.939911,8.147727,0.565781,-171.829910,0.057427,0.000000
37.810001,36.315628,-171.829910,-0.003130,0.002243,0.056968,161.539978,8.229239,0.569680,-171.829910,0.057775,0.000000
38.020000,36.736778,-171.874390,-0.003117,0.002258,0.057359,163.413345,8.324673,0.573586,-171.874390,0.058130,0.000000
38.230003,36.898018,-171.829910,-0.003100,0.002271,0.057688,164.130585,8.361211,0.576879,-171.829910,0.058477,0.000000
38.440002,37.072289,-171.918869,-0.003100,0.002283,0.058000,164.905777,8.400701,0.580005,-171.918869,0.058824,0.000000
38.650002,36.854080,-171.918869,-0.003100,0.002291,0.058182,163.935135,8.351254,0.581822,-171.918869,0.059180,0.000000
38.860001,37.148994,-171.963364,-0.003070,0.002311,0.058711,165.246979,8.418082,0.587113,-171.963364,0.059527,0.000000
39.070004,38.076950,-172.052322,-0.003078,0.002326,0.059084,169.374741,8.628360,0.590845,-172.052322,0.059873,0.000000
39.280003,38.305962,-172.096802,-0.003053,0.002339,0.059414,170.393433,8.680255,0.594138,-172.096802,0.060229,0.000000
39.490002,38.546143,-172.052322,-0.003061,0.002353,0.059778,171.461807,8.734681,0.597779,-172.052322,0.060576,0.000000
39.700001,38.686523,-172.052322,-0.003053,0.002365,0.060073,172.086258,8.766492,0.600731,-172.052322,0.060922,0.000000
39.910004,38.703651,-172.141281,-0.003044,0.002377,0.060377,172.162445,8.770372,0.603766,-172.141281,0.061278,0.000000
40.120003,39.232048,-172.230240,-0.003022,0.002394,0.060801,174.512863,8.890109,0.608013,-172.230240,0.061625,0.000000
40.330002,39.706078,-172.185760,-0.003005,0.002409,0.061192,176.621460,8.997525,0.611919,-172.185760,0.061972,0.000000
40.540001,39.674431,-172.230240,-0.002984,0.002417,0.061399,176.480682,8.990355,0.613993,-172.230240,0.062327,0.000000
40.750004,39.360146,-172.230240,-0.002997,0.002429,0.061695,175.082672,8.919136,0.616945,-172.230240,0.062675,0.000000
40.960003,40.466835,-172.274719,-0.002958,0.002447,0.062154,180.005478,9.169915,0.621540,-172.274719,0.063030,0.000000
41.170002,41.152374,-172.319199,-0.002971,0.002465,0.062623,183.054901,9.325262,0.626226,-172.319199,0.063377,0.000000
41.380001,41.310631,-172.319199,-0.002949,0.002478,0.062934,183.758865,9.361122,0.629345,-172.319199,0.063724,0.000000
41.590000,41.334839,-172.319199,-0.002949,0.002489,0.063221,183.866547,9.366609,0.632206,-172.319199,0.064080,0.000000
41.800003,41.497192,-172.363678,-0.002940,0.002500,0.063489,184.588730,9.403398,0.634893,-172.363678,0.064426,0.000000
42.010002,41.710564,-172.408173,-0.002928,0.002514,0.063863,185.537857,9.451749,0.638625,-172.408173,0.064773,0.000000
42.220001,42.401314,-172.452652,-0.002915,0.002530,0.064261,188.610458,9.608274,0.642615,-172.452652,0.065129,0.000000
42.430000,42.893959,-172.408173,-0.002910,0.002545,0.064643,190.801865,9.719911,0.646430,-172.408173,0.065476,0.000000
42.640003,42.651917,-172.541611,-0.002897,0.002552,0.064825,189.725204,9.665062,0.648254,-172.541611,0.065822,0.000000
42.850002,43.561996,-172.541611,-0.002902,0.002572,0.065337,193.773437,9.871289,0.653371,-172.541611,0.066178,0.000000
43.060001,43.921707,-172.497131,-0.002893,0.002586,0.065684,195.373505,9.952802,0.656838,-172.497131,0.066525,0.000000
43.270000,44.198380,-172.586090,-0.002871,0.002598,0.065996,196.604218,10.015496,0.659957,-172.586090,0.066881,0.000000
43.480003,44.637779,-172.586090,-0.002854,0.002613,0.066377,198.558762,10.115066,0.663772,-172.586090,0.067227,0.000000
43.690002,44.673897,-172.630569,-0.002846,0.002625,0.066681,198.719421,10.123250,0.666808,-172.630569,0.067574,0.000000
43.900002,44.903282,-172.719528,-0.002846,0.002636,0.066959,199.739777,10.175229,0.669586,-172.719528,0.067930,0.000000
44.110001,45.601479,-172.675049,-0.002833,0.002653,0.067392,202.845505,10.333443,0.673923,-172.675049,0.068276,0.000000
44.320004,46.127640,-172.808502,-0.002820,0.002667,0.067748,205.185989,10.452673,0.677481,-172.808502,0.068624,0.000000
44.530003,45.662918,-172.764008,-0.002828,0.002671,0.067852,203.118805,10.347364,0.678518,-172.764008,0.068979,0.000000
44.740002,46.125038,-172.764008,-0.002794,0.002694,0.068433,205.174423,10.452084,0.684332,-172.764008,0.069326,0.000000
44.950001,47.319977,-172.852982,-0.002798,0.002708,0.068788,210.489777,10.722859,0.687882,-172.852982,0.069673,0.000000
45.160004,48.029350,-172.808502,-0.002772,0.002726,0.069248,213.645218,10.883607,0.692484,-172.808502,0.070029,0.000000
45.370003,48.246071,-172.941940,-0.002777,0.002739,0.069569,214.609238,10.932716,0.695686,-172.941940,0.070376,0.000000
45.580002,48.333580,-172.852982,-0.002764,0.002748,0.069803,214.998505,10.952546,0.698033,-172.852982,0.070731,0.000000
45.790001,48.489975,-172.941940,-0.002742,0.002761,0.070124,215.694183,10.987986,0.701243,-172.941940,0.071078,0.000000
46.000004,49.287598,-173.030899,-0.002746,0.002777,0.070532,219.242187,11.168730,0.705315,-173.030899,0.071425,0.000000
46.210003,49.726624,-172.897461,-0.002738,0.002793,0.070930,221.195068,11.268213,0.709304,-172.897461,0.071781,0.000000
46.420002,49.900894,-173.075378,-0.002725,0.002803,0.071191,221.970261,11.307705,0.711908,-173.075378,0.072127,0.000000
46.630001,50.326141,-173.030899,-0.002716,0.002818,0.071590,223.861862,11.404067,0.715898,-173.030899,0.072474,0.000000
46.840004,50.816559,-173.030899,-0.002712,0.002832,0.071945,226.043350,11.515197,0.719448,-173.030899,0.072830,0.000000
47.050003,51.445496,-173.164337,-0.002721,0.002848,0.072327,228.840988,11.657716,0.723271,-173.164337,0.073176,0.000000
47.260002,51.823082,-173.164337,-0.002690,0.002860,0.072656,230.520584,11.743279,0.726564,-173.164337,0.073524,0.000000
47.470001,52.120979,-173.208817,-0.002677,0.002873,0.072968,231.845688,11.810783,0.729682,-173.208817,0.073879,0.000000
47.680004,52.167152,-173.208817,-0.002673,0.002883,0.073229,232.051086,11.821246,0.732286,-173.208817,0.074226,0.000000
47.890003,52.943550,-173.208817,-0.002665,0.002900,0.073671,235.504669,11.997180,0.736707,-173.208817,0.074573,0.000000
48.100002,53.623131,-173.253311,-0.002660,0.002915,0.074044,238.527603,12.151175,0.740439,-173.253311,0.074928,0.000000
48.310001,53.300652,-173.253311,-0.002639,0.002923,0.074235,237.093140,12.078100,0.742347,-173.253311,0.075276,0.000000
48.520000,53.671165,-173.297791,-0.002634,0.002933,0.074495,238.741272,12.162060,0.744951,-173.297791,0.075631,0.000000
48.730003,55.164375,-173.297791,-0.002626,0.002956,0.075093,245.383392,12.500426,0.750931,-173.297791,0.075978,0.000000
48.940002,55.538612,-173.342270,-0.002626,0.002970,0.075449,247.048080,12.585230,0.754489,-173.342270,0.076325,0.000000
49.150002,55.962372,-173.386749,-0.002600,0.002985,0.075830,248.933060,12.681254,0.758304,-173.386749,0.076680,0.000000
49.360001,56.419647,-173.386749,-0.002604,0.002997,0.076134,250.967133,12.784875,0.761339,-173.386749,0.077027,0.000000
49.570004,56.568970,-173.431229,-0.002578,0.003007,0.076368,251.631348,12.818712,0.763678,-173.431229,0.077374,0.000000
49.780003,56.794250,-173.520187,-0.002578,0.003021,0.076732,252.633438,12.869761,0.767319,-173.520187,0.077730,0.000000
49.990002,58.216339,-173.475708,-0.002557,0.003039,0.077201,258.959198,13.192011,0.772005,-173.475708,0.078076,0.000000
50.200001,58.129204,-173.520187,-0.002565,0.003048,0.077426,258.571625,13.172266,0.774261,-173.520187,0.078423,0.000000
50.410004,58.477005,-173.564667,-0.002565,0.003059,0.077704,260.118713,13.251079,0.777039,-173.564667,0.078779,0.000000
50.620003,58.913422,-173.609146,-0.002548,0.003075,0.078111,262.059998,13.349973,0.781111,-173.609146,0.079126,0.000000
50.830002,60.197365,-173.609146,-0.002552,0.003093,0.078571,267.771240,13.640918,0.785706,-173.609146,0.079481,0.000000
51.040001,60.534737,-173.609146,-0.002522,0.003105,0.078874,269.271942,13.717368,0.788742,-173.609146,0.079828,0.000000
51.250004,61.035950,-173.653625,-0.002522,0.003120,0.079238,271.501465,13.830944,0.792383,-173.653625,0.080175,0.000000
51.460003,61.310387,-173.609146,-0.002501,0.003130,0.079507,272.722229,13.893132,0.795070,-173.609146,0.080530,0.000000
51.670002,61.736008,-173.742599,-0.002501,0.003141,0.079794,274.615479,13.989579,0.797939,-173.742599,0.080878,0.000000
51.880001,62.576820,-173.742599,-0.002505,0.003159,0.080236,278.355591,14.180110,0.802360,-173.742599,0.081225,0.000000
52.090004,62.936539,-173.742599,-0.002488,0.003170,0.080522,279.955719,14.261624,0.805221,-173.742599,0.081580,0.000000
52.300003,63.209480,-173.831558,-0.002466,0.003181,0.080799,281.169800,14.323473,0.807992,-173.831558,0.081927,0.000000
52.510002,64.195152,-173.787079,-0.002475,0.003200,0.081285,285.554291,14.546829,0.812852,-173.787079,0.082274,0.000000
52.720001,65.267952,-173.876038,-0.002470,0.003217,0.081701,290.326355,14.789929,0.817015,-173.876038,0.082630,0.000000
52.930004,65.990364,-173.876038,-0.002449,0.003231,0.082075,293.539795,14.953630,0.820747,-173.876038,0.082976,0.000000
53.140003,66.566429,-173.876038,-0.002449,0.003245,0.082430,296.102264,15.084168,0.824297,-173.876038,0.083332,0.000000
53.350002,67.059074,-173.920517,-0.002445,0.003259,0.082768,298.293671,15.195804,0.827681,-173.920517,0.083679,0.000000
53.560001,66.698235,-173.920517,-0.002440,0.003260,0.082811,296.688568,15.114037,0.828112,-173.920517,0.084025,0.000000
53.770004,67.340218,-174.009476,-0.002419,0.003267,0.082976,299.544250,15.259511,0.829763,-174.009476,0.083228,0.000000
53.980003,66.424171,-174.009476,-0.002414,0.003267,0.082976,295.469482,15.051932,0.829763,-174.009476,0.083228,0.000000
54.190002,65.531227,-174.009476,-0.002402,0.003264,0.082907,291.497467,14.849588,0.829066,-174.009476,0.082976,0.000000
54.400002,64.729134,-174.098450,-0.002414,0.003263,0.082889,287.929565,14.667831,0.828892,-174.098450,0.082976,0.000000
54.610004,63.979179,-174.053955,-0.002402,0.003263,0.082873,284.593597,14.497890,0.828725,-174.053955,0.082976,0.000000
54.820004,63.280602,-174.142929,-0.002406,0.003262,0.082863,281.486176,14.339589,0.828635,-174.142929,0.082976,0.000000
55.030003,62.628212,-174.187408,-0.002406,0.003262,0.082863,278.584198,14.191755,0.828635,-174.187408,0.082976,0.000000
55.240002,62.008209,-174.142929,-0.002393,0.003262,0.082855,275.826294,14.051261,0.828551,-174.142929,0.082976,0.000000
55.450001,61.448532,-174.231888,-0.002393,0.003262,0.082855,273.336731,13.924437,0.828551,-174.231888,0.082976,0.000000
55.660004,60.910828,-174.231888,-0.002384,0.003262,0.082855,270.944885,13.802590,0.828551,-174.231888,0.082976,0.000000
55.870003,60.389137,-174.276367,-0.002376,0.003262,0.082855,268.624298,13.684374,0.828551,-174.276367,0.082976,0.000000
56.080002,59.902443,-174.409805,-0.002376,0.003262,0.082855,266.459381,13.574088,0.828551,-174.409805,0.082976,0.000000
56.290001,59.445915,-174.320847,-0.002376,0.003262,0.082846,264.428650,13.470637,0.828461,-174.320847,0.082976,0.000000
56.500004,59.019547,-174.409805,-0.002376,0.003262,0.082846,262.532043,13.374021,0.828461,-174.409805,0.082976,0.000000
56.710003,58.616646,-174.365326,-0.002384,0.003262,0.082846,260.739868,13.282722,0.828461,-174.365326,0.082976,0.000000
56.920002,58.220436,-174.409805,-0.002367,0.003262,0.082846,258.977448,13.192940,0.828461,-174.409805,0.082976,0.000000
57.130001,57.841736,-174.409805,-0.002371,0.003262,0.082846,257.292877,13.107125,0.828461,-174.409805,0.082976,0.000000
57.340004,57.496918,-174.409805,-0.002358,0.003262,0.082846,255.759064,13.028988,0.828461,-174.409805,0.082976,0.000000
57.550003,57.166252,-174.543259,-0.002358,0.003262,0.082846,254.288193,12.954058,0.828461,-174.543259,0.082976,0.000000
57.760002,56.838188,-174.498764,-0.002358,0.003262,0.082846,252.828888,12.879717,0.828461,-174.498764,0.082976,0.000000
57.970001,56.528008,-174.543259,-0.002354,0.003262,0.082846,251.449142,12.809429,0.828461,-174.543259,0.082976,0.000000
58.180004,56.240158,-174.587738,-0.002358,0.003262,0.082846,250.168716,12.744202,0.828461,-174.587738,0.082976,0.000000
58.390003,55.962746,-174.587738,-0.002367,0.003262,0.082846,248.934723,12.681339,0.828461,-174.587738,0.082976,0.000000
58.600002,55.692772,-174.632217,-0.002358,0.003262,0.082846,247.733826,12.620163,0.828461,-174.632217,0.082976,0.000000
58.810001,55.444031,-174.632217,-0.002367,0.003262,0.082846,246.627365,12.563796,0.828461,-174.632217,0.082976,0.000000
59.020004,55.189323,-174.632217,-0.002350,0.003262,0.082846,245.494370,12.506080,0.828461,-174.632217,0.082976,0.000000
59.230003,54.942818,-174.721176,-0.002363,0.003262,0.082846,244.397858,12.450220,0.828461,-174.721176,0.082976,0.000000
59.440002,54.716415,-174.676697,-0.002363,0.003262,0.082846,243.390778,12.398917,0.828461,-174.676697,0.082976,0.000000
59.650002,54.490387,-174.765656,-0.002354,0.003262,0.082846,242.385345,12.347698,0.828461,-174.765656,0.082976,0.000000
59.860004,54.287437,-174.810135,-0.002350,0.003262,0.082846,241.482590,12.301709,0.828461,-174.810135,0.082976,0.000000
60.070004,54.088219,-174.765656,-0.002350,0.003262,0.082846,240.596420,12.256566,0.828461,-174.765656,0.082976,0.000000
60.280003,53.884163,-174.854614,-0.002358,0.003262,0.082846,239.688721,12.210326,0.828461,-174.854614,0.082976,0.000000
60.490002,53.688667,-174.854614,-0.002341,0.003262,0.082846,238.819122,12.166026,0.828461,-174.854614,0.082976,0.000000
60.700005,53.502106,-174.943573,-0.002345,0.003262,0.082846,237.989258,12.123751,0.828461,-174.943573,0.082976,0.000000
60.910004,53.339752,-174.943573,-0.002345,0.003262,0.082846,237.267075,12.086960,0.828461,-174.943573,0.082976,0.000000
61.120003,53.163246,-174.988068,-0.002345,0.003262,0.082846,236.481934,12.046964,0.828461,-174.988068,0.082976,0.000000
61.330002,53.000893,-174.988068,-0.002345,0.003262,0.082846,235.759750,12.010174,0.828461,-174.988068,0.082976,0.000000
61.540005,52.842636,-174.988068,-0.002341,0.003262,0.082846,235.055786,11.974313,0.828461,-174.988068,0.082976,0.000000
61.750004,52.688103,-174.988068,-0.002337,0.003262,0.082846,234.368393,11.939294,0.828461,-174.988068,0.082976,0.000000
61.960003,52.517181,-175.121506,-0.002341,0.003262,0.082846,233.608093,11.900563,0.828461,-175.121506,0.082976,0.000000
62.170002,52.389832,-175.165985,-0.002333,0.003262,0.082846,233.041611,11.871706,0.828461,-175.165985,0.082976,0.000000
62.380001,52.226730,-175.210464,-0.002337,0.003262,0.082846,232.316101,11.834746,0.828461,-175.210464,0.082976,0.000000
62.590004,52.088577,-175.121506,-0.002337,0.003262,0.082846,231.701569,11.803440,0.828461,-175.121506,0.082976,0.000000
62.800003,51.954529,-175.165985,-0.002328,0.003262,0.082846,231.105286,11.773064,0.828461,-175.165985,0.082976,0.000000
63.010002,51.834251,-175.210464,-0.002345,0.003262,0.082846,230.570267,11.745809,0.828461,-175.210464,0.082976,0.000000
63.220001,51.699455,-175.210464,-0.002328,0.003262,0.082846,229.970657,11.715263,0.828461,-175.210464,0.082976,0.000000
63.430004,51.578430,-175.343903,-0.002345,0.003262,0.082846,229.432312,11.687840,0.828461,-175.343903,0.082976,0.000000
63.640003,51.449593,-175.299423,-0.002333,0.003262,0.082846,228.859222,11.658645,0.828461,-175.299423,0.082976,0.000000
63.850002,51.328568,-175.343903,-0.002328,0.003262,0.082846,228.320877,11.631219,0.828461,-175.343903,0.082976,0.000000
64.060005,51.219093,-175.388397,-0.002350,0.003262,0.082846,227.833908,11.606413,0.828461,-175.388397,0.082976,0.000000
64.270004,51.108124,-175.388397,-0.002333,0.003262,0.082846,227.340286,11.581266,0.828461,-175.388397,0.082976,0.000000
64.480003,51.004974,-175.432877,-0.002324,0.003262,0.082846,226.881454,11.557892,0.828461,-175.432877,0.082976,0.000000
64.690002,50.886192,-175.388397,-0.002337,0.003262,0.082846,226.353088,11.530976,0.828461,-175.388397,0.082976,0.000000
64.900002,50.809479,-175.477356,-0.002320,0.003262,0.082846,226.011856,11.513592,0.828461,-175.477356,0.082976,0.000000
65.110001,50.692932,-175.521835,-0.002333,0.003262,0.082846,225.493423,11.487183,0.828461,-175.521835,0.082976,0.000000
65.320000,50.595367,-175.477356,-0.002324,0.003262,0.082846,225.059433,11.465075,0.828461,-175.477356,0.082976,0.000000
65.530006,50.498177,-175.610794,-0.002337,0.003262,0.082846,224.627106,11.443050,0.828461,-175.610794,0.082976,0.000000
65.740005,50.398758,-175.610794,-0.002324,0.003262,0.082846,224.184875,11.420522,0.828461,-175.610794,0.082976,0.000000
65.950005,50.310127,-175.610794,-0.002328,0.003262,0.082846,223.790619,11.400438,0.828461,-175.610794,0.082976,0.000000
66.160004,50.219269,-175.655273,-0.002307,0.003262,0.082846,223.386459,11.379849,0.828461,-175.655273,0.082976,0.000000
66.370003,50.131393,-175.655273,-0.002307,0.003262,0.082846,222.995575,11.359937,0.828461,-175.655273,0.082976,0.000000
66.580002,50.049095,-175.699753,-0.002320,0.003262,0.082846,222.629501,11.341287,0.828461,-175.699753,0.082976,0.000000
66.790001,49.959724,-175.699753,-0.002333,0.003262,0.082846,222.231949,11.321035,0.828461,-175.699753,0.082976,0.000000
67.000000,49.874825,-175.744232,-0.002328,0.003262,0.082846,221.854294,11.301797,0.828461,-175.744232,0.082976,0.000000
67.210007,49.794769,-175.788712,-0.002337,0.003262,0.082846,221.498199,11.283656,0.828461,-175.788712,0.082976,0.000000
67.420006,49.728485,-175.788712,-0.002328,0.003262,0.082846,221.203354,11.268636,0.828461,-175.788712,0.082976,0.000000
67.630005,49.641350,-175.833206,-0.002328,0.003262,0.082846,220.815750,11.248891,0.828461,-175.833206,0.082976,0.000000
67.840004,49.561661,-175.788712,-0.002324,0.003262,0.082846,220.461273,11.230833,0.828461,-175.788712,0.082976,0.000000
68.050003,49.480110,-175.877686,-0.002337,0.003262,0.082846,220.098526,11.212353,0.828461,-175.877686,0.082976,0.000000
68.260002,49.412338,-175.922165,-0.002324,0.003262,0.082846,219.797058,11.196996,0.828461,-175.922165,0.082976,0.000000
68.470001,49.332649,-175.877686,-0.002315,0.003262,0.082846,219.442581,11.178938,0.828461,-175.877686,0.082976,0.000000
68.680000,49.268974,-176.011124,-0.002324,0.003262,0.082846,219.159348,11.164509,0.828461,-176.011124,0.082976,0.000000
68.890007,49.206421,-175.966644,-0.002320,0.003262,0.082846,218.881088,11.150334,0.828461,-175.966644,0.082976,0.000000
69.100006,49.132690,-176.011124,-0.002320,0.003262,0.082846,218.553116,11.133627,0.828461,-176.011124,0.082976,0.000000
69.310005,49.060822,-176.055603,-0.002307,0.003262,0.082846,218.233429,11.117341,0.828461,-176.055603,0.082976,0.000000
69.520004,49.007942,-176.055603,-0.002328,0.003262,0.082846,217.998215,11.105359,0.828461,-176.055603,0.082976,0.000000
69.730003,48.936073,-176.055603,-0.002328,0.003262,0.082846,217.678528,11.089073,0.828461,-176.055603,0.082976,0.000000
69.940002,48.875748,-176.100082,-0.002328,0.003262,0.082846,217.410187,11.075402,0.828461,-176.100082,0.082976,0.000000
70.150002,48.808723,-176.144562,-0.002311,0.003262,0.082846,217.112045,11.060214,0.828461,-176.144562,0.082976,0.000000
70.360001,48.739090,-176.189041,-0.002324,0.003262,0.082846,216.802307,11.044436,0.828461,-176.189041,0.082976,0.000000
70.570000,48.687706,-176.189041,-0.002320,0.003262,0.082846,216.573730,11.032792,0.828461,-176.189041,0.082976,0.000000
70.780006,48.638550,-176.233521,-0.002324,0.003262,0.082846,216.355072,11.021653,0.828461,-176.233521,0.082976,0.000000
70.990005,48.567429,-176.278015,-0.002311,0.003262,0.082846,216.038712,11.005537,0.828461,-176.278015,0.082976,0.000000
71.200005,48.507103,-176.322495,-0.002315,0.003262,0.082846,215.770370,10.991867,0.828461,-176.322495,0.082976,0.000000
71.410004,48.447525,-176.322495,-0.002315,0.003262,0.082846,215.505356,10.978366,0.828461,-176.322495,0.082976,0.000000
71.620003,48.388687,-176.278015,-0.002324,0.003262,0.082846,215.243637,10.965034,0.828461,-176.278015,0.082976,0.000000
71.830002,48.341766,-176.366974,-0.002320,0.003262,0.082846,215.034912,10.954401,0.828461,-176.366974,0.082976,0.000000
72.040001,48.281815,-176.366974,-0.002324,0.003262,0.082846,214.768234,10.940815,0.828461,-176.366974,0.082976,0.000000
72.250000,48.225220,-176.411453,-0.002320,0.003262,0.082846,214.516495,10.927991,0.828461,-176.411453,0.082976,0.000000
72.460007,48.167130,-176.411453,-0.002320,0.003262,0.082846,214.258087,10.914827,0.828461,-176.411453,0.082976,0.000000
72.670006,48.123558,-176.411453,-0.002311,0.003262,0.082846,214.064270,10.904955,0.828461,-176.411453,0.082976,0.000000
72.880005,48.057648,-176.500412,-0.002298,0.003262,0.082846,213.771088,10.890018,0.828461,-176.500412,0.082976,0.000000
73.090004,48.004402,-176.544891,-0.002320,0.003262,0.082846,213.534241,10.877954,0.828461,-176.544891,0.082976,0.000000
73.300003,47.961578,-176.544891,-0.002315,0.003262,0.082846,213.343750,10.868249,0.828461,-176.544891,0.082976,0.000000
73.510002,47.912048,-176.589371,-0.002315,0.003262,0.082846,213.123428,10.857025,0.828461,-176.589371,0.082976,0.000000
73.720001,47.855453,-176.633850,-0.002311,0.003262,0.082846,212.871689,10.844201,0.828461,-176.633850,0.082976,0.000000
73.930000,47.816353,-176.633850,-0.002324,0.003262,0.082846,212.697754,10.835340,0.828461,-176.633850,0.082976,0.000000
74.140007,47.763474,-176.633850,-0.002320,0.003262,0.082846,212.462540,10.823358,0.828461,-176.633850,0.082976,0.000000
74.350006,47.711716,-176.678345,-0.002311,0.003262,0.082846,212.232315,10.811629,0.828461,-176.678345,0.082976,0.000000
74.560005,47.671127,-176.722824,-0.002311,0.003262,0.082846,212.051758,10.802432,0.828461,-176.722824,0.082976,0.000000
74.770004,47.620483,-176.722824,-0.002302,0.003262,0.082846,211.826492,10.790956,0.828461,-176.722824,0.082976,0.000000
74.980003,47.581009,-176.767303,-0.002298,0.003262,0.082846,211.650894,10.782011,0.828461,-176.767303,0.082976,0.000000
75.190002,47.531860,-176.767303,-0.002315,0.003262,0.082846,211.432281,10.770874,0.828461,-176.767303,0.082976,0.000000
75.400002,47.495369,-176.767303,-0.002307,0.003262,0.082846,211.269958,10.762604,0.828461,-176.767303,0.082976,0.000000
75.610001,47.443977,-176.945221,-0.002324,0.003262,0.082846,211.041351,10.750959,0.828461,-176.945221,0.082976,0.000000
75.820007,47.397057,-176.900742,-0.002315,0.003262,0.082846,210.832642,10.740327,0.828461,-176.900742,0.082976,0.000000
76.030006,47.347534,-176.945221,-0.002298,0.003262,0.082846,210.612350,10.729105,0.828461,-176.945221,0.082976,0.000000
76.240005,47.312904,-176.900742,-0.002311,0.003262,0.082846,210.458313,10.721257,0.828461,-176.900742,0.082976,0.000000
76.450005,47.277527,-176.900742,-0.002320,0.003262,0.082846,210.300949,10.713242,0.828461,-176.900742,0.082976,0.000000
76.660004,47.228378,-177.034180,-0.002307,0.003262,0.082846,210.082321,10.702104,0.828461,-177.034180,0.082976,0.000000
76.870003,47.192253,-176.989700,-0.002324,0.003262,0.082846,209.921631,10.693918,0.828461,-176.989700,0.082976,0.000000
77.080002,47.153152,-176.989700,-0.002307,0.003262,0.082846,209.747696,10.685058,0.828461,-176.989700,0.082976,0.000000
77.290001,47.092461,-177.034180,-0.002311,0.003262,0.082846,209.477722,10.671305,0.828461,-177.034180,0.082976,0.000000
77.500000,47.052986,-177.034180,-0.002324,0.003262,0.082846,209.302139,10.662359,0.828461,-177.034180,0.082976,0.000000
77.710007,47.025803,-177.123154,-0.002320,0.003262,0.082846,209.181213,10.656199,0.828461,-177.123154,0.082976,0.000000
77.920006,46.991173,-177.123154,-0.002307,0.003262,0.082846,209.027176,10.648353,0.828461,-177.123154,0.082976,0.000000
78.130005,46.951332,-177.167633,-0.002307,0.003262,0.082846,208.849960,10.639324,0.828461,-177.167633,0.082976,0.000000
78.340004,46.909256,-177.212112,-0.002315,0.003262,0.082846,208.662796,10.629789,0.828461,-177.212112,0.082976,0.000000
78.550003,46.867172,-177.212112,-0.002311,0.003262,0.082846,208.475601,10.620253,0.828461,-177.212112,0.082976,0.000000
78.760002,46.841850,-177.345551,-0.002311,0.003262,0.082846,208.362961,10.614515,0.828461,-177.345551,0.082976,0.000000
78.970001,46.793816,-177.301071,-0.002311,0.003262,0.082846,208.149292,10.603630,0.828461,-177.301071,0.082976,0.000000
79.180000,46.762169,-177.301071,-0.002320,0.003262,0.082846,208.008514,10.596459,0.828461,-177.301071,0.082976,0.000000
79.390007,46.734612,-177.301071,-0.002324,0.003262,0.082846,207.885941,10.590214,0.828461,-177.301071,0.082976,0.000000
79.600006,46.681358,-177.301071,-0.002311,0.003262,0.082846,207.649048,10.578147,0.828461,-177.301071,0.082976,0.000000
79.810005,46.656784,-177.434509,-0.002311,0.003262,0.082846,207.539734,10.572578,0.828461,-177.434509,0.082976,0.000000
80.020004,46.625877,-177.390030,-0.002302,0.003262,0.082846,207.402267,10.565576,0.828461,-177.390030,0.082976,0.000000
80.230003,46.584167,-177.434509,-0.002302,0.003262,0.082846,207.216721,10.556123,0.828461,-177.434509,0.082976,0.000000
80.440002,46.551033,-177.478989,-0.002315,0.003262,0.082846,207.069336,10.548615,0.828461,-177.478989,0.082976,0.000000
80.650002,46.532036,-177.523483,-0.002311,0.003262,0.082846,206.984833,10.544310,0.828461,-177.523483,0.082976,0.000000
80.860001,46.488472,-177.612442,-0.002307,0.003262,0.082846,206.791046,10.534438,0.828461,-177.612442,0.082976,0.000000
81.070007,46.473206,-177.567963,-0.002311,0.003262,0.082846,206.723145,10.530979,0.828461,-177.567963,0.082976,0.000000
81.280006,46.418465,-177.567963,-0.002298,0.003262,0.082846,206.479645,10.518575,0.828461,-177.567963,0.082976,0.000000
81.490005,46.387558,-177.656921,-0.002307,0.003262,0.082846,206.342163,10.511571,0.828461,-177.656921,0.082976,0.000000
81.700005,46.374153,-177.612442,-0.002311,0.003262,0.082846,206.282532,10.508533,0.828461,-177.612442,0.082976,0.000000
81.910004,46.320160,-177.701401,-0.002298,0.003262,0.082846,206.042358,10.496298,0.828461,-177.701401,0.082976,0.000000
82.120003,46.306381,-177.701401,-0.002302,0.003262,0.082846,205.981064,10.493176,0.828461,-177.701401,0.082976,0.000000
82.330002,46.258720,-177.701401,-0.002311,0.003262,0.082846,205.769058,10.482376,0.828461,-177.701401,0.082976,0.000000
82.540001,46.218872,-177.790359,-0.002315,0.003262,0.082846,205.591812,10.473346,0.828461,-177.790359,0.082976,0.000000
82.750008,46.200996,-177.701401,-0.002302,0.003262,0.082846,205.512299,10.469296,0.828461,-177.701401,0.082976,0.000000
82.960007,46.158180,-177.879318,-0.002294,0.003262,0.082846,205.321838,10.459593,0.828461,-177.879318,0.082976,0.000000
83.170006,46.132858,-177.834839,-0.002307,0.003262,0.082846,205.209198,10.453856,0.828461,-177.834839,0.082976,0.000000
83.380005,46.106415,-177.834839,-0.002311,0.003262,0.082846,205.091583,10.447863,0.828461,-177.834839,0.082976,0.000000
83.590004,46.075134,-177.879318,-0.002311,0.003262,0.082846,204.952438,10.440774,0.828461,-177.879318,0.082976,0.000000
83.800003,46.049446,-177.879318,-0.002294,0.003262,0.082846,204.838165,10.434954,0.828461,-177.879318,0.082976,0.000000
84.010002,46.014816,-177.968292,-0.002315,0.003262,0.082846,204.684128,10.427107,0.828461,-177.968292,0.082976,0.000000
84.100006,46.002151,-177.968292,-0.002307,0.003262,0.082846,204.627792,10.424236,0.828461,-177.968292,0.082976,0.000000