File: Data/compression 10/AutoHeating-17-10-2-240424_04242024_224654.csv
Time (sec),S:Load (lbs),S:HL1 (DIM),S:LVDT (in),S:Position (in),Ch:Position (mm),Ch:Load (N),Ch:Stress (MPa),Ch:Strain (mm/mm),Ch:HL1 (DIM),Set Point (),Cycles ()
0.010000,-0.000000,-145.408234,-0.013741,-0.000000,-0.000000,-0.000000,-0.000000,-0.000000,-145.408234,0.000191,0.000000
0.240000,0.002983,-145.452713,-0.013719,-0.000000,-0.000000,0.013269,0.000676,-0.000000,-145.452713,0.000191,0.000000
0.470000,-0.027184,-145.497192,-0.013749,0.000074,0.001890,-0.120918,-0.006160,0.018902,-145.497192,0.002462,0.000000
0.700000,0.002235,-145.586151,-0.013685,0.000208,0.005290,0.009944,0.000507,0.052898,-145.586151,0.006296,0.000000
0.930000,-0.022713,-145.586151,-0.013555,0.000358,0.009088,-0.101031,-0.005147,0.090883,-145.586151,0.010129,0.000000
1.160000,0.014153,-145.630630,-0.013409,0.000513,0.013025,0.062954,0.003207,0.130253,-145.630630,0.013962,0.000000
1.390000,0.008194,-145.630630,-0.013241,0.000658,0.016720,0.036449,0.001857,0.167202,-145.630630,0.017795,0.000000
1.620000,-0.024574,-145.675110,-0.013094,0.000813,0.020640,-0.109312,-0.005569,0.206398,-145.675110,0.021628,0.000000
1.850000,-0.016380,-145.719589,-0.012926,0.000965,0.024516,-0.072863,-0.003712,0.245163,-145.719589,0.025444,0.000000
2.080000,-0.000740,-145.808563,-0.012797,0.001112,0.028254,-0.003292,-0.000168,0.282542,-145.808563,0.029278,0.000000
2.310000,-0.002235,-145.808563,-0.012620,0.001264,0.032104,-0.009944,-0.000507,0.321042,-145.808563,0.033110,0.000000
2.540000,0.040962,-145.808563,-0.012473,0.001410,0.035825,0.182209,0.009282,0.358248,-145.808563,0.036944,0.000000
2.770000,0.030167,-145.853043,-0.012309,0.001569,0.039857,0.134188,0.006836,0.398572,-145.853043,0.040777,0.000000
3.000000,0.015266,-145.942001,-0.012184,0.001717,0.043621,0.067908,0.003459,0.436209,-145.942001,0.044610,0.000000
3.230000,-0.012657,-145.986481,-0.012029,0.001866,0.047385,-0.056302,-0.002868,0.473846,-145.986481,0.048443,0.000000
3.460000,-0.013031,-145.942001,-0.011870,0.002017,0.051227,-0.057965,-0.002953,0.512270,-145.942001,0.052276,0.000000
3.690000,0.026810,-145.986481,-0.011684,0.002170,0.055129,0.119255,0.006075,0.551293,-145.986481,0.056110,0.000000
3.920000,0.005211,-145.986481,-0.011559,0.002317,0.058858,0.023179,0.001181,0.588581,-145.986481,0.059942,0.000000
4.150000,0.030907,-146.119919,-0.011421,0.002470,0.062744,0.137480,0.007004,0.627437,-146.119919,0.063775,0.000000
4.380000,0.010429,-146.119919,-0.011262,0.002622,0.066603,0.046392,0.002363,0.666028,-146.119919,0.067609,0.000000
4.610000,0.014893,-146.164398,-0.011102,0.002775,0.070497,0.066245,0.003375,0.704967,-146.164398,0.071442,0.000000
4.840000,0.014526,-146.164398,-0.010956,0.002922,0.074217,0.064617,0.003292,0.742172,-146.164398,0.075257,0.000000
5.070000,0.034256,-146.119919,-0.010792,0.003070,0.077981,0.152378,0.007763,0.779809,-146.119919,0.079091,0.000000
5.300000,0.020851,-146.253372,-0.010645,0.003229,0.082004,0.092750,0.004725,0.820043,-146.253372,0.082924,0.000000
5.530000,-0.000374,-146.297852,-0.010494,0.003376,0.085751,-0.001663,-0.000085,0.857513,-146.297852,0.086757,0.000000
5.760000,-0.042824,-146.297852,-0.010343,0.003524,0.089515,-0.190490,-0.009704,0.895150,-146.297852,0.090590,0.000000
5.990000,-0.047661,-146.342331,-0.010210,0.003676,0.093382,-0.212006,-0.010800,0.933824,-146.342331,0.094423,0.000000
6.220000,0.053619,-146.342331,-0.010050,0.003823,0.097095,0.238511,0.012150,0.970947,-146.342331,0.098257,0.000000
6.450000,0.039101,-146.475769,-0.009925,0.003976,0.100997,0.173928,0.008860,1.009969,-146.475769,0.102089,0.000000
6.680000,0.056602,-146.475769,-0.009753,0.004133,0.104969,0.251780,0.012826,1.049688,-146.475769,0.105923,0.000000
6.910000,0.014893,-146.431290,-0.009597,0.004281,0.108742,0.066245,0.003375,1.087415,-146.431290,0.109756,0.000000
7.140000,0.027184,-146.520248,-0.009442,0.004431,0.112539,0.120918,0.006160,1.125393,-146.520248,0.113589,0.000000
7.370000,0.018250,-146.564728,-0.009291,0.004583,0.116407,0.081178,0.004135,1.164075,-146.564728,0.117422,0.000000
7.600000,0.026436,-146.609207,-0.009145,0.004736,0.120284,0.117593,0.005990,1.202840,-146.609207,0.121255,0.000000
7.830000,0.018250,-146.698181,-0.008990,0.004886,0.124100,0.081178,0.004135,1.240999,-146.698181,0.125071,0.000000
8.060000,-0.035378,-146.698181,-0.008860,0.005035,0.127898,-0.157367,-0.008017,1.278984,-146.698181,0.128904,0.000000
8.290000,-0.009682,-146.609207,-0.008701,0.005181,0.131610,-0.043066,-0.002194,1.316099,-146.609207,0.132737,0.000000
8.520000,0.032028,-146.698181,-0.008545,0.005336,0.135547,0.142469,0.007258,1.355469,-146.698181,0.136570,0.000000
8.750000,0.073730,-146.787140,-0.008382,0.005482,0.139250,0.327969,0.016708,1.392501,-146.787140,0.140404,0.000000
8.980000,0.068893,-146.831619,-0.008231,0.005639,0.143222,0.306453,0.015611,1.432219,-146.831619,0.144237,0.000000
9.210000,0.058464,-146.831619,-0.008088,0.005792,0.147125,0.260061,0.013248,1.471249,-146.831619,0.148070,0.000000
9.440001,0.010429,-146.876099,-0.007933,0.005939,0.150854,0.046392,0.002363,1.508538,-146.876099,0.151903,0.000000
9.670000,0.034630,-146.920578,-0.007795,0.006090,0.154678,0.154041,0.007847,1.546781,-146.920578,0.155736,0.000000
9.900001,0.031654,-146.965057,-0.007614,0.006241,0.158511,0.140806,0.007173,1.585114,-146.965057,0.159570,0.000000
10.130000,0.013031,-147.054031,-0.007476,0.006392,0.162345,0.057965,0.002953,1.623447,-147.054031,0.163402,0.000000
10.360001,0.025322,-147.009537,-0.007317,0.006546,0.166273,0.112638,0.005738,1.662727,-147.009537,0.167236,0.000000
10.590000,0.014893,-147.009537,-0.007161,0.006693,0.169993,0.066245,0.003375,1.699933,-147.009537,0.171052,0.000000
10.820001,0.017876,-147.098511,-0.007002,0.006844,0.173827,0.079515,0.004051,1.738266,-147.098511,0.174885,0.000000
11.050000,0.061440,-147.142990,-0.006855,0.006998,0.177738,0.273297,0.013922,1.777379,-147.142990,0.178717,0.000000
11.280001,0.051392,-147.231949,-0.006691,0.007146,0.181519,0.228601,0.011646,1.815190,-147.231949,0.182551,0.000000
11.510000,0.055115,-147.187469,-0.006554,0.007297,0.185352,0.245163,0.012489,1.853516,-147.187469,0.186384,0.000000
11.740001,0.005585,-147.231949,-0.006381,0.007450,0.189228,0.024842,0.001266,1.892281,-147.231949,0.190217,0.000000
11.970000,-0.006699,-147.276428,-0.006239,0.007595,0.192914,-0.029797,-0.001518,1.929138,-147.276428,0.194050,0.000000
12.200001,0.032394,-147.365387,-0.006088,0.007752,0.196903,0.144098,0.007341,1.969031,-147.365387,0.197883,0.000000
12.430000,0.048035,-147.365387,-0.005963,0.007899,0.200624,0.213669,0.010885,2.006237,-147.365387,0.201717,0.000000
12.660001,0.056229,-147.409866,-0.005812,0.008045,0.204353,0.250117,0.012742,2.043525,-147.409866,0.205549,0.000000
12.890000,0.051758,-147.409866,-0.005635,0.008206,0.208437,0.230230,0.011728,2.084372,-147.409866,0.209383,0.000000
13.120001,0.021973,-147.409866,-0.005506,0.008353,0.212175,0.097739,0.004979,2.121752,-147.409866,0.213216,0.000000
13.350000,0.056229,-147.498840,-0.005355,0.008503,0.215965,0.250117,0.012742,2.159653,-147.498840,0.217049,0.000000
13.580001,0.065910,-147.543320,-0.005213,0.008654,0.219815,0.293184,0.014935,2.198153,-147.543320,0.220865,0.000000
13.810000,0.065163,-147.543320,-0.005044,0.008805,0.223649,0.289858,0.014766,2.236487,-147.543320,0.224698,0.000000
14.040001,0.122139,-147.543320,-0.004894,0.008957,0.227516,0.543301,0.027677,2.275161,-147.543320,0.228531,0.000000
14.270000,0.748466,-147.587799,-0.004781,-0.000009,-0.000216,3.329345,0.169605,-0.002165,-147.587799,-0.000043,0.000000
14.500001,0.704903,-147.721237,-0.004790,-0.000009,-0.000226,3.135564,0.159733,-0.002256,-147.721237,-0.000043,0.000000
14.730000,0.671013,-147.721237,-0.004790,-0.000009,-0.000234,2.984814,0.152054,-0.002339,-147.721237,-0.000043,0.000000
14.960001,0.645699,-147.721237,-0.004777,-0.000009,-0.000234,2.872211,0.146317,-0.002339,-147.721237,0.000278,0.000000
15.190001,0.656494,-147.765717,-0.004799,-0.000009,-0.000226,2.920232,0.148764,-0.002256,-147.765717,0.000659,0.000000
15.420001,0.870605,-147.810196,-0.004794,0.000012,0.000304,3.872647,0.197282,0.003035,-147.810196,0.001049,0.000000
15.650001,1.067596,-147.854675,-0.004769,0.000027,0.000677,4.748906,0.241921,0.006767,-147.854675,0.001431,0.000000
15.880001,1.203140,-147.899155,-0.004773,0.000040,0.001006,5.351835,0.272635,0.010060,-147.899155,0.001813,0.000000
16.110001,1.418365,-147.899155,-0.004747,0.000052,0.001310,6.309205,0.321406,0.013096,-147.899155,0.002194,0.000000
16.340000,1.670464,-147.943649,-0.004756,0.000067,0.001691,7.430593,0.378532,0.016911,-147.943649,0.002576,0.000000
16.570002,2.080070,-147.988129,-0.004730,0.000088,0.002246,9.252616,0.471351,0.022460,-147.988129,0.002966,0.000000
16.800001,2.280785,-148.032608,-0.004712,0.000101,0.002567,10.145436,0.516833,0.025669,-148.032608,0.003347,0.000000
17.030001,2.471809,-148.121567,-0.004712,0.000110,0.002802,10.995157,0.560120,0.028016,-148.121567,0.003729,0.000000
17.260000,2.896683,-148.032608,-0.004695,0.000132,0.003347,12.885088,0.656398,0.033474,-148.032608,0.004111,0.000000
17.490002,3.193466,-148.077087,-0.004682,0.000147,0.003729,14.205247,0.723650,0.037289,-148.077087,0.004501,0.000000
17.720001,3.523018,-148.121567,-0.004669,0.000164,0.004154,15.671166,0.798327,0.041543,-148.121567,0.004883,0.000000
17.950001,3.701385,-148.210526,-0.004656,0.000174,0.004423,16.464584,0.838746,0.044230,-148.210526,0.005264,0.000000
18.180000,4.084930,-148.299484,-0.004644,0.000191,0.004857,18.170677,0.925658,0.048568,-148.299484,0.005646,0.000000
18.410002,4.272232,-148.255005,-0.004639,0.000201,0.005108,19.003838,0.968102,0.051081,-148.255005,0.006027,0.000000
18.640001,4.784988,-148.255005,-0.004609,0.000221,0.005611,21.284691,1.084294,0.056115,-148.255005,0.006418,0.000000
18.870001,5.103737,-148.299484,-0.004596,0.000233,0.005923,22.702555,1.156523,0.059234,-148.299484,0.006799,0.000000
19.100000,5.426956,-148.432938,-0.004600,0.000251,0.006365,24.140306,1.229766,0.063654,-148.432938,0.007181,0.000000
19.330002,5.855934,-148.432938,-0.004583,0.000269,0.006825,26.048496,1.326974,0.068249,-148.432938,0.007562,0.000000
19.560001,6.088661,-148.477417,-0.004553,0.000281,0.007146,27.083717,1.379710,0.071459,-148.477417,0.007944,0.000000
19.790001,6.420822,-148.432938,-0.004562,0.000298,0.007562,28.561243,1.454979,0.075622,-148.432938,0.008334,0.000000
20.020000,6.695259,-148.521896,-0.004549,0.000311,0.007892,29.782000,1.517167,0.078923,-148.521896,0.008716,0.000000
20.250002,6.944000,-148.566376,-0.004544,0.000324,0.008230,30.888456,1.573533,0.082299,-148.566376,0.009097,0.000000
20.480001,7.352867,-148.566376,-0.004544,0.000339,0.008611,32.707188,1.666183,0.086114,-148.566376,0.009479,0.000000
20.710001,7.690979,-148.610855,-0.004510,0.000353,0.008967,34.211182,1.742801,0.089672,-148.610855,0.009860,0.000000
20.940001,7.779610,-148.610855,-0.004510,0.000364,0.009245,34.605431,1.762885,0.092450,-148.610855,0.010251,0.000000
21.170000,8.202621,-148.699814,-0.004484,0.000379,0.009635,36.487083,1.858741,0.096348,-148.699814,0.010633,0.000000
21.400002,8.862839,-148.744293,-0.004467,0.000402,0.010216,39.423874,2.008348,0.102162,-148.744293,0.011014,0.000000
21.630001,9.047165,-148.788788,-0.004475,0.000419,0.010633,40.243801,2.050117,0.106325,-148.788788,0.011396,0.000000
21.860001,9.166321,-148.788788,-0.004454,0.000429,0.010892,40.773830,2.077118,0.108922,-148.788788,0.011777,0.000000
22.090000,9.447464,-148.788788,-0.004432,0.000444,0.011283,42.024418,2.140826,0.112828,-148.788788,0.012168,0.000000
22.320002,9.713333,-148.833267,-0.004424,0.000460,0.011673,43.207066,2.201073,0.116734,-148.833267,0.012549,0.000000
22.550001,10.138214,-148.966705,-0.004415,0.000475,0.012063,45.097027,2.297352,0.120632,-148.966705,0.012931,0.000000
22.780001,10.125923,-148.966705,-0.004411,0.000486,0.012332,45.042355,2.294567,0.123319,-148.966705,0.013312,0.000000
23.010000,10.693047,-148.922226,-0.004402,0.000505,0.012818,47.565048,2.423079,0.128179,-148.922226,0.013694,0.000000
23.240002,11.214745,-149.011185,-0.004363,0.000524,0.013312,49.885674,2.541297,0.133122,-149.011185,0.014084,0.000000
23.470001,11.386780,-149.055664,-0.004359,0.000539,0.013685,50.650925,2.580281,0.136847,-149.055664,0.014466,0.000000
23.700001,11.552856,-149.100143,-0.004355,0.000554,0.014075,51.389671,2.617915,0.140753,-149.100143,0.014847,0.000000
23.930000,11.816498,-149.189117,-0.004337,0.000567,0.014396,52.562408,2.677657,0.143962,-149.189117,0.015229,0.000000
24.160002,12.020554,-149.100143,-0.004320,0.000581,0.014752,53.470093,2.723897,0.147520,-149.100143,0.015610,0.000000
24.390001,12.452133,-149.144623,-0.004307,0.000596,0.015151,55.389854,2.821694,0.151509,-149.144623,0.016000,0.000000
24.620001,12.766792,-149.189117,-0.004290,0.000613,0.015567,56.789528,2.892997,0.155665,-149.189117,0.016382,0.000000
24.850000,12.793228,-149.278076,-0.004286,0.000621,0.015784,56.907120,2.898987,0.157838,-149.278076,0.016763,0.000000
25.080002,13.428123,-149.233597,-0.004273,0.000645,0.016391,59.731277,3.042856,0.163909,-149.233597,0.017146,0.000000
25.310001,13.698463,-149.322556,-0.004255,0.000661,0.016798,60.933807,3.104116,0.167981,-149.322556,0.017527,0.000000
25.540001,13.799011,-149.367035,-0.004238,0.000675,0.017136,61.381069,3.126901,0.171365,-149.367035,0.017917,0.000000
25.770000,13.938278,-149.367035,-0.004225,0.000686,0.017423,62.000557,3.158459,0.174226,-149.367035,0.018298,0.000000
26.000002,14.426086,-149.455994,-0.004225,0.000706,0.017926,64.170441,3.268998,0.179260,-149.455994,0.018680,0.000000
26.230001,14.628281,-149.500473,-0.004195,0.000719,0.018264,65.069839,3.314816,0.182636,-149.500473,0.019061,0.000000
26.460001,14.870323,-149.500473,-0.004195,0.000732,0.018602,66.146500,3.369663,0.186020,-149.500473,0.019452,0.000000
26.690001,14.852821,-149.500473,-0.004178,0.000741,0.018810,66.068649,3.365697,0.188102,-149.500473,0.019834,0.000000
26.920002,15.385689,-149.544952,-0.004182,0.000760,0.019314,68.438965,3.486447,0.193136,-149.544952,0.020215,0.000000
27.150002,15.761040,-149.589432,-0.004161,0.000779,0.019781,70.108604,3.571502,0.197814,-149.589432,0.020597,0.000000
27.380001,16.078674,-149.633926,-0.004143,0.000794,0.020172,71.521515,3.643480,0.201720,-149.633926,0.020978,0.000000
27.610001,16.345291,-149.678406,-0.004143,0.000810,0.020562,72.707489,3.703896,0.205618,-149.678406,0.021369,0.000000
27.840002,16.382896,-149.678406,-0.004109,0.000821,0.020865,72.874763,3.712417,0.208654,-149.678406,0.021750,0.000000
28.070002,16.714684,-149.722885,-0.004105,0.000837,0.021256,74.350624,3.787601,0.212560,-149.722885,0.022132,0.000000
28.300001,16.998062,-149.811844,-0.004113,0.000853,0.021655,75.611160,3.851816,0.216549,-149.811844,0.022513,0.000000
28.530001,17.144775,-149.856323,-0.004083,0.000866,0.021993,76.263771,3.885062,0.219933,-149.856323,0.022895,0.000000
28.760002,17.130997,-149.767365,-0.004070,0.000876,0.022262,76.202477,3.881939,0.222620,-149.767365,0.023285,0.000000
28.990002,17.812065,-149.856323,-0.004057,0.000898,0.022799,79.232025,4.036272,0.227995,-149.856323,0.023667,0.000000
29.220001,18.134911,-149.900803,-0.004040,0.000915,0.023251,80.668114,4.109430,0.232506,-149.900803,0.024048,0.000000
29.450001,18.219070,-149.945282,-0.004031,0.000928,0.023572,81.042473,4.128500,0.235716,-149.945282,0.024430,0.000000
29.680002,18.419777,-150.034241,-0.004014,0.000944,0.023979,81.935257,4.173981,0.239788,-150.034241,0.024812,0.000000
29.910002,18.400787,-149.989761,-0.004014,0.000955,0.024257,81.850792,4.169678,0.242566,-149.989761,0.025202,0.000000
30.140001,18.898277,-149.989761,-0.003975,0.000973,0.024708,84.063736,4.282411,0.247078,-149.989761,0.025584,0.000000
30.370001,19.153725,-150.123215,-0.003958,0.000987,0.025080,85.200020,4.340296,0.250802,-150.123215,0.025965,0.000000
30.600002,19.011475,-150.212173,-0.003967,0.000997,0.025332,84.567261,4.308062,0.253315,-150.212173,0.026347,0.000000
30.830002,19.476570,-150.078735,-0.003962,0.001017,0.025835,86.636108,4.413454,0.258349,-150.078735,0.026728,0.000000
31.060001,19.952461,-150.167694,-0.003945,0.001035,0.026277,88.752983,4.521292,0.262770,-150.167694,0.027118,0.000000
31.290001,20.257805,-150.212173,-0.003915,0.001052,0.026719,90.111214,4.590484,0.267191,-150.212173,0.027500,0.000000
31.520002,20.286110,-150.256653,-0.003898,0.001066,0.027067,90.237122,4.596898,0.270665,-150.256653,0.027882,0.000000
31.750002,20.343452,-150.345612,-0.003898,0.001078,0.027378,90.492195,4.609892,0.273784,-150.345612,0.028263,0.000000
31.980001,20.381065,-150.301132,-0.003876,0.001092,0.027734,90.659508,4.618415,0.277342,-150.301132,0.028645,0.000000
32.210003,20.837219,-150.345612,-0.003876,0.001110,0.028202,92.688583,4.721781,0.282020,-150.345612,0.029035,0.000000
32.440002,20.804077,-150.345612,-0.003842,0.001122,0.028489,92.541161,4.714271,0.284889,-150.345612,0.029416,0.000000
32.670002,20.818604,-150.434570,-0.003850,0.001135,0.028818,92.605774,4.717563,0.288182,-150.434570,0.029798,0.000000
32.900002,21.483284,-150.434570,-0.003846,0.001155,0.029347,95.562424,4.868182,0.293473,-150.434570,0.030180,0.000000
33.130001,21.628510,-150.479065,-0.003824,0.001167,0.029651,96.208412,4.901090,0.296509,-150.479065,0.030562,0.000000
33.360001,21.952850,-150.479065,-0.003807,0.001187,0.030153,97.651154,4.974587,0.301535,-150.479065,0.030951,0.000000
33.590000,21.905930,-150.523544,-0.003781,0.001198,0.030431,97.442444,4.963955,0.304313,-150.523544,0.031333,0.000000
33.820004,22.174782,-150.523544,-0.003777,0.001214,0.030830,98.638359,5.024877,0.308302,-150.523544,0.031714,0.000000
34.050003,22.431343,-150.612503,-0.003773,0.001231,0.031255,99.779594,5.083015,0.312549,-150.612503,0.032096,0.000000
34.280003,22.605988,-150.612503,-0.003760,0.001245,0.031611,100.556458,5.122590,0.316107,-150.612503,0.032487,0.000000
34.510002,22.636520,-150.701462,-0.003734,0.001257,0.031932,100.692268,5.129508,0.319316,-150.701462,0.032868,0.000000
34.740002,23.196198,-150.701462,-0.003725,0.001278,0.032469,103.181839,5.256334,0.324691,-150.701462,0.033250,0.000000
34.970001,23.143326,-150.745941,-0.003708,0.001290,0.032773,102.946655,5.244353,0.327726,-150.745941,0.033631,0.000000
35.200001,23.314987,-150.790421,-0.003691,0.001308,0.033215,103.710243,5.283252,0.332147,-150.790421,0.034013,0.000000
35.430000,23.338448,-150.790421,-0.003678,0.001319,0.033510,103.814598,5.288568,0.335099,-150.790421,0.034403,0.000000
35.660000,23.313499,-150.834900,-0.003669,0.001332,0.033831,103.703629,5.282915,0.338309,-150.834900,0.034785,0.000000
35.890003,23.852318,-150.923874,-0.003648,0.001350,0.034299,106.100410,5.405013,0.342987,-150.923874,0.035166,0.000000
36.120003,24.149475,-150.968353,-0.003648,0.001366,0.034707,107.422234,5.472350,0.347067,-150.968353,0.035548,0.000000
36.350002,24.132713,-150.968353,-0.003630,0.001377,0.034975,107.347672,5.468551,0.349755,-150.968353,0.035929,0.000000
36.580002,24.030685,-151.012833,-0.003630,0.001391,0.035322,106.893829,5.445431,0.353222,-151.012833,0.036320,0.000000
36.810001,24.816765,-150.968353,-0.003600,0.001411,0.035843,110.390480,5.623559,0.358430,-150.968353,0.036701,0.000000
37.040001,24.849533,-151.057312,-0.003583,0.001426,0.036215,110.536247,5.630985,0.362154,-151.057312,0.037083,0.000000
37.270000,24.946724,-151.146271,-0.003574,0.001441,0.036597,110.968567,5.653008,0.365969,-151.146271,0.037464,0.000000
37.500000,25.039444,-151.235229,-0.003566,0.001454,0.036927,111.381012,5.674019,0.369269,-151.235229,0.037846,0.000000
37.730003,25.062531,-151.146271,-0.003553,0.001467,0.037256,111.483704,5.679251,0.372562,-151.146271,0.038237,0.000000
37.960003,25.871696,-151.235229,-0.003531,0.001489,0.037829,115.083054,5.862610,0.378285,-151.235229,0.038618,0.000000
38.190002,25.829987,-151.235229,-0.003518,0.001502,0.038141,114.897522,5.853158,0.381411,-151.235229,0.039000,0.000000
38.420002,25.546616,-151.368683,-0.003518,0.001510,0.038358,113.637024,5.788946,0.383576,-151.368683,0.039381,0.000000
38.650002,26.333435,-151.324188,-0.003497,0.001534,0.038973,117.136971,5.967242,0.389731,-151.324188,0.039763,0.000000
38.880001,26.378494,-151.324188,-0.003471,0.001548,0.039311,117.337402,5.977452,0.393114,-151.324188,0.040152,0.000000
39.110001,26.610481,-151.413162,-0.003462,0.001564,0.039728,118.369331,6.030021,0.397278,-151.413162,0.040534,0.000000
39.340000,26.495422,-151.502121,-0.003436,0.001576,0.040040,117.857529,6.003949,0.400396,-151.502121,0.040916,0.000000
39.570004,26.685699,-151.502121,-0.003436,0.001590,0.040395,118.703918,6.047066,0.403954,-151.502121,0.041298,0.000000
39.800003,26.907639,-151.546600,-0.003428,0.001608,0.040838,119.691154,6.097358,0.408375,-151.546600,0.041679,0.000000
40.030003,27.149307,-151.502121,-0.003397,0.001622,0.041211,120.766151,6.152121,0.412107,-151.502121,0.042069,0.000000
40.260002,27.044296,-151.591080,-0.003397,0.001632,0.041454,120.299042,6.128325,0.414537,-151.591080,0.042451,0.000000
40.490002,27.793510,-151.635559,-0.003393,0.001655,0.042034,123.631706,6.298100,0.420343,-151.635559,0.042832,0.000000
40.720001,27.878784,-151.680038,-0.003363,0.001669,0.042390,124.011024,6.317423,0.423901,-151.680038,0.043214,0.000000
40.950001,28.089546,-151.680038,-0.003363,0.001687,0.042850,124.948540,6.365182,0.428496,-151.680038,0.043596,0.000000
41.180000,28.161415,-151.680038,-0.003341,0.001701,0.043197,125.268234,6.381468,0.431970,-151.680038,0.043986,0.000000
41.410004,27.984535,-151.680038,-0.003311,0.001710,0.043431,124.481430,6.341386,0.434309,-151.680038,0.044367,0.000000
41.640003,28.260834,-151.813492,-0.003303,0.001726,0.043830,125.710464,6.403996,0.438298,-151.813492,0.044749,0.000000
41.870003,28.544960,-151.857971,-0.003294,0.001743,0.044264,126.974327,6.468380,0.442636,-151.857971,0.045130,0.000000
42.100002,28.559853,-151.857971,-0.003303,0.001753,0.044532,127.040565,6.471755,0.445323,-151.857971,0.045512,0.000000
42.330002,28.764656,-151.857971,-0.003285,0.001769,0.044931,127.951584,6.518165,0.449312,-151.857971,0.045902,0.000000
42.560001,29.018242,-151.946930,-0.003281,0.001783,0.045287,129.079590,6.575628,0.452870,-151.946930,0.046284,0.000000
42.790001,29.695213,-151.946930,-0.003242,0.001804,0.045815,132.090912,6.729032,0.458154,-151.946930,0.046665,0.000000
43.020000,29.928696,-152.035889,-0.003238,0.001820,0.046232,133.129486,6.781940,0.462317,-152.035889,0.047047,0.000000
43.250004,29.754791,-152.035889,-0.003234,0.001831,0.046518,132.355927,6.742532,0.465179,-152.035889,0.047438,0.000000
43.480003,30.077644,-152.080368,-0.003216,0.001848,0.046943,133.792038,6.815691,0.469433,-152.080368,0.047819,0.000000
43.710003,30.487999,-152.124847,-0.003195,0.001865,0.047377,135.617386,6.908679,0.473770,-152.124847,0.048201,0.000000
43.940002,30.346870,-152.124847,-0.003186,0.001875,0.047637,134.989624,6.876699,0.476367,-152.124847,0.048582,0.000000
44.170002,30.363998,-152.213821,-0.003169,0.001887,0.047940,135.065811,6.880580,0.479402,-152.213821,0.048964,0.000000
44.400002,31.142624,-152.258301,-0.003156,0.001909,0.048495,138.529312,7.057020,0.484951,-152.258301,0.049354,0.000000
44.630001,31.552979,-152.258301,-0.003130,0.001927,0.048938,140.354660,7.150007,0.489379,-152.258301,0.049736,0.000000
44.860001,31.588356,-152.258301,-0.003117,0.001939,0.049250,140.512024,7.158024,0.492498,-152.258301,0.050117,0.000000
45.090004,31.720924,-152.302780,-0.003130,0.001953,0.049614,141.101715,7.188064,0.496139,-152.302780,0.050499,0.000000
45.320004,31.870987,-152.302780,-0.003100,0.001969,0.050022,141.769226,7.222069,0.500219,-152.302780,0.050880,0.000000
45.550003,32.218040,-152.347260,-0.003083,0.001985,0.050421,143.313004,7.300712,0.504209,-152.347260,0.051271,0.000000
45.780003,32.315231,-152.391739,-0.003074,0.001999,0.050768,143.745331,7.322736,0.507676,-152.391739,0.051652,0.000000
46.010002,32.518173,-152.436218,-0.003048,0.002012,0.051097,144.648056,7.368723,0.510968,-152.436218,0.052034,0.000000
46.240002,33.195518,-152.480698,-0.003048,0.002033,0.051635,147.661041,7.522212,0.516351,-152.480698,0.052415,0.000000
46.470001,33.487457,-152.525177,-0.003027,0.002049,0.052034,148.959656,7.588366,0.520340,-152.525177,0.052797,0.000000
46.700001,33.676994,-152.525177,-0.003027,0.002064,0.052415,149.802750,7.631316,0.524155,-152.525177,0.053187,0.000000
46.930004,33.584648,-152.614136,-0.003009,0.002076,0.052727,149.391983,7.610390,0.527274,-152.614136,0.053568,0.000000
47.160004,33.815887,-152.614136,-0.002979,0.002092,0.053126,150.420578,7.662790,0.531263,-152.614136,0.053951,0.000000
47.390003,34.221031,-152.658630,-0.002975,0.002108,0.053543,152.222748,7.754597,0.535426,-152.658630,0.054332,0.000000
47.620003,34.243004,-152.658630,-0.002966,0.002121,0.053881,152.320496,7.759575,0.538810,-152.658630,0.054714,0.000000
47.850002,34.367744,-152.747589,-0.002940,0.002133,0.054175,152.875366,7.787842,0.541755,-152.747589,0.055104,0.000000
48.080002,34.065376,-152.703110,-0.002940,0.002141,0.054375,151.530365,7.719325,0.543753,-152.703110,0.055485,0.000000
48.310001,35.235748,-152.747589,-0.002919,0.002164,0.054965,156.736435,7.984535,0.549650,-152.747589,0.055867,0.000000
48.540001,35.729141,-152.836548,-0.002893,0.002183,0.055450,158.931152,8.096339,0.554502,-152.836548,0.056248,0.000000
48.770000,36.008415,-152.881027,-0.002906,0.002197,0.055806,160.173431,8.159623,0.558060,-152.881027,0.056630,0.000000
49.000004,36.209869,-152.881027,-0.002884,0.002212,0.056197,161.069550,8.205274,0.561966,-152.881027,0.057020,0.000000
49.230003,36.173378,-152.881027,-0.002854,0.002227,0.056569,160.907227,8.197004,0.565690,-152.881027,0.057402,0.000000
49.460003,36.239662,-152.925507,-0.002846,0.002237,0.056829,161.202072,8.212025,0.568294,-152.925507,0.057783,0.000000
49.690002,36.722626,-153.014465,-0.002841,0.002255,0.057281,163.350403,8.321466,0.572806,-153.014465,0.058165,0.000000
49.920002,36.745712,-153.014465,-0.002833,0.002265,0.057540,163.453094,8.326697,0.575402,-153.014465,0.058546,0.000000
50.150002,36.895035,-153.058960,-0.002815,0.002284,0.058018,164.117310,8.360535,0.580179,-153.058960,0.058937,0.000000
50.380001,37.892998,-153.014465,-0.002802,0.002301,0.058451,168.556473,8.586676,0.584509,-153.014465,0.059318,0.000000
50.610001,38.722267,-153.147919,-0.002785,0.002321,0.058945,172.245239,8.774590,0.589452,-153.147919,0.059700,0.000000
50.840004,38.426231,-153.192398,-0.002764,0.002331,0.059215,170.928421,8.707508,0.592147,-153.192398,0.060081,0.000000
51.070004,38.604225,-153.236877,-0.002755,0.002345,0.059561,171.720169,8.747842,0.595614,-153.236877,0.060463,0.000000
51.300003,38.746475,-153.236877,-0.002759,0.002359,0.059908,172.352936,8.780077,0.599081,-153.236877,0.060854,0.000000
51.530003,39.308014,-153.192398,-0.002721,0.002376,0.060342,174.850784,8.907324,0.603418,-153.192398,0.061235,0.000000
51.760002,39.654686,-153.236877,-0.002725,0.002389,0.060689,176.392853,8.985880,0.606885,-153.236877,0.061617,0.000000
51.990002,39.501648,-153.281357,-0.002703,0.002399,0.060932,175.712112,8.951201,0.609315,-153.281357,0.061998,0.000000
52.220001,40.375977,-153.370316,-0.002690,0.002419,0.061443,179.601318,9.149326,0.614432,-153.370316,0.062389,0.000000
52.450001,40.930061,-153.414795,-0.002677,0.002438,0.061928,182.066010,9.274885,0.619285,-153.414795,0.062770,0.000000
52.680004,41.457718,-153.414795,-0.002677,0.002454,0.062327,184.413147,9.394453,0.623274,-153.414795,0.063152,0.000000
52.910004,41.564957,-153.459274,-0.002643,0.002466,0.062631,184.890167,9.418754,0.626309,-153.459274,0.063533,0.000000
53.140003,41.540009,-153.503769,-0.002639,0.002478,0.062944,184.779190,9.413101,0.629436,-153.503769,0.063915,0.000000
53.370003,42.114578,-153.548248,-0.002621,0.002498,0.063438,187.335007,9.543300,0.634379,-153.548248,0.064305,0.000000
53.600002,42.728249,-153.548248,-0.002608,0.002512,0.063794,190.064743,9.682360,0.637936,-153.548248,0.064687,0.000000
53.830002,42.510040,-153.548248,-0.002608,0.002520,0.064018,189.094101,9.632913,0.640185,-153.548248,0.065068,0.000000
54.060001,43.462196,-153.637207,-0.002578,0.002544,0.064608,193.329498,9.848674,0.646082,-153.637207,0.065450,0.000000
54.290001,43.878883,-153.681686,-0.002574,0.002558,0.064964,195.183014,9.943097,0.649639,-153.681686,0.065831,0.000000
54.520004,44.171570,-153.681686,-0.002570,0.002574,0.065389,196.484955,10.009420,0.653894,-153.681686,0.066221,0.000000
54.750004,44.726028,-153.726166,-0.002544,0.002588,0.065744,198.951309,10.135062,0.657444,-153.726166,0.066603,0.000000
54.980003,44.728638,-153.726166,-0.002548,0.002601,0.066074,198.962921,10.135654,0.660744,-153.726166,0.066985,0.000000
55.210003,45.236923,-153.726166,-0.002518,0.002617,0.066464,201.223877,10.250834,0.664643,-153.726166,0.067367,0.000000
55.440002,45.786171,-153.859604,-0.002509,0.002634,0.066906,203.667053,10.375295,0.669063,-153.859604,0.067748,0.000000
55.670002,46.155937,-153.859604,-0.002505,0.002648,0.067262,205.311859,10.459085,0.672621,-153.859604,0.068138,0.000000
55.900002,45.936989,-153.948578,-0.002492,0.002656,0.067453,204.337936,10.409471,0.674529,-153.948578,0.068519,0.000000
56.130001,47.041069,-153.948578,-0.002458,0.002681,0.068086,209.249130,10.659658,0.680857,-153.948578,0.068901,0.000000
56.360004,47.352371,-154.037537,-0.002449,0.002695,0.068441,210.633865,10.730201,0.684415,-154.037537,0.069283,0.000000
56.590004,47.761238,-154.037537,-0.002440,0.002709,0.068797,212.452591,10.822851,0.687973,-154.037537,0.069665,0.000000
56.820004,47.903114,-154.082016,-0.002427,0.002722,0.069127,213.083694,10.855000,0.691266,-154.082016,0.070055,0.000000
57.050003,48.062859,-154.037537,-0.002432,0.002735,0.069457,213.794266,10.891200,0.694566,-154.037537,0.070436,0.000000
57.280003,48.821381,-154.037537,-0.002406,0.002752,0.069907,217.168350,11.063084,0.699070,-154.037537,0.070818,0.000000
57.510002,49.198227,-154.126495,-0.002384,0.002766,0.070245,218.844650,11.148478,0.702454,-154.126495,0.071199,0.000000
57.740002,49.238068,-154.215454,-0.002371,0.002778,0.070549,219.021866,11.157506,0.705489,-154.215454,0.071581,0.000000
57.970001,50.183891,-154.215454,-0.002354,0.002800,0.071130,223.229095,11.371832,0.711303,-154.215454,0.071971,0.000000
58.200005,50.905922,-154.259933,-0.002367,0.002814,0.071485,226.440857,11.535447,0.714853,-154.259933,0.072353,0.000000
58.430004,51.104401,-154.304413,-0.002341,0.002827,0.071798,227.323730,11.580423,0.717979,-154.304413,0.072734,0.000000
58.660004,51.667801,-154.259933,-0.002328,0.002843,0.072214,229.829865,11.708091,0.722143,-154.259933,0.073116,0.000000
58.890003,51.815254,-154.437866,-0.002311,0.002855,0.072509,230.485764,11.741504,0.725087,-154.437866,0.073497,0.000000
59.120003,52.268806,-154.393387,-0.002311,0.002870,0.072890,232.503265,11.844280,0.728903,-154.393387,0.073888,0.000000
59.350002,53.294693,-154.437866,-0.002289,0.002890,0.073402,237.066635,12.076750,0.734020,-154.437866,0.074269,0.000000
59.580002,53.470451,-154.393387,-0.002272,0.002900,0.073671,237.848450,12.116578,0.736707,-154.393387,0.074651,0.000000
59.810001,53.359482,-154.482346,-0.002272,0.002912,0.073966,237.354828,12.091432,0.739659,-154.482346,0.075033,0.000000
60.040005,54.904083,-154.571304,-0.002264,0.002936,0.074573,244.225555,12.441443,0.745730,-154.571304,0.075414,0.000000
60.270004,55.271622,-154.571304,-0.002255,0.002950,0.074929,245.860458,12.524729,0.749288,-154.571304,0.075805,0.000000
60.500004,55.739693,-154.571304,-0.002233,0.002964,0.075276,247.942535,12.630795,0.752755,-154.571304,0.076186,0.000000
60.730003,55.883797,-154.571304,-0.002207,0.002976,0.075596,248.583542,12.663449,0.755965,-154.571304,0.076568,0.000000
60.960003,56.378311,-154.660263,-0.002190,0.002991,0.075969,250.783249,12.775508,0.759689,-154.660263,0.076949,0.000000
61.190002,56.985649,-154.660263,-0.002199,0.003007,0.076385,253.484833,12.913133,0.763852,-154.660263,0.077339,0.000000
61.420002,57.634323,-154.749222,-0.002186,0.003023,0.076793,256.370270,13.060124,0.767932,-154.749222,0.077721,0.000000
61.650002,57.733742,-154.749222,-0.002182,0.003033,0.077027,256.812500,13.082653,0.770272,-154.749222,0.078103,0.000000
61.880001,59.037796,-154.749222,-0.002156,0.003054,0.077582,262.613220,13.378156,0.775820,-154.749222,0.078484,0.000000
62.110004,59.563957,-154.793716,-0.002139,0.003072,0.078025,264.953705,13.497386,0.780249,-154.793716,0.078866,0.000000
62.340004,60.149323,-154.882675,-0.002126,0.003085,0.078372,267.557556,13.630032,0.783715,-154.882675,0.079256,0.000000
62.570004,60.803207,-154.927155,-0.002130,0.003103,0.078814,270.466187,13.778204,0.788136,-154.927155,0.079637,0.000000
62.800003,60.599525,-154.927155,-0.002104,0.003112,0.079039,269.560150,13.732048,0.790392,-154.927155,0.080019,0.000000
63.030003,61.141327,-154.882675,-0.002091,0.003125,0.079386,271.970215,13.854823,0.793859,-154.882675,0.080401,0.000000
63.260002,61.969856,-154.971634,-0.002082,0.003143,0.079837,275.655701,14.042570,0.798371,-154.971634,0.080783,0.000000
63.490002,62.144493,-155.060593,-0.002061,0.003152,0.080071,276.432526,14.082143,0.800710,-155.060593,0.081172,0.000000
63.720001,62.786095,-155.060593,-0.002065,0.003170,0.080513,279.286499,14.227532,0.805130,-155.060593,0.081554,0.000000
63.950005,63.555038,-155.105072,-0.002039,0.003191,0.081042,282.706940,14.401777,0.810422,-155.105072,0.081935,0.000000
64.180000,64.596191,-155.105072,-0.002026,0.003206,0.081424,287.338196,14.637707,0.814237,-155.105072,0.082317,0.000000
64.410004,65.266846,-155.149551,-0.002022,0.003222,0.081832,290.321442,14.789679,0.818317,-155.149551,0.082699,0.000000
64.639999,65.488403,-155.194031,-0.001992,0.003235,0.082178,291.306976,14.839885,0.821784,-155.194031,0.083089,0.000000
64.870003,66.173187,-155.283005,-0.002001,0.003248,0.082499,294.353027,14.995058,0.824994,-155.283005,0.083471,0.000000
65.100006,66.961136,-155.194031,-0.001983,0.003266,0.082959,297.858002,15.173611,0.829588,-155.194031,0.083852,0.000000
65.330002,67.109711,-155.283005,-0.001962,0.003276,0.083210,298.518890,15.207277,0.832102,-155.283005,0.084234,0.000000
65.560005,67.480225,-155.283005,-0.001940,0.003285,0.083427,300.167023,15.291238,0.834274,-155.283005,0.084598,0.000000
65.790001,66.368317,-155.371964,-0.001944,0.003280,0.083315,295.221008,15.039275,0.833146,-155.371964,0.083540,0.000000
66.020004,65.392700,-155.371964,-0.001953,0.003279,0.083280,290.881256,14.818198,0.832798,-155.371964,0.083315,0.000000
66.250000,64.470703,-155.416443,-0.001923,0.003277,0.083245,286.779999,14.609270,0.832450,-155.416443,0.083315,0.000000
66.480003,63.601959,-155.460922,-0.001927,0.003277,0.083228,282.915649,14.412410,0.832276,-155.460922,0.083315,0.000000
66.710007,62.790192,-155.460922,-0.001910,0.003277,0.083228,279.304718,14.228460,0.832276,-155.460922,0.083315,0.000000
66.940002,62.055496,-155.549881,-0.001906,0.003276,0.083219,276.036621,14.061976,0.832192,-155.549881,0.083315,0.000000
67.170006,61.365868,-155.594360,-0.001888,0.003276,0.083219,272.969025,13.905704,0.832192,-155.594360,0.083315,0.000000
67.400002,60.717567,-155.594360,-0.001901,0.003276,0.083219,270.085236,13.758797,0.832192,-155.594360,0.083315,0.000000
67.630005,60.104271,-155.638855,-0.001884,0.003276,0.083219,267.357147,13.619823,0.832192,-155.638855,0.083315,0.000000
67.860001,59.519646,-155.683334,-0.001884,0.003276,0.083210,264.756592,13.487345,0.832102,-155.683334,0.083315,0.000000
68.090004,58.990501,-155.727814,-0.001880,0.003276,0.083210,262.402863,13.367438,0.832102,-155.727814,0.083315,0.000000
68.320000,58.490402,-155.772293,-0.001871,0.003276,0.083210,260.178314,13.254114,0.832102,-155.772293,0.083315,0.000000
68.550003,57.999619,-155.772293,-0.001863,0.003276,0.083210,257.995178,13.142901,0.832102,-155.772293,0.083315,0.000000
68.780006,57.545700,-155.772293,-0.001850,0.003276,0.083210,255.976059,13.040042,0.832102,-155.772293,0.083315,0.000000
69.010002,57.105179,-155.772293,-0.001871,0.003276,0.083210,254.016525,12.940218,0.832102,-155.772293,0.083315,0.000000
69.240005,56.706741,-155.905731,-0.001863,0.003276,0.083210,252.244186,12.849931,0.832102,-155.905731,0.083315,0.000000
69.470001,56.326920,-155.950211,-0.001854,0.003276,0.083210,250.554657,12.763862,0.832102,-155.950211,0.083315,0.000000
69.700005,55.974281,-155.905731,-0.001854,0.003276,0.083210,248.986038,12.683953,0.832102,-155.905731,0.083315,0.000000
69.930000,55.608246,-155.905731,-0.001850,0.003276,0.083202,247.357834,12.601009,0.832018,-155.905731,0.083315,0.000000
70.160004,55.285393,-156.039169,-0.001837,0.003276,0.083202,245.921707,12.527849,0.832018,-156.039169,0.083315,0.000000
70.390007,54.968132,-156.083664,-0.001841,0.003276,0.083202,244.510468,12.455956,0.832018,-156.083664,0.083315,0.000000
70.620003,54.666138,-156.083664,-0.001832,0.003276,0.083202,243.167130,12.387524,0.832018,-156.083664,0.083315,0.000000
70.850006,54.382767,-156.083664,-0.001854,0.003276,0.083202,241.906631,12.323311,0.832018,-156.083664,0.083315,0.000000
71.080002,54.122101,-156.172623,-0.001845,0.003276,0.083202,240.747131,12.264243,0.832018,-156.172623,0.083315,0.000000
71.310005,53.837242,-156.172623,-0.001824,0.003276,0.083202,239.480011,12.199693,0.832018,-156.172623,0.083315,0.000000
71.540001,53.574715,-156.217102,-0.001832,0.003276,0.083202,238.312241,12.140204,0.832018,-156.217102,0.083315,0.000000
71.770004,53.333794,-156.217102,-0.001828,0.003276,0.083202,237.240570,12.085610,0.832018,-156.217102,0.083315,0.000000
72.000000,53.105156,-156.306061,-0.001837,0.003276,0.083202,236.223526,12.033801,0.832018,-156.306061,0.083315,0.000000
72.230003,52.888062,-156.261581,-0.001828,0.003276,0.083202,235.257843,11.984606,0.832018,-156.261581,0.083315,0.000000
72.460007,52.660912,-156.306061,-0.001815,0.003276,0.083202,234.247437,11.933133,0.832018,-156.306061,0.083315,0.000000
72.690002,52.444565,-156.395020,-0.001824,0.003276,0.083202,233.285080,11.884109,0.832018,-156.395020,0.083315,0.000000
72.920006,52.247581,-156.439499,-0.001832,0.003276,0.083202,232.408844,11.839471,0.832018,-156.439499,0.083315,0.000000
73.150002,52.070702,-156.439499,-0.001824,0.003276,0.083202,231.622055,11.799390,0.832018,-156.439499,0.083315,0.000000
73.380005,51.880791,-156.439499,-0.001815,0.003276,0.083202,230.777283,11.756355,0.832018,-156.439499,0.083315,0.000000
73.610001,51.701683,-156.572952,-0.001807,0.003276,0.083202,229.980576,11.715769,0.832018,-156.572952,0.083315,0.000000
73.840004,51.517731,-156.528473,-0.001811,0.003276,0.083202,229.162308,11.674085,0.832018,-156.528473,0.083315,0.000000
74.070007,51.350533,-156.572952,-0.001824,0.003276,0.083202,228.418579,11.636197,0.832018,-156.572952,0.083315,0.000000
74.300003,51.192650,-156.572952,-0.001819,0.003276,0.083202,227.716278,11.600420,0.832018,-156.572952,0.083315,0.000000
74.530006,51.039230,-156.617432,-0.001807,0.003276,0.083202,227.033829,11.565655,0.832018,-156.617432,0.083315,0.000000
74.760002,50.887306,-156.661911,-0.001802,0.003276,0.083202,226.358047,11.531229,0.832018,-156.661911,0.083315,0.000000
74.990005,50.740219,-156.706390,-0.001798,0.003276,0.083202,225.703766,11.497898,0.832018,-156.706390,0.083315,0.000000
75.220001,50.594620,-156.795349,-0.001802,0.003276,0.083202,225.056107,11.464905,0.832018,-156.795349,0.083315,0.000000
75.450005,50.446045,-156.750870,-0.001802,0.003276,0.083202,224.395218,11.431237,0.832018,-156.750870,0.083315,0.000000
75.680000,50.316086,-156.795349,-0.001815,0.003276,0.083202,223.817123,11.401788,0.832018,-156.795349,0.083315,0.000000
75.910004,50.182777,-156.839828,-0.001802,0.003276,0.083202,223.224136,11.371579,0.832018,-156.839828,0.083315,0.000000
76.140007,50.058029,-156.884308,-0.001798,0.003276,0.083202,222.669235,11.343311,0.832018,-156.884308,0.083315,0.000000
76.370003,49.937752,-156.973282,-0.001802,0.003276,0.083202,222.134216,11.316056,0.832018,-156.973282,0.083315,0.000000
76.600006,49.807800,-156.884308,-0.001802,0.003276,0.083202,221.556168,11.286609,0.832018,-156.884308,0.083315,0.000000
76.830002,49.691246,-156.928802,-0.001789,0.003276,0.083202,221.037704,11.260198,0.832018,-156.928802,0.083315,0.000000
77.060005,49.579903,-156.928802,-0.001781,0.003276,0.083202,220.542419,11.234966,0.832018,-156.928802,0.083315,0.000000
77.290001,49.478622,-157.017761,-0.001794,0.003276,0.083202,220.091904,11.212016,0.832018,-157.017761,0.083315,0.000000
77.520004,49.355736,-157.106720,-0.001811,0.003276,0.083202,219.545273,11.184170,0.832018,-157.106720,0.083315,0.000000
77.750000,49.243652,-157.106720,-0.001802,0.003276,0.083202,219.046707,11.158772,0.832018,-157.106720,0.083315,0.000000
77.980003,49.140877,-157.151199,-0.001807,0.003276,0.083202,218.589539,11.135482,0.832018,-157.151199,0.083315,0.000000
78.210007,49.052254,-157.195679,-0.001781,0.003276,0.083202,218.195328,11.115399,0.832018,-157.195679,0.083315,0.000000
78.440002,48.942406,-157.240158,-0.001794,0.003276,0.083202,217.706696,11.090508,0.832018,-157.240158,0.083315,0.000000
78.670006,48.851913,-157.240158,-0.001794,0.003276,0.083202,217.304169,11.070002,0.832018,-157.240158,0.083315,0.000000
78.900002,48.759941,-157.284637,-0.001802,0.003276,0.083202,216.895050,11.049161,0.832018,-157.284637,0.083315,0.000000
79.130005,48.662010,-157.329117,-0.001794,0.003276,0.083202,216.459427,11.026969,0.832018,-157.329117,0.083315,0.000000
79.360001,48.569656,-157.373611,-0.001781,0.003276,0.083202,216.048615,11.006042,0.832018,-157.373611,0.083315,0.000000
79.590004,48.482147,-157.373611,-0.001781,0.003276,0.083202,215.659363,10.986212,0.832018,-157.373611,0.083315,0.000000
79.820007,48.392036,-157.462570,-0.001798,0.003276,0.083202,215.258530,10.965793,0.832018,-157.462570,0.083315,0.000000
80.050003,48.301926,-157.462570,-0.001789,0.003276,0.083202,214.857697,10.945373,0.832018,-157.462570,0.083315,0.000000
80.280006,48.224472,-157.418091,-0.001785,0.003276,0.083202,214.513168,10.927821,0.832018,-157.418091,0.083315,0.000000
80.510002,48.140312,-157.462570,-0.001781,0.003276,0.083202,214.138809,10.908751,0.832018,-157.462570,0.083315,0.000000
80.740005,48.062119,-157.551529,-0.001798,0.003276,0.083202,213.790985,10.891032,0.832018,-157.551529,0.083315,0.000000
80.970001,47.982796,-157.640488,-0.001798,0.003276,0.083202,213.438141,10.873056,0.832018,-157.640488,0.083315,0.000000
81.200005,47.913162,-157.596008,-0.001789,0.003276,0.083202,213.128387,10.857278,0.832018,-157.596008,0.083315,0.000000
81.430000,47.833481,-157.596008,-0.001789,0.003276,0.083202,212.773956,10.839221,0.832018,-157.596008,0.083315,0.000000
81.660004,47.754532,-157.640488,-0.001776,0.003276,0.083202,212.422760,10.821332,0.832018,-157.640488,0.083315,0.000000
81.890007,47.691978,-157.729446,-0.001785,0.003276,0.083202,212.144516,10.807157,0.832018,-157.729446,0.083315,0.000000
82.120003,47.616386,-157.773926,-0.001798,0.003276,0.083202,211.808258,10.790028,0.832018,-157.773926,0.083315,0.000000
82.350006,47.546379,-157.729446,-0.001785,0.003276,0.083202,211.496857,10.774163,0.832018,-157.729446,0.083315,0.000000
82.580002,47.465576,-157.773926,-0.001772,0.003276,0.083202,211.137421,10.755854,0.832018,-157.773926,0.083315,0.000000
82.810005,47.402267,-157.818420,-0.001781,0.003276,0.083202,210.855820,10.741508,0.832018,-157.818420,0.083315,0.000000
83.040001,47.341949,-157.951859,-0.001776,0.003276,0.083202,210.587509,10.727839,0.832018,-157.951859,0.083315,0.000000
83.270004,47.269707,-157.907379,-0.001763,0.003276,0.083202,210.266159,10.711469,0.832018,-157.907379,0.083315,0.000000
83.500008,47.211617,-157.951859,-0.001781,0.003276,0.083202,210.007751,10.698305,0.832018,-157.951859,0.083315,0.000000
83.730003,47.137138,-157.951859,-0.001768,0.003276,0.083202,209.676468,10.681429,0.832018,-157.951859,0.083315,0.000000
83.960007,47.061180,-157.996338,-0.001763,0.003276,0.083202,209.338577,10.664216,0.832018,-157.996338,0.083315,0.000000
84.190002,47.017982,-158.040817,-0.001768,0.003276,0.083202,209.146439,10.654427,0.832018,-158.040817,0.083315,0.000000
84.420006,46.956543,-158.085297,-0.001781,0.003276,0.083202,208.873138,10.640505,0.832018,-158.085297,0.083315,0.000000
84.650002,46.891373,-158.085297,-0.001789,0.003276,0.083202,208.583237,10.625737,0.832018,-158.085297,0.083315,0.000000
84.880005,46.826210,-158.129776,-0.001763,0.003276,0.083202,208.293381,10.610971,0.832018,-158.129776,0.083315,0.000000
85.110001,46.774826,-158.218750,-0.001763,0.003276,0.083202,208.064819,10.599327,0.832018,-158.218750,0.083315,0.000000
85.340004,46.716362,-158.263229,-0.001776,0.003276,0.083202,207.804764,10.586079,0.832018,-158.263229,0.083315,0.000000
85.570007,46.667953,-158.263229,-0.001781,0.003276,0.083202,207.589432,10.575109,0.832018,-158.263229,0.083315,0.000000
85.800003,46.608002,-158.307709,-0.001776,0.003276,0.083202,207.322739,10.561524,0.832018,-158.307709,0.083315,0.000000
86.030006,46.546188,-158.263229,-0.001772,0.003276,0.083202,207.047791,10.547518,0.832018,-158.263229,0.083315,0.000000
86.260002,46.495171,-158.441147,-0.001776,0.003276,0.083202,206.820847,10.535956,0.832018,-158.441147,0.083315,0.000000
86.490005,46.450485,-158.485626,-0.001776,0.003276,0.083202,206.622070,10.525830,0.832018,-158.485626,0.083315,0.000000
86.720001,46.397240,-158.485626,-0.001772,0.003276,0.083202,206.385223,10.513764,0.832018,-158.485626,0.083315,0.000000
86.950005,46.336540,-158.441147,-0.001781,0.003276,0.083202,206.115219,10.500010,0.832018,-158.441147,0.083315,0.000000
87.180008,46.287758,-158.485626,-0.001755,0.003276,0.083202,205.898224,10.488956,0.832018,-158.485626,0.083315,0.000000
87.410004,46.245308,-158.485626,-0.001768,0.003276,0.083202,205.709396,10.479337,0.832018,-158.485626,0.083315,0.000000
87.640007,46.210678,-158.574585,-0.001759,0.003276,0.083202,205.555359,10.471489,0.832018,-158.574585,0.083315,0.000000
87.870003,46.148117,-158.619064,-0.001768,0.003276,0.083202,205.277084,10.457313,0.832018,-158.619064,0.083315,0.000000
88.100006,46.081841,-158.619064,-0.001772,0.003276,0.083202,204.982269,10.442294,0.832018,-158.619064,0.083315,0.000000
88.330002,46.040878,-158.619064,-0.001772,0.003276,0.083202,204.800049,10.433012,0.832018,-158.619064,0.083315,0.000000
88.560005,46.004013,-158.619064,-0.001768,0.003276,0.083202,204.636078,10.424659,0.832018,-158.619064,0.083315,0.000000
88.790001,45.950760,-158.708038,-0.001759,0.003276,0.083202,204.399185,10.412592,0.832018,-158.708038,0.083315,0.000000
89.020004,45.918365,-158.708038,-0.001759,0.003276,0.083202,204.255096,10.405251,0.832018,-158.708038,0.083315,0.000000
89.250008,45.863998,-158.708038,-0.001776,0.003276,0.083202,204.013260,10.392930,0.832018,-158.708038,0.083315,0.000000
89.480003,45.831978,-158.752518,-0.001772,0.003276,0.083202,203.870819,10.385674,0.832018,-158.752518,0.083315,0.000000
89.710007,45.781334,-158.796997,-0.001763,0.003276,0.083202,203.645538,10.374199,0.832018,-158.796997,0.083315,0.000000
89.940002,45.724731,-158.885956,-0.001776,0.003276,0.083202,203.393768,10.361372,0.832018,-158.885956,0.083315,0.000000
90.170006,45.700157,-158.930435,-0.001755,0.003276,0.083202,203.284454,10.355804,0.832018,-158.930435,0.083315,0.000000
90.400002,45.655846,-158.930435,-0.001759,0.003276,0.083202,203.087341,10.345762,0.832018,-158.930435,0.083315,0.000000
90.630005,45.606689,-158.930435,-0.001759,0.003276,0.083202,202.868683,10.334623,0.832018,-158.930435,0.083315,0.000000
90.860001,45.567963,-159.019394,-0.001768,0.003276,0.083202,202.696426,10.325848,0.832018,-159.019394,0.083315,0.000000
91.090004,45.525887,-159.063889,-0.001763,0.003276,0.083202,202.509262,10.316313,0.832018,-159.063889,0.083315,0.000000
91.320007,45.491997,-159.063889,-0.001763,0.003276,0.083202,202.358505,10.308634,0.832018,-159.063889,0.083315,0.000000
91.550003,45.454765,-158.974915,-0.001763,0.003276,0.083202,202.192902,10.300197,0.832018,-158.974915,0.083315,0.000000
91.780006,45.417152,-159.063889,-0.001763,0.003276,0.083202,202.025589,10.291675,0.832018,-159.063889,0.083315,0.000000
92.010002,45.368370,-159.197327,-0.001755,0.003276,0.083202,201.808594,10.280620,0.832018,-159.197327,0.083315,0.000000
92.240005,45.322945,-159.197327,-0.001755,0.003276,0.083202,201.606522,10.270327,0.832018,-159.197327,0.083315,0.000000
92.470001,45.295387,-159.197327,-0.001750,0.003276,0.083202,201.483948,10.264081,0.832018,-159.197327,0.083315,0.000000
92.700005,45.259636,-159.286285,-0.001772,0.003276,0.083202,201.324921,10.255980,0.832018,-159.286285,0.083315,0.000000
92.930008,45.220909,-159.241806,-0.001763,0.003276,0.083202,201.152649,10.247205,0.832018,-159.241806,0.083315,0.000000
93.160004,45.195221,-159.330765,-0.001750,0.003276,0.083202,201.038376,10.241384,0.832018,-159.330765,0.083315,0.000000
93.390007,45.171013,-159.375244,-0.001746,0.003276,0.083202,200.930695,10.235897,0.832018,-159.375244,0.083315,0.000000
93.620003,45.119629,-159.419724,-0.001755,0.003276,0.083202,200.702133,10.224255,0.832018,-159.419724,0.083315,0.000000
93.850006,45.076805,-159.375244,-0.001763,0.003276,0.083202,200.511642,10.214550,0.832018,-159.375244,0.083315,0.000000
94.080002,45.061913,-159.375244,-0.001755,0.003276,0.083202,200.445404,10.211175,0.832018,-159.375244,0.083315,0.000000
94.310005,45.026909,-159.464203,-0.001755,0.003276,0.083202,200.289688,10.203243,0.832018,-159.464203,0.083315,0.000000
94.540001,44.987808,-159.508698,-0.001746,0.003276,0.083202,200.115768,10.194383,0.832018,-159.508698,0.083315,0.000000
94.770004,44.940887,-159.553177,-0.001763,0.003276,0.083202,199.907059,10.183751,0.832018,-159.553177,0.083315,0.000000
95.000008,44.915565,-159.553177,-0.001763,0.003276,0.083202,199.794418,10.178013,0.832018,-159.553177,0.083315,0.000000
95.230003,44.882057,-159.642136,-0.001755,0.003276,0.083202,199.645355,10.170420,0.832018,-159.642136,0.083315,0.000000
95.460007,44.846680,-159.642136,-0.001750,0.003276,0.083202,199.487991,10.162403,0.832018,-159.642136,0.083315,0.000000
95.690002,44.820610,-159.686615,-0.001750,0.003276,0.083202,199.372025,10.156496,0.832018,-159.686615,0.083315,0.000000
95.920006,44.800133,-159.775574,-0.001759,0.003276,0.083202,199.280945,10.151855,0.832018,-159.775574,0.083315,0.000000
96.000008,44.781143,-159.686615,-0.001768,0.003276,0.083202,199.196472,10.147552,0.832018,-159.686615,0.083315,0.000000