File: Data/compression 10/AutoHeating-17-10-6-240424_04242024_232735.csv
Time (sec),S:Load (lbs),S:HL1 (DIM),S:LVDT (in),S:Position (in),Ch:Position (mm),Ch:Load (N),Ch:Stress (MPa),Ch:Strain (mm/mm),Ch:HL1 (DIM),Set Point (),Cycles ()
0.110000,-0.003349,-112.358879,-0.008985,-0.000000,-0.000000,-0.014898,-0.000759,-0.000000,-112.358879,0.000165,0.000000
0.340000,-0.004471,-112.447845,-0.008964,-0.000000,-0.000000,-0.019887,-0.001013,-0.000000,-112.447845,0.000165,0.000000
0.570000,0.004471,-112.403366,-0.008981,0.000101,0.002567,0.019887,0.001013,0.025670,-112.403366,0.003269,0.000000
0.800000,-0.016014,-112.403366,-0.008882,0.000243,0.006183,-0.071234,-0.003629,0.061833,-112.403366,0.007085,0.000000
1.030000,-0.076340,-112.447845,-0.008735,0.000389,0.009878,-0.339576,-0.017299,0.098777,-112.447845,0.010918,0.000000
1.260000,-0.046921,-112.492325,-0.008589,0.000535,0.013589,-0.208714,-0.010632,0.135894,-112.492325,0.014752,0.000000
1.490000,-0.007446,-112.536804,-0.008425,0.000690,0.017518,-0.033123,-0.001687,0.175180,-112.536804,0.018585,0.000000
1.720000,0.037239,-112.536804,-0.008282,0.000836,0.021247,0.165648,0.008438,0.212470,-112.536804,0.022418,0.000000
1.950000,0.041328,-112.536804,-0.008114,0.000992,0.025193,0.183838,0.009365,0.251929,-112.536804,0.026251,0.000000
2.180000,0.021965,-112.536804,-0.007968,0.001147,0.029130,0.097705,0.004977,0.291301,-112.536804,0.030084,0.000000
2.410000,-0.030533,-112.670250,-0.007821,0.001295,0.032894,-0.135817,-0.006919,0.328939,-112.670250,0.033917,0.000000
2.640000,-0.010056,-112.670250,-0.007683,0.001440,0.036580,-0.044729,-0.002279,0.365796,-112.670250,0.037750,0.000000
2.870000,0.001488,-112.625771,-0.007502,0.001594,0.040482,0.006618,0.000337,0.404821,-112.625771,0.041583,0.000000
3.100000,-0.019737,-112.670250,-0.007360,0.001744,0.044307,-0.087796,-0.004473,0.443066,-112.670250,0.045417,0.000000
3.330000,-0.024208,-112.670250,-0.007213,0.001898,0.048218,-0.107683,-0.005486,0.482178,-112.670250,0.049250,0.000000
3.560000,-0.019363,-112.714729,-0.007054,0.002047,0.051990,-0.086133,-0.004388,0.519902,-112.714729,0.053083,0.000000
3.790000,-0.010803,-112.759209,-0.006898,0.002196,0.055771,-0.048055,-0.002448,0.557713,-112.759209,0.056899,0.000000
4.020000,0.011543,-112.714729,-0.006752,0.002353,0.059769,0.051347,0.002616,0.597692,-112.714729,0.060732,0.000000
4.250000,0.019737,-112.759209,-0.006601,0.002498,0.063438,0.087796,0.004473,0.634376,-112.759209,0.064565,0.000000
4.480000,0.021225,-112.759209,-0.006446,0.002654,0.067418,0.094413,0.004810,0.674181,-112.759209,0.068398,0.000000
4.710000,-0.019363,-112.803696,-0.006278,0.002802,0.071182,-0.086133,-0.004388,0.711819,-112.803696,0.072231,0.000000
4.940000,-0.034256,-112.892654,-0.006140,0.002949,0.074894,-0.152378,-0.007763,0.748936,-112.892654,0.076064,0.000000
5.170000,-0.005211,-112.848175,-0.005993,0.003104,0.078831,-0.023179,-0.001181,0.788308,-112.848175,0.079898,0.000000
5.400000,0.019363,-112.803696,-0.005842,0.003249,0.082517,0.086133,0.004388,0.825165,-112.803696,0.083731,0.000000
5.630000,0.030533,-112.803696,-0.005696,0.003404,0.086471,0.135817,0.006919,0.864711,-112.803696,0.087564,0.000000
5.860000,0.011543,-112.937134,-0.005527,0.003558,0.090374,0.051347,0.002616,0.903736,-112.937134,0.091397,0.000000
6.090000,-0.017502,-112.981613,-0.005385,0.003708,0.094181,-0.077852,-0.003966,0.941807,-112.981613,0.095230,0.000000
6.320000,0.013031,-112.981613,-0.005230,0.003858,0.097997,0.057965,0.002953,0.979965,-112.981613,0.099063,0.000000
6.550000,0.030907,-112.981613,-0.005066,0.004010,0.101856,0.137480,0.007004,1.018557,-112.981613,0.102896,0.000000
6.780000,0.042450,-112.981613,-0.004941,0.004159,0.105645,0.188827,0.009619,1.056454,-112.981613,0.106712,0.000000
7.010000,0.375351,-113.070580,-0.004773,0.004311,0.109496,1.669644,0.085056,1.094959,-113.070580,0.110545,0.000000
7.240000,0.654259,-113.070580,-0.004730,-0.000000,-0.000009,2.910288,0.148257,-0.000087,-113.070580,0.000217,0.000000
7.470000,0.627449,-113.070580,-0.004734,-0.000000,-0.000009,2.791033,0.142182,-0.000087,-113.070580,0.000217,0.000000
7.700000,0.710487,-113.070580,-0.004743,-0.000000,-0.000009,3.160406,0.160999,-0.000087,-113.070580,0.000399,0.000000
7.930000,0.657234,-113.115059,-0.004725,-0.000000,-0.000009,2.923524,0.148931,-0.000087,-113.115059,0.000781,0.000000
8.160001,0.675484,-113.115059,-0.004730,-0.000000,-0.000000,3.004702,0.153067,-0.000000,-113.115059,0.001162,0.000000
8.390000,0.630798,-113.204018,-0.004738,0.000000,0.000009,2.805931,0.142941,0.000087,-113.204018,0.001544,0.000000
8.620001,1.311493,-113.248505,-0.004708,0.000044,0.001110,5.833812,0.297189,0.011101,-113.248505,0.001934,0.000000
8.850000,1.409798,-113.159538,-0.004700,0.000050,0.001275,6.271093,0.319465,0.012748,-113.159538,0.002315,0.000000
9.080001,1.720734,-113.159538,-0.004687,0.000069,0.001760,7.654205,0.389924,0.017605,-113.159538,0.002697,0.000000
9.310000,2.112465,-113.248505,-0.004682,0.000090,0.002281,9.396713,0.478691,0.022808,-113.248505,0.003079,0.000000
9.540001,2.405525,-113.337463,-0.004652,0.000104,0.002645,10.700311,0.545100,0.026450,-113.337463,0.003460,0.000000
9.770000,2.627831,-113.292984,-0.004644,0.000118,0.002992,11.689174,0.595475,0.029919,-113.292984,0.003850,0.000000
10.000000,2.823700,-113.248505,-0.004652,0.000129,0.003269,12.560445,0.639860,0.032694,-113.248505,0.004232,0.000000
10.230000,3.266075,-113.248505,-0.004631,0.000146,0.003703,14.528228,0.740103,0.037031,-113.248505,0.004614,0.000000
10.460000,3.738991,-113.381943,-0.004592,0.000165,0.004197,16.631861,0.847267,0.041974,-113.381943,0.004995,0.000000
10.690001,3.915497,-113.381943,-0.004596,0.000177,0.004501,17.417000,0.887264,0.045009,-113.381943,0.005377,0.000000
10.920000,4.179138,-113.381943,-0.004583,0.000189,0.004804,18.589735,0.947006,0.048044,-113.381943,0.005767,0.000000
11.150001,4.635292,-113.426422,-0.004579,0.000206,0.005238,20.618809,1.050372,0.052380,-113.426422,0.006149,0.000000
11.380000,5.006546,-113.381943,-0.004553,0.000224,0.005689,22.270229,1.134500,0.056890,-113.381943,0.006530,0.000000
11.610001,5.327156,-113.470909,-0.004540,0.000239,0.006079,23.696373,1.207151,0.060793,-113.470909,0.006912,0.000000
11.840000,5.520050,-113.470909,-0.004531,0.000252,0.006391,24.554409,1.250861,0.063915,-113.470909,0.007302,0.000000
12.070001,5.821297,-113.515388,-0.004523,0.000266,0.006756,25.894421,1.319125,0.067557,-113.515388,0.007684,0.000000
12.300000,6.208565,-113.559868,-0.004514,0.000281,0.007129,27.617075,1.406881,0.071286,-113.559868,0.008065,0.000000
12.530001,6.512047,-113.470909,-0.004497,0.000294,0.007458,28.967031,1.475651,0.074581,-113.470909,0.008447,0.000000
12.760000,6.779037,-113.604347,-0.004488,0.000307,0.007805,30.154665,1.536152,0.078050,-113.604347,0.008828,0.000000
12.990001,7.299614,-113.604347,-0.004488,0.000328,0.008334,32.470306,1.654116,0.083340,-113.604347,0.009219,0.000000
13.220000,7.657097,-113.648827,-0.004467,0.000343,0.008724,34.060467,1.735123,0.087243,-113.648827,0.009600,0.000000
13.450001,7.972496,-113.604347,-0.004445,0.000359,0.009123,35.463432,1.806593,0.091232,-113.604347,0.009982,0.000000
13.680000,8.172455,-113.604347,-0.004424,0.000374,0.009496,36.352894,1.851905,0.094961,-113.604347,0.010363,0.000000
13.910001,8.481529,-113.604347,-0.004437,0.000388,0.009843,37.727726,1.921942,0.098430,-113.604347,0.010745,0.000000
14.140000,8.708672,-113.693314,-0.004406,0.000401,0.010190,38.738106,1.973413,0.101899,-113.693314,0.011135,0.000000
14.370001,9.021095,-113.782272,-0.004406,0.000415,0.010537,40.127834,2.044209,0.105368,-113.782272,0.011517,0.000000
14.600000,9.435173,-113.737793,-0.004398,0.000431,0.010936,41.969746,2.138041,0.109357,-113.737793,0.011898,0.000000
14.830001,9.610931,-113.782272,-0.004389,0.000442,0.011222,42.751556,2.177868,0.112219,-113.782272,0.012280,0.000000
15.060000,10.175446,-113.737793,-0.004359,0.000465,0.011820,45.262642,2.305789,0.118203,-113.737793,0.012661,0.000000
15.290001,10.497551,-113.782272,-0.004350,0.000481,0.012228,46.695438,2.378779,0.122279,-113.782272,0.013052,0.000000
15.520000,10.696022,-113.826752,-0.004329,0.000496,0.012601,47.578281,2.423753,0.126008,-113.826752,0.013433,0.000000
15.750001,10.798431,-113.871231,-0.004316,0.000507,0.012870,48.033821,2.446960,0.128696,-113.871231,0.013815,0.000000
15.980000,11.135796,-113.826752,-0.004307,0.000523,0.013286,49.534492,2.523407,0.132859,-113.826752,0.014196,0.000000
16.210001,11.595680,-113.782272,-0.004294,0.000542,0.013754,51.580162,2.627619,0.137542,-113.782272,0.014578,0.000000
16.440001,11.776276,-113.960197,-0.004277,0.000554,0.014066,52.383492,2.668542,0.140664,-113.960197,0.014968,0.000000
16.670000,11.829903,-113.915718,-0.004290,0.000562,0.014283,52.622036,2.680694,0.142832,-113.915718,0.015350,0.000000
16.900002,12.585815,-113.915718,-0.004277,0.000586,0.014882,55.984505,2.851986,0.148816,-113.915718,0.015731,0.000000
17.130001,12.874405,-113.960197,-0.004255,0.000602,0.015298,57.268211,2.917382,0.152979,-113.960197,0.016113,0.000000
17.360001,13.040108,-113.960197,-0.004243,0.000617,0.015662,58.005295,2.954931,0.156621,-113.960197,0.016495,0.000000
17.590000,13.255714,-114.049156,-0.004212,0.000630,0.016000,58.964363,3.003788,0.160003,-114.049156,0.016885,0.000000
17.820002,13.440041,-114.093643,-0.004208,0.000644,0.016356,59.784286,3.045557,0.163559,-114.093643,0.017266,0.000000
18.050001,13.682449,-114.093643,-0.004195,0.000659,0.016729,60.862576,3.100487,0.167288,-114.093643,0.017648,0.000000
18.280001,14.025406,-114.093643,-0.004195,0.000673,0.017102,62.388123,3.178202,0.171017,-114.093643,0.018030,0.000000
18.510000,14.369850,-114.093643,-0.004174,0.000688,0.017475,63.920284,3.256255,0.174746,-114.093643,0.018411,0.000000
18.740002,14.625298,-114.138123,-0.004152,0.000707,0.017969,65.056572,3.314140,0.179689,-114.138123,0.018801,0.000000
18.970001,15.164497,-114.182602,-0.004130,0.000726,0.018429,67.455055,3.436324,0.184285,-114.182602,0.019183,0.000000
19.200001,15.427391,-114.138123,-0.004139,0.000742,0.018853,68.624466,3.495897,0.188535,-114.138123,0.019565,0.000000
19.430000,15.335411,-114.182602,-0.004118,0.000754,0.019140,68.215317,3.475054,0.191397,-114.182602,0.019946,0.000000
19.660002,15.556602,-114.182602,-0.004092,0.000768,0.019513,69.199226,3.525177,0.195126,-114.182602,0.020328,0.000000
19.890001,15.759171,-114.271561,-0.004079,0.000782,0.019868,70.100288,3.571079,0.198681,-114.271561,0.020718,0.000000
20.120001,16.157242,-114.182602,-0.004083,0.000799,0.020284,71.871002,3.661283,0.202844,-114.182602,0.021100,0.000000
20.350000,16.411201,-114.316048,-0.004074,0.000813,0.020649,73.000671,3.718831,0.206486,-114.316048,0.021481,0.000000
20.580002,16.311028,-114.227081,-0.004057,0.000822,0.020874,72.555077,3.696131,0.208741,-114.227081,0.021863,0.000000
20.810001,16.955978,-114.316048,-0.004036,0.000841,0.021360,75.423958,3.842280,0.213598,-114.316048,0.022253,0.000000
21.040001,17.247543,-114.360527,-0.004027,0.000859,0.021819,76.720901,3.908349,0.218194,-114.360527,0.022635,0.000000
21.270000,17.482140,-114.405006,-0.004001,0.000873,0.022184,77.764442,3.961509,0.221836,-114.405006,0.023016,0.000000
21.500002,17.618805,-114.405006,-0.004001,0.000889,0.022574,78.372360,3.992478,0.225739,-114.405006,0.023398,0.000000
21.730001,17.751740,-114.405006,-0.004010,0.000903,0.022929,78.963684,4.022602,0.229294,-114.405006,0.023779,0.000000
21.960001,17.876114,-114.405006,-0.003984,0.000916,0.023259,79.516930,4.050785,0.232590,-114.405006,0.024170,0.000000
22.190001,18.245132,-114.493965,-0.003980,0.000934,0.023727,81.158401,4.134406,0.237273,-114.493965,0.024551,0.000000
22.420002,18.172890,-114.538452,-0.003945,0.000942,0.023935,80.837051,4.118036,0.239354,-114.538452,0.024933,0.000000
22.650002,18.627556,-114.538452,-0.003945,0.000964,0.024490,82.859505,4.221065,0.244905,-114.538452,0.025314,0.000000
22.880001,18.950409,-114.538452,-0.003936,0.000980,0.024889,84.295631,4.294224,0.248894,-114.538452,0.025696,0.000000
23.110001,19.298203,-114.582932,-0.003919,0.000997,0.025323,85.842690,4.373035,0.253230,-114.582932,0.026086,0.000000
23.340002,19.144409,-114.582932,-0.003893,0.001009,0.025627,85.158585,4.338185,0.256265,-114.582932,0.026468,0.000000
23.570002,19.340279,-114.671890,-0.003902,0.001024,0.025999,86.029854,4.382570,0.259994,-114.671890,0.026849,0.000000
23.800001,19.531303,-114.671890,-0.003880,0.001038,0.026372,86.879578,4.425857,0.263723,-114.671890,0.027231,0.000000
24.030001,19.821754,-114.627411,-0.003880,0.001055,0.026797,88.171570,4.491673,0.267973,-114.627411,0.027612,0.000000
24.260000,19.908150,-114.627411,-0.003846,0.001068,0.027135,88.555870,4.511251,0.271355,-114.627411,0.028003,0.000000
24.490002,19.699249,-114.671890,-0.003837,0.001076,0.027335,87.626640,4.463913,0.273349,-114.671890,0.028384,0.000000
24.720001,20.392601,-114.760857,-0.003829,0.001098,0.027890,90.710823,4.621029,0.278900,-114.760857,0.028766,0.000000
24.950001,20.666298,-114.716370,-0.003807,0.001115,0.028332,91.928284,4.683050,0.283323,-114.716370,0.029147,0.000000
25.180000,20.683052,-114.716370,-0.003816,0.001129,0.028679,92.002808,4.686847,0.286792,-114.716370,0.029529,0.000000
25.410002,20.725136,-114.760857,-0.003790,0.001143,0.029043,92.190010,4.696383,0.290434,-114.760857,0.029919,0.000000
25.640001,20.731461,-114.805336,-0.003790,0.001155,0.029347,92.218140,4.697816,0.293469,-114.805336,0.030301,0.000000
25.870001,21.381256,-114.894295,-0.003777,0.001178,0.029911,95.108574,4.845062,0.299106,-114.894295,0.030682,0.000000
26.100000,21.416260,-114.894295,-0.003751,0.001191,0.030258,95.264282,4.852994,0.302575,-114.894295,0.031064,0.000000
26.330002,21.063248,-114.894295,-0.003738,0.001197,0.030396,93.694008,4.773000,0.303963,-114.894295,0.031446,0.000000
26.560001,21.642288,-114.849815,-0.003755,0.001221,0.031012,96.269707,4.904212,0.310120,-114.849815,0.031836,0.000000
26.790001,22.004608,-114.849815,-0.003725,0.001236,0.031402,97.881386,4.986315,0.314022,-114.849815,0.032217,0.000000
27.020000,22.117058,-114.938774,-0.003699,0.001252,0.031810,98.381584,5.011797,0.318098,-114.938774,0.032599,0.000000
27.250002,22.118179,-114.938774,-0.003695,0.001263,0.032087,98.386574,5.012051,0.320873,-114.938774,0.032981,0.000000
27.480001,21.987846,-114.983261,-0.003699,0.001274,0.032348,97.806824,4.982517,0.323475,-114.983261,0.033362,0.000000
27.710001,22.311813,-114.983261,-0.003669,0.001291,0.032781,99.247902,5.055929,0.327811,-114.983261,0.033752,0.000000
27.940001,22.700195,-114.983261,-0.003660,0.001309,0.033249,100.975510,5.143938,0.332494,-114.983261,0.034134,0.000000
28.170002,22.881172,-115.027740,-0.003648,0.001323,0.033605,101.780540,5.184948,0.336050,-115.027740,0.034516,0.000000
28.400002,23.115395,-115.116699,-0.003630,0.001340,0.034039,102.822411,5.238023,0.340386,-115.116699,0.034897,0.000000
28.630001,23.126190,-115.072220,-0.003622,0.001354,0.034385,102.870430,5.240469,0.343855,-115.072220,0.035287,0.000000
28.860001,23.267319,-115.072220,-0.003604,0.001368,0.034758,103.498199,5.272449,0.347584,-115.072220,0.035669,0.000000
29.090002,23.467285,-115.072220,-0.003600,0.001384,0.035166,104.387695,5.317763,0.351660,-115.072220,0.036051,0.000000
29.320002,23.441963,-115.205666,-0.003591,0.001398,0.035504,104.275063,5.312025,0.355042,-115.205666,0.036432,0.000000
29.550001,23.462440,-115.161179,-0.003566,0.001410,0.035808,104.366150,5.316665,0.358077,-115.161179,0.036814,0.000000
29.780001,24.018768,-115.161179,-0.003561,0.001429,0.036302,106.840820,5.442731,0.363021,-115.161179,0.037204,0.000000
30.010002,24.080582,-115.161179,-0.003540,0.001442,0.036632,107.115776,5.456738,0.366316,-115.161179,0.037586,0.000000
30.240002,23.963654,-115.205666,-0.003548,0.001456,0.036970,106.595657,5.430242,0.369698,-115.205666,0.037967,0.000000
30.470001,24.701324,-115.294624,-0.003531,0.001477,0.037525,109.876976,5.597400,0.375249,-115.294624,0.038349,0.000000
30.700001,24.753456,-115.294624,-0.003527,0.001492,0.037889,110.108871,5.609213,0.378891,-115.294624,0.038730,0.000000
30.930002,24.705421,-115.250145,-0.003492,0.001507,0.038271,109.895203,5.598329,0.382707,-115.250145,0.039121,0.000000
31.160002,24.727394,-115.294624,-0.003488,0.001519,0.038583,109.992943,5.603307,0.385829,-115.294624,0.039502,0.000000
31.390001,24.518860,-115.250145,-0.003484,0.001529,0.038834,109.065338,5.556053,0.388344,-115.250145,0.039884,0.000000
31.620001,25.109444,-115.339104,-0.003471,0.001549,0.039355,111.692383,5.689881,0.393547,-115.339104,0.040265,0.000000
31.850002,25.457245,-115.383591,-0.003449,0.001565,0.039754,113.239479,5.768694,0.397536,-115.383591,0.040647,0.000000
32.080002,25.370110,-115.428070,-0.003449,0.001577,0.040066,112.851883,5.748949,0.400658,-115.428070,0.041037,0.000000
32.310001,25.501183,-115.428070,-0.003436,0.001592,0.040447,113.434929,5.778651,0.404474,-115.428070,0.041419,0.000000
32.540001,25.917496,-115.428070,-0.003410,0.001612,0.040933,115.286781,5.872988,0.409330,-115.428070,0.041800,0.000000
32.770000,26.194916,-115.428070,-0.003389,0.001628,0.041341,116.520805,5.935853,0.413406,-115.428070,0.042182,0.000000
33.000000,25.992340,-115.517029,-0.003389,0.001639,0.041627,115.619705,5.889948,0.416268,-115.517029,0.042563,0.000000
33.230003,26.105911,-115.561508,-0.003385,0.001654,0.042017,116.124893,5.915684,0.420171,-115.561508,0.042954,0.000000
33.460003,26.280930,-115.472549,-0.003363,0.001670,0.042407,116.903412,5.955344,0.424073,-115.472549,0.043335,0.000000
33.690002,26.561325,-115.517029,-0.003350,0.001687,0.042850,118.150673,6.018882,0.428496,-115.517029,0.043717,0.000000
33.920002,26.470840,-115.561508,-0.003341,0.001699,0.043144,117.748177,5.998378,0.431445,-115.561508,0.044098,0.000000
34.150002,26.360245,-115.561508,-0.003337,0.001708,0.043379,117.256226,5.973317,0.433786,-115.561508,0.044480,0.000000
34.380001,27.292297,-115.561508,-0.003316,0.001731,0.043960,121.402199,6.184523,0.439597,-115.561508,0.044870,0.000000
34.610001,27.467682,-115.650475,-0.003303,0.001748,0.044411,122.182350,6.224266,0.444106,-115.650475,0.045252,0.000000
34.840000,27.669510,-115.650475,-0.003290,0.001764,0.044810,123.080124,6.270000,0.448096,-115.650475,0.045633,0.000000
35.070004,27.553329,-115.650475,-0.003281,0.001777,0.045130,122.563332,6.243674,0.451304,-115.650475,0.046015,0.000000
35.300003,27.576416,-115.739433,-0.003268,0.001790,0.045477,122.666023,6.248905,0.454773,-115.739433,0.046397,0.000000
35.530003,27.864258,-115.783913,-0.003251,0.001806,0.045876,123.946411,6.314131,0.458762,-115.783913,0.046787,0.000000
35.760002,27.781219,-115.739433,-0.003238,0.001818,0.046180,123.577034,6.295314,0.461798,-115.739433,0.047168,0.000000
35.990002,28.130875,-115.739433,-0.003247,0.001834,0.046587,125.132378,6.374547,0.465874,-115.739433,0.047550,0.000000
36.220001,28.607513,-115.783913,-0.003234,0.001853,0.047073,127.252579,6.482555,0.470730,-115.783913,0.047932,0.000000
36.450001,28.951210,-115.828400,-0.003208,0.001870,0.047498,128.781418,6.560438,0.474979,-115.828400,0.048313,0.000000
36.680000,28.936691,-115.828400,-0.003195,0.001883,0.047836,128.716827,6.557148,0.478362,-115.828400,0.048703,0.000000
36.910000,29.031647,-115.828400,-0.003199,0.001898,0.048218,129.139221,6.578665,0.482178,-115.828400,0.049085,0.000000
37.140003,29.073723,-115.917358,-0.003182,0.001913,0.048582,129.326385,6.588200,0.485820,-115.917358,0.049467,0.000000
37.370003,29.285606,-115.872879,-0.003178,0.001926,0.048912,130.268890,6.636213,0.489115,-115.872879,0.049848,0.000000
37.600002,29.572701,-115.961838,-0.003156,0.001942,0.049328,131.545944,6.701270,0.493278,-115.961838,0.050238,0.000000
37.830002,29.669144,-115.961838,-0.003152,0.001954,0.049640,131.974945,6.723124,0.496400,-115.961838,0.050620,0.000000
38.060001,29.369385,-115.961838,-0.003139,0.001964,0.049891,130.641541,6.655198,0.498915,-115.961838,0.051002,0.000000
38.290001,30.234039,-115.961838,-0.003109,0.001986,0.050455,134.487717,6.851131,0.504552,-115.961838,0.051383,0.000000
38.520000,30.636574,-115.961838,-0.003104,0.002005,0.050915,136.278290,6.942347,0.509148,-115.961838,0.051765,0.000000
38.750000,30.651840,-116.095284,-0.003096,0.002018,0.051262,136.346191,6.945806,0.512617,-116.095284,0.052155,0.000000
38.980003,30.597099,-116.050804,-0.003078,0.002031,0.051600,136.102692,6.933402,0.515999,-116.050804,0.052537,0.000000
39.210003,30.771744,-116.050804,-0.003083,0.002045,0.051938,136.879547,6.972977,0.519382,-116.050804,0.052918,0.000000
39.440002,31.103523,-116.095284,-0.003061,0.002063,0.052389,138.355377,7.048159,0.523891,-116.095284,0.053300,0.000000
39.670002,31.112465,-116.050804,-0.003057,0.002074,0.052675,138.395157,7.050185,0.526753,-116.050804,0.053681,0.000000
39.900002,31.363068,-116.184242,-0.003040,0.002090,0.053074,139.509888,7.106973,0.530742,-116.184242,0.054072,0.000000
40.130001,32.054565,-116.273209,-0.003018,0.002111,0.053612,142.585831,7.263668,0.536119,-116.273209,0.054453,0.000000
40.360001,32.391937,-116.139763,-0.003009,0.002127,0.054028,144.086533,7.340118,0.540282,-116.139763,0.054835,0.000000
40.590000,32.591530,-116.184242,-0.002988,0.002142,0.054418,144.974365,7.385346,0.544184,-116.184242,0.055216,0.000000
40.820004,32.355438,-116.228722,-0.002992,0.002154,0.054705,143.924179,7.331847,0.547046,-116.228722,0.055598,0.000000
41.050003,32.591156,-116.228722,-0.002971,0.002170,0.055130,144.972702,7.385261,0.551295,-116.228722,0.055988,0.000000
41.280003,32.652596,-116.317688,-0.002979,0.002183,0.055459,145.246002,7.399184,0.554591,-116.317688,0.056370,0.000000
41.510002,33.045822,-116.273209,-0.002945,0.002200,0.055893,146.995163,7.488290,0.558927,-116.273209,0.056751,0.000000
41.740002,33.162003,-116.273209,-0.002953,0.002213,0.056222,147.511948,7.514617,0.562222,-116.273209,0.057133,0.000000
41.970001,32.878998,-116.273209,-0.002936,0.002223,0.056456,146.253082,7.450488,0.564564,-116.273209,0.057514,0.000000
42.200001,33.798012,-116.406647,-0.002919,0.002245,0.057011,150.341064,7.658739,0.570114,-116.406647,0.057905,0.000000
42.430000,34.180069,-116.495613,-0.002915,0.002261,0.057436,152.040543,7.745314,0.574364,-116.495613,0.058286,0.000000
42.660004,34.129425,-116.451126,-0.002897,0.002273,0.057740,151.815262,7.733839,0.577399,-116.451126,0.058668,0.000000
42.890003,34.533821,-116.451126,-0.002884,0.002291,0.058200,153.614105,7.825476,0.581995,-116.451126,0.059049,0.000000
43.120003,34.617973,-116.406647,-0.002871,0.002305,0.058546,153.988434,7.844545,0.585464,-116.406647,0.059431,0.000000
43.350002,34.650002,-116.451126,-0.002863,0.002318,0.058885,154.130905,7.851803,0.588846,-116.451126,0.059821,0.000000
43.580002,35.010086,-116.540092,-0.002850,0.002334,0.059292,155.732635,7.933399,0.592922,-116.540092,0.060203,0.000000
43.810001,34.673088,-116.540092,-0.002837,0.002341,0.059457,154.233597,7.857034,0.594570,-116.540092,0.060584,0.000000
44.040001,35.825211,-116.540092,-0.002824,0.002365,0.060073,159.358490,8.118109,0.600727,-116.540092,0.060966,0.000000
44.270000,36.291046,-116.540092,-0.002815,0.002385,0.060567,161.430634,8.223668,0.605671,-116.540092,0.061348,0.000000
44.500004,36.464569,-116.629051,-0.002798,0.002398,0.060905,162.202499,8.262990,0.609053,-116.629051,0.061738,0.000000
44.730003,36.517822,-116.584572,-0.002798,0.002411,0.061243,162.439392,8.275057,0.612435,-116.584572,0.062119,0.000000
44.960003,36.572563,-116.629051,-0.002794,0.002423,0.061547,162.682892,8.287461,0.615470,-116.629051,0.062501,0.000000
45.190002,37.149734,-116.629051,-0.002777,0.002442,0.062024,165.250275,8.418250,0.620240,-116.629051,0.062883,0.000000
45.420002,37.421196,-116.718018,-0.002755,0.002457,0.062414,166.457794,8.479764,0.624142,-116.718018,0.063264,0.000000
45.650002,37.388054,-116.673538,-0.002759,0.002468,0.062683,166.310364,8.472254,0.626831,-116.673538,0.063654,0.000000
45.880001,37.175430,-116.762497,-0.002746,0.002482,0.063039,165.364578,8.424073,0.630386,-116.762497,0.064036,0.000000
46.110001,38.265739,-116.762497,-0.002734,0.002502,0.063542,170.214508,8.671141,0.635416,-116.762497,0.064418,0.000000
46.340004,38.584114,-116.718018,-0.002725,0.002517,0.063923,171.630707,8.743286,0.639232,-116.718018,0.064799,0.000000
46.570004,38.803818,-116.718018,-0.002708,0.002533,0.064331,172.608002,8.793071,0.643308,-116.718018,0.065189,0.000000
46.800003,39.041763,-116.806976,-0.002690,0.002546,0.064669,173.666443,8.846991,0.646690,-116.806976,0.065571,0.000000
47.030003,39.067825,-116.806976,-0.002690,0.002559,0.065007,173.782364,8.852896,0.650072,-116.806976,0.065953,0.000000
47.260002,39.901573,-116.895943,-0.002673,0.002579,0.065510,177.491058,9.041825,0.655102,-116.895943,0.066334,0.000000
47.490002,40.094833,-116.851456,-0.002660,0.002592,0.065848,178.350723,9.085619,0.658484,-116.851456,0.066716,0.000000
47.720001,39.356041,-116.851456,-0.002656,0.002596,0.065944,175.064407,8.918207,0.659438,-116.851456,0.067106,0.000000
47.950001,40.832130,-116.940422,-0.002647,0.002624,0.066646,181.630386,9.252692,0.666463,-116.940422,0.067488,0.000000
48.180004,41.056671,-116.940422,-0.002634,0.002638,0.067011,182.629196,9.303575,0.670105,-116.940422,0.067869,0.000000
48.410004,41.390686,-116.984901,-0.002639,0.002653,0.067392,184.114960,9.379264,0.673921,-116.984901,0.068251,0.000000
48.640003,41.329994,-116.895943,-0.002608,0.002665,0.067687,183.845001,9.365511,0.676870,-116.895943,0.068632,0.000000
48.870003,41.077896,-117.029381,-0.002604,0.002676,0.067982,182.723602,9.308384,0.679818,-117.029381,0.069022,0.000000
49.100002,41.607780,-117.029381,-0.002596,0.002692,0.068389,185.080658,9.428458,0.683894,-117.029381,0.069404,0.000000
49.330002,42.354759,-117.073860,-0.002583,0.002708,0.068780,188.403381,9.597726,0.687797,-117.073860,0.069786,0.000000
49.560001,42.491791,-117.118347,-0.002561,0.002723,0.069161,189.012924,9.628778,0.691612,-117.118347,0.070167,0.000000
49.790001,43.058540,-117.118347,-0.002561,0.002742,0.069638,191.533951,9.757205,0.696382,-117.118347,0.070549,0.000000
50.020004,43.629387,-117.118347,-0.002535,0.002758,0.070055,194.073212,9.886560,0.700545,-117.118347,0.070939,0.000000
50.250004,43.815201,-117.118347,-0.002518,0.002771,0.070375,194.899750,9.928667,0.703754,-117.118347,0.071321,0.000000
50.480003,44.025223,-117.162827,-0.002518,0.002787,0.070792,195.833969,9.976258,0.707916,-117.162827,0.071702,0.000000
50.710003,44.015915,-117.207306,-0.002522,0.002798,0.071069,195.792572,9.974149,0.710691,-117.207306,0.072084,0.000000
50.940002,44.243805,-117.162827,-0.002509,0.002812,0.071425,196.806274,10.025789,0.714247,-117.162827,0.072465,0.000000
51.170002,44.991905,-117.162827,-0.002505,0.002830,0.071884,200.133987,10.195312,0.718843,-117.162827,0.072856,0.000000
51.400002,45.077919,-117.251785,-0.002488,0.002842,0.072197,200.516602,10.214803,0.721965,-117.251785,0.073237,0.000000
51.630001,45.526627,-117.296265,-0.002458,0.002859,0.072630,202.512543,10.316481,0.726301,-117.296265,0.073619,0.000000
51.860001,46.371544,-117.340752,-0.002475,0.002879,0.073133,206.270935,10.507942,0.731331,-117.340752,0.074000,0.000000
52.090004,46.630341,-117.296265,-0.002453,0.002894,0.073506,207.422119,10.566586,0.735060,-117.296265,0.074382,0.000000
52.320004,47.054100,-117.296265,-0.002453,0.002909,0.073879,209.307083,10.662612,0.738789,-117.296265,0.074772,0.000000
52.550003,47.111816,-117.340752,-0.002423,0.002922,0.074208,209.563828,10.675691,0.742085,-117.340752,0.075154,0.000000
52.780003,46.911858,-117.340752,-0.002427,0.002932,0.074477,208.674362,10.630379,0.744773,-117.340752,0.075535,0.000000
53.010002,47.889328,-117.385231,-0.002423,0.002952,0.074980,213.022369,10.851877,0.749803,-117.385231,0.075917,0.000000
53.240002,48.153717,-117.385231,-0.002410,0.002966,0.075345,214.198425,10.911788,0.753446,-117.385231,0.076299,0.000000
53.470001,48.147758,-117.385231,-0.002406,0.002977,0.075613,214.171921,10.910438,0.756134,-117.385231,0.076689,0.000000
53.700001,48.300056,-117.429710,-0.002393,0.002991,0.075960,214.849380,10.944949,0.759603,-117.429710,0.077070,0.000000
53.930004,49.213860,-117.429710,-0.002380,0.003012,0.076507,218.914185,11.152020,0.765067,-117.429710,0.077452,0.000000
54.160004,49.858810,-117.518669,-0.002376,0.003029,0.076932,221.783066,11.298168,0.769316,-117.518669,0.077834,0.000000
54.390003,49.681190,-117.474190,-0.002363,0.003038,0.077166,220.992966,11.257918,0.771658,-117.474190,0.078215,0.000000
54.620003,49.995094,-117.518669,-0.002358,0.003054,0.077573,222.389282,11.329050,0.775733,-117.518669,0.078605,0.000000
54.850002,50.285179,-117.474190,-0.002324,0.003069,0.077946,223.679642,11.394785,0.779462,-117.474190,0.078987,0.000000
55.080002,50.578606,-117.607635,-0.002320,0.003082,0.078284,224.984879,11.461276,0.782845,-117.607635,0.079368,0.000000
55.310001,50.825119,-117.607635,-0.002307,0.003097,0.078675,226.081421,11.517137,0.786747,-117.607635,0.079750,0.000000
55.540001,51.174400,-117.563156,-0.002307,0.003111,0.079022,227.635101,11.596285,0.790216,-117.563156,0.080140,0.000000
55.770004,52.040543,-117.652115,-0.002307,0.003130,0.079507,231.487900,11.792556,0.795073,-117.652115,0.080522,0.000000
56.000004,52.408073,-117.652115,-0.002285,0.003149,0.079976,233.122757,11.875839,0.799756,-117.652115,0.080903,0.000000
56.230003,52.893272,-117.696594,-0.002281,0.003163,0.080331,235.281021,11.985786,0.803311,-117.696594,0.081285,0.000000
56.460003,52.998657,-117.741081,-0.002285,0.003178,0.080721,235.749802,12.009667,0.807214,-117.741081,0.081667,0.000000
56.690002,53.099197,-117.785561,-0.002242,0.003189,0.081008,236.197021,12.032450,0.810076,-117.785561,0.082057,0.000000
56.920002,53.690147,-117.785561,-0.002251,0.003207,0.081459,238.825699,12.166361,0.814585,-117.785561,0.082438,0.000000
57.150002,53.713608,-117.741081,-0.002242,0.003220,0.081797,238.930054,12.171678,0.817967,-117.741081,0.082820,0.000000
57.380001,54.212959,-117.830040,-0.002220,0.003237,0.082213,241.151291,12.284832,0.822130,-117.830040,0.083202,0.000000
57.610004,54.953979,-117.874519,-0.002203,0.003255,0.082681,244.447510,12.452749,0.826813,-117.874519,0.083583,0.000000
57.840004,55.595581,-117.830040,-0.002207,0.003273,0.083132,247.301498,12.598139,0.831323,-117.830040,0.083973,0.000000
58.070004,55.540840,-117.785561,-0.002186,0.003284,0.083418,247.057999,12.585734,0.834184,-117.785561,0.084355,0.000000
58.300003,55.860710,-117.874519,-0.002173,0.003300,0.083817,248.480850,12.658217,0.838174,-117.874519,0.084737,0.000000
58.530003,55.922523,-117.918999,-0.002160,0.003314,0.084164,248.755814,12.672225,0.841643,-117.918999,0.085118,0.000000
58.760002,56.023811,-117.963486,-0.002156,0.003326,0.084468,249.206360,12.695177,0.844678,-117.963486,0.085500,0.000000
58.990002,56.746208,-117.963486,-0.002134,0.003344,0.084945,252.419739,12.858875,0.849448,-117.963486,0.085890,0.000000
59.220001,56.821800,-117.963486,-0.002121,0.003357,0.085274,252.755997,12.876004,0.852743,-117.963486,0.086272,0.000000
59.450005,56.728340,-117.963486,-0.002117,0.003372,0.085639,252.340256,12.854826,0.856385,-117.963486,0.086653,0.000000
59.680004,57.618683,-118.007965,-0.002113,0.003389,0.086072,256.300690,13.056580,0.860722,-118.007965,0.087035,0.000000
59.910004,58.111702,-118.052444,-0.002091,0.003405,0.086497,258.493774,13.168300,0.864971,-118.052444,0.087416,0.000000
60.140003,58.436035,-118.052444,-0.002091,0.003421,0.086905,259.936462,13.241796,0.869047,-118.052444,0.087807,0.000000
60.370003,58.584610,-118.096924,-0.002057,0.003434,0.087217,260.597351,13.275462,0.872169,-118.096924,0.088188,0.000000
60.600002,58.725372,-118.052444,-0.002065,0.003447,0.087555,261.223511,13.307360,0.875551,-118.052444,0.088570,0.000000
60.830002,59.490967,-118.096924,-0.002039,0.003465,0.088023,264.629028,13.480846,0.880234,-118.096924,0.088951,0.000000
61.060001,59.164024,-118.141403,-0.002026,0.003473,0.088214,263.174713,13.406760,0.882142,-118.141403,0.089333,0.000000
61.290005,59.843605,-118.185890,-0.002013,0.003491,0.088674,266.197662,13.560754,0.886738,-118.185890,0.089723,0.000000
61.520004,60.885872,-118.141403,-0.002001,0.003512,0.089203,270.833893,13.796936,0.892028,-118.141403,0.090105,0.000000
61.750004,61.357300,-118.141403,-0.001996,0.003527,0.089593,272.930908,13.903763,0.895931,-118.141403,0.090486,0.000000
61.980003,61.777336,-118.185890,-0.001988,0.003541,0.089949,274.799316,13.998944,0.899486,-118.185890,0.090868,0.000000
62.210003,61.821274,-118.274849,-0.001979,0.003556,0.090322,274.994751,14.008901,0.903216,-118.274849,0.091249,0.000000
62.440002,62.369034,-118.319328,-0.001957,0.003571,0.090703,277.431305,14.133025,0.907031,-118.319328,0.091640,0.000000
62.670002,62.507927,-118.274849,-0.001940,0.003583,0.091015,278.049133,14.164498,0.910153,-118.274849,0.092021,0.000000
62.900002,63.302574,-118.363808,-0.001927,0.003601,0.091466,281.583923,14.344568,0.914663,-118.363808,0.092403,0.000000
63.130005,63.465294,-118.363808,-0.001923,0.003612,0.091752,282.307739,14.381441,0.917525,-118.363808,0.092784,0.000000
63.360004,63.477592,-118.408295,-0.001897,0.003624,0.092056,282.362427,14.384228,0.920560,-118.408295,0.093166,0.000000
63.590004,64.759300,-118.408295,-0.001897,0.003646,0.092602,288.063751,14.674667,0.926024,-118.408295,0.093556,0.000000
63.820004,65.511864,-118.408295,-0.001884,0.003663,0.093036,291.411316,14.845201,0.930360,-118.408295,0.093938,0.000000
64.050003,65.925941,-118.363808,-0.001863,0.003676,0.093374,293.253235,14.939032,0.933742,-118.363808,0.094319,0.000000
64.280006,66.545937,-118.408295,-0.001858,0.003692,0.093782,296.011108,15.079525,0.937818,-118.408295,0.094701,0.000000
64.510002,66.925758,-118.408295,-0.001845,0.003703,0.094068,297.700653,15.165593,0.940680,-118.408295,0.095091,0.000000
64.740005,67.450432,-118.541733,-0.001824,0.003720,0.094476,300.034515,15.284486,0.944756,-118.541733,0.095473,0.000000
64.970001,66.386559,-118.541733,-0.001815,0.003710,0.094241,295.302155,15.043408,0.942414,-118.541733,0.094476,0.000000
65.200005,65.480949,-118.497253,-0.001819,0.003709,0.094207,291.273804,14.838195,0.942067,-118.497253,0.094241,0.000000
65.430000,64.560081,-118.497253,-0.001802,0.003708,0.094172,287.177582,14.629524,0.941720,-118.497253,0.094241,0.000000
65.660004,63.740852,-118.541733,-0.001789,0.003707,0.094155,283.533478,14.443883,0.941547,-118.541733,0.094241,0.000000
65.889999,63.000580,-118.675179,-0.001785,0.003707,0.094155,280.240570,14.276135,0.941547,-118.675179,0.094241,0.000000
66.120003,62.295303,-118.630699,-0.001785,0.003707,0.094146,277.103363,14.116318,0.941460,-118.630699,0.094241,0.000000
66.350006,61.665627,-118.586212,-0.001785,0.003707,0.094146,274.302399,13.973630,0.941460,-118.586212,0.094241,0.000000
66.580002,61.087326,-118.586212,-0.001785,0.003706,0.094137,271.730011,13.842587,0.941373,-118.586212,0.094241,0.000000
66.810005,60.559303,-118.675179,-0.001768,0.003706,0.094137,269.381226,13.722935,0.941373,-118.675179,0.094241,0.000000
67.040001,60.059212,-118.719658,-0.001776,0.003706,0.094137,267.156708,13.609612,0.941373,-118.719658,0.094241,0.000000
67.270004,59.599701,-118.764137,-0.001772,0.003706,0.094137,265.112701,13.505485,0.941373,-118.764137,0.094241,0.000000
67.500000,59.169609,-118.719658,-0.001763,0.003706,0.094137,263.199554,13.408026,0.941373,-118.719658,0.094241,0.000000
67.730003,58.776382,-118.719658,-0.001763,0.003706,0.094129,261.450409,13.318919,0.941287,-118.719658,0.094241,0.000000
67.960007,58.393211,-118.764137,-0.001759,0.003706,0.094129,259.745972,13.232090,0.941287,-118.764137,0.094241,0.000000
68.190002,58.058823,-118.853104,-0.001750,0.003706,0.094129,258.258545,13.156318,0.941287,-118.853104,0.094241,0.000000
68.420006,57.709908,-118.853104,-0.001746,0.003706,0.094129,256.706482,13.077251,0.941287,-118.853104,0.094241,0.000000
68.650002,57.381851,-118.853104,-0.001750,0.003706,0.094129,255.247223,13.002913,0.941287,-118.853104,0.094241,0.000000
68.880005,57.094376,-118.764137,-0.001746,0.003706,0.094129,253.968460,12.937770,0.941287,-118.764137,0.094241,0.000000
69.110001,56.843025,-118.897583,-0.001742,0.003706,0.094129,252.850403,12.880814,0.941287,-118.897583,0.094241,0.000000
69.340004,56.578270,-118.942062,-0.001746,0.003706,0.094129,251.672714,12.820819,0.941287,-118.942062,0.094241,0.000000
69.570000,56.297501,-118.897583,-0.001755,0.003706,0.094129,250.423782,12.757195,0.941287,-118.897583,0.094241,0.000000
69.800003,56.081528,-118.942062,-0.001742,0.003706,0.094129,249.463089,12.708256,0.941287,-118.942062,0.094241,0.000000
70.030006,55.874489,-118.986542,-0.001746,0.003706,0.094129,248.542145,12.661341,0.941287,-118.986542,0.094241,0.000000
70.260002,55.647339,-118.986542,-0.001742,0.003706,0.094129,247.531723,12.609867,0.941287,-118.986542,0.094241,0.000000
70.490005,55.439552,-119.075508,-0.001755,0.003706,0.094129,246.607452,12.562781,0.941287,-119.075508,0.094241,0.000000
70.720001,55.247040,-119.119987,-0.001742,0.003706,0.094129,245.751114,12.519158,0.941287,-119.119987,0.094241,0.000000
70.950005,55.080215,-119.075508,-0.001742,0.003706,0.094129,245.009033,12.481356,0.941287,-119.075508,0.094241,0.000000
71.180000,54.887329,-119.031029,-0.001733,0.003706,0.094129,244.151031,12.437647,0.941287,-119.031029,0.094241,0.000000
71.410004,54.714920,-119.075508,-0.001733,0.003706,0.094129,243.384125,12.398578,0.941287,-119.075508,0.094241,0.000000
71.640007,54.566711,-119.164467,-0.001729,0.003706,0.094129,242.724854,12.364994,0.941287,-119.164467,0.094241,0.000000
71.870003,54.415901,-119.253433,-0.001733,0.003706,0.094129,242.054016,12.330819,0.941287,-119.253433,0.094241,0.000000
72.100006,54.240143,-119.164467,-0.001729,0.003706,0.094129,241.272202,12.290992,0.941287,-119.164467,0.094241,0.000000
72.330002,54.114655,-119.164467,-0.001738,0.003706,0.094129,240.714005,12.262556,0.941287,-119.164467,0.094241,0.000000
72.560005,53.984322,-119.208946,-0.001716,0.003706,0.094129,240.134262,12.233022,0.941287,-119.208946,0.094241,0.000000
72.790001,53.844681,-119.297913,-0.001733,0.003706,0.094129,239.513107,12.201379,0.941287,-119.297913,0.094241,0.000000
73.020004,53.700951,-119.253433,-0.001716,0.003706,0.094129,238.873764,12.168809,0.941287,-119.253433,0.094241,0.000000
73.250000,53.576576,-119.297913,-0.001738,0.003706,0.094129,238.320511,12.140625,0.941287,-119.297913,0.094241,0.000000
73.480003,53.473427,-119.342392,-0.001738,0.003706,0.094129,237.861679,12.117251,0.941287,-119.342392,0.094241,0.000000
73.710007,53.343842,-119.297913,-0.001720,0.003706,0.094129,237.285263,12.087887,0.941287,-119.297913,0.094241,0.000000
73.940002,53.215378,-119.342392,-0.001712,0.003706,0.094129,236.713821,12.058777,0.941287,-119.342392,0.094241,0.000000
74.170006,53.126381,-119.431351,-0.001720,0.003706,0.094129,236.317947,12.038610,0.941287,-119.431351,0.094241,0.000000
74.400002,53.019135,-119.475838,-0.001725,0.003706,0.094129,235.840897,12.014308,0.941287,-119.475838,0.094241,0.000000
74.630005,52.917847,-119.431351,-0.001716,0.003706,0.094129,235.390335,11.991356,0.941287,-119.431351,0.094241,0.000000
74.860001,52.822151,-119.431351,-0.001712,0.003706,0.094129,234.964661,11.969671,0.941287,-119.431351,0.094241,0.000000
75.090004,52.720490,-119.475838,-0.001712,0.003706,0.094129,234.512451,11.946633,0.941287,-119.475838,0.094241,0.000000
75.320007,52.640434,-119.475838,-0.001712,0.003706,0.094129,234.156342,11.928493,0.941287,-119.475838,0.094241,0.000000
75.550003,52.532814,-119.520317,-0.001720,0.003706,0.094129,233.677628,11.904105,0.941287,-119.520317,0.094241,0.000000
75.780006,52.446800,-119.520317,-0.001733,0.003706,0.094129,233.295013,11.884615,0.941287,-119.520317,0.094241,0.000000
76.010002,52.383492,-119.520317,-0.001699,0.003706,0.094129,233.013412,11.870269,0.941287,-119.520317,0.094241,0.000000
76.240005,52.285934,-119.564796,-0.001716,0.003706,0.094129,232.579453,11.848162,0.941287,-119.564796,0.094241,0.000000
76.470001,52.204010,-119.653755,-0.001725,0.003706,0.094129,232.215027,11.829598,0.941287,-119.653755,0.094241,0.000000
76.700005,52.116135,-119.609276,-0.001707,0.003706,0.094129,231.824142,11.809685,0.941287,-119.609276,0.094241,0.000000
76.930000,52.053200,-119.653755,-0.001712,0.003706,0.094129,231.544189,11.795424,0.941287,-119.653755,0.094241,0.000000
77.160004,51.979095,-119.653755,-0.001707,0.003706,0.094129,231.214569,11.778631,0.941287,-119.653755,0.094241,0.000000
77.390007,51.897552,-119.609276,-0.001699,0.003706,0.094129,230.851837,11.760154,0.941287,-119.609276,0.094241,0.000000
77.620003,51.813766,-119.742722,-0.001690,0.003706,0.094129,230.479141,11.741167,0.941287,-119.742722,0.094241,0.000000
77.850006,51.762375,-119.787201,-0.001720,0.003706,0.094129,230.250549,11.729522,0.941287,-119.787201,0.094241,0.000000
78.080002,51.690880,-119.698242,-0.001720,0.003706,0.094129,229.932510,11.713321,0.941287,-119.698242,0.094241,0.000000
78.310005,51.620506,-119.742722,-0.001716,0.003706,0.094129,229.619476,11.697373,0.941287,-119.742722,0.094241,0.000000
78.540001,51.557945,-119.742722,-0.001707,0.003706,0.094129,229.341202,11.683197,0.941287,-119.742722,0.094241,0.000000
78.770004,51.494270,-119.787201,-0.001707,0.003706,0.094129,229.057953,11.668769,0.941287,-119.787201,0.094241,0.000000
79.000000,51.431335,-119.831680,-0.001712,0.003706,0.094129,228.778000,11.654508,0.941287,-119.831680,0.094241,0.000000
79.230003,51.362076,-119.831680,-0.001712,0.003706,0.094129,228.469925,11.638813,0.941287,-119.831680,0.094241,0.000000
79.460007,51.298027,-119.876160,-0.001716,0.003706,0.094129,228.185028,11.624299,0.941287,-119.876160,0.094241,0.000000
79.690002,51.250366,-119.831680,-0.001703,0.003706,0.094129,227.973007,11.613500,0.941287,-119.831680,0.094241,0.000000
79.920006,51.207169,-119.920647,-0.001703,0.003706,0.094129,227.780869,11.603710,0.941287,-119.920647,0.094241,0.000000
80.150002,51.153549,-119.965126,-0.001707,0.003706,0.094129,227.542358,11.591560,0.941287,-119.965126,0.094241,0.000000
80.380005,51.067528,-119.965126,-0.001712,0.003706,0.094129,227.159714,11.572067,0.941287,-119.965126,0.094241,0.000000
80.610001,51.023590,-119.965126,-0.001720,0.003706,0.094129,226.964264,11.562111,0.941287,-119.965126,0.094241,0.000000
80.840004,50.979279,-119.965126,-0.001707,0.003706,0.094129,226.767151,11.552070,0.941287,-119.965126,0.094241,0.000000
81.070007,50.923424,-120.009605,-0.001699,0.003706,0.094129,226.518707,11.539413,0.941287,-120.009605,0.094241,0.000000
81.300003,50.867935,-120.009605,-0.001707,0.003706,0.094129,226.271881,11.526838,0.941287,-120.009605,0.094241,0.000000
81.530006,50.832939,-120.098564,-0.001707,0.003706,0.094129,226.116211,11.518909,0.941287,-120.098564,0.094241,0.000000
81.760002,50.776711,-120.054085,-0.001716,0.003706,0.094129,225.866089,11.506167,0.941287,-120.054085,0.094241,0.000000
81.990005,50.719360,-120.098564,-0.001694,0.003706,0.094129,225.610977,11.493172,0.941287,-120.098564,0.094241,0.000000
82.220001,50.687340,-120.098564,-0.001712,0.003706,0.094129,225.468552,11.485916,0.941287,-120.098564,0.094241,0.000000
82.450005,50.636322,-120.232010,-0.001707,0.003706,0.094129,225.241608,11.474355,0.941287,-120.232010,0.094241,0.000000
82.680000,50.584190,-120.143051,-0.001699,0.003706,0.094129,225.009720,11.462542,0.941287,-120.143051,0.094241,0.000000
82.910004,50.536903,-120.232010,-0.001703,0.003706,0.094129,224.799377,11.451826,0.941287,-120.232010,0.094241,0.000000
83.140007,50.661270,-120.187531,-0.001686,0.003706,0.094129,225.352585,11.480007,0.941287,-120.187531,0.094241,0.000000
83.370003,50.484764,-120.276489,-0.001669,0.003706,0.094129,224.567444,11.440011,0.941287,-120.276489,0.094241,0.000000
83.600006,50.436356,-120.276489,-0.001681,0.003706,0.094129,224.352112,11.429042,0.941287,-120.276489,0.094241,0.000000
83.830002,50.359650,-120.365456,-0.001681,0.003706,0.094129,224.010910,11.411660,0.941287,-120.365456,0.094241,0.000000
84.060005,50.319435,-120.232010,-0.001681,0.003706,0.094129,223.832031,11.402547,0.941287,-120.232010,0.094241,0.000000
84.290001,50.303047,-120.276489,-0.001669,0.003706,0.094129,223.759125,11.398833,0.941287,-120.276489,0.094241,0.000000
84.520004,50.236397,-120.320976,-0.001677,0.003706,0.094129,223.462646,11.383730,0.941287,-120.320976,0.094241,0.000000
84.750008,50.187241,-120.365456,-0.001673,0.003706,0.094129,223.244003,11.372591,0.941287,-120.365456,0.094241,0.000000
84.980003,50.161919,-120.409935,-0.001673,0.003706,0.094129,223.131363,11.366854,0.941287,-120.409935,0.094241,0.000000
85.210007,50.115005,-120.320976,-0.001677,0.003706,0.094129,222.922684,11.356222,0.941287,-120.320976,0.094241,0.000000
85.440002,50.092659,-120.409935,-0.001673,0.003706,0.094129,222.823273,11.351158,0.941287,-120.409935,0.094241,0.000000
85.670006,50.046486,-120.409935,-0.001673,0.003706,0.094129,222.617889,11.340695,0.941287,-120.409935,0.094241,0.000000
85.900002,49.996590,-120.498894,-0.001677,0.003706,0.094129,222.395935,11.329390,0.941287,-120.498894,0.094241,0.000000
86.130005,49.963821,-120.498894,-0.001681,0.003706,0.094129,222.250183,11.321964,0.941287,-120.498894,0.094241,0.000000
86.360001,49.931793,-120.543381,-0.001673,0.003706,0.094129,222.107712,11.314706,0.941287,-120.543381,0.094241,0.000000
86.590004,49.894928,-120.454414,-0.001669,0.003706,0.094129,221.943726,11.306352,0.941287,-120.454414,0.094241,0.000000
86.820007,49.837212,-120.543381,-0.001677,0.003706,0.094129,221.686996,11.293274,0.941287,-120.543381,0.094241,0.000000
87.050003,49.815987,-120.632339,-0.001660,0.003706,0.094129,221.592575,11.288464,0.941287,-120.632339,0.094241,0.000000
87.280006,49.780235,-120.676819,-0.001677,0.003706,0.094129,221.433548,11.280362,0.941287,-120.676819,0.094241,0.000000
87.510002,49.757896,-120.632339,-0.001686,0.003706,0.094129,221.334183,11.275300,0.941287,-120.632339,0.094241,0.000000
87.740005,49.717308,-120.587860,-0.001664,0.003706,0.094129,221.153625,11.266103,0.941287,-120.587860,0.094241,0.000000
87.970001,49.669273,-120.632339,-0.001681,0.003706,0.094129,220.939957,11.255218,0.941287,-120.632339,0.094241,0.000000
88.200005,49.651398,-120.676819,-0.001677,0.003706,0.094129,220.860443,11.251167,0.941287,-120.676819,0.094241,0.000000
88.430008,49.629059,-120.721298,-0.001686,0.003706,0.094129,220.761078,11.246106,0.941287,-120.721298,0.094241,0.000000
88.660004,49.570595,-120.721298,-0.001677,0.003706,0.094129,220.501022,11.232858,0.941287,-120.721298,0.094241,0.000000
88.890007,49.547508,-120.721298,-0.001677,0.003706,0.094129,220.398331,11.227626,0.941287,-120.721298,0.094241,0.000000
89.120003,49.517715,-120.721298,-0.001686,0.003706,0.094129,220.265793,11.220874,0.941287,-120.721298,0.094241,0.000000
89.350006,49.495003,-120.765785,-0.001681,0.003706,0.094129,220.164764,11.215728,0.941287,-120.765785,0.094241,0.000000
89.580002,49.444359,-120.854744,-0.001669,0.003706,0.094129,219.939499,11.204251,0.941287,-120.854744,0.094241,0.000000
89.810005,49.423882,-120.810265,-0.001690,0.003706,0.094129,219.848404,11.199612,0.941287,-120.810265,0.094241,0.000000
90.040001,49.408241,-120.810265,-0.001660,0.003706,0.094129,219.778839,11.196068,0.941287,-120.810265,0.094241,0.000000
90.270004,49.363182,-120.854744,-0.001669,0.003706,0.094129,219.578400,11.185857,0.941287,-120.854744,0.094241,0.000000
90.500008,49.333389,-120.943703,-0.001673,0.003706,0.094129,219.445877,11.179106,0.941287,-120.943703,0.094241,0.000000
90.730003,49.298759,-120.943703,-0.001681,0.003706,0.094129,219.291840,11.171259,0.941287,-120.943703,0.094241,0.000000
90.960007,49.295410,-120.899223,-0.001673,0.003706,0.094129,219.276932,11.170500,0.941287,-120.899223,0.094241,0.000000
91.190002,49.251846,-120.899223,-0.001673,0.003706,0.094129,219.083160,11.160628,0.941287,-120.899223,0.094241,0.000000
91.420006,49.221680,-120.988190,-0.001664,0.003706,0.094129,218.948959,11.153792,0.941287,-120.988190,0.094241,0.000000
91.650002,49.193382,-121.032669,-0.001677,0.003706,0.094129,218.823090,11.147380,0.941287,-121.032669,0.094241,0.000000
91.880005,49.165825,-121.077148,-0.001669,0.003706,0.094129,218.700516,11.141135,0.941287,-121.077148,0.094241,0.000000
92.110001,49.148697,-121.032669,-0.001686,0.003706,0.094129,218.624329,11.137254,0.941287,-121.032669,0.094241,0.000000
92.340004,49.116669,-121.032669,-0.001677,0.003706,0.094129,218.481857,11.129995,0.941287,-121.032669,0.094241,0.000000
92.570007,49.095818,-121.032669,-0.001660,0.003706,0.094129,218.389099,11.125272,0.941287,-121.032669,0.094241,0.000000
92.800003,49.062675,-121.077148,-0.001677,0.003706,0.094129,218.241684,11.117761,0.941287,-121.077148,0.094241,0.000000
93.030006,49.032516,-121.166107,-0.001664,0.003706,0.094129,218.107529,11.110928,0.941287,-121.166107,0.094241,0.000000
93.260002,48.997887,-121.210594,-0.001669,0.003706,0.094129,217.953491,11.103080,0.941287,-121.210594,0.094241,0.000000
93.490005,48.972191,-121.166107,-0.001677,0.003706,0.094129,217.839188,11.097258,0.941287,-121.166107,0.094241,0.000000
93.720001,48.955063,-121.210594,-0.001681,0.003706,0.094129,217.763000,11.093376,0.941287,-121.210594,0.094241,0.000000
93.950005,48.930855,-121.166107,-0.001677,0.003706,0.094129,217.655319,11.087890,0.941287,-121.166107,0.094241,0.000000
94.180008,48.897713,-121.255074,-0.001686,0.003706,0.094129,217.507889,11.080380,0.941287,-121.255074,0.094241,0.000000
94.410004,48.871651,-121.255074,-0.001664,0.003706,0.094129,217.391953,11.074474,0.941287,-121.255074,0.094241,0.000000
94.640007,48.859734,-121.299553,-0.001651,0.003706,0.094129,217.338943,11.071774,0.941287,-121.299553,0.094241,0.000000
94.870003,48.823990,-121.299553,-0.001660,0.003706,0.094129,217.179947,11.063674,0.941287,-121.299553,0.094241,0.000000
95.100006,48.809464,-121.344032,-0.001651,0.003706,0.094129,217.115341,11.060383,0.941287,-121.344032,0.094241,0.000000
95.200005,48.791588,-121.344032,-0.001638,0.003706,0.094129,217.035828,11.056332,0.941287,-121.344032,0.094241,0.000000