File: Data/compression 10/AutoHeating-17-10-7-samepoint-240424_04242024_233201.csv
Time (sec),S:Load (lbs),S:HL1 (DIM),S:LVDT (in),S:Position (in),Ch:Position (mm),Ch:Load (N),Ch:Stress (MPa),Ch:Strain (mm/mm),Ch:HL1 (DIM),Set Point (),Cycles ()
0.110000,0.002235,-136.556519,-0.009757,-0.005013,-0.127326,0.009944,0.000507,-1.273261,-136.556519,-0.127161,0.000000
0.260000,0.004463,-136.600998,-0.009753,-0.005013,-0.127326,0.019853,0.001011,-1.273261,-136.600998,-0.127161,0.000000
0.410000,0.024574,-136.645477,-0.009761,-0.005009,-0.127222,0.109312,0.005569,-1.272220,-136.645477,-0.126710,0.000000
0.560000,0.014145,-136.645477,-0.009740,-0.004924,-0.125071,0.062920,0.003205,-1.250713,-136.645477,-0.124213,0.000000
0.710000,-0.015640,-136.689957,-0.009744,-0.004836,-0.122825,-0.069571,-0.003544,-1.228252,-136.689957,-0.121715,0.000000
0.860000,-0.031281,-136.734436,-0.009619,-0.004734,-0.120232,-0.139143,-0.007088,-1.202322,-136.734436,-0.119218,0.000000
1.010000,0.023460,-136.734436,-0.009533,-0.004646,-0.118003,0.104357,0.005316,-1.180034,-136.734436,-0.116720,0.000000
1.160000,0.014145,-136.689957,-0.009429,-0.004541,-0.115350,0.062920,0.003205,-1.153497,-136.689957,-0.114222,0.000000
1.310000,-0.002983,-136.689957,-0.009339,-0.004438,-0.112722,-0.013269,-0.000676,-1.127220,-136.689957,-0.111725,0.000000
1.460000,-0.036491,-136.778931,-0.009227,-0.004343,-0.110302,-0.162322,-0.008269,-1.103024,-136.778931,-0.109210,0.000000
1.610000,-0.012291,-136.778931,-0.009136,-0.004239,-0.107675,-0.054673,-0.002785,-1.076748,-136.778931,-0.106712,0.000000
1.760000,-0.015266,-136.734436,-0.009037,-0.004145,-0.105273,-0.067908,-0.003459,-1.052725,-136.734436,-0.104215,0.000000
1.910000,-0.022346,-136.823410,-0.008933,-0.004043,-0.102697,-0.099402,-0.005064,-1.026969,-136.823410,-0.101717,0.000000
2.060000,-0.056976,-136.823410,-0.008830,-0.003954,-0.100425,-0.253443,-0.012911,-1.004247,-136.823410,-0.099219,0.000000
2.210000,-0.058090,-136.823410,-0.008722,-0.003848,-0.097745,-0.258398,-0.013163,-0.977450,-136.823410,-0.096722,0.000000
2.360000,-0.021225,-136.867889,-0.008632,-0.003754,-0.095351,-0.094413,-0.004810,-0.953515,-136.867889,-0.094224,0.000000
2.510000,0.008934,-136.912369,-0.008524,-0.003657,-0.092897,0.039741,0.002024,-0.928972,-136.912369,-0.091726,0.000000
2.660000,-0.011917,-136.867889,-0.008420,-0.003555,-0.090304,-0.053010,-0.002700,-0.903042,-136.867889,-0.089229,0.000000
2.810000,-0.034264,-136.867889,-0.008317,-0.003458,-0.087833,-0.152412,-0.007764,-0.878326,-136.867889,-0.086731,0.000000
2.960000,0.019363,-136.867889,-0.008226,-0.003356,-0.085231,0.086133,0.004388,-0.852309,-136.867889,-0.084234,0.000000
3.110000,0.030533,-136.912369,-0.008144,-0.003266,-0.082967,0.135817,0.006919,-0.829675,-136.912369,-0.081736,0.000000
3.260000,0.004463,-136.912369,-0.008028,-0.003161,-0.080296,0.019853,0.001011,-0.802964,-136.912369,-0.079238,0.000000
3.410000,0.002235,-136.956848,-0.007946,-0.003063,-0.077807,0.009944,0.000507,-0.778075,-136.956848,-0.076723,0.000000
3.560000,0.006699,-136.956848,-0.007838,-0.002962,-0.075223,0.029797,0.001518,-0.752232,-136.956848,-0.074226,0.000000
3.710000,-0.006332,-137.001328,-0.007752,-0.002870,-0.072899,-0.028168,-0.001435,-0.728990,-137.001328,-0.071728,0.000000
3.860000,-0.002983,-136.956848,-0.007653,-0.002769,-0.070332,-0.013269,-0.000676,-0.703320,-136.956848,-0.069231,0.000000
4.010000,-0.041710,-136.956848,-0.007554,-0.002677,-0.067999,-0.185535,-0.009452,-0.679992,-136.956848,-0.066733,0.000000
4.160000,-0.067398,-137.001328,-0.007433,-0.002571,-0.065293,-0.299802,-0.015273,-0.652934,-137.001328,-0.064235,0.000000
4.310000,-0.016014,-137.001328,-0.007334,-0.002472,-0.062787,-0.071234,-0.003629,-0.627871,-137.001328,-0.061738,0.000000
4.460000,0.016754,-137.045807,-0.007256,-0.002382,-0.060515,0.074526,0.003797,-0.605150,-137.045807,-0.059240,0.000000
4.610000,-0.027931,-137.045807,-0.007140,-0.002279,-0.057879,-0.124244,-0.006329,-0.578786,-137.045807,-0.056743,0.000000
4.760000,-0.014526,-137.090286,-0.007049,-0.002180,-0.055381,-0.064617,-0.003292,-0.553810,-137.090286,-0.054245,0.000000
4.910000,0.007072,-137.045807,-0.006929,-0.002080,-0.052823,0.031460,0.001603,-0.528227,-137.045807,-0.051747,0.000000
5.060000,0.026062,-137.045807,-0.006829,-0.001983,-0.050377,0.115930,0.005906,-0.503771,-137.045807,-0.049250,0.000000
5.210000,0.001862,-137.045807,-0.006739,-0.001882,-0.047793,0.008281,0.000422,-0.477928,-137.045807,-0.046752,0.000000
5.360000,-0.002609,-137.090286,-0.006653,-0.001784,-0.045304,-0.011607,-0.000591,-0.453039,-137.090286,-0.044237,0.000000
5.510000,-0.001495,-137.090286,-0.006558,-0.001686,-0.042832,-0.006652,-0.000339,-0.428323,-137.090286,-0.041740,0.000000
5.660000,0.011917,-137.090286,-0.006433,-0.001585,-0.040248,0.053010,0.002700,-0.402479,-137.090286,-0.039242,0.000000
5.810000,0.023827,-137.134766,-0.006351,-0.001493,-0.037915,0.105986,0.005399,-0.379151,-137.134766,-0.036744,0.000000
5.960001,0.006699,-137.090286,-0.006247,-0.001392,-0.035348,0.029797,0.001518,-0.353481,-137.090286,-0.034247,0.000000
6.110000,-0.036125,-137.179260,-0.006153,-0.001296,-0.032920,-0.160693,-0.008186,-0.329199,-137.179260,-0.031749,0.000000
6.260000,-0.002983,-137.179260,-0.006049,-0.001191,-0.030240,-0.013269,-0.000676,-0.302402,-137.179260,-0.029252,0.000000
6.410000,0.015266,-137.134766,-0.005967,-0.001100,-0.027933,0.067908,0.003459,-0.279333,-137.134766,-0.026754,0.000000
6.560000,-0.022346,-137.223740,-0.005851,-0.000999,-0.025384,-0.099402,-0.005064,-0.253837,-137.223740,-0.024256,0.000000
6.710001,-0.040962,-137.179260,-0.005760,-0.000902,-0.022912,-0.182209,-0.009282,-0.229121,-137.179260,-0.021759,0.000000
6.860000,0.005211,-137.223740,-0.005657,-0.000799,-0.020284,0.023179,0.001181,-0.202844,-137.223740,-0.019261,0.000000
7.010000,0.021599,-137.223740,-0.005562,-0.000705,-0.017917,0.096076,0.004894,-0.179169,-137.223740,-0.016763,0.000000
7.160000,0.029419,-137.223740,-0.005458,-0.000605,-0.015359,0.130862,0.006666,-0.153586,-137.223740,-0.014266,0.000000
7.310000,0.009308,-137.268219,-0.005364,-0.000506,-0.012861,0.041403,0.002109,-0.128610,-137.268219,-0.011751,0.000000
7.460001,-0.002983,-137.312698,-0.005256,-0.000408,-0.010372,-0.013269,-0.000676,-0.103720,-137.312698,-0.009253,0.000000
7.610000,0.018990,-137.268219,-0.005152,-0.000305,-0.007736,0.084470,0.004303,-0.077357,-137.268219,-0.006756,0.000000
7.760000,0.031281,-137.312698,-0.005070,-0.000215,-0.005455,0.139143,0.007088,-0.054548,-137.312698,-0.004258,0.000000
7.910000,-0.011543,-137.312698,-0.004945,-0.000110,-0.002801,-0.051347,-0.002616,-0.028011,-137.312698,-0.001760,0.000000
8.060000,-0.011543,-137.312698,-0.004868,-0.000017,-0.000442,-0.051347,-0.002616,-0.004423,-137.312698,0.000737,0.000000
8.210000,-0.010056,-137.357178,-0.004760,0.000086,0.002177,-0.044729,-0.002279,0.021767,-137.357178,0.003235,0.000000
8.360001,0.002975,-137.401657,-0.004665,0.000182,0.004614,0.013236,0.000674,0.046136,-137.401657,0.005732,0.000000
8.510000,-0.002235,-137.357178,-0.004562,0.000282,0.007155,-0.009944,-0.000507,0.071546,-137.357178,0.008230,0.000000
8.660001,-0.053253,-137.357178,-0.004454,0.000377,0.009565,-0.236882,-0.012067,0.095655,-137.357178,0.010728,0.000000
8.810000,-0.059578,-137.357178,-0.004355,0.000479,0.012176,-0.265016,-0.013501,0.121758,-137.357178,0.013225,0.000000
8.960000,0.030907,-137.401657,-0.004268,0.000576,0.014630,0.137480,0.007004,0.146301,-137.401657,0.015723,0.000000
9.110001,0.040588,-137.357178,-0.004178,0.000668,0.016963,0.180546,0.009197,0.169629,-137.357178,0.018238,0.000000
9.260000,0.004837,-137.446136,-0.004074,0.000771,0.019573,0.021516,0.001096,0.195733,-137.446136,0.020735,0.000000
9.410001,-0.007080,-137.401657,-0.003975,0.000874,0.022210,-0.031494,-0.001604,0.222096,-137.401657,0.023233,0.000000
9.560000,0.040215,-137.490616,-0.003880,0.000972,0.024690,0.178883,0.009113,0.246899,-137.490616,0.025731,0.000000
9.710000,0.035370,-137.490616,-0.003777,0.001066,0.027075,0.157333,0.008015,0.270748,-137.490616,0.028228,0.000000
9.860001,0.022713,-137.535095,-0.003686,0.001168,0.029676,0.101031,0.005147,0.296765,-137.535095,0.030726,0.000000
10.010000,0.003349,-137.446136,-0.003570,0.001267,0.032191,0.014898,0.000759,0.321914,-137.446136,0.033223,0.000000
10.160001,-0.008942,-137.446136,-0.003475,0.001367,0.034715,-0.039774,-0.002026,0.347150,-137.446136,0.035721,0.000000
10.310000,0.007446,-137.535095,-0.003367,0.001465,0.037213,0.033123,0.001687,0.372126,-137.535095,0.038219,0.000000
10.460000,0.033882,-137.490616,-0.003290,0.001558,0.039580,0.150715,0.007678,0.395802,-137.490616,0.040716,0.000000
10.610001,0.001488,-137.535095,-0.003191,0.001655,0.042026,0.006618,0.000337,0.420258,-137.535095,0.043214,0.000000
10.760000,-0.057350,-137.579575,-0.003074,0.001755,0.044584,-0.255106,-0.012996,0.445841,-137.579575,0.045711,0.000000
10.910001,0.006325,-137.579575,-0.002988,0.001859,0.047229,0.028134,0.001433,0.472291,-137.579575,0.048209,0.000000
11.060000,0.066277,-137.579575,-0.002880,0.001952,0.049588,0.294813,0.015018,0.495880,-137.579575,0.050724,0.000000
11.210001,0.032768,-137.624069,-0.002777,0.002052,0.052112,0.145760,0.007425,0.521116,-137.624069,0.053222,0.000000
11.360001,0.017502,-137.579575,-0.002695,0.002149,0.054592,0.077852,0.003966,0.545919,-137.579575,0.055719,0.000000
11.510000,0.036118,-137.624069,-0.002587,0.002252,0.057194,0.160659,0.008184,0.571935,-137.624069,0.058217,0.000000
11.660001,0.074471,-137.579575,-0.002496,0.002344,0.059526,0.331261,0.016875,0.595264,-137.579575,0.060714,0.000000
11.810000,0.054733,-137.668549,-0.002393,0.002446,0.062119,0.243466,0.012403,0.621194,-137.668549,0.063212,0.000000
11.960001,0.073730,-137.668549,-0.002298,0.002547,0.064704,0.327969,0.016708,0.647037,-137.668549,0.065710,0.000000
12.110001,0.102028,-137.624069,-0.002199,0.002645,0.067175,0.453843,0.023120,0.671753,-137.624069,0.068207,0.000000
12.260000,0.265503,-137.713028,-0.002113,0.002746,0.069742,1.181016,0.060164,0.697423,-137.713028,0.070705,0.000000
12.410001,0.670639,-137.713028,-0.002026,0.000006,0.000156,2.983151,0.151969,0.001561,-137.713028,0.001284,0.000000
12.560000,0.587227,-137.713028,-0.002001,-0.000001,-0.000026,2.612116,0.133068,-0.000260,-137.713028,0.000182,0.000000
12.710001,0.574196,-137.757507,-0.002001,-0.000001,-0.000035,2.554151,0.130115,-0.000347,-137.757507,0.000182,0.000000
12.860001,0.552597,-137.757507,-0.002022,-0.000001,-0.000035,2.458074,0.125220,-0.000347,-137.757507,0.000182,0.000000
13.010000,0.507538,-137.757507,-0.002005,-0.000001,-0.000026,2.257641,0.115010,-0.000260,-137.757507,0.000260,0.000000
13.160001,0.518341,-137.757507,-0.002013,-0.000001,-0.000026,2.305696,0.117458,-0.000260,-137.757507,0.000512,0.000000
13.310000,0.520203,-137.801987,-0.002009,-0.000001,-0.000026,2.313977,0.117880,-0.000260,-137.801987,0.000763,0.000000
13.460001,0.500465,-137.757507,-0.001996,-0.000001,-0.000026,2.226181,0.113407,-0.000260,-137.757507,0.001015,0.000000
13.610001,0.698196,-137.713028,-0.001996,0.000021,0.000529,3.105733,0.158214,0.005290,-137.713028,0.001257,0.000000
13.760000,0.816238,-137.801987,-0.001983,0.000031,0.000798,3.630810,0.184962,0.007979,-137.801987,0.001509,0.000000
13.910001,0.898529,-137.801987,-0.001983,0.000041,0.001032,3.996857,0.203610,0.010320,-137.801987,0.001760,0.000000
14.060000,0.929070,-137.846466,-0.001979,0.000048,0.001231,4.132708,0.210530,0.012315,-137.846466,0.002012,0.000000
14.210001,1.002800,-137.846466,-0.001957,0.000057,0.001440,4.460677,0.227238,0.014396,-137.846466,0.002263,0.000000
14.360001,1.033333,-137.890945,-0.001953,0.000062,0.001570,4.596494,0.234157,0.015697,-137.890945,0.002515,0.000000
14.510000,1.222496,-137.846466,-0.001927,0.000074,0.001891,5.437934,0.277022,0.018906,-137.846466,0.002758,0.000000
14.660001,1.330856,-137.890945,-0.001957,0.000083,0.002107,5.919945,0.301576,0.021074,-137.890945,0.003009,0.000000
14.810000,1.535286,-137.890945,-0.001940,0.000095,0.002402,6.829293,0.347901,0.024022,-137.890945,0.003261,0.000000
14.960001,1.686104,-137.890945,-0.001927,0.000104,0.002645,7.500165,0.382077,0.026450,-137.890945,0.003512,0.000000
15.110001,1.787384,-137.890945,-0.001906,0.000111,0.002818,7.950681,0.405027,0.028185,-137.890945,0.003764,0.000000
15.260001,1.869308,-137.935425,-0.001932,0.000117,0.002966,8.315100,0.423591,0.029659,-137.935425,0.004007,0.000000
15.410001,2.275566,-137.935425,-0.001910,0.000134,0.003408,10.122224,0.515651,0.034082,-137.935425,0.004258,0.000000
15.560000,2.566391,-137.979904,-0.001901,0.000148,0.003764,11.415877,0.581553,0.037638,-137.979904,0.004510,0.000000
15.710001,2.773804,-137.979904,-0.001880,0.000158,0.004007,12.338495,0.628553,0.040066,-137.979904,0.004761,0.000000
15.860001,3.035576,-137.979904,-0.001871,0.000168,0.004258,13.502915,0.687871,0.042581,-137.979904,0.005013,0.000000
16.010000,3.360291,-137.979904,-0.001871,0.000178,0.004510,14.947319,0.761453,0.045096,-137.979904,0.005264,0.000000
16.160000,3.485779,-138.024384,-0.001854,0.000184,0.004683,15.505519,0.789889,0.046830,-138.024384,0.005507,0.000000
16.310001,3.696167,-138.024384,-0.001863,0.000190,0.004830,16.441372,0.837563,0.048304,-138.024384,0.005758,0.000000
16.460001,3.964272,-138.068878,-0.001854,0.000199,0.005047,17.633961,0.898317,0.050473,-138.068878,0.006010,0.000000
16.610001,4.179504,-138.068878,-0.001845,0.000206,0.005238,18.591364,0.947089,0.052380,-138.068878,0.006261,0.000000
16.760000,4.924622,-138.068878,-0.001832,0.000222,0.005637,21.905811,1.115935,0.056370,-138.068878,0.006513,0.000000
16.910002,5.309288,-138.068878,-0.001828,0.000231,0.005880,23.616892,1.203102,0.058798,-138.068878,0.006764,0.000000
17.060001,5.612770,-138.113358,-0.001828,0.000241,0.006131,24.966848,1.271872,0.061313,-138.113358,0.007007,0.000000
17.210001,5.836563,-138.113358,-0.001815,0.000247,0.006270,25.962330,1.322584,0.062700,-138.113358,0.007259,0.000000
17.360001,6.275589,-138.113358,-0.001815,0.000258,0.006548,27.915215,1.422069,0.065476,-138.113358,0.007510,0.000000
17.510000,7.030762,-138.157837,-0.001802,0.000271,0.006894,31.274389,1.593193,0.068944,-138.157837,0.007762,0.000000
17.660002,7.575546,-138.157837,-0.001807,0.000283,0.007189,33.697712,1.716643,0.071893,-138.157837,0.008013,0.000000
17.810001,8.116974,-138.202316,-0.001781,0.000293,0.007449,36.106102,1.839333,0.074495,-138.202316,0.008265,0.000000
17.960001,8.620422,-138.202316,-0.001789,0.000303,0.007701,38.345554,1.953416,0.077010,-138.202316,0.008507,0.000000
18.110001,8.793571,-138.157837,-0.001781,0.000307,0.007805,39.115761,1.992652,0.078050,-138.157837,0.008759,0.000000
18.260000,9.319733,-138.202316,-0.001781,0.000317,0.008057,41.456242,2.111882,0.080565,-138.202316,0.009010,0.000000
18.410002,9.798607,-138.291275,-0.001776,0.000325,0.008265,43.586380,2.220396,0.082646,-138.291275,0.009262,0.000000
18.560001,10.333336,-138.157837,-0.001772,0.000334,0.008473,45.964973,2.341568,0.084728,-138.157837,0.009513,0.000000
18.710001,11.022598,-138.246796,-0.001763,0.000347,0.008802,49.030968,2.497756,0.088023,-138.246796,0.009765,0.000000
18.860001,11.855965,-138.246796,-0.001759,0.000356,0.009054,52.737965,2.686600,0.090538,-138.246796,0.010008,0.000000
19.010000,12.214188,-138.246796,-0.001772,0.000364,0.009236,54.331421,2.767774,0.092359,-138.246796,0.010259,0.000000
19.160002,12.655075,-138.246796,-0.001768,0.000370,0.009409,56.292587,2.867681,0.094094,-138.246796,0.010511,0.000000
19.310001,13.158150,-138.291275,-0.001729,0.000378,0.009600,58.530373,2.981679,0.096002,-138.291275,0.010762,0.000000
19.460001,14.668495,-138.291275,-0.001733,0.000399,0.010129,65.248726,3.323928,0.101292,-138.291275,0.011014,0.000000
19.610001,15.374138,-138.335754,-0.001742,0.000410,0.010407,68.387581,3.483829,0.104067,-138.335754,0.011265,0.000000
19.760000,16.032120,-138.335754,-0.001738,0.000420,0.010658,71.314430,3.632930,0.106582,-138.335754,0.011508,0.000000
19.910002,16.616005,-138.335754,-0.001725,0.000430,0.010918,73.911682,3.765240,0.109184,-138.335754,0.011760,0.000000
20.060001,17.216637,-138.335754,-0.001725,0.000438,0.011118,76.583427,3.901346,0.111178,-138.335754,0.012011,0.000000
20.210001,17.915581,-138.335754,-0.001733,0.000449,0.011404,79.692482,4.059729,0.114040,-138.335754,0.012263,0.000000
20.360001,18.199699,-138.335754,-0.001716,0.000451,0.011456,80.956306,4.124111,0.114560,-138.335754,0.012514,0.000000
20.510000,19.075150,-138.335754,-0.001716,0.000465,0.011812,84.850502,4.322491,0.118116,-138.335754,0.012766,0.000000
20.660002,19.850426,-138.424713,-0.001703,0.000475,0.012054,88.299103,4.498170,0.120544,-138.424713,0.013008,0.000000
20.810001,20.610817,-138.424713,-0.001725,0.000485,0.012315,91.681496,4.670478,0.123146,-138.424713,0.013260,0.000000
20.960001,21.160439,-138.469208,-0.001699,0.000493,0.012514,94.126335,4.795024,0.125141,-138.469208,0.013511,0.000000
21.110001,21.930878,-138.424713,-0.001686,0.000504,0.012800,97.553413,4.969608,0.128003,-138.424713,0.013763,0.000000
21.260000,22.764992,-138.469208,-0.001686,0.000515,0.013086,101.263741,5.158621,0.130864,-138.469208,0.014014,0.000000
21.410002,23.546974,-138.469208,-0.001699,0.000524,0.013312,104.742172,5.335821,0.133119,-138.469208,0.014266,0.000000
21.560001,24.532639,-138.513687,-0.001677,0.000535,0.013598,109.126625,5.559175,0.135981,-138.513687,0.014509,0.000000
21.710001,25.465805,-138.513687,-0.001681,0.000548,0.013928,113.277557,5.770634,0.139276,-138.513687,0.014760,0.000000
21.860001,26.124908,-138.513687,-0.001669,0.000558,0.014162,116.209396,5.919989,0.141618,-138.513687,0.015012,0.000000
22.010000,26.805603,-138.513687,-0.001686,0.000567,0.014405,119.237274,6.074236,0.144046,-138.513687,0.015263,0.000000
22.160002,27.237923,-138.469208,-0.001664,0.000572,0.014535,121.160332,6.172202,0.145347,-138.469208,0.015515,0.000000
22.310001,28.106300,-138.558167,-0.001673,0.000583,0.014804,125.023071,6.368979,0.148036,-138.558167,0.015757,0.000000
22.460001,28.908386,-138.513687,-0.001656,0.000592,0.015046,128.590927,6.550734,0.150464,-138.513687,0.016009,0.000000
22.610001,29.773407,-138.513687,-0.001660,0.000604,0.015333,132.438736,6.746750,0.153325,-138.513687,0.016260,0.000000
22.760000,30.413521,-138.558167,-0.001647,0.000611,0.015532,135.286102,6.891802,0.155320,-138.558167,0.016512,0.000000
22.910002,31.018250,-138.558167,-0.001660,0.000620,0.015740,137.976059,7.028836,0.157401,-138.558167,0.016763,0.000000
23.060001,31.390625,-138.602646,-0.001651,0.000628,0.015948,139.632477,7.113217,0.159483,-138.602646,0.017015,0.000000
23.210001,32.451141,-138.602646,-0.001656,0.000641,0.016278,144.349884,7.353534,0.162778,-138.602646,0.017258,0.000000
23.360001,33.506073,-138.647125,-0.001643,0.000651,0.016538,149.042450,7.592585,0.165380,-138.647125,0.017509,0.000000
23.510000,34.200172,-138.602646,-0.001630,0.000662,0.016824,152.129959,7.749870,0.168242,-138.602646,0.017761,0.000000
23.660002,35.319527,-138.558167,-0.001643,0.000673,0.017084,157.109100,8.003519,0.170844,-138.558167,0.018012,0.000000
23.810001,36.035225,-138.691605,-0.001634,0.000681,0.017301,160.292679,8.165699,0.173012,-138.691605,0.018264,0.000000
23.960001,36.983284,-138.736084,-0.001634,0.000694,0.017631,164.509857,8.380532,0.176307,-138.736084,0.018515,0.000000
24.110001,37.625259,-138.691605,-0.001608,0.000702,0.017830,167.365509,8.526006,0.178302,-138.691605,0.018758,0.000000
24.260000,38.357712,-138.647125,-0.001613,0.000712,0.018073,170.623627,8.691981,0.180730,-138.647125,0.019010,0.000000
24.410002,38.781097,-138.691605,-0.001613,0.000717,0.018203,172.506943,8.787923,0.182031,-138.691605,0.019261,0.000000
24.560001,39.982750,-138.647125,-0.001617,0.000732,0.018593,177.852158,9.060220,0.185933,-138.647125,0.019513,0.000000
24.710001,40.486938,-138.780563,-0.001617,0.000737,0.018715,180.094894,9.174471,0.187147,-138.780563,0.019764,0.000000
24.860001,41.601448,-138.736084,-0.001600,0.000751,0.019088,185.052490,9.427023,0.190876,-138.736084,0.020016,0.000000
25.010002,42.065056,-138.825043,-0.001600,0.000756,0.019200,187.114716,9.532078,0.192004,-138.825043,0.020258,0.000000
25.160002,42.574089,-138.780563,-0.001604,0.000764,0.019417,189.379013,9.647427,0.194172,-138.780563,0.020510,0.000000
25.310001,44.187950,-138.825043,-0.001595,0.000780,0.019807,196.557816,10.013132,0.198074,-138.825043,0.020761,0.000000
25.460001,45.314003,-138.825043,-0.001600,0.000794,0.020172,201.566757,10.268300,0.201717,-138.825043,0.021013,0.000000
25.610001,46.084816,-138.869522,-0.001582,0.000804,0.020432,204.995499,10.442968,0.204318,-138.869522,0.021264,0.000000
25.760002,46.730507,-138.869522,-0.001582,0.000813,0.020657,207.867676,10.589285,0.206573,-138.869522,0.021516,0.000000
25.910002,47.408600,-138.869522,-0.001582,0.000820,0.020831,210.883987,10.742942,0.208308,-138.869522,0.021759,0.000000
26.060001,48.201004,-138.869522,-0.001569,0.000831,0.021100,214.408768,10.922503,0.210996,-138.869522,0.022010,0.000000
26.210001,48.739082,-138.914017,-0.001578,0.000839,0.021308,216.802261,11.044434,0.213077,-138.914017,0.022262,0.000000
26.360001,49.576180,-138.825043,-0.001569,0.000850,0.021585,220.525864,11.234123,0.215853,-138.825043,0.022513,0.000000
26.510002,50.722343,-138.825043,-0.001565,0.000863,0.021932,225.624252,11.493848,0.219321,-138.825043,0.022765,0.000000
26.660002,51.473045,-138.914017,-0.001569,0.000870,0.022106,228.963547,11.663959,0.221056,-138.914017,0.023016,0.000000
26.810001,51.975746,-138.869522,-0.001552,0.000877,0.022279,231.199661,11.777872,0.222790,-138.869522,0.023259,0.000000
26.960001,52.330246,-139.002975,-0.001569,0.000881,0.022374,232.776566,11.858203,0.223744,-139.002975,0.023510,0.000000
27.110001,52.892159,-138.958496,-0.001548,0.000889,0.022591,235.276077,11.985535,0.225912,-138.958496,0.023762,0.000000
27.260002,54.476227,-138.914017,-0.001548,0.000906,0.023016,242.322357,12.344489,0.230162,-138.914017,0.024013,0.000000
27.410002,55.394501,-138.958496,-0.001548,0.000918,0.023311,246.407043,12.552573,0.233110,-138.958496,0.024265,0.000000
27.560001,56.336975,-138.958496,-0.001552,0.000929,0.023597,250.599380,12.766141,0.235972,-138.958496,0.024516,0.000000
27.710001,57.026978,-139.002975,-0.001544,0.000939,0.023840,253.668671,12.922498,0.238400,-139.002975,0.024759,0.000000
27.860001,57.915085,-139.002975,-0.001535,0.000950,0.024135,257.619171,13.123746,0.241349,-139.002975,0.025011,0.000000
28.010002,58.437523,-139.002975,-0.001539,0.000955,0.024265,259.943085,13.242132,0.242650,-139.002975,0.025262,0.000000
28.160002,59.428040,-139.047455,-0.001535,0.000968,0.024595,264.349121,13.466587,0.245945,-139.047455,0.025514,0.000000
28.310001,60.105011,-139.047455,-0.001518,0.000978,0.024846,267.360443,13.619990,0.248460,-139.047455,0.025765,0.000000
28.460001,60.884010,-139.091934,-0.001526,0.000989,0.025132,270.825592,13.796515,0.251322,-139.091934,0.026008,0.000000
28.610001,61.670837,-139.136414,-0.001526,0.000999,0.025366,274.325592,13.974812,0.253663,-139.136414,0.026260,0.000000
28.760002,62.426010,-139.002975,-0.001518,0.001007,0.025583,277.684753,14.145936,0.255832,-139.002975,0.026511,0.000000
28.910002,62.308708,-139.091934,-0.001518,0.001008,0.025609,277.162964,14.119355,0.256092,-139.091934,0.026763,0.000000
29.060001,63.486153,-139.136414,-0.001509,0.001028,0.026121,282.400513,14.386168,0.261208,-139.136414,0.027014,0.000000
29.210001,64.633797,-139.091934,-0.001505,0.001039,0.026390,287.505493,14.646228,0.263897,-139.091934,0.027266,0.000000
29.360001,65.391960,-139.180893,-0.001500,0.001049,0.026633,290.877960,14.818030,0.266325,-139.180893,0.027508,0.000000
29.510002,66.042854,-139.136414,-0.001496,0.001060,0.026927,293.773285,14.965525,0.269274,-139.136414,0.027760,0.000000
29.660002,66.680733,-139.136414,-0.001496,0.001068,0.027118,296.610718,15.110070,0.271182,-139.136414,0.028011,0.000000
29.810001,67.216209,-139.136414,-0.001483,0.001078,0.027370,298.992645,15.231411,0.273696,-139.136414,0.028263,0.000000
29.960001,67.403145,-139.180893,-0.001492,0.001074,0.027283,299.824158,15.273770,0.272829,-139.180893,0.027508,0.000000
30.110001,67.018852,-139.225372,-0.001475,0.001074,0.027283,298.114746,15.186688,0.272829,-139.225372,0.027508,0.000000
30.260002,66.678123,-139.136414,-0.001475,0.001074,0.027283,296.599121,15.109479,0.272829,-139.136414,0.027508,0.000000
30.410002,66.423424,-139.269852,-0.001479,0.001073,0.027266,295.466156,15.051763,0.272656,-139.269852,0.027283,0.000000
30.560001,66.124779,-139.225372,-0.001483,0.001073,0.027257,294.137695,14.984089,0.272569,-139.225372,0.027283,0.000000
30.710001,65.856682,-139.225372,-0.001466,0.001073,0.027248,292.945160,14.923338,0.272482,-139.225372,0.027283,0.000000
30.860001,65.614265,-139.225372,-0.001470,0.001073,0.027248,291.866821,14.868405,0.272482,-139.225372,0.027283,0.000000
31.010002,65.380409,-139.269852,-0.001483,0.001073,0.027248,290.826599,14.815413,0.272482,-139.269852,0.027283,0.000000
31.160002,65.176720,-139.314346,-0.001466,0.001072,0.027240,289.920532,14.769256,0.272396,-139.314346,0.027283,0.000000
31.310001,64.978615,-139.358826,-0.001475,0.001072,0.027240,289.039307,14.724364,0.272396,-139.358826,0.027283,0.000000
31.460001,64.784981,-139.314346,-0.001470,0.001072,0.027240,288.177979,14.680487,0.272396,-139.314346,0.027283,0.000000
31.610001,64.624870,-139.358826,-0.001457,0.001072,0.027240,287.465790,14.644205,0.272396,-139.358826,0.027283,0.000000
31.760002,64.447243,-139.314346,-0.001466,0.001072,0.027240,286.675659,14.603953,0.272396,-139.314346,0.027283,0.000000
31.910002,64.290474,-139.403305,-0.001470,0.001072,0.027240,285.978302,14.568430,0.272396,-139.403305,0.027283,0.000000
32.060001,64.136681,-139.358826,-0.001462,0.001072,0.027240,285.294189,14.533580,0.272396,-139.358826,0.027283,0.000000
32.210003,63.988487,-139.314346,-0.001457,0.001072,0.027240,284.635010,14.499999,0.272396,-139.314346,0.027283,0.000000
32.360001,63.855171,-139.403305,-0.001466,0.001072,0.027240,284.041992,14.469789,0.272396,-139.403305,0.027283,0.000000
32.510002,63.728569,-139.358826,-0.001457,0.001072,0.027240,283.478821,14.441101,0.272396,-139.358826,0.027283,0.000000
32.660000,63.613503,-139.403305,-0.001466,0.001072,0.027240,282.966980,14.415026,0.272396,-139.403305,0.027283,0.000000
32.810001,63.485405,-139.447784,-0.001462,0.001072,0.027240,282.397186,14.385999,0.272396,-139.447784,0.027283,0.000000
32.960003,63.387474,-139.447784,-0.001453,0.001072,0.027240,281.961578,14.363807,0.272396,-139.447784,0.027283,0.000000
33.110001,63.265709,-139.447784,-0.001466,0.001072,0.027240,281.419922,14.336215,0.272396,-139.447784,0.027283,0.000000
33.260002,63.152138,-139.447784,-0.001466,0.001072,0.027240,280.914734,14.310478,0.272396,-139.447784,0.027283,0.000000
33.410000,63.051964,-139.492264,-0.001470,0.001072,0.027240,280.469147,14.287779,0.272396,-139.492264,0.027283,0.000000
33.560001,62.951050,-139.536743,-0.001444,0.001072,0.027240,280.020264,14.264912,0.272396,-139.536743,0.027283,0.000000
33.710003,62.874718,-139.492264,-0.001457,0.001072,0.027240,279.680725,14.247614,0.272396,-139.492264,0.027283,0.000000
33.860001,62.761513,-139.536743,-0.001444,0.001072,0.027240,279.177155,14.221962,0.272396,-139.536743,0.027283,0.000000
34.010002,62.694115,-139.581223,-0.001453,0.001072,0.027240,278.877350,14.206690,0.272396,-139.581223,0.027283,0.000000
34.160000,62.598419,-139.581223,-0.001457,0.001072,0.027240,278.451691,14.185005,0.272396,-139.581223,0.027283,0.000000
34.310001,62.523193,-139.492264,-0.001457,0.001072,0.027240,278.117065,14.167958,0.272396,-139.492264,0.027283,0.000000
34.460003,62.439781,-139.670181,-0.001453,0.001072,0.027240,277.746033,14.149056,0.272396,-139.670181,0.027283,0.000000
34.610001,62.351158,-139.625702,-0.001453,0.001072,0.027240,277.351807,14.128974,0.272396,-139.625702,0.027283,0.000000
34.760002,62.278175,-139.625702,-0.001436,0.001072,0.027240,277.027161,14.112435,0.272396,-139.625702,0.027283,0.000000
34.910000,62.210403,-139.625702,-0.001453,0.001072,0.027240,276.725708,14.097078,0.272396,-139.625702,0.027283,0.000000
35.060001,62.138535,-139.670181,-0.001457,0.001072,0.027240,276.406006,14.080793,0.272396,-139.670181,0.027283,0.000000
35.210003,62.064064,-139.670181,-0.001453,0.001072,0.027240,276.074738,14.063918,0.272396,-139.670181,0.027283,0.000000
35.360001,61.993309,-139.670181,-0.001449,0.001072,0.027240,275.760010,14.047885,0.272396,-139.670181,0.027283,0.000000
35.510002,61.919952,-139.670181,-0.001444,0.001072,0.027240,275.433716,14.031262,0.272396,-139.670181,0.027283,0.000000
35.660000,61.861115,-139.670181,-0.001457,0.001072,0.027240,275.171967,14.017929,0.272396,-139.670181,0.027283,0.000000
35.810001,61.794090,-139.670181,-0.001449,0.001072,0.027240,274.873840,14.002742,0.272396,-139.670181,0.027283,0.000000
35.960003,61.732277,-139.670181,-0.001444,0.001072,0.027240,274.598877,13.988734,0.272396,-139.670181,0.027283,0.000000
36.110001,61.677910,-139.714661,-0.001440,0.001072,0.027240,274.357056,13.976414,0.272396,-139.714661,0.027283,0.000000
36.260002,61.608650,-139.714661,-0.001444,0.001072,0.027240,274.048950,13.960720,0.272396,-139.714661,0.027283,0.000000
36.410000,61.559868,-139.759155,-0.001449,0.001072,0.027240,273.831970,13.949665,0.272396,-139.759155,0.027283,0.000000
36.560001,61.501030,-139.803635,-0.001444,0.001072,0.027240,273.570251,13.936333,0.272396,-139.803635,0.027283,0.000000
36.710003,61.445175,-139.759155,-0.001453,0.001072,0.027240,273.321777,13.923676,0.272396,-139.759155,0.027283,0.000000
36.860001,61.382248,-139.848114,-0.001440,0.001072,0.027240,273.041870,13.909416,0.272396,-139.848114,0.027283,0.000000
37.010002,61.327133,-139.803635,-0.001431,0.001072,0.027240,272.796722,13.896927,0.272396,-139.803635,0.027283,0.000000
37.160004,61.279846,-139.848114,-0.001453,0.001072,0.027240,272.586365,13.886211,0.272396,-139.848114,0.027283,0.000000
37.310001,61.237022,-139.803635,-0.001457,0.001072,0.027240,272.395874,13.876508,0.272396,-139.803635,0.027283,0.000000
37.460003,61.190475,-139.848114,-0.001444,0.001072,0.027240,272.188843,13.865959,0.272396,-139.848114,0.027283,0.000000
37.610001,61.141319,-139.848114,-0.001449,0.001072,0.027240,271.970184,13.854821,0.272396,-139.848114,0.027283,0.000000
37.760002,61.090309,-139.848114,-0.001440,0.001072,0.027240,271.743256,13.843262,0.272396,-139.848114,0.027283,0.000000
37.910004,61.038918,-139.892593,-0.001453,0.001072,0.027240,271.514679,13.831616,0.272396,-139.892593,0.027283,0.000000
38.060001,60.996841,-139.937073,-0.001449,0.001072,0.027240,271.327515,13.822082,0.272396,-139.937073,0.027283,0.000000
38.210003,60.955879,-139.848114,-0.001444,0.001072,0.027240,271.145294,13.812800,0.272396,-139.848114,0.027283,0.000000
38.360001,60.901512,-139.892593,-0.001440,0.001072,0.027240,270.903442,13.800480,0.272396,-139.892593,0.027283,0.000000
38.510002,60.857948,-139.937073,-0.001444,0.001072,0.027240,270.709686,13.790607,0.272396,-139.937073,0.027283,0.000000
38.660004,60.821083,-139.892593,-0.001444,0.001072,0.027240,270.545685,13.782255,0.272396,-139.892593,0.027283,0.000000
38.810001,60.769325,-139.981552,-0.001444,0.001072,0.027240,270.315460,13.770527,0.272396,-139.981552,0.027283,0.000000
38.960003,60.737671,-139.981552,-0.001440,0.001072,0.027240,270.174652,13.763352,0.272396,-139.981552,0.027283,0.000000
39.110001,60.699692,-139.981552,-0.001449,0.001072,0.027240,270.005707,13.754747,0.272396,-139.981552,0.027283,0.000000
39.260002,60.657234,-140.026031,-0.001444,0.001072,0.027240,269.816864,13.745126,0.272396,-140.026031,0.027283,0.000000
39.410004,60.621864,-139.981552,-0.001449,0.001072,0.027240,269.659515,13.737110,0.272396,-139.981552,0.027283,0.000000
39.560001,60.587975,-139.981552,-0.001444,0.001072,0.027240,269.508759,13.729431,0.272396,-139.981552,0.027283,0.000000
39.710003,60.539192,-139.981552,-0.001444,0.001072,0.027240,269.291779,13.718377,0.272396,-139.981552,0.027283,0.000000
39.860001,60.504196,-140.070511,-0.001440,0.001072,0.027240,269.136108,13.710447,0.272396,-140.070511,0.027283,0.000000
40.010002,60.462112,-140.026031,-0.001436,0.001072,0.027240,268.948914,13.700911,0.272396,-140.026031,0.027283,0.000000
40.160004,60.426369,-140.070511,-0.001444,0.001072,0.027240,268.789917,13.692811,0.272396,-140.070511,0.027283,0.000000
40.310001,60.397697,-140.114990,-0.001453,0.001072,0.027240,268.662384,13.686315,0.272396,-140.114990,0.027283,0.000000
40.460003,60.372375,-140.114990,-0.001440,0.001072,0.027240,268.549744,13.680575,0.272396,-140.114990,0.027283,0.000000
40.610001,60.330292,-140.114990,-0.001444,0.001072,0.027240,268.362549,13.671040,0.272396,-140.114990,0.027283,0.000000
40.760002,60.287102,-140.159470,-0.001444,0.001072,0.027240,268.170410,13.661252,0.272396,-140.159470,0.027283,0.000000
40.910004,60.250237,-140.203964,-0.001449,0.001072,0.027240,268.006439,13.652899,0.272396,-140.203964,0.027283,0.000000
41.060001,60.207787,-140.114990,-0.001449,0.001072,0.027240,267.817596,13.643280,0.272396,-140.114990,0.027283,0.000000
41.210003,60.173157,-140.203964,-0.001431,0.001072,0.027240,267.663574,13.635432,0.272396,-140.203964,0.027283,0.000000
41.360001,60.146713,-140.114990,-0.001440,0.001072,0.027240,267.545929,13.629439,0.272396,-140.114990,0.027283,0.000000
41.510002,60.122887,-140.203964,-0.001440,0.001072,0.027240,267.439972,13.624041,0.272396,-140.203964,0.027283,0.000000
41.660004,60.088997,-140.203964,-0.001440,0.001072,0.027240,267.289215,13.616362,0.272396,-140.203964,0.027283,0.000000
41.810001,60.060326,-140.203964,-0.001440,0.001072,0.027240,267.161682,13.609864,0.272396,-140.203964,0.027283,0.000000
41.960003,60.027931,-140.248444,-0.001453,0.001072,0.027240,267.017578,13.602524,0.272396,-140.248444,0.027283,0.000000
42.110001,60.000748,-140.248444,-0.001440,0.001072,0.027240,266.896667,13.596363,0.272396,-140.248444,0.027283,0.000000
42.260002,59.969467,-140.248444,-0.001431,0.001072,0.027240,266.757507,13.589276,0.272396,-140.248444,0.027283,0.000000
42.410004,59.936325,-140.248444,-0.001436,0.001072,0.027240,266.610077,13.581765,0.272396,-140.248444,0.027283,0.000000
42.560001,59.899834,-140.292923,-0.001444,0.001072,0.027240,266.447754,13.573497,0.272396,-140.292923,0.027283,0.000000
42.710003,59.871902,-140.337402,-0.001444,0.001072,0.027240,266.323517,13.567167,0.272396,-140.337402,0.027283,0.000000
42.860001,59.841743,-140.337402,-0.001436,0.001072,0.027240,266.189362,13.560333,0.272396,-140.337402,0.027283,0.000000
43.010002,59.813072,-140.292923,-0.001436,0.001072,0.027240,266.061829,13.553836,0.272396,-140.292923,0.027283,0.000000
43.160004,59.785141,-140.292923,-0.001436,0.001072,0.027240,265.937592,13.547506,0.272396,-140.292923,0.027283,0.000000
43.310001,59.766525,-140.381882,-0.001436,0.001072,0.027240,265.854797,13.543288,0.272396,-140.381882,0.027283,0.000000
43.460003,59.744926,-140.337402,-0.001431,0.001072,0.027240,265.758698,13.538394,0.272396,-140.337402,0.027283,0.000000
43.610001,59.703590,-140.381882,-0.001431,0.001072,0.027240,265.574829,13.529027,0.272396,-140.381882,0.027283,0.000000
43.760002,59.686089,-140.426361,-0.001440,0.001072,0.027240,265.496979,13.525061,0.272396,-140.426361,0.027283,0.000000
43.910004,59.654808,-140.426361,-0.001436,0.001072,0.027240,265.357849,13.517972,0.272396,-140.426361,0.027283,0.000000
44.060001,59.618690,-140.426361,-0.001431,0.001072,0.027240,265.197174,13.509789,0.272396,-140.426361,0.027283,0.000000
44.210003,59.597839,-140.426361,-0.001431,0.001072,0.027240,265.104431,13.505064,0.272396,-140.426361,0.027283,0.000000
44.360001,59.563583,-140.426361,-0.001440,0.001072,0.027240,264.952057,13.497301,0.272396,-140.426361,0.027283,0.000000
44.510002,59.538628,-140.470840,-0.001453,0.001072,0.027240,264.841034,13.491646,0.272396,-140.470840,0.027283,0.000000
44.660004,59.509583,-140.470840,-0.001449,0.001072,0.027240,264.711853,13.485064,0.272396,-140.470840,0.027283,0.000000
44.810001,59.485756,-140.515320,-0.001440,0.001072,0.027240,264.605865,13.479665,0.272396,-140.515320,0.027283,0.000000
44.960003,59.458946,-140.470840,-0.001444,0.001072,0.027240,264.486603,13.473590,0.272396,-140.470840,0.027283,0.000000
45.110001,59.444794,-140.559799,-0.001444,0.001072,0.027240,264.423645,13.470384,0.272396,-140.559799,0.027283,0.000000
45.260002,59.423943,-140.559799,-0.001427,0.001072,0.027240,264.330902,13.465658,0.272396,-140.559799,0.027283,0.000000
45.410004,59.399361,-140.470840,-0.001431,0.001072,0.027240,264.221558,13.460088,0.272396,-140.470840,0.027283,0.000000
45.560001,59.370689,-140.559799,-0.001436,0.001072,0.027240,264.094025,13.453591,0.272396,-140.559799,0.027283,0.000000
45.710003,59.346489,-140.648773,-0.001449,0.001072,0.027240,263.986359,13.448107,0.272396,-140.648773,0.027283,0.000000
45.860001,59.322655,-140.559799,-0.001440,0.001072,0.027240,263.880341,13.442706,0.272396,-140.559799,0.027283,0.000000
46.010002,59.302544,-140.559799,-0.001427,0.001072,0.027240,263.790894,13.438148,0.272396,-140.559799,0.027283,0.000000
46.160004,59.279457,-140.604294,-0.001440,0.001072,0.027240,263.688202,13.432917,0.272396,-140.604294,0.027283,0.000000
46.310001,59.245949,-140.604294,-0.001431,0.001072,0.027240,263.539154,13.425324,0.272396,-140.604294,0.027283,0.000000
46.460003,59.212807,-140.648773,-0.001440,0.001072,0.027240,263.391724,13.417813,0.272396,-140.648773,0.027283,0.000000
46.610001,59.203865,-140.648773,-0.001436,0.001072,0.027240,263.351959,13.415788,0.272396,-140.648773,0.027283,0.000000
46.760002,59.177055,-140.604294,-0.001444,0.001072,0.027240,263.232697,13.409712,0.272396,-140.604294,0.027283,0.000000
46.910004,59.159554,-140.693253,-0.001431,0.001072,0.027240,263.154846,13.405746,0.272396,-140.693253,0.027283,0.000000
47.060001,59.147636,-140.693253,-0.001427,0.001072,0.027240,263.101837,13.403046,0.272396,-140.693253,0.027283,0.000000
47.210003,59.126785,-140.737732,-0.001431,0.001072,0.027240,263.009064,13.398320,0.272396,-140.737732,0.027283,0.000000
47.360001,59.111145,-140.737732,-0.001431,0.001072,0.027240,262.939514,13.394777,0.272396,-140.737732,0.027283,0.000000
47.510002,59.079498,-140.693253,-0.001440,0.001072,0.027240,262.798737,13.387606,0.272396,-140.693253,0.027283,0.000000
47.660004,59.052689,-140.693253,-0.001431,0.001072,0.027240,262.679474,13.381531,0.272396,-140.693253,0.027283,0.000000
47.810001,59.035187,-140.782211,-0.001436,0.001072,0.027240,262.601624,13.377564,0.272396,-140.782211,0.027283,0.000000
47.960003,59.009117,-140.782211,-0.001427,0.001072,0.027240,262.485657,13.371657,0.272396,-140.782211,0.027283,0.000000
48.110001,58.996460,-140.826691,-0.001440,0.001072,0.027240,262.429352,13.368789,0.272396,-140.826691,0.027283,0.000000
48.260002,58.981560,-140.782211,-0.001436,0.001072,0.027240,262.363068,13.365413,0.272396,-140.782211,0.027283,0.000000
48.410004,58.957733,-140.782211,-0.001436,0.001072,0.027240,262.257080,13.360013,0.272396,-140.782211,0.027283,0.000000
48.560001,58.920868,-140.782211,-0.001440,0.001072,0.027240,262.093109,13.351660,0.272396,-140.782211,0.027283,0.000000
48.710003,58.910065,-140.826691,-0.001440,0.001072,0.027240,262.045044,13.349212,0.272396,-140.826691,0.027283,0.000000
48.860001,58.892189,-140.871170,-0.001440,0.001072,0.027240,261.965546,13.345161,0.272396,-140.871170,0.027283,0.000000
49.010002,58.872459,-140.826691,-0.001431,0.001072,0.027240,261.877777,13.340690,0.272396,-140.826691,0.027283,0.000000
49.160004,58.850113,-140.871170,-0.001436,0.001072,0.027240,261.778381,13.335626,0.272396,-140.871170,0.027283,0.000000
49.310001,58.838943,-140.915649,-0.001436,0.001072,0.027240,261.728699,13.333095,0.272396,-140.915649,0.027283,0.000000
49.460003,58.818092,-140.915649,-0.001431,0.001072,0.027240,261.635956,13.328370,0.272396,-140.915649,0.027283,0.000000
49.610001,58.796120,-140.915649,-0.001436,0.001072,0.027240,261.538208,13.323391,0.272396,-140.915649,0.027283,0.000000
49.760002,58.774521,-140.915649,-0.001440,0.001072,0.027240,261.442139,13.318497,0.272396,-140.915649,0.027283,0.000000
49.910004,58.754784,-140.871170,-0.001427,0.001072,0.027240,261.354340,13.314024,0.272396,-140.871170,0.027283,0.000000
50.060001,58.729836,-140.915649,-0.001444,0.001072,0.027240,261.243347,13.308371,0.272396,-140.915649,0.027283,0.000000
50.210003,58.711220,-140.915649,-0.001427,0.001072,0.027240,261.160553,13.304153,0.272396,-140.915649,0.027283,0.000000
50.360001,58.694092,-141.004608,-0.001436,0.001072,0.027240,261.084351,13.300271,0.272396,-141.004608,0.027283,0.000000
50.510002,58.672867,-141.004608,-0.001440,0.001072,0.027240,260.989960,13.295462,0.272396,-141.004608,0.027283,0.000000
50.660004,58.660950,-141.004608,-0.001427,0.001072,0.027240,260.936951,13.292762,0.272396,-141.004608,0.027283,0.000000
50.810001,58.657967,-141.004608,-0.001431,0.001072,0.027240,260.923676,13.292085,0.272396,-141.004608,0.027283,0.000000
50.960003,58.615517,-141.049103,-0.001431,0.001072,0.027240,260.734833,13.282466,0.272396,-141.049103,0.027283,0.000000
51.110001,58.608444,-141.004608,-0.001431,0.001072,0.027240,260.703369,13.280863,0.272396,-141.004608,0.027283,0.000000
51.260002,58.585358,-141.049103,-0.001440,0.001072,0.027240,260.600677,13.275632,0.272396,-141.049103,0.027283,0.000000
51.410004,58.571579,-141.093582,-0.001427,0.001072,0.027240,260.539398,13.272510,0.272396,-141.093582,0.027283,0.000000
51.560001,58.561150,-141.004608,-0.001431,0.001072,0.027240,260.493011,13.270146,0.272396,-141.004608,0.027283,0.000000
51.710003,58.536201,-141.093582,-0.001423,0.001072,0.027240,260.382019,13.264493,0.272396,-141.093582,0.027283,0.000000
51.860001,58.520195,-141.093582,-0.001431,0.001072,0.027240,260.310822,13.260866,0.272396,-141.093582,0.027283,0.000000
52.010002,58.505295,-141.138062,-0.001431,0.001072,0.027240,260.244537,13.257489,0.272396,-141.138062,0.027283,0.000000
52.160004,58.490776,-141.182541,-0.001449,0.001072,0.027240,260.179962,13.254199,0.272396,-141.182541,0.027283,0.000000
52.310001,58.460983,-141.138062,-0.001423,0.001072,0.027240,260.047455,13.247448,0.272396,-141.138062,0.027283,0.000000
52.460003,58.444229,-141.138062,-0.001427,0.001072,0.027240,259.972900,13.243651,0.272396,-141.138062,0.027283,0.000000
52.610001,58.434174,-141.227020,-0.001436,0.001072,0.027240,259.928192,13.241373,0.272396,-141.227020,0.027283,0.000000
52.760002,58.421143,-141.182541,-0.001431,0.001072,0.027240,259.870209,13.238420,0.272396,-141.182541,0.027283,0.000000
52.910004,58.397308,-141.271500,-0.001431,0.001072,0.027240,259.764191,13.233019,0.272396,-141.271500,0.027283,0.000000
53.060001,58.380180,-141.182541,-0.001427,0.001072,0.027240,259.688019,13.229138,0.272396,-141.182541,0.027283,0.000000
53.210003,58.365288,-141.227020,-0.001423,0.001072,0.027240,259.621765,13.225763,0.272396,-141.227020,0.027283,0.000000
53.360004,58.360069,-141.271500,-0.001436,0.001072,0.027240,259.598541,13.224581,0.272396,-141.271500,0.027283,0.000000
53.510002,58.345177,-141.227020,-0.001427,0.001072,0.027240,259.532318,13.221207,0.272396,-141.227020,0.027283,0.000000
53.660004,58.334381,-141.227020,-0.001444,0.001072,0.027240,259.484283,13.218760,0.272396,-141.227020,0.027283,0.000000
53.810001,58.312408,-141.360458,-0.001423,0.001072,0.027240,259.386536,13.213781,0.272396,-141.360458,0.027283,0.000000
53.960003,58.296768,-141.271500,-0.001431,0.001072,0.027240,259.316986,13.210237,0.272396,-141.271500,0.027283,0.000000
54.110004,58.287460,-141.404938,-0.001427,0.001072,0.027240,259.275574,13.208127,0.272396,-141.404938,0.027283,0.000000
54.260002,58.268845,-141.360458,-0.001423,0.001072,0.027240,259.192780,13.203909,0.272396,-141.360458,0.027283,0.000000
54.410004,58.243523,-141.360458,-0.001427,0.001072,0.027240,259.080139,13.198171,0.272396,-141.360458,0.027283,0.000000
54.560001,58.230484,-141.360458,-0.001436,0.001072,0.027240,259.022125,13.195216,0.272396,-141.360458,0.027283,0.000000
54.710003,58.205162,-141.404938,-0.001418,0.001072,0.027240,258.909485,13.189478,0.272396,-141.404938,0.027283,0.000000
54.860004,58.194366,-141.449417,-0.001436,0.001072,0.027240,258.861481,13.187033,0.272396,-141.449417,0.027283,0.000000
55.010002,58.168297,-141.449417,-0.001436,0.001072,0.027240,258.745514,13.181124,0.272396,-141.449417,0.027283,0.000000
55.160004,58.166435,-141.360458,-0.001427,0.001072,0.027240,258.737213,13.180703,0.272396,-141.360458,0.027283,0.000000
55.310001,58.136650,-141.404938,-0.001440,0.001072,0.027240,258.604736,13.173953,0.272396,-141.404938,0.027283,0.000000
55.460003,58.131065,-141.404938,-0.001418,0.001072,0.027240,258.579895,13.172688,0.272396,-141.404938,0.027283,0.000000
55.610004,58.119148,-141.493912,-0.001431,0.001072,0.027240,258.526886,13.169988,0.272396,-141.493912,0.027283,0.000000
55.760002,58.099785,-141.449417,-0.001431,0.001072,0.027240,258.440765,13.165599,0.272396,-141.449417,0.027283,0.000000
55.910004,58.095314,-141.493912,-0.001431,0.001072,0.027240,258.420868,13.164586,0.272396,-141.493912,0.027283,0.000000
56.060001,58.076698,-141.449417,-0.001440,0.001072,0.027240,258.338043,13.160368,0.272396,-141.449417,0.027283,0.000000
56.210003,58.060684,-141.493912,-0.001427,0.001072,0.027240,258.266815,13.156739,0.272396,-141.493912,0.027283,0.000000
56.360004,58.027168,-141.538391,-0.001431,0.001072,0.027240,258.117737,13.149144,0.272396,-141.538391,0.027283,0.000000
56.510002,58.031265,-141.538391,-0.001431,0.001072,0.027240,258.135956,13.150072,0.272396,-141.538391,0.027283,0.000000
56.660004,58.017860,-141.582870,-0.001414,0.001072,0.027240,258.076324,13.147035,0.272396,-141.582870,0.027283,0.000000
56.810001,58.009300,-141.627350,-0.001431,0.001072,0.027240,258.038269,13.145096,0.272396,-141.627350,0.027283,0.000000
56.960003,57.994400,-141.627350,-0.001427,0.001072,0.027240,257.971985,13.141720,0.272396,-141.627350,0.027283,0.000000
57.110004,57.969078,-141.627350,-0.001427,0.001072,0.027240,257.859344,13.135981,0.272396,-141.627350,0.027283,0.000000
57.260002,57.963867,-141.582870,-0.001431,0.001072,0.027240,257.836151,13.134800,0.272396,-141.582870,0.027283,0.000000
57.410004,57.940781,-141.627350,-0.001414,0.001072,0.027240,257.733459,13.129569,0.272396,-141.627350,0.027283,0.000000
57.560001,57.929985,-141.671829,-0.001431,0.001072,0.027240,257.685455,13.127122,0.272396,-141.671829,0.027283,0.000000
57.710003,57.903915,-141.671829,-0.001431,0.001072,0.027240,257.569489,13.121215,0.272396,-141.671829,0.027283,0.000000
57.860004,57.905029,-141.627350,-0.001436,0.001072,0.027240,257.574432,13.121468,0.272396,-141.627350,0.027283,0.000000
58.010002,57.890137,-141.671829,-0.001431,0.001072,0.027240,257.508179,13.118093,0.272396,-141.671829,0.027283,0.000000
58.160004,57.883064,-141.671829,-0.001427,0.001072,0.027240,257.476715,13.116489,0.272396,-141.671829,0.027283,0.000000
58.310001,57.873383,-141.671829,-0.001427,0.001072,0.027240,257.433655,13.114296,0.272396,-141.671829,0.027283,0.000000
58.460003,57.854759,-141.716309,-0.001431,0.001072,0.027240,257.350830,13.110076,0.272396,-141.716309,0.027283,0.000000
58.610004,57.834656,-141.716309,-0.001427,0.001072,0.027240,257.261383,13.105520,0.272396,-141.716309,0.027283,0.000000
58.760002,57.833168,-141.716309,-0.001444,0.001072,0.027240,257.254791,13.105184,0.272396,-141.716309,0.027283,0.000000
58.910004,57.810822,-141.805267,-0.001427,0.001072,0.027240,257.155365,13.100120,0.272396,-141.805267,0.027283,0.000000
59.060001,57.798164,-141.805267,-0.001423,0.001072,0.027240,257.099091,13.097251,0.272396,-141.805267,0.027283,0.000000
59.210003,57.796669,-141.760788,-0.001423,0.001072,0.027240,257.092438,13.096913,0.272396,-141.760788,0.027283,0.000000
59.360004,57.773216,-141.716309,-0.001431,0.001072,0.027240,256.988098,13.091599,0.272396,-141.716309,0.027283,0.000000
59.510002,57.765762,-141.894241,-0.001414,0.001072,0.027240,256.954956,13.089909,0.272396,-141.894241,0.027283,0.000000
59.660004,57.747147,-141.849747,-0.001418,0.001072,0.027240,256.872131,13.085690,0.272396,-141.849747,0.027283,0.000000
59.810001,57.741188,-141.849747,-0.001427,0.001072,0.027240,256.845642,13.084340,0.272396,-141.849747,0.027283,0.000000
59.960003,57.731506,-141.805267,-0.001414,0.001072,0.027240,256.802551,13.082147,0.272396,-141.805267,0.027283,0.000000
60.110004,57.717354,-141.849747,-0.001427,0.001072,0.027240,256.739624,13.078939,0.272396,-141.849747,0.027283,0.000000
60.260002,57.707306,-141.849747,-0.001423,0.001072,0.027240,256.694916,13.076662,0.272396,-141.849747,0.027283,0.000000
60.400002,57.690170,-141.849747,-0.001431,0.001072,0.027240,256.618683,13.072780,0.272396,-141.849747,0.027283,0.000000