File: Data/compression 10/AutoHeating-17-10-5-240424_04242024_232454.csv
Time (sec),S:Load (lbs),S:HL1 (DIM),S:LVDT (in),S:Position (in),Ch:Position (mm),Ch:Load (N),Ch:Stress (MPa),Ch:Strain (mm/mm),Ch:HL1 (DIM),Set Point (),Cycles ()
0.110000,-0.007446,-96.568146,-0.019548,-0.000976,-0.024794,-0.033123,-0.001687,-0.247940,-96.568146,-0.024603,0.000000
0.380000,-0.005219,-96.612625,-0.019544,-0.000976,-0.024794,-0.023213,-0.001183,-0.247940,-96.612625,-0.024603,0.000000
0.650000,0.007820,-96.657104,-0.019548,-0.000834,-0.021186,0.034786,0.001772,-0.211863,-96.657104,-0.020232,0.000000
0.920000,0.014519,-96.701584,-0.019372,-0.000656,-0.016668,0.064583,0.003290,-0.166681,-96.701584,-0.015740,0.000000
1.190000,-0.014900,-96.657104,-0.019204,-0.000486,-0.012341,-0.066279,-0.003376,-0.123406,-96.657104,-0.011248,0.000000
1.460000,0.000374,-96.746071,-0.019022,-0.000310,-0.007874,0.001663,0.000085,-0.078744,-96.746071,-0.006738,0.000000
1.730000,-0.032394,-96.746071,-0.018854,-0.000130,-0.003313,-0.144098,-0.007341,-0.033128,-96.746071,-0.002246,0.000000
2.000000,-0.042076,-96.790550,-0.018673,0.000045,0.001136,-0.187164,-0.009535,0.011361,-96.790550,0.002246,0.000000
2.270000,0.013405,-96.835030,-0.018496,0.000222,0.005646,0.059628,0.003038,0.056456,-96.835030,0.006756,0.000000
2.540000,-0.007080,-96.835030,-0.018298,0.000395,0.010042,-0.031494,-0.001604,0.100425,-96.835030,0.011248,0.000000
2.810000,0.020103,-96.879509,-0.018134,0.000576,0.014639,0.089425,0.004556,0.146388,-96.879509,0.015740,0.000000
3.080000,0.012283,-96.879509,-0.017932,0.000757,0.019235,0.054639,0.002783,0.192351,-96.879509,0.020250,0.000000
3.350000,-0.013031,-96.968475,-0.017755,0.000930,0.023623,-0.057965,-0.002953,0.236232,-96.968475,0.024742,0.000000
3.620000,-0.005219,-97.012955,-0.017561,0.001110,0.028185,-0.023213,-0.001183,0.281848,-97.012955,0.029234,0.000000
3.890000,-0.061073,-97.012955,-0.017406,0.001285,0.032634,-0.271668,-0.013839,0.326337,-97.012955,0.033744,0.000000
4.160000,-0.008194,-97.012955,-0.017229,0.001458,0.037022,-0.036449,-0.001857,0.370219,-97.012955,0.038236,0.000000
4.430000,0.019737,-97.146400,-0.017026,0.001647,0.041826,0.087796,0.004473,0.418263,-97.146400,0.042746,0.000000
4.700000,-0.010056,-97.146400,-0.016880,0.001812,0.046024,-0.044729,-0.002279,0.460237,-97.146400,0.047238,0.000000
4.970000,0.033142,-97.101913,-0.016681,0.001994,0.050637,0.147423,0.007510,0.506373,-97.101913,0.051730,0.000000
5.240000,0.007072,-97.057434,-0.016504,0.002173,0.055182,0.031460,0.001603,0.551816,-97.057434,0.056240,0.000000
5.510000,-0.006332,-97.190880,-0.016310,0.002351,0.059726,-0.028168,-0.001435,0.597258,-97.190880,0.060732,0.000000
5.780000,-0.005219,-97.190880,-0.016155,0.002525,0.064140,-0.023213,-0.001183,0.641400,-97.190880,0.065224,0.000000
6.050000,-0.027184,-97.235359,-0.015966,0.002699,0.068554,-0.120918,-0.006160,0.685542,-97.235359,0.069734,0.000000
6.320000,0.014145,-97.235359,-0.015810,0.002872,0.072951,0.062920,0.003205,0.729510,-97.235359,0.074226,0.000000
6.590000,-0.007820,-97.279839,-0.015608,0.003057,0.077651,-0.034786,-0.001772,0.776514,-97.279839,0.078718,0.000000
6.860000,0.020851,-97.279839,-0.015444,0.003235,0.082170,0.092750,0.004725,0.821696,-97.279839,0.083228,0.000000
7.130000,0.034630,-97.368805,-0.015267,0.003414,0.086714,0.154041,0.007847,0.867139,-97.368805,0.087720,0.000000
7.400001,0.000374,-97.368805,-0.015073,0.003590,0.091197,0.001663,0.000085,0.911974,-97.368805,0.092212,0.000000
7.670001,0.008934,-97.413284,-0.014883,0.003766,0.095664,0.039741,0.002024,0.956637,-97.413284,0.096722,0.000000
7.940001,-0.027184,-97.413284,-0.014720,0.003943,0.100147,-0.120918,-0.006160,1.001472,-97.413284,0.101214,0.000000
8.210000,0.000740,-97.502243,-0.014530,0.004119,0.104631,0.003292,0.000168,1.046308,-97.502243,0.105706,0.000000
8.480000,-0.001488,-97.546722,-0.014362,0.004297,0.109140,-0.006618,-0.000337,1.091403,-97.546722,0.110216,0.000000
8.750000,0.003349,-97.457764,-0.014194,0.004470,0.113546,0.014898,0.000759,1.135459,-97.457764,0.114708,0.000000
9.020000,0.046921,-97.502243,-0.013987,0.004647,0.118038,0.208714,0.010632,1.180381,-97.502243,0.119200,0.000000
9.290001,0.005959,-97.591209,-0.013805,0.004829,0.122652,0.026505,0.001350,1.226517,-97.591209,0.123710,0.000000
9.560000,0.004463,-97.546722,-0.013629,0.005006,0.127161,0.019853,0.001011,1.271613,-97.546722,0.128202,0.000000
9.830001,0.018242,-97.680168,-0.013456,0.005182,0.131610,0.081144,0.004134,1.316102,-97.680168,0.132694,0.000000
10.100000,-0.027557,-97.724648,-0.013249,0.005355,0.136007,-0.122581,-0.006245,1.360070,-97.724648,0.137204,0.000000
10.370001,0.021599,-97.724648,-0.013081,0.005532,0.140508,0.096076,0.004894,1.405079,-97.724648,0.141696,0.000000
10.640000,-0.012665,-97.680168,-0.012896,0.005715,0.145174,-0.056336,-0.002870,1.451736,-97.680168,0.146188,0.000000
10.910001,-0.011917,-97.680168,-0.012710,0.005892,0.149666,-0.053010,-0.002700,1.496658,-97.680168,0.150698,0.000000
11.180000,0.046173,-97.769127,-0.012542,0.006068,0.154115,0.205388,0.010463,1.541147,-97.769127,0.155190,0.000000
11.450001,-0.009682,-97.813614,-0.012365,0.006246,0.158642,-0.043066,-0.002194,1.586416,-97.813614,0.159682,0.000000
11.720000,0.038727,-97.813614,-0.012176,0.006423,0.163142,0.172265,0.008776,1.631425,-97.813614,0.164192,0.000000
11.990001,0.010796,-97.858093,-0.011999,0.006599,0.167617,0.048021,0.002446,1.676174,-97.858093,0.168684,0.000000
12.260000,-0.013031,-97.858093,-0.011826,0.006771,0.171980,-0.057965,-0.002953,1.719795,-97.858093,0.173176,0.000000
12.530001,0.021599,-97.947052,-0.011650,0.006949,0.176506,0.096076,0.004894,1.765064,-97.947052,0.177686,0.000000
12.800000,-0.051392,-97.902573,-0.011477,0.007131,0.181129,-0.228601,-0.011646,1.811288,-97.902573,0.182178,0.000000
13.070001,0.025688,-97.991531,-0.011292,0.007306,0.185560,0.114267,0.005821,1.855603,-97.991531,0.186670,0.000000
13.340001,0.035004,-97.902573,-0.011094,0.007488,0.190183,0.155704,0.007932,1.901826,-97.902573,0.191180,0.000000
13.610001,0.005959,-98.036018,-0.010925,0.007662,0.194605,0.026505,0.001350,1.946054,-98.036018,0.195672,0.000000
13.880001,0.045052,-98.080498,-0.010753,0.007837,0.199072,0.200399,0.010209,1.990717,-98.080498,0.200164,0.000000
14.150001,-0.006706,-98.080498,-0.010550,0.008019,0.203685,-0.029831,-0.001520,2.036853,-98.080498,0.204674,0.000000
14.420001,0.019737,-98.080498,-0.010382,0.008191,0.208056,0.087796,0.004473,2.080561,-98.080498,0.209166,0.000000
14.690001,0.001862,-98.124977,-0.010201,0.008367,0.212531,0.008281,0.000422,2.125310,-98.124977,0.213658,0.000000
14.960001,-0.028671,-98.124977,-0.010029,0.008542,0.216971,-0.127536,-0.006497,2.169712,-98.124977,0.218168,0.000000
15.230000,0.056602,-98.213943,-0.009848,0.008717,0.221403,0.251780,0.012826,2.214027,-98.213943,0.222660,0.000000
15.500001,0.001862,-98.258423,-0.009671,0.008902,0.226120,0.008281,0.000422,2.261204,-98.258423,0.227170,0.000000
15.770000,0.029045,-98.213943,-0.009494,0.009079,0.230604,0.129199,0.006582,2.306040,-98.213943,0.231662,0.000000
16.040001,0.047287,-98.302902,-0.009304,0.009261,0.235226,0.210343,0.010715,2.352263,-98.302902,0.236154,0.000000
16.310001,-0.008942,-98.347382,-0.009140,0.009429,0.239493,-0.039774,-0.002026,2.394930,-98.347382,0.240664,0.000000
16.580000,0.020103,-98.391861,-0.008968,0.009597,0.243760,0.089425,0.004556,2.437598,-98.391861,0.245156,0.000000
16.850000,0.006699,-98.347382,-0.008778,0.009786,0.248556,0.029797,0.001518,2.485555,-98.347382,0.249648,0.000000
17.120001,-0.005959,-98.391861,-0.008584,0.009961,0.253022,-0.026505,-0.001350,2.530218,-98.391861,0.254158,0.000000
17.390001,0.057343,-98.391861,-0.008395,0.010140,0.257557,0.255072,0.012994,2.575573,-98.391861,0.258650,0.000000
17.660002,0.000374,-98.436348,-0.008239,0.010318,0.262084,0.001663,0.000085,2.620843,-98.436348,0.263142,0.000000
17.930000,0.037239,-98.480827,-0.008037,0.010492,0.266507,0.165648,0.008438,2.665071,-98.480827,0.267652,0.000000
18.200001,0.033508,-98.525307,-0.007881,0.010674,0.271112,0.149052,0.007593,2.711121,-98.525307,0.272144,0.000000
18.470001,0.028671,-98.525307,-0.007683,0.010846,0.275492,0.127536,0.006497,2.754916,-98.525307,0.276636,0.000000
18.740002,0.015640,-98.569786,-0.007511,0.011027,0.280079,0.069571,0.003544,2.800792,-98.569786,0.281146,0.000000
19.010000,-0.046547,-98.569786,-0.007321,0.011200,0.284485,-0.207051,-0.010548,2.844847,-98.569786,0.285638,0.000000
19.280001,0.029785,-98.614265,-0.007157,0.011373,0.288882,0.132491,0.006749,2.888815,-98.614265,0.290130,0.000000
19.550001,0.043938,-98.703232,-0.006967,0.011556,0.293530,0.195445,0.009956,2.935299,-98.703232,0.294640,0.000000
19.820002,0.011917,-98.658752,-0.006782,0.011739,0.298170,0.053010,0.002700,2.981695,-98.658752,0.299132,0.000000
20.090000,0.054367,-98.658752,-0.006605,0.011912,0.302566,0.241837,0.012320,3.025664,-98.658752,0.303624,0.000000
20.360001,-0.000000,-98.703232,-0.006433,0.012090,0.307076,-0.000000,-0.000000,3.070759,-98.703232,0.308134,0.000000
20.630001,0.018242,-98.792191,-0.006256,0.012266,0.311568,0.081144,0.004134,3.115682,-98.792191,0.312626,0.000000
20.900002,0.017502,-98.792191,-0.006062,0.012446,0.316130,0.077852,0.003966,3.161298,-98.792191,0.317118,0.000000
21.170000,-0.037987,-98.747711,-0.005911,0.012616,0.320440,-0.168974,-0.008608,3.204399,-98.747711,0.321628,0.000000
21.440001,0.067024,-98.747711,-0.005734,0.012793,0.324941,0.298139,0.015188,3.249408,-98.747711,0.326120,0.000000
21.710001,0.016754,-98.836670,-0.005553,0.012974,0.329546,0.074526,0.003797,3.295457,-98.836670,0.330612,0.000000
21.980001,0.045799,-98.925636,-0.005368,0.013155,0.334133,0.203725,0.010378,3.341334,-98.925636,0.335122,0.000000
22.250002,0.047661,-98.881157,-0.005191,0.013333,0.338652,0.212006,0.010800,3.386516,-98.881157,0.339614,0.000000
22.520000,0.008194,-98.925636,-0.005001,0.013505,0.343031,0.036449,0.001857,3.430311,-98.925636,0.344106,0.000000
22.790001,0.074471,-98.925636,-0.004829,0.013678,0.347428,0.331261,0.016875,3.474279,-98.925636,0.348616,0.000000
23.060001,0.439026,-98.970116,-0.004656,0.013861,0.352076,1.952885,0.099485,3.520763,-98.970116,0.353108,0.000000
23.330002,0.740646,-99.059074,-0.004600,-0.000003,-0.000069,3.294559,0.167833,-0.000694,-99.059074,0.000139,0.000000
23.600000,0.625214,-99.059074,-0.004609,-0.000003,-0.000078,2.781089,0.141675,-0.000781,-99.059074,0.000139,0.000000
23.870001,0.652763,-99.059074,-0.004609,-0.000003,-0.000069,2.903636,0.147918,-0.000694,-99.059074,0.000512,0.000000
24.140001,0.645691,-99.103561,-0.004609,-0.000003,-0.000069,2.872177,0.146316,-0.000694,-99.103561,0.000954,0.000000
24.410002,0.670265,-99.148041,-0.004609,-0.000002,-0.000061,2.981488,0.151884,-0.000607,-99.148041,0.001405,0.000000
24.680000,1.108925,-99.148041,-0.004592,0.000033,0.000841,4.932744,0.251286,0.008412,-99.148041,0.001856,0.000000
24.950001,1.461563,-99.237000,-0.004570,0.000059,0.001500,6.501358,0.331195,0.015003,-99.237000,0.002307,0.000000
25.220001,1.735252,-99.237000,-0.004549,0.000077,0.001960,7.718788,0.393214,0.019599,-99.237000,0.002758,0.000000
25.490002,1.965004,-99.192520,-0.004531,0.000093,0.002350,8.740774,0.445276,0.023502,-99.192520,0.003209,0.000000
25.760002,2.210030,-99.281487,-0.004518,0.000107,0.002723,9.830703,0.500800,0.027231,-99.281487,0.003660,0.000000
26.030001,2.588730,-99.325966,-0.004501,0.000126,0.003200,11.515245,0.586615,0.032001,-99.325966,0.004111,0.000000
26.300001,2.945465,-99.370445,-0.004497,0.000144,0.003651,13.102083,0.667452,0.036510,-99.370445,0.004562,0.000000
26.570002,3.194206,-99.325966,-0.004475,0.000157,0.003981,14.208539,0.723817,0.039806,-99.325966,0.005004,0.000000
26.840002,3.669357,-99.325966,-0.004458,0.000181,0.004588,16.322117,0.831488,0.045876,-99.325966,0.005455,0.000000
27.110001,4.123276,-99.414925,-0.004441,0.000201,0.005108,18.341246,0.934348,0.051080,-99.414925,0.005906,0.000000
27.380001,4.518738,-99.459404,-0.004432,0.000220,0.005576,20.100349,1.023961,0.055763,-99.459404,0.006357,0.000000
27.650002,4.780891,-99.459404,-0.004432,0.000234,0.005940,21.266468,1.083366,0.059405,-99.459404,0.006808,0.000000
27.920002,4.931702,-99.459404,-0.004393,0.000247,0.006279,21.937305,1.117540,0.062787,-99.459404,0.007259,0.000000
28.190001,5.552818,-99.503891,-0.004393,0.000266,0.006764,24.700169,1.258287,0.067644,-99.503891,0.007710,0.000000
28.460001,5.873055,-99.548370,-0.004376,0.000282,0.007163,26.124651,1.330853,0.071633,-99.548370,0.008161,0.000000
28.730001,6.466988,-99.592850,-0.004363,0.000304,0.007710,28.766598,1.465440,0.077096,-99.592850,0.008612,0.000000
29.000002,6.908997,-99.548370,-0.004346,0.000325,0.008256,30.732752,1.565601,0.082560,-99.548370,0.009054,0.000000
29.270000,7.177849,-99.637329,-0.004342,0.000342,0.008681,31.928667,1.626524,0.086809,-99.637329,0.009505,0.000000
29.540001,7.461227,-99.592850,-0.004320,0.000356,0.009045,33.189198,1.690738,0.090452,-99.592850,0.009956,0.000000
29.810001,7.804550,-99.681808,-0.004299,0.000373,0.009470,34.716373,1.768536,0.094701,-99.681808,0.010407,0.000000
30.080002,8.312469,-99.681808,-0.004281,0.000394,0.009999,36.975712,1.883633,0.099991,-99.681808,0.010858,0.000000
30.350002,8.502007,-99.815254,-0.004264,0.000406,0.010311,37.818813,1.926582,0.103113,-99.815254,0.011309,0.000000
30.620001,8.769745,-99.770775,-0.004268,0.000421,0.010702,39.009773,1.987253,0.107016,-99.770775,0.011760,0.000000
30.890001,9.426231,-99.770775,-0.004247,0.000444,0.011274,41.929970,2.136015,0.112739,-99.770775,0.012211,0.000000
31.160002,9.597527,-99.815254,-0.004238,0.000459,0.011656,42.691929,2.174831,0.116555,-99.815254,0.012661,0.000000
31.430002,10.216034,-99.904213,-0.004234,0.000483,0.012263,45.443188,2.314986,0.122626,-99.904213,0.013112,0.000000
31.700001,10.319183,-99.904213,-0.004208,0.000497,0.012635,45.902020,2.338360,0.126355,-99.904213,0.013555,0.000000
31.970001,10.747414,-99.859734,-0.004195,0.000515,0.013086,47.806885,2.435399,0.130864,-99.859734,0.014006,0.000000
32.240002,11.094093,-99.859734,-0.004165,0.000533,0.013529,49.348991,2.513958,0.135287,-99.859734,0.014457,0.000000
32.510002,11.335762,-99.859734,-0.004143,0.000547,0.013902,50.423988,2.568721,0.139016,-99.859734,0.014908,0.000000
32.780003,12.062630,-99.948700,-0.004130,0.000575,0.014595,53.657257,2.733431,0.145954,-99.948700,0.015359,0.000000
33.050003,12.344887,-100.037659,-0.004118,0.000594,0.015090,54.912800,2.797391,0.150897,-100.037659,0.015810,0.000000
33.320000,12.428673,-100.037659,-0.004096,0.000607,0.015411,55.285500,2.816378,0.154106,-100.037659,0.016260,0.000000
33.590000,12.836418,-100.037659,-0.004083,0.000627,0.015914,57.099239,2.908774,0.159136,-100.037659,0.016711,0.000000
33.860001,13.091866,-99.993179,-0.004070,0.000642,0.016304,58.235527,2.966659,0.163038,-99.993179,0.017162,0.000000
34.130001,13.460144,-100.126617,-0.004070,0.000661,0.016789,59.873711,3.050112,0.167895,-100.126617,0.017605,0.000000
34.400002,13.452324,-100.126617,-0.004040,0.000673,0.017084,59.838924,3.048340,0.170843,-100.126617,0.018056,0.000000
34.670002,14.184410,-100.126617,-0.004031,0.000695,0.017665,63.095406,3.214233,0.176654,-100.126617,0.018507,0.000000
34.940002,14.560875,-100.126617,-0.004010,0.000714,0.018142,64.770004,3.299541,0.181424,-100.126617,0.018958,0.000000
35.210003,14.732544,-100.215584,-0.003988,0.000733,0.018619,65.533630,3.338442,0.186193,-100.215584,0.019409,0.000000
35.480003,14.883354,-100.215584,-0.003980,0.000748,0.018992,66.204468,3.372616,0.189922,-100.215584,0.019859,0.000000
35.750000,15.222954,-100.215584,-0.003962,0.000765,0.019443,67.715080,3.449571,0.194432,-100.215584,0.020310,0.000000
36.020000,15.574478,-100.260063,-0.003945,0.000785,0.019929,69.278740,3.529227,0.199288,-100.260063,0.020761,0.000000
36.290001,15.587509,-100.260063,-0.003941,0.000795,0.020180,69.336700,3.532180,0.201803,-100.260063,0.021212,0.000000
36.560001,16.362785,-100.304543,-0.003919,0.000821,0.020848,72.785301,3.707860,0.208481,-100.304543,0.021655,0.000000
36.830002,16.686752,-100.393509,-0.003893,0.000842,0.021377,74.226379,3.781272,0.213771,-100.393509,0.022106,0.000000
37.100002,16.809639,-100.393509,-0.003885,0.000858,0.021802,74.773010,3.809119,0.218020,-100.393509,0.022557,0.000000
37.370003,16.996567,-100.437988,-0.003863,0.000876,0.022253,75.604507,3.851477,0.222530,-100.437988,0.023008,0.000000
37.640003,16.880386,-100.393509,-0.003854,0.000887,0.022531,75.087708,3.825150,0.225305,-100.393509,0.023458,0.000000
37.910004,17.564438,-100.437988,-0.003833,0.000910,0.023120,78.130524,3.980159,0.231202,-100.437988,0.023909,0.000000
38.180000,17.561081,-100.526947,-0.003846,0.000924,0.023467,78.115593,3.979398,0.234671,-100.526947,0.024360,0.000000
38.450001,18.203423,-100.482468,-0.003811,0.000946,0.024039,80.972870,4.124954,0.240395,-100.482468,0.024811,0.000000
38.720001,18.371368,-100.526947,-0.003790,0.000965,0.024508,81.719925,4.163012,0.245078,-100.526947,0.025262,0.000000
38.990002,18.502815,-100.615913,-0.003777,0.000982,0.024933,82.304634,4.192798,0.249327,-100.615913,0.025713,0.000000
39.260002,18.500954,-100.615913,-0.003755,0.000995,0.025271,82.296349,4.192376,0.252710,-100.615913,0.026156,0.000000
39.530003,18.728470,-100.615913,-0.003755,0.001012,0.025705,83.308395,4.243932,0.257046,-100.615913,0.026606,0.000000
39.800003,19.291870,-100.704872,-0.003742,0.001035,0.026277,85.814522,4.371600,0.262769,-100.704872,0.027057,0.000000
40.070004,19.325012,-100.704872,-0.003699,0.001048,0.026624,85.961945,4.379110,0.266238,-100.704872,0.027508,0.000000
40.340000,19.113503,-100.749352,-0.003691,0.001062,0.026971,85.021103,4.331182,0.269707,-100.749352,0.027959,0.000000
40.610001,20.001610,-100.704872,-0.003678,0.001088,0.027630,88.971603,4.532430,0.276298,-100.704872,0.028410,0.000000
40.880001,19.929375,-100.793839,-0.003669,0.001103,0.028011,88.650284,4.516061,0.280114,-100.793839,0.028861,0.000000
41.150002,20.114441,-100.793839,-0.003639,0.001118,0.028402,89.473503,4.557998,0.284016,-100.793839,0.029312,0.000000
41.420002,20.228760,-100.838318,-0.003635,0.001135,0.028818,89.982018,4.583902,0.288179,-100.838318,0.029763,0.000000
41.690002,20.815994,-100.793839,-0.003609,0.001158,0.029416,92.594170,4.716971,0.294163,-100.793839,0.030205,0.000000
41.960003,20.762741,-100.882797,-0.003600,0.001171,0.029755,92.357285,4.704905,0.297545,-100.882797,0.030656,0.000000
42.230003,20.798492,-100.927277,-0.003604,0.001186,0.030136,92.516312,4.713006,0.301361,-100.927277,0.031107,0.000000
42.500004,21.264702,-100.971756,-0.003579,0.001209,0.030717,94.590118,4.818650,0.307171,-100.971756,0.031558,0.000000
42.770000,21.360031,-100.927277,-0.003561,0.001225,0.031107,95.014160,4.840252,0.311074,-100.927277,0.032009,0.000000
43.040001,21.546959,-100.927277,-0.003544,0.001243,0.031576,95.845657,4.882611,0.315757,-100.927277,0.032460,0.000000
43.310001,21.528343,-101.060722,-0.003527,0.001256,0.031905,95.762856,4.878393,0.319052,-101.060722,0.032911,0.000000
43.580002,22.188927,-101.105202,-0.003510,0.001281,0.032530,98.701279,5.028082,0.325296,-101.105202,0.033362,0.000000
43.850002,22.095833,-101.060722,-0.003497,0.001294,0.032877,98.287170,5.006988,0.328765,-101.060722,0.033813,0.000000
44.120003,22.225052,-101.105202,-0.003475,0.001310,0.033275,98.861969,5.036269,0.332754,-101.105202,0.034255,0.000000
44.390003,22.834991,-101.105202,-0.003454,0.001334,0.033891,101.575111,5.174483,0.338912,-101.105202,0.034706,0.000000
44.660004,22.855103,-101.105202,-0.003432,0.001352,0.034342,101.664574,5.179040,0.343421,-101.105202,0.035157,0.000000
44.930000,22.830528,-101.194160,-0.003423,0.001368,0.034758,101.555260,5.173472,0.347584,-101.194160,0.035608,0.000000
45.200001,22.725517,-101.149681,-0.003402,0.001381,0.035071,101.088150,5.149676,0.350706,-101.149681,0.036059,0.000000
45.470001,23.199173,-101.238647,-0.003389,0.001401,0.035582,103.195076,5.257008,0.355823,-101.238647,0.036510,0.000000
45.740002,23.592773,-101.194160,-0.003372,0.001421,0.036085,104.945900,5.346199,0.360853,-101.194160,0.036961,0.000000
46.010002,23.249443,-101.327606,-0.003372,0.001431,0.036337,103.418686,5.268399,0.363368,-101.327606,0.037412,0.000000
46.280003,23.892159,-101.327606,-0.003350,0.001456,0.036970,106.277626,5.414041,0.369698,-101.327606,0.037863,0.000000
46.550003,24.029938,-101.327606,-0.003337,0.001473,0.037403,106.890503,5.445262,0.374034,-101.327606,0.038314,0.000000
46.820004,24.308472,-101.416565,-0.003311,0.001491,0.037872,108.129486,5.508379,0.378717,-101.416565,0.038756,0.000000
47.090004,24.225807,-101.327606,-0.003277,0.001506,0.038245,107.761772,5.489646,0.382446,-101.327606,0.039207,0.000000
47.360001,24.498009,-101.416565,-0.003290,0.001524,0.038722,108.972588,5.551328,0.387216,-101.416565,0.039658,0.000000
47.630001,24.732605,-101.461052,-0.003264,0.001543,0.039190,110.016121,5.604488,0.391899,-101.461052,0.040109,0.000000
47.900002,24.597809,-101.461052,-0.003268,0.001556,0.039519,109.416519,5.573943,0.395195,-101.461052,0.040560,0.000000
48.170002,25.040932,-101.550011,-0.003234,0.001579,0.040101,111.387627,5.674356,0.401005,-101.550011,0.041011,0.000000
48.440002,25.368614,-101.461052,-0.003208,0.001597,0.040551,112.845230,5.748610,0.405515,-101.461052,0.041462,0.000000
48.710003,25.753281,-101.505531,-0.003212,0.001618,0.041106,114.556313,5.835777,0.411065,-101.505531,0.041913,0.000000
48.980003,25.603584,-101.550011,-0.003191,0.001633,0.041479,113.890434,5.801855,0.414794,-101.550011,0.042364,0.000000
49.250004,25.005928,-101.594490,-0.003178,0.001643,0.041722,111.231926,5.666424,0.417222,-101.594490,0.042806,0.000000
49.520000,25.821419,-101.594490,-0.003152,0.001664,0.042277,114.859406,5.851217,0.422773,-101.594490,0.043257,0.000000
49.790001,25.858658,-101.638969,-0.003143,0.001681,0.042685,115.025055,5.859655,0.426849,-101.638969,0.043708,0.000000
50.060001,26.613083,-101.638969,-0.003117,0.001704,0.043275,118.380905,6.030611,0.432746,-101.638969,0.044159,0.000000
50.330002,26.978012,-101.683456,-0.003104,0.001725,0.043804,120.004189,6.113305,0.438036,-101.683456,0.044610,0.000000
50.600002,26.978012,-101.727936,-0.003087,0.001741,0.044211,120.004189,6.113305,0.442112,-101.727936,0.045061,0.000000
50.870003,26.896835,-101.816895,-0.003070,0.001755,0.044575,119.643097,6.094910,0.445754,-101.816895,0.045512,0.000000
51.140003,26.868904,-101.772415,-0.003057,0.001771,0.044983,119.518852,6.088581,0.449830,-101.772415,0.045963,0.000000
51.410004,27.433426,-101.816895,-0.003044,0.001792,0.045521,122.029976,6.216503,0.455207,-101.816895,0.046414,0.000000
51.680004,27.334373,-101.772415,-0.003022,0.001805,0.045859,121.589363,6.194057,0.458589,-101.772415,0.046856,0.000000
51.950001,27.458374,-101.861382,-0.003027,0.001820,0.046240,122.140945,6.222157,0.462405,-101.861382,0.047307,0.000000
52.220001,28.104439,-101.905861,-0.003009,0.001844,0.046848,125.014786,6.368557,0.468475,-101.905861,0.047758,0.000000
52.490002,28.238121,-101.905861,-0.002975,0.001861,0.047272,125.609436,6.398849,0.472725,-101.905861,0.048209,0.000000
52.760002,28.627251,-101.905861,-0.002958,0.001881,0.047767,127.340370,6.487028,0.477668,-101.905861,0.048660,0.000000
53.030003,28.477180,-101.950340,-0.002940,0.001895,0.048131,126.672829,6.453022,0.481310,-101.950340,0.049111,0.000000
53.300003,28.922539,-102.039299,-0.002940,0.001916,0.048669,128.653885,6.553941,0.486687,-102.039299,0.049562,0.000000
53.570004,29.132561,-102.083786,-0.002915,0.001933,0.049102,129.588104,6.601533,0.491023,-102.083786,0.050013,0.000000
53.840004,29.084892,-102.039299,-0.002889,0.001948,0.049467,129.376068,6.590731,0.494666,-102.039299,0.050464,0.000000
54.110004,29.809532,-102.083786,-0.002880,0.001973,0.050117,132.599426,6.754937,0.501170,-102.083786,0.050915,0.000000
54.380001,30.050087,-102.083786,-0.002884,0.001992,0.050594,133.669464,6.809447,0.505939,-102.083786,0.051357,0.000000
54.650002,29.904488,-102.172745,-0.002850,0.002005,0.050932,133.021805,6.776454,0.509322,-102.172745,0.051808,0.000000
54.920002,29.845650,-102.172745,-0.002833,0.002021,0.051331,132.760086,6.763121,0.513311,-102.172745,0.052259,0.000000
55.190002,30.309258,-102.172745,-0.002820,0.002040,0.051825,134.822311,6.868176,0.518254,-102.172745,0.052710,0.000000
55.460003,30.539009,-102.172745,-0.002802,0.002059,0.052302,135.844299,6.920238,0.523024,-102.172745,0.053161,0.000000
55.730003,30.145782,-102.217224,-0.002785,0.002069,0.052563,134.095139,6.831132,0.525626,-102.217224,0.053612,0.000000
56.000004,31.048042,-102.306190,-0.002777,0.002093,0.053161,138.108597,7.035587,0.531609,-102.306190,0.054063,0.000000
56.270004,31.511642,-102.306190,-0.002759,0.002113,0.053681,140.170792,7.140640,0.536813,-102.306190,0.054514,0.000000
56.540001,31.617027,-102.306190,-0.002734,0.002132,0.054141,140.639557,7.164521,0.541409,-102.306190,0.054965,0.000000
56.810001,31.577187,-102.350670,-0.002721,0.002146,0.054514,140.462341,7.155493,0.545138,-102.350670,0.055407,0.000000
57.080002,31.642723,-102.395149,-0.002708,0.002163,0.054930,140.753860,7.170343,0.549301,-102.395149,0.055858,0.000000
57.350002,32.237396,-102.395149,-0.002695,0.002183,0.055459,143.399094,7.305099,0.554591,-102.395149,0.056309,0.000000
57.620003,31.883644,-102.484108,-0.002665,0.002193,0.055702,141.825531,7.224937,0.557019,-102.484108,0.056760,0.000000
57.890003,33.092369,-102.395149,-0.002643,0.002222,0.056430,147.202209,7.498838,0.564304,-102.395149,0.057211,0.000000
58.160004,33.367546,-102.439629,-0.002643,0.002241,0.056916,148.426254,7.561194,0.569160,-102.439629,0.057662,0.000000
58.430004,33.458412,-102.484108,-0.002626,0.002257,0.057332,148.830444,7.581784,0.573323,-102.484108,0.058113,0.000000
58.700005,33.675133,-102.528595,-0.002608,0.002275,0.057783,149.794479,7.630894,0.577833,-102.528595,0.058564,0.000000
58.970001,33.519104,-102.617554,-0.002591,0.002288,0.058121,149.100418,7.595537,0.581215,-102.617554,0.059015,0.000000
59.240002,34.134262,-102.573074,-0.002565,0.002310,0.058668,151.836777,7.734934,0.586678,-102.573074,0.059466,0.000000
59.510002,33.809555,-102.662033,-0.002565,0.002320,0.058928,150.392410,7.661355,0.589280,-102.662033,0.059908,0.000000
59.780003,34.891296,-102.617554,-0.002544,0.002347,0.059604,155.204239,7.906481,0.596044,-102.617554,0.060359,0.000000
60.050003,34.995560,-102.662033,-0.002531,0.002364,0.060038,155.668030,7.930107,0.600380,-102.662033,0.060810,0.000000
60.320004,35.065193,-102.706512,-0.002509,0.002379,0.060437,155.977768,7.945887,0.604370,-102.706512,0.061261,0.000000
60.590004,35.094612,-102.750999,-0.002488,0.002393,0.060784,156.108627,7.952553,0.607839,-102.750999,0.061712,0.000000
60.860004,35.385437,-102.750999,-0.002466,0.002411,0.061235,157.402283,8.018455,0.612348,-102.750999,0.062163,0.000000
61.130001,35.997620,-102.750999,-0.002462,0.002433,0.061790,160.125412,8.157177,0.617898,-102.750999,0.062614,0.000000
61.400002,36.116028,-102.839958,-0.002449,0.002447,0.062145,160.652115,8.184009,0.621454,-102.839958,0.063065,0.000000
61.670002,36.010651,-102.839958,-0.002427,0.002464,0.062596,160.183380,8.160130,0.625963,-102.839958,0.063516,0.000000
61.940002,36.907326,-102.884438,-0.002414,0.002484,0.063082,164.171982,8.363319,0.630820,-102.884438,0.063958,0.000000
62.210003,36.946793,-102.884438,-0.002410,0.002500,0.063498,164.347534,8.372263,0.634983,-102.884438,0.064409,0.000000
62.480003,37.240967,-102.884438,-0.002389,0.002516,0.063906,165.656097,8.438924,0.639059,-102.884438,0.064860,0.000000
62.750004,37.335922,-102.973404,-0.002371,0.002532,0.064322,166.078476,8.460442,0.643221,-102.973404,0.065311,0.000000
63.020004,38.047897,-103.017883,-0.002363,0.002556,0.064912,169.245499,8.621777,0.649118,-103.017883,0.065762,0.000000
63.290005,38.202431,-103.017883,-0.002341,0.002570,0.065267,169.932892,8.656795,0.652674,-103.017883,0.066213,0.000000
63.560001,38.264244,-103.017883,-0.002315,0.002585,0.065658,170.207855,8.670802,0.656577,-103.017883,0.066664,0.000000
63.830002,38.749077,-103.062363,-0.002320,0.002605,0.066178,172.364502,8.780666,0.661780,-103.062363,0.067115,0.000000
64.100006,39.186241,-103.106842,-0.002281,0.002624,0.066638,174.309113,8.879728,0.666376,-103.106842,0.067566,0.000000
64.370003,39.448761,-103.062363,-0.002264,0.002641,0.067089,175.476852,8.939217,0.670886,-103.062363,0.068008,0.000000
64.639999,39.344131,-103.106842,-0.002255,0.002655,0.067435,175.011444,8.915507,0.674355,-103.106842,0.068459,0.000000
64.910004,39.919067,-103.106842,-0.002238,0.002676,0.067973,177.568878,9.045791,0.679731,-103.106842,0.068910,0.000000
65.180000,39.837524,-103.195808,-0.002233,0.002690,0.068320,177.206161,9.027312,0.683200,-103.195808,0.069361,0.000000
65.450005,39.776451,-103.151329,-0.002207,0.002703,0.068658,176.934494,9.013473,0.686583,-103.151329,0.069812,0.000000
65.720001,41.525116,-103.240288,-0.002190,0.002734,0.069439,184.712936,9.409725,0.694388,-103.240288,0.070263,0.000000
65.990005,41.681885,-103.284767,-0.002186,0.002751,0.069872,185.410278,9.445251,0.698724,-103.284767,0.070714,0.000000
66.260002,41.602570,-103.240288,-0.002151,0.002766,0.070263,185.057465,9.427277,0.702626,-103.240288,0.071165,0.000000
66.530006,41.406700,-103.284767,-0.002143,0.002779,0.070592,184.186203,9.382893,0.705922,-103.284767,0.071615,0.000000
66.800003,41.717255,-103.373734,-0.002130,0.002798,0.071060,185.567612,9.453265,0.710605,-103.373734,0.072066,0.000000
67.070000,42.538712,-103.418213,-0.002108,0.002818,0.071572,189.221634,9.639409,0.715721,-103.418213,0.072509,0.000000
67.340004,42.105270,-103.462692,-0.002078,0.002828,0.071832,187.293594,9.541191,0.718323,-103.462692,0.072960,0.000000
67.610001,42.938271,-103.462692,-0.002074,0.002852,0.072439,190.998962,9.729951,0.724394,-103.462692,0.073411,0.000000
67.880005,43.296486,-103.373734,-0.002065,0.002869,0.072882,192.592392,9.811124,0.728817,-103.373734,0.073862,0.000000
68.150002,43.839035,-103.462692,-0.002048,0.002889,0.073385,195.005768,9.934068,0.733846,-103.462692,0.074313,0.000000
68.420006,43.684502,-103.507172,-0.002031,0.002904,0.073766,194.318375,9.899049,0.737662,-103.507172,0.074764,0.000000
68.690002,43.688972,-103.551651,-0.002005,0.002918,0.074122,194.338257,9.900063,0.741218,-103.551651,0.075214,0.000000
68.960007,44.382324,-103.551651,-0.001996,0.002939,0.074659,197.422440,10.057178,0.746595,-103.551651,0.075665,0.000000
69.230003,44.394989,-103.551651,-0.001979,0.002954,0.075024,197.478775,10.060048,0.750237,-103.551651,0.076116,0.000000
69.500000,44.962486,-103.596138,-0.001957,0.002978,0.075631,200.003128,10.188645,0.756307,-103.596138,0.076559,0.000000
69.770004,45.505028,-103.685097,-0.001953,0.002994,0.076056,202.416473,10.311587,0.760557,-103.685097,0.077010,0.000000
70.040001,46.009224,-103.596138,-0.001923,0.003015,0.076593,204.659256,10.425839,0.765934,-103.596138,0.077461,0.000000
70.310005,46.055397,-103.596138,-0.001906,0.003031,0.076984,204.864639,10.436302,0.769836,-103.596138,0.077912,0.000000
70.580002,45.175110,-103.640617,-0.001893,0.003039,0.077192,200.948929,10.236826,0.771918,-103.640617,0.078363,0.000000
70.850006,46.299675,-103.729576,-0.001876,0.003063,0.077799,205.951233,10.491656,0.777988,-103.729576,0.078813,0.000000
71.120003,46.363724,-103.818542,-0.001876,0.003079,0.078206,206.236145,10.506170,0.782064,-103.818542,0.079264,0.000000
71.390007,47.070854,-103.818542,-0.001841,0.003100,0.078744,209.381622,10.666409,0.787441,-103.818542,0.079715,0.000000
71.660004,47.861031,-103.729576,-0.001828,0.003122,0.079308,212.896500,10.845465,0.793078,-103.729576,0.080166,0.000000
71.930000,48.041260,-103.818542,-0.001807,0.003139,0.079741,213.698196,10.886305,0.797414,-103.818542,0.080609,0.000000
72.200005,47.997322,-103.818542,-0.001789,0.003153,0.080097,213.502747,10.876348,0.800970,-103.818542,0.081060,0.000000
72.470001,47.931038,-103.907501,-0.001776,0.003167,0.080453,213.207901,10.861328,0.804525,-103.907501,0.081511,0.000000
72.740005,48.698128,-103.951981,-0.001759,0.003189,0.081008,216.620087,11.035153,0.810076,-103.951981,0.081961,0.000000
73.010002,48.720840,-103.951981,-0.001750,0.003204,0.081372,216.721115,11.040300,0.813718,-103.951981,0.082412,0.000000
73.280006,48.836273,-103.951981,-0.001729,0.003219,0.081762,217.234589,11.066458,0.817620,-103.951981,0.082863,0.000000
73.550003,49.771301,-103.951981,-0.001725,0.003242,0.082343,221.393799,11.278337,0.823431,-103.951981,0.083314,0.000000
73.820000,50.231926,-104.040947,-0.001720,0.003260,0.082803,223.442764,11.382717,0.828027,-104.040947,0.083765,0.000000
74.090004,50.848572,-104.085426,-0.001690,0.003279,0.083288,226.185745,11.522451,0.832884,-104.085426,0.084216,0.000000
74.360001,50.718620,-104.085426,-0.001677,0.003292,0.083627,225.607697,11.493003,0.836266,-104.085426,0.084667,0.000000
74.630005,51.337875,-104.085426,-0.001660,0.003313,0.084138,228.362274,11.633329,0.841382,-104.085426,0.085110,0.000000
74.900002,51.551239,-104.085426,-0.001643,0.003326,0.084476,229.311371,11.681677,0.844764,-104.085426,0.085560,0.000000
75.170006,52.262848,-104.174385,-0.001647,0.003345,0.084962,232.476761,11.842931,0.849621,-104.174385,0.086011,0.000000
75.440002,53.411987,-104.218872,-0.001630,0.003370,0.085587,237.588379,12.103330,0.855865,-104.218872,0.086462,0.000000
75.710007,54.256531,-104.174385,-0.001595,0.003390,0.086107,241.345108,12.294705,0.861068,-104.174385,0.086913,0.000000
75.980003,54.285202,-104.218872,-0.001595,0.003404,0.086454,241.472641,12.301203,0.864537,-104.218872,0.087364,0.000000
76.250000,54.696297,-104.263351,-0.001582,0.003419,0.086844,243.301285,12.394358,0.868440,-104.263351,0.087815,0.000000
76.520004,55.467484,-104.307831,-0.001556,0.003439,0.087338,246.731689,12.569111,0.873383,-104.307831,0.088266,0.000000
76.790001,55.956039,-104.307831,-0.001552,0.003455,0.087763,248.904892,12.679819,0.877632,-104.307831,0.088717,0.000000
77.060005,56.063278,-104.352310,-0.001548,0.003465,0.088015,249.381912,12.704121,0.880147,-104.352310,0.089159,0.000000
77.330002,57.096611,-104.396790,-0.001535,0.003490,0.088639,253.978409,12.938276,0.886391,-104.396790,0.089610,0.000000
77.600006,58.302727,-104.396790,-0.001513,0.003511,0.089168,259.343475,13.211587,0.891681,-104.396790,0.090061,0.000000
77.870003,58.843414,-104.441277,-0.001513,0.003526,0.089558,261.748566,13.334108,0.895584,-104.441277,0.090512,0.000000
78.140007,59.543098,-104.485756,-0.001492,0.003544,0.090009,264.860931,13.492659,0.900093,-104.485756,0.090963,0.000000
78.410004,60.128845,-104.485756,-0.001483,0.003560,0.090434,267.466461,13.625391,0.904343,-104.485756,0.091414,0.000000
78.680000,61.228088,-104.485756,-0.001462,0.003581,0.090963,272.356140,13.874483,0.909633,-104.485756,0.091865,0.000000
78.950005,61.480927,-104.530235,-0.001466,0.003591,0.091223,273.480835,13.931777,0.912235,-104.530235,0.092316,0.000000
79.220001,62.693367,-104.574715,-0.001449,0.003615,0.091822,278.874023,14.206520,0.918219,-104.574715,0.092767,0.000000
79.490005,63.877510,-104.663681,-0.001440,0.003635,0.092334,284.141357,14.474851,0.923335,-104.663681,0.093209,0.000000
79.760002,64.769341,-104.619194,-0.001418,0.003656,0.092854,288.108429,14.676943,0.928539,-104.619194,0.093660,0.000000
80.030006,65.547981,-104.619194,-0.001431,0.003673,0.093305,291.571991,14.853385,0.933048,-104.619194,0.094111,0.000000
80.300003,65.762093,-104.663681,-0.001414,0.003685,0.093608,292.524384,14.901904,0.936083,-104.663681,0.094562,0.000000
80.570007,67.235939,-104.663681,-0.001401,0.003706,0.094137,299.080383,15.235881,0.941373,-104.663681,0.095013,0.000000
80.840004,66.682976,-104.708160,-0.001388,0.003702,0.094033,296.620697,15.110579,0.940333,-104.708160,0.094250,0.000000
81.110001,65.706612,-104.752640,-0.001384,0.003702,0.094025,292.277618,14.889331,0.940246,-104.752640,0.094033,0.000000
81.380005,64.821846,-104.752640,-0.001362,0.003701,0.094016,288.341980,14.688841,0.940159,-104.752640,0.094033,0.000000
81.650002,64.056999,-104.797119,-0.001362,0.003701,0.094007,284.939758,14.515524,0.940073,-104.797119,0.094033,0.000000
81.920006,63.333107,-104.841599,-0.001367,0.003701,0.093999,281.719727,14.351488,0.939986,-104.841599,0.094033,0.000000
82.190002,62.705658,-104.930565,-0.001362,0.003701,0.093999,278.928711,14.209305,0.939986,-104.930565,0.094033,0.000000
82.460007,62.119919,-104.886086,-0.001350,0.003701,0.093999,276.323212,14.076575,0.939986,-104.886086,0.094033,0.000000
82.730003,61.604179,-104.886086,-0.001358,0.003701,0.093999,274.029083,13.959707,0.939986,-104.886086,0.094033,0.000000
83.000008,61.124939,-104.975044,-0.001354,0.003700,0.093990,271.897308,13.851110,0.939899,-104.975044,0.094033,0.000000
83.270004,60.700058,-104.975044,-0.001350,0.003700,0.093990,270.007355,13.754830,0.939899,-104.975044,0.094033,0.000000
83.540001,60.288963,-104.975044,-0.001350,0.003700,0.093990,268.178711,13.661674,0.939899,-104.975044,0.094033,0.000000
83.810005,59.925896,-105.019524,-0.001345,0.003700,0.093990,266.563690,13.579402,0.939899,-105.019524,0.094033,0.000000
84.080002,59.586296,-105.064003,-0.001332,0.003700,0.093990,265.053070,13.502447,0.939899,-105.064003,0.094033,0.000000
84.350006,59.257866,-105.019524,-0.001337,0.003700,0.093990,263.592163,13.428024,0.939899,-105.019524,0.094033,0.000000
84.620003,58.966667,-105.108490,-0.001345,0.003700,0.093990,262.296844,13.362038,0.939899,-105.108490,0.094033,0.000000
84.890007,58.681801,-105.152969,-0.001324,0.003700,0.093990,261.029694,13.297485,0.939899,-105.152969,0.094033,0.000000
85.160004,58.415184,-105.108490,-0.001328,0.003700,0.093990,259.843719,13.237070,0.939899,-105.108490,0.094033,0.000000
85.430000,58.187294,-105.152969,-0.001319,0.003700,0.093990,258.830017,13.185429,0.939899,-105.152969,0.094033,0.000000
85.700005,57.959030,-105.241928,-0.001328,0.003700,0.093990,257.814636,13.133704,0.939899,-105.241928,0.094033,0.000000
85.970001,57.723686,-105.286407,-0.001332,0.003700,0.093990,256.767792,13.080375,0.939899,-105.286407,0.094033,0.000000
86.240005,57.520744,-105.330894,-0.001319,0.003700,0.093990,255.865051,13.034387,0.939899,-105.330894,0.094033,0.000000
86.510002,57.343864,-105.286407,-0.001319,0.003700,0.093990,255.078247,12.994305,0.939899,-105.286407,0.094033,0.000000
86.780006,57.153214,-105.286407,-0.001315,0.003700,0.093990,254.230194,12.951103,0.939899,-105.286407,0.094033,0.000000
87.050003,56.973358,-105.286407,-0.001324,0.003700,0.093990,253.430161,12.910348,0.939899,-105.286407,0.094033,0.000000
87.320007,56.799835,-105.419853,-0.001328,0.003700,0.093990,252.658279,12.871026,0.939899,-105.419853,0.094033,0.000000
87.590004,56.647530,-105.464333,-0.001315,0.003700,0.093990,251.980789,12.836514,0.939899,-105.464333,0.094033,0.000000
87.860001,56.495232,-105.419853,-0.001311,0.003700,0.093990,251.303345,12.802002,0.939899,-105.419853,0.094033,0.000000
88.130005,56.350006,-105.419853,-0.001315,0.003700,0.093990,250.657349,12.769094,0.939899,-105.419853,0.094033,0.000000
88.400002,56.220421,-105.464333,-0.001319,0.003700,0.093990,250.080917,12.739730,0.939899,-105.464333,0.094033,0.000000
88.670006,56.068489,-105.508820,-0.001311,0.003700,0.093990,249.405090,12.705301,0.939899,-105.508820,0.094033,0.000000
88.940002,55.942627,-105.508820,-0.001298,0.003700,0.093990,248.845230,12.676781,0.939899,-105.508820,0.094033,0.000000
89.210007,55.817886,-105.553299,-0.001306,0.003700,0.093990,248.290359,12.648514,0.939899,-105.553299,0.094033,0.000000
89.480003,55.710640,-105.508820,-0.001311,0.003700,0.093990,247.813309,12.624211,0.939899,-105.508820,0.094033,0.000000
89.750008,55.592224,-105.508820,-0.001315,0.003700,0.093990,247.286560,12.597378,0.939899,-105.508820,0.094033,0.000000
90.020004,55.473068,-105.597778,-0.001306,0.003700,0.093990,246.756531,12.570376,0.939899,-105.597778,0.094033,0.000000
90.290001,55.365822,-105.686737,-0.001293,0.003700,0.093990,246.279480,12.546075,0.939899,-105.686737,0.094033,0.000000
90.560005,55.269379,-105.686737,-0.001298,0.003700,0.093990,245.850479,12.524220,0.939899,-105.686737,0.094033,0.000000
90.830002,55.171448,-105.686737,-0.001298,0.003700,0.093990,245.414856,12.502028,0.939899,-105.686737,0.094033,0.000000
91.100006,55.074631,-105.775703,-0.001311,0.003700,0.093990,244.984192,12.480090,0.939899,-105.775703,0.094033,0.000000
91.370003,54.979675,-105.775703,-0.001306,0.003700,0.093990,244.561813,12.458572,0.939899,-105.775703,0.094033,0.000000
91.640007,54.889565,-105.864662,-0.001306,0.003700,0.093990,244.160980,12.438153,0.939899,-105.864662,0.094033,0.000000
91.910004,54.800934,-105.820183,-0.001306,0.003700,0.093990,243.766724,12.418069,0.939899,-105.820183,0.094033,0.000000
92.180008,54.714172,-105.864662,-0.001302,0.003700,0.093990,243.380798,12.398409,0.939899,-105.864662,0.094033,0.000000
92.450005,54.645287,-105.909142,-0.001315,0.003700,0.093990,243.074371,12.382799,0.939899,-105.909142,0.094033,0.000000
92.720001,54.550705,-105.953629,-0.001311,0.003700,0.093990,242.653656,12.361366,0.939899,-105.953629,0.094033,0.000000
92.990005,54.469894,-105.998108,-0.001293,0.003700,0.093990,242.294189,12.343054,0.939899,-105.998108,0.094033,0.000000
93.260002,54.397285,-105.998108,-0.001306,0.003700,0.093990,241.971207,12.326601,0.939899,-105.998108,0.094033,0.000000
93.530006,54.322067,-105.998108,-0.001306,0.003700,0.093990,241.636627,12.309557,0.939899,-105.998108,0.094033,0.000000
93.800003,54.267700,-106.042587,-0.001302,0.003700,0.093990,241.394791,12.297236,0.939899,-106.042587,0.094033,0.000000
94.070007,54.194344,-106.087067,-0.001315,0.003700,0.093990,241.068481,12.280614,0.939899,-106.087067,0.094033,0.000000
94.340004,54.132896,-106.087067,-0.001298,0.003700,0.093990,240.795151,12.266689,0.939899,-106.087067,0.094033,0.000000
94.610008,54.062149,-106.087067,-0.001311,0.003700,0.093990,240.480453,12.250658,0.939899,-106.087067,0.094033,0.000000
94.880005,54.003311,-106.176033,-0.001293,0.003700,0.093990,240.218719,12.237325,0.939899,-106.176033,0.094033,0.000000
95.150002,53.944481,-106.176033,-0.001293,0.003700,0.093990,239.957031,12.223994,0.939899,-106.176033,0.094033,0.000000
95.420006,53.856972,-106.220512,-0.001319,0.003700,0.093990,239.567780,12.204165,0.939899,-106.220512,0.094033,0.000000
95.690002,53.806328,-106.220512,-0.001293,0.003700,0.093990,239.342499,12.192688,0.939899,-106.220512,0.094033,0.000000
95.960007,53.733345,-106.264992,-0.001298,0.003700,0.093990,239.017853,12.176150,0.939899,-106.264992,0.094033,0.000000
96.230003,53.685684,-106.264992,-0.001302,0.003700,0.093990,238.805847,12.165350,0.939899,-106.264992,0.094033,0.000000
96.500008,53.642860,-106.353951,-0.001306,0.003700,0.093990,238.615356,12.155645,0.939899,-106.353951,0.094033,0.000000
96.770004,53.576950,-106.309471,-0.001302,0.003700,0.093990,238.322174,12.140711,0.939899,-106.309471,0.094033,0.000000
97.040001,53.521095,-106.442917,-0.001298,0.003700,0.093990,238.073715,12.128054,0.939899,-106.442917,0.094033,0.000000
97.310005,53.471191,-106.398437,-0.001285,0.003700,0.093990,237.851746,12.116745,0.939899,-106.398437,0.094033,0.000000
97.580002,53.425392,-106.353951,-0.001289,0.003700,0.093990,237.648010,12.106367,0.939899,-106.353951,0.094033,0.000000
97.850006,53.363953,-106.398437,-0.001293,0.003700,0.093990,237.374710,12.092444,0.939899,-106.398437,0.094033,0.000000
98.120003,53.306976,-106.576355,-0.001289,0.003700,0.093990,237.121277,12.079534,0.939899,-106.576355,0.094033,0.000000
98.390007,53.254105,-106.531876,-0.001298,0.003700,0.093990,236.886093,12.067553,0.939899,-106.531876,0.094033,0.000000
98.660004,53.208672,-106.576355,-0.001298,0.003700,0.093990,236.683990,12.057258,0.939899,-106.576355,0.094033,0.000000
98.930008,53.178139,-106.531876,-0.001311,0.003700,0.093990,236.548172,12.050339,0.939899,-106.531876,0.094033,0.000000
99.200005,53.131592,-106.576355,-0.001289,0.003700,0.093990,236.341125,12.039790,0.939899,-106.576355,0.094033,0.000000
99.470001,53.077599,-106.665321,-0.001298,0.003700,0.093990,236.100952,12.027555,0.939899,-106.665321,0.094033,0.000000
99.740005,53.035889,-106.665321,-0.001289,0.003700,0.093990,235.915421,12.018105,0.939899,-106.665321,0.094033,0.000000
100.010002,52.987854,-106.620842,-0.001281,0.003700,0.093990,235.701752,12.007219,0.939899,-106.620842,0.094033,0.000000
100.280006,52.964394,-106.620842,-0.001289,0.003700,0.093990,235.597397,12.001903,0.939899,-106.620842,0.094033,0.000000
100.550003,52.910774,-106.709801,-0.001293,0.003700,0.093990,235.358871,11.989753,0.939899,-106.709801,0.094033,0.000000
100.820007,52.867950,-106.754280,-0.001285,0.003700,0.093990,235.168396,11.980048,0.939899,-106.754280,0.094033,0.000000
101.090004,52.840393,-106.709801,-0.001298,0.003700,0.093990,235.045807,11.973804,0.939899,-106.709801,0.094033,0.000000
101.360008,52.793106,-106.709801,-0.001281,0.003700,0.093990,234.835464,11.963089,0.939899,-106.709801,0.094033,0.000000
101.630005,52.769646,-106.754280,-0.001285,0.003700,0.093990,234.731110,11.957772,0.939899,-106.754280,0.094033,0.000000
101.900002,52.721977,-106.843246,-0.001293,0.003700,0.093990,234.519073,11.946971,0.939899,-106.843246,0.094033,0.000000
102.170006,52.689957,-106.887726,-0.001302,0.003700,0.093990,234.376633,11.939714,0.939899,-106.887726,0.094033,0.000000
102.440002,52.653465,-106.843246,-0.001281,0.003700,0.093990,234.214310,11.931446,0.939899,-106.843246,0.094033,0.000000
102.710007,52.610641,-106.932205,-0.001285,0.003700,0.093990,234.023819,11.921741,0.939899,-106.932205,0.094033,0.000000
102.980003,52.569679,-106.932205,-0.001289,0.003700,0.093990,233.841614,11.912459,0.939899,-106.932205,0.094033,0.000000
103.250008,52.543617,-106.932205,-0.001281,0.003700,0.093990,233.725677,11.906554,0.939899,-106.932205,0.094033,0.000000
103.520004,52.508240,-106.976685,-0.001293,0.003700,0.093990,233.568314,11.898537,0.939899,-106.976685,0.094033,0.000000
103.790009,52.477333,-107.021172,-0.001293,0.003700,0.093990,233.430832,11.891534,0.939899,-107.021172,0.094033,0.000000
104.060005,52.450150,-107.021172,-0.001293,0.003700,0.093990,233.309921,11.885374,0.939899,-107.021172,0.094033,0.000000
104.330002,52.415520,-107.065651,-0.001298,0.003700,0.093990,233.155884,11.877526,0.939899,-107.065651,0.094033,0.000000
104.600006,52.380142,-107.110130,-0.001298,0.003700,0.093990,232.998505,11.869510,0.939899,-107.110130,0.094033,0.000000
104.870003,52.347000,-107.110130,-0.001293,0.003700,0.093990,232.851089,11.862000,0.939899,-107.110130,0.094033,0.000000
105.140007,52.303436,-107.154610,-0.001289,0.003700,0.093990,232.657303,11.852128,0.939899,-107.154610,0.094033,0.000000
105.410004,52.276253,-107.110130,-0.001289,0.003700,0.093990,232.536392,11.845968,0.939899,-107.110130,0.094033,0.000000
105.680008,52.244972,-107.199089,-0.001281,0.003700,0.093990,232.397247,11.838880,0.939899,-107.199089,0.094033,0.000000
105.950005,52.195816,-107.154610,-0.001285,0.003700,0.093990,232.178589,11.827741,0.939899,-107.154610,0.094033,0.000000
106.220009,52.176086,-107.243576,-0.001293,0.003700,0.093990,232.090820,11.823271,0.939899,-107.243576,0.094033,0.000000
106.490005,52.145546,-107.332535,-0.001289,0.003700,0.093990,231.954971,11.816349,0.939899,-107.332535,0.094033,0.000000
106.760002,52.107567,-107.243576,-0.001281,0.003700,0.093990,231.786026,11.807744,0.939899,-107.243576,0.094033,0.000000
107.030006,52.090439,-107.288055,-0.001276,0.003700,0.093990,231.709839,11.803862,0.939899,-107.288055,0.094033,0.000000
107.300003,52.042404,-107.377014,-0.001293,0.003700,0.093990,231.496170,11.792977,0.939899,-107.377014,0.094033,0.000000
107.570007,52.023781,-107.377014,-0.001298,0.003700,0.093990,231.413330,11.788757,0.939899,-107.377014,0.094033,0.000000
107.840004,51.995483,-107.421494,-0.001285,0.003700,0.093990,231.287460,11.782345,0.939899,-107.421494,0.094033,0.000000
108.110008,51.961967,-107.421494,-0.001281,0.003700,0.093990,231.138382,11.774750,0.939899,-107.421494,0.094033,0.000000
108.380005,51.941116,-107.421494,-0.001281,0.003700,0.093990,231.045624,11.770025,0.939899,-107.421494,0.094033,0.000000
108.650002,51.904251,-107.554939,-0.001289,0.003700,0.093990,230.881638,11.761672,0.939899,-107.554939,0.094033,0.000000
108.920006,51.877068,-107.510460,-0.001281,0.003700,0.093990,230.760727,11.755512,0.939899,-107.510460,0.094033,0.000000
109.190002,51.842438,-107.510460,-0.001276,0.003700,0.093990,230.606674,11.747664,0.939899,-107.510460,0.094033,0.000000
109.460007,51.833504,-107.510460,-0.001276,0.003700,0.093990,230.566940,11.745640,0.939899,-107.510460,0.094033,0.000000
109.730003,51.795891,-107.599419,-0.001285,0.003700,0.093990,230.399628,11.737117,0.939899,-107.599419,0.094033,0.000000
110.000008,51.763496,-107.599419,-0.001289,0.003700,0.093990,230.255539,11.729775,0.939899,-107.599419,0.094033,0.000000
110.270004,51.746735,-107.643898,-0.001272,0.003700,0.093990,230.180969,11.725977,0.939899,-107.643898,0.094033,0.000000
110.540009,51.702049,-107.688385,-0.001276,0.003700,0.093990,229.982208,11.715852,0.939899,-107.688385,0.094033,0.000000
110.810005,51.681946,-107.643898,-0.001276,0.003700,0.093990,229.892776,11.711296,0.939899,-107.643898,0.094033,0.000000
111.080002,51.643219,-107.688385,-0.001272,0.003700,0.093990,229.720505,11.702520,0.939899,-107.688385,0.094033,0.000000
111.100006,51.643593,-107.688385,-0.001285,0.003700,0.093990,229.722168,11.702605,0.939899,-107.688385,0.094033,0.000000