File: Data/compression 4/AutoNoheating-10-4-1-240223_02232024_161809.csv
Time (sec),S:Load (lbs),S:HL1 (DIM),S:LVDT (in),S:Position (in),Ch:Position (mm),Ch:Load (N),Ch:Stress (MPa),Ch:Strain (mm/mm),Ch:HL1 (DIM),Set Point (),Cycles ()
0.010000,-0.001862,-87.271629,0.000009,-0.000000,-0.000000,-0.008281,-0.000422,-0.000000,-87.271629,-0.000260,0.000000
0.210000,-0.001495,-87.271629,-0.000004,-0.000000,-0.000000,-0.006652,-0.000339,-0.000000,-87.271629,-0.000260,0.000000
0.410000,0.088997,-87.271629,0.000009,0.000014,0.000347,0.395878,0.020167,0.003471,-87.271629,0.001041,0.000000
0.610000,0.084526,-87.316109,0.000013,0.000139,0.003538,0.375991,0.019154,0.035385,-87.316109,0.004371,0.000000
0.810000,0.091232,-87.360588,0.000060,0.000259,0.006591,0.405822,0.020674,0.065910,-87.360588,0.007701,0.000000
1.010000,0.067024,-87.271629,0.000194,0.000389,0.009869,0.298139,0.015188,0.098691,-87.271629,0.011031,0.000000
1.210000,0.066650,-87.271629,0.000336,0.000530,0.013459,0.296476,0.015103,0.134595,-87.271629,0.014361,0.000000
1.410000,0.075592,-87.316109,0.000457,0.000658,0.016703,0.336250,0.017129,0.167027,-87.316109,0.017691,0.000000
1.610000,0.090485,-87.316109,0.000591,0.000788,0.020016,0.402496,0.020504,0.200157,-87.316109,0.021022,0.000000
1.810000,0.100540,-87.316109,0.000729,0.000919,0.023346,0.447225,0.022783,0.233460,-87.316109,0.024369,0.000000
2.010000,0.083778,-87.360588,0.000845,0.001051,0.026685,0.372665,0.018984,0.266846,-87.360588,0.027699,0.000000
2.210000,0.080429,-87.360588,0.000983,0.001182,0.030015,0.357766,0.018225,0.300150,-87.360588,0.031029,0.000000
2.410000,0.088623,-87.316109,0.001112,0.001312,0.033328,0.394215,0.020082,0.333275,-87.316109,0.034360,0.000000
2.610000,0.062553,-87.360588,0.001242,0.001443,0.036640,0.278251,0.014175,0.366404,-87.360588,0.037690,0.000000
2.810000,0.079689,-87.405067,0.001371,0.001566,0.039780,0.354474,0.018058,0.397796,-87.405067,0.041020,0.000000
3.010000,0.069633,-87.360588,0.001500,0.001697,0.043101,0.309745,0.015779,0.431012,-87.360588,0.044350,0.000000
3.210000,0.056969,-87.360588,0.001630,0.001830,0.046475,0.253409,0.012909,0.464747,-87.360588,0.047680,0.000000
3.410000,0.034630,-87.405067,0.001763,0.001961,0.049813,0.154041,0.007847,0.498134,-87.405067,0.051010,0.000000
3.610000,0.051384,-87.316109,0.001910,0.002094,0.053196,0.228567,0.011644,0.531956,-87.316109,0.054358,0.000000
3.810000,0.081177,-87.360588,0.002031,0.002222,0.056439,0.361092,0.018395,0.564392,-87.360588,0.057688,0.000000
4.010000,0.084900,-87.405067,0.002164,0.002353,0.059778,0.377654,0.019239,0.597779,-87.405067,0.061018,0.000000
4.210000,0.098305,-87.360588,0.002302,0.002491,0.063264,0.437281,0.022276,0.632641,-87.360588,0.064348,0.000000
4.410000,0.104263,-87.449547,0.002436,0.002620,0.066551,0.463786,0.023626,0.665509,-87.449547,0.067678,0.000000
4.610000,0.109100,-87.405067,0.002570,0.002754,0.069942,0.485303,0.024722,0.699418,-87.405067,0.071008,0.000000
4.810000,0.096443,-87.449547,0.002677,0.002880,0.073159,0.429001,0.021854,0.731594,-87.449547,0.074339,0.000000
5.010000,0.098679,-87.405067,0.002815,0.003005,0.076333,0.438944,0.022361,0.763334,-87.405067,0.077669,0.000000
5.210000,0.091972,-87.360588,0.002949,0.003136,0.079655,0.409113,0.020841,0.796546,-87.360588,0.080999,0.000000
5.410000,0.087509,-87.494034,0.003074,0.003268,0.083011,0.389260,0.019830,0.830111,-87.494034,0.084329,0.000000
5.610000,0.090485,-87.449547,0.003203,0.003400,0.086367,0.402496,0.020504,0.863671,-87.449547,0.087677,0.000000
5.810000,0.144104,-87.405067,0.003337,0.003533,0.089741,0.641007,0.032654,0.897406,-87.405067,0.091007,0.000000
6.010000,0.138519,-87.449547,0.003462,0.003664,0.093071,0.616165,0.031389,0.930709,-87.449547,0.094337,0.000000
6.210001,0.137405,-87.405067,0.003600,0.003795,0.096383,0.611210,0.031137,0.963835,-87.405067,0.097667,0.000000
6.410000,0.137779,-87.405067,0.003725,0.003927,0.099757,0.612873,0.031221,0.997570,-87.405067,0.100997,0.000000
6.610000,0.129959,-87.494034,0.003859,0.004053,0.102948,0.578087,0.029449,1.029484,-87.494034,0.104327,0.000000
6.810000,0.125114,-87.494034,0.003992,0.004189,0.106392,0.556537,0.028351,1.063915,-87.494034,0.107658,0.000000
7.010000,0.105377,-87.449547,0.004130,0.004320,0.109721,0.468741,0.023879,1.097215,-87.449547,0.110987,0.000000
7.210001,0.100540,-87.494034,0.004251,0.004450,0.113034,0.447225,0.022783,1.130344,-87.494034,0.114318,0.000000
7.410000,0.096443,-87.449547,0.004389,0.004581,0.116356,0.429001,0.021854,1.163556,-87.449547,0.117665,0.000000
7.610000,0.093094,-87.449547,0.004518,0.004722,0.119937,0.414102,0.021095,1.199373,-87.449547,0.120996,0.000000
7.810000,0.098679,-87.494034,0.004661,0.004853,0.123259,0.438944,0.022361,1.232589,-87.494034,0.124325,0.000000
8.010000,0.122879,-87.494034,0.004790,0.004979,0.126476,0.546593,0.027845,1.264764,-87.494034,0.127656,0.000000
8.210000,0.112457,-87.494034,0.004924,0.005113,0.129876,0.500235,0.025483,1.298756,-87.494034,0.130986,0.000000
8.410001,0.107986,-87.582993,0.005070,0.005247,0.133284,0.480348,0.024470,1.332839,-87.582993,0.134316,0.000000
8.610001,0.096817,-87.538513,0.005187,0.005377,0.136579,0.430664,0.021939,1.365795,-87.538513,0.137646,0.000000
8.810000,0.121391,-87.494034,0.005329,0.005507,0.139866,0.539975,0.027508,1.398663,-87.494034,0.140976,0.000000
9.010000,0.100540,-87.494034,0.005463,0.005637,0.143188,0.447225,0.022783,1.431879,-87.494034,0.144306,0.000000
9.210000,0.096069,-87.582993,0.005596,0.005764,0.146414,0.427338,0.021770,1.464137,-87.582993,0.147637,0.000000
9.410001,0.078568,-87.538513,0.005700,0.005893,0.149692,0.349486,0.017804,1.496918,-87.538513,0.150984,0.000000
9.610001,0.073730,-87.582993,0.005838,0.006026,0.153048,0.327969,0.016708,1.530483,-87.582993,0.154314,0.000000
9.810000,0.098305,-87.582993,0.005967,0.006158,0.156422,0.437281,0.022276,1.564218,-87.582993,0.157644,0.000000
10.010000,0.170174,-87.538513,0.006092,0.006292,0.159813,0.756970,0.038562,1.598127,-87.538513,0.160975,0.000000
10.210000,0.266617,-87.582993,0.006222,0.006420,0.163065,1.185971,0.060416,1.630646,-87.582993,0.164305,0.000000
10.410001,0.395454,-87.538513,0.006364,0.006554,0.166464,1.759069,0.089611,1.664642,-87.538513,0.167635,0.000000
10.610001,0.553719,-87.538513,0.006502,0.006688,0.169863,2.463063,0.125474,1.698634,-87.538513,0.170965,0.000000
10.810000,0.567123,-87.582993,0.006579,-0.000008,-0.000199,2.522691,0.128512,-0.001995,-87.582993,-0.000061,0.000000
11.010000,0.543663,-87.582993,0.006584,-0.000008,-0.000208,2.418334,0.123196,-0.002082,-87.582993,-0.000061,0.000000
11.210001,0.522812,-87.627472,0.006597,-0.000008,-0.000208,2.325583,0.118471,-0.002082,-87.627472,-0.000061,0.000000
11.410001,0.517593,-87.538513,0.006597,-0.000008,-0.000208,2.302370,0.117288,-0.002082,-87.538513,0.000260,0.000000
11.610001,0.506424,-87.582993,0.006597,-0.000008,-0.000199,2.252686,0.114757,-0.001995,-87.582993,0.000598,0.000000
11.810000,0.539566,-87.582993,0.006579,0.000004,0.000095,2.400110,0.122267,0.000954,-87.582993,0.000928,0.000000
12.010000,0.551483,-87.582993,0.006601,0.000019,0.000477,2.453120,0.124968,0.004769,-87.582993,0.001257,0.000000
12.210001,0.586861,-87.627472,0.006618,0.000029,0.000737,2.610487,0.132985,0.007373,-87.627472,0.001596,0.000000
12.410001,0.612549,-87.627472,0.006618,0.000038,0.000971,2.724753,0.138806,0.009712,-87.627472,0.001925,0.000000
12.610001,0.637497,-87.627472,0.006635,0.000053,0.001353,2.835728,0.144459,0.013527,-87.627472,0.002263,0.000000
12.810000,0.652397,-87.671951,0.006648,0.000065,0.001639,2.902008,0.147835,0.016389,-87.671951,0.002593,0.000000
13.010000,0.679581,-87.671951,0.006661,0.000078,0.001986,3.022926,0.153995,0.019859,-87.671951,0.002931,0.000000
13.210001,0.697823,-87.582993,0.006670,0.000084,0.002142,3.104070,0.158129,0.021419,-87.582993,0.003261,0.000000
13.410001,0.739532,-87.582993,0.006674,0.000104,0.002636,3.289605,0.167580,0.026362,-87.582993,0.003590,0.000000
13.610001,0.787193,-87.716438,0.006704,0.000122,0.003105,3.501611,0.178381,0.031047,-87.716438,0.003928,0.000000
13.810000,0.786446,-87.671951,0.006709,0.000135,0.003417,3.498285,0.178211,0.034170,-87.671951,0.004258,0.000000
14.010000,0.790916,-87.671951,0.006730,0.000147,0.003738,3.518172,0.179224,0.037376,-87.671951,0.004596,0.000000
14.210001,0.812889,-87.671951,0.006735,0.000159,0.004041,3.615911,0.184203,0.040411,-87.671951,0.004926,0.000000
14.410001,0.831131,-87.671951,0.006756,0.000170,0.004310,3.697055,0.188337,0.043102,-87.671951,0.005264,0.000000
14.610001,0.870979,-87.760918,0.006756,0.000186,0.004726,3.874310,0.197367,0.047262,-87.760918,0.005594,0.000000
14.810000,0.899651,-87.716438,0.006782,0.000200,0.005082,4.001846,0.203864,0.050820,-87.716438,0.005932,0.000000
15.010001,0.882523,-87.760918,0.006782,0.000206,0.005221,3.925657,0.199982,0.052205,-87.760918,0.006261,0.000000
15.210001,0.898163,-87.805397,0.006795,0.000216,0.005490,3.995228,0.203527,0.054896,-87.805397,0.006591,0.000000
15.410001,0.969284,-87.716438,0.006817,0.000235,0.005967,4.311591,0.219643,0.059665,-87.716438,0.006929,0.000000
15.610001,0.985298,-87.760918,0.006842,0.000252,0.006392,4.382825,0.223272,0.063916,-87.760918,0.007259,0.000000
15.810000,0.981941,-87.716438,0.006851,0.000263,0.006678,4.367893,0.222511,0.066777,-87.716438,0.007597,0.000000
16.010000,0.999443,-87.760918,0.006868,0.000278,0.007051,4.445745,0.226477,0.070505,-87.760918,0.007926,0.000000
16.210001,1.001678,-87.716438,0.006868,0.000287,0.007293,4.455688,0.226984,0.072935,-87.716438,0.008265,0.000000
16.410000,0.995346,-87.716438,0.006890,0.000298,0.007580,4.427520,0.225549,0.075796,-87.716438,0.008594,0.000000
16.610001,1.057167,-87.760918,0.006898,0.000314,0.007970,4.702514,0.239557,0.079699,-87.760918,0.008932,0.000000
16.810001,1.059395,-87.760918,0.006907,0.000323,0.008212,4.712424,0.240062,0.082125,-87.760918,0.009262,0.000000
17.010000,1.090675,-87.760918,0.006920,0.000337,0.008568,4.851566,0.247151,0.085682,-87.760918,0.009591,0.000000
17.210001,1.119720,-87.805397,0.006933,0.000345,0.008759,4.980765,0.253732,0.087590,-87.805397,0.009930,0.000000
17.410002,1.180420,-87.760918,0.006967,0.000366,0.009296,5.250770,0.267487,0.092965,-87.760918,0.010259,0.000000
17.610001,1.159569,-87.805397,0.006976,0.000377,0.009583,5.158020,0.262762,0.095830,-87.805397,0.010597,0.000000
17.810001,1.207977,-87.805397,0.006989,0.000393,0.009973,5.373352,0.273732,0.099732,-87.805397,0.010927,0.000000
18.010000,1.210205,-87.849876,0.007002,0.000406,0.010320,5.383261,0.274236,0.103199,-87.849876,0.011265,0.000000
18.210001,1.203133,-87.760918,0.007015,0.000416,0.010572,5.351801,0.272634,0.105716,-87.760918,0.011595,0.000000
18.410002,1.203880,-87.849876,0.007019,0.000426,0.010814,5.355127,0.272803,0.108142,-87.849876,0.011924,0.000000
18.610001,1.279472,-87.805397,0.007041,0.000442,0.011231,5.691377,0.289933,0.112305,-87.805397,0.012263,0.000000
18.810001,1.298088,-87.805397,0.007049,0.000454,0.011525,5.774184,0.294151,0.115254,-87.805397,0.012592,0.000000
19.010000,1.295113,-87.805397,0.007058,0.000462,0.011742,5.760949,0.293477,0.117423,-87.805397,0.012930,0.000000
19.210001,1.339790,-87.849876,0.007080,0.000481,0.012210,5.959685,0.303601,0.122104,-87.849876,0.013260,0.000000
19.410002,1.355431,-87.849876,0.007084,0.000495,0.012566,6.029256,0.307145,0.125662,-87.849876,0.013598,0.000000
19.610001,1.400116,-87.805397,0.007123,0.000511,0.012973,6.228027,0.317271,0.129735,-87.805397,0.013928,0.000000
19.810001,1.413155,-87.849876,0.007127,0.000523,0.013294,6.286026,0.320225,0.132944,-87.849876,0.014266,0.000000
20.010000,1.367348,-87.894356,0.007148,0.000533,0.013546,6.082266,0.309845,0.135461,-87.894356,0.014595,0.000000
20.210001,1.391182,-87.894356,0.007144,0.000545,0.013850,6.188286,0.315246,0.138497,-87.894356,0.014925,0.000000
20.410002,1.432518,-87.849876,0.007153,0.000558,0.014179,6.372159,0.324613,0.141790,-87.849876,0.015263,0.000000
20.610001,1.491722,-87.894356,0.007174,0.000575,0.014595,6.635511,0.338029,0.145953,-87.894356,0.015593,0.000000
20.810001,1.482788,-87.894356,0.007183,0.000584,0.014830,6.595771,0.336005,0.148296,-87.894356,0.015931,0.000000
21.010000,1.511086,-87.894356,0.007205,0.000594,0.015090,6.721644,0.342417,0.150896,-87.894356,0.016260,0.000000
21.210001,1.536407,-87.938843,0.007217,0.000605,0.015376,6.834282,0.348155,0.153758,-87.938843,0.016599,0.000000
21.410002,1.601196,-87.938843,0.007248,0.000628,0.015948,7.122477,0.362836,0.159484,-87.938843,0.016928,0.000000
21.610001,1.602318,-87.938843,0.007252,0.000642,0.016295,7.127466,0.363090,0.162951,-87.938843,0.017266,0.000000
21.810001,1.575874,-87.894356,0.007265,0.000650,0.016521,7.009839,0.357098,0.165207,-87.894356,0.017596,0.000000
22.010000,1.592636,-87.983322,0.007282,0.000665,0.016894,7.084399,0.360896,0.168935,-87.983322,0.017926,0.000000
22.210001,1.582954,-87.894356,0.007299,0.000675,0.017145,7.041333,0.358703,0.171452,-87.894356,0.018264,0.000000
22.410002,1.638809,-87.983322,0.007304,0.000688,0.017466,7.289787,0.371359,0.174658,-87.983322,0.018593,0.000000
22.610001,1.727432,-87.983322,0.007321,0.000705,0.017917,7.684002,0.391442,0.179169,-87.983322,0.018932,0.000000
22.810001,1.690567,-87.938843,0.007338,0.000714,0.018134,7.520018,0.383088,0.181338,-87.938843,0.019261,0.000000
23.010000,1.762062,-87.938843,0.007347,0.000727,0.018472,7.838044,0.399289,0.184718,-87.938843,0.019599,0.000000
23.210001,1.832443,-87.983322,0.007377,0.000748,0.019010,8.151114,0.415238,0.190096,-87.983322,0.019929,0.000000
23.410002,1.856644,-87.938843,0.007399,0.000767,0.019469,8.258763,0.420721,0.194691,-87.938843,0.020258,0.000000
23.610001,1.816803,-87.938843,0.007411,0.000777,0.019747,8.081543,0.411693,0.197466,-87.938843,0.020597,0.000000
23.810001,1.787384,-88.027802,0.007416,0.000787,0.019998,7.950681,0.405027,0.199982,-88.027802,0.020926,0.000000
24.010000,1.797066,-87.983322,0.007429,0.000800,0.020311,7.993748,0.407221,0.203105,-87.983322,0.021264,0.000000
24.210001,1.795578,-87.983322,0.007433,0.000810,0.020571,7.987130,0.406884,0.205705,-87.983322,0.021594,0.000000
24.410002,1.905426,-88.027802,0.007459,0.000824,0.020926,8.475759,0.431776,0.209263,-88.027802,0.021932,0.000000
24.610001,1.910271,-88.027802,0.007459,0.000833,0.021160,8.497309,0.432874,0.211602,-88.027802,0.022262,0.000000
24.810001,1.973946,-88.027802,0.007485,0.000847,0.021525,8.780549,0.447302,0.215247,-88.027802,0.022600,0.000000
25.010002,1.961655,-88.027802,0.007502,0.000856,0.021732,8.725876,0.444517,0.217325,-88.027802,0.022929,0.000000
25.210001,2.142632,-88.027802,0.007524,0.000884,0.022444,9.530901,0.485527,0.224437,-88.027802,0.023259,0.000000
25.410002,2.071877,-88.072281,0.007545,0.000896,0.022765,9.216167,0.469494,0.227646,-88.072281,0.023597,0.000000
25.610001,2.055862,-88.027802,0.007558,0.000905,0.022982,9.144933,0.465865,0.229815,-88.027802,0.023927,0.000000
25.810001,2.035385,-88.072281,0.007558,0.000917,0.023285,9.053845,0.461225,0.232851,-88.072281,0.024265,0.000000
26.010002,1.997032,-87.983322,0.007575,0.000926,0.023528,8.883243,0.452534,0.235277,-87.983322,0.024595,0.000000
26.210001,2.109489,-88.072281,0.007597,0.000942,0.023918,9.383477,0.478017,0.239179,-88.072281,0.024933,0.000000
26.410002,2.261040,-88.027802,0.007618,0.000958,0.024334,10.057607,0.512359,0.243342,-88.027802,0.025262,0.000000
26.610001,2.248383,-88.072281,0.007627,0.000970,0.024638,10.001306,0.509491,0.246378,-88.072281,0.025592,0.000000
26.810001,2.148956,-88.072281,0.007640,0.000972,0.024690,9.559035,0.486960,0.246900,-88.072281,0.025930,0.000000
27.010002,2.286736,-88.116760,0.007657,0.000992,0.025202,10.171907,0.518182,0.252017,-88.116760,0.026260,0.000000
27.210001,2.379829,-88.027802,0.007675,0.001009,0.025635,10.586010,0.539277,0.256351,-88.027802,0.026598,0.000000
27.410002,2.345947,-88.072281,0.007683,0.001022,0.025965,10.435294,0.531599,0.259648,-88.072281,0.026927,0.000000
27.610001,2.350044,-88.072281,0.007700,0.001034,0.026268,10.453519,0.532528,0.262683,-88.072281,0.027266,0.000000
27.810001,2.342590,-88.027802,0.007700,0.001044,0.026520,10.420362,0.530839,0.265196,-88.027802,0.027595,0.000000
28.010002,2.374992,-88.161247,0.007731,0.001055,0.026797,10.564494,0.538181,0.267974,-88.161247,0.027933,0.000000
28.210001,2.490051,-88.116760,0.007735,0.001074,0.027274,11.076302,0.564254,0.272743,-88.116760,0.028263,0.000000
28.410002,2.546280,-88.072281,0.007761,0.001088,0.027647,11.326419,0.576995,0.276471,-88.072281,0.028592,0.000000
28.610001,2.516121,-88.116760,0.007765,0.001099,0.027925,11.192265,0.570161,0.279246,-88.116760,0.028931,0.000000
28.810001,2.541069,-88.116760,0.007769,0.001108,0.028141,11.303240,0.575814,0.281415,-88.116760,0.029260,0.000000
29.010002,2.693741,-88.116760,0.007804,0.001129,0.028679,11.982358,0.610410,0.286793,-88.116760,0.029598,0.000000
29.210001,2.680710,-88.116760,0.007812,0.001141,0.028983,11.924393,0.607458,0.289828,-88.116760,0.029928,0.000000
29.410002,2.711243,-88.116760,0.007821,0.001155,0.029330,12.060210,0.614376,0.293295,-88.116760,0.030266,0.000000
29.610001,2.720551,-88.116760,0.007834,0.001168,0.029668,12.101613,0.616486,0.296679,-88.116760,0.030596,0.000000
29.810001,2.710869,-88.116760,0.007851,0.001180,0.029963,12.058547,0.614292,0.299627,-88.116760,0.030934,0.000000
30.010002,2.795029,-88.161247,0.007860,0.001193,0.030292,12.432909,0.633363,0.302920,-88.161247,0.031264,0.000000
30.210001,2.924980,-88.161247,0.007886,0.001209,0.030700,13.010962,0.662810,0.306997,-88.161247,0.031593,0.000000
30.410002,2.897797,-88.161247,0.007899,0.001220,0.030986,12.890043,0.656650,0.309858,-88.161247,0.031931,0.000000
30.610001,2.911209,-88.161247,0.007916,0.001231,0.031264,12.949705,0.659689,0.312636,-88.161247,0.032261,0.000000
30.810001,2.990524,-88.205727,0.007925,0.001243,0.031584,13.302516,0.677662,0.315842,-88.205727,0.032599,0.000000
31.010002,3.002068,-88.161247,0.007925,0.001255,0.031871,13.353864,0.680278,0.318707,-88.161247,0.032929,0.000000
31.210001,3.240013,-88.205727,0.007946,0.001278,0.032452,14.412298,0.734197,0.324517,-88.205727,0.033267,0.000000
31.410002,3.125320,-88.205727,0.007963,0.001289,0.032738,13.902120,0.708208,0.327378,-88.205727,0.033596,0.000000
31.610001,3.140961,-88.161247,0.007972,0.001299,0.032998,13.971691,0.711752,0.329978,-88.161247,0.033926,0.000000
31.810001,3.216179,-88.205727,0.008002,0.001312,0.033319,14.306278,0.728797,0.333188,-88.205727,0.034264,0.000000
32.010002,3.366241,-88.250206,0.008006,0.001328,0.033744,14.973790,0.762801,0.337439,-88.250206,0.034594,0.000000
32.210003,3.366989,-88.250206,0.008019,0.001340,0.034030,14.977116,0.762971,0.340300,-88.250206,0.034932,0.000000
32.410000,3.433273,-88.250206,0.008041,0.001352,0.034342,15.271962,0.777991,0.343422,-88.250206,0.035261,0.000000
32.610001,3.407578,-88.250206,0.008045,0.001360,0.034533,15.157661,0.772168,0.345330,-88.250206,0.035600,0.000000
32.810001,3.681641,-88.250206,0.008063,0.001379,0.035019,16.376755,0.834272,0.350186,-88.250206,0.035929,0.000000
33.010002,3.723351,-88.205727,0.008075,0.001393,0.035391,16.562290,0.843723,0.353914,-88.205727,0.036267,0.000000
33.210003,3.778831,-88.250206,0.008093,0.001407,0.035747,16.809082,0.856295,0.357472,-88.250206,0.036597,0.000000
33.410000,3.792984,-88.250206,0.008101,0.001421,0.036085,16.872036,0.859502,0.360852,-88.250206,0.036927,0.000000
33.610001,3.829102,-88.339172,0.008119,0.001433,0.036389,17.032694,0.867687,0.363887,-88.339172,0.037265,0.000000
33.810001,3.867828,-88.250206,0.008123,0.001443,0.036649,17.204960,0.876462,0.366488,-88.250206,0.037594,0.000000
34.010002,3.857407,-88.294685,0.008144,0.001452,0.036874,17.158602,0.874101,0.368743,-88.294685,0.037933,0.000000
34.210003,4.124397,-88.294685,0.008162,0.001470,0.037343,18.346235,0.934602,0.373425,-88.294685,0.038262,0.000000
34.410000,4.084923,-88.294685,0.008179,0.001480,0.037594,18.170645,0.925657,0.375942,-88.294685,0.038600,0.000000
34.610001,4.132217,-88.294685,0.008179,0.001489,0.037829,18.381021,0.936374,0.378285,-88.294685,0.038930,0.000000
34.810001,4.405167,-88.339172,0.008188,0.001507,0.038271,19.595160,0.998225,0.382706,-88.339172,0.039268,0.000000
35.010002,4.544807,-88.339172,0.008209,0.001523,0.038696,20.216312,1.029868,0.386956,-88.339172,0.039598,0.000000
35.210003,4.569382,-88.294685,0.008226,0.001537,0.039051,20.325624,1.035437,0.390510,-88.294685,0.039927,0.000000
35.410000,4.641991,-88.383652,0.008226,0.001550,0.039381,20.648605,1.051890,0.393807,-88.383652,0.040265,0.000000
35.610001,4.628960,-88.294685,0.008244,0.001561,0.039641,20.590641,1.048937,0.396407,-88.294685,0.040595,0.000000
35.810001,4.720192,-88.294685,0.008261,0.001574,0.039979,20.996462,1.069611,0.399791,-88.294685,0.040933,0.000000
36.010002,5.030380,-88.339172,0.008274,0.001592,0.040430,22.376249,1.139900,0.404299,-88.339172,0.041263,0.000000
36.210003,5.015854,-88.339172,0.008287,0.001600,0.040638,22.311632,1.136609,0.406380,-88.339172,0.041601,0.000000
36.410000,4.847542,-88.383652,0.008291,0.001604,0.040742,21.562943,1.098469,0.407421,-88.383652,0.041930,0.000000
36.610001,5.229599,-88.339172,0.008308,0.001622,0.041202,23.262419,1.185044,0.412020,-88.339172,0.042260,0.000000
36.810001,5.511482,-88.339172,0.008317,0.001640,0.041661,24.516298,1.248920,0.416615,-88.339172,0.042598,0.000000
37.010002,5.700645,-88.383652,0.008347,0.001656,0.042052,25.357737,1.291785,0.420517,-88.383652,0.042928,0.000000
37.210003,5.600853,-88.383652,0.008343,0.001667,0.042329,24.913837,1.269171,0.423291,-88.383652,0.043266,0.000000
37.410004,5.841408,-88.383652,0.008364,0.001681,0.042702,25.983879,1.323682,0.427023,-88.383652,0.043596,0.000000
37.610001,5.949768,-88.383652,0.008373,0.001692,0.042988,26.465891,1.348237,0.429885,-88.383652,0.043934,0.000000
37.810001,5.882362,-88.383652,0.008377,0.001701,0.043205,26.166054,1.332962,0.432053,-88.383652,0.044263,0.000000
38.010002,6.419327,-88.428131,0.008403,0.001719,0.043665,28.554592,1.454640,0.436648,-88.428131,0.044602,0.000000
38.210003,6.308731,-88.383652,0.008395,0.001728,0.043890,28.062637,1.429579,0.438904,-88.383652,0.044931,0.000000
38.410004,6.518753,-88.428131,0.008416,0.001740,0.044185,28.996862,1.477171,0.441852,-88.428131,0.045261,0.000000
38.610001,6.780899,-88.517090,0.008416,0.001751,0.044471,30.162945,1.536574,0.444714,-88.517090,0.045599,0.000000
38.810001,7.105240,-88.428131,0.008442,0.001768,0.044896,31.605686,1.610070,0.448964,-88.428131,0.045928,0.000000
39.010002,7.254555,-88.428131,0.008446,0.001783,0.045278,32.269871,1.643906,0.452779,-88.428131,0.046267,0.000000
39.210003,7.456383,-88.428131,0.008476,0.001795,0.045581,33.167648,1.689641,0.455815,-88.428131,0.046596,0.000000
39.410004,7.723373,-88.472610,0.008476,0.001810,0.045980,34.355282,1.750141,0.459804,-88.472610,0.046934,0.000000
39.610001,7.737152,-88.517090,0.008489,0.001818,0.046180,34.416573,1.753264,0.461799,-88.517090,0.047264,0.000000
39.810001,7.886475,-88.472610,0.008498,0.001828,0.046431,35.080791,1.787101,0.464312,-88.472610,0.047593,0.000000
40.010002,8.366837,-88.472610,0.008498,0.001842,0.046795,37.217548,1.895952,0.467953,-88.472610,0.047932,0.000000
40.210003,8.550041,-88.517090,0.008507,0.001856,0.047151,38.032482,1.937467,0.471511,-88.517090,0.048261,0.000000
40.410004,9.142860,-88.517090,0.008532,0.001872,0.047559,40.669476,2.071802,0.475587,-88.517090,0.048599,0.000000
40.610001,9.476135,-88.517090,0.008545,0.001886,0.047914,42.151955,2.147323,0.479141,-88.517090,0.048929,0.000000
40.810001,9.588219,-88.472610,0.008558,0.001900,0.048252,42.650528,2.172721,0.482525,-88.472610,0.049267,0.000000
41.010002,9.801956,-88.472610,0.008576,0.001911,0.048530,43.601280,2.221155,0.485299,-88.472610,0.049597,0.000000
41.210003,10.063362,-88.517090,0.008584,0.001924,0.048868,44.764069,2.280390,0.488683,-88.517090,0.049935,0.000000
41.410004,10.404457,-88.472610,0.008584,0.001937,0.049198,46.281338,2.357684,0.491976,-88.472610,0.050265,0.000000
41.610001,10.535530,-88.561577,0.008601,0.001945,0.049397,46.864380,2.387385,0.493970,-88.561577,0.050594,0.000000
41.810001,11.030785,-88.517090,0.008614,0.001961,0.049805,49.067379,2.499612,0.498047,-88.517090,0.050932,0.000000
42.010002,11.852989,-88.561577,0.008614,0.001980,0.050299,52.724728,2.685926,0.502990,-88.561577,0.051262,0.000000
42.210003,11.849632,-88.561577,0.008619,0.001985,0.050420,52.709797,2.685165,0.504205,-88.561577,0.051600,0.000000
42.410004,12.280838,-88.517090,0.008640,0.002000,0.050802,54.627895,2.782878,0.508020,-88.517090,0.051930,0.000000
42.610001,13.119049,-88.517090,0.008658,0.002018,0.051262,58.356445,2.972819,0.512619,-88.517090,0.052268,0.000000
42.810001,13.551376,-88.517090,0.008653,0.002032,0.051617,60.279533,3.070786,0.516173,-88.517090,0.052597,0.000000
43.010002,13.873108,-88.561577,0.008662,0.002043,0.051895,61.710667,3.143691,0.518947,-88.561577,0.052936,0.000000
43.210003,13.982208,-88.517090,0.008683,0.002051,0.052085,62.195969,3.168414,0.520855,-88.517090,0.053265,0.000000
43.410004,14.865479,-88.561577,0.008683,0.002070,0.052580,66.124954,3.368566,0.525798,-88.561577,0.053594,0.000000
43.610001,15.114594,-88.517090,0.008696,0.002080,0.052840,67.233070,3.425016,0.528402,-88.517090,0.053933,0.000000
43.810001,15.334671,-88.561577,0.008696,0.002089,0.053048,68.212021,3.474886,0.530483,-88.561577,0.054262,0.000000
44.010002,16.334862,-88.561577,0.008701,0.002106,0.053482,72.661095,3.701533,0.534817,-88.561577,0.054601,0.000000
44.210003,16.731064,-88.606056,0.008714,0.002117,0.053759,74.423492,3.791313,0.537591,-88.606056,0.054930,0.000000
44.410004,17.543213,-88.650536,0.008714,0.002136,0.054245,78.036110,3.975349,0.542451,-88.650536,0.055268,0.000000
44.610001,18.865135,-88.606056,0.008722,0.002155,0.054748,83.916313,4.274901,0.547477,-88.606056,0.055598,0.000000
44.810001,19.559608,-88.606056,0.008748,0.002171,0.055147,87.005486,4.432271,0.551467,-88.606056,0.055928,0.000000
45.010002,19.512688,-88.606056,0.008765,0.002177,0.055294,86.796768,4.421638,0.552943,-88.606056,0.056265,0.000000
45.210003,19.867928,-88.650536,0.008748,0.002189,0.055589,88.376953,4.502137,0.555891,-88.650536,0.056595,0.000000
45.410004,20.624588,-88.650536,0.008770,0.002203,0.055953,91.742752,4.673599,0.559532,-88.650536,0.056934,0.000000
45.610001,20.990265,-88.650536,0.008778,0.002213,0.056205,93.369362,4.756462,0.562049,-88.650536,0.057263,0.000000
45.810001,21.782295,-88.695015,0.008787,0.002223,0.056474,96.892487,4.935939,0.564737,-88.695015,0.057601,0.000000
46.010002,22.306229,-88.650536,0.008778,0.002237,0.056812,99.223061,5.054664,0.568120,-88.650536,0.057930,0.000000
46.210003,23.180557,-88.650536,0.008795,0.002250,0.057150,103.112267,5.252789,0.571500,-88.650536,0.058269,0.000000
46.410004,23.610275,-88.695015,0.008795,0.002257,0.057324,105.023750,5.350165,0.573237,-88.695015,0.058598,0.000000
46.610001,25.819191,-88.695015,0.008800,0.002286,0.058061,114.849495,5.850712,0.580607,-88.695015,0.058928,0.000000
46.810001,26.332314,-88.739494,0.008817,0.002297,0.058338,117.131981,5.966987,0.583381,-88.739494,0.059266,0.000000
47.010002,26.559837,-88.650536,0.008821,0.002305,0.058546,118.144058,6.018545,0.585463,-88.650536,0.059596,0.000000
47.210003,27.448692,-88.739494,0.008834,0.002319,0.058902,122.097885,6.219963,0.589020,-88.739494,0.059934,0.000000
47.410004,27.713448,-88.650536,0.008830,0.002326,0.059084,123.275574,6.279957,0.590841,-88.650536,0.060263,0.000000
47.610001,28.746407,-88.695015,0.008830,0.002341,0.059457,127.870399,6.514029,0.594569,-88.695015,0.060602,0.000000
47.810001,30.013962,-88.739494,0.008843,0.002357,0.059865,133.508774,6.801261,0.598646,-88.739494,0.060931,0.000000
48.010002,30.873772,-88.739494,0.008852,0.002370,0.060194,137.333389,6.996097,0.601942,-88.739494,0.061269,0.000000
48.210003,30.983994,-88.783981,0.008843,0.002382,0.060498,137.823685,7.021073,0.604978,-88.783981,0.061599,0.000000
48.410004,32.324165,-88.739494,0.008860,0.002394,0.060801,143.785065,7.324760,0.608013,-88.739494,0.061928,0.000000
48.610001,33.588364,-88.739494,0.008864,0.002411,0.061243,149.408508,7.611232,0.612434,-88.739494,0.062267,0.000000
48.810001,34.479080,-88.695015,0.008864,0.002422,0.061521,153.370605,7.813071,0.615208,-88.695015,0.062596,0.000000
49.010002,35.349319,-88.739494,0.008869,0.002435,0.061859,157.241623,8.010270,0.618592,-88.739494,0.062934,0.000000
49.210003,36.026665,-88.783981,0.008877,0.002447,0.062154,160.254608,8.163759,0.621540,-88.783981,0.063264,0.000000
49.410004,36.993340,-88.739494,0.008877,0.002461,0.062501,164.554596,8.382811,0.625011,-88.739494,0.063602,0.000000
49.610001,38.669014,-88.783981,0.008886,0.002477,0.062926,172.008362,8.762524,0.629258,-88.783981,0.063932,0.000000
49.810001,39.557121,-88.828461,0.008886,0.002490,0.063247,175.958862,8.963772,0.632467,-88.828461,0.064261,0.000000
50.010002,40.415443,-88.872940,0.008877,0.002500,0.063507,179.776871,9.158271,0.635068,-88.872940,0.064599,0.000000
50.210003,41.278976,-88.828461,0.008895,0.002516,0.063906,183.618057,9.353950,0.639057,-88.828461,0.064929,0.000000
50.410004,42.480247,-88.783981,0.008899,0.002526,0.064166,188.961578,9.626162,0.641661,-88.783981,0.065267,0.000000
50.610001,43.698280,-88.783981,0.008908,0.002542,0.064565,194.379654,9.902172,0.645650,-88.783981,0.065597,0.000000
50.810001,44.895828,-88.783981,0.008899,0.002557,0.064938,199.706619,10.173540,0.649378,-88.783981,0.065935,0.000000
51.010002,45.913147,-88.783981,0.008916,0.002568,0.065233,204.231873,10.404068,0.652327,-88.783981,0.066265,0.000000
51.210003,46.836632,-88.828461,0.008921,0.002581,0.065562,208.339737,10.613333,0.655623,-88.828461,0.066603,0.000000
51.410004,47.986145,-88.828461,0.008921,0.002595,0.065918,213.453033,10.873816,0.659177,-88.828461,0.066932,0.000000
51.610001,49.597404,-88.828461,0.008921,0.002611,0.066317,220.620270,11.238932,0.663167,-88.828461,0.067262,0.000000
51.810001,50.425560,-88.828461,0.008921,0.002621,0.066577,224.304092,11.426596,0.665771,-88.828461,0.067600,0.000000
52.010002,51.168068,-88.828461,0.008921,0.002631,0.066828,227.606934,11.594850,0.668284,-88.828461,0.067930,0.000000
52.210003,52.596489,-88.872940,0.008925,0.002646,0.067210,233.960861,11.918535,0.672099,-88.872940,0.068268,0.000000
52.410004,53.354645,-88.828461,0.008933,0.002657,0.067487,237.333313,12.090336,0.674873,-88.828461,0.068597,0.000000
52.610001,55.527061,-88.872940,0.008933,0.002678,0.068016,246.996704,12.582612,0.680165,-88.872940,0.068936,0.000000
52.810001,56.524651,-88.872940,0.008938,0.002689,0.068311,251.434204,12.808668,0.683113,-88.872940,0.069265,0.000000
53.010002,57.511810,-88.872940,0.008933,0.002700,0.068572,255.825302,13.032363,0.685717,-88.872940,0.069595,0.000000
53.210003,58.681427,-88.872940,0.008933,0.002711,0.068867,261.028015,13.297401,0.688665,-88.872940,0.069933,0.000000
53.410004,60.294174,-88.917419,0.008933,0.002729,0.069309,268.201874,13.662855,0.693086,-88.917419,0.070263,0.000000
53.610004,61.354691,-88.872940,0.008942,0.002740,0.069586,272.919281,13.903172,0.695861,-88.872940,0.070601,0.000000
53.810001,62.557823,-88.917419,0.008942,0.002752,0.069898,278.271088,14.175805,0.698983,-88.917419,0.070930,0.000000
54.010002,63.569191,-88.917419,0.008942,0.002766,0.070254,282.769897,14.404984,0.702541,-88.917419,0.071268,0.000000
54.210003,65.332375,-88.917419,0.008946,0.002780,0.070601,290.612915,14.804527,0.706008,-88.917419,0.071598,0.000000
54.410004,66.553017,-88.961899,0.008951,0.002792,0.070922,296.042603,15.081130,0.709217,-88.961899,0.071936,0.000000
54.610004,67.512611,-88.917419,0.008946,0.002796,0.071008,300.311096,15.298576,0.710084,-88.917419,0.071208,0.000000
54.810001,67.307442,-88.917419,0.008955,0.002795,0.071000,299.398468,15.252085,0.709997,-88.917419,0.071208,0.000000
55.010002,67.130562,-89.006386,0.008964,0.002795,0.070991,298.611664,15.212003,0.709910,-89.006386,0.070991,0.000000
55.210003,66.957405,-88.917419,0.008951,0.002795,0.070982,297.841400,15.172765,0.709823,-88.917419,0.070991,0.000000
55.410004,66.812553,-89.006386,0.008946,0.002794,0.070974,297.197083,15.139941,0.709736,-89.006386,0.070991,0.000000
55.610004,66.690041,-89.006386,0.008955,0.002794,0.070974,296.652130,15.112179,0.709736,-89.006386,0.070991,0.000000
55.810001,66.597328,-88.872940,0.008955,0.002794,0.070974,296.239716,15.091170,0.709736,-88.872940,0.070991,0.000000
56.010002,66.494179,-88.961899,0.008951,0.002794,0.070965,295.780884,15.067796,0.709649,-88.961899,0.070991,0.000000
56.210003,66.406670,-89.006386,0.008951,0.002794,0.070965,295.391632,15.047966,0.709649,-89.006386,0.070991,0.000000
56.410004,66.322517,-88.961899,0.008946,0.002794,0.070965,295.017303,15.028897,0.709649,-88.961899,0.070991,0.000000
56.610004,66.243568,-89.006386,0.008955,0.002794,0.070965,294.666107,15.011007,0.709649,-89.006386,0.070991,0.000000
56.810001,66.186974,-89.006386,0.008972,0.002794,0.070965,294.414368,14.998183,0.709649,-89.006386,0.070991,0.000000
57.010002,66.125160,-89.050865,0.008955,0.002794,0.070965,294.139404,14.984176,0.709649,-89.050865,0.070991,0.000000
57.210003,66.074516,-88.961899,0.008968,0.002794,0.070965,293.914124,14.972700,0.709649,-88.961899,0.070991,0.000000
57.410004,66.021629,-89.006386,0.008964,0.002794,0.070965,293.678864,14.960714,0.709649,-89.006386,0.070991,0.000000
57.610004,65.963539,-89.050865,0.008959,0.002794,0.070965,293.420471,14.947552,0.709649,-89.050865,0.070991,0.000000
57.810001,65.914024,-89.006386,0.008964,0.002794,0.070965,293.200226,14.936332,0.709649,-89.006386,0.070991,0.000000
58.010002,65.873802,-89.050865,0.008955,0.002794,0.070965,293.021301,14.927217,0.709649,-89.050865,0.070991,0.000000
58.210003,65.845879,-89.095345,0.008964,0.002794,0.070965,292.897095,14.920889,0.709649,-89.095345,0.070991,0.000000
58.410004,65.798210,-89.050865,0.008955,0.002794,0.070965,292.685059,14.910088,0.709649,-89.050865,0.070991,0.000000
58.610004,65.751289,-89.050865,0.008959,0.002794,0.070965,292.476349,14.899455,0.709649,-89.050865,0.070991,0.000000
58.810001,65.709953,-89.050865,0.008964,0.002794,0.070965,292.292480,14.890088,0.709649,-89.050865,0.070991,0.000000
59.010002,65.681664,-89.095345,0.008964,0.002794,0.070957,292.166626,14.883677,0.709566,-89.095345,0.070991,0.000000
59.210003,65.660805,-89.050865,0.008959,0.002794,0.070957,292.073853,14.878951,0.709566,-89.050865,0.070991,0.000000
59.410004,65.624687,-89.095345,0.008955,0.002794,0.070957,291.913177,14.870767,0.709566,-89.095345,0.070991,0.000000
59.610004,65.584846,-89.095345,0.008964,0.002794,0.070957,291.735962,14.861739,0.709566,-89.095345,0.070991,0.000000
59.810001,65.563988,-89.139824,0.008968,0.002794,0.070957,291.643188,14.857012,0.709566,-89.139824,0.070991,0.000000
60.010002,65.530846,-89.050865,0.008955,0.002794,0.070957,291.495758,14.849503,0.709566,-89.050865,0.070991,0.000000
60.210003,65.502541,-89.139824,0.008972,0.002794,0.070957,291.369843,14.843087,0.709566,-89.139824,0.070991,0.000000
60.410004,65.489891,-89.095345,0.008968,0.002794,0.070957,291.313599,14.840221,0.709566,-89.095345,0.070991,0.000000
60.610004,65.471642,-89.139824,0.008964,0.002794,0.070957,291.232422,14.836086,0.709566,-89.139824,0.070991,0.000000
60.810001,65.426964,-89.139824,0.008968,0.002794,0.070957,291.033661,14.825962,0.709566,-89.139824,0.070991,0.000000
61.010002,65.406471,-89.095345,0.008964,0.002794,0.070957,290.942505,14.821319,0.709566,-89.095345,0.070991,0.000000
61.210003,65.373329,-89.184303,0.008964,0.002794,0.070957,290.795105,14.813807,0.709566,-89.184303,0.070991,0.000000
61.410004,65.369606,-89.184303,0.008964,0.002794,0.070957,290.778534,14.812964,0.709566,-89.184303,0.070991,0.000000
61.610004,65.347649,-89.139824,0.008955,0.002794,0.070957,290.680847,14.807989,0.709566,-89.139824,0.070991,0.000000
61.810001,65.326042,-89.184303,0.008955,0.002794,0.070957,290.584747,14.803092,0.709566,-89.184303,0.070991,0.000000
62.010002,65.301460,-89.139824,0.008968,0.002794,0.070957,290.475403,14.797522,0.709566,-89.139824,0.070991,0.000000
62.210003,65.276146,-89.139824,0.008959,0.002794,0.070957,290.362793,14.791786,0.709566,-89.139824,0.070991,0.000000
62.410004,65.270561,-89.139824,0.008959,0.002794,0.070957,290.337952,14.790521,0.709566,-89.139824,0.070991,0.000000
62.610004,65.255287,-89.184303,0.008964,0.002794,0.070957,290.270020,14.787059,0.709566,-89.184303,0.070991,0.000000
62.810001,65.238533,-89.139824,0.008968,0.002794,0.070957,290.195496,14.783262,0.709566,-89.139824,0.070991,0.000000
63.010002,65.214333,-89.184303,0.008959,0.002794,0.070957,290.087830,14.777779,0.709566,-89.184303,0.070991,0.000000
63.210003,65.183418,-89.184303,0.008951,0.002794,0.070957,289.950317,14.770773,0.709566,-89.184303,0.070991,0.000000
63.410004,65.176720,-89.228790,0.008959,0.002794,0.070957,289.920532,14.769256,0.709566,-89.228790,0.070991,0.000000
63.610004,65.175240,-89.184303,0.008951,0.002794,0.070957,289.913940,14.768920,0.709566,-89.184303,0.070991,0.000000
63.810001,65.169273,-89.184303,0.008972,0.002794,0.070957,289.887421,14.767569,0.709566,-89.184303,0.070991,0.000000
64.010002,65.125328,-89.228790,0.008972,0.002794,0.070957,289.691925,14.757610,0.709566,-89.228790,0.070991,0.000000
64.210007,65.128319,-89.184303,0.008964,0.002794,0.070957,289.705231,14.758287,0.709566,-89.184303,0.070991,0.000000
64.410004,65.104485,-89.228790,0.008968,0.002794,0.070957,289.599213,14.752887,0.709566,-89.228790,0.070991,0.000000
64.610001,65.082512,-89.184303,0.008959,0.002794,0.070957,289.501465,14.747909,0.709566,-89.184303,0.070991,0.000000
64.810005,65.086601,-89.273270,0.008977,0.002794,0.070957,289.519653,14.748835,0.709566,-89.273270,0.070991,0.000000
65.010002,65.078423,-89.228790,0.008972,0.002794,0.070957,289.483276,14.746982,0.709566,-89.228790,0.070991,0.000000
65.210007,65.055336,-89.273270,0.008959,0.002794,0.070957,289.380585,14.741750,0.709566,-89.273270,0.070991,0.000000
65.410004,65.034111,-89.228790,0.008964,0.002794,0.070957,289.286163,14.736940,0.709566,-89.228790,0.070991,0.000000
65.610001,65.021065,-89.317749,0.008977,0.002794,0.070957,289.228149,14.733984,0.709566,-89.317749,0.070991,0.000000
65.810005,65.004692,-89.228790,0.008964,0.002794,0.070957,289.155304,14.730273,0.709566,-89.228790,0.070991,0.000000
66.010002,65.002449,-89.228790,0.008964,0.002794,0.070957,289.145325,14.729765,0.709566,-89.228790,0.070991,0.000000
66.210007,64.991280,-89.273270,0.008955,0.002794,0.070957,289.095642,14.727234,0.709566,-89.273270,0.070991,0.000000
66.410004,64.982719,-89.273270,0.008964,0.002794,0.070957,289.057587,14.725295,0.709566,-89.273270,0.070991,0.000000
66.610001,64.966698,-89.317749,0.008959,0.002794,0.070957,288.986298,14.721663,0.709566,-89.317749,0.070991,0.000000
66.810005,64.959999,-89.273270,0.008968,0.002794,0.070957,288.956512,14.720146,0.709566,-89.273270,0.070991,0.000000
67.010002,64.927971,-89.273270,0.008959,0.002794,0.070957,288.814026,14.712889,0.709566,-89.273270,0.070991,0.000000
67.210007,64.932823,-89.317749,0.008959,0.002794,0.070957,288.835632,14.713987,0.709566,-89.317749,0.070991,0.000000
67.410004,64.919044,-89.362228,0.008964,0.002794,0.070957,288.774323,14.710866,0.709566,-89.362228,0.070991,0.000000
67.610001,64.898933,-89.317749,0.008968,0.002794,0.070957,288.684875,14.706308,0.709566,-89.317749,0.070991,0.000000
67.810005,64.891853,-89.317749,0.008968,0.002794,0.070957,288.653381,14.704704,0.709566,-89.317749,0.070991,0.000000
68.010002,64.894829,-89.273270,0.008964,0.002794,0.070957,288.666626,14.705379,0.709566,-89.273270,0.070991,0.000000
68.210007,64.876213,-89.317749,0.008951,0.002794,0.070957,288.583801,14.701160,0.709566,-89.317749,0.070991,0.000000
68.410004,64.857979,-89.317749,0.008968,0.002794,0.070957,288.502686,14.697028,0.709566,-89.317749,0.070991,0.000000
68.610001,64.856850,-89.362228,0.008959,0.002794,0.070957,288.497681,14.696773,0.709566,-89.362228,0.070991,0.000000
68.810005,64.849037,-89.362228,0.008959,0.002794,0.070957,288.462921,14.695002,0.709566,-89.362228,0.070991,0.000000
69.010002,64.839348,-89.317749,0.008968,0.002794,0.070957,288.419830,14.692806,0.709566,-89.317749,0.070991,0.000000
69.210007,64.820732,-89.362228,0.008959,0.002794,0.070957,288.337006,14.688588,0.709566,-89.362228,0.070991,0.000000
69.410004,64.820366,-89.362228,0.008972,0.002794,0.070957,288.335388,14.688504,0.709566,-89.362228,0.070991,0.000000
69.610001,64.812920,-89.362228,0.008959,0.002794,0.070957,288.302277,14.686818,0.709566,-89.362228,0.070991,0.000000
69.810005,64.791313,-89.362228,0.008959,0.002794,0.070957,288.206146,14.681921,0.709566,-89.362228,0.070991,0.000000
70.010002,64.799141,-89.406715,0.008959,0.002794,0.070957,288.240967,14.683695,0.709566,-89.406715,0.070991,0.000000
70.210007,64.782387,-89.406715,0.008972,0.002794,0.070957,288.166443,14.679899,0.709566,-89.406715,0.070991,0.000000
70.410004,64.767479,-89.362228,0.008968,0.002794,0.070957,288.100128,14.676520,0.709566,-89.362228,0.070991,0.000000
70.610001,64.749611,-89.362228,0.008968,0.002794,0.070957,288.020660,14.672471,0.709566,-89.362228,0.070991,0.000000
70.810005,64.749977,-89.406715,0.008964,0.002794,0.070957,288.022278,14.672555,0.709566,-89.406715,0.070991,0.000000
71.010002,64.762276,-89.406715,0.008972,0.002794,0.070957,288.076996,14.675342,0.709566,-89.406715,0.070991,0.000000
71.210007,64.742165,-89.362228,0.008968,0.002794,0.070957,287.987518,14.670785,0.709566,-89.362228,0.070991,0.000000
71.410004,64.725029,-89.406715,0.008964,0.002794,0.070957,287.911316,14.666901,0.709566,-89.406715,0.070991,0.000000
71.610001,64.720192,-89.362228,0.008972,0.002794,0.070957,287.889801,14.665805,0.709566,-89.362228,0.070991,0.000000
71.810005,64.713112,-89.406715,0.008977,0.002794,0.070957,287.858307,14.664201,0.709566,-89.406715,0.070991,0.000000
72.010002,64.710884,-89.406715,0.008968,0.002794,0.070957,287.848389,14.663696,0.709566,-89.406715,0.070991,0.000000
72.210007,64.693016,-89.406715,0.008959,0.002794,0.070957,287.768921,14.659647,0.709566,-89.406715,0.070991,0.000000
72.410004,64.686684,-89.406715,0.008964,0.002794,0.070957,287.740753,14.658212,0.709566,-89.406715,0.070991,0.000000
72.610001,64.691154,-89.451195,0.008977,0.002794,0.070957,287.760620,14.659225,0.709566,-89.451195,0.070991,0.000000
72.810005,64.674385,-89.406715,0.008968,0.002794,0.070957,287.686035,14.655425,0.709566,-89.406715,0.070991,0.000000
73.010002,64.662849,-89.451195,0.008968,0.002794,0.070957,287.634705,14.652811,0.709566,-89.451195,0.070991,0.000000
73.210007,64.661736,-89.495674,0.008968,0.002794,0.070957,287.629761,14.652558,0.709566,-89.495674,0.070991,0.000000
73.410004,64.648323,-89.495674,0.008959,0.002794,0.070957,287.570099,14.649519,0.709566,-89.495674,0.070991,0.000000
73.610001,64.639381,-89.451195,0.008968,0.002794,0.070957,287.530334,14.647493,0.709566,-89.451195,0.070991,0.000000
73.810005,64.652794,-89.406715,0.008968,0.002794,0.070957,287.589996,14.650533,0.709566,-89.406715,0.070991,0.000000
74.010002,64.633064,-89.451195,0.008959,0.002794,0.070957,287.502228,14.646062,0.709566,-89.451195,0.070991,0.000000
74.210007,64.623009,-89.495674,0.008968,0.002794,0.070957,287.457489,14.643784,0.709566,-89.495674,0.070991,0.000000
74.410004,64.613319,-89.495674,0.008964,0.002794,0.070957,287.414398,14.641587,0.709566,-89.495674,0.070991,0.000000
74.610001,64.604012,-89.495674,0.008964,0.002794,0.070957,287.372986,14.639479,0.709566,-89.495674,0.070991,0.000000
74.810005,64.602898,-89.495674,0.008968,0.002794,0.070957,287.368042,14.639226,0.709566,-89.495674,0.070991,0.000000
75.010002,64.599174,-89.495674,0.008972,0.002794,0.070957,287.351471,14.638382,0.709566,-89.495674,0.070991,0.000000
75.210007,64.588753,-89.495674,0.008972,0.002794,0.070957,287.305115,14.636021,0.709566,-89.495674,0.070991,0.000000
75.410004,64.590614,-89.540154,0.008959,0.002794,0.070957,287.313416,14.636442,0.709566,-89.540154,0.070991,0.000000
75.610001,64.570503,-89.495674,0.008968,0.002794,0.070957,287.223938,14.631886,0.709566,-89.495674,0.070991,0.000000
75.810005,64.567146,-89.495674,0.008968,0.002794,0.070957,287.209015,14.631124,0.709566,-89.495674,0.070991,0.000000
76.010002,64.569756,-89.540154,0.008972,0.002794,0.070957,287.220612,14.631716,0.709566,-89.540154,0.070991,0.000000
76.210007,64.570869,-89.540154,0.008968,0.002794,0.070957,287.225586,14.631968,0.709566,-89.540154,0.070991,0.000000
76.410004,64.564537,-89.584633,0.008968,0.002794,0.070957,287.197418,14.630533,0.709566,-89.584633,0.070991,0.000000
76.610001,64.535866,-89.540154,0.008959,0.002794,0.070957,287.069855,14.624036,0.709566,-89.540154,0.070991,0.000000
76.810005,64.538475,-89.540154,0.008964,0.002794,0.070957,287.081482,14.624627,0.709566,-89.540154,0.070991,0.000000
77.010002,64.541832,-89.540154,0.008964,0.002794,0.070957,287.096405,14.625388,0.709566,-89.540154,0.070991,0.000000
77.210007,64.525444,-89.584633,0.008964,0.002794,0.070957,287.023499,14.621675,0.709566,-89.584633,0.070991,0.000000
77.410004,64.531395,-89.584633,0.008955,0.002794,0.070957,287.049988,14.623023,0.709566,-89.584633,0.070991,0.000000
77.610001,64.520973,-89.584633,0.008968,0.002794,0.070957,287.003632,14.620662,0.709566,-89.584633,0.070991,0.000000
77.810005,64.518745,-89.629120,0.008959,0.002794,0.070957,286.993713,14.620157,0.709566,-89.629120,0.070991,0.000000
78.010002,64.506447,-89.584633,0.008968,0.002794,0.070957,286.938995,14.617370,0.709566,-89.584633,0.070991,0.000000
78.210007,64.492668,-89.584633,0.008968,0.002794,0.070957,286.877716,14.614248,0.709566,-89.584633,0.070991,0.000000
78.410004,64.500496,-89.584633,0.008964,0.002794,0.070957,286.912537,14.616022,0.709566,-89.584633,0.070991,0.000000
78.610001,64.487083,-89.584633,0.008972,0.002794,0.070957,286.852875,14.612983,0.709566,-89.584633,0.070991,0.000000
78.810005,64.487465,-89.629120,0.008972,0.002794,0.070957,286.854584,14.613069,0.709566,-89.629120,0.070991,0.000000
79.010002,64.478523,-89.584633,0.008964,0.002794,0.070957,286.814789,14.611042,0.709566,-89.584633,0.070991,0.000000
79.210007,64.482613,-89.629120,0.008959,0.002794,0.070957,286.832977,14.611969,0.709566,-89.629120,0.070991,0.000000
79.410004,64.478157,-89.673599,0.008968,0.002794,0.070957,286.813171,14.610959,0.709566,-89.673599,0.070991,0.000000
79.610001,64.465126,-89.629120,0.008972,0.002794,0.070957,286.755188,14.608006,0.709566,-89.629120,0.070991,0.000000
79.810005,64.464378,-89.629120,0.008968,0.002794,0.070957,286.751862,14.607837,0.709566,-89.629120,0.070991,0.000000
80.010002,64.454689,-89.584633,0.008968,0.002794,0.070957,286.708771,14.605641,0.709566,-89.584633,0.070991,0.000000
80.210007,64.446129,-89.673599,0.008964,0.002794,0.070957,286.670685,14.603702,0.709566,-89.673599,0.070991,0.000000
80.410004,64.459160,-89.629120,0.008972,0.002794,0.070957,286.728668,14.606654,0.709566,-89.629120,0.070991,0.000000
80.610001,64.452461,-89.629120,0.008972,0.002794,0.070957,286.698853,14.605137,0.709566,-89.629120,0.070991,0.000000
80.810005,64.433098,-89.629120,0.008977,0.002794,0.070957,286.612732,14.600749,0.709566,-89.629120,0.070991,0.000000
81.010002,64.428627,-89.673599,0.008959,0.002794,0.070957,286.592834,14.599736,0.709566,-89.673599,0.070991,0.000000
81.210007,64.425270,-89.673599,0.008955,0.002794,0.070957,286.577911,14.598975,0.709566,-89.673599,0.070991,0.000000
81.410004,64.430855,-89.673599,0.008959,0.002794,0.070957,286.602753,14.600241,0.709566,-89.673599,0.070991,0.000000
81.610001,64.431984,-89.762558,0.008955,0.002794,0.070957,286.607788,14.600496,0.709566,-89.762558,0.070991,0.000000
81.810005,64.422661,-89.673599,0.008968,0.002794,0.070957,286.566315,14.598383,0.709566,-89.673599,0.070991,0.000000
82.010002,64.419685,-89.762558,0.008968,0.002794,0.070957,286.553070,14.597710,0.709566,-89.762558,0.070991,0.000000
82.210007,64.416344,-89.762558,0.008968,0.002794,0.070957,286.538208,14.596952,0.709566,-89.762558,0.070991,0.000000
82.410004,64.421547,-89.718079,0.008968,0.002794,0.070957,286.561340,14.598131,0.709566,-89.718079,0.070991,0.000000
82.610001,64.388786,-89.718079,0.008959,0.002794,0.070957,286.415619,14.590708,0.709566,-89.718079,0.070991,0.000000
82.810005,64.385429,-89.762558,0.008959,0.002794,0.070957,286.400696,14.589947,0.709566,-89.762558,0.070991,0.000000
83.010002,64.400703,-89.807037,0.008968,0.002794,0.070957,286.468628,14.593409,0.709566,-89.807037,0.070991,0.000000
83.210007,64.389153,-89.718079,0.008959,0.002794,0.070957,286.417267,14.590790,0.709566,-89.718079,0.070991,0.000000
83.410004,64.396233,-89.718079,0.008972,0.002794,0.070957,286.448761,14.592395,0.709566,-89.718079,0.070991,0.000000
83.610001,64.375374,-89.762558,0.008972,0.002794,0.070957,286.355957,14.587668,0.709566,-89.762558,0.070991,0.000000
83.810005,64.380959,-89.762558,0.008972,0.002794,0.070957,286.380798,14.588934,0.709566,-89.762558,0.070991,0.000000
84.010002,64.367561,-89.762558,0.008968,0.002794,0.070957,286.321198,14.585897,0.709566,-89.762558,0.070991,0.000000
84.210007,64.383934,-89.807037,0.008964,0.002794,0.070957,286.394043,14.589608,0.709566,-89.807037,0.070991,0.000000
84.410004,64.363838,-89.807037,0.008968,0.002794,0.070957,286.304657,14.585054,0.709566,-89.807037,0.070991,0.000000
84.610001,64.350060,-89.762558,0.008959,0.002794,0.070957,286.243347,14.581932,0.709566,-89.762558,0.070991,0.000000
84.810005,64.363091,-89.807037,0.008968,0.002794,0.070957,286.301331,14.584885,0.709566,-89.807037,0.070991,0.000000
85.000008,64.376869,-89.851524,0.008959,0.002794,0.070957,286.362610,14.588008,0.709566,-89.851524,0.070991,0.000000