File: Data/compression 4/AutoNoheating-12-4-5-240223_02232024_164618.csv
Time (sec),S:Load (lbs),S:HL1 (DIM),S:LVDT (in),S:Position (in),Ch:Position (mm),Ch:Load (N),Ch:Stress (MPa),Ch:Strain (mm/mm),Ch:HL1 (DIM),Set Point (),Cycles ()
0.010000,-0.013405,-137.890945,0.000022,-0.000000,-0.000000,-0.059628,-0.003038,-0.000000,-137.890945,0.000191,0.000000
0.230000,-0.008942,-137.846466,0.000013,-0.000000,-0.000000,-0.039774,-0.002026,-0.000000,-137.846466,0.000191,0.000000
0.450000,-0.007446,-137.846466,0.000009,0.000056,0.001422,-0.033123,-0.001687,0.014224,-137.846466,0.002029,0.000000
0.670000,0.007820,-137.890945,0.000043,0.000180,0.004570,0.034786,0.001772,0.045703,-137.890945,0.005706,0.000000
0.890000,0.131447,-137.890945,0.000194,0.000335,0.008499,0.584705,0.029786,0.084986,-137.890945,0.009366,0.000000
1.110000,0.435303,-137.890945,0.000315,0.000471,0.011959,1.936323,0.098641,0.119591,-137.890945,0.013026,0.000000
1.330000,0.615532,-137.890945,0.000375,-0.000005,-0.000130,2.738023,0.139482,-0.001302,-137.890945,0.000061,0.000000
1.550000,0.574570,-137.935425,0.000388,-0.000005,-0.000139,2.555814,0.130199,-0.001389,-137.935425,0.000061,0.000000
1.770000,0.516106,-137.935425,0.000375,-0.000005,-0.000139,2.295753,0.116951,-0.001389,-137.935425,0.000173,0.000000
1.990000,0.567497,-137.890945,0.000379,-0.000005,-0.000139,2.524354,0.128597,-0.001389,-137.890945,0.000546,0.000000
2.210000,0.571220,-137.935425,0.000379,0.000004,0.000113,2.540915,0.129440,0.001128,-137.935425,0.000911,0.000000
2.430000,0.655373,-137.890945,0.000371,0.000012,0.000312,2.915243,0.148510,0.003123,-137.890945,0.001275,0.000000
2.650000,0.767090,-137.890945,0.000401,0.000036,0.000911,3.412186,0.173825,0.009106,-137.890945,0.001648,0.000000
2.870000,0.846771,-137.935425,0.000405,0.000051,0.001283,3.766627,0.191881,0.012835,-137.935425,0.002012,0.000000
3.090000,0.885132,-137.935425,0.000427,0.000062,0.001570,3.937263,0.200574,0.015696,-137.935425,0.002376,0.000000
3.310000,0.924599,-138.024384,0.000440,0.000075,0.001917,4.112821,0.209517,0.019167,-138.024384,0.002740,0.000000
3.530000,0.989021,-137.979904,0.000453,0.000087,0.002212,4.399386,0.224115,0.022115,-137.979904,0.003113,0.000000
3.750000,1.071686,-137.979904,0.000453,0.000104,0.002645,4.767097,0.242847,0.026449,-137.979904,0.003478,0.000000
3.970000,1.158081,-138.024384,0.000466,0.000119,0.003018,5.151402,0.262425,0.030181,-138.024384,0.003842,0.000000
4.190000,1.209465,-137.979904,0.000470,0.000132,0.003347,5.379969,0.274069,0.033474,-137.979904,0.004215,0.000000
4.410000,1.264572,-137.979904,0.000487,0.000141,0.003573,5.625098,0.286556,0.035729,-137.979904,0.004579,0.000000
4.630000,1.386345,-137.935425,0.000509,0.000164,0.004163,6.166770,0.314150,0.041626,-137.935425,0.004943,0.000000
4.850000,1.453743,-137.979904,0.000517,0.000181,0.004588,6.466572,0.329423,0.045877,-137.979904,0.005308,0.000000
5.070000,1.487999,-138.113358,0.000530,0.000193,0.004900,6.618950,0.337185,0.048999,-138.113358,0.005680,0.000000
5.290000,1.492096,-137.979904,0.000548,0.000206,0.005238,6.637174,0.338114,0.052379,-137.979904,0.006044,0.000000
5.510000,1.555397,-138.024384,0.000569,0.000219,0.005559,6.918752,0.352458,0.055589,-138.024384,0.006409,0.000000
5.730000,1.676788,-137.935425,0.000548,0.000237,0.006027,7.458727,0.379966,0.060271,-137.935425,0.006782,0.000000
5.950000,1.705833,-138.024384,0.000578,0.000250,0.006348,7.587926,0.386547,0.063480,-138.024384,0.007146,0.000000
6.170000,1.771744,-137.979904,0.000586,0.000261,0.006634,7.881110,0.401483,0.066342,-137.979904,0.007510,0.000000
6.390000,1.810844,-138.113358,0.000599,0.000274,0.006955,8.055038,0.410343,0.069551,-138.113358,0.007874,0.000000
6.610000,1.887924,-138.068878,0.000621,0.000292,0.007415,8.397906,0.427810,0.074146,-138.068878,0.008247,0.000000
6.830000,1.938194,-138.068878,0.000625,0.000307,0.007805,8.621519,0.439201,0.078048,-138.068878,0.008611,0.000000
7.050000,1.930748,-138.068878,0.000638,0.000322,0.008187,8.588396,0.437514,0.081867,-138.068878,0.008976,0.000000
7.270000,1.981018,-138.157837,0.000642,0.000335,0.008507,8.812009,0.448905,0.085073,-138.157837,0.009349,0.000000
7.490000,2.032784,-138.113358,0.000651,0.000349,0.008863,9.042273,0.460635,0.088631,-138.113358,0.009713,0.000000
7.710001,2.109863,-138.068878,0.000677,0.000366,0.009296,9.385140,0.478102,0.092965,-138.068878,0.010077,0.000000
7.930000,2.134064,-138.113358,0.000698,0.000378,0.009592,9.492789,0.483586,0.095917,-138.113358,0.010441,0.000000
8.150001,2.159760,-138.113358,0.000690,0.000390,0.009895,9.607090,0.489408,0.098949,-138.113358,0.010814,0.000000
8.370001,2.189919,-138.113358,0.000703,0.000402,0.010216,9.741244,0.496243,0.102158,-138.113358,0.011179,0.000000
8.590000,2.310944,-138.157837,0.000716,0.000424,0.010780,10.279591,0.523667,0.107798,-138.157837,0.011543,0.000000
8.810000,2.305733,-138.157837,0.000720,0.000437,0.011100,10.256412,0.522487,0.111003,-138.157837,0.011916,0.000000
9.030001,2.294189,-138.113358,0.000742,0.000449,0.011404,10.205065,0.519871,0.114039,-138.113358,0.012280,0.000000
9.250000,2.339989,-138.202316,0.000733,0.000465,0.011803,10.408790,0.530249,0.118028,-138.202316,0.012644,0.000000
9.470000,2.372757,-138.113358,0.000755,0.000480,0.012184,10.554550,0.537674,0.121843,-138.113358,0.013008,0.000000
9.690001,2.435318,-138.157837,0.000763,0.000495,0.012583,10.832835,0.551851,0.125833,-138.157837,0.013381,0.000000
9.910001,2.446487,-138.246796,0.000772,0.000509,0.012930,10.882520,0.554382,0.129303,-138.246796,0.013746,0.000000
10.130000,2.437180,-138.113358,0.000793,0.000517,0.013130,10.841116,0.552273,0.131298,-138.113358,0.014110,0.000000
10.350000,2.447227,-138.202316,0.000793,0.000530,0.013459,10.885812,0.554550,0.134595,-138.202316,0.014483,0.000000
10.570001,2.577934,-138.202316,0.000819,0.000555,0.014092,11.467224,0.584168,0.140923,-138.202316,0.014847,0.000000
10.790001,2.541443,-138.246796,0.000806,0.000566,0.014387,11.304902,0.575899,0.143871,-138.246796,0.015211,0.000000
11.010000,2.561546,-138.246796,0.000832,0.000582,0.014786,11.394327,0.580455,0.147861,-138.246796,0.015575,0.000000
11.230000,2.569366,-138.246796,0.000845,0.000593,0.015064,11.429112,0.582227,0.150635,-138.246796,0.015948,0.000000
11.450001,2.611076,-138.202316,0.000836,0.000610,0.015497,11.614648,0.591678,0.154973,-138.202316,0.016313,0.000000
11.670001,2.626717,-138.246796,0.000862,0.000622,0.015801,11.684219,0.595223,0.158008,-138.246796,0.016677,0.000000
11.890000,2.642723,-138.291275,0.000871,0.000635,0.016130,11.755420,0.598850,0.161305,-138.291275,0.017041,0.000000
12.110001,2.696350,-138.291275,0.000875,0.000650,0.016512,11.993964,0.611002,0.165120,-138.291275,0.017414,0.000000
12.330001,2.673264,-138.246796,0.000888,0.000662,0.016807,11.891271,0.605770,0.168068,-138.246796,0.017778,0.000000
12.550000,2.781250,-138.246796,0.000901,0.000684,0.017379,12.371618,0.630240,0.173791,-138.246796,0.018143,0.000000
12.770000,2.760765,-138.246796,0.000905,0.000698,0.017735,12.280497,0.625598,0.177349,-138.246796,0.018515,0.000000
12.990001,2.734703,-138.291275,0.000918,0.000710,0.018030,12.164567,0.619693,0.180297,-138.291275,0.018879,0.000000
13.210001,2.756676,-138.291275,0.000927,0.000723,0.018359,12.262306,0.624672,0.183590,-138.291275,0.019244,0.000000
13.430000,2.764496,-138.291275,0.000927,0.000736,0.018697,12.297091,0.626444,0.186974,-138.291275,0.019608,0.000000
13.650001,2.834129,-138.291275,0.000949,0.000752,0.019096,12.606837,0.642223,0.190963,-138.291275,0.019981,0.000000
13.870001,2.846413,-138.246796,0.000940,0.000765,0.019443,12.661476,0.645006,0.194430,-138.246796,0.020345,0.000000
14.090001,2.804337,-138.291275,0.000953,0.000774,0.019651,12.474312,0.635472,0.196512,-138.291275,0.020709,0.000000
14.310000,2.798752,-138.335754,0.000966,0.000784,0.019920,12.449470,0.634206,0.199203,-138.335754,0.021082,0.000000
14.530001,2.981583,-138.335754,0.000979,0.000815,0.020701,13.262742,0.675636,0.207007,-138.335754,0.021446,0.000000
14.750001,2.929077,-138.335754,0.000987,0.000828,0.021030,13.029186,0.663738,0.210300,-138.335754,0.021811,0.000000
14.970000,2.859077,-138.335754,0.000992,0.000837,0.021264,12.717812,0.647876,0.212643,-138.335754,0.022175,0.000000
15.190001,2.878441,-138.380234,0.001005,0.000850,0.021603,12.803945,0.652264,0.216027,-138.380234,0.022548,0.000000
15.410001,2.914932,-138.380234,0.001009,0.000863,0.021932,12.966267,0.660533,0.219320,-138.380234,0.022912,0.000000
15.630001,3.015472,-138.424713,0.001018,0.000883,0.022435,13.413491,0.683316,0.224350,-138.424713,0.023276,0.000000
15.850000,2.956635,-138.335754,0.001035,0.000892,0.022669,13.151767,0.669983,0.226692,-138.335754,0.023649,0.000000
16.070002,2.973763,-138.335754,0.001035,0.000903,0.022947,13.227957,0.673864,0.229467,-138.335754,0.024014,0.000000
16.290001,3.107079,-138.424713,0.001035,0.000926,0.023528,13.820975,0.704074,0.235277,-138.424713,0.024378,0.000000
16.510000,3.132027,-138.424713,0.001069,0.000945,0.024005,13.931951,0.709727,0.240049,-138.424713,0.024742,0.000000
16.730001,3.069839,-138.424713,0.001074,0.000957,0.024308,13.655328,0.695636,0.243085,-138.424713,0.025115,0.000000
16.950001,3.025528,-138.380234,0.001087,0.000968,0.024595,13.458220,0.685594,0.245946,-138.380234,0.025479,0.000000
17.170000,2.997597,-138.335754,0.001078,0.000978,0.024829,13.333976,0.679265,0.248285,-138.335754,0.025843,0.000000
17.390001,3.136116,-138.380234,0.001087,0.000996,0.025306,13.950141,0.710654,0.253058,-138.380234,0.026216,0.000000
17.610001,3.196815,-138.424713,0.001091,0.001012,0.025696,14.220145,0.724409,0.256960,-138.424713,0.026581,0.000000
17.830000,3.161072,-138.469208,0.001099,0.001024,0.026000,14.061150,0.716309,0.259996,-138.469208,0.026945,0.000000
18.050001,3.199799,-138.424713,0.001125,0.001041,0.026442,14.233415,0.725085,0.264417,-138.424713,0.027309,0.000000
18.270000,3.266823,-138.424713,0.001130,0.001057,0.026849,14.531553,0.740273,0.268493,-138.424713,0.027682,0.000000
18.490002,3.291023,-138.469208,0.001155,0.001075,0.027317,14.639202,0.745757,0.273175,-138.469208,0.028046,0.000000
18.710001,3.206871,-138.469208,0.001160,0.001088,0.027630,14.264874,0.726687,0.276297,-138.469208,0.028410,0.000000
18.930000,3.180435,-138.424713,0.001155,0.001098,0.027881,14.147283,0.720697,0.278814,-138.424713,0.028783,0.000000
19.150002,3.237404,-138.469208,0.001173,0.001112,0.028254,14.400692,0.733606,0.282542,-138.469208,0.029147,0.000000
19.370001,3.344650,-138.424713,0.001181,0.001131,0.028731,14.877748,0.757909,0.287311,-138.424713,0.029512,0.000000
19.590000,3.289536,-138.469208,0.001199,0.001139,0.028939,14.632585,0.745419,0.289393,-138.469208,0.029876,0.000000
19.810001,3.358055,-138.558167,0.001186,0.001154,0.029312,14.937375,0.760946,0.293121,-138.558167,0.030249,0.000000
20.030001,3.464554,-138.513687,0.001207,0.001177,0.029884,15.411105,0.785079,0.298844,-138.513687,0.030613,0.000000
20.250002,3.490616,-138.469208,0.001233,0.001193,0.030301,15.527035,0.790985,0.303007,-138.469208,0.030977,0.000000
20.470001,3.457474,-138.469208,0.001246,0.001206,0.030639,15.379611,0.783475,0.306391,-138.469208,0.031350,0.000000
20.690001,3.438484,-138.469208,0.001259,0.001220,0.030977,15.295141,0.779172,0.309771,-138.469208,0.031714,0.000000
20.910002,3.382629,-138.513687,0.001255,0.001230,0.031237,15.046687,0.766515,0.312375,-138.513687,0.032078,0.000000
21.130001,3.458221,-138.602646,0.001268,0.001246,0.031636,15.382937,0.783644,0.316364,-138.602646,0.032443,0.000000
21.350000,3.528229,-138.513687,0.001281,0.001260,0.031992,15.694345,0.799508,0.319918,-138.513687,0.032816,0.000000
21.570002,3.571426,-138.469208,0.001289,0.001274,0.032356,15.886498,0.809297,0.323563,-138.469208,0.033180,0.000000
21.790001,3.578499,-138.602646,0.001289,0.001285,0.032642,15.917958,0.810899,0.326424,-138.602646,0.033544,0.000000
22.010000,3.727448,-138.558167,0.001302,0.001307,0.033206,16.580515,0.844652,0.332060,-138.558167,0.033917,0.000000
22.230001,3.710693,-138.513687,0.001332,0.001321,0.033562,16.505989,0.840855,0.335618,-138.513687,0.034281,0.000000
22.450001,3.668610,-138.558167,0.001341,0.001333,0.033848,16.318790,0.831319,0.338479,-138.558167,0.034646,0.000000
22.670002,3.655579,-138.513687,0.001341,0.001346,0.034186,16.260826,0.828366,0.341859,-138.513687,0.035010,0.000000
22.890001,3.701012,-138.558167,0.001354,0.001359,0.034516,16.462921,0.838661,0.345156,-138.558167,0.035383,0.000000
23.110001,3.796333,-138.558167,0.001350,0.001377,0.034975,16.886934,0.860261,0.349751,-138.558167,0.035747,0.000000
23.330002,3.835060,-138.558167,0.001384,0.001393,0.035383,17.059200,0.869037,0.353827,-138.558167,0.036111,0.000000
23.550001,3.771011,-138.513687,0.001384,0.001402,0.035617,16.774296,0.854523,0.356170,-138.513687,0.036475,0.000000
23.770000,3.750534,-138.513687,0.001388,0.001411,0.035834,16.683208,0.849883,0.358339,-138.513687,0.036848,0.000000
23.990002,3.939323,-138.558167,0.001406,0.001435,0.036441,17.522985,0.892663,0.364410,-138.558167,0.037213,0.000000
24.210001,3.946777,-138.602646,0.001427,0.001450,0.036822,17.556143,0.894352,0.368225,-138.602646,0.037577,0.000000
24.430000,3.899857,-138.602646,0.001431,0.001461,0.037117,17.347429,0.883720,0.371173,-138.602646,0.037950,0.000000
24.650002,3.913261,-138.602646,0.001444,0.001474,0.037438,17.407057,0.886758,0.374383,-138.602646,0.038314,0.000000
24.870001,3.942680,-138.602646,0.001436,0.001488,0.037794,17.537918,0.893424,0.377937,-138.602646,0.038678,0.000000
25.090002,3.968002,-138.647125,0.001440,0.001501,0.038123,17.650557,0.899162,0.381234,-138.647125,0.039042,0.000000
25.310001,4.082687,-138.647125,0.001470,0.001519,0.038592,18.160700,0.925150,0.385915,-138.647125,0.039416,0.000000
25.530001,4.049179,-138.647125,0.001483,0.001531,0.038895,18.011648,0.917557,0.388951,-138.647125,0.039780,0.000000
25.750002,4.035774,-138.647125,0.001496,0.001540,0.039112,17.952021,0.914520,0.391120,-138.647125,0.040144,0.000000
25.970001,4.247650,-138.647125,0.001492,0.001562,0.039684,18.894491,0.962531,0.396842,-138.647125,0.040517,0.000000
26.190001,4.281906,-138.691605,0.001518,0.001580,0.040135,19.046869,0.970294,0.401350,-138.691605,0.040881,0.000000
26.410002,4.191795,-138.736084,0.001526,0.001591,0.040422,18.646036,0.949874,0.404215,-138.736084,0.041245,0.000000
26.630001,4.202225,-138.691605,0.001544,0.001606,0.040794,18.692429,0.952238,0.407944,-138.691605,0.041610,0.000000
26.850000,4.206688,-138.691605,0.001552,0.001617,0.041072,18.712282,0.953249,0.410718,-138.691605,0.041982,0.000000
27.070002,4.350052,-138.647125,0.001561,0.001636,0.041557,19.349997,0.985736,0.415574,-138.647125,0.042347,0.000000
27.290001,4.343353,-138.691605,0.001569,0.001649,0.041887,19.320200,0.984218,0.418871,-138.691605,0.042711,0.000000
27.510002,4.367180,-138.691605,0.001574,0.001660,0.042164,19.426186,0.989617,0.421645,-138.691605,0.043084,0.000000
27.730001,4.405540,-138.736084,0.001595,0.001678,0.042615,19.596823,0.998310,0.426153,-138.736084,0.043448,0.000000
27.950001,4.549644,-138.691605,0.001608,0.001696,0.043066,20.237829,1.030964,0.430664,-138.691605,0.043812,0.000000
28.170002,4.511292,-138.647125,0.001625,0.001708,0.043379,20.067226,1.022273,0.433787,-138.647125,0.044177,0.000000
28.390001,4.528793,-138.780563,0.001613,0.001724,0.043786,20.145079,1.026239,0.437863,-138.780563,0.044549,0.000000
28.610001,4.518364,-138.825043,0.001643,0.001736,0.044107,20.098686,1.023876,0.441069,-138.825043,0.044913,0.000000
28.830002,4.553368,-138.780563,0.001660,0.001748,0.044393,20.254391,1.031808,0.443934,-138.780563,0.045278,0.000000
29.050001,4.695618,-138.825043,0.001664,0.001766,0.044853,20.887150,1.064042,0.448529,-138.825043,0.045651,0.000000
29.270000,4.676994,-138.736084,0.001677,0.001778,0.045156,20.804310,1.059822,0.451564,-138.736084,0.046015,0.000000
29.490002,4.703064,-138.780563,0.001681,0.001790,0.045477,20.920273,1.065729,0.454774,-138.780563,0.046379,0.000000
29.710001,4.674393,-138.825043,0.001690,0.001801,0.045737,20.792738,1.059232,0.457374,-138.825043,0.046743,0.000000
29.930002,4.921646,-138.780563,0.001703,0.001823,0.046310,21.892576,1.115261,0.463097,-138.780563,0.047116,0.000000
30.150002,4.903397,-138.825043,0.001716,0.001835,0.046613,21.811398,1.111126,0.466133,-138.825043,0.047481,0.000000
30.370001,4.898186,-138.825043,0.001742,0.001849,0.046969,21.788218,1.109945,0.469690,-138.825043,0.047845,0.000000
30.590002,4.970802,-138.825043,0.001742,0.001864,0.047351,22.111233,1.126400,0.473505,-138.825043,0.048218,0.000000
30.810001,5.021439,-138.780563,0.001755,0.001880,0.047749,22.336475,1.137874,0.477495,-138.780563,0.048582,0.000000
31.030001,5.083252,-138.869522,0.001776,0.001894,0.048105,22.611435,1.151881,0.481049,-138.869522,0.048946,0.000000
31.250002,5.081390,-138.825043,0.001776,0.001907,0.048443,22.603153,1.151459,0.484432,-138.825043,0.049310,0.000000
31.470001,5.013252,-138.825043,0.001798,0.001917,0.048695,22.300060,1.136019,0.486946,-138.825043,0.049683,0.000000
31.690002,5.061661,-138.825043,0.001794,0.001931,0.049050,22.515392,1.146989,0.490503,-138.825043,0.050048,0.000000
31.910002,5.340195,-138.869522,0.001811,0.001953,0.049605,23.754372,1.210105,0.496052,-138.869522,0.050412,0.000000
32.130001,5.318222,-138.869522,0.001837,0.001967,0.049961,23.656633,1.205126,0.499610,-138.869522,0.050785,0.000000
32.350002,5.367744,-138.825043,0.001841,0.001981,0.050325,23.876921,1.216348,0.503251,-138.825043,0.051149,0.000000
32.570000,5.339821,-138.869522,0.001854,0.001993,0.050611,23.752710,1.210021,0.506112,-138.869522,0.051513,0.000000
32.790001,5.464561,-138.869522,0.001867,0.002008,0.051010,24.307583,1.238287,0.510102,-138.869522,0.051877,0.000000
33.010002,5.504784,-138.869522,0.001871,0.002022,0.051349,24.486500,1.247402,0.513485,-138.869522,0.052250,0.000000
33.230003,5.540901,-138.869522,0.001880,0.002033,0.051643,24.647160,1.255586,0.516434,-138.869522,0.052615,0.000000
33.450001,5.599739,-138.869522,0.001893,0.002048,0.052025,24.908884,1.268919,0.520249,-138.869522,0.052979,0.000000
33.670002,5.712189,-138.825043,0.001919,0.002063,0.052398,25.409084,1.294400,0.523977,-138.825043,0.053352,0.000000
33.890003,5.953865,-138.914017,0.001923,0.002085,0.052970,26.484114,1.349165,0.529700,-138.914017,0.053716,0.000000
34.110001,5.879013,-138.914017,0.001940,0.002097,0.053274,26.151155,1.332203,0.532735,-138.914017,0.054080,0.000000
34.330002,5.850342,-138.914017,0.001949,0.002110,0.053586,26.023621,1.325706,0.535858,-138.914017,0.054445,0.000000
34.550003,5.895401,-138.958496,0.001970,0.002122,0.053907,26.224052,1.335917,0.539067,-138.958496,0.054817,0.000000
34.770000,5.959450,-138.914017,0.001988,0.002135,0.054236,26.508957,1.350431,0.542364,-138.914017,0.055181,0.000000
34.990002,6.105789,-138.869522,0.001992,0.002150,0.054618,27.159906,1.383592,0.546179,-138.869522,0.055546,0.000000
35.210003,6.193298,-138.914017,0.001992,0.002164,0.054973,27.549168,1.403422,0.549733,-138.914017,0.055919,0.000000
35.430000,6.119194,-138.958496,0.002009,0.002173,0.055190,27.219534,1.386629,0.551902,-138.958496,0.056283,0.000000
35.650002,6.108398,-139.002975,0.002022,0.002184,0.055476,27.171513,1.384183,0.554763,-139.002975,0.056647,0.000000
35.870003,6.701210,-138.914017,0.002039,0.002215,0.056265,29.808472,1.518516,0.562655,-138.914017,0.057011,0.000000
36.090000,6.593597,-138.958496,0.002065,0.002227,0.056578,29.329786,1.494130,0.565777,-138.958496,0.057384,0.000000
36.310001,6.471085,-138.958496,0.002057,0.002238,0.056846,28.784822,1.466369,0.568465,-138.958496,0.057748,0.000000
36.530003,6.520615,-138.958496,0.002061,0.002250,0.057141,29.005142,1.477592,0.571413,-138.958496,0.058113,0.000000
36.750000,6.615944,-139.002975,0.002082,0.002262,0.057454,29.429188,1.499194,0.574536,-139.002975,0.058477,0.000000
36.970001,6.996506,-139.002975,0.002104,0.002283,0.057983,31.122011,1.585431,0.579827,-139.002975,0.058850,0.000000
37.190002,6.915329,-139.002975,0.002113,0.002292,0.058226,30.760920,1.567036,0.582257,-139.002975,0.059214,0.000000
37.410004,6.929108,-139.002975,0.002121,0.002305,0.058538,30.822210,1.570158,0.585376,-139.002975,0.059578,0.000000
37.630001,7.438141,-139.002975,0.002121,0.002328,0.059127,33.086502,1.685507,0.591273,-139.002975,0.059951,0.000000
37.850002,7.500328,-139.047455,0.002143,0.002346,0.059578,33.363125,1.699599,0.595784,-139.047455,0.060316,0.000000
38.070004,7.358826,-139.002975,0.002173,0.002356,0.059838,32.733692,1.667534,0.598384,-139.002975,0.060680,0.000000
38.290001,7.353241,-139.002975,0.002169,0.002367,0.060133,32.708851,1.666268,0.601333,-139.002975,0.061044,0.000000
38.510002,7.362549,-139.002975,0.002190,0.002378,0.060411,32.750252,1.668377,0.604111,-139.002975,0.061417,0.000000
38.730003,7.699173,-139.047455,0.002182,0.002396,0.060853,34.247631,1.744658,0.608532,-139.047455,0.061781,0.000000
38.950001,7.870094,-139.136414,0.002199,0.002411,0.061235,35.007927,1.783389,0.612347,-139.136414,0.062145,0.000000
39.170002,7.812744,-139.002975,0.002216,0.002422,0.061512,34.752823,1.770393,0.615121,-139.002975,0.062518,0.000000
39.390003,8.088676,-139.047455,0.002233,0.002440,0.061981,35.980228,1.832920,0.619807,-139.047455,0.062883,0.000000
39.610001,8.385078,-139.002975,0.002246,0.002458,0.062431,37.298691,1.900086,0.624315,-139.002975,0.063247,0.000000
39.830002,8.529938,-139.091934,0.002268,0.002475,0.062865,37.943058,1.932912,0.628652,-139.091934,0.063611,0.000000
40.050003,8.436470,-139.047455,0.002276,0.002487,0.063169,37.527294,1.911731,0.631688,-139.047455,0.063984,0.000000
40.270000,8.434235,-139.047455,0.002294,0.002497,0.063411,37.517349,1.911225,0.634114,-139.047455,0.064348,0.000000
40.490002,8.627869,-139.091934,0.002298,0.002510,0.063758,38.378677,1.955103,0.637585,-139.091934,0.064712,0.000000
40.710003,9.092590,-139.136414,0.002302,0.002530,0.064270,40.445862,2.060410,0.642702,-139.136414,0.065085,0.000000
40.930000,8.921295,-139.180893,0.002328,0.002538,0.064461,39.683903,2.021595,0.644609,-139.180893,0.065450,0.000000
41.150002,9.136154,-139.136414,0.002328,0.002553,0.064842,40.639645,2.070282,0.648424,-139.136414,0.065814,0.000000
41.370003,9.760254,-139.091934,0.002354,0.002576,0.065441,43.415779,2.211705,0.654408,-139.091934,0.066178,0.000000
41.590000,9.918510,-139.091934,0.002358,0.002593,0.065866,44.119740,2.247567,0.658659,-139.091934,0.066551,0.000000
41.810001,9.861542,-139.091934,0.002371,0.002606,0.066195,43.866329,2.234657,0.661952,-139.091934,0.066915,0.000000
42.030003,9.884254,-139.180893,0.002376,0.002618,0.066507,43.967361,2.239804,0.665074,-139.180893,0.067279,0.000000
42.250004,9.881645,-139.225372,0.002393,0.002628,0.066759,43.955753,2.239213,0.667591,-139.225372,0.067652,0.000000
42.470001,10.219017,-139.180893,0.002419,0.002644,0.067158,45.456459,2.315662,0.671580,-139.180893,0.068016,0.000000
42.690002,10.464035,-139.136414,0.002423,0.002659,0.067531,46.546352,2.371184,0.675309,-139.136414,0.068381,0.000000
42.910004,10.664375,-139.180893,0.002436,0.002672,0.067869,47.437511,2.416582,0.678692,-139.180893,0.068745,0.000000
43.130001,10.813698,-139.225372,0.002445,0.002684,0.068173,48.101730,2.450419,0.681728,-139.225372,0.069118,0.000000
43.350002,11.450455,-139.225372,0.002449,0.002706,0.068745,50.934166,2.594710,0.687450,-139.225372,0.069482,0.000000
43.570004,11.547638,-139.136414,0.002470,0.002722,0.069127,51.366459,2.616732,0.691266,-139.136414,0.069846,0.000000
43.790001,11.467957,-139.180893,0.002492,0.002731,0.069378,51.012020,2.598676,0.693779,-139.180893,0.070219,0.000000
44.010002,11.628075,-139.180893,0.002492,0.002745,0.069716,51.724258,2.634959,0.697163,-139.180893,0.070583,0.000000
44.230003,11.855225,-139.225372,0.002501,0.002757,0.070037,52.734673,2.686432,0.700372,-139.225372,0.070948,0.000000
44.450001,12.390694,-139.269852,0.002522,0.002778,0.070558,55.116558,2.807771,0.705576,-139.269852,0.071312,0.000000
44.670002,12.585442,-139.225372,0.002535,0.002792,0.070913,55.982841,2.851902,0.709130,-139.225372,0.071685,0.000000
44.890003,12.484161,-139.180893,0.002552,0.002801,0.071139,55.532322,2.828951,0.711386,-139.180893,0.072049,0.000000
45.110001,12.503891,-139.225372,0.002548,0.002810,0.071364,55.620087,2.833422,0.713638,-139.225372,0.072413,0.000000
45.330002,13.353645,-139.269852,0.002570,0.002833,0.071962,59.399982,3.025979,0.719622,-139.269852,0.072786,0.000000
45.550003,13.624733,-139.358826,0.002591,0.002850,0.072379,60.605839,3.087409,0.723785,-139.358826,0.073150,0.000000
45.770000,13.670540,-139.225372,0.002600,0.002861,0.072665,60.809597,3.097789,0.726647,-139.225372,0.073515,0.000000
45.990002,13.857841,-139.225372,0.002608,0.002873,0.072986,61.642757,3.140232,0.729856,-139.225372,0.073879,0.000000
46.210003,14.198936,-139.269852,0.002626,0.002888,0.073358,63.160023,3.217525,0.733585,-139.269852,0.074252,0.000000
46.430000,14.469276,-139.314346,0.002626,0.002904,0.073766,64.362556,3.278785,0.737661,-139.314346,0.074616,0.000000
46.650002,14.915375,-139.358826,0.002643,0.002918,0.074122,66.346901,3.379872,0.741219,-139.358826,0.074980,0.000000
46.870003,15.047569,-139.358826,0.002656,0.002930,0.074425,66.934929,3.409828,0.744254,-139.358826,0.075353,0.000000
47.090004,15.122414,-139.314346,0.002673,0.002940,0.074677,67.267853,3.426788,0.746767,-139.314346,0.075718,0.000000
47.310001,15.580063,-139.269852,0.002686,0.002960,0.075180,69.303581,3.530493,0.751797,-139.269852,0.076082,0.000000
47.530003,16.617493,-139.403305,0.002686,0.002980,0.075700,73.918297,3.765578,0.757002,-139.403305,0.076446,0.000000
47.750004,16.562378,-139.358826,0.002712,0.002992,0.075995,73.673134,3.753088,0.759950,-139.358826,0.076819,0.000000
47.970001,16.802933,-139.358826,0.002729,0.003005,0.076333,74.743179,3.807599,0.763330,-139.358826,0.077183,0.000000
48.190002,16.966774,-139.358826,0.002738,0.003017,0.076620,75.471977,3.844726,0.766195,-139.358826,0.077547,0.000000
48.410004,17.660133,-139.314346,0.002734,0.003036,0.077123,78.556198,4.001843,0.771225,-139.314346,0.077920,0.000000
48.630001,17.886162,-139.403305,0.002759,0.003048,0.077426,79.561623,4.053062,0.774257,-139.403305,0.078284,0.000000
48.850002,18.149429,-139.403305,0.002768,0.003060,0.077721,80.732697,4.112719,0.777209,-139.403305,0.078649,0.000000
49.070004,18.565742,-139.447784,0.002785,0.003077,0.078146,82.584549,4.207057,0.781456,-139.447784,0.079013,0.000000
49.290001,19.150742,-139.358826,0.002798,0.003092,0.078527,85.186752,4.339620,0.785271,-139.358826,0.079386,0.000000
49.510002,19.688446,-139.314346,0.002807,0.003106,0.078900,87.578583,4.461465,0.789003,-139.314346,0.079750,0.000000
49.730003,20.147583,-139.403305,0.002794,0.003123,0.079325,89.620926,4.565508,0.793250,-139.403305,0.080114,0.000000
49.950001,20.456284,-139.403305,0.002828,0.003136,0.079663,90.994095,4.635460,0.796633,-139.403305,0.080479,0.000000
50.170002,20.671509,-139.358826,0.002841,0.003148,0.079949,91.951462,4.684231,0.799495,-139.358826,0.080851,0.000000
50.390003,21.339546,-139.403305,0.002850,0.003164,0.080357,94.923042,4.835610,0.803571,-139.403305,0.081216,0.000000
50.610001,21.720116,-139.358826,0.002850,0.003176,0.080678,96.615898,4.921849,0.806781,-139.358826,0.081580,0.000000
50.830002,22.060463,-139.447784,0.002863,0.003189,0.081007,98.129837,4.998972,0.810073,-139.447784,0.081953,0.000000
51.050003,22.222816,-139.358826,0.002880,0.003199,0.081259,98.852028,5.035762,0.812590,-139.358826,0.082317,0.000000
51.270004,23.371208,-139.492264,0.002893,0.003222,0.081831,103.960327,5.295991,0.818313,-139.492264,0.082681,0.000000
51.490002,23.767418,-139.403305,0.002897,0.003234,0.082144,105.722755,5.385774,0.821436,-139.403305,0.083046,0.000000
51.710003,24.227295,-139.447784,0.002915,0.003251,0.082569,107.768387,5.489984,0.825686,-139.447784,0.083418,0.000000
51.930004,24.753456,-139.447784,0.002919,0.003263,0.082881,110.108871,5.609213,0.828809,-139.447784,0.083783,0.000000
52.150002,25.402504,-139.536743,0.002936,0.003280,0.083323,112.995979,5.756289,0.833229,-139.536743,0.084147,0.000000
52.370003,25.939095,-139.447784,0.002949,0.003295,0.083704,115.382858,5.877883,0.837045,-139.447784,0.084520,0.000000
52.590004,26.335670,-139.403305,0.002936,0.003307,0.083999,117.146912,5.967749,0.839993,-139.403305,0.084884,0.000000
52.810001,26.479774,-139.492264,0.002962,0.003319,0.084303,117.787918,6.000402,0.843029,-139.492264,0.085248,0.000000
53.030003,26.909492,-139.536743,0.002962,0.003332,0.084624,119.699402,6.097778,0.846238,-139.536743,0.085612,0.000000
53.250004,28.278709,-139.536743,0.002988,0.003352,0.085136,125.789986,6.408047,0.851355,-139.536743,0.085985,0.000000
53.470001,28.719223,-139.492264,0.002997,0.003366,0.085500,127.749481,6.507869,0.854996,-139.492264,0.086350,0.000000
53.690002,29.418541,-139.536743,0.002997,0.003380,0.085847,130.860199,6.666337,0.858467,-139.536743,0.086714,0.000000
53.910004,29.683670,-139.536743,0.003005,0.003391,0.086133,132.039566,6.726416,0.861329,-139.536743,0.087087,0.000000
54.130001,30.159935,-139.625702,0.003014,0.003405,0.086497,134.158096,6.834339,0.864970,-139.625702,0.087451,0.000000
54.350002,31.128845,-139.536743,0.003031,0.003421,0.086887,138.468018,7.053897,0.868872,-139.536743,0.087815,0.000000
54.570004,31.599899,-139.492264,0.003048,0.003432,0.087173,140.563370,7.160640,0.871733,-139.492264,0.088179,0.000000
54.790001,32.228462,-139.447784,0.003061,0.003447,0.087564,143.359360,7.303074,0.875639,-139.447784,0.088553,0.000000
55.010002,32.880112,-139.536743,0.003053,0.003461,0.087911,146.258041,7.450740,0.879106,-139.536743,0.088917,0.000000
55.230003,34.469025,-139.581223,0.003057,0.003484,0.088500,153.325882,7.810792,0.885003,-139.581223,0.089281,0.000000
55.450001,34.979553,-139.581223,0.003083,0.003496,0.088804,155.596817,7.926480,0.888039,-139.581223,0.089654,0.000000
55.670002,35.396233,-139.536743,0.003083,0.003509,0.089116,157.450302,8.020901,0.891161,-139.536743,0.090018,0.000000
55.890003,35.903038,-139.536743,0.003091,0.003521,0.089428,159.704697,8.135745,0.894284,-139.536743,0.090382,0.000000
56.110004,36.540909,-139.581223,0.003104,0.003535,0.089784,162.542084,8.280289,0.897838,-139.581223,0.090747,0.000000
56.330002,37.361992,-139.581223,0.003109,0.003548,0.090131,166.194443,8.466349,0.901308,-139.581223,0.091119,0.000000
56.550003,38.026306,-139.625702,0.003113,0.003562,0.090478,169.149460,8.616884,0.904775,-139.625702,0.091484,0.000000
56.770004,38.374840,-139.625702,0.003130,0.003573,0.090755,170.699814,8.695863,0.907550,-139.625702,0.091848,0.000000
56.990002,38.826157,-139.625702,0.003130,0.003585,0.091059,172.707367,8.798133,0.910585,-139.625702,0.092221,0.000000
57.210003,41.345261,-139.625702,0.003134,0.003614,0.091787,183.912903,9.368970,0.917871,-139.625702,0.092585,0.000000
57.430004,41.916481,-139.670181,0.003152,0.003626,0.092099,186.453827,9.498410,0.920994,-139.670181,0.092949,0.000000
57.650002,42.214378,-139.625702,0.003165,0.003636,0.092342,187.778931,9.565915,0.923424,-139.625702,0.093314,0.000000
57.870003,42.819855,-139.670181,0.003182,0.003648,0.092654,190.472229,9.703118,0.926542,-139.670181,0.093686,0.000000
58.090004,43.692322,-139.625702,0.003173,0.003665,0.093079,194.353149,9.900822,0.930793,-139.625702,0.094050,0.000000
58.310001,44.849655,-139.625702,0.003186,0.003682,0.093513,199.501236,10.163076,0.935130,-139.625702,0.094415,0.000000
58.530003,45.433167,-139.670181,0.003186,0.003691,0.093747,202.096817,10.295302,0.937469,-139.670181,0.094788,0.000000
58.750004,45.918739,-139.670181,0.003203,0.003701,0.094016,204.256760,10.405335,0.940160,-139.670181,0.095152,0.000000
58.970001,47.373970,-139.714661,0.003203,0.003725,0.094606,210.729950,10.735095,0.946057,-139.714661,0.095516,0.000000
59.190002,49.051880,-139.670181,0.003203,0.003743,0.095083,218.193665,11.115315,0.950826,-139.670181,0.095880,0.000000
59.410004,49.630547,-139.670181,0.003221,0.003754,0.095351,220.767700,11.246443,0.953513,-139.670181,0.096253,0.000000
59.630001,50.188362,-139.714661,0.003229,0.003766,0.095655,223.248978,11.372845,0.956549,-139.714661,0.096618,0.000000
59.850002,50.732765,-139.759155,0.003225,0.003777,0.095924,225.670609,11.496209,0.959240,-139.759155,0.096982,0.000000
60.070004,51.696465,-139.670181,0.003247,0.003793,0.096340,229.957352,11.714586,0.963400,-139.670181,0.097355,0.000000
60.290005,53.100685,-139.714661,0.003260,0.003809,0.096748,236.203644,12.032787,0.967476,-139.714661,0.097719,0.000000
60.510002,53.464493,-139.670181,0.003247,0.003819,0.096991,237.821945,12.115227,0.969906,-139.670181,0.098083,0.000000
60.730003,54.844131,-139.759155,0.003264,0.003839,0.097502,243.958878,12.427857,0.975023,-139.759155,0.098447,0.000000
60.950005,56.552948,-139.759155,0.003268,0.003859,0.098031,251.560074,12.815081,0.980310,-139.759155,0.098820,0.000000
61.170002,57.737465,-139.714661,0.003285,0.003874,0.098396,256.829071,13.083497,0.983955,-139.714661,0.099185,0.000000
61.390003,58.347038,-139.714661,0.003277,0.003885,0.098673,259.540588,13.221627,0.986730,-139.714661,0.099549,0.000000
61.610004,58.822929,-139.759155,0.003281,0.003895,0.098924,261.657471,13.329466,0.989243,-139.759155,0.099922,0.000000
61.830002,59.969467,-139.759155,0.003285,0.003909,0.099280,266.757507,13.589276,0.992801,-139.759155,0.100286,0.000000
62.050003,61.286545,-139.759155,0.003298,0.003927,0.099757,272.616180,13.887730,0.997570,-139.759155,0.100650,0.000000
62.270004,62.046562,-139.759155,0.003316,0.003937,0.099991,275.996887,14.059952,0.999913,-139.759155,0.101014,0.000000
62.490002,62.834869,-139.759155,0.003316,0.003949,0.100312,279.503448,14.238585,1.003118,-139.759155,0.101387,0.000000
62.710003,64.067047,-139.759155,0.003311,0.003969,0.100815,284.984467,14.517800,1.008148,-139.759155,0.101752,0.000000
62.930004,66.315063,-139.848114,0.003333,0.003990,0.101344,294.984131,15.027208,1.013440,-139.848114,0.102116,0.000000
63.150002,67.399414,-139.759155,0.003341,0.004003,0.101674,299.807556,15.272925,1.016736,-139.759155,0.102480,0.000000
63.370003,67.049759,-139.759155,0.003350,0.003996,0.101500,298.252228,15.193693,1.014999,-139.759155,0.101708,0.000000
63.590004,66.583176,-139.803635,0.003346,0.003996,0.101492,296.176758,15.087963,1.014916,-139.803635,0.101500,0.000000
63.810001,66.153091,-139.803635,0.003346,0.003995,0.101483,294.263641,14.990505,1.014829,-139.803635,0.101500,0.000000
64.030006,65.776611,-139.803635,0.003354,0.003995,0.101483,292.588989,14.905192,1.014829,-139.803635,0.101500,0.000000
64.250000,65.453018,-139.848114,0.003359,0.003995,0.101483,291.149567,14.831865,1.014829,-139.848114,0.101500,0.000000
64.470001,65.163315,-139.803635,0.003359,0.003995,0.101474,289.860901,14.766218,1.014742,-139.803635,0.101500,0.000000
64.690002,64.897812,-139.892593,0.003363,0.003995,0.101474,288.679871,14.706054,1.014742,-139.892593,0.101500,0.000000
64.910004,64.641998,-139.892593,0.003359,0.003995,0.101474,287.541962,14.648087,1.014742,-139.892593,0.101500,0.000000
65.130005,64.435699,-139.892593,0.003359,0.003995,0.101474,286.624298,14.601338,1.014742,-139.892593,0.101500,0.000000
65.350006,64.214890,-139.892593,0.003363,0.003995,0.101474,285.642090,14.551302,1.014742,-139.892593,0.101500,0.000000
65.570000,64.039871,-139.892593,0.003380,0.003995,0.101474,284.863586,14.511642,1.014742,-139.892593,0.101500,0.000000
65.790001,63.869324,-139.892593,0.003363,0.003995,0.101474,284.104950,14.472996,1.014742,-139.892593,0.101500,0.000000
66.010002,63.691330,-139.981552,0.003363,0.003995,0.101474,283.313171,14.432661,1.014742,-139.981552,0.101500,0.000000
66.230003,63.545731,-139.937073,0.003359,0.003995,0.101474,282.665527,14.399669,1.014742,-139.937073,0.101500,0.000000
66.450005,63.408691,-139.892593,0.003363,0.003995,0.101474,282.055939,14.368615,1.014742,-139.892593,0.101500,0.000000
66.670006,63.273163,-139.892593,0.003380,0.003995,0.101474,281.453094,14.337903,1.014742,-139.892593,0.101500,0.000000
66.889999,63.165909,-139.937073,0.003376,0.003995,0.101474,280.975983,14.313600,1.014742,-139.937073,0.101500,0.000000
67.110001,63.025894,-139.981552,0.003359,0.003995,0.101474,280.353180,14.281872,1.014742,-139.981552,0.101500,0.000000
67.330002,62.901154,-139.981552,0.003372,0.003995,0.101474,279.798309,14.253605,1.014742,-139.981552,0.101500,0.000000
67.550003,62.820351,-139.937073,0.003367,0.003995,0.101474,279.438873,14.235295,1.014742,-139.937073,0.101500,0.000000
67.770004,62.720184,-139.937073,0.003367,0.003995,0.101474,278.993317,14.212597,1.014742,-139.937073,0.101500,0.000000
67.990005,62.617783,-139.892593,0.003376,0.003995,0.101474,278.537811,14.189392,1.014742,-139.892593,0.101500,0.000000
68.210007,62.516121,-140.026031,0.003367,0.003995,0.101474,278.085602,14.166355,1.014742,-140.026031,0.101500,0.000000
68.430000,62.433456,-139.981552,0.003372,0.003995,0.101474,277.717896,14.147624,1.014742,-139.981552,0.101500,0.000000
68.650002,62.345947,-139.981552,0.003372,0.003995,0.101474,277.328613,14.127793,1.014742,-139.981552,0.101500,0.000000
68.870003,62.269615,-139.981552,0.003363,0.003995,0.101474,276.989075,14.110497,1.014742,-139.981552,0.101500,0.000000
69.090004,62.185455,-140.026031,0.003367,0.003995,0.101474,276.614716,14.091426,1.014742,-140.026031,0.101500,0.000000
69.310005,62.112846,-139.937073,0.003359,0.003995,0.101474,276.291748,14.074972,1.014742,-139.937073,0.101500,0.000000
69.530006,62.047676,-140.026031,0.003367,0.003995,0.101474,276.001862,14.060205,1.014742,-140.026031,0.101500,0.000000
69.750000,61.978790,-140.026031,0.003393,0.003995,0.101474,275.695435,14.044595,1.014742,-140.026031,0.101500,0.000000
69.970001,61.907295,-140.026031,0.003376,0.003995,0.101474,275.377411,14.028393,1.014742,-140.026031,0.101500,0.000000
70.190002,61.845848,-140.070511,0.003376,0.003995,0.101474,275.104065,14.014470,1.014742,-140.070511,0.101500,0.000000
70.410004,61.778076,-140.026031,0.003376,0.003995,0.101474,274.802612,13.999112,1.014742,-140.026031,0.101500,0.000000
70.630005,61.723717,-140.070511,0.003376,0.003995,0.101474,274.560791,13.986794,1.014742,-140.070511,0.101500,0.000000
70.850006,61.652962,-140.026031,0.003376,0.003995,0.101474,274.246063,13.970761,1.014742,-140.026031,0.101500,0.000000
71.070000,61.601578,-140.070511,0.003376,0.003995,0.101474,274.017517,13.959117,1.014742,-140.070511,0.101500,0.000000
71.290001,61.550560,-140.070511,0.003376,0.003995,0.101474,273.790558,13.947556,1.014742,-140.070511,0.101500,0.000000
71.510002,61.497681,-140.026031,0.003380,0.003995,0.101474,273.555359,13.935574,1.014742,-140.026031,0.101500,0.000000
71.730003,61.426186,-140.070511,0.003389,0.003995,0.101474,273.237335,13.919373,1.014742,-140.070511,0.101500,0.000000
71.950005,61.401611,-140.070511,0.003380,0.003995,0.101474,273.128021,13.913804,1.014742,-140.070511,0.101500,0.000000
72.170006,61.345009,-140.070511,0.003380,0.003995,0.101474,272.876221,13.900978,1.014742,-140.070511,0.101500,0.000000
72.390007,61.302559,-140.114990,0.003393,0.003995,0.101474,272.687408,13.891358,1.014742,-140.114990,0.101500,0.000000
72.610001,61.250427,-140.114990,0.003372,0.003995,0.101474,272.455505,13.879545,1.014742,-140.114990,0.101500,0.000000
72.830002,61.216171,-140.070511,0.003385,0.003995,0.101474,272.303131,13.871782,1.014742,-140.070511,0.101500,0.000000
73.050003,61.159943,-140.114990,0.003385,0.003995,0.101474,272.053009,13.859041,1.014742,-140.114990,0.101500,0.000000
73.270004,61.121216,-140.114990,0.003393,0.003995,0.101474,271.880737,13.850266,1.014742,-140.114990,0.101500,0.000000
73.490005,61.073555,-140.159470,0.003376,0.003995,0.101474,271.668732,13.839465,1.014742,-140.159470,0.101500,0.000000
73.710007,61.039291,-140.159470,0.003385,0.003995,0.101474,271.516327,13.831701,1.014742,-140.159470,0.101500,0.000000
73.930000,61.002426,-140.159470,0.003385,0.003995,0.101474,271.352356,13.823347,1.014742,-140.159470,0.101500,0.000000
74.150002,60.956253,-140.070511,0.003385,0.003995,0.101474,271.146942,13.812884,1.014742,-140.070511,0.101500,0.000000
74.370003,60.915291,-140.114990,0.003376,0.003995,0.101474,270.964752,13.803602,1.014742,-140.114990,0.101500,0.000000
74.590004,60.882523,-140.203964,0.003380,0.003995,0.101474,270.819000,13.796177,1.014742,-140.203964,0.101500,0.000000
74.810005,60.850128,-140.114990,0.003389,0.003995,0.101474,270.674896,13.788836,1.014742,-140.114990,0.101500,0.000000
75.030006,60.818100,-140.114990,0.003385,0.003995,0.101474,270.532410,13.781579,1.014742,-140.114990,0.101500,0.000000
75.250000,60.786827,-140.203964,0.003376,0.003995,0.101474,270.393311,13.774492,1.014742,-140.203964,0.101500,0.000000
75.470001,60.750336,-140.159470,0.003389,0.003995,0.101474,270.230988,13.766223,1.014742,-140.159470,0.101500,0.000000
75.690002,60.726128,-140.203964,0.003393,0.003995,0.101474,270.123322,13.760737,1.014742,-140.203964,0.101500,0.000000
75.910004,60.680695,-140.203964,0.003389,0.003995,0.101474,269.921204,13.750443,1.014742,-140.203964,0.101500,0.000000
76.130005,60.640854,-140.203964,0.003380,0.003995,0.101474,269.743988,13.741414,1.014742,-140.203964,0.101500,0.000000
76.350006,60.625961,-140.159470,0.003397,0.003995,0.101474,269.677734,13.738039,1.014742,-140.159470,0.101500,0.000000
76.570007,60.575317,-140.248444,0.003380,0.003995,0.101474,269.452484,13.726563,1.014742,-140.248444,0.101500,0.000000
76.790001,60.549622,-140.248444,0.003389,0.003995,0.101474,269.338165,13.720740,1.014742,-140.248444,0.101500,0.000000
77.010002,60.532867,-140.292923,0.003389,0.003995,0.101474,269.263641,13.716944,1.014742,-140.292923,0.101500,0.000000
77.230003,60.482971,-140.248444,0.003389,0.003995,0.101474,269.041687,13.705638,1.014742,-140.248444,0.101500,0.000000
77.450005,60.457275,-140.203964,0.003385,0.003995,0.101474,268.927399,13.699815,1.014742,-140.203964,0.101500,0.000000
77.670006,60.434929,-140.203964,0.003385,0.003995,0.101474,268.828003,13.694751,1.014742,-140.203964,0.101500,0.000000
77.890007,60.397324,-140.292923,0.003393,0.003995,0.101474,268.660706,13.686229,1.014742,-140.292923,0.101500,0.000000
78.110001,60.379448,-140.292923,0.003393,0.003995,0.101474,268.581207,13.682178,1.014742,-140.292923,0.101500,0.000000
78.330002,60.344444,-140.292923,0.003393,0.003995,0.101474,268.425507,13.674246,1.014742,-140.292923,0.101500,0.000000
78.550003,60.308701,-140.292923,0.003385,0.003995,0.101474,268.266510,13.666146,1.014742,-140.292923,0.101500,0.000000
78.770004,60.289703,-140.292923,0.003385,0.003995,0.101474,268.182007,13.661842,1.014742,-140.292923,0.101500,0.000000
78.990005,60.263641,-140.292923,0.003393,0.003995,0.101474,268.066071,13.655936,1.014742,-140.292923,0.101500,0.000000
79.210007,60.231247,-140.337402,0.003397,0.003995,0.101474,267.921967,13.648596,1.014742,-140.337402,0.101500,0.000000
79.430000,60.212257,-140.337402,0.003385,0.003995,0.101474,267.837494,13.644293,1.014742,-140.337402,0.101500,0.000000
79.650002,60.188797,-140.292923,0.003393,0.003995,0.101474,267.733154,13.638976,1.014742,-140.292923,0.101500,0.000000
79.870003,60.161980,-140.337402,0.003389,0.003995,0.101474,267.613861,13.632899,1.014742,-140.337402,0.101500,0.000000
80.090004,60.132935,-140.381882,0.003393,0.003995,0.101474,267.484650,13.626318,1.014742,-140.381882,0.101500,0.000000
80.310005,60.098679,-140.381882,0.003385,0.003995,0.101474,267.332275,13.618556,1.014742,-140.381882,0.101500,0.000000
80.530006,60.083038,-140.337402,0.003389,0.003995,0.101474,267.262695,13.615011,1.014742,-140.337402,0.101500,0.000000
80.750008,60.076340,-140.337402,0.003406,0.003995,0.101474,267.232910,13.613494,1.014742,-140.337402,0.101500,0.000000
80.970001,60.046173,-140.292923,0.003389,0.003995,0.101474,267.098724,13.606658,1.014742,-140.292923,0.101500,0.000000
81.190002,60.017502,-140.426361,0.003389,0.003995,0.101474,266.971191,13.600160,1.014742,-140.426361,0.101500,0.000000
81.410004,59.989578,-140.426361,0.003385,0.003995,0.101474,266.846985,13.593832,1.014742,-140.426361,0.101500,0.000000
81.630005,59.966484,-140.337402,0.003389,0.003995,0.101474,266.744232,13.588599,1.014742,-140.337402,0.101500,0.000000
81.850006,59.943031,-140.381882,0.003389,0.003995,0.101474,266.639923,13.583285,1.014742,-140.381882,0.101500,0.000000
82.070007,59.924782,-140.381882,0.003389,0.003995,0.101474,266.558746,13.579150,1.014742,-140.381882,0.101500,0.000000
82.290001,59.899086,-140.426361,0.003397,0.003995,0.101474,266.444427,13.573327,1.014742,-140.426361,0.101500,0.000000
82.510002,59.882706,-140.426361,0.003393,0.003995,0.101474,266.371582,13.569614,1.014742,-140.426361,0.101500,0.000000
82.730003,59.861481,-140.381882,0.003389,0.003995,0.101474,266.277161,13.564805,1.014742,-140.381882,0.101500,0.000000
82.950005,59.839134,-140.381882,0.003393,0.003995,0.101474,266.177765,13.559742,1.014742,-140.381882,0.101500,0.000000
83.170006,59.831314,-140.381882,0.003397,0.003995,0.101474,266.142975,13.557970,1.014742,-140.381882,0.101500,0.000000
83.390007,59.798920,-140.515320,0.003389,0.003995,0.101474,265.998871,13.550630,1.014742,-140.515320,0.101500,0.000000
83.610001,59.784767,-140.426361,0.003406,0.003995,0.101474,265.935913,13.547421,1.014742,-140.426361,0.101500,0.000000
83.830002,59.781418,-140.426361,0.003393,0.003995,0.101474,265.921021,13.546662,1.014742,-140.426361,0.101500,0.000000
84.050003,59.748276,-140.381882,0.003389,0.003995,0.101474,265.773590,13.539153,1.014742,-140.381882,0.101500,0.000000
84.270004,59.726677,-140.470840,0.003397,0.003995,0.101474,265.677521,13.534258,1.014742,-140.470840,0.101500,0.000000
84.490005,59.695770,-140.559799,0.003393,0.003995,0.101474,265.540039,13.527255,1.014742,-140.559799,0.101500,0.000000
84.710007,59.681992,-140.470840,0.003406,0.003995,0.101474,265.478760,13.524133,1.014742,-140.470840,0.101500,0.000000
84.930000,59.667473,-140.515320,0.003389,0.003995,0.101474,265.414185,13.520843,1.014742,-140.515320,0.101500,0.000000
85.150002,59.654816,-140.426361,0.003406,0.003995,0.101474,265.357880,13.517974,1.014742,-140.426361,0.101500,0.000000
85.370003,59.636192,-140.515320,0.003393,0.003995,0.101474,265.275024,13.513755,1.014742,-140.515320,0.101500,0.000000
85.590004,59.619438,-140.515320,0.003406,0.003995,0.101474,265.200500,13.509958,1.014742,-140.515320,0.101500,0.000000
85.810005,59.603424,-140.559799,0.003397,0.003995,0.101474,265.129272,13.506330,1.014742,-140.559799,0.101500,0.000000
86.030006,59.580338,-140.470840,0.003402,0.003995,0.101474,265.026581,13.501098,1.014742,-140.470840,0.101500,0.000000
86.250008,59.565819,-140.515320,0.003389,0.003995,0.101474,264.962006,13.497808,1.014742,-140.515320,0.101500,0.000000
86.470001,59.552406,-140.604294,0.003389,0.003995,0.101474,264.902344,13.494768,1.014742,-140.604294,0.101500,0.000000
86.690002,59.524857,-140.559799,0.003397,0.003995,0.101474,264.779785,13.488525,1.014742,-140.559799,0.101500,0.000000
86.910004,59.521133,-140.559799,0.003397,0.003995,0.101474,264.763214,13.487681,1.014742,-140.559799,0.101500,0.000000
87.130005,59.501396,-140.559799,0.003397,0.003995,0.101474,264.675415,13.483210,1.014742,-140.559799,0.101500,0.000000
87.350006,59.482407,-140.515320,0.003389,0.003995,0.101474,264.590973,13.478906,1.014742,-140.515320,0.101500,0.000000
87.570007,59.462296,-140.604294,0.003393,0.003995,0.101474,264.501495,13.474349,1.014742,-140.604294,0.101500,0.000000
87.790001,59.445541,-140.604294,0.003406,0.003995,0.101474,264.426971,13.470552,1.014742,-140.604294,0.101500,0.000000
88.010002,59.423569,-140.604294,0.003397,0.003995,0.101474,264.329224,13.465573,1.014742,-140.604294,0.101500,0.000000
88.230003,59.433250,-140.604294,0.003397,0.003995,0.101474,264.372314,13.467767,1.014742,-140.604294,0.101500,0.000000
88.450005,59.398994,-140.604294,0.003402,0.003995,0.101474,264.219910,13.460005,1.014742,-140.604294,0.101500,0.000000
88.670006,59.384842,-140.693253,0.003393,0.003995,0.101474,264.156982,13.456798,1.014742,-140.693253,0.101500,0.000000
88.890007,59.370323,-140.604294,0.003389,0.003995,0.101474,264.092377,13.453507,1.014742,-140.604294,0.101500,0.000000
89.110001,59.347229,-140.604294,0.003397,0.003995,0.101474,263.989655,13.448275,1.014742,-140.604294,0.101500,0.000000
89.330002,59.345741,-140.648773,0.003389,0.003995,0.101474,263.983032,13.447937,1.014742,-140.648773,0.101500,0.000000
89.550003,59.323402,-140.604294,0.003402,0.003995,0.101474,263.883667,13.442875,1.014742,-140.604294,0.101500,0.000000
89.770004,59.314461,-140.693253,0.003402,0.003995,0.101474,263.843903,13.440848,1.014742,-140.693253,0.101500,0.000000
89.990005,59.307762,-140.693253,0.003406,0.003995,0.101474,263.814087,13.439331,1.014742,-140.693253,0.101500,0.000000
90.210007,59.281693,-140.604294,0.003406,0.003995,0.101474,263.698151,13.433423,1.014742,-140.604294,0.101500,0.000000
90.430008,59.266426,-140.604294,0.003402,0.003995,0.101474,263.630219,13.429964,1.014742,-140.604294,0.101500,0.000000
90.650002,59.266426,-140.737732,0.003402,0.003995,0.101474,263.630219,13.429964,1.014742,-140.737732,0.101500,0.000000
90.870003,59.238503,-140.693253,0.003397,0.003995,0.101474,263.506012,13.423636,1.014742,-140.693253,0.101500,0.000000
91.090004,59.238503,-140.693253,0.003406,0.003995,0.101474,263.506012,13.423636,1.014742,-140.693253,0.101500,0.000000
91.310005,59.229187,-140.648773,0.003402,0.003995,0.101474,263.464569,13.421526,1.014742,-140.648773,0.101500,0.000000
91.530006,59.206100,-140.648773,0.003389,0.003995,0.101474,263.361877,13.416294,1.014742,-140.648773,0.101500,0.000000
91.750008,59.206474,-140.604294,0.003393,0.003995,0.101474,263.363556,13.416378,1.014742,-140.604294,0.101500,0.000000
91.970001,59.181900,-140.737732,0.003393,0.003995,0.101474,263.254242,13.410810,1.014742,-140.737732,0.101500,0.000000
92.190002,59.170357,-140.737732,0.003410,0.003995,0.101474,263.202881,13.408195,1.014742,-140.737732,0.101500,0.000000
92.410004,59.158066,-140.693253,0.003402,0.003995,0.101474,263.148224,13.405409,1.014742,-140.693253,0.101500,0.000000
92.630005,59.144661,-140.693253,0.003402,0.003995,0.101474,263.088593,13.402371,1.014742,-140.693253,0.101500,0.000000
92.850006,59.136841,-140.737732,0.003402,0.003995,0.101474,263.053802,13.400599,1.014742,-140.737732,0.101500,0.000000
93.070007,59.123810,-140.782211,0.003397,0.003995,0.101474,262.995850,13.397647,1.014742,-140.782211,0.101500,0.000000
93.290001,59.096252,-140.826691,0.003397,0.003995,0.101474,262.873260,13.391402,1.014742,-140.826691,0.101500,0.000000
93.510002,59.093643,-140.693253,0.003397,0.003995,0.101474,262.861664,13.390811,1.014742,-140.693253,0.101500,0.000000
93.600006,59.108917,-140.737732,0.003397,0.003995,0.101474,262.929596,13.394273,1.014742,-140.737732,0.101500,0.000000