File: Data/compression 4/AutoNoheating-12-4-1-240223_02232024_163339.csv
Time (sec),S:Load (lbs),S:HL1 (DIM),S:LVDT (in),S:Position (in),Ch:Position (mm),Ch:Load (N),Ch:Stress (MPa),Ch:Strain (mm/mm),Ch:HL1 (DIM),Set Point (),Cycles ()
0.010000,-0.013031,-114.849815,0.000000,-0.000000,-0.000000,-0.057965,-0.002953,-0.000000,-114.849815,0.000165,0.000000
0.280000,-0.007080,-114.760857,0.000000,-0.000000,-0.000000,-0.031494,-0.001604,-0.000000,-114.760857,0.000165,0.000000
0.550000,-0.009308,-114.760857,0.000004,0.000104,0.002654,-0.041403,-0.002109,0.026538,-114.760857,0.003634,0.000000
0.820000,-0.045807,-114.805336,0.000142,0.000283,0.007181,-0.203759,-0.010380,0.071807,-114.805336,0.008126,0.000000
1.090000,-0.015266,-114.805336,0.000336,0.000456,0.011586,-0.067908,-0.003459,0.115861,-114.805336,0.012618,0.000000
1.360000,-0.000000,-114.849815,0.000513,0.000628,0.015940,-0.000000,-0.000000,0.159397,-114.849815,0.017128,0.000000
1.630000,-0.036125,-114.805336,0.000694,0.000811,0.020588,-0.160693,-0.008186,0.205879,-114.805336,0.021620,0.000000
1.900000,-0.001862,-114.805336,0.000871,0.000986,0.025037,-0.008281,-0.000422,0.250369,-114.805336,0.026112,0.000000
2.170000,-0.020111,-114.849815,0.001056,0.001168,0.029659,-0.089459,-0.004557,0.296592,-114.849815,0.030622,0.000000
2.440000,-0.017502,-114.849815,0.001212,0.001336,0.033926,-0.077852,-0.003966,0.339259,-114.849815,0.035114,0.000000
2.710000,-0.024574,-114.849815,0.001418,0.001515,0.038470,-0.109312,-0.005569,0.384702,-114.849815,0.039606,0.000000
2.980000,-0.072243,-114.849815,0.001595,0.001695,0.043058,-0.321352,-0.016370,0.430579,-114.849815,0.044116,0.000000
3.250000,-0.004471,-114.894295,0.001763,0.001868,0.047446,-0.019887,-0.001013,0.474461,-114.894295,0.048608,0.000000
3.520000,0.000374,-114.894295,0.001944,0.002053,0.052137,0.001663,0.000085,0.521375,-114.894295,0.053100,0.000000
3.790000,-0.008568,-114.894295,0.002121,0.002224,0.056491,-0.038112,-0.001941,0.564913,-114.894295,0.057610,0.000000
4.060000,0.002602,-114.894295,0.002311,0.002400,0.060957,0.011573,0.000590,0.609574,-114.894295,0.062102,0.000000
4.330000,-0.021973,-114.894295,0.002496,0.002582,0.065588,-0.097739,-0.004979,0.655883,-114.894295,0.066594,0.000000
4.600000,-0.011543,-114.894295,0.002673,0.002757,0.070020,-0.051347,-0.002616,0.700200,-114.894295,0.071104,0.000000
4.870000,-0.029045,-114.983261,0.002833,0.002933,0.074486,-0.129199,-0.006582,0.744862,-114.983261,0.075596,0.000000
5.140000,-0.045807,-114.938774,0.003022,0.003108,0.078952,-0.203759,-0.010380,0.789523,-114.938774,0.080088,0.000000
5.410000,0.026062,-114.938774,0.003203,0.003283,0.083384,0.115930,0.005906,0.833837,-114.938774,0.084598,0.000000
5.680000,-0.023834,-114.849815,0.003397,0.003468,0.088084,-0.106020,-0.005401,0.880842,-114.849815,0.089090,0.000000
5.950000,0.000740,-114.983261,0.003553,0.003642,0.092507,0.003292,0.000168,0.925068,-114.983261,0.093600,0.000000
6.220000,0.006332,-114.983261,0.003738,0.003821,0.097043,0.028168,0.001435,0.970426,-114.983261,0.098092,0.000000
6.490000,-0.024574,-114.983261,0.003919,0.003995,0.101474,-0.109312,-0.005569,1.014740,-114.983261,0.102584,0.000000
6.760000,-0.003723,-114.983261,0.004092,0.004164,0.105776,-0.016561,-0.000844,1.057755,-114.983261,0.107094,0.000000
7.030000,-0.051758,-114.938774,0.004273,0.004351,0.110510,-0.230230,-0.011728,1.105104,-114.938774,0.111586,0.000000
7.300000,0.007072,-114.983261,0.004454,0.004526,0.114951,0.031460,0.001603,1.149509,-114.983261,0.116078,0.000000
7.570000,0.015266,-114.983261,0.004648,0.004708,0.119573,0.067908,0.003459,1.195730,-114.983261,0.120588,0.000000
7.840000,-0.022346,-115.027740,0.004820,0.004881,0.123979,-0.099402,-0.005064,1.239786,-115.027740,0.125080,0.000000
8.110001,0.000740,-115.027740,0.005006,0.005058,0.128462,0.003292,0.000168,1.284622,-115.027740,0.129572,0.000000
8.380000,-0.015266,-114.983261,0.005191,0.005240,0.133085,-0.067908,-0.003459,1.330847,-114.983261,0.134082,0.000000
8.650001,-0.005585,-114.983261,0.005355,0.005411,0.137429,-0.024842,-0.001266,1.374293,-114.983261,0.138574,0.000000
8.920000,-0.023460,-115.072220,0.005527,0.005584,0.141843,-0.104357,-0.005316,1.418433,-115.072220,0.143066,0.000000
9.190001,-0.067032,-114.983261,0.005721,0.005764,0.146405,-0.298173,-0.015190,1.464052,-114.983261,0.147576,0.000000
9.460000,0.020103,-115.027740,0.005894,0.005940,0.150871,0.089425,0.004556,1.508714,-115.027740,0.152068,0.000000
9.730000,0.002602,-115.072220,0.006096,0.006124,0.155537,0.011573,0.000590,1.555370,-115.072220,0.156560,0.000000
10.000000,-0.009308,-115.116699,0.006243,0.006300,0.160021,-0.041403,-0.002109,1.600206,-115.116699,0.161070,0.000000
10.270000,0.016380,-115.072220,0.006437,0.006475,0.164461,0.072863,0.003712,1.644607,-115.072220,0.165562,0.000000
10.540001,-0.026810,-115.116699,0.006622,0.006654,0.169014,-0.119255,-0.006075,1.690135,-115.116699,0.170054,0.000000
10.810000,0.012657,-115.072220,0.006791,0.006827,0.173402,0.056302,0.002868,1.734017,-115.072220,0.174564,0.000000
11.080001,-0.017502,-115.072220,0.006967,0.007011,0.178067,-0.077852,-0.003966,1.780674,-115.072220,0.179056,0.000000
11.350000,-0.004097,-115.116699,0.007136,0.007180,0.182369,-0.018224,-0.000928,1.823689,-115.116699,0.183548,0.000000
11.620001,0.088997,-115.205666,0.007308,0.007355,0.186809,0.395878,0.020167,1.868090,-115.205666,0.188058,0.000000
11.890000,0.192146,-115.116699,0.007506,0.007539,0.191483,0.854709,0.043541,1.914833,-115.116699,0.192550,0.000000
12.160001,0.678833,-115.116699,0.007683,0.007717,0.196002,3.019600,0.153826,1.960017,-115.116699,0.197042,0.000000
12.430000,0.507545,-115.205666,0.007692,-0.000000,-0.000000,2.257675,0.115011,-0.000000,-115.205666,0.000234,0.000000
12.700001,0.488182,-115.161179,0.007696,-0.000000,-0.000000,2.171542,0.110624,-0.000000,-115.161179,0.000234,0.000000
12.970000,0.552971,-115.161179,0.007705,-0.000000,-0.000000,2.459737,0.125305,-0.000000,-115.161179,0.000659,0.000000
13.240001,0.539940,-115.161179,0.007692,0.000000,0.000009,2.401772,0.122352,0.000087,-115.161179,0.001110,0.000000
13.510000,0.649040,-115.205666,0.007709,0.000025,0.000625,2.887075,0.147075,0.006245,-115.205666,0.001561,0.000000
13.780001,0.777885,-115.161179,0.007726,0.000048,0.001214,3.460207,0.176271,0.012142,-115.161179,0.002012,0.000000
14.050000,0.838211,-115.205666,0.007748,0.000065,0.001648,3.728549,0.189941,0.016479,-115.205666,0.002463,0.000000
14.320001,0.863533,-115.294624,0.007769,0.000082,0.002073,3.841187,0.195679,0.020730,-115.294624,0.002914,0.000000
14.590001,0.933533,-115.205666,0.007782,0.000096,0.002446,4.152561,0.211542,0.024458,-115.205666,0.003356,0.000000
14.860001,1.004662,-115.250145,0.007808,0.000116,0.002949,4.468958,0.227660,0.029488,-115.250145,0.003807,0.000000
15.130001,1.093285,-115.250145,0.007830,0.000133,0.003391,4.863173,0.247742,0.033909,-115.250145,0.004258,0.000000
15.400001,1.126801,-115.250145,0.007838,0.000146,0.003721,5.012259,0.255337,0.037206,-115.250145,0.004709,0.000000
15.670001,1.249680,-115.205666,0.007856,0.000171,0.004336,5.558852,0.283181,0.043364,-115.205666,0.005160,0.000000
15.940001,1.311119,-115.250145,0.007886,0.000187,0.004761,5.832149,0.297104,0.047614,-115.250145,0.005611,0.000000
16.210001,1.365486,-115.205666,0.007890,0.000206,0.005221,6.073986,0.309424,0.052209,-115.205666,0.006062,0.000000
16.480001,1.427673,-115.250145,0.007907,0.000221,0.005602,6.350608,0.323515,0.056024,-115.250145,0.006513,0.000000
16.750000,1.527100,-115.339104,0.007933,0.000242,0.006149,6.792878,0.346046,0.061489,-115.339104,0.006964,0.000000
17.020000,1.566200,-115.294624,0.007955,0.000257,0.006522,6.966807,0.354906,0.065218,-115.294624,0.007415,0.000000
17.290001,1.645515,-115.205666,0.007968,0.000272,0.006903,7.319618,0.372879,0.069033,-115.205666,0.007857,0.000000
17.560001,1.739723,-115.250145,0.007989,0.000292,0.007424,7.738675,0.394227,0.074237,-115.250145,0.008308,0.000000
17.830000,1.789619,-115.294624,0.008002,0.000311,0.007901,7.960625,0.405534,0.079006,-115.294624,0.008759,0.000000
18.100000,1.829468,-115.339104,0.008015,0.000330,0.008377,8.137879,0.414563,0.083775,-115.339104,0.009210,0.000000
18.370001,1.863724,-115.294624,0.008028,0.000346,0.008785,8.290257,0.422326,0.087851,-115.294624,0.009661,0.000000
18.640001,1.956444,-115.294624,0.008058,0.000364,0.009236,8.702697,0.443336,0.092363,-115.294624,0.010112,0.000000
18.910002,1.992561,-115.339104,0.008084,0.000382,0.009696,8.863356,0.451521,0.096958,-115.339104,0.010563,0.000000
19.180000,2.078209,-115.339104,0.008097,0.000397,0.010077,9.244335,0.470929,0.100773,-115.339104,0.011014,0.000000
19.450001,2.147095,-115.472549,0.008119,0.000418,0.010615,9.550755,0.486539,0.106151,-115.472549,0.011465,0.000000
19.720001,2.192154,-115.339104,0.008136,0.000436,0.011075,9.751187,0.496749,0.110746,-115.339104,0.011907,0.000000
19.990002,2.211891,-115.339104,0.008157,0.000455,0.011551,9.838984,0.501222,0.115515,-115.339104,0.012358,0.000000
20.260000,2.224182,-115.339104,0.008170,0.000469,0.011907,9.893656,0.504007,0.119073,-115.339104,0.012809,0.000000
20.530001,2.262161,-115.428070,0.008175,0.000481,0.012228,10.062595,0.512613,0.122282,-115.428070,0.013260,0.000000
20.800001,2.408501,-115.383591,0.008201,0.000505,0.012818,10.713546,0.545774,0.128179,-115.383591,0.013711,0.000000
21.070002,2.407387,-115.339104,0.008213,0.000517,0.013130,10.708591,0.545522,0.131298,-115.339104,0.014162,0.000000
21.340000,2.426003,-115.383591,0.008235,0.000530,0.013468,10.791398,0.549740,0.134682,-115.383591,0.014613,0.000000
21.610001,2.625221,-115.472549,0.008252,0.000562,0.014283,11.677567,0.594884,0.142834,-115.472549,0.015064,0.000000
21.880001,2.572723,-115.383591,0.008269,0.000578,0.014691,11.444045,0.582987,0.146911,-115.383591,0.015515,0.000000
22.150002,2.582031,-115.517029,0.008295,0.000591,0.015012,11.485449,0.585097,0.150120,-115.517029,0.015966,0.000000
22.420002,2.595062,-115.383591,0.008317,0.000603,0.015315,11.543413,0.588050,0.153152,-115.383591,0.016408,0.000000
22.690001,2.822578,-115.428070,0.008343,0.000631,0.016035,12.555456,0.639605,0.160351,-115.428070,0.016859,0.000000
22.960001,2.776405,-115.472549,0.008347,0.000642,0.016295,12.350068,0.629142,0.162955,-115.472549,0.017310,0.000000
23.230001,2.819977,-115.517029,0.008364,0.000657,0.016686,12.543883,0.639016,0.166857,-115.517029,0.017761,0.000000
23.500002,2.995735,-115.517029,0.008403,0.000684,0.017371,13.325696,0.678843,0.173708,-115.517029,0.018212,0.000000
23.770000,3.009888,-115.472549,0.008420,0.000701,0.017804,13.388649,0.682050,0.178041,-115.472549,0.018663,0.000000
24.040001,2.992386,-115.428070,0.008420,0.000717,0.018203,13.310797,0.678084,0.182031,-115.428070,0.019114,0.000000
24.310001,2.951050,-115.517029,0.008446,0.000728,0.018490,13.126925,0.668717,0.184896,-115.517029,0.019565,0.000000
24.580002,3.210968,-115.605995,0.008459,0.000755,0.019166,14.283099,0.727616,0.191660,-115.605995,0.020016,0.000000
24.850000,3.170380,-115.517029,0.008485,0.000766,0.019452,14.102553,0.718418,0.194521,-115.517029,0.020458,0.000000
25.120001,3.213570,-115.561508,0.008515,0.000783,0.019886,14.294672,0.728205,0.198858,-115.561508,0.020909,0.000000
25.390001,3.273895,-115.561508,0.008515,0.000801,0.020354,14.563013,0.741875,0.203540,-115.561508,0.021360,0.000000
25.660002,3.386726,-115.561508,0.008541,0.000825,0.020944,15.064911,0.767443,0.209437,-115.561508,0.021811,0.000000
25.930000,3.349113,-115.561508,0.008563,0.000840,0.021343,14.897601,0.758920,0.213426,-115.561508,0.022262,0.000000
26.200001,3.402740,-115.517029,0.008580,0.000859,0.021820,15.136146,0.771072,0.218195,-115.517029,0.022713,0.000000
26.470001,3.406090,-115.561508,0.008610,0.000869,0.022063,15.151044,0.771831,0.220625,-115.561508,0.023164,0.000000
26.740002,3.500298,-115.605995,0.008627,0.000889,0.022574,15.570101,0.793179,0.225742,-115.605995,0.023615,0.000000
27.010002,3.552429,-115.561508,0.008645,0.000906,0.023008,15.801994,0.804992,0.230076,-115.561508,0.024066,0.000000
27.280001,3.740105,-115.650475,0.008683,0.000935,0.023745,16.636816,0.847520,0.237449,-115.650475,0.024508,0.000000
27.550001,3.701378,-115.561508,0.008692,0.000952,0.024187,16.464552,0.838744,0.241870,-115.561508,0.024959,0.000000
27.820002,3.639565,-115.605995,0.008718,0.000968,0.024577,16.189592,0.824737,0.245772,-115.605995,0.025410,0.000000
28.090002,3.580734,-115.605995,0.008735,0.000979,0.024872,15.927901,0.811406,0.248721,-115.605995,0.025861,0.000000
28.360001,3.714417,-115.650475,0.008748,0.001000,0.025410,16.522551,0.841699,0.254099,-115.650475,0.026312,0.000000
28.630001,3.788147,-115.650475,0.008770,0.001016,0.025809,16.850519,0.858406,0.258088,-115.650475,0.026763,0.000000
28.900002,3.714043,-115.605995,0.008787,0.001024,0.026008,16.520887,0.841614,0.260083,-115.605995,0.027214,0.000000
29.170002,3.823891,-115.650475,0.008808,0.001046,0.026581,17.009516,0.866506,0.265806,-115.650475,0.027665,0.000000
29.440001,3.956459,-115.650475,0.008821,0.001069,0.027153,17.599209,0.896546,0.271528,-115.650475,0.028116,0.000000
29.710001,3.957947,-115.694954,0.008834,0.001088,0.027630,17.605827,0.896884,0.276301,-115.694954,0.028566,0.000000
29.980001,3.975822,-115.739433,0.008886,0.001106,0.028098,17.685341,0.900934,0.280983,-115.739433,0.029009,0.000000
30.250002,4.019012,-115.694954,0.008899,0.001127,0.028619,17.877460,0.910721,0.286187,-115.694954,0.029460,0.000000
30.520002,4.008957,-115.694954,0.008908,0.001143,0.029026,17.832731,0.908443,0.290264,-115.694954,0.029911,0.000000
30.790001,3.995186,-115.694954,0.008933,0.001157,0.029390,17.771475,0.905322,0.293905,-115.694954,0.030362,0.000000
31.060001,4.127747,-115.694954,0.008951,0.001179,0.029945,18.361134,0.935361,0.299453,-115.694954,0.030813,0.000000
31.330002,4.143013,-115.783913,0.008977,0.001198,0.030423,18.429043,0.938820,0.304226,-115.783913,0.031264,0.000000
31.600002,4.105034,-115.694954,0.009002,0.001217,0.030900,18.260103,0.930214,0.308995,-115.694954,0.031715,0.000000
31.870001,4.147484,-115.694954,0.009028,0.001232,0.031281,18.448929,0.939833,0.312810,-115.694954,0.032166,0.000000
32.140003,4.131096,-115.694954,0.009041,0.001248,0.031697,18.376032,0.936120,0.316974,-115.694954,0.032617,0.000000
32.410000,4.185837,-115.739433,0.009067,0.001267,0.032174,18.619532,0.948524,0.321743,-115.739433,0.033059,0.000000
32.680000,4.202591,-115.739433,0.009084,0.001283,0.032599,18.694057,0.952321,0.325993,-115.739433,0.033510,0.000000
32.950001,4.294571,-115.739433,0.009106,0.001303,0.033085,19.103205,0.973164,0.330849,-115.739433,0.033961,0.000000
33.220001,4.354897,-115.739433,0.009123,0.001321,0.033562,19.371548,0.986834,0.335618,-115.739433,0.034412,0.000000
33.490002,4.291222,-115.783913,0.009149,0.001341,0.034056,19.088306,0.972405,0.340561,-115.783913,0.034863,0.000000
33.760002,4.293823,-115.783913,0.009179,0.001358,0.034490,19.099880,0.972994,0.344899,-115.783913,0.035313,0.000000
34.030003,4.224564,-115.828400,0.009192,0.001368,0.034750,18.791798,0.957300,0.347499,-115.828400,0.035765,0.000000
34.300003,4.348564,-115.783913,0.009214,0.001387,0.035235,19.343380,0.985399,0.352355,-115.783913,0.036215,0.000000
34.570004,4.420807,-115.828400,0.009209,0.001408,0.035773,19.664732,1.001769,0.357733,-115.828400,0.036667,0.000000
34.840000,4.505333,-115.872879,0.009244,0.001427,0.036250,20.040722,1.020923,0.362502,-115.872879,0.037109,0.000000
35.110001,4.569382,-115.828400,0.009261,0.001448,0.036779,20.325624,1.035437,0.367793,-115.828400,0.037560,0.000000
35.380001,4.541824,-115.872879,0.009291,0.001466,0.037230,20.203043,1.029192,0.372301,-115.872879,0.038011,0.000000
35.650002,4.511665,-115.739433,0.009317,0.001483,0.037664,20.068890,1.022358,0.376639,-115.739433,0.038462,0.000000
35.920002,4.503471,-115.872879,0.009330,0.001495,0.037967,20.032442,1.020501,0.379674,-115.872879,0.038913,0.000000
36.190002,4.609222,-115.872879,0.009356,0.001517,0.038540,20.502846,1.044465,0.385397,-115.872879,0.039364,0.000000
36.460003,4.615929,-115.917358,0.009365,0.001532,0.038921,20.532677,1.045984,0.389212,-115.917358,0.039814,0.000000
36.730003,4.660240,-115.872879,0.009390,0.001548,0.039329,20.729784,1.056026,0.393288,-115.872879,0.040266,0.000000
37.000000,4.764130,-115.872879,0.009421,0.001571,0.039892,21.191908,1.079567,0.398924,-115.872879,0.040716,0.000000
37.270000,4.741417,-115.872879,0.009434,0.001586,0.040291,21.090876,1.074420,0.402913,-115.872879,0.041168,0.000000
37.540001,4.760406,-115.961838,0.009442,0.001605,0.040769,21.175346,1.078724,0.407686,-115.961838,0.041610,0.000000
37.810001,4.790573,-115.961838,0.009485,0.001621,0.041185,21.309534,1.085559,0.411846,-115.961838,0.042061,0.000000
38.080002,4.870255,-115.872879,0.009511,0.001643,0.041722,21.663975,1.103616,0.417224,-115.872879,0.042512,0.000000
38.350002,4.839348,-115.872879,0.009528,0.001657,0.042078,21.526495,1.096612,0.420778,-115.872879,0.042963,0.000000
38.620003,4.845306,-115.917358,0.009528,0.001672,0.042460,21.552999,1.097962,0.424597,-115.917358,0.043414,0.000000
38.890003,4.974152,-115.917358,0.009550,0.001693,0.043015,22.126131,1.127159,0.430146,-115.917358,0.043864,0.000000
39.160004,4.982346,-115.961838,0.009572,0.001710,0.043422,22.162580,1.129016,0.434222,-115.961838,0.044315,0.000000
39.430000,5.028519,-115.872879,0.009606,0.001730,0.043943,22.367968,1.139479,0.439426,-115.872879,0.044766,0.000000
39.700001,5.025909,-115.961838,0.009606,0.001746,0.044342,22.356361,1.138887,0.443416,-115.961838,0.045217,0.000000
39.970001,5.067245,-116.006317,0.009649,0.001763,0.044792,22.540234,1.148254,0.447923,-116.006317,0.045659,0.000000
40.240002,5.124962,-116.006317,0.009649,0.001781,0.045226,22.796968,1.161333,0.452261,-116.006317,0.046111,0.000000
40.510002,5.141716,-115.961838,0.009679,0.001796,0.045616,22.871494,1.165130,0.456163,-115.961838,0.046561,0.000000
40.780003,5.254547,-115.961838,0.009692,0.001818,0.046171,23.373392,1.190697,0.461712,-115.961838,0.047013,0.000000
41.050003,5.286201,-116.050804,0.009718,0.001835,0.046605,23.514198,1.197870,0.466049,-116.050804,0.047463,0.000000
41.320004,5.276886,-116.050804,0.009744,0.001855,0.047125,23.472761,1.195759,0.471253,-116.050804,0.047914,0.000000
41.590000,5.238533,-116.050804,0.009761,0.001868,0.047438,23.302158,1.187069,0.474376,-116.050804,0.048365,0.000000
41.860001,5.200928,-116.050804,0.009779,0.001880,0.047758,23.134882,1.178547,0.477582,-116.050804,0.048816,0.000000
42.130001,5.454514,-116.006317,0.009796,0.001904,0.048357,24.262888,1.236010,0.483566,-116.006317,0.049267,0.000000
42.400002,5.397537,-116.050804,0.009817,0.001918,0.048730,24.009445,1.223099,0.487298,-116.050804,0.049710,0.000000
42.670002,5.340935,-116.095284,0.009822,0.001929,0.048998,23.757664,1.210273,0.489985,-116.095284,0.050160,0.000000
42.940002,5.679420,-116.095284,0.009852,0.001961,0.049814,25.263325,1.286975,0.498138,-116.095284,0.050612,0.000000
43.210003,5.571434,-116.006317,0.009878,0.001978,0.050247,24.782976,1.262505,0.502471,-116.006317,0.051062,0.000000
43.480003,5.508133,-116.006317,0.009899,0.001992,0.050594,24.501398,1.248161,0.505942,-116.006317,0.051514,0.000000
43.750004,5.451530,-116.050804,0.009908,0.002002,0.050846,24.249619,1.235335,0.508455,-116.050804,0.051964,0.000000
44.020000,5.822044,-116.184242,0.009934,0.002032,0.051609,25.897747,1.319294,0.516089,-116.184242,0.052415,0.000000
44.290001,5.643303,-116.095284,0.009955,0.002040,0.051825,25.102665,1.278791,0.518254,-116.095284,0.052866,0.000000
44.560001,5.685013,-116.095284,0.009964,0.002056,0.052216,25.288200,1.288242,0.522157,-116.095284,0.053317,0.000000
44.830002,5.947906,-116.050804,0.009998,0.002084,0.052944,26.457609,1.347815,0.529442,-116.050804,0.053768,0.000000
45.100002,5.890556,-116.184242,0.010029,0.002100,0.053352,26.202503,1.334819,0.533519,-116.184242,0.054210,0.000000
45.370003,5.830231,-116.184242,0.010033,0.002115,0.053725,25.934162,1.321149,0.537247,-116.184242,0.054661,0.000000
45.640003,5.740120,-116.184242,0.010063,0.002127,0.054020,25.533329,1.300730,0.540195,-116.184242,0.055112,0.000000
45.910004,6.054031,-116.139763,0.010076,0.002153,0.054696,26.929676,1.371863,0.546963,-116.139763,0.055563,0.000000
46.180000,5.970245,-116.139763,0.010080,0.002165,0.054991,26.556978,1.352877,0.549911,-116.139763,0.056014,0.000000
46.450001,6.105789,-116.184242,0.010102,0.002185,0.055511,27.159906,1.383592,0.555112,-116.184242,0.056465,0.000000
46.720001,6.104301,-116.273209,0.010141,0.002201,0.055893,27.153290,1.383254,0.558931,-116.273209,0.056916,0.000000
46.990002,6.294952,-116.184242,0.010158,0.002224,0.056483,28.001347,1.426457,0.564827,-116.184242,0.057367,0.000000
47.260002,6.218246,-116.184242,0.010171,0.002239,0.056882,27.660141,1.409075,0.568817,-116.184242,0.057818,0.000000
47.530003,6.333679,-116.139763,0.010179,0.002258,0.057341,28.173613,1.435232,0.573412,-116.139763,0.058261,0.000000
47.800003,6.220482,-116.228722,0.010214,0.002270,0.057653,27.670086,1.409581,0.576534,-116.228722,0.058711,0.000000
48.070004,6.403687,-116.273209,0.010240,0.002290,0.058165,28.485020,1.451096,0.581651,-116.273209,0.059162,0.000000
48.340004,6.434967,-116.184242,0.010248,0.002305,0.058555,28.624163,1.458184,0.585554,-116.184242,0.059613,0.000000
48.610001,6.817764,-116.228722,0.010266,0.002334,0.059284,30.326931,1.544927,0.592836,-116.228722,0.060064,0.000000
48.880001,6.742546,-116.228722,0.010292,0.002352,0.059743,29.992342,1.527883,0.597434,-116.228722,0.060515,0.000000
49.150002,6.636421,-116.228722,0.010305,0.002367,0.060116,29.520275,1.503834,0.601162,-116.228722,0.060966,0.000000
49.420002,6.576843,-116.273209,0.010326,0.002381,0.060489,29.255260,1.490334,0.604891,-116.273209,0.061417,0.000000
49.690002,6.818512,-116.317688,0.010343,0.002400,0.060966,30.330256,1.545097,0.609663,-116.317688,0.061868,0.000000
49.960003,6.945862,-116.184242,0.010369,0.002418,0.061426,30.896736,1.573955,0.614258,-116.184242,0.062310,0.000000
50.230003,6.649078,-116.228722,0.010386,0.002423,0.061547,29.576578,1.506703,0.615473,-116.228722,0.062761,0.000000
50.500004,7.015121,-116.273209,0.010395,0.002448,0.062180,31.204819,1.589649,0.621801,-116.273209,0.063212,0.000000
50.770004,7.179337,-116.317688,0.010421,0.002469,0.062718,31.935284,1.626861,0.627180,-116.317688,0.063663,0.000000
51.040001,7.256050,-116.273209,0.010438,0.002488,0.063195,32.276524,1.644245,0.631949,-116.273209,0.064114,0.000000
51.310001,7.313019,-116.317688,0.010464,0.002506,0.063646,32.529934,1.657154,0.636460,-116.317688,0.064565,0.000000
51.580002,7.476494,-116.317688,0.010477,0.002527,0.064183,33.257107,1.694198,0.641835,-116.317688,0.065016,0.000000
51.850002,7.480591,-116.406647,0.010490,0.002542,0.064574,33.275330,1.695126,0.645737,-116.406647,0.065467,0.000000
52.120003,7.480965,-116.362167,0.010520,0.002556,0.064921,33.276993,1.695211,0.649208,-116.362167,0.065918,0.000000
52.390003,7.663048,-116.362167,0.010546,0.002578,0.065484,34.086941,1.736472,0.654844,-116.362167,0.066369,0.000000
52.660004,7.824287,-116.362167,0.010550,0.002598,0.065979,34.804169,1.773009,0.659787,-116.362167,0.066811,0.000000
52.930004,7.858543,-116.362167,0.010576,0.002616,0.066447,34.956547,1.780771,0.664469,-116.362167,0.067262,0.000000
53.200001,7.881264,-116.451126,0.010598,0.002631,0.066837,35.057613,1.785920,0.668371,-116.451126,0.067713,0.000000
53.470001,8.013451,-116.362167,0.010624,0.002650,0.067314,35.645607,1.815874,0.673144,-116.362167,0.068164,0.000000
53.740002,8.133728,-116.406647,0.010641,0.002667,0.067739,36.180630,1.843129,0.677390,-116.406647,0.068615,0.000000
54.010002,8.285286,-116.362167,0.010645,0.002685,0.068199,36.854794,1.877473,0.681989,-116.362167,0.069066,0.000000
54.280003,8.392899,-116.406647,0.010658,0.002701,0.068607,37.333477,1.901858,0.686065,-116.406647,0.069517,0.000000
54.550003,8.548180,-116.451126,0.010693,0.002719,0.069075,38.024200,1.937045,0.690747,-116.451126,0.069968,0.000000
54.820004,8.699738,-116.406647,0.010718,0.002743,0.069664,38.698364,1.971389,0.696644,-116.406647,0.070419,0.000000
55.090004,8.646858,-116.451126,0.010727,0.002758,0.070046,38.463146,1.959406,0.700459,-116.451126,0.070861,0.000000
55.360004,8.818893,-116.451126,0.010744,0.002774,0.070462,39.228397,1.998390,0.704623,-116.451126,0.071312,0.000000
55.630001,8.945877,-116.495613,0.010762,0.002792,0.070913,39.793247,2.027165,0.709130,-116.495613,0.071763,0.000000
55.900002,8.989441,-116.495613,0.010774,0.002805,0.071251,39.987030,2.037036,0.712514,-116.495613,0.072214,0.000000
56.170002,9.329422,-116.406647,0.010805,0.002828,0.071832,41.499340,2.114077,0.718324,-116.406647,0.072665,0.000000
56.440002,9.483582,-116.451126,0.010818,0.002847,0.072309,42.185078,2.149010,0.723093,-116.451126,0.073116,0.000000
56.710003,9.590080,-116.495613,0.010848,0.002866,0.072795,42.658806,2.173143,0.727953,-116.495613,0.073567,0.000000
56.980003,9.631042,-116.540092,0.010856,0.002883,0.073220,42.841015,2.182425,0.732199,-116.540092,0.074018,0.000000
57.250004,9.586357,-116.540092,0.010869,0.002894,0.073498,42.642246,2.172300,0.734977,-116.540092,0.074469,0.000000
57.520004,9.996712,-116.495613,0.010895,0.002916,0.074070,44.467594,2.265287,0.740700,-116.495613,0.074920,0.000000
57.790001,10.080124,-116.495613,0.010912,0.002932,0.074469,44.838631,2.284189,0.744689,-116.495613,0.075362,0.000000
58.060001,10.140816,-116.540092,0.010917,0.002947,0.074842,45.108601,2.297942,0.748418,-116.540092,0.075813,0.000000
58.330002,10.619690,-116.540092,0.010943,0.002970,0.075440,47.238739,2.406456,0.754402,-116.540092,0.076264,0.000000
58.600002,10.657669,-116.584572,0.010969,0.002985,0.075813,47.407681,2.415062,0.758130,-116.584572,0.076715,0.000000
58.870003,10.863220,-116.540092,0.010981,0.003004,0.076299,48.322018,2.461641,0.762986,-116.540092,0.077166,0.000000
59.140003,10.990196,-116.495613,0.011003,0.003020,0.076697,48.886833,2.490414,0.766975,-116.495613,0.077617,0.000000
59.410004,11.354004,-116.495613,0.011016,0.003042,0.077278,50.505131,2.572854,0.772785,-116.495613,0.078068,0.000000
59.680004,11.431091,-116.584572,0.011037,0.003058,0.077669,50.848034,2.590322,0.776691,-116.584572,0.078519,0.000000
59.950005,11.543175,-116.584572,0.011050,0.003071,0.078007,51.346607,2.615721,0.780071,-116.584572,0.078970,0.000000
60.220001,11.952408,-116.584572,0.011072,0.003092,0.078545,53.166965,2.708454,0.785449,-116.584572,0.079412,0.000000
60.490002,12.171738,-116.584572,0.011089,0.003108,0.078953,54.142593,2.758155,0.789525,-116.584572,0.079863,0.000000
60.760002,12.466286,-116.629051,0.011106,0.003129,0.079481,55.452808,2.824901,0.794813,-116.629051,0.080314,0.000000
61.030003,12.548203,-116.673538,0.011119,0.003144,0.079854,55.817192,2.843463,0.798545,-116.673538,0.080765,0.000000
61.300003,12.914993,-116.584572,0.011141,0.003164,0.080357,57.448761,2.926579,0.803575,-116.584572,0.081216,0.000000
61.570004,13.136925,-116.629051,0.011163,0.003180,0.080765,58.435959,2.976870,0.807647,-116.629051,0.081667,0.000000
61.840004,13.360352,-116.584572,0.011167,0.003196,0.081172,59.429813,3.027499,0.811724,-116.584572,0.082118,0.000000
62.110004,13.863800,-116.629051,0.011193,0.003217,0.081719,61.669262,3.141582,0.817189,-116.629051,0.082569,0.000000
62.380001,14.125206,-116.673538,0.011206,0.003235,0.082170,62.832054,3.200817,0.821697,-116.673538,0.083020,0.000000
62.650002,14.410812,-116.673538,0.011227,0.003254,0.082664,64.102493,3.265537,0.826640,-116.673538,0.083462,0.000000
62.920002,14.449165,-116.718018,0.011227,0.003267,0.082985,64.273094,3.274228,0.829850,-116.718018,0.083913,0.000000
63.190002,14.488266,-116.584572,0.011253,0.003279,0.083280,64.447029,3.283088,0.832798,-116.584572,0.084364,0.000000
63.460003,15.340996,-116.673538,0.011262,0.003302,0.083878,68.240158,3.476319,0.838782,-116.673538,0.084815,0.000000
63.730003,15.373398,-116.718018,0.011270,0.003317,0.084260,68.384293,3.483662,0.842597,-116.718018,0.085266,0.000000
64.000000,15.457924,-116.673538,0.011305,0.003330,0.084572,68.760277,3.502816,0.845720,-116.673538,0.085717,0.000000
64.270004,16.777611,-116.718018,0.011331,0.003360,0.085352,74.630539,3.801861,0.853524,-116.718018,0.086168,0.000000
64.540001,16.872192,-116.718018,0.011335,0.003379,0.085821,75.051262,3.823293,0.858210,-116.718018,0.086619,0.000000
64.810005,16.964172,-116.762497,0.011348,0.003391,0.086142,75.460411,3.844136,0.861416,-116.762497,0.087070,0.000000
65.080002,16.874428,-116.718018,0.011361,0.003401,0.086376,75.061203,3.823800,0.863758,-116.718018,0.087521,0.000000
65.350006,18.094322,-116.762497,0.011387,0.003430,0.087122,80.487564,4.100232,0.871219,-116.762497,0.087963,0.000000
65.620003,17.981491,-116.673538,0.011391,0.003439,0.087347,79.985664,4.074664,0.873470,-116.673538,0.088414,0.000000
65.889999,18.323700,-116.718018,0.011395,0.003454,0.087737,81.507889,4.152210,0.877373,-116.718018,0.088865,0.000000
66.160004,19.651581,-116.806976,0.011417,0.003485,0.088518,87.414597,4.453112,0.885177,-116.806976,0.089316,0.000000
66.430000,19.842613,-116.851456,0.011434,0.003500,0.088891,88.264351,4.496400,0.888909,-116.851456,0.089767,0.000000
66.700005,19.988953,-116.762497,0.011451,0.003514,0.089255,88.915298,4.529562,0.892550,-116.762497,0.090218,0.000000
66.970001,20.048157,-116.806976,0.011464,0.003525,0.089541,89.178658,4.542977,0.895412,-116.806976,0.090669,0.000000
67.240005,21.437111,-116.806976,0.011495,0.003554,0.090261,95.357033,4.857718,0.902610,-116.806976,0.091119,0.000000
67.510002,21.386467,-116.806976,0.011486,0.003563,0.090512,95.131760,4.846243,0.905124,-116.806976,0.091571,0.000000
67.780006,21.971092,-116.851456,0.011503,0.003582,0.090990,97.732300,4.978721,0.909896,-116.851456,0.092013,0.000000
68.050003,22.562790,-116.762497,0.011520,0.003599,0.091414,100.364304,5.112801,0.914143,-116.762497,0.092464,0.000000
68.320000,23.445686,-116.806976,0.011538,0.003622,0.091987,104.291618,5.312869,0.919870,-116.806976,0.092915,0.000000
68.590004,23.836678,-116.806976,0.011546,0.003638,0.092395,106.030838,5.401468,0.923946,-116.806976,0.093366,0.000000
68.860001,24.552376,-116.895943,0.011559,0.003656,0.092863,109.214424,5.563648,0.928628,-116.895943,0.093817,0.000000
69.130005,24.712494,-116.895943,0.011572,0.003667,0.093140,109.926666,5.599931,0.931402,-116.895943,0.094268,0.000000
69.400002,25.630020,-116.851456,0.011602,0.003688,0.093687,114.008026,5.807846,0.936867,-116.851456,0.094719,0.000000
69.670006,26.166611,-116.851456,0.011607,0.003704,0.094077,116.394897,5.929439,0.940770,-116.851456,0.095170,0.000000
69.940002,27.707489,-116.895943,0.011628,0.003732,0.094796,123.249069,6.278607,0.947965,-116.895943,0.095620,0.000000
70.210007,28.160294,-116.895943,0.011641,0.003750,0.095248,125.263245,6.381214,0.952476,-116.895943,0.096063,0.000000
70.480003,28.622032,-116.984901,0.011663,0.003765,0.095629,127.317162,6.485846,0.956292,-116.984901,0.096514,0.000000
70.750000,28.871529,-116.940422,0.011667,0.003780,0.096011,128.426971,6.542382,0.960107,-116.940422,0.096965,0.000000
71.020004,29.660583,-116.895943,0.011676,0.003798,0.096479,131.936859,6.721184,0.964789,-116.895943,0.097416,0.000000
71.290001,30.664871,-116.940422,0.011676,0.003817,0.096947,136.404160,6.948759,0.969474,-116.940422,0.097867,0.000000
71.560005,30.581459,-116.940422,0.011710,0.003828,0.097242,136.033127,6.929858,0.972423,-116.940422,0.098318,0.000000
71.830002,31.675491,-116.984901,0.011706,0.003847,0.097702,140.899628,7.177769,0.977018,-116.984901,0.098768,0.000000
72.100006,32.966507,-116.940422,0.011727,0.003868,0.098240,146.642349,7.470317,0.982396,-116.940422,0.099220,0.000000
72.370003,33.770828,-116.940422,0.011740,0.003886,0.098708,150.220154,7.652579,0.987078,-116.940422,0.099670,0.000000
72.640007,34.664520,-116.984901,0.011749,0.003904,0.099150,154.195480,7.855093,0.991502,-116.984901,0.100121,0.000000
72.910004,35.697113,-117.029381,0.011758,0.003925,0.099696,158.788696,8.089082,0.996964,-117.029381,0.100564,0.000000
73.180000,36.406113,-117.029381,0.011783,0.003940,0.100078,161.942474,8.249743,1.000779,-117.029381,0.101015,0.000000
73.450005,36.944191,-116.984901,0.011779,0.003954,0.100442,164.335968,8.371674,1.004424,-116.984901,0.101465,0.000000
73.720001,38.241158,-116.984901,0.011783,0.003977,0.101006,170.105164,8.665570,1.010060,-116.984901,0.101917,0.000000
73.990005,39.221619,-117.029381,0.011809,0.003996,0.101500,174.466476,8.887746,1.015003,-117.029381,0.102367,0.000000
74.260002,40.126480,-117.029381,0.011822,0.004015,0.101977,178.491501,9.092790,1.019772,-117.029381,0.102819,0.000000
74.530006,40.877930,-116.984901,0.011831,0.004029,0.102324,181.834106,9.263071,1.023243,-116.984901,0.103269,0.000000
74.800003,41.742577,-116.984901,0.011844,0.004048,0.102827,185.680252,9.459003,1.028273,-116.984901,0.103721,0.000000
75.070007,42.804214,-117.029381,0.011848,0.004064,0.103226,190.402649,9.699574,1.032262,-117.029381,0.104171,0.000000
75.340004,43.559387,-117.118347,0.011857,0.004081,0.103668,193.761826,9.870698,1.036683,-117.118347,0.104614,0.000000
75.610001,44.359612,-117.118347,0.011883,0.004099,0.104111,197.321411,10.052032,1.041107,-117.118347,0.105065,0.000000
75.880005,46.023376,-117.029381,0.011895,0.004118,0.104605,204.722198,10.429046,1.046050,-117.029381,0.105516,0.000000
76.150002,47.078308,-117.118347,0.011908,0.004139,0.105134,209.414780,10.668097,1.051338,-117.118347,0.105966,0.000000
76.420006,47.888588,-117.029381,0.011908,0.004154,0.105516,213.019073,10.851708,1.055157,-117.029381,0.106418,0.000000
76.690002,48.457573,-117.118347,0.011917,0.004169,0.105888,215.550049,10.980643,1.058885,-117.118347,0.106868,0.000000
76.960007,49.780609,-117.162827,0.011926,0.004188,0.106383,221.435211,11.280447,1.063828,-117.162827,0.107319,0.000000
77.230003,50.967361,-117.118347,0.011934,0.004204,0.106773,226.714142,11.549370,1.067730,-117.118347,0.107770,0.000000
77.500000,52.224121,-117.118347,0.011952,0.004225,0.107311,232.304489,11.834154,1.073109,-117.118347,0.108221,0.000000
77.770004,53.672279,-117.162827,0.011964,0.004244,0.107796,238.746216,12.162312,1.077965,-117.162827,0.108664,0.000000
78.040001,54.770401,-117.162827,0.011977,0.004263,0.108273,243.630905,12.411150,1.082734,-117.162827,0.109114,0.000000
78.310005,55.756073,-117.162827,0.011986,0.004278,0.108672,248.015396,12.634506,1.086723,-117.162827,0.109566,0.000000
78.580002,56.588326,-117.162827,0.011990,0.004292,0.109010,251.717438,12.823098,1.090103,-117.162827,0.110016,0.000000
78.850006,58.020470,-117.118347,0.012003,0.004314,0.109583,258.087952,13.147627,1.095829,-117.118347,0.110467,0.000000
79.120003,59.119713,-117.162827,0.012016,0.004330,0.109973,262.977631,13.396718,1.099732,-117.162827,0.110918,0.000000
79.390007,59.989578,-117.162827,0.012016,0.004344,0.110329,266.846985,13.593832,1.103286,-117.162827,0.111369,0.000000
79.660004,61.719246,-117.251785,0.012033,0.004367,0.110918,274.540924,13.985781,1.109182,-117.251785,0.111820,0.000000
79.930000,62.818863,-117.162827,0.012042,0.004383,0.111326,279.432251,14.234958,1.113259,-117.162827,0.112271,0.000000
80.200005,64.102798,-117.162827,0.012051,0.004402,0.111803,285.143494,14.525902,1.118028,-117.162827,0.112722,0.000000
80.470001,65.078049,-117.251785,0.012051,0.004418,0.112219,289.481628,14.746897,1.122191,-117.251785,0.113165,0.000000
80.740005,66.700104,-117.207306,0.012072,0.004439,0.112757,296.696869,15.114459,1.127569,-117.207306,0.113615,0.000000
81.010002,67.311539,-117.251785,0.012085,0.004441,0.112800,299.416687,15.253013,1.128001,-117.251785,0.113008,0.000000
81.280006,66.691910,-117.251785,0.012094,0.004441,0.112791,296.660431,15.112602,1.127914,-117.251785,0.113008,0.000000
81.550003,66.190323,-117.207306,0.012089,0.004440,0.112774,294.429260,14.998941,1.127743,-117.207306,0.112791,0.000000
81.820007,65.724487,-117.251785,0.012089,0.004440,0.112766,292.357117,14.893382,1.127656,-117.251785,0.112791,0.000000
82.090004,65.333496,-117.251785,0.012085,0.004439,0.112757,290.617920,14.804782,1.127569,-117.251785,0.112791,0.000000
82.360001,64.983093,-117.251785,0.012102,0.004439,0.112757,289.059235,14.725379,1.127569,-117.251785,0.112791,0.000000
82.630005,64.671417,-117.296265,0.012094,0.004439,0.112757,287.672821,14.654753,1.127569,-117.296265,0.112791,0.000000
82.900002,64.395493,-117.251785,0.012115,0.004439,0.112748,286.445465,14.592227,1.127482,-117.251785,0.112791,0.000000
83.170006,64.141525,-117.296265,0.012107,0.004439,0.112748,285.315765,14.534678,1.127482,-117.296265,0.112791,0.000000
83.440002,63.890915,-117.385231,0.012107,0.004439,0.112748,284.200989,14.477888,1.127482,-117.385231,0.112791,0.000000
83.710007,63.674576,-117.296265,0.012120,0.004439,0.112748,283.238647,14.428864,1.127482,-117.296265,0.112791,0.000000
83.980003,63.486893,-117.251785,0.012111,0.004439,0.112748,282.403809,14.386335,1.127482,-117.251785,0.112791,0.000000
84.250008,63.304062,-117.340752,0.012102,0.004439,0.112748,281.590546,14.344906,1.127482,-117.340752,0.112791,0.000000
84.520004,63.123840,-117.296265,0.012107,0.004439,0.112748,280.788879,14.304067,1.127482,-117.296265,0.112791,0.000000
84.790001,62.967812,-117.429710,0.012124,0.004439,0.112748,280.094818,14.268710,1.127482,-117.429710,0.112791,0.000000
85.060005,62.811043,-117.251785,0.012115,0.004439,0.112748,279.397461,14.233186,1.127482,-117.251785,0.112791,0.000000
85.330002,62.667679,-117.340752,0.012107,0.004439,0.112748,278.759766,14.200699,1.127482,-117.340752,0.112791,0.000000
85.600006,62.531387,-117.340752,0.012115,0.004439,0.112748,278.153503,14.169815,1.127482,-117.340752,0.112791,0.000000
85.870003,62.424515,-117.385231,0.012107,0.004439,0.112748,277.678101,14.145597,1.127482,-117.385231,0.112791,0.000000
86.140007,62.293068,-117.429710,0.012115,0.004439,0.112748,277.093414,14.115811,1.127482,-117.429710,0.112791,0.000000
86.410004,62.178383,-117.385231,0.012124,0.004439,0.112748,276.583252,14.089824,1.127482,-117.385231,0.112791,0.000000
86.680000,62.084541,-117.385231,0.012120,0.004439,0.112748,276.165833,14.068558,1.127482,-117.385231,0.112791,0.000000
86.950005,61.969109,-117.429710,0.012120,0.004439,0.112748,275.652374,14.042400,1.127482,-117.429710,0.112791,0.000000
87.220001,61.864471,-117.429710,0.012124,0.004439,0.112748,275.186920,14.018689,1.127482,-117.429710,0.112791,0.000000
87.490005,61.771751,-117.429710,0.012120,0.004439,0.112748,274.774475,13.997679,1.127482,-117.429710,0.112791,0.000000
87.760002,61.690941,-117.429710,0.012120,0.004439,0.112748,274.415009,13.979367,1.127482,-117.429710,0.112791,0.000000
88.030006,61.597855,-117.340752,0.012124,0.004439,0.112748,274.000946,13.958273,1.127482,-117.340752,0.112791,0.000000
88.300003,61.503265,-117.474190,0.012128,0.004439,0.112748,273.580200,13.936839,1.127482,-117.474190,0.112791,0.000000
88.570007,61.434380,-117.518669,0.012111,0.004439,0.112748,273.273773,13.921229,1.127482,-117.518669,0.112791,0.000000
88.840004,61.346130,-117.518669,0.012133,0.004439,0.112748,272.881226,13.901232,1.127482,-117.518669,0.112791,0.000000
89.110001,61.272026,-117.563156,0.012133,0.004439,0.112748,272.551575,13.884439,1.127482,-117.563156,0.112791,0.000000
89.380005,61.199783,-117.429710,0.012137,0.004439,0.112748,272.230225,13.868070,1.127482,-117.429710,0.112791,0.000000
89.650002,61.137230,-117.518669,0.012120,0.004439,0.112748,271.951996,13.853894,1.127482,-117.518669,0.112791,0.000000
89.920006,61.078392,-117.518669,0.012124,0.004439,0.112748,271.690247,13.840562,1.127482,-117.518669,0.112791,0.000000
90.190002,60.995354,-117.518669,0.012128,0.004439,0.112748,271.320892,13.821745,1.127482,-117.518669,0.112791,0.000000
90.460007,60.927208,-117.474190,0.012124,0.004439,0.112748,271.017761,13.806303,1.127482,-117.474190,0.112791,0.000000
90.730003,60.873962,-117.563156,0.012120,0.004439,0.112748,270.780914,13.794237,1.127482,-117.563156,0.112791,0.000000
91.000008,60.812515,-117.563156,0.012133,0.004439,0.112748,270.507568,13.780313,1.127482,-117.563156,0.112791,0.000000
91.270004,60.746605,-117.563156,0.012124,0.004439,0.112748,270.214386,13.765377,1.127482,-117.563156,0.112791,0.000000
91.540001,60.689636,-117.563156,0.012133,0.004439,0.112748,269.960999,13.752468,1.127482,-117.563156,0.112791,0.000000
91.810005,60.629684,-117.518669,0.012120,0.004439,0.112748,269.694305,13.738883,1.127482,-117.518669,0.112791,0.000000
92.080002,60.583511,-117.563156,0.012137,0.004439,0.112748,269.488922,13.728420,1.127482,-117.563156,0.112791,0.000000
92.350006,60.527283,-117.607635,0.012128,0.004439,0.112748,269.238800,13.715678,1.127482,-117.607635,0.112791,0.000000
92.620003,60.473289,-117.652115,0.012128,0.004439,0.112748,268.998627,13.703444,1.127482,-117.652115,0.112791,0.000000
92.890007,60.411476,-117.563156,0.012120,0.004439,0.112748,268.723663,13.689436,1.127482,-117.563156,0.112791,0.000000
93.160004,60.377960,-117.607635,0.012141,0.004439,0.112748,268.574585,13.681841,1.127482,-117.607635,0.112791,0.000000
93.430008,60.332161,-117.563156,0.012128,0.004439,0.112748,268.370850,13.671463,1.127482,-117.563156,0.112791,0.000000
93.700005,60.275558,-117.652115,0.012124,0.004439,0.112748,268.119080,13.658637,1.127482,-117.652115,0.112791,0.000000
93.970001,60.231247,-117.652115,0.012133,0.004439,0.112748,267.921967,13.648596,1.127482,-117.652115,0.112791,0.000000
94.240005,60.196243,-117.607635,0.012120,0.004439,0.112748,267.766266,13.640663,1.127482,-117.607635,0.112791,0.000000
94.510002,60.137779,-117.652115,0.012141,0.004439,0.112748,267.506195,13.627416,1.127482,-117.652115,0.112791,0.000000
94.780006,60.104263,-117.652115,0.012124,0.004439,0.112748,267.357117,13.619822,1.127482,-117.652115,0.112791,0.000000
95.050003,60.070755,-117.652115,0.012137,0.004439,0.112748,267.208069,13.612228,1.127482,-117.652115,0.112791,0.000000
95.320007,60.004471,-117.652115,0.012137,0.004439,0.112748,266.913208,13.597208,1.127482,-117.652115,0.112791,0.000000
95.590004,59.985481,-117.652115,0.012146,0.004439,0.112748,266.828735,13.592904,1.127482,-117.652115,0.112791,0.000000
95.860008,59.937813,-117.696594,0.012133,0.004439,0.112748,266.616699,13.582102,1.127482,-117.696594,0.112791,0.000000
96.130005,59.900948,-117.696594,0.012124,0.004439,0.112748,266.452728,13.573750,1.127482,-117.696594,0.112791,0.000000
96.400002,59.861855,-117.785561,0.012133,0.004439,0.112748,266.278839,13.564890,1.127482,-117.785561,0.112791,0.000000
96.670006,59.820145,-117.785561,0.012128,0.004439,0.112748,266.093292,13.555439,1.127482,-117.785561,0.112791,0.000000
96.940002,59.783653,-117.652115,0.012146,0.004439,0.112748,265.930969,13.547170,1.127482,-117.652115,0.112791,0.000000
97.210007,59.747902,-117.741081,0.012133,0.004439,0.112748,265.771942,13.539068,1.127482,-117.741081,0.112791,0.000000
97.480003,59.719231,-117.785561,0.012141,0.004439,0.112748,265.644409,13.532571,1.127482,-117.785561,0.112791,0.000000
97.750008,59.672310,-117.741081,0.012137,0.004439,0.112748,265.435699,13.521938,1.127482,-117.741081,0.112791,0.000000
98.020004,59.639542,-117.785561,0.012146,0.004439,0.112748,265.289917,13.514513,1.127482,-117.785561,0.112791,0.000000
98.290001,59.613106,-117.741081,0.012150,0.004439,0.112748,265.172333,13.508523,1.127482,-117.741081,0.112791,0.000000
98.560005,59.585922,-117.741081,0.012128,0.004439,0.112748,265.051422,13.502363,1.127482,-117.741081,0.112791,0.000000
98.830002,59.548683,-117.785561,0.012137,0.004439,0.112748,264.885773,13.493924,1.127482,-117.785561,0.112791,0.000000
99.100006,59.513313,-117.830040,0.012141,0.004439,0.112748,264.728424,13.485910,1.127482,-117.830040,0.112791,0.000000
99.370003,59.489853,-117.785561,0.012146,0.004439,0.112748,264.624084,13.480594,1.127482,-117.785561,0.112791,0.000000
99.640007,59.450005,-117.785561,0.012141,0.004439,0.112748,264.446838,13.471563,1.127482,-117.785561,0.112791,0.000000
99.910004,59.420593,-117.785561,0.012141,0.004439,0.112748,264.316010,13.464899,1.127482,-117.785561,0.112791,0.000000
100.180008,59.399734,-117.830040,0.012137,0.004439,0.112748,264.223206,13.460172,1.127482,-117.830040,0.112791,0.000000
100.450005,59.358406,-117.830040,0.012141,0.004439,0.112748,264.039368,13.450808,1.127482,-117.830040,0.112791,0.000000
100.720001,59.329727,-117.830040,0.012137,0.004439,0.112748,263.911804,13.444308,1.127482,-117.830040,0.112791,0.000000
100.990005,59.313347,-117.785561,0.012137,0.004439,0.112748,263.838959,13.440597,1.127482,-117.785561,0.112791,0.000000
101.260002,59.269409,-117.830040,0.012141,0.004439,0.112748,263.643494,13.430639,1.127482,-117.830040,0.112791,0.000000
101.530006,59.237755,-117.918999,0.012133,0.004439,0.112748,263.502686,13.423467,1.127482,-117.918999,0.112791,0.000000
101.800003,59.232170,-117.874519,0.012141,0.004439,0.112748,263.477844,13.422201,1.127482,-117.874519,0.112791,0.000000
102.070007,59.202003,-117.830040,0.012154,0.004439,0.112748,263.343658,13.415365,1.127482,-117.830040,0.112791,0.000000
102.340004,59.170357,-117.874519,0.012146,0.004439,0.112748,263.202881,13.408195,1.127482,-117.874519,0.112791,0.000000
102.610008,59.146149,-117.830040,0.012146,0.004439,0.112748,263.095215,13.402709,1.127482,-117.830040,0.112791,0.000000
102.880005,59.101097,-117.874519,0.012137,0.004439,0.112748,262.894806,13.392500,1.127482,-117.874519,0.112791,0.000000
103.150002,59.089920,-117.918999,0.012150,0.004439,0.112748,262.845093,13.389968,1.127482,-117.918999,0.112791,0.000000
103.420006,59.070190,-117.963486,0.012137,0.004439,0.112748,262.757324,13.385496,1.127482,-117.963486,0.112791,0.000000
103.690002,59.036301,-117.874519,0.012141,0.004439,0.112748,262.606567,13.377817,1.127482,-117.874519,0.112791,0.000000
103.960007,59.015823,-117.963486,0.012146,0.004439,0.112748,262.515503,13.373177,1.127482,-117.963486,0.112791,0.000000
104.230003,58.994598,-117.918999,0.012137,0.004439,0.112748,262.421082,13.368367,1.127482,-117.918999,0.112791,0.000000
104.500008,58.960709,-117.963486,0.012150,0.004439,0.112748,262.270325,13.360688,1.127482,-117.963486,0.112791,0.000000
104.770004,58.940605,-117.918999,0.012146,0.004439,0.112748,262.180908,13.356133,1.127482,-117.918999,0.112791,0.000000
105.040009,58.935760,-117.918999,0.012137,0.004439,0.112748,262.159363,13.355034,1.127482,-117.918999,0.112791,0.000000
105.310005,58.895546,-117.963486,0.012141,0.004439,0.112748,261.980469,13.345922,1.127482,-117.963486,0.112791,0.000000
105.580002,58.871338,-117.963486,0.012141,0.004439,0.112748,261.872803,13.340436,1.127482,-117.963486,0.112791,0.000000
105.850006,58.867615,-118.007965,0.012158,0.004439,0.112748,261.856232,13.339592,1.127482,-118.007965,0.112791,0.000000
106.120003,58.826286,-117.963486,0.012146,0.004439,0.112748,261.672394,13.330227,1.127482,-117.963486,0.112791,0.000000
106.390007,58.808411,-117.918999,0.012146,0.004439,0.112748,261.592865,13.326177,1.127482,-117.918999,0.112791,0.000000
106.660004,58.786812,-118.052444,0.012146,0.004439,0.112748,261.496796,13.321282,1.127482,-118.052444,0.112791,0.000000
106.930008,58.764473,-118.052444,0.012146,0.004439,0.112748,261.397430,13.316220,1.127482,-118.052444,0.112791,0.000000
107.200005,58.732445,-118.052444,0.012150,0.004439,0.112748,261.254974,13.308962,1.127482,-118.052444,0.112791,0.000000
107.470009,58.711967,-117.963486,0.012150,0.004439,0.112748,261.163879,13.304321,1.127482,-117.963486,0.112791,0.000000
107.740005,58.706009,-118.007965,0.012141,0.004439,0.112748,261.137360,13.302972,1.127482,-118.007965,0.112791,0.000000
108.010002,58.681061,-118.052444,0.012137,0.004439,0.112748,261.026398,13.297318,1.127482,-118.052444,0.112791,0.000000
108.280006,58.655739,-118.096924,0.012141,0.004439,0.112748,260.913757,13.291580,1.127482,-118.096924,0.112791,0.000000
108.550003,58.646057,-118.096924,0.012150,0.004439,0.112748,260.870697,13.289387,1.127482,-118.096924,0.112791,0.000000
108.820007,58.627068,-118.007965,0.012137,0.004439,0.112748,260.786224,13.285084,1.127482,-118.007965,0.112791,0.000000
109.090004,58.602859,-118.096924,0.012150,0.004439,0.112748,260.678528,13.279597,1.127482,-118.096924,0.112791,0.000000
109.360008,58.576790,-118.096924,0.012150,0.004439,0.112748,260.562561,13.273690,1.127482,-118.096924,0.112791,0.000000
109.630005,58.559662,-118.141403,0.012154,0.004439,0.112748,260.486389,13.269810,1.127482,-118.141403,0.112791,0.000000
109.900002,58.533974,-118.052444,0.012154,0.004439,0.112748,260.372131,13.263988,1.127482,-118.052444,0.112791,0.000000
110.170006,58.519447,-118.141403,0.012154,0.004439,0.112748,260.307495,13.260696,1.127482,-118.141403,0.112791,0.000000
110.440002,58.506042,-118.096924,0.012141,0.004439,0.112748,260.247864,13.257659,1.127482,-118.096924,0.112791,0.000000
110.710007,58.476997,-118.141403,0.012150,0.004439,0.112748,260.118683,13.251077,1.127482,-118.141403,0.112791,0.000000
110.980003,58.454659,-118.141403,0.012141,0.004439,0.112748,260.019318,13.246015,1.127482,-118.141403,0.112791,0.000000
111.250008,58.457260,-118.096924,0.012141,0.004439,0.112748,260.030884,13.246605,1.127482,-118.096924,0.112791,0.000000
111.400002,58.436409,-118.141403,0.012154,0.004439,0.112748,259.938141,13.241879,1.127482,-118.141403,0.112791,0.000000