File: Data/compression 4/AutoNoheating-12-4-4-240223_02232024_164316.csv
Time (sec),S:Load (lbs),S:HL1 (DIM),S:LVDT (in),S:Position (in),Ch:Position (mm),Ch:Load (N),Ch:Stress (MPa),Ch:Strain (mm/mm),Ch:HL1 (DIM),Set Point (),Cycles ()
0.010000,0.017502,-132.330826,0.000004,-0.000000,-0.000000,0.077852,0.003966,-0.000000,-132.330826,0.000226,0.000000
0.290000,0.017502,-132.330826,0.000004,-0.000000,-0.000000,0.077852,0.003966,-0.000000,-132.330826,0.000226,0.000000
0.570000,0.064423,-132.375305,0.000004,0.000119,0.003035,0.286566,0.014598,0.030353,-132.375305,0.004024,0.000000
0.850000,0.064796,-132.241867,0.000185,0.000306,0.007762,0.288229,0.014683,0.077617,-132.241867,0.008690,0.000000
1.130000,0.060326,-132.241867,0.000358,0.000485,0.012315,0.268342,0.013670,0.123147,-132.241867,0.013355,0.000000
1.410000,0.087883,-132.330826,0.000552,0.000667,0.016937,0.390923,0.019915,0.169370,-132.330826,0.018021,0.000000
1.690000,0.056229,-132.330826,0.000746,0.000851,0.021611,0.250117,0.012742,0.216114,-132.330826,0.022687,0.000000
1.970000,0.081924,-132.375305,0.000923,0.001028,0.026112,0.364418,0.018564,0.261122,-132.375305,0.027352,0.000000
2.250000,0.040962,-132.375305,0.001117,0.001217,0.030908,0.182209,0.009282,0.309080,-132.375305,0.032018,0.000000
2.530000,0.077080,-132.375305,0.001293,0.001397,0.035496,0.342868,0.017467,0.354955,-132.375305,0.036684,0.000000
2.810000,-0.000374,-132.330826,0.001483,0.001584,0.040222,-0.001663,-0.000085,0.402219,-132.330826,0.041349,0.000000
3.090000,0.056229,-132.375305,0.001673,0.001771,0.044992,0.250117,0.012742,0.449916,-132.375305,0.046015,0.000000
3.370000,0.061073,-132.419785,0.001854,0.001954,0.049640,0.271668,0.013839,0.496400,-132.419785,0.050681,0.000000
3.650000,0.055855,-132.375305,0.002044,0.002138,0.054306,0.248455,0.012657,0.543057,-132.375305,0.055346,0.000000
3.930000,0.090858,-132.375305,0.002246,0.002319,0.058893,0.404159,0.020589,0.588933,-132.375305,0.060012,0.000000
4.210000,0.044685,-132.464279,0.002419,0.002503,0.063568,0.198770,0.010126,0.635677,-132.464279,0.064678,0.000000
4.490000,0.066658,-132.419785,0.002613,0.002678,0.068034,0.296510,0.015105,0.680339,-132.419785,0.069343,0.000000
4.770000,0.012291,-132.419785,0.002802,0.002866,0.072786,0.054673,0.002785,0.727864,-132.419785,0.074009,0.000000
5.050000,0.083038,-132.419785,0.002979,0.003052,0.077513,0.369373,0.018817,0.775128,-132.419785,0.078675,0.000000
5.330000,0.064049,-132.419785,0.003182,0.003236,0.082204,0.284903,0.014514,0.822043,-132.419785,0.083323,0.000000
5.610000,0.072983,-132.464279,0.003372,0.003423,0.086957,0.324644,0.016538,0.869568,-132.464279,0.087989,0.000000
5.890000,0.089371,-132.508759,0.003557,0.003609,0.091657,0.397541,0.020252,0.916571,-132.508759,0.092654,0.000000
6.170000,0.081177,-132.508759,0.003747,0.003793,0.096331,0.361092,0.018395,0.963314,-132.508759,0.097320,0.000000
6.450000,0.073730,-132.464279,0.003932,0.003975,0.100971,0.327969,0.016708,1.009712,-132.464279,0.101986,0.000000
6.730000,0.049896,-132.508759,0.004113,0.004151,0.105446,0.221950,0.011307,1.054460,-132.508759,0.106652,0.000000
7.010000,0.061073,-132.464279,0.004286,0.004336,0.110146,0.271668,0.013839,1.101463,-132.464279,0.111317,0.000000
7.290000,0.015266,-132.508759,0.004497,0.004523,0.114881,0.067908,0.003459,1.148814,-132.508759,0.115983,0.000000
7.570000,0.099800,-132.597717,0.004674,0.004703,0.119460,0.443933,0.022615,1.194604,-132.597717,0.120648,0.000000
7.850000,0.067024,-132.553238,0.004872,0.004895,0.124325,0.298139,0.015188,1.243255,-132.553238,0.125314,0.000000
8.130000,0.066658,-132.553238,0.005062,0.005076,0.128931,0.296510,0.015105,1.289306,-132.553238,0.129980,0.000000
8.410001,0.084526,-132.553238,0.005256,0.005262,0.133665,0.375991,0.019154,1.336655,-132.553238,0.134646,0.000000
8.690001,0.075218,-132.553238,0.005441,0.005441,0.138192,0.334587,0.017045,1.381924,-132.553238,0.139311,0.000000
8.970000,0.053993,-132.642197,0.005618,0.005625,0.142875,0.240174,0.012235,1.428754,-132.642197,0.143977,0.000000
9.250000,0.027931,-132.553238,0.005795,0.005806,0.147472,0.124244,0.006329,1.474718,-132.553238,0.148642,0.000000
9.530001,0.098679,-132.597717,0.005971,0.005989,0.152111,0.438944,0.022361,1.521113,-132.597717,0.153308,0.000000
9.810000,0.056976,-132.553238,0.006178,0.006177,0.156898,0.253443,0.012911,1.568985,-132.553238,0.157974,0.000000
10.090000,0.099052,-132.597717,0.006381,0.006358,0.161495,0.440607,0.022446,1.614948,-132.597717,0.162640,0.000000
10.370001,0.068520,-132.642197,0.006558,0.006544,0.166213,0.304790,0.015527,1.662125,-132.642197,0.167305,0.000000
10.650001,0.075592,-132.642197,0.006726,0.006726,0.170844,0.336250,0.017129,1.708435,-132.642197,0.171953,0.000000
10.930000,0.077454,-132.597717,0.006942,0.006917,0.175683,0.344531,0.017551,1.756827,-132.597717,0.176619,0.000000
11.210001,0.074104,-132.642197,0.007110,0.007091,0.180123,0.329632,0.016792,1.801228,-132.642197,0.181285,0.000000
11.490001,0.061440,-132.686676,0.007304,0.007284,0.185023,0.273297,0.013922,1.850227,-132.686676,0.185951,0.000000
11.770000,0.074104,-132.686676,0.007489,0.007463,0.189550,0.329632,0.016792,1.895496,-132.686676,0.190616,0.000000
12.050000,0.115807,-132.731155,0.007675,0.007643,0.194120,0.515133,0.026242,1.941199,-132.731155,0.195282,0.000000
12.330001,0.061073,-132.642197,0.007869,0.007831,0.198898,0.271668,0.013839,1.988983,-132.642197,0.199948,0.000000
12.610001,0.108734,-132.686676,0.008041,0.008011,0.203477,0.483674,0.024640,2.034773,-132.686676,0.204613,0.000000
12.890000,0.060326,-132.686676,0.008239,0.008198,0.208230,0.268342,0.013670,2.082296,-132.686676,0.209279,0.000000
13.170001,0.071869,-132.731155,0.008412,0.008380,0.212852,0.319689,0.016286,2.128519,-132.731155,0.213945,0.000000
13.450001,0.068886,-132.775635,0.008601,0.008568,0.217630,0.306419,0.015610,2.176303,-132.775635,0.218610,0.000000
13.730000,0.089371,-132.686676,0.008791,0.008750,0.222244,0.397541,0.020252,2.222439,-132.686676,0.223276,0.000000
14.010000,0.093468,-132.731155,0.008994,0.008934,0.226918,0.415765,0.021180,2.269183,-132.731155,0.227942,0.000000
14.290001,0.075966,-132.775635,0.009175,0.009116,0.231549,0.337913,0.017214,2.315495,-132.775635,0.232607,0.000000
14.570001,0.091980,-132.775635,0.009339,0.009296,0.236111,0.409147,0.020843,2.361110,-132.775635,0.237273,0.000000
14.850000,0.058090,-132.731155,0.009533,0.009483,0.240872,0.258398,0.013163,2.408720,-132.731155,0.241939,0.000000
15.130001,0.109482,-132.775635,0.009727,0.009663,0.245434,0.486999,0.024809,2.454336,-132.775635,0.246604,0.000000
15.410001,0.031281,-132.775635,0.009912,0.009850,0.250186,0.139143,0.007088,2.501859,-132.775635,0.251270,0.000000
15.690001,0.077827,-132.775635,0.010111,0.010029,0.254739,0.346194,0.017636,2.547388,-132.775635,0.255936,0.000000
15.970001,0.094208,-132.820114,0.010296,0.010220,0.259587,0.419057,0.021348,2.595868,-132.820114,0.260584,0.000000
16.250000,0.099426,-132.775635,0.010464,0.010402,0.264200,0.442270,0.022530,2.642002,-132.775635,0.265250,0.000000
16.530001,0.115807,-132.775635,0.010645,0.010586,0.268892,0.515133,0.026242,2.688920,-132.775635,0.269915,0.000000
16.810001,0.097565,-132.775635,0.010852,0.010771,0.273575,0.433989,0.022108,2.735750,-132.775635,0.274581,0.000000
17.090000,0.082298,-132.864594,0.011025,0.010949,0.278110,0.366081,0.018649,2.781105,-132.864594,0.279247,0.000000
17.370001,0.051018,-132.864594,0.011219,0.011131,0.282733,0.226938,0.011561,2.827330,-132.864594,0.283912,0.000000
17.650002,0.100540,-132.909088,0.011400,0.011313,0.287338,0.447225,0.022783,2.873381,-132.909088,0.288578,0.000000
17.930000,0.040215,-132.775635,0.011594,0.011505,0.292238,0.178883,0.009113,2.922376,-132.775635,0.293244,0.000000
18.210001,0.087883,-132.820114,0.011766,0.011686,0.296825,0.390923,0.019915,2.968253,-132.820114,0.297909,0.000000
18.490002,0.110596,-132.909088,0.011982,0.011876,0.301647,0.491954,0.025061,3.016472,-132.909088,0.302575,0.000000
18.770000,0.087135,-132.909088,0.012150,0.012055,0.306200,0.387597,0.019745,3.062001,-132.909088,0.307241,0.000000
19.050001,0.098305,-132.953568,0.012335,0.012241,0.310926,0.437281,0.022276,3.109263,-132.953568,0.311907,0.000000
19.330002,0.074104,-132.909088,0.012516,0.012418,0.315427,0.329632,0.016792,3.154273,-132.909088,0.316572,0.000000
19.610001,0.079315,-132.864594,0.012702,0.012595,0.319911,0.352812,0.017973,3.199109,-132.864594,0.321238,0.000000
19.890001,0.041336,-132.864594,0.012891,0.012783,0.324698,0.183872,0.009367,3.246980,-132.864594,0.325903,0.000000
20.170000,0.129585,-132.953568,0.013064,0.012966,0.329329,0.576424,0.029364,3.293288,-132.953568,0.330569,0.000000
20.450001,0.070755,-132.998047,0.013262,0.013157,0.334177,0.314734,0.016033,3.341769,-132.998047,0.335235,0.000000
20.730001,0.100166,-132.953568,0.013448,0.013340,0.338843,0.445562,0.022698,3.388425,-132.953568,0.339900,0.000000
21.010000,0.113205,-132.909088,0.013655,0.013525,0.343543,0.503561,0.025653,3.435430,-132.909088,0.344549,0.000000
21.290001,0.090118,-132.998047,0.013844,0.013708,0.348174,0.400867,0.020421,3.481738,-132.998047,0.349215,0.000000
21.570002,0.094955,-132.998047,0.014008,0.013886,0.352692,0.422383,0.021517,3.526922,-132.998047,0.353880,0.000000
21.850000,0.072243,-132.998047,0.014181,0.014069,0.357358,0.321352,0.016370,3.573579,-132.998047,0.358546,0.000000
22.130001,0.090485,-132.998047,0.014375,0.014252,0.361997,0.402496,0.020504,3.619974,-132.998047,0.363212,0.000000
22.410002,0.091606,-132.998047,0.014573,0.014438,0.366724,0.407484,0.020758,3.667236,-132.998047,0.367877,0.000000
22.690001,0.133682,-132.953568,0.014754,0.014622,0.371398,0.594648,0.030293,3.713979,-132.953568,0.372543,0.000000
22.970001,0.084900,-132.998047,0.014944,0.014808,0.376133,0.377654,0.019239,3.761332,-132.998047,0.377209,0.000000
23.250002,0.126236,-133.042526,0.015120,0.014991,0.380781,0.561526,0.028605,3.807814,-133.042526,0.381874,0.000000
23.530001,0.137405,-132.953568,0.015310,0.015180,0.385569,0.611210,0.031137,3.855686,-132.953568,0.386540,0.000000
23.810001,0.177254,-132.998047,0.015496,0.015355,0.390009,0.788464,0.040166,3.900086,-132.998047,0.391205,0.000000
24.090002,0.259918,-133.042526,0.015681,0.015541,0.394735,1.156174,0.058898,3.947352,-133.042526,0.395871,0.000000
24.370001,0.487434,-133.042526,0.015853,0.015723,0.399375,2.168216,0.110454,3.993747,-133.042526,0.400537,0.000000
24.650002,0.594307,-133.087006,0.015910,0.000004,0.000112,2.643609,0.134672,0.001124,-133.087006,0.000329,0.000000
24.930000,0.573456,-133.087006,0.015897,0.000004,0.000112,2.550859,0.129947,0.001124,-133.087006,0.000329,0.000000
25.210001,0.574944,-133.042526,0.015905,0.000005,0.000121,2.557477,0.130284,0.001211,-133.042526,0.000754,0.000000
25.490002,0.552231,-133.131485,0.015905,0.000005,0.000121,2.456445,0.125137,0.001211,-133.131485,0.001223,0.000000
25.770000,0.691872,-133.175964,0.015918,0.000032,0.000824,3.077599,0.156780,0.008236,-133.175964,0.001691,0.000000
26.050001,0.780869,-133.087006,0.015935,0.000052,0.001309,3.473477,0.176947,0.013092,-133.087006,0.002159,0.000000
26.330002,0.844543,-133.087006,0.015953,0.000069,0.001752,3.756717,0.191376,0.017516,-133.087006,0.002627,0.000000
26.610001,0.925720,-133.131485,0.015970,0.000087,0.002220,4.117809,0.209771,0.022198,-133.131485,0.003087,0.000000
26.890001,1.034454,-133.131485,0.015983,0.000108,0.002740,4.601483,0.234411,0.027403,-133.131485,0.003556,0.000000
27.170002,1.134621,-133.175964,0.015991,0.000125,0.003183,5.047045,0.257109,0.031827,-133.175964,0.004024,0.000000
27.450001,1.203880,-133.175964,0.016017,0.000136,0.003451,5.355127,0.272803,0.034514,-133.175964,0.004492,0.000000
27.730001,1.362885,-133.175964,0.016035,0.000164,0.004171,6.062413,0.308834,0.041713,-133.175964,0.004960,0.000000
28.010002,1.425812,-133.131485,0.016060,0.000180,0.004579,6.342328,0.323094,0.045790,-133.131485,0.005429,0.000000
28.290001,1.505501,-133.175964,0.016082,0.000198,0.005038,6.696802,0.341151,0.050385,-133.175964,0.005888,0.000000
28.570002,1.610512,-133.220444,0.016099,0.000216,0.005481,7.163914,0.364947,0.054805,-133.220444,0.006357,0.000000
28.850002,1.719246,-133.175964,0.016104,0.000236,0.006001,7.647588,0.389587,0.060010,-133.175964,0.006825,0.000000
29.130001,1.834679,-133.131485,0.016129,0.000252,0.006409,8.161058,0.415744,0.064086,-133.131485,0.007293,0.000000
29.410002,1.943039,-133.220444,0.016151,0.000269,0.006825,8.643069,0.440299,0.068249,-133.220444,0.007762,0.000000
29.690001,2.054382,-133.175964,0.016173,0.000288,0.007311,9.138349,0.465530,0.073105,-133.175964,0.008221,0.000000
29.970001,2.178009,-133.220444,0.016181,0.000313,0.007944,9.688268,0.493544,0.079437,-133.220444,0.008689,0.000000
30.250002,2.181732,-133.264923,0.016198,0.000328,0.008325,9.704829,0.494388,0.083253,-133.264923,0.009158,0.000000
30.530001,2.251740,-133.309418,0.016203,0.000345,0.008759,10.016237,0.510251,0.087586,-133.309418,0.009626,0.000000
30.810001,2.368660,-133.220444,0.016233,0.000365,0.009270,10.536325,0.536746,0.092703,-133.220444,0.010094,0.000000
31.090002,2.466599,-133.264923,0.016246,0.000383,0.009722,10.971978,0.558939,0.097215,-133.264923,0.010563,0.000000
31.370001,2.508675,-133.309418,0.016259,0.000395,0.010042,11.159142,0.568474,0.100425,-133.309418,0.011022,0.000000
31.650002,2.649803,-133.264923,0.016280,0.000419,0.010632,11.786913,0.600454,0.106321,-133.264923,0.011491,0.000000
31.930002,2.734329,-133.264923,0.016302,0.000439,0.011161,12.162904,0.619608,0.111609,-133.264923,0.011959,0.000000
32.210003,2.767471,-133.264923,0.016306,0.000458,0.011621,12.310328,0.627118,0.116208,-133.264923,0.012427,0.000000
32.490002,2.806946,-133.353897,0.016336,0.000474,0.012028,12.485918,0.636063,0.120284,-133.353897,0.012896,0.000000
32.770000,2.902275,-133.309418,0.016349,0.000492,0.012488,12.909965,0.657665,0.124879,-133.309418,0.013355,0.000000
33.050003,2.985680,-133.353897,0.016358,0.000511,0.012973,13.280966,0.676565,0.129735,-133.353897,0.013824,0.000000
33.330002,3.010635,-133.398376,0.016379,0.000524,0.013303,13.391975,0.682220,0.133031,-133.398376,0.014292,0.000000
33.610001,3.178947,-133.309418,0.016397,0.000546,0.013875,14.140664,0.720360,0.138754,-133.309418,0.014760,0.000000
33.890003,3.235916,-133.353897,0.016414,0.000566,0.014387,14.394073,0.733269,0.143871,-133.353897,0.015228,0.000000
34.170002,3.284325,-133.398376,0.016431,0.000584,0.014829,14.609406,0.744239,0.148292,-133.398376,0.015688,0.000000
34.450001,3.349121,-133.442856,0.016440,0.000603,0.015306,14.897635,0.758922,0.153065,-133.442856,0.016156,0.000000
34.730003,3.458969,-133.353897,0.016470,0.000623,0.015827,15.386263,0.783814,0.158265,-133.353897,0.016624,0.000000
35.010002,3.467903,-133.353897,0.016479,0.000637,0.016174,15.426003,0.785838,0.161736,-133.353897,0.017093,0.000000
35.290001,3.496574,-133.353897,0.016496,0.000652,0.016555,15.553539,0.792335,0.165551,-133.353897,0.017561,0.000000
35.570004,3.687981,-133.398376,0.016522,0.000679,0.017249,16.404957,0.835708,0.172489,-133.398376,0.018029,0.000000
35.850002,3.667870,-133.442856,0.016526,0.000692,0.017587,16.315498,0.831151,0.175873,-133.442856,0.018489,0.000000
36.130001,3.713669,-133.398376,0.016548,0.000713,0.018116,16.519224,0.841529,0.181160,-133.398376,0.018957,0.000000
36.410000,3.731918,-133.353897,0.016565,0.000729,0.018515,16.600401,0.845665,0.185149,-133.353897,0.019426,0.000000
36.690002,3.846611,-133.442856,0.016582,0.000747,0.018984,17.110580,0.871655,0.189835,-133.442856,0.019894,0.000000
36.970001,3.853683,-133.442856,0.016599,0.000763,0.019382,17.142040,0.873257,0.193824,-133.442856,0.020362,0.000000
37.250000,3.914749,-133.487335,0.016604,0.000783,0.019877,17.413673,0.887095,0.198768,-133.487335,0.020822,0.000000
37.530003,4.095352,-133.487335,0.016630,0.000807,0.020510,18.217037,0.928020,0.205096,-133.487335,0.021290,0.000000
37.810001,4.089020,-133.398376,0.016647,0.000825,0.020961,18.188868,0.926585,0.209607,-133.398376,0.021759,0.000000
38.090000,4.068916,-133.487335,0.016660,0.000841,0.021368,18.099443,0.922030,0.213684,-133.487335,0.022227,0.000000
38.370003,4.115089,-133.531815,0.016677,0.000858,0.021785,18.304832,0.932493,0.217847,-133.531815,0.022695,0.000000
38.650002,4.191795,-133.531815,0.016677,0.000875,0.022227,18.646036,0.949874,0.222268,-133.531815,0.023164,0.000000
38.930000,4.235741,-133.487335,0.016694,0.000894,0.022695,18.841515,0.959833,0.226950,-133.487335,0.023623,0.000000
39.210003,4.236481,-133.487335,0.016720,0.000908,0.023051,18.844807,0.960000,0.230508,-133.487335,0.024091,0.000000
39.490002,4.382080,-133.531815,0.016724,0.000932,0.023675,19.492466,0.992994,0.236753,-133.531815,0.024560,0.000000
39.770000,4.348190,-133.576294,0.016746,0.000950,0.024135,19.341717,0.985314,0.241348,-133.576294,0.025028,0.000000
40.050003,4.281166,-133.531815,0.016759,0.000966,0.024534,19.043577,0.970126,0.245337,-133.531815,0.025496,0.000000
40.330002,4.257706,-133.531815,0.016763,0.000980,0.024889,18.939220,0.964810,0.248891,-133.531815,0.025956,0.000000
40.610001,4.443893,-133.531815,0.016789,0.001002,0.025453,19.767426,1.007001,0.254530,-133.531815,0.026424,0.000000
40.890003,4.428253,-133.576294,0.016798,0.001020,0.025913,19.697853,1.003457,0.259125,-133.576294,0.026892,0.000000
41.170002,4.427505,-133.576294,0.016798,0.001035,0.026285,19.694529,1.003287,0.262853,-133.576294,0.027361,0.000000
41.450001,4.550018,-133.620773,0.016836,0.001059,0.026892,20.239492,1.031049,0.268924,-133.620773,0.027829,0.000000
41.730003,4.499374,-133.531815,0.016849,0.001078,0.027369,20.014217,1.019573,0.273693,-133.531815,0.028289,0.000000
42.010002,4.478897,-133.576294,0.016854,0.001095,0.027820,19.923130,1.014933,0.278205,-133.576294,0.028757,0.000000
42.290001,4.374260,-133.576294,0.016862,0.001107,0.028107,19.457680,0.991221,0.281066,-133.576294,0.029225,0.000000
42.570004,4.577576,-133.620773,0.016875,0.001129,0.028670,20.362074,1.037293,0.286702,-133.620773,0.029694,0.000000
42.850002,4.548531,-133.620773,0.016884,0.001147,0.029139,20.232874,1.030712,0.291388,-133.620773,0.030162,0.000000
43.130001,4.624870,-133.665253,0.016914,0.001168,0.029659,20.572451,1.048011,0.296588,-133.665253,0.030630,0.000000
43.410004,4.761902,-133.620773,0.016923,0.001192,0.030275,21.181997,1.079062,0.302746,-133.620773,0.031090,0.000000
43.690002,4.639015,-133.665253,0.016957,0.001208,0.030682,20.635370,1.051216,0.306823,-133.665253,0.031558,0.000000
43.970001,4.552254,-133.665253,0.016936,0.001224,0.031081,20.249435,1.031556,0.310812,-133.665253,0.032027,0.000000
44.250004,4.598427,-133.620773,0.016974,0.001241,0.031515,20.454824,1.042018,0.315149,-133.620773,0.032495,0.000000
44.530003,4.624496,-133.709732,0.016974,0.001257,0.031940,20.570787,1.047926,0.319396,-133.709732,0.032963,0.000000
44.810001,4.650185,-133.665253,0.016992,0.001276,0.032417,20.685055,1.053747,0.324169,-133.665253,0.033423,0.000000
45.090004,4.674393,-133.709732,0.017000,0.001293,0.032833,20.792738,1.059232,0.328328,-133.709732,0.033891,0.000000
45.370003,4.863182,-133.709732,0.017018,0.001323,0.033605,21.632515,1.102013,0.336049,-133.709732,0.034359,0.000000
45.650002,4.717216,-133.665253,0.017043,0.001337,0.033960,20.983227,1.068936,0.339603,-133.665253,0.034827,0.000000
45.930000,4.663963,-133.665253,0.017052,0.001357,0.034472,20.746346,1.056869,0.344721,-133.665253,0.035296,0.000000
46.210003,4.666946,-133.665253,0.017069,0.001371,0.034819,20.759615,1.057545,0.348188,-133.665253,0.035764,0.000000
46.490002,4.813286,-133.798706,0.017082,0.001391,0.035330,21.410564,1.090706,0.353305,-133.798706,0.036224,0.000000
46.770000,4.727272,-133.798706,0.017087,0.001404,0.035660,21.027956,1.071215,0.356601,-133.798706,0.036692,0.000000
47.050003,4.855736,-133.754227,0.017095,0.001426,0.036224,21.599392,1.100325,0.362237,-133.754227,0.037160,0.000000
47.330002,4.898933,-133.754227,0.017112,0.001447,0.036753,21.791544,1.110114,0.367528,-133.754227,0.037629,0.000000
47.610001,4.875847,-133.798706,0.017130,0.001463,0.037152,21.688850,1.104883,0.371518,-133.798706,0.038097,0.000000
47.890003,4.884781,-133.798706,0.017143,0.001482,0.037637,21.728590,1.106907,0.376374,-133.798706,0.038557,0.000000
48.170002,4.922394,-133.843185,0.017160,0.001501,0.038123,21.895901,1.115430,0.381230,-133.843185,0.039025,0.000000
48.450001,4.983833,-133.798706,0.017168,0.001521,0.038635,22.169197,1.129353,0.386347,-133.798706,0.039493,0.000000
48.730003,4.916809,-133.798706,0.017190,0.001534,0.038964,21.871059,1.114165,0.389644,-133.798706,0.039962,0.000000
49.010002,5.066498,-133.798706,0.017207,0.001559,0.039597,22.536907,1.148085,0.395972,-133.798706,0.040430,0.000000
49.290001,4.977135,-133.843185,0.017229,0.001575,0.040005,22.139400,1.127835,0.400048,-133.843185,0.040898,0.000000
49.570004,5.035591,-133.887665,0.017225,0.001595,0.040517,22.399427,1.141081,0.405165,-133.887665,0.041358,0.000000
49.850002,5.023674,-133.843185,0.017237,0.001611,0.040915,22.346418,1.138381,0.409155,-133.843185,0.041826,0.000000
50.130001,5.032990,-133.798706,0.017268,0.001628,0.041349,22.387856,1.140492,0.413492,-133.798706,0.042294,0.000000
50.410004,5.148796,-133.843185,0.017272,0.001649,0.041887,22.902988,1.166734,0.418867,-133.843185,0.042763,0.000000
50.690002,5.180443,-133.887665,0.017298,0.001667,0.042347,23.043760,1.173905,0.423465,-133.887665,0.043231,0.000000
50.970001,5.209488,-133.932144,0.017306,0.001683,0.042754,23.172960,1.180487,0.427542,-133.932144,0.043691,0.000000
51.250004,5.339447,-133.887665,0.017328,0.001708,0.043387,23.751047,1.209936,0.433870,-133.887665,0.044159,0.000000
51.530003,5.280617,-133.887665,0.017332,0.001725,0.043821,23.489357,1.196605,0.438208,-133.887665,0.044627,0.000000
51.810001,5.265717,-133.932144,0.017345,0.001742,0.044237,23.423077,1.193228,0.442371,-133.932144,0.045096,0.000000
52.090004,5.341682,-133.932144,0.017367,0.001760,0.044714,23.760990,1.210443,0.447140,-133.932144,0.045564,0.000000
52.370003,5.394188,-133.976624,0.017371,0.001778,0.045173,23.994547,1.222340,0.451735,-133.976624,0.046024,0.000000
52.650002,5.377060,-133.932144,0.017388,0.001794,0.045564,23.918358,1.218459,0.455637,-133.932144,0.046492,0.000000
52.930004,5.537178,-133.887665,0.017419,0.001816,0.046128,24.630598,1.254743,0.461277,-133.887665,0.046960,0.000000
53.210003,5.550583,-133.932144,0.017427,0.001835,0.046613,24.690226,1.257780,0.466133,-133.932144,0.047429,0.000000
53.490002,5.541649,-133.976624,0.017444,0.001854,0.047090,24.650486,1.255756,0.470901,-133.976624,0.047897,0.000000
53.770004,5.488029,-133.976624,0.017449,0.001869,0.047463,24.411974,1.243605,0.474630,-133.976624,0.048365,0.000000
54.050003,5.641068,-133.932144,0.017462,0.001889,0.047983,25.092722,1.278284,0.479834,-133.932144,0.048825,0.000000
54.330002,5.686127,-133.976624,0.017483,0.001907,0.048443,25.293156,1.288495,0.484429,-133.976624,0.049293,0.000000
54.610004,5.645538,-134.021103,0.017500,0.001921,0.048799,25.112608,1.279297,0.487987,-134.021103,0.049761,0.000000
54.890003,5.880882,-133.976624,0.017500,0.001944,0.049388,26.159472,1.332627,0.493883,-133.976624,0.050230,0.000000
55.170002,5.892426,-133.976624,0.017544,0.001964,0.049874,26.210817,1.335243,0.498739,-133.976624,0.050698,0.000000
55.450001,5.859657,-133.976624,0.017539,0.001980,0.050299,26.065058,1.327817,0.502990,-133.976624,0.051157,0.000000
55.730003,5.898010,-134.021103,0.017552,0.001997,0.050732,26.235661,1.336508,0.507324,-134.021103,0.051626,0.000000
56.010002,6.067062,-134.021103,0.017574,0.002020,0.051296,26.987640,1.374816,0.512963,-134.021103,0.052094,0.000000
56.290001,5.985519,-134.065582,0.017578,0.002035,0.051678,26.624920,1.356338,0.516778,-134.065582,0.052562,0.000000
56.570004,6.067436,-134.021103,0.017608,0.002050,0.052077,26.989304,1.374901,0.520768,-134.021103,0.053031,0.000000
56.850002,6.291603,-133.976624,0.017625,0.002075,0.052710,27.986448,1.425698,0.527100,-133.976624,0.053499,0.000000
57.130001,6.209312,-134.021103,0.017630,0.002090,0.053091,27.620401,1.407050,0.530915,-134.021103,0.053959,0.000000
57.410004,6.273735,-134.065582,0.017656,0.002110,0.053586,27.906967,1.421649,0.535858,-134.065582,0.054427,0.000000
57.690002,6.261070,-134.065582,0.017651,0.002125,0.053985,27.850632,1.418779,0.539847,-134.065582,0.054895,0.000000
57.970001,6.392891,-134.154541,0.017682,0.002145,0.054479,28.436998,1.448650,0.544790,-134.154541,0.055364,0.000000
58.250004,6.453590,-134.065582,0.017690,0.002161,0.054895,28.707005,1.462404,0.548954,-134.065582,0.055832,0.000000
58.530003,6.573868,-134.154541,0.017707,0.002180,0.055372,29.242023,1.489660,0.553723,-134.154541,0.056292,0.000000
58.810001,6.709778,-134.199036,0.017716,0.002201,0.055901,29.846582,1.520457,0.559014,-134.199036,0.056760,0.000000
59.090004,6.747017,-134.110062,0.017733,0.002221,0.056413,30.012230,1.528896,0.564127,-134.110062,0.057228,0.000000
59.370003,6.730263,-134.154541,0.017746,0.002238,0.056838,29.937704,1.525099,0.568378,-134.154541,0.057696,0.000000
59.650002,6.788727,-134.065582,0.017755,0.002255,0.057289,30.197765,1.538347,0.572889,-134.065582,0.058165,0.000000
59.930004,6.950333,-134.154541,0.017772,0.002273,0.057740,30.916624,1.574968,0.577397,-134.154541,0.058624,0.000000
60.210003,7.018852,-134.199036,0.017789,0.002290,0.058173,31.221415,1.590495,0.581735,-134.199036,0.059092,0.000000
60.490002,7.051987,-134.199036,0.017802,0.002305,0.058555,31.368803,1.598003,0.585550,-134.199036,0.059561,0.000000
60.770004,7.198334,-134.199036,0.017820,0.002324,0.059041,32.019787,1.631166,0.590406,-134.199036,0.060029,0.000000
61.050003,7.348030,-134.110062,0.017845,0.002347,0.059613,32.685669,1.665087,0.596129,-134.110062,0.060497,0.000000
61.330002,7.282860,-134.199036,0.017858,0.002364,0.060038,32.395779,1.650320,0.600379,-134.199036,0.060966,0.000000
61.610004,7.247856,-134.199036,0.017858,0.002377,0.060385,32.240074,1.642388,0.603846,-134.199036,0.061425,0.000000
61.890003,7.514107,-134.243515,0.017876,0.002397,0.060896,33.424416,1.702721,0.608963,-134.243515,0.061894,0.000000
62.170002,7.542778,-134.199036,0.017888,0.002413,0.061295,33.551952,1.709218,0.612952,-134.199036,0.062362,0.000000
62.450005,7.692841,-134.199036,0.017910,0.002432,0.061764,34.219463,1.743223,0.617638,-134.199036,0.062830,0.000000
62.730003,8.056282,-134.243515,0.017932,0.002455,0.062353,35.836132,1.825580,0.623535,-134.243515,0.063299,0.000000
63.010002,8.097610,-134.287994,0.017940,0.002475,0.062874,36.019970,1.834945,0.628735,-134.287994,0.063758,0.000000
63.290005,8.014572,-134.199036,0.017953,0.002492,0.063290,35.650597,1.816128,0.632899,-134.199036,0.064227,0.000000
63.570004,7.977333,-134.243515,0.017966,0.002505,0.063620,35.484951,1.807690,0.636195,-134.243515,0.064695,0.000000
63.850002,8.268532,-134.243515,0.017988,0.002527,0.064183,36.780266,1.873676,0.641831,-134.243515,0.065163,0.000000
64.130005,8.508713,-134.287994,0.018009,0.002544,0.064626,37.848644,1.928102,0.646256,-134.287994,0.065632,0.000000
64.410004,8.681496,-134.376953,0.018018,0.002563,0.065111,38.617222,1.967255,0.651112,-134.376953,0.066100,0.000000
64.690002,9.003593,-134.287994,0.018026,0.002587,0.065701,40.049984,2.040243,0.657009,-134.287994,0.066559,0.000000
64.970001,8.972313,-134.332474,0.018057,0.002603,0.066108,39.910843,2.033155,0.661085,-134.332474,0.067028,0.000000
65.250000,9.017746,-134.332474,0.018061,0.002619,0.066525,40.112938,2.043450,0.665248,-134.332474,0.067496,0.000000
65.530006,9.248619,-134.376953,0.018083,0.002638,0.066993,41.139912,2.095767,0.669930,-134.376953,0.067964,0.000000
65.810005,9.310799,-134.376953,0.018091,0.002655,0.067444,41.416500,2.109857,0.674438,-134.376953,0.068433,0.000000
66.090004,9.482094,-134.332474,0.018100,0.002671,0.067843,42.178459,2.148673,0.678427,-134.332474,0.068892,0.000000
66.370003,9.696579,-134.287994,0.018126,0.002688,0.068276,43.132538,2.197276,0.682765,-134.287994,0.069360,0.000000
66.650002,10.478188,-134.376953,0.018147,0.002720,0.069083,46.609306,2.374391,0.690830,-134.376953,0.069829,0.000000
66.930000,10.260727,-134.421432,0.018160,0.002735,0.069473,45.641994,2.325114,0.694733,-134.421432,0.070297,0.000000
67.210007,10.330727,-134.376953,0.018173,0.002752,0.069890,45.953365,2.340976,0.698896,-134.376953,0.070765,0.000000
67.490005,10.458450,-134.376953,0.018199,0.002768,0.070306,46.521511,2.369919,0.703059,-134.376953,0.071225,0.000000
67.770004,10.842743,-134.332474,0.018203,0.002788,0.070809,48.230930,2.457000,0.708090,-134.332474,0.071693,0.000000
68.050003,11.000626,-134.376953,0.018229,0.002802,0.071182,48.933228,2.492777,0.711818,-134.376953,0.072162,0.000000
68.330002,11.038239,-134.465912,0.018212,0.002816,0.071537,49.100536,2.501301,0.715372,-134.465912,0.072630,0.000000
68.610001,11.780006,-134.465912,0.018242,0.002844,0.072240,52.400085,2.669388,0.722396,-134.465912,0.073098,0.000000
68.890007,11.925972,-134.376953,0.018264,0.002861,0.072665,53.049374,2.702464,0.726647,-134.376953,0.073567,0.000000
69.170006,12.011246,-134.421432,0.018281,0.002877,0.073072,53.428688,2.721787,0.730723,-134.421432,0.074026,0.000000
69.450005,12.439476,-134.465912,0.018294,0.002897,0.073593,55.333553,2.818825,0.735927,-134.465912,0.074495,0.000000
69.730003,12.847969,-134.510391,0.018307,0.002919,0.074130,57.150620,2.911391,0.741302,-134.510391,0.074963,0.000000
70.010002,12.768654,-134.421432,0.018315,0.002931,0.074460,56.797810,2.893418,0.744599,-134.421432,0.075431,0.000000
70.290001,13.518982,-134.510391,0.018324,0.002955,0.075067,60.135433,3.063445,0.750670,-134.510391,0.075899,0.000000
70.570000,13.639259,-134.465912,0.018350,0.002972,0.075483,60.670456,3.090700,0.754833,-134.465912,0.076359,0.000000
70.850006,13.929710,-134.510391,0.018363,0.002992,0.075986,61.962448,3.156518,0.759863,-134.510391,0.076827,0.000000
71.130005,14.107704,-134.599365,0.018384,0.003008,0.076394,62.754204,3.196851,0.763936,-134.599365,0.077296,0.000000
71.410004,14.467041,-134.510391,0.018393,0.003024,0.076810,64.352615,3.278278,0.768099,-134.510391,0.077764,0.000000
71.690002,15.036026,-134.510391,0.018427,0.003046,0.077356,66.883583,3.407212,0.773564,-134.510391,0.078232,0.000000
71.970001,15.223335,-134.554871,0.018440,0.003060,0.077712,67.716774,3.449657,0.777118,-134.554871,0.078700,0.000000
72.250000,15.799767,-134.554871,0.018440,0.003079,0.078206,70.280869,3.580278,0.782062,-134.554871,0.079160,0.000000
72.530006,16.480461,-134.554871,0.018445,0.003102,0.078796,73.308754,3.734526,0.787958,-134.554871,0.079629,0.000000
72.810005,16.815224,-134.554871,0.018471,0.003123,0.079316,74.797852,3.810384,0.793163,-134.554871,0.080097,0.000000
73.090004,16.851341,-134.554871,0.018475,0.003134,0.079602,74.958511,3.818568,0.796024,-134.554871,0.080565,0.000000
73.370003,17.600555,-134.599365,0.018501,0.003156,0.080175,78.291183,3.988343,0.801747,-134.599365,0.081033,0.000000
73.650002,17.901062,-134.554871,0.018501,0.003174,0.080608,79.627899,4.056438,0.806084,-134.554871,0.081493,0.000000
73.930000,18.121506,-134.599365,0.018527,0.003187,0.080955,80.608482,4.106392,0.809555,-134.599365,0.081961,0.000000
74.210007,19.232666,-134.554871,0.018535,0.003212,0.081580,85.551170,4.358184,0.815796,-134.554871,0.082430,0.000000
74.490005,19.784523,-134.554871,0.018561,0.003231,0.082057,88.005951,4.483237,0.820569,-134.554871,0.082898,0.000000
74.770004,20.127846,-134.599365,0.018578,0.003250,0.082551,89.533127,4.561035,0.825512,-134.599365,0.083366,0.000000
75.050003,20.596664,-134.599365,0.018578,0.003265,0.082924,91.618538,4.667271,0.829240,-134.599365,0.083826,0.000000
75.330002,21.195816,-134.599365,0.018600,0.003285,0.083436,94.283699,4.803041,0.834357,-134.599365,0.084294,0.000000
75.610001,21.705589,-134.643845,0.018604,0.003302,0.083878,96.551285,4.918557,0.838778,-134.643845,0.084762,0.000000
75.890007,22.221703,-134.599365,0.018630,0.003319,0.084303,98.847069,5.035510,0.843029,-134.599365,0.085231,0.000000
76.170006,23.096771,-134.599365,0.018634,0.003340,0.084832,102.739571,5.233803,0.848320,-134.599365,0.085699,0.000000
76.450005,23.792366,-134.688324,0.018643,0.003359,0.085309,105.833733,5.391427,0.853089,-134.688324,0.086167,0.000000
76.730003,24.145378,-134.688324,0.018656,0.003375,0.085717,107.404007,5.471421,0.857165,-134.688324,0.086627,0.000000
77.010002,24.926987,-134.643845,0.018656,0.003394,0.086202,110.880775,5.648536,0.862021,-134.643845,0.087095,0.000000
77.290001,25.842278,-134.643845,0.018686,0.003416,0.086766,114.952194,5.855944,0.867657,-134.643845,0.087564,0.000000
77.570007,26.398232,-134.688324,0.018699,0.003430,0.087121,117.425201,5.981925,0.871215,-134.688324,0.088032,0.000000
77.850006,26.693893,-134.732803,0.018708,0.003447,0.087555,118.740372,6.048923,0.875548,-134.732803,0.088500,0.000000
78.130005,28.025124,-134.732803,0.018712,0.003469,0.088110,124.661972,6.350584,0.881101,-134.732803,0.088960,0.000000
78.410004,28.935951,-134.732803,0.018734,0.003488,0.088596,128.713547,6.556981,0.885957,-134.732803,0.089428,0.000000
78.690002,29.615898,-134.732803,0.018751,0.003505,0.089038,131.738098,6.711059,0.890378,-134.732803,0.089897,0.000000
78.970001,30.050461,-134.777283,0.018751,0.003521,0.089445,133.671127,6.809532,0.894454,-134.777283,0.090365,0.000000
79.250000,31.083046,-134.821762,0.018759,0.003541,0.089948,138.264297,7.043519,0.899484,-134.821762,0.090833,0.000000
79.530006,31.642349,-134.732803,0.018781,0.003556,0.090321,140.752197,7.170259,0.903212,-134.732803,0.091302,0.000000
79.810005,32.450027,-134.732803,0.018781,0.003575,0.090798,144.344925,7.353281,0.907985,-134.732803,0.091761,0.000000
80.090004,33.833763,-134.732803,0.018794,0.003595,0.091319,150.500092,7.666841,0.913185,-134.732803,0.092229,0.000000
80.370003,34.866722,-134.777283,0.018820,0.003615,0.091813,155.094925,7.900912,0.918128,-134.777283,0.092698,0.000000
80.650002,35.746643,-134.821762,0.018815,0.003633,0.092281,159.009003,8.100305,0.922814,-134.821762,0.093166,0.000000
80.930000,36.385628,-134.777283,0.018824,0.003648,0.092654,161.851349,8.245101,0.926542,-134.777283,0.093634,0.000000
81.210007,37.100586,-134.821762,0.018841,0.003666,0.093114,165.031647,8.407113,0.931137,-134.821762,0.094094,0.000000
81.490005,38.127220,-134.777283,0.018854,0.003682,0.093513,169.598343,8.639751,0.935126,-134.777283,0.094562,0.000000
81.770004,39.000801,-134.866241,0.018863,0.003699,0.093946,173.484222,8.837708,0.939464,-134.866241,0.095030,0.000000
82.050003,39.717995,-134.910721,0.018867,0.003717,0.094415,176.674469,9.000226,0.944146,-134.910721,0.095499,0.000000
82.330002,41.926903,-134.866241,0.018880,0.003743,0.095065,186.500183,9.500772,0.950652,-134.866241,0.095967,0.000000
82.610001,42.826561,-134.866241,0.018876,0.003759,0.095490,190.502060,9.704638,0.954899,-134.866241,0.096435,0.000000
82.890007,43.407455,-134.866241,0.018906,0.003774,0.095872,193.085999,9.836270,0.958718,-134.866241,0.096895,0.000000
83.170006,44.235619,-134.910721,0.018910,0.003788,0.096218,196.769852,10.023934,0.962185,-134.910721,0.097363,0.000000
83.450005,45.975342,-134.910721,0.018915,0.003812,0.096817,204.508530,10.418161,0.968169,-134.910721,0.097832,0.000000
83.730003,46.230789,-134.910721,0.018919,0.003821,0.097042,205.644821,10.476047,0.970424,-134.910721,0.098300,0.000000
84.010002,47.950401,-134.910721,0.018936,0.003848,0.097727,213.294037,10.865716,0.977275,-134.910721,0.098768,0.000000
84.290001,50.024521,-134.910721,0.018953,0.003871,0.098335,222.520187,11.335719,0.983346,-134.910721,0.099228,0.000000
84.570007,50.832939,-134.955200,0.018949,0.003887,0.098734,226.116211,11.518909,0.987335,-134.955200,0.099696,0.000000
84.850006,51.753441,-134.955200,0.018966,0.003902,0.099106,230.210800,11.727497,0.991063,-134.955200,0.100164,0.000000
85.130005,52.813583,-134.910721,0.018962,0.003918,0.099505,234.926559,11.967729,0.995053,-134.910721,0.100633,0.000000
85.410004,54.356697,-134.910721,0.018971,0.003941,0.100104,241.790665,12.317404,1.001037,-134.910721,0.101101,0.000000
85.690002,55.095116,-134.955200,0.018988,0.003956,0.100476,245.075317,12.484732,1.004765,-134.955200,0.101560,0.000000
85.970001,56.911919,-134.955200,0.018997,0.003978,0.101032,253.156860,12.896425,1.010317,-134.955200,0.102029,0.000000
86.250008,58.951775,-134.999680,0.019001,0.003998,0.101560,262.230591,13.358664,1.015605,-134.999680,0.102497,0.000000
86.530006,59.641411,-134.999680,0.019009,0.004013,0.101925,265.298248,13.514937,1.019250,-134.999680,0.102965,0.000000
86.810005,60.965569,-134.955200,0.019009,0.004030,0.102358,271.188385,13.814995,1.023583,-134.955200,0.103434,0.000000
87.090004,62.475906,-134.955200,0.019022,0.004049,0.102836,277.906708,14.157242,1.028356,-134.955200,0.103902,0.000000
87.370003,63.906189,-134.955200,0.019031,0.004067,0.103304,284.268921,14.481350,1.033038,-134.955200,0.104362,0.000000
87.650002,65.035217,-134.999680,0.019031,0.004083,0.103711,289.291107,14.737191,1.037114,-134.999680,0.104830,0.000000
87.930008,67.757645,-135.044174,0.019031,0.004108,0.104336,301.401062,15.354102,1.043359,-135.044174,0.104440,0.000000
88.210007,67.129074,-135.044174,0.019044,0.004104,0.104249,298.605042,15.211665,1.042489,-135.044174,0.104440,0.000000
88.490005,66.603287,-134.999680,0.019057,0.004104,0.104232,296.266205,15.092520,1.042318,-134.999680,0.104249,0.000000
88.770004,66.150482,-135.088654,0.019061,0.004104,0.104232,294.252045,14.989913,1.042318,-135.088654,0.104249,0.000000
89.050003,65.793381,-135.044174,0.019061,0.004103,0.104223,292.663574,14.908993,1.042231,-135.044174,0.104249,0.000000
89.330002,65.455261,-135.088654,0.019057,0.004103,0.104223,291.159546,14.832374,1.042231,-135.088654,0.104249,0.000000
89.610001,65.167038,-135.044174,0.019053,0.004103,0.104223,289.877472,14.767062,1.042231,-135.044174,0.104249,0.000000
89.890007,64.907135,-135.133133,0.019066,0.004103,0.104223,288.721344,14.708167,1.042231,-135.133133,0.104249,0.000000
90.170006,64.689285,-135.133133,0.019083,0.004103,0.104223,287.752319,14.658802,1.042231,-135.133133,0.104249,0.000000
90.450005,64.480011,-135.133133,0.019066,0.004103,0.104223,286.821411,14.611379,1.042231,-135.133133,0.104249,0.000000
90.730003,64.287872,-135.088654,0.019074,0.004103,0.104214,285.966736,14.567840,1.042144,-135.088654,0.104249,0.000000
91.010002,64.101685,-135.177612,0.019070,0.004103,0.104214,285.138519,14.525650,1.042144,-135.177612,0.104249,0.000000
91.290001,63.943802,-135.133133,0.019087,0.004103,0.104214,284.436249,14.489873,1.042144,-135.133133,0.104249,0.000000
91.570007,63.795975,-135.133133,0.019074,0.004103,0.104214,283.778656,14.456375,1.042144,-135.133133,0.104249,0.000000
91.850006,63.661911,-135.177612,0.019083,0.004103,0.104214,283.182312,14.425995,1.042144,-135.177612,0.104249,0.000000
92.130005,63.525620,-135.222092,0.019078,0.004103,0.104214,282.576080,14.395111,1.042144,-135.222092,0.104249,0.000000
92.410004,63.403122,-135.133133,0.019083,0.004103,0.104214,282.031158,14.367352,1.042144,-135.133133,0.104249,0.000000
92.690002,63.311508,-135.177612,0.019074,0.004103,0.104214,281.623657,14.346593,1.042144,-135.177612,0.104249,0.000000
92.970001,63.197571,-135.266571,0.019083,0.004103,0.104214,281.116821,14.320774,1.042144,-135.266571,0.104249,0.000000
93.250008,63.094048,-135.177612,0.019078,0.004103,0.104214,280.656342,14.297316,1.042144,-135.177612,0.104249,0.000000
93.530006,62.999466,-135.222092,0.019070,0.004103,0.104214,280.235626,14.275884,1.042144,-135.222092,0.104249,0.000000
93.810005,62.904884,-135.177612,0.019087,0.004103,0.104214,279.814911,14.254450,1.042144,-135.177612,0.104249,0.000000
94.090004,62.813278,-135.222092,0.019096,0.004103,0.104214,279.407410,14.233692,1.042144,-135.222092,0.104249,0.000000
94.370003,62.732475,-135.266571,0.019087,0.004103,0.104214,279.047974,14.215383,1.042144,-135.266571,0.104249,0.000000
94.650002,62.631935,-135.266571,0.019091,0.004103,0.104214,278.600769,14.192599,1.042144,-135.266571,0.104249,0.000000
94.930008,62.585388,-135.222092,0.019083,0.004103,0.104214,278.393707,14.182052,1.042144,-135.222092,0.104249,0.000000
95.210007,62.515007,-135.222092,0.019087,0.004103,0.104214,278.080627,14.166102,1.042144,-135.222092,0.104249,0.000000
95.490005,62.458778,-135.222092,0.019091,0.004103,0.104214,277.830536,14.153361,1.042144,-135.222092,0.104249,0.000000
95.770004,62.388771,-135.266571,0.019087,0.004103,0.104214,277.519104,14.137498,1.042144,-135.266571,0.104249,0.000000
96.050003,62.339622,-135.311050,0.019078,0.004103,0.104214,277.300476,14.126360,1.042144,-135.311050,0.104249,0.000000
96.330002,62.265144,-135.266571,0.019070,0.004103,0.104214,276.969208,14.109484,1.042144,-135.266571,0.104249,0.000000
96.610008,62.197746,-135.311050,0.019100,0.004103,0.104214,276.669403,14.094211,1.042144,-135.311050,0.104249,0.000000
96.890007,62.137794,-135.266571,0.019100,0.004103,0.104214,276.402710,14.080626,1.042144,-135.266571,0.104249,0.000000
97.170006,62.083427,-135.311050,0.019096,0.004103,0.104214,276.160889,14.068306,1.042144,-135.311050,0.104249,0.000000
97.450005,62.037994,-135.355530,0.019091,0.004103,0.104214,275.958771,14.058011,1.042144,-135.355530,0.104249,0.000000
97.730003,61.991821,-135.311050,0.019091,0.004103,0.104214,275.753387,14.047548,1.042144,-135.311050,0.104249,0.000000
98.010002,61.938950,-135.266571,0.019100,0.004103,0.104214,275.518219,14.035567,1.042144,-135.266571,0.104249,0.000000
98.290001,61.893143,-135.355530,0.019100,0.004103,0.104214,275.314453,14.025187,1.042144,-135.355530,0.104249,0.000000
98.570007,61.853676,-135.444489,0.019087,0.004103,0.104214,275.138885,14.016244,1.042144,-135.444489,0.104249,0.000000
98.850006,61.791115,-135.400009,0.019100,0.004103,0.104214,274.860596,14.002067,1.042144,-135.400009,0.104249,0.000000
99.130005,61.738609,-135.355530,0.019087,0.004103,0.104214,274.627045,13.990169,1.042144,-135.355530,0.104249,0.000000
99.410004,61.737122,-135.355530,0.019109,0.004103,0.104214,274.620422,13.989832,1.042144,-135.355530,0.104249,0.000000
99.690002,61.657806,-135.400009,0.019109,0.004103,0.104214,274.267609,13.971858,1.042144,-135.400009,0.104249,0.000000
99.970001,61.628387,-135.444489,0.019100,0.004103,0.104214,274.136749,13.965192,1.042144,-135.444489,0.104249,0.000000
100.250008,61.579231,-135.444489,0.019091,0.004103,0.104214,273.918091,13.954053,1.042144,-135.444489,0.104249,0.000000
100.530006,61.540138,-135.400009,0.019091,0.004103,0.104214,273.744202,13.945195,1.042144,-135.400009,0.104249,0.000000
100.810005,61.521141,-135.444489,0.019104,0.004103,0.104214,273.659698,13.940890,1.042144,-135.444489,0.104249,0.000000
101.090004,61.463051,-135.444489,0.019104,0.004103,0.104214,273.401306,13.927727,1.042144,-135.444489,0.104249,0.000000
101.370003,61.427307,-135.444489,0.019096,0.004103,0.104214,273.242310,13.919626,1.042144,-135.444489,0.104249,0.000000
101.650002,61.412041,-135.444489,0.019091,0.004103,0.104214,273.174408,13.916168,1.042144,-135.444489,0.104249,0.000000
101.930008,61.387833,-135.444489,0.019100,0.004103,0.104214,273.066711,13.910682,1.042144,-135.444489,0.104249,0.000000
102.210007,61.340546,-135.444489,0.019100,0.004103,0.104214,272.856384,13.899966,1.042144,-135.444489,0.104249,0.000000
102.490005,61.305542,-135.488983,0.019091,0.004103,0.104214,272.700684,13.892035,1.042144,-135.488983,0.104249,0.000000
102.770004,61.275009,-135.533463,0.019104,0.004103,0.104214,272.564850,13.885116,1.042144,-135.533463,0.104249,0.000000
103.050003,61.222504,-135.533463,0.019087,0.004103,0.104214,272.331299,13.873218,1.042144,-135.533463,0.104249,0.000000
103.330002,61.186752,-135.533463,0.019083,0.004103,0.104214,272.172272,13.865116,1.042144,-135.533463,0.104249,0.000000
103.610008,61.175957,-135.533463,0.019104,0.004103,0.104214,272.124237,13.862670,1.042144,-135.533463,0.104249,0.000000
103.890007,61.128288,-135.533463,0.019100,0.004103,0.104214,271.912201,13.851868,1.042144,-135.533463,0.104249,0.000000
104.170006,61.108559,-135.577942,0.019104,0.004103,0.104214,271.824432,13.847397,1.042144,-135.577942,0.104249,0.000000
104.450005,61.084351,-135.577942,0.019091,0.004103,0.104214,271.716766,13.841912,1.042144,-135.577942,0.104249,0.000000
104.730003,61.040039,-135.488983,0.019091,0.004103,0.104214,271.519653,13.831870,1.042144,-135.488983,0.104249,0.000000
105.010002,61.018066,-135.488983,0.019091,0.004103,0.104214,271.421906,13.826892,1.042144,-135.488983,0.104249,0.000000
105.290009,60.978226,-135.533463,0.019104,0.004103,0.104214,271.244690,13.817863,1.042144,-135.533463,0.104249,0.000000
105.570007,60.962585,-135.622421,0.019096,0.004103,0.104214,271.175110,13.814320,1.042144,-135.622421,0.104249,0.000000
105.850006,60.926842,-135.622421,0.019100,0.004103,0.104214,271.016113,13.806220,1.042144,-135.622421,0.104249,0.000000
106.130005,60.903008,-135.577942,0.019100,0.004103,0.104214,270.910095,13.800818,1.042144,-135.577942,0.104249,0.000000
106.410004,60.891838,-135.533463,0.019100,0.004103,0.104214,270.860413,13.798288,1.042144,-135.533463,0.104249,0.000000
106.690002,60.866516,-135.622421,0.019104,0.004103,0.104214,270.747772,13.792550,1.042144,-135.622421,0.104249,0.000000
106.970009,60.846031,-135.622421,0.019100,0.004103,0.104214,270.656677,13.787908,1.042144,-135.622421,0.104249,0.000000
107.250008,60.820709,-135.622421,0.019104,0.004103,0.104214,270.544037,13.782169,1.042144,-135.622421,0.104249,0.000000
107.530006,60.790176,-135.622421,0.019104,0.004103,0.104214,270.408203,13.775250,1.042144,-135.622421,0.104249,0.000000
107.810005,60.768951,-135.622421,0.019104,0.004103,0.104214,270.313782,13.770441,1.042144,-135.622421,0.104249,0.000000
108.090004,60.740280,-135.711380,0.019100,0.004103,0.104214,270.186249,13.763945,1.042144,-135.711380,0.104249,0.000000
108.370003,60.725014,-135.666901,0.019113,0.004103,0.104214,270.118347,13.760485,1.042144,-135.666901,0.104249,0.000000
108.650002,60.704903,-135.711380,0.019104,0.004103,0.104214,270.028900,13.755927,1.042144,-135.711380,0.104249,0.000000
108.930008,60.699692,-135.666901,0.019087,0.004103,0.104214,270.005707,13.754747,1.042144,-135.666901,0.104249,0.000000
109.210007,60.677719,-135.711380,0.019104,0.004103,0.104214,269.907990,13.749767,1.042144,-135.711380,0.104249,0.000000
109.490005,60.658356,-135.666901,0.019113,0.004103,0.104214,269.821838,13.745380,1.042144,-135.666901,0.104249,0.000000
109.770004,60.623352,-135.711380,0.019100,0.004103,0.104214,269.666138,13.737449,1.042144,-135.711380,0.104249,0.000000
110.050003,60.587608,-135.711380,0.019109,0.004103,0.104214,269.507141,13.729348,1.042144,-135.711380,0.104249,0.000000
110.330002,60.589844,-135.666901,0.019096,0.004103,0.104214,269.517090,13.729856,1.042144,-135.666901,0.104249,0.000000
110.610008,60.552605,-135.711380,0.019100,0.004103,0.104214,269.351440,13.721416,1.042144,-135.711380,0.104249,0.000000
110.890007,60.537338,-135.755859,0.019104,0.004103,0.104214,269.283539,13.717957,1.042144,-135.755859,0.104249,0.000000
111.170006,60.518715,-135.755859,0.019100,0.004103,0.104214,269.200684,13.713737,1.042144,-135.755859,0.104249,0.000000
111.450005,60.501961,-135.711380,0.019104,0.004103,0.104214,269.126160,13.709941,1.042144,-135.711380,0.104249,0.000000
111.730003,60.488182,-135.800339,0.019100,0.004103,0.104214,269.064880,13.706818,1.042144,-135.800339,0.104249,0.000000
112.010002,60.471428,-135.711380,0.019100,0.004103,0.104214,268.990356,13.703021,1.042144,-135.711380,0.104249,0.000000
112.290009,60.439400,-135.844818,0.019113,0.004103,0.104214,268.847870,13.695764,1.042144,-135.844818,0.104249,0.000000
112.570007,60.424881,-135.800339,0.019100,0.004103,0.104214,268.783295,13.692473,1.042144,-135.800339,0.104249,0.000000
112.850006,60.407005,-135.800339,0.019104,0.004103,0.104214,268.703766,13.688423,1.042144,-135.800339,0.104249,0.000000
113.130005,60.409241,-135.755859,0.019100,0.004103,0.104214,268.713715,13.688930,1.042144,-135.755859,0.104249,0.000000
113.410004,60.390991,-135.800339,0.019100,0.004103,0.104214,268.632538,13.684794,1.042144,-135.800339,0.104249,0.000000
113.690002,60.374985,-135.844818,0.019104,0.004103,0.104214,268.561340,13.681168,1.042144,-135.844818,0.104249,0.000000
113.970009,60.351524,-135.889313,0.019104,0.004103,0.104214,268.457001,13.675851,1.042144,-135.889313,0.104249,0.000000
114.250008,60.339233,-135.800339,0.019109,0.004103,0.104214,268.402313,13.673066,1.042144,-135.800339,0.104249,0.000000
114.530006,60.314659,-135.800339,0.019104,0.004103,0.104214,268.292999,13.667498,1.042144,-135.800339,0.104249,0.000000
114.810005,60.315399,-135.800339,0.019100,0.004103,0.104214,268.296295,13.667665,1.042144,-135.800339,0.104249,0.000000
115.090004,60.296410,-135.889313,0.019104,0.004103,0.104214,268.211823,13.663363,1.042144,-135.889313,0.104249,0.000000
115.370003,60.261040,-135.889313,0.019104,0.004103,0.104214,268.054504,13.655347,1.042144,-135.889313,0.104249,0.000000
115.650009,60.251724,-135.933792,0.019091,0.004103,0.104214,268.013062,13.653236,1.042144,-135.933792,0.104249,0.000000
115.930008,60.238693,-135.889313,0.019104,0.004103,0.104214,267.955078,13.650283,1.042144,-135.889313,0.104249,0.000000
116.210007,60.225662,-135.844818,0.019113,0.004103,0.104214,267.897125,13.647330,1.042144,-135.844818,0.104249,0.000000
116.490005,60.217468,-135.933792,0.019100,0.004103,0.104214,267.860687,13.645473,1.042144,-135.933792,0.104249,0.000000
116.770004,60.186562,-135.933792,0.019109,0.004103,0.104214,267.723206,13.638470,1.042144,-135.933792,0.104249,0.000000
117.050003,60.167946,-135.933792,0.019100,0.004103,0.104214,267.640381,13.634252,1.042144,-135.933792,0.104249,0.000000
117.330002,60.150444,-135.978271,0.019100,0.004103,0.104214,267.562531,13.630286,1.042144,-135.978271,0.104249,0.000000
117.610008,60.141876,-135.978271,0.019096,0.004103,0.104214,267.524414,13.628344,1.042144,-135.978271,0.104249,0.000000
117.890007,60.124001,-135.978271,0.019113,0.004103,0.104214,267.444916,13.624293,1.042144,-135.978271,0.104249,0.000000
118.170006,60.096817,-136.022751,0.019113,0.004103,0.104214,267.324005,13.618134,1.042144,-136.022751,0.104249,0.000000
118.400009,60.111717,-135.978271,0.019109,0.004103,0.104214,267.390259,13.621510,1.042144,-135.978271,0.104249,0.000000