File: Data/compression 4/AutoNoheating-12-4-2-240223_02232024_163631.csv
Time (sec),S:Load (lbs),S:HL1 (DIM),S:LVDT (in),S:Position (in),Ch:Position (mm),Ch:Load (N),Ch:Stress (MPa),Ch:Strain (mm/mm),Ch:HL1 (DIM),Set Point (),Cycles ()
0.010000,-0.003357,-119.920647,-0.000022,-0.000000,-0.000000,-0.014932,-0.000761,-0.000000,-119.920647,0.000199,0.000000
0.270000,-0.005959,-120.009605,-0.000004,-0.000000,-0.000000,-0.026505,-0.001350,-0.000000,-120.009605,0.000199,0.000000
0.530000,0.004089,-119.965126,0.000000,0.000101,0.002558,0.018190,0.000927,0.025582,-119.965126,0.003443,0.000000
0.790000,-0.029793,-119.965126,0.000134,0.000266,0.006764,-0.132525,-0.006751,0.067644,-119.965126,0.007779,0.000000
1.050000,-0.012665,-120.009605,0.000306,0.000437,0.011109,-0.056336,-0.002870,0.111090,-120.009605,0.012115,0.000000
1.310000,0.014519,-120.009605,0.000474,0.000605,0.015367,0.064583,0.003290,0.153671,-120.009605,0.016451,0.000000
1.570000,-0.040222,-120.009605,0.000651,0.000778,0.019764,-0.178917,-0.009114,0.197640,-120.009605,0.020770,0.000000
1.830000,-0.002609,-120.098564,0.000819,0.000950,0.024126,-0.011607,-0.000591,0.241261,-120.098564,0.025106,0.000000
2.090000,-0.021225,-120.009605,0.000979,0.001113,0.028272,-0.094413,-0.004810,0.282717,-120.009605,0.029442,0.000000
2.350000,-0.076714,-120.054085,0.001160,0.001286,0.032677,-0.341239,-0.017384,0.326769,-120.054085,0.033778,0.000000
2.610000,0.002228,-120.098564,0.001319,0.001454,0.036944,0.009910,0.000505,0.369440,-120.098564,0.038097,0.000000
2.870000,-0.004471,-120.054085,0.001513,0.001631,0.041427,-0.019887,-0.001013,0.414272,-120.054085,0.042433,0.000000
3.130000,-0.024208,-120.098564,0.001669,0.001800,0.045711,-0.107683,-0.005486,0.457113,-120.098564,0.046770,0.000000
3.390000,-0.004845,-120.054085,0.001867,0.001970,0.050039,-0.021550,-0.001098,0.500390,-120.054085,0.051106,0.000000
3.650000,-0.003357,-120.098564,0.002031,0.002144,0.054462,-0.014932,-0.000761,0.544616,-120.098564,0.055424,0.000000
3.910000,-0.037987,-120.009605,0.002203,0.002310,0.058685,-0.168974,-0.008608,0.586852,-120.009605,0.059760,0.000000
4.170000,-0.010429,-120.098564,0.002371,0.002481,0.063021,-0.046392,-0.002363,0.630212,-120.098564,0.064097,0.000000
4.430000,-0.023834,-120.143051,0.002535,0.002650,0.067314,-0.106020,-0.005401,0.673140,-120.143051,0.068433,0.000000
4.690000,-0.055115,-120.098564,0.002725,0.002821,0.071650,-0.245163,-0.012489,0.716503,-120.098564,0.072752,0.000000
4.950000,0.013405,-120.187531,0.002893,0.002990,0.075943,0.059628,0.003038,0.759428,-120.187531,0.077088,0.000000
5.210000,0.010048,-120.098564,0.003078,0.003166,0.080418,0.044695,0.002277,0.804177,-120.098564,0.081424,0.000000
5.470000,-0.009682,-120.098564,0.003247,0.003333,0.084659,-0.043066,-0.002194,0.846586,-120.098564,0.085743,0.000000
5.730000,-0.002235,-120.143051,0.003402,0.003504,0.089012,-0.009944,-0.000507,0.890120,-120.143051,0.090079,0.000000
5.990000,0.014145,-120.098564,0.003579,0.003680,0.093461,0.062920,0.003205,0.934608,-120.098564,0.094415,0.000000
6.250000,-0.024582,-120.143051,0.003751,0.003843,0.097623,-0.109346,-0.005570,0.976234,-120.143051,0.098751,0.000000
6.510000,0.028297,-120.143051,0.003919,0.004012,0.101916,0.125873,0.006412,1.019162,-120.143051,0.103070,0.000000
6.770000,0.004837,-120.143051,0.004100,0.004191,0.106452,0.021516,0.001096,1.064521,-120.143051,0.107406,0.000000
7.030000,0.025322,-120.187531,0.004255,0.004355,0.110615,0.112638,0.005738,1.106147,-120.187531,0.111742,0.000000
7.290000,0.116920,-120.187531,0.004441,0.004525,0.114942,0.520088,0.026495,1.149420,-120.187531,0.116078,0.000000
7.550000,0.288216,-120.232010,0.004600,0.004700,0.119374,1.282047,0.065311,1.193737,-120.232010,0.120397,0.000000
7.810000,0.668030,-120.187531,0.004777,0.000008,0.000199,2.971545,0.151378,0.001995,-120.187531,0.001205,0.000000
8.070001,0.593559,-120.232010,0.004786,0.000003,0.000087,2.640284,0.134502,0.000867,-120.232010,0.000269,0.000000
8.330000,0.560043,-120.187531,0.004790,0.000003,0.000078,2.491197,0.126908,0.000780,-120.187531,0.000269,0.000000
8.590000,0.525040,-120.276489,0.004799,0.000003,0.000078,2.335493,0.118976,0.000780,-120.276489,0.000668,0.000000
8.850000,0.557808,-120.276489,0.004786,0.000015,0.000382,2.481254,0.126401,0.003815,-120.276489,0.001101,0.000000
9.110001,0.617760,-120.187531,0.004807,0.000027,0.000694,2.747932,0.139986,0.006938,-120.187531,0.001535,0.000000
9.370001,0.678459,-120.276489,0.004816,0.000039,0.000997,3.017937,0.153741,0.009973,-120.276489,0.001969,0.000000
9.630000,0.745117,-120.232010,0.004825,0.000064,0.001631,3.314447,0.168846,0.016305,-120.232010,0.002402,0.000000
9.890000,0.777885,-120.276489,0.004855,0.000079,0.001995,3.460207,0.176271,0.019946,-120.276489,0.002836,0.000000
10.150001,0.762619,-120.320976,0.004863,0.000097,0.002463,3.392299,0.172812,0.024628,-120.320976,0.003269,0.000000
10.410001,0.790169,-120.232010,0.004881,0.000113,0.002879,3.514846,0.179055,0.028792,-120.232010,0.003703,0.000000
10.670000,0.849007,-120.276489,0.004902,0.000130,0.003313,3.776570,0.192388,0.033129,-120.276489,0.004137,0.000000
10.930000,0.879166,-120.320976,0.004915,0.000145,0.003694,3.910724,0.199222,0.036944,-120.320976,0.004570,0.000000
11.190001,0.928322,-120.276489,0.004941,0.000164,0.004163,4.129382,0.210361,0.041626,-120.276489,0.005004,0.000000
11.450001,0.930557,-120.365456,0.004950,0.000182,0.004622,4.139326,0.210867,0.046225,-120.365456,0.005437,0.000000
11.710001,0.962578,-120.320976,0.004971,0.000201,0.005108,4.281760,0.218123,0.051081,-120.320976,0.005871,0.000000
11.970000,0.968910,-120.409935,0.004997,0.000217,0.005516,4.309928,0.219558,0.055157,-120.409935,0.006305,0.000000
12.230000,0.985298,-120.320976,0.005001,0.000233,0.005906,4.382825,0.223272,0.059060,-120.320976,0.006738,0.000000
12.490001,1.002792,-120.320976,0.005027,0.000246,0.006253,4.460643,0.227236,0.062526,-120.320976,0.007172,0.000000
12.750001,1.092537,-120.409935,0.005036,0.000266,0.006764,4.859847,0.247572,0.067644,-120.409935,0.007606,0.000000
13.010000,1.120094,-120.320976,0.005057,0.000281,0.007146,4.982428,0.253817,0.071459,-120.320976,0.008039,0.000000
13.270000,1.127914,-120.365456,0.005070,0.000294,0.007458,5.017214,0.255589,0.074581,-120.365456,0.008473,0.000000
13.530001,1.162170,-120.409935,0.005070,0.000312,0.007935,5.169592,0.263352,0.079350,-120.409935,0.008906,0.000000
13.790001,1.226593,-120.320976,0.005109,0.000336,0.008525,5.456158,0.277950,0.085247,-120.320976,0.009340,0.000000
14.050000,1.201271,-120.409935,0.005126,0.000350,0.008898,5.343521,0.272212,0.088979,-120.409935,0.009774,0.000000
14.310000,1.239998,-120.365456,0.005135,0.000366,0.009288,5.515786,0.280988,0.092881,-120.365456,0.010207,0.000000
14.570001,1.321922,-120.409935,0.005148,0.000384,0.009748,5.880204,0.299552,0.097476,-120.409935,0.010641,0.000000
14.830001,1.384102,-120.409935,0.005170,0.000402,0.010198,6.156793,0.313642,0.101984,-120.409935,0.011075,0.000000
15.090001,1.377403,-120.365456,0.005187,0.000411,0.010441,6.126996,0.312124,0.104414,-120.365456,0.011499,0.000000
15.350000,1.433258,-120.543381,0.005200,0.000431,0.010944,6.375450,0.324781,0.109444,-120.543381,0.011933,0.000000
15.610001,1.569916,-120.365456,0.005221,0.000457,0.011612,6.983334,0.355748,0.116121,-120.365456,0.012367,0.000000
15.870001,1.588913,-120.454414,0.005243,0.000471,0.011959,7.067838,0.360053,0.119591,-120.454414,0.012800,0.000000
16.130001,1.610138,-120.454414,0.005256,0.000484,0.012297,7.162251,0.364862,0.122971,-120.454414,0.013234,0.000000
16.390001,1.679771,-120.454414,0.005273,0.000501,0.012731,7.471996,0.380642,0.127309,-120.454414,0.013668,0.000000
16.650002,1.811958,-120.498894,0.005286,0.000522,0.013251,8.059993,0.410596,0.132513,-120.498894,0.014101,0.000000
16.910002,1.843239,-120.498894,0.005307,0.000533,0.013546,8.199136,0.417684,0.135461,-120.498894,0.014535,0.000000
17.170000,1.939316,-120.498894,0.005316,0.000550,0.013962,8.626508,0.439455,0.139625,-120.498894,0.014969,0.000000
17.430000,1.991814,-120.498894,0.005329,0.000568,0.014439,8.860029,0.451351,0.144394,-120.498894,0.015402,0.000000
17.690001,2.133690,-120.498894,0.005364,0.000590,0.014986,9.491127,0.483501,0.149855,-120.498894,0.015836,0.000000
17.950001,2.163857,-120.543381,0.005368,0.000606,0.015384,9.625315,0.490337,0.153845,-120.543381,0.016269,0.000000
18.210001,2.233490,-120.498894,0.005381,0.000623,0.015818,9.935060,0.506116,0.158182,-120.498894,0.016703,0.000000
18.470001,2.282265,-120.498894,0.005394,0.000635,0.016139,10.152020,0.517169,0.161392,-120.498894,0.017136,0.000000
18.730001,2.456535,-120.543381,0.005424,0.000656,0.016651,10.927215,0.556659,0.166509,-120.543381,0.017570,0.000000
18.990002,2.471802,-120.543381,0.005437,0.000666,0.016911,10.995123,0.560118,0.169109,-120.543381,0.018004,0.000000
19.250000,2.642349,-120.632339,0.005458,0.000690,0.017535,11.753757,0.598765,0.175354,-120.632339,0.018437,0.000000
19.510000,2.735817,-120.498894,0.005493,0.000713,0.018099,12.169521,0.619945,0.180990,-120.498894,0.018871,0.000000
19.770000,2.718315,-120.587860,0.005510,0.000727,0.018472,12.091670,0.615979,0.184718,-120.587860,0.019304,0.000000
20.030001,2.767097,-120.632339,0.005510,0.000741,0.018828,12.308664,0.627033,0.188276,-120.632339,0.019738,0.000000
20.290001,2.874710,-120.587860,0.005536,0.000758,0.019261,12.787349,0.651419,0.192610,-120.587860,0.020172,0.000000
20.550001,2.954773,-120.587860,0.005545,0.000776,0.019703,13.143487,0.669561,0.197034,-120.587860,0.020605,0.000000
20.810001,3.036324,-120.587860,0.005553,0.000790,0.020068,13.506242,0.688041,0.200675,-120.587860,0.021039,0.000000
21.070002,3.092552,-120.587860,0.005579,0.000804,0.020423,13.756359,0.700782,0.204233,-120.587860,0.021472,0.000000
21.330002,3.225113,-120.632339,0.005601,0.000827,0.020996,14.346019,0.730821,0.209956,-120.632339,0.021906,0.000000
21.590000,3.241501,-120.587860,0.005618,0.000842,0.021394,14.418916,0.734535,0.213945,-120.587860,0.022340,0.000000
21.850000,3.310387,-120.632339,0.005627,0.000861,0.021863,14.725335,0.750144,0.218627,-120.632339,0.022773,0.000000
22.110001,3.334595,-120.587860,0.005648,0.000875,0.022218,14.833018,0.755630,0.222185,-120.587860,0.023207,0.000000
22.370001,3.464554,-120.676819,0.005674,0.000898,0.022799,15.411105,0.785079,0.227995,-120.676819,0.023640,0.000000
22.630001,3.474602,-120.632339,0.005670,0.000913,0.023181,15.455800,0.787356,0.231810,-120.632339,0.024074,0.000000
22.890001,3.509232,-120.676819,0.005678,0.000925,0.023502,15.609841,0.795203,0.235019,-120.676819,0.024508,0.000000
23.150002,3.654457,-120.632339,0.005717,0.000948,0.024074,16.255836,0.828112,0.240742,-120.632339,0.024941,0.000000
23.410002,3.684250,-120.676819,0.005747,0.000967,0.024551,16.388363,0.834863,0.245511,-120.676819,0.025375,0.000000
23.670002,3.697655,-120.721298,0.005760,0.000983,0.024976,16.447990,0.837901,0.249761,-120.721298,0.025809,0.000000
23.930000,3.759468,-120.721298,0.005773,0.000999,0.025384,16.722950,0.851908,0.253838,-120.721298,0.026242,0.000000
24.190001,3.809364,-120.632339,0.005782,0.001016,0.025800,16.944899,0.863214,0.258001,-120.632339,0.026667,0.000000
24.450001,3.902832,-120.721298,0.005808,0.001034,0.026268,17.360664,0.884394,0.262683,-120.721298,0.027101,0.000000
24.710001,3.937836,-120.676819,0.005825,0.001047,0.026598,17.516369,0.892326,0.265980,-120.676819,0.027534,0.000000
24.970001,3.949005,-120.721298,0.005842,0.001063,0.026997,17.566051,0.894857,0.269969,-120.721298,0.027968,0.000000
25.230001,4.143761,-120.676819,0.005864,0.001088,0.027638,18.432367,0.938990,0.276384,-120.676819,0.028401,0.000000
25.490002,4.169823,-120.632339,0.005881,0.001106,0.028081,18.548298,0.944895,0.280809,-120.632339,0.028835,0.000000
25.750002,4.098701,-120.810265,0.005894,0.001120,0.028445,18.231936,0.928779,0.284450,-120.810265,0.029269,0.000000
26.010002,4.139664,-120.765785,0.005911,0.001135,0.028835,18.414145,0.938061,0.288352,-120.765785,0.029702,0.000000
26.270000,4.271851,-120.765785,0.005933,0.001154,0.029321,19.002140,0.968015,0.293208,-120.765785,0.030136,0.000000
26.530001,4.312439,-120.721298,0.005954,0.001170,0.029720,19.182686,0.977213,0.297198,-120.721298,0.030570,0.000000
26.790001,4.278183,-120.765785,0.005967,0.001181,0.030006,19.030308,0.969450,0.300059,-120.765785,0.031003,0.000000
27.050001,4.455063,-120.854744,0.005989,0.001205,0.030604,19.817110,1.009532,0.306043,-120.854744,0.031437,0.000000
27.310001,4.536980,-120.854744,0.005997,0.001225,0.031116,20.181494,1.028094,0.311160,-120.854744,0.031871,0.000000
27.570002,4.504585,-120.810265,0.006023,0.001241,0.031524,20.037395,1.020754,0.315236,-120.810265,0.032304,0.000000
27.830002,4.510918,-120.810265,0.006049,0.001255,0.031888,20.065563,1.022189,0.318877,-120.810265,0.032738,0.000000
28.090002,4.590981,-120.765785,0.006053,0.001271,0.032295,20.421701,1.040331,0.322954,-120.765785,0.033171,0.000000
28.350002,4.580177,-120.854744,0.006058,0.001284,0.032625,20.373646,1.037883,0.326250,-120.854744,0.033605,0.000000
28.610001,4.661354,-120.854744,0.006092,0.001305,0.033154,20.734739,1.056278,0.331542,-120.854744,0.034039,0.000000
28.870001,4.751839,-120.854744,0.006114,0.001324,0.033640,21.137234,1.076782,0.336398,-120.854744,0.034472,0.000000
29.130001,4.815521,-120.854744,0.006135,0.001341,0.034073,21.420507,1.091213,0.340731,-120.854744,0.034906,0.000000
29.390001,4.776421,-120.854744,0.006144,0.001356,0.034438,21.246580,1.082352,0.344376,-120.854744,0.035340,0.000000
29.650002,4.849777,-120.899223,0.006174,0.001375,0.034932,21.572887,1.098975,0.349319,-120.899223,0.035773,0.000000
29.910002,4.856476,-120.854744,0.006187,0.001391,0.035322,21.602684,1.100493,0.353222,-120.854744,0.036207,0.000000
30.170002,4.916428,-120.854744,0.006209,0.001408,0.035764,21.869362,1.114078,0.357642,-120.854744,0.036640,0.000000
30.430002,4.936165,-120.899223,0.006204,0.001426,0.036215,21.957157,1.118551,0.362154,-120.899223,0.037074,0.000000
30.690001,4.938026,-120.854744,0.006230,0.001440,0.036571,21.965439,1.118973,0.365708,-120.854744,0.037508,0.000000
30.950001,5.119743,-120.943703,0.006265,0.001463,0.037152,22.773756,1.160150,0.371518,-120.943703,0.037941,0.000000
31.210001,5.058678,-120.899223,0.006273,0.001477,0.037516,22.502123,1.146313,0.375163,-120.899223,0.038375,0.000000
31.470001,5.069107,-120.854744,0.006286,0.001496,0.037993,22.548513,1.148676,0.379932,-120.854744,0.038808,0.000000
31.730001,5.090698,-120.943703,0.006312,0.001512,0.038401,22.644556,1.153569,0.384008,-120.943703,0.039242,0.000000
31.990002,5.152145,-120.899223,0.006316,0.001529,0.038835,22.917887,1.167493,0.388345,-120.899223,0.039676,0.000000
32.250000,5.127937,-120.988190,0.006334,0.001542,0.039164,22.810204,1.162007,0.391638,-120.988190,0.040109,0.000000
32.510002,5.234062,-120.943703,0.006355,0.001562,0.039676,23.282272,1.186055,0.396755,-120.943703,0.040543,0.000000
32.770000,5.198692,-120.899223,0.006372,0.001577,0.040066,23.124939,1.178041,0.400658,-120.899223,0.040976,0.000000
33.030003,5.327156,-121.032669,0.006407,0.001600,0.040630,23.696373,1.207151,0.406297,-121.032669,0.041401,0.000000
33.290001,5.286942,-120.943703,0.006428,0.001616,0.041054,23.517490,1.198038,0.410544,-120.943703,0.041835,0.000000
33.550003,5.260132,-120.988190,0.006446,0.001631,0.041427,23.398235,1.191963,0.414272,-120.988190,0.042269,0.000000
33.810001,5.257523,-120.988190,0.006450,0.001644,0.041766,23.386629,1.191372,0.417656,-120.988190,0.042702,0.000000
34.070004,5.402748,-120.988190,0.006480,0.001665,0.042303,24.032623,1.224280,0.423034,-120.988190,0.043136,0.000000
34.330002,5.375565,-120.988190,0.006497,0.001680,0.042667,23.911705,1.218120,0.426675,-120.988190,0.043569,0.000000
34.590000,5.326782,-120.988190,0.006510,0.001692,0.042988,23.694712,1.207066,0.429885,-120.988190,0.044003,0.000000
34.850002,5.405731,-121.032669,0.006523,0.001712,0.043474,24.045893,1.224956,0.434741,-121.032669,0.044437,0.000000
35.110001,5.532333,-121.077148,0.006549,0.001735,0.044072,24.609049,1.253645,0.440725,-121.077148,0.044870,0.000000
35.370003,5.436638,-120.988190,0.006566,0.001749,0.044428,24.183372,1.231960,0.444279,-120.988190,0.045304,0.000000
35.630001,5.419876,-121.032669,0.006575,0.001763,0.044792,24.108812,1.228161,0.447923,-121.032669,0.045737,0.000000
35.890003,5.545364,-121.077148,0.006605,0.001783,0.045278,24.667013,1.256598,0.452779,-121.077148,0.046171,0.000000
36.150002,5.573669,-121.077148,0.006622,0.001800,0.045711,24.792919,1.263012,0.457113,-121.077148,0.046605,0.000000
36.410000,5.434029,-121.121628,0.006635,0.001810,0.045980,24.171766,1.231368,0.459804,-121.121628,0.047038,0.000000
36.670002,5.494354,-121.077148,0.006657,0.001829,0.046449,24.440109,1.245039,0.464486,-121.077148,0.047472,0.000000
36.930000,5.786667,-121.121628,0.006670,0.001856,0.047134,25.740379,1.311277,0.471337,-121.121628,0.047905,0.000000
37.190002,5.667503,-121.077148,0.006696,0.001869,0.047481,25.210314,1.284275,0.474808,-121.077148,0.048339,0.000000
37.450001,5.580742,-121.121628,0.006717,0.001883,0.047827,24.824379,1.264614,0.478274,-121.121628,0.048773,0.000000
37.710003,5.577019,-121.121628,0.006713,0.001899,0.048226,24.807817,1.263770,0.482264,-121.121628,0.049206,0.000000
37.970001,5.817200,-121.077148,0.006739,0.001921,0.048790,25.876196,1.318196,0.487899,-121.077148,0.049640,0.000000
38.230003,5.699905,-121.210594,0.006760,0.001932,0.049076,25.354446,1.291617,0.490765,-121.210594,0.050074,0.000000
38.490002,5.795227,-121.121628,0.006773,0.001950,0.049536,25.778458,1.313217,0.495359,-121.121628,0.050507,0.000000
38.750000,5.842522,-121.166107,0.006808,0.001967,0.049970,25.988834,1.323934,0.499697,-121.166107,0.050941,0.000000
39.010002,5.941574,-121.121628,0.006799,0.001989,0.050516,26.429441,1.346380,0.505159,-121.121628,0.051374,0.000000
39.270000,5.880875,-121.166107,0.006838,0.002005,0.050923,26.159437,1.332625,0.509235,-121.166107,0.051808,0.000000
39.530003,5.807518,-121.166107,0.006855,0.002019,0.051288,25.833130,1.316002,0.512876,-121.166107,0.052242,0.000000
39.790001,5.888695,-121.121628,0.006860,0.002034,0.051661,26.194223,1.334397,0.516608,-121.121628,0.052675,0.000000
40.050003,6.049187,-121.210594,0.006885,0.002054,0.052181,26.908127,1.370765,0.521808,-121.210594,0.053109,0.000000
40.310001,5.930031,-121.166107,0.006894,0.002066,0.052484,26.378094,1.343764,0.524844,-121.166107,0.053543,0.000000
40.570004,6.204468,-121.166107,0.006929,0.002089,0.053057,27.598850,1.405952,0.530570,-121.166107,0.053976,0.000000
40.830002,6.272614,-121.210594,0.006937,0.002113,0.053672,27.901978,1.421395,0.536725,-121.210594,0.054410,0.000000
41.090000,6.094246,-121.255074,0.006967,0.002126,0.054002,27.108561,1.380976,0.540021,-121.255074,0.054844,0.000000
41.350002,6.130363,-121.255074,0.006989,0.002142,0.054418,27.269218,1.389160,0.544185,-121.255074,0.055277,0.000000
41.610001,6.158295,-121.255074,0.006989,0.002157,0.054783,27.393463,1.395490,0.547826,-121.255074,0.055711,0.000000
41.870003,6.310593,-121.255074,0.007011,0.002176,0.055259,28.070917,1.430001,0.552595,-121.255074,0.056144,0.000000
42.130001,6.270004,-121.255074,0.007036,0.002189,0.055598,27.890371,1.420803,0.555978,-121.255074,0.056569,0.000000
42.390003,6.294212,-121.255074,0.007049,0.002204,0.055988,27.998055,1.426289,0.559881,-121.255074,0.057003,0.000000
42.650002,6.487099,-121.299553,0.007062,0.002225,0.056526,28.856056,1.469998,0.565259,-121.299553,0.057437,0.000000
42.910004,6.410759,-121.299553,0.007071,0.002239,0.056864,28.516479,1.452699,0.568639,-121.299553,0.057870,0.000000
43.170002,6.585777,-121.255074,0.007097,0.002260,0.057402,29.295000,1.492358,0.574017,-121.255074,0.058304,0.000000
43.430000,6.506462,-121.299553,0.007118,0.002273,0.057740,28.942188,1.474385,0.577397,-121.299553,0.058737,0.000000
43.690002,6.739937,-121.255074,0.007136,0.002296,0.058330,29.980736,1.527292,0.583298,-121.255074,0.059171,0.000000
43.950001,6.678123,-121.388512,0.007161,0.002312,0.058720,29.705776,1.513284,0.587200,-121.388512,0.059605,0.000000
44.210003,6.638283,-121.299553,0.007170,0.002324,0.059041,29.528557,1.504256,0.590406,-121.299553,0.060038,0.000000
44.470001,6.840477,-121.255074,0.007192,0.002346,0.059587,30.427961,1.550074,0.595871,-121.255074,0.060472,0.000000
44.730003,6.902290,-121.344032,0.007200,0.002365,0.060073,30.702921,1.564081,0.600727,-121.344032,0.060905,0.000000
44.990002,6.919792,-121.388512,0.007230,0.002382,0.060515,30.780773,1.568047,0.605152,-121.388512,0.061339,0.000000
45.250004,6.893356,-121.388512,0.007248,0.002396,0.060871,30.663181,1.562057,0.608706,-121.388512,0.061773,0.000000
45.510002,7.019218,-121.388512,0.007248,0.002414,0.061321,31.223043,1.590578,0.613214,-121.388512,0.062206,0.000000
45.770000,7.140610,-121.344032,0.007278,0.002433,0.061799,31.763018,1.618085,0.617986,-121.344032,0.062640,0.000000
46.030003,7.172264,-121.388512,0.007282,0.002449,0.062215,31.903824,1.625258,0.622146,-121.388512,0.063073,0.000000
46.290001,7.092575,-121.344032,0.007312,0.002463,0.062562,31.549349,1.607200,0.625617,-121.344032,0.063507,0.000000
46.550003,7.461227,-121.344032,0.007330,0.002486,0.063151,33.189198,1.690738,0.631514,-121.344032,0.063941,0.000000
46.810001,7.489151,-121.432999,0.007347,0.002504,0.063603,33.313408,1.697066,0.636025,-121.432999,0.064374,0.000000
47.070004,7.395683,-121.388512,0.007368,0.002519,0.063993,32.897644,1.675886,0.639927,-121.388512,0.064808,0.000000
47.330002,7.396431,-121.432999,0.007373,0.002533,0.064348,32.900967,1.676055,0.643481,-121.432999,0.065241,0.000000
47.590004,7.584854,-121.388512,0.007407,0.002553,0.064842,33.739117,1.718753,0.648424,-121.388512,0.065675,0.000000
47.850002,7.636238,-121.432999,0.007424,0.002570,0.065276,33.967682,1.730396,0.652762,-121.432999,0.066108,0.000000
48.110001,7.509636,-121.388512,0.007433,0.002580,0.065528,33.404530,1.701708,0.655275,-121.388512,0.066542,0.000000
48.370003,7.861900,-121.432999,0.007463,0.002603,0.066126,34.971478,1.781532,0.661259,-121.432999,0.066976,0.000000
48.630001,8.008987,-121.477478,0.007468,0.002624,0.066646,35.625755,1.814862,0.666463,-121.477478,0.067409,0.000000
48.890003,7.989624,-121.521957,0.007493,0.002640,0.067063,35.539623,1.810475,0.670627,-121.521957,0.067843,0.000000
49.150002,7.955360,-121.477478,0.007506,0.002654,0.067409,35.387211,1.802710,0.674094,-121.477478,0.068277,0.000000
49.410004,8.093140,-121.477478,0.007519,0.002672,0.067869,36.000084,1.833932,0.678692,-121.477478,0.068710,0.000000
49.670002,8.219002,-121.477478,0.007532,0.002689,0.068294,36.559944,1.862452,0.682939,-121.477478,0.069144,0.000000
49.930004,8.296082,-121.521957,0.007545,0.002704,0.068676,36.902813,1.879919,0.686758,-121.521957,0.069577,0.000000
50.190002,8.439445,-121.432999,0.007575,0.002723,0.069161,37.540527,1.912406,0.691614,-121.432999,0.070011,0.000000
50.450001,8.611107,-121.432999,0.007597,0.002740,0.069595,38.304115,1.951305,0.695948,-121.432999,0.070445,0.000000
50.710003,8.509453,-121.566437,0.007601,0.002755,0.069968,37.851936,1.928270,0.699679,-121.566437,0.070878,0.000000
50.970001,8.753357,-121.477478,0.007618,0.002774,0.070454,38.936874,1.983539,0.704535,-121.477478,0.071312,0.000000
51.230003,8.761925,-121.566437,0.007640,0.002789,0.070852,38.974987,1.985481,0.708525,-121.566437,0.071737,0.000000
51.490002,9.056465,-121.477478,0.007649,0.002810,0.071381,40.285168,2.052224,0.713812,-121.477478,0.072170,0.000000
51.750004,8.932098,-121.477478,0.007662,0.002824,0.071720,39.731956,2.024042,0.717196,-121.477478,0.072604,0.000000
52.010002,9.071365,-121.610924,0.007683,0.002838,0.072092,40.351448,2.055601,0.720924,-121.610924,0.073038,0.000000
52.270004,9.453415,-121.566437,0.007709,0.002861,0.072682,42.050888,2.142174,0.726821,-121.566437,0.073471,0.000000
52.530003,9.426979,-121.566437,0.007722,0.002876,0.073038,41.933296,2.136184,0.730379,-121.566437,0.073905,0.000000
52.790001,9.546509,-121.566437,0.007735,0.002895,0.073523,42.464993,2.163270,0.735235,-121.566437,0.074339,0.000000
53.050003,9.639977,-121.610924,0.007756,0.002910,0.073922,42.880756,2.184450,0.739224,-121.610924,0.074772,0.000000
53.310001,9.747589,-121.566437,0.007765,0.002927,0.074356,43.359444,2.208835,0.743558,-121.566437,0.075206,0.000000
53.570004,9.812386,-121.610924,0.007787,0.002941,0.074712,43.647671,2.223518,0.747116,-121.610924,0.075640,0.000000
53.830002,10.051445,-121.699883,0.007804,0.002961,0.075197,44.711060,2.277690,0.751972,-121.699883,0.076073,0.000000
54.090004,10.038040,-121.566437,0.007808,0.002975,0.075553,44.651432,2.274652,0.755526,-121.566437,0.076507,0.000000
54.350002,10.509094,-121.610924,0.007825,0.002998,0.076151,46.746784,2.381395,0.761510,-121.610924,0.076940,0.000000
54.610004,10.590271,-121.699883,0.007851,0.003016,0.076602,47.107880,2.399790,0.766021,-121.699883,0.077374,0.000000
54.870003,10.598465,-121.655403,0.007877,0.003029,0.076949,47.144325,2.401647,0.769488,-121.655403,0.077808,0.000000
55.130001,10.590645,-121.699883,0.007877,0.003043,0.077305,47.109543,2.399874,0.773046,-121.699883,0.078241,0.000000
55.390003,11.088135,-121.655403,0.007907,0.003063,0.077808,49.322487,2.512607,0.778076,-121.655403,0.078675,0.000000
55.650002,11.160370,-121.655403,0.007920,0.003078,0.078180,49.643806,2.528976,0.781804,-121.655403,0.079108,0.000000
55.910004,11.141380,-121.744362,0.007916,0.003091,0.078510,49.559334,2.524673,0.785101,-121.744362,0.079542,0.000000
56.170002,11.444489,-121.610924,0.007950,0.003109,0.078978,50.907627,2.593358,0.789783,-121.610924,0.079976,0.000000
56.430004,11.954643,-121.744362,0.007955,0.003134,0.079611,53.176910,2.708961,0.796115,-121.744362,0.080409,0.000000
56.690002,11.879051,-121.699883,0.007985,0.003148,0.079967,52.840660,2.691832,0.799669,-121.699883,0.080843,0.000000
56.950005,11.933792,-121.655403,0.007994,0.003163,0.080348,53.084160,2.704236,0.803484,-121.655403,0.081276,0.000000
57.210003,12.247696,-121.744362,0.008006,0.003181,0.080800,54.480473,2.775367,0.807996,-121.744362,0.081710,0.000000
57.470001,12.526237,-121.699883,0.008028,0.003198,0.081233,55.719486,2.838486,0.812329,-121.699883,0.082144,0.000000
57.730003,12.351219,-121.788841,0.008041,0.003209,0.081502,54.940968,2.798826,0.815020,-121.788841,0.082577,0.000000
57.990002,12.798439,-121.788841,0.008045,0.003230,0.082048,56.930302,2.900168,0.820482,-121.788841,0.083011,0.000000
58.250004,13.624733,-121.744362,0.008084,0.003255,0.082673,60.605839,3.087409,0.826727,-121.744362,0.083444,0.000000
58.510002,13.543930,-121.744362,0.008084,0.003268,0.083002,60.246410,3.069098,0.830020,-121.744362,0.083878,0.000000
58.770004,13.519348,-121.744362,0.008106,0.003281,0.083349,60.137066,3.063528,0.833491,-121.744362,0.084312,0.000000
59.030003,13.649307,-121.833328,0.008123,0.003298,0.083757,60.715153,3.092977,0.837567,-121.833328,0.084745,0.000000
59.290001,14.329262,-121.788841,0.008136,0.003320,0.084329,63.739738,3.247057,0.843290,-121.788841,0.085179,0.000000
59.550003,14.321442,-121.788841,0.008157,0.003330,0.084589,63.704952,3.245285,0.845894,-121.788841,0.085612,0.000000
59.810001,14.674820,-121.788841,0.008157,0.003347,0.085023,65.276863,3.325362,0.850227,-121.788841,0.086046,0.000000
60.070004,14.944420,-121.744362,0.008166,0.003366,0.085491,66.476097,3.386454,0.854909,-121.744362,0.086471,0.000000
60.330002,15.631447,-121.922287,0.008188,0.003387,0.086029,69.532150,3.542136,0.860288,-121.922287,0.086905,0.000000
60.590004,15.693634,-121.788841,0.008213,0.003403,0.086428,69.808769,3.556228,0.864277,-121.788841,0.087338,0.000000
60.850002,15.832901,-121.788841,0.008222,0.003416,0.086766,70.428261,3.587787,0.867661,-121.788841,0.087772,0.000000
61.110004,16.142715,-121.833328,0.008231,0.003432,0.087182,71.806381,3.657992,0.871820,-121.833328,0.088205,0.000000
61.370003,16.810753,-121.788841,0.008257,0.003453,0.087694,74.777962,3.809371,0.876937,-121.788841,0.088639,0.000000
61.630001,16.761597,-121.788841,0.008257,0.003462,0.087945,74.559303,3.798232,0.879454,-121.788841,0.089073,0.000000
61.890003,17.632202,-121.833328,0.008265,0.003488,0.088587,78.431953,3.995514,0.885870,-121.833328,0.089506,0.000000
62.150002,18.465576,-121.877808,0.008304,0.003512,0.089194,82.138985,4.184359,0.891941,-121.877808,0.089940,0.000000
62.410004,18.369133,-121.966766,0.008304,0.003525,0.089524,81.709984,4.162505,0.895237,-121.966766,0.090373,0.000000
62.670002,18.641708,-121.833328,0.008321,0.003541,0.089931,82.922462,4.224272,0.899314,-121.833328,0.090807,0.000000
62.930004,18.915398,-121.877808,0.008343,0.003555,0.090304,84.139893,4.286290,0.903042,-121.877808,0.091241,0.000000
63.190002,19.501884,-121.877808,0.008343,0.003573,0.090764,86.748718,4.419190,0.907637,-121.877808,0.091674,0.000000
63.450005,19.840378,-121.877808,0.008364,0.003587,0.091119,88.254410,4.495894,0.911195,-121.877808,0.092108,0.000000
63.710003,20.133430,-121.966766,0.008373,0.003601,0.091466,89.557968,4.562300,0.914662,-121.966766,0.092542,0.000000
63.970001,21.038666,-121.877808,0.008382,0.003624,0.092048,93.584656,4.767430,0.920475,-121.877808,0.092975,0.000000
64.230003,21.256134,-121.966766,0.008399,0.003637,0.092377,94.552010,4.816709,0.923768,-121.966766,0.093409,0.000000
64.490005,22.009071,-121.922287,0.008412,0.003658,0.092915,97.901237,4.987327,0.929146,-121.922287,0.093842,0.000000
64.750000,22.278671,-121.966766,0.008425,0.003672,0.093261,99.100479,5.048419,0.932613,-121.966766,0.094276,0.000000
65.010002,23.214439,-121.966766,0.008425,0.003695,0.093842,103.262985,5.260467,0.938423,-121.966766,0.094710,0.000000
65.270004,23.553299,-121.966766,0.008446,0.003710,0.094241,104.770309,5.337254,0.942412,-121.966766,0.095143,0.000000
65.530006,23.764809,-122.011246,0.008468,0.003722,0.094545,105.711151,5.385183,0.945448,-122.011246,0.095577,0.000000
65.790001,24.723297,-121.966766,0.008476,0.003744,0.095109,109.974716,5.602379,0.951087,-121.966766,0.096011,0.000000
66.050003,25.275146,-122.011246,0.008498,0.003764,0.095594,112.429466,5.727430,0.955943,-122.011246,0.096444,0.000000
66.310005,25.996811,-121.966766,0.008494,0.003782,0.096054,115.639587,5.890962,0.960538,-121.966766,0.096878,0.000000
66.570000,26.363220,-122.011246,0.008511,0.003796,0.096427,117.269463,5.973991,0.964270,-122.011246,0.097312,0.000000
66.830002,26.867790,-122.055733,0.008511,0.003812,0.096834,119.513901,6.088328,0.968343,-122.055733,0.097745,0.000000
67.090004,27.750313,-122.011246,0.008532,0.003831,0.097303,123.439560,6.288311,0.973028,-122.011246,0.098179,0.000000
67.350006,28.188591,-122.011246,0.008550,0.003844,0.097641,125.389114,6.387626,0.976408,-122.011246,0.098612,0.000000
67.610001,28.551659,-122.055733,0.008550,0.003857,0.097979,127.004120,6.469898,0.979792,-122.055733,0.099046,0.000000
67.870003,29.889214,-122.011246,0.008567,0.003884,0.098647,132.953857,6.772993,0.986469,-122.011246,0.099480,0.000000
68.130005,30.918457,-122.100212,0.008567,0.003903,0.099124,137.532166,7.006223,0.991238,-122.100212,0.099913,0.000000
68.390007,31.122139,-122.011246,0.008589,0.003916,0.099471,138.438187,7.052377,0.994708,-122.011246,0.100347,0.000000
68.650002,31.547768,-122.055733,0.008601,0.003929,0.099800,140.331482,7.148826,0.998005,-122.055733,0.100780,0.000000
68.910004,32.798935,-122.055733,0.008597,0.003952,0.100373,145.896942,7.432345,1.003728,-122.055733,0.101214,0.000000
69.170006,33.418564,-122.055733,0.008614,0.003967,0.100772,148.653198,7.572755,1.007717,-122.055733,0.101639,0.000000
69.430000,33.628578,-122.100212,0.008627,0.003978,0.101032,149.587387,7.620345,1.010317,-122.100212,0.102073,0.000000
69.690002,35.064819,-122.100212,0.008636,0.004000,0.101613,155.976105,7.945802,1.016127,-122.100212,0.102506,0.000000
69.950005,36.024796,-122.055733,0.008645,0.004021,0.102133,160.246292,8.163335,1.021331,-122.055733,0.102940,0.000000
70.210007,36.743851,-122.144691,0.008645,0.004037,0.102549,163.444809,8.326276,1.025495,-122.144691,0.103373,0.000000
70.470001,37.304642,-122.100212,0.008658,0.004050,0.102879,165.939331,8.453353,1.028791,-122.100212,0.103807,0.000000
70.730003,38.202805,-122.189171,0.008670,0.004068,0.103321,169.934555,8.656879,1.033212,-122.189171,0.104241,0.000000
70.990005,38.887596,-122.144691,0.008688,0.004086,0.103781,172.980667,8.812056,1.037811,-122.144691,0.104674,0.000000
71.250000,39.715385,-122.144691,0.008675,0.004101,0.104163,176.662857,8.999635,1.041626,-122.144691,0.105108,0.000000
71.510002,40.674240,-122.189171,0.008688,0.004121,0.104666,180.928055,9.216914,1.046656,-122.189171,0.105541,0.000000
71.770004,41.887802,-122.100212,0.008701,0.004138,0.105116,186.326248,9.491912,1.051164,-122.100212,0.105975,0.000000
72.030006,42.353271,-122.189171,0.008705,0.004151,0.105429,188.396759,9.597388,1.054286,-122.189171,0.106409,0.000000
72.290001,43.536667,-122.144691,0.008727,0.004172,0.105975,193.660767,9.865550,1.059752,-122.144691,0.106842,0.000000
72.550003,44.232262,-122.189171,0.008722,0.004189,0.106400,196.754929,10.023174,1.063998,-122.189171,0.107276,0.000000
72.810005,45.576523,-122.189171,0.008735,0.004208,0.106894,202.734497,10.327787,1.068941,-122.189171,0.107709,0.000000
73.070000,45.976822,-122.144691,0.008731,0.004221,0.107206,204.515121,10.418497,1.072064,-122.144691,0.108143,0.000000
73.330002,46.678749,-122.233650,0.008761,0.004233,0.107519,207.637451,10.577557,1.075186,-122.233650,0.108577,0.000000
73.590004,48.320534,-122.189171,0.008761,0.004259,0.108178,214.940475,10.949590,1.081776,-122.189171,0.109010,0.000000
73.850006,49.119652,-122.233650,0.008783,0.004274,0.108559,218.495117,11.130672,1.085595,-122.233650,0.109444,0.000000
74.110001,50.144791,-122.278137,0.008770,0.004292,0.109019,223.055176,11.362972,1.090190,-122.278137,0.109877,0.000000
74.370003,50.899590,-122.233650,0.008791,0.004308,0.109435,226.412689,11.534012,1.094353,-122.233650,0.110311,0.000000
74.630005,51.970161,-122.278137,0.008804,0.004325,0.109860,231.174820,11.776607,1.098600,-122.278137,0.110745,0.000000
74.890007,52.676178,-122.189171,0.008795,0.004339,0.110207,234.315338,11.936593,1.102071,-122.189171,0.111178,0.000000
75.150002,53.699455,-122.278137,0.008813,0.004357,0.110667,238.867111,12.168471,1.106665,-122.278137,0.111612,0.000000
75.410004,54.169762,-122.322617,0.008813,0.004365,0.110866,240.959137,12.275043,1.108660,-122.322617,0.112045,0.000000
75.670006,56.292290,-122.233650,0.008826,0.004395,0.111621,250.400604,12.756016,1.116207,-122.233650,0.112479,0.000000
75.930000,57.431000,-122.278137,0.008830,0.004412,0.112071,255.465851,13.014050,1.120715,-122.278137,0.112913,0.000000
76.190002,58.117653,-122.322617,0.008830,0.004426,0.112427,258.520233,13.169648,1.124273,-122.322617,0.113346,0.000000
76.450005,58.850113,-122.322617,0.008852,0.004441,0.112791,261.778381,13.335626,1.127914,-122.322617,0.113780,0.000000
76.710007,60.035378,-122.278137,0.008843,0.004457,0.113216,267.050690,13.604211,1.132164,-122.278137,0.114214,0.000000
76.970001,61.292130,-122.322617,0.008864,0.004475,0.113676,272.641022,13.888995,1.136759,-122.322617,0.114647,0.000000
77.230003,62.043953,-122.322617,0.008856,0.004488,0.113988,275.985291,14.059361,1.139882,-122.322617,0.115081,0.000000
77.490005,62.961105,-122.322617,0.008864,0.004506,0.114448,280.064972,14.267190,1.144477,-122.322617,0.115515,0.000000
77.750000,65.056824,-122.367096,0.008869,0.004529,0.115037,289.387207,14.742087,1.150373,-122.367096,0.115948,0.000000
78.010002,66.144882,-122.322617,0.008869,0.004545,0.115445,294.227142,14.988645,1.154450,-122.322617,0.116382,0.000000
78.270004,66.840103,-122.367096,0.008890,0.004559,0.115809,297.319641,15.146184,1.158095,-122.367096,0.116807,0.000000
78.530006,67.617996,-122.411575,0.008877,0.004562,0.115887,300.779877,15.322456,1.158874,-122.411575,0.116130,0.000000
78.790001,67.000229,-122.278137,0.008899,0.004562,0.115887,298.031891,15.182469,1.158874,-122.278137,0.116130,0.000000
79.050003,66.478531,-122.322617,0.008899,0.004559,0.115809,295.711273,15.064250,1.158095,-122.322617,0.115887,0.000000
79.310005,66.001160,-122.411575,0.008890,0.004558,0.115783,293.587830,14.956077,1.157833,-122.411575,0.115887,0.000000
79.570007,65.593399,-122.367096,0.008908,0.004558,0.115766,291.774017,14.863676,1.157659,-122.367096,0.115887,0.000000
79.830002,65.232574,-122.411575,0.008912,0.004557,0.115757,290.168976,14.781913,1.157572,-122.411575,0.115887,0.000000
80.090004,64.898560,-122.411575,0.008921,0.004557,0.115749,288.683197,14.706223,1.157485,-122.411575,0.115887,0.000000
80.350006,64.622253,-122.411575,0.008912,0.004557,0.115740,287.454132,14.643612,1.157398,-122.411575,0.115887,0.000000
80.610001,64.334412,-122.456055,0.008912,0.004557,0.115740,286.173767,14.578386,1.157398,-122.456055,0.115887,0.000000
80.870003,64.099823,-122.367096,0.008925,0.004557,0.115740,285.130249,14.525228,1.157398,-122.367096,0.115887,0.000000
81.130005,63.879745,-122.456055,0.008912,0.004557,0.115740,284.151306,14.475357,1.157398,-122.456055,0.115887,0.000000
81.390007,63.658554,-122.411575,0.008925,0.004556,0.115731,283.167389,14.425235,1.157311,-122.411575,0.115887,0.000000
81.650002,63.479080,-122.456055,0.008929,0.004556,0.115731,282.369049,14.384564,1.157311,-122.456055,0.115887,0.000000
81.910004,63.300339,-122.500542,0.008921,0.004556,0.115731,281.573975,14.344062,1.157311,-122.500542,0.115887,0.000000
82.170006,63.140213,-122.456055,0.008925,0.004556,0.115731,280.861694,14.307777,1.157311,-122.456055,0.115887,0.000000
82.430000,62.953285,-122.545021,0.008921,0.004556,0.115731,280.030212,14.265418,1.157311,-122.545021,0.115887,0.000000
82.690002,62.838966,-122.411575,0.008938,0.004556,0.115731,279.521667,14.239513,1.157311,-122.411575,0.115887,0.000000
82.950005,62.691505,-122.456055,0.008933,0.004556,0.115731,278.865753,14.206098,1.157311,-122.456055,0.115887,0.000000
83.210007,62.555595,-122.500542,0.008933,0.004556,0.115731,278.261200,14.175300,1.157311,-122.500542,0.115887,0.000000
83.470001,62.424889,-122.500542,0.008933,0.004556,0.115731,277.679779,14.145682,1.157311,-122.500542,0.115887,0.000000
83.730003,62.316902,-122.633980,0.008925,0.004556,0.115731,277.199432,14.121212,1.157311,-122.633980,0.115887,0.000000
83.990005,62.208168,-122.545021,0.008942,0.004556,0.115723,276.715759,14.096572,1.157228,-122.545021,0.115887,0.000000
84.250008,62.078209,-122.545021,0.008933,0.004556,0.115723,276.137665,14.067122,1.157228,-122.545021,0.115887,0.000000
84.510002,61.998894,-122.545021,0.008942,0.004556,0.115723,275.784851,14.049150,1.157228,-122.545021,0.115887,0.000000
84.770004,61.898354,-122.633980,0.008938,0.004556,0.115723,275.337616,14.026367,1.157228,-122.633980,0.115887,0.000000
85.030006,61.804146,-122.545021,0.008942,0.004556,0.115723,274.918579,14.005020,1.157228,-122.545021,0.115887,0.000000
85.290001,61.698021,-122.500542,0.008933,0.004556,0.115723,274.446503,13.980971,1.157228,-122.500542,0.115887,0.000000
85.550003,61.615723,-122.589500,0.008951,0.004556,0.115723,274.080414,13.962322,1.157228,-122.589500,0.115887,0.000000
85.810005,61.540878,-122.545021,0.008942,0.004556,0.115723,273.747498,13.945362,1.157228,-122.545021,0.115887,0.000000
86.070007,61.448898,-122.545021,0.008933,0.004556,0.115723,273.338348,13.924520,1.157228,-122.545021,0.115887,0.000000
86.330002,61.364372,-122.678467,0.008942,0.004556,0.115723,272.962372,13.905365,1.157228,-122.678467,0.115887,0.000000
86.590004,61.311493,-122.545021,0.008946,0.004556,0.115723,272.727142,13.893383,1.157228,-122.545021,0.115887,0.000000
86.850006,61.237022,-122.633980,0.008951,0.004556,0.115723,272.395874,13.876508,1.157228,-122.633980,0.115887,0.000000
87.110001,61.154350,-122.589500,0.008946,0.004556,0.115723,272.028137,13.857774,1.157228,-122.589500,0.115887,0.000000
87.370003,61.085838,-122.589500,0.008951,0.004556,0.115723,271.723389,13.842249,1.157228,-122.589500,0.115887,0.000000
87.630005,61.034081,-122.678467,0.008938,0.004556,0.115723,271.493164,13.830521,1.157228,-122.678467,0.115887,0.000000
87.890007,60.961838,-122.633980,0.008951,0.004556,0.115723,271.171783,13.814150,1.157228,-122.633980,0.115887,0.000000
88.150002,60.899651,-122.678467,0.008946,0.004556,0.115723,270.895172,13.800057,1.157228,-122.678467,0.115887,0.000000
88.410004,60.840446,-122.633980,0.008951,0.004556,0.115723,270.631836,13.786642,1.157228,-122.633980,0.115887,0.000000
88.670006,60.780495,-122.633980,0.008951,0.004556,0.115723,270.365143,13.773057,1.157228,-122.633980,0.115887,0.000000
88.930008,60.740646,-122.722946,0.008946,0.004556,0.115723,270.187897,13.764028,1.157228,-122.722946,0.115887,0.000000
89.190002,60.667664,-122.633980,0.008955,0.004556,0.115723,269.863251,13.747489,1.157228,-122.633980,0.115887,0.000000
89.450005,60.614784,-122.678467,0.008946,0.004556,0.115723,269.628021,13.735506,1.157228,-122.678467,0.115887,0.000000
89.710007,60.565636,-122.678467,0.008946,0.004556,0.115723,269.409393,13.724369,1.157228,-122.678467,0.115887,0.000000
89.970001,60.521324,-122.678467,0.008951,0.004556,0.115723,269.212280,13.714329,1.157228,-122.678467,0.115887,0.000000
90.230003,60.464722,-122.722946,0.008942,0.004556,0.115723,268.960510,13.701502,1.157228,-122.722946,0.115887,0.000000
90.490005,60.419662,-122.722946,0.008951,0.004556,0.115723,268.760071,13.691291,1.157228,-122.722946,0.115887,0.000000
90.750008,60.383545,-122.767426,0.008951,0.004556,0.115723,268.599426,13.683106,1.157228,-122.767426,0.115887,0.000000
91.010002,60.322472,-122.678467,0.008942,0.004556,0.115723,268.327759,13.669268,1.157228,-122.678467,0.115887,0.000000
91.270004,60.291191,-122.722946,0.008951,0.004556,0.115723,268.188599,13.662179,1.157228,-122.722946,0.115887,0.000000
91.530006,60.244278,-122.811905,0.008942,0.004556,0.115723,267.979919,13.651548,1.157228,-122.811905,0.115887,0.000000
91.790001,60.191399,-122.678467,0.008946,0.004556,0.115723,267.744720,13.639565,1.157228,-122.678467,0.115887,0.000000
92.050003,60.160118,-122.767426,0.008951,0.004556,0.115723,267.605560,13.632478,1.157228,-122.767426,0.115887,0.000000
92.310005,60.105011,-122.811905,0.008951,0.004556,0.115723,267.360443,13.619990,1.157228,-122.811905,0.115887,0.000000
92.570007,60.081177,-122.767426,0.008964,0.004556,0.115723,267.254425,13.614590,1.157228,-122.767426,0.115887,0.000000
92.830002,60.036865,-122.811905,0.008959,0.004556,0.115723,267.057312,13.604548,1.157228,-122.811905,0.115887,0.000000
93.090004,59.998138,-122.811905,0.008955,0.004556,0.115723,266.885040,13.595773,1.157228,-122.811905,0.115887,0.000000
93.350006,59.967232,-122.856384,0.008964,0.004556,0.115723,266.747559,13.588769,1.157228,-122.856384,0.115887,0.000000
93.610008,59.936325,-122.811905,0.008959,0.004556,0.115714,266.610077,13.581765,1.157141,-122.811905,0.115887,0.000000
93.870003,59.881958,-122.811905,0.008942,0.004556,0.115714,266.368256,13.569446,1.157141,-122.811905,0.115887,0.000000
94.130005,59.843231,-122.856384,0.008951,0.004556,0.115714,266.195984,13.560670,1.157141,-122.856384,0.115887,0.000000
94.390007,59.823868,-122.811905,0.008951,0.004556,0.115714,266.109863,13.556282,1.157141,-122.811905,0.115887,0.000000
94.650002,59.776207,-122.900871,0.008951,0.004556,0.115714,265.897858,13.545483,1.157141,-122.900871,0.115887,0.000000
94.910004,59.742317,-122.856384,0.008959,0.004556,0.115714,265.747101,13.537803,1.157141,-122.856384,0.115887,0.000000
95.170006,59.707687,-122.900871,0.008955,0.004556,0.115714,265.593048,13.529956,1.157141,-122.900871,0.115887,0.000000
95.430008,59.681992,-122.856384,0.008951,0.004556,0.115714,265.478760,13.524133,1.157141,-122.856384,0.115887,0.000000
95.690002,59.655930,-122.856384,0.008968,0.004556,0.115714,265.362823,13.518227,1.157141,-122.856384,0.115887,0.000000
95.950005,59.596344,-122.945351,0.008951,0.004556,0.115714,265.097778,13.504725,1.157141,-122.945351,0.115887,0.000000
96.210007,59.586662,-122.856384,0.008964,0.004556,0.115714,265.054718,13.502531,1.157141,-122.856384,0.115887,0.000000
96.470001,59.546822,-122.989830,0.008972,0.004556,0.115714,264.877502,13.493503,1.157141,-122.989830,0.115887,0.000000
96.730003,59.525597,-122.945351,0.008955,0.004556,0.115714,264.783081,13.488692,1.157141,-122.945351,0.115887,0.000000
96.990005,59.490219,-122.900871,0.008959,0.004556,0.115714,264.625702,13.480677,1.157141,-122.900871,0.115887,0.000000
97.250008,59.454475,-122.989830,0.008946,0.004556,0.115714,264.466705,13.472576,1.157141,-122.989830,0.115887,0.000000
97.510002,59.430641,-122.900871,0.008968,0.004556,0.115714,264.360687,13.467175,1.157141,-122.900871,0.115887,0.000000
97.770004,59.380371,-122.989830,0.008964,0.004556,0.115714,264.137085,13.455784,1.157141,-122.989830,0.115887,0.000000
98.030006,59.360634,-122.989830,0.008968,0.004556,0.115714,264.049286,13.451312,1.157141,-122.989830,0.115887,0.000000
98.290001,59.341270,-122.989830,0.008955,0.004556,0.115714,263.963165,13.446924,1.157141,-122.989830,0.115887,0.000000
98.550003,59.312599,-122.989830,0.008964,0.004556,0.115714,263.835632,13.440427,1.157141,-122.989830,0.115887,0.000000
98.810005,59.290260,-122.989830,0.008955,0.004556,0.115714,263.736237,13.435365,1.157141,-122.989830,0.115887,0.000000
99.070007,59.249672,-122.989830,0.008968,0.004556,0.115714,263.555695,13.426167,1.157141,-122.989830,0.115887,0.000000
99.330002,59.226952,-122.989830,0.008955,0.004556,0.115714,263.454651,13.421020,1.157141,-122.989830,0.115887,0.000000
99.590004,59.199028,-123.034309,0.008964,0.004556,0.115714,263.330414,13.414692,1.157141,-123.034309,0.115887,0.000000
99.850006,59.183388,-123.034309,0.008964,0.004556,0.115714,263.260864,13.411147,1.157141,-123.034309,0.115887,0.000000
100.110008,59.142052,-123.034309,0.008964,0.004556,0.115714,263.076996,13.401780,1.157141,-123.034309,0.115887,0.000000
100.370003,59.117477,-123.123276,0.008959,0.004556,0.115714,262.967682,13.396212,1.157141,-123.123276,0.115887,0.000000
100.630005,59.113380,-122.989830,0.008964,0.004556,0.115714,262.949463,13.395284,1.157141,-122.989830,0.115887,0.000000
100.890007,59.080612,-123.034309,0.008959,0.004556,0.115714,262.803680,13.387857,1.157141,-123.034309,0.115887,0.000000
101.150002,59.059013,-123.078789,0.008964,0.004556,0.115714,262.707611,13.382963,1.157141,-123.078789,0.115887,0.000000
101.410004,59.029594,-123.078789,0.008968,0.004556,0.115714,262.576752,13.376297,1.157141,-123.078789,0.115887,0.000000
101.670006,59.007629,-123.078789,0.008964,0.004556,0.115714,262.479034,13.371320,1.157141,-123.078789,0.115887,0.000000
101.930008,58.981934,-123.123276,0.008951,0.004556,0.115714,262.364746,13.365498,1.157141,-123.123276,0.115887,0.000000
102.190002,58.975601,-123.123276,0.008964,0.004556,0.115714,262.336578,13.364062,1.157141,-123.123276,0.115887,0.000000
102.450005,58.938362,-123.034309,0.008959,0.004556,0.115714,262.170929,13.355624,1.157141,-123.034309,0.115887,0.000000
102.710007,58.921234,-123.078789,0.008959,0.004556,0.115714,262.094727,13.351742,1.157141,-123.078789,0.115887,0.000000
102.970001,58.897034,-123.123276,0.008968,0.004556,0.115714,261.987091,13.346258,1.157141,-123.123276,0.115887,0.000000
103.230003,58.878044,-123.123276,0.008968,0.004556,0.115714,261.902618,13.341955,1.157141,-123.123276,0.115887,0.000000
103.490005,58.870590,-123.167755,0.008972,0.004556,0.115714,261.869476,13.340266,1.157141,-123.167755,0.115887,0.000000
103.750008,58.834846,-123.123276,0.008955,0.004556,0.115714,261.710480,13.332168,1.157141,-123.123276,0.115887,0.000000
104.010002,58.823677,-123.167755,0.008964,0.004556,0.115714,261.660797,13.329636,1.157141,-123.167755,0.115887,0.000000
104.270004,58.804687,-123.212234,0.008964,0.004556,0.115714,261.576324,13.325333,1.157141,-123.212234,0.115887,0.000000
104.530006,58.784576,-123.123276,0.008959,0.004556,0.115714,261.486847,13.320776,1.157141,-123.123276,0.115887,0.000000
104.790009,58.770050,-123.167755,0.008959,0.004556,0.115714,261.422241,13.317484,1.157141,-123.167755,0.115887,0.000000
105.050003,58.746597,-123.167755,0.008968,0.004556,0.115714,261.317902,13.312169,1.157141,-123.167755,0.115887,0.000000
105.310005,58.706375,-123.167755,0.008968,0.004556,0.115714,261.139008,13.303055,1.157141,-123.167755,0.115887,0.000000
105.570007,58.705635,-123.256714,0.008964,0.004556,0.115714,261.135712,13.302887,1.157141,-123.256714,0.115887,0.000000
105.830002,58.688873,-123.123276,0.008972,0.004556,0.115714,261.061157,13.299089,1.157141,-123.123276,0.115887,0.000000
106.090004,58.668396,-123.123276,0.008959,0.004556,0.115714,260.970062,13.294448,1.157141,-123.123276,0.115887,0.000000
106.350006,58.642700,-123.167755,0.008951,0.004556,0.115714,260.855743,13.288627,1.157141,-123.167755,0.115887,0.000000
106.610008,58.626686,-123.256714,0.008959,0.004556,0.115714,260.784515,13.284997,1.157141,-123.256714,0.115887,0.000000
106.870003,58.604347,-123.212234,0.008955,0.004556,0.115714,260.685150,13.279935,1.157141,-123.212234,0.115887,0.000000
107.130005,58.585732,-123.256714,0.008959,0.004556,0.115714,260.602356,13.275717,1.157141,-123.256714,0.115887,0.000000
107.390007,58.576416,-123.256714,0.008959,0.004556,0.115714,260.560913,13.273606,1.157141,-123.256714,0.115887,0.000000
107.650002,58.539551,-123.212234,0.008964,0.004556,0.115714,260.396942,13.265252,1.157141,-123.212234,0.115887,0.000000
107.910004,58.542534,-123.256714,0.008964,0.004556,0.115714,260.410187,13.265927,1.157141,-123.256714,0.115887,0.000000
108.170006,58.504555,-123.301193,0.008968,0.004556,0.115714,260.241272,13.257322,1.157141,-123.301193,0.115887,0.000000
108.430008,58.500084,-123.256714,0.008968,0.004556,0.115714,260.221375,13.256309,1.157141,-123.256714,0.115887,0.000000
108.690002,58.479233,-123.345680,0.008968,0.004556,0.115714,260.128632,13.251583,1.157141,-123.345680,0.115887,0.000000
108.950005,58.452789,-123.256714,0.008959,0.004556,0.115714,260.010986,13.245592,1.157141,-123.256714,0.115887,0.000000
109.000008,58.445717,-123.256714,0.008972,0.004556,0.115714,259.979523,13.243989,1.157141,-123.256714,0.115887,0.000000