File: Data/compression 4/AutoNoheating-10-4-2-240223_02232024_162119.csv
Time (sec),S:Load (lbs),S:HL1 (DIM),S:LVDT (in),S:Position (in),Ch:Position (mm),Ch:Load (N),Ch:Stress (MPa),Ch:Strain (mm/mm),Ch:HL1 (DIM),Set Point (),Cycles ()
0.010000,-0.009315,-92.787262,0.000017,-0.000000,-0.000000,-0.041437,-0.002111,-0.000000,-92.787262,0.000191,0.000000
0.240000,0.005585,-92.876228,0.000013,-0.000000,-0.000000,0.024842,0.001266,-0.000000,-92.876228,0.000191,0.000000
0.470000,0.027924,-92.920708,0.000004,0.000072,0.001830,0.124210,0.006328,0.018296,-92.920708,0.002411,0.000000
0.700000,0.005211,-92.965187,0.000039,0.000207,0.005255,0.023179,0.001181,0.052553,-92.965187,0.006244,0.000000
0.930000,0.033508,-92.920708,0.000181,0.000351,0.008924,0.149052,0.007593,0.089236,-92.920708,0.010077,0.000000
1.160000,0.023087,-92.920708,0.000341,0.000505,0.012835,0.102694,0.005231,0.128350,-92.920708,0.013910,0.000000
1.390000,-0.017136,-92.920708,0.000517,0.000659,0.016746,-0.076223,-0.003883,0.167459,-92.920708,0.017743,0.000000
1.620000,0.006325,-92.920708,0.000660,0.000804,0.020423,0.028134,0.001433,0.204229,-92.920708,0.021577,0.000000
1.850000,0.006325,-92.920708,0.000793,0.000955,0.024256,0.028134,0.001433,0.242563,-92.920708,0.025410,0.000000
2.080000,0.022339,-92.965187,0.000949,0.001107,0.028107,0.099368,0.005062,0.281066,-92.965187,0.029243,0.000000
2.310000,0.001862,-92.965187,0.001104,0.001260,0.032001,0.008281,0.000422,0.320005,-92.965187,0.033076,0.000000
2.540000,0.019363,-92.920708,0.001272,0.001408,0.035756,0.086133,0.004388,0.357555,-92.920708,0.036909,0.000000
2.770000,-0.011543,-92.965187,0.001406,0.001561,0.039641,-0.051347,-0.002616,0.396407,-92.965187,0.040725,0.000000
3.000000,0.017128,-92.920708,0.001552,0.001713,0.043500,0.076189,0.003881,0.434998,-92.920708,0.044558,0.000000
3.230000,0.010048,-92.965187,0.001720,0.001863,0.047324,0.044695,0.002277,0.473244,-92.965187,0.048391,0.000000
3.460000,0.030533,-92.920708,0.001854,0.002009,0.051036,0.135817,0.006919,0.510363,-92.920708,0.052224,0.000000
3.690000,0.005211,-93.009666,0.002009,0.002165,0.054991,0.023179,0.001181,0.549907,-93.009666,0.056057,0.000000
3.920000,-0.022346,-92.965187,0.002147,0.002313,0.058754,-0.099402,-0.005064,0.587544,-92.965187,0.059891,0.000000
4.150000,-0.010429,-93.009666,0.002298,0.002464,0.062579,-0.046392,-0.002363,0.625787,-93.009666,0.063724,0.000000
4.380000,0.016754,-93.009666,0.002449,0.002614,0.066403,0.074526,0.003797,0.664033,-93.009666,0.067557,0.000000
4.610000,0.055107,-93.054146,0.002591,0.002766,0.070262,0.245129,0.012487,0.702624,-93.054146,0.071390,0.000000
4.840000,0.036865,-93.054146,0.002746,0.002920,0.074156,0.163985,0.008354,0.741563,-93.054146,0.075223,0.000000
5.070000,0.011169,-93.054146,0.002897,0.003073,0.078059,0.049684,0.002531,0.780589,-93.054146,0.079056,0.000000
5.300000,0.007446,-93.054146,0.003057,0.003219,0.081762,0.033123,0.001687,0.817621,-93.054146,0.082889,0.000000
5.530000,0.036865,-92.965187,0.003212,0.003374,0.085690,0.163985,0.008354,0.856904,-92.965187,0.086723,0.000000
5.760000,0.056229,-93.009666,0.003367,0.003517,0.089341,0.250117,0.012742,0.893413,-93.009666,0.090538,0.000000
5.990000,0.051384,-93.054146,0.003514,0.003668,0.093166,0.228567,0.011644,0.931659,-93.054146,0.094371,0.000000
6.220000,0.061813,-93.098633,0.003652,0.003825,0.097147,0.274960,0.014007,0.971465,-93.098633,0.098204,0.000000
6.450000,0.068138,-93.143112,0.003803,0.003973,0.100902,0.303093,0.015440,1.009015,-93.143112,0.102038,0.000000
6.680000,0.185814,-93.098633,0.003941,0.004126,0.104813,0.826542,0.042106,1.048128,-93.098633,0.105871,0.000000
6.910000,0.313538,-93.009666,0.004105,0.004276,0.108603,1.394685,0.071049,1.086026,-93.009666,0.109704,0.000000
7.140000,0.468811,-93.098633,0.004243,0.004420,0.112280,2.085376,0.106234,1.122797,-93.098633,0.113537,0.000000
7.370000,0.665428,-93.054146,0.004402,0.004582,0.116373,2.959972,0.150788,1.163730,-93.054146,0.117370,0.000000
7.600000,0.589462,-93.143112,0.004437,-0.000000,-0.000000,2.622059,0.133574,-0.000000,-93.143112,0.000243,0.000000
7.830000,0.573074,-93.054146,0.004454,-0.000000,-0.000000,2.549162,0.129860,-0.000000,-93.054146,0.000243,0.000000
8.060000,0.537331,-93.054146,0.004467,-0.000000,-0.000000,2.390166,0.121761,-0.000000,-93.054146,0.000373,0.000000
8.290000,0.516479,-93.143112,0.004475,-0.000000,-0.000000,2.297415,0.117036,-0.000000,-93.143112,0.000763,0.000000
8.520000,0.513870,-93.143112,0.004458,-0.000000,-0.000000,2.285809,0.116445,-0.000000,-93.143112,0.001145,0.000000
8.750000,0.596909,-93.187592,0.004458,0.000027,0.000685,2.655182,0.135261,0.006851,-93.187592,0.001526,0.000000
8.980000,0.618507,-93.143112,0.004462,0.000042,0.001067,2.751258,0.140156,0.010666,-93.143112,0.001908,0.000000
9.210000,0.648666,-93.143112,0.004484,0.000052,0.001310,2.885412,0.146990,0.013096,-93.143112,0.002289,0.000000
9.440001,0.696709,-93.187592,0.004506,0.000071,0.001795,3.099115,0.157876,0.017952,-93.187592,0.002680,0.000000
9.670000,0.726868,-93.187592,0.004523,0.000088,0.002229,3.233269,0.164711,0.022285,-93.187592,0.003061,0.000000
9.900001,0.740646,-93.143112,0.004527,0.000102,0.002602,3.294559,0.167833,0.026017,-93.143112,0.003443,0.000000
10.130000,0.741760,-93.143112,0.004549,0.000117,0.002983,3.299514,0.168085,0.029833,-93.143112,0.003824,0.000000
10.360001,0.774529,-93.187592,0.004553,0.000130,0.003313,3.445275,0.175511,0.033129,-93.187592,0.004206,0.000000
10.590000,0.803574,-93.187592,0.004587,0.000150,0.003799,3.574474,0.182092,0.037985,-93.187592,0.004596,0.000000
10.820001,0.808792,-93.232071,0.004583,0.000163,0.004128,3.597687,0.183275,0.041278,-93.232071,0.004978,0.000000
11.050000,0.791290,-93.232071,0.004600,0.000171,0.004336,3.519835,0.179309,0.043360,-93.232071,0.005359,0.000000
11.280001,0.853477,-93.187592,0.004605,0.000192,0.004874,3.796458,0.193401,0.048738,-93.187592,0.005741,0.000000
11.510000,0.903000,-93.232071,0.004635,0.000210,0.005342,4.016744,0.204623,0.053420,-93.232071,0.006122,0.000000
11.740001,0.889595,-93.232071,0.004648,0.000224,0.005689,3.957116,0.201585,0.056891,-93.232071,0.006513,0.000000
11.970000,0.871719,-93.232071,0.004656,0.000238,0.006044,3.877601,0.197534,0.060445,-93.232071,0.006895,0.000000
12.200001,0.903000,-93.143112,0.004674,0.000251,0.006374,4.016744,0.204623,0.063741,-93.143112,0.007276,0.000000
12.430000,0.943588,-93.276558,0.004682,0.000269,0.006834,4.197290,0.213820,0.068336,-93.276558,0.007658,0.000000
12.660001,0.963699,-93.232071,0.004704,0.000282,0.007155,4.286749,0.218377,0.071546,-93.232071,0.008039,0.000000
12.890000,0.959976,-93.321037,0.004704,0.000291,0.007389,4.270187,0.217534,0.073889,-93.321037,0.008429,0.000000
13.120001,0.978966,-93.232071,0.004725,0.000304,0.007718,4.354657,0.221837,0.077182,-93.232071,0.008811,0.000000
13.350000,1.036682,-93.276558,0.004751,0.000328,0.008325,4.611392,0.234916,0.083253,-93.276558,0.009192,0.000000
13.580001,1.048599,-93.232071,0.004764,0.000344,0.008750,4.664402,0.237616,0.087503,-93.232071,0.009574,0.000000
13.810000,1.060883,-93.276558,0.004777,0.000355,0.009010,4.719041,0.240399,0.090103,-93.276558,0.009956,0.000000
14.040001,1.069824,-93.276558,0.004794,0.000371,0.009435,4.758816,0.242426,0.094354,-93.276558,0.010346,0.000000
14.270000,1.091049,-93.365517,0.004794,0.000385,0.009791,4.853229,0.247235,0.097908,-93.365517,0.010728,0.000000
14.500001,1.129402,-93.321037,0.004816,0.000401,0.010190,5.023832,0.255926,0.101897,-93.321037,0.011109,0.000000
14.730000,1.133125,-93.276558,0.004825,0.000413,0.010485,5.040393,0.256770,0.104845,-93.276558,0.011491,0.000000
14.960001,1.146156,-93.276558,0.004850,0.000424,0.010771,5.098358,0.259723,0.107711,-93.276558,0.011881,0.000000
15.190001,1.177063,-93.321037,0.004859,0.000441,0.011196,5.235837,0.266726,0.111957,-93.321037,0.012263,0.000000
15.420001,1.241112,-93.321037,0.004863,0.000465,0.011820,5.520741,0.281240,0.118202,-93.321037,0.012644,0.000000
15.650001,1.249680,-93.365517,0.004876,0.000479,0.012176,5.558852,0.283181,0.121756,-93.365517,0.013026,0.000000
15.880001,1.236649,-93.321037,0.004907,0.000491,0.012470,5.500887,0.280229,0.124705,-93.321037,0.013407,0.000000
16.110001,1.230316,-93.365517,0.004919,0.000506,0.012852,5.472720,0.278794,0.128524,-93.365517,0.013797,0.000000
16.340000,1.259735,-93.365517,0.004924,0.000518,0.013165,5.603581,0.285460,0.131646,-93.365517,0.014179,0.000000
16.570002,1.347984,-93.365517,0.004937,0.000537,0.013633,5.996134,0.305458,0.136328,-93.365517,0.014560,0.000000
16.800001,1.350220,-93.365517,0.004941,0.000549,0.013954,6.006077,0.305964,0.139538,-93.365517,0.014942,0.000000
17.030001,1.369209,-93.321037,0.004971,0.000564,0.014335,6.090547,0.310267,0.143353,-93.321037,0.015324,0.000000
17.260000,1.413521,-93.365517,0.004988,0.000584,0.014838,6.287654,0.320308,0.148383,-93.365517,0.015714,0.000000
17.490002,1.430649,-93.409996,0.005001,0.000600,0.015246,6.363844,0.324190,0.152459,-93.409996,0.016096,0.000000
17.720001,1.407936,-93.409996,0.005014,0.000613,0.015575,6.262813,0.319043,0.155752,-93.409996,0.016477,0.000000
17.950001,1.404213,-93.365517,0.005036,0.000626,0.015896,6.246251,0.318199,0.158962,-93.365517,0.016859,0.000000
18.180000,1.436607,-93.409996,0.005044,0.000641,0.016278,6.390349,0.325540,0.162777,-93.409996,0.017241,0.000000
18.410002,1.479431,-93.454475,0.005062,0.000656,0.016668,6.580838,0.335244,0.166679,-93.454475,0.017631,0.000000
18.640001,1.528587,-93.454475,0.005079,0.000670,0.017015,6.799496,0.346383,0.170150,-93.454475,0.018012,0.000000
18.870001,1.584442,-93.365517,0.005070,0.000687,0.017448,7.047951,0.359040,0.174484,-93.365517,0.018394,0.000000
19.100000,1.603432,-93.454475,0.005113,0.000706,0.017943,7.132421,0.363343,0.179427,-93.454475,0.018775,0.000000
19.330002,1.605667,-93.409996,0.005126,0.000722,0.018342,7.142364,0.363849,0.183416,-93.409996,0.019157,0.000000
19.560001,1.624657,-93.454475,0.005139,0.000738,0.018741,7.226834,0.368152,0.187405,-93.454475,0.019547,0.000000
19.790001,1.598961,-93.454475,0.005165,0.000749,0.019027,7.112533,0.362330,0.190270,-93.454475,0.019929,0.000000
20.020000,1.641785,-93.454475,0.005157,0.000766,0.019460,7.303023,0.372034,0.194604,-93.454475,0.020311,0.000000
20.250002,1.698761,-93.454475,0.005182,0.000780,0.019807,7.556466,0.384945,0.198075,-93.454475,0.020692,0.000000
20.480001,1.705833,-93.454475,0.005208,0.000794,0.020172,7.587926,0.386547,0.201716,-93.454475,0.021074,0.000000
20.710001,1.735252,-93.498962,0.005221,0.000807,0.020501,7.718788,0.393214,0.205013,-93.498962,0.021464,0.000000
20.940001,1.759827,-93.543442,0.005221,0.000820,0.020839,7.828100,0.398782,0.208393,-93.543442,0.021845,0.000000
21.170000,1.839890,-93.454475,0.005243,0.000846,0.021490,8.184237,0.416925,0.214899,-93.454475,0.022227,0.000000
21.400002,1.829834,-93.454475,0.005260,0.000860,0.021837,8.139508,0.414646,0.218366,-93.454475,0.022609,0.000000
21.630001,1.775093,-93.498962,0.005286,0.000870,0.022088,7.896008,0.402242,0.220883,-93.498962,0.022990,0.000000
21.860001,1.760948,-93.498962,0.005299,0.000883,0.022418,7.833089,0.399037,0.224176,-93.498962,0.023380,0.000000
22.090000,1.859253,-93.498962,0.005295,0.000902,0.022904,8.270370,0.421313,0.229035,-93.498962,0.023762,0.000000
22.320002,1.932236,-93.498962,0.005312,0.000919,0.023354,8.595014,0.437851,0.233543,-93.498962,0.024143,0.000000
22.550001,1.938568,-93.498962,0.005338,0.000931,0.023658,8.623181,0.439286,0.236579,-93.498962,0.024525,0.000000
22.780001,1.988838,-93.543442,0.005346,0.000946,0.024022,8.846794,0.450677,0.240220,-93.543442,0.024915,0.000000
23.010000,1.954582,-93.587921,0.005364,0.000958,0.024326,8.694416,0.442915,0.243255,-93.587921,0.025297,0.000000
23.240002,2.039856,-93.587921,0.005376,0.000977,0.024811,9.073732,0.462238,0.248111,-93.587921,0.025679,0.000000
23.470001,1.987724,-93.543442,0.005389,0.000985,0.025019,8.841839,0.450425,0.250193,-93.543442,0.026060,0.000000
23.700001,2.044693,-93.587921,0.005398,0.001003,0.025479,9.095248,0.463334,0.254792,-93.587921,0.026442,0.000000
23.930000,2.024216,-93.543442,0.005411,0.001015,0.025783,9.004161,0.458694,0.257827,-93.543442,0.026832,0.000000
24.160002,2.148956,-93.632401,0.005420,0.001037,0.026338,9.559035,0.486960,0.263376,-93.632401,0.027213,0.000000
24.390001,2.154915,-93.632401,0.005441,0.001051,0.026702,9.585540,0.488311,0.267017,-93.632401,0.027595,0.000000
24.620001,2.196251,-93.587921,0.005445,0.001066,0.027075,9.769412,0.497678,0.270749,-93.587921,0.027977,0.000000
24.850000,2.193268,-93.587921,0.005467,0.001080,0.027439,9.756143,0.497002,0.274390,-93.587921,0.028358,0.000000
25.080002,2.222313,-93.587921,0.005489,0.001098,0.027898,9.885342,0.503583,0.278985,-93.587921,0.028749,0.000000
25.310001,2.252853,-93.632401,0.005497,0.001114,0.028297,10.021193,0.510504,0.282974,-93.632401,0.029130,0.000000
25.540001,2.233116,-93.676880,0.005519,0.001128,0.028662,9.933396,0.506031,0.286619,-93.676880,0.029512,0.000000
25.770000,2.250618,-93.632401,0.005523,0.001140,0.028948,10.011249,0.509997,0.289480,-93.632401,0.029893,0.000000
26.000002,2.310196,-93.543442,0.005545,0.001158,0.029416,10.276265,0.523498,0.294162,-93.543442,0.030275,0.000000
26.230001,2.354507,-93.676880,0.005558,0.001175,0.029850,10.473372,0.533539,0.298500,-93.676880,0.030665,0.000000
26.460001,2.372009,-93.676880,0.005575,0.001189,0.030188,10.551225,0.537505,0.301879,-93.676880,0.031047,0.000000
26.690001,2.320625,-93.676880,0.005583,0.001197,0.030396,10.322657,0.525861,0.303961,-93.676880,0.031428,0.000000
26.920002,2.394348,-93.676880,0.005583,0.001215,0.030865,10.650593,0.542567,0.308647,-93.676880,0.031810,0.000000
27.150002,2.494522,-93.632401,0.005618,0.001238,0.031446,11.096189,0.565267,0.314457,-93.632401,0.032191,0.000000
27.380001,2.444618,-93.676880,0.005631,0.001252,0.031810,10.874205,0.553958,0.318098,-93.676880,0.032582,0.000000
27.610001,2.440529,-93.721367,0.005644,0.001265,0.032122,10.856014,0.553032,0.321220,-93.721367,0.032963,0.000000
27.840002,2.479256,-93.676880,0.005652,0.001279,0.032495,11.028280,0.561807,0.324948,-93.676880,0.033345,0.000000
28.070002,2.546654,-93.721367,0.005657,0.001296,0.032929,11.328082,0.577080,0.329286,-93.721367,0.033726,0.000000
28.300001,2.569740,-93.632401,0.005683,0.001310,0.033284,11.430776,0.582312,0.332840,-93.632401,0.034108,0.000000
28.530001,2.549629,-93.721367,0.005691,0.001320,0.033527,11.341317,0.577754,0.335270,-93.721367,0.034498,0.000000
28.760002,2.644958,-93.765846,0.005713,0.001339,0.034013,11.765363,0.599356,0.340126,-93.765846,0.034880,0.000000
28.990002,2.685921,-93.676880,0.005721,0.001357,0.034472,11.947572,0.608638,0.344721,-93.676880,0.035261,0.000000
29.220001,2.677353,-93.721367,0.005730,0.001372,0.034837,11.909460,0.606697,0.348366,-93.721367,0.035643,0.000000
29.450001,2.662834,-93.721367,0.005760,0.001387,0.035218,11.844878,0.603407,0.352181,-93.721367,0.036025,0.000000
29.680002,2.645332,-93.765846,0.005764,0.001397,0.035487,11.767026,0.599441,0.354868,-93.765846,0.036415,0.000000
29.910002,2.706398,-93.765846,0.005773,0.001412,0.035860,12.038660,0.613279,0.358596,-93.765846,0.036796,0.000000
30.140001,2.811783,-93.765846,0.005790,0.001430,0.036319,12.507435,0.637159,0.363195,-93.765846,0.037178,0.000000
30.370001,2.783478,-93.721367,0.005812,0.001443,0.036640,12.381528,0.630745,0.366401,-93.721367,0.037559,0.000000
30.600002,2.809174,-93.810326,0.005833,0.001458,0.037022,12.495829,0.636568,0.370219,-93.810326,0.037941,0.000000
30.830002,2.887749,-93.765846,0.005833,0.001474,0.037438,12.845347,0.654373,0.374379,-93.765846,0.038331,0.000000
31.060001,2.891472,-93.810326,0.005855,0.001491,0.037880,12.861909,0.655217,0.378804,-93.810326,0.038713,0.000000
31.290001,2.914932,-93.810326,0.005868,0.001507,0.038279,12.966267,0.660533,0.382793,-93.810326,0.039095,0.000000
31.520002,2.923119,-93.810326,0.005877,0.001520,0.038609,13.002681,0.662388,0.386090,-93.810326,0.039476,0.000000
31.750002,2.958122,-93.810326,0.005890,0.001534,0.038973,13.158385,0.670320,0.389731,-93.810326,0.039866,0.000000
31.980001,2.986053,-93.810326,0.005911,0.001553,0.039441,13.282629,0.676649,0.394413,-93.810326,0.040248,0.000000
32.210003,2.998337,-93.810326,0.005924,0.001565,0.039745,13.337268,0.679433,0.397448,-93.810326,0.040629,0.000000
32.440002,2.993126,-93.854805,0.005924,0.001577,0.040048,13.314089,0.678252,0.400484,-93.854805,0.041011,0.000000
32.670002,3.105209,-93.810326,0.005946,0.001595,0.040517,13.812661,0.703651,0.405169,-93.810326,0.041393,0.000000
32.900002,3.132019,-93.810326,0.005950,0.001613,0.040976,13.931916,0.709726,0.409764,-93.810326,0.041783,0.000000
33.130001,3.095901,-93.854805,0.005971,0.001624,0.041245,13.771257,0.701541,0.412451,-93.854805,0.042164,0.000000
33.360001,3.140961,-93.899284,0.005993,0.001642,0.041705,13.971691,0.711752,0.417050,-93.899284,0.042546,0.000000
33.590000,3.145798,-93.854805,0.005997,0.001654,0.042009,13.993207,0.712848,0.420085,-93.854805,0.042928,0.000000
33.820004,3.250061,-93.943771,0.006006,0.001671,0.042442,14.456993,0.736474,0.424419,-93.943771,0.043309,0.000000
34.050003,3.230698,-93.854805,0.006032,0.001684,0.042763,14.370861,0.732087,0.427629,-93.854805,0.043700,0.000000
34.280003,3.269798,-93.854805,0.006036,0.001697,0.043110,14.544789,0.740947,0.431096,-93.854805,0.044081,0.000000
34.510002,3.314857,-93.943771,0.006040,0.001711,0.043457,14.745222,0.751157,0.434566,-93.943771,0.044463,0.000000
34.740002,3.423592,-93.943771,0.006062,0.001731,0.043960,15.228896,0.775797,0.439597,-93.943771,0.044844,0.000000
34.970001,3.437737,-93.899284,0.006084,0.001745,0.044332,15.291816,0.779002,0.443325,-93.899284,0.045226,0.000000
35.200001,3.415771,-93.899284,0.006084,0.001760,0.044714,15.194111,0.774025,0.447140,-93.899284,0.045616,0.000000
35.430000,3.425827,-93.943771,0.006101,0.001775,0.045087,15.238840,0.776303,0.450872,-93.943771,0.045997,0.000000
35.660000,3.377419,-93.899284,0.006122,0.001786,0.045365,15.023508,0.765334,0.453646,-93.899284,0.046379,0.000000
35.890003,3.512215,-93.943771,0.006135,0.001802,0.045764,15.623111,0.795879,0.457635,-93.943771,0.046761,0.000000
36.120003,3.590782,-93.899284,0.006140,0.001816,0.046136,15.972597,0.813683,0.461364,-93.899284,0.047142,0.000000
36.350002,3.657814,-93.899284,0.006153,0.001833,0.046553,16.270769,0.828873,0.465527,-93.899284,0.047533,0.000000
36.580002,3.703987,-93.943771,0.006170,0.001849,0.046969,16.476158,0.839335,0.469690,-93.943771,0.047914,0.000000
36.810001,3.822769,-93.943771,0.006174,0.001869,0.047480,17.004526,0.866252,0.474804,-93.943771,0.048296,0.000000
37.040001,3.746437,-93.943771,0.006200,0.001884,0.047854,16.664984,0.848955,0.478536,-93.943771,0.048677,0.000000
37.270000,3.658928,-93.899284,0.006213,0.001894,0.048105,16.275724,0.829125,0.481049,-93.899284,0.049059,0.000000
37.500000,3.753136,-93.943771,0.006234,0.001909,0.048486,16.694782,0.850473,0.484864,-93.943771,0.049449,0.000000
37.730003,3.767662,-93.943771,0.006247,0.001922,0.048825,16.759398,0.853764,0.488248,-93.943771,0.049831,0.000000
37.960003,3.882355,-93.988251,0.006247,0.001940,0.049267,17.269577,0.879754,0.492672,-93.988251,0.050212,0.000000
38.190002,3.868576,-93.988251,0.006260,0.001951,0.049553,17.208286,0.876632,0.495534,-93.988251,0.050594,0.000000
38.420002,3.919220,-93.988251,0.006265,0.001967,0.049952,17.433561,0.888108,0.499523,-93.988251,0.050975,0.000000
38.650002,4.074127,-94.032730,0.006299,0.001987,0.050464,18.122623,0.923210,0.504636,-94.032730,0.051366,0.000000
38.880001,4.103912,-94.032730,0.006303,0.002003,0.050880,18.255114,0.929960,0.508800,-94.032730,0.051747,0.000000
39.110001,4.075241,-94.032730,0.006325,0.002018,0.051253,18.127577,0.923463,0.512532,-94.032730,0.052129,0.000000
39.340000,4.094604,-94.032730,0.006329,0.002031,0.051600,18.213711,0.927851,0.515999,-94.032730,0.052510,0.000000
39.570004,4.128120,-94.032730,0.006347,0.002044,0.051912,18.362797,0.935445,0.519121,-94.032730,0.052892,0.000000
39.800003,4.341858,-94.032730,0.006355,0.002061,0.052354,19.313549,0.983879,0.523542,-94.032730,0.053282,0.000000
40.030003,4.207436,-94.077209,0.006372,0.002071,0.052615,18.715609,0.953419,0.526146,-94.077209,0.053664,0.000000
40.260002,4.377983,-94.121689,0.006390,0.002089,0.053065,19.474241,0.992065,0.530654,-94.121689,0.054045,0.000000
40.490002,4.498253,-94.121689,0.006385,0.002109,0.053560,20.009228,1.019319,0.535597,-94.121689,0.054427,0.000000
40.720001,4.513527,-94.077209,0.006420,0.002125,0.053976,20.077171,1.022780,0.539760,-94.077209,0.054817,0.000000
40.950001,4.490807,-94.032730,0.006433,0.002138,0.054297,19.976105,1.017631,0.542970,-94.032730,0.055199,0.000000
41.180000,4.468468,-94.121689,0.006437,0.002152,0.054652,19.876738,1.012569,0.546524,-94.121689,0.055580,0.000000
41.410004,4.594330,-94.121689,0.006459,0.002167,0.055051,20.436600,1.041090,0.550513,-94.121689,0.055962,0.000000
41.640003,4.683701,-94.121689,0.006454,0.002182,0.055416,20.834141,1.061342,0.554158,-94.121689,0.056343,0.000000
41.870003,4.717583,-94.077209,0.006472,0.002195,0.055754,20.984856,1.069020,0.557538,-94.077209,0.056734,0.000000
42.100002,4.882919,-94.077209,0.006493,0.002211,0.056153,21.720310,1.106485,0.561527,-94.077209,0.057116,0.000000
42.330002,4.992393,-94.166176,0.006502,0.002228,0.056595,22.207275,1.131292,0.565952,-94.166176,0.057497,0.000000
42.560001,5.163315,-94.166176,0.006528,0.002250,0.057150,22.967571,1.170024,0.571500,-94.166176,0.057879,0.000000
42.790001,5.011757,-94.166176,0.006536,0.002262,0.057445,22.293407,1.135680,0.574449,-94.166176,0.058260,0.000000
43.020000,5.024788,-94.121689,0.006549,0.002274,0.057757,22.351374,1.138633,0.577571,-94.121689,0.058650,0.000000
43.250004,5.072830,-94.210655,0.006566,0.002286,0.058052,22.565075,1.149520,0.580520,-94.210655,0.059032,0.000000
43.480003,5.272049,-94.166176,0.006575,0.002304,0.058529,23.451244,1.194663,0.585289,-94.166176,0.059414,0.000000
43.710003,5.429932,-94.210655,0.006588,0.002322,0.058980,24.153542,1.230440,0.589800,-94.210655,0.059795,0.000000
43.940002,5.302582,-94.210655,0.006605,0.002330,0.059188,23.587061,1.201582,0.591882,-94.210655,0.060177,0.000000
44.170002,5.486160,-94.210655,0.006627,0.002347,0.059605,24.403660,1.243182,0.596045,-94.210655,0.060567,0.000000
44.400002,5.630272,-94.210655,0.006635,0.002364,0.060038,25.044701,1.275838,0.600379,-94.210655,0.060949,0.000000
44.630001,5.714798,-94.210655,0.006653,0.002378,0.060394,25.420691,1.294992,0.603937,-94.210655,0.061330,0.000000
44.860001,5.753525,-94.166176,0.006648,0.002392,0.060758,25.592957,1.303767,0.607578,-94.166176,0.061712,0.000000
45.090004,5.764694,-94.210655,0.006661,0.002404,0.061070,25.642641,1.306298,0.610700,-94.210655,0.062093,0.000000
45.320004,5.826134,-94.166176,0.006683,0.002420,0.061460,25.915937,1.320221,0.614603,-94.166176,0.062484,0.000000
45.550003,6.304260,-94.255135,0.006709,0.002442,0.062015,28.042749,1.428566,0.620151,-94.255135,0.062865,0.000000
45.780003,6.172440,-94.255135,0.006722,0.002452,0.062293,27.456383,1.398695,0.622929,-94.255135,0.063247,0.000000
46.010002,6.287880,-94.255135,0.006722,0.002466,0.062648,27.969887,1.424854,0.626483,-94.255135,0.063628,0.000000
46.240002,6.526566,-94.299614,0.006735,0.002485,0.063117,29.031614,1.478941,0.631165,-94.299614,0.064010,0.000000
46.470001,6.594711,-94.255135,0.006760,0.002499,0.063481,29.334742,1.494383,0.634810,-94.255135,0.064400,0.000000
46.700001,6.725792,-94.255135,0.006773,0.002515,0.063889,29.917816,1.524086,0.638887,-94.255135,0.064782,0.000000
46.930004,6.766747,-94.255135,0.006791,0.002530,0.064270,30.099993,1.533367,0.642702,-94.255135,0.065163,0.000000
47.160004,6.918678,-94.299614,0.006791,0.002546,0.064660,30.775818,1.567795,0.646604,-94.299614,0.065545,0.000000
47.390003,7.225510,-94.210655,0.006812,0.002562,0.065077,32.140671,1.637324,0.650767,-94.210655,0.065926,0.000000
47.620003,7.308548,-94.255135,0.006821,0.002576,0.065432,32.510044,1.656141,0.654321,-94.255135,0.066317,0.000000
47.850002,7.365150,-94.255135,0.006842,0.002590,0.065779,32.761826,1.668967,0.657792,-94.255135,0.066698,0.000000
48.080002,7.469414,-94.299614,0.006851,0.002603,0.066108,33.225613,1.692593,0.661085,-94.299614,0.067080,0.000000
48.310001,7.901741,-94.299614,0.006860,0.002623,0.066611,35.148701,1.790560,0.666115,-94.299614,0.067462,0.000000
48.540001,8.163887,-94.344101,0.006873,0.002641,0.067080,36.314785,1.849963,0.670797,-94.344101,0.067843,0.000000
48.770000,8.121437,-94.299614,0.006885,0.002654,0.067401,36.125957,1.840344,0.674007,-94.299614,0.068233,0.000000
49.000004,8.273369,-94.255135,0.006907,0.002668,0.067765,36.801781,1.874772,0.677651,-94.255135,0.068615,0.000000
49.230003,8.430885,-94.344101,0.006929,0.002682,0.068129,37.502449,1.910466,0.681292,-94.344101,0.068996,0.000000
49.460003,8.770485,-94.388580,0.006942,0.002699,0.068554,39.013065,1.987420,0.685543,-94.388580,0.069378,0.000000
49.690002,8.919807,-94.344101,0.006950,0.002713,0.068901,39.677284,2.021257,0.689010,-94.344101,0.069768,0.000000
49.920002,8.910126,-94.388580,0.006959,0.002722,0.069144,39.634220,2.019063,0.691440,-94.388580,0.070150,0.000000
50.150002,9.575180,-94.388580,0.006980,0.002743,0.069681,42.592529,2.169767,0.696814,-94.388580,0.070532,0.000000
50.380001,9.877548,-94.344101,0.006985,0.002758,0.070063,43.937531,2.238285,0.700629,-94.344101,0.070913,0.000000
50.610001,10.067459,-94.433060,0.007002,0.002777,0.070532,44.782295,2.281319,0.705315,-94.433060,0.071295,0.000000
50.840004,10.165024,-94.388580,0.007015,0.002789,0.070844,45.216286,2.303427,0.708438,-94.388580,0.071685,0.000000
51.070004,10.371689,-94.388580,0.007032,0.002801,0.071156,46.135574,2.350258,0.711556,-94.388580,0.072066,0.000000
51.300003,10.396637,-94.388580,0.007049,0.002810,0.071381,46.246552,2.355912,0.713812,-94.388580,0.072448,0.000000
51.530003,11.098930,-94.388580,0.007054,0.002834,0.071971,49.370506,2.515054,0.719709,-94.388580,0.072830,0.000000
51.760002,11.330917,-94.433060,0.007062,0.002846,0.072283,50.402439,2.567622,0.722832,-94.433060,0.073211,0.000000
51.990002,11.691002,-94.433060,0.007088,0.002863,0.072708,52.004173,2.649219,0.727082,-94.433060,0.073601,0.000000
52.220001,12.196686,-94.344101,0.007101,0.002880,0.073159,54.253567,2.763808,0.731590,-94.344101,0.073983,0.000000
52.450001,12.506874,-94.433060,0.007110,0.002893,0.073489,55.633354,2.834098,0.734887,-94.433060,0.074364,0.000000
52.680004,12.853180,-94.477539,0.007131,0.002909,0.073896,57.173801,2.912572,0.738963,-94.477539,0.074746,0.000000
52.910004,13.093361,-94.477539,0.007140,0.002923,0.074243,58.242180,2.966998,0.742430,-94.477539,0.075128,0.000000
53.140003,13.592339,-94.433060,0.007140,0.002940,0.074685,60.461742,3.080068,0.746854,-94.433060,0.075518,0.000000
53.370003,14.197815,-94.477539,0.007161,0.002957,0.075102,63.155037,3.217271,0.751018,-94.477539,0.075900,0.000000
53.600002,14.239891,-94.433060,0.007179,0.002967,0.075353,63.342197,3.226805,0.753531,-94.433060,0.076281,0.000000
53.830002,14.588806,-94.522018,0.007192,0.002980,0.075700,64.894249,3.305871,0.757002,-94.522018,0.076663,0.000000
54.060001,15.443031,-94.433060,0.007200,0.003001,0.076221,68.694031,3.499441,0.762206,-94.433060,0.077044,0.000000
54.290001,15.889503,-94.566505,0.007205,0.003016,0.076602,70.680038,3.600613,0.766021,-94.566505,0.077434,0.000000
54.520004,16.429817,-94.522018,0.007222,0.003032,0.077018,73.083473,3.723050,0.770185,-94.522018,0.077816,0.000000
54.750004,16.668137,-94.522018,0.007239,0.003044,0.077313,74.143578,3.777054,0.773133,-94.522018,0.078198,0.000000
54.980003,16.965286,-94.477539,0.007239,0.003055,0.077591,75.465363,3.844389,0.775907,-94.477539,0.078579,0.000000
55.210003,17.793442,-94.566505,0.007261,0.003073,0.078042,79.149185,4.032052,0.780415,-94.566505,0.078961,0.000000
55.440002,18.093948,-94.566505,0.007269,0.003085,0.078362,80.485901,4.100147,0.783625,-94.566505,0.079351,0.000000
55.670002,18.469673,-94.566505,0.007282,0.003097,0.078675,82.157211,4.185288,0.786747,-94.566505,0.079733,0.000000
55.900002,19.266922,-94.477539,0.007286,0.003113,0.079082,85.703552,4.365947,0.790824,-94.477539,0.080114,0.000000
56.130001,20.371002,-94.522018,0.007299,0.003134,0.079594,90.614746,4.616135,0.795941,-94.522018,0.080496,0.000000
56.360004,20.844666,-94.566505,0.007312,0.003150,0.080010,92.721703,4.723468,0.800100,-94.566505,0.080878,0.000000
56.590004,21.440834,-94.566505,0.007317,0.003164,0.080375,95.373596,4.858562,0.803745,-94.566505,0.081268,0.000000
56.820004,21.718620,-94.610985,0.007338,0.003177,0.080687,96.609245,4.921510,0.806868,-94.610985,0.081649,0.000000
57.050003,22.106262,-94.566505,0.007343,0.003186,0.080929,98.333565,5.009350,0.809294,-94.566505,0.082031,0.000000
57.280003,22.887123,-94.610985,0.007368,0.003203,0.081354,101.807007,5.186296,0.813544,-94.610985,0.082412,0.000000
57.510002,23.599846,-94.610985,0.007364,0.003218,0.081736,104.977356,5.347801,0.817359,-94.610985,0.082794,0.000000
57.740002,24.398956,-94.655464,0.007381,0.003232,0.082100,108.531975,5.528883,0.821001,-94.655464,0.083184,0.000000
57.970001,25.296745,-94.610985,0.007377,0.003250,0.082543,112.525543,5.732325,0.825425,-94.610985,0.083566,0.000000
58.200005,26.452591,-94.610985,0.007394,0.003269,0.083037,117.667000,5.994243,0.830368,-94.610985,0.083947,0.000000
58.430004,27.106850,-94.610985,0.007416,0.003286,0.083462,120.577286,6.142500,0.834619,-94.610985,0.084329,0.000000
58.660004,27.379051,-94.610985,0.007420,0.003296,0.083713,121.788101,6.204182,0.837132,-94.610985,0.084719,0.000000
58.890003,28.067940,-94.655464,0.007433,0.003310,0.084086,124.852432,6.360286,0.840860,-94.655464,0.085101,0.000000
59.120003,28.843971,-94.655464,0.007433,0.003326,0.084477,128.304398,6.536138,0.844766,-94.655464,0.085482,0.000000
59.350002,29.774902,-94.655464,0.007446,0.003340,0.084841,132.445374,6.747089,0.848407,-94.655464,0.085864,0.000000
59.580002,30.572891,-94.655464,0.007450,0.003355,0.085222,135.995010,6.927917,0.852222,-94.655464,0.086246,0.000000
59.810001,31.466583,-94.744423,0.007463,0.003374,0.085708,139.970352,7.130429,0.857078,-94.744423,0.086636,0.000000
60.040005,32.584076,-94.699944,0.007472,0.003389,0.086081,144.941208,7.383657,0.860806,-94.699944,0.087017,0.000000
60.270004,33.427872,-94.655464,0.007476,0.003404,0.086471,148.694595,7.574864,0.864708,-94.655464,0.087399,0.000000
60.500004,34.306297,-94.699944,0.007493,0.003420,0.086870,152.602036,7.773918,0.868698,-94.699944,0.087780,0.000000
60.730003,34.961304,-94.655464,0.007511,0.003433,0.087191,155.515640,7.922345,0.871907,-94.655464,0.088162,0.000000
60.960003,35.627480,-94.699944,0.007519,0.003445,0.087503,158.478943,8.073302,0.875030,-94.699944,0.088553,0.000000
61.190002,36.669006,-94.744423,0.007528,0.003460,0.087876,163.111893,8.309316,0.878758,-94.744423,0.088934,0.000000
61.420002,37.525833,-94.744423,0.007528,0.003475,0.088275,166.923248,8.503476,0.882747,-94.744423,0.089316,0.000000
61.650002,38.872330,-94.699944,0.007537,0.003496,0.088786,172.912766,8.808596,0.887864,-94.699944,0.089697,0.000000
61.880001,40.270592,-94.744423,0.007549,0.003514,0.089263,179.132538,9.125447,0.892633,-94.744423,0.090079,0.000000
62.110004,41.219391,-94.788910,0.007567,0.003529,0.089637,183.353012,9.340447,0.896365,-94.788910,0.090469,0.000000
62.340004,41.865463,-94.788910,0.007567,0.003541,0.089940,186.226883,9.486850,0.899401,-94.788910,0.090850,0.000000
62.570004,42.533493,-94.744423,0.007571,0.003553,0.090244,189.198425,9.638227,0.902436,-94.744423,0.091232,0.000000
62.800003,43.632744,-94.788910,0.007580,0.003569,0.090651,194.088135,9.887321,0.906509,-94.788910,0.091614,0.000000
63.030003,44.866035,-94.744423,0.007601,0.003586,0.091076,199.574097,10.166789,0.910759,-94.744423,0.091995,0.000000
63.260002,45.414543,-94.744423,0.007610,0.003595,0.091310,202.013977,10.291082,0.913102,-94.744423,0.092386,0.000000
63.490002,46.647095,-94.833389,0.007606,0.003612,0.091752,207.496643,10.570382,0.917523,-94.833389,0.092767,0.000000
63.720001,48.134720,-94.788910,0.007618,0.003632,0.092255,214.113922,10.907483,0.922553,-94.788910,0.093149,0.000000
63.950005,49.738907,-94.788910,0.007631,0.003651,0.092724,221.249710,11.270997,0.927239,-94.788910,0.093530,0.000000
64.180000,50.526100,-94.788910,0.007631,0.003662,0.093027,224.751312,11.449378,0.930274,-94.788910,0.093912,0.000000
64.410004,51.172539,-94.833389,0.007644,0.003673,0.093296,227.626816,11.595862,0.932961,-94.833389,0.094302,0.000000
64.639999,52.329498,-94.833389,0.007644,0.003689,0.093712,232.773239,11.858033,0.937125,-94.833389,0.094684,0.000000
64.870003,53.861809,-94.833389,0.007657,0.003707,0.094163,239.589294,12.205260,0.941633,-94.833389,0.095065,0.000000
65.100006,55.296562,-94.788910,0.007670,0.003724,0.094588,245.971390,12.530380,0.945883,-94.788910,0.095447,0.000000
65.330002,55.649940,-94.833389,0.007687,0.003730,0.094753,247.543304,12.610457,0.947530,-94.833389,0.095828,0.000000
65.560005,56.935005,-94.877869,0.007679,0.003749,0.095230,253.259552,12.901657,0.952299,-94.877869,0.096218,0.000000
65.790001,58.083397,-94.877869,0.007696,0.003764,0.095603,258.367859,13.161886,0.956030,-94.877869,0.096600,0.000000
66.020004,59.380745,-94.877869,0.007679,0.003777,0.095932,264.138733,13.455870,0.959323,-94.877869,0.096982,0.000000
66.250000,60.479988,-94.833389,0.007709,0.003792,0.096314,269.028412,13.704961,0.963142,-94.833389,0.097363,0.000000
66.480003,61.475342,-94.833389,0.007705,0.003806,0.096670,273.455963,13.930511,0.966696,-94.833389,0.097754,0.000000
66.710007,62.719437,-94.877869,0.007722,0.003822,0.097077,278.989990,14.212427,0.970773,-94.877869,0.098135,0.000000
66.940002,64.844200,-94.877869,0.007718,0.003842,0.097598,288.441406,14.693906,0.975977,-94.877869,0.098517,0.000000
67.170006,65.648140,-94.877869,0.007735,0.003852,0.097840,292.017517,14.876081,0.978403,-94.877869,0.098899,0.000000
67.400002,66.745903,-94.922348,0.007731,0.003866,0.098205,296.900604,15.124838,0.982048,-94.922348,0.099280,0.000000
67.630005,67.175987,-94.877869,0.007743,0.003865,0.098170,298.813721,15.222297,0.981700,-94.877869,0.098404,0.000000
67.860001,66.829308,-94.966827,0.007752,0.003865,0.098170,297.271606,15.143737,0.981700,-94.966827,0.098404,0.000000
68.090004,66.609612,-94.922348,0.007752,0.003862,0.098083,296.294342,15.093954,0.980833,-94.922348,0.098170,0.000000
68.320000,66.332191,-95.011314,0.007756,0.003861,0.098057,295.060333,15.031090,0.980572,-95.011314,0.098170,0.000000
68.550003,66.109520,-94.922348,0.007761,0.003860,0.098048,294.069824,14.980632,0.980485,-94.922348,0.098170,0.000000
68.780006,65.904335,-94.877869,0.007769,0.003860,0.098040,293.157135,14.934135,0.980398,-94.877869,0.098170,0.000000
69.010002,65.695061,-94.922348,0.007769,0.003859,0.098031,292.226227,14.886714,0.980310,-94.922348,0.098170,0.000000
69.240005,65.550957,-95.011314,0.007765,0.003859,0.098031,291.585205,14.854059,0.980310,-95.011314,0.098170,0.000000
69.470001,65.396049,-95.011314,0.007765,0.003859,0.098022,290.896149,14.818957,0.980223,-95.011314,0.098170,0.000000
69.700005,65.263481,-94.966827,0.007765,0.003859,0.098022,290.306458,14.788917,0.980223,-94.966827,0.098170,0.000000
69.930000,65.129051,-94.966827,0.007761,0.003859,0.098022,289.708496,14.758454,0.980223,-94.966827,0.098170,0.000000
70.160004,65.019585,-95.011314,0.007765,0.003859,0.098022,289.221558,14.733649,0.980223,-95.011314,0.098170,0.000000
70.390007,64.897072,-95.055794,0.007774,0.003859,0.098022,288.676605,14.705887,0.980223,-95.055794,0.098170,0.000000
70.620003,64.800621,-95.055794,0.007769,0.003859,0.098014,288.247559,14.684031,0.980136,-95.055794,0.098170,0.000000
70.850006,64.723167,-95.011314,0.007769,0.003859,0.098014,287.903015,14.666480,0.980136,-95.011314,0.098170,0.000000
71.080002,64.629707,-94.966827,0.007765,0.003859,0.098014,287.487305,14.645302,0.980136,-94.966827,0.098170,0.000000
71.310005,64.538841,-95.011314,0.007774,0.003859,0.098014,287.083099,14.624711,0.980136,-95.011314,0.098170,0.000000
71.540001,64.464378,-95.100273,0.007774,0.003859,0.098014,286.751862,14.607837,0.980136,-95.100273,0.098170,0.000000
71.770004,64.382454,-95.100273,0.007761,0.003859,0.098014,286.387451,14.589273,0.980136,-95.100273,0.098170,0.000000
72.000000,64.317665,-95.055794,0.007774,0.003859,0.098014,286.099274,14.574592,0.980136,-95.055794,0.098170,0.000000
72.230003,64.242439,-95.100273,0.007774,0.003859,0.098014,285.764648,14.557545,0.980136,-95.100273,0.098170,0.000000
72.460007,64.190681,-95.100273,0.007778,0.003858,0.098005,285.534424,14.545816,0.980053,-95.100273,0.098170,0.000000
72.690002,64.141533,-95.011314,0.007778,0.003858,0.098005,285.315796,14.534679,0.980053,-95.011314,0.098170,0.000000
72.920006,64.070030,-95.100273,0.007778,0.003858,0.098005,284.997742,14.518476,0.980053,-95.100273,0.098170,0.000000
73.150002,64.018639,-95.055794,0.007765,0.003858,0.098005,284.769135,14.506831,0.980053,-95.055794,0.098170,0.000000
73.380005,63.975075,-95.144753,0.007774,0.003858,0.098005,284.575348,14.496960,0.980053,-95.144753,0.098170,0.000000
73.610001,63.906181,-95.055794,0.007769,0.003858,0.098005,284.268890,14.481348,0.980053,-95.055794,0.098170,0.000000
73.840004,63.845116,-95.100273,0.007774,0.003858,0.098005,283.997253,14.467510,0.980053,-95.100273,0.098170,0.000000
74.070007,63.823524,-95.144753,0.007774,0.003858,0.098005,283.901215,14.462617,0.980053,-95.144753,0.098170,0.000000
74.300003,63.769905,-95.189232,0.007769,0.003858,0.098005,283.662720,14.450467,0.980053,-95.189232,0.098170,0.000000
74.530006,63.708458,-95.100273,0.007774,0.003858,0.098005,283.389374,14.436543,0.980053,-95.100273,0.098170,0.000000
74.760002,63.680901,-95.055794,0.007778,0.003858,0.098005,283.266785,14.430298,0.980053,-95.055794,0.098170,0.000000
74.990005,63.620201,-95.144753,0.007774,0.003858,0.098005,282.996796,14.416544,0.980053,-95.144753,0.098170,0.000000
75.220001,63.591164,-95.189232,0.007778,0.003858,0.098005,282.867615,14.409964,0.980053,-95.189232,0.098170,0.000000
75.450005,63.562492,-95.144753,0.007782,0.003858,0.098005,282.740082,14.403467,0.980053,-95.144753,0.098170,0.000000
75.680000,63.525627,-95.189232,0.007782,0.003858,0.098005,282.576111,14.395113,0.980053,-95.189232,0.098170,0.000000
75.910004,63.489128,-95.100273,0.007778,0.003858,0.098005,282.413757,14.386842,0.980053,-95.100273,0.098170,0.000000
76.140007,63.463814,-95.189232,0.007787,0.003858,0.098005,282.301147,14.381106,0.980053,-95.189232,0.098170,0.000000
76.370003,63.420616,-95.189232,0.007778,0.003858,0.098005,282.108978,14.371317,0.980053,-95.189232,0.098170,0.000000
76.600006,63.387093,-95.233719,0.007774,0.003858,0.098005,281.959869,14.363720,0.980053,-95.233719,0.098170,0.000000
76.830002,63.360283,-95.189232,0.007774,0.003858,0.098005,281.840607,14.357646,0.980053,-95.189232,0.098170,0.000000
77.060005,63.317101,-95.189232,0.007778,0.003858,0.098005,281.648529,14.347859,0.980053,-95.189232,0.098170,0.000000
77.290001,63.309273,-95.233719,0.007778,0.003858,0.098005,281.613708,14.346086,0.980053,-95.233719,0.098170,0.000000
77.520004,63.279854,-95.233719,0.007774,0.003858,0.098005,281.482849,14.339419,0.980053,-95.233719,0.098170,0.000000
77.750000,63.234428,-95.189232,0.007778,0.003858,0.098005,281.280792,14.329126,0.980053,-95.189232,0.098170,0.000000
77.980003,63.213951,-95.189232,0.007774,0.003858,0.098005,281.189697,14.324486,0.980053,-95.189232,0.098170,0.000000
78.210007,63.181557,-95.189232,0.007774,0.003858,0.098005,281.045593,14.317145,0.980053,-95.189232,0.098170,0.000000
78.440002,63.157341,-95.233719,0.007782,0.003858,0.098005,280.937897,14.311658,0.980053,-95.233719,0.098170,0.000000
78.670006,63.141335,-95.278198,0.007769,0.003858,0.098005,280.866669,14.308031,0.980053,-95.278198,0.098170,0.000000
78.900002,63.116005,-95.233719,0.007782,0.003858,0.098005,280.753998,14.302291,0.980053,-95.233719,0.098170,0.000000
79.130005,63.074303,-95.278198,0.007774,0.003858,0.098005,280.568512,14.292841,0.980053,-95.278198,0.098170,0.000000
79.360001,63.041542,-95.278198,0.007778,0.003858,0.098005,280.422791,14.285418,0.980053,-95.278198,0.098170,0.000000
79.590004,63.025154,-95.233719,0.007787,0.003858,0.098005,280.349884,14.281704,0.980053,-95.233719,0.098170,0.000000
79.820007,62.999458,-95.233719,0.007778,0.003858,0.098005,280.235596,14.275881,0.980053,-95.233719,0.098170,0.000000
80.050003,62.987541,-95.322678,0.007782,0.003858,0.098005,280.182587,14.273181,0.980053,-95.322678,0.098170,0.000000
80.280006,62.962593,-95.278198,0.007778,0.003858,0.098005,280.071594,14.267528,0.980053,-95.278198,0.098170,0.000000
80.510002,62.938019,-95.278198,0.007787,0.003858,0.098005,279.962280,14.261959,0.980053,-95.278198,0.098170,0.000000
80.740005,62.919029,-95.367157,0.007787,0.003858,0.098005,279.877808,14.257656,0.980053,-95.367157,0.098170,0.000000
80.970001,62.893707,-95.278198,0.007778,0.003858,0.098005,279.765167,14.251918,0.980053,-95.278198,0.098170,0.000000
81.200005,62.863541,-95.322678,0.007774,0.003858,0.098005,279.630981,14.245083,0.980053,-95.322678,0.098170,0.000000
81.430000,62.839340,-95.367157,0.007778,0.003858,0.098005,279.523346,14.239598,0.980053,-95.367157,0.098170,0.000000
81.660004,62.856094,-95.278198,0.007782,0.003858,0.098005,279.597870,14.243395,0.980053,-95.278198,0.098170,0.000000
81.890007,62.821465,-95.322678,0.007787,0.003858,0.098005,279.443817,14.235547,0.980053,-95.322678,0.098170,0.000000
82.120003,62.799492,-95.411636,0.007795,0.003858,0.098005,279.346100,14.230568,0.980053,-95.411636,0.098170,0.000000
82.350006,62.780876,-95.411636,0.007774,0.003858,0.098005,279.263275,14.226350,0.980053,-95.411636,0.098170,0.000000
82.580002,62.758904,-95.411636,0.007791,0.003858,0.098005,279.165558,14.221371,0.980053,-95.411636,0.098170,0.000000
82.810005,62.738426,-95.367157,0.007778,0.003858,0.098005,279.074463,14.216730,0.980053,-95.367157,0.098170,0.000000
83.040001,62.743637,-95.278198,0.007791,0.003858,0.098005,279.097626,14.217912,0.980053,-95.278198,0.098170,0.000000
83.270004,62.711243,-95.411636,0.007778,0.003858,0.098005,278.953552,14.210570,0.980053,-95.411636,0.098170,0.000000
83.500008,62.691505,-95.411636,0.007774,0.003858,0.098005,278.865753,14.206098,0.980053,-95.411636,0.098170,0.000000
83.730003,62.666557,-95.411636,0.007782,0.003858,0.098005,278.754761,14.200444,0.980053,-95.411636,0.098170,0.000000
83.960007,62.649429,-95.367157,0.007787,0.003858,0.098005,278.678589,14.196564,0.980053,-95.367157,0.098170,0.000000
84.190002,62.633789,-95.322678,0.007782,0.003858,0.098005,278.609009,14.193020,0.980053,-95.322678,0.098170,0.000000
84.420006,62.631554,-95.411636,0.007782,0.003858,0.098005,278.599060,14.192513,0.980053,-95.411636,0.098170,0.000000
84.650002,62.603630,-95.456123,0.007778,0.003858,0.098005,278.474854,14.186185,0.980053,-95.456123,0.098170,0.000000
84.880005,62.581284,-95.456123,0.007782,0.003858,0.098005,278.375458,14.181121,0.980053,-95.456123,0.098170,0.000000
85.110001,62.572723,-95.411636,0.007782,0.003858,0.098005,278.337372,14.179182,0.980053,-95.411636,0.098170,0.000000
85.340004,62.554100,-95.456123,0.007782,0.003858,0.098005,278.254547,14.174962,0.980053,-95.456123,0.098170,0.000000
85.570007,62.536972,-95.456123,0.007791,0.003858,0.098005,278.178345,14.171081,0.980053,-95.456123,0.098170,0.000000
85.800003,62.529152,-95.500603,0.007778,0.003858,0.098005,278.143555,14.169309,0.980053,-95.500603,0.098170,0.000000
86.030006,62.518356,-95.456123,0.007769,0.003858,0.098005,278.095551,14.166862,0.980053,-95.456123,0.098170,0.000000
86.260002,62.519096,-95.411636,0.007787,0.003858,0.098005,278.098816,14.167029,0.980053,-95.411636,0.098170,0.000000
86.490005,62.492661,-95.456123,0.007795,0.003858,0.098005,277.981232,14.161039,0.980053,-95.456123,0.098170,0.000000
86.720001,62.459145,-95.500603,0.007787,0.003858,0.098005,277.832153,14.153445,0.980053,-95.500603,0.098170,0.000000
86.950005,62.446861,-95.500603,0.007778,0.003858,0.098005,277.777527,14.150661,0.980053,-95.500603,0.098170,0.000000
87.180008,62.452072,-95.456123,0.007791,0.003858,0.098005,277.800690,14.151841,0.980053,-95.456123,0.098170,0.000000
87.410004,62.433823,-95.411636,0.007791,0.003858,0.098005,277.719513,14.147706,0.980053,-95.411636,0.098170,0.000000
87.640007,62.413719,-95.456123,0.007791,0.003858,0.098005,277.630096,14.143150,0.980053,-95.456123,0.098170,0.000000
87.870003,62.414833,-95.500603,0.007791,0.003858,0.098005,277.635040,14.143403,0.980053,-95.500603,0.098170,0.000000
88.100006,62.386909,-95.545082,0.007778,0.003858,0.098005,277.510834,14.137075,0.980053,-95.545082,0.098170,0.000000
88.330002,62.374245,-95.500603,0.007774,0.003858,0.098005,277.454498,14.134206,0.980053,-95.500603,0.098170,0.000000
88.560005,62.353394,-95.545082,0.007795,0.003858,0.098005,277.361755,14.129480,0.980053,-95.545082,0.098170,0.000000
88.790001,62.344826,-95.545082,0.007791,0.003858,0.098005,277.323639,14.127540,0.980053,-95.545082,0.098170,0.000000
89.020004,62.339615,-95.589561,0.007787,0.003858,0.098005,277.300446,14.126358,0.980053,-95.589561,0.098170,0.000000
89.250008,62.323601,-95.589561,0.007778,0.003858,0.098005,277.229218,14.122730,0.980053,-95.589561,0.098170,0.000000
89.480003,62.306473,-95.545082,0.007769,0.003858,0.098005,277.153046,14.118849,0.980053,-95.545082,0.098170,0.000000
89.710007,62.294189,-95.545082,0.007782,0.003858,0.098005,277.098389,14.116065,0.980053,-95.545082,0.098170,0.000000
89.940002,62.278915,-95.545082,0.007791,0.003858,0.098005,277.030457,14.112604,0.980053,-95.545082,0.098170,0.000000
90.170006,62.263283,-95.589561,0.007787,0.003858,0.098005,276.960907,14.109061,0.980053,-95.589561,0.098170,0.000000
90.400002,62.264397,-95.634048,0.007791,0.003858,0.098005,276.965881,14.109314,0.980053,-95.634048,0.098170,0.000000
90.630005,62.245033,-95.589561,0.007787,0.003858,0.098005,276.879730,14.104926,0.980053,-95.589561,0.098170,0.000000
90.860001,62.252106,-95.545082,0.007782,0.003858,0.098005,276.911194,14.106528,0.980053,-95.545082,0.098170,0.000000
91.090004,62.242050,-95.545082,0.007791,0.003858,0.098005,276.866455,14.104250,0.980053,-95.545082,0.098170,0.000000
91.320007,62.217102,-95.589561,0.007774,0.003858,0.098005,276.755493,14.098597,0.980053,-95.589561,0.098170,0.000000
91.550003,62.198112,-95.678528,0.007787,0.003858,0.098005,276.671021,14.094294,0.980053,-95.678528,0.098170,0.000000
91.780006,62.195137,-95.678528,0.007782,0.003858,0.098005,276.657776,14.093620,0.980053,-95.678528,0.098170,0.000000
92.010002,62.182098,-95.589561,0.007778,0.003858,0.098005,276.599792,14.090665,0.980053,-95.589561,0.098170,0.000000
92.240005,62.172417,-95.589561,0.007791,0.003858,0.098005,276.556732,14.088470,0.980053,-95.589561,0.098170,0.000000
92.470001,62.171303,-95.678528,0.007800,0.003858,0.098005,276.551758,14.088219,0.980053,-95.678528,0.098170,0.000000
92.700005,62.164970,-95.678528,0.007787,0.003858,0.098005,276.523590,14.086784,0.980053,-95.678528,0.098170,0.000000
92.930008,62.140022,-95.634048,0.007769,0.003858,0.098005,276.412628,14.081131,0.980053,-95.634048,0.098170,0.000000
93.160004,62.129967,-95.634048,0.007795,0.003858,0.098005,276.367889,14.078852,0.980053,-95.634048,0.098170,0.000000
93.390007,62.121407,-95.634048,0.007795,0.003858,0.098005,276.329803,14.076912,0.980053,-95.634048,0.098170,0.000000
93.620003,62.105766,-95.634048,0.007782,0.003858,0.098005,276.260254,14.073368,0.980053,-95.634048,0.098170,0.000000
93.850006,62.110237,-95.723007,0.007782,0.003858,0.097997,276.280121,14.074381,0.979966,-95.723007,0.098170,0.000000
94.080002,62.108742,-95.678528,0.007787,0.003858,0.097997,276.273468,14.074042,0.979966,-95.678528,0.098170,0.000000
94.310005,62.095711,-95.678528,0.007778,0.003858,0.097997,276.215515,14.071089,0.979966,-95.678528,0.098170,0.000000
94.540001,62.079697,-95.634048,0.007787,0.003858,0.097997,276.144287,14.067460,0.979966,-95.634048,0.098170,0.000000
94.770004,62.059219,-95.678528,0.007804,0.003858,0.097997,276.053192,14.062820,0.979966,-95.678528,0.098170,0.000000
95.000008,62.044327,-95.723007,0.007791,0.003858,0.097997,275.986938,14.059445,0.979966,-95.723007,0.098170,0.000000
95.230003,62.043953,-95.767487,0.007782,0.003858,0.097997,275.985291,14.059361,0.979966,-95.767487,0.098170,0.000000
95.460007,62.032410,-95.767487,0.007787,0.003858,0.097997,275.933929,14.056746,0.979966,-95.767487,0.098170,0.000000
95.690002,62.026077,-95.723007,0.007800,0.003858,0.097997,275.905762,14.055310,0.979966,-95.723007,0.098170,0.000000
95.920006,62.015282,-95.678528,0.007787,0.003858,0.097997,275.857758,14.052863,0.979966,-95.678528,0.098170,0.000000
96.150002,62.008202,-95.767487,0.007795,0.003858,0.097997,275.826263,14.051259,0.979966,-95.767487,0.098170,0.000000
96.380005,61.985863,-95.767487,0.007774,0.003858,0.097997,275.726898,14.046197,0.979966,-95.767487,0.098170,0.000000
96.610008,61.966125,-95.767487,0.007782,0.003858,0.097997,275.639099,14.041725,0.979966,-95.767487,0.098170,0.000000
96.840004,61.979530,-95.723007,0.007791,0.003858,0.097997,275.698730,14.044763,0.979966,-95.723007,0.098170,0.000000
97.070007,61.972458,-95.811966,0.007791,0.003858,0.097997,275.667267,14.043159,0.979966,-95.811966,0.098170,0.000000
97.300003,61.956444,-95.856453,0.007787,0.003858,0.097997,275.596039,14.039531,0.979966,-95.856453,0.098170,0.000000
97.530006,61.950859,-95.767487,0.007782,0.003858,0.097997,275.571198,14.038265,0.979966,-95.767487,0.098170,0.000000
97.760002,61.941551,-95.767487,0.007791,0.003858,0.097997,275.529785,14.036157,0.979966,-95.767487,0.098170,0.000000
97.990005,61.942665,-95.811966,0.007800,0.003858,0.097997,275.534729,14.036408,0.979966,-95.811966,0.098170,0.000000
98.000008,61.946388,-95.811966,0.007782,0.003858,0.097997,275.551300,14.037252,0.979966,-95.811966,0.098170,0.000000