File: Data/compression 4/AutoNoheating-10-4-3-240223_02232024_162456.csv
Time (sec),S:Load (lbs),S:HL1 (DIM),S:LVDT (in),S:Position (in),Ch:Position (mm),Ch:Load (N),Ch:Stress (MPa),Ch:Strain (mm/mm),Ch:HL1 (DIM),Set Point (),Cycles ()
0.010000,0.009308,-99.281487,0.000004,-0.000000,-0.000000,0.041403,0.002109,-0.000000,-99.281487,0.000199,0.000000
0.290000,0.002235,-99.325966,-0.000004,-0.000000,-0.000000,0.009944,0.000507,-0.000000,-99.325966,0.000199,0.000000
0.570000,0.017128,-99.325966,-0.000017,0.000125,0.003174,0.076189,0.003881,0.031740,-99.325966,0.004119,0.000000
0.850000,0.018250,-99.325966,0.000112,0.000302,0.007675,0.081178,0.004135,0.076750,-99.325966,0.008785,0.000000
1.130000,-0.008934,-99.281487,0.000323,0.000481,0.012228,-0.039741,-0.002024,0.122279,-99.281487,0.013451,0.000000
1.410000,0.012291,-99.370445,0.000517,0.000670,0.017006,0.054673,0.002785,0.170063,-99.370445,0.018116,0.000000
1.690000,0.000374,-99.414925,0.000690,0.000849,0.021577,0.001663,0.000085,0.215766,-99.414925,0.022782,0.000000
1.970000,0.049896,-99.370445,0.000862,0.001032,0.026207,0.221950,0.011307,0.262074,-99.370445,0.027448,0.000000
2.250000,-0.007820,-99.414925,0.001065,0.001223,0.031072,-0.034786,-0.001772,0.310725,-99.414925,0.032113,0.000000
2.530000,0.016388,-99.325966,0.001250,0.001405,0.035678,0.072897,0.003714,0.356776,-99.325966,0.036779,0.000000
2.810000,0.010429,-99.414925,0.001449,0.001591,0.040421,0.046392,0.002363,0.404212,-99.414925,0.041445,0.000000
3.090000,0.000374,-99.414925,0.001656,0.001768,0.044905,0.001663,0.000085,0.449048,-99.414925,0.046110,0.000000
3.370000,-0.003723,-99.414925,0.001807,0.001960,0.049796,-0.016561,-0.000844,0.497960,-99.414925,0.050776,0.000000
3.650000,-0.005211,-99.459404,0.001988,0.002137,0.054271,-0.023179,-0.001181,0.542709,-99.459404,0.055442,0.000000
3.930000,0.048409,-99.459404,0.002173,0.002322,0.058980,0.215332,0.010970,0.589800,-99.459404,0.060090,0.000000
4.210000,0.031654,-99.414925,0.002363,0.002506,0.063663,0.140806,0.007173,0.636631,-99.414925,0.064756,0.000000
4.490000,0.094955,-99.414925,0.002552,0.002684,0.068164,0.422383,0.021517,0.681641,-99.414925,0.069421,0.000000
4.770000,0.105011,-99.459404,0.002716,0.002877,0.073081,0.467112,0.023796,0.730810,-99.459404,0.074087,0.000000
5.050000,0.253586,-99.503891,0.002897,0.003052,0.077521,1.128006,0.057463,0.775211,-99.503891,0.078753,0.000000
5.330000,0.467331,-99.503891,0.003087,0.003244,0.082387,2.078792,0.105899,0.823866,-99.503891,0.083418,0.000000
5.610000,0.634148,-99.414925,0.003216,-0.000002,-0.000052,2.820830,0.143700,-0.000522,-99.414925,0.000104,0.000000
5.890000,0.568611,-99.459404,0.003221,-0.000002,-0.000061,2.529309,0.128849,-0.000609,-99.459404,0.000104,0.000000
6.170000,0.558189,-99.503891,0.003221,-0.000003,-0.000070,2.482950,0.126488,-0.000696,-99.503891,0.000286,0.000000
6.450000,0.509781,-99.459404,0.003212,-0.000003,-0.000070,2.267619,0.115518,-0.000696,-99.459404,0.000754,0.000000
6.730000,0.510521,-99.459404,0.003225,-0.000002,-0.000061,2.270911,0.115686,-0.000609,-99.459404,0.001223,0.000000
7.010000,0.609573,-99.503891,0.003221,0.000033,0.000832,2.711518,0.138131,0.008323,-99.503891,0.001682,0.000000
7.290000,0.631172,-99.503891,0.003242,0.000045,0.001153,2.807594,0.143026,0.011533,-99.503891,0.002151,0.000000
7.570000,0.738045,-99.548370,0.003255,0.000066,0.001674,3.282987,0.167243,0.016737,-99.548370,0.002619,0.000000
7.850000,0.778259,-99.548370,0.003268,0.000083,0.002099,3.461870,0.176356,0.020987,-99.548370,0.003087,0.000000
8.130000,0.832253,-99.503891,0.003294,0.000107,0.002714,3.702044,0.188591,0.027141,-99.503891,0.003556,0.000000
8.410001,0.855713,-99.548370,0.003316,0.000128,0.003252,3.806401,0.193907,0.032520,-99.548370,0.004015,0.000000
8.690001,0.833740,-99.592850,0.003337,0.000142,0.003607,3.708662,0.188928,0.036074,-99.592850,0.004484,0.000000
8.970000,0.873215,-99.548370,0.003346,0.000160,0.004059,3.884253,0.197873,0.040585,-99.548370,0.004952,0.000000
9.250000,0.918640,-99.503891,0.003346,0.000175,0.004449,4.086316,0.208167,0.044488,-99.503891,0.005420,0.000000
9.530001,1.018440,-99.548370,0.003372,0.000197,0.005012,4.530249,0.230782,0.050123,-99.548370,0.005888,0.000000
9.810000,1.006523,-99.548370,0.003376,0.000206,0.005229,4.477239,0.228081,0.052292,-99.548370,0.006357,0.000000
10.090000,1.107811,-99.592850,0.003397,0.000231,0.005862,4.927789,0.251034,0.058624,-99.592850,0.006816,0.000000
10.370001,1.143929,-99.637329,0.003415,0.000252,0.006391,5.088448,0.259218,0.063912,-99.637329,0.007284,0.000000
10.650001,1.156960,-99.548370,0.003436,0.000270,0.006868,5.146413,0.262171,0.068684,-99.548370,0.007753,0.000000
10.930000,1.161430,-99.592850,0.003454,0.000286,0.007276,5.166300,0.263184,0.072761,-99.592850,0.008221,0.000000
11.210001,1.242981,-99.592850,0.003471,0.000307,0.007796,5.529056,0.281664,0.077961,-99.592850,0.008689,0.000000
11.490001,1.277985,-99.637329,0.003497,0.000323,0.008212,5.684760,0.289595,0.082125,-99.637329,0.009149,0.000000
11.770000,1.336449,-99.681808,0.003505,0.000341,0.008655,5.944820,0.302844,0.086549,-99.681808,0.009617,0.000000
12.050000,1.381126,-99.681808,0.003514,0.000362,0.009201,6.143557,0.312968,0.092011,-99.681808,0.010086,0.000000
12.330001,1.426559,-99.637329,0.003527,0.000383,0.009739,6.345654,0.323263,0.097389,-99.637329,0.010554,0.000000
12.610001,1.435493,-99.637329,0.003553,0.000401,0.010190,6.385394,0.325287,0.101897,-99.637329,0.011022,0.000000
12.890000,1.467896,-99.726295,0.003570,0.000414,0.010511,6.529525,0.332630,0.105107,-99.726295,0.011482,0.000000
13.170001,1.557259,-99.726295,0.003583,0.000437,0.011100,6.927032,0.352880,0.111003,-99.726295,0.011950,0.000000
13.450001,1.597107,-99.681808,0.003596,0.000455,0.011560,7.104287,0.361910,0.115598,-99.681808,0.012419,0.000000
13.730000,1.635460,-99.681808,0.003596,0.000468,0.011889,7.274889,0.370601,0.118895,-99.681808,0.012887,0.000000
14.010000,1.705841,-99.726295,0.003635,0.000490,0.012436,7.587960,0.386549,0.124360,-99.726295,0.013355,0.000000
14.290001,1.775848,-99.726295,0.003652,0.000514,0.013060,7.899368,0.402413,0.130602,-99.726295,0.013824,0.000000
14.570001,1.752388,-99.726295,0.003660,0.000530,0.013450,7.795011,0.397097,0.134504,-99.726295,0.014283,0.000000
14.850000,1.805260,-99.770775,0.003669,0.000546,0.013875,8.030196,0.409078,0.138754,-99.770775,0.014751,0.000000
15.130001,1.898354,-99.770775,0.003699,0.000567,0.014405,8.444299,0.430173,0.144046,-99.770775,0.015220,0.000000
15.410001,1.942665,-99.681808,0.003695,0.000585,0.014847,8.641406,0.440214,0.148466,-99.681808,0.015688,0.000000
15.690001,1.927773,-99.726295,0.003721,0.000594,0.015098,8.575160,0.436839,0.150983,-99.726295,0.016156,0.000000
15.970001,2.070763,-99.815254,0.003738,0.000619,0.015723,9.211212,0.469242,0.157228,-99.815254,0.016616,0.000000
16.250000,2.114700,-99.726295,0.003742,0.000640,0.016260,9.406657,0.479198,0.162603,-99.726295,0.017084,0.000000
16.530001,2.125130,-99.726295,0.003760,0.000658,0.016703,9.453049,0.481561,0.167027,-99.726295,0.017552,0.000000
16.810001,2.138908,-99.815254,0.003781,0.000671,0.017041,9.514339,0.484684,0.170407,-99.815254,0.018021,0.000000
17.090000,2.278923,-99.815254,0.003803,0.000694,0.017639,10.137156,0.516411,0.176391,-99.815254,0.018489,0.000000
17.370001,2.302376,-99.859734,0.003824,0.000710,0.018029,10.241479,0.521726,0.180293,-99.859734,0.018957,0.000000
17.650002,2.295677,-99.770775,0.003811,0.000723,0.018359,10.211682,0.520208,0.183590,-99.770775,0.019417,0.000000
17.930000,2.450211,-99.815254,0.003846,0.000747,0.018975,10.899081,0.555226,0.189748,-99.815254,0.019885,0.000000
18.210001,2.489311,-99.815254,0.003867,0.000768,0.019495,11.073009,0.564086,0.194952,-99.815254,0.020354,0.000000
18.490002,2.520218,-99.859734,0.003872,0.000785,0.019937,11.210489,0.571090,0.199373,-99.859734,0.020822,0.000000
18.770000,2.583145,-99.859734,0.003893,0.000803,0.020388,11.490403,0.585349,0.203885,-99.859734,0.021290,0.000000
19.050001,2.678848,-99.904213,0.003906,0.000822,0.020891,11.916112,0.607036,0.208915,-99.904213,0.021750,0.000000
19.330002,2.668419,-99.815254,0.003919,0.000839,0.021307,11.869720,0.604672,0.213074,-99.815254,0.022218,0.000000
19.610001,2.716461,-99.859734,0.003928,0.000855,0.021706,12.083423,0.615559,0.217064,-99.859734,0.022687,0.000000
19.890001,2.849396,-99.904213,0.003967,0.000876,0.022262,12.674746,0.645682,0.222616,-99.904213,0.023155,0.000000
20.170000,2.877693,-99.948700,0.003975,0.000897,0.022773,12.800618,0.652095,0.227733,-99.948700,0.023623,0.000000
20.450001,2.923866,-99.904213,0.003992,0.000915,0.023250,13.006007,0.662558,0.232502,-99.904213,0.024091,0.000000
20.730001,2.920517,-99.904213,0.003992,0.000929,0.023597,12.991108,0.661799,0.235969,-99.904213,0.024551,0.000000
21.010000,3.043404,-99.904213,0.004001,0.000951,0.024143,13.537735,0.689645,0.241435,-99.904213,0.025019,0.000000
21.290001,3.022545,-99.904213,0.004018,0.000964,0.024473,13.444951,0.684918,0.244731,-99.904213,0.025487,0.000000
21.570002,3.095901,-99.948700,0.004027,0.000978,0.024829,13.771257,0.701541,0.248285,-99.948700,0.025956,0.000000
21.850000,3.267197,-99.948700,0.004061,0.001006,0.025548,14.533216,0.740357,0.255484,-99.948700,0.026424,0.000000
22.130001,3.296989,-99.904213,0.004061,0.001025,0.026043,14.665742,0.747108,0.260427,-99.904213,0.026884,0.000000
22.410002,3.315979,-99.904213,0.004092,0.001041,0.026450,14.750212,0.751412,0.264504,-99.904213,0.027352,0.000000
22.690001,3.356941,-99.904213,0.004100,0.001058,0.026884,14.932421,0.760694,0.268837,-99.904213,0.027820,0.000000
22.970001,3.458595,-99.993179,0.004113,0.001075,0.027300,15.384600,0.783729,0.273001,-99.993179,0.028289,0.000000
23.250002,3.502907,-99.993179,0.004117,0.001091,0.027708,15.581708,0.793770,0.277077,-99.993179,0.028757,0.000000
23.530001,3.603447,-99.948700,0.004143,0.001110,0.028185,16.028933,0.816553,0.281846,-99.948700,0.029217,0.000000
23.810001,3.748672,-99.993179,0.004156,0.001134,0.028809,16.674929,0.849461,0.288091,-99.993179,0.029685,0.000000
24.090002,3.750160,-100.037659,0.004182,0.001153,0.029295,16.681545,0.849798,0.292947,-100.037659,0.030153,0.000000
24.370001,3.663773,-100.082138,0.004195,0.001166,0.029616,16.297274,0.830223,0.296157,-100.082138,0.030622,0.000000
24.650002,3.715530,-100.037659,0.004195,0.001183,0.030041,16.527504,0.841951,0.300407,-100.037659,0.031090,0.000000
24.930000,3.913261,-99.993179,0.004221,0.001202,0.030535,17.407057,0.886758,0.305350,-99.993179,0.031558,0.000000
25.210001,3.945290,-100.037659,0.004238,0.001219,0.030968,17.549524,0.894015,0.309684,-100.037659,0.032018,0.000000
25.490002,3.983643,-100.037659,0.004247,0.001235,0.031376,17.720127,0.902706,0.313760,-100.037659,0.032486,0.000000
25.770000,4.122536,-100.082138,0.004255,0.001258,0.031966,18.337955,0.934180,0.319657,-100.082138,0.032954,0.000000
26.050001,4.213768,-100.082138,0.004273,0.001282,0.032555,18.743776,0.954853,0.325554,-100.082138,0.033423,0.000000
26.330002,4.202225,-100.082138,0.004281,0.001297,0.032954,18.692429,0.952238,0.329543,-100.082138,0.033891,0.000000
26.610001,4.198128,-100.037659,0.004307,0.001313,0.033345,18.674206,0.951309,0.333445,-100.037659,0.034351,0.000000
26.890001,4.282280,-100.082138,0.004320,0.001330,0.033787,19.048532,0.970379,0.337870,-100.082138,0.034819,0.000000
27.170002,4.452827,-100.126617,0.004333,0.001349,0.034273,19.807165,1.009025,0.342726,-100.126617,0.035287,0.000000
27.450001,4.573105,-100.126617,0.004337,0.001372,0.034845,20.342186,1.036280,0.348449,-100.126617,0.035756,0.000000
27.730001,4.663963,-100.037659,0.004363,0.001394,0.035409,20.746346,1.056869,0.354088,-100.037659,0.036224,0.000000
28.010002,4.641624,-100.082138,0.004376,0.001410,0.035825,20.646976,1.051807,0.358252,-100.082138,0.036692,0.000000
28.290001,4.599548,-100.126617,0.004393,0.001426,0.036224,20.459812,1.042272,0.362237,-100.126617,0.037152,0.000000
28.570002,4.683327,-100.171104,0.004415,0.001443,0.036640,20.832478,1.061257,0.366401,-100.171104,0.037620,0.000000
28.850002,4.884041,-100.082138,0.004406,0.001464,0.037178,21.725298,1.106739,0.371779,-100.082138,0.038089,0.000000
29.130001,4.763763,-100.171104,0.004437,0.001475,0.037464,21.190277,1.079484,0.374640,-100.171104,0.038557,0.000000
29.410002,5.064636,-100.171104,0.004428,0.001500,0.038089,22.528627,1.147663,0.380885,-100.171104,0.039025,0.000000
29.690001,5.192360,-100.171104,0.004471,0.001525,0.038730,23.096771,1.176605,0.387301,-100.171104,0.039485,0.000000
29.970001,5.103363,-100.215584,0.004480,0.001538,0.039077,22.700893,1.156439,0.390771,-100.215584,0.039953,0.000000
30.250002,5.074318,-100.304543,0.004493,0.001553,0.039450,22.571693,1.149857,0.394500,-100.304543,0.040421,0.000000
30.530001,5.135017,-100.215584,0.004493,0.001570,0.039884,22.841698,1.163612,0.398837,-100.215584,0.040890,0.000000
30.810001,5.380035,-100.171104,0.004510,0.001591,0.040421,23.931593,1.219133,0.404212,-100.171104,0.041358,0.000000
31.090002,5.313011,-100.171104,0.004540,0.001604,0.040742,23.633453,1.203946,0.407421,-100.171104,0.041817,0.000000
31.370001,5.466057,-100.215584,0.004540,0.001625,0.041271,24.314236,1.238626,0.412713,-100.215584,0.042286,0.000000
31.650002,5.527496,-100.215584,0.004540,0.001645,0.041792,24.587532,1.252549,0.417917,-100.215584,0.042754,0.000000
31.930002,5.662292,-100.215584,0.004566,0.001667,0.042338,25.187136,1.283094,0.423378,-100.215584,0.043222,0.000000
32.210003,5.542389,-100.260063,0.004583,0.001679,0.042659,24.653778,1.255923,0.426588,-100.260063,0.043691,0.000000
32.490002,5.768425,-100.260063,0.004605,0.001700,0.043188,25.659235,1.307144,0.431875,-100.260063,0.044159,0.000000
32.770000,5.855560,-100.260063,0.004609,0.001720,0.043682,26.046833,1.326889,0.436822,-100.260063,0.044619,0.000000
33.050003,5.820183,-100.349022,0.004626,0.001734,0.044046,25.889465,1.318872,0.440463,-100.349022,0.045087,0.000000
33.330002,6.004135,-100.260063,0.004631,0.001756,0.044601,26.707727,1.360556,0.446012,-100.260063,0.045555,0.000000
33.610001,6.035416,-100.260063,0.004661,0.001776,0.045113,26.846870,1.367645,0.451129,-100.260063,0.046024,0.000000
33.890003,6.094994,-100.260063,0.004674,0.001797,0.045633,27.111885,1.381145,0.456333,-100.260063,0.046492,0.000000
34.170002,6.108398,-100.349022,0.004678,0.001812,0.046015,27.171513,1.384183,0.460149,-100.349022,0.046952,0.000000
34.450001,6.239471,-100.349022,0.004687,0.001833,0.046570,27.754555,1.413885,0.465697,-100.349022,0.047420,0.000000
34.730003,6.309479,-100.349022,0.004721,0.001852,0.047030,28.065964,1.429748,0.470296,-100.349022,0.047888,0.000000
35.010002,6.317673,-100.349022,0.004730,0.001866,0.047402,28.102411,1.431605,0.474024,-100.349022,0.048357,0.000000
35.290001,6.446136,-100.304543,0.004734,0.001885,0.047871,28.673847,1.460715,0.478706,-100.304543,0.048825,0.000000
35.570004,6.651688,-100.349022,0.004756,0.001911,0.048530,29.588184,1.507294,0.485299,-100.349022,0.049293,0.000000
35.850002,6.525085,-100.437988,0.004769,0.001926,0.048920,29.025030,1.478606,0.489201,-100.437988,0.049752,0.000000
36.130001,6.544449,-100.393509,0.004773,0.001943,0.049354,29.111162,1.482993,0.493535,-100.393509,0.050221,0.000000
36.410000,6.690788,-100.304543,0.004794,0.001963,0.049865,29.762114,1.516154,0.498652,-100.304543,0.050689,0.000000
36.690002,6.774200,-100.349022,0.004820,0.001982,0.050343,30.133148,1.535056,0.503425,-100.349022,0.051157,0.000000
36.970001,6.650200,-100.437988,0.004825,0.001992,0.050585,29.581566,1.506957,0.505851,-100.437988,0.051626,0.000000
37.250000,6.976768,-100.393509,0.004846,0.002017,0.051236,31.034216,1.580958,0.512357,-100.393509,0.052085,0.000000
37.530003,7.036720,-100.437988,0.004855,0.002038,0.051764,31.300896,1.594544,0.517645,-100.437988,0.052554,0.000000
37.810001,7.000977,-100.393509,0.004876,0.002056,0.052216,31.141899,1.586444,0.522157,-100.393509,0.053022,0.000000
38.090000,6.987198,-100.393509,0.004894,0.002069,0.052562,31.080608,1.583322,0.525624,-100.393509,0.053490,0.000000
38.370003,7.137634,-100.482468,0.004898,0.002090,0.053083,31.749783,1.617411,0.530828,-100.482468,0.053959,0.000000
38.650002,7.163330,-100.482468,0.004907,0.002105,0.053464,31.864084,1.623234,0.534643,-100.482468,0.054418,0.000000
38.930000,7.107475,-100.482468,0.004924,0.002121,0.053872,31.615629,1.610577,0.538719,-100.482468,0.054887,0.000000
39.210003,7.387497,-100.393509,0.004945,0.002145,0.054470,32.861229,1.674031,0.544703,-100.393509,0.055355,0.000000
39.490002,7.525276,-100.437988,0.004958,0.002165,0.054999,33.474102,1.705252,0.549994,-100.437988,0.055823,0.000000
39.770000,7.493996,-100.526947,0.004971,0.002182,0.055424,33.334957,1.698164,0.554241,-100.526947,0.056292,0.000000
40.050003,7.453033,-100.526947,0.004980,0.002200,0.055884,33.152748,1.688882,0.558840,-100.526947,0.056760,0.000000
40.330002,7.673851,-100.482468,0.004988,0.002220,0.056396,34.134995,1.738919,0.563957,-100.482468,0.057219,0.000000
40.610001,7.559906,-100.437988,0.005014,0.002236,0.056795,33.628143,1.713099,0.567946,-100.437988,0.057688,0.000000
40.890003,7.569962,-100.482468,0.005023,0.002250,0.057150,33.672871,1.715378,0.571500,-100.482468,0.058156,0.000000
41.170002,7.817589,-100.571434,0.005040,0.002271,0.057688,34.774372,1.771491,0.576879,-100.571434,0.058624,0.000000
41.450001,7.866737,-100.526947,0.005049,0.002291,0.058200,34.992996,1.782628,0.581996,-100.526947,0.059093,0.000000
41.730003,7.898392,-100.526947,0.005053,0.002313,0.058746,35.133801,1.789801,0.587457,-100.526947,0.059552,0.000000
42.010002,7.788544,-100.571434,0.005083,0.002326,0.059075,34.645172,1.764909,0.590754,-100.571434,0.060020,0.000000
42.290001,7.973610,-100.571434,0.005096,0.002346,0.059587,35.468388,1.806846,0.595871,-100.571434,0.060489,0.000000
42.570004,7.933769,-100.571434,0.005092,0.002361,0.059969,35.291168,1.797818,0.599686,-100.571434,0.060957,0.000000
42.850002,7.965050,-100.615913,0.005113,0.002376,0.060341,35.430309,1.804906,0.603414,-100.615913,0.061425,0.000000
43.130001,8.156075,-100.571434,0.005113,0.002399,0.060940,36.280033,1.848193,0.609398,-100.571434,0.061894,0.000000
43.410004,8.251404,-100.571434,0.005144,0.002419,0.061443,36.704079,1.869795,0.614429,-100.571434,0.062353,0.000000
43.690002,8.236504,-100.615913,0.005165,0.002438,0.061928,36.637798,1.866418,0.619285,-100.615913,0.062822,0.000000
43.970001,8.135597,-100.660393,0.005170,0.002452,0.062293,36.188946,1.843553,0.622926,-100.660393,0.063290,0.000000
44.250004,8.284546,-100.615913,0.005174,0.002473,0.062813,36.851501,1.877305,0.628130,-100.615913,0.063758,0.000000
44.530003,8.283798,-100.615913,0.005195,0.002489,0.063221,36.848175,1.877136,0.632206,-100.615913,0.064227,0.000000
44.810001,8.449135,-100.615913,0.005200,0.002507,0.063680,37.583630,1.914601,0.636801,-100.615913,0.064686,0.000000
45.090004,8.642769,-100.615913,0.005221,0.002530,0.064270,38.444958,1.958479,0.642702,-100.615913,0.065155,0.000000
45.370003,8.569778,-100.660393,0.005238,0.002549,0.064756,38.120277,1.941939,0.647558,-100.660393,0.065623,0.000000
45.650002,8.422318,-100.660393,0.005256,0.002564,0.065120,37.464340,1.908524,0.651199,-100.660393,0.066091,0.000000
45.930000,8.382477,-100.660393,0.005243,0.002581,0.065545,37.287121,1.899496,0.655449,-100.660393,0.066559,0.000000
46.210003,8.619308,-100.660393,0.005282,0.002600,0.066048,38.340599,1.953163,0.660479,-100.660393,0.067019,0.000000
46.490002,8.692291,-100.704872,0.005286,0.002618,0.066490,38.665241,1.969701,0.664900,-100.704872,0.067487,0.000000
46.770000,8.643135,-100.749352,0.005290,0.002633,0.066872,38.446587,1.958562,0.668715,-100.749352,0.067956,0.000000
47.050003,8.882576,-100.704872,0.005312,0.002656,0.067453,39.511673,2.012820,0.674529,-100.704872,0.068424,0.000000
47.330002,8.996521,-100.704872,0.005320,0.002678,0.068034,40.018524,2.038641,0.680339,-100.704872,0.068892,0.000000
47.610001,8.836395,-100.704872,0.005338,0.002695,0.068441,39.306248,2.002356,0.684415,-100.704872,0.069360,0.000000
47.890003,8.633087,-100.749352,0.005355,0.002707,0.068753,38.401890,1.956285,0.687534,-100.749352,0.069820,0.000000
48.170002,8.627869,-100.793839,0.005346,0.002719,0.069066,38.378677,1.955103,0.690656,-100.793839,0.070289,0.000000
48.450001,9.116798,-100.704872,0.005364,0.002748,0.069794,40.553543,2.065896,0.697942,-100.704872,0.070757,0.000000
48.730003,9.098549,-100.749352,0.005385,0.002767,0.070289,40.472366,2.061761,0.702885,-100.749352,0.071225,0.000000
49.010002,9.353249,-100.660393,0.005398,0.002791,0.070896,41.605328,2.119476,0.708956,-100.660393,0.071693,0.000000
49.290001,9.202072,-100.749352,0.005433,0.002809,0.071338,40.932861,2.085219,0.713377,-100.749352,0.072153,0.000000
49.570004,8.978271,-100.749352,0.005424,0.002823,0.071702,39.937347,2.034505,0.717022,-100.749352,0.072622,0.000000
49.850002,9.100037,-100.793839,0.005415,0.002841,0.072153,40.478985,2.062098,0.721530,-100.793839,0.073090,0.000000
50.130001,9.237068,-100.793839,0.005441,0.002860,0.072647,41.088531,2.093149,0.726473,-100.793839,0.073558,0.000000
50.410004,9.070251,-100.749352,0.005471,0.002873,0.072968,40.346493,2.055348,0.729682,-100.749352,0.074026,0.000000
50.690002,9.263512,-100.793839,0.005476,0.002893,0.073489,41.206158,2.099142,0.734887,-100.793839,0.074495,0.000000
50.970001,9.670143,-100.793839,0.005484,0.002921,0.074182,43.014946,2.191286,0.741824,-100.793839,0.074954,0.000000
51.250004,9.425491,-100.793839,0.005493,0.002936,0.074573,41.926678,2.135847,0.745727,-100.793839,0.075422,0.000000
51.530003,9.324203,-100.793839,0.005510,0.002951,0.074954,41.476128,2.112895,0.749542,-100.793839,0.075891,0.000000
51.810001,9.323463,-100.838318,0.005519,0.002968,0.075388,41.472836,2.112727,0.753879,-100.838318,0.076359,0.000000
52.090004,9.631416,-100.882797,0.005540,0.002990,0.075934,42.842678,2.182510,0.759341,-100.882797,0.076827,0.000000
52.370003,9.460121,-100.927277,0.005545,0.003003,0.076264,42.080719,2.143694,0.762637,-100.927277,0.077287,0.000000
52.650002,9.591194,-100.882797,0.005545,0.003023,0.076775,42.663761,2.173396,0.767755,-100.882797,0.077755,0.000000
52.930004,9.653015,-100.838318,0.005553,0.003040,0.077226,42.938755,2.187404,0.772262,-100.838318,0.078224,0.000000
53.210003,9.855209,-100.838318,0.005583,0.003064,0.077825,43.838161,2.233222,0.778246,-100.838318,0.078692,0.000000
53.490002,9.584122,-100.882797,0.005588,0.003076,0.078137,42.632301,2.171793,0.781369,-100.882797,0.079160,0.000000
53.770004,9.866005,-100.971756,0.005588,0.003098,0.078700,43.886181,2.235669,0.787005,-100.971756,0.079629,0.000000
54.050003,9.988892,-100.927277,0.005618,0.003118,0.079203,44.432808,2.263515,0.792035,-100.927277,0.080088,0.000000
54.330002,9.682426,-100.882797,0.005627,0.003132,0.079551,43.069584,2.194069,0.795505,-100.882797,0.080557,0.000000
54.610004,10.081238,-100.882797,0.005639,0.003154,0.080114,44.843586,2.284441,0.801141,-100.882797,0.081025,0.000000
54.890003,10.019798,-100.927277,0.005644,0.003173,0.080600,44.570290,2.270519,0.805997,-100.927277,0.081493,0.000000
55.170002,9.997459,-100.927277,0.005661,0.003192,0.081085,44.470921,2.265457,0.810853,-100.927277,0.081962,0.000000
55.450001,9.994476,-100.927277,0.005665,0.003208,0.081493,44.457649,2.264781,0.814930,-100.927277,0.082421,0.000000
55.730003,10.052940,-100.971756,0.005691,0.003229,0.082013,44.717712,2.278029,0.820134,-100.971756,0.082889,0.000000
56.010002,10.215668,-100.971756,0.005704,0.003249,0.082525,45.441559,2.314903,0.825251,-100.971756,0.083358,0.000000
56.290001,10.160553,-101.016243,0.005721,0.003265,0.082924,45.196396,2.302414,0.829240,-101.016243,0.083826,0.000000
56.570004,10.250671,-100.971756,0.005717,0.003281,0.083349,45.597263,2.322835,0.833491,-100.971756,0.084294,0.000000
56.850002,10.524734,-101.016243,0.005747,0.003306,0.083982,46.816357,2.384939,0.839819,-101.016243,0.084754,0.000000
57.130001,10.409302,-100.971756,0.005764,0.003323,0.084416,46.302887,2.358782,0.844157,-100.971756,0.085222,0.000000
57.410004,10.302803,-100.971756,0.005769,0.003340,0.084832,45.829155,2.334649,0.848320,-100.971756,0.085690,0.000000
57.690002,10.421959,-101.016243,0.005777,0.003359,0.085309,46.359188,2.361650,0.853089,-101.016243,0.086159,0.000000
57.970001,10.509094,-101.016243,0.005795,0.003378,0.085794,46.746784,2.381395,0.857945,-101.016243,0.086627,0.000000
58.250004,10.354187,-101.016243,0.005803,0.003390,0.086098,46.057724,2.346292,0.860980,-101.016243,0.087095,0.000000
58.530003,10.647247,-101.016243,0.005825,0.003413,0.086696,47.361320,2.412701,0.866964,-101.016243,0.087555,0.000000
58.810001,10.820770,-101.016243,0.005833,0.003434,0.087226,48.133190,2.452022,0.872256,-101.016243,0.088023,0.000000
59.090004,10.716507,-101.060722,0.005851,0.003452,0.087676,47.669403,2.428395,0.876763,-101.060722,0.088492,0.000000
59.370003,10.612244,-101.149681,0.005864,0.003467,0.088067,47.205616,2.404769,0.880666,-101.149681,0.088960,0.000000
59.650002,10.743690,-101.060722,0.005868,0.003487,0.088570,47.790321,2.434555,0.885696,-101.060722,0.089428,0.000000
59.930004,10.883705,-101.060722,0.005872,0.003503,0.088986,48.413139,2.466283,0.889859,-101.060722,0.089888,0.000000
60.210003,10.731033,-101.105202,0.005907,0.003518,0.089350,47.734020,2.431687,0.893500,-101.105202,0.090356,0.000000
60.490002,11.128723,-101.149681,0.005915,0.003539,0.089897,49.503033,2.521805,0.898966,-101.149681,0.090825,0.000000
60.770004,11.308205,-101.149681,0.005928,0.003562,0.090478,50.301407,2.562476,0.904775,-101.149681,0.091293,0.000000
61.050003,11.270599,-101.060722,0.005933,0.003580,0.090920,50.134129,2.553954,0.909200,-101.060722,0.091761,0.000000
61.330002,11.187927,-101.105202,0.005959,0.003595,0.091310,49.766384,2.535220,0.913102,-101.105202,0.092229,0.000000
61.610004,11.491783,-101.105202,0.005963,0.003618,0.091891,51.118004,2.604075,0.918912,-101.105202,0.092689,0.000000
61.890003,11.364059,-101.149681,0.005976,0.003631,0.092229,50.549862,2.575133,0.922292,-101.149681,0.093157,0.000000
62.170002,11.269478,-101.149681,0.005980,0.003648,0.092654,50.129143,2.553700,0.926542,-101.149681,0.093625,0.000000
62.450005,11.712601,-101.194160,0.005997,0.003669,0.093201,52.100250,2.654113,0.932008,-101.194160,0.094094,0.000000
62.730003,11.901772,-101.105202,0.006015,0.003689,0.093704,52.941723,2.696980,0.937038,-101.105202,0.094562,0.000000
63.010002,11.952042,-101.194160,0.006028,0.003708,0.094181,53.165337,2.708371,0.941807,-101.194160,0.095022,0.000000
63.290005,11.771439,-101.149681,0.006040,0.003723,0.094553,52.361973,2.667446,0.945535,-101.149681,0.095490,0.000000
63.570004,12.097267,-101.238647,0.006049,0.003741,0.095022,53.811333,2.741280,0.950217,-101.238647,0.095958,0.000000
63.850002,11.976990,-101.194160,0.006071,0.003756,0.095412,53.276310,2.714025,0.954119,-101.194160,0.096427,0.000000
64.130005,12.031731,-101.194160,0.006084,0.003773,0.095837,53.519810,2.726429,0.958369,-101.194160,0.096895,0.000000
64.410004,12.700134,-101.238647,0.006092,0.003796,0.096427,56.493019,2.877892,0.964266,-101.238647,0.097355,0.000000
64.690002,12.764931,-101.238647,0.006092,0.003816,0.096938,56.781246,2.892575,0.969384,-101.238647,0.097823,0.000000
64.970001,12.941803,-101.238647,0.006105,0.003835,0.097415,57.568016,2.932655,0.974153,-101.238647,0.098291,0.000000
65.250000,12.861374,-101.238647,0.006118,0.003850,0.097797,57.210247,2.914429,0.977968,-101.238647,0.098760,0.000000
65.530006,12.920952,-101.194160,0.006144,0.003865,0.098179,57.475266,2.927930,0.981787,-101.194160,0.099228,0.000000
65.810005,13.263161,-101.283127,0.006153,0.003883,0.098629,58.997486,3.005475,0.986294,-101.283127,0.099696,0.000000
66.090004,13.647827,-101.283127,0.006161,0.003904,0.099167,60.708569,3.092642,0.991673,-101.283127,0.100156,0.000000
66.370003,13.942001,-101.283127,0.006174,0.003922,0.099609,62.017120,3.159303,0.996094,-101.283127,0.100624,0.000000
66.650002,14.246971,-101.283127,0.006187,0.003944,0.100182,63.373692,3.228410,1.001816,-101.283127,0.101092,0.000000
66.930000,14.314369,-101.238647,0.006209,0.003962,0.100624,63.673492,3.243683,1.006241,-101.238647,0.101561,0.000000
67.210007,14.302078,-101.283127,0.006222,0.003976,0.100979,63.618820,3.240897,1.009795,-101.283127,0.102029,0.000000
67.490005,14.351608,-101.327606,0.006230,0.003988,0.101300,63.839142,3.252121,1.013004,-101.327606,0.102489,0.000000
67.770004,15.021507,-101.372086,0.006247,0.004011,0.101890,66.819000,3.403922,1.018901,-101.372086,0.102957,0.000000
68.050003,15.237106,-101.327606,0.006269,0.004028,0.102324,67.778030,3.452778,1.023239,-101.327606,0.103425,0.000000
68.330002,15.979996,-101.327606,0.006269,0.004051,0.102905,71.082573,3.621119,1.029049,-101.327606,0.103893,0.000000
68.610001,16.487160,-101.327606,0.006295,0.004075,0.103512,73.338547,3.736044,1.035120,-101.327606,0.104362,0.000000
68.890007,16.545998,-101.327606,0.006303,0.004092,0.103937,73.600273,3.749377,1.039370,-101.327606,0.104830,0.000000
69.170006,16.440620,-101.372086,0.006312,0.004104,0.104241,73.131531,3.725498,1.042405,-101.372086,0.105290,0.000000
69.450005,16.636482,-101.327606,0.006321,0.004117,0.104579,74.002769,3.769881,1.045785,-101.327606,0.105758,0.000000
69.730003,17.225204,-101.372086,0.006338,0.004137,0.105073,76.621536,3.903287,1.050728,-101.372086,0.106226,0.000000
70.010002,17.929733,-101.416565,0.006359,0.004160,0.105654,79.755440,4.062936,1.056538,-101.416565,0.106695,0.000000
70.290001,18.771294,-101.416565,0.006364,0.004186,0.106322,83.498886,4.253636,1.063219,-101.416565,0.107163,0.000000
70.570000,19.074409,-101.372086,0.006390,0.004204,0.106781,84.847214,4.322323,1.067814,-101.372086,0.107623,0.000000
70.850006,19.187981,-101.327606,0.006403,0.004219,0.107154,85.352402,4.348058,1.071542,-101.327606,0.108091,0.000000
71.130005,19.591629,-101.372086,0.006424,0.004237,0.107623,87.147919,4.439527,1.076227,-101.372086,0.108559,0.000000
71.410004,20.131577,-101.461052,0.006433,0.004253,0.108039,89.549728,4.561881,1.080387,-101.461052,0.109028,0.000000
71.690002,20.353508,-101.461052,0.006446,0.004267,0.108386,90.536926,4.612171,1.083858,-101.461052,0.109496,0.000000
71.970001,21.218903,-101.416565,0.006446,0.004289,0.108941,94.386391,4.808272,1.089406,-101.416565,0.109955,0.000000
72.250000,22.253349,-101.461052,0.006476,0.004314,0.109574,98.987839,5.042681,1.095738,-101.461052,0.110424,0.000000
72.530006,22.588860,-101.461052,0.006485,0.004332,0.110025,100.480263,5.118709,1.100246,-101.461052,0.110892,0.000000
72.810005,22.870369,-101.416565,0.006515,0.004349,0.110467,101.732483,5.182500,1.104671,-101.416565,0.111360,0.000000
73.090004,23.076294,-101.505531,0.006506,0.004361,0.110771,102.648483,5.229163,1.107706,-101.505531,0.111829,0.000000
73.370003,23.931259,-101.461052,0.006515,0.004383,0.111317,106.451561,5.422901,1.113168,-101.461052,0.112297,0.000000
73.650002,24.764633,-101.461052,0.006541,0.004401,0.111777,110.158592,5.611746,1.117766,-101.461052,0.112757,0.000000
73.930000,25.166420,-101.505531,0.006541,0.004416,0.112167,111.945824,5.702792,1.121669,-101.505531,0.113225,0.000000
74.210007,25.990479,-101.505531,0.006558,0.004436,0.112679,115.611420,5.889527,1.126786,-101.505531,0.113693,0.000000
74.490005,26.835022,-101.505531,0.006571,0.004458,0.113233,119.368141,6.080903,1.132335,-101.505531,0.114162,0.000000
74.770004,27.288940,-101.550011,0.006579,0.004473,0.113606,121.387268,6.183762,1.136063,-101.550011,0.114630,0.000000
75.050003,27.940598,-101.461052,0.006614,0.004492,0.114109,124.285988,6.331430,1.141093,-101.461052,0.115090,0.000000
75.330002,28.906898,-101.594490,0.006614,0.004513,0.114621,128.584305,6.550397,1.146210,-101.594490,0.115558,0.000000
75.610001,29.268105,-101.594490,0.006631,0.004525,0.114925,130.191025,6.632247,1.149246,-101.594490,0.116026,0.000000
75.890007,30.401978,-101.594490,0.006631,0.004550,0.115566,135.234756,6.889186,1.155665,-101.594490,0.116494,0.000000
76.170006,31.408127,-101.505531,0.006648,0.004568,0.116035,139.710327,7.117183,1.160347,-101.505531,0.116963,0.000000
76.450005,32.160324,-101.550011,0.006661,0.004587,0.116520,143.056259,7.287634,1.165203,-101.550011,0.117431,0.000000
76.730003,32.715157,-101.594490,0.006683,0.004604,0.116945,145.524292,7.413360,1.169453,-101.594490,0.117890,0.000000
77.010002,33.527298,-101.638969,0.006683,0.004622,0.117396,149.136871,7.597394,1.173961,-101.638969,0.118359,0.000000
77.290001,34.658195,-101.638969,0.006691,0.004643,0.117925,154.167358,7.853659,1.179252,-101.638969,0.118827,0.000000
77.570007,35.324371,-101.594490,0.006704,0.004659,0.118342,157.130646,8.004617,1.183416,-101.594490,0.119295,0.000000
77.850006,36.134277,-101.594490,0.006726,0.004678,0.118810,160.733292,8.188144,1.188097,-101.594490,0.119764,0.000000
78.130005,37.503494,-101.638969,0.006730,0.004699,0.119365,166.823868,8.498414,1.193650,-101.638969,0.120223,0.000000
78.410004,38.474266,-101.727936,0.006743,0.004720,0.119876,171.142090,8.718393,1.198763,-101.727936,0.120692,0.000000
78.690002,38.971016,-101.594490,0.006756,0.004735,0.120258,173.351730,8.830958,1.202582,-101.594490,0.121160,0.000000
78.970001,39.947372,-101.594490,0.006769,0.004751,0.120665,177.694794,9.052204,1.206655,-101.594490,0.121628,0.000000
79.250000,41.090927,-101.638969,0.006786,0.004772,0.121203,182.781570,9.311337,1.212033,-101.638969,0.122097,0.000000
79.530006,41.737740,-101.683456,0.006799,0.004784,0.121524,185.658737,9.457908,1.215243,-101.683456,0.122556,0.000000
79.810005,43.214943,-101.727936,0.006791,0.004808,0.122123,192.229660,9.792645,1.221227,-101.727936,0.123025,0.000000
80.090004,44.447495,-101.727936,0.006808,0.004829,0.122652,197.712326,10.071947,1.226518,-101.727936,0.123493,0.000000
80.370003,45.393318,-101.727936,0.006838,0.004847,0.123120,201.919571,10.286273,1.231200,-101.727936,0.123961,0.000000
80.650002,46.277702,-101.683456,0.006847,0.004862,0.123502,205.853500,10.486678,1.235015,-101.683456,0.124430,0.000000
80.930000,47.316994,-101.772415,0.006838,0.004881,0.123978,210.476501,10.722184,1.239784,-101.772415,0.124898,0.000000
81.210007,48.286652,-101.727936,0.006864,0.004899,0.124430,214.789749,10.941912,1.244296,-101.727936,0.125357,0.000000
81.490005,49.197479,-101.683456,0.006860,0.004912,0.124776,218.841324,11.148308,1.247763,-101.683456,0.125826,0.000000
81.770004,50.288528,-101.683456,0.006877,0.004934,0.125314,223.694550,11.395544,1.253141,-101.683456,0.126294,0.000000
82.050003,51.877815,-101.727936,0.006881,0.004953,0.125808,230.764053,11.755681,1.258084,-101.727936,0.126762,0.000000
82.330002,53.076851,-101.772415,0.006898,0.004974,0.126329,236.097626,12.027386,1.263288,-101.772415,0.127230,0.000000
82.610001,54.170143,-101.816895,0.006916,0.004990,0.126736,240.960831,12.275130,1.267361,-101.816895,0.127690,0.000000
82.890007,55.264915,-101.772415,0.006920,0.005010,0.127265,245.830627,12.523209,1.272652,-101.772415,0.128158,0.000000
83.170006,56.691475,-101.816895,0.006937,0.005028,0.127716,252.176270,12.846472,1.277164,-101.816895,0.128627,0.000000
83.450005,57.172951,-101.772415,0.006942,0.005038,0.127976,254.317993,12.955576,1.279764,-101.772415,0.129095,0.000000
83.730003,58.004829,-101.816895,0.006946,0.005057,0.128445,258.018372,13.144082,1.284446,-101.816895,0.129563,0.000000
84.010002,60.208534,-101.816895,0.006959,0.005083,0.129104,267.820923,13.643449,1.291039,-101.816895,0.130032,0.000000
84.290001,61.659294,-101.772415,0.006967,0.005104,0.129633,274.274231,13.972197,1.296327,-101.772415,0.130491,0.000000
84.570007,62.441650,-101.816895,0.006985,0.005116,0.129945,277.754333,14.149480,1.299449,-101.816895,0.130960,0.000000
84.850006,63.675316,-101.861382,0.006985,0.005136,0.130465,283.241943,14.429032,1.304653,-101.861382,0.131428,0.000000
85.130005,64.904152,-101.861382,0.007002,0.005150,0.130821,288.708099,14.707491,1.308207,-101.861382,0.131896,0.000000
85.410004,65.918114,-101.905861,0.007002,0.005168,0.131263,293.218414,14.937258,1.312632,-101.905861,0.132365,0.000000
85.690002,67.282112,-101.772415,0.007023,0.005187,0.131749,299.285797,15.246345,1.317488,-101.772415,0.132824,0.000000
85.970001,67.022209,-101.905861,0.007036,0.005179,0.131549,298.129669,15.187449,1.315493,-101.905861,0.131801,0.000000
86.250008,66.508705,-101.861382,0.007041,0.005176,0.131480,295.845490,15.071088,1.314801,-101.861382,0.131549,0.000000
86.530006,66.034676,-101.905861,0.007036,0.005175,0.131445,293.736908,14.963672,1.314452,-101.905861,0.131549,0.000000
86.810005,65.635490,-101.816895,0.007036,0.005174,0.131419,291.961243,14.873215,1.314191,-101.816895,0.131549,0.000000
87.090004,65.289558,-101.861382,0.007045,0.005173,0.131402,290.422455,14.794826,1.314021,-101.861382,0.131549,0.000000
87.370003,64.967445,-101.905861,0.007058,0.005173,0.131393,288.989624,14.721833,1.313934,-101.905861,0.131549,0.000000
87.650002,64.694496,-101.905861,0.007062,0.005173,0.131385,287.775482,14.659982,1.313847,-101.905861,0.131549,0.000000
87.930008,64.443153,-102.039299,0.007045,0.005172,0.131376,286.657471,14.603027,1.313760,-102.039299,0.131549,0.000000
88.210007,64.226433,-101.950340,0.007049,0.005172,0.131367,285.693451,14.553918,1.313673,-101.950340,0.131549,0.000000
88.490005,64.005989,-101.950340,0.007054,0.005172,0.131367,284.712860,14.503964,1.313673,-101.950340,0.131549,0.000000
88.770004,63.817192,-101.994820,0.007062,0.005172,0.131367,283.873047,14.461182,1.313673,-101.994820,0.131549,0.000000
89.050003,63.628395,-101.994820,0.007054,0.005172,0.131359,283.033234,14.418400,1.313586,-101.994820,0.131549,0.000000
89.330002,63.459709,-101.950340,0.007062,0.005172,0.131359,282.282898,14.380176,1.313586,-101.950340,0.131549,0.000000
89.610001,63.312263,-101.994820,0.007062,0.005172,0.131359,281.627014,14.346764,1.313586,-101.994820,0.131549,0.000000
89.890007,63.166664,-101.950340,0.007058,0.005172,0.131359,280.979370,14.313770,1.313586,-101.950340,0.131549,0.000000
90.170006,63.025536,-101.994820,0.007067,0.005172,0.131359,280.351593,14.281791,1.313586,-101.994820,0.131549,0.000000
90.450005,62.896690,-101.994820,0.007058,0.005172,0.131359,279.778442,14.252594,1.313586,-101.994820,0.131549,0.000000
90.730003,62.779388,-102.039299,0.007045,0.005172,0.131359,279.256653,14.226013,1.313586,-102.039299,0.131549,0.000000
91.010002,62.654648,-102.039299,0.007067,0.005171,0.131350,278.701782,14.197746,1.313499,-102.039299,0.131549,0.000000
91.290001,62.532883,-101.994820,0.007062,0.005171,0.131350,278.160156,14.170154,1.313499,-101.994820,0.131549,0.000000
91.570007,62.427124,-102.083786,0.007075,0.005171,0.131350,277.689728,14.146189,1.313499,-102.083786,0.131549,0.000000
91.850006,62.333290,-102.083786,0.007058,0.005171,0.131350,277.272308,14.124926,1.313499,-102.083786,0.131549,0.000000
92.130005,62.237587,-102.083786,0.007049,0.005171,0.131350,276.846619,14.103238,1.313499,-102.083786,0.131549,0.000000
92.410004,62.153809,-102.039299,0.007067,0.005171,0.131350,276.473938,14.084254,1.313499,-102.039299,0.131549,0.000000
92.690002,62.055496,-101.994820,0.007062,0.005171,0.131350,276.036621,14.061976,1.313499,-101.994820,0.131549,0.000000
92.970001,61.965385,-102.039299,0.007071,0.005171,0.131350,275.635803,14.041557,1.313499,-102.039299,0.131549,0.000000
93.250008,61.877502,-102.128265,0.007062,0.005171,0.131350,275.244873,14.021643,1.313499,-102.128265,0.131549,0.000000
93.530006,61.796700,-102.172745,0.007071,0.005171,0.131350,274.885437,14.003332,1.313499,-102.172745,0.131549,0.000000
93.810005,61.728928,-102.128265,0.007067,0.005171,0.131350,274.583984,13.987975,1.313499,-102.128265,0.131549,0.000000
94.090004,61.658180,-102.128265,0.007075,0.005171,0.131350,274.269287,13.971944,1.313499,-102.128265,0.131549,0.000000
94.370003,61.578117,-102.083786,0.007062,0.005171,0.131350,273.913147,13.953800,1.313499,-102.083786,0.131549,0.000000
94.650002,61.518913,-102.172745,0.007075,0.005171,0.131350,273.649780,13.940385,1.313499,-102.172745,0.131549,0.000000
94.930008,61.442200,-102.128265,0.007075,0.005171,0.131350,273.308563,13.923001,1.313499,-102.128265,0.131549,0.000000
95.210007,61.373688,-102.128265,0.007075,0.005171,0.131350,273.003784,13.907476,1.313499,-102.128265,0.131549,0.000000
95.490005,61.318947,-102.172745,0.007084,0.005171,0.131350,272.760284,13.895072,1.313499,-102.172745,0.131549,0.000000
95.770004,61.248566,-102.172745,0.007071,0.005171,0.131350,272.447235,13.879124,1.313499,-102.172745,0.131549,0.000000
96.050003,61.197922,-102.172745,0.007058,0.005171,0.131350,272.221954,13.867647,1.313499,-102.172745,0.131549,0.000000
96.330002,61.148026,-102.128265,0.007071,0.005171,0.131350,272.000000,13.856341,1.313499,-102.128265,0.131549,0.000000
96.610008,61.105949,-102.128265,0.007084,0.005171,0.131350,271.812836,13.846806,1.313499,-102.128265,0.131549,0.000000
96.890007,61.053444,-102.128265,0.007071,0.005171,0.131350,271.579285,13.834908,1.313499,-102.128265,0.131549,0.000000
97.170006,60.975616,-102.217224,0.007071,0.005171,0.131350,271.233093,13.817272,1.313499,-102.217224,0.131549,0.000000
97.450005,60.917526,-102.172745,0.007071,0.005171,0.131350,270.974701,13.804109,1.313499,-102.172745,0.131549,0.000000
97.730003,60.873962,-102.172745,0.007067,0.005171,0.131350,270.780914,13.794237,1.313499,-102.172745,0.131549,0.000000
98.010002,60.812523,-102.172745,0.007075,0.005171,0.131350,270.507599,13.780314,1.313499,-102.172745,0.131549,0.000000
98.290001,60.765228,-102.217224,0.007071,0.005171,0.131350,270.297241,13.769598,1.313499,-102.217224,0.131549,0.000000
98.570007,60.720169,-102.217224,0.007067,0.005171,0.131350,270.096802,13.759387,1.313499,-102.217224,0.131549,0.000000
98.850006,60.676605,-102.261703,0.007075,0.005171,0.131350,269.903015,13.749516,1.313499,-102.261703,0.131549,0.000000
99.130005,60.636017,-102.306190,0.007062,0.005171,0.131350,269.722473,13.740318,1.313499,-102.306190,0.131549,0.000000
99.410004,60.591331,-102.306190,0.007071,0.005171,0.131350,269.523712,13.730192,1.313499,-102.306190,0.131549,0.000000
99.690002,60.559677,-102.261703,0.007075,0.005171,0.131341,269.382904,13.723019,1.313412,-102.261703,0.131549,0.000000
99.970001,60.509407,-102.306190,0.007075,0.005171,0.131341,269.159271,13.711628,1.313412,-102.306190,0.131549,0.000000
100.250008,60.471428,-102.350670,0.007075,0.005171,0.131341,268.990356,13.703021,1.313412,-102.350670,0.131549,0.000000
100.530006,60.421158,-102.261703,0.007080,0.005171,0.131341,268.766724,13.691630,1.313412,-102.261703,0.131549,0.000000
100.810005,60.386894,-102.261703,0.007080,0.005171,0.131341,268.614319,13.683866,1.313412,-102.261703,0.131549,0.000000
101.090004,60.346306,-102.306190,0.007084,0.005171,0.131341,268.433777,13.674668,1.313412,-102.306190,0.131549,0.000000
101.370003,60.300880,-102.350670,0.007084,0.005171,0.131341,268.231720,13.664375,1.313412,-102.350670,0.131549,0.000000
101.650002,60.275185,-102.350670,0.007084,0.005171,0.131341,268.117401,13.658552,1.313412,-102.350670,0.131549,0.000000
101.930008,60.229759,-102.350670,0.007062,0.005171,0.131341,267.915344,13.648258,1.313412,-102.350670,0.131549,0.000000
102.210007,60.202576,-102.350670,0.007075,0.005171,0.131341,267.794434,13.642098,1.313412,-102.350670,0.131549,0.000000
102.490005,60.154541,-102.350670,0.007088,0.005171,0.131341,267.580750,13.631213,1.313412,-102.350670,0.131549,0.000000
102.770004,60.126984,-102.350670,0.007071,0.005171,0.131341,267.458191,13.624969,1.313412,-102.350670,0.131549,0.000000
103.050003,60.096451,-102.350670,0.007080,0.005171,0.131341,267.322357,13.618051,1.313412,-102.350670,0.131549,0.000000
103.330002,60.059212,-102.395149,0.007067,0.005171,0.131341,267.156708,13.609612,1.313412,-102.395149,0.131549,0.000000
103.610008,60.016388,-102.395149,0.007080,0.005171,0.131341,266.966217,13.599908,1.313412,-102.395149,0.131549,0.000000
103.890007,59.994415,-102.439629,0.007075,0.005171,0.131341,266.868500,13.594929,1.313412,-102.439629,0.131549,0.000000
104.170006,59.958298,-102.395149,0.007084,0.005171,0.131341,266.707825,13.586745,1.313412,-102.395149,0.131549,0.000000
104.450005,59.941170,-102.395149,0.007071,0.005171,0.131341,266.631653,13.582863,1.313412,-102.395149,0.131549,0.000000
104.730003,59.892761,-102.484108,0.007071,0.005171,0.131341,266.416321,13.571894,1.313412,-102.484108,0.131549,0.000000
105.010002,59.867813,-102.439629,0.007084,0.005171,0.131341,266.305328,13.566240,1.313412,-102.439629,0.131549,0.000000
105.290009,59.834671,-102.528595,0.007084,0.005171,0.131341,266.157898,13.558731,1.313412,-102.528595,0.131549,0.000000
105.570007,59.803017,-102.395149,0.007080,0.005171,0.131341,266.017090,13.551557,1.313412,-102.395149,0.131549,0.000000
105.850006,59.779182,-102.395149,0.007088,0.005171,0.131341,265.911072,13.546156,1.313412,-102.395149,0.131549,0.000000
106.130005,59.750885,-102.395149,0.007084,0.005171,0.131341,265.785217,13.539744,1.313412,-102.395149,0.131549,0.000000
106.410004,59.727425,-102.484108,0.007084,0.005171,0.131341,265.680847,13.534428,1.313412,-102.484108,0.131549,0.000000
106.690002,59.690933,-102.528595,0.007088,0.005171,0.131341,265.518524,13.526159,1.313412,-102.528595,0.131549,0.000000
106.970009,59.647736,-102.573074,0.007088,0.005171,0.131341,265.326385,13.516370,1.313412,-102.573074,0.131549,0.000000
107.250008,59.630234,-102.484108,0.007088,0.005171,0.131341,265.248535,13.512404,1.313412,-102.484108,0.131549,0.000000
107.530006,59.611992,-102.484108,0.007071,0.005171,0.131341,265.167389,13.508270,1.313412,-102.484108,0.131549,0.000000
107.810005,59.576614,-102.528595,0.007084,0.005171,0.131341,265.010010,13.500254,1.313412,-102.528595,0.131549,0.000000
108.090004,59.553528,-102.617554,0.007075,0.005171,0.131341,264.907318,13.495022,1.313412,-102.617554,0.131549,0.000000
108.370003,59.539375,-102.573074,0.007084,0.005171,0.131341,264.844360,13.491816,1.313412,-102.573074,0.131549,0.000000
108.650002,59.508842,-102.528595,0.007088,0.005171,0.131341,264.708557,13.484897,1.313412,-102.528595,0.131549,0.000000
108.930008,59.492462,-102.528595,0.007092,0.005171,0.131341,264.635681,13.481185,1.313412,-102.528595,0.131549,0.000000
109.210007,59.473839,-102.573074,0.007092,0.005171,0.131341,264.552856,13.476964,1.313412,-102.573074,0.131549,0.000000
109.490005,59.455963,-102.617554,0.007088,0.005171,0.131341,264.473328,13.472914,1.313412,-102.617554,0.131549,0.000000
109.770004,59.425804,-102.573074,0.007088,0.005171,0.131341,264.339172,13.466080,1.313412,-102.573074,0.131549,0.000000
110.050003,59.406067,-102.528595,0.007088,0.005171,0.131341,264.251373,13.461607,1.313412,-102.528595,0.131549,0.000000
110.330002,59.367714,-102.617554,0.007080,0.005171,0.131341,264.080780,13.452916,1.313412,-102.617554,0.131549,0.000000
110.610008,59.348724,-102.617554,0.007092,0.005171,0.131341,263.996307,13.448613,1.313412,-102.617554,0.131549,0.000000
110.890007,59.332336,-102.662033,0.007092,0.005171,0.131341,263.923401,13.444900,1.313412,-102.662033,0.131549,0.000000
111.170006,59.300690,-102.617554,0.007084,0.005171,0.131341,263.782654,13.437728,1.313412,-102.617554,0.131549,0.000000
111.450005,59.292870,-102.662033,0.007088,0.005171,0.131341,263.747864,13.435956,1.313412,-102.662033,0.131549,0.000000
111.730003,59.256004,-102.573074,0.007092,0.005171,0.131341,263.583862,13.427602,1.313412,-102.573074,0.131549,0.000000
112.010002,59.249298,-102.662033,0.007092,0.005171,0.131341,263.554047,13.426084,1.313412,-102.662033,0.131549,0.000000
112.290009,59.219139,-102.662033,0.007084,0.005171,0.131341,263.419891,13.419249,1.313412,-102.662033,0.131549,0.000000
112.570007,59.207970,-102.662033,0.007080,0.005171,0.131341,263.370209,13.416718,1.313412,-102.662033,0.131549,0.000000
112.850006,59.168869,-102.662033,0.007092,0.005171,0.131341,263.196289,13.407858,1.313412,-102.662033,0.131549,0.000000
113.130005,59.146523,-102.662033,0.007097,0.005171,0.131341,263.096863,13.402794,1.313412,-102.662033,0.131549,0.000000
113.410004,59.141312,-102.750999,0.007092,0.005171,0.131341,263.073700,13.401612,1.313412,-102.750999,0.131549,0.000000
113.690002,59.106682,-102.750999,0.007084,0.005171,0.131341,262.919647,13.393766,1.313412,-102.750999,0.131549,0.000000
113.970009,59.097000,-102.706512,0.007084,0.005171,0.131341,262.876587,13.391572,1.313412,-102.706512,0.131549,0.000000
114.250008,59.081360,-102.662033,0.007088,0.005171,0.131341,262.807007,13.388027,1.313412,-102.662033,0.131549,0.000000
114.530006,59.054176,-102.706512,0.007088,0.005171,0.131341,262.686096,13.381867,1.313412,-102.706512,0.131549,0.000000
114.810005,59.031090,-102.706512,0.007097,0.005171,0.131341,262.583405,13.376636,1.313412,-102.706512,0.131549,0.000000
115.090004,58.997200,-102.750999,0.007088,0.005171,0.131341,262.432648,13.368957,1.313412,-102.750999,0.131549,0.000000
115.370003,58.980072,-102.706512,0.007088,0.005171,0.131341,262.356476,13.365075,1.313412,-102.706512,0.131549,0.000000
115.650009,58.966293,-102.706512,0.007084,0.005171,0.131341,262.295166,13.361954,1.313412,-102.706512,0.131549,0.000000
115.930008,58.939484,-102.795479,0.007097,0.005171,0.131341,262.175903,13.355878,1.313412,-102.795479,0.131549,0.000000
116.200005,58.933525,-102.750999,0.007080,0.005171,0.131341,262.149414,13.354527,1.313412,-102.750999,0.131549,0.000000