File: Data/compression 4/AutoNoheating-12-4-3-240223_02232024_163935.csv
Time (sec),S:Load (lbs),S:HL1 (DIM),S:LVDT (in),S:Position (in),Ch:Position (mm),Ch:Load (N),Ch:Stress (MPa),Ch:Strain (mm/mm),Ch:HL1 (DIM),Set Point (),Cycles ()
0.010000,0.003357,-125.614204,0.000000,-0.000000,-0.000000,0.014932,0.000761,-0.000000,-125.614204,-0.000191,0.000000
0.270000,0.002983,-125.614204,-0.000017,-0.000000,-0.000000,0.013269,0.000676,-0.000000,-125.614204,-0.000191,0.000000
0.530000,-0.002228,-125.658684,0.000013,0.000090,0.002298,-0.009910,-0.000505,0.022982,-125.658684,0.003018,0.000000
0.790000,-0.027550,-125.614204,0.000116,0.000248,0.006305,-0.122547,-0.006243,0.063047,-125.614204,0.007354,0.000000
1.050000,-0.002975,-125.614204,0.000285,0.000415,0.010537,-0.013236,-0.000674,0.105368,-125.614204,0.011673,0.000000
1.310000,-0.017502,-125.658684,0.000466,0.000594,0.015098,-0.077852,-0.003966,0.150983,-125.658684,0.016009,0.000000
1.570000,-0.049149,-125.658684,0.000629,0.000759,0.019278,-0.218624,-0.011137,0.192784,-125.658684,0.020345,0.000000
1.830000,0.017136,-125.658684,0.000815,0.000925,0.023502,0.076223,0.003883,0.235017,-125.658684,0.024664,0.000000
2.090000,0.007080,-125.703171,0.000979,0.001106,0.028098,0.031494,0.001604,0.280981,-125.703171,0.029000,0.000000
2.350000,-0.008560,-125.614204,0.001160,0.001271,0.032278,-0.038078,-0.001940,0.322782,-125.614204,0.033336,0.000000
2.610000,0.017502,-125.703171,0.001328,0.001437,0.036493,0.077852,0.003966,0.364928,-125.703171,0.037672,0.000000
2.870000,-0.018616,-125.703171,0.001487,0.001615,0.041020,-0.082807,-0.004218,0.410197,-125.703171,0.041991,0.000000
3.130000,-0.023087,-125.703171,0.001664,0.001780,0.045217,-0.102694,-0.005231,0.452172,-125.703171,0.046327,0.000000
3.390000,-0.001862,-125.747650,0.001845,0.001951,0.049553,-0.008281,-0.000422,0.495534,-125.747650,0.050663,0.000000
3.650000,-0.040955,-125.614204,0.002031,0.002129,0.054072,-0.182175,-0.009280,0.540716,-125.614204,0.055000,0.000000
3.910000,-0.008560,-125.703171,0.002199,0.002296,0.058312,-0.038078,-0.001940,0.583122,-125.703171,0.059318,0.000000
4.170000,0.030907,-125.747650,0.002354,0.002457,0.062397,0.137480,0.007004,0.623968,-125.747650,0.063655,0.000000
4.430000,-0.005211,-125.703171,0.002539,0.002639,0.067019,-0.023179,-0.001181,0.670193,-125.703171,0.067991,0.000000
4.690000,-0.000740,-125.747650,0.002721,0.002809,0.071347,-0.003292,-0.000168,0.713466,-125.747650,0.072327,0.000000
4.950000,0.002983,-125.703171,0.002884,0.002974,0.075535,0.013269,0.000676,0.755353,-125.703171,0.076645,0.000000
5.210000,-0.013405,-125.792130,0.003070,0.003149,0.079993,-0.059628,-0.003038,0.799928,-125.792130,0.080981,0.000000
5.470000,-0.002228,-125.747650,0.003221,0.003315,0.084199,-0.009910,-0.000505,0.841990,-125.747650,0.085318,0.000000
5.730000,-0.017502,-125.792130,0.003393,0.003484,0.088500,-0.077852,-0.003966,0.885005,-125.792130,0.089654,0.000000
5.990000,-0.023827,-125.836609,0.003574,0.003658,0.092914,-0.105986,-0.005399,0.929144,-125.836609,0.093973,0.000000
6.250000,-0.005211,-125.747650,0.003747,0.003830,0.097294,-0.023179,-0.001181,0.972939,-125.747650,0.098309,0.000000
6.510000,0.034264,-125.792130,0.003915,0.003997,0.101526,0.152412,0.007764,1.015262,-125.792130,0.102645,0.000000
6.770000,-0.001488,-125.747650,0.004100,0.004169,0.105888,-0.006618,-0.000337,1.058883,-125.747650,0.106964,0.000000
7.030000,-0.008560,-125.836609,0.004286,0.004341,0.110250,-0.038078,-0.001940,1.102504,-125.836609,0.111300,0.000000
7.290000,0.001122,-125.792130,0.004424,0.004504,0.114396,0.004989,0.000254,1.143956,-125.792130,0.115636,0.000000
7.550000,-0.043190,-125.792130,0.004618,0.004679,0.118845,-0.192119,-0.009787,1.188448,-125.792130,0.119972,0.000000
7.810000,-0.005585,-125.881088,0.004786,0.004848,0.123146,-0.024842,-0.001266,1.231459,-125.881088,0.124291,0.000000
8.070001,0.020485,-125.792130,0.004954,0.005019,0.127482,0.091121,0.004642,1.274823,-125.792130,0.128627,0.000000
8.330000,-0.012657,-125.836609,0.005126,0.005192,0.131879,-0.056302,-0.002868,1.318792,-125.836609,0.132963,0.000000
8.590000,0.003731,-125.925575,0.005303,0.005366,0.136284,0.016595,0.000845,1.362844,-125.925575,0.137299,0.000000
8.850000,0.019363,-125.792130,0.005476,0.005536,0.140612,0.086133,0.004388,1.406121,-125.792130,0.141618,0.000000
9.110001,-0.029045,-125.881088,0.005652,0.005705,0.144896,-0.129199,-0.006582,1.448962,-125.881088,0.145954,0.000000
9.370001,0.010429,-125.881088,0.005816,0.005873,0.149180,0.046392,0.002363,1.491803,-125.881088,0.150290,0.000000
9.630000,-0.008560,-125.881088,0.005984,0.006044,0.153525,-0.038078,-0.001940,1.535250,-125.881088,0.154626,0.000000
9.890000,-0.051010,-125.970055,0.006165,0.006213,0.157809,-0.226904,-0.011559,1.578091,-125.970055,0.158945,0.000000
10.150001,0.018623,-125.925575,0.006347,0.006384,0.162162,0.082841,0.004220,1.621625,-125.925575,0.163281,0.000000
10.410001,0.010429,-125.970055,0.006528,0.006561,0.166646,0.046392,0.002363,1.666461,-125.970055,0.167617,0.000000
10.670000,-0.011543,-125.881088,0.006696,0.006727,0.170861,-0.051347,-0.002616,1.708609,-125.881088,0.171954,0.000000
10.930000,0.020485,-125.925575,0.006860,0.006898,0.175214,0.091121,0.004642,1.752143,-125.925575,0.176272,0.000000
11.190001,0.025696,-126.014534,0.007036,0.007071,0.179611,0.114301,0.005823,1.796112,-126.014534,0.180609,0.000000
11.450001,0.008942,-125.881088,0.007205,0.007237,0.183808,0.039774,0.002026,1.838083,-125.881088,0.184945,0.000000
11.710001,0.014900,-125.970055,0.007360,0.007405,0.188084,0.066279,0.003376,1.880841,-125.970055,0.189263,0.000000
11.970000,-0.004837,-125.970055,0.007558,0.007585,0.192654,-0.021516,-0.001096,1.926544,-125.970055,0.193599,0.000000
12.230000,-0.026436,-125.925575,0.007718,0.007747,0.196765,-0.117593,-0.005990,1.967648,-125.925575,0.197935,0.000000
12.490001,0.054741,-125.925575,0.007894,0.007916,0.201066,0.243500,0.012404,2.010663,-125.925575,0.202272,0.000000
12.750001,0.047295,-126.014534,0.008084,0.008098,0.205697,0.210377,0.010717,2.056971,-126.014534,0.206590,0.000000
13.010000,0.041336,-125.925575,0.008226,0.008262,0.209843,0.183872,0.009367,2.098427,-125.925575,0.210927,0.000000
13.270000,0.118042,-125.925575,0.008412,0.008430,0.214118,0.525077,0.026749,2.141181,-125.925575,0.215263,0.000000
13.530001,0.191406,-126.059013,0.008580,0.008608,0.218645,0.851418,0.043373,2.186449,-126.059013,0.219599,0.000000
13.790001,0.415947,-126.014534,0.008735,0.008768,0.222712,1.850224,0.094255,2.227121,-126.014534,0.223918,0.000000
14.050000,0.672882,-126.059013,0.008895,0.008912,0.226363,2.993129,0.152477,2.263634,-126.059013,0.227629,0.000000
14.310000,0.568985,-126.059013,0.008899,-0.000000,-0.000009,2.530972,0.128934,-0.000087,-126.059013,0.000199,0.000000
14.570001,0.541061,-125.970055,0.008899,-0.000000,-0.000009,2.406761,0.122606,-0.000087,-125.970055,0.000199,0.000000
14.830001,0.520576,-126.103493,0.008895,-0.000000,-0.000009,2.315640,0.117964,-0.000087,-126.103493,0.000616,0.000000
15.090001,0.504944,-126.014534,0.008895,-0.000000,-0.000009,2.246102,0.114422,-0.000087,-126.014534,0.001049,0.000000
15.350000,0.591705,-126.059013,0.008908,0.000020,0.000503,2.632037,0.134082,0.005030,-126.059013,0.001483,0.000000
15.610001,0.601761,-126.103493,0.008925,0.000033,0.000841,2.676766,0.136361,0.008410,-126.103493,0.001917,0.000000
15.870001,0.691872,-126.059013,0.008942,0.000059,0.001509,3.077599,0.156780,0.015090,-126.059013,0.002350,0.000000
16.130001,0.688896,-126.103493,0.008964,0.000074,0.001873,3.064363,0.156106,0.018731,-126.103493,0.002784,0.000000
16.390001,0.712723,-126.014534,0.008985,0.000093,0.002359,3.170349,0.161505,0.023587,-126.014534,0.003217,0.000000
16.650002,0.738792,-126.147980,0.008998,0.000105,0.002671,3.286313,0.167413,0.026710,-126.147980,0.003651,0.000000
16.910002,0.815498,-126.103493,0.009011,0.000123,0.003113,3.627518,0.184795,0.031135,-126.103493,0.004085,0.000000
17.170000,0.835983,-126.103493,0.009024,0.000138,0.003504,3.718639,0.189437,0.035037,-126.103493,0.004518,0.000000
17.430000,0.898163,-126.147980,0.009046,0.000158,0.004015,3.995228,0.203527,0.040150,-126.147980,0.004952,0.000000
17.690001,0.960350,-126.103493,0.009076,0.000182,0.004613,4.271850,0.217618,0.046134,-126.103493,0.005386,0.000000
17.950001,1.007271,-126.103493,0.009080,0.000196,0.004987,4.480564,0.228251,0.049866,-126.103493,0.005819,0.000000
18.210001,1.014717,-126.059013,0.009093,0.000214,0.005429,4.513687,0.229938,0.054287,-126.059013,0.006253,0.000000
18.470001,1.029984,-126.147980,0.009110,0.000226,0.005741,4.581595,0.233398,0.057409,-126.147980,0.006686,0.000000
18.730001,1.202019,-126.192459,0.009123,0.000244,0.006200,5.346847,0.272381,0.062004,-126.192459,0.007120,0.000000
18.990002,1.263092,-126.147980,0.009149,0.000262,0.006660,5.618514,0.286221,0.066603,-126.147980,0.007554,0.000000
19.250000,1.318573,-126.147980,0.009158,0.000274,0.006964,5.865305,0.298793,0.069638,-126.147980,0.007979,0.000000
19.510000,1.369591,-126.147980,0.009184,0.000292,0.007423,6.092244,0.310354,0.074233,-126.147980,0.008412,0.000000
19.770000,1.481674,-126.192459,0.009201,0.000311,0.007909,6.590816,0.335752,0.079089,-126.192459,0.008846,0.000000
20.030001,1.539764,-126.236938,0.009205,0.000330,0.008377,6.849214,0.348916,0.083775,-126.236938,0.009279,0.000000
20.290001,1.652222,-126.147980,0.009231,0.000348,0.008828,7.349449,0.374399,0.088283,-126.147980,0.009713,0.000000
20.550001,1.734512,-126.236938,0.009240,0.000368,0.009357,7.715496,0.393046,0.093574,-126.236938,0.010147,0.000000
20.810001,1.829094,-126.192459,0.009261,0.000383,0.009722,8.136216,0.414479,0.097215,-126.192459,0.010580,0.000000
21.070002,1.832451,-126.192459,0.009278,0.000395,0.010042,8.151149,0.415239,0.100425,-126.192459,0.011014,0.000000
21.330002,2.031296,-126.281418,0.009296,0.000418,0.010606,9.035655,0.460298,0.106060,-126.281418,0.011447,0.000000
21.590000,2.108376,-126.192459,0.009300,0.000435,0.011057,9.378523,0.477765,0.110572,-126.192459,0.011881,0.000000
21.850000,2.180992,-126.281418,0.009334,0.000450,0.011430,9.701537,0.494220,0.114300,-126.281418,0.012315,0.000000
22.110001,2.238708,-126.236938,0.009343,0.000467,0.011872,9.958273,0.507299,0.118721,-126.236938,0.012748,0.000000
22.370001,2.329567,-126.236938,0.009365,0.000484,0.012297,10.362432,0.527887,0.122971,-126.236938,0.013182,0.000000
22.630001,2.435318,-126.281418,0.009382,0.000503,0.012783,10.832835,0.551851,0.127827,-126.281418,0.013615,0.000000
22.890001,2.508301,-126.281418,0.009390,0.000520,0.013208,11.157479,0.568389,0.132078,-126.281418,0.014049,0.000000
23.150002,2.561180,-126.281418,0.009412,0.000531,0.013485,11.392698,0.580372,0.134852,-126.281418,0.014483,0.000000
23.410002,2.733215,-126.281418,0.009438,0.000554,0.014075,12.157949,0.619355,0.140749,-126.281418,0.014916,0.000000
23.670002,2.853119,-126.281418,0.009451,0.000576,0.014630,12.691307,0.646526,0.146301,-126.281418,0.015350,0.000000
23.930000,2.798012,-126.325897,0.009464,0.000589,0.014968,12.446178,0.634039,0.149681,-126.325897,0.015783,0.000000
24.190001,2.887383,-126.325897,0.009477,0.000605,0.015376,12.843719,0.654290,0.153758,-126.325897,0.016217,0.000000
24.450001,2.964836,-126.325897,0.009494,0.000622,0.015792,13.188250,0.671841,0.157921,-126.325897,0.016651,0.000000
24.710001,3.101868,-126.281418,0.009507,0.000641,0.016278,13.797796,0.702893,0.162777,-126.281418,0.017084,0.000000
24.970001,3.109314,-126.325897,0.009533,0.000654,0.016607,13.830919,0.704581,0.166074,-126.325897,0.017518,0.000000
25.230001,3.282097,-126.370384,0.009546,0.000676,0.017180,14.599496,0.743734,0.171796,-126.370384,0.017951,0.000000
25.490002,3.331993,-126.281418,0.009554,0.000693,0.017605,14.821445,0.755040,0.176047,-126.281418,0.018385,0.000000
25.750002,3.323799,-126.414864,0.009572,0.000710,0.018038,14.784997,0.753184,0.180381,-126.414864,0.018819,0.000000
26.010002,3.389336,-126.370384,0.009602,0.000727,0.018454,15.076518,0.768034,0.184544,-126.370384,0.019252,0.000000
26.270000,3.461205,-126.414864,0.009606,0.000742,0.018853,15.396207,0.784320,0.188533,-126.414864,0.019686,0.000000
26.530001,3.540146,-126.370384,0.009623,0.000759,0.019278,15.747355,0.802208,0.192784,-126.370384,0.020120,0.000000
26.790001,3.614250,-126.370384,0.009641,0.000776,0.019721,16.076988,0.819001,0.197208,-126.370384,0.020553,0.000000
27.050001,3.622818,-126.459343,0.009653,0.000789,0.020050,16.115099,0.820942,0.200501,-126.459343,0.020987,0.000000
27.310001,3.794479,-126.414864,0.009675,0.000812,0.020614,16.878687,0.859841,0.206141,-126.414864,0.021420,0.000000
27.570002,3.809746,-126.414864,0.009701,0.000827,0.021013,16.946596,0.863301,0.210130,-126.414864,0.021854,0.000000
27.830002,3.872681,-126.414864,0.009705,0.000845,0.021455,17.226543,0.877562,0.214551,-126.414864,0.022288,0.000000
28.090002,3.882729,-126.414864,0.009731,0.000859,0.021828,17.271240,0.879839,0.218279,-126.414864,0.022721,0.000000
28.350002,4.038010,-126.503822,0.009748,0.000882,0.022392,17.961964,0.915026,0.223918,-126.503822,0.023146,0.000000
28.610001,4.020508,-126.370384,0.009761,0.000894,0.022704,17.884111,0.911060,0.227041,-126.370384,0.023580,0.000000
28.870001,4.084557,-126.503822,0.009783,0.000909,0.023094,18.169016,0.925574,0.230943,-126.503822,0.024013,0.000000
29.130001,4.191803,-126.503822,0.009783,0.000928,0.023571,18.646070,0.949876,0.235712,-126.503822,0.024447,0.000000
29.390001,4.239464,-126.459343,0.009817,0.000946,0.024022,18.858076,0.960676,0.240220,-126.459343,0.024881,0.000000
29.650002,4.262550,-126.503822,0.009809,0.000965,0.024499,18.960772,0.965908,0.244989,-126.503822,0.025314,0.000000
29.910002,4.282288,-126.459343,0.009848,0.000979,0.024872,19.048567,0.970380,0.248721,-126.459343,0.025748,0.000000
30.170002,4.349312,-126.548309,0.009856,0.000997,0.025323,19.346704,0.985568,0.253228,-126.548309,0.026182,0.000000
30.430002,4.414848,-126.503822,0.009869,0.001014,0.025757,19.638226,1.000419,0.257566,-126.503822,0.026615,0.000000
30.690001,4.437195,-126.548309,0.009886,0.001029,0.026147,19.737629,1.005483,0.261468,-126.548309,0.027049,0.000000
30.950001,4.464005,-126.548309,0.009891,0.001042,0.026459,19.856884,1.011558,0.264591,-126.548309,0.027482,0.000000
31.210001,4.703438,-126.503822,0.009934,0.001069,0.027153,20.921936,1.065814,0.271528,-126.503822,0.027916,0.000000
31.470001,4.653542,-126.592789,0.009934,0.001085,0.027569,20.699987,1.054508,0.275692,-126.592789,0.028350,0.000000
31.730001,4.629707,-126.548309,0.009951,0.001099,0.027925,20.593967,1.049107,0.279246,-126.548309,0.028783,0.000000
31.990002,4.619659,-126.548309,0.009964,0.001115,0.028315,20.549271,1.046830,0.283148,-126.548309,0.029217,0.000000
32.250000,4.691154,-126.592789,0.009977,0.001131,0.028740,20.867298,1.063031,0.287398,-126.592789,0.029650,0.000000
32.510002,4.748123,-126.548309,0.010003,0.001147,0.029130,21.120707,1.075940,0.291301,-126.548309,0.030084,0.000000
32.770000,4.749245,-126.592789,0.009994,0.001162,0.029503,21.125696,1.076194,0.295029,-126.592789,0.030518,0.000000
33.030003,4.687798,-126.592789,0.010020,0.001171,0.029746,20.852365,1.062270,0.297459,-126.592789,0.030951,0.000000
33.290001,5.033737,-126.548309,0.010059,0.001204,0.030578,22.391182,1.140661,0.305782,-126.548309,0.031385,0.000000
33.550003,4.936920,-126.637268,0.010067,0.001221,0.031021,21.960518,1.118722,0.310206,-126.637268,0.031818,0.000000
33.810001,4.872871,-126.592789,0.010085,0.001234,0.031342,21.675615,1.104208,0.313416,-126.592789,0.032252,0.000000
34.070004,4.805840,-126.592789,0.010085,0.001244,0.031602,21.377441,1.089019,0.316016,-126.592789,0.032686,0.000000
34.330002,5.081772,-126.681747,0.010119,0.001271,0.032278,22.604851,1.151546,0.322780,-126.681747,0.033119,0.000000
34.590000,4.962982,-126.681747,0.010132,0.001282,0.032555,22.076447,1.124628,0.325554,-126.681747,0.033553,0.000000
34.850002,4.942505,-126.681747,0.010132,0.001293,0.032851,21.985359,1.119988,0.328506,-126.681747,0.033986,0.000000
35.110001,5.187149,-126.681747,0.010154,0.001322,0.033588,23.073591,1.175425,0.335875,-126.681747,0.034420,0.000000
35.370003,5.094803,-126.726227,0.010175,0.001338,0.033986,22.662815,1.154499,0.339865,-126.726227,0.034854,0.000000
35.630001,5.025543,-126.681747,0.010192,0.001354,0.034394,22.354733,1.138804,0.343941,-126.681747,0.035287,0.000000
35.890003,4.930962,-126.726227,0.010201,0.001364,0.034654,21.934013,1.117372,0.346541,-126.726227,0.035721,0.000000
36.150002,5.198692,-126.681747,0.010214,0.001388,0.035261,23.124939,1.178041,0.352612,-126.681747,0.036154,0.000000
36.410000,5.229599,-126.726227,0.010240,0.001404,0.035669,23.262419,1.185044,0.356688,-126.726227,0.036588,0.000000
36.670002,5.207634,-126.726227,0.010236,0.001420,0.036076,23.164713,1.180067,0.360765,-126.726227,0.037022,0.000000
36.930000,5.148056,-126.681747,0.010253,0.001435,0.036449,22.899696,1.166566,0.364493,-126.681747,0.037455,0.000000
37.190002,5.355461,-126.681747,0.010287,0.001462,0.037126,23.822281,1.213565,0.371260,-126.681747,0.037880,0.000000
37.450001,5.140976,-126.770714,0.010305,0.001471,0.037360,22.868202,1.164962,0.373599,-126.770714,0.038314,0.000000
37.710003,5.226624,-126.770714,0.010313,0.001491,0.037872,23.249182,1.184370,0.378717,-126.770714,0.038747,0.000000
37.970001,5.092941,-126.770714,0.010317,0.001502,0.038158,22.654533,1.154077,0.381578,-126.770714,0.039181,0.000000
38.230003,5.282104,-126.815193,0.010339,0.001524,0.038704,23.495974,1.196942,0.387043,-126.815193,0.039615,0.000000
38.490002,5.226624,-126.815193,0.010356,0.001536,0.039025,23.249182,1.184370,0.390249,-126.815193,0.040048,0.000000
38.750000,5.345039,-126.815193,0.010378,0.001557,0.039537,23.775923,1.211203,0.395366,-126.815193,0.040482,0.000000
39.010002,5.528618,-126.770714,0.010391,0.001582,0.040187,24.592520,1.252803,0.401873,-126.770714,0.040915,0.000000
39.270000,5.357697,-126.770714,0.010404,0.001597,0.040551,23.832224,1.214071,0.405514,-126.770714,0.041349,0.000000
39.530003,5.335732,-126.770714,0.010425,0.001612,0.040950,23.734520,1.209094,0.409503,-126.770714,0.041783,0.000000
39.790001,5.300354,-126.815193,0.010421,0.001626,0.041297,23.577152,1.201077,0.412974,-126.815193,0.042216,0.000000
40.050003,5.450050,-126.815193,0.010455,0.001645,0.041783,24.243034,1.234999,0.417830,-126.815193,0.042650,0.000000
40.310001,5.478722,-126.859673,0.010468,0.001662,0.042208,24.370571,1.241496,0.422076,-126.859673,0.043084,0.000000
40.570004,5.479095,-126.815193,0.010477,0.001676,0.042563,24.372234,1.241581,0.425634,-126.815193,0.043517,0.000000
40.830002,5.513351,-126.815193,0.010486,0.001694,0.043023,24.524612,1.249343,0.430229,-126.815193,0.043951,0.000000
41.090000,5.561012,-126.904152,0.010507,0.001711,0.043465,24.736618,1.260143,0.434654,-126.904152,0.044385,0.000000
41.350002,5.593407,-126.859673,0.010520,0.001729,0.043916,24.880716,1.267484,0.439161,-126.859673,0.044818,0.000000
41.610001,5.600861,-126.859673,0.010555,0.001746,0.044359,24.913872,1.269173,0.443586,-126.859673,0.045252,0.000000
41.870003,5.747574,-126.859673,0.010550,0.001767,0.044879,25.566484,1.302419,0.448790,-126.859673,0.045685,0.000000
42.130001,5.692085,-126.859673,0.010572,0.001781,0.045243,25.319660,1.289845,0.452431,-126.859673,0.046119,0.000000
42.390003,5.648895,-126.948631,0.010589,0.001794,0.045573,25.127541,1.280058,0.455728,-126.948631,0.046553,0.000000
42.650002,5.833961,-126.859673,0.010611,0.001816,0.046119,25.950756,1.321995,0.461189,-126.859673,0.046986,0.000000
42.910004,5.804916,-126.948631,0.010632,0.001832,0.046535,25.821558,1.315413,0.465353,-126.948631,0.047420,0.000000
43.170002,5.811623,-126.904152,0.010637,0.001848,0.046952,25.851389,1.316932,0.469516,-126.904152,0.047854,0.000000
43.430000,5.832100,-126.904152,0.010654,0.001866,0.047402,25.942476,1.321573,0.474024,-126.904152,0.048287,0.000000
43.690002,5.881996,-126.948631,0.010654,0.001882,0.047810,26.164425,1.332879,0.478100,-126.948631,0.048721,0.000000
43.950001,6.005623,-126.904152,0.010688,0.001903,0.048330,26.714344,1.360894,0.483305,-126.904152,0.049154,0.000000
44.210003,5.973602,-126.993118,0.010697,0.001918,0.048729,26.571911,1.353638,0.487294,-126.993118,0.049588,0.000000
44.470001,5.913651,-126.948631,0.010705,0.001929,0.048998,26.305231,1.340052,0.489981,-126.948631,0.050022,0.000000
44.730003,6.122177,-126.948631,0.010727,0.001952,0.049579,27.232803,1.387305,0.495791,-126.948631,0.050455,0.000000
44.990002,6.284531,-126.993118,0.010740,0.001974,0.050143,27.954988,1.424095,0.501430,-126.993118,0.050889,0.000000
45.250004,6.146759,-126.993118,0.010757,0.001988,0.050490,27.342150,1.392876,0.504897,-126.993118,0.051322,0.000000
45.510002,6.199257,-127.037598,0.010766,0.002004,0.050897,27.575672,1.404772,0.508974,-127.037598,0.051756,0.000000
45.770000,6.237244,-126.993118,0.010792,0.002020,0.051314,27.744646,1.413380,0.513137,-126.993118,0.052190,0.000000
46.030003,6.347839,-126.993118,0.010809,0.002039,0.051799,28.236599,1.438441,0.517993,-126.993118,0.052623,0.000000
46.290001,6.321770,-126.993118,0.010813,0.002052,0.052120,28.120636,1.432534,0.521203,-126.993118,0.053048,0.000000
46.550003,6.553383,-127.037598,0.010831,0.002075,0.052693,29.150904,1.485018,0.526926,-127.037598,0.053482,0.000000
46.810001,6.616318,-127.082077,0.010856,0.002092,0.053135,29.430851,1.499279,0.531350,-127.082077,0.053915,0.000000
47.070004,6.583176,-127.037598,0.010861,0.002110,0.053586,29.283428,1.491769,0.535858,-127.037598,0.054349,0.000000
47.330002,6.617805,-127.082077,0.010878,0.002126,0.053993,29.437469,1.499616,0.539934,-127.082077,0.054783,0.000000
47.590004,6.500511,-127.037598,0.010908,0.002138,0.054297,28.915718,1.473037,0.542970,-127.037598,0.055216,0.000000
47.850002,6.745155,-127.082077,0.010921,0.002157,0.054800,30.003950,1.528474,0.548000,-127.082077,0.055650,0.000000
48.110001,6.824104,-127.171036,0.010938,0.002175,0.055251,30.355131,1.546364,0.552508,-127.171036,0.056083,0.000000
48.370003,6.802879,-127.126556,0.010934,0.002188,0.055580,30.260719,1.541554,0.555804,-127.126556,0.056517,0.000000
48.630001,7.059814,-127.082077,0.010964,0.002210,0.056144,31.403624,1.599777,0.561440,-127.082077,0.056951,0.000000
48.890003,7.003960,-127.126556,0.010977,0.002224,0.056500,31.155169,1.587120,0.564998,-127.126556,0.057384,0.000000
49.150002,7.110825,-127.082077,0.010986,0.002243,0.056977,31.630527,1.611336,0.569767,-127.082077,0.057818,0.000000
49.410004,7.162590,-127.082077,0.010999,0.002261,0.057427,31.860792,1.623066,0.574275,-127.082077,0.058251,0.000000
49.670002,7.330902,-127.082077,0.011016,0.002280,0.057913,32.609482,1.661206,0.579134,-127.082077,0.058685,0.000000
49.930004,7.258659,-127.082077,0.011037,0.002293,0.058243,32.288128,1.644836,0.582427,-127.082077,0.059119,0.000000
50.190002,7.346169,-127.126556,0.011050,0.002308,0.058624,32.677391,1.664665,0.586242,-127.126556,0.059552,0.000000
50.450001,7.523041,-127.082077,0.011063,0.002327,0.059110,33.464157,1.704745,0.591102,-127.082077,0.059986,0.000000
50.710003,7.617996,-127.126556,0.011081,0.002347,0.059622,33.886539,1.726263,0.596216,-127.126556,0.060419,0.000000
50.970001,7.649277,-127.171036,0.011089,0.002363,0.060029,34.025681,1.733351,0.600292,-127.171036,0.060853,0.000000
51.230003,7.632896,-127.171036,0.011119,0.002378,0.060402,33.952820,1.729639,0.604024,-127.171036,0.061287,0.000000
51.490002,7.728966,-127.215523,0.011115,0.002395,0.060844,34.380157,1.751409,0.608445,-127.215523,0.061720,0.000000
51.750004,7.903236,-127.171036,0.011145,0.002413,0.061296,35.155350,1.790899,0.612956,-127.171036,0.062154,0.000000
52.010002,7.896164,-127.215523,0.011154,0.002428,0.061668,35.123890,1.789296,0.616684,-127.215523,0.062588,0.000000
52.270004,7.951645,-127.126556,0.011175,0.002441,0.061998,35.370682,1.801869,0.619977,-127.126556,0.063021,0.000000
52.530003,8.402962,-127.215523,0.011201,0.002467,0.062666,37.378239,1.904138,0.626657,-127.215523,0.063455,0.000000
52.790001,8.353065,-127.215523,0.011206,0.002484,0.063099,37.156292,1.892832,0.630991,-127.215523,0.063888,0.000000
53.050003,8.312477,-127.215523,0.011219,0.002498,0.063455,36.975746,1.883634,0.634549,-127.215523,0.064322,0.000000
53.310001,8.342262,-127.171036,0.011240,0.002513,0.063819,37.108234,1.890384,0.638190,-127.171036,0.064756,0.000000
53.570004,8.576485,-127.126556,0.011249,0.002530,0.064270,38.150108,1.943459,0.642702,-127.126556,0.065189,0.000000
53.830002,8.642395,-127.260002,0.011270,0.002547,0.064686,38.443295,1.958395,0.646861,-127.260002,0.065623,0.000000
54.090004,8.706444,-127.260002,0.011279,0.002561,0.065059,38.728195,1.972908,0.650593,-127.260002,0.066057,0.000000
54.350002,8.542229,-127.215523,0.011296,0.002571,0.065311,37.997730,1.935697,0.653106,-127.215523,0.066490,0.000000
54.610004,9.330910,-127.304482,0.011318,0.002603,0.066117,41.505959,2.114414,0.661172,-127.304482,0.066924,0.000000
54.870003,9.299263,-127.260002,0.011331,0.002620,0.066560,41.365189,2.107243,0.665596,-127.260002,0.067358,0.000000
55.130001,9.178238,-127.348961,0.011326,0.002633,0.066889,40.826839,2.079818,0.668889,-127.348961,0.067791,0.000000
55.390003,9.021469,-127.304482,0.011339,0.002643,0.067123,40.129498,2.044294,0.671232,-127.304482,0.068216,0.000000
55.650002,9.574074,-127.260002,0.011369,0.002668,0.067765,42.587608,2.169516,0.677648,-127.260002,0.068650,0.000000
55.910004,9.543541,-127.304482,0.011369,0.002681,0.068086,42.451790,2.162597,0.680857,-127.304482,0.069083,0.000000
56.170002,9.536461,-127.304482,0.011400,0.002693,0.068398,42.420296,2.160993,0.683980,-127.304482,0.069517,0.000000
56.430004,10.296104,-127.348961,0.011417,0.002723,0.069153,45.799358,2.333131,0.691527,-127.348961,0.069951,0.000000
56.690002,10.192581,-127.348961,0.011426,0.002738,0.069534,45.338867,2.309672,0.695342,-127.348961,0.070384,0.000000
56.950005,10.204498,-127.348961,0.011447,0.002753,0.069933,45.391876,2.312372,0.699331,-127.348961,0.070818,0.000000
57.210003,10.051453,-127.437927,0.011443,0.002763,0.070184,44.711094,2.277692,0.701844,-127.437927,0.071251,0.000000
57.470001,10.696030,-127.304482,0.011477,0.002787,0.070783,47.578316,2.423755,0.707828,-127.304482,0.071685,0.000000
57.730003,10.856148,-127.393440,0.011495,0.002804,0.071217,48.290558,2.460038,0.712166,-127.393440,0.072119,0.000000
57.990002,10.897858,-127.393440,0.011516,0.002818,0.071589,48.476093,2.469490,0.715894,-127.393440,0.072552,0.000000
58.250004,11.075478,-127.348961,0.011516,0.002836,0.072032,49.266186,2.509739,0.720318,-127.348961,0.072986,0.000000
58.510002,11.615044,-127.437927,0.011533,0.002859,0.072613,51.666294,2.632006,0.726128,-127.437927,0.073419,0.000000
58.770004,11.352898,-127.348961,0.011546,0.002869,0.072873,50.500210,2.572603,0.728729,-127.348961,0.073853,0.000000
59.030003,11.700317,-127.393440,0.011572,0.002889,0.073393,52.045612,2.651330,0.733933,-127.393440,0.074287,0.000000
59.290001,11.633667,-127.348961,0.011581,0.002901,0.073679,51.749134,2.636226,0.736794,-127.348961,0.074720,0.000000
59.550003,12.014603,-127.393440,0.011598,0.002918,0.074122,53.443623,2.722548,0.741219,-127.393440,0.075154,0.000000
59.810001,12.236534,-127.437927,0.011602,0.002935,0.074538,54.430820,2.772838,0.745378,-127.437927,0.075587,0.000000
60.070004,12.464058,-127.437927,0.011632,0.002952,0.074972,55.442898,2.824396,0.749716,-127.437927,0.076021,0.000000
60.330002,13.390892,-127.482407,0.011628,0.002980,0.075700,59.565662,3.034420,0.757002,-127.482407,0.076454,0.000000
60.590004,13.297050,-127.437927,0.011663,0.002995,0.076064,59.148235,3.013155,0.760643,-127.437927,0.076888,0.000000
60.850002,13.389397,-127.393440,0.011663,0.003011,0.076472,59.559010,3.034081,0.764719,-127.393440,0.077322,0.000000
61.110004,13.410622,-127.437927,0.011689,0.003024,0.076819,59.653423,3.038890,0.768186,-127.437927,0.077755,0.000000
61.370003,13.841087,-127.482407,0.011706,0.003041,0.077252,61.568230,3.136435,0.772524,-127.482407,0.078189,0.000000
61.630001,14.271179,-127.482407,0.011710,0.003059,0.077704,63.481377,3.233896,0.777035,-127.482407,0.078622,0.000000
61.890003,14.403374,-127.482407,0.011723,0.003074,0.078068,64.069405,3.263851,0.780676,-127.482407,0.079056,0.000000
62.150002,14.652115,-127.482407,0.011745,0.003089,0.078467,65.175865,3.320217,0.784666,-127.482407,0.079490,0.000000
62.410004,15.256851,-127.482407,0.011762,0.003110,0.078987,67.865860,3.457252,0.789870,-127.482407,0.079923,0.000000
62.670002,15.524208,-127.482407,0.011775,0.003127,0.079429,69.055130,3.517836,0.794290,-127.482407,0.080357,0.000000
62.930004,15.958771,-127.571365,0.011775,0.003145,0.079871,70.988159,3.616309,0.798715,-127.571365,0.080791,0.000000
63.190002,16.420883,-127.482407,0.011796,0.003165,0.080400,73.043739,3.721025,0.804003,-127.482407,0.081224,0.000000
63.450005,16.689362,-127.571365,0.011801,0.003180,0.080765,74.237991,3.781863,0.807647,-127.571365,0.081658,0.000000
63.710003,16.618614,-127.482407,0.011818,0.003192,0.081086,73.923286,3.765832,0.810857,-127.482407,0.082091,0.000000
63.970001,17.481400,-127.571365,0.011839,0.003215,0.081649,77.761147,3.961342,0.816493,-127.571365,0.082525,0.000000
64.230003,17.824730,-127.571365,0.011839,0.003230,0.082048,79.288361,4.039142,0.820482,-127.571365,0.082950,0.000000
64.490005,18.158005,-127.526886,0.011865,0.003247,0.082482,80.770836,4.114663,0.824819,-127.526886,0.083384,0.000000
64.750000,18.544151,-127.571365,0.011874,0.003266,0.082959,82.488503,4.202165,0.829588,-127.571365,0.083817,0.000000
65.010002,18.927696,-127.571365,0.011887,0.003281,0.083332,84.194595,4.289077,0.833317,-127.571365,0.084251,0.000000
65.270004,19.397255,-127.615852,0.011904,0.003298,0.083757,86.283302,4.395481,0.837567,-127.615852,0.084684,0.000000
65.530006,19.852295,-127.571365,0.011904,0.003315,0.084190,88.307419,4.498594,0.841901,-127.571365,0.085118,0.000000
65.790001,20.058960,-127.571365,0.011930,0.003328,0.084528,89.226707,4.545425,0.845284,-127.571365,0.085552,0.000000
66.050003,20.775406,-127.660332,0.011934,0.003348,0.085049,92.413620,4.707774,0.850489,-127.660332,0.085985,0.000000
66.310005,21.915985,-127.526886,0.011939,0.003372,0.085656,97.487167,4.966233,0.856560,-127.526886,0.086419,0.000000
66.570000,22.051529,-127.571365,0.011977,0.003385,0.085985,98.090103,4.996948,0.859852,-127.571365,0.086853,0.000000
66.830002,22.541573,-127.615852,0.011977,0.003402,0.086419,100.269920,5.107993,0.864190,-127.615852,0.087286,0.000000
67.090004,23.068848,-127.660332,0.012003,0.003420,0.086861,102.615356,5.227476,0.868611,-127.660332,0.087720,0.000000
67.350006,23.682518,-127.660332,0.012003,0.003436,0.087277,105.345100,5.366535,0.872774,-127.660332,0.088154,0.000000
67.610001,24.019142,-127.615852,0.012008,0.003449,0.087616,106.842484,5.442816,0.876158,-127.615852,0.088587,0.000000
67.870003,25.098282,-127.704811,0.012025,0.003472,0.088188,111.642731,5.687352,0.881881,-127.704811,0.089021,0.000000
68.130005,25.873558,-127.704811,0.012029,0.003490,0.088656,115.091331,5.863032,0.886562,-127.704811,0.089454,0.000000
68.390007,26.321152,-127.660332,0.012051,0.003506,0.089064,117.082329,5.964458,0.890639,-127.660332,0.089888,0.000000
68.650002,26.964241,-127.749290,0.012051,0.003524,0.089506,119.942932,6.110185,0.895063,-127.749290,0.090322,0.000000
68.910004,27.254692,-127.704811,0.012068,0.003538,0.089862,121.234924,6.176002,0.898617,-127.704811,0.090755,0.000000
69.170006,28.307755,-127.749290,0.012077,0.003556,0.090322,125.919182,6.414629,0.903216,-127.749290,0.091189,0.000000
69.430000,29.003349,-127.704811,0.012081,0.003574,0.090772,129.013336,6.572253,0.907724,-127.704811,0.091622,0.000000
69.690002,29.338112,-127.704811,0.012111,0.003586,0.091093,130.502441,6.648111,0.910933,-127.704811,0.092056,0.000000
69.950005,30.454109,-127.793770,0.012115,0.003608,0.091648,135.466644,6.901000,0.916482,-127.793770,0.092490,0.000000
70.210007,31.252480,-127.660332,0.012128,0.003623,0.092013,139.017975,7.081913,0.920127,-127.660332,0.092923,0.000000
70.470001,32.102982,-127.749290,0.012133,0.003642,0.092498,142.801193,7.274640,0.924983,-127.749290,0.093357,0.000000
70.730003,32.841766,-127.793770,0.012133,0.003659,0.092949,146.087479,7.442051,0.929491,-127.793770,0.093790,0.000000
70.990005,33.937660,-127.704811,0.012150,0.003679,0.093435,150.962250,7.690384,0.934347,-127.704811,0.094224,0.000000
71.250000,34.363655,-127.793770,0.012154,0.003692,0.093764,152.857178,7.786916,0.937643,-127.793770,0.094658,0.000000
71.510002,35.096855,-127.749290,0.012158,0.003707,0.094146,156.118607,7.953061,0.941459,-127.749290,0.095091,0.000000
71.770004,36.085503,-127.838257,0.012176,0.003725,0.094614,160.516327,8.177092,0.946144,-127.838257,0.095525,0.000000
72.030006,37.165382,-127.793770,0.012171,0.003745,0.095126,165.319870,8.421796,0.951258,-127.793770,0.095958,0.000000
72.290001,38.041199,-127.793770,0.012197,0.003760,0.095516,169.215698,8.620258,0.955160,-127.793770,0.096392,0.000000
72.550003,38.770676,-127.838257,0.012189,0.003776,0.095907,172.460571,8.785561,0.959066,-127.838257,0.096826,0.000000
72.810005,39.456215,-127.793770,0.012202,0.003792,0.096323,175.510010,8.940907,0.963225,-127.793770,0.097259,0.000000
73.070000,40.783356,-127.882736,0.012223,0.003811,0.096800,181.413422,9.241640,0.967998,-127.882736,0.097693,0.000000
73.330002,41.098381,-127.793770,0.012219,0.003819,0.097008,182.814728,9.313025,0.970076,-127.793770,0.098118,0.000000
73.590004,42.336517,-127.838257,0.012227,0.003839,0.097511,188.322235,9.593593,0.975106,-127.838257,0.098551,0.000000
73.850006,44.220352,-127.882736,0.012232,0.003865,0.098170,196.701950,10.020474,0.981700,-127.882736,0.098985,0.000000
74.110001,44.895088,-127.793770,0.012245,0.003882,0.098595,199.703323,10.173372,0.985950,-127.793770,0.099419,0.000000
74.370003,45.904961,-127.882736,0.012258,0.003896,0.098959,204.195465,10.402213,0.989591,-127.882736,0.099852,0.000000
74.630005,46.478416,-127.838257,0.012258,0.003911,0.099332,206.746323,10.532160,0.993319,-127.838257,0.100286,0.000000
74.890007,47.621971,-127.838257,0.012262,0.003928,0.099774,211.833115,10.791293,0.997744,-127.838257,0.100719,0.000000
75.150002,48.617699,-127.971695,0.012275,0.003941,0.100112,216.262329,11.016928,1.001124,-127.971695,0.101153,0.000000
75.410004,49.609322,-127.927216,0.012271,0.003957,0.100503,220.673279,11.241632,1.005026,-127.927216,0.101587,0.000000
75.670006,50.160065,-127.971695,0.012284,0.003967,0.100772,223.123108,11.366433,1.007717,-127.971695,0.102020,0.000000
75.930000,52.818428,-127.927216,0.012284,0.004001,0.101621,234.948105,11.968826,1.016214,-127.927216,0.102454,0.000000
76.190002,53.683083,-127.927216,0.012305,0.004016,0.102012,238.794281,12.164761,1.020116,-127.927216,0.102887,0.000000
76.450005,54.326164,-127.927216,0.012301,0.004028,0.102315,241.654846,12.310484,1.023152,-127.927216,0.103321,0.000000
76.710007,55.210548,-127.882736,0.012309,0.004041,0.102645,245.588791,12.510889,1.026448,-127.882736,0.103755,0.000000
76.970001,57.048210,-128.016174,0.012309,0.004065,0.103252,253.763107,12.927309,1.032519,-128.016174,0.104188,0.000000
77.230003,57.762794,-127.882736,0.012322,0.004078,0.103581,256.941742,13.089236,1.035812,-127.882736,0.104622,0.000000
77.490005,58.587227,-127.971695,0.012331,0.004091,0.103920,260.609009,13.276055,1.039196,-127.971695,0.105056,0.000000
77.750000,60.573830,-128.016174,0.012331,0.004116,0.104544,269.445862,13.726226,1.045441,-128.016174,0.105489,0.000000
78.010002,61.948631,-128.016174,0.012340,0.004133,0.104986,275.561279,14.037761,1.049862,-128.016174,0.105923,0.000000
78.270004,62.957764,-128.016174,0.012344,0.004149,0.105385,280.050110,14.266433,1.053851,-128.016174,0.106356,0.000000
78.530006,63.801926,-128.016174,0.012348,0.004161,0.105697,283.805145,14.457724,1.056974,-128.016174,0.106790,0.000000
78.790001,64.954422,-127.971695,0.012344,0.004180,0.106174,288.931702,14.718883,1.061743,-127.971695,0.107224,0.000000
79.050003,66.519882,-128.016174,0.012357,0.004198,0.106617,295.895203,15.073621,1.066167,-128.016174,0.107657,0.000000
79.310005,67.642578,-127.927216,0.012365,0.004215,0.107067,300.889221,15.328027,1.070675,-127.927216,0.108082,0.000000
79.570007,67.297760,-128.105133,0.012365,0.004207,0.106868,299.355377,15.249890,1.068680,-128.105133,0.107085,0.000000
79.830002,66.826340,-128.016174,0.012370,0.004205,0.106807,297.258392,15.143065,1.068075,-128.016174,0.106868,0.000000
80.090004,66.403702,-128.060654,0.012370,0.004204,0.106781,295.378418,15.047295,1.067814,-128.060654,0.106868,0.000000
80.350006,66.036911,-128.060654,0.012365,0.004204,0.106773,293.746857,14.964178,1.067726,-128.060654,0.106868,0.000000
80.610001,65.729324,-128.016174,0.012378,0.004203,0.106764,292.378632,14.894478,1.067639,-128.016174,0.106868,0.000000
80.870003,65.441483,-128.105133,0.012378,0.004203,0.106764,291.098267,14.829251,1.067639,-128.105133,0.106868,0.000000
81.130005,65.173004,-128.016174,0.012374,0.004203,0.106755,289.903992,14.768414,1.067552,-128.016174,0.106868,0.000000
81.390007,64.959259,-128.105133,0.012378,0.004203,0.106755,288.953217,14.719978,1.067552,-128.105133,0.106868,0.000000
81.650002,64.732483,-128.016174,0.012383,0.004203,0.106747,287.944458,14.668591,1.067469,-128.016174,0.106868,0.000000
81.910004,64.547791,-128.060654,0.012396,0.004203,0.106747,287.122925,14.626739,1.067469,-128.060654,0.106868,0.000000
82.170006,64.360107,-128.105133,0.012378,0.004203,0.106747,286.288055,14.584209,1.067469,-128.105133,0.106868,0.000000
82.430000,64.201477,-128.149612,0.012396,0.004203,0.106747,285.582428,14.548263,1.067469,-128.149612,0.106868,0.000000
82.690002,64.052170,-128.194107,0.012404,0.004203,0.106747,284.918274,14.514429,1.067469,-128.194107,0.106868,0.000000
82.950005,63.911774,-128.105133,0.012383,0.004203,0.106747,284.293762,14.482615,1.067469,-128.105133,0.106868,0.000000
83.210007,63.769531,-128.149612,0.012404,0.004203,0.106747,283.661041,14.450382,1.067469,-128.149612,0.106868,0.000000
83.470001,63.650742,-128.194107,0.012396,0.004203,0.106747,283.132629,14.423464,1.067469,-128.194107,0.106868,0.000000
83.730003,63.535675,-128.149612,0.012391,0.004203,0.106747,282.620789,14.397390,1.067469,-128.149612,0.106868,0.000000
83.990005,63.407211,-128.194107,0.012387,0.004203,0.106747,282.049377,14.368279,1.067469,-128.194107,0.106868,0.000000
84.250008,63.301086,-128.194107,0.012387,0.004203,0.106747,281.577301,14.344232,1.067469,-128.194107,0.106868,0.000000
84.510002,63.196075,-128.149612,0.012400,0.004203,0.106747,281.110168,14.320436,1.067469,-128.149612,0.106868,0.000000
84.770004,63.113037,-128.238586,0.012396,0.004203,0.106747,280.740814,14.301619,1.067469,-128.238586,0.106868,0.000000
85.030006,63.022179,-128.149612,0.012391,0.004203,0.106747,280.336639,14.281030,1.067469,-128.149612,0.106868,0.000000
85.290001,62.945099,-128.283066,0.012391,0.004203,0.106747,279.993774,14.263563,1.067469,-128.283066,0.106868,0.000000
85.550003,62.842323,-128.194107,0.012413,0.004203,0.106747,279.536621,14.240274,1.067469,-128.194107,0.106868,0.000000
85.810005,62.782372,-128.283066,0.012396,0.004203,0.106747,279.269928,14.226688,1.067469,-128.283066,0.106868,0.000000
86.070007,62.685928,-128.194107,0.012391,0.004203,0.106747,278.840942,14.204834,1.067469,-128.194107,0.106868,0.000000
86.330002,62.633049,-128.238586,0.012409,0.004203,0.106747,278.605713,14.192851,1.067469,-128.238586,0.106868,0.000000
86.590004,62.547409,-128.238586,0.012404,0.004203,0.106747,278.224762,14.173446,1.067469,-128.238586,0.106868,0.000000
86.850006,62.478889,-128.238586,0.012396,0.004203,0.106747,277.919983,14.157919,1.067469,-128.238586,0.106868,0.000000
87.110001,62.409256,-128.327545,0.012404,0.004203,0.106747,277.610229,14.142139,1.067469,-128.327545,0.106868,0.000000
87.370003,62.359360,-128.283066,0.012387,0.004203,0.106747,277.388275,14.130833,1.067469,-128.283066,0.106868,0.000000
87.630005,62.293076,-128.283066,0.012404,0.004202,0.106738,277.093445,14.115813,1.067382,-128.283066,0.106868,0.000000
87.890007,62.233498,-128.372025,0.012387,0.004202,0.106738,276.828430,14.102312,1.067382,-128.372025,0.106868,0.000000
88.150002,62.179131,-128.283066,0.012391,0.004202,0.106738,276.586578,14.089992,1.067382,-128.283066,0.106868,0.000000
88.410004,62.118805,-128.327545,0.012400,0.004202,0.106738,276.318237,14.076323,1.067382,-128.327545,0.106868,0.000000
88.670006,62.060341,-128.283066,0.012409,0.004202,0.106738,276.058197,14.063075,1.067382,-128.283066,0.106868,0.000000
88.930008,62.016403,-128.327545,0.012409,0.004202,0.106738,275.862732,14.053119,1.067382,-128.327545,0.106868,0.000000
89.190002,61.950119,-128.372025,0.012404,0.004202,0.106738,275.567902,14.038098,1.067382,-128.372025,0.106868,0.000000
89.450005,61.921448,-128.327545,0.012409,0.004202,0.106738,275.440369,14.031601,1.067382,-128.327545,0.106868,0.000000
89.710007,61.871925,-128.372025,0.012400,0.004202,0.106738,275.220062,14.020379,1.067382,-128.372025,0.106868,0.000000
89.970001,61.815697,-128.327545,0.012404,0.004202,0.106738,274.969940,14.007637,1.067382,-128.327545,0.106868,0.000000
90.230003,61.781807,-128.372025,0.012404,0.004202,0.106738,274.819214,13.999958,1.067382,-128.372025,0.106868,0.000000
90.490005,61.742340,-128.327545,0.012400,0.004202,0.106738,274.643646,13.991014,1.067382,-128.327545,0.106868,0.000000
90.750008,61.691322,-128.327545,0.012413,0.004202,0.106738,274.416718,13.979453,1.067382,-128.327545,0.106868,0.000000
91.010002,61.662277,-128.372025,0.012409,0.004202,0.106738,274.287506,13.972872,1.067382,-128.372025,0.106868,0.000000
91.270004,61.604187,-128.372025,0.012409,0.004202,0.106738,274.029114,13.959708,1.067382,-128.372025,0.106868,0.000000
91.530006,61.547585,-128.416504,0.012409,0.004202,0.106738,273.777344,13.946882,1.067382,-128.416504,0.106868,0.000000
91.790001,61.529709,-128.460983,0.012409,0.004202,0.106738,273.697815,13.942831,1.067382,-128.460983,0.106868,0.000000
92.050003,61.502525,-128.372025,0.012417,0.004202,0.106738,273.576904,13.936671,1.067382,-128.372025,0.106868,0.000000
92.310005,61.451141,-128.460983,0.012404,0.004202,0.106738,273.348328,13.925027,1.067382,-128.460983,0.106868,0.000000
92.570007,61.407578,-128.372025,0.012404,0.004202,0.106738,273.154541,13.915156,1.067382,-128.372025,0.106868,0.000000
92.830002,61.382996,-128.460983,0.012400,0.004202,0.106738,273.045197,13.909586,1.067382,-128.460983,0.106868,0.000000
93.090004,61.348740,-128.460983,0.012409,0.004202,0.106738,272.892822,13.901823,1.067382,-128.460983,0.106868,0.000000
93.350006,61.320068,-128.416504,0.012413,0.004202,0.106738,272.765289,13.895327,1.067382,-128.416504,0.106868,0.000000
93.610008,61.274635,-128.505463,0.012413,0.004202,0.106738,272.563202,13.885031,1.067382,-128.505463,0.106868,0.000000
93.870003,61.245216,-128.416504,0.012400,0.004202,0.106738,272.432343,13.878365,1.067382,-128.416504,0.106868,0.000000
94.130005,61.214684,-128.505463,0.012417,0.004202,0.106738,272.296509,13.871446,1.067382,-128.505463,0.106868,0.000000
94.390007,61.188248,-128.460983,0.012409,0.004202,0.106738,272.178925,13.865455,1.067382,-128.460983,0.106868,0.000000
94.650002,61.144310,-128.549942,0.012417,0.004202,0.106738,271.983459,13.855498,1.067382,-128.549942,0.106868,0.000000
94.910004,61.129410,-128.549942,0.012400,0.004202,0.106738,271.917206,13.852122,1.067382,-128.549942,0.106868,0.000000
95.170006,61.089943,-128.549942,0.012409,0.004202,0.106738,271.741638,13.843179,1.067382,-128.549942,0.106868,0.000000
95.430008,61.064621,-128.505463,0.012413,0.004202,0.106738,271.628998,13.837440,1.067382,-128.505463,0.106868,0.000000
95.690002,61.034828,-128.549942,0.012413,0.004202,0.106738,271.496490,13.830690,1.067382,-128.549942,0.106868,0.000000
95.950005,61.016586,-128.549942,0.012417,0.004202,0.106738,271.415344,13.826556,1.067382,-128.549942,0.106868,0.000000
96.210007,60.976364,-128.594437,0.012409,0.004202,0.106738,271.236420,13.817442,1.067382,-128.594437,0.106868,0.000000
96.470001,60.959984,-128.549942,0.012404,0.004202,0.106738,271.163544,13.813729,1.067382,-128.549942,0.106868,0.000000
96.730003,60.933540,-128.549942,0.012426,0.004202,0.106738,271.045929,13.807738,1.067382,-128.549942,0.106868,0.000000
96.990005,60.899284,-128.549942,0.012400,0.004202,0.106738,270.893555,13.799975,1.067382,-128.549942,0.106868,0.000000
97.250008,60.878433,-128.638916,0.012404,0.004202,0.106738,270.800781,13.795251,1.067382,-128.638916,0.106868,0.000000
97.510002,60.850136,-128.638916,0.012417,0.004202,0.106738,270.674927,13.788837,1.067382,-128.638916,0.106868,0.000000
97.770004,60.829651,-128.549942,0.012404,0.004202,0.106738,270.583801,13.784196,1.067382,-128.549942,0.106868,0.000000
98.030006,60.806190,-128.638916,0.012417,0.004202,0.106738,270.479431,13.778879,1.067382,-128.638916,0.106868,0.000000
98.290001,60.778267,-128.594437,0.012409,0.004202,0.106738,270.355225,13.772552,1.067382,-128.594437,0.106868,0.000000
98.550003,60.763000,-128.638916,0.012409,0.004202,0.106738,270.287323,13.769093,1.067382,-128.638916,0.106868,0.000000
98.810005,60.725388,-128.683395,0.012404,0.004202,0.106738,270.120026,13.760570,1.067382,-128.683395,0.106868,0.000000
99.070007,60.704910,-128.594437,0.012409,0.004202,0.106738,270.028931,13.755929,1.067382,-128.594437,0.106868,0.000000
99.330002,60.694107,-128.594437,0.012413,0.004202,0.106738,269.980865,13.753482,1.067382,-128.594437,0.106868,0.000000
99.590004,60.652771,-128.638916,0.012409,0.004202,0.106738,269.796997,13.744115,1.067382,-128.638916,0.106868,0.000000
99.850006,60.650909,-128.683395,0.012417,0.004202,0.106738,269.788727,13.743692,1.067382,-128.683395,0.106868,0.000000
100.110008,60.623734,-128.727875,0.012413,0.004202,0.106738,269.667847,13.737535,1.067382,-128.727875,0.106868,0.000000
100.370003,60.592819,-128.638916,0.012413,0.004202,0.106738,269.530334,13.730529,1.067382,-128.638916,0.106868,0.000000
100.630005,60.569366,-128.683395,0.012409,0.004202,0.106738,269.425995,13.725215,1.067382,-128.683395,0.106868,0.000000
100.890007,60.548141,-128.638916,0.012417,0.004202,0.106738,269.331573,13.720406,1.067382,-128.638916,0.106868,0.000000
101.150002,60.535477,-128.683395,0.012417,0.004202,0.106738,269.275238,13.717535,1.067382,-128.683395,0.106868,0.000000
101.410004,60.519096,-128.727875,0.012404,0.004202,0.106738,269.202393,13.713823,1.067382,-128.727875,0.106868,0.000000
101.670006,60.484833,-128.683395,0.012417,0.004202,0.106738,269.049988,13.706059,1.067382,-128.683395,0.106868,0.000000
101.930008,60.483345,-128.772354,0.012413,0.004202,0.106738,269.043365,13.705722,1.067382,-128.772354,0.106868,0.000000
102.190002,60.446854,-128.727875,0.012417,0.004202,0.106738,268.881042,13.697453,1.067382,-128.727875,0.106868,0.000000
102.450005,60.439781,-128.727875,0.012421,0.004202,0.106738,268.849579,13.695850,1.067382,-128.727875,0.106868,0.000000
102.710007,60.413338,-128.772354,0.012413,0.004202,0.106738,268.731934,13.689858,1.067382,-128.772354,0.106868,0.000000
102.970001,60.396957,-128.683395,0.012409,0.004202,0.106738,268.659088,13.686146,1.067382,-128.683395,0.106868,0.000000
103.230003,60.382805,-128.772354,0.012421,0.004202,0.106738,268.596130,13.682939,1.067382,-128.772354,0.106868,0.000000
103.490005,60.363441,-128.772354,0.012413,0.004202,0.106738,268.510010,13.678551,1.067382,-128.772354,0.106868,0.000000
103.750008,60.341843,-128.816833,0.012413,0.004202,0.106738,268.413910,13.673657,1.067382,-128.816833,0.106868,0.000000
104.010002,60.325089,-128.772354,0.012413,0.004202,0.106738,268.339386,13.669860,1.067382,-128.772354,0.106868,0.000000
104.270004,60.311684,-128.772354,0.012421,0.004202,0.106738,268.279755,13.666822,1.067382,-128.772354,0.106868,0.000000
104.530006,60.284874,-128.816833,0.012413,0.004202,0.106738,268.160522,13.660748,1.067382,-128.816833,0.106868,0.000000
104.790009,60.272957,-128.772354,0.012426,0.004202,0.106738,268.107513,13.658048,1.067382,-128.772354,0.106868,0.000000
105.050003,60.251732,-128.816833,0.012430,0.004202,0.106738,268.013092,13.653237,1.067382,-128.816833,0.106868,0.000000
105.310005,60.241676,-128.816833,0.012413,0.004202,0.106738,267.968353,13.650959,1.067382,-128.816833,0.106868,0.000000
105.570007,60.222687,-128.816833,0.012421,0.004202,0.106738,267.883881,13.646656,1.067382,-128.816833,0.106868,0.000000
105.830002,60.202576,-128.861313,0.012409,0.004202,0.106738,267.794434,13.642098,1.067382,-128.861313,0.106868,0.000000
106.090004,60.195129,-128.816833,0.012417,0.004202,0.106738,267.761322,13.640410,1.067382,-128.816833,0.106868,0.000000
106.350006,60.175018,-128.816833,0.012417,0.004202,0.106738,267.671844,13.635855,1.067382,-128.816833,0.106868,0.000000
106.610008,60.159752,-128.816833,0.012421,0.004202,0.106738,267.603943,13.632395,1.067382,-128.816833,0.106868,0.000000
106.870003,60.125122,-128.861313,0.012421,0.004202,0.106738,267.449890,13.624547,1.067382,-128.861313,0.106868,0.000000
107.130005,60.126610,-128.905792,0.012421,0.004202,0.106738,267.456512,13.624885,1.067382,-128.905792,0.106868,0.000000
107.390007,60.100922,-128.905792,0.012413,0.004202,0.106738,267.342255,13.619064,1.067382,-128.905792,0.106868,0.000000
107.650002,60.091240,-128.905792,0.012421,0.004202,0.106738,267.299194,13.616870,1.067382,-128.905792,0.106868,0.000000
107.910004,60.064056,-128.905792,0.012421,0.004202,0.106738,267.178253,13.610710,1.067382,-128.905792,0.106868,0.000000
108.170006,60.058838,-128.905792,0.012426,0.004202,0.106738,267.155060,13.609528,1.067382,-128.905792,0.106868,0.000000
108.430008,60.035011,-128.905792,0.012404,0.004202,0.106738,267.049072,13.604128,1.067382,-128.905792,0.106868,0.000000
108.690002,60.045059,-128.905792,0.012421,0.004202,0.106738,267.093750,13.606405,1.067382,-128.905792,0.106868,0.000000
108.950005,60.013786,-128.950272,0.012434,0.004202,0.106738,266.954651,13.599319,1.067382,-128.950272,0.106868,0.000000
109.210007,59.990700,-128.905792,0.012426,0.004202,0.106738,266.851959,13.594087,1.067382,-128.905792,0.106868,0.000000
109.470009,59.983620,-128.950272,0.012417,0.004202,0.106738,266.820465,13.592483,1.067382,-128.950272,0.106868,0.000000
109.730003,59.976921,-128.994751,0.012417,0.004202,0.106738,266.790680,13.590964,1.067382,-128.994751,0.106868,0.000000
109.800003,59.972824,-128.994751,0.012426,0.004202,0.106738,266.772430,13.590036,1.067382,-128.994751,0.106868,0.000000