File: Data/compression sample NH 10,12,15/AutoNoheating-12-2-3-240201_02012024_184035.csv
Time (sec),S:Load (lbs),S:HL1 (DIM),S:LVDT (in),S:Position (in),Ch:Position (mm),Ch:Load (N),Ch:Stress (MPa),Ch:Strain (mm/mm),Ch:HL1 (DIM),Set Point (),Cycles ()
0.110000,-0.006332,-196.072037,0.000004,-0.000000,-0.000000,-0.028168,-0.001435,-0.000000,-196.072037,0.000216,0.000000
0.340000,-0.004471,-196.027557,0.000047,-0.000000,-0.000000,-0.019887,-0.001013,-0.000000,-196.027557,0.000373,0.000000
0.570000,0.012657,-195.938583,0.000039,0.000124,0.003139,0.056302,0.002868,0.031392,-195.938583,0.004188,0.000000
0.800000,0.036491,-196.027557,0.000138,0.000268,0.006816,0.162322,0.008269,0.068162,-196.027557,0.008022,0.000000
1.030000,0.033890,-196.027557,0.000289,0.000432,0.010970,0.150749,0.007680,0.109701,-196.027557,0.011855,0.000000
1.260000,0.008568,-195.983063,0.000448,0.000579,0.014708,0.038112,0.001941,0.147081,-195.983063,0.015688,0.000000
1.490000,0.026436,-196.072037,0.000612,0.000728,0.018489,0.117593,0.005990,0.184892,-196.072037,0.019521,0.000000
1.720000,0.016014,-195.983063,0.000763,0.000876,0.022244,0.071234,0.003629,0.222442,-195.983063,0.023354,0.000000
1.950000,0.020477,-196.027557,0.000918,0.001021,0.025921,0.091088,0.004640,0.259212,-196.027557,0.027187,0.000000
2.180000,0.007072,-196.116516,0.001069,0.001174,0.029815,0.031460,0.001603,0.298151,-196.116516,0.031021,0.000000
2.410000,0.014153,-196.072037,0.001237,0.001331,0.033796,0.062954,0.003207,0.337957,-196.072037,0.034854,0.000000
2.640000,-0.018616,-196.072037,0.001375,0.001478,0.037551,-0.082807,-0.004218,0.375507,-196.072037,0.038687,0.000000
2.870000,0.029045,-196.072037,0.001574,0.001632,0.041453,0.129199,0.006582,0.414533,-196.072037,0.042520,0.000000
3.100000,0.033890,-196.072037,0.001703,0.001777,0.045130,0.150749,0.007680,0.451303,-196.072037,0.046353,0.000000
3.330000,0.044312,-196.072037,0.001858,0.001935,0.049154,0.197107,0.010041,0.491541,-196.072037,0.050186,0.000000
3.560000,0.030159,-196.116516,0.002009,0.002086,0.052979,0.134154,0.006834,0.529787,-196.116516,0.054002,0.000000
3.790000,0.017876,-196.116516,0.002160,0.002229,0.056621,0.079515,0.004051,0.566209,-196.116516,0.057835,0.000000
4.020000,0.021599,-196.116516,0.002324,0.002379,0.060419,0.096076,0.004894,0.604194,-196.116516,0.061668,0.000000
4.250000,0.034630,-196.160995,0.002505,0.002534,0.064374,0.154041,0.007847,0.643739,-196.160995,0.065501,0.000000
4.480000,0.081924,-196.160995,0.002647,0.002680,0.068077,0.364418,0.018564,0.680770,-196.160995,0.069334,0.000000
4.710000,0.469193,-196.205475,0.002815,0.002841,0.072153,2.087073,0.106321,0.721530,-196.205475,0.073168,0.000000
4.940000,0.707504,-196.116516,0.002854,-0.000002,-0.000061,3.147136,0.160323,-0.000606,-196.116516,0.000147,0.000000
5.170000,0.665802,-196.116516,0.002850,-0.000003,-0.000069,2.961635,0.150873,-0.000693,-196.116516,0.000147,0.000000
5.400000,0.666550,-196.116516,0.002876,-0.000003,-0.000069,2.964961,0.151042,-0.000693,-196.116516,0.000312,0.000000
5.630000,0.615906,-196.205475,0.002859,-0.000002,-0.000061,2.739686,0.139566,-0.000606,-196.205475,0.000694,0.000000
5.860000,0.600266,-196.205475,0.002854,-0.000002,-0.000061,2.670114,0.136022,-0.000606,-196.205475,0.001075,0.000000
6.090000,0.814003,-196.116516,0.002880,0.000026,0.000650,3.620866,0.184456,0.006502,-196.116516,0.001457,0.000000
6.320000,0.895554,-196.205475,0.002902,0.000038,0.000971,3.983621,0.202935,0.009712,-196.205475,0.001838,0.000000
6.550000,0.946945,-196.116516,0.002915,0.000046,0.001171,4.212223,0.214581,0.011707,-196.116516,0.002229,0.000000
6.780000,1.049347,-196.205475,0.002906,0.000063,0.001596,4.667728,0.237785,0.015957,-196.205475,0.002610,0.000000
7.010000,1.190475,-196.249954,0.002966,0.000087,0.002212,5.295499,0.269766,0.022115,-196.249954,0.002992,0.000000
7.240000,1.255264,-196.205475,0.002962,0.000100,0.002541,5.583694,0.284447,0.025408,-196.205475,0.003373,0.000000
7.470000,1.305908,-196.205475,0.002992,0.000112,0.002853,5.808970,0.295923,0.028531,-196.205475,0.003755,0.000000
7.700000,1.391182,-196.205475,0.002988,0.000129,0.003269,6.188286,0.315246,0.032694,-196.205475,0.004145,0.000000
7.930000,1.482788,-196.205475,0.002992,0.000146,0.003712,6.595771,0.336005,0.037118,-196.205475,0.004527,0.000000
8.160001,1.570297,-196.249954,0.003027,0.000161,0.004093,6.985031,0.355834,0.040934,-196.249954,0.004909,0.000000
8.390000,1.575134,-196.249954,0.003027,0.000168,0.004258,7.006547,0.356931,0.042580,-196.249954,0.005290,0.000000
8.620001,1.711052,-196.249954,0.003061,0.000185,0.004700,7.611139,0.387730,0.047005,-196.249954,0.005672,0.000000
8.850000,1.821648,-196.249954,0.003096,0.000207,0.005264,8.103093,0.412791,0.052640,-196.249954,0.006062,0.000000
9.080001,1.860748,-196.294434,0.003091,0.000222,0.005646,8.277021,0.421652,0.056455,-196.294434,0.006443,0.000000
9.310000,1.903564,-196.294434,0.003109,0.000238,0.006053,8.467478,0.431354,0.060532,-196.294434,0.006825,0.000000
9.540001,1.940430,-196.249954,0.003139,0.000252,0.006409,8.631462,0.439708,0.064086,-196.249954,0.007206,0.000000
9.770000,1.989586,-196.249954,0.003165,0.000263,0.006686,8.850120,0.450847,0.066864,-196.249954,0.007588,0.000000
10.000000,2.088264,-196.205475,0.003156,0.000282,0.007172,9.289064,0.473208,0.071720,-196.205475,0.007979,0.000000
10.230000,2.076347,-196.294434,0.003173,0.000290,0.007363,9.236054,0.470507,0.073628,-196.294434,0.008360,0.000000
10.460000,2.167953,-196.294434,0.003178,0.000305,0.007753,9.643538,0.491265,0.077530,-196.294434,0.008742,0.000000
10.690001,2.266632,-196.294434,0.003229,0.000327,0.008299,10.082483,0.513626,0.082991,-196.294434,0.009123,0.000000
10.920000,2.359352,-196.294434,0.003255,0.000347,0.008820,10.494923,0.534637,0.088196,-196.294434,0.009513,0.000000
11.150001,2.317650,-196.249954,0.003260,0.000361,0.009167,10.309422,0.525187,0.091666,-196.249954,0.009895,0.000000
11.380000,2.297165,-196.338913,0.003307,0.000373,0.009479,10.218300,0.520545,0.094789,-196.338913,0.010277,0.000000
11.610001,2.349297,-196.338913,0.003328,0.000387,0.009834,10.450193,0.532358,0.098343,-196.338913,0.010658,0.000000
11.840000,2.463615,-196.294434,0.003328,0.000406,0.010320,10.958709,0.558263,0.103199,-196.294434,0.011040,0.000000
12.070001,2.491547,-196.338913,0.003337,0.000420,0.010676,11.082952,0.564593,0.106757,-196.338913,0.011430,0.000000
12.300000,2.459892,-196.294434,0.003367,0.000428,0.010875,10.942147,0.557420,0.108751,-196.294434,0.011812,0.000000
12.530001,2.580917,-196.294434,0.003372,0.000450,0.011430,11.480494,0.584844,0.114300,-196.294434,0.012193,0.000000
12.760000,2.573837,-196.383392,0.003397,0.000464,0.011777,11.449000,0.583240,0.117771,-196.383392,0.012575,0.000000
12.990001,2.659859,-196.427887,0.003402,0.000483,0.012263,11.831642,0.602733,0.122627,-196.427887,0.012956,0.000000
13.220000,2.596924,-196.338913,0.003436,0.000494,0.012540,11.551694,0.588471,0.125401,-196.338913,0.013347,0.000000
13.450001,2.637886,-196.294434,0.003454,0.000507,0.012878,11.733903,0.597753,0.128781,-196.294434,0.013728,0.000000
13.680000,2.674004,-196.338913,0.003492,0.000521,0.013225,11.894562,0.605938,0.132252,-196.338913,0.014110,0.000000
13.910001,2.709007,-196.427887,0.003501,0.000536,0.013615,12.050266,0.613870,0.136154,-196.427887,0.014491,0.000000
14.140000,2.751831,-196.472366,0.003523,0.000552,0.014014,12.240756,0.623574,0.140143,-196.472366,0.014873,0.000000
14.370001,2.760773,-196.383392,0.003531,0.000563,0.014309,12.280530,0.625600,0.143092,-196.383392,0.015263,0.000000
14.600000,2.871361,-196.338913,0.003531,0.000584,0.014838,12.772450,0.650660,0.148383,-196.338913,0.015645,0.000000
14.830001,2.846786,-196.427887,0.003583,0.000592,0.015046,12.663138,0.645091,0.150465,-196.427887,0.016026,0.000000
15.060000,2.903389,-196.427887,0.003570,0.000613,0.015575,12.914919,0.657917,0.155752,-196.427887,0.016408,0.000000
15.290001,2.940994,-196.472366,0.003604,0.000631,0.016035,13.082196,0.666439,0.160351,-196.472366,0.016789,0.000000
15.520000,2.916794,-196.472366,0.003604,0.000643,0.016330,12.974547,0.660955,0.163299,-196.472366,0.017180,0.000000
15.750001,2.992760,-196.472366,0.003630,0.000662,0.016816,13.312460,0.678169,0.168155,-196.472366,0.017561,0.000000
15.980000,2.986427,-196.383392,0.003652,0.000674,0.017119,13.284292,0.676734,0.171191,-196.383392,0.017943,0.000000
16.210001,2.955894,-196.472366,0.003678,0.000683,0.017345,13.148476,0.669815,0.173447,-196.472366,0.018325,0.000000
16.440001,3.034088,-196.516846,0.003699,0.000698,0.017717,13.496298,0.687534,0.177175,-196.516846,0.018706,0.000000
16.670000,3.129417,-196.472366,0.003738,0.000720,0.018281,13.920344,0.709136,0.182810,-196.472366,0.019096,0.000000
16.900002,3.124947,-196.472366,0.003717,0.000732,0.018593,13.900456,0.708123,0.185933,-196.472366,0.019478,0.000000
17.130001,3.128677,-196.427887,0.003738,0.000746,0.018957,13.917052,0.708968,0.189574,-196.427887,0.019859,0.000000
17.360001,3.153252,-196.516846,0.003773,0.000760,0.019304,14.026364,0.714537,0.193045,-196.516846,0.020241,0.000000
17.590000,3.226608,-196.516846,0.003773,0.000778,0.019764,14.352671,0.731160,0.197640,-196.516846,0.020623,0.000000
17.820002,3.248207,-196.561325,0.003798,0.000792,0.020120,14.448747,0.736054,0.201197,-196.561325,0.021013,0.000000
18.050001,3.213203,-196.472366,0.003811,0.000804,0.020423,14.293043,0.728122,0.204233,-196.472366,0.021394,0.000000
18.280001,3.219162,-196.472366,0.003833,0.000816,0.020727,14.319548,0.729473,0.207268,-196.472366,0.021776,0.000000
18.510000,3.356194,-196.561325,0.003859,0.000838,0.021273,14.929094,0.760524,0.212730,-196.561325,0.022158,0.000000
18.740002,3.416893,-196.516846,0.003876,0.000857,0.021759,15.199100,0.774279,0.217586,-196.516846,0.022539,0.000000
18.970001,3.383377,-196.561325,0.003898,0.000868,0.022036,15.050013,0.766684,0.220360,-196.561325,0.022929,0.000000
19.200001,3.394920,-196.516846,0.003906,0.000884,0.022444,15.101360,0.769300,0.224437,-196.516846,0.023311,0.000000
19.430000,3.381142,-196.472366,0.003919,0.000894,0.022695,15.040070,0.766178,0.226954,-196.472366,0.023693,0.000000
19.660002,3.494347,-196.605804,0.003932,0.000913,0.023181,15.543630,0.791830,0.231810,-196.605804,0.024074,0.000000
19.890001,3.431038,-196.605804,0.003958,0.000919,0.023346,15.262019,0.777484,0.233456,-196.605804,0.024464,0.000000
20.120001,3.504395,-196.605804,0.003954,0.000939,0.023857,15.588326,0.794107,0.238573,-196.605804,0.024846,0.000000
20.350000,3.608665,-196.561325,0.003997,0.000956,0.024291,16.052145,0.817735,0.242911,-196.561325,0.025227,0.000000
20.580002,3.674202,-196.561325,0.004018,0.000976,0.024803,16.343666,0.832586,0.248028,-196.561325,0.025609,0.000000
20.810001,3.647018,-196.605804,0.004070,0.000991,0.025176,16.222748,0.826426,0.251756,-196.605804,0.025991,0.000000
21.040001,3.641434,-196.650284,0.004057,0.001004,0.025505,16.197906,0.825161,0.255049,-196.650284,0.026381,0.000000
21.270000,3.630257,-196.605804,0.004053,0.001015,0.025791,16.148188,0.822628,0.257914,-196.605804,0.026763,0.000000
21.500002,3.712929,-196.605804,0.004070,0.001031,0.026190,16.515932,0.841362,0.261903,-196.605804,0.027144,0.000000
21.730001,3.790382,-196.561325,0.004126,0.001050,0.026667,16.860462,0.858913,0.266672,-196.561325,0.027526,0.000000
21.960001,3.771019,-196.605804,0.004126,0.001062,0.026971,16.774330,0.854525,0.269708,-196.605804,0.027907,0.000000
22.190001,3.794846,-196.650284,0.004143,0.001075,0.027309,16.880316,0.859924,0.273088,-196.650284,0.028297,0.000000
22.420002,3.903580,-196.694763,0.004174,0.001095,0.027812,17.363989,0.884564,0.278118,-196.694763,0.028679,0.000000
22.650002,3.906563,-196.605804,0.004174,0.001109,0.028168,17.377258,0.885240,0.281676,-196.605804,0.029061,0.000000
22.880001,3.887939,-196.605804,0.004208,0.001120,0.028454,17.294418,0.881020,0.284537,-196.605804,0.029442,0.000000
23.110001,3.906189,-196.650284,0.004243,0.001137,0.028870,17.375597,0.885155,0.288700,-196.650284,0.029824,0.000000
23.340002,3.874161,-196.650284,0.004217,0.001147,0.029139,17.233128,0.877897,0.291388,-196.650284,0.030214,0.000000
23.570002,4.055511,-196.694763,0.004247,0.001168,0.029668,18.039816,0.918992,0.296679,-196.694763,0.030596,0.000000
23.800001,4.130356,-196.694763,0.004260,0.001184,0.030076,18.372740,0.935952,0.300755,-196.694763,0.030977,0.000000
24.030001,4.073380,-196.694763,0.004286,0.001196,0.030379,18.119297,0.923041,0.303787,-196.694763,0.031359,0.000000
24.260000,4.082321,-196.694763,0.004303,0.001210,0.030726,18.159071,0.925067,0.307258,-196.694763,0.031741,0.000000
24.490002,4.227921,-196.694763,0.004350,0.001231,0.031264,18.806730,0.958060,0.312636,-196.694763,0.032131,0.000000
24.720001,4.244301,-196.694763,0.004372,0.001246,0.031645,18.879593,0.961772,0.316451,-196.694763,0.032512,0.000000
24.950001,4.208923,-196.694763,0.004355,0.001261,0.032018,18.722225,0.953756,0.320179,-196.694763,0.032894,0.000000
25.180000,4.207436,-196.694763,0.004402,0.001273,0.032330,18.715609,0.953419,0.323302,-196.694763,0.033275,0.000000
25.410002,4.242065,-196.739243,0.004389,0.001288,0.032703,18.869650,0.961266,0.327030,-196.739243,0.033657,0.000000
25.640001,4.326599,-196.739243,0.004406,0.001302,0.033076,19.245674,0.980421,0.330758,-196.739243,0.034047,0.000000
25.870001,4.308723,-196.739243,0.004432,0.001312,0.033319,19.166159,0.976371,0.333188,-196.739243,0.034429,0.000000
26.100000,4.485229,-196.694763,0.004458,0.001335,0.033908,19.951298,1.016368,0.339085,-196.694763,0.034810,0.000000
26.330002,4.564171,-196.739243,0.004471,0.001355,0.034420,20.302446,1.034256,0.344202,-196.739243,0.035192,0.000000
26.560001,4.510178,-196.783722,0.004501,0.001367,0.034724,20.062271,1.022021,0.347238,-196.783722,0.035573,0.000000
26.790001,4.509056,-196.783722,0.004501,0.001383,0.035131,20.057283,1.021767,0.351314,-196.783722,0.035964,0.000000
27.020000,4.561562,-196.828201,0.004523,0.001396,0.035469,20.290840,1.033665,0.354694,-196.828201,0.036345,0.000000
27.250002,4.519485,-196.783722,0.004549,0.001408,0.035756,20.103676,1.024130,0.357555,-196.783722,0.036727,0.000000
27.480001,4.686310,-196.694763,0.004566,0.001426,0.036233,20.845747,1.061933,0.362328,-196.694763,0.037109,0.000000
27.710001,4.684814,-196.739243,0.004579,0.001439,0.036553,20.839096,1.061594,0.365534,-196.739243,0.037490,0.000000
27.940001,4.735092,-196.828201,0.004600,0.001453,0.036900,21.062742,1.072987,0.369005,-196.828201,0.037880,0.000000
28.170002,4.775681,-196.739243,0.004605,0.001470,0.037325,21.243288,1.082185,0.373255,-196.739243,0.038262,0.000000
28.400002,4.965958,-196.739243,0.004639,0.001490,0.037854,22.089684,1.125302,0.378542,-196.739243,0.038643,0.000000
28.630001,4.922020,-196.783722,0.004631,0.001501,0.038132,21.894238,1.115346,0.381321,-196.783722,0.039025,0.000000
28.860001,4.936913,-196.783722,0.004687,0.001516,0.038514,21.960484,1.118720,0.385136,-196.783722,0.039416,0.000000
29.090002,4.988304,-196.872696,0.004695,0.001532,0.038913,22.189085,1.130366,0.389125,-196.872696,0.039797,0.000000
29.320002,5.100388,-196.783722,0.004704,0.001550,0.039372,22.687656,1.155764,0.393720,-196.783722,0.040179,0.000000
29.550001,5.092567,-196.828201,0.004725,0.001563,0.039702,22.652872,1.153992,0.397017,-196.828201,0.040560,0.000000
29.780001,5.000961,-196.872696,0.004721,0.001573,0.039944,22.245386,1.133234,0.399443,-196.872696,0.040942,0.000000
30.010002,5.274658,-196.783722,0.004751,0.001594,0.040482,23.462851,1.195255,0.404821,-196.783722,0.041332,0.000000
30.240002,5.332001,-196.828201,0.004799,0.001611,0.040924,23.717924,1.208249,0.409242,-196.828201,0.041714,0.000000
30.470001,5.346893,-196.872696,0.004790,0.001626,0.041297,23.784170,1.211623,0.412974,-196.872696,0.042095,0.000000
30.700001,5.347267,-196.872696,0.004825,0.001641,0.041688,23.785831,1.211708,0.416876,-196.872696,0.042477,0.000000
30.930002,5.387115,-196.872696,0.004842,0.001655,0.042034,23.963087,1.220738,0.420343,-196.872696,0.042858,0.000000
31.160002,5.413551,-196.872696,0.004850,0.001669,0.042399,24.080679,1.226728,0.423988,-196.872696,0.043248,0.000000
31.390001,5.528244,-196.872696,0.004876,0.001684,0.042780,24.590858,1.252718,0.427803,-196.872696,0.043630,0.000000
31.620001,5.481323,-196.917175,0.004872,0.001695,0.043049,24.382143,1.242086,0.430490,-196.917175,0.044012,0.000000
31.850002,5.629158,-196.828201,0.004889,0.001712,0.043491,25.039745,1.275585,0.434915,-196.828201,0.044393,0.000000
32.080002,5.797470,-196.872696,0.004932,0.001733,0.044012,25.788435,1.313726,0.440115,-196.872696,0.044775,0.000000
32.310001,5.910667,-196.872696,0.004950,0.001751,0.044480,26.291962,1.339376,0.444801,-196.872696,0.045165,0.000000
32.540001,5.791512,-196.917175,0.004967,0.001763,0.044784,25.761930,1.312375,0.447836,-196.917175,0.045547,0.000000
32.770000,5.792252,-196.917175,0.004971,0.001776,0.045104,25.765223,1.312543,0.451042,-196.917175,0.045928,0.000000
33.000000,5.840660,-196.917175,0.004997,0.001789,0.045434,25.980555,1.323513,0.454339,-196.917175,0.046310,0.000000
33.230003,6.065575,-196.872696,0.005014,0.001810,0.045963,26.981024,1.374479,0.459630,-196.872696,0.046691,0.000000
33.460003,6.094620,-196.917175,0.005023,0.001824,0.046318,27.110222,1.381060,0.463184,-196.917175,0.047082,0.000000
33.690002,6.049934,-196.917175,0.005053,0.001833,0.046553,26.911451,1.370935,0.465527,-196.917175,0.047463,0.000000
33.920002,6.281921,-196.961655,0.005066,0.001853,0.047073,27.943382,1.423504,0.470731,-196.961655,0.047845,0.000000
34.150002,6.431992,-197.050613,0.005079,0.001871,0.047533,28.610928,1.457510,0.475326,-197.050613,0.048226,0.000000
34.380001,6.381348,-196.961655,0.005088,0.001884,0.047854,28.385653,1.446034,0.478536,-196.961655,0.048608,0.000000
34.610001,6.363472,-196.917175,0.005105,0.001899,0.048226,28.306137,1.441983,0.482264,-196.917175,0.048998,0.000000
34.840000,6.382095,-197.006134,0.005118,0.001911,0.048530,28.388977,1.446203,0.485299,-197.006134,0.049380,0.000000
35.070004,6.548546,-196.961655,0.005131,0.001927,0.048946,29.129387,1.483922,0.489463,-196.961655,0.049762,0.000000
35.300003,6.621529,-197.006134,0.005161,0.001942,0.049336,29.454031,1.500460,0.493365,-197.006134,0.050143,0.000000
35.530003,6.616684,-197.006134,0.005182,0.001954,0.049623,29.432480,1.499362,0.496226,-197.006134,0.050525,0.000000
35.760002,6.569771,-197.006134,0.005182,0.001962,0.049831,29.223801,1.488731,0.498308,-197.006134,0.050915,0.000000
35.990002,6.981613,-197.006134,0.005213,0.001985,0.050429,31.055767,1.582056,0.504292,-197.006134,0.051296,0.000000
36.220001,7.094437,-197.006134,0.005217,0.002003,0.050889,31.557631,1.607622,0.508887,-197.006134,0.051678,0.000000
36.450001,6.995758,-197.006134,0.005234,0.002017,0.051227,31.118687,1.585261,0.512270,-197.006134,0.052059,0.000000
36.680000,7.154396,-197.006134,0.005264,0.002035,0.051678,31.824343,1.621209,0.516778,-197.006134,0.052450,0.000000
36.910000,7.056831,-197.050613,0.005286,0.002045,0.051938,31.390354,1.599101,0.519382,-197.050613,0.052831,0.000000
37.140003,7.276901,-197.050613,0.005307,0.002063,0.052389,32.369274,1.648969,0.523890,-197.050613,0.053213,0.000000
37.370003,7.289192,-197.006134,0.005303,0.002076,0.052736,32.423946,1.651755,0.527361,-197.006134,0.053594,0.000000
37.600002,7.231476,-197.050613,0.005325,0.002085,0.052961,32.167210,1.638676,0.529613,-197.050613,0.053976,0.000000
37.830002,7.699921,-197.050613,0.005346,0.002110,0.053594,34.250957,1.744827,0.535945,-197.050613,0.054366,0.000000
38.060001,7.680557,-197.006134,0.005359,0.002123,0.053924,34.164825,1.740439,0.539242,-197.006134,0.054748,0.000000
38.290001,7.614647,-197.050613,0.005381,0.002133,0.054184,33.871639,1.725504,0.541842,-197.050613,0.055130,0.000000
38.520000,7.717789,-197.050613,0.005368,0.002148,0.054557,34.330441,1.748876,0.545570,-197.050613,0.055511,0.000000
38.750000,7.836952,-197.095093,0.005389,0.002163,0.054930,34.860504,1.775879,0.549302,-197.095093,0.055893,0.000000
38.980003,8.119957,-197.095093,0.005415,0.002182,0.055424,36.119373,1.840008,0.554245,-197.095093,0.056283,0.000000
39.210003,8.045479,-197.050613,0.005437,0.002193,0.055693,35.788078,1.823132,0.556932,-197.050613,0.056664,0.000000
39.440002,8.027977,-197.050613,0.005458,0.002203,0.055945,35.710224,1.819166,0.559445,-197.050613,0.057046,0.000000
39.670002,8.390297,-197.139572,0.005476,0.002223,0.056456,37.321903,1.901268,0.564562,-197.139572,0.057428,0.000000
39.900002,8.578346,-197.139572,0.005484,0.002241,0.056933,38.158390,1.943881,0.569331,-197.139572,0.057809,0.000000
40.130001,8.657288,-197.095093,0.005489,0.002258,0.057341,38.509537,1.961769,0.573408,-197.095093,0.058200,0.000000
40.360001,8.734367,-197.095093,0.005501,0.002273,0.057723,38.852406,1.979236,0.577227,-197.095093,0.058581,0.000000
40.590000,8.710907,-197.095093,0.005566,0.002284,0.058018,38.748051,1.973920,0.580175,-197.095093,0.058963,0.000000
40.820004,8.668457,-197.139572,0.005527,0.002294,0.058260,38.559223,1.964300,0.582601,-197.139572,0.059344,0.000000
41.050003,9.061684,-197.139572,0.005549,0.002313,0.058746,40.308384,2.053407,0.587457,-197.139572,0.059726,0.000000
41.280003,9.011787,-197.184052,0.005570,0.002322,0.058989,40.086433,2.042100,0.589887,-197.184052,0.060116,0.000000
41.510002,9.433685,-197.184052,0.005605,0.002345,0.059552,41.963127,2.137704,0.595523,-197.184052,0.060498,0.000000
41.740002,9.577423,-197.139572,0.005618,0.002360,0.059951,42.602505,2.170275,0.599512,-197.139572,0.060879,0.000000
41.970001,9.941971,-197.139572,0.005614,0.002381,0.060489,44.224094,2.252883,0.604891,-197.139572,0.061261,0.000000
42.200001,9.829887,-197.228531,0.005622,0.002392,0.060758,43.725521,2.227484,0.607578,-197.228531,0.061642,0.000000
42.430000,9.820206,-197.228531,0.005652,0.002406,0.061122,43.682457,2.225291,0.611219,-197.228531,0.062033,0.000000
42.660004,9.945694,-197.139572,0.005687,0.002419,0.061443,44.240658,2.253726,0.614429,-197.139572,0.062414,0.000000
42.890003,10.155716,-197.228531,0.005708,0.002435,0.061859,45.174881,2.301318,0.618592,-197.228531,0.062796,0.000000
43.120003,10.326630,-197.184052,0.005713,0.002448,0.062189,45.935143,2.340048,0.621889,-197.184052,0.063177,0.000000
43.350002,10.504257,-197.228531,0.005708,0.002464,0.062596,46.725269,2.380299,0.625965,-197.228531,0.063559,0.000000
43.580002,10.716507,-197.184052,0.005726,0.002481,0.063012,47.669403,2.428395,0.630124,-197.184052,0.063949,0.000000
43.810001,10.992432,-197.184052,0.005743,0.002495,0.063377,48.896778,2.490921,0.633769,-197.184052,0.064331,0.000000
44.040001,11.118294,-197.184052,0.005769,0.002510,0.063758,49.456642,2.519441,0.637585,-197.184052,0.064712,0.000000
44.270000,11.192398,-197.228531,0.005769,0.002526,0.064166,49.786274,2.536234,0.641661,-197.228531,0.065094,0.000000
44.500004,11.280655,-197.228531,0.005825,0.002538,0.064461,50.178860,2.556233,0.644609,-197.228531,0.065476,0.000000
44.730003,11.362572,-197.184052,0.005790,0.002549,0.064747,50.543243,2.574795,0.647471,-197.184052,0.065866,0.000000
44.960003,12.039543,-197.228531,0.005808,0.002572,0.065337,53.554562,2.728199,0.653368,-197.228531,0.066247,0.000000
45.190002,12.103592,-197.273026,0.005842,0.002586,0.065684,53.839466,2.742713,0.656838,-197.273026,0.066629,0.000000
45.420002,12.164665,-197.273026,0.005842,0.002597,0.065970,54.111134,2.756552,0.659700,-197.273026,0.067010,0.000000
45.650002,12.421600,-197.317505,0.005864,0.002614,0.066395,55.254040,2.814775,0.663946,-197.317505,0.067401,0.000000
45.880001,12.933617,-197.273026,0.005881,0.002635,0.066924,57.531601,2.930799,0.669238,-197.273026,0.067782,0.000000
46.110001,13.073997,-197.273026,0.005894,0.002649,0.067288,58.156044,2.962610,0.672879,-197.273026,0.068164,0.000000
46.340004,13.096710,-197.228531,0.005915,0.002661,0.067591,58.257076,2.967757,0.675914,-197.228531,0.068546,0.000000
46.570004,13.170067,-197.317505,0.005915,0.002673,0.067904,58.583382,2.984380,0.679037,-197.317505,0.068927,0.000000
46.800003,13.540955,-197.361984,0.005941,0.002691,0.068346,60.233173,3.068424,0.683461,-197.361984,0.069317,0.000000
47.030003,13.711868,-197.317505,0.005924,0.002702,0.068624,60.993435,3.107154,0.686236,-197.317505,0.069699,0.000000
47.260002,13.728630,-197.228531,0.005950,0.002712,0.068884,61.067997,3.110952,0.688836,-197.228531,0.070080,0.000000
47.490002,14.667381,-197.273026,0.005997,0.002739,0.069569,65.243767,3.323676,0.695686,-197.273026,0.070462,0.000000
47.720001,15.158913,-197.317505,0.006010,0.002759,0.070080,67.430214,3.435059,0.700804,-197.317505,0.070844,0.000000
47.950001,15.140663,-197.317505,0.006010,0.002772,0.070410,67.349030,3.430923,0.704100,-197.317505,0.071234,0.000000
48.180004,15.185722,-197.317505,0.006027,0.002785,0.070748,67.549469,3.441134,0.707484,-197.317505,0.071616,0.000000
48.410004,15.425903,-197.273026,0.006058,0.002797,0.071052,68.617844,3.495560,0.710519,-197.273026,0.071997,0.000000
48.640003,15.670547,-197.361984,0.006040,0.002813,0.071451,69.706078,3.550997,0.714509,-197.361984,0.072379,0.000000
48.870003,16.242516,-197.317505,0.006079,0.002830,0.071876,72.250320,3.680607,0.718755,-197.317505,0.072760,0.000000
49.100002,16.258896,-197.450943,0.006084,0.002842,0.072188,72.323181,3.684319,0.721878,-197.450943,0.073150,0.000000
49.330002,16.660690,-197.361984,0.006079,0.002855,0.072509,74.110451,3.775366,0.725087,-197.361984,0.073532,0.000000
49.560001,17.467621,-197.406464,0.006114,0.002877,0.073072,77.699860,3.958219,0.730723,-197.406464,0.073914,0.000000
49.790001,17.711525,-197.406464,0.006127,0.002892,0.073445,78.784798,4.013489,0.734451,-197.406464,0.074295,0.000000
50.020004,17.709290,-197.361984,0.006148,0.002903,0.073749,78.774857,4.012982,0.737487,-197.361984,0.074677,0.000000
50.250004,18.055595,-197.406464,0.006157,0.002918,0.074113,80.315300,4.091456,0.741132,-197.406464,0.075067,0.000000
50.480003,18.444725,-197.406464,0.006165,0.002933,0.074486,82.046234,4.179635,0.744860,-197.406464,0.075448,0.000000
50.710003,19.123932,-197.406464,0.006174,0.002952,0.074989,85.067497,4.333545,0.749890,-197.406464,0.075830,0.000000
50.940002,19.184258,-197.406464,0.006174,0.002962,0.075240,85.335838,4.347215,0.752403,-197.406464,0.076212,0.000000
51.170002,19.489601,-197.495422,0.006204,0.002978,0.075648,86.694077,4.416407,0.756479,-197.495422,0.076593,0.000000
51.400002,20.249611,-197.539902,0.006217,0.002996,0.076108,90.074768,4.588627,0.761078,-197.539902,0.076984,0.000000
51.630001,20.663696,-197.406464,0.006217,0.003013,0.076532,91.916710,4.682460,0.765325,-197.406464,0.077365,0.000000
51.860001,21.052078,-197.450943,0.006247,0.003028,0.076914,93.644318,4.770469,0.769144,-197.450943,0.077747,0.000000
52.090004,21.402107,-197.406464,0.006256,0.003042,0.077270,95.201324,4.849787,0.772698,-197.406464,0.078128,0.000000
52.320004,21.631119,-197.450943,0.006282,0.003056,0.077625,96.220024,4.901682,0.776252,-197.450943,0.078510,0.000000
52.550003,22.376610,-197.406464,0.006278,0.003075,0.078111,99.536133,5.070612,0.781111,-197.406464,0.078900,0.000000
52.780003,22.434326,-197.495422,0.006282,0.003084,0.078328,99.792870,5.083691,0.783276,-197.495422,0.079282,0.000000
53.010002,22.852501,-197.450943,0.006321,0.003098,0.078692,101.653000,5.178451,0.786921,-197.450943,0.079663,0.000000
53.240002,23.689964,-197.406464,0.006299,0.003117,0.079160,105.378227,5.368223,0.791603,-197.406464,0.080045,0.000000
53.470001,24.515144,-197.495422,0.006321,0.003137,0.079681,109.048805,5.555211,0.796807,-197.495422,0.080426,0.000000
53.700001,25.082268,-197.539902,0.006329,0.003154,0.080106,111.571503,5.683723,0.801058,-197.539902,0.080817,0.000000
53.930004,25.106468,-197.539902,0.006359,0.003165,0.080383,111.679146,5.689207,0.803832,-197.539902,0.081198,0.000000
54.160004,25.400642,-197.539902,0.006355,0.003178,0.080730,112.987701,5.755868,0.807299,-197.539902,0.081580,0.000000
54.390003,25.999046,-197.584381,0.006377,0.003197,0.081198,115.649536,5.891468,0.811985,-197.584381,0.081962,0.000000
54.620003,26.674904,-197.495422,0.006411,0.003211,0.081554,118.655899,6.044620,0.815539,-197.495422,0.082352,0.000000
54.850002,27.140366,-197.539902,0.006394,0.003224,0.081892,120.726379,6.150095,0.818923,-197.539902,0.082733,0.000000
55.080002,27.209625,-197.584381,0.006394,0.003234,0.082144,121.034454,6.165789,0.821436,-197.584381,0.083115,0.000000
55.310001,28.321907,-197.539902,0.006424,0.003255,0.082681,125.982132,6.417836,0.826814,-197.539902,0.083496,0.000000
55.540001,29.242409,-197.539902,0.006424,0.003274,0.083158,130.076736,6.626424,0.831583,-197.539902,0.083878,0.000000
55.770004,29.558556,-197.539902,0.006441,0.003287,0.083496,131.483017,6.698064,0.834963,-197.539902,0.084268,0.000000
56.000004,29.943962,-197.584381,0.006454,0.003300,0.083809,133.197403,6.785399,0.838086,-197.584381,0.084650,0.000000
56.230003,30.323036,-197.584381,0.006459,0.003313,0.084138,134.883606,6.871298,0.841382,-197.584381,0.085031,0.000000
56.460003,30.976921,-197.584381,0.006476,0.003327,0.084511,137.792221,7.019471,0.845110,-197.584381,0.085413,0.000000
56.690002,31.692619,-197.628860,0.006467,0.003344,0.084927,140.975815,7.181650,0.849274,-197.628860,0.085794,0.000000
56.920002,32.048981,-197.584381,0.006510,0.003354,0.085179,142.560989,7.262403,0.851791,-197.584381,0.086185,0.000000
57.150002,32.890915,-197.673340,0.006515,0.003373,0.085665,146.306091,7.453188,0.856647,-197.673340,0.086567,0.000000
57.380001,33.807327,-197.584381,0.006541,0.003389,0.086081,150.382507,7.660850,0.860806,-197.584381,0.086948,0.000000
57.610004,34.518929,-197.584381,0.006515,0.003406,0.086506,153.547867,7.822101,0.865057,-197.584381,0.087330,0.000000
57.840004,35.212654,-197.584381,0.006532,0.003422,0.086922,156.633713,7.979301,0.869220,-197.584381,0.087711,0.000000
58.070004,35.933945,-197.584381,0.006532,0.003436,0.087277,159.842163,8.142749,0.872774,-197.584381,0.088101,0.000000
58.300003,36.547241,-197.628860,0.006575,0.003452,0.087676,162.570251,8.281724,0.876763,-197.628860,0.088483,0.000000
58.530003,37.132607,-197.673340,0.006566,0.003465,0.088023,165.174088,8.414370,0.880234,-197.673340,0.088864,0.000000
58.760002,37.589508,-197.628860,0.006579,0.003476,0.088283,167.206482,8.517904,0.882834,-197.628860,0.089246,0.000000
58.990002,37.945496,-197.628860,0.006579,0.003488,0.088587,168.789993,8.598572,0.885870,-197.628860,0.089628,0.000000
59.220001,39.502014,-197.628860,0.006588,0.003510,0.089151,175.713730,8.951284,0.891509,-197.628860,0.090018,0.000000
59.450005,40.070999,-197.673340,0.006605,0.003523,0.089472,178.244705,9.080218,0.894715,-197.673340,0.090400,0.000000
59.680004,40.498482,-197.717834,0.006592,0.003536,0.089819,180.146240,9.177087,0.898186,-197.717834,0.090781,0.000000
59.910004,41.076408,-197.628860,0.006592,0.003549,0.090157,182.716995,9.308047,0.901566,-197.628860,0.091163,0.000000
60.140003,41.917595,-197.673340,0.006610,0.003564,0.090521,186.458771,9.498663,0.905211,-197.673340,0.091544,0.000000
60.370003,43.249573,-197.673340,0.006657,0.003584,0.091033,192.383713,9.800493,0.910328,-197.673340,0.091935,0.000000
60.600002,43.558266,-197.717834,0.006644,0.003594,0.091284,193.756836,9.870444,0.912841,-197.717834,0.092316,0.000000
60.830002,44.239708,-197.717834,0.006653,0.003606,0.091588,196.788055,10.024861,0.915876,-197.717834,0.092698,0.000000
61.060001,45.187767,-197.717834,0.006644,0.003622,0.092004,201.005234,10.239694,0.920040,-197.717834,0.093079,0.000000
61.290005,46.708916,-197.673340,0.006666,0.003646,0.092611,207.771637,10.584392,0.926111,-197.673340,0.093461,0.000000
61.520004,47.470787,-197.717834,0.006687,0.003658,0.092915,211.160614,10.757034,0.929146,-197.717834,0.093851,0.000000
61.750004,48.257607,-197.762314,0.006674,0.003673,0.093305,214.660553,10.935330,0.933049,-197.762314,0.094233,0.000000
61.980003,48.753609,-197.762314,0.006687,0.003686,0.093626,216.866882,11.047726,0.936258,-197.762314,0.094614,0.000000
62.210003,49.283493,-197.762314,0.006674,0.003698,0.093921,219.223923,11.167799,0.939207,-197.762314,0.094996,0.000000
62.440002,50.404335,-197.717834,0.006709,0.003713,0.094311,224.209686,11.421786,0.943109,-197.717834,0.095377,0.000000
62.670002,50.790489,-197.673340,0.006704,0.003722,0.094545,225.927383,11.509289,0.945448,-197.673340,0.095768,0.000000
62.900002,52.422966,-197.717834,0.006696,0.003746,0.095152,233.188995,11.879213,0.951519,-197.717834,0.096149,0.000000
63.130005,53.336021,-197.762314,0.006722,0.003759,0.095473,237.250473,12.086115,0.954728,-197.762314,0.096531,0.000000
63.360004,54.910042,-197.762314,0.006722,0.003781,0.096036,244.252060,12.442793,0.960364,-197.762314,0.096913,0.000000
63.590004,55.484245,-197.806793,0.006739,0.003794,0.096366,246.806244,12.572909,0.963661,-197.806793,0.097303,0.000000
63.820004,56.150047,-197.762314,0.006760,0.003806,0.096670,249.767883,12.723783,0.966696,-197.762314,0.097684,0.000000
64.050003,56.856804,-197.762314,0.006743,0.003817,0.096964,252.911697,12.883936,0.969645,-197.762314,0.098066,0.000000
64.280006,58.064407,-197.762314,0.006782,0.003838,0.097476,258.283386,13.157583,0.974762,-197.762314,0.098447,0.000000
64.510002,58.808037,-197.851273,0.006769,0.003848,0.097736,261.591217,13.326092,0.977362,-197.851273,0.098829,0.000000
64.740005,59.942284,-197.806793,0.006786,0.003865,0.098179,266.636597,13.583116,0.981787,-197.806793,0.099219,0.000000
64.970001,60.948807,-197.762314,0.006812,0.003881,0.098586,271.113831,13.811196,0.985863,-197.762314,0.099601,0.000000
65.200005,62.057358,-197.762314,0.006786,0.003897,0.098977,276.044922,14.062398,0.989765,-197.762314,0.099983,0.000000
65.430000,62.941002,-197.806793,0.006786,0.003910,0.099306,279.975555,14.262634,0.993058,-197.806793,0.100364,0.000000
65.660004,64.049187,-197.851273,0.006795,0.003927,0.099748,284.904999,14.513753,0.997483,-197.851273,0.100746,0.000000
65.889999,64.864677,-197.806793,0.006791,0.003939,0.100061,288.532501,14.698546,1.000605,-197.806793,0.101136,0.000000
66.120003,65.444084,-197.806793,0.006795,0.003949,0.100303,291.109833,14.829841,1.003031,-197.806793,0.101517,0.000000
66.350006,67.412819,-197.806793,0.006804,0.003973,0.100902,299.867187,15.275963,1.009015,-197.806793,0.101899,0.000000
66.580002,66.872887,-197.851273,0.006842,0.003964,0.100685,297.465454,15.153612,1.006850,-197.851273,0.100910,0.000000
66.810005,66.477791,-197.851273,0.006821,0.003964,0.100676,295.707977,15.064083,1.006763,-197.851273,0.100685,0.000000
67.040001,66.040260,-197.806793,0.006842,0.003963,0.100650,293.761749,14.964937,1.006502,-197.806793,0.100685,0.000000
67.270004,65.652245,-197.762314,0.006821,0.003962,0.100633,292.035767,14.877011,1.006328,-197.762314,0.100685,0.000000
67.500000,65.306313,-197.895752,0.006847,0.003962,0.100624,290.496979,14.798622,1.006241,-197.895752,0.100685,0.000000
67.730003,65.020332,-197.940231,0.006873,0.003962,0.100624,289.224884,14.733818,1.006241,-197.940231,0.100685,0.000000
67.960007,64.738075,-197.940231,0.006842,0.003961,0.100615,287.969330,14.669857,1.006154,-197.940231,0.100685,0.000000
68.190002,64.501991,-197.806793,0.006864,0.003961,0.100615,286.919189,14.616361,1.006154,-197.806793,0.100685,0.000000
68.420006,64.275963,-197.806793,0.006890,0.003961,0.100615,285.913757,14.565142,1.006154,-197.806793,0.100685,0.000000
68.650002,64.059242,-197.851273,0.006868,0.003961,0.100615,284.949738,14.516032,1.006154,-197.851273,0.100685,0.000000
68.880005,63.875648,-197.895752,0.006873,0.003961,0.100607,284.133087,14.474428,1.006067,-197.895752,0.100685,0.000000
69.110001,63.710701,-197.851273,0.006881,0.003961,0.100607,283.399353,14.437052,1.006067,-197.851273,0.100685,0.000000
69.340004,63.555046,-197.895752,0.006864,0.003961,0.100607,282.706970,14.401779,1.006067,-197.895752,0.100685,0.000000
69.570000,63.401619,-197.895752,0.006873,0.003961,0.100607,282.024475,14.367012,1.006067,-197.895752,0.100685,0.000000
69.800003,63.255287,-197.940231,0.006855,0.003961,0.100607,281.373566,14.333853,1.006067,-197.940231,0.100685,0.000000
70.030006,63.114525,-197.940231,0.006860,0.003961,0.100607,280.747437,14.301956,1.006067,-197.940231,0.100685,0.000000
70.260002,62.986801,-197.984711,0.006864,0.003961,0.100607,280.179291,14.273013,1.006067,-197.984711,0.100685,0.000000
70.490005,62.895569,-197.851273,0.006860,0.003961,0.100607,279.773468,14.252339,1.006067,-197.851273,0.100685,0.000000
70.720001,62.769707,-197.940231,0.006860,0.003961,0.100607,279.213593,14.223819,1.006067,-197.940231,0.100685,0.000000
70.950005,62.660973,-198.029190,0.006873,0.003961,0.100607,278.729919,14.199179,1.006067,-198.029190,0.100685,0.000000
71.180000,62.563416,-197.984711,0.006860,0.003961,0.100607,278.295959,14.177073,1.006067,-197.984711,0.100685,0.000000
71.410004,62.468460,-197.984711,0.006860,0.003961,0.100607,277.873596,14.155556,1.006067,-197.984711,0.100685,0.000000
71.640007,62.371643,-197.940231,0.006868,0.003961,0.100607,277.442932,14.133616,1.006067,-197.940231,0.100685,0.000000
71.870003,62.288979,-197.984711,0.006855,0.003961,0.100607,277.075226,14.114884,1.006067,-197.984711,0.100685,0.000000
72.100006,62.200722,-197.984711,0.006860,0.003961,0.100607,276.682617,14.094886,1.006067,-197.984711,0.100685,0.000000
72.330002,62.114334,-198.029190,0.006860,0.003961,0.100607,276.298370,14.075310,1.006067,-198.029190,0.100685,0.000000
72.560005,62.044327,-198.029190,0.006885,0.003961,0.100607,275.986938,14.059445,1.006067,-198.029190,0.100685,0.000000
72.790001,61.972084,-198.073669,0.006864,0.003961,0.100607,275.665588,14.043075,1.006067,-198.073669,0.100685,0.000000
73.020004,61.907669,-197.984711,0.006868,0.003961,0.100607,275.379059,14.028479,1.006067,-197.984711,0.100685,0.000000
73.250000,61.832451,-198.029190,0.006847,0.003961,0.100607,275.044464,14.011434,1.006067,-198.029190,0.100685,0.000000
73.480003,61.760208,-198.029190,0.006881,0.003961,0.100607,274.723114,13.995063,1.006067,-198.029190,0.100685,0.000000
73.710007,61.692062,-198.029190,0.006864,0.003961,0.100607,274.420013,13.979621,1.006067,-198.029190,0.100685,0.000000
73.940002,61.632484,-198.073669,0.006868,0.003961,0.100607,274.154968,13.966121,1.006067,-198.073669,0.100685,0.000000
74.170006,61.578865,-198.029190,0.006860,0.003961,0.100607,273.916473,13.953970,1.006067,-198.029190,0.100685,0.000000
74.400002,61.524124,-198.073669,0.006860,0.003961,0.100607,273.672974,13.941566,1.006067,-198.073669,0.100685,0.000000
74.630005,61.466774,-198.073669,0.006864,0.003961,0.100607,273.417877,13.928570,1.006067,-198.073669,0.100685,0.000000
74.860001,61.404961,-198.073669,0.006851,0.003961,0.100598,273.142914,13.914563,1.005980,-198.073669,0.100685,0.000000
75.090004,61.356186,-198.029190,0.006890,0.003961,0.100598,272.925934,13.903511,1.005980,-198.029190,0.100685,0.000000
75.320007,61.307777,-198.029190,0.006868,0.003961,0.100598,272.710602,13.892541,1.005980,-198.029190,0.100685,0.000000
75.550003,61.263466,-198.073669,0.006877,0.003961,0.100598,272.513519,13.882500,1.005980,-198.073669,0.100685,0.000000
75.780006,61.207237,-198.073669,0.006864,0.003961,0.100598,272.263397,13.869758,1.005980,-198.073669,0.100685,0.000000
76.010002,61.149887,-198.162643,0.006885,0.003961,0.100598,272.008270,13.856762,1.005980,-198.162643,0.100685,0.000000
76.240005,61.113770,-198.073669,0.006877,0.003961,0.100598,271.847626,13.848578,1.005980,-198.073669,0.100685,0.000000
76.470001,61.069458,-198.073669,0.006873,0.003961,0.100598,271.650513,13.838537,1.005980,-198.073669,0.100685,0.000000
76.700005,61.024025,-198.118149,0.006885,0.003961,0.100598,271.448425,13.828241,1.005980,-198.118149,0.100685,0.000000
76.930000,60.974129,-198.162643,0.006877,0.003961,0.100598,271.226471,13.816936,1.005980,-198.162643,0.100685,0.000000
77.160004,60.927208,-198.162643,0.006855,0.003961,0.100598,271.017761,13.806303,1.005980,-198.162643,0.100685,0.000000
77.390007,60.888855,-198.118149,0.006864,0.003961,0.100598,270.847168,13.797612,1.005980,-198.118149,0.100685,0.000000
77.620003,60.859062,-198.162643,0.006855,0.003961,0.100598,270.714630,13.790860,1.005980,-198.162643,0.100685,0.000000
77.850006,60.827415,-198.073669,0.006868,0.003961,0.100598,270.573853,13.783689,1.005980,-198.073669,0.100685,0.000000
78.080002,60.770065,-198.207123,0.006877,0.003961,0.100598,270.318756,13.770694,1.005980,-198.207123,0.100685,0.000000
78.310005,60.726501,-198.207123,0.006885,0.003961,0.100598,270.124969,13.760821,1.005980,-198.207123,0.100685,0.000000
78.540001,60.692986,-198.118149,0.006873,0.003961,0.100598,269.975891,13.753227,1.005980,-198.118149,0.100685,0.000000
78.770004,60.661705,-198.118149,0.006877,0.003961,0.100598,269.836731,13.746140,1.005980,-198.118149,0.100685,0.000000
79.000000,60.627449,-198.162643,0.006881,0.003961,0.100598,269.684357,13.738376,1.005980,-198.162643,0.100685,0.000000
79.230003,60.583885,-198.162643,0.006868,0.003961,0.100598,269.490570,13.728504,1.005980,-198.162643,0.100685,0.000000
79.460007,60.545158,-198.251602,0.006881,0.003961,0.100598,269.318329,13.719729,1.005980,-198.251602,0.100685,0.000000
79.690002,60.510155,-198.207123,0.006873,0.003961,0.100598,269.162598,13.711797,1.005980,-198.207123,0.100685,0.000000
79.920006,60.489670,-198.207123,0.006877,0.003961,0.100598,269.071503,13.707155,1.005980,-198.207123,0.100685,0.000000
80.150002,60.441635,-198.162643,0.006885,0.003961,0.100598,268.857819,13.696271,1.005980,-198.162643,0.100685,0.000000
80.380005,60.411850,-198.251602,0.006873,0.003961,0.100598,268.725342,13.689521,1.005980,-198.251602,0.100685,0.000000
80.610001,60.373863,-198.251602,0.006877,0.003961,0.100598,268.556366,13.680913,1.005980,-198.251602,0.100685,0.000000
80.840004,60.348915,-198.296082,0.006860,0.003961,0.100598,268.445374,13.675260,1.005980,-198.296082,0.100685,0.000000
81.070007,60.321358,-198.207123,0.006877,0.003961,0.100598,268.322815,13.669015,1.005980,-198.207123,0.100685,0.000000
81.300003,60.304230,-198.251602,0.006890,0.003961,0.100598,268.246613,13.665134,1.005980,-198.251602,0.100685,0.000000
81.530006,60.258057,-198.207123,0.006860,0.003961,0.100598,268.041229,13.654671,1.005980,-198.207123,0.100685,0.000000
81.760002,60.224915,-198.296082,0.006868,0.003961,0.100598,267.893799,13.647161,1.005980,-198.296082,0.100685,0.000000
81.990005,60.191772,-198.251602,0.006860,0.003961,0.100598,267.746368,13.639650,1.005980,-198.251602,0.100685,0.000000
82.220001,60.172409,-198.251602,0.006855,0.003961,0.100598,267.660248,13.635262,1.005980,-198.251602,0.100685,0.000000
82.450005,60.155281,-198.251602,0.006864,0.003961,0.100598,267.584045,13.631382,1.005980,-198.251602,0.100685,0.000000
82.680000,60.102036,-198.296082,0.006873,0.003961,0.100598,267.347198,13.619316,1.005980,-198.296082,0.100685,0.000000
82.910004,60.073357,-198.296082,0.006877,0.003961,0.100598,267.219635,13.612817,1.005980,-198.296082,0.100685,0.000000
83.140007,60.053627,-198.296082,0.006860,0.003961,0.100598,267.131866,13.608346,1.005980,-198.296082,0.100685,0.000000
83.370003,60.039474,-198.296082,0.006838,0.003961,0.100598,267.068909,13.605140,1.005980,-198.296082,0.100685,0.000000
83.600006,60.001495,-198.296082,0.006881,0.003961,0.100598,266.899994,13.596533,1.005980,-198.296082,0.100685,0.000000
83.830002,59.970955,-198.296082,0.006877,0.003961,0.100598,266.764130,13.589613,1.005980,-198.296082,0.100685,0.000000
84.060005,59.956810,-198.385040,0.006881,0.003961,0.100598,266.701202,13.586407,1.005980,-198.385040,0.100685,0.000000
84.290001,59.930367,-198.385040,0.006864,0.003961,0.100598,266.583588,13.580416,1.005980,-198.385040,0.100685,0.000000
84.520004,59.903931,-198.251602,0.006868,0.003961,0.100598,266.466003,13.574425,1.005980,-198.251602,0.100685,0.000000
84.750008,59.885681,-198.340561,0.006881,0.003961,0.100598,266.384827,13.570290,1.005980,-198.340561,0.100685,0.000000
84.980003,59.845093,-198.340561,0.006864,0.003961,0.100598,266.204254,13.561092,1.005980,-198.340561,0.100685,0.000000
85.210007,59.821266,-198.385040,0.006873,0.003961,0.100598,266.098267,13.555693,1.005980,-198.385040,0.100685,0.000000
85.440002,59.798180,-198.429520,0.006860,0.003961,0.100598,265.995575,13.550461,1.005980,-198.429520,0.100685,0.000000
85.670006,59.777695,-198.429520,0.006885,0.003961,0.100598,265.904480,13.545819,1.005980,-198.429520,0.100685,0.000000
85.900002,59.760941,-198.385040,0.006864,0.003961,0.100598,265.829926,13.542023,1.005980,-198.385040,0.100685,0.000000
86.130005,59.733757,-198.385040,0.006877,0.003961,0.100598,265.709015,13.535863,1.005980,-198.385040,0.100685,0.000000
86.360001,59.710670,-198.429520,0.006885,0.003961,0.100598,265.606323,13.530631,1.005980,-198.429520,0.100685,0.000000
86.590004,59.690933,-198.429520,0.006890,0.003961,0.100598,265.518524,13.526159,1.005980,-198.429520,0.100685,0.000000
86.820007,59.660774,-198.429520,0.006885,0.003961,0.100598,265.384369,13.519325,1.005980,-198.429520,0.100685,0.000000
87.050003,59.650345,-198.429520,0.006860,0.003961,0.100598,265.337982,13.516961,1.005980,-198.429520,0.100685,0.000000
87.280006,59.632843,-198.429520,0.006911,0.003961,0.100598,265.260132,13.512996,1.005980,-198.429520,0.100685,0.000000
87.510002,59.615341,-198.429520,0.006860,0.003961,0.100598,265.182281,13.509029,1.005980,-198.429520,0.100685,0.000000
87.740005,59.587784,-198.473999,0.006885,0.003961,0.100598,265.059692,13.502785,1.005980,-198.473999,0.100685,0.000000
87.970001,59.570656,-198.429520,0.006890,0.003961,0.100598,264.983521,13.498904,1.005980,-198.429520,0.100685,0.000000
88.200005,59.547195,-198.473999,0.006864,0.003961,0.100598,264.879150,13.493587,1.005980,-198.473999,0.100685,0.000000
88.430008,59.537514,-198.429520,0.006903,0.003961,0.100598,264.836090,13.491393,1.005980,-198.429520,0.100685,0.000000
88.660004,59.516663,-198.385040,0.006877,0.003961,0.100598,264.743347,13.486668,1.005980,-198.385040,0.100685,0.000000
88.890007,59.496552,-198.473999,0.006890,0.003961,0.100598,264.653870,13.482112,1.005980,-198.473999,0.100685,0.000000
89.120003,59.481285,-198.473999,0.006851,0.003961,0.100598,264.585968,13.478652,1.005980,-198.473999,0.100685,0.000000
89.350006,59.464157,-198.429520,0.006885,0.003961,0.100598,264.509796,13.474771,1.005980,-198.429520,0.100685,0.000000
89.580002,59.448517,-198.473999,0.006873,0.003961,0.100598,264.440216,13.471227,1.005980,-198.473999,0.100685,0.000000
89.810005,59.429527,-198.518478,0.006873,0.003961,0.100598,264.355743,13.466924,1.005980,-198.518478,0.100685,0.000000
90.040001,59.406815,-198.562973,0.006885,0.003961,0.100598,264.254700,13.461777,1.005980,-198.562973,0.100685,0.000000
90.270004,59.378883,-198.562973,0.006890,0.003961,0.100598,264.130463,13.455447,1.005980,-198.562973,0.100685,0.000000
90.500008,59.374420,-198.518478,0.006885,0.003961,0.100598,264.110626,13.454436,1.005980,-198.518478,0.100685,0.000000
90.730003,59.361008,-198.518478,0.006890,0.003961,0.100598,264.050964,13.451397,1.005980,-198.518478,0.100685,0.000000
90.960007,59.339783,-198.518478,0.006885,0.003961,0.100598,263.956543,13.446587,1.005980,-198.518478,0.100685,0.000000
91.190002,59.326012,-198.518478,0.006898,0.003961,0.100598,263.895294,13.443466,1.005980,-198.518478,0.100685,0.000000
91.420006,59.307762,-198.562973,0.006885,0.003961,0.100598,263.814087,13.439331,1.005980,-198.562973,0.100685,0.000000
91.650002,59.292496,-198.518478,0.006851,0.003961,0.100598,263.746185,13.435872,1.005980,-198.518478,0.100685,0.000000
91.880005,59.269783,-198.562973,0.006890,0.003961,0.100598,263.645172,13.430725,1.005980,-198.562973,0.100685,0.000000
92.110001,59.273132,-198.518478,0.006877,0.003961,0.100598,263.660065,13.431484,1.005980,-198.518478,0.100685,0.000000
92.340004,59.258606,-198.562973,0.006894,0.003961,0.100598,263.595459,13.428192,1.005980,-198.562973,0.100685,0.000000
92.570007,59.209831,-198.518478,0.006873,0.003961,0.100598,263.378479,13.417139,1.005980,-198.518478,0.100685,0.000000
92.800003,59.194557,-198.562973,0.006864,0.003961,0.100598,263.310547,13.413678,1.005980,-198.562973,0.100685,0.000000
93.030006,59.184875,-198.562973,0.006864,0.003961,0.100598,263.267487,13.411485,1.005980,-198.562973,0.100685,0.000000
93.260002,59.165146,-198.562973,0.006898,0.003961,0.100598,263.179718,13.407014,1.005980,-198.562973,0.100685,0.000000
93.490005,59.150246,-198.562973,0.006881,0.003961,0.100598,263.113434,13.403637,1.005980,-198.562973,0.100685,0.000000
93.720001,59.130882,-198.651932,0.006873,0.003961,0.100598,263.027313,13.399249,1.005980,-198.651932,0.100685,0.000000
93.950005,59.102959,-198.607452,0.006877,0.003961,0.100598,262.903076,13.392921,1.005980,-198.607452,0.100685,0.000000
94.180008,59.083595,-198.607452,0.006890,0.003961,0.100598,262.816956,13.388534,1.005980,-198.607452,0.100685,0.000000
94.410004,59.057152,-198.651932,0.006881,0.003961,0.100598,262.699341,13.382542,1.005980,-198.651932,0.100685,0.000000
94.640007,59.047104,-198.651932,0.006885,0.003961,0.100598,262.654633,13.380265,1.005980,-198.651932,0.100685,0.000000
94.870003,59.024384,-198.651932,0.006868,0.003961,0.100598,262.553558,13.375116,1.005980,-198.651932,0.100685,0.000000
95.100006,59.004654,-198.607452,0.006877,0.003961,0.100598,262.465820,13.370646,1.005980,-198.607452,0.100685,0.000000
95.330002,58.978584,-198.696411,0.006877,0.003961,0.100598,262.349854,13.364738,1.005980,-198.696411,0.100685,0.000000
95.560005,58.962944,-198.607452,0.006894,0.003961,0.100598,262.280273,13.361195,1.005980,-198.607452,0.100685,0.000000
95.790001,58.945816,-198.651932,0.006885,0.003961,0.100598,262.204071,13.357312,1.005980,-198.651932,0.100685,0.000000
96.020004,58.943207,-198.651932,0.006873,0.003961,0.100598,262.192474,13.356722,1.005980,-198.651932,0.100685,0.000000
96.250008,58.926826,-198.651932,0.006873,0.003961,0.100598,262.119629,13.353009,1.005980,-198.651932,0.100685,0.000000
96.480003,58.903366,-198.651932,0.006885,0.003961,0.100598,262.015259,13.347693,1.005980,-198.651932,0.100685,0.000000
96.710007,58.891075,-198.696411,0.006877,0.003961,0.100598,261.960571,13.344909,1.005980,-198.696411,0.100685,0.000000
96.900002,58.881020,-198.651932,0.006873,0.003961,0.100598,261.915863,13.342630,1.005980,-198.651932,0.100685,0.000000