File: Data/compression sample NH 10,12,15/AutoNoheating-12-2-4-240201_02012024_184313.csv
Time (sec),S:Load (lbs),S:HL1 (DIM),S:LVDT (in),S:Position (in),Ch:Position (mm),Ch:Load (N),Ch:Stress (MPa),Ch:Strain (mm/mm),Ch:HL1 (DIM),Set Point (),Cycles ()
0.110000,0.004845,-200.253235,0.000004,-0.000000,-0.000000,0.021550,0.001098,-0.000000,-200.253235,-0.000000,0.000000
0.350000,0.006332,-200.342209,-0.000004,-0.000000,-0.000000,0.028168,0.001435,-0.000000,-200.342209,-0.000000,0.000000
0.590000,-0.003723,-200.342209,-0.000013,0.000095,0.002420,-0.016561,-0.000844,0.024197,-200.342209,0.003365,0.000000
0.830000,0.006706,-200.297729,0.000147,0.000253,0.006435,0.029831,0.001520,0.064351,-200.297729,0.007371,0.000000
1.070000,0.019363,-200.342209,0.000280,0.000398,0.010103,0.086133,0.004388,0.101034,-200.342209,0.011361,0.000000
1.310000,0.016014,-200.386688,0.000461,0.000564,0.014327,0.071234,0.003629,0.143266,-200.386688,0.015367,0.000000
1.550000,-0.019737,-200.297729,0.000595,0.000718,0.018238,-0.087796,-0.004473,0.182379,-200.297729,0.019357,0.000000
1.790000,-0.010429,-200.297729,0.000793,0.000875,0.022218,-0.046392,-0.002363,0.222185,-200.297729,0.023363,0.000000
2.030000,0.021225,-200.342209,0.000949,0.001030,0.026164,0.094413,0.004810,0.261642,-200.342209,0.027370,0.000000
2.270000,-0.005211,-200.386688,0.001117,0.001193,0.030310,-0.023179,-0.001181,0.303098,-200.386688,0.031359,0.000000
2.510000,-0.012657,-200.342209,0.001289,0.001350,0.034282,-0.056302,-0.002868,0.342817,-200.342209,0.035366,0.000000
2.750000,0.003349,-200.342209,0.001436,0.001507,0.038271,0.014898,0.000759,0.382710,-200.342209,0.039355,0.000000
2.990000,0.023087,-200.431168,0.001630,0.001665,0.042286,0.102694,0.005231,0.422860,-200.431168,0.043361,0.000000
3.230000,0.018990,-200.431168,0.001755,0.001822,0.046267,0.084470,0.004303,0.462666,-200.431168,0.047351,0.000000
3.470000,-0.006699,-200.431168,0.001932,0.001977,0.050213,-0.029797,-0.001518,0.502127,-200.431168,0.051357,0.000000
3.710000,0.003723,-200.386688,0.002104,0.002129,0.054089,0.016561,0.000844,0.540892,-200.386688,0.055347,0.000000
3.950000,0.001862,-200.386688,0.002255,0.002291,0.058191,0.008281,0.000422,0.581909,-200.386688,0.059353,0.000000
4.190000,-0.005959,-200.386688,0.002423,0.002445,0.062102,-0.026505,-0.001350,0.621022,-200.386688,0.063342,0.000000
4.430000,-0.002235,-200.386688,0.002578,0.002612,0.066334,-0.009944,-0.000507,0.663341,-200.386688,0.067349,0.000000
4.670000,0.006332,-200.475647,0.002738,0.002763,0.070185,0.028168,0.001435,0.701848,-200.475647,0.071338,0.000000
4.910000,0.011917,-200.386688,0.002936,0.002921,0.074191,0.053010,0.002700,0.741911,-200.386688,0.075345,0.000000
5.150000,0.033890,-200.475647,0.003083,0.003079,0.078207,0.150749,0.007680,0.782065,-200.475647,0.079334,0.000000
5.390000,0.026070,-200.431168,0.003260,0.003240,0.082300,0.115964,0.005907,0.822999,-200.431168,0.083340,0.000000
5.630000,0.005211,-200.431168,0.003410,0.003391,0.086142,0.023179,0.001181,0.861416,-200.431168,0.087330,0.000000
5.870000,0.014526,-200.520126,0.003583,0.003549,0.090148,0.064617,0.003292,0.901483,-200.520126,0.091336,0.000000
6.110000,0.016014,-200.431168,0.003729,0.003705,0.094111,0.071234,0.003629,0.941114,-200.431168,0.095326,0.000000
6.350000,0.010429,-200.520126,0.003898,0.003867,0.098222,0.046392,0.002363,0.982222,-200.520126,0.099332,0.000000
6.590000,-0.031281,-200.431168,0.004074,0.004026,0.102255,-0.139143,-0.007088,1.022546,-200.431168,0.103322,0.000000
6.830000,0.023087,-200.520126,0.004221,0.004182,0.106235,0.102694,0.005231,1.062352,-200.520126,0.107328,0.000000
7.070000,0.031654,-200.564606,0.004406,0.004334,0.110094,0.140806,0.007173,1.100943,-200.564606,0.111335,0.000000
7.310000,0.048035,-200.520126,0.004553,0.004502,0.114344,0.213669,0.010885,1.143440,-200.520126,0.115324,0.000000
7.550000,0.024208,-200.520126,0.004717,0.004656,0.118264,0.107683,0.005486,1.182636,-200.520126,0.119331,0.000000
7.790000,0.009682,-200.475647,0.004876,0.004805,0.122045,0.043066,0.002194,1.220447,-200.475647,0.123320,0.000000
8.030001,0.040588,-200.520126,0.005023,0.004965,0.126104,0.180546,0.009197,1.261036,-200.520126,0.127326,0.000000
8.270000,0.048035,-200.520126,0.005208,0.005124,0.130153,0.213669,0.010885,1.301535,-200.520126,0.131315,0.000000
8.510000,0.350777,-200.564606,0.005381,0.005284,0.134221,1.560333,0.079487,1.342207,-200.564606,0.135322,0.000000
8.750000,0.581276,-200.564606,0.005458,-0.000000,-0.000000,2.585644,0.131719,-0.000000,-200.564606,0.000234,0.000000
8.990001,0.538078,-200.564606,0.005454,-0.000000,-0.000000,2.393492,0.121930,-0.000000,-200.564606,0.000234,0.000000
9.230000,0.558189,-200.520126,0.005471,-0.000000,-0.000000,2.482950,0.126488,-0.000000,-200.520126,0.000321,0.000000
9.470000,0.612556,-200.564606,0.005458,-0.000000,-0.000000,2.724787,0.138807,-0.000000,-200.564606,0.000720,0.000000
9.710000,0.583878,-200.564606,0.005463,0.000005,0.000121,2.597217,0.132309,0.001215,-200.564606,0.001119,0.000000
9.950001,0.726868,-200.609085,0.005476,0.000024,0.000616,3.233269,0.164711,0.006158,-200.609085,0.001518,0.000000
10.190001,0.876564,-200.609085,0.005514,0.000046,0.001180,3.899152,0.198632,0.011798,-200.609085,0.001917,0.000000
10.430000,0.938751,-200.609085,0.005506,0.000057,0.001448,4.175774,0.212724,0.014485,-200.609085,0.002316,0.000000
10.670000,1.005409,-200.564606,0.005514,0.000074,0.001874,4.472284,0.227829,0.018735,-200.564606,0.002715,0.000000
10.910001,1.115257,-200.520126,0.005549,0.000088,0.002229,4.960912,0.252721,0.022289,-200.520126,0.003122,0.000000
11.150001,1.248940,-200.698044,0.005545,0.000105,0.002663,5.555561,0.283014,0.026627,-200.698044,0.003521,0.000000
11.390000,1.351715,-200.564606,0.005605,0.000117,0.002983,6.012729,0.306303,0.029833,-200.564606,0.003920,0.000000
11.630000,1.422089,-200.698044,0.005575,0.000130,0.003296,6.325766,0.322250,0.032955,-200.698044,0.004319,0.000000
11.870001,1.537155,-200.653564,0.005627,0.000143,0.003625,6.837607,0.348324,0.036252,-200.653564,0.004718,0.000000
12.110001,1.699135,-200.698044,0.005618,0.000166,0.004215,7.558129,0.385029,0.042149,-200.698044,0.005117,0.000000
12.350000,1.783661,-200.698044,0.005631,0.000180,0.004579,7.934120,0.404183,0.045790,-200.698044,0.005516,0.000000
12.590000,1.868935,-200.609085,0.005657,0.000197,0.005004,8.313437,0.423507,0.050040,-200.609085,0.005915,0.000000
12.830001,1.992195,-200.742538,0.005683,0.000213,0.005420,8.861727,0.451438,0.054203,-200.742538,0.006322,0.000000
13.070001,2.110237,-200.698044,0.005687,0.000232,0.005889,9.386804,0.478187,0.058885,-200.698044,0.006721,0.000000
13.310000,2.210030,-200.653564,0.005696,0.000247,0.006270,9.830703,0.500800,0.062701,-200.653564,0.007120,0.000000
13.550000,2.192528,-200.698044,0.005708,0.000253,0.006426,9.752851,0.496834,0.064264,-200.698044,0.007519,0.000000
13.790001,2.389511,-200.653564,0.005739,0.000275,0.006973,10.629076,0.541471,0.069725,-200.653564,0.007918,0.000000
14.030001,2.516121,-200.742538,0.005786,0.000294,0.007467,11.192265,0.570161,0.074668,-200.742538,0.008317,0.000000
14.270000,2.580170,-200.653564,0.005782,0.000310,0.007874,11.477168,0.584675,0.078745,-200.653564,0.008716,0.000000
14.510000,2.665070,-200.653564,0.005782,0.000327,0.008308,11.854821,0.603913,0.083082,-200.653564,0.009115,0.000000
14.750001,2.742897,-200.742538,0.005795,0.000341,0.008664,12.201015,0.621549,0.086636,-200.742538,0.009522,0.000000
14.990001,2.855354,-200.609085,0.005846,0.000360,0.009149,12.701250,0.647033,0.091492,-200.609085,0.009921,0.000000
15.230000,2.895943,-200.742538,0.005864,0.000371,0.009418,12.881797,0.656230,0.094183,-200.742538,0.010320,0.000000
15.470000,2.980843,-200.787018,0.005872,0.000385,0.009774,13.259450,0.675469,0.097737,-200.787018,0.010719,0.000000
15.710001,3.116386,-200.742538,0.005881,0.000404,0.010268,13.862379,0.706183,0.102680,-200.742538,0.011118,0.000000
15.950001,3.239265,-200.787018,0.005920,0.000425,0.010806,14.408973,0.734028,0.108059,-200.787018,0.011517,0.000000
16.190001,3.264587,-200.742538,0.005920,0.000442,0.011222,14.521610,0.739766,0.112222,-200.742538,0.011916,0.000000
16.430000,3.213943,-200.831497,0.005946,0.000453,0.011508,14.296334,0.728290,0.115084,-200.831497,0.012315,0.000000
16.670000,3.270172,-200.742538,0.005976,0.000468,0.011890,14.546453,0.741032,0.118899,-200.742538,0.012723,0.000000
16.910002,3.368484,-200.787018,0.005993,0.000485,0.012315,14.983768,0.763310,0.123149,-200.787018,0.013121,0.000000
17.150002,3.476845,-200.742538,0.006032,0.000504,0.012792,15.465778,0.787864,0.127918,-200.742538,0.013520,0.000000
17.390001,3.432159,-200.742538,0.006049,0.000512,0.013009,15.267008,0.777738,0.130087,-200.742538,0.013919,0.000000
17.630001,3.568817,-200.831497,0.006027,0.000533,0.013537,15.874891,0.808706,0.135374,-200.831497,0.014318,0.000000
17.870001,3.566956,-200.787018,0.006092,0.000546,0.013858,15.866611,0.808284,0.138584,-200.787018,0.014717,0.000000
18.110001,3.698402,-200.831497,0.006092,0.000567,0.014405,16.451315,0.838070,0.144049,-200.831497,0.015116,0.000000
18.350000,3.629517,-200.875977,0.006096,0.000579,0.014700,16.144896,0.822460,0.146998,-200.875977,0.015523,0.000000
18.590000,3.662659,-200.787018,0.006135,0.000594,0.015090,16.292320,0.829970,0.150900,-200.787018,0.015922,0.000000
18.830002,3.763199,-200.787018,0.006135,0.000611,0.015532,16.739544,0.852753,0.155321,-200.787018,0.016321,0.000000
19.070002,3.788887,-200.787018,0.006161,0.000627,0.015922,16.853811,0.858574,0.159223,-200.787018,0.016720,0.000000
19.310001,3.787773,-200.831497,0.006170,0.000638,0.016217,16.848856,0.858322,0.162171,-200.831497,0.017119,0.000000
19.550001,3.762077,-200.875977,0.006204,0.000648,0.016469,16.734556,0.852499,0.164688,-200.875977,0.017518,0.000000
19.790001,3.833946,-200.831497,0.006217,0.000664,0.016876,17.054245,0.868785,0.168765,-200.831497,0.017917,0.000000
20.030001,3.974335,-200.920456,0.006222,0.000689,0.017492,17.678724,0.900597,0.174923,-200.920456,0.018316,0.000000
20.270000,3.928528,-200.787018,0.006260,0.000703,0.017856,17.474964,0.890217,0.178564,-200.787018,0.018723,0.000000
20.510000,3.993698,-200.831497,0.006282,0.000723,0.018359,17.764856,0.904985,0.183594,-200.831497,0.019122,0.000000
20.750002,4.013428,-200.875977,0.006316,0.000738,0.018741,17.852617,0.909456,0.187409,-200.875977,0.019521,0.000000
20.990002,4.028702,-200.831497,0.006316,0.000752,0.019096,17.920561,0.912917,0.190963,-200.831497,0.019920,0.000000
21.230001,4.040245,-200.964935,0.006351,0.000763,0.019391,17.971907,0.915533,0.193912,-200.964935,0.020319,0.000000
21.470001,4.032425,-200.875977,0.006347,0.000775,0.019686,17.937122,0.913761,0.196864,-200.875977,0.020718,0.000000
21.710001,4.193283,-200.875977,0.006377,0.000797,0.020250,18.652655,0.950212,0.202499,-200.875977,0.021117,0.000000
21.950001,4.198128,-200.920456,0.006420,0.000813,0.020640,18.674206,0.951309,0.206402,-200.920456,0.021516,0.000000
22.190001,4.185471,-200.875977,0.006416,0.000829,0.021048,18.617903,0.948441,0.210478,-200.875977,0.021924,0.000000
22.430000,4.186211,-201.009415,0.006428,0.000841,0.021369,18.621195,0.948609,0.213688,-201.009415,0.022323,0.000000
22.670002,4.163498,-200.875977,0.006463,0.000855,0.021707,18.520164,0.943462,0.217068,-200.875977,0.022721,0.000000
22.910002,4.306862,-200.964935,0.006476,0.000875,0.022218,19.157879,0.975949,0.222185,-200.964935,0.023120,0.000000
23.150002,4.261055,-200.964935,0.006485,0.000886,0.022513,18.954119,0.965569,0.225133,-200.964935,0.023519,0.000000
23.390001,4.299782,-201.009415,0.006506,0.000902,0.022912,19.126385,0.974344,0.229122,-201.009415,0.023918,0.000000
23.630001,4.455811,-200.964935,0.006536,0.000922,0.023424,19.820435,1.009701,0.234240,-200.964935,0.024317,0.000000
23.870001,4.479271,-200.964935,0.006562,0.000941,0.023910,19.924791,1.015017,0.239096,-200.964935,0.024716,0.000000
24.110001,4.420059,-201.053894,0.006579,0.000955,0.024248,19.661406,1.001600,0.242479,-201.053894,0.025124,0.000000
24.350000,4.435326,-200.964935,0.006597,0.000968,0.024586,19.729313,1.005059,0.245859,-200.964935,0.025523,0.000000
24.590002,4.395111,-201.009415,0.006588,0.000981,0.024916,19.550430,0.995946,0.249156,-201.009415,0.025922,0.000000
24.830002,4.570869,-201.009415,0.006644,0.000999,0.025384,20.332243,1.035774,0.253838,-201.009415,0.026321,0.000000
25.070002,4.469963,-200.964935,0.006653,0.001008,0.025592,19.883389,1.012908,0.255919,-200.964935,0.026719,0.000000
25.310001,4.697105,-201.009415,0.006679,0.001032,0.026225,20.893768,1.064379,0.262252,-201.009415,0.027118,0.000000
25.550001,4.686684,-200.964935,0.006700,0.001048,0.026615,20.847410,1.062018,0.266154,-200.964935,0.027517,0.000000
25.790001,4.747002,-201.009415,0.006709,0.001068,0.027127,21.115719,1.075686,0.271271,-201.009415,0.027916,0.000000
26.030001,4.689659,-201.053894,0.006722,0.001082,0.027491,20.860645,1.062692,0.274912,-201.053894,0.028324,0.000000
26.270000,4.654655,-200.964935,0.006752,0.001094,0.027795,20.704941,1.054760,0.277948,-200.964935,0.028723,0.000000
26.510002,4.637154,-201.098373,0.006752,0.001106,0.028098,20.627090,1.050794,0.280983,-201.098373,0.029122,0.000000
26.750002,4.699715,-201.009415,0.006786,0.001122,0.028497,20.905375,1.064971,0.284972,-201.009415,0.029521,0.000000
26.990002,4.816635,-201.009415,0.006782,0.001140,0.028957,21.425463,1.091465,0.289567,-201.009415,0.029920,0.000000
27.230001,4.822968,-201.053894,0.006808,0.001153,0.029286,21.453630,1.092900,0.292864,-201.053894,0.030319,0.000000
27.470001,4.936913,-201.053894,0.006868,0.001176,0.029859,21.960484,1.118720,0.298587,-201.053894,0.030717,0.000000
27.710001,4.971176,-201.098373,0.006877,0.001191,0.030249,22.112896,1.126485,0.302489,-201.098373,0.031116,0.000000
27.950001,4.932449,-201.053894,0.006864,0.001204,0.030579,21.940630,1.117709,0.305785,-201.053894,0.031524,0.000000
28.190001,4.978622,-201.053894,0.006894,0.001221,0.031004,22.146019,1.128172,0.310036,-201.053894,0.031923,0.000000
28.430002,4.938774,-201.142868,0.006903,0.001232,0.031298,21.968765,1.119142,0.312984,-201.142868,0.032321,0.000000
28.670002,4.979362,-201.142868,0.006954,0.001243,0.031585,22.149311,1.128340,0.315846,-201.142868,0.032720,0.000000
28.910002,5.134644,-201.098373,0.006933,0.001267,0.032174,22.840034,1.163527,0.321743,-201.098373,0.033119,0.000000
29.150002,5.196831,-201.098373,0.006993,0.001282,0.032564,23.116657,1.177619,0.325645,-201.098373,0.033518,0.000000
29.390001,5.180817,-201.142868,0.006993,0.001296,0.032929,23.045424,1.173990,0.329286,-201.142868,0.033917,0.000000
29.630001,5.271301,-201.142868,0.007041,0.001315,0.033397,23.447920,1.194494,0.333972,-201.142868,0.034316,0.000000
29.870001,5.283592,-201.098373,0.007041,0.001330,0.033787,23.502592,1.197279,0.337874,-201.098373,0.034724,0.000000
30.110001,5.289177,-201.187347,0.007054,0.001347,0.034212,23.527433,1.198545,0.342120,-201.187347,0.035123,0.000000
30.350002,5.249710,-201.053894,0.007071,0.001360,0.034550,23.351877,1.189601,0.345504,-201.053894,0.035522,0.000000
30.590002,5.404617,-201.142868,0.007092,0.001379,0.035036,24.040939,1.224704,0.350360,-201.142868,0.035921,0.000000
30.830002,5.334236,-201.142868,0.007136,0.001390,0.035305,23.727867,1.208755,0.353047,-201.142868,0.036319,0.000000
31.070002,5.472755,-201.098373,0.007127,0.001408,0.035765,24.344032,1.240144,0.357646,-201.098373,0.036718,0.000000
31.310001,5.553932,-201.187347,0.007140,0.001425,0.036190,24.705124,1.258539,0.361897,-201.187347,0.037117,0.000000
31.550001,5.685387,-201.142868,0.007174,0.001446,0.036736,25.289864,1.288327,0.367358,-201.142868,0.037525,0.000000
31.790001,5.571434,-201.231827,0.007187,0.001459,0.037048,24.782976,1.262505,0.370481,-201.231827,0.037924,0.000000
32.030003,5.594521,-201.142868,0.007239,0.001473,0.037421,24.885670,1.267736,0.374209,-201.142868,0.038323,0.000000
32.270000,5.593033,-201.187347,0.007235,0.001487,0.037777,24.879053,1.267399,0.377767,-201.187347,0.038722,0.000000
32.510002,5.778107,-201.187347,0.007278,0.001508,0.038314,25.702303,1.309338,0.383141,-201.187347,0.039121,0.000000
32.750000,5.736397,-201.231827,0.007286,0.001521,0.038635,25.516768,1.299886,0.386351,-201.231827,0.039520,0.000000
32.990002,5.695068,-201.231827,0.007265,0.001533,0.038930,25.332930,1.290521,0.389299,-201.231827,0.039919,0.000000
33.230003,5.846619,-201.187347,0.007308,0.001549,0.039346,26.007059,1.324863,0.393463,-201.187347,0.040317,0.000000
33.470001,5.919235,-201.231827,0.007304,0.001567,0.039806,26.330072,1.341318,0.398057,-201.231827,0.040725,0.000000
33.710003,5.934875,-201.276306,0.007325,0.001582,0.040170,26.399645,1.344862,0.401702,-201.276306,0.041124,0.000000
33.950001,6.012329,-201.142868,0.007364,0.001599,0.040604,26.744175,1.362413,0.406036,-201.142868,0.041523,0.000000
34.190002,6.026474,-201.320786,0.007381,0.001612,0.040951,26.807095,1.365619,0.409507,-201.320786,0.041922,0.000000
34.430000,6.180267,-201.231827,0.007424,0.001633,0.041471,27.491201,1.400469,0.414707,-201.231827,0.042321,0.000000
34.670002,5.906570,-201.231827,0.007416,0.001634,0.041497,26.273737,1.338448,0.414968,-201.231827,0.042720,0.000000
34.910000,6.117706,-201.231827,0.007442,0.001656,0.042061,27.212917,1.386292,0.420608,-201.231827,0.043119,0.000000
35.150002,6.238358,-201.231827,0.007450,0.001673,0.042494,27.749599,1.413632,0.424942,-201.231827,0.043518,0.000000
35.390003,6.420074,-201.276306,0.007468,0.001694,0.043032,28.557917,1.454810,0.430320,-201.276306,0.043925,0.000000
35.630001,6.455452,-201.276306,0.007506,0.001712,0.043483,28.715284,1.462826,0.434828,-201.276306,0.044324,0.000000
35.870003,6.464386,-201.276306,0.007511,0.001728,0.043882,28.755026,1.464851,0.438817,-201.276306,0.044723,0.000000
36.110001,6.444649,-201.320786,0.007537,0.001742,0.044255,28.667229,1.460378,0.442549,-201.320786,0.045122,0.000000
36.350002,6.593971,-201.320786,0.007562,0.001760,0.044714,29.331450,1.494215,0.447144,-201.320786,0.045521,0.000000
36.590000,6.497528,-201.276306,0.007562,0.001771,0.044974,28.902449,1.472361,0.449744,-201.276306,0.045920,0.000000
36.830002,6.586899,-201.320786,0.007597,0.001784,0.045321,29.299990,1.492613,0.453215,-201.320786,0.046319,0.000000
37.070004,6.788353,-201.320786,0.007597,0.001806,0.045876,30.196102,1.538263,0.458763,-201.320786,0.046718,0.000000
37.310001,6.943626,-201.320786,0.007653,0.001827,0.046397,30.886793,1.573448,0.463968,-201.320786,0.047125,0.000000
37.550003,6.964485,-201.365265,0.007657,0.001843,0.046813,30.979578,1.578175,0.468131,-201.365265,0.047524,0.000000
37.790001,6.811440,-201.320786,0.007666,0.001855,0.047125,30.298796,1.543494,0.471253,-201.320786,0.047923,0.000000
38.030003,6.909744,-201.320786,0.007675,0.001870,0.047507,30.736078,1.565771,0.475069,-201.320786,0.048322,0.000000
38.270000,7.047150,-201.409744,0.007696,0.001888,0.047958,31.347288,1.596907,0.479576,-201.409744,0.048721,0.000000
38.510002,7.104126,-201.365265,0.007731,0.001903,0.048339,31.600731,1.609818,0.483392,-201.365265,0.049120,0.000000
38.750000,7.033371,-201.320786,0.007731,0.001914,0.048617,31.285997,1.593785,0.486170,-201.320786,0.049519,0.000000
38.990002,7.130562,-201.454224,0.007748,0.001927,0.048955,31.718323,1.615808,0.489550,-201.454224,0.049918,0.000000
39.230003,7.289566,-201.365265,0.007774,0.001949,0.049510,32.425610,1.651839,0.495102,-201.365265,0.050325,0.000000
39.470001,7.498840,-201.320786,0.007804,0.001968,0.049978,33.356506,1.699262,0.499784,-201.320786,0.050724,0.000000
39.710003,7.406113,-201.409744,0.007821,0.001981,0.050325,32.944035,1.678249,0.503251,-201.409744,0.051123,0.000000
39.950001,7.426598,-201.365265,0.007821,0.001994,0.050655,33.035156,1.682891,0.506548,-201.365265,0.051522,0.000000
40.190002,7.613899,-201.454224,0.007851,0.002013,0.051123,33.868317,1.725334,0.511230,-201.454224,0.051921,0.000000
40.430000,7.663055,-201.409744,0.007847,0.002027,0.051487,34.086971,1.736473,0.514874,-201.409744,0.052320,0.000000
40.670002,7.600494,-201.454224,0.007881,0.002037,0.051739,33.808689,1.722297,0.517388,-201.454224,0.052719,0.000000
40.910004,7.707741,-201.454224,0.007903,0.002051,0.052103,34.285744,1.746599,0.521032,-201.454224,0.053118,0.000000
41.150002,7.957970,-201.409744,0.007929,0.002074,0.052676,35.398815,1.803302,0.526755,-201.409744,0.053525,0.000000
41.390003,8.033562,-201.409744,0.007933,0.002087,0.053022,35.735065,1.820431,0.530222,-201.409744,0.053924,0.000000
41.630001,8.117348,-201.365265,0.007972,0.002106,0.053491,36.107765,1.839417,0.534908,-201.365265,0.054323,0.000000
41.870003,8.216774,-201.454224,0.007946,0.002123,0.053915,36.550037,1.861948,0.539155,-201.454224,0.054722,0.000000
42.110001,8.354546,-201.454224,0.007981,0.002140,0.054349,37.162876,1.893167,0.543492,-201.454224,0.055121,0.000000
42.350002,8.393272,-201.498703,0.008019,0.002154,0.054705,37.335140,1.901943,0.547046,-201.498703,0.055520,0.000000
42.590000,8.190331,-201.498703,0.008011,0.002161,0.054896,36.432411,1.855955,0.548957,-201.498703,0.055919,0.000000
42.830002,8.376892,-201.454224,0.008045,0.002177,0.055303,37.262276,1.898231,0.553030,-201.454224,0.056318,0.000000
43.070004,8.731766,-201.498703,0.008075,0.002200,0.055893,38.840836,1.978646,0.558927,-201.498703,0.056725,0.000000
43.310001,8.774216,-201.454224,0.008063,0.002215,0.056248,39.029659,1.988266,0.562485,-201.454224,0.057124,0.000000
43.550003,8.824112,-201.543182,0.008080,0.002229,0.056613,39.251610,1.999572,0.566126,-201.543182,0.057523,0.000000
43.790001,8.855392,-201.543182,0.008106,0.002242,0.056942,39.390755,2.006661,0.569422,-201.543182,0.057922,0.000000
44.030003,8.871773,-201.498703,0.008101,0.002256,0.057298,39.463615,2.010372,0.572976,-201.498703,0.058321,0.000000
44.270000,9.108978,-201.543182,0.008140,0.002272,0.057705,40.518761,2.064124,0.577053,-201.543182,0.058720,0.000000
44.510002,9.257553,-201.498703,0.008166,0.002287,0.058095,41.179653,2.097791,0.580955,-201.498703,0.059119,0.000000
44.750004,9.487305,-201.543182,0.008149,0.002306,0.058564,42.201637,2.149854,0.585641,-201.543182,0.059527,0.000000
44.990002,9.766960,-201.587677,0.008179,0.002327,0.059110,43.445610,2.213225,0.591102,-201.587677,0.059925,0.000000
45.230003,9.763237,-201.498703,0.008188,0.002342,0.059483,43.429047,2.212381,0.594830,-201.498703,0.060324,0.000000
45.470001,9.778130,-201.543182,0.008231,0.002357,0.059856,43.495293,2.215756,0.598562,-201.543182,0.060723,0.000000
45.710003,9.809036,-201.543182,0.008239,0.002369,0.060177,43.632771,2.222759,0.601768,-201.543182,0.061122,0.000000
45.950001,9.804939,-201.543182,0.008235,0.002380,0.060463,43.614548,2.221831,0.604633,-201.543182,0.061521,0.000000
46.190002,10.220139,-201.587677,0.008269,0.002400,0.060949,45.461449,2.315917,0.609489,-201.587677,0.061920,0.000000
46.430000,9.995598,-201.543182,0.008274,0.002405,0.061087,44.462639,2.265035,0.610874,-201.543182,0.062319,0.000000
46.670002,9.616516,-201.676636,0.008269,0.002405,0.061087,42.776402,2.179134,0.610874,-201.676636,0.062727,0.000000
46.910004,10.986107,-201.632156,0.008321,0.002451,0.062267,48.868645,2.489487,0.622668,-201.632156,0.063126,0.000000
47.150002,11.066162,-201.587677,0.008343,0.002470,0.062727,49.224747,2.507628,0.627267,-201.587677,0.063525,0.000000
47.390003,11.028557,-201.676636,0.008360,0.002485,0.063108,49.057472,2.499107,0.631082,-201.676636,0.063923,0.000000
47.630001,10.994301,-201.543182,0.008373,0.002496,0.063394,48.905094,2.491344,0.633943,-201.543182,0.064322,0.000000
47.870003,11.262405,-201.676636,0.008382,0.002514,0.063846,50.097683,2.552097,0.638455,-201.676636,0.064721,0.000000
48.110001,11.419548,-201.632156,0.008399,0.002528,0.064201,50.796688,2.587707,0.642009,-201.632156,0.065120,0.000000
48.350002,11.429604,-201.632156,0.008433,0.002540,0.064513,50.841415,2.589985,0.645132,-201.632156,0.065519,0.000000
48.590004,11.683929,-201.721115,0.008433,0.002557,0.064947,51.972713,2.647616,0.649465,-201.721115,0.065927,0.000000
48.830002,12.181419,-201.587677,0.008481,0.002577,0.065450,54.185661,2.760349,0.654495,-201.587677,0.066326,0.000000
49.070004,12.214188,-201.632156,0.008459,0.002591,0.065823,54.331421,2.767774,0.658227,-201.632156,0.066725,0.000000
49.310001,12.242119,-201.587677,0.008494,0.002604,0.066143,54.455666,2.774104,0.661433,-201.587677,0.067124,0.000000
49.550003,12.499428,-201.587677,0.008498,0.002620,0.066551,55.600231,2.832411,0.665509,-201.587677,0.067523,0.000000
49.790001,12.542992,-201.721115,0.008502,0.002633,0.066872,55.794014,2.842283,0.668719,-201.721115,0.067921,0.000000
50.030003,13.037506,-201.676636,0.008537,0.002652,0.067358,57.993725,2.954341,0.673575,-201.676636,0.068320,0.000000
50.270004,13.283272,-201.721115,0.008558,0.002667,0.067748,59.086945,3.010032,0.677477,-201.721115,0.068719,0.000000
50.510002,13.418816,-201.632156,0.008550,0.002681,0.068104,59.689873,3.040747,0.681035,-201.632156,0.069127,0.000000
50.750004,13.552124,-201.632156,0.008584,0.002695,0.068450,60.282860,3.070955,0.684502,-201.632156,0.069525,0.000000
50.990002,13.842949,-201.721115,0.008601,0.002713,0.068910,61.576511,3.136857,0.689101,-201.721115,0.069924,0.000000
51.230003,14.133400,-201.632156,0.008601,0.002729,0.069318,62.868504,3.202674,0.693177,-201.632156,0.070323,0.000000
51.470001,14.382515,-201.765594,0.008614,0.002746,0.069751,63.976624,3.259125,0.697511,-201.765594,0.070722,0.000000
51.710003,14.460342,-201.765594,0.008636,0.002761,0.070133,64.322815,3.276760,0.701326,-201.765594,0.071121,0.000000
51.950001,14.769783,-201.765594,0.008658,0.002778,0.070549,65.699280,3.346881,0.705489,-201.765594,0.071520,0.000000
52.190002,14.927292,-201.721115,0.008683,0.002789,0.070835,66.399910,3.382573,0.708351,-201.721115,0.071919,0.000000
52.430004,15.510803,-201.721115,0.008705,0.002808,0.071321,68.995499,3.514798,0.713207,-201.721115,0.072327,0.000000
52.670002,15.825089,-201.810074,0.008692,0.002823,0.071711,70.393509,3.586016,0.717109,-201.810074,0.072726,0.000000
52.910004,16.561638,-201.765594,0.008722,0.002848,0.072327,73.669846,3.752921,0.723267,-201.765594,0.073125,0.000000
53.150002,16.381035,-201.765594,0.008731,0.002859,0.072613,72.866486,3.711996,0.726128,-201.765594,0.073523,0.000000
53.390003,16.557541,-201.765594,0.008739,0.002875,0.073029,73.651619,3.751992,0.730292,-201.765594,0.073922,0.000000
53.630001,16.672607,-201.765594,0.008778,0.002888,0.073350,74.163460,3.778067,0.733501,-201.765594,0.074321,0.000000
53.870003,17.443787,-201.810074,0.008770,0.002908,0.073853,77.593842,3.952818,0.738531,-201.810074,0.074720,0.000000
54.110004,17.472458,-201.765594,0.008817,0.002918,0.074113,77.721375,3.959316,0.741132,-201.765594,0.075119,0.000000
54.350002,17.831055,-201.765594,0.008795,0.002934,0.074521,79.316490,4.040575,0.745208,-201.765594,0.075527,0.000000
54.590004,18.155022,-201.810074,0.008800,0.002949,0.074911,80.757568,4.113986,0.749110,-201.810074,0.075926,0.000000
54.830002,18.644691,-201.765594,0.008834,0.002967,0.075371,82.935730,4.224947,0.753709,-201.765594,0.076325,0.000000
55.070004,18.989510,-201.854553,0.008826,0.002983,0.075779,84.469559,4.303084,0.757785,-201.854553,0.076724,0.000000
55.310001,19.427048,-201.854553,0.008869,0.002999,0.076169,86.415825,4.402232,0.761687,-201.854553,0.077123,0.000000
55.550003,19.712654,-201.854553,0.008886,0.003014,0.076550,87.686264,4.466951,0.765503,-201.854553,0.077521,0.000000
55.790001,20.344940,-201.854553,0.008877,0.003032,0.077001,90.498817,4.610229,0.770010,-201.854553,0.077920,0.000000
56.030003,20.466339,-201.810074,0.008886,0.003044,0.077322,91.038826,4.637739,0.773220,-201.810074,0.078319,0.000000
56.270004,20.788811,-201.899033,0.008912,0.003062,0.077773,92.473251,4.710812,0.777732,-201.899033,0.078727,0.000000
56.510002,21.167885,-201.810074,0.008929,0.003077,0.078155,94.159454,4.796711,0.781547,-201.810074,0.079126,0.000000
56.750004,21.946518,-201.899033,0.008955,0.003095,0.078623,97.622986,4.973152,0.786229,-201.899033,0.079525,0.000000
56.990002,22.416077,-201.854553,0.008964,0.003112,0.079039,99.711685,5.079556,0.790392,-201.854553,0.079924,0.000000
57.230003,22.845421,-201.810074,0.008964,0.003127,0.079421,101.621506,5.176847,0.794207,-201.810074,0.080323,0.000000
57.470001,23.164917,-201.899033,0.008964,0.003143,0.079820,103.042694,5.249245,0.798196,-201.899033,0.080722,0.000000
57.710003,23.498566,-201.899033,0.008994,0.003157,0.080184,104.526840,5.324851,0.801838,-201.899033,0.081121,0.000000
57.950005,23.036079,-201.899033,0.008981,0.003159,0.080227,102.469597,5.220050,0.802273,-201.899033,0.081528,0.000000
58.190002,24.410133,-201.899033,0.009007,0.003183,0.080843,108.581696,5.531415,0.808431,-201.899033,0.081927,0.000000
58.430004,24.788834,-201.810074,0.008998,0.003197,0.081207,110.266235,5.617230,0.812072,-201.810074,0.082326,0.000000
58.670002,26.354660,-201.943512,0.009046,0.003226,0.081953,117.231384,5.972051,0.819528,-201.943512,0.082725,0.000000
58.910004,26.709160,-201.899033,0.009084,0.003242,0.082352,118.808273,6.052382,0.823517,-201.899033,0.083124,0.000000
59.150002,26.737457,-201.987991,0.009054,0.003255,0.082673,118.934151,6.058794,0.826727,-201.987991,0.083523,0.000000
59.390003,27.231972,-201.987991,0.009084,0.003271,0.083072,121.133858,6.170853,0.830716,-201.987991,0.083922,0.000000
59.630001,27.966660,-201.943512,0.009071,0.003289,0.083540,124.401917,6.337336,0.835402,-201.943512,0.084321,0.000000
59.870003,28.411644,-201.943512,0.009089,0.003303,0.083896,126.381302,6.438170,0.838956,-201.943512,0.084728,0.000000
60.110004,28.654808,-201.987991,0.009110,0.003315,0.084190,127.462952,6.493272,0.841904,-201.987991,0.085127,0.000000
60.350002,28.887169,-201.943512,0.009119,0.003324,0.084442,128.496552,6.545926,0.844418,-201.943512,0.085526,0.000000
60.590004,30.557632,-202.032486,0.009166,0.003354,0.085179,135.927139,6.924459,0.851791,-202.032486,0.085925,0.000000
60.830002,31.143745,-201.943512,0.009166,0.003367,0.085526,138.534302,7.057274,0.855261,-201.943512,0.086324,0.000000
61.070004,31.468826,-202.121445,0.009149,0.003382,0.085890,139.980331,7.130938,0.858902,-202.121445,0.086723,0.000000
61.310001,31.735069,-201.987991,0.009149,0.003393,0.086185,141.164642,7.191269,0.861851,-201.987991,0.087122,0.000000
61.550003,32.747551,-202.076965,0.009201,0.003413,0.086679,145.668381,7.420701,0.866794,-202.076965,0.087521,0.000000
61.790005,33.273338,-201.987991,0.009179,0.003427,0.087052,148.007202,7.539846,0.870522,-201.987991,0.087928,0.000000
62.030003,33.434578,-201.987991,0.009184,0.003436,0.087286,148.724426,7.576384,0.872865,-201.987991,0.088327,0.000000
62.270004,34.035217,-202.032486,0.009235,0.003451,0.087659,151.396210,7.712491,0.876593,-202.032486,0.088726,0.000000
62.510002,35.008598,-201.987991,0.009205,0.003467,0.088067,155.726028,7.933062,0.880669,-201.987991,0.089125,0.000000
62.750004,36.059807,-202.032486,0.009222,0.003491,0.088683,160.402039,8.171269,0.886827,-202.032486,0.089524,0.000000
62.990002,37.106918,-202.076965,0.009240,0.003507,0.089082,165.059814,8.408548,0.890817,-202.076965,0.089923,0.000000
63.230003,37.785378,-202.032486,0.009253,0.003522,0.089463,168.077759,8.562289,0.894632,-202.032486,0.090322,0.000000
63.470001,38.558426,-202.121445,0.009240,0.003540,0.089923,171.516449,8.737465,0.899227,-202.121445,0.090721,0.000000
63.710003,39.057404,-201.987991,0.009274,0.003553,0.090244,173.736008,8.850534,0.902436,-201.987991,0.091128,0.000000
63.950005,39.274872,-202.032486,0.009270,0.003563,0.090512,174.703354,8.899813,0.905124,-202.032486,0.091527,0.000000
64.190002,39.817413,-202.032486,0.009296,0.003576,0.090842,177.116699,9.022755,0.908420,-202.032486,0.091926,0.000000
64.430000,41.487877,-202.032486,0.009296,0.003601,0.091458,184.547287,9.401287,0.914578,-202.032486,0.092325,0.000000
64.670006,42.040482,-202.076965,0.009321,0.003614,0.091796,187.005402,9.526509,0.917962,-202.076965,0.092724,0.000000
64.910004,42.601273,-202.032486,0.009300,0.003628,0.092143,189.499924,9.653586,0.921429,-202.032486,0.093123,0.000000
65.150002,43.229462,-202.121445,0.009321,0.003641,0.092481,192.294250,9.795936,0.924813,-202.121445,0.093522,0.000000
65.389999,43.928032,-202.076965,0.009330,0.003657,0.092897,195.401642,9.954234,0.928972,-202.076965,0.093921,0.000000
65.630005,44.958389,-202.076965,0.009339,0.003673,0.093288,199.984909,10.187716,0.932878,-202.076965,0.094328,0.000000
65.870003,45.754150,-202.121445,0.009360,0.003686,0.093617,203.524628,10.368039,0.936171,-202.121445,0.094727,0.000000
66.110001,46.863075,-202.121445,0.009360,0.003705,0.094103,208.457367,10.619325,0.941027,-202.121445,0.095126,0.000000
66.350006,48.430016,-202.165924,0.009365,0.003728,0.094684,215.427475,10.974398,0.946837,-202.165924,0.095525,0.000000
66.590004,49.200455,-202.076965,0.009365,0.003742,0.095048,218.854553,11.148982,0.950482,-202.076965,0.095924,0.000000
66.830002,49.877060,-202.121445,0.009378,0.003756,0.095404,221.864243,11.302303,0.954036,-202.121445,0.096323,0.000000
67.070000,50.434868,-202.165924,0.009386,0.003769,0.095725,224.345490,11.428704,0.957245,-202.165924,0.096722,0.000000
67.310005,50.920074,-202.121445,0.009390,0.003779,0.095993,226.503799,11.538654,0.959933,-202.121445,0.097121,0.000000
67.550003,52.198799,-202.121445,0.009403,0.003798,0.096471,232.191849,11.828417,0.964705,-202.121445,0.097528,0.000000
67.790001,52.726082,-202.165924,0.009416,0.003812,0.096817,234.537323,11.947901,0.968172,-202.165924,0.097927,0.000000
68.030006,54.414787,-202.165924,0.009399,0.003833,0.097355,242.049057,12.330566,0.973551,-202.165924,0.098326,0.000000
68.270004,55.637283,-202.165924,0.009434,0.003852,0.097832,247.487000,12.607588,0.978320,-202.165924,0.098725,0.000000
68.510002,56.784195,-202.165924,0.009455,0.003868,0.098240,252.588715,12.867482,0.982396,-202.165924,0.099124,0.000000
68.750000,57.587402,-202.210403,0.009455,0.003883,0.098630,256.161560,13.049492,0.986298,-202.210403,0.099523,0.000000
68.990005,58.188408,-202.254883,0.009438,0.003894,0.098907,258.834961,13.185681,0.989073,-202.254883,0.099922,0.000000
69.230003,59.020660,-202.165924,0.009455,0.003911,0.099350,262.537018,13.374272,0.993497,-202.165924,0.100321,0.000000
69.470001,60.273323,-202.210403,0.009442,0.003925,0.099705,268.109131,13.658131,0.997051,-202.210403,0.100729,0.000000
69.710007,61.025520,-202.254883,0.009472,0.003939,0.100061,271.455078,13.828581,1.000605,-202.254883,0.101127,0.000000
69.950005,61.977676,-202.299362,0.009481,0.003955,0.100459,275.690460,14.044342,1.004594,-202.299362,0.101526,0.000000
70.190002,63.668251,-202.254883,0.009481,0.003975,0.100971,283.210510,14.427432,1.009712,-202.254883,0.101925,0.000000
70.430000,64.659874,-202.299362,0.009468,0.003990,0.101336,287.621490,14.652137,1.013356,-202.299362,0.102324,0.000000
70.670006,65.341316,-202.210403,0.009477,0.004002,0.101656,290.652679,14.806554,1.016562,-202.210403,0.102723,0.000000
70.910004,66.614830,-202.254883,0.009490,0.004019,0.102081,296.317566,15.095137,1.020813,-202.254883,0.103122,0.000000
71.150002,67.344673,-202.299362,0.009516,0.004031,0.102394,299.564056,15.260521,1.023935,-202.299362,0.103530,0.000000
71.390007,67.387505,-202.299362,0.009507,0.004027,0.102281,299.754578,15.270226,1.022807,-202.299362,0.102558,0.000000
71.630005,66.855003,-202.299362,0.009520,0.004027,0.102281,297.385895,15.149560,1.022807,-202.299362,0.102558,0.000000
71.870003,66.474068,-202.343842,0.009524,0.004024,0.102211,295.691406,15.063239,1.022115,-202.343842,0.102281,0.000000
72.110001,66.064461,-202.254883,0.009524,0.004023,0.102194,293.869385,14.970421,1.021941,-202.254883,0.102281,0.000000
72.350006,65.726723,-202.343842,0.009516,0.004023,0.102185,292.367065,14.893888,1.021854,-202.343842,0.102281,0.000000
72.590004,65.409462,-202.299362,0.009546,0.004023,0.102177,290.955811,14.821997,1.021766,-202.299362,0.102281,0.000000
72.830002,65.131660,-202.299362,0.009511,0.004023,0.102177,289.720093,14.759045,1.021766,-202.299362,0.102281,0.000000
73.070000,64.869896,-202.343842,0.009533,0.004023,0.102177,288.555695,14.699728,1.021766,-202.343842,0.102281,0.000000
73.310005,64.656151,-202.254883,0.009524,0.004022,0.102168,287.604919,14.651293,1.021679,-202.254883,0.102281,0.000000
73.550003,64.439430,-202.388321,0.009524,0.004022,0.102168,286.640900,14.602183,1.021679,-202.388321,0.102281,0.000000
73.790001,64.246162,-202.343842,0.009541,0.004022,0.102168,285.781189,14.558389,1.021679,-202.343842,0.102281,0.000000
74.030006,64.069664,-202.388321,0.009528,0.004022,0.102168,284.996094,14.518394,1.021679,-202.388321,0.102281,0.000000
74.270004,63.900978,-202.388321,0.009559,0.004022,0.102168,284.245758,14.480168,1.021679,-202.388321,0.102281,0.000000
74.510002,63.747185,-202.299362,0.009563,0.004022,0.102168,283.561646,14.445318,1.021679,-202.299362,0.102281,0.000000
74.750000,63.594887,-202.388321,0.009550,0.004022,0.102168,282.884186,14.410808,1.021679,-202.388321,0.102281,0.000000
74.990005,63.470146,-202.343842,0.009533,0.004022,0.102168,282.329315,14.382542,1.021679,-202.343842,0.102281,0.000000
75.230003,63.334602,-202.343842,0.009537,0.004022,0.102168,281.726379,14.351826,1.021679,-202.343842,0.102281,0.000000
75.470001,63.220650,-202.343842,0.009528,0.004022,0.102168,281.219482,14.326004,1.021679,-202.343842,0.102281,0.000000
75.710007,63.097397,-202.388321,0.009524,0.004022,0.102168,280.671234,14.298075,1.021679,-202.388321,0.102281,0.000000
75.950005,62.984200,-202.477295,0.009524,0.004022,0.102168,280.167725,14.272424,1.021679,-202.477295,0.102281,0.000000
76.190002,62.873230,-202.432816,0.009533,0.004022,0.102168,279.674103,14.247277,1.021679,-202.432816,0.102281,0.000000
76.430000,62.776787,-202.432816,0.009550,0.004022,0.102159,279.245087,14.225423,1.021592,-202.432816,0.102281,0.000000
76.670006,62.685555,-202.388321,0.009554,0.004022,0.102159,278.839264,14.204749,1.021592,-202.388321,0.102281,0.000000
76.910004,62.592087,-202.388321,0.009541,0.004022,0.102159,278.423492,14.183570,1.021592,-202.388321,0.102281,0.000000
77.150002,62.523575,-202.477295,0.009533,0.004022,0.102159,278.118744,14.168045,1.021592,-202.477295,0.102281,0.000000
77.390007,62.424889,-202.432816,0.009541,0.004022,0.102159,277.679779,14.145682,1.021592,-202.432816,0.102281,0.000000
77.630005,62.350792,-202.477295,0.009554,0.004022,0.102159,277.350189,14.128891,1.021592,-202.477295,0.102281,0.000000
77.870003,62.265144,-202.477295,0.009572,0.004022,0.102159,276.969208,14.109484,1.021592,-202.477295,0.102281,0.000000
78.110001,62.193275,-202.432816,0.009550,0.004022,0.102159,276.649506,14.093198,1.021592,-202.432816,0.102281,0.000000
78.350006,62.121033,-202.566254,0.009559,0.004022,0.102159,276.328156,14.076828,1.021592,-202.566254,0.102281,0.000000
78.590004,62.046562,-202.477295,0.009567,0.004022,0.102159,275.996887,14.059952,1.021592,-202.477295,0.102281,0.000000
78.830002,61.994431,-202.521774,0.009546,0.004022,0.102159,275.765015,14.048139,1.021592,-202.521774,0.102281,0.000000
79.070007,61.903572,-202.521774,0.009537,0.004022,0.102159,275.360840,14.027550,1.021592,-202.521774,0.102281,0.000000
79.310005,61.863724,-202.521774,0.009554,0.004022,0.102159,275.183594,14.018520,1.021592,-202.521774,0.102281,0.000000
79.550003,61.791115,-202.566254,0.009533,0.004022,0.102159,274.860596,14.002067,1.021592,-202.566254,0.102281,0.000000
79.790001,61.744942,-202.477295,0.009550,0.004022,0.102159,274.655212,13.991604,1.021592,-202.477295,0.102281,0.000000
80.030006,61.676796,-202.477295,0.009576,0.004022,0.102159,274.352081,13.976162,1.021592,-202.477295,0.102281,0.000000
80.270004,61.633598,-202.477295,0.009546,0.004022,0.102159,274.159943,13.966373,1.021592,-202.477295,0.102281,0.000000
80.510002,61.565086,-202.566254,0.009546,0.004022,0.102159,273.855194,13.950849,1.021592,-202.566254,0.102281,0.000000
80.750008,61.506622,-202.477295,0.009559,0.004022,0.102159,273.595123,13.937600,1.021592,-202.477295,0.102281,0.000000
80.990005,61.464546,-202.477295,0.009559,0.004022,0.102159,273.407959,13.928065,1.021592,-202.477295,0.102281,0.000000
81.230003,61.397514,-202.566254,0.009563,0.004022,0.102159,273.109772,13.912876,1.021592,-202.566254,0.102281,0.000000
81.470001,61.357300,-202.566254,0.009541,0.004022,0.102159,272.930908,13.903763,1.021592,-202.566254,0.102281,0.000000
81.710007,61.305916,-202.566254,0.009572,0.004022,0.102159,272.702332,13.892119,1.021592,-202.566254,0.102281,0.000000
81.950005,61.261604,-202.566254,0.009533,0.004022,0.102159,272.505219,13.882078,1.021592,-202.566254,0.102281,0.000000
82.190002,61.209099,-202.566254,0.009537,0.004022,0.102159,272.271667,13.870180,1.021592,-202.566254,0.102281,0.000000
82.430000,61.160316,-202.610733,0.009559,0.004022,0.102159,272.054687,13.859126,1.021592,-202.610733,0.102281,0.000000
82.670006,61.122704,-202.566254,0.009559,0.004022,0.102159,271.887360,13.850602,1.021592,-202.566254,0.102281,0.000000
82.910004,61.081001,-202.610733,0.009563,0.004022,0.102159,271.701874,13.841153,1.021592,-202.610733,0.102281,0.000000
83.150002,61.037064,-202.655212,0.009567,0.004022,0.102159,271.506409,13.831197,1.021592,-202.655212,0.102281,0.000000
83.390007,60.984558,-202.521774,0.009550,0.004022,0.102159,271.272858,13.819299,1.021592,-202.521774,0.102281,0.000000
83.630005,60.963333,-202.610733,0.009537,0.004022,0.102159,271.178436,13.814488,1.021592,-202.610733,0.102281,0.000000
83.870003,60.902260,-202.655212,0.009589,0.004022,0.102159,270.906769,13.800650,1.021592,-202.655212,0.102281,0.000000
84.110001,60.873589,-202.610733,0.009541,0.004022,0.102159,270.779236,13.794152,1.021592,-202.610733,0.102281,0.000000
84.350006,60.818848,-202.699692,0.009572,0.004022,0.102159,270.535736,13.781748,1.021592,-202.699692,0.102281,0.000000
84.590004,60.797997,-202.566254,0.009563,0.004022,0.102159,270.442993,13.777023,1.021592,-202.566254,0.102281,0.000000
84.830002,60.750710,-202.699692,0.009554,0.004022,0.102159,270.232666,13.766308,1.021592,-202.699692,0.102281,0.000000
85.070007,60.722404,-202.655212,0.009546,0.004022,0.102159,270.106750,13.759893,1.021592,-202.655212,0.102281,0.000000
85.310005,60.694107,-202.610733,0.009550,0.004022,0.102159,269.980865,13.753482,1.021592,-202.610733,0.102281,0.000000
85.550003,60.653145,-202.699692,0.009563,0.004022,0.102159,269.798676,13.744199,1.021592,-202.699692,0.102281,0.000000
85.790001,60.613670,-202.610733,0.009559,0.004022,0.102159,269.623077,13.735254,1.021592,-202.610733,0.102281,0.000000
86.030006,60.572708,-202.610733,0.009554,0.004022,0.102159,269.440857,13.725971,1.021592,-202.610733,0.102281,0.000000
86.270004,60.543297,-202.655212,0.009541,0.004022,0.102159,269.310028,13.719307,1.021592,-202.655212,0.102281,0.000000
86.510002,60.505310,-202.610733,0.009537,0.004022,0.102159,269.141052,13.710699,1.021592,-202.610733,0.102281,0.000000
86.750008,60.479988,-202.699692,0.009585,0.004022,0.102159,269.028412,13.704961,1.021592,-202.699692,0.102281,0.000000
86.990005,60.443497,-202.655212,0.009576,0.004022,0.102159,268.866089,13.696692,1.021592,-202.655212,0.102281,0.000000
87.230003,60.414078,-202.699692,0.009541,0.004022,0.102159,268.735229,13.690025,1.021592,-202.699692,0.102281,0.000000
87.470001,60.386528,-202.655212,0.009585,0.004022,0.102159,268.612701,13.683783,1.021592,-202.655212,0.102281,0.000000
87.710007,60.347427,-202.699692,0.009572,0.004022,0.102159,268.438751,13.674923,1.021592,-202.699692,0.102281,0.000000
87.950005,60.336624,-202.788651,0.009567,0.004022,0.102159,268.390717,13.672474,1.021592,-202.788651,0.102281,0.000000
88.190002,60.296783,-202.699692,0.009550,0.004022,0.102159,268.213501,13.663446,1.021592,-202.699692,0.102281,0.000000
88.430008,60.276672,-202.744171,0.009546,0.004022,0.102159,268.124023,13.658889,1.021592,-202.744171,0.102281,0.000000
88.670006,60.246513,-202.788651,0.009554,0.004022,0.102159,267.989868,13.652055,1.021592,-202.788651,0.102281,0.000000
88.910004,60.216354,-202.744171,0.009559,0.004022,0.102159,267.855713,13.645221,1.021592,-202.744171,0.102281,0.000000
89.150002,60.184700,-202.788651,0.009554,0.004022,0.102159,267.714905,13.638048,1.021592,-202.788651,0.102281,0.000000
89.390007,60.150070,-202.744171,0.009559,0.004022,0.102151,267.560883,13.630200,1.021505,-202.744171,0.102281,0.000000
89.630005,60.149323,-202.788651,0.009572,0.004022,0.102151,267.557556,13.630032,1.021505,-202.788651,0.102281,0.000000
89.870003,60.109856,-202.744171,0.009567,0.004022,0.102151,267.381989,13.621088,1.021505,-202.744171,0.102281,0.000000
90.110001,60.083786,-202.833130,0.009546,0.004022,0.102151,267.266022,13.615180,1.021505,-202.833130,0.102281,0.000000
90.350006,60.061813,-202.744171,0.009585,0.004022,0.102151,267.168274,13.610202,1.021505,-202.744171,0.102281,0.000000
90.590004,60.029793,-202.833130,0.009554,0.004022,0.102151,267.025848,13.602945,1.021505,-202.833130,0.102281,0.000000
90.830002,60.010803,-202.788651,0.009550,0.004022,0.102151,266.941376,13.598642,1.021505,-202.788651,0.102281,0.000000
91.070007,59.978409,-202.788651,0.009567,0.004022,0.102151,266.797302,13.591302,1.021505,-202.788651,0.102281,0.000000
91.310005,59.965370,-202.788651,0.009576,0.004022,0.102151,266.739288,13.588347,1.021505,-202.788651,0.102281,0.000000
91.550003,59.931114,-202.788651,0.009567,0.004022,0.102151,266.586914,13.580585,1.021505,-202.788651,0.102281,0.000000
91.790001,59.921806,-202.833130,0.009567,0.004022,0.102151,266.545502,13.578475,1.021505,-202.833130,0.102281,0.000000
92.030006,59.886803,-202.922104,0.009559,0.004022,0.102151,266.389801,13.570543,1.021505,-202.922104,0.102281,0.000000
92.270004,59.875259,-202.833130,0.009572,0.004022,0.102151,266.338470,13.567928,1.021505,-202.833130,0.102281,0.000000
92.510002,59.852547,-202.922104,0.009563,0.004022,0.102151,266.237427,13.562780,1.021505,-202.922104,0.102281,0.000000
92.750008,59.840256,-202.833130,0.009559,0.004022,0.102151,266.182739,13.559997,1.021505,-202.833130,0.102281,0.000000
92.990005,59.813072,-202.833130,0.009563,0.004022,0.102151,266.061829,13.553836,1.021505,-202.833130,0.102281,0.000000
93.230003,59.790733,-202.922104,0.009563,0.004022,0.102151,265.962463,13.548774,1.021505,-202.922104,0.102281,0.000000
93.470001,59.768013,-202.833130,0.009572,0.004022,0.102151,265.861389,13.543625,1.021505,-202.833130,0.102281,0.000000
93.710007,59.749023,-202.922104,0.009563,0.004022,0.102151,265.776917,13.539322,1.021505,-202.922104,0.102281,0.000000
93.950005,59.738594,-202.877625,0.009550,0.004022,0.102151,265.730530,13.536959,1.021505,-202.877625,0.102281,0.000000
94.190002,59.719231,-202.877625,0.009567,0.004022,0.102151,265.644409,13.532571,1.021505,-202.877625,0.102281,0.000000
94.430008,59.692421,-202.922104,0.009554,0.004022,0.102151,265.525146,13.526496,1.021505,-202.922104,0.102281,0.000000
94.670006,59.667099,-202.788651,0.009550,0.004022,0.102151,265.412506,13.520758,1.021505,-202.788651,0.102281,0.000000
94.910004,59.656677,-202.966583,0.009576,0.004022,0.102151,265.366150,13.518396,1.021505,-202.966583,0.102281,0.000000
95.150002,59.633217,-202.922104,0.009563,0.004022,0.102151,265.261810,13.513080,1.021505,-202.922104,0.102281,0.000000
95.390007,59.614227,-202.922104,0.009572,0.004022,0.102151,265.177338,13.508777,1.021505,-202.922104,0.102281,0.000000
95.630005,59.599327,-203.011063,0.009550,0.004022,0.102151,265.111053,13.505401,1.021505,-203.011063,0.102281,0.000000
95.870003,59.581825,-202.922104,0.009580,0.004022,0.102151,265.033203,13.501434,1.021505,-202.922104,0.102281,0.000000
96.110008,59.572891,-202.922104,0.009580,0.004022,0.102151,264.993469,13.499411,1.021505,-202.922104,0.102281,0.000000
96.350006,59.542732,-202.966583,0.009572,0.004022,0.102151,264.859314,13.492577,1.021505,-202.966583,0.102281,0.000000
96.590004,59.547195,-202.966583,0.009559,0.004022,0.102151,264.879150,13.493587,1.021505,-202.966583,0.102281,0.000000
96.830002,59.524857,-203.011063,0.009572,0.004022,0.102151,264.779785,13.488525,1.021505,-203.011063,0.102281,0.000000
97.070007,59.503258,-202.966583,0.009546,0.004022,0.102151,264.683716,13.483631,1.021505,-202.966583,0.102281,0.000000
97.310005,59.481285,-203.055542,0.009550,0.004022,0.102151,264.585968,13.478652,1.021505,-203.055542,0.102281,0.000000
97.550003,59.469002,-203.011063,0.009576,0.004022,0.102151,264.531342,13.475868,1.021505,-203.011063,0.102281,0.000000
97.790001,59.457085,-202.966583,0.009576,0.004022,0.102151,264.478333,13.473167,1.021505,-202.966583,0.102281,0.000000
98.030006,59.436600,-203.011063,0.009559,0.004022,0.102151,264.387207,13.468526,1.021505,-203.011063,0.102281,0.000000
98.270004,59.425056,-202.966583,0.009559,0.004022,0.102151,264.335846,13.465910,1.021505,-202.966583,0.102281,0.000000
98.510002,59.405327,-203.055542,0.009567,0.004022,0.102151,264.248077,13.461439,1.021505,-203.055542,0.102281,0.000000
98.750008,59.395645,-203.011063,0.009572,0.004022,0.102151,264.205017,13.459246,1.021505,-203.011063,0.102281,0.000000
98.990005,59.366226,-202.966583,0.009546,0.004022,0.102151,264.074158,13.452579,1.021505,-202.966583,0.102281,0.000000
99.230003,59.369202,-203.055542,0.009559,0.004022,0.102151,264.087402,13.453253,1.021505,-203.055542,0.102281,0.000000
99.470001,59.349838,-203.055542,0.009580,0.004022,0.102151,264.001251,13.448866,1.021505,-203.055542,0.102281,0.000000
99.710007,59.342392,-203.055542,0.009550,0.004022,0.102151,263.968140,13.447178,1.021505,-203.055542,0.102281,0.000000
99.950005,59.314835,-203.055542,0.009563,0.004022,0.102151,263.845551,13.440934,1.021505,-203.055542,0.102281,0.000000
100.190002,59.318558,-203.055542,0.009563,0.004022,0.102151,263.862122,13.441777,1.021505,-203.055542,0.102281,0.000000
100.430008,59.294357,-203.055542,0.009559,0.004022,0.102151,263.754486,13.436294,1.021505,-203.055542,0.102281,0.000000
100.670006,59.267174,-203.011063,0.009580,0.004022,0.102151,263.633545,13.430133,1.021505,-203.011063,0.102281,0.000000
100.910004,59.261215,-203.100021,0.009537,0.004022,0.102151,263.607056,13.428783,1.021505,-203.100021,0.102281,0.000000
101.150002,59.232918,-203.055542,0.009546,0.004022,0.102151,263.481171,13.422371,1.021505,-203.055542,0.102281,0.000000
101.390007,59.229935,-203.100021,0.009541,0.004022,0.102151,263.467896,13.421695,1.021505,-203.100021,0.102281,0.000000
101.630005,59.198654,-203.144501,0.009576,0.004022,0.102151,263.328766,13.414606,1.021505,-203.144501,0.102281,0.000000
101.800003,59.204987,-203.100021,0.009559,0.004022,0.102151,263.356934,13.416041,1.021505,-203.100021,0.102281,0.000000