File: Data/compression sample NH 10,12,15/AutoNoheating-10-2-3-240201_02012024_191401.csv
Time (sec),S:Load (lbs),S:HL1 (DIM),S:LVDT (in),S:Position (in),Ch:Position (mm),Ch:Load (N),Ch:Stress (MPa),Ch:Strain (mm/mm),Ch:HL1 (DIM),Set Point (),Cycles ()
0.110000,-0.021965,-248.648514,0.000043,-0.000000,-0.000009,-0.097705,-0.004977,-0.000087,-248.648514,0.000217,0.000000
0.370000,0.008194,-248.648514,0.000000,0.000014,0.000364,0.036449,0.001857,0.003641,-248.648514,0.001032,0.000000
0.630000,0.018250,-248.604034,0.000017,0.000168,0.004267,0.081178,0.004135,0.042667,-248.604034,0.005368,0.000000
0.890000,-0.035370,-248.737473,0.000198,0.000341,0.008664,-0.157333,-0.008015,0.086636,-248.737473,0.009704,0.000000
1.150000,-0.004837,-248.648514,0.000392,0.000514,0.013043,-0.021516,-0.001096,0.130431,-248.648514,0.014023,0.000000
1.410000,-0.008186,-248.737473,0.000586,0.000676,0.017180,-0.036415,-0.001855,0.171796,-248.737473,0.018359,0.000000
1.670000,-0.048775,-248.692993,0.000742,0.000851,0.021611,-0.216961,-0.011053,0.216110,-248.692993,0.022695,0.000000
1.930000,-0.002602,-248.692993,0.000901,0.001020,0.025913,-0.011573,-0.000590,0.259125,-248.692993,0.027014,0.000000
2.190000,-0.032768,-248.737473,0.001074,0.001185,0.030110,-0.145760,-0.007425,0.301100,-248.737473,0.031350,0.000000
2.450000,-0.009682,-248.648514,0.001255,0.001360,0.034541,-0.043066,-0.002194,0.345413,-248.648514,0.035686,0.000000
2.710000,0.004845,-248.604034,0.001470,0.001530,0.038869,0.021550,0.001098,0.388690,-248.604034,0.040022,0.000000
2.970000,0.021599,-248.692993,0.001600,0.001704,0.043283,0.096076,0.004894,0.432833,-248.692993,0.044341,0.000000
3.230000,-0.005951,-248.737473,0.001807,0.001875,0.047637,-0.026471,-0.001348,0.476367,-248.737473,0.048677,0.000000
3.490000,-0.008186,-248.737473,0.002026,0.002041,0.051851,-0.036415,-0.001855,0.518512,-248.737473,0.053014,0.000000
3.750000,-0.012283,-248.692993,0.002139,0.002216,0.056274,-0.054639,-0.002783,0.562742,-248.692993,0.057349,0.000000
4.010000,-0.049149,-248.737473,0.002320,0.002383,0.060523,-0.218624,-0.011137,0.605235,-248.737473,0.061668,0.000000
4.270000,-0.009308,-248.781952,0.002483,0.002553,0.064842,-0.041403,-0.002109,0.648424,-248.781952,0.066004,0.000000
4.530000,0.015640,-248.737473,0.002690,0.002729,0.069309,0.069571,0.003544,0.693086,-248.737473,0.070341,0.000000
4.790000,-0.025314,-248.737473,0.002846,0.002897,0.073584,-0.112604,-0.005736,0.735840,-248.737473,0.074677,0.000000
5.050000,0.020859,-248.737473,0.003040,0.003068,0.077929,0.092784,0.004727,0.779287,-248.737473,0.078996,0.000000
5.310000,0.067032,-248.737473,0.003216,0.003239,0.082282,0.298173,0.015190,0.822821,-248.737473,0.083332,0.000000
5.570000,0.476639,-248.781952,0.003385,0.003403,0.086445,2.120195,0.108008,0.864451,-248.781952,0.087668,0.000000
5.830000,0.579041,-248.737473,0.003449,0.000003,0.000078,2.575701,0.131212,0.000780,-248.737473,0.000304,0.000000
6.090000,0.547020,-248.781952,0.003432,0.000003,0.000078,2.433266,0.123956,0.000780,-248.781952,0.000304,0.000000
6.350000,0.522812,-248.781952,0.003449,0.000003,0.000078,2.325583,0.118471,0.000780,-248.781952,0.000659,0.000000
6.610000,0.536591,-248.737473,0.003454,0.000003,0.000078,2.386874,0.121593,0.000780,-248.737473,0.001093,0.000000
6.870000,0.531754,-248.826447,0.003441,0.000003,0.000078,2.365358,0.120497,0.000780,-248.826447,0.001526,0.000000
7.130000,0.701180,-248.781952,0.003454,0.000033,0.000850,3.119002,0.158890,0.008497,-248.781952,0.001951,0.000000
7.390000,0.865028,-248.870926,0.003497,0.000064,0.001621,3.847838,0.196018,0.016214,-248.870926,0.002385,0.000000
7.650001,0.921249,-248.826447,0.003518,0.000077,0.001951,4.097922,0.208758,0.019511,-248.826447,0.002818,0.000000
7.910000,0.989769,-248.781952,0.003527,0.000094,0.002376,4.402712,0.224285,0.023762,-248.781952,0.003252,0.000000
8.170000,1.034828,-248.870926,0.003557,0.000107,0.002714,4.603146,0.234495,0.027141,-248.870926,0.003686,0.000000
8.430000,1.145050,-248.826447,0.003544,0.000123,0.003122,5.093437,0.259472,0.031218,-248.826447,0.004119,0.000000
8.690001,1.206490,-248.915405,0.003561,0.000138,0.003504,5.366734,0.273394,0.035037,-248.915405,0.004553,0.000000
8.950001,1.333839,-248.870926,0.003613,0.000160,0.004059,5.933214,0.302252,0.040585,-248.870926,0.004987,0.000000
9.210000,1.436989,-248.826447,0.003600,0.000182,0.004613,6.392045,0.325626,0.046134,-248.826447,0.005420,0.000000
9.470000,1.479813,-248.870926,0.003652,0.000197,0.005004,6.582535,0.335330,0.050036,-248.870926,0.005854,0.000000
9.730000,1.561363,-248.870926,0.003617,0.000213,0.005403,6.945291,0.353810,0.054026,-248.870926,0.006287,0.000000
9.990001,1.606049,-248.870926,0.003648,0.000227,0.005758,7.144061,0.363936,0.057583,-248.870926,0.006721,0.000000
10.250001,1.756859,-248.915405,0.003665,0.000248,0.006296,7.814898,0.398110,0.062958,-248.915405,0.007155,0.000000
10.510000,1.829842,-248.915405,0.003669,0.000262,0.006652,8.139542,0.414648,0.066516,-248.915405,0.007588,0.000000
10.770000,1.863358,-248.959885,0.003682,0.000277,0.007024,8.288629,0.422243,0.070244,-248.959885,0.008022,0.000000
11.030001,1.997406,-248.870926,0.003738,0.000295,0.007501,8.884906,0.452619,0.075013,-248.870926,0.008455,0.000000
11.290001,2.117310,-248.915405,0.003747,0.000314,0.007987,9.418263,0.479789,0.079869,-248.915405,0.008889,0.000000
11.550000,2.137047,-248.915405,0.003721,0.000329,0.008351,9.506059,0.484262,0.083514,-248.915405,0.009323,0.000000
11.810000,2.224556,-248.870926,0.003747,0.000347,0.008811,9.895319,0.504092,0.088109,-248.870926,0.009756,0.000000
12.070001,2.292328,-248.959885,0.003786,0.000363,0.009210,10.196784,0.519449,0.092098,-248.959885,0.010190,0.000000
12.330001,2.460266,-248.915405,0.003798,0.000384,0.009748,10.943810,0.557504,0.097476,-248.915405,0.010623,0.000000
12.590000,2.516869,-248.915405,0.003807,0.000399,0.010147,11.195591,0.570331,0.101465,-248.915405,0.011057,0.000000
12.850000,2.546288,-248.915405,0.003820,0.000412,0.010468,11.326452,0.576997,0.104675,-248.915405,0.011491,0.000000
13.110001,2.731354,-248.959885,0.003863,0.000437,0.011092,12.149669,0.618934,0.110916,-248.959885,0.011924,0.000000
13.370001,2.781250,-249.004364,0.003867,0.000453,0.011517,12.371618,0.630240,0.115167,-249.004364,0.012358,0.000000
13.630001,2.826309,-248.959885,0.003906,0.000470,0.011942,12.572051,0.640451,0.119417,-248.959885,0.012791,0.000000
13.890000,2.848656,-248.959885,0.003902,0.000483,0.012280,12.671453,0.645515,0.122797,-248.959885,0.013225,0.000000
14.150001,3.040428,-249.004364,0.003954,0.000504,0.012800,13.524500,0.688971,0.128001,-249.004364,0.013659,0.000000
14.410001,3.069473,-249.093323,0.003915,0.000517,0.013121,13.653699,0.695553,0.131211,-249.093323,0.014092,0.000000
14.670001,3.161072,-249.004364,0.003975,0.000533,0.013529,14.061150,0.716309,0.135287,-249.004364,0.014526,0.000000
14.930000,3.242249,-249.004364,0.003984,0.000550,0.013971,14.422242,0.734704,0.139708,-249.004364,0.014959,0.000000
15.190001,3.414658,-249.004364,0.003971,0.000576,0.014621,15.189156,0.773772,0.146214,-249.004364,0.015393,0.000000
15.450001,3.390457,-249.048843,0.004031,0.000589,0.014951,15.081507,0.768289,0.149507,-249.048843,0.015827,0.000000
15.710001,3.476097,-249.048843,0.004049,0.000605,0.015376,15.462452,0.787695,0.153758,-249.048843,0.016260,0.000000
15.970001,3.479820,-249.048843,0.004061,0.000618,0.015705,15.479013,0.788539,0.157054,-249.048843,0.016694,0.000000
16.230001,3.656700,-249.004364,0.004061,0.000636,0.016156,16.265814,0.828620,0.161562,-249.004364,0.017119,0.000000
16.490002,3.680908,-249.093323,0.004074,0.000651,0.016546,16.373497,0.834106,0.165464,-249.093323,0.017552,0.000000
16.750000,3.827248,-249.004364,0.004092,0.000672,0.017058,17.024448,0.867267,0.170581,-249.004364,0.017986,0.000000
17.010000,3.961678,-249.048843,0.004126,0.000692,0.017587,17.622421,0.897729,0.175873,-249.048843,0.018420,0.000000
17.270000,4.000404,-249.137802,0.004148,0.000708,0.017995,17.794687,0.906505,0.179949,-249.137802,0.018853,0.000000
17.530001,4.019768,-248.959885,0.004148,0.000723,0.018376,17.880819,0.910892,0.183764,-248.959885,0.019287,0.000000
17.790001,4.064819,-249.093323,0.004178,0.000739,0.018767,18.081219,0.921101,0.187666,-249.093323,0.019720,0.000000
18.050001,4.154564,-249.093323,0.004186,0.000757,0.019235,18.480423,0.941438,0.192348,-249.093323,0.020154,0.000000
18.310001,4.169456,-249.093323,0.004195,0.000771,0.019591,18.546669,0.944812,0.195906,-249.093323,0.020588,0.000000
18.570002,4.308350,-249.182281,0.004212,0.000789,0.020041,19.164495,0.976286,0.200414,-249.182281,0.021021,0.000000
18.830002,4.465118,-249.093323,0.004217,0.000812,0.020631,19.861839,1.011810,0.206311,-249.093323,0.021455,0.000000
19.090000,4.475922,-249.137802,0.004294,0.000827,0.021013,19.909893,1.014258,0.210130,-249.137802,0.021889,0.000000
19.350000,4.507568,-249.182281,0.004277,0.000847,0.021507,20.050665,1.021430,0.215073,-249.182281,0.022322,0.000000
19.610001,4.544067,-249.182281,0.004333,0.000863,0.021915,20.213020,1.029700,0.219145,-249.182281,0.022756,0.000000
19.870001,4.626732,-249.137802,0.004299,0.000881,0.022383,20.580730,1.048432,0.223831,-249.137802,0.023190,0.000000
20.130001,4.647209,-249.137802,0.004342,0.000893,0.022678,20.671820,1.053073,0.226780,-249.137802,0.023623,0.000000
20.390001,4.705673,-249.182281,0.004363,0.000909,0.023077,20.931879,1.066321,0.230769,-249.182281,0.024057,0.000000
20.650002,4.854622,-249.137802,0.004393,0.000931,0.023649,21.594437,1.100073,0.236492,-249.137802,0.024491,0.000000
20.910002,4.959633,-249.137802,0.004381,0.000953,0.024196,22.061548,1.123869,0.241957,-249.137802,0.024924,0.000000
21.170000,4.904892,-249.182281,0.004402,0.000967,0.024569,21.818048,1.111465,0.245685,-249.182281,0.025358,0.000000
21.430000,4.873985,-249.137802,0.004454,0.000983,0.024976,21.680569,1.104461,0.249761,-249.137802,0.025791,0.000000
21.690001,4.910851,-249.182281,0.004432,0.000999,0.025366,21.844555,1.112815,0.253664,-249.182281,0.026225,0.000000
21.950001,5.054962,-249.182281,0.004480,0.001018,0.025861,22.485594,1.145471,0.258607,-249.182281,0.026659,0.000000
22.210001,5.074326,-249.182281,0.004475,0.001033,0.026251,22.571728,1.149859,0.262509,-249.182281,0.027092,0.000000
22.470001,5.095177,-249.271255,0.004493,0.001050,0.026667,22.664478,1.154584,0.266672,-249.271255,0.027526,0.000000
22.730001,5.176727,-249.182281,0.004523,0.001068,0.027127,23.027233,1.173063,0.271267,-249.182281,0.027959,0.000000
22.990002,5.252319,-249.271255,0.004544,0.001087,0.027621,23.363483,1.190193,0.276210,-249.271255,0.028393,0.000000
23.250002,5.231094,-249.182281,0.004575,0.001104,0.028037,23.269070,1.185383,0.280374,-249.182281,0.028827,0.000000
23.510000,5.224388,-249.226776,0.004579,0.001117,0.028367,23.239239,1.183863,0.283670,-249.226776,0.029260,0.000000
23.770000,5.310036,-249.315735,0.004587,0.001135,0.028835,23.620218,1.203271,0.288352,-249.315735,0.029694,0.000000
24.030001,5.353600,-249.271255,0.004583,0.001153,0.029277,23.814001,1.213143,0.292773,-249.271255,0.030127,0.000000
24.290001,5.228485,-249.271255,0.004644,0.001164,0.029555,23.257463,1.184792,0.295551,-249.271255,0.030561,0.000000
24.550001,5.471642,-249.271255,0.004626,0.001185,0.030101,24.339077,1.239892,0.301013,-249.271255,0.030995,0.000000
24.810001,5.510002,-249.226776,0.004665,0.001204,0.030578,24.509714,1.248584,0.305782,-249.226776,0.031428,0.000000
25.070002,5.521172,-249.315735,0.004674,0.001221,0.031012,24.559399,1.251115,0.310119,-249.315735,0.031862,0.000000
25.330002,5.516701,-249.315735,0.004712,0.001238,0.031446,24.539511,1.250102,0.314457,-249.315735,0.032287,0.000000
25.590002,5.518936,-249.315735,0.004700,0.001253,0.031827,24.549454,1.250609,0.318272,-249.315735,0.032720,0.000000
25.850000,5.620224,-249.360214,0.004734,0.001274,0.032348,25.000006,1.273561,0.323476,-249.360214,0.033154,0.000000
26.110001,5.526756,-249.315735,0.004773,0.001286,0.032659,24.584240,1.252381,0.326595,-249.315735,0.033588,0.000000
26.370001,5.518936,-249.315735,0.004756,0.001300,0.033024,24.549454,1.250609,0.330240,-249.315735,0.034021,0.000000
26.630001,5.775871,-249.315735,0.004764,0.001326,0.033683,25.692358,1.308831,0.336829,-249.315735,0.034455,0.000000
26.890001,5.677567,-249.315735,0.004825,0.001339,0.034013,25.255077,1.286555,0.340126,-249.315735,0.034888,0.000000
27.150002,5.651131,-249.315735,0.004863,0.001354,0.034403,25.137486,1.280565,0.344028,-249.315735,0.035322,0.000000
27.410002,5.664536,-249.271255,0.004820,0.001370,0.034793,25.197113,1.283602,0.347930,-249.271255,0.035756,0.000000
27.670002,5.851089,-249.360214,0.004863,0.001392,0.035365,26.026945,1.325876,0.353653,-249.360214,0.036189,0.000000
27.930002,5.685013,-249.315735,0.004902,0.001401,0.035573,25.288200,1.288242,0.355735,-249.315735,0.036623,0.000000
28.190001,5.617989,-249.360214,0.004907,0.001410,0.035825,24.990061,1.273054,0.358252,-249.360214,0.037056,0.000000
28.450001,6.015678,-249.271255,0.004937,0.001445,0.036692,26.759073,1.363172,0.366923,-249.271255,0.037490,0.000000
28.710001,5.980309,-249.360214,0.004971,0.001463,0.037152,26.601742,1.355157,0.371518,-249.360214,0.037924,0.000000
28.970001,5.903969,-249.404694,0.004967,0.001477,0.037516,26.262165,1.337858,0.375163,-249.404694,0.038357,0.000000
29.230001,5.904343,-249.404694,0.004963,0.001493,0.037915,26.263828,1.337943,0.379152,-249.404694,0.038791,0.000000
29.490002,5.871948,-249.449173,0.005006,0.001507,0.038288,26.119730,1.330603,0.382880,-249.449173,0.039224,0.000000
29.750002,5.908806,-249.404694,0.005001,0.001521,0.038643,26.283682,1.338955,0.386434,-249.404694,0.039658,0.000000
30.010002,5.932266,-249.404694,0.005062,0.001537,0.039034,26.388039,1.344271,0.390336,-249.404694,0.040092,0.000000
30.270002,6.098717,-249.449173,0.005053,0.001560,0.039623,27.128447,1.381989,0.396233,-249.449173,0.040525,0.000000
30.530001,6.200005,-249.404694,0.005053,0.001581,0.040161,27.578999,1.404941,0.401611,-249.404694,0.040959,0.000000
30.790001,6.117340,-249.493652,0.005096,0.001596,0.040534,27.211288,1.386209,0.405340,-249.493652,0.041393,0.000000
31.050001,6.119942,-249.404694,0.005113,0.001612,0.040942,27.222860,1.386799,0.409416,-249.404694,0.041826,0.000000
31.310001,6.074516,-249.493652,0.005135,0.001626,0.041289,27.020798,1.376505,0.412887,-249.493652,0.042260,0.000000
31.570002,6.201866,-249.449173,0.005105,0.001646,0.041817,27.587278,1.405363,0.418174,-249.449173,0.042694,0.000000
31.830002,6.204102,-249.449173,0.005182,0.001661,0.042191,27.597221,1.405869,0.421906,-249.449173,0.043127,0.000000
32.090000,6.199257,-249.404694,0.005195,0.001675,0.042546,27.575672,1.404772,0.425460,-249.404694,0.043561,0.000000
32.350002,6.285652,-249.493652,0.005226,0.001695,0.043040,27.959978,1.424349,0.430403,-249.493652,0.043994,0.000000
32.610001,6.381348,-249.449173,0.005234,0.001713,0.043517,28.385653,1.446034,0.435172,-249.449173,0.044428,0.000000
32.870003,6.318794,-249.538132,0.005260,0.001728,0.043890,28.107401,1.431859,0.438900,-249.538132,0.044862,0.000000
33.130001,6.327354,-249.493652,0.005264,0.001746,0.044341,28.145477,1.433799,0.443412,-249.493652,0.045295,0.000000
33.390003,6.318047,-249.582611,0.005295,0.001760,0.044705,28.104074,1.431690,0.447053,-249.582611,0.045729,0.000000
33.650002,6.528435,-249.493652,0.005286,0.001782,0.045261,29.039928,1.479364,0.452605,-249.493652,0.046162,0.000000
33.910000,6.532158,-249.538132,0.005333,0.001798,0.045668,29.056490,1.480208,0.456682,-249.538132,0.046596,0.000000
34.170002,6.459175,-249.538132,0.005277,0.001813,0.046041,28.731846,1.463670,0.460410,-249.538132,0.047030,0.000000
34.430000,6.666962,-249.493652,0.005368,0.001836,0.046622,29.656126,1.510755,0.466220,-249.493652,0.047455,0.000000
34.690002,6.636055,-249.582611,0.005385,0.001853,0.047073,29.518646,1.503752,0.470727,-249.582611,0.047888,0.000000
34.950001,6.567535,-249.538132,0.005389,0.001869,0.047472,29.213856,1.488225,0.474717,-249.538132,0.048322,0.000000
35.210003,6.513168,-249.538132,0.005407,0.001884,0.047845,28.972019,1.475905,0.478449,-249.538132,0.048756,0.000000
35.470001,6.710899,-249.627090,0.005394,0.001903,0.048330,29.851572,1.520712,0.483305,-249.627090,0.049189,0.000000
35.730003,6.622650,-249.582611,0.005441,0.001915,0.048651,29.459019,1.500714,0.486514,-249.582611,0.049623,0.000000
35.990002,6.691910,-249.627090,0.005467,0.001931,0.049050,29.767101,1.516408,0.490503,-249.627090,0.050056,0.000000
36.250000,6.780533,-249.538132,0.005445,0.001949,0.049492,30.161316,1.536491,0.494924,-249.538132,0.050490,0.000000
36.510002,7.008797,-249.538132,0.005471,0.001975,0.050169,31.176685,1.588216,0.501688,-249.538132,0.050923,0.000000
36.770000,6.838623,-249.582611,0.005514,0.001989,0.050525,30.419714,1.549654,0.505246,-249.582611,0.051357,0.000000
37.030003,6.853516,-249.538132,0.005519,0.002005,0.050932,30.485960,1.553029,0.509322,-249.538132,0.051791,0.000000
37.290001,6.750000,-249.627090,0.005514,0.002017,0.051236,30.025499,1.529572,0.512357,-249.627090,0.052224,0.000000
37.550003,6.881073,-249.627090,0.005527,0.002035,0.051678,30.608541,1.559273,0.516778,-249.627090,0.052658,0.000000
37.810001,6.914589,-249.582611,0.005566,0.002050,0.052077,30.757627,1.566868,0.520768,-249.582611,0.053091,0.000000
38.070004,7.119019,-249.627090,0.005566,0.002072,0.052641,31.666977,1.613193,0.526407,-249.627090,0.053525,0.000000
38.330002,7.185677,-249.627090,0.005627,0.002092,0.053126,31.963486,1.628298,0.531263,-249.627090,0.053959,0.000000
38.590000,7.124237,-249.671585,0.005614,0.002107,0.053517,31.690189,1.614375,0.535165,-249.671585,0.054392,0.000000
38.850002,7.105614,-249.671585,0.005635,0.002122,0.053898,31.607347,1.610155,0.538980,-249.671585,0.054826,0.000000
39.110001,7.095932,-249.627090,0.005674,0.002140,0.054349,31.564281,1.607961,0.543488,-249.627090,0.055259,0.000000
39.370003,7.174873,-249.671585,0.005691,0.002158,0.054817,31.915430,1.625850,0.548174,-249.671585,0.055693,0.000000
39.630001,7.103378,-249.627090,0.005696,0.002170,0.055121,31.597404,1.609649,0.551209,-249.627090,0.056127,0.000000
39.890003,7.212860,-249.671585,0.005700,0.002188,0.055572,32.084404,1.634457,0.555717,-249.671585,0.056560,0.000000
40.150002,7.405373,-249.671585,0.005721,0.002211,0.056153,32.940742,1.678081,0.561527,-249.671585,0.056994,0.000000
40.410004,7.340958,-249.627090,0.005708,0.002226,0.056534,32.654209,1.663485,0.565342,-249.627090,0.057427,0.000000
40.670002,7.356224,-249.760544,0.005747,0.002244,0.057003,32.722118,1.666944,0.570028,-249.760544,0.057861,0.000000
40.930000,7.387131,-249.671585,0.005756,0.002261,0.057427,32.859600,1.673948,0.574275,-249.671585,0.058295,0.000000
41.190002,7.508522,-249.716064,0.005808,0.002280,0.057922,33.399574,1.701455,0.579218,-249.716064,0.058728,0.000000
41.450001,7.385269,-249.716064,0.005829,0.002292,0.058225,32.851318,1.673526,0.582253,-249.716064,0.059162,0.000000
41.710003,7.534958,-249.671585,0.005868,0.002311,0.058711,33.517166,1.707446,0.587109,-249.671585,0.059596,0.000000
41.970001,7.624329,-249.716064,0.005812,0.002331,0.059206,33.914707,1.727697,0.592056,-249.716064,0.060029,0.000000
42.230003,7.703270,-249.760544,0.005881,0.002350,0.059691,34.265858,1.745586,0.596912,-249.760544,0.060463,0.000000
42.490002,7.604225,-249.805023,0.005872,0.002366,0.060090,33.825283,1.723142,0.600901,-249.805023,0.060897,0.000000
42.750004,7.569962,-249.716064,0.005885,0.002382,0.060498,33.672871,1.715378,0.604978,-249.716064,0.061330,0.000000
43.010002,7.555817,-249.760544,0.005920,0.002398,0.060897,33.609951,1.712173,0.608967,-249.760544,0.061764,0.000000
43.270000,7.727104,-249.805023,0.005907,0.002417,0.061382,34.371876,1.750987,0.613823,-249.805023,0.062189,0.000000
43.530003,7.737160,-249.716064,0.005963,0.002432,0.061773,34.416607,1.753266,0.617725,-249.716064,0.062622,0.000000
43.790001,7.762856,-249.805023,0.005963,0.002448,0.062180,34.530907,1.759088,0.621801,-249.805023,0.063056,0.000000
44.050003,7.835838,-249.849503,0.006023,0.002465,0.062614,34.855549,1.775626,0.626135,-249.849503,0.063489,0.000000
44.310001,7.922600,-249.805023,0.006006,0.002485,0.063125,35.241486,1.795287,0.631252,-249.805023,0.063923,0.000000
44.570004,7.906212,-249.805023,0.005997,0.002502,0.063559,35.168587,1.791573,0.635590,-249.805023,0.064357,0.000000
44.830002,7.863396,-249.805023,0.006049,0.002515,0.063888,34.978130,1.781871,0.638883,-249.805023,0.064790,0.000000
45.090004,8.017555,-249.805023,0.006071,0.002534,0.064366,35.663868,1.816804,0.643655,-249.805023,0.065224,0.000000
45.350002,8.023140,-249.805023,0.006071,0.002551,0.064799,35.688709,1.818069,0.647989,-249.805023,0.065658,0.000000
45.610001,7.953133,-249.893982,0.006092,0.002564,0.065137,35.377300,1.802206,0.651373,-249.893982,0.066091,0.000000
45.870003,8.242470,-249.849503,0.006096,0.002584,0.065640,36.664337,1.867770,0.656403,-249.849503,0.066525,0.000000
46.130001,8.281937,-249.760544,0.006114,0.002603,0.066126,36.839893,1.876714,0.661259,-249.760544,0.066959,0.000000
46.390003,8.287521,-249.849503,0.006204,0.002620,0.066551,36.864735,1.877979,0.665509,-249.849503,0.067392,0.000000
46.650002,8.357529,-249.893982,0.006170,0.002638,0.067002,37.176144,1.893843,0.670017,-249.893982,0.067826,0.000000
46.910004,8.268532,-249.893982,0.006174,0.002653,0.067375,36.780266,1.873676,0.673745,-249.893982,0.068259,0.000000
47.170002,8.458069,-249.849503,0.006196,0.002673,0.067895,37.623371,1.916626,0.678950,-249.849503,0.068693,0.000000
47.430004,8.246933,-249.893982,0.006226,0.002683,0.068147,36.684189,1.868782,0.681467,-249.893982,0.069127,0.000000
47.690002,8.428284,-249.893982,0.006239,0.002702,0.068632,37.490879,1.909876,0.686323,-249.893982,0.069560,0.000000
47.950001,8.743309,-249.893982,0.006260,0.002725,0.069205,38.892181,1.981262,0.692045,-249.893982,0.069994,0.000000
48.210003,8.552284,-249.849503,0.006256,0.002736,0.069499,38.042461,1.937975,0.694994,-249.849503,0.070427,0.000000
48.470001,8.601433,-249.938461,0.006265,0.002754,0.069942,38.261086,1.949113,0.699418,-249.938461,0.070861,0.000000
48.730003,8.626755,-249.893982,0.006265,0.002768,0.070306,38.373722,1.954851,0.703059,-249.893982,0.071295,0.000000
48.990002,8.964500,-249.938461,0.006347,0.002790,0.070861,39.876091,2.031385,0.708608,-249.938461,0.071728,0.000000
49.250004,8.739586,-249.982941,0.006295,0.002799,0.071095,38.875618,1.980419,0.710951,-249.982941,0.072162,0.000000
49.510002,8.612610,-249.849503,0.006372,0.002809,0.071355,38.310802,1.951645,0.713551,-249.849503,0.072595,0.000000
49.770000,9.290321,-249.982941,0.006359,0.002843,0.072205,41.325413,2.105217,0.722052,-249.982941,0.073029,0.000000
50.030003,9.352509,-249.938461,0.006385,0.002861,0.072673,41.602036,2.119309,0.726734,-249.938461,0.073463,0.000000
50.290001,9.208771,-249.982941,0.006420,0.002875,0.073029,40.962658,2.086737,0.730292,-249.982941,0.073896,0.000000
50.550003,9.248993,-249.982941,0.006403,0.002892,0.073445,41.141575,2.095852,0.734451,-249.982941,0.074330,0.000000
50.810001,9.211006,-249.938461,0.006441,0.002906,0.073818,40.972603,2.087244,0.738183,-249.938461,0.074763,0.000000
51.070004,9.338730,-249.982941,0.006459,0.002922,0.074209,41.540745,2.116186,0.742085,-249.982941,0.075197,0.000000
51.330002,9.405014,-249.982941,0.006446,0.002935,0.074555,41.835590,2.131207,0.745552,-249.982941,0.075631,0.000000
51.590004,9.725624,-249.938461,0.006493,0.002958,0.075145,43.261738,2.203858,0.751449,-249.938461,0.076064,0.000000
51.850002,10.050339,-249.982941,0.006532,0.002980,0.075700,44.706139,2.277439,0.757002,-249.982941,0.076498,0.000000
52.110001,9.940483,-250.027420,0.006515,0.002996,0.076090,44.217476,2.252546,0.760904,-250.027420,0.076931,0.000000
52.370003,9.946075,-250.027420,0.006528,0.003011,0.076481,44.242352,2.253813,0.764806,-250.027420,0.077356,0.000000
52.630001,9.898781,-249.938461,0.006536,0.003024,0.076810,44.031975,2.243096,0.768103,-249.938461,0.077790,0.000000
52.890003,10.152367,-250.027420,0.006601,0.003045,0.077339,45.159981,2.300559,0.773390,-250.027420,0.078224,0.000000
53.150002,10.217903,-250.071899,0.006592,0.003059,0.077686,45.451504,2.315410,0.776861,-250.071899,0.078657,0.000000
53.410004,10.327011,-249.982941,0.006592,0.003074,0.078085,45.936840,2.340134,0.780850,-249.982941,0.079091,0.000000
53.670002,10.594002,-250.116394,0.006622,0.003093,0.078571,47.124474,2.400635,0.785706,-250.116394,0.079524,0.000000
53.930004,10.812584,-250.071899,0.006640,0.003111,0.079030,48.096775,2.450166,0.790301,-250.071899,0.079958,0.000000
54.190002,10.786888,-250.071899,0.006666,0.003127,0.079429,47.982475,2.444344,0.794290,-250.071899,0.080392,0.000000
54.450001,10.904182,-250.071899,0.006640,0.003144,0.079863,48.504227,2.470923,0.798628,-250.071899,0.080825,0.000000
54.710003,11.006218,-250.027420,0.006691,0.003160,0.080253,48.958103,2.494045,0.802530,-250.027420,0.081259,0.000000
54.970001,11.392365,-250.071899,0.006713,0.003181,0.080799,50.675770,2.581547,0.807992,-250.071899,0.081692,0.000000
55.230003,11.538338,-250.116394,0.006704,0.003196,0.081189,51.325089,2.614625,0.811894,-250.116394,0.082126,0.000000
55.490002,11.500351,-250.071899,0.006769,0.003211,0.081554,51.156116,2.606017,0.815539,-250.071899,0.082560,0.000000
55.750004,12.013115,-250.116394,0.006735,0.003234,0.082135,53.437004,2.722211,0.821349,-250.116394,0.082993,0.000000
56.010002,12.153870,-250.116394,0.006804,0.003251,0.082577,54.063110,2.754106,0.825773,-250.116394,0.083427,0.000000
56.270004,12.164665,-250.116394,0.006808,0.003267,0.082985,54.111134,2.756552,0.829846,-250.116394,0.083861,0.000000
56.530003,12.205627,-250.116394,0.006808,0.003281,0.083332,54.293343,2.765835,0.833317,-250.116394,0.084294,0.000000
56.790001,12.709450,-250.160873,0.006825,0.003300,0.083826,56.534454,2.880002,0.838260,-250.160873,0.084728,0.000000
57.050003,12.693810,-250.160873,0.006842,0.003314,0.084164,56.464886,2.876458,0.841643,-250.160873,0.085162,0.000000
57.310001,13.010696,-250.160873,0.006855,0.003330,0.084580,57.874470,2.948266,0.845803,-250.160873,0.085595,0.000000
57.570004,13.245293,-250.205353,0.006881,0.003347,0.085014,58.918003,3.001426,0.850140,-250.205353,0.086029,0.000000
57.830002,14.004929,-250.249832,0.006907,0.003374,0.085699,62.297035,3.173562,0.856991,-250.249832,0.086462,0.000000
58.090004,13.840340,-250.160873,0.006898,0.003388,0.086055,61.564907,3.136266,0.860549,-250.160873,0.086896,0.000000
58.350002,13.924873,-250.205353,0.006946,0.003404,0.086454,61.940929,3.155421,0.864538,-250.205353,0.087330,0.000000
58.610004,13.979980,-250.116394,0.006967,0.003416,0.086757,62.186058,3.167909,0.867570,-250.116394,0.087763,0.000000
58.870003,14.439117,-250.160873,0.006946,0.003433,0.087199,64.228401,3.271951,0.871994,-250.160873,0.088197,0.000000
59.130001,14.668869,-250.160873,0.006972,0.003449,0.087598,65.250389,3.324013,0.875984,-250.160873,0.088631,0.000000
59.390003,15.155563,-250.160873,0.007019,0.003470,0.088136,67.415314,3.434300,0.881362,-250.160873,0.089064,0.000000
59.650002,15.689171,-250.205353,0.007015,0.003490,0.088656,69.788918,3.555217,0.886562,-250.205353,0.089498,0.000000
59.910004,15.811684,-250.205353,0.007002,0.003505,0.089038,70.333885,3.582979,0.890381,-250.205353,0.089931,0.000000
60.170002,15.928604,-250.205353,0.007036,0.003520,0.089420,70.853973,3.609473,0.894197,-250.205353,0.090365,0.000000
60.430004,16.299118,-250.249832,0.007049,0.003539,0.089897,72.502098,3.693433,0.898966,-250.249832,0.090798,0.000000
60.690002,16.707611,-250.205353,0.007054,0.003556,0.090330,74.319168,3.785999,0.903303,-250.205353,0.091232,0.000000
60.950005,16.760857,-250.249832,0.007097,0.003569,0.090642,74.556015,3.798064,0.906422,-250.249832,0.091666,0.000000
61.210003,17.236755,-250.205353,0.007080,0.003586,0.091093,76.672920,3.905905,0.910933,-250.205353,0.092099,0.000000
61.470001,18.037727,-250.205353,0.007101,0.003609,0.091674,80.235817,4.087408,0.916743,-250.205353,0.092524,0.000000
61.730003,18.144600,-250.249832,0.007097,0.003624,0.092056,80.711212,4.111625,0.920558,-250.249832,0.092958,0.000000
61.990002,18.607086,-250.249832,0.007183,0.003643,0.092541,82.768456,4.216426,0.925414,-250.249832,0.093392,0.000000
62.250004,18.956741,-250.294312,0.007187,0.003660,0.092958,84.323799,4.295659,0.929578,-250.294312,0.093825,0.000000
62.510002,19.472107,-250.294312,0.007209,0.003679,0.093443,86.616257,4.412442,0.934434,-250.294312,0.094259,0.000000
62.770004,19.592010,-250.249832,0.007187,0.003690,0.093738,87.149612,4.439613,0.937382,-250.249832,0.094692,0.000000
63.030003,19.923416,-250.338791,0.007200,0.003704,0.094094,88.623779,4.514710,0.940940,-250.338791,0.095126,0.000000
63.290005,20.787323,-250.294312,0.007205,0.003728,0.094701,92.466629,4.710474,0.947011,-250.294312,0.095560,0.000000
63.550003,21.519035,-250.294312,0.007213,0.003749,0.095212,95.721451,4.876283,0.952124,-250.294312,0.095993,0.000000
63.810001,21.819916,-250.294312,0.007230,0.003764,0.095603,97.059830,4.944464,0.956030,-250.294312,0.096427,0.000000
64.070000,21.985992,-250.294312,0.007261,0.003780,0.096002,97.798576,4.982097,0.960020,-250.294312,0.096860,0.000000
64.330002,22.349800,-250.294312,0.007278,0.003794,0.096357,99.416878,5.064537,0.963574,-250.294312,0.097294,0.000000
64.590004,23.238281,-250.249832,0.007291,0.003815,0.096904,103.369034,5.265870,0.969035,-250.249832,0.097727,0.000000
64.850006,23.697044,-250.383270,0.007304,0.003830,0.097294,105.409721,5.369827,0.972941,-250.383270,0.098161,0.000000
65.110001,23.991219,-250.294312,0.007321,0.003846,0.097693,106.718269,5.436488,0.976931,-250.294312,0.098595,0.000000
65.370003,24.783623,-250.383270,0.007321,0.003864,0.098153,110.243057,5.616049,0.981525,-250.383270,0.099028,0.000000
65.630005,25.520554,-250.383270,0.007317,0.003884,0.098664,113.521095,5.783041,0.986643,-250.383270,0.099462,0.000000
65.889999,25.936119,-250.338791,0.007343,0.003899,0.099046,115.369621,5.877208,0.990458,-250.338791,0.099895,0.000000
66.150002,26.431747,-250.383270,0.007360,0.003913,0.099401,117.574287,5.989520,0.994012,-250.383270,0.100329,0.000000
66.410004,27.245750,-250.383270,0.007351,0.003932,0.099878,121.195152,6.173975,0.998785,-250.383270,0.100763,0.000000
66.670006,27.797981,-250.383270,0.007381,0.003949,0.100294,123.651596,6.299113,1.002944,-250.383270,0.101196,0.000000
66.930000,28.093269,-250.383270,0.007386,0.003963,0.100668,124.965103,6.366025,1.006676,-250.383270,0.101630,0.000000
67.190002,29.105751,-250.338791,0.007420,0.003983,0.101162,129.468842,6.595458,1.011619,-250.338791,0.102064,0.000000
67.450005,29.883636,-250.427750,0.007429,0.004000,0.101604,132.929047,6.771729,1.016040,-250.427750,0.102497,0.000000
67.710007,30.695786,-250.427750,0.007433,0.004018,0.102064,136.541672,6.955764,1.020639,-250.427750,0.102931,0.000000
67.970001,31.442390,-250.338791,0.007476,0.004036,0.102523,139.862732,7.124947,1.025233,-250.338791,0.103365,0.000000
68.230003,31.901527,-250.427750,0.007455,0.004051,0.102896,141.905075,7.228990,1.028962,-250.427750,0.103798,0.000000
68.490005,32.909538,-250.383270,0.007468,0.004071,0.103399,146.388931,7.457408,1.033992,-250.383270,0.104232,0.000000
68.750000,33.144875,-250.427750,0.007515,0.004083,0.103720,147.435760,7.510736,1.037201,-250.427750,0.104665,0.000000
69.010002,33.643112,-250.427750,0.007489,0.004098,0.104093,149.652039,7.623638,1.040929,-250.427750,0.105099,0.000000
69.270004,35.316551,-250.427750,0.007511,0.004123,0.104726,157.095871,8.002845,1.047261,-250.427750,0.105533,0.000000
69.530006,35.723930,-250.472229,0.007532,0.004136,0.105047,158.907974,8.095159,1.050471,-250.472229,0.105966,0.000000
69.790001,36.346909,-250.427750,0.007524,0.004151,0.105446,161.679123,8.236327,1.054460,-250.427750,0.106400,0.000000
70.050003,37.016434,-250.472229,0.007541,0.004166,0.105810,164.657318,8.388043,1.058101,-250.472229,0.106834,0.000000
70.310005,38.391602,-250.427750,0.007545,0.004188,0.106382,170.774368,8.699661,1.063824,-250.427750,0.107258,0.000000
70.570000,38.693596,-250.516724,0.007541,0.004197,0.106608,172.117706,8.768094,1.066080,-250.516724,0.107692,0.000000
70.830002,39.207848,-250.516724,0.007601,0.004213,0.107016,174.405212,8.884625,1.070156,-250.516724,0.108126,0.000000
71.090004,41.202644,-250.472229,0.007575,0.004240,0.107692,183.278519,9.336653,1.076920,-250.472229,0.108559,0.000000
71.350006,42.504456,-250.561203,0.007580,0.004260,0.108195,189.069260,9.631647,1.081950,-250.561203,0.108993,0.000000
71.610001,42.995987,-250.516724,0.007618,0.004273,0.108525,191.255707,9.743031,1.085247,-250.516724,0.109427,0.000000
71.870003,43.793983,-250.472229,0.007580,0.004289,0.108932,194.805374,9.923859,1.089323,-250.472229,0.109860,0.000000
72.130005,44.198380,-250.561203,0.007614,0.004302,0.109270,196.604218,10.015496,1.092703,-250.561203,0.110294,0.000000
72.390007,45.414925,-250.516724,0.007597,0.004318,0.109687,202.015671,10.291169,1.096866,-250.516724,0.110727,0.000000
72.650002,46.166740,-250.516724,0.007627,0.004334,0.110077,205.359924,10.461534,1.100769,-250.516724,0.111161,0.000000
72.910004,47.370247,-250.561203,0.007644,0.004354,0.110580,210.713379,10.734251,1.105799,-250.561203,0.111595,0.000000
73.170006,48.936073,-250.472229,0.007670,0.004376,0.111161,217.678528,11.089073,1.111609,-250.472229,0.112028,0.000000
73.430000,49.871849,-250.605682,0.007662,0.004391,0.111534,221.841064,11.301123,1.115337,-250.605682,0.112462,0.000000
73.690002,50.935715,-250.561203,0.007675,0.004408,0.111967,226.573380,11.542198,1.119674,-250.561203,0.112895,0.000000
73.950005,51.657745,-250.605682,0.007700,0.004422,0.112323,229.785126,11.705812,1.123228,-250.605682,0.113329,0.000000
74.210007,52.854179,-250.561203,0.007666,0.004441,0.112791,235.107132,11.976928,1.127914,-250.561203,0.113763,0.000000
74.470001,53.821228,-250.561203,0.007666,0.004456,0.113190,239.408783,12.196065,1.131903,-250.561203,0.114196,0.000000
74.730003,54.685875,-250.650162,0.007718,0.004470,0.113546,243.254913,12.391996,1.135457,-250.650162,0.114630,0.000000
74.990005,55.978386,-250.605682,0.007687,0.004490,0.114049,249.004303,12.684883,1.140487,-250.605682,0.115063,0.000000
75.250000,57.548309,-250.605682,0.007700,0.004510,0.114552,255.987671,13.040634,1.145517,-250.605682,0.115497,0.000000
75.510002,58.254326,-250.650162,0.007709,0.004524,0.114916,259.128174,13.200619,1.149158,-250.650162,0.115931,0.000000
75.770004,59.474960,-250.605682,0.007739,0.004541,0.115350,264.557831,13.477219,1.153496,-250.605682,0.116364,0.000000
76.030006,60.370888,-250.605682,0.007752,0.004557,0.115740,268.543121,13.680239,1.157398,-250.605682,0.116798,0.000000
76.290001,61.745689,-250.605682,0.007769,0.004576,0.116225,274.658539,13.991774,1.162254,-250.605682,0.117231,0.000000
76.550003,63.127190,-250.605682,0.007774,0.004593,0.116659,280.803772,14.304826,1.166592,-250.605682,0.117665,0.000000
76.810005,63.893539,-250.650162,0.007743,0.004606,0.116980,284.212646,14.478482,1.169801,-250.650162,0.118099,0.000000
77.070007,65.701035,-250.650162,0.007748,0.004629,0.117587,292.252808,14.888067,1.175872,-250.650162,0.118532,0.000000
77.330002,67.295151,-250.694641,0.007761,0.004648,0.118064,299.343781,15.249299,1.180641,-250.694641,0.118966,0.000000
77.590004,66.995773,-250.650162,0.007791,0.004641,0.117890,298.012085,15.181459,1.178904,-250.650162,0.118099,0.000000
77.850006,66.436096,-250.650162,0.007787,0.004641,0.117882,295.522522,15.054634,1.178821,-250.650162,0.117882,0.000000
78.110001,65.962433,-250.694641,0.007761,0.004641,0.117873,293.415558,14.947301,1.178734,-250.694641,0.117882,0.000000
78.370003,65.547989,-250.694641,0.007769,0.004641,0.117873,291.572021,14.853387,1.178734,-250.694641,0.117882,0.000000
78.630005,65.175232,-250.783600,0.007804,0.004640,0.117865,289.913910,14.768919,1.178647,-250.783600,0.117882,0.000000
78.890007,64.867279,-250.694641,0.007812,0.004640,0.117865,288.544067,14.699136,1.178647,-250.694641,0.117882,0.000000
79.150002,64.572739,-250.739120,0.007795,0.004640,0.117865,287.233887,14.632392,1.178647,-250.739120,0.117882,0.000000
79.410004,64.326981,-250.739120,0.007769,0.004640,0.117865,286.140686,14.576702,1.178647,-250.739120,0.117882,0.000000
79.670006,64.062210,-250.694641,0.007812,0.004640,0.117865,284.962952,14.516704,1.178647,-250.694641,0.117882,0.000000
79.930000,63.867844,-250.783600,0.007795,0.004640,0.117865,284.098358,14.472661,1.178647,-250.783600,0.117882,0.000000
80.190002,63.664154,-250.739120,0.007800,0.004640,0.117865,283.192291,14.426503,1.178647,-250.739120,0.117882,0.000000
80.450005,63.486160,-250.694641,0.007787,0.004640,0.117856,282.400543,14.386169,1.178560,-250.694641,0.117882,0.000000
80.710007,63.301086,-250.739120,0.007774,0.004640,0.117856,281.577301,14.344232,1.178560,-250.739120,0.117882,0.000000
80.970001,63.163307,-250.739120,0.007795,0.004640,0.117856,280.964417,14.313009,1.178560,-250.739120,0.117882,0.000000
81.230003,62.997978,-250.783600,0.007791,0.004640,0.117856,280.229004,14.275546,1.178560,-250.783600,0.117882,0.000000
81.490005,62.874352,-250.783600,0.007795,0.004640,0.117856,279.679077,14.247532,1.178560,-250.783600,0.117882,0.000000
81.750008,62.742531,-250.783600,0.007808,0.004640,0.117856,279.092712,14.217661,1.178560,-250.783600,0.117882,0.000000
82.010002,62.625603,-250.828079,0.007834,0.004640,0.117856,278.572601,14.191165,1.178560,-250.828079,0.117882,0.000000
82.270004,62.497505,-250.783600,0.007825,0.004640,0.117856,278.002777,14.162137,1.178560,-250.783600,0.117882,0.000000
82.530006,62.404785,-250.828079,0.007804,0.004640,0.117856,277.590363,14.141127,1.178560,-250.828079,0.117882,0.000000
82.790001,62.274086,-250.828079,0.007804,0.004640,0.117856,277.008972,14.111509,1.178560,-250.828079,0.117882,0.000000
83.050003,62.199608,-250.783600,0.007812,0.004640,0.117856,276.677673,14.094633,1.178560,-250.783600,0.117882,0.000000
83.310005,62.087151,-250.828079,0.007834,0.004640,0.117856,276.177429,14.069149,1.178560,-250.828079,0.117882,0.000000
83.570007,62.009331,-250.828079,0.007812,0.004640,0.117856,275.831268,14.051515,1.178560,-250.828079,0.117882,0.000000
83.830002,61.915115,-250.872559,0.007812,0.004640,0.117856,275.412201,14.030166,1.178560,-250.872559,0.117882,0.000000
84.090004,61.827240,-250.783600,0.007808,0.004640,0.117856,275.021301,14.010253,1.178560,-250.783600,0.117882,0.000000
84.350006,61.749786,-250.872559,0.007800,0.004640,0.117856,274.676758,13.992702,1.178560,-250.872559,0.117882,0.000000
84.610001,61.684990,-250.917038,0.007800,0.004640,0.117856,274.388550,13.978019,1.178560,-250.917038,0.117882,0.000000
84.870003,61.614616,-250.872559,0.007817,0.004640,0.117856,274.075500,13.962071,1.178560,-250.872559,0.117882,0.000000
85.130005,61.549820,-250.872559,0.007800,0.004640,0.117856,273.787262,13.947389,1.178560,-250.872559,0.117882,0.000000
85.390007,61.453003,-250.828079,0.007817,0.004640,0.117856,273.356598,13.925449,1.178560,-250.828079,0.117882,0.000000
85.650002,61.400124,-250.828079,0.007821,0.004640,0.117856,273.121399,13.913466,1.178560,-250.828079,0.117882,0.000000
85.910004,61.329750,-250.917038,0.007795,0.004640,0.117856,272.808350,13.897520,1.178560,-250.917038,0.117882,0.000000
86.170006,61.269798,-250.872559,0.007830,0.004640,0.117856,272.541687,13.883935,1.178560,-250.872559,0.117882,0.000000
86.430000,61.204262,-250.872559,0.007812,0.004640,0.117856,272.250153,13.869084,1.178560,-250.872559,0.117882,0.000000
86.690002,61.141701,-250.917038,0.007791,0.004640,0.117856,271.971863,13.854907,1.178560,-250.917038,0.117882,0.000000
86.950005,61.077652,-250.917038,0.007821,0.004640,0.117856,271.686951,13.840394,1.178560,-250.917038,0.117882,0.000000
87.210007,61.023285,-250.961533,0.007795,0.004640,0.117856,271.445129,13.828074,1.178560,-250.961533,0.117882,0.000000
87.470001,60.970779,-250.917038,0.007821,0.004640,0.117856,271.211578,13.816176,1.178560,-250.917038,0.117882,0.000000
87.730003,60.911201,-250.961533,0.007787,0.004640,0.117856,270.946564,13.802676,1.178560,-250.961533,0.117882,0.000000
87.990005,60.858322,-250.961533,0.007812,0.004640,0.117856,270.711334,13.790693,1.178560,-250.961533,0.117882,0.000000
88.250008,60.820343,-250.961533,0.007800,0.004640,0.117856,270.542389,13.782086,1.178560,-250.961533,0.117882,0.000000
88.510002,60.764114,-250.961533,0.007778,0.004640,0.117856,270.292267,13.769345,1.178560,-250.961533,0.117882,0.000000
88.770004,60.724640,-250.917038,0.007812,0.004640,0.117856,270.116699,13.760401,1.178560,-250.917038,0.117882,0.000000
89.030006,60.659851,-250.961533,0.007812,0.004640,0.117856,269.828491,13.745719,1.178560,-250.961533,0.117882,0.000000
89.290001,60.619263,-250.961533,0.007834,0.004640,0.117856,269.647949,13.736522,1.178560,-250.961533,0.117882,0.000000
89.550003,60.568245,-251.006012,0.007808,0.004640,0.117856,269.421021,13.724961,1.178560,-251.006012,0.117882,0.000000
89.810005,60.537712,-251.050491,0.007834,0.004640,0.117856,269.285187,13.718041,1.178560,-251.050491,0.117882,0.000000
90.070007,60.483719,-251.050491,0.007808,0.004640,0.117856,269.045013,13.705807,1.178560,-251.050491,0.117882,0.000000
90.330002,60.446480,-251.006012,0.007812,0.004640,0.117856,268.879364,13.697368,1.178560,-251.006012,0.117882,0.000000
90.590004,60.398445,-250.961533,0.007847,0.004640,0.117856,268.665710,13.686483,1.178560,-250.961533,0.117882,0.000000
90.850006,60.372375,-250.961533,0.007821,0.004640,0.117856,268.549744,13.680575,1.178560,-250.961533,0.117882,0.000000
91.110001,60.322479,-251.050491,0.007808,0.004640,0.117856,268.327789,13.669270,1.178560,-251.050491,0.117882,0.000000
91.370003,60.292694,-251.006012,0.007830,0.004640,0.117856,268.195312,13.662519,1.178560,-251.006012,0.117882,0.000000
91.630005,60.238327,-251.050491,0.007812,0.004640,0.117856,267.953461,13.650200,1.178560,-251.050491,0.117882,0.000000
91.890007,60.223801,-251.050491,0.007821,0.004640,0.117856,267.888855,13.646909,1.178560,-251.050491,0.117882,0.000000
92.150002,60.167946,-251.006012,0.007795,0.004640,0.117856,267.640381,13.634252,1.178560,-251.006012,0.117882,0.000000
92.410004,60.135551,-251.094971,0.007838,0.004640,0.117856,267.496307,13.626910,1.178560,-251.094971,0.117882,0.000000
92.670006,60.093842,-250.961533,0.007808,0.004640,0.117856,267.310760,13.617459,1.178560,-250.961533,0.117882,0.000000
92.930008,60.070381,-251.050491,0.007825,0.004640,0.117856,267.206390,13.612143,1.178560,-251.050491,0.117882,0.000000
93.190002,60.024956,-251.094971,0.007812,0.004640,0.117856,267.004333,13.601850,1.178560,-251.094971,0.117882,0.000000
93.450005,60.002609,-251.094971,0.007800,0.004640,0.117856,266.904938,13.596786,1.178560,-251.094971,0.117882,0.000000
93.710007,59.959045,-251.094971,0.007825,0.004640,0.117856,266.711151,13.586914,1.178560,-251.094971,0.117882,0.000000
93.970001,59.938194,-251.050491,0.007795,0.004640,0.117856,266.618408,13.582190,1.178560,-251.050491,0.117882,0.000000
94.230003,59.902817,-251.139450,0.007821,0.004640,0.117856,266.461029,13.574172,1.178560,-251.139450,0.117882,0.000000
94.490005,59.862602,-251.094971,0.007821,0.004640,0.117856,266.282166,13.565059,1.178560,-251.094971,0.117882,0.000000
94.750008,59.839516,-251.050491,0.007834,0.004640,0.117856,266.179474,13.559828,1.178560,-251.050491,0.117882,0.000000
95.010002,59.795944,-251.094971,0.007808,0.004640,0.117856,265.985657,13.549954,1.178560,-251.094971,0.117882,0.000000
95.270004,59.787384,-251.094971,0.007843,0.004640,0.117856,265.947571,13.548016,1.178560,-251.094971,0.117882,0.000000
95.530006,59.747910,-251.094971,0.007812,0.004640,0.117856,265.771973,13.539069,1.178560,-251.094971,0.117882,0.000000
95.790001,59.706207,-251.139450,0.007804,0.004640,0.117856,265.586487,13.529620,1.178560,-251.139450,0.117882,0.000000
96.050003,59.685722,-251.094971,0.007804,0.004640,0.117856,265.495361,13.524978,1.178560,-251.094971,0.117882,0.000000
96.310005,59.654076,-251.183929,0.007830,0.004640,0.117856,265.354584,13.517807,1.178560,-251.183929,0.117882,0.000000
96.570007,59.623161,-251.183929,0.007834,0.004640,0.117856,265.217072,13.510801,1.178560,-251.183929,0.117882,0.000000
96.830002,59.584068,-251.228409,0.007791,0.004640,0.117856,265.043182,13.501944,1.178560,-251.228409,0.117882,0.000000
97.090004,59.568428,-251.139450,0.007825,0.004640,0.117856,264.973602,13.498399,1.178560,-251.139450,0.117882,0.000000
97.350006,59.548317,-251.139450,0.007795,0.004640,0.117856,264.884155,13.493842,1.178560,-251.139450,0.117882,0.000000
97.610008,59.513313,-251.228409,0.007795,0.004640,0.117856,264.728424,13.485910,1.178560,-251.228409,0.117882,0.000000
97.870003,59.499168,-251.183929,0.007834,0.004640,0.117856,264.665527,13.482704,1.178560,-251.183929,0.117882,0.000000
98.130005,59.477943,-251.139450,0.007830,0.004640,0.117856,264.571106,13.477895,1.178560,-251.139450,0.117882,0.000000
98.390007,59.458946,-251.183929,0.007821,0.004640,0.117856,264.486603,13.473590,1.178560,-251.183929,0.117882,0.000000
98.650002,59.422829,-251.139450,0.007825,0.004640,0.117856,264.325958,13.465405,1.178560,-251.139450,0.117882,0.000000
98.910004,59.405701,-251.228409,0.007821,0.004640,0.117856,264.249756,13.461524,1.178560,-251.228409,0.117882,0.000000
99.170006,59.374794,-251.183929,0.007843,0.004640,0.117856,264.112274,13.454520,1.178560,-251.183929,0.117882,0.000000
99.430008,59.357292,-251.228409,0.007825,0.004640,0.117856,264.034424,13.450555,1.178560,-251.228409,0.117882,0.000000
99.690002,59.330856,-251.228409,0.007795,0.004640,0.117856,263.916840,13.444564,1.178560,-251.228409,0.117882,0.000000
99.950005,59.307022,-251.228409,0.007856,0.004640,0.117856,263.810822,13.439163,1.178560,-251.228409,0.117882,0.000000
100.210007,59.291008,-251.272888,0.007838,0.004640,0.117856,263.739563,13.435534,1.178560,-251.272888,0.117882,0.000000
100.470001,59.258614,-251.272888,0.007791,0.004640,0.117856,263.595490,13.428194,1.178560,-251.272888,0.117882,0.000000
100.730003,59.235901,-251.272888,0.007808,0.004640,0.117856,263.494446,13.423047,1.178560,-251.272888,0.117882,0.000000
100.990005,59.228821,-251.272888,0.007821,0.004640,0.117856,263.462952,13.421442,1.178560,-251.272888,0.117882,0.000000
101.250008,59.194939,-251.228409,0.007838,0.004640,0.117856,263.312225,13.413765,1.178560,-251.228409,0.117882,0.000000
101.510002,59.171104,-251.317368,0.007834,0.004640,0.117856,263.206207,13.408364,1.178560,-251.317368,0.117882,0.000000
101.770004,59.162537,-251.272888,0.007830,0.004640,0.117856,263.168121,13.406423,1.178560,-251.272888,0.117882,0.000000
102.030006,59.126045,-251.317368,0.007847,0.004640,0.117856,263.005798,13.398153,1.178560,-251.317368,0.117882,0.000000
102.290009,59.123070,-251.317368,0.007825,0.004640,0.117856,262.992554,13.397479,1.178560,-251.317368,0.117882,0.000000
102.550003,59.102219,-251.272888,0.007817,0.004640,0.117856,262.899811,13.392755,1.178560,-251.272888,0.117882,0.000000
102.810005,59.079872,-251.361847,0.007843,0.004640,0.117856,262.800385,13.387691,1.178560,-251.361847,0.117882,0.000000
103.070007,59.069077,-251.317368,0.007812,0.004640,0.117856,262.752380,13.385244,1.178560,-251.317368,0.117882,0.000000
103.330002,59.047104,-251.361847,0.007834,0.004640,0.117856,262.654633,13.380265,1.178560,-251.361847,0.117882,0.000000
103.590004,59.024765,-251.406342,0.007808,0.004640,0.117856,262.555267,13.375203,1.178560,-251.406342,0.117882,0.000000
103.850006,59.008751,-251.317368,0.007812,0.004640,0.117856,262.484039,13.371573,1.178560,-251.317368,0.117882,0.000000
104.110008,58.992363,-251.361847,0.007864,0.004640,0.117856,262.411133,13.367861,1.178560,-251.361847,0.117882,0.000000
104.370003,58.976357,-251.361847,0.007847,0.004640,0.117856,262.339935,13.364234,1.178560,-251.361847,0.117882,0.000000
104.630005,58.937256,-251.361847,0.007821,0.004640,0.117856,262.166016,13.355373,1.178560,-251.361847,0.117882,0.000000
104.890007,58.942841,-251.361847,0.007817,0.004640,0.117856,262.190857,13.356639,1.178560,-251.361847,0.117882,0.000000
105.150002,58.912682,-251.317368,0.007830,0.004640,0.117856,262.056702,13.349805,1.178560,-251.317368,0.117882,0.000000
105.410004,58.895180,-251.361847,0.007834,0.004640,0.117856,261.978851,13.345839,1.178560,-251.361847,0.117882,0.000000
105.670006,58.878792,-251.361847,0.007830,0.004640,0.117856,261.905945,13.342125,1.178560,-251.361847,0.117882,0.000000
105.930008,58.863152,-251.361847,0.007795,0.004640,0.117856,261.836365,13.338581,1.178560,-251.361847,0.117882,0.000000
106.190002,58.848999,-251.450821,0.007838,0.004640,0.117856,261.773407,13.335374,1.178560,-251.450821,0.117882,0.000000
106.450005,58.836342,-251.361847,0.007847,0.004640,0.117856,261.717133,13.332505,1.178560,-251.361847,0.117882,0.000000
106.710007,58.806549,-251.406342,0.007847,0.004640,0.117856,261.584595,13.325754,1.178560,-251.406342,0.117882,0.000000
106.970009,58.790169,-251.406342,0.007812,0.004640,0.117856,261.511719,13.322042,1.178560,-251.406342,0.117882,0.000000
107.230003,58.787560,-251.406342,0.007851,0.004640,0.117856,261.500122,13.321452,1.178560,-251.406342,0.117882,0.000000
107.490005,58.768196,-251.450821,0.007808,0.004640,0.117856,261.414001,13.317063,1.178560,-251.450821,0.117882,0.000000
107.750008,58.749207,-251.406342,0.007817,0.004640,0.117856,261.329529,13.312760,1.178560,-251.406342,0.117882,0.000000
107.900002,58.749207,-251.406342,0.007830,0.004640,0.117856,261.329529,13.312760,1.178560,-251.406342,0.117882,0.000000