File: Data/compression sample NH 10,12,15/AutoNoheating-12-2-1-240201_02012024_183453.csv
Time (sec),S:Load (lbs),S:HL1 (DIM),S:LVDT (in),S:Position (in),Ch:Position (mm),Ch:Load (N),Ch:Stress (MPa),Ch:Strain (mm/mm),Ch:HL1 (DIM),Set Point (),Cycles ()
0.110000,-0.006332,-186.686554,-0.000017,-0.000000,-0.000000,-0.028168,-0.001435,-0.000000,-186.686554,-0.000017,0.000000
0.340000,-0.010422,-186.642075,-0.000013,-0.000000,-0.000000,-0.046358,-0.002362,-0.000000,-186.642075,0.000121,0.000000
0.570000,0.003349,-186.642075,0.000013,0.000131,0.003322,0.014898,0.000759,0.033216,-186.642075,0.003955,0.000000
0.800000,0.022713,-186.686554,0.000000,0.000271,0.006895,0.101031,0.005147,0.068946,-186.686554,0.007788,0.000000
1.030000,-0.020851,-186.642075,0.000155,0.000418,0.010606,-0.092750,-0.004725,0.106064,-186.642075,0.011621,0.000000
1.260000,-0.013779,-186.686554,0.000285,0.000571,0.014492,-0.061291,-0.003122,0.144916,-186.686554,0.015454,0.000000
1.490000,0.010429,-186.686554,0.000440,0.000719,0.018273,0.046392,0.002363,0.182727,-186.686554,0.019287,0.000000
1.720000,0.022713,-186.686554,0.000617,0.000863,0.021915,0.101031,0.005147,0.219149,-186.686554,0.023120,0.000000
1.950000,-0.004463,-186.686554,0.000780,0.001019,0.025887,-0.019853,-0.001011,0.258868,-186.686554,0.026936,0.000000
2.180000,-0.017876,-186.686554,0.000940,0.001170,0.029720,-0.079515,-0.004051,0.297201,-186.686554,0.030769,0.000000
2.410000,-0.045425,-186.731033,0.001095,0.001318,0.033475,-0.202062,-0.010294,0.334751,-186.731033,0.034602,0.000000
2.640000,-0.006699,-186.642075,0.001229,0.001469,0.037317,-0.029797,-0.001518,0.373168,-186.642075,0.038436,0.000000
2.870000,0.025322,-186.731033,0.001393,0.001619,0.041124,0.112638,0.005738,0.411240,-186.731033,0.042269,0.000000
3.100000,0.018250,-186.731033,0.001582,0.001773,0.045035,0.081178,0.004135,0.450353,-186.731033,0.046102,0.000000
3.330000,0.020851,-186.775513,0.001720,0.001931,0.049059,0.092750,0.004725,0.490591,-186.775513,0.049935,0.000000
3.560000,-0.007820,-186.731033,0.001867,0.002076,0.052727,-0.034786,-0.001772,0.527274,-186.731033,0.053768,0.000000
3.790000,0.010056,-186.731033,0.002070,0.002227,0.056569,0.044729,0.002279,0.565694,-186.731033,0.057601,0.000000
4.020000,0.007446,-186.731033,0.002199,0.002372,0.060246,0.033123,0.001687,0.602464,-186.731033,0.061435,0.000000
4.250000,0.022346,-186.731033,0.002354,0.002526,0.064157,0.099402,0.005064,0.641574,-186.731033,0.065267,0.000000
4.480000,-0.010056,-186.819992,0.002505,0.002682,0.068129,-0.044729,-0.002279,0.681292,-186.819992,0.069101,0.000000
4.710000,-0.064789,-186.819992,0.002686,0.002829,0.071859,-0.288195,-0.014681,0.718585,-186.819992,0.072916,0.000000
4.940000,-0.020477,-186.775513,0.002828,0.002977,0.075613,-0.091088,-0.004640,0.756135,-186.775513,0.076750,0.000000
5.170000,0.014526,-186.731033,0.003001,0.003132,0.079542,0.064617,0.003292,0.795422,-186.731033,0.080583,0.000000
5.400000,0.035378,-186.864471,0.003134,0.003277,0.083245,0.157367,0.008017,0.832450,-186.864471,0.084416,0.000000
5.630000,0.029793,-186.819992,0.003294,0.003440,0.087382,0.132525,0.006751,0.873819,-186.819992,0.088249,0.000000
5.860000,0.023460,-186.819992,0.003445,0.003588,0.091137,0.104357,0.005316,0.911369,-186.819992,0.092082,0.000000
6.090000,-0.017876,-186.819992,0.003570,0.003733,0.094814,-0.079515,-0.004051,0.948139,-186.819992,0.095915,0.000000
6.320000,0.013031,-186.819992,0.003773,0.003884,0.098656,0.057965,0.002953,0.986556,-186.819992,0.099748,0.000000
6.550000,0.018623,-186.819992,0.003915,0.004037,0.102541,0.082841,0.004220,1.025408,-186.819992,0.103582,0.000000
6.780000,-0.016754,-186.864471,0.004092,0.004187,0.106339,-0.074526,-0.003797,1.063393,-186.864471,0.107415,0.000000
7.010000,-0.001488,-186.864471,0.004195,0.004341,0.110268,-0.006618,-0.000337,1.102680,-186.864471,0.111248,0.000000
7.240000,0.011169,-186.775513,0.004389,0.004486,0.113954,0.049684,0.002531,1.139537,-186.775513,0.115081,0.000000
7.470000,0.003349,-186.819992,0.004549,0.004640,0.117847,0.014898,0.000759,1.178473,-186.819992,0.118914,0.000000
7.700000,0.021225,-186.908951,0.004717,0.004794,0.121767,0.094413,0.004810,1.217673,-186.908951,0.122730,0.000000
7.930000,0.037239,-186.864471,0.004855,0.004936,0.125384,0.165648,0.008438,1.253837,-186.864471,0.126563,0.000000
8.160001,0.022713,-186.864471,0.005027,0.005095,0.129416,0.101031,0.005147,1.294162,-186.864471,0.130396,0.000000
8.390000,-0.011917,-186.864471,0.005161,0.005244,0.133189,-0.053010,-0.002700,1.331886,-186.864471,0.134229,0.000000
8.620001,-0.027557,-186.908951,0.005355,0.005393,0.136970,-0.122581,-0.006245,1.369697,-186.908951,0.138062,0.000000
8.850000,0.012291,-186.864471,0.005493,0.005548,0.140924,0.054673,0.002785,1.409241,-186.864471,0.141896,0.000000
9.080001,0.026070,-186.953430,0.005648,0.005693,0.144593,0.115964,0.005907,1.445928,-186.953430,0.145729,0.000000
9.310000,0.030167,-186.908951,0.005782,0.005842,0.148382,0.134188,0.006836,1.483823,-186.908951,0.149562,0.000000
9.540001,0.023087,-186.908951,0.005959,0.006001,0.152432,0.102694,0.005231,1.524325,-186.908951,0.153395,0.000000
9.770000,-0.000374,-186.908951,0.006127,0.006149,0.156196,-0.001663,-0.000085,1.561962,-186.908951,0.157228,0.000000
10.000000,0.018623,-186.953430,0.006260,0.006299,0.160003,0.082841,0.004220,1.600034,-186.953430,0.161061,0.000000
10.230000,0.034264,-186.953430,0.006446,0.006448,0.163785,0.152412,0.007764,1.637845,-186.953430,0.164894,0.000000
10.460000,0.021599,-186.953430,0.006562,0.006596,0.167540,0.096076,0.004894,1.675395,-186.953430,0.168710,0.000000
10.690001,0.012665,-186.953430,0.006722,0.006753,0.171537,0.056336,0.002870,1.715375,-186.953430,0.172544,0.000000
10.920000,-0.023827,-186.908951,0.006890,0.006902,0.175310,-0.105986,-0.005399,1.753099,-186.908951,0.176376,0.000000
11.150001,-0.019737,-186.908951,0.007062,0.007052,0.179108,-0.087796,-0.004473,1.791084,-186.908951,0.180209,0.000000
11.380000,0.037613,-186.997925,0.007205,0.007203,0.182959,0.167311,0.008523,1.829588,-186.997925,0.184043,0.000000
11.610001,0.074478,-186.997925,0.007373,0.007348,0.186645,0.331295,0.016877,1.866445,-186.997925,0.187876,0.000000
11.840000,0.145599,-186.953430,0.007537,0.007512,0.190807,0.647658,0.032993,1.908072,-186.953430,0.191709,0.000000
12.070001,0.255447,-186.953430,0.007713,0.007661,0.194597,1.136287,0.057885,1.945970,-186.953430,0.195542,0.000000
12.300000,0.442383,-186.997925,0.007890,0.007809,0.198352,1.967817,0.100245,1.983520,-186.997925,0.199375,0.000000
12.530001,0.685539,-186.997925,0.008088,0.000022,0.000564,3.049431,0.155345,0.005636,-186.997925,0.000520,0.000000
12.760000,0.631172,-187.042404,0.008080,0.000011,0.000269,2.807594,0.143026,0.002687,-187.042404,0.000520,0.000000
12.990001,0.611809,-186.997925,0.008058,0.000011,0.000269,2.721461,0.138638,0.002687,-186.997925,0.000520,0.000000
13.220000,0.532867,-187.042404,0.008075,0.000011,0.000269,2.370313,0.120749,0.002687,-187.042404,0.000841,0.000000
13.450001,0.550743,-186.997925,0.008097,0.000011,0.000269,2.449828,0.124800,0.002687,-186.997925,0.001223,0.000000
13.680000,0.529518,-187.086884,0.008075,0.000011,0.000269,2.355414,0.119991,0.002687,-187.086884,0.001604,0.000000
13.910001,0.640106,-187.086884,0.008071,0.000040,0.001014,2.847335,0.145050,0.010144,-187.086884,0.001986,0.000000
14.140000,0.682190,-187.042404,0.008106,0.000060,0.001526,3.034532,0.154586,0.015261,-187.042404,0.002376,0.000000
14.370001,0.733200,-187.042404,0.008136,0.000080,0.002038,3.261437,0.166146,0.020378,-187.042404,0.002758,0.000000
14.600000,0.726501,-187.042404,0.008132,0.000093,0.002350,3.231640,0.164628,0.023500,-187.042404,0.003139,0.000000
14.830001,0.730972,-187.086884,0.008166,0.000107,0.002723,3.251527,0.165641,0.027229,-187.086884,0.003521,0.000000
15.060000,0.773788,-187.042404,0.008183,0.000120,0.003053,3.441983,0.175343,0.030525,-187.042404,0.003902,0.000000
15.290001,0.812889,-187.042404,0.008222,0.000137,0.003478,3.615911,0.184203,0.034776,-187.042404,0.004292,0.000000
15.520000,0.802834,-187.086884,0.008231,0.000139,0.003538,3.571182,0.181925,0.035381,-187.086884,0.004674,0.000000
15.750001,0.822945,-187.131363,0.008244,0.000158,0.004015,3.660640,0.186482,0.040150,-187.131363,0.005056,0.000000
15.980000,0.882523,-187.131363,0.008244,0.000178,0.004509,3.925657,0.199982,0.045093,-187.131363,0.005437,0.000000
16.210001,0.911942,-187.131363,0.008257,0.000196,0.004978,4.056519,0.206649,0.049779,-187.131363,0.005819,0.000000
16.440001,0.929443,-187.042404,0.008282,0.000212,0.005385,4.134370,0.210615,0.053851,-187.042404,0.006209,0.000000
16.670000,0.915665,-187.131363,0.008308,0.000226,0.005750,4.073080,0.207493,0.057496,-187.131363,0.006591,0.000000
16.900002,0.929817,-187.131363,0.008321,0.000237,0.006018,4.136034,0.210700,0.060184,-187.131363,0.006972,0.000000
17.130001,1.003174,-187.175842,0.008326,0.000257,0.006530,4.462340,0.227322,0.065301,-187.175842,0.007354,0.000000
17.360001,1.015091,-187.175842,0.008347,0.000271,0.006894,4.515350,0.230023,0.068942,-187.175842,0.007736,0.000000
17.590000,1.038918,-187.086884,0.008373,0.000285,0.007233,4.621336,0.235422,0.072326,-187.086884,0.008126,0.000000
17.820002,1.041153,-187.131363,0.008386,0.000294,0.007458,4.631279,0.235929,0.074581,-187.131363,0.008507,0.000000
18.050001,1.089935,-187.175842,0.008395,0.000318,0.008082,4.848274,0.246983,0.080823,-187.175842,0.008889,0.000000
18.280001,1.104828,-187.220322,0.008433,0.000334,0.008490,4.914520,0.250358,0.084899,-187.220322,0.009270,0.000000
18.510000,1.115257,-187.175842,0.008420,0.000344,0.008742,4.960912,0.252721,0.087416,-187.175842,0.009652,0.000000
18.740002,1.124939,-187.220322,0.008429,0.000361,0.009158,5.003978,0.254915,0.091576,-187.220322,0.010042,0.000000
18.970001,1.147278,-187.086884,0.008455,0.000375,0.009522,5.103347,0.259977,0.095220,-187.086884,0.010424,0.000000
19.200001,1.232552,-187.220322,0.008468,0.000395,0.010025,5.482663,0.279300,0.100251,-187.220322,0.010805,0.000000
19.430000,1.243355,-187.264801,0.008511,0.000408,0.010363,5.530718,0.281748,0.103630,-187.264801,0.011187,0.000000
19.660002,1.266441,-187.175842,0.008520,0.000419,0.010641,5.633412,0.286980,0.106409,-187.175842,0.011577,0.000000
19.890001,1.276497,-187.220322,0.008511,0.000435,0.011040,5.678142,0.289258,0.110398,-187.220322,0.011959,0.000000
20.120001,1.330116,-187.220322,0.008558,0.000454,0.011542,5.916653,0.301409,0.115424,-187.220322,0.012340,0.000000
20.350000,1.337936,-187.220322,0.008606,0.000468,0.011881,5.951438,0.303181,0.118808,-187.220322,0.012722,0.000000
20.580002,1.328255,-187.264801,0.008610,0.000480,0.012193,5.908372,0.300987,0.121930,-187.264801,0.013104,0.000000
20.810001,1.332726,-187.220322,0.008593,0.000497,0.012618,5.928259,0.302000,0.126181,-187.220322,0.013494,0.000000
21.040001,1.400864,-187.264801,0.008627,0.000511,0.012982,6.231353,0.317440,0.129822,-187.264801,0.013875,0.000000
21.270000,1.451134,-187.264801,0.008653,0.000526,0.013372,6.454965,0.328832,0.133724,-187.264801,0.014257,0.000000
21.500002,1.406082,-187.264801,0.008675,0.000527,0.013390,6.254566,0.318623,0.133898,-187.264801,0.014638,0.000000
21.730001,1.353577,-187.309280,0.008670,0.000528,0.013407,6.021010,0.306725,0.134072,-187.309280,0.015020,0.000000
21.960001,1.572533,-187.309280,0.008709,0.000572,0.014517,6.994975,0.356341,0.145173,-187.309280,0.015411,0.000000
22.190001,1.572906,-187.264801,0.008722,0.000591,0.015020,6.996637,0.356426,0.150204,-187.264801,0.015792,0.000000
22.420002,1.568810,-187.309280,0.008709,0.000602,0.015280,6.978413,0.355497,0.152804,-187.309280,0.016174,0.000000
22.650002,1.589661,-187.264801,0.008739,0.000621,0.015766,7.071164,0.360222,0.157660,-187.264801,0.016555,0.000000
22.880001,1.602692,-187.264801,0.008778,0.000631,0.016018,7.129128,0.363175,0.160177,-187.264801,0.016937,0.000000
23.110001,1.696899,-187.309280,0.008783,0.000648,0.016451,7.548185,0.384523,0.164510,-187.309280,0.017327,0.000000
23.340002,1.714775,-187.264801,0.008795,0.000662,0.016807,7.627700,0.388574,0.168068,-187.264801,0.017709,0.000000
23.570002,1.749779,-187.264801,0.008817,0.000674,0.017127,7.783405,0.396506,0.171274,-187.264801,0.018090,0.000000
23.800001,1.748291,-187.309280,0.008830,0.000686,0.017431,7.776787,0.396168,0.174310,-187.309280,0.018472,0.000000
24.030001,1.858887,-187.398254,0.008843,0.000712,0.018073,8.268741,0.421230,0.180729,-187.398254,0.018853,0.000000
24.260000,1.849205,-187.309280,0.008877,0.000721,0.018315,8.225675,0.419036,0.183155,-187.309280,0.019244,0.000000
24.490002,1.877502,-187.353760,0.008890,0.000739,0.018767,8.351548,0.425448,0.187666,-187.353760,0.019625,0.000000
24.720001,1.908035,-187.309280,0.008912,0.000753,0.019131,8.487365,0.432367,0.191308,-187.309280,0.020007,0.000000
24.950001,1.948997,-187.398254,0.008946,0.000770,0.019547,8.669574,0.441649,0.195471,-187.398254,0.020388,0.000000
25.180000,1.976555,-187.442734,0.008942,0.000784,0.019911,8.792155,0.447894,0.199112,-187.442734,0.020770,0.000000
25.410002,1.964264,-187.398254,0.008946,0.000795,0.020180,8.737482,0.445109,0.201803,-187.398254,0.021160,0.000000
25.640001,2.084167,-187.353760,0.008972,0.000817,0.020744,9.270840,0.472279,0.207439,-187.353760,0.021542,0.000000
25.870001,2.129601,-187.353760,0.008998,0.000834,0.021186,9.472937,0.482574,0.211863,-187.353760,0.021923,0.000000
26.100000,2.154549,-187.398254,0.008998,0.000848,0.021550,9.583911,0.488228,0.215504,-187.398254,0.022305,0.000000
26.330002,2.139282,-187.398254,0.009037,0.000862,0.021906,9.516003,0.484768,0.219058,-187.398254,0.022686,0.000000
26.560001,2.183220,-187.353760,0.009037,0.000877,0.022287,9.711447,0.494725,0.222874,-187.353760,0.023077,0.000000
26.790001,2.193275,-187.353760,0.009071,0.000888,0.022556,9.756176,0.497003,0.225565,-187.353760,0.023458,0.000000
27.020000,2.264397,-187.398254,0.009063,0.000907,0.023042,10.072539,0.513120,0.230421,-187.398254,0.023840,0.000000
27.250002,2.292328,-187.398254,0.009076,0.000920,0.023363,10.196784,0.519449,0.233630,-187.398254,0.024221,0.000000
27.480001,2.347809,-187.442734,0.009106,0.000933,0.023701,10.443575,0.532021,0.237010,-187.442734,0.024603,0.000000
27.710001,2.425636,-187.487213,0.009123,0.000952,0.024170,10.789769,0.549657,0.241696,-187.487213,0.024993,0.000000
27.940001,2.517242,-187.353760,0.009158,0.000972,0.024698,11.197253,0.570415,0.246983,-187.353760,0.025375,0.000000
28.170002,2.454308,-187.353760,0.009153,0.000985,0.025019,10.917305,0.556154,0.250193,-187.353760,0.025757,0.000000
28.400002,2.472183,-187.487213,0.009149,0.000999,0.025366,10.996820,0.560205,0.253664,-187.487213,0.026138,0.000000
28.630001,2.501602,-187.531693,0.009209,0.001011,0.025687,11.127683,0.566871,0.256869,-187.531693,0.026528,0.000000
28.860001,2.609589,-187.442734,0.009227,0.001031,0.026181,11.608030,0.591341,0.261813,-187.442734,0.026910,0.000000
29.090002,2.643471,-187.442734,0.009240,0.001044,0.026528,11.758745,0.599019,0.265283,-187.442734,0.027291,0.000000
29.320002,2.674751,-187.487213,0.009244,0.001055,0.026797,11.897888,0.606107,0.267971,-187.487213,0.027673,0.000000
29.550001,2.786835,-187.531693,0.009274,0.001075,0.027317,12.396460,0.631506,0.273175,-187.531693,0.028054,0.000000
29.780001,2.885513,-187.531693,0.009287,0.001093,0.027768,12.835404,0.653867,0.277683,-187.531693,0.028445,0.000000
30.010002,2.867645,-187.442734,0.009287,0.001106,0.028098,12.755923,0.649818,0.280979,-187.442734,0.028827,0.000000
30.240002,2.852005,-187.531693,0.009313,0.001121,0.028462,12.686352,0.646274,0.284620,-187.531693,0.029208,0.000000
30.470001,2.867645,-187.487213,0.009326,0.001132,0.028749,12.755923,0.649818,0.287485,-187.487213,0.029590,0.000000
30.700001,2.955894,-187.531693,0.009334,0.001149,0.029173,13.148476,0.669815,0.291732,-187.531693,0.029971,0.000000
30.930002,3.014359,-187.576172,0.009343,0.001165,0.029590,13.408536,0.683063,0.295896,-187.576172,0.030361,0.000000
31.160002,3.057182,-187.487213,0.009369,0.001176,0.029858,13.599026,0.692767,0.298583,-187.487213,0.030743,0.000000
31.390001,2.999458,-187.487213,0.009365,0.001183,0.030049,13.342257,0.679687,0.300490,-187.487213,0.031125,0.000000
31.620001,3.206131,-187.531693,0.009399,0.001209,0.030717,14.261583,0.726520,0.307171,-187.531693,0.031506,0.000000
31.850002,3.291031,-187.576172,0.009429,0.001227,0.031159,14.639236,0.745758,0.311591,-187.576172,0.031888,0.000000
32.080002,3.243736,-187.576172,0.009442,0.001237,0.031420,14.428860,0.735041,0.314195,-187.576172,0.032278,0.000000
32.310001,3.345024,-187.576172,0.009477,0.001255,0.031879,14.879411,0.757993,0.318790,-187.576172,0.032659,0.000000
32.540001,3.343163,-187.487213,0.009464,0.001267,0.032183,14.871130,0.757571,0.321826,-187.487213,0.033041,0.000000
32.770000,3.467903,-187.576172,0.009503,0.001285,0.032651,15.426003,0.785838,0.326508,-187.576172,0.033423,0.000000
33.000000,3.458595,-187.576172,0.009494,0.001297,0.032937,15.384600,0.783729,0.329369,-187.576172,0.033804,0.000000
33.230003,3.393433,-187.620651,0.009516,0.001305,0.033154,15.094742,0.768963,0.331538,-187.620651,0.034195,0.000000
33.460003,3.688721,-187.620651,0.009528,0.001332,0.033839,16.408249,0.835876,0.338389,-187.620651,0.034576,0.000000
33.690002,3.680901,-187.531693,0.009541,0.001345,0.034160,16.373463,0.834104,0.341598,-187.531693,0.034958,0.000000
33.920002,3.717026,-187.576172,0.009585,0.001358,0.034498,16.534157,0.842290,0.344982,-187.576172,0.035339,0.000000
34.150002,3.762825,-187.665131,0.009585,0.001373,0.034871,16.737881,0.852668,0.348710,-187.665131,0.035721,0.000000
34.380001,3.798576,-187.665131,0.009576,0.001388,0.035261,16.896912,0.860770,0.352612,-187.665131,0.036111,0.000000
34.610001,3.919220,-187.620651,0.009602,0.001405,0.035686,17.433561,0.888108,0.356863,-187.620651,0.036493,0.000000
34.840000,3.937469,-187.620651,0.009628,0.001417,0.035990,17.514738,0.892243,0.359898,-187.620651,0.036874,0.000000
35.070004,3.921082,-187.665131,0.009645,0.001425,0.036207,17.441841,0.888530,0.362067,-187.665131,0.037256,0.000000
35.300003,4.085670,-187.665131,0.009658,0.001446,0.036718,18.173969,0.925826,0.367180,-187.665131,0.037637,0.000000
35.530003,4.210793,-187.665131,0.009653,0.001463,0.037169,18.730541,0.954179,0.371692,-187.665131,0.038028,0.000000
35.760002,4.381706,-187.665131,0.009692,0.001482,0.037655,19.490803,0.992909,0.376548,-187.665131,0.038409,0.000000
35.990002,4.338142,-187.665131,0.009714,0.001496,0.037993,19.297022,0.983037,0.379932,-187.665131,0.038791,0.000000
36.220001,4.373146,-187.620651,0.009722,0.001510,0.038349,19.452724,0.990969,0.383486,-187.620651,0.039173,0.000000
36.450001,4.408516,-187.709610,0.009731,0.001524,0.038713,19.610058,0.998984,0.387127,-187.709610,0.039554,0.000000
36.680000,4.484108,-187.754089,0.009748,0.001537,0.039042,19.946308,1.016113,0.390423,-187.754089,0.039944,0.000000
36.910000,4.360855,-187.754089,0.009748,0.001542,0.039155,19.398052,0.988184,0.391551,-187.754089,0.040326,0.000000
37.140003,4.758919,-187.709610,0.009770,0.001566,0.039780,21.168728,1.078386,0.397796,-187.709610,0.040707,0.000000
37.370003,4.880318,-187.709610,0.009779,0.001583,0.040213,21.708736,1.105896,0.402130,-187.709610,0.041089,0.000000
37.600002,4.989044,-187.754089,0.009822,0.001603,0.040716,22.192377,1.130534,0.407160,-187.754089,0.041479,0.000000
37.830002,4.957024,-187.754089,0.009839,0.001614,0.040985,22.049942,1.123278,0.409847,-187.754089,0.041861,0.000000
38.060001,5.040810,-187.754089,0.009856,0.001630,0.041401,22.422642,1.142264,0.414011,-187.754089,0.042242,0.000000
38.290001,5.124588,-187.754089,0.009860,0.001645,0.041774,22.795305,1.161248,0.417743,-187.754089,0.042624,0.000000
38.520000,5.267952,-187.754089,0.009856,0.001661,0.042182,23.433022,1.193735,0.421815,-187.754089,0.043005,0.000000
38.750000,5.339447,-187.754089,0.009882,0.001674,0.042511,23.751047,1.209936,0.425112,-187.754089,0.043396,0.000000
38.980003,5.357697,-187.798569,0.009921,0.001686,0.042823,23.832224,1.214071,0.428234,-187.798569,0.043777,0.000000
39.210003,5.567345,-187.798569,0.009904,0.001705,0.043300,24.764786,1.261578,0.433003,-187.798569,0.044159,0.000000
39.440002,5.781082,-187.754089,0.009938,0.001723,0.043760,25.715538,1.310012,0.437602,-187.754089,0.044541,0.000000
39.670002,5.773262,-187.709610,0.009951,0.001735,0.044081,25.680752,1.308240,0.440808,-187.709610,0.044922,0.000000
39.900002,5.755760,-187.798569,0.009960,0.001748,0.044402,25.602900,1.304274,0.444017,-187.798569,0.045312,0.000000
40.130001,5.872688,-187.798569,0.009964,0.001762,0.044758,26.123022,1.330770,0.447575,-187.798569,0.045694,0.000000
40.360001,5.947906,-187.798569,0.009998,0.001775,0.045087,26.457609,1.347815,0.450868,-187.798569,0.046075,0.000000
40.590000,6.355286,-187.798569,0.010011,0.001798,0.045676,28.269722,1.440128,0.456765,-187.798569,0.046457,0.000000
40.820004,6.337410,-187.798569,0.010042,0.001811,0.045989,28.190208,1.436078,0.459887,-187.798569,0.046839,0.000000
41.050003,6.356773,-187.798569,0.010046,0.001822,0.046266,28.276340,1.440465,0.462662,-187.798569,0.047229,0.000000
41.280003,6.643501,-187.887543,0.010050,0.001841,0.046752,29.551769,1.505439,0.467518,-187.887543,0.047611,0.000000
41.510002,6.816650,-187.754089,0.010093,0.001858,0.047186,30.321976,1.544675,0.471855,-187.754089,0.047992,0.000000
41.740002,6.805107,-187.843063,0.010076,0.001868,0.047446,30.270628,1.542059,0.474459,-187.843063,0.048374,0.000000
41.970001,7.004700,-187.843063,0.010106,0.001886,0.047914,31.158461,1.587288,0.479141,-187.843063,0.048755,0.000000
42.200001,7.084763,-187.887543,0.010132,0.001900,0.048252,31.514597,1.605430,0.482521,-187.887543,0.049145,0.000000
42.430000,7.383034,-187.887543,0.010123,0.001916,0.048668,32.841373,1.673019,0.486685,-187.887543,0.049527,0.000000
42.660004,7.350258,-187.887543,0.010145,0.001926,0.048911,32.695580,1.665592,0.489114,-187.887543,0.049909,0.000000
42.890003,7.498093,-187.843063,0.010167,0.001940,0.049276,33.353184,1.699092,0.492755,-187.843063,0.050290,0.000000
43.120003,7.703270,-187.843063,0.010162,0.001957,0.049701,34.265858,1.745586,0.497006,-187.843063,0.050672,0.000000
43.350002,8.243584,-187.887543,0.010188,0.001980,0.050290,36.669292,1.868023,0.502903,-187.887543,0.051062,0.000000
43.580002,8.171341,-187.976501,0.010201,0.001992,0.050594,36.347939,1.851652,0.505938,-187.976501,0.051444,0.000000
43.810001,8.246193,-187.887543,0.010218,0.002006,0.050958,36.680897,1.868614,0.509579,-187.887543,0.051825,0.000000
44.040001,8.545578,-187.887543,0.010236,0.002024,0.051400,38.012630,1.936456,0.514004,-187.887543,0.052207,0.000000
44.270000,8.488602,-187.887543,0.010257,0.002033,0.051643,37.759186,1.923545,0.516430,-187.887543,0.052588,0.000000
44.500004,8.797676,-187.932022,0.010287,0.002049,0.052042,39.134018,1.993582,0.520419,-187.932022,0.052979,0.000000
44.730003,9.065407,-187.932022,0.010287,0.002065,0.052450,40.324944,2.054250,0.524496,-187.932022,0.053360,0.000000
44.960003,9.194992,-187.932022,0.010300,0.002078,0.052771,40.901367,2.083615,0.527705,-187.932022,0.053742,0.000000
45.190002,9.211754,-187.887543,0.010296,0.002089,0.053048,40.975929,2.087413,0.530480,-187.887543,0.054123,0.000000
45.420002,9.830261,-187.976501,0.010339,0.002112,0.053646,43.727184,2.227569,0.536463,-187.976501,0.054513,0.000000
45.650002,9.870110,-187.976501,0.010343,0.002124,0.053950,43.904442,2.236599,0.539499,-187.976501,0.054895,0.000000
45.880001,10.155716,-187.976501,0.010356,0.002141,0.054384,45.174881,2.301318,0.543836,-187.976501,0.055277,0.000000
46.110001,10.367226,-187.932022,0.010386,0.002155,0.054748,46.115723,2.349247,0.547477,-187.932022,0.055658,0.000000
46.340004,10.631607,-187.976501,0.010378,0.002171,0.055155,47.291752,2.409157,0.551554,-187.976501,0.056040,0.000000
46.570004,10.817421,-187.976501,0.010408,0.002185,0.055511,48.118290,2.451262,0.555108,-187.976501,0.056430,0.000000
46.800003,10.991692,-188.020981,0.010412,0.002199,0.055858,48.893486,2.490753,0.558579,-188.020981,0.056812,0.000000
47.030003,11.780746,-188.020981,0.010438,0.002222,0.056439,52.403378,2.669555,0.564388,-188.020981,0.057194,0.000000
47.260002,11.830276,-187.976501,0.010447,0.002235,0.056777,52.623699,2.680779,0.567772,-187.976501,0.057575,0.000000
47.490002,12.029869,-187.976501,0.010464,0.002250,0.057159,53.511532,2.726007,0.571587,-187.976501,0.057957,0.000000
47.720001,12.334839,-188.065460,0.010455,0.002266,0.057566,54.868103,2.795115,0.575664,-188.065460,0.058347,0.000000
47.950001,12.404846,-187.976501,0.010499,0.002278,0.057861,55.179512,2.810978,0.578612,-187.976501,0.058728,0.000000
48.180004,12.928032,-187.976501,0.010511,0.002297,0.058338,57.506760,2.929534,0.583381,-187.976501,0.059110,0.000000
48.410004,13.021492,-188.065460,0.010516,0.002307,0.058598,57.922489,2.950712,0.585981,-188.065460,0.059491,0.000000
48.640003,13.391258,-188.020981,0.010537,0.002321,0.058954,59.567291,3.034503,0.589539,-188.020981,0.059873,0.000000
48.870003,13.494781,-188.020981,0.010537,0.002336,0.059344,60.027786,3.057961,0.593441,-188.020981,0.060263,0.000000
49.100002,14.598862,-188.020981,0.010568,0.002360,0.059943,64.938980,3.308150,0.599425,-188.020981,0.060645,0.000000
49.330002,14.861389,-188.065460,0.010568,0.002376,0.060350,66.106758,3.367639,0.603501,-188.065460,0.061027,0.000000
49.560001,14.869576,-188.109940,0.010568,0.002388,0.060654,66.143173,3.369494,0.606537,-188.109940,0.061408,0.000000
49.790001,14.971611,-188.020981,0.010568,0.002401,0.060983,66.597054,3.392616,0.609830,-188.020981,0.061790,0.000000
50.020004,15.266899,-188.020981,0.010611,0.002415,0.061339,67.910561,3.459529,0.613388,-188.020981,0.062180,0.000000
50.250004,15.991165,-188.065460,0.010619,0.002432,0.061764,71.132256,3.623650,0.617638,-188.065460,0.062562,0.000000
50.480003,16.391464,-188.109940,0.010637,0.002448,0.062171,72.912872,3.714359,0.621711,-188.109940,0.062943,0.000000
50.710003,16.354973,-188.065460,0.010649,0.002456,0.062379,72.750549,3.706090,0.623792,-188.065460,0.063325,0.000000
50.940002,17.250900,-188.065460,0.010649,0.002477,0.062917,76.735840,3.909110,0.629171,-188.065460,0.063706,0.000000
51.170002,17.957291,-188.109940,0.010654,0.002496,0.063403,79.878021,4.069180,0.634027,-188.109940,0.064096,0.000000
51.400002,18.036980,-188.109940,0.010675,0.002508,0.063715,80.232491,4.087238,0.637149,-188.109940,0.064478,0.000000
51.630001,18.351265,-188.154419,0.010701,0.002522,0.064053,81.630501,4.158456,0.640533,-188.154419,0.064859,0.000000
51.860001,18.664429,-188.154419,0.010705,0.002535,0.064391,83.023529,4.229420,0.643913,-188.154419,0.065241,0.000000
52.090004,19.043503,-188.198898,0.010718,0.002550,0.064764,84.709732,4.315320,0.647641,-188.198898,0.065623,0.000000
52.320004,19.802025,-188.154419,0.010701,0.002566,0.065172,88.083809,4.487203,0.651717,-188.154419,0.066013,0.000000
52.550003,19.923416,-188.109940,0.010753,0.002576,0.065432,88.623779,4.514710,0.654321,-188.109940,0.066395,0.000000
52.780003,20.611565,-188.109940,0.010744,0.002594,0.065892,91.684822,4.670648,0.658916,-188.109940,0.066776,0.000000
53.010002,21.314232,-188.109940,0.010740,0.002612,0.066334,94.810440,4.829874,0.663341,-188.109940,0.067158,0.000000
53.240002,21.707451,-188.198898,0.010744,0.002624,0.066646,96.559563,4.918979,0.666459,-188.198898,0.067539,0.000000
53.470001,22.476402,-188.154419,0.010800,0.002644,0.067166,99.980034,5.093225,0.671664,-188.154419,0.067930,0.000000
53.700001,23.085236,-188.154419,0.010796,0.002659,0.067531,102.688255,5.231189,0.675309,-188.154419,0.068311,0.000000
53.930004,23.396164,-188.154419,0.010813,0.002673,0.067886,104.071335,5.301647,0.678863,-188.154419,0.068693,0.000000
54.160004,23.958443,-188.243378,0.010843,0.002687,0.068259,106.572479,5.429061,0.682591,-188.243378,0.069074,0.000000
54.390003,24.382576,-188.198898,0.010800,0.002700,0.068589,108.459114,5.525171,0.685887,-188.198898,0.069465,0.000000
54.620003,24.507698,-188.243378,0.010822,0.002710,0.068840,109.015686,5.553524,0.688401,-188.243378,0.069846,0.000000
54.850002,25.916382,-188.198898,0.010856,0.002733,0.069421,115.281822,5.872736,0.694214,-188.198898,0.070228,0.000000
55.080002,26.342743,-188.198898,0.010856,0.002747,0.069777,117.178375,5.969351,0.697768,-188.198898,0.070609,0.000000
55.310001,26.751610,-188.243378,0.010874,0.002762,0.070158,118.997101,6.062001,0.701583,-188.243378,0.070991,0.000000
55.540001,27.218567,-188.198898,0.010874,0.002773,0.070427,121.074234,6.167815,0.704271,-188.198898,0.071381,0.000000
55.770004,27.917511,-188.287872,0.010878,0.002787,0.070800,124.183289,6.326199,0.708002,-188.287872,0.071763,0.000000
56.000004,28.936317,-188.198898,0.010900,0.002808,0.071312,128.715164,6.557063,0.713120,-188.198898,0.072144,0.000000
56.230003,29.242409,-188.243378,0.010912,0.002819,0.071607,130.076736,6.626424,0.716068,-188.243378,0.072526,0.000000
56.460003,29.278160,-188.287872,0.010934,0.002825,0.071763,130.235764,6.634526,0.717627,-188.287872,0.072908,0.000000
56.690002,30.811592,-188.287872,0.010912,0.002851,0.072422,137.056808,6.982007,0.724217,-188.287872,0.073298,0.000000
56.920002,31.820343,-188.287872,0.010934,0.002870,0.072908,141.543961,7.210593,0.729077,-188.287872,0.073679,0.000000
57.150002,32.551682,-188.287872,0.010964,0.002882,0.073194,144.797104,7.376317,0.731938,-188.287872,0.074061,0.000000
57.380001,33.168709,-188.287872,0.010956,0.002899,0.073627,147.541779,7.516137,0.736272,-188.287872,0.074442,0.000000
57.610004,33.661354,-188.332352,0.010986,0.002910,0.073922,149.733185,7.627772,0.739220,-188.332352,0.074824,0.000000
57.840004,34.513344,-188.287872,0.010981,0.002928,0.074364,153.523026,7.820835,0.743645,-188.287872,0.075214,0.000000
58.070004,34.778473,-188.243378,0.010977,0.002934,0.074529,154.702377,7.880915,0.745291,-188.243378,0.075596,0.000000
58.300003,35.258087,-188.287872,0.011007,0.002950,0.074928,156.835800,7.989597,0.749281,-188.287872,0.075978,0.000000
58.530003,36.578896,-188.287872,0.010981,0.002966,0.075344,162.711060,8.288897,0.753444,-188.287872,0.076359,0.000000
58.760002,37.587280,-188.287872,0.011033,0.002984,0.075795,167.196579,8.517399,0.757952,-188.287872,0.076741,0.000000
58.990002,38.847015,-188.376831,0.011046,0.003003,0.076281,172.800156,8.802860,0.762812,-188.376831,0.077131,0.000000
59.220001,39.280830,-188.287872,0.011029,0.003014,0.076550,174.729858,8.901164,0.765499,-188.287872,0.077512,0.000000
59.450005,40.109726,-188.287872,0.011012,0.003029,0.076931,178.416977,9.088993,0.769314,-188.287872,0.077894,0.000000
59.680004,40.959854,-188.332352,0.011046,0.003045,0.077348,182.198532,9.281635,0.773477,-188.332352,0.078276,0.000000
59.910004,42.000267,-188.332352,0.011046,0.003062,0.077781,186.826523,9.517396,0.777815,-188.332352,0.078657,0.000000
60.140003,42.647072,-188.376831,0.011085,0.003074,0.078068,189.703644,9.663964,0.780676,-188.376831,0.079048,0.000000
60.370003,43.339317,-188.376831,0.011076,0.003089,0.078449,192.782913,9.820829,0.784491,-188.376831,0.079429,0.000000
60.600002,44.420685,-188.287872,0.011068,0.003105,0.078865,197.593079,10.065871,0.788655,-188.287872,0.079811,0.000000
60.830002,45.710213,-188.332352,0.011094,0.003124,0.079351,203.329178,10.358082,0.793511,-188.332352,0.080192,0.000000
61.060001,46.385696,-188.421310,0.011106,0.003135,0.079637,206.333878,10.511149,0.796372,-188.421310,0.080574,0.000000
61.290005,47.019096,-188.421310,0.011115,0.003151,0.080027,209.151382,10.654679,0.800274,-188.421310,0.080964,0.000000
61.520004,47.852470,-188.376831,0.011098,0.003163,0.080340,212.858414,10.843525,0.803397,-188.376831,0.081346,0.000000
61.750004,48.636688,-188.332352,0.011115,0.003174,0.080608,216.346802,11.021231,0.806084,-188.332352,0.081727,0.000000
61.980003,50.533180,-188.332352,0.011124,0.003198,0.081242,224.782806,11.450982,0.812416,-188.332352,0.082109,0.000000
62.210003,51.221695,-188.421310,0.011154,0.003211,0.081554,227.845474,11.607002,0.815539,-188.421310,0.082490,0.000000
62.440002,51.833504,-188.421310,0.011141,0.003221,0.081823,230.566940,11.745640,0.818226,-188.421310,0.082880,0.000000
62.670002,53.376984,-188.376831,0.011158,0.003243,0.082369,237.432678,12.095398,0.823688,-188.376831,0.083262,0.000000
62.900002,54.585335,-188.376831,0.011128,0.003259,0.082785,242.807693,12.369213,0.827851,-188.376831,0.083644,0.000000
63.130005,55.273109,-188.376831,0.011150,0.003271,0.083089,245.867065,12.525065,0.830887,-188.376831,0.084025,0.000000
63.360004,56.379425,-188.465790,0.011171,0.003286,0.083470,250.788208,12.775761,0.834702,-188.465790,0.084416,0.000000
63.590004,57.246307,-188.465790,0.011184,0.003299,0.083782,254.644287,12.972199,0.837824,-188.465790,0.084797,0.000000
63.820004,58.531738,-188.465790,0.011175,0.003316,0.084216,260.362183,13.263482,0.842162,-188.465790,0.085179,0.000000
64.050003,59.222488,-188.421310,0.011201,0.003325,0.084459,263.434784,13.420008,0.844588,-188.421310,0.085560,0.000000
64.280006,60.618889,-188.465790,0.011206,0.003344,0.084927,269.646271,13.736437,0.849274,-188.465790,0.085942,0.000000
64.510002,61.671585,-188.465790,0.011188,0.003358,0.085300,274.328918,13.974981,0.853002,-188.465790,0.086332,0.000000
64.740005,63.506264,-188.465790,0.011210,0.003380,0.085855,282.489960,14.390725,0.858550,-188.465790,0.086714,0.000000
64.970001,64.378365,-188.554749,0.011214,0.003392,0.086159,286.369263,14.588346,0.861586,-188.554749,0.087095,0.000000
65.200005,65.177467,-188.465790,0.011210,0.003406,0.086506,289.923859,14.769425,0.865057,-188.465790,0.087477,0.000000
65.430000,66.739571,-188.421310,0.011227,0.003423,0.086939,296.872437,15.123404,0.869390,-188.421310,0.087858,0.000000
65.660004,67.319725,-188.510269,0.011253,0.003434,0.087226,299.453094,15.254868,0.872256,-188.510269,0.088249,0.000000
65.889999,67.136147,-188.510269,0.011240,0.003425,0.086983,298.636505,15.213268,0.869826,-188.510269,0.087251,0.000000
66.120003,66.706429,-188.510269,0.011240,0.003423,0.086948,296.725006,15.115892,0.869477,-188.510269,0.086983,0.000000
66.350006,66.325493,-188.510269,0.011253,0.003422,0.086922,295.030518,15.029572,0.869220,-188.510269,0.086983,0.000000
66.580002,66.002647,-188.465790,0.011270,0.003422,0.086913,293.594452,14.956414,0.869133,-188.465790,0.086983,0.000000
66.810005,65.706245,-188.510269,0.011253,0.003422,0.086913,292.275970,14.889248,0.869133,-188.510269,0.086983,0.000000
67.040001,65.426964,-188.643707,0.011240,0.003421,0.086905,291.033661,14.825962,0.869046,-188.643707,0.086983,0.000000
67.270004,65.181572,-188.554749,0.011266,0.003421,0.086905,289.942108,14.770355,0.869046,-188.554749,0.086983,0.000000
67.500000,64.985695,-188.554749,0.011275,0.003421,0.086905,289.070801,14.725968,0.869046,-188.554749,0.086983,0.000000
67.730003,64.782753,-188.510269,0.011270,0.003421,0.086896,288.168091,14.679982,0.868959,-188.510269,0.086983,0.000000
67.960007,64.612206,-188.599228,0.011257,0.003421,0.086896,287.409454,14.641335,0.868959,-188.599228,0.086983,0.000000
68.190002,64.443901,-188.554749,0.011275,0.003421,0.086896,286.660797,14.603196,0.868959,-188.554749,0.086983,0.000000
68.420006,64.285637,-188.643707,0.011253,0.003421,0.086896,285.956787,14.567333,0.868959,-188.643707,0.086983,0.000000
68.650002,64.140785,-188.554749,0.011275,0.003421,0.086896,285.312469,14.534510,0.868959,-188.554749,0.086983,0.000000
68.880005,64.017906,-188.599228,0.011279,0.003421,0.086896,284.765869,14.506665,0.868959,-188.599228,0.086983,0.000000
69.110001,63.893166,-188.554749,0.011283,0.003421,0.086896,284.210999,14.478398,0.868959,-188.554749,0.086983,0.000000
69.340004,63.773628,-188.643707,0.011266,0.003421,0.086896,283.679260,14.451311,0.868959,-188.643707,0.086983,0.000000
69.570000,63.667503,-188.688202,0.011275,0.003421,0.086896,283.207214,14.427262,0.868959,-188.688202,0.086983,0.000000
69.800003,63.575157,-188.599228,0.011270,0.003421,0.086896,282.796417,14.406337,0.868959,-188.599228,0.086983,0.000000
70.030006,63.463066,-188.643707,0.011275,0.003421,0.086896,282.297821,14.380937,0.868959,-188.643707,0.086983,0.000000
70.260002,63.372948,-188.599228,0.011279,0.003421,0.086896,281.896942,14.360516,0.868959,-188.599228,0.086983,0.000000
70.490005,63.283958,-188.643707,0.011275,0.003421,0.086896,281.501099,14.340350,0.868959,-188.643707,0.086983,0.000000
70.720001,63.198677,-188.732681,0.011270,0.003421,0.086887,281.121765,14.321025,0.868872,-188.732681,0.086983,0.000000
70.950005,63.118996,-188.643707,0.011275,0.003421,0.086887,280.767303,14.302969,0.868872,-188.643707,0.086983,0.000000
71.180000,63.046013,-188.643707,0.011270,0.003421,0.086887,280.442657,14.286430,0.868872,-188.643707,0.086983,0.000000
71.410004,62.957390,-188.688202,0.011283,0.003421,0.086887,280.048462,14.266348,0.868872,-188.688202,0.086983,0.000000
71.640007,62.904510,-188.732681,0.011266,0.003421,0.086887,279.813232,14.254366,0.868872,-188.732681,0.086983,0.000000
71.870003,62.828545,-188.732681,0.011279,0.003421,0.086887,279.475311,14.237151,0.868872,-188.732681,0.086983,0.000000
72.100006,62.760399,-188.777161,0.011279,0.003421,0.086887,279.172211,14.221710,0.868872,-188.777161,0.086983,0.000000
72.330002,62.694122,-188.688202,0.011283,0.003421,0.086887,278.877380,14.206692,0.868872,-188.688202,0.086983,0.000000
72.560005,62.637894,-188.688202,0.011288,0.003421,0.086887,278.627258,14.193950,0.868872,-188.688202,0.086983,0.000000
72.790001,62.576820,-188.777161,0.011288,0.003421,0.086887,278.355591,14.180110,0.868872,-188.777161,0.086983,0.000000
73.020004,62.526550,-188.688202,0.011292,0.003421,0.086887,278.131989,14.168719,0.868872,-188.688202,0.086983,0.000000
73.250000,62.474045,-188.732681,0.011292,0.003421,0.086887,277.898437,14.156821,0.868872,-188.732681,0.086983,0.000000
73.480003,62.416702,-188.643707,0.011275,0.003421,0.086887,277.643372,14.143827,0.868872,-188.643707,0.086983,0.000000
73.710007,62.357124,-188.688202,0.011288,0.003421,0.086887,277.378357,14.130326,0.868872,-188.688202,0.086983,0.000000
73.940002,62.304245,-188.732681,0.011275,0.003421,0.086887,277.143127,14.118344,0.868872,-188.732681,0.086983,0.000000
74.170006,62.250992,-188.777161,0.011288,0.003421,0.086887,276.906250,14.106277,0.868872,-188.777161,0.086983,0.000000
74.400002,62.202591,-188.732681,0.011275,0.003421,0.086887,276.690948,14.095308,0.868872,-188.732681,0.086983,0.000000
74.630005,62.169075,-188.777161,0.011253,0.003421,0.086887,276.541870,14.087713,0.868872,-188.777161,0.086983,0.000000
74.860001,62.125504,-188.732681,0.011300,0.003421,0.086887,276.348053,14.077841,0.868872,-188.732681,0.086983,0.000000
75.090004,62.084175,-188.732681,0.011288,0.003421,0.086887,276.164215,14.068476,0.868872,-188.732681,0.086983,0.000000
75.320007,62.036507,-188.821640,0.011288,0.003421,0.086887,275.952148,14.057673,0.868872,-188.821640,0.086983,0.000000
75.550003,61.984001,-188.821640,0.011270,0.003421,0.086887,275.718597,14.045775,0.868872,-188.821640,0.086983,0.000000
75.780006,61.941185,-188.777161,0.011266,0.003421,0.086887,275.528137,14.036074,0.868872,-188.777161,0.086983,0.000000
76.010002,61.919586,-188.821640,0.011279,0.003421,0.086887,275.432068,14.031178,0.868872,-188.821640,0.086983,0.000000
76.240005,61.869690,-188.777161,0.011288,0.003421,0.086887,275.210114,14.019873,0.868872,-188.777161,0.086983,0.000000
76.470001,61.827606,-188.777161,0.011266,0.003421,0.086887,275.022919,14.010335,0.868872,-188.777161,0.086983,0.000000
76.700005,61.802658,-188.821640,0.011266,0.003421,0.086887,274.911957,14.004683,0.868872,-188.821640,0.086983,0.000000
76.930000,61.759094,-188.821640,0.011279,0.003421,0.086887,274.718170,13.994810,0.868872,-188.821640,0.086983,0.000000
77.160004,61.715897,-188.821640,0.011283,0.003421,0.086887,274.526031,13.985022,0.868872,-188.821640,0.086983,0.000000
77.390007,61.693558,-188.866119,0.011275,0.003421,0.086887,274.426636,13.979959,0.868872,-188.866119,0.086983,0.000000
77.620003,61.647377,-188.866119,0.011270,0.003421,0.086887,274.221222,13.969495,0.868872,-188.866119,0.086983,0.000000
77.850006,61.625412,-188.821640,0.011257,0.003421,0.086887,274.123535,13.964519,0.868872,-188.821640,0.086983,0.000000
78.080002,61.596367,-188.866119,0.011275,0.003421,0.086887,273.994324,13.957936,0.868872,-188.866119,0.086983,0.000000
78.310005,61.537903,-188.821640,0.011313,0.003421,0.086887,273.734253,13.944689,0.868872,-188.821640,0.086983,0.000000
78.540001,61.528969,-188.821640,0.011288,0.003421,0.086887,273.694519,13.942664,0.868872,-188.821640,0.086983,0.000000
78.770004,61.499176,-188.910599,0.011266,0.003421,0.086887,273.562012,13.935912,0.868872,-188.910599,0.086983,0.000000
79.000000,61.462685,-188.910599,0.011270,0.003421,0.086887,273.399689,13.927644,0.868872,-188.910599,0.086983,0.000000
79.230003,61.444809,-188.910599,0.011288,0.003421,0.086887,273.320160,13.923593,0.868872,-188.910599,0.086983,0.000000
79.460007,61.414276,-188.866119,0.011292,0.003421,0.086887,273.184357,13.916675,0.868872,-188.866119,0.086983,0.000000
79.690002,61.374428,-188.910599,0.011292,0.003421,0.086887,273.007080,13.907644,0.868872,-188.910599,0.086983,0.000000
79.920006,61.352463,-188.910599,0.011283,0.003421,0.086887,272.909393,13.902667,0.868872,-188.910599,0.086983,0.000000
80.150002,61.337196,-188.910599,0.011288,0.003421,0.086887,272.841461,13.899207,0.868872,-188.910599,0.086983,0.000000
80.380005,61.302193,-188.910599,0.011292,0.003421,0.086887,272.685760,13.891275,0.868872,-188.910599,0.086983,0.000000
80.610001,61.292885,-188.866119,0.011266,0.003421,0.086887,272.644379,13.889167,0.868872,-188.866119,0.086983,0.000000
80.840004,61.266441,-188.910599,0.011266,0.003421,0.086887,272.526733,13.883174,0.868872,-188.910599,0.086983,0.000000
81.070007,61.229950,-188.955078,0.011283,0.003421,0.086887,272.364410,13.874905,0.868872,-188.955078,0.086983,0.000000
81.300003,61.203140,-188.910599,0.011283,0.003421,0.086887,272.245178,13.868830,0.868872,-188.910599,0.086983,0.000000
81.530006,61.173347,-188.910599,0.011296,0.003421,0.086887,272.112640,13.862079,0.868872,-188.910599,0.086983,0.000000
81.760002,61.155106,-188.910599,0.011292,0.003421,0.086887,272.031494,13.857945,0.868872,-188.910599,0.086983,0.000000
81.990005,61.126434,-188.955078,0.011283,0.003421,0.086887,271.903961,13.851448,0.868872,-188.955078,0.086983,0.000000
82.220001,61.109673,-189.044037,0.011288,0.003421,0.086887,271.829407,13.847650,0.868872,-189.044037,0.086983,0.000000
82.450005,61.075790,-188.999557,0.011309,0.003421,0.086887,271.678680,13.839972,0.868872,-188.999557,0.086983,0.000000
82.680000,61.057541,-188.955078,0.011283,0.003421,0.086887,271.597504,13.835836,0.868872,-188.955078,0.086983,0.000000
82.910004,61.030357,-188.910599,0.011279,0.003421,0.086887,271.476593,13.829677,0.868872,-188.910599,0.086983,0.000000
83.140007,61.010254,-188.999557,0.011288,0.003421,0.086887,271.387177,13.825121,0.868872,-188.999557,0.086983,0.000000
83.370003,61.001686,-188.999557,0.011288,0.003421,0.086887,271.349060,13.823179,0.868872,-188.999557,0.086983,0.000000
83.600006,60.973389,-188.999557,0.011288,0.003421,0.086887,271.223175,13.816768,0.868872,-188.999557,0.086983,0.000000
83.830002,60.944710,-189.044037,0.011288,0.003421,0.086887,271.095612,13.810269,0.868872,-189.044037,0.086983,0.000000
84.060005,60.936150,-188.999557,0.011296,0.003421,0.086887,271.057526,13.808329,0.868872,-188.999557,0.086983,0.000000
84.290001,60.910828,-189.044037,0.011266,0.003421,0.086887,270.944885,13.802590,0.868872,-189.044037,0.086983,0.000000
84.520004,60.882896,-189.044037,0.011279,0.003421,0.086887,270.820648,13.796262,0.868872,-189.044037,0.086983,0.000000
84.750008,60.869865,-189.088516,0.011292,0.003421,0.086887,270.762695,13.793308,0.868872,-189.088516,0.086983,0.000000
84.980003,60.858696,-188.999557,0.011296,0.003421,0.086887,270.713013,13.790777,0.868872,-188.999557,0.086983,0.000000
85.210007,60.827789,-189.044037,0.011288,0.003421,0.086887,270.575531,13.783774,0.868872,-189.044037,0.086983,0.000000
85.440002,60.815125,-189.044037,0.011296,0.003421,0.086887,270.519196,13.780904,0.868872,-189.044037,0.086983,0.000000
85.670006,60.787941,-189.133011,0.011292,0.003421,0.086887,270.398254,13.774744,0.868872,-189.133011,0.086983,0.000000
85.900002,60.754059,-189.044037,0.011288,0.003421,0.086887,270.247559,13.767067,0.868872,-189.044037,0.086983,0.000000
86.130005,60.739906,-189.044037,0.011292,0.003421,0.086887,270.184601,13.763859,0.868872,-189.044037,0.086983,0.000000
86.360001,60.738419,-188.999557,0.011300,0.003421,0.086887,270.177979,13.763522,0.868872,-188.999557,0.086983,0.000000
86.590004,60.709000,-189.044037,0.011288,0.003421,0.086887,270.047119,13.756856,0.868872,-189.044037,0.086983,0.000000
86.820007,60.713844,-189.088516,0.011292,0.003421,0.086887,270.068665,13.757954,0.868872,-189.088516,0.086983,0.000000
87.050003,60.678093,-189.088516,0.011275,0.003421,0.086887,269.909637,13.749852,0.868872,-189.088516,0.086983,0.000000
87.280006,60.661713,-189.088516,0.011283,0.003421,0.086887,269.836761,13.746140,0.868872,-189.088516,0.086983,0.000000
87.510002,60.638626,-189.088516,0.011279,0.003421,0.086887,269.734070,13.740909,0.868872,-189.088516,0.086983,0.000000
87.740005,60.622612,-189.133011,0.011300,0.003421,0.086887,269.662842,13.737280,0.868872,-189.133011,0.086983,0.000000
87.970001,60.613304,-189.088516,0.011313,0.003421,0.086887,269.621429,13.735171,0.868872,-189.088516,0.086983,0.000000
88.200005,60.602127,-189.177490,0.011300,0.003421,0.086887,269.571716,13.732638,0.868872,-189.177490,0.086983,0.000000
88.430008,60.578674,-189.177490,0.011296,0.003421,0.086887,269.467407,13.727324,0.868872,-189.177490,0.086983,0.000000
88.660004,60.541809,-189.133011,0.011305,0.003421,0.086887,269.303406,13.718970,0.868872,-189.133011,0.086983,0.000000
88.890007,60.539200,-189.088516,0.011275,0.003421,0.086887,269.291809,13.718379,0.868872,-189.088516,0.086983,0.000000
89.120003,60.527657,-189.177490,0.011283,0.003421,0.086887,269.240448,13.715763,0.868872,-189.177490,0.086983,0.000000
89.350006,60.506805,-189.221970,0.011300,0.003421,0.086887,269.147705,13.711039,0.868872,-189.221970,0.086983,0.000000
89.580002,60.498238,-189.177490,0.011296,0.003421,0.086887,269.109589,13.709096,0.868872,-189.177490,0.086983,0.000000
89.810005,60.472176,-189.177490,0.011288,0.003421,0.086887,268.993683,13.703191,0.868872,-189.177490,0.086983,0.000000
90.040001,60.451317,-189.221970,0.011266,0.003421,0.086887,268.900879,13.698463,0.868872,-189.221970,0.086983,0.000000
90.270004,60.449081,-189.177490,0.011288,0.003421,0.086887,268.890930,13.697957,0.868872,-189.177490,0.086983,0.000000
90.500008,60.447220,-189.221970,0.011296,0.003421,0.086887,268.882660,13.697536,0.868872,-189.221970,0.086983,0.000000
90.730003,60.430466,-189.177490,0.011296,0.003421,0.086887,268.808136,13.693739,0.868872,-189.177490,0.086983,0.000000
90.960007,60.419670,-189.221970,0.011309,0.003421,0.086887,268.760101,13.691293,0.868872,-189.221970,0.086983,0.000000
91.190002,60.404770,-189.133011,0.011309,0.003421,0.086887,268.693848,13.687917,0.868872,-189.133011,0.086983,0.000000
91.420006,60.368652,-189.177490,0.011288,0.003421,0.086887,268.533173,13.679732,0.868872,-189.177490,0.086983,0.000000
91.650002,60.352272,-189.266449,0.011292,0.003421,0.086887,268.460327,13.676020,0.868872,-189.266449,0.086983,0.000000
91.880005,60.346680,-189.221970,0.011279,0.003421,0.086887,268.435425,13.674753,0.868872,-189.221970,0.086983,0.000000
92.110001,60.345192,-189.221970,0.011296,0.003421,0.086887,268.428833,13.674416,0.868872,-189.221970,0.086983,0.000000
92.340004,60.326202,-189.221970,0.011300,0.003421,0.086887,268.344360,13.670113,0.868872,-189.221970,0.086983,0.000000
92.570007,60.295670,-189.310928,0.011305,0.003421,0.086887,268.208527,13.663194,0.868872,-189.310928,0.086983,0.000000
92.800003,60.270348,-189.221970,0.011309,0.003421,0.086887,268.095886,13.657455,0.868872,-189.221970,0.086983,0.000000
93.030006,60.262901,-189.266449,0.011283,0.003421,0.086887,268.062775,13.655769,0.868872,-189.266449,0.086983,0.000000
93.260002,60.255455,-189.266449,0.011283,0.003421,0.086887,268.029663,13.654081,0.868872,-189.266449,0.086983,0.000000
93.490005,60.239815,-189.266449,0.011283,0.003421,0.086887,267.960083,13.650537,0.868872,-189.266449,0.086983,0.000000
93.720001,60.223427,-189.221970,0.011296,0.003421,0.086887,267.887177,13.646824,0.868872,-189.221970,0.086983,0.000000
93.950005,60.218216,-189.310928,0.011292,0.003421,0.086887,267.864014,13.645643,0.868872,-189.310928,0.086983,0.000000
94.180008,60.199226,-189.310928,0.011296,0.003421,0.086887,267.779541,13.641339,0.868872,-189.310928,0.086983,0.000000
94.410004,60.179489,-189.310928,0.011279,0.003421,0.086887,267.691742,13.636867,0.868872,-189.310928,0.086983,0.000000
94.640007,60.172409,-189.310928,0.011283,0.003421,0.086887,267.660248,13.635262,0.868872,-189.310928,0.086983,0.000000
94.870003,60.167946,-189.266449,0.011305,0.003421,0.086887,267.640381,13.634252,0.868872,-189.266449,0.086983,0.000000
95.100006,60.129959,-189.355408,0.011296,0.003421,0.086887,267.471405,13.625643,0.868872,-189.355408,0.086983,0.000000
95.330002,60.116554,-189.355408,0.011300,0.003421,0.086887,267.411774,13.622605,0.868872,-189.355408,0.086983,0.000000
95.560005,60.112457,-189.355408,0.011300,0.003421,0.086887,267.393555,13.621677,0.868872,-189.355408,0.086983,0.000000
95.790001,60.099052,-189.310928,0.011288,0.003421,0.086887,267.333923,13.618640,0.868872,-189.310928,0.086983,0.000000
96.020004,60.095703,-189.355408,0.011296,0.003421,0.086887,267.319031,13.617881,0.868872,-189.355408,0.086983,0.000000
96.200005,60.064049,-189.399887,0.011279,0.003421,0.086887,267.178223,13.610708,0.868872,-189.399887,0.086983,0.000000