File: Data/compression sample NH 10,12,15/AutoNoheating-15-2-2-240201_02012024_181804.csv
Time (sec),S:Load (lbs),S:HL1 (DIM),S:LVDT (in),S:Position (in),Ch:Position (mm),Ch:Load (N),Ch:Stress (MPa),Ch:Strain (mm/mm),Ch:HL1 (DIM),Set Point (),Cycles ()
0.110000,-0.006332,-158.974915,0.000009,-0.000000,-0.000000,-0.028168,-0.001435,-0.000000,-158.974915,0.000191,0.000000
0.350000,-0.004845,-159.063889,0.000009,-0.000000,-0.000000,-0.021550,-0.001098,-0.000000,-159.063889,0.000191,0.000000
0.590000,-0.006332,-158.974915,-0.000013,0.000127,0.003226,-0.028168,-0.001435,0.032259,-158.974915,0.004111,0.000000
0.830000,0.020851,-159.063889,0.000095,0.000269,0.006825,0.092750,0.004725,0.068249,-159.063889,0.008117,0.000000
1.070000,0.018616,-159.019394,0.000306,0.000436,0.011066,0.082807,0.004218,0.110659,-159.019394,0.012106,0.000000
1.310000,-0.011169,-158.974915,0.000423,0.000588,0.014925,-0.049684,-0.002531,0.149250,-158.974915,0.016113,0.000000
1.550000,0.004097,-159.063889,0.000621,0.000744,0.018906,0.018224,0.000928,0.189056,-159.063889,0.020102,0.000000
1.790000,-0.014526,-159.063889,0.000767,0.000898,0.022808,-0.064617,-0.003292,0.228082,-159.063889,0.024109,0.000000
2.030000,-0.014526,-159.108368,0.000918,0.001059,0.026901,-0.064617,-0.003292,0.269011,-159.108368,0.028098,0.000000
2.270000,-0.049896,-159.019394,0.001125,0.001225,0.031116,-0.221950,-0.011307,0.311160,-159.019394,0.032105,0.000000
2.510000,-0.052505,-159.019394,0.001272,0.001378,0.034992,-0.233556,-0.011898,0.349925,-159.019394,0.036094,0.000000
2.750000,0.003723,-159.108368,0.001414,0.001534,0.038973,0.016561,0.000844,0.389731,-159.108368,0.040101,0.000000
2.990000,0.003723,-159.019394,0.001582,0.001687,0.042858,0.016561,0.000844,0.428583,-159.019394,0.044090,0.000000
3.230000,-0.006332,-159.063889,0.001768,0.001854,0.047081,-0.028168,-0.001435,0.470814,-159.063889,0.048096,0.000000
3.470000,0.001488,-159.108368,0.001923,0.002003,0.050871,0.006618,0.000337,0.508713,-159.108368,0.052085,0.000000
3.710000,0.002975,-159.108368,0.002078,0.002166,0.055017,0.013236,0.000674,0.550169,-159.108368,0.056092,0.000000
3.950000,0.009682,-159.108368,0.002233,0.002312,0.058737,0.043066,0.002194,0.587370,-159.108368,0.060081,0.000000
4.190000,-0.014526,-159.063889,0.002410,0.002483,0.063065,-0.064617,-0.003292,0.630647,-159.063889,0.064088,0.000000
4.430000,-0.052132,-159.108368,0.002587,0.002635,0.066941,-0.231893,-0.011813,0.669412,-159.108368,0.068094,0.000000
4.670000,-0.011169,-159.152847,0.002746,0.002799,0.071095,-0.049684,-0.002531,0.710951,-159.152847,0.072084,0.000000
4.910000,0.027184,-159.108368,0.002915,0.002945,0.074798,0.120918,0.006160,0.747982,-159.108368,0.076090,0.000000
5.150000,0.010422,-159.197327,0.003074,0.003115,0.079117,0.046358,0.002362,0.791168,-159.197327,0.080080,0.000000
5.390000,-0.010056,-159.108368,0.003225,0.003266,0.082959,-0.044729,-0.002279,0.829588,-159.108368,0.084086,0.000000
5.630000,0.001862,-159.152847,0.003376,0.003422,0.086922,0.008281,0.000422,0.869220,-159.152847,0.088075,0.000000
5.870000,0.024200,-159.197327,0.003566,0.003578,0.090876,0.107649,0.005484,0.908765,-159.197327,0.092082,0.000000
6.110000,0.010422,-159.197327,0.003721,0.003739,0.094961,0.046358,0.002362,0.949611,-159.197327,0.096071,0.000000
6.350000,-0.036491,-159.152847,0.003889,0.003895,0.098942,-0.162322,-0.008269,0.989417,-159.152847,0.100078,0.000000
6.590000,-0.004845,-159.108368,0.004053,0.004052,0.102931,-0.021550,-0.001098,1.029310,-159.108368,0.104067,0.000000
6.830000,0.003723,-159.197327,0.004221,0.004208,0.106894,0.016561,0.000844,1.068941,-159.197327,0.108074,0.000000
7.070000,0.014153,-159.197327,0.004368,0.004366,0.110892,0.062954,0.003207,1.108921,-159.197327,0.112063,0.000000
7.310000,-0.013779,-159.197327,0.004544,0.004526,0.114951,-0.061291,-0.003122,1.149507,-159.197327,0.116069,0.000000
7.550000,-0.001122,-159.197327,0.004712,0.004684,0.118966,-0.004989,-0.000254,1.189661,-159.197327,0.120059,0.000000
7.790000,0.017128,-159.108368,0.004885,0.004840,0.122947,0.076189,0.003881,1.229466,-159.108368,0.124065,0.000000
8.030001,0.017502,-159.286285,0.005036,0.004996,0.126910,0.077852,0.003966,1.269098,-159.286285,0.128054,0.000000
8.270000,0.000374,-159.197327,0.005230,0.005159,0.131046,0.001663,0.000085,1.310463,-159.197327,0.132061,0.000000
8.510000,-0.017876,-159.197327,0.005355,0.005310,0.134862,-0.079515,-0.004051,1.348622,-159.197327,0.136050,0.000000
8.750000,0.004097,-159.241806,0.005536,0.005471,0.138973,0.018224,0.000928,1.389730,-159.241806,0.140057,0.000000
8.990001,0.024948,-159.197327,0.005687,0.005622,0.142806,0.110975,0.005653,1.428060,-159.197327,0.144063,0.000000
9.230000,0.027184,-159.286285,0.005829,0.005789,0.147030,0.120918,0.006160,1.470295,-159.286285,0.148053,0.000000
9.470000,0.012283,-159.241806,0.006019,0.005940,0.150880,0.054639,0.002783,1.508799,-159.241806,0.152059,0.000000
9.710000,0.013031,-159.286285,0.006165,0.006103,0.155016,0.057965,0.002953,1.550164,-159.286285,0.156049,0.000000
9.950001,0.021225,-159.286285,0.006342,0.006252,0.158798,0.094413,0.004810,1.587975,-159.286285,0.160055,0.000000
10.190001,0.046173,-159.197327,0.006515,0.006416,0.162978,0.205388,0.010463,1.629776,-159.197327,0.164045,0.000000
10.430000,0.021225,-159.330765,0.006653,0.006573,0.166958,0.094413,0.004810,1.669582,-159.330765,0.168051,0.000000
10.670000,0.227142,-159.330765,0.006842,0.006731,0.170956,1.010380,0.051471,1.709561,-159.330765,0.172040,0.000000
10.910001,0.698570,-159.286285,0.006929,-0.000008,-0.000191,3.107396,0.158298,-0.001908,-159.286285,0.000026,0.000000
11.150001,0.672501,-159.330765,0.006937,-0.000008,-0.000191,2.991432,0.152391,-0.001908,-159.330765,0.000026,0.000000
11.390000,0.678459,-159.330765,0.006916,-0.000008,-0.000191,3.017937,0.153741,-0.001908,-159.330765,0.000156,0.000000
11.630000,0.650909,-159.375244,0.006898,-0.000008,-0.000191,2.895390,0.147498,-0.001908,-159.375244,0.000555,0.000000
11.870001,0.623352,-159.330765,0.006937,-0.000008,-0.000191,2.772808,0.141254,-0.001908,-159.330765,0.000954,0.000000
12.110001,0.785332,-159.286285,0.006937,0.000020,0.000512,3.493330,0.177959,0.005117,-159.286285,0.001353,0.000000
12.350000,1.065727,-159.375244,0.006963,0.000039,0.000997,4.740592,0.241497,0.009973,-159.375244,0.001752,0.000000
12.590000,1.155098,-159.330765,0.006950,0.000048,0.001223,5.138133,0.261749,0.012225,-159.330765,0.002151,0.000000
12.830001,1.281334,-159.419724,0.006954,0.000061,0.001561,5.699658,0.290354,0.015609,-159.419724,0.002558,0.000000
13.070001,1.533058,-159.330765,0.006993,0.000086,0.002185,6.819383,0.347396,0.021854,-159.330765,0.002957,0.000000
13.310000,1.684242,-159.330765,0.006998,0.000101,0.002576,7.491884,0.381655,0.025756,-159.330765,0.003356,0.000000
13.550000,1.823509,-159.464203,0.007011,0.000115,0.002922,8.111374,0.413213,0.029223,-159.464203,0.003755,0.000000
13.790001,1.971336,-159.375244,0.007032,0.000131,0.003321,8.768942,0.446711,0.033212,-159.375244,0.004154,0.000000
14.030001,2.169441,-159.330765,0.007045,0.000146,0.003720,9.650157,0.491602,0.037202,-159.330765,0.004553,0.000000
14.270000,2.380951,-159.375244,0.007080,0.000162,0.004119,10.590999,0.539531,0.041191,-159.375244,0.004952,0.000000
14.510000,2.581657,-159.375244,0.007067,0.000177,0.004501,11.483786,0.585012,0.045010,-159.375244,0.005351,0.000000
14.750001,2.666183,-159.464203,0.007080,0.000186,0.004735,11.859776,0.604166,0.047349,-159.464203,0.005758,0.000000
14.990001,2.988663,-159.375244,0.007123,0.000209,0.005316,13.294236,0.677241,0.053159,-159.375244,0.006157,0.000000
15.230000,3.215065,-159.464203,0.007118,0.000228,0.005801,14.301323,0.728544,0.058015,-159.464203,0.006556,0.000000
15.470000,3.304802,-159.508698,0.007136,0.000239,0.006062,14.700493,0.748879,0.060619,-159.508698,0.006955,0.000000
15.710001,3.493973,-159.330765,0.007157,0.000258,0.006565,15.541967,0.791746,0.065649,-159.330765,0.007354,0.000000
15.950001,3.724464,-159.508698,0.007183,0.000275,0.006973,16.567245,0.843976,0.069725,-159.508698,0.007753,0.000000
16.190001,3.912888,-159.419724,0.007213,0.000290,0.007363,17.405394,0.886673,0.073628,-159.419724,0.008152,0.000000
16.430000,4.002632,-159.419724,0.007179,0.000300,0.007631,17.804598,0.907009,0.076315,-159.419724,0.008551,0.000000
16.670000,4.048431,-159.508698,0.007187,0.000310,0.007883,18.008322,0.917388,0.078832,-159.508698,0.008958,0.000000
16.910002,4.242065,-159.419724,0.007209,0.000324,0.008230,18.869650,0.961266,0.082299,-159.419724,0.009357,0.000000
17.150002,4.637901,-159.553177,0.007239,0.000351,0.008906,20.630415,1.050963,0.089062,-159.553177,0.009756,0.000000
17.390001,4.741043,-159.464203,0.007252,0.000365,0.009262,21.089212,1.074336,0.092620,-159.464203,0.010155,0.000000
17.630001,4.752213,-159.464203,0.007248,0.000377,0.009574,21.138897,1.076867,0.095743,-159.464203,0.010554,0.000000
17.870001,4.974892,-159.553177,0.007295,0.000395,0.010042,22.129423,1.127327,0.100425,-159.553177,0.010953,0.000000
18.110001,5.187889,-159.419724,0.007291,0.000414,0.010528,23.076883,1.175593,0.105281,-159.419724,0.011352,0.000000
18.350000,5.228477,-159.508698,0.007325,0.000425,0.010797,23.257429,1.184790,0.107968,-159.508698,0.011760,0.000000
18.590000,5.178581,-159.508698,0.007330,0.000436,0.011083,23.035480,1.173483,0.110829,-159.508698,0.012159,0.000000
18.830002,5.486160,-159.508698,0.007355,0.000454,0.011525,24.403660,1.243182,0.115254,-159.508698,0.012558,0.000000
19.070002,5.803421,-159.553177,0.007360,0.000478,0.012132,25.814905,1.315074,0.121325,-159.553177,0.012956,0.000000
19.310001,5.746826,-159.464203,0.007364,0.000489,0.012419,25.563160,1.302249,0.124186,-159.464203,0.013355,0.000000
19.550001,5.814224,-159.508698,0.007386,0.000505,0.012818,25.862961,1.317522,0.128175,-159.508698,0.013754,0.000000
19.790001,5.960564,-159.553177,0.007433,0.000519,0.013182,26.513912,1.350683,0.131817,-159.553177,0.014153,0.000000
20.030001,6.141907,-159.508698,0.007403,0.000538,0.013667,27.320566,1.391776,0.136673,-159.508698,0.014552,0.000000
20.270000,6.179520,-159.642136,0.007446,0.000550,0.013980,27.487877,1.400299,0.139795,-159.642136,0.014959,0.000000
20.510000,6.251015,-159.553177,0.007459,0.000566,0.014370,27.805902,1.416500,0.143697,-159.553177,0.015358,0.000000
20.750002,6.458801,-159.553177,0.007459,0.000582,0.014786,28.730183,1.463585,0.147861,-159.553177,0.015757,0.000000
20.990002,6.704941,-159.553177,0.007480,0.000606,0.015393,29.825066,1.519361,0.153932,-159.553177,0.016156,0.000000
21.230001,6.643120,-159.597656,0.007493,0.000618,0.015705,29.550074,1.505352,0.157054,-159.597656,0.016555,0.000000
21.470001,6.639397,-159.597656,0.007528,0.000632,0.016061,29.533512,1.504509,0.160608,-159.597656,0.016954,0.000000
21.710001,6.704193,-159.553177,0.007545,0.000648,0.016451,29.821741,1.519192,0.164510,-159.553177,0.017353,0.000000
21.950001,6.897453,-159.597656,0.007545,0.000666,0.016911,30.681404,1.562985,0.169109,-159.597656,0.017752,0.000000
22.190001,6.969322,-159.686615,0.007575,0.000680,0.017266,31.001093,1.579271,0.172663,-159.686615,0.018160,0.000000
22.430000,6.935432,-159.642136,0.007571,0.000690,0.017535,30.850344,1.571591,0.175350,-159.642136,0.018558,0.000000
22.670002,7.022202,-159.686615,0.007597,0.000705,0.017908,31.236313,1.591254,0.179082,-159.686615,0.018957,0.000000
22.910002,7.437393,-159.642136,0.007614,0.000731,0.018567,33.083176,1.685337,0.185672,-159.642136,0.019356,0.000000
23.150002,7.348022,-159.686615,0.007623,0.000744,0.018888,32.685635,1.665086,0.188881,-159.686615,0.019755,0.000000
23.390001,7.374092,-159.686615,0.007653,0.000756,0.019200,32.801601,1.670993,0.192004,-159.686615,0.020154,0.000000
23.630001,7.431808,-159.686615,0.007640,0.000771,0.019582,33.058334,1.684072,0.195819,-159.686615,0.020553,0.000000
23.870001,7.476868,-159.731094,0.007649,0.000786,0.019963,33.258770,1.694282,0.199634,-159.731094,0.020952,0.000000
24.110001,7.800827,-159.642136,0.007683,0.000806,0.020466,34.699810,1.767693,0.204664,-159.642136,0.021360,0.000000
24.350000,7.721138,-159.686615,0.007705,0.000818,0.020770,34.345337,1.749635,0.207700,-159.686615,0.021759,0.000000
24.590002,7.803810,-159.686615,0.007700,0.000831,0.021117,34.713081,1.768369,0.211167,-159.686615,0.022158,0.000000
24.830002,8.125168,-159.642136,0.007739,0.000854,0.021698,36.142551,1.841189,0.216980,-159.642136,0.022556,0.000000
25.070002,8.084946,-159.731094,0.007739,0.000867,0.022027,35.963634,1.832075,0.220273,-159.731094,0.022955,0.000000
25.310001,8.002655,-159.686615,0.007769,0.000878,0.022305,35.597588,1.813428,0.223051,-159.686615,0.023354,0.000000
25.550001,8.305397,-159.731094,0.007782,0.000900,0.022860,36.944252,1.882030,0.228600,-159.731094,0.023753,0.000000
25.790001,8.213043,-159.731094,0.007787,0.000912,0.023155,36.533440,1.861102,0.231549,-159.731094,0.024152,0.000000
26.030001,8.544083,-159.686615,0.007825,0.000932,0.023675,38.005978,1.936117,0.236753,-159.686615,0.024560,0.000000
26.270000,8.472961,-159.775574,0.007838,0.000944,0.023979,37.689613,1.920001,0.239788,-159.775574,0.024959,0.000000
26.510002,8.448761,-159.686615,0.007860,0.000957,0.024299,37.581966,1.914517,0.242994,-159.686615,0.025358,0.000000
26.750002,8.760803,-159.731094,0.007847,0.000978,0.024846,38.969997,1.985226,0.248459,-159.731094,0.025757,0.000000
26.990002,8.898582,-159.820053,0.007873,0.000996,0.025305,39.582870,2.016448,0.253054,-159.820053,0.026156,0.000000
27.230001,8.866928,-159.820053,0.007894,0.001009,0.025626,39.442066,2.009275,0.256264,-159.820053,0.026554,0.000000
27.470001,8.905289,-159.775574,0.007894,0.001024,0.026017,39.612701,2.017967,0.260166,-159.775574,0.026953,0.000000
27.710001,8.964867,-159.686615,0.007903,0.001040,0.026407,39.877720,2.031468,0.264068,-159.686615,0.027352,0.000000
27.950001,9.074341,-159.775574,0.007946,0.001053,0.026745,40.364685,2.056275,0.267452,-159.775574,0.027760,0.000000
28.190001,9.134666,-159.820053,0.007968,0.001065,0.027057,40.633026,2.069945,0.270575,-159.820053,0.028159,0.000000
28.430002,9.289948,-159.820053,0.007963,0.001082,0.027482,41.323750,2.105132,0.274821,-159.820053,0.028558,0.000000
28.670002,9.739769,-159.864532,0.007985,0.001111,0.028211,43.324657,2.207063,0.282107,-159.864532,0.028957,0.000000
28.910002,9.651146,-159.909012,0.008019,0.001123,0.028523,42.930443,2.186981,0.285230,-159.909012,0.029356,0.000000
29.150002,9.599014,-159.820053,0.007985,0.001137,0.028878,42.698547,2.175168,0.288784,-159.820053,0.029755,0.000000
29.390001,9.711472,-159.820053,0.008037,0.001153,0.029277,43.198784,2.200651,0.292773,-159.820053,0.030153,0.000000
29.630001,9.882393,-159.775574,0.008050,0.001170,0.029728,43.959080,2.239382,0.297285,-159.775574,0.030552,0.000000
29.870001,9.823181,-159.864532,0.008045,0.001181,0.029988,43.695694,2.225965,0.299885,-159.864532,0.030960,0.000000
30.110001,9.730835,-159.864532,0.008071,0.001193,0.030301,43.284916,2.205039,0.303007,-159.864532,0.031359,0.000000
30.350002,10.068207,-159.820053,0.008084,0.001210,0.030734,44.785622,2.281488,0.307345,-159.820053,0.031758,0.000000
30.590002,10.355675,-159.864532,0.008123,0.001234,0.031333,46.064342,2.346629,0.313329,-159.864532,0.032156,0.000000
30.830002,10.389191,-159.864532,0.008132,0.001249,0.031714,46.213428,2.354224,0.317144,-159.864532,0.032555,0.000000
31.070002,10.368340,-159.864532,0.008136,0.001263,0.032078,46.120678,2.349499,0.320785,-159.864532,0.032954,0.000000
31.310001,10.360146,-159.820053,0.008162,0.001275,0.032382,46.084229,2.347642,0.323820,-159.820053,0.033353,0.000000
31.550001,10.561974,-159.909012,0.008179,0.001294,0.032868,46.982006,2.393378,0.328676,-159.909012,0.033761,0.000000
31.790001,10.704590,-159.953506,0.008196,0.001311,0.033293,47.616394,2.425695,0.332927,-159.953506,0.034160,0.000000
32.030003,10.593620,-159.820053,0.008205,0.001321,0.033561,47.122776,2.400549,0.335614,-159.820053,0.034559,0.000000
32.270000,10.637932,-159.953506,0.008209,0.001334,0.033891,47.319885,2.410590,0.338911,-159.953506,0.034958,0.000000
32.510002,11.154419,-159.864532,0.008231,0.001360,0.034533,49.617332,2.527627,0.345330,-159.864532,0.035357,0.000000
32.750000,11.155159,-159.909012,0.008226,0.001373,0.034880,49.620625,2.527795,0.348797,-159.909012,0.035756,0.000000
32.990002,11.025948,-159.997986,0.008274,0.001386,0.035192,49.045864,2.498516,0.351920,-159.997986,0.036154,0.000000
33.230003,11.165588,-159.909012,0.008282,0.001404,0.035651,49.667019,2.530159,0.356514,-159.909012,0.036553,0.000000
33.470001,10.992432,-159.953506,0.008287,0.001410,0.035825,48.896778,2.490921,0.358252,-159.953506,0.036961,0.000000
33.710003,11.657860,-159.909012,0.008317,0.001439,0.036553,51.856750,2.641709,0.365534,-159.909012,0.037360,0.000000
33.950001,11.390869,-159.953506,0.008313,0.001447,0.036744,50.669117,2.581208,0.367441,-159.953506,0.037759,0.000000
34.190002,11.463486,-159.997986,0.008326,0.001462,0.037134,50.992130,2.597663,0.371344,-159.997986,0.038158,0.000000
34.430000,11.893578,-159.997986,0.008334,0.001485,0.037716,52.905273,2.695123,0.377157,-159.997986,0.038557,0.000000
34.670002,11.945335,-159.997986,0.008360,0.001502,0.038140,53.135506,2.706852,0.381404,-159.997986,0.038956,0.000000
34.910000,11.887619,-159.953506,0.008382,0.001513,0.038435,52.878769,2.693773,0.384352,-159.953506,0.039355,0.000000
35.150002,11.971397,-159.997986,0.008403,0.001531,0.038895,53.251434,2.712758,0.388951,-159.997986,0.039754,0.000000
35.390003,12.081627,-159.997986,0.008416,0.001547,0.039303,53.741760,2.737736,0.393027,-159.997986,0.040161,0.000000
35.630001,12.214935,-159.997986,0.008455,0.001562,0.039667,54.334747,2.767944,0.396668,-159.997986,0.040560,0.000000
35.870003,12.281586,-160.042465,0.008442,0.001578,0.040083,54.631222,2.783047,0.400832,-160.042465,0.040959,0.000000
36.110001,12.133385,-159.953506,0.008455,0.001587,0.040317,53.971992,2.749464,0.403171,-159.953506,0.041358,0.000000
36.350002,12.490860,-159.997986,0.008468,0.001608,0.040855,55.562119,2.830469,0.408549,-159.997986,0.041757,0.000000
36.590000,12.782799,-159.997986,0.008494,0.001629,0.041367,56.860729,2.896624,0.413666,-159.997986,0.042156,0.000000
36.830002,12.572037,-160.042465,0.008511,0.001637,0.041592,55.923214,2.848864,0.415922,-160.042465,0.042555,0.000000
37.070004,12.821899,-160.086945,0.008532,0.001658,0.042112,57.034657,2.905484,0.421123,-160.086945,0.042954,0.000000
37.310001,12.961914,-160.042465,0.008558,0.001676,0.042563,57.657475,2.937212,0.425634,-160.042465,0.043361,0.000000
37.550003,13.089264,-160.042465,0.008550,0.001691,0.042962,58.223953,2.966070,0.429623,-160.042465,0.043760,0.000000
37.790001,13.005104,-160.086945,0.008580,0.001703,0.043257,57.849590,2.946999,0.432572,-160.086945,0.044159,0.000000
38.030003,12.979416,-160.042465,0.008567,0.001714,0.043526,57.735325,2.941178,0.435259,-160.042465,0.044558,0.000000
38.270000,13.179749,-160.086945,0.008597,0.001731,0.043968,58.626450,2.986574,0.439684,-160.086945,0.044957,0.000000
38.510002,13.609840,-160.086945,0.008606,0.001752,0.044488,60.539593,3.084034,0.444884,-160.086945,0.045356,0.000000
38.750000,13.561058,-160.131424,0.008619,0.001764,0.044818,60.322598,3.072979,0.448181,-160.131424,0.045755,0.000000
38.990002,13.547653,-160.086945,0.008636,0.001778,0.045174,60.262970,3.069942,0.451739,-160.086945,0.046154,0.000000
39.230003,13.803474,-160.131424,0.008645,0.001796,0.045607,61.400921,3.127912,0.456072,-160.131424,0.046561,0.000000
39.470001,14.091316,-160.131424,0.008670,0.001816,0.046119,62.681305,3.193138,0.461189,-160.131424,0.046960,0.000000
39.710003,13.936783,-160.131424,0.008688,0.001824,0.046336,61.993908,3.158120,0.463358,-160.131424,0.047359,0.000000
39.950001,13.915558,-160.131424,0.008688,0.001838,0.046674,61.899494,3.153311,0.466742,-160.131424,0.047758,0.000000
40.190002,14.165794,-160.131424,0.008714,0.001855,0.047108,63.012600,3.210015,0.471076,-160.131424,0.048157,0.000000
40.430000,14.687859,-160.131424,0.008748,0.001878,0.047697,65.334862,3.328316,0.476972,-160.131424,0.048556,0.000000
40.670002,14.492363,-160.131424,0.008748,0.001889,0.047983,64.465248,3.284016,0.479834,-160.131424,0.048955,0.000000
40.910004,14.667381,-160.175903,0.008770,0.001905,0.048391,65.243767,3.323676,0.483910,-160.175903,0.049354,0.000000
41.150002,14.680412,-160.131424,0.008757,0.001918,0.048729,65.301735,3.326629,0.487294,-160.131424,0.049761,0.000000
41.390003,15.137314,-160.131424,0.008791,0.001940,0.049276,67.334137,3.430164,0.492755,-160.131424,0.050160,0.000000
41.630001,15.042358,-160.175903,0.008813,0.001953,0.049614,66.911751,3.408647,0.496139,-160.175903,0.050559,0.000000
41.870003,15.183487,-160.264862,0.008791,0.001968,0.049987,67.539520,3.440627,0.499867,-160.264862,0.050958,0.000000
42.110001,15.308601,-160.131424,0.008826,0.001984,0.050403,68.096062,3.468979,0.504031,-160.131424,0.051357,0.000000
42.350002,15.802368,-160.131424,0.008843,0.002006,0.050950,70.292442,3.580868,0.509496,-160.131424,0.051756,0.000000
42.590000,15.767365,-160.220383,0.008873,0.002021,0.051322,70.136742,3.572936,0.513224,-160.220383,0.052155,0.000000
42.830002,15.707787,-160.220383,0.008882,0.002034,0.051660,69.871727,3.559435,0.516604,-160.220383,0.052554,0.000000
43.070004,15.761780,-160.175903,0.008886,0.002047,0.051990,70.111900,3.571670,0.519901,-160.175903,0.052961,0.000000
43.310001,16.137505,-160.175903,0.008903,0.002067,0.052502,71.783203,3.656811,0.525018,-160.175903,0.053360,0.000000
43.550003,16.167297,-160.309341,0.008921,0.002080,0.052840,71.915733,3.663562,0.528402,-160.309341,0.053759,0.000000
43.790001,16.048882,-160.220383,0.008938,0.002092,0.053135,71.388992,3.636729,0.531350,-160.220383,0.054158,0.000000
44.030003,16.203789,-160.220383,0.008946,0.002106,0.053499,72.078049,3.671831,0.534991,-160.220383,0.054557,0.000000
44.270000,16.963051,-160.264862,0.008977,0.002132,0.054149,75.455421,3.843882,0.541494,-160.264862,0.054956,0.000000
44.510002,16.922836,-160.264862,0.009002,0.002145,0.054479,75.276535,3.834769,0.544790,-160.264862,0.055355,0.000000
44.750004,16.898636,-160.220383,0.008998,0.002160,0.054852,75.168884,3.829286,0.548518,-160.220383,0.055762,0.000000
44.990002,16.864746,-160.309341,0.009002,0.002171,0.055147,75.018135,3.821606,0.551467,-160.309341,0.056161,0.000000
45.230003,17.240471,-160.220383,0.009037,0.002190,0.055624,76.689445,3.906747,0.556240,-160.220383,0.056560,0.000000
45.470001,17.464264,-160.353836,0.009037,0.002206,0.056040,77.684929,3.957459,0.560399,-160.353836,0.056959,0.000000
45.710003,17.382721,-160.220383,0.009067,0.002217,0.056309,77.322205,3.938981,0.563090,-160.220383,0.057358,0.000000
45.950001,17.478790,-160.309341,0.009063,0.002231,0.056656,77.749542,3.960750,0.566557,-160.309341,0.057757,0.000000
46.190002,18.145340,-160.309341,0.009071,0.002254,0.057254,80.714500,4.111793,0.572541,-160.309341,0.058156,0.000000
46.430000,18.200447,-160.309341,0.009102,0.002268,0.057610,80.959633,4.124280,0.576099,-160.309341,0.058555,0.000000
46.670002,18.161720,-160.309341,0.009110,0.002282,0.057974,80.787369,4.115504,0.579740,-160.309341,0.058963,0.000000
46.910004,18.556435,-160.309341,0.009127,0.002300,0.058408,82.543144,4.204948,0.584077,-160.309341,0.059362,0.000000
47.150002,18.573563,-160.309341,0.009123,0.002313,0.058754,82.619331,4.208829,0.587544,-160.309341,0.059760,0.000000
47.390003,19.008499,-160.353836,0.009166,0.002332,0.059240,84.554024,4.307387,0.592400,-160.353836,0.060159,0.000000
47.630001,18.917267,-160.309341,0.009162,0.002346,0.059578,84.148209,4.286714,0.595784,-160.309341,0.060558,0.000000
47.870003,18.974236,-160.353836,0.009179,0.002362,0.060003,84.401611,4.299623,0.600035,-160.353836,0.060957,0.000000
48.110001,19.558487,-160.309341,0.009214,0.002380,0.060446,87.000496,4.432016,0.604455,-160.309341,0.061356,0.000000
48.350002,19.840378,-160.398315,0.009209,0.002396,0.060871,88.254410,4.495894,0.608706,-160.398315,0.061755,0.000000
48.590004,19.841866,-160.353836,0.009209,0.002412,0.061261,88.261024,4.496231,0.612608,-160.353836,0.062163,0.000000
48.830002,19.866440,-160.353836,0.009231,0.002424,0.061582,88.370338,4.501800,0.615818,-160.353836,0.062562,0.000000
49.070004,20.044807,-160.398315,0.009235,0.002438,0.061937,89.163757,4.542219,0.619372,-160.398315,0.062961,0.000000
49.310001,20.222427,-160.353836,0.009265,0.002452,0.062293,89.953850,4.582468,0.622926,-160.353836,0.063360,0.000000
49.550003,20.312172,-160.398315,0.009274,0.002465,0.062622,90.353050,4.602804,0.626222,-160.398315,0.063758,0.000000
49.790001,20.820091,-160.398315,0.009278,0.002485,0.063125,92.612389,4.717900,0.631252,-160.398315,0.064157,0.000000
50.030003,21.816559,-160.353836,0.009296,0.002511,0.063784,97.044899,4.943703,0.637842,-160.353836,0.064556,0.000000
50.270004,21.592392,-160.398315,0.009330,0.002522,0.064062,96.047760,4.892906,0.640620,-160.398315,0.064955,0.000000
50.510002,21.682503,-160.398315,0.009334,0.002539,0.064487,96.448586,4.913325,0.644867,-160.398315,0.065363,0.000000
50.750004,21.844482,-160.442795,0.009343,0.002552,0.064825,97.169113,4.950030,0.648250,-160.442795,0.065762,0.000000
50.990002,22.216110,-160.398315,0.009352,0.002571,0.065293,98.822197,5.034243,0.652932,-160.398315,0.066161,0.000000
51.230003,22.079079,-160.353836,0.009369,0.002580,0.065528,98.212646,5.003191,0.655275,-160.353836,0.066560,0.000000
51.470001,22.153923,-160.487274,0.009378,0.002593,0.065874,98.545570,5.020151,0.658742,-160.487274,0.066959,0.000000
51.710003,22.715462,-160.398315,0.009408,0.002611,0.066308,101.043419,5.147398,0.663080,-160.398315,0.067358,0.000000
51.950001,23.591286,-160.487274,0.009386,0.002635,0.066941,104.939278,5.345862,0.669412,-160.487274,0.067756,0.000000
52.190002,23.743958,-160.487274,0.009438,0.002651,0.067340,105.618401,5.380458,0.673401,-160.487274,0.068155,0.000000
52.430004,23.803162,-160.398315,0.009455,0.002664,0.067661,105.881752,5.393874,0.676611,-160.398315,0.068563,0.000000
52.670002,23.872055,-160.531754,0.009451,0.002677,0.068008,106.188202,5.409485,0.680077,-160.531754,0.068962,0.000000
52.910004,24.433594,-160.442795,0.009472,0.002697,0.068502,108.686050,5.536731,0.685021,-160.442795,0.069360,0.000000
53.150002,24.591103,-160.487274,0.009472,0.002710,0.068840,109.386688,5.572423,0.688404,-160.487274,0.069759,0.000000
53.390003,24.538223,-160.487274,0.009494,0.002722,0.069127,109.151466,5.560441,0.691266,-160.487274,0.070158,0.000000
53.630001,24.803352,-160.531754,0.009490,0.002736,0.069499,110.330818,5.620520,0.694994,-160.531754,0.070557,0.000000
53.870003,25.823280,-160.576233,0.009520,0.002760,0.070098,114.867691,5.851639,0.700978,-160.576233,0.070956,0.000000
54.110004,25.984146,-160.531754,0.009550,0.002774,0.070462,115.583252,5.888092,0.704619,-160.531754,0.071355,0.000000
54.350002,26.352425,-160.531754,0.009533,0.002792,0.070904,117.221436,5.971545,0.709043,-160.531754,0.071763,0.000000
54.590004,26.444771,-160.531754,0.009554,0.002803,0.071208,117.632217,5.992471,0.712079,-160.531754,0.072162,0.000000
54.830002,26.553879,-160.442795,0.009559,0.002818,0.071572,118.117554,6.017195,0.715720,-160.442795,0.072561,0.000000
55.070004,27.453156,-160.576233,0.009585,0.002838,0.072092,122.117737,6.220974,0.720924,-160.576233,0.072960,0.000000
55.310001,27.197708,-160.531754,0.009589,0.002847,0.072318,120.981445,6.163089,0.723180,-160.531754,0.073358,0.000000
55.550003,27.482574,-160.531754,0.009636,0.002862,0.072691,122.248596,6.227640,0.726908,-160.531754,0.073757,0.000000
55.790001,28.485001,-160.620712,0.009619,0.002885,0.073289,126.707611,6.454793,0.732892,-160.620712,0.074156,0.000000
56.030003,28.875252,-160.531754,0.009641,0.002902,0.073706,128.443527,6.543225,0.737055,-160.531754,0.074555,0.000000
56.270004,28.849556,-160.620712,0.009641,0.002912,0.073966,128.329239,6.537403,0.739656,-160.620712,0.074963,0.000000
56.510002,29.371994,-160.576233,0.009679,0.002930,0.074425,130.653152,6.655789,0.744254,-160.576233,0.075362,0.000000
56.750004,29.702660,-160.620712,0.009649,0.002947,0.074841,132.124023,6.730719,0.748414,-160.620712,0.075761,0.000000
56.990002,30.140198,-160.620712,0.009679,0.002960,0.075188,134.070297,6.829866,0.751885,-160.620712,0.076160,0.000000
57.230003,30.514061,-160.576233,0.009714,0.002977,0.075605,135.733322,6.914585,0.756048,-160.576233,0.076559,0.000000
57.470001,30.679024,-160.620712,0.009701,0.002989,0.075925,136.467117,6.951966,0.759254,-160.620712,0.076958,0.000000
57.710003,31.332909,-160.620712,0.009714,0.003008,0.076403,139.375732,7.100139,0.764026,-160.620712,0.077356,0.000000
57.950005,32.308899,-160.620712,0.009740,0.003029,0.076931,143.717163,7.321301,0.769314,-160.620712,0.077764,0.000000
58.190002,32.182663,-160.665192,0.009761,0.003041,0.077252,143.155640,7.292696,0.772524,-160.665192,0.078163,0.000000
58.430004,32.866707,-160.620712,0.009779,0.003057,0.077643,146.198410,7.447702,0.776426,-160.620712,0.078562,0.000000
58.670002,33.350052,-160.665192,0.009766,0.003075,0.078102,148.348434,7.557230,0.781024,-160.665192,0.078961,0.000000
58.910004,33.855354,-160.665192,0.009796,0.003090,0.078493,150.596130,7.671733,0.784927,-160.665192,0.079360,0.000000
59.150002,33.993134,-160.709671,0.009809,0.003103,0.078822,151.209015,7.702954,0.788220,-160.709671,0.079759,0.000000
59.390003,34.100380,-160.709671,0.009791,0.003113,0.079065,151.686066,7.727256,0.790649,-160.709671,0.080158,0.000000
59.630001,34.627655,-160.665192,0.009822,0.003131,0.079516,154.031509,7.846739,0.795157,-160.665192,0.080557,0.000000
59.870003,35.856491,-160.709671,0.009826,0.003152,0.080054,159.497635,8.125197,0.800536,-160.709671,0.080964,0.000000
60.110004,36.191994,-160.665192,0.009856,0.003166,0.080409,160.990036,8.201223,0.804090,-160.665192,0.081363,0.000000
60.350002,36.298866,-160.754150,0.009856,0.003178,0.080721,161.465424,8.225440,0.807212,-160.754150,0.081762,0.000000
60.590004,37.113243,-160.665192,0.009869,0.003195,0.081155,165.087952,8.409981,0.811550,-160.665192,0.082161,0.000000
60.830002,37.681114,-160.754150,0.009869,0.003213,0.081606,167.613968,8.538663,0.816057,-160.754150,0.082560,0.000000
61.070004,38.023697,-160.754150,0.009886,0.003223,0.081857,169.137848,8.616293,0.818574,-160.754150,0.082959,0.000000
61.310001,38.501450,-160.665192,0.009878,0.003241,0.082317,171.263000,8.724553,0.823169,-160.665192,0.083358,0.000000
61.550003,39.226089,-160.709671,0.009912,0.003259,0.082785,174.486359,8.888759,0.827851,-160.709671,0.083757,0.000000
61.790005,40.445976,-160.709671,0.009938,0.003277,0.083245,179.912689,9.165190,0.832450,-160.709671,0.084164,0.000000
62.030003,40.516731,-160.709671,0.009938,0.003288,0.083522,180.227417,9.181223,0.835224,-160.709671,0.084563,0.000000
62.270004,41.111038,-160.798645,0.009942,0.003305,0.083939,182.871033,9.315895,0.839388,-160.798645,0.084962,0.000000
62.510002,41.598473,-160.709671,0.009960,0.003320,0.084338,185.039246,9.426349,0.843377,-160.709671,0.085361,0.000000
62.750004,42.612816,-160.798645,0.009960,0.003339,0.084806,189.551270,9.656201,0.848059,-160.798645,0.085760,0.000000
62.990002,42.898796,-160.843124,0.009985,0.003352,0.085136,190.823380,9.721006,0.851355,-160.843124,0.086159,0.000000
63.230003,43.609657,-160.754150,0.009994,0.003367,0.085526,193.985443,9.882090,0.855258,-160.754150,0.086558,0.000000
63.470001,44.260193,-160.798645,0.009990,0.003384,0.085942,196.879166,10.029503,0.859421,-160.798645,0.086957,0.000000
63.710003,45.629776,-160.754150,0.009985,0.003406,0.086506,202.971375,10.339855,0.865057,-160.754150,0.087364,0.000000
63.950005,46.090775,-160.843124,0.010007,0.003420,0.086861,205.022003,10.444319,0.868611,-160.843124,0.087763,0.000000
64.190002,46.433731,-160.754150,0.010046,0.003433,0.087208,206.547546,10.522034,0.872081,-160.754150,0.088162,0.000000
64.430000,46.948349,-160.798645,0.010020,0.003448,0.087590,208.836685,10.638647,0.875897,-160.798645,0.088561,0.000000
64.670006,48.082596,-160.798645,0.010059,0.003469,0.088101,213.882065,10.895672,0.881014,-160.798645,0.088960,0.000000
64.910004,48.472092,-160.754150,0.010080,0.003479,0.088379,215.614639,10.983933,0.883788,-160.754150,0.089359,0.000000
65.150002,48.835533,-160.887604,0.010059,0.003493,0.088717,217.231308,11.066290,0.887172,-160.887604,0.089758,0.000000
65.389999,49.401909,-160.843124,0.010093,0.003508,0.089099,219.750671,11.194633,0.890987,-160.843124,0.090157,0.000000
65.630005,51.244781,-160.754150,0.010089,0.003531,0.089697,227.948166,11.612234,0.896971,-160.754150,0.090564,0.000000
65.870003,51.693489,-160.887604,0.010098,0.003543,0.090001,229.944122,11.713912,0.900006,-160.887604,0.090963,0.000000
66.110001,52.178314,-160.843124,0.010115,0.003559,0.090391,232.100739,11.823775,0.903909,-160.843124,0.091362,0.000000
66.350006,52.663521,-160.843124,0.010128,0.003570,0.090677,234.259033,11.933724,0.906770,-160.843124,0.091761,0.000000
66.590004,53.654030,-160.887604,0.010141,0.003589,0.091154,238.665039,12.158176,0.911539,-160.887604,0.092160,0.000000
66.830002,54.581612,-160.843124,0.010141,0.003606,0.091588,242.791138,12.368370,0.915876,-160.843124,0.092559,0.000000
67.070000,55.000526,-160.887604,0.010162,0.003618,0.091891,244.654556,12.463298,0.918912,-160.887604,0.092958,0.000000
67.310005,55.620155,-160.887604,0.010154,0.003629,0.092186,247.410812,12.603707,0.921860,-160.887604,0.093357,0.000000
67.550003,57.180771,-160.932083,0.010184,0.003654,0.092802,254.352768,12.957348,0.928018,-160.932083,0.093764,0.000000
67.790001,57.894234,-160.843124,0.010184,0.003667,0.093131,257.526428,13.119020,0.931311,-160.843124,0.094163,0.000000
68.030006,58.218575,-160.976562,0.010171,0.003681,0.093487,258.969147,13.192517,0.934869,-160.976562,0.094562,0.000000
68.270004,59.611618,-160.932083,0.010201,0.003699,0.093955,265.165710,13.508185,0.939551,-160.932083,0.094961,0.000000
68.510002,60.328430,-160.843124,0.010201,0.003714,0.094337,268.354248,13.670618,0.943366,-160.843124,0.095360,0.000000
68.750000,61.539391,-160.932083,0.010214,0.003733,0.094814,273.740875,13.945025,0.948139,-160.932083,0.095759,0.000000
68.990005,62.147102,-160.887604,0.010205,0.003745,0.095117,276.444122,14.082735,0.951171,-160.887604,0.096158,0.000000
69.230003,62.697464,-160.976562,0.010227,0.003761,0.095533,278.892242,14.207449,0.955334,-160.976562,0.096557,0.000000
69.470001,64.268135,-160.932083,0.010227,0.003779,0.095985,285.878937,14.563368,0.959846,-160.932083,0.096964,0.000000
69.710007,65.358437,-160.932083,0.010227,0.003795,0.096401,290.728851,14.810433,0.964009,-160.932083,0.097363,0.000000
69.950005,66.028343,-161.021042,0.010240,0.003811,0.096808,293.708740,14.962237,0.968082,-161.021042,0.097762,0.000000
70.190002,66.704933,-160.976562,0.010236,0.003824,0.097120,296.718353,15.115554,0.971204,-160.976562,0.098161,0.000000
70.430000,67.317863,-161.021042,0.010270,0.003825,0.097155,299.444824,15.254446,0.971552,-161.021042,0.097441,0.000000
70.670006,66.576851,-160.976562,0.010257,0.003825,0.097155,296.148621,15.086531,0.971552,-160.976562,0.097441,0.000000
70.910004,65.998177,-160.932083,0.010283,0.003822,0.097069,293.574554,14.955400,0.970686,-160.932083,0.097155,0.000000
71.150002,65.445580,-161.110001,0.010279,0.003821,0.097042,291.116486,14.830180,0.970424,-161.110001,0.097155,0.000000
71.390007,64.958885,-161.021042,0.010287,0.003820,0.097034,288.951538,14.719894,0.970337,-161.021042,0.097155,0.000000
71.630005,64.514275,-161.021042,0.010292,0.003820,0.097025,286.973816,14.619143,0.970250,-161.021042,0.097155,0.000000
71.870003,64.127007,-161.021042,0.010296,0.003820,0.097025,285.251160,14.531387,0.970250,-161.021042,0.097155,0.000000
72.110001,63.768410,-160.976562,0.010292,0.003820,0.097016,283.656067,14.450129,0.970163,-160.976562,0.097155,0.000000
72.350006,63.443703,-161.021042,0.010300,0.003820,0.097016,282.211670,14.376549,0.970163,-161.021042,0.097155,0.000000
72.590004,63.152138,-161.021042,0.010313,0.003820,0.097016,280.914734,14.310478,0.970163,-161.021042,0.097155,0.000000
72.830002,62.874344,-161.065521,0.010296,0.003820,0.097016,279.679047,14.247530,0.970163,-161.065521,0.097155,0.000000
73.070000,62.628952,-161.065521,0.010322,0.003819,0.097008,278.587494,14.191924,0.970076,-161.065521,0.097155,0.000000
73.310005,62.393982,-161.065521,0.010305,0.003819,0.097008,277.542297,14.138679,0.970076,-161.065521,0.097155,0.000000
73.550003,62.162743,-161.021042,0.010283,0.003819,0.097008,276.513702,14.086279,0.970076,-161.021042,0.097155,0.000000
73.790001,61.982513,-161.021042,0.010305,0.003819,0.097008,275.711975,14.045438,0.970076,-161.021042,0.097155,0.000000
74.030006,61.783669,-161.110001,0.010313,0.003819,0.097008,274.827484,14.000379,0.970076,-161.110001,0.097155,0.000000
74.270004,61.601944,-161.065521,0.010313,0.003819,0.097008,274.019135,13.959201,0.970076,-161.065521,0.097155,0.000000
74.510002,61.431030,-161.110001,0.010305,0.003819,0.097008,273.258881,13.920470,0.970076,-161.110001,0.097155,0.000000
74.750000,61.274261,-161.154480,0.010317,0.003819,0.097008,272.561523,13.884946,0.970076,-161.154480,0.097155,0.000000
74.990005,61.119728,-161.110001,0.010317,0.003819,0.097008,271.874115,13.849928,0.970076,-161.110001,0.097155,0.000000
75.230003,60.967796,-161.154480,0.010305,0.003819,0.097008,271.198303,13.815500,0.970076,-161.154480,0.097155,0.000000
75.470001,60.825180,-161.110001,0.010317,0.003819,0.097008,270.563904,13.783182,0.970076,-161.110001,0.097155,0.000000
75.710007,60.690750,-161.110001,0.010305,0.003819,0.097008,269.965942,13.752721,0.970076,-161.110001,0.097155,0.000000
75.950005,60.573830,-161.154480,0.010313,0.003819,0.097008,269.445862,13.726226,0.970076,-161.154480,0.097155,0.000000
76.190002,60.449455,-161.065521,0.010326,0.003819,0.097008,268.892609,13.698043,0.970076,-161.065521,0.097155,0.000000
76.430000,60.339607,-161.154480,0.010305,0.003819,0.097008,268.403992,13.673150,0.970076,-161.154480,0.097155,0.000000
76.670006,60.219704,-161.154480,0.010322,0.003819,0.097008,267.870605,13.645980,0.970076,-161.154480,0.097155,0.000000
76.910004,60.134796,-161.198959,0.010317,0.003819,0.097008,267.492920,13.626740,0.970076,-161.198959,0.097155,0.000000
77.150002,60.016754,-161.154480,0.010322,0.003819,0.096999,266.967865,13.599991,0.969993,-161.154480,0.097155,0.000000
77.390007,59.928505,-161.198959,0.010330,0.003819,0.096999,266.575317,13.579993,0.969993,-161.198959,0.097155,0.000000
77.630005,59.824615,-161.243454,0.010330,0.003819,0.096999,266.113190,13.556452,0.969993,-161.243454,0.097155,0.000000
77.870003,59.749023,-161.110001,0.010309,0.003819,0.096999,265.776917,13.539322,0.969993,-161.110001,0.097155,0.000000
78.110001,59.646622,-161.198959,0.010317,0.003819,0.096999,265.321411,13.516117,0.969993,-161.198959,0.097155,0.000000
78.350006,59.572517,-161.287933,0.010335,0.003819,0.096999,264.991791,13.499325,0.969993,-161.287933,0.097155,0.000000
78.590004,59.486870,-161.198959,0.010335,0.003819,0.096999,264.610809,13.479918,0.969993,-161.198959,0.097155,0.000000
78.830002,59.403458,-161.243454,0.010322,0.003819,0.096999,264.239777,13.461017,0.969993,-161.243454,0.097155,0.000000
79.070007,59.329727,-161.198959,0.010343,0.003819,0.096999,263.911804,13.444308,0.969993,-161.198959,0.097155,0.000000
79.310005,59.241852,-161.243454,0.010305,0.003819,0.096999,263.520905,13.424396,0.969993,-161.243454,0.097155,0.000000
79.550003,59.187111,-161.287933,0.010335,0.003819,0.096999,263.277405,13.411991,0.969993,-161.287933,0.097155,0.000000
79.790001,59.113754,-161.198959,0.010317,0.003819,0.096999,262.951111,13.395369,0.969993,-161.198959,0.097155,0.000000
80.030006,59.042259,-161.287933,0.010352,0.003819,0.096999,262.633087,13.379167,0.969993,-161.287933,0.097155,0.000000
80.270004,58.967781,-161.332413,0.010330,0.003819,0.096999,262.301788,13.362290,0.969993,-161.332413,0.097155,0.000000
80.510002,58.913048,-161.287933,0.010326,0.003819,0.096999,262.058319,13.349887,0.969993,-161.287933,0.097155,0.000000
80.750008,58.846390,-161.243454,0.010343,0.003819,0.096999,261.761810,13.334783,0.969993,-161.243454,0.097155,0.000000
80.990005,58.793518,-161.243454,0.010326,0.003819,0.096999,261.526642,13.322802,0.969993,-161.243454,0.097155,0.000000
81.230003,58.716431,-161.376892,0.010330,0.003819,0.096999,261.183716,13.305333,0.969993,-161.376892,0.097155,0.000000
81.470001,58.668396,-161.332413,0.010326,0.003819,0.096999,260.970062,13.294448,0.969993,-161.332413,0.097155,0.000000
81.710007,58.607704,-161.332413,0.010330,0.003819,0.096999,260.700073,13.280695,0.969993,-161.332413,0.097155,0.000000
81.950005,58.546257,-161.376892,0.010330,0.003819,0.096999,260.426758,13.266771,0.969993,-161.376892,0.097155,0.000000
82.190002,58.491524,-161.287933,0.010335,0.003819,0.096999,260.183289,13.254369,0.969993,-161.287933,0.097155,0.000000
82.430000,58.441254,-161.376892,0.010352,0.003819,0.096999,259.959686,13.242977,0.969993,-161.376892,0.097155,0.000000
82.670006,58.370499,-161.376892,0.010330,0.003819,0.096999,259.644958,13.226944,0.969993,-161.376892,0.097155,0.000000
82.910004,58.333633,-161.332413,0.010322,0.003819,0.096999,259.480957,13.218590,0.969993,-161.332413,0.097155,0.000000
83.150002,58.282990,-161.332413,0.010317,0.003819,0.096999,259.255676,13.207114,0.969993,-161.332413,0.097155,0.000000
83.390007,58.238304,-161.287933,0.010317,0.003819,0.096999,259.056915,13.196989,0.969993,-161.287933,0.097155,0.000000
83.630005,58.192131,-161.376892,0.010330,0.003819,0.096999,258.851532,13.186526,0.969993,-161.376892,0.097155,0.000000
83.870003,58.149681,-161.376892,0.010343,0.003819,0.096999,258.662689,13.176907,0.969993,-161.376892,0.097155,0.000000
84.110001,58.099411,-161.421371,0.010352,0.003819,0.096999,258.439087,13.165515,0.969993,-161.421371,0.097155,0.000000
84.350006,58.062920,-161.376892,0.010335,0.003819,0.096999,258.276764,13.157246,0.969993,-161.376892,0.097155,0.000000
84.590004,58.020470,-161.376892,0.010322,0.003819,0.096999,258.087952,13.147627,0.969993,-161.376892,0.097155,0.000000
84.830002,57.967216,-161.421371,0.010348,0.003819,0.096999,257.851044,13.135559,0.969993,-161.421371,0.097155,0.000000
85.070007,57.926628,-161.376892,0.010326,0.003819,0.096999,257.670502,13.126362,0.969993,-161.376892,0.097155,0.000000
85.310005,57.883064,-161.465851,0.010326,0.003819,0.096999,257.476715,13.116489,0.969993,-161.465851,0.097155,0.000000
85.550003,57.857742,-161.421371,0.010352,0.003819,0.096999,257.364105,13.110752,0.969993,-161.421371,0.097155,0.000000
85.790001,57.800766,-161.376892,0.010339,0.003819,0.096999,257.110657,13.097840,0.969993,-161.376892,0.097155,0.000000
86.030006,57.766510,-161.465851,0.010335,0.003819,0.096999,256.958282,13.090078,0.969993,-161.465851,0.097155,0.000000
86.270004,57.717361,-161.376892,0.010317,0.003819,0.096999,256.739655,13.078941,0.969993,-161.376892,0.097155,0.000000
86.510002,57.683846,-161.465851,0.010309,0.003819,0.096999,256.590546,13.071346,0.969993,-161.465851,0.097155,0.000000
86.750008,57.650330,-161.421371,0.010335,0.003819,0.096999,256.441467,13.063751,0.969993,-161.421371,0.097155,0.000000
86.990005,57.603409,-161.421371,0.010330,0.003819,0.096999,256.232758,13.053119,0.969993,-161.421371,0.097155,0.000000
87.230003,57.558357,-161.465851,0.010326,0.003819,0.096999,256.032349,13.042910,0.969993,-161.465851,0.097155,0.000000
87.470001,57.513672,-161.421371,0.010322,0.003819,0.096999,255.833588,13.032784,0.969993,-161.421371,0.097155,0.000000
87.710007,57.485367,-161.554810,0.010309,0.003819,0.096999,255.707687,13.026370,0.969993,-161.554810,0.097155,0.000000
87.950005,57.449997,-161.465851,0.010335,0.003819,0.096999,255.550354,13.018355,0.969993,-161.465851,0.097155,0.000000
88.190002,57.413872,-161.465851,0.010343,0.003819,0.096999,255.389664,13.010169,0.969993,-161.465851,0.097155,0.000000
88.430008,57.376640,-161.554810,0.010348,0.003819,0.096999,255.224045,13.001733,0.969993,-161.554810,0.097155,0.000000
88.670006,57.351318,-161.465851,0.010348,0.003819,0.096999,255.111404,12.995995,0.969993,-161.465851,0.097155,0.000000
88.910004,57.299553,-161.510330,0.010330,0.003819,0.096999,254.881134,12.984264,0.969993,-161.510330,0.097155,0.000000
89.150002,57.282051,-161.510330,0.010352,0.003819,0.096999,254.803284,12.980298,0.969993,-161.510330,0.097155,0.000000
89.390007,57.249657,-161.554810,0.010322,0.003819,0.096999,254.659195,12.972958,0.969993,-161.554810,0.097155,0.000000
89.630005,57.227692,-161.554810,0.010348,0.003819,0.096999,254.561493,12.967980,0.969993,-161.554810,0.097155,0.000000
89.870003,57.188217,-161.554810,0.010348,0.003819,0.096999,254.385895,12.959035,0.969993,-161.554810,0.097155,0.000000
90.110001,57.171829,-161.599289,0.010339,0.003819,0.096999,254.313004,12.955321,0.969993,-161.599289,0.097155,0.000000
90.350006,57.124916,-161.554810,0.010352,0.003819,0.096999,254.104324,12.944692,0.969993,-161.554810,0.097155,0.000000
90.590004,57.109650,-161.554810,0.010326,0.003819,0.096999,254.036407,12.941232,0.969993,-161.554810,0.097155,0.000000
90.830002,57.073524,-161.554810,0.010352,0.003819,0.096999,253.875717,12.933045,0.969993,-161.554810,0.097155,0.000000
91.070007,57.038895,-161.510330,0.010339,0.003819,0.096999,253.721680,12.925199,0.969993,-161.510330,0.097155,0.000000
91.310005,57.031822,-161.599289,0.010335,0.003819,0.096999,253.690216,12.923595,0.969993,-161.599289,0.097155,0.000000
91.550003,56.992348,-161.554810,0.010339,0.003819,0.096999,253.514618,12.914651,0.969993,-161.554810,0.097155,0.000000
91.790001,56.958466,-161.554810,0.010322,0.003819,0.096999,253.363907,12.906972,0.969993,-161.554810,0.097155,0.000000
92.030006,56.932396,-161.643784,0.010339,0.003819,0.096999,253.247940,12.901065,0.969993,-161.643784,0.097155,0.000000
92.270004,56.905212,-161.599289,0.010335,0.003819,0.096999,253.127029,12.894905,0.969993,-161.599289,0.097155,0.000000
92.510002,56.872070,-161.688263,0.010330,0.003819,0.096999,252.979599,12.887396,0.969993,-161.688263,0.097155,0.000000
92.750008,56.856430,-161.599289,0.010348,0.003819,0.096999,252.910034,12.883852,0.969993,-161.599289,0.097155,0.000000
92.990005,56.816589,-161.688263,0.010348,0.003819,0.096999,252.732819,12.874823,0.969993,-161.688263,0.097155,0.000000
93.230003,56.796852,-161.643784,0.010348,0.003819,0.096999,252.645020,12.870351,0.969993,-161.643784,0.097155,0.000000
93.470001,56.764458,-161.688263,0.010335,0.003819,0.096999,252.500916,12.863010,0.969993,-161.688263,0.097155,0.000000
93.710007,56.746582,-161.643784,0.010335,0.003819,0.096999,252.421402,12.858959,0.969993,-161.643784,0.097155,0.000000
93.950005,56.703018,-161.599289,0.010330,0.003819,0.096999,252.227615,12.849088,0.969993,-161.599289,0.097155,0.000000
94.190002,56.689613,-161.732742,0.010313,0.003819,0.096999,252.167999,12.846050,0.969993,-161.732742,0.097155,0.000000
94.430008,56.665031,-161.688263,0.010343,0.003819,0.096999,252.058655,12.840480,0.969993,-161.688263,0.097155,0.000000
94.670006,56.639709,-161.688263,0.010343,0.003819,0.096999,251.946014,12.834742,0.969993,-161.688263,0.097155,0.000000
94.910004,56.615509,-161.688263,0.010356,0.003819,0.096999,251.838364,12.829258,0.969993,-161.688263,0.097155,0.000000
95.150002,56.590561,-161.643784,0.010335,0.003819,0.096999,251.727386,12.823605,0.969993,-161.643784,0.097155,0.000000
95.390007,56.574921,-161.777222,0.010343,0.003819,0.096999,251.657822,12.820060,0.969993,-161.777222,0.097155,0.000000
95.630005,56.531723,-161.688263,0.010339,0.003819,0.096999,251.465668,12.810272,0.969993,-161.688263,0.097155,0.000000
95.870003,56.524651,-161.688263,0.010305,0.003819,0.096999,251.434204,12.808668,0.969993,-161.688263,0.097155,0.000000
96.110008,56.505287,-161.732742,0.010361,0.003819,0.096999,251.348068,12.804281,0.969993,-161.732742,0.097155,0.000000
96.350006,56.489647,-161.777222,0.010352,0.003819,0.096999,251.278503,12.800736,0.969993,-161.777222,0.097155,0.000000
96.590004,56.453896,-161.732742,0.010335,0.003819,0.096999,251.119476,12.792635,0.969993,-161.732742,0.097155,0.000000
96.830002,56.443100,-161.732742,0.010348,0.003819,0.096999,251.071442,12.790190,0.969993,-161.732742,0.097155,0.000000
97.070007,56.412193,-161.821701,0.010348,0.003819,0.096999,250.933975,12.783186,0.969993,-161.821701,0.097155,0.000000
97.310005,56.401764,-161.732742,0.010348,0.003819,0.096999,250.887573,12.780823,0.969993,-161.732742,0.097155,0.000000
97.550003,56.369743,-161.732742,0.010352,0.003819,0.096999,250.745148,12.773566,0.969993,-161.732742,0.097155,0.000000
97.790001,56.351494,-161.777222,0.010330,0.003819,0.096999,250.663971,12.769431,0.969993,-161.777222,0.097155,0.000000
98.030006,56.326546,-161.732742,0.010339,0.003819,0.096999,250.552994,12.763778,0.969993,-161.732742,0.097155,0.000000
98.270004,56.310905,-161.732742,0.010335,0.003819,0.096999,250.483414,12.760234,0.969993,-161.732742,0.097155,0.000000
98.510002,56.298622,-161.777222,0.010356,0.003819,0.096999,250.428772,12.757450,0.969993,-161.777222,0.097155,0.000000
98.750008,56.255051,-161.777222,0.010348,0.003819,0.096999,250.234970,12.747577,0.969993,-161.777222,0.097155,0.000000
98.990005,56.258400,-161.866180,0.010330,0.003819,0.096999,250.249863,12.748335,0.969993,-161.866180,0.097155,0.000000
99.230003,56.232712,-161.777222,0.010348,0.003819,0.096999,250.135590,12.742515,0.969993,-161.777222,0.097155,0.000000
99.470001,56.202919,-161.821701,0.010335,0.003819,0.096999,250.003067,12.735764,0.969993,-161.821701,0.097155,0.000000
99.710007,56.191750,-161.821701,0.010317,0.003819,0.096999,249.953384,12.733232,0.969993,-161.821701,0.097155,0.000000
99.950005,56.166428,-161.777222,0.010361,0.003819,0.096999,249.840744,12.727494,0.969993,-161.777222,0.097155,0.000000
100.190002,56.152649,-161.821701,0.010343,0.003819,0.096999,249.779465,12.724372,0.969993,-161.821701,0.097155,0.000000
100.430008,56.129189,-161.821701,0.010335,0.003819,0.096999,249.675095,12.719055,0.969993,-161.821701,0.097155,0.000000
100.670006,56.109825,-161.910660,0.010335,0.003819,0.096999,249.588974,12.714668,0.969993,-161.910660,0.097155,0.000000
100.900002,56.088226,-161.866180,0.010343,0.003819,0.096999,249.492889,12.709774,0.969993,-161.866180,0.097155,0.000000