File: Data/compression sample NH 10,12,15/AutoNoheating-10-2-2-240201_02012024_191026.csv
Time (sec),S:Load (lbs),S:HL1 (DIM),S:LVDT (in),S:Position (in),Ch:Position (mm),Ch:Load (N),Ch:Stress (MPa),Ch:Strain (mm/mm),Ch:HL1 (DIM),Set Point (),Cycles ()
0.110000,0.001122,-242.999435,0.000004,-0.000000,-0.000009,0.004989,0.000254,-0.000087,-242.999435,0.000208,0.000000
0.370000,0.003357,-242.999435,-0.000026,0.000009,0.000217,0.014932,0.000761,0.002169,-242.999435,0.000815,0.000000
0.630000,0.010429,-243.043915,-0.000009,0.000166,0.004223,0.046392,0.002363,0.042232,-243.043915,0.005151,0.000000
0.890000,-0.010422,-242.999435,0.000181,0.000333,0.008447,-0.046358,-0.002362,0.084468,-242.999435,0.009487,0.000000
1.150000,-0.008934,-243.088394,0.000358,0.000499,0.012679,-0.039741,-0.002024,0.126786,-243.088394,0.013824,0.000000
1.410000,-0.010048,-243.043915,0.000487,0.000670,0.017024,-0.044695,-0.002277,0.170237,-243.043915,0.018142,0.000000
1.670000,-0.056595,-243.132874,0.000703,0.000841,0.021368,-0.251746,-0.012825,0.213684,-243.132874,0.022478,0.000000
1.930000,-0.018990,-243.088394,0.000854,0.001013,0.025722,-0.084470,-0.004303,0.257218,-243.088394,0.026814,0.000000
2.190000,0.000374,-243.043915,0.001052,0.001186,0.030127,0.001663,0.000085,0.301274,-243.043915,0.031151,0.000000
2.450000,-0.023460,-243.132874,0.001216,0.001353,0.034368,-0.104357,-0.005316,0.343680,-243.132874,0.035469,0.000000
2.710000,0.007820,-243.132874,0.001427,0.001526,0.038765,0.034786,0.001772,0.387649,-243.132874,0.039806,0.000000
2.970000,0.011917,-243.132874,0.001604,0.001695,0.043058,0.053010,0.002700,0.430577,-243.132874,0.044142,0.000000
3.230000,-0.026062,-243.177353,0.001733,0.001865,0.047368,-0.115930,-0.005906,0.473680,-243.177353,0.048478,0.000000
3.490000,-0.007446,-243.088394,0.001957,0.002031,0.051582,-0.033123,-0.001687,0.515824,-243.088394,0.052797,0.000000
3.750000,-0.004837,-243.177353,0.002173,0.002207,0.056066,-0.021516,-0.001096,0.560660,-243.177353,0.057133,0.000000
4.010000,-0.061440,-243.088394,0.002289,0.002377,0.060376,-0.273297,-0.013922,0.603763,-243.088394,0.061469,0.000000
4.270000,0.015640,-243.132874,0.002501,0.002547,0.064686,0.069571,0.003544,0.646861,-243.132874,0.065788,0.000000
4.530000,0.000374,-243.088394,0.002656,0.002721,0.069118,0.001663,0.000085,0.691179,-243.088394,0.070124,0.000000
4.790000,-0.022339,-243.132874,0.002867,0.002889,0.073393,-0.099368,-0.005062,0.733933,-243.132874,0.074460,0.000000
5.050000,0.008942,-243.266327,0.002988,0.003056,0.077616,0.039774,0.002026,0.776165,-243.266327,0.078796,0.000000
5.310000,0.009682,-243.177353,0.003208,0.003232,0.082091,0.043066,0.002194,0.820913,-243.177353,0.083115,0.000000
5.570000,-0.014145,-243.132874,0.003406,0.003398,0.086297,-0.062920,-0.003205,0.862975,-243.132874,0.087451,0.000000
5.830000,0.003723,-243.221848,0.003514,0.003568,0.090634,0.016561,0.000844,0.906339,-243.221848,0.091787,0.000000
6.090000,-0.016006,-243.132874,0.003742,0.003743,0.095065,-0.071200,-0.003627,0.950652,-243.132874,0.096123,0.000000
6.350000,-0.027924,-243.266327,0.003872,0.003913,0.099392,-0.124210,-0.006328,0.993925,-243.266327,0.100442,0.000000
6.610000,0.037987,-243.177353,0.004087,0.004079,0.103607,0.168974,0.008608,1.036073,-243.177353,0.104778,0.000000
6.870000,0.029793,-243.221848,0.004260,0.004259,0.108178,0.132525,0.006751,1.081776,-243.221848,0.109114,0.000000
7.130000,0.015640,-243.221848,0.004419,0.004424,0.112358,0.069571,0.003544,1.123576,-243.221848,0.113450,0.000000
7.390000,0.078949,-243.221848,0.004622,0.004593,0.116659,0.351183,0.017890,1.166592,-243.221848,0.117769,0.000000
7.650001,0.467331,-243.266327,0.004812,0.004769,0.121125,2.078792,0.105899,1.211253,-243.266327,0.122105,0.000000
7.910000,0.599525,-243.266327,0.004829,0.000011,0.000269,2.666822,0.135854,0.002687,-243.266327,0.000486,0.000000
8.170000,0.566757,-243.221848,0.004850,0.000011,0.000269,2.521062,0.128429,0.002687,-243.221848,0.000486,0.000000
8.430000,0.551483,-243.266327,0.004846,0.000011,0.000269,2.453120,0.124968,0.002687,-243.266327,0.000798,0.000000
8.690001,0.564888,-243.221848,0.004833,0.000011,0.000269,2.512747,0.128005,0.002687,-243.221848,0.001232,0.000000
8.950001,0.604362,-243.310806,0.004820,0.000018,0.000468,2.688339,0.136950,0.004682,-243.310806,0.001665,0.000000
9.210000,0.757034,-243.266327,0.004863,0.000043,0.001101,3.367457,0.171546,0.011014,-243.266327,0.002099,0.000000
9.470000,0.883644,-243.310806,0.004889,0.000069,0.001743,3.930645,0.200237,0.017433,-243.310806,0.002532,0.000000
9.730000,0.962585,-243.266327,0.004937,0.000084,0.002134,4.281794,0.218125,0.021335,-243.266327,0.002966,0.000000
9.990001,1.019562,-243.221848,0.004928,0.000100,0.002541,4.535237,0.231036,0.025412,-243.221848,0.003400,0.000000
10.250001,1.078392,-243.355286,0.004954,0.000115,0.002914,4.796927,0.244367,0.029140,-243.355286,0.003825,0.000000
10.510000,1.212822,-243.221848,0.004980,0.000133,0.003391,5.394902,0.274829,0.033909,-243.221848,0.004258,0.000000
10.770000,1.290276,-243.355286,0.005006,0.000149,0.003781,5.739432,0.292381,0.037811,-243.355286,0.004692,0.000000
11.030001,1.342033,-243.266327,0.005001,0.000163,0.004145,5.969663,0.304109,0.041452,-243.266327,0.005126,0.000000
11.290001,1.467148,-243.355286,0.005010,0.000183,0.004657,6.526199,0.332460,0.046569,-243.355286,0.005559,0.000000
11.550000,1.561363,-243.310806,0.005040,0.000202,0.005143,6.945291,0.353810,0.051425,-243.310806,0.005993,0.000000
11.810000,1.565826,-243.266327,0.005066,0.000215,0.005455,6.965144,0.354821,0.054548,-243.266327,0.006426,0.000000
12.070001,1.663765,-243.355286,0.005066,0.000235,0.005958,7.400796,0.377015,0.059578,-243.355286,0.006860,0.000000
12.330001,1.686104,-243.310806,0.005057,0.000248,0.006305,7.500165,0.382077,0.063049,-243.310806,0.007293,0.000000
12.590000,1.873405,-243.310806,0.005088,0.000270,0.006851,8.333323,0.424520,0.068510,-243.310806,0.007727,0.000000
12.850000,1.930756,-243.399765,0.005101,0.000286,0.007267,8.588429,0.437515,0.072674,-243.399765,0.008161,0.000000
13.110001,1.935219,-243.399765,0.005118,0.000298,0.007580,8.608283,0.438527,0.075796,-243.399765,0.008594,0.000000
13.370001,2.091621,-243.399765,0.005161,0.000322,0.008187,9.303997,0.473968,0.081867,-243.399765,0.009028,0.000000
13.630001,2.135559,-243.355286,0.005161,0.000337,0.008568,9.499441,0.483925,0.085682,-243.355286,0.009461,0.000000
13.890000,2.159760,-243.399765,0.005178,0.000355,0.009019,9.607090,0.489408,0.090190,-243.399765,0.009895,0.000000
14.150001,2.197372,-243.399765,0.005234,0.000369,0.009384,9.774401,0.497932,0.093835,-243.399765,0.010329,0.000000
14.410001,2.356003,-243.399765,0.005247,0.000389,0.009869,10.480024,0.533878,0.098691,-243.399765,0.010762,0.000000
14.670001,2.411858,-243.444244,0.005226,0.000406,0.010320,10.728478,0.546535,0.103199,-243.444244,0.011196,0.000000
14.930000,2.460266,-243.399765,0.005273,0.000420,0.010667,10.943810,0.557504,0.106670,-243.399765,0.011629,0.000000
15.190001,2.495270,-243.399765,0.005303,0.000435,0.011057,11.099514,0.565436,0.110572,-243.399765,0.012063,0.000000
15.450001,2.678474,-243.399765,0.005307,0.000462,0.011734,11.914450,0.606951,0.117336,-243.399765,0.012497,0.000000
15.710001,2.649063,-243.444244,0.005295,0.000477,0.012106,11.783621,0.600286,0.121064,-243.444244,0.012930,0.000000
15.970001,2.604004,-243.355286,0.005355,0.000487,0.012375,11.583188,0.590076,0.123755,-243.355286,0.013364,0.000000
16.230001,2.787209,-243.399765,0.005364,0.000510,0.012956,12.398123,0.631590,0.129565,-243.399765,0.013797,0.000000
16.490002,2.878067,-243.444244,0.005342,0.000525,0.013347,12.802281,0.652179,0.133467,-243.444244,0.014231,0.000000
16.750000,2.920151,-243.533203,0.005428,0.000540,0.013711,12.989479,0.661716,0.137108,-243.533203,0.014665,0.000000
17.010000,3.018082,-243.444244,0.005402,0.000558,0.014171,13.425097,0.683907,0.141706,-243.444244,0.015098,0.000000
17.270000,3.101868,-243.488724,0.005420,0.000578,0.014691,13.797796,0.702893,0.146907,-243.488724,0.015532,0.000000
17.530001,3.152878,-243.488724,0.005450,0.000595,0.015116,14.024701,0.714452,0.151157,-243.488724,0.015966,0.000000
17.790001,3.150276,-243.488724,0.005480,0.000610,0.015497,14.013128,0.713863,0.154973,-243.488724,0.016399,0.000000
18.050001,3.217300,-243.533203,0.005471,0.000627,0.015922,14.311267,0.729051,0.159223,-243.533203,0.016833,0.000000
18.310001,3.306671,-243.488724,0.005514,0.000644,0.016365,14.708808,0.749302,0.163648,-243.488724,0.017267,0.000000
18.570002,3.350983,-243.488724,0.005545,0.000661,0.016781,14.905915,0.759344,0.167807,-243.488724,0.017700,0.000000
18.830002,3.386726,-243.533203,0.005562,0.000676,0.017180,15.064911,0.767443,0.171796,-243.533203,0.018134,0.000000
19.090000,3.531952,-243.533203,0.005558,0.000699,0.017761,15.710907,0.800352,0.177610,-243.533203,0.018567,0.000000
19.350000,3.540146,-243.488724,0.005579,0.000715,0.018151,15.747355,0.802208,0.181512,-243.488724,0.018992,0.000000
19.610001,3.571053,-243.488724,0.005601,0.000734,0.018654,15.884835,0.809212,0.186542,-243.488724,0.019426,0.000000
19.870001,3.594513,-243.577682,0.005618,0.000749,0.019027,15.989192,0.814528,0.190270,-243.577682,0.019859,0.000000
20.130001,3.662285,-243.488724,0.005644,0.000767,0.019487,16.290657,0.829886,0.194865,-243.488724,0.020293,0.000000
20.390001,3.698402,-243.533203,0.005674,0.000782,0.019859,16.451315,0.838070,0.198593,-243.533203,0.020727,0.000000
20.650002,3.753891,-243.577682,0.005678,0.000797,0.020233,16.698141,0.850644,0.202325,-243.577682,0.021160,0.000000
20.910002,3.804535,-243.577682,0.005713,0.000815,0.020709,16.923416,0.862120,0.207094,-243.577682,0.021594,0.000000
21.170000,3.918106,-243.622162,0.005739,0.000838,0.021290,17.428606,0.887856,0.212904,-243.622162,0.022028,0.000000
21.430000,3.920341,-243.622162,0.005764,0.000855,0.021715,17.438549,0.888362,0.217155,-243.622162,0.022461,0.000000
21.690001,3.870071,-243.577682,0.005769,0.000868,0.022053,17.214937,0.876971,0.220534,-243.577682,0.022895,0.000000
21.950001,3.871933,-243.666656,0.005803,0.000884,0.022452,17.223219,0.877393,0.224524,-243.666656,0.023329,0.000000
22.210001,3.992950,-243.577682,0.005786,0.000905,0.022982,17.761530,0.904815,0.229815,-243.577682,0.023762,0.000000
22.470001,4.010452,-243.622162,0.005842,0.000920,0.023380,17.839382,0.908781,0.233804,-243.622162,0.024196,0.000000
22.730001,3.997047,-243.622162,0.005868,0.000932,0.023684,17.779755,0.905744,0.236840,-243.622162,0.024629,0.000000
22.990002,4.099075,-243.622162,0.005907,0.000954,0.024231,18.233597,0.928864,0.242305,-243.622162,0.025063,0.000000
23.250002,4.129982,-243.711136,0.005902,0.000973,0.024716,18.371077,0.935867,0.247161,-243.711136,0.025497,0.000000
23.510000,4.109131,-243.577682,0.005902,0.000989,0.025132,18.278326,0.931142,0.251321,-243.577682,0.025930,0.000000
23.770000,4.107269,-243.711136,0.005924,0.001004,0.025514,18.270046,0.930721,0.255140,-243.711136,0.026364,0.000000
24.030001,4.191429,-243.622162,0.005959,0.001024,0.026000,18.644407,0.949791,0.259996,-243.622162,0.026797,0.000000
24.290001,4.195892,-243.622162,0.005963,0.001040,0.026416,18.664261,0.950803,0.264159,-243.622162,0.027231,0.000000
24.550001,4.110619,-243.711136,0.005989,0.001049,0.026632,18.284945,0.931479,0.266324,-243.711136,0.027665,0.000000
24.810001,4.280800,-243.622162,0.006006,0.001072,0.027231,19.041948,0.970043,0.272308,-243.622162,0.028098,0.000000
25.070002,4.303139,-243.755615,0.006040,0.001088,0.027630,19.141317,0.975105,0.276297,-243.755615,0.028532,0.000000
25.330002,4.345589,-243.711136,0.006049,0.001110,0.028202,19.330143,0.984724,0.282024,-243.711136,0.028965,0.000000
25.590002,4.307976,-243.666656,0.006101,0.001125,0.028584,19.162834,0.976201,0.285839,-243.666656,0.029399,0.000000
25.850000,4.286751,-243.755615,0.006114,0.001139,0.028931,19.068420,0.971392,0.289306,-243.755615,0.029833,0.000000
26.110001,4.341866,-243.666656,0.006114,0.001159,0.029434,19.313583,0.983881,0.294336,-243.666656,0.030266,0.000000
26.370001,4.347076,-243.755615,0.006161,0.001175,0.029841,19.336761,0.985062,0.298412,-243.755615,0.030700,0.000000
26.630001,4.397720,-243.711136,0.006148,0.001192,0.030275,19.562037,0.996538,0.302750,-243.711136,0.031133,0.000000
26.890001,4.447617,-243.711136,0.006170,0.001212,0.030795,19.783987,1.007844,0.307954,-243.711136,0.031567,0.000000
27.150002,4.417831,-243.755615,0.006209,0.001227,0.031160,19.651495,1.001095,0.311595,-243.755615,0.032001,0.000000
27.410002,4.407028,-243.711136,0.006217,0.001245,0.031610,19.603441,0.998647,0.316103,-243.711136,0.032434,0.000000
27.670002,4.397720,-243.755615,0.006239,0.001260,0.031992,19.562037,0.996538,0.319922,-243.755615,0.032868,0.000000
27.930002,4.531776,-243.755615,0.006273,0.001280,0.032521,20.158348,1.026915,0.325210,-243.755615,0.033301,0.000000
28.190001,4.449112,-243.755615,0.006308,0.001294,0.032859,19.790638,1.008183,0.328593,-243.755615,0.033735,0.000000
28.450001,4.323250,-243.800095,0.006291,0.001298,0.032981,19.230776,0.979662,0.329808,-243.800095,0.034160,0.000000
28.710001,4.615189,-243.800095,0.006329,0.001332,0.033831,20.529385,1.045817,0.338305,-243.800095,0.034594,0.000000
28.970001,4.609604,-243.755615,0.006385,0.001351,0.034307,20.504541,1.044551,0.343074,-243.755615,0.035027,0.000000
29.230001,4.518745,-243.800095,0.006381,0.001364,0.034637,20.100384,1.023962,0.346371,-243.800095,0.035461,0.000000
29.490002,4.520973,-243.800095,0.006428,0.001381,0.035079,20.110292,1.024467,0.350792,-243.800095,0.035894,0.000000
29.750002,4.441292,-243.844574,0.006407,0.001392,0.035357,19.755852,1.006411,0.353570,-243.844574,0.036328,0.000000
30.010002,4.582420,-243.800095,0.006463,0.001411,0.035843,20.383623,1.038391,0.358426,-243.800095,0.036762,0.000000
30.270002,4.467728,-243.844574,0.006454,0.001419,0.036033,19.873446,1.012402,0.360333,-243.844574,0.037195,0.000000
30.530001,4.653542,-243.800095,0.006459,0.001444,0.036684,20.699987,1.054508,0.366836,-243.800095,0.037629,0.000000
30.790001,4.752220,-243.844574,0.006510,0.001468,0.037291,21.138931,1.076869,0.372907,-243.844574,0.038062,0.000000
31.050001,4.671791,-243.889053,0.006510,0.001482,0.037646,20.781164,1.058643,0.376465,-243.889053,0.038496,0.000000
31.310001,4.638649,-243.889053,0.006571,0.001499,0.038080,20.633741,1.051133,0.380798,-243.889053,0.038930,0.000000
31.570002,4.612953,-243.889053,0.006562,0.001513,0.038436,20.519440,1.045310,0.384356,-243.889053,0.039363,0.000000
31.830002,4.698227,-243.889053,0.006605,0.001533,0.038930,20.898758,1.064633,0.389299,-243.889053,0.039797,0.000000
32.090000,4.689285,-243.844574,0.006622,0.001548,0.039329,20.858982,1.062607,0.393288,-243.844574,0.040231,0.000000
32.350002,4.664337,-243.889053,0.006622,0.001562,0.039676,20.748009,1.056954,0.396755,-243.889053,0.040664,0.000000
32.610001,4.768234,-243.933533,0.006657,0.001583,0.040196,21.210165,1.080497,0.401960,-243.933533,0.041098,0.000000
32.870003,4.824463,-243.889053,0.006683,0.001601,0.040664,21.460283,1.093239,0.406642,-243.889053,0.041532,0.000000
33.130001,4.725784,-243.933533,0.006666,0.001614,0.040985,21.021338,1.070878,0.409851,-243.933533,0.041965,0.000000
33.390003,4.748123,-243.889053,0.006696,0.001633,0.041471,21.120707,1.075940,0.414707,-243.889053,0.042399,0.000000
33.650002,4.725784,-243.978012,0.006752,0.001647,0.041826,21.021338,1.070878,0.418265,-243.978012,0.042833,0.000000
33.910000,4.888878,-243.844574,0.006778,0.001669,0.042381,21.746815,1.107836,0.423814,-243.844574,0.043266,0.000000
34.170002,4.881432,-243.978012,0.006799,0.001685,0.042798,21.713692,1.106148,0.427977,-243.978012,0.043700,0.000000
34.430000,4.819244,-243.889053,0.006786,0.001698,0.043136,21.437069,1.092056,0.431357,-243.889053,0.044133,0.000000
34.690002,4.955162,-243.933533,0.006804,0.001721,0.043717,22.041662,1.122856,0.437171,-243.933533,0.044567,0.000000
34.950001,4.912712,-244.022491,0.006842,0.001738,0.044133,21.852835,1.113236,0.441330,-244.022491,0.045001,0.000000
35.210003,4.880692,-243.978012,0.006885,0.001754,0.044558,21.710400,1.105980,0.445581,-243.978012,0.045434,0.000000
35.470001,4.828186,-243.978012,0.006890,0.001770,0.044957,21.476845,1.094083,0.449570,-243.978012,0.045868,0.000000
35.730003,4.976387,-243.933533,0.006903,0.001789,0.045443,22.136076,1.127665,0.454426,-243.933533,0.046301,0.000000
35.990002,4.977135,-243.978012,0.006933,0.001806,0.045868,22.139400,1.127835,0.458676,-243.978012,0.046735,0.000000
36.250000,4.967079,-243.933533,0.006959,0.001819,0.046197,22.094671,1.125556,0.461973,-243.933533,0.047168,0.000000
36.510002,4.956650,-243.978012,0.006980,0.001835,0.046614,22.048279,1.123193,0.466136,-243.978012,0.047602,0.000000
36.770000,5.140228,-243.933533,0.006998,0.001862,0.047299,22.864878,1.164792,0.472987,-243.933533,0.048036,0.000000
37.030003,4.972664,-243.978012,0.007011,0.001872,0.047559,22.119514,1.126822,0.475587,-243.978012,0.048469,0.000000
37.290001,5.038948,-244.022491,0.007054,0.001892,0.048062,22.414360,1.141842,0.480617,-244.022491,0.048894,0.000000
37.550003,5.086609,-243.978012,0.007036,0.001911,0.048547,22.626366,1.152642,0.485473,-243.978012,0.049328,0.000000
37.810001,5.037827,-244.022491,0.007080,0.001923,0.048851,22.409372,1.141588,0.488509,-244.022491,0.049762,0.000000
38.070004,5.058311,-244.111465,0.007101,0.001939,0.049259,22.500494,1.146230,0.492585,-244.111465,0.050195,0.000000
38.330002,5.175232,-244.022491,0.007127,0.001960,0.049788,23.020582,1.172724,0.497876,-244.022491,0.050629,0.000000
38.590000,5.157730,-244.066986,0.007114,0.001978,0.050230,22.942730,1.168758,0.502297,-244.066986,0.051062,0.000000
38.850002,5.188637,-244.066986,0.007131,0.001995,0.050663,23.080210,1.175762,0.506635,-244.066986,0.051496,0.000000
39.110001,5.159592,-244.022491,0.007148,0.002010,0.051054,22.951010,1.169180,0.510537,-244.022491,0.051930,0.000000
39.370003,5.155502,-244.111465,0.007196,0.002026,0.051470,22.932819,1.168254,0.514700,-244.111465,0.052363,0.000000
39.630001,5.201302,-244.022491,0.007200,0.002043,0.051895,23.136545,1.178632,0.518947,-244.022491,0.052797,0.000000
39.890003,5.213593,-244.022491,0.007239,0.002061,0.052337,23.191217,1.181417,0.523372,-244.022491,0.053230,0.000000
40.150002,5.270561,-244.111465,0.007256,0.002076,0.052727,23.444628,1.194326,0.527274,-244.111465,0.053664,0.000000
40.410004,5.372223,-244.111465,0.007274,0.002099,0.053308,23.896841,1.217363,0.533084,-244.111465,0.054098,0.000000
40.670002,5.295135,-244.111465,0.007274,0.002113,0.053664,23.553940,1.199895,0.536641,-244.111465,0.054531,0.000000
40.930000,5.267212,-244.111465,0.007325,0.002130,0.054098,23.429729,1.193567,0.540975,-244.111465,0.054965,0.000000
41.190002,5.331635,-244.066986,0.007325,0.002148,0.054566,23.716295,1.208166,0.545661,-244.066986,0.055398,0.000000
41.450001,5.409088,-244.155945,0.007368,0.002168,0.055060,24.060825,1.225717,0.550604,-244.155945,0.055832,0.000000
41.710003,5.349503,-244.066986,0.007373,0.002181,0.055398,23.795776,1.212215,0.553984,-244.066986,0.056265,0.000000
41.970001,5.390091,-244.155945,0.007399,0.002197,0.055806,23.976322,1.221412,0.558060,-244.155945,0.056699,0.000000
42.230003,5.445953,-244.155945,0.007424,0.002215,0.056265,24.224810,1.234071,0.562655,-244.155945,0.057133,0.000000
42.490002,5.547234,-244.111465,0.007446,0.002237,0.056821,24.675327,1.257021,0.568207,-244.111465,0.057566,0.000000
42.750004,5.510742,-244.200424,0.007485,0.002253,0.057237,24.513006,1.248752,0.572371,-244.200424,0.058000,0.000000
43.010002,5.425095,-244.155945,0.007472,0.002267,0.057584,24.132027,1.229344,0.575838,-244.155945,0.058434,0.000000
43.270000,5.429939,-244.200424,0.007502,0.002283,0.057983,24.153576,1.230442,0.579827,-244.200424,0.058867,0.000000
43.530003,5.575905,-244.155945,0.007511,0.002304,0.058512,24.802864,1.263518,0.585118,-244.155945,0.059301,0.000000
43.790001,5.580002,-244.155945,0.007549,0.002320,0.058919,24.821087,1.264446,0.589195,-244.155945,0.059735,0.000000
44.050003,5.532341,-244.244904,0.007562,0.002331,0.059214,24.609081,1.253646,0.592143,-244.244904,0.060168,0.000000
44.310001,5.677567,-244.111465,0.007575,0.002353,0.059778,25.255077,1.286555,0.597779,-244.111465,0.060602,0.000000
44.570004,5.720390,-244.244904,0.007580,0.002373,0.060263,25.445566,1.296259,0.602635,-244.244904,0.061036,0.000000
44.830002,5.686127,-244.200424,0.007610,0.002389,0.060680,25.293156,1.288495,0.606798,-244.200424,0.061469,0.000000
45.090004,5.654480,-244.200424,0.007640,0.002403,0.061036,25.152384,1.281323,0.610356,-244.200424,0.061903,0.000000
45.350002,5.811989,-244.200424,0.007679,0.002422,0.061530,25.853018,1.317016,0.615299,-244.200424,0.062336,0.000000
45.610001,5.825027,-244.200424,0.007666,0.002439,0.061946,25.911016,1.319970,0.619459,-244.200424,0.062770,0.000000
45.870003,5.670860,-244.244904,0.007687,0.002447,0.062154,25.225246,1.285035,0.621540,-244.244904,0.063204,0.000000
46.130001,5.947906,-244.289383,0.007687,0.002471,0.062770,26.457609,1.347815,0.627698,-244.289383,0.063637,0.000000
46.390003,5.988869,-244.200424,0.007761,0.002489,0.063221,26.639818,1.357097,0.632210,-244.200424,0.064062,0.000000
46.650002,6.088661,-244.333862,0.007774,0.002508,0.063715,27.083717,1.379710,0.637153,-244.333862,0.064496,0.000000
46.910004,6.049934,-244.289383,0.007812,0.002525,0.064131,26.911451,1.370935,0.641313,-244.289383,0.064929,0.000000
47.170002,6.024620,-244.333862,0.007774,0.002537,0.064452,26.798849,1.365198,0.644522,-244.333862,0.065363,0.000000
47.430004,6.148987,-244.244904,0.007808,0.002559,0.064999,27.352060,1.393380,0.649988,-244.244904,0.065797,0.000000
47.690002,6.179893,-244.289383,0.007860,0.002574,0.065380,27.489540,1.400384,0.653803,-244.289383,0.066230,0.000000
47.950001,6.283043,-244.333862,0.007851,0.002592,0.065848,27.948370,1.423758,0.658485,-244.333862,0.066664,0.000000
48.210003,6.387306,-244.289383,0.007869,0.002612,0.066334,28.412157,1.447384,0.663341,-244.289383,0.067097,0.000000
48.470001,6.376884,-244.378342,0.007925,0.002627,0.066724,28.365799,1.445023,0.667243,-244.378342,0.067531,0.000000
48.730003,6.445770,-244.333862,0.007925,0.002645,0.067175,28.672218,1.460632,0.671755,-244.333862,0.067965,0.000000
48.990002,6.428268,-244.333862,0.007959,0.002658,0.067513,28.594366,1.456666,0.675134,-244.333862,0.068398,0.000000
49.250004,6.663979,-244.333862,0.007942,0.002679,0.068043,29.642857,1.510079,0.680426,-244.333862,0.068832,0.000000
49.510002,6.635307,-244.333862,0.007989,0.002692,0.068381,29.515322,1.503582,0.683809,-244.333862,0.069265,0.000000
49.770000,6.396988,-244.333862,0.007976,0.002699,0.068546,28.455223,1.449578,0.685456,-244.333862,0.069699,0.000000
50.030003,6.981239,-244.333862,0.007998,0.002730,0.069352,31.054104,1.581972,0.693521,-244.333862,0.070133,0.000000
50.290001,7.026299,-244.333862,0.008063,0.002749,0.069829,31.254538,1.592182,0.698290,-244.333862,0.070566,0.000000
50.550003,6.913094,-244.422821,0.008050,0.002762,0.070159,30.750977,1.566529,0.701587,-244.422821,0.071000,0.000000
50.810001,6.998001,-244.378342,0.008063,0.002781,0.070627,31.128664,1.585770,0.706269,-244.378342,0.071433,0.000000
51.070004,6.914963,-244.422821,0.008080,0.002792,0.070922,30.759291,1.566953,0.709217,-244.422821,0.071867,0.000000
51.330002,7.162590,-244.378342,0.008114,0.002809,0.071347,31.860792,1.623066,0.713468,-244.378342,0.072301,0.000000
51.590004,7.207268,-244.378342,0.008144,0.002823,0.071711,32.059528,1.633190,0.717109,-244.378342,0.072734,0.000000
51.850002,7.379677,-244.422821,0.008114,0.002843,0.072205,32.826443,1.672259,0.722052,-244.422821,0.073168,0.000000
52.110001,7.695450,-244.378342,0.008183,0.002867,0.072821,34.231071,1.743814,0.728210,-244.378342,0.073601,0.000000
52.370003,7.635872,-244.422821,0.008157,0.002882,0.073211,33.966053,1.730313,0.732112,-244.422821,0.074035,0.000000
52.630001,7.645180,-244.378342,0.008183,0.002898,0.073610,34.007458,1.732423,0.736102,-244.378342,0.074469,0.000000
52.890003,7.638855,-244.467300,0.008226,0.002912,0.073966,33.979324,1.730989,0.739659,-244.467300,0.074902,0.000000
53.150002,7.875679,-244.467300,0.008201,0.002932,0.074469,35.032768,1.784654,0.744686,-244.467300,0.075336,0.000000
53.410004,7.934517,-244.467300,0.008239,0.002947,0.074850,35.294495,1.797987,0.748505,-244.467300,0.075769,0.000000
53.670002,7.978455,-244.467300,0.008248,0.002961,0.075206,35.489937,1.807944,0.752059,-244.467300,0.076203,0.000000
53.930004,8.269279,-244.422821,0.008257,0.002981,0.075709,36.783592,1.873846,0.757089,-244.422821,0.076637,0.000000
54.190002,8.501266,-244.467300,0.008269,0.002999,0.076186,37.815521,1.926415,0.761858,-244.467300,0.077070,0.000000
54.450001,8.406311,-244.467300,0.008321,0.003013,0.076542,37.393139,1.904897,0.765416,-244.467300,0.077504,0.000000
54.710003,8.541855,-244.422821,0.008330,0.003031,0.076992,37.996067,1.935612,0.769923,-244.422821,0.077938,0.000000
54.970001,8.561218,-244.511795,0.008343,0.003046,0.077356,38.082199,1.940000,0.773564,-244.511795,0.078371,0.000000
55.230003,8.951088,-244.511795,0.008343,0.003067,0.077903,39.816429,2.028346,0.779030,-244.511795,0.078805,0.000000
55.490002,9.068390,-244.511795,0.008390,0.003083,0.078311,40.338211,2.054927,0.783106,-244.511795,0.079230,0.000000
55.750004,9.060196,-244.556274,0.008412,0.003097,0.078657,40.301765,2.053070,0.786573,-244.556274,0.079663,0.000000
56.010002,9.451187,-244.511795,0.008420,0.003119,0.079230,42.040981,2.141670,0.792300,-244.511795,0.080097,0.000000
56.270004,9.501083,-244.600754,0.008433,0.003135,0.079629,42.262928,2.152976,0.796289,-244.600754,0.080531,0.000000
56.530003,9.634392,-244.511795,0.008476,0.003152,0.080071,42.855915,2.183184,0.800710,-244.511795,0.080964,0.000000
56.790001,9.620621,-244.556274,0.008494,0.003166,0.080427,42.794659,2.180064,0.804267,-244.556274,0.081398,0.000000
57.050003,9.965065,-244.511795,0.008511,0.003186,0.080912,44.326824,2.258116,0.809124,-244.511795,0.081831,0.000000
57.310001,10.064484,-244.556274,0.008515,0.003200,0.081268,44.769058,2.280644,0.812678,-244.556274,0.082265,0.000000
57.570004,10.386589,-244.556274,0.008507,0.003217,0.081719,46.201855,2.353635,0.817189,-244.556274,0.082699,0.000000
57.830002,10.423454,-244.600754,0.008558,0.003232,0.082100,46.365841,2.361989,0.821004,-244.600754,0.083132,0.000000
58.090004,11.206924,-244.556274,0.008532,0.003261,0.082820,49.850891,2.539525,0.828199,-244.556274,0.083566,0.000000
58.350002,10.848328,-244.600754,0.008584,0.003269,0.083028,48.255772,2.458266,0.830281,-244.600754,0.084000,0.000000
58.610004,11.124626,-244.556274,0.008576,0.003291,0.083583,49.484810,2.520876,0.835833,-244.556274,0.084433,0.000000
58.870003,11.412849,-244.600754,0.008619,0.003307,0.084008,50.766891,2.586189,0.840084,-244.600754,0.084867,0.000000
59.130001,11.602753,-244.645233,0.008645,0.003321,0.084355,51.611622,2.629221,0.843551,-244.645233,0.085301,0.000000
59.390003,11.803841,-244.556274,0.008649,0.003337,0.084754,52.506107,2.674788,0.847540,-244.556274,0.085734,0.000000
59.650002,12.133759,-244.645233,0.008636,0.003357,0.085257,53.973652,2.749549,0.852570,-244.645233,0.086168,0.000000
59.910004,12.511345,-244.600754,0.008658,0.003376,0.085743,55.653240,2.835111,0.857426,-244.600754,0.086601,0.000000
60.170002,12.711311,-244.689713,0.008696,0.003392,0.086150,56.542736,2.880424,0.861503,-244.689713,0.087035,0.000000
60.430004,12.903084,-244.600754,0.008688,0.003408,0.086567,57.395782,2.923881,0.865666,-244.600754,0.087469,0.000000
60.690002,13.144753,-244.645233,0.008722,0.003424,0.086966,58.470779,2.978643,0.869655,-244.645233,0.087902,0.000000
60.950005,13.546539,-244.600754,0.008735,0.003441,0.087408,60.258015,3.069690,0.874076,-244.600754,0.088336,0.000000
61.210003,13.798637,-244.600754,0.008770,0.003460,0.087876,61.379406,3.126816,0.878762,-244.600754,0.088769,0.000000
61.470001,14.068604,-244.645233,0.008744,0.003474,0.088249,62.580273,3.187991,0.882490,-244.645233,0.089203,0.000000
61.730003,14.737015,-244.600754,0.008791,0.003497,0.088821,65.553513,3.339455,0.888213,-244.600754,0.089637,0.000000
61.990002,14.811859,-244.645233,0.008800,0.003510,0.089160,65.886436,3.356415,0.891596,-244.645233,0.090070,0.000000
62.250004,15.188705,-244.734192,0.008808,0.003529,0.089645,67.562737,3.441810,0.896452,-244.734192,0.090504,0.000000
62.510002,15.563683,-244.645233,0.008808,0.003547,0.090096,69.230721,3.526781,0.900960,-244.645233,0.090937,0.000000
62.770004,15.999359,-244.689713,0.008877,0.003566,0.090582,71.168701,3.625507,0.905816,-244.689713,0.091371,0.000000
63.030003,16.125961,-244.734192,0.008847,0.003578,0.090876,71.731857,3.654195,0.908765,-244.734192,0.091805,0.000000
63.290005,16.494614,-244.689713,0.008869,0.003594,0.091275,73.371704,3.737733,0.912754,-244.689713,0.092238,0.000000
63.550003,16.990242,-244.734192,0.008912,0.003611,0.091718,75.576370,3.850044,0.917178,-244.734192,0.092672,0.000000
63.810001,17.833290,-244.689713,0.008921,0.003635,0.092334,79.326439,4.041081,0.923337,-244.689713,0.093105,0.000000
64.070000,18.150925,-244.778671,0.008933,0.003652,0.092759,80.739342,4.113058,0.927587,-244.778671,0.093539,0.000000
64.330002,18.231361,-244.734192,0.008951,0.003665,0.093097,81.097145,4.131285,0.930967,-244.734192,0.093964,0.000000
64.590004,18.527397,-244.734192,0.008925,0.003681,0.093487,82.413979,4.198368,0.934869,-244.734192,0.094398,0.000000
64.850006,19.365608,-244.778671,0.008990,0.003702,0.094033,86.142525,4.388310,0.940334,-244.778671,0.094831,0.000000
65.110001,19.847084,-244.689713,0.008977,0.003717,0.094424,88.284241,4.497414,0.944237,-244.689713,0.095265,0.000000
65.370003,19.832184,-244.823151,0.009007,0.003729,0.094719,88.217957,4.494037,0.947185,-244.823151,0.095698,0.000000
65.630005,20.885628,-244.734192,0.009020,0.003751,0.095273,92.903915,4.732751,0.952734,-244.734192,0.096132,0.000000
65.889999,21.381630,-244.823151,0.009015,0.003769,0.095742,95.110237,4.845146,0.957419,-244.823151,0.096566,0.000000
66.150002,21.811722,-244.823151,0.009046,0.003785,0.096149,97.023384,4.942607,0.961492,-244.823151,0.096999,0.000000
66.410004,22.293571,-244.734192,0.009063,0.003801,0.096557,99.166756,5.051795,0.965568,-244.734192,0.097433,0.000000
66.670006,22.892342,-244.778671,0.009076,0.003820,0.097025,101.830223,5.187479,0.970254,-244.778671,0.097866,0.000000
66.930000,23.529099,-244.778671,0.009071,0.003836,0.097441,104.662659,5.331770,0.974414,-244.778671,0.098300,0.000000
67.190002,23.618843,-244.823151,0.009076,0.003845,0.097676,105.061859,5.352106,0.976757,-244.823151,0.098734,0.000000
67.450005,24.552010,-244.823151,0.009102,0.003869,0.098274,109.212791,5.563565,0.982740,-244.823151,0.099167,0.000000
67.710007,25.326172,-244.778671,0.009102,0.003884,0.098656,112.656441,5.738992,0.986556,-244.778671,0.099601,0.000000
67.970001,26.126396,-244.867630,0.009110,0.003906,0.099202,116.216011,5.920326,0.992021,-244.867630,0.100034,0.000000
68.230003,26.779167,-244.867630,0.009166,0.003923,0.099644,119.119682,6.068246,0.996442,-244.867630,0.100468,0.000000
68.490005,27.204414,-244.823151,0.009158,0.003936,0.099983,121.011276,6.164608,0.999825,-244.823151,0.100902,0.000000
68.750000,28.079117,-244.867630,0.009158,0.003957,0.100520,124.902153,6.362819,1.005204,-244.867630,0.101335,0.000000
69.010002,28.647362,-244.867630,0.009184,0.003973,0.100902,127.429832,6.491585,1.009019,-244.867630,0.101769,0.000000
69.270004,29.229378,-244.867630,0.009184,0.003988,0.101283,130.018768,6.623472,1.012834,-244.867630,0.102203,0.000000
69.530006,30.375916,-244.823151,0.009205,0.004010,0.101847,135.118820,6.883281,1.018470,-244.823151,0.102636,0.000000
69.790001,30.946014,-244.912109,0.009227,0.004024,0.102220,137.654755,7.012467,1.022198,-244.912109,0.103070,0.000000
70.050003,31.609581,-244.912109,0.009240,0.004041,0.102654,140.606445,7.162833,1.026535,-244.912109,0.103504,0.000000
70.310005,32.127556,-244.867630,0.009248,0.004055,0.103009,142.910507,7.280208,1.030089,-244.867630,0.103937,0.000000
70.570000,33.313560,-244.912109,0.009240,0.004077,0.103547,148.186111,7.548961,1.035468,-244.912109,0.104371,0.000000
70.830002,33.692261,-244.912109,0.009253,0.004088,0.103833,149.870667,7.634776,1.038329,-244.912109,0.104804,0.000000
71.090004,33.968567,-244.956604,0.009265,0.004098,0.104085,151.099731,7.697388,1.040846,-244.956604,0.105238,0.000000
71.350006,35.967087,-244.912109,0.009253,0.004128,0.104839,159.989594,8.150258,1.048389,-244.912109,0.105672,0.000000
71.610001,37.200386,-244.912109,0.009291,0.004147,0.105342,165.475586,8.429729,1.053420,-244.912109,0.106105,0.000000
71.870003,37.688194,-244.956604,0.009300,0.004160,0.105672,167.645462,8.540267,1.056716,-244.956604,0.106539,0.000000
72.130005,38.396072,-244.956604,0.009313,0.004177,0.106105,170.794266,8.700674,1.061050,-244.956604,0.106972,0.000000
72.390007,38.758392,-245.001083,0.009322,0.004189,0.106391,172.405945,8.782778,1.063911,-245.001083,0.107406,0.000000
72.650002,40.068771,-244.956604,0.009300,0.004207,0.106868,178.234802,9.079713,1.068684,-244.956604,0.107840,0.000000
72.910004,40.234474,-244.912109,0.009343,0.004216,0.107085,178.971878,9.117263,1.070853,-244.912109,0.108273,0.000000
73.170006,41.682632,-245.001083,0.009334,0.004239,0.107666,185.413605,9.445420,1.076663,-245.001083,0.108707,0.000000
73.430000,43.146797,-245.001083,0.009356,0.004262,0.108247,191.926544,9.777205,1.082472,-245.001083,0.109132,0.000000
73.690002,44.415848,-245.001083,0.009343,0.004278,0.108672,197.571564,10.064775,1.086723,-245.001083,0.109566,0.000000
73.950005,45.311028,-245.001083,0.009360,0.004295,0.109106,201.553513,10.267626,1.091057,-245.001083,0.109999,0.000000
74.210007,46.059868,-244.912109,0.009378,0.004310,0.109478,204.884521,10.437316,1.094785,-244.912109,0.110433,0.000000
74.470001,47.152039,-245.001083,0.009399,0.004329,0.109947,209.742737,10.684805,1.099470,-245.001083,0.110866,0.000000
74.730003,48.128395,-244.956604,0.009369,0.004344,0.110346,214.085800,10.906051,1.103460,-244.956604,0.111300,0.000000
74.990005,48.929001,-245.001083,0.009429,0.004359,0.110719,217.647064,11.087471,1.107188,-245.001083,0.111734,0.000000
75.250000,50.178680,-245.045563,0.009378,0.004378,0.111196,223.205917,11.370651,1.111957,-245.045563,0.112167,0.000000
75.510002,51.608963,-245.090042,0.009408,0.004398,0.111699,229.568130,11.694758,1.116987,-245.090042,0.112601,0.000000
75.770004,52.115021,-245.045563,0.009390,0.004409,0.111976,231.819183,11.809432,1.119761,-245.045563,0.113034,0.000000
76.030006,53.593338,-245.001083,0.009425,0.004429,0.112488,238.395081,12.144423,1.124878,-245.001083,0.113468,0.000000
76.290001,54.317230,-245.045563,0.009429,0.004443,0.112844,241.615112,12.308461,1.128436,-245.045563,0.113901,0.000000
76.550003,55.977638,-245.045563,0.009429,0.004464,0.113381,249.000977,12.684713,1.133811,-245.045563,0.114335,0.000000
76.810005,57.081352,-245.045563,0.009472,0.004481,0.113806,253.910538,12.934819,1.138061,-245.045563,0.114769,0.000000
77.070007,57.911369,-245.045563,0.009481,0.004492,0.114101,257.602631,13.122904,1.141010,-245.045563,0.115202,0.000000
77.330002,59.592255,-245.045563,0.009438,0.004515,0.114691,265.079590,13.503798,1.146906,-245.045563,0.115636,0.000000
77.590004,61.088821,-245.090042,0.009472,0.004533,0.115133,271.736664,13.842925,1.151331,-245.090042,0.116069,0.000000
77.850006,61.946396,-245.090042,0.009455,0.004549,0.115532,275.551331,14.037253,1.155320,-245.090042,0.116503,0.000000
78.110001,63.117134,-245.045563,0.009472,0.004563,0.115905,280.759033,14.302547,1.159048,-245.045563,0.116937,0.000000
78.370003,64.170212,-245.090042,0.009494,0.004580,0.116338,285.443359,14.541178,1.163382,-245.090042,0.117370,0.000000
78.630005,65.453766,-245.179001,0.009494,0.004595,0.116711,291.152893,14.832035,1.167114,-245.179001,0.117804,0.000000
78.890007,66.879593,-245.179001,0.009490,0.004614,0.117206,297.495300,15.155132,1.172057,-245.179001,0.118237,0.000000
79.150002,67.095932,-245.090042,0.009520,0.004611,0.117128,298.457611,15.204156,1.171277,-245.090042,0.117362,0.000000
79.410004,66.569778,-245.134521,0.009516,0.004611,0.117128,296.117157,15.084927,1.171277,-245.134521,0.117362,0.000000
79.670006,66.204102,-245.179001,0.009498,0.004608,0.117032,294.490540,15.002064,1.170324,-245.179001,0.117128,0.000000
79.930000,65.807526,-245.134521,0.009511,0.004607,0.117006,292.726501,14.912198,1.170062,-245.134521,0.117128,0.000000
80.190002,65.461960,-245.179001,0.009516,0.004607,0.117006,291.189331,14.833892,1.170062,-245.179001,0.117128,0.000000
80.450005,65.149536,-245.134521,0.009511,0.004606,0.116998,289.799622,14.763096,1.169975,-245.134521,0.117128,0.000000
80.710007,64.875854,-245.179001,0.009524,0.004606,0.116998,288.582214,14.701079,1.169975,-245.179001,0.117128,0.000000
80.970001,64.627472,-245.267960,0.009520,0.004606,0.116998,287.477356,14.644794,1.169975,-245.267960,0.117128,0.000000
81.230003,64.398102,-245.090042,0.009541,0.004606,0.116989,286.457062,14.592818,1.169888,-245.090042,0.117128,0.000000
81.490005,64.191803,-245.223480,0.009537,0.004606,0.116989,285.539398,14.546071,1.169888,-245.223480,0.117128,0.000000
81.750008,64.003006,-245.223480,0.009550,0.004606,0.116989,284.699585,14.503288,1.169888,-245.223480,0.117128,0.000000
82.010002,63.818680,-245.179001,0.009572,0.004606,0.116989,283.879669,14.461520,1.169888,-245.179001,0.117128,0.000000
82.270004,63.663040,-245.267960,0.009507,0.004606,0.116989,283.187347,14.426250,1.169888,-245.267960,0.117128,0.000000
82.530006,63.506638,-245.179001,0.009559,0.004606,0.116989,282.491638,14.390810,1.169888,-245.179001,0.117128,0.000000
82.790001,63.349121,-245.223480,0.009550,0.004606,0.116989,281.790955,14.355116,1.169888,-245.223480,0.117128,0.000000
83.050003,63.228104,-245.267960,0.009541,0.004606,0.116989,281.252655,14.327693,1.169888,-245.267960,0.117128,0.000000
83.310005,63.107826,-245.267960,0.009559,0.004606,0.116989,280.717621,14.300438,1.169888,-245.267960,0.117128,0.000000
83.570007,62.987549,-245.223480,0.009550,0.004606,0.116989,280.182617,14.273183,1.169888,-245.223480,0.117128,0.000000
83.830002,62.873604,-245.223480,0.009546,0.004606,0.116989,279.675751,14.247363,1.169888,-245.223480,0.117128,0.000000
84.090004,62.766731,-245.312439,0.009550,0.004606,0.116989,279.200378,14.223145,1.169888,-245.312439,0.117128,0.000000
84.350006,62.679596,-245.179001,0.009559,0.004606,0.116980,278.812775,14.203400,1.169801,-245.179001,0.117128,0.000000
84.610001,62.557831,-245.267960,0.009567,0.004606,0.116980,278.271118,14.175807,1.169801,-245.267960,0.117128,0.000000
84.870003,62.469582,-245.312439,0.009580,0.004606,0.116980,277.878571,14.155809,1.169801,-245.312439,0.117128,0.000000
85.130005,62.391380,-245.267960,0.009537,0.004606,0.116980,277.530731,14.138088,1.169801,-245.267960,0.117128,0.000000
85.390007,62.306480,-245.312439,0.009533,0.004606,0.116980,277.153076,14.118851,1.169801,-245.312439,0.117128,0.000000
85.650002,62.220093,-245.312439,0.009537,0.004606,0.116980,276.768799,14.099275,1.169801,-245.312439,0.117128,0.000000
85.910004,62.131462,-245.267960,0.009541,0.004606,0.116980,276.374542,14.079190,1.169801,-245.267960,0.117128,0.000000
86.170006,62.086411,-245.312439,0.009541,0.004606,0.116980,276.174133,14.068982,1.169801,-245.312439,0.117128,0.000000
86.430000,62.000015,-245.312439,0.009550,0.004606,0.116980,275.789856,14.049404,1.169801,-245.312439,0.117128,0.000000
86.690002,61.919212,-245.356934,0.009554,0.004606,0.116980,275.430420,14.031094,1.169801,-245.356934,0.117128,0.000000
86.950005,61.866707,-245.312439,0.009524,0.004606,0.116980,275.196869,14.019196,1.169801,-245.312439,0.117128,0.000000
87.210007,61.792976,-245.312439,0.009554,0.004606,0.116980,274.868896,14.002489,1.169801,-245.312439,0.117128,0.000000
87.470001,61.733772,-245.356934,0.009537,0.004606,0.116980,274.605530,13.989073,1.169801,-245.356934,0.117128,0.000000
87.730003,61.678658,-245.312439,0.009554,0.004606,0.116980,274.360382,13.976583,1.169801,-245.312439,0.117128,0.000000
87.990005,61.615356,-245.356934,0.009580,0.004606,0.116980,274.078796,13.962240,1.169801,-245.356934,0.117128,0.000000
88.250008,61.555031,-245.356934,0.009559,0.004606,0.116980,273.810455,13.948569,1.169801,-245.356934,0.117128,0.000000
88.510002,61.488380,-245.356934,0.009589,0.004606,0.116980,273.513977,13.933467,1.169801,-245.356934,0.117128,0.000000
88.770004,61.446297,-245.401413,0.009589,0.004606,0.116980,273.326782,13.923930,1.169801,-245.401413,0.117128,0.000000
89.030006,61.405708,-245.356934,0.009580,0.004606,0.116980,273.146240,13.914733,1.169801,-245.356934,0.117128,0.000000
89.290001,61.329002,-245.401413,0.009567,0.004606,0.116980,272.805023,13.897351,1.169801,-245.401413,0.117128,0.000000
89.550003,61.291389,-245.401413,0.009524,0.004606,0.116980,272.637726,13.888827,1.169801,-245.401413,0.117128,0.000000
89.810005,61.259743,-245.445892,0.009550,0.004606,0.116980,272.496948,13.881656,1.169801,-245.445892,0.117128,0.000000
90.070007,61.172234,-245.401413,0.009580,0.004606,0.116980,272.107697,13.861826,1.169801,-245.401413,0.117128,0.000000
90.330002,61.151756,-245.445892,0.009567,0.004606,0.116980,272.016602,13.857186,1.169801,-245.445892,0.117128,0.000000
90.590004,61.107071,-245.445892,0.009576,0.004606,0.116980,271.817841,13.847060,1.169801,-245.445892,0.117128,0.000000
90.850006,61.061264,-245.445892,0.009572,0.004606,0.116980,271.614075,13.836679,1.169801,-245.445892,0.117128,0.000000
91.110001,61.013229,-245.401413,0.009585,0.004606,0.116980,271.400391,13.825796,1.169801,-245.401413,0.117128,0.000000
91.370003,60.980087,-245.401413,0.009554,0.004606,0.116980,271.252991,13.818285,1.169801,-245.401413,0.117128,0.000000
91.630005,60.941734,-245.445892,0.009563,0.004606,0.116980,271.082367,13.809594,1.169801,-245.445892,0.117128,0.000000
91.890007,60.892578,-245.445892,0.009541,0.004606,0.116980,270.863708,13.798455,1.169801,-245.445892,0.117128,0.000000
92.150002,60.850876,-245.445892,0.009572,0.004606,0.116980,270.678223,13.789005,1.169801,-245.445892,0.117128,0.000000
92.410004,60.830765,-245.445892,0.009537,0.004606,0.116980,270.588745,13.784449,1.169801,-245.445892,0.117128,0.000000
92.670006,60.765602,-245.445892,0.009546,0.004606,0.116980,270.298889,13.769682,1.169801,-245.445892,0.117128,0.000000
92.930008,60.739166,-245.445892,0.009589,0.004606,0.116980,270.181305,13.763692,1.169801,-245.445892,0.117128,0.000000
93.190002,60.711609,-245.445892,0.009550,0.004606,0.116980,270.058716,13.757447,1.169801,-245.445892,0.117128,0.000000
93.450005,60.657990,-245.445892,0.009550,0.004606,0.116980,269.820221,13.745296,1.169801,-245.445892,0.117128,0.000000
93.710007,60.621864,-245.445892,0.009563,0.004606,0.116980,269.659515,13.737110,1.169801,-245.445892,0.117128,0.000000
93.970001,60.608086,-245.579330,0.009572,0.004606,0.116980,269.598236,13.733989,1.169801,-245.579330,0.117128,0.000000
94.230003,60.561546,-245.490372,0.009546,0.004606,0.116980,269.391205,13.723443,1.169801,-245.490372,0.117128,0.000000
94.490005,60.522820,-245.490372,0.009585,0.004606,0.116980,269.218933,13.714666,1.169801,-245.490372,0.117128,0.000000
94.750008,60.502335,-245.490372,0.009585,0.004606,0.116980,269.127838,13.710025,1.169801,-245.490372,0.117128,0.000000
95.010002,60.467331,-245.534851,0.009563,0.004606,0.116980,268.972107,13.702093,1.169801,-245.534851,0.117128,0.000000
95.270004,60.430092,-245.579330,0.009576,0.004606,0.116980,268.806488,13.693655,1.169801,-245.579330,0.117128,0.000000
95.530006,60.405144,-245.534851,0.009559,0.004606,0.116980,268.695496,13.688001,1.169801,-245.534851,0.117128,0.000000
95.790001,60.386154,-245.579330,0.009559,0.004606,0.116980,268.611023,13.683698,1.169801,-245.579330,0.117128,0.000000
96.050003,60.343704,-245.579330,0.009572,0.004606,0.116980,268.422211,13.674079,1.169801,-245.579330,0.117128,0.000000
96.310005,60.331413,-245.490372,0.009602,0.004606,0.116980,268.367523,13.671294,1.169801,-245.490372,0.117128,0.000000
96.570007,60.285614,-245.623810,0.009572,0.004606,0.116980,268.163818,13.660915,1.169801,-245.623810,0.117128,0.000000
96.830002,60.261040,-245.623810,0.009546,0.004606,0.116980,268.054504,13.655347,1.169801,-245.623810,0.117128,0.000000
97.090004,60.240929,-245.623810,0.009585,0.004606,0.116980,267.965027,13.650789,1.169801,-245.623810,0.117128,0.000000
97.350006,60.217468,-245.534851,0.009550,0.004606,0.116980,267.860687,13.645473,1.169801,-245.534851,0.117128,0.000000
97.610008,60.180603,-245.623810,0.009580,0.004606,0.116980,267.696686,13.637119,1.169801,-245.623810,0.117128,0.000000
97.870003,60.155655,-245.579330,0.009580,0.004606,0.116980,267.585724,13.631466,1.169801,-245.579330,0.117128,0.000000
98.130005,60.145599,-245.579330,0.009546,0.004606,0.116980,267.540985,13.629188,1.169801,-245.579330,0.117128,0.000000
98.390007,60.100174,-245.668289,0.009589,0.004606,0.116980,267.338928,13.618895,1.169801,-245.668289,0.117128,0.000000
98.650002,60.086769,-245.668289,0.009563,0.004606,0.116980,267.279297,13.615856,1.169801,-245.668289,0.117128,0.000000
98.910004,60.074478,-245.579330,0.009593,0.004606,0.116980,267.224640,13.613071,1.169801,-245.579330,0.117128,0.000000
99.170006,60.014900,-245.668289,0.009550,0.004606,0.116980,266.959595,13.599571,1.169801,-245.668289,0.117128,0.000000
99.430008,60.013786,-245.623810,0.009554,0.004606,0.116980,266.954651,13.599319,1.169801,-245.623810,0.117128,0.000000
99.690002,59.989952,-245.668289,0.009576,0.004606,0.116980,266.848633,13.593918,1.169801,-245.668289,0.117128,0.000000
99.950005,59.963516,-245.623810,0.009567,0.004606,0.116980,266.731049,13.587927,1.169801,-245.623810,0.117128,0.000000
100.210007,59.941170,-245.668289,0.009546,0.004606,0.116980,266.631653,13.582863,1.169801,-245.668289,0.117128,0.000000
100.470001,59.928139,-245.757248,0.009576,0.004606,0.116980,266.573669,13.579910,1.169801,-245.757248,0.117128,0.000000
100.730003,59.894623,-245.668289,0.009572,0.004606,0.116980,266.424591,13.572315,1.169801,-245.668289,0.117128,0.000000
100.990005,59.873024,-245.757248,0.009567,0.004606,0.116980,266.328522,13.567422,1.169801,-245.757248,0.117128,0.000000
101.250008,59.858131,-245.712769,0.009546,0.004606,0.116980,266.262268,13.564046,1.169801,-245.712769,0.117128,0.000000
101.510002,59.835045,-245.668289,0.009585,0.004606,0.116980,266.159576,13.558815,1.169801,-245.668289,0.117128,0.000000
101.770004,59.808235,-245.712769,0.009563,0.004606,0.116980,266.040314,13.552740,1.169801,-245.712769,0.117128,0.000000
102.030006,59.791847,-245.712769,0.009572,0.004606,0.116980,265.967407,13.549026,1.169801,-245.712769,0.117128,0.000000
102.290009,59.770248,-245.757248,0.009572,0.004606,0.116980,265.871338,13.544131,1.169801,-245.757248,0.117128,0.000000
102.550003,59.735992,-245.757248,0.009585,0.004606,0.116980,265.718964,13.536369,1.169801,-245.757248,0.117128,0.000000
102.810005,59.742325,-245.757248,0.009580,0.004606,0.116980,265.747131,13.537804,1.169801,-245.757248,0.117128,0.000000
103.070007,59.704338,-245.757248,0.009576,0.004606,0.116980,265.578156,13.529197,1.169801,-245.757248,0.117128,0.000000
103.330002,59.693542,-245.757248,0.009576,0.004606,0.116980,265.530151,13.526751,1.169801,-245.757248,0.117128,0.000000
103.590004,59.673065,-245.757248,0.009589,0.004606,0.116980,265.439056,13.522110,1.169801,-245.757248,0.117128,0.000000
103.850006,59.657425,-245.757248,0.009528,0.004606,0.116980,265.369476,13.518566,1.169801,-245.757248,0.117128,0.000000
104.110008,59.623909,-245.801743,0.009572,0.004606,0.116980,265.220398,13.510971,1.169801,-245.801743,0.117128,0.000000
104.370003,59.612740,-245.757248,0.009528,0.004606,0.116980,265.170715,13.508440,1.169801,-245.757248,0.117128,0.000000
104.630005,59.609756,-245.712769,0.009563,0.004606,0.116980,265.157440,13.507764,1.169801,-245.712769,0.117128,0.000000
104.890007,59.561722,-245.801743,0.009567,0.004606,0.116980,264.943756,13.496880,1.169801,-245.801743,0.117128,0.000000
105.150002,59.570656,-245.801743,0.009520,0.004606,0.116980,264.983521,13.498904,1.169801,-245.801743,0.117128,0.000000
105.410004,59.563583,-245.801743,0.009593,0.004606,0.116980,264.952057,13.497301,1.169801,-245.801743,0.117128,0.000000
105.670006,59.519646,-245.846222,0.009589,0.004606,0.116980,264.756592,13.487345,1.169801,-245.846222,0.117128,0.000000
105.930008,59.509590,-245.846222,0.009567,0.004606,0.116980,264.711884,13.485065,1.169801,-245.846222,0.117128,0.000000
106.190002,59.502518,-245.890701,0.009550,0.004606,0.116980,264.680420,13.483463,1.169801,-245.890701,0.117128,0.000000
106.450005,59.474586,-245.801743,0.009550,0.004606,0.116980,264.556183,13.477134,1.169801,-245.801743,0.117128,0.000000
106.710007,59.461182,-245.890701,0.009559,0.004606,0.116980,264.496552,13.474096,1.169801,-245.890701,0.117128,0.000000
106.970009,59.450752,-245.890701,0.009572,0.004606,0.116980,264.450165,13.471733,1.169801,-245.890701,0.117128,0.000000
107.230003,59.423943,-245.846222,0.009546,0.004606,0.116980,264.330902,13.465658,1.169801,-245.846222,0.117128,0.000000
107.490005,59.409424,-245.890701,0.009589,0.004606,0.116980,264.266327,13.462368,1.169801,-245.890701,0.117128,0.000000
107.750008,59.394157,-245.846222,0.009572,0.004606,0.116980,264.198395,13.458908,1.169801,-245.846222,0.117128,0.000000
108.010002,59.377769,-245.846222,0.009589,0.004606,0.116980,264.125519,13.455195,1.169801,-245.846222,0.117128,0.000000
108.270004,59.346863,-245.935181,0.009546,0.004606,0.116980,263.988037,13.448191,1.169801,-245.935181,0.117128,0.000000
108.530006,59.343140,-245.890701,0.009567,0.004606,0.116980,263.971466,13.447348,1.169801,-245.890701,0.117128,0.000000
108.790009,59.342026,-245.935181,0.009585,0.004606,0.116980,263.966522,13.447095,1.169801,-245.935181,0.117128,0.000000
109.050003,59.311119,-245.890701,0.009546,0.004606,0.116980,263.829041,13.440092,1.169801,-245.890701,0.117128,0.000000
109.310005,59.285423,-245.846222,0.009597,0.004606,0.116980,263.714722,13.434269,1.169801,-245.846222,0.117128,0.000000
109.570007,59.291382,-245.890701,0.009567,0.004606,0.116980,263.741241,13.435619,1.169801,-245.890701,0.117128,0.000000
109.600006,59.269409,-245.935181,0.009576,0.004606,0.116980,263.643494,13.430639,1.169801,-245.935181,0.117128,0.000000