File: Data/compression sample NH 10,12,15/AutoNoheating-15-2-4-240201_02012024_182359.csv
Time (sec),S:Load (lbs),S:HL1 (DIM),S:LVDT (in),S:Position (in),Ch:Position (mm),Ch:Load (N),Ch:Stress (MPa),Ch:Strain (mm/mm),Ch:HL1 (DIM),Set Point (),Cycles ()
0.110000,-0.017128,-169.027618,0.000000,-0.000000,-0.000000,-0.076189,-0.003881,-0.000000,-169.027618,0.000191,0.000000
0.350000,-0.031654,-169.027618,0.000004,0.000001,0.000035,-0.140806,-0.007173,0.000348,-169.027618,0.000468,0.000000
0.590000,-0.009682,-169.072098,-0.000017,0.000133,0.003391,-0.043066,-0.002194,0.033909,-169.072098,0.004457,0.000000
0.830000,-0.020485,-169.027618,0.000091,0.000292,0.007415,-0.091121,-0.004642,0.074146,-169.027618,0.008464,0.000000
1.070000,-0.022713,-169.027618,0.000263,0.000450,0.011421,-0.101031,-0.005147,0.114213,-169.027618,0.012453,0.000000
1.310000,-0.003723,-169.027618,0.000423,0.000607,0.015419,-0.016561,-0.000844,0.154193,-169.027618,0.016460,0.000000
1.550000,0.014893,-169.027618,0.000591,0.000761,0.019339,0.066245,0.003375,0.193393,-169.027618,0.020449,0.000000
1.790000,0.013031,-169.027618,0.000763,0.000921,0.023389,0.057965,0.002953,0.233891,-169.027618,0.024456,0.000000
2.030000,-0.025696,-169.072098,0.000927,0.001079,0.027404,-0.114301,-0.005823,0.274042,-169.072098,0.028445,0.000000
2.270000,-0.000748,-169.072098,0.001065,0.001233,0.031315,-0.003326,-0.000169,0.313155,-169.072098,0.032452,0.000000
2.510000,0.000374,-169.116577,0.001255,0.001388,0.035244,0.001663,0.000085,0.352442,-169.116577,0.036458,0.000000
2.750000,-0.008568,-169.027618,0.001414,0.001550,0.039363,-0.038112,-0.001941,0.393633,-169.027618,0.040447,0.000000
2.990000,-0.026436,-169.027618,0.001595,0.001712,0.043491,-0.117593,-0.005990,0.434915,-169.027618,0.044454,0.000000
3.230000,-0.002609,-169.161057,0.001750,0.001864,0.047342,-0.011607,-0.000591,0.473418,-169.161057,0.048443,0.000000
3.470000,0.008560,-169.116577,0.001923,0.002024,0.051418,0.038078,0.001940,0.514178,-169.116577,0.052450,0.000000
3.710000,0.027557,-169.161057,0.002061,0.002180,0.055372,0.122581,0.006245,0.553723,-169.161057,0.056439,0.000000
3.950000,0.003349,-169.116577,0.002238,0.002338,0.059379,0.014898,0.000759,0.593789,-169.116577,0.060446,0.000000
4.190000,-0.019363,-169.116577,0.002402,0.002492,0.063299,-0.086133,-0.004388,0.632990,-169.116577,0.064435,0.000000
4.430000,0.013405,-169.116577,0.002539,0.002643,0.067123,0.059628,0.003038,0.671232,-169.116577,0.068441,0.000000
4.670000,-0.008194,-169.116577,0.002708,0.002802,0.071173,-0.036449,-0.001857,0.711731,-169.116577,0.072431,0.000000
4.910000,-0.009682,-169.205536,0.002902,0.002972,0.075492,-0.043066,-0.002194,0.754920,-169.205536,0.076437,0.000000
5.150000,-0.059952,-169.161057,0.003065,0.003126,0.079403,-0.266679,-0.013585,0.794033,-169.161057,0.080426,0.000000
5.390000,0.001862,-169.161057,0.003225,0.003282,0.083358,0.008281,0.000422,0.833578,-169.161057,0.084433,0.000000
5.630000,0.024948,-169.161057,0.003397,0.003434,0.087226,0.110975,0.005653,0.872256,-169.161057,0.088422,0.000000
5.870000,0.015640,-169.116577,0.003557,0.003599,0.091423,0.069571,0.003544,0.914230,-169.116577,0.092429,0.000000
6.110000,-0.000000,-169.250015,0.003708,0.003755,0.095386,-0.000000,-0.000000,0.953862,-169.250015,0.096418,0.000000
6.350000,-0.008934,-169.161057,0.003885,0.003911,0.099332,-0.039741,-0.002024,0.993319,-169.161057,0.100425,0.000000
6.590000,0.001114,-169.205536,0.004023,0.004059,0.103104,0.004955,0.000252,1.031043,-169.205536,0.104414,0.000000
6.830000,-0.017876,-169.205536,0.004204,0.004227,0.107371,-0.079515,-0.004051,1.073710,-169.205536,0.108421,0.000000
7.070000,-0.050644,-169.250015,0.004381,0.004386,0.111413,-0.225275,-0.011476,1.114125,-169.250015,0.112427,0.000000
7.310000,-0.020485,-169.205536,0.004506,0.004539,0.115289,-0.091121,-0.004642,1.152890,-169.205536,0.116417,0.000000
7.550000,0.022339,-169.161057,0.004695,0.004691,0.119157,0.099368,0.005062,1.191568,-169.161057,0.120423,0.000000
7.790000,0.020851,-169.250015,0.004868,0.004857,0.123380,0.092750,0.004725,1.233800,-169.250015,0.124412,0.000000
8.030001,0.010056,-169.205536,0.005053,0.005017,0.127430,0.044729,0.002279,1.274302,-169.205536,0.128419,0.000000
8.270000,0.003723,-169.205536,0.005208,0.005173,0.131385,0.016561,0.000844,1.313847,-169.205536,0.132408,0.000000
8.510000,0.007072,-169.294495,0.005342,0.005324,0.135235,0.031460,0.001603,1.352351,-169.294495,0.136414,0.000000
8.750000,0.008934,-169.250015,0.005501,0.005480,0.139181,0.039741,0.002024,1.391812,-169.250015,0.140404,0.000000
8.990001,0.003723,-169.338974,0.005678,0.005647,0.143439,0.016561,0.000844,1.434392,-169.338974,0.144410,0.000000
9.230000,-0.042450,-169.250015,0.005833,0.005801,0.147350,-0.188827,-0.009619,1.473501,-169.250015,0.148400,0.000000
9.470000,0.016380,-169.250015,0.006023,0.005959,0.151348,0.072863,0.003712,1.513481,-169.250015,0.152406,0.000000
9.710000,0.043198,-169.294495,0.006157,0.006109,0.155173,0.192153,0.009789,1.551727,-169.294495,0.156396,0.000000
9.950001,0.035004,-169.250015,0.006372,0.006280,0.159500,0.155704,0.007932,1.595000,-169.250015,0.160402,0.000000
10.190001,0.002975,-169.294495,0.006519,0.006430,0.163316,0.013236,0.000674,1.633160,-169.294495,0.164391,0.000000
10.430000,0.029419,-169.338974,0.006704,0.006590,0.167392,0.130862,0.006666,1.673919,-169.338974,0.168398,0.000000
10.670000,0.026062,-169.294495,0.006842,0.006737,0.171129,0.115930,0.005906,1.711295,-169.294495,0.172387,0.000000
10.910001,0.017502,-169.338974,0.006993,0.006900,0.175249,0.077852,0.003966,1.752490,-169.338974,0.176394,0.000000
11.150001,-0.018616,-169.250015,0.007183,0.007060,0.179334,-0.082807,-0.004218,1.793336,-169.250015,0.180383,0.000000
11.390000,-0.008194,-169.383469,0.007330,0.007219,0.183375,-0.036449,-0.001857,1.833748,-169.383469,0.184389,0.000000
11.630000,0.047661,-169.338974,0.007498,0.007370,0.187199,0.212006,0.010800,1.871994,-169.338974,0.188396,0.000000
11.870001,0.036491,-169.294495,0.007640,0.007534,0.191371,0.162322,0.008269,1.913707,-169.294495,0.192385,0.000000
12.110001,0.018616,-169.338974,0.007808,0.007691,0.195343,0.082807,0.004218,1.953426,-169.338974,0.196392,0.000000
12.350000,0.011917,-169.338974,0.007994,0.007844,0.199245,0.053010,0.002700,1.992452,-169.338974,0.200381,0.000000
12.590000,0.042450,-169.472427,0.008114,0.008002,0.203252,0.188827,0.009619,2.032515,-169.472427,0.204388,0.000000
12.830001,0.020851,-169.294495,0.008295,0.008162,0.207319,0.092750,0.004725,2.073191,-169.294495,0.208377,0.000000
13.070001,0.028297,-169.383469,0.008481,0.008317,0.211256,0.125873,0.006412,2.112562,-169.383469,0.212384,0.000000
13.310000,0.022713,-169.383469,0.008636,0.008476,0.215289,0.101031,0.005147,2.152886,-169.383469,0.216373,0.000000
13.550000,0.315773,-169.338974,0.008783,0.008632,0.219243,1.404629,0.071555,2.192435,-169.338974,0.220379,0.000000
13.790001,0.720543,-169.383469,0.008886,0.000029,0.000746,3.205135,0.163277,0.007460,-169.383469,0.000902,0.000000
14.030001,0.691864,-169.383469,0.008882,0.000029,0.000737,3.077565,0.156779,0.007373,-169.383469,0.000902,0.000000
14.270000,0.661705,-169.383469,0.008869,0.000029,0.000737,2.943411,0.149944,0.007373,-169.383469,0.001067,0.000000
14.510000,0.665802,-169.427948,0.008882,0.000029,0.000737,2.961635,0.150873,0.007373,-169.427948,0.001475,0.000000
14.750001,0.657234,-169.338974,0.008864,0.000029,0.000746,2.923524,0.148931,0.007460,-169.338974,0.001874,0.000000
14.990001,0.854225,-169.472427,0.008895,0.000056,0.001422,3.799783,0.193570,0.014224,-169.472427,0.002272,0.000000
15.230000,1.024025,-169.427948,0.008860,0.000070,0.001778,4.555090,0.232047,0.017781,-169.427948,0.002671,0.000000
15.470000,1.200531,-169.427948,0.008912,0.000087,0.002203,5.340229,0.272044,0.022028,-169.427948,0.003070,0.000000
15.710001,1.331604,-169.427948,0.008921,0.000099,0.002515,5.923270,0.301746,0.025151,-169.427948,0.003469,0.000000
15.950001,1.464912,-169.427948,0.008921,0.000111,0.002810,6.516256,0.331954,0.028099,-169.427948,0.003868,0.000000
16.190001,1.777336,-169.516907,0.008933,0.000137,0.003486,7.905986,0.402750,0.034863,-169.516907,0.004267,0.000000
16.430000,1.895744,-169.472427,0.008955,0.000150,0.003807,8.432692,0.429582,0.038072,-169.472427,0.004674,0.000000
16.670000,2.029060,-169.472427,0.008977,0.000165,0.004180,9.025711,0.459792,0.041800,-169.472427,0.005073,0.000000
16.910002,2.263649,-169.516907,0.008985,0.000181,0.004605,10.069214,0.512950,0.046051,-169.516907,0.005472,0.000000
17.150002,2.426750,-169.516907,0.009015,0.000197,0.005013,10.794724,0.549909,0.050127,-169.516907,0.005871,0.000000
17.390001,2.628578,-169.516907,0.008998,0.000213,0.005403,11.692500,0.595644,0.054029,-169.516907,0.006270,0.000000
17.630001,2.675865,-169.561386,0.009028,0.000220,0.005576,11.902843,0.606360,0.055763,-169.561386,0.006669,0.000000
17.870001,2.958870,-169.516907,0.009028,0.000237,0.006027,13.161711,0.670490,0.060274,-169.516907,0.007068,0.000000
18.110001,3.286186,-169.516907,0.009076,0.000263,0.006686,14.617686,0.744660,0.066864,-169.516907,0.007476,0.000000
18.350000,3.350609,-169.516907,0.009080,0.000273,0.006938,14.904252,0.759259,0.069381,-169.516907,0.007874,0.000000
18.590000,3.591904,-169.605865,0.009084,0.000293,0.007441,15.977586,0.813937,0.074411,-169.605865,0.008273,0.000000
18.830002,3.779205,-169.561386,0.009119,0.000308,0.007823,16.810745,0.856380,0.078226,-169.561386,0.008672,0.000000
19.070002,3.921082,-169.472427,0.009119,0.000321,0.008152,17.441841,0.888530,0.081519,-169.472427,0.009071,0.000000
19.310001,4.153069,-169.561386,0.009145,0.000339,0.008612,18.473772,0.941099,0.086118,-169.561386,0.009470,0.000000
19.550001,4.323242,-169.516907,0.009149,0.000354,0.008985,19.230742,0.979661,0.089846,-169.516907,0.009869,0.000000
19.790001,4.374634,-169.605865,0.009158,0.000365,0.009271,19.459343,0.991306,0.092707,-169.605865,0.010268,0.000000
20.030001,4.766739,-169.516907,0.009179,0.000391,0.009930,21.203514,1.080158,0.099301,-169.516907,0.010676,0.000000
20.270000,4.899673,-169.605865,0.009209,0.000408,0.010355,21.794836,1.110282,0.103547,-169.605865,0.011075,0.000000
20.510000,4.919785,-169.561386,0.009209,0.000420,0.010667,21.884295,1.114839,0.106670,-169.561386,0.011474,0.000000
20.750002,4.995750,-169.650345,0.009231,0.000434,0.011014,22.222208,1.132053,0.110140,-169.650345,0.011872,0.000000
20.990002,5.162941,-169.605865,0.009235,0.000450,0.011430,22.965908,1.169939,0.114304,-169.605865,0.012271,0.000000
21.230001,5.346153,-169.561386,0.009257,0.000465,0.011812,23.780878,1.211456,0.118119,-169.561386,0.012670,0.000000
21.470001,5.461960,-169.605865,0.009253,0.000480,0.012193,24.296011,1.237698,0.121934,-169.605865,0.013069,0.000000
21.710001,5.512970,-169.650345,0.009300,0.000495,0.012575,24.522915,1.249257,0.125749,-169.650345,0.013468,0.000000
21.950001,5.743469,-169.605865,0.009313,0.000513,0.013034,25.548227,1.301489,0.130344,-169.605865,0.013876,0.000000
22.190001,5.854813,-169.605865,0.009309,0.000530,0.013468,26.043507,1.326720,0.134682,-169.605865,0.014275,0.000000
22.430000,5.904709,-169.605865,0.009347,0.000546,0.013876,26.265457,1.338026,0.138758,-169.605865,0.014674,0.000000
22.670002,6.011955,-169.605865,0.009343,0.000560,0.014214,26.742512,1.362329,0.142142,-169.605865,0.015073,0.000000
22.910002,6.027222,-169.650345,0.009382,0.000572,0.014535,26.810421,1.365788,0.145348,-169.650345,0.015472,0.000000
23.150002,6.231651,-169.650345,0.009369,0.000589,0.014969,27.719769,1.412112,0.149685,-169.650345,0.015870,0.000000
23.390001,6.336288,-169.650345,0.009386,0.000607,0.015411,28.185219,1.435823,0.154106,-169.650345,0.016269,0.000000
23.630001,6.363098,-169.650345,0.009408,0.000618,0.015697,28.304474,1.441899,0.156971,-169.650345,0.016668,0.000000
23.870001,6.624878,-169.650345,0.009416,0.000639,0.016243,29.468929,1.501219,0.162433,-169.650345,0.017076,0.000000
24.110001,6.663231,-169.739304,0.009451,0.000655,0.016642,29.639532,1.509910,0.166422,-169.739304,0.017475,0.000000
24.350000,6.693764,-169.650345,0.009451,0.000668,0.016972,29.775349,1.516829,0.169718,-169.650345,0.017874,0.000000
24.590002,6.812180,-169.739304,0.009490,0.000688,0.017466,30.302088,1.543662,0.174662,-169.739304,0.018273,0.000000
24.830002,6.840111,-169.650345,0.009498,0.000702,0.017839,30.426332,1.549991,0.178390,-169.650345,0.018672,0.000000
25.070002,6.996506,-169.739304,0.009472,0.000719,0.018273,31.122011,1.585431,0.182727,-169.739304,0.019071,0.000000
25.310001,7.026299,-169.694824,0.009524,0.000732,0.018602,31.254538,1.592182,0.186020,-169.694824,0.019469,0.000000
25.550001,6.888145,-169.694824,0.009516,0.000740,0.018801,30.640001,1.560876,0.188015,-169.694824,0.019868,0.000000
25.790001,7.290680,-169.739304,0.009559,0.000765,0.019443,32.430565,1.652092,0.194434,-169.739304,0.020276,0.000000
26.030001,7.342064,-169.739304,0.009563,0.000781,0.019842,32.659130,1.663736,0.198423,-169.739304,0.020675,0.000000
26.270000,7.339836,-169.783783,0.009585,0.000796,0.020224,32.649223,1.663231,0.202238,-169.783783,0.021074,0.000000
26.510002,7.398293,-169.783783,0.009572,0.000811,0.020597,32.909248,1.676477,0.205966,-169.783783,0.021473,0.000000
26.750002,7.386009,-169.739304,0.009593,0.000824,0.020926,32.854610,1.673694,0.209263,-169.739304,0.021872,0.000000
26.990002,7.659698,-169.783783,0.009628,0.000844,0.021438,34.072041,1.735713,0.214380,-169.783783,0.022271,0.000000
27.230001,7.603470,-169.783783,0.009623,0.000855,0.021715,33.821922,1.722971,0.217155,-169.783783,0.022670,0.000000
27.470001,7.533836,-169.828278,0.009649,0.000864,0.021941,33.512177,1.707192,0.219410,-169.828278,0.023068,0.000000
27.710001,7.960205,-169.783783,0.009675,0.000891,0.022626,35.408760,1.803808,0.226261,-169.783783,0.023476,0.000000
27.950001,8.064468,-169.739304,0.009697,0.000910,0.023120,35.872547,1.827435,0.231204,-169.739304,0.023875,0.000000
28.190001,7.965416,-169.828278,0.009718,0.000922,0.023424,35.431938,1.804989,0.234240,-169.828278,0.024274,0.000000
28.430002,7.994835,-169.739304,0.009727,0.000937,0.023797,35.562801,1.811655,0.237968,-169.739304,0.024673,0.000000
28.670002,7.996696,-169.783783,0.009710,0.000950,0.024126,35.571083,1.812077,0.241264,-169.783783,0.025072,0.000000
28.910002,8.218636,-169.872757,0.009744,0.000968,0.024586,36.558315,1.862369,0.245859,-169.872757,0.025470,0.000000
29.150002,7.983292,-169.783783,0.009744,0.000972,0.024681,35.511456,1.809040,0.246813,-169.783783,0.025869,0.000000
29.390001,8.148254,-169.828278,0.009779,0.000992,0.025184,36.245247,1.846421,0.251843,-169.828278,0.026268,0.000000
29.630001,8.372047,-169.828278,0.009766,0.001008,0.025601,37.240726,1.897133,0.256007,-169.828278,0.026676,0.000000
29.870001,8.613716,-169.828278,0.009791,0.001030,0.026173,38.315723,1.951896,0.261729,-169.828278,0.027075,0.000000
30.110001,8.610741,-169.872757,0.009817,0.001045,0.026554,38.302486,1.951222,0.265544,-169.872757,0.027474,0.000000
30.350002,8.613716,-169.828278,0.009835,0.001060,0.026928,38.315723,1.951896,0.269276,-169.828278,0.027873,0.000000
30.590002,8.556000,-169.917236,0.009848,0.001072,0.027240,38.058987,1.938817,0.272399,-169.917236,0.028272,0.000000
30.830002,8.796928,-169.917236,0.009873,0.001093,0.027760,39.130692,1.993412,0.277599,-169.917236,0.028671,0.000000
31.070002,8.822617,-169.917236,0.009869,0.001106,0.028081,39.244957,1.999233,0.280809,-169.917236,0.029070,0.000000
31.310001,8.786125,-169.961716,0.009882,0.001118,0.028393,39.082638,1.990964,0.283931,-169.961716,0.029477,0.000000
31.550001,8.930237,-169.828278,0.009916,0.001136,0.028844,39.723679,2.023621,0.288439,-169.828278,0.029876,0.000000
31.790001,9.253830,-169.961716,0.009921,0.001161,0.029477,41.163090,2.096948,0.294771,-169.961716,0.030275,0.000000
32.030003,9.025932,-169.917236,0.009934,0.001170,0.029711,40.149353,2.045305,0.297114,-169.917236,0.030674,0.000000
32.270000,9.190521,-170.006195,0.009960,0.001190,0.030214,40.881481,2.082602,0.302144,-170.006195,0.031073,0.000000
32.510002,9.080299,-169.961716,0.009960,0.001199,0.030448,40.391190,2.057625,0.304483,-169.961716,0.031472,0.000000
32.750000,9.440758,-169.917236,0.009994,0.001222,0.031047,41.994587,2.139306,0.310467,-169.917236,0.031871,0.000000
32.990002,9.443367,-170.006195,0.009994,0.001236,0.031394,42.006195,2.139898,0.313938,-170.006195,0.032270,0.000000
33.230003,9.355110,-169.917236,0.010016,0.001247,0.031680,41.613609,2.119898,0.316799,-169.917236,0.032677,0.000000
33.470001,9.612419,-169.961716,0.010024,0.001266,0.032166,42.758175,2.178205,0.321656,-169.961716,0.033076,0.000000
33.710003,9.774406,-169.961716,0.010050,0.001287,0.032695,43.478733,2.214912,0.326947,-169.961716,0.033475,0.000000
33.950001,9.764351,-169.917236,0.010067,0.001301,0.033041,43.434002,2.212634,0.330414,-169.917236,0.033874,0.000000
34.190002,9.799728,-170.006195,0.010042,0.001317,0.033458,43.591370,2.220650,0.334577,-170.006195,0.034273,0.000000
34.430000,9.838081,-170.006195,0.010111,0.001332,0.033831,43.761971,2.229341,0.338305,-170.006195,0.034672,0.000000
34.670002,9.926331,-169.961716,0.010098,0.001347,0.034221,44.154522,2.249339,0.342207,-169.961716,0.035071,0.000000
34.910000,9.952774,-170.050674,0.010106,0.001361,0.034577,44.272152,2.255331,0.345765,-170.050674,0.035470,0.000000
35.150002,9.990005,-170.006195,0.010128,0.001375,0.034932,44.437763,2.263767,0.349319,-170.006195,0.035877,0.000000
35.390003,10.125549,-170.006195,0.010128,0.001391,0.035340,45.040691,2.294482,0.353396,-170.006195,0.036276,0.000000
35.630001,10.502396,-169.917236,0.010154,0.001414,0.035921,46.716988,2.379877,0.359205,-169.917236,0.036675,0.000000
35.870003,10.430893,-170.006195,0.010179,0.001427,0.036250,46.398930,2.363674,0.362502,-170.006195,0.037074,0.000000
36.110001,10.434990,-170.006195,0.010175,0.001442,0.036632,46.417152,2.364602,0.366317,-170.006195,0.037473,0.000000
36.350002,10.391052,-170.050674,0.010205,0.001456,0.036970,46.221710,2.354646,0.369701,-170.050674,0.037872,0.000000
36.590000,10.663254,-170.050674,0.010223,0.001476,0.037490,47.432522,2.416328,0.374901,-170.050674,0.038271,0.000000
36.830002,10.665863,-170.006195,0.010244,0.001488,0.037794,47.444130,2.416919,0.377937,-170.006195,0.038670,0.000000
37.070004,10.585060,-170.050674,0.010227,0.001499,0.038072,47.084698,2.398609,0.380715,-170.050674,0.039078,0.000000
37.310001,10.625648,-170.095154,0.010240,0.001514,0.038444,47.265244,2.407806,0.384443,-170.095154,0.039476,0.000000
37.550003,11.222191,-170.050674,0.010279,0.001541,0.039138,49.918797,2.542985,0.391381,-170.050674,0.039875,0.000000
37.790001,10.971581,-170.050674,0.010292,0.001551,0.039389,48.804028,2.486196,0.393894,-170.050674,0.040274,0.000000
38.030003,11.039726,-170.095154,0.010309,0.001567,0.039797,49.107155,2.501638,0.397970,-170.095154,0.040673,0.000000
38.270000,11.106750,-170.139633,0.010343,0.001580,0.040144,49.405293,2.516826,0.401441,-170.139633,0.041072,0.000000
38.510002,11.342094,-170.095154,0.010335,0.001600,0.040630,50.452156,2.570155,0.406297,-170.095154,0.041471,0.000000
38.750000,11.377464,-170.095154,0.010326,0.001613,0.040959,50.609489,2.578170,0.409594,-170.095154,0.041870,0.000000
38.990002,11.190163,-170.139633,0.010352,0.001622,0.041193,49.776329,2.535727,0.411933,-170.139633,0.042277,0.000000
39.230003,11.680206,-170.139633,0.010386,0.001646,0.041818,51.956154,2.646773,0.418178,-170.139633,0.042676,0.000000
39.470001,11.855225,-170.139633,0.010399,0.001663,0.042252,52.734673,2.686432,0.422515,-170.139633,0.043075,0.000000
39.710003,11.653397,-170.095154,0.010408,0.001674,0.042529,51.836899,2.640697,0.425290,-170.095154,0.043474,0.000000
39.950001,11.920013,-170.139633,0.010421,0.001694,0.043023,53.022869,2.701114,0.430233,-170.139633,0.043873,0.000000
40.190002,11.992996,-170.184113,0.010451,0.001708,0.043387,53.347511,2.717652,0.433874,-170.184113,0.044272,0.000000
40.430000,12.153488,-170.050674,0.010438,0.001728,0.043890,54.061417,2.754020,0.438904,-170.050674,0.044671,0.000000
40.670002,12.204880,-170.139633,0.010477,0.001741,0.044220,54.290016,2.765665,0.442201,-170.139633,0.045070,0.000000
40.910004,12.206367,-170.139633,0.010481,0.001753,0.044515,54.296635,2.766002,0.445149,-170.139633,0.045477,0.000000
41.150002,12.511345,-170.139633,0.010477,0.001772,0.045018,55.653240,2.835111,0.450179,-170.139633,0.045876,0.000000
41.390003,12.852066,-170.184113,0.010520,0.001794,0.045564,57.168846,2.912320,0.455641,-170.184113,0.046275,0.000000
41.630001,12.833443,-170.139633,0.010533,0.001809,0.045946,57.086002,2.908100,0.459456,-170.139633,0.046674,0.000000
41.870003,12.708328,-170.228607,0.010555,0.001821,0.046249,56.529469,2.879748,0.462491,-170.228607,0.047073,0.000000
42.110001,12.826370,-170.228607,0.010550,0.001837,0.046665,57.054543,2.906497,0.466655,-170.228607,0.047472,0.000000
42.350002,13.017395,-170.184113,0.010568,0.001852,0.047047,57.904266,2.949784,0.470470,-170.184113,0.047871,0.000000
42.590000,13.143631,-170.228607,0.010585,0.001869,0.047481,58.465790,2.978389,0.474808,-170.228607,0.048270,0.000000
42.830002,13.119057,-170.184113,0.010585,0.001879,0.047715,58.356480,2.972821,0.477150,-170.184113,0.048678,0.000000
43.070004,13.552124,-170.228607,0.010628,0.001900,0.048252,60.282860,3.070955,0.482525,-170.228607,0.049076,0.000000
43.310001,13.716713,-170.228607,0.010637,0.001917,0.048695,61.014988,3.108252,0.486949,-170.228607,0.049475,0.000000
43.550003,13.882416,-170.273087,0.010611,0.001935,0.049137,61.752071,3.145800,0.491370,-170.273087,0.049874,0.000000
43.790001,13.828796,-170.273087,0.010641,0.001948,0.049475,61.513557,3.133650,0.494754,-170.273087,0.050273,0.000000
44.030003,13.899918,-170.184113,0.010662,0.001961,0.049814,61.829922,3.149766,0.498138,-170.184113,0.050672,0.000000
44.270000,14.065620,-170.273087,0.010680,0.001978,0.050238,62.567005,3.187315,0.502384,-170.273087,0.051071,0.000000
44.510002,14.160210,-170.228607,0.010693,0.001993,0.050629,62.987759,3.208750,0.506287,-170.228607,0.051479,0.000000
44.750004,14.307297,-170.273087,0.010736,0.002006,0.050941,63.642033,3.242080,0.509409,-170.273087,0.051878,0.000000
44.990002,14.496086,-170.273087,0.010718,0.002022,0.051349,64.481812,3.284860,0.513485,-170.273087,0.052277,0.000000
45.230003,14.859894,-170.228607,0.010740,0.002040,0.051817,66.100105,3.367300,0.518167,-170.228607,0.052676,0.000000
45.470001,14.949638,-170.317566,0.010757,0.002055,0.052190,66.499313,3.387636,0.521899,-170.317566,0.053074,0.000000
45.710003,15.085922,-170.317566,0.010774,0.002072,0.052641,67.105537,3.418519,0.526407,-170.317566,0.053473,0.000000
45.950001,15.297058,-170.273087,0.010766,0.002090,0.053074,68.044716,3.466363,0.530744,-170.273087,0.053872,0.000000
46.190002,15.433350,-170.317566,0.010805,0.002104,0.053447,68.650970,3.497247,0.534473,-170.317566,0.054271,0.000000
46.430000,15.685814,-170.273087,0.010831,0.002122,0.053890,69.773987,3.554456,0.538897,-170.273087,0.054679,0.000000
46.670002,15.605759,-170.406525,0.010835,0.002133,0.054167,69.417885,3.536315,0.541671,-170.406525,0.055078,0.000000
46.910004,15.553253,-170.362045,0.010831,0.002144,0.054453,69.184326,3.524418,0.544533,-170.362045,0.055477,0.000000
47.150002,16.214958,-170.362045,0.010861,0.002167,0.055052,72.127739,3.674362,0.550517,-170.362045,0.055876,0.000000
47.390003,16.400772,-170.317566,0.010848,0.002184,0.055477,72.954277,3.716468,0.554767,-170.317566,0.056275,0.000000
47.630001,16.414551,-170.362045,0.010856,0.002197,0.055797,73.015572,3.719590,0.557973,-170.362045,0.056674,0.000000
47.870003,16.519928,-170.362045,0.010869,0.002210,0.056144,73.484306,3.743469,0.561444,-170.362045,0.057072,0.000000
48.110001,16.777237,-170.317566,0.010934,0.002228,0.056586,74.628876,3.801776,0.565865,-170.317566,0.057471,0.000000
48.350002,17.119453,-170.362045,0.010904,0.002244,0.056985,76.151131,3.879324,0.569854,-170.362045,0.057879,0.000000
48.590004,17.006622,-170.362045,0.010925,0.002253,0.057237,75.649231,3.853756,0.572371,-170.362045,0.058278,0.000000
48.830002,17.168228,-170.362045,0.010951,0.002270,0.057653,76.368095,3.890376,0.576534,-170.362045,0.058676,0.000000
49.070004,17.958405,-170.362045,0.010973,0.002294,0.058261,79.882973,4.069433,0.582605,-170.362045,0.059075,0.000000
49.310001,18.236565,-170.362045,0.010994,0.002310,0.058685,81.120293,4.132465,0.586852,-170.362045,0.059474,0.000000
49.550003,18.083153,-170.451004,0.010999,0.002322,0.058989,80.437881,4.097701,0.589887,-170.451004,0.059873,0.000000
49.790001,18.189278,-170.406525,0.010990,0.002337,0.059353,80.909950,4.121749,0.593532,-170.406525,0.060272,0.000000
50.030003,18.114433,-170.362045,0.011020,0.002348,0.059639,80.577026,4.104789,0.596393,-170.362045,0.060671,0.000000
50.270004,18.732941,-170.495483,0.011033,0.002366,0.060108,83.328285,4.244945,0.601075,-170.495483,0.061079,0.000000
50.510002,18.511749,-170.362045,0.011042,0.002374,0.060298,82.344376,4.194822,0.602983,-170.362045,0.061478,0.000000
50.750004,19.206596,-170.451004,0.011059,0.002397,0.060879,85.435211,4.352277,0.608793,-170.451004,0.061877,0.000000
50.990002,19.362625,-170.406525,0.011072,0.002410,0.061209,86.129257,4.387633,0.612089,-170.406525,0.062276,0.000000
51.230003,20.237328,-170.406525,0.011068,0.002434,0.061816,90.020126,4.585844,0.618160,-170.406525,0.062674,0.000000
51.470001,20.153542,-170.495483,0.011106,0.002445,0.062111,89.647430,4.566858,0.621109,-170.495483,0.063073,0.000000
51.710003,20.262276,-170.406525,0.011115,0.002460,0.062475,90.131104,4.591497,0.624750,-170.406525,0.063472,0.000000
51.950001,20.307335,-170.495483,0.011119,0.002474,0.062831,90.331535,4.601708,0.628308,-170.495483,0.063871,0.000000
52.190002,20.832001,-170.495483,0.011145,0.002492,0.063299,92.665367,4.720599,0.632990,-170.495483,0.064279,0.000000
52.430004,20.973503,-170.539963,0.011167,0.002506,0.063646,93.294800,4.752664,0.636460,-170.539963,0.064678,0.000000
52.670002,21.172356,-170.451004,0.011171,0.002520,0.064010,94.179344,4.797724,0.640101,-170.451004,0.065077,0.000000
52.910004,21.701866,-170.495483,0.011163,0.002540,0.064513,96.534721,4.917713,0.645132,-170.495483,0.065476,0.000000
53.150002,22.652534,-170.539963,0.011180,0.002563,0.065112,100.763504,5.133138,0.651115,-170.539963,0.065875,0.000000
53.390003,22.270477,-170.539963,0.011210,0.002573,0.065354,99.064034,5.046563,0.653542,-170.539963,0.066274,0.000000
53.630001,22.721046,-170.495483,0.011244,0.002589,0.065753,101.068260,5.148663,0.657531,-170.495483,0.066672,0.000000
53.870003,22.624977,-170.539963,0.011262,0.002601,0.066065,100.640923,5.126893,0.660653,-170.539963,0.067071,0.000000
54.110004,23.520164,-170.539963,0.011266,0.002623,0.066621,104.622917,5.329745,0.666206,-170.539963,0.067479,0.000000
54.350002,23.586815,-170.539963,0.011253,0.002635,0.066941,104.919395,5.344849,0.669412,-170.539963,0.067878,0.000000
54.590004,23.397652,-170.584442,0.011283,0.002645,0.067175,104.077950,5.301983,0.671755,-170.584442,0.068277,0.000000
54.830002,24.360237,-170.539963,0.011275,0.002667,0.067739,108.359749,5.520109,0.677390,-170.539963,0.068676,0.000000
55.070004,25.097160,-170.628922,0.011318,0.002687,0.068259,111.637741,5.687098,0.682594,-170.628922,0.069075,0.000000
55.310001,25.202538,-170.539963,0.011309,0.002702,0.068641,112.106483,5.710977,0.686410,-170.539963,0.069474,0.000000
55.550003,25.663910,-170.584442,0.011339,0.002718,0.069031,114.158775,5.815525,0.690312,-170.584442,0.069873,0.000000
55.790001,25.844139,-170.539963,0.011357,0.002731,0.069361,114.960472,5.856365,0.693609,-170.539963,0.070271,0.000000
56.030003,26.198639,-170.584442,0.011339,0.002746,0.069760,116.537369,5.936697,0.697598,-170.584442,0.070679,0.000000
56.270004,26.476051,-170.673416,0.011391,0.002761,0.070124,117.771355,5.999559,0.701239,-170.673416,0.071078,0.000000
56.510002,26.851776,-170.628922,0.011391,0.002775,0.070488,119.442665,6.084699,0.704884,-170.628922,0.071477,0.000000
56.750004,27.347404,-170.628922,0.011400,0.002791,0.070887,121.647331,6.197011,0.708873,-170.628922,0.071876,0.000000
56.990002,28.511444,-170.628922,0.011408,0.002814,0.071486,126.825241,6.460786,0.714857,-170.628922,0.072275,0.000000
57.230003,28.534531,-170.584442,0.011413,0.002826,0.071789,126.927933,6.466017,0.717892,-170.584442,0.072674,0.000000
57.470001,28.971321,-170.673416,0.011434,0.002845,0.072257,128.870880,6.564995,0.722574,-170.673416,0.073073,0.000000
57.710003,29.004089,-170.628922,0.011438,0.002855,0.072509,129.016632,6.572421,0.725087,-170.628922,0.073480,0.000000
57.950005,29.850494,-170.673416,0.011443,0.002876,0.073038,132.781631,6.764219,0.730379,-170.673416,0.073879,0.000000
58.190002,30.045990,-170.717896,0.011473,0.002887,0.073333,133.651245,6.808519,0.733327,-170.717896,0.074278,0.000000
58.430004,30.173340,-170.673416,0.011477,0.002901,0.073688,134.217712,6.837377,0.736885,-170.673416,0.074677,0.000000
58.670002,30.583694,-170.717896,0.011495,0.002916,0.074061,136.043060,6.930364,0.740613,-170.717896,0.075076,0.000000
58.910004,32.099625,-170.628922,0.011503,0.002941,0.074694,142.786255,7.273879,0.746941,-170.628922,0.075475,0.000000
59.150002,32.160690,-170.762375,0.011520,0.002953,0.074998,143.057892,7.287716,0.749977,-170.762375,0.075874,0.000000
59.390003,32.544235,-170.628922,0.011525,0.002968,0.075380,144.763992,7.374629,0.753796,-170.628922,0.076273,0.000000
59.630001,32.921448,-170.673416,0.011559,0.002984,0.075796,146.441910,7.460106,0.757955,-170.673416,0.076680,0.000000
59.870003,33.658745,-170.717896,0.011551,0.002999,0.076177,149.721573,7.627181,0.761774,-170.717896,0.077079,0.000000
60.110004,33.955528,-170.628922,0.011598,0.003012,0.076507,151.041733,7.694433,0.765067,-170.628922,0.077478,0.000000
60.350002,33.961113,-170.762375,0.011589,0.003023,0.076784,151.066574,7.695698,0.767842,-170.762375,0.077877,0.000000
60.590004,35.461029,-170.717896,0.011589,0.003048,0.077417,157.738541,8.035584,0.774174,-170.717896,0.078276,0.000000
60.830002,36.022568,-170.762375,0.011589,0.003063,0.077790,160.236389,8.162830,0.777902,-170.762375,0.078675,0.000000
61.070004,36.307800,-170.762375,0.011611,0.003079,0.078207,161.505157,8.227465,0.782065,-170.762375,0.079074,0.000000
61.310001,37.056648,-170.717896,0.011641,0.003095,0.078605,164.836197,8.397157,0.786055,-170.717896,0.079473,0.000000
61.550003,37.395874,-170.806854,0.011641,0.003108,0.078953,166.345154,8.474027,0.789525,-170.806854,0.079880,0.000000
61.790005,38.389740,-170.717896,0.011658,0.003129,0.079481,170.766098,8.699240,0.794813,-170.717896,0.080279,0.000000
62.030003,38.647049,-170.806854,0.011654,0.003140,0.079767,171.910660,8.757546,0.797674,-170.806854,0.080678,0.000000
62.270004,38.986649,-170.762375,0.011689,0.003151,0.080045,173.421280,8.834501,0.800452,-170.762375,0.081077,0.000000
62.510002,39.870667,-170.762375,0.011684,0.003172,0.080565,177.353577,9.034822,0.805653,-170.762375,0.081476,0.000000
62.750004,41.139709,-170.806854,0.011706,0.003193,0.081112,182.998566,9.322392,0.811118,-170.806854,0.081875,0.000000
62.990002,41.714653,-170.806854,0.011710,0.003209,0.081519,185.556046,9.452676,0.815194,-170.806854,0.082274,0.000000
63.230003,41.847214,-170.851334,0.011732,0.003220,0.081788,186.145706,9.482715,0.817882,-170.851334,0.082673,0.000000
63.470001,42.553604,-170.851334,0.011762,0.003237,0.082222,189.287888,9.642785,0.822219,-170.851334,0.083080,0.000000
63.710003,43.416023,-170.806854,0.011758,0.003255,0.082681,193.124115,9.838211,0.826814,-170.806854,0.083479,0.000000
63.950005,44.001022,-170.806854,0.011749,0.003269,0.083028,195.726318,9.970774,0.830285,-170.806854,0.083878,0.000000
64.190002,44.145500,-170.806854,0.011766,0.003277,0.083245,196.368988,10.003513,0.832450,-170.806854,0.084277,0.000000
64.430000,45.401138,-170.851334,0.011788,0.003300,0.083809,201.954346,10.288045,0.838089,-170.851334,0.084676,0.000000
64.670006,46.233765,-170.895813,0.011779,0.003318,0.084268,205.658051,10.476721,0.842684,-170.895813,0.085075,0.000000
64.910004,47.139000,-170.806854,0.011801,0.003335,0.084702,209.684738,10.681849,0.847022,-170.806854,0.085474,0.000000
65.150002,47.582497,-170.940292,0.011826,0.003347,0.085023,211.657516,10.782348,0.850231,-170.940292,0.085873,0.000000
65.389999,48.164513,-170.895813,0.011814,0.003360,0.085352,214.246460,10.914234,0.853524,-170.895813,0.086280,0.000000
65.630005,48.939049,-170.851334,0.011835,0.003376,0.085760,217.691757,11.089746,0.857600,-170.851334,0.086679,0.000000
65.870003,49.600380,-170.851334,0.011844,0.003394,0.086211,220.633514,11.239607,0.862112,-170.851334,0.087078,0.000000
66.110001,50.251663,-170.851334,0.011839,0.003404,0.086463,223.530563,11.387190,0.864625,-170.851334,0.087477,0.000000
66.350006,51.041092,-170.940292,0.011865,0.003420,0.086861,227.042114,11.566076,0.868614,-170.940292,0.087876,0.000000
66.590004,52.090813,-170.895813,0.011861,0.003438,0.087321,231.711502,11.803947,0.873209,-170.895813,0.088275,0.000000
66.830002,52.921944,-170.940292,0.011861,0.003455,0.087763,235.408569,11.992284,0.877634,-170.940292,0.088674,0.000000
67.070000,53.981720,-170.895813,0.011874,0.003475,0.088266,240.122681,12.232432,0.882664,-170.895813,0.089073,0.000000
67.310005,54.850464,-170.895813,0.011887,0.003489,0.088613,243.987045,12.429293,0.886131,-170.895813,0.089481,0.000000
67.550003,55.598930,-170.984772,0.011900,0.003505,0.089029,247.316391,12.598897,0.890294,-170.984772,0.089880,0.000000
67.790001,56.612160,-170.895813,0.011913,0.003521,0.089446,251.823471,12.828499,0.894458,-170.895813,0.090278,0.000000
68.030006,56.972984,-170.984772,0.011900,0.003531,0.089689,253.428497,12.910262,0.896888,-170.984772,0.090677,0.000000
68.270004,57.242958,-170.940292,0.011939,0.003542,0.089957,254.629395,12.971440,0.899575,-170.940292,0.091076,0.000000
68.510002,58.910812,-170.940292,0.011921,0.003566,0.090582,262.048370,13.349380,0.905820,-170.940292,0.091475,0.000000
68.750000,59.984360,-170.984772,0.011947,0.003583,0.091007,266.823761,13.592650,0.910067,-170.984772,0.091874,0.000000
68.990005,60.614418,-170.984772,0.011960,0.003596,0.091336,269.626404,13.735424,0.913363,-170.984772,0.092273,0.000000
69.230003,61.324905,-171.073730,0.011947,0.003609,0.091666,272.786804,13.896422,0.916660,-171.073730,0.092681,0.000000
69.470001,62.426750,-170.984772,0.011986,0.003627,0.092134,277.688049,14.146104,0.921342,-170.984772,0.093080,0.000000
69.710007,63.438492,-170.984772,0.012003,0.003643,0.092533,282.188507,14.375367,0.925331,-170.984772,0.093479,0.000000
69.950005,63.916245,-171.029251,0.011999,0.003652,0.092767,284.313660,14.483628,0.927674,-171.029251,0.093878,0.000000
70.190002,64.689285,-170.984772,0.012016,0.003669,0.093192,287.752319,14.658802,0.931921,-170.984772,0.094276,0.000000
70.430000,66.652069,-171.029251,0.012012,0.003693,0.093808,296.483215,15.103575,0.938079,-171.029251,0.094675,0.000000
70.670006,67.148437,-171.073730,0.012016,0.003695,0.093860,298.691162,15.216054,0.938601,-171.073730,0.094051,0.000000
70.910004,66.431992,-170.984772,0.012021,0.003695,0.093851,295.504242,15.053704,0.938514,-170.984772,0.094051,0.000000
71.150002,65.814224,-171.073730,0.012055,0.003695,0.093843,292.756287,14.913716,0.938427,-171.073730,0.093851,0.000000
71.390007,65.289551,-171.073730,0.012033,0.003694,0.093834,290.422424,14.794824,0.938340,-171.073730,0.093851,0.000000
71.630005,64.803238,-171.029251,0.012038,0.003694,0.093834,288.259186,14.684624,0.938340,-171.029251,0.093851,0.000000
71.870003,64.390640,-171.073730,0.012055,0.003694,0.093834,286.423859,14.591127,0.938340,-171.073730,0.093851,0.000000
72.110001,64.011566,-171.029251,0.012046,0.003694,0.093825,284.737671,14.505228,0.938253,-171.029251,0.093851,0.000000
72.350006,63.663406,-171.073730,0.012055,0.003694,0.093825,283.188965,14.426334,0.938253,-171.073730,0.093851,0.000000
72.590004,63.372208,-171.029251,0.012064,0.003694,0.093825,281.893646,14.360347,0.938253,-171.029251,0.093851,0.000000
72.830002,63.087341,-171.118225,0.012046,0.003694,0.093825,280.626495,14.295796,0.938253,-171.118225,0.093851,0.000000
73.070000,62.837479,-171.073730,0.012046,0.003694,0.093825,279.515076,14.239176,0.938253,-171.073730,0.093851,0.000000
73.310005,62.598785,-171.118225,0.012089,0.003694,0.093825,278.453308,14.185087,0.938253,-171.118225,0.093851,0.000000
73.550003,62.372383,-171.162704,0.012051,0.003694,0.093825,277.446228,14.133783,0.938253,-171.162704,0.093851,0.000000
73.790001,62.176147,-171.029251,0.012055,0.003694,0.093817,276.573303,14.089316,0.938166,-171.029251,0.093851,0.000000
74.030006,61.985489,-171.118225,0.012042,0.003694,0.093817,275.725220,14.046113,0.938166,-171.118225,0.093851,0.000000
74.270004,61.811218,-171.162704,0.012081,0.003694,0.093817,274.950043,14.006622,0.938166,-171.162704,0.093851,0.000000
74.510002,61.645515,-171.118225,0.012072,0.003694,0.093817,274.212952,13.969073,0.938166,-171.118225,0.093851,0.000000
74.750000,61.495819,-171.162704,0.012077,0.003694,0.093817,273.547058,13.935152,0.938166,-171.162704,0.093851,0.000000
74.990005,61.326767,-171.118225,0.012059,0.003694,0.093817,272.795074,13.896844,0.938166,-171.118225,0.093851,0.000000
75.230003,61.222870,-171.162704,0.012072,0.003694,0.093817,272.332916,13.873301,0.938166,-171.162704,0.093851,0.000000
75.470001,61.079880,-171.118225,0.012081,0.003694,0.093817,271.696869,13.840899,0.938166,-171.118225,0.093851,0.000000
75.710007,60.959236,-171.162704,0.012055,0.003694,0.093817,271.160217,13.813560,0.938166,-171.162704,0.093851,0.000000
75.950005,60.831139,-171.118225,0.012072,0.003694,0.093817,270.590424,13.784534,0.938166,-171.118225,0.093851,0.000000
76.190002,60.722031,-171.162704,0.012072,0.003694,0.093817,270.105072,13.759809,0.938166,-171.162704,0.093851,0.000000
76.430000,60.616653,-171.162704,0.012072,0.003694,0.093817,269.636353,13.735930,0.938166,-171.162704,0.093851,0.000000
76.670006,60.503822,-171.207184,0.012064,0.003694,0.093817,269.134430,13.710361,0.938166,-171.207184,0.093851,0.000000
76.910004,60.413704,-171.251663,0.012064,0.003694,0.093817,268.733582,13.689941,0.938166,-171.251663,0.093851,0.000000
77.150002,60.310936,-171.207184,0.012081,0.003694,0.093817,268.276428,13.666653,0.938166,-171.207184,0.093851,0.000000
77.390007,60.211884,-171.207184,0.012081,0.003694,0.093817,267.835846,13.644208,0.938166,-171.207184,0.093851,0.000000
77.630005,60.128471,-171.207184,0.012089,0.003694,0.093817,267.464813,13.625306,0.938166,-171.207184,0.093851,0.000000
77.870003,60.040962,-171.251663,0.012085,0.003694,0.093817,267.075531,13.605476,0.938166,-171.251663,0.093851,0.000000
78.110001,59.972076,-171.207184,0.012072,0.003694,0.093817,266.769135,13.589867,0.938166,-171.207184,0.093851,0.000000
78.350006,59.875626,-171.251663,0.012094,0.003694,0.093817,266.340088,13.568010,0.938166,-171.251663,0.093851,0.000000
78.590004,59.805626,-171.207184,0.012077,0.003694,0.093817,266.028717,13.552149,0.938166,-171.207184,0.093851,0.000000
78.830002,59.736359,-171.296143,0.012059,0.003694,0.093817,265.720581,13.536452,0.938166,-171.296143,0.093851,0.000000
79.070007,59.664497,-171.251663,0.012081,0.003694,0.093817,265.400940,13.520168,0.938166,-171.251663,0.093851,0.000000
79.310005,59.592628,-171.251663,0.012077,0.003694,0.093817,265.081238,13.503882,0.938166,-171.251663,0.093851,0.000000
79.550003,59.514427,-171.251663,0.012089,0.003694,0.093817,264.733398,13.486161,0.938166,-171.251663,0.093851,0.000000
79.790001,59.454849,-171.207184,0.012094,0.003694,0.093817,264.468384,13.472661,0.938166,-171.207184,0.093851,0.000000
80.030006,59.386703,-171.251663,0.012094,0.003694,0.093817,264.165253,13.457219,0.938166,-171.251663,0.093851,0.000000
80.270004,59.318932,-171.251663,0.012102,0.003694,0.093817,263.863800,13.441861,0.938166,-171.251663,0.093851,0.000000
80.510002,59.266800,-171.340622,0.012102,0.003694,0.093817,263.631897,13.430049,0.938166,-171.340622,0.093851,0.000000
80.750008,59.200516,-171.251663,0.012085,0.003694,0.093817,263.337036,13.415029,0.938166,-171.251663,0.093851,0.000000
80.990005,59.145782,-171.340622,0.012089,0.003694,0.093817,263.093567,13.402625,0.938166,-171.340622,0.093851,0.000000
81.230003,59.085831,-171.340622,0.012055,0.003694,0.093817,262.826904,13.389041,0.938166,-171.340622,0.093851,0.000000
81.470001,59.032951,-171.251663,0.012081,0.003694,0.093817,262.591675,13.377058,0.938166,-171.251663,0.093851,0.000000
81.710007,58.982307,-171.340622,0.012077,0.003694,0.093817,262.366394,13.365582,0.938166,-171.340622,0.093851,0.000000
81.950005,58.930176,-171.340622,0.012098,0.003694,0.093817,262.134521,13.353768,0.938166,-171.340622,0.093851,0.000000
82.190002,58.891449,-171.340622,0.012064,0.003694,0.093817,261.962250,13.344993,0.938166,-171.340622,0.093851,0.000000
82.430000,58.827400,-171.385101,0.012098,0.003694,0.093817,261.677338,13.330480,0.938166,-171.385101,0.093851,0.000000
82.670006,58.778618,-171.296143,0.012089,0.003694,0.093817,261.460358,13.319426,0.938166,-171.296143,0.093851,0.000000
82.910004,58.751808,-171.385101,0.012094,0.003694,0.093817,261.341095,13.313351,0.938166,-171.385101,0.093851,0.000000
83.150002,58.683662,-171.385101,0.012089,0.003694,0.093817,261.037964,13.297908,0.938166,-171.385101,0.093851,0.000000
83.390007,58.641586,-171.385101,0.012089,0.003694,0.093817,260.850800,13.288374,0.938166,-171.385101,0.093851,0.000000
83.630005,58.584244,-171.429581,0.012085,0.003694,0.093817,260.595734,13.275380,0.938166,-171.429581,0.093851,0.000000
83.870003,58.551102,-171.340622,0.012098,0.003694,0.093817,260.448303,13.267869,0.938166,-171.340622,0.093851,0.000000
84.110001,58.495621,-171.474060,0.012068,0.003694,0.093817,260.201508,13.255298,0.938166,-171.474060,0.093851,0.000000
84.350006,58.456894,-171.385101,0.012098,0.003694,0.093817,260.029236,13.246521,0.938166,-171.385101,0.093851,0.000000
84.590004,58.418907,-171.429581,0.012098,0.003694,0.093817,259.860291,13.237913,0.938166,-171.429581,0.093851,0.000000
84.830002,58.377945,-171.429581,0.012085,0.003694,0.093817,259.678070,13.228631,0.938166,-171.429581,0.093851,0.000000
85.070007,58.339592,-171.429581,0.012094,0.003694,0.093817,259.507477,13.219941,0.938166,-171.429581,0.093851,0.000000
85.310005,58.302727,-171.429581,0.012072,0.003694,0.093817,259.343475,13.211587,0.938166,-171.429581,0.093851,0.000000
85.550003,58.262138,-171.474060,0.012094,0.003694,0.093817,259.162933,13.202390,0.938166,-171.474060,0.093851,0.000000
85.790001,58.209259,-171.474060,0.012098,0.003694,0.093817,258.927704,13.190407,0.938166,-171.474060,0.093851,0.000000
86.030006,58.177238,-171.474060,0.012098,0.003694,0.093817,258.785278,13.183150,0.938166,-171.474060,0.093851,0.000000
86.270004,58.137024,-171.429581,0.012107,0.003694,0.093817,258.606384,13.174039,0.938166,-171.429581,0.093851,0.000000
86.510002,58.096062,-171.474060,0.012098,0.003694,0.093817,258.424194,13.164756,0.938166,-171.474060,0.093851,0.000000
86.750008,58.062172,-171.429581,0.012089,0.003694,0.093817,258.273437,13.157077,0.938166,-171.429581,0.093851,0.000000
86.990005,58.035362,-171.518555,0.012089,0.003694,0.093817,258.154175,13.151001,0.938166,-171.518555,0.093851,0.000000
87.230003,58.005951,-171.518555,0.012085,0.003694,0.093817,258.023346,13.144337,0.938166,-171.518555,0.093851,0.000000
87.470001,57.957169,-171.474060,0.012098,0.003694,0.093817,257.806366,13.133282,0.938166,-171.474060,0.093851,0.000000
87.710007,57.932220,-171.518555,0.012098,0.003694,0.093817,257.695374,13.127628,0.938166,-171.518555,0.093851,0.000000
87.950005,57.886414,-171.518555,0.012102,0.003694,0.093817,257.491638,13.117249,0.938166,-171.518555,0.093851,0.000000
88.190002,57.865562,-171.563034,0.012094,0.003694,0.093817,257.398865,13.112524,0.938166,-171.563034,0.093851,0.000000
88.430008,57.830933,-171.518555,0.012102,0.003694,0.093817,257.244843,13.104676,0.938166,-171.518555,0.093851,0.000000
88.670006,57.791832,-171.518555,0.012111,0.003694,0.093817,257.070923,13.095816,0.938166,-171.518555,0.093851,0.000000
88.910004,57.763535,-171.563034,0.012068,0.003694,0.093817,256.945038,13.089404,0.938166,-171.563034,0.093851,0.000000
89.150002,57.732628,-171.607513,0.012098,0.003694,0.093817,256.807556,13.082401,0.938166,-171.607513,0.093851,0.000000
89.390007,57.711403,-171.518555,0.012094,0.003694,0.093817,256.713135,13.077591,0.938166,-171.518555,0.093851,0.000000
89.630005,57.677887,-171.518555,0.012089,0.003694,0.093817,256.564056,13.069996,0.938166,-171.518555,0.093851,0.000000
89.870003,57.656662,-171.518555,0.012089,0.003694,0.093817,256.469635,13.065187,0.938166,-171.518555,0.093851,0.000000
90.110001,57.614212,-171.563034,0.012094,0.003694,0.093817,256.280823,13.055567,0.938166,-171.563034,0.093851,0.000000
90.350006,57.601921,-171.563034,0.012107,0.003694,0.093817,256.226135,13.052782,0.938166,-171.563034,0.093851,0.000000
90.590004,57.556496,-171.563034,0.012068,0.003694,0.093817,256.024078,13.042488,0.938166,-171.563034,0.093851,0.000000
90.830002,57.546066,-171.607513,0.012107,0.003694,0.093817,255.977692,13.040125,0.938166,-171.607513,0.093851,0.000000
91.070007,57.523354,-171.563034,0.012107,0.003694,0.093817,255.876663,13.034978,0.938166,-171.563034,0.093851,0.000000
91.310005,57.480904,-171.651993,0.012085,0.003694,0.093817,255.687836,13.025358,0.938166,-171.651993,0.093851,0.000000
91.550003,57.463028,-171.563034,0.012111,0.003694,0.093817,255.608307,13.021309,0.938166,-171.563034,0.093851,0.000000
91.790001,57.447014,-171.651993,0.012102,0.003694,0.093817,255.537079,13.017679,0.938166,-171.651993,0.093851,0.000000
92.030006,57.422813,-171.651993,0.012098,0.003694,0.093817,255.429428,13.012196,0.938166,-171.651993,0.093851,0.000000
92.270004,57.390419,-171.607513,0.012107,0.003694,0.093817,255.285339,13.004855,0.938166,-171.607513,0.093851,0.000000
92.510002,57.365463,-171.696472,0.012081,0.003694,0.093817,255.174332,12.999200,0.938166,-171.696472,0.093851,0.000000
92.750008,57.333443,-171.607513,0.012098,0.003694,0.093817,255.031891,12.991943,0.938166,-171.607513,0.093851,0.000000
92.990005,57.326736,-171.607513,0.012081,0.003694,0.093817,255.002060,12.990424,0.938166,-171.607513,0.093851,0.000000
93.230003,57.295830,-171.651993,0.012094,0.003694,0.093817,254.864578,12.983421,0.938166,-171.651993,0.093851,0.000000
93.470001,57.279449,-171.651993,0.012098,0.003694,0.093817,254.791718,12.979709,0.938166,-171.651993,0.093851,0.000000
93.710007,57.229179,-171.696472,0.012098,0.003694,0.093817,254.568100,12.968317,0.938166,-171.696472,0.093851,0.000000
93.950005,57.206467,-171.651993,0.012107,0.003694,0.093817,254.467072,12.963170,0.938166,-171.651993,0.093851,0.000000
94.190002,57.174438,-171.696472,0.012089,0.003694,0.093817,254.324600,12.955914,0.938166,-171.696472,0.093851,0.000000
94.430008,57.169228,-171.696472,0.012107,0.003694,0.093817,254.301422,12.954732,0.938166,-171.696472,0.093851,0.000000
94.670006,57.144653,-171.651993,0.012094,0.003694,0.093817,254.192108,12.949163,0.938166,-171.651993,0.093851,0.000000
94.910004,57.119698,-171.696472,0.012089,0.003694,0.093817,254.081100,12.943508,0.938166,-171.696472,0.093851,0.000000
95.150002,57.088425,-171.651993,0.012111,0.003694,0.093817,253.942001,12.936421,0.938166,-171.651993,0.093851,0.000000
95.390007,57.075760,-171.740952,0.012115,0.003694,0.093817,253.885666,12.933552,0.938166,-171.740952,0.093851,0.000000
95.630005,57.066452,-171.740952,0.012102,0.003694,0.093817,253.844254,12.931443,0.938166,-171.740952,0.093851,0.000000
95.870003,57.028099,-171.651993,0.012098,0.003694,0.093817,253.673660,12.922751,0.938166,-171.651993,0.093851,0.000000
96.110008,57.019531,-171.740952,0.012094,0.003694,0.093817,253.635544,12.920811,0.938166,-171.740952,0.093851,0.000000
96.350006,56.983788,-171.696472,0.012085,0.003694,0.093817,253.476547,12.912711,0.938166,-171.696472,0.093851,0.000000
96.590004,56.978203,-171.740952,0.012098,0.003694,0.093817,253.451706,12.911446,0.938166,-171.740952,0.093851,0.000000
96.830002,56.941704,-171.785431,0.012120,0.003694,0.093817,253.289352,12.903175,0.938166,-171.785431,0.093851,0.000000
97.070007,56.930161,-171.740952,0.012111,0.003694,0.093817,253.238007,12.900558,0.938166,-171.740952,0.093851,0.000000
97.310005,56.899254,-171.829910,0.012098,0.003694,0.093817,253.100525,12.893556,0.938166,-171.829910,0.093851,0.000000
97.550003,56.881012,-171.785431,0.012094,0.003694,0.093817,253.019379,12.889422,0.938166,-171.785431,0.093851,0.000000
97.790001,56.859787,-171.740952,0.012089,0.003694,0.093817,252.924957,12.884612,0.938166,-171.740952,0.093851,0.000000
98.030006,56.838928,-171.785431,0.012111,0.003694,0.093817,252.832184,12.879886,0.938166,-171.785431,0.093851,0.000000
98.270004,56.823296,-171.785431,0.012102,0.003694,0.093817,252.762650,12.876343,0.938166,-171.785431,0.093851,0.000000
98.510002,56.803932,-171.829910,0.012094,0.003694,0.093817,252.676514,12.871955,0.938166,-171.829910,0.093851,0.000000
98.750008,56.775253,-171.785431,0.012111,0.003694,0.093817,252.548935,12.865456,0.938166,-171.785431,0.093851,0.000000
98.990005,56.762596,-171.874390,0.012115,0.003694,0.093817,252.492645,12.862588,0.938166,-171.874390,0.093851,0.000000
99.230003,56.734299,-171.829910,0.012115,0.003694,0.093817,252.366760,12.856176,0.938166,-171.829910,0.093851,0.000000
99.470001,56.724983,-171.785431,0.012077,0.003694,0.093817,252.325333,12.854065,0.938166,-171.785431,0.093851,0.000000
99.710007,56.687752,-171.874390,0.012102,0.003694,0.093817,252.159714,12.845629,0.938166,-171.874390,0.093851,0.000000
99.950005,56.695572,-171.785431,0.012102,0.003694,0.093817,252.194504,12.847400,0.938166,-171.785431,0.093851,0.000000
100.190002,56.663918,-171.874390,0.012115,0.003694,0.093817,252.053696,12.840227,0.938166,-171.874390,0.093851,0.000000
100.430008,56.660194,-171.829910,0.012107,0.003694,0.093817,252.037140,12.839383,0.938166,-171.829910,0.093851,0.000000
100.670006,56.639343,-171.829910,0.012115,0.003694,0.093817,251.944382,12.834659,0.938166,-171.829910,0.093851,0.000000
100.910004,56.620346,-171.874390,0.012089,0.003694,0.093817,251.859879,12.830354,0.938166,-171.874390,0.093851,0.000000
101.100006,56.602104,-171.829910,0.012107,0.003694,0.093817,251.778732,12.826220,0.938166,-171.829910,0.093851,0.000000