File: Data/compression sample NH 10,12,15/AutoNoheating-15-2-1-240201_02012024_181434.csv
Time (sec),S:Load (lbs),S:HL1 (DIM),S:LVDT (in),S:Position (in),Ch:Position (mm),Ch:Load (N),Ch:Stress (MPa),Ch:Strain (mm/mm),Ch:HL1 (DIM),Set Point (),Cycles ()
0.110000,-0.000748,-153.014465,-0.000009,-0.000000,-0.000000,-0.003326,-0.000169,-0.000000,-153.014465,0.000217,0.000000
0.410000,0.036865,-153.058960,0.000009,0.000025,0.000625,0.163985,0.008354,0.006245,-153.058960,0.001223,0.000000
0.710000,0.022339,-153.058960,0.000039,0.000198,0.005021,0.099368,0.005062,0.050214,-153.058960,0.006218,0.000000
1.010000,0.055855,-153.058960,0.000224,0.000390,0.009904,0.248455,0.012657,0.099036,-153.058960,0.011213,0.000000
1.310000,0.023460,-153.103439,0.000423,0.000592,0.015029,0.104357,0.005316,0.150291,-153.103439,0.016208,0.000000
1.610000,0.041702,-153.103439,0.000642,0.000778,0.019755,0.185501,0.009450,0.197553,-153.103439,0.021221,0.000000
1.910000,0.017868,-153.103439,0.000849,0.000983,0.024959,0.079481,0.004049,0.249587,-153.103439,0.026216,0.000000
2.210000,0.007446,-153.147919,0.001078,0.001180,0.029980,0.033123,0.001687,0.299802,-153.147919,0.031211,0.000000
2.510000,0.014145,-153.103439,0.001285,0.001382,0.035105,0.062920,0.003205,0.351053,-153.103439,0.036207,0.000000
2.810000,0.049522,-153.147919,0.001475,0.001579,0.040101,0.220287,0.011222,0.401006,-153.147919,0.041202,0.000000
3.110000,0.028297,-153.103439,0.001707,0.001776,0.045122,0.125873,0.006412,0.451216,-153.103439,0.046197,0.000000
3.410000,0.056595,-153.147919,0.001876,0.001970,0.050048,0.251746,0.012825,0.500477,-153.147919,0.051192,0.000000
3.710000,0.042076,-153.192398,0.002113,0.002166,0.055008,0.187164,0.009535,0.550081,-153.192398,0.056205,0.000000
4.010000,0.028671,-153.147919,0.002311,0.002363,0.060021,0.127536,0.006497,0.600209,-153.147919,0.061200,0.000000
4.310000,0.032394,-153.147919,0.002509,0.002552,0.064825,0.144098,0.007341,0.648250,-153.147919,0.066196,0.000000
4.610000,-0.016388,-153.147919,0.002716,0.002757,0.070037,-0.072897,-0.003714,0.700372,-153.147919,0.071190,0.000000
4.910000,0.057343,-153.192398,0.002910,0.002950,0.074928,0.255072,0.012994,0.749284,-153.192398,0.076186,0.000000
5.210000,0.032394,-153.236877,0.003139,0.003149,0.079993,0.144098,0.007341,0.799930,-153.236877,0.081181,0.000000
5.510000,0.073730,-153.236877,0.003328,0.003352,0.085144,0.327969,0.016708,0.851442,-153.236877,0.086193,0.000000
5.810000,0.057716,-153.236877,0.003531,0.003545,0.090035,0.256735,0.013079,0.900355,-153.236877,0.091189,0.000000
6.110000,0.025322,-153.192398,0.003751,0.003741,0.095022,0.112638,0.005738,0.950221,-153.192398,0.096184,0.000000
6.410000,0.028297,-153.192398,0.003980,0.003937,0.100009,0.125873,0.006412,1.000087,-153.192398,0.101179,0.000000
6.710001,-0.015640,-153.281357,0.004182,0.004137,0.105073,-0.069571,-0.003544,1.050732,-153.281357,0.106175,0.000000
7.010000,0.058090,-153.192398,0.004393,0.004327,0.109912,0.258398,0.013163,1.099122,-153.192398,0.111170,0.000000
7.310000,0.023827,-153.236877,0.004605,0.004530,0.115063,0.105986,0.005399,1.150635,-153.236877,0.116165,0.000000
7.610000,0.067024,-153.281357,0.004781,0.004724,0.119981,0.298139,0.015188,1.199808,-153.281357,0.121178,0.000000
7.910000,0.055481,-153.236877,0.005001,0.004923,0.125045,0.246792,0.012572,1.250454,-153.236877,0.126172,0.000000
8.210000,0.043938,-153.281357,0.005195,0.005110,0.129798,0.195445,0.009956,1.297977,-153.281357,0.131168,0.000000
8.510000,0.008934,-153.281357,0.005402,0.005315,0.134992,0.039741,0.002024,1.349924,-153.281357,0.136163,0.000000
8.810000,0.027550,-153.325836,0.005609,0.005517,0.140144,0.122547,0.006243,1.401437,-153.325836,0.141158,0.000000
9.110001,0.052132,-153.281357,0.005816,0.005715,0.145156,0.231893,0.011813,1.451564,-153.281357,0.146154,0.000000
9.410001,0.053619,-153.281357,0.006066,0.005911,0.150143,0.238511,0.012150,1.501426,-153.281357,0.151166,0.000000
9.710000,0.055107,-153.325836,0.006247,0.006105,0.155060,0.245129,0.012487,1.550600,-153.325836,0.156161,0.000000
10.010000,0.053619,-153.370316,0.006437,0.006298,0.159969,0.238511,0.012150,1.599686,-153.370316,0.161157,0.000000
10.310000,0.048035,-153.325836,0.006644,0.006490,0.164834,0.213669,0.010885,1.648337,-153.325836,0.166152,0.000000
10.610001,0.022713,-153.414795,0.006847,0.006690,0.169924,0.101031,0.005147,1.699244,-153.414795,0.171147,0.000000
10.910001,0.049896,-153.370316,0.007058,0.006883,0.174833,0.221950,0.011307,1.748326,-153.370316,0.176142,0.000000
11.210001,0.001114,-153.370316,0.007274,0.007091,0.180114,0.004955,0.000252,1.801141,-153.370316,0.181155,0.000000
11.510000,0.060692,-153.370316,0.007485,0.007280,0.184919,0.269971,0.013753,1.849186,-153.370316,0.186150,0.000000
11.810000,0.052132,-153.370316,0.007705,0.007482,0.190052,0.231893,0.011813,1.900524,-153.370316,0.191145,0.000000
12.110001,0.059204,-153.414795,0.007933,0.007682,0.195117,0.263353,0.013416,1.951170,-153.414795,0.196140,0.000000
12.410001,0.037231,-153.414795,0.008088,0.007868,0.199844,0.165614,0.008437,1.998436,-153.414795,0.201136,0.000000
12.710001,0.054367,-153.414795,0.008308,0.008071,0.205012,0.241837,0.012320,2.050122,-153.414795,0.206131,0.000000
13.010000,0.055107,-153.414795,0.008528,0.008267,0.209973,0.245129,0.012487,2.099727,-153.414795,0.211126,0.000000
13.310000,-0.001862,-153.459274,0.008748,0.008466,0.215029,-0.008281,-0.000422,2.150286,-153.459274,0.216139,0.000000
13.610001,0.073357,-153.459274,0.008938,0.008654,0.219816,0.326307,0.016623,2.198157,-153.459274,0.221134,0.000000
13.910001,0.035004,-153.414795,0.009153,0.008858,0.224984,0.155704,0.007932,2.249844,-153.414795,0.226129,0.000000
14.210001,0.061066,-153.459274,0.009360,0.009051,0.229884,0.271634,0.013838,2.298843,-153.459274,0.231124,0.000000
14.510000,0.024948,-153.459274,0.009554,0.009243,0.234784,0.110975,0.005653,2.347838,-153.459274,0.236120,0.000000
14.810000,0.048775,-153.459274,0.009774,0.009445,0.239909,0.216961,0.011053,2.399094,-153.459274,0.241115,0.000000
15.110001,0.042076,-153.459274,0.009973,0.009645,0.244974,0.187164,0.009535,2.449739,-153.459274,0.246127,0.000000
15.410001,0.037979,-153.459274,0.010197,0.009848,0.250143,0.168940,0.008606,2.501426,-153.459274,0.251122,0.000000
15.710001,0.057343,-153.503769,0.010382,0.010039,0.254999,0.255072,0.012994,2.549990,-153.503769,0.256118,0.000000
16.010000,0.043564,-153.503769,0.010585,0.010240,0.260107,0.193782,0.009872,2.601071,-153.503769,0.261113,0.000000
16.310001,0.069633,-153.548248,0.010792,0.010431,0.264937,0.309745,0.015779,2.649374,-153.548248,0.266108,0.000000
16.610001,0.036118,-153.503769,0.011003,0.010624,0.269837,0.160659,0.008184,2.698373,-153.503769,0.271103,0.000000
16.910002,0.068512,-153.503769,0.011206,0.010817,0.274763,0.304756,0.015525,2.747633,-153.503769,0.276116,0.000000
17.210001,0.002228,-153.592728,0.011426,0.011023,0.279993,0.009910,0.000505,2.799925,-153.592728,0.281111,0.000000
17.510000,0.040215,-153.548248,0.011615,0.011215,0.284858,0.178883,0.009113,2.848576,-153.548248,0.286106,0.000000
17.810001,0.066277,-153.548248,0.011805,0.011418,0.290018,0.294813,0.015018,2.900176,-153.548248,0.291102,0.000000
18.110001,0.086388,-153.503769,0.012021,0.011614,0.294995,0.384271,0.019576,2.949955,-153.503769,0.296097,0.000000
18.410002,0.067772,-153.548248,0.012232,0.011810,0.299965,0.301465,0.015357,2.999647,-153.548248,0.301092,0.000000
18.710001,0.086761,-153.592728,0.012460,0.012007,0.304969,0.385934,0.019660,3.049687,-153.592728,0.306087,0.000000
19.010000,0.071121,-153.592728,0.012641,0.012197,0.309799,0.316363,0.016116,3.097990,-153.592728,0.311100,0.000000
19.310001,0.018990,-153.637207,0.012870,0.012404,0.315063,0.084470,0.004303,3.150630,-153.637207,0.316095,0.000000
19.610001,0.066277,-153.637207,0.013077,0.012593,0.319859,0.294813,0.015018,3.198588,-153.637207,0.321090,0.000000
19.910002,0.051010,-153.592728,0.013254,0.012790,0.324872,0.226904,0.011559,3.248715,-153.592728,0.326086,0.000000
20.210001,0.103142,-153.592728,0.013478,0.012985,0.329823,0.458798,0.023372,3.298233,-153.592728,0.331081,0.000000
20.510000,0.064415,-153.637207,0.013702,0.013186,0.334914,0.286532,0.014597,3.349140,-153.637207,0.336076,0.000000
20.810001,0.072609,-153.637207,0.013887,0.013381,0.339883,0.322981,0.016453,3.398832,-153.637207,0.341089,0.000000
21.110001,0.070000,-153.637207,0.014099,0.013582,0.344974,0.311374,0.015862,3.449739,-153.637207,0.346084,0.000000
21.410002,0.057343,-153.637207,0.014297,0.013777,0.349926,0.255072,0.012994,3.499257,-153.637207,0.351079,0.000000
21.710001,0.049896,-153.637207,0.014547,0.013976,0.354990,0.221950,0.011307,3.549902,-153.637207,0.356074,0.000000
22.010000,0.072609,-153.637207,0.014724,0.014174,0.360011,0.322981,0.016453,3.600113,-153.637207,0.361070,0.000000
22.310001,0.070000,-153.681686,0.014939,0.014366,0.364894,0.311374,0.015862,3.648938,-153.681686,0.366065,0.000000
22.610001,0.059204,-153.726166,0.015155,0.014566,0.369976,0.263353,0.013416,3.699758,-153.726166,0.371060,0.000000
22.910002,0.100166,-153.726166,0.015323,0.014758,0.374850,0.445562,0.022698,3.748496,-153.726166,0.376072,0.000000
23.210001,0.058830,-153.681686,0.015539,0.014957,0.379905,0.261690,0.013331,3.799054,-153.681686,0.381068,0.000000
23.510000,0.067772,-153.726166,0.015737,0.015147,0.384736,0.301465,0.015357,3.847361,-153.726166,0.386063,0.000000
23.810001,0.021965,-153.681686,0.015970,0.015351,0.389905,0.097705,0.004977,3.899047,-153.681686,0.391058,0.000000
24.110001,0.079315,-153.770645,0.016168,0.015548,0.394917,0.352812,0.017973,3.949171,-153.770645,0.396053,0.000000
24.410002,0.073357,-153.770645,0.016362,0.015746,0.399947,0.326307,0.016623,3.999472,-153.770645,0.401049,0.000000
24.710001,0.103516,-153.681686,0.016591,0.015946,0.405029,0.460460,0.023457,4.050292,-153.681686,0.406061,0.000000
25.010002,0.082291,-153.726166,0.016789,0.016139,0.409929,0.366047,0.018647,4.099291,-153.726166,0.411056,0.000000
25.310001,0.072609,-153.770645,0.017009,0.016338,0.414985,0.322981,0.016453,4.149850,-153.770645,0.416052,0.000000
25.610001,0.076706,-153.770645,0.017203,0.016530,0.419850,0.341205,0.017382,4.198501,-153.770645,0.421047,0.000000
25.910002,0.015640,-153.770645,0.017406,0.016731,0.424958,0.069571,0.003544,4.249578,-153.770645,0.426042,0.000000
26.210001,0.094208,-153.770645,0.017613,0.016918,0.429727,0.419057,0.021348,4.297275,-153.770645,0.431037,0.000000
26.510002,0.064049,-153.859604,0.017807,0.017122,0.434897,0.284903,0.014514,4.348966,-153.859604,0.436050,0.000000
26.810001,0.110588,-153.815125,0.018009,0.017317,0.439848,0.491920,0.025060,4.398483,-153.815125,0.441045,0.000000
27.110001,0.087135,-153.815125,0.018208,0.017515,0.444887,0.387597,0.019745,4.448868,-153.815125,0.446040,0.000000
27.410002,0.079681,-153.815125,0.018419,0.017710,0.449830,0.354441,0.018056,4.498299,-153.815125,0.451035,0.000000
27.710001,0.078568,-153.815125,0.018621,0.017910,0.454903,0.349486,0.017804,4.549031,-153.815125,0.456031,0.000000
28.010002,0.067398,-153.770645,0.018850,0.018111,0.460020,0.299802,0.015273,4.600199,-153.770645,0.461026,0.000000
28.310001,0.091232,-153.859604,0.019078,0.018306,0.464980,0.405822,0.020674,4.649804,-153.859604,0.466021,0.000000
28.610001,0.047661,-153.815125,0.019277,0.018502,0.469958,0.212006,0.010800,4.699583,-153.815125,0.471034,0.000000
28.910002,0.095322,-153.859604,0.019484,0.018696,0.474876,0.424012,0.021600,4.748756,-153.859604,0.476029,0.000000
29.210001,0.085640,-153.904083,0.019678,0.018892,0.479854,0.380946,0.019406,4.798535,-153.904083,0.481024,0.000000
29.510002,0.085640,-153.859604,0.019880,0.019081,0.484658,0.380946,0.019406,4.846577,-153.859604,0.486019,0.000000
29.810001,0.047661,-153.859604,0.020061,0.019282,0.489757,0.212006,0.010800,4.897571,-153.859604,0.491014,0.000000
30.110001,0.074097,-153.815125,0.020268,0.019479,0.494770,0.329598,0.016791,4.947698,-153.815125,0.496010,0.000000
30.410002,0.059204,-153.815125,0.020497,0.019684,0.499964,0.263353,0.013416,4.999642,-153.815125,0.501022,0.000000
30.710001,0.116920,-153.859604,0.020700,0.019880,0.504942,0.520088,0.026495,5.049421,-153.859604,0.506017,0.000000
31.010002,0.090111,-153.948578,0.020881,0.020076,0.509929,0.400833,0.020419,5.099287,-153.948578,0.511013,0.000000
31.310001,0.106499,-153.948578,0.021109,0.020274,0.514959,0.473730,0.024133,5.149588,-153.948578,0.516008,0.000000
31.610001,0.090485,-153.948578,0.021303,0.020463,0.519754,0.402496,0.020504,5.197543,-153.948578,0.521003,0.000000
31.910002,0.059578,-153.948578,0.021523,0.020665,0.524880,0.265016,0.013501,5.248798,-153.948578,0.525999,0.000000
32.210003,0.092346,-153.948578,0.021713,0.020855,0.529719,0.410776,0.020926,5.297188,-153.948578,0.531011,0.000000
32.510002,0.043564,-153.948578,0.021933,0.021060,0.534931,0.193782,0.009872,5.349309,-153.948578,0.536006,0.000000
32.810001,0.124367,-153.993057,0.022122,0.021248,0.539692,0.553211,0.028182,5.396920,-153.993057,0.541001,0.000000
33.110001,0.090858,-153.948578,0.022347,0.021451,0.544843,0.404159,0.020589,5.448432,-153.948578,0.545997,0.000000
33.410000,0.106499,-153.904083,0.022532,0.021645,0.549778,0.473730,0.024133,5.497776,-153.904083,0.550992,0.000000
33.710003,0.084526,-154.037537,0.022752,0.021837,0.554660,0.375991,0.019154,5.546601,-154.037537,0.555987,0.000000
34.010002,0.108727,-153.993057,0.022959,0.022043,0.559898,0.483640,0.024638,5.598984,-153.993057,0.560982,0.000000
34.310001,0.100166,-153.993057,0.023157,0.022240,0.564902,0.445562,0.022698,5.649020,-153.993057,0.565995,0.000000
34.610001,0.091972,-153.993057,0.023368,0.022441,0.570010,0.409113,0.020841,5.700101,-153.993057,0.570990,0.000000
34.910000,0.115059,-153.993057,0.023567,0.022626,0.574702,0.511808,0.026073,5.747018,-153.993057,0.575985,0.000000
35.210003,0.081177,-153.993057,0.023800,0.022832,0.579940,0.361092,0.018395,5.799398,-153.993057,0.580981,0.000000
35.510002,0.123253,-154.037537,0.023989,0.023023,0.584787,0.548256,0.027929,5.847875,-154.037537,0.585976,0.000000
35.810001,0.107986,-154.037537,0.024188,0.023218,0.589740,0.480348,0.024470,5.897396,-154.037537,0.590971,0.000000
36.110001,0.136658,-154.037537,0.024403,0.023412,0.594674,0.607884,0.030967,5.946740,-154.037537,0.595984,0.000000
36.410000,0.457642,-154.082016,0.024602,0.023614,0.599799,2.035691,0.103703,5.997995,-154.082016,0.600979,0.000000
36.710003,0.576431,-154.037537,0.024666,-0.000000,-0.000000,2.564094,0.130621,-0.000000,-154.037537,0.000234,0.000000
37.010002,0.561539,-154.082016,0.024640,-0.000000,-0.000000,2.497849,0.127246,-0.000000,-154.082016,0.000234,0.000000
37.310001,0.651276,-154.082016,0.024645,-0.000000,-0.000000,2.897019,0.147581,-0.000000,-154.082016,0.000729,0.000000
37.610001,0.647179,-154.082016,0.024653,-0.000000,-0.000000,2.878794,0.146653,-0.000000,-154.082016,0.001232,0.000000
37.910004,0.889221,-154.126495,0.024666,0.000037,0.000937,3.955453,0.201500,0.009368,-154.126495,0.001726,0.000000
38.210003,1.048599,-154.126495,0.024675,0.000052,0.001327,4.664402,0.237616,0.013270,-154.126495,0.002229,0.000000
38.510002,1.233665,-154.126495,0.024683,0.000072,0.001830,5.487618,0.279553,0.018300,-154.126495,0.002732,0.000000
38.810001,1.317078,-154.126495,0.024714,0.000088,0.002237,5.858654,0.298454,0.022373,-154.126495,0.003226,0.000000
39.110001,1.594872,-154.126495,0.024718,0.000113,0.002870,7.094343,0.361403,0.028705,-154.126495,0.003729,0.000000
39.410004,1.744934,-154.170975,0.024735,0.000130,0.003304,7.761855,0.395408,0.033042,-154.170975,0.004232,0.000000
39.710003,1.881592,-154.170975,0.024739,0.000145,0.003686,8.369739,0.426375,0.036857,-154.170975,0.004726,0.000000
40.010002,2.153053,-154.126495,0.024765,0.000173,0.004406,9.577259,0.487889,0.044056,-154.126495,0.005229,0.000000
40.310001,2.372757,-154.126495,0.024791,0.000194,0.004934,10.554550,0.537674,0.049344,-154.126495,0.005732,0.000000
40.610001,2.503830,-154.215454,0.024813,0.000211,0.005359,11.137592,0.567376,0.053594,-154.215454,0.006227,0.000000
40.910004,2.745499,-154.126495,0.024821,0.000233,0.005915,12.212588,0.622139,0.059147,-154.126495,0.006730,0.000000
41.210003,2.961479,-154.215454,0.024852,0.000250,0.006357,13.173317,0.671081,0.063567,-154.215454,0.007233,0.000000
41.510002,3.032600,-154.215454,0.024873,0.000265,0.006730,13.489680,0.687197,0.067295,-154.215454,0.007727,0.000000
41.810001,3.237404,-154.170975,0.024890,0.000280,0.007103,14.400692,0.733606,0.071027,-154.170975,0.008230,0.000000
42.110001,3.581474,-154.215454,0.024925,0.000308,0.007822,15.931193,0.811574,0.078222,-154.215454,0.008733,0.000000
42.410004,3.664886,-154.259933,0.024925,0.000322,0.008187,16.302229,0.830475,0.081867,-154.259933,0.009227,0.000000
42.710003,3.832825,-154.215454,0.024946,0.000341,0.008672,17.049255,0.868531,0.086723,-154.215454,0.009730,0.000000
43.010002,4.162750,-154.304413,0.024951,0.000369,0.009375,18.516838,0.943293,0.093748,-154.304413,0.010233,0.000000
43.310001,4.203339,-154.259933,0.024985,0.000382,0.009713,18.697384,0.952490,0.097128,-154.259933,0.010728,0.000000
43.610001,4.355263,-154.259933,0.024981,0.000400,0.010173,19.373177,0.986917,0.101727,-154.259933,0.011231,0.000000
43.910004,4.721306,-154.259933,0.025002,0.000427,0.010840,21.001417,1.069863,0.108403,-154.259933,0.011734,0.000000
44.210003,4.848656,-154.304413,0.025059,0.000448,0.011369,21.567898,1.098721,0.113694,-154.304413,0.012228,0.000000
44.510002,4.936913,-154.304413,0.025050,0.000465,0.011803,21.960484,1.118720,0.118028,-154.304413,0.012731,0.000000
44.810001,4.983459,-154.304413,0.025059,0.000481,0.012228,22.167536,1.129268,0.122279,-154.304413,0.013234,0.000000
45.110001,5.288429,-154.304413,0.025084,0.000505,0.012826,23.524109,1.198375,0.128263,-154.304413,0.013728,0.000000
45.410004,5.351364,-154.348907,0.025119,0.000521,0.013225,23.804056,1.212636,0.132252,-154.348907,0.014231,0.000000
45.710003,5.513718,-154.304413,0.025145,0.000540,0.013719,24.526241,1.249426,0.137195,-154.304413,0.014734,0.000000
46.010002,5.777359,-154.348907,0.025149,0.000568,0.014431,25.698977,1.309168,0.144307,-154.348907,0.015229,0.000000
46.310001,5.788902,-154.304413,0.025166,0.000587,0.014899,25.750324,1.311784,0.148989,-154.304413,0.015732,0.000000
46.610001,5.848106,-154.304413,0.025205,0.000603,0.015315,26.013676,1.325200,0.153152,-154.304413,0.016235,0.000000
46.910004,6.070412,-154.348907,0.025209,0.000626,0.015896,27.002541,1.375575,0.158962,-154.348907,0.016729,0.000000
47.210003,6.095360,-154.348907,0.025235,0.000642,0.016295,27.113514,1.381228,0.162951,-154.348907,0.017232,0.000000
47.510002,6.203720,-154.348907,0.025244,0.000659,0.016729,27.595526,1.405783,0.167289,-154.348907,0.017726,0.000000
47.810001,6.479279,-154.393387,0.025278,0.000686,0.017414,28.821270,1.468225,0.174139,-154.393387,0.018229,0.000000
48.110001,6.534386,-154.348907,0.025283,0.000704,0.017873,29.066399,1.480713,0.178734,-154.348907,0.018732,0.000000
48.410004,6.558220,-154.393387,0.025313,0.000722,0.018342,29.172419,1.486114,0.183420,-154.393387,0.019227,0.000000
48.710003,6.610352,-154.393387,0.025334,0.000739,0.018758,29.404312,1.497927,0.187579,-154.393387,0.019730,0.000000
49.010002,6.788719,-154.393387,0.025339,0.000761,0.019339,30.197731,1.538346,0.193393,-154.393387,0.020233,0.000000
49.310001,6.802498,-154.437866,0.025356,0.000775,0.019695,30.259022,1.541468,0.196947,-154.437866,0.020727,0.000000
49.610001,6.891121,-154.437866,0.025382,0.000795,0.020198,30.653236,1.561550,0.201977,-154.437866,0.021230,0.000000
49.910004,7.144707,-154.437866,0.025416,0.000820,0.020839,31.781242,1.619014,0.208393,-154.437866,0.021732,0.000000
50.210003,7.075821,-154.482346,0.025438,0.000835,0.021221,31.474823,1.603404,0.212211,-154.482346,0.022227,0.000000
50.510002,7.297005,-154.437866,0.025451,0.000860,0.021837,32.458698,1.653525,0.218366,-154.437866,0.022730,0.000000
50.810001,7.338341,-154.437866,0.025451,0.000878,0.022296,32.642570,1.662892,0.222964,-154.437866,0.023233,0.000000
51.110001,7.467186,-154.437866,0.025485,0.000899,0.022825,33.215702,1.692088,0.228252,-154.437866,0.023727,0.000000
51.410004,7.433296,-154.437866,0.025481,0.000912,0.023164,33.064953,1.684409,0.231636,-154.437866,0.024230,0.000000
51.710003,7.685020,-154.526825,0.025537,0.000937,0.023788,34.184677,1.741451,0.237881,-154.526825,0.024733,0.000000
52.010002,7.749069,-154.526825,0.025546,0.000956,0.024274,34.469582,1.755964,0.242737,-154.526825,0.025227,0.000000
52.310001,7.785187,-154.526825,0.025572,0.000975,0.024768,34.630241,1.764148,0.247680,-154.526825,0.025730,0.000000
52.610001,7.730446,-154.526825,0.025567,0.000988,0.025089,34.386742,1.751744,0.250889,-154.526825,0.026233,0.000000
52.910004,8.029091,-154.482346,0.025580,0.001012,0.025705,35.715179,1.819418,0.257047,-154.482346,0.026728,0.000000
53.210003,7.944565,-154.526825,0.025610,0.001027,0.026078,35.339188,1.800264,0.260775,-154.526825,0.027231,0.000000
53.510002,8.254005,-154.482346,0.025641,0.001053,0.026754,36.715649,1.870384,0.267539,-154.482346,0.027734,0.000000
53.810001,8.498657,-154.571304,0.025679,0.001079,0.027413,37.803917,1.925823,0.274129,-154.571304,0.028228,0.000000
54.110004,8.389175,-154.526825,0.025675,0.001095,0.027803,37.316917,1.901014,0.278031,-154.526825,0.028731,0.000000
54.410004,8.419708,-154.571304,0.025697,0.001112,0.028246,37.452732,1.907933,0.282455,-154.571304,0.029234,0.000000
54.710003,8.603294,-154.571304,0.025723,0.001135,0.028827,38.269363,1.949534,0.288265,-154.571304,0.029728,0.000000
55.010002,8.421204,-154.571304,0.025731,0.001145,0.029087,37.459385,1.908272,0.290869,-154.571304,0.030231,0.000000
55.310001,8.752243,-154.615784,0.025727,0.001169,0.029702,38.931923,1.983287,0.297023,-154.615784,0.030734,0.000000
55.610004,8.968216,-154.571304,0.025748,0.001192,0.030275,39.892616,2.032227,0.302750,-154.571304,0.031229,0.000000
55.910004,8.998749,-154.660263,0.025774,0.001212,0.030795,40.028435,2.039145,0.307950,-154.660263,0.031732,0.000000
56.210003,8.989815,-154.571304,0.025830,0.001229,0.031229,39.988693,2.037121,0.312288,-154.571304,0.032235,0.000000
56.510002,9.277283,-154.615784,0.025843,0.001254,0.031862,41.267414,2.102262,0.318620,-154.615784,0.032729,0.000000
56.810001,9.227760,-154.660263,0.025856,0.001269,0.032244,41.047127,2.091040,0.322435,-154.660263,0.033232,0.000000
57.110004,9.167435,-154.615784,0.025865,0.001286,0.032669,40.778786,2.077370,0.326686,-154.615784,0.033735,0.000000
57.410004,9.429214,-154.615784,0.025899,0.001309,0.033241,41.943241,2.136691,0.332408,-154.615784,0.034229,0.000000
57.710003,9.669395,-154.704742,0.025904,0.001332,0.033822,43.011620,2.191116,0.338218,-154.704742,0.034732,0.000000
58.010002,9.640350,-154.660263,0.025938,0.001350,0.034281,42.882420,2.184535,0.342813,-154.660263,0.035235,0.000000
58.310001,9.581139,-154.660263,0.025960,0.001363,0.034611,42.619034,2.171117,0.346110,-154.660263,0.035730,0.000000
58.610004,9.992615,-154.704742,0.025977,0.001390,0.035313,44.449371,2.264359,0.353134,-154.704742,0.036233,0.000000
58.910004,9.969894,-154.704742,0.025981,0.001406,0.035712,44.348305,2.259211,0.357124,-154.704742,0.036736,0.000000
59.210003,10.025757,-154.704742,0.026011,0.001426,0.036224,44.596794,2.271869,0.362241,-154.704742,0.037230,0.000000
59.510002,10.325516,-154.704742,0.026029,0.001450,0.036822,45.930187,2.339795,0.368225,-154.704742,0.037733,0.000000
59.810001,10.400360,-154.704742,0.026063,0.001471,0.037351,46.263111,2.356755,0.373512,-154.704742,0.038236,0.000000
60.110004,10.357910,-154.749222,0.026067,0.001486,0.037750,46.074284,2.347136,0.377502,-154.749222,0.038730,0.000000
60.410004,10.513565,-154.749222,0.026067,0.001508,0.038305,46.766674,2.382408,0.383054,-154.749222,0.039233,0.000000
60.710003,10.684479,-154.749222,0.026145,0.001527,0.038782,47.526936,2.421138,0.387823,-154.749222,0.039728,0.000000
61.010002,10.669960,-154.749222,0.026119,0.001544,0.039216,47.462353,2.417847,0.392161,-154.749222,0.040230,0.000000
61.310001,10.923912,-154.749222,0.026154,0.001567,0.039797,48.591988,2.475394,0.397970,-154.749222,0.040733,0.000000
61.610004,11.215485,-154.793716,0.026171,0.001593,0.040456,49.888966,2.541465,0.404560,-154.793716,0.041228,0.000000
61.910004,11.106377,-154.838196,0.026175,0.001609,0.040872,49.403629,2.516741,0.408723,-154.838196,0.041731,0.000000
62.210003,11.321609,-154.838196,0.026201,0.001631,0.041436,50.361034,2.565513,0.414359,-154.838196,0.042234,0.000000
62.510002,11.392357,-154.838196,0.026218,0.001650,0.041921,50.675735,2.581545,0.419215,-154.838196,0.042728,0.000000
62.810001,11.314163,-154.838196,0.026214,0.001663,0.042242,50.327911,2.563826,0.422425,-154.838196,0.043231,0.000000
63.110004,11.470184,-154.793716,0.026253,0.001683,0.042737,51.021927,2.599181,0.427368,-154.793716,0.043734,0.000000
63.410004,11.728241,-154.838196,0.026287,0.001704,0.043283,52.169823,2.657657,0.432833,-154.838196,0.044228,0.000000
63.710003,11.819847,-154.882675,0.026279,0.001721,0.043708,52.577305,2.678416,0.437083,-154.882675,0.044731,0.000000
64.010002,11.943100,-154.882675,0.026313,0.001740,0.044185,53.125561,2.706345,0.441852,-154.882675,0.045234,0.000000
64.310005,12.398140,-154.882675,0.026335,0.001767,0.044879,55.149681,2.809459,0.448790,-154.882675,0.045729,0.000000
64.610001,12.251793,-154.971634,0.026365,0.001781,0.045234,54.498695,2.776296,0.452344,-154.971634,0.046232,0.000000
64.910004,12.370956,-154.882675,0.026369,0.001799,0.045703,55.028763,2.803299,0.457026,-154.882675,0.046735,0.000000
65.210007,12.863976,-154.882675,0.026404,0.001826,0.046379,57.221821,2.915019,0.463793,-154.882675,0.047229,0.000000
65.510002,12.920952,-154.927155,0.026425,0.001846,0.046882,57.475266,2.927930,0.468824,-154.927155,0.047732,0.000000
65.810005,12.885574,-154.882675,0.026434,0.001862,0.047298,57.317898,2.919913,0.472983,-154.882675,0.048235,0.000000
66.110001,12.923927,-154.882675,0.026425,0.001879,0.047732,57.488499,2.928604,0.477321,-154.882675,0.048729,0.000000
66.410004,13.379341,-154.882675,0.026464,0.001904,0.048357,59.514282,3.031802,0.483566,-154.882675,0.049232,0.000000
66.710007,13.321251,-154.971634,0.026486,0.001919,0.048738,59.255882,3.018639,0.487381,-154.971634,0.049735,0.000000
67.010002,13.631065,-154.927155,0.026512,0.001940,0.049284,60.634007,3.088844,0.492843,-154.927155,0.050230,0.000000
67.310005,13.990028,-154.971634,0.026503,0.001966,0.049926,62.230755,3.170186,0.499262,-154.971634,0.050733,0.000000
67.610001,14.000458,-154.971634,0.026533,0.001985,0.050420,62.277145,3.172549,0.504205,-154.971634,0.051236,0.000000
67.910004,14.006790,-155.016113,0.026555,0.002001,0.050837,62.305313,3.173984,0.508368,-155.016113,0.051730,0.000000
68.210007,14.375809,-154.971634,0.026568,0.002025,0.051427,63.946793,3.257605,0.514265,-154.971634,0.052233,0.000000
68.510002,14.252182,-155.016113,0.026602,0.002037,0.051739,63.396873,3.229591,0.517388,-155.016113,0.052736,0.000000
68.810005,14.517311,-154.971634,0.026615,0.002057,0.052259,64.576225,3.289670,0.522592,-154.971634,0.053230,0.000000
69.110001,14.953728,-154.971634,0.026632,0.002081,0.052866,66.517502,3.388563,0.528659,-154.971634,0.053733,0.000000
69.410004,15.149597,-154.971634,0.026645,0.002102,0.053395,67.388771,3.432948,0.533950,-154.971634,0.054236,0.000000
69.710007,15.162262,-155.016113,0.026658,0.002120,0.053846,67.445107,3.435817,0.538462,-155.016113,0.054731,0.000000
70.010002,15.180504,-155.060593,0.026697,0.002137,0.054271,67.526253,3.439951,0.542709,-155.060593,0.055234,0.000000
70.310005,15.629959,-155.105072,0.026684,0.002161,0.054878,69.525528,3.541800,0.548779,-155.105072,0.055737,0.000000
70.610001,15.612457,-155.060593,0.026718,0.002174,0.055216,69.447678,3.537833,0.552163,-155.060593,0.056231,0.000000
70.910004,15.807953,-155.149551,0.026749,0.002193,0.055702,70.317284,3.582133,0.557019,-155.149551,0.056734,0.000000
71.210007,16.334114,-155.105072,0.026744,0.002218,0.056343,72.657768,3.701363,0.563435,-155.105072,0.057237,0.000000
71.510002,16.287941,-155.060593,0.026775,0.002233,0.056725,72.452377,3.690900,0.567254,-155.060593,0.057731,0.000000
71.810005,16.811127,-155.105072,0.026775,0.002257,0.057332,74.779625,3.809456,0.573325,-155.105072,0.058234,0.000000
72.110001,16.844635,-155.060593,0.026800,0.002275,0.057783,74.928680,3.817049,0.577832,-155.060593,0.058737,0.000000
72.410004,17.164505,-155.149551,0.026809,0.002296,0.058312,76.351532,3.889532,0.583124,-155.149551,0.059231,0.000000
72.710007,17.195038,-155.149551,0.026831,0.002310,0.058685,76.487350,3.896451,0.586852,-155.149551,0.059734,0.000000
73.010002,17.692154,-155.105072,0.026865,0.002334,0.059284,78.698631,4.009099,0.592836,-155.105072,0.060237,0.000000
73.310005,17.949097,-155.194031,0.026869,0.002354,0.059795,79.841568,4.067323,0.597953,-155.194031,0.060732,0.000000
73.610001,18.080544,-155.149551,0.026891,0.002373,0.060272,80.426277,4.097110,0.602722,-155.149551,0.061235,0.000000
73.910004,18.013885,-155.149551,0.026912,0.002386,0.060593,80.129768,4.082005,0.605931,-155.149551,0.061729,0.000000
74.210007,18.753044,-155.238525,0.026925,0.002410,0.061226,83.417709,4.249501,0.612260,-155.238525,0.062232,0.000000
74.510002,18.650642,-155.194031,0.026943,0.002424,0.061564,82.962204,4.226296,0.615643,-155.194031,0.062735,0.000000
74.810005,19.296341,-155.149551,0.026964,0.002449,0.062198,85.834412,4.372613,0.621976,-155.149551,0.063229,0.000000
75.110001,20.120773,-155.194031,0.026973,0.002477,0.062926,89.501671,4.559433,0.629258,-155.194031,0.063732,0.000000
75.410004,19.976662,-155.149551,0.026999,0.002492,0.063299,88.860626,4.526776,0.632990,-155.149551,0.064235,0.000000
75.710007,20.120399,-155.283005,0.027016,0.002510,0.063758,89.500008,4.559348,0.637585,-155.283005,0.064730,0.000000
76.010002,20.616768,-155.238525,0.027029,0.002532,0.064313,91.707962,4.671826,0.643133,-155.238525,0.065233,0.000000
76.310005,20.292061,-155.194031,0.027046,0.002542,0.064574,90.263596,4.598247,0.645737,-155.194031,0.065736,0.000000
76.610001,21.038666,-155.238525,0.027059,0.002566,0.065172,93.584656,4.767430,0.651721,-155.238525,0.066230,0.000000
76.910004,21.657921,-155.283005,0.027089,0.002591,0.065805,96.339241,4.907755,0.658049,-155.283005,0.066733,0.000000
77.210007,22.007584,-155.238525,0.027098,0.002610,0.066291,97.894623,4.986990,0.662905,-155.238525,0.067236,0.000000
77.510002,22.067162,-155.194031,0.027132,0.002628,0.066742,98.159637,5.000490,0.667417,-155.194031,0.067730,0.000000
77.810005,22.734077,-155.283005,0.027132,0.002652,0.067358,101.126228,5.151616,0.673575,-155.283005,0.068233,0.000000
78.110001,22.876328,-155.283005,0.027163,0.002668,0.067765,101.758987,5.183850,0.677651,-155.283005,0.068736,0.000000
78.410004,22.797012,-155.238525,0.027150,0.002680,0.068069,101.406174,5.165877,0.680687,-155.238525,0.069231,0.000000
78.710007,23.535423,-155.283005,0.027188,0.002704,0.068684,104.690788,5.333203,0.686841,-155.283005,0.069734,0.000000
79.010002,24.321503,-155.327484,0.027206,0.002728,0.069300,108.187447,5.511332,0.692999,-155.327484,0.070237,0.000000
79.310005,24.398216,-155.327484,0.027214,0.002746,0.069751,108.528687,5.528715,0.697511,-155.327484,0.070731,0.000000
79.610001,24.669304,-155.327484,0.027236,0.002761,0.070133,109.734543,5.590144,0.701326,-155.327484,0.071234,0.000000
79.910004,25.243126,-155.371964,0.027232,0.002787,0.070783,112.287033,5.720174,0.707828,-155.371964,0.071737,0.000000
80.210007,25.822540,-155.371964,0.027236,0.002803,0.071199,114.864395,5.851471,0.711992,-155.371964,0.072231,0.000000
80.510002,26.025856,-155.283005,0.027288,0.002820,0.071633,115.768791,5.897543,0.716329,-155.283005,0.072734,0.000000
80.810005,27.024559,-155.371964,0.027288,0.002847,0.072318,120.211243,6.123853,0.723180,-155.371964,0.073237,0.000000
81.110001,27.296761,-155.371964,0.027296,0.002866,0.072804,121.422058,6.185534,0.728036,-155.371964,0.073732,0.000000
81.410004,27.640457,-155.327484,0.027313,0.002885,0.073272,122.950897,6.263417,0.732718,-155.327484,0.074235,0.000000
81.710007,28.083214,-155.416443,0.027339,0.002903,0.073749,124.920372,6.363747,0.737487,-155.416443,0.074738,0.000000
82.010002,28.524841,-155.371964,0.027374,0.002921,0.074200,126.884834,6.463821,0.741998,-155.371964,0.075232,0.000000
82.310005,29.071487,-155.416443,0.027365,0.002939,0.074651,129.316437,6.587693,0.746506,-155.416443,0.075735,0.000000
82.610001,29.622971,-155.416443,0.027387,0.002961,0.075206,131.769562,6.712661,0.752059,-155.416443,0.076238,0.000000
82.910004,30.995911,-155.371964,0.027404,0.002991,0.075978,137.876694,7.023774,0.759776,-155.371964,0.076732,0.000000
83.210007,31.138901,-155.416443,0.027426,0.003007,0.076368,138.512741,7.056176,0.763678,-155.416443,0.077235,0.000000
83.510002,31.756294,-155.416443,0.027443,0.003028,0.076906,141.259048,7.196079,0.769057,-155.416443,0.077738,0.000000
83.810005,32.380386,-155.505402,0.027464,0.003047,0.077383,144.035156,7.337501,0.773826,-155.505402,0.078232,0.000000
84.110001,32.352837,-155.460922,0.027434,0.003061,0.077738,143.912598,7.331257,0.777380,-155.460922,0.078735,0.000000
84.410004,32.697281,-155.460922,0.027473,0.003075,0.078094,145.444763,7.409309,0.780937,-155.460922,0.079238,0.000000
84.710007,33.970047,-155.505402,0.027482,0.003100,0.078744,151.106323,7.697722,0.787440,-155.505402,0.079733,0.000000
85.010002,34.603455,-155.460922,0.027486,0.003119,0.079230,153.923859,7.841255,0.792296,-155.460922,0.080236,0.000000
85.310005,35.061470,-155.460922,0.027512,0.003137,0.079689,155.961212,7.945043,0.796894,-155.460922,0.080739,0.000000
85.610001,36.079536,-155.505402,0.027512,0.003163,0.080348,160.489792,8.175740,0.803484,-155.505402,0.081233,0.000000
85.910004,36.633629,-155.460922,0.027546,0.003178,0.080730,162.954514,8.301298,0.807299,-155.460922,0.081736,0.000000
86.210007,36.784813,-155.549881,0.027555,0.003193,0.081103,163.627014,8.335558,0.811031,-155.549881,0.082239,0.000000
86.510002,38.265366,-155.505402,0.027564,0.003221,0.081805,170.212845,8.671056,0.818052,-155.505402,0.082733,0.000000
86.810005,39.162407,-155.460922,0.027572,0.003243,0.082369,174.203079,8.874328,0.823692,-155.460922,0.083236,0.000000
87.110001,39.532547,-155.549881,0.027598,0.003259,0.082785,175.849548,8.958203,0.827855,-155.549881,0.083731,0.000000
87.410004,39.926147,-155.505402,0.027598,0.003275,0.083184,177.600372,9.047394,0.831844,-155.505402,0.084234,0.000000
87.710007,41.262962,-155.549881,0.027633,0.003301,0.083835,183.546829,9.350321,0.838347,-155.549881,0.084737,0.000000
88.010002,41.490112,-155.505402,0.027641,0.003315,0.084199,184.557236,9.401793,0.841988,-155.505402,0.085231,0.000000
88.310005,42.570732,-155.549881,0.027671,0.003337,0.084754,189.364075,9.646666,0.847540,-155.549881,0.085734,0.000000
88.610001,43.862869,-155.594360,0.027680,0.003361,0.085370,195.111786,9.939468,0.853698,-155.594360,0.086237,0.000000
88.910004,44.497391,-155.549881,0.027693,0.003379,0.085838,197.934280,10.083253,0.858380,-155.549881,0.086731,0.000000
89.210007,45.071213,-155.549881,0.027684,0.003397,0.086280,200.486771,10.213284,0.862805,-155.549881,0.087234,0.000000
89.510002,46.301903,-155.594360,0.027697,0.003421,0.086896,205.961151,10.492161,0.868959,-155.594360,0.087737,0.000000
89.810005,46.774445,-155.594360,0.027719,0.003435,0.087243,208.063126,10.599241,0.872430,-155.594360,0.088232,0.000000
90.110001,47.594414,-155.638855,0.027723,0.003455,0.087763,211.710526,10.785048,0.877634,-155.638855,0.088735,0.000000
90.410004,48.914101,-155.638855,0.027749,0.003478,0.088336,217.580780,11.084093,0.883357,-155.638855,0.089238,0.000000
90.710007,49.713211,-155.594360,0.027749,0.003498,0.088839,221.135406,11.265174,0.888387,-155.594360,0.089732,0.000000
91.010002,50.538017,-155.594360,0.027779,0.003516,0.089298,224.804321,11.452079,0.892982,-155.594360,0.090235,0.000000
91.310005,51.104019,-155.594360,0.027775,0.003531,0.089697,227.322037,11.580336,0.896971,-155.594360,0.090738,0.000000
91.610001,52.500793,-155.638855,0.027805,0.003554,0.090278,233.535187,11.896851,0.902781,-155.638855,0.091232,0.000000
91.910004,53.264900,-155.549881,0.027818,0.003571,0.090703,236.934113,12.069999,0.907031,-155.549881,0.091735,0.000000
92.210007,53.975014,-155.638855,0.027835,0.003587,0.091119,240.092850,12.230913,0.911195,-155.638855,0.092238,0.000000
92.510002,55.511795,-155.638855,0.027818,0.003612,0.091752,246.928802,12.579153,0.917523,-155.638855,0.092733,0.000000
92.810005,56.437515,-155.683334,0.027835,0.003631,0.092230,251.046600,12.788924,0.922296,-155.683334,0.093236,0.000000
93.110001,57.808586,-155.727814,0.027861,0.003655,0.092828,257.145447,13.099613,0.928280,-155.727814,0.093739,0.000000
93.410004,58.462105,-155.683334,0.027874,0.003670,0.093227,260.052429,13.247703,0.932269,-155.683334,0.094233,0.000000
93.710007,59.785141,-155.638855,0.027887,0.003693,0.093790,265.937592,13.547506,0.937905,-155.638855,0.094736,0.000000
94.010002,60.533607,-155.638855,0.027896,0.003707,0.094155,269.266937,13.717112,0.941546,-155.638855,0.095239,0.000000
94.310005,62.068527,-155.683334,0.027891,0.003732,0.094788,276.094604,14.064929,0.947878,-155.683334,0.095733,0.000000
94.610008,63.142082,-155.683334,0.027904,0.003751,0.095282,280.869995,14.308200,0.952821,-155.683334,0.096236,0.000000
94.910004,63.884583,-155.772293,0.027913,0.003766,0.095664,284.172821,14.476453,0.956636,-155.772293,0.096739,0.000000
95.210007,64.746628,-155.727814,0.027921,0.003782,0.096071,288.007385,14.671796,0.960712,-155.727814,0.097233,0.000000
95.510002,66.145630,-155.772293,0.027934,0.003807,0.096687,294.230469,14.988814,0.966870,-155.772293,0.097736,0.000000
95.810005,67.087372,-155.816772,0.027943,0.003821,0.097042,298.419525,15.202215,0.970424,-155.816772,0.098239,0.000000
96.110008,66.854263,-155.772293,0.027939,0.003815,0.096904,297.382629,15.149393,0.969039,-155.772293,0.097173,0.000000
96.410004,66.061111,-155.816772,0.027947,0.003813,0.096860,293.854492,14.969662,0.968604,-155.816772,0.096904,0.000000
96.710007,65.384506,-155.816772,0.027965,0.003812,0.096817,290.844818,14.816340,0.968172,-155.816772,0.096904,0.000000
97.010002,64.839722,-155.816772,0.027965,0.003811,0.096800,288.421478,14.692890,0.967998,-155.816772,0.096904,0.000000
97.310005,64.361969,-155.772293,0.027977,0.003811,0.096791,286.296326,14.584630,0.967911,-155.772293,0.096904,0.000000
97.610008,63.924805,-155.772293,0.027977,0.003810,0.096782,284.351746,14.485568,0.967824,-155.772293,0.096904,0.000000
97.910004,63.547592,-155.816772,0.027982,0.003810,0.096774,282.673798,14.400090,0.967737,-155.816772,0.096904,0.000000
98.210007,63.203896,-155.816772,0.027982,0.003810,0.096774,281.144958,14.322208,0.967737,-155.816772,0.096904,0.000000
98.510002,62.891098,-155.816772,0.027986,0.003810,0.096774,279.753571,14.251327,0.967737,-155.816772,0.096904,0.000000
98.810005,62.604744,-155.816772,0.027973,0.003810,0.096765,278.479797,14.186438,0.967650,-155.816772,0.096904,0.000000
99.110008,62.357117,-155.816772,0.028012,0.003810,0.096765,277.378296,14.130325,0.967650,-155.816772,0.096904,0.000000
99.410004,62.108002,-155.816772,0.027990,0.003810,0.096765,276.270203,14.073874,0.967650,-155.816772,0.096904,0.000000
99.710007,61.878990,-155.816772,0.027982,0.003810,0.096765,275.251495,14.021979,0.967650,-155.816772,0.096904,0.000000
100.010002,61.680519,-155.905731,0.027999,0.003810,0.096765,274.368652,13.977006,0.967650,-155.905731,0.096904,0.000000
100.310005,61.504013,-155.861252,0.027999,0.003810,0.096765,273.583527,13.937008,0.967650,-155.861252,0.096904,0.000000
100.610008,61.308517,-155.950211,0.028016,0.003810,0.096765,272.713898,13.892708,0.967650,-155.950211,0.096904,0.000000
100.910004,61.140579,-155.905731,0.028003,0.003809,0.096756,271.966888,13.854653,0.967563,-155.905731,0.096904,0.000000
101.210007,60.988647,-155.905731,0.027995,0.003809,0.096756,271.291046,13.820226,0.967563,-155.905731,0.096904,0.000000
101.510002,60.837463,-155.905731,0.027990,0.003809,0.096756,270.618561,13.785966,0.967563,-155.905731,0.096904,0.000000
101.810005,60.700806,-155.950211,0.027990,0.003809,0.096756,270.010681,13.754999,0.967563,-155.950211,0.096904,0.000000
102.110008,60.569359,-155.950211,0.028003,0.003809,0.096756,269.425964,13.725212,0.967563,-155.950211,0.096904,0.000000
102.410004,60.419662,-155.950211,0.027999,0.003809,0.096756,268.760071,13.691291,0.967563,-155.950211,0.096904,0.000000
102.710007,60.317635,-155.950211,0.027999,0.003809,0.096756,268.306244,13.668171,0.967563,-155.950211,0.096904,0.000000
103.010002,60.191772,-155.905731,0.027999,0.003809,0.096756,267.746368,13.639650,0.967563,-155.905731,0.096904,0.000000
103.310005,60.079689,-155.950211,0.027999,0.003809,0.096756,267.247803,13.614252,0.967563,-155.950211,0.096904,0.000000
103.610008,59.986969,-155.994690,0.028025,0.003809,0.096756,266.835358,13.593242,0.967563,-155.994690,0.096904,0.000000
103.910004,59.878609,-155.994690,0.027999,0.003809,0.096756,266.353363,13.568687,0.967563,-155.994690,0.096904,0.000000
104.210007,59.764664,-156.039169,0.028003,0.003809,0.096756,265.846497,13.542866,0.967563,-156.039169,0.096904,0.000000
104.510002,59.670822,-156.039169,0.028003,0.003809,0.096756,265.429077,13.521602,0.967563,-156.039169,0.096904,0.000000
104.810005,59.595230,-155.950211,0.028016,0.003809,0.096756,265.092834,13.504472,0.967563,-155.950211,0.096904,0.000000
105.110008,59.496178,-155.994690,0.028021,0.003809,0.096756,264.652222,13.482026,0.967563,-155.994690,0.096904,0.000000
105.410004,59.397873,-156.083664,0.028008,0.003809,0.096756,264.214935,13.459750,0.967563,-156.083664,0.096904,0.000000
105.710007,59.343880,-156.039169,0.028021,0.003809,0.096756,263.974762,13.447515,0.967563,-156.039169,0.096904,0.000000
106.010002,59.253395,-156.083664,0.028025,0.003809,0.096756,263.572266,13.427011,0.967563,-156.083664,0.096904,0.000000
106.310005,59.178177,-156.083664,0.028038,0.003809,0.096756,263.237671,13.409966,0.967563,-156.083664,0.096904,0.000000
106.610008,59.095131,-155.994690,0.028008,0.003809,0.096756,262.868286,13.391148,0.967563,-155.994690,0.096904,0.000000
106.910004,59.017685,-156.039169,0.028029,0.003809,0.096756,262.523773,13.373598,0.967563,-156.039169,0.096904,0.000000
107.210007,58.947304,-156.128143,0.028038,0.003809,0.096756,262.210693,13.357650,0.967563,-156.128143,0.096904,0.000000
107.510002,58.888092,-156.128143,0.028025,0.003809,0.096756,261.947327,13.344233,0.967563,-156.128143,0.096904,0.000000
107.810005,58.809898,-156.128143,0.028033,0.003809,0.096748,261.599487,13.326513,0.967476,-156.128143,0.096904,0.000000
108.110008,58.751808,-156.128143,0.028008,0.003809,0.096748,261.341095,13.313351,0.967476,-156.128143,0.096904,0.000000
108.410004,58.695206,-156.128143,0.028033,0.003809,0.096748,261.089325,13.300524,0.967476,-156.128143,0.096904,0.000000
108.710007,58.606583,-156.128143,0.028021,0.003809,0.096748,260.695099,13.280441,0.967476,-156.128143,0.096904,0.000000
109.010002,58.551102,-156.172623,0.028033,0.003809,0.096748,260.448303,13.267869,0.967476,-156.172623,0.096904,0.000000
109.310005,58.501572,-156.172623,0.028029,0.003809,0.096748,260.227997,13.256645,0.967476,-156.172623,0.096904,0.000000
109.610008,58.447205,-156.217102,0.028038,0.003809,0.096748,259.986145,13.244327,0.967476,-156.217102,0.096904,0.000000
109.910004,58.382042,-156.172623,0.028016,0.003809,0.096748,259.696289,13.229560,0.967476,-156.172623,0.096904,0.000000
110.210007,58.346291,-156.217102,0.028008,0.003809,0.096748,259.537262,13.221458,0.967476,-156.217102,0.096904,0.000000
110.510002,58.293045,-156.261581,0.028029,0.003809,0.096748,259.300415,13.209393,0.967476,-156.261581,0.096904,0.000000
110.810005,58.216339,-156.217102,0.028029,0.003809,0.096748,258.959198,13.192011,0.967476,-156.217102,0.096904,0.000000
111.110008,58.179840,-156.217102,0.027999,0.003809,0.096748,258.796844,13.183741,0.967476,-156.217102,0.096904,0.000000
111.410004,58.131432,-156.261581,0.028012,0.003809,0.096748,258.581512,13.172771,0.967476,-156.261581,0.096904,0.000000
111.710007,58.079300,-156.172623,0.028021,0.003809,0.096748,258.349640,13.160957,0.967476,-156.172623,0.096904,0.000000
112.010002,58.023071,-156.261581,0.028003,0.003809,0.096748,258.099518,13.148216,0.967476,-156.261581,0.096904,0.000000
112.310005,57.991798,-156.172623,0.028025,0.003809,0.096748,257.960388,13.141129,0.967476,-156.172623,0.096904,0.000000
112.610008,57.940407,-156.261581,0.028033,0.003809,0.096748,257.731812,13.129483,0.967476,-156.261581,0.096904,0.000000
112.910004,57.878967,-156.261581,0.028025,0.003809,0.096748,257.458496,13.115561,0.967476,-156.261581,0.096904,0.000000
113.210007,57.840614,-156.261581,0.028012,0.003809,0.096748,257.287903,13.106871,0.967476,-156.261581,0.096904,0.000000
113.510002,57.801514,-156.261581,0.028029,0.003809,0.096748,257.113983,13.098010,0.967476,-156.261581,0.096904,0.000000
113.810005,57.754593,-156.306061,0.028025,0.003809,0.096748,256.905273,13.087378,0.967476,-156.306061,0.096904,0.000000
114.110008,57.720711,-156.350540,0.028029,0.003809,0.096748,256.754547,13.079700,0.967476,-156.350540,0.096904,0.000000
114.410004,57.666344,-156.306061,0.028038,0.003809,0.096748,256.512695,13.067381,0.967476,-156.306061,0.096904,0.000000
114.710007,57.633575,-156.306061,0.028025,0.003809,0.096748,256.366943,13.059955,0.967476,-156.306061,0.096904,0.000000
115.010002,57.599686,-156.350540,0.028038,0.003809,0.096748,256.216187,13.052275,0.967476,-156.350540,0.096904,0.000000
115.310005,57.539734,-156.350540,0.028008,0.003809,0.096748,255.949524,13.038691,0.967476,-156.350540,0.096904,0.000000
115.610008,57.495796,-156.306061,0.028012,0.003809,0.096748,255.754074,13.028734,0.967476,-156.306061,0.096904,0.000000
115.910004,57.468239,-156.350540,0.028016,0.003809,0.096748,255.631500,13.022489,0.967476,-156.350540,0.096904,0.000000
116.210007,57.418343,-156.350540,0.028012,0.003809,0.096748,255.409546,13.011183,0.967476,-156.350540,0.096904,0.000000
116.510002,57.375519,-156.350540,0.028029,0.003809,0.096748,255.219055,13.001479,0.967476,-156.350540,0.096904,0.000000
116.810005,57.347961,-156.395020,0.028016,0.003809,0.096748,255.096466,12.995234,0.967476,-156.395020,0.096904,0.000000
117.110008,57.319290,-156.395020,0.028046,0.003809,0.096748,254.968933,12.988737,0.967476,-156.395020,0.096904,0.000000
117.410004,57.276466,-156.350540,0.028051,0.003809,0.096748,254.778442,12.979033,0.967476,-156.350540,0.096904,0.000000
117.710007,57.239601,-156.439499,0.028021,0.003809,0.096748,254.614456,12.970679,0.967476,-156.439499,0.096904,0.000000
118.010002,57.212791,-156.439499,0.028029,0.003809,0.096748,254.495209,12.964604,0.967476,-156.439499,0.096904,0.000000
118.310005,57.186729,-156.439499,0.028021,0.003809,0.096748,254.379272,12.958698,0.967476,-156.439499,0.096904,0.000000
118.610008,57.139061,-156.439499,0.028025,0.003809,0.096748,254.167236,12.947896,0.967476,-156.439499,0.096904,0.000000
118.910004,57.110016,-156.395020,0.028029,0.003809,0.096748,254.038040,12.941315,0.967476,-156.395020,0.096904,0.000000
119.210007,57.073524,-156.483978,0.028038,0.003809,0.096748,253.875717,12.933045,0.967476,-156.483978,0.096904,0.000000
119.510002,57.048950,-156.483978,0.028021,0.003809,0.096748,253.766403,12.927477,0.967476,-156.483978,0.096904,0.000000
119.810005,57.013199,-156.439499,0.028016,0.003809,0.096748,253.607376,12.919375,0.967476,-156.439499,0.096904,0.000000
120.110008,56.979317,-156.483978,0.028046,0.003809,0.096748,253.456665,12.911697,0.967476,-156.483978,0.096904,0.000000
120.410004,56.940956,-156.439499,0.028021,0.003809,0.096748,253.286026,12.903006,0.967476,-156.439499,0.096904,0.000000
120.710007,56.923088,-156.528473,0.028029,0.003809,0.096748,253.206543,12.898956,0.967476,-156.528473,0.096904,0.000000
121.010002,56.907822,-156.572952,0.028021,0.003809,0.096748,253.138626,12.895496,0.967476,-156.572952,0.096904,0.000000
121.310005,56.854195,-156.528473,0.028008,0.003809,0.096748,252.900085,12.883345,0.967476,-156.528473,0.096904,0.000000
121.610008,56.833344,-156.572952,0.028038,0.003809,0.096748,252.807343,12.878619,0.967476,-156.572952,0.096904,0.000000
121.910004,56.815468,-156.572952,0.028021,0.003809,0.096748,252.727829,12.874569,0.967476,-156.572952,0.096904,0.000000
122.210007,56.783447,-156.572952,0.028029,0.003809,0.096748,252.585388,12.867313,0.967476,-156.572952,0.096904,0.000000
122.510002,56.748444,-156.572952,0.028025,0.003809,0.096748,252.429687,12.859382,0.967476,-156.572952,0.096904,0.000000
122.810005,56.729828,-156.572952,0.028021,0.003809,0.096748,252.346878,12.855163,0.967476,-156.572952,0.096904,0.000000
123.110008,56.710091,-156.617432,0.028033,0.003809,0.096748,252.259079,12.850690,0.967476,-156.617432,0.096904,0.000000
123.410004,56.678436,-156.572952,0.028021,0.003809,0.096748,252.118271,12.843517,0.967476,-156.572952,0.096904,0.000000
123.710007,56.644920,-156.572952,0.028038,0.003809,0.096748,251.969193,12.835922,0.967476,-156.572952,0.096904,0.000000
124.010002,56.631149,-156.572952,0.028033,0.003809,0.096748,251.907928,12.832802,0.967476,-156.572952,0.096904,0.000000
124.310005,56.598381,-156.572952,0.028025,0.003809,0.096748,251.762177,12.825377,0.967476,-156.572952,0.096904,0.000000
124.610008,56.576408,-156.617432,0.028021,0.003809,0.096748,251.664429,12.820397,0.967476,-156.617432,0.096904,0.000000
124.910004,56.538422,-156.617432,0.027999,0.003809,0.096748,251.495453,12.811790,0.967476,-156.617432,0.096904,0.000000
125.210007,56.524277,-156.617432,0.028042,0.003809,0.096748,251.432541,12.808584,0.967476,-156.617432,0.096904,0.000000
125.510010,56.488152,-156.617432,0.027995,0.003809,0.096748,251.271851,12.800398,0.967476,-156.617432,0.096904,0.000000
125.810005,56.467300,-156.706390,0.028025,0.003809,0.096748,251.179092,12.795673,0.967476,-156.706390,0.096904,0.000000
126.110008,56.444962,-156.661911,0.028046,0.003809,0.096748,251.079727,12.790610,0.967476,-156.661911,0.096904,0.000000
126.410004,56.424477,-156.661911,0.028033,0.003809,0.096748,250.988602,12.785969,0.967476,-156.661911,0.096904,0.000000
126.500008,56.411819,-156.661911,0.028038,0.003809,0.096748,250.932312,12.783101,0.967476,-156.661911,0.096904,0.000000