File: Data/compression sample NH 10,12,15/AutoNoheating-10-2-4-240201_02012024_191648.csv
Time (sec),S:Load (lbs),S:HL1 (DIM),S:LVDT (in),S:Position (in),Ch:Position (mm),Ch:Load (N),Ch:Stress (MPa),Ch:Strain (mm/mm),Ch:HL1 (DIM),Set Point (),Cycles ()
0.110000,-0.015266,-252.963165,-0.000009,-0.000000,-0.000000,-0.067908,-0.003459,-0.000000,-252.963165,0.000208,0.000000
0.360000,-0.042824,-252.963165,-0.000013,0.000007,0.000182,-0.190490,-0.009704,0.001821,-252.963165,0.000746,0.000000
0.610000,-0.016380,-252.963165,0.000030,0.000152,0.003850,-0.072863,-0.003712,0.038504,-252.963165,0.004909,0.000000
0.860000,0.002983,-252.874207,0.000155,0.000313,0.007961,0.013269,0.000676,0.079611,-252.874207,0.009071,0.000000
1.110000,0.040962,-253.007645,0.000336,0.000483,0.012263,0.182209,0.009282,0.122627,-253.007645,0.013234,0.000000
1.360000,0.068893,-252.963165,0.000517,0.000647,0.016443,0.306453,0.015611,0.164427,-252.963165,0.017397,0.000000
1.610000,0.354874,-252.963165,0.000668,0.000806,0.020466,1.578557,0.080416,0.204664,-252.963165,0.021559,0.000000
1.860000,0.670273,-252.963165,0.000750,0.000007,0.000173,2.981523,0.151886,0.001733,-252.963165,0.000295,0.000000
2.110000,0.625961,-253.007645,0.000776,0.000006,0.000165,2.784415,0.141845,0.001646,-253.007645,0.000295,0.000000
2.360000,0.629311,-253.007645,0.000785,0.000006,0.000165,2.799313,0.142604,0.001646,-253.007645,0.000512,0.000000
2.610000,0.579041,-253.007645,0.000750,0.000006,0.000165,2.575701,0.131212,0.001646,-253.007645,0.000928,0.000000
2.860000,0.638618,-253.007645,0.000789,0.000023,0.000581,2.840717,0.144713,0.005810,-253.007645,0.001344,0.000000
3.110000,0.735435,-253.007645,0.000789,0.000036,0.000919,3.271380,0.166652,0.009194,-253.007645,0.001760,0.000000
3.360000,0.785706,-252.963165,0.000819,0.000047,0.001197,3.494993,0.178043,0.011968,-252.963165,0.002177,0.000000
3.610000,0.939873,-253.007645,0.000789,0.000066,0.001682,4.180763,0.212978,0.016824,-253.007645,0.002602,0.000000
3.860000,1.001686,-253.052124,0.000862,0.000081,0.002064,4.455722,0.226985,0.020639,-253.052124,0.003018,0.000000
4.110000,1.097008,-253.052124,0.000815,0.000098,0.002480,4.879734,0.248586,0.024802,-253.052124,0.003434,0.000000
4.360000,1.166649,-253.007645,0.000867,0.000116,0.002957,5.189513,0.264366,0.029571,-253.007645,0.003850,0.000000
4.610000,1.275749,-253.052124,0.000854,0.000136,0.003460,5.674816,0.289089,0.034602,-253.052124,0.004267,0.000000
4.860000,1.302933,-253.096619,0.000918,0.000152,0.003850,5.795734,0.295249,0.038504,-253.096619,0.004683,0.000000
5.110000,1.386719,-253.052124,0.000867,0.000167,0.004249,6.168433,0.314235,0.042493,-253.052124,0.005099,0.000000
5.360000,1.480186,-253.052124,0.000888,0.000182,0.004614,6.584198,0.335415,0.046138,-253.052124,0.005515,0.000000
5.610000,1.604927,-253.096619,0.000936,0.000201,0.005108,7.139072,0.363682,0.051081,-253.096619,0.005932,0.000000
5.860000,1.665253,-253.096619,0.000931,0.000215,0.005472,7.407414,0.377352,0.054722,-253.096619,0.006348,0.000000
6.110000,1.701370,-253.096619,0.000953,0.000227,0.005767,7.568073,0.385536,0.057670,-253.096619,0.006764,0.000000
6.360000,1.841385,-253.096619,0.000979,0.000248,0.006287,8.190889,0.417264,0.062875,-253.096619,0.007181,0.000000
6.610000,1.915489,-253.141098,0.001000,0.000265,0.006730,8.520521,0.434056,0.067295,-253.141098,0.007597,0.000000
6.860000,1.938576,-253.096619,0.001000,0.000281,0.007137,8.623216,0.439288,0.071372,-253.096619,0.008013,0.000000
7.110000,2.000763,-253.096619,0.001061,0.000294,0.007458,8.899838,0.453379,0.074581,-253.096619,0.008429,0.000000
7.360000,2.162369,-253.096619,0.001052,0.000316,0.008022,9.618697,0.490000,0.080217,-253.096619,0.008846,0.000000
7.610000,2.249130,-253.096619,0.001069,0.000332,0.008421,10.004631,0.509660,0.084206,-253.096619,0.009262,0.000000
7.860001,2.260674,-253.185577,0.001095,0.000341,0.008672,10.055978,0.512276,0.086723,-253.185577,0.009678,0.000000
8.110001,2.367172,-253.141098,0.001104,0.000364,0.009236,10.529708,0.536409,0.092359,-253.141098,0.010094,0.000000
8.360001,2.446861,-253.096619,0.001151,0.000381,0.009687,10.884183,0.554467,0.096871,-253.096619,0.010511,0.000000
8.610001,2.502342,-253.141098,0.001160,0.000399,0.010138,11.130974,0.567039,0.101378,-253.141098,0.010936,0.000000
8.860001,2.528412,-253.141098,0.001151,0.000414,0.010511,11.246938,0.572946,0.105107,-253.141098,0.011352,0.000000
9.110001,2.592461,-253.230057,0.001138,0.000430,0.010927,11.531841,0.587460,0.109270,-253.230057,0.011768,0.000000
9.360001,2.739922,-253.230057,0.001168,0.000449,0.011404,12.187779,0.620875,0.114039,-253.230057,0.012184,0.000000
9.610001,2.723160,-253.141098,0.001203,0.000457,0.011612,12.113219,0.617077,0.116121,-253.141098,0.012601,0.000000
9.860001,2.814018,-253.230057,0.001181,0.000474,0.012028,12.517379,0.637666,0.120284,-253.230057,0.013017,0.000000
10.110001,2.852005,-253.185577,0.001212,0.000488,0.012393,12.686352,0.646274,0.123925,-253.185577,0.013433,0.000000
10.360001,3.061279,-253.230057,0.001259,0.000515,0.013069,13.617250,0.693696,0.130692,-253.230057,0.013850,0.000000
10.610001,3.025528,-253.185577,0.001250,0.000525,0.013347,13.458220,0.685594,0.133467,-253.185577,0.014266,0.000000
10.860001,3.034096,-253.185577,0.001289,0.000542,0.013763,13.496332,0.687536,0.137630,-253.185577,0.014682,0.000000
11.110001,3.070587,-253.230057,0.001276,0.000556,0.014118,13.658654,0.695805,0.141184,-253.230057,0.015098,0.000000
11.360001,3.240387,-253.230057,0.001289,0.000574,0.014587,14.413961,0.734282,0.145866,-253.230057,0.015515,0.000000
11.610001,3.251183,-253.274536,0.001311,0.000588,0.014934,14.461983,0.736728,0.149337,-253.274536,0.015931,0.000000
11.860001,3.317841,-253.230057,0.001362,0.000603,0.015306,14.758492,0.751833,0.153065,-253.230057,0.016347,0.000000
12.110001,3.466042,-253.230057,0.001362,0.000624,0.015861,15.417723,0.785416,0.158614,-253.230057,0.016763,0.000000
12.360001,3.494347,-253.274536,0.001367,0.000642,0.016295,15.543630,0.791830,0.162951,-253.274536,0.017180,0.000000
12.610001,3.463066,-253.230057,0.001384,0.000655,0.016633,15.404488,0.784742,0.166335,-253.230057,0.017596,0.000000
12.860001,3.561745,-253.230057,0.001388,0.000676,0.017171,15.843431,0.807103,0.171709,-253.230057,0.018012,0.000000
13.110001,3.600845,-253.230057,0.001406,0.000691,0.017552,16.017361,0.815963,0.175525,-253.230057,0.018429,0.000000
13.360001,3.701385,-253.274536,0.001436,0.000709,0.018012,16.464584,0.838746,0.180123,-253.274536,0.018845,0.000000
13.610001,3.658562,-253.274536,0.001492,0.000719,0.018272,16.274096,0.829042,0.182723,-253.274536,0.019261,0.000000
13.860001,3.713303,-253.230057,0.001483,0.000735,0.018663,16.517595,0.841446,0.186626,-253.230057,0.019686,0.000000
14.110001,3.858528,-253.363495,0.001440,0.000757,0.019227,17.163589,0.874355,0.192265,-253.363495,0.020102,0.000000
14.360001,3.915123,-253.274536,0.001483,0.000776,0.019703,17.415337,0.887180,0.197034,-253.274536,0.020519,0.000000
14.610001,3.902466,-253.319016,0.001526,0.000792,0.020128,17.359035,0.884311,0.201284,-253.319016,0.020935,0.000000
14.860001,3.896133,-253.319016,0.001561,0.000806,0.020466,17.330868,0.882876,0.204664,-253.319016,0.021351,0.000000
15.110001,3.975822,-253.274536,0.001544,0.000825,0.020952,17.685341,0.900934,0.209520,-253.274536,0.021767,0.000000
15.360001,3.984756,-253.274536,0.001544,0.000838,0.021273,17.725082,0.902959,0.212730,-253.274536,0.022184,0.000000
15.610001,4.053276,-253.363495,0.001548,0.000854,0.021689,18.029873,0.918485,0.216893,-253.363495,0.022600,0.000000
15.860001,4.096100,-253.319016,0.001556,0.000873,0.022184,18.220362,0.928190,0.221836,-253.319016,0.023016,0.000000
16.110001,4.220100,-253.319016,0.001582,0.000895,0.022739,18.771944,0.956288,0.227385,-253.319016,0.023432,0.000000
16.360001,4.149345,-253.319016,0.001625,0.000909,0.023086,18.457211,0.940255,0.230856,-253.319016,0.023849,0.000000
16.610001,4.100937,-253.363495,0.001630,0.000925,0.023502,18.241879,0.929286,0.235019,-253.363495,0.024265,0.000000
16.860001,4.124771,-253.319016,0.001651,0.000939,0.023840,18.347898,0.934686,0.238399,-253.319016,0.024681,0.000000
17.110001,4.246162,-253.363495,0.001673,0.000960,0.024378,18.887875,0.962194,0.243778,-253.363495,0.025098,0.000000
17.360001,4.252495,-253.319016,0.001673,0.000975,0.024759,18.916042,0.963629,0.247593,-253.319016,0.025514,0.000000
17.610001,4.166847,-253.363495,0.001673,0.000983,0.024967,18.535063,0.944221,0.249674,-253.363495,0.025930,0.000000
17.860001,4.364952,-253.363495,0.001707,0.001009,0.025635,19.416277,0.989112,0.256351,-253.363495,0.026346,0.000000
18.110001,4.385063,-253.452454,0.001720,0.001026,0.026069,19.505735,0.993670,0.260688,-253.452454,0.026763,0.000000
18.360001,4.308723,-253.363495,0.001755,0.001041,0.026450,19.166159,0.976371,0.264504,-253.363495,0.027179,0.000000
18.610001,4.318779,-253.407974,0.001729,0.001055,0.026797,19.210888,0.978649,0.267974,-253.407974,0.027595,0.000000
18.860001,4.345963,-253.363495,0.001794,0.001071,0.027213,19.331806,0.984809,0.272134,-253.363495,0.028020,0.000000
19.110001,4.404427,-253.407974,0.001785,0.001089,0.027665,19.591867,0.998057,0.276646,-253.407974,0.028436,0.000000
19.360001,4.392136,-253.407974,0.001794,0.001102,0.028003,19.537195,0.995272,0.280025,-253.407974,0.028853,0.000000
19.610001,4.369049,-253.363495,0.001807,0.001115,0.028324,19.434502,0.990041,0.283235,-253.363495,0.029269,0.000000
19.860001,4.482620,-253.452454,0.001863,0.001137,0.028887,19.939692,1.015776,0.288875,-253.452454,0.029685,0.000000
20.110001,4.500496,-253.452454,0.001837,0.001155,0.029330,20.019205,1.019827,0.293295,-253.452454,0.030101,0.000000
20.360001,4.506828,-253.407974,0.001876,0.001172,0.029781,20.047373,1.021262,0.297807,-253.407974,0.030518,0.000000
20.610001,4.513527,-253.407974,0.001863,0.001187,0.030153,20.077171,1.022780,0.301535,-253.407974,0.030934,0.000000
20.860001,4.550392,-253.452454,0.001901,0.001205,0.030604,20.241156,1.031134,0.306043,-253.452454,0.031350,0.000000
21.110001,4.536247,-253.496933,0.001880,0.001218,0.030943,20.178236,1.027928,0.309427,-253.496933,0.031767,0.000000
21.360001,4.504219,-253.452454,0.001923,0.001230,0.031246,20.035767,1.020671,0.312462,-253.452454,0.032183,0.000000
21.610001,4.591354,-253.452454,0.001914,0.001251,0.031775,20.423365,1.040416,0.317750,-253.452454,0.032599,0.000000
21.860001,4.649071,-253.496933,0.001940,0.001268,0.032209,20.680099,1.053494,0.322087,-253.496933,0.033015,0.000000
22.110001,4.619652,-253.541428,0.001979,0.001284,0.032625,20.549238,1.046828,0.326250,-253.541428,0.033432,0.000000
22.360001,4.632690,-253.452454,0.001957,0.001302,0.033059,20.607237,1.049783,0.330588,-253.452454,0.033848,0.000000
22.610001,4.609970,-253.496933,0.001996,0.001314,0.033379,20.506170,1.044634,0.333794,-253.496933,0.034264,0.000000
22.860001,4.716469,-253.496933,0.002035,0.001334,0.033891,20.979900,1.068767,0.338911,-253.496933,0.034680,0.000000
23.110001,4.642372,-253.541428,0.002022,0.001347,0.034221,20.650303,1.051977,0.342207,-253.541428,0.035097,0.000000
23.360001,4.570503,-253.541428,0.002013,0.001358,0.034489,20.330614,1.035691,0.344895,-253.541428,0.035513,0.000000
23.610001,4.763016,-253.541428,0.002091,0.001381,0.035070,21.186953,1.079315,0.350705,-253.541428,0.035929,0.000000
23.860001,4.892975,-253.496933,0.002104,0.001404,0.035660,21.765039,1.108764,0.356601,-253.496933,0.036354,0.000000
24.110001,4.790199,-253.541428,0.002108,0.001417,0.035981,21.307871,1.085475,0.359811,-253.541428,0.036770,0.000000
24.360001,4.771584,-253.585907,0.002113,0.001432,0.036363,21.225063,1.081256,0.363626,-253.585907,0.037187,0.000000
24.610001,4.729134,-253.541428,0.002104,0.001444,0.036684,21.036238,1.071637,0.366836,-253.541428,0.037603,0.000000
24.860001,4.877708,-253.630386,0.002160,0.001464,0.037187,21.697130,1.105304,0.371866,-253.630386,0.038019,0.000000
25.110001,4.799881,-253.585907,0.002143,0.001474,0.037438,21.350937,1.087669,0.374383,-253.585907,0.038436,0.000000
25.360001,4.880692,-253.541428,0.002156,0.001492,0.037906,21.710400,1.105980,0.379065,-253.541428,0.038852,0.000000
25.610001,4.935799,-253.585907,0.002182,0.001510,0.038357,21.955528,1.118468,0.383573,-253.585907,0.039268,0.000000
25.860001,5.028893,-253.630386,0.002186,0.001532,0.038913,22.369631,1.139563,0.389125,-253.630386,0.039684,0.000000
26.110001,4.958511,-253.585907,0.002199,0.001547,0.039303,22.056561,1.123615,0.393027,-253.585907,0.040101,0.000000
26.360001,4.881058,-253.585907,0.002203,0.001559,0.039589,21.712029,1.106063,0.395889,-253.585907,0.040517,0.000000
26.610001,4.990540,-253.630386,0.002255,0.001577,0.040066,22.199028,1.130872,0.400658,-253.630386,0.040933,0.000000
26.860001,5.084373,-253.585907,0.002272,0.001597,0.040551,22.616423,1.152135,0.405514,-253.585907,0.041349,0.000000
27.110001,5.040436,-253.630386,0.002276,0.001610,0.040890,22.420979,1.142179,0.408897,-253.630386,0.041766,0.000000
27.360001,4.949203,-253.674866,0.002255,0.001620,0.041158,22.015156,1.121505,0.411585,-253.674866,0.042182,0.000000
27.610001,5.063148,-253.585907,0.002315,0.001640,0.041644,22.522009,1.147326,0.416441,-253.585907,0.042598,0.000000
27.860001,5.123100,-253.630386,0.002328,0.001660,0.042156,22.788689,1.160911,0.421558,-253.630386,0.043014,0.000000
28.110001,5.141724,-253.674866,0.002337,0.001677,0.042590,22.871529,1.165131,0.425895,-253.674866,0.043431,0.000000
28.360001,5.071716,-253.674866,0.002341,0.001690,0.042919,22.560122,1.149267,0.429188,-253.674866,0.043847,0.000000
28.610001,5.006180,-253.674866,0.002320,0.001699,0.043153,22.268600,1.134417,0.431531,-253.674866,0.044263,0.000000
28.860001,5.298119,-253.674866,0.002367,0.001726,0.043847,23.567209,1.200571,0.438469,-253.674866,0.044680,0.000000
29.110001,5.261253,-253.674866,0.002389,0.001740,0.044185,23.403223,1.192217,0.441852,-253.674866,0.045104,0.000000
29.360001,5.217682,-253.674866,0.002410,0.001752,0.044497,23.209408,1.182344,0.444975,-253.674866,0.045521,0.000000
29.610001,5.380409,-253.719345,0.002389,0.001775,0.045087,23.933256,1.219218,0.450872,-253.719345,0.045937,0.000000
29.860001,5.343544,-253.674866,0.002449,0.001791,0.045503,23.769270,1.210864,0.455031,-253.674866,0.046353,0.000000
30.110001,5.314873,-253.630386,0.002427,0.001808,0.045928,23.641735,1.204367,0.459282,-253.630386,0.046770,0.000000
30.360001,5.272049,-253.674866,0.002436,0.001821,0.046249,23.451244,1.194663,0.462491,-253.674866,0.047186,0.000000
30.610001,5.382645,-253.674866,0.002453,0.001840,0.046743,23.943199,1.219725,0.467435,-253.674866,0.047602,0.000000
30.860001,5.390091,-253.763824,0.002466,0.001855,0.047108,23.976322,1.221412,0.471076,-253.763824,0.048018,0.000000
31.110001,5.410202,-253.763824,0.002501,0.001870,0.047489,24.065781,1.225969,0.474891,-253.763824,0.048435,0.000000
31.360001,5.368866,-253.763824,0.002509,0.001881,0.047784,23.881908,1.216602,0.477843,-253.763824,0.048851,0.000000
31.610001,5.674957,-253.674866,0.002505,0.001910,0.048513,25.243471,1.285964,0.485125,-253.674866,0.049267,0.000000
31.860001,5.552818,-253.719345,0.002527,0.001921,0.048799,24.700169,1.258287,0.487987,-253.719345,0.049683,0.000000
32.110001,5.545746,-253.763824,0.002578,0.001937,0.049206,24.668709,1.256684,0.492063,-253.763824,0.050100,0.000000
32.360001,5.550217,-253.808304,0.002587,0.001953,0.049605,24.688597,1.257697,0.496052,-253.808304,0.050516,0.000000
32.610001,5.633995,-253.763824,0.002583,0.001970,0.050048,25.061262,1.276682,0.500477,-253.763824,0.050932,0.000000
32.860001,5.547981,-253.808304,0.002604,0.001982,0.050334,24.678654,1.257190,0.503338,-253.808304,0.051349,0.000000
33.110001,5.705864,-253.808304,0.002626,0.001999,0.050785,25.380951,1.292967,0.507846,-253.808304,0.051764,0.000000
33.360001,5.767303,-253.763824,0.002608,0.002018,0.051262,25.654247,1.306890,0.512619,-253.763824,0.052181,0.000000
33.610001,5.865982,-253.763824,0.002613,0.002039,0.051791,26.093191,1.329250,0.517906,-253.763824,0.052597,0.000000
33.860001,5.754272,-253.852783,0.002677,0.002051,0.052103,25.596283,1.303937,0.521029,-253.852783,0.053014,0.000000
34.110001,5.762466,-253.852783,0.002677,0.002068,0.052528,25.632730,1.305794,0.525279,-253.852783,0.053439,0.000000
34.360001,5.809013,-253.808304,0.002725,0.002084,0.052936,25.839783,1.316341,0.529355,-253.808304,0.053855,0.000000
34.610001,5.766937,-253.763824,0.002699,0.002099,0.053326,25.652618,1.306807,0.533258,-253.763824,0.054271,0.000000
34.860001,5.850349,-253.763824,0.002712,0.002116,0.053751,26.023653,1.325708,0.537508,-253.763824,0.054687,0.000000
35.110001,5.873436,-253.852783,0.002759,0.002130,0.054098,26.126348,1.330940,0.540975,-253.852783,0.055104,0.000000
35.360001,6.027596,-253.763824,0.002746,0.002151,0.054644,26.812084,1.365873,0.546440,-253.763824,0.055520,0.000000
35.610001,6.011208,-253.852783,0.002777,0.002165,0.054999,26.739187,1.362159,0.549994,-253.852783,0.055936,0.000000
35.860001,6.085312,-253.941757,0.002790,0.002186,0.055529,27.068819,1.378951,0.555286,-253.941757,0.056352,0.000000
36.110001,6.091644,-253.852783,0.002790,0.002202,0.055936,27.096987,1.380386,0.559362,-253.852783,0.056769,0.000000
36.360001,6.153458,-253.808304,0.002807,0.002220,0.056396,27.371946,1.394393,0.563957,-253.808304,0.057185,0.000000
36.610001,6.126648,-253.808304,0.002833,0.002233,0.056708,27.252691,1.388318,0.567079,-253.808304,0.057601,0.000000
36.860001,6.215645,-253.897263,0.002824,0.002252,0.057194,27.648569,1.408485,0.571935,-253.897263,0.058018,0.000000
37.110001,6.231285,-253.808304,0.002880,0.002266,0.057558,27.718140,1.412029,0.575577,-253.808304,0.058433,0.000000
37.360001,6.404060,-253.941757,0.002850,0.002289,0.058139,28.486683,1.451181,0.581386,-253.941757,0.058850,0.000000
37.610001,6.388428,-253.897263,0.002867,0.002305,0.058555,28.417147,1.447638,0.585550,-253.897263,0.059266,0.000000
37.860001,6.301659,-253.852783,0.002897,0.002320,0.058928,28.031178,1.427976,0.589278,-253.852783,0.059682,0.000000
38.110001,6.284904,-253.941757,0.002928,0.002335,0.059301,27.956652,1.424180,0.593010,-253.941757,0.060099,0.000000
38.360001,6.457314,-253.941757,0.002919,0.002353,0.059778,28.723566,1.463248,0.597779,-253.941757,0.060515,0.000000
38.610001,6.461411,-253.897263,0.002928,0.002370,0.060194,28.741789,1.464177,0.601942,-253.897263,0.060931,0.000000
38.860001,6.424919,-253.941757,0.002953,0.002381,0.060480,28.579468,1.455908,0.604804,-253.941757,0.061347,0.000000
39.110001,6.665100,-253.897263,0.002971,0.002404,0.061070,29.647846,1.510333,0.610700,-253.897263,0.061773,0.000000
39.360001,6.584663,-253.941757,0.002966,0.002418,0.061425,29.290045,1.492106,0.614254,-253.941757,0.062189,0.000000
39.610001,6.594719,-253.897263,0.002997,0.002434,0.061833,29.334774,1.494385,0.618331,-253.897263,0.062605,0.000000
39.860001,6.589134,-253.941757,0.003044,0.002449,0.062215,29.309933,1.493119,0.622146,-253.941757,0.063021,0.000000
40.110001,6.615944,-253.986237,0.003035,0.002463,0.062570,29.429188,1.499194,0.625704,-253.986237,0.063437,0.000000
40.360001,6.678505,-253.986237,0.003070,0.002478,0.062952,29.707474,1.513371,0.629519,-253.986237,0.063854,0.000000
40.610001,6.792076,-253.986237,0.003083,0.002498,0.063455,30.212664,1.539106,0.634549,-253.986237,0.064270,0.000000
40.860001,6.726540,-253.941757,0.003061,0.002510,0.063750,29.921143,1.524256,0.637497,-253.941757,0.064686,0.000000
41.110001,7.000229,-254.075195,0.003117,0.002532,0.064322,31.138573,1.586275,0.643220,-254.075195,0.065102,0.000000
41.360001,6.981987,-254.030716,0.003126,0.002549,0.064747,31.057428,1.582141,0.647471,-254.030716,0.065519,0.000000
41.610001,7.005447,-253.986237,0.003139,0.002565,0.065146,31.161787,1.587457,0.651460,-253.986237,0.065935,0.000000
41.860001,7.143227,-254.030716,0.003165,0.002583,0.065614,31.774658,1.618678,0.656142,-254.030716,0.066351,0.000000
42.110001,7.028908,-254.075195,0.003182,0.002595,0.065918,31.266144,1.592773,0.659177,-254.075195,0.066768,0.000000
42.360001,7.161095,-253.986237,0.003182,0.002614,0.066395,31.854139,1.622727,0.663946,-253.986237,0.067184,0.000000
42.610001,7.152534,-254.030716,0.003173,0.002627,0.066724,31.816063,1.620788,0.667243,-254.030716,0.067600,0.000000
42.860001,7.111198,-254.030716,0.003212,0.002639,0.067019,31.632191,1.611421,0.670191,-254.030716,0.068016,0.000000
43.110001,7.415802,-253.986237,0.003199,0.002664,0.067661,32.987133,1.680445,0.676611,-253.986237,0.068433,0.000000
43.360001,7.466812,-254.075195,0.003238,0.002679,0.068051,33.214039,1.692004,0.680513,-254.075195,0.068849,0.000000
43.610001,7.530861,-253.986237,0.003229,0.002697,0.068493,33.498943,1.706517,0.684934,-253.986237,0.069265,0.000000
43.860001,7.421387,-254.075195,0.003268,0.002708,0.068788,33.011978,1.681710,0.687882,-254.075195,0.069681,0.000000
44.110001,7.635872,-254.119675,0.003268,0.002728,0.069283,33.966053,1.730313,0.692825,-254.119675,0.070098,0.000000
44.360001,7.638847,-254.030716,0.003311,0.002741,0.069621,33.979290,1.730988,0.696209,-254.030716,0.070523,0.000000
44.610001,7.519691,-254.075195,0.003333,0.002751,0.069864,33.449257,1.703986,0.698639,-254.075195,0.070939,0.000000
44.860001,7.876053,-254.075195,0.003324,0.002774,0.070454,35.034431,1.784739,0.704535,-254.075195,0.071355,0.000000
45.110001,8.153839,-254.075195,0.003328,0.002797,0.071052,36.270088,1.847686,0.710519,-254.075195,0.071771,0.000000
45.360001,7.940842,-254.075195,0.003333,0.002809,0.071338,35.322628,1.799420,0.713381,-254.075195,0.072188,0.000000
45.610001,8.001915,-254.119675,0.003337,0.002826,0.071780,35.594296,1.813260,0.717802,-254.119675,0.072604,0.000000
45.860001,8.018669,-254.075195,0.003363,0.002840,0.072127,35.668823,1.817056,0.721272,-254.075195,0.073020,0.000000
46.110001,8.241722,-254.119675,0.003410,0.002857,0.072561,36.661011,1.867601,0.725606,-254.119675,0.073437,0.000000
46.360001,8.016808,-254.119675,0.003393,0.002864,0.072751,35.660542,1.816635,0.727514,-254.119675,0.073853,0.000000
46.610001,8.377640,-254.164154,0.003406,0.002886,0.073315,37.265602,1.898400,0.733153,-254.164154,0.074269,0.000000
46.860001,8.557869,-254.075195,0.003436,0.002904,0.073757,38.067303,1.939241,0.737574,-254.075195,0.074685,0.000000
47.110001,8.794319,-254.119675,0.003441,0.002924,0.074278,39.119087,1.992821,0.742778,-254.119675,0.075102,0.000000
47.360001,8.812569,-254.075195,0.003466,0.002942,0.074729,39.200264,1.996957,0.747290,-254.075195,0.075518,0.000000
47.610001,8.649094,-254.164154,0.003484,0.002954,0.075041,38.473091,1.959913,0.750408,-254.164154,0.075934,0.000000
47.860001,8.712776,-254.164154,0.003505,0.002968,0.075397,38.756363,1.974343,0.753966,-254.164154,0.076350,0.000000
48.110001,9.021095,-254.164154,0.003488,0.002991,0.075969,40.127834,2.044209,0.759689,-254.164154,0.076767,0.000000
48.360001,9.186058,-254.164154,0.003548,0.003006,0.076359,40.861626,2.081590,0.763591,-254.164154,0.077183,0.000000
48.610001,9.007690,-254.208633,0.003570,0.003016,0.076602,40.068207,2.041172,0.766021,-254.208633,0.077599,0.000000
48.860001,9.321976,-254.208633,0.003566,0.003035,0.077088,41.466217,2.112390,0.770877,-254.208633,0.078016,0.000000
49.110001,9.583755,-254.208633,0.003540,0.003053,0.077556,42.630672,2.171710,0.775559,-254.208633,0.078432,0.000000
49.360001,9.699562,-254.164154,0.003561,0.003072,0.078024,43.145805,2.197952,0.780241,-254.164154,0.078857,0.000000
49.610001,9.619873,-254.253113,0.003583,0.003084,0.078345,42.791332,2.179894,0.783451,-254.253113,0.079273,0.000000
49.860001,9.588966,-254.208633,0.003622,0.003097,0.078657,42.653854,2.172891,0.786573,-254.208633,0.079689,0.000000
50.110001,9.985168,-254.253113,0.003600,0.003116,0.079134,44.416248,2.262671,0.791342,-254.253113,0.080106,0.000000
50.360001,10.098373,-254.208633,0.003669,0.003132,0.079559,44.919807,2.288324,0.795592,-254.208633,0.080522,0.000000
50.610001,10.141563,-254.253113,0.003648,0.003146,0.079906,45.111927,2.298111,0.799063,-254.253113,0.080938,0.000000
50.860001,10.488243,-254.253113,0.003673,0.003166,0.080418,46.654034,2.376670,0.804177,-254.253113,0.081354,0.000000
51.110001,10.861732,-254.253113,0.003695,0.003188,0.080964,48.315399,2.461304,0.809642,-254.253113,0.081771,0.000000
51.360001,10.808861,-254.253113,0.003686,0.003202,0.081328,48.080215,2.449323,0.813283,-254.253113,0.082187,0.000000
51.610001,10.836411,-254.208633,0.003729,0.003216,0.081693,48.202763,2.455566,0.816928,-254.208633,0.082603,0.000000
51.860001,10.842743,-254.297592,0.003712,0.003228,0.081996,48.230930,2.457000,0.819963,-254.297592,0.083019,0.000000
52.110001,11.378960,-254.297592,0.003738,0.003249,0.082534,50.616142,2.578509,0.825338,-254.297592,0.083436,0.000000
52.360001,11.214371,-254.297592,0.003768,0.003261,0.082820,49.884014,2.541213,0.828199,-254.297592,0.083852,0.000000
52.610001,11.448593,-254.253113,0.003786,0.003275,0.083193,50.925884,2.594288,0.831931,-254.253113,0.084268,0.000000
52.860001,11.930443,-254.342072,0.003786,0.003298,0.083774,53.069260,2.703477,0.837741,-254.342072,0.084685,0.000000
53.110004,12.303932,-254.297592,0.003829,0.003317,0.084251,54.730625,2.788111,0.842510,-254.297592,0.085101,0.000000
53.360004,12.279358,-254.342072,0.003794,0.003333,0.084667,54.621311,2.782542,0.846673,-254.342072,0.085517,0.000000
53.610004,12.394791,-254.342072,0.003863,0.003346,0.084980,55.134781,2.808700,0.849796,-254.342072,0.085933,0.000000
53.860004,12.523262,-254.386566,0.003859,0.003361,0.085370,55.706253,2.837812,0.853698,-254.386566,0.086350,0.000000
54.110004,12.795464,-254.342072,0.003863,0.003375,0.085725,56.917065,2.899493,0.857252,-254.342072,0.086766,0.000000
54.360004,13.069160,-254.342072,0.003880,0.003391,0.086142,58.134529,2.961514,0.861416,-254.342072,0.087191,0.000000
54.610004,13.428123,-254.342072,0.003880,0.003410,0.086618,59.731277,3.042856,0.866185,-254.342072,0.087607,0.000000
54.860004,14.154251,-254.342072,0.003936,0.003434,0.087226,62.961254,3.207399,0.872256,-254.342072,0.088023,0.000000
55.110004,14.001953,-254.386566,0.003954,0.003445,0.087512,62.283798,3.172888,0.875117,-254.386566,0.088440,0.000000
55.360004,14.284958,-254.386566,0.003971,0.003462,0.087937,63.542667,3.237018,0.879367,-254.386566,0.088856,0.000000
55.610004,14.501305,-254.431046,0.003984,0.003478,0.088336,64.505028,3.286042,0.883357,-254.431046,0.089272,0.000000
55.860004,14.882614,-254.431046,0.003984,0.003495,0.088769,66.201172,3.372449,0.887690,-254.431046,0.089688,0.000000
56.110004,15.170830,-254.386566,0.003988,0.003511,0.089177,67.483223,3.437759,0.891767,-254.386566,0.090105,0.000000
56.360004,15.502609,-254.431046,0.004023,0.003526,0.089567,68.959053,3.512941,0.895669,-254.431046,0.090521,0.000000
56.610004,16.046280,-254.386566,0.004023,0.003546,0.090061,71.377419,3.636139,0.900612,-254.386566,0.090937,0.000000
56.860004,16.157990,-254.386566,0.004031,0.003561,0.090460,71.874329,3.661453,0.904601,-254.386566,0.091353,0.000000
57.110004,16.589943,-254.431046,0.004057,0.003580,0.090920,73.795753,3.759335,0.909200,-254.431046,0.091770,0.000000
57.360004,16.888214,-254.475525,0.004087,0.003596,0.091328,75.122528,3.826924,0.913276,-254.475525,0.092186,0.000000
57.610004,17.054665,-254.431046,0.004066,0.003610,0.091683,75.862938,3.864642,0.916830,-254.431046,0.092602,0.000000
57.860004,17.605400,-254.475525,0.004070,0.003627,0.092134,78.312729,3.989441,0.921342,-254.475525,0.093019,0.000000
58.110004,17.971069,-254.475525,0.004122,0.003644,0.092568,79.939308,4.072302,0.925676,-254.475525,0.093435,0.000000
58.360004,18.118530,-254.520004,0.004122,0.003656,0.092871,80.595245,4.105718,0.928711,-254.520004,0.093851,0.000000
58.610004,19.003288,-254.475525,0.004152,0.003680,0.093469,84.530846,4.306207,0.934695,-254.475525,0.094267,0.000000
58.860004,19.746910,-254.431046,0.004139,0.003700,0.093981,87.838646,4.474714,0.939812,-254.431046,0.094684,0.000000
59.110004,19.793831,-254.475525,0.004161,0.003713,0.094311,88.047356,4.485346,0.943109,-254.475525,0.095100,0.000000
59.360004,20.094711,-254.520004,0.004186,0.003729,0.094727,89.385742,4.553526,0.947272,-254.520004,0.095516,0.000000
59.610004,20.684921,-254.475525,0.004169,0.003747,0.095169,92.011124,4.687270,0.951693,-254.475525,0.095941,0.000000
59.860004,21.027130,-254.564484,0.004217,0.003763,0.095577,93.533348,4.764816,0.955769,-254.564484,0.096357,0.000000
60.110004,21.395035,-254.475525,0.004221,0.003776,0.095907,95.169868,4.848184,0.959066,-254.475525,0.096774,0.000000
60.360004,22.349800,-254.520004,0.004230,0.003797,0.096444,99.416878,5.064537,0.964440,-254.520004,0.097190,0.000000
60.610004,22.718071,-254.520004,0.004264,0.003812,0.096826,101.055023,5.147988,0.968256,-254.520004,0.097606,0.000000
60.860004,23.262108,-254.520004,0.004238,0.003828,0.097242,103.475021,5.271269,0.972419,-254.520004,0.098022,0.000000
61.110004,23.672089,-254.564484,0.004273,0.003844,0.097641,105.298706,5.364172,0.976408,-254.564484,0.098439,0.000000
61.360004,23.951370,-254.520004,0.004307,0.003857,0.097970,106.541016,5.427458,0.979705,-254.520004,0.098855,0.000000
61.610004,24.757561,-254.520004,0.004294,0.003875,0.098430,110.127129,5.610143,0.984300,-254.520004,0.099271,0.000000
61.860004,25.263611,-254.520004,0.004320,0.003890,0.098811,112.378151,5.724816,0.988115,-254.520004,0.099688,0.000000
62.110004,25.511986,-254.564484,0.004312,0.003902,0.099107,113.482979,5.781098,0.991067,-254.564484,0.100104,0.000000
62.360004,26.741928,-254.520004,0.004294,0.003926,0.099722,118.954041,6.059808,0.997221,-254.520004,0.100520,0.000000
62.610004,27.213356,-254.608963,0.004346,0.003942,0.100138,121.051056,6.166635,1.001385,-254.608963,0.100936,0.000000
62.860004,28.015816,-254.564484,0.004359,0.003960,0.100572,124.620575,6.348475,1.005722,-254.564484,0.101353,0.000000
63.110004,28.656296,-254.653442,0.004337,0.003977,0.101006,127.469566,6.493609,1.010056,-254.653442,0.101769,0.000000
63.360004,28.962761,-254.564484,0.004376,0.003989,0.101327,128.832794,6.563056,1.013266,-254.564484,0.102185,0.000000
63.610004,29.888107,-254.564484,0.004368,0.004009,0.101830,132.948944,6.772742,1.018296,-254.564484,0.102601,0.000000
63.860004,30.375542,-254.608963,0.004402,0.004022,0.102168,135.117157,6.883196,1.021679,-254.608963,0.103018,0.000000
64.110001,30.598961,-254.608963,0.004419,0.004034,0.102463,136.110977,6.933824,1.024628,-254.608963,0.103434,0.000000
64.360001,31.946953,-254.653442,0.004411,0.004056,0.103035,142.107147,7.239283,1.030351,-254.653442,0.103850,0.000000
64.610001,32.810860,-254.608963,0.004424,0.004074,0.103486,145.949997,7.435047,1.034858,-254.608963,0.104275,0.000000
64.860001,33.256218,-254.653442,0.004428,0.004088,0.103824,147.931046,7.535966,1.038242,-254.653442,0.104691,0.000000
65.110001,33.941750,-254.608963,0.004445,0.004103,0.104206,150.980438,7.691310,1.042057,-254.608963,0.105108,0.000000
65.360001,34.343544,-254.653442,0.004462,0.004116,0.104553,152.767715,7.782358,1.045528,-254.653442,0.105524,0.000000
65.610001,35.748878,-254.653442,0.004445,0.004138,0.105099,159.018951,8.100811,1.050990,-254.653442,0.105940,0.000000
65.860001,36.224396,-254.653442,0.004484,0.004149,0.105376,161.134155,8.208566,1.053764,-254.653442,0.106357,0.000000
66.110001,36.842163,-254.608963,0.004480,0.004164,0.105758,163.882126,8.348554,1.057583,-254.608963,0.106773,0.000000
66.360001,38.584496,-254.653442,0.004480,0.004189,0.106400,171.632401,8.743372,1.063998,-254.653442,0.107189,0.000000
66.610001,39.321045,-254.653442,0.004506,0.004204,0.106773,174.908737,8.910275,1.067726,-254.653442,0.107605,0.000000
66.860001,39.986473,-254.653442,0.004527,0.004219,0.107163,177.868713,9.061065,1.071633,-254.653442,0.108022,0.000000
67.110001,40.707756,-254.697922,0.004536,0.004234,0.107553,181.077148,9.224509,1.075535,-254.697922,0.108438,0.000000
67.360001,41.340050,-254.697922,0.004506,0.004247,0.107874,183.889725,9.367789,1.078740,-254.697922,0.108854,0.000000
67.610001,42.307472,-254.742401,0.004540,0.004263,0.108290,188.193039,9.587010,1.082904,-254.742401,0.109270,0.000000
67.860001,42.950188,-254.697922,0.004549,0.004277,0.108629,191.051971,9.732652,1.086288,-254.697922,0.109687,0.000000
68.110001,43.918358,-254.742401,0.004557,0.004295,0.109097,195.358612,9.952043,1.090969,-254.742401,0.110103,0.000000
68.360001,45.294647,-254.786880,0.004540,0.004315,0.109609,201.480652,10.263914,1.096087,-254.786880,0.110519,0.000000
68.610001,46.565926,-254.742401,0.004570,0.004334,0.110086,207.135590,10.551990,1.100856,-254.742401,0.110936,0.000000
68.860001,47.380302,-254.742401,0.004570,0.004348,0.110450,210.758118,10.736530,1.104497,-254.742401,0.111352,0.000000
69.110001,48.164146,-254.875854,0.004592,0.004364,0.110840,214.244827,10.914152,1.108403,-254.875854,0.111768,0.000000
69.360001,49.117790,-254.742401,0.004596,0.004378,0.111213,218.486847,11.130251,1.112131,-254.742401,0.112184,0.000000
69.610001,50.354813,-254.831375,0.004600,0.004397,0.111681,223.989395,11.410564,1.116813,-254.831375,0.112609,0.000000
69.860001,51.072746,-254.875854,0.004644,0.004412,0.112054,227.182922,11.573250,1.120541,-254.875854,0.113026,0.000000
70.110001,51.664818,-254.786880,0.004626,0.004425,0.112384,229.816589,11.707416,1.123837,-254.786880,0.113442,0.000000
70.360001,53.369911,-254.831375,0.004631,0.004447,0.112947,237.401215,12.093795,1.129473,-254.831375,0.113858,0.000000
70.610001,54.487778,-254.786880,0.004618,0.004461,0.113303,242.373734,12.347107,1.133031,-254.786880,0.114274,0.000000
70.860001,55.534515,-254.831375,0.004635,0.004479,0.113763,247.029861,12.584301,1.137626,-254.831375,0.114691,0.000000
71.110001,56.153770,-254.786880,0.004661,0.004489,0.114023,249.784439,12.724626,1.140230,-254.786880,0.115107,0.000000
71.360001,57.771355,-254.831375,0.004687,0.004511,0.114587,256.979828,13.091176,1.145866,-254.831375,0.115523,0.000000
71.610001,58.726494,-254.786880,0.004687,0.004526,0.114951,261.228485,13.307613,1.149507,-254.786880,0.115939,0.000000
71.860001,59.601562,-254.831375,0.004656,0.004537,0.115246,265.121002,13.505907,1.152455,-254.831375,0.116356,0.000000
72.110001,60.799492,-254.786880,0.004665,0.004557,0.115749,270.449646,13.777362,1.157485,-254.786880,0.116772,0.000000
72.360001,62.579430,-254.831375,0.004708,0.004578,0.116286,278.367218,14.180702,1.162864,-254.831375,0.117188,0.000000
72.610001,63.928909,-254.875854,0.004717,0.004595,0.116720,284.369995,14.486498,1.167197,-254.875854,0.117605,0.000000
72.860001,64.863190,-254.786880,0.004700,0.004608,0.117049,288.525879,14.698209,1.170494,-254.786880,0.118021,0.000000
73.110001,65.677933,-254.875854,0.004730,0.004622,0.117388,292.150024,14.882833,1.173878,-254.875854,0.118437,0.000000
73.360001,67.556931,-254.875854,0.004717,0.004642,0.117908,300.508240,15.308619,1.179078,-254.875854,0.118845,0.000000
73.610001,66.977890,-254.875854,0.004717,0.004634,0.117708,297.932526,15.177407,1.177083,-254.875854,0.117951,0.000000
73.860001,66.512054,-254.920334,0.004700,0.004632,0.117665,295.860382,15.071847,1.176652,-254.920334,0.117708,0.000000
74.110001,66.073395,-254.831375,0.004712,0.004631,0.117639,293.909149,14.972445,1.176391,-254.831375,0.117708,0.000000
74.360001,65.698425,-254.875854,0.004708,0.004631,0.117622,292.241180,14.887476,1.176217,-254.875854,0.117708,0.000000
74.610001,65.360306,-254.920334,0.004730,0.004630,0.117605,290.737152,14.810857,1.176046,-254.920334,0.117708,0.000000
74.860001,65.069489,-254.875854,0.004738,0.004630,0.117605,289.443542,14.744957,1.176046,-254.875854,0.117708,0.000000
75.110001,64.802872,-254.964813,0.004725,0.004630,0.117596,288.257568,14.684541,1.175959,-254.964813,0.117708,0.000000
75.360001,64.571991,-254.920334,0.004773,0.004630,0.117596,287.230560,14.632222,1.175959,-254.920334,0.117708,0.000000
75.610001,64.350800,-254.920334,0.004773,0.004630,0.117596,286.246643,14.582099,1.175959,-254.920334,0.117708,0.000000
75.860001,64.151581,-254.875854,0.004756,0.004629,0.117587,285.360474,14.536956,1.175872,-254.875854,0.117708,0.000000
76.110001,63.968384,-254.964813,0.004756,0.004629,0.117587,284.545593,14.495443,1.175872,-254.964813,0.117708,0.000000
76.360001,63.794113,-254.964813,0.004760,0.004629,0.117587,283.770386,14.455953,1.175872,-254.964813,0.117708,0.000000
76.610001,63.635483,-254.964813,0.004769,0.004629,0.117587,283.064758,14.420007,1.175872,-254.964813,0.117708,0.000000
76.860001,63.507004,-255.009293,0.004751,0.004629,0.117587,282.493256,14.390892,1.175872,-255.009293,0.117708,0.000000
77.110001,63.355087,-254.964813,0.004773,0.004629,0.117579,281.817505,14.356468,1.175785,-254.964813,0.117708,0.000000
77.360001,63.226242,-254.964813,0.004760,0.004629,0.117579,281.244385,14.327271,1.175785,-254.964813,0.117708,0.000000
77.610001,63.092186,-254.920334,0.004777,0.004629,0.117579,280.648071,14.296894,1.175785,-254.920334,0.117708,0.000000
77.860001,62.996117,-254.920334,0.004781,0.004629,0.117579,280.220734,14.275125,1.175785,-254.920334,0.117708,0.000000
78.110001,62.887009,-255.009293,0.004760,0.004629,0.117579,279.735382,14.250400,1.175785,-255.009293,0.117708,0.000000
78.360001,62.773804,-255.009293,0.004747,0.004629,0.117579,279.231812,14.224748,1.175785,-255.009293,0.117708,0.000000
78.610001,62.683693,-255.009293,0.004773,0.004629,0.117579,278.830994,14.204328,1.175785,-255.009293,0.117708,0.000000
78.860001,62.589485,-254.964813,0.004725,0.004629,0.117579,278.411926,14.182981,1.175785,-254.964813,0.117708,0.000000
79.110001,62.487450,-255.053772,0.004747,0.004629,0.117579,277.958069,14.159859,1.175785,-255.053772,0.117708,0.000000
79.360001,62.415588,-255.009293,0.004734,0.004629,0.117579,277.638397,14.143575,1.175785,-255.009293,0.117708,0.000000
79.610001,62.336273,-255.009293,0.004760,0.004629,0.117579,277.285583,14.125601,1.175785,-255.009293,0.117708,0.000000
79.860001,62.246155,-255.053772,0.004743,0.004629,0.117579,276.884735,14.105181,1.175785,-255.053772,0.117708,0.000000
80.110001,62.183594,-255.009293,0.004764,0.004629,0.117579,276.606445,14.091003,1.175785,-255.009293,0.117708,0.000000
80.360001,62.101677,-255.053772,0.004756,0.004629,0.117579,276.242065,14.072441,1.175785,-255.053772,0.117708,0.000000
80.610001,62.040977,-255.053772,0.004769,0.004629,0.117579,275.972046,14.058686,1.175785,-255.053772,0.117708,0.000000
80.860001,61.960175,-255.098251,0.004743,0.004629,0.117579,275.612610,14.040376,1.175785,-255.098251,0.117708,0.000000
81.110001,61.879738,-255.098251,0.004777,0.004629,0.117579,275.254822,14.022149,1.175785,-255.098251,0.117708,0.000000
81.360001,61.842506,-255.009293,0.004756,0.004629,0.117579,275.089203,14.013713,1.175785,-255.009293,0.117708,0.000000
81.610001,61.773613,-255.053772,0.004747,0.004629,0.117579,274.782745,13.998100,1.175785,-255.053772,0.117708,0.000000
81.860001,61.725952,-255.053772,0.004786,0.004629,0.117579,274.570740,13.987301,1.175785,-255.053772,0.117708,0.000000
82.110001,61.667114,-255.098251,0.004717,0.004629,0.117579,274.309021,13.973969,1.175785,-255.098251,0.117708,0.000000
82.360001,61.604187,-255.053772,0.004773,0.004629,0.117579,274.029114,13.959708,1.175785,-255.053772,0.117708,0.000000
82.610001,61.556892,-255.053772,0.004738,0.004629,0.117579,273.818726,13.948992,1.175785,-255.053772,0.117708,0.000000
82.860001,61.497314,-255.053772,0.004777,0.004629,0.117579,273.553711,13.935491,1.175785,-255.053772,0.117708,0.000000
83.110001,61.433266,-255.142731,0.004777,0.004629,0.117579,273.268799,13.920977,1.175785,-255.142731,0.117708,0.000000
83.360001,61.392303,-255.142731,0.004756,0.004629,0.117579,273.086609,13.911695,1.175785,-255.142731,0.117708,0.000000
83.610001,61.348366,-255.053772,0.004769,0.004629,0.117579,272.891174,13.901738,1.175785,-255.053772,0.117708,0.000000
83.860001,61.302567,-255.142731,0.004760,0.004629,0.117579,272.687439,13.891360,1.175785,-255.142731,0.117708,0.000000
84.110001,61.253036,-255.142731,0.004764,0.004629,0.117579,272.467102,13.880136,1.175785,-255.142731,0.117708,0.000000
84.360001,61.206863,-255.098251,0.004760,0.004629,0.117579,272.261719,13.869674,1.175785,-255.098251,0.117708,0.000000
84.610001,61.169998,-255.142731,0.004781,0.004629,0.117579,272.097748,13.861320,1.175785,-255.142731,0.117708,0.000000
84.860001,61.124573,-255.142731,0.004777,0.004629,0.117579,271.895691,13.851027,1.175785,-255.142731,0.117708,0.000000
85.110001,61.077652,-255.142731,0.004738,0.004629,0.117579,271.686951,13.840394,1.175785,-255.142731,0.117708,0.000000
85.360001,61.029617,-255.187210,0.004781,0.004629,0.117579,271.473297,13.829509,1.175785,-255.187210,0.117708,0.000000
85.610001,60.995728,-255.187210,0.004747,0.004629,0.117579,271.322540,13.821830,1.175785,-255.187210,0.117708,0.000000
85.860001,60.970406,-255.142731,0.004790,0.004629,0.117579,271.209900,13.816091,1.175785,-255.142731,0.117708,0.000000
86.110001,60.922745,-255.187210,0.004734,0.004629,0.117579,270.997894,13.805291,1.175785,-255.187210,0.117708,0.000000
86.360001,60.883270,-255.187210,0.004764,0.004629,0.117579,270.822327,13.796347,1.175785,-255.187210,0.117708,0.000000
86.610001,60.850502,-255.187210,0.004764,0.004629,0.117579,270.676544,13.788921,1.175785,-255.187210,0.117708,0.000000
86.860001,60.818108,-255.187210,0.004756,0.004629,0.117579,270.532440,13.781580,1.175785,-255.187210,0.117708,0.000000
87.110001,60.788315,-255.187210,0.004799,0.004629,0.117579,270.399933,13.774829,1.175785,-255.187210,0.117708,0.000000
87.360001,60.727249,-255.187210,0.004743,0.004629,0.117579,270.128296,13.760991,1.175785,-255.187210,0.117708,0.000000
87.610001,60.713470,-255.187210,0.004773,0.004629,0.117579,270.067017,13.757870,1.175785,-255.187210,0.117708,0.000000
87.860001,60.688522,-255.142731,0.004764,0.004629,0.117579,269.956024,13.752216,1.175785,-255.142731,0.117708,0.000000
88.110001,60.636391,-255.231705,0.004743,0.004629,0.117579,269.724152,13.740402,1.175785,-255.231705,0.117708,0.000000
88.360001,60.616280,-255.187210,0.004773,0.004629,0.117579,269.634674,13.735845,1.175785,-255.187210,0.117708,0.000000
88.610001,60.574577,-255.276184,0.004738,0.004629,0.117579,269.449188,13.726396,1.175785,-255.276184,0.117708,0.000000
88.860001,60.550369,-255.276184,0.004777,0.004629,0.117579,269.341492,13.720910,1.175785,-255.276184,0.117708,0.000000
89.110001,60.527283,-255.231705,0.004794,0.004629,0.117579,269.238800,13.715678,1.175785,-255.231705,0.117708,0.000000
89.360001,60.479248,-255.231705,0.004760,0.004629,0.117579,269.025146,13.704793,1.175785,-255.231705,0.117708,0.000000
89.610001,60.456161,-255.276184,0.004769,0.004629,0.117579,268.922424,13.699562,1.175785,-255.276184,0.117708,0.000000
89.860001,60.424881,-255.320663,0.004786,0.004629,0.117579,268.783295,13.692473,1.175785,-255.320663,0.117708,0.000000
90.110001,60.407753,-255.365143,0.004747,0.004629,0.117579,268.707092,13.688593,1.175785,-255.365143,0.117708,0.000000
90.360001,60.375725,-255.276184,0.004751,0.004629,0.117579,268.564636,13.681334,1.175785,-255.276184,0.117708,0.000000
90.610001,60.339981,-255.276184,0.004751,0.004629,0.117579,268.405640,13.673235,1.175785,-255.276184,0.117708,0.000000
90.860001,60.322105,-255.231705,0.004777,0.004629,0.117579,268.326111,13.669184,1.175785,-255.231705,0.117708,0.000000
91.110001,60.277420,-255.276184,0.004734,0.004629,0.117579,268.127350,13.659059,1.175785,-255.276184,0.117708,0.000000
91.360001,60.270721,-255.320663,0.004794,0.004629,0.117579,268.097565,13.657541,1.175785,-255.320663,0.117708,0.000000
91.610001,60.242416,-255.320663,0.004764,0.004629,0.117579,267.971649,13.651126,1.175785,-255.320663,0.117708,0.000000
91.860001,60.205551,-255.276184,0.004781,0.004629,0.117579,267.807678,13.642774,1.175785,-255.276184,0.117708,0.000000
92.110001,60.186188,-255.320663,0.004786,0.004629,0.117579,267.721527,13.638385,1.175785,-255.320663,0.117708,0.000000
92.360001,60.144112,-255.365143,0.004777,0.004629,0.117579,267.534363,13.628851,1.175785,-255.365143,0.117708,0.000000
92.610001,60.145233,-255.409622,0.004777,0.004629,0.117579,267.539368,13.629105,1.175785,-255.409622,0.117708,0.000000
92.860001,60.103897,-255.409622,0.004756,0.004629,0.117570,267.355499,13.619738,1.175698,-255.409622,0.117708,0.000000
93.110001,60.089745,-255.409622,0.004760,0.004629,0.117570,267.292542,13.616531,1.175698,-255.409622,0.117708,0.000000
93.360008,60.051765,-255.365143,0.004773,0.004629,0.117570,267.123596,13.607924,1.175698,-255.365143,0.117708,0.000000
93.610008,60.034637,-255.409622,0.004743,0.004629,0.117570,267.047394,13.604044,1.175698,-255.409622,0.117708,0.000000
93.860008,60.018997,-255.365143,0.004773,0.004629,0.117570,266.977844,13.600499,1.175698,-255.365143,0.117708,0.000000
94.110008,59.990692,-255.365143,0.004794,0.004629,0.117570,266.851929,13.594085,1.175698,-255.365143,0.117708,0.000000
94.360008,59.958672,-255.365143,0.004764,0.004629,0.117570,266.709503,13.586829,1.175698,-255.365143,0.117708,0.000000
94.610008,59.937447,-255.409622,0.004773,0.004629,0.117570,266.615082,13.582020,1.175698,-255.409622,0.117708,0.000000
94.860008,59.905792,-255.365143,0.004790,0.004629,0.117570,266.474274,13.574846,1.175698,-255.365143,0.117708,0.000000
95.110008,59.896111,-255.409622,0.004751,0.004629,0.117570,266.431213,13.572653,1.175698,-255.409622,0.117708,0.000000
95.360008,59.875633,-255.454102,0.004743,0.004629,0.117570,266.340118,13.568012,1.175698,-255.454102,0.117708,0.000000
95.610008,59.850685,-255.409622,0.004756,0.004629,0.117570,266.229156,13.562359,1.175698,-255.409622,0.117708,0.000000
95.860008,59.829086,-255.409622,0.004773,0.004629,0.117570,266.133057,13.557466,1.175698,-255.409622,0.117708,0.000000
96.110008,59.814934,-255.409622,0.004760,0.004629,0.117570,266.070099,13.554257,1.175698,-255.409622,0.117708,0.000000
96.360008,59.794083,-255.365143,0.004799,0.004629,0.117570,265.977356,13.549532,1.175698,-255.365143,0.117708,0.000000
96.610008,59.772484,-255.454102,0.004812,0.004629,0.117570,265.881287,13.544639,1.175698,-255.454102,0.117708,0.000000
96.860008,59.759453,-255.409622,0.004764,0.004629,0.117570,265.823334,13.541686,1.175698,-255.409622,0.117708,0.000000
97.110008,59.725197,-255.454102,0.004773,0.004629,0.117570,265.670929,13.533923,1.175698,-255.454102,0.117708,0.000000
97.360008,59.715881,-255.454102,0.004769,0.004629,0.117570,265.629517,13.531813,1.175698,-255.454102,0.117708,0.000000
97.610008,59.697639,-255.409622,0.004769,0.004629,0.117570,265.548370,13.527678,1.175698,-255.409622,0.117708,0.000000
97.860008,59.663383,-255.498581,0.004743,0.004629,0.117570,265.395996,13.519916,1.175698,-255.498581,0.117708,0.000000
98.110008,59.648857,-255.543060,0.004751,0.004629,0.117570,265.331360,13.516624,1.175698,-255.543060,0.117708,0.000000
98.360008,59.634705,-255.454102,0.004799,0.004629,0.117570,265.268402,13.513417,1.175698,-255.454102,0.117708,0.000000
98.610008,59.628746,-255.498581,0.004751,0.004629,0.117570,265.241913,13.512067,1.175698,-255.498581,0.117708,0.000000
98.860008,59.605659,-255.454102,0.004781,0.004629,0.117570,265.139221,13.506836,1.175698,-255.454102,0.117708,0.000000
99.110008,59.583321,-255.498581,0.004790,0.004629,0.117570,265.039856,13.501774,1.175698,-255.498581,0.117708,0.000000
99.360008,59.572151,-255.498581,0.004756,0.004629,0.117570,264.990173,13.499243,1.175698,-255.498581,0.117708,0.000000
99.610008,59.537521,-255.498581,0.004769,0.004629,0.117570,264.836121,13.491395,1.175698,-255.498581,0.117708,0.000000
99.860008,59.552414,-255.543060,0.004790,0.004629,0.117570,264.902374,13.494769,1.175698,-255.543060,0.117708,0.000000
100.110008,59.524109,-255.454102,0.004777,0.004629,0.117570,264.776459,13.488356,1.175698,-255.454102,0.117708,0.000000
100.360008,59.501396,-255.498581,0.004807,0.004629,0.117570,264.675415,13.483210,1.175698,-255.498581,0.117708,0.000000
100.610008,59.485756,-255.543060,0.004751,0.004629,0.117570,264.605865,13.479665,1.175698,-255.543060,0.117708,0.000000
100.860008,59.469002,-255.543060,0.004769,0.004629,0.117570,264.531342,13.475868,1.175698,-255.543060,0.117708,0.000000
101.110008,59.463043,-255.498581,0.004773,0.004629,0.117570,264.504822,13.474519,1.175698,-255.498581,0.117708,0.000000
101.360008,59.437721,-255.632019,0.004756,0.004629,0.117570,264.392181,13.468780,1.175698,-255.632019,0.117708,0.000000
101.610008,59.424316,-255.543060,0.004769,0.004629,0.117570,264.332550,13.465742,1.175698,-255.543060,0.117708,0.000000
101.860008,59.413887,-255.543060,0.004794,0.004629,0.117570,264.286163,13.463379,1.175698,-255.543060,0.117708,0.000000
102.110008,59.394897,-255.498581,0.004794,0.004629,0.117570,264.201691,13.459076,1.175698,-255.498581,0.117708,0.000000
102.360008,59.385216,-255.587540,0.004760,0.004629,0.117570,264.158630,13.456882,1.175698,-255.587540,0.117708,0.000000
102.610008,59.352821,-255.587540,0.004781,0.004629,0.117570,264.014526,13.449542,1.175698,-255.587540,0.117708,0.000000
102.860008,59.350212,-255.543060,0.004781,0.004629,0.117570,264.002930,13.448950,1.175698,-255.543060,0.117708,0.000000
103.110008,59.335320,-255.543060,0.004773,0.004629,0.117570,263.936676,13.445576,1.175698,-255.543060,0.117708,0.000000
103.360008,59.328621,-255.587540,0.004764,0.004629,0.117570,263.906891,13.444057,1.175698,-255.587540,0.117708,0.000000
103.610008,59.323402,-255.587540,0.004738,0.004629,0.117570,263.883667,13.442875,1.175698,-255.587540,0.117708,0.000000
103.860008,59.290260,-255.587540,0.004751,0.004629,0.117570,263.736237,13.435365,1.175698,-255.587540,0.117708,0.000000
103.900002,59.292496,-255.632019,0.004786,0.004629,0.117570,263.746185,13.435872,1.175698,-255.632019,0.117708,0.000000