File: Data/compression sample NH 10,12,15/AutoNoheating-12-2-2-240201_02012024_183730.csv
Time (sec),S:Load (lbs),S:HL1 (DIM),S:LVDT (in),S:Position (in),Ch:Position (mm),Ch:Load (N),Ch:Stress (MPa),Ch:Strain (mm/mm),Ch:HL1 (DIM),Set Point (),Cycles ()
0.110000,-0.004471,-190.956726,0.000013,-0.000000,-0.000000,-0.019887,-0.001013,-0.000000,-190.956726,0.000182,0.000000
0.350000,-0.030907,-191.045685,0.000017,0.000000,0.000009,-0.137480,-0.007004,0.000087,-191.045685,0.000321,0.000000
0.590000,-0.010796,-191.001205,-0.000004,0.000125,0.003174,-0.048021,-0.002446,0.031740,-191.001205,0.004310,0.000000
0.830000,-0.016754,-191.045685,0.000134,0.000289,0.007337,-0.074526,-0.003797,0.073366,-191.045685,0.008317,0.000000
1.070000,0.005585,-191.045685,0.000306,0.000446,0.011317,0.024842,0.001266,0.113172,-191.045685,0.012306,0.000000
1.310000,0.008194,-191.045685,0.000453,0.000595,0.015124,0.036449,0.001857,0.151244,-191.045685,0.016313,0.000000
1.550000,0.002983,-191.090164,0.000647,0.000754,0.019140,0.013269,0.000676,0.191398,-191.090164,0.020302,0.000000
1.790000,-0.026436,-191.001205,0.000776,0.000912,0.023172,-0.117593,-0.005990,0.231723,-191.001205,0.024308,0.000000
2.030000,-0.000374,-191.090164,0.000949,0.001072,0.027222,-0.001663,-0.000085,0.272225,-191.090164,0.028298,0.000000
2.270000,0.010796,-191.001205,0.001138,0.001225,0.031125,0.048021,0.002446,0.311247,-191.001205,0.032304,0.000000
2.510000,-0.015640,-191.045685,0.001311,0.001391,0.035322,-0.069571,-0.003544,0.353222,-191.045685,0.036293,0.000000
2.750000,-0.000748,-191.045685,0.001457,0.001543,0.039181,-0.003326,-0.000169,0.391812,-191.045685,0.040300,0.000000
2.990000,0.015640,-191.001205,0.001647,0.001706,0.043327,0.069571,0.003544,0.433268,-191.001205,0.044307,0.000000
3.230000,0.036118,-191.090164,0.001794,0.001857,0.047177,0.160659,0.008184,0.471772,-191.090164,0.048296,0.000000
3.470000,0.023087,-191.090164,0.001966,0.002023,0.051383,0.102694,0.005231,0.513834,-191.090164,0.052302,0.000000
3.710000,-0.002975,-191.045685,0.002117,0.002169,0.055104,-0.013236,-0.000674,0.551035,-191.045685,0.056292,0.000000
3.950000,0.014153,-191.134644,0.002289,0.002328,0.059136,0.062954,0.003207,0.591363,-191.134644,0.060298,0.000000
4.190000,0.010796,-191.045685,0.002440,0.002485,0.063108,0.048021,0.002446,0.631082,-191.045685,0.064288,0.000000
4.430000,-0.014153,-191.134644,0.002574,0.002647,0.067236,-0.062954,-0.003207,0.672360,-191.134644,0.068294,0.000000
4.670000,-0.042076,-191.090164,0.002772,0.002805,0.071243,-0.187164,-0.009535,0.712427,-191.090164,0.072283,0.000000
4.910000,0.008568,-191.134644,0.002928,0.002961,0.075206,0.038112,0.001941,0.752059,-191.134644,0.076290,0.000000
5.150000,0.005959,-191.134644,0.003091,0.003115,0.079126,0.026505,0.001350,0.791259,-191.134644,0.080279,0.000000
5.390000,0.035751,-191.134644,0.003264,0.003280,0.083323,0.159030,0.008101,0.833229,-191.134644,0.084286,0.000000
5.630000,0.004471,-191.134644,0.003432,0.003435,0.087252,0.019887,0.001013,0.872517,-191.134644,0.088275,0.000000
5.870000,-0.001114,-191.134644,0.003591,0.003587,0.091119,-0.004955,-0.000252,0.911195,-191.134644,0.092281,0.000000
6.110000,0.010056,-191.223602,0.003738,0.003741,0.095013,0.044729,0.002279,0.950134,-191.223602,0.096271,0.000000
6.350000,-0.005959,-191.134644,0.003915,0.003900,0.099054,-0.026505,-0.001350,0.990545,-191.134644,0.100277,0.000000
6.590000,-0.004471,-191.134644,0.004096,0.004065,0.103252,-0.019887,-0.001013,1.032519,-191.134644,0.104267,0.000000
6.830000,-0.029793,-191.223602,0.004247,0.004219,0.107163,-0.132525,-0.006751,1.071633,-191.223602,0.108273,0.000000
7.070000,0.009308,-191.179123,0.004406,0.004379,0.111230,0.041403,0.002109,1.112305,-191.179123,0.112263,0.000000
7.310000,0.047661,-191.179123,0.004549,0.004533,0.115142,0.212006,0.010800,1.151418,-191.179123,0.116269,0.000000
7.550000,0.051018,-191.179123,0.004738,0.004699,0.119348,0.226938,0.011561,1.193476,-191.179123,0.120276,0.000000
7.790000,0.024948,-191.179123,0.004876,0.004853,0.123259,0.110975,0.005653,1.232589,-191.179123,0.124265,0.000000
8.030001,0.011917,-191.179123,0.005036,0.005008,0.127196,0.053010,0.002700,1.271959,-191.179123,0.128272,0.000000
8.270000,0.027184,-191.179123,0.005226,0.005157,0.130994,0.120918,0.006160,1.309945,-191.179123,0.132261,0.000000
8.510000,0.017876,-191.223602,0.005381,0.005325,0.135244,0.079515,0.004051,1.352438,-191.223602,0.136267,0.000000
8.750000,-0.015266,-191.179123,0.005523,0.005478,0.139146,-0.067908,-0.003459,1.391464,-191.179123,0.140256,0.000000
8.990001,0.192520,-191.223602,0.005726,0.005638,0.143197,0.856372,0.043626,1.431966,-191.223602,0.144263,0.000000
9.230000,0.699318,-191.268097,0.005885,-0.000008,-0.000191,3.110722,0.158468,-0.001908,-191.268097,0.001015,0.000000
9.470000,0.630424,-191.179123,0.005864,-0.000008,-0.000208,2.804268,0.142856,-0.002082,-191.179123,-0.000044,0.000000
9.710000,0.625214,-191.268097,0.005868,-0.000009,-0.000217,2.781089,0.141675,-0.002169,-191.268097,-0.000044,0.000000
9.950001,0.577919,-191.268097,0.005915,-0.000009,-0.000217,2.570712,0.130958,-0.002169,-191.268097,0.000260,0.000000
10.190001,0.600266,-191.268097,0.005890,-0.000008,-0.000208,2.670114,0.136022,-0.002082,-191.268097,0.000659,0.000000
10.430000,0.593559,-191.312576,0.005898,-0.000008,-0.000208,2.640284,0.134502,-0.002082,-191.312576,0.001058,0.000000
10.670000,0.755913,-191.223602,0.005890,0.000020,0.000512,3.362468,0.171292,0.005117,-191.223602,0.001457,0.000000
10.910001,0.831505,-191.268097,0.005941,0.000042,0.001075,3.698718,0.188422,0.010753,-191.268097,0.001856,0.000000
11.150001,0.882523,-191.223602,0.005941,0.000059,0.001492,3.925657,0.199982,0.014916,-191.223602,0.002255,0.000000
11.390000,0.921997,-191.312576,0.005971,0.000074,0.001891,4.101248,0.208928,0.018906,-191.312576,0.002654,0.000000
11.630000,0.973755,-191.312576,0.005993,0.000090,0.002281,4.331478,0.220656,0.022808,-191.312576,0.003061,0.000000
11.870001,1.022911,-191.268097,0.005993,0.000105,0.002671,4.550136,0.231795,0.026710,-191.268097,0.003460,0.000000
12.110001,1.100365,-191.357056,0.006027,0.000122,0.003087,4.894667,0.249346,0.030873,-191.357056,0.003859,0.000000
12.350000,1.108551,-191.268097,0.006040,0.000130,0.003296,4.931081,0.251201,0.032955,-191.268097,0.004258,0.000000
12.590000,1.193085,-191.357056,0.006053,0.000145,0.003677,5.307106,0.270357,0.036770,-191.357056,0.004657,0.000000
12.830001,1.277611,-191.312576,0.006071,0.000172,0.004362,5.683096,0.289511,0.043621,-191.312576,0.005056,0.000000
13.070001,1.307770,-191.312576,0.006088,0.000188,0.004787,5.817251,0.296345,0.047871,-191.312576,0.005455,0.000000
13.310000,1.272026,-191.357056,0.006109,0.000201,0.005099,5.658255,0.288245,0.050994,-191.357056,0.005854,0.000000
13.550000,1.298088,-191.401535,0.006127,0.000214,0.005437,5.774184,0.294151,0.054374,-191.401535,0.006261,0.000000
13.790001,1.339798,-191.357056,0.006135,0.000229,0.005828,5.959719,0.303603,0.058276,-191.357056,0.006660,0.000000
14.030001,1.422089,-191.401535,0.006170,0.000247,0.006279,6.325766,0.322250,0.062788,-191.401535,0.007059,0.000000
14.270000,1.447037,-191.357056,0.006200,0.000263,0.006669,6.436741,0.327903,0.066690,-191.357056,0.007458,0.000000
14.510000,1.482040,-191.357056,0.006217,0.000274,0.006955,6.592445,0.335835,0.069551,-191.357056,0.007857,0.000000
14.750001,1.539017,-191.357056,0.006234,0.000295,0.007493,6.845888,0.348746,0.074930,-191.357056,0.008256,0.000000
14.990001,1.589287,-191.401535,0.006252,0.000313,0.007961,7.069501,0.360138,0.079611,-191.401535,0.008655,0.000000
15.230000,1.544975,-191.357056,0.006269,0.000327,0.008308,6.872393,0.350096,0.083078,-191.357056,0.009063,0.000000
15.470000,1.573647,-191.312576,0.006265,0.000340,0.008638,6.999929,0.356593,0.086375,-191.312576,0.009461,0.000000
15.710001,1.612000,-191.446014,0.006303,0.000353,0.008958,7.170532,0.365284,0.089585,-191.446014,0.009860,0.000000
15.950001,1.654823,-191.401535,0.006312,0.000371,0.009418,7.361022,0.374988,0.094180,-191.401535,0.010259,0.000000
16.190001,1.693550,-191.401535,0.006303,0.000386,0.009799,7.533287,0.383764,0.097995,-191.401535,0.010658,0.000000
16.430000,1.701744,-191.446014,0.006347,0.000396,0.010069,7.569736,0.385621,0.100686,-191.446014,0.011057,0.000000
16.670000,1.788506,-191.446014,0.006355,0.000421,0.010693,7.955670,0.405281,0.106927,-191.446014,0.011456,0.000000
16.910002,1.791855,-191.446014,0.006398,0.000436,0.011075,7.970569,0.406040,0.110746,-191.446014,0.011855,0.000000
17.150002,1.808983,-191.446014,0.006416,0.000450,0.011421,8.046758,0.409921,0.114213,-191.446014,0.012263,0.000000
17.390001,1.838028,-191.534973,0.006403,0.000469,0.011907,8.175957,0.416503,0.119069,-191.534973,0.012662,0.000000
17.630001,1.851807,-191.490494,0.006450,0.000480,0.012193,8.237247,0.419625,0.121930,-191.490494,0.013061,0.000000
17.870001,1.914368,-191.446014,0.006480,0.000499,0.012679,8.515532,0.433802,0.126786,-191.446014,0.013459,0.000000
18.110001,1.917717,-191.534973,0.006493,0.000514,0.013043,8.530431,0.434561,0.130431,-191.534973,0.013858,0.000000
18.350000,1.924797,-191.446014,0.006489,0.000521,0.013234,8.561925,0.436165,0.132339,-191.446014,0.014257,0.000000
18.590000,2.008575,-191.534973,0.006506,0.000544,0.013815,8.934589,0.455150,0.138149,-191.534973,0.014656,0.000000
18.830002,2.032410,-191.490494,0.006558,0.000558,0.014179,9.040609,0.460551,0.141790,-191.490494,0.015055,0.000000
19.070002,2.016396,-191.534973,0.006562,0.000568,0.014439,8.969376,0.456922,0.144394,-191.534973,0.015463,0.000000
19.310001,2.028313,-191.534973,0.006562,0.000586,0.014881,9.022386,0.459622,0.148814,-191.534973,0.015862,0.000000
19.550001,2.083427,-191.534973,0.006597,0.000603,0.015306,9.267548,0.472111,0.153065,-191.534973,0.016260,0.000000
19.790001,2.137794,-191.579453,0.006640,0.000623,0.015827,9.509385,0.484431,0.158269,-191.579453,0.016659,0.000000
20.030001,2.100182,-191.534973,0.006622,0.000631,0.016026,9.342074,0.475908,0.160264,-191.534973,0.017058,0.000000
20.270000,2.105766,-191.534973,0.006653,0.000641,0.016278,9.366917,0.477173,0.162777,-191.534973,0.017457,0.000000
20.510000,2.192528,-191.579453,0.006679,0.000661,0.016789,9.752851,0.496834,0.167894,-191.579453,0.017856,0.000000
20.750002,2.283012,-191.579453,0.006687,0.000687,0.017440,10.155346,0.517338,0.174400,-191.579453,0.018255,0.000000
20.990002,2.260300,-191.579453,0.006722,0.000698,0.017717,10.054316,0.512191,0.177175,-191.579453,0.018663,0.000000
21.230001,2.303123,-191.534973,0.006730,0.000716,0.018177,10.244805,0.521895,0.181770,-191.534973,0.019061,0.000000
21.470001,2.316902,-191.579453,0.006752,0.000730,0.018533,10.306095,0.525017,0.185327,-191.579453,0.019460,0.000000
21.710001,2.357117,-191.623932,0.006748,0.000745,0.018923,10.484979,0.534130,0.189230,-191.623932,0.019859,0.000000
21.950001,2.336266,-191.579453,0.006773,0.000757,0.019227,10.392228,0.529405,0.192265,-191.579453,0.020258,0.000000
22.190001,2.405899,-191.668411,0.006795,0.000776,0.019703,10.701974,0.545185,0.197034,-191.668411,0.020657,0.000000
22.430000,2.480370,-191.534973,0.006817,0.000792,0.020128,11.033235,0.562060,0.201284,-191.534973,0.021056,0.000000
22.670002,2.513145,-191.668411,0.006864,0.000813,0.020648,11.179029,0.569487,0.206485,-191.668411,0.021455,0.000000
22.910002,2.517235,-191.668411,0.006864,0.000828,0.021022,11.197220,0.570414,0.210217,-191.668411,0.021863,0.000000
23.150002,2.511284,-191.623932,0.006873,0.000841,0.021360,11.170749,0.569065,0.213597,-191.623932,0.022262,0.000000
23.390001,2.509789,-191.579453,0.006864,0.000855,0.021724,11.164097,0.568726,0.217242,-191.579453,0.022661,0.000000
23.630001,2.575325,-191.534973,0.006916,0.000871,0.022131,11.455618,0.583577,0.221314,-191.534973,0.023059,0.000000
23.870001,2.639748,-191.668411,0.006967,0.000889,0.022591,11.742184,0.598175,0.225913,-191.668411,0.023458,0.000000
24.110001,2.650551,-191.623932,0.006954,0.000902,0.022904,11.790239,0.600623,0.229035,-191.623932,0.023857,0.000000
24.350000,2.682571,-191.623932,0.006963,0.000918,0.023328,11.932673,0.607879,0.233282,-191.623932,0.024256,0.000000
24.590002,2.748856,-191.668411,0.006998,0.000940,0.023875,12.227520,0.622900,0.238747,-191.668411,0.024655,0.000000
24.830002,2.714226,-191.623932,0.007028,0.000948,0.024092,12.073480,0.615052,0.240916,-191.623932,0.025063,0.000000
25.070002,2.755188,-191.668411,0.007019,0.000969,0.024620,12.255689,0.624335,0.246204,-191.668411,0.025462,0.000000
25.310001,2.762260,-191.623932,0.007054,0.000980,0.024898,12.287148,0.625937,0.248982,-191.623932,0.025861,0.000000
25.550001,2.798004,-191.757385,0.007062,0.000995,0.025262,12.446144,0.634037,0.252623,-191.757385,0.026260,0.000000
25.790001,2.916046,-191.668411,0.007088,0.001017,0.025835,12.971221,0.660785,0.258346,-191.668411,0.026659,0.000000
26.030001,2.910461,-191.668411,0.007118,0.001027,0.026095,12.946379,0.659520,0.260950,-191.668411,0.027057,0.000000
26.270000,2.907860,-191.757385,0.007127,0.001043,0.026503,12.934807,0.658930,0.265026,-191.757385,0.027456,0.000000
26.510002,3.019196,-191.712906,0.007144,0.001064,0.027031,13.430053,0.684160,0.270313,-191.712906,0.027855,0.000000
26.750002,3.032974,-191.712906,0.007161,0.001081,0.027448,13.491343,0.687282,0.274477,-191.712906,0.028263,0.000000
26.990002,2.999084,-191.712906,0.007183,0.001094,0.027795,13.340594,0.679602,0.277948,-191.712906,0.028662,0.000000
27.230001,3.027390,-191.668411,0.007192,0.001108,0.028133,13.466501,0.686016,0.281327,-191.668411,0.029061,0.000000
27.470001,3.135750,-191.757385,0.007213,0.001127,0.028618,13.948512,0.710571,0.286183,-191.757385,0.029460,0.000000
27.710001,3.144684,-191.668411,0.007239,0.001140,0.028965,13.988253,0.712596,0.289654,-191.668411,0.029859,0.000000
27.950001,3.095535,-191.712906,0.007226,0.001148,0.029147,13.769629,0.701458,0.291475,-191.712906,0.030258,0.000000
28.190001,3.180809,-191.668411,0.007261,0.001165,0.029581,14.148945,0.720782,0.295812,-191.668411,0.030657,0.000000
28.430002,3.366623,-191.801865,0.007299,0.001195,0.030344,14.975487,0.762888,0.303443,-191.801865,0.031064,0.000000
28.670002,3.315231,-191.712906,0.007312,0.001209,0.030700,14.746885,0.751242,0.306997,-191.712906,0.031463,0.000000
28.910002,3.299591,-191.712906,0.007355,0.001223,0.031064,14.677314,0.747698,0.310641,-191.712906,0.031862,0.000000
29.150002,3.327148,-191.846344,0.007355,0.001237,0.031411,14.799895,0.753943,0.314108,-191.846344,0.032261,0.000000
29.390001,3.394173,-191.801865,0.007377,0.001254,0.031845,15.098034,0.769131,0.318446,-191.801865,0.032660,0.000000
29.630001,3.476471,-191.801865,0.007390,0.001270,0.032252,15.464115,0.787780,0.322522,-191.801865,0.033059,0.000000
29.870001,3.442215,-191.801865,0.007407,0.001279,0.032495,15.311737,0.780017,0.324948,-191.801865,0.033458,0.000000
30.110001,3.475723,-191.757385,0.007386,0.001293,0.032842,15.460790,0.787610,0.328419,-191.757385,0.033857,0.000000
30.350002,3.635101,-191.890823,0.007429,0.001315,0.033397,16.169739,0.823726,0.333968,-191.890823,0.034264,0.000000
30.590002,3.655952,-191.801865,0.007476,0.001331,0.033813,16.262489,0.828451,0.338131,-191.801865,0.034663,0.000000
30.830002,3.578125,-191.801865,0.007468,0.001342,0.034091,15.916295,0.810815,0.340905,-191.801865,0.035062,0.000000
31.070002,3.688721,-191.801865,0.007511,0.001362,0.034585,16.408249,0.835876,0.345849,-191.801865,0.035461,0.000000
31.310001,3.741974,-191.801865,0.007502,0.001377,0.034966,16.645132,0.847943,0.349664,-191.801865,0.035860,0.000000
31.550001,3.804527,-191.846344,0.007541,0.001395,0.035444,16.923382,0.862118,0.354436,-191.846344,0.036259,0.000000
31.790001,3.724846,-191.846344,0.007545,0.001403,0.035626,16.568941,0.844062,0.356257,-191.846344,0.036657,0.000000
32.030003,3.843254,-191.890823,0.007562,0.001421,0.036085,17.095648,0.870894,0.360852,-191.890823,0.037056,0.000000
32.270000,3.987366,-191.846344,0.007562,0.001445,0.036692,17.736689,0.903550,0.366923,-191.846344,0.037464,0.000000
32.510002,4.009705,-191.846344,0.007610,0.001461,0.037109,17.836058,0.908612,0.371086,-191.846344,0.037863,0.000000
32.750000,3.956459,-191.890823,0.007623,0.001474,0.037438,17.599209,0.896546,0.374383,-191.890823,0.038262,0.000000
32.990002,4.018272,-191.846344,0.007649,0.001490,0.037854,17.874168,0.910554,0.378542,-191.846344,0.038661,0.000000
33.230003,4.104286,-191.890823,0.007640,0.001508,0.038314,18.256777,0.930045,0.383141,-191.890823,0.039060,0.000000
33.470001,4.137428,-191.890823,0.007687,0.001522,0.038652,18.404200,0.937555,0.386521,-191.890823,0.039459,0.000000
33.710003,4.176529,-191.935303,0.007687,0.001536,0.039008,18.578129,0.946415,0.390079,-191.935303,0.039858,0.000000
33.950001,4.213020,-191.935303,0.007692,0.001551,0.039407,18.740450,0.954684,0.394068,-191.935303,0.040257,0.000000
34.190002,4.445007,-191.935303,0.007726,0.001574,0.039970,19.772381,1.007253,0.399704,-191.935303,0.040664,0.000000
34.430000,4.452827,-191.935303,0.007731,0.001590,0.040387,19.807165,1.009025,0.403867,-191.935303,0.041063,0.000000
34.670002,4.376869,-191.890823,0.007756,0.001602,0.040699,19.469286,0.991813,0.406990,-191.890823,0.041462,0.000000
34.910000,4.398094,-191.935303,0.007774,0.001617,0.041072,19.563700,0.996622,0.410718,-191.935303,0.041861,0.000000
35.150002,4.536240,-191.935303,0.007782,0.001634,0.041514,20.178202,1.027927,0.415142,-191.935303,0.042260,0.000000
35.390003,4.569756,-191.935303,0.007804,0.001650,0.041913,20.327288,1.035521,0.419132,-191.935303,0.042659,0.000000
35.630001,4.576828,-191.979782,0.007830,0.001661,0.042199,20.358747,1.037124,0.421993,-191.979782,0.043058,0.000000
35.870003,4.703812,-191.935303,0.007843,0.001680,0.042676,20.923599,1.065899,0.426762,-191.935303,0.043457,0.000000
36.110001,4.780144,-191.935303,0.007877,0.001697,0.043093,21.263142,1.083196,0.430925,-191.935303,0.043864,0.000000
36.350002,4.914948,-192.024261,0.007890,0.001716,0.043578,21.862778,1.113743,0.435781,-192.024261,0.044263,0.000000
36.590000,4.844193,-191.935303,0.007903,0.001728,0.043890,21.548044,1.097710,0.438904,-191.935303,0.044662,0.000000
36.830002,4.862068,-192.068741,0.007920,0.001742,0.044246,21.627560,1.101760,0.442458,-192.068741,0.045061,0.000000
37.070004,4.905632,-192.024261,0.007920,0.001756,0.044610,21.821341,1.111632,0.446099,-192.024261,0.045460,0.000000
37.310001,5.070969,-192.024261,0.007946,0.001775,0.045087,22.556795,1.149098,0.450872,-192.024261,0.045859,0.000000
37.550003,5.086609,-192.024261,0.007963,0.001788,0.045408,22.626366,1.152642,0.454078,-192.024261,0.046258,0.000000
37.790001,5.063896,-192.068741,0.008011,0.001797,0.045642,22.525335,1.147495,0.456420,-192.068741,0.046657,0.000000
38.030003,5.337959,-192.068741,0.008006,0.001822,0.046275,23.744429,1.209599,0.462753,-192.068741,0.047064,0.000000
38.270000,5.355087,-192.024261,0.008050,0.001838,0.046683,23.820618,1.213480,0.466829,-192.024261,0.047463,0.000000
38.510002,5.361794,-192.068741,0.008032,0.001851,0.047012,23.850449,1.215000,0.470122,-192.068741,0.047862,0.000000
38.750000,5.496590,-192.024261,0.008058,0.001870,0.047498,24.450052,1.245545,0.474978,-192.024261,0.048261,0.000000
38.990002,5.502922,-192.024261,0.008058,0.001883,0.047836,24.478220,1.246980,0.478362,-192.024261,0.048660,0.000000
39.230003,5.648148,-192.113220,0.008097,0.001900,0.048261,25.124216,1.279889,0.482612,-192.113220,0.049059,0.000000
39.470001,5.677193,-192.068741,0.008088,0.001913,0.048599,25.253414,1.286470,0.485992,-192.068741,0.049458,0.000000
39.710003,5.655220,-192.068741,0.008110,0.001924,0.048877,25.155676,1.281491,0.488770,-192.068741,0.049857,0.000000
39.950001,5.990356,-192.113220,0.008132,0.001947,0.049449,26.646437,1.357434,0.494493,-192.113220,0.050265,0.000000
40.190002,5.959450,-192.024261,0.008183,0.001960,0.049779,26.508957,1.350431,0.497786,-192.024261,0.050663,0.000000
40.430000,5.949394,-192.113220,0.008166,0.001972,0.050091,26.464228,1.348152,0.500908,-192.113220,0.051062,0.000000
40.670002,6.132973,-192.113220,0.008192,0.001990,0.050542,27.280825,1.389751,0.505420,-192.113220,0.051461,0.000000
40.910004,6.198143,-192.157715,0.008201,0.002006,0.050941,27.570717,1.404519,0.509409,-192.157715,0.051860,0.000000
41.150002,6.369431,-192.113220,0.008205,0.002024,0.051418,28.332642,1.443334,0.514178,-192.113220,0.052259,0.000000
41.390003,6.220482,-192.068741,0.008222,0.002033,0.051626,27.670086,1.409581,0.516260,-192.068741,0.052658,0.000000
41.630001,6.326981,-192.157715,0.008248,0.002044,0.051912,28.143816,1.433714,0.519121,-192.157715,0.053065,0.000000
41.870003,6.517265,-192.157715,0.008252,0.002063,0.052406,28.990244,1.476833,0.524064,-192.157715,0.053464,0.000000
42.110001,6.821495,-192.202194,0.008265,0.002087,0.053005,30.343525,1.545773,0.530048,-192.202194,0.053863,0.000000
42.350002,6.795799,-192.157715,0.008308,0.002100,0.053352,30.229225,1.539950,0.533519,-192.157715,0.054262,0.000000
42.590000,6.892616,-192.113220,0.008321,0.002118,0.053785,30.659889,1.561889,0.537853,-192.113220,0.054661,0.000000
42.830002,6.898575,-192.157715,0.008334,0.002129,0.054071,30.686394,1.563239,0.540714,-192.157715,0.055060,0.000000
43.070004,7.094444,-192.113220,0.008351,0.002145,0.054479,31.557665,1.607624,0.544790,-192.113220,0.055459,0.000000
43.310001,7.119392,-192.157715,0.008364,0.002158,0.054817,31.668638,1.613277,0.548174,-192.157715,0.055858,0.000000
43.550003,7.387497,-192.202194,0.008390,0.002176,0.055277,32.861229,1.674031,0.552769,-192.202194,0.056265,0.000000
43.790001,7.504791,-192.202194,0.008386,0.002194,0.055728,33.382980,1.700610,0.557280,-192.202194,0.056664,0.000000
44.030003,7.823547,-192.202194,0.008451,0.002217,0.056309,34.800877,1.772841,0.563090,-192.202194,0.057063,0.000000
44.270000,7.731567,-192.246674,0.008438,0.002227,0.056569,34.391731,1.751998,0.565690,-192.246674,0.057462,0.000000
44.510002,7.823547,-192.246674,0.008446,0.002243,0.056968,34.800877,1.772841,0.569680,-192.246674,0.057861,0.000000
44.750004,7.947548,-192.157715,0.008489,0.002258,0.057341,35.352459,1.800940,0.573408,-192.157715,0.058260,0.000000
44.990002,8.164642,-192.246674,0.008494,0.002276,0.057801,36.318142,1.850134,0.578006,-192.246674,0.058659,0.000000
45.230003,8.290871,-192.246674,0.008502,0.002290,0.058173,36.879635,1.878738,0.581735,-192.246674,0.059058,0.000000
45.470001,8.343376,-192.202194,0.008528,0.002303,0.058486,37.113190,1.890636,0.584857,-192.202194,0.059466,0.000000
45.710003,8.567177,-192.246674,0.008545,0.002320,0.058919,38.108707,1.941350,0.589195,-192.246674,0.059865,0.000000
45.950001,8.935074,-192.202194,0.008550,0.002340,0.059448,39.745193,2.024717,0.594482,-192.202194,0.060263,0.000000
46.190002,8.747398,-192.291153,0.008558,0.002349,0.059656,38.910370,1.982189,0.596564,-192.291153,0.060662,0.000000
46.430000,9.149193,-192.246674,0.008589,0.002370,0.060203,40.697643,2.073237,0.602029,-192.246674,0.061061,0.000000
46.670002,9.129829,-192.291153,0.008610,0.002381,0.060480,40.611511,2.068849,0.604804,-192.291153,0.061460,0.000000
46.910004,9.375595,-192.246674,0.008606,0.002398,0.060897,41.704731,2.124540,0.608967,-192.246674,0.061859,0.000000
47.150002,9.787437,-192.246674,0.008619,0.002417,0.061400,43.536697,2.217865,0.613997,-192.246674,0.062258,0.000000
47.390003,9.661949,-192.335632,0.008653,0.002426,0.061625,42.978497,2.189429,0.616249,-192.335632,0.062666,0.000000
47.630001,9.911064,-192.335632,0.008670,0.002445,0.062102,44.086617,2.245879,0.621022,-192.335632,0.063065,0.000000
47.870003,10.346001,-192.291153,0.008679,0.002463,0.062562,46.021309,2.344437,0.625617,-192.291153,0.063464,0.000000
48.110001,10.541862,-192.335632,0.008701,0.002480,0.062987,46.892548,2.388820,0.629867,-192.335632,0.063863,0.000000
48.350002,10.652458,-192.291153,0.008714,0.002496,0.063394,47.384502,2.413882,0.633943,-192.291153,0.064261,0.000000
48.590004,10.727676,-192.335632,0.008722,0.002508,0.063698,47.719090,2.430926,0.636979,-192.335632,0.064660,0.000000
48.830002,11.187561,-192.291153,0.008752,0.002528,0.064201,49.764755,2.535138,0.642005,-192.291153,0.065059,0.000000
49.070004,11.136917,-192.380112,0.008765,0.002538,0.064470,49.539482,2.523662,0.644696,-192.380112,0.065458,0.000000
49.310001,11.108246,-192.380112,0.008765,0.002546,0.064669,49.411945,2.517164,0.646691,-192.380112,0.065866,0.000000
49.550003,11.572968,-192.335632,0.008783,0.002565,0.065146,51.479130,2.622472,0.651460,-192.335632,0.066265,0.000000
49.790001,12.539268,-192.380112,0.008813,0.002595,0.065918,55.777451,2.841439,0.659177,-192.380112,0.066664,0.000000
50.030003,12.507988,-192.335632,0.008834,0.002610,0.066282,55.638309,2.834351,0.662822,-192.335632,0.067063,0.000000
50.270004,12.559753,-192.380112,0.008843,0.002621,0.066586,55.868572,2.846081,0.665858,-192.380112,0.067462,0.000000
50.510002,12.734764,-192.380112,0.008852,0.002635,0.066941,56.647060,2.885739,0.669412,-192.380112,0.067861,0.000000
50.750004,13.142143,-192.335632,0.008847,0.002655,0.067427,58.459171,2.978052,0.674268,-192.335632,0.068259,0.000000
50.990002,13.466103,-192.424591,0.008873,0.002669,0.067782,59.900215,3.051462,0.677822,-192.424591,0.068658,0.000000
51.230003,13.392006,-192.380112,0.008890,0.002678,0.068034,59.570618,3.034672,0.680339,-192.380112,0.069066,0.000000
51.470001,13.668678,-192.424591,0.008912,0.002692,0.068372,60.801319,3.097367,0.683722,-192.424591,0.069465,0.000000
51.710003,14.480820,-192.335632,0.008903,0.002715,0.068962,64.413902,3.281401,0.689619,-192.335632,0.069864,0.000000
51.950001,14.823029,-192.335632,0.008921,0.002732,0.069395,65.936127,3.358946,0.693953,-192.335632,0.070263,0.000000
52.190002,14.856918,-192.424591,0.008955,0.002745,0.069716,66.086876,3.366626,0.697163,-192.424591,0.070662,0.000000
52.430004,15.380096,-192.424591,0.008968,0.002763,0.070176,68.414085,3.485180,0.701757,-192.424591,0.071061,0.000000
52.670002,15.769226,-192.469070,0.008968,0.002781,0.070636,70.145020,3.573358,0.706356,-192.469070,0.071460,0.000000
52.910004,16.088356,-192.424591,0.008977,0.002795,0.070982,71.564583,3.645674,0.709823,-192.424591,0.071858,0.000000
53.150002,15.845192,-192.424591,0.008985,0.002803,0.071199,70.482933,3.590572,0.711992,-192.424591,0.072266,0.000000
53.390003,16.436523,-192.513550,0.009024,0.002823,0.071693,73.113304,3.724569,0.716935,-192.513550,0.072665,0.000000
53.630001,17.349205,-192.424591,0.009046,0.002844,0.072240,77.173119,3.931386,0.722400,-192.424591,0.073064,0.000000
53.870003,17.736847,-192.469070,0.009033,0.002862,0.072691,78.897438,4.019227,0.726908,-192.469070,0.073463,0.000000
54.110004,18.020218,-192.469070,0.009080,0.002878,0.073090,80.157936,4.083440,0.730897,-192.469070,0.073861,0.000000
54.350002,18.226891,-192.469070,0.009097,0.002890,0.073411,81.077255,4.130272,0.734107,-192.469070,0.074260,0.000000
54.590004,18.940353,-192.513550,0.009093,0.002910,0.073914,84.250900,4.291945,0.739137,-192.513550,0.074659,0.000000
54.830002,19.007378,-192.469070,0.009123,0.002920,0.074165,84.549042,4.307134,0.741650,-192.469070,0.075067,0.000000
55.070004,19.199898,-192.513550,0.009110,0.002933,0.074495,85.405411,4.350759,0.744947,-192.513550,0.075466,0.000000
55.310001,20.071991,-192.558044,0.009123,0.002953,0.074998,89.284676,4.548378,0.749977,-192.558044,0.075865,0.000000
55.550003,20.980209,-192.513550,0.009097,0.002974,0.075544,93.324631,4.754183,0.755439,-192.513550,0.076264,0.000000
55.790001,21.389076,-192.469070,0.009166,0.002991,0.075960,95.143364,4.846834,0.759602,-192.469070,0.076663,0.000000
56.030003,21.423332,-192.513550,0.009166,0.003002,0.076246,95.295738,4.854597,0.762463,-192.513550,0.077062,0.000000
56.270004,21.824379,-192.558044,0.009179,0.003018,0.076663,97.079689,4.945475,0.766627,-192.558044,0.077461,0.000000
56.510002,22.526672,-192.513550,0.009192,0.003036,0.077114,100.203644,5.104617,0.771138,-192.513550,0.077859,0.000000
56.750004,23.041290,-192.558044,0.009188,0.003052,0.077513,102.492775,5.221231,0.775128,-192.558044,0.078267,0.000000
56.990002,23.189865,-192.558044,0.009240,0.003060,0.077721,103.153671,5.254899,0.777209,-192.558044,0.078666,0.000000
57.230003,24.151703,-192.558044,0.009240,0.003082,0.078293,107.432137,5.472854,0.782932,-192.558044,0.079065,0.000000
57.470001,24.631325,-192.602524,0.009235,0.003098,0.078683,109.565605,5.581538,0.786834,-192.602524,0.079464,0.000000
57.710003,25.487030,-192.602524,0.009240,0.003116,0.079143,113.371971,5.775444,0.791429,-192.602524,0.079863,0.000000
57.950005,25.655716,-192.602524,0.009274,0.003128,0.079446,114.122322,5.813668,0.794465,-192.602524,0.080262,0.000000
58.190002,26.157677,-192.602524,0.009283,0.003142,0.079819,116.355156,5.927414,0.798193,-192.602524,0.080661,0.000000
58.430004,26.777679,-192.602524,0.009278,0.003160,0.080253,119.113068,6.067909,0.802530,-192.602524,0.081060,0.000000
58.670002,27.469170,-192.602524,0.009300,0.003175,0.080643,122.188972,6.224603,0.806432,-192.602524,0.081467,0.000000
58.910004,27.902245,-192.602524,0.009313,0.003187,0.080947,124.115379,6.322739,0.809468,-192.602524,0.081866,0.000000
59.150002,28.042999,-192.602524,0.009309,0.003197,0.081207,124.741493,6.354634,0.812072,-192.602524,0.082265,0.000000
59.390003,29.436043,-192.691483,0.009330,0.003221,0.081823,130.938065,6.670303,0.818226,-192.691483,0.082664,0.000000
59.630001,30.193451,-192.647003,0.009326,0.003239,0.082265,134.307175,6.841934,0.822651,-192.647003,0.083063,0.000000
59.870003,30.586304,-192.647003,0.009356,0.003253,0.082638,136.054672,6.930955,0.826379,-192.647003,0.083462,0.000000
60.110004,31.519470,-192.647003,0.009378,0.003271,0.083089,140.205612,7.142414,0.830890,-192.647003,0.083861,0.000000
60.350002,32.059776,-192.647003,0.009365,0.003286,0.083471,142.609009,7.264849,0.834706,-192.647003,0.084260,0.000000
60.590004,32.712547,-192.647003,0.009390,0.003301,0.083843,145.512680,7.412769,0.838434,-192.647003,0.084667,0.000000
60.830002,33.182480,-192.647003,0.009395,0.003313,0.084138,147.603043,7.519258,0.841382,-192.647003,0.085066,0.000000
61.070004,33.461014,-192.647003,0.009421,0.003323,0.084416,148.842026,7.582374,0.844157,-192.647003,0.085465,0.000000
61.310001,34.931892,-192.647003,0.009425,0.003345,0.084971,155.384811,7.915680,0.849709,-192.647003,0.085864,0.000000
61.550003,35.456192,-192.735962,0.009416,0.003360,0.085352,157.717026,8.034488,0.853524,-192.735962,0.086263,0.000000
61.790005,35.879951,-192.691483,0.009438,0.003372,0.085656,159.601990,8.130513,0.856560,-192.691483,0.086662,0.000000
62.030003,36.799706,-192.647003,0.009434,0.003389,0.086089,163.693268,8.338932,0.860893,-192.647003,0.087061,0.000000
62.270004,37.751862,-192.691483,0.009442,0.003408,0.086575,167.928665,8.554694,0.865753,-192.691483,0.087460,0.000000
62.510002,38.860794,-192.691483,0.009481,0.003424,0.086966,172.861450,8.805982,0.869655,-192.691483,0.087867,0.000000
62.750004,38.859673,-192.691483,0.009468,0.003431,0.087156,172.856461,8.805728,0.871563,-192.691483,0.088266,0.000000
62.990002,39.876991,-192.735962,0.009481,0.003450,0.087624,177.381714,9.036255,0.876245,-192.735962,0.088665,0.000000
63.230003,40.907349,-192.780441,0.009490,0.003466,0.088041,181.964981,9.269737,0.880408,-192.780441,0.089064,0.000000
63.470001,42.453438,-192.735962,0.009481,0.003489,0.088613,188.842316,9.620087,0.886131,-192.735962,0.089463,0.000000
63.710003,42.933052,-192.735962,0.009503,0.003502,0.088951,190.975754,9.728768,0.889515,-192.735962,0.089862,0.000000
63.950005,43.834198,-192.780441,0.009511,0.003517,0.089324,194.984253,9.932972,0.893243,-192.780441,0.090261,0.000000
64.190002,44.235245,-192.780441,0.009533,0.003530,0.089654,196.768188,10.023850,0.896539,-192.780441,0.090660,0.000000
64.430000,45.191124,-192.780441,0.009533,0.003544,0.090018,201.020157,10.240455,0.900181,-192.780441,0.091067,0.000000
64.670006,45.870705,-192.735962,0.009541,0.003558,0.090382,204.043091,10.394450,0.903822,-192.735962,0.091466,0.000000
64.910004,46.988564,-192.780441,0.009563,0.003576,0.090825,209.015564,10.647760,0.908246,-192.780441,0.091865,0.000000
65.150002,48.089668,-192.780441,0.009554,0.003594,0.091284,213.913528,10.897274,0.912841,-192.780441,0.092264,0.000000
65.389999,49.761993,-192.735962,0.009550,0.003616,0.091839,221.352402,11.276229,0.918393,-192.735962,0.092663,0.000000
65.630005,50.271774,-192.824921,0.009572,0.003626,0.092091,223.620026,11.391747,0.920907,-192.824921,0.093062,0.000000
65.870003,51.079445,-192.824921,0.009585,0.003642,0.092498,227.212723,11.574768,0.924983,-192.824921,0.093461,0.000000
66.110001,51.884888,-192.780441,0.009589,0.003656,0.092854,230.795502,11.757283,0.928537,-192.780441,0.093860,0.000000
66.350006,52.754753,-192.824921,0.009593,0.003674,0.093322,234.664856,11.954398,0.933223,-192.824921,0.094267,0.000000
66.590004,54.014488,-192.735962,0.009615,0.003689,0.093712,240.268448,12.239858,0.937125,-192.735962,0.094666,0.000000
66.830002,54.723488,-192.824921,0.009602,0.003701,0.094016,243.422226,12.400519,0.940160,-192.824921,0.095065,0.000000
67.070000,55.839111,-192.824921,0.009610,0.003720,0.094476,248.384766,12.653323,0.944755,-192.824921,0.095464,0.000000
67.310005,57.465637,-192.869400,0.009628,0.003739,0.094970,255.619919,13.021899,0.949698,-192.869400,0.095863,0.000000
67.550003,57.818275,-192.869400,0.009619,0.003747,0.095178,257.188538,13.101809,0.951780,-192.869400,0.096262,0.000000
67.790001,59.357658,-192.824921,0.009636,0.003768,0.095716,264.036041,13.450638,0.957158,-192.824921,0.096661,0.000000
68.030006,60.012291,-192.869400,0.009662,0.003780,0.096011,266.947998,13.598980,0.960107,-192.869400,0.097069,0.000000
68.270004,61.044884,-192.824921,0.009662,0.003796,0.096418,271.541199,13.832969,0.964183,-192.824921,0.097467,0.000000
68.510002,62.708267,-192.869400,0.009641,0.003816,0.096921,278.940308,14.209896,0.969213,-192.869400,0.097866,0.000000
68.750000,63.228104,-192.958359,0.009662,0.003825,0.097147,281.252655,14.327693,0.971465,-192.958359,0.098265,0.000000
68.990005,64.209671,-192.869400,0.009671,0.003843,0.097606,285.618896,14.550119,0.976064,-192.869400,0.098664,0.000000
69.230003,65.970627,-192.958359,0.009679,0.003862,0.098092,293.451996,14.949158,0.980920,-192.958359,0.099063,0.000000
69.470001,67.254196,-192.869400,0.009675,0.003878,0.098508,299.161591,15.240019,0.985083,-192.869400,0.099462,0.000000
69.710007,67.142853,-192.913879,0.009714,0.003875,0.098413,298.666321,15.214788,0.984129,-192.913879,0.098629,0.000000
69.950005,66.614090,-192.913879,0.009718,0.003875,0.098413,296.314270,15.094969,0.984129,-192.913879,0.098413,0.000000
70.190002,66.178406,-192.869400,0.009722,0.003873,0.098387,294.376251,14.996241,0.983868,-192.869400,0.098413,0.000000
70.430000,65.779602,-192.958359,0.009714,0.003873,0.098387,292.602295,14.905870,0.983868,-192.958359,0.098413,0.000000
70.670006,65.425842,-192.958359,0.009727,0.003873,0.098378,291.028687,14.825707,0.983781,-192.958359,0.098413,0.000000
70.910004,65.117142,-192.958359,0.009705,0.003873,0.098378,289.655518,14.755754,0.983781,-192.958359,0.098413,0.000000
71.150002,64.859085,-192.913879,0.009740,0.003873,0.098378,288.507629,14.697279,0.983781,-192.913879,0.098413,0.000000
71.390007,64.595459,-192.913879,0.009740,0.003873,0.098369,287.334961,14.637540,0.983694,-192.913879,0.098413,0.000000
71.630005,64.379105,-193.002853,0.009731,0.003873,0.098369,286.372559,14.588514,0.983694,-193.002853,0.098413,0.000000
71.870003,64.155304,-192.958359,0.009722,0.003873,0.098369,285.377045,14.537800,0.983694,-192.958359,0.098413,0.000000
72.110001,63.990723,-193.047333,0.009744,0.003873,0.098369,284.644958,14.500505,0.983694,-193.047333,0.098413,0.000000
72.350006,63.797455,-192.958359,0.009731,0.003873,0.098369,283.785248,14.456710,0.983694,-192.958359,0.098413,0.000000
72.590004,63.649628,-193.002853,0.009718,0.003873,0.098369,283.127686,14.423211,0.983694,-193.002853,0.098413,0.000000
72.830002,63.494720,-193.002853,0.009735,0.003873,0.098369,282.438629,14.388109,0.983694,-193.002853,0.098413,0.000000
73.070000,63.346893,-192.958359,0.009731,0.003872,0.098361,281.781067,14.354611,0.983607,-192.958359,0.098413,0.000000
73.310005,63.195328,-193.002853,0.009727,0.003872,0.098361,281.106873,14.320266,0.983607,-193.002853,0.098413,0.000000
73.550003,63.103355,-193.002853,0.009740,0.003872,0.098361,280.697754,14.299425,0.983607,-193.002853,0.098413,0.000000
73.790001,62.957016,-193.002853,0.009740,0.003872,0.098361,280.046783,14.266264,0.983607,-193.002853,0.098413,0.000000
74.030006,62.870995,-193.047333,0.009740,0.003872,0.098361,279.664154,14.246771,0.983607,-193.047333,0.098413,0.000000
74.270004,62.756302,-193.002853,0.009735,0.003872,0.098361,279.153961,14.220781,0.983607,-193.002853,0.098413,0.000000
74.510002,62.652412,-193.047333,0.009727,0.003872,0.098361,278.691864,14.197240,0.983607,-193.047333,0.098413,0.000000
74.750000,62.574211,-193.047333,0.009735,0.003872,0.098361,278.343994,14.179519,0.983607,-193.047333,0.098413,0.000000
74.990005,62.473297,-193.047333,0.009727,0.003872,0.098361,277.895111,14.156651,0.983607,-193.047333,0.098413,0.000000
75.230003,62.372757,-193.047333,0.009753,0.003872,0.098361,277.447876,14.133869,0.983607,-193.047333,0.098413,0.000000
75.470001,62.294563,-193.091812,0.009753,0.003872,0.098361,277.100067,14.116150,0.983607,-193.091812,0.098413,0.000000
75.710007,62.230141,-193.091812,0.009731,0.003872,0.098361,276.813477,14.101552,0.983607,-193.091812,0.098413,0.000000
75.950005,62.137047,-193.091812,0.009740,0.003872,0.098361,276.399384,14.080456,0.983607,-193.091812,0.098413,0.000000
76.190002,62.050659,-193.091812,0.009740,0.003872,0.098361,276.015106,14.060881,0.983607,-193.091812,0.098413,0.000000
76.430000,61.997780,-193.091812,0.009774,0.003872,0.098361,275.779907,14.048898,0.983607,-193.091812,0.098413,0.000000
76.670006,61.925911,-193.136292,0.009757,0.003872,0.098361,275.460205,14.032612,0.983607,-193.136292,0.098413,0.000000
76.910004,61.863724,-193.180771,0.009740,0.003872,0.098361,275.183594,14.018520,0.983607,-193.180771,0.098413,0.000000
77.150002,61.800049,-193.091812,0.009740,0.003872,0.098361,274.900360,14.004091,0.983607,-193.091812,0.098413,0.000000
77.390007,61.753502,-193.091812,0.009727,0.003872,0.098361,274.693298,13.993543,0.983607,-193.091812,0.098413,0.000000
77.630005,61.682007,-193.180771,0.009757,0.003872,0.098361,274.375275,13.977343,0.983607,-193.180771,0.098413,0.000000
77.870003,61.633232,-193.136292,0.009757,0.003872,0.098361,274.158295,13.966290,0.983607,-193.136292,0.098413,0.000000
78.110001,61.559128,-193.180771,0.009753,0.003872,0.098361,273.828674,13.949497,0.983607,-193.180771,0.098413,0.000000
78.350006,61.509972,-193.136292,0.009748,0.003872,0.098361,273.610016,13.938359,0.983607,-193.136292,0.098413,0.000000
78.590004,61.462685,-193.136292,0.009761,0.003872,0.098361,273.399689,13.927644,0.983607,-193.136292,0.098413,0.000000
78.830002,61.421349,-193.091812,0.009740,0.003872,0.098361,273.215790,13.918277,0.983607,-193.091812,0.098413,0.000000
79.070007,61.362144,-193.136292,0.009744,0.003872,0.098361,272.952454,13.904860,0.983607,-193.136292,0.098413,0.000000
79.310005,61.315224,-193.225250,0.009761,0.003872,0.098361,272.743744,13.894228,0.983607,-193.225250,0.098413,0.000000
79.550003,61.277611,-193.136292,0.009740,0.003872,0.098361,272.576416,13.885705,0.983607,-193.136292,0.098413,0.000000
79.790001,61.216545,-193.180771,0.009744,0.003872,0.098361,272.304779,13.871868,0.983607,-193.180771,0.098413,0.000000
80.030006,61.193459,-193.225250,0.009753,0.003872,0.098361,272.202087,13.866636,0.983607,-193.225250,0.098413,0.000000
80.270004,61.142441,-193.136292,0.009744,0.003872,0.098361,271.975159,13.855076,0.983607,-193.136292,0.098413,0.000000
80.510002,61.099991,-193.269730,0.009735,0.003872,0.098361,271.786346,13.845456,0.983607,-193.269730,0.098413,0.000000
80.750008,61.075043,-193.225250,0.009748,0.003872,0.098361,271.675354,13.839803,0.983607,-193.225250,0.098413,0.000000
80.990005,61.023651,-193.225250,0.009744,0.003872,0.098361,271.446747,13.828157,0.983607,-193.225250,0.098413,0.000000
81.230003,60.994240,-193.180771,0.009740,0.003872,0.098361,271.315918,13.821492,0.983607,-193.180771,0.098413,0.000000
81.470001,60.940247,-193.180771,0.009731,0.003872,0.098361,271.075745,13.809258,0.983607,-193.180771,0.098413,0.000000
81.710007,60.934654,-193.269730,0.009740,0.003872,0.098361,271.050873,13.807990,0.983607,-193.269730,0.098413,0.000000
81.950005,60.889977,-193.269730,0.009757,0.003872,0.098361,270.852142,13.797866,0.983607,-193.269730,0.098413,0.000000
82.190002,60.843430,-193.269730,0.009761,0.003872,0.098361,270.645081,13.787318,0.983607,-193.269730,0.098413,0.000000
82.430000,60.829277,-193.225250,0.009766,0.003872,0.098361,270.582153,13.784111,0.983607,-193.225250,0.098413,0.000000
82.670006,60.774162,-193.225250,0.009744,0.003872,0.098361,270.336975,13.771623,0.983607,-193.225250,0.098413,0.000000
82.910004,60.757034,-193.269730,0.009757,0.003872,0.098361,270.260773,13.767741,0.983607,-193.269730,0.098413,0.000000
83.150002,60.710487,-193.269730,0.009735,0.003872,0.098361,270.053741,13.757193,0.983607,-193.269730,0.098413,0.000000
83.390007,60.690010,-193.269730,0.009735,0.003872,0.098361,269.962646,13.752553,0.983607,-193.269730,0.098413,0.000000
83.630005,60.665802,-193.269730,0.009740,0.003872,0.098361,269.854950,13.747066,0.983607,-193.269730,0.098413,0.000000
83.870003,60.618889,-193.314209,0.009766,0.003872,0.098361,269.646271,13.736437,0.983607,-193.314209,0.098413,0.000000
84.110001,60.591705,-193.314209,0.009757,0.003872,0.098361,269.525360,13.730276,0.983607,-193.314209,0.098413,0.000000
84.350006,60.569733,-193.269730,0.009748,0.003872,0.098361,269.427612,13.725298,0.983607,-193.269730,0.098413,0.000000
84.590004,60.546646,-193.314209,0.009735,0.003872,0.098361,269.324921,13.720066,0.983607,-193.314209,0.098413,0.000000
84.830002,60.492653,-193.269730,0.009761,0.003872,0.098361,269.084747,13.707830,0.983607,-193.269730,0.098413,0.000000
85.070007,60.496750,-193.358688,0.009744,0.003872,0.098361,269.102997,13.708759,0.983607,-193.358688,0.098413,0.000000
85.310005,60.449455,-193.314209,0.009748,0.003872,0.098361,268.892609,13.698043,0.983607,-193.314209,0.098413,0.000000
85.550003,60.438660,-193.314209,0.009727,0.003872,0.098361,268.844574,13.695596,0.983607,-193.314209,0.098413,0.000000
85.790001,60.402534,-193.403168,0.009748,0.003872,0.098361,268.683899,13.687410,0.983607,-193.403168,0.098413,0.000000
86.030006,60.358223,-193.358688,0.009748,0.003872,0.098352,268.486786,13.677369,0.983520,-193.358688,0.098413,0.000000
86.270004,60.359718,-193.314209,0.009748,0.003872,0.098352,268.493439,13.677708,0.983520,-193.314209,0.098413,0.000000
86.510002,60.313171,-193.358688,0.009761,0.003872,0.098352,268.286377,13.667159,0.983520,-193.358688,0.098413,0.000000
86.750008,60.288963,-193.358688,0.009740,0.003872,0.098352,268.178711,13.661674,0.983520,-193.358688,0.098413,0.000000
86.990005,60.270721,-193.447662,0.009744,0.003872,0.098352,268.097565,13.657541,0.983520,-193.447662,0.098413,0.000000
87.230003,60.237946,-193.358688,0.009731,0.003872,0.098352,267.951752,13.650113,0.983520,-193.358688,0.098413,0.000000
87.470001,60.223053,-193.447662,0.009766,0.003872,0.098352,267.885529,13.646739,0.983520,-193.447662,0.098413,0.000000
87.710007,60.179855,-193.403168,0.009727,0.003872,0.098352,267.693359,13.636950,0.983520,-193.403168,0.098413,0.000000
87.950005,60.173157,-193.403168,0.009761,0.003872,0.098352,267.663574,13.635432,0.983520,-193.403168,0.098413,0.000000
88.190002,60.141502,-193.447662,0.009735,0.003872,0.098352,267.522766,13.628260,0.983520,-193.447662,0.098413,0.000000
88.430008,60.129585,-193.447662,0.009740,0.003872,0.098352,267.469757,13.625559,0.983520,-193.447662,0.098413,0.000000
88.670006,60.112457,-193.447662,0.009753,0.003872,0.098352,267.393555,13.621677,0.983520,-193.447662,0.098413,0.000000
88.910004,60.070007,-193.403168,0.009748,0.003872,0.098352,267.204742,13.612059,0.983520,-193.403168,0.098413,0.000000
89.150002,60.086769,-193.447662,0.009753,0.003872,0.098352,267.279297,13.615856,0.983520,-193.447662,0.098413,0.000000
89.390007,60.040588,-193.492142,0.009757,0.003872,0.098352,267.073883,13.605392,0.983520,-193.492142,0.098413,0.000000
89.630005,60.008194,-193.447662,0.009757,0.003872,0.098352,266.929779,13.598051,0.983520,-193.447662,0.098413,0.000000
89.870003,59.999634,-193.492142,0.009753,0.003872,0.098352,266.891693,13.596111,0.983520,-193.492142,0.098413,0.000000
90.110001,59.972816,-193.492142,0.009753,0.003872,0.098352,266.772400,13.590034,0.983520,-193.492142,0.098413,0.000000
90.350006,59.950851,-193.492142,0.009757,0.003872,0.098352,266.674713,13.585057,0.983520,-193.492142,0.098413,0.000000
90.590004,59.937073,-193.492142,0.009722,0.003872,0.098352,266.613403,13.581935,0.983520,-193.492142,0.098413,0.000000
90.830002,59.921806,-193.447662,0.009766,0.003872,0.098352,266.545502,13.578475,0.983520,-193.447662,0.098413,0.000000
91.070007,59.901321,-193.536621,0.009757,0.003872,0.098352,266.454376,13.573833,0.983520,-193.536621,0.098413,0.000000
91.310005,59.885681,-193.492142,0.009740,0.003872,0.098352,266.384827,13.570290,0.983520,-193.492142,0.098413,0.000000
91.550003,59.864090,-193.581100,0.009740,0.003872,0.098352,266.288757,13.565397,0.983520,-193.581100,0.098413,0.000000
91.790001,59.845467,-193.492142,0.009740,0.003872,0.098352,266.205933,13.561176,0.983520,-193.492142,0.098413,0.000000
92.030006,59.822380,-193.536621,0.009753,0.003872,0.098352,266.103241,13.555945,0.983520,-193.536621,0.098413,0.000000
92.270004,59.812325,-193.581100,0.009740,0.003872,0.098352,266.058502,13.553667,0.983520,-193.581100,0.098413,0.000000
92.510002,59.789986,-193.492142,0.009753,0.003872,0.098352,265.959137,13.548605,0.983520,-193.492142,0.098413,0.000000
92.750008,59.770248,-193.492142,0.009757,0.003872,0.098352,265.871338,13.544131,0.983520,-193.492142,0.098413,0.000000
92.990005,59.747162,-193.581100,0.009761,0.003872,0.098352,265.768646,13.538900,0.983520,-193.581100,0.098413,0.000000
93.230003,59.726311,-193.581100,0.009753,0.003872,0.098352,265.675903,13.534175,0.983520,-193.581100,0.098413,0.000000
93.470001,59.720726,-193.581100,0.009770,0.003872,0.098352,265.651062,13.532909,0.983520,-193.581100,0.098413,0.000000
93.710007,59.690186,-193.581100,0.009744,0.003872,0.098352,265.515198,13.525990,0.983520,-193.581100,0.098413,0.000000
93.950005,59.695778,-193.536621,0.009757,0.003872,0.098352,265.540070,13.527257,0.983520,-193.536621,0.098413,0.000000
94.190002,59.664871,-193.581100,0.009735,0.003872,0.098352,265.402588,13.520252,0.983520,-193.581100,0.098413,0.000000
94.430008,59.650719,-193.536621,0.009748,0.003872,0.098352,265.339661,13.517046,0.983520,-193.536621,0.098413,0.000000
94.670006,59.635452,-193.670059,0.009757,0.003872,0.098352,265.271729,13.513586,0.983520,-193.670059,0.098413,0.000000
94.910004,59.633591,-193.581100,0.009757,0.003872,0.098352,265.263458,13.513165,0.983520,-193.581100,0.098413,0.000000
95.150002,59.610130,-193.625580,0.009735,0.003872,0.098352,265.159088,13.507849,0.983520,-193.625580,0.098413,0.000000
95.390007,59.589645,-193.581100,0.009753,0.003872,0.098352,265.067993,13.503206,0.983520,-193.581100,0.098413,0.000000
95.630005,59.576614,-193.625580,0.009761,0.003872,0.098352,265.010010,13.500254,0.983520,-193.625580,0.098413,0.000000
95.870003,59.557999,-193.670059,0.009744,0.003872,0.098352,264.927216,13.496036,0.983520,-193.670059,0.098413,0.000000
96.110008,59.555016,-193.581100,0.009757,0.003872,0.098352,264.913940,13.495359,0.983520,-193.581100,0.098413,0.000000
96.350006,59.519646,-193.625580,0.009774,0.003872,0.098352,264.756592,13.487345,0.983520,-193.625580,0.098413,0.000000
96.590004,59.519646,-193.625580,0.009766,0.003872,0.098352,264.756592,13.487345,0.983520,-193.625580,0.098413,0.000000
96.830002,59.498787,-193.625580,0.009761,0.003872,0.098352,264.663818,13.482618,0.983520,-193.625580,0.098413,0.000000
97.070007,59.480171,-193.670059,0.009727,0.003872,0.098352,264.581024,13.478399,0.983520,-193.670059,0.098413,0.000000
97.310005,59.467140,-193.625580,0.009779,0.003872,0.098352,264.523041,13.475446,0.983520,-193.625580,0.098413,0.000000
97.550003,59.470490,-193.714539,0.009766,0.003872,0.098352,264.537964,13.476205,0.983520,-193.714539,0.098413,0.000000
97.790001,59.442932,-193.625580,0.009744,0.003872,0.098352,264.415375,13.469961,0.983520,-193.625580,0.098413,0.000000
98.030006,59.434372,-193.670059,0.009757,0.003872,0.098352,264.377289,13.468021,0.983520,-193.670059,0.098413,0.000000
98.270004,59.429153,-193.759018,0.009766,0.003872,0.098352,264.354065,13.466839,0.983520,-193.759018,0.098413,0.000000
98.510002,59.404205,-193.714539,0.009748,0.003872,0.098352,264.243103,13.461185,0.983520,-193.714539,0.098413,0.000000
98.750008,59.390800,-193.759018,0.009744,0.003872,0.098352,264.183472,13.458147,0.983520,-193.759018,0.098413,0.000000
98.990005,59.378883,-193.759018,0.009748,0.003872,0.098352,264.130463,13.455447,0.983520,-193.759018,0.098413,0.000000
99.230003,59.371437,-193.670059,0.009770,0.003872,0.098352,264.097351,13.453760,0.983520,-193.670059,0.098413,0.000000
99.470001,59.354683,-193.759018,0.009744,0.003872,0.098352,264.022827,13.449963,0.983520,-193.759018,0.098413,0.000000
99.710007,59.352821,-193.670059,0.009753,0.003872,0.098352,264.014526,13.449542,0.983520,-193.670059,0.098413,0.000000
99.950005,59.323029,-193.714539,0.009753,0.003872,0.098352,263.882019,13.442790,0.983520,-193.714539,0.098413,0.000000
100.100006,59.309250,-193.803497,0.009731,0.003872,0.098352,263.820709,13.439669,0.983520,-193.803497,0.098413,0.000000