File: Data/compression sample NH 10,12,15/AutoNoheating-15-2-3-240201_02012024_182043.csv
Time (sec),S:Load (lbs),S:HL1 (DIM),S:LVDT (in),S:Position (in),Ch:Position (mm),Ch:Load (N),Ch:Stress (MPa),Ch:Strain (mm/mm),Ch:HL1 (DIM),Set Point (),Cycles ()
0.110000,-0.002975,-163.467499,-0.000004,-0.000000,-0.000000,-0.013236,-0.000674,-0.000000,-163.467499,0.000199,0.000000
0.330000,0.005959,-163.467499,-0.000026,-0.000000,-0.000000,0.026505,0.001350,-0.000000,-163.467499,0.000199,0.000000
0.550000,-0.006332,-163.511978,0.000013,0.000106,0.002680,-0.028168,-0.001435,0.026797,-163.511978,0.003790,0.000000
0.770000,0.010429,-163.556458,0.000069,0.000251,0.006374,0.046392,0.002363,0.063741,-163.556458,0.007449,0.000000
0.990000,0.026810,-163.511978,0.000233,0.000393,0.009973,0.119255,0.006075,0.099732,-163.511978,0.011126,0.000000
1.210000,0.016762,-163.467499,0.000345,0.000543,0.013780,0.074560,0.003798,0.137800,-163.467499,0.014786,0.000000
1.430000,0.021599,-163.556458,0.000509,0.000686,0.017431,0.096076,0.004894,0.174313,-163.556458,0.018446,0.000000
1.650000,-0.001862,-163.600937,0.000660,0.000830,0.021082,-0.008281,-0.000422,0.210822,-163.600937,0.022123,0.000000
1.870000,-0.011543,-163.556458,0.000832,0.000969,0.024612,-0.051347,-0.002616,0.246120,-163.556458,0.025783,0.000000
2.090000,-0.009308,-163.511978,0.000949,0.001115,0.028315,-0.041403,-0.002109,0.283148,-163.511978,0.029442,0.000000
2.310000,-0.004097,-163.511978,0.001099,0.001264,0.032096,-0.018224,-0.000928,0.320959,-163.511978,0.033102,0.000000
2.530000,0.031654,-163.511978,0.001242,0.001402,0.035600,0.140806,0.007173,0.355996,-163.511978,0.036779,0.000000
2.750000,0.035378,-163.600937,0.001358,0.001542,0.039155,0.157367,0.008017,0.391551,-163.600937,0.040439,0.000000
2.970000,0.033516,-163.600937,0.001561,0.001699,0.043144,0.149086,0.007595,0.431444,-163.600937,0.044099,0.000000
3.190000,0.045807,-163.556458,0.001707,0.001840,0.046743,0.203759,0.010380,0.467435,-163.556458,0.047776,0.000000
3.410000,0.029793,-163.556458,0.001845,0.001981,0.050316,0.132525,0.006751,0.503164,-163.556458,0.051435,0.000000
3.630000,-0.003349,-163.600937,0.002022,0.002122,0.053889,-0.014898,-0.000759,0.538893,-163.600937,0.055095,0.000000
3.850000,0.014526,-163.600937,0.002156,0.002271,0.057688,0.064617,0.003292,0.576879,-163.600937,0.058772,0.000000
4.070000,0.020851,-163.645416,0.002307,0.002413,0.061296,0.092750,0.004725,0.612956,-163.645416,0.062431,0.000000
4.290000,0.166077,-163.556458,0.002440,0.002553,0.064842,0.738746,0.037634,0.648424,-163.556458,0.066091,0.000000
4.510000,0.723518,-163.556458,0.002544,-0.000000,-0.000000,3.218370,0.163952,-0.000000,-163.556458,0.000191,0.000000
4.730000,0.665062,-163.600937,0.002552,-0.000000,-0.000009,2.958343,0.150705,-0.000087,-163.600937,0.000191,0.000000
4.950000,0.631546,-163.645416,0.002535,-0.000001,-0.000017,2.809257,0.143110,-0.000170,-163.645416,0.000191,0.000000
5.170000,0.598030,-163.600937,0.002561,-0.000001,-0.000017,2.660171,0.135516,-0.000170,-163.600937,0.000477,0.000000
5.390000,0.615158,-163.600937,0.002570,-0.000001,-0.000017,2.736360,0.139397,-0.000170,-163.600937,0.000850,0.000000
5.610000,0.618515,-163.600937,0.002557,-0.000000,-0.000009,2.751292,0.140158,-0.000087,-163.600937,0.001214,0.000000
5.830000,0.896301,-163.645416,0.002570,0.000033,0.000850,3.986947,0.203105,0.008501,-163.645416,0.001578,0.000000
6.050000,1.065735,-163.600937,0.002583,0.000050,0.001266,4.740625,0.241499,0.012664,-163.600937,0.001951,0.000000
6.270000,1.196060,-163.645416,0.002613,0.000065,0.001639,5.320342,0.271031,0.016392,-163.645416,0.002316,0.000000
6.490000,1.255638,-163.600937,0.002600,0.000072,0.001830,5.585357,0.284532,0.018300,-163.600937,0.002680,0.000000
6.710001,1.380760,-163.645416,0.002643,0.000089,0.002264,6.141928,0.312885,0.022637,-163.645416,0.003044,0.000000
6.930000,1.563965,-163.600937,0.002643,0.000106,0.002688,6.956863,0.354400,0.026884,-163.600937,0.003417,0.000000
7.150001,1.793350,-163.734375,0.002656,0.000121,0.003070,7.977220,0.406379,0.030699,-163.734375,0.003781,0.000000
7.370000,1.919952,-163.734375,0.002677,0.000133,0.003382,8.540375,0.435067,0.033822,-163.734375,0.004146,0.000000
7.590000,1.987350,-163.689896,0.002686,0.000141,0.003590,8.840177,0.450340,0.035904,-163.689896,0.004518,0.000000
7.810000,2.152687,-163.689896,0.002690,0.000153,0.003894,9.575630,0.487806,0.038939,-163.689896,0.004883,0.000000
8.030001,2.248756,-163.689896,0.002699,0.000165,0.004197,10.002968,0.509575,0.041974,-163.689896,0.005247,0.000000
8.250000,2.613686,-163.689896,0.002708,0.000191,0.004857,11.626254,0.592270,0.048568,-163.689896,0.005611,0.000000
8.470000,2.685555,-163.734375,0.002734,0.000198,0.005039,11.945943,0.608555,0.050388,-163.734375,0.005984,0.000000
8.690001,2.883278,-163.689896,0.002738,0.000215,0.005472,12.825460,0.653360,0.054722,-163.689896,0.006348,0.000000
8.910001,3.064629,-163.689896,0.002729,0.000230,0.005854,13.632149,0.694455,0.058537,-163.689896,0.006713,0.000000
9.130000,3.254906,-163.734375,0.002746,0.000244,0.006209,14.478543,0.737572,0.062095,-163.734375,0.007085,0.000000
9.350000,3.396782,-163.734375,0.002755,0.000258,0.006556,15.109641,0.769722,0.065562,-163.734375,0.007449,0.000000
9.570001,3.493225,-163.778854,0.002794,0.000269,0.006834,15.538641,0.791576,0.068340,-163.778854,0.007814,0.000000
9.790001,3.692444,-163.734375,0.002807,0.000284,0.007224,16.424810,0.836720,0.072242,-163.734375,0.008178,0.000000
10.010000,4.048805,-163.734375,0.002828,0.000308,0.007814,18.009985,0.917472,0.078139,-163.734375,0.008551,0.000000
10.230000,4.142647,-163.778854,0.002846,0.000322,0.008169,18.427414,0.938737,0.081693,-163.778854,0.008915,0.000000
10.450001,4.157166,-163.778854,0.002854,0.000329,0.008369,18.491997,0.942027,0.083688,-163.778854,0.009279,0.000000
10.670000,4.358994,-163.823349,0.002854,0.000346,0.008776,19.389772,0.987762,0.087764,-163.823349,0.009652,0.000000
10.890000,4.433098,-163.734375,0.002902,0.000357,0.009080,19.719404,1.004554,0.090800,-163.734375,0.010017,0.000000
11.110001,4.742165,-163.734375,0.002897,0.000377,0.009583,21.094202,1.074590,0.095830,-163.734375,0.010381,0.000000
11.330001,4.819244,-163.823349,0.002923,0.000387,0.009826,21.437069,1.092056,0.098260,-163.823349,0.010745,0.000000
11.550000,4.921646,-163.778854,0.002919,0.000400,0.010164,21.892576,1.115261,0.101640,-163.778854,0.011118,0.000000
11.770000,5.206886,-163.823349,0.002936,0.000420,0.010667,23.161386,1.179897,0.106670,-163.823349,0.011482,0.000000
11.990001,5.419136,-163.778854,0.002949,0.000439,0.011153,24.105520,1.227994,0.111526,-163.778854,0.011846,0.000000
12.210001,5.456749,-163.867828,0.002975,0.000453,0.011500,24.272831,1.236517,0.114996,-163.867828,0.012211,0.000000
12.430000,5.439621,-163.867828,0.002984,0.000465,0.011820,24.196642,1.232636,0.118202,-163.867828,0.012584,0.000000
12.650001,5.509254,-163.823349,0.002979,0.000476,0.012089,24.506388,1.248415,0.120893,-163.823349,0.012948,0.000000
12.870001,5.782944,-163.823349,0.003001,0.000495,0.012584,25.723818,1.310434,0.125836,-163.823349,0.013312,0.000000
13.090000,5.854813,-163.867828,0.003040,0.000508,0.012896,26.043507,1.326720,0.128959,-163.867828,0.013685,0.000000
13.310000,5.907692,-163.823349,0.003044,0.000522,0.013269,26.278727,1.338702,0.132687,-163.823349,0.014049,0.000000
13.530001,5.950516,-163.778854,0.003053,0.000531,0.013477,26.469215,1.348406,0.134769,-163.778854,0.014413,0.000000
13.750001,6.189949,-163.912308,0.003065,0.000553,0.014040,27.534269,1.402663,0.140404,-163.912308,0.014778,0.000000
13.970000,6.385445,-163.912308,0.003087,0.000569,0.014457,28.403877,1.446962,0.144568,-163.912308,0.015151,0.000000
14.190001,6.320282,-163.867828,0.003083,0.000579,0.014708,28.114017,1.432196,0.147081,-163.867828,0.015515,0.000000
14.410001,6.379486,-163.912308,0.003091,0.000594,0.015090,28.377371,1.445612,0.150900,-163.912308,0.015879,0.000000
14.630001,6.474442,-163.823349,0.003113,0.000606,0.015394,28.799755,1.467129,0.153935,-163.823349,0.016252,0.000000
14.850000,6.523224,-163.867828,0.003147,0.000620,0.015758,29.016748,1.478184,0.157577,-163.867828,0.016616,0.000000
15.070001,6.769730,-163.912308,0.003156,0.000639,0.016235,30.113262,1.534043,0.162345,-163.912308,0.016981,0.000000
15.290001,6.704193,-163.912308,0.003186,0.000649,0.016478,29.821741,1.519192,0.164775,-163.912308,0.017345,0.000000
15.510001,6.832664,-163.912308,0.003191,0.000664,0.016868,30.393209,1.548304,0.168678,-163.912308,0.017717,0.000000
15.730000,7.111198,-163.912308,0.003191,0.000684,0.017371,31.632191,1.611421,0.173708,-163.912308,0.018082,0.000000
15.950001,7.103752,-163.956787,0.003221,0.000696,0.017683,31.599068,1.609733,0.176830,-163.956787,0.018446,0.000000
16.170000,7.039330,-163.956787,0.003203,0.000707,0.017952,31.312502,1.595135,0.179518,-163.956787,0.018819,0.000000
16.390001,7.158493,-163.912308,0.003225,0.000722,0.018333,31.842567,1.622138,0.183333,-163.912308,0.019183,0.000000
16.610001,7.224030,-163.912308,0.003251,0.000735,0.018680,32.134087,1.636989,0.186803,-163.912308,0.019547,0.000000
16.830000,7.305580,-164.001266,0.003272,0.000750,0.019044,32.496845,1.655468,0.190445,-164.001266,0.019912,0.000000
17.050001,7.466812,-164.001266,0.003264,0.000767,0.019469,33.214039,1.692004,0.194695,-164.001266,0.020284,0.000000
17.270000,7.454529,-164.001266,0.003294,0.000776,0.019721,33.159401,1.689220,0.197208,-164.001266,0.020649,0.000000
17.490002,7.459740,-164.001266,0.003290,0.000787,0.019981,33.182579,1.690401,0.199808,-164.001266,0.021013,0.000000
17.710001,7.774025,-163.956787,0.003316,0.000809,0.020536,34.580589,1.761619,0.205361,-163.956787,0.021386,0.000000
17.930000,7.813866,-163.912308,0.003320,0.000821,0.020866,34.757809,1.770647,0.208657,-163.912308,0.021750,0.000000
18.150002,7.761734,-164.045746,0.003333,0.000832,0.021143,34.525917,1.758834,0.211432,-164.045746,0.022114,0.000000
18.370001,7.882385,-164.001266,0.003376,0.000850,0.021594,35.062599,1.786174,0.215940,-164.001266,0.022478,0.000000
18.590000,7.907700,-163.956787,0.003354,0.000861,0.021880,35.175205,1.791910,0.218801,-163.956787,0.022852,0.000000
18.810001,8.083466,-164.001266,0.003367,0.000880,0.022349,35.957050,1.831740,0.223487,-164.001266,0.023216,0.000000
19.030001,8.099472,-164.045746,0.003415,0.000891,0.022626,36.028252,1.835367,0.226261,-164.045746,0.023580,0.000000
19.250000,8.130379,-164.001266,0.003415,0.000904,0.022964,36.165730,1.842370,0.229641,-164.001266,0.023953,0.000000
19.470001,8.166130,-164.045746,0.003445,0.000916,0.023268,36.324760,1.850471,0.232676,-164.045746,0.024317,0.000000
19.690001,8.438705,-164.001266,0.003458,0.000938,0.023814,37.537235,1.912238,0.238142,-164.001266,0.024681,0.000000
19.910002,8.608139,-164.045746,0.003475,0.000955,0.024256,38.290916,1.950632,0.242563,-164.045746,0.025046,0.000000
20.130001,8.527328,-164.001266,0.003462,0.000966,0.024543,37.931450,1.932320,0.245428,-164.001266,0.025419,0.000000
20.350000,8.572014,-164.090225,0.003479,0.000980,0.024889,38.130222,1.942446,0.248895,-164.090225,0.025783,0.000000
20.570002,8.531052,-164.090225,0.003514,0.000992,0.025193,37.948013,1.933164,0.251930,-164.090225,0.026147,0.000000
20.790001,8.805122,-164.045746,0.003540,0.001010,0.025661,39.167141,1.995269,0.256612,-164.045746,0.026520,0.000000
21.010000,8.586540,-164.045746,0.003548,0.001014,0.025757,38.194839,1.945738,0.257566,-164.045746,0.026884,0.000000
21.230001,8.476318,-164.090225,0.003531,0.001020,0.025904,37.704548,1.920761,0.259042,-164.090225,0.027248,0.000000
21.450001,9.041580,-164.134705,0.003557,0.001048,0.026624,40.218956,2.048851,0.266241,-164.134705,0.027613,0.000000
21.670000,9.248619,-164.090225,0.003591,0.001068,0.027136,41.139912,2.095767,0.271358,-164.090225,0.027986,0.000000
21.890001,9.255692,-164.090225,0.003591,0.001081,0.027465,41.171371,2.097370,0.274651,-164.090225,0.028350,0.000000
22.110001,9.206909,-164.134705,0.003596,0.001096,0.027838,40.954376,2.086315,0.278379,-164.134705,0.028714,0.000000
22.330002,9.245262,-164.045746,0.003613,0.001108,0.028150,41.124981,2.095006,0.281502,-164.045746,0.029087,0.000000
22.550001,9.483582,-164.090225,0.003617,0.001128,0.028653,42.185078,2.149010,0.286532,-164.090225,0.029451,0.000000
22.770000,9.557312,-164.090225,0.003656,0.001142,0.029009,42.513046,2.165718,0.290089,-164.090225,0.029816,0.000000
22.990002,9.495125,-164.090225,0.003660,0.001152,0.029269,42.236423,2.151626,0.292690,-164.090225,0.030180,0.000000
23.210001,9.470177,-164.090225,0.003665,0.001163,0.029546,42.125450,2.145972,0.295464,-164.090225,0.030552,0.000000
23.430000,9.515610,-164.134705,0.003669,0.001178,0.029911,42.327545,2.156268,0.299109,-164.134705,0.030917,0.000000
23.650002,9.974373,-164.134705,0.003704,0.001201,0.030501,44.368225,2.260225,0.305006,-164.134705,0.031281,0.000000
23.870001,9.977348,-164.223679,0.003721,0.001214,0.030847,44.381462,2.260899,0.308473,-164.223679,0.031654,0.000000
24.090002,9.963196,-164.223679,0.003712,0.001229,0.031212,44.318508,2.257693,0.312118,-164.223679,0.032018,0.000000
24.310001,9.905479,-164.134705,0.003751,0.001239,0.031463,44.061771,2.244614,0.314631,-164.134705,0.032382,0.000000
24.530001,10.058899,-164.134705,0.003751,0.001254,0.031845,44.744217,2.279379,0.318446,-164.134705,0.032747,0.000000
24.750002,10.293121,-164.134705,0.003781,0.001272,0.032313,45.786091,2.332454,0.323128,-164.134705,0.033119,0.000000
24.970001,10.193329,-164.179184,0.003786,0.001283,0.032582,45.342190,2.309841,0.325819,-164.179184,0.033484,0.000000
25.190001,10.229820,-164.223679,0.003781,0.001295,0.032903,45.504513,2.318110,0.329028,-164.223679,0.033848,0.000000
25.410002,10.604797,-164.223679,0.003811,0.001318,0.033475,47.172493,2.403081,0.334751,-164.223679,0.034212,0.000000
25.630001,10.629372,-164.179184,0.003820,0.001332,0.033839,47.281807,2.408650,0.338392,-164.179184,0.034585,0.000000
25.850000,10.562721,-164.179184,0.003820,0.001345,0.034151,46.985332,2.393547,0.341515,-164.179184,0.034949,0.000000
26.070002,10.594368,-164.268158,0.003829,0.001358,0.034498,47.126102,2.400718,0.344982,-164.268158,0.035313,0.000000
26.290001,10.673317,-164.223679,0.003872,0.001373,0.034871,47.477283,2.418608,0.348714,-164.223679,0.035687,0.000000
26.510002,10.874397,-164.223679,0.003880,0.001388,0.035253,48.371735,2.464174,0.352529,-164.223679,0.036051,0.000000
26.730001,10.919083,-164.179184,0.003885,0.001403,0.035626,48.570507,2.474299,0.356257,-164.179184,0.036415,0.000000
26.950001,10.955200,-164.223679,0.003906,0.001415,0.035938,48.731163,2.482484,0.359380,-164.223679,0.036779,0.000000
27.170002,10.960785,-164.268158,0.003911,0.001429,0.036285,48.756008,2.483749,0.362850,-164.268158,0.037152,0.000000
27.390001,11.328316,-164.268158,0.003932,0.001449,0.036814,50.390865,2.567033,0.368138,-164.268158,0.037516,0.000000
27.610001,11.382309,-164.268158,0.003945,0.001464,0.037187,50.631039,2.579268,0.371866,-164.268158,0.037880,0.000000
27.830002,11.174896,-164.223679,0.003954,0.001471,0.037360,49.708420,2.532268,0.373603,-164.223679,0.038254,0.000000
28.050001,11.330925,-164.268158,0.003975,0.001488,0.037794,50.402473,2.567624,0.377937,-164.268158,0.038618,0.000000
28.270000,11.528656,-164.268158,0.003980,0.001506,0.038245,51.282024,2.612431,0.382448,-164.268158,0.038982,0.000000
28.490002,11.680954,-164.312637,0.004001,0.001521,0.038626,51.959476,2.646942,0.386264,-164.312637,0.039346,0.000000
28.710001,11.633293,-164.268158,0.004018,0.001533,0.038930,51.747471,2.636142,0.389299,-164.268158,0.039719,0.000000
28.930002,11.560677,-164.223679,0.004005,0.001542,0.039173,51.424458,2.619687,0.391725,-164.223679,0.040083,0.000000
29.150002,11.568497,-164.312637,0.004023,0.001552,0.039433,51.459244,2.621459,0.394329,-164.312637,0.040448,0.000000
29.370001,11.850014,-164.401596,0.004031,0.001573,0.039953,52.711494,2.685251,0.399534,-164.401596,0.040820,0.000000
29.590002,12.189613,-164.357117,0.004083,0.001591,0.040404,54.222107,2.762206,0.404041,-164.357117,0.041185,0.000000
29.810001,11.955391,-164.312637,0.004070,0.001597,0.040560,53.180233,2.709130,0.405604,-164.312637,0.041549,0.000000
30.030001,12.171738,-164.268158,0.004113,0.001615,0.041029,54.142593,2.758155,0.410286,-164.268158,0.041913,0.000000
30.250002,12.326645,-164.357117,0.004105,0.001630,0.041410,54.831654,2.793258,0.414102,-164.357117,0.042286,0.000000
30.470001,12.373566,-164.401596,0.004105,0.001643,0.041740,55.040367,2.803890,0.417398,-164.401596,0.042650,0.000000
30.690001,12.438728,-164.357117,0.004122,0.001657,0.042095,55.330227,2.818656,0.420952,-164.357117,0.043015,0.000000
30.910002,12.356438,-164.357117,0.004130,0.001668,0.042364,54.964180,2.800009,0.423640,-164.357117,0.043387,0.000000
31.130001,12.600716,-164.357117,0.004148,0.001686,0.042833,56.050781,2.855363,0.428325,-164.357117,0.043751,0.000000
31.350002,13.084053,-164.401596,0.004178,0.001708,0.043379,58.200775,2.964889,0.433787,-164.401596,0.044116,0.000000
31.570002,13.046074,-164.401596,0.004178,0.001721,0.043717,58.031834,2.956283,0.437171,-164.401596,0.044480,0.000000
31.790001,12.821159,-164.401596,0.004199,0.001729,0.043925,57.031364,2.905316,0.439252,-164.401596,0.044853,0.000000
32.010002,12.981277,-164.446075,0.004212,0.001746,0.044342,57.743607,2.941599,0.443416,-164.446075,0.045217,0.000000
32.230003,13.066925,-164.357117,0.004212,0.001759,0.044688,58.124584,2.961007,0.446883,-164.357117,0.045581,0.000000
32.450001,13.407272,-164.357117,0.004238,0.001778,0.045165,59.638527,3.038131,0.451652,-164.357117,0.045954,0.000000
32.670002,13.263908,-164.401596,0.004255,0.001787,0.045382,59.000813,3.005645,0.453820,-164.401596,0.046319,0.000000
32.890003,13.348808,-164.401596,0.004268,0.001800,0.045712,59.378464,3.024883,0.457117,-164.401596,0.046683,0.000000
33.110001,13.827309,-164.401596,0.004268,0.001822,0.046267,61.506939,3.133313,0.462666,-164.401596,0.047047,0.000000
33.330002,14.025780,-164.401596,0.004294,0.001839,0.046718,62.389786,3.178287,0.467177,-164.401596,0.047420,0.000000
33.550003,13.978867,-164.401596,0.004312,0.001853,0.047056,62.181103,3.167656,0.470557,-164.401596,0.047784,0.000000
33.770000,13.898430,-164.401596,0.004342,0.001864,0.047351,61.823303,3.149429,0.473505,-164.401596,0.048148,0.000000
33.990002,13.871994,-164.446075,0.004342,0.001877,0.047672,61.705711,3.143439,0.476715,-164.446075,0.048521,0.000000
34.210003,14.259636,-164.446075,0.004346,0.001895,0.048131,63.430027,3.231280,0.481310,-164.446075,0.048886,0.000000
34.430000,14.282722,-164.490555,0.004376,0.001907,0.048443,63.532722,3.236511,0.484432,-164.490555,0.049250,0.000000
34.650002,14.400391,-164.446075,0.004385,0.001922,0.048825,64.056137,3.263175,0.488248,-164.446075,0.049614,0.000000
34.870003,14.276016,-164.446075,0.004385,0.001930,0.049033,63.502892,3.234992,0.490329,-164.446075,0.049987,0.000000
35.090000,14.870697,-164.490555,0.004415,0.001953,0.049614,66.148163,3.369748,0.496143,-164.490555,0.050351,0.000000
35.310001,14.994698,-164.490555,0.004432,0.001968,0.049987,66.699745,3.397847,0.499871,-164.490555,0.050715,0.000000
35.530003,14.906441,-164.401596,0.004419,0.001980,0.050282,66.307159,3.377848,0.502820,-164.401596,0.051089,0.000000
35.750000,14.966393,-164.535034,0.004428,0.001994,0.050655,66.573837,3.391433,0.506548,-164.535034,0.051453,0.000000
35.970001,14.966026,-164.535034,0.004441,0.002006,0.050941,66.572212,3.391350,0.509409,-164.535034,0.051817,0.000000
36.190002,15.174179,-164.490555,0.004467,0.002023,0.051375,67.498123,3.438518,0.513747,-164.490555,0.052181,0.000000
36.410000,15.481384,-164.446075,0.004462,0.002038,0.051765,68.864639,3.508132,0.517649,-164.446075,0.052554,0.000000
36.630001,15.375633,-164.446075,0.004497,0.002049,0.052042,68.394234,3.484168,0.520423,-164.446075,0.052918,0.000000
36.850002,15.642250,-164.490555,0.004493,0.002063,0.052406,69.580200,3.544585,0.524064,-164.490555,0.053283,0.000000
37.070004,16.146072,-164.490555,0.004536,0.002084,0.052936,71.821320,3.658752,0.529355,-164.490555,0.053647,0.000000
37.290001,16.086494,-164.535034,0.004527,0.002096,0.053230,71.556297,3.645252,0.532304,-164.535034,0.054020,0.000000
37.510002,16.054092,-164.579514,0.004531,0.002108,0.053543,71.412170,3.637909,0.535426,-164.579514,0.054384,0.000000
37.730003,16.166550,-164.579514,0.004553,0.002122,0.053898,71.912407,3.663393,0.538980,-164.579514,0.054748,0.000000
37.950001,16.324814,-164.579514,0.004544,0.002135,0.054236,72.616402,3.699256,0.542364,-164.579514,0.055121,0.000000
38.170002,16.477112,-164.579514,0.004570,0.002150,0.054618,73.293854,3.733767,0.546179,-164.579514,0.055485,0.000000
38.390003,16.744102,-164.623993,0.004587,0.002165,0.054991,74.481491,3.794268,0.549907,-164.623993,0.055850,0.000000
38.610001,16.648399,-164.579514,0.004618,0.002175,0.055242,74.055779,3.772581,0.552424,-164.579514,0.056214,0.000000
38.830002,16.661064,-164.579514,0.004605,0.002187,0.055555,74.112114,3.775451,0.555547,-164.579514,0.056586,0.000000
39.050003,17.331703,-164.535034,0.004609,0.002209,0.056118,77.095268,3.927420,0.561183,-164.535034,0.056951,0.000000
39.270000,17.440063,-164.623993,0.004656,0.002222,0.056448,77.577278,3.951975,0.564479,-164.623993,0.057315,0.000000
39.490002,17.316437,-164.623993,0.004661,0.002234,0.056734,77.027359,3.923961,0.567341,-164.623993,0.057688,0.000000
39.710003,17.705940,-164.668488,0.004665,0.002251,0.057176,78.759956,4.012223,0.571761,-164.668488,0.058052,0.000000
39.930000,17.657158,-164.623993,0.004669,0.002260,0.057402,78.542961,4.001169,0.574017,-164.623993,0.058416,0.000000
40.150002,18.110710,-164.579514,0.004678,0.002279,0.057879,80.560463,4.103946,0.578786,-164.579514,0.058781,0.000000
40.370003,18.192261,-164.668488,0.004700,0.002293,0.058234,80.923218,4.122426,0.582344,-164.668488,0.059154,0.000000
40.590000,18.209015,-164.668488,0.004708,0.002303,0.058486,80.997742,4.126222,0.584857,-164.668488,0.059518,0.000000
40.810001,18.578033,-164.668488,0.004725,0.002320,0.058928,82.639221,4.209842,0.589282,-164.668488,0.059882,0.000000
41.030003,18.925461,-164.579514,0.004747,0.002337,0.059353,84.184654,4.288571,0.593532,-164.579514,0.060255,0.000000
41.250004,19.346611,-164.668488,0.004751,0.002353,0.059778,86.058022,4.384005,0.597779,-164.668488,0.060619,0.000000
41.470001,19.235275,-164.668488,0.004743,0.002365,0.060073,85.562775,4.358776,0.600727,-164.668488,0.060983,0.000000
41.690002,19.386826,-164.623993,0.004781,0.002380,0.060446,86.236908,4.393117,0.604459,-164.623993,0.061348,0.000000
41.910004,19.302299,-164.668488,0.004781,0.002391,0.060723,85.860916,4.373964,0.607233,-164.668488,0.061721,0.000000
42.130001,19.943901,-164.623993,0.004807,0.002409,0.061200,88.714905,4.519352,0.612002,-164.623993,0.062085,0.000000
42.350002,19.474335,-164.712967,0.004799,0.002413,0.061278,86.626167,4.412947,0.612782,-164.712967,0.062449,0.000000
42.570004,19.816544,-164.712967,0.004816,0.002427,0.061651,88.148392,4.490493,0.616510,-164.712967,0.062822,0.000000
42.790001,20.464478,-164.757446,0.004846,0.002448,0.062189,91.030540,4.637317,0.621889,-164.757446,0.063186,0.000000
43.010002,21.080376,-164.712967,0.004838,0.002468,0.062683,93.770195,4.776881,0.626832,-164.712967,0.063550,0.000000
43.230003,21.200279,-164.668488,0.004872,0.002482,0.063039,94.303551,4.804052,0.630389,-164.668488,0.063915,0.000000
43.450001,21.309013,-164.712967,0.004868,0.002496,0.063403,94.787224,4.828691,0.634030,-164.712967,0.064288,0.000000
43.670002,21.333595,-164.712967,0.004894,0.002508,0.063707,94.896568,4.834262,0.637066,-164.712967,0.064652,0.000000
43.890003,21.958809,-164.712967,0.004894,0.002528,0.064218,97.677658,4.975937,0.642183,-164.712967,0.065016,0.000000
44.110001,22.096581,-164.757446,0.004902,0.002541,0.064548,98.290497,5.007157,0.645476,-164.757446,0.065389,0.000000
44.330002,22.015038,-164.712967,0.004915,0.002551,0.064799,97.927780,4.988679,0.647993,-164.712967,0.065753,0.000000
44.550003,22.090256,-164.757446,0.004945,0.002562,0.065085,98.262367,5.005723,0.650854,-164.757446,0.066118,0.000000
44.770000,22.397835,-164.757446,0.004945,0.002578,0.065484,99.630547,5.075422,0.654844,-164.757446,0.066482,0.000000
44.990002,23.400261,-164.846405,0.004950,0.002600,0.066048,104.089561,5.302575,0.660479,-164.846405,0.066854,0.000000
45.210003,23.571548,-164.757446,0.004997,0.002613,0.066369,104.851486,5.341389,0.663689,-164.757446,0.067219,0.000000
45.430000,23.787155,-164.757446,0.004988,0.002628,0.066750,105.810547,5.390246,0.667504,-164.757446,0.067583,0.000000
45.650002,23.711563,-164.801926,0.005010,0.002637,0.066985,105.474304,5.373117,0.669847,-164.801926,0.067956,0.000000
45.870003,24.112984,-164.801926,0.005014,0.002653,0.067384,107.259911,5.464080,0.673836,-164.801926,0.068320,0.000000
46.090004,24.723671,-164.757446,0.005032,0.002672,0.067861,109.976379,5.602464,0.678605,-164.757446,0.068684,0.000000
46.310001,24.635422,-164.801926,0.005057,0.002682,0.068112,109.583832,5.582467,0.681122,-164.801926,0.069049,0.000000
46.530003,24.756439,-164.801926,0.005053,0.002694,0.068415,110.122139,5.609889,0.684154,-164.801926,0.069421,0.000000
46.750004,25.772270,-164.846405,0.005053,0.002716,0.068997,114.640785,5.840080,0.689967,-164.846405,0.069786,0.000000
46.970001,26.140549,-164.801926,0.005066,0.002731,0.069378,116.278969,5.923533,0.693783,-164.801926,0.070150,0.000000
47.190002,26.179276,-164.890884,0.005083,0.002743,0.069673,116.451233,5.932309,0.696731,-164.890884,0.070523,0.000000
47.410004,26.436958,-164.846405,0.005096,0.002757,0.070020,117.597466,5.990700,0.700198,-164.846405,0.070887,0.000000
47.630001,26.773582,-164.757446,0.005101,0.002772,0.070402,119.094841,6.066980,0.704017,-164.757446,0.071251,0.000000
47.850002,27.275169,-164.801926,0.005113,0.002786,0.070766,121.326012,6.180642,0.707658,-164.801926,0.071616,0.000000
48.070004,27.588333,-164.846405,0.005135,0.002800,0.071130,122.719032,6.251606,0.711299,-164.846405,0.071989,0.000000
48.290001,27.908569,-164.890884,0.005135,0.002813,0.071451,124.143517,6.324172,0.714509,-164.890884,0.072353,0.000000
48.510002,28.041138,-164.890884,0.005157,0.002826,0.071789,124.733208,6.354213,0.717892,-164.890884,0.072717,0.000000
48.730003,28.935951,-164.846405,0.005178,0.002847,0.072318,128.713547,6.556981,0.723180,-164.846405,0.073090,0.000000
48.950001,29.488548,-164.846405,0.005174,0.002863,0.072708,131.171616,6.682200,0.727082,-164.846405,0.073454,0.000000
49.170002,29.320236,-164.846405,0.005178,0.002869,0.072873,130.422928,6.644061,0.728732,-164.846405,0.073818,0.000000
49.390003,29.886986,-164.935364,0.005230,0.002887,0.073324,132.943954,6.772488,0.733240,-164.935364,0.074182,0.000000
49.610001,30.407188,-164.890884,0.005213,0.002904,0.073758,135.257935,6.890368,0.737578,-164.890884,0.074556,0.000000
49.830002,30.947136,-164.890884,0.005230,0.002919,0.074139,137.659729,7.012722,0.741393,-164.890884,0.074920,0.000000
50.050003,31.144493,-164.890884,0.005238,0.002930,0.074425,138.537628,7.057443,0.744254,-164.890884,0.075284,0.000000
50.270004,31.086769,-164.935364,0.005251,0.002938,0.074634,138.280853,7.044363,0.746336,-164.935364,0.075648,0.000000
50.490002,31.336258,-164.935364,0.005256,0.002950,0.074937,139.390640,7.100897,0.749371,-164.935364,0.076021,0.000000
50.710003,31.721298,-164.890884,0.005273,0.002968,0.075379,141.103378,7.188149,0.753792,-164.890884,0.076385,0.000000
50.930004,33.267387,-164.935364,0.005282,0.002990,0.075943,147.980728,7.538497,0.759432,-164.935364,0.076750,0.000000
51.150002,33.094978,-164.935364,0.005320,0.002997,0.076117,147.213821,7.499429,0.761165,-164.935364,0.077123,0.000000
51.370003,33.751472,-164.935364,0.005299,0.003013,0.076542,150.134048,7.648193,0.765416,-164.935364,0.077487,0.000000
51.590004,34.335724,-164.979843,0.005320,0.003028,0.076923,152.732925,7.780586,0.769231,-164.979843,0.077851,0.000000
51.810001,34.754639,-165.024323,0.005342,0.003042,0.077278,154.596359,7.875514,0.772785,-165.024323,0.078215,0.000000
52.030003,35.110626,-164.979843,0.005338,0.003055,0.077608,156.179871,7.956182,0.776081,-164.979843,0.078588,0.000000
52.250004,35.295326,-164.979843,0.005359,0.003067,0.077912,157.001450,7.998035,0.779117,-164.979843,0.078953,0.000000
52.470001,35.846436,-164.979843,0.005376,0.003084,0.078345,159.452911,8.122918,0.783454,-164.979843,0.079317,0.000000
52.690002,37.315445,-164.979843,0.005372,0.003106,0.078892,165.987396,8.455800,0.788916,-164.979843,0.079689,0.000000
52.910004,37.704948,-165.024323,0.005372,0.003120,0.079256,167.719986,8.544064,0.792557,-165.024323,0.080054,0.000000
53.130001,37.716866,-164.979843,0.005372,0.003129,0.079481,167.772995,8.546764,0.794813,-164.979843,0.080418,0.000000
53.350002,38.320480,-164.979843,0.005402,0.003145,0.079871,170.458008,8.683545,0.798715,-164.979843,0.080782,0.000000
53.570004,38.695084,-164.935364,0.005420,0.003159,0.080236,172.124329,8.768431,0.802360,-164.935364,0.081155,0.000000
53.790001,39.483772,-165.024323,0.005420,0.003173,0.080600,175.632584,8.947150,0.806001,-165.024323,0.081519,0.000000
54.010002,39.751137,-165.024323,0.005411,0.003185,0.080895,176.821884,9.007736,0.808949,-165.024323,0.081884,0.000000
54.230003,40.193886,-164.979843,0.005445,0.003197,0.081198,178.791336,9.108065,0.811985,-164.979843,0.082256,0.000000
54.450001,41.495697,-164.979843,0.005445,0.003220,0.081779,184.582077,9.403059,0.817795,-164.979843,0.082621,0.000000
54.670002,42.441895,-165.024323,0.005450,0.003237,0.082231,188.790970,9.617471,0.822306,-165.024323,0.082985,0.000000
54.890003,42.930824,-165.113297,0.005458,0.003251,0.082586,190.965851,9.728264,0.825860,-165.113297,0.083349,0.000000
55.110004,43.198555,-165.157776,0.005493,0.003263,0.082872,192.156769,9.788933,0.828722,-165.157776,0.083722,0.000000
55.330002,43.529594,-165.024323,0.005489,0.003276,0.083202,193.629303,9.863947,0.832018,-165.024323,0.084086,0.000000
55.550003,44.491432,-165.024323,0.005497,0.003293,0.083653,197.907776,10.081903,0.836526,-165.024323,0.084450,0.000000
55.770004,44.999352,-164.979843,0.005510,0.003305,0.083956,200.167114,10.197000,0.839562,-164.979843,0.084823,0.000000
55.990002,45.586586,-165.068802,0.005519,0.003320,0.084338,202.779266,10.330068,0.843377,-165.068802,0.085188,0.000000
56.210003,45.700531,-165.068802,0.005527,0.003329,0.084546,203.286118,10.355888,0.845459,-165.068802,0.085552,0.000000
56.430004,47.185547,-165.113297,0.005562,0.003352,0.085136,209.891800,10.692398,0.851355,-165.113297,0.085916,0.000000
56.650002,47.916145,-165.068802,0.005553,0.003366,0.085500,213.141663,10.857954,0.855000,-165.068802,0.086289,0.000000
56.870003,48.364113,-165.113297,0.005553,0.003378,0.085804,215.134323,10.959465,0.858036,-165.113297,0.086653,0.000000
57.090004,48.990067,-165.113297,0.005583,0.003392,0.086168,217.918701,11.101308,0.861677,-165.113297,0.087017,0.000000
57.310001,49.477501,-165.157776,0.005588,0.003404,0.086454,220.086914,11.211762,0.864538,-165.157776,0.087391,0.000000
57.530003,50.184265,-165.068802,0.005601,0.003421,0.086888,223.230759,11.371917,0.868876,-165.068802,0.087755,0.000000
57.750004,51.079819,-165.113297,0.005605,0.003436,0.087269,227.214386,11.574853,0.872691,-165.113297,0.088119,0.000000
57.970001,51.346069,-165.113297,0.005614,0.003446,0.087529,228.398727,11.635185,0.875291,-165.113297,0.088483,0.000000
58.190002,52.307533,-165.202255,0.005614,0.003461,0.087919,232.675522,11.853057,0.879193,-165.202255,0.088856,0.000000
58.410004,53.551628,-165.113297,0.005605,0.003481,0.088414,238.209534,12.134973,0.884136,-165.113297,0.089220,0.000000
58.630001,54.294884,-165.157776,0.005635,0.003494,0.088743,241.515701,12.303397,0.887433,-165.157776,0.089585,0.000000
58.850002,54.761467,-165.113297,0.005635,0.003507,0.089073,243.591171,12.409126,0.890730,-165.113297,0.089957,0.000000
59.070004,55.469719,-165.157776,0.005639,0.003521,0.089437,246.741638,12.569617,0.894371,-165.157776,0.090322,0.000000
59.290001,56.231964,-165.157776,0.005683,0.003533,0.089741,250.132263,12.742346,0.897406,-165.157776,0.090686,0.000000
59.510002,57.010597,-165.291214,0.005670,0.003550,0.090166,253.595795,12.918786,0.901657,-165.291214,0.091050,0.000000
59.730003,58.010048,-165.246735,0.005687,0.003564,0.090530,258.041595,13.145265,0.905298,-165.246735,0.091423,0.000000
59.950005,58.352997,-165.202255,0.005678,0.003573,0.090764,259.567108,13.222979,0.907641,-165.202255,0.091787,0.000000
60.170002,58.701172,-165.202255,0.005696,0.003584,0.091041,261.115845,13.301876,0.910415,-165.202255,0.092152,0.000000
60.390003,60.333275,-165.202255,0.005691,0.003606,0.091588,268.375824,13.671715,0.915876,-165.202255,0.092524,0.000000
60.610004,61.183403,-165.246735,0.005713,0.003621,0.091970,272.157379,13.864357,0.919695,-165.246735,0.092889,0.000000
60.830002,61.599716,-165.202255,0.005717,0.003631,0.092230,274.009216,13.958695,0.922296,-165.202255,0.093253,0.000000
61.050003,62.647575,-165.113297,0.005730,0.003649,0.092672,278.670319,14.196143,0.926720,-165.113297,0.093617,0.000000
61.270004,63.305557,-165.157776,0.005708,0.003659,0.092932,281.597168,14.345244,0.929320,-165.157776,0.093990,0.000000
61.490002,64.440918,-165.291214,0.005747,0.003677,0.093400,286.647522,14.602521,0.934002,-165.291214,0.094354,0.000000
61.710003,65.219925,-165.291214,0.005743,0.003689,0.093704,290.112701,14.779046,0.937038,-165.291214,0.094719,0.000000
61.930004,65.797836,-165.202255,0.005739,0.003701,0.094007,292.683380,14.910003,0.940073,-165.202255,0.095091,0.000000
62.150002,66.784637,-165.246735,0.005760,0.003718,0.094441,297.072906,15.133615,0.944411,-165.246735,0.095456,0.000000
62.370003,67.108215,-165.246735,0.005782,0.003714,0.094328,298.512238,15.206940,0.943283,-165.246735,0.094588,0.000000
62.590004,66.482635,-165.246735,0.005777,0.003714,0.094328,295.729523,15.065181,0.943283,-165.246735,0.094328,0.000000
62.810001,65.928177,-165.335693,0.005777,0.003711,0.094250,293.263184,14.939538,0.942503,-165.335693,0.094328,0.000000
63.030003,65.426590,-165.335693,0.005782,0.003709,0.094215,291.032013,14.825877,0.942155,-165.335693,0.094328,0.000000
63.250004,64.977875,-165.246735,0.005782,0.003709,0.094198,289.036011,14.724196,0.941981,-165.246735,0.094328,0.000000
63.470001,64.598434,-165.246735,0.005795,0.003708,0.094189,287.348175,14.638215,0.941894,-165.246735,0.094328,0.000000
63.690002,64.229034,-165.202255,0.005782,0.003708,0.094181,285.705017,14.554507,0.941807,-165.202255,0.094328,0.000000
63.910004,63.918106,-165.291214,0.005799,0.003708,0.094181,284.321930,14.484050,0.941807,-165.291214,0.094328,0.000000
64.130005,63.626160,-165.335693,0.005795,0.003708,0.094172,283.023285,14.417893,0.941724,-165.335693,0.094328,0.000000
64.350006,63.348373,-165.291214,0.005803,0.003708,0.094172,281.787628,14.354946,0.941724,-165.291214,0.094328,0.000000
64.570000,63.099258,-165.335693,0.005790,0.003707,0.094164,280.679504,14.298496,0.941636,-165.335693,0.094328,0.000000
64.790001,62.871368,-165.335693,0.005799,0.003707,0.094164,279.665802,14.246856,0.941636,-165.335693,0.094328,0.000000
65.010002,62.647575,-165.380173,0.005812,0.003707,0.094164,278.670319,14.196143,0.941636,-165.380173,0.094328,0.000000
65.230003,62.453568,-165.380173,0.005812,0.003707,0.094164,277.807343,14.152181,0.941636,-165.380173,0.094328,0.000000
65.450005,62.261795,-165.335693,0.005808,0.003707,0.094155,276.954285,14.108725,0.941549,-165.335693,0.094328,0.000000
65.670006,62.076355,-165.380173,0.005803,0.003707,0.094155,276.129425,14.066703,0.941549,-165.380173,0.094328,0.000000
65.889999,61.918465,-165.380173,0.005816,0.003707,0.094155,275.427094,14.030925,0.941549,-165.380173,0.094328,0.000000
66.110001,61.752762,-165.424652,0.005812,0.003707,0.094155,274.690002,13.993376,0.941549,-165.424652,0.094328,0.000000
66.330002,61.605301,-165.380173,0.005812,0.003707,0.094155,274.034058,13.959961,0.941549,-165.380173,0.094328,0.000000
66.550003,61.468643,-165.424652,0.005808,0.003707,0.094155,273.426178,13.928993,0.941549,-165.424652,0.094328,0.000000
66.770004,61.306290,-165.380173,0.005795,0.003707,0.094155,272.704010,13.892203,0.941549,-165.380173,0.094328,0.000000
66.990005,61.187126,-165.380173,0.005821,0.003707,0.094146,272.173920,13.865201,0.941462,-165.380173,0.094328,0.000000
67.210007,61.070206,-165.424652,0.005812,0.003707,0.094146,271.653839,13.838706,0.941462,-165.424652,0.094328,0.000000
67.430000,60.939125,-165.469131,0.005821,0.003707,0.094146,271.070770,13.809004,0.941462,-165.469131,0.094328,0.000000
67.650002,60.830391,-165.380173,0.005821,0.003707,0.094146,270.587097,13.784364,0.941462,-165.380173,0.094328,0.000000
67.870003,60.720543,-165.380173,0.005821,0.003707,0.094146,270.098450,13.759472,0.941462,-165.380173,0.094328,0.000000
68.090004,60.612930,-165.424652,0.005795,0.003707,0.094146,269.619781,13.735086,0.941462,-165.424652,0.094328,0.000000
68.310005,60.508667,-165.469131,0.005842,0.003707,0.094146,269.156006,13.711459,0.941462,-165.469131,0.094328,0.000000
68.530006,60.414825,-165.424652,0.005833,0.003707,0.094146,268.738556,13.690195,0.941462,-165.424652,0.094328,0.000000
68.750000,60.324341,-165.424652,0.005842,0.003707,0.094146,268.336060,13.669691,0.941462,-165.424652,0.094328,0.000000
68.970001,60.240181,-165.469131,0.005821,0.003707,0.094146,267.961700,13.650620,0.941462,-165.469131,0.094328,0.000000
69.190002,60.140015,-165.380173,0.005816,0.003707,0.094146,267.516144,13.627922,0.941462,-165.380173,0.094328,0.000000
69.410004,60.050278,-165.513626,0.005816,0.003707,0.094146,267.116974,13.607587,0.941462,-165.513626,0.094328,0.000000
69.630005,59.978775,-165.469131,0.005838,0.003707,0.094146,266.798920,13.591385,0.941462,-165.469131,0.094328,0.000000
69.850006,59.903557,-165.469131,0.005812,0.003707,0.094146,266.464325,13.574340,0.941462,-165.469131,0.094328,0.000000
70.070000,59.832809,-165.513626,0.005838,0.003707,0.094146,266.149628,13.558309,0.941462,-165.513626,0.094328,0.000000
70.290001,59.730034,-165.469131,0.005825,0.003707,0.094146,265.692474,13.535019,0.941462,-165.469131,0.094328,0.000000
70.510002,59.665611,-165.469131,0.005821,0.003707,0.094146,265.405884,13.520421,0.941462,-165.469131,0.094328,0.000000
70.730003,59.601936,-165.513626,0.005825,0.003707,0.094146,265.122650,13.505991,0.941462,-165.513626,0.094328,0.000000
70.950005,59.537514,-165.469131,0.005842,0.003707,0.094146,264.836090,13.491393,0.941462,-165.469131,0.094328,0.000000
71.170006,59.482407,-165.469131,0.005833,0.003707,0.094146,264.590973,13.478906,0.941462,-165.469131,0.094328,0.000000
71.390007,59.404205,-165.513626,0.005825,0.003707,0.094146,264.243103,13.461185,0.941462,-165.513626,0.094328,0.000000
71.610001,59.339417,-165.602585,0.005829,0.003707,0.094146,263.954895,13.446505,0.941462,-165.602585,0.094328,0.000000
71.830002,59.278717,-165.558105,0.005833,0.003707,0.094146,263.684906,13.432750,0.941462,-165.558105,0.094328,0.000000
72.050003,59.218765,-165.469131,0.005829,0.003707,0.094146,263.418213,13.419164,0.941462,-165.469131,0.094328,0.000000
72.270004,59.186745,-165.513626,0.005846,0.003707,0.094146,263.275787,13.411908,0.941462,-165.513626,0.094328,0.000000
72.490005,59.111153,-165.558105,0.005838,0.003707,0.094146,262.939545,13.394779,0.941462,-165.558105,0.094328,0.000000
72.710007,59.053802,-165.558105,0.005816,0.003707,0.094146,262.684418,13.381783,0.941462,-165.558105,0.094328,0.000000
72.930000,59.006142,-165.602585,0.005829,0.003707,0.094146,262.472412,13.370983,0.941462,-165.602585,0.094328,0.000000
73.150002,58.936508,-165.602585,0.005825,0.003707,0.094146,262.162689,13.355204,0.941462,-165.602585,0.094328,0.000000
73.370003,58.907089,-165.513626,0.005842,0.003707,0.094146,262.031830,13.348537,0.941462,-165.513626,0.094328,0.000000
73.590004,58.849373,-165.602585,0.005821,0.003707,0.094146,261.775085,13.335459,0.941462,-165.602585,0.094328,0.000000
73.810005,58.796127,-165.602585,0.005812,0.003706,0.094138,261.538239,13.323393,0.941375,-165.602585,0.094328,0.000000
74.030006,58.750694,-165.602585,0.005833,0.003706,0.094138,261.336151,13.313098,0.941375,-165.602585,0.094328,0.000000
74.250000,58.700424,-165.647064,0.005825,0.003706,0.094138,261.112518,13.301706,0.941375,-165.647064,0.094328,0.000000
74.470001,58.650154,-165.602585,0.005842,0.003706,0.094138,260.888916,13.290315,0.941375,-165.602585,0.094328,0.000000
74.690002,58.621483,-165.558105,0.005816,0.003706,0.094138,260.761383,13.283818,0.941375,-165.558105,0.094328,0.000000
74.910004,58.576050,-165.647064,0.005833,0.003706,0.094138,260.559296,13.273522,0.941375,-165.647064,0.094328,0.000000
75.130005,58.537323,-165.647064,0.005821,0.003706,0.094138,260.387024,13.264748,0.941375,-165.647064,0.094328,0.000000
75.350006,58.475883,-165.647064,0.005825,0.003706,0.094138,260.113708,13.250825,0.941375,-165.647064,0.094328,0.000000
75.570007,58.456520,-165.558105,0.005829,0.003706,0.094138,260.027588,13.246437,0.941375,-165.558105,0.094328,0.000000
75.790001,58.393959,-165.647064,0.005833,0.003706,0.094138,259.749298,13.232260,0.941375,-165.647064,0.094328,0.000000
76.010002,58.364174,-165.647064,0.005829,0.003706,0.094138,259.616821,13.225512,0.941375,-165.647064,0.094328,0.000000
76.230003,58.331032,-165.691544,0.005842,0.003706,0.094138,259.469391,13.218000,0.941375,-165.691544,0.094328,0.000000
76.450005,58.276291,-165.647064,0.005833,0.003706,0.094138,259.225891,13.205596,0.941375,-165.647064,0.094328,0.000000
76.670006,58.247993,-165.647064,0.005851,0.003706,0.094138,259.100006,13.199183,0.941375,-165.647064,0.094328,0.000000
76.890007,58.201073,-165.691544,0.005859,0.003706,0.094138,258.891296,13.188552,0.941375,-165.691544,0.094328,0.000000
77.110001,58.163094,-165.691544,0.005838,0.003706,0.094138,258.722351,13.179946,0.941375,-165.691544,0.094328,0.000000
77.330002,58.134048,-165.691544,0.005833,0.003706,0.094138,258.593170,13.173364,0.941375,-165.691544,0.094328,0.000000
77.550003,58.098297,-165.647064,0.005838,0.003706,0.094138,258.434143,13.165262,0.941375,-165.647064,0.094328,0.000000
77.770004,58.066643,-165.691544,0.005833,0.003706,0.094138,258.293335,13.158090,0.941375,-165.691544,0.094328,0.000000
77.990005,58.014145,-165.647064,0.005825,0.003706,0.094138,258.059814,13.146193,0.941375,-165.647064,0.094328,0.000000
78.210007,57.979881,-165.736023,0.005838,0.003706,0.094138,257.907379,13.138430,0.941375,-165.736023,0.094328,0.000000
78.430000,57.965363,-165.736023,0.005821,0.003706,0.094138,257.842804,13.135139,0.941375,-165.736023,0.094328,0.000000
78.650002,57.918442,-165.736023,0.005842,0.003706,0.094138,257.634094,13.124507,0.941375,-165.736023,0.094328,0.000000
78.870003,57.901688,-165.780502,0.005846,0.003706,0.094138,257.559570,13.120710,0.941375,-165.780502,0.094328,0.000000
79.090004,57.851784,-165.691544,0.005829,0.003706,0.094138,257.337585,13.109402,0.941375,-165.691544,0.094328,0.000000
79.310005,57.811943,-165.736023,0.005838,0.003706,0.094138,257.160370,13.100373,0.941375,-165.736023,0.094328,0.000000
79.530006,57.780663,-165.736023,0.005855,0.003706,0.094138,257.021210,13.093285,0.941375,-165.736023,0.094328,0.000000
79.750000,57.750877,-165.780502,0.005855,0.003706,0.094138,256.888733,13.086536,0.941375,-165.780502,0.094328,0.000000
79.970001,57.739700,-165.736023,0.005833,0.003706,0.094138,256.839020,13.084003,0.941375,-165.736023,0.094328,0.000000
80.190002,57.706932,-165.736023,0.005842,0.003706,0.094138,256.693268,13.076578,0.941375,-165.736023,0.094328,0.000000
80.410004,57.667839,-165.780502,0.005846,0.003706,0.094138,256.519348,13.067719,0.941375,-165.780502,0.094328,0.000000
80.630005,57.648842,-165.780502,0.005838,0.003706,0.094138,256.434845,13.063415,0.941375,-165.780502,0.094328,0.000000
80.850006,57.601555,-165.736023,0.005838,0.003706,0.094138,256.224518,13.052699,0.941375,-165.736023,0.094328,0.000000
81.070007,57.581070,-165.736023,0.005838,0.003706,0.094138,256.133392,13.048058,0.941375,-165.736023,0.094328,0.000000
81.290001,57.558357,-165.736023,0.005833,0.003706,0.094138,256.032349,13.042910,0.941375,-165.736023,0.094328,0.000000
81.510002,57.528938,-165.824982,0.005838,0.003706,0.094138,255.901505,13.036243,0.941375,-165.824982,0.094328,0.000000
81.730003,57.491333,-165.869461,0.005833,0.003706,0.094138,255.734222,13.027722,0.941375,-165.869461,0.094328,0.000000
81.950005,57.459679,-165.824982,0.005846,0.003706,0.094138,255.593414,13.020550,0.941375,-165.824982,0.094328,0.000000
82.170006,57.440689,-165.824982,0.005838,0.003706,0.094138,255.508942,13.016247,0.941375,-165.824982,0.094328,0.000000
82.390007,57.412384,-165.780502,0.005842,0.003706,0.094138,255.383041,13.009831,0.941375,-165.780502,0.094328,0.000000
82.610001,57.390793,-165.824982,0.005838,0.003706,0.094138,255.287003,13.004939,0.941375,-165.824982,0.094328,0.000000
82.830002,57.371056,-165.824982,0.005851,0.003706,0.094138,255.199203,13.000467,0.941375,-165.824982,0.094328,0.000000
83.050003,57.329720,-165.869461,0.005829,0.003706,0.094138,255.015335,12.991100,0.941375,-165.869461,0.094328,0.000000
83.270004,57.309616,-165.780502,0.005855,0.003706,0.094138,254.925903,12.986545,0.941375,-165.780502,0.094328,0.000000
83.490005,57.273865,-165.824982,0.005846,0.003706,0.094138,254.766876,12.978443,0.941375,-165.824982,0.094328,0.000000
83.710007,57.257484,-165.869461,0.005838,0.003706,0.094138,254.694016,12.974731,0.941375,-165.869461,0.094328,0.000000
83.930000,57.247429,-165.869461,0.005842,0.003706,0.094138,254.649277,12.972453,0.941375,-165.869461,0.094328,0.000000
84.150002,57.210190,-165.869461,0.005846,0.003706,0.094138,254.483627,12.964015,0.941375,-165.869461,0.094328,0.000000
84.370003,57.194176,-165.869461,0.005855,0.003706,0.094138,254.412399,12.960385,0.941375,-165.869461,0.094328,0.000000
84.590004,57.162895,-165.869461,0.005838,0.003706,0.094138,254.273254,12.953297,0.941375,-165.869461,0.094328,0.000000
84.810005,57.135712,-165.913940,0.005833,0.003706,0.094138,254.152344,12.947137,0.941375,-165.913940,0.094328,0.000000
85.030006,57.131622,-165.958435,0.005851,0.003706,0.094138,254.134155,12.946211,0.941375,-165.958435,0.094328,0.000000
85.250008,57.096245,-165.913940,0.005842,0.003706,0.094138,253.976776,12.938194,0.941375,-165.913940,0.094328,0.000000
85.470001,57.077621,-165.958435,0.005838,0.003706,0.094138,253.893936,12.933974,0.941375,-165.958435,0.094328,0.000000
85.690002,57.047836,-165.824982,0.005842,0.003706,0.094138,253.761444,12.927224,0.941375,-165.824982,0.094328,0.000000
85.910004,57.022514,-165.958435,0.005838,0.003706,0.094138,253.648819,12.921486,0.941375,-165.958435,0.094328,0.000000
86.130005,57.015068,-165.913940,0.005838,0.003706,0.094138,253.615692,12.919799,0.941375,-165.913940,0.094328,0.000000
86.350006,56.973732,-165.958435,0.005855,0.003706,0.094138,253.431824,12.910432,0.941375,-165.958435,0.094328,0.000000
86.570007,56.963676,-165.913940,0.005851,0.003706,0.094138,253.387085,12.908154,0.941375,-165.913940,0.094328,0.000000
86.790001,56.951393,-165.958435,0.005833,0.003706,0.094138,253.332443,12.905370,0.941375,-165.958435,0.094328,0.000000
87.010002,56.914902,-165.913940,0.005838,0.003706,0.094138,253.170120,12.897101,0.941375,-165.913940,0.094328,0.000000
87.230003,56.897766,-166.002914,0.005838,0.003706,0.094138,253.093903,12.893218,0.941375,-166.002914,0.094328,0.000000
87.450005,56.854202,-165.958435,0.005846,0.003706,0.094138,252.900116,12.883347,0.941375,-165.958435,0.094328,0.000000
87.670006,56.857925,-166.002914,0.005846,0.003706,0.094138,252.916687,12.884190,0.941375,-166.002914,0.094328,0.000000
87.890007,56.842285,-165.958435,0.005855,0.003706,0.094138,252.847107,12.880646,0.941375,-165.958435,0.094328,0.000000
88.110001,56.807655,-165.958435,0.005846,0.003706,0.094138,252.693069,12.872799,0.941375,-165.958435,0.094328,0.000000
88.330002,56.799088,-166.047394,0.005842,0.003706,0.094138,252.654953,12.870857,0.941375,-166.047394,0.094328,0.000000
88.550003,56.758873,-165.958435,0.005855,0.003706,0.094138,252.476074,12.861745,0.941375,-165.958435,0.094328,0.000000
88.770004,56.749939,-166.002914,0.005855,0.003706,0.094138,252.436340,12.859720,0.941375,-166.002914,0.094328,0.000000
88.990005,56.738396,-166.002914,0.005842,0.003706,0.094138,252.384995,12.857104,0.941375,-166.002914,0.094328,0.000000
89.210007,56.710091,-165.958435,0.005825,0.003706,0.094138,252.259079,12.850690,0.941375,-165.958435,0.094328,0.000000
89.430008,56.714561,-166.002914,0.005821,0.003706,0.094138,252.278976,12.851703,0.941375,-166.002914,0.094328,0.000000
89.650002,56.680679,-166.091873,0.005842,0.003706,0.094138,252.128250,12.844026,0.941375,-166.091873,0.094328,0.000000
89.870003,56.658333,-166.002914,0.005842,0.003706,0.094138,252.028854,12.838962,0.941375,-166.002914,0.094328,0.000000
90.090004,56.641205,-166.047394,0.005855,0.003706,0.094138,251.952667,12.835080,0.941375,-166.047394,0.094328,0.000000
90.310005,56.626312,-166.002914,0.005846,0.003706,0.094138,251.886414,12.831706,0.941375,-166.002914,0.094328,0.000000
90.530006,56.619232,-166.047394,0.005846,0.003706,0.094138,251.854919,12.830102,0.941375,-166.047394,0.094328,0.000000
90.750008,56.594284,-166.091873,0.005855,0.003706,0.094138,251.743942,12.824448,0.941375,-166.091873,0.094328,0.000000
90.970001,56.571945,-166.002914,0.005855,0.003706,0.094138,251.644577,12.819386,0.941375,-166.002914,0.094328,0.000000
91.190002,56.554443,-166.047394,0.005864,0.003706,0.094138,251.566727,12.815420,0.941375,-166.047394,0.094328,0.000000
91.410004,56.533958,-166.091873,0.005846,0.003706,0.094138,251.475601,12.810779,0.941375,-166.091873,0.094328,0.000000
91.630005,56.541039,-166.180832,0.005842,0.003706,0.094138,251.507095,12.812383,0.941375,-166.180832,0.094328,0.000000
91.850006,56.514969,-166.136353,0.005842,0.003706,0.094138,251.391144,12.806476,0.941375,-166.136353,0.094328,0.000000
92.070007,56.498589,-166.136353,0.005842,0.003706,0.094138,251.318268,12.802763,0.941375,-166.136353,0.094328,0.000000
92.290001,56.470284,-166.091873,0.005851,0.003706,0.094138,251.192368,12.796350,0.941375,-166.091873,0.094328,0.000000
92.510002,56.437889,-166.047394,0.005825,0.003706,0.094138,251.048264,12.789008,0.941375,-166.047394,0.094328,0.000000
92.700005,56.445709,-166.136353,0.005833,0.003706,0.094138,251.083054,12.790780,0.941375,-166.136353,0.094328,0.000000