File: Data/compression sample NH 10,12,15/AutoNoheating-10-2-1-240201_02012024_190744.csv
Time (sec),S:Load (lbs),S:HL1 (DIM),S:LVDT (in),S:Position (in),Ch:Position (mm),Ch:Load (N),Ch:Stress (MPa),Ch:Strain (mm/mm),Ch:HL1 (DIM),Set Point (),Cycles ()
0.110000,-0.001114,-238.818222,0.000000,-0.000000,-0.000000,-0.004955,-0.000252,-0.000000,-238.818222,0.000182,0.000000
0.360000,-0.008568,-238.862701,0.000009,0.000006,0.000156,-0.038112,-0.001941,0.001563,-238.862701,0.000685,0.000000
0.610000,-0.007446,-238.907181,0.000039,0.000151,0.003825,-0.033123,-0.001687,0.038246,-238.907181,0.004848,0.000000
0.860000,0.007072,-238.818222,0.000203,0.000316,0.008031,0.031460,0.001603,0.080308,-238.818222,0.009011,0.000000
1.110000,0.011543,-238.907181,0.000345,0.000475,0.012072,0.051347,0.002616,0.120719,-238.907181,0.013191,0.000000
1.360000,-0.021599,-238.907181,0.000556,0.000641,0.016269,-0.096076,-0.004894,0.162694,-238.907181,0.017353,0.000000
1.610000,-0.056229,-238.907181,0.000724,0.000792,0.020128,-0.250117,-0.012742,0.201284,-238.907181,0.021516,0.000000
1.860000,0.008194,-238.907181,0.000880,0.000962,0.024430,0.036449,0.001857,0.244300,-238.907181,0.025679,0.000000
2.110000,0.017502,-238.907181,0.001035,0.001131,0.028740,0.077852,0.003966,0.287398,-238.907181,0.029841,0.000000
2.360000,-0.010056,-238.862701,0.001199,0.001295,0.032902,-0.044729,-0.002279,0.329025,-238.862701,0.034004,0.000000
2.610000,0.005211,-238.862701,0.001375,0.001462,0.037143,0.023179,0.001181,0.371434,-238.862701,0.038167,0.000000
2.860000,0.023460,-238.951675,0.001591,0.001622,0.041211,0.104357,0.005316,0.412107,-238.951675,0.042347,0.000000
3.110000,-0.002235,-238.907181,0.001733,0.001786,0.045356,-0.009944,-0.000507,0.453559,-238.907181,0.046510,0.000000
3.360000,-0.004845,-238.907181,0.001893,0.001945,0.049406,-0.021550,-0.001098,0.494061,-238.907181,0.050672,0.000000
3.610000,0.012657,-238.907181,0.002070,0.002110,0.053586,0.056302,0.002868,0.535862,-238.907181,0.054835,0.000000
3.860000,0.000748,-238.951675,0.002242,0.002281,0.057948,0.003326,0.000169,0.579483,-238.951675,0.058997,0.000000
4.110000,-0.042076,-238.951675,0.002423,0.002443,0.062050,-0.187164,-0.009535,0.620499,-238.951675,0.063160,0.000000
4.360000,0.020477,-238.907181,0.002591,0.002605,0.066178,0.091088,0.004640,0.661781,-238.907181,0.067323,0.000000
4.610000,0.039474,-238.996155,0.002751,0.002775,0.070488,0.175591,0.008945,0.704884,-238.996155,0.071486,0.000000
4.860000,-0.000374,-238.907181,0.002906,0.002936,0.074573,-0.001663,-0.000085,0.745730,-238.907181,0.075666,0.000000
5.110000,0.030159,-238.951675,0.003104,0.003102,0.078779,0.134154,0.006834,0.787788,-238.951675,0.079828,0.000000
5.360000,0.043564,-238.907181,0.003242,0.003259,0.082785,0.193782,0.009872,0.827855,-238.907181,0.083991,0.000000
5.610000,0.149696,-239.040634,0.003432,0.003429,0.087104,0.665883,0.033922,0.871044,-239.040634,0.088154,0.000000
5.860000,0.469559,-238.996155,0.003600,0.003584,0.091033,2.088701,0.106404,0.910328,-238.996155,0.092316,0.000000
6.110000,0.597656,-238.951675,0.003665,-0.000000,-0.000000,2.658508,0.135431,-0.000000,-238.951675,0.000217,0.000000
6.360000,0.571594,-238.951675,0.003648,-0.000000,-0.000000,2.542578,0.129525,-0.000000,-238.951675,0.000217,0.000000
6.610000,0.589096,-238.951675,0.003652,-0.000000,-0.000000,2.620430,0.133491,-0.000000,-238.951675,0.000425,0.000000
6.860000,0.535469,-238.951675,0.003669,-0.000000,-0.000000,2.381885,0.121339,-0.000000,-238.951675,0.000850,0.000000
7.110000,0.546272,-238.996155,0.003682,0.000012,0.000304,2.429940,0.123787,0.003035,-238.996155,0.001266,0.000000
7.360000,0.672134,-238.996155,0.003699,0.000033,0.000832,2.989803,0.152308,0.008323,-238.996155,0.001682,0.000000
7.610000,0.729103,-239.040634,0.003665,0.000046,0.001179,3.243212,0.165217,0.011794,-239.040634,0.002099,0.000000
7.860001,0.754051,-239.040634,0.003729,0.000064,0.001613,3.354187,0.170870,0.016131,-239.040634,0.002515,0.000000
8.110001,0.819221,-238.996155,0.003717,0.000079,0.001995,3.644079,0.185638,0.019946,-238.996155,0.002931,0.000000
8.360001,0.843422,-238.996155,0.003747,0.000093,0.002350,3.751728,0.191122,0.023500,-238.996155,0.003347,0.000000
8.610001,0.974495,-239.040634,0.003798,0.000110,0.002801,4.334770,0.220824,0.028012,-239.040634,0.003764,0.000000
8.860001,1.008759,-238.996155,0.003807,0.000125,0.003165,4.487182,0.228588,0.031653,-238.996155,0.004180,0.000000
9.110001,1.068710,-239.040634,0.003781,0.000139,0.003521,4.753861,0.242173,0.035207,-239.040634,0.004596,0.000000
9.360001,1.181534,-239.085114,0.003816,0.000167,0.004249,5.255725,0.267739,0.042493,-239.085114,0.005012,0.000000
9.610001,1.191963,-239.040634,0.003854,0.000180,0.004570,5.302117,0.270103,0.045703,-239.040634,0.005429,0.000000
9.860001,1.190102,-239.040634,0.003859,0.000197,0.005004,5.293837,0.269681,0.050040,-239.040634,0.005845,0.000000
10.110001,1.255264,-238.996155,0.003902,0.000212,0.005394,5.583694,0.284447,0.053942,-238.996155,0.006261,0.000000
10.360001,1.352081,-239.040634,0.003915,0.000230,0.005854,6.014358,0.306386,0.058537,-239.040634,0.006678,0.000000
10.610001,1.395279,-239.085114,0.003889,0.000245,0.006235,6.206511,0.316175,0.062352,-239.085114,0.007094,0.000000
10.860001,1.403847,-239.085114,0.003919,0.000254,0.006452,6.244622,0.318116,0.064521,-239.085114,0.007510,0.000000
11.110001,1.476456,-239.085114,0.003932,0.000274,0.006955,6.567603,0.334570,0.069551,-239.085114,0.007926,0.000000
11.360001,1.544601,-239.174072,0.003975,0.000292,0.007423,6.870730,0.350012,0.074233,-239.174072,0.008343,0.000000
11.610001,1.581467,-239.085114,0.003975,0.000309,0.007848,7.034715,0.358365,0.078484,-239.085114,0.008759,0.000000
11.860001,1.616096,-239.040634,0.004027,0.000325,0.008265,7.188756,0.366213,0.082647,-239.040634,0.009184,0.000000
12.110001,1.628387,-239.085114,0.004001,0.000339,0.008611,7.243429,0.368998,0.086114,-239.085114,0.009600,0.000000
12.360001,1.686844,-239.085114,0.004053,0.000358,0.009088,7.503456,0.382244,0.090883,-239.085114,0.010016,0.000000
12.610001,1.724083,-239.174072,0.004049,0.000373,0.009470,7.669104,0.390683,0.094702,-239.174072,0.010433,0.000000
12.860001,1.779938,-239.174072,0.004083,0.000390,0.009895,7.917559,0.403340,0.098949,-239.174072,0.010849,0.000000
13.110001,1.822021,-239.174072,0.004100,0.000410,0.010407,8.104756,0.412876,0.104066,-239.174072,0.011265,0.000000
13.360001,1.848083,-239.129593,0.004130,0.000425,0.010797,8.220686,0.418782,0.107968,-239.129593,0.011681,0.000000
13.610001,1.851067,-239.174072,0.004165,0.000444,0.011274,8.233955,0.419458,0.112737,-239.174072,0.012098,0.000000
13.860001,1.870430,-239.129593,0.004186,0.000460,0.011690,8.320088,0.423845,0.116900,-239.129593,0.012514,0.000000
14.110001,1.886063,-239.218552,0.004182,0.000473,0.012011,8.389626,0.427388,0.120110,-239.218552,0.012930,0.000000
14.360001,1.944527,-239.218552,0.004221,0.000490,0.012436,8.649687,0.440636,0.124360,-239.218552,0.013347,0.000000
14.610001,1.957191,-239.174072,0.004204,0.000505,0.012818,8.706022,0.443506,0.128175,-239.174072,0.013763,0.000000
14.860001,2.034271,-239.174072,0.004221,0.000525,0.013329,9.048890,0.460972,0.133293,-239.174072,0.014179,0.000000
15.110001,2.115822,-239.174072,0.004255,0.000547,0.013902,9.411646,0.479452,0.139015,-239.174072,0.014595,0.000000
15.360001,2.081932,-239.218552,0.004277,0.000563,0.014292,9.260897,0.471773,0.142918,-239.218552,0.015012,0.000000
15.610001,2.020119,-239.218552,0.004312,0.000575,0.014604,8.985937,0.457765,0.146040,-239.218552,0.015428,0.000000
15.860001,2.039482,-239.307510,0.004320,0.000591,0.015012,9.072069,0.462153,0.150117,-239.307510,0.015844,0.000000
16.110001,2.089378,-239.263031,0.004372,0.000608,0.015454,9.294019,0.473460,0.154537,-239.263031,0.016260,0.000000
16.360001,2.141884,-239.218552,0.004393,0.000626,0.015905,9.527575,0.485358,0.159049,-239.218552,0.016677,0.000000
16.610001,2.108376,-239.263031,0.004376,0.000636,0.016147,9.378523,0.477765,0.161475,-239.263031,0.017093,0.000000
16.860001,2.185081,-239.218552,0.004415,0.000657,0.016685,9.719728,0.495147,0.166853,-239.218552,0.017509,0.000000
17.110001,2.228645,-239.263031,0.004437,0.000677,0.017206,9.913509,0.505018,0.172058,-239.263031,0.017934,0.000000
17.360001,2.213379,-239.218552,0.004445,0.000693,0.017596,9.845601,0.501559,0.175960,-239.218552,0.018350,0.000000
17.610001,2.172424,-239.218552,0.004467,0.000707,0.017960,9.663426,0.492278,0.179601,-239.218552,0.018767,0.000000
17.860001,2.191040,-239.263031,0.004514,0.000720,0.018290,9.746233,0.496497,0.182897,-239.263031,0.019183,0.000000
18.110001,2.230507,-239.263031,0.004506,0.000737,0.018723,9.921790,0.505440,0.187235,-239.263031,0.019599,0.000000
18.360001,2.255089,-239.263031,0.004531,0.000753,0.019122,10.031136,0.511010,0.191224,-239.263031,0.020016,0.000000
18.610001,2.240189,-239.263031,0.004540,0.000767,0.019478,9.964856,0.507634,0.194778,-239.263031,0.020432,0.000000
18.860001,2.307961,-239.307510,0.004557,0.000787,0.019981,10.266321,0.522991,0.199808,-239.307510,0.020848,0.000000
19.110001,2.317642,-239.307510,0.004605,0.000804,0.020415,10.309387,0.525185,0.204146,-239.307510,0.021264,0.000000
19.360001,2.305733,-239.263031,0.004609,0.000820,0.020839,10.256412,0.522487,0.208393,-239.263031,0.021681,0.000000
19.610001,2.312431,-239.307510,0.004648,0.000839,0.021299,10.286208,0.524004,0.212991,-239.307510,0.022097,0.000000
19.860001,2.307220,-239.352005,0.004661,0.000851,0.021620,10.263029,0.522824,0.216197,-239.352005,0.022513,0.000000
20.110001,2.361961,-239.263031,0.004665,0.000871,0.022123,10.506529,0.535228,0.221227,-239.263031,0.022929,0.000000
20.360001,2.344826,-239.352005,0.004695,0.000884,0.022452,10.430305,0.531345,0.224524,-239.352005,0.023346,0.000000
20.610001,2.344460,-239.263031,0.004721,0.000898,0.022799,10.428677,0.531262,0.227995,-239.263031,0.023762,0.000000
20.860001,2.409248,-239.307510,0.004730,0.000921,0.023398,10.716872,0.545943,0.233978,-239.307510,0.024178,0.000000
21.110001,2.397705,-239.352005,0.004738,0.000935,0.023753,10.665524,0.543328,0.237532,-239.352005,0.024595,0.000000
21.360001,2.388771,-239.396484,0.004790,0.000951,0.024152,10.625784,0.541303,0.241522,-239.396484,0.025011,0.000000
21.610001,2.390633,-239.352005,0.004799,0.000966,0.024525,10.634065,0.541725,0.245250,-239.352005,0.025427,0.000000
21.860001,2.368286,-239.396484,0.004786,0.000979,0.024872,10.534663,0.536661,0.248721,-239.396484,0.025843,0.000000
22.110001,2.438293,-239.352005,0.004855,0.000999,0.025375,10.846071,0.552525,0.253751,-239.352005,0.026268,0.000000
22.360001,2.419678,-239.396484,0.004842,0.001012,0.025696,10.763264,0.548307,0.256957,-239.396484,0.026685,0.000000
22.610001,2.498245,-239.352005,0.004876,0.001032,0.026216,11.112750,0.566110,0.262161,-239.352005,0.027101,0.000000
22.860001,2.515373,-239.485443,0.004902,0.001053,0.026745,11.188939,0.569992,0.267452,-239.485443,0.027517,0.000000
23.110001,2.479630,-239.352005,0.004928,0.001068,0.027135,11.029943,0.561892,0.271354,-239.352005,0.027933,0.000000
23.360001,2.465851,-239.396484,0.004928,0.001083,0.027517,10.968653,0.558770,0.275169,-239.396484,0.028350,0.000000
23.610001,2.490425,-239.485443,0.004980,0.001098,0.027890,11.077964,0.564338,0.278898,-239.485443,0.028766,0.000000
23.860001,2.468826,-239.396484,0.004980,0.001109,0.028176,10.981888,0.559444,0.281763,-239.396484,0.029182,0.000000
24.110001,2.481865,-239.396484,0.005010,0.001123,0.028514,11.039886,0.562399,0.285143,-239.396484,0.029598,0.000000
24.360001,2.525429,-239.440964,0.005032,0.001141,0.028974,11.233668,0.572270,0.289741,-239.440964,0.030015,0.000000
24.610001,2.580910,-239.485443,0.005027,0.001161,0.029485,11.480460,0.584843,0.294855,-239.485443,0.030431,0.000000
24.860001,2.621498,-239.396484,0.005075,0.001183,0.030049,11.661006,0.594040,0.300494,-239.396484,0.030847,0.000000
25.110001,2.587616,-239.485443,0.005066,0.001196,0.030379,11.510291,0.586362,0.303787,-239.485443,0.031264,0.000000
25.360001,2.563042,-239.440964,0.005139,0.001211,0.030769,11.400979,0.580794,0.307689,-239.440964,0.031680,0.000000
25.610001,2.576820,-239.440964,0.005148,0.001226,0.031151,11.462270,0.583916,0.311508,-239.440964,0.032096,0.000000
25.860001,2.558197,-239.440964,0.005161,0.001239,0.031471,11.379429,0.579696,0.314714,-239.440964,0.032512,0.000000
26.110001,2.671028,-239.529922,0.005165,0.001260,0.032001,11.881327,0.605264,0.320005,-239.529922,0.032929,0.000000
26.360001,2.653900,-239.440964,0.005191,0.001275,0.032382,11.805138,0.601382,0.323820,-239.440964,0.033345,0.000000
26.610001,2.676987,-239.440964,0.005182,0.001293,0.032851,11.907831,0.606614,0.328506,-239.440964,0.033761,0.000000
26.860001,2.725769,-239.529922,0.005243,0.001313,0.033353,12.124826,0.617668,0.333533,-239.529922,0.034177,0.000000
27.110001,2.623734,-239.574402,0.005230,0.001322,0.033570,11.670950,0.594547,0.335701,-239.574402,0.034602,0.000000
27.360001,2.678848,-239.574402,0.005260,0.001341,0.034073,11.916112,0.607036,0.340731,-239.574402,0.035019,0.000000
27.610001,2.660225,-239.440964,0.005260,0.001353,0.034368,11.833271,0.602816,0.343680,-239.440964,0.035435,0.000000
27.860001,2.710495,-239.529922,0.005299,0.001370,0.034810,12.056884,0.614207,0.348104,-239.529922,0.035851,0.000000
28.110001,2.750343,-239.574402,0.005329,0.001385,0.035183,12.234138,0.623237,0.351832,-239.574402,0.036267,0.000000
28.360001,2.727631,-239.485443,0.005342,0.001398,0.035513,12.133107,0.618090,0.355129,-239.485443,0.036684,0.000000
28.610001,2.816994,-239.485443,0.005364,0.001423,0.036146,12.530614,0.638340,0.361457,-239.485443,0.037100,0.000000
28.860001,2.863541,-239.574402,0.005376,0.001443,0.036649,12.737665,0.648888,0.366488,-239.574402,0.037516,0.000000
29.110001,2.841202,-239.574402,0.005437,0.001460,0.037083,12.638297,0.643826,0.370825,-239.574402,0.037932,0.000000
29.360001,2.792046,-239.529922,0.005445,0.001473,0.037412,12.419639,0.632687,0.374122,-239.529922,0.038349,0.000000
29.610001,2.758163,-239.529922,0.005463,0.001486,0.037750,12.268924,0.625009,0.377502,-239.529922,0.038765,0.000000
29.860001,2.885139,-239.574402,0.005445,0.001507,0.038271,12.833741,0.653782,0.382706,-239.574402,0.039181,0.000000
30.110001,2.874718,-239.574402,0.005501,0.001520,0.038609,12.787383,0.651420,0.386090,-239.574402,0.039598,0.000000
30.360001,2.887001,-239.574402,0.005497,0.001533,0.038938,12.842022,0.654204,0.389382,-239.574402,0.040014,0.000000
30.610001,2.935783,-239.574402,0.005514,0.001553,0.039459,13.059017,0.665258,0.394587,-239.574402,0.040430,0.000000
30.860001,2.995361,-239.663361,0.005519,0.001576,0.040040,13.324033,0.678759,0.400396,-239.663361,0.040846,0.000000
31.110001,2.958870,-239.618881,0.005596,0.001593,0.040465,13.161711,0.670490,0.404647,-239.618881,0.041263,0.000000
31.360001,2.959244,-239.618881,0.005601,0.001607,0.040812,13.163374,0.670574,0.408118,-239.618881,0.041679,0.000000
31.610001,2.977859,-239.663361,0.005631,0.001625,0.041263,13.246181,0.674793,0.412625,-239.663361,0.042095,0.000000
31.860001,3.049728,-239.618881,0.005627,0.001642,0.041696,13.565869,0.691078,0.416963,-239.618881,0.042511,0.000000
32.110001,3.017334,-239.663361,0.005665,0.001652,0.041965,13.421772,0.683738,0.419650,-239.663361,0.042928,0.000000
32.360001,3.068718,-239.618881,0.005639,0.001670,0.042407,13.650339,0.695381,0.424071,-239.618881,0.043353,0.000000
32.610001,3.129417,-239.663361,0.005674,0.001688,0.042876,13.920344,0.709136,0.428757,-239.663361,0.043769,0.000000
32.860001,3.111542,-239.707840,0.005708,0.001701,0.043214,13.840829,0.705085,0.432137,-239.707840,0.044185,0.000000
33.110001,3.158836,-239.663361,0.005704,0.001720,0.043691,14.051206,0.715803,0.436909,-239.663361,0.044601,0.000000
33.360001,3.146919,-239.663361,0.005756,0.001735,0.044072,13.998196,0.713102,0.440725,-239.663361,0.045018,0.000000
33.610001,3.225861,-239.663361,0.005773,0.001754,0.044558,14.349344,0.730990,0.445581,-239.663361,0.045434,0.000000
33.860001,3.235916,-239.663361,0.005756,0.001769,0.044931,14.394073,0.733269,0.449309,-239.663361,0.045850,0.000000
34.110001,3.251930,-239.663361,0.005782,0.001784,0.045321,14.465308,0.736898,0.453211,-239.663361,0.046267,0.000000
34.360001,3.344650,-239.663361,0.005833,0.001805,0.045850,14.877748,0.757909,0.458502,-239.663361,0.046683,0.000000
34.610001,3.335342,-239.707840,0.005855,0.001823,0.046301,14.836344,0.755799,0.463010,-239.707840,0.047099,0.000000
34.860001,3.338692,-239.707840,0.005846,0.001837,0.046665,14.851242,0.756558,0.466655,-239.707840,0.047515,0.000000
35.110001,3.327148,-239.707840,0.005911,0.001853,0.047073,14.799895,0.753943,0.470731,-239.707840,0.047932,0.000000
35.360001,3.342789,-239.707840,0.005911,0.001868,0.047455,14.869467,0.757487,0.474546,-239.707840,0.048348,0.000000
35.610001,3.438858,-239.752319,0.005937,0.001888,0.047949,15.296804,0.779256,0.479489,-239.752319,0.048764,0.000000
35.860001,3.397156,-239.707840,0.005959,0.001899,0.048244,15.111303,0.769807,0.482438,-239.707840,0.049180,0.000000
36.110001,3.481308,-239.707840,0.005963,0.001916,0.048669,15.485631,0.788876,0.486688,-239.707840,0.049597,0.000000
36.360001,3.509239,-239.752319,0.005933,0.001934,0.049111,15.609876,0.795205,0.491109,-239.752319,0.050013,0.000000
36.610001,3.627281,-239.752319,0.006019,0.001958,0.049727,16.134953,0.821954,0.497267,-239.752319,0.050429,0.000000
36.860001,3.515938,-239.707840,0.006028,0.001971,0.050056,15.639672,0.796723,0.500564,-239.707840,0.050846,0.000000
37.110001,3.528976,-239.752319,0.006028,0.001985,0.050420,15.697671,0.799677,0.504205,-239.752319,0.051261,0.000000
37.360001,3.578873,-239.707840,0.006049,0.002001,0.050819,15.919621,0.810984,0.508194,-239.707840,0.051687,0.000000
37.610001,3.647385,-239.796814,0.006049,0.002019,0.051270,16.224377,0.826509,0.512702,-239.796814,0.052103,0.000000
37.860001,3.679039,-239.752319,0.006092,0.002033,0.051643,16.365183,0.833682,0.516434,-239.752319,0.052519,0.000000
38.110001,3.710320,-239.752319,0.006096,0.002049,0.052051,16.504326,0.840770,0.520510,-239.752319,0.052936,0.000000
38.360001,3.816071,-239.752319,0.006114,0.002070,0.052580,16.974730,0.864734,0.525798,-239.752319,0.053351,0.000000
38.610001,3.814583,-239.796814,0.006170,0.002085,0.052970,16.968111,0.864397,0.529700,-239.796814,0.053768,0.000000
38.860001,3.803040,-239.841293,0.006170,0.002101,0.053360,16.916765,0.861781,0.533602,-239.841293,0.054184,0.000000
39.110001,3.833199,-239.841293,0.006187,0.002115,0.053733,17.050919,0.868615,0.537334,-239.841293,0.054601,0.000000
39.360001,3.955338,-239.796814,0.006174,0.002135,0.054228,17.594219,0.896292,0.542277,-239.796814,0.055017,0.000000
39.610001,3.970978,-239.885773,0.006222,0.002150,0.054618,17.663792,0.899836,0.546179,-239.885773,0.055433,0.000000
39.860001,3.901344,-239.796814,0.006243,0.002160,0.054861,17.354046,0.884057,0.548605,-239.796814,0.055849,0.000000
40.110001,4.080086,-239.841293,0.006273,0.002181,0.055398,18.149128,0.924561,0.553984,-239.841293,0.056265,0.000000
40.360001,4.142647,-239.841293,0.006299,0.002199,0.055858,18.427414,0.938737,0.558579,-239.841293,0.056682,0.000000
40.610001,4.156052,-239.885773,0.006316,0.002216,0.056292,18.487041,0.941775,0.562916,-239.885773,0.057098,0.000000
40.860001,4.183601,-239.885773,0.006295,0.002231,0.056656,18.609589,0.948018,0.566557,-239.885773,0.057515,0.000000
41.110001,4.204086,-239.841293,0.006312,0.002247,0.057072,18.700710,0.952660,0.570721,-239.841293,0.057930,0.000000
41.360001,4.303139,-239.841293,0.006368,0.002265,0.057532,19.141317,0.975105,0.575315,-239.841293,0.058347,0.000000
41.610001,4.326965,-239.885773,0.006372,0.002280,0.057913,19.247303,0.980504,0.579134,-239.885773,0.058763,0.000000
41.860001,4.291222,-239.841293,0.006394,0.002291,0.058200,19.088306,0.972405,0.581996,-239.841293,0.059179,0.000000
42.110001,4.506081,-239.885773,0.006411,0.002315,0.058807,20.044048,1.021092,0.588067,-239.885773,0.059596,0.000000
42.360001,4.485970,-239.841293,0.006411,0.002331,0.059197,19.954590,1.016535,0.591969,-239.841293,0.060020,0.000000
42.610001,4.430489,-239.841293,0.006428,0.002342,0.059483,19.707798,1.003963,0.594830,-239.841293,0.060437,0.000000
42.860001,4.567146,-239.930252,0.006472,0.002362,0.059986,20.315681,1.034930,0.599860,-239.930252,0.060853,0.000000
43.110001,4.451340,-239.930252,0.006446,0.002369,0.060177,19.800549,1.008688,0.601768,-239.930252,0.061269,0.000000
43.360001,4.741417,-239.930252,0.006502,0.002394,0.060810,21.090876,1.074420,0.608096,-239.930252,0.061686,0.000000
43.610001,4.649811,-239.930252,0.006506,0.002405,0.061079,20.683392,1.053662,0.610787,-239.930252,0.062102,0.000000
43.860001,4.684814,-239.930252,0.006558,0.002420,0.061478,20.839096,1.061594,0.614777,-239.930252,0.062518,0.000000
44.110001,5.000961,-239.885773,0.006554,0.002446,0.062119,22.245386,1.133234,0.621192,-239.885773,0.062934,0.000000
44.360001,5.036713,-239.930252,0.006571,0.002463,0.062570,22.404417,1.141335,0.625704,-239.930252,0.063351,0.000000
44.610001,4.986069,-239.974731,0.006592,0.002478,0.062934,22.179142,1.129859,0.629345,-239.974731,0.063767,0.000000
44.860001,5.053841,-240.019211,0.006618,0.002493,0.063325,22.480606,1.145217,0.633247,-240.019211,0.064183,0.000000
45.110001,5.015854,-240.019211,0.006635,0.002504,0.063602,22.311632,1.136609,0.636021,-240.019211,0.064599,0.000000
45.360001,5.178581,-240.019211,0.006631,0.002520,0.064001,23.035480,1.173483,0.640011,-240.019211,0.065016,0.000000
45.610001,5.133896,-240.019211,0.006618,0.002529,0.064235,22.836710,1.163357,0.642353,-240.019211,0.065432,0.000000
45.860001,4.894089,-240.019211,0.006661,0.002529,0.064235,21.769995,1.109016,0.642353,-240.019211,0.065848,0.000000
46.110001,5.603088,-240.019211,0.006704,0.002573,0.065345,24.923782,1.269678,0.653455,-240.019211,0.066265,0.000000
46.360001,5.671234,-240.019211,0.006735,0.002592,0.065840,25.226910,1.285120,0.658398,-240.019211,0.066681,0.000000
46.610001,5.669373,-240.019211,0.006726,0.002607,0.066230,25.218628,1.284698,0.662300,-240.019211,0.067097,0.000000
46.860001,5.676445,-240.019211,0.006752,0.002622,0.066594,25.250088,1.286301,0.665941,-240.019211,0.067513,0.000000
47.110001,5.695808,-240.019211,0.006756,0.002634,0.066915,25.336222,1.290689,0.669151,-240.019211,0.067930,0.000000
47.360001,5.846619,-240.019211,0.006791,0.002650,0.067323,26.007059,1.324863,0.673227,-240.019211,0.068346,0.000000
47.610001,6.026474,-240.063690,0.006804,0.002669,0.067791,26.807095,1.365619,0.677909,-240.063690,0.068771,0.000000
47.860001,6.147499,-240.019211,0.006799,0.002686,0.068216,27.345442,1.393043,0.682159,-240.019211,0.069187,0.000000
48.110001,6.292351,-240.063690,0.006834,0.002706,0.068745,27.989775,1.425867,0.687450,-240.063690,0.069603,0.000000
48.360001,6.282295,-240.063690,0.006855,0.002718,0.069049,27.945045,1.423589,0.690486,-240.063690,0.070020,0.000000
48.610001,6.463272,-240.019211,0.006864,0.002738,0.069534,28.750071,1.464598,0.695342,-240.019211,0.070436,0.000000
48.860001,6.354538,-240.019211,0.006885,0.002749,0.069820,28.266397,1.439959,0.698203,-240.019211,0.070852,0.000000
49.110001,6.609238,-240.019211,0.006937,0.002765,0.070228,29.399357,1.497675,0.702280,-240.019211,0.071268,0.000000
49.360001,6.803246,-240.108170,0.006924,0.002783,0.070679,30.262348,1.541637,0.706788,-240.108170,0.071685,0.000000
49.610001,6.866173,-240.108170,0.006946,0.002797,0.071043,30.542261,1.555897,0.710432,-240.108170,0.072101,0.000000
49.860001,6.965973,-240.108170,0.006954,0.002813,0.071459,30.986195,1.578512,0.714592,-240.108170,0.072517,0.000000
50.110001,7.286957,-240.108170,0.006946,0.002834,0.071988,32.414001,1.651248,0.719883,-240.108170,0.072934,0.000000
50.360001,7.412071,-240.108170,0.007015,0.002852,0.072431,32.970539,1.679599,0.724308,-240.108170,0.073350,0.000000
50.610001,7.495857,-240.108170,0.007041,0.002868,0.072838,33.343239,1.698586,0.728384,-240.108170,0.073766,0.000000
50.860001,7.433296,-240.197128,0.007045,0.002879,0.073133,33.064953,1.684409,0.731333,-240.197128,0.074182,0.000000
51.110001,7.942703,-240.108170,0.007054,0.002901,0.073679,35.330910,1.799842,0.736794,-240.108170,0.074599,0.000000
51.360001,7.761734,-240.197128,0.007067,0.002910,0.073914,34.525917,1.758834,0.739137,-240.197128,0.075015,0.000000
51.610001,8.192940,-240.152649,0.007080,0.002931,0.074442,36.444016,1.856547,0.744425,-240.152649,0.075431,0.000000
51.860001,8.263313,-240.152649,0.007092,0.002945,0.074807,36.757053,1.872494,0.748069,-240.152649,0.075847,0.000000
52.110001,8.830070,-240.152649,0.007131,0.002972,0.075483,39.278114,2.000922,0.754833,-240.152649,0.076264,0.000000
52.360001,8.675163,-240.152649,0.007140,0.002986,0.075839,38.589054,1.965820,0.758387,-240.152649,0.076680,0.000000
52.610001,8.919067,-240.152649,0.007123,0.003003,0.076264,39.673992,2.021090,0.762637,-240.152649,0.077105,0.000000
52.860001,8.855392,-240.152649,0.007170,0.003013,0.076541,39.390755,2.006661,0.765412,-240.152649,0.077521,0.000000
53.110004,9.372612,-240.241623,0.007144,0.003035,0.077096,41.691460,2.123864,0.770964,-240.241623,0.077937,0.000000
53.360004,9.443741,-240.197128,0.007217,0.003049,0.077434,42.007858,2.139982,0.774344,-240.197128,0.078354,0.000000
53.610004,9.551727,-240.241623,0.007226,0.003062,0.077781,42.488205,2.164452,0.777815,-240.241623,0.078770,0.000000
53.860004,10.113266,-240.241623,0.007243,0.003084,0.078328,44.986053,2.291699,0.783276,-240.241623,0.079186,0.000000
54.110004,10.089806,-240.197128,0.007269,0.003096,0.078649,44.881699,2.286383,0.786486,-240.197128,0.079603,0.000000
54.360004,10.337433,-240.197128,0.007274,0.003113,0.079082,45.983196,2.342496,0.790824,-240.197128,0.080019,0.000000
54.610004,10.807739,-240.241623,0.007261,0.003133,0.079568,48.075226,2.449069,0.795680,-240.241623,0.080435,0.000000
54.860004,10.813698,-240.241623,0.007291,0.003147,0.079941,48.101730,2.450419,0.799408,-240.241623,0.080851,0.000000
55.110004,11.303368,-240.241623,0.007304,0.003166,0.080409,50.279892,2.561380,0.804090,-240.241623,0.081268,0.000000
55.360004,11.109734,-240.286102,0.007325,0.003176,0.080669,49.418564,2.517502,0.806694,-240.286102,0.081684,0.000000
55.610004,11.566261,-240.286102,0.007325,0.003193,0.081111,51.449299,2.620952,0.811114,-240.286102,0.082100,0.000000
55.860004,12.220146,-240.286102,0.007343,0.003217,0.081701,54.357925,2.769125,0.817011,-240.286102,0.082516,0.000000
56.110004,12.054810,-240.286102,0.007386,0.003231,0.082057,53.622471,2.731659,0.820569,-240.286102,0.082933,0.000000
56.360004,12.725082,-240.286102,0.007373,0.003249,0.082534,56.603992,2.883545,0.825338,-240.286102,0.083349,0.000000
56.610004,12.736252,-240.286102,0.007412,0.003262,0.082855,56.653679,2.886076,0.828548,-240.286102,0.083765,0.000000
56.860004,13.357742,-240.330582,0.007437,0.003282,0.083375,59.418205,3.026908,0.833752,-240.330582,0.084181,0.000000
57.110004,13.154427,-240.286102,0.007420,0.003292,0.083609,58.513813,2.980836,0.836091,-240.286102,0.084598,0.000000
57.360004,13.580421,-240.330582,0.007455,0.003306,0.083965,60.408733,3.077367,0.839649,-240.330582,0.085014,0.000000
57.610004,14.311020,-240.330582,0.007442,0.003329,0.084555,63.658596,3.242923,0.845546,-240.330582,0.085439,0.000000
57.860004,15.002510,-240.375061,0.007480,0.003350,0.085101,66.734497,3.399617,0.851007,-240.375061,0.085855,0.000000
58.110004,15.111618,-240.330582,0.007442,0.003365,0.085474,67.219833,3.424342,0.854735,-240.330582,0.086271,0.000000
58.360004,15.237854,-240.375061,0.007480,0.003379,0.085821,67.781357,3.452947,0.858206,-240.375061,0.086688,0.000000
58.610004,15.555489,-240.375061,0.007493,0.003394,0.086211,69.194267,3.524924,0.862108,-240.375061,0.087104,0.000000
58.860004,16.302841,-240.375061,0.007524,0.003415,0.086749,72.518661,3.694277,0.867487,-240.375061,0.087520,0.000000
59.110004,16.655472,-240.286102,0.007506,0.003430,0.087130,74.087242,3.774184,0.871302,-240.286102,0.087937,0.000000
59.360004,16.664787,-240.330582,0.007532,0.003439,0.087356,74.128677,3.776295,0.873558,-240.330582,0.088353,0.000000
59.610004,17.736099,-240.330582,0.007575,0.003463,0.087962,78.894112,4.019058,0.879625,-240.330582,0.088769,0.000000
59.860004,18.147942,-240.375061,0.007571,0.003479,0.088379,80.726074,4.112382,0.883788,-240.375061,0.089185,0.000000
60.110004,18.346420,-240.375061,0.007558,0.003494,0.088752,81.608955,4.157358,0.887520,-240.375061,0.089602,0.000000
60.360004,18.868484,-240.375061,0.007597,0.003511,0.089177,83.931213,4.275660,0.891767,-240.375061,0.090018,0.000000
60.610004,19.073288,-240.375061,0.007618,0.003525,0.089524,84.842224,4.322069,0.895237,-240.375061,0.090434,0.000000
60.860004,19.831810,-240.419540,0.007649,0.003542,0.089957,88.216293,4.493952,0.899571,-240.419540,0.090850,0.000000
61.110004,20.258926,-240.419540,0.007631,0.003558,0.090373,90.116203,4.590738,0.903735,-240.419540,0.091267,0.000000
61.360004,20.502457,-240.419540,0.007657,0.003571,0.090703,91.199486,4.645923,0.907031,-240.419540,0.091683,0.000000
61.610004,21.676544,-240.419540,0.007679,0.003592,0.091241,96.422081,4.911975,0.912406,-240.419540,0.092099,0.000000
61.860004,22.171059,-240.464020,0.007687,0.003609,0.091666,98.621796,5.024034,0.916656,-240.464020,0.092516,0.000000
62.110004,22.638756,-240.464020,0.007670,0.003626,0.092099,100.702217,5.130015,0.920994,-240.464020,0.092932,0.000000
62.360004,23.188377,-240.464020,0.007713,0.003641,0.092472,103.147057,5.254561,0.924722,-240.464020,0.093348,0.000000
62.610004,23.893654,-240.464020,0.007713,0.003659,0.092949,106.284279,5.414379,0.929491,-240.464020,0.093764,0.000000
62.860004,24.511047,-240.508499,0.007713,0.003675,0.093348,109.030586,5.554283,0.933480,-240.508499,0.094189,0.000000
63.110004,24.789581,-240.464020,0.007748,0.003687,0.093652,110.269562,5.617399,0.936516,-240.464020,0.094606,0.000000
63.360004,25.570068,-240.464020,0.007731,0.003706,0.094120,113.741348,5.794261,0.941201,-240.464020,0.095022,0.000000
63.610004,26.533401,-240.508499,0.007765,0.003724,0.094597,118.026466,6.012555,0.945970,-240.508499,0.095438,0.000000
63.860004,27.019348,-240.508499,0.007800,0.003738,0.094952,120.188065,6.122672,0.949524,-240.508499,0.095854,0.000000
64.110001,27.709351,-240.552979,0.007765,0.003756,0.095412,123.257347,6.279028,0.954123,-240.552979,0.096271,0.000000
64.360001,27.970009,-240.464020,0.007808,0.003767,0.095690,124.416817,6.338095,0.956897,-240.464020,0.096687,0.000000
64.610001,29.201820,-240.508499,0.007800,0.003789,0.096245,129.896179,6.617227,0.962446,-240.508499,0.097103,0.000000
64.860001,29.617386,-240.508499,0.007830,0.003800,0.096531,131.744705,6.711396,0.965307,-240.508499,0.097519,0.000000
65.110001,30.187866,-240.552979,0.007834,0.003813,0.096852,134.282333,6.840668,0.968517,-240.552979,0.097936,0.000000
65.360001,31.533989,-240.552979,0.007851,0.003838,0.097494,140.270187,7.145704,0.974936,-240.552979,0.098352,0.000000
65.610001,32.841019,-240.552979,0.007886,0.003858,0.098005,146.084152,7.441881,0.980049,-240.552979,0.098768,0.000000
65.860001,33.333290,-240.552979,0.007881,0.003872,0.098352,148.273880,7.553432,0.983520,-240.552979,0.099185,0.000000
66.110001,33.809555,-240.552979,0.007894,0.003886,0.098699,150.392410,7.661355,0.986991,-240.552979,0.099601,0.000000
66.360001,34.293640,-240.597458,0.007890,0.003898,0.099011,152.545731,7.771050,0.990110,-240.597458,0.100017,0.000000
66.610001,35.237236,-240.464020,0.007869,0.003916,0.099471,156.743057,7.984872,0.994708,-240.464020,0.100433,0.000000
66.860001,35.293091,-240.597458,0.007907,0.003924,0.099670,156.991516,7.997529,0.996703,-240.597458,0.100850,0.000000
67.110001,36.876793,-240.641953,0.007886,0.003947,0.100251,164.036163,8.356400,1.002513,-240.641953,0.101266,0.000000
67.360001,37.951080,-240.641953,0.007907,0.003962,0.100641,168.814835,8.599837,1.006415,-240.641953,0.101682,0.000000
67.610001,39.472969,-240.641953,0.007938,0.003986,0.101240,175.584534,8.944703,1.012399,-240.641953,0.102098,0.000000
67.860001,40.059082,-240.686432,0.007916,0.003999,0.101587,178.191696,9.077518,1.015866,-240.686432,0.102523,0.000000
68.110001,40.844048,-240.597458,0.007933,0.004015,0.101977,181.683395,9.255393,1.019772,-240.597458,0.102940,0.000000
68.360001,41.327759,-240.597458,0.007968,0.004025,0.102246,183.835052,9.365005,1.022459,-240.597458,0.103356,0.000000
68.610001,42.806450,-240.641953,0.007946,0.004048,0.102818,190.412598,9.700080,1.028182,-240.641953,0.103772,0.000000
68.860001,43.582474,-240.641953,0.007976,0.004061,0.103139,193.864532,9.875930,1.031392,-240.641953,0.104188,0.000000
69.110001,44.359985,-240.686432,0.007985,0.004075,0.103495,197.323074,10.052116,1.034945,-240.686432,0.104605,0.000000
69.360001,45.789154,-240.597458,0.007985,0.004099,0.104110,203.680328,10.375971,1.041103,-240.597458,0.105021,0.000000
69.610001,47.004578,-240.641953,0.007998,0.004115,0.104509,209.086807,10.651390,1.045093,-240.641953,0.105437,0.000000
69.860001,47.567978,-240.641953,0.007994,0.004126,0.104795,211.592926,10.779058,1.047954,-240.641953,0.105854,0.000000
70.110001,48.703712,-240.597458,0.008032,0.004143,0.105229,216.644928,11.036419,1.052292,-240.597458,0.106270,0.000000
70.360001,49.265251,-240.730911,0.008019,0.004154,0.105524,219.142776,11.163666,1.055240,-240.730911,0.106686,0.000000
70.610001,50.711914,-240.730911,0.008032,0.004174,0.106010,225.577866,11.491484,1.060096,-240.730911,0.107102,0.000000
70.860001,51.830894,-240.686432,0.008037,0.004189,0.106409,230.555328,11.745049,1.064085,-240.686432,0.107519,0.000000
71.110001,52.910400,-240.686432,0.008041,0.004205,0.106799,235.357208,11.989668,1.067988,-240.686432,0.107935,0.000000
71.360001,54.479950,-240.730911,0.008045,0.004228,0.107397,242.338928,12.345333,1.073972,-240.730911,0.108351,0.000000
71.610001,56.040939,-240.730911,0.008045,0.004246,0.107840,249.282547,12.699059,1.078396,-240.730911,0.108767,0.000000
71.860001,56.811752,-240.730911,0.008054,0.004259,0.108169,252.711288,12.873727,1.081689,-240.730911,0.109184,0.000000
72.110001,57.725922,-240.686432,0.008058,0.004274,0.108550,256.777710,13.080881,1.085504,-240.686432,0.109600,0.000000
72.360001,58.434547,-240.730911,0.008041,0.004285,0.108828,259.929840,13.241457,1.088282,-240.730911,0.110016,0.000000
72.610001,60.239441,-240.775391,0.008045,0.004306,0.109374,267.958405,13.650453,1.093744,-240.775391,0.110433,0.000000
72.860001,61.250427,-240.775391,0.008084,0.004320,0.109739,272.455505,13.879545,1.097389,-240.775391,0.110857,0.000000
73.110001,61.989960,-240.775391,0.008101,0.004330,0.109981,275.745117,14.047126,1.099815,-240.775391,0.111274,0.000000
73.360001,64.623001,-240.730911,0.008119,0.004363,0.110823,287.457458,14.643782,1.108229,-240.730911,0.111690,0.000000
73.610001,65.670868,-240.730911,0.008101,0.004376,0.111143,292.118622,14.881231,1.111434,-240.730911,0.112106,0.000000
73.860001,67.098160,-240.819870,0.008123,0.004393,0.111586,298.467529,15.204660,1.115859,-240.819870,0.112523,0.000000
74.110001,67.171524,-240.775391,0.008127,0.004390,0.111517,298.793854,15.221285,1.115166,-240.775391,0.111742,0.000000
74.360001,66.700470,-240.819870,0.008114,0.004390,0.111499,296.698517,15.114543,1.114992,-240.819870,0.111517,0.000000
74.610001,66.244308,-240.775391,0.008114,0.004389,0.111482,294.669403,15.011175,1.114818,-240.775391,0.111517,0.000000
74.860001,65.854446,-240.864349,0.008132,0.004389,0.111482,292.935211,14.922832,1.114818,-240.864349,0.111517,0.000000
75.110001,65.527878,-240.819870,0.008123,0.004389,0.111473,291.482544,14.848829,1.114731,-240.819870,0.111517,0.000000
75.360001,65.232574,-240.819870,0.008153,0.004389,0.111473,290.168976,14.781913,1.114731,-240.819870,0.111517,0.000000
75.610001,64.951431,-240.819870,0.008132,0.004389,0.111473,288.918396,14.718204,1.114731,-240.819870,0.111517,0.000000
75.860001,64.714233,-240.864349,0.008132,0.004388,0.111464,287.863281,14.664455,1.114644,-240.864349,0.111517,0.000000
76.110001,64.504959,-240.819870,0.008110,0.004388,0.111464,286.932404,14.617033,1.114644,-240.819870,0.111517,0.000000
76.360001,64.310593,-240.908829,0.008127,0.004388,0.111464,286.067810,14.572989,1.114644,-240.908829,0.111517,0.000000
76.610001,64.111374,-240.864349,0.008153,0.004388,0.111464,285.181641,14.527844,1.114644,-240.864349,0.111517,0.000000
76.860001,63.945663,-240.864349,0.008157,0.004388,0.111464,284.444519,14.490294,1.114644,-240.864349,0.111517,0.000000
77.110001,63.794479,-240.819870,0.008162,0.004388,0.111464,283.772003,14.456036,1.114644,-240.819870,0.111517,0.000000
77.360001,63.656326,-240.864349,0.008127,0.004388,0.111464,283.157471,14.424729,1.114644,-240.864349,0.111517,0.000000
77.610001,63.509979,-240.864349,0.008166,0.004388,0.111464,282.506500,14.391567,1.114644,-240.864349,0.111517,0.000000
77.860001,63.376678,-240.864349,0.008149,0.004388,0.111464,281.913544,14.361361,1.114644,-240.864349,0.111517,0.000000
78.110001,63.271667,-240.864349,0.008157,0.004388,0.111464,281.446442,14.337565,1.114644,-240.864349,0.111517,0.000000
78.360001,63.157349,-240.908829,0.008132,0.004388,0.111456,280.937927,14.311660,1.114557,-240.908829,0.111517,0.000000
78.610001,63.041542,-240.908829,0.008157,0.004388,0.111456,280.422791,14.285418,1.114557,-240.908829,0.111517,0.000000
78.860001,62.947327,-240.908829,0.008140,0.004388,0.111456,280.003693,14.264068,1.114557,-240.908829,0.111517,0.000000
79.110001,62.861313,-240.953308,0.008153,0.004388,0.111456,279.621094,14.244577,1.114557,-240.953308,0.111517,0.000000
79.360001,62.758163,-240.908829,0.008144,0.004388,0.111456,279.162262,14.221204,1.114557,-240.908829,0.111517,0.000000
79.610001,62.674377,-240.953308,0.008153,0.004388,0.111456,278.789551,14.202217,1.114557,-240.953308,0.111517,0.000000
79.860001,62.591339,-240.953308,0.008170,0.004388,0.111456,278.420197,14.183400,1.114557,-240.953308,0.111517,0.000000
80.110001,62.514259,-240.908829,0.008166,0.004388,0.111456,278.077301,14.165934,1.114557,-240.908829,0.111517,0.000000
80.360001,62.422661,-240.908829,0.008162,0.004388,0.111456,277.669861,14.145177,1.114557,-240.908829,0.111517,0.000000
80.610001,62.352280,-240.953308,0.008149,0.004388,0.111456,277.356781,14.129228,1.114557,-240.953308,0.111517,0.000000
80.860001,62.283020,-240.953308,0.008162,0.004388,0.111456,277.048706,14.113534,1.114557,-240.953308,0.111517,0.000000
81.110001,62.194389,-240.953308,0.008175,0.004388,0.111456,276.654449,14.093451,1.114557,-240.953308,0.111517,0.000000
81.360001,62.138535,-240.953308,0.008162,0.004388,0.111456,276.406006,14.080793,1.114557,-240.953308,0.111517,0.000000
81.610001,62.083054,-240.953308,0.008166,0.004388,0.111456,276.159210,14.068221,1.114557,-240.953308,0.111517,0.000000
81.860001,62.014908,-241.042267,0.008140,0.004388,0.111456,275.856079,14.052779,1.114557,-241.042267,0.111517,0.000000
82.110001,61.946396,-240.997787,0.008140,0.004388,0.111456,275.551331,14.037253,1.114557,-240.997787,0.111517,0.000000
82.360001,61.898727,-240.997787,0.008188,0.004388,0.111456,275.339294,14.026452,1.114557,-240.997787,0.111517,0.000000
82.610001,61.838036,-240.953308,0.008188,0.004388,0.111456,275.069305,14.012699,1.114557,-240.953308,0.111517,0.000000
82.860001,61.790367,-240.997787,0.008153,0.004388,0.111456,274.857269,14.001897,1.114557,-240.997787,0.111517,0.000000
83.110001,61.734512,-240.953308,0.008175,0.004388,0.111456,274.608826,13.989241,1.114557,-240.953308,0.111517,0.000000
83.360001,61.675674,-240.997787,0.008136,0.004388,0.111456,274.347107,13.975907,1.114557,-240.997787,0.111517,0.000000
83.610001,61.624290,-240.953308,0.008136,0.004388,0.111456,274.118530,13.964263,1.114557,-240.953308,0.111517,0.000000
83.860001,61.579979,-240.997787,0.008157,0.004388,0.111456,273.921417,13.954223,1.114557,-240.997787,0.111517,0.000000
84.110001,61.523376,-241.042267,0.008175,0.004388,0.111456,273.669647,13.941397,1.114557,-241.042267,0.111517,0.000000
84.360001,61.483536,-241.042267,0.008162,0.004388,0.111456,273.492432,13.932368,1.114557,-241.042267,0.111517,0.000000
84.610001,61.430283,-241.086761,0.008132,0.004388,0.111456,273.255554,13.920301,1.114557,-241.086761,0.111517,0.000000
84.860001,61.386345,-240.997787,0.008144,0.004388,0.111456,273.060089,13.910345,1.114557,-240.997787,0.111517,0.000000
85.110001,61.358414,-241.086761,0.008175,0.004388,0.111456,272.935852,13.904016,1.114557,-241.086761,0.111517,0.000000
85.360001,61.305168,-241.086761,0.008166,0.004388,0.111456,272.699005,13.891950,1.114557,-241.086761,0.111517,0.000000
85.610001,61.259735,-241.042267,0.008162,0.004388,0.111456,272.496918,13.881655,1.114557,-241.042267,0.111517,0.000000
85.860001,61.234413,-241.086761,0.008162,0.004388,0.111456,272.384277,13.875916,1.114557,-241.086761,0.111517,0.000000
86.110001,61.186378,-241.086761,0.008157,0.004388,0.111456,272.170593,13.865032,1.114557,-241.086761,0.111517,0.000000
86.360001,61.138718,-241.042267,0.008144,0.004388,0.111456,271.958588,13.854231,1.114557,-241.042267,0.111517,0.000000
86.610001,61.113022,-241.042267,0.008179,0.004388,0.111456,271.844299,13.848409,1.114557,-241.042267,0.111517,0.000000
86.860001,61.082863,-241.131241,0.008166,0.004388,0.111456,271.710144,13.841575,1.114557,-241.131241,0.111517,0.000000
87.110001,61.033333,-241.131241,0.008144,0.004388,0.111456,271.489838,13.830351,1.114557,-241.131241,0.111517,0.000000
87.360001,61.006149,-241.086761,0.008183,0.004388,0.111456,271.368896,13.824191,1.114557,-241.086761,0.111517,0.000000
87.610001,60.966682,-241.175720,0.008153,0.004388,0.111456,271.193359,13.815248,1.114557,-241.175720,0.111517,0.000000
87.860001,60.943970,-241.086761,0.008175,0.004388,0.111456,271.092316,13.810101,1.114557,-241.086761,0.111517,0.000000
88.110001,60.899651,-241.131241,0.008166,0.004388,0.111456,270.895172,13.800057,1.114557,-241.131241,0.111517,0.000000
88.360001,60.876564,-241.131241,0.008157,0.004388,0.111456,270.792480,13.794827,1.114557,-241.131241,0.111517,0.000000
88.610001,60.844543,-241.131241,0.008153,0.004388,0.111456,270.650055,13.787570,1.114557,-241.131241,0.111517,0.000000
88.860001,60.806564,-241.086761,0.008183,0.004388,0.111456,270.481110,13.778965,1.114557,-241.086761,0.111517,0.000000
89.110001,60.772675,-241.086761,0.008127,0.004388,0.111456,270.330353,13.771284,1.114557,-241.086761,0.111517,0.000000
89.360001,60.758522,-241.131241,0.008149,0.004388,0.111456,270.267395,13.768078,1.114557,-241.131241,0.111517,0.000000
89.610001,60.720169,-241.131241,0.008157,0.004388,0.111456,270.096802,13.759387,1.114557,-241.131241,0.111517,0.000000
89.860001,60.693359,-241.131241,0.008183,0.004388,0.111456,269.977539,13.753312,1.114557,-241.131241,0.111517,0.000000
90.110001,60.665802,-241.220200,0.008153,0.004388,0.111456,269.854950,13.747066,1.114557,-241.220200,0.111517,0.000000
90.360001,60.642342,-241.175720,0.008196,0.004388,0.111456,269.750610,13.741751,1.114557,-241.175720,0.111517,0.000000
90.610001,60.603249,-241.220200,0.008132,0.004388,0.111456,269.576721,13.732893,1.114557,-241.220200,0.111517,0.000000
90.860001,60.577927,-241.175720,0.008157,0.004388,0.111456,269.464081,13.727155,1.114557,-241.175720,0.111517,0.000000
91.110001,60.552605,-241.175720,0.008140,0.004388,0.111456,269.351440,13.721416,1.114557,-241.175720,0.111517,0.000000
91.360001,60.534729,-241.175720,0.008153,0.004388,0.111456,269.271912,13.717366,1.114557,-241.175720,0.111517,0.000000
91.610001,60.496376,-241.175720,0.008166,0.004388,0.111456,269.101318,13.708675,1.114557,-241.175720,0.111517,0.000000
91.860001,60.474777,-241.220200,0.008144,0.004388,0.111456,269.005249,13.703780,1.114557,-241.220200,0.111517,0.000000
92.110001,60.469933,-241.264679,0.008144,0.004388,0.111456,268.983704,13.702682,1.114557,-241.264679,0.111517,0.000000
92.360001,60.415199,-241.220200,0.008157,0.004388,0.111456,268.740234,13.690280,1.114557,-241.220200,0.111517,0.000000
92.610001,60.399559,-241.220200,0.008196,0.004388,0.111456,268.670654,13.686735,1.114557,-241.220200,0.111517,0.000000
92.860001,60.385780,-241.220200,0.008179,0.004388,0.111456,268.609375,13.683614,1.114557,-241.220200,0.111517,0.000000
93.110001,60.364182,-241.264679,0.008196,0.004388,0.111456,268.513275,13.678720,1.114557,-241.264679,0.111517,0.000000
93.360008,60.331787,-241.264679,0.008188,0.004388,0.111456,268.369202,13.671378,1.114557,-241.264679,0.111517,0.000000
93.610008,60.306839,-241.264679,0.008175,0.004388,0.111456,268.258209,13.665725,1.114557,-241.264679,0.111517,0.000000
93.860008,60.290825,-241.220200,0.008175,0.004388,0.111456,268.186981,13.662097,1.114557,-241.220200,0.111517,0.000000
94.110008,60.281517,-241.220200,0.008144,0.004388,0.111456,268.145569,13.659986,1.114557,-241.220200,0.111517,0.000000
94.360008,60.232361,-241.220200,0.008170,0.004388,0.111456,267.926910,13.648849,1.114557,-241.220200,0.111517,0.000000
94.610008,60.231987,-241.264679,0.008157,0.004388,0.111456,267.925262,13.648763,1.114557,-241.264679,0.111517,0.000000
94.860008,60.208534,-241.309158,0.008179,0.004388,0.111456,267.820923,13.643449,1.114557,-241.309158,0.111517,0.000000
95.110008,60.183952,-241.264679,0.008153,0.004388,0.111456,267.711578,13.637878,1.114557,-241.264679,0.111517,0.000000
95.360008,60.175758,-241.264679,0.008175,0.004388,0.111456,267.675140,13.636022,1.114557,-241.264679,0.111517,0.000000
95.610008,60.122887,-241.353638,0.008162,0.004388,0.111456,267.439972,13.624041,1.114557,-241.353638,0.111517,0.000000
95.860008,60.129585,-241.353638,0.008175,0.004388,0.111456,267.469757,13.625559,1.114557,-241.353638,0.111517,0.000000
96.110008,60.103897,-241.264679,0.008157,0.004388,0.111456,267.355499,13.619738,1.114557,-241.264679,0.111517,0.000000
96.360008,60.093094,-241.309158,0.008175,0.004388,0.111456,267.307434,13.617290,1.114557,-241.309158,0.111517,0.000000
96.610008,60.062187,-241.264679,0.008188,0.004388,0.111456,267.169952,13.610286,1.114557,-241.264679,0.111517,0.000000
96.860008,60.037239,-241.309158,0.008179,0.004388,0.111456,267.058990,13.604633,1.114557,-241.309158,0.111517,0.000000
97.110008,60.033142,-241.398117,0.008196,0.004388,0.111456,267.040741,13.603704,1.114557,-241.398117,0.111517,0.000000
97.360008,60.014526,-241.353638,0.008157,0.004388,0.111456,266.957947,13.599486,1.114557,-241.353638,0.111517,0.000000
97.610008,59.993675,-241.353638,0.008183,0.004388,0.111456,266.865204,13.594761,1.114557,-241.353638,0.111517,0.000000
97.860008,59.978401,-241.442596,0.008166,0.004388,0.111456,266.797241,13.591299,1.114557,-241.442596,0.111517,0.000000
98.110008,59.946754,-241.353638,0.008149,0.004388,0.111456,266.656494,13.584128,1.114557,-241.353638,0.111517,0.000000
98.360008,59.950104,-241.353638,0.008183,0.004388,0.111456,266.671387,13.584888,1.114557,-241.353638,0.111517,0.000000
98.610008,59.935585,-241.398117,0.008132,0.004388,0.111456,266.606812,13.581597,1.114557,-241.398117,0.111517,0.000000
98.860008,59.906540,-241.398117,0.008209,0.004388,0.111456,266.477600,13.575016,1.114557,-241.398117,0.111517,0.000000
99.110008,59.900948,-241.353638,0.008179,0.004388,0.111456,266.452728,13.573750,1.114557,-241.353638,0.111517,0.000000
99.360008,59.868927,-241.398117,0.008201,0.004388,0.111456,266.310303,13.566493,1.114557,-241.398117,0.111517,0.000000
99.610008,59.885315,-241.353638,0.008175,0.004388,0.111456,266.383179,13.570207,1.114557,-241.353638,0.111517,0.000000
99.860008,59.845467,-241.398117,0.008179,0.004388,0.111456,266.205933,13.561176,1.114557,-241.398117,0.111517,0.000000
100.110008,59.835411,-241.442596,0.008170,0.004388,0.111456,266.161194,13.558898,1.114557,-241.442596,0.111517,0.000000
100.360008,59.819405,-241.487076,0.008170,0.004388,0.111456,266.089996,13.555271,1.114557,-241.487076,0.111517,0.000000
100.610008,59.795197,-241.398117,0.008175,0.004388,0.111456,265.982330,13.549785,1.114557,-241.398117,0.111517,0.000000
100.860008,59.806000,-241.442596,0.008149,0.004388,0.111456,266.030365,13.552233,1.114557,-241.442596,0.111517,0.000000
101.110008,59.767273,-241.442596,0.008157,0.004388,0.111456,265.858093,13.543458,1.114557,-241.442596,0.111517,0.000000
101.360008,59.759819,-241.487076,0.008179,0.004388,0.111456,265.824951,13.541769,1.114557,-241.487076,0.111517,0.000000
101.610008,59.746788,-241.442596,0.008162,0.004388,0.111456,265.766998,13.538815,1.114557,-241.442596,0.111517,0.000000
101.860008,59.722588,-241.487076,0.008196,0.004388,0.111456,265.659332,13.533332,1.114557,-241.487076,0.111517,0.000000
102.110008,59.728912,-241.442596,0.008149,0.004388,0.111456,265.687469,13.534764,1.114557,-241.442596,0.111517,0.000000
102.360008,59.692421,-241.487076,0.008166,0.004388,0.111456,265.525146,13.526496,1.114557,-241.487076,0.111517,0.000000
102.610008,59.671944,-241.442596,0.008188,0.004388,0.111456,265.434052,13.521856,1.114557,-241.442596,0.111517,0.000000
102.860008,59.652580,-241.487076,0.008166,0.004388,0.111456,265.347931,13.517467,1.114557,-241.487076,0.111517,0.000000
103.110008,59.667473,-241.487076,0.008157,0.004388,0.111456,265.414185,13.520843,1.114557,-241.487076,0.111517,0.000000
103.360008,59.641037,-241.531570,0.008170,0.004388,0.111456,265.296570,13.514852,1.114557,-241.531570,0.111517,0.000000
103.610008,59.606407,-241.442596,0.008179,0.004388,0.111456,265.142548,13.507005,1.114557,-241.442596,0.111517,0.000000
103.860008,59.618317,-241.487076,0.008192,0.004388,0.111456,265.195526,13.509704,1.114557,-241.487076,0.111517,0.000000
104.110008,59.579964,-241.576050,0.008157,0.004388,0.111456,265.024902,13.501013,1.114557,-241.576050,0.111517,0.000000
104.360008,59.589645,-241.487076,0.008162,0.004388,0.111456,265.067993,13.503206,1.114557,-241.487076,0.111517,0.000000
104.500008,59.573265,-241.576050,0.008183,0.004388,0.111456,264.995117,13.499495,1.114557,-241.576050,0.111517,0.000000