File: Data/compression 29/AutoNoHeating-17-29-reverse-1-1_10232024_171935.csv
Time (sec),S:Load (lbs),S:HL1 (DIM),S:LVDT (in),S:Position (in),Ch:Position (mm),Ch:Load (N),Ch:Stress (MPa),Ch:Strain (mm/mm),Ch:HL1 (DIM),Set Point (),Cycles ()
0.110000,0.049896,-137.090286,-0.007769,-0.007655,-0.194449,0.221950,0.011307,-1.944490,-137.090286,-0.194241,0.000000
0.560000,0.048409,-137.223740,-0.007769,-0.007563,-0.192108,0.215332,0.010970,-1.921076,-137.223740,-0.191345,0.000000
1.010000,-0.000748,-137.223740,-0.007606,-0.007278,-0.184857,-0.003326,-0.000169,-1.848573,-137.223740,-0.183851,0.000000
1.460000,0.071495,-137.268219,-0.007312,-0.006986,-0.177443,0.318026,0.016201,-1.774427,-137.268219,-0.176359,0.000000
1.910000,0.125488,-137.357178,-0.007105,-0.000011,-0.000269,0.558200,0.028436,-0.002687,-137.357178,-0.000009,0.000000
2.360000,0.122505,-137.401657,-0.007101,-0.000011,-0.000269,0.544930,0.027760,-0.002687,-137.401657,0.000164,0.000000
2.810000,0.101280,-137.401657,-0.007088,-0.000010,-0.000243,0.450517,0.022950,-0.002430,-137.401657,0.000919,0.000000
3.260000,0.118782,-137.535095,-0.007114,0.000030,0.000771,0.528369,0.026916,0.007714,-137.535095,0.001665,0.000000
3.710000,0.051010,-137.579575,-0.007071,0.000057,0.001448,0.226904,0.011559,0.014481,-137.579575,0.002419,0.000000
4.160000,0.092720,-137.579575,-0.007049,0.000089,0.002272,0.412439,0.021011,0.022717,-137.579575,0.003165,0.000000
4.610000,0.098679,-137.713028,-0.007015,0.000116,0.002948,0.438944,0.022361,0.029484,-137.713028,0.003920,0.000000
5.060000,0.123627,-137.757507,-0.007002,0.000142,0.003599,0.549919,0.028014,0.035987,-137.757507,0.004665,0.000000
5.510000,0.073357,-137.757507,-0.006963,0.000177,0.004501,0.326307,0.016623,0.045010,-137.757507,0.005420,0.000000
5.960001,0.083038,-137.846466,-0.006924,0.000208,0.005272,0.369373,0.018817,0.052724,-137.846466,0.006166,0.000000
6.410000,0.079681,-137.935425,-0.006890,0.000240,0.006105,0.354441,0.018056,0.061050,-137.935425,0.006920,0.000000
6.860000,0.109848,-137.979904,-0.006877,0.000258,0.006547,0.488628,0.024892,0.065471,-137.979904,0.007666,0.000000
7.310000,0.096443,-138.068878,-0.006842,0.000298,0.007580,0.429001,0.021854,0.075796,-138.068878,0.008421,0.000000
7.760000,0.087135,-138.157837,-0.006808,0.000323,0.008195,0.387597,0.019745,0.081951,-138.157837,0.009166,0.000000
8.210000,0.098679,-138.246796,-0.006791,0.000355,0.009028,0.438944,0.022361,0.090277,-138.246796,0.009921,0.000000
8.660001,0.113945,-138.202316,-0.006765,0.000383,0.009721,0.506853,0.025820,0.097211,-138.202316,0.010667,0.000000
9.110001,0.103516,-138.246796,-0.006726,0.000415,0.010536,0.460460,0.023457,0.105364,-138.246796,0.011421,0.000000
9.560000,0.052872,-138.380234,-0.006700,0.000441,0.011204,0.235185,0.011981,0.112040,-138.380234,0.012167,0.000000
10.010000,0.066277,-138.424713,-0.006666,0.000472,0.011976,0.294813,0.015018,0.119762,-138.424713,0.012913,0.000000
10.460000,0.070374,-138.513687,-0.006640,0.000497,0.012618,0.313037,0.015947,0.126181,-138.513687,0.013667,0.000000
10.910001,0.068512,-138.558167,-0.006618,0.000527,0.013389,0.304756,0.015525,0.133894,-138.558167,0.014413,0.000000
11.360001,0.062553,-138.602646,-0.006575,0.000563,0.014309,0.278251,0.014175,0.143092,-138.602646,0.015168,0.000000
11.810000,0.078194,-138.691605,-0.006558,0.000590,0.014985,0.347823,0.017719,0.149852,-138.691605,0.015913,0.000000
12.260000,0.087135,-138.736084,-0.006528,0.000620,0.015757,0.387597,0.019745,0.157573,-138.736084,0.016668,0.000000
12.710001,0.097183,-138.780563,-0.006502,0.000641,0.016277,0.432293,0.022022,0.162773,-138.780563,0.017414,0.000000
13.160001,0.081917,-138.825043,-0.006437,0.000680,0.017283,0.364384,0.018563,0.172833,-138.825043,0.018168,0.000000
13.610001,0.024948,-138.869522,-0.006433,0.000707,0.017951,0.110975,0.005653,0.179510,-138.869522,0.018914,0.000000
14.060000,0.077820,-139.002975,-0.006398,0.000740,0.018793,0.346160,0.017634,0.187928,-139.002975,0.019669,0.000000
14.510000,0.086014,-139.047455,-0.006359,0.000764,0.019400,0.382608,0.019491,0.193999,-139.047455,0.020414,0.000000
14.960001,0.069633,-139.136414,-0.006329,0.000800,0.020328,0.309745,0.015779,0.203279,-139.136414,0.021169,0.000000
15.410001,0.017868,-139.180893,-0.006316,0.000825,0.020952,0.079481,0.004049,0.209517,-139.180893,0.021915,0.000000
15.860001,0.043938,-139.269852,-0.006282,0.000856,0.021750,0.195445,0.009956,0.217495,-139.269852,0.022669,0.000000
16.310001,0.068138,-139.314346,-0.006260,0.000879,0.022331,0.303093,0.015440,0.223309,-139.314346,0.023415,0.000000
16.760000,0.060318,-139.314346,-0.006222,0.000917,0.023294,0.268308,0.013668,0.232938,-139.314346,0.024170,0.000000
17.210001,0.014893,-139.447784,-0.006170,0.000946,0.024039,0.066245,0.003375,0.240394,-139.447784,0.024915,0.000000
17.660002,0.002975,-139.492264,-0.006148,0.000973,0.024724,0.013236,0.000674,0.247244,-139.492264,0.025670,0.000000
18.110001,0.079315,-139.581223,-0.006122,0.001003,0.025487,0.352812,0.017973,0.254875,-139.581223,0.026416,0.000000
18.560001,0.062927,-139.625702,-0.006105,0.001025,0.026034,0.279914,0.014260,0.260340,-139.625702,0.027170,0.000000
19.010000,0.069633,-139.670181,-0.006062,0.001064,0.027031,0.309745,0.015779,0.270310,-139.670181,0.027916,0.000000
19.460001,0.023827,-139.803635,-0.006045,0.001091,0.027708,0.105986,0.005399,0.277077,-139.803635,0.028671,0.000000
19.910002,0.085640,-139.848114,-0.006006,0.001127,0.028618,0.380946,0.019406,0.286183,-139.848114,0.029416,0.000000
20.360001,0.110962,-139.848114,-0.005993,0.001147,0.029138,0.493583,0.025144,0.291384,-139.848114,0.030171,0.000000
20.810001,0.096817,-139.937073,-0.005933,0.001181,0.030006,0.430664,0.021939,0.300059,-139.937073,0.030917,0.000000
21.260000,0.069633,-140.026031,-0.005933,0.001206,0.030630,0.309745,0.015779,0.306304,-140.026031,0.031671,0.000000
21.710001,0.094582,-140.070511,-0.005877,0.001242,0.031558,0.420720,0.021432,0.315585,-140.070511,0.032417,0.000000
22.160002,0.118042,-140.159470,-0.005864,0.001267,0.032174,0.525077,0.026749,0.321739,-140.159470,0.033171,0.000000
22.610001,0.107613,-140.203964,-0.005842,0.001302,0.033075,0.478685,0.024385,0.330754,-140.203964,0.033917,0.000000
23.060001,0.073723,-140.248444,-0.005816,0.001324,0.033631,0.327936,0.016706,0.336311,-140.248444,0.034671,0.000000
23.510000,0.072609,-140.337402,-0.005782,0.001355,0.034429,0.322981,0.016453,0.344289,-140.337402,0.035418,0.000000
23.960001,0.100540,-140.381882,-0.005730,0.001386,0.035209,0.447225,0.022783,0.352094,-140.381882,0.036171,0.000000
24.410002,0.132561,-140.470840,-0.005726,0.001409,0.035799,0.589660,0.030039,0.357991,-140.470840,0.036918,0.000000
24.860001,0.122879,-140.515320,-0.005691,0.001447,0.036761,0.546593,0.027845,0.367612,-140.515320,0.037672,0.000000
25.310001,0.082291,-140.604294,-0.005661,0.001476,0.037490,0.366047,0.018647,0.374901,-140.604294,0.038418,0.000000
25.760002,0.101654,-140.648773,-0.005618,0.001510,0.038349,0.452180,0.023035,0.383486,-140.648773,0.039172,0.000000
26.210001,0.133682,-140.693253,-0.005605,0.001529,0.038834,0.594648,0.030293,0.388338,-140.693253,0.039919,0.000000
26.660002,0.127724,-140.737732,-0.005566,0.001564,0.039736,0.568143,0.028943,0.397361,-140.737732,0.040672,0.000000
27.110001,0.057343,-140.871170,-0.005536,0.001590,0.040395,0.255072,0.012994,0.403954,-140.871170,0.041419,0.000000
27.560001,0.101280,-140.871170,-0.005506,0.001627,0.041314,0.450517,0.022950,0.413144,-140.871170,0.042173,0.000000
28.010002,0.113945,-140.960129,-0.005471,0.001649,0.041878,0.506853,0.025820,0.418783,-140.960129,0.042918,0.000000
28.460001,0.123627,-140.960129,-0.005445,0.001685,0.042806,0.549919,0.028014,0.428064,-140.960129,0.043673,0.000000
28.910002,0.091225,-141.049103,-0.005407,0.001710,0.043422,0.405788,0.020672,0.434218,-141.049103,0.044419,0.000000
29.360001,0.104637,-141.138062,-0.005385,0.001741,0.044228,0.465449,0.023711,0.442280,-141.138062,0.045173,0.000000
29.810001,0.109848,-141.138062,-0.005355,0.001770,0.044948,0.488628,0.024892,0.449479,-141.138062,0.045919,0.000000
30.260002,0.100906,-141.271500,-0.005333,0.001796,0.045616,0.448854,0.022866,0.456156,-141.271500,0.046665,0.000000
30.710001,0.075958,-141.227020,-0.005299,0.001830,0.046491,0.337879,0.017212,0.464914,-141.227020,0.047419,0.000000
31.160002,0.052872,-141.315979,-0.005277,0.001858,0.047194,0.235185,0.011981,0.471939,-141.315979,0.048166,0.000000
31.610001,0.089737,-141.315979,-0.005221,0.001891,0.048044,0.399170,0.020335,0.480439,-141.315979,0.048920,0.000000
32.060001,0.112083,-141.404938,-0.005208,0.001910,0.048521,0.498572,0.025398,0.485208,-141.404938,0.049666,0.000000
32.510002,0.088997,-141.493912,-0.005170,0.001950,0.049536,0.395878,0.020167,0.495359,-141.493912,0.050420,0.000000
32.960003,0.052872,-141.538391,-0.005144,0.001974,0.050143,0.235185,0.011981,0.501430,-141.538391,0.051166,0.000000
33.410000,0.111710,-141.627350,-0.005105,0.002010,0.051054,0.496909,0.025314,0.510537,-141.627350,0.051920,0.000000
33.860001,0.107239,-141.671829,-0.005083,0.002034,0.051661,0.477022,0.024301,0.516608,-141.671829,0.052666,0.000000
34.310001,0.087135,-141.760788,-0.005036,0.002070,0.052588,0.387597,0.019745,0.525881,-141.760788,0.053421,0.000000
34.760002,0.043938,-141.760788,-0.005019,0.002095,0.053222,0.195445,0.009956,0.532217,-141.760788,0.054166,0.000000
35.210003,0.080055,-141.849747,-0.004984,0.002127,0.054037,0.356103,0.018141,0.540369,-141.849747,0.054921,0.000000
35.660000,0.088249,-141.938721,-0.004945,0.002150,0.054609,0.392552,0.019998,0.546092,-141.938721,0.055667,0.000000
36.110001,0.102402,-142.027679,-0.004924,0.002187,0.055537,0.455506,0.023205,0.555373,-142.027679,0.056421,0.000000
36.560001,0.072235,-141.983200,-0.004894,0.002212,0.056196,0.321318,0.016369,0.561958,-141.983200,0.057167,0.000000
37.010002,0.094955,-142.072159,-0.004868,0.002244,0.057003,0.422383,0.021517,0.570028,-142.072159,0.057922,0.000000
37.460003,0.153046,-142.116638,-0.004846,0.002273,0.057739,0.680781,0.034681,0.577393,-142.116638,0.058667,0.000000
37.910004,0.202568,-142.205597,-0.004812,0.002295,0.058303,0.901068,0.045903,0.583033,-142.205597,0.059422,0.000000
38.360001,0.247253,-142.339050,-0.004790,0.002336,0.059335,1.099838,0.056028,0.593350,-142.339050,0.060168,0.000000
38.810001,0.287468,-142.339050,-0.004769,0.002360,0.059942,1.278721,0.065141,0.599421,-142.339050,0.060922,0.000000
39.260002,0.532120,-142.383530,-0.004721,0.002391,0.060740,2.366987,0.120580,0.607400,-142.383530,0.061668,0.000000
39.710003,0.772301,-142.428009,-0.004695,0.002418,0.061408,3.435365,0.175006,0.614084,-142.428009,0.062423,0.000000
40.160004,1.155838,-142.472488,-0.004674,0.002455,0.062362,5.141424,0.261917,0.623622,-142.472488,0.063168,0.000000
40.610001,1.417992,-142.561447,-0.004656,0.002478,0.062952,6.307542,0.321321,0.629519,-142.561447,0.063923,0.000000
41.060001,1.946388,-142.650406,-0.004626,0.002513,0.063828,8.657968,0.441058,0.638277,-142.650406,0.064669,0.000000
41.510002,2.263275,-142.650406,-0.004596,0.002533,0.064330,10.067551,0.512865,0.643303,-142.650406,0.065423,0.000000
41.960003,2.920143,-142.739365,-0.004566,0.002569,0.065250,12.989446,0.661714,0.652501,-142.739365,0.066169,0.000000
42.410004,3.416145,-142.739365,-0.004549,0.002599,0.066021,15.195773,0.774110,0.660214,-142.739365,0.066924,0.000000
42.860001,3.932625,-142.872818,-0.004531,0.002629,0.066768,17.493189,0.891145,0.667678,-142.872818,0.067669,0.000000
43.310001,4.456924,-142.961777,-0.004484,0.002657,0.067487,19.825390,1.009953,0.674869,-142.961777,0.068424,0.000000
43.760002,4.707161,-142.961777,-0.004475,0.002675,0.067956,20.938498,1.066658,0.679555,-142.961777,0.069170,0.000000
44.210003,5.444824,-143.050735,-0.004424,0.002714,0.068927,24.219788,1.233815,0.689267,-143.050735,0.069924,0.000000
44.660004,5.819809,-143.050735,-0.004424,0.002739,0.069577,25.887804,1.318787,0.695770,-143.050735,0.070670,0.000000
45.110001,6.537743,-143.228668,-0.004389,0.002776,0.070505,29.081331,1.481474,0.705050,-143.228668,0.071425,0.000000
45.560001,6.817390,-143.228668,-0.004376,0.002800,0.071121,30.325268,1.544843,0.711212,-143.228668,0.072170,0.000000
46.010002,7.317863,-143.317627,-0.004342,0.002830,0.071875,32.551483,1.658252,0.718752,-143.317627,0.072925,0.000000
46.460003,7.693214,-143.362106,-0.004312,0.002862,0.072690,34.221127,1.743307,0.726904,-143.362106,0.073671,0.000000
46.910004,8.039520,-143.451065,-0.004281,0.002889,0.073375,35.761574,1.821781,0.733755,-143.451065,0.074425,0.000000
47.360001,8.480782,-143.495544,-0.004260,0.002921,0.074182,37.724400,1.921773,0.741824,-143.495544,0.075171,0.000000
47.810001,9.097427,-143.584503,-0.004238,0.002953,0.075006,40.467377,2.061507,0.750060,-143.584503,0.075926,0.000000
48.260002,9.241165,-143.628998,-0.004195,0.002980,0.075691,41.106754,2.094078,0.756911,-143.628998,0.076671,0.000000
48.710003,9.739395,-143.673477,-0.004182,0.003013,0.076524,43.322994,2.206979,0.765238,-143.673477,0.077425,0.000000
49.160004,9.938248,-143.717957,-0.004139,0.003039,0.077191,44.207535,2.252039,0.771914,-143.717957,0.078172,0.000000
49.610001,9.985535,-143.762436,-0.004113,0.003060,0.077712,44.417877,2.262754,0.777122,-143.762436,0.078917,0.000000
50.060001,10.851303,-143.851395,-0.004079,0.003100,0.078744,48.269009,2.458941,0.787440,-143.851395,0.079672,0.000000
50.510002,11.087761,-143.940353,-0.004053,0.003130,0.079490,49.320824,2.512523,0.794896,-143.940353,0.080418,0.000000
50.960003,11.545776,-143.984833,-0.004027,0.003162,0.080313,51.358177,2.616310,0.803132,-143.984833,0.081172,0.000000
51.410004,11.502953,-144.029312,-0.003992,0.003183,0.080842,51.167690,2.606606,0.808423,-144.029312,0.081918,0.000000
51.860001,12.209343,-144.118286,-0.003967,0.003219,0.081762,54.309872,2.766677,0.817621,-144.118286,0.082673,0.000000
52.310001,12.201897,-144.162766,-0.003941,0.003244,0.082387,54.276749,2.764989,0.823866,-144.162766,0.083418,0.000000
52.760002,12.742584,-144.207245,-0.003906,0.003277,0.083236,56.681847,2.887511,0.832359,-144.207245,0.084173,0.000000
53.210003,13.005852,-144.251724,-0.003889,0.003304,0.083913,57.852917,2.947168,0.839126,-144.251724,0.084919,0.000000
53.660004,13.424026,-144.296204,-0.003863,0.003336,0.084728,59.713051,3.041928,0.847279,-144.296204,0.085673,0.000000
54.110004,13.670166,-144.385162,-0.003829,0.003363,0.085430,60.807934,3.097704,0.854304,-144.385162,0.086419,0.000000
54.560001,14.069717,-144.518616,-0.003790,0.003395,0.086237,62.585228,3.188243,0.862366,-144.518616,0.087173,0.000000
55.010002,14.117752,-144.518616,-0.003755,0.003421,0.086887,62.798897,3.199128,0.868868,-144.518616,0.087919,0.000000
55.460003,14.138237,-144.607574,-0.003738,0.003444,0.087476,62.890018,3.203770,0.874765,-144.607574,0.088674,0.000000
55.910004,14.898994,-144.563095,-0.003699,0.003483,0.088474,66.274040,3.376160,0.884742,-144.563095,0.089419,0.000000
56.360004,15.159653,-144.652054,-0.003669,0.003513,0.089228,67.433502,3.435226,0.892281,-144.652054,0.090174,0.000000
56.810001,15.447121,-144.696533,-0.003630,0.003544,0.090018,68.712227,3.500367,0.900184,-144.696533,0.090919,0.000000
57.260002,15.291473,-144.785492,-0.003626,0.003563,0.090495,68.019875,3.465097,0.904953,-144.785492,0.091675,0.000000
57.710003,16.001213,-144.829971,-0.003566,0.003603,0.091519,71.176949,3.625927,0.915188,-144.829971,0.092420,0.000000
58.160004,15.844070,-144.918945,-0.003535,0.003626,0.092108,70.477943,3.590318,0.921077,-144.918945,0.093175,0.000000
58.610004,16.525139,-144.874451,-0.003492,0.003663,0.093036,73.507492,3.744650,0.930357,-144.874451,0.093920,0.000000
59.060001,16.577644,-145.007904,-0.003471,0.003687,0.093659,73.741043,3.756548,0.936595,-145.007904,0.094675,0.000000
59.510002,17.139931,-145.052383,-0.003432,0.003723,0.094553,76.242218,3.883964,0.945527,-145.052383,0.095420,0.000000
59.960003,16.870705,-145.141342,-0.003397,0.003747,0.095169,75.044640,3.822956,0.951689,-145.141342,0.096176,0.000000
60.410004,17.068436,-145.230301,-0.003359,0.003777,0.095932,75.924194,3.867763,0.959319,-145.230301,0.096921,0.000000
60.860004,17.230789,-145.274780,-0.003346,0.003803,0.096609,76.646378,3.904553,0.966087,-145.274780,0.097676,0.000000
61.310001,18.054848,-145.319260,-0.003311,0.003844,0.097632,80.311974,4.091287,0.976321,-145.319260,0.098421,0.000000
61.760002,17.796425,-145.319260,-0.003260,0.003868,0.098248,79.162453,4.032728,0.982483,-145.319260,0.099176,0.000000
62.210003,18.015747,-145.452713,-0.003238,0.003897,0.098993,80.138046,4.082427,0.989932,-145.452713,0.099921,0.000000
62.660004,18.253319,-145.497192,-0.003203,0.003927,0.099749,81.194817,4.136261,0.997486,-145.497192,0.100677,0.000000
63.110004,18.137146,-145.452713,-0.003160,0.003949,0.100312,80.678055,4.109936,1.003118,-145.452713,0.101422,0.000000
63.560001,18.673729,-145.630630,-0.003139,0.003985,0.101214,83.064896,4.231528,1.012141,-145.630630,0.102177,0.000000
64.010002,18.786934,-145.675110,-0.003096,0.004012,0.101917,83.568459,4.257180,1.019166,-145.675110,0.102922,0.000000
64.460007,19.243835,-145.675110,-0.003083,0.004046,0.102775,85.600853,4.360715,1.027750,-145.675110,0.103677,0.000000
64.910004,19.071426,-145.764084,-0.003040,0.004069,0.103364,84.833939,4.321647,1.033640,-145.764084,0.104422,0.000000
65.360001,19.659401,-145.808563,-0.003001,0.004102,0.104197,87.449387,4.454884,1.041966,-145.808563,0.105176,0.000000
65.810005,19.634453,-145.942001,-0.002975,0.004129,0.104873,87.338409,4.449231,1.048734,-145.942001,0.105923,0.000000
66.260002,20.381805,-145.942001,-0.002932,0.004166,0.105818,90.662796,4.618583,1.058181,-145.942001,0.106677,0.000000
66.710007,20.016502,-145.986481,-0.002897,0.004189,0.106409,89.037849,4.535804,1.064085,-145.986481,0.107423,0.000000
67.160004,20.620125,-146.030960,-0.002880,0.004221,0.107215,91.722893,4.672587,1.072155,-146.030960,0.108177,0.000000
67.610001,20.675980,-146.030960,-0.002837,0.004250,0.107953,91.971352,4.685244,1.079528,-146.030960,0.108923,0.000000
68.060005,20.811150,-146.119919,-0.002811,0.004279,0.108689,92.572617,4.715874,1.086886,-146.119919,0.109677,0.000000
68.510002,21.002548,-146.208893,-0.002751,0.004310,0.109470,93.424004,4.759246,1.094698,-146.208893,0.110424,0.000000
68.960007,20.897537,-146.253372,-0.002733,0.004334,0.110077,92.956886,4.735450,1.100769,-146.253372,0.111170,0.000000
69.410004,21.409927,-146.297852,-0.002703,0.004368,0.110935,95.236115,4.851559,1.109353,-146.297852,0.111924,0.000000
69.860001,21.424820,-146.386810,-0.002660,0.004396,0.111647,95.302361,4.854933,1.116468,-146.386810,0.112670,0.000000
70.310005,22.123390,-146.475769,-0.002626,0.004433,0.112601,98.409752,5.013232,1.126006,-146.475769,0.113424,0.000000
70.760002,21.603188,-146.520248,-0.002608,0.004451,0.113059,96.095779,4.895352,1.130594,-146.520248,0.114171,0.000000
71.210007,22.576195,-146.564728,-0.002583,0.004488,0.114006,100.423927,5.115839,1.140056,-146.564728,0.114925,0.000000
71.660004,22.273087,-146.609207,-0.002535,0.004513,0.114622,99.075638,5.047153,1.146218,-146.609207,0.115671,0.000000
72.110001,22.909470,-146.742661,-0.002501,0.004548,0.115523,101.906410,5.191360,1.155226,-146.742661,0.116425,0.000000
72.560005,22.903885,-146.831619,-0.002462,0.004574,0.116190,101.881569,5.190094,1.161902,-146.831619,0.117171,0.000000
73.010002,23.558510,-146.876099,-0.002427,0.004607,0.117006,104.793488,5.338435,1.170062,-146.876099,0.117925,0.000000
73.460007,23.475845,-146.965057,-0.002397,0.004633,0.117674,104.425774,5.319702,1.176739,-146.965057,0.118672,0.000000
73.910004,23.284073,-146.965057,-0.002367,0.004659,0.118351,103.572731,5.276247,1.183506,-146.965057,0.119426,0.000000
74.360001,24.030312,-147.009537,-0.002328,0.004691,0.119156,106.892166,5.445347,1.191561,-147.009537,0.120172,0.000000
74.810005,23.702621,-147.054031,-0.002294,0.004712,0.119686,105.434525,5.371091,1.196859,-147.054031,0.120926,0.000000
75.260002,25.000336,-147.187469,-0.002272,0.004754,0.120744,111.207047,5.665157,1.207442,-147.187469,0.121672,0.000000
75.710007,24.872986,-147.231949,-0.002229,0.004782,0.121463,110.640564,5.636299,1.214633,-147.231949,0.122426,0.000000
76.160004,25.510490,-147.231949,-0.002199,0.004814,0.122270,113.476326,5.780759,1.222703,-147.231949,0.123173,0.000000
76.610001,25.132530,-147.320908,-0.002160,0.004833,0.122764,111.795074,5.695113,1.227638,-147.320908,0.123927,0.000000
77.060005,26.311836,-147.409866,-0.002126,0.004873,0.123771,117.040894,5.962348,1.237706,-147.409866,0.124671,0.000000
77.510002,25.973351,-147.498840,-0.002091,0.004897,0.124378,115.535233,5.885645,1.243777,-147.498840,0.125427,0.000000
77.960007,26.826828,-147.498840,-0.002048,0.004932,0.125279,119.331688,6.079046,1.252785,-147.498840,0.126172,0.000000
78.410004,26.721069,-147.543320,-0.002013,0.004956,0.125895,118.861252,6.055081,1.258947,-147.543320,0.126927,0.000000
78.860001,27.983414,-147.676758,-0.001996,0.004993,0.126832,124.476440,6.341132,1.268318,-147.676758,0.127672,0.000000
79.310005,27.770790,-147.721237,-0.001944,0.005018,0.127448,123.530647,6.292951,1.274480,-147.721237,0.128428,0.000000
79.760002,28.092896,-147.721237,-0.001919,0.005046,0.128176,124.963440,6.365941,1.281762,-147.721237,0.129172,0.000000
80.210007,28.426537,-147.854675,-0.001897,0.005073,0.128861,126.447548,6.441545,1.288605,-147.854675,0.129928,0.000000
80.660004,29.188782,-147.899155,-0.001854,0.005105,0.129658,129.838181,6.614273,1.296584,-147.899155,0.130673,0.000000
81.110001,29.924217,-147.943649,-0.001841,0.005138,0.130509,133.109573,6.780925,1.305092,-147.943649,0.131428,0.000000
81.560005,30.286537,-148.032608,-0.001811,0.005166,0.131228,134.721252,6.863028,1.312284,-148.032608,0.132173,0.000000
82.010002,30.825737,-148.032608,-0.001776,0.005193,0.131914,137.119720,6.985212,1.319142,-148.032608,0.132929,0.000000
82.460007,30.946007,-148.121567,-0.001750,0.005217,0.132503,137.654709,7.012465,1.325031,-148.121567,0.133673,0.000000
82.910004,32.346130,-148.210526,-0.001712,0.005257,0.133536,143.882767,7.329738,1.335356,-148.210526,0.134429,0.000000
83.360001,32.393791,-148.210526,-0.001681,0.005282,0.134159,144.094772,7.340538,1.341594,-148.210526,0.135174,0.000000
83.810005,33.711250,-148.255005,-0.001656,0.005317,0.135053,149.955124,7.639078,1.350526,-148.255005,0.135929,0.000000
84.260002,33.859077,-148.343979,-0.001643,0.005340,0.135643,150.612701,7.672577,1.356431,-148.343979,0.136674,0.000000
84.710007,34.676064,-148.343979,-0.001617,0.005369,0.136371,154.246841,7.857708,1.363713,-148.343979,0.137430,0.000000
85.160004,35.531403,-148.432938,-0.001578,0.005400,0.137169,158.051575,8.051531,1.371691,-148.432938,0.138174,0.000000
85.610001,36.819069,-148.521896,-0.001561,0.005434,0.138028,163.779404,8.343320,1.380275,-148.521896,0.138930,0.000000
86.060005,36.982910,-148.521896,-0.001548,0.005457,0.138609,164.508194,8.380447,1.386089,-148.521896,0.139675,0.000000
86.510002,37.347092,-148.566376,-0.001518,0.005486,0.139354,166.128159,8.462972,1.393538,-148.566376,0.140430,0.000000
86.960007,38.645554,-148.655334,-0.001492,0.005515,0.140084,171.904007,8.757208,1.400835,-148.655334,0.141175,0.000000
87.410004,39.505363,-148.699814,-0.001479,0.005546,0.140863,175.728638,8.952044,1.408632,-148.699814,0.141931,0.000000
87.860001,41.128532,-148.744293,-0.001440,0.005579,0.141713,182.948853,9.319859,1.417125,-148.744293,0.142675,0.000000
88.310005,41.200401,-148.922226,-0.001423,0.005600,0.142242,183.268539,9.336144,1.422424,-148.922226,0.143431,0.000000
88.760002,42.681328,-148.877747,-0.001388,0.005634,0.143101,189.856033,9.671727,1.431008,-148.877747,0.144176,0.000000
89.210007,43.852066,-148.922226,-0.001375,0.005665,0.143899,195.063736,9.937019,1.438987,-148.922226,0.144922,0.000000
89.660004,45.425339,-149.011185,-0.001367,0.005699,0.144748,202.061996,10.293530,1.447480,-149.011185,0.145676,0.000000
90.110001,46.294830,-149.055664,-0.001324,0.005724,0.145381,205.929687,10.490559,1.453808,-149.055664,0.146422,0.000000
90.560005,47.830498,-149.144623,-0.001311,0.005755,0.146179,212.760681,10.838546,1.461787,-149.144623,0.147176,0.000000
91.010002,48.678017,-149.144623,-0.001285,0.005783,0.146899,216.530640,11.030596,1.468993,-149.144623,0.147923,0.000000
91.460007,50.579346,-149.189117,-0.001272,0.005818,0.147783,224.988159,11.461443,1.477835,-149.189117,0.148677,0.000000
91.910004,50.965126,-149.322556,-0.001250,0.005837,0.148269,226.704208,11.548862,1.482695,-149.322556,0.149423,0.000000
92.360001,51.444740,-149.367035,-0.001229,0.005859,0.148825,228.837631,11.657545,1.488251,-149.367035,0.150177,0.000000
92.810005,53.973152,-149.411514,-0.001203,0.005898,0.149821,240.084564,12.230491,1.498213,-149.411514,0.150923,0.000000
93.260002,55.663353,-149.455994,-0.001181,0.005932,0.150663,247.602966,12.613497,1.506630,-149.455994,0.151677,0.000000
93.710007,57.432121,-149.500473,-0.001164,0.005963,0.151452,255.470840,13.014305,1.514518,-149.500473,0.152424,0.000000
94.160004,57.849174,-149.589432,-0.001147,0.005981,0.151920,257.325989,13.108810,1.519196,-149.589432,0.153178,0.000000
94.610008,60.032394,-149.589432,-0.001138,0.006019,0.152875,267.037415,13.603536,1.528749,-149.589432,0.153924,0.000000
95.060005,61.149887,-149.722885,-0.001112,0.006044,0.153508,272.008270,13.856762,1.535078,-149.722885,0.154678,0.000000
95.510002,63.562866,-149.767365,-0.001095,0.006082,0.154471,282.741760,14.403551,1.544706,-149.767365,0.155424,0.000000
95.960007,64.782745,-149.811844,-0.001082,0.006103,0.155016,288.168030,14.679980,1.550157,-149.811844,0.156178,0.000000
96.410004,65.848480,-149.900803,-0.001082,0.006118,0.155406,292.908661,14.921478,1.554063,-149.900803,0.027252,0.000000
96.860008,65.355087,-149.945282,-0.001065,0.006131,0.155727,290.713959,14.809674,1.557272,-149.945282,294.500458,0.000000
97.310005,65.093307,-149.989761,-0.001052,0.006141,0.155988,289.549500,14.750354,1.559876,-149.989761,294.500458,0.000000
97.760002,65.120499,-150.078735,-0.001043,0.006149,0.156197,289.670441,14.756516,1.561966,-150.078735,294.500458,0.000000
98.210007,65.326782,-150.078735,-0.001039,0.006160,0.156455,290.588043,14.803261,1.564554,-150.078735,294.500458,0.000000
98.660004,65.095551,-150.167694,-0.001022,0.006168,0.156664,289.559479,14.750862,1.566644,-150.167694,294.500458,0.000000
99.110008,64.991287,-150.212173,-0.001013,0.006172,0.156776,289.095673,14.727236,1.567764,-150.212173,294.500458,0.000000
99.560005,65.194595,-150.256653,-0.001005,0.006180,0.156976,290.000031,14.773306,1.569762,-150.256653,294.500458,0.000000
100.010002,65.112671,-150.345612,-0.001005,0.006186,0.157132,289.635620,14.754742,1.571322,-150.345612,294.500458,0.000000
100.460007,65.107452,-150.434570,-0.000992,0.006191,0.157262,289.612427,14.753560,1.572624,-150.434570,294.500458,0.000000
100.910004,65.202408,-150.434570,-0.000992,0.006198,0.157427,290.034790,14.775077,1.574274,-150.434570,294.500458,0.000000
101.360008,65.244492,-150.523544,-0.000987,0.006202,0.157539,290.221985,14.784614,1.575394,-150.523544,294.500458,0.000000
101.810005,65.137253,-150.568024,-0.000987,0.006206,0.157635,289.744965,14.760312,1.576348,-150.568024,294.500458,0.000000
102.260002,65.209122,-150.612503,-0.000979,0.006210,0.157730,290.064667,14.776598,1.577302,-150.612503,294.500458,0.000000
102.710007,65.108582,-150.701462,-0.000979,0.006213,0.157818,289.617432,14.753816,1.578180,-150.701462,294.500458,0.000000
103.160004,65.051971,-150.790421,-0.000979,0.006216,0.157895,289.365631,14.740987,1.578952,-150.790421,294.500458,0.000000
103.610008,64.933929,-150.790421,-0.000953,0.006218,0.157948,288.840546,14.714238,1.579482,-150.790421,294.500458,0.000000
104.060005,65.520798,-150.879379,-0.000966,0.006226,0.158147,291.451050,14.847225,1.581465,-150.879379,294.500458,0.000000
104.510002,65.240402,-150.879379,-0.000961,0.006227,0.158156,290.203796,14.783687,1.581556,-150.879379,294.500458,0.000000
104.960007,65.197205,-150.968353,-0.000953,0.006232,0.158295,290.011658,14.773898,1.582949,-150.968353,294.500458,0.000000
105.410004,65.190125,-150.968353,-0.000944,0.006232,0.158295,289.980164,14.772293,1.582949,-150.968353,294.500458,0.000000
105.860008,64.965958,-151.057312,-0.000944,0.006233,0.158312,288.983002,14.721497,1.583116,-151.057312,294.500458,0.000000
106.310005,64.895950,-151.190750,-0.000944,0.006235,0.158365,288.671600,14.705633,1.583645,-151.190750,294.500458,0.000000
106.760002,65.146561,-151.190750,-0.000957,0.006240,0.158493,289.786377,14.762422,1.584932,-151.190750,294.500458,0.000000
107.210007,64.986069,-151.279709,-0.000949,0.006240,0.158502,289.072479,14.726054,1.585023,-151.279709,294.500458,0.000000
107.660004,64.955154,-151.368683,-0.000931,0.006243,0.158581,288.934967,14.719049,1.585810,-151.368683,294.500458,0.000000
108.110008,64.873245,-151.413162,-0.000940,0.006243,0.158581,288.570618,14.700487,1.585810,-151.413162,294.500458,0.000000
108.560005,65.535690,-151.502121,-0.000931,0.006252,0.158807,291.517303,14.850599,1.588066,-151.502121,294.500458,0.000000
109.010002,65.381897,-151.457642,-0.000944,0.006252,0.158807,290.833191,14.815749,1.588066,-151.457642,294.500458,0.000000
109.460007,65.231461,-151.591080,-0.000936,0.006252,0.158807,290.164032,14.781660,1.588066,-151.591080,294.500458,0.000000
109.910004,65.057938,-151.635559,-0.000936,0.006252,0.158807,289.392151,14.742340,1.588066,-151.635559,294.500458,0.000000
110.360008,65.849976,-151.635559,-0.000931,0.006263,0.159075,292.915314,14.921818,1.590746,-151.635559,294.500458,0.000000
110.810005,65.757629,-151.769012,-0.000931,0.006263,0.159075,292.504547,14.900892,1.590746,-151.769012,294.500458,0.000000
111.260002,65.620590,-151.813492,-0.000936,0.006263,0.159075,291.894958,14.869839,1.590746,-151.813492,294.500458,0.000000
111.710007,65.492859,-151.946930,-0.000949,0.006263,0.159075,291.326782,14.840894,1.590746,-151.946930,294.500458,0.000000
112.160004,65.329773,-151.857971,-0.000936,0.006263,0.159084,290.601349,14.803939,1.590837,-151.857971,294.500458,0.000000
112.610008,65.193481,-151.991409,-0.000927,0.006263,0.159084,289.995087,14.773054,1.590837,-151.991409,294.500458,0.000000
113.060005,65.212463,-151.991409,-0.000936,0.006267,0.159170,290.079529,14.777355,1.591700,-151.991409,294.500458,0.000000
113.510002,65.181183,-152.124847,-0.000931,0.006267,0.159170,289.940369,14.770267,1.591700,-152.124847,294.500458,0.000000
113.960007,65.124954,-152.169327,-0.000918,0.006268,0.159205,289.690277,14.757525,1.592048,-152.169327,294.500458,0.000000
114.410004,65.120117,-152.213821,-0.000918,0.006270,0.159258,289.668762,14.756430,1.592578,-152.213821,294.500458,0.000000
114.860008,65.195709,-152.302780,-0.000923,0.006272,0.159318,290.005005,14.773559,1.593183,-152.302780,294.500458,0.000000
115.310005,65.203903,-152.347260,-0.000927,0.006273,0.159326,290.041443,14.775416,1.593259,-152.347260,294.500458,0.000000
115.760002,65.206879,-152.391739,-0.000923,0.006275,0.159379,290.054687,14.776090,1.593789,-152.391739,294.500458,0.000000
116.210007,65.184174,-152.480698,-0.000910,0.006275,0.159379,289.953674,14.770945,1.593789,-152.480698,294.500458,0.000000
116.660004,65.229965,-152.480698,-0.000918,0.006277,0.159439,290.157379,14.781322,1.594395,-152.480698,294.500458,0.000000
117.110008,65.214706,-152.569656,-0.000918,0.006278,0.159449,290.089508,14.777864,1.594485,-152.569656,294.500458,0.000000
117.560005,65.138000,-152.569656,-0.000910,0.006278,0.159456,289.748291,14.760482,1.594561,-152.569656,294.500458,0.000000
118.010002,65.212463,-152.614136,-0.000923,0.006280,0.159517,290.079529,14.777355,1.595167,-152.614136,294.500458,0.000000
118.460007,65.137253,-152.747589,-0.000910,0.006280,0.159517,289.744965,14.760312,1.595167,-152.747589,294.500458,0.000000
118.910004,65.053833,-152.792068,-0.000923,0.006280,0.159517,289.373901,14.741409,1.595167,-152.792068,294.500458,0.000000
119.360008,65.593399,-152.836548,-0.000918,0.006287,0.159700,291.774017,14.863676,1.596999,-152.836548,294.500458,0.000000
119.810005,65.587082,-152.881027,-0.000905,0.006287,0.159700,291.745911,14.862246,1.596999,-152.881027,294.500458,0.000000
120.260002,65.525269,-152.925507,-0.000927,0.006287,0.159700,291.470947,14.848238,1.596999,-152.925507,294.500458,0.000000
120.710007,65.459717,-153.058960,-0.000910,0.006287,0.159700,291.179352,14.833384,1.596999,-153.058960,294.500458,0.000000
121.160004,65.358063,-153.058960,-0.000905,0.006287,0.159700,290.727173,14.810349,1.596999,-153.058960,294.500458,0.000000
121.610008,65.287689,-153.147919,-0.000897,0.006288,0.159707,290.414154,14.794401,1.597074,-153.147919,294.500458,0.000000
122.060005,65.214325,-153.192398,-0.000914,0.006288,0.159707,290.087799,14.777778,1.597074,-153.192398,294.500458,0.000000
122.510002,65.182312,-153.281357,-0.000905,0.006289,0.159751,289.945404,14.770522,1.597513,-153.281357,294.500458,0.000000
122.960007,65.206146,-153.281357,-0.000918,0.006290,0.159777,290.051422,14.775925,1.597771,-153.281357,294.500458,0.000000
123.410004,65.166290,-153.370316,-0.000901,0.006290,0.159777,289.874146,14.766892,1.597771,-153.370316,294.500458,0.000000
123.860008,65.147675,-153.370316,-0.000901,0.006291,0.159803,289.791321,14.762674,1.598028,-153.370316,294.500458,0.000000
124.310005,65.153641,-153.459274,-0.000910,0.006294,0.159856,289.817871,14.764026,1.598558,-153.459274,294.500458,0.000000
124.760002,65.182312,-153.548248,-0.000910,0.006294,0.159856,289.945404,14.770522,1.598558,-153.548248,294.500458,0.000000
125.210007,65.124954,-153.637207,-0.000905,0.006294,0.159856,289.690277,14.757525,1.598558,-153.637207,294.500458,0.000000
125.660004,65.103363,-153.681686,-0.000905,0.006294,0.159872,289.594208,14.752633,1.598724,-153.681686,294.500458,0.000000
126.110008,65.087357,-153.726166,-0.000901,0.006295,0.159891,289.523010,14.749006,1.598906,-153.726166,294.500458,0.000000
126.560005,65.091080,-153.815125,-0.000901,0.006296,0.159907,289.539581,14.749849,1.599073,-153.815125,294.500458,0.000000
127.010010,65.092560,-153.815125,-0.000892,0.006297,0.159933,289.546173,14.750185,1.599330,-153.815125,294.500458,0.000000
127.460007,65.120499,-153.904083,-0.000910,0.006298,0.159960,289.670441,14.756516,1.599603,-153.904083,294.500458,0.000000
127.910004,65.098145,-153.948578,-0.000910,0.006298,0.159960,289.571014,14.751450,1.599603,-153.948578,294.500458,0.000000
128.360001,65.041916,-154.037537,-0.000901,0.006298,0.159960,289.320892,14.738708,1.599603,-154.037537,294.500458,0.000000
128.810013,65.241135,-154.082016,-0.000901,0.006301,0.160047,290.207062,14.783853,1.600466,-154.082016,294.500458,0.000000
129.260010,65.230347,-154.126495,-0.000905,0.006301,0.160047,290.159088,14.781407,1.600466,-154.126495,294.500458,0.000000
129.710007,65.216187,-154.170975,-0.000888,0.006301,0.160047,290.096100,14.778199,1.600466,-154.170975,294.500458,0.000000
130.160004,65.160339,-154.215454,-0.000905,0.006301,0.160047,289.847656,14.765544,1.600466,-154.215454,294.500458,0.000000
130.610001,65.120865,-154.215454,-0.000892,0.006301,0.160047,289.672089,14.756599,1.600466,-154.215454,294.500458,0.000000
131.060013,65.057938,-154.304413,-0.000897,0.006301,0.160047,289.392151,14.742340,1.600466,-154.304413,294.500458,0.000000
131.510010,65.345032,-154.393387,-0.000910,0.006306,0.160168,290.669220,14.807396,1.601677,-154.393387,294.500458,0.000000
131.960007,65.342056,-154.437866,-0.000892,0.006306,0.160168,290.655975,14.806722,1.601677,-154.437866,294.500458,0.000000
132.410004,65.340195,-154.482346,-0.000892,0.006306,0.160168,290.647705,14.806300,1.601677,-154.482346,294.500458,0.000000
132.860001,65.290298,-154.526825,-0.000892,0.006306,0.160168,290.425751,14.794993,1.601677,-154.526825,294.500458,0.000000
133.310013,65.262360,-154.571304,-0.000888,0.006306,0.160168,290.301483,14.788662,1.601677,-154.571304,294.500458,0.000000
133.760010,65.226242,-154.615784,-0.000905,0.006306,0.160177,290.140808,14.780478,1.601768,-154.615784,294.500458,0.000000
134.210007,65.211731,-154.660263,-0.000910,0.006307,0.160193,290.076263,14.777190,1.601934,-154.660263,294.500458,0.000000
134.660004,65.199814,-154.749222,-0.000897,0.006308,0.160219,290.023254,14.774489,1.602191,-154.749222,294.500458,0.000000
135.110001,65.230713,-154.793716,-0.000901,0.006309,0.160237,290.160706,14.781491,1.602373,-154.793716,294.500458,0.000000
135.560013,65.216187,-154.793716,-0.000901,0.006309,0.160237,290.096100,14.778199,1.602373,-154.793716,294.500458,0.000000
136.010010,65.197571,-154.927155,-0.000901,0.006309,0.160246,290.013275,14.773981,1.602464,-154.927155,294.500458,0.000000
136.460007,65.193100,-154.971634,-0.000888,0.006310,0.160263,289.993378,14.772967,1.602630,-154.971634,294.500458,0.000000
136.910004,65.167038,-155.016113,-0.000897,0.006310,0.160263,289.877472,14.767062,1.602630,-155.016113,294.500458,0.000000
137.360001,65.148422,-155.149551,-0.000897,0.006310,0.160263,289.794647,14.762843,1.602630,-155.149551,294.500458,0.000000
137.810013,65.158844,-155.194031,-0.000897,0.006312,0.160324,289.841003,14.765205,1.603236,-155.194031,294.500458,0.000000
138.260010,65.233322,-155.194031,-0.000897,0.006312,0.160333,290.172302,14.782083,1.603327,-155.194031,294.500458,0.000000
138.710007,65.223267,-155.238525,-0.000892,0.006312,0.160333,290.127594,14.779803,1.603327,-155.238525,294.500458,0.000000
139.160004,65.213211,-155.327484,-0.000901,0.006312,0.160333,290.082855,14.777525,1.603327,-155.327484,294.500458,0.000000
139.610001,65.170013,-155.371964,-0.000901,0.006312,0.160333,289.890686,14.767735,1.603327,-155.371964,294.500458,0.000000
140.060013,65.142090,-155.416443,-0.000897,0.006313,0.160358,289.766479,14.761409,1.603584,-155.416443,294.500458,0.000000
140.510010,65.210602,-155.460922,-0.000901,0.006314,0.160375,290.071259,14.776934,1.603751,-155.460922,294.500458,0.000000
140.960007,65.191238,-155.505402,-0.000901,0.006314,0.160375,289.985107,14.772546,1.603751,-155.505402,294.500458,0.000000
141.410004,65.176727,-155.594360,-0.000892,0.006314,0.160384,289.920563,14.769257,1.603842,-155.594360,294.500458,0.000000
141.860001,65.144699,-155.638855,-0.000888,0.006314,0.160384,289.778107,14.762000,1.603842,-155.638855,294.500458,0.000000
142.310013,65.129807,-155.683334,-0.000892,0.006315,0.160402,289.711853,14.758625,1.604023,-155.683334,294.500458,0.000000
142.760010,65.109329,-155.683334,-0.000897,0.006315,0.160402,289.620758,14.753985,1.604023,-155.683334,294.500458,0.000000
143.210007,65.314499,-155.816772,-0.000892,0.006319,0.160514,290.533386,14.800477,1.605144,-155.816772,294.500458,0.000000
143.660004,65.394928,-155.861252,-0.000901,0.006319,0.160514,290.891174,14.818703,1.605144,-155.861252,294.500458,0.000000
144.110001,65.372955,-155.905731,-0.000880,0.006319,0.160514,290.793427,14.813724,1.605144,-155.905731,294.500458,0.000000
144.560013,65.366257,-155.950211,-0.000888,0.006319,0.160514,290.763641,14.812205,1.605144,-155.950211,294.500458,0.000000
145.010010,65.353226,-155.994690,-0.000888,0.006319,0.160514,290.705658,14.809253,1.605144,-155.994690,294.500458,0.000000
145.460007,65.327911,-156.083664,-0.000888,0.006319,0.160514,290.593048,14.803516,1.605144,-156.083664,294.500458,0.000000
145.910004,65.299973,-156.128143,-0.000884,0.006319,0.160514,290.468781,14.797185,1.605144,-156.128143,294.500458,0.000000
146.360001,65.267212,-156.172623,-0.000892,0.006319,0.160514,290.323059,14.789762,1.605144,-156.172623,294.500458,0.000000
146.810013,65.274658,-156.217102,-0.000892,0.006320,0.160540,290.356171,14.791450,1.605401,-156.217102,294.500458,0.000000
147.260010,65.256409,-156.306061,-0.000888,0.006320,0.160540,290.274994,14.787313,1.605401,-156.306061,294.500458,0.000000
147.710007,65.256409,-156.350540,-0.000888,0.006321,0.160549,290.274994,14.787313,1.605492,-156.350540,294.500458,0.000000
148.160004,65.246735,-156.350540,-0.000888,0.006321,0.160558,290.231964,14.785122,1.605583,-156.350540,294.500458,0.000000
148.610001,65.273544,-156.439499,-0.000884,0.006322,0.160584,290.351227,14.791197,1.605840,-156.439499,294.500458,0.000000
149.060013,65.270935,-156.528473,-0.000884,0.006322,0.160584,290.339630,14.790605,1.605840,-156.528473,294.500458,0.000000
149.510010,65.258270,-156.483978,-0.000892,0.006322,0.160584,290.283295,14.787735,1.605840,-156.483978,294.500458,0.000000
149.960007,65.257156,-156.617432,-0.000875,0.006322,0.160584,290.278320,14.787483,1.605840,-156.617432,294.500458,0.000000
150.410004,65.211731,-156.661911,-0.000880,0.006322,0.160584,290.076263,14.777190,1.605840,-156.661911,294.500458,0.000000
150.860001,65.405365,-156.706390,-0.000888,0.006326,0.160688,290.937592,14.821068,1.606885,-156.706390,294.500458,0.000000
151.310013,65.441849,-156.795349,-0.000884,0.006326,0.160688,291.099884,14.829334,1.606885,-156.795349,294.500458,0.000000
151.760010,65.432907,-156.839828,-0.000888,0.006326,0.160688,291.060120,14.827309,1.606885,-156.839828,294.500458,0.000000
152.210007,65.401642,-156.884308,-0.000884,0.006326,0.160688,290.921021,14.820224,1.606885,-156.884308,294.500458,0.000000
152.660004,65.401260,-156.928802,-0.000892,0.006326,0.160688,290.919342,14.820137,1.606885,-156.928802,294.500458,0.000000
153.110001,65.371094,-157.017761,-0.000892,0.006326,0.160688,290.785156,14.813301,1.606885,-157.017761,294.500458,0.000000
153.560013,65.364777,-157.017761,-0.000888,0.006326,0.160688,290.757050,14.811871,1.606885,-157.017761,294.500458,0.000000
154.010010,65.322693,-157.151199,-0.000884,0.006326,0.160688,290.569855,14.802334,1.606885,-157.151199,294.500458,0.000000
154.460007,65.310410,-157.151199,-0.000875,0.006327,0.160696,290.515198,14.799551,1.606960,-157.151199,294.500458,0.000000
154.910004,65.292160,-157.195679,-0.000875,0.006327,0.160705,290.434021,14.795415,1.607051,-157.195679,294.500458,0.000000
155.360001,65.296997,-157.240158,-0.000884,0.006327,0.160714,290.455536,14.796512,1.607142,-157.240158,294.500458,0.000000
155.810013,65.274277,-157.284637,-0.000884,0.006328,0.160723,290.354492,14.791362,1.607233,-157.284637,294.500458,0.000000
156.260010,65.275024,-157.418091,-0.000888,0.006328,0.160731,290.357819,14.791532,1.607309,-157.418091,294.500458,0.000000
156.710007,65.296631,-157.462570,-0.000875,0.006328,0.160740,290.453918,14.796428,1.607399,-157.462570,294.500458,0.000000
157.160004,65.270187,-157.507050,-0.000888,0.006319,0.160505,290.336304,14.790436,1.605053,-157.507050,0.160540,0.000000
157.610001,65.172256,-157.551529,-0.000888,0.006302,0.160063,289.900665,14.768245,1.600632,-157.551529,0.159795,0.000000
158.060013,65.155121,-157.596008,-0.000888,0.006285,0.159630,289.824463,14.764361,1.596302,-157.596008,0.159040,0.000000
158.510010,65.108948,-157.640488,-0.000880,0.006256,0.158893,289.619049,14.753899,1.588929,-157.640488,0.158295,0.000000
158.960007,65.034851,-157.729446,-0.000884,0.006226,0.158147,289.289459,14.737107,1.581465,-157.729446,0.157539,0.000000
159.410004,64.983826,-157.773926,-0.000871,0.006201,0.157497,289.062500,14.725546,1.574970,-157.773926,0.156795,0.000000
159.860001,64.948822,-157.818420,-0.000875,0.006168,0.156655,288.906799,14.717614,1.566553,-157.818420,0.156039,0.000000
160.310013,64.885895,-157.862900,-0.000867,0.006153,0.156292,288.626862,14.703354,1.562919,-157.862900,0.155294,0.000000
160.760010,64.846420,-157.907379,-0.000875,0.006110,0.155206,288.451294,14.694408,1.552064,-157.907379,0.154539,0.000000
161.210007,64.704559,-157.996338,-0.000875,0.006080,0.154427,287.820251,14.662263,1.544267,-157.996338,0.153794,0.000000
161.660004,64.047318,-158.040817,-0.000871,0.006052,0.153715,284.896698,14.513330,1.537152,-158.040817,0.153038,0.000000
162.110001,63.461197,-158.174255,-0.000854,0.006034,0.153264,282.289490,14.380512,1.532640,-158.174255,0.152294,0.000000
162.560013,61.858139,-158.218750,-0.000862,0.006006,0.152562,275.158752,14.017255,1.525615,-158.218750,0.151538,0.000000
163.010010,59.969093,-158.218750,-0.000836,0.005975,0.151756,266.755859,13.589190,1.517561,-158.218750,0.150793,0.000000
163.460007,57.995522,-158.263229,-0.000841,0.005950,0.151123,257.976959,13.141973,1.511233,-158.263229,0.150038,0.000000
163.910004,55.610847,-158.352188,-0.000836,0.005920,0.150359,247.369400,12.601598,1.503587,-158.352188,0.149293,0.000000
164.360001,53.784729,-158.352188,-0.000845,0.005904,0.149970,239.246429,12.187795,1.499696,-158.352188,0.148539,0.000000
164.810013,49.473778,-158.396667,-0.000828,0.005860,0.148851,220.070358,11.210917,1.488508,-158.396667,0.147793,0.000000
165.260010,46.110504,-158.530106,-0.000823,0.005831,0.148095,205.109772,10.448790,1.480954,-158.530106,0.147039,0.000000
165.710007,43.356438,-158.530106,-0.000823,0.005803,0.147402,192.859070,9.824709,1.474020,-158.530106,0.146292,0.000000
166.160004,39.735489,-158.574585,-0.000841,0.005771,0.146578,176.752289,9.004190,1.465784,-158.574585,0.145538,0.000000
166.610001,36.507019,-158.574585,-0.000828,0.005743,0.145876,162.391327,8.272609,1.458759,-158.574585,0.144792,0.000000
167.060013,34.228844,-158.708038,-0.000828,0.005719,0.145252,152.257507,7.756367,1.452522,-158.708038,0.144038,0.000000
167.510010,30.334946,-158.796997,-0.000828,0.005684,0.144376,134.936584,6.873997,1.443756,-158.796997,0.143292,0.000000
167.960007,27.484062,-158.796997,-0.000836,0.005658,0.143725,122.255211,6.227978,1.437246,-158.796997,0.142538,0.000000
168.410004,23.643784,-158.841476,-0.000828,0.005622,0.142797,105.172806,5.357758,1.427965,-158.841476,0.141791,0.000000
168.860001,21.004784,-158.885956,-0.000823,0.005600,0.142233,93.433945,4.759752,1.422333,-158.885956,0.141037,0.000000
169.310013,18.101768,-158.930435,-0.000832,0.005573,0.141566,80.520691,4.101920,1.415657,-158.930435,0.140291,0.000000
169.760010,14.967880,-158.974915,-0.000828,0.005543,0.140803,66.580460,3.391770,1.408026,-158.974915,0.139537,0.000000
170.210007,11.091110,-159.108368,-0.000832,0.005506,0.139840,49.335724,2.513281,1.398398,-159.108368,0.138791,0.000000
170.660004,7.993347,-159.108368,-0.000841,0.005479,0.139163,35.556183,1.811318,1.391630,-159.108368,0.138037,0.000000
171.110001,4.724655,-159.152847,-0.000823,0.005447,0.138349,21.016315,1.070622,1.383485,-159.152847,0.137290,0.000000
171.560013,2.336632,-159.197327,-0.000832,0.005424,0.137767,10.393857,0.529488,1.377671,-159.197327,0.136536,0.000000
172.010010,-0.340721,-159.286285,-0.000828,0.005399,0.137143,-1.515603,-0.077209,1.371434,-159.286285,0.135790,0.000000
172.460007,-0.310562,-159.286285,-0.000832,0.005356,0.136032,-1.381449,-0.070374,1.360322,-159.286285,0.135036,0.000000
172.910004,0.025688,-159.419724,-0.000836,0.005325,0.135262,0.114267,0.005821,1.352615,-159.419724,0.134290,0.000000
173.360001,0.074097,-159.419724,-0.000819,0.005301,0.134645,0.329598,0.016791,1.346454,-159.419724,0.133536,0.000000
173.810013,0.062180,-159.464203,-0.000823,0.005279,0.134090,0.276589,0.014090,1.340897,-159.464203,0.132789,0.000000
174.260010,0.042450,-159.553177,-0.000823,0.005242,0.133154,0.188827,0.009619,1.331541,-159.553177,0.132035,0.000000
174.710007,0.074471,-159.642136,-0.000819,0.005219,0.132555,0.331261,0.016875,1.325546,-159.642136,0.131289,0.000000
175.160004,0.044312,-159.686615,-0.000832,0.005184,0.131661,0.197107,0.010041,1.316614,-159.686615,0.130535,0.000000
175.610016,0.029785,-159.686615,-0.000845,0.005159,0.131029,0.132491,0.006749,1.310285,-159.686615,0.129789,0.000000
176.060013,-0.033516,-159.731094,-0.000845,0.005122,0.130100,-0.149086,-0.007595,1.301005,-159.731094,0.129035,0.000000
176.510010,-0.033516,-159.864532,-0.000845,0.005095,0.129416,-0.149086,-0.007595,1.294162,-159.864532,0.128288,0.000000
176.960007,-0.014900,-159.864532,-0.000858,0.005070,0.128783,-0.066279,-0.003376,1.287833,-159.864532,0.127534,0.000000
177.410004,-0.007454,-159.909012,-0.000875,0.005037,0.127951,-0.033157,-0.001689,1.279506,-159.909012,0.126788,0.000000
177.860016,-0.051765,-159.997986,-0.000892,0.005008,0.127204,-0.230264,-0.011730,1.272043,-159.997986,0.126043,0.000000
178.310013,-0.083786,-159.997986,-0.000957,0.004974,0.126329,-0.372699,-0.018986,1.263292,-159.997986,0.125288,0.000000
178.760010,-0.042824,-160.042465,-0.000996,0.004945,0.125609,-0.190490,-0.009704,1.256086,-160.042465,0.124543,0.000000
179.210007,-0.045807,-160.131424,-0.001048,0.004916,0.124855,-0.203759,-0.010380,1.248546,-160.131424,0.123787,0.000000
179.660004,-0.044685,-160.175903,-0.001091,0.004889,0.124169,-0.198770,-0.010126,1.241688,-160.175903,0.123042,0.000000
180.110016,-0.069267,-160.264862,-0.001130,0.004856,0.123336,-0.308116,-0.015696,1.233361,-160.264862,0.122287,0.000000
180.560013,-0.079315,-160.309341,-0.001155,0.004829,0.122668,-0.352812,-0.017973,1.226684,-160.309341,0.121542,0.000000
181.010010,-0.074104,-160.398315,-0.001194,0.004802,0.121966,-0.329632,-0.016792,1.219660,-160.398315,0.120787,0.000000
181.460007,-0.061447,-160.353836,-0.001216,0.004773,0.121247,-0.273331,-0.013924,1.212468,-160.353836,0.120042,0.000000
181.910004,-0.076714,-160.487274,-0.001259,0.004744,0.120500,-0.341239,-0.017384,1.205005,-160.487274,0.119286,0.000000
182.360016,-0.045059,-160.531754,-0.001281,0.004714,0.119737,-0.200433,-0.010211,1.197374,-160.531754,0.118541,0.000000
182.810013,-0.074104,-160.576233,-0.001328,0.004678,0.118828,-0.329632,-0.016792,1.188275,-160.576233,0.117786,0.000000
183.260010,-0.070755,-160.620712,-0.001362,0.004645,0.117995,-0.314734,-0.016033,1.179949,-160.620712,0.117041,0.000000
183.710007,-0.065544,-160.665192,-0.001397,0.004626,0.117500,-0.291555,-0.014853,1.174998,-160.665192,0.116286,0.000000
184.160004,-0.105385,-160.754150,-0.001423,0.004590,0.116590,-0.468775,-0.023881,1.165899,-160.754150,0.115541,0.000000
184.400009,-0.052505,-160.754150,-0.001431,0.004592,0.116625,-0.233556,-0.011898,1.166247,-160.754150,0.116504,0.000000