File: Data/compression 29/AutoNoHeating-17-29-reverse-1-4_10232024_173213.csv
Time (sec),S:Load (lbs),S:HL1 (DIM),S:LVDT (in),S:Position (in),Ch:Position (mm),Ch:Load (N),Ch:Stress (MPa),Ch:Strain (mm/mm),Ch:HL1 (DIM),Set Point (),Cycles ()
0.110000,0.007820,-217.689774,-0.012637,-0.005677,-0.144202,0.034786,0.001772,-1.442022,-217.689774,-0.144003,0.000000
0.550000,0.019363,-217.734253,-0.012633,-0.005594,-0.142095,0.086133,0.004388,-1.420948,-217.734253,-0.141297,0.000000
0.990000,0.030533,-217.823212,-0.012452,-0.005329,-0.135365,0.135817,0.006919,-1.353653,-217.823212,-0.133978,0.000000
1.430000,-0.013405,-217.778732,-0.012150,-0.005024,-0.127621,-0.059628,-0.003038,-1.276214,-217.778732,-0.126641,0.000000
1.870000,-0.071869,-217.912186,-0.011861,-0.004744,-0.120501,-0.319689,-0.016286,-1.205012,-217.912186,-0.119304,0.000000
2.310000,0.044685,-217.912186,-0.011551,-0.004450,-0.113026,0.198770,0.010126,-1.130260,-217.912186,-0.111985,0.000000
2.750000,0.068886,-217.867691,-0.011253,-0.004164,-0.105776,0.306419,0.015610,-1.057757,-217.867691,-0.104649,0.000000
3.190000,-0.006332,-217.956665,-0.010964,-0.003879,-0.098534,-0.028168,-0.001435,-0.985344,-217.956665,-0.097329,0.000000
3.630000,-0.004845,-218.001144,-0.010658,-0.003585,-0.091050,-0.021550,-0.001098,-0.910502,-218.001144,-0.089992,0.000000
4.070000,0.027550,-218.045624,-0.010365,-0.003303,-0.083887,0.122547,0.006243,-0.838869,-218.045624,-0.082655,0.000000
4.510000,0.048035,-218.045624,-0.010080,-0.003011,-0.076490,0.213669,0.010885,-0.764897,-218.045624,-0.075336,0.000000
4.950000,0.018242,-218.045624,-0.009800,-0.002725,-0.069222,0.081144,0.004134,-0.692219,-218.045624,-0.067999,0.000000
5.390000,0.012657,-218.179062,-0.009533,-0.002436,-0.061868,0.056302,0.002868,-0.618679,-218.179062,-0.060663,0.000000
5.830000,0.047661,-218.223541,-0.009227,-0.002152,-0.054653,0.212006,0.010800,-0.546531,-218.223541,-0.053344,0.000000
6.270000,0.009308,-218.223541,-0.008903,-0.001852,-0.047047,0.041403,0.002109,-0.470470,-218.223541,-0.046007,0.000000
6.710001,0.021225,-218.268021,-0.008632,-0.001571,-0.039901,0.094413,0.004810,-0.399011,-218.268021,-0.038670,0.000000
7.150001,0.066650,-218.268021,-0.008330,-0.001281,-0.032547,0.296476,0.015103,-0.325471,-218.268021,-0.031350,0.000000
7.590000,0.037605,-218.268021,-0.008037,-0.000997,-0.025332,0.167277,0.008521,-0.253315,-218.268021,-0.024014,0.000000
8.030001,-0.020859,-218.356995,-0.007705,-0.000702,-0.017839,-0.092784,-0.004727,-0.178390,-218.356995,-0.016694,0.000000
8.470000,-0.009315,-218.401474,-0.007433,-0.000414,-0.010528,-0.041437,-0.002111,-0.105281,-218.401474,-0.009358,0.000000
8.910001,0.083778,-218.490433,-0.007114,-0.000130,-0.003296,0.372665,0.018984,-0.032959,-218.490433,-0.002021,0.000000
9.350000,0.072235,-218.490433,-0.006834,0.000161,0.004102,0.321318,0.016369,0.041021,-218.490433,0.005299,0.000000
9.790001,0.027184,-218.445953,-0.006541,0.000450,0.011421,0.120918,0.006160,0.114213,-218.445953,0.012635,0.000000
10.230000,0.040955,-218.534912,-0.006239,0.000741,0.018828,0.182175,0.009280,0.188276,-218.534912,0.019972,0.000000
10.670000,0.093460,-218.534912,-0.005937,0.001030,0.026155,0.415731,0.021178,0.261551,-218.534912,0.027291,0.000000
11.110001,0.093460,-218.623871,-0.005665,0.001320,0.033518,0.415731,0.021178,0.335183,-218.623871,0.034628,0.000000
11.550000,0.004089,-218.623871,-0.005545,-0.000000,-0.000000,0.018190,0.000927,-0.000000,-218.623871,0.000235,0.000000
11.990001,0.087135,-218.668350,-0.005549,-0.000000,-0.000000,0.387597,0.019745,-0.000000,-218.668350,0.000590,0.000000
12.430000,0.097931,-218.668350,-0.005558,0.000008,0.000191,0.435618,0.022191,0.001908,-218.668350,0.001319,0.000000
12.870001,0.097183,-218.712830,-0.005545,0.000042,0.001076,0.432293,0.022022,0.010757,-218.712830,0.002056,0.000000
13.310000,0.058456,-218.846283,-0.005523,0.000072,0.001839,0.260027,0.013246,0.018387,-218.846283,0.002784,0.000000
13.750001,0.090111,-218.846283,-0.005476,0.000100,0.002533,0.400833,0.020419,0.025329,-218.846283,0.003521,0.000000
14.190001,0.100166,-218.757324,-0.005458,0.000120,0.003053,0.445562,0.022698,0.030529,-218.757324,0.004250,0.000000
14.630001,0.082664,-218.935242,-0.005441,0.000147,0.003738,0.367710,0.018732,0.037380,-218.935242,0.004987,0.000000
15.070001,0.072983,-218.935242,-0.005402,0.000182,0.004631,0.324644,0.016538,0.046312,-218.935242,0.005724,0.000000
15.510001,0.077080,-218.979721,-0.005381,0.000210,0.005334,0.342868,0.017467,0.053337,-218.979721,0.006452,0.000000
15.950001,0.064789,-219.068680,-0.005329,0.000242,0.006157,0.288195,0.014681,0.061573,-219.068680,0.007190,0.000000
16.390001,0.081543,-218.979721,-0.005307,0.000269,0.006834,0.362721,0.018478,0.068340,-218.979721,0.007918,0.000000
16.830000,0.084900,-219.157639,-0.005273,0.000299,0.007589,0.377654,0.019239,0.075887,-219.157639,0.008655,0.000000
17.270000,0.034256,-219.113159,-0.005256,0.000328,0.008334,0.152378,0.007763,0.083343,-219.113159,0.009384,0.000000
17.710001,0.043564,-219.157639,-0.005213,0.000355,0.009028,0.193782,0.009872,0.090277,-219.157639,0.010121,0.000000
18.150002,0.090111,-219.246613,-0.005182,0.000384,0.009757,0.400833,0.020419,0.097567,-219.246613,0.010858,0.000000
18.590000,0.070000,-219.246613,-0.005135,0.000425,0.010788,0.311374,0.015862,0.107885,-219.246613,0.011586,0.000000
19.030001,0.046547,-219.291092,-0.005135,0.000447,0.011343,0.207051,0.010548,0.113433,-219.291092,0.012324,0.000000
19.470001,0.059204,-219.335571,-0.005113,0.000471,0.011960,0.263353,0.013416,0.119595,-219.335571,0.013052,0.000000
19.910002,0.091225,-219.380051,-0.005075,0.000500,0.012705,0.405788,0.020672,0.127051,-219.380051,0.013789,0.000000
20.350000,0.086388,-219.424530,-0.005062,0.000525,0.013330,0.384271,0.019576,0.133296,-219.424530,0.014517,0.000000
20.790001,0.059952,-219.380051,-0.005014,0.000566,0.014370,0.266679,0.013585,0.143705,-219.380051,0.015255,0.000000
21.230001,0.054733,-219.513489,-0.004993,0.000592,0.015029,0.243466,0.012403,0.150291,-219.513489,0.015992,0.000000
21.670000,0.089363,-219.469009,-0.004954,0.000615,0.015610,0.397507,0.020250,0.156104,-219.469009,0.016720,0.000000
22.110001,0.132935,-219.513489,-0.004941,0.000642,0.016313,0.591322,0.030123,0.163129,-219.513489,0.017457,0.000000
22.550001,0.093086,-219.602463,-0.004889,0.000684,0.017362,0.414068,0.021094,0.173621,-219.602463,0.018186,0.000000
22.990002,0.065536,-219.557968,-0.004872,0.000708,0.017977,0.291521,0.014851,0.179775,-219.557968,0.018923,0.000000
23.430000,0.123627,-219.646942,-0.004838,0.000737,0.018732,0.549919,0.028014,0.187322,-219.646942,0.019652,0.000000
23.870001,0.163841,-219.646942,-0.004816,0.000763,0.019392,0.728802,0.037127,0.193915,-219.646942,0.020388,0.000000
24.310001,0.159370,-219.735901,-0.004781,0.000800,0.020311,0.708915,0.036114,0.203105,-219.735901,0.021117,0.000000
24.750002,0.134796,-219.824860,-0.004760,0.000823,0.020909,0.599603,0.030545,0.209093,-219.824860,0.021855,0.000000
25.190001,0.199219,-219.780380,-0.004734,0.000853,0.021672,0.886169,0.045144,0.216723,-219.780380,0.022591,0.000000
25.630001,0.280769,-219.824860,-0.004704,0.000877,0.022288,1.248924,0.063623,0.222877,-219.824860,0.023320,0.000000
26.070002,0.369392,-219.824860,-0.004678,0.000908,0.023051,1.643139,0.083706,0.230508,-219.824860,0.024057,0.000000
26.510002,0.575684,-219.824860,-0.004648,0.000942,0.023927,2.560769,0.130452,0.239273,-219.824860,0.024786,0.000000
26.950001,0.701920,-219.958298,-0.004626,0.000965,0.024508,3.122294,0.159057,0.245080,-219.958298,0.025523,0.000000
27.390001,1.110786,-219.958298,-0.004600,0.000999,0.025366,4.941025,0.251708,0.253664,-219.958298,0.026251,0.000000
27.830002,1.447037,-220.047272,-0.004596,0.001024,0.026008,6.436741,0.327903,0.260083,-220.047272,0.026989,0.000000
28.270000,1.875633,-220.002777,-0.004544,0.001058,0.026876,8.343233,0.425025,0.268758,-220.002777,0.027725,0.000000
28.710001,2.185081,-220.047272,-0.004531,0.001082,0.027474,9.719728,0.495147,0.274738,-220.047272,0.028454,0.000000
29.150002,2.685173,-220.180710,-0.004506,0.001110,0.028203,11.944246,0.608469,0.282028,-220.180710,0.029191,0.000000
29.590002,3.116753,-220.180710,-0.004475,0.001138,0.028905,13.864008,0.706266,0.289052,-220.180710,0.029920,0.000000
30.030001,3.511093,-220.269669,-0.004467,0.001164,0.029555,15.618122,0.795625,0.295555,-220.269669,0.030657,0.000000
30.470001,4.214882,-220.225189,-0.004419,0.001196,0.030379,18.748732,0.955106,0.303791,-220.225189,0.031385,0.000000
30.910002,4.726891,-220.269669,-0.004419,0.001226,0.031142,21.026258,1.071129,0.311421,-220.269669,0.032122,0.000000
31.350002,5.248589,-220.314148,-0.004381,0.001252,0.031801,23.346888,1.189347,0.318014,-220.314148,0.032860,0.000000
31.790001,5.774002,-220.314148,-0.004355,0.001278,0.032469,25.684044,1.308408,0.324691,-220.314148,0.033588,0.000000
32.230003,6.377251,-220.403107,-0.004329,0.001313,0.033345,28.367428,1.445106,0.333449,-220.403107,0.034325,0.000000
32.670002,6.747383,-220.403107,-0.004312,0.001341,0.034056,30.013859,1.528979,0.340565,-220.403107,0.035053,0.000000
33.110001,7.234825,-220.447586,-0.004286,0.001369,0.034785,32.182110,1.639435,0.347847,-220.447586,0.035791,0.000000
33.550003,7.492500,-220.536560,-0.004264,0.001394,0.035409,33.328304,1.697825,0.354092,-220.536560,0.036519,0.000000
33.990002,8.351196,-220.492081,-0.004238,0.001433,0.036398,37.147976,1.892408,0.363978,-220.492081,0.037256,0.000000
34.430000,8.470726,-220.581039,-0.004208,0.001457,0.037013,37.679672,1.919494,0.370132,-220.581039,0.037994,0.000000
34.870003,8.880333,-220.581039,-0.004178,0.001486,0.037751,39.501694,2.012312,0.377505,-220.581039,0.038722,0.000000
35.310001,9.329788,-220.625519,-0.004148,0.001516,0.038514,41.500969,2.114160,0.385136,-220.625519,0.039459,0.000000
35.750000,9.464218,-220.669998,-0.004126,0.001538,0.039078,42.098946,2.144622,0.390775,-220.669998,0.040187,0.000000
36.190002,10.034317,-220.669998,-0.004096,0.001571,0.039901,44.634872,2.273809,0.399011,-220.669998,0.040925,0.000000
36.630001,10.284927,-220.758957,-0.004079,0.001599,0.040621,45.749641,2.330598,0.406210,-220.758957,0.041653,0.000000
37.070004,10.655434,-220.803436,-0.004049,0.001629,0.041367,47.397736,2.414556,0.413666,-220.803436,0.042390,0.000000
37.510002,10.913490,-220.758957,-0.004023,0.001656,0.042069,48.545628,2.473032,0.420691,-220.758957,0.043119,0.000000
37.950001,11.541679,-220.847916,-0.004010,0.001690,0.042928,51.339954,2.615382,0.429283,-220.847916,0.043856,0.000000
38.390003,11.672012,-220.892410,-0.003980,0.001718,0.043631,51.919704,2.644916,0.436308,-220.892410,0.044593,0.000000
38.830002,11.887619,-220.936890,-0.003958,0.001745,0.044324,52.878769,2.693773,0.443241,-220.936890,0.045322,0.000000
39.270000,12.169128,-220.981369,-0.003932,0.001771,0.044983,54.130985,2.757564,0.449835,-220.981369,0.046058,0.000000
39.710003,12.364624,-220.981369,-0.003919,0.001798,0.045677,55.000595,2.801864,0.456769,-220.981369,0.046787,0.000000
40.150002,12.861740,-221.070328,-0.003876,0.001833,0.046562,57.211876,2.914512,0.465618,-221.070328,0.047524,0.000000
40.590000,12.926537,-221.070328,-0.003850,0.001858,0.047204,57.500107,2.929195,0.472037,-221.070328,0.048253,0.000000
41.030003,13.468338,-221.159286,-0.003837,0.001892,0.048045,59.910160,3.051969,0.480447,-221.159286,0.048990,0.000000
41.470001,13.591217,-221.159286,-0.003829,0.001914,0.048625,60.456753,3.079814,0.486253,-221.159286,0.049727,0.000000
41.910004,14.318832,-221.203766,-0.003790,0.001953,0.049614,63.693348,3.244694,0.496139,-221.203766,0.050456,0.000000
42.350002,14.109932,-221.292725,-0.003760,0.001977,0.050204,62.764111,3.197356,0.502044,-221.292725,0.051193,0.000000
42.790001,14.567955,-221.248245,-0.003760,0.002010,0.051045,64.801498,3.301146,0.510446,-221.248245,0.051921,0.000000
43.230003,14.295746,-221.292725,-0.003742,0.002027,0.051488,63.590652,3.239462,0.514882,-221.292725,0.052658,0.000000
43.670002,15.212898,-221.381699,-0.003695,0.002068,0.052537,67.670349,3.447292,0.525374,-221.381699,0.053387,0.000000
44.110001,14.979797,-221.381699,-0.003704,0.002093,0.053170,66.633469,3.394471,0.531702,-221.381699,0.054124,0.000000
44.550003,15.160767,-221.426178,-0.003673,0.002121,0.053882,67.438461,3.435479,0.538818,-221.426178,0.054861,0.000000
44.990002,15.574104,-221.426178,-0.003656,0.002150,0.054618,69.277077,3.529143,0.546175,-221.426178,0.055590,0.000000
45.430000,15.760292,-221.515137,-0.003643,0.002180,0.055373,70.105278,3.571333,0.553730,-221.515137,0.056327,0.000000
45.870003,16.019089,-221.559616,-0.003609,0.002211,0.056171,71.256462,3.629977,0.561709,-221.559616,0.057055,0.000000
46.310001,15.837746,-221.515137,-0.003604,0.002235,0.056778,70.449814,3.588884,0.567780,-221.515137,0.057792,0.000000
46.750004,16.268951,-221.693054,-0.003579,0.002266,0.057558,72.367912,3.686597,0.575577,-221.693054,0.058521,0.000000
47.190002,16.463699,-221.604095,-0.003557,0.002295,0.058295,73.234192,3.730728,0.582950,-221.604095,0.059258,0.000000
47.630001,16.825272,-221.693054,-0.003535,0.002330,0.059179,74.842545,3.812661,0.591791,-221.693054,0.059995,0.000000
48.070004,16.414177,-221.693054,-0.003514,0.002352,0.059735,73.013908,3.719506,0.597347,-221.693054,0.060723,0.000000
48.510002,16.655846,-221.737534,-0.003514,0.002382,0.060507,74.088905,3.774269,0.605068,-221.737534,0.061461,0.000000
48.950001,16.741859,-221.782028,-0.003484,0.002408,0.061165,74.471512,3.793760,0.611654,-221.782028,0.062189,0.000000
49.390003,17.297813,-221.826508,-0.003479,0.002444,0.062077,76.944519,3.919741,0.620768,-221.826508,0.062926,0.000000
49.830002,17.036034,-221.870987,-0.003454,0.002468,0.062675,75.780060,3.860420,0.626748,-221.870987,0.063654,0.000000
50.270004,16.987625,-221.870987,-0.003441,0.002493,0.063333,75.564728,3.849451,0.633334,-221.870987,0.064392,0.000000
50.710003,17.649338,-221.915466,-0.003436,0.002527,0.064175,78.508179,3.999397,0.641752,-221.915466,0.065120,0.000000
51.150002,17.466499,-221.959946,-0.003423,0.002551,0.064791,77.694870,3.957965,0.647913,-221.959946,0.065857,0.000000
51.590004,17.726791,-221.959946,-0.003397,0.002582,0.065589,78.852707,4.016948,0.655892,-221.959946,0.066594,0.000000
52.030003,17.744659,-222.093384,-0.003385,0.002610,0.066299,78.932190,4.020997,0.662992,-222.093384,0.067323,0.000000
52.470001,18.170280,-222.093384,-0.003372,0.002642,0.067115,80.825447,4.117444,0.671153,-222.093384,0.068060,0.000000
52.910004,17.697746,-222.137863,-0.003363,0.002662,0.067627,78.723511,4.010366,0.676270,-222.137863,0.068788,0.000000
53.350002,18.642822,-222.137863,-0.003337,0.002702,0.068632,82.927414,4.224524,0.686323,-222.137863,0.069525,0.000000
53.790001,18.213852,-222.137863,-0.003316,0.002727,0.069258,81.019257,4.127318,0.692575,-222.137863,0.070254,0.000000
54.230003,18.515099,-222.182358,-0.003298,0.002758,0.070063,82.359268,4.195581,0.700629,-222.182358,0.070991,0.000000
54.670002,18.874443,-222.226837,-0.003294,0.002788,0.070809,83.957718,4.277010,0.708093,-222.226837,0.071728,0.000000
55.110004,18.658463,-222.315796,-0.003268,0.002810,0.071365,82.996986,4.228068,0.713650,-222.315796,0.072457,0.000000
55.550003,18.907951,-222.360275,-0.003260,0.002842,0.072179,84.106766,4.284603,0.721795,-222.360275,0.073194,0.000000
55.990002,19.031212,-222.360275,-0.003238,0.002872,0.072952,84.655060,4.312534,0.729516,-222.360275,0.073922,0.000000
56.430004,19.346237,-222.360275,-0.003225,0.002902,0.073715,86.056358,4.383920,0.737146,-222.360275,0.074659,0.000000
56.870003,19.121323,-222.404755,-0.003208,0.002928,0.074366,85.055893,4.332954,0.743656,-222.404755,0.075388,0.000000
57.310001,19.549553,-222.493713,-0.003195,0.002958,0.075129,86.960754,4.429992,0.751287,-222.493713,0.076125,0.000000
57.750004,20.048904,-222.493713,-0.003169,0.002985,0.075831,89.181984,4.543147,0.758311,-222.493713,0.076862,0.000000
58.190002,20.353874,-222.538193,-0.003160,0.003016,0.076611,90.538551,4.612254,0.766108,-222.538193,0.077590,0.000000
58.630001,20.351639,-222.582672,-0.003156,0.003039,0.077201,90.528610,4.611747,0.772013,-222.582672,0.078328,0.000000
59.070004,20.141998,-222.627167,-0.003139,0.003065,0.077860,89.596085,4.564242,0.778598,-222.627167,0.079056,0.000000
59.510002,21.232300,-222.627167,-0.003117,0.003103,0.078805,94.445984,4.811308,0.788045,-222.627167,0.079793,0.000000
59.950005,21.109047,-222.716125,-0.003104,0.003128,0.079439,93.897728,4.783379,0.794389,-222.716125,0.080523,0.000000
60.390003,21.576378,-222.760605,-0.003078,0.003160,0.080253,95.976524,4.889277,0.802534,-222.760605,0.081259,0.000000
60.830002,21.879860,-222.760605,-0.003074,0.003186,0.080912,97.326477,4.958047,0.809120,-222.760605,0.081996,0.000000
61.270004,22.824196,-222.805084,-0.003065,0.003223,0.081858,101.527092,5.172037,0.818582,-222.805084,0.082726,0.000000
61.710003,22.575821,-222.760605,-0.003027,0.003248,0.082500,100.422264,5.115754,0.825001,-222.760605,0.083461,0.000000
62.150002,22.773178,-222.894043,-0.003014,0.003275,0.083184,101.300156,5.160476,0.831844,-222.894043,0.084191,0.000000
62.590004,22.816376,-222.894043,-0.002997,0.003298,0.083757,101.492310,5.170264,0.837567,-222.894043,0.084927,0.000000
63.030003,23.038681,-222.938522,-0.002971,0.003325,0.084459,102.481171,5.220640,0.844592,-222.938522,0.085657,0.000000
63.470001,24.207558,-223.071976,-0.002945,0.003364,0.085457,107.680595,5.485511,0.854569,-223.071976,0.086394,0.000000
63.910004,24.237350,-222.983002,-0.002940,0.003392,0.086150,107.813118,5.492262,0.861503,-222.983002,0.087122,0.000000
64.350006,24.700211,-223.116455,-0.002932,0.003420,0.086862,109.872025,5.597147,0.868618,-223.116455,0.087860,0.000000
64.790001,24.617912,-223.071976,-0.002897,0.003442,0.087425,109.505943,5.578499,0.874250,-223.071976,0.088595,0.000000
65.230003,25.994949,-223.160934,-0.002880,0.003481,0.088414,115.631310,5.890540,0.884136,-223.160934,0.089325,0.000000
65.670006,26.099586,-223.160934,-0.002859,0.003506,0.089056,116.096756,5.914251,0.890556,-223.160934,0.090062,0.000000
66.110001,26.728523,-223.160934,-0.002837,0.003535,0.089793,118.894409,6.056770,0.897928,-223.160934,0.090791,0.000000
66.550003,27.041687,-223.294373,-0.002820,0.003562,0.090479,120.287430,6.127734,0.904787,-223.294373,0.091528,0.000000
66.990005,28.188591,-223.249893,-0.002802,0.003597,0.091354,125.389114,6.387626,0.913537,-223.249893,0.092256,0.000000
67.430000,28.244820,-223.338852,-0.002781,0.003622,0.091996,125.639236,6.400368,0.919957,-223.338852,0.092993,0.000000
67.870003,28.967224,-223.338852,-0.002759,0.003651,0.092724,128.852646,6.564067,0.927239,-223.338852,0.093731,0.000000
68.310005,29.355980,-223.383331,-0.002738,0.003679,0.093435,130.581924,6.652160,0.934354,-223.383331,0.094459,0.000000
68.750000,30.076523,-223.472305,-0.002721,0.003709,0.094215,133.787048,6.815437,0.942151,-223.472305,0.095196,0.000000
69.190002,31.056236,-223.427811,-0.002695,0.003739,0.094962,138.145035,7.037444,0.949615,-223.427811,0.095924,0.000000
69.630005,31.163849,-223.427811,-0.002669,0.003763,0.095578,138.623718,7.061829,0.955777,-223.427811,0.096662,0.000000
70.070000,32.364746,-223.561264,-0.002665,0.003797,0.096436,143.965576,7.333956,0.964361,-223.561264,0.097390,0.000000
70.510002,32.823883,-223.516785,-0.002634,0.003821,0.097051,146.007919,7.437998,0.970508,-223.516785,0.098127,0.000000
70.950005,34.081017,-223.561264,-0.002630,0.003856,0.097953,151.599930,7.722869,0.979531,-223.561264,0.098864,0.000000
71.390007,34.162567,-223.650223,-0.002600,0.003879,0.098525,151.962692,7.741348,0.985254,-223.650223,0.099593,0.000000
71.830002,35.135201,-223.650223,-0.002587,0.003907,0.099246,156.289185,7.961750,0.992460,-223.650223,0.100330,0.000000
72.270004,36.180824,-223.694702,-0.002561,0.003939,0.100061,160.940338,8.198692,1.000605,-223.694702,0.101058,0.000000
72.710007,37.076378,-223.694702,-0.002557,0.003969,0.100807,164.923965,8.401627,1.008069,-223.694702,0.101796,0.000000
73.150002,37.494926,-223.828140,-0.002531,0.003996,0.101509,166.785767,8.496471,1.015094,-223.828140,0.102524,0.000000
73.590004,38.822060,-223.828140,-0.002514,0.004025,0.102247,172.689148,8.797204,1.022467,-223.828140,0.103261,0.000000
74.030006,39.717987,-223.872620,-0.002496,0.004052,0.102931,176.674423,9.000225,1.029310,-223.872620,0.103998,0.000000
74.470001,40.552475,-223.917114,-0.002470,0.004077,0.103564,180.386414,9.189322,1.035638,-223.917114,0.104727,0.000000
74.910004,41.863602,-223.872620,-0.002453,0.004110,0.104389,186.218597,9.486428,1.043889,-223.872620,0.105464,0.000000
75.350006,42.726013,-224.006073,-0.002440,0.004138,0.105117,190.054794,9.681852,1.051171,-224.006073,0.106192,0.000000
75.790001,44.088524,-223.961594,-0.002414,0.004172,0.105957,196.115555,9.990602,1.059574,-223.961594,0.106929,0.000000
76.230003,44.714485,-224.006073,-0.002406,0.004197,0.106608,198.899963,10.132447,1.066084,-224.006073,0.107658,0.000000
76.670006,46.935684,-224.050552,-0.002384,0.004231,0.107458,208.780350,10.635777,1.074577,-224.050552,0.108395,0.000000
77.110001,47.598137,-224.050552,-0.002363,0.004256,0.108109,211.727081,10.785892,1.081087,-224.050552,0.109123,0.000000
77.550003,48.943520,-224.095032,-0.002371,0.004287,0.108881,217.711655,11.090759,1.088808,-224.095032,0.109860,0.000000
77.990005,50.275124,-224.183990,-0.002350,0.004314,0.109574,223.634918,11.392507,1.095742,-224.183990,0.110598,0.000000
78.430000,50.977043,-224.183990,-0.002320,0.004335,0.110121,226.757217,11.551562,1.101208,-224.183990,0.111326,0.000000
78.870003,52.789375,-224.272949,-0.002324,0.004368,0.110953,234.818863,11.962244,1.109534,-224.272949,0.112063,0.000000
79.310005,54.209236,-224.272949,-0.002289,0.004398,0.111707,241.134720,12.283988,1.117074,-224.272949,0.112791,0.000000
79.750000,55.872253,-224.361923,-0.002285,0.004428,0.112480,248.532196,12.660834,1.124795,-224.361923,0.113529,0.000000
80.190002,56.997559,-224.406403,-0.002255,0.004453,0.113096,253.537796,12.915832,1.130957,-224.406403,0.114257,0.000000
80.630005,59.005768,-224.361923,-0.002255,0.004488,0.113996,262.470764,13.370898,1.139965,-224.361923,0.114994,0.000000
81.070007,60.280022,-224.450882,-0.002233,0.004515,0.114673,268.138916,13.659648,1.146732,-224.450882,0.115731,0.000000
81.510002,61.835426,-224.495361,-0.002233,0.004543,0.115394,275.057709,14.012108,1.153939,-224.495361,0.116460,0.000000
81.950005,63.343903,-224.539841,-0.002216,0.004568,0.116027,281.767761,14.353933,1.160267,-224.539841,0.117197,0.000000
82.390007,64.668808,-224.584320,-0.002182,0.004598,0.116799,287.661224,14.654160,1.167988,-224.584320,0.117925,0.000000
82.830002,65.163681,-224.539841,-0.002186,0.004604,0.116929,289.862518,14.766301,1.169290,-224.539841,290.293182,0.000000
83.270004,65.078049,-224.673279,-0.002164,0.004620,0.117336,289.481628,14.746897,1.173363,-224.673279,294.500458,0.000000
83.710007,64.949570,-224.628799,-0.002169,0.004630,0.117604,288.910126,14.717783,1.176043,-224.628799,294.500458,0.000000
84.150002,65.164810,-224.717758,-0.002143,0.004640,0.117848,289.867554,14.766557,1.178480,-224.717758,294.500458,0.000000
84.590004,65.048248,-224.762253,-0.002143,0.004647,0.118046,289.349060,14.740144,1.180463,-224.762253,294.500458,0.000000
85.030006,64.980103,-224.762253,-0.002143,0.004654,0.118204,289.045929,14.724701,1.182038,-224.762253,294.500458,0.000000
85.470001,65.067993,-224.851212,-0.002139,0.004661,0.118385,289.436890,14.744618,1.183855,-224.851212,294.500458,0.000000
85.910004,65.234818,-224.940170,-0.002126,0.004669,0.118585,290.178955,14.782421,1.185853,-224.940170,294.500458,0.000000
86.350006,64.976761,-224.895691,-0.002121,0.004671,0.118653,289.031067,14.723944,1.186534,-224.895691,294.500458,0.000000
86.790001,65.340942,-224.895691,-0.002100,0.004680,0.118862,290.651031,14.806470,1.188624,-224.895691,294.500458,0.000000
87.230003,65.015106,-224.940170,-0.002117,0.004681,0.118906,289.201630,14.732634,1.189063,-224.940170,294.500458,0.000000
87.670006,65.814972,-224.984650,-0.002100,0.004691,0.119139,292.759613,14.913886,1.191394,-224.984650,294.500458,0.000000
88.110001,65.280243,-225.029129,-0.002104,0.004691,0.119139,290.381012,14.792715,1.191394,-225.029129,294.500458,0.000000
88.550003,64.958511,-225.162567,-0.002095,0.004694,0.119227,288.949890,14.719809,1.192272,-225.162567,294.500458,0.000000
88.990005,64.946594,-225.118088,-0.002082,0.004698,0.119323,288.896881,14.717109,1.193226,-225.118088,294.500458,0.000000
89.430008,65.334229,-225.073608,-0.002104,0.004705,0.119495,290.621155,14.804948,1.194952,-225.073608,294.500458,0.000000
89.870003,65.095917,-225.251541,-0.002087,0.004705,0.119495,289.561096,14.750946,1.194952,-225.251541,294.500458,0.000000
90.310005,65.241882,-225.162567,-0.002070,0.004709,0.119616,290.210388,14.784021,1.196163,-225.162567,294.500458,0.000000
90.750008,64.999847,-225.296021,-0.002078,0.004710,0.119634,289.133759,14.729176,1.196345,-225.296021,294.500458,0.000000
91.190002,65.001328,-225.296021,-0.002070,0.004713,0.119712,289.140350,14.729511,1.197117,-225.296021,294.500458,0.000000
91.630005,65.046768,-225.296021,-0.002074,0.004717,0.119799,289.342468,14.739808,1.197995,-225.296021,294.500458,0.000000
92.070007,64.894089,-225.384979,-0.002078,0.004718,0.119825,288.663330,14.705211,1.198252,-225.384979,294.500458,0.000000
92.510002,64.888870,-225.429459,-0.002061,0.004720,0.119886,288.640106,14.704028,1.198858,-225.429459,294.500458,0.000000
92.950005,65.693939,-225.473938,-0.002065,0.004730,0.120154,292.221222,14.886459,1.201538,-225.473938,294.500458,0.000000
93.390007,65.603836,-225.429459,-0.002065,0.004731,0.120163,291.820435,14.866042,1.201628,-225.429459,294.500458,0.000000
93.830002,65.461212,-225.518417,-0.002065,0.004731,0.120163,291.186005,14.833723,1.201628,-225.518417,294.500458,0.000000
94.270004,65.269821,-225.562897,-0.002061,0.004731,0.120163,290.334656,14.790353,1.201628,-225.562897,294.500458,0.000000
94.710007,65.079529,-225.562897,-0.002057,0.004731,0.120163,289.488190,14.747232,1.201628,-225.562897,294.500458,0.000000
95.150002,65.679794,-225.651871,-0.002065,0.004740,0.120388,292.158325,14.883254,1.203884,-225.651871,294.500458,0.000000
95.590004,65.561386,-225.696350,-0.002048,0.004740,0.120388,291.631622,14.856422,1.203884,-225.696350,294.500458,0.000000
96.030006,65.400146,-225.696350,-0.002057,0.004740,0.120388,290.914368,14.819884,1.203884,-225.696350,294.500458,0.000000
96.470001,65.275024,-225.829788,-0.002065,0.004740,0.120398,290.357819,14.791532,1.203975,-225.829788,294.500458,0.000000
96.910004,65.101135,-225.696350,-0.002035,0.004740,0.120398,289.584320,14.752128,1.203975,-225.696350,294.500458,0.000000
97.350006,64.966324,-225.785309,-0.002065,0.004740,0.120398,288.984650,14.721580,1.203975,-225.785309,294.500458,0.000000
97.790001,64.895203,-225.785309,-0.002048,0.004753,0.120718,288.668274,14.705463,1.207185,-225.785309,294.500458,0.000000
98.230003,65.868958,-225.874268,-0.002039,0.004746,0.120544,292.999756,14.926120,1.205444,-225.874268,294.500458,0.000000
98.670006,65.767670,-225.874268,-0.002052,0.004746,0.120544,292.549194,14.903167,1.205444,-225.874268,294.500458,0.000000
99.110008,65.582230,-225.963226,-0.002052,0.004746,0.120544,291.724335,14.861145,1.205444,-225.963226,294.500458,0.000000
99.550003,65.419876,-226.007706,-0.002048,0.004746,0.120553,291.002136,14.824356,1.205534,-226.007706,294.500458,0.000000
99.990005,65.264969,-226.007706,-0.002022,0.004747,0.120570,290.313080,14.789253,1.205701,-226.007706,294.500458,0.000000
100.430008,65.126083,-226.052200,-0.002039,0.004747,0.120570,289.695282,14.757781,1.205701,-226.052200,294.500458,0.000000
100.870003,65.482819,-226.096680,-0.002044,0.004756,0.120805,291.282135,14.838619,1.208048,-226.096680,294.500458,0.000000
101.310005,65.398651,-226.096680,-0.002039,0.004756,0.120805,290.907715,14.819546,1.208048,-226.096680,294.500458,0.000000
101.750008,65.301834,-226.185638,-0.002044,0.004756,0.120805,290.477051,14.797607,1.208048,-226.185638,294.500458,0.000000
102.190002,65.259766,-226.230118,-0.002039,0.004757,0.120821,290.289948,14.788074,1.208214,-226.230118,294.500458,0.000000
102.630005,65.166672,-226.274597,-0.002039,0.004757,0.120830,289.875824,14.766979,1.208305,-226.274597,294.500458,0.000000
103.070007,65.337219,-226.230118,-0.002031,0.004762,0.120944,290.634460,14.805625,1.209440,-226.230118,294.500458,0.000000
103.510002,65.293640,-226.319077,-0.002035,0.004762,0.120944,290.440613,14.795751,1.209440,-226.319077,294.500458,0.000000
103.950005,65.222153,-226.363556,-0.002035,0.004762,0.120944,290.122620,14.779552,1.209440,-226.363556,294.500458,0.000000
104.390007,65.158844,-226.408035,-0.002026,0.004763,0.120979,289.841003,14.765205,1.209789,-226.408035,294.500458,0.000000
104.830002,65.248596,-226.408035,-0.002031,0.004766,0.121056,290.240265,14.785542,1.210561,-226.408035,294.500458,0.000000
105.270004,65.285080,-226.541489,-0.002035,0.004766,0.121056,290.402527,14.793811,1.210561,-226.541489,294.500458,0.000000
105.710007,65.238907,-226.497009,-0.002035,0.004766,0.121065,290.197144,14.783348,1.210652,-226.497009,294.500458,0.000000
106.150002,65.184906,-226.630447,-0.002031,0.004767,0.121074,289.956940,14.771111,1.210742,-226.630447,294.500458,0.000000
106.590004,65.228104,-226.585968,-0.002018,0.004768,0.121117,290.149109,14.780899,1.211166,-226.585968,294.500458,0.000000
107.030006,65.180817,-226.630447,-0.002026,0.004768,0.121117,289.938751,14.770185,1.211166,-226.630447,294.500458,0.000000
107.470009,65.311523,-226.719406,-0.002026,0.004772,0.121204,290.520172,14.799802,1.212044,-226.719406,294.500458,0.000000
107.910004,65.304443,-226.674927,-0.002035,0.004772,0.121204,290.488678,14.798199,1.212044,-226.674927,294.500458,0.000000
108.350006,65.258636,-226.719406,-0.002031,0.004772,0.121204,290.284912,14.787818,1.212044,-226.719406,294.500458,0.000000
108.790009,65.208374,-226.808365,-0.002022,0.004772,0.121204,290.061340,14.776429,1.212044,-226.808365,294.500458,0.000000
109.230003,65.158478,-226.808365,-0.002026,0.004773,0.121230,289.839386,14.765121,1.212302,-226.808365,294.500458,0.000000
109.670006,65.125702,-226.897339,-0.002039,0.004773,0.121247,289.693604,14.757695,1.212468,-226.897339,294.500458,0.000000
110.110008,65.164062,-226.808365,-0.002022,0.004775,0.121291,289.864227,14.766387,1.212907,-226.808365,294.500458,0.000000
110.550003,65.156616,-226.941818,-0.002013,0.004775,0.121291,289.831116,14.764701,1.212907,-226.941818,294.500458,0.000000
110.990005,65.112671,-226.941818,-0.002022,0.004776,0.121300,289.635620,14.754742,1.212998,-226.941818,294.500458,0.000000
111.430008,65.263855,-226.941818,-0.002039,0.004779,0.121377,290.308136,14.789001,1.213770,-226.941818,294.500458,0.000000
111.870003,65.259384,-227.030777,-0.002031,0.004779,0.121377,290.288239,14.787988,1.213770,-227.030777,294.500458,0.000000
112.310005,65.238907,-227.030777,-0.002022,0.004779,0.121377,290.197144,14.783348,1.213770,-227.030777,294.500458,0.000000
112.750008,65.190125,-227.119736,-0.002009,0.004779,0.121377,289.980164,14.772293,1.213770,-227.119736,294.500458,0.000000
113.190002,65.150650,-227.119736,-0.002022,0.004779,0.121386,289.804565,14.763348,1.213861,-227.119736,294.500458,0.000000
113.630005,65.260880,-227.119736,-0.002031,0.004782,0.121456,290.294891,14.788326,1.214558,-227.119736,294.500458,0.000000
114.070007,65.263489,-227.208694,-0.002026,0.004782,0.121456,290.306488,14.788918,1.214558,-227.208694,294.500458,0.000000
114.510002,65.243378,-227.208694,-0.002018,0.004782,0.121463,290.217041,14.784361,1.214633,-227.208694,294.500458,0.000000
114.950005,65.242996,-227.208694,-0.002026,0.004783,0.121491,290.215332,14.784274,1.214906,-227.208694,294.500458,0.000000
115.390007,65.266464,-227.297653,-0.002018,0.004784,0.121516,290.319733,14.789592,1.215163,-227.297653,294.500458,0.000000
115.830002,65.279861,-227.297653,-0.002022,0.004784,0.121524,290.379333,14.792628,1.215239,-227.297653,294.500458,0.000000
116.270004,65.244873,-227.342148,-0.002018,0.004784,0.121524,290.223694,14.784699,1.215239,-227.342148,294.500458,0.000000
116.710007,65.254547,-227.342148,-0.002018,0.004786,0.121559,290.266724,14.786892,1.215587,-227.342148,294.500458,0.000000
117.150009,65.285461,-227.431107,-0.002026,0.004786,0.121577,290.404236,14.793897,1.215769,-227.431107,294.500458,0.000000
117.590004,65.269821,-227.431107,-0.002026,0.004786,0.121577,290.334656,14.790353,1.215769,-227.431107,294.500458,0.000000
118.030006,65.252319,-227.475586,-0.002013,0.004787,0.121586,290.256805,14.786387,1.215860,-227.475586,294.500458,0.000000
118.470009,65.224380,-227.520065,-0.002026,0.004787,0.121594,290.132538,14.780056,1.215935,-227.520065,294.500458,0.000000
118.910004,65.190872,-227.475586,-0.002022,0.004787,0.121594,289.983490,14.772463,1.215935,-227.475586,294.500458,0.000000
119.350006,65.150284,-227.609024,-0.002018,0.004787,0.121594,289.802948,14.763266,1.215935,-227.609024,294.500458,0.000000
119.790009,65.107452,-227.653503,-0.002018,0.004787,0.121594,289.612427,14.753560,1.215935,-227.653503,294.500458,0.000000
120.230003,65.064270,-227.653503,-0.002031,0.004787,0.121594,289.420319,14.743774,1.215935,-227.653503,294.500458,0.000000
120.670006,65.413177,-227.742462,-0.002009,0.004796,0.121819,290.972351,14.822838,1.218191,-227.742462,294.500458,0.000000
121.110008,65.682037,-227.697983,-0.002005,0.004796,0.121812,292.168304,14.883762,1.218115,-227.697983,294.500458,0.000000
121.550003,65.674576,-227.875916,-0.002022,0.004796,0.121812,292.135101,14.882072,1.218115,-227.875916,294.500458,0.000000
121.990005,65.661179,-227.786957,-0.002001,0.004796,0.121812,292.075500,14.879036,1.218115,-227.786957,294.500458,0.000000
122.430008,65.636597,-227.875916,-0.002009,0.004796,0.121812,291.966156,14.873466,1.218115,-227.875916,294.500458,0.000000
122.870003,65.584839,-227.875916,-0.001996,0.004796,0.121812,291.735931,14.861737,1.218115,-227.875916,294.500458,0.000000
123.310005,65.567337,-227.964874,-0.002009,0.004796,0.121812,291.658081,14.857771,1.218115,-227.964874,294.500458,0.000000
123.750008,65.535309,-228.009354,-0.002018,0.004796,0.121812,291.515625,14.850513,1.218115,-228.009354,294.500458,0.000000
124.190002,65.503662,-227.964874,-0.002009,0.004796,0.121812,291.374847,14.843342,1.218115,-227.964874,294.500458,0.000000
124.630005,65.450409,-228.098312,-0.002026,0.004796,0.121812,291.137970,14.831275,1.218115,-228.098312,294.500458,0.000000
125.070007,65.400513,-228.098312,-0.002009,0.004796,0.121812,290.916016,14.819968,1.218115,-228.098312,294.500458,0.000000
125.510010,65.358063,-228.098312,-0.002009,0.004796,0.121819,290.727173,14.810349,1.218191,-228.098312,294.500458,0.000000
125.950005,65.317108,-228.187286,-0.002013,0.004796,0.121819,290.545013,14.801068,1.218191,-228.187286,294.500458,0.000000
126.390007,65.296631,-228.187286,-0.001992,0.004796,0.121819,290.453918,14.796428,1.218191,-228.187286,294.500458,0.000000
126.830009,65.275772,-228.231766,-0.002018,0.004796,0.121828,290.361145,14.791701,1.218282,-228.231766,294.500458,0.000000
127.270004,65.245987,-228.276245,-0.002005,0.004797,0.121845,290.228638,14.784952,1.218449,-228.276245,294.500458,0.000000
127.710007,65.231461,-228.276245,-0.002022,0.004798,0.121863,290.164032,14.781660,1.218630,-228.276245,294.500458,0.000000
128.150009,65.287689,-228.454163,-0.002005,0.004799,0.121889,290.414154,14.794401,1.218888,-228.454163,294.500458,0.000000
128.590012,65.280609,-228.409683,-0.002013,0.004799,0.121889,290.382660,14.792797,1.218888,-228.409683,294.500458,0.000000
129.029999,65.265350,-228.454163,-0.002009,0.004799,0.121889,290.314789,14.789339,1.218888,-228.454163,294.500458,0.000000
129.470001,65.253799,-228.498642,-0.002018,0.004799,0.121898,290.263397,14.786722,1.218978,-228.498642,294.500458,0.000000
129.910004,65.265717,-228.454163,-0.002005,0.004800,0.121914,290.316406,14.789423,1.219145,-228.454163,294.500458,0.000000
130.350006,65.259766,-228.543121,-0.002009,0.004800,0.121924,290.289948,14.788074,1.219236,-228.543121,294.500458,0.000000
130.790009,65.259384,-228.543121,-0.002018,0.004800,0.121924,290.288239,14.787988,1.219236,-228.543121,294.500458,0.000000
131.230011,65.270187,-228.632095,-0.002013,0.004800,0.121933,290.336304,14.790436,1.219327,-228.632095,294.500458,0.000000
131.670013,65.240768,-228.632095,-0.002001,0.004800,0.121933,290.205444,14.783769,1.219327,-228.632095,294.500458,0.000000
132.110001,65.226624,-228.632095,-0.002001,0.004802,0.121975,290.142517,14.780564,1.219751,-228.632095,294.500458,0.000000
132.550003,65.248962,-228.721054,-0.002018,0.004802,0.121975,290.241882,14.785626,1.219751,-228.721054,294.500458,0.000000
132.990005,65.233322,-228.676575,-0.002005,0.004802,0.121975,290.172302,14.782083,1.219751,-228.676575,294.500458,0.000000
133.430008,65.221771,-228.765533,-0.002005,0.004802,0.121975,290.120941,14.779465,1.219751,-228.765533,294.500458,0.000000
133.870010,65.205765,-228.721054,-0.002001,0.004803,0.121984,290.049713,14.775837,1.219841,-228.721054,294.500458,0.000000
134.310013,65.238541,-228.854492,-0.002013,0.004804,0.122028,290.195526,14.783265,1.220280,-228.854492,294.500458,0.000000
134.750000,65.287689,-228.898972,-0.002009,0.004804,0.122028,290.414154,14.794401,1.220280,-228.898972,294.500458,0.000000
135.190002,65.267960,-228.898972,-0.002005,0.004804,0.122028,290.326385,14.789931,1.220280,-228.898972,294.500458,0.000000
135.630005,65.245605,-228.987930,-0.002013,0.004804,0.122028,290.226959,14.784865,1.220280,-228.987930,294.500458,0.000000
136.070007,65.246353,-228.943451,-0.001992,0.004804,0.122028,290.230286,14.785034,1.220280,-228.943451,294.500458,0.000000
136.510010,65.254913,-229.032410,-0.002005,0.004806,0.122070,290.268341,14.786975,1.220704,-229.032410,294.500458,0.000000
136.950012,65.279495,-229.076904,-0.002001,0.004806,0.122070,290.377686,14.792545,1.220704,-229.076904,294.500458,0.000000
137.389999,65.299973,-229.076904,-0.001996,0.004806,0.122070,290.468781,14.797185,1.220704,-229.076904,294.500458,0.000000
137.830002,65.278381,-229.165863,-0.002013,0.004806,0.122070,290.372742,14.792293,1.220704,-229.165863,294.500458,0.000000
138.270004,65.264221,-229.121384,-0.002005,0.004806,0.122070,290.309753,14.789083,1.220704,-229.121384,294.500458,0.000000
138.710007,65.245987,-229.210342,-0.002005,0.004806,0.122070,290.228638,14.784952,1.220704,-229.210342,294.500458,0.000000
139.150009,65.209869,-229.254822,-0.001996,0.004806,0.122070,290.067993,14.776768,1.220704,-229.254822,294.500458,0.000000
139.590012,65.189377,-229.299301,-0.002005,0.004806,0.122070,289.976837,14.772124,1.220704,-229.299301,294.500458,0.000000
140.030014,65.177460,-229.299301,-0.002009,0.004806,0.122070,289.923828,14.769423,1.220704,-229.299301,294.500458,0.000000
140.470001,65.184174,-229.299301,-0.002005,0.004810,0.122166,289.953674,14.770945,1.221658,-229.299301,294.500458,0.000000
140.910004,65.307800,-229.388260,-0.002001,0.004810,0.122166,290.503601,14.798959,1.221658,-229.388260,294.500458,0.000000
141.350006,65.321198,-229.432739,-0.001996,0.004810,0.122166,290.563202,14.801995,1.221658,-229.432739,294.500458,0.000000
141.790009,65.305939,-229.432739,-0.002013,0.004810,0.122166,290.495331,14.798536,1.221658,-229.432739,294.500458,0.000000
142.230011,65.296631,-229.477234,-0.002013,0.004810,0.122166,290.453918,14.796428,1.221658,-229.477234,294.500458,0.000000
142.670013,65.293274,-229.521713,-0.001996,0.004810,0.122166,290.438995,14.795667,1.221658,-229.521713,294.500458,0.000000
143.110001,65.269073,-229.521713,-0.002005,0.004810,0.122166,290.331329,14.790184,1.221658,-229.521713,1681.640747,0.000000
143.550003,65.143585,-229.566193,-0.002005,0.004796,0.121828,289.773132,14.761747,1.218282,-229.566193,0.121619,0.000000
143.990005,65.130554,-229.610672,-0.001996,0.004773,0.121247,289.715179,14.758794,1.212468,-229.610672,0.120883,0.000000
144.430008,65.072083,-229.744110,-0.002001,0.004752,0.120709,289.455078,14.745544,1.207094,-229.744110,0.120154,0.000000
144.870010,65.041916,-229.699631,-0.002009,0.004726,0.120033,289.320892,14.738708,1.200326,-229.699631,0.119418,0.000000
145.310013,64.990540,-229.744110,-0.002009,0.004696,0.119288,289.092346,14.727067,1.192878,-229.744110,0.118688,0.000000
145.750000,64.929840,-229.788589,-0.001992,0.004668,0.118567,288.822357,14.713312,1.185671,-229.788589,0.117951,0.000000
146.190002,64.865784,-229.788589,-0.001996,0.004647,0.118046,288.537415,14.698797,1.180463,-229.788589,0.117223,0.000000
146.630005,64.826691,-229.877548,-0.002009,0.004618,0.117301,288.363525,14.689939,1.173015,-229.877548,0.116485,0.000000
147.070007,64.765244,-229.877548,-0.001996,0.004588,0.116538,288.090179,14.676014,1.165384,-229.877548,0.115748,0.000000
147.510010,64.600296,-229.922043,-0.001988,0.004556,0.115722,287.356476,14.638636,1.157224,-229.922043,0.115020,0.000000
147.950012,63.903946,-229.922043,-0.001992,0.004529,0.115038,284.258942,14.480842,1.150381,-229.922043,0.114283,0.000000
148.390015,62.965202,-230.055481,-0.001979,0.004507,0.114482,280.083221,14.268119,1.144825,-230.055481,0.113554,0.000000
148.830002,61.294739,-230.055481,-0.001932,0.004476,0.113685,272.652618,13.889586,1.136846,-230.055481,0.112817,0.000000
149.270004,59.757584,-230.011002,-0.001936,0.004451,0.113061,265.815002,13.541262,1.130609,-230.011002,0.112089,0.000000
149.710007,57.595589,-230.099960,-0.001927,0.004424,0.112375,256.197968,13.051348,1.123750,-230.099960,0.111352,0.000000
150.150009,55.008720,-230.144440,-0.001914,0.004397,0.111673,244.691010,12.465155,1.116726,-230.144440,0.110614,0.000000
150.590012,53.010567,-230.144440,-0.001923,0.004373,0.111065,235.802780,12.012365,1.110655,-230.144440,0.109886,0.000000
151.030014,49.187424,-230.233398,-0.001910,0.004339,0.110207,218.796585,11.146030,1.102071,-230.233398,0.109149,0.000000
151.470001,45.930275,-230.233398,-0.001910,0.004310,0.109462,204.308060,10.407948,1.094622,-230.233398,0.108421,0.000000
151.910004,42.952042,-230.277878,-0.001923,0.004281,0.108725,191.060226,9.733071,1.087249,-230.277878,0.107683,0.000000
152.350006,40.097809,-230.233398,-0.001923,0.004256,0.108100,178.363968,9.086293,1.080996,-230.233398,0.106955,0.000000
152.790009,36.207634,-230.411331,-0.001914,0.004221,0.107206,161.059601,8.204767,1.072064,-230.411331,0.106218,0.000000
153.230011,33.888870,-230.366852,-0.001901,0.004195,0.106564,150.745224,7.679328,1.065645,-230.366852,0.105480,0.000000
153.670013,30.733017,-230.411331,-0.001910,0.004169,0.105889,136.707291,6.964201,1.058892,-230.411331,0.104752,0.000000
154.110001,27.708977,-230.411331,-0.001901,0.004142,0.105213,123.255684,6.278944,1.052125,-230.411331,0.104015,0.000000
154.550003,23.994186,-230.411331,-0.001901,0.004107,0.104327,106.731468,5.437160,1.043268,-230.411331,0.103287,0.000000
154.990005,21.040901,-230.500290,-0.001927,0.004081,0.103652,93.594604,4.767937,1.036516,-230.500290,0.102549,0.000000
155.430008,18.203049,-230.500290,-0.001897,0.004054,0.102984,80.971207,4.124870,1.029840,-230.500290,0.101821,0.000000
155.870010,15.439674,-230.589249,-0.001914,0.004030,0.102368,68.679100,3.498680,1.023678,-230.589249,0.101084,0.000000
156.310013,12.122208,-230.589249,-0.001914,0.003999,0.101579,53.922272,2.746932,1.015790,-230.589249,0.100356,0.000000
156.750000,8.704948,-230.633728,-0.001906,0.003966,0.100728,38.721546,1.972570,1.007282,-230.633728,0.099618,0.000000
157.190002,5.336838,-230.678207,-0.001910,0.003934,0.099914,23.739441,1.209345,0.999137,-230.678207,0.098881,0.000000
157.630005,2.957382,-230.633728,-0.001919,0.003910,0.099323,13.155093,0.670152,0.993232,-230.633728,0.098153,0.000000
158.070007,0.100166,-230.767181,-0.001932,0.003884,0.098665,0.445562,0.022698,0.986646,-230.767181,0.097416,0.000000
158.510010,-3.486900,-230.722687,-0.001901,0.003846,0.097693,-15.510508,-0.790143,0.976927,-230.722687,0.096687,0.000000
158.950012,0.008934,-230.811661,-0.001914,0.003822,0.097078,0.039741,0.002024,0.970780,-230.811661,0.095950,0.000000
159.390015,0.096817,-230.856140,-0.001914,0.003791,0.096288,0.430664,0.021939,0.962877,-230.856140,0.095222,0.000000
159.830002,0.117294,-230.856140,-0.001901,0.003764,0.095594,0.521751,0.026579,0.955943,-230.856140,0.094485,0.000000
160.270004,0.113945,-230.989578,-0.001914,0.003740,0.094987,0.506853,0.025820,0.949872,-230.989578,0.093747,0.000000
160.710007,0.100166,-230.945099,-0.001901,0.003706,0.094120,0.445562,0.022698,0.941197,-230.945099,0.093019,0.000000
161.150009,0.130699,-230.989578,-0.001906,0.003671,0.093245,0.581379,0.029617,0.932447,-230.989578,0.092282,0.000000
161.590012,0.114685,-231.034058,-0.001906,0.003645,0.092585,0.510145,0.025988,0.925846,-231.034058,0.091554,0.000000
162.030014,0.102402,-231.078537,-0.001893,0.003612,0.091735,0.455506,0.023205,0.917353,-231.078537,0.090816,0.000000
162.470001,0.057716,-231.167496,-0.001910,0.003583,0.091016,0.256735,0.013079,0.910161,-231.167496,0.090088,0.000000
162.910004,0.124367,-231.123016,-0.001893,0.003560,0.090435,0.553211,0.028182,0.904348,-231.123016,0.089351,0.000000
163.350006,0.115059,-231.167496,-0.001901,0.003532,0.089723,0.511808,0.026073,0.897232,-231.167496,0.088613,0.000000
163.790009,0.077820,-231.256470,-0.001888,0.003499,0.088865,0.346160,0.017634,0.888648,-231.256470,0.087885,0.000000
164.230011,0.028297,-231.211990,-0.001893,0.003472,0.088180,0.125873,0.006412,0.881805,-231.211990,0.087148,0.000000
164.670013,0.032021,-231.300949,-0.001884,0.003445,0.087504,0.142435,0.007256,0.875037,-231.300949,0.086420,0.000000
165.110001,0.050636,-231.389908,-0.001888,0.003413,0.086680,0.225241,0.011474,0.866802,-231.389908,0.085682,0.000000
165.550003,0.044685,-231.345428,-0.001888,0.003388,0.086055,0.198770,0.010126,0.860549,-231.345428,0.084954,0.000000
165.990005,0.044312,-231.434387,-0.001884,0.003356,0.085248,0.197107,0.010041,0.852479,-231.434387,0.084217,0.000000
166.430008,0.010422,-231.434387,-0.001880,0.003327,0.084512,0.046358,0.002362,0.845122,-231.434387,0.083480,0.000000
166.870010,-0.012665,-231.523346,-0.001871,0.003297,0.083748,-0.056336,-0.002870,0.837476,-231.523346,0.082751,0.000000
167.310013,0.002228,-231.389908,-0.001893,0.003269,0.083028,0.009910,0.000505,0.830285,-231.389908,0.082014,0.000000
167.750015,0.004089,-231.523346,-0.001888,0.003247,0.082465,0.018190,0.000927,0.824653,-231.523346,0.081286,0.000000
168.190002,0.005585,-231.567825,-0.001880,0.003216,0.081684,0.024842,0.001266,0.816841,-231.567825,0.080549,0.000000
168.630005,-0.032768,-231.567825,-0.001884,0.003184,0.080877,-0.145760,-0.007425,0.808771,-231.567825,0.079820,0.000000
169.070007,-0.013779,-231.567825,-0.001888,0.003151,0.080028,-0.061291,-0.003122,0.800278,-231.567825,0.079083,0.000000
169.510010,-0.037987,-231.656799,-0.001893,0.003123,0.079334,-0.168974,-0.008608,0.793344,-231.656799,0.078353,0.000000
169.950012,-0.026817,-231.656799,-0.001884,0.003098,0.078702,-0.119289,-0.006077,0.787016,-231.656799,0.077618,0.000000
170.390015,-0.090492,-231.745758,-0.001901,0.003066,0.077886,-0.402530,-0.020506,0.778856,-231.745758,0.076880,0.000000
170.830002,-0.078949,-231.701279,-0.001893,0.003040,0.077227,-0.351183,-0.017890,0.772270,-231.701279,0.076152,0.000000
171.270004,-0.061813,-231.834717,-0.001897,0.003005,0.076334,-0.274960,-0.014007,0.763338,-231.834717,0.075415,0.000000
171.710007,-0.070381,-231.834717,-0.001893,0.002984,0.075796,-0.313071,-0.015949,0.757963,-231.834717,0.074685,0.000000
172.150009,-0.097191,-231.879196,-0.001914,0.002945,0.074815,-0.432327,-0.022024,0.748153,-231.879196,0.073949,0.000000
172.590012,-0.094589,-231.879196,-0.001906,0.002917,0.074087,-0.420754,-0.021434,0.740870,-231.879196,0.073220,0.000000
173.030014,-0.090858,-231.879196,-0.001906,0.002897,0.073593,-0.404159,-0.020589,0.735935,-231.879196,0.072482,0.000000
173.470001,-0.114319,-232.012634,-0.001919,0.002863,0.072717,-0.508516,-0.025905,0.727169,-232.012634,0.071746,0.000000
173.910004,-0.140762,-231.968155,-0.001919,0.002834,0.071972,-0.626142,-0.031897,0.719720,-231.968155,0.071017,0.000000
174.350006,-0.127724,-232.012634,-0.001970,0.002809,0.071338,-0.568143,-0.028943,0.713377,-232.012634,0.070281,0.000000
174.790009,-0.125496,-232.057129,-0.002013,0.002779,0.070584,-0.558234,-0.028438,0.705837,-232.057129,0.069551,0.000000
175.230011,-0.101288,-232.101608,-0.002035,0.002751,0.069872,-0.450551,-0.022952,0.698722,-232.101608,0.068814,0.000000
175.670013,-0.116180,-232.190567,-0.002078,0.002722,0.069127,-0.516796,-0.026327,0.691273,-232.190567,0.068086,0.000000
176.110016,-0.125122,-232.146088,-0.002113,0.002691,0.068355,-0.556571,-0.028353,0.683552,-232.146088,0.067348,0.000000
176.550003,-0.106873,-232.235046,-0.002130,0.002661,0.067583,-0.475393,-0.024218,0.675831,-232.235046,0.066613,0.000000
176.990005,-0.107620,-232.235046,-0.002151,0.002634,0.066906,-0.478719,-0.024387,0.669063,-232.235046,0.065883,0.000000
177.430008,-0.104637,-232.279526,-0.002177,0.002607,0.066213,-0.465449,-0.023711,0.662130,-232.279526,0.065146,0.000000
177.870010,-0.108360,-232.368484,-0.002216,0.002575,0.065398,-0.482011,-0.024555,0.653984,-232.368484,0.064417,0.000000
178.310013,-0.112457,-232.279526,-0.002233,0.002549,0.064757,-0.500235,-0.025483,0.647565,-232.279526,0.063680,0.000000
178.750015,-0.090858,-232.412964,-0.002264,0.002524,0.064115,-0.404159,-0.020589,0.641146,-232.412964,0.062952,0.000000
179.190002,-0.112457,-232.412964,-0.002298,0.002493,0.063317,-0.500235,-0.025483,0.633168,-232.412964,0.062215,0.000000
179.630005,-0.112831,-232.412964,-0.002337,0.002460,0.062493,-0.501898,-0.025568,0.624932,-232.412964,0.061477,0.000000
180.070007,-0.113953,-232.590897,-0.002354,0.002431,0.061756,-0.506887,-0.025822,0.617559,-232.590897,0.060749,0.000000
180.510010,-0.087135,-232.501938,-0.002393,0.002402,0.061009,-0.387597,-0.019745,0.610095,-232.501938,0.060012,0.000000
180.950012,-0.078575,-232.590897,-0.002432,0.002378,0.060402,-0.349520,-0.017805,0.604024,-232.590897,0.059284,0.000000
181.390015,-0.093468,-232.501938,-0.002436,0.002355,0.059821,-0.415765,-0.021180,0.598210,-232.501938,0.058546,0.000000
181.830002,-0.105759,-232.635376,-0.002475,0.002315,0.058798,-0.470438,-0.023965,0.587976,-232.635376,0.057818,0.000000
182.270004,-0.037239,-232.679855,-0.002514,0.002281,0.057932,-0.165648,-0.008438,0.579316,-232.679855,0.057081,0.000000
182.700012,-0.064796,-232.679855,-0.002514,0.002275,0.057783,-0.288229,-0.014683,0.577832,-232.679855,0.057723,0.000000