File: Data/compression 29/AutoNoHeating-17-29-reverse-2-4_10232024_185038.csv
Time (sec),S:Load (lbs),S:HL1 (DIM),S:LVDT (in),S:Position (in),Ch:Position (mm),Ch:Load (N),Ch:Stress (MPa),Ch:Strain (mm/mm),Ch:HL1 (DIM),Set Point (),Cycles ()
0.110000,-0.005219,-443.119232,-0.010895,-0.005945,-0.150993,-0.023213,-0.001183,-1.509931,-443.119232,-0.150785,0.000000
0.510000,0.010422,-443.163727,-0.010891,-0.005861,-0.148868,0.046358,0.002362,-1.488683,-443.163727,-0.148079,0.000000
0.910000,-0.002609,-443.163727,-0.010714,-0.005612,-0.142546,-0.011607,-0.000591,-1.425460,-443.163727,-0.141419,0.000000
1.310000,-0.078949,-443.208191,-0.010438,-0.005349,-0.135869,-0.351183,-0.017890,-1.358686,-443.208191,-0.134758,0.000000
1.710000,-0.051392,-443.163727,-0.010175,-0.005088,-0.129234,-0.228601,-0.011646,-1.292345,-443.163727,-0.128098,0.000000
2.110000,-0.002983,-443.119232,-0.009912,-0.004828,-0.122643,-0.013269,-0.000676,-1.226435,-443.119232,-0.121420,0.000000
2.510000,-0.000374,-443.163727,-0.009632,-0.004566,-0.115965,-0.001663,-0.000085,-1.159654,-443.163727,-0.114760,0.000000
2.910000,-0.023460,-443.208191,-0.009390,-0.004308,-0.109427,-0.104357,-0.005316,-1.094266,-443.208191,-0.108100,0.000000
3.310000,-0.015274,-443.163727,-0.009102,-0.004036,-0.102524,-0.067942,-0.003461,-1.025237,-443.163727,-0.101440,0.000000
3.710000,-0.003723,-443.252686,-0.008843,-0.003775,-0.095890,-0.016561,-0.000844,-0.958896,-443.252686,-0.094779,0.000000
4.110000,0.025322,-443.252686,-0.008580,-0.003515,-0.089272,0.112638,0.005738,-0.892720,-443.252686,-0.088102,0.000000
4.510000,0.055107,-443.252686,-0.008308,-0.003251,-0.082586,0.245129,0.012487,-0.825864,-443.252686,-0.081441,0.000000
4.910000,0.043938,-443.297150,-0.008045,-0.002991,-0.075969,0.195445,0.009956,-0.759689,-443.297150,-0.074781,0.000000
5.310000,0.019730,-443.297150,-0.007778,-0.002731,-0.069370,0.087762,0.004471,-0.693696,-443.297150,-0.068121,0.000000
5.710000,-0.015274,-443.297150,-0.007515,-0.002470,-0.062744,-0.067942,-0.003461,-0.627437,-443.297150,-0.061443,0.000000
6.110000,0.029411,-443.341644,-0.007226,-0.002208,-0.056092,0.130828,0.006665,-0.560921,-443.341644,-0.054783,0.000000
6.510000,0.055107,-443.297150,-0.006954,-0.001938,-0.049232,0.245129,0.012487,-0.492324,-443.297150,-0.048123,0.000000
6.910000,0.046173,-443.297150,-0.006687,-0.001678,-0.042616,0.205388,0.010463,-0.426156,-443.297150,-0.041462,0.000000
7.310000,0.020103,-443.341644,-0.006420,-0.001415,-0.035938,0.089425,0.004556,-0.359383,-443.341644,-0.034802,0.000000
7.710001,-0.057350,-443.386108,-0.006135,-0.001151,-0.029235,-0.255106,-0.012996,-0.292345,-443.386108,-0.028124,0.000000
8.110001,-0.031654,-443.386108,-0.005881,-0.000891,-0.022644,-0.140806,-0.007173,-0.226435,-443.386108,-0.021464,0.000000
8.510000,0.014893,-443.386108,-0.005609,-0.000630,-0.016000,0.066245,0.003375,-0.160003,-443.386108,-0.014803,0.000000
8.910001,0.036118,-443.430603,-0.005333,-0.000367,-0.009323,0.160659,0.008184,-0.093230,-443.430603,-0.008144,0.000000
9.310000,0.106499,-443.430603,-0.005187,0.000003,0.000069,0.473730,0.024133,0.000689,-443.430603,0.000277,0.000000
9.710000,0.095695,-443.430603,-0.005187,0.000003,0.000069,0.425675,0.021685,0.000689,-443.430603,0.000390,0.000000
10.110001,0.141869,-443.475067,-0.005195,0.000004,0.000104,0.631063,0.032148,0.001037,-443.475067,0.001057,0.000000
10.510000,0.164955,-443.475067,-0.005170,0.000030,0.000754,0.733757,0.037379,0.007540,-443.475067,0.001726,0.000000
10.910001,0.265129,-443.475067,-0.005157,0.000052,0.001318,1.179353,0.060079,0.013179,-443.475067,0.002394,0.000000
11.310000,0.449081,-443.475067,-0.005135,0.000083,0.002107,1.997614,0.101763,0.021074,-443.475067,0.003061,0.000000
11.710001,0.612923,-443.475067,-0.005083,0.000107,0.002723,2.726416,0.138890,0.027229,-443.475067,0.003721,0.000000
12.110001,0.805809,-443.519562,-0.005092,0.000125,0.003165,3.584418,0.182599,0.031649,-443.519562,0.004388,0.000000
12.510000,1.294739,-443.475067,-0.005049,0.000160,0.004058,5.759285,0.293392,0.040582,-443.475067,0.005056,0.000000
12.910001,1.628754,-443.519562,-0.005032,0.000178,0.004527,7.245058,0.369081,0.045267,-443.519562,0.005724,0.000000
13.310000,2.245773,-443.564056,-0.005006,0.000212,0.005394,9.989698,0.508900,0.053942,-443.564056,0.006391,0.000000
13.710001,2.704910,-443.608521,-0.004984,0.000240,0.006105,12.032042,0.612941,0.061050,-443.608521,0.007059,0.000000
14.110001,3.165909,-443.475067,-0.004967,0.000265,0.006730,14.082665,0.717405,0.067295,-443.475067,0.007726,0.000000
14.510000,3.680901,-443.608521,-0.004945,0.000288,0.007319,16.373463,0.834104,0.073192,-443.608521,0.008395,0.000000
14.910001,4.054016,-443.564056,-0.004907,0.000310,0.007883,18.033165,0.918653,0.078832,-443.564056,0.009053,0.000000
15.310000,4.873611,-443.608521,-0.004889,0.000348,0.008828,21.678907,1.104376,0.088279,-443.608521,0.009721,0.000000
15.710001,5.083252,-443.653015,-0.004876,0.000368,0.009357,22.611435,1.151881,0.093570,-443.653015,0.010390,0.000000
16.110001,5.770653,-443.697479,-0.004855,0.000399,0.010129,25.669146,1.307649,0.101291,-443.697479,0.011057,0.000000
16.510000,5.944176,-443.741974,-0.004829,0.000417,0.010580,26.441013,1.346969,0.105803,-443.741974,0.011725,0.000000
16.910002,6.775314,-443.697479,-0.004799,0.000450,0.011439,30.138103,1.535308,0.114387,-443.697479,0.012393,0.000000
17.310001,7.016235,-443.697479,-0.004786,0.000475,0.012063,31.209774,1.589902,0.120632,-443.697479,0.013060,0.000000
17.710001,7.372971,-443.786438,-0.004773,0.000500,0.012696,32.796612,1.670739,0.126961,-443.786438,0.013728,0.000000
18.110001,7.859665,-443.741974,-0.004747,0.000529,0.013424,34.961536,1.781026,0.134243,-443.741974,0.014395,0.000000
18.510000,8.210068,-443.786438,-0.004730,0.000551,0.013997,36.520206,1.860428,0.139965,-443.786438,0.015055,0.000000
18.910002,8.845703,-443.741974,-0.004695,0.000585,0.014847,39.347652,2.004465,0.148466,-443.741974,0.015722,0.000000
19.310001,8.920555,-443.830933,-0.004674,0.000609,0.015479,39.680611,2.021427,0.154795,-443.830933,0.016390,0.000000
19.710001,9.346176,-443.830933,-0.004639,0.000635,0.016121,41.573868,2.117874,0.161214,-443.830933,0.017059,0.000000
20.110001,9.608322,-443.830933,-0.004618,0.000662,0.016806,42.739952,2.177277,0.168064,-443.830933,0.017726,0.000000
20.510000,10.175819,-443.786438,-0.004587,0.000685,0.017405,45.264305,2.305874,0.174052,-443.786438,0.018394,0.000000
20.910002,10.659531,-443.786438,-0.004566,0.000715,0.018168,47.415962,2.415484,0.181683,-443.786438,0.019061,0.000000
21.310001,10.715385,-443.875397,-0.004536,0.000739,0.018758,47.664413,2.428141,0.187579,-443.875397,0.019729,0.000000
21.710001,11.008072,-443.919891,-0.004527,0.000762,0.019365,48.966351,2.494465,0.193650,-443.919891,0.020388,0.000000
22.110001,11.486572,-443.919891,-0.004497,0.000790,0.020068,51.094826,2.602895,0.200675,-443.919891,0.021056,0.000000
22.510000,11.606850,-443.964386,-0.004484,0.000811,0.020588,51.629845,2.630150,0.205876,-443.964386,0.021724,0.000000
22.910002,12.170990,-443.964386,-0.004458,0.000841,0.021360,54.139267,2.757986,0.213597,-443.964386,0.022391,0.000000
23.310001,12.567940,-443.964386,-0.004441,0.000869,0.022080,55.904987,2.847936,0.220796,-443.964386,0.023059,0.000000
23.710001,12.658798,-443.964386,-0.004415,0.000891,0.022634,56.309147,2.868525,0.226344,-443.964386,0.023728,0.000000
24.110001,13.094101,-443.964386,-0.004376,0.000921,0.023389,58.245468,2.967166,0.233891,-443.964386,0.024395,0.000000
24.510000,13.297791,-444.008850,-0.004359,0.000941,0.023901,59.151527,3.013322,0.239009,-444.008850,0.025063,0.000000
24.910002,13.834747,-444.053345,-0.004337,0.000973,0.024716,61.540031,3.134999,0.247161,-444.053345,0.025721,0.000000
25.310001,14.098389,-444.097809,-0.004299,0.001001,0.025427,62.712765,3.194741,0.254269,-444.097809,0.026390,0.000000
25.710001,14.549332,-444.097809,-0.004286,0.001031,0.026182,64.718658,3.296926,0.261816,-444.097809,0.027057,0.000000
26.110001,14.295372,-444.097809,-0.004273,0.001044,0.026511,63.588989,3.239378,0.265109,-444.097809,0.027725,0.000000
26.510002,15.047195,-444.097809,-0.004238,0.001081,0.027447,66.933266,3.409743,0.274473,-444.097809,0.028393,0.000000
26.910002,15.434837,-444.142303,-0.004217,0.001110,0.028202,68.657585,3.497584,0.282020,-444.142303,0.029060,0.000000
27.310001,15.543571,-444.142303,-0.004195,0.001135,0.028827,69.141258,3.522224,0.288265,-444.142303,0.029728,0.000000
27.710001,15.804604,-444.142303,-0.004174,0.001162,0.029520,70.302391,3.581374,0.295199,-444.142303,0.030396,0.000000
28.110001,15.734970,-444.186768,-0.004143,0.001179,0.029954,69.992645,3.565595,0.299537,-444.186768,0.031055,0.000000
28.510002,15.873489,-444.186768,-0.004130,0.001201,0.030500,70.608810,3.596984,0.305002,-444.186768,0.031723,0.000000
28.910002,16.535194,-444.231262,-0.004096,0.001237,0.031411,73.552216,3.746928,0.314108,-444.231262,0.032390,0.000000
29.310001,16.702766,-444.231262,-0.004074,0.001262,0.032053,74.297615,3.784901,0.320528,-444.231262,0.033059,0.000000
29.710001,17.103806,-444.231262,-0.004057,0.001293,0.032833,76.081528,3.875778,0.328332,-444.231262,0.033726,0.000000
30.110001,16.834213,-444.231262,-0.004036,0.001307,0.033197,74.882324,3.814687,0.331973,-444.231262,0.034394,0.000000
30.510002,17.012947,-444.231262,-0.004018,0.001333,0.033857,75.677368,3.855189,0.338566,-444.231262,0.035062,0.000000
30.910002,17.661247,-444.320221,-0.003997,0.001365,0.034663,78.561150,4.002096,0.346628,-444.320221,0.035729,0.000000
31.310001,17.853767,-444.320221,-0.003967,0.001391,0.035330,79.417526,4.045722,0.353305,-444.320221,0.036397,0.000000
31.710001,18.328911,-444.275726,-0.003936,0.001421,0.036094,81.531067,4.153390,0.360935,-444.275726,0.037056,0.000000
32.110001,18.458496,-444.320221,-0.003923,0.001447,0.036745,82.107491,4.182755,0.367445,-444.320221,0.037724,0.000000
32.510002,18.620110,-444.364716,-0.003898,0.001470,0.037334,82.826385,4.219377,0.373342,-444.364716,0.038392,0.000000
32.910000,18.824539,-444.453674,-0.003876,0.001499,0.038080,83.735733,4.265701,0.380798,-444.453674,0.039059,0.000000
33.310001,18.782463,-444.453674,-0.003859,0.001521,0.038626,83.548569,4.256167,0.386264,-444.453674,0.039728,0.000000
33.710003,19.345116,-444.453674,-0.003829,0.001552,0.039433,86.051369,4.383666,0.394325,-444.453674,0.040395,0.000000
34.110001,19.325386,-444.453674,-0.003820,0.001574,0.039979,85.963608,4.379195,0.399791,-444.453674,0.041063,0.000000
34.510002,19.720467,-444.453674,-0.003811,0.001605,0.040760,87.721016,4.468721,0.407595,-444.453674,0.041731,0.000000
34.910000,19.961769,-444.498138,-0.003781,0.001631,0.041419,88.794380,4.523402,0.414189,-444.498138,0.042390,0.000000
35.310001,19.898094,-444.498138,-0.003747,0.001653,0.041991,88.511147,4.508972,0.419911,-444.498138,0.043058,0.000000
35.710003,20.197105,-444.498138,-0.003725,0.001682,0.042711,89.841209,4.576730,0.427110,-444.498138,0.043725,0.000000
36.110001,20.115189,-444.498138,-0.003691,0.001703,0.043248,89.476830,4.558167,0.432485,-444.498138,0.044393,0.000000
36.510002,21.035316,-444.498138,-0.003673,0.001741,0.044211,93.569763,4.766671,0.442114,-444.498138,0.045061,0.000000
36.910000,20.648422,-444.542633,-0.003652,0.001762,0.044758,91.848770,4.678999,0.447579,-444.542633,0.045728,0.000000
37.310001,20.975739,-444.542633,-0.003639,0.001789,0.045451,93.304749,4.753170,0.454513,-444.542633,0.046396,0.000000
37.710003,20.947067,-444.631592,-0.003613,0.001812,0.046024,93.177208,4.746674,0.460236,-444.631592,0.047064,0.000000
38.110001,20.791039,-444.587097,-0.003591,0.001831,0.046500,92.483162,4.711317,0.465005,-444.587097,0.047724,0.000000
38.510002,21.813950,-444.631592,-0.003566,0.001872,0.047541,97.033295,4.943111,0.475406,-444.631592,0.048391,0.000000
38.910004,21.481422,-444.542633,-0.003531,0.001892,0.048045,95.554138,4.867760,0.480447,-444.542633,0.049059,0.000000
39.310001,21.812462,-444.587097,-0.003527,0.001919,0.048747,97.026680,4.942774,0.487472,-444.587097,0.049727,0.000000
39.710003,21.846718,-444.676056,-0.003501,0.001940,0.049285,97.179054,4.950537,0.492846,-444.676056,0.050394,0.000000
40.110001,22.130836,-444.720551,-0.003471,0.001966,0.049934,98.442879,5.014919,0.499341,-444.720551,0.051062,0.000000
40.510002,22.637634,-444.631592,-0.003445,0.001998,0.050750,100.697227,5.129761,0.507501,-444.631592,0.051730,0.000000
40.910004,22.641731,-444.676056,-0.003423,0.002024,0.051400,100.715454,5.130690,0.513996,-444.676056,0.052397,0.000000
41.310001,22.704666,-444.720551,-0.003410,0.002047,0.051990,100.995399,5.144951,0.519901,-444.720551,0.053057,0.000000
41.710003,22.871857,-444.676056,-0.003380,0.002075,0.052693,101.739098,5.182837,0.526926,-444.676056,0.053725,0.000000
42.110001,23.570053,-444.720551,-0.003380,0.002104,0.053430,104.844833,5.341050,0.534298,-444.720551,0.054393,0.000000
42.510002,23.691826,-444.720551,-0.003341,0.002132,0.054158,105.386505,5.368645,0.541581,-444.720551,0.055060,0.000000
42.910004,23.617722,-444.809509,-0.003328,0.002153,0.054686,105.056870,5.351852,0.546864,-444.809509,0.055728,0.000000
43.310001,24.050041,-444.720551,-0.003298,0.002180,0.055381,106.979927,5.449818,0.553813,-444.720551,0.056396,0.000000
43.710003,23.715279,-444.809509,-0.003290,0.002202,0.055935,105.490829,5.373959,0.559354,-444.809509,0.057063,0.000000
44.110001,24.644722,-444.809509,-0.003277,0.002231,0.056664,109.625198,5.584574,0.566637,-444.809509,0.057731,0.000000
44.510002,24.962730,-444.809509,-0.003247,0.002260,0.057393,111.039772,5.656635,0.573934,-444.809509,0.058399,0.000000
44.910004,25.211472,-444.809509,-0.003225,0.002284,0.058008,112.146225,5.713001,0.580081,-444.809509,0.059057,0.000000
45.310001,25.750671,-444.765015,-0.003212,0.002314,0.058780,114.544708,5.835186,0.587802,-444.765015,0.059726,0.000000
45.710003,25.931641,-444.854004,-0.003182,0.002338,0.059396,115.349701,5.876194,0.593964,-444.854004,0.060394,0.000000
46.110001,26.317421,-444.854004,-0.003160,0.002365,0.060073,117.065735,5.963613,0.600731,-444.854004,0.061062,0.000000
46.510002,26.506210,-444.854004,-0.003152,0.002391,0.060732,117.905510,6.006393,0.607317,-444.854004,0.061729,0.000000
46.910004,27.002213,-444.942963,-0.003139,0.002421,0.061486,120.111839,6.118789,0.614856,-444.942963,0.062397,0.000000
47.310001,27.084137,-444.898468,-0.003117,0.002445,0.062093,120.476257,6.137353,0.620927,-444.898468,0.063065,0.000000
47.710003,27.416664,-444.898468,-0.003087,0.002470,0.062744,121.955414,6.212705,0.627437,-444.898468,0.063732,0.000000
48.110001,27.851967,-444.898468,-0.003083,0.002497,0.063411,123.891739,6.311346,0.634114,-444.898468,0.064391,0.000000
48.510002,28.088425,-444.987427,-0.003061,0.002524,0.064114,124.943550,6.364928,0.641138,-444.987427,0.065059,0.000000
48.910004,28.598206,-444.942963,-0.003053,0.002552,0.064825,127.211174,6.480446,0.648254,-444.942963,0.065726,0.000000
49.310001,27.759995,-444.987427,-0.003018,0.002563,0.065102,123.482620,6.290504,0.651025,-444.987427,0.066395,0.000000
49.710003,28.630226,-445.031921,-0.003001,0.002599,0.066012,127.353607,6.487702,0.660124,-445.031921,0.067063,0.000000
50.110001,29.572701,-445.031921,-0.002979,0.002630,0.066794,131.545944,6.701270,0.667936,-445.031921,0.067731,0.000000
50.510002,29.893684,-445.120880,-0.002971,0.002657,0.067496,132.973755,6.774005,0.674960,-445.120880,0.068398,0.000000
50.910004,30.469376,-445.031921,-0.002971,0.002684,0.068173,135.534546,6.904459,0.681728,-445.031921,0.069066,0.000000
51.310001,30.193443,-445.120880,-0.002936,0.002702,0.068641,134.307144,6.841932,0.686406,-445.120880,0.069725,0.000000
51.710003,30.058273,-445.120880,-0.002923,0.002724,0.069196,133.705872,6.811302,0.691962,-445.120880,0.070392,0.000000
52.110001,31.267365,-445.120880,-0.002910,0.002758,0.070046,139.084183,7.085286,0.700455,-445.120880,0.071060,0.000000
52.510002,31.527283,-445.165344,-0.002876,0.002781,0.070636,140.240356,7.144185,0.706360,-445.165344,0.071728,0.000000
52.910004,32.086960,-445.209839,-0.002867,0.002811,0.071399,142.729919,7.271009,0.713990,-445.209839,0.072395,0.000000
53.310001,32.486519,-445.165344,-0.002854,0.002833,0.071962,144.507248,7.361550,0.719622,-445.165344,0.073063,0.000000
53.710003,32.097015,-445.209839,-0.002837,0.002853,0.072457,142.774658,7.273288,0.724573,-445.209839,0.073732,0.000000
54.110004,33.339622,-445.254333,-0.002824,0.002886,0.073298,148.302048,7.554866,0.732975,-445.254333,0.074400,0.000000
54.510002,33.884399,-445.209839,-0.002790,0.002912,0.073974,150.725342,7.678315,0.739743,-445.209839,0.075058,0.000000
54.910004,34.708832,-445.254333,-0.002794,0.002940,0.074686,154.392593,7.865134,0.746858,-445.254333,0.075726,0.000000
55.310001,34.939331,-445.254333,-0.002781,0.002968,0.075379,155.417908,7.917366,0.753792,-445.254333,0.076394,0.000000
55.710003,34.440727,-445.254333,-0.002755,0.002985,0.075821,153.200012,7.804380,0.758213,-445.254333,0.077061,0.000000
56.110004,35.910851,-445.298798,-0.002742,0.003018,0.076654,159.739441,8.137515,0.766540,-445.298798,0.077729,0.000000
56.510002,36.329773,-445.343292,-0.002729,0.003044,0.077313,161.602905,8.232444,0.773125,-445.343292,0.078397,0.000000
56.910004,37.299057,-445.343292,-0.002712,0.003074,0.078085,165.914490,8.452087,0.780847,-445.343292,0.079064,0.000000
57.310001,37.856125,-445.387756,-0.002699,0.003100,0.078743,168.392456,8.578321,0.787432,-445.387756,0.079732,0.000000
57.710003,37.503487,-445.387756,-0.002695,0.003123,0.079334,166.823837,8.498412,0.793337,-445.387756,0.080401,0.000000
58.110004,38.734177,-445.387756,-0.002656,0.003152,0.080062,172.298218,8.777289,0.800619,-445.387756,0.081060,0.000000
58.510002,39.172462,-445.387756,-0.002652,0.003178,0.080713,174.247818,8.876607,0.807129,-445.387756,0.081727,0.000000
58.910004,39.899330,-445.432251,-0.002634,0.003207,0.081450,177.481079,9.041317,0.814502,-445.432251,0.082395,0.000000
59.310001,40.079559,-445.432251,-0.002634,0.003228,0.081979,178.282791,9.082158,0.819786,-445.432251,0.083063,0.000000
59.710003,41.399254,-445.476715,-0.002604,0.003263,0.082872,184.153076,9.381205,0.828718,-445.476715,0.083730,0.000000
60.110004,41.525108,-445.476715,-0.002604,0.003284,0.083402,184.712906,9.409724,0.834017,-445.476715,0.084398,0.000000
60.510002,41.992813,-445.476715,-0.002583,0.003310,0.084077,186.793365,9.515708,0.840769,-445.476715,0.085066,0.000000
60.910004,42.989281,-445.521210,-0.002565,0.003336,0.084737,191.225876,9.741510,0.847370,-445.521210,0.085733,0.000000
61.310001,43.045509,-445.521210,-0.002552,0.003356,0.085231,191.475983,9.754252,0.852305,-445.521210,0.086393,0.000000
61.710003,44.772202,-445.565674,-0.002539,0.003393,0.086177,199.156693,10.145526,0.861768,-445.565674,0.087061,0.000000
62.110004,44.744644,-445.610168,-0.002535,0.003414,0.086705,199.034119,10.139281,0.867051,-445.610168,0.087729,0.000000
62.510002,45.494972,-445.610168,-0.002518,0.003440,0.087364,202.371750,10.309308,0.873637,-445.610168,0.088396,0.000000
62.910004,46.264671,-445.565674,-0.002509,0.003467,0.088050,205.795532,10.483725,0.880495,-445.565674,0.089064,0.000000
63.310001,46.866425,-445.610168,-0.002483,0.003489,0.088631,208.472275,10.620084,0.886309,-445.610168,0.089732,0.000000
63.710003,48.215157,-445.610168,-0.002470,0.003521,0.089429,214.471725,10.925711,0.894287,-445.610168,0.090399,0.000000
64.110001,48.415123,-445.610168,-0.002470,0.003545,0.090036,215.361221,10.971024,0.900358,-445.610168,0.091067,0.000000
64.510002,49.281258,-445.654663,-0.002436,0.003572,0.090720,219.213989,11.167293,0.907201,-445.654663,0.091727,0.000000
64.910004,49.800346,-445.699127,-0.002436,0.003593,0.091267,221.523010,11.284920,0.912667,-445.699127,0.092395,0.000000
65.310005,49.974617,-445.699127,-0.002436,0.003614,0.091804,222.298203,11.324409,0.918041,-445.699127,0.093062,0.000000
65.710007,51.353508,-445.654663,-0.002410,0.003647,0.092628,228.431808,11.636870,0.926277,-445.654663,0.093730,0.000000
66.110001,52.691818,-445.699127,-0.002393,0.003677,0.093383,234.384918,11.940137,0.933832,-445.699127,0.094398,0.000000
66.510002,53.490929,-445.699127,-0.002384,0.003704,0.094093,237.939529,12.121218,0.940932,-445.699127,0.095065,0.000000
66.910004,53.778397,-445.699127,-0.002384,0.003723,0.094553,239.218262,12.186359,0.945535,-445.699127,0.095733,0.000000
67.310005,53.988045,-445.743622,-0.002358,0.003746,0.095151,240.150818,12.233866,0.951515,-445.743622,0.096401,0.000000
67.710007,55.978752,-445.743622,-0.002363,0.003781,0.096037,249.005920,12.684966,0.960372,-445.743622,0.097059,0.000000
68.110001,56.732430,-445.832581,-0.002337,0.003806,0.096661,252.358444,12.855752,0.966609,-445.832581,0.097728,0.000000
68.510002,57.846939,-445.788086,-0.002337,0.003835,0.097398,257.316040,13.108303,0.973982,-445.788086,0.098396,0.000000
68.910004,58.336609,-445.832581,-0.002311,0.003856,0.097945,259.494202,13.219264,0.979448,-445.832581,0.099064,0.000000
69.310005,60.207039,-445.877045,-0.002302,0.003888,0.098759,267.814270,13.643110,0.987593,-445.877045,0.099731,0.000000
69.710007,61.027748,-445.877045,-0.002281,0.003914,0.099410,271.464996,13.829086,0.994103,-445.877045,0.100399,0.000000
70.110001,61.954208,-445.832581,-0.002276,0.003941,0.100104,275.586090,14.039024,1.001037,-445.832581,0.101067,0.000000
70.510002,63.214691,-445.921539,-0.002255,0.003968,0.100797,281.192993,14.324654,1.007971,-445.921539,0.101734,0.000000
70.910004,64.068161,-445.921539,-0.002255,0.003991,0.101362,284.989410,14.518053,1.013618,-445.921539,0.102393,0.000000
71.310005,65.598618,-445.921539,-0.002242,0.004021,0.102132,291.797211,14.864860,1.021324,-445.921539,0.103060,0.000000
71.710007,66.286392,-445.921539,-0.002225,0.004039,0.102584,294.856598,15.020711,1.025835,-445.921539,0.103711,0.000000
72.110001,64.555969,-445.966003,-0.002225,0.004033,0.102446,287.159302,14.628592,1.024458,-445.966003,294.500458,0.000000
72.510002,65.498444,-445.966003,-0.002182,0.004011,0.101873,291.351624,14.842159,1.018735,-445.966003,294.500458,0.000000
72.910004,65.644043,-446.010498,-0.002190,0.004076,0.103521,291.999298,14.875153,1.035207,-446.010498,294.500458,0.000000
73.310005,65.332367,-446.010498,-0.002182,0.004082,0.103695,290.612885,14.804526,1.036948,-446.010498,294.500458,0.000000
73.710007,65.266464,-446.010498,-0.002177,0.004093,0.103963,290.319733,14.789592,1.039627,-446.010498,294.500458,0.000000
74.110001,65.038574,-446.054962,-0.002177,0.004102,0.104197,289.306030,14.737952,1.041974,-446.054962,294.500458,0.000000
74.510002,66.148239,-446.099457,-0.002164,0.004115,0.104509,294.242065,14.989405,1.045093,-446.099457,294.500458,0.000000
74.910004,65.039322,-446.099457,-0.002156,0.004119,0.104621,289.309357,14.738121,1.046213,-446.099457,294.500458,0.000000
75.310005,65.856674,-446.054962,-0.002147,0.004138,0.105098,292.945129,14.923336,1.050982,-446.054962,294.500458,0.000000
75.710007,65.032990,-446.143951,-0.002151,0.004138,0.105116,289.281189,14.736687,1.051164,-446.143951,294.500458,0.000000
76.110001,65.386734,-446.099457,-0.002156,0.004150,0.105419,290.854706,14.816845,1.054192,-446.099457,294.500458,0.000000
76.510002,65.222153,-446.099457,-0.002134,0.004157,0.105584,290.122620,14.779552,1.055842,-446.099457,294.500458,0.000000
76.910004,65.044159,-446.188416,-0.002130,0.004163,0.105749,289.330872,14.739217,1.057492,-446.188416,294.500458,0.000000
77.310005,65.155869,-446.188416,-0.002130,0.004171,0.105940,289.827789,14.764531,1.059400,-446.188416,294.500458,0.000000
77.710007,65.076920,-446.143951,-0.002134,0.004178,0.106114,289.476593,14.746641,1.061141,-446.143951,294.500458,0.000000
78.110001,65.258270,-446.232910,-0.002134,0.004185,0.106287,290.283295,14.787735,1.062867,-446.232910,294.500458,0.000000
78.510002,65.063889,-446.277374,-0.002126,0.004189,0.106391,289.418640,14.743688,1.063911,-446.277374,294.500458,0.000000
78.910004,65.353226,-446.232910,-0.002113,0.004197,0.106608,290.705658,14.809253,1.066076,-446.232910,294.500458,0.000000
79.310005,65.281723,-446.277374,-0.002121,0.004207,0.106851,290.387604,14.793050,1.068514,-446.277374,294.500458,0.000000
79.710007,65.330139,-446.188416,-0.002104,0.004207,0.106851,290.602966,14.804021,1.068514,-446.188416,294.500458,0.000000
80.110001,65.246353,-446.321869,-0.002100,0.004211,0.106963,290.230286,14.785034,1.069634,-446.321869,294.500458,0.000000
80.510002,65.278381,-446.321869,-0.002087,0.004221,0.107206,290.372742,14.792293,1.072056,-446.321869,294.500458,0.000000
80.910004,65.367371,-446.321869,-0.002100,0.004221,0.107215,290.768585,14.812458,1.072147,-446.321869,294.500458,0.000000
81.310005,65.191620,-446.277374,-0.002082,0.004224,0.107293,289.986816,14.772633,1.072935,-446.277374,294.500458,0.000000
81.710007,65.156235,-446.366333,-0.002095,0.004229,0.107415,289.829407,14.764614,1.074146,-446.366333,294.500458,0.000000
82.110001,65.037460,-446.410828,-0.002070,0.004231,0.107466,289.301086,14.737700,1.074660,-446.410828,294.500458,0.000000
82.510002,65.772141,-446.366333,-0.002070,0.004242,0.107752,292.569092,14.904180,1.077522,-446.366333,294.500458,0.000000
82.910004,65.520798,-446.366333,-0.002074,0.004242,0.107752,291.451050,14.847225,1.077522,-446.366333,294.500458,0.000000
83.310005,65.233322,-446.366333,-0.002082,0.004243,0.107770,290.172302,14.782083,1.077703,-446.366333,294.500458,0.000000
83.710007,64.983093,-446.410828,-0.002074,0.004245,0.107822,289.059235,14.725379,1.078218,-446.410828,294.500458,0.000000
84.110001,64.854248,-446.410828,-0.002082,0.004247,0.107866,288.486115,14.696182,1.078657,-446.410828,294.500458,0.000000
84.510002,65.598999,-446.410828,-0.002074,0.004258,0.108143,291.798920,14.864945,1.081428,-446.410828,294.500458,0.000000
84.910004,65.359558,-446.499786,-0.002065,0.004258,0.108143,290.733826,14.810687,1.081428,-446.499786,294.500458,0.000000
85.310005,65.126450,-446.455292,-0.002057,0.004259,0.108178,289.696930,14.757865,1.081776,-446.455292,294.500458,0.000000
85.710007,65.301468,-446.455292,-0.002065,0.004264,0.108299,290.475433,14.797524,1.082987,-446.455292,294.500458,0.000000
86.110001,65.162949,-446.499786,-0.002070,0.004266,0.108352,289.859283,14.766135,1.083517,-446.499786,294.500458,0.000000
86.510002,65.111923,-446.499786,-0.002044,0.004268,0.108412,289.632294,14.754573,1.084123,-446.499786,294.500458,0.000000
86.910004,65.145447,-446.588745,-0.002048,0.004271,0.108489,289.781433,14.762170,1.084895,-446.588745,294.500458,0.000000
87.310005,65.189377,-446.499786,-0.002044,0.004275,0.108576,289.976837,14.772124,1.085758,-446.499786,294.500458,0.000000
87.710007,65.040802,-446.544281,-0.002057,0.004276,0.108603,289.315948,14.738456,1.086030,-446.544281,294.500458,0.000000
88.110001,65.122360,-446.588745,-0.002039,0.004278,0.108664,289.678711,14.756938,1.086636,-446.588745,294.500458,0.000000
88.510002,65.064270,-446.588745,-0.002057,0.004280,0.108724,289.420319,14.743774,1.087241,-446.588745,294.500458,0.000000
88.910004,64.994263,-446.544281,-0.002039,0.004283,0.108794,289.108917,14.727910,1.087938,-446.544281,294.500458,0.000000
89.310005,65.038574,-446.588745,-0.002052,0.004285,0.108836,289.306030,14.737952,1.088362,-446.588745,294.500458,0.000000
89.710007,65.364777,-446.633240,-0.002052,0.004290,0.108966,290.757050,14.811871,1.089664,-446.633240,294.500458,0.000000
90.110001,65.217682,-446.677704,-0.002035,0.004290,0.108966,290.102753,14.778538,1.089664,-446.677704,294.500458,0.000000
90.510002,65.051971,-446.677704,-0.002035,0.004290,0.108975,289.365631,14.740987,1.089755,-446.677704,294.500458,0.000000
90.910004,65.415039,-446.722198,-0.002026,0.004297,0.109150,290.980621,14.823260,1.091496,-446.722198,294.500458,0.000000
91.310005,65.294769,-446.677704,-0.002048,0.004297,0.109150,290.445648,14.796006,1.091496,-446.677704,294.500458,0.000000
91.710007,65.128311,-446.677704,-0.002031,0.004297,0.109150,289.705200,14.758286,1.091496,-446.677704,294.500458,0.000000
92.110001,65.245239,-446.766663,-0.002026,0.004302,0.109262,290.225311,14.784782,1.092616,-446.766663,294.500458,0.000000
92.510002,65.151779,-446.677704,-0.002048,0.004302,0.109262,289.809601,14.763604,1.092616,-446.677704,294.500458,0.000000
92.910004,65.077667,-446.766663,-0.002026,0.004304,0.109313,289.479919,14.746810,1.093131,-446.766663,294.500458,0.000000
93.310005,65.123474,-446.722198,-0.002035,0.004306,0.109374,289.683685,14.757190,1.093736,-446.722198,294.500458,0.000000
93.710007,65.089966,-446.766663,-0.002031,0.004307,0.109408,289.534637,14.749597,1.094085,-446.766663,294.500458,0.000000
94.110008,65.079910,-446.766663,-0.002031,0.004309,0.109443,289.489899,14.747318,1.094433,-446.766663,294.500458,0.000000
94.510002,65.049744,-446.855621,-0.002031,0.004310,0.109469,289.355713,14.740482,1.094690,-446.855621,294.500458,0.000000
94.910004,65.020691,-446.766663,-0.002026,0.004311,0.109504,289.226471,14.733899,1.095038,-446.766663,294.500458,0.000000
95.310005,64.981964,-446.900116,-0.002026,0.004312,0.109531,289.054199,14.725123,1.095311,-446.900116,294.500458,0.000000
95.710007,65.012878,-446.855621,-0.002022,0.004314,0.109583,289.191711,14.732129,1.095826,-446.855621,294.500458,0.000000
96.110008,65.010651,-446.811157,-0.002022,0.004316,0.109617,289.181824,14.731625,1.096174,-446.811157,294.500458,0.000000
96.510002,64.964462,-446.900116,-0.002018,0.004317,0.109643,288.976349,14.721158,1.096431,-446.900116,294.500458,0.000000
96.910004,64.981232,-446.900116,-0.002013,0.004319,0.109695,289.050964,14.724958,1.096946,-446.900116,294.500458,0.000000
97.310005,64.943619,-446.944611,-0.002026,0.004319,0.109704,288.883636,14.716434,1.097037,-446.944611,294.500458,0.000000
97.710007,64.842697,-446.944611,-0.002001,0.004319,0.109713,288.434723,14.693565,1.097128,-446.944611,294.500458,0.000000
98.110008,65.467178,-446.944611,-0.002009,0.004327,0.109904,291.212555,14.835074,1.099035,-446.944611,294.500458,0.000000
98.510002,65.362915,-446.944611,-0.002005,0.004327,0.109904,290.748779,14.811448,1.099035,-446.944611,294.500458,0.000000
98.910004,65.273163,-446.989075,-0.002009,0.004327,0.109904,290.349518,14.791110,1.099035,-446.989075,294.500458,0.000000
99.310005,65.186783,-447.033569,-0.001996,0.004327,0.109904,289.965302,14.771536,1.099035,-447.033569,294.500458,0.000000
99.710007,65.078781,-447.033569,-0.002009,0.004329,0.109947,289.484863,14.747063,1.099474,-447.033569,294.500458,0.000000
100.110008,65.095169,-447.033569,-0.002009,0.004330,0.109973,289.557770,14.750776,1.099732,-447.033569,294.500458,0.000000
100.510002,65.019577,-447.033569,-0.002001,0.004330,0.109973,289.221527,14.733647,1.099732,-447.033569,294.500458,0.000000
100.910004,65.679047,-447.033569,-0.001996,0.004338,0.110190,292.154999,14.883085,1.101897,-447.033569,294.500458,0.000000
101.310005,65.615005,-447.122528,-0.002009,0.004338,0.110190,291.870117,14.868573,1.101897,-447.122528,294.500458,0.000000
101.710007,65.565475,-447.122528,-0.002013,0.004338,0.110190,291.649811,14.857348,1.101897,-447.122528,294.500458,0.000000
102.110008,65.478714,-447.122528,-0.001992,0.004338,0.110190,291.263855,14.837688,1.101897,-447.122528,294.500458,0.000000
102.510002,65.353592,-447.166992,-0.001996,0.004338,0.110190,290.707306,14.809336,1.101897,-447.166992,294.500458,0.000000
102.910004,65.285828,-447.122528,-0.001996,0.004339,0.110199,290.405853,14.793981,1.101987,-447.122528,294.500458,0.000000
103.310005,65.178589,-447.122528,-0.002005,0.004339,0.110199,289.928833,14.769679,1.101987,-447.122528,294.500458,0.000000
103.710007,65.100754,-447.166992,-0.001996,0.004339,0.110215,289.582611,14.752042,1.102154,-447.166992,294.500458,0.000000
104.110008,65.258636,-447.211487,-0.001996,0.004343,0.110311,290.284912,14.787818,1.103108,-447.211487,294.500458,0.000000
104.510002,65.228485,-447.211487,-0.001988,0.004343,0.110311,290.150787,14.780987,1.103108,-447.211487,294.500458,0.000000
104.910004,65.157364,-447.255951,-0.001996,0.004343,0.110311,289.834442,14.764870,1.103108,-447.255951,294.500458,0.000000
105.310005,65.311523,-447.211487,-0.001996,0.004347,0.110415,290.520172,14.799802,1.104152,-447.211487,294.500458,0.000000
105.710007,65.324188,-447.300446,-0.001992,0.004347,0.110415,290.576508,14.802672,1.104152,-447.300446,294.500458,0.000000
106.110008,65.295883,-447.255951,-0.001996,0.004347,0.110415,290.450592,14.796259,1.104152,-447.255951,294.500458,0.000000
106.510002,65.226242,-447.300446,-0.001996,0.004347,0.110415,290.140808,14.780478,1.104152,-447.300446,294.500458,0.000000
106.910004,65.272797,-447.300446,-0.001988,0.004350,0.110485,290.347900,14.791027,1.104849,-447.300446,294.500458,0.000000
107.310005,65.269440,-447.344910,-0.001988,0.004350,0.110485,290.332977,14.790266,1.104849,-447.344910,294.500458,0.000000
107.710007,65.206512,-447.300446,-0.001992,0.004350,0.110485,290.053040,14.776007,1.104849,-447.300446,294.500458,0.000000
108.110008,65.105591,-447.344910,-0.001983,0.004350,0.110485,289.604126,14.753138,1.104849,-447.344910,294.500458,0.000000
108.510002,65.218430,-447.344910,-0.001983,0.004353,0.110555,290.106049,14.778708,1.105545,-447.344910,294.500458,0.000000
108.910004,65.175980,-447.389404,-0.001979,0.004353,0.110555,289.917236,14.769088,1.105545,-447.389404,294.500458,0.000000
109.310005,65.116028,-447.433899,-0.001979,0.004353,0.110555,289.650543,14.755503,1.105545,-447.433899,294.500458,0.000000
109.710007,65.047501,-447.389404,-0.001992,0.004353,0.110555,289.345734,14.739974,1.105545,-447.389404,294.500458,0.000000
110.110008,65.155869,-447.478363,-0.001975,0.004355,0.110623,289.827789,14.764531,1.106226,-447.478363,294.500458,0.000000
110.510002,65.132782,-447.478363,-0.001975,0.004355,0.110623,289.725098,14.759299,1.106226,-447.478363,294.500458,0.000000
110.910004,65.070602,-447.478363,-0.001983,0.004355,0.110623,289.448486,14.745210,1.106226,-447.478363,294.500458,0.000000
111.310005,65.016968,-447.522858,-0.001983,0.004356,0.110641,289.209930,14.733055,1.106408,-447.522858,294.500458,0.000000
111.710007,64.968185,-447.522858,-0.001988,0.004356,0.110641,288.992920,14.722001,1.106408,-447.522858,294.500458,0.000000
112.110008,64.916428,-447.567322,-0.001975,0.004356,0.110641,288.762695,14.710273,1.106408,-447.567322,294.500458,0.000000
112.510002,64.891113,-447.567322,-0.001983,0.004357,0.110667,288.650085,14.704536,1.106665,-447.567322,294.500458,0.000000
112.910004,64.852386,-447.567322,-0.001988,0.004357,0.110676,288.477814,14.695761,1.106756,-447.567322,294.500458,0.000000
113.310005,64.814774,-447.611816,-0.001979,0.004358,0.110683,288.310516,14.687238,1.106832,-447.611816,294.500458,0.000000
113.710007,64.773437,-447.656281,-0.001983,0.004358,0.110683,288.126648,14.677870,1.106832,-447.656281,294.500458,0.000000
114.110008,64.716476,-447.611816,-0.001988,0.004358,0.110683,287.873260,14.664964,1.106832,-447.611816,294.500458,0.000000
114.510002,65.838806,-447.611816,-0.001983,0.004370,0.110987,292.865631,14.919287,1.109875,-447.611816,294.500458,0.000000
114.910004,65.832474,-447.656281,-0.001970,0.004370,0.110987,292.837463,14.917851,1.109875,-447.656281,294.500458,0.000000
115.310005,65.787033,-447.656281,-0.001983,0.004370,0.110987,292.635345,14.907555,1.109875,-447.656281,294.500458,0.000000
115.710007,65.756134,-447.700775,-0.001970,0.004370,0.110987,292.497894,14.900553,1.109875,-447.700775,294.500458,0.000000
116.110008,65.670120,-447.700775,-0.001975,0.004370,0.110987,292.115295,14.881063,1.109875,-447.700775,294.500458,0.000000
116.510002,65.609421,-447.745239,-0.001970,0.004370,0.110987,291.845276,14.867308,1.109875,-447.745239,294.500458,0.000000
116.910004,65.555054,-447.745239,-0.001979,0.004370,0.110987,291.603455,14.854987,1.109875,-447.745239,294.500458,0.000000
117.310005,65.507385,-447.745239,-0.001966,0.004370,0.110987,291.391388,14.844186,1.109875,-447.745239,294.500458,0.000000
117.710007,65.457489,-447.745239,-0.001966,0.004370,0.110987,291.169464,14.832879,1.109875,-447.745239,294.500458,0.000000
118.110008,65.374451,-447.789734,-0.001966,0.004370,0.110987,290.800079,14.814062,1.109875,-447.789734,294.500458,0.000000
118.510002,65.315994,-447.834229,-0.001970,0.004370,0.110987,290.540039,14.800816,1.109875,-447.834229,294.500458,0.000000
118.910004,65.273544,-447.789734,-0.001975,0.004370,0.110997,290.351227,14.791197,1.109966,-447.789734,294.500458,0.000000
119.310005,65.223267,-447.878693,-0.001962,0.004370,0.110997,290.127594,14.779803,1.109966,-447.878693,294.500458,0.000000
119.710007,65.145813,-447.878693,-0.001970,0.004370,0.110997,289.783051,14.762252,1.109966,-447.878693,294.500458,0.000000
120.110008,65.079529,-447.923187,-0.001970,0.004370,0.110997,289.488190,14.747232,1.109966,-447.923187,294.500458,0.000000
120.510002,65.028885,-447.878693,-0.001966,0.004370,0.110997,289.262939,14.735756,1.109966,-447.878693,294.500458,0.000000
120.910004,64.975266,-447.923187,-0.001970,0.004370,0.110997,289.024414,14.723605,1.109966,-447.923187,294.500458,0.000000
121.310005,64.914200,-447.967651,-0.001970,0.004370,0.110997,288.752777,14.709768,1.109966,-447.967651,294.500458,0.000000
121.710007,64.835251,-447.967651,-0.001966,0.004370,0.110997,288.401611,14.691878,1.109966,-447.967651,294.500458,0.000000
122.110008,64.925003,-448.012146,-0.001970,0.004373,0.111065,288.800842,14.712215,1.110647,-448.012146,294.500458,0.000000
122.510002,64.899307,-447.967651,-0.001983,0.004373,0.111065,288.686523,14.706393,1.110647,-447.967651,294.500458,0.000000
122.910004,64.866531,-448.056610,-0.001957,0.004373,0.111074,288.540741,14.698966,1.110738,-448.056610,294.500458,0.000000
123.310005,64.923141,-448.012146,-0.001979,0.004375,0.111118,288.792542,14.711794,1.111177,-448.012146,294.500458,0.000000
123.710007,64.912704,-448.056610,-0.001966,0.004375,0.111118,288.746124,14.709429,1.111177,-448.056610,294.500458,0.000000
124.110008,64.862061,-448.056610,-0.001966,0.004375,0.111118,288.520844,14.697952,1.111177,-448.056610,294.500458,0.000000
124.510002,64.853134,-448.056610,-0.001966,0.004375,0.111127,288.481140,14.695930,1.111268,-448.056610,294.500458,0.000000
124.910004,64.827438,-448.101105,-0.001970,0.004375,0.111134,288.366852,14.690108,1.111344,-448.101105,294.500458,0.000000
125.310005,64.786102,-448.101105,-0.001957,0.004376,0.111143,288.182983,14.680740,1.111434,-448.101105,294.500458,0.000000
125.710007,64.772690,-448.101105,-0.001970,0.004376,0.111143,288.123322,14.677702,1.111434,-448.101105,294.500458,0.000000
126.110008,64.724655,-448.145569,-0.001975,0.004376,0.111143,287.909637,14.666817,1.111434,-448.145569,294.500458,0.000000
126.510010,64.695618,-448.145569,-0.001975,0.004376,0.111143,287.780487,14.660236,1.111434,-448.145569,294.500458,0.000000
126.910004,64.655396,-448.145569,-0.001962,0.004376,0.111153,287.601562,14.651122,1.111525,-448.145569,294.500458,0.000000
127.310005,65.970627,-448.101105,-0.001962,0.004391,0.111543,293.451996,14.949158,1.115431,-448.101105,294.500458,0.000000
127.710007,65.902100,-448.234558,-0.001970,0.004387,0.111430,293.147186,14.933629,1.114296,-448.234558,294.500458,0.000000
128.110001,65.871948,-448.279022,-0.001962,0.004387,0.111430,293.013062,14.926797,1.114296,-448.279022,294.500458,0.000000
128.510010,65.810867,-448.234558,-0.001966,0.004387,0.111430,292.741364,14.912956,1.114296,-448.234558,294.500458,0.000000
128.910004,65.763214,-448.279022,-0.001966,0.004387,0.111430,292.529388,14.902158,1.114296,-448.279022,294.500458,0.000000
129.310013,65.687241,-448.279022,-0.001970,0.004387,0.111430,292.191437,14.884942,1.114296,-448.279022,294.500458,0.000000
129.710007,65.650375,-448.234558,-0.001966,0.004387,0.111430,292.027466,14.876588,1.114296,-448.234558,294.500458,0.000000
130.110001,65.588943,-448.279022,-0.001962,0.004387,0.111430,291.754181,14.862667,1.114296,-448.279022,294.500458,0.000000
130.510010,65.552444,-448.279022,-0.001970,0.004387,0.111430,291.591827,14.854396,1.114296,-448.279022,294.500458,0.000000
130.910004,65.520050,-448.367981,-0.001966,0.004387,0.111439,291.447723,14.847055,1.114387,-448.367981,294.500458,0.000000
131.310013,65.476105,-448.367981,-0.001962,0.004387,0.111439,291.252258,14.837097,1.114387,-448.367981,294.500458,0.000000
131.710007,65.416901,-448.279022,-0.001966,0.004387,0.111439,290.988922,14.823681,1.114387,-448.279022,294.500458,0.000000
132.110001,65.353226,-448.323517,-0.001953,0.004387,0.111439,290.705658,14.809253,1.114387,-448.323517,294.500458,0.000000
132.510010,65.306686,-448.412476,-0.001970,0.004386,0.111413,290.498657,14.798706,1.114129,-448.412476,0.111378,0.000000
132.910004,65.167419,-448.412476,-0.001944,0.004368,0.110936,289.879150,14.767148,1.109360,-448.412476,0.110710,0.000000
133.310013,65.138733,-448.456940,-0.001962,0.004345,0.110362,289.751556,14.760648,1.103622,-448.456940,0.110043,0.000000
133.710007,65.044907,-448.412476,-0.001953,0.004320,0.109729,289.334198,14.739387,1.097294,-448.412476,0.109374,0.000000
134.110001,64.937286,-448.456940,-0.001940,0.004299,0.109183,288.855469,14.714999,1.091829,-448.456940,0.108706,0.000000
134.510010,64.897812,-448.501434,-0.001949,0.004273,0.108542,288.679871,14.706054,1.085425,-448.501434,0.108038,0.000000
134.910004,64.871368,-448.456940,-0.001953,0.004251,0.107970,288.562256,14.700063,1.079702,-448.456940,0.107380,0.000000
135.310013,64.790939,-448.501434,-0.001944,0.004218,0.107138,288.204498,14.681837,1.071375,-448.501434,0.106712,0.000000
135.710007,64.731369,-448.501434,-0.001953,0.004198,0.106633,287.939514,14.668338,1.066334,-448.501434,0.106044,0.000000
136.110001,64.600662,-448.545898,-0.001940,0.004167,0.105836,287.358093,14.638720,1.058355,-448.545898,0.105377,0.000000
136.510010,64.355270,-448.545898,-0.001953,0.004143,0.105228,286.266541,14.583113,1.052284,-448.545898,0.104709,0.000000
136.910004,63.935608,-448.590393,-0.001936,0.004123,0.104735,284.399780,14.488016,1.047349,-448.590393,0.104041,0.000000
137.310013,62.784225,-448.590393,-0.001944,0.004092,0.103928,279.278198,14.227109,1.039279,-448.590393,0.103374,0.000000
137.710007,61.747917,-448.590393,-0.001932,0.004072,0.103425,274.668457,13.992278,1.034253,-448.590393,0.102705,0.000000
138.110001,60.270340,-448.634857,-0.001914,0.004049,0.102844,268.095856,13.657454,1.028439,-448.634857,0.102046,0.000000
138.510010,59.072044,-448.590393,-0.001914,0.004034,0.102453,262.765564,13.385917,1.024533,-448.590393,0.101378,0.000000
138.910004,56.616997,-448.634857,-0.001897,0.004001,0.101630,251.844986,12.829596,1.016297,-448.634857,0.100711,0.000000
139.310013,53.937775,-448.634857,-0.001906,0.003970,0.100841,239.927200,12.222475,1.008410,-448.634857,0.100043,0.000000
139.710007,52.001808,-448.679352,-0.001906,0.003950,0.100329,231.315598,11.783778,1.003292,-448.679352,0.099375,0.000000
140.110001,49.198967,-448.679352,-0.001910,0.003921,0.099601,218.847931,11.148645,0.996010,-448.679352,0.098708,0.000000
140.510010,47.267838,-448.723846,-0.001906,0.003905,0.099194,210.257843,10.711045,0.991938,-448.723846,0.098040,0.000000
140.910004,44.016281,-448.723846,-0.001910,0.003876,0.098438,195.794205,9.974233,0.984383,-448.723846,0.097372,0.000000
141.310013,40.636261,-448.723846,-0.001919,0.003846,0.097693,180.759109,9.208308,0.976934,-448.723846,0.096712,0.000000
141.710007,38.513367,-448.723846,-0.001910,0.003823,0.097103,171.316010,8.727254,0.971030,-448.723846,0.096045,0.000000
142.110001,34.905823,-448.768311,-0.001906,0.003792,0.096323,155.268860,7.909772,0.963233,-448.768311,0.095377,0.000000
142.510010,33.037628,-448.768311,-0.001914,0.003774,0.095854,146.958710,7.486434,0.958540,-448.768311,0.094709,0.000000
142.910004,29.901131,-448.768311,-0.001910,0.003744,0.095109,133.006866,6.775693,0.951091,-448.768311,0.094042,0.000000
143.310013,26.538612,-448.768311,-0.001910,0.003713,0.094311,118.049644,6.013736,0.943113,-448.768311,0.093374,0.000000
143.710007,24.138298,-448.812805,-0.001901,0.003692,0.093772,107.372513,5.469817,0.937723,-448.812805,0.092706,0.000000
144.110001,21.659042,-448.768311,-0.001906,0.003666,0.093105,96.344231,4.908009,0.931046,-448.768311,0.092039,0.000000
144.510010,17.959145,-448.812805,-0.001914,0.003635,0.092325,79.886269,4.069601,0.923249,-448.812805,0.091371,0.000000
144.910004,15.836624,-448.857269,-0.001906,0.003615,0.091822,70.444824,3.588630,0.918223,-448.857269,0.090711,0.000000
145.310013,12.164291,-448.857269,-0.001910,0.003580,0.090929,54.109470,2.756468,0.909291,-448.857269,0.090043,0.000000
145.710007,10.449516,-448.857269,-0.001893,0.003565,0.090555,46.481770,2.367894,0.905551,-448.857269,0.089376,0.000000
146.110001,7.143593,-448.901764,-0.001910,0.003534,0.089775,31.776287,1.618761,0.897754,-448.901764,0.088708,0.000000
146.510010,4.820732,-448.812805,-0.001901,0.003511,0.089176,21.443687,1.092394,0.891759,-448.812805,0.088040,0.000000
146.910004,2.195503,-448.946228,-0.001906,0.003485,0.088517,9.766087,0.497508,0.885173,-448.946228,0.087373,0.000000
147.310013,-1.111164,-448.946228,-0.001910,0.003450,0.087624,-4.942705,-0.251793,0.876241,-448.946228,0.086705,0.000000
147.710007,-2.947704,-448.990723,-0.001910,0.003426,0.087017,-13.112043,-0.667959,0.870170,-448.990723,0.086037,0.000000
148.110001,-0.268112,-448.946228,-0.001910,0.003399,0.086340,-1.192623,-0.060755,0.863403,-448.946228,0.085379,0.000000
148.510010,-0.076714,-449.035187,-0.001906,0.003375,0.085717,-0.341239,-0.017384,0.857165,-449.035187,0.084710,0.000000
148.910004,0.025322,-448.990723,-0.001910,0.003355,0.085221,0.112638,0.005738,0.852215,-448.990723,0.084042,0.000000
149.310013,0.055481,-448.990723,-0.001919,0.003321,0.084363,0.246792,0.012572,0.843630,-448.990723,0.083374,0.000000
149.710007,0.026062,-449.079681,-0.001901,0.003298,0.083774,0.115930,0.005906,0.837741,-449.079681,0.082707,0.000000
150.110001,0.067024,-449.035187,-0.001906,0.003286,0.083453,0.298139,0.015188,0.834531,-449.035187,0.082039,0.000000
150.510010,-0.020111,-449.124176,-0.001906,0.003242,0.082351,-0.089459,-0.004557,0.823510,-449.124176,0.081371,0.000000
150.910004,0.005959,-449.124176,-0.001906,0.003209,0.081502,0.026505,0.001350,0.815017,-449.124176,0.080704,0.000000
151.310013,0.001114,-449.124176,-0.001914,0.003191,0.081041,0.004955,0.000252,0.810414,-449.124176,0.080045,0.000000
151.710007,0.001862,-449.168640,-0.001901,0.003169,0.080487,0.008281,0.000422,0.804873,-449.168640,0.079378,0.000000
152.110001,-0.028305,-449.124176,-0.001906,0.003139,0.079741,-0.125907,-0.006414,0.797409,-449.124176,0.078710,0.000000
152.510010,-0.031654,-449.168640,-0.001914,0.003115,0.079117,-0.140806,-0.007173,0.791172,-449.168640,0.078041,0.000000
152.910004,-0.032028,-449.124176,-0.001910,0.003082,0.078284,-0.142469,-0.007258,0.782845,-449.124176,0.077373,0.000000
153.310013,-0.060326,-449.124176,-0.001923,0.003061,0.077738,-0.268342,-0.013670,0.777380,-449.124176,0.076705,0.000000
153.710007,-0.043198,-449.213135,-0.001919,0.003044,0.077313,-0.192153,-0.009789,0.773125,-449.213135,0.076038,0.000000
154.110001,-0.046547,-449.168640,-0.001923,0.003021,0.076733,-0.207051,-0.010548,0.767327,-449.168640,0.075370,0.000000
154.510010,-0.048782,-449.257599,-0.001919,0.002983,0.075770,-0.216995,-0.011054,0.757698,-449.257599,0.074712,0.000000
154.910004,-0.043571,-449.257599,-0.001940,0.002952,0.074989,-0.193816,-0.009873,0.749886,-449.257599,0.074044,0.000000
155.310013,-0.051765,-449.257599,-0.001927,0.002928,0.074382,-0.230264,-0.011730,0.743815,-449.257599,0.073376,0.000000
155.710007,-0.049904,-449.213135,-0.001932,0.002901,0.073688,-0.221983,-0.011308,0.736881,-449.213135,0.072709,0.000000
156.110001,-0.088631,-449.302094,-0.001944,0.002876,0.073046,-0.394249,-0.020084,0.730462,-449.302094,0.072041,0.000000
156.510010,-0.078575,-449.346558,-0.001953,0.002853,0.072465,-0.349520,-0.017805,0.724648,-449.346558,0.071372,0.000000
156.910004,-0.065170,-449.302094,-0.001970,0.002820,0.071625,-0.289892,-0.014768,0.716246,-449.302094,0.070704,0.000000
157.310013,-0.075966,-449.302094,-0.001970,0.002796,0.071025,-0.337913,-0.017214,0.710251,-449.302094,0.070036,0.000000
157.710007,-0.062187,-449.302094,-0.001996,0.002775,0.070488,-0.276622,-0.014092,0.704876,-449.302094,0.069369,0.000000
158.110001,-0.070755,-449.391052,-0.002052,0.002741,0.069629,-0.314734,-0.016033,0.696292,-449.391052,0.068710,0.000000
158.510010,-0.074104,-449.391052,-0.002048,0.002722,0.069136,-0.329632,-0.016792,0.691356,-449.391052,0.068043,0.000000
158.910004,-0.068146,-449.435516,-0.002074,0.002689,0.068294,-0.303127,-0.015442,0.682939,-449.435516,0.067375,0.000000
159.310013,-0.073364,-449.435516,-0.002091,0.002667,0.067731,-0.326341,-0.016625,0.677307,-449.435516,0.066707,0.000000
159.710007,-0.052505,-449.391052,-0.002147,0.002638,0.067010,-0.233556,-0.011898,0.670101,-449.391052,0.066040,0.000000
160.110001,-0.094215,-449.391052,-0.002156,0.002611,0.066326,-0.419091,-0.021350,0.663257,-449.391052,0.065372,0.000000
160.510010,-0.080437,-449.480011,-0.002182,0.002587,0.065700,-0.357800,-0.018227,0.657005,-449.480011,0.064704,0.000000
160.910004,-0.088631,-449.524506,-0.002182,0.002561,0.065051,-0.394249,-0.020084,0.650510,-449.524506,0.064035,0.000000
161.310013,-0.051765,-449.480011,-0.002216,0.002539,0.064495,-0.230264,-0.011730,0.644954,-449.480011,0.063377,0.000000
161.710007,-0.070755,-449.524506,-0.002259,0.002511,0.063767,-0.314734,-0.016033,0.637672,-449.524506,0.062709,0.000000
162.110001,-0.092728,-449.524506,-0.002289,0.002483,0.063065,-0.412473,-0.021012,0.630647,-449.524506,0.062041,0.000000
162.510010,-0.034637,-449.524506,-0.002315,0.002450,0.062241,-0.154075,-0.007849,0.622411,-449.524506,0.061374,0.000000
162.910004,-0.056602,-449.613464,-0.002311,0.002433,0.061790,-0.251780,-0.012826,0.617899,-449.613464,0.060706,0.000000
163.310013,-0.050644,-449.568970,-0.002345,0.002399,0.060939,-0.225275,-0.011476,0.609391,-449.568970,0.060038,0.000000
163.710007,-0.059212,-449.613464,-0.002376,0.002378,0.060402,-0.263387,-0.013418,0.604016,-449.613464,0.059371,0.000000
164.110001,-0.057350,-449.568970,-0.002389,0.002350,0.059699,-0.255106,-0.012996,0.596991,-449.568970,0.058703,0.000000
164.510010,-0.045059,-449.613464,-0.002427,0.002319,0.058901,-0.200433,-0.010211,0.589013,-449.613464,0.058043,0.000000
164.910004,-0.068520,-449.613464,-0.002445,0.002301,0.058450,-0.304790,-0.015527,0.584501,-449.613464,0.057375,0.000000
165.310013,-0.077087,-449.613464,-0.002488,0.002275,0.057775,-0.342902,-0.017468,0.577749,-449.613464,0.056708,0.000000
165.710007,-0.076340,-449.702423,-0.002509,0.002245,0.057029,-0.339576,-0.017299,0.570285,-449.702423,0.056040,0.000000
166.110001,-0.027931,-449.702423,-0.002531,0.002221,0.056421,-0.124244,-0.006329,0.564214,-449.702423,0.056291,0.000000
166.300003,-0.028679,-449.702423,-0.002527,0.002222,0.056440,-0.127570,-0.006499,0.564396,-449.702423,0.056291,0.000000