File: Data/compression 29/AutoNoHeating-17-29-reverse-2-2_10232024_184345.csv
Time (sec),S:Load (lbs),S:HL1 (DIM),S:LVDT (in),S:Position (in),Ch:Position (mm),Ch:Load (N),Ch:Stress (MPa),Ch:Strain (mm/mm),Ch:HL1 (DIM),Set Point (),Cycles ()
0.110000,0.008560,-426.127502,-0.008908,-0.003996,-0.101509,0.038078,0.001940,-1.015086,-426.127502,-0.101353,0.000000
0.530000,0.007072,-426.038544,-0.008921,-0.003899,-0.099029,0.031460,0.001603,-0.990287,-426.038544,-0.098352,0.000000
0.950000,0.000740,-426.127502,-0.008761,-0.003645,-0.092594,0.003292,0.000168,-0.925937,-426.127502,-0.091345,0.000000
1.370000,0.029411,-426.171997,-0.008494,-0.003367,-0.085517,0.130828,0.006665,-0.855174,-426.171997,-0.084355,0.000000
1.790000,0.016380,-426.216461,-0.008196,-0.003093,-0.078553,0.072863,0.003712,-0.785532,-426.216461,-0.077366,0.000000
2.210000,-0.016762,-426.127502,-0.007925,-0.002822,-0.071668,-0.074560,-0.003798,-0.716677,-426.127502,-0.070358,0.000000
2.630000,0.008560,-426.171997,-0.007653,-0.002541,-0.064530,0.038078,0.001940,-0.645302,-426.171997,-0.063368,0.000000
3.050000,0.043190,-426.216461,-0.007360,-0.002269,-0.057627,0.192119,0.009787,-0.576273,-426.216461,-0.056361,0.000000
3.470000,0.032021,-426.260956,-0.007075,-0.001997,-0.050724,0.142435,0.007256,-0.507236,-426.260956,-0.049371,0.000000
3.890000,0.068512,-426.349915,-0.006773,-0.001709,-0.043396,0.304756,0.015525,-0.433961,-426.349915,-0.042364,0.000000
4.310000,0.008186,-426.305420,-0.006506,-0.001442,-0.036632,0.036415,0.001855,-0.366317,-426.305420,-0.035374,0.000000
4.730000,-0.029419,-426.260956,-0.006213,-0.001166,-0.029607,-0.130862,-0.006666,-0.296070,-426.260956,-0.028384,0.000000
5.150000,0.011169,-426.305420,-0.005954,-0.000886,-0.022496,0.049684,0.002531,-0.224959,-426.305420,-0.021377,0.000000
5.570000,0.062553,-426.394409,-0.005652,-0.000608,-0.015436,0.278251,0.014175,-0.154363,-426.394409,-0.014387,0.000000
5.990000,0.081177,-426.438873,-0.005381,-0.000339,-0.008603,0.361092,0.018395,-0.086031,-426.438873,-0.007380,0.000000
6.410000,0.058456,-426.305420,-0.005092,-0.000062,-0.001570,0.260027,0.013246,-0.015700,-426.305420,-0.000390,0.000000
6.830000,0.106865,-426.349915,-0.004928,-0.000008,-0.000191,0.475359,0.024216,-0.001908,-426.349915,0.000017,0.000000
7.250000,0.114685,-426.394409,-0.004945,-0.000008,-0.000191,0.510145,0.025988,-0.001908,-426.394409,0.000208,0.000000
7.670001,0.095322,-426.527832,-0.004958,-0.000003,-0.000087,0.424012,0.021600,-0.000871,-426.527832,0.000911,0.000000
8.090000,0.139267,-426.527832,-0.004919,0.000023,0.000581,0.619490,0.031558,0.005806,-426.527832,0.001604,0.000000
8.510000,0.315765,-426.483368,-0.004907,0.000055,0.001388,1.404595,0.071553,0.013875,-426.483368,0.002307,0.000000
8.930000,0.505310,-426.483368,-0.004885,0.000082,0.002081,2.247731,0.114505,0.020809,-426.483368,0.003009,0.000000
9.350000,0.641220,-426.438873,-0.004868,0.000098,0.002489,2.852289,0.145303,0.024889,-426.438873,0.003711,0.000000
9.770000,0.991623,-426.527832,-0.004829,0.000133,0.003382,4.410959,0.224705,0.033822,-426.527832,0.004405,0.000000
10.190001,1.407936,-426.616791,-0.004799,0.000163,0.004136,6.262813,0.319043,0.041361,-426.616791,0.005107,0.000000
10.610001,1.922180,-426.572327,-0.004781,0.000190,0.004821,8.550284,0.435572,0.048212,-426.572327,0.005810,0.000000
11.030001,2.327324,-426.483368,-0.004769,0.000212,0.005394,10.352454,0.527379,0.053942,-426.483368,0.006512,0.000000
11.450001,3.019196,-426.527832,-0.004721,0.000252,0.006400,13.430053,0.684160,0.063995,-426.527832,0.007206,0.000000
11.870001,3.359917,-426.616791,-0.004712,0.000272,0.006920,14.945656,0.761368,0.069203,-426.616791,0.007909,0.000000
12.290001,3.830223,-426.616791,-0.004687,0.000295,0.007501,17.037683,0.867941,0.075009,-426.616791,0.008611,0.000000
12.710001,4.338509,-426.616791,-0.004665,0.000320,0.008125,19.298651,0.983120,0.081254,-426.616791,0.009305,0.000000
13.130001,5.225868,-426.616791,-0.004644,0.000362,0.009201,23.245823,1.184199,0.092011,-426.616791,0.010007,0.000000
13.550000,5.507385,-426.616791,-0.004613,0.000383,0.009739,24.498074,1.247991,0.097385,-426.616791,0.010710,0.000000
13.970000,5.860397,-426.705750,-0.004587,0.000408,0.010363,26.068350,1.327985,0.103630,-426.705750,0.011412,0.000000
14.390000,6.595459,-426.705750,-0.004557,0.000441,0.011213,29.338066,1.494552,0.112131,-426.705750,0.012106,0.000000
14.810000,7.016235,-426.705750,-0.004540,0.000464,0.011794,31.209774,1.589902,0.117937,-426.705750,0.012809,0.000000
15.230000,7.731941,-426.705750,-0.004484,0.000501,0.012731,34.393391,1.752083,0.127309,-426.705750,0.013511,0.000000
15.650001,7.809021,-426.750244,-0.004488,0.000523,0.013277,34.736259,1.769549,0.132767,-426.750244,0.014205,0.000000
16.070002,8.153465,-426.794739,-0.004462,0.000550,0.013962,36.268425,1.847602,0.139617,-426.794739,0.014907,0.000000
16.490002,8.626007,-426.750244,-0.004445,0.000576,0.014630,38.370396,1.954681,0.146301,-426.750244,0.015610,0.000000
16.910002,8.847565,-426.839203,-0.004406,0.000598,0.015185,39.355934,2.004887,0.151850,-426.839203,0.016312,0.000000
17.330000,9.425491,-426.839203,-0.004389,0.000632,0.016052,41.926678,2.135847,0.160517,-426.839203,0.017006,0.000000
17.750000,9.786690,-426.794739,-0.004359,0.000660,0.016772,43.533371,2.217695,0.167716,-426.794739,0.017709,0.000000
18.170000,10.439461,-426.883698,-0.004350,0.000693,0.017596,46.437042,2.365616,0.175960,-426.883698,0.018411,0.000000
18.590000,10.628998,-426.883698,-0.004307,0.000717,0.018203,47.280144,2.408565,0.182031,-426.883698,0.019114,0.000000
19.010000,10.970833,-426.883698,-0.004286,0.000743,0.018862,48.800701,2.486026,0.188616,-426.883698,0.019807,0.000000
19.430000,11.324219,-426.928162,-0.004251,0.000770,0.019564,50.372643,2.566105,0.195641,-426.928162,0.020510,0.000000
19.850000,11.601631,-426.883698,-0.004238,0.000796,0.020223,51.606632,2.628967,0.202235,-426.883698,0.021212,0.000000
20.270000,12.023155,-426.883698,-0.004217,0.000823,0.020900,53.481667,2.724486,0.209002,-426.883698,0.021906,0.000000
20.690001,12.421967,-426.928162,-0.004186,0.000852,0.021637,55.255669,2.814858,0.216367,-426.928162,0.022608,0.000000
21.110001,12.869934,-427.017120,-0.004156,0.000884,0.022444,57.248325,2.916369,0.224437,-427.017120,0.023310,0.000000
21.530001,12.944405,-427.017120,-0.004126,0.000909,0.023077,57.579586,2.933244,0.230765,-427.017120,0.024013,0.000000
21.950001,13.398705,-427.017120,-0.004109,0.000937,0.023796,59.600414,3.036190,0.237964,-427.017120,0.024707,0.000000
22.370001,13.582657,-427.017120,-0.004083,0.000958,0.024343,60.418674,3.077874,0.243429,-427.017120,0.025410,0.000000
22.790001,14.188881,-427.106079,-0.004049,0.000995,0.025279,63.115295,3.215246,0.252793,-427.106079,0.026112,0.000000
23.210001,14.321068,-427.106079,-0.004018,0.001016,0.025799,63.703293,3.245200,0.257994,-427.106079,0.026805,0.000000
23.630001,14.611893,-427.017120,-0.004005,0.001043,0.026484,64.996948,3.311102,0.264844,-427.017120,0.027508,0.000000
24.050001,15.236359,-427.061615,-0.003967,0.001075,0.027300,67.774712,3.452608,0.272997,-427.061615,0.028210,0.000000
24.470001,14.817444,-427.150574,-0.003949,0.001088,0.027647,65.911285,3.357681,0.276471,-427.150574,0.028913,0.000000
24.890001,16.003448,-427.150574,-0.003906,0.001131,0.028739,71.186897,3.626433,0.287395,-427.150574,0.029607,0.000000
25.310001,15.880936,-427.195068,-0.003885,0.001153,0.029286,70.641930,3.598671,0.292860,-427.195068,0.030309,0.000000
25.730001,16.202667,-427.150574,-0.003850,0.001180,0.029963,72.073067,3.671577,0.299627,-427.150574,0.031012,0.000000
26.150002,16.571686,-427.195068,-0.003824,0.001210,0.030734,73.714539,3.755198,0.307341,-427.195068,0.031714,0.000000
26.570002,16.531471,-427.150574,-0.003807,0.001229,0.031228,73.535660,3.746085,0.312284,-427.150574,0.032408,0.000000
26.990002,17.145142,-427.239532,-0.003773,0.001263,0.032078,76.265396,3.885144,0.320785,-427.239532,0.033110,0.000000
27.410002,17.311592,-427.284027,-0.003747,0.001291,0.032798,77.005806,3.922863,0.327984,-427.284027,0.033813,0.000000
27.830002,17.771103,-427.284027,-0.003712,0.001321,0.033552,79.049812,4.026989,0.335523,-427.284027,0.034507,0.000000
28.250002,17.526077,-427.284027,-0.003695,0.001338,0.033995,77.959885,3.971466,0.339952,-427.284027,0.035209,0.000000
28.670002,18.622719,-427.239532,-0.003665,0.001382,0.035105,82.837990,4.219968,0.351049,-427.239532,0.035912,0.000000
29.090002,18.267845,-427.284027,-0.003630,0.001401,0.035582,81.259430,4.139553,0.355818,-427.284027,0.036614,0.000000
29.510002,18.366150,-427.372986,-0.003596,0.001426,0.036232,81.696716,4.161829,0.362320,-427.372986,0.037308,0.000000
29.930002,18.909813,-427.328491,-0.003570,0.001459,0.037047,84.115051,4.285025,0.370473,-427.328491,0.038010,0.000000
30.350002,19.059883,-427.328491,-0.003531,0.001482,0.037646,84.782593,4.319031,0.376461,-427.328491,0.038713,0.000000
30.770002,19.816170,-427.372986,-0.003492,0.001519,0.038591,88.146729,4.490408,0.385908,-427.372986,0.039407,0.000000
31.190001,19.438583,-427.417450,-0.003488,0.001540,0.039121,86.467140,4.404846,0.391207,-427.417450,0.040109,0.000000
31.610001,19.911125,-427.417450,-0.003449,0.001571,0.039900,88.569107,4.511926,0.399004,-427.417450,0.040812,0.000000
32.030003,19.758453,-427.372986,-0.003419,0.001592,0.040430,87.889992,4.477330,0.404302,-427.372986,0.041514,0.000000
32.450001,20.290947,-427.417450,-0.003402,0.001628,0.041340,90.258636,4.597994,0.413401,-427.417450,0.042208,0.000000
32.870003,20.625336,-427.461945,-0.003372,0.001655,0.042026,91.746078,4.673768,0.420260,-427.461945,0.042910,0.000000
33.290001,20.320732,-427.506409,-0.003341,0.001676,0.042580,90.391129,4.604744,0.425801,-427.506409,0.043613,0.000000
33.710003,20.891579,-427.550903,-0.003316,0.001705,0.043317,92.930382,4.734099,0.433174,-427.550903,0.044315,0.000000
34.130001,20.972015,-427.506409,-0.003277,0.001730,0.043934,93.288185,4.752326,0.439335,-427.506409,0.045008,0.000000
34.550003,21.937950,-427.506409,-0.003251,0.001768,0.044904,97.584877,4.971210,0.449040,-427.506409,0.045711,0.000000
34.970001,21.520515,-427.506409,-0.003212,0.001790,0.045469,95.728035,4.876619,0.454687,-427.506409,0.046413,0.000000
35.390003,21.765541,-427.550903,-0.003186,0.001819,0.046197,96.817963,4.932142,0.461969,-427.550903,0.047107,0.000000
35.810001,21.949493,-427.595367,-0.003152,0.001846,0.046890,97.636223,4.973826,0.468903,-427.595367,0.047809,0.000000
36.230003,21.861610,-427.639862,-0.003126,0.001864,0.047341,97.245300,4.953912,0.473415,-427.639862,0.048512,0.000000
36.650002,22.971657,-427.595367,-0.003083,0.001907,0.048425,102.183029,5.205452,0.484255,-427.595367,0.049214,0.000000
37.070004,22.566887,-427.639862,-0.003053,0.001927,0.048937,100.382530,5.113729,0.489372,-427.639862,0.049909,0.000000
37.490002,23.425575,-427.639862,-0.003040,0.001961,0.049821,104.202164,5.308311,0.498213,-427.639862,0.050612,0.000000
37.910004,23.102356,-427.684357,-0.003005,0.001984,0.050386,102.764412,5.235069,0.503860,-427.684357,0.051314,0.000000
38.330002,24.137924,-427.728821,-0.002971,0.002017,0.051226,107.370850,5.469732,0.512263,-427.728821,0.052007,0.000000
38.750000,23.591652,-427.728821,-0.002958,0.002035,0.051696,104.940910,5.345945,0.516956,-427.728821,0.052710,0.000000
39.170002,23.916367,-427.684357,-0.002915,0.002062,0.052380,106.385315,5.419526,0.523799,-427.684357,0.053412,0.000000
39.590000,24.804474,-427.728821,-0.002893,0.002097,0.053273,110.335808,5.620774,0.532732,-427.728821,0.054115,0.000000
40.010002,24.630577,-427.728821,-0.002854,0.002118,0.053803,109.562279,5.581368,0.538030,-427.728821,0.054808,0.000000
40.430000,25.125832,-427.773315,-0.002824,0.002147,0.054539,111.765282,5.693595,0.545388,-427.773315,0.055511,0.000000
40.850002,25.357445,-427.728821,-0.002785,0.002174,0.055225,112.795547,5.746079,0.552246,-427.728821,0.056213,0.000000
41.270000,25.780830,-427.773315,-0.002759,0.002201,0.055901,114.678864,5.842020,0.559014,-427.773315,0.056916,0.000000
41.690002,26.015800,-427.862274,-0.002729,0.002228,0.056595,115.724060,5.895265,0.565948,-427.862274,0.057609,0.000000
42.110001,26.379608,-427.817780,-0.002729,0.002259,0.057376,117.342354,5.977705,0.573760,-427.817780,0.058312,0.000000
42.530003,27.067375,-427.906738,-0.002665,0.002289,0.058139,120.401695,6.133555,0.581390,-427.906738,0.059014,0.000000
42.950001,27.106476,-427.862274,-0.002634,0.002313,0.058763,120.575630,6.142416,0.587628,-427.862274,0.059707,0.000000
43.370003,26.997742,-427.862274,-0.002604,0.002335,0.059318,120.091949,6.117776,0.593184,-427.862274,0.060410,0.000000
43.790001,27.078926,-427.906738,-0.002574,0.002363,0.060028,120.453079,6.136172,0.600284,-427.906738,0.061112,0.000000
44.210003,28.736351,-427.951233,-0.002561,0.002402,0.061000,127.825676,6.511750,0.610004,-427.951233,0.061815,0.000000
44.630001,28.546066,-427.995697,-0.002522,0.002424,0.061582,126.979248,6.468631,0.615818,-427.995697,0.062510,0.000000
45.050003,28.924400,-428.040192,-0.002492,0.002453,0.062301,128.662155,6.554363,0.623009,-428.040192,0.063212,0.000000
45.470001,29.135536,-427.995697,-0.002453,0.002476,0.062891,129.601334,6.602207,0.628913,-427.995697,0.063915,0.000000
45.890003,29.392097,-427.995697,-0.002427,0.002500,0.063498,130.742584,6.660344,0.634984,-427.995697,0.064617,0.000000
46.310001,30.305901,-428.040192,-0.002402,0.002532,0.064313,134.807373,6.867415,0.643129,-428.040192,0.065311,0.000000
46.730003,30.407562,-428.040192,-0.002380,0.002558,0.064981,135.259598,6.890452,0.649806,-428.040192,0.066013,0.000000
47.150002,31.015274,-428.040192,-0.002345,0.002587,0.065701,137.962830,7.028162,0.657012,-428.040192,0.066716,0.000000
47.570004,31.372002,-428.040192,-0.002302,0.002612,0.066343,139.549637,7.108997,0.663432,-428.040192,0.067409,0.000000
47.990002,31.510529,-428.084686,-0.002285,0.002635,0.066941,140.165833,7.140388,0.669412,-428.084686,0.068111,0.000000
48.410004,32.440712,-428.173645,-0.002238,0.002671,0.067843,144.303497,7.351171,0.678435,-428.173645,0.068814,0.000000
48.830002,32.927780,-428.218109,-0.002220,0.002697,0.068493,146.470078,7.461542,0.684930,-428.218109,0.069516,0.000000
49.250004,33.339996,-428.173645,-0.002182,0.002723,0.069161,148.303711,7.554951,0.691606,-428.173645,0.070210,0.000000
49.670002,32.956451,-428.173645,-0.002169,0.002743,0.069681,146.597610,7.468039,0.696814,-428.173645,0.070912,0.000000
50.090004,35.188080,-428.173645,-0.002121,0.002786,0.070765,156.524399,7.973732,0.707654,-428.173645,0.071615,0.000000
50.510002,35.148605,-428.129150,-0.002104,0.002809,0.071338,156.348801,7.964788,0.713377,-428.129150,0.072310,0.000000
50.930004,35.287872,-428.218109,-0.002074,0.002832,0.071928,156.968292,7.996346,0.719281,-428.218109,0.073012,0.000000
51.350002,36.107834,-428.307068,-0.002031,0.002864,0.072734,160.615662,8.182152,0.727336,-428.307068,0.073715,0.000000
51.770004,36.360306,-428.218109,-0.002013,0.002886,0.073298,161.738724,8.239363,0.732983,-428.218109,0.074417,0.000000
52.190002,37.875488,-428.262604,-0.001983,0.002924,0.074260,168.478592,8.582708,0.742596,-428.262604,0.075110,0.000000
52.610001,37.558228,-428.307068,-0.001944,0.002944,0.074771,167.067337,8.510816,0.747714,-428.307068,0.075813,0.000000
53.030003,38.423248,-428.351562,-0.001927,0.002975,0.075569,170.915146,8.706832,0.755692,-428.351562,0.076515,0.000000
53.450001,38.293663,-428.351562,-0.001893,0.002993,0.076029,170.338715,8.677468,0.760295,-428.351562,0.077218,0.000000
53.870003,40.417305,-428.351562,-0.001850,0.003035,0.077097,179.785156,9.158692,0.770968,-428.351562,0.077911,0.000000
54.290001,40.186432,-428.307068,-0.001837,0.003057,0.077642,178.758179,9.106376,0.776418,-428.307068,0.078614,0.000000
54.710003,40.365173,-428.440521,-0.001807,0.003080,0.078232,179.553253,9.146879,0.782323,-428.440521,0.079316,0.000000
55.130001,41.399254,-428.351562,-0.001776,0.003108,0.078944,184.153076,9.381205,0.789438,-428.351562,0.080010,0.000000
55.550003,41.781677,-428.440521,-0.001750,0.003134,0.079593,185.854187,9.467864,0.795933,-428.440521,0.080712,0.000000
55.970001,43.809242,-428.485016,-0.001725,0.003173,0.080582,194.873245,9.927316,0.805819,-428.485016,0.081415,0.000000
56.390003,43.706467,-428.440521,-0.001694,0.003193,0.081103,194.416077,9.904027,0.811027,-428.440521,0.082117,0.000000
56.810001,44.391266,-428.485016,-0.001656,0.003219,0.081770,197.462219,10.059204,0.817704,-428.485016,0.082810,0.000000
57.230003,45.171753,-428.529480,-0.001638,0.003246,0.082447,200.933990,10.236066,0.824471,-428.529480,0.083513,0.000000
57.650002,45.068977,-428.573975,-0.001604,0.003269,0.083036,200.476822,10.212776,0.830361,-428.573975,0.084215,0.000000
58.070004,47.443230,-428.618439,-0.001578,0.003308,0.084025,211.038025,10.750790,0.840247,-428.618439,0.084910,0.000000
58.490002,47.461845,-428.618439,-0.001539,0.003330,0.084580,211.120834,10.755009,0.845803,-428.618439,0.085613,0.000000
58.910004,49.024323,-428.618439,-0.001509,0.003364,0.085448,218.071075,11.109070,0.854478,-428.618439,0.086315,0.000000
59.330002,49.506546,-428.662933,-0.001487,0.003388,0.086046,220.216110,11.218344,0.860458,-428.662933,0.087018,0.000000
59.750004,50.802399,-428.707397,-0.001457,0.003420,0.086878,225.980362,11.511988,0.868785,-428.707397,0.087711,0.000000
60.170002,50.761063,-428.662933,-0.001423,0.003443,0.087451,225.796478,11.502621,0.874508,-428.662933,0.088414,0.000000
60.590004,51.297653,-428.662933,-0.001406,0.003466,0.088049,228.183365,11.624214,0.880488,-428.662933,0.089116,0.000000
61.010002,53.137177,-428.662933,-0.001375,0.003500,0.088891,236.365967,12.041057,0.888905,-428.662933,0.089819,0.000000
61.430004,53.133080,-428.751892,-0.001358,0.003519,0.089377,236.347748,12.040128,0.893765,-428.751892,0.090512,0.000000
61.850002,54.403244,-428.751892,-0.001332,0.003549,0.090156,241.997711,12.327951,0.901562,-428.751892,0.091214,0.000000
62.270004,55.278313,-428.751892,-0.001285,0.003579,0.090903,245.890213,12.526245,0.909026,-428.751892,0.091917,0.000000
62.690002,56.161583,-428.751892,-0.001272,0.003609,0.091657,249.819199,12.726397,0.916565,-428.751892,0.092610,0.000000
63.110004,56.897766,-428.751892,-0.001255,0.003628,0.092143,253.093903,12.893218,0.921425,-428.751892,0.093313,0.000000
63.530003,59.213921,-428.796356,-0.001237,0.003669,0.093183,263.396667,13.418066,0.931826,-428.796356,0.094015,0.000000
63.950005,59.665237,-428.840851,-0.001190,0.003693,0.093790,265.404236,13.520336,0.937897,-428.840851,0.094718,0.000000
64.370003,60.557442,-428.885315,-0.001168,0.003718,0.094441,269.372955,13.722512,0.944407,-428.885315,0.095411,0.000000
64.790001,60.709740,-428.840851,-0.001130,0.003734,0.094839,270.050415,13.757023,0.948389,-428.840851,0.096114,0.000000
65.210007,62.669167,-428.840851,-0.001117,0.003770,0.095759,278.766388,14.201036,0.957594,-428.840851,0.096816,0.000000
65.630005,64.402939,-428.840851,-0.001086,0.003802,0.096583,286.478577,14.593915,0.965829,-428.840851,0.097511,0.000000
66.050003,64.987549,-428.929810,-0.001082,0.003827,0.097199,289.079041,14.726389,0.971991,-428.929810,0.098213,0.000000
66.470001,66.197388,-428.974304,-0.001052,0.003843,0.097623,294.460693,15.000543,0.976230,-428.974304,0.097883,0.000000
66.889999,66.853516,-428.929810,-0.001005,0.003795,0.096401,297.379303,15.149223,0.964013,-428.929810,294.500458,0.000000
67.310005,65.135757,-428.974304,-0.000996,0.003862,0.098083,289.738312,14.759974,0.980833,-428.974304,294.500458,0.000000
67.730003,65.593033,-428.974304,-0.000996,0.003887,0.098742,291.772369,14.863594,0.987419,-428.974304,294.500458,0.000000
68.150002,64.938782,-429.018768,-0.000970,0.003895,0.098942,288.862122,14.715339,0.989417,-429.018768,294.500458,0.000000
68.570000,65.999664,-429.018768,-0.000953,0.003913,0.099393,293.581177,14.955738,0.993929,-429.018768,294.500458,0.000000
68.990005,65.559143,-429.063263,-0.000931,0.003926,0.099721,291.621643,14.855914,0.997214,-429.063263,294.500458,0.000000
69.410004,65.206879,-429.063263,-0.000927,0.003936,0.099974,290.054687,14.776090,0.999742,-429.063263,294.500458,0.000000
69.830002,64.990158,-429.063263,-0.000931,0.003945,0.100191,289.090668,14.726980,1.001907,-429.063263,294.500458,0.000000
70.250000,65.014740,-429.063263,-0.000918,0.003953,0.100416,289.200012,14.732551,1.004163,-429.063263,294.500458,0.000000
70.670006,65.427322,-429.107727,-0.000892,0.003965,0.100710,291.035278,14.826044,1.007100,-429.107727,294.500458,0.000000
71.090004,66.186218,-429.152222,-0.000880,0.003984,0.101196,294.411011,14.998012,1.011960,-429.152222,294.500458,0.000000
71.510002,65.241882,-429.152222,-0.000854,0.003975,0.100963,290.210388,14.784021,1.009628,-429.152222,294.500458,0.000000
71.930000,65.367752,-429.152222,-0.000849,0.003990,0.101344,290.770294,14.812545,1.013443,-429.152222,294.500458,0.000000
72.350006,65.854813,-429.152222,-0.000854,0.003995,0.101465,292.936829,14.922914,1.014655,-429.152222,294.500458,0.000000
72.770004,65.404236,-429.196686,-0.000854,0.004006,0.101752,290.932556,14.820811,1.017516,-429.196686,294.500458,0.000000
73.190002,65.088104,-429.241180,-0.000819,0.004009,0.101829,289.526337,14.749176,1.018288,-429.241180,294.500458,0.000000
73.610001,65.601593,-429.285645,-0.000823,0.004021,0.102142,291.810455,14.865534,1.021422,-429.285645,294.500458,0.000000
74.030006,65.083633,-429.196686,-0.000823,0.004022,0.102150,289.506470,14.748162,1.021498,-429.196686,294.500458,0.000000
74.450005,64.898926,-429.241180,-0.000815,0.004027,0.102289,288.684845,14.706306,1.022891,-429.241180,294.500458,0.000000
74.870003,65.275772,-429.330139,-0.000811,0.004036,0.102515,290.361145,14.791701,1.025146,-429.330139,294.500458,0.000000
75.290001,65.108200,-429.330139,-0.000793,0.004040,0.102619,289.615753,14.753729,1.026191,-429.330139,294.500458,0.000000
75.710007,65.174866,-429.285645,-0.000789,0.004046,0.102766,289.912292,14.768836,1.027660,-429.285645,294.500458,0.000000
76.130005,65.052719,-429.330139,-0.000793,0.004051,0.102896,289.368958,14.741157,1.028962,-429.330139,294.500458,0.000000
76.550003,65.093689,-429.374634,-0.000798,0.004058,0.103069,289.551178,14.750442,1.030687,-429.374634,294.500458,0.000000
76.970001,65.063889,-429.419098,-0.000785,0.004060,0.103131,289.418640,14.743688,1.031308,-429.419098,294.500458,0.000000
77.390007,65.530472,-429.463593,-0.000780,0.004069,0.103347,291.494110,14.849417,1.033473,-429.463593,294.500458,0.000000
77.810005,65.201294,-429.463593,-0.000767,0.004069,0.103356,290.029846,14.774824,1.033564,-429.463593,294.500458,0.000000
78.230003,65.552078,-429.419098,-0.000759,0.004078,0.103573,291.590210,14.854314,1.035729,-429.419098,294.500458,0.000000
78.650002,65.233322,-429.419098,-0.000776,0.004078,0.103580,290.172302,14.782083,1.035805,-429.419098,294.500458,0.000000
79.070007,65.180817,-429.463593,-0.000755,0.004082,0.103676,289.938751,14.770185,1.036758,-429.463593,294.500458,0.000000
79.490005,65.151779,-429.552551,-0.000755,0.004086,0.103780,289.809601,14.763604,1.037803,-429.552551,294.500458,0.000000
79.910004,65.135757,-429.552551,-0.000750,0.004089,0.103859,289.738312,14.759974,1.038590,-429.552551,294.500458,0.000000
80.330002,65.153259,-429.552551,-0.000750,0.004093,0.103962,289.816162,14.763940,1.039620,-429.552551,294.500458,0.000000
80.750008,65.104111,-429.552551,-0.000750,0.004096,0.104032,289.597534,14.752803,1.040316,-429.552551,294.500458,0.000000
81.170006,65.056442,-429.552551,-0.000746,0.004098,0.104092,289.385498,14.742001,1.040922,-429.552551,294.500458,0.000000
81.590004,65.313004,-429.552551,-0.000729,0.004105,0.104257,290.526764,14.800138,1.042572,-429.552551,294.500458,0.000000
82.010002,65.165176,-429.597015,-0.000733,0.004105,0.104257,289.869171,14.766640,1.042572,-429.597015,294.500458,0.000000
82.430000,65.480209,-429.685974,-0.000720,0.004113,0.104474,291.270508,14.838028,1.044737,-429.685974,294.500458,0.000000
82.850006,65.406097,-429.641510,-0.000724,0.004113,0.104466,290.940857,14.821234,1.044661,-429.641510,294.500458,0.000000
83.270004,65.180069,-429.641510,-0.000716,0.004113,0.104466,289.935425,14.770015,1.044661,-429.641510,294.500458,0.000000
83.690002,65.353592,-429.597015,-0.000724,0.004118,0.104604,290.707306,14.809336,1.046039,-429.597015,294.500458,0.000000
84.110001,65.184174,-429.685974,-0.000729,0.004118,0.104604,289.953674,14.770945,1.046039,-429.685974,294.500458,0.000000
84.530006,65.311523,-429.774963,-0.000716,0.004123,0.104734,290.520172,14.799802,1.047341,-429.774963,294.500458,0.000000
84.950005,65.215073,-429.685974,-0.000711,0.004123,0.104734,290.091125,14.777947,1.047341,-429.685974,294.500458,0.000000
85.370003,65.509995,-429.685974,-0.000711,0.004130,0.104890,291.403015,14.844777,1.048900,-429.685974,294.500458,0.000000
85.790001,65.349503,-429.685974,-0.000716,0.004130,0.104890,290.689117,14.808409,1.048900,-429.685974,294.500458,0.000000
86.210007,65.202408,-429.863922,-0.000707,0.004130,0.104908,290.034790,14.775077,1.049082,-429.863922,294.500458,0.000000
86.630005,65.112671,-429.774963,-0.000698,0.004132,0.104952,289.635620,14.754742,1.049521,-429.774963,294.500458,0.000000
87.050003,65.170013,-429.774963,-0.000694,0.004135,0.105020,289.890686,14.767735,1.050202,-429.774963,294.500458,0.000000
87.470001,65.022186,-429.730469,-0.000690,0.004135,0.105038,289.233124,14.734238,1.050384,-429.730469,294.500458,0.000000
87.890007,64.895584,-429.774963,-0.000686,0.004136,0.105064,288.669983,14.705549,1.050641,-429.774963,294.500458,0.000000
88.310005,64.773819,-429.819427,-0.000703,0.004137,0.105073,288.128326,14.677958,1.050732,-429.819427,294.500458,0.000000
88.730003,65.762833,-429.863922,-0.000686,0.004148,0.105367,292.527679,14.902071,1.053669,-429.863922,294.500458,0.000000
89.150002,65.635117,-429.819427,-0.000694,0.004148,0.105367,291.959595,14.873131,1.053669,-429.819427,294.500458,0.000000
89.570007,65.496964,-429.908386,-0.000673,0.004148,0.105367,291.345032,14.841825,1.053669,-429.908386,294.500458,0.000000
89.990005,65.317108,-429.863922,-0.000694,0.004148,0.105367,290.545013,14.801068,1.053669,-429.863922,294.500458,0.000000
90.410004,65.154373,-429.952881,-0.000681,0.004148,0.105367,289.821136,14.764193,1.053669,-429.952881,294.500458,0.000000
90.830002,65.088470,-429.997345,-0.000686,0.004151,0.105446,289.527985,14.749258,1.054457,-429.997345,294.500458,0.000000
91.250008,65.034103,-430.041840,-0.000686,0.004151,0.105446,289.286133,14.736938,1.054457,-430.041840,294.500458,0.000000
91.670006,64.914948,-429.952881,-0.000686,0.004151,0.105446,288.756104,14.709937,1.054457,-429.952881,294.500458,0.000000
92.090004,64.980484,-429.997345,-0.000677,0.004155,0.105541,289.047638,14.724789,1.055410,-429.997345,294.500458,0.000000
92.510002,64.923508,-430.041840,-0.000681,0.004155,0.105541,288.794189,14.711877,1.055410,-430.041840,294.500458,0.000000
92.930008,65.203156,-430.041840,-0.000673,0.004160,0.105671,290.038116,14.775247,1.056712,-430.041840,294.500458,0.000000
93.350006,65.151398,-430.086304,-0.000668,0.004160,0.105671,289.807892,14.763517,1.056712,-430.086304,294.500458,0.000000
93.770004,65.016235,-430.041840,-0.000660,0.004161,0.105680,289.206665,14.732890,1.056803,-430.041840,294.500458,0.000000
94.190002,65.245605,-430.041840,-0.000651,0.004172,0.105966,290.226959,14.784865,1.059665,-430.041840,294.500458,0.000000
94.610008,65.731186,-430.086304,-0.000664,0.004170,0.105923,292.386932,14.894899,1.059226,-430.086304,294.500458,0.000000
95.030006,65.612762,-430.175262,-0.000673,0.004170,0.105923,291.860138,14.868065,1.059226,-430.175262,294.500458,0.000000
95.450005,65.511490,-430.175262,-0.000673,0.004170,0.105923,291.409668,14.845116,1.059226,-430.175262,294.500458,0.000000
95.870003,65.391205,-430.175262,-0.000655,0.004170,0.105923,290.874603,14.817859,1.059226,-430.175262,294.500458,0.000000
96.290001,65.291046,-430.219757,-0.000660,0.004171,0.105932,290.429077,14.795162,1.059316,-430.219757,294.500458,0.000000
96.710007,65.159958,-430.219757,-0.000668,0.004171,0.105941,289.845978,14.765458,1.059407,-430.219757,294.500458,0.000000
97.130005,65.053101,-430.264252,-0.000651,0.004171,0.105941,289.370636,14.741242,1.059407,-430.264252,294.500458,0.000000
97.550003,64.932449,-430.264252,-0.000660,0.004171,0.105941,288.833954,14.713903,1.059407,-430.264252,294.500458,0.000000
97.970001,64.802490,-430.219757,-0.000647,0.004171,0.105941,288.255859,14.684454,1.059407,-430.219757,294.500458,0.000000
98.390007,64.697113,-430.264252,-0.000647,0.004171,0.105948,287.787140,14.660576,1.059483,-430.264252,294.500458,0.000000
98.810005,66.578339,-430.264252,-0.000629,0.004147,0.105334,296.155243,15.086867,1.053336,-430.264252,294.500458,0.000000
99.230003,66.397736,-430.353210,-0.000647,0.004147,0.105334,295.351868,15.045941,1.053336,-430.353210,294.500458,0.000000
99.650002,66.259949,-430.397675,-0.000642,0.004147,0.105334,294.738983,15.014719,1.053336,-430.397675,294.500458,0.000000
100.070007,66.114349,-430.397675,-0.000625,0.004147,0.105334,294.091309,14.981726,1.053336,-430.397675,294.500458,0.000000
100.490005,65.992218,-430.353210,-0.000634,0.004147,0.105334,293.548035,14.954050,1.053336,-430.353210,294.500458,0.000000
100.910004,65.857788,-430.397675,-0.000629,0.004147,0.105334,292.950073,14.923589,1.053336,-430.397675,294.500458,0.000000
101.330002,65.745331,-430.397675,-0.000642,0.004147,0.105334,292.449829,14.898106,1.053336,-430.397675,294.500458,0.000000
101.750008,65.605316,-430.486633,-0.000642,0.004148,0.105359,291.827026,14.866377,1.053594,-430.486633,294.500458,0.000000
102.170006,65.510361,-430.531128,-0.000642,0.004148,0.105359,291.404633,14.844859,1.053594,-430.531128,294.500458,0.000000
102.590004,65.369614,-430.442169,-0.000629,0.004148,0.105367,290.778564,14.812966,1.053669,-430.442169,294.500458,0.000000
103.010002,65.267212,-430.486633,-0.000629,0.004148,0.105367,290.323059,14.789762,1.053669,-430.486633,294.500458,0.000000
103.430008,65.248962,-430.531128,-0.000625,0.004177,0.106088,290.241882,14.785626,1.060876,-430.531128,294.500458,0.000000
103.850006,65.183792,-430.531128,-0.000634,0.004179,0.106148,289.951996,14.770859,1.061481,-430.531128,294.500458,0.000000
104.270004,65.338333,-430.620087,-0.000638,0.004186,0.106330,290.639435,14.805878,1.063298,-430.620087,294.500458,0.000000
104.690002,65.295883,-430.575592,-0.000625,0.004186,0.106330,290.450592,14.796259,1.063298,-430.575592,294.500458,0.000000
105.110008,65.230347,-430.575592,-0.000638,0.004186,0.106330,290.159088,14.781407,1.063298,-430.575592,294.500458,0.000000
105.530006,65.188644,-430.531128,-0.000625,0.004188,0.106365,289.973572,14.771957,1.063646,-430.531128,294.500458,0.000000
105.950005,65.198685,-430.620087,-0.000634,0.004190,0.106434,290.018219,14.774233,1.064343,-430.620087,294.500458,0.000000
106.370003,65.283218,-430.664581,-0.000634,0.004191,0.106460,290.394257,14.793388,1.064600,-430.664581,294.500458,0.000000
106.790009,65.255661,-430.709045,-0.000629,0.004191,0.106460,290.271667,14.787145,1.064600,-430.709045,294.500458,0.000000
107.210007,65.207260,-430.620087,-0.000629,0.004192,0.106469,290.056366,14.776176,1.064691,-430.620087,294.500458,0.000000
107.630005,65.129059,-430.620087,-0.000625,0.004193,0.106495,289.708527,14.758455,1.064948,-430.620087,294.500458,0.000000
108.050003,65.073196,-430.709045,-0.000634,0.004193,0.106495,289.460022,14.745797,1.064948,-430.709045,294.500458,0.000000
108.470009,65.024048,-430.798004,-0.000629,0.004195,0.106555,289.241425,14.734660,1.065554,-430.798004,294.500458,0.000000
108.890007,65.175598,-430.798004,-0.000625,0.004196,0.106581,289.915527,14.769001,1.065811,-430.798004,294.500458,0.000000
109.310005,65.127945,-430.753540,-0.000617,0.004196,0.106581,289.703583,14.758204,1.065811,-430.753540,294.500458,0.000000
109.730003,65.086609,-430.753540,-0.000629,0.004197,0.106599,289.519684,14.748837,1.065993,-430.753540,294.500458,0.000000
110.150002,65.047134,-430.753540,-0.000638,0.004197,0.106616,289.344116,14.739891,1.066159,-430.753540,294.500458,0.000000
110.570007,65.019211,-430.886963,-0.000629,0.004198,0.106625,289.219879,14.733563,1.066250,-430.886963,294.500458,0.000000
110.990005,64.982712,-430.886963,-0.000617,0.004198,0.106634,289.057526,14.725293,1.066341,-430.886963,294.500458,0.000000
111.410004,65.493240,-430.798004,-0.000621,0.004205,0.106816,291.328491,14.840981,1.068158,-430.798004,294.500458,0.000000
111.830002,65.473129,-430.886963,-0.000625,0.004205,0.106807,291.239014,14.836423,1.068067,-430.886963,294.500458,0.000000
112.250008,65.390839,-430.842499,-0.000621,0.004205,0.106807,290.872986,14.817776,1.068067,-430.842499,294.500458,0.000000
112.670006,65.332001,-430.842499,-0.000634,0.004205,0.106807,290.611267,14.804443,1.068067,-430.842499,294.500458,0.000000
113.090004,65.288437,-430.931458,-0.000621,0.004205,0.106816,290.417480,14.794571,1.068158,-430.931458,294.500458,0.000000
113.510002,65.240768,-430.975922,-0.000612,0.004205,0.106816,290.205444,14.783769,1.068158,-430.975922,294.500458,0.000000
113.930008,65.190125,-430.975922,-0.000617,0.004205,0.106816,289.980164,14.772293,1.068158,-430.975922,294.500458,0.000000
114.350006,65.087357,-430.975922,-0.000617,0.004205,0.106816,289.523010,14.749006,1.068158,-430.975922,294.500458,0.000000
114.770004,65.057938,-430.975922,-0.000629,0.004206,0.106834,289.392151,14.742340,1.068340,-430.975922,294.500458,0.000000
115.190002,65.025909,-431.020416,-0.000625,0.004207,0.106851,289.249695,14.735082,1.068506,-431.020416,294.500458,0.000000
115.610008,65.062408,-431.020416,-0.000612,0.004210,0.106946,289.412048,14.743353,1.069460,-431.020416,294.500458,0.000000
116.030006,65.346146,-431.020416,-0.000621,0.004212,0.106990,290.674164,14.807648,1.069899,-431.020416,294.500458,0.000000
116.450005,65.338333,-430.975922,-0.000608,0.004212,0.106990,290.639435,14.805878,1.069899,-430.975922,294.500458,0.000000
116.870003,65.311523,-431.020416,-0.000608,0.004212,0.106990,290.520172,14.799802,1.069899,-431.020416,294.500458,0.000000
117.290009,65.263107,-431.109375,-0.000612,0.004212,0.106990,290.304810,14.788831,1.069899,-431.109375,294.500458,0.000000
117.710007,65.221039,-431.109375,-0.000621,0.004212,0.106990,290.117676,14.779299,1.069899,-431.109375,294.500458,0.000000
118.130005,65.184174,-431.109375,-0.000608,0.004214,0.107025,289.953674,14.770945,1.070247,-431.109375,294.500458,0.000000
118.550003,65.175232,-431.153870,-0.000617,0.004214,0.107025,289.913910,14.768919,1.070247,-431.153870,294.500458,0.000000
118.970009,65.141724,-431.153870,-0.000599,0.004214,0.107032,289.764862,14.761325,1.070323,-431.153870,294.500458,0.000000
119.390007,65.176346,-431.153870,-0.000608,0.004216,0.107076,289.918854,14.769171,1.070762,-431.153870,294.500458,0.000000
119.810005,65.177460,-431.153870,-0.000621,0.004216,0.107076,289.923828,14.769423,1.070762,-431.153870,294.500458,0.000000
120.230003,65.142090,-431.198334,-0.000595,0.004216,0.107076,289.766479,14.761409,1.070762,-431.198334,294.500458,0.000000
120.650009,65.095917,-431.198334,-0.000617,0.004216,0.107076,289.561096,14.750946,1.070762,-431.198334,294.500458,0.000000
121.070007,65.048996,-431.242828,-0.000625,0.004216,0.107076,289.352386,14.740314,1.070762,-431.242828,294.500458,0.000000
121.490005,65.142838,-431.287292,-0.000608,0.004218,0.107146,289.769806,14.761578,1.071458,-431.287292,294.500458,0.000000
121.910004,65.143204,-431.287292,-0.000608,0.004218,0.107146,289.771454,14.761662,1.071458,-431.287292,294.500458,0.000000
122.330009,65.099274,-431.331787,-0.000604,0.004218,0.107146,289.576019,14.751707,1.071458,-431.331787,294.500458,0.000000
122.750008,65.063141,-431.331787,-0.000612,0.004218,0.107146,289.415314,14.743518,1.071458,-431.331787,294.500458,0.000000
123.170006,65.030380,-431.331787,-0.000608,0.004218,0.107146,289.269592,14.736094,1.071458,-431.331787,294.500458,0.000000
123.590004,65.058304,-431.287292,-0.000595,0.004220,0.107197,289.393799,14.742422,1.071973,-431.287292,294.500458,0.000000
124.010002,65.052719,-431.331787,-0.000599,0.004220,0.107197,289.368958,14.741157,1.071973,-431.331787,294.500458,0.000000
124.430008,65.044525,-431.376251,-0.000608,0.004220,0.107197,289.332489,14.739301,1.071973,-431.376251,294.500458,0.000000
124.850006,65.013992,-431.465240,-0.000595,0.004220,0.107197,289.196686,14.732382,1.071973,-431.465240,294.500458,0.000000
125.270004,64.976761,-431.376251,-0.000612,0.004220,0.107197,289.031067,14.723944,1.071973,-431.376251,294.500458,0.000000
125.690002,65.001328,-431.420746,-0.000595,0.004222,0.107241,289.140350,14.729511,1.072412,-431.420746,294.500458,0.000000
126.110008,64.988297,-431.465240,-0.000612,0.004222,0.107249,289.082367,14.726559,1.072488,-431.465240,294.500458,0.000000
126.530006,64.964096,-431.465240,-0.000599,0.004222,0.107249,288.974731,14.721074,1.072488,-431.465240,294.500458,0.000000
126.950005,64.924622,-431.465240,-0.000608,0.004222,0.107249,288.799133,14.712130,1.072488,-431.465240,1681.640747,0.000000
127.370003,64.968567,-431.509705,-0.000595,0.004213,0.107016,288.994629,14.722088,1.070156,-431.509705,0.107007,0.000000
127.790009,64.910477,-431.509705,-0.000591,0.004201,0.106704,288.736206,14.708923,1.067038,-431.509705,0.106304,0.000000
128.210007,64.767853,-431.554199,-0.000582,0.004177,0.106097,288.101807,14.676605,1.060967,-431.554199,0.105611,0.000000
128.630005,64.701202,-431.554199,-0.000578,0.004155,0.105524,287.805328,14.661502,1.055244,-431.554199,0.104908,0.000000
129.050003,64.615189,-431.598663,-0.000573,0.004123,0.104727,287.422699,14.642012,1.047265,-431.598663,0.104206,0.000000
129.470001,64.566025,-431.598663,-0.000578,0.004093,0.103962,287.204010,14.630871,1.039620,-431.598663,0.103512,0.000000
129.889999,64.539215,-431.598663,-0.000569,0.004072,0.103417,287.084778,14.624795,1.034170,-431.598663,0.102810,0.000000
130.310013,64.456558,-431.554199,-0.000591,0.004043,0.102696,286.717102,14.606065,1.026963,-431.554199,0.102107,0.000000
130.730011,64.335907,-431.643158,-0.000582,0.004014,0.101959,286.180420,14.578725,1.019590,-431.643158,0.101405,0.000000
131.150009,64.253983,-431.643158,-0.000591,0.003993,0.101422,285.815979,14.560161,1.014216,-431.643158,0.100710,0.000000
131.570007,63.795593,-431.732117,-0.000582,0.003964,0.100677,283.776978,14.456288,1.006767,-431.732117,0.100008,0.000000
131.990005,63.027390,-431.732117,-0.000569,0.003942,0.100130,280.359833,14.282210,1.001302,-431.732117,0.099305,0.000000
132.410004,61.617584,-431.643158,-0.000552,0.003912,0.099375,274.088715,13.962744,0.993747,-431.643158,0.098612,0.000000
132.830002,59.680878,-431.732117,-0.000565,0.003882,0.098595,265.473816,13.523881,0.985950,-431.732117,0.097909,0.000000
133.250000,58.417046,-431.776581,-0.000565,0.003865,0.098170,259.851990,13.237492,0.981696,-431.776581,0.097207,0.000000
133.670013,56.249466,-431.776581,-0.000556,0.003839,0.097511,250.210114,12.746311,0.975110,-431.776581,0.096504,0.000000
134.090012,53.999588,-431.732117,-0.000548,0.003814,0.096869,240.202164,12.236482,0.968691,-431.732117,0.095811,0.000000
134.510010,51.082420,-431.776581,-0.000539,0.003783,0.096080,227.225952,11.575441,0.960803,-431.776581,0.095108,0.000000
134.930008,47.781342,-431.821075,-0.000556,0.003752,0.095290,212.542023,10.827407,0.952900,-431.821075,0.094406,0.000000
135.350006,45.648766,-431.776581,-0.000548,0.003733,0.094806,203.055847,10.344158,0.948056,-431.776581,0.093703,0.000000
135.770004,43.171371,-431.910034,-0.000548,0.003709,0.094215,192.035858,9.782773,0.942151,-431.910034,0.093010,0.000000
136.190002,39.954071,-431.865540,-0.000548,0.003680,0.093478,177.724579,9.053722,0.934778,-431.865540,0.092308,0.000000
136.610001,36.650757,-431.865540,-0.000548,0.003650,0.092698,163.030716,8.305181,0.926981,-431.865540,0.091605,0.000000
137.030014,33.314674,-431.910034,-0.000552,0.003619,0.091934,148.191071,7.549213,0.919336,-431.910034,0.090912,0.000000
137.450012,30.884941,-431.910034,-0.000556,0.003596,0.091336,137.383072,6.998628,0.913356,-431.910034,0.090209,0.000000
137.870010,27.460976,-431.954529,-0.000552,0.003562,0.090477,122.152519,6.222746,0.904772,-431.954529,0.089507,0.000000
138.290009,24.654404,-431.998993,-0.000552,0.003537,0.089844,109.668266,5.586768,0.898443,-431.998993,0.088804,0.000000
138.710007,21.495567,-431.998993,-0.000548,0.003506,0.089063,95.617058,4.870965,0.890631,-431.998993,0.088109,0.000000
139.130005,18.931038,-431.998993,-0.000552,0.003485,0.088509,84.209465,4.289834,0.885090,-431.998993,0.087407,0.000000
139.550003,16.599991,-431.998993,-0.000556,0.003464,0.087997,73.840446,3.761612,0.879973,-431.998993,0.086704,0.000000
139.970001,12.318451,-432.043488,-0.000586,0.003422,0.086922,54.795208,2.791401,0.869224,-432.043488,0.086002,0.000000
140.389999,9.512627,-432.087952,-0.000569,0.003397,0.086288,42.314278,2.155592,0.862880,-432.087952,0.085308,0.000000
140.810013,6.394753,-432.132446,-0.000586,0.003367,0.085517,28.445280,1.449072,0.855174,-432.132446,0.084606,0.000000
141.230011,4.249138,-432.043488,-0.000591,0.003346,0.084988,18.901110,0.962868,0.849875,-432.043488,0.083904,0.000000
141.650009,2.385414,-432.087952,-0.000604,0.003328,0.084529,10.610852,0.540543,0.845288,-432.087952,0.083210,0.000000
142.070007,-0.770073,-432.176910,-0.000604,0.003293,0.083643,-3.425456,-0.174501,0.836432,-432.176910,0.082508,0.000000
142.490005,-3.375561,-432.176910,-0.000612,0.003264,0.082898,-15.015244,-0.764913,0.828983,-432.176910,0.081805,0.000000
142.910004,-0.209648,-432.176910,-0.000694,0.003230,0.082047,-0.932561,-0.047507,0.820474,-432.176910,0.081103,0.000000
143.330002,-0.060699,-432.176910,-0.000720,0.003204,0.081372,-0.270005,-0.013755,0.813722,-432.176910,0.080409,0.000000
143.750000,0.023087,-432.176910,-0.000767,0.003176,0.080677,0.102694,0.005231,0.806773,-432.176910,0.079707,0.000000
144.170013,-0.023087,-432.221405,-0.000798,0.003149,0.079984,-0.102694,-0.005231,0.799839,-432.221405,0.079004,0.000000
144.590012,0.010796,-432.221405,-0.000841,0.003119,0.079230,0.048021,0.002446,0.792300,-432.221405,0.078309,0.000000
145.010010,0.039093,-432.310364,-0.000854,0.003111,0.079012,0.173894,0.008859,0.790120,-432.310364,0.077607,0.000000
145.430008,0.030159,-432.265869,-0.000892,0.003076,0.078137,0.134154,0.006834,0.781369,-432.265869,0.076906,0.000000
145.850006,-0.013405,-432.265869,-0.000936,0.003036,0.077104,-0.059628,-0.003038,0.771044,-432.265869,0.076204,0.000000
146.270004,-0.005959,-432.265869,-0.001000,0.003012,0.076515,-0.026505,-0.001350,0.765154,-432.265869,0.075509,0.000000
146.690002,0.007446,-432.310364,-0.001022,0.002983,0.075769,0.033123,0.001687,0.757691,-432.310364,0.074806,0.000000
147.110001,0.000740,-432.354858,-0.001056,0.002958,0.075136,0.003292,0.000168,0.751362,-432.354858,0.074104,0.000000
147.530014,-0.007820,-432.354858,-0.001082,0.002929,0.074390,-0.034786,-0.001772,0.743898,-432.354858,0.073401,0.000000
147.950012,-0.034637,-432.399323,-0.001121,0.002904,0.073766,-0.154075,-0.007849,0.737661,-432.399323,0.072708,0.000000
148.370010,-0.015640,-432.310364,-0.001151,0.002870,0.072908,-0.069571,-0.003544,0.729077,-432.310364,0.072005,0.000000
148.790009,-0.030167,-432.399323,-0.001177,0.002849,0.072370,-0.134188,-0.006836,0.723702,-432.399323,0.071303,0.000000
149.210007,-0.004097,-432.532776,-0.001207,0.002824,0.071737,-0.018224,-0.000928,0.717374,-432.532776,0.070609,0.000000
149.630005,0.001114,-432.443817,-0.001246,0.002798,0.071068,0.004955,0.000252,0.710682,-432.443817,0.069907,0.000000
150.050003,0.001114,-432.443817,-0.001289,0.002769,0.070323,0.004955,0.000252,0.703233,-432.443817,0.069205,0.000000
150.470001,-0.008942,-432.443817,-0.001311,0.002741,0.069612,-0.039774,-0.002026,0.696118,-432.443817,0.068502,0.000000
150.890015,-0.016014,-432.488281,-0.001354,0.002713,0.068900,-0.071234,-0.003629,0.689002,-432.488281,0.067809,0.000000
151.310013,-0.016762,-432.532776,-0.001401,0.002680,0.068077,-0.074560,-0.003798,0.680766,-432.532776,0.067106,0.000000
151.730011,-0.052132,-432.577240,-0.001431,0.002654,0.067418,-0.231893,-0.011813,0.674181,-432.577240,0.066404,0.000000
152.150009,-0.055115,-432.532776,-0.001444,0.002630,0.066793,-0.245163,-0.012489,0.667928,-432.532776,0.065709,0.000000
152.570007,-0.062935,-432.488281,-0.001492,0.002599,0.066013,-0.279948,-0.014261,0.660131,-432.488281,0.065006,0.000000
152.990005,-0.020859,-432.577240,-0.001522,0.002569,0.065259,-0.092784,-0.004727,0.652592,-432.577240,0.064304,0.000000
153.410004,-0.045059,-432.621735,-0.001544,0.002547,0.064685,-0.200433,-0.010211,0.646854,-432.621735,0.063601,0.000000
153.830002,-0.077087,-432.621735,-0.001591,0.002515,0.063888,-0.342902,-0.017468,0.638875,-432.621735,0.062908,0.000000
154.250000,-0.054367,-432.621735,-0.001625,0.002481,0.063012,-0.241837,-0.012320,0.630124,-432.621735,0.062206,0.000000
154.670013,-0.030540,-432.666199,-0.001647,0.002465,0.062613,-0.135851,-0.006921,0.626128,-432.666199,0.061503,0.000000
155.090012,-0.049904,-432.621735,-0.001686,0.002435,0.061850,-0.221983,-0.011308,0.618497,-432.621735,0.060801,0.000000
155.510010,-0.066658,-432.755188,-0.001712,0.002406,0.061112,-0.296510,-0.015105,0.611124,-432.755188,0.060107,0.000000
155.930008,-0.087883,-432.710693,-0.001750,0.002379,0.060437,-0.390923,-0.019915,0.604372,-432.710693,0.059405,0.000000
156.350006,-0.059952,-432.799652,-0.001789,0.002351,0.059726,-0.266679,-0.013585,0.597256,-432.799652,0.058702,0.000000
156.770004,-0.041336,-432.755188,-0.001802,0.002326,0.059093,-0.183872,-0.009367,0.590928,-432.755188,0.058009,0.000000
157.190002,-0.029419,-432.710693,-0.001841,0.002300,0.058416,-0.130862,-0.006666,0.584161,-432.710693,0.057306,0.000000
157.610001,-0.061073,-432.755188,-0.001880,0.002267,0.057583,-0.271668,-0.013839,0.575834,-432.755188,0.056604,0.000000
158.030014,-0.047668,-432.844147,-0.001906,0.002242,0.056941,-0.212040,-0.010802,0.569415,-432.844147,0.055901,0.000000
158.450012,-0.030907,-432.888611,-0.001932,0.002217,0.056309,-0.137480,-0.007004,0.563086,-432.888611,0.055208,0.000000
158.870010,-0.033890,-432.888611,-0.001962,0.002191,0.055658,-0.150749,-0.007680,0.556576,-432.888611,0.054506,0.000000
159.290009,-0.043945,-432.888611,-0.001996,0.002159,0.054826,-0.195479,-0.009958,0.548265,-432.888611,0.053803,0.000000
159.710007,-0.036865,-432.888611,-0.002031,0.002132,0.054141,-0.163985,-0.008354,0.541407,-432.888611,0.053108,0.000000
160.130005,-0.020485,-432.888611,-0.002057,0.002100,0.053334,-0.091121,-0.004642,0.533337,-432.888611,0.052406,0.000000
160.550003,-0.033890,-432.933105,-0.002100,0.002080,0.052831,-0.150749,-0.007680,0.528311,-432.933105,0.051703,0.000000
160.970001,-0.042824,-432.933105,-0.002117,0.002060,0.052319,-0.190490,-0.009704,0.523194,-432.933105,0.051001,0.000000
161.390015,-0.022720,-432.888611,-0.002169,0.002014,0.051166,-0.101065,-0.005149,0.511657,-432.888611,0.050307,0.000000
161.810013,-0.032028,-433.022064,-0.002177,0.001995,0.050672,-0.142469,-0.007258,0.506722,-433.022064,0.049605,0.000000
162.230011,-0.014900,-432.933105,-0.002225,0.001965,0.049917,-0.066279,-0.003376,0.499167,-432.933105,0.048902,0.000000
162.650009,-0.012291,-433.022064,-0.002229,0.001942,0.049328,-0.054673,-0.002785,0.493278,-433.022064,0.048200,0.000000
163.070007,-0.027931,-433.022064,-0.002272,0.001908,0.048460,-0.124244,-0.006329,0.484603,-433.022064,0.047506,0.000000
163.490005,-0.035004,-433.066528,-0.002302,0.001881,0.047767,-0.155704,-0.007932,0.477669,-433.066528,0.046804,0.000000
163.910004,0.007820,-433.022064,-0.002341,0.001847,0.046925,0.034786,0.001772,0.469251,-433.022064,0.046102,0.000000
164.330002,0.029411,-433.066528,-0.002354,0.001831,0.046518,0.130828,0.006665,0.465179,-433.066528,0.045408,0.000000
164.750015,0.023087,-433.111023,-0.002402,0.001804,0.045832,0.102694,0.005231,0.458320,-433.111023,0.044706,0.000000
165.170013,-0.016388,-433.155487,-0.002453,0.001769,0.044931,-0.072897,-0.003714,0.449312,-433.155487,0.044003,0.000000
165.590012,-0.032768,-433.155487,-0.002436,0.001743,0.044280,-0.145760,-0.007425,0.442802,-433.155487,0.043301,0.000000
166.010010,0.033882,-433.155487,-0.002488,0.001718,0.043647,0.150715,0.007678,0.436474,-433.155487,0.042606,0.000000
166.430008,0.043564,-433.155487,-0.002514,0.001689,0.042901,0.193782,0.009872,0.429010,-433.155487,0.041903,0.000000
166.850006,0.015266,-433.155487,-0.002548,0.001661,0.042199,0.067908,0.003459,0.421986,-433.155487,0.041202,0.000000
167.270004,-0.019363,-433.244476,-0.002574,0.001631,0.041426,-0.086133,-0.004388,0.414264,-433.244476,0.040507,0.000000
167.690002,-0.000374,-433.244476,-0.002600,0.001606,0.040803,-0.001663,-0.000085,0.408027,-433.244476,0.039805,0.000000
168.110001,0.007072,-433.244476,-0.002626,0.001579,0.040100,0.031460,0.001603,0.401002,-433.244476,0.039103,0.000000
168.530014,0.001862,-433.244476,-0.002660,0.001552,0.039423,0.008281,0.000422,0.394235,-433.244476,0.038400,0.000000
168.950012,-0.001862,-433.244476,-0.002690,0.001524,0.038721,-0.008281,-0.000422,0.387210,-433.244476,0.037707,0.000000
169.370010,-0.027184,-433.333435,-0.002733,0.001497,0.038019,-0.120918,-0.006160,0.380193,-433.333435,0.037004,0.000000
169.790009,-0.013405,-433.333435,-0.002751,0.001467,0.037255,-0.059628,-0.003038,0.372555,-433.333435,0.036302,0.000000
170.210007,-0.039474,-433.288940,-0.002781,0.001443,0.036657,-0.175591,-0.008945,0.366575,-433.288940,0.035599,0.000000
170.630005,-0.013405,-433.333435,-0.002811,0.001425,0.036189,-0.059628,-0.003038,0.361889,-433.333435,0.034906,0.000000
171.050003,-0.026070,-433.333435,-0.002846,0.001390,0.035305,-0.115964,-0.005907,0.353047,-433.333435,0.034203,0.000000
171.470001,0.004837,-433.377899,-0.002889,0.001367,0.034732,0.021516,0.001096,0.347325,-433.377899,0.034576,0.000000
171.600006,-0.007080,-433.333435,-0.002884,0.001368,0.034749,-0.031494,-0.001604,0.347491,-433.333435,0.034576,0.000000