File: Data/compression 29/AutoNoHeating-17-29-reverse-2-3_10232024_184712.csv
Time (sec),S:Load (lbs),S:HL1 (DIM),S:LVDT (in),S:Position (in),Ch:Position (mm),Ch:Load (N),Ch:Stress (MPa),Ch:Strain (mm/mm),Ch:HL1 (DIM),Set Point (),Cycles ()
0.110000,-0.046921,-434.801300,-0.011020,-0.006072,-0.154237,-0.208714,-0.010632,-1.542367,-434.801300,-0.154029,0.000000
0.530000,0.032768,-434.801300,-0.011025,-0.005974,-0.151730,0.145760,0.007425,-1.517304,-434.801300,-0.150941,0.000000
0.950000,0.008186,-434.801300,-0.010831,-0.005711,-0.145070,0.036415,0.001855,-1.450697,-434.801300,-0.143951,0.000000
1.370000,-0.049904,-434.890259,-0.010537,-0.005439,-0.138149,-0.221983,-0.011308,-1.381494,-434.890259,-0.136944,0.000000
1.790000,-0.064423,-434.890259,-0.010266,-0.005163,-0.131142,-0.286566,-0.014598,-1.311421,-434.890259,-0.129954,0.000000
2.210000,0.019363,-434.934753,-0.009964,-0.004885,-0.124074,0.086133,0.004388,-1.240742,-434.934753,-0.122947,0.000000
2.630000,0.049896,-434.934753,-0.009688,-0.004614,-0.117197,0.221950,0.011307,-1.171970,-434.934753,-0.115957,0.000000
3.050000,0.007072,-434.934753,-0.009434,-0.004342,-0.110285,0.031460,0.001603,-1.102850,-434.934753,-0.108967,0.000000
3.470000,-0.032028,-434.934753,-0.009123,-0.004055,-0.102992,-0.142469,-0.007258,-1.029923,-434.934753,-0.101960,0.000000
3.890000,-0.060699,-435.023712,-0.008856,-0.003786,-0.096176,-0.270005,-0.013755,-0.961757,-435.023712,-0.094970,0.000000
4.310000,0.007820,-435.023712,-0.008567,-0.003510,-0.089160,0.034786,0.001772,-0.891600,-435.023712,-0.087963,0.000000
4.730000,0.020477,-434.934753,-0.008300,-0.003233,-0.082110,0.091088,0.004640,-0.821095,-434.934753,-0.080973,0.000000
5.150000,0.036865,-435.023712,-0.008019,-0.002962,-0.075232,0.163985,0.008354,-0.752324,-435.023712,-0.073966,0.000000
5.570000,0.002975,-435.023712,-0.007748,-0.002686,-0.068233,0.013236,0.000674,-0.682333,-435.023712,-0.066976,0.000000
5.990000,-0.060326,-435.112671,-0.007429,-0.002402,-0.061009,-0.268342,-0.013670,-0.610095,-435.112671,-0.059986,0.000000
6.410000,0.023827,-435.068176,-0.007161,-0.002132,-0.054159,0.105986,0.005399,-0.541588,-435.068176,-0.052979,0.000000
6.830000,0.024574,-435.068176,-0.006860,-0.001853,-0.047056,0.109312,0.005569,-0.470561,-435.068176,-0.045990,0.000000
7.250000,0.057716,-435.068176,-0.006592,-0.001579,-0.040118,0.256735,0.013079,-0.401184,-435.068176,-0.038982,0.000000
7.670001,0.042076,-435.157135,-0.006325,-0.001307,-0.033189,0.187164,0.009535,-0.331890,-435.157135,-0.031992,0.000000
8.090000,-0.018997,-435.112671,-0.006032,-0.001029,-0.026147,-0.084504,-0.004305,-0.261468,-435.112671,-0.025002,0.000000
8.510000,0.035004,-435.157135,-0.005756,-0.000755,-0.019174,0.155704,0.007932,-0.191743,-435.157135,-0.017995,0.000000
8.930000,0.013405,-435.157135,-0.005445,-0.000477,-0.012124,0.059628,0.003038,-0.121238,-435.157135,-0.011006,0.000000
9.350000,0.049522,-435.201630,-0.005182,-0.000206,-0.005221,0.220287,0.011222,-0.052209,-435.201630,-0.003998,0.000000
9.770000,0.189537,-435.201630,-0.004928,-0.000005,-0.000139,0.843103,0.042950,-0.001393,-435.201630,0.000113,0.000000
10.190001,0.170540,-435.201630,-0.004937,-0.000005,-0.000139,0.758599,0.038645,-0.001393,-435.201630,0.000113,0.000000
10.610001,0.098305,-435.246094,-0.004928,-0.000005,-0.000122,0.437281,0.022276,-0.001219,-435.246094,0.000746,0.000000
11.030001,0.184692,-435.290588,-0.004928,0.000022,0.000555,0.821553,0.041852,0.005549,-435.290588,0.001440,0.000000
11.450001,0.300499,-435.335083,-0.004889,0.000042,0.001057,1.336686,0.068094,0.010575,-435.335083,0.002142,0.000000
11.870001,0.482216,-435.246094,-0.004876,0.000066,0.001682,2.145003,0.109272,0.016820,-435.246094,0.002844,0.000000
12.290001,0.915291,-435.335083,-0.004833,0.000105,0.002662,4.071417,0.207408,0.026623,-435.335083,0.003538,0.000000
12.710001,1.269791,-435.335083,-0.004825,0.000131,0.003330,5.648311,0.287739,0.033300,-435.335083,0.004241,0.000000
13.130001,1.821640,-435.379547,-0.004790,0.000160,0.004058,8.103060,0.412790,0.040582,-435.379547,0.004943,0.000000
13.550000,2.229767,-435.335083,-0.004777,0.000184,0.004665,9.918498,0.505272,0.046653,-435.335083,0.005646,0.000000
13.970000,2.931686,-435.379547,-0.004751,0.000220,0.005576,13.040792,0.664330,0.055759,-435.379547,0.006339,0.000000
14.390000,3.214317,-435.424042,-0.004738,0.000240,0.006088,14.297997,0.728375,0.060876,-435.424042,0.007041,0.000000
14.810000,3.857033,-435.424042,-0.004704,0.000267,0.006790,17.156939,0.874016,0.067901,-435.424042,0.007744,0.000000
15.230000,4.354523,-435.468506,-0.004687,0.000293,0.007432,19.369884,0.986749,0.074320,-435.468506,0.008446,0.000000
15.650001,4.760780,-435.468506,-0.004652,0.000317,0.008047,21.177008,1.078808,0.080474,-435.468506,0.009141,0.000000
16.070002,5.521912,-435.468506,-0.004626,0.000355,0.009010,24.562689,1.251283,0.090103,-435.468506,0.009843,0.000000
16.490002,5.860764,-435.513000,-0.004605,0.000377,0.009574,26.069979,1.328068,0.095743,-435.513000,0.010545,0.000000
16.910002,6.312828,-435.468506,-0.004592,0.000402,0.010207,28.080862,1.430507,0.102071,-435.468506,0.011239,0.000000
17.330000,6.692276,-435.601959,-0.004566,0.000427,0.010840,29.768730,1.516491,0.108399,-435.601959,0.011941,0.000000
17.750000,7.553574,-435.601959,-0.004544,0.000465,0.011803,33.599972,1.711664,0.118028,-435.601959,0.012644,0.000000
18.170000,7.781464,-435.601959,-0.004510,0.000490,0.012445,34.613678,1.763305,0.124447,-435.601959,0.013346,0.000000
18.590000,8.170593,-435.513000,-0.004493,0.000517,0.013121,36.344612,1.851483,0.131207,-435.513000,0.014040,0.000000
19.010000,8.647606,-435.557465,-0.004467,0.000544,0.013806,38.466473,1.959576,0.138058,-435.557465,0.014743,0.000000
19.430000,8.898956,-435.690918,-0.004449,0.000565,0.014361,39.584534,2.016532,0.143614,-435.690918,0.015445,0.000000
19.850000,9.499962,-435.646423,-0.004419,0.000597,0.015168,42.257942,2.152722,0.151676,-435.646423,0.016139,0.000000
20.270000,9.718918,-435.646423,-0.004381,0.000624,0.015844,43.231907,2.202338,0.158443,-435.646423,0.016841,0.000000
20.690001,10.199654,-435.690918,-0.004355,0.000655,0.016625,45.370327,2.311275,0.166248,-435.690918,0.017544,0.000000
21.110001,10.382111,-435.690918,-0.004355,0.000676,0.017180,46.181934,2.352620,0.171796,-435.690918,0.018246,0.000000
21.530001,10.488609,-435.779877,-0.004324,0.000695,0.017665,46.655663,2.376753,0.176649,-435.779877,0.018940,0.000000
21.950001,11.021851,-435.779877,-0.004290,0.000727,0.018454,49.027641,2.497587,0.184544,-435.779877,0.019643,0.000000
22.370001,11.482849,-435.690918,-0.004268,0.000760,0.019304,51.078262,2.602051,0.193045,-435.690918,0.020345,0.000000
22.790001,11.792290,-435.690918,-0.004225,0.000786,0.019972,52.454723,2.672171,0.199721,-435.690918,0.021047,0.000000
23.210001,12.311745,-435.779877,-0.004217,0.000816,0.020735,54.765377,2.789881,0.207352,-435.779877,0.021741,0.000000
23.630001,12.922066,-435.779877,-0.004186,0.000848,0.021550,57.480221,2.928182,0.215504,-435.779877,0.022444,0.000000
24.050001,13.050903,-435.913330,-0.004165,0.000874,0.022210,58.053318,2.957377,0.222098,-435.913330,0.023146,0.000000
24.470001,13.463867,-435.824371,-0.004148,0.000905,0.022990,59.890274,3.050956,0.229902,-435.824371,0.023840,0.000000
24.890001,13.784477,-435.824371,-0.004105,0.000931,0.023640,61.316418,3.123607,0.236405,-435.824371,0.024542,0.000000
25.310001,13.799004,-435.779877,-0.004092,0.000947,0.024057,61.381035,3.126899,0.240568,-435.779877,0.025244,0.000000
25.730001,14.497574,-435.824371,-0.004053,0.000983,0.024958,64.488426,3.285197,0.249584,-435.824371,0.025947,0.000000
26.150002,14.879257,-435.868835,-0.004044,0.001012,0.025705,66.186241,3.371688,0.257047,-435.868835,0.026641,0.000000
26.570002,15.195770,-435.957794,-0.004023,0.001039,0.026390,67.594162,3.443411,0.263898,-435.957794,0.027344,0.000000
26.990002,15.119812,-435.913330,-0.003980,0.001060,0.026918,67.256287,3.426198,0.269182,-435.913330,0.028046,0.000000
27.410002,15.201729,-435.913330,-0.003971,0.001080,0.027439,67.620667,3.444761,0.274390,-435.913330,0.028749,0.000000
27.830002,16.077179,-435.957794,-0.003928,0.001120,0.028453,71.514862,3.643141,0.284533,-435.957794,0.029442,0.000000
28.250002,16.208252,-436.046753,-0.003906,0.001145,0.029087,72.097908,3.672842,0.290869,-436.046753,0.030144,0.000000
28.670002,16.626427,-436.002289,-0.003885,0.001177,0.029901,73.958038,3.767602,0.299014,-436.002289,0.030847,0.000000
29.090002,16.855438,-436.046753,-0.003842,0.001201,0.030509,74.976730,3.819497,0.305085,-436.046753,0.031541,0.000000
29.510002,17.076996,-436.002289,-0.003820,0.001227,0.031177,75.962273,3.869702,0.311769,-436.002289,0.032244,0.000000
29.930002,17.534645,-435.957794,-0.003798,0.001259,0.031975,77.997993,3.973407,0.319748,-435.957794,0.032946,0.000000
30.350002,17.292229,-436.046753,-0.003790,0.001282,0.032555,76.919678,3.918475,0.325554,-436.046753,0.033648,0.000000
30.770002,17.960640,-436.135712,-0.003738,0.001312,0.033328,79.892914,4.069939,0.333275,-436.135712,0.034342,0.000000
31.190001,17.807968,-436.135712,-0.003729,0.001333,0.033848,79.213799,4.035343,0.338476,-436.135712,0.035044,0.000000
31.610001,18.783585,-436.091248,-0.003682,0.001369,0.034784,83.553558,4.256421,0.347839,-436.091248,0.035747,0.000000
32.030003,18.706131,-436.091248,-0.003656,0.001395,0.035426,83.209030,4.238870,0.354259,-436.091248,0.036441,0.000000
32.450001,19.078499,-436.135712,-0.003643,0.001425,0.036206,84.865402,4.323249,0.362063,-436.135712,0.037143,0.000000
32.870003,19.171593,-436.224701,-0.003617,0.001453,0.036918,85.279503,4.344345,0.369179,-436.224701,0.037846,0.000000
33.290001,19.917458,-436.224701,-0.003600,0.001485,0.037725,88.597275,4.513361,0.377248,-436.224701,0.038548,0.000000
33.710003,19.579338,-436.180206,-0.003548,0.001506,0.038244,87.093246,4.436741,0.382441,-436.180206,0.039242,0.000000
34.130001,19.775208,-436.224701,-0.003527,0.001534,0.038956,87.964516,4.481126,0.389557,-436.224701,0.039944,0.000000
34.550003,20.177002,-436.224701,-0.003492,0.001563,0.039702,89.751785,4.572174,0.397020,-436.224701,0.040647,0.000000
34.970001,20.068642,-436.269165,-0.003488,0.001583,0.040196,89.269775,4.547619,0.401956,-436.269165,0.041349,0.000000
35.390003,20.979088,-436.224701,-0.003441,0.001623,0.041219,93.319641,4.753930,0.412190,-436.224701,0.042043,0.000000
35.810001,20.668159,-436.269165,-0.003436,0.001644,0.041756,91.936562,4.683472,0.417565,-436.269165,0.042745,0.000000
36.230003,20.819344,-436.269165,-0.003397,0.001671,0.042433,92.609062,4.717731,0.424332,-436.269165,0.043448,0.000000
36.650002,20.979088,-436.358124,-0.003376,0.001693,0.043005,93.319641,4.753930,0.430055,-436.358124,0.044141,0.000000
37.070004,21.412529,-436.269165,-0.003354,0.001724,0.043787,95.247688,4.852148,0.437867,-436.269165,0.044843,0.000000
37.490002,21.914864,-436.358124,-0.003316,0.001755,0.044585,97.482185,4.965979,0.445845,-436.358124,0.045546,0.000000
37.910004,21.781921,-436.358124,-0.003285,0.001781,0.045234,96.890823,4.935854,0.452340,-436.358124,0.046248,0.000000
38.330002,21.689575,-436.358124,-0.003251,0.001804,0.045824,96.480049,4.914928,0.458245,-436.358124,0.046943,0.000000
38.750000,22.582153,-436.358124,-0.003234,0.001837,0.046648,100.450432,5.117189,0.466481,-436.358124,0.047646,0.000000
39.170002,23.250191,-436.358124,-0.003225,0.001872,0.047541,103.422012,5.268569,0.475413,-436.358124,0.048348,0.000000
39.590000,23.097519,-436.491577,-0.003182,0.001895,0.048130,102.742897,5.233973,0.481302,-436.491577,0.049042,0.000000
40.010002,23.281097,-436.447083,-0.003169,0.001921,0.048798,103.559494,5.275572,0.487979,-436.447083,0.049744,0.000000
40.430000,23.439728,-436.491577,-0.003122,0.001947,0.049449,104.265114,5.311518,0.494489,-436.491577,0.050447,0.000000
40.850002,23.427811,-436.491577,-0.003109,0.001969,0.050012,104.212105,5.308818,0.500121,-436.491577,0.051149,0.000000
41.270000,24.255966,-436.491577,-0.003083,0.002001,0.050837,107.895927,5.496480,0.508372,-436.491577,0.051842,0.000000
41.690002,24.676003,-436.491577,-0.003065,0.002031,0.051582,109.764343,5.591662,0.515821,-436.491577,0.052545,0.000000
42.110001,25.008904,-436.536041,-0.003022,0.002058,0.052268,111.245155,5.667099,0.522679,-436.536041,0.053247,0.000000
42.530003,24.670792,-436.580536,-0.003005,0.002077,0.052754,109.741165,5.590481,0.527539,-436.580536,0.053950,0.000000
42.950001,25.973351,-436.536041,-0.002984,0.002116,0.053750,115.535233,5.885645,0.537501,-436.536041,0.054643,0.000000
43.370003,26.085060,-436.625031,-0.002953,0.002142,0.054410,116.032143,5.910959,0.544101,-436.625031,0.055346,0.000000
43.790001,26.444031,-436.625031,-0.002923,0.002171,0.055138,117.628922,5.992303,0.551383,-436.625031,0.056048,0.000000
44.210003,26.653671,-436.669495,-0.002910,0.002195,0.055753,118.561455,6.039808,0.557530,-436.669495,0.056743,0.000000
44.630001,26.756073,-436.625031,-0.002871,0.002222,0.056448,119.016960,6.063013,0.564479,-436.625031,0.057444,0.000000
45.050003,27.500450,-436.669495,-0.002854,0.002251,0.057185,122.328110,6.231691,0.571852,-436.669495,0.058147,0.000000
45.470001,27.804306,-436.625031,-0.002824,0.002281,0.057930,123.679733,6.300546,0.579301,-436.625031,0.058849,0.000000
45.890003,28.273491,-436.669495,-0.002785,0.002309,0.058642,125.766769,6.406865,0.586416,-436.669495,0.059544,0.000000
46.310001,28.278709,-436.758453,-0.002772,0.002331,0.059197,125.789986,6.408047,0.591973,-436.758453,0.060246,0.000000
46.730003,28.419838,-436.713989,-0.002751,0.002354,0.059795,126.417755,6.440027,0.597953,-436.713989,0.060949,0.000000
47.150002,29.463226,-436.713989,-0.002733,0.002389,0.060670,131.058975,6.676463,0.606704,-436.713989,0.061642,0.000000
47.570004,29.624458,-436.713989,-0.002708,0.002415,0.061330,131.776169,6.712998,0.613304,-436.713989,0.062345,0.000000
47.990002,30.104446,-436.802948,-0.002669,0.002446,0.062128,133.911270,6.821765,0.621283,-436.802948,0.063047,0.000000
48.410004,30.044121,-436.847412,-0.002652,0.002469,0.062717,133.642929,6.808095,0.627172,-436.847412,0.063750,0.000000
48.830002,31.601761,-436.758453,-0.002639,0.002500,0.063489,140.571655,7.161061,0.634893,-436.758453,0.064443,0.000000
49.250004,31.860184,-436.802948,-0.002604,0.002526,0.064166,141.721176,7.219621,0.641661,-436.802948,0.065146,0.000000
49.670002,31.991257,-436.758453,-0.002591,0.002551,0.064808,142.304214,7.249322,0.648080,-436.758453,0.065848,0.000000
50.090004,32.952728,-436.802948,-0.002561,0.002581,0.065553,146.581055,7.467195,0.655529,-436.802948,0.066551,0.000000
50.510002,32.886444,-436.847412,-0.002548,0.002601,0.066074,146.286209,7.452175,0.660737,-436.847412,0.067244,0.000000
50.930004,33.888870,-436.847412,-0.002518,0.002634,0.066897,150.745224,7.679328,0.668973,-436.847412,0.067946,0.000000
51.350002,34.467911,-436.891907,-0.002505,0.002662,0.067625,153.320923,7.810540,0.676255,-436.891907,0.068649,0.000000
51.770004,35.391396,-436.936371,-0.002470,0.002693,0.068407,157.428787,8.019805,0.684067,-436.936371,0.069344,0.000000
52.190002,35.357132,-436.891907,-0.002453,0.002712,0.068893,157.276382,8.012041,0.688927,-436.891907,0.070046,0.000000
52.610001,35.563057,-436.980865,-0.002436,0.002736,0.069491,158.192383,8.058703,0.694907,-436.980865,0.070749,0.000000
53.030003,36.969879,-436.980865,-0.002397,0.002773,0.070428,164.450241,8.377495,0.704278,-436.980865,0.071451,0.000000
53.450001,37.528069,-436.980865,-0.002367,0.002799,0.071103,166.933182,8.503983,0.711030,-436.980865,0.072145,0.000000
53.870003,38.404633,-436.980865,-0.002354,0.002829,0.071849,170.832336,8.702615,0.718494,-436.980865,0.072847,0.000000
54.290001,38.950157,-436.980865,-0.002333,0.002853,0.072473,173.258957,8.826231,0.724732,-436.980865,0.073550,0.000000
54.710003,40.455658,-437.114319,-0.002315,0.002891,0.073428,179.955750,9.167383,0.734285,-437.114319,0.074243,0.000000
55.130001,40.428848,-437.025330,-0.002298,0.002912,0.073966,179.836502,9.161308,0.739659,-437.025330,0.074945,0.000000
55.550003,41.292381,-437.069824,-0.002268,0.002942,0.074729,183.677689,9.356987,0.747290,-437.069824,0.075648,0.000000
55.970001,41.620811,-437.158783,-0.002229,0.002964,0.075283,185.138611,9.431410,0.752831,-437.158783,0.076350,0.000000
56.390003,41.961906,-437.025330,-0.002216,0.002989,0.075925,186.655884,9.508704,0.759250,-437.025330,0.077044,0.000000
56.810001,43.944046,-437.158783,-0.002203,0.003025,0.076844,195.472885,9.957863,0.768440,-437.158783,0.077746,0.000000
57.230003,43.809990,-437.158783,-0.002177,0.003045,0.077348,194.876572,9.927485,0.773481,-437.158783,0.078449,0.000000
57.650002,45.288681,-437.203278,-0.002156,0.003077,0.078163,201.454117,10.262562,0.781626,-437.203278,0.079151,0.000000
58.070004,45.582108,-437.158783,-0.002143,0.003101,0.078770,202.759338,10.329053,0.787697,-437.158783,0.079845,0.000000
58.490002,47.510628,-437.158783,-0.002121,0.003137,0.079681,211.337830,10.766062,0.796811,-437.158783,0.080547,0.000000
58.910004,48.125038,-437.203278,-0.002108,0.003160,0.080270,214.070862,10.905290,0.802701,-437.203278,0.081250,0.000000
59.330002,48.839249,-437.158783,-0.002074,0.003185,0.080903,217.247833,11.067132,0.809029,-437.158783,0.081944,0.000000
59.750004,50.204369,-437.292236,-0.002057,0.003216,0.081693,223.320190,11.376472,0.816932,-437.292236,0.082647,0.000000
60.170002,50.685478,-437.292236,-0.002039,0.003235,0.082178,225.460266,11.485494,0.821776,-437.292236,0.083349,0.000000
60.590004,52.802788,-437.247742,-0.002013,0.003275,0.083175,234.878525,11.965283,0.831753,-437.247742,0.084052,0.000000
61.010002,53.188934,-437.247742,-0.002005,0.003297,0.083748,236.596191,12.052785,0.837476,-437.247742,0.084745,0.000000
61.430004,54.355202,-437.336700,-0.001988,0.003325,0.084450,241.784012,12.317064,0.844501,-437.336700,0.085448,0.000000
61.850002,55.040741,-437.381195,-0.001962,0.003346,0.084997,244.833450,12.472410,0.849966,-437.381195,0.086150,0.000000
62.270004,55.582542,-437.336700,-0.001932,0.003372,0.085639,247.243500,12.595184,0.856385,-437.336700,0.086844,0.000000
62.690002,57.821991,-437.381195,-0.001919,0.003406,0.086523,257.205048,13.102651,0.865227,-437.381195,0.087546,0.000000
63.110004,58.921234,-437.381195,-0.001906,0.003433,0.087199,262.094727,13.351742,0.871994,-437.381195,0.088249,0.000000
63.530003,60.330292,-437.425659,-0.001893,0.003464,0.087979,268.362549,13.671040,0.879791,-437.425659,0.088951,0.000000
63.950005,61.259735,-437.470154,-0.001893,0.003488,0.088595,272.496918,13.881655,0.885953,-437.470154,0.089644,0.000000
64.370003,62.844177,-437.425659,-0.001850,0.003518,0.089367,279.544861,14.240694,0.893674,-437.425659,0.090347,0.000000
64.790001,64.230530,-437.425659,-0.001828,0.003546,0.090070,285.711670,14.554846,0.900699,-437.425659,0.091049,0.000000
65.210007,65.548721,-437.514648,-0.001828,0.003573,0.090756,291.575287,14.853553,0.907557,-437.514648,0.091752,0.000000
65.630005,65.653732,-437.470154,-0.001802,0.003582,0.090972,292.042389,14.877348,0.909722,-437.470154,0.015971,0.000000
66.050003,65.542023,-437.514648,-0.001794,0.003595,0.091301,291.545471,14.852035,0.913007,-437.514648,294.500458,0.000000
66.470001,65.008041,-437.559113,-0.001785,0.003608,0.091649,289.170197,14.731032,0.916490,-437.559113,294.500458,0.000000
66.889999,65.019958,-437.559113,-0.001763,0.003619,0.091935,289.223206,14.733733,0.919351,-437.559113,294.500458,0.000000
67.310005,65.137619,-437.559113,-0.001759,0.003631,0.092238,289.746613,14.760396,0.922379,-437.559113,294.500458,0.000000
67.730003,66.338516,-437.559113,-0.001733,0.003619,0.091935,295.088470,15.032523,0.919351,-437.559113,294.500458,0.000000
68.150002,65.235184,-437.648071,-0.001729,0.003644,0.092568,290.180603,14.782503,0.925679,-437.648071,294.500458,0.000000
68.570000,65.890930,-437.603607,-0.001725,0.003659,0.092931,293.097504,14.931098,0.929313,-437.603607,294.500458,0.000000
68.990005,65.468658,-437.603607,-0.001707,0.003674,0.093313,291.219147,14.835410,0.933128,-437.603607,294.500458,0.000000
69.410004,65.091827,-437.648071,-0.001699,0.003677,0.093408,289.542908,14.750019,0.934082,-437.648071,294.500458,0.000000
69.830002,65.253433,-437.692566,-0.001707,0.003688,0.093687,290.261780,14.786639,0.936867,-437.692566,294.500458,0.000000
70.250000,65.495468,-437.737030,-0.001707,0.003697,0.093903,291.338379,14.841485,0.939032,-437.737030,294.500458,0.000000
70.670006,65.605316,-437.737030,-0.001699,0.003706,0.094138,291.827026,14.866377,0.941379,-437.737030,294.500458,0.000000
71.090004,65.065384,-437.692566,-0.001681,0.003712,0.094285,289.425293,14.744026,0.942848,-437.692566,294.500458,0.000000
71.510002,65.335724,-437.737030,-0.001664,0.003716,0.094389,290.627808,14.805286,0.943892,-437.737030,294.500458,0.000000
71.930000,65.582611,-437.737030,-0.001673,0.003727,0.094666,291.726013,14.861233,0.946663,-437.737030,294.500458,0.000000
72.350006,65.187897,-437.825989,-0.001673,0.003727,0.094666,289.970245,14.771788,0.946663,-437.825989,294.500458,0.000000
72.770004,64.871368,-437.870483,-0.001673,0.003730,0.094743,288.562256,14.700063,0.947435,-437.870483,294.500458,0.000000
73.190002,65.568085,-437.825989,-0.001647,0.003742,0.095039,291.661407,14.857941,0.950387,-437.825989,294.500458,0.000000
73.610001,65.054962,-437.781525,-0.001647,0.003742,0.095039,289.378937,14.741665,0.950387,-437.781525,294.500458,0.000000
74.030006,64.768234,-437.825989,-0.001647,0.003757,0.095429,288.103485,14.676692,0.954293,-437.825989,294.500458,0.000000
74.450005,65.814590,-437.870483,-0.001638,0.003752,0.095308,292.757935,14.913799,0.953082,-437.870483,294.500458,0.000000
74.870003,65.315613,-437.959442,-0.001630,0.003753,0.095317,290.538361,14.800730,0.953173,-437.959442,294.500458,0.000000
75.290001,66.017914,-437.870483,-0.001625,0.003766,0.095655,293.662354,14.959873,0.956549,-437.870483,294.500458,0.000000
75.710007,65.502548,-437.914978,-0.001621,0.003766,0.095655,291.369873,14.843089,0.956549,-437.914978,294.500458,0.000000
76.130005,65.024414,-437.914978,-0.001625,0.003766,0.095655,289.243042,14.734743,0.956549,-437.914978,294.500458,0.000000
76.550003,65.679794,-437.914978,-0.001617,0.003779,0.095993,292.158325,14.883254,0.959925,-437.914978,294.500458,0.000000
76.970001,65.315613,-438.048401,-0.001617,0.003780,0.096002,290.538361,14.800730,0.960016,-438.048401,294.500458,0.000000
77.390007,65.015488,-438.003937,-0.001625,0.003781,0.096036,289.203339,14.732720,0.960364,-438.003937,294.500458,0.000000
77.810005,65.196091,-437.959442,-0.001595,0.003787,0.096183,290.006683,14.773645,0.961833,-437.959442,294.500458,0.000000
78.230003,64.990906,-438.003937,-0.001604,0.003788,0.096227,289.093994,14.727150,0.962272,-438.003937,294.500458,0.000000
78.650002,65.513718,-438.003937,-0.001621,0.003797,0.096453,291.419556,14.845620,0.964527,-438.003937,294.500458,0.000000
79.070007,65.232208,-438.003937,-0.001600,0.003798,0.096462,290.167358,14.781830,0.964618,-438.003937,294.500458,0.000000
79.490005,65.024048,-438.137360,-0.001604,0.003799,0.096504,289.241425,14.734660,0.965042,-438.137360,294.500458,0.000000
79.910004,65.180450,-438.003937,-0.001587,0.003804,0.096627,289.937134,14.770102,0.966269,-438.003937,294.500458,0.000000
80.330002,65.288803,-438.092896,-0.001578,0.003809,0.096739,290.419098,14.794654,0.967389,-438.092896,294.500458,0.000000
80.750008,65.060547,-438.092896,-0.001582,0.003809,0.096756,289.403778,14.742930,0.967555,-438.092896,294.500458,0.000000
81.170006,65.126816,-438.092896,-0.001582,0.003813,0.096851,289.698547,14.757947,0.968509,-438.092896,294.500458,0.000000
81.590004,65.217316,-438.092896,-0.001574,0.003817,0.096946,290.101105,14.778456,0.969463,-438.092896,294.500458,0.000000
82.010002,65.558777,-438.181854,-0.001565,0.003824,0.097129,291.619995,14.855831,0.971295,-438.181854,294.500458,0.000000
82.430000,65.423599,-438.137360,-0.001574,0.003824,0.097129,291.018707,14.825199,0.971295,-438.137360,294.500458,0.000000
82.850006,65.238159,-438.181854,-0.001565,0.003827,0.097207,290.193817,14.783178,0.972067,-438.181854,294.500458,0.000000
83.270004,65.271301,-438.226318,-0.001582,0.003828,0.097225,290.341248,14.790689,0.972249,-438.226318,294.500458,0.000000
83.690002,65.642181,-438.226318,-0.001574,0.003835,0.097416,291.990997,14.874731,0.974156,-438.226318,294.500458,0.000000
84.110001,65.543884,-438.270813,-0.001569,0.003835,0.097416,291.553772,14.852456,0.974156,-438.270813,294.500458,0.000000
84.530006,65.320831,-438.270813,-0.001574,0.003836,0.097425,290.561584,14.801912,0.974247,-438.270813,294.500458,0.000000
84.950005,65.133530,-438.226318,-0.001561,0.003836,0.097432,289.728424,14.759469,0.974323,-438.226318,294.500458,0.000000
85.370003,65.779221,-438.270813,-0.001569,0.003845,0.097658,292.600586,14.905785,0.976579,-438.270813,294.500458,0.000000
85.790001,65.601227,-438.359772,-0.001552,0.003845,0.097658,291.808838,14.865450,0.976579,-438.359772,294.500458,0.000000
86.210007,65.380402,-438.359772,-0.001552,0.003845,0.097658,290.826538,14.815411,0.976579,-438.359772,294.500458,0.000000
86.630005,65.207626,-438.359772,-0.001548,0.003845,0.097658,290.058014,14.776259,0.976579,-438.359772,294.500458,0.000000
87.050003,64.997986,-438.270813,-0.001561,0.003845,0.097658,289.125488,14.728754,0.976579,-438.270813,294.500458,0.000000
87.470001,64.770828,-438.315277,-0.001552,0.003845,0.097667,288.115021,14.677279,0.976669,-438.315277,294.500458,0.000000
87.890007,65.651123,-438.404266,-0.001556,0.003856,0.097953,292.030792,14.876758,0.979531,-438.404266,294.500458,0.000000
88.310005,65.530472,-438.404266,-0.001548,0.003856,0.097953,291.494110,14.849417,0.979531,-438.404266,294.500458,0.000000
88.730003,65.352859,-438.448730,-0.001544,0.003856,0.097953,290.704041,14.809170,0.979531,-438.448730,294.500458,0.000000
89.150002,65.182678,-438.404266,-0.001522,0.003856,0.097953,289.947021,14.770606,0.979531,-438.404266,294.500458,0.000000
89.570007,65.066132,-438.404266,-0.001539,0.003858,0.098005,289.428619,14.744196,0.980046,-438.404266,294.500458,0.000000
89.990005,64.967072,-438.493225,-0.001548,0.003858,0.098005,288.987976,14.721749,0.980046,-438.493225,294.500458,0.000000
90.410004,65.370728,-438.537689,-0.001544,0.003865,0.098179,290.783508,14.813218,0.981787,-438.537689,294.500458,0.000000
90.830002,65.265350,-438.493225,-0.001539,0.003865,0.098179,290.314789,14.789339,0.981787,-438.493225,294.500458,0.000000
91.250008,65.120117,-438.537689,-0.001526,0.003866,0.098188,289.668762,14.756430,0.981877,-438.537689,294.500458,0.000000
91.670006,65.104111,-438.537689,-0.001539,0.003868,0.098248,289.597534,14.752803,0.982483,-438.537689,294.500458,0.000000
92.090004,65.019577,-438.537689,-0.001526,0.003868,0.098248,289.221527,14.733647,0.982483,-438.537689,294.500458,0.000000
92.510002,65.050491,-438.582184,-0.001531,0.003871,0.098326,289.359039,14.740652,0.983255,-438.582184,294.500458,0.000000
92.930008,64.986069,-438.671143,-0.001526,0.003871,0.098326,289.072479,14.726054,0.983255,-438.671143,294.500458,0.000000
93.350006,65.031128,-438.537689,-0.001535,0.003873,0.098386,289.272919,14.736264,0.983861,-438.537689,294.500458,0.000000
93.770004,64.938400,-438.671143,-0.001518,0.003873,0.098386,288.860443,14.715252,0.983861,-438.671143,294.500458,0.000000
94.190002,65.038193,-438.582184,-0.001518,0.003877,0.098474,289.304321,14.737865,0.984739,-438.582184,294.500458,0.000000
94.610008,64.960007,-438.671143,-0.001518,0.003877,0.098474,288.956543,14.720148,0.984739,-438.671143,294.500458,0.000000
95.030006,65.413925,-438.715607,-0.001526,0.003887,0.098742,290.975677,14.823008,0.987419,-438.715607,294.500458,0.000000
95.450005,65.670120,-438.715607,-0.001513,0.003887,0.098733,292.115295,14.881063,0.987328,-438.715607,294.500458,0.000000
95.870003,65.581863,-438.671143,-0.001513,0.003887,0.098733,291.722687,14.861063,0.987328,-438.671143,294.500458,0.000000
96.290001,65.489517,-438.715607,-0.001518,0.003887,0.098733,291.311920,14.840137,0.987328,-438.715607,294.500458,0.000000
96.710007,65.365891,-438.715607,-0.001513,0.003887,0.098733,290.761993,14.812122,0.987328,-438.715607,294.500458,0.000000
97.130005,65.240402,-438.849060,-0.001509,0.003887,0.098742,290.203796,14.783687,0.987419,-438.849060,294.500458,0.000000
97.550003,65.284714,-438.849060,-0.001518,0.003890,0.098802,290.400909,14.793728,0.988024,-438.849060,294.500458,0.000000
97.970001,65.199432,-438.760101,-0.001513,0.003890,0.098802,290.021545,14.774403,0.988024,-438.760101,294.500458,0.000000
98.390007,65.199432,-438.804596,-0.001513,0.003892,0.098855,290.021545,14.774403,0.988554,-438.804596,294.500458,0.000000
98.810005,65.125336,-438.849060,-0.001513,0.003893,0.098872,289.691956,14.757612,0.988721,-438.849060,294.500458,0.000000
99.230003,65.236298,-438.893555,-0.001518,0.003897,0.098986,290.185547,14.782756,0.989856,-438.893555,294.500458,0.000000
99.650002,65.302948,-438.893555,-0.001509,0.003897,0.098986,290.482025,14.797860,0.989856,-438.893555,294.500458,0.000000
100.070007,65.245239,-438.893555,-0.001500,0.003897,0.098986,290.225311,14.784782,0.989856,-438.893555,294.500458,0.000000
100.490005,65.188644,-438.938019,-0.001513,0.003898,0.099002,289.973572,14.771957,0.990023,-438.938019,294.500458,0.000000
100.910004,65.196091,-438.982513,-0.001513,0.003900,0.099072,290.006683,14.773645,0.990719,-438.982513,294.500458,0.000000
101.330002,65.171143,-438.982513,-0.001505,0.003900,0.099063,289.895721,14.767992,0.990628,-438.982513,294.500458,0.000000
101.750008,65.073944,-438.982513,-0.001500,0.003900,0.099063,289.463348,14.745967,0.990628,-438.982513,294.500458,0.000000
102.170006,64.990906,-438.982513,-0.001500,0.003900,0.099063,289.093994,14.727150,0.990628,-438.982513,294.500458,0.000000
102.590004,64.889999,-438.982513,-0.001492,0.003900,0.099063,288.645142,14.704284,0.990628,-438.982513,294.500458,0.000000
103.010002,65.573669,-438.938019,-0.001496,0.003910,0.099307,291.686249,14.859206,0.993066,-438.938019,294.500458,0.000000
103.430008,65.563614,-439.026978,-0.001496,0.003910,0.099307,291.641510,14.856928,0.993066,-439.026978,294.500458,0.000000
103.850006,65.521164,-439.026978,-0.001509,0.003910,0.099307,291.452698,14.847308,0.993066,-439.026978,294.500458,0.000000
104.270004,65.407959,-439.026978,-0.001492,0.003910,0.099307,290.949127,14.821655,0.993066,-439.026978,294.500458,0.000000
104.690002,65.340561,-439.026978,-0.001496,0.003910,0.099314,290.649323,14.806382,0.993141,-439.026978,294.500458,0.000000
105.110008,65.249710,-439.071472,-0.001496,0.003910,0.099314,290.245209,14.785795,0.993141,-439.071472,294.500458,0.000000
105.530006,65.171143,-439.115936,-0.001500,0.003910,0.099314,289.895721,14.767992,0.993141,-439.115936,294.500458,0.000000
105.950005,65.058685,-439.204926,-0.001492,0.003910,0.099323,289.395477,14.742508,0.993232,-439.204926,294.500458,0.000000
106.370003,65.097031,-439.160431,-0.001483,0.003914,0.099419,289.566040,14.751199,0.994186,-439.160431,294.500458,0.000000
106.790009,65.203537,-439.160431,-0.001492,0.003914,0.099419,290.039825,14.775332,0.994186,-439.160431,294.500458,0.000000
107.210007,65.136505,-439.160431,-0.001487,0.003914,0.099419,289.741638,14.760143,0.994186,-439.160431,294.500458,0.000000
107.630005,65.105972,-439.204926,-0.001496,0.003916,0.099470,289.605835,14.753223,0.994701,-439.204926,294.500458,0.000000
108.050003,65.084000,-439.204926,-0.001492,0.003916,0.099470,289.508087,14.748245,0.994701,-439.204926,294.500458,0.000000
108.470009,65.016602,-439.249390,-0.001500,0.003916,0.099470,289.208282,14.732972,0.994701,-439.249390,294.500458,0.000000
108.890007,64.952927,-439.249390,-0.001487,0.003918,0.099514,288.925049,14.718543,0.995140,-439.249390,294.500458,0.000000
109.310005,65.125702,-439.204926,-0.001479,0.003920,0.099565,289.693604,14.757695,0.995654,-439.204926,294.500458,0.000000
109.730003,65.070221,-439.249390,-0.001487,0.003920,0.099565,289.446808,14.745123,0.995654,-439.249390,294.500458,0.000000
110.150002,65.013626,-439.293884,-0.001496,0.003920,0.099565,289.195038,14.732298,0.995654,-439.293884,294.500458,0.000000
110.570007,64.947342,-439.338348,-0.001487,0.003920,0.099565,288.900208,14.717278,0.995654,-439.338348,294.500458,0.000000
110.990005,64.855743,-439.382843,-0.001479,0.003920,0.099565,288.492767,14.696522,0.995654,-439.382843,294.500458,0.000000
111.410004,64.817017,-439.338348,-0.001479,0.003921,0.099593,288.320496,14.687746,0.995927,-439.338348,294.500458,0.000000
111.830002,65.339813,-439.338348,-0.001479,0.003928,0.099774,290.645996,14.806213,0.997744,-439.338348,294.500458,0.000000
112.250008,65.358810,-439.338348,-0.001487,0.003928,0.099774,290.730499,14.810518,0.997744,-439.338348,294.500458,0.000000
112.670006,65.311523,-439.382843,-0.001500,0.003928,0.099774,290.520172,14.799802,0.997744,-439.382843,294.500458,0.000000
113.090004,65.260498,-439.427307,-0.001483,0.003928,0.099774,290.293182,14.788240,0.997744,-439.427307,294.500458,0.000000
113.510002,65.195343,-439.338348,-0.001475,0.003928,0.099774,290.003357,14.773476,0.997744,-439.338348,294.500458,0.000000
113.930008,65.126816,-439.427307,-0.001466,0.003928,0.099774,289.698547,14.757947,0.997744,-439.427307,294.500458,0.000000
114.350006,65.052719,-439.427307,-0.001475,0.003928,0.099774,289.368958,14.741157,0.997744,-439.427307,294.500458,0.000000
114.770004,64.990906,-439.516266,-0.001487,0.003928,0.099774,289.093994,14.727150,0.997744,-439.516266,294.500458,0.000000
115.190002,64.913834,-439.471802,-0.001492,0.003928,0.099774,288.751160,14.709685,0.997744,-439.471802,294.500458,0.000000
115.610008,64.842331,-439.516266,-0.001470,0.003928,0.099774,288.433105,14.693482,0.997744,-439.516266,294.500458,0.000000
116.030006,64.773819,-439.516266,-0.001466,0.003928,0.099774,288.128326,14.677958,0.997744,-439.516266,294.500458,0.000000
116.450005,65.875671,-439.516266,-0.001475,0.003940,0.100077,293.029633,14.927641,1.000772,-439.516266,294.500458,0.000000
116.870003,65.795975,-439.516266,-0.001487,0.003939,0.100061,292.675110,14.909581,1.000605,-439.516266,294.500458,0.000000
117.290009,65.757996,-439.649719,-0.001475,0.003939,0.100061,292.506165,14.900975,1.000605,-439.649719,294.500458,0.000000
117.710007,65.675705,-439.649719,-0.001470,0.003939,0.100061,292.140137,14.882328,1.000605,-439.649719,294.500458,0.000000
118.130005,65.610168,-439.560760,-0.001470,0.003939,0.100061,291.848602,14.867476,1.000605,-439.560760,294.500458,0.000000
118.550003,65.540527,-439.605225,-0.001470,0.003939,0.100061,291.538818,14.851695,1.000605,-439.605225,294.500458,0.000000
118.970009,65.493607,-439.649719,-0.001479,0.003939,0.100061,291.330109,14.841063,1.000605,-439.649719,294.500458,0.000000
119.390007,65.405731,-439.694214,-0.001479,0.003939,0.100061,290.939209,14.821150,1.000605,-439.694214,294.500458,0.000000
119.810005,65.324554,-439.738678,-0.001475,0.003939,0.100061,290.578125,14.802755,1.000605,-439.738678,294.500458,0.000000
120.230003,65.282471,-439.738678,-0.001462,0.003940,0.100070,290.390930,14.793220,1.000696,-439.738678,294.500458,0.000000
120.650009,65.233688,-439.694214,-0.001449,0.003940,0.100070,290.173950,14.782165,1.000696,-439.694214,294.500458,0.000000
121.070007,65.159592,-439.738678,-0.001475,0.003940,0.100070,289.844330,14.765374,1.000696,-439.738678,294.500458,0.000000
121.490005,65.078049,-439.738678,-0.001466,0.003940,0.100077,289.481628,14.746897,1.000772,-439.738678,294.500458,0.000000
121.910004,65.039322,-439.738678,-0.001466,0.003940,0.100077,289.309357,14.738121,1.000772,-439.738678,294.500458,0.000000
122.330009,64.992401,-439.827637,-0.001466,0.003940,0.100077,289.100647,14.727489,1.000772,-439.827637,294.500458,0.000000
122.750008,64.936539,-439.738678,-0.001462,0.003940,0.100077,288.852142,14.714830,1.000772,-439.738678,294.500458,0.000000
123.170006,65.249329,-439.783173,-0.001462,0.003947,0.100242,290.243500,14.785709,1.002422,-439.783173,294.500458,0.000000
123.590004,65.267960,-439.827637,-0.001475,0.003947,0.100242,290.326385,14.789931,1.002422,-439.827637,294.500458,0.000000
124.010002,65.252319,-439.916595,-0.001470,0.003947,0.100242,290.256805,14.786387,1.002422,-439.916595,294.500458,0.000000
124.430008,65.206146,-439.827637,-0.001462,0.003947,0.100242,290.051422,14.775925,1.002422,-439.827637,294.500458,0.000000
124.850006,65.159958,-439.872131,-0.001466,0.003947,0.100242,289.845978,14.765458,1.002422,-439.872131,294.500458,0.000000
125.270004,65.135010,-439.961090,-0.001462,0.003947,0.100260,289.734985,14.759804,1.002604,-439.961090,294.500458,0.000000
125.690002,65.087723,-439.916595,-0.001462,0.003947,0.100260,289.524658,14.749088,1.002604,-439.916595,294.500458,0.000000
126.110008,65.134277,-439.961090,-0.001470,0.003949,0.100303,289.731750,14.759639,1.003027,-439.961090,1681.640747,0.000000
126.530006,64.983826,-439.961090,-0.001453,0.003937,0.100000,289.062500,14.725546,1.000000,-439.961090,0.099800,0.000000
126.950005,64.948090,-440.005554,-0.001457,0.003918,0.099505,288.903534,14.717447,0.995049,-440.005554,0.099098,0.000000
127.370003,64.786850,-439.916595,-0.001440,0.003891,0.098828,288.186310,14.680909,0.988281,-439.916595,0.098404,0.000000
127.790009,64.741425,-439.961090,-0.001440,0.003861,0.098074,287.984253,14.670616,0.980742,-439.961090,0.097702,0.000000
128.210007,64.633804,-440.005554,-0.001436,0.003839,0.097511,287.505524,14.646229,0.975110,-440.005554,0.096999,0.000000
128.630005,64.572357,-440.094543,-0.001444,0.003814,0.096878,287.232178,14.632306,0.968782,-440.094543,0.096306,0.000000
129.050003,64.534012,-440.094543,-0.001440,0.003790,0.096271,287.061615,14.623615,0.962711,-440.094543,0.095603,0.000000
129.470001,64.387665,-440.094543,-0.001440,0.003758,0.095446,286.410645,14.590453,0.954460,-440.094543,0.094901,0.000000
129.889999,64.277069,-440.094543,-0.001427,0.003727,0.094675,285.918671,14.565392,0.946754,-440.094543,0.094198,0.000000
130.310013,64.148972,-440.050049,-0.001436,0.003709,0.094206,285.348877,14.536366,0.942060,-440.050049,0.093504,0.000000
130.730011,63.613495,-440.183502,-0.001427,0.003685,0.093591,282.966949,14.415024,0.935914,-440.183502,0.092801,0.000000
131.150009,62.770821,-440.183502,-0.001427,0.003661,0.093001,279.218567,14.224072,0.930009,-440.183502,0.092099,0.000000
131.570007,61.447784,-440.094543,-0.001406,0.003632,0.092247,273.333405,13.924267,0.922470,-440.094543,0.091405,0.000000
131.990005,59.397873,-440.139008,-0.001393,0.003602,0.091484,264.214935,13.459750,0.914839,-440.139008,0.090703,0.000000
132.410004,58.192505,-440.183502,-0.001406,0.003584,0.091042,258.853180,13.186610,0.910419,-440.183502,0.090000,0.000000
132.830002,55.814163,-440.227966,-0.001414,0.003552,0.090217,248.273804,12.647670,0.902168,-440.227966,0.089298,0.000000
133.250000,53.416084,-440.272461,-0.001397,0.003529,0.089637,237.606613,12.104258,0.896369,-440.272461,0.088604,0.000000
133.670013,50.446411,-440.227966,-0.001397,0.003498,0.088847,224.396851,11.431320,0.888466,-440.227966,0.087902,0.000000
134.090012,47.386253,-440.272461,-0.001384,0.003469,0.088102,210.784576,10.737878,0.881018,-440.272461,0.087199,0.000000
134.510010,45.260010,-440.272461,-0.001401,0.003450,0.087642,201.326584,10.256065,0.876415,-440.272461,0.086497,0.000000
134.930008,42.384918,-440.272461,-0.001397,0.003426,0.087018,188.537537,9.604560,0.870178,-440.272461,0.085804,0.000000
135.350006,38.385643,-440.316925,-0.001393,0.003387,0.086037,170.747864,8.698311,0.860367,-440.316925,0.085101,0.000000
135.770004,35.973412,-440.361420,-0.001397,0.003366,0.085508,160.017731,8.151691,0.855083,-440.361420,0.084399,0.000000
136.190002,32.528221,-440.316925,-0.001397,0.003334,0.084676,144.692749,7.371000,0.846757,-440.316925,0.083704,0.000000
136.610001,30.610504,-440.361420,-0.001393,0.003315,0.084190,136.162323,6.936440,0.841897,-440.361420,0.083003,0.000000
137.030014,26.588882,-440.361420,-0.001401,0.003278,0.083254,118.273254,6.025127,0.832541,-440.361420,0.082300,0.000000
137.450012,24.010201,-440.361420,-0.001388,0.003256,0.082698,106.802704,5.440789,0.826984,-440.361420,0.081598,0.000000
137.870010,21.251663,-440.450378,-0.001393,0.003222,0.081840,94.532120,4.815696,0.818400,-440.450378,0.080903,0.000000
138.290009,18.297638,-440.450378,-0.001393,0.003201,0.081312,81.391960,4.146304,0.813117,-440.450378,0.080200,0.000000
138.710007,15.093369,-440.405884,-0.001401,0.003172,0.080556,67.138657,3.420206,0.805562,-440.405884,0.079498,0.000000
139.130005,12.168381,-440.494873,-0.001410,0.003143,0.079828,54.127663,2.757395,0.798280,-440.494873,0.078805,0.000000
139.550003,9.549858,-440.539337,-0.001401,0.003118,0.079186,42.479889,2.164029,0.791861,-440.539337,0.078102,0.000000
139.970001,6.540718,-440.539337,-0.001406,0.003089,0.078467,29.094566,1.482148,0.784669,-440.539337,0.077400,0.000000
140.389999,3.988106,-440.450378,-0.001406,0.003063,0.077790,17.739981,0.903718,0.777902,-440.450378,0.076697,0.000000
140.810013,1.186005,-440.450378,-0.001401,0.003036,0.077123,5.275612,0.268752,0.771225,-440.450378,0.076004,0.000000
141.230011,-2.234612,-440.494873,-0.001406,0.003002,0.076238,-9.940048,-0.506370,0.762384,-440.494873,0.075301,0.000000
141.650009,-4.538479,-440.583832,-0.001397,0.002973,0.075509,-20.188162,-1.028434,0.755087,-440.583832,0.074599,0.000000
142.070007,-6.955921,-440.583832,-0.001406,0.002951,0.074955,-30.941483,-1.576234,0.749545,-440.583832,0.073896,0.000000
142.490005,0.020851,-440.628296,-0.001487,0.002927,0.074355,0.092750,0.004725,0.743550,-440.628296,0.073203,0.000000
142.910004,-0.009682,-440.628296,-0.001483,0.002896,0.073550,-0.043066,-0.002194,0.735496,-440.628296,0.072500,0.000000
143.330002,-0.024582,-440.539337,-0.001492,0.002868,0.072838,-0.109346,-0.005570,0.728380,-440.539337,0.071798,0.000000
143.750000,-0.027931,-440.628296,-0.001544,0.002837,0.072058,-0.124244,-0.006329,0.720583,-440.628296,0.071103,0.000000
144.170013,-0.010056,-440.672791,-0.001561,0.002819,0.071598,-0.044729,-0.002279,0.715981,-440.672791,0.070401,0.000000
144.590012,-0.032028,-440.672791,-0.001574,0.002794,0.070973,-0.142469,-0.007258,0.709728,-440.672791,0.069698,0.000000
145.010010,-0.041336,-440.672791,-0.001582,0.002756,0.070002,-0.183872,-0.009367,0.700024,-440.672791,0.068996,0.000000
145.430008,-0.000000,-440.717255,-0.001625,0.002734,0.069439,-0.000000,-0.000000,0.694392,-440.717255,0.068302,0.000000
145.850006,-0.034637,-440.717255,-0.001664,0.002704,0.068676,-0.154075,-0.007849,0.686762,-440.717255,0.067600,0.000000
146.270004,-0.018623,-440.761749,-0.001686,0.002676,0.067981,-0.082841,-0.004220,0.679813,-440.761749,0.066897,0.000000
146.690002,-0.015274,-440.761749,-0.001725,0.002649,0.067297,-0.067942,-0.003461,0.672969,-440.761749,0.066204,0.000000
147.110001,-0.071869,-440.806213,-0.001720,0.002619,0.066534,-0.319689,-0.016286,0.665339,-440.806213,0.065501,0.000000
147.530014,-0.074478,-440.806213,-0.001763,0.002593,0.065866,-0.331295,-0.016877,0.658663,-440.806213,0.064799,0.000000
147.950012,-0.065544,-440.850708,-0.001794,0.002566,0.065164,-0.291555,-0.014853,0.651638,-440.850708,0.064096,0.000000
148.370010,-0.063683,-440.850708,-0.001828,0.002537,0.064434,-0.283274,-0.014431,0.644341,-440.850708,0.063403,0.000000
148.790009,-0.054367,-440.895172,-0.001845,0.002510,0.063759,-0.241837,-0.012320,0.637588,-440.895172,0.062701,0.000000
149.210007,-0.067032,-440.806213,-0.001871,0.002480,0.062996,-0.298173,-0.015190,0.629958,-440.806213,0.061998,0.000000
149.630005,-0.051018,-440.895172,-0.001906,0.002446,0.062119,-0.226938,-0.011561,0.621192,-440.895172,0.061296,0.000000
150.050003,-0.047295,-440.806213,-0.001932,0.002428,0.061659,-0.210377,-0.010717,0.616590,-440.806213,0.060602,0.000000
150.470001,-0.043198,-440.939667,-0.001962,0.002402,0.061019,-0.192153,-0.009789,0.610186,-440.939667,0.059900,0.000000
150.890015,-0.079689,-440.939667,-0.002009,0.002369,0.060177,-0.354474,-0.018058,0.601768,-440.939667,0.059197,0.000000
151.310013,-0.059212,-440.984161,-0.002013,0.002347,0.059605,-0.263387,-0.013418,0.596045,-440.984161,0.058502,0.000000
151.730011,-0.064423,-440.895172,-0.002048,0.002316,0.058832,-0.286566,-0.014598,0.588324,-440.895172,0.057800,0.000000
152.150009,-0.037613,-440.895172,-0.002065,0.002295,0.058304,-0.167311,-0.008523,0.583040,-440.895172,0.057097,0.000000
152.570007,-0.042084,-440.939667,-0.002113,0.002263,0.057488,-0.187198,-0.009536,0.574880,-440.939667,0.056395,0.000000
152.990005,-0.075226,-440.984161,-0.002134,0.002233,0.056716,-0.334621,-0.017046,0.567159,-440.984161,0.055702,0.000000
153.410004,-0.037987,-441.028625,-0.002169,0.002202,0.055927,-0.168974,-0.008608,0.559271,-441.028625,0.054999,0.000000
153.830002,-0.046547,-441.028625,-0.002195,0.002180,0.055381,-0.207051,-0.010548,0.553806,-441.028625,0.054297,0.000000
154.250000,-0.027931,-441.028625,-0.002225,0.002156,0.054764,-0.124244,-0.006329,0.547644,-441.028625,0.053603,0.000000
154.670013,-0.045059,-441.028625,-0.002255,0.002119,0.053820,-0.200433,-0.010211,0.538197,-441.028625,0.052901,0.000000
155.090012,-0.051018,-441.073120,-0.002272,0.002097,0.053266,-0.226938,-0.011561,0.532656,-441.073120,0.052198,0.000000
155.510010,-0.059952,-441.117584,-0.002307,0.002067,0.052510,-0.266679,-0.013585,0.525101,-441.117584,0.051496,0.000000
155.930008,-0.063683,-441.117584,-0.002333,0.002044,0.051921,-0.283274,-0.014431,0.519212,-441.117584,0.050802,0.000000
156.350006,-0.042450,-441.028625,-0.002371,0.002009,0.051036,-0.188827,-0.009619,0.510355,-441.028625,0.050100,0.000000
156.770004,-0.041710,-441.117584,-0.002389,0.001981,0.050325,-0.185535,-0.009452,0.503255,-441.117584,0.049397,0.000000
157.190002,-0.035751,-441.162079,-0.002427,0.001961,0.049821,-0.159030,-0.008101,0.498213,-441.162079,0.048695,0.000000
157.610001,-0.030167,-441.162079,-0.002440,0.001933,0.049093,-0.134188,-0.006836,0.490931,-441.162079,0.048000,0.000000
158.030014,-0.049904,-441.251038,-0.002479,0.001904,0.048374,-0.221983,-0.011308,0.483740,-441.251038,0.047298,0.000000
158.450012,-0.041710,-441.206543,-0.002496,0.001875,0.047619,-0.185535,-0.009452,0.476185,-441.206543,0.046597,0.000000
158.870010,-0.046547,-441.162079,-0.002539,0.001847,0.046916,-0.207051,-0.010548,0.469160,-441.162079,0.045902,0.000000
159.290009,0.018616,-441.251038,-0.002574,0.001817,0.046145,0.082807,0.004218,0.461454,-441.251038,0.045199,0.000000
159.710007,-0.008194,-441.295502,-0.002596,0.001792,0.045511,-0.036449,-0.001857,0.455111,-441.295502,0.044497,0.000000
160.130005,-0.007080,-441.251038,-0.002626,0.001767,0.044878,-0.031494,-0.001604,0.448783,-441.251038,0.043794,0.000000
160.550003,-0.038361,-441.339996,-0.002647,0.001735,0.044064,-0.170636,-0.008693,0.440637,-441.339996,0.043101,0.000000
160.970001,-0.009315,-441.295502,-0.002665,0.001713,0.043517,-0.041437,-0.002111,0.435172,-441.295502,0.042398,0.000000
161.390015,0.030533,-441.251038,-0.002699,0.001686,0.042831,0.135817,0.006919,0.428314,-441.251038,0.041696,0.000000
161.810013,0.015640,-441.428955,-0.002725,0.001655,0.042026,0.069571,0.003544,0.420260,-441.428955,0.040993,0.000000
162.230011,0.007072,-441.384491,-0.002751,0.001625,0.041263,0.031460,0.001603,0.412629,-441.384491,0.040300,0.000000
162.650009,-0.038361,-441.384491,-0.002785,0.001597,0.040560,-0.170636,-0.008693,0.405604,-441.384491,0.039598,0.000000
163.070007,0.004463,-441.384491,-0.002828,0.001564,0.039719,0.019853,0.001011,0.397187,-441.384491,0.038895,0.000000
163.490005,-0.018250,-441.384491,-0.002841,0.001548,0.039321,-0.081178,-0.004135,0.393205,-441.384491,0.038202,0.000000
163.910004,-0.016388,-441.473450,-0.002876,0.001517,0.038539,-0.072897,-0.003714,0.385393,-441.473450,0.037498,0.000000
164.330002,-0.023834,-441.517914,-0.002902,0.001487,0.037776,-0.106020,-0.005401,0.377763,-441.517914,0.036796,0.000000
164.750015,-0.032768,-441.517914,-0.002928,0.001462,0.037143,-0.145760,-0.007425,0.371434,-441.517914,0.036094,0.000000
165.170013,-0.045807,-441.562408,-0.002958,0.001433,0.036397,-0.203759,-0.010380,0.363971,-441.562408,0.035400,0.000000
165.590012,-0.038361,-441.473450,-0.002988,0.001413,0.035885,-0.170636,-0.008693,0.358853,-441.473450,0.034698,0.000000
166.010010,-0.037239,-441.562408,-0.003018,0.001395,0.035435,-0.165648,-0.008438,0.354349,-441.562408,0.033995,0.000000
166.430008,-0.020485,-441.562408,-0.003057,0.001349,0.034256,-0.091121,-0.004642,0.342556,-441.562408,0.033301,0.000000
166.850006,-0.039474,-441.562408,-0.003070,0.001329,0.033752,-0.175591,-0.008945,0.337522,-441.562408,0.032599,0.000000
167.270004,-0.026817,-441.562408,-0.003100,0.001299,0.032997,-0.119289,-0.006077,0.329975,-441.562408,0.031896,0.000000
167.690002,-0.024208,-441.517914,-0.003117,0.001268,0.032217,-0.107683,-0.005486,0.322170,-441.517914,0.031194,0.000000
168.110001,-0.032028,-441.606873,-0.003160,0.001246,0.031654,-0.142469,-0.007258,0.316538,-441.606873,0.030500,0.000000
168.530014,-0.071129,-441.695831,-0.003191,0.001212,0.030778,-0.316397,-0.016118,0.307780,-441.695831,0.029798,0.000000
168.950012,-0.065170,-441.695831,-0.003238,0.001177,0.029901,-0.289892,-0.014768,0.299014,-441.695831,0.029095,0.000000
169.370010,-0.044319,-441.651367,-0.003251,0.001158,0.029407,-0.197141,-0.010043,0.294071,-441.651367,0.028393,0.000000
169.790009,-0.062561,-441.651367,-0.003260,0.001129,0.028688,-0.278285,-0.014177,0.286880,-441.651367,0.027699,0.000000
170.210007,-0.062561,-441.651367,-0.003307,0.001098,0.027890,-0.278285,-0.014177,0.278901,-441.651367,0.026997,0.000000
170.630005,-0.070755,-441.740326,-0.003337,0.001079,0.027396,-0.314734,-0.016033,0.273958,-441.740326,0.026294,0.000000
171.050003,-0.064423,-441.784821,-0.003376,0.001048,0.026615,-0.286566,-0.014598,0.266146,-441.784821,0.025600,0.000000
171.470001,-0.056976,-441.784821,-0.003380,0.001022,0.025956,-0.253443,-0.012911,0.259561,-441.784821,0.024898,0.000000
171.890015,-0.089745,-441.740326,-0.003415,0.000995,0.025262,-0.399204,-0.020336,0.252619,-441.740326,0.024195,0.000000
172.310013,-0.085648,-441.740326,-0.003449,0.000964,0.024491,-0.380979,-0.019408,0.244905,-441.740326,0.023493,0.000000
172.730011,-0.059952,-441.784821,-0.003475,0.000933,0.023701,-0.266679,-0.013585,0.237010,-441.784821,0.022799,0.000000
173.000015,-0.007080,-441.740326,-0.003488,0.000929,0.023597,-0.031494,-0.001604,0.235973,-441.740326,0.023458,0.000000