File: Data/compression 29/AutoNoHeating-17-29-reverse-1-3_10232024_172757.csv
Time (sec),S:Load (lbs),S:HL1 (DIM),S:LVDT (in),S:Position (in),Ch:Position (mm),Ch:Load (N),Ch:Stress (MPa),Ch:Strain (mm/mm),Ch:HL1 (DIM),Set Point (),Cycles ()
0.110000,-0.061073,-194.515198,-0.015332,-0.005555,-0.141106,-0.271668,-0.013839,-1.411062,-194.515198,-0.140890,0.000000
0.620000,-0.004471,-194.559677,-0.015340,-0.005444,-0.138271,-0.019887,-0.001013,-1.382705,-194.559677,-0.137143,0.000000
1.130000,0.008934,-194.604156,-0.015073,-0.005117,-0.129963,0.039741,0.002024,-1.299627,-194.604156,-0.128645,0.000000
1.640000,-0.045807,-194.648636,-0.014720,-0.004776,-0.121307,-0.203759,-0.010380,-1.213074,-194.648636,-0.120145,0.000000
2.150000,0.024948,-194.737610,-0.014400,-0.004440,-0.112783,0.110975,0.005653,-1.127831,-194.737610,-0.111647,0.000000
2.660000,0.049149,-194.737610,-0.014068,-0.004111,-0.104431,0.218624,0.011137,-1.044313,-194.737610,-0.103148,0.000000
3.170000,-0.011917,-194.782089,-0.013745,-0.003775,-0.095880,-0.053010,-0.002700,-0.958805,-194.782089,-0.094650,0.000000
3.680000,-0.005959,-194.915527,-0.013409,-0.003437,-0.087295,-0.026505,-0.001350,-0.872948,-194.915527,-0.086168,0.000000
4.190000,0.041328,-194.915527,-0.013029,-0.003100,-0.078736,0.183838,0.009365,-0.787357,-194.915527,-0.077669,0.000000
4.700000,0.033882,-194.960007,-0.012710,-0.002770,-0.070350,0.150715,0.007678,-0.703498,-194.960007,-0.069170,0.000000
5.210000,0.034256,-194.960007,-0.012374,-0.002443,-0.062041,0.152378,0.007763,-0.620412,-194.960007,-0.060671,0.000000
5.720000,0.002602,-195.004486,-0.012029,-0.002100,-0.053344,0.011573,0.000590,-0.533436,-195.004486,-0.052173,0.000000
6.230000,0.038353,-195.048965,-0.011658,-0.001764,-0.044810,0.170603,0.008691,-0.448101,-195.048965,-0.043674,0.000000
6.740000,0.086761,-195.182419,-0.011300,-0.001431,-0.036355,0.385934,0.019660,-0.363547,-195.182419,-0.035175,0.000000
7.250000,0.004837,-195.182419,-0.010964,-0.001096,-0.027830,0.021516,0.001096,-0.278296,-195.182419,-0.026693,0.000000
7.760000,0.034256,-195.182419,-0.010615,-0.000756,-0.019192,0.152378,0.007763,-0.191917,-195.182419,-0.018195,0.000000
8.270000,0.072983,-195.360336,-0.010287,-0.000428,-0.010876,0.324644,0.016538,-0.108755,-195.360336,-0.009696,0.000000
8.780001,0.031647,-195.315857,-0.009964,-0.000093,-0.002368,0.140772,0.007171,-0.023678,-195.315857,-0.001197,0.000000
9.290001,0.062553,-195.449295,-0.009632,0.000235,0.005975,0.278251,0.014175,0.059748,-195.449295,0.007302,0.000000
9.800000,0.042816,-195.449295,-0.009287,0.000578,0.014682,0.190456,0.009702,0.146816,-195.449295,0.015800,0.000000
10.310000,-0.016388,-195.449295,-0.008912,0.000912,0.023172,-0.072897,-0.003714,0.231719,-195.449295,0.024300,0.000000
10.820001,0.087502,-195.582748,-0.008601,0.001239,0.031480,0.389226,0.019828,0.314797,-195.582748,0.032798,0.000000
11.330001,0.071121,-195.582748,-0.008252,0.001582,0.040178,0.316363,0.016116,0.401782,-195.582748,0.041280,0.000000
11.840000,0.046547,-195.627228,-0.007899,0.001920,0.048773,0.207051,0.010548,0.487729,-195.627228,0.049778,0.000000
12.350000,0.066650,-195.716187,-0.007571,0.002246,0.057054,0.296476,0.015103,0.570543,-195.716187,0.058278,0.000000
12.860001,0.052132,-195.716187,-0.007209,0.002579,0.065519,0.231893,0.011813,0.655188,-195.716187,0.066776,0.000000
13.370001,0.064789,-195.805145,-0.006989,-0.000000,-0.000000,0.288195,0.014681,-0.000000,-195.805145,0.000216,0.000000
13.880001,0.077080,-195.805145,-0.007002,-0.000000,-0.000000,0.342868,0.017467,-0.000000,-195.805145,0.000581,0.000000
14.390000,0.105377,-195.849625,-0.007006,0.000024,0.000615,0.468741,0.023879,0.006154,-195.849625,0.001431,0.000000
14.900001,0.064789,-195.938583,-0.006980,0.000053,0.001344,0.288195,0.014681,0.013436,-195.938583,0.002281,0.000000
15.410001,0.080803,-195.938583,-0.006950,0.000086,0.002185,0.359429,0.018310,0.021854,-195.938583,0.003130,0.000000
15.920001,0.086388,-196.072037,-0.006920,0.000113,0.002879,0.384271,0.019576,0.028788,-196.072037,0.003980,0.000000
16.430000,0.103889,-196.027557,-0.006894,0.000155,0.003928,0.462123,0.023542,0.039280,-196.027557,0.004830,0.000000
16.940001,0.065163,-196.072037,-0.006847,0.000183,0.004657,0.289858,0.014766,0.046569,-196.072037,0.005680,0.000000
17.450001,0.087875,-196.160995,-0.006817,0.000222,0.005646,0.390889,0.019913,0.056455,-196.160995,0.006530,0.000000
17.960001,0.093834,-196.205475,-0.006795,0.000251,0.006365,0.417394,0.021263,0.063654,-196.205475,0.007380,0.000000
18.470001,0.091225,-196.294434,-0.006752,0.000288,0.007310,0.405788,0.020672,0.073101,-196.294434,0.008230,0.000000
18.980001,0.031273,-196.294434,-0.006735,0.000318,0.008082,0.139109,0.007087,0.080823,-196.294434,0.009080,0.000000
19.490002,0.059578,-196.338913,-0.006687,0.000351,0.008923,0.265016,0.013501,0.089233,-196.338913,0.009929,0.000000
20.000000,0.056595,-196.427887,-0.006687,0.000370,0.009400,0.251746,0.012825,0.094002,-196.427887,0.010779,0.000000
20.510000,0.084900,-196.427887,-0.006614,0.000422,0.010719,0.377654,0.019239,0.107188,-196.427887,0.011629,0.000000
21.020000,0.041702,-196.561325,-0.006597,0.000451,0.011464,0.185501,0.009450,0.114644,-196.561325,0.012479,0.000000
21.530001,0.076332,-196.516846,-0.006545,0.000489,0.012418,0.339542,0.017297,0.124182,-196.516846,0.013329,0.000000
22.040001,0.064415,-196.605804,-0.006523,0.000515,0.013086,0.286532,0.014597,0.130859,-196.605804,0.014179,0.000000
22.550001,0.060318,-196.650284,-0.006463,0.000555,0.014092,0.268308,0.013668,0.140919,-196.650284,0.015029,0.000000
23.060001,0.020851,-196.650284,-0.006441,0.000586,0.014890,0.092750,0.004725,0.148898,-196.650284,0.015878,0.000000
23.570002,0.053993,-196.828201,-0.006407,0.000617,0.015670,0.240174,0.012235,0.156702,-196.828201,0.016728,0.000000
24.080002,0.058090,-196.828201,-0.006390,0.000658,0.016720,0.258398,0.013163,0.167202,-196.828201,0.017579,0.000000
24.590002,0.020103,-196.828201,-0.006338,0.000690,0.017518,0.089425,0.004556,0.175180,-196.828201,0.018429,0.000000
25.100000,0.000366,-196.917175,-0.006316,0.000720,0.018298,0.001629,0.000083,0.182985,-196.917175,0.019278,0.000000
25.610001,0.074097,-196.872696,-0.006265,0.000747,0.018974,0.329598,0.016791,0.189744,-196.872696,0.020128,0.000000
26.120001,0.040588,-197.006134,-0.006234,0.000795,0.020189,0.180546,0.009197,0.201886,-197.006134,0.020978,0.000000
26.630001,0.004463,-197.050613,-0.006200,0.000822,0.020891,0.019853,0.001011,0.208911,-197.050613,0.021827,0.000000
27.140001,0.002975,-197.139572,-0.006170,0.000848,0.021533,0.013236,0.000674,0.215330,-197.139572,0.022678,0.000000
27.650002,0.079681,-197.139572,-0.006135,0.000887,0.022522,0.354441,0.018056,0.225216,-197.139572,0.023528,0.000000
28.160002,0.046173,-197.095093,-0.006092,0.000928,0.023571,0.205388,0.010463,0.235708,-197.095093,0.024378,0.000000
28.670002,0.020477,-197.273026,-0.006071,0.000955,0.024248,0.091088,0.004640,0.242476,-197.273026,0.025227,0.000000
29.180002,0.083778,-197.273026,-0.006036,0.000991,0.025167,0.372665,0.018984,0.251665,-197.273026,0.026077,0.000000
29.690001,0.109100,-197.317505,-0.005997,0.001018,0.025869,0.485303,0.024722,0.258690,-197.317505,0.026927,0.000000
30.200001,0.097557,-197.361984,-0.005967,0.001057,0.026849,0.433956,0.022107,0.268493,-197.361984,0.027777,0.000000
30.710001,0.062180,-197.361984,-0.005937,0.001088,0.027638,0.276589,0.014090,0.276381,-197.361984,0.028627,0.000000
31.220001,0.081543,-197.495422,-0.005915,0.001121,0.028480,0.362721,0.018478,0.284798,-197.495422,0.029477,0.000000
31.730001,0.092346,-197.539902,-0.005872,0.001149,0.029182,0.410776,0.020926,0.291815,-197.539902,0.030327,0.000000
32.240002,0.104637,-197.495422,-0.005846,0.001190,0.030214,0.465449,0.023711,0.302141,-197.495422,0.031176,0.000000
32.750000,0.071861,-197.628860,-0.005812,0.001224,0.031090,0.319655,0.016284,0.310899,-197.628860,0.032026,0.000000
33.260002,0.096443,-197.673340,-0.005777,0.001256,0.031905,0.429001,0.021854,0.319052,-197.673340,0.032876,0.000000
33.770000,0.119156,-197.762314,-0.005726,0.001293,0.032842,0.530032,0.027001,0.328415,-197.762314,0.033726,0.000000
34.280003,0.079681,-197.762314,-0.005704,0.001324,0.033639,0.354441,0.018056,0.336394,-197.762314,0.034576,0.000000
34.790001,0.085640,-197.762314,-0.005652,0.001359,0.034507,0.380946,0.019406,0.345069,-197.762314,0.035426,0.000000
35.300003,0.093460,-197.806793,-0.005627,0.001386,0.035192,0.415731,0.021178,0.351920,-197.806793,0.036276,0.000000
35.810001,0.126976,-197.895752,-0.005609,0.001428,0.036267,0.564817,0.028773,0.362669,-197.895752,0.037126,0.000000
36.320004,0.067024,-197.940231,-0.005566,0.001458,0.037022,0.298139,0.015188,0.370216,-197.940231,0.037984,0.000000
36.830002,0.096443,-197.984711,-0.005532,0.001492,0.037906,0.429001,0.021854,0.379065,-197.984711,0.038834,0.000000
37.340000,0.097183,-198.029190,-0.005493,0.001513,0.038435,0.432293,0.022022,0.384349,-198.029190,0.039684,0.000000
37.850002,0.109848,-198.118149,-0.005454,0.001559,0.039606,0.488628,0.024892,0.396059,-198.118149,0.040534,0.000000
38.360001,0.084152,-198.118149,-0.005428,0.001587,0.040300,0.374328,0.019069,0.403000,-198.118149,0.041384,0.000000
38.870003,0.099419,-198.251602,-0.005385,0.001625,0.041280,0.442236,0.022529,0.412796,-198.251602,0.042233,0.000000
39.380001,0.110588,-198.251602,-0.005372,0.001652,0.041965,0.491920,0.025060,0.419646,-198.251602,0.043083,0.000000
39.890003,0.096817,-198.296082,-0.005325,0.001690,0.042936,0.430664,0.021939,0.429358,-198.296082,0.043934,0.000000
40.400002,0.043190,-198.385040,-0.005295,0.001722,0.043743,0.192119,0.009787,0.437428,-198.385040,0.044784,0.000000
40.910004,0.079315,-198.385040,-0.005256,0.001759,0.044671,0.352812,0.017973,0.446708,-198.385040,0.045633,0.000000
41.420002,0.099045,-198.473999,-0.005230,0.001784,0.045312,0.440573,0.022444,0.453120,-198.473999,0.046483,0.000000
41.930000,0.071495,-198.473999,-0.005178,0.001826,0.046379,0.318026,0.016201,0.463793,-198.473999,0.047333,0.000000
42.440002,0.066277,-198.518478,-0.005161,0.001860,0.047246,0.294813,0.015018,0.472461,-198.518478,0.048182,0.000000
42.950001,0.072235,-198.562973,-0.005105,0.001891,0.048027,0.321318,0.016369,0.480265,-198.562973,0.049033,0.000000
43.460003,0.075592,-198.651932,-0.005101,0.001916,0.048660,0.336250,0.017129,0.486601,-198.651932,0.049883,0.000000
43.970001,0.043190,-198.651932,-0.005036,0.001962,0.049839,0.192119,0.009787,0.498395,-198.651932,0.050733,0.000000
44.480003,0.039093,-198.740891,-0.005032,0.001997,0.050715,0.173894,0.008859,0.507153,-198.740891,0.051582,0.000000
44.990002,0.078194,-198.696411,-0.004993,0.002020,0.051296,0.347823,0.017719,0.512959,-198.696411,0.052432,0.000000
45.500004,0.056595,-198.874329,-0.004941,0.002066,0.052484,0.251746,0.012825,0.524844,-198.874329,0.053282,0.000000
46.010002,0.005211,-198.785370,-0.004907,0.002093,0.053169,0.023179,0.001181,0.531694,-198.785370,0.054132,0.000000
46.520000,0.028297,-198.874329,-0.004872,0.002125,0.053985,0.125873,0.006412,0.539847,-198.874329,0.054982,0.000000
47.030003,0.098679,-198.918808,-0.004855,0.002158,0.054817,0.438944,0.022361,0.548174,-198.918808,0.055832,0.000000
47.540001,0.051384,-199.007782,-0.004799,0.002200,0.055875,0.228567,0.011644,0.558749,-199.007782,0.056682,0.000000
48.050003,0.012283,-199.096741,-0.004777,0.002228,0.056595,0.054639,0.002783,0.565948,-199.096741,0.057531,0.000000
48.560001,0.053993,-199.096741,-0.004751,0.002261,0.057419,0.240174,0.012235,0.574191,-199.096741,0.058381,0.000000
49.070004,0.107239,-199.141220,-0.004717,0.002291,0.058200,0.477022,0.024301,0.581996,-199.141220,0.059231,0.000000
49.580002,0.100540,-199.141220,-0.004665,0.002334,0.059274,0.447225,0.022783,0.592745,-199.141220,0.060081,0.000000
50.090004,0.115059,-199.230179,-0.004644,0.002360,0.059951,0.511808,0.026073,0.599512,-199.230179,0.060931,0.000000
50.600002,0.339600,-199.319138,-0.004600,0.002395,0.060844,1.510615,0.076954,0.608445,-199.319138,0.061781,0.000000
51.110001,0.561165,-199.319138,-0.004592,0.002422,0.061520,2.496186,0.127162,0.615204,-199.319138,0.062631,0.000000
51.620003,0.961838,-199.363617,-0.004562,0.002461,0.062518,4.278468,0.217956,0.625181,-199.363617,0.063481,0.000000
52.130001,1.438469,-199.408096,-0.004527,0.002496,0.063402,6.398629,0.325962,0.634023,-199.408096,0.064330,0.000000
52.640003,1.974686,-199.452591,-0.004497,0.002528,0.064218,8.783840,0.447470,0.642176,-199.452591,0.065180,0.000000
53.150002,2.385414,-199.541550,-0.004488,0.002558,0.064981,10.610852,0.540543,0.649813,-199.541550,0.066031,0.000000
53.660004,3.105583,-199.586029,-0.004458,0.002594,0.065891,13.814324,0.703735,0.658912,-199.586029,0.066880,0.000000
54.170002,3.817184,-199.586029,-0.004437,0.002628,0.066759,16.979685,0.864986,0.667587,-199.586029,0.067730,0.000000
54.680004,4.331802,-199.674988,-0.004402,0.002656,0.067453,19.268820,0.981600,0.674529,-199.674988,0.068580,0.000000
55.190002,5.265343,-199.719467,-0.004359,0.002699,0.068545,23.421413,1.193144,0.685452,-199.719467,0.069430,0.000000
55.700001,5.603828,-199.808426,-0.004329,0.002727,0.069273,24.927074,1.269846,0.692734,-199.808426,0.070279,0.000000
56.210003,6.267029,-199.763947,-0.004307,0.002762,0.070158,27.877136,1.420129,0.701583,-199.763947,0.071130,0.000000
56.720001,6.649826,-199.852921,-0.004294,0.002794,0.070965,29.579903,1.506872,0.709645,-199.852921,0.071980,0.000000
57.230003,7.465691,-199.941879,-0.004255,0.002832,0.071927,33.209049,1.691750,0.719274,-199.941879,0.072830,0.000000
57.740002,7.957596,-199.897400,-0.004221,0.002864,0.072734,35.397156,1.803217,0.727343,-199.897400,0.073679,0.000000
58.250004,8.350822,-199.986359,-0.004178,0.002896,0.073566,37.146313,1.892323,0.735662,-199.986359,0.074529,0.000000
58.760002,8.806602,-200.030838,-0.004169,0.002925,0.074304,39.173725,1.995605,0.743035,-200.030838,0.075379,0.000000
59.270004,9.526405,-200.030838,-0.004117,0.002966,0.075327,42.375568,2.158714,0.753270,-200.030838,0.076229,0.000000
59.780003,9.633644,-200.164276,-0.004100,0.002994,0.076038,42.852589,2.183015,0.760378,-200.164276,0.077079,0.000000
60.290005,10.210075,-200.164276,-0.004074,0.003029,0.076948,45.416683,2.313636,0.769484,-200.164276,0.077929,0.000000
60.800003,10.306152,-200.253235,-0.004049,0.003055,0.077599,45.844055,2.335407,0.775994,-200.253235,0.078779,0.000000
61.310001,10.947746,-200.253235,-0.004014,0.003094,0.078579,48.698009,2.480795,0.785790,-200.253235,0.079637,0.000000
61.820004,11.330177,-200.386688,-0.003971,0.003127,0.079437,50.399147,2.567455,0.794374,-200.386688,0.080487,0.000000
62.330002,11.848145,-200.431168,-0.003941,0.003162,0.080322,52.703178,2.684828,0.803223,-200.431168,0.081337,0.000000
62.840004,11.927460,-200.431168,-0.003923,0.003184,0.080869,53.055992,2.702801,0.808688,-200.431168,0.082187,0.000000
63.350002,12.587677,-200.520126,-0.003876,0.003229,0.082022,55.992783,2.852408,0.820217,-200.520126,0.083037,0.000000
63.860004,13.057983,-200.564606,-0.003867,0.003260,0.082811,58.084812,2.958981,0.828112,-200.564606,0.083886,0.000000
64.370003,13.324974,-200.609085,-0.003833,0.003290,0.083574,59.272446,3.019482,0.835743,-200.609085,0.084736,0.000000
64.880005,13.793045,-200.564606,-0.003807,0.003330,0.084572,61.354530,3.125549,0.845720,-200.564606,0.085586,0.000000
65.389999,14.384003,-200.653564,-0.003760,0.003365,0.085483,63.983238,3.259462,0.854826,-200.653564,0.086436,0.000000
65.900002,14.723602,-200.698044,-0.003725,0.003400,0.086350,65.493851,3.336416,0.863501,-200.698044,0.087286,0.000000
66.410004,14.613754,-200.787018,-0.003717,0.003420,0.086862,65.005226,3.311524,0.868618,-200.787018,0.088137,0.000000
66.920006,15.878700,-200.742538,-0.003678,0.003471,0.088153,70.631989,3.598165,0.881532,-200.742538,0.088986,0.000000
67.430000,15.724541,-200.831497,-0.003665,0.003497,0.088812,69.946251,3.563232,0.888118,-200.831497,0.089835,0.000000
67.940002,16.244003,-200.920456,-0.003622,0.003531,0.089697,72.256935,3.680944,0.896975,-200.920456,0.090686,0.000000
68.450005,16.414917,-200.964935,-0.003596,0.003560,0.090417,73.017197,3.719673,0.904166,-200.964935,0.091535,0.000000
68.960007,17.327980,-200.920456,-0.003570,0.003604,0.091552,77.078705,3.926576,0.915521,-200.920456,0.092385,0.000000
69.470001,17.068810,-201.009415,-0.003531,0.003630,0.092212,75.925858,3.867847,0.922122,-201.009415,0.093236,0.000000
69.980003,17.796791,-201.142868,-0.003501,0.003669,0.093183,79.164078,4.032811,0.931826,-201.142868,0.094085,0.000000
70.490005,17.835892,-201.098373,-0.003497,0.003696,0.093868,79.338005,4.041671,0.938684,-201.098373,0.094934,0.000000
71.000000,18.467438,-201.187347,-0.003441,0.003737,0.094927,82.147263,4.184782,0.949267,-201.187347,0.095785,0.000000
71.510002,18.475998,-201.276306,-0.003428,0.003767,0.095690,82.185341,4.186721,0.956897,-201.276306,0.096634,0.000000
72.020004,18.764587,-201.231827,-0.003397,0.003797,0.096453,83.469055,4.252116,0.964527,-201.231827,0.097485,0.000000
72.530006,18.620110,-201.365265,-0.003372,0.003822,0.097076,82.826385,4.219377,0.970765,-201.365265,0.098335,0.000000
73.040001,19.467628,-201.320786,-0.003346,0.003864,0.098135,86.596336,4.411427,0.981348,-201.320786,0.099184,0.000000
73.550003,19.707436,-201.454224,-0.003307,0.003897,0.098986,87.663055,4.465769,0.989856,-201.454224,0.100035,0.000000
74.060005,20.008690,-201.498703,-0.003316,0.003931,0.099852,89.003098,4.534034,0.998516,-201.498703,0.100884,0.000000
74.570007,20.565010,-201.498703,-0.003277,0.003968,0.100798,91.477730,4.660098,1.007978,-201.498703,0.101733,0.000000
75.080002,20.584000,-201.587677,-0.003260,0.003998,0.101543,91.562202,4.664401,1.015427,-201.587677,0.102584,0.000000
75.590004,21.220016,-201.543182,-0.003221,0.004035,0.102489,94.391350,4.808525,1.024889,-201.543182,0.103434,0.000000
76.100006,20.982811,-201.632156,-0.003212,0.004061,0.103147,93.336205,4.754773,1.031475,-201.632156,0.104283,0.000000
76.610001,21.808365,-201.676636,-0.003186,0.004101,0.104171,97.008453,4.941846,1.041709,-201.676636,0.105134,0.000000
77.120003,21.847458,-201.765594,-0.003152,0.004134,0.105004,97.182343,4.950705,1.050036,-201.765594,0.105983,0.000000
77.630005,22.355751,-201.810074,-0.003143,0.004168,0.105862,99.443344,5.065886,1.058620,-201.810074,0.106834,0.000000
78.140007,22.493156,-201.810074,-0.003122,0.004198,0.106634,100.054558,5.097022,1.066341,-201.810074,0.107683,0.000000
78.650002,22.871117,-201.899033,-0.003083,0.004232,0.107493,101.735809,5.182669,1.074925,-201.899033,0.108533,0.000000
79.160004,23.058044,-201.943512,-0.003074,0.004265,0.108334,102.567307,5.225028,1.083343,-201.943512,0.109383,0.000000
79.670006,23.532448,-202.032486,-0.003053,0.004301,0.109235,104.677559,5.332529,1.092351,-202.032486,0.110233,0.000000
80.180000,23.548088,-202.076965,-0.003027,0.004327,0.109912,104.747124,5.336073,1.099118,-202.076965,0.111082,0.000000
80.690002,24.806335,-201.987991,-0.003005,0.004369,0.110961,110.344093,5.621196,1.109610,-201.987991,0.111933,0.000000
81.200005,24.992523,-202.210403,-0.002979,0.004400,0.111759,111.172295,5.663386,1.117589,-202.210403,0.112782,0.000000
81.710007,25.319832,-202.165924,-0.002962,0.004433,0.112592,112.628235,5.737556,1.125915,-202.165924,0.113632,0.000000
82.220001,25.214828,-202.165924,-0.002936,0.004460,0.113277,112.161156,5.713762,1.132774,-202.165924,0.114482,0.000000
82.730003,26.156555,-202.299362,-0.002923,0.004498,0.114239,116.350166,5.927160,1.142387,-202.299362,0.115332,0.000000
83.240005,26.703201,-202.299362,-0.002910,0.004533,0.115141,118.781769,6.051032,1.151410,-202.299362,0.116183,0.000000
83.750008,26.965721,-202.388321,-0.002893,0.004563,0.115904,119.949516,6.110520,1.159041,-202.388321,0.117032,0.000000
84.260002,28.128639,-202.388321,-0.002863,0.004605,0.116971,125.122437,6.374041,1.169714,-202.388321,0.117881,0.000000
84.770004,28.069809,-202.477295,-0.002828,0.004632,0.117656,124.860748,6.360710,1.176557,-202.477295,0.118732,0.000000
85.280006,28.495430,-202.566254,-0.002820,0.004666,0.118523,126.754005,6.457157,1.185232,-202.566254,0.119581,0.000000
85.790001,28.788109,-202.477295,-0.002798,0.004700,0.119391,128.055908,6.523479,1.193907,-202.477295,0.120431,0.000000
86.300003,30.783287,-202.610733,-0.002794,0.004743,0.120475,136.930893,6.975593,1.204747,-202.610733,0.121289,0.000000
86.810005,30.257866,-202.610733,-0.002764,0.004769,0.121133,134.593704,6.856531,1.211333,-202.610733,0.122140,0.000000
87.320007,30.901695,-202.699692,-0.002729,0.004804,0.122010,137.457611,7.002424,1.220099,-202.699692,0.122989,0.000000
87.830002,31.013779,-202.788651,-0.002712,0.004831,0.122703,137.956177,7.027822,1.227033,-202.788651,0.123840,0.000000
88.340004,32.591522,-202.788651,-0.002699,0.004875,0.123813,144.974335,7.385345,1.238130,-202.788651,0.124690,0.000000
88.850006,32.422470,-202.833130,-0.002677,0.004903,0.124525,144.222351,7.347037,1.245246,-202.833130,0.125539,0.000000
89.360001,33.226044,-202.877625,-0.002669,0.004936,0.125383,147.796829,7.529130,1.253830,-202.877625,0.126390,0.000000
89.870003,33.392128,-202.922104,-0.002647,0.004964,0.126095,148.535599,7.566764,1.260945,-202.922104,0.127239,0.000000
90.380005,35.000031,-203.055542,-0.002647,0.005006,0.127144,155.687912,7.931120,1.271437,-203.055542,0.128088,0.000000
90.890007,35.321762,-203.011063,-0.002600,0.005037,0.127951,157.119049,8.004025,1.279506,-203.011063,0.128939,0.000000
91.400002,35.937294,-203.144501,-0.002587,0.005067,0.128705,159.857071,8.143507,1.287046,-203.144501,0.129789,0.000000
91.910004,36.115654,-203.055542,-0.002570,0.005097,0.129468,160.650452,8.183924,1.294676,-203.055542,0.130638,0.000000
92.420006,37.681854,-203.144501,-0.002552,0.005139,0.130543,167.617264,8.538830,1.305425,-203.144501,0.131489,0.000000
92.930008,38.019226,-203.188980,-0.002544,0.005170,0.131324,169.117966,8.615280,1.313237,-203.188980,0.132338,0.000000
93.440002,38.664917,-203.233459,-0.002505,0.005199,0.132052,171.990143,8.761595,1.320520,-203.233459,0.133189,0.000000
93.950005,39.917953,-203.366913,-0.002488,0.005237,0.133024,177.563919,9.045538,1.330239,-203.366913,0.134038,0.000000
94.460007,40.788559,-203.366913,-0.002496,0.005271,0.133873,181.436569,9.242820,1.338732,-203.366913,0.134888,0.000000
94.970001,41.821892,-203.455872,-0.002466,0.005306,0.134776,186.033066,9.476975,1.347756,-203.455872,0.135738,0.000000
95.480003,42.676117,-203.500351,-0.002458,0.005339,0.135599,189.832855,9.670547,1.355992,-203.500351,0.136588,0.000000
95.990005,43.680405,-203.500351,-0.002440,0.005372,0.136448,194.300140,9.898122,1.364485,-203.500351,0.137437,0.000000
96.500008,44.301521,-203.544830,-0.002414,0.005404,0.137265,197.063004,10.038869,1.372645,-203.544830,0.138288,0.000000
97.010002,45.239159,-203.589310,-0.002406,0.005437,0.138088,201.233826,10.251340,1.380881,-203.589310,0.139137,0.000000
97.520004,46.363716,-203.678268,-0.002380,0.005469,0.138903,206.236115,10.506168,1.389026,-203.678268,0.139987,0.000000
98.030006,47.459610,-203.722763,-0.002371,0.005500,0.139693,211.110886,10.754501,1.396929,-203.722763,0.140837,0.000000
98.540001,48.824356,-203.722763,-0.002358,0.005539,0.140689,217.181580,11.063757,1.406891,-203.722763,0.141687,0.000000
99.050003,49.995842,-203.856201,-0.002337,0.005574,0.141575,222.392609,11.329220,1.415748,-203.856201,0.142538,0.000000
99.560005,50.968102,-203.811722,-0.002337,0.005601,0.142259,226.717438,11.549537,1.422591,-203.811722,0.143387,0.000000
100.070007,52.602821,-203.945160,-0.002302,0.005638,0.143213,233.989029,11.919971,1.432129,-203.945160,0.144236,0.000000
100.580002,53.438423,-203.900681,-0.002298,0.005669,0.143985,237.705978,12.109320,1.439850,-203.900681,0.145087,0.000000
101.090004,55.194534,-203.945160,-0.002281,0.005705,0.144896,245.517548,12.507260,1.448964,-203.945160,0.145936,0.000000
101.600006,55.542328,-204.123077,-0.002255,0.005729,0.145529,247.064621,12.586071,1.455292,-204.123077,0.146786,0.000000
102.110008,58.011902,-204.034119,-0.002246,0.005771,0.146595,258.049835,13.145685,1.465950,-204.034119,0.147637,0.000000
102.620003,59.566933,-204.167572,-0.002220,0.005805,0.147437,264.966949,13.498059,1.474368,-204.167572,0.148486,0.000000
103.130005,61.068336,-204.167572,-0.002229,0.005836,0.148226,271.645538,13.838284,1.482256,-204.167572,0.149335,0.000000
103.640007,62.555588,-204.212051,-0.002195,0.005873,0.149179,278.261139,14.175299,1.491794,-204.212051,0.150186,0.000000
104.150002,64.416336,-204.256531,-0.002182,0.005905,0.149986,286.538177,14.596951,1.499863,-204.256531,0.151035,0.000000
104.660004,65.987000,-204.301010,-0.002164,0.005937,0.150802,293.524841,14.952868,1.508023,-204.301010,0.151886,0.000000
105.170006,65.904343,-204.345490,-0.002156,0.005946,0.151035,293.157166,14.934137,1.510355,-204.345490,294.500458,0.000000
105.680008,65.351364,-204.478928,-0.002134,0.005958,0.151331,290.697388,14.808831,1.513307,-204.478928,294.500458,0.000000
106.190002,65.285080,-204.389969,-0.002130,0.005972,0.151677,290.402527,14.793811,1.516774,-204.389969,294.500458,0.000000
106.700005,64.779404,-204.567886,-0.002130,0.005980,0.151886,288.153168,14.679223,1.518863,-204.567886,294.500458,0.000000
107.210007,65.615372,-204.567886,-0.002113,0.005991,0.152172,291.871765,14.868656,1.521725,-204.567886,294.500458,0.000000
107.720009,65.561005,-204.612381,-0.002104,0.006007,0.152571,291.629913,14.856336,1.525706,-204.612381,294.500458,0.000000
108.230003,65.133896,-204.656860,-0.002113,0.006011,0.152692,289.730042,14.759551,1.526917,-204.656860,294.500458,0.000000
108.740005,64.989410,-204.656860,-0.002091,0.006018,0.152866,289.087341,14.726811,1.528659,-204.656860,294.500458,0.000000
109.250008,65.596756,-204.834778,-0.002087,0.006032,0.153213,291.788940,14.864437,1.532125,-204.834778,294.500458,0.000000
109.760002,65.009155,-204.745819,-0.002082,0.006033,0.153229,289.175171,14.731285,1.532292,-204.745819,294.500458,0.000000
110.270004,65.035965,-204.879257,-0.002078,0.006041,0.153429,289.294434,14.737360,1.534290,-204.879257,294.500458,0.000000
110.780006,65.011765,-204.923737,-0.002078,0.006046,0.153577,289.186768,14.731876,1.535774,-204.923737,294.500458,0.000000
111.290009,64.872116,-205.012711,-0.002070,0.006050,0.153673,288.565582,14.700232,1.536728,-205.012711,294.500458,0.000000
111.800003,65.085861,-205.057190,-0.002052,0.006057,0.153854,289.516357,14.748668,1.538545,-205.057190,294.500458,0.000000
112.310005,65.019577,-205.012711,-0.002065,0.006062,0.153976,289.221527,14.733647,1.539756,-205.012711,294.500458,0.000000
112.820007,65.259766,-205.146149,-0.002057,0.006071,0.154201,290.289948,14.788074,1.542012,-205.146149,294.500458,0.000000
113.330002,65.095917,-205.101669,-0.002065,0.006074,0.154280,289.561096,14.750946,1.542799,-205.101669,294.500458,0.000000
113.840004,65.093307,-205.146149,-0.002057,0.006079,0.154409,289.549500,14.750354,1.544086,-205.146149,294.500458,0.000000
114.350006,65.127197,-205.235107,-0.002035,0.006081,0.154452,289.700256,14.758034,1.544525,-205.235107,294.500458,0.000000
114.860008,65.011017,-205.279587,-0.002035,0.006083,0.154496,289.183441,14.731707,1.544964,-205.279587,294.500458,0.000000
115.370003,64.977875,-205.368546,-0.002039,0.006086,0.154592,289.036011,14.724196,1.545918,-205.368546,294.500458,0.000000
115.880005,64.864670,-205.368546,-0.002026,0.006089,0.154661,288.532471,14.698545,1.546614,-205.368546,294.500458,0.000000
116.390007,65.526001,-205.413025,-0.002026,0.006098,0.154878,291.474213,14.848404,1.548779,-205.413025,294.500458,0.000000
116.900009,65.240768,-205.457520,-0.002035,0.006098,0.154878,290.205444,14.783769,1.548779,-205.457520,294.500458,0.000000
117.410004,65.008774,-205.457520,-0.002031,0.006099,0.154904,289.173462,14.731198,1.549036,-205.457520,294.500458,0.000000
117.920006,65.143204,-205.590958,-0.002022,0.006103,0.155025,289.771454,14.761662,1.550248,-205.590958,294.500458,0.000000
118.430008,64.971176,-205.546478,-0.002026,0.006104,0.155043,289.006226,14.722679,1.550429,-205.546478,294.500458,0.000000
118.940002,65.208374,-205.590958,-0.002022,0.006109,0.155181,290.061340,14.776429,1.551807,-205.590958,294.500458,0.000000
119.450005,65.031494,-205.679916,-0.002005,0.006110,0.155190,289.274536,14.736347,1.551898,-205.679916,294.500458,0.000000
119.960007,64.851273,-205.724396,-0.002013,0.006111,0.155216,288.472870,14.695509,1.552155,-205.724396,294.500458,0.000000
120.470009,64.904144,-205.724396,-0.002018,0.006114,0.155294,288.708038,14.707489,1.552942,-205.724396,294.500458,0.000000
120.980003,65.577393,-205.813354,-0.002009,0.006123,0.155527,291.702820,14.860049,1.555274,-205.813354,294.500458,0.000000
121.490005,65.482071,-205.857849,-0.002005,0.006123,0.155527,291.278809,14.838449,1.555274,-205.857849,294.500458,0.000000
122.000008,65.296997,-205.902328,-0.002013,0.006123,0.155527,290.455536,14.796512,1.555274,-205.902328,294.500458,0.000000
122.510002,65.118637,-205.902328,-0.002009,0.006123,0.155527,289.662170,14.756094,1.555274,-205.902328,294.500458,0.000000
123.020004,65.986633,-205.991287,-0.002009,0.006129,0.155667,293.523193,14.952785,1.556667,-205.991287,294.500458,0.000000
123.530006,65.764328,-206.035767,-0.002005,0.006128,0.155658,292.534332,14.902411,1.556576,-206.035767,294.500458,0.000000
124.040009,65.531586,-206.080246,-0.001988,0.006129,0.155667,291.499054,14.849669,1.556667,-206.080246,294.500458,0.000000
124.550003,65.311890,-206.124725,-0.002005,0.006129,0.155667,290.521790,14.799886,1.556667,-206.124725,294.500458,0.000000
125.060005,65.108582,-206.124725,-0.001996,0.006130,0.155692,289.617432,14.753816,1.556924,-206.124725,294.500458,0.000000
125.570007,64.924622,-206.213684,-0.001996,0.006130,0.155692,288.799133,14.712130,1.556924,-206.213684,294.500458,0.000000
126.080009,64.738068,-206.302658,-0.001996,0.006130,0.155692,287.969299,14.669856,1.556924,-206.302658,294.500458,0.000000
126.590004,64.550385,-206.302658,-0.002001,0.006130,0.155692,287.134460,14.627326,1.556924,-206.302658,294.500458,0.000000
127.100006,64.399200,-206.391617,-0.001996,0.006130,0.155692,286.461945,14.593067,1.556924,-206.391617,294.500458,0.000000
127.610008,66.866913,-206.391617,-0.001979,0.006036,0.153308,297.438873,15.152259,1.533079,-206.391617,294.500458,0.000000
128.120010,66.676636,-206.480576,-0.001975,0.006036,0.153308,296.592499,15.109142,1.533079,-206.480576,294.500458,0.000000
128.630005,66.382843,-206.480576,-0.001992,0.006036,0.153317,295.285645,15.042567,1.533170,-206.480576,294.500458,0.000000
129.139999,66.287888,-206.525055,-0.001975,0.006036,0.153317,294.863251,15.021050,1.533170,-206.525055,294.500458,0.000000
129.650009,66.135956,-206.614014,-0.001983,0.006036,0.153317,294.187439,14.986622,1.533170,-206.614014,294.500458,0.000000
130.160004,65.924072,-206.614014,-0.001988,0.006038,0.153359,293.244934,14.938608,1.533594,-206.614014,294.500458,0.000000
130.670013,65.844391,-206.702972,-0.001975,0.006044,0.153524,292.890472,14.920552,1.535244,-206.702972,294.500458,0.000000
131.180008,65.638840,-206.702972,-0.001970,0.006050,0.153680,291.976135,14.873974,1.536804,-206.702972,294.500458,0.000000
131.690002,65.518936,-206.747467,-0.001983,0.006083,0.154513,291.442780,14.846803,1.545130,-206.747467,294.500458,0.000000
132.200012,65.463455,-206.836426,-0.001975,0.006104,0.155050,291.195984,14.834231,1.550505,-206.836426,294.500458,0.000000
132.710007,65.302216,-206.880905,-0.001979,0.006109,0.155173,290.478760,14.797693,1.551731,-206.880905,294.500458,0.000000
133.220001,65.216187,-206.969864,-0.001962,0.006111,0.155225,290.096100,14.778199,1.552246,-206.969864,294.500458,0.000000
133.730011,65.091446,-206.969864,-0.001979,0.006120,0.155450,289.541199,14.749933,1.554502,-206.969864,294.500458,0.000000
134.240005,65.410950,-206.969864,-0.001975,0.006145,0.156092,290.962433,14.822333,1.560921,-206.969864,294.500458,0.000000
134.750000,65.295135,-207.103302,-0.001966,0.006146,0.156109,290.447266,14.796089,1.561087,-207.103302,294.500458,0.000000
135.260010,65.280991,-207.058823,-0.001957,0.006147,0.156127,290.384338,14.792884,1.561269,-207.058823,294.500458,0.000000
135.770004,65.235931,-207.147797,-0.001975,0.006148,0.156162,290.183929,14.782673,1.561617,-207.147797,294.500458,0.000000
136.280014,65.218796,-207.103302,-0.001966,0.006149,0.156195,290.107697,14.778790,1.561950,-207.103302,294.500458,0.000000
136.790009,65.168900,-207.236755,-0.001966,0.006150,0.156204,289.885742,14.767485,1.562041,-207.236755,294.500458,0.000000
137.300003,65.159592,-207.281235,-0.001957,0.006158,0.156413,289.844330,14.765374,1.564131,-207.281235,294.500458,0.000000
137.810013,65.615372,-207.281235,-0.001970,0.006158,0.156421,291.871765,14.868656,1.564206,-207.281235,294.500458,0.000000
138.320007,65.587814,-207.370193,-0.001962,0.006158,0.156421,291.749176,14.862411,1.564206,-207.370193,294.500458,0.000000
138.830002,65.520798,-207.370193,-0.001979,0.006158,0.156421,291.451050,14.847225,1.564206,-207.370193,294.500458,0.000000
139.340012,65.447815,-207.503632,-0.001957,0.006158,0.156421,291.126434,14.830687,1.564206,-207.503632,294.500458,0.000000
139.850006,65.345779,-207.548111,-0.001962,0.006159,0.156430,290.672546,14.807566,1.564297,-207.548111,294.500458,0.000000
140.360001,65.289551,-207.503632,-0.001970,0.006159,0.156439,290.422424,14.794824,1.564388,-207.503632,294.500458,0.000000
140.870010,65.229233,-207.548111,-0.001962,0.006159,0.156448,290.154114,14.781156,1.564479,-207.548111,294.500458,0.000000
141.380005,65.164810,-207.637085,-0.001966,0.006160,0.156455,289.867554,14.766557,1.564554,-207.637085,294.500458,0.000000
141.889999,65.228485,-207.681564,-0.001957,0.006162,0.156516,290.150787,14.780987,1.565160,-207.681564,294.500458,0.000000
142.400009,65.202789,-207.726044,-0.001970,0.006162,0.156516,290.036499,14.775164,1.565160,-207.726044,294.500458,0.000000
142.910004,65.133530,-207.815002,-0.001970,0.006162,0.156525,289.728424,14.759469,1.565251,-207.815002,294.500458,0.000000
143.420013,65.174118,-207.770523,-0.001953,0.006164,0.156569,289.908966,14.768666,1.565690,-207.770523,294.500458,0.000000
143.930008,65.132034,-207.903961,-0.001966,0.006164,0.156569,289.721771,14.759130,1.565690,-207.903961,294.500458,0.000000
144.440002,65.139481,-207.815002,-0.001957,0.006166,0.156604,289.754883,14.760817,1.566038,-207.815002,294.500458,0.000000
144.950012,65.150284,-208.037415,-0.001966,0.006166,0.156620,289.802948,14.763266,1.566205,-208.037415,294.500458,0.000000
145.460007,65.102997,-207.948441,-0.001966,0.006167,0.156630,289.592590,14.752550,1.566296,-207.948441,294.500458,0.000000
145.970001,65.108948,-207.992920,-0.001957,0.006168,0.156664,289.619049,14.753899,1.566644,-207.992920,294.500458,0.000000
146.480011,65.120117,-208.081894,-0.001962,0.006168,0.156673,289.668762,14.756430,1.566735,-208.081894,294.500458,0.000000
146.990005,65.082504,-208.126373,-0.001953,0.006168,0.156673,289.501434,14.747907,1.566735,-208.126373,294.500458,0.000000
147.500000,65.284332,-208.170853,-0.001962,0.006172,0.156760,290.399200,14.793641,1.567598,-208.170853,294.500458,0.000000
148.010010,65.282471,-208.170853,-0.001957,0.006172,0.156760,290.390930,14.793220,1.567598,-208.170853,294.500458,0.000000
148.520004,65.236679,-208.259811,-0.001966,0.006172,0.156760,290.187256,14.782843,1.567598,-208.259811,294.500458,0.000000
149.030014,65.183792,-208.259811,-0.001962,0.006172,0.156760,289.951996,14.770859,1.567598,-208.259811,294.500458,0.000000
149.540009,65.148788,-208.259811,-0.001970,0.006173,0.156802,289.796295,14.762927,1.568021,-208.259811,294.500458,0.000000
150.050003,65.146927,-208.437744,-0.001962,0.006173,0.156802,289.787994,14.762505,1.568021,-208.437744,294.500458,0.000000
150.560013,65.121231,-208.393250,-0.001953,0.006173,0.156802,289.673706,14.756681,1.568021,-208.393250,294.500458,0.000000
151.070007,65.526382,-208.482224,-0.001953,0.006179,0.156951,291.475922,14.848491,1.569505,-208.482224,294.500458,0.000000
151.580002,65.554306,-208.526703,-0.001970,0.006179,0.156951,291.600128,14.854818,1.569505,-208.526703,294.500458,0.000000
152.090012,65.519302,-208.526703,-0.001953,0.006179,0.156951,291.444427,14.846886,1.569505,-208.526703,294.500458,0.000000
152.600006,65.486542,-208.660141,-0.001953,0.006179,0.156951,291.298676,14.839462,1.569505,-208.660141,294.500458,0.000000
153.110001,65.418396,-208.660141,-0.001975,0.006179,0.156951,290.995544,14.824020,1.569505,-208.660141,294.500458,0.000000
153.620010,65.365509,-208.704620,-0.001953,0.006179,0.156951,290.760315,14.812036,1.569505,-208.704620,294.500458,0.000000
154.130005,65.317108,-208.793579,-0.001979,0.006179,0.156951,290.545013,14.801068,1.569505,-208.793579,294.500458,0.000000
154.640015,65.289551,-208.749100,-0.001940,0.006180,0.156960,290.422424,14.794824,1.569596,-208.749100,294.500458,0.000000
155.150009,65.264969,-208.838058,-0.001949,0.006180,0.156967,290.313080,14.789253,1.569672,-208.838058,294.500458,0.000000
155.660004,65.240402,-208.882553,-0.001953,0.006180,0.156967,290.203796,14.783687,1.569672,-208.882553,294.500458,0.000000
156.170013,65.181564,-208.971512,-0.001940,0.006180,0.156967,289.942078,14.770354,1.569672,-208.971512,294.500458,0.000000
156.680008,65.122360,-208.927032,-0.001966,0.006180,0.156967,289.678711,14.756938,1.569672,-208.927032,294.500458,0.000000
157.190002,65.076187,-209.015991,-0.001949,0.006180,0.156976,289.473328,14.746475,1.569762,-209.015991,294.500458,0.000000
157.700012,65.386002,-209.104950,-0.001957,0.006186,0.157116,290.851471,14.816680,1.571155,-209.104950,294.500458,0.000000
158.210007,65.421005,-209.060471,-0.001944,0.006186,0.157116,291.007172,14.824612,1.571155,-209.060471,294.500458,0.000000
158.720001,65.415405,-209.104950,-0.001949,0.006186,0.157116,290.982269,14.823343,1.571155,-209.104950,294.500458,0.000000
159.230011,65.386002,-209.238388,-0.001957,0.006186,0.157116,290.851471,14.816680,1.571155,-209.238388,294.500458,0.000000
159.740005,65.354721,-209.238388,-0.001953,0.006186,0.157116,290.712311,14.809591,1.571155,-209.238388,294.500458,0.000000
160.250000,65.319717,-209.327362,-0.001957,0.006186,0.157116,290.556610,14.801660,1.571155,-209.327362,294.500458,0.000000
160.760010,65.302948,-209.282867,-0.001962,0.006186,0.157116,290.482025,14.797860,1.571155,-209.282867,294.500458,0.000000
161.270004,65.258270,-209.371841,-0.001949,0.006186,0.157116,290.283295,14.787735,1.571155,-209.371841,294.500458,0.000000
161.780014,65.226624,-209.460800,-0.001944,0.006186,0.157116,290.142517,14.780564,1.571155,-209.460800,294.500458,0.000000
162.290009,65.172623,-209.416321,-0.001944,0.006186,0.157116,289.902313,14.768328,1.571155,-209.416321,294.500458,0.000000
162.800003,65.119751,-209.549759,-0.001949,0.006186,0.157116,289.667114,14.756347,1.571155,-209.549759,294.500458,0.000000
163.310013,65.073578,-209.549759,-0.001957,0.006186,0.157116,289.461731,14.745884,1.571155,-209.549759,294.500458,0.000000
163.820007,65.563995,-209.638718,-0.001949,0.006192,0.157288,291.643219,14.857014,1.572881,-209.638718,294.500458,0.000000
164.330002,65.575897,-209.727692,-0.001953,0.006192,0.157288,291.696167,14.859711,1.572881,-209.727692,294.500458,0.000000
164.840012,65.571442,-209.683197,-0.001940,0.006192,0.157288,291.676331,14.858701,1.572881,-209.683197,294.500458,0.000000
165.350006,65.539780,-209.772171,-0.001944,0.006192,0.157288,291.535492,14.851526,1.572881,-209.772171,1681.640747,0.000000
165.860001,65.435516,-209.772171,-0.001944,0.006175,0.156855,291.071716,14.827900,1.568551,-209.772171,0.156655,0.000000
166.370010,65.343918,-209.816650,-0.001936,0.006156,0.156352,290.664276,14.807143,1.563525,-209.816650,0.155806,0.000000
166.880005,65.288055,-209.905609,-0.001940,0.006125,0.155580,290.415771,14.794485,1.555804,-209.905609,0.154955,0.000000
167.390015,65.210602,-209.905609,-0.001944,0.006089,0.154669,290.071259,14.776934,1.546690,-209.905609,0.154106,0.000000
167.900009,65.125336,-209.994568,-0.001940,0.006052,0.153724,289.691956,14.757612,1.537243,-209.994568,0.153256,0.000000
168.410004,65.066132,-209.950089,-0.001940,0.006032,0.153203,289.428619,14.744196,1.532035,-209.950089,0.152406,0.000000
168.920013,64.975647,-210.039047,-0.001953,0.005995,0.152284,289.026123,14.723693,1.522845,-210.039047,0.151556,0.000000
169.430008,64.900055,-210.083527,-0.001949,0.005963,0.151452,288.689850,14.706562,1.514518,-210.083527,0.150707,0.000000
169.940002,64.301651,-210.172501,-0.001940,0.005927,0.150542,286.028015,14.570963,1.505419,-210.172501,0.149856,0.000000
170.450012,63.275009,-210.216980,-0.001949,0.005901,0.149891,281.461304,14.338323,1.498909,-210.216980,0.149007,0.000000
170.960007,61.320061,-210.261459,-0.001936,0.005865,0.148981,272.765259,13.895325,1.489810,-210.261459,0.148156,0.000000
171.470001,59.084335,-210.261459,-0.001884,0.005835,0.148200,262.820251,13.388702,1.481998,-210.261459,0.147307,0.000000
171.980011,56.556297,-210.350418,-0.001871,0.005801,0.147351,251.574982,12.815840,1.473505,-210.350418,0.146457,0.000000
172.490005,54.072205,-210.350418,-0.001867,0.005777,0.146743,240.525177,12.252936,1.467434,-210.350418,0.145606,0.000000
173.000015,50.357788,-210.394897,-0.001880,0.005738,0.145746,224.002625,11.411238,1.457457,-210.394897,0.144757,0.000000
173.510010,46.507080,-210.394897,-0.001867,0.005703,0.144862,206.873825,10.538655,1.448616,-210.394897,0.143908,0.000000
174.020004,43.409691,-210.528336,-0.001871,0.005675,0.144141,193.095947,9.836777,1.441409,-210.528336,0.143057,0.000000
174.530014,40.227394,-210.572815,-0.001863,0.005646,0.143396,178.940384,9.115658,1.433960,-210.572815,0.142208,0.000000
175.040009,35.773445,-210.572815,-0.001858,0.005605,0.142354,159.128235,8.106379,1.423544,-210.572815,0.141358,0.000000
175.550003,32.787392,-210.661789,-0.001863,0.005578,0.141670,145.845596,7.429729,1.416701,-210.661789,0.140507,0.000000
176.060013,29.291183,-210.661789,-0.001858,0.005544,0.140812,130.293686,6.637477,1.408117,-210.661789,0.139658,0.000000
176.570007,25.883606,-210.750748,-0.001867,0.005513,0.140040,115.136032,5.865309,1.400396,-210.750748,0.138807,0.000000
177.080002,22.057480,-210.750748,-0.001871,0.005476,0.139093,98.116570,4.998296,1.390934,-210.750748,0.137958,0.000000
177.590012,18.614899,-210.795227,-0.001871,0.005444,0.138270,82.803207,4.218196,1.382698,-210.795227,0.137109,0.000000
178.100006,14.799942,-210.884186,-0.001867,0.005409,0.137395,65.833427,3.353715,1.373947,-210.884186,0.136258,0.000000
178.610016,10.403709,-210.928665,-0.001850,0.005368,0.136346,46.278011,2.357514,1.363455,-210.928665,0.135408,0.000000
179.120010,7.447075,-210.973145,-0.001863,0.005339,0.135599,33.126244,1.687531,1.355992,-210.973145,0.134559,0.000000
179.630005,4.283394,-211.017639,-0.001858,0.005310,0.134880,19.053488,0.970631,1.348800,-211.017639,0.133708,0.000000
180.140015,0.697449,-211.106598,-0.001854,0.005275,0.133987,3.102407,0.158044,1.339868,-211.106598,0.132859,0.000000
180.650009,-3.103729,-211.106598,-0.001876,0.005237,0.133031,-13.806077,-0.703315,1.330315,-211.106598,0.132010,0.000000
181.160004,0.023827,-211.151077,-0.001867,0.005199,0.132061,0.105986,0.005399,1.320610,-211.151077,0.131159,0.000000
181.670013,0.165703,-211.240036,-0.001854,0.005172,0.131359,0.737083,0.037549,1.313586,-211.240036,0.130309,0.000000
182.180008,0.172775,-211.240036,-0.001850,0.005149,0.130786,0.768543,0.039151,1.307863,-211.240036,0.129459,0.000000
182.690002,0.134048,-211.328995,-0.001841,0.005105,0.129677,0.596277,0.030376,1.296766,-211.328995,0.128609,0.000000
183.200012,0.145966,-211.373474,-0.001841,0.005071,0.128791,0.649287,0.033076,1.287909,-211.373474,0.127760,0.000000
183.710007,0.145226,-211.328995,-0.001824,0.005038,0.127958,0.645995,0.032909,1.279582,-211.328995,0.126909,0.000000
184.220001,0.136658,-211.462448,-0.001819,0.005017,0.127430,0.607884,0.030967,1.274298,-211.462448,0.126060,0.000000
184.730011,0.094208,-211.373474,-0.001811,0.004973,0.126311,0.419057,0.021348,1.263110,-211.373474,0.125210,0.000000
185.240005,0.115059,-211.595886,-0.001807,0.004942,0.125539,0.511808,0.026073,1.255389,-211.595886,0.124360,0.000000
185.750015,0.122505,-211.595886,-0.001815,0.004907,0.124638,0.544930,0.027760,1.246381,-211.595886,0.123501,0.000000
186.260010,0.108360,-211.595886,-0.001807,0.004878,0.123892,0.482011,0.024555,1.238917,-211.595886,0.122652,0.000000
186.770004,0.074844,-211.729324,-0.001819,0.004840,0.122947,0.332924,0.016960,1.229470,-211.729324,0.121801,0.000000
187.280014,0.073723,-211.729324,-0.001807,0.004805,0.122045,0.327936,0.016706,1.220447,-211.729324,0.120952,0.000000
187.790009,0.082664,-211.818283,-0.001815,0.004774,0.121263,0.367710,0.018732,1.212635,-211.818283,0.120102,0.000000
188.300003,0.033882,-211.773804,-0.001815,0.004737,0.120319,0.150715,0.007678,1.203188,-211.773804,0.119251,0.000000
188.810013,0.025322,-211.862762,-0.001807,0.004708,0.119581,0.112638,0.005738,1.195815,-211.862762,0.118402,0.000000
189.320007,0.033882,-211.907257,-0.001819,0.004673,0.118697,0.150715,0.007678,1.186973,-211.907257,0.117553,0.000000
189.830002,-0.016762,-211.907257,-0.001798,0.004644,0.117951,-0.074560,-0.003798,1.179510,-211.907257,0.116702,0.000000
190.340012,0.015266,-212.040695,-0.001802,0.004607,0.117023,0.067908,0.003459,1.170229,-212.040695,0.115853,0.000000
190.850006,-0.010803,-212.040695,-0.001802,0.004568,0.116025,-0.048055,-0.002448,1.160252,-212.040695,0.115003,0.000000
191.360016,-0.019363,-212.085175,-0.001824,0.004532,0.115124,-0.086133,-0.004388,1.151244,-212.085175,0.114152,0.000000
191.870010,-0.046181,-212.129654,-0.001815,0.004502,0.114343,-0.205422,-0.010465,1.143432,-212.129654,0.113303,0.000000
192.380005,-0.080437,-212.129654,-0.001802,0.004468,0.113485,-0.357800,-0.018227,1.134848,-212.129654,0.112452,0.000000
192.890015,-0.093094,-212.263092,-0.001802,0.004436,0.112678,-0.414102,-0.021095,1.126778,-212.263092,0.111603,0.000000
193.400009,-0.067772,-212.263092,-0.001828,0.004397,0.111689,-0.301465,-0.015357,1.116892,-212.263092,0.110754,0.000000
193.910004,-0.078201,-212.352066,-0.001824,0.004372,0.111056,-0.347857,-0.017721,1.110564,-212.352066,0.109903,0.000000
194.420013,-0.128471,-212.352066,-0.001832,0.004333,0.110051,-0.571469,-0.029112,1.100511,-212.352066,0.109053,0.000000
194.930008,-0.105011,-212.485504,-0.001832,0.004303,0.109296,-0.467112,-0.023796,1.092957,-212.485504,0.108204,0.000000
195.440002,-0.107994,-212.441025,-0.001845,0.004268,0.108411,-0.480382,-0.024472,1.084115,-212.441025,0.107353,0.000000
195.950012,-0.118416,-212.441025,-0.001837,0.004236,0.107588,-0.526740,-0.026833,1.075879,-212.441025,0.106504,0.000000
196.460007,-0.135918,-212.574463,-0.001871,0.004203,0.106764,-0.604592,-0.030799,1.067643,-212.574463,0.105655,0.000000
196.970016,-0.140388,-212.618942,-0.001910,0.004168,0.105879,-0.624479,-0.031812,1.058787,-212.618942,0.104804,0.000000
197.480011,-0.111717,-212.574463,-0.001927,0.004137,0.105081,-0.496943,-0.025315,1.050808,-212.574463,0.103954,0.000000
197.990005,-0.121399,-212.663422,-0.001983,0.004095,0.104024,-0.540009,-0.027509,1.040241,-212.663422,0.103104,0.000000
198.500015,-0.117676,-212.663422,-0.002001,0.004070,0.103382,-0.523448,-0.026666,1.033821,-212.663422,0.102254,0.000000
199.010010,-0.110596,-212.796875,-0.002031,0.004037,0.102549,-0.491954,-0.025061,1.025495,-212.796875,0.101405,0.000000
199.520004,-0.113579,-212.752396,-0.002091,0.004000,0.101596,-0.505224,-0.025737,1.015957,-212.752396,0.100554,0.000000
200.030014,-0.117676,-212.796875,-0.002126,0.003965,0.100719,-0.523448,-0.026666,1.007191,-212.796875,0.099705,0.000000
200.540009,-0.102776,-212.930313,-0.002151,0.003928,0.099783,-0.457169,-0.023289,0.997835,-212.930313,0.098855,0.000000
201.050003,-0.119904,-212.885834,-0.002173,0.003904,0.099149,-0.533358,-0.027171,0.991491,-212.885834,0.098005,0.000000
201.560013,-0.118042,-213.019272,-0.002203,0.003872,0.098360,-0.525077,-0.026749,0.983603,-213.019272,0.097155,0.000000
202.070007,-0.113579,-212.974792,-0.002255,0.003829,0.097267,-0.505224,-0.025737,0.972673,-212.974792,0.096306,0.000000
202.580017,-0.100174,-213.108231,-0.002285,0.003800,0.096513,-0.445596,-0.022700,0.965133,-213.108231,0.095455,0.000000
203.090012,-0.093842,-213.108231,-0.002324,0.003766,0.095655,-0.417428,-0.021265,0.956549,-213.108231,0.094606,0.000000
203.600006,-0.078575,-213.152710,-0.002337,0.003739,0.094962,-0.349520,-0.017805,0.949615,-213.152710,0.093755,0.000000
204.110016,-0.099800,-213.241684,-0.002371,0.003700,0.093980,-0.443933,-0.022615,0.939805,-213.241684,0.092906,0.000000
204.620010,-0.059586,-213.241684,-0.002410,0.003665,0.093096,-0.265050,-0.013502,0.930963,-213.241684,0.092056,0.000000
205.130005,-0.061447,-213.241684,-0.002440,0.003632,0.092264,-0.273331,-0.013924,0.922636,-213.241684,0.091205,0.000000
205.640015,-0.083412,-213.419601,-0.002470,0.003598,0.091379,-0.371036,-0.018901,0.913795,-213.419601,0.090356,0.000000
206.150009,-0.080811,-213.375122,-0.002527,0.003568,0.090626,-0.359463,-0.018312,0.906255,-213.375122,0.089507,0.000000
206.660004,-0.051018,-213.464081,-0.002552,0.003538,0.089853,-0.226938,-0.011561,0.898534,-213.464081,0.088656,0.000000
207.170013,-0.051765,-213.419601,-0.002587,0.003496,0.088795,-0.230264,-0.011730,0.887951,-213.419601,0.087807,0.000000
207.680008,-0.113953,-213.464081,-0.002613,0.003464,0.087997,-0.506887,-0.025822,0.879973,-213.464081,0.086957,0.000000
208.190002,-0.066658,-213.597534,-0.002665,0.003435,0.087243,-0.296510,-0.015105,0.872433,-213.597534,0.086106,0.000000
208.700012,-0.051018,-213.597534,-0.002716,0.003400,0.086350,-0.226938,-0.011561,0.863501,-213.597534,0.085257,0.000000
209.200012,-0.070381,-213.686493,-0.002729,0.003377,0.085785,-0.313071,-0.015949,0.857854,-213.686493,0.085725,0.000000