File: Data/compression 29/AutoNoHeating-17-29-reverse-1-2_10232024_172326.csv
Time (sec),S:Load (lbs),S:HL1 (DIM),S:LVDT (in),S:Position (in),Ch:Position (mm),Ch:Load (N),Ch:Stress (MPa),Ch:Strain (mm/mm),Ch:HL1 (DIM),Set Point (),Cycles ()
0.110000,0.023453,-166.136353,-0.012564,-0.005501,-0.139719,0.104323,0.005314,-1.397186,-166.136353,-0.139510,0.000000
0.660000,0.058456,-166.180832,-0.012594,-0.005352,-0.135929,0.260027,0.013246,-1.359292,-166.180832,-0.135036,0.000000
1.210000,0.008560,-166.225311,-0.012309,-0.005004,-0.127110,0.038078,0.001940,-1.271096,-166.225311,-0.125861,0.000000
1.760000,-0.033890,-166.314270,-0.011904,-0.004642,-0.117917,-0.150749,-0.007680,-1.179169,-166.314270,-0.116703,0.000000
2.310000,0.075218,-166.358749,-0.011525,-0.004278,-0.108672,0.334587,0.017045,-1.086719,-166.358749,-0.107545,0.000000
2.860000,0.072609,-166.403244,-0.011158,-0.003926,-0.099714,0.322981,0.016453,-0.997138,-166.403244,-0.098369,0.000000
3.410000,0.081543,-166.492203,-0.010809,-0.003561,-0.090452,0.362721,0.018478,-0.904522,-166.492203,-0.089211,0.000000
3.960000,0.037979,-166.536682,-0.010447,-0.003195,-0.081155,0.168940,0.008606,-0.811550,-166.536682,-0.080054,0.000000
4.510000,0.045799,-166.625641,-0.010093,-0.002842,-0.072179,0.203725,0.010378,-0.721795,-166.625641,-0.070896,0.000000
5.060000,0.068886,-166.714600,-0.009830,-0.000000,-0.000009,0.306419,0.015610,-0.000091,-166.714600,0.000147,0.000000
5.610000,0.055481,-166.714600,-0.009835,-0.000000,-0.000009,0.246792,0.012572,-0.000091,-166.714600,0.000555,0.000000
6.160000,0.057716,-166.803574,-0.009839,0.000020,0.000503,0.256735,0.013079,0.005026,-166.803574,0.001474,0.000000
6.710001,0.068138,-166.848053,-0.009826,0.000063,0.001596,0.303093,0.015440,0.015957,-166.848053,0.002384,0.000000
7.260000,0.090111,-166.937012,-0.009817,0.000088,0.002237,0.400833,0.020419,0.022369,-166.937012,0.003304,0.000000
7.810000,0.093834,-167.025970,-0.009731,0.000133,0.003373,0.417394,0.021263,0.033731,-167.025970,0.004223,0.000000
8.360001,0.093086,-167.070450,-0.009731,0.000167,0.004249,0.414068,0.021094,0.042489,-167.070450,0.005134,0.000000
8.910001,0.078194,-167.070450,-0.009671,0.000201,0.005099,0.347823,0.017719,0.050990,-167.070450,0.006053,0.000000
9.460000,0.095322,-167.203888,-0.009662,0.000241,0.006122,0.424012,0.021600,0.061224,-167.203888,0.006973,0.000000
10.010000,0.032768,-167.248383,-0.009628,0.000269,0.006842,0.145760,0.007425,0.068423,-167.248383,0.007892,0.000000
10.560000,0.064041,-167.248383,-0.009576,0.000311,0.007909,0.284869,0.014512,0.079089,-167.248383,0.008802,0.000000
11.110001,0.088249,-167.292862,-0.009546,0.000339,0.008620,0.392552,0.019998,0.086197,-167.292862,0.009721,0.000000
11.660001,0.079681,-167.426300,-0.009494,0.000384,0.009748,0.354441,0.018056,0.097476,-167.426300,0.010641,0.000000
12.210001,0.047287,-167.515259,-0.009472,0.000418,0.010606,0.210343,0.010715,0.106060,-167.515259,0.011551,0.000000
12.760000,0.087875,-167.515259,-0.009416,0.000453,0.011499,0.390889,0.019913,0.114993,-167.515259,0.012470,0.000000
13.310000,0.059204,-167.604218,-0.009399,0.000481,0.012210,0.263353,0.013416,0.122101,-167.604218,0.013389,0.000000
13.860001,0.026436,-167.604218,-0.009339,0.000528,0.013407,0.117593,0.005990,0.134069,-167.604218,0.014300,0.000000
14.410001,0.042076,-167.693192,-0.009321,0.000566,0.014370,0.187164,0.009535,0.143697,-167.693192,0.015220,0.000000
14.960001,0.077820,-167.826630,-0.009291,0.000591,0.015003,0.346160,0.017634,0.150026,-167.826630,0.016139,0.000000
15.510001,0.033882,-167.826630,-0.009235,0.000639,0.016234,0.150715,0.007678,0.162342,-167.826630,0.017058,0.000000
16.060001,-0.010056,-167.871109,-0.009222,0.000668,0.016980,-0.044729,-0.002279,0.169798,-167.871109,0.017968,0.000000
16.610001,0.050270,-168.004547,-0.009171,0.000706,0.017934,0.223612,0.011391,0.179343,-168.004547,0.018888,0.000000
17.160002,0.035370,-168.049026,-0.009149,0.000750,0.019044,0.157333,0.008015,0.190441,-168.049026,0.019807,0.000000
17.710001,-0.016388,-168.138000,-0.009089,0.000779,0.019790,-0.072897,-0.003714,0.197897,-168.138000,0.020718,0.000000
18.260000,0.014145,-168.182480,-0.009046,0.000816,0.020726,0.062920,0.003205,0.207261,-168.182480,0.021637,0.000000
18.810001,0.048409,-168.226959,-0.009020,0.000836,0.021229,0.215332,0.010970,0.212295,-168.226959,0.022556,0.000000
19.360001,0.036118,-168.271439,-0.008968,0.000894,0.022704,0.160659,0.008184,0.227041,-168.271439,0.023475,0.000000
19.910002,0.027924,-168.315918,-0.008942,0.000923,0.023432,0.124210,0.006328,0.234323,-168.315918,0.024386,0.000000
20.460001,0.080055,-168.404877,-0.008899,0.000962,0.024438,0.356103,0.018141,0.244383,-168.404877,0.025305,0.000000
21.010000,0.077454,-168.404877,-0.008886,0.001000,0.025400,0.344531,0.017551,0.254004,-168.404877,0.026225,0.000000
21.560001,0.061813,-168.538330,-0.008817,0.001033,0.026242,0.274960,0.014007,0.262422,-168.538330,0.027135,0.000000
22.110001,0.072235,-168.582809,-0.008783,0.001071,0.027204,0.321318,0.016369,0.272043,-168.582809,0.028054,0.000000
22.660002,0.114319,-168.671768,-0.008748,0.001103,0.028020,0.508516,0.025905,0.280196,-168.671768,0.028974,0.000000
23.210001,0.075218,-168.716248,-0.008709,0.001137,0.028887,0.334587,0.017045,0.288871,-168.716248,0.029893,0.000000
23.760000,0.055107,-168.760727,-0.008683,0.001171,0.029755,0.245129,0.012487,0.297546,-168.760727,0.030804,0.000000
24.310001,0.104263,-168.805206,-0.008658,0.001213,0.030812,0.463786,0.023626,0.308121,-168.805206,0.031723,0.000000
24.860001,0.114685,-168.849686,-0.008627,0.001242,0.031558,0.510145,0.025988,0.315585,-168.849686,0.032642,0.000000
25.410002,0.064415,-168.938660,-0.008589,0.001284,0.032616,0.286532,0.014597,0.326160,-168.938660,0.033553,0.000000
25.960001,0.061440,-168.983139,-0.008550,0.001320,0.033518,0.273297,0.013922,0.335183,-168.983139,0.034472,0.000000
26.510002,0.117668,-169.072098,-0.008524,0.001353,0.034377,0.523414,0.026664,0.343767,-169.072098,0.035391,0.000000
27.060001,0.112083,-169.116577,-0.008468,0.001394,0.035418,0.498572,0.025398,0.354175,-169.116577,0.036302,0.000000
27.610001,0.065910,-169.205536,-0.008451,0.001426,0.036215,0.293184,0.014935,0.362154,-169.205536,0.037221,0.000000
28.160002,0.083405,-169.250015,-0.008399,0.001467,0.037255,0.371002,0.018900,0.372555,-169.250015,0.038140,0.000000
28.710001,0.103889,-169.294495,-0.008373,0.001491,0.037880,0.462123,0.023542,0.378800,-169.294495,0.039059,0.000000
29.260002,0.072235,-169.338974,-0.008321,0.001534,0.038956,0.321318,0.016369,0.389557,-169.338974,0.039970,0.000000
29.810001,0.088997,-169.472427,-0.008295,0.001572,0.039919,0.395878,0.020167,0.399185,-169.472427,0.040890,0.000000
30.360001,0.109100,-169.472427,-0.008257,0.001602,0.040682,0.485303,0.024722,0.406816,-169.472427,0.041809,0.000000
30.910002,0.076332,-169.561386,-0.008209,0.001646,0.041800,0.339542,0.017297,0.418004,-169.561386,0.042719,0.000000
31.460001,0.041702,-169.561386,-0.008179,0.001677,0.042589,0.185501,0.009450,0.425892,-169.561386,0.043638,0.000000
32.010002,0.083405,-169.694824,-0.008132,0.001716,0.043578,0.371002,0.018900,0.435778,-169.694824,0.044558,0.000000
32.560001,0.090485,-169.783783,-0.008110,0.001741,0.044228,0.402496,0.020504,0.442280,-169.783783,0.045477,0.000000
33.110001,0.065910,-169.739304,-0.008050,0.001787,0.045382,0.293184,0.014935,0.453816,-169.739304,0.046388,0.000000
33.660000,0.043938,-169.872757,-0.008028,0.001820,0.046240,0.195445,0.009956,0.462401,-169.872757,0.047307,0.000000
34.210003,0.082664,-169.917236,-0.007981,0.001853,0.047064,0.367710,0.018732,0.470644,-169.917236,0.048226,0.000000
34.760002,0.054733,-170.050674,-0.007942,0.001904,0.048365,0.243466,0.012403,0.483649,-170.050674,0.049137,0.000000
35.310001,0.019363,-170.006195,-0.007903,0.001932,0.049076,0.086133,0.004388,0.490757,-170.006195,0.050056,0.000000
35.860001,0.075218,-170.095154,-0.007886,0.001970,0.050048,0.334587,0.017045,0.500477,-170.095154,0.050975,0.000000
36.410000,0.082291,-170.139633,-0.007838,0.001996,0.050698,0.366047,0.018647,0.506979,-170.139633,0.051895,0.000000
36.960003,0.067398,-170.184113,-0.007787,0.002043,0.051895,0.299802,0.015273,0.518947,-170.184113,0.052805,0.000000
37.510002,0.020477,-170.273087,-0.007761,0.002078,0.052771,0.091088,0.004640,0.527705,-170.273087,0.053724,0.000000
38.060001,0.078941,-170.228607,-0.007718,0.002110,0.053603,0.351149,0.017888,0.536032,-170.228607,0.054643,0.000000
38.610001,0.030159,-170.362045,-0.007675,0.002157,0.054791,0.134154,0.006834,0.547909,-170.362045,0.055554,0.000000
39.160004,-0.016388,-170.406525,-0.007644,0.002185,0.055511,-0.072897,-0.003714,0.555108,-170.406525,0.056474,0.000000
39.710003,0.069633,-170.495483,-0.007601,0.002222,0.056439,0.309745,0.015779,0.564388,-170.495483,0.057393,0.000000
40.260002,0.050270,-170.539963,-0.007584,0.002256,0.057306,0.223612,0.011391,0.573063,-170.539963,0.058303,0.000000
40.810001,0.004837,-170.628922,-0.007515,0.002299,0.058399,0.021516,0.001096,0.583987,-170.628922,0.059222,0.000000
41.360001,0.028671,-170.628922,-0.007489,0.002329,0.059162,0.127536,0.006497,0.591617,-170.628922,0.060142,0.000000
41.910004,0.062180,-170.762375,-0.007450,0.002363,0.060012,0.276589,0.014090,0.600118,-170.762375,0.061061,0.000000
42.460003,0.082664,-170.762375,-0.007411,0.002409,0.061191,0.367710,0.018732,0.611912,-170.762375,0.061972,0.000000
43.010002,0.071121,-170.895813,-0.007390,0.002435,0.061850,0.316363,0.016116,0.618505,-170.895813,0.062891,0.000000
43.560001,0.085640,-170.895813,-0.007343,0.002479,0.062978,0.380946,0.019406,0.629776,-170.895813,0.063810,0.000000
44.110001,0.106125,-170.984772,-0.007291,0.002505,0.063637,0.472067,0.024048,0.636370,-170.984772,0.064721,0.000000
44.660004,0.074844,-171.073730,-0.007274,0.002545,0.064634,0.332924,0.016960,0.646339,-171.073730,0.065640,0.000000
45.210003,0.055855,-171.162704,-0.007226,0.002582,0.065571,0.248455,0.012657,0.655710,-171.162704,0.066560,0.000000
45.760002,0.074844,-171.251663,-0.007179,0.002615,0.066420,0.332924,0.016960,0.664204,-171.251663,0.067479,0.000000
46.310001,0.098305,-171.251663,-0.007140,0.002661,0.067582,0.437281,0.022276,0.675823,-171.251663,0.068389,0.000000
46.860001,0.062927,-171.385101,-0.007123,0.002691,0.068346,0.279914,0.014260,0.683461,-171.385101,0.069308,0.000000
47.410004,0.118408,-171.385101,-0.007080,0.002729,0.069317,0.526706,0.026832,0.693173,-171.385101,0.070228,0.000000
47.960003,0.112083,-171.429581,-0.007045,0.002760,0.070106,0.498572,0.025398,0.701061,-171.429581,0.071139,0.000000
48.510002,0.117294,-171.563034,-0.006993,0.002798,0.071077,0.521751,0.026579,0.710773,-171.563034,0.072058,0.000000
49.060001,0.052132,-171.607513,-0.006967,0.002832,0.071927,0.231893,0.011813,0.719274,-171.607513,0.072977,0.000000
49.610001,0.074097,-171.563034,-0.006929,0.002869,0.072873,0.329598,0.016791,0.728729,-171.563034,0.073896,0.000000
50.160004,0.102768,-171.696472,-0.006907,0.002909,0.073879,0.457135,0.023288,0.738789,-171.696472,0.074807,0.000000
50.710003,0.060318,-171.740952,-0.006834,0.002941,0.074712,0.268308,0.013668,0.747116,-171.740952,0.075726,0.000000
51.260002,0.075958,-171.785431,-0.006804,0.002981,0.075726,0.337879,0.017212,0.757259,-171.785431,0.076645,0.000000
51.810001,0.095322,-171.829910,-0.006791,0.003011,0.076472,0.424012,0.021600,0.764715,-171.829910,0.077556,0.000000
52.360001,0.081177,-171.918869,-0.006726,0.003049,0.077434,0.361092,0.018395,0.774344,-171.918869,0.078475,0.000000
52.910004,0.023827,-172.007843,-0.006713,0.003085,0.078362,0.105986,0.005399,0.783625,-172.007843,0.079394,0.000000
53.460003,0.058830,-172.007843,-0.006661,0.003123,0.079316,0.261690,0.013331,0.793163,-172.007843,0.080305,0.000000
54.010002,0.063301,-172.096802,-0.006631,0.003167,0.080435,0.281577,0.014344,0.804351,-172.096802,0.081224,0.000000
54.560001,0.039841,-172.141281,-0.006592,0.003193,0.081111,0.177220,0.009028,0.811111,-172.141281,0.082144,0.000000
55.110004,0.080803,-172.230240,-0.006554,0.003238,0.082247,0.359429,0.018310,0.822473,-172.230240,0.083063,0.000000
55.660004,0.082664,-172.319199,-0.006523,0.003265,0.082932,0.367710,0.018732,0.829323,-172.319199,0.083973,0.000000
56.210003,0.059204,-172.274719,-0.006472,0.003310,0.084078,0.263353,0.013416,0.840777,-172.274719,0.084892,0.000000
56.760002,0.037231,-172.452652,-0.006437,0.003343,0.084910,0.165614,0.008437,0.849096,-172.452652,0.085812,0.000000
57.310001,0.058090,-172.497131,-0.006403,0.003374,0.085707,0.258398,0.013163,0.857074,-172.497131,0.086723,0.000000
57.860004,0.047287,-172.586090,-0.006372,0.003420,0.086869,0.210343,0.010715,0.868694,-172.586090,0.087642,0.000000
58.410004,-0.001495,-172.541611,-0.006316,0.003449,0.087607,-0.006652,-0.000339,0.876067,-172.541611,0.088560,0.000000
58.960003,0.070374,-172.630569,-0.006303,0.003487,0.088578,0.313037,0.015947,0.885779,-172.630569,0.089480,0.000000
59.510002,0.087135,-172.764008,-0.006256,0.003517,0.089333,0.387597,0.019745,0.893326,-172.764008,0.090391,0.000000
60.060001,0.046547,-172.764008,-0.006204,0.003563,0.090504,0.207051,0.010548,0.905037,-172.764008,0.091310,0.000000
60.610004,-0.000748,-172.852982,-0.006183,0.003591,0.091214,-0.003326,-0.000169,0.912145,-172.852982,0.092230,0.000000
61.160004,0.053246,-172.897461,-0.006144,0.003629,0.092168,0.236848,0.012066,0.921682,-172.897461,0.093139,0.000000
61.710003,0.060318,-173.030899,-0.006105,0.003672,0.093279,0.268308,0.013668,0.932787,-173.030899,0.094059,0.000000
62.260002,0.036865,-173.030899,-0.006071,0.003703,0.094059,0.163985,0.008354,0.940592,-173.030899,0.094978,0.000000
62.810001,0.031647,-173.075378,-0.006049,0.003740,0.094987,0.140772,0.007171,0.949872,-173.075378,0.095898,0.000000
63.360004,0.130699,-173.164337,-0.005997,0.003774,0.095863,0.581379,0.029617,0.958631,-173.164337,0.096809,0.000000
63.910004,0.094582,-173.164337,-0.005967,0.003813,0.096843,0.420720,0.021432,0.968426,-173.164337,0.097727,0.000000
64.460007,0.066277,-173.342270,-0.005933,0.003844,0.097632,0.294813,0.015018,0.976321,-173.342270,0.098646,0.000000
65.010002,0.082291,-173.386749,-0.005885,0.003886,0.098707,0.366047,0.018647,0.987070,-173.386749,0.099557,0.000000
65.560005,0.093460,-173.342270,-0.005864,0.003914,0.099410,0.415731,0.021178,0.994095,-173.342270,0.100477,0.000000
66.110001,0.051384,-173.475708,-0.005825,0.003953,0.100398,0.228567,0.011644,1.003981,-173.475708,0.101396,0.000000
66.660004,0.077080,-173.520187,-0.005790,0.003993,0.101413,0.342868,0.017467,1.014132,-173.520187,0.102306,0.000000
67.210007,0.115433,-173.564667,-0.005756,0.004021,0.102124,0.513470,0.026157,1.021240,-173.564667,0.103225,0.000000
67.760002,0.095695,-173.653625,-0.005700,0.004061,0.103157,0.425675,0.021685,1.031566,-173.653625,0.104145,0.000000
68.310005,0.079315,-173.742599,-0.005687,0.004099,0.104110,0.352812,0.017973,1.041103,-173.742599,0.105064,0.000000
68.860001,0.103516,-173.787079,-0.005648,0.004138,0.105107,0.460460,0.023457,1.051073,-173.787079,0.105975,0.000000
69.410004,0.124001,-173.831558,-0.005601,0.004164,0.105758,0.551582,0.028099,1.057583,-173.831558,0.106894,0.000000
69.960007,0.074097,-173.920517,-0.005570,0.004205,0.106798,0.329598,0.016791,1.067984,-173.920517,0.107813,0.000000
70.510002,0.077820,-173.964996,-0.005536,0.004243,0.107779,0.346160,0.017634,1.077787,-173.964996,0.108724,0.000000
71.060005,0.102028,-174.009476,-0.005493,0.004271,0.108481,0.453843,0.023120,1.084811,-174.009476,0.109643,0.000000
71.610001,0.119156,-174.098450,-0.005458,0.004316,0.109635,0.530032,0.027001,1.096348,-174.098450,0.110562,0.000000
72.160004,0.096069,-174.142929,-0.005433,0.004344,0.110346,0.427338,0.021770,1.103456,-174.142929,0.111482,0.000000
72.710007,0.098679,-174.142929,-0.005372,0.004388,0.111464,0.438944,0.022361,1.114644,-174.142929,0.112392,0.000000
73.260002,0.113571,-174.231888,-0.005359,0.004413,0.112097,0.505190,0.025736,1.120972,-174.231888,0.113311,0.000000
73.810005,0.064415,-174.320847,-0.005307,0.004457,0.113208,0.286532,0.014597,1.132077,-174.320847,0.114230,0.000000
74.360001,0.062927,-174.409805,-0.005282,0.004493,0.114118,0.279914,0.014260,1.141184,-174.409805,0.115141,0.000000
74.910004,0.070000,-174.409805,-0.005238,0.004523,0.114881,0.311374,0.015862,1.148814,-174.409805,0.116061,0.000000
75.460007,0.069633,-174.454285,-0.005200,0.004574,0.116182,0.309745,0.015779,1.161819,-174.454285,0.116980,0.000000
76.010002,0.065910,-174.543259,-0.005152,0.004602,0.116893,0.293184,0.014935,1.168935,-174.543259,0.117899,0.000000
76.560005,0.087502,-174.632217,-0.005144,0.004644,0.117951,0.389226,0.019828,1.179510,-174.632217,0.118809,0.000000
77.110001,0.114319,-174.587738,-0.005113,0.004668,0.118558,0.508516,0.025905,1.185580,-174.587738,0.119729,0.000000
77.660004,0.047661,-174.721176,-0.005032,0.004714,0.119729,0.212006,0.010800,1.197291,-174.721176,0.120648,0.000000
78.210007,0.050270,-174.810135,-0.005027,0.004750,0.120640,0.223612,0.011391,1.206397,-174.810135,0.121559,0.000000
78.760002,0.074844,-174.854614,-0.004988,0.004777,0.121325,0.332924,0.016960,1.213248,-174.854614,0.122478,0.000000
79.310005,0.051758,-174.943573,-0.004941,0.004827,0.122600,0.230230,0.011728,1.225996,-174.943573,0.123397,0.000000
79.860001,0.017128,-174.988068,-0.004919,0.004854,0.123302,0.076189,0.003881,1.233020,-174.988068,0.124308,0.000000
80.410004,0.078568,-175.121506,-0.004859,0.004893,0.124291,0.349486,0.017804,1.242907,-175.121506,0.125227,0.000000
80.960007,0.096817,-175.077026,-0.004842,0.004921,0.124984,0.430664,0.021939,1.249840,-175.077026,0.126147,0.000000
81.510002,0.039467,-175.165985,-0.004794,0.004966,0.126147,0.175557,0.008943,1.261468,-175.165985,0.127066,0.000000
82.060005,0.034256,-175.210464,-0.004764,0.005003,0.127066,0.152378,0.007763,1.270657,-175.210464,0.127976,0.000000
82.610001,0.081543,-175.299423,-0.004730,0.005034,0.127855,0.362721,0.018478,1.278545,-175.299423,0.128895,0.000000
83.160004,0.076706,-175.299423,-0.004674,0.005080,0.129043,0.341205,0.017382,1.290430,-175.299423,0.129815,0.000000
83.710007,0.080055,-175.388397,-0.004644,0.005108,0.129754,0.356103,0.018141,1.297538,-175.388397,0.130726,0.000000
84.260002,0.286354,-175.432877,-0.004609,0.005149,0.130786,1.273767,0.064889,1.307863,-175.432877,0.131645,0.000000
84.810005,0.507912,-175.521835,-0.004579,0.005179,0.131540,2.259304,0.115094,1.315402,-175.521835,0.132564,0.000000
85.360001,0.919388,-175.566315,-0.004549,0.005218,0.132546,4.089641,0.208336,1.325463,-175.566315,0.133483,0.000000
85.910004,1.432144,-175.699753,-0.004518,0.005254,0.133457,6.370495,0.324529,1.334569,-175.699753,0.134394,0.000000
86.460007,2.023842,-175.699753,-0.004475,0.005287,0.134299,9.002499,0.458609,1.342987,-175.699753,0.135313,0.000000
87.010002,2.806938,-175.744232,-0.004462,0.005327,0.135296,12.485885,0.636061,1.352956,-175.744232,0.136232,0.000000
87.560005,3.280602,-175.833206,-0.004419,0.005356,0.136041,14.592844,0.743395,1.360412,-175.833206,0.137143,0.000000
88.110001,4.129982,-175.877686,-0.004381,0.005397,0.137091,18.371077,0.935867,1.370912,-175.877686,0.138062,0.000000
88.660004,4.731735,-175.922165,-0.004372,0.005428,0.137863,21.047810,1.072227,1.378625,-175.922165,0.138981,0.000000
89.210007,5.551697,-176.011124,-0.004324,0.005473,0.139007,24.695181,1.258032,1.390071,-176.011124,0.139900,0.000000
89.760002,6.127388,-176.055603,-0.004303,0.005507,0.139883,27.255983,1.388486,1.398829,-176.055603,0.140811,0.000000
90.310005,6.700836,-176.100082,-0.004251,0.005540,0.140707,29.806808,1.518431,1.407073,-176.100082,0.141731,0.000000
90.860001,7.598259,-176.189041,-0.004234,0.005582,0.141791,33.798744,1.721790,1.417912,-176.189041,0.142650,0.000000
91.410004,7.821678,-176.233521,-0.004208,0.005614,0.142597,34.792561,1.772418,1.425974,-176.233521,0.143560,0.000000
91.960007,8.405563,-176.322495,-0.004174,0.005652,0.143560,37.389812,1.904728,1.435603,-176.322495,0.144479,0.000000
92.510002,8.777931,-176.366974,-0.004143,0.005681,0.144306,39.046188,1.989108,1.443059,-176.366974,0.145399,0.000000
93.060005,9.518211,-176.411453,-0.004100,0.005726,0.145434,42.339119,2.156857,1.454338,-176.411453,0.146310,0.000000
93.610008,9.752434,-176.411453,-0.004070,0.005757,0.146240,43.380993,2.209933,1.462400,-176.411453,0.147229,0.000000
94.160004,10.260345,-176.455933,-0.004044,0.005794,0.147168,45.640297,2.325028,1.471681,-176.455933,0.148148,0.000000
94.710007,10.452866,-176.633850,-0.004023,0.005825,0.147966,46.496670,2.368653,1.479659,-176.633850,0.149067,0.000000
95.260002,11.234100,-176.678345,-0.003967,0.005867,0.149024,49.971775,2.545684,1.490242,-176.678345,0.149978,0.000000
95.810005,11.568863,-176.722824,-0.003932,0.005902,0.149900,51.460873,2.621542,1.499000,-176.722824,0.150897,0.000000
96.360008,11.928947,-176.678345,-0.003902,0.005934,0.150724,53.062607,2.703138,1.507236,-176.678345,0.151816,0.000000
96.910004,12.631989,-176.811783,-0.003859,0.005975,0.151755,56.189892,2.862450,1.517554,-176.811783,0.152727,0.000000
97.460007,12.868446,-176.811783,-0.003842,0.006008,0.152614,57.241707,2.916032,1.526138,-176.811783,0.153646,0.000000
98.010002,13.462006,-176.945221,-0.003803,0.006046,0.153568,59.881992,3.050534,1.535683,-176.945221,0.154565,0.000000
98.560005,13.658615,-176.989700,-0.003773,0.006075,0.154297,60.756554,3.095087,1.542965,-176.989700,0.155484,0.000000
99.110008,14.413788,-177.034180,-0.003729,0.006121,0.155477,64.115730,3.266211,1.554767,-177.034180,0.156396,0.000000
99.660004,14.812973,-177.078659,-0.003695,0.006158,0.156403,65.891396,3.356668,1.564032,-177.078659,0.157315,0.000000
100.210007,14.615242,-177.167633,-0.003673,0.006182,0.157010,65.011841,3.311861,1.570103,-177.167633,0.158234,0.000000
100.760002,15.913704,-177.212112,-0.003617,0.006233,0.158312,70.787689,3.606097,1.583123,-177.212112,0.159145,0.000000
101.310005,15.763268,-177.256592,-0.003591,0.006260,0.159015,70.118515,3.572007,1.590148,-177.256592,0.160064,0.000000
101.860008,16.442474,-177.390030,-0.003566,0.006299,0.159994,73.139778,3.725918,1.599943,-177.390030,0.160983,0.000000
102.410004,17.144394,-177.390030,-0.003535,0.006342,0.161087,76.262070,3.884975,1.610874,-177.390030,0.161902,0.000000
102.960007,17.105301,-177.390030,-0.003501,0.006373,0.161885,76.088181,3.876117,1.618853,-177.390030,0.162813,0.000000
103.510002,17.407295,-177.478989,-0.003462,0.006409,0.162786,77.431519,3.944550,1.627861,-177.478989,0.163732,0.000000
104.060005,17.850418,-177.523483,-0.003410,0.006444,0.163679,79.402626,4.044962,1.636793,-177.523483,0.164651,0.000000
104.610008,18.459618,-177.656921,-0.003376,0.006486,0.164738,82.112480,4.183009,1.647376,-177.656921,0.165561,0.000000
105.160004,18.289818,-177.612442,-0.003350,0.006516,0.165519,81.357170,4.144532,1.655188,-177.612442,0.166482,0.000000
105.710007,18.921730,-177.745880,-0.003328,0.006554,0.166463,84.168060,4.287725,1.664635,-177.745880,0.167401,0.000000
106.260002,19.458321,-177.745880,-0.003294,0.006592,0.167426,86.554932,4.409319,1.674263,-177.745880,0.168310,0.000000
106.810005,19.327614,-177.879318,-0.003251,0.006622,0.168198,85.973518,4.379700,1.681985,-177.879318,0.169229,0.000000
107.360008,19.950966,-177.834839,-0.003212,0.006662,0.169222,88.746330,4.520953,1.692219,-177.834839,0.170150,0.000000
107.910004,20.158752,-177.923798,-0.003182,0.006695,0.170045,89.670609,4.568038,1.700455,-177.923798,0.171069,0.000000
108.460007,20.636505,-177.968292,-0.003152,0.006732,0.170983,91.795761,4.676299,1.709826,-177.968292,0.171979,0.000000
109.010002,20.887856,-178.012772,-0.003122,0.006765,0.171841,92.913818,4.733255,1.718410,-178.012772,0.172899,0.000000
109.560005,21.254272,-178.101730,-0.003091,0.006805,0.172846,94.543724,4.816287,1.728463,-178.101730,0.173818,0.000000
110.110008,21.378647,-178.190689,-0.003057,0.006835,0.173618,95.096970,4.844471,1.736184,-178.190689,0.174728,0.000000
110.660004,22.098442,-178.235168,-0.003018,0.006877,0.174686,98.298782,5.007578,1.746858,-178.235168,0.175647,0.000000
111.210007,22.248131,-178.279648,-0.002979,0.006914,0.175605,98.964630,5.041499,1.756047,-178.279648,0.176568,0.000000
111.760002,22.247391,-178.324127,-0.002945,0.006940,0.176272,98.961334,5.041331,1.762724,-178.324127,0.177487,0.000000
112.310005,23.427811,-178.368607,-0.002915,0.006988,0.177487,104.212105,5.308818,1.774866,-178.368607,0.178396,0.000000
112.860008,23.459831,-178.457581,-0.002889,0.007020,0.178301,104.354538,5.316074,1.783011,-178.457581,0.179315,0.000000
113.410004,24.058983,-178.591019,-0.002859,0.007059,0.179290,107.019699,5.451844,1.792897,-178.591019,0.180236,0.000000
113.960007,23.827370,-178.591019,-0.002824,0.007082,0.179880,105.989433,5.399359,1.798802,-178.591019,0.181146,0.000000
114.510002,25.039810,-178.679977,-0.002781,0.007127,0.181016,111.382637,5.674102,1.810156,-178.679977,0.182065,0.000000
115.060005,25.456497,-178.724457,-0.002781,0.007163,0.181953,113.236153,5.768525,1.819528,-178.724457,0.182984,0.000000
115.610008,25.717155,-178.768936,-0.002725,0.007195,0.182758,114.395622,5.827590,1.827582,-178.768936,0.183904,0.000000
116.160004,26.782883,-178.813431,-0.002690,0.007239,0.183860,119.136215,6.069088,1.838604,-178.813431,0.184814,0.000000
116.710007,26.944870,-178.902390,-0.002665,0.007271,0.184675,119.856766,6.105795,1.846749,-178.902390,0.185733,0.000000
117.260002,27.742859,-178.991348,-0.002647,0.007309,0.185656,123.406403,6.286622,1.856559,-178.991348,0.186652,0.000000
117.810005,27.691475,-179.035828,-0.002621,0.007337,0.186358,123.177834,6.274978,1.863584,-179.035828,0.187563,0.000000
118.360008,28.931107,-179.080307,-0.002578,0.007381,0.187485,128.691986,6.555882,1.874848,-179.080307,0.188482,0.000000
118.910004,29.318741,-179.124786,-0.002565,0.007416,0.188370,130.416275,6.643722,1.883704,-179.124786,0.189401,0.000000
119.460007,29.527267,-179.258240,-0.002522,0.007446,0.189133,131.343842,6.690974,1.891335,-179.258240,0.190313,0.000000
120.010002,31.293060,-179.213745,-0.002488,0.007497,0.190416,139.198486,7.091109,1.904158,-179.213745,0.191232,0.000000
120.560005,31.281517,-179.302719,-0.002470,0.007525,0.191127,139.147141,7.088493,1.911274,-179.302719,0.192151,0.000000
121.110008,32.167389,-179.391678,-0.002432,0.007564,0.192125,143.087692,7.289235,1.921251,-179.391678,0.193070,0.000000
121.660004,32.036690,-179.436157,-0.002402,0.007588,0.192732,142.506317,7.259617,1.927322,-179.436157,0.193981,0.000000
122.210007,33.765984,-179.480637,-0.002358,0.007636,0.193946,150.198593,7.651481,1.939463,-179.480637,0.194900,0.000000
122.760002,34.366623,-179.525116,-0.002333,0.007670,0.194830,152.870377,7.787588,1.948305,-179.525116,0.195819,0.000000
123.310005,34.523018,-179.614075,-0.002307,0.007699,0.195551,153.566055,7.823028,1.955511,-179.614075,0.196731,0.000000
123.860008,36.628784,-179.614075,-0.002255,0.007748,0.196808,162.932968,8.300201,1.968077,-179.614075,0.197649,0.000000
124.410004,36.453773,-179.703049,-0.002229,0.007776,0.197510,162.154480,8.260543,1.975102,-179.703049,0.198568,0.000000
124.960007,37.659889,-179.792007,-0.002203,0.007814,0.198473,167.519547,8.533853,1.984731,-179.792007,0.199487,0.000000
125.510010,38.387131,-179.836487,-0.002156,0.007848,0.199341,170.754486,8.698648,1.993406,-179.836487,0.200399,0.000000
126.060005,39.891518,-179.925446,-0.002130,0.007892,0.200467,177.446335,9.039547,2.004670,-179.925446,0.201318,0.000000
126.610008,40.159622,-179.925446,-0.002100,0.007920,0.201179,178.638916,9.100301,2.011785,-179.925446,0.202237,0.000000
127.160004,41.009003,-179.969925,-0.002044,0.007955,0.202046,182.417160,9.292773,2.020460,-179.969925,0.203147,0.000000
127.710007,42.661964,-180.014404,-0.002035,0.007998,0.203156,189.769897,9.667339,2.031558,-180.014404,0.204067,0.000000
128.260010,43.222015,-180.147858,-0.001992,0.008028,0.203919,192.261124,9.794249,2.039188,-180.147858,0.204986,0.000000
128.810013,44.340996,-180.236816,-0.001957,0.008066,0.204865,197.238602,10.047813,2.048650,-180.236816,0.205905,0.000000
129.360001,45.256287,-180.325775,-0.001919,0.008099,0.205705,201.310013,10.255220,2.057053,-180.325775,0.206816,0.000000
129.910004,46.414360,-180.325775,-0.001893,0.008138,0.206712,206.461380,10.517644,2.067120,-180.325775,0.207735,0.000000
130.460007,47.625320,-180.325775,-0.001858,0.008173,0.207587,211.848007,10.792052,2.075871,-180.325775,0.208654,0.000000
131.010010,48.921921,-180.459213,-0.001828,0.008209,0.208515,217.615570,11.085866,2.085152,-180.459213,0.209564,0.000000
131.560013,50.716751,-180.503693,-0.001802,0.008250,0.209557,225.599380,11.492580,2.095568,-180.503693,0.210485,0.000000
132.110001,51.404526,-180.503693,-0.001768,0.008281,0.210336,228.658752,11.648432,2.103364,-180.503693,0.211404,0.000000
132.660004,52.929390,-180.592667,-0.001746,0.008321,0.211360,235.441681,11.993971,2.113599,-180.592667,0.212314,0.000000
133.210007,54.122849,-180.637146,-0.001725,0.008352,0.212149,240.750458,12.264412,2.121487,-180.637146,0.213233,0.000000
133.760010,55.598930,-180.637146,-0.001690,0.008388,0.213060,247.316391,12.598897,2.130601,-180.637146,0.214153,0.000000
134.310013,56.952499,-180.815063,-0.001673,0.008425,0.213988,253.337372,12.905621,2.139881,-180.815063,0.215072,0.000000
134.860001,58.673607,-180.770584,-0.001638,0.008463,0.214968,260.993225,13.295630,2.149677,-180.770584,0.215982,0.000000
135.410004,59.047096,-180.859543,-0.001613,0.008493,0.215731,262.654602,13.380262,2.157307,-180.859543,0.216901,0.000000
135.960007,61.628754,-180.948502,-0.001582,0.008534,0.216754,274.138397,13.965275,2.167541,-180.948502,0.217821,0.000000
136.510010,63.192352,-181.037476,-0.001574,0.008572,0.217726,281.093628,14.319592,2.177261,-181.037476,0.218731,0.000000
137.060013,64.709763,-181.081955,-0.001539,0.008604,0.218541,287.843414,14.663442,2.185406,-181.081955,0.219650,0.000000
137.610001,65.509995,-181.126434,-0.001531,0.008623,0.219027,291.403015,14.844777,2.190266,-181.126434,0.038397,0.000000
138.160004,65.116028,-181.170914,-0.001513,0.008638,0.219399,289.650543,14.755503,2.193990,-181.170914,294.500458,0.000000
138.710007,65.413544,-181.215393,-0.001505,0.008662,0.220024,290.973969,14.822921,2.200243,-181.215393,294.500458,0.000000
139.260010,64.992020,-181.304352,-0.001475,0.008674,0.220327,289.098938,14.727402,2.203271,-181.304352,294.500458,0.000000
139.810013,65.520050,-181.304352,-0.001475,0.008692,0.220778,291.447723,14.847055,2.207782,-181.304352,294.500458,0.000000
140.360001,65.206512,-181.393326,-0.001470,0.008703,0.221046,290.053040,14.776007,2.210462,-181.393326,294.500458,0.000000
140.910004,65.256775,-181.437805,-0.001453,0.008714,0.221325,290.276642,14.787396,2.213248,-181.437805,294.500458,0.000000
141.460007,64.763016,-181.437805,-0.001453,0.008719,0.221463,288.080292,14.675508,2.214625,-181.437805,294.500458,0.000000
142.010010,65.054214,-181.526764,-0.001427,0.008730,0.221741,289.375610,14.741495,2.217411,-181.526764,294.500458,0.000000
142.560013,64.776794,-181.615723,-0.001427,0.008737,0.221932,288.141571,14.678632,2.219319,-181.615723,294.500458,0.000000
143.110001,65.533081,-181.615723,-0.001427,0.008747,0.222183,291.505707,14.850009,2.221832,-181.615723,294.500458,0.000000
143.660004,65.334976,-181.749161,-0.001401,0.008758,0.222451,290.624481,14.805117,2.224511,-181.749161,294.500458,0.000000
144.210007,65.204269,-181.749161,-0.001406,0.008764,0.222609,290.043091,14.775498,2.226086,-181.749161,294.500458,0.000000
144.760010,65.219543,-181.838135,-0.001397,0.008772,0.222807,290.111023,14.778960,2.228069,-181.838135,294.500458,0.000000
145.310013,65.084000,-181.927094,-0.001388,0.008777,0.222937,289.508087,14.748245,2.229371,-181.927094,294.500458,0.000000
145.860001,65.566971,-181.971573,-0.001393,0.008787,0.223198,291.656464,14.857688,2.231975,-181.971573,294.500458,0.000000
146.410004,65.070602,-182.016052,-0.001393,0.008788,0.223207,289.448486,14.745210,2.232066,-182.016052,294.500458,0.000000
146.960007,65.595261,-182.016052,-0.001371,0.008799,0.223484,291.782288,14.864099,2.234837,-182.016052,294.500458,0.000000
147.510010,65.223267,-182.149490,-0.001358,0.008799,0.223493,290.127594,14.779803,2.234927,-182.149490,294.500458,0.000000
148.060013,64.913086,-182.238449,-0.001371,0.008803,0.223597,288.747833,14.709516,2.235972,-182.238449,294.500458,0.000000
148.610001,65.585587,-182.282944,-0.001358,0.008813,0.223856,291.739258,14.861906,2.238561,-182.282944,294.500458,0.000000
149.160004,65.281723,-182.327423,-0.001358,0.008813,0.223856,290.387604,14.793050,2.238561,-182.327423,294.500458,0.000000
149.710007,65.154007,-182.416382,-0.001345,0.008817,0.223944,289.819489,14.764109,2.239439,-182.416382,294.500458,0.000000
150.260010,65.064636,-182.416382,-0.001354,0.008821,0.224047,289.421967,14.743857,2.240469,-182.416382,294.500458,0.000000
150.810013,65.365891,-182.505341,-0.001341,0.008827,0.224195,290.761993,14.812122,2.241952,-182.505341,294.500458,0.000000
151.360001,65.233322,-182.505341,-0.001345,0.008829,0.224256,290.172302,14.782083,2.242558,-182.505341,294.500458,0.000000
151.910004,65.132416,-182.549820,-0.001332,0.008831,0.224316,289.723450,14.759216,2.243163,-182.549820,294.500458,0.000000
152.460007,65.055328,-182.638779,-0.001337,0.008835,0.224403,289.380554,14.741748,2.244026,-182.638779,294.500458,0.000000
153.010010,65.146927,-182.727753,-0.001328,0.008837,0.224472,289.787994,14.762505,2.244723,-182.727753,294.500458,0.000000
153.560013,65.083633,-182.727753,-0.001328,0.008841,0.224559,289.506470,14.748162,2.245586,-182.727753,294.500458,0.000000
154.110001,65.080276,-182.816711,-0.001332,0.008843,0.224612,289.491516,14.747402,2.246116,-182.816711,294.500458,0.000000
154.660004,65.105225,-182.905670,-0.001328,0.008847,0.224707,289.602509,14.753055,2.247069,-182.905670,294.500458,0.000000
155.210007,64.995743,-182.905670,-0.001324,0.008847,0.224707,289.115509,14.728246,2.247069,-182.905670,294.500458,0.000000
155.760010,65.637344,-182.994629,-0.001328,0.008856,0.224949,291.969482,14.873634,2.249492,-182.994629,294.500458,0.000000
156.310013,65.490631,-183.039108,-0.001324,0.008856,0.224949,291.316864,14.840389,2.249492,-183.039108,294.500458,0.000000
156.860001,65.292526,-183.083588,-0.001315,0.008857,0.224958,290.435669,14.795499,2.249583,-183.083588,294.500458,0.000000
157.410004,65.140228,-183.172562,-0.001319,0.008858,0.225002,289.758209,14.760986,2.250022,-183.172562,294.500458,0.000000
157.960007,65.027405,-183.217041,-0.001319,0.008859,0.225019,289.256348,14.735421,2.250188,-183.217041,294.500458,0.000000
158.510010,64.981964,-183.306000,-0.001311,0.008861,0.225070,289.054199,14.725123,2.250703,-183.306000,294.500458,0.000000
159.060013,65.285461,-183.350479,-0.001315,0.008867,0.225219,290.404236,14.793897,2.252187,-183.350479,294.500458,0.000000
159.610001,65.180069,-183.394958,-0.001311,0.008867,0.225219,289.935425,14.770015,2.252187,-183.394958,294.500458,0.000000
160.160004,65.014374,-183.439438,-0.001315,0.008867,0.225219,289.198364,14.732468,2.252187,-183.439438,294.500458,0.000000
160.710007,64.882172,-183.572891,-0.001302,0.008868,0.225244,288.610321,14.702510,2.252444,-183.572891,294.500458,0.000000
161.260010,64.929840,-183.572891,-0.001311,0.008870,0.225305,288.822357,14.713312,2.253050,-183.572891,294.500458,0.000000
161.810013,64.786850,-183.572891,-0.001311,0.008871,0.225314,288.186310,14.680909,2.253140,-183.572891,294.500458,0.000000
162.360001,65.025162,-183.661850,-0.001302,0.008875,0.225435,289.246368,14.734913,2.254352,-183.661850,294.500458,0.000000
162.910004,64.926483,-183.750809,-0.001289,0.008875,0.225435,288.807434,14.712552,2.254352,-183.750809,294.500458,0.000000
163.460007,64.783493,-183.839767,-0.001306,0.008875,0.225435,288.171356,14.680149,2.254352,-183.839767,294.500458,0.000000
164.010010,66.267776,-183.839767,-0.001293,0.008878,0.225496,294.773804,15.016493,2.254957,-183.839767,294.500458,0.000000
164.560013,66.061111,-183.884247,-0.001289,0.008878,0.225496,293.854492,14.969662,2.254957,-183.884247,294.500458,0.000000
165.110001,65.881989,-183.973221,-0.001293,0.008878,0.225496,293.057709,14.929071,2.254957,-183.973221,294.500458,0.000000
165.660004,65.687241,-184.017700,-0.001293,0.008878,0.225496,292.191437,14.884942,2.254957,-184.017700,294.500458,0.000000
166.210007,65.535309,-184.106659,-0.001289,0.008878,0.225505,291.515625,14.850513,2.255048,-184.106659,294.500458,0.000000
166.760010,65.362534,-184.106659,-0.001298,0.008878,0.225505,290.747070,14.811362,2.255048,-184.106659,294.500458,0.000000
167.310013,65.210983,-184.195618,-0.001298,0.008878,0.225514,290.072937,14.777020,2.255139,-184.195618,294.500458,0.000000
167.860001,65.041916,-184.240097,-0.001285,0.008878,0.225514,289.320892,14.738708,2.255139,-184.240097,294.500458,0.000000
168.410004,64.897812,-184.329056,-0.001285,0.008878,0.225514,288.679871,14.706054,2.255139,-184.329056,294.500458,0.000000
168.960007,64.755569,-184.418030,-0.001285,0.008878,0.225514,288.047150,14.673822,2.255139,-184.418030,294.500458,0.000000
169.510010,66.726532,-184.462509,-0.001285,0.008847,0.224707,296.814453,15.120448,2.247069,-184.462509,294.500458,0.000000
170.060013,66.597321,-184.506989,-0.001285,0.008846,0.224689,296.239685,15.091168,2.246888,-184.506989,294.500458,0.000000
170.610001,66.384323,-184.551468,-0.001281,0.008846,0.224689,295.292206,15.042902,2.246888,-184.551468,294.500458,0.000000
171.160004,66.243561,-184.595947,-0.001298,0.008846,0.224689,294.666077,15.011005,2.246888,-184.595947,294.500458,0.000000
171.710007,66.093872,-184.684906,-0.001281,0.008846,0.224689,294.000214,14.977086,2.246888,-184.684906,294.500458,0.000000
172.260010,65.973221,-184.729385,-0.001276,0.008846,0.224698,293.463531,14.949745,2.246979,-184.729385,294.500458,0.000000
172.810013,65.836945,-184.773865,-0.001263,0.008847,0.224707,292.857361,14.918864,2.247069,-184.773865,294.500458,0.000000
173.360001,65.679047,-184.773865,-0.001276,0.008847,0.224716,292.154999,14.883085,2.247160,-184.773865,294.500458,0.000000
173.910004,65.555801,-184.862839,-0.001272,0.008847,0.224724,291.606781,14.855157,2.247236,-184.862839,294.500458,0.000000
174.460007,65.472763,-184.996277,-0.001268,0.008847,0.224724,291.237396,14.836340,2.247236,-184.996277,294.500458,0.000000
175.010010,65.382645,-184.951797,-0.001281,0.008867,0.225210,290.836517,14.815919,2.252096,-184.951797,294.500458,0.000000
175.560013,65.296997,-185.085236,-0.001272,0.008867,0.225219,290.455536,14.796512,2.252187,-185.085236,294.500458,0.000000
176.110016,65.188263,-185.085236,-0.001281,0.008868,0.225235,289.971863,14.771872,2.252353,-185.085236,294.500458,0.000000
176.660004,65.095551,-185.085236,-0.001276,0.008874,0.225409,289.559479,14.750862,2.254094,-185.085236,294.500458,0.000000
177.210007,64.993515,-185.174194,-0.001276,0.008875,0.225435,289.105591,14.727740,2.254352,-185.174194,294.500458,0.000000
177.760010,65.835815,-185.263168,-0.001255,0.008906,0.226224,292.852325,14.918609,2.262239,-185.263168,294.500458,0.000000
178.310013,65.761353,-185.263168,-0.001272,0.008906,0.226224,292.521118,14.901735,2.262239,-185.263168,294.500458,0.000000
178.860016,65.670853,-185.352127,-0.001259,0.008906,0.226224,292.118530,14.881227,2.262239,-185.352127,294.500458,0.000000
179.410004,65.588196,-185.396606,-0.001272,0.008906,0.226224,291.750854,14.862498,2.262239,-185.396606,294.500458,0.000000
179.960007,65.528244,-185.485565,-0.001263,0.008906,0.226224,291.484192,14.848912,2.262239,-185.485565,294.500458,0.000000
180.510010,65.435150,-185.574524,-0.001272,0.008906,0.226224,291.070099,14.827816,2.262239,-185.574524,294.500458,0.000000
181.060013,65.343552,-185.574524,-0.001268,0.008906,0.226224,290.662628,14.807060,2.262239,-185.574524,294.500458,0.000000
181.610016,65.265350,-185.619003,-0.001263,0.008906,0.226224,290.314789,14.789339,2.262239,-185.619003,294.500458,0.000000
182.160004,65.184906,-185.707977,-0.001259,0.008907,0.226233,289.956940,14.771111,2.262330,-185.707977,294.500458,0.000000
182.710007,65.089966,-185.752457,-0.001255,0.008907,0.226233,289.534637,14.749597,2.262330,-185.752457,294.500458,0.000000
183.260010,65.011017,-185.841415,-0.001263,0.008907,0.226233,289.183441,14.731707,2.262330,-185.841415,294.500458,0.000000
183.810013,64.935425,-185.796936,-0.001259,0.008907,0.226233,288.847198,14.714578,2.262330,-185.796936,294.500458,0.000000
184.360016,65.937103,-185.974854,-0.001268,0.008919,0.226536,293.302887,14.941561,2.265358,-185.974854,294.500458,0.000000
184.910004,65.837311,-186.019333,-0.001263,0.008918,0.226528,292.858978,14.918947,2.265282,-186.019333,294.500458,0.000000
185.460007,65.785172,-185.974854,-0.001255,0.008918,0.226528,292.627045,14.907133,2.265282,-185.974854,294.500458,0.000000
186.010010,65.749054,-186.108292,-0.001268,0.008918,0.226528,292.466400,14.898949,2.265282,-186.108292,294.500458,0.000000
186.560013,65.598618,-186.152786,-0.001259,0.008918,0.226528,291.797211,14.864860,2.265282,-186.152786,294.500458,0.000000
187.110016,65.567337,-186.197266,-0.001250,0.008918,0.226528,291.658081,14.857771,2.265282,-186.197266,294.500458,0.000000
187.660004,65.506271,-186.241745,-0.001259,0.008918,0.226528,291.386444,14.843933,2.265282,-186.241745,294.500458,0.000000
188.210007,65.393814,-186.330704,-0.001272,0.008918,0.226528,290.886200,14.818450,2.265282,-186.330704,294.500458,0.000000
188.760010,65.322693,-186.330704,-0.001276,0.008918,0.226528,290.569855,14.802334,2.265282,-186.330704,294.500458,0.000000
189.310013,65.286575,-186.464142,-0.001255,0.008918,0.226528,290.409180,14.794149,2.265282,-186.464142,294.500458,0.000000
189.860016,65.219910,-186.464142,-0.001263,0.008918,0.226528,290.112640,14.779043,2.265282,-186.464142,294.500458,0.000000
190.410004,65.138000,-186.508621,-0.001268,0.008918,0.226528,289.748291,14.760482,2.265282,-186.508621,294.500458,0.000000
190.960007,65.062775,-186.686554,-0.001259,0.008918,0.226528,289.413666,14.743436,2.265282,-186.686554,294.500458,0.000000
191.510010,65.013245,-186.642075,-0.001250,0.008918,0.226528,289.193359,14.732212,2.265282,-186.642075,294.500458,0.000000
192.060013,64.948456,-186.731033,-0.001263,0.008918,0.226528,288.905151,14.717530,2.265282,-186.731033,294.500458,0.000000
192.610016,64.889618,-186.775513,-0.001250,0.008918,0.226528,288.643433,14.704198,2.265282,-186.775513,294.500458,0.000000
193.160004,65.887207,-186.864471,-0.001242,0.008931,0.226857,293.080933,14.930255,2.268568,-186.864471,294.500458,0.000000
193.710007,65.842529,-186.864471,-0.001250,0.008931,0.226857,292.882202,14.920131,2.268568,-186.864471,294.500458,0.000000
194.260010,65.865234,-186.997925,-0.001259,0.008931,0.226857,292.983185,14.925275,2.268568,-186.997925,294.500458,0.000000
194.810013,65.791885,-186.997925,-0.001263,0.008931,0.226857,292.656921,14.908654,2.268568,-186.997925,294.500458,0.000000
195.360016,65.767303,-187.042404,-0.001250,0.008931,0.226857,292.547577,14.903084,2.268568,-187.042404,294.500458,0.000000
195.910004,65.682770,-187.175842,-0.001255,0.008931,0.226857,292.171539,14.883928,2.268568,-187.175842,294.500458,0.000000
196.460007,65.611282,-187.131363,-0.001263,0.008931,0.226857,291.853546,14.867729,2.268568,-187.131363,294.500458,0.000000
197.010010,65.590057,-187.220322,-0.001259,0.008931,0.226857,291.759155,14.862919,2.268568,-187.220322,294.500458,0.000000
197.560013,65.552444,-187.264801,-0.001255,0.008931,0.226857,291.591827,14.854396,2.268568,-187.264801,294.500458,0.000000
198.110016,65.501801,-187.309280,-0.001246,0.008931,0.226857,291.366547,14.842920,2.268568,-187.309280,1681.640747,0.000000
198.660004,65.454132,-187.353760,-0.001250,0.008915,0.226433,291.154510,14.832118,2.264328,-187.353760,0.226086,0.000000
199.210007,65.279129,-187.398254,-0.001237,0.008884,0.225661,290.376068,14.792462,2.256607,-187.398254,0.225175,0.000000
199.760010,65.174484,-187.531693,-0.001242,0.008856,0.224940,289.910583,14.768749,2.249401,-187.531693,0.224256,0.000000
200.310013,65.087723,-187.531693,-0.001259,0.008813,0.223849,289.524658,14.749088,2.238485,-187.531693,0.223337,0.000000
200.860016,65.050858,-187.576172,-0.001250,0.008791,0.223302,289.360657,14.740735,2.233020,-187.576172,0.222425,0.000000
201.410004,64.968567,-187.665131,-0.001259,0.008749,0.222227,288.994629,14.722088,2.222271,-187.665131,0.221506,0.000000
201.960007,64.869141,-187.620651,-0.001250,0.008713,0.221299,288.552338,14.699557,2.212990,-187.620651,0.220587,0.000000
202.510010,64.391754,-187.754089,-0.001237,0.008675,0.220344,286.428833,14.591380,2.203437,-187.754089,0.219668,0.000000
203.060013,63.500671,-187.798569,-0.001263,0.008647,0.219643,282.465088,14.389458,2.196428,-187.798569,0.218757,0.000000
203.610016,61.654449,-187.798569,-0.001237,0.008613,0.218775,274.252686,13.971098,2.187752,-187.798569,0.217838,0.000000
204.160004,59.250412,-187.887543,-0.001237,0.008576,0.217838,263.558990,13.426334,2.178381,-187.887543,0.216919,0.000000
204.710007,56.509377,-187.887543,-0.001216,0.008544,0.217005,251.366257,12.805208,2.170054,-187.887543,0.216008,0.000000
205.260010,53.239952,-187.976501,-0.001220,0.008505,0.216026,236.823135,12.064346,2.160259,-187.976501,0.215089,0.000000
205.810013,50.020042,-187.976501,-0.001203,0.008475,0.215272,222.500259,11.334704,2.152719,-187.976501,0.214170,0.000000
206.360016,46.003265,-188.109940,-0.001216,0.008439,0.214361,204.632751,10.424489,2.143605,-188.109940,0.213251,0.000000
206.910004,42.068405,-188.154419,-0.001212,0.008404,0.213458,187.129608,9.532837,2.134582,-188.154419,0.212339,0.000000
207.460007,37.866180,-188.154419,-0.001216,0.008365,0.212470,168.437180,8.580599,2.124696,-188.154419,0.211420,0.000000
208.010010,34.520782,-188.243378,-0.001207,0.008334,0.211681,153.556107,7.822521,2.116808,-188.243378,0.210501,0.000000
208.560013,30.659653,-188.287872,-0.001212,0.008296,0.210727,136.380951,6.947577,2.107270,-188.287872,0.209592,0.000000
209.110016,26.982849,-188.332352,-0.001207,0.008262,0.209860,120.025711,6.114401,2.098596,-188.332352,0.208671,0.000000
209.660004,23.125816,-188.421310,-0.001207,0.008226,0.208950,102.868767,5.240385,2.089497,-188.421310,0.207752,0.000000
210.210007,19.402092,-188.510269,-0.001203,0.008192,0.208073,86.304817,4.396577,2.080731,-188.510269,0.206842,0.000000
210.760010,15.273972,-188.554749,-0.001216,0.008155,0.207136,67.942017,3.461131,2.071359,-188.554749,0.205922,0.000000
211.310013,10.974930,-188.599228,-0.001207,0.008115,0.206114,48.818928,2.486955,2.061140,-188.599228,0.205003,0.000000
211.860016,7.232956,-188.643707,-0.001216,0.008078,0.205186,32.173794,1.639011,2.051860,-188.643707,0.204084,0.000000
212.410004,3.762817,-188.688202,-0.001199,0.008045,0.204344,16.737848,0.852667,2.043442,-188.688202,0.203174,0.000000
212.960007,0.126602,-188.732681,-0.001207,0.008007,0.203372,0.563155,0.028688,2.033722,-188.732681,0.202253,0.000000
213.510010,-3.500675,-188.777161,-0.001212,0.007971,0.202453,-15.571781,-0.793264,2.024533,-188.777161,0.201334,0.000000
214.060013,0.093086,-188.866119,-0.001203,0.007932,0.201474,0.414068,0.021094,2.014737,-188.866119,0.200425,0.000000
214.610016,0.148575,-188.910599,-0.001194,0.007906,0.200823,0.660894,0.033668,2.008227,-188.910599,0.199506,0.000000
215.160004,0.084900,-188.999557,-0.001199,0.007860,0.199636,0.377654,0.019239,1.996358,-188.999557,0.198585,0.000000
215.710007,0.088249,-188.999557,-0.001199,0.007821,0.198655,0.392552,0.019998,1.986548,-188.999557,0.197666,0.000000
216.260010,0.092346,-189.133011,-0.001181,0.007790,0.197866,0.410776,0.020926,1.978660,-189.133011,0.196756,0.000000
216.810013,-0.009315,-189.088516,-0.001199,0.007750,0.196843,-0.041437,-0.002111,1.968426,-189.088516,0.195837,0.000000
217.360016,0.053246,-189.177490,-0.001190,0.007720,0.196089,0.236848,0.012066,1.960886,-189.177490,0.194917,0.000000
217.910004,0.033882,-189.266449,-0.001199,0.007685,0.195195,0.150715,0.007678,1.951954,-189.266449,0.194007,0.000000
218.460007,0.016380,-189.266449,-0.001207,0.007647,0.194242,0.072863,0.003712,1.942416,-189.266449,0.193088,0.000000
219.010010,-0.072243,-189.399887,-0.001199,0.007606,0.193191,-0.321352,-0.016370,1.931909,-189.399887,0.192169,0.000000
219.560013,-0.055115,-189.399887,-0.001207,0.007571,0.192298,-0.245163,-0.012489,1.922976,-189.399887,0.191248,0.000000
220.110016,-0.037613,-189.444366,-0.001207,0.007538,0.191457,-0.167311,-0.008523,1.914574,-189.444366,0.190339,0.000000
220.660004,-0.052132,-189.533325,-0.001207,0.007501,0.190529,-0.231893,-0.011813,1.905293,-189.533325,0.189420,0.000000
221.210007,-0.088257,-189.533325,-0.001229,0.007467,0.189671,-0.392586,-0.019999,1.896709,-189.533325,0.188501,0.000000
221.760010,-0.079315,-189.622299,-0.001242,0.007432,0.188778,-0.352812,-0.017973,1.887777,-189.622299,0.187589,0.000000
222.310013,-0.084534,-189.711258,-0.001276,0.007397,0.187884,-0.376025,-0.019156,1.878845,-189.711258,0.186670,0.000000
222.860016,-0.078949,-189.800217,-0.001324,0.007356,0.186835,-0.351183,-0.017890,1.868353,-189.800217,0.185751,0.000000
223.410004,-0.088997,-189.844696,-0.001358,0.007319,0.185907,-0.395878,-0.020167,1.859072,-189.844696,0.184840,0.000000
223.960007,-0.076714,-189.933655,-0.001406,0.007283,0.184996,-0.341239,-0.017384,1.849958,-189.933655,0.183921,0.000000
224.510010,-0.082672,-189.889175,-0.001436,0.007258,0.184346,-0.367744,-0.018734,1.843463,-189.889175,0.183002,0.000000
225.060013,-0.108734,-190.022629,-0.001492,0.007212,0.183193,-0.483674,-0.024640,1.831927,-190.022629,0.182083,0.000000
225.610016,-0.124748,-190.067108,-0.001518,0.007175,0.182248,-0.554908,-0.028268,1.822480,-190.067108,0.181172,0.000000
226.160004,-0.135178,-190.111588,-0.001548,0.007138,0.181311,-0.601300,-0.030632,1.813109,-190.111588,0.180253,0.000000
226.710007,-0.131081,-190.111588,-0.001604,0.007098,0.180287,-0.583076,-0.029703,1.802874,-190.111588,0.179334,0.000000
227.260010,-0.086769,-190.200546,-0.001643,0.007061,0.179359,-0.385968,-0.019662,1.793594,-190.200546,0.178422,0.000000
227.810013,-0.126984,-190.289505,-0.001677,0.007030,0.178552,-0.564851,-0.028775,1.785524,-190.289505,0.177503,0.000000
228.360016,-0.134430,-190.333984,-0.001699,0.006993,0.177617,-0.597974,-0.030462,1.776168,-190.333984,0.176584,0.000000
228.600006,-0.081924,-190.289505,-0.001725,0.006987,0.177478,-0.364418,-0.018564,1.774775,-190.289505,0.177296,0.000000