File: Data/compression 29/AutoNoHeating-17-29-reverse-2-1_10232024_184026.csv
Time (sec),S:Load (lbs),S:HL1 (DIM),S:LVDT (in),S:Position (in),Ch:Position (mm),Ch:Load (N),Ch:Stress (MPa),Ch:Strain (mm/mm),Ch:HL1 (DIM),Set Point (),Cycles ()
0.110000,0.006325,-417.008911,-0.010839,-0.005475,-0.139059,0.028134,0.001433,-1.390593,-417.008911,-0.138834,0.000000
0.480000,0.042816,-417.097870,-0.010848,-0.005406,-0.137316,0.190456,0.009702,-1.373160,-417.097870,-0.136545,0.000000
0.850000,0.005959,-417.097870,-0.010701,-0.005183,-0.131653,0.026505,0.001350,-1.316530,-417.097870,-0.130370,0.000000
1.220000,0.004463,-417.142365,-0.010438,-0.004940,-0.125470,0.019853,0.001011,-1.254700,-417.142365,-0.124213,0.000000
1.590000,0.028297,-417.097870,-0.010197,-0.004700,-0.119382,0.125873,0.006412,-1.193816,-417.097870,-0.118055,0.000000
1.960000,0.049522,-417.097870,-0.009947,-0.004446,-0.112938,0.220287,0.011222,-1.129382,-417.097870,-0.111881,0.000000
2.330000,0.044312,-417.186829,-0.009722,-0.004205,-0.106807,0.197107,0.010041,-1.068075,-417.186829,-0.105723,0.000000
2.700000,0.027924,-417.142365,-0.009472,-0.003969,-0.100806,0.124210,0.006328,-1.008061,-417.142365,-0.099566,0.000000
3.070000,-0.011917,-417.186829,-0.009227,-0.003729,-0.094709,-0.053010,-0.002700,-0.947094,-417.186829,-0.093392,0.000000
3.440000,-0.045807,-417.186829,-0.008968,-0.003484,-0.088500,-0.203759,-0.010380,-0.884999,-417.186829,-0.087234,0.000000
3.810000,-0.021225,-417.186829,-0.008722,-0.003237,-0.082230,-0.094413,-0.004810,-0.822299,-417.186829,-0.081060,0.000000
4.180000,0.057716,-417.186829,-0.008494,-0.002994,-0.076047,0.256735,0.013079,-0.760469,-417.186829,-0.074902,0.000000
4.550000,0.065910,-417.275787,-0.008222,-0.002747,-0.069768,0.293184,0.014935,-0.697677,-417.275787,-0.068745,0.000000
4.920000,0.044312,-417.320282,-0.007985,-0.002515,-0.063880,0.197107,0.010041,-0.638799,-417.320282,-0.062570,0.000000
5.290000,0.038727,-417.320282,-0.007748,-0.002270,-0.057670,0.172265,0.008776,-0.576704,-417.320282,-0.056413,0.000000
5.660000,0.042450,-417.275787,-0.007485,-0.002028,-0.051504,0.188827,0.009619,-0.515041,-417.275787,-0.050238,0.000000
6.030000,0.064789,-417.320282,-0.007235,-0.001778,-0.045173,0.288195,0.014681,-0.451735,-417.320282,-0.044081,0.000000
6.400000,0.055855,-417.275787,-0.006976,-0.001538,-0.039068,0.248455,0.012657,-0.390684,-417.275787,-0.037923,0.000000
6.770000,0.047287,-417.320282,-0.006722,-0.001294,-0.032867,0.210343,0.010715,-0.328673,-417.320282,-0.031749,0.000000
7.140000,0.012283,-417.364777,-0.006485,-0.001057,-0.026858,0.054639,0.002783,-0.268576,-417.364777,-0.025591,0.000000
7.510000,-0.004097,-417.320282,-0.006226,-0.000811,-0.020605,-0.018224,-0.000928,-0.206050,-417.320282,-0.019417,0.000000
7.880001,-0.048042,-417.364777,-0.005980,-0.000568,-0.014430,-0.213703,-0.010887,-0.144303,-417.364777,-0.013259,0.000000
8.250000,0.041702,-417.453735,-0.005721,-0.000324,-0.008230,0.185501,0.009450,-0.082299,-417.453735,-0.007102,0.000000
8.620001,0.067772,-417.453735,-0.005467,-0.000075,-0.001917,0.301465,0.015357,-0.019167,-417.453735,-0.000927,0.000000
8.990001,0.070374,-417.498199,-0.005247,0.000155,0.003929,0.313037,0.015947,0.039287,-417.498199,0.005230,0.000000
9.360001,0.106125,-417.409241,-0.005006,0.000007,0.000173,0.472067,0.024048,0.001733,-417.409241,0.000425,0.000000
9.730000,0.107613,-417.498199,-0.004997,0.000006,0.000165,0.478685,0.024385,0.001650,-417.498199,0.000425,0.000000
10.100000,0.119530,-417.498199,-0.004988,0.000006,0.000165,0.531695,0.027086,0.001650,-417.498199,0.000833,0.000000
10.470000,0.094955,-417.587158,-0.004997,0.000011,0.000278,0.422383,0.021517,0.002778,-417.587158,0.001448,0.000000
10.840000,0.135170,-417.542694,-0.004975,0.000029,0.000737,0.601266,0.030630,0.007373,-417.542694,0.002064,0.000000
11.210001,0.217087,-417.542694,-0.004954,0.000066,0.001665,0.965650,0.049193,0.016654,-417.542694,0.002680,0.000000
11.580001,0.303482,-417.631653,-0.004945,0.000089,0.002255,1.349956,0.068770,0.022550,-417.631653,0.003295,0.000000
11.950001,0.489296,-417.631653,-0.004915,0.000115,0.002914,2.176497,0.110876,0.029136,-417.631653,0.003920,0.000000
12.320001,0.646065,-417.587158,-0.004889,0.000137,0.003469,2.873840,0.146400,0.034692,-417.587158,0.004536,0.000000
12.690001,0.831131,-417.676117,-0.004863,0.000158,0.004024,3.697055,0.188337,0.040241,-417.676117,0.005151,0.000000
13.060000,1.229195,-417.587158,-0.004846,0.000194,0.004917,5.467731,0.278539,0.049173,-417.587158,0.005767,0.000000
13.430000,1.385963,-417.676117,-0.004816,0.000214,0.005429,6.165073,0.314064,0.054291,-417.676117,0.006383,0.000000
13.800000,1.767647,-417.676117,-0.004799,0.000239,0.006079,7.862885,0.400554,0.060793,-417.676117,0.006998,0.000000
14.170001,2.132950,-417.720612,-0.004769,0.000261,0.006617,9.487835,0.483333,0.066168,-417.720612,0.007614,0.000000
14.540001,2.438293,-417.720612,-0.004751,0.000280,0.007120,10.846071,0.552525,0.071201,-417.720612,0.008230,0.000000
14.910001,3.024780,-417.676117,-0.004734,0.000316,0.008022,13.454895,0.685425,0.080217,-417.676117,0.008846,0.000000
15.280001,3.253784,-417.809570,-0.004708,0.000334,0.008473,14.473555,0.737318,0.084729,-417.809570,0.009470,0.000000
15.650001,3.734894,-417.809570,-0.004682,0.000360,0.009141,16.613638,0.846339,0.091405,-417.809570,0.010086,0.000000
16.020000,4.152321,-417.809570,-0.004665,0.000380,0.009661,18.470446,0.940929,0.096606,-417.809570,0.010701,0.000000
16.390001,4.587250,-417.854065,-0.004652,0.000400,0.010172,20.405106,1.039486,0.101723,-417.854065,0.011318,0.000000
16.760000,5.340935,-417.809570,-0.004622,0.000438,0.011127,23.757664,1.210273,0.111268,-417.809570,0.011933,0.000000
17.130001,5.414665,-417.854065,-0.004605,0.000455,0.011560,24.085634,1.226981,0.115598,-417.854065,0.012548,0.000000
17.500000,5.744957,-417.987488,-0.004583,0.000477,0.012106,25.554846,1.301826,0.121064,-417.987488,0.013165,0.000000
17.870001,6.372032,-417.809570,-0.004557,0.000505,0.012818,28.344215,1.443923,0.128179,-417.809570,0.013780,0.000000
18.240002,6.507950,-417.854065,-0.004544,0.000519,0.013190,28.948807,1.474723,0.131904,-417.854065,0.014396,0.000000
18.610001,7.485802,-417.943024,-0.004506,0.000560,0.014223,33.298508,1.696307,0.142229,-417.943024,0.015021,0.000000
18.980001,7.603844,-417.987488,-0.004480,0.000581,0.014760,33.823586,1.723056,0.147603,-417.987488,0.015636,0.000000
19.350000,7.771408,-418.031982,-0.004475,0.000601,0.015272,34.568951,1.761026,0.152721,-418.031982,0.016252,0.000000
19.720001,8.462906,-418.031982,-0.004441,0.000632,0.016052,37.644886,1.917722,0.160525,-418.031982,0.016868,0.000000
20.090000,8.452477,-417.943024,-0.004415,0.000647,0.016434,37.598492,1.915359,0.164340,-417.943024,0.017483,0.000000
20.460001,8.768623,-417.987488,-0.004415,0.000673,0.017093,39.004784,1.986998,0.170933,-417.987488,0.018099,0.000000
20.830002,9.331650,-417.987488,-0.004368,0.000702,0.017822,41.509251,2.114582,0.178216,-417.987488,0.018715,0.000000
21.200001,9.435913,-418.076447,-0.004355,0.000722,0.018351,41.973038,2.138208,0.183507,-418.076447,0.019330,0.000000
21.570002,9.833237,-418.120941,-0.004320,0.000748,0.019001,43.740421,2.228243,0.190009,-418.120941,0.019946,0.000000
21.940001,10.249924,-418.076447,-0.004299,0.000773,0.019625,45.593937,2.322666,0.196254,-418.076447,0.020571,0.000000
22.310001,10.321045,-418.120941,-0.004286,0.000790,0.020077,45.910301,2.338782,0.200766,-418.120941,0.021186,0.000000
22.680000,10.860611,-418.165436,-0.004260,0.000818,0.020787,48.310410,2.461050,0.207874,-418.165436,0.021802,0.000000
23.050001,11.123505,-418.165436,-0.004243,0.000844,0.021438,49.479820,2.520622,0.214376,-418.165436,0.022418,0.000000
23.420002,11.431458,-418.165436,-0.004208,0.000869,0.022071,50.849663,2.590405,0.220712,-418.165436,0.023033,0.000000
23.790001,11.761757,-418.165436,-0.004182,0.000892,0.022661,52.318909,2.665252,0.226609,-418.165436,0.023650,0.000000
24.160002,11.873466,-418.120941,-0.004178,0.000914,0.023224,52.815815,2.690566,0.232241,-418.120941,0.024265,0.000000
24.530001,12.633850,-418.209900,-0.004143,0.000947,0.024066,56.198174,2.862871,0.240659,-418.209900,0.024880,0.000000
24.900002,12.552673,-418.343353,-0.004122,0.000967,0.024560,55.837078,2.844476,0.245602,-418.343353,0.025497,0.000000
25.270000,12.776093,-418.298859,-0.004087,0.000990,0.025158,56.830898,2.895104,0.251582,-418.298859,0.026121,0.000000
25.640001,13.172676,-418.254395,-0.004057,0.001014,0.025765,58.594990,2.984971,0.257653,-418.254395,0.026736,0.000000
26.010002,13.045319,-418.209900,-0.004049,0.001029,0.026147,58.028477,2.956111,0.261468,-418.209900,0.027353,0.000000
26.380001,13.991150,-418.298859,-0.004018,0.001067,0.027110,62.235744,3.170440,0.271097,-418.298859,0.027968,0.000000
26.750002,13.788948,-418.298859,-0.004001,0.001085,0.027569,61.336304,3.124620,0.275692,-418.298859,0.028584,0.000000
27.120001,14.147919,-418.343353,-0.003958,0.001108,0.028151,62.933086,3.205964,0.281505,-418.343353,0.029200,0.000000
27.490002,14.580986,-418.298859,-0.003936,0.001135,0.028836,64.859467,3.304099,0.288356,-418.298859,0.029815,0.000000
27.860001,14.619339,-418.343353,-0.003932,0.001156,0.029356,65.030067,3.312789,0.293556,-418.343353,0.030431,0.000000
28.230001,14.776482,-418.387817,-0.003902,0.001176,0.029867,65.729073,3.348399,0.298674,-418.387817,0.031047,0.000000
28.600002,15.277695,-418.387817,-0.003863,0.001206,0.030639,67.958580,3.461975,0.306395,-418.387817,0.031671,0.000000
28.970001,15.442284,-418.476776,-0.003837,0.001230,0.031246,68.690712,3.499271,0.312458,-418.476776,0.032287,0.000000
29.340002,15.559952,-418.387817,-0.003811,0.001255,0.031879,69.214119,3.525935,0.318794,-418.387817,0.032903,0.000000
29.710001,15.863808,-418.432312,-0.003798,0.001280,0.032512,70.565742,3.594790,0.325122,-418.432312,0.033518,0.000000
30.080002,15.922646,-418.476776,-0.003760,0.001299,0.032989,70.827461,3.608123,0.329891,-418.476776,0.034134,0.000000
30.450001,16.478966,-418.521271,-0.003742,0.001331,0.033796,73.302101,3.734187,0.337961,-418.521271,0.034750,0.000000
30.820002,16.445457,-418.521271,-0.003704,0.001352,0.034342,73.153046,3.726594,0.343419,-418.521271,0.035365,0.000000
31.190001,16.613396,-418.565735,-0.003678,0.001377,0.034966,73.900078,3.764649,0.349664,-418.565735,0.035981,0.000000
31.560001,16.504662,-418.521271,-0.003660,0.001392,0.035348,73.416405,3.740010,0.353479,-418.521271,0.036597,0.000000
31.930002,17.117584,-418.565735,-0.003617,0.001424,0.036181,76.142815,3.878900,0.361806,-418.565735,0.037221,0.000000
32.300003,17.682106,-418.654724,-0.003591,0.001454,0.036926,78.653938,4.006823,0.369262,-418.654724,0.037837,0.000000
32.670002,17.381599,-418.610229,-0.003557,0.001475,0.037473,77.317215,3.938727,0.374727,-418.610229,0.038453,0.000000
33.040001,17.399475,-418.610229,-0.003535,0.001495,0.037967,77.396729,3.942777,0.379670,-418.610229,0.039068,0.000000
33.410000,17.908508,-418.565735,-0.003501,0.001524,0.038722,79.661026,4.058126,0.387217,-418.565735,0.039685,0.000000
33.780003,18.069374,-418.654724,-0.003471,0.001550,0.039381,80.376587,4.094579,0.393811,-418.654724,0.040299,0.000000
34.150002,17.940903,-418.788147,-0.003466,0.001571,0.039909,79.805122,4.065467,0.399094,-418.788147,0.040915,0.000000
34.520000,18.350136,-418.743683,-0.003402,0.001599,0.040604,81.625481,4.158200,0.406036,-418.743683,0.041532,0.000000
34.890003,18.221672,-418.743683,-0.003376,0.001621,0.041176,81.054047,4.129090,0.411759,-418.743683,0.042155,0.000000
35.260002,18.624207,-418.743683,-0.003354,0.001647,0.041844,82.844604,4.220306,0.418435,-418.743683,0.042772,0.000000
35.630001,18.328171,-418.743683,-0.003341,0.001663,0.042243,81.527779,4.153223,0.422432,-418.743683,0.043388,0.000000
36.000000,19.247559,-418.788147,-0.003307,0.001699,0.043162,85.617416,4.361559,0.431622,-418.788147,0.044002,0.000000
36.370003,19.221115,-418.788147,-0.003264,0.001723,0.043777,85.499786,4.355567,0.437769,-418.788147,0.044619,0.000000
36.740002,18.870346,-418.832642,-0.003229,0.001742,0.044246,83.939491,4.276082,0.442462,-418.832642,0.045235,0.000000
37.110001,19.206970,-418.832642,-0.003225,0.001766,0.044853,85.436867,4.352362,0.448533,-418.832642,0.045851,0.000000
37.480003,19.343254,-418.832642,-0.003169,0.001788,0.045416,86.043091,4.383244,0.454165,-418.832642,0.046466,0.000000
37.850002,19.083710,-418.832642,-0.003169,0.001808,0.045919,84.888580,4.324430,0.459191,-418.832642,0.047082,0.000000
38.220001,20.201950,-418.877106,-0.003104,0.001845,0.046873,89.862762,4.577827,0.468729,-418.877106,0.047706,0.000000
38.590000,19.773720,-418.832642,-0.003074,0.001864,0.047333,87.957901,4.480789,0.473331,-418.832642,0.048322,0.000000
38.960003,20.076088,-418.877106,-0.003061,0.001889,0.047992,89.302902,4.549306,0.479917,-418.877106,0.048938,0.000000
39.330002,20.109596,-418.921600,-0.003027,0.001912,0.048564,89.451950,4.556900,0.485640,-418.921600,0.049553,0.000000
39.700001,20.254082,-418.966064,-0.002988,0.001933,0.049103,90.094658,4.589641,0.491030,-418.966064,0.050169,0.000000
40.070004,20.909454,-418.966064,-0.002979,0.001968,0.049978,93.009895,4.738150,0.499780,-418.966064,0.050785,0.000000
40.440002,20.521812,-418.966064,-0.002919,0.001987,0.050464,91.285583,4.650310,0.504640,-418.966064,0.051401,0.000000
40.810001,20.393349,-419.010559,-0.002897,0.002010,0.051045,90.714142,4.621199,0.510454,-419.010559,0.052016,0.000000
41.180000,21.173843,-419.010559,-0.002871,0.002039,0.051790,94.185959,4.798061,0.517902,-419.010559,0.052632,0.000000
41.550003,21.051331,-419.099518,-0.002850,0.002059,0.052311,93.640999,4.770299,0.523110,-419.099518,0.053256,0.000000
41.920002,21.633347,-419.055054,-0.002807,0.002089,0.053057,96.229935,4.902186,0.530574,-419.055054,0.053872,0.000000
42.290001,21.132881,-419.099518,-0.002772,0.002104,0.053439,94.003754,4.788780,0.534389,-419.099518,0.054488,0.000000
42.660004,21.257622,-419.010559,-0.002755,0.002129,0.054072,94.558624,4.817046,0.540718,-419.010559,0.055104,0.000000
43.030003,21.950981,-419.099518,-0.002712,0.002159,0.054844,97.642838,4.974164,0.548439,-419.099518,0.055719,0.000000
43.400002,21.921936,-419.099518,-0.002690,0.002183,0.055442,97.513641,4.967582,0.554419,-419.099518,0.056335,0.000000
43.770000,21.495567,-419.188477,-0.002656,0.002199,0.055849,95.617058,4.870965,0.558492,-419.188477,0.056951,0.000000
44.140003,21.969231,-419.144012,-0.002626,0.002227,0.056570,97.724022,4.978299,0.565698,-419.144012,0.057566,0.000000
44.510002,22.178131,-419.144012,-0.002596,0.002251,0.057168,98.653252,5.025636,0.571678,-419.144012,0.058182,0.000000
44.880001,22.522575,-419.188477,-0.002583,0.002279,0.057896,100.185417,5.103688,0.578960,-419.188477,0.058806,0.000000
45.250004,22.664444,-419.232971,-0.002539,0.002299,0.058382,100.816483,5.135837,0.583820,-419.232971,0.059422,0.000000
45.620003,22.943726,-419.188477,-0.002501,0.002324,0.059041,102.058792,5.199122,0.590406,-419.188477,0.060038,0.000000
45.990002,23.132523,-419.232971,-0.002453,0.002350,0.059699,102.898598,5.241904,0.596991,-419.232971,0.060654,0.000000
46.360001,23.101982,-419.277435,-0.002423,0.002375,0.060315,102.762749,5.234984,0.603153,-419.277435,0.061269,0.000000
46.730003,23.116882,-419.232971,-0.002393,0.002399,0.060922,102.829025,5.238360,0.609224,-419.232971,0.061885,0.000000
47.100002,23.609901,-419.277435,-0.002363,0.002425,0.061599,105.022087,5.350080,0.615992,-419.277435,0.062501,0.000000
47.470001,23.459091,-419.321930,-0.002341,0.002443,0.062041,104.351250,5.315906,0.620412,-419.321930,0.063116,0.000000
47.840004,24.429123,-419.321930,-0.002311,0.002475,0.062874,108.666168,5.535718,0.628739,-419.321930,0.063732,0.000000
48.210003,24.004242,-419.321930,-0.002276,0.002495,0.063377,106.776199,5.439439,0.633766,-419.321930,0.064358,0.000000
48.580002,23.958069,-419.366394,-0.002251,0.002519,0.063993,106.570816,5.428976,0.639927,-419.366394,0.064972,0.000000
48.950001,24.347572,-419.366394,-0.002220,0.002544,0.064626,108.303413,5.517239,0.646256,-419.366394,0.065588,0.000000
49.320004,23.624794,-419.410889,-0.002190,0.002555,0.064903,105.088333,5.353455,0.649026,-419.410889,0.066205,0.000000
49.690002,24.975021,-419.455383,-0.002147,0.002592,0.065831,111.094444,5.659420,0.658307,-419.455383,0.066819,0.000000
50.060001,25.002945,-419.366394,-0.002117,0.002614,0.066403,111.218651,5.665748,0.664030,-419.366394,0.067435,0.000000
50.430004,25.126198,-419.410889,-0.002100,0.002639,0.067019,111.766907,5.693677,0.670191,-419.410889,0.068052,0.000000
50.800003,25.498199,-419.455383,-0.002082,0.002664,0.067678,113.421654,5.777975,0.676777,-419.455383,0.068666,0.000000
51.170002,25.178703,-419.499847,-0.002031,0.002682,0.068121,112.000465,5.705576,0.681213,-419.499847,0.069283,0.000000
51.540001,25.256531,-419.455383,-0.002009,0.002709,0.068815,112.346657,5.723211,0.688147,-419.455383,0.069908,0.000000
51.910004,26.060486,-419.499847,-0.001979,0.002736,0.069491,115.922829,5.905391,0.694914,-419.499847,0.070522,0.000000
52.280003,26.053780,-419.455383,-0.001940,0.002759,0.070089,115.892998,5.903871,0.700894,-419.455383,0.071139,0.000000
52.650002,26.318909,-419.499847,-0.001927,0.002785,0.070748,117.072350,5.963950,0.707480,-419.499847,0.071755,0.000000
53.020004,26.606384,-419.544342,-0.001906,0.002808,0.071329,118.351105,6.029093,0.713294,-419.544342,0.072369,0.000000
53.390003,26.402695,-419.588806,-0.001863,0.002827,0.071797,117.445053,5.982936,0.717972,-419.588806,0.072986,0.000000
53.760002,27.698181,-419.544342,-0.001837,0.002862,0.072700,123.207664,6.276497,0.726995,-419.544342,0.073602,0.000000
54.130001,27.283730,-419.544342,-0.001807,0.002881,0.073167,121.364090,6.182581,0.731673,-419.544342,0.074216,0.000000
54.500004,27.473640,-419.544342,-0.001781,0.002903,0.073740,122.208855,6.225616,0.737396,-419.544342,0.074833,0.000000
54.870003,27.989746,-419.633301,-0.001750,0.002930,0.074416,124.504608,6.342567,0.744163,-419.633301,0.075458,0.000000
55.240002,28.073898,-419.633301,-0.001716,0.002951,0.074954,124.878937,6.361636,0.749538,-419.633301,0.076073,0.000000
55.610004,29.347412,-419.633301,-0.001690,0.002986,0.075847,130.543808,6.650218,0.758470,-419.633301,0.076689,0.000000
55.980003,28.655548,-419.633301,-0.001664,0.003004,0.076291,127.466248,6.493440,0.762906,-419.633301,0.077305,0.000000
56.350002,29.090103,-419.677765,-0.001638,0.003028,0.076905,129.399246,6.591912,0.769053,-419.677765,0.077920,0.000000
56.720001,29.637497,-419.722260,-0.001617,0.003054,0.077582,131.834167,6.715952,0.775820,-419.722260,0.078536,0.000000
57.090004,29.392471,-419.766724,-0.001582,0.003074,0.078077,130.744247,6.660429,0.780771,-419.766724,0.079152,0.000000
57.460003,30.962769,-419.766724,-0.001565,0.003107,0.078926,137.729279,7.016264,0.789264,-419.766724,0.079768,0.000000
57.830002,30.676041,-419.722260,-0.001526,0.003127,0.079429,136.453842,6.951290,0.794290,-419.722260,0.080383,0.000000
58.200005,30.736366,-419.766724,-0.001509,0.003146,0.079906,136.722183,6.964961,0.799059,-419.766724,0.081008,0.000000
58.570004,31.497864,-419.811218,-0.001492,0.003172,0.080574,140.109497,7.137518,0.805736,-419.811218,0.081623,0.000000
58.940002,31.512764,-419.855682,-0.001462,0.003193,0.081094,140.175781,7.140894,0.810944,-419.855682,0.082239,0.000000
59.310001,32.972458,-419.811218,-0.001449,0.003227,0.081962,146.668823,7.471666,0.819619,-419.811218,0.082855,0.000000
59.680004,33.404411,-419.855682,-0.001401,0.003250,0.082543,148.590240,7.569548,0.825433,-419.855682,0.083470,0.000000
60.050003,33.272591,-419.900177,-0.001375,0.003270,0.083055,148.003876,7.539677,0.830550,-419.900177,0.084086,0.000000
60.420002,33.788330,-419.944672,-0.001362,0.003295,0.083688,150.298004,7.656545,0.836878,-419.944672,0.084702,0.000000
60.790005,34.451897,-419.989136,-0.001337,0.003316,0.084234,153.249695,7.806911,0.842344,-419.989136,0.085318,0.000000
61.160004,34.734528,-419.944672,-0.001324,0.003341,0.084858,154.506897,7.870956,0.848581,-419.944672,0.085942,0.000000
61.530003,36.333122,-419.900177,-0.001285,0.003374,0.085700,161.617798,8.233203,0.856999,-419.900177,0.086558,0.000000
61.900002,36.147682,-419.989136,-0.001272,0.003392,0.086168,160.792923,8.191182,0.861677,-419.989136,0.087173,0.000000
62.270004,36.720016,-420.033630,-0.001250,0.003416,0.086757,163.338791,8.320874,0.867566,-420.033630,0.087789,0.000000
62.640003,37.671059,-420.033630,-0.001212,0.003443,0.087442,167.569244,8.536384,0.874424,-420.033630,0.088405,0.000000
63.010002,37.979378,-420.122589,-0.001186,0.003463,0.087954,168.940704,8.606250,0.879541,-420.122589,0.089021,0.000000
63.380005,39.409660,-420.033630,-0.001177,0.003496,0.088787,175.302917,8.930356,0.887868,-420.033630,0.089636,0.000000
63.750004,39.434242,-420.033630,-0.001155,0.003514,0.089255,175.412277,8.935926,0.892546,-420.033630,0.090252,0.000000
64.120003,39.832680,-420.122589,-0.001121,0.003537,0.089845,177.184616,9.026215,0.898451,-420.122589,0.090869,0.000000
64.490005,41.247696,-420.122589,-0.001099,0.003566,0.090564,183.478912,9.346861,0.905642,-420.122589,0.091492,0.000000
64.860001,41.890038,-420.078094,-0.001069,0.003586,0.091094,186.336197,9.492418,0.910941,-420.078094,0.092108,0.000000
65.230003,42.768089,-420.078094,-0.001061,0.003612,0.091734,190.241959,9.691388,0.917345,-420.078094,0.092723,0.000000
65.600006,43.380646,-420.167053,-0.001052,0.003635,0.092342,192.966751,9.830194,0.923416,-420.167053,0.093339,0.000000
65.970001,43.766792,-420.167053,-0.001018,0.003655,0.092837,194.684418,9.917697,0.928367,-420.167053,0.093955,0.000000
66.340004,44.901413,-420.211548,-0.001009,0.003681,0.093495,199.731461,10.174806,0.934952,-420.211548,0.094572,0.000000
66.710007,45.520668,-420.211548,-0.000979,0.003701,0.094007,202.486038,10.315131,0.940069,-420.211548,0.095186,0.000000
67.080002,47.799591,-420.122589,-0.000957,0.003738,0.094953,212.623199,10.831542,0.949532,-420.122589,0.095803,0.000000
67.450005,48.304153,-420.167053,-0.000949,0.003757,0.095438,214.867599,10.945877,0.954376,-420.167053,0.096419,0.000000
67.820000,49.096931,-420.256012,-0.000923,0.003782,0.096054,218.394058,11.125524,0.960538,-420.256012,0.097042,0.000000
68.190002,50.034943,-420.256012,-0.000901,0.003804,0.096617,222.566544,11.338080,0.966170,-420.256012,0.097659,0.000000
68.560005,50.831070,-420.300507,-0.000888,0.003825,0.097164,226.107895,11.518485,0.971636,-420.300507,0.098275,0.000000
68.930000,51.716576,-420.256012,-0.000875,0.003848,0.097728,230.046814,11.719144,0.977283,-420.256012,0.098889,0.000000
69.300003,53.418686,-420.256012,-0.000854,0.003878,0.098491,237.618179,12.104848,0.984913,-420.256012,0.099506,0.000000
69.670006,54.421486,-420.300507,-0.000858,0.003904,0.099168,242.078857,12.332085,0.991680,-420.300507,0.100122,0.000000
70.040001,55.567650,-420.345001,-0.000832,0.003927,0.099757,247.177246,12.591809,0.997570,-420.345001,0.100736,0.000000
70.410004,56.655724,-420.300507,-0.000802,0.003950,0.100329,252.017242,12.838370,1.003292,-420.300507,0.101353,0.000000
70.780006,57.444778,-420.345001,-0.000785,0.003967,0.100771,255.527130,13.017173,1.007713,-420.345001,0.101969,0.000000
71.150002,59.479797,-420.345001,-0.000780,0.004000,0.101604,264.579346,13.478315,1.016040,-420.345001,0.102593,0.000000
71.520004,60.499352,-420.433960,-0.000776,0.004023,0.102185,269.114563,13.709349,1.021854,-420.433960,0.103209,0.000000
71.890007,61.407936,-420.389465,-0.000755,0.004045,0.102732,273.156128,13.915237,1.027319,-420.389465,0.103825,0.000000
72.260002,63.263840,-420.433960,-0.000729,0.004074,0.103469,281.411621,14.335792,1.034692,-420.433960,0.104440,0.000000
72.630005,64.269989,-420.433960,-0.000711,0.004094,0.103981,285.887177,14.563787,1.039809,-420.433960,0.105056,0.000000
73.000000,65.786667,-420.433960,-0.000707,0.004119,0.104614,292.633698,14.907472,1.046137,-420.433960,0.105672,0.000000
73.370003,65.390457,-420.478424,-0.000690,0.004119,0.104623,290.871277,14.817690,1.046228,-420.478424,0.018360,0.000000
73.740005,65.385254,-420.522919,-0.000681,0.004133,0.104986,290.848145,14.816510,1.049862,-420.522919,294.500458,0.000000
74.110001,65.857422,-420.611877,-0.000677,0.004139,0.105142,292.948456,14.923505,1.051421,-420.611877,294.500458,0.000000
74.480003,64.986816,-420.478424,-0.000647,0.004149,0.105386,289.075806,14.726223,1.053859,-420.478424,294.500458,0.000000
74.850006,65.059799,-420.567383,-0.000655,0.004158,0.105619,289.400452,14.742761,1.056190,-420.567383,294.500458,0.000000
75.220001,65.085114,-420.567383,-0.000664,0.004165,0.105802,289.513031,14.748498,1.058022,-420.567383,294.500458,0.000000
75.590004,65.191238,-420.611877,-0.000660,0.004173,0.106001,289.985107,14.772546,1.060005,-420.611877,294.500458,0.000000
75.960007,65.187515,-420.567383,-0.000634,0.004179,0.106149,289.968536,14.771702,1.061489,-420.567383,294.500458,0.000000
76.330002,65.279129,-420.567383,-0.000629,0.004185,0.106305,290.376068,14.792462,1.063048,-420.567383,294.500458,0.000000
76.700005,65.382645,-420.656342,-0.000638,0.004193,0.106496,290.836517,14.815919,1.064956,-420.656342,294.500458,0.000000
77.070007,65.058304,-420.656342,-0.000617,0.004193,0.106512,289.393799,14.742422,1.065122,-420.656342,294.500458,0.000000
77.440002,65.225128,-420.700836,-0.000612,0.004200,0.106668,290.135864,14.780226,1.066682,-420.700836,294.500458,0.000000
77.810005,65.259018,-420.700836,-0.000617,0.004205,0.106807,290.286621,14.787905,1.068075,-420.700836,294.500458,0.000000
78.180000,64.977127,-420.700836,-0.000608,0.004206,0.106833,289.032684,14.724028,1.068332,-420.700836,294.500458,0.000000
78.550003,65.566589,-420.700836,-0.000599,0.004216,0.107094,291.654755,14.857601,1.070936,-420.700836,294.500458,0.000000
78.920006,65.293274,-420.745331,-0.000617,0.004216,0.107094,290.438995,14.795667,1.070936,-420.745331,294.500458,0.000000
79.290001,64.995377,-420.789795,-0.000595,0.004217,0.107112,289.113861,14.728163,1.071118,-420.789795,294.500458,0.000000
79.660004,65.300720,-420.834290,-0.000591,0.004225,0.107303,290.472107,14.797355,1.073025,-420.834290,294.500458,0.000000
80.030006,65.062408,-420.789795,-0.000591,0.004225,0.107303,289.412048,14.743353,1.073025,-420.789795,294.500458,0.000000
80.400002,64.793915,-420.789795,-0.000595,0.004225,0.107319,288.217712,14.682511,1.073192,-420.789795,294.500458,0.000000
80.770004,65.857422,-420.834290,-0.000586,0.004239,0.107666,292.948456,14.923505,1.076659,-420.834290,294.500458,0.000000
81.140007,65.665268,-420.878754,-0.000582,0.004239,0.107666,292.093689,14.879962,1.076659,-420.878754,294.500458,0.000000
81.510002,65.444092,-420.923248,-0.000578,0.004239,0.107675,291.109863,14.829843,1.076750,-420.923248,294.500458,0.000000
81.880005,65.183044,-420.923248,-0.000573,0.004239,0.107675,289.948669,14.770689,1.076750,-420.923248,294.500458,0.000000
82.250008,64.959259,-420.834290,-0.000569,0.004240,0.107684,288.953217,14.719978,1.076841,-420.834290,294.500458,0.000000
82.620003,64.730240,-420.967712,-0.000582,0.004240,0.107692,287.934479,14.668082,1.076916,-420.967712,294.500458,0.000000
82.990005,64.488571,-421.012207,-0.000565,0.004240,0.107692,286.859497,14.613319,1.076916,-421.012207,294.500458,0.000000
83.360001,66.895218,-421.012207,-0.000543,0.004144,0.105263,297.564789,15.158673,1.052632,-421.012207,294.500458,0.000000
83.730003,66.582428,-420.967712,-0.000539,0.004144,0.105263,296.173431,15.087794,1.052632,-420.967712,294.500458,0.000000
84.100006,66.285278,-421.056671,-0.000543,0.004144,0.105263,294.851654,15.020458,1.052632,-421.056671,294.500458,0.000000
84.470001,66.043228,-421.012207,-0.000556,0.004144,0.105263,293.774963,14.965610,1.052632,-421.012207,294.500458,0.000000
84.840004,65.857788,-421.056671,-0.000535,0.004146,0.105307,292.950073,14.923589,1.053071,-421.056671,294.500458,0.000000
85.210007,65.570694,-421.012207,-0.000543,0.004184,0.106270,291.673004,14.858532,1.062700,-421.012207,294.500458,0.000000
85.580002,65.370361,-421.101166,-0.000543,0.004206,0.106833,290.781891,14.813136,1.068332,-421.101166,294.500458,0.000000
85.950005,65.219543,-421.056671,-0.000539,0.004220,0.107189,290.111023,14.778960,1.071890,-421.056671,294.500458,0.000000
86.320007,65.081024,-421.145630,-0.000556,0.004243,0.107761,289.494843,14.747571,1.077613,-421.145630,294.500458,0.000000
86.690002,65.235931,-421.145630,-0.000543,0.004257,0.108117,290.183929,14.782673,1.081170,-421.145630,294.500458,0.000000
87.060005,65.162201,-421.145630,-0.000548,0.004258,0.108152,289.855957,14.765966,1.081519,-421.145630,294.500458,0.000000
87.430008,65.272415,-421.145630,-0.000535,0.004263,0.108282,290.346191,14.790941,1.082821,-421.145630,294.500458,0.000000
87.800003,65.224014,-421.190125,-0.000535,0.004263,0.108282,290.130920,14.779973,1.082821,-421.190125,294.500458,0.000000
88.170006,65.109695,-421.190125,-0.000543,0.004264,0.108308,289.622375,14.754068,1.083078,-421.190125,294.500458,0.000000
88.540001,65.053833,-421.190125,-0.000543,0.004265,0.108343,289.373901,14.741409,1.083426,-421.190125,294.500458,0.000000
88.910004,65.113785,-421.279083,-0.000535,0.004269,0.108421,289.640594,14.754994,1.084213,-421.279083,294.500458,0.000000
89.280006,65.261246,-421.234619,-0.000526,0.004271,0.108489,290.296509,14.788410,1.084895,-421.234619,294.500458,0.000000
89.650002,65.206512,-421.279083,-0.000543,0.004271,0.108489,290.053040,14.776007,1.084895,-421.279083,294.500458,0.000000
90.020004,65.246353,-421.279083,-0.000530,0.004275,0.108577,290.230286,14.785034,1.085773,-421.279083,294.500458,0.000000
90.390007,65.254547,-421.368042,-0.000535,0.004275,0.108585,290.266724,14.786892,1.085849,-421.368042,294.500458,0.000000
90.760002,65.180069,-421.323578,-0.000535,0.004275,0.108585,289.935425,14.770015,1.085849,-421.323578,294.500458,0.000000
91.130005,65.142838,-421.279083,-0.000530,0.004277,0.108629,289.769806,14.761578,1.086288,-421.279083,294.500458,0.000000
91.500008,65.075806,-421.234619,-0.000539,0.004277,0.108638,289.471649,14.746388,1.086378,-421.234619,294.500458,0.000000
91.870003,65.167038,-421.323578,-0.000539,0.004280,0.108715,289.877472,14.767062,1.087151,-421.323578,294.500458,0.000000
92.240005,65.116028,-421.457001,-0.000526,0.004280,0.108715,289.650543,14.755503,1.087151,-421.457001,294.500458,0.000000
92.610001,65.138000,-421.412537,-0.000526,0.004283,0.108776,289.748291,14.760482,1.087756,-421.412537,294.500458,0.000000
92.980003,65.152893,-421.412537,-0.000522,0.004283,0.108785,289.814545,14.763856,1.087847,-421.412537,294.500458,0.000000
93.350006,65.097778,-421.412537,-0.000522,0.004284,0.108803,289.569366,14.751368,1.088029,-421.412537,294.500458,0.000000
93.720001,65.069473,-421.457001,-0.000522,0.004284,0.108820,289.443481,14.744953,1.088195,-421.457001,294.500458,0.000000
94.090004,65.091080,-421.457001,-0.000526,0.004286,0.108863,289.539581,14.749849,1.088634,-421.457001,294.500458,0.000000
94.460007,65.086227,-421.501495,-0.000513,0.004287,0.108880,289.518005,14.748750,1.088801,-421.501495,294.500458,0.000000
94.830002,65.059418,-421.457001,-0.000522,0.004288,0.108906,289.398743,14.742675,1.089058,-421.457001,294.500458,0.000000
95.200005,65.054214,-421.501495,-0.000517,0.004288,0.108915,289.375610,14.741495,1.089149,-421.501495,294.500458,0.000000
95.570007,65.048996,-421.501495,-0.000530,0.004290,0.108959,289.352386,14.740314,1.089588,-421.501495,294.500458,0.000000
95.940002,65.032990,-421.590454,-0.000517,0.004290,0.108959,289.281189,14.736687,1.089588,-421.590454,294.500458,0.000000
96.310005,65.002457,-421.634949,-0.000526,0.004291,0.108985,289.145355,14.729767,1.089845,-421.634949,294.500458,0.000000
96.680008,65.006546,-421.545959,-0.000517,0.004291,0.109001,289.163544,14.730694,1.090012,-421.545959,294.500458,0.000000
97.050003,64.978622,-421.590454,-0.000522,0.004292,0.109010,289.039337,14.724366,1.090103,-421.590454,294.500458,0.000000
97.420006,64.952927,-421.545959,-0.000509,0.004292,0.109019,288.925049,14.718543,1.090194,-421.545959,294.500458,0.000000
97.790001,65.461960,-421.634949,-0.000517,0.004300,0.109210,291.189331,14.833892,1.092101,-421.634949,294.500458,0.000000
98.160004,65.479462,-421.679413,-0.000504,0.004299,0.109201,291.267181,14.837858,1.092010,-421.679413,294.500458,0.000000
98.530006,65.417648,-421.634949,-0.000500,0.004299,0.109201,290.992218,14.823851,1.092010,-421.634949,294.500458,0.000000
98.900002,65.357697,-421.634949,-0.000522,0.004299,0.109201,290.725555,14.810266,1.092010,-421.634949,294.500458,0.000000
99.270004,65.305191,-421.723907,-0.000513,0.004299,0.109201,290.492004,14.798368,1.092010,-421.723907,294.500458,0.000000
99.640007,65.251572,-421.679413,-0.000500,0.004299,0.109201,290.253479,14.786218,1.092010,-421.679413,294.500458,0.000000
100.010002,65.207260,-421.768372,-0.000513,0.004300,0.109210,290.056366,14.776176,1.092101,-421.768372,294.500458,0.000000
100.380005,65.112305,-421.768372,-0.000500,0.004300,0.109210,289.634003,14.754659,1.092101,-421.768372,294.500458,0.000000
100.750008,65.056076,-421.768372,-0.000509,0.004300,0.109210,289.383881,14.741918,1.092101,-421.768372,294.500458,0.000000
101.120003,64.988678,-421.768372,-0.000522,0.004300,0.109227,289.084076,14.726645,1.092268,-421.768372,294.500458,0.000000
101.490005,65.062408,-421.901825,-0.000517,0.004303,0.109287,289.412048,14.743353,1.092873,-421.901825,294.500458,0.000000
101.860008,65.056824,-421.812866,-0.000509,0.004303,0.109287,289.387207,14.742087,1.092873,-421.812866,294.500458,0.000000
102.230003,65.055328,-421.857330,-0.000500,0.004304,0.109315,289.380554,14.741748,1.093146,-421.857330,294.500458,0.000000
102.600006,65.227371,-421.857330,-0.000504,0.004307,0.109392,290.145844,14.780734,1.093918,-421.857330,294.500458,0.000000
102.970001,65.250076,-421.812866,-0.000509,0.004307,0.109392,290.246826,14.785879,1.093918,-421.812866,294.500458,0.000000
103.340004,65.208740,-421.946289,-0.000500,0.004307,0.109392,290.062958,14.776512,1.093918,-421.946289,294.500458,0.000000
103.710007,65.160339,-421.901825,-0.000500,0.004307,0.109392,289.847656,14.765544,1.093918,-421.901825,294.500458,0.000000
104.080002,65.183426,-421.901825,-0.000504,0.004308,0.109427,289.950348,14.770775,1.094266,-421.901825,294.500458,0.000000
104.450005,65.160339,-421.946289,-0.000500,0.004308,0.109427,289.847656,14.765544,1.094266,-421.946289,294.500458,0.000000
104.820007,65.138000,-421.946289,-0.000513,0.004309,0.109443,289.748291,14.760482,1.094433,-421.946289,294.500458,0.000000
105.190002,65.109695,-421.990784,-0.000496,0.004309,0.109443,289.622375,14.754068,1.094433,-421.990784,294.500458,0.000000
105.560005,65.069855,-422.035278,-0.000500,0.004309,0.109443,289.445160,14.745040,1.094433,-422.035278,294.500458,0.000000
105.930008,65.240402,-422.035278,-0.000500,0.004312,0.109522,290.203796,14.783687,1.095220,-422.035278,294.500458,0.000000
106.300003,65.243378,-421.990784,-0.000504,0.004312,0.109522,290.217041,14.784361,1.095220,-421.990784,294.500458,0.000000
106.670006,65.202408,-422.124237,-0.000500,0.004312,0.109522,290.034790,14.775077,1.095220,-422.124237,294.500458,0.000000
107.040009,65.164810,-422.124237,-0.000496,0.004312,0.109522,289.867554,14.766557,1.095220,-422.124237,294.500458,0.000000
107.410004,65.205017,-422.079742,-0.000504,0.004314,0.109566,290.046417,14.775668,1.095659,-422.079742,294.500458,0.000000
107.780006,65.201294,-422.079742,-0.000496,0.004314,0.109566,290.029846,14.774824,1.095659,-422.079742,294.500458,0.000000
108.150002,65.147675,-422.079742,-0.000509,0.004314,0.109566,289.791321,14.762674,1.095659,-422.079742,294.500458,0.000000
108.520004,65.124954,-422.079742,-0.000513,0.004314,0.109566,289.690277,14.757525,1.095659,-422.079742,294.500458,0.000000
108.890007,65.075806,-422.168701,-0.000509,0.004314,0.109566,289.471649,14.746388,1.095659,-422.168701,294.500458,0.000000
109.260002,65.558029,-422.168701,-0.000496,0.004321,0.109757,291.616669,14.855662,1.097567,-422.168701,294.500458,0.000000
109.630005,65.606445,-422.168701,-0.000492,0.004321,0.109757,291.832031,14.866633,1.097567,-422.168701,294.500458,0.000000
110.000008,65.596756,-422.213196,-0.000504,0.004321,0.109757,291.788940,14.864437,1.097567,-422.213196,294.500458,0.000000
110.370003,65.585220,-422.213196,-0.000513,0.004321,0.109757,291.737640,14.861823,1.097567,-422.213196,294.500458,0.000000
110.740005,65.565475,-422.302155,-0.000496,0.004321,0.109757,291.649811,14.857348,1.097567,-422.302155,294.500458,0.000000
111.110008,65.535309,-422.213196,-0.000496,0.004321,0.109757,291.515625,14.850513,1.097567,-422.213196,294.500458,0.000000
111.480003,65.500320,-422.302155,-0.000479,0.004321,0.109757,291.359985,14.842586,1.097567,-422.302155,294.500458,0.000000
111.850006,65.431793,-422.257660,-0.000487,0.004321,0.109757,291.055145,14.827056,1.097567,-422.257660,294.500458,0.000000
112.220009,65.381531,-422.302155,-0.000509,0.004321,0.109757,290.831573,14.815667,1.097567,-422.302155,294.500458,0.000000
112.590004,65.303329,-422.391113,-0.000466,0.004321,0.109757,290.483704,14.797946,1.097567,-422.391113,294.500458,0.000000
112.960007,65.325302,-422.346619,-0.000461,0.004321,0.109757,290.581451,14.802925,1.097567,-422.346619,294.500458,0.000000
113.330002,65.274658,-422.346619,-0.000457,0.004321,0.109757,290.356171,14.791450,1.097567,-422.346619,294.500458,0.000000
113.700005,65.228851,-422.391113,-0.000466,0.004321,0.109757,290.152435,14.781069,1.097567,-422.391113,294.500458,0.000000
114.070007,65.185287,-422.391113,-0.000466,0.004321,0.109757,289.958649,14.771197,1.097567,-422.391113,294.500458,0.000000
114.440002,65.145813,-422.391113,-0.000461,0.004321,0.109764,289.783051,14.762252,1.097642,-422.391113,294.500458,0.000000
114.810005,65.119751,-422.435577,-0.000466,0.004321,0.109764,289.667114,14.756347,1.097642,-422.435577,294.500458,0.000000
115.180008,65.087723,-422.391113,-0.000470,0.004324,0.109834,289.524658,14.749088,1.098339,-422.391113,294.500458,0.000000
115.550003,65.284714,-422.480072,-0.000457,0.004326,0.109869,290.400909,14.793728,1.098687,-422.480072,294.500458,0.000000
115.920006,65.286942,-422.480072,-0.000466,0.004326,0.109869,290.410828,14.794232,1.098687,-422.480072,294.500458,0.000000
116.290009,65.276886,-422.524567,-0.000479,0.004326,0.109869,290.366089,14.791954,1.098687,-422.524567,294.500458,0.000000
116.660004,65.239655,-422.524567,-0.000457,0.004326,0.109869,290.200470,14.783518,1.098687,-422.524567,294.500458,0.000000
117.030006,65.213959,-422.480072,-0.000461,0.004326,0.109869,290.086182,14.777695,1.098687,-422.480072,294.500458,0.000000
117.400009,65.179703,-422.524567,-0.000461,0.004326,0.109869,289.933807,14.769932,1.098687,-422.524567,294.500458,0.000000
117.770004,65.151031,-422.569031,-0.000448,0.004326,0.109869,289.806274,14.763435,1.098687,-422.569031,294.500458,0.000000
118.140007,65.109695,-422.613525,-0.000461,0.004326,0.109869,289.622375,14.754068,1.098687,-422.613525,294.500458,0.000000
118.510002,65.069107,-422.657990,-0.000453,0.004326,0.109878,289.441833,14.744871,1.098778,-422.657990,294.500458,0.000000
118.880005,65.281723,-422.613525,-0.000466,0.004330,0.109973,290.387604,14.793050,1.099732,-422.613525,294.500458,0.000000
119.250008,65.304443,-422.569031,-0.000453,0.004330,0.109973,290.488678,14.798199,1.099732,-422.569031,294.500458,0.000000
119.620003,65.289551,-422.613525,-0.000461,0.004330,0.109973,290.422424,14.794824,1.099732,-422.613525,294.500458,0.000000
119.990005,65.284332,-422.702484,-0.000457,0.004330,0.109973,290.399200,14.793641,1.099732,-422.702484,294.500458,0.000000
120.360008,65.248962,-422.746948,-0.000457,0.004330,0.109973,290.241882,14.785626,1.099732,-422.746948,294.500458,0.000000
120.730003,65.228485,-422.702484,-0.000461,0.004330,0.109973,290.150787,14.780987,1.099732,-422.702484,294.500458,0.000000
121.100006,65.216934,-422.657990,-0.000457,0.004330,0.109973,290.099426,14.778368,1.099732,-422.657990,294.500458,0.000000
121.470009,65.166290,-422.657990,-0.000457,0.004330,0.109973,289.874146,14.766892,1.099732,-422.657990,294.500458,0.000000
121.840004,65.139481,-422.791443,-0.000444,0.004330,0.109973,289.754883,14.760817,1.099732,-422.791443,294.500458,0.000000
122.210007,65.110062,-422.791443,-0.000470,0.004330,0.109973,289.624023,14.754150,1.099732,-422.791443,294.500458,0.000000
122.580009,65.241882,-422.746948,-0.000466,0.004333,0.110059,290.210388,14.784021,1.100595,-422.746948,294.500458,0.000000
122.950005,65.266098,-422.791443,-0.000457,0.004333,0.110059,290.318115,14.789509,1.100595,-422.791443,294.500458,0.000000
123.320007,65.251572,-422.791443,-0.000461,0.004333,0.110059,290.253479,14.786218,1.100595,-422.791443,294.500458,0.000000
123.690002,65.233322,-422.835907,-0.000448,0.004333,0.110059,290.172302,14.782083,1.100595,-422.835907,294.500458,0.000000
124.060005,65.230713,-422.835907,-0.000470,0.004333,0.110059,290.160706,14.781491,1.100595,-422.835907,294.500458,0.000000
124.430008,65.187149,-422.880402,-0.000457,0.004333,0.110059,289.966919,14.771620,1.100595,-422.880402,294.500458,0.000000
124.800003,65.170013,-422.835907,-0.000457,0.004333,0.110059,289.890686,14.767735,1.100595,-422.835907,294.500458,0.000000
125.170006,65.125702,-422.880402,-0.000453,0.004333,0.110059,289.693604,14.757695,1.100595,-422.880402,294.500458,0.000000
125.540009,65.102997,-422.969360,-0.000461,0.004333,0.110059,289.592590,14.752550,1.100595,-422.969360,294.500458,0.000000
125.910004,65.110443,-422.969360,-0.000470,0.004334,0.110094,289.625702,14.754238,1.100943,-422.969360,294.500458,0.000000
126.280006,65.115646,-422.969360,-0.000453,0.004334,0.110094,289.648865,14.755416,1.100943,-422.969360,294.500458,0.000000
126.650009,65.101135,-422.924896,-0.000457,0.004334,0.110094,289.584320,14.752128,1.100943,-422.924896,294.500458,0.000000
127.020004,65.085861,-423.013855,-0.000470,0.004334,0.110094,289.516357,14.748668,1.100943,-423.013855,294.500458,0.000000
127.390007,65.073578,-422.969360,-0.000461,0.004335,0.110103,289.461731,14.745884,1.101034,-422.969360,294.500458,0.000000
127.760010,65.045639,-423.058319,-0.000448,0.004335,0.110103,289.337463,14.739552,1.101034,-423.058319,294.500458,0.000000
128.130005,65.032242,-423.102814,-0.000457,0.004335,0.110103,289.277863,14.736517,1.101034,-423.102814,294.500458,0.000000
128.500000,64.995377,-423.013855,-0.000448,0.004335,0.110103,289.113861,14.728163,1.101034,-423.013855,294.500458,0.000000
128.870010,64.991287,-423.013855,-0.000466,0.004335,0.110103,289.095673,14.727236,1.101034,-423.013855,294.500458,0.000000
129.240005,64.960373,-423.102814,-0.000457,0.004335,0.110103,288.958160,14.720231,1.101034,-423.102814,294.500458,0.000000
129.610001,64.953674,-423.102814,-0.000474,0.004335,0.110103,288.928375,14.718713,1.101034,-423.102814,294.500458,0.000000
129.980011,65.562500,-423.147278,-0.000461,0.004348,0.110450,291.636566,14.856675,1.104501,-423.147278,294.500458,0.000000
130.350006,65.844009,-423.102814,-0.000457,0.004345,0.110355,292.888794,14.920465,1.103547,-423.102814,294.500458,0.000000
130.720001,65.837311,-423.147278,-0.000457,0.004345,0.110355,292.858978,14.918947,1.103547,-423.147278,294.500458,0.000000
131.090012,65.809753,-423.191772,-0.000470,0.004345,0.110355,292.736389,14.912704,1.103547,-423.191772,294.500458,0.000000
131.460007,65.805664,-423.191772,-0.000461,0.004345,0.110355,292.718201,14.911777,1.103547,-423.191772,294.500458,0.000000
131.830002,65.774384,-423.236237,-0.000457,0.004345,0.110355,292.579071,14.904688,1.103547,-423.236237,294.500458,0.000000
132.200012,65.760971,-423.191772,-0.000457,0.004345,0.110355,292.519409,14.901649,1.103547,-423.191772,294.500458,0.000000
132.570007,65.764694,-423.236237,-0.000466,0.004345,0.110355,292.535980,14.902493,1.103547,-423.236237,294.500458,0.000000
132.940002,65.740860,-423.236237,-0.000461,0.004345,0.110355,292.429962,14.897092,1.103547,-423.236237,294.500458,0.000000
133.310013,65.699158,-423.280731,-0.000466,0.004345,0.110355,292.244446,14.887642,1.103547,-423.280731,294.500458,0.000000
133.680008,65.658203,-423.369690,-0.000453,0.004345,0.110355,292.062286,14.878362,1.103547,-423.369690,1681.640747,0.000000
134.050003,65.625061,-423.280731,-0.000453,0.004336,0.110129,291.914856,14.870852,1.101291,-423.280731,0.110069,0.000000
134.420013,65.597504,-423.236237,-0.000444,0.004322,0.109782,291.792267,14.864607,1.097824,-423.236237,0.109452,0.000000
134.790009,65.479828,-423.280731,-0.000461,0.004304,0.109315,291.268829,14.837941,1.093146,-423.280731,0.108836,0.000000
135.160004,65.468292,-423.369690,-0.000461,0.004288,0.108906,291.217499,14.835327,1.089058,-423.369690,0.108222,0.000000
135.530014,65.397171,-423.369690,-0.000461,0.004258,0.108152,290.901154,14.819211,1.081519,-423.369690,0.107605,0.000000
135.900009,65.382645,-423.325226,-0.000453,0.004234,0.107536,290.836517,14.815919,1.075357,-423.325226,0.106982,0.000000
136.270004,65.359558,-423.325226,-0.000444,0.004209,0.106903,290.733826,14.810687,1.069028,-423.325226,0.106365,0.000000
136.639999,65.295502,-423.414185,-0.000448,0.004186,0.106331,290.448883,14.796172,1.063306,-423.414185,0.105749,0.000000
137.010010,65.281357,-423.414185,-0.000457,0.004163,0.105749,290.385986,14.792967,1.057492,-423.414185,0.105135,0.000000
137.380005,65.196457,-423.458649,-0.000440,0.004145,0.105272,290.008331,14.773728,1.052723,-423.458649,0.104518,0.000000
137.750000,65.114166,-423.458649,-0.000444,0.004112,0.104449,289.642273,14.755081,1.044487,-423.458649,0.103902,0.000000
138.120010,64.938782,-423.414185,-0.000440,0.004096,0.104032,288.862122,14.715339,1.040324,-423.414185,0.103286,0.000000
138.490005,64.326599,-423.503143,-0.000435,0.004071,0.103409,286.139008,14.576616,1.034086,-423.503143,0.102671,0.000000
138.860001,63.498444,-423.503143,-0.000431,0.004049,0.102853,282.455170,14.388953,1.028530,-423.503143,0.102046,0.000000
139.230011,62.385788,-423.503143,-0.000418,0.004029,0.102332,277.505859,14.136822,1.023322,-423.503143,0.101431,0.000000
139.600006,60.905235,-423.503143,-0.000418,0.004006,0.101743,270.920013,13.801323,1.017433,-423.503143,0.100815,0.000000
139.970001,58.959961,-423.503143,-0.000414,0.003979,0.101057,262.266998,13.360518,1.010575,-423.503143,0.100199,0.000000
140.340012,56.994209,-423.503143,-0.000418,0.003952,0.100390,253.522903,12.915072,1.003898,-423.503143,0.099583,0.000000
140.710007,55.102554,-423.592102,-0.000414,0.003935,0.099948,245.108398,12.486417,0.999477,-423.592102,0.098968,0.000000
141.080002,52.780067,-423.592102,-0.000414,0.003910,0.099315,234.777466,11.960134,0.993149,-423.592102,0.098352,0.000000
141.450012,50.148140,-423.636566,-0.000423,0.003887,0.098724,223.070068,11.363731,0.987244,-423.636566,0.097736,0.000000
141.820007,47.534828,-423.636566,-0.000410,0.003861,0.098075,211.445480,10.771545,0.980750,-423.636566,0.097121,0.000000
142.190002,45.623444,-423.636566,-0.000414,0.003845,0.097675,202.943207,10.338420,0.976753,-423.636566,0.096496,0.000000
142.560013,41.947754,-423.636566,-0.000431,0.003811,0.096808,186.592926,9.505496,0.968078,-423.636566,0.095881,0.000000
142.930008,40.289207,-423.725525,-0.000418,0.003795,0.096384,179.215347,9.129664,0.963839,-423.725525,0.095265,0.000000
143.300003,38.660080,-423.725525,-0.000410,0.003783,0.096080,171.968628,8.760499,0.960796,-423.725525,0.094649,0.000000
143.670013,34.550949,-423.681061,-0.000418,0.003741,0.095030,153.690292,7.829357,0.950304,-423.681061,0.094033,0.000000
144.040009,32.288414,-423.725525,-0.000423,0.003720,0.094493,143.626038,7.316659,0.944929,-423.725525,0.093418,0.000000
144.410004,29.022705,-423.770020,-0.000423,0.003692,0.093781,129.099442,6.576639,0.937814,-423.770020,0.092802,0.000000
144.780014,27.922722,-423.770020,-0.000418,0.003682,0.093513,124.206467,6.327379,0.935134,-423.770020,0.092186,0.000000
145.150009,24.960495,-423.814514,-0.000418,0.003650,0.092697,111.029823,5.656129,0.926974,-423.814514,0.091571,0.000000
145.520004,21.708565,-423.814514,-0.000414,0.003624,0.092048,96.564522,4.919231,0.920479,-423.814514,0.090946,0.000000
145.889999,18.971626,-423.814514,-0.000418,0.003597,0.091362,84.390007,4.299032,0.913621,-423.814514,0.090330,0.000000
146.260010,15.982971,-423.814514,-0.000427,0.003571,0.090703,71.095810,3.621793,0.907035,-423.814514,0.089715,0.000000
146.630005,14.157967,-423.858978,-0.000414,0.003555,0.090287,62.977779,3.208241,0.902872,-423.858978,0.089099,0.000000
147.000000,11.968048,-423.903473,-0.000423,0.003534,0.089775,53.236538,2.711998,0.897754,-423.903473,0.088483,0.000000
147.370010,8.643135,-423.903473,-0.000444,0.003503,0.088978,38.446587,1.958562,0.889776,-423.903473,0.087868,0.000000
147.740005,5.857414,-423.858978,-0.000440,0.003475,0.088275,26.055080,1.327309,0.882751,-423.858978,0.087252,0.000000
148.110001,4.042099,-423.858978,-0.000453,0.003456,0.087772,17.980154,0.915953,0.877725,-423.858978,0.086635,0.000000
148.480011,0.980827,-423.858978,-0.000444,0.003429,0.087087,4.362938,0.222259,0.870866,-423.858978,0.086021,0.000000
148.850006,-0.993492,-423.947937,-0.000457,0.003406,0.086514,-4.419274,-0.225129,0.865144,-423.947937,0.085396,0.000000
149.220001,-3.108940,-424.036896,-0.000444,0.003380,0.085856,-13.829256,-0.704496,0.858558,-424.036896,0.084779,0.000000
149.590012,-0.301628,-423.947937,-0.000522,0.003355,0.085214,-1.341709,-0.068350,0.852139,-423.947937,0.084165,0.000000
149.960007,0.016006,-424.036896,-0.000548,0.003334,0.084684,0.071200,0.003627,0.846840,-424.036896,0.083549,0.000000
150.330002,0.044685,-423.992432,-0.000591,0.003303,0.083886,0.198770,0.010126,0.838861,-423.992432,0.082932,0.000000
150.700012,0.021591,-424.036896,-0.000629,0.003282,0.083367,0.096042,0.004893,0.833669,-424.036896,0.082318,0.000000
151.070007,0.023827,-424.036896,-0.000651,0.003250,0.082551,0.105986,0.005399,0.825508,-424.036896,0.081701,0.000000
151.440002,-0.007820,-424.036896,-0.000694,0.003231,0.082066,-0.034786,-0.001772,0.820664,-424.036896,0.081085,0.000000
151.810013,0.005585,-424.036896,-0.000720,0.003210,0.081536,0.024842,0.001266,0.815365,-424.036896,0.080471,0.000000
152.180008,0.049522,-424.081390,-0.000772,0.003183,0.080852,0.220287,0.011222,0.808522,-424.081390,0.079845,0.000000
152.550003,0.040215,-424.081390,-0.000798,0.003171,0.080539,0.178883,0.009113,0.805388,-424.081390,0.080392,0.000000
152.600006,0.043938,-424.081390,-0.000802,0.003171,0.080548,0.195445,0.009956,0.805479,-424.081390,0.080392,0.000000